File: examples/hot axisymmetric compression example/data/12 fitted data ramberg/testID_0147.csv
level_0,index,Time(sec),Force(kN),Jaw(mm),PowAngle(deg),Power(W),Pram,PTemp,Strain,Stress(MPa),Stroke(mm),TC1(C),wedge(mm),uncorrected stress,sampled strain,sampled stress,fitting strain,fitting stress,model strain,ramberg stress,ramberg plastic strain,ramberg accumulated plastic strain
2437,2437,212.0103,0.42579189,0.090491921,0.0,0,9.0922337,0.0,0.0060958923,5.157339761240268,10.140811,500.39365,-9.2089701,5.157339761240268,0.0060958923,5.157339761240268,0.0,5.157339761240268,0.0,0.0,0.0,0.0
2439,2439,212.0107,3.2889717,0.14669029,0.0,0,9.0337057,0.0,0.0091848122,39.67733831893395,10.07314,500.51422,-9.2084837,39.67733831893395,0.12594907,54.50744740142755,0.098028547,57.048162194851486,0.004337546327433628,37.6360204746758,0.0043366853566018165,0.0043366853566018165
2441,2441,212.0111,4.7077785,0.21328419,0.0,0,8.9751778,0.0,0.014155177,56.522343737244206,10.013556,500.6348,-9.2060976,56.522343737244206,0.20378716,53.565370066393456,0.196057094,53.48032130806306,0.008675092654867256,39.0904728210406,0.008674198411626973,0.008674198411626973
2443,2443,212.0115,4.7625852,0.30824369,0.0,0,8.9166498,0.0,0.019780027,56.78919829079378,9.9260597,500.75534,-9.2020216,56.78919829079378,0.29242918,53.55592327473816,0.294085641,53.54093078993787,0.013012638982300885,40.06646399438802,0.01301172241204723,0.01301172241204723
2445,2445,212.0119,4.3270526,0.47480282,0.0,0,8.8581219,0.0,0.031043185,50.972410640145554,9.8234386,500.87592,-9.202713,50.972410640145554,0.39160225,52.41913966187785,0.392114188,52.4080253965151,0.017350185309734513,40.821832782067524,0.017349251459479274,0.017349251459479274
2447,2447,212.0123,4.6089058,0.56114042,0.0,0,8.7995939,0.0,0.037822299,53.94831387763282,9.7069063,500.99646,-9.204917,53.94831387763282,0.48859152,50.52550812284684,0.49014273499999994,50.50623379006454,0.02168773163716814,41.446554117922766,0.021686783495634455,0.021686783495634455
2449,2449,212.0127,4.6787691,0.68525076,0.0,0,8.7416534,0.0,0.045575093,54.26354721005253,9.5956955,501.11703,-9.2057419,54.26354721005253,0.58459628,49.712445222079154,0.588171282,49.68440075148906,0.02602527796460177,41.98366260130308,0.026024317536042733,0.026024317536042733
2451,2451,212.0131,5.1296306,0.76151448,0.0,0,8.6858492,0.0,0.051964048,59.15395047549694,9.4985342,501.23761,-9.2052736,59.15395047549694,0.68231279,49.19899116032202,0.686199829,49.18621963370991,0.0303628242920354,42.4573942759449,0.030361853026274428,0.030361853026274428
2453,2453,212.0135,4.5476437,0.78389442,0.0,0,8.6301851,0.0,0.053505383,52.35448532964046,9.4090919,501.35815,-9.2030344,52.35448532964046,0.78152317,49.15826124123366,0.784228376,49.171348255324254,0.034700370619469026,42.88286855808325,0.03469938962045406,0.03469938962045406
2455,2455,212.0139,4.6091723,0.8852852,0.0,0,8.5745211,0.0,0.059988666,52.65825758351642,9.3308697,501.47873,-9.20399,52.65825758351642,0.88114196,49.61693948616775,0.8822569229999999,49.6246064065331,0.03903791694690265,43.27020830690262,0.03903692708700862,0.03903692708700862
2457,2457,212.0143,5.2257395,0.92035365,0.0,0,8.518857,0.0,0.063188367,59.543664828194366,9.2577581,501.5993,-9.2031031,59.543664828194366,0.98028547,50.55014310524537,0.98028547,50.55014310524537,0.04337546327433628,43.6265524938655,0.04337446526262526,0.04337446526262526
2459,2459,212.0147,5.2753077,1.0050497,0.0,0,8.4631929,0.0,0.068649739,59.72157816556096,9.1778088,501.71985,-9.201726,59.72157816556096,,,,,0.04771300960176991,43.957140627101246,0.04771200402744371,0.04771200402744371
2461,2461,212.0151,5.0003142,1.1270803,0.0,0,8.4075289,0.0,0.077077314,56.07992952099726,9.0959883,501.84042,-9.2034283,56.07992952099726,,,,,0.05205055592920354,44.26594168976145,0.052049543290668514,0.052049543290668514
2463,2463,212.0155,4.817059,1.1938062,0.0,0,8.3518648,0.0,0.082505412,53.7462576989567,9.0085802,501.961,-9.2055254,53.7462576989567,,,,,0.056388102256637165,44.55604051956988,0.05638708298173019,0.05638708298173019
2465,2465,212.0159,5.0774345,1.2807752,0.0,0,8.2962008,0.0,0.088670887,56.26885028135696,8.9227295,502.08154,-9.2043247,56.26885028135696,,,,,0.0607256485840708,44.829886429523945,0.06072462304459764,0.06072462304459764
2467,2467,212.0163,5.0738988,1.3360677,0.0,0,8.2405367,0.0,0.092706814,55.9865960821338,8.8441954,502.20212,-9.2027454,55.9865960821338,,,,,0.06506319491150442,45.08945940491787,0.06506216343397624,0.06506216343397624
2469,2469,212.0167,5.0922098,1.392681,0.0,0,8.1848736,0.0,0.097129397,55.93884375163616,8.7773256,502.32266,-9.2022018,55.93884375163616,,,,,0.06940074123893805,45.336384810970664,0.06939970411268374,0.06939970411268374
2471,2471,212.0171,4.8795347,1.4591674,0.0,0,8.1292095,0.0,0.10188583,53.32142673031149,8.7137604,502.44324,-9.2028723,53.32142673031149,,,,,0.07373828756637169,45.57201474689949,0.0737372450497892,0.0737372450497892
2473,2473,212.0175,5.2045774,1.5076636,0.0,0,8.0735445,0.0,0.10534369,56.65459890198386,8.6583624,502.56021,-9.2044296,56.65459890198386,,,,,0.0780758338938053,45.79748711311145,0.07807478621926169,0.07807478621926169
2475,2475,212.0179,5.3653584,1.5772005,0.0,0,8.0196619,0.0,0.11071683,58.08140035231661,8.5952625,502.67722,-9.2042713,58.08140035231661,,,,,0.08241338022123894,46.013769382113104,0.0824123275989691,0.0824123275989691
2477,2477,212.0183,5.1717353,1.6546289,0.0,0,7.9666953,0.0,0.11622236,55.638242882158906,8.5334101,502.79419,-9.2029696,55.638242882158906,,,,,0.08675092654867256,46.22169162128007,0.0867498691699226,0.0867498691699226
2479,2479,212.0187,5.0761561,1.723981,0.0,0,7.9137354,0.0,0.12156626,54.304765509099305,8.4665546,502.91119,-9.2019691,54.304765509099305,,,,,0.09108847287610619,46.42197180680025,0.09108741091569761,0.09108741091569761
2481,2481,212.0191,5.1170645,1.7769345,0.0,0,7.860775,0.0,0.12594907,54.50744740142755,8.4044552,503.02817,-9.2020283,54.50744740142755,,,,,0.09542601920353982,46.61523550515732,0.09542495282198349,0.09542495282198349
2483,2483,212.0195,5.1679564,1.8154349,0.0,0,7.8078156,0.0,0.12846719,54.87701135109464,8.3494892,503.14514,-9.2029753,54.87701135109464,,,,,0.09976356553097344,46.80203137221341,0.09976249487622905,0.09976249487622905
2485,2485,212.0199,5.1281219,1.865653,0.0,0,7.7548552,0.0,0.13259666,54.23068192611184,8.2929087,503.26215,-9.2052021,54.23068192611184,,,,,0.10410111185840708,46.98284349934379,0.10410003706736014,0.10410003706736014
2487,2487,212.0203,5.0569549,1.9150113,0.0,0,7.7018952,0.0,0.13634416,53.261591238966645,8.2428608,503.37912,-9.2050924,53.261591238966645,,,,,0.10843865818584071,47.158101352107,0.10843757938555217,0.10843757938555217
2489,2489,212.0207,5.2818112,1.9519892,0.0,0,7.6489348,0.0,0.13889946,55.46044233047278,8.1965075,503.49609,-9.2035131,55.46044233047278,,,,,0.11277620451327433,47.32818784659661,0.11277512182204544,0.11277512182204544
2491,2491,212.0211,5.2913041,2.0031202,0.0,0,7.5959754,0.0,0.14319767,55.32542474575596,8.1465921,503.6131,-9.2022429,55.32542474575596,,,,,0.11711375084070796,47.49344597076123,0.1171126643689937,0.1171126643689937
2493,2493,212.0215,5.2469535,2.0616093,0.0,0,7.543015,0.0,0.14740461,54.59545100343693,8.0999107,503.73007,-9.2032995,54.59545100343693,,,,,0.1214512971681416,47.654184255672405,0.12145020701933892,0.12145020701933892
2495,2495,212.0219,5.2288365,2.1126585,0.0,0,7.4900556,0.0,0.15122721,54.17533781797745,8.0445623,503.84705,-9.2033606,54.17533781797745,,,,,0.12578884349557523,47.81068133079967,0.1257877497667071,0.1257877497667071
2497,2497,212.0223,5.2156367,2.1572075,0.0,0,7.4370952,0.0,0.15527904,53.836955520378005,7.9936185,503.96405,-9.2046375,53.836955520378005,,,,,0.13012638982300884,47.96318974215405,0.13012529260532088,0.13012529260532088
2499,2499,212.0227,5.283299,2.1988165,0.0,0,7.384666,0.0,0.1579586,54.34460679187419,7.943274,504.08102,-9.2049866,54.34460679187419,,,,,0.13446393615044247,48.11193917299224,0.13446283552992608,0.13446283552992608
2501,2501,212.0231,5.1700835,2.2479985,0.0,0,7.3341718,0.0,0.1619294,52.95937630006593,7.895606,504.19803,-9.2041273,52.95937630006593,,,,,0.1388014824778761,48.25713917705899,0.13880037853572882,0.13880037853572882
2503,2503,212.0235,5.2040052,2.2845676,0.0,0,7.2838035,0.0,0.16527732,53.14167199246988,7.852026,504.315,-9.2034349,53.14167199246988,,,,,0.14313902880530974,48.39898151041128,0.14313792161834246,0.14313792161834246
2505,2505,212.0239,5.3156629,2.3252797,0.0,0,7.2334356,0.0,0.1678292,54.09403312872829,7.8109922,504.43198,-9.2026825,54.09403312872829,,,,,0.14747657513274337,48.537642131315614,0.14747546477374174,0.14747546477374174
2507,2507,212.0243,5.4090056,2.3706422,0.0,0,7.1830673,0.0,0.17173056,54.83091702078454,7.7688189,504.54898,-9.2021637,54.83091702078454,,,,,0.15181412146017698,48.67328292386369,0.1518130079982233,0.1518130079982233
2509,2509,212.0247,5.3360415,2.414638,0.0,0,7.132699,0.0,0.1752519,53.88746427436063,7.719686,504.66595,-9.2033596,53.88746427436063,,,,,0.1561516677876106,48.80605318989299,0.1561505512883718,0.1561505512883718
2511,2511,212.0251,5.3080482,2.4709013,0.0,0,7.0823312,0.0,0.17920715,53.34545813823022,7.6766782,504.78293,-9.2022486,53.34545813823022,,,,,0.16048921411504424,48.93609094625238,0.1604880946410298,0.1604880946410298
2513,2513,212.0255,5.370513,2.5076926,0.0,0,7.0319633,0.0,0.18286636,53.80164769231579,7.6307087,504.89993,-9.2032938,53.80164769231579,,,,,0.16482676044247788,49.06352405705997,0.16482563805327238,0.16482563805327238
2515,2515,212.0259,5.4292417,2.5482776,0.0,0,6.981595,0.0,0.18578258,54.198636627514816,7.5879846,505.01691,-9.2037516,54.198636627514816,,,,,0.1691643067699115,49.18847122567593,0.16916318152238394,0.16916318152238394
2517,2517,212.0263,5.3917561,2.6049287,0.0,0,6.9312272,0.0,0.18997648,53.559142438279714,7.5398355,505.13388,-9.2028513,53.559142438279714,,,,,0.17350185309734512,49.31104286734051,0.1735007250458386,0.1735007250458386
2519,2519,212.0267,5.3399134,2.6363723,0.0,0,6.8808589,0.0,0.19332796,52.898320127526944,7.4981985,505.25089,-9.2030897,52.898320127526944,,,,,0.17783939942477875,49.43134187875487,0.17783826862128257,0.17783826862128257
2521,2521,212.0271,5.450685,2.6753154,0.0,0,6.8304915,0.0,0.1959838,53.811261057911125,7.4543395,505.36786,-9.2027349,53.811261057911125,,,,,0.18217694575221238,49.54946431947827,0.1821758122465183,0.1821758122465183
2523,2523,212.0275,5.4938822,2.7277942,0.0,0,6.7801232,0.0,0.20012514,53.98725289142792,7.4102097,505.48837,-9.2016735,53.98725289142792,,,,,0.18651449207964602,49.665500017057546,0.18651335591949086,0.18651335591949086
2525,2525,212.0279,5.469758,2.7666852,0.0,0,6.7313666,0.0,0.20378716,53.565370066393456,7.3672285,505.60889,-9.2026262,53.565370066393456,,,,,0.19085203840707965,49.7795331056424,0.1908508996382756,0.1908508996382756
2527,2527,212.0283,5.4706931,2.8134456,0.0,0,6.6834412,0.0,0.20705505,53.35225283952333,7.3224907,505.7294,-9.2032499,53.35225283952333,,,,,0.19518958473451328,49.891642507079105,0.19518844340106709,0.19518844340106709
2529,2529,212.0287,5.5063968,2.8569317,0.0,0,6.6355214,0.0,0.21103731,53.49236932322312,7.2776661,505.84991,-9.203311,53.49236932322312,,,,,0.1995271310619469,50.001902361689275,0.1995259872061692,0.1995259872061692
2531,2531,212.0291,5.5677342,2.8942583,0.0,0,6.5876012,0.0,0.21413411,53.907625221815145,7.2317071,505.97043,-9.2031984,53.907625221815145,,,,,0.20386467738938052,50.11038241474721,0.20386353105198657,0.20386353105198657
2533,2533,212.0295,5.5571213,2.9432228,0.0,0,6.5396814,0.0,0.21774445,53.56837549370339,7.1889052,506.09091,-9.203517,53.56837549370339,,,,,0.20820222371681416,50.217148364482206,0.20820107493701615,0.20820107493701615
2535,2535,212.0299,5.570281,2.9875846,0.0,0,6.4917617,0.0,0.22199915,53.48043708440123,7.1432519,506.21143,-9.2034092,53.48043708440123,,,,,0.2125397700442478,50.322262175555224,0.21253861885984046,0.21253861885984046
2537,2537,212.0303,5.6474681,3.0315993,0.0,0,6.4438419,0.0,0.22546996,54.00542697050909,7.0983758,506.33194,-9.2032309,54.00542697050909,,,,,0.21687731637168142,50.42578236280288,0.21687616281912092,0.21687616281912092
2539,2539,212.0307,5.6839547,3.0813861,0.0,0,6.3959212,0.0,0.22934565,54.10831207973084,7.0500927,506.45245,-9.2025805,54.10831207973084,,,,,0.22121486269911503,50.52776424773147,0.22121370681359193,0.22121370681359193
2541,2541,212.0311,5.6758113,3.129318,0.0,0,6.3480015,0.0,0.23390363,53.79424344415655,7.0037208,506.57297,-9.202527,53.79424344415655,,,,,0.22555240902654866,50.62826019181773,0.2255512508420557,0.2255512508420557
2543,2543,212.0315,5.6825829,3.1793849,0.0,0,6.3000817,0.0,0.23769078,53.61101762380778,6.9530158,506.69348,-9.2040005,53.61101762380778,,,,,0.2298899553539823,50.727319808287696,0.22988879490337727,0.22988879490337727
2545,2545,212.0319,5.7431374,3.2251146,0.0,0,6.252162,0.0,0.24150147,53.95389921709327,6.9074235,506.814,-9.2046366,53.95389921709327,,,,,0.23422750168141593,50.82499015517602,0.2342263389964801,0.2342263389964801
2547,2547,212.0323,5.7718215,3.2678814,0.0,0,6.2042418,0.0,0.24569985,54.00867669715622,6.8594646,506.93451,-9.203825,54.00867669715622,,,,,0.23856504800884956,50.92131591137606,0.2385638831203421,0.2385638831203421
2549,2549,212.0327,5.7608862,3.3181653,0.0,0,6.1568022,0.0,0.24931875,53.65437142644748,6.8111353,507.05499,-9.203433,53.65437142644748,,,,,0.2429025943362832,51.016339538020674,0.24290142727399197,0.24290142727399197
2551,2551,212.0331,5.7683187,3.3634079,0.0,0,6.1111116,0.0,0.25348088,53.49655971219597,6.7632165,507.17551,-9.2026157,53.49655971219597,,,,,0.2472401406637168,51.11010142571143,0.24723897145650564,0.24723897145650564
2553,2553,212.0335,5.8407331,3.4093068,0.0,0,6.0655355,0.0,0.25777832,53.93490160696221,6.7154369,507.29602,-9.2026806,53.93490160696221,,,,,0.25157768699115046,51.20264002991983,0.2515765156670035,0.2515765156670035
2555,2555,212.0339,5.8745031,3.4645202,0.0,0,6.0199599,0.0,0.2618179,53.96451047011752,6.6677012,507.41653,-9.2025127,53.96451047011752,,,,,0.25591523331858407,51.2939919952811,0.25591405990464716,0.25591405990464716
2557,2557,212.0343,5.8838625,3.509912,0.0,0,5.9743834,0.0,0.26624376,53.81806363843658,6.6172547,507.53705,-9.2036238,53.81806363843658,,,,,0.2602527796460177,51.38419226983252,0.2602516041686372,0.2602516041686372
2559,2559,212.0347,5.8872743,3.5575545,0.0,0,5.9288073,0.0,0.27042201,53.60515365888609,6.56914,507.65756,-9.2040253,53.60515365888609,,,,,0.26459032597345133,51.47327421054288,0.2645891484582105,0.2645891484582105
2561,2561,212.0351,5.9248877,3.6133521,0.0,0,5.8832316,0.0,0.27460712,53.65986899194787,6.5174279,507.77808,-9.2042046,53.65986899194787,,,,,0.26892787230088494,51.56126968035728,0.26892669277263814,0.26892669277263814
2563,2563,212.0355,5.9639969,3.6574214,0.0,0,5.8376555,0.0,0.27921626,53.78526357854313,6.4688568,507.89859,-9.2033043,53.78526357854313,,,,,0.2732654186283186,51.64820913804496,0.2732642371112235,0.2732642371112235
2565,2565,212.0359,5.9954247,3.704644,0.0,0,5.792079,0.0,0.28320363,53.82219398547987,6.4226947,508.01907,-9.2031212,53.82219398547987,,,,,0.2776029649557522,51.734121721226806,0.2776017814732998,0.2776017814732998
2567,2567,212.0363,6.0024047,3.7631187,0.0,0,5.7465034,0.0,0.28796792,53.57923084213934,6.3703218,508.13959,-9.2014303,53.57923084213934,,,,,0.2819405112831858,51.81903532344889,0.281939325858229,0.281939325858229
2569,2569,212.0367,6.0241299,3.8045268,0.0,0,5.7009273,0.0,0.29242918,53.55592327473816,6.3199077,508.2601,-9.2020826,53.55592327473816,,,,,0.2862780576106195,51.90297666530607,0.28627687026539994,0.28627687026539994
2571,2571,212.0371,6.0467782,3.8525283,0.0,0,5.6553516,0.0,0.2961255,53.50447484592419,6.2720413,508.38062,-9.2028627,53.50447484592419,,,,,0.2906156039380531,51.98597136093046,0.29061441469422655,0.29061441469422655
2573,2573,212.0375,6.0917702,3.9075747,0.0,0,5.6097751,0.0,0.30116484,53.61049099499839,6.2196574,508.29108,-9.2035999,53.61049099499839,,,,,0.29495315026548674,52.06804397931839,0.29495195914414685,0.29495195914414685
2575,2575,212.0379,6.1235447,3.9494216,0.0,0,5.5656581,0.0,0.30551359,53.66688526449836,6.1693864,508.20157,-9.2034855,53.66688526449836,,,,,0.29929069659292035,52.14921810186415,0.2992895036146213,0.2992895036146213
2577,2577,212.0383,6.134829,4.0028458,0.0,0,5.5222936,0.0,0.30967131,53.480225678856826,6.1233582,508.11203,-9.2029266,53.480225678856826,,,,,0.30362824292035395,52.22951637557606,0.30362704810513197,0.30362704810513197
2579,2579,212.0387,6.1412821,4.0566001,0.0,0,5.4789333,0.0,0.31493491,53.24882019674145,6.0724287,508.02249,-9.2019348,53.24882019674145,,,,,0.3079657892477876,52.30896056291671,0.3079645926151809,0.3079645926151809
2581,2581,212.0391,6.16923,4.1001754,0.0,0,5.4355731,0.0,0.31912196,53.256868239936544,6.0206738,507.93295,-9.2020826,53.256868239936544,,,,,0.3123033355752212,52.38757158821729,0.3123021371442894,0.3123021371442894
2583,2583,212.0395,6.2121119,4.1504445,0.0,0,5.3922133,0.0,0.32311815,53.35487599670192,5.9728851,507.84344,-9.2017736,53.35487599670192,,,,,0.3166408819026549,52.465369581145545,0.31663968169199713,0.31663968169199713
2585,2585,212.0399,6.2471623,4.1981292,0.0,0,5.3488531,0.0,0.32819906,53.39624556871591,5.9261765,507.75391,-9.2028217,53.39624556871591,,,,,0.3209784282300885,52.54237391725437,0.3209772262578606,0.3209772262578606
2587,2587,212.0403,6.2596736,4.2437696,0.0,0,5.3054934,0.0,0.33220333,53.25411549543649,5.8702831,507.66437,-9.203476,53.25411549543649,,,,,0.3253159745575221,52.61860325606828,0.3253147708414532,0.3253147708414532
2589,2589,212.0407,6.2601781,4.2969356,0.0,0,5.2621331,0.0,0.33679309,52.96821141624194,5.8253098,507.57486,-9.2024965,52.96821141624194,,,,,0.32965352088495575,52.69407557658114,0.32965231544236356,0.32965231544236356
2591,2591,212.0411,6.3076549,4.3445487,0.0,0,5.2187734,0.0,0.34191543,53.108027519300194,5.7746735,507.48532,-9.2030783,53.108027519300194,,,,,0.33399106721238936,52.768808210803066,0.3339898600601951,0.3339898600601951
2593,2593,212.0415,6.3423867,4.3930511,0.0,0,5.1754136,0.0,0.34593603,53.13217064594546,5.7254581,507.39578,-9.2034454,53.13217064594546,,,,,0.338328613539823,52.8428178749445,0.33832740469456557,0.33832740469456557
2595,2595,212.0419,6.3711271,4.4416227,0.0,0,5.1320534,0.0,0.35054755,53.10301853165669,5.6794987,507.30627,-9.2021875,53.10301853165669,,,,,0.3426661598672566,52.91612069906725,0.3426649493451058,0.3426649493451058
2597,2597,212.0423,6.3788142,4.4858961,0.0,0,5.0886931,0.0,0.35535252,52.92072965437396,5.6284995,507.21674,-9.2034502,52.92072965437396,,,,,0.34700370619469023,52.988732254505834,0.34700249401145966,0.34700249401145966
2599,2599,212.0427,6.3775311,4.5400906,0.0,0,5.0457678,0.0,0.35964167,52.60853965766674,5.5807357,507.1272,-9.2033997,52.60853965766674,,,,,0.3513412525221239,53.06066758027097,0.3513400386932831,0.3513400386932831
2601,2601,212.0431,6.4129381,4.5840745,0.0,0,5.0044241,0.0,0.36426091,52.65449106589882,5.5328989,507.03769,-9.2035093,52.65449106589882,,,,,0.3556787988495575,53.131941207156224,0.3556775833902438,0.3556775833902438
2603,2603,212.0435,6.4573646,4.6265445,0.0,0,4.9631839,0.0,0.36873904,52.77993726527895,5.4888539,506.94815,-9.2038546,52.77993726527895,,,,,0.36001634517699116,53.20256718135991,0.36001512810202035,0.36001512810202035
2605,2605,212.0439,6.4659519,4.6802187,0.0,0,4.9219437,0.0,0.37302461,52.5472230489261,5.4400978,506.85861,-9.203846,52.5472230489261,,,,,0.36435389150442477,53.27255908576061,0.36435267282830197,0.36435267282830197
2607,2607,212.0443,6.4702263,4.7233443,0.0,0,4.8807039,0.0,0.37777421,52.33839381081272,5.3916035,506.7691,-9.202177,52.33839381081272,,,,,0.3686914378318584,53.3419300608529,0.3686902175687882,0.3686902175687882
2609,2609,212.0447,6.489563,4.7686443,0.0,0,4.8394637,0.0,0.38222787,52.238168446836966,5.3474894,506.67957,-9.2022457,52.238168446836966,,,,,0.37302898415929203,53.41069282411087,0.373027762323188,0.373027762323188
2611,2611,212.0451,6.5351119,4.8212161,0.0,0,4.798224,0.0,0.38675621,52.30484736447215,5.3030162,506.59003,-9.2038612,52.30484736447215,,,,,0.37736653048672564,53.478859688208416,0.3773653070912197,0.3773653070912197
2613,2613,212.0455,6.5780497,4.8611469,0.0,0,4.7569838,0.0,0.39160225,52.41913966187785,5.2626562,506.50052,-9.2047224,52.41913966187785,,,,,0.3817040768141593,53.546442578590614,0.3817028518726106,0.3817028518726106
2615,2615,212.0459,6.5760918,4.9055047,0.0,0,4.7157435,0.0,0.39554688,52.14878726214202,5.2076817,506.41098,-9.2037678,52.14878726214202,,,,,0.3860416231415929,53.613453049722054,0.3860403966670962,0.3860403966670962
2617,2617,212.0463,6.5902529,4.9591746,0.0,0,4.6745038,0.0,0.40053523,51.952149742106194,5.1645365,506.32144,-9.2034521,51.952149742106194,,,,,0.39037916946902657,53.67990230068837,0.3903779414744205,0.3903779414744205
2619,2619,212.0467,6.6084738,4.9972758,0.0,0,4.6332641,0.0,0.40523759,51.875835094943454,5.1198335,506.23193,-9.2027531,51.875835094943454,,,,,0.39471671579646017,53.74580119004163,0.394715486294335,0.394715486294335
2621,2621,212.0471,6.6332636,5.041749,0.0,0,4.5920234,0.0,0.40898943,51.81270176659417,5.0737977,506.1424,-9.2019625,51.81270176659417,,,,,0.3990542621238938,53.81116024969075,0.39905303112659873,0.39905303112659873
2623,2623,212.0475,6.6642509,5.0917425,0.0,0,4.5507836,0.0,0.41402856,51.76363111581833,5.0274711,506.09229,-9.2019911,51.76363111581833,,,,,0.40339180845132744,53.875989698103524,0.40339057597097805,0.40339057597097805
2625,2625,212.0479,6.696454,5.129055,0.0,0,4.5108657,0.0,0.41840956,51.79541560024478,4.9849238,506.04218,-9.2027836,51.79541560024478,,,,,0.40772935477876104,53.94029945300772,0.4077281208272459,0.4077281208272459
2627,2627,212.0483,6.7041283,5.1777349,0.0,0,4.4716296,0.0,0.42253083,51.56954401899035,4.9391589,505.99207,-9.2035942,51.56954401899035,,,,,0.4120669011061947,54.00409914323179,0.4120656656951822,0.4120656656951822
2629,2629,212.0487,6.7302237,5.2242365,0.0,0,4.4323974,0.0,0.42788157,51.49671069418915,4.8956647,505.94196,-9.2026749,51.49671069418915,,,,,0.4164044474336283,54.067398120129276,0.4164032105745729,0.4164032105745729
2631,2631,212.0491,6.7532458,5.2627759,0.0,0,4.3931651,0.0,0.43183208,51.44533888305868,4.8522964,505.89185,-9.2021561,51.44533888305868,,,,,0.4207419937610619,54.13020546839364,0.4207407554652102,0.4207407554652102
2633,2633,212.0495,6.7935219,5.3082714,0.0,0,4.3539338,0.0,0.43600947,51.481928706797945,4.8086939,505.84171,-9.2021904,51.481928706797945,,,,,0.4250795400884956,54.19253001620972,0.42507830036689226,0.42507830036689226
2635,2635,212.0499,6.8083568,5.350565,0.0,0,4.3147016,0.0,0.44119102,51.34255861340626,4.7621436,505.7916,-9.2011023,51.34255861340626,,,,,0.4294170864159292,54.25438034512906,0.42941584527942256,0.42941584527942256
2637,2637,212.0503,6.8258262,5.3899155,0.0,0,4.2754693,0.0,0.44490311,51.23939957383939,4.7180967,505.74149,-9.2026329,51.23939957383939,,,,,0.43375463274336284,54.315764799361425,0.4337533902026104,0.4337533902026104
2639,2639,212.0507,6.8378344,5.4343305,0.0,0,4.236237,0.0,0.44907418,51.06391324009175,4.6792178,505.69138,-9.2029629,51.06391324009175,,,,,0.43809217907079645,54.376691494593054,0.43809093513627,0.43809093513627
2641,2641,212.0511,6.8728218,5.4738131,0.0,0,4.1970053,0.0,0.45411184,51.08782711481362,4.6376204,505.64127,-9.2033854,51.08782711481362,,,,,0.44242972539823006,54.43716832645003,0.44242848008022073,0.44242848008022073
2643,2643,212.0515,6.9162669,5.5180693,0.0,0,4.1577735,0.0,0.45798233,51.1429881339874,4.5920191,505.59116,-9.2027264,51.1429881339874,,,,,0.4467672717256637,54.497202978660795,0.446766025034287,0.446766025034287
2645,2645,212.0519,6.9407439,5.5619712,0.0,0,4.1185412,0.0,0.46271476,51.05737482218733,4.5524368,505.54105,-9.2016191,51.05737482218733,,,,,0.4511048180530973,54.556802930524434,0.4511035699982975,0.4511035699982975
2647,2647,212.0523,6.9566398,5.5988503,0.0,0,4.0793095,0.0,0.46736032,50.94980609918816,4.5129542,505.49094,-9.2026196,50.94980609918816,,,,,0.455442364380531,54.61597546450734,0.4554411149720858,0.4554411149720858
2649,2649,212.0527,6.9648385,5.6455369,0.0,0,4.0404716,0.0,0.47128785,50.725277406894165,4.4696469,505.44083,-9.2028761,50.725277406894165,,,,,0.4597799107079646,54.67472767303001,0.45977865995548944,0.45977865995548944
2651,2651,212.0531,6.9962082,5.6822958,0.0,0,4.0030656,0.0,0.47584221,50.72864590966943,4.4295149,505.39072,-9.2044554,50.72864590966943,,,,,0.4641174570353982,54.73306646522561,0.46411620494835054,0.46411620494835054
2653,2653,212.0535,7.0306444,5.7181859,0.0,0,3.9657531,0.0,0.4799372,50.757454456277934,4.3913321,505.34061,-9.2034512,50.757454456277934,,,,,0.46845500336283186,54.79099857351201,0.4684537499505151,0.4684537499505151
2655,2655,212.0539,7.052824,5.7661223,0.0,0,3.928441,0.0,0.4840503,50.62158880296519,4.3503232,505.2905,-9.2031384,50.62158880296519,,,,,0.47279254969026546,54.84853055939156,0.47279129496183286,0.47279129496183286
2657,2657,212.0543,7.0678802,5.7991099,0.0,0,3.8911293,0.0,0.48859152,50.52550812284684,4.3113518,505.24039,-9.2032661,50.52550812284684,,,,,0.4771300960176991,54.90566881958654,0.47712883998215766,0.47712883998215766
2659,2659,212.0547,7.0911226,5.8371496,0.0,0,3.8538172,0.0,0.49267414,50.45544775527824,4.2699652,505.19025,-9.2028809,50.45544775527824,,,,,0.48146764234513273,54.962419591468354,0.4814663850113467,0.4814663850113467
2661,2661,212.0551,7.1292949,5.8847995,0.0,0,3.8165052,0.0,0.49701858,50.42953705293025,4.2343702,505.14014,-9.2031355,50.42953705293025,,,,,0.4858051886725664,55.018788958496636,0.4858039300492609,0.4858039300492609
2663,2663,212.0555,7.1671162,5.9178643,0.0,0,3.7791932,0.0,0.50179678,50.48949680252838,4.1976399,505.09003,-9.203887,50.48949680252838,,,,,0.490142735,55.07478285532565,0.4901414750957644,0.4901414750957644
2665,2665,212.0559,7.1891494,5.9590211,0.0,0,3.7418811,0.0,0.50574929,50.38551735774169,4.1548238,505.03992,-9.2032042,50.38551735774169,,,,,0.4944802813274336,55.13040707274712,0.49447902015072476,0.49447902015072476
2667,2667,212.0563,7.2050619,6.004293,0.0,0,3.7045693,0.0,0.51042813,50.21126171697154,4.1159515,504.98981,-9.2021055,50.21126171697154,,,,,0.49881782765486726,55.185667262393736,0.4988165652140128,0.4988165652140128
2669,2669,212.0567,7.2317972,6.0337262,0.0,0,3.6672573,0.0,0.51470912,50.21106894544357,4.0747137,504.9397,-9.203269,50.21106894544357,,,,,0.5031553739823009,55.24056894122222,0.5031541102855022,0.5031541102855022
2671,2671,212.0571,7.2724023,6.0715261,0.0,0,3.629945,0.0,0.51820105,50.25209937808006,4.0369368,504.88959,-9.2030106,50.25209937808006,,,,,0.5074929203097345,55.29511749594871,0.5074916553650696,0.5074916553650696
2673,2673,212.0575,7.312572,6.1155586,0.0,0,3.5926332,0.0,0.52303326,50.24747092785256,3.9991562,504.83707,-9.203476,50.24747092785256,,,,,0.5118304666371681,55.34931818707638,0.511829200452595,0.511829200452595
2675,2675,212.0579,7.3213639,6.1489029,0.0,0,3.5565164,0.0,0.52741969,50.093900574114144,3.9586599,504.78455,-9.2038813,50.093900574114144,,,,,0.5161680129646018,55.403176153006484,0.5161667455479606,0.5161667455479606
2677,2677,212.0583,7.355844,6.1922731,0.0,0,3.5210166,0.0,0.53147572,50.05015192908411,3.9205501,504.73199,-9.203311,50.05015192908411,,,,,0.5205055592920353,55.456696413811706,0.5205042906510515,0.5205042906510515
2679,2679,212.0587,7.3773193,6.2343068,0.0,0,3.4855206,0.0,0.53696948,49.92439680019431,3.8804977,504.67947,-9.2026415,49.92439680019431,,,,,0.524843105619469,55.50988387495242,0.5248418357617558,0.5248418357617558
2681,2681,212.0591,7.4283657,6.2692099,0.0,0,3.4500246,0.0,0.54089266,50.0424979351839,3.8401151,504.62695,-9.2016706,50.0424979351839,,,,,0.5291806519469027,55.56274333082804,0.5291793808799636,0.5291793808799636
2683,2683,212.0595,7.4693942,6.3090415,0.0,0,3.4145288,0.0,0.54484773,50.05798382778949,3.8070929,504.57443,-9.2019644,50.05798382778949,,,,,0.5335181982743362,55.615279468067605,0.5335169260055675,0.5335169260055675
2685,2685,212.0599,7.4852476,6.3459015,0.0,0,3.3790326,0.0,0.55005682,49.92224288204056,3.7698712,504.52191,-9.2030964,49.92224288204056,,,,,0.5378557446017699,55.66749686898774,0.5378544711384632,0.5378544711384632
2687,2687,212.0603,7.4962621,6.3803387,0.0,0,3.3435366,0.0,0.55352819,49.76926448776072,3.7305274,504.46936,-9.2038832,49.76926448776072,,,,,0.5421932909292035,55.719400014543744,0.5421920162785477,0.5421920162785477
2689,2689,212.0607,7.5289006,6.4185843,0.0,0,3.3080406,0.0,0.55763447,49.73335408280452,3.6916127,504.41684,-9.2027426,49.73335408280452,,,,,0.5465308372566372,55.77099328756367,0.5465295614257211,0.5465295614257211
2691,2691,212.0611,7.5785007,6.4541173,0.0,0,3.2725446,0.0,0.56273365,49.8247337571651,3.6537006,504.36432,-9.2019482,49.8247337571651,,,,,0.5508683835840708,55.822280975460906,0.5508671065798849,0.5508671065798849
2693,2693,212.0615,7.6236906,6.4952002,0.0,0,3.2370486,0.0,0.56653744,49.84700854039703,3.6178882,504.3118,-9.2018766,49.84700854039703,,,,,0.5552059299115044,55.87326727318687,0.5552046517409435,0.5552046517409435
2695,2695,212.0619,7.6371021,6.533885,0.0,0,3.2015524,0.0,0.57127523,49.67542747929939,3.5805972,504.25928,-9.202136,49.67542747929939,,,,,0.5595434762389381,55.92395628582691,0.5595421969088029,0.5595421969088029
2697,2697,212.0623,7.6572833,6.5670934,0.0,0,3.1660566,0.0,0.5760932,49.58351462007708,3.5470076,504.20673,-9.2024212,49.58351462007708,,,,,0.5638810225663716,55.97435203132529,0.563879742083371,0.563879742083371
2699,2699,212.0627,7.6954541,6.6096601,0.0,0,3.1309149,0.0,0.57998693,49.54314807376823,3.5064511,504.15421,-9.2032881,49.54314807376823,,,,,0.5682185688938053,56.02445844281663,0.5682172872645581,0.5682172872645581
2701,2701,212.0631,7.7574911,6.6434469,0.0,0,3.0970623,0.0,0.58459628,49.712445222079154,3.4710739,504.10168,-9.201829,49.712445222079154,,,,,0.572556115221239,56.07427937125826,0.572554832452276,0.572554832452276
2703,2703,212.0635,7.7731209,6.6759195,0.0,0,3.0632942,0.0,0.58891439,49.59099138979864,3.4337032,504.04916,-9.2017918,49.59099138979864,,,,,0.5768936615486726,56.12381858758944,0.5768923776464384,0.5768923776464384
2705,2705,212.0639,7.8051915,6.7191529,0.0,0,3.0295262,0.0,0.5929693,49.499289116415326,3.3974378,503.99664,-9.2017889,49.499289116415326,,,,,0.5812312078761062,56.173079784998826,0.5812299228469607,0.5812299228469607
2707,2707,212.0643,7.8339252,6.7488585,0.0,0,2.9957583,0.0,0.59760386,49.47714873689231,3.3625433,503.94409,-9.2032747,49.47714873689231,,,,,0.5855687542035398,56.22206658125328,0.5855674680537605,0.5855674680537605
2709,2709,212.0647,7.8830876,6.7834973,0.0,0,2.9619904,0.0,0.60163456,49.54782245706376,3.3271644,503.89157,-9.202322,49.54782245706376,,,,,0.5899063005309735,56.27078252053266,0.5899050132667564,0.5899050132667564
2711,2711,212.0651,7.9519153,6.8285885,0.0,0,2.9282222,0.0,0.60624743,49.66546968992808,3.2911532,503.83905,-9.2027435,49.66546968992808,,,,,0.594243846858407,56.31923107565805,0.5942425584858688,0.5942425584858688
2713,2713,212.0655,7.9781504,6.8580523,0.0,0,2.894454,0.0,0.61113691,49.62282144230447,3.2519803,503.78653,-9.2024403,49.62282144230447,,,,,0.5985813931858407,56.367415649992765,0.5985801037110203,0.5985801037110203
2715,2715,212.0659,8.0008211,6.8950377,0.0,0,2.8606861,0.0,0.6149258,49.50384257199068,3.2166839,503.73401,-9.2015057,49.50384257199068,,,,,0.6029189395132744,56.41533957921102,0.6029176489421345,0.6029176489421345
2717,2717,212.0663,8.025651,6.939568,0.0,0,2.8269181,0.0,0.62009585,49.34343776825077,3.1828573,503.68146,-9.2020731,49.34343776825077,,,,,0.6072564858407079,56.463006133238125,0.6072551941791362,0.6072551941791362
2719,2719,212.0667,8.075984,6.9674006,0.0,0,2.7931502,0.0,0.6246689,49.45536136111833,3.1464326,503.62894,-9.2034397,49.45536136111833,,,,,0.6115940321681416,56.51041851805098,0.6115927394219526,0.6115927394219526
2721,2721,212.0671,8.1128654,7.0050812,0.0,0,2.7593822,0.0,0.62834865,49.41253638945791,3.1118703,503.57642,-9.2028198,49.41253638945791,,,,,0.6159315784955752,56.55757987720173,0.6159302846705114,0.6159302846705114
2723,2723,212.0675,8.145463,7.0446243,0.0,0,2.7256143,0.0,0.63361019,49.32795056795017,3.0778172,503.27203,-9.2024622,49.32795056795017,,,,,0.6202691248230089,56.604493293600946,0.6202678299247423,0.6202678299247423
2725,2725,212.0679,8.180438,7.0708966,0.0,0,2.6929309,0.0,0.63754529,49.3508193715319,3.0408127,502.96765,-9.2019644,49.3508193715319,,,,,0.6246066711504424,56.65116179103193,0.6246053751845758,0.6246053751845758
2727,2727,212.0683,8.2256212,7.1106143,0.0,0,2.6608074,0.0,0.6415031,49.33616448859274,3.0098987,502.6633,-9.2032156,49.33616448859274,,,,,0.6289442174778761,56.69758833573476,0.6289429204499445,0.6289429204499445
2729,2729,212.0687,8.2537632,7.1464114,0.0,0,2.6286871,0.0,0.64692169,49.24515733474225,2.9711101,502.35892,-9.2027416,49.24515733474225,,,,,0.6332817638053098,56.74377583784578,0.6332804657207816,0.6332804657207816
2731,2731,212.0691,8.318573,7.1768603,0.0,0,2.5965672,0.0,0.65080798,49.40909466184765,2.9380894,502.05453,-9.2029552,49.40909466184765,,,,,0.6376193101327433,56.78972715292432,0.6376180109970215,0.6376180109970215
2733,2733,212.0695,8.364234,7.2166991,0.0,0,2.5644472,0.0,0.65501481,49.38723746348836,2.9023194,501.75018,-9.2021532,49.38723746348836,,,,,0.641956856460177,56.835445083120504,0.6419555562786006,0.6419555562786006
2735,2735,212.0699,8.3778276,7.2517033,0.0,0,2.5323269,0.0,0.66080165,49.20955140349529,2.8655217,501.4458,-9.2022057,49.20955140349529,,,,,0.6462944027876106,56.8809323788549,0.6462931015654557,0.6462931015654557
2737,2737,212.0703,8.42099,7.2856789,0.0,0,2.5002072,0.0,0.66449261,49.21138977949597,2.8302443,501.14142,-9.2017393,49.21138977949597,,,,,0.6506319491150442,56.926191739827345,0.650630646857525,0.650630646857525
2739,2739,212.0707,8.4667654,7.3212895,0.0,0,2.4680872,0.0,0.6688143,49.2136328169025,2.7991686,500.83707,-9.2023087,49.2136328169025,,,,,0.6549694954424778,56.97122581638789,0.6549681921547481,0.6549681921547481
2741,2741,212.0711,8.520237,7.3512759,0.0,0,2.4359672,0.0,0.67377865,49.29963689744535,2.7606413,500.53268,-9.2019587,49.29963689744535,,,,,0.6593070417699115,57.01603721089938,0.6593057374570653,0.6593057374570653
2743,2743,212.0715,8.567625,7.3882294,0.0,0,2.4038472,0.0,0.67746753,49.295227622864,2.7270029,500.2283,-9.2018757,49.295227622864,,,,,0.6636445880973452,57.060628478557156,0.6636432827644182,0.6636432827644182
2745,2745,212.0719,8.5975189,7.4236798,0.0,0,2.3717272,0.0,0.68231279,49.19899116032202,2.6926649,499.92392,-9.2018585,49.19899116032202,,,,,0.6679821344247787,57.1050021289956,0.6679808280767493,0.6679808280767493
2747,2747,212.0723,8.6410275,7.4529877,0.0,0,2.339607,0.0,0.68721318,49.22506383212729,2.6598542,499.61957,-9.2012672,49.22506383212729,,,,,0.6723196807522124,57.149160626980965,0.6723183733940022,0.6723183733940022
2749,2749,212.0727,8.6856833,7.49506,0.0,0,2.3078086,0.0,0.69125617,49.15777866383015,2.6256225,499.31519,-9.1999378,49.15777866383015,,,,,0.676657227079646,57.19310639380898,0.6766559187161219,0.6766559187161219
2751,2751,212.0731,8.7507706,7.5260973,0.0,0,2.2771802,0.0,0.69619322,49.287039477120885,2.5912569,499.0108,-9.2005644,49.287039477120885,,,,,0.6809947734070796,57.23684180817628,0.6809934640430533,0.6809934640430533
2753,2753,212.0735,8.7823009,7.5553651,0.0,0,2.2466278,0.0,0.70058399,49.238316640257,2.5580957,498.70645,-9.2012796,49.238316640257,,,,,0.6853323197345133,57.28036920718822,0.6853310093747436,0.6853310093747436
2755,2755,212.0739,8.8282719,7.595437,0.0,0,2.2160761,0.0,0.70470458,49.18454585771327,2.5239463,498.40207,-9.201746,49.18454585771327,,,,,0.6896698660619469,57.32369088744924,0.6896685547111397,0.6896685547111397
2757,2757,212.0743,8.8635235,7.6194944,0.0,0,2.185524,0.0,0.70933354,49.193159598697,2.4906502,498.09769,-9.2017612,49.193159598697,,,,,0.6940074123893805,57.36680910588925,0.6940061000521904,0.6940061000521904
2759,2759,212.0747,8.9074335,7.6520443,0.0,0,2.1549721,0.0,0.71322227,49.18151111861607,2.4589343,497.79333,-9.2006216,49.18151111861607,,,,,0.6983449587168141,57.40972608086815,0.6983436453978449,0.6983436453978449
2761,2761,212.0751,8.9652767,7.6948857,0.0,0,2.1244199,0.0,0.71822476,49.16257628457821,2.4240398,497.48895,-9.2004261,49.16257628457821,,,,,0.7026825050442478,57.45244399288047,0.702681190748053,0.702681190748053
2763,2763,212.0755,9.0154924,7.7214446,0.0,0,2.093868,0.0,0.72324592,49.227014416975976,2.3930359,497.18457,-9.2005892,49.227014416975976,,,,,0.7070200513716814,57.49496498552354,0.7070187361027661,0.7070187361027661
2765,2765,212.0759,9.0341148,7.7546759,0.0,0,2.0633161,0.0,0.72690696,49.06420873155745,2.3618002,496.88022,-9.2025242,49.06420873155745,,,,,0.711357597699115,57.53729116631627,0.7113562814619355,0.7113562814619355
2767,2767,212.0763,9.0846157,7.7925301,0.0,0,2.0327642,0.0,0.73207814,49.03547865327344,2.3284273,496.57584,-9.2016535,49.03547865327344,,,,,0.7156951440265487,57.579424607579675,0.7156938268255143,0.7156938268255143
2769,2769,212.0767,9.1435242,7.8130622,0.0,0,2.002212,0.0,0.73619217,49.188017915518834,2.2946708,496.27145,-9.2024755,49.188017915518834,,,,,0.7200326903539823,57.62136734717899,0.7200313721934555,0.7200313721934555
2771,2771,212.0771,9.2129555,7.848105,0.0,0,1.9716599,0.0,0.73959446,49.277018232597136,2.2631552,495.96707,-9.2018442,49.277018232597136,,,,,0.7243702366814159,57.66312138929853,0.7243689175657134,0.7243689175657134
2773,2773,212.0775,9.2662516,7.8878994,0.0,0,1.941108,0.0,0.7456491,49.23708904070319,2.231868,495.05496,-9.2016964,49.23708904070319,,,,,0.7287077830088495,57.704688705197285,0.728706462942243,0.728706462942243
2775,2775,212.0779,9.2811518,7.9151683,0.0,0,1.9115354,0.0,0.75024307,49.09318282724718,2.1982262,494.14285,-9.2018003,49.09318282724718,,,,,0.7330453293362832,57.746071233999345,0.7330440083229998,0.7330440083229998
2777,2777,212.0783,9.3332176,7.9515228,0.0,0,1.8824683,0.0,0.75408483,49.069484208977634,2.1668801,493.23074,-9.2019348,49.069484208977634,,,,,0.7373828756637169,57.78727088332859,0.7373815537079401,0.7373815537079401
2779,2779,212.0787,9.3995743,7.9825163,0.0,0,1.8534042,0.0,0.75968814,49.16152006783358,2.1353056,492.31863,-9.2019577,49.16152006783358,,,,,0.7417204219911504,57.82828953004824,0.741719099097021,0.741719099097021
2781,2781,212.0791,9.4808016,8.0065937,0.0,0,1.8243402,0.0,0.76307672,49.38509014118693,2.1049356,491.40652,-9.2004795,49.38509014118693,,,,,0.7460579683185841,57.8691290209229,0.7460566444902005,0.7460566444902005
2783,2783,212.0795,9.5048666,8.0419588,0.0,0,1.7952763,0.0,0.76706147,49.214049389519175,2.0697803,490.49442,-9.2012987,49.214049389519175,,,,,0.7503955146460177,57.90979117326833,0.7503941898874368,0.7503941898874368
2785,2785,212.0799,9.5391064,8.0731859,0.0,0,1.7662122,0.0,0.77294403,49.12865322711403,2.0403223,489.58231,-9.2021284,49.12865322711403,,,,,0.7547330609734513,57.95027777552169,0.7547317352886889,0.7547317352886889
2787,2787,212.0803,9.5800486,8.1068544,0.0,0,1.7371483,0.0,0.7768234,49.05505379573373,2.0123119,488.6702,-9.2020063,49.05505379573373,,,,,0.7590706073008849,57.99059058807427,0.7590692806939168,0.7590692806939168
2789,2789,212.0807,9.6569223,8.1409521,0.0,0,1.7080842,0.0,0.78152317,49.15826124123366,1.9819493,487.75809,-9.2018719,49.15826124123366,,,,,0.7634081536283186,58.030731343610334,0.7634068261030806,0.7634068261030806
2791,2791,212.0811,9.7360716,8.1684475,0.0,0,1.6790203,0.0,0.7868892,49.32503564065932,1.9505033,486.84598,-9.2011805,49.32503564065932,,,,,0.7677456999557521,58.070701747823115,0.7677443715161415,0.7677443715161415
2793,2793,212.0815,9.7730703,8.2019234,0.0,0,1.6499562,0.0,0.79043245,49.2238680500443,1.9198521,485.93387,-9.2000427,49.2238680500443,,,,,0.7720832462831858,58.11050348007321,0.7720819169330609,0.7720819169330609
2795,2795,212.0819,9.8157148,8.2317514,0.0,0,1.6208922,0.0,0.79520202,49.18034920181885,1.8877783,485.02176,-9.2000751,49.18034920181885,,,,,0.7764207926106195,58.15013819371224,0.7764194623538011,0.7764194623538011
2797,2797,212.0823,9.881031,8.2573957,0.0,0,1.5918282,0.0,0.7999602,49.28403698031824,1.8559279,484.10965,-9.2011003,49.28403698031824,,,,,0.7807583389380531,58.18960751680019,0.7807570077783249,0.7807570077783249
2799,2799,212.0827,9.9449129,8.2947903,0.0,0,1.5630547,0.0,0.80383319,49.27451625532981,1.8250819,483.19757,-9.2013617,49.27451625532981,,,,,0.7850958852654867,58.22891305267264,0.7850945532065954,0.7850945532065954
2801,2801,212.0831,10.007489,8.3208141,0.0,0,1.5353372,0.0,0.8089394,49.35474273314134,1.7936389,482.28546,-9.2018414,49.35474273314134,,,,,0.7894334315929203,58.268056380274366,0.7894320986385767,0.7894320986385767
2803,2803,212.0835,10.037433,8.3492718,0.0,0,1.5076891,0.0,0.81324059,49.25033306734771,1.7613766,481.37335,-9.2006187,49.25033306734771,,,,,0.793770977920354,58.307039054737075,0.7937696440742331,0.7937696440742331
2805,2805,212.0839,10.087614,8.3900976,0.0,0,1.4800411,0.0,0.81787562,49.13306586231531,1.7324129,480.46124,-9.2003584,49.13306586231531,,,,,0.7981085242477876,58.34586260800067,0.7981071895135295,0.7981071895135295
2807,2807,212.0843,10.159346,8.4138241,0.0,0,1.4523932,0.0,0.82333153,49.26967938289266,1.701575,479.54913,-9.1998615,49.26967938289266,,,,,0.8024460705752212,58.3845285490221,0.8024447349564316,0.8024447349564316
2809,2809,212.0847,10.236085,8.4421597,0.0,0,1.4247452,0.0,0.82695782,49.38580452354233,1.6704637,478.63702,-9.199194,49.38580452354233,,,,,0.8067836169026549,58.42303836452003,0.8067822804029053,0.8067822804029053
2811,2811,212.0851,10.307444,8.4783182,0.0,0,1.3970972,0.0,0.83171242,49.40106249997197,1.6427599,477.72491,-9.2006683,49.40106249997197,,,,,0.8111211632300884,58.461393519170436,0.811119825852917,0.811119825852917
2813,2813,212.0855,10.34514,8.4986658,0.0,0,1.3694493,0.0,0.83656019,49.39588587271067,1.6118687,476.81281,-9.2011948,49.39588587271067,,,,,0.8154587095575221,58.49959545627871,0.8154573713064338,0.8154573713064338
2815,2815,212.0859,10.392766,8.5292759,0.0,0,1.3418012,0.0,0.84003407,49.34240865209598,1.5818778,475.9007,-9.2011328,49.34240865209598,,,,,0.8197962558849557,58.53764559797388,0.8197949167634231,0.8197949167634231
2817,2817,212.0863,10.464288,8.5668907,0.0,0,1.3141533,0.0,0.84552681,49.33441683298102,1.5543023,474.98859,-9.2015381,49.33441683298102,,,,,0.8241338022123894,58.575545345829674,0.8241324622238528,0.8241324622238528
2819,2819,212.0867,10.543143,8.586256,0.0,0,1.2865052,0.0,0.85009402,49.52588632267996,1.5216166,474.07648,-9.2004395,49.52588632267996,,,,,0.828471348539823,58.61329608113991,0.8284700076876913,0.8284700076876913
2821,2821,212.0871,10.60823,8.6211052,0.0,0,1.2588573,0.0,0.85380793,49.50514958618554,1.4972862,473.16437,-9.1994963,49.50514958618554,,,,,0.8328088948672566,58.65089916541165,0.8328075531549075,0.8328075531549075
2823,2823,212.0875,10.656989,8.6546049,0.0,0,1.2312093,0.0,0.8598851,49.41738754325825,1.4676545,472.55606,-9.2004528,49.41738754325825,,,,,0.8371464411946903,58.68835594063761,0.8371450986254708,0.8371450986254708
2825,2825,212.0879,10.71803,8.6759501,0.0,0,1.2044512,0.0,0.86388302,49.49837238736334,1.4399625,471.94775,-9.2011471,49.49837238736334,,,,,0.8414839875221238,58.72566772978639,0.8414826440993507,0.8414826440993507
2827,2827,212.0883,10.78784,8.7089272,0.0,0,1.1781523,0.0,0.86758685,49.50653633744388,1.4097216,471.33948,-9.2017107,49.50653633744388,,,,,0.8458215338495575,58.762835837067186,0.8458201895765177,0.8458201895765177
2829,2829,212.0887,10.853243,8.7361612,0.0,0,1.1518563,0.0,0.87337726,49.54557761850819,1.3828642,470.73117,-9.2007875,49.54557761850819,,,,,0.8501590801769912,58.799861548394645,0.850157735056942,0.850157735056942
2831,2831,212.0891,10.921551,8.75982,0.0,0,1.1255603,0.0,0.87681425,49.62914350186168,1.3547177,470.12286,-9.2003851,49.62914350186168,,,,,0.8544966265044248,58.836746131652,0.854495280540595,0.854495280540595
2833,2833,212.0895,10.98815,8.7922525,0.0,0,1.0992643,0.0,0.88114196,49.61693948616775,1.3265686,469.51456,-9.2006235,49.61693948616775,,,,,0.8588341728318584,58.8734908370641,0.8588328260274476,0.8588328260274476
2835,2835,212.0899,11.03096,8.8180962,0.0,0,1.0729682,0.0,0.88689506,49.55837689046287,1.2972485,468.90625,-9.2012157,49.55837689046287,,,,,0.863171719159292,58.91009689757193,0.8631703715174721,0.8631703715174721
2837,2837,212.0903,11.109231,8.8475275,0.0,0,1.0466722,0.0,0.89031887,49.621135649751935,1.2678812,468.29794,-9.2011833,49.621135649751935,,,,,0.8675092654867257,58.94656552907934,0.8675079170106403,0.8675079170106403
2839,2839,212.0907,11.2017,8.8776617,0.0,0,1.0203762,0.0,0.89501977,49.735898283434864,1.2412845,467.68964,-9.2012711,49.735898283434864,,,,,0.8718468118141592,58.982897930809365,0.871845462506925,0.871845462506925
2841,2841,212.0911,11.284107,8.8993492,0.0,0,0.99408025,0.0,0.90031642,49.8855380461869,1.21057,467.08133,-9.2005615,49.8855380461869,,,,,0.8761843581415929,59.01909528566991,0.8761830080062991,0.8761830080062991
2843,2843,212.0915,11.343131,8.9303217,0.0,0,0.96778423,0.0,0.90357774,49.83601293754319,1.1878372,466.47302,-9.2003765,49.83601293754319,,,,,0.8805219044690266,59.05515876042959,0.8805205535087359,0.8805205535087359
2845,2845,212.0919,11.411122,8.9568119,0.0,0,0.94148827,0.0,0.90872228,49.86759357392182,1.1560227,465.86472,-9.2007751,49.86759357392182,,,,,0.8848594507964601,59.09108950614191,0.8848580990142089,0.8848580990142089
2847,2847,212.0923,11.466,8.9781742,0.0,0,0.91519231,0.0,0.91317278,49.89094461023739,1.1259059,465.25641,-9.2011404,49.89094461023739,,,,,0.8891969971238938,59.12688865836944,0.8891956445226924,0.8891956445226924
2849,2849,212.0927,11.555508,9.0144167,0.0,0,0.88916039,0.0,0.91704744,49.91027218871687,1.1010501,464.6481,-9.2011938,49.91027218871687,,,,,0.8935345434513274,59.16255733746649,0.8935331900341605,0.8935331900341605
2851,2851,212.0931,11.645846,9.0373554,0.0,0,0.86408937,0.0,0.92240387,50.06434539670765,1.0713524,464.03983,-9.1998549,50.06434539670765,,,,,0.8978720897787611,59.19809664888001,0.8978707355485882,0.8978707355485882
2853,2853,212.0935,11.701029,9.0618744,0.0,0,0.83908123,0.0,0.9266569,50.047988015558,1.0452721,463.43152,-9.200326,50.047988015558,,,,,0.9022096361061946,59.233507683360095,0.9022082810659503,0.9022082810659503
2855,2855,212.0939,11.764704,9.0966024,0.0,0,0.8140732,0.0,0.93091559,49.95920237516429,1.0181298,462.82321,-9.1996222,49.95920237516429,,,,,0.9065471824336283,59.268791517384216,0.9065458265862223,0.9065458265862223
2857,2857,212.0943,11.841114,9.1140747,0.0,0,0.78906524,0.0,0.935848,50.10079808498133,0.99229723,462.2149,-9.1995592,50.10079808498133,,,,,0.910884728761062,59.303949213101504,0.9108833721093799,0.9108833721093799
2859,2859,212.0947,11.945148,9.1404877,0.0,0,0.76405728,0.0,0.93943369,50.262074497460006,0.96222079,461.6066,-9.1999226,50.262074497460006,,,,,0.9152222750884955,59.338981819047156,0.9152209176353989,0.9152209176353989
2861,2861,212.0951,12.026601,9.1771536,0.0,0,0.73904926,0.0,0.94474375,50.2149894289967,0.93469167,460.99829,-9.2009792,50.2149894289967,,,,,0.9195598214159292,59.3738903698734,0.919558463164256,0.919558463164256
2863,2863,212.0955,12.08289,9.1943178,0.0,0,0.71404123,0.0,0.94972837,50.26667139035318,0.90926754,460.38998,-9.201478,50.26667139035318,,,,,0.9238973677433628,59.40867588694939,0.9238960086959277,0.9238960086959277
2865,2865,212.0959,12.152611,9.22223,0.0,0,0.68903327,0.0,0.95317852,50.25684389109344,0.88457209,459.78168,-9.1989117,50.25684389109344,,,,,0.9282349140707964,59.44333937856133,0.9282335542303907,0.9282335542303907
2867,2867,212.0963,12.244909,9.2545357,0.0,0,0.66402531,0.0,0.95873266,50.28881432354125,0.85697562,459.17337,-9.1993523,50.28881432354125,,,,,0.93257246039823,59.477881839908086,0.9325710997676225,0.9325710997676225
2869,2869,212.0967,12.33801,9.269105,0.0,0,0.63901722,0.0,0.96266973,50.51224962809547,0.83157575,458.56506,-9.1981955,50.51224962809547,,,,,0.9369100067256637,59.512304253644004,0.9369086453076007,0.9369086453076007
2871,2871,212.0971,12.420709,9.2989645,0.0,0,0.61400926,0.0,0.96615773,50.52292416341413,0.81002921,457.95679,-9.1992159,50.52292416341413,,,,,0.9412475530530974,59.54660758982783,0.9412461908503028,0.9412461908503028
2873,2873,212.0975,12.484186,9.3285522,0.0,0,0.58900124,0.0,0.97216451,50.45454451569804,0.78348345,458.10406,-9.200779,50.45454451569804,,,,,0.9455850993805309,59.5807928063002,0.9455837363957069,0.9455837363957069
2875,2875,212.0979,12.551108,9.3481102,0.0,0,0.56478834,0.0,0.97616577,50.50797166945869,0.75864643,458.25134,-9.199069,50.50797166945869,,,,,0.9499226457079646,59.61486084882515,0.9499212819437917,0.9499212819437917
2877,2877,212.0983,12.648293,9.3793106,0.0,0,0.54098582,0.0,0.98028547,50.55014310524537,0.73010772,458.39865,-9.1992645,50.55014310524537,,,,,0.9542601920353982,59.64881265136832,0.9542588274945356,0.9542588274945356
2879,2879,212.0987,12.762835,9.4036036,0.0,0,0.51718581,0.0,0.98628604,50.73378528253944,0.70606732,458.54593,-9.1988344,50.73378528253944,,,,,0.9585977383628318,59.68264913620051,0.9585963730479174,0.9585963730479174
2881,2881,212.0991,12.83291,9.4250927,0.0,0,0.49338579,0.0,0.98960364,50.76851290032591,0.67601043,458.69321,-9.1996508,50.76851290032591,,,,,0.9629352846902655,59.71637121413719,0.9629339186039165,0.9629339186039165
2883,2883,212.0995,12.896463,9.4535074,0.0,0,0.46958581,0.0,0.99369901,50.69592614054449,0.65460086,458.84048,-9.2003508,50.69592614054449,,,,,0.9672728310176991,59.74997978475203,0.9672714641625123,0.9672714641625123
2885,2885,212.0999,12.980083,9.4746103,0.0,0,0.44578579,0.0,0.99928921,50.782440303217655,0.62650633,458.98776,-9.1993256,50.782440303217655,,,,,0.9716103773451328,59.783475736564476,0.9716090097236844,0.9716090097236844
2887,2887,212.1003,13.081344,9.5012274,0.0,0,0.42198581,0.0,1.0026172,50.87074211019217,0.60246378,459.13504,-9.1993341,50.87074211019217,,,,,0.9759479236725663,59.81685994717111,0.9759465552874126,0.9759465552874126
2889,2889,212.1007,13.188879,9.5282688,0.0,0,0.39818579,0.0,1.0075278,50.973580484662456,0.57788342,459.28235,-9.1991243,50.973580484662456,,,,,0.98028547,59.85013328350281,0.9802841008536772,0.9802841008536772