File: examples/hot axisymmetric compression example/data/12 fitted data ramberg/testID_0129.csv
level_0,index,Time(sec),Force(kN),Jaw(mm),PowAngle(deg),Power(W),Pram,PTemp,Strain,Stress(MPa),Stroke(mm),TC1(C),wedge(mm),uncorrected stress,sampled strain,sampled stress,fitting strain,fitting stress,model strain,ramberg stress,ramberg plastic strain,ramberg accumulated plastic strain
1774,1774,145.3503,0.52556747,0.050097056,0.0,0,9.0044422,0.0,0.0032141537,6.384213538472041,10.00265,303.39368,-9.3250828,6.384213538472041,0.0032141537,6.384213538472041,0.0,6.384213538472041,0.0,0.0,0.0,0.0
1777,1777,145.3509,4.7011647,0.12949336,0.0,0,8.9166508,0.0,0.0083984258,56.78359625436036,9.9236908,303.59198,-9.3231831,56.78359625436036,0.14934053,128.32204603680574,0.141066492,127.94269240147946,0.0061601088209607,120.43351615260384,0.006153849833094475,0.006153849833094475
1780,1780,145.3515,6.6184416,0.21798514,0.0,0,8.8288584,0.0,0.013947632,79.43516292907294,9.8221865,303.79025,-9.3203363,79.43516292907294,0.28454873,128.9237738065899,0.282132984,128.974270083883,0.0123202176419214,121.06101805942818,0.01231392604247871,0.01231392604247871
1783,1783,145.3521,7.6919594,0.37193671,0.0,0,8.7416534,0.0,0.024935033,91.29533938636408,9.703846,303.98853,-9.3187199,91.29533938636408,0.42443106,125.83998684715952,0.42319947599999996,125.86994601177173,0.0184803264628821,121.43518725135901,0.01847401541768621,0.01847401541768621
1786,1786,145.3527,8.7618446,0.4727008,0.0,0,8.6580172,0.0,0.031506926,103.22991977430311,9.5792437,304.18683,-9.3177567,103.22991977430311,0.56728101,123.05970420498444,0.564265968,123.09944209054945,0.0246404352838428,121.70391559883961,0.0246341102727052,0.0246341102727052
1789,1789,145.3533,9.5329552,0.52010524,0.0,0,8.574522,0.0,0.035461325,111.92395109476244,9.4705238,304.3851,-9.3152819,111.92395109476244,0.70925802,122.09504763099184,0.7053324599999999,122.12204417847644,0.030800544104803495,121.91424081476846,0.030794208162963077,0.030794208162963077
1792,1792,145.3539,9.5885201,0.63841605,0.0,0,8.4910259,0.0,0.043158013,111.5946434857586,9.3792095,304.58337,-9.3174839,111.5946434857586,0.84920102,123.17201885155028,0.8463989519999999,123.13195537990913,0.0369606529257642,122.08732221994472,0.036954307988799756,0.036954307988799756
1795,1795,145.3545,10.259974,0.70405984,0.0,0,8.4075298,0.0,0.047828346,118.82635946393124,9.2825155,304.78165,-9.3162365,118.82635946393124,,,,,0.0431207617467249,122.23453224361376,0.04311440915918459,0.04311440915918459
1798,1798,145.3551,10.37673,0.84499371,0.0,0,8.3240337,0.0,0.057651304,118.91265054532566,9.1693258,304.97995,-9.3146648,118.91265054532566,,,,,0.0492808705676856,122.36270105413205,0.04927451131915045,0.04927451131915045
1801,1801,145.3557,10.684331,0.94807428,0.0,0,8.2405376,0.0,0.064939976,121.48406951049922,9.0595474,305.17822,-9.3151875,121.48406951049922,,,,,0.05544097938864629,122.47625722714896,0.05543461423854211,0.05543461423854211
1804,1804,145.3563,10.917842,1.0244187,0.0,0,8.1570415,0.0,0.070509739,123.41739036372616,8.9568806,305.3765,-9.3152189,123.41739036372616,,,,,0.06160108820960699,122.57823825190371,0.06159471775949982,0.06159471775949982
1807,1807,145.3569,11.018468,1.1135898,0.0,0,8.0735455,0.0,0.076597527,123.70396202042596,8.8668547,305.57477,-9.3144197,123.70396202042596,,,,,0.0677611970305677,122.67081931778543,0.06775482176897792,0.06775482176897792
1810,1810,145.3575,11.344,1.2027155,0.0,0,7.993176,0.0,0.083086818,126.48294700582711,8.7747612,305.77307,-9.3146391,126.48294700582711,,,,,0.0739213058515284,122.7556122688601,0.0739149261832081,0.0739149261832081
1813,1813,145.3581,11.365428,1.3216728,0.0,0,7.9137359,0.0,0.091476999,125.55056717693626,8.6763983,305.97134,-9.3149958,125.55056717693626,,,,,0.0800814146724891,122.83384514076104,0.08007503093836874,0.08007503093836874
1816,1816,145.3587,11.409471,1.4201654,0.0,0,7.8342957,0.0,0.098725595,125.06335909987868,8.5684242,306.16962,-9.314126,125.06335909987868,,,,,0.0862415234934498,122.90647534710097,0.08623513598470262,0.08623513598470262
1819,1819,145.3593,11.704576,1.503168,0.0,0,7.7548552,0.0,0.10510895,127.45615385633,8.4749823,306.29453,-9.3145342,127.45615385633,,,,,0.0924016323144105,122.97426394540429,0.0923952412826572,0.0923952412826572
1822,1822,145.3599,11.737772,1.5766145,0.0,0,7.675415,0.0,0.11017173,127.07039754719057,8.3888464,306.38269,-9.3151932,127.07039754719057,,,,,0.0985617411353712,123.03782602535085,0.09855534680026598,0.09855534680026598
1825,1825,145.3605,11.855275,1.6586162,0.0,0,7.5959754,0.0,0.11644947,127.49970492380028,8.3098698,306.47089,-9.3144016,127.49970492380028,,,,,0.10472184995633188,123.09766588472287,0.10471545251132033,0.10471545251132033
1828,1828,145.3611,12.073888,1.7555597,0.0,0,7.5165353,0.0,0.12354897,128.83596546670685,8.2209597,306.55908,-9.3143454,128.83596546670685,,,,,0.11088195877729258,123.15420219555578,0.11087555839406173,0.11087555839406173
1831,1831,145.3617,12.056451,1.8486938,0.0,0,7.4370952,0.0,0.13081762,127.67616385244531,8.1251259,306.64728,-9.3147602,127.67616385244531,,,,,0.11704206759825328,123.20778639840084,0.11703566443022557,0.11703566443022557
1834,1834,145.3623,12.156249,1.9321619,0.0,0,7.3593612,0.0,0.13734955,127.85296354150977,8.0369329,306.73547,-9.3140612,127.85296354150977,,,,,0.12320217641921398,123.25871640146927,0.12319577060432947,0.12319577060432947
1837,1837,145.3629,12.379287,2.0022688,0.0,0,7.2838039,0.0,0.14270529,129.4459133200222,7.952199,306.82367,-9.3157425,129.4459133200222,,,,,0.12936228524017468,123.3072469546548,0.12935587690313394,0.12935587690313394
1840,1840,145.3635,12.356412,2.0847921,0.0,0,7.2082515,0.0,0.14934053,128.32204603680574,7.8745937,306.91183,-9.3157501,128.32204603680574,,,,,0.1355223940611354,123.35359762287568,0.1355159833152281,0.1355159833152281
1843,1843,145.3641,12.539111,2.1623356,0.0,0,7.1326995,0.0,0.15536024,129.37567690864674,7.7926216,307.00003,-9.3137083,129.37567690864674,,,,,0.14168250288209608,123.39795899673632,0.14167608983070681,0.14167608983070681
1846,1846,145.3647,12.632498,2.2457948,0.0,0,7.0571475,0.0,0.1619945,129.4242410478896,7.7098904,307.08823,-9.3136215,129.4242410478896,,,,,0.1478426117030568,123.44049758862066,0.1478361964409164,0.1478361964409164
1849,1849,145.3653,12.643237,2.3278129,0.0,0,6.981595,0.0,0.16855134,128.6341714746537,7.6222744,307.17642,-9.3142405,128.6341714746537,,,,,0.15400272052401748,123.4813597350348,0.15399630313825166,0.15399630313825166
1852,1852,145.3659,12.824482,2.3949547,0.0,0,6.9060431,0.0,0.17384575,129.73067401113457,7.5452909,307.26462,-9.3151283,129.73067401113457,,,,,0.1601628293449782,123.52067473787581,0.16015640991599273,0.16015640991599273
1855,1855,145.3665,12.860203,2.4777644,0.0,0,6.830492,0.0,0.18058698,129.1673679697561,7.4675965,307.35281,-9.3137474,129.1673679697561,,,,,0.16632293816593888,123.5585574164788,0.16631651676817236,0.16631651676817236
1858,1858,145.3671,12.998834,2.5493269,0.0,0,6.7554417,0.0,0.1861964,129.75196302610618,7.3900986,307.44101,-9.3140135,129.75196302610618,,,,,0.1724830469868996,123.59511019813432,0.1724766236894674,0.1724766236894674
1861,1861,145.3677,13.039785,2.625962,0.0,0,6.6834416,0.0,0.19240451,129.2928011178165,7.314723,307.52917,-9.3153524,129.2928011178165,,,,,0.17864315580786028,123.63042484402789,0.1786367306751089,0.1786367306751089
1864,1864,145.3683,13.130764,2.7029896,0.0,0,6.6115613,0.0,0.19847886,129.31628177256275,7.2351093,307.61737,-9.3161335,129.31628177256275,,,,,0.184803264628821,123.66458388434147,0.18479683772080782,0.18479683772080782
1867,1867,145.3689,13.257141,2.770582,0.0,0,6.5396819,0.0,0.20395929,129.78236879480474,7.1576424,307.70557,-9.3134193,129.78236879480474,,,,,0.19096337344978168,123.69766181947668,0.1909569448226923,0.1909569448226923
1870,1870,145.3695,13.290393,2.8494861,0.0,0,6.467802,0.0,0.21028921,129.19666902081286,7.0853338,307.69638,-9.3145323,129.19666902081286,,,,,0.1971234822707424,123.72972613174392,0.19711705197725524,0.19711705197725524
1873,1873,145.3701,13.420928,2.9194093,0.0,0,6.3959212,0.0,0.21598081,129.65003800734638,7.0089979,307.68723,-9.3157883,129.65003800734638,,,,,0.20328359109170308,123.76083814230405,0.20327715918130976,0.20327715918130976
1876,1876,145.3707,13.53595,2.9987597,0.0,0,6.3240418,0.0,0.22245872,129.82757512865015,6.9355936,307.67804,-9.3151207,129.82757512865015,,,,,0.20944369991266376,123.79105374104934,0.2094372664319512,0.2094372664319512
1879,1879,145.3713,13.564178,3.0751727,0.0,0,6.252162,0.0,0.22870559,129.19724270776013,6.8601632,307.66888,-9.3145695,129.19724270776013,,,,,0.21560380873362447,123.82042401126057,0.21559737372652482,0.21559737372652482
1882,1882,145.3719,13.682456,3.1446402,0.0,0,6.1802821,0.0,0.23461297,129.49737783370708,6.785964,307.6597,-9.3146105,129.49737783370708,,,,,0.22176391755458516,123.84899576691339,0.2217574810625976,0.2217574810625976
1885,1885,145.3725,13.798254,3.2163393,0.0,0,6.1111121,0.0,0.24061614,129.73299356642954,6.7138028,307.65051,-9.3158779,129.73299356642954,,,,,0.22792402637554587,123.87681201680323,0.22791758843793442,0.22791758843793442
1888,1888,145.3731,13.847589,3.2858362,0.0,0,6.042748,0.0,0.24653347,129.35980631322295,6.6395173,307.64136,-9.3160086,129.35980631322295,,,,,0.23408413519650656,123.90391236709723,0.23407769585047683,0.23407769585047683
1891,1891,145.3737,13.948739,3.3628192,0.0,0,5.9743834,0.0,0.25317904,129.3705838733156,6.5672588,307.63217,-9.313262,129.3705838733156,,,,,0.24024424401746727,123.93033337205992,0.2402378032983252,0.2402378032983252
1894,1894,145.3743,14.056162,3.4359632,0.0,0,5.9060202,0.0,0.25949132,129.4723627127807,6.4914894,307.62302,-9.3136101,129.4723627127807,,,,,0.24640435283842796,123.95610884061212,0.24639791077972234,0.24639791077972234
1897,1897,145.3749,14.113262,3.5059433,0.0,0,5.8376555,0.0,0.26564622,129.13885169864503,6.4186358,307.61383,-9.3151484,129.13885169864503,,,,,0.2525644616593887,123.98127010517675,0.25255801829304003,0.25255801829304003
1900,1900,145.3755,14.206112,3.5769587,0.0,0,5.7692914,0.0,0.27189019,129.1103852207844,6.3476205,307.60464,-9.3146095,129.1103852207844,,,,,0.25872457048034936,124.00584625852764,0.2587181258367662,0.2587181258367662
1903,1903,145.3761,14.310921,3.6456411,0.0,0,5.7009277,0.0,0.27805081,129.20730815297006,6.2733159,307.59549,-9.3138905,129.20730815297006,,,,,0.26488467930131004,124.02986436282751,0.2648782334094944,0.2648782334094944
1906,1906,145.3767,14.37946,3.7177169,0.0,0,5.6325636,0.0,0.28454873,128.9237738065899,6.203547,307.5863,-9.3144226,128.9237738065899,,,,,0.2710447881222708,124.05334963478572,0.27103834100991425,0.27103834100991425
1909,1909,145.3773,14.478974,3.7855611,0.0,0,5.5656581,0.0,0.2906858,128.96061100230887,6.1332126,307.57715,-9.315176,128.96061100230887,,,,,0.27720489694323147,124.07632561021549,0.27719844863680243,0.27719844863680243
1912,1912,145.3779,14.561862,3.8538578,0.0,0,5.5006137,0.0,0.29683629,128.832708747164,6.0637798,307.56796,-9.3152695,128.832708747164,,,,,0.28336500576419216,124.09881429057135,0.2833585562890156,0.2833585562890156
1915,1915,145.3785,14.665788,3.9236367,0.0,0,5.4355736,0.0,0.30315289,128.8607417943777,5.9926014,307.55878,-9.31429,128.8607417943777,,,,,0.28952511458515284,124.12083627382626,0.28951866396548315,0.28951866396548315
1918,1918,145.3791,14.734923,3.995415,0.0,0,5.3705335,0.0,0.30968499,128.54674240133625,5.9229851,307.48581,-9.3141794,128.54674240133625,,,,,0.2956852234061136,124.14241087172735,0.2956787716652016,0.2956787716652016
1921,1921,145.3797,14.817845,4.0664878,0.0,0,5.3054934,0.0,0.31616205,128.35245694413626,5.8494949,307.28525,-9.315197,128.35245694413626,,,,,0.30184533222707427,124.16355621496581,0.30183887938722864,0.30183887938722864
1924,1924,145.3803,14.939839,4.1307001,0.0,0,5.2404532,0.0,0.3219966,128.57309426583817,5.779418,307.08466,-9.3156309,128.57309426583817,,,,,0.30800544104803496,124.18428934784708,0.3079989871306784,0.3079989871306784
1927,1927,145.3809,14.985287,4.1993766,0.0,0,5.1754136,0.0,0.3283062,128.06714900714326,5.7082248,306.88409,-9.3152037,128.06714900714326,,,,,0.31416554986899564,124.20462631353442,0.3141590948947172,0.3141590948947172
1930,1930,145.3815,15.073768,4.2701097,0.0,0,5.1103735,0.0,0.33466759,127.89376777035856,5.6445694,306.68353,-9.3150053,127.89376777035856,,,,,0.3203256586899564,124.22458223132874,0.3203192026785593,0.3203192026785593
1933,1933,145.3821,15.189404,4.3369827,0.0,0,5.0457683,0.0,0.34093359,127.9891583553053,5.5750661,306.48294,-9.314558,127.9891583553053,,,,,0.32648576751091707,124.24417136629137,0.32647931048146317,0.32647931048146317
1936,1936,145.3827,15.256269,4.4061756,0.0,0,4.9838042,0.0,0.34720665,127.63192853417996,5.5062675,306.28238,-9.3149776,127.63192853417996,,,,,0.33264587633187775,124.26340719269584,0.3326394183027287,0.3326394183027287
1939,1939,145.3833,15.343184,4.4726954,0.0,0,4.9219441,0.0,0.35334292,127.46876709594464,5.4386721,306.08182,-9.3149614,127.46876709594464,,,,,0.33880598515283844,124.28230245154556,0.3387995261416937,0.3387995261416937
1942,1942,145.3839,15.454971,4.5403876,0.0,0,4.8600841,0.0,0.35977986,127.48474294237847,5.3712635,305.88123,-9.3151703,127.48474294237847,,,,,0.3449660939737992,124.30086920295358,0.34495963399773144,0.34495963399773144
1945,1945,145.3845,15.54435,4.6092186,0.0,0,4.798224,0.0,0.36627302,127.2883874549018,5.304441,305.68066,-9.3149538,127.2883874549018,,,,,0.35112620279475987,124.31911887397243,0.3511197418702479,0.3511197418702479
1948,1948,145.3851,15.60767,4.6751943,0.0,0,4.7363639,0.0,0.37259623,126.908196466304,5.242415,305.4801,-9.3154593,126.908196466304,,,,,0.35728631161572055,124.33706230229438,0.35727984975868,0.35727984975868
1951,1951,145.3857,15.72253,4.7406473,0.0,0,4.6745043,0.0,0.37881455,126.94383899442278,5.1745019,305.27951,-9.3147154,126.94383899442278,,,,,0.36344642043668124,124.3547097760952,0.36343995766249293,0.36343995766249293
1954,1954,145.3863,15.805582,4.8068652,0.0,0,4.6126437,0.0,0.38539064,126.700640058107,5.1095471,305.07895,-9.3154116,126.700640058107,,,,,0.369606529257642,124.37207107081272,0.36960006558117886,0.36960006558117886
1957,1957,145.3869,15.884947,4.872324,0.0,0,4.5507841,0.0,0.39188343,126.4288605605398,5.0429454,304.87839,-9.3147001,126.4288605605398,,,,,0.37576663807860267,124.38915548264698,0.3757601735142544,0.3757601735142544
1960,1960,145.3875,15.964799,4.9377451,0.0,0,4.4912457,0.0,0.39851242,126.15221809499126,4.9783463,304.6778,-9.3152685,126.15221809499126,,,,,0.38192674689956335,124.40597185953108,0.3819202814612599,0.3819202814612599
1963,1963,145.3881,16.09096,5.001061,0.0,0,4.4323978,0.0,0.40504208,126.25916076443715,4.915319,304.47723,-9.3152046,126.25916076443715,,,,,0.38808685572052404,124.42252862953939,0.38808038942175727,0.38808038942175727
1966,1966,145.3887,16.162401,5.0631576,0.0,0,4.3735499,0.0,0.41137311,125.94287055593568,4.8503008,304.27667,-9.3145361,125.94287055593568,,,,,0.3942469645414848,124.43883382713818,0.394240497395329,0.394240497395329
1969,1969,145.3893,16.240744,5.125988,0.0,0,4.314702,0.0,0.4179076,125.66166867534672,4.7865381,304.0567,-9.3149424,125.66166867534672,,,,,0.40040707336244546,124.45489511737915,0.40040060538157674,0.40040060538157674
1972,1972,145.3899,16.37797,5.1877069,0.0,0,4.2558532,0.0,0.42443106,125.83998684715952,4.72365,303.82709,-9.3137856,125.83998684715952,,,,,0.40656718218340615,124.47071981823815,0.40656071338012006,0.40656071338012006
1975,1975,145.3905,16.467936,5.2501802,0.0,0,4.1970053,0.0,0.43083686,125.63191154476422,4.6594777,303.59744,-9.3143339,125.63191154476422,,,,,0.41272729100436684,124.48631492138647,0.41272082139059574,0.41272082139059574
1978,1978,145.3911,16.536455,5.3100753,0.0,0,4.1381574,0.0,0.4371289,125.2886819068482,4.5957785,303.3678,-9.3151808,125.2886819068482,,,,,0.4188873998253275,124.5016871112884,0.4188809294126563,0.4188809294126563
1981,1981,145.3917,16.675472,5.3722343,0.0,0,4.0793095,0.0,0.4435429,125.43554816837568,4.5322161,303.13815,-9.3151474,125.43554816837568,,,,,0.42504750864628826,124.51684278302824,0.4250410374459695,0.4250410374459695
1984,1984,145.3923,16.768036,5.4348736,0.0,0,4.0217257,0.0,0.45004058,125.21319152190937,4.4686427,302.90851,-9.3137255,125.21319152190937,,,,,0.43120761746724895,124.53178805882695,0.431201145490217,0.431201145490217
1987,1987,145.3929,16.845648,5.4947405,0.0,0,3.9657533,0.0,0.4563438,124.91054914498984,4.4059167,302.67889,-9.3149414,124.91054914498984,,,,,0.43736772628820964,124.5465288033571,0.4373612535450941,0.4373612535450941
1990,1990,145.3935,16.967203,5.5555148,0.0,0,3.9097853,0.0,0.4625603,124.90968663660962,4.3474445,302.44925,-9.3152514,124.90968663660962,,,,,0.4435278351091703,124.56107063805489,0.4435213616103086,0.4435213616103086
1993,1993,145.3941,17.079205,5.6189742,0.0,0,3.8538175,0.0,0.4691081,124.78578071139331,4.2850413,302.2196,-9.3150949,124.78578071139331,,,,,0.44968794393013106,124.5754189544395,0.4496814696855804,0.4496814696855804
1996,1996,145.3947,17.157579,5.6791706,0.0,0,3.7978494,0.0,0.47543344,124.45443256209325,4.2240238,301.98996,-9.3154583,124.45443256209325,,,,,0.45584805275109175,124.5895789264826,0.45584157777064055,0.45584157777064055
1999,1999,145.3953,17.27037,5.7384095,0.0,0,3.7418811,0.0,0.48173589,124.37697413807804,4.1655688,301.76035,-9.3140907,124.37697413807804,,,,,0.46200816157205243,124.60355552220315,0.4620016858652308,0.4620016858652308
2002,2002,145.3959,17.405281,5.7989025,0.0,0,3.6859133,0.0,0.48808435,124.42669975222915,4.1063199,301.5307,-9.3154869,124.42669975222915,,,,,0.4681682703930131,124.61735351450758,0.4681617939691032,0.4681617939691032
2005,2005,145.3965,17.51119,5.8601589,0.0,0,3.6299453,0.0,0.49462637,124.24446440115366,4.0449495,301.30106,-9.3145676,124.24446440115366,,,,,0.47432837921397386,124.6309774912754,0.4743219020820193,0.4743219020820193
2008,2008,145.3971,17.599844,5.9213548,0.0,0,3.5743496,0.0,0.50119728,123.93012285045742,3.9874914,301.07141,-9.3135662,123.93012285045742,,,,,0.48048848803493455,124.64443186483648,0.4804820102037497,0.4804820102037497
2011,2011,145.3977,17.756914,5.9796805,0.0,0,3.5210168,0.0,0.50759637,124.12883981491755,3.925617,300.84177,-9.3141489,124.12883981491755,,,,,0.48664859685589523,124.65772088082892,0.48664211833407384,0.48664211833407384
2014,2014,145.3983,17.847696,6.0388784,0.0,0,3.4677727,0.0,0.51426178,123.83770619394632,3.8681691,300.61215,-9.3164845,123.83770619394632,,,,,0.4928087056768559,124.67084862657698,0.4928022264727792,0.4928022264727792
2017,2017,145.3989,17.951368,6.0986633,0.0,0,3.4145288,0.0,0.52096295,123.61652000571635,3.8117471,300.38251,-9.3146343,123.61652000571635,,,,,0.49896881449781666,124.68381903877997,0.4989623346196614,0.4989623346196614
2020,2020,145.3995,18.099054,6.1569848,0.0,0,3.3612847,0.0,0.52754724,123.7082958807284,3.7531781,300.43961,-9.3131104,123.7082958807284,,,,,0.5051289233187773,124.69663591091191,0.5051224427745231,0.5051224427745231
2023,2023,145.4001,18.218601,6.2163916,0.0,0,3.3080409,0.0,0.53444368,123.57657474080226,3.6939623,300.49673,-9.3136482,123.57657474080226,,,,,0.5112890321397381,124.70930290013298,0.5112825509371742,0.5112825509371742
2026,2026,145.4007,18.312866,6.2710624,0.0,0,3.2547965,0.0,0.54090661,123.3381086415808,3.6336637,300.55383,-9.3147039,123.3381086415808,,,,,0.5174491409606987,124.72182353369251,0.5174426591074316,0.5174426591074316
2029,2029,145.4013,18.450602,6.3264403,0.0,0,3.2015526,0.0,0.54736423,123.3697070697352,3.5797498,300.61096,-9.3145018,123.3697070697352,,,,,0.5236092497816595,124.73420121507503,0.5236027672851182,0.5236027672851182
2032,2032,145.4019,18.591589,6.3827076,0.0,0,3.1483088,0.0,0.55398357,123.39484525001318,3.5199361,300.66806,-9.3137922,123.39484525001318,,,,,0.5297693586026201,124.74643922971882,0.5297628754700633,0.5297628754700633
2035,2035,145.4025,18.69245,6.4397545,0.0,0,3.0970623,0.0,0.56085855,123.12877684888004,3.4679277,300.72516,-9.313839,123.12877684888004,,,,,0.5359294674235808,124.75854075043226,0.5359229836621022,0.5359229836621022
2038,2038,145.4031,18.816294,6.4933481,0.0,0,3.0464106,0.0,0.56728101,123.05970420498444,3.411572,300.78229,-9.3136349,123.05970420498444,,,,,0.5420895762445416,124.77050884248298,0.5420830918610754,0.5420830918610754
2041,2041,145.4037,18.977388,6.5457015,0.0,0,2.9957583,0.0,0.57355702,123.24135472718314,3.3539329,300.83939,-9.3134956,123.24135472718314,,,,,0.5482496850655022,124.78234646848357,0.5482432000668289,0.5482432000668289
2044,2044,145.4043,19.090517,6.6006804,0.0,0,2.9451065,0.0,0.58004481,123.05477230301572,3.3004746,300.89651,-9.3150225,123.05477230301572,,,,,0.5544097938864629,124.79405649284152,0.554403308279214,0.554403308279214
2047,2047,145.4049,19.209026,6.6571465,0.0,0,2.8944542,0.0,0.58687019,122.86644674318754,3.2469618,300.95361,-9.3142557,122.86644674318754,,,,,0.5605699027074237,124.80564168613598,0.5605634164980867,0.5605634164980867
2050,2050,145.4055,19.358335,6.7099161,0.0,0,2.8438022,0.0,0.59311801,122.92451524734904,3.1931617,301.01071,-9.3129816,122.92451524734904,,,,,0.5667300115283843,124.81710472914853,0.5667235247233074,0.5667235247233074
2053,2053,145.4061,19.500429,6.7657523,0.0,0,2.7931502,0.0,0.59967953,122.87059383935238,3.1402991,301.06784,-9.3139944,122.87059383935238,,,,,0.5728901203493451,124.82844821672951,0.5728836329547418,0.5728836329547418
2056,2056,145.4067,19.602577,6.8230147,0.0,0,2.7424984,0.0,0.60659522,122.5282692109296,3.086925,301.12494,-9.3139229,122.5282692109296,,,,,0.5790502291703057,124.8396746614385,0.5790437411922587,0.5790437411922587
2059,2059,145.4073,19.747774,6.8738847,0.0,0,2.6929309,0.0,0.61273623,122.55331445750804,3.0332365,301.18207,-9.3139296,122.55331445750804,,,,,0.5852103379912664,124.85078649696307,0.5852038494357319,0.5852038494357319
2062,2062,145.4079,19.909882,6.924047,0.0,0,2.6447473,0.0,0.61863321,122.68181115769244,2.97967,301.23917,-9.3125706,122.68181115769244,,,,,0.5913704468122272,124.86178608149885,0.5913639576850389,0.5913639576850389
2065,2065,145.4085,20.009516,6.978148,0.0,0,2.5965672,0.0,0.6251691,122.34440869633916,2.9283862,301.29626,-9.3132095,122.34440869633916,,,,,0.5975305556331878,124.87267570072537,0.5975240659400608,0.5975240659400608
2068,2068,145.4091,20.15873,7.0330005,0.0,0,2.5483873,0.0,0.63174671,122.28483950612645,2.8760159,301.32822,-9.3142004,122.28483950612645,,,,,0.6036906644541485,124.88345757078595,0.6036841742006825,0.6036841742006825
2071,2071,145.4097,20.34166,7.0862241,0.0,0,2.5002072,0.0,0.63848013,122.4427400288756,2.8211775,301.30978,-9.3122969,122.4427400288756,,,,,0.6098507732751092,124.89413384118406,0.6098442824667923,0.6098442824667923
2074,2074,145.4103,20.45908,7.1375432,0.0,0,2.4520273,0.0,0.6447385,122.22636149860898,2.774004,301.29135,-9.312211,122.22636149860898,,,,,0.6160108820960699,124.90470659730566,0.6160043907382818,0.6160043907382818
2077,2077,145.4109,20.595894,7.1889453,0.0,0,2.4038472,0.0,0.65113455,122.11271833611484,2.7212906,301.27295,-9.3134375,122.11271833611484,,,,,0.6221709909170307,124.91517786303459,0.6221644990150458,0.6221644990150458
2080,2080,145.4115,20.770449,7.2388196,0.0,0,2.3556671,0.0,0.65762413,122.23652444568776,2.6701498,301.25452,-9.3143969,122.23652444568776,,,,,0.6283310997379913,124.92554960311986,0.6283246072969821,0.6283246072969821
2083,2083,145.4121,20.918495,7.2892342,0.0,0,2.3078089,0.0,0.66435599,122.18008100195308,2.6235673,301.23608,-9.3124523,122.18008100195308,,,,,0.634491208558952,124.93582372548583,0.6344847155839918,0.6344847155839918
2086,2086,145.4127,21.034847,7.3372574,0.0,0,2.2619042,0.0,0.67084599,121.97090527960492,2.5747633,301.21765,-9.3120975,121.97090527960492,,,,,0.6406513173799128,124.94600208337964,0.6406448238759783,0.6406448238759783
2089,2089,145.4133,21.215948,7.3855538,0.0,0,2.2160764,0.0,0.67729354,122.11937176987496,2.5300026,301.19925,-9.3138151,122.11937176987496,,,,,0.6468114262008734,124.95608647748287,0.6468049321728482,0.6468049321728482
2092,2092,145.4139,21.372766,7.4333873,0.0,0,2.1702483,0.0,0.68379831,122.12227207916058,2.4761646,301.18082,-9.3136616,122.12227207916058,,,,,0.6529715350218341,124.96607865783746,0.6529650404745104,0.6529650404745104
2095,2095,145.4145,21.492685,7.4804988,0.0,0,2.1244202,0.0,0.69037092,121.91620729437447,2.4315534,301.16238,-9.3121843,121.91620729437447,,,,,0.6591316438427948,124.9759803258137,0.6591251487808767,0.6591251487808767
2098,2098,145.4151,21.665821,7.525136,0.0,0,2.0785923,0.0,0.69662195,122.04692409171848,2.3802593,301.14398,-9.3126497,122.04692409171848,,,,,0.6652917526637555,124.98579313578306,0.6652852570918609,0.6652852570918609
2101,2101,145.4157,21.863144,7.568747,0.0,0,2.0327644,0.0,0.70252991,122.31896713945795,2.3337073,301.12555,-9.3135433,122.31896713945795,,,,,0.6714518614847163,124.99551869697278,0.6714453654073795,0.6714453654073795
2104,2104,145.4163,21.993797,7.6180501,0.0,0,1.9869361,0.0,0.70925802,122.09504763099184,2.2880318,301.10712,-9.3134985,122.09504763099184,,,,,0.6776119703056769,125.00515857499872,0.6776054737273511,0.6776054737273511
2107,2107,145.4169,22.163984,7.6659393,0.0,0,1.9411081,0.0,0.7159375,122.10498751348736,2.2354882,301.08868,-9.3119278,122.10498751348736,,,,,0.6837720791266376,125.01471429345078,0.6837655820516966,0.6837655820516966
2110,2110,145.4175,22.375509,7.7112556,0.0,0,1.8970004,0.0,0.72225606,122.37713994375925,2.1921711,301.07028,-9.3126469,122.37713994375925,,,,,0.6899321879475984,125.02418733545137,0.6899256903803387,0.6899256903803387
2113,2113,145.4181,22.515869,7.7560744,0.0,0,1.8534043,0.0,0.72830749,122.25577048104414,2.1459889,301.05185,-9.3134289,122.25577048104414,,,,,0.696092296768559,125.03357914500648,0.6960857987132025,0.6960857987132025
2116,2116,145.4187,22.673286,7.8006473,0.0,0,1.8098084,0.0,0.73424911,122.22004831551088,2.097398,301.03342,-9.3127098,122.22004831551088,,,,,0.7022524055895197,125.04289112836871,0.702245907050215,0.702245907050215
2119,2119,145.4193,22.890894,7.8480573,0.0,0,1.7662123,0.0,0.74060309,122.43669975933597,2.0490618,300.94745,-9.312109,122.43669975933597,,,,,0.7084125144104804,125.05212465542854,0.7084060153913048,0.7084060153913048
2122,2122,145.4199,23.046822,7.8968306,0.0,0,1.7226164,0.0,0.74701726,122.28000450431456,2.0061841,300.8277,-9.3121157,122.28000450431456,,,,,0.7145726232314411,125.06128106085689,0.7145661237364027,0.7145661237364027
2125,2125,145.4205,23.214388,7.9432235,0.0,0,1.6790204,0.0,0.75357729,122.2197189561812,1.9607846,300.70795,-9.3122015,122.2197189561812,,,,,0.7207327320524018,125.07036164542536,0.7207262320854411,0.7207262320854411
2128,2128,145.4211,23.387114,7.9874821,0.0,0,1.6354244,0.0,0.75959098,122.21655996870147,1.9178052,300.5882,-9.3118753,122.21655996870147,,,,,0.7268928408733625,125.07936767699731,0.7268863404383539,0.7268863404383539
2131,2131,145.4217,23.592585,8.0297308,0.0,0,1.5918283,0.0,0.76558822,122.4114556459096,1.8723141,300.46844,-9.3105793,122.4114556459096,,,,,0.7330529496943232,125.08830039177047,0.7330464487950772,0.7330464487950772
2134,2134,145.4223,23.74542,8.0765781,0.0,0,1.5491644,0.0,0.77206403,122.22349166480625,1.8287334,300.34869,-9.3112841,122.22349166480625,,,,,0.739213058515284,125.09716099523729,0.7392065571555481,0.7392065571555481
2137,2137,145.4229,23.936632,8.124814,0.0,0,1.5076892,0.0,0.77892435,122.18939975344978,1.7840128,300.22894,-9.3122606,122.18939975344978,,,,,0.7453731673362446,125.10595066325146,0.7453666655197054,0.7453666655197054
2140,2140,145.4235,24.162607,8.1678562,0.0,0,1.4662173,0.0,0.78533518,122.42557429303396,1.7407427,300.10919,-9.3101959,122.42557429303396,,,,,0.7515332761572053,125.11467054298035,0.7515267738874898,0.7515267738874898
2143,2143,145.4241,24.330328,8.2090149,0.0,0,1.4247453,0.0,0.79128855,122.39196083959288,1.6971092,299.98944,-9.3104286,122.39196083959288,,,,,0.757693384978166,125.12332175376498,0.7576868822588428,0.7576868822588428
2146,2146,145.4247,24.512484,8.2510042,0.0,0,1.3832734,0.0,0.79778296,122.40019161162972,1.6548525,299.86969,-9.3118868,122.40019161162972,,,,,0.7638534937991267,125.13190538815176,0.763846990633708,0.763846990633708
2149,2149,145.4253,24.729696,8.2976551,0.0,0,1.3418013,0.0,0.8046664,122.4668428179082,1.6109612,299.74994,-9.3120937,122.4668428179082,,,,,0.7700136026200874,125.14042251261057,0.7700070990120297,0.7700070990120297
2152,2152,145.4259,24.923965,8.3408384,0.0,0,1.3003293,0.0,0.8113687,122.47908277132264,1.5667945,299.63019,-9.3110619,122.47908277132264,,,,,0.7761737114410481,125.14887416843715,0.7761672073937537,0.7761672073937537
2155,2155,145.4265,25.101582,8.3790159,0.0,0,1.2588574,0.0,0.81738985,122.50611714966196,1.5258949,299.51044,-9.3102798,122.50611714966196,,,,,0.7823338202620088,125.15726137252386,0.7823273157788273,0.7823273157788273
2158,2158,145.4271,25.322117,8.4195881,0.0,0,1.2176627,0.0,0.82363254,122.67558103551374,1.4828721,299.39069,-9.3105574,122.67558103551374,,,,,0.7884939290829696,125.16558511809149,0.788487424167199,0.788487424167199
2161,2161,145.4277,25.546101,8.4626846,0.0,0,1.1781524,0.0,0.83041221,122.7888099909125,1.4412141,299.27094,-9.3120098,122.7888099909125,,,,,0.7946540379039302,125.17384637548085,0.7946475325588181,0.7946475325588181
2164,2164,145.4283,25.722374,8.5041342,0.0,0,1.1387084,0.0,0.83693725,122.69478153469046,1.3994939,299.15118,-9.3120203,122.69478153469046,,,,,0.8008141467248909,125.1820460927795,0.8008076409536355,0.8008076409536355
2167,2167,145.4289,25.94441,8.5425911,0.0,0,1.0992644,0.0,0.84331298,122.87292714881396,1.3561178,299.03143,-9.3102608,122.87292714881396,,,,,0.8069742555458516,125.19018519655019,0.8069677493516031,0.8069677493516031
2170,2170,145.4295,26.192226,8.5804043,0.0,0,1.0598203,0.0,0.84920102,123.17201885155028,1.3158344,298.39642,-9.3096666,123.17201885155028,,,,,0.8131343643668123,125.19826459247867,0.8131278577526737,0.8131278577526737
2173,2173,145.4301,26.372452,8.6221113,0.0,0,1.0203763,0.0,0.85561448,123.04819911410488,1.2733774,297.76144,-9.3108168,123.04819911410488,,,,,0.819294473187773,125.20628516595879,0.8192879661568014,0.8192879661568014
2176,2176,145.4307,26.590214,8.6630898,0.0,0,0.98093235,0.0,0.86212844,123.1018707747332,1.2331939,297.12646,-9.3111496,123.1018707747332,,,,,0.8254545820087337,125.2142477827235,0.825448074563941,0.825448074563941
2179,2179,145.4313,26.856544,8.7036448,0.0,0,0.94148839,0.0,0.86828727,123.37282965504012,1.1931293,296.49146,-9.3105507,123.37282965504012,,,,,0.8316146908296944,125.22215328943798,0.8316081829740487,0.8316081829740487
2182,2182,145.4319,27.053873,8.7409039,0.0,0,0.90204442,0.0,0.87416846,123.38888884173876,1.1507571,295.85648,-9.3101988,123.38888884173876,,,,,0.837774799650655,125.23000251423018,0.8377682913870814,0.8377682913870814
2185,2185,145.4325,27.262068,8.7792969,0.0,0,0.86408949,0.0,0.88009578,123.41377887888386,1.1085191,295.22147,-9.3104334,123.41377887888386,,,,,0.8439349084716158,125.23779626723801,0.843928399802997,0.843928399802997
2188,2188,145.4331,27.527691,8.8222446,0.0,0,0.82657731,0.0,0.88675398,123.57172061179858,1.0707238,294.58649,-9.3097534,123.57172061179858,,,,,0.8500950172925765,125.24553534112107,0.8500885082217544,0.8500885082217544
2191,2191,145.4337,27.739672,8.8626347,0.0,0,0.78906536,0.0,0.8929382,123.53334198821408,1.0333078,293.95151,-9.3093834,123.53334198821408,,,,,0.8562551261135372,125.25322051159372,0.856248616643313,0.856248616643313
2194,2194,145.4343,27.943096,8.902216,0.0,0,0.75155336,0.0,0.89883727,123.46192721348076,0.99315792,293.3165,-9.3106251,123.46192721348076,,,,,0.8624152349344979,125.26085253786883,0.8624087250676337,0.8624087250676337
2197,2197,145.4349,28.214409,8.9377699,0.0,0,0.71404135,0.0,0.9047538,123.774212987742,0.95466918,292.68152,-9.3090124,123.774212987742,,,,,0.8685753437554586,125.26843216312922,0.8685688334946776,0.8685688334946776
2200,2200,145.4355,28.450665,8.9771729,0.0,0,0.67652941,0.0,0.91097492,123.81992241233976,0.91499358,292.04651,-9.3086157,123.81992241233976,,,,,0.8747354525764193,125.27596011500866,0.874728941924407,0.874728941924407
2203,2203,145.4361,28.658619,9.0188437,0.0,0,0.63901734,0.0,0.91772509,123.66948367933918,0.87911451,291.41153,-9.3099775,123.66948367933918,,,,,0.88089556139738,125.28343710597854,0.8808890503567849,0.8808890503567849
2206,2206,145.4367,28.911192,9.0568113,0.0,0,0.6015054,0.0,0.92406428,123.78919199911392,0.84073949,290.77655,-9.3097029,123.78919199911392,,,,,0.8870556702183406,125.29086383379043,0.8870491587917749,0.8870491587917749
2209,2209,145.4373,29.178493,9.092885,0.0,0,0.56478846,0.0,0.93029618,124.0033090791082,0.80356157,290.14154,-9.3088903,124.0033090791082,,,,,0.8932157790393014,125.29824098189472,0.8932092672293417,0.8932092672293417
2212,2212,145.4379,29.378765,9.1254988,0.0,0,0.52908593,0.0,0.9364025,124.00746451025812,0.76651096,289.50656,-9.3091469,124.00746451025812,,,,,0.8993758878602621,125.30556921981783,0.8993693756694504,0.8993693756694504
2215,2215,145.4385,29.639879,9.1602726,0.0,0,0.49338591,0.0,0.94249296,124.19850079985036,0.73243886,288.87155,-9.3086052,124.19850079985036,,,,,0.9055359966812228,125.31284920350129,0.9055294841120667,0.9055294841120667
2218,2218,145.4391,29.934464,9.1980829,0.0,0,0.45768592,0.0,0.94894713,124.43231346903931,0.69654131,288.50107,-9.3088026,124.43231346903931,,,,,0.9116961055021835,125.32008157574613,0.9116895925571576,0.9116895925571576
2221,2221,145.4397,30.170923,9.2350845,0.0,0,0.42198589,0.0,0.95604163,124.4282870059553,0.65905255,288.65948,-9.308403,124.4282870059553,,,,,0.9178562143231442,125.32726696647987,0.9178497010046901,0.9178497010046901
2224,2224,145.4403,30.423075,9.268404,0.0,0,0.3862859,0.0,0.9621765,124.57200080365848,0.62259305,288.81793,-9.3091555,124.57200080365848,,,,,0.9240163231441049,125.33440599316762,0.9240098094546321,0.9240098094546321
2227,2227,145.4409,30.721663,9.299222,0.0,0,0.35058588,0.0,0.96802145,124.95755091115583,0.58370239,288.97638,-9.3082352,124.95755091115583,,,,,0.9301764319650656,125.34149926108482,0.9301699179069522,0.9301699179069522
2230,2230,145.4415,30.991417,9.3329363,0.0,0,0.31488591,0.0,0.97385222,125.1309553930874,0.54600674,289.1348,-9.308218,125.1309553930874,,,,,0.9363365407860262,125.34854736369097,0.9363300263616197,0.9363300263616197
2232,2232,145.4419,31.166315,9.3570166,0.0,0,0.29108587,0.0,0.97712195,125.17357097740737,0.52276528,289.24042,-9.3075857,125.17357097740737,,,,,0.94044328,125.3532212947314,0.9404367653326869,0.9404367653326869