File: examples/hot axisymmetric compression example/data/12 fitted data ramberg/testID_0140.csv
level_0,index,Time(sec),Force(kN),Jaw(mm),PowAngle(deg),Power(W),Pram,PTemp,Strain,Stress(MPa),Stroke(mm),TC1(C),wedge(mm),uncorrected stress,sampled strain,sampled stress,fitting strain,fitting stress,model strain,ramberg stress,ramberg plastic strain,ramberg accumulated plastic strain
1972,1972,165.3437,0.48988101,0.038960356,0.0,0,9.0629654,0.0,0.0026651777,5.955437402151924,10.05454,360.74109,-9.287818,5.955437402151924,0.0026651777,5.955437402151924,0.0,5.955437402151924,0.0,0.0,0.0,0.0
1974,1974,165.3441,4.1785111,0.10166378,0.0,0,9.0044374,0.0,0.0060520191,50.57121671432526,9.9893322,360.92413,-9.2873917,50.57121671432526,0.10926408,99.40156749327512,0.095390999,99.89642357032312,0.004193010945054945,92.10581660297588,0.0041879605929481594,0.0041879605929481594
1976,1976,165.3445,6.2359042,0.143987,0.0,0,8.9459095,0.0,0.0094992639,75.24297843807358,9.9335051,361.10718,-9.2851009,75.24297843807358,0.19436148,100.12404602220504,0.190781998,100.0558088422793,0.00838602189010989,92.72616163533559,0.008380937523204075,0.008380937523204075
1978,1978,165.3449,6.7424273,0.23419167,0.0,0,8.8873816,0.0,0.0147804,80.82874484751883,9.8504953,361.29022,-9.2831631,80.82874484751883,0.28321919,99.73997664561404,0.286172997,99.68560260767319,0.012579032835164837,93.09610892088781,0.012573928183285479,0.012573928183285479
1980,1980,165.3453,6.9424734,0.39043668,0.0,0,8.8288536,0.0,0.025315521,82.28863386878265,9.7645473,361.47327,-9.2825356,82.28863386878265,0.37823701,97.91292253794008,0.381563996,97.8573602086413,0.01677204378021978,93.36182920110822,0.016766924558348793,0.016766924558348793
1982,1982,165.3457,7.5262156,0.43537864,0.0,0,8.7703257,0.0,0.029317416,88.91506489430515,9.6610699,361.65628,-9.2829514,88.91506489430515,0.47404271,95.96326428411248,0.47695499500000005,95.91660520506785,0.020965054725274726,93.56981487158016,0.02095992409911997,0.02095992409911997
1984,1984,165.3461,7.9085369,0.54334193,0.0,0,8.7136831,0.0,0.035983499,92.6930650950142,9.5701656,361.79779,-9.2820959,92.6930650950142,0.57016802,94.6725549739653,0.572345994,94.66175947915782,0.025158065670329674,93.74098098864397,0.02515292565878329,0.02515292565878329
1986,1986,165.3465,8.5026789,0.59598184,0.0,0,8.6580124,0.0,0.04035588,99.26947616387784,9.4851303,361.81476,-9.2809668,99.26947616387784,0.6645112,94.42347200306618,0.667736993,94.42532573999442,0.02935107661538462,93.88656920507468,0.029345928620935716,0.029345928620935716
1988,1988,165.3469,7.8667517,0.61699843,0.0,0,8.6023483,0.0,0.041656833,91.70189641592354,9.4132805,361.83173,-9.281662,91.70189641592354,0.76020855,94.72603013776651,0.763127992,94.77391241227969,0.03354408756043956,94.01333141858105,0.03353893261535675,0.03353893261535675
1990,1990,165.3473,8.1063938,0.719522,0.0,0,8.5466843,0.0,0.048441101,93.77608278873171,9.352169,361.84869,-9.2834377,93.77608278873171,0.85864025,96.19870283476088,0.8585189910000001,96.19706231595578,0.03773709850549451,94.12564561370597,0.037731937401992474,0.037731937401992474
1992,1992,165.3477,8.6379719,0.7520079,0.0,0,8.4910212,0.0,0.05119225,99.68257413142332,9.2893124,361.86569,-9.2823381,99.68257413142332,0.95390999,97.6541750510039,0.95390999,97.6541750510039,0.04193010945054945,94.22651467819554,0.04192494281618833,0.04192494281618833
1994,1994,165.3481,8.8279161,0.82727009,0.0,0,8.4353561,0.0,0.056059334,101.29939335372352,9.2172651,361.88266,-9.2798548,101.29939335372352,,,,,0.0461231203956044,94.31808908688173,0.04611794874002936,0.04611794874002936
1996,1996,165.3485,8.5641785,0.92894113,0.0,0,8.3796921,0.0,0.063141622,97.51917565423356,9.1399374,361.89963,-9.2809172,97.51917565423356,,,,,0.05031613134065935,94.40196241355262,0.05031095508613663,0.05031095508613663
1998,1998,165.3489,8.5072651,1.000856,0.0,0,8.324029,0.0,0.068578117,96.34135213335732,9.0644188,361.9166,-9.2810936,96.34135213335732,,,,,0.05450914228571429,94.47934880469964,0.05450396178793595,0.05450396178793595
2000,2000,165.3493,8.8295813,1.0721527,0.0,0,8.2683649,0.0,0.07377822,99.44628452920604,8.9827671,361.93356,-9.2817259,99.44628452920604,,,,,0.05870215323076924,94.55119486768874,0.058696968793522916,0.058696968793522916
2002,2002,165.3497,8.8362751,1.1142014,0.0,0,8.2127008,0.0,0.076761588,99.19987648740558,8.9147663,361.95053,-9.2811451,99.19987648740558,,,,,0.06289516417582418,94.61825308650475,0.06288997606163725,0.06288997606163725
2004,2004,165.3501,9.0458469,1.1677152,0.0,0,8.1570368,0.0,0.080820203,101.13333143744732,8.8558168,361.9675,-9.2800016,101.13333143744732,,,,,0.06708817512087913,94.68113163414198,0.06708298355893161,0.06708298355893161
2006,2006,165.3505,8.6738167,1.2305402,0.0,0,8.1013727,0.0,0.085169159,96.50195543703109,8.7988205,361.98447,-9.2788944,96.50195543703109,,,,,0.07128118606593407,94.74032914711803,0.07127599125806468,0.07127599125806468
2008,2008,165.3509,9.2040672,1.2769774,0.0,0,8.0462637,0.0,0.088435955,102.03106406809404,8.7439842,362.00146,-9.2792521,102.03106406809404,,,,,0.07547419701098902,94.79625960506479,0.07546899913633713,0.07546899913633713
2010,2010,165.3513,9.2089806,1.3525676,0.0,0,7.9931717,0.0,0.094166905,101.48240647828904,8.6797743,362.01843,-9.2798014,101.48240647828904,,,,,0.07966720795604396,94.84927051554996,0.07966200717469439,0.07966200717469439
2012,2012,165.3517,9.136673,1.4349113,0.0,0,7.9402113,0.0,0.099872671,100.03363886432982,8.6158447,362.0354,-9.2804556,100.03363886432982,,,,,0.0838602189010989,94.89965645774836,0.08385501535698409,0.08385501535698409
2014,2014,165.3521,9.0861015,1.4941436,0.0,0,7.8872514,0.0,0.10442524,99.01352768747395,8.5477304,362.05237,-9.2809563,99.01352768747395,,,,,0.08805322984615385,94.94766933870487,0.08804802366939364,0.08804802366939364
2016,2016,165.3525,9.1648827,1.5533683,0.0,0,7.8342915,0.0,0.10926408,99.40156749327512,8.4837694,362.06934,-9.2800493,99.40156749327512,,,,,0.0922462407912088,94.99352627640616,0.09224103210001801,0.09224103210001801
2018,2018,165.3529,9.3427105,1.5919124,0.0,0,7.7813311,0.0,0.11162143,101.01812497378609,8.4240971,362.0863,-9.2778301,101.01812497378609,,,,,0.09643925173626375,95.03741574005961,0.09643404063852304,0.09643404063852304
2020,2020,165.3533,9.2236605,1.6434853,0.0,0,7.7283711,0.0,0.11559139,99.31852257719808,8.3699236,362.10327,-9.2796583,99.31852257719808,,,,,0.1006322626813187,95.07950239090009,0.10062704927588001,0.10062704927588001
2022,2022,165.3537,9.2585688,1.696395,0.0,0,7.6754107,0.0,0.1198269,99.2697039634833,8.3207865,362.12024,-9.2804947,99.2697039634833,,,,,0.10482527362637363,95.1199309405073,0.1048200580041541,0.1048200580041541
2024,2024,165.3541,9.4884377,1.7408608,0.0,0,7.6224508,0.0,0.12258908,101.36852187235507,8.2674465,362.13724,-9.2800188,101.36852187235507,,,,,0.10901828457142858,95.15882925659429,0.10901306681633406,0.10901306681633406
2026,2026,165.3545,9.561183,1.8015329,0.0,0,7.5694909,0.0,0.12762466,101.64266224094268,8.210537,362.15421,-9.2797976,101.64266224094268,,,,,0.11321129551648353,95.1963108863109,0.11320607570619386,0.11320607570619386
2028,2028,165.3549,9.4504337,1.8600278,0.0,0,7.516531,0.0,0.13199699,99.98590299367469,8.1537437,362.17117,-9.2792606,99.98590299367469,,,,,0.11740430646153847,95.23247712328197,0.11739908466817935,0.11739908466817935
2030,2030,165.3553,9.4876032,1.9278661,0.0,0,7.4635711,0.0,0.13683532,99.8209183450945,8.0960484,362.18814,-9.2791948,99.8209183450945,,,,,0.12159731740659342,95.2674187140573,0.12159209369731473,0.12159209369731473
2032,2032,165.3557,9.5230379,1.9720715,0.0,0,7.4106107,0.0,0.14093213,99.828571451965,8.0379028,362.20511,-9.2790718,99.828571451965,,,,,0.12579032835164836,95.30121727718505,0.12578510278912466,0.12578510278912466
2034,2034,165.3561,9.6986599,2.0123925,0.0,0,7.3593569,0.0,0.143566,101.33034565132716,7.9862394,362.14963,-9.2809143,101.33034565132716,,,,,0.1299833392967033,95.33394649087977,0.12997811193956924,0.12997811193956924
2036,2036,165.3565,9.6096287,2.0720975,0.0,0,7.3089838,0.0,0.14816882,99.90238861480933,7.9369092,361.87686,-9.2819309,99.90238861480933,,,,,0.13417635024175825,95.36567309338865,0.13417112114498905,0.13417112114498905
2038,2038,165.3569,9.585454,2.1129725,0.0,0,7.258616,0.0,0.15171768,99.31110921924956,7.8858633,361.60413,-9.28092,99.31110921924956,,,,,0.1383693611868132,95.39645773037772,0.1383641304020588,0.1383641304020588
2040,2040,165.3573,9.753932,2.1581726,0.0,0,7.2082477,0.0,0.15469356,100.67407444953724,7.8384099,361.33139,-9.280158,100.67407444953724,,,,,0.14256237213186815,95.4263556765574,0.14255713970774764,0.14255713970774764
2042,2042,165.3577,9.8788395,2.216342,0.0,0,7.1578794,0.0,0.15954465,101.46459767484544,7.7852383,361.05862,-9.2794552,101.46459767484544,,,,,0.1467553830769231,95.45541745344966,0.14675014905928535,0.14675014905928535
2044,2044,165.3581,9.8580055,2.2636201,0.0,0,7.107511,0.0,0.16330622,100.84610419854322,7.7343311,360.78589,-9.2802315,100.84610419854322,,,,,0.15094839402197804,95.48368936062812,0.15094315845413322,0.15094315845413322
2046,2046,165.3585,9.7714491,2.3224714,0.0,0,7.0571437,0.0,0.16748936,99.46148281166336,7.6833019,360.51315,-9.2807932,99.46148281166336,,,,,0.155141404967033,95.51121393462235,0.15513616788995896,0.15513616788995896
2048,2048,165.3589,9.8535604,2.3688974,0.0,0,7.0067749,0.0,0.1718315,99.90015265337496,7.6323571,360.24042,-9.2816362,99.90015265337496,,,,,0.1593344159120879,95.53803034711073,0.1593291773646146,0.1593291773646146
2050,2050,165.3593,9.974802,2.4084136,0.0,0,6.9564075,0.0,0.1746628,100.78715217248951,7.5848083,359.96765,-9.2810144,100.78715217248951,,,,,0.16352742685714286,95.56417475161192,0.1635221868761179,0.1635221868761179
2052,2052,165.3597,10.002891,2.4633989,0.0,0,6.9060392,0.0,0.1788628,100.5934146083966,7.5325508,359.69492,-9.2802143,100.5934146083966,,,,,0.1677204378021978,95.58968058665185,0.16771519642263522,0.16771519642263522
2054,2054,165.3601,9.9541254,2.5035887,0.0,0,6.8556719,0.0,0.18263035,99.75562150488406,7.4893522,359.42218,-9.2804461,99.75562150488406,,,,,0.17191344874725276,95.61457884166839,0.17190820600246745,0.17190820600246745
2056,2056,165.3605,10.065613,2.5543368,0.0,0,6.8053036,0.0,0.18607397,100.42929733425052,7.4380584,359.14941,-9.2804489,100.42929733425052,,,,,0.1761064596923077,95.63889829119596,0.17610121561403674,0.17610121561403674
2058,2058,165.3609,10.121484,2.6056612,0.0,0,6.7554379,0.0,0.19033869,100.53557188445424,7.3883848,358.87668,-9.2813196,100.53557188445424,,,,,0.18029947063736265,95.66266570154492,0.18029422525587552,0.18029422525587552
2060,2060,165.3613,10.119414,2.6501408,0.0,0,6.7073984,0.0,0.19436148,100.12404602220504,7.3423014,358.60394,-9.2815447,100.12404602220504,,,,,0.1844924815824176,95.68590601393352,0.18448723492661614,0.18448723492661614
2062,2062,165.3617,10.176924,2.7089381,0.0,0,6.6594777,0.0,0.19838375,100.1732575417228,7.2916608,358.33121,-9.2821798,100.1732575417228,,,,,0.18868549252747255,95.70864250723234,0.18868024462498223,0.18868024462498223
2064,2064,165.3621,10.204155,2.7484403,0.0,0,6.6115575,0.0,0.20221446,100.09110094141498,7.2413669,358.05844,-9.2802601,100.09110094141498,,,,,0.1928785034725275,95.73089694284714,0.1928732543497805,0.1928732543497805
2066,2066,165.3625,10.297059,2.7914608,0.0,0,6.5636377,0.0,0.20571251,100.61749045802097,7.1919775,357.78571,-9.2808409,100.61749045802097,,,,,0.19707151441758244,95.7526896941869,0.19706626409989392,0.19706626409989392
2068,2068,165.3629,10.280476,2.8482873,0.0,0,6.515718,0.0,0.20970513,99.94780390587113,7.145988,357.51297,-9.2795668,99.94780390587113,,,,,0.2012645253626374,95.7740398625447,0.20125927387427503,0.20125927387427503
2070,2070,165.3633,10.340587,2.8854682,0.0,0,6.4677982,0.0,0.21357173,100.19808653266064,7.0962567,357.24023,-9.279604,100.19808653266064,,,,,0.2054575363076923,95.79496538116811,0.20545228367194057,0.20545228367194057
2072,2072,165.3637,10.436534,2.9347942,0.0,0,6.419878,0.0,0.21735449,100.68037483182462,7.046452,356.96747,-9.281146,100.68037483182462,,,,,0.20965054725274726,95.81548310881223,0.20964529349196614,0.20964529349196614
2074,2074,165.3641,10.473282,2.9935119,0.0,0,6.3719578,0.0,0.22183646,100.50033558491806,6.9982648,356.69473,-9.2816858,100.50033558491806,,,,,0.2138435581978022,95.8356089142026,0.21383830333348164,0.21383830333348164
2076,2076,165.3645,10.49384,3.0350168,0.0,0,6.324038,0.0,0.22606848,100.31897945030244,6.9473524,356.422,-9.2807322,100.31897945030244,,,,,0.21803656914285716,95.85535775223353,0.21803131319566701,0.21803131319566701
2078,2078,165.3649,10.49893,3.0877049,0.0,0,6.2761183,0.0,0.2298739,99.88670916724077,6.8978038,356.14923,-9.2807693,99.88670916724077,,,,,0.2222295800879121,95.87474373298939,0.22222432307774861,0.22222432307774861
2080,2080,165.3653,10.578212,3.1368823,0.0,0,6.2281981,0.0,0.23406082,100.18867228050686,6.849515,355.8765,-9.2809772,100.18867228050686,,,,,0.22642259103296705,95.89378018440198,0.2264173329789956,0.2264173329789956
2082,2082,165.3657,10.644554,3.1767426,0.0,0,6.1802783,0.0,0.23786992,100.4480488376603,6.8025427,355.60376,-9.2794924,100.4480488376603,,,,,0.230615601978022,95.91247970920693,0.230610342898717,0.230610342898717
2084,2084,165.3661,10.662606,3.2267425,0.0,0,6.1339011,0.0,0.24155773,100.15474620715082,6.7527723,355.37073,-9.280591,100.15474620715082,,,,,0.23480861292307695,95.93085423668576,0.23480335283625867,0.23480335283625867
2086,2086,165.3665,10.676274,3.2742579,0.0,0,6.0883203,0.0,0.24596006,99.84190511981,6.7028604,355.25677,-9.2801208,99.84190511981,,,,,0.2390016238681319,95.94891507000948,0.23899636279100084,0.23899636279100084
2088,2088,165.3669,10.740751,3.3204424,0.0,0,6.0427446,0.0,0.24995808,100.01337548186451,6.657402,355.14282,-9.2807665,100.01337548186451,,,,,0.24319463481318684,95.96667292939584,0.2431893727623557,0.2431893727623557
2090,2090,165.3673,10.8171,3.3692687,0.0,0,5.9971681,0.0,0.25371528,100.26482789759112,6.6091642,355.02887,-9.2813492,100.26482789759112,,,,,0.24738764575824176,95.98413799165398,0.24738238274976518,0.24738238274976518
2092,2092,165.3677,10.856305,3.4178038,0.0,0,5.951592,0.0,0.25844234,100.16977955651484,6.5615416,354.91495,-9.2813358,100.16977955651484,,,,,0.2515806567032967,96.00131992633415,0.2515753927526992,0.2515753927526992
2094,2094,165.3681,10.869115,3.4650776,0.0,0,5.9060163,0.0,0.26228654,99.84086985750962,6.5121017,354.80099,-9.2812243,99.84086985750962,,,,,0.2557736676483517,96.01822792908052,0.25576840277065344,0.25576840277065344
2096,2096,165.3685,10.906929,3.5151849,0.0,0,5.8604403,0.0,0.26636583,99.71261247880264,6.4641418,354.68704,-9.2809067,99.71261247880264,,,,,0.2599666785934066,96.03487075211964,0.259961412803148,0.259961412803148
2098,2098,165.3689,10.954626,3.5621493,0.0,0,5.8148637,0.0,0.27108854,99.70088956450212,6.418108,354.57309,-9.2803841,99.70088956450212,,,,,0.2641596895384616,96.05125673242638,0.26415442284972585,0.26415442284972585
2100,2100,165.3693,11.017509,3.610029,0.0,0,5.7692881,0.0,0.27462664,99.81403046153714,6.3689752,354.45914,-9.2816763,99.81403046153714,,,,,0.2683527004835165,96.06739381763153,0.26834743290995106,0.26834743290995106
2102,2102,165.3697,11.054774,3.656214,0.0,0,5.723712,0.0,0.27892065,99.70716727635111,6.3190908,354.34518,-9.2812595,99.70716727635111,,,,,0.2725457114285714,96.0832895900386,0.27254044298340796,0.27254044298340796
2104,2104,165.3701,11.105408,3.7000539,0.0,0,5.6781363,0.0,0.28321919,99.73997664561404,6.2730708,354.23123,-9.2810268,99.73997664561404,,,,,0.2767387223736264,96.0989512886088,0.27673345306969965,0.27673345306969965
2106,2106,165.3705,11.143604,3.7520118,0.0,0,5.6325603,0.0,0.28707242,99.5788686556428,6.2259569,354.11728,-9.2809753,99.5788686556428,,,,,0.2809317333186813,96.11438582955394,0.2809264631684468,0.2809264631684468
2108,2108,165.3709,11.185519,3.7971101,0.0,0,5.5874381,0.0,0.29153091,99.51412798594409,6.1790247,354.00333,-9.2817802,99.51412798594409,,,,,0.2851247442637363,96.12959982526944,0.285119473279287,0.285119473279287
2110,2110,165.3713,11.234664,3.84235,0.0,0,5.5439701,0.0,0.29574358,99.50870059497308,6.1334825,353.8894,-9.2823067,99.50870059497308,,,,,0.2893177552087912,96.1445996018877,0.2893124834018732,0.2893124834018732
2112,2112,165.3717,11.305867,3.8975136,0.0,0,5.5006099,0.0,0.29985383,99.59612428554404,6.0849323,353.77545,-9.2815256,99.59612428554404,,,,,0.2935107661538462,96.1593912156316,0.29350549353587346,0.29350549353587346
2114,2114,165.3721,11.348713,3.9393439,0.0,0,5.4572496,0.0,0.304483,99.5600170699396,6.0337152,353.6615,-9.2809763,99.5600170699396,,,,,0.2977037770989011,96.17398046801827,0.29769850368096956,0.29769850368096956
2116,2116,165.3725,11.36283,3.9843807,0.0,0,5.4138899,0.0,0.30830631,99.23801277977496,5.9855409,353.54755,-9.2813444,99.23801277977496,,,,,0.3018967880439561,96.18837291997541,0.3018915138368567,0.3018915138368567
2118,2118,165.3729,11.408148,4.0400519,0.0,0,5.3705297,0.0,0.31292361,99.08040648810038,5.9393563,353.43359,-9.2818918,99.08040648810038,,,,,0.306089798989011,96.2025739049334,0.30608452400324226,0.30608452400324226
2120,2120,165.3733,11.484165,4.0808768,0.0,0,5.3271699,0.0,0.3174673,99.33204948886626,5.8905826,353.31964,-9.2811527,99.33204948886626,,,,,0.310282809934066,96.2165885412528,0.31027753417984577,0.31027753417984577
2122,2122,165.3737,11.540627,4.1264057,0.0,0,5.2838097,0.0,0.32126015,99.362481021863,5.8430037,353.20569,-9.281147,99.362481021863,,,,,0.3144758208791209,96.23042174351461,0.31447054436639765,0.31447054436639765
2124,2124,165.3741,11.569389,4.1805959,0.0,0,5.2404499,0.0,0.32596865,99.06363736610948,5.7941899,353.09174,-9.2802448,99.06363736610948,,,,,0.3186688318241758,96.24407823330019,0.31866355456263906,0.31866355456263906
2126,2126,165.3745,11.594121,4.220397,0.0,0,5.1970901,0.0,0.33030972,98.8731284511062,5.7454948,352.97781,-9.2809,98.8731284511062,,,,,0.3228618427692308,96.25756254919405,0.32285656476832114,0.32285656476832114
2128,2128,165.3749,11.642632,4.2693334,0.0,0,5.1537299,0.0,0.33416975,98.79008760780076,5.698278,352.86386,-9.2809553,98.79008760780076,,,,,0.3270548537142857,96.27087905613077,0.3270495749832045,0.3270495749832045
2130,2130,165.3753,11.708944,4.3202987,0.0,0,5.1103697,0.0,0.33933714,98.83241449071708,5.6515117,352.74991,-9.2808056,98.83241449071708,,,,,0.3312478646593407,96.28403195417297,0.3312425852070589,0.3312425852070589
2132,2132,165.3757,11.779339,4.3603611,0.0,0,5.0670099,0.0,0.34325859,99.015066920279,5.6070838,352.63596,-9.2812853,99.015066920279,,,,,0.3354408756043956,96.29702528673158,0.33543559543966256,0.33543559543966256
2134,2134,165.3761,11.780351,4.4096322,0.0,0,5.0250454,0.0,0.34732506,98.51734162789236,5.5567904,352.49033,-9.2809391,98.51734162789236,,,,,0.3396338865494506,96.30986294829802,0.33962860568080205,0.33962860568080205
2136,2136,165.3765,11.815627,4.4531174,0.0,0,4.9838009,0.0,0.35208818,98.36417248992174,5.5140963,352.24979,-9.2806501,98.36417248992174,,,,,0.3438268974945055,96.32254869167713,0.3438216159302715,0.3438216159302715
2138,2138,165.3769,11.875482,4.4950285,0.0,0,4.9425607,0.0,0.35583708,98.42827029449997,5.4677253,352.00925,-9.2808924,98.42827029449997,,,,,0.3480199084395605,96.33508613478077,0.34801462618787254,0.34801462618787254
2140,2140,165.3773,11.951224,4.5444174,0.0,0,4.9013209,0.0,0.36011955,98.54106326052734,5.4213018,351.76868,-9.2811842,98.54106326052734,,,,,0.3522129193846154,96.34747876707276,0.35220763645341385,0.35220763645341385
2142,2142,165.3777,11.980403,4.5884948,0.0,0,4.8600807,0.0,0.36512721,98.3208726427868,5.3756256,351.52814,-9.2817392,98.3208726427868,,,,,0.3564059303296704,96.35972995554204,0.3564006467267109,0.3564006467267109
2144,2144,165.3781,12.002568,4.6379089,0.0,0,4.818841,0.0,0.36919084,97.9851880930708,5.3314915,351.2876,-9.281539,97.9851880930708,,,,,0.3605989412747253,96.37184295047523,0.3605936570075853,0.3605936570075853
2146,2146,165.3785,12.045468,4.6832986,0.0,0,4.7776008,0.0,0.37371403,97.85821563662928,5.2872243,351.04703,-9.2808714,97.85821563662928,,,,,0.3647919522197802,96.38382089067429,0.364786667295865,0.364786667295865
2148,2148,165.3789,12.103669,4.7228737,0.0,0,4.7363605,0.0,0.37823701,97.91292253794008,5.2428207,350.80649,-9.2810392,97.91292253794008,,,,,0.3689849631648352,96.39566680864682,0.36897967759138384,0.36897967759138384
2150,2150,165.3793,12.174501,4.7700286,0.0,0,4.6951208,0.0,0.38193902,97.98474076678605,5.1976991,350.56595,-9.280961,97.98474076678605,,,,,0.3731779741098901,96.4073836352477,0.37317268789398095,0.37317268789398095
2152,2152,165.3797,12.213825,4.8116989,0.0,0,4.6538811,0.0,0.38646331,97.85686367653382,5.1511207,350.32538,-9.2808704,97.85686367653382,,,,,0.3773709850549451,96.41897420428718,0.37736569820350113,0.37736569820350113
2154,2154,165.3801,12.251293,4.8528504,0.0,0,4.6126404,0.0,0.39076704,97.71682224174688,5.1080942,350.08484,-9.2809381,97.71682224174688,,,,,0.381563996,96.43044125669941,0.3815587085197939,0.3815587085197939
2156,2156,165.3805,12.268497,4.9072948,0.0,0,4.5714006,0.0,0.39516154,97.27070773936042,5.0665421,349.84427,-9.2809067,97.27070773936042,,,,,0.385757006945055,96.4417874446246,0.3857517188427139,0.3857517188427139
2158,2158,165.3809,12.325236,4.9452405,0.0,0,4.5305729,0.0,0.39986271,97.31206829376166,5.0224442,349.60373,-9.2810869,97.31206829376166,,,,,0.3899500178901099,96.45301533517501,0.3899447291721204,0.3899447291721204
2160,2160,165.3813,12.39559,4.9883819,0.0,0,4.4912429,0.0,0.40390018,97.40040724993544,4.9764814,349.36319,-9.2815027,97.40040724993544,,,,,0.3941430288351649,96.46412741405854,0.39413773950787717,0.39413773950787717
2162,2162,165.3817,12.441247,5.0387354,0.0,0,4.4520106,0.0,0.40840435,97.2118629124907,4.9358106,349.12262,-9.2815933,97.2118629124907,,,,,0.3983360397802198,96.47512608902534,0.39833074984985206,0.39833074984985206
2164,2164,165.3821,12.461862,5.0719314,0.0,0,4.4127784,0.0,0.41276711,97.01148814456762,4.8906794,348.88208,-9.281723,97.01148814456762,,,,,0.4025290507252748,96.48601369304393,0.4025237601979172,0.4025237601979172
2166,2166,165.3825,12.505978,5.1169972,0.0,0,4.3735466,0.0,0.4165622,96.86242783907628,4.848907,348.64154,-9.2809906,96.86242783907628,,,,,0.4067220616703297,96.49679248740058,0.4067167705519486,0.4067167705519486
2168,2168,165.3829,12.576447,5.1660771,0.0,0,4.3343148,0.0,0.42146003,96.86878107905548,4.803967,348.40097,-9.2807837,96.86878107905548,,,,,0.4109150726153846,96.50746466463711,0.410909780911826,0.410909780911826
2170,2170,165.3833,12.659675,5.2015119,0.0,0,4.295083,0.0,0.42585137,97.11773892440202,4.7587252,348.16043,-9.2796736,97.11773892440202,,,,,0.4151080835604396,96.51803235127414,0.4151027912774329,0.4151027912774329
2172,2172,165.3837,12.683419,5.2496114,0.0,0,4.2558503,0.0,0.42992023,96.766591528005,4.7173023,347.91989,-9.2798843,96.766591528005,,,,,0.4193010945054945,96.52849761051743,0.41929580164865604,0.41929580164865604
2174,2174,165.3841,12.706209,5.2973652,0.0,0,4.2166185,0.0,0.43514299,96.40997624618504,4.6744514,347.67932,-9.2819271,96.40997624618504,,,,,0.4234941054505495,96.53886244464832,0.42348881202538574,0.42348881202538574
2176,2176,165.3845,12.768609,5.3321252,0.0,0,4.1773863,0.0,0.43920434,96.49535898663372,4.6293383,347.43878,-9.2825079,96.49535898663372,,,,,0.4276871163956044,96.54912879747818,0.42768182240751534,0.42768182240751534
2178,2178,165.3849,12.830825,5.3758993,0.0,0,4.1381545,0.0,0.44289756,96.47437790249784,4.5883832,347.19821,-9.2828236,96.47437790249784,,,,,0.4318801273406594,96.55929855661812,0.43187483279494143,0.43187483279494143
2180,2180,165.3853,12.895928,5.4155326,0.0,0,4.0989227,0.0,0.44783261,96.5168734120662,4.5462322,346.95767,-9.2803078,96.5168734120662,,,,,0.4360731382857143,96.56937355556056,0.43606784318756336,0.43606784318756336
2182,2182,165.3857,12.941602,5.4546642,0.0,0,4.0596905,0.0,0.45165762,96.41574463151224,4.5030866,346.71713,-9.2793055,96.41574463151224,,,,,0.4402661492307693,96.57935557582726,0.44026085358528355,0.44026085358528355
2184,2184,165.3861,12.971951,5.5008316,0.0,0,4.0217228,0.0,0.45602828,96.11794490494349,4.4626918,346.47809,-9.2796907,96.11794490494349,,,,,0.4444591601758242,96.58924634885437,0.44445386398800696,0.44445386398800696
2186,2186,165.3865,13.032932,5.5412979,0.0,0,3.9844062,0.0,0.46115875,96.10837069158735,4.4242988,346.24359,-9.2803593,96.10837069158735,,,,,0.44865217112087913,96.59904755786381,0.4486468743956413,0.4486468743956413
2188,2188,165.3869,13.09472,5.5867453,0.0,0,3.9470942,0.0,0.46527967,96.04326803659632,4.3816214,346.00909,-9.2815638,96.04326803659632,,,,,0.4528451820659341,96.60876083966154,0.452839884808097,0.452839884808097
2190,2190,165.3873,13.15993,5.6261926,0.0,0,3.9097824,0.0,0.46952981,96.06724922869788,4.3381901,345.77463,-9.2823162,96.06724922869788,,,,,0.457038193010989,96.61838778634471,0.45703289522528656,0.45703289522528656
2192,2192,165.3877,13.201122,5.6612182,0.0,0,3.8724704,0.0,0.47404271,95.96326428411248,4.2982178,345.54013,-9.2823915,95.96326428411248,,,,,0.461231203956044,96.6279299468872,0.4612259056471252,0.4612259056471252
2194,2194,165.3881,13.244125,5.7067513,0.0,0,3.8351583,0.0,0.47791436,95.74800063389422,4.2577443,345.30563,-9.2802925,95.74800063389422,,,,,0.4654242149010989,96.6373888286969,0.4654189160735301,0.4654189160735301
2196,2196,165.3885,13.296914,5.744915,0.0,0,3.7978463,0.0,0.48245519,95.68538527077445,4.218914,345.07114,-9.2807646,95.68538527077445,,,,,0.4696172258461539,96.6467658991153,0.46961192650442096,0.46961192650442096
2198,2198,165.3889,13.372079,5.782084,0.0,0,3.7605343,0.0,0.48685524,95.79110927960504,4.1784806,344.83664,-9.2800541,95.79110927960504,,,,,0.4738102367912088,96.65606258681491,0.47380493693971926,0.47380493693971926
2200,2200,165.3893,13.444922,5.8293681,0.0,0,3.7232223,0.0,0.49096075,95.75624140297592,4.136775,344.60214,-9.2813196,95.75624140297592,,,,,0.4780032477362638,96.66528028312429,0.4779979473793489,0.4779979473793489
2202,2202,165.3897,13.486806,5.8645625,0.0,0,3.6859105,0.0,0.49577522,95.6388545987265,4.097795,344.36768,-9.2814589,95.6388545987265,,,,,0.4821962586813187,96.67442034337016,0.48219095782323546,0.48219095782323546
2204,2204,165.3901,13.537451,5.9037166,0.0,0,3.6485984,0.0,0.49984232,95.53374580113936,4.0569925,344.13318,-9.282342,95.53374580113936,,,,,0.4863892696263737,96.68348408808582,0.4863839682713066,0.4863839682713066
2206,2206,165.3905,13.594055,5.9504642,0.0,0,3.6112862,0.0,0.50432903,95.376526992973,4.017859,343.89868,-9.2812119,95.376526992973,,,,,0.4905822805714286,96.69247280418642,0.49057697872349165,0.49057697872349165
2208,2208,165.3909,13.67968,5.9803905,0.0,0,3.5743468,0.0,0.50870192,95.61862538004304,3.9781563,343.66418,-9.2800474,95.61862538004304,,,,,0.49477529151648353,96.7013877461342,0.4947699891797219,0.4947699891797219
2210,2210,165.3913,13.737982,6.0196972,0.0,0,3.5387621,0.0,0.51240093,95.55301894113738,3.9366882,343.42969,-9.2799931,95.55301894113738,,,,,0.4989683024615385,96.71023013700376,0.49896299963993035,0.49896299963993035
2212,2212,165.3917,13.800986,6.0671425,0.0,0,3.5032659,0.0,0.51746702,95.41745058504188,3.9003835,343.19519,-9.2804909,95.41745058504188,,,,,0.5031613134065934,96.7190011694975,0.5031560101040514,0.5031560101040514
2214,2214,165.3921,13.828938,6.1018224,0.0,0,3.4677699,0.0,0.52228218,95.19039719047257,3.8620045,342.96069,-9.280838,95.19039719047257,,,,,0.5073543243516484,96.7277020069957,0.5073490205720215,0.5073490205720215
2216,2216,165.3925,13.894278,6.1449747,0.0,0,3.4322741,0.0,0.52627873,95.1146348182384,3.8225565,342.72623,-9.2812643,95.1146348182384,,,,,0.5115473352967034,96.73633378450893,0.5115420310437783,0.5115420310437783
2218,2218,165.3929,13.975206,6.1881833,0.0,0,3.3967779,0.0,0.53148544,95.13928889092698,3.7812099,342.49173,-9.2814884,95.13928889092698,,,,,0.5157403462417582,96.7448976095384,0.515735041519261,0.515735041519261
2220,2220,165.3933,14.044254,6.2160888,0.0,0,3.3612819,0.0,0.53510493,95.26575240352471,3.7426453,342.25723,-9.2807894,95.26575240352471,,,,,0.5199333571868132,96.75339456303507,0.5199280519984104,0.5199280519984104
2222,2222,165.3937,14.091854,6.2545681,0.0,0,3.3257859,0.0,0.53861374,95.11319096465292,3.7037222,342.02274,-9.2803736,95.11319096465292,,,,,0.5241263681318682,96.76182570017245,0.5241210624811687,0.5241210624811687
2224,2224,165.3941,14.129383,6.2942486,0.0,0,3.2902899,0.0,0.54392242,94.87484167452448,3.667088,341.78824,-9.2811432,94.87484167452448,,,,,0.5283193790769232,96.77019205123923,0.5283140729674795,0.5283140729674795
2226,2226,165.3945,14.20035,6.3295593,0.0,0,3.2547936,0.0,0.54782307,94.91160724739296,3.628072,341.55374,-9.2804785,94.91160724739296,,,,,0.532512390021978,96.77849462233134,0.5325070834572871,0.5325070834572871
2228,2228,165.3949,14.278234,6.3725004,0.0,0,3.2192979,0.0,0.55224109,94.89437886172811,3.5931046,341.31927,-9.2815075,94.89437886172811,,,,,0.536705400967033,96.78673439619001,0.5367000939505383,0.5367000939505383
2230,2230,165.3953,14.359899,6.4086022,0.0,0,3.1838019,0.0,0.55746686,94.98235740209972,3.5564468,341.08478,-9.2811842,94.98235740209972,,,,,0.540898411912088,96.79491233288798,0.5408931044471802,0.5408931044471802
2232,2232,165.3957,14.411586,6.446928,0.0,0,3.1483059,0.0,0.56115997,94.8396523934944,3.5168419,340.85028,-9.2801847,94.8396523934944,,,,,0.5450914228571428,96.80302937045815,0.5450861149471611,0.5450861149471611
2234,2234,165.3961,14.454937,6.4853783,0.0,0,3.1139472,0.0,0.56555474,94.63725631840634,3.4791944,340.6239,-9.280241,94.63725631840634,,,,,0.5492844338021978,96.81108642568098,0.5492791254504311,0.5492791254504311
2236,2236,165.3965,14.519673,6.5158715,0.0,0,3.0801756,0.0,0.57016802,94.6725549739653,3.4422085,340.42188,-9.2808857,94.6725549739653,,,,,0.5534774447472528,96.8190843946665,0.5534721359569409,0.5534721359569409
2238,2238,165.3969,14.609849,6.556736,0.0,0,3.0464077,0.0,0.57375509,94.7365580234668,3.4064612,340.21985,-9.2804279,94.7365580234668,,,,,0.5576704556923078,96.82702415344248,0.5576651464666426,0.5576651464666426
2240,2240,165.3973,14.690093,6.591783,0.0,0,3.0126395,0.0,0.57837778,94.80499391590249,3.3696764,340.01779,-9.2801561,94.80499391590249,,,,,0.5618634666373626,96.83490655859428,0.5618581569794888,0.5618581569794888
2242,2242,165.3977,14.720103,6.6250072,0.0,0,2.9788716,0.0,0.58287632,94.5693494313308,3.3318977,339.81577,-9.2794456,94.5693494313308,,,,,0.5660564775824176,96.84273244783347,0.5660511674954342,0.5660511674954342
2244,2244,165.3981,14.773238,6.6709623,0.0,0,2.9451036,0.0,0.58710933,94.31467056345132,3.2947209,339.61374,-9.2794333,94.31467056345132,,,,,0.5702494885274726,96.85050264055349,0.5702441780144334,0.5702441780144334
2246,2246,165.3985,14.845007,6.7001452,0.0,0,2.9113355,0.0,0.59169704,94.392464001283,3.2591476,339.41171,-9.2806911,94.392464001283,,,,,0.5744424994725276,96.85821793832157,0.5744371885364427,0.5744371885364427
2248,2248,165.3989,14.949669,6.7338729,0.0,0,2.8775675,0.0,0.59559554,94.6151854344546,3.2259247,339.20966,-9.2808561,94.6151854344546,,,,,0.5786355104175824,96.86587912545663,0.5786301990614189,0.5786301990614189
2250,2250,165.3993,15.025197,6.7771578,0.0,0,2.8437996,0.0,0.60000217,94.52201293318636,3.1900043,339.00763,-9.2807722,94.52201293318636,,,,,0.5828285213626374,96.87348696943599,0.58282320958932,0.58282320958932
2252,2252,165.3997,15.060502,6.8039923,0.0,0,2.8100314,0.0,0.60446692,94.38913620038474,3.1527247,338.8056,-9.2800493,94.38913620038474,,,,,0.5870215323076924,96.8810422214963,0.5870162201201049,0.5870162201201049
2254,2254,165.4001,15.116457,6.8386068,0.0,0,2.7762637,0.0,0.6080538,94.28018447044808,3.1199746,338.60358,-9.2800016,94.28018447044808,,,,,0.5912145432527472,96.88854561696539,0.5912092306537331,0.5912092306537331
2256,2256,165.4005,15.199747,6.8808932,0.0,0,2.7424955,0.0,0.61283457,94.2349803482986,3.0877483,338.40152,-9.2790174,94.2349803482986,,,,,0.5954075541978022,96.89599787580018,0.5954022411901654,0.5954022411901654
2258,2258,165.4009,15.289216,6.9069982,0.0,0,2.7090657,0.0,0.61729127,94.43898065182604,3.0512562,338.19949,-9.2786856,94.43898065182604,,,,,0.5996005651428572,96.90339970295256,0.5995952517293629,0.5995952517293629
2260,2260,165.4013,15.35642,6.9463186,0.0,0,2.6768651,0.0,0.620951,94.32349217176773,3.0177326,337.99747,-9.2795944,94.32349217176773,,,,,0.6037935760879122,96.91075178883327,0.6037882622712878,0.6037882622712878
2262,2262,165.4017,15.404053,6.9840064,0.0,0,2.6447449,0.0,0.62612629,94.10586112238724,2.9849229,337.79544,-9.2807827,94.10586112238724,,,,,0.607986587032967,96.91805480967102,0.607981272815903,0.607981272815903
2264,2264,165.4021,15.475149,7.0094833,0.0,0,2.6126249,0.0,0.62996513,94.19367232111745,2.9497838,337.59341,-9.2809439,94.19367232111745,,,,,0.612179597978022,96.92530942793971,0.6121742833631723,0.6121742833631723
2266,2266,165.4025,15.567039,7.0465245,0.0,0,2.5805047,0.0,0.63339782,94.2461247223214,2.9156861,337.39136,-9.2807512,94.2461247223214,,,,,0.616372608923077,96.93251629266821,0.6163672939130599,0.6163672939130599
2268,2268,165.4029,15.662562,7.0809121,0.0,0,2.5483847,0.0,0.63864547,94.35094956900308,2.8824201,337.18933,-9.2798996,94.35094956900308,,,,,0.620565619868132,96.93967603987444,0.6205603044655312,0.6205603044655312
2270,2270,165.4033,15.726118,7.1113701,0.0,0,2.5162647,0.0,0.64239758,94.31268019403176,2.8484223,336.9873,-9.2793655,94.31268019403176,,,,,0.6247586308131868,96.9467892928606,0.6247533150205516,0.6247533150205516
2272,2272,165.4037,15.784067,7.1494503,0.0,0,2.4841447,0.0,0.64652103,94.13169549836454,2.8149145,336.78528,-9.2795868,94.13169549836454,,,,,0.6289516417582418,96.95385666258433,0.6289463255780882,0.6289463255780882
2274,2274,165.4041,15.866069,7.1816831,0.0,0,2.4520247,0.0,0.65184474,94.17099714846766,2.7776527,336.58322,-9.2797279,94.17099714846766,,,,,0.6331446527032968,96.96087874795302,0.6331393361381077,0.6331393361381077
2276,2276,165.4045,15.96032,7.2155991,0.0,0,2.4199049,0.0,0.65529025,94.25432998175414,2.7485073,336.3812,-9.2803183,94.25432998175414,,,,,0.6373376636483516,96.96785613616353,0.637332346700578,0.637332346700578
2278,2278,165.4049,16.06078,7.250412,0.0,0,2.3877847,0.0,0.65949583,94.3557990742666,2.7136946,336.17917,-9.2802782,94.3557990742666,,,,,0.6415306745934066,96.97478940298646,0.6415253572654677,0.6415253572654677
2280,2280,165.4053,16.140276,7.2785392,0.0,0,2.3556647,0.0,0.6645112,94.42347200306618,2.6805918,335.97714,-9.2807951,94.42347200306618,,,,,0.6457236855384616,96.98167911310126,0.6457183678327456,0.6457183678327456
2282,2282,165.4057,16.187246,7.3171229,0.0,0,2.3235447,0.0,0.66812104,94.14877732478678,2.6491666,335.77509,-9.280694,94.14877732478678,,,,,0.6499166964835166,96.98852582029895,0.6499113784023814,0.6499113784023814
2284,2284,165.4061,16.275148,7.3479977,0.0,0,2.2924569,0.0,0.67267919,94.21790543998448,2.6169672,335.51941,-9.28057,94.21790543998448,,,,,0.6541097074285714,96.99533006788468,0.6541043889743454,0.6541043889743454
2286,2286,165.4065,16.36824,7.3762765,0.0,0,2.2619016,0.0,0.67698896,94.34951117785089,2.5829976,335.10281,-9.2803192,94.34951117785089,,,,,0.6583027183736264,97.00209238879246,0.6582973995486083,0.6582973995486083
2288,2288,165.4069,16.470812,7.4182968,0.0,0,2.2313497,0.0,0.6810233,94.33166015135755,2.5506685,334.68622,-9.2793226,94.33166015135755,,,,,0.6624957293186814,97.00881330599049,0.6624904101251415,0.6624904101251415
2290,2290,165.4073,16.545916,7.4468036,0.0,0,2.2007978,0.0,0.68591589,94.34665210545847,2.5162528,334.26962,-9.2791271,94.34665210545847,,,,,0.6666887402637364,97.01549333262643,0.6666834207039168,0.6666834207039168
2292,2292,165.4077,16.609678,7.475955,0.0,0,2.1702456,0.0,0.68981194,94.28402411939942,2.483248,333.85303,-9.2791996,94.28402411939942,,,,,0.6708817512087912,97.02213297233487,0.6708764312849066,0.6708764312849066
2294,2294,165.4081,16.702509,7.5166459,0.0,0,2.1396937,0.0,0.69407839,94.21266528087892,2.4530053,333.43646,-9.2791014,94.21266528087892,,,,,0.6750747621538462,97.02873271943295,0.6750694418680838,0.6750694418680838
2296,2296,165.4085,16.791569,7.5396347,0.0,0,2.1091418,0.0,0.69869411,94.37516131241529,2.4206202,333.01987,-9.2799234,94.37516131241529,,,,,0.6792677730989012,97.03529305914672,0.6792624524534218,0.6792624524534218
2298,2298,165.4089,16.911333,7.5715284,0.0,0,2.0785899,0.0,0.70211726,94.57337233177576,2.3880038,332.60327,-9.2794228,94.57337233177576,,,,,0.683460784043956,97.04181446790736,0.6834554630408943,0.6834554630408943
2300,2300,165.4093,16.984333,7.6124797,0.0,0,2.048038,0.0,0.70718127,94.36912816081274,2.3527038,332.18668,-9.2791243,94.36912816081274,,,,,0.687653794989011,97.04829741342948,0.687648473630476,0.687648473630476
2302,2302,165.4097,17.064978,7.636869,0.0,0,2.0174859,0.0,0.71183449,94.4506668448426,2.3203888,331.77008,-9.2786207,94.4506668448426,,,,,0.691846805934066,97.0547423550591,0.6918414842221415,0.6918414842221415
2304,2304,165.4101,17.154661,7.6724119,0.0,0,1.9869336,0.0,0.71538788,94.41001259881484,2.2884614,331.35352,-9.2791939,94.41001259881484,,,,,0.696039816879121,97.06114974390321,0.6960344948158662,0.6960344948158662
2306,2306,165.4105,17.275444,7.7099977,0.0,0,1.9563816,0.0,0.72086841,94.50277826343876,2.2561915,330.93692,-9.2794619,94.50277826343876,,,,,0.7002328278241758,97.06752002300315,0.7002275054116255,0.7002275054116255
2308,2308,165.4109,17.375885,7.7318563,0.0,0,1.9261349,0.0,0.72480589,94.71762979039995,2.2243168,330.52032,-9.2782001,94.71762979039995,,,,,0.7044258387692308,97.0738536275961,0.7044205160093958,0.7044205160093958
2310,2310,165.4113,17.460325,7.7660575,0.0,0,1.896998,0.0,0.72819567,94.65180269702697,2.1920414,330.10373,-9.2786655,94.65180269702697,,,,,0.7086188497142858,97.08015098527402,0.7086135266091537,0.7086135266091537
2312,2312,165.4117,17.547049,7.7989192,0.0,0,1.867934,0.0,0.73366916,94.61385515963744,2.1619256,329.68713,-9.2791319,94.61385515963744,,,,,0.7128118606593408,97.08641251607237,0.7128065372108761,0.7128065372108761
2314,2314,165.4121,17.625904,7.8262897,0.0,0,1.83887,0.0,0.7373808,94.61392550451224,2.1294873,329.27057,-9.2788429,94.61392550451224,,,,,0.7170048716043956,97.0926386328231,0.71699954781454,0.71699954781454
2316,2316,165.4125,17.744289,7.8624372,0.0,0,1.809806,0.0,0.74150944,94.68413745749774,2.0975449,328.85397,-9.2785339,94.68413745749774,,,,,0.7211978825494506,97.09882974113692,0.7211925584201238,0.7211925584201238
2318,2318,165.4129,17.857702,7.8933187,0.0,0,1.7807419,0.0,0.74725044,94.80325992871497,2.0686724,328.43738,-9.2792521,94.80325992871497,,,,,0.7253908934945056,97.10498623972748,0.7253855690276052,0.7253855690276052
2320,2320,165.4133,17.951406,7.9253654,0.0,0,1.751678,0.0,0.75092953,94.79362995773764,2.0362165,328.02078,-9.2779188,94.79362995773764,,,,,0.7295839044395604,97.11110852044547,0.7295785796369628,0.7295785796369628
2322,2322,165.4137,18.018539,7.9588418,0.0,0,1.722614,0.0,0.75530845,94.6163873376093,2.0064957,327.60419,-9.2791548,94.6163873376093,,,,,0.7337769153846154,97.11719696849302,0.7337715902481756,0.7337715902481756
2324,2324,165.4141,18.113796,7.9832983,0.0,0,1.69355,0.0,0.76020855,94.72603013776651,1.9760492,327.18762,-9.2795916,94.72603013776651,,,,,0.7379699263296704,97.1232519625556,0.7379646008612227,0.7379646008612227
2326,2326,165.4145,18.239067,8.0181532,0.0,0,1.6644859,0.0,0.76373029,94.82062179298087,1.945863,326.77103,-9.2797785,94.82062179298087,,,,,0.7421629372747254,97.12927387500555,0.7421576114760838,0.7421576114760838
2328,2328,165.4149,18.371584,8.0489359,0.0,0,1.635422,0.0,0.76848948,95.01087561312382,1.9168034,326.35443,-9.2785006,95.01087561312382,,,,,0.7463559482197802,97.13526307195386,0.7463506220927386,0.7463506220927386
2330,2330,165.4153,18.455282,8.0749779,0.0,0,1.6063581,0.0,0.77329701,95.01989997764642,1.8862258,325.93784,-9.2777433,95.01989997764642,,,,,0.7505489591648352,97.14121991344257,0.7505436327111676,0.7505436327111676
2332,2332,165.4157,18.540852,8.1150618,0.0,0,1.577294,0.0,0.77739024,94.80502309844552,1.8541812,325.52124,-9.2791929,94.80502309844552,,,,,0.7547419701098902,97.14714475355197,0.7547366433313515,0.7547366433313515
2334,2334,165.4161,18.645041,8.1420145,0.0,0,1.5491621,0.0,0.7824561,94.89452646315132,1.8244863,325.02896,-9.2794828,94.89452646315132,,,,,0.7589349810549452,97.15303794057937,0.7589296539532708,0.7589296539532708
2336,2336,165.4165,18.790535,8.1669102,0.0,0,1.521511,0.0,0.7862972,95.22237889402896,1.7922995,324.30969,-9.2783012,95.22237889402896,,,,,0.763127992,97.15889981709013,0.7631226645769069,0.7631226645769069
2338,2338,165.4169,18.92234,8.2057695,0.0,0,1.493863,0.0,0.79043609,95.2416446935595,1.7584344,323.59045,-9.2778301,95.2416446935595,,,,,0.767321002945055,97.16473072015002,0.7673156752022414,0.7673156752022414
2340,2340,165.4173,19.01157,8.2288799,0.0,0,1.466215,0.0,0.79560196,95.30313826833952,1.7306777,322.87122,-9.2775478,95.30313826833952,,,,,0.77151401389011,97.17053098129877,0.7715086858292561,0.7715086858292561
2342,2342,165.4177,19.103497,8.2601957,0.0,0,1.438567,0.0,0.79941744,95.23612497099846,1.7004297,322.15195,-9.278573,95.23612497099846,,,,,0.7757070248351648,97.17630092680886,0.775701696457933,0.775701696457933
2344,2344,165.4181,19.222555,8.2993612,0.0,0,1.4109191,0.0,0.80462515,95.1653405085299,1.6673073,321.43271,-9.2791996,95.1653405085299,,,,,0.7799000357802198,97.18204087771201,0.7798947070882546,0.7798947070882546
2346,2346,165.4185,19.369392,8.3204908,0.0,0,1.3832711,0.0,0.80929607,95.53112306573384,1.6418191,320.71344,-9.2782164,95.53112306573384,,,,,0.7840930467252748,97.1877511499563,0.7840877177202035,0.7840877177202035
2348,2348,165.4189,19.500069,8.3534775,0.0,0,1.355623,0.0,0.81294149,95.60794870484526,1.6079036,319.9942,-9.2774649,95.60794870484526,,,,,0.7882860576703298,97.1934320544686,0.7882807283537627,0.7882807283537627
2350,2350,165.4193,19.578259,8.3893509,0.0,0,1.3279752,0.0,0.81861019,95.37141839434987,1.5770131,319.27496,-9.2765675,95.37141839434987,,,,,0.7924790686153846,97.19908389730601,0.7924737389889154,0.7924737389889154
2352,2352,165.4197,19.68635,8.4083967,0.0,0,1.3003271,0.0,0.82253569,95.56700906044732,1.5478009,318.55569,-9.2778044,95.56700906044732,,,,,0.7966720795604396,97.20470697972632,0.7966667496256452,0.7966667496256452
2354,2354,165.4201,19.813206,8.4405203,0.0,0,1.2726791,0.0,0.82596642,95.62099452759784,1.5178077,317.83646,-9.2782192,95.62099452759784,,,,,0.8008650905054946,97.21030159830232,0.8008597602639357,0.8008597602639357
2356,2356,165.4205,19.96196,8.4727821,0.0,0,1.2450311,0.0,0.83189732,95.77036524900402,1.4877943,317.11719,-9.2779493,95.77036524900402,,,,,0.8050581014505496,97.21586804502365,0.8050527709037708,0.8050527709037708
2358,2358,165.4209,20.092169,8.4985762,0.0,0,1.2176605,0.0,0.83598822,95.93750591025584,1.4569328,316.39795,-9.2782421,95.93750591025584,,,,,0.8092511123956044,97.22140660736513,0.8092457815451349,0.8092457815451349
2360,2360,165.4213,20.168373,8.5337391,0.0,0,1.1912985,0.0,0.84018362,95.6752105856824,1.4329267,315.67871,-9.277585,95.6752105856824,,,,,0.8134441233406594,97.22691756843209,0.8134387921880125,0.8134387921880125
2362,2362,165.4217,20.277111,8.5604305,0.0,0,1.1650023,0.0,0.84590977,95.71314171973778,1.3995641,314.95944,-9.2764578,95.71314171973778,,,,,0.8176371342857144,97.23240120695968,0.8176318028323882,0.8176318028323882
2364,2364,165.4221,20.408875,8.5864134,0.0,0,1.1387062,0.0,0.84916699,95.86683160644948,1.3713864,314.2402,-9.2763004,95.86683160644948,,,,,0.8218301452307692,97.23785779751701,0.821824813478247,0.821824813478247
2366,2366,165.4225,20.554562,8.6161432,0.0,0,1.1124103,0.0,0.85327786,96.01151128988111,1.3440082,313.52097,-9.2765074,96.01151128988111,,,,,0.8260231561758242,97.24328761048767,0.8260178241255741,0.8260178241255741
2368,2368,165.4229,20.685276,8.6393185,0.0,0,1.0861143,0.0,0.85864025,96.19870283476088,1.3111376,312.8017,-9.2770643,96.19870283476088,,,,,0.8302161671208792,97.24869091219384,0.8302108347743549,0.8302108347743549
2370,2370,165.4233,20.790396,8.6718626,0.0,0,1.0598181,0.0,0.86209726,96.08997754002954,1.2853876,312.08246,-9.2768154,96.08997754002954,,,,,0.8344091780659342,97.25406796504885,0.834403845424575,0.834403845424575
2372,2372,165.4237,20.902067,8.7025156,0.0,0,1.0335222,0.0,0.86734462,96.040170839636,1.2579583,311.36319,-9.2769365,96.040170839636,,,,,0.838602189010989,97.25941902746159,0.83859685607622,0.83859685607622
2374,2374,165.4241,21.044373,8.7247906,0.0,0,1.0072262,0.0,0.87196076,96.27995685318496,1.2292207,310.64395,-9.2782612,96.27995685318496,,,,,0.842795199956044,97.26474435409811,0.8427898667292764,0.8427898667292764
2376,2376,165.4245,21.195522,8.7594995,0.0,0,0.98093021,0.0,0.87551641,96.32158893387452,1.1999631,309.92471,-9.2769995,96.32158893387452,,,,,0.846988210901099,97.27004419586595,0.84698287738373,0.84698287738373
2378,2378,165.4249,21.332617,8.7819014,0.0,0,0.95463419,0.0,0.88036907,96.5224169040504,1.1733481,309.20544,-9.2757387,96.5224169040504,,,,,0.8511812218461539,97.27531879996293,0.8511758880395675,0.8511758880395675
2380,2380,165.4253,21.44066,8.8060722,0.0,0,0.92833829,0.0,0.88442338,96.55341595657494,1.143857,308.48621,-9.2764158,96.55341595657494,,,,,0.8553742327912088,97.2805684100149,0.8553688986967755,0.8553688986967755
2382,2382,165.4257,21.556599,8.8411179,0.0,0,0.90204227,0.0,0.88852382,96.40803843105569,1.1154759,307.76694,-9.2768002,96.40803843105569,,,,,0.8595672437362638,97.28579326612844,0.8595619093553408,0.8595619093553408
2384,2384,165.4261,21.696682,8.8619671,0.0,0,0.87659407,0.0,0.89371824,96.63483659207007,1.0866153,307.02588,-9.2776175,96.63483659207007,,,,,0.8637602546813188,97.29099360491064,0.8637549200152504,0.8637549200152504
2386,2386,165.4265,21.84329,8.8872356,0.0,0,0.85158336,0.0,0.89720535,96.80009942521374,1.0632375,306.21939,-9.277688,96.80009942521374,,,,,0.8679532656263736,97.29616965958797,0.8679479306764916,0.8679479306764916
2388,2388,165.4269,21.971323,8.9229479,0.0,0,0.82657528,0.0,0.90221786,96.67411489682569,1.0343957,305.41293,-9.27707,96.67411489682569,,,,,0.8721462765714286,97.30132166009008,0.8721409413390517,0.8721409413390517
2390,2390,165.4273,22.085575,8.9407015,0.0,0,0.80156738,0.0,0.90699631,96.83032154101969,1.0064918,304.60645,-9.2764711,96.83032154101969,,,,,0.8763392875164836,97.30644983298974,0.8763339520029184,0.8763339520029184
2392,2392,165.4277,22.212997,8.9689217,0.0,0,0.77655935,0.0,0.91019446,96.8349971960909,0.97744524,303.79999,-9.276762,96.8349971960909,,,,,0.8805322984615386,97.31155440176185,0.8805269626680794,0.8805269626680794
2394,2394,165.4281,22.35442,8.9993086,0.0,0,0.75155133,0.0,0.91535079,96.8511699534799,0.95346636,302.9935,-9.2762747,96.8511699534799,,,,,0.8847253094065934,97.31663558666186,0.8847199733345223,0.8847199733345223
2396,2396,165.4285,22.514118,9.014143,0.0,0,0.72654337,0.0,0.91922426,97.24788318953097,0.92721885,302.18704,-9.2762747,97.24788318953097,,,,,0.8889183203516484,97.32169360486327,0.8889129840022357,0.8889129840022357
2398,2398,165.4289,22.651861,9.0452299,0.0,0,0.70153534,0.0,0.92253268,97.22046229937312,0.89885873,301.38055,-9.2766724,97.22046229937312,,,,,0.8931113312967034,97.32672867052861,0.8931059946712077,0.8931059946712077
2400,2400,165.4293,22.777182,9.0759106,0.0,0,0.67652738,0.0,0.92872494,97.14064838728676,0.87541097,300.5741,-9.2769365,97.14064838728676,,,,,0.8973043422417583,97.33174099485858,0.8972990053414265,0.8972990053414265
2402,2402,165.4297,22.908232,9.0966425,0.0,0,0.65151936,0.0,0.93258172,97.27974843576132,0.84909153,299.76761,-9.276288,97.27974843576132,,,,,0.9014973531868132,97.33673078609567,0.9014920160128809,0.9014920160128809
2404,2404,165.4301,23.054361,9.1268787,0.0,0,0.62651134,0.0,0.93627638,97.28409873617996,0.82710302,298.96112,-9.2756405,97.28409873617996,,,,,0.9056903641318682,97.34169824967198,0.9056850266855595,0.9056850266855595
2406,2406,165.4305,23.206108,9.1479073,0.0,0,0.60150337,0.0,0.94184405,97.49305781723552,0.79866338,298.15466,-9.2752457,97.49305781723552,,,,,0.9098833750769232,97.34664358813448,0.9098780373594514,0.9098780373594514
2408,2408,165.4309,23.340189,9.1691484,0.0,0,0.57674313,0.0,0.94450456,97.6180901175435,0.7733475,297.34818,-9.2754049,97.6180901175435,,,,,0.914076386021978,97.35156700132805,0.9140710480345453,0.9140710480345453
2410,2410,165.4313,23.457289,9.1963444,0.0,0,0.5528841,0.0,0.94854587,97.5438855853164,0.7488789,296.54172,-9.2760458,97.5438855853164,,,,,0.918269396967033,97.35646868637414,0.9182640587108308,0.9182640587108308
2412,2412,165.4317,23.590269,9.2175713,0.0,0,0.52908403,0.0,0.95390999,97.6541750510039,0.72388071,295.73523,-9.2749662,97.6541750510039,,,,,0.922462407912088,97.36134883772506,0.9224570693882971,0.9224570693882971
2414,2414,165.4321,23.749422,9.2456474,0.0,0,0.50528395,0.0,0.95693195,97.723509198515,0.70075846,294.92877,-9.2747393,97.723509198515,,,,,0.926655418857143,97.36620764721027,0.9266500800669334,0.9266500800669334
2416,2416,165.4325,23.925352,9.2707348,0.0,0,0.48148397,0.0,0.96181226,97.91676341408268,0.67316246,294.12228,-9.2747622,97.91676341408268,,,,,0.9308484298021978,97.37104530410676,0.9308430907467296,0.9308430907467296
2418,2418,165.4329,24.075239,9.2896042,0.0,0,0.45768398,0.0,0.96652138,98.12854972919992,0.64705789,293.3158,-9.2748747,98.12854972919992,,,,,0.9350414407472528,97.37586199516382,0.9350361014276755,0.9350361014276755
2420,2420,165.4333,24.196636,9.3209858,0.0,0,0.43388397,0.0,0.96986002,97.9520063401133,0.62387884,292.50934,-9.2755423,97.9520063401133,,,,,0.9392344516923078,97.3806579046448,0.9392291121097608,0.9392291121097608
2422,2422,165.4337,24.34091,9.341258,0.0,0,0.41008398,0.0,0.97462767,98.0997746873654,0.60042071,291.70285,-9.2771034,98.0997746873654,,,,,0.9434274626373627,97.38543321440278,0.9434221227929755,0.9434221227929755
2424,2424,165.4341,24.50054,9.361331,0.0,0,0.38628396,0.0,0.97851205,98.30829429388568,0.57436228,290.89639,-9.2751007,98.30829429388568,,,,,0.9476204735824176,97.39018810389166,0.9476151334773102,0.9476151334773102
2426,2426,165.4345,24.67432,9.3946247,0.0,0,0.36248395,0.0,0.98253649,98.27924111701024,0.55022371,290.0899,-9.2739639,98.27924111701024,,,,,0.9518134845274726,97.39492275018648,0.9518081441627547,0.9518081441627547
2427,2427,165.4347,24.74828,9.3969994,0.0,0,0.35058397,0.0,0.98461026,98.52186526189978,0.53980845,289.68668,-9.2732239,98.52186526189978,,,,,0.95390999,97.39728253685558,0.95390464950589,0.95390464950589