File: examples/hot axisymmetric compression example/data/12 fitted data ramberg/testID_0132.csv
level_0,index,Time(sec),Force(kN),Jaw(mm),PowAngle(deg),Power(W),Pram,PTemp,Strain,Stress(MPa),Stroke(mm),TC1(C),wedge(mm),uncorrected stress,sampled strain,sampled stress,fitting strain,fitting stress,model strain,ramberg stress,ramberg plastic strain,ramberg accumulated plastic strain
1773,1773,145.3439,0.48595235,0.046863034,0.0,0,9.0336914,0.0,0.0029801505,5.9043565671639655,10.035624,302.31415,-9.3252954,5.9043565671639655,0.0029801505,5.9043565671639655,0.0,5.9043565671639655,0.0,0.0,0.0,0.0
1776,1776,145.3445,4.4151216,0.10353631,0.0,0,8.9459,0.0,0.0063896924,53.42769082837276,9.9191151,302.71082,-9.3260231,53.42769082837276,0.15472282,118.85105411484746,0.1470295605,118.60567312884254,0.006364916038961039,108.43943196494693,0.006362031110949906,0.006362031110949906
1779,1779,145.3451,6.616365,0.17955042,0.0,0,8.8581076,0.0,0.011563532,79.63016661189569,9.8258114,303.10748,-9.3209686,79.63016661189569,0.29418182,120.18728854049375,0.294059121,120.1870980081871,0.012729832077922078,109.81553326008842,0.012726910540044031,0.012726910540044031
1782,1782,145.3457,7.5911856,0.36879843,0.0,0,8.7703152,0.0,0.024135502,90.11987082722096,9.6949463,303.50412,-9.3195801,90.11987082722096,0.44344744,117.7918487969784,0.44108868149999997,117.83856352500278,0.019094748116883116,110.64844938648218,0.01909180442006325,0.01909180442006325
1785,1785,145.3463,8.659667,0.48920563,0.0,0,8.6858358,0.0,0.032477558,101.90242553502208,9.5374994,303.90079,-9.3199062,101.90242553502208,0.58917427,116.35157059628456,0.588118242,116.35265076275206,0.025459664155844157,111.25230641767831,0.025456704393981965,0.025456704393981965
1788,1788,145.3469,9.4807901,0.58609968,0.0,0,8.6023397,0.0,0.039895389,110.7700821578776,9.4110508,304.29745,-9.3184366,110.7700821578776,0.73831195,116.94348604994502,0.7351478025,116.9087960398278,0.03182458019480519,111.72821091312021,0.031821607771956265,0.031821607771956265
1791,1791,145.3475,9.1060486,0.6652503,0.0,0,8.5188437,0.0,0.045004513,105.7679891841152,9.317009,304.69412,-9.3173285,105.7679891841152,0.88482463,119.54727760532224,0.8821773629999999,119.47201046996179,0.03818949623376623,112.12200044000843,0.038186513334521256,0.038186513334521256
1794,1794,145.3481,9.7720718,0.73870283,0.0,0,8.4353476,0.0,0.050457243,112.88267867495895,9.2277689,305.09079,-9.3181734,112.88267867495895,,,,,0.04455441227272727,112.45845725788527,0.044551420422368475,0.044551420422368475
1797,1797,145.3487,10.098038,0.87873399,0.0,0,8.3518515,0.0,0.059781276,115.42399440148851,9.1155424,305.48743,-9.3165159,115.42399440148851,,,,,0.050919328311688314,112.75253686403279,0.05091632863762113,0.05091632863762113
1800,1800,145.3493,9.9760637,1.0074372,0.0,0,8.2683554,0.0,0.06915947,112.91805080159808,8.9923487,305.88409,-9.3170824,112.91805080159808,,,,,0.05728424435064935,113.01397545289156,0.05728123772125702,0.05728123772125702
1803,1803,145.3499,10.175343,1.1063942,0.0,0,8.1848602,0.0,0.076612458,114.30164157080269,8.8746815,306.28076,-9.317543,114.30164157080269,,,,,0.06364916038961038,113.24947434217181,0.06364614749499395,0.06364614749499395
1806,1806,145.3505,10.484765,1.1717598,0.0,0,8.1013641,0.0,0.080936141,117.18382432523096,8.7794209,306.67743,-9.3173437,117.18382432523096,,,,,0.07001407642857142,113.46384729037727,0.07001105783076647,0.07001105783076647
1809,1809,145.3511,10.526853,1.2491795,0.0,0,8.0196486,0.0,0.086745836,116.94823016128608,8.6992769,307.0741,-9.3180618,116.94823016128608,,,,,0.07637899246753246,113.66067123725726,0.0763759686334135,0.0763759686334135
1812,1812,145.3517,10.728621,1.352932,0.0,0,7.9402027,0.0,0.093955375,118.22536380422888,8.6112547,307.47073,-9.3175488,118.22536380422888,,,,,0.0827439085064935,113.84267822606448,0.0827408798302516,0.0827408798302516
1815,1815,145.3523,10.6746,1.4624104,0.0,0,7.8607621,0.0,0.10185686,116.61737112792495,8.5122957,307.84357,-9.3158455,116.61737112792495,,,,,0.08910882454545455,114.01200312263937,0.08910579136448472,0.08910579136448472
1818,1818,145.3529,10.830628,1.5617573,0.0,0,7.781322,0.0,0.10943027,117.38934893531965,8.4128742,308.19254,-9.3159847,117.38934893531965,,,,,0.09547374058441559,114.17034653514148,0.0954707031908698,0.0954707031908698
1821,1821,145.3535,10.991618,1.617704,0.0,0,7.7018824,0.0,0.11333983,118.601198161242,8.3251629,308.5415,-9.3171158,118.601198161242,,,,,0.10183865662337663,114.3190855907714,0.10183561527276964,0.10183561527276964
1824,1824,145.3541,10.939074,1.6946143,0.0,0,7.6224422,0.0,0.11931576,117.30484779152418,8.2525024,308.89047,-9.3169165,117.30484779152418,,,,,0.10820357266233765,114.45935142240855,0.10820052758009155,0.10820052758009155
1827,1827,145.3547,11.223829,1.7738726,0.0,0,7.5430021,0.0,0.12491523,119.58707187815492,8.1759071,309.23947,-9.3153448,119.58707187815492,,,,,0.1145684887012987,114.59208470863958,0.11456544008780968,0.11456544008780968
1830,1830,145.3553,11.253432,1.8627543,0.0,0,7.4635625,0.0,0.13172413,119.03507452431056,8.0883837,309.58844,-9.3153906,119.03507452431056,,,,,0.12093340474025974,114.71807633828021,0.12093035277488318,0.12093035277488318
1833,1833,145.3559,11.208066,1.9562832,0.0,0,7.3846536,0.0,0.1389633,117.64596872377138,8.0025978,309.93741,-9.3167067,117.64596872377138,,,,,0.12729832077922076,114.83799774511319,0.12729526562344917,0.12729526562344917
1836,1836,145.3565,11.423698,2.0141978,0.0,0,7.3089752,0.0,0.14356565,119.33542948273528,7.9218516,310.28641,-9.3174982,119.33542948273528,,,,,0.13366323681818182,114.95242391437928,0.13366017861821075,0.13366017861821075
1839,1839,145.3571,11.416974,2.0909884,0.0,0,7.2334232,0.0,0.14962262,118.50454766298866,7.8498912,310.63538,-9.3164139,118.50454766298866,,,,,0.14002815285714285,115.06185109119114,0.14002509174596575,0.14002509174596575
1842,1842,145.3577,11.512878,2.1559482,0.0,0,7.1578708,0.0,0.15472282,118.85105411484746,7.7832088,310.98434,-9.3154745,118.85105411484746,,,,,0.1463930688961039,115.16671059276536,0.14639000499523944,0.14639000499523944
1845,1845,145.3583,11.680368,2.2326384,0.0,0,7.0823188,0.0,0.16084681,119.80271960273689,7.706172,311.33331,-9.3158398,119.80271960273689,,,,,0.15275798493506493,115.26737971159734,0.15275491835599425,0.15275491835599425
1848,1848,145.3589,11.655504,2.3138511,0.0,0,7.0067663,0.0,0.16739337,118.72609008821964,7.6302166,311.68231,-9.3161316,118.72609008821964,,,,,0.15912290097402598,115.36419041628002,0.15911983181939854,0.15911983181939854
1851,1851,145.3595,11.782069,2.3753376,0.0,0,6.9312148,0.0,0.17229559,119.38642977315968,7.552062,312.03128,-9.317379,119.38642977315968,,,,,0.165487817012987,115.4574363638389,0.16548474537763977,0.16548474537763977
1854,1854,145.3601,11.869367,2.4481528,0.0,0,6.8556633,0.0,0.17819816,119.52063572671616,7.4802351,312.38025,-9.3166323,119.52063572671616,,,,,0.17185273305194804,115.54737860318026,0.171849659023773,0.171849659023773
1857,1857,145.3607,11.94117,2.5143871,0.0,0,6.7801108,0.0,0.1834054,119.55688458224692,7.4078751,312.72925,-9.3159313,119.55688458224692,,,,,0.1782176490909091,115.63425025222796,0.1782145727515964,0.1782145727515964
1860,1860,145.3613,12.046187,2.5850325,0.0,0,6.7073903,0.0,0.18922755,119.86926299934778,7.3379259,313.07822,-9.3165722,119.86926299934778,,,,,0.18458256512987012,115.71826036337265,0.1845794865555483,0.1845794865555483
1863,1863,145.3619,12.093709,2.6630957,0.0,0,6.63551,0.0,0.19540149,119.522126349877,7.2635326,313.42719,-9.3187666,119.522126349877,,,,,0.19094748116883117,115.79959714085146,0.1909444004306217,0.1909444004306217
1866,1866,145.3625,12.217202,2.7307868,0.0,0,6.5636296,0.0,0.20088403,120.02417285316234,7.1882825,313.43024,-9.3166008,120.02417285316234,,,,,0.1973123972077922,115.87843063646699,0.1973093143722925,0.1973093143722925
1869,1869,145.3631,12.292533,2.8076999,0.0,0,6.4917502,0.0,0.20687667,119.9427688362424,7.1160946,313.36417,-9.3158941,119.9427688362424,,,,,0.20367731324675326,115.9549150218507,0.20367422837645918,0.20367422837645918
1872,1872,145.3637,12.334142,2.8772104,0.0,0,6.4198699,0.0,0.21261005,119.603727193388,7.0435524,313.29813,-9.3174276,119.603727193388,,,,,0.21004222928571428,116.02919051541727,0.2100391424393913,0.2100391424393913
1875,1875,145.3643,12.493302,2.9501719,0.0,0,6.3479896,0.0,0.21854044,120.354858581764,6.9709177,313.23209,-9.3176813,120.354858581764,,,,,0.2164071453246753,116.10138502437238,0.21640405655768605,0.21640405655768605
1878,1878,145.3649,12.53576,3.0247054,0.0,0,6.2761102,0.0,0.22461519,119.95169307540104,6.8987613,313.16602,-9.3160524,119.95169307540104,,,,,0.22277206136363636,116.17161555180796,0.22276897072823068,0.22276897072823068
1881,1881,145.3655,12.599799,3.0973668,0.0,0,6.2042303,0.0,0.23060182,119.76850731343691,6.823247,313.09998,-9.3164768,119.76850731343691,,,,,0.2291369774025974,116.23998940766982,0.22913388494817025,0.22913388494817025
1884,1884,145.3661,12.753761,3.1742907,0.0,0,6.1338935,0.0,0.23708327,120.37891647831788,6.7469201,313.03391,-9.3174582,120.37891647831788,,,,,0.23550189344155845,116.30660525559355,0.23549879921488,0.23549879921488
1887,1887,145.3667,12.821433,3.2441916,0.0,0,6.0655246,0.0,0.24291351,120.23820647351828,6.6767626,312.96786,-9.3164234,120.23820647351828,,,,,0.24186680948051947,116.37155402200132,0.24186371352594083,0.24186371352594083
1890,1890,145.3673,12.893808,3.318537,0.0,0,5.9971604,0.0,0.24937907,120.08311248282136,6.5992594,312.90179,-9.3165274,120.08311248282136,,,,,0.2482317255194805,116.43491968815185,0.24822862787911854,0.24822862787911854
1893,1893,145.3679,13.049384,3.3931844,0.0,0,5.9287963,0.0,0.25565362,120.68457673018548,6.5289049,312.83575,-9.3165598,120.68457673018548,,,,,0.2545966415584415,116.49677998342882,0.2545935422723452,0.2545935422723452
1896,1896,145.3685,13.091213,3.4678149,0.0,0,5.8604326,0.0,0.26225778,120.22130207419242,6.4525023,312.76971,-9.3172522,120.22130207419242,,,,,0.2609615575974026,116.55720699359135,0.2609584567037031,0.2609584567037031
1899,1899,145.3691,13.161179,3.5414712,0.0,0,5.792068,0.0,0.26870215,120.020171501781,6.3789692,312.70364,-9.3168831,120.020171501781,,,,,0.26732647363636364,116.61626769696741,0.2673233711714103,0.2673233711714103
1902,1902,145.3697,13.293506,3.6090386,0.0,0,5.7237043,0.0,0.27476391,120.44507362341186,6.3040943,312.6376,-9.3172817,120.44507362341186,,,,,0.2736913896753247,116.67402443797336,0.27368828567380815,0.27368828567380815
1905,1905,145.3703,13.371292,3.6825376,0.0,0,5.6553407,0.0,0.28133219,120.29427447619818,6.2338758,312.57153,-9.3175783,120.29427447619818,,,,,0.2800563057142857,116.73053534719948,0.2800532002093501,0.2800532002093501
1908,1908,145.3709,13.461764,3.7512138,0.0,0,5.587431,0.0,0.2875292,120.30322249023484,6.1622062,312.50549,-9.3167953,120.30322249023484,,,,,0.28642122175324675,116.78585471431467,0.286418114776592,0.286418114776592
1911,1911,145.3715,13.54546,3.8244486,0.0,0,5.5222831,0.0,0.29418182,120.18728854049375,6.0881515,312.43942,-9.3161917,120.18728854049375,,,,,0.2927861377922078,116.84003332098739,0.2927830293741827,0.2927830293741827
1914,1914,145.3721,13.65076,3.8973558,0.0,0,5.4572425,0.0,0.30083707,120.2547318218248,6.0164375,312.30865,-9.3163033,120.2547318218248,,,,,0.2991510538311688,116.89311873817897,0.29914794400085665,0.29914794400085665
1917,1917,145.3727,13.739833,3.9667037,0.0,0,5.3922029,0.0,0.30713481,120.20933417966926,5.9440675,311.85468,-9.3176193,120.20933417966926,,,,,0.30551596987012986,116.94515559246118,0.30551285865542666,0.30551285865542666
1920,1920,145.3733,13.8182,4.0381088,0.0,0,5.3271627,0.0,0.31365588,120.03524076725284,5.8713269,311.40067,-9.3173933,120.03524076725284,,,,,0.3118808859090909,116.99618580528582,0.3118777733367774,0.3118777733367774
1923,1923,145.3739,13.947438,4.106832,0.0,0,5.2621226,0.0,0.31992856,120.32258133902498,5.8016691,310.94669,-9.3163195,120.32258133902498,,,,,0.31824580194805197,117.04624880831358,0.31824268804385986,0.31824268804385986
1926,1926,145.3745,14.019763,4.1785297,0.0,0,5.197083,0.0,0.32639766,120.07037362510204,5.7285304,310.49271,-9.3154173,120.07037362510204,,,,,0.32461071798701296,117.09538173777297,0.32460760277568595,0.32460760277568595
1929,1929,145.3751,14.088339,4.2495651,0.0,0,5.1320429,0.0,0.33285624,119.78522815620138,5.6557002,310.0387,-9.3165054,119.78522815620138,,,,,0.330975634025974,117.14361961008626,0.3309725175313243,0.3309725175313243
1932,1932,145.3757,14.195162,4.3197527,0.0,0,5.0670028,0.0,0.33935517,119.82474859097216,5.5874305,309.58472,-9.3173695,119.82474859097216,,,,,0.3373405500649351,117.19099548090483,0.3373374323098953,0.3373374323098953
1935,1935,145.3763,14.28328,4.3895702,0.0,0,5.0044141,0.0,0.3456555,119.69889809642756,5.5161238,309.13074,-9.3168621,119.69889809642756,,,,,0.3437054661038961,117.23754058961951,0.34370234711056796,0.34370234711056796
1938,1938,145.3769,14.358398,4.4586129,0.0,0,4.9425535,0.0,0.35205334,119.46371026586586,5.4480991,308.67673,-9.316782,119.46371026586586,,,,,0.35007038214285713,117.28328449065103,0.350067261932556,0.350067261932556
1941,1941,145.3775,14.446808,4.5280714,0.0,0,4.8806939,0.0,0.35853049,119.32386731747184,5.3798857,308.22275,-9.3167105,119.32386731747184,,,,,0.3564352981818182,117.32825517299274,0.3564321767751148,0.3564321767751148
1944,1944,145.3781,14.55571,4.5963521,0.0,0,4.8188338,0.0,0.36499941,119.35612121950926,5.3072343,307.76877,-9.3160038,119.35612121950926,,,,,0.36280021422077924,117.37247916959872,0.3627970916375385,0.3627970916375385
1947,1947,145.3787,14.625874,4.6675763,0.0,0,4.7569737,0.0,0.3717663,119.0223228532526,5.2436962,307.31476,-9.3182554,119.0223228532526,,,,,0.36916513025974024,117.4159816568722,0.36916200651915715,0.36916200651915715
1950,1950,145.3793,14.717671,4.7361517,0.0,0,4.6951137,0.0,0.37834498,118.88835966126932,5.1765866,306.86078,-9.3170919,118.88835966126932,,,,,0.3755300462987013,117.45878654625373,0.3755269214193348,0.3755269214193348
1953,1953,145.3799,14.838024,4.8010712,0.0,0,4.6332541,0.0,0.38474354,119.01957062114808,5.109879,306.4068,-9.3158855,119.01957062114808,,,,,0.38189496233766235,117.50091656790839,0.3818918363374667,0.3818918363374667
1956,1956,145.3805,14.926108,4.8689137,0.0,0,4.5713935,0.0,0.39144412,118.84187968648848,5.0423589,305.95279,-9.3165541,118.84187968648848,,,,,0.38825987837662335,117.54239334770085,0.3882567512729774,0.3882567512729774
1959,1959,145.3811,14.984212,4.9366126,0.0,0,4.5108562,0.0,0.39821142,118.41854156934778,4.9788361,305.49881,-9.3178835,118.41854156934778,,,,,0.3946247944155844,117.58323747788556,0.3946216662253192,0.3946216662253192
1962,1962,145.3817,15.106074,5.0019522,0.0,0,4.452004,0.0,0.40499952,118.5194034017784,4.911634,305.04483,-9.3162355,118.5194034017784,,,,,0.40098971045454546,117.62346858220857,0.40098658119396996,0.40098658119396996
1965,1965,145.3823,15.199157,5.0642648,0.0,0,4.3931556,0.0,0.41138703,118.42224483561328,4.8489532,304.60922,-9.3154345,118.42224483561328,,,,,0.4073546264935065,117.6631053761922,0.40735149617843175,0.40735149617843175
1968,1968,145.3829,15.255095,5.1255102,0.0,0,4.3343081,0.0,0.41787696,118.04164544541536,4.7820807,304.19205,-9.3182125,118.04164544541536,,,,,0.4137195425324675,117.70216572248738,0.4137164111782294,0.4137164111782294
1971,1971,145.3835,15.38324,5.1865249,0.0,0,4.2754598,0.0,0.42422941,118.21288091036362,4.7211199,303.77484,-9.3176003,118.21288091036362,,,,,0.42008445857142857,117.74066668208563,0.420081326192909,0.420081326192909
1974,1974,145.3841,15.49304,5.2490888,0.0,0,4.2166119,0.0,0.43074942,118.20932905547885,4.6560783,303.35764,-9.3153343,118.20932905547885,,,,,0.4264493746103896,117.77862456207788,0.4264462412220367,0.4264462412220367
1977,1977,145.3847,15.543545,5.3125334,0.0,0,4.157764,0.0,0.4374297,117.73247755683144,4.5955486,302.94046,-9.3154068,117.73247755683144,,,,,0.4328142906493506,117.81605495934546,0.4328111562651976,0.4328111562651976
1980,1980,145.3853,15.656432,5.3706508,0.0,0,4.0989161,0.0,0.44344744,117.7918487969784,4.5284491,302.52325,-9.3181334,117.7918487969784,,,,,0.4391792066883117,117.85297280159924,0.43917607132199454,0.43917607132199454
1983,1983,145.3859,15.783778,5.4312253,0.0,0,4.040462,0.0,0.44973353,117.91373709872684,4.4706955,302.10605,-9.3168316,117.91373709872684,,,,,0.44554412272727273,117.88939238532977,0.4455409863920472,0.4455409863920472
1986,1986,145.3865,15.850039,5.4927607,0.0,0,3.9844,0.0,0.45612958,117.55555676519585,4.408246,301.68887,-9.3154221,117.55555676519585,,,,,0.45190903876623373,117.92532741096262,0.451905901474991,0.451905901474991
1989,1989,145.3871,15.95125,5.5524378,0.0,0,3.928432,0.0,0.46212047,117.47335857752134,4.3464365,301.27167,-9.3165932,117.47335857752134,,,,,0.4582739548051948,117.96079101577975,0.4582708165704766,0.4582708165704766
1992,1992,145.3877,16.08423,5.6095977,0.0,0,3.8724642,0.0,0.46815804,117.64818075210314,4.2872024,300.85449,-9.3175039,117.64818075210314,,,,,0.46463887084415584,117.99579580449523,0.46463573167816846,0.46463573167816846
1995,1995,145.3883,16.149536,5.6699429,0.0,0,3.8164961,0.0,0.47443473,117.27292031311045,4.2300372,300.43729,-9.3177843,117.27292031311045,,,,,0.4710037868831169,118.03035387778188,0.47100064679774484,0.47100064679774484
1998,1998,145.3889,16.222931,5.7295656,0.0,0,3.7605278,0.0,0.48075214,116.95918140795418,4.1722798,300.02008,-9.3160553,116.95918140795418,,,,,0.4773687029220779,118.06447685900044,0.47736556192889634,0.47736556192889634
2001,2001,145.3895,16.376244,5.7878714,0.0,0,3.70456,0.0,0.48676535,117.22850937918122,4.1173248,299.60291,-9.3168869,117.22850937918122,,,,,0.48373361896103895,118.09817591899916,0.48373047707132594,0.48373047707132594
2004,2004,145.3901,16.463808,5.8474898,0.0,0,3.648592,0.0,0.49304503,116.995807018964,4.0555577,299.1857,-9.3173075,116.995807018964,,,,,0.490098535,118.13146179955228,0.4900953922247478,0.4900953922247478
2007,2007,145.3907,16.545973,5.9054837,0.0,0,3.5926239,0.0,0.49944493,116.73926500052391,3.9962664,298.76849,-9.3163538,116.73926500052391,,,,,0.496463451038961,118.1643448349772,0.4964603073888869,0.4964603073888869
2010,2010,145.3913,16.682716,5.9622512,0.0,0,3.5387561,0.0,0.50568879,116.87445090182406,3.9405899,298.35132,-9.3161621,116.87445090182406,,,,,0.5028283670779221,118.19683497276982,0.5028252225634788,0.5028252225634788
2013,2013,145.3919,16.784481,6.0179768,0.0,0,3.4855118,0.0,0.51197684,116.76790857919244,3.887635,297.93411,-9.3157406,116.76790857919244,,,,,0.509193283116883,118.22894179272743,0.5091901377482683,0.5091901377482683
2016,2016,145.3925,16.883944,6.0765743,0.0,0,3.4322681,0.0,0.5184809,116.59289143509928,3.8320196,297.82166,-9.3164501,116.59289143509928,,,,,0.5155581991558441,118.26067452478823,0.5155550529430102,0.5155550529430102
2019,2019,145.3931,17.000141,6.1306658,0.0,0,3.3790238,0.0,0.5246557,116.58934464687285,3.7744374,297.77008,-9.3169127,116.58934464687285,,,,,0.5219231151948052,118.29204206619868,0.5219199681474677,0.5219199681474677
2022,2022,145.3937,17.126286,6.1878033,0.0,0,3.3257799,0.0,0.53134698,116.59666453082993,3.7169509,297.71848,-9.3147173,116.59666453082993,,,,,0.5282880312337662,118.32305299715985,0.5282848833614123,0.5282848833614123
2025,2025,145.3943,17.228601,6.2434397,0.0,0,3.2725358,0.0,0.5377779,116.45282903099007,3.6628618,297.6669,-9.3165312,116.45282903099007,,,,,0.5346529472727273,118.35371559598183,0.5346497985846241,0.5346497985846241
2028,2028,145.3949,17.342213,6.2986188,0.0,0,3.2192919,0.0,0.54433018,116.38162848674204,3.6063247,297.61533,-9.3176575,116.38162848674204,,,,,0.5410178633116883,118.38403785300385,0.5410147138168904,0.5410147138168904
2031,2031,145.3955,17.495571,6.3513665,0.0,0,3.1660478,0.0,0.5505299,116.60140682078443,3.5506649,297.56372,-9.3164721,116.60140682078443,,,,,0.5473827793506494,118.41402748397097,0.5473796290580057,0.5473796290580057
2034,2034,145.3961,17.599285,6.4036579,0.0,0,3.1139417,0.0,0.55665976,116.48534389995636,3.4960945,297.51215,-9.3159838,116.48534389995636,,,,,0.5537476953896103,118.44369194242933,0.553744544307772,0.553744544307772
2037,2037,145.3967,17.701675,6.4598465,0.0,0,3.0632861,0.0,0.5635618,116.29039952542284,3.4414494,297.46054,-9.3165636,116.29039952542284,,,,,0.5601126114285714,118.4730384316612,0.5601094595659976,0.5601094595659976
2040,2040,145.3973,17.850729,6.515379,0.0,0,3.012634,0.0,0.56996816,116.39973884152592,3.385812,297.40897,-9.3168049,116.39973884152592,,,,,0.5664775274675324,118.50207391570716,0.5664743748324972,0.5664743748324972
2043,2043,145.3979,17.998005,6.5678945,0.0,0,2.9619823,0.0,0.57613993,116.53055065821016,3.3305182,297.35739,-9.3154659,116.53055065821016,,,,,0.5728424435064935,118.5308051299835,0.5728392901070916,0.5728392901070916
2046,2046,145.3985,18.110058,6.6221848,0.0,0,2.9113297,0.0,0.58265835,116.39299819012795,3.275912,297.30579,-9.3156967,116.39299819012795,,,,,0.5792073595454545,118.55923859116253,0.5792042053896075,0.5792042053896075
2049,2049,145.3991,18.243259,6.6782203,0.0,0,2.860678,0.0,0.58917427,116.35157059628456,3.2241805,297.25421,-9.3160238,116.35157059628456,,,,,0.5855722755844156,118.58738060662333,0.5855691206798769,0.5855691206798769
2052,2052,145.3997,18.408461,6.7330785,0.0,0,2.8100257,0.0,0.59563667,116.5184286039576,3.1706839,297.20261,-9.3151398,116.5184286039576,,,,,0.5919371916233767,118.6152372834215,0.5919340359777375,0.5919340359777375
2055,2055,145.4003,18.518465,6.7874594,0.0,0,2.7593739,0.0,0.60198075,116.33025476907784,3.115792,297.15103,-9.3144417,116.33025476907784,,,,,0.5983021076623376,118.64281453657765,0.5982989512830319,0.5982989512830319
2058,2058,145.4009,18.659168,6.8413191,0.0,0,2.7090602,0.0,0.60845912,116.33134199331673,3.0631411,297.09946,-9.3163013,116.33134199331673,,,,,0.6046670237012987,118.67011809726063,0.6046638665956077,0.6046638665956077
2061,2061,145.4015,18.832317,6.895977,0.0,0,2.6607995,0.0,0.61492503,116.5065049598746,3.0081792,297.04785,-9.3154097,116.5065049598746,,,,,0.6110319397402597,118.69715352023483,0.611028781915317,0.611028781915317
2064,2064,145.4021,18.964592,6.9509711,0.0,0,2.6126194,0.0,0.62160653,116.40837071796254,2.9534571,296.93933,-9.3146114,116.40837071796254,,,,,0.6173968557792208,118.72392619111339,0.6173936972420166,0.6173936972420166
2067,2067,145.4027,19.084354,7.0048614,0.0,0,2.5644393,0.0,0.62807393,116.2396024056608,2.9006441,296.54648,-9.3154516,116.2396024056608,,,,,0.6237617718181818,118.75044133323799,0.6237586125755675,0.6237586125755675
2070,2070,145.4033,19.258989,7.0593696,0.0,0,2.5162592,0.0,0.63484156,116.38049364464364,2.848057,296.15363,-9.3156919,116.38049364464364,,,,,0.6301266878571429,118.77670401407913,0.6301235279158349,0.6301235279158349
2073,2073,145.4039,19.408175,7.1142402,0.0,0,2.4680793,0.0,0.6415627,116.34573607063908,2.7977238,295.76077,-9.3145142,116.34573607063908,,,,,0.6364916038961039,118.80271915138113,0.6364884432626879,0.6364884432626879
2076,2076,145.4045,19.517765,7.1638751,0.0,0,2.4198995,0.0,0.64805943,116.15082989729326,2.7471976,295.36789,-9.3150234,116.15082989729326,,,,,0.6428565199350649,118.8284915192166,0.6428533586159996,0.6428533586159996
2079,2079,145.4051,19.691189,7.2127824,0.0,0,2.3717194,0.0,0.65434653,116.33591430404834,2.6969476,294.97504,-9.3159418,116.33591430404834,,,,,0.6492214359740259,118.8540257534229,0.6492182739756466,0.6492182739756466
2082,2082,145.4057,19.870012,7.2642984,0.0,0,2.3235393,0.0,0.66117918,116.49201314986284,2.6468127,294.58218,-9.315587,116.49201314986284,,,,,0.655586352012987,118.87932635686239,0.6555831893415092,0.6555831893415092
2085,2085,145.4063,19.979452,7.316958,0.0,0,2.2771728,0.0,0.66818273,116.20802571726092,2.5951331,294.18933,-9.3155069,116.20802571726092,,,,,0.661951268051948,118.90439770459118,0.6619481047134708,0.6619481047134708
2088,2088,145.4069,20.148596,7.3646746,0.0,0,2.2313447,0.0,0.67483169,116.34587672063996,2.544971,293.79648,-9.3157272,116.34587672063996,,,,,0.6683161840909091,118.92924404867682,0.6683130200914185,0.6683130200914185
2091,2091,145.4075,20.337152,7.410419,0.0,0,2.1855166,0.0,0.68107462,116.61597192674446,2.4955158,293.40363,-9.3142681,116.61597192674446,,,,,0.6746811001298701,118.95386952268277,0.6746779354752422,0.6746779354752422
2094,2094,145.4081,20.458813,7.4596848,0.0,0,2.1396887,0.0,0.68782759,116.42645962763208,2.4459431,293.01074,-9.314352,116.42645962763208,,,,,0.6810460161688312,118.97827814617123,0.6810428508648351,0.6810428508648351
2097,2097,145.4087,20.614857,7.505754,0.0,0,2.0938606,0.0,0.69424766,116.47844566998448,2.3947897,292.61789,-9.3144779,116.47844566998448,,,,,0.6874109322077921,119.00247382880463,0.6874077662600928,0.6874077662600928
2100,2100,145.4093,20.808584,7.5537748,0.0,0,2.0480328,0.0,0.70070249,116.69328475108702,2.3481266,292.22504,-9.3153028,116.69328475108702,,,,,0.6937758482467532,119.0264603744293,0.6937726816609147,0.6937726816609147
2103,2103,145.4099,20.95722,7.5999227,0.0,0,2.0022047,0.0,0.70716482,116.67521293553034,2.2971528,291.83218,-9.3148308,116.67521293553034,,,,,0.7001407642857143,119.05024148466865,0.7001375970672019,0.7001375970672019
2106,2106,145.4105,21.10605,7.6474285,0.0,0,1.9563764,0.0,0.71356839,116.6207673841682,2.2533748,291.43933,-9.3140364,116.6207673841682,,,,,0.7065056803246753,119.07382076284738,0.7065025124788586,0.7065025124788586
2109,2109,145.4111,21.30599,7.6932774,0.0,0,1.9115282,0.0,0.71955824,116.86510148501766,2.2026865,291.04648,-9.3147802,116.86510148501766,,,,,0.7128705963636364,119.09720171727267,0.7128674278957916,0.7128674278957916
2112,2112,145.4117,21.478121,7.7418361,0.0,0,1.8679291,0.0,0.72598487,116.89047622939805,2.1561317,290.65359,-9.3151283,116.89047622939805,,,,,0.7192355124025974,119.12038776462906,0.71923234331791,0.71923234331791
2115,2115,145.4123,21.615974,7.7910886,0.0,0,1.8243332,0.0,0.73241735,116.70268649960308,2.108043,290.25687,-9.3136501,116.70268649960308,,,,,0.7256004284415585,119.1433822331602,0.725597258745125,0.725597258745125
2118,2118,145.4129,21.814165,7.8342261,0.0,0,1.7807372,0.0,0.73831195,116.94348604994502,2.0628397,289.85623,-9.3138227,116.94348604994502,,,,,0.7319653444805194,119.1661883656241,0.7319621741773504,0.7319621741773504
2121,2121,145.4135,22.004814,7.8807969,0.0,0,1.7371411,0.0,0.74468714,117.06237601570857,2.0171866,289.4556,-9.3146973,117.06237601570857,,,,,0.7383302605194805,119.18880932234916,0.7383270896145024,0.7383270896145024
2124,2124,145.4141,22.165545,7.9304786,0.0,0,1.6935452,0.0,0.75128388,116.94677273837684,1.9694046,289.05493,-9.3148422,116.94677273837684,,,,,0.7446951765584415,119.21124818397631,0.7446920050564989,0.7446920050564989
2127,2127,145.4147,22.359474,7.9776425,0.0,0,1.6499492,0.0,0.75788158,117.04028101209455,1.9233854,288.6543,-9.3135681,117.04028101209455,,,,,0.7510600925974026,119.23350795402229,0.75105692050326,0.75105692050326
2130,2130,145.4153,22.581501,8.022397,0.0,0,1.6063532,0.0,0.76415944,117.31141636137116,1.8783053,288.25366,-9.3130531,117.31141636137116,,,,,0.7574250086363636,119.25559156156406,0.7574218359547077,0.7574218359547077
2133,2133,145.4159,22.741468,8.067318,0.0,0,1.5630479,0.0,0.77066207,117.24161834883148,1.8346001,287.85303,-9.3139591,117.24161834883148,,,,,0.7637899246753247,119.2775018636728,0.7637867514107659,0.7637867514107659
2136,2136,145.4165,22.91404,8.1125813,0.0,0,1.5215064,0.0,0.77723467,117.21659580441994,1.7902395,287.45239,-9.3136902,117.21659580441994,,,,,0.7701548407142857,119.29924164779412,0.7701516668713607,0.7701516668713607
2139,2139,145.4171,23.140074,8.1580067,0.0,0,1.4800345,0.0,0.78394336,117.44571723584308,1.7475624,287.05176,-9.3132086,117.44571723584308,,,,,0.7765197567532467,119.3208136338211,0.7765165823364195,0.7765165823364195
2142,2142,145.4177,23.329546,8.2016068,0.0,0,1.4385624,0.0,0.79048699,117.51007011140813,1.7003193,286.65112,-9.3134356,117.51007011140813,,,,,0.7828846727922077,119.34222047653333,0.7828814978058718,0.7828814978058718
2145,2145,145.4183,23.518902,8.244647,0.0,0,1.3970906,0.0,0.79690272,117.57077656559716,1.6593269,286.25049,-9.3138056,117.57077656559716,,,,,0.7892495888311688,119.36346476750211,0.7892464132796487,0.7892464132796487
2148,2148,145.4189,23.736843,8.2870045,0.0,0,1.3556185,0.0,0.80345333,117.77310582438204,1.618763,285.84985,-9.3137465,117.77310582438204,,,,,0.7956145048701299,119.38454903713495,0.7956113287576828,0.7956113287576828
2151,2151,145.4195,23.960146,8.3289261,0.0,0,1.3141465,0.0,0.81015605,117.9946621279582,1.5739563,285.44922,-9.3126373,117.9946621279582,,,,,0.8019794209090909,119.40547575657205,0.8019762442399084,0.8019762442399084
2154,2154,145.4201,24.142883,8.3715963,0.0,0,1.2726746,0.0,0.81680989,117.98537325566652,1.5284599,285.04858,-9.3123341,117.98537325566652,,,,,0.808344336948052,119.42624733966522,0.8083411597262612,0.8083411597262612
2157,2157,145.4207,24.343658,8.4113903,0.0,0,1.2312026,0.0,0.8229658,118.11149462464942,1.4869902,284.64795,-9.312788,118.11149462464942,,,,,0.814709252987013,119.44686614442921,0.8147060752166786,0.8147060752166786
2160,2160,145.4213,24.598259,8.4515724,0.0,0,1.1912941,0.0,0.82930303,118.47425975123818,1.4432249,284.24731,-9.3125925,118.47425975123818,,,,,0.821074169025974,119.46733447516054,0.821070990711099,0.821070990711099
2163,2163,145.4219,24.793865,8.4938412,0.0,0,1.1518499,0.0,0.8358748,118.49114637076876,1.4021909,283.84668,-9.3128023,118.49114637076876,,,,,0.827439085064935,119.48765458376064,0.827435906209463,0.827435906209463
2166,2166,145.4225,24.98707,8.5347176,0.0,0,1.1124059,0.0,0.84213775,118.51267213778137,1.3591563,283.95078,-9.3128433,118.51267213778137,,,,,0.8338040011038961,119.50782867148834,0.8338008217117115,0.8338008217117115
2169,2169,145.4231,25.25576,8.5730009,0.0,0,1.0729618,0.0,0.84791434,118.9332917530213,1.3187071,284.15573,-9.3120356,118.9332917530213,,,,,0.8401689171428571,119.5278588903563,0.8401657372177876,0.8401657372177876
2172,2172,145.4237,25.45463,8.6141376,0.0,0,1.0335178,0.0,0.85412806,118.94508973458936,1.2823125,284.36069,-9.3115635,118.94508973458936,,,,,0.8465338331818182,119.54774734468467,0.8465306527276353,0.8465306527276353
2175,2175,145.4243,25.661581,8.6570005,0.0,0,0.99407381,0.0,0.86071217,118.94069314691924,1.2397858,284.56561,-9.3128109,118.94069314691924,,,,,0.8528987492207792,119.56749609251196,0.8528955682411997,0.8528955682411997
2178,2178,145.4249,25.923254,8.6962566,0.0,0,0.95462978,0.0,0.86672169,119.2546861485282,1.1977643,284.77057,-9.3126278,119.2546861485282,,,,,0.8592636652597402,119.58710714683868,0.8592604837584272,0.8592604837584272
2181,2181,145.4255,26.158842,8.7343092,0.0,0,0.91518587,0.0,0.87240875,119.45917145275784,1.1622334,284.97549,-9.3119974,119.45917145275784,,,,,0.8656285812987012,119.60658247710228,0.8656253992792656,0.8656253992792656
2184,2184,145.4261,26.354504,8.7754364,0.0,0,0.87658989,0.0,0.87862068,119.39517437522824,1.1198897,285.18045,-9.3120804,119.39517437522824,,,,,0.8719934973376623,119.62592401026511,0.8719903148036635,0.8719903148036635
2187,2187,145.4267,26.60099,8.8164787,0.0,0,0.83907515,0.0,0.88482463,119.54727760532224,1.0826416,285.38538,-9.312294,119.54727760532224,,,,,0.8783584133766233,119.64513363219484,0.8783552303315708,0.8783552303315708
2190,2190,145.4273,26.867025,8.8567877,0.0,0,0.80156314,0.0,0.89132869,119.78598104931324,1.0413457,285.59033,-9.3123226,119.78598104931324,,,,,0.8847233294155844,119.66421318864853,0.8847201458629385,0.8847201458629385
2193,2193,145.4279,27.073471,8.8959675,0.0,0,0.76405114,0.0,0.89752138,119.76912196032426,1.0029526,285.79529,-9.3115377,119.76912196032426,,,,,0.8910882454545455,119.68316448658858,0.8910850613977183,0.8910850613977183
2196,2196,145.4285,27.326963,8.9337368,0.0,0,0.72653913,0.0,0.90358943,119.97845995440927,0.96273899,286.00021,-9.312068,119.97845995440927,,,,,0.8974531614935065,119.70198929516563,0.8974499769358631,0.8974499769358631
2199,2199,145.4291,27.6014,8.9706736,0.0,0,0.68902713,0.0,0.90979266,120.28238355270142,0.92625773,286.20517,-9.3117228,120.28238355270142,,,,,0.9038180775324675,119.72068934682174,0.903814892477327,0.903814892477327
2202,2202,145.4297,27.824667,9.0088959,0.0,0,0.65151519,0.0,0.91641819,120.31540172528314,0.88687372,286.4101,-9.31073,120.31540172528314,,,,,0.9101829935714285,119.73926633820452,0.9101798080220649,0.9101798080220649
2205,2205,145.4303,28.067116,9.0479803,0.0,0,0.61400312,0.0,0.923159,120.39418826574774,0.85050988,286.61505,-9.3109474,120.39418826574774,,,,,0.9165479096103896,119.7577219312655,0.9165447235700324,0.9165447235700324
2208,2208,145.4309,28.367775,9.0818872,0.0,0,0.57673913,0.0,0.92929095,120.83367551450604,0.81309479,286.81998,-9.3113604,120.83367551450604,,,,,0.9229128256493506,119.7760577541608,0.9229096391211863,0.9229096391211863
2211,2211,145.4315,28.613094,9.1158895,0.0,0,0.54098004,0.0,0.93560529,121.01862375122434,0.77488047,287.02493,-9.3110609,121.01862375122434,,,,,0.9292777416883117,119.79427540219565,0.9292745546754841,0.9292745546754841
2214,2214,145.4321,28.856306,9.1532822,0.0,0,0.50527996,0.0,0.94210631,121.09345347078164,0.73606956,287.24408,-9.3099651,121.09345347078164,,,,,0.9356426577272727,119.81237643864,0.9356394702328843,0.9356394702328843
2217,2217,145.4327,29.141888,9.1871176,0.0,0,0.46957999,0.0,0.9483878,121.42020953706064,0.70053548,287.53418,-9.3101158,121.42020953706064,,,,,0.9420075737662338,119.83036239561935,0.9420043857933461,0.9420043857933461
2220,2220,145.4333,29.405602,9.2211237,0.0,0,0.43387997,0.0,0.95452726,121.63495223488442,0.66510969,287.82428,-9.311451,121.63495223488442,,,,,0.9483724898051947,119.84823477499344,0.9483693013568294,0.9483693013568294
2223,2223,145.4339,29.648695,9.2551441,0.0,0,0.39817998,0.0,0.96046227,121.74875626670412,0.6284954,288.11438,-9.31001,121.74875626670412,,,,,0.9547374058441558,119.8659950490296,0.9547342169232952,0.9547342169232952
2226,2226,145.4345,29.934786,9.2881193,0.0,0,0.36247995,0.0,0.96631825,122.05084556483595,0.5934431,288.40448,-9.3083372,122.05084556483595,,,,,0.9611023218831168,119.88364466130919,0.9610991324927052,0.9610991324927052
2229,2229,145.4351,30.22558,9.322854,0.0,0,0.32677999,0.0,0.97239572,122.30824903379391,0.5569061,288.69458,-9.3091059,122.30824903379391,,,,,0.9674672379220779,119.90118502743627,0.9674640480650214,0.9674640480650214
2232,2232,145.4357,30.478161,9.3560038,0.0,0,0.29107997,0.0,0.97811514,122.43702394163942,0.52265799,288.98468,-9.3099823,122.43702394163942,,,,,0.973832153961039,119.91861753565986,0.9738289636402072,0.9738289636402072
2235,2235,145.4363,30.737118,9.3900795,0.0,0,0.25673065,0.0,0.98374611,122.55124043822212,0.4882437,289.27475,-9.3111095,122.55124043822212,,,,,0.98019707,119.93594354772455,0.9801938792182261,0.9801938792182261