File: examples/hot axisymmetric compression example/data/12 fitted data ramberg/testID_0135.csv
level_0,index,Time(sec),Force(kN),Jaw(mm),PowAngle(deg),Power(W),Pram,PTemp,Strain,Stress(MPa),Stroke(mm),TC1(C),wedge(mm),uncorrected stress,sampled strain,sampled stress,fitting strain,fitting stress,model strain,ramberg stress,ramberg plastic strain,ramberg accumulated plastic strain
1873,1873,155.3448,1.1591333,0.038278293,0.0,0,9.0337067,0.0,0.0023505834,14.092158177686304,10.0417,331.97104,-9.3067589,14.092158177686304,0.0023505834,14.092158177686304,0.0,14.092158177686304,0.0,0.0,0.0,0.0
1876,1876,155.3454,5.035481,0.10520047,0.0,0,8.9459143,0.0,0.0064311218,60.92745650203855,9.9510784,332.13556,-9.3061476,60.92745650203855,0.14845818,111.59930492162256,0.142109505,111.36023082887692,0.006219234354485776,104.60382990848814,0.006212470574200097,0.006212470574200097
1879,1879,155.346,6.5432987,0.18562315,0.0,0,8.8581219,0.0,0.011464315,78.71642507575301,9.8470488,332.30008,-9.3023567,78.71642507575301,0.2839182,111.43317644500152,0.28421901,111.43002783471589,0.012438468708971553,105.22588799613531,0.012431664705835205,0.012431664705835205
1882,1882,155.3466,7.3206873,0.34721956,0.0,0,8.7703304,0.0,0.022551104,87.04526488026514,9.7235603,332.4646,-9.302289,87.04526488026514,0.42431304,109.12546891793473,0.426328515,109.08108075750106,0.018657703063457327,105.59676681202282,0.018650875078954087,0.018650875078954087
1885,1885,155.3472,8.1628437,0.4735606,0.0,0,8.6858492,0.0,0.031053908,96.16656462116896,9.5806141,332.62912,-9.3017092,96.16656462116896,0.56576598,107.09772080629423,0.56843802,107.07991547552045,0.024876937417943105,105.86311321070315,0.02487009221123565,0.02487009221123565
1888,1888,155.3478,8.7680159,0.54077864,0.0,0,8.6023531,0.0,0.036245137,102.786151398192,9.4595575,332.79364,-9.3000517,102.786151398192,0.7085644,106.97728511740554,0.710547525,106.98568057030063,0.031096171772428884,106.0715636325908,0.03108931308712456,0.03108931308712456
1891,1891,155.3484,8.7617273,0.64329618,0.0,0,8.518857,0.0,0.043202978,101.935126871665,9.3645163,332.95816,-9.2998018,101.935126871665,0.85338998,108.33986373855382,0.85265703,108.33056771017534,0.037315406126914655,106.24309548013358,0.03730853635020259,0.03730853635020259
1894,1894,155.349,9.2199793,0.72554564,0.0,0,8.4353609,0.0,0.048816726,106.6101500333204,9.2660284,333.11536,-9.2992067,106.6101500333204,,,,,0.04353464048140043,106.3889828616205,0.04352776127147549,0.04352776127147549
1897,1897,155.3496,9.1771364,0.86437494,0.0,0,8.3518648,0.0,0.058741193,105.01186367277536,9.1544733,333.26529,-9.299921,105.01186367277536,,,,,0.04975387483588621,106.51599663776837,0.04974698741313316,0.04974698741313316
1900,1900,155.3502,9.5109367,0.97748214,0.0,0,8.2683697,0.0,0.066916391,107.90003319974434,9.0386744,333.41522,-9.2996569,107.90003319974434,,,,,0.05597310919037199,106.62852679278548,0.05596621449131515,0.05596621449131515
1903,1903,155.3508,9.5786724,1.0511856,0.0,0,8.1848736,0.0,0.072599664,108.0571218576843,8.9315138,333.56516,-9.2991743,108.0571218576843,,,,,0.06219234354485777,106.72958426650683,0.06218544231133131,0.06218544231133131
1906,1906,155.3514,9.5498028,1.1380879,0.0,0,8.1013775,0.0,0.07867045,107.01267325017923,8.8438473,333.71509,-9.299654,107.01267325017923,,,,,0.06841157789934355,106.82132518602545,0.06840467073376447,0.06840467073376447
1909,1909,155.352,10.003962,1.2111076,0.0,0,8.0196619,0.0,0.084020741,111.4691104780904,8.7600842,333.86499,-9.3004379,111.4691104780904,,,,,0.07463081225382931,106.90534723717025,0.07462389965530677,0.07462389965530677
1912,1912,155.3526,9.9610615,1.3298308,0.0,0,7.9402156,0.0,0.092641607,109.96653124824,8.6634588,334.01492,-9.299036,109.96653124824,,,,,0.08085004660831509,106.98286764629552,0.08084312899725128,0.08084312899725128
1915,1915,155.3532,9.8699818,1.4291692,0.0,0,7.8607755,0.0,0.099952213,108.11144665491292,8.5600929,334.16486,-9.299037,108.11144665491292,,,,,0.08706928096280087,107.05483538391329,0.08706235869823666,0.08706235869823666
1918,1918,155.3538,10.16041,1.507689,0.0,0,7.7813354,0.0,0.10600219,110.60125440311676,8.4619703,334.31479,-9.3005457,110.60125440311676,,,,,0.09328851531728664,107.12200478450983,0.09328158870948693,0.09328158870948693
1921,1921,155.3544,10.249875,1.5867324,0.0,0,7.7018952,0.0,0.11155573,110.87287247423782,8.3797235,334.46472,-9.3010616,110.87287247423782,,,,,0.09950774967177242,107.18498549563785,0.09950081899158174,0.09950081899158174
1924,1924,155.355,10.262007,1.6632041,0.0,0,7.6224551,0.0,0.11729763,110.32379778103947,8.2977314,334.61462,-9.3005953,110.32379778103947,,,,,0.1057269840262582,107.24427734660573,0.10572004951220165,0.10572004951220165
1927,1927,155.3556,10.417029,1.7593325,0.0,0,7.543015,0.0,0.12426782,111.12216081127774,8.2115355,334.76456,-9.2988167,111.12216081127774,,,,,0.11194621838074398,107.30029529471399,0.11193928024451515,0.11193928024451515
1930,1930,155.3562,10.541996,1.8464801,0.0,0,7.4635754,0.0,0.13084002,111.6585321050166,8.1220493,334.91449,-9.299777,111.6585321050166,,,,,0.11816545273522976,107.3533876582584,0.11815851116599965,0.11815851116599965
1933,1933,155.3568,10.536559,1.9307352,0.0,0,7.3846664,0.0,0.13738585,110.83096451321532,8.0327435,335.06442,-9.3000803,110.83096451321532,,,,,0.12438468708971553,107.40384969567268,0.12437774225756347,0.12437774225756347
1936,1936,155.3574,10.620845,2.000381,0.0,0,7.3089881,0.0,0.14244166,111.07588855825686,7.9507747,335.21436,-9.299202,111.07588855825686,,,,,0.1306039214442013,107.45193388834764,0.1305969735028809,0.1305969735028809
1939,1939,155.358,10.73982,2.0777459,0.0,0,7.2334356,0.0,0.14845818,111.59930492162256,7.8749065,335.36426,-9.2997808,111.59930492162256,,,,,0.1368231557986871,107.49785784397321,0.1368162048878813,0.1368162048878813
1942,1942,155.3586,10.873198,2.1633999,0.0,0,7.1578832,0.0,0.15501551,112.17712558359769,7.793961,335.51419,-9.2992554,112.17712558359769,,,,,0.14304239015317285,107.5418104524533,0.1430354364003508,0.1430354364003508
1945,1945,155.3592,10.863918,2.2433038,0.0,0,7.0823312,0.0,0.16123544,111.32802494956148,7.7141223,335.55133,-9.2991695,111.32802494956148,,,,,0.14926162450765862,107.58395673892893,0.14925466802961873,0.14925466802961873
1948,1948,155.3598,10.938725,2.3221536,0.0,0,7.0067792,0.0,0.167594,111.3459512930292,7.6334338,335.56592,-9.2990103,111.3459512930292,,,,,0.1554808588621444,107.6244417316195,0.1554738997663075,0.1554738997663075
1951,1951,155.3604,11.110624,2.3897243,0.0,0,6.9312277,0.0,0.1728743,112.44397794027331,7.5550556,335.58051,-9.2990942,112.44397794027331,,,,,0.16170009321663018,107.6633935754906,0.16169313160213106,0.16169313160213106
1954,1954,155.361,11.077086,2.4698379,0.0,0,6.8556757,0.0,0.17938784,111.334053018843,7.4776125,335.59509,-9.2992182,111.334053018843,,,,,0.16791932757111597,107.70092606159218,0.1679123635297316,0.1679123635297316
1957,1957,155.3616,11.214992,2.5475187,0.0,0,6.7801232,0.0,0.18563634,111.96359271865292,7.4023719,335.60968,-9.2998705,111.96359271865292,,,,,0.17413856192560173,107.7371406992196,0.17413159554254545,0.17413159554254545
1960,1960,155.3622,11.323764,2.6204758,0.0,0,6.7074022,0.0,0.19173405,112.3319752574224,7.3231673,335.62427,-9.2990208,112.3319752574224,,,,,0.18035779628008752,107.77212842650304,0.18035082763469246,0.18035082763469246
1963,1963,155.3628,11.322593,2.6988747,0.0,0,6.6355219,0.0,0.19816615,111.54926718518398,7.2487154,335.63885,-9.2991953,111.54926718518398,,,,,0.1865770306345733,107.80597103284335,0.18657005980088404,0.18657005980088404
1966,1966,155.3634,11.440473,2.7649434,0.0,0,6.5636415,0.0,0.20353675,112.05392845640148,7.1712313,335.65344,-9.2999163,112.05392845640148,,,,,0.19279626498905908,107.83874234941587,0.19278929203634623,0.19278929203634623
1969,1969,155.364,11.547348,2.8412855,0.0,0,6.4917622,0.0,0.20990214,112.3347193417017,7.0978374,335.66803,-9.2997026,112.3347193417017,,,,,0.19901549934354484,107.87050925195268,0.19900852433675473,0.19900852433675473
1972,1972,155.3646,11.580754,2.9150717,0.0,0,6.4198818,0.0,0.21603476,111.91708507674464,7.0251117,335.68262,-9.2990608,111.91708507674464,,,,,0.2052347336980306,107.90133251005199,0.20522775669818014,0.20522775669818014
1975,1975,155.3652,11.671983,2.9861882,0.0,0,6.3480015,0.0,0.22197007,112.07723130396973,6.9491901,335.6972,-9.2997465,112.07723130396973,,,,,0.2114539680525164,107.93126751055233,0.21144698911704113,0.21144698911704113
1978,1978,155.3658,11.752444,3.0630379,0.0,0,6.2761221,0.0,0.22829302,112.0646753273809,6.8778858,335.71179,-9.2992163,112.0646753273809,,,,,0.21767320240700216,107.96036487668694,0.21766622159006432,0.21766622159006432
1981,1981,155.3664,11.834893,3.1339464,0.0,0,6.2042422,0.0,0.23417592,112.12119975781268,6.7989225,335.72638,-9.2998438,112.12119975781268,,,,,0.22389243676148796,107.98867100055539,0.22388545411425,0.22388545411425
1984,1984,155.367,11.891304,3.2085242,0.0,0,6.1339049,0.0,0.24047473,111.88442234379887,6.7232947,335.74097,-9.3002682,111.88442234379887,,,,,0.23011167111597372,108.016228503141,0.2301046866868422,0.2301046866868422
1987,1987,155.3676,11.99191,3.2784057,0.0,0,6.065536,0.0,0.24627861,112.1021462948776,6.6499748,335.75555,-9.2990656,112.1021462948776,,,,,0.2363309054704595,108.0430766332874,0.23632391930530308,0.23632391930530308
1990,1990,155.3682,12.082607,3.3530359,0.0,0,5.9971719,0.0,0.25263929,112.16557991340808,6.5776553,335.77014,-9.2990103,112.16557991340808,,,,,0.24255013982494528,108.06925161529999,0.24254315196729032,0.24254315196729032
1993,1993,155.3688,12.126412,3.4289088,0.0,0,5.9288077,0.0,0.25892854,111.77172602369336,6.5041752,335.75851,-9.2995682,111.77172602369336,,,,,0.24876937417943107,108.09478695270711,0.2487623846706376,0.2487623846706376
1996,1996,155.3694,12.204626,3.4986577,0.0,0,5.8604436,0.0,0.26483378,111.751876829355,6.4332318,335.61591,-9.300355,111.751876829355,,,,,0.2549886085339168,108.11971369481726,0.2549816174133372,0.2549816174133372
1999,1999,155.37,12.309864,3.5725951,0.0,0,5.792079,0.0,0.27131981,111.92333910871558,6.3611064,335.4733,-9.2988977,111.92333910871558,,,,,0.2612078428884026,108.14406067137554,0.26120085019352496,0.26120085019352496
2002,2002,155.3706,12.368779,3.6456797,0.0,0,5.7237153,0.0,0.27745619,111.67210632632758,6.2851334,335.33069,-9.2986155,111.67210632632758,,,,,0.2674270772428884,108.1678546997391,0.2674200830094669,0.2674200830094669
2005,2005,155.3712,12.429432,3.7183619,0.0,0,5.6553516,0.0,0.2839182,111.43317644500152,6.2149382,335.18805,-9.3002558,111.43317644500152,,,,,0.2736463115973742,108.19112076839875,0.2736393158595472,0.2736393158595472
2008,2008,155.3718,12.549323,3.7886684,0.0,0,5.5874419,0.0,0.29020765,111.7397318411788,6.1454268,335.04544,-9.3009138,111.7397318411788,,,,,0.2798655459518599,108.21388220007346,0.27985854874225774,0.27985854874225774
2011,2011,155.3724,12.588557,3.8565321,0.0,0,5.5222936,0.0,0.29646945,111.34502586365114,6.0756316,334.90283,-9.2994833,111.34502586365114,,,,,0.2860847803063457,108.23616079691269,0.28607778165618886,0.28607778165618886
2014,2014,155.373,12.657077,3.9296618,0.0,0,5.4572535,0.0,0.3030988,111.14479592908936,6.0054808,334.76022,-9.2984905,111.14479592908936,,,,,0.2923040146608315,108.2579769702412,0.2922970146000207,0.2922970146000207
2017,2017,155.3736,12.761629,3.9981651,0.0,0,5.3922133,0.0,0.30936274,111.30124350979592,5.934021,334.61761,-9.299674,111.30124350979592,,,,,0.29852324901531724,108.27934985669374,0.2985162475725159,0.2985162475725159
2020,2020,155.3742,12.819632,4.0658169,0.0,0,5.3271737,0.0,0.3157438,111.05139284933024,5.8651133,334.47501,-9.3007841,111.05139284933024,,,,,0.30474248336980303,108.30029742252016,0.3047354805725127,0.3047354805725127
2023,2023,155.3748,12.897276,4.1323857,0.0,0,5.2621331,0.0,0.32195321,110.97573395356632,5.7938738,334.3324,-9.3005972,110.97573395356632,,,,,0.3109617177242888,108.32083655732968,0.3109547135989191,0.3109547135989191
2026,2026,155.3754,12.968908,4.1990499,0.0,0,5.1970935,0.0,0.32829797,110.83847925661716,5.7234111,334.18976,-9.2983484,110.83847925661716,,,,,0.3171809520787746,108.34098315869804,0.31717394665070703,0.31717394665070703
2029,2029,155.376,13.073525,4.2693133,0.0,0,5.1320534,0.0,0.33492976,110.93173327345778,5.6551867,334.04715,-9.2993155,110.93173327345778,,,,,0.32340018643326035,108.36075220856303,0.32339317972690773,0.32339317972690773
2032,2032,155.3766,13.129013,4.3339806,0.0,0,5.0670133,0.0,0.34104559,110.6622359380773,5.5878911,333.90454,-9.3005772,110.6622359380773,,,,,0.32961942078774614,108.38015784241459,0.3296124128266073,0.3296124128266073
2035,2035,155.3772,13.203218,4.4010959,0.0,0,5.0044241,0.0,0.34740645,110.51487300801192,5.5214028,333.76193,-9.2999992,110.51487300801192,,,,,0.33583865514223193,108.39921341207173,0.3358316459489423,0.3358316459489423
2038,2038,155.3778,13.306314,4.4653192,0.0,0,4.942564,0.0,0.35347098,110.63239233247316,5.4524474,333.61932,-9.2995806,110.63239233247316,,,,,0.3420578894967177,108.4179315426618,0.3420508790930965,0.3420508790930965
2041,2041,155.3784,13.373243,4.5321574,0.0,0,4.8807039,0.0,0.35974675,110.4090473580636,5.3846421,333.47672,-9.2991552,110.4090473580636,,,,,0.34827712385120346,108.43632418463382,0.348270112258297,0.348270112258297
2044,2044,155.379,13.423159,4.6017432,0.0,0,4.8188443,0.0,0.36628771,110.00610726720224,5.3162141,333.19882,-9.3003283,110.00610726720224,,,,,0.35449635820568925,108.45440266106428,0.35448934544381183,0.35448934544381183
2047,2047,155.3796,13.550257,4.6665959,0.0,0,4.7569842,0.0,0.37233898,110.28077031350182,5.2496953,332.78564,-9.3005276,110.28077031350182,,,,,0.36071559256017505,108.47217771096699,0.36070857864894645,0.36070857864894645
2050,2050,155.3802,13.627867,4.7348475,0.0,0,4.6951241,0.0,0.37884751,110.10051180511316,5.1839461,332.3725,-9.2986488,110.10051180511316,,,,,0.3669348269146608,108.48965952887743,0.36692781187304174,0.36692781187304174
2053,2053,155.3808,13.678047,4.8007107,0.0,0,4.6332641,0.0,0.3851231,109.71940493822189,5.1203671,331.95932,-9.298687,109.71940493822189,,,,,0.3731540612691466,108.50685780117465,0.3731470451154713,0.3731470451154713
2056,2056,155.3814,13.797959,4.867177,0.0,0,4.571404,0.0,0.39142606,109.88046822326284,5.0521331,331.54617,-9.2989187,109.88046822326284,,,,,0.37937329562363237,108.5237817393587,0.37936627837563963,0.37936627837563963
2059,2059,155.382,13.879668,4.9367285,0.0,0,4.5108657,0.0,0.39828721,109.68804952229311,4.9896722,331.133,-9.2990322,109.68804952229311,,,,,0.38559252997811816,108.54044011071103,0.3855855116529798,0.3855855116529798
2062,2062,155.3826,13.943447,5.0022488,0.0,0,4.4520135,0.0,0.40480086,109.39403861442416,4.9196129,330.71985,-9.2990437,109.39403861442416,,,,,0.3918117643326039,108.55684126647547,0.3918047449469516,0.3918047449469516
2065,2065,155.3832,14.035857,5.067492,0.0,0,4.3931656,0.0,0.41138682,109.31896625317482,4.8551917,330.30667,-9.2990484,109.31896625317482,,,,,0.3980309986870897,108.57299316783195,0.39802397825704056,0.39802397825704056
2068,2068,155.3838,14.166578,5.1301508,0.0,0,4.3343177,0.0,0.41776314,109.56141072051965,4.7913637,329.89352,-9.2987299,109.56141072051965,,,,,0.4042502330415755,108.58890340988674,0.4042432115827554,0.4042432115827554
2071,2071,155.3844,14.213331,5.1943502,0.0,0,4.2754698,0.0,0.42431304,109.12546891793473,4.7258554,329.48035,-9.298501,109.12546891793473,,,,,0.4104694673960612,108.60457924386526,0.4104624449236272,0.4104624449236272
2074,2074,155.385,14.296603,5.2599535,0.0,0,4.2166214,0.0,0.43109354,108.94491931621738,4.6601415,329.06717,-9.2996197,108.94491931621738,,,,,0.416688701750547,108.62002759757927,0.41668167827920816,0.41668167827920816
2077,2077,155.3856,14.406914,5.3233943,0.0,0,4.1577735,0.0,0.43774655,108.98640150546748,4.5986776,328.65402,-9.2989922,108.98640150546748,,,,,0.4229079361050328,108.63525509446426,0.42290091164906995,0.42290091164906995
2080,2080,155.3862,14.476885,5.3842916,0.0,0,4.0989256,0.0,0.44425079,108.74477353870653,4.5360746,328.24084,-9.2997112,108.74477353870653,,,,,0.4291271704595186,108.6502680711908,0.42912014503280277,0.42912014503280277
2083,2083,155.3868,14.551303,5.4448647,0.0,0,4.0404716,0.0,0.45066559,108.5328502236154,4.4760036,327.8277,-9.3003511,108.5328502236154,,,,,0.43534640481400433,108.66507259402816,0.4353393784300144,0.4353393784300144
2086,2086,155.3874,14.673254,5.5055194,0.0,0,3.9844093,0.0,0.45724797,108.6638698374742,4.4131999,327.41452,-9.2998905,108.6638698374742,,,,,0.4415656391684901,108.67967447404389,0.44155861184032913,0.44155861184032913
2089,2089,155.388,14.771003,5.5671039,0.0,0,3.9284413,0.0,0.46390623,108.59184525732238,4.3551521,327.00137,-9.2989826,108.59184525732238,,,,,0.4477848735229759,108.69407928130899,0.4477778452633868,0.4477778452633868
2092,2092,155.3886,14.813074,5.6270056,0.0,0,3.8724735,0.0,0.47033474,108.12463043986894,4.2892404,326.5882,-9.2992401,108.12463043986894,,,,,0.45400410787746165,108.70829235801025,0.45399707869884187,0.45399707869884187
2095,2095,155.3892,14.933197,5.6867352,0.0,0,3.8165054,0.0,0.47672167,108.22074650209218,4.2320499,326.19308,-9.2994862,108.22074650209218,,,,,0.46022334223194744,108.7223188307905,0.46021631214636294,0.46021631214636294
2098,2098,155.3898,15.036221,5.7437754,0.0,0,3.7605371,0.0,0.48285884,108.21654384853832,4.1723542,325.80157,-9.2990446,108.21654384853832,,,,,0.46644257658643323,108.73616362222228,0.4664355456056318,0.4664355456056318
2101,2101,155.3904,15.108071,5.8020015,0.0,0,3.7045693,0.0,0.48907685,107.96343039252302,4.1134057,325.41003,-9.2986803,107.96343039252302,,,,,0.472661810940919,108.74983146152667,0.4726547790763424,0.4726547790763424
2104,2104,155.391,15.20761,5.8610253,0.0,0,3.6486013,0.0,0.49546212,107.88868663421488,4.0540786,325.01852,-9.2989073,107.88868663421488,,,,,0.47888104529540476,108.76332689457502,0.478874012558201,0.478874012558201
2107,2107,155.3916,15.329807,5.9210601,0.0,0,3.5926332,0.0,0.50187719,107.9495086974934,3.9953015,324.62701,-9.2990274,107.9495086974934,,,,,0.48510027964989055,108.77665429329087,0.48509324605092485,0.48509324605092485
2110,2110,155.3922,15.400765,5.9775362,0.0,0,3.538765,0.0,0.50796753,107.68722797176396,3.9390416,324.23547,-9.2993078,107.68722797176396,,,,,0.49131951400437635,108.7898178644487,0.491312479554242,0.491312479554242
2113,2113,155.3928,15.484628,6.0357661,0.0,0,3.4855206,0.0,0.51419485,107.48359452122769,3.8815224,323.84396,-9.2983294,107.48359452122769,,,,,0.49753874835886214,108.80282165788492,0.49753171306789046,0.49753171306789046
2116,2116,155.3934,15.601207,6.094552,0.0,0,3.432277,0.0,0.52052432,107.48908159484408,3.8235867,323.45245,-9.298687,107.48908159484408,,,,,0.5037579827133479,108.81566957424396,0.5037509465916181,0.5037509465916181
2119,2119,155.394,15.704908,6.1524725,0.0,0,3.3790326,0.0,0.52707326,107.40626070865578,3.7678261,323.06091,-9.2994566,107.40626070865578,,,,,0.5099772170678336,108.8283653722436,0.5099701801251818,0.5099701801251818
2122,2122,155.3946,15.782007,6.2104144,0.0,0,3.3257887,0.0,0.53344232,107.1318894031759,3.7143695,322.6694,-9.2985296,107.1318894031759,,,,,0.5161964514223194,108.84091267547781,0.5161894136683474,0.5161894136683474
2125,2125,155.3952,15.910109,6.2657266,0.0,0,3.2725446,0.0,0.53956282,107.22985745834902,3.6564522,322.27789,-9.298645,107.22985745834902,,,,,0.5224156857768052,108.85331497887688,0.5224086472208888,0.5224086472208888
2128,2128,155.3958,16.027884,6.3227782,0.0,0,3.2193007,0.0,0.54602277,107.2217143177094,3.6016009,321.88635,-9.2989092,107.2217143177094,,,,,0.528634920131291,108.86557565467838,0.5286278807825879,0.5286278807825879
2131,2131,155.3964,16.116499,6.3793349,0.0,0,3.1660566,0.0,0.5527848,107.01502582375949,3.5472233,321.49484,-9.299489,107.01502582375949,,,,,0.5348541544857768,108.87769795819122,0.5348471143532344,0.5348471143532344
2134,2134,155.397,16.22463,6.4347997,0.0,0,3.11395,0.0,0.55931878,106.94356517455228,3.4919317,321.10333,-9.2982264,106.94356517455228,,,,,0.5410733888402626,108.88968503309833,0.5410663479326249,0.5410663479326249
2137,2137,155.3976,16.364223,6.4881454,0.0,0,3.0632944,0.0,0.56576598,107.09772080629423,3.438653,320.71179,-9.298336,107.09772080629423,,,,,0.5472926231947484,108.90153991655075,0.547285581520563,0.547285581520563
2140,2140,155.3982,16.444641,6.5441842,0.0,0,3.0126424,0.0,0.57264704,106.81530143058448,3.3851559,320.32028,-9.2989388,106.81530143058448,,,,,0.553511857549234,108.91326554393008,0.5535048151168587,0.5535048151168587
2143,2143,155.3988,16.554806,6.5964613,0.0,0,2.9619906,0.0,0.579153,106.77124981783886,3.3279808,319.8793,-9.2986498,106.77124981783886,,,,,0.5597310919037198,108.92486475335845,0.5597240487213289,0.5597240487213289
2146,2146,155.3994,16.702253,6.6474009,0.0,0,2.9113381,0.0,0.58545423,106.97531558088536,3.271745,319.19098,-9.2982988,106.97531558088536,,,,,0.5659503262582056,108.936340289952,0.5659432823337959,0.5659432823337959
2149,2149,155.4,16.821007,6.6990104,0.0,0,2.8606863,0.0,0.59184533,106.97368630038798,3.2186007,318.50269,-9.2985563,106.97368630038798,,,,,0.5721695606126914,108.94769480986292,0.572162515954088,0.572162515954088
2152,2152,155.4006,16.908846,6.7533393,0.0,0,2.810034,0.0,0.59853095,106.72558121666547,3.1675386,317.81439,-9.2989902,106.72558121666547,,,,,0.5783887949671772,108.95893088409882,0.5783817495820388,0.5783817495820388
2155,2155,155.4012,17.057444,6.8050747,0.0,0,2.7593822,0.0,0.60480642,106.88841306622804,3.1151087,317.12607,-9.2987871,106.88841306622804,,,,,0.584608029321663,108.97005100212314,0.5846009832174874,0.5846009832174874
2158,2158,155.4018,17.191942,6.854495,0.0,0,2.7090683,0.0,0.61103457,106.98486223574284,3.0598712,316.43777,-9.2981672,106.98486223574284,,,,,0.5908272636761488,108.9810575752818,0.5908202168602781,0.5908202168602781
2161,2161,155.4024,17.275969,6.906002,0.0,0,2.6608074,0.0,0.61720014,106.72595050067964,3.0062704,315.74948,-9.2982159,106.72595050067964,,,,,0.5970464980306345,108.9919529400326,0.5970394505102594,0.5970394505102594
2164,2164,155.403,17.433531,6.9577346,0.0,0,2.6126273,0.0,0.62345147,106.9067971872448,2.9543869,315.06116,-9.2984161,106.9067971872448,,,,,0.6032657323851203,109.00273936104652,0.6032586841672852,0.6032586841672852
2167,2167,155.4036,17.584597,7.0116396,0.0,0,2.5644474,0.0,0.62993997,107.00006863273296,2.9037111,314.37286,-9.2976418,107.00006863273296,,,,,0.6094849667396061,109.01341903411523,0.6094779178312135,0.6094779178312135
2170,2170,155.4042,17.692129,7.0640726,0.0,0,2.5162673,0.0,0.63634616,106.83893940657228,2.8539729,313.68457,-9.2975616,106.83893940657228,,,,,0.6157042010940919,109.02399408892248,0.6156971515019065,0.6156971515019065
2173,2173,155.4048,17.833265,7.11689,0.0,0,2.4680872,0.0,0.64280814,106.86311036275391,2.8042059,312.99625,-9.2978039,106.86311036275391,,,,,0.6219234354485776,109.03446659167453,0.6219163851792305,0.6219163851792305
2176,2176,155.4054,17.996161,7.1694236,0.0,0,2.4199073,0.0,0.64922911,107.00790644118786,2.7514412,312.30795,-9.2982178,107.00790644118786,,,,,0.6281426698030634,109.04483854762903,0.6281356188630561,0.6281356188630561
2179,2179,155.406,18.099159,7.2210426,0.0,0,2.3717272,0.0,0.65576899,106.79867603784544,2.7008929,311.61963,-9.2981176,106.79867603784544,,,,,0.6343619041575492,109.05511190344833,0.6343548525532572,0.6343548525532572
2182,2182,155.4066,18.230543,7.2710638,0.0,0,2.3235474,0.0,0.66205138,106.77179185463386,2.6488342,310.93134,-9.298274,106.77179185463386,,,,,0.640581138512035,109.06528854948367,0.6405740862497117,0.6405740862497117
2185,2185,155.4072,18.410078,7.3229365,0.0,0,2.2771804,0.0,0.66873616,106.9831155427242,2.6012104,310.24304,-9.2979784,106.9831155427242,,,,,0.6468003728665207,109.07537032191738,0.6467933199523006,0.6467933199523006
2188,2188,155.4078,18.520248,7.3720222,0.0,0,2.2313523,0.0,0.67516512,106.82341170938508,2.5484123,309.55472,-9.2972078,106.82341170938508,,,,,0.6530196072210065,109.08535900483646,0.6530125536609089,0.6530125536609089
2191,2191,155.4084,18.661201,7.4226117,0.0,0,2.1855242,0.0,0.68181831,106.8055909960837,2.4984539,308.86642,-9.2969141,106.8055909960837,,,,,0.6592388415754923,109.09525633218134,0.6592317873754244,0.6592317873754244
2194,2194,155.409,18.824783,7.4742832,0.0,0,2.1396964,0.0,0.68881553,106.88566256031685,2.4481802,308.67691,-9.2982121,106.88566256031685,,,,,0.6654580759299781,109.10506398959858,0.6654510210957381,0.6654510210957381
2197,2197,155.4096,18.983519,7.5239382,0.0,0,2.0938683,0.0,0.69576418,106.95712083315232,2.399771,308.98611,-9.2979527,106.95712083315232,,,,,0.6716773102844639,109.11478361625758,0.6716702548217438,0.6716702548217438
2200,2200,155.4102,19.108616,7.5694718,0.0,0,2.0480404,0.0,0.70194995,106.89585835238331,2.3493211,309.29535,-9.2974224,106.89585835238331,,,,,0.6778965446389497,109.1244168065183,0.6778894885533385,0.6778894885533385
2203,2203,155.4108,19.269325,7.6176548,0.0,0,2.0022123,0.0,0.7085644,106.97728511740554,2.3008835,309.60458,-9.297266,106.97728511740554,,,,,0.6841157789934355,109.13396511156377,0.6841087222904222,0.6841087222904222
2206,2206,155.4114,19.44445,7.6657629,0.0,0,1.9563841,0.0,0.71533453,107.1256541745957,2.2530749,309.91382,-9.2974968,107.1256541745957,,,,,0.6903350133479211,109.14343004096368,0.6903279560328968,0.6903279560328968
2209,2209,155.412,19.563211,7.7156596,0.0,0,1.9115355,0.0,0.722413,106.9200954695822,2.2068613,310.22305,-9.2983131,106.9200954695822,,,,,0.6965542477024069,109.15281306413026,0.6965471897806675,0.6965471897806675
2212,2212,155.4126,19.718729,7.7599859,0.0,0,1.8679364,0.0,0.72872561,107.00001555161752,2.1584723,310.53229,-9.2972012,107.00001555161752,,,,,0.7027734820568927,109.16211561174522,0.702766423533642,0.702766423533642
2215,2215,155.4132,19.896124,7.8049712,0.0,0,1.8243403,0.0,0.73508471,107.17398702823624,2.1113904,310.84152,-9.2959728,107.17398702823624,,,,,0.7089927164113785,109.17133907711501,0.70898565729173,0.70898565729173
2218,2218,155.4138,20.035231,7.8515983,0.0,0,1.7807443,0.0,0.74146932,107.10006973226044,2.0636063,311.15076,-9.2980366,107.10006973226044,,,,,0.7152119507658643,109.1804848174516,0.7152048910548439,0.7152048910548439
2221,2221,155.4144,20.183193,7.8981905,0.0,0,1.7371484,0.0,0.74815768,107.06219576047197,2.0155904,311.45999,-9.2981501,107.06219576047197,,,,,0.7214311851203501,109.18955415514827,0.7214241248228979,0.7214241248228979
2224,2224,155.415,20.383091,7.9458451,0.0,0,1.6935524,0.0,0.75465739,107.2663254868226,1.9695709,311.76923,-9.2959156,107.2663254868226,,,,,0.7276504194748359,109.19854837891201,0.7276433585958089,0.7276433585958089
2227,2227,155.4156,20.545795,7.9911013,0.0,0,1.6499563,0.0,0.76081157,107.30281318410938,1.9217697,312.07846,-9.2970161,107.30281318410938,,,,,0.7338696538293216,109.20746874495329,0.7338625923734954,0.7338625923734954
2230,2230,155.4162,20.691137,8.0374117,0.0,0,1.6063604,0.0,0.76726997,107.21699090691232,1.8785838,312.3877,-9.2961273,107.21699090691232,,,,,0.7400888881838074,109.21631647802556,0.7400818261558786,0.7400818261558786
2233,2233,155.4168,20.873987,8.083622,0.0,0,1.5630548,0.0,0.7737267,107.3138532626028,1.830716,312.6969,-9.2965002,107.3138532626028,,,,,0.7463081225382932,109.2250927724976,0.7463010599428811,0.7463010599428811
2236,2236,155.4174,21.069689,8.1307926,0.0,0,1.5215132,0.0,0.78013891,107.44340113646786,1.7875166,313.00613,-9.2964592,107.44340113646786,,,,,0.7525273568927789,109.23379879335926,0.7525202937344275,0.7525202937344275
2239,2239,155.418,21.211546,8.1768026,0.0,0,1.4800413,0.0,0.78666872,107.3059247773162,1.7430874,313.31537,-9.2961731,107.3059247773162,,,,,0.7587465912472647,109.24243567716145,0.7587395275304444,0.7587395275304444
2242,2242,155.4186,21.383205,8.222167,0.0,0,1.4385693,0.0,0.79308569,107.3185552966406,1.6988813,313.6246,-9.2964935,107.3185552966406,,,,,0.7649658256017505,109.25100453293358,0.76495876133086,0.76495876133086
2245,2245,155.4192,21.613348,8.2676983,0.0,0,1.3970973,0.0,0.79962891,107.60533461679366,1.657537,314.44785,-9.2968969,107.60533461679366,,,,,0.7711850599562363,109.25950644308833,0.7711779951356045,0.7711779951356045
2248,2248,155.4198,21.769255,8.3118029,0.0,0,1.3556253,0.0,0.80622101,107.53430923769211,1.6156923,315.37384,-9.2977753,107.53430923769211,,,,,0.777404294310722,109.26794246426948,0.7773972289446093,0.7773972289446093
2251,2251,155.4204,21.946598,8.3556967,0.0,0,1.3141534,0.0,0.81279022,107.56018406495888,1.5702448,316.29987,-9.2959394,107.56018406495888,,,,,0.7836235286652078,109.27631362812488,0.7836164627578078,0.7836164627578078
2254,2254,155.421,22.186573,8.4009171,0.0,0,1.2726814,0.0,0.81988859,107.85077292096764,1.5283859,317.22589,-9.2966776,107.85077292096764,,,,,0.7898427630196936,109.28462094214984,0.7898356965751351,0.7898356965751351
2257,2257,155.4216,22.357359,8.4421787,0.0,0,1.2312094,0.0,0.82639235,107.86666218339154,1.4837654,318.15192,-9.2968893,107.86666218339154,,,,,0.7960619973741794,109.29286539038797,0.7960549303965272,0.7960549303965272
2260,2260,155.4222,22.541872,8.4847879,0.0,0,1.1913006,0.0,0.83314502,107.90893314607234,1.4408987,319.07794,-9.2966461,107.90893314607234,,,,,0.8022812317286652,109.30104793418676,0.8022741642219222,0.8022741642219222
2263,2263,155.4228,22.778797,8.5272522,0.0,0,1.1518564,0.0,0.8399902,108.18907304940372,1.3957857,320.00394,-9.2950516,108.18907304940372,,,,,0.808500466083151,109.30916951288343,0.8084933980512592,0.8084933980512592
2266,2266,155.4234,22.986305,8.5692635,0.0,0,1.1124125,0.0,0.84702361,108.32193838020898,1.354113,320.92996,-9.2958622,108.32193838020898,,,,,0.8147197004376368,109.31723104446111,0.8147126318844788,0.8147126318844788
2269,2269,155.424,23.1658,8.6097345,0.0,0,1.0729684,0.0,0.85338998,108.33986373855382,1.3092707,321.85599,-9.2958345,108.33986373855382,,,,,0.8209389347921224,109.32523342621111,0.8209318657215232,0.8209318657215232
2272,2272,155.4246,23.388901,8.6473103,0.0,0,1.0335244,0.0,0.85957015,108.60706207394573,1.2681223,322.78201,-9.2951212,108.60706207394573,,,,,0.8271581691466082,109.33317753534254,0.8271510995623356,0.8271510995623356
2275,2275,155.4252,23.624323,8.6863337,0.0,0,0.99408036,0.0,0.8660416,108.8859830715383,1.2268815,323.70804,-9.2946701,108.8859830715383,,,,,0.833377403501094,109.34106422958786,0.8333703334068604,0.8333703334068604
2278,2278,155.4258,23.803156,8.7291775,0.0,0,0.95463634,0.0,0.87278235,108.8094019952846,1.1839637,324.63403,-9.2954369,108.8094019952846,,,,,0.8395966378555798,109.34889434775371,0.8395895672550435,0.8395895672550435
2281,2281,155.4264,24.030979,8.7694855,0.0,0,0.91519243,0.0,0.87926608,108.99512716492984,1.14059,325.56006,-9.2951803,108.99512716492984,,,,,0.8458158722100656,109.35666871030632,0.8458088011068319,0.8458088011068319
2284,2284,155.427,24.274147,8.8075399,0.0,0,0.87659609,0.0,0.88533211,109.28194027072432,1.1016883,326.48608,-9.2951021,109.28194027072432,,,,,0.8520351065645514,109.36438811987757,0.8520280349621735,0.8520280349621735
2287,2287,155.4276,24.464502,8.848321,0.0,0,0.83908135,0.0,0.89136308,109.2574112732713,1.0641881,327.41211,-9.2949114,109.2574112732713,,,,,0.8582543409190372,109.3720533617972,0.8582472688210177,0.8582472688210177
2290,2290,155.4282,24.68215,8.8883047,0.0,0,0.8015694,0.0,0.89767623,109.35739284149656,1.0232382,328.33813,-9.2939939,109.35739284149656,,,,,0.8644735752735229,109.37966520458507,0.8644665026833145,0.8644665026833145
2293,2293,155.4288,24.930958,8.9285526,0.0,0,0.7640574,0.0,0.90396065,109.57306764827447,0.98172408,329.15976,-9.2945127,109.57306764827447,,,,,0.8706928096280087,109.38722440041956,0.8706857365490157,0.8706857365490157
2296,2296,155.4294,25.147011,8.9674568,0.0,0,0.72654539,0.0,0.91022372,109.65804887243324,0.94189668,329.45938,-9.2942667,109.65804887243324,,,,,0.8769120439824944,109.39473168560973,0.8769049704180736,0.8769049704180736
2299,2299,155.43,25.352745,9.0076914,0.0,0,0.68903339,0.0,0.91646546,109.65366381363442,0.90498447,329.75903,-9.294528,109.65366381363442,,,,,0.8831312783369802,109.40218778102174,0.8831242042904413,0.8831242042904413
2302,2302,155.4306,25.577824,9.0463753,0.0,0,0.65152138,0.0,0.92278445,109.75262951229294,0.86421251,330.05869,-9.2947245,109.75262951229294,,,,,0.889350512691466,109.40959339255105,0.8893434381660734,0.8893434381660734
2305,2305,155.4312,25.818495,9.0841246,0.0,0,0.61400938,0.0,0.92906946,109.92385406764528,0.82519126,330.35834,-9.2939873,109.92385406764528,,,,,0.8955697470459518,109.41694921146534,0.8955626720449251,0.8955626720449251
2308,2308,155.4318,26.028986,9.1227932,0.0,0,0.57674509,0.0,0.93563354,109.93033471841105,0.78967071,330.65799,-9.2935305,109.93033471841105,,,,,0.9017889814004376,109.4242559148915,0.9017819059269527,0.9017819059269527
2311,2311,155.4324,26.275074,9.1583643,0.0,0,0.54098594,0.0,0.94181228,110.14345178577572,0.74853909,330.95764,-9.29459,110.14345178577572,,,,,0.9080082157549233,109.43151416611553,0.9080011398121132,0.9080011398121132
2314,2314,155.433,26.527681,9.1952162,0.0,0,0.50528592,0.0,0.94813037,110.33814340570164,0.7128132,331.25729,-9.294116,110.33814340570164,,,,,0.9142274501094091,109.43872461504164,0.9142203737003647,0.9142203737003647
2317,2317,155.4336,26.739105,9.2316523,0.0,0,0.4695859,0.0,0.95477909,110.35621818999184,0.67456758,331.55695,-9.2926464,110.35621818999184,,,,,0.9204466844638949,109.44588789848079,0.920439607591666,0.920439607591666
2320,2320,155.4342,26.958889,9.26577,0.0,0,0.4338859,0.0,0.96095687,110.4501338237651,0.64105415,331.85657,-9.2925882,110.4501338237651,,,,,0.9266659188183807,109.45300464052096,0.9266588414859767,0.9266588414859767
2323,2323,155.4348,27.242138,9.2999039,0.0,0,0.39818591,0.0,0.96721929,110.78847768416723,0.60362548,332.15622,-9.2936678,110.78847768416723,,,,,0.9328851531728665,109.46007545289896,0.9328780753832572,0.9328780753832572
2326,2326,155.4354,27.483419,9.3341208,0.0,0,0.36248589,0.0,0.97357059,110.93827886383184,0.57016671,332.45587,-9.2931805,110.93827886383184,,,,,0.9391043875273523,109.46710093528436,0.9390973092834688,0.9390973092834688
2329,2329,155.436,27.705269,9.3663092,0.0,0,0.32678592,0.0,0.97954702,111.04530748109936,0.53535354,332.75552,-9.2922373,111.04530748109936,,,,,0.945323621881838,109.47408167561377,0.9453165431865734,0.9453165431865734
2330,2330,155.4362,27.782387,9.3851385,0.0,0,0.31488591,0.0,0.98076451,110.8918748543449,0.52509475,332.85541,-9.2919397,110.8918748543449,,,,,0.9473967,109.47639874634257,0.9473896211549114,0.9473896211549114