File: examples/hot axisymmetric compression example/data/12 fitted data ramberg/testID_0143.csv
level_0,index,Time(sec),Force(kN),Jaw(mm),PowAngle(deg),Power(W),Pram,PTemp,Strain,Stress(MPa),Stroke(mm),TC1(C),wedge(mm),uncorrected stress,sampled strain,sampled stress,fitting strain,fitting stress,model strain,ramberg stress,ramberg plastic strain,ramberg accumulated plastic strain
2104,2104,178.7032,0.13591053,0.026852572,0.0,0,9.0922346,0.0,0.0015671256,1.6536743440229518,10.11375,395.25552,-9.2656384,1.6536743440229518,0.0015671256,1.6536743440229518,0.0,1.6536743440229518,0.0,0.0,0.0,0.0
2106,2106,178.7036,2.2440124,0.051866949,0.0,0,9.0337067,0.0,0.0033286866,27.255205694818816,10.033341,395.2543,-9.2641487,27.255205694818816,0.10935435,79.3042820680317,0.09549168300000001,79.88018947489442,0.0042066820704845815,73.45758540650515,0.004203454753538423,0.004203454753538423
2108,2108,178.704,4.9732537,0.11809945,0.0,0,8.9751787,0.0,0.0074258014,60.11905713277755,9.9830065,395.25311,-9.263319,60.11905713277755,0.1954546,80.56775173952352,0.19098336600000002,80.51747291787922,0.008413364140969163,74.08220300775932,0.008410109381806408,0.008410109381806408
2110,2110,178.7044,5.604177,0.17081104,0.0,0,8.9166508,0.0,0.010920446,67.49050113319419,9.9122725,395.25189,-9.2599459,67.49050113319419,0.28267893,79.66273309699415,0.28647504900000004,79.63998683239464,0.012620046211453744,74.4548091453745,0.012616775082053722,0.012616775082053722
2112,2112,178.7048,5.8561554,0.31763175,0.0,0,8.8581219,0.0,0.020450082,69.78140427552226,9.8205853,395.2507,-9.2590733,69.78140427552226,0.37835464,78.66893279460383,0.38196673200000003,78.60454013253519,0.016826728281938326,74.72248119653743,0.01682344539252003,0.01682344539252003
2114,2114,178.7052,5.8871808,0.41789082,0.0,0,8.7995939,0.0,0.027756009,69.64050085460596,9.7238588,395.24948,-9.2605333,69.64050085460596,0.47522196,76.86094121096632,0.477458415,76.85145141188175,0.021033410352422906,74.9320167208885,0.021030118257181346,0.021030118257181346
2116,2116,178.7056,6.4134865,0.49276227,0.0,0,8.7416534,0.0,0.032731459,75.45081353739069,9.6203413,395.24826,-9.2606897,75.45081353739069,0.56916451,76.15892623136298,0.5729500980000001,76.1435839475592,0.02524009242290749,75.10447201712819,0.025236792750941255,0.025236792750941255
2118,2118,178.706,6.7114391,0.59732461,0.0,0,8.6858492,0.0,0.040242348,78.34880530586723,9.5340824,395.24707,-9.2595167,78.34880530586723,0.66384506,76.05638286780085,0.6684417810000001,76.08807883780783,0.029446774493392072,75.25116607446367,0.029443468376506438,0.029443468376506438
2120,2120,178.7064,6.8731894,0.60030901,0.0,0,8.6301851,0.0,0.040619753,80.21931440763056,9.4509554,395.24585,-9.2578926,80.21931440763056,0.76219779,76.68166694928674,0.7639334640000001,76.69832163502102,0.03365345656387665,75.37889787337441,0.03365014483516759,0.03365014483516759
2122,2122,178.7068,6.2518263,0.68237853,0.0,0,8.574522,0.0,0.045977995,72.5231315131405,9.3916607,395.24466,-9.2592793,72.5231315131405,0.85812902,77.7414344791016,0.8594251470000001,77.77233446702495,0.03786013863436123,75.49207625197104,0.03785682193322492,0.03785682193322492
2124,2124,178.7072,7.0778928,0.74948776,0.0,0,8.518857,0.0,0.051024765,81.69463283457303,9.326642,395.24344,-9.260911,81.69463283457303,0.95491683,80.20947750262945,0.95491683,80.20947750262945,0.04206682070484581,75.59372544402295,0.04206349953781046,0.04206349953781046
2126,2126,178.7076,7.0941296,0.79130012,0.0,0,8.4631929,0.0,0.053485643,81.62527861026584,9.2591267,395.24222,-9.2589741,81.62527861026584,,,,,0.0462735027753304,75.68601132248463,0.046270177553767826,0.046270177553767826
2128,2128,178.708,7.1585369,0.900231,0.0,0,8.4075298,0.0,0.061469458,81.69126683140601,9.185936,395.24103,-9.2590914,81.69126683140601,,,,,0.05048018484581498,75.77053894301417,0.05047685591057981,0.05047685591057981
2130,2130,178.7084,6.8214841,0.97625262,0.0,0,8.3518648,0.0,0.066667072,77.39589256154163,9.1054316,395.26666,-9.2593565,77.39589256154163,,,,,0.05468686691629956,75.84853124826712,0.05468353455451712,0.05468353455451712
2132,2132,178.7088,7.1740437,1.0523185,0.0,0,8.2962017,0.0,0.072113097,80.92343710921745,9.0266905,395.31015,-9.258297,80.92343710921745,,,,,0.058893548986784144,75.92094173686912,0.05889021344368836,0.05889021344368836
2134,2134,178.7092,7.1496048,1.1083504,0.0,0,8.2405376,0.0,0.076708786,80.30081210443947,8.949151,395.35367,-9.2584534,80.30081210443947,,,,,0.06310023105726872,75.98852839482585,0.06309689254479182,0.06309689254479182
2136,2136,178.7096,7.2617078,1.1630371,0.0,0,8.1848736,0.0,0.079915278,81.2159313978457,8.8888388,395.39719,-9.2580919,81.2159313978457,,,,,0.0673069131277533,76.0519038596415,0.06730357183091165,0.06730357183091165
2138,2138,178.71,7.1148467,1.2274517,0.0,0,8.1292095,0.0,0.084980257,79.17641779119002,8.8234692,395.44067,-9.2598982,79.17641779119002,,,,,0.07151359519823788,76.11157044151521,0.07151025127997913,0.07151025127997913
2140,2140,178.7104,7.2655821,1.2751551,0.0,0,8.0735455,0.0,0.088628411,80.55358940326512,8.7691669,395.48419,-9.2594395,80.55358940326512,,,,,0.07572027726872246,76.1679451801995,0.07571693087367186,0.07571693087367186
2142,2142,178.7108,7.6482916,1.3441589,0.0,0,8.0196619,0.0,0.092894413,84.33943342877214,8.7064438,395.52771,-9.2586184,84.33943342877214,,,,,0.07992695933920704,76.22137815997145,0.07992361059660907,0.07992361059660907
2144,2144,178.7112,7.3557901,1.4258395,0.0,0,7.9666953,0.0,0.099500515,80.59331994262789,8.6438341,395.57123,-9.2570295,80.59331994262789,,,,,0.08413364140969162,76.27216615055873,0.08413029043575236,0.08413029043575236
2146,2146,178.7116,7.3580623,1.494807,0.0,0,7.9137359,0.0,0.10447919,80.17842031549114,8.5735121,395.61472,-9.2575378,80.17842031549114,,,,,0.08834032348017622,76.32056293725948,0.08833697037995185,0.08833697037995185
2148,2148,178.712,7.3181362,1.5640289,0.0,0,7.8607755,0.0,0.10935435,79.3042820680317,8.5058327,395.65823,-9.2593222,79.3042820680317,,,,,0.0925470055506608,76.36678726095022,0.09254365041959724,0.09254365041959724
2150,2150,178.7124,7.5281801,1.6037377,0.0,0,7.8078156,0.0,0.1130789,81.32133121870272,8.4457493,395.70175,-9.2594328,81.32133121870272,,,,,0.09675368762114538,76.41102900302327,0.09675033054634623,0.09675033054634623
2152,2152,178.7128,7.5635109,1.6441867,0.0,0,7.7548552,0.0,0.1154943,81.43776619541936,8.3890371,395.74527,-9.2587252,81.43776619541936,,,,,0.10096036969162996,76.45345406121594,0.10095701075291016,0.10095701075291016
2154,2154,178.7132,7.3882747,1.7157056,0.0,0,7.7018952,0.0,0.12094569,79.0928445828736,8.3350897,395.78876,-9.258873,79.0928445828736,,,,,0.10516705176211454,76.49420823608756,0.10516369103288341,0.10516369103288341
2156,2156,178.7136,7.5584836,1.750376,0.0,0,7.6489348,0.0,0.12409171,80.68773969954785,8.2813921,395.83228,-9.2578487,80.68773969954785,,,,,0.10937373383259912,76.53342035956223,0.1093703713806058,0.1093703713806058
2158,2158,178.714,7.7334609,1.8038816,0.0,0,7.5959754,0.0,0.12739657,82.19683206392506,8.2262077,395.87579,-9.2571058,82.19683206392506,,,,,0.1135804159030837,76.57120483666081,0.11357705179105103,0.11357705179105103
2160,2160,178.7144,7.6887465,1.8742211,0.0,0,7.543015,0.0,0.13318361,81.25254703939179,8.1692057,395.91928,-9.2585278,81.25254703939179,,,,,0.11778709797356829,76.60766372765646,0.11778373225973512,0.11778373225973512
2162,2162,178.7148,7.676743,1.9225612,0.0,0,7.4900556,0.0,0.13683695,80.8038299298713,8.1125555,395.9628,-9.2580624,80.8038299298713,,,,,0.12199378004405287,76.64288846716485,0.12199041278264094,0.12199041278264094
2164,2164,178.7152,7.6174173,1.9849712,0.0,0,7.4370952,0.0,0.14124145,79.76699730742018,8.0539808,396.00632,-9.2586689,79.76699730742018,,,,,0.12620046211453745,76.676961293609,0.1261970933561554,0.1261970933561554
2166,2166,178.7156,7.7422872,2.0267885,0.0,0,7.3846664,0.0,0.14515767,80.79372142133776,7.9994335,396.04984,-9.2594652,80.79372142133776,,,,,0.13040714418502203,76.70995644569281,0.13040377397701688,0.13040377397701688
2168,2168,178.716,7.7852144,2.0764158,0.0,0,7.3341722,0.0,0.14848624,80.90647776981228,7.9431882,396.09332,-9.2586317,80.90647776981228,,,,,0.1346138262555066,76.74194117012657,0.1346104546422709,0.1346104546422709
2170,2170,178.7164,7.7431321,2.133065,0.0,0,7.2838039,0.0,0.15283884,80.08853946920257,7.8980451,396.13684,-9.2590103,80.08853946920257,,,,,0.1388205083259912,76.77297657531552,0.13881713534923273,0.13881713534923273
2172,2172,178.7168,7.7921095,2.1677539,0.0,0,7.2334356,0.0,0.15607327,80.36056393107951,7.8498445,396.18036,-9.2592506,80.36056393107951,,,,,0.14302719039647577,76.80311835831039,0.14302381609545534,0.14302381609545534
2174,2174,178.7172,7.9278631,2.2236152,0.0,0,7.1830673,0.0,0.15974365,81.37626612704801,7.796525,396.22388,-9.2589159,81.37626612704801,,,,,0.14723387246696035,76.83241742722497,0.1472304968787021,0.1472304968787021
2176,2176,178.7176,7.9301043,2.2795722,0.0,0,7.1326995,0.0,0.16439046,81.0141272846861,7.7478247,396.26736,-9.2585306,81.0141272846861,,,,,0.15144055453744493,76.86092043637726,0.1514371776969233,0.1514371776969233
2178,2178,178.718,7.8831692,2.3275468,0.0,0,7.0823312,0.0,0.16850804,80.20635550089804,7.693768,396.31088,-9.2587757,80.20635550089804,,,,,0.1556472366079295,76.88867024863248,0.15564385854823576,0.15564385854823576
2180,2180,178.7184,7.9270511,2.3872886,0.0,0,7.0319633,0.0,0.17266183,80.24170407160409,7.6422544,396.30881,-9.258666,80.24170407160409,,,,,0.1598539186784141,76.91570633654666,0.1598505394309053,0.1598505394309053
2182,2182,178.7188,8.0068913,2.4250073,0.0,0,6.981595,0.0,0.17616057,80.78768060631751,7.5933323,396.28223,-9.2590828,80.78768060631751,,,,,0.16406060074889867,76.94206513170974,0.1640572203433313,0.1640572203433313
2184,2184,178.7192,8.0318403,2.472069,0.0,0,6.9312277,0.0,0.17981607,80.71120618984284,7.5462508,396.25562,-9.2594185,80.71120618984284,,,,,0.16826728281938325,76.9677803301095,0.16826390128403337,0.16826390128403337
2186,2186,178.7196,7.9742489,2.5290058,0.0,0,6.8808594,0.0,0.18388546,79.73820888380797,7.4991331,396.22903,-9.2600021,79.73820888380797,,,,,0.17247396488986785,76.99288316004835,0.17247058225163953,0.17247058225163953
2188,2188,178.72,8.0424042,2.5625873,0.0,0,6.830492,0.0,0.18722649,80.18517628181806,7.4483905,396.20242,-9.259716,80.18517628181806,,,,,0.17668064696035243,77.01740261813153,0.17667726324487576,0.17667726324487576
2190,2190,178.7204,8.1801758,2.6130958,0.0,0,6.7801232,0.0,0.19096272,81.19995078999247,7.4017735,396.17584,-9.2587461,81.19995078999247,,,,,0.180887329030837,77.04136567745599,0.18088394426255705,0.18088394426255705
2192,2192,178.7208,8.1582155,2.6715469,0.0,0,6.7313671,0.0,0.1954546,80.56775173952352,7.352489,396.14923,-9.2585402,80.56775173952352,,,,,0.1850940111013216,77.06479747210648,0.18509062530357917,0.18509062530357917
2194,2194,178.7212,8.1505136,2.7112846,0.0,0,6.6834416,0.0,0.19934496,80.2103275883326,7.3035665,396.12265,-9.2589865,80.2103275883326,,,,,0.18930069317180617,77.0877214611896,0.18929730636691142,0.18929730636691142
2196,2196,178.7216,8.1411629,2.760375,0.0,0,6.6355219,0.0,0.20284297,79.77108778654002,7.2527447,396.09604,-9.2594976,79.77108778654002,,,,,0.19350737524229075,77.11015957471572,0.1935039874515903,0.1935039874515903
2198,2198,178.722,8.2489758,2.8083301,0.0,0,6.5876017,0.0,0.20681663,80.48377582682684,7.2041125,396.06946,-9.2592506,80.48377582682684,,,,,0.19771405731277533,77.1321323441306,0.19771066855671385,0.19771066855671385
2200,2200,178.7224,8.303277,2.850575,0.0,0,6.5396819,0.0,0.21059974,80.70877259812114,7.1600103,396.04285,-9.2593784,80.70877259812114,,,,,0.2019207393832599,77.15365901902923,0.2019173496814363,0.2019173496814363
2202,2202,178.7228,8.2694073,2.8978937,0.0,0,6.4917622,0.0,0.21405278,80.03949608770397,7.1096253,396.01627,-9.258749,80.03949608770397,,,,,0.2061274214537445,77.17475767201435,0.20612403082496364,0.20612403082496364
2204,2204,178.7232,8.3296375,2.9447079,0.0,0,6.4438419,0.0,0.21826966,80.28354508561563,7.0634685,395.98965,-9.259366,80.28354508561563,,,,,0.21033410352422907,77.19544529301355,0.21033071198654946,0.21033071198654946
2206,2206,178.7236,8.3862495,2.9907782,0.0,0,6.3959212,0.0,0.2221853,80.49335508211746,7.014719,395.96307,-9.2594271,80.49335508211746,,,,,0.21454078559471365,77.215737874234,0.21453739316549109,0.21453739316549109
2208,2208,178.724,8.4216385,3.0419867,0.0,0,6.3480015,0.0,0.22600317,80.4581239358159,6.9654341,395.93646,-9.2588844,80.4581239358159,,,,,0.21874746766519823,77.2356504871154,0.21874407436112642,0.21874407436112642
2210,2210,178.7244,8.457181,3.0908265,0.0,0,6.3000817,0.0,0.23059489,80.43857699534962,6.9184642,395.90988,-9.2594185,80.43857699534962,,,,,0.2229541497356828,77.25519735176171,0.2229507555728307,0.2229507555728307
2212,2212,178.7248,8.4615965,3.1362555,0.0,0,6.252162,0.0,0.23414764,80.14633324484836,6.8706841,395.88327,-9.25879,80.14633324484836,,,,,0.2271608318061674,77.27439190016021,0.2271574368000138,0.2271574368000138
2214,2214,178.7252,8.5042715,3.1808672,0.0,0,6.2042422,0.0,0.23778807,80.22062532269955,6.8235297,395.85669,-9.2582531,80.22062532269955,,,,,0.23136751387665197,77.29324683344761,0.23136411804211768,0.23136411804211768
2216,2216,178.7256,8.5238829,3.226397,0.0,0,6.1568027,0.0,0.24222152,80.06810335228938,6.7746878,395.83008,-9.2595692,80.06810335228938,,,,,0.23557419594713658,77.31177417417577,0.2355707992986142,0.2355707992986142
2218,2218,178.726,8.5547056,3.2739201,0.0,0,6.1111121,0.0,0.24567169,80.00402955430569,6.7321658,395.8035,-9.2602167,80.00402955430569,,,,,0.23978087801762116,77.32998531395437,0.23977748056900278,0.23977748056900278
2220,2220,178.7264,8.6149483,3.319783,0.0,0,6.065536,0.0,0.24970233,80.22373265134034,6.6821585,395.77689,-9.259264,80.22373265134034,,,,,0.24398756008810574,77.34789105691155,0.24398416185280877,0.24398416185280877
2222,2222,178.7268,8.6645889,3.3643241,0.0,0,6.0199599,0.0,0.25399768,80.35025157350842,6.6347942,395.75031,-9.2586832,80.35025157350842,,,,,0.24819424215859032,77.36550165958141,0.24819084314958162,0.24819084314958162
2224,2224,178.7272,8.6637316,3.4172273,0.0,0,5.9743834,0.0,0.25769547,79.94352263813897,6.5877752,395.72369,-9.2585096,79.94352263813897,,,,,0.2524009242290749,77.38282686735995,0.25239752445889313,0.25239752445889313
2226,2226,178.7276,8.6633205,3.4609272,0.0,0,5.9288077,0.0,0.26201352,79.61030298770358,6.5413198,395.69711,-9.2595701,79.61030298770358,,,,,0.2566076062995595,77.39987594802633,0.2566042057803361,0.2566042057803361
2228,2228,178.728,8.7478552,3.5040331,0.0,0,5.8832321,0.0,0.26585999,80.05896992246507,6.4936275,395.6705,-9.2594357,80.05896992246507,,,,,0.26081428837004406,77.41665772252466,0.260810887113523,0.260810887113523
2230,2230,178.7284,8.8125906,3.5587184,0.0,0,5.8376555,0.0,0.26988918,80.23198685422221,6.4482689,395.42978,-9.2589912,80.23198685422221,,,,,0.26502097044052864,77.43318059333207,0.2650175684580847,0.2650175684580847
2232,2232,178.7288,8.8285923,3.601383,0.0,0,5.792079,0.0,0.27439368,80.04980527486681,6.4015245,395.09729,-9.2595949,80.04980527486681,,,,,0.2692276525110132,77.44945257059551,0.2692242498136693,0.2692242498136693
2234,2234,178.7292,8.8281221,3.6478341,0.0,0,5.7465038,0.0,0.2781921,79.68856035198883,6.3548412,394.7648,-9.2602301,79.68856035198883,,,,,0.2734343345814978,77.46548129623193,0.273430931179941,0.273430931179941
2236,2236,178.7296,8.872159,3.7026391,0.0,0,5.7009277,0.0,0.28267893,79.66273309699415,6.305769,394.43231,-9.2598305,79.66273309699415,,,,,0.2776410166519824,77.48127406621707,0.2776376125565793,0.2776376125565793
2238,2238,178.73,8.9514685,3.7417226,0.0,0,5.6553516,0.0,0.28685182,80.07022164808197,6.256577,394.09982,-9.2591629,80.07022164808197,,,,,0.28184769872246695,77.49683785124982,0.28184429394327787,0.28184429394327787
2240,2240,178.7304,9.0033321,3.7887454,0.0,0,5.6097755,0.0,0.29046336,80.16546694042354,6.2072148,393.76733,-9.2586985,80.16546694042354,,,,,0.28605438079295153,77.51217931583726,0.286050975339744,0.286050975339744
2242,2242,178.7308,9.0003233,3.845155,0.0,0,5.5656581,0.0,0.29557553,79.69650364836677,6.1604524,393.43484,-9.2589397,79.69650364836677,,,,,0.2902610628634361,77.52730483603196,0.29025765674569753,0.29025765674569753
2244,2244,178.7312,9.0131102,3.8857987,0.0,0,5.5222936,0.0,0.29979196,79.49064931496913,6.1123128,393.10236,-9.2599154,79.49064931496913,,,,,0.2944677449339207,77.54222051584814,0.29446433816087025,0.29446433816087025
2246,2246,178.7316,9.0775051,3.9363463,0.0,0,5.4789333,0.0,0.30362156,79.6588643731296,6.064846,392.76987,-9.2592659,79.6588643731296,,,,,0.2986744270044053,77.55693220261304,0.2986710195850053,0.2986710195850053
2248,2248,178.732,9.1368561,3.9877903,0.0,0,5.4355736,0.0,0.30865377,79.77018216458076,6.0163336,392.43738,-9.2600155,79.77018216458076,,,,,0.30288110907488985,77.57144550117425,0.30287770101785644,0.30287770101785644
2250,2250,178.7324,9.168293,4.0288234,0.0,0,5.3922133,0.0,0.31260329,79.7168462215949,5.9679255,392.10489,-9.2600403,79.7168462215949,,,,,0.30708779114537443,77.58576578719673,0.30708438245918745,0.30708438245918745
2252,2252,178.7328,9.179554,4.0794702,0.0,0,5.3488536,0.0,0.31660557,79.40961657685206,5.9197598,391.7724,-9.2594872,79.40961657685206,,,,,0.311294473215859,77.59989821947228,0.3112910639087717,0.3112910639087717
2254,2254,178.7332,9.2052765,4.1255403,0.0,0,5.3054934,0.0,0.32146928,79.2625254695906,5.8725834,391.43988,-9.2579689,79.2625254695906,,,,,0.3155011552863436,77.61384775150326,0.3154977453663916,0.3154977453663916
2256,2256,178.7336,9.2702007,4.1707706,0.0,0,5.2621331,0.0,0.32532373,79.45608617465842,5.8235745,391.10739,-9.25877,79.45608617465842,,,,,0.3197078373568282,77.6276191422794,0.319704426831838,0.319704426831838
2258,2258,178.734,9.3098984,4.222033,0.0,0,5.2187734,0.0,0.32981375,79.3803022544494,5.7766924,390.7749,-9.2594395,79.3803022544494,,,,,0.32391451942731275,77.64121696634037,0.32391110830490993,0.32391110830490993
2260,2260,178.7344,9.3626852,4.2662416,0.0,0,5.1754136,0.0,0.33466905,79.46951726733302,5.7283301,390.44241,-9.2593908,79.46951726733302,,,,,0.32812120149779733,77.65464562322249,0.32811778978541417,0.32811778978541417
2262,2262,178.7348,9.3803768,4.3165469,0.0,0,5.1320534,0.0,0.33860311,79.20822109378378,5.6797042,390.10992,-9.2593584,79.20822109378378,,,,,0.3323278835682819,77.66790934634083,0.33232447127316467,0.33232447127316467
2264,2264,178.7352,9.406023,4.3620028,0.0,0,5.0886931,0.0,0.34300163,79.05191997378405,5.6331615,389.77744,-9.2586718,79.05191997378405,,,,,0.3365345656387665,77.68101221115431,0.3365311527679824,0.3365311527679824
2266,2266,178.7356,9.4492188,4.4047132,0.0,0,5.0457683,0.0,0.34763196,79.0629673455883,5.5863838,389.44495,-9.2585049,79.0629673455883,,,,,0.3407412477092511,77.69395814310467,0.34073783426969495,0.34073783426969495
2268,2268,178.736,9.5103407,4.4566669,0.0,0,5.0044241,0.0,0.35169294,79.14339696436932,5.5390587,389.11246,-9.2593365,79.14339696436932,,,,,0.3449479297797357,77.70675092480745,0.34494451577813595,0.34494451577813595
2270,2270,178.7364,9.541584,4.4985266,0.0,0,4.9631839,0.0,0.3562071,79.05496427248528,5.4929638,388.77997,-9.2586794,79.05496427248528,,,,,0.3491546118502203,77.71939420293337,0.34915119729314537,0.34915119729314537
2272,2272,178.7368,9.5613117,4.5406752,0.0,0,4.9219441,0.0,0.36043009,78.86681141995378,5.4457412,388.44748,-9.2584801,78.86681141995378,,,,,0.35336129392070487,77.73189149469734,0.3533578788145686,0.3533578788145686
2274,2274,178.7372,9.5756207,4.5945449,0.0,0,4.8807039,0.0,0.36465773,78.5347299483876,5.4010162,388.11499,-9.2591057,78.5347299483876,,,,,0.35756797599118945,77.7442461939082,0.35756456034225653,0.35756456034225653
2276,2276,178.7376,9.6437359,4.6357093,0.0,0,4.8394642,0.0,0.3694852,78.74693808389485,5.3567333,387.7825,-9.2579536,78.74693808389485,,,,,0.361774658061674,77.7564615766802,0.36177124187606524,0.36177124187606524
2278,2278,178.738,9.7130098,4.6805673,0.0,0,4.798224,0.0,0.37368101,78.93231974932816,5.3112621,387.45001,-9.2589693,78.93231974932816,,,,,0.3659813401321586,77.76854080686685,0.3659779234158558,0.3659779234158558
2280,2280,178.7384,9.7376871,4.735146,0.0,0,4.7569842,0.0,0.37835464,78.66893279460383,5.2642975,386.92191,-9.2596006,78.66893279460383,,,,,0.3701880222026432,77.78048694109098,0.3701846049614938,0.3701846049614938
2282,2282,178.7388,9.7665787,4.7722235,0.0,0,4.715744,0.0,0.38290742,78.58620492469112,5.2187638,386.32864,-9.2600288,78.58620492469112,,,,,0.37439470427312777,77.79230293361644,0.37439128651284953,0.37439128651284953
2284,2284,178.7392,9.7920942,4.8177352,0.0,0,4.6745043,0.0,0.38688716,78.40240550015828,5.1706262,385.73535,-9.2599506,78.40240550015828,,,,,0.37860138634361234,77.80399164082327,0.37859796806979745,0.37859796806979745
2286,2286,178.7396,9.8505211,4.8685794,0.0,0,4.6332641,0.0,0.39169189,78.43286190581635,5.1261802,385.14209,-9.2594433,78.43286190581635,,,,,0.3828080684140969,77.8155558255377,0.38280464963221617,0.38280464963221617
2288,2288,178.74,9.9093723,4.907846,0.0,0,4.5920238,0.0,0.3961851,78.56163068569303,5.081862,384.5488,-9.2595682,78.56163068569303,,,,,0.3870147504845815,77.82699816107976,0.3870113311999883,0.3870113311999883
2290,2290,178.7404,9.9334545,4.9567504,0.0,0,4.5507841,0.0,0.40030029,78.32824430761983,5.0366573,383.95554,-9.2592373,78.32824430761983,,,,,0.3912214325550661,77.8383212350401,0.3912180127730001,0.3912180127730001
2292,2292,178.7408,9.9593763,5.0053301,0.0,0,4.5108657,0.0,0.40554118,78.10999530162722,4.99261,383.36224,-9.2593737,78.10999530162722,,,,,0.39542811462555066,77.84952755300537,0.3954246943511415,0.3954246943511415
2294,2294,178.7412,9.9832115,5.0446692,0.0,0,4.4716296,0.0,0.40972328,77.95381475467073,4.9474139,382.76898,-9.2601643,77.95381475467073,,,,,0.39963479669603524,77.86061954196566,0.3996313759343059,0.3996313759343059
2296,2296,178.7416,10.034413,5.089869,0.0,0,4.4323978,0.0,0.41365483,77.95731855144511,4.90346,382.17569,-9.2594347,77.95731855144511,,,,,0.4038414787665198,77.87159955352885,0.40383805752239,0.40383805752239
2298,2298,178.742,10.087618,5.1336951,0.0,0,4.3931656,0.0,0.41883022,77.9843239371874,4.8606701,381.58243,-9.2589531,77.9843239371874,,,,,0.4080481608370044,77.88246986710645,0.4080447391152936,0.4080447391152936
2300,2300,178.7424,10.138528,5.1730847,0.0,0,4.3539338,0.0,0.42255324,78.02886574777814,4.8153477,380.98914,-9.2584743,78.02886574777814,,,,,0.412254842907489,77.8932326927821,0.4122514207129196,0.4122514207129196
2302,2302,178.7428,10.16398,5.2207112,0.0,0,4.314702,0.0,0.42700607,77.8016251260433,4.7713461,380.39587,-9.2572994,77.8016251260433,,,,,0.41646152497797356,77.90389017410705,0.41645810231517383,0.41645810231517383
2304,2304,178.7432,10.192187,5.2621861,0.0,0,4.2754698,0.0,0.43214923,77.64799640312215,4.730165,379.80258,-9.2586193,77.64799640312215,,,,,0.42066820704845814,77.91444439079216,0.42066478392196494,0.42066478392196494
2306,2306,178.7436,10.252347,5.3059621,0.0,0,4.2362375,0.0,0.4359372,77.71392216109078,4.6837745,379.20932,-9.2594481,77.71392216109078,,,,,0.4248748891189427,77.92489736116768,0.42487146553320426,0.42487146553320426
2308,2308,178.744,10.312185,5.348846,0.0,0,4.1970053,0.0,0.44034755,77.78080940393093,4.6411362,378.61603,-9.2595482,77.78080940393093,,,,,0.4290815711894273,77.93525104464304,0.42907814714880566,0.42907814714880566
2310,2310,178.7444,10.348422,5.3858819,0.0,0,4.1577735,0.0,0.44499665,77.71895984892085,4.6005664,378.02277,-9.2587862,77.71895984892085,,,,,0.4332882532599119,77.94550734395985,0.4332848287686856,0.4332848287686856
2312,2312,178.7448,10.364152,5.4350452,0.0,0,4.1185417,0.0,0.44902331,77.39144074498007,4.5578141,377.42947,-9.258234,77.39144074498007,,,,,0.43749493533039646,77.95566810734657,0.43749151039276285,0.43749151039276285
2314,2314,178.7452,10.398704,5.4756908,0.0,0,4.0793095,0.0,0.4538618,77.27972784161521,4.5129328,376.83621,-9.258606,77.27972784161521,,,,,0.44170161740088104,77.96573513059431,0.44169819202095856,0.44169819202095856
2316,2316,178.7456,10.451297,5.5139022,0.0,0,4.0404716,0.0,0.45822716,77.32120496745458,4.4729056,376.24292,-9.257946,77.32120496745458,,,,,0.4459082994713656,77.97571015905211,0.445904873653196,0.445904873653196
2318,2318,178.746,10.508549,5.562139,0.0,0,4.0030656,0.0,0.46227795,77.30125526221825,4.4309483,375.64966,-9.258584,77.30125526221825,,,,,0.4501149815418502,77.98559488945462,0.45011155528940056,0.45011155528940056
2320,2320,178.7464,10.558542,5.5960083,0.0,0,3.9657533,0.0,0.46674648,77.35607454504883,4.3884697,375.05637,-9.2588053,77.35607454504883,,,,,0.4543216636123348,77.99539097177576,0.4543182369294999,0.4543182369294999
2322,2322,178.7468,10.574763,5.6347337,0.0,0,3.9284413,0.0,0.47074535,77.11652959172397,4.3468013,374.4631,-9.2585211,77.11652959172397,,,,,0.45852834568281936,78.00510001089582,0.45852491857342337,0.45852491857342337
2324,2324,178.7472,10.601468,5.6832657,0.0,0,3.8911293,0.0,0.47522196,76.86094121096632,4.3043571,373.86981,-9.2585516,76.86094121096632,,,,,0.46273502775330394,78.01472356824299,0.4627316002211025,0.4627316002211025
2326,2326,178.7476,10.65982,5.7153859,0.0,0,3.8538175,0.0,0.47974291,76.9842708015801,4.2664981,373.27652,-9.2586689,76.9842708015801,,,,,0.4669417098237885,78.02426316339577,0.46693828187247044,0.46693828187247044
2328,2328,178.748,10.741591,5.7566161,0.0,0,3.8165054,0.0,0.48359162,77.1870874530502,4.2274804,372.68326,-9.2590389,77.1870874530502,,,,,0.47114839189427316,78.03372027544535,0.47114496352746227,0.47114496352746227
2330,2330,178.7484,10.762524,5.8041015,0.0,0,3.7791932,0.0,0.48844972,76.89002856842917,4.1898484,372.16483,-9.2588911,76.89002856842917,,,,,0.47535507396475774,78.04309634459295,0.4753516451860146,0.4753516451860146
2332,2332,178.7488,10.783298,5.835146,0.0,0,3.7418811,0.0,0.49271712,76.74529517796292,4.14783,371.6651,-9.2581406,76.74529517796292,,,,,0.4795617560352423,78.052392773364,0.47955832684806593,0.47955832684806593
2334,2334,178.7492,10.829594,5.87501,0.0,0,3.7045693,0.0,0.49623141,76.69670080677278,4.1085963,371.16537,-9.2590322,76.69670080677278,,,,,0.4837684381057269,78.06161092801803,0.48376500851355614,0.48376500851355614
2336,2336,178.7496,10.909001,5.9186082,0.0,0,3.6672573,0.0,0.50124347,76.84248560986029,4.071939,370.66568,-9.258544,76.84248560986029,,,,,0.4879751201762115,78.07075213972918,0.4879716901824268,0.4879716901824268
2338,2338,178.75,10.958789,5.9500604,0.0,0,3.6299453,0.0,0.50524402,76.89125383350402,4.0306087,370.16595,-9.2593708,76.89125383350402,,,,,0.49218180224669605,78.07981770576386,0.49217837185462093,0.49217837185462093
2340,2340,178.7504,10.995233,5.9937601,0.0,0,3.5926332,0.0,0.5091821,76.72600603221751,3.99229,369.66623,-9.2586498,76.72600603221751,,,,,0.49638848431718063,78.08880889073555,0.49638505353008294,0.49638505353008294
2342,2342,178.7508,11.015442,6.0339165,0.0,0,3.5565166,0.0,0.5143767,76.47944469188921,3.9482462,369.1665,-9.2573357,76.47944469188921,,,,,0.5005951663876652,78.09772692753667,0.5005917352087587,0.5005917352087587
2344,2344,178.7512,11.06016,6.0669718,0.0,0,3.5210168,0.0,0.51805264,76.46954386577653,3.9164646,368.66678,-9.2585258,76.46954386577653,,,,,0.5048018484581498,78.10657301855815,0.5047984168905953,0.5047984168905953
2346,2346,178.7516,11.145169,6.1074004,0.0,0,3.4855206,0.0,0.52201223,76.6623992052419,3.8768837,368.16705,-9.258769,76.6623992052419,,,,,0.5090085305286344,78.11534833652912,0.5090050985755413,0.5090050985755413
2348,2348,178.752,11.196854,6.144114,0.0,0,3.4500248,0.0,0.52710003,76.65760334234977,3.8374016,367.66733,-9.259613,76.65760334234977,,,,,0.513215212599119,78.12405402562439,0.5132117802635465,0.5132117802635465
2350,2350,178.7524,11.20516,6.1829333,0.0,0,3.4145288,0.0,0.5307951,76.33316350019506,3.8040664,367.1676,-9.2591343,76.33316350019506,,,,,0.5174218946696035,78.13269120230903,0.5174184619545616,0.5174184619545616
2352,2352,178.7528,11.243414,6.2248478,0.0,0,3.3790326,0.0,0.53539979,76.18059625263434,3.7654777,366.66791,-9.2577162,76.18059625263434,,,,,0.5216285767400881,78.14126095625294,0.521625143648539,0.521625143648539
2354,2354,178.7532,11.310415,6.2580681,0.0,0,3.3435369,0.0,0.54009712,76.3051125568703,3.7305918,366.16818,-9.2579327,76.3051125568703,,,,,0.5258352588105727,78.14976435117342,0.5258318253454318,0.5258318253454318
2356,2356,178.7536,11.376888,6.2960062,0.0,0,3.3080409,0.0,0.5434444,76.3750742519974,3.6912429,365.66846,-9.258213,76.3750742519974,,,,,0.5300419408810573,78.15820242567722,0.5300385070451944,0.5300385070451944
2358,2358,178.754,11.415022,6.330739,0.0,0,3.2725446,0.0,0.54788804,76.28335685165614,3.6502736,365.16873,-9.2580824,76.28335685165614,,,,,0.5342486229515419,78.16657619403388,0.5342451887477823,0.5342451887477823
2360,2360,178.7544,11.460011,6.3626504,0.0,0,3.2370486,0.0,0.55214781,76.2632409053614,3.6173503,364.66901,-9.2586269,76.2632409053614,,,,,0.5384553050220264,78.17488664689097,0.5384518704531518,0.5384518704531518
2362,2362,178.7548,11.508285,6.4091105,0.0,0,3.2015526,0.0,0.55616021,76.11546199377261,3.5803151,364.16928,-9.2578945,76.11546199377261,,,,,0.542661987092511,78.18313475208497,0.5426585521612607,0.5426585521612607
2364,2364,178.7552,11.561522,6.4430699,0.0,0,3.1660566,0.0,0.56106955,76.12310970589148,3.5434155,363.66956,-9.25809,76.12310970589148,,,,,0.5468686691629956,78.19132145529356,0.5468652338720671,0.5468652338720671
2366,2366,178.7556,11.623982,6.4766402,0.0,0,3.1309152,0.0,0.56496066,76.19196785158424,3.5030935,363.16983,-9.2577448,76.19196785158424,,,,,0.5510753512334802,78.19944768068594,0.5510719155855306,0.5510719155855306
2368,2368,178.756,11.685492,6.5191803,0.0,0,3.0970623,0.0,0.56916451,76.15892623136298,3.4675186,362.67014,-9.2571793,76.15892623136298,,,,,0.5552820333039648,78.20751433161747,0.5552785973016116,0.5552785973016116
2370,2370,178.7564,11.728062,6.5466404,0.0,0,3.0632944,0.0,0.5735178,76.15372801918475,3.4292064,362.17041,-9.2589016,76.15372801918475,,,,,0.5594887153744493,78.21552229125751,0.559485279020271,0.559485279020271
2372,2372,178.7568,11.761429,6.5813122,0.0,0,3.0295265,0.0,0.57712471,76.01246635213968,3.3926764,361.67068,-9.2585735,76.01246635213968,,,,,0.5636953974449339,78.2234724231073,0.5636919607414711,0.5636919607414711
2374,2374,178.7572,11.83155,6.6276798,0.0,0,2.9957583,0.0,0.5820927,75.98407159271702,3.3590267,361.17096,-9.2579641,75.98407159271702,,,,,0.5679020795154185,78.231365571681,0.5678986424651747,0.5678986424651747
2376,2376,178.7576,11.905659,6.6543941,0.0,0,2.9619906,0.0,0.58658075,76.18078438961888,3.3263307,360.67123,-9.2573786,76.18078438961888,,,,,0.5721087615859031,78.239202563013,0.5721053241913455,0.5721053241913455
2378,2378,178.758,11.975874,6.6919804,0.0,0,2.9282222,0.0,0.58998245,76.23484729575212,3.286756,360.17151,-9.2575026,76.23484729575212,,,,,0.5763154436563876,78.24698420515595,0.5763120059199481,0.5763120059199481
2380,2380,178.7584,12.000839,6.7318497,0.0,0,2.8944542,0.0,0.59506458,75.97361327702393,3.2525361,359.7804,-9.2578707,75.97361327702393,,,,,0.5805221257268722,78.25471128882155,0.5805186876509477,0.5805186876509477
2382,2382,178.7588,12.054117,6.7591147,0.0,0,2.8606863,0.0,0.598975,76.0222671934669,3.2172654,359.40845,-9.2570152,76.0222671934669,,,,,0.5847288077973568,78.26238458771672,0.5847253693843103,0.5847253693843103
2384,2384,178.7592,12.11551,6.799686,0.0,0,2.8269184,0.0,0.60283619,75.97772723216931,3.1839182,359.0365,-9.2578316,75.97772723216931,,,,,0.5889354898678414,78.27000485915671,0.5889320511200026,0.5889320511200026
2386,2386,178.7596,12.198811,6.8364105,0.0,0,2.7931502,0.0,0.60819793,76.10658632972765,3.1500909,358.66455,-9.2597198,76.10658632972765,,,,,0.593142171938326,78.2775728444524,0.5931387328579921,0.5931387328579921
2388,2388,178.76,12.251677,6.8652744,0.0,0,2.7593822,0.0,0.61175871,76.12573792852328,3.1179035,358.2926,-9.257288,76.12573792852328,,,,,0.5973488540088105,78.28508926939875,0.5973454145982469,0.5973454145982469
2390,2390,178.7604,12.293481,6.9037604,0.0,0,2.7256143,0.0,0.61583209,75.96979121276189,3.0827169,357.92065,-9.2569418,75.96979121276189,,,,,0.6015555360792951,78.2925548446997,0.6015520963407357,0.6015520963407357
2392,2392,178.7608,12.340849,6.9370251,0.0,0,2.6929309,0.0,0.62095088,75.90178516811787,3.0444949,357.54871,-9.2574606,75.90178516811787,,,,,0.6057622181497797,78.29997026637076,0.6057587780854279,0.6057587780854279
2394,2394,178.7612,12.411038,6.9700346,0.0,0,2.6608074,0.0,0.62433505,75.9734472404014,3.0133786,357.17676,-9.2578545,75.9734472404014,,,,,0.6099689002202643,78.30733621613129,0.6099654598322938,0.6099654598322938
2396,2396,178.7616,12.499801,7.0076103,0.0,0,2.6286874,0.0,0.6289382,76.10399183831473,2.9783685,356.80481,-9.2578163,76.10399183831473,,,,,0.6141755822907489,78.31465336183564,0.6141721415813037,0.6141721415813037
2398,2398,178.762,12.556847,7.0394726,0.0,0,2.5965672,0.0,0.63384688,76.09963037113585,2.942342,356.43286,-9.2574921,76.09963037113585,,,,,0.6183822643612334,78.32192235781147,0.6183788233324291,0.6183788233324291
2400,2400,178.7624,12.604875,7.0773106,0.0,0,2.5644474,0.0,0.63738525,75.97141715961591,2.9070539,356.06088,-9.257062,75.97141715961591,,,,,0.622588946431718,78.32914384522712,0.6225855050856418,0.6225855050856418
2402,2402,178.7628,12.666077,7.1122441,0.0,0,2.5323272,0.0,0.64219582,75.95126779525006,2.8730109,355.68893,-9.2571239,75.95126779525006,,,,,0.6267956285022026,78.3363184524943,0.6267921868409141,0.6267921868409141
2404,2404,178.7632,12.740947,7.1397195,0.0,0,2.5002072,0.0,0.64657116,76.0924126185309,2.8377461,355.31699,-9.2573662,76.0924126185309,,,,,0.6310023105726872,78.34344679551776,0.630998868598219,0.630998868598219
2406,2406,178.7636,12.835055,7.1816649,0.0,0,2.4680872,0.0,0.65040714,76.18101164815694,2.8043635,354.94504,-9.2575197,76.18101164815694,,,,,0.6352089926431718,78.35052947809397,0.63520555035753,0.63520555035753
2408,2408,178.764,12.905334,7.2121439,0.0,0,2.4359674,0.0,0.65531135,76.2522030042378,2.7701929,354.57309,-9.2572756,76.2522030042378,,,,,0.6394156747136563,78.35756709218438,0.639412232118821,0.639412232118821
2410,2410,178.7644,12.956738,7.2435174,0.0,0,2.4038472,0.0,0.65948105,76.19837950427141,2.7335229,354.20114,-9.2583818,76.19837950427141,,,,,0.6436223567841409,78.36456021829682,0.6436189138820666,0.6436189138820666
2412,2412,178.7648,13.017118,7.2869277,0.0,0,2.3717272,0.0,0.66384506,76.05638286780085,2.6998038,353.82919,-9.2584381,76.05638286780085,,,,,0.6478290388546255,78.37150942565536,0.6478255956472417,0.6478255956472417
2414,2414,178.7652,13.095934,7.3146343,0.0,0,2.3396072,0.0,0.66882092,76.1976638021565,2.6653666,353.45724,-9.2566996,76.1976638021565,,,,,0.6520357209251101,78.37841527261318,0.6520322774143219,0.6520322774143219
2416,2416,178.7656,13.204463,7.3478403,0.0,0,2.3078089,0.0,0.67255318,76.44333620972367,2.6304197,353.0853,-9.2565708,76.44333620972367,,,,,0.6562424029955947,78.38527830686424,0.656238959183283,0.656238959183283
2418,2418,178.766,13.268116,7.3908782,0.0,0,2.2771804,0.0,0.67754233,76.30934066681262,2.5981803,352.71335,-9.2554045,76.30934066681262,,,,,0.6604490850660792,78.39209906573018,0.6604456409541014,0.6604456409541014
2420,2420,178.7664,13.316802,7.4169307,0.0,0,2.246628,0.0,0.68238115,76.28402026299321,2.5651722,352.34137,-9.2562847,76.28402026299321,,,,,0.6646557671365638,78.3988780764206,0.664652322726754,0.664652322726754
2422,2422,178.7668,13.379766,7.451992,0.0,0,2.2160764,0.0,0.685983,76.23180962299925,2.5338945,351.96942,-9.2573614,76.23180962299925,,,,,0.6688624492070484,78.40561585627495,0.6688590045012182,0.6688590045012182
2424,2424,178.7672,13.460683,7.4911861,0.0,0,2.1855242,0.0,0.69122666,76.22842868976154,2.4952269,351.59747,-9.257822,76.22842868976154,,,,,0.673069131277533,78.4123129130393,0.6730656862774713,0.6730656862774713
2426,2426,178.7676,13.572949,7.5162954,0.0,0,2.1549723,0.0,0.69558471,76.56416505824208,2.4626122,351.22552,-9.2567043,76.56416505824208,,,,,0.6772758133480177,78.4189697450569,0.677272368055492,0.677272368055492
2428,2428,178.768,13.632801,7.5549436,0.0,0,2.1244202,0.0,0.69939977,76.43789643258484,2.4290204,350.85358,-9.2561569,76.43789643258484,,,,,0.6814824954185023,78.42558684154314,0.6814790498352582,0.6814790498352582
2430,2430,178.7684,13.682165,7.5905004,0.0,0,2.0938683,0.0,0.70519209,76.28629632925906,2.3954031,350.29446,-9.2560959,76.28629632925906,,,,,0.6856891774889868,78.43216468279495,0.6856857316167491,0.6856857316167491
2432,2432,178.7688,13.751842,7.6177235,0.0,0,2.0633163,0.0,0.70893782,76.34510758398181,2.3622303,349.71454,-9.2568693,76.34510758398181,,,,,0.6898958595594714,78.43870374035876,0.6898924133999439,0.6898924133999439
2434,2434,178.7692,13.84233,7.6548443,0.0,0,2.0327644,0.0,0.71294093,76.3949157530872,2.3276346,349.13461,-9.2563133,76.3949157530872,,,,,0.694102541629956,78.44520447733461,0.6940990951848224,0.6940990951848224
2436,2436,178.7696,13.954132,7.6861339,0.0,0,2.0022123,0.0,0.71843517,76.62736365824495,2.2957926,348.55472,-9.2559414,76.62736365824495,,,,,0.6983092237004406,78.45166734852039,0.6983057769713644,0.6983057769713644
2438,2438,178.77,14.015668,7.7172723,0.0,0,1.9716601,0.0,0.72211057,76.58083427780744,2.2623768,347.97479,-9.2568684,76.58083427780744,,,,,0.7025159057709252,78.45809280058982,0.7025124587595504,0.7025124587595504
2440,2440,178.7704,14.070989,7.7533965,0.0,0,1.9411081,0.0,0.72643578,76.43529505254304,2.22961,347.39487,-9.2567959,76.43529505254304,,,,,0.7067225878414097,78.46448127231385,0.7067191405493611,0.7067191405493611
2442,2442,178.7708,14.138835,7.7825365,0.0,0,1.9115355,0.0,0.73183846,76.44083331119792,2.1991067,346.81497,-9.2566233,76.44083331119792,,,,,0.7109292699118943,78.47083319477166,0.7109258223407776,0.7109258223407776
2444,2444,178.7712,14.251122,7.8188663,0.0,0,1.8824685,0.0,0.73561978,76.59169113962578,2.1644263,346.23505,-9.2567596,76.59169113962578,,,,,0.7151359519823789,78.47714899148436,0.7151325041337813,0.7151325041337813
2446,2446,178.7716,14.349546,7.851181,0.0,0,1.8534043,0.0,0.7404955,76.71202339093165,2.1298022,345.65512,-9.2561646,76.71202339093165,,,,,0.7193426340528635,78.48342907862619,0.7193391859283539,0.7193391859283539
2448,2448,178.772,14.400675,7.8771391,0.0,0,1.8243403,0.0,0.74518394,76.6559005621459,2.0994291,345.07523,-9.2555008,76.6559005621459,,,,,0.723549316123348,78.48967386514579,0.7235458677244773,0.7235458677244773
2450,2450,178.7724,14.44885,7.9153633,0.0,0,1.7952764,0.0,0.74892944,76.42553419878567,2.0672643,344.4953,-9.255827,76.42553419878567,,,,,0.7277559981938326,78.49588375299916,0.727752549522134,0.727752549522134
2452,2452,178.7728,14.537847,7.9427824,0.0,0,1.7662123,0.0,0.75377852,76.54489131295124,2.0374527,343.91537,-9.2572241,76.54489131295124,,,,,0.7319626802643172,78.50205913725978,0.7319592313213066,0.7319592313213066
2454,2454,178.7732,14.651127,7.9698343,0.0,0,1.7371484,0.0,0.75785893,76.79192864132841,2.007571,343.33548,-9.2567167,76.79192864132841,,,,,0.7361693623348018,78.50820040628709,0.7361659131219781,0.7361659131219781
2456,2456,178.7736,14.732725,8.0112486,0.0,0,1.7080843,0.0,0.76219779,76.68166694928674,1.9748286,342.75555,-9.2555637,76.68166694928674,,,,,0.7403760444052864,78.51430794189454,0.7403725949241315,0.7403725949241315
2458,2458,178.774,14.80388,8.0354147,0.0,0,1.6790204,0.0,0.76729566,76.73656873847465,1.9473344,342.17563,-9.2545109,76.73656873847465,,,,,0.744582726475771,78.5203821194542,0.7445792767277506,0.7445792767277506
2460,2460,178.7744,14.870378,8.0652895,0.0,0,1.6499563,0.0,0.77112335,76.68951404812006,1.9163439,341.59573,-9.2552061,76.68951404812006,,,,,0.7487894085462555,78.52642330810392,0.748785958532819,0.748785958532819
2462,2462,178.7748,14.955606,8.1026697,0.0,0,1.6208923,0.0,0.77575129,76.63602570415219,1.8820648,341.01581,-9.256217,76.63602570415219,,,,,0.7529960906167401,78.5324318708205,0.7529926403393209,0.7529926403393209
2464,2464,178.7752,15.068161,8.1244612,0.0,0,1.5918283,0.0,0.78052145,76.9231771048268,1.8532611,340.43591,-9.2563114,76.9231771048268,,,,,0.7572027726872247,78.53840816461978,0.7571993221472404,0.7571993221472404
2466,2466,178.7756,15.148449,8.155715,0.0,0,1.5630548,0.0,0.78379762,76.91544396203886,1.8253641,339.85599,-9.2558985,76.91544396203886,,,,,0.7614094547577093,78.54435254064401,0.7614060039565622,0.7614060039565622
2468,2468,178.776,15.226792,8.1930561,0.0,0,1.5353373,0.0,0.78913444,76.811655994599,1.7931772,339.27606,-9.2559195,76.811655994599,,,,,0.7656161368281938,78.550265344262,0.7656126857672712,0.7656126857672712
2470,2470,178.7764,15.300573,8.2129078,0.0,0,1.5076892,0.0,0.79332703,76.91588065688978,1.7654605,338.69617,-9.2557116,76.91588065688978,,,,,0.7698228188986784,78.5561469152937,0.7698193675793523,0.7698193675793523
2472,2472,178.7768,15.385717,8.2465973,0.0,0,1.4800413,0.0,0.79684734,76.88658358765247,1.7359889,338.11624,-9.2541504,76.88658358765247,,,,,0.774029500969163,78.56199758802806,0.774026049392791,0.774026049392791
2474,2474,178.7772,15.493406,8.280714,0.0,0,1.4523933,0.0,0.80282724,76.95833521588423,1.7057096,337.53632,-9.2550478,76.95833521588423,,,,,0.7782361830396476,78.56781769140045,0.7782327312075726,0.7782327312075726
2476,2476,178.7776,15.612204,8.3035412,0.0,0,1.4247453,0.0,0.80656773,77.23394358131108,1.6749763,336.95642,-9.2554569,77.23394358131108,,,,,0.7824428651101322,78.57360754907367,0.7824394130236831,0.7824394130236831
2478,2478,178.778,15.684915,8.3361664,0.0,0,1.3970973,0.0,0.81017733,77.14205534041034,1.6448609,336.3765,-9.2548876,77.14205534041034,,,,,0.7866495471806167,78.57936747958469,0.7866460948411084,0.7866460948411084
2480,2480,178.7784,15.7638,8.3632965,0.0,0,1.3694494,0.0,0.81564522,77.15258210792696,1.61875,336.3082,-9.2550535,77.15258210792696,,,,,0.7908562292511013,78.58509779644629,0.7908527766598348,0.7908527766598348
2482,2482,178.7788,15.855324,8.3891363,0.0,0,1.3418013,0.0,0.81894404,77.23891781354799,1.5883693,336.26678,-9.2553596,77.23891781354799,,,,,0.7950629113215859,78.59079880819628,0.7950594584798487,0.7950594584798487
2484,2484,178.7792,15.976054,8.4219208,0.0,0,1.3141534,0.0,0.82334453,77.3647278481738,1.5604085,336.22537,-9.2549133,77.3647278481738,,,,,0.7992695933920705,78.59647081858667,0.7992661403011367,0.7992661403011367
2486,2486,178.7796,16.071495,8.4480848,0.0,0,1.2865053,0.0,0.82877672,77.45571040442313,1.5320762,336.18396,-9.2543793,77.45571040442313,,,,,0.8034762754625551,78.60211412662277,0.8034728221236859,0.8034728221236859
2488,2488,178.78,16.1399,8.4794941,0.0,0,1.2588574,0.0,0.83223248,77.33784447113499,1.500494,336.14255,-9.254735,77.33784447113499,,,,,0.8076829575330396,78.60772902669325,0.807679503947483,0.807679503947483
2490,2490,178.7804,16.238802,8.5107298,0.0,0,1.2312094,0.0,0.83718127,77.36392598964413,1.4720142,336.10117,-9.2545233,77.36392598964413,,,,,0.8118896396035242,78.61331580864417,0.8118861857725155,0.8118861857725155
2492,2492,178.7808,16.335087,8.5318871,0.0,0,1.2044513,0.0,0.84173799,77.51748890135117,1.4448106,336.05975,-9.2540741,77.51748890135117,,,,,0.8160963216740088,78.61887475787653,0.8160928675987709,0.8160928675987709
2494,2494,178.7812,16.45615,8.5643578,0.0,0,1.1781524,0.0,0.84493929,77.62016108854678,1.4171616,336.01834,-9.254405,77.62016108854678,,,,,0.8203030037444934,78.62440615547634,0.8202995494262366,0.8202995494262366
2496,2496,178.7816,16.574009,8.5894299,0.0,0,1.1518564,0.0,0.84976536,77.80912316298368,1.3865159,335.97693,-9.2545891,77.80912316298368,,,,,0.824509685814978,78.62991027821292,0.8245062312549007,0.8245062312549007
2498,2498,178.782,16.661295,8.6127739,0.0,0,1.1255604,0.0,0.85387295,77.87541983624699,1.359666,335.93552,-9.2547512,77.87541983624699,,,,,0.8287163678854625,78.6353873987329,0.8287129130847511,0.8287129130847511
2500,2500,178.7824,16.756947,8.6520367,0.0,0,1.0992644,0.0,0.85812902,77.7414344791016,1.3308578,335.8941,-9.2552757,77.7414344791016,,,,,0.8329230499559471,78.64083778555549,0.8329195949157762,0.8329195949157762
2502,2502,178.7828,16.869261,8.6742001,0.0,0,1.0729684,0.0,0.86355507,77.93227262832565,1.3054667,335.85269,-9.2554073,77.93227262832565,,,,,0.8371297320264317,78.64626170321496,0.837126276747964,0.837126276747964
2504,2504,178.7832,16.989447,8.6990318,0.0,0,1.0466723,0.0,0.86715144,78.11486699249846,1.2730482,335.81128,-9.2541752,78.11486699249846,,,,,0.8413364140969163,78.65165941227966,0.8413329585813033,0.8413329585813033
2506,2506,178.7836,17.120995,8.7336521,0.0,0,1.0203763,0.0,0.8715148,78.1961161924243,1.2463048,335.7699,-9.2538738,78.1961161924243,,,,,0.8455430961674009,78.65703116951106,0.8455396404157828,0.8455396404157828
2508,2508,178.784,17.199291,8.7507191,0.0,0,0.99408036,0.0,0.87599289,78.29440326454916,1.2182313,335.72849,-9.2535658,78.29440326454916,,,,,0.8497497782378854,78.66237722785372,0.8497463222513914,0.8497463222513914
2510,2510,178.7844,17.293865,8.7784929,0.0,0,0.96778435,0.0,0.879233,78.30059387875619,1.1918098,335.68707,-9.2546625,78.30059387875619,,,,,0.85395646030837,78.66769783657377,0.853953004088118,0.853953004088118
2512,2512,178.7848,17.410635,8.8170681,0.0,0,0.94148839,0.0,0.88512808,78.2359165915216,1.1657525,335.64566,-9.2546806,78.2359165915216,,,,,0.8581631423788546,78.67299324130195,0.858159685925952,0.858159685925952
2514,2514,178.7852,17.564594,8.8370066,0.0,0,0.91519243,0.0,0.88993967,78.61831437058127,1.1378379,335.60425,-9.2545376,78.61831437058127,,,,,0.8623698244493392,78.67826368411708,0.8623663677648827,0.8623663677648827
2516,2516,178.7856,17.684801,8.8663549,0.0,0,0.88916051,0.0,0.89297396,78.69775698783738,1.1081825,335.56284,-9.2541428,78.69775698783738,,,,,0.8665765065198238,78.68350940357095,0.8665730496048997,0.8665730496048997
2518,2518,178.786,17.769032,8.8941603,0.0,0,0.86408949,0.0,0.89840704,78.63600508582557,1.0800579,335.52142,-9.2534323,78.63600508582557,,,,,0.8707831885903083,78.68873063482428,0.8707797314459924,0.8707797314459924
2520,2520,178.7864,17.870144,8.9110117,0.0,0,0.83908135,0.0,0.9018361,78.81736562827321,1.0547609,335.48001,-9.2541771,78.81736562827321,,,,,0.8749898706607929,78.69392760967928,0.8749864132881509,0.8749864132881509
2522,2522,178.7868,18.001381,8.9438629,0.0,0,0.81407332,0.0,0.90561861,78.87359803829355,1.0290455,335.43863,-9.2538786,78.87359803829355,,,,,0.8791965527312775,78.69910055663293,0.879193095131365,0.879193095131365
2524,2524,178.7872,18.155556,8.9722481,0.0,0,0.78906536,0.0,0.91185713,79.09367791556397,1.0009395,335.39722,-9.2535124,79.09367791556397,,,,,0.8834032348017621,78.70424970093248,0.8833997769756249,0.8833997769756249
2526,2526,178.7876,18.283663,8.9973774,0.0,0,0.7640574,0.0,0.91557735,79.24570467493625,0.97219366,335.3558,-9.2529373,79.24570467493625,,,,,0.8876099168722467,78.70937526469032,0.8876064588209207,0.8876064588209207
2528,2528,178.788,18.396196,9.0285501,0.0,0,0.73904938,0.0,0.9199478,79.22660676518237,0.94454592,335.31442,-9.2532845,79.22660676518237,,,,,0.8918165989427312,78.7144774668638,0.891813140667243,0.891813140667243
2530,2530,178.7884,18.493698,9.049284,0.0,0,0.71404135,0.0,0.92526025,79.3076008302154,0.91627121,335.83603,-9.2534294,79.3076008302154,,,,,0.8960232810132158,78.71955652339358,0.8960198225145821,0.8960198225145821
2532,2532,178.7888,18.645817,9.0744715,0.0,0,0.68903339,0.0,0.92809474,79.54482639983563,0.89132529,336.35764,-9.2533512,79.54482639983563,,,,,0.9002299630837004,78.72461264720792,0.9002265043629288,0.9002265043629288
2534,2534,178.7892,18.812153,9.1034517,0.0,0,0.66402543,0.0,0.93269235,79.77252996968986,0.86615294,336.87927,-9.2534046,79.77252996968986,,,,,0.904436645154185,78.72964604827814,0.9044331862122738,0.9044331862122738
2536,2536,178.7896,18.929262,9.1256514,0.0,0,0.63901734,0.0,0.93807244,79.89766650955005,0.83799779,337.40088,-9.2533503,79.89766650955005,,,,,0.9086433272246696,78.73465693370983,0.908639868062608,0.908639868062608
2538,2538,178.79,19.030834,9.1596165,0.0,0,0.61400938,0.0,0.94199824,79.75498863798728,0.81180769,337.92249,-9.2530069,79.75498863798728,,,,,0.9128500092951541,78.73964550777642,0.9128465499139224,0.9128465499139224
2540,2540,178.7904,19.151556,9.1844721,0.0,0,0.58900136,0.0,0.94699627,79.84009855435222,0.78764427,338.44409,-9.2533875,79.84009855435222,,,,,0.9170566913656387,78.74461197193231,0.9170532317662082,0.9170532317662082
2542,2542,178.7908,19.294996,9.2024527,0.0,0,0.56478846,0.0,0.95120293,80.13137328022299,0.75955498,338.9657,-9.2519588,80.13137328022299,,,,,0.9212633734361233,78.74955652492467,0.9212599136194567,0.9212599136194567
2544,2544,178.7912,19.457239,9.2370825,0.0,0,0.54098594,0.0,0.95491683,80.20947750262945,0.73465091,339.4873,-9.2523775,80.20947750262945,,,,,0.9254700555066079,78.75447936284182,0.9254665954736593,0.9254665954736593
2546,2546,178.7916,19.578884,9.2575121,0.0,0,0.51718587,0.0,0.96004307,80.3573141780145,0.7074784,340.00894,-9.2532272,80.3573141780145,,,,,0.9296767375770925,78.7593806790619,0.9296732773288073,0.9296732773288073
2548,2548,178.792,19.677319,9.2812471,0.0,0,0.49338591,0.0,0.96412194,80.34840504722395,0.68147075,340.53055,-9.2532349,80.34840504722395,,,,,0.933883419647577,78.76426066446632,0.9338799591848925,0.9338799591848925
2550,2550,178.7924,19.813173,9.3157148,0.0,0,0.4695859,0.0,0.96878517,80.29935449209407,0.65474093,341.05215,-9.2525778,80.29935449209407,,,,,0.9380901017180616,78.76911950731322,0.9380866410419066,0.9380866410419066
2552,2552,178.7928,19.958094,9.3324451,0.0,0,0.44578591,0.0,0.97384787,80.5914745161568,0.62939209,341.57376,-9.2516985,80.5914745161568,,,,,0.9422967837885463,78.77395739340663,0.9422933228998416,0.9422933228998416
2554,2554,178.7932,20.10977,9.3548555,0.0,0,0.42198589,0.0,0.97666061,80.80548774592998,0.60571742,342.09537,-9.252492,80.80548774592998,,,,,0.9465034658590309,78.77877450610532,0.946500004758689,0.946500004758689
2556,2556,178.7936,20.236414,9.3867683,0.0,0,0.39818591,0.0,0.98171741,80.74337607961363,0.57793403,342.617,-9.2538071,80.74337607961363,,,,,0.9507101479295155,78.78357102634587,0.9507066866184413,0.9507066866184413
2558,2558,178.794,20.352856,9.402277,0.0,0,0.37438589,0.0,0.9863174,80.9288933213612,0.55119634,343.13861,-9.2525034,80.9288933213612,,,,,0.95491683,78.78834713266933,0.9549133684790904,0.9549133684790904