File: examples/hot axisymmetric compression example/data/12 fitted data ramberg/testID_0139.csv
level_0,index,Time(sec),Force(kN),Jaw(mm),PowAngle(deg),Power(W),Pram,PTemp,Strain,Stress(MPa),Stroke(mm),TC1(C),wedge(mm),uncorrected stress,sampled strain,sampled stress,fitting strain,fitting stress,model strain,ramberg stress,ramberg plastic strain,ramberg accumulated plastic strain
1972,1972,165.3437,1.0057675,0.012191684,0.0,0,9.0629425,0.0,0.00098395417,12.250299034079536,10.084554,362.57523,-9.2901678,12.250299034079536,0.00098395417,12.250299034079536,0.0,12.250299034079536,0.0,0.0,0.0,0.0
1974,1974,165.3441,2.9290299,0.04168338,0.0,0,9.0044146,0.0,0.0021816557,35.601045083530444,10.008451,362.74573,-9.2895546,35.601045083530444,0.10652275,96.18081193263168,0.095156479,96.37405864187367,0.004182702373626374,90.8262576166181,0.004177899599940308,0.004177899599940308
1976,1976,165.3445,5.3089318,0.088600598,0.0,0,8.9458866,0.0,0.0056985379,64.31231447720796,9.9541521,362.9162,-9.2880573,64.31231447720796,0.19307476,98.4795764247036,0.190312958,98.4425632266966,0.008365404747252747,91.45153935725719,0.008360568909486214,0.008360568909486214
1978,1978,165.3449,6.1955533,0.14413022,0.0,0,8.8873577,0.0,0.0091574807,74.75533353342615,9.8848896,363.08667,-9.2855635,74.75533353342615,0.28174245,97.35601276098284,0.285469437,97.34821598231645,0.012548107120879122,91.82448398838649,0.012543251562288374,0.012543251562288374
1980,1980,165.3453,6.7792959,0.27897361,0.0,0,8.8288298,0.0,0.017488703,81.00814841013009,9.8028316,363.25714,-9.2839947,81.00814841013009,0.37645867,96.57977012080336,0.380625916,96.49067051878194,0.016730809494505495,92.09238026771993,0.01672593976990995,0.01672593976990995
1982,1982,165.3457,6.9407258,0.37495244,0.0,0,8.7703018,0.0,0.025029739,82.36089207491317,9.7065926,363.42764,-9.2840738,82.36089207491317,0.47381309,94.4756476172453,0.475782395,94.45145644921911,0.020913511868131868,92.30208221122356,0.02090863105477188,0.02090863105477188
1984,1984,165.3461,7.4629827,0.46529588,0.0,0,8.7136612,0.0,0.030638635,87.9748586449586,9.606493,363.59811,-9.2840986,87.9748586449586,0.56715256,93.64634963282252,0.570938874,93.61813658767998,0.025096214241758244,92.47466920653993,0.025091324302223716,0.025091324302223716
1986,1986,165.3465,7.8228846,0.54433584,0.0,0,8.6579905,0.0,0.036522839,91.68243788758,9.5139418,363.76859,-9.2840757,91.68243788758,0.66249794,93.21540866087054,0.666095353,93.22299089401919,0.029278916615384617,92.62147188334454,0.02927401891311658,0.02927401891311658
1988,1988,165.3469,7.9609499,0.56655842,0.0,0,8.6023264,0.0,0.038411759,93.14744542903192,9.4393501,363.93906,-9.2827959,93.14744542903192,0.75846589,93.87509267744858,0.761251832,93.90387212284445,0.03346161898901099,92.74929588986761,0.0334567145275767,0.0334567145275767
1990,1990,165.3473,7.71205,0.64359951,0.0,0,8.5466623,0.0,0.043118067,89.72101389323467,9.3742037,364.10956,-9.2832355,89.72101389323467,0.85458928,95.06043610639772,0.856408311,95.0983611931921,0.037644321362637366,92.86255422965824,0.03763941091225024,0.03763941091225024
1992,1992,165.3477,8.2013712,0.70056087,0.0,0,8.4909992,0.0,0.04763839,95.00939417060904,9.3145542,364.26282,-9.2834988,95.00939417060904,0.95156479,97.5363989286328,0.95156479,97.5363989286328,0.041827023736263735,92.96427390818353,0.041822107907073074,0.041822107907073074
1994,1994,165.3481,8.4234905,0.76524359,0.0,0,8.4353342,0.0,0.051814888,97.110942342259,9.245801,364.3475,-9.2831326,97.110942342259,,,,,0.04600972610989011,93.0566227331448,0.046004805397414396,0.046004805397414396
1996,1996,165.3485,8.4266939,0.86982626,0.0,0,8.3796701,0.0,0.058823511,96.38495241773693,9.1670876,364.43219,-9.2828646,96.38495241773693,,,,,0.05019242848351649,93.14120716301868,0.05018750329832677,0.05018750329832677
1998,1998,165.3489,8.1389208,0.95276463,0.0,0,8.324007,0.0,0.065346576,92.50893248345936,9.0815506,364.51688,-9.282979,92.50893248345936,,,,,0.05437513085714286,93.21925118882635,0.05437020154508715,0.05437020154508715
2000,2000,165.3493,8.524291,1.0306028,0.0,0,8.268343,0.0,0.070602126,96.31457758142226,9.0033627,364.60156,-9.2830572,96.31457758142226,,,,,0.058557833230769234,93.29170911296598,0.05855290008723329,0.05855290008723329
2002,2002,165.3497,8.4880257,1.0846555,0.0,0,8.2126789,0.0,0.074712612,95.5074829353212,8.9297323,364.68625,-9.2831011,95.5074829353212,,,,,0.0627405356043956,93.35933955064012,0.06273559888465058,0.06273559888465058
2004,2004,165.3501,8.7481346,1.1216658,0.0,0,8.1570148,0.0,0.077657342,98.15381506370726,8.8665361,364.77094,-9.2838411,98.15381506370726,,,,,0.06692323797802198,93.42275564101695,0.06691829790491706,0.06691829790491706
2006,2006,165.3505,8.4462013,1.1906265,0.0,0,8.1013508,0.0,0.081993423,94.26161810072132,8.8139572,364.85562,-9.2836733,94.26161810072132,,,,,0.07110594035164836,93.48246010045139,0.07110099712144972,0.07110099712144972
2008,2008,165.3509,8.8192949,1.2374334,0.0,0,8.0462427,0.0,0.08576563,98.0678315923785,8.755827,364.94031,-9.2828321,98.0678315923785,,,,,0.07528864272527473,93.53887030205061,0.07528369651217844,0.07528369651217844
2010,2010,165.3513,8.9373493,1.3048011,0.0,0,7.9931507,0.0,0.090645507,98.8589362959897,8.6939907,365.02499,-9.2830687,98.8589362959897,,,,,0.0794713450989011,93.59233660701314,0.07946639605857653,0.07946639605857653
2012,2012,165.3517,8.9198666,1.3934797,0.0,0,7.9401903,0.0,0.096616209,97.9801710473496,8.6288719,365.10968,-9.2823191,97.9801710473496,,,,,0.08365404747252747,93.64315601740445,0.08364909574493896,0.08364909574493896
2014,2014,165.3521,8.813386,1.4569892,0.0,0,7.8872304,0.0,0.10169546,96.32547500488133,8.5531673,365.19437,-9.2831802,96.32547500488133,,,,,0.08783674984615385,93.6915825154702,0.08783179555783548,0.08783179555783548
2016,2016,165.3525,8.8447132,1.5205263,0.0,0,7.8342705,0.0,0.10652275,96.18081193263168,8.4878016,365.27905,-9.283843,96.18081193263168,,,,,0.09201945221978022,93.73783501036696,0.09201449548569043,0.09201449548569043
2018,2018,165.3529,9.0381498,1.5661951,0.0,0,7.7813101,0.0,0.10970087,97.92654398715116,8.4262524,365.36374,-9.2834253,97.92654398715116,,,,,0.0962021545934066,93.78210352835019,0.09619719551845549,0.09619719551845549
2020,2020,165.3533,9.0898952,1.6090285,0.0,0,7.7283502,0.0,0.11328877,98.14968756694849,8.3711777,365.44843,-9.2827206,98.14968756694849,,,,,0.10038485696703298,93.82455409276058,0.10037989564735154,0.10037989564735154
2022,2022,165.3537,9.0352116,1.6708652,0.0,0,7.6753898,0.0,0.11758974,97.07487229463575,8.3171129,365.53314,-9.2831879,97.07487229463575,,,,,0.10456755934065934,93.86533261378437,0.10456259586466307,0.10456259586466307
2024,2024,165.3541,9.1194754,1.7237386,0.0,0,7.6224298,0.0,0.12146928,97.56214995174015,8.2653189,365.61783,-9.2822351,97.56214995174015,,,,,0.10875026171428571,93.90456801953367,0.10874529616357251,0.10874529616357251
2026,2026,165.3545,9.2821722,1.7773423,0.0,0,7.5694699,0.0,0.12588696,98.87127995998353,8.2070417,365.70251,-9.2830687,98.87127995998353,,,,,0.11293296408791209,93.94237479986775,0.11292799653802581,0.11292799653802581
2028,2028,165.3549,9.236762,1.8407034,0.0,0,7.51651,0.0,0.13025147,97.88005212713692,8.1506901,365.7872,-9.2836027,97.88005212713692,,,,,0.11711566646153847,93.97885509026155,0.11711069698262215,0.11711069698262215
2030,2030,165.3553,9.3156147,1.9031997,0.0,0,7.4635501,0.0,0.13529457,98.21070150422156,8.0918713,365.87189,-9.2831211,98.21070150422156,,,,,0.12129836883516484,94.01410039235537,0.12129339749252306,0.12129339749252306
2032,2032,165.3557,9.2057114,1.9535009,0.0,0,7.4105897,0.0,0.13936977,96.65038140004349,8.0358095,365.95657,-9.2835531,96.65038140004349,,,,,0.1254810712087912,94.0481930044762,0.1254760980633767,0.1254760980633767
2034,2034,165.3561,9.4069576,1.9955343,0.0,0,7.3593369,0.0,0.14226459,98.42025294783174,7.9807391,366.04126,-9.2831821,98.42025294783174,,,,,0.1296637735824176,94.08120721911908,0.1296587986912546,0.1296587986912546
2036,2036,165.3565,9.3902264,2.0489485,0.0,0,7.3089638,0.0,0.14673793,97.81006389835557,7.9289131,366.12595,-9.2830954,97.81006389835557,,,,,0.13384647595604396,94.1132103314593,0.13384149937259823,0.13384149937259823
2038,2038,165.3569,9.4385624,2.0985575,0.0,0,7.2585959,0.0,0.1503718,97.90727865898226,7.8789687,366.21063,-9.2833738,97.90727865898226,,,,,0.13802917832967032,94.14426349368841,0.13802420010417402,0.13802420010417402
2040,2040,165.3573,9.4719496,2.1479578,0.0,0,7.2082276,0.0,0.15391921,97.8475863348004,7.8294449,366.29532,-9.2835398,97.8475863348004,,,,,0.1422118807032967,94.17442244265821,0.14220690088303464,0.14220690088303464
2042,2042,165.3577,9.6092548,2.2003059,0.0,0,7.1578593,0.0,0.15854424,98.829453225995,7.7759266,366.30789,-9.2841663,98.829453225995,,,,,0.14639458307692307,94.20373812260296,0.14638960170648618,0.14638960170648618
2044,2044,165.3581,9.5873289,2.2534966,0.0,0,7.107491,0.0,0.16219933,98.16135913854282,7.722373,365.91348,-9.2839756,98.16135913854282,,,,,0.15057728545054946,94.23225722082667,0.15057230257205997,0.15057230257205997
2046,2046,165.3585,9.5757141,2.3094473,0.0,0,7.0571237,0.0,0.16669196,97.57739729385008,7.6681747,365.51907,-9.283865,97.57739729385008,,,,,0.15475998782417583,94.26002263038586,0.1547550034774878,0.1547550034774878
2048,2048,165.3589,9.6069336,2.3522658,0.0,0,7.0067549,0.0,0.17067081,97.5384395228231,7.618618,365.12469,-9.2832251,97.5384395228231,,,,,0.1589426901978022,94.28707385147507,0.15893770442068098,0.15893770442068098
2050,2050,165.3593,9.7459536,2.398993,0.0,0,6.9563875,0.0,0.17346089,98.55453990880213,7.5714412,364.73029,-9.282444,98.55453990880213,,,,,0.16312539257142858,94.31344734112808,0.16312040539971173,0.16312040539971173
2052,2052,165.3597,9.761548,2.4474723,0.0,0,6.9060192,0.0,0.17784378,98.30135695842915,7.5234857,364.33588,-9.2822647,98.30135695842915,,,,,0.16730809494505494,94.33917681872651,0.16730310641279697,0.16730310641279697
2054,2054,165.3601,9.7169628,2.490206,0.0,0,6.8556519,0.0,0.18130945,97.49181002457657,7.4744096,363.94147,-9.2837648,97.49181002457657,,,,,0.17149079731868133,94.36429353428143,0.17148580745828432,0.17148580745828432
2056,2056,165.3605,9.7862492,2.5480623,0.0,0,6.8052835,0.0,0.18527085,97.6952819968624,7.4214625,363.54706,-9.2840643,97.6952819968624,,,,,0.1756734996923077,94.38882650432726,0.1756685085346393,0.1756685085346393
2058,2058,165.3609,9.9122419,2.5921414,0.0,0,6.7554183,0.0,0.18957418,98.57358926560872,7.3747916,363.15265,-9.2839355,98.57358926560872,,,,,0.17985620206593406,94.41280272050919,0.17985120964043472,0.17985120964043472
2060,2060,165.3613,9.9441032,2.6397099,0.0,0,6.7073793,0.0,0.19307476,98.4795764247036,7.3252101,362.75827,-9.2830238,98.4795764247036,,,,,0.18403890443956045,94.43624733416621,0.18403391077434061,0.18403391077434061
2062,2062,165.3617,9.8918209,2.7002828,0.0,0,6.6594586,0.0,0.19776779,97.44131629034683,7.2780228,362.36386,-9.2824373,97.44131629034683,,,,,0.1882216068131868,94.45918382035426,0.1882166119351156,0.1882166119351156
2064,2064,165.3621,9.9269533,2.7356856,0.0,0,6.6115384,0.0,0.20132951,97.48207376611336,7.2301779,361.96945,-9.2825098,97.48207376611336,,,,,0.1924043091868132,94.48163412406537,0.1923993131215993,0.1923993131215993
2066,2066,165.3625,10.031512,2.7802339,0.0,0,6.5636187,0.0,0.204382,98.12056062796944,7.1796041,361.57504,-9.2839403,98.12056062796944,,,,,0.19658701156043956,94.50361879063553,0.19658201433270525,0.19658201433270525
2068,2068,165.3629,10.108747,2.8335557,0.0,0,6.5156989,0.0,0.20894687,98.4076463544443,7.1328602,361.18063,-9.2846851,98.4076463544443,,,,,0.20076971393406595,94.52515708267147,0.20076471556741493,0.20076471556741493
2070,2070,165.3633,10.109157,2.8744314,0.0,0,6.4677792,0.0,0.21251687,98.05254318069775,7.0842848,360.78622,-9.283391,98.05254318069775,,,,,0.20495241630769231,94.54626708493922,0.204947416824772,0.204947416824772
2072,2072,165.3637,10.142405,2.9295084,0.0,0,6.4198589,0.0,0.21651204,97.88953334902806,7.0364084,360.39185,-9.2822304,97.88953334902806,,,,,0.20913511868131868,94.56696579876751,0.20913011810387744,0.20913011810387744
2074,2074,165.3641,10.200469,2.9780786,0.0,0,6.3719387,0.0,0.22123326,98.01930102250094,6.9886065,359.99744,-9.2827072,98.01930102250094,,,,,0.21331782105494507,94.58726922710875,0.2133128194038851,0.2133128194038851
2076,2076,165.3645,10.261048,3.0228174,0.0,0,6.324019,0.0,0.22473121,98.20235884053557,6.9379644,359.60303,-9.282814,98.20235884053557,,,,,0.21750052342857143,94.60719245141696,0.21749552072399742,0.21749552072399742
2078,2078,165.3649,10.273978,3.0762265,0.0,0,6.2760992,0.0,0.22878152,97.8490512099162,6.8893237,359.20862,-9.284153,97.8490512099162,,,,,0.22168322580219782,94.62674970129632,0.22167822206346202,0.22167822206346202
2080,2080,165.3653,10.332596,3.1185398,0.0,0,6.228179,0.0,0.23306149,98.0271861782953,6.8409204,358.81421,-9.2840567,98.0271861782953,,,,,0.22586592817582418,94.64595441763217,0.2258609234215681,0.2258609234215681
2082,2082,165.3657,10.37124,3.1667886,0.0,0,6.1802592,0.0,0.23656249,97.95867854240944,6.7921948,358.4198,-9.2846756,97.95867854240944,,,,,0.23004863054945054,94.66481930997566,0.23004362479764365,0.23004362479764365
2084,2084,165.3661,10.413713,3.2127392,0.0,0,6.133883,0.0,0.24056274,97.94370081799096,6.7455969,358.02542,-9.2837982,97.94370081799096,,,,,0.23423133292307693,94.68335640880257,0.2342263261910525,0.2342263261910525
2086,2086,165.3665,10.455701,3.2540381,0.0,0,6.0883021,0.0,0.24458826,97.96304694421454,6.6975012,357.63101,-9.2826328,97.96304694421454,,,,,0.2384140352967033,94.70157711323574,0.23840902760119184,0.23840902760119184
2088,2088,165.3669,10.509563,3.3120468,0.0,0,6.0427265,0.0,0.24866982,97.93740482073788,6.6488538,357.2366,-9.2832232,97.93740482073788,,,,,0.2425967376703297,94.7194922344997,0.24259172902749007,0.24259172902749007
2090,2090,165.3673,10.581858,3.3555956,0.0,0,5.9971499,0.0,0.25290731,98.21022213285916,6.5999637,356.84219,-9.2831602,98.21022213285916,,,,,0.24677944004395605,94.73711203582052,0.2467744304694044,0.2467744304694044
2092,2092,165.3677,10.591735,3.4025173,0.0,0,5.9515738,0.0,0.25706318,97.8695018428946,6.5517206,356.45117,-9.2835073,97.8695018428946,,,,,0.2509621424175824,94.75444626897512,0.25095713192641916,0.25095713192641916
2094,2094,165.3681,10.606057,3.4573381,0.0,0,5.9059982,0.0,0.26107797,97.4959176311697,6.5048108,356.09042,-9.2837715,97.4959176311697,,,,,0.2551448447912088,94.77150420779228,0.2551398333980441,0.2551398333980441
2096,2096,165.3685,10.677283,3.4971936,0.0,0,5.8604221,0.0,0.26537064,97.78033780705812,6.4552164,355.72968,-9.28407,97.78033780705812,,,,,0.2593275471648352,94.78829467893343,0.2593225348838123,0.2593225348838123
2098,2098,165.3689,10.752674,3.544327,0.0,0,5.8148456,0.0,0.26917809,98.02966931118986,6.4089937,355.3689,-9.2846889,98.02966931118986,,,,,0.2635102495384615,94.80482609033149,0.2635052363832792,0.2635052363832792
2100,2100,165.3693,10.789203,3.5990839,0.0,0,5.7692699,0.0,0.27349806,97.84846797673508,6.3616028,355.00815,-9.2831736,97.84846797673508,,,,,0.2676929519120879,94.82110645731868,0.26768793789602113,0.26768793789602113
2102,2102,165.3697,10.807729,3.6394849,0.0,0,5.7236938,0.0,0.27789763,97.6363782022146,6.3128538,354.6474,-9.2828588,97.6363782022146,,,,,0.2718756542857143,94.83714342672984,0.27187063942163353,0.27187063942163353
2104,2104,165.3701,10.829756,3.6903262,0.0,0,5.6781182,0.0,0.28174245,97.35601276098284,6.2657046,354.28665,-9.2823706,97.35601276098284,,,,,0.27605835665934064,94.85294429927123,0.2760533409597304,0.2760533409597304
2106,2106,165.3705,10.912553,3.7412558,0.0,0,5.6325421,0.0,0.28637415,97.61641268493022,6.2191682,353.92587,-9.28302,97.61641268493022,,,,,0.28024105903296703,94.8685160500918,0.280236042509943,0.280236042509943
2108,2108,165.3709,10.97462,3.7799921,0.0,0,5.5874209,0.0,0.29028088,97.80142830131352,6.1700487,353.56512,-9.283371,97.80142830131352,,,,,0.2844237614065934,94.88386534798964,0.2844187440719186,0.2844187440719186
2110,2110,165.3713,11.00006,3.8294463,0.0,0,5.5439529,0.0,0.29393277,97.5543705829336,6.1245646,353.20438,-9.2847471,97.5543705829336,,,,,0.2886064637802198,94.89899857307235,0.2886014456453198,0.2886014456453198
2112,2112,165.3717,11.042579,3.8791046,0.0,0,5.5005927,0.0,0.2990298,97.45383137174755,6.0764904,352.84363,-9.2852068,97.45383137174755,,,,,0.29278916615384615,94.91392183325628,0.2927841472298237,0.2927841472298237
2114,2114,165.3721,11.091552,3.9245772,0.0,0,5.4572325,0.0,0.30304542,97.44667948905676,6.0295196,352.48285,-9.2834759,97.44667948905676,,,,,0.29697186852747254,94.92864097961899,0.29696684882512087,0.29696684882512087
2116,2116,165.3725,11.159499,3.9745898,0.0,0,5.4138727,0.0,0.30711851,97.55740477456688,5.9815774,352.1221,-9.2827425,97.55740477456688,,,,,0.30115457090109893,94.94316162055595,0.3011495504309148,0.3011495504309148
2118,2118,165.3729,11.218306,4.0203505,0.0,0,5.3705125,0.0,0.31198385,97.62420747345313,5.935781,351.76135,-9.2833996,97.62420747345313,,,,,0.30533727327472526,94.95748913513677,0.3053322520469209,0.3053322520469209
2120,2120,165.3733,11.242106,4.0667605,0.0,0,5.3271527,0.0,0.31571057,97.37666564663829,5.8877592,351.4006,-9.2842932,97.37666564663829,,,,,0.30951997564835165,94.97162868541606,0.30951495367286636,0.30951495367286636
2122,2122,165.3737,11.281223,4.1145964,0.0,0,5.2837925,0.0,0.31992337,97.24517913792336,5.8397565,351.03986,-9.284874,97.24517913792336,,,,,0.31370267802197804,94.985585228047,0.31369765530848903,0.31369765530848903
2124,2124,165.3741,11.318838,4.1568313,0.0,0,5.2404327,0.0,0.32458159,97.15275036073054,5.7900524,350.67908,-9.2843723,97.15275036073054,,,,,0.3178853803956044,94.99936352500833,0.31788035695353706,0.31788035695353706
2126,2126,165.3745,11.389072,4.206903,0.0,0,5.197073,0.0,0.32836619,97.2584768743861,5.7447996,350.31833,-9.2841873,97.2584768743861,,,,,0.32206808276923077,95.01296815370915,0.32206305860776846,0.32206305860776846
2128,2128,165.3749,11.453753,4.2538238,0.0,0,5.1537127,0.0,0.33306038,97.34229615951271,5.6949902,349.95758,-9.2825603,97.34229615951271,,,,,0.32625078514285716,95.02640351647165,0.3262457602709504,0.3262457602709504
2130,2130,165.3753,11.49268,4.2981105,0.0,0,5.1103525,0.0,0.33762789,97.22934188742252,5.6474042,349.59683,-9.2825451,97.22934188742252,,,,,0.33043348751648355,95.03967384931367,0.33042846194285896,0.33042846194285896
2132,2132,165.3757,11.530754,4.355063,0.0,0,5.0669928,0.0,0.34185171,96.97878261261933,5.6028318,349.23605,-9.2832642,96.97878261261933,,,,,0.3346161898901099,95.05278323031882,0.3346111636232784,0.3346111636232784
2134,2134,165.3761,11.561649,4.3962421,0.0,0,5.0250292,0.0,0.34665629,96.82339669973716,5.5553803,348.87531,-9.2840338,96.82339669973716,,,,,0.3387988922637363,95.06573558734947,0.3387938653120011,0.3387938653120011
2136,2136,165.3765,11.611034,4.4372211,0.0,0,4.9837847,0.0,0.35036817,96.82195475297954,5.5072236,348.51456,-9.2850704,96.82195475297954,,,,,0.34298159463736266,95.07853470535927,0.3429765670088269,0.3429765670088269
2138,2138,165.3769,11.690038,4.4916329,0.0,0,4.9425445,0.0,0.35499561,96.92587380087085,5.4606299,348.15381,-9.2854519,96.92587380087085,,,,,0.347164297010989,95.09118423333054,0.34715926871356273,0.34715926871356273
2140,2140,165.3773,11.70984,4.5287557,0.0,0,4.9013047,0.0,0.35949618,96.71080228610504,5.4155989,347.79303,-9.2834148,96.71080228610504,,,,,0.3513469993846154,95.10368769061601,0.35134197042602267,0.35134197042602267
2142,2142,165.3777,11.745206,4.5754275,0.0,0,4.8600645,0.0,0.36317596,96.5245834696154,5.3694739,347.43869,-9.2824507,96.5245834696154,,,,,0.3555297017582418,95.11604847317572,0.355524672146027,0.355524672146027
2144,2144,165.3781,11.788837,4.6286659,0.0,0,4.8188248,0.0,0.36823803,96.33545243732009,5.3237553,347.20456,-9.2825327,96.33545243732009,,,,,0.3597124041318681,95.12826985911722,0.35970737387340246,0.35970737387340246
2146,2146,165.3785,11.859876,4.6644855,0.0,0,4.7775846,0.0,0.37246743,96.54520024194122,5.2788749,346.97046,-9.2836981,96.54520024194122,,,,,0.3638951065054945,95.14035501424783,0.36389007560798164,0.36389007560798164
2148,2148,165.3789,11.928674,4.7149534,0.0,0,4.7363443,0.0,0.37645867,96.57977012080336,5.2377677,346.73636,-9.283947,96.57977012080336,,,,,0.3680778088791209,95.15230699711753,0.3680727773496028,0.3680727773496028
2150,2150,165.3793,11.956252,4.7616639,0.0,0,4.6951046,0.0,0.3815873,96.31550854344434,5.1894631,346.50223,-9.2836542,96.31550854344434,,,,,0.3722605112527473,95.16412876377457,0.37225547909810963,0.37225547909810963
2152,2152,165.3797,11.988939,4.7998567,0.0,0,4.6538649,0.0,0.38547409,96.17904726020514,5.1447363,346.26813,-9.2840633,96.17904726020514,,,,,0.3764432136263736,95.17582317237776,0.37643818085335096,0.37643818085335096
2154,2154,165.3801,12.038085,4.8483248,0.0,0,4.6126242,0.0,0.3896738,96.06384056155996,5.1006293,346.034,-9.2830763,96.06384056155996,,,,,0.380625916,95.1873929874259,0.3806208826151807,0.3806208826151807
2156,2156,165.3805,12.114473,4.8927226,0.0,0,4.5713844,0.0,0.39486563,96.20370875483064,5.0523376,345.7999,-9.2828484,96.20370875483064,,,,,0.3848086183736264,95.1988408838789,0.38480358438345724,0.38480358438345724
2158,2158,165.3809,12.173349,4.9373932,0.0,0,4.5305572,0.0,0.39872545,96.19630749939952,5.0124102,345.5658,-9.2823896,96.19630749939952,,,,,0.38899132074725273,95.21016945095288,0.3889862861580438,0.3889862861580438
2160,2160,165.3813,12.199394,4.9840746,0.0,0,4.4912271,0.0,0.40315181,95.9046678648248,4.9662104,345.33167,-9.2830038,95.9046678648248,,,,,0.3931740231208791,95.22138119572828,0.3931689879388078,0.3931689879388078
2162,2162,165.3817,12.226334,5.0237241,0.0,0,4.4519949,0.0,0.40806201,95.69295264419932,4.9243994,345.09756,-9.2840261,95.69295264419932,,,,,0.3973567254945055,95.23247854666944,0.3973516897256208,0.3973516897256208
2164,2164,165.3821,12.272808,5.0720568,0.0,0,4.4127631,0.0,0.41192201,95.53842030537297,4.8791766,344.86346,-9.2842712,95.53842030537297,,,,,0.4015394278681319,95.24346385685064,0.40153439151835835,0.40153439151835835
2166,2166,165.3825,12.353411,5.1151991,0.0,0,4.3735313,0.0,0.41656852,95.70016364799952,4.8351755,344.62933,-9.2828655,95.70016364799952,,,,,0.40572213024175824,95.25433940705052,0.4057170933168998,0.4057170933168998
2168,2168,165.3829,12.423361,5.1543531,0.0,0,4.3342991,0.0,0.42103687,95.81695162719562,4.7904181,344.39523,-9.28193,95.81695162719562,,,,,0.40990483261538463,95.26510740867457,0.40989979512112834,0.40989979512112834
2170,2170,165.3833,12.460442,5.206326,0.0,0,4.2950673,0.0,0.4252342,95.53690384619811,4.7463264,344.1611,-9.2822599,95.53690384619811,,,,,0.414087534989011,95.27577000660861,0.4140824969309305,0.4140824969309305
2172,2172,165.3837,12.48038,5.2453418,0.0,0,4.2558346,0.0,0.43007609,95.2641141542473,4.7013683,343.927,-9.2826986,95.2641141542473,,,,,0.41827023736263735,95.28632928180946,0.41826519874619617,0.41826519874619617
2174,2174,165.3841,12.534426,5.2872624,0.0,0,4.2166028,0.0,0.43425009,95.2172698342334,4.6589146,343.6929,-9.2834435,95.2172698342334,,,,,0.42245293973626374,95.29678725382772,0.4224479005668187,0.4224479005668187
2176,2176,165.3845,12.609901,5.3385782,0.0,0,4.177371,0.0,0.43881246,95.22481100639688,4.6168437,343.45877,-9.2837925,95.22481100639688,,,,,0.42663564210989013,95.30714588326553,0.4266306023926943,0.4266306023926943
2178,2178,165.3849,12.676383,5.3716297,0.0,0,4.1381388,0.0,0.44343099,95.360468253863,4.574306,343.22467,-9.283061,95.360468253863,,,,,0.43081834448351647,95.31740707400736,0.4308133042237223,0.4308133042237223
2180,2180,165.3853,12.695992,5.4138904,0.0,0,4.098907,0.0,0.44715595,95.03872995467746,4.5314183,342.99057,-9.2829533,95.03872995467746,,,,,0.43500104685714286,95.32757267537772,0.434996006059805,0.434996006059805
2182,2182,165.3857,12.738661,5.4635806,0.0,0,4.0596752,0.0,0.45203808,94.80446441984591,4.4860234,342.75644,-9.2820864,94.80446441984591,,,,,0.43918374923076925,95.33764448426615,0.4391787079008473,0.4391787079008473
2184,2184,165.3861,12.80549,5.4985785,0.0,0,4.021708,0.0,0.45664817,94.90976435693275,4.4446602,342.52234,-9.281724,94.90976435693275,,,,,0.44336645160439564,95.34762424706385,0.4433614097467569,0.4433614097467569
2186,2186,165.3865,12.888484,5.5437956,0.0,0,3.9843915,0.0,0.46053892,95.01500545949108,4.4033132,342.28821,-9.2826347,95.01500545949108,,,,,0.447549153978022,95.35751366151769,0.44754411159744395,0.44754411159744395
2188,2188,165.3869,12.952784,5.5893145,0.0,0,3.9470794,0.0,0.46582785,94.9731166554233,4.3601556,342.05411,-9.2838888,94.9731166554233,,,,,0.45173185635164836,95.36731437860067,0.45172681345282123,0.45172681345282123
2190,2190,165.3873,12.971778,5.6240315,0.0,0,3.9097676,0.0,0.46986216,94.71827725814276,4.3164225,341.82001,-9.283658,94.71827725814276,,,,,0.45591455872527475,95.37702800415728,0.4559095153128038,0.4559095153128038
2192,2192,165.3877,13.00938,5.6694541,0.0,0,3.8724556,0.0,0.47381309,94.4756476172453,4.277339,341.58591,-9.2829838,94.4756476172453,,,,,0.4600972610989011,95.38665610054143,0.46009221717730897,0.46009221717730897
2194,2194,165.3881,13.081762,5.7082076,0.0,0,3.8351436,0.0,0.47888979,94.5575251184011,4.2366724,341.37241,-9.2828035,94.5575251184011,,,,,0.4642799634725275,95.39620018820943,0.4642749190462565,0.4642749190462565
2196,2196,165.3885,13.156265,5.7446094,0.0,0,3.7978315,0.0,0.48243305,94.67678665414368,4.1928811,341.15891,-9.2830753,94.67678665414368,,,,,0.46846266584615387,95.4056617471776,0.46845762091956805,0.46845762091956805
2198,2198,165.3889,13.206782,5.7896657,0.0,0,3.7605195,0.0,0.48681635,94.51932769717304,4.1558857,340.94543,-9.2830105,94.51932769717304,,,,,0.4726453682197802,95.41504221848201,0.47264032279716733,0.47264032279716733
2200,2200,165.3893,13.229138,5.8281374,0.0,0,3.7232075,0.0,0.49208137,94.23366115734817,4.1138458,340.73193,-9.2819071,94.23366115734817,,,,,0.4768280705934066,95.4243430054901,0.47682302467898025,0.47682302467898025
2202,2202,165.3897,13.285624,5.8701973,0.0,0,3.6858957,0.0,0.49573573,94.14664944325928,4.0767479,340.51843,-9.2822905,94.14664944325928,,,,,0.481010772967033,95.43356547525612,0.4810057265649345,0.4810057265649345
2204,2204,165.3901,13.362424,5.9085016,0.0,0,3.6485837,0.0,0.50014716,94.24257527518756,4.0360732,340.30496,-9.2832251,94.24257527518756,,,,,0.4851934753406594,95.44271095975853,0.48518842845495963,0.48518842845495963
2206,2206,165.3905,13.431986,5.9398451,0.0,0,3.6112714,0.0,0.50437552,94.36439543134178,3.9996116,340.09146,-9.2837963,94.36439543134178,,,,,0.4893761777142857,95.45178075703738,0.489371130348987,0.489371130348987
2208,2208,165.3909,13.476682,5.9856653,0.0,0,3.5743327,0.0,0.50812143,94.1374231386315,3.9597654,339.87796,-9.2831783,94.1374231386315,,,,,0.4935588800879121,95.46077613242089,0.4935538322469497,0.4935538322469497
2210,2210,165.3913,13.515279,6.020669,0.0,0,3.538748,0.0,0.51292104,93.9925243182484,3.9231369,339.66449,-9.2821779,93.9925243182484,,,,,0.4977415824615385,95.46969831956977,0.4977365341487825,0.4977365341487825
2212,2212,165.3917,13.563208,6.0558295,0.0,0,3.5032518,0.0,0.5169338,93.90796318022718,3.8854055,339.45099,-9.281848,93.90796318022718,,,,,0.5019242848351648,95.47854852155429,0.5019192360544217,0.5019192360544217
2214,2214,165.3921,13.644002,6.1038342,0.0,0,3.4677558,0.0,0.5212158,93.89334730190204,3.8485775,339.23749,-9.2819948,93.89334730190204,,,,,0.5061069872087912,95.4873279118093,0.5061019379638054,0.5061019379638054
2216,2216,165.3925,13.703314,6.1330786,0.0,0,3.43226,0.0,0.5258258,93.95026308425194,3.8085089,339.02402,-9.2832842,93.95026308425194,,,,,0.5102896895824176,95.49603763517474,0.510284639876873,0.510284639876873
2218,2218,165.3929,13.765594,6.1693816,0.0,0,3.3967638,0.0,0.52933294,93.93920157208473,3.769325,338.81052,-9.2822218,93.93920157208473,,,,,0.514472391956044,95.50467880879346,0.5144673417935655,0.5144673417935655
2220,2220,165.3933,13.809322,6.215209,0.0,0,3.3612678,0.0,0.53409809,93.6828008749654,3.7337537,338.59705,-9.282361,93.6828008749654,,,,,0.5186550943296704,95.51325252294241,0.5186500437138251,0.5186500437138251
2222,2222,165.3937,13.858036,6.2420425,0.0,0,3.3257718,0.0,0.53827935,93.68723532637794,3.6962907,338.38354,-9.2827682,93.68723532637794,,,,,0.5228377967032967,95.52175984197633,0.5228327456375954,0.5228327456375954
2224,2224,165.3941,13.935164,6.2828789,0.0,0,3.2902758,0.0,0.54188854,93.70965890933525,3.6571038,338.17004,-9.2827244,93.70965890933525,,,,,0.527020499076923,95.53020180512397,0.5270154475648219,0.5270154475648219
2226,2226,165.3945,14.00873,6.3240881,0.0,0,3.2547796,0.0,0.54700619,93.69808859994824,3.6207623,337.95657,-9.2825708,93.69808859994824,,,,,0.5312032014505494,95.53857942721503,0.5311981494954506,0.5311981494954506
2228,2228,165.3949,14.073476,6.3511457,0.0,0,3.2192838,0.0,0.55071193,93.797155086159,3.5860949,337.74307,-9.2825375,93.797155086159,,,,,0.5353859038241758,95.5468936994936,0.5353808514294291,0.5353808514294291
2230,2230,165.3953,14.116409,6.3915462,0.0,0,3.1837878,0.0,0.5542177,93.58303056722474,3.5468712,337.52957,-9.2826118,93.58303056722474,,,,,0.5395686061978022,95.55514559037611,0.5395635533667064,0.5395635533667064
2232,2232,165.3957,14.163875,6.4283996,0.0,0,3.1482918,0.0,0.55959964,93.43976794845294,3.5146928,337.3161,-9.2835121,93.43976794845294,,,,,0.5437513085714286,95.56333604607134,0.5437462553072321,0.5437462553072321
2234,2234,165.3961,14.232369,6.4598398,0.0,0,3.1139338,0.0,0.56305283,93.49902527738588,3.4796193,337.1026,-9.2824612,93.49902527738588,,,,,0.547934010945055,95.57146599129217,0.5479289572509577,0.5479289572509577
2236,2236,165.3965,14.334474,6.5014553,0.0,0,3.0801623,0.0,0.56715256,93.64634963282252,3.4435768,336.8891,-9.2822771,93.64634963282252,,,,,0.5521167133186813,95.57953632994091,0.552111659197835,0.552111659197835
2238,2238,165.3969,14.3998,6.5361514,0.0,0,3.0463943,0.0,0.57249439,93.63466242853538,3.407428,336.67563,-9.2824306,93.63466242853538,,,,,0.5562994156923077,95.58754794564616,0.5562943611478176,0.5562943611478176
2240,2240,165.3973,14.427806,6.5740385,0.0,0,3.0126262,0.0,0.57596797,93.33700152395149,3.3728235,336.46213,-9.2827425,93.33700152395149,,,,,0.5604821180659341,95.59550170245389,0.5604770631008598,0.5604770631008598
2242,2242,165.3977,14.486943,6.6108837,0.0,0,2.9788582,0.0,0.58044207,93.25102911007558,3.3382447,336.24863,-9.2824535,93.25102911007558,,,,,0.5646648204395605,95.60339844536924,0.5646597650569167,0.5646597650569167
2244,2244,165.3981,14.572481,6.640511,0.0,0,2.9450903,0.0,0.58485651,93.42260693013692,3.3014617,336.24268,-9.2824345,93.42260693013692,,,,,0.5688475228131868,95.61123900087227,0.5688424670159448,0.5688424670159448
2246,2246,165.3985,14.669436,6.6808858,0.0,0,2.9113221,0.0,0.58841211,93.52416593098194,3.2654819,336.24753,-9.2817593,93.52416593098194,,,,,0.5730302251868132,95.61902417750944,0.5730251689779012,0.5730251689779012
2248,2248,165.3989,14.729045,6.7121696,0.0,0,2.8775542,0.0,0.59295088,93.499595167782,3.2300525,336.25238,-9.2816772,93.499595167782,,,,,0.5772129275604396,95.62675476643065,0.5772078709427442,0.5772078709427442
2250,2250,165.3993,14.777076,6.7435126,0.0,0,2.8437862,0.0,0.59704739,93.39776190639834,3.1949391,336.25723,-9.2824888,93.39776190639834,,,,,0.5813956299340659,95.63443154182613,0.5813905729104326,0.5813905729104326
2252,2252,165.3997,14.841427,6.7906418,0.0,0,2.8100181,0.0,0.60141647,93.19016115551145,3.1596224,336.26208,-9.2834444,93.19016115551145,,,,,0.5855783323076923,95.64205526140884,0.5855732748809267,0.5855732748809267
2254,2254,165.4001,14.939795,6.8207884,0.0,0,2.7762504,0.0,0.60651308,93.41220579102946,3.1250751,336.26694,-9.2830172,93.41220579102946,,,,,0.5897610346813187,95.64962666691848,0.589755976854187,0.589755976854187
2256,2256,165.4005,15.031834,6.8553219,0.0,0,2.7424822,0.0,0.61016911,93.5316646645611,3.0901191,336.27179,-9.2814789,93.5316646645611,,,,,0.5939437370549451,95.65714648459891,0.5939386788301754,0.5939386788301754
2258,2258,165.4009,15.081806,6.8969107,0.0,0,2.7090528,0.0,0.61477214,93.29152080451917,3.0535588,336.27664,-9.2803545,93.29152080451917,,,,,0.5981264394285715,95.66461542553672,0.5981213808088539,0.5981213808088539
2260,2260,165.4013,15.136976,6.9222369,0.0,0,2.6768525,0.0,0.61922473,93.29593170714352,3.014221,336.28149,-9.2796001,93.29593170714352,,,,,0.6023091418021979,95.67203418613705,0.6023040827901859,0.6023040827901859
2262,2262,165.4017,15.208533,6.9582186,0.0,0,2.644732,0.0,0.62264925,93.25608085674622,2.9820521,336.28635,-9.281682,93.25608085674622,,,,,0.6064918441758241,95.67940344853682,0.6064867847741352,0.6064867847741352
2264,2264,165.4021,15.30498,6.9999061,0.0,0,2.612612,0.0,0.62789029,93.28672856312052,2.946656,336.2912,-9.2827463,93.28672856312052,,,,,0.6106745465494505,95.68672388095901,0.6106694867606668,0.6106694867606668
2266,2266,165.4025,15.417205,7.0260606,0.0,0,2.580492,0.0,0.6320796,93.6163323392983,2.9114375,336.29605,-9.2814379,93.6163323392983,,,,,0.6148572489230769,95.69399613810039,0.6148521887497457,0.6148521887497457
2268,2268,165.4029,15.476049,7.0666256,0.0,0,2.548372,0.0,0.63603109,93.4217772576627,2.8791173,336.3009,-9.2822647,93.4217772576627,,,,,0.6190399512967033,95.7012208615266,0.6190348907413381,0.6190348907413381
2270,2270,165.4033,15.532187,7.1054969,0.0,0,2.516252,0.0,0.64178157,93.22984504084415,2.8415048,336.30576,-9.2810011,93.22984504084415,,,,,0.6232226536703297,95.70839867996864,0.6232175927354109,0.6232175927354109
2272,2272,165.4037,15.604596,7.1360044,0.0,0,2.4841321,0.0,0.64553189,93.24588290918396,2.8096764,336.31061,-9.2815275,93.24588290918396,,,,,0.6274053560439561,95.71553020970714,0.6274002947319314,0.6274002947319314
2274,2274,165.4041,15.71481,7.1741204,0.0,0,2.4520121,0.0,0.64960092,93.37773728576794,2.7745459,336.31546,-9.2814798,93.37773728576794,,,,,0.6315880584175825,95.72261605486733,0.6315829967308675,0.6315829967308675
2276,2276,165.4045,15.799938,7.2036915,0.0,0,2.4198921,0.0,0.65472585,93.4726616311577,2.739006,336.32031,-9.2809381,93.4726616311577,,,,,0.6357707607912088,95.72965680777166,0.635765698732188,0.635765698732188
2278,2278,165.4049,15.861618,7.2360268,0.0,0,2.3877721,0.0,0.65802276,93.38644438775222,2.7050934,336.32516,-9.2810793,93.38644438775222,,,,,0.6399534631648351,95.73665304922281,0.6399484007358622,0.6399484007358622
2280,2280,165.4053,15.920197,7.2728672,0.0,0,2.3556519,0.0,0.66249794,93.21540866087054,2.6713896,336.33002,-9.2809782,93.21540866087054,,,,,0.6441361655384615,95.74360534878892,0.6441311027418601,0.6441311027418601
2282,2282,165.4057,16.011412,7.3024936,0.0,0,2.3235321,0.0,0.66759527,93.33216932124252,2.6372011,336.33487,-9.2809572,93.33216932124252,,,,,0.6483188679120879,95.750514265144,0.6483138047501521,0.6483138047501521
2284,2284,165.4061,16.123079,7.3408914,0.0,0,2.2924447,0.0,0.67102146,93.4383838955962,2.6041875,336.33972,-9.2809896,93.4383838955962,,,,,0.6525015702857143,95.75738034628738,0.652496506760709,0.652496506760709
2286,2286,165.4065,16.215031,7.3744226,0.0,0,2.2618895,0.0,0.67603713,93.49284022769513,2.5700819,336.34457,-9.281127,93.49284022769513,,,,,0.6566842726593407,95.76420412983816,0.6566792087735027,0.6566792087735027
2288,2288,165.4069,16.27808,7.4024725,0.0,0,2.2313375,0.0,0.68036169,93.45454769198734,2.5354612,336.34943,-9.2819319,93.45454769198734,,,,,0.6608669750329671,95.7709861433092,0.6608619107885051,0.6608619107885051
2290,2290,165.4073,16.34885,7.4448814,0.0,0,2.2007856,0.0,0.68446112,93.25062058102976,2.503684,336.35428,-9.2816515,93.25062058102976,,,,,0.6650496774065934,95.77772690434203,0.6650446128056887,0.6650446128056887
2292,2292,165.4077,16.437534,7.4724236,0.0,0,2.1702335,0.0,0.68944895,93.3579546832902,2.4726224,336.35913,-9.2811556,93.3579546832902,,,,,0.6692323797802198,95.78442692095223,0.6692273148250271,0.6692273148250271
2294,2294,165.4081,16.545715,7.5021687,0.0,0,2.1396816,0.0,0.69324189,93.539128198873,2.439559,336.19641,-9.2811003,93.539128198873,,,,,0.6734150821538462,95.79108669178815,0.6734100168464935,0.6734100168464935
2296,2296,165.4085,16.6371,7.5434365,0.0,0,2.1091297,0.0,0.6975686,93.45129553472414,2.4068434,336.01517,-9.2805948,93.45129553472414,,,,,0.6775977845274725,95.79770670632489,0.6775927188700621,0.6775927188700621
2298,2298,165.4089,16.692152,7.5663757,0.0,0,2.0785778,0.0,0.70234746,93.42337924213167,2.3751507,335.83389,-9.2811642,93.42337924213167,,,,,0.6817804869010989,95.8042874451212,0.6817754208957076,0.6817754208957076
2300,2300,165.4093,16.774078,7.5992417,0.0,0,2.0480258,0.0,0.70562643,93.39644954204933,2.3425171,335.65265,-9.2815266,93.39644954204933,,,,,0.6859631892747253,95.81082938001148,0.6859581229234051,0.6859581229234051
2302,2302,165.4097,16.865967,7.6390319,0.0,0,2.0174737,0.0,0.71072632,93.3170591584758,2.3091893,335.47141,-9.2806845,93.3170591584758,,,,,0.6901458916483517,95.81733297435768,0.6901408249531299,0.6901408249531299
2304,2304,165.4101,16.980677,7.6613708,0.0,0,1.9869215,0.0,0.71526879,93.61763615246797,2.2771306,335.29016,-9.2805967,93.61763615246797,,,,,0.694328594021978,95.82379868317517,0.694323526984858,0.694323526984858
2306,2306,165.4105,17.079645,7.6982131,0.0,0,1.9563695,0.0,0.71885204,93.60899436178244,2.2433448,335.10892,-9.2806997,93.60899436178244,,,,,0.6985112963956044,95.8302269534039,0.6985062290185658,0.6985062290185658
2308,2308,165.4109,17.145739,7.7315102,0.0,0,1.9261233,0.0,0.72426331,93.46830954401776,2.2167783,334.92764,-9.2806444,93.46830954401776,,,,,0.7026939987692308,95.83661822409339,0.7026889310542302,0.7026889310542302
2310,2310,165.4113,17.234276,7.7555523,0.0,0,1.8969866,0.0,0.72778785,93.58591441755208,2.1835251,334.7464,-9.2810078,93.58591441755208,,,,,0.7068767011428572,95.84297292654102,0.7068716330918282,0.7068716330918282
2312,2312,165.4117,17.335302,7.7929649,0.0,0,1.8679224,0.0,0.73184377,93.56306567460597,2.1492035,334.56516,-9.2809143,93.56306567460597,,,,,0.7110594035164836,95.84929148450642,0.7110543351313375,0.7110543351313375
2314,2314,165.4121,17.444813,7.8236475,0.0,0,1.8388585,0.0,0.73761195,93.68246716497012,2.1191292,334.38391,-9.2795906,93.68246716497012,,,,,0.71524210589011,95.85557431438686,0.7152370371727361,0.7152370371727361
2316,2316,165.4125,17.548361,7.8533835,0.0,0,1.8097944,0.0,0.74090546,93.7786809139524,2.0860639,334.20267,-9.2791348,93.7786809139524,,,,,0.7194248082637362,95.86182182537593,0.7194197392160022,0.7194197392160022
2318,2318,165.4129,17.626953,7.8886948,0.0,0,1.7807305,0.0,0.74531263,93.65009527346308,2.0559661,334.02139,-9.2801352,93.65009527346308,,,,,0.7236075106373626,95.86803441965556,0.7236024412611147,0.7236024412611147
2320,2320,165.4133,17.713835,7.9137306,0.0,0,1.7516665,0.0,0.75042433,93.7207910673988,2.0264308,333.84015,-9.2804089,93.7207910673988,,,,,0.727790213010989,95.87421249249826,0.7277851433080527,0.7277851433080527
2322,2322,165.4137,17.81942,7.9477472,0.0,0,1.7226025,0.0,0.75366992,93.745088255909,1.9955238,333.65891,-9.2805395,93.745088255909,,,,,0.7319729153846154,95.88035643248547,0.7319678453567956,0.7319678453567956
2324,2324,165.4141,17.934723,7.9778895,0.0,0,1.6935385,0.0,0.75846589,93.87509267744858,1.9615514,333.47766,-9.280798,93.87509267744858,,,,,0.7361556177582418,95.88646662165279,0.7361505474073232,0.7361505474073232
2326,2326,165.4145,18.032112,8.0021534,0.0,0,1.6644745,0.0,0.76285815,93.99909675583726,1.9333258,333.29642,-9.2809238,93.99909675583726,,,,,0.7403383201318682,95.89254343559156,0.7403332494596156,0.7403332494596156
2328,2328,165.4149,18.111834,8.0418978,0.0,0,1.6354104,0.0,0.76678991,93.77995404821382,1.9060591,333.11514,-9.279974,93.77995404821382,,,,,0.7445210225054946,95.89858724362287,0.7445159515136534,0.7445159515136534
2330,2330,165.4153,18.207983,8.0682678,0.0,0,1.6063465,0.0,0.77175212,93.8543881110182,1.8735899,332.9339,-9.2796526,93.8543881110182,,,,,0.7487037248791208,95.9045984089556,0.748698653569417,0.748698653569417
2332,2332,165.4157,18.316322,8.0969114,0.0,0,1.5772824,0.0,0.77591068,93.95014119008908,1.8443764,332.75266,-9.2797098,93.95014119008908,,,,,0.7528864272527472,95.91057728875455,0.7528813556268881,0.7528813556268881
2334,2334,165.4161,18.44138,8.1354618,0.0,0,1.5491512,0.0,0.78031832,93.96457484947754,1.8144982,332.57141,-9.2793636,93.96457484947754,,,,,0.7570691296263736,95.91652423439572,0.7570640576860478,0.7570640576860478
2336,2336,165.4165,18.540485,8.1543226,0.0,0,1.5215,0.0,0.7849381,94.1610981289001,1.7857356,332.39017,-9.2808132,94.1610981289001,,,,,0.761251832,95.92243959145026,0.7612467597468778,0.7612467597468778
2338,2338,165.4169,18.628313,8.1817894,0.0,0,1.493852,0.0,0.78794366,94.15580136052236,1.7548785,332.20889,-9.2805338,94.15580136052236,,,,,0.7654345343736264,95.92832369987421,0.7654294618093602,0.7654294618093602
2340,2340,165.4173,18.725248,8.2211008,0.0,0,1.466204,0.0,0.79310673,93.9963493996994,1.724668,332.02765,-9.2793684,93.9963493996994,,,,,0.7696172367472528,95.93417689418851,0.7696121638734774,0.7696121638734774
2342,2342,165.4177,18.838457,8.241004,0.0,0,1.4385561,0.0,0.79753822,94.23382603962214,1.6964521,331.84641,-9.2785215,94.23382603962214,,,,,0.7737999391208792,95.9399995034743,0.7737948659392118,0.7737948659392118
2344,2344,165.4181,18.973158,8.2738266,0.0,0,1.4109081,0.0,0.8009885,94.35815142854952,1.6693604,331.67145,-9.2798948,94.35815142854952,,,,,0.7779826414945055,95.94579185161967,0.7779775680065463,0.7779775680065463
2346,2346,165.4185,19.098444,8.3097439,0.0,0,1.3832601,0.0,0.80694735,94.37591772362032,1.6414533,331.49759,-9.2804689,94.37591772362032,,,,,0.7821653438681319,95.95155425730458,0.7821602700754642,0.7821602700754642
2348,2348,165.4189,19.188293,8.3311424,0.0,0,1.355612,0.0,0.81082547,94.45755913700576,1.6114777,331.32373,-9.2795782,94.45755913700576,,,,,0.7863480462417582,95.95728703420745,0.7863429721459488,0.7863429721459488
2350,2350,165.4193,19.289429,8.3661261,0.0,0,1.3279642,0.0,0.8145588,94.35985361522832,1.5808899,331.14987,-9.2793865,94.35985361522832,,,,,0.7905307486153846,95.96299049107448,0.7905256742179839,0.7905256742179839
2352,2352,165.4197,19.413481,8.3928843,0.0,0,1.3003161,0.0,0.82011044,94.50819023183308,1.5504496,330.97601,-9.2788858,94.50819023183308,,,,,0.794713450989011,95.96866493177193,0.7947083762915533,0.7947083762915533
2354,2354,165.4201,19.558126,8.4181614,0.0,0,1.2726681,0.0,0.82343769,94.7759692327342,1.5216247,330.80215,-9.2782564,94.7759692327342,,,,,0.7988961533626374,95.97431065551717,0.7988910783666412,0.7988910783666412
2356,2356,165.4205,19.666561,8.4501114,0.0,0,1.2450202,0.0,0.8275699,94.74675401915712,1.4942333,330.62827,-9.2785759,94.74675401915712,,,,,0.8030788557362638,95.97992795683454,0.8030737804432321,0.8030737804432321
2358,2358,165.4209,19.749311,8.4752083,0.0,0,1.2176499,0.0,0.83281088,94.70784901298413,1.4656005,330.45441,-9.2794485,94.70784901298413,,,,,0.8072615581098901,95.98551712572333,0.8072564825213104,0.8072564825213104
2360,2360,165.4213,19.862228,8.5061197,0.0,0,1.191288,0.0,0.83618569,94.70728088371142,1.4356955,330.28055,-9.2799416,94.70728088371142,,,,,0.8114442604835165,95.99107844777596,0.8114391846008614,0.8114391846008614
2362,2362,165.4217,20.006973,8.5361347,0.0,0,1.1649919,0.0,0.84100235,94.86723745854889,1.4057859,330.10669,-9.280324,94.86723745854889,,,,,0.8156269628571429,95.99661220419412,0.81562188668187,0.81562188668187
2364,2364,165.4221,20.153505,8.5585833,0.0,0,1.1386957,0.0,0.8458823,95.16256285788133,1.3771396,329.93283,-9.2787046,95.16256285788133,,,,,0.8198096652307693,96.00211867193177,0.8198045887643215,0.8198045887643215
2366,2366,165.4225,20.270716,8.5947485,0.0,0,1.1123998,0.0,0.84952837,95.06864957586868,1.3491476,329.75897,-9.2783003,95.06864957586868,,,,,0.8239923676043956,96.00759812376039,0.8239872908482017,0.8239872908482017
2368,2368,165.4229,20.362679,8.6191893,0.0,0,1.0861038,0.0,0.85458928,95.06043610639772,1.3236126,329.58511,-9.2786026,95.06043610639772,,,,,0.828175069978022,96.01305082834824,0.8281699929334961,0.8281699929334961
2370,2370,165.4233,20.489817,8.6426029,0.0,0,1.0598078,0.0,0.85843647,95.23026718748248,1.2948987,329.41125,-9.2801027,95.23026718748248,,,,,0.8323577723516483,96.0184770503778,0.8323526950201909,0.8323526950201909
2372,2372,165.4237,20.645992,8.6790762,0.0,0,1.0335118,0.0,0.86258894,95.29101824752472,1.2652103,329.2374,-9.2793207,95.29101824752472,,,,,0.8365404747252747,96.02387705057325,0.8365353971082724,0.8365353971082724
2374,2374,165.4241,20.814018,8.6993914,0.0,0,1.0072157,0.0,0.8678202,95.69304548886844,1.2384472,329.06354,-9.2793636,95.69304548886844,,,,,0.8407231770989011,96.02925108582805,0.8407180991977268,0.8407180991977268
2376,2376,165.4245,20.916698,8.7266788,0.0,0,0.98091978,0.0,0.87139434,95.66094358016656,1.2105994,328.88968,-9.2786379,95.66094358016656,,,,,0.8449058794725275,96.03459940922258,0.8449008012885408,0.8449008012885408
2378,2378,165.4249,21.024885,8.7656345,0.0,0,0.95462376,0.0,0.87680584,95.43218917393308,1.1824056,328.71582,-9.2788029,95.43218917393308,,,,,0.8490885818461539,96.03992227015374,0.8490835033807014,0.8490835033807014
2380,2380,165.4253,21.16214,8.7825022,0.0,0,0.92832786,0.0,0.88131279,95.73983723299568,1.1534637,328.54196,-9.2784395,95.73983723299568,,,,,0.8532712842197803,96.04521991439192,0.8532662054741952,0.8532662054741952
2382,2382,165.4257,21.335882,8.8108902,0.0,0,0.90203184,0.0,0.88420689,95.99074884384562,1.1286167,328.3681,-9.27845,95.99074884384562,,,,,0.8574539865934067,96.05049258413744,0.8574489075690097,0.8574489075690097
2384,2384,165.4261,21.475676,8.8448734,0.0,0,0.87658417,0.0,0.88993096,95.97486296213133,1.1006775,328.19424,-9.2787571,95.97486296213133,,,,,0.8616366889670329,96.05574051807957,0.8616316096651321,0.8616316096651321
2386,2386,165.4265,21.585197,8.863286,0.0,0,0.85157341,0.0,0.89417917,96.1131385153174,1.0729889,328.02039,-9.2782803,96.1131385153174,,,,,0.8658193913406593,96.06096395153016,0.8658143117625502,0.8658143117625502
2388,2388,165.4269,21.710665,8.8984442,0.0,0,0.82656538,0.0,0.89812523,95.9973282566676,1.0447857,327.84653,-9.278389,95.9973282566676,,,,,0.8700020937142857,96.06616311639044,0.8699970138612515,0.8699970138612515
2390,2390,165.4273,21.845133,8.9245214,0.0,0,0.80155742,0.0,0.90389919,96.0885013876234,1.0172267,327.67267,-9.2781897,96.0885013876234,,,,,0.8741847960879121,96.07133824125646,0.8741797159612241,0.8741797159612241
2392,2392,165.4277,22.004887,8.9440794,0.0,0,0.77654946,0.0,0.90685254,96.41087110924472,0.99099863,327.49881,-9.277915,96.41087110924472,,,,,0.8783674984615385,96.0764895515547,0.878362418062456,0.878362418062456
2394,2394,165.4281,22.162109,8.9745321,0.0,0,0.75154138,0.0,0.91082376,96.50326968237567,0.9610101,327.31107,-9.2777491,96.50326968237567,,,,,0.8825502008351649,96.08161726949166,0.8825451201649354,0.8825451201649354
2396,2396,165.4285,22.298059,8.9974222,0.0,0,0.72653341,0.0,0.91653752,96.64416019546186,0.93525434,327.11987,-9.277874,96.64416019546186,,,,,0.8867329032087913,96.0867216141358,0.8867278222686507,0.8867278222686507
2398,2398,165.4289,22.437054,9.0263939,0.0,0,0.70152539,0.0,0.91982192,96.672065836309,0.90863687,326.92868,-9.278389,96.672065836309,,,,,0.8909156055824176,96.09180280156589,0.8909105243735904,0.8909105243735904
2400,2400,165.4293,22.57822,9.0577488,0.0,0,0.67651743,0.0,0.92503822,96.65456543577685,0.88233292,326.73752,-9.2783909,96.65456543577685,,,,,0.895098307956044,96.09686104478119,0.8950932264797434,0.8950932264797434
2402,2402,165.4297,22.745703,9.0805635,0.0,0,0.65150946,0.0,0.93060327,96.91284786929218,0.85168618,326.54633,-9.2776098,96.91284786929218,,,,,0.8992810103296703,96.10189655392425,0.8992759285870987,0.8992759285870987
2404,2404,165.4301,22.902576,9.1123753,0.0,0,0.62650138,0.0,0.9339062,96.93722404509734,0.82933867,326.35513,-9.2770529,96.93722404509734,,,,,0.9034637127032967,96.10690953617396,0.9034586306956451,0.9034586306956451
2406,2406,165.4305,23.036587,9.1329346,0.0,0,0.60149342,0.0,0.93864822,97.0857751297752,0.80227184,326.16394,-9.2777796,97.0857751297752,,,,,0.9076464150769231,96.11190019592867,0.907641332805372,0.907641332805372
2408,2408,165.4309,23.175552,9.150795,0.0,0,0.57673365,0.0,0.94221163,97.30552572140688,0.77396542,325.97275,-9.2793283,97.30552572140688,,,,,0.9118291174505495,96.11686873473778,0.9118240349162685,0.9118240349162685
2410,2410,165.4313,23.329514,9.1871271,0.0,0,0.55287462,0.0,0.94617289,97.20265099230724,0.74954104,325.78156,-9.2791739,97.20265099230724,,,,,0.9160118198241758,96.12181535148363,0.9160067370283242,0.9160067370283242
2412,2412,165.4317,23.506536,9.2065592,0.0,0,0.52907455,0.0,0.95156479,97.5363989286328,0.72128016,325.59039,-9.2774296,97.5363989286328,,,,,0.9201945221978022,96.12674024230357,0.9201894391415288,0.9201894391415288
2414,2414,165.4321,23.670557,9.2324924,0.0,0,0.50527453,0.0,0.95531327,97.67428893094376,0.69519377,325.3992,-9.2762861,97.67428893094376,,,,,0.9243772245714286,96.13164360076122,0.9243721412558721,0.9243721412558721
2416,2416,165.4325,23.800245,9.2691631,0.0,0,0.48147455,0.0,0.96053934,97.4378228712562,0.66930711,325.20801,-9.275547,97.4378228712562,,,,,0.928559926945055,96.13652561777451,0.9285548433713438,0.9285548433713438
2418,2418,165.4329,23.943539,9.2834396,0.0,0,0.45767456,0.0,0.96531433,97.72225022856487,0.64471871,325.01682,-9.277565,97.72225022856487,,,,,0.9327426293186813,96.1413864817218,0.932737545487934,0.932737545487934
2420,2420,165.4333,24.105267,9.3096066,0.0,0,0.43387455,0.0,0.96816522,97.82464724143465,0.61880863,324.82562,-9.2783041,97.82464724143465,,,,,0.9369253316923077,96.14622637852726,0.936920247605633,0.936920247605633
2422,2422,165.4337,24.284681,9.3411751,0.0,0,0.41007456,0.0,0.97383046,97.87493814653136,0.59383464,324.63443,-9.278101,97.87493814653136,,,,,0.9411080340659341,96.15104549162615,0.941102949724431,0.941102949724431
2424,2424,165.4341,24.448692,9.3541088,0.0,0,0.38627455,0.0,0.97775757,98.25637363813615,0.56883657,324.44327,-9.2771616,98.25637363813615,,,,,0.9452907364395604,96.15584400203835,0.9452856518443183,0.9452856518443183
2426,2426,165.4345,24.600714,9.3829746,0.0,0,0.36247453,0.0,0.98100591,98.23946902377436,0.54742277,324.25208,-9.2756119,98.23946902377436,,,,,0.9494734388131868,96.16062208844885,0.9494683539652857,0.9494683539652857
2427,2427,165.4347,24.671164,9.3896418,0.0,0,0.35057452,0.0,0.98390716,98.37536569117664,0.5349496,324.15646,-9.2760677,98.37536569117664,,,,,0.95156479,96.16300352783493,0.9515597050261716,0.9515597050261716