File: examples/hot axisymmetric compression example/data/12 fitted data ramberg/testID_0133.csv
level_0,index,Time(sec),Force(kN),Jaw(mm),PowAngle(deg),Power(W),Pram,PTemp,Strain,Stress(MPa),Stroke(mm),TC1(C),wedge(mm),uncorrected stress,sampled strain,sampled stress,fitting strain,fitting stress,model strain,ramberg stress,ramberg plastic strain,ramberg accumulated plastic strain
1774,1774,145.3667,1.1697621,0.0090850368,0.0,0,9.0044422,0.0,0.00034193476,14.250903528912788,9.9895821,300.78027,-9.3248425,14.250903528912788,0.00034193476,14.250903528912788,0.0,14.250903528912788,0.0,0.0,0.0,0.0
1777,1777,145.3673,5.4786444,0.081910416,0.0,0,8.9166508,0.0,0.004877578,66.39990382701819,9.8912134,300.95319,-9.3231211,66.39990382701819,0.15430027,124.76844793522504,0.146353188,124.40962005652585,0.0063493790889370925,109.88341350698448,0.006345123516124762,0.006345123516124762
1780,1780,145.3679,7.0650787,0.1944975,0.0,0,8.8288584,0.0,0.011987154,84.93925866444657,9.7862291,301.1261,-9.3211899,84.93925866444657,0.29306009,124.85201126198264,0.292706376,124.85244902001014,0.012698758177874185,111.68268452577165,0.01269443292276327,0.01269443292276327
1783,1783,145.3685,7.9067864,0.37756398,0.0,0,8.7416534,0.0,0.024808284,93.8066160158609,9.6475267,301.29901,-9.3195724,93.8066160158609,0.44218212,122.05364485293718,0.439059564,122.10585899176917,0.019048137266811278,112.77578623883089,0.019043769677977895,0.019043769677977895
1786,1786,145.3691,8.9396152,0.51451308,0.0,0,8.6580172,0.0,0.034084674,105.00095658895306,9.4996624,301.47192,-9.3180056,105.00095658895306,0.59050745,120.86134099898403,0.585412752,120.86589764609037,0.02539751635574837,113.57014922201326,0.02539311800276773,0.02539311800276773
1789,1789,145.3697,9.6544418,0.57233876,0.0,0,8.574522,0.0,0.038553711,112.91393090731415,9.378974,301.64484,-9.3159409,112.91393090731415,0.73770684,121.64385319814616,0.7317659400000001,121.55113563097585,0.031746895444685466,114.19728683603267,0.0317424728038738,0.0317424728038738
1792,1792,145.3703,9.6504068,0.66833168,0.0,0,8.4910259,0.0,0.045162011,112.06504717859464,9.2895164,301.81775,-9.318428,112.06504717859464,0.88250148,124.9934844299088,0.878119128,124.82651490721229,0.038096274533622555,114.71693576496872,0.03809183176780946,0.03809183176780946
1795,1795,145.3709,10.293255,0.73957378,0.0,0,8.4075298,0.0,0.050010592,118.8953981111208,9.1978664,301.99063,-9.3173685,118.8953981111208,,,,,0.04444565362255965,115.16144011355676,0.044441193641949886,0.044441193641949886
1798,1798,145.3715,10.114444,0.90015411,0.0,0,8.3240337,0.0,0.061361965,115.42394421090816,9.0785971,302.16354,-9.3156061,115.42394421090816,,,,,0.05079503271149674,115.55034204713418,0.05079055766946467,0.05079055766946467
1801,1801,145.3721,10.486087,1.0222548,0.0,0,8.2405376,0.0,0.070131019,118.55639861611058,8.9535294,302.33646,-9.3166351,118.55639861611058,,,,,0.057144411800433836,115.89637657675578,0.057139923357151394,0.057139923357151394
1804,1804,145.3727,10.751703,1.0816581,0.0,0,8.1570415,0.0,0.07492277,121.00634914776154,8.8456907,302.50937,-9.3183184,121.00634914776154,,,,,0.06349379088937093,116.20831675877224,0.06348929036524648,0.06348929036524648
1807,1807,145.3733,10.697309,1.1613271,0.0,0,8.0735455,0.0,0.080440737,119.6560089947079,8.7610731,302.68228,-9.3164644,119.6560089947079,,,,,0.06984316997830803,116.49246943108399,0.06983865844949827,0.06983865844949827
1810,1810,145.3739,11.040557,1.2373143,0.0,0,7.993176,0.0,0.085867077,122.76871826827956,8.680541,302.85519,-9.3157167,122.76871826827956,,,,,0.07619254906724511,116.75352424950786,0.0761880274282854,0.0761880274282854
1813,1813,145.3745,11.152799,1.3583628,0.0,0,7.9137359,0.0,0.094668835,122.84716381176258,8.583951,303.02811,-9.3150377,122.84716381176258,,,,,0.0825419281561822,116.99506540197906,0.0825373971627992,0.0825373971627992
1816,1816,145.3751,11.066709,1.4627407,0.0,0,7.8342957,0.0,0.10229009,120.89789730651604,8.4804688,303.20712,-9.3170214,120.89789730651604,,,,,0.0888913072451193,117.21989525161185,0.08888676754450957,0.08888676754450957
1819,1819,145.3757,11.198463,1.5334156,0.0,0,7.7548552,0.0,0.1077795,121.65128511636102,8.3859339,303.41675,-9.3170576,121.65128511636102,,,,,0.0952406863340564,117.43024731455036,0.09523613848691671,0.09523613848691671
1822,1822,145.3763,11.414923,1.6102185,0.0,0,7.675415,0.0,0.11320975,123.2427947021633,8.309516,303.62637,-9.3166409,123.2427947021633,,,,,0.10159006542299348,117.62793115162064,0.10158550991993981,0.10158550991993981
1825,1825,145.3769,11.52183,1.6755713,0.0,0,7.5959754,0.0,0.11804302,123.74424393829756,8.2322197,303.83597,-9.3143301,123.74424393829756,,,,,0.10793944451193058,117.81443376848333,0.10793488178599002,0.10793488178599002
1828,1828,145.3775,11.594741,1.7733762,0.0,0,7.5165353,0.0,0.12509046,123.54403679757282,8.1565714,304.04559,-9.3162451,123.54403679757282,,,,,0.11428882360086767,117.99099232986995,0.11428425403715434,0.11428425403715434
1831,1831,145.3781,11.656916,1.8620093,0.0,0,7.4370952,0.0,0.13182445,123.31052644068932,8.0635433,304.25522,-9.3165197,123.31052644068932,,,,,0.12063820268980477,118.15864742146304,0.12063362663313289,0.12063362663313289
1834,1834,145.3787,11.729156,1.9353223,0.0,0,7.3593612,0.0,0.13755345,123.32887278962755,7.984921,304.46484,-9.3170691,123.32887278962755,,,,,0.12698758177874186,118.31828279831146,0.12698299953969952,0.12698299953969952
1837,1837,145.3793,11.894421,2.0020769,0.0,0,7.2838039,0.0,0.14246064,124.3778177631364,7.9048223,304.67447,-9.3146276,124.3778177631364,,,,,0.13333696086767896,118.47065554243345,0.13333237272753393,0.13333237272753393
1840,1840,145.3799,11.902253,2.0724616,0.0,0,7.2082515,0.0,0.14791985,123.73291514049254,7.8400321,304.88406,-9.3154535,123.73291514049254,,,,,0.13968633995661606,118.61641928398342,0.13968174617132226,0.13968174617132226
1843,1843,145.3805,12.085208,2.1550851,0.0,0,7.1326995,0.0,0.15430027,124.76844793522504,7.7640781,305.09369,-9.3152103,124.76844793522504,,,,,0.14603571904555313,118.75614231953772,0.14603111984905548,0.14603111984905548
1846,1846,145.3811,12.12826,2.2331917,0.0,0,7.0571475,0.0,0.16041236,124.39081575210554,7.6831708,305.30331,-9.315588,124.39081575210554,,,,,0.15238509813449022,118.89032191919425,0.15238049374147528,0.15238049374147528
1849,1849,145.3817,12.145635,2.3120048,0.0,0,6.981595,0.0,0.16685422,123.738161400924,7.6037364,305.51294,-9.3152027,123.738161400924,,,,,0.15873447722342732,119.01939574734064,0.1587298678316318,0.1587298678316318
1852,1852,145.3823,12.327658,2.3746924,0.0,0,6.9060431,0.0,0.17173798,124.9217291763909,7.53192,305.72256,-9.3155613,124.9217291763909,,,,,0.1650838563123644,119.14375106984545,0.16507924210452696,0.16507924210452696
1855,1855,145.3829,12.367624,2.4406192,0.0,0,6.830492,0.0,0.17730474,124.61882003120812,7.4602981,305.93216,-9.3153324,124.61882003120812,,,,,0.1714332354013015,119.26373224477861,0.1714286165468244,0.1714286165468244
1858,1858,145.3835,12.440351,2.5159817,0.0,0,6.7554417,0.0,0.18327819,124.53753698094076,7.3870745,306.14178,-9.3148441,124.53753698094076,,,,,0.1777826144902386,119.3796468669013,0.17777799114661158,0.17777799114661158
1861,1861,145.3841,12.567738,2.5871909,0.0,0,6.6834416,0.0,0.18918726,125.035555656417,7.3148279,306.35141,-9.315383,125.035555656417,,,,,0.1841319935791757,119.4917708473604,0.18412736589320303,0.18412736589320303
1864,1864,145.3847,12.615844,2.6644945,0.0,0,6.6115613,0.0,0.19553165,124.66705714458207,7.2378378,306.56104,-9.3169794,124.66705714458207,,,,,0.1904813726681128,119.60035264260117,0.1904767407769765,0.1904767407769765
1867,1867,145.3853,12.707409,2.728678,0.0,0,6.5396819,0.0,0.20079114,124.86334318718164,7.1663017,306.66309,-9.3165121,124.86334318718164,,,,,0.1968307517570499,119.70561679844563,0.1968261157892357,0.1968261157892357
1870,1870,145.3859,12.797793,2.7968121,0.0,0,6.467802,0.0,0.20642574,124.99385200429876,7.0981159,306.65756,-9.3150129,124.99385200429876,,,,,0.20318013084598696,119.80776693855836,0.20317549092209475,0.20317549092209475
1873,1873,145.3865,12.901271,2.8705442,0.0,0,6.3959212,0.0,0.21234958,125.1778973491803,7.0233951,306.65207,-9.314992,125.1778973491803,,,,,0.20952950993492406,119.90698829863422,0.20952486616837981,0.20952486616837981
1876,1876,145.3871,12.99898,2.9430242,0.0,0,6.3240418,0.0,0.21831729,125.30709221910816,6.9553328,306.64658,-9.3169937,125.30709221910816,,,,,0.21587888902386115,120.00344988713077,0.2158742415215455,0.2158742415215455
1879,1879,145.3877,13.021606,3.0229459,0.0,0,6.252162,0.0,0.22485399,124.62055522784776,6.8759513,306.64105,-9.3163567,124.62055522784776,,,,,0.22222826811279825,120.09730633670824,0.2222236169756032,0.2222236169756032
1882,1882,145.3883,13.151754,3.0897844,0.0,0,6.1802821,0.0,0.23032108,125.10186973915162,6.8020692,306.63556,-9.317008,125.10186973915162,,,,,0.22857764720173535,120.1886994981151,0.2285729925250593,0.2285729925250593
1885,1885,145.3889,13.264668,3.1598115,0.0,0,6.1111121,0.0,0.23612222,125.3682333202525,6.7321334,306.63007,-9.3157005,125.3682333202525,,,,,0.23492702629067244,120.27775981845303,0.23492236816486187,0.23492236816486187
1888,1888,145.3895,13.316385,3.2309186,0.0,0,6.042748,0.0,0.24203523,125.03354708436856,6.6554928,306.62454,-9.3164654,125.03354708436856,,,,,0.24127640537960954,120.36460753806257,0.24127174389035416,0.24127174389035416
1891,1891,145.3901,13.438315,3.3067482,0.0,0,5.9743834,0.0,0.24840316,125.2920466398202,6.5843534,306.61905,-9.3168173,125.2920466398202,,,,,0.24762578446854663,120.44935373378456,0.24762111969723444,0.24762111969723444
1894,1894,145.3907,13.538468,3.3878658,0.0,0,5.9060202,0.0,0.25522402,125.27041939596045,6.5062132,306.61356,-9.31637,125.27041939596045,,,,,0.25397516355748373,120.53210123196807,0.2539704955815204,0.2539704955815204
1897,1897,145.3913,13.593933,3.4579542,0.0,0,5.8376555,0.0,0.26121387,124.95460613772464,6.4341035,306.60803,-9.3146029,124.95460613772464,,,,,0.2603245426464208,120.61294541013018,0.2603198715395183,0.2603198715395183
1900,1900,145.3919,13.681659,3.5279825,0.0,0,5.7692914,0.0,0.26743135,124.92718194042163,6.3611689,306.60254,-9.3158607,124.92718194042163,,,,,0.2666739217353579,120.69197490320832,0.2666692475677955,0.2666692475677955
1903,1903,145.3925,13.804158,3.5995421,0.0,0,5.7009277,0.0,0.27368799,125.18592047975092,6.2894483,306.59702,-9.3166294,125.18592047975092,,,,,0.273023300824295,120.76927222788024,0.27301862366315616,0.27301862366315616
1906,1906,145.3931,13.866257,3.671411,0.0,0,5.6325636,0.0,0.28008589,124.88153165132496,6.2183595,306.59152,-9.315239,124.88153165132496,,,,,0.2793726799132321,120.84491433601644,0.2793679998226202,0.2793679998226202
1909,1909,145.3937,13.961963,3.747525,0.0,0,5.5656581,0.0,0.28677252,124.81817931523436,6.1439166,306.58603,-9.3156834,124.81817931523436,,,,,0.2857220590021692,120.91897310662955,0.28571737604340386,0.28571737604340386
1912,1912,145.3943,14.059449,3.8159423,0.0,0,5.5006137,0.0,0.29306009,124.85201126198264,6.0733056,306.58051,-9.3168058,124.85201126198264,,,,,0.29207143809110625,120.99151578463572,0.2920667523229028,0.2920667523229028
1915,1915,145.3949,14.13276,3.8868816,0.0,0,5.4355736,0.0,0.29956377,124.6297990825437,6.0038462,306.57501,-9.3164825,124.6297990825437,,,,,0.2984208171800434,121.0626053729129,0.2984161286586772,0.2984161286586772
1918,1918,145.3955,14.225893,3.9548206,0.0,0,5.3705335,0.0,0.30581865,124.6091363425791,5.9314981,306.4332,-9.3153982,124.6091363425791,,,,,0.30477019626898044,121.13230098366517,0.3047655050484376,0.3047655050484376
1921,1921,145.3961,14.310912,4.0257974,0.0,0,5.3054934,0.0,0.31229964,124.46883342425988,5.8618388,306.2641,-9.3166485,124.46883342425988,,,,,0.31111957535791757,121.20065815405572,0.31111488149003325,0.31111488149003325
1924,1924,145.3967,14.407469,4.0932422,0.0,0,5.2404532,0.0,0.31857809,124.46184534327206,5.7924542,306.095,-9.317337,124.46184534327206,,,,,0.31746895444685463,121.26772913032418,0.3174642579814407,0.3174642579814407
1927,1927,145.3973,14.488023,4.1611991,0.0,0,5.1754136,0.0,0.32495835,124.29959160296964,5.7217617,305.9259,-9.315568,124.29959160296964,,,,,0.32381833353579176,121.33356312416456,0.3238136345207541,0.3238136345207541
1930,1930,145.3979,14.575425,4.2338605,0.0,0,5.1103735,0.0,0.33168256,124.12621296817888,5.6536398,305.75684,-9.3160477,124.12621296817888,,,,,0.3301677126247288,121.39820654453095,0.33016301110617613,0.33016301110617613
1933,1933,145.3985,14.691102,4.3030353,0.0,0,5.0457683,0.0,0.33804458,124.22525709023805,5.5825591,305.58774,-9.316268,124.22525709023805,,,,,0.33651709171366595,121.46170320767934,0.3365123877360099,0.3365123877360099
1936,1936,145.3991,14.764081,4.3717084,0.0,0,4.9838042,0.0,0.34451923,123.95817811148054,5.5120559,305.41864,-9.3158941,123.95817811148054,,,,,0.342866470802603,121.52409452773452,0.34286176440865135,0.34286176440865135
1939,1939,145.3997,14.837488,4.438879,0.0,0,4.9219441,0.0,0.35081282,123.70521426689038,5.4391065,305.24957,-9.3166351,123.70521426689038,,,,,0.3492158498915401,121.58541969019105,0.3492111411225831,0.3492111411225831
1942,1942,145.4003,14.958204,4.5070615,0.0,0,4.8600841,0.0,0.35709503,123.82194959176596,5.3727984,305.08047,-9.3164377,123.82194959176596,,,,,0.3555652289804772,121.64571580976224,0.3555605178763677,0.3555605178763677
1945,1945,145.4009,15.037447,4.5783396,0.0,0,4.798224,0.0,0.36380199,123.54270347866674,5.3023224,304.91138,-9.3150396,123.54270347866674,,,,,0.3619146080694143,121.70501807461841,0.3619098946686424,0.3619098946686424
1948,1948,145.4015,15.113685,4.6460614,0.0,0,4.7363639,0.0,0.37020391,123.27583221505223,5.2345643,304.74231,-9.3168097,123.27583221505223,,,,,0.3682639871583514,121.76335987816795,0.3682592714981139,0.3682592714981139
1951,1951,145.4021,15.23859,4.7142181,0.0,0,4.6745043,0.0,0.37661839,123.3880810622522,5.1664209,304.57321,-9.3153725,123.3880810622522,,,,,0.37461336624728847,121.82077293975962,0.37460864836355373,0.37460864836355373
1954,1954,145.4027,15.331079,4.7834463,0.0,0,4.6126437,0.0,0.38326976,123.21041221791766,5.1022501,304.40411,-9.3157835,123.21041221791766,,,,,0.3809627453362256,121.87728741527305,0.3809580252637942,0.3809580252637942
1957,1957,145.4033,15.405949,4.8503432,0.0,0,4.5507841,0.0,0.38960901,122.9122196437133,5.037272,304.23502,-9.3157091,122.9122196437133,,,,,0.38731212442516266,121.93293199888352,0.38730740219772375,0.38730740219772375
1960,1960,145.4039,15.504635,4.9181695,0.0,0,4.4912457,0.0,0.3961615,122.78114718741092,4.9731097,304.06595,-9.3147516,122.78114718741092,,,,,0.3936615035140998,121.98773401643385,0.3936567791642844,0.3936567791642844
1963,1963,145.4045,15.616889,4.9838576,0.0,0,4.4323978,0.0,0.40275124,122.77402203984995,4.9075828,303.89685,-9.3159485,122.77402203984995,,,,,0.40001088260303685,122.04171951165254,0.40000615616246726,0.40000615616246726
1966,1966,145.4051,15.688069,5.0491948,0.0,0,4.3735499,0.0,0.40936786,122.43810931484344,4.8403625,303.71606,-9.3173704,122.43810931484344,,,,,0.4063602616919739,122.09491332549825,0.40635553319131046,0.40635553319131046
1969,1969,145.4057,15.786965,5.1146836,0.0,0,4.314702,0.0,0.416105,122.30654269414266,4.7777338,303.47681,-9.3163385,122.30654269414266,,,,,0.41270964078091105,122.14733916953384,0.4127049102498957,0.4127049102498957
1972,1972,145.4063,15.91543,5.1769938,0.0,0,4.2558532,0.0,0.42258334,122.4350946152405,4.7129731,303.23755,-9.3162622,122.4350946152405,,,,,0.4190590198698481,122.19901969374875,0.4190542873373457,0.4190542873373457
1975,1975,145.4069,15.999142,5.2397289,0.0,0,4.1970053,0.0,0.42915961,122.20171687296737,4.6483698,302.99829,-9.3163767,122.20171687296737,,,,,0.42540839895878524,122.24997654932477,0.42540366445282196,0.42540366445282196
1978,1978,145.4075,16.078693,5.3010736,0.0,0,4.1381574,0.0,0.4356983,121.9469933000264,4.5869856,302.75906,-9.3173103,121.9469933000264,,,,,0.4317577780477223,122.30023044683034,0.43175304159552247,0.43175304159552247
1981,1981,145.4081,16.206141,5.3617578,0.0,0,4.0793095,0.0,0.44218212,122.05364485293718,4.5241184,302.51981,-9.3172693,122.05364485293718,,,,,0.43810715713665943,122.34980121028737,0.4381024187646795,0.4381024187646795
1984,1984,145.4087,16.304237,5.4235363,0.0,0,4.0217257,0.0,0.44864953,121.91151156490368,4.4605384,302.28055,-9.3164616,121.91151156490368,,,,,0.4444565362255965,122.39870782725384,0.4444517959595575,0.4444517959595575
1987,1987,145.4093,16.379642,5.4820099,0.0,0,3.9657533,0.0,0.45497501,121.63753416432584,4.3971372,302.04129,-9.3162394,121.63753416432584,,,,,0.4508059153145336,122.44696849557356,0.450801173179452,0.450801173179452
1990,1990,145.4099,16.544161,5.5419536,0.0,0,3.9097853,0.0,0.46133837,121.99163277482543,4.338419,301.80203,-9.3171005,121.99163277482543,,,,,0.4571552944034707,122.49460066674061,0.45715055042368685,0.45715055042368685
1993,1993,145.4105,16.645782,5.6007051,0.0,0,3.8538175,0.0,0.46766299,121.8851959427448,4.2769122,301.56277,-9.316803,121.8851959427448,,,,,0.4635046734924078,122.54162108641543,0.46349992769161374,0.46349992769161374
1996,1996,145.4111,16.713514,5.662899,0.0,0,3.7978494,0.0,0.47421321,121.4713997456213,4.2167516,301.32352,-9.3154535,121.4713997456213,,,,,0.4698540525813449,122.5880458322433,0.4698493049826099,0.4698493049826099
1999,1999,145.4117,16.847345,5.7207851,0.0,0,3.7418811,0.0,0.48028803,121.59039499739364,4.1547432,301.08426,-9.3160267,121.59039499739364,,,,,0.47620343167028195,122.63389034899517,0.4761986822960772,0.4761986822960772
2002,2002,145.4123,16.975269,5.7807612,0.0,0,3.6859133,0.0,0.48658738,121.62228174529751,4.0963206,300.845,-9.3155775,121.62228174529751,,,,,0.4825528107592191,122.67916948171529,0.4825480596314408,0.4825480596314408
2005,2005,145.4129,17.074329,5.8414302,0.0,0,3.6299453,0.0,0.49294996,121.42492593732533,4.0369072,300.60574,-9.3154783,121.42492593732533,,,,,0.48890218984815614,122.7238975063376,0.4888974369881477,0.4888974369881477
2008,2008,145.4135,17.189512,5.898973,0.0,0,3.5743496,0.0,0.49920359,121.3777494702096,3.9772835,300.36652,-9.3163891,121.3777494702096,,,,,0.49525156893709327,122.76808815876038,0.49524681436566603,0.49524681436566603
2011,2011,145.4141,17.321552,5.9604478,0.0,0,3.5210168,0.0,0.50571573,121.37732387088056,3.9183011,300.12726,-9.3151407,121.37732387088056,,,,,0.5016009480260304,122.81175466177177,0.5015961917634836,0.5015961917634836
2014,2014,145.4147,17.433939,6.019083,0.0,0,3.4677727,0.0,0.51212841,121.2692228333629,3.8592832,299.888,-9.3154345,121.2692228333629,,,,,0.5079503271149675,122.85490975048509,0.5079455691811073,0.5079455691811073
2017,2017,145.4153,17.539701,6.0796762,0.0,0,3.4145288,0.0,0.51869649,121.07357237867426,3.8030462,299.42776,-9.3159409,121.07357237867426,,,,,0.5142997062039045,122.89756569618011,0.5142949466180619,0.5142949466180619
2020,2020,145.4159,17.669851,6.1387277,0.0,0,3.3612847,0.0,0.52539104,121.0574449954979,3.7444155,298.74658,-9.3148546,121.0574449954979,,,,,0.5206490852928416,122.9397343286097,0.520644324073889,0.520644324073889
2023,2023,145.4165,17.807259,6.1951599,0.0,0,3.3080409,0.0,0.53183806,121.11791795189562,3.684551,298.06537,-9.3147316,121.11791795189562,,,,,0.5269984643817787,122.98142705714982,0.5269937015481471,0.5269937015481471
2026,2026,145.4171,17.907398,6.2521362,0.0,0,3.2547965,0.0,0.53832865,120.90445165734025,3.6282737,297.38419,-9.3162022,120.90445165734025,,,,,0.5333478434707158,123.02265489050507,0.5333430790404097,0.5333430790404097
2029,2029,145.4177,18.044048,6.3082824,0.0,0,3.2015526,0.0,0.54485434,120.93864182195618,3.5737033,296.703,-9.3166914,120.93864182195618,,,,,0.5396972225596529,123.06342845541697,0.5396924565502652,0.5396924565502652
2032,2032,145.4183,18.190474,6.3653355,0.0,0,3.1483088,0.0,0.55148977,121.0097891921754,3.5186622,296.02182,-9.3147087,121.0097891921754,,,,,0.54604660164859,123.10375801420598,0.5460418340773162,0.5460418340773162
2035,2035,145.4189,18.292593,6.4217539,0.0,0,3.0970623,0.0,0.55829692,120.78377452994329,3.4638808,295.34064,-9.3153667,120.78377452994329,,,,,0.552395980737527,123.14365348131987,0.5523912116211788,0.5523912116211788
2038,2038,145.4195,18.396149,6.4742312,0.0,0,3.0464106,0.0,0.5645889,120.62052450187716,3.4088602,294.65945,-9.315485,120.62052450187716,,,,,0.5587453598264642,123.18312443902849,0.5587405891814818,0.5587405891814818
2041,2041,145.4201,18.56175,6.5291281,0.0,0,2.9957583,0.0,0.57110608,120.81214330604143,3.3535023,293.97827,-9.315587,120.81214330604143,,,,,0.5650947389154013,123.2221801521293,0.5650899667578664,0.5650899667578664
2044,2044,145.4207,18.682224,6.5834913,0.0,0,2.9451065,0.0,0.57776886,120.70485970209884,3.2978785,293.29706,-9.3156519,120.70485970209884,,,,,0.5714441180043384,123.26082958188,0.5714393443499856,0.5714393443499856
2047,2047,145.4213,18.799366,6.6355495,0.0,0,2.8944542,0.0,0.58425146,120.60259806493195,3.2422667,292.61588,-9.3153906,120.60259806493195,,,,,0.5777934970932754,123.29908139929894,0.5777887219575034,0.5777887219575034
2050,2050,145.4219,18.975084,6.6876826,0.0,0,2.8438022,0.0,0.59050745,120.86134099898403,3.19034,291.93469,-9.3146877,120.86134099898403,,,,,0.5841428761822125,123.336943997491,0.584138099580095,0.584138099580095
2053,2053,145.4225,19.102442,6.740417,0.0,0,2.7931502,0.0,0.59694284,120.78795087927332,3.1350842,291.25351,-9.3150787,120.78795087927332,,,,,0.5904922552711497,123.37442550355928,0.5904874772174458,0.5904874772174458
2056,2056,145.4231,19.220507,6.7932677,0.0,0,2.7424984,0.0,0.60331285,120.64232115421932,3.083045,290.57233,-9.3158436,120.64232115421932,,,,,0.5968416343600867,123.41153378975424,0.5968368548692504,0.5968368548692504
2059,2059,145.4237,19.385887,6.8490973,0.0,0,2.6929309,0.0,0.60992503,120.72963409037844,3.0312455,289.89114,-9.3141136,120.72963409037844,,,,,0.6031910134490238,123.44827648411562,0.6031862325352138,0.6031862325352138
2062,2062,145.4243,19.550022,6.9010954,0.0,0,2.6447473,0.0,0.61634988,120.85867900576008,2.9791231,289.20996,-9.3140869,120.85867900576008,,,,,0.6095403925379609,123.48466098046812,0.6095356102150494,0.6095356102150494
2065,2065,145.4249,19.65251,6.9531245,0.0,0,2.5965672,0.0,0.62244576,120.59375507372644,2.9250031,288.52878,-9.3138552,120.59375507372644,,,,,0.6158897716268981,123.52069444802096,0.6158849879084798,0.6158849879084798
2068,2068,145.4255,19.813995,7.0030346,0.0,0,2.5483873,0.0,0.6285069,120.71553813436202,2.8722403,288.43521,-9.313653,120.71553813436202,,,,,0.6222391507158351,123.55638384039781,0.6222343656152355,0.6222343656152355
2071,2071,145.4261,20.004013,7.0580816,0.0,0,2.5002072,0.0,0.63521248,120.90526295289948,2.8187697,288.45917,-9.3146219,120.90526295289948,,,,,0.6285885298047722,123.59173590426487,0.6285837433350553,0.6285837433350553
2074,2074,145.4267,20.120838,7.1106963,0.0,0,2.4520273,0.0,0.64159542,120.68061685604958,2.7724142,288.48312,-9.3140526,120.68061685604958,,,,,0.6349379088937093,123.62675718747113,0.6349331210676855,0.6349331210676855
2077,2077,145.4273,20.267786,7.1649876,0.0,0,2.4038472,0.0,0.64837694,120.5943996317514,2.7180035,288.50705,-9.3143854,120.5943996317514,,,,,0.6412872879826463,123.66145404686281,0.6412824988128801,0.6412824988128801
2080,2080,145.4279,20.456915,7.2146854,0.0,0,2.3556671,0.0,0.65446478,120.82559777091248,2.6704488,288.53101,-9.3140621,120.82559777091248,,,,,0.6476366670715835,123.69583265569412,0.6476318765704,0.6476318765704
2083,2083,145.4285,20.577688,7.2653804,0.0,0,2.3078089,0.0,0.66095501,120.62132233239709,2.6196735,288.55496,-9.313777,120.62132233239709,,,,,0.6539860461605206,123.7298990106082,0.6539812543400129,0.6539812543400129
2086,2086,145.4291,20.728754,7.3129683,0.0,0,2.2619042,0.0,0.66721487,120.63901160250532,2.5708187,288.57892,-9.3146009,120.63901160250532,,,,,0.6603354252494577,123.76365893842188,0.660330632121493,0.660330632121493
2089,2089,145.4297,20.929333,7.3635507,0.0,0,2.2160764,0.0,0.67388046,120.87485656275028,2.5230958,288.60287,-9.3141766,120.87485656275028,,,,,0.6666848043383947,123.79711810244298,0.6666800099146212,0.6666800099146212
2092,2092,145.4303,21.07737,7.4118052,0.0,0,2.1702483,0.0,0.68047333,120.83476761119702,2.471674,288.6268,-9.3133564,120.83476761119702,,,,,0.6730341834273319,123.83028200864877,0.6730293877191842,0.6730293877191842
2095,2095,145.4309,21.213852,7.4597869,0.0,0,2.1244202,0.0,0.68690366,120.72130862314155,2.427237,288.65076,-9.3134079,120.72130862314155,,,,,0.679383562516269,123.86315601141375,0.6793787655349744,0.6793787655349744
2098,2098,145.4315,21.389336,7.5026913,0.0,0,2.0785923,0.0,0.69297898,120.9120924831005,2.3814678,288.67471,-9.3153801,120.9120924831005,,,,,0.685732941605206,123.89574531911929,0.6857281433617904,0.6857281433617904
2101,2101,145.4321,21.572294,7.5502739,0.0,0,2.0327644,0.0,0.69971609,121.04262094995076,2.3337109,288.69867,-9.3148031,121.04262094995076,,,,,0.6920823206941431,123.9280549993619,0.6920775211994359,0.6920775211994359
2104,2104,145.4327,21.734564,7.5977325,0.0,0,1.9869361,0.0,0.70621037,121.04484325758152,2.2856123,288.72263,-9.3135815,121.04484325758152,,,,,0.6984316997830802,123.96008998411892,0.6984268990477197,0.6984268990477197
2107,2107,145.4333,21.914976,7.6407423,0.0,0,1.9411081,0.0,0.71248204,121.21951385840264,2.2386763,288.74655,-9.3125067,121.21951385840264,,,,,0.7047810788720174,123.99185507450329,0.7047762769064562,0.7047762769064562
2110,2110,145.4339,22.107725,7.6860089,0.0,0,1.8970004,0.0,0.71868432,121.40422998662734,2.1890833,288.77051,-9.3137779,121.40422998662734,,,,,0.7111304579609544,124.02335494538632,0.711125654775464,0.711125654775464
2113,2113,145.4345,22.267347,7.7319455,0.0,0,1.8534043,0.0,0.7250843,121.37971242565852,2.1409898,288.79446,-9.3146362,121.37971242565852,,,,,0.7174798370498915,124.05459414979323,0.7174750326545668,0.7174750326545668
2116,2116,145.4351,22.433331,7.7799201,0.0,0,1.8098084,0.0,0.73161429,121.3362860811316,2.095361,288.94333,-9.3142691,121.3362860811316,,,,,0.7238292161388286,124.08557712318736,0.723824410543593,0.723824410543593
2119,2119,145.4357,22.652525,7.8239064,0.0,0,1.7662123,0.0,0.73770684,121.64385319814616,2.051388,289.71652,-9.3127661,121.64385319814616,,,,,0.7301785952277657,124.11630818741999,0.7301737884423753,0.7301737884423753
2122,2122,145.4363,22.824776,7.8677669,0.0,0,1.7226164,0.0,0.74363303,121.68657690856104,2.0040975,290.48975,-9.3118315,121.68657690856104,,,,,0.7365279743167028,124.14679155471097,0.7365231663507503,0.7365231663507503
2125,2125,145.4369,23.018791,7.9133563,0.0,0,1.6790204,0.0,0.7496413,121.7959765698116,1.9561533,291.26294,-9.3126163,121.7959765698116,,,,,0.7428773534056399,124.17703133122876,0.7428725442685592,0.7428725442685592
2128,2128,145.4375,23.225227,7.960794,0.0,0,1.6354244,0.0,0.75609511,121.91703475258088,1.9112514,292.03616,-9.3132782,121.91703475258088,,,,,0.7492267324945769,124.20703152069963,0.7492219221956468,0.7492219221956468
2131,2131,145.4381,23.422426,8.0071239,0.0,0,1.5918283,0.0,0.76255035,121.99546590296924,1.8673031,292.80939,-9.3134432,121.99546590296924,,,,,0.755576111583514,124.23679602784541,0.7555713001318618,0.7555713001318618
2134,2134,145.4387,23.596394,8.0531816,0.0,0,1.5491644,0.0,0.7688573,121.94327027159656,1.8225425,293.58258,-9.3124294,121.94327027159656,,,,,0.7619254906724512,124.26632866152933,0.761920678077057,0.761920678077057
2137,2137,145.4393,23.809093,8.0966492,0.0,0,1.5076892,0.0,0.77495944,122.12978642326334,1.7819145,294.3558,-9.3124924,122.12978642326334,,,,,0.7682748697613883,124.29563313798995,0.7682700560310882,0.7682700560310882
2140,2140,145.4399,24.028248,8.139761,0.0,0,1.4662173,0.0,0.78104132,122.34029008026104,1.7374384,295.129,-9.3123827,122.34029008026104,,,,,0.7746242488503253,124.32471308380835,0.774619433993815,0.774619433993815
2143,2143,145.4405,24.209473,8.1845503,0.0,0,1.4247453,0.0,0.78758681,122.3065094849634,1.692557,295.90222,-9.3112907,122.3065094849634,,,,,0.7809736279392624,124.35357203876013,0.7809688119651004,0.7809688119651004
2146,2146,145.4411,24.406879,8.2300587,0.0,0,1.3832734,0.0,0.79446554,122.32391008867828,1.6515518,296.67545,-9.3119478,122.32391008867828,,,,,0.7873230070281996,124.3822134585883,0.7873181899448106,0.7873181899448106
2149,2149,145.4417,24.650583,8.2708349,0.0,0,1.3418013,0.0,0.80061108,122.6584462303552,1.608936,297.44864,-9.3124704,122.6584462303552,,,,,0.7936723861171366,124.41064071767101,0.7936675679328147,0.7936675679328147
2152,2152,145.4423,24.854773,8.3159208,0.0,0,1.3003293,0.0,0.80731505,122.68562357906816,1.5683808,298.22186,-9.3134604,122.68562357906816,,,,,0.8000217652060737,124.43885711158988,0.8000169459289852,0.8000169459289852
2155,2155,145.4429,25.048002,8.3567734,0.0,0,1.2588574,0.0,0.81383461,122.73634960013774,1.5243255,298.99509,-9.312541,122.73634960013774,,,,,0.8063711442950108,124.46686585954168,0.8063663239331974,0.8063663239331974
2158,2158,145.4435,25.296705,8.3950405,0.0,0,1.2176627,0.0,0.81982136,123.10059966176256,1.4831997,299.76828,-9.3118792,123.10059966176256,,,,,0.8127205233839478,124.49467010666858,0.8127157019453296,0.8127157019453296
2161,2161,145.4441,25.52323,8.4349089,0.0,0,1.1781524,0.0,0.82612205,123.3047102690445,1.4350355,300.5415,-9.3117685,123.3047102690445,,,,,0.819069902472885,124.52227292639823,0.8190650799652628,0.8190650799652628
2164,2164,145.4447,25.712929,8.4766598,0.0,0,1.1387084,0.0,0.8326295,123.27343766886597,1.3976132,301.3147,-9.3129511,123.27343766886597,,,,,0.8254192815618221,124.54967732258422,0.8254144579928804,0.8254144579928804
2167,2167,145.4453,25.954029,8.519577,0.0,0,1.0992644,0.0,0.83949107,123.44588762882908,1.3571594,301.76025,-9.3121653,123.44588762882908,,,,,0.8317686606507592,124.57688623160522,0.8317638360280689,0.8317638360280689
2170,2170,145.4459,26.225338,8.5578833,0.0,0,1.0598203,0.0,0.84563822,123.84927940141928,1.3154886,301.87817,-9.3108006,123.84927940141928,,,,,0.8381180397396962,124.60390252435076,0.838113214070717,0.838113214070717
2173,2173,145.4465,26.420279,8.5946646,0.0,0,1.0203763,0.0,0.85146093,123.91175164646128,1.2755611,301.99606,-9.310957,123.91175164646128,,,,,0.8444674188286334,124.63072900822361,0.8444625921207162,0.8444625921207162
2176,2176,145.4471,26.677223,8.6336727,0.0,0,0.98093235,0.0,0.85760081,124.19780227661782,1.2356583,302.11398,-9.3115711,124.19780227661782,,,,,0.8508167979175705,124.6573684289809,0.8508119701779598,0.8508119701779598
2179,2179,145.4477,26.955057,8.6752625,0.0,0,0.94148839,0.0,0.86398762,124.50113602085924,1.1928174,302.23187,-9.310111,124.50113602085924,,,,,0.8571661770065075,124.68382347249909,0.857161348242344,0.857161348242344
2182,2182,145.4483,27.159533,8.715457,0.0,0,0.90204442,0.0,0.87031454,124.48130692276078,1.1535516,302.34979,-9.3099432,124.48130692276078,,,,,0.8635155560954446,124.71009676660186,0.863510726313767,0.863510726313767
2185,2185,145.4489,27.409204,8.7553978,0.0,0,0.86408949,0.0,0.87646317,124.65855659356296,1.114055,302.46771,-9.3107719,124.65855659356296,,,,,0.8698649351843818,124.73619088261378,0.8698601043921295,0.8698601043921295
2188,2188,145.4495,27.697981,8.7953835,0.0,0,0.82657731,0.0,0.88250148,124.9934844299088,1.0736564,302.5856,-9.3105936,124.9934844299088,,,,,0.8762143142733189,124.76210833710046,0.8762094824773334,0.8762094824773334
2191,2191,145.4501,27.941566,8.8350391,0.0,0,0.78906536,0.0,0.88851613,125.11373724094705,1.0347989,302.70352,-9.3102922,125.11373724094705,,,,,0.8825636933622559,124.78785159331612,0.8825588605692838,0.8825588605692838
2194,2194,145.4507,28.170416,8.8761225,0.0,0,0.75155336,0.0,0.89487028,125.11584201370006,0.99261039,302.82144,-9.3106833,125.11584201370006,,,,,0.888913072451193,124.81342306278461,0.8889082386678872,0.8889082386678872
2197,2197,145.4513,28.451115,8.9139433,0.0,0,0.71404135,0.0,0.90088582,125.41168102779484,0.95594561,302.93933,-9.3107281,125.41168102779484,,,,,0.8952624515401301,124.83882510669599,0.895257616773052,0.895257616773052
2200,2200,145.4519,28.712351,8.953269,0.0,0,0.67652941,0.0,0.90694743,125.56536553840496,0.91484618,303.05725,-9.310338,125.56536553840496,,,,,0.9016118306290672,124.86406003732694,0.901606994884689,0.901606994884689
2203,2203,145.4525,28.949812,8.9918709,0.0,0,0.63901734,0.0,0.91325748,125.61619809429216,0.88019204,303.17517,-9.3103809,125.61619809429216,,,,,0.9079612097180043,124.88913011940346,0.90795637300271,0.90795637300271
2206,2206,145.4531,29.215694,9.0287342,0.0,0,0.6015054,0.0,0.91931492,125.81801400924594,0.84174174,303.29306,-9.3113556,125.81801400924594,,,,,0.9143105888069414,124.91403757135366,0.9143057511270295,0.9143057511270295
2209,2209,145.4537,29.499987,9.0677996,0.0,0,0.56478846,0.0,0.9259221,126.02371854596832,0.80413371,303.41098,-9.311079,126.02371854596832,,,,,0.9206599678958785,124.93878456665793,0.9206551292575632,0.9206551292575632
2212,2212,145.4543,29.744986,9.1029387,0.0,0,0.52908593,0.0,0.93217391,126.14646136007777,0.76778913,303.5289,-9.3100023,126.14646136007777,,,,,0.9270093469848156,124.96337323491842,0.9270045073942287,0.9270045073942287
2215,2215,145.4549,30.019468,9.1377859,0.0,0,0.49338591,0.0,0.93830049,126.38580717943688,0.73075408,303.64679,-9.3089647,126.38580717943688,,,,,0.9333587260737527,124.98780566323255,0.9333538855369449,0.9333538855369449
2218,2218,145.4555,30.317293,9.1731071,0.0,0,0.45768592,0.0,0.94477767,126.6930571935014,0.69409734,303.7215,-9.3099461,126.6930571935014,,,,,0.9397081051626898,125.012083897096,0.9397032636856327,0.9397032636856327
2221,2221,145.4561,30.568037,9.20753,0.0,0,0.42198589,0.0,0.95103753,126.81066929640254,0.65952563,303.78754,-9.3109322,126.81066929640254,,,,,0.9460574842516268,125.0362099417852,0.9460526418402145,0.9460526418402145
2224,2224,145.4567,30.831066,9.2389202,0.0,0,0.3862859,0.0,0.95708233,127.04624075104444,0.62222552,303.85361,-9.3094559,127.04624075104444,,,,,0.9524068633405639,125.06018576307696,0.9524020200006142,0.9524020200006142
2227,2227,145.4573,31.134478,9.2707853,0.0,0,0.35058588,0.0,0.96292084,127.41940257780335,0.58622754,303.91965,-9.308238,127.41940257780335,,,,,0.9587562424295011,125.08401328861635,0.9587513981667574,0.9587513981667574
2230,2230,145.4579,31.428186,9.3059893,0.0,0,0.31488591,0.0,0.96923852,127.64322825318914,0.55303949,303.98572,-9.3081779,127.64322825318914,,,,,0.9651056215184382,125.10769440864017,0.9651007763385703,0.9651007763385703
2233,2233,145.4585,31.710527,9.3372126,0.0,0,0.27942541,0.0,0.97489464,127.91454025083954,0.51964384,304.05176,-9.3081808,127.91454025083954,,,,,0.9714550006073752,125.13123097710172,0.9714501545159814,0.9714501545159814
2235,2235,145.4589,31.91988,9.362114,0.0,0,0.25673628,0.0,0.97746998,128.05626085470516,0.49414158,304.09579,-9.3083849,128.05626085470516,,,,,0.97568792,125.14684261580841,0.9756830733039975,0.9756830733039975