File: examples/hot axisymmetric compression example/data/12 fitted data ramberg/testID_0136.csv
level_0,index,Time(sec),Force(kN),Jaw(mm),PowAngle(deg),Power(W),Pram,PTemp,Strain,Stress(MPa),Stroke(mm),TC1(C),wedge(mm),uncorrected stress,sampled strain,sampled stress,fitting strain,fitting stress,model strain,ramberg stress,ramberg plastic strain,ramberg accumulated plastic strain
1873,1873,155.3444,0.78002334,0.0084406519,0.0,0,9.0337067,0.0,0.00027091574,9.503253454249052,10.043098,330.94385,-9.3071289,9.503253454249052,0.00027091574,9.503253454249052,0.0,9.503253454249052,0.0,0.0,0.0,0.0
1876,1876,155.345,4.5954895,0.05845885,0.0,0,8.9459143,0.0,0.0031700295,55.78945747057495,9.9364424,331.24695,-9.3062782,55.78945747057495,0.15457343,113.57958906613646,0.14821728,113.3625765194775,0.0061353558169934645,105.3055043155289,0.006127987606588234,0.006127987606588234
1879,1879,155.3456,6.3817549,0.14786839,0.0,0,8.8581219,0.0,0.008974934,76.98140560735686,9.8414745,331.55005,-9.3032179,76.98140560735686,0.29297319,112.75350818345466,0.29643456,112.69368055430463,0.012270711633986929,105.98061387924572,0.01226329618626638,0.01226329618626638
1882,1882,155.3462,7.3667412,0.33487865,0.0,0,8.7703304,0.0,0.021530801,87.6715020031598,9.7203999,331.85318,-9.3024158,87.6715020031598,0.44265571,109.72425842684636,0.44465184,109.6796784874061,0.018406067450980394,106.38383237240174,0.018398623790122116,0.018398623790122116
1885,1885,155.3468,8.3517656,0.45969856,0.0,0,8.6858492,0.0,0.030168159,98.4924222616118,9.5755301,332.15628,-9.3029509,98.4924222616118,0.59062147,107.79327132366213,0.59286912,107.7780460315438,0.024541423267973858,106.67372805032997,0.024533959323158307,0.024533959323158307
1888,1888,155.3474,9.019805,0.54606152,0.0,0,8.6023531,0.0,0.036769722,105.6966054480578,9.4427843,332.45938,-9.3001213,105.6966054480578,0.73965144,107.95851301027656,0.7410864,107.96044930835421,0.03067677908496732,106.90079681500063,0.030669299252184225,0.030669299252184225
1891,1891,155.348,8.8246059,0.6391629,0.0,0,8.518857,0.0,0.042979002,102.69823163790988,9.3431339,332.76248,-9.2990723,102.69823163790988,0.88782233,109.9045112276407,0.88930368,109.9303076003337,0.03681213490196079,107.08777262552813,0.03680464198650816,0.03680464198650816
1894,1894,155.3486,9.3999557,0.71614653,0.0,0,8.4353609,0.0,0.04858141,108.76768059263738,9.2535515,333.06558,-9.3007307,108.76768059263738,,,,,0.04294749071895425,107.24688209860813,0.04293998667063556,0.04293998667063556
1897,1897,155.3492,9.514636,0.85662758,0.0,0,8.3518648,0.0,0.058249995,108.93761147075128,9.1437864,333.36868,-9.2998466,108.93761147075128,,,,,0.049082846535947716,107.38547228945698,0.04907533279049408,0.04907533279049408
1900,1900,155.3498,9.6427393,0.97319984,0.0,0,8.2683697,0.0,0.066777848,109.431068727997,9.0206957,333.67178,-9.2978764,109.431068727997,,,,,0.05521820235294118,107.5083090458067,0.05521068001261805,0.05521068001261805
1903,1903,155.3504,9.747077,1.060209,0.0,0,8.1848736,0.0,0.073364787,109.88072689306136,8.9104795,333.97488,-9.2981911,109.88072689306136,,,,,0.06135355816993464,107.61866245805881,0.06134602810819974,0.06134602810819974
1906,1906,155.351,9.8612118,1.1308146,0.0,0,8.1013775,0.0,0.078197502,110.56436717741636,8.8155851,334.27798,-9.3005352,110.56436717741636,,,,,0.0674889139869281,107.71887509147325,0.06748137691333023,0.06748137691333023
1909,1909,155.3516,10.108418,1.213627,0.0,0,8.0196619,0.0,0.084362604,112.61094969716378,8.734704,334.58109,-9.2990227,112.61094969716378,,,,,0.07362426980392157,107.81068335475021,0.07361672630651322,0.07361672630651322
1912,1912,155.3522,10.240388,1.3268926,0.0,0,7.9402156,0.0,0.092352778,113.07626503361432,8.6376324,334.88422,-9.2977648,113.07626503361432,,,,,0.07975962562091503,107.89541055857245,0.07975207619515688,0.07975207619515688
1915,1915,155.3528,10.114515,1.4302582,0.0,0,7.8607755,0.0,0.099989399,110.78041061182572,8.5352907,335.20221,-9.299015,110.78041061182572,,,,,0.0858949814379085,107.97408866104786,0.08588742650705528,0.08588742650705528
1918,1918,155.3534,10.281072,1.5218863,0.0,0,7.7813354,0.0,0.10681913,111.7882107654504,8.436018,335.5946,-9.2994347,111.7882107654504,,,,,0.09203033725490196,108.04753817036027,0.09202277718479755,0.09202277718479755
1921,1921,155.354,10.493971,1.5904995,0.0,0,7.7018952,0.0,0.11158706,113.4789902222027,8.35254,335.98703,-9.2987576,113.4789902222027,,,,,0.09816569307189543,108.11642237041099,0.09815812818197384,0.09815812818197384
1924,1924,155.3546,10.45472,1.6713763,0.0,0,7.6224551,0.0,0.11777365,112.3215257275036,8.2723417,336.37946,-9.2983818,112.3215257275036,,,,,0.10430104888888889,108.18128518388414,0.10429347946052592,0.10429347946052592
1927,1927,155.3552,10.61489,1.7623681,0.0,0,7.543015,0.0,0.12431422,113.20487371080654,8.187952,336.77188,-9.2987976,113.20487371080654,,,,,0.11043640470588235,108.24257826670153,0.11042883098885153,0.11042883098885153
1930,1930,155.3558,10.706024,1.8526021,0.0,0,7.4635754,0.0,0.13117211,113.3390384507005,8.0968761,337.16431,-9.2992783,113.3390384507005,,,,,0.11657176052287582,108.30068081523335,0.11656418274041837,0.11656418274041837
1933,1933,155.3564,10.693617,1.9386661,0.0,0,7.3846664,0.0,0.13774888,112.40944670418936,8.0119753,337.55673,-9.2995195,112.40944670418936,,,,,0.12270711633986928,108.35591432069444,0.12269953469273169,0.12269953469273169
1936,1936,155.357,10.826219,2.0015326,0.0,0,7.3089881,0.0,0.14247122,113.21293390076607,7.9308977,337.94916,-9.2987423,113.21293390076607,,,,,0.12884247215686276,108.40855374398005,0.12883488682655259,0.12883488682655259
1939,1939,155.3576,10.868293,2.0804834,0.0,0,7.2334356,0.0,0.14873137,112.90847564081636,7.8539758,338.34158,-9.2986383,112.90847564081636,,,,,0.1349778279738562,108.45883610604209,0.13497023912529668,0.13497023912529668
1942,1942,155.3582,11.004064,2.1579189,0.0,0,7.1578832,0.0,0.15457343,113.57958906613646,7.7787728,338.73401,-9.2991924,113.57958906613646,,,,,0.14111318379084967,108.50696718012766,0.14110559157456606,0.14110559157456606
1945,1945,155.3588,11.074766,2.2370169,0.0,0,7.0823312,0.0,0.16092272,113.54912008402708,7.6996598,339.12643,-9.2991457,113.54912008402708,,,,,0.14724853960784315,108.55312676830496,0.14724094416178007,0.14724094416178007
1948,1948,155.3594,11.067369,2.3190763,0.0,0,7.0067792,0.0,0.16744104,112.68499046404276,7.622716,339.51883,-9.2987518,112.68499046404276,,,,,0.1533838954248366,108.59747290761555,0.15337629687588078,0.15337629687588078
1951,1951,155.36,11.211173,2.3809314,0.0,0,6.9312277,0.0,0.17236458,113.54715748133492,7.5452824,339.91125,-9.2976809,113.54715748133492,,,,,0.15951925124183006,108.64014525643394,0.15951164970709636,0.15951164970709636
1954,1954,155.3606,11.236587,2.4538002,0.0,0,6.8556757,0.0,0.17835611,113.09364917125784,7.4736919,340.30368,-9.2975082,113.09364917125784,,,,,0.16565460705882354,108.6812678457923,0.1656470026467484,0.1656470026467484
1957,1957,155.3612,11.300659,2.5262682,0.0,0,6.7801232,0.0,0.1841795,113.02739059340132,7.4015446,340.69611,-9.2992134,113.02739059340132,,,,,0.171789962875817,108.72095133361974,0.17178235568709416,0.17178235568709416
1960,1960,155.3618,11.432032,2.6003876,0.0,0,6.7074022,0.0,0.19024187,113.60546263382425,7.3275065,341.08853,-9.2995701,113.60546263382425,,,,,0.17792531869281045,108.75929486596331,0.17791770882119637,0.17791770882119637
1963,1963,155.3624,11.438499,2.6754484,0.0,0,6.6355219,0.0,0.19631736,112.92394486605656,7.2534933,341.48096,-9.2984257,112.92394486605656,,,,,0.18406067450980393,108.79638762475498,0.18405306204281505,0.18405306204281505
1966,1966,155.363,11.519349,2.7374406,0.0,0,6.5636415,0.0,0.2014609,113.1017379930998,7.1816525,341.71637,-9.2991152,113.1017379930998,,,,,0.19019603032679738,108.83231012352128,0.19018841534631664,0.19018841534631664
1969,1969,155.3636,11.629908,2.8086963,0.0,0,6.4917622,0.0,0.2072994,113.4672236004988,7.1099911,341.79474,-9.2988729,113.4672236004988,,,,,0.19633138614379086,108.86713529872132,0.19632376872659782,0.19632376872659782
1972,1972,155.3642,11.692984,2.8790197,0.0,0,6.4198818,0.0,0.21299733,113.36805535576713,7.0411649,341.87314,-9.2984629,113.36805535576713,,,,,0.20246674196078432,108.90092943429197,0.20245912217902065,0.20245912217902065
1975,1975,155.3648,11.773714,2.9511137,0.0,0,6.3480015,0.0,0.21892655,113.4130329860737,6.9689021,341.95154,-9.298562,113.4130329860737,,,,,0.20860209777777777,108.93375294912977,0.20859447569935768,0.20859447569935768
1978,1978,155.3654,11.815033,3.0238991,0.0,0,6.2761221,0.0,0.22491424,113.06351028406652,6.8970256,342.02994,-9.2990379,113.06351028406652,,,,,0.21473745359477125,108.96566107122145,0.21472982928374462,0.21472982928374462
1981,1981,155.366,11.907089,3.0933189,0.0,0,6.2042422,0.0,0.23068088,113.2257984569212,6.8249307,342.10834,-9.2994642,113.2257984569212,,,,,0.2208728094117647,108.99670441741466,0.22086518292863977,0.22086518292863977
1984,1984,155.3666,11.982752,3.1652734,0.0,0,6.1339049,0.0,0.23665354,113.19555823601384,6.7549152,342.18674,-9.2991343,113.19555823601384,,,,,0.22700816522875816,109.02692949432162,0.22700053663078912,0.22700053663078912
1987,1987,155.3672,12.053741,3.2336247,0.0,0,6.065536,0.0,0.24216123,113.14964317423924,6.6815634,342.26514,-9.2985945,113.14964317423924,,,,,0.23314352104575164,109.0563791329264,0.2331358903871958,0.2331358903871958
1990,1990,155.3678,12.139424,3.3067658,0.0,0,5.9971719,0.0,0.2483108,113.18165859480162,6.6110101,342.34354,-9.299099,113.18165859480162,,,,,0.2392788768627451,109.08509286708775,0.23927124419509355,0.23927124419509355
1993,1993,155.3684,12.240971,3.3836129,0.0,0,5.9288077,0.0,0.25473005,113.3100719432249,6.5376782,342.42194,-9.2988777,113.3100719432249,,,,,0.24541423267973855,109.11310726444471,0.2454065980519238,0.2454065980519238
1996,1996,155.369,12.265512,3.4571176,0.0,0,5.8604436,0.0,0.26114753,112.75277028333105,6.4652977,342.50034,-9.2990627,112.75277028333105,,,,,0.25154958849673204,109.14045621685011,0.2515419519553152,0.2515419519553152
1999,1999,155.3696,12.360831,3.5325558,0.0,0,5.792079,0.0,0.26750776,112.81750622980692,6.3942719,342.5787,-9.29953,112.81750622980692,,,,,0.2576849443137255,109.16717119590727,0.2576773059030656,0.2576773059030656
2002,2002,155.3702,12.473477,3.5987163,0.0,0,5.7237153,0.0,0.2733427,113.12732535615926,6.3198738,342.6571,-9.298912,113.12732535615926,,,,,0.26382030013071894,109.19328147876358,0.2638126598931264,0.2638126598931264
2005,2005,155.3708,12.509054,3.671382,0.0,0,5.6553516,0.0,0.27981049,112.65867943998768,6.2484865,342.7355,-9.2982273,112.65867943998768,,,,,0.2699556559477124,109.21881434812556,0.2699480139235888,0.2699480139235888
2008,2008,155.3714,12.618874,3.7453392,0.0,0,5.5874419,0.0,0.28646258,112.83515199723082,6.1779265,342.8139,-9.2978306,112.83515199723082,,,,,0.2760910117647059,109.24379526986122,0.27608336799267097,0.27608336799267097
2011,2011,155.372,12.697213,3.8160734,0.0,0,5.5222936,0.0,0.29297319,112.75350818345466,6.1027727,342.8923,-9.2990189,112.75350818345466,,,,,0.28222636758169933,109.26824805133583,0.2822187220987069,0.2822187220987069
2014,2014,155.3726,12.765089,3.8882537,0.0,0,5.4572535,0.0,0.29964942,112.55373018328928,6.0368633,342.9707,-9.2990513,112.55373018328928,,,,,0.2883617233986928,109.29219498279133,0.28835407624013715,0.28835407624013715
2017,2017,155.3732,12.836389,3.9525352,0.0,0,5.3922133,0.0,0.30561826,112.46358565280542,5.9616561,342.85159,-9.2987165,112.46358565280542,,,,,0.2944970792156863,109.31565696392914,0.29448943041549935,0.29448943041549935
2020,2020,155.3738,12.935192,4.0222526,0.0,0,5.3271737,0.0,0.31203991,112.54349437079078,5.8903952,342.69296,-9.2980337,112.54349437079078,,,,,0.3006324350326797,109.33865361757815,0.30062478462342035,0.30062478462342035
2023,2023,155.3744,13.024099,4.0930786,0.0,0,5.2621331,0.0,0.31861457,112.51317978573124,5.817101,342.53433,-9.2981615,112.51317978573124,,,,,0.3067677908496732,109.36120339194193,0.3067601388626095,0.3067601388626095
2026,2026,155.375,13.064973,4.1648774,0.0,0,5.1970935,0.0,0.32525688,112.0486837989822,5.746325,342.37573,-9.2980881,112.0486837989822,,,,,0.3129031466666667,109.38332365278121,0.3128954931318516,0.3128954931318516
2029,2029,155.3756,13.170399,4.2352223,0.0,0,5.1320534,0.0,0.33184513,112.14519236713964,5.6782079,342.2171,-9.2992067,112.14519236713964,,,,,0.3190385024836601,109.40503076673015,0.31903084743000154,0.31903084743000154
2032,2032,155.3762,13.273414,4.3018899,0.0,0,5.0670133,0.0,0.33805034,112.25080508487136,5.6078033,342.0585,-9.2985144,112.25080508487136,,,,,0.3251738583006536,109.42634017674521,0.32516620175597877,0.32516620175597877
2035,2035,155.3768,13.315804,4.3730354,0.0,0,5.0044241,0.0,0.344598,111.78313629355831,5.5357351,341.89987,-9.2990561,111.78313629355831,,,,,0.3313092141176471,109.4472664705016,0.3313015561087626,0.3313015561087626
2038,2038,155.3774,13.412508,4.4435744,0.0,0,4.942564,0.0,0.35110807,111.76973393251072,5.4653802,341.74127,-9.2978077,111.76973393251072,,,,,0.3374445699346405,109.46782344262498,0.3374369104873878,0.3374369104873878
2041,2041,155.378,13.517685,4.5119915,0.0,0,4.8807039,0.0,0.35750416,111.8393900480314,5.3945618,341.58264,-9.3003836,111.8393900480314,,,,,0.343579925751634,109.48802415130801,0.34357226489094067,0.34357226489094067
2044,2044,155.3786,13.552657,4.5808854,0.0,0,4.8188443,0.0,0.36392957,111.31405155527204,5.3300791,341.42404,-9.3001432,111.31405155527204,,,,,0.34971528156862747,109.50788096999383,0.34970761931855554,0.34970761931855554
2047,2047,155.3792,13.65273,4.6482615,0.0,0,4.7569842,0.0,0.37038463,111.3332345846632,5.2586217,341.26541,-9.299552,111.3332345846632,,,,,0.3558506373856209,109.5274056345349,0.3558429737694111,0.3558429737694111
2050,2050,155.3798,13.751411,4.7218757,0.0,0,4.6951241,0.0,0.37725165,111.2543514290935,5.1909266,341.10678,-9.2980652,111.2543514290935,,,,,0.3619859932026144,109.54660928641586,0.3619783282427279,0.3619783282427279
2053,2053,155.3804,13.807782,4.7895651,0.0,0,4.6332641,0.0,0.38376939,110.8944523951622,5.1208668,340.94818,-9.2992678,110.8944523951622,,,,,0.36812134901960786,109.56550251235878,0.3681136827377652,0.3681136827377652
2056,2056,155.381,13.891472,4.8548775,0.0,0,4.571404,0.0,0.3902508,110.77436775009758,5.0579095,340.78955,-9.2994728,110.77436775009758,,,,,0.3742567048366013,109.58409538063309,0.3742490372538184,0.3742490372538184
2059,2059,155.3816,13.978306,4.9200096,0.0,0,4.5108657,0.0,0.39656997,110.6716880138694,4.9905386,340.63095,-9.2979698,110.6716880138694,,,,,0.38039206065359477,109.60239747447372,0.3803843917902171,0.3803843917902171
2062,2062,155.3822,14.056276,4.9829936,0.0,0,4.4520135,0.0,0.40295729,110.51568730867622,4.9253206,340.47232,-9.2989321,110.51568730867622,,,,,0.38652741647058825,109.62041792286381,0.3865197463463225,0.3865197463463225
2065,2065,155.3828,14.129436,5.050899,0.0,0,4.3931656,0.0,0.40974897,110.25266206416862,4.8602748,340.21127,-9.2986383,110.25266206416862,,,,,0.39266277228758173,109.63816542884312,0.39265510092152567,0.39265510092152567
2068,2068,155.3834,14.231879,5.1176648,0.0,0,4.3343177,0.0,0.41654751,110.22172874236465,4.7961621,339.4382,-9.2986202,110.22172874236465,,,,,0.39879812810457516,109.65564829571339,0.3987904555152455,0.3987904555152455
2071,2071,155.384,14.328987,5.182663,0.0,0,4.2754698,0.0,0.42338052,110.1598162236984,4.7285833,338.66513,-9.298584,110.1598162236984,,,,,0.40493348392156864,109.67287445121272,0.40492581012692747,0.40492581012692747
2074,2074,155.3846,14.388628,5.2453485,0.0,0,4.2166214,0.0,0.42991006,109.82989688616308,4.6642947,337.89203,-9.2984772,109.82989688616308,,,,,0.4110688397385621,109.68985146989722,0.4110611647560415,0.4110611647560415
2077,2077,155.3852,14.471498,5.3056931,0.0,0,4.1577735,0.0,0.43627355,109.69895630803104,4.6016378,337.11896,-9.2985973,109.69895630803104,,,,,0.41720419555555555,109.70658659386991,0.4171965194020808,0.4171965194020808
2080,2080,155.3858,14.577426,5.3667006,0.0,0,4.0989256,0.0,0.44265571,109.72425842684636,4.5383639,336.34589,-9.2983866,109.72425842684636,,,,,0.42333955137254903,109.72308675204197,0.4233318740645607,0.4233318740645607
2083,2083,155.3864,14.641874,5.4294853,0.0,0,4.0404716,0.0,0.44935483,109.40535330726188,4.4775233,335.57278,-9.2978792,109.40535330726188,,,,,0.4294749071895425,109.73935857793974,0.4294672287430169,0.4294672287430169
2086,2086,155.387,14.716002,5.4936204,0.0,0,3.9844093,0.0,0.45619649,109.13363567938951,4.4132171,334.79971,-9.2995958,109.13363567938951,,,,,0.43561026300653594,109.75540842635804,0.43560258343700486,0.43560258343700486
2089,2089,155.3876,14.850708,5.5527167,0.0,0,3.9284413,0.0,0.46244353,109.36476684250972,4.3547535,334.02664,-9.2992992,109.36476684250972,,,,,0.4417456188235294,109.77124238879608,0.44173793814609835,0.44173793814609835
2092,2092,155.3882,14.929558,5.6101418,0.0,0,3.8724735,0.0,0.468532,109.1952177152898,4.2931786,333.25357,-9.2979918,109.1952177152898,,,,,0.4478809746405229,109.78686630783606,0.44787329286988853,0.44787329286988853
2095,2095,155.3888,15.014074,5.6725411,0.0,0,3.8165054,0.0,0.47510365,108.9934024392926,4.2283607,332.48047,-9.2982368,108.9934024392926,,,,,0.4540163304575163,109.80228579057534,0.45400864760798304,0.45400864760798304
2098,2098,155.3894,15.121556,5.7370248,0.0,0,3.7605371,0.0,0.48193794,108.92007348550813,4.1707568,331.7074,-9.2989101,108.92007348550813,,,,,0.4601516862745098,109.81750622112753,0.4601440023600053,0.4601440023600053
2101,2101,155.39,15.229249,5.7973456,0.0,0,3.7045693,0.0,0.4883506,108.89146545380667,4.1077962,330.93433,-9.2985611,108.89146545380667,,,,,0.4662870420915033,109.8325327723976,0.4662793571255932,0.4662793571255932
2104,2104,155.3906,15.289019,5.8532844,0.0,0,3.6486013,0.0,0.49429893,108.56988399952866,4.0499473,330.16122,-9.2989168,108.56988399952866,,,,,0.4724223979084967,109.8473704169154,0.4724147119043989,0.4724147119043989
2107,2107,155.3912,15.410011,5.9130907,0.0,0,3.5926332,0.0,0.50064379,108.62186357487076,3.9898736,329.38815,-9.298521,108.62186357487076,,,,,0.4785577537254902,109.86202393718953,0.47855006669608774,0.47855006669608774
2110,2110,155.3918,15.527831,5.9734111,0.0,0,3.538765,0.0,0.50704378,108.63183322696293,3.9312842,328.61508,-9.2990732,108.63183322696293,,,,,0.4846931095424837,109.87649793520859,0.4846854215003377,0.4846854215003377
2113,2113,155.3924,15.589083,6.0339785,0.0,0,3.4855206,0.0,0.51371586,108.23306788953084,3.8764627,327.84198,-9.2991896,108.23306788953084,,,,,0.4908284653594771,109.89079684151179,0.49082077631683885,0.49082077631683885
2116,2116,155.393,15.682066,6.0924835,0.0,0,3.432277,0.0,0.52010107,108.07461303676216,3.819962,327.08496,-9.2972965,108.07461303676216,,,,,0.4969638211764706,109.90492492357207,0.4969561311452925,0.4969561311452925
2119,2119,155.3936,15.821076,6.1474814,0.0,0,3.3790326,0.0,0.52618325,108.26995497533274,3.7631726,326.34399,-9.2993917,108.26995497533274,,,,,0.5030991769934641,109.91888629376216,0.503091485985411,0.503091485985411
2122,2122,155.3942,15.901533,6.2053041,0.0,0,3.3257887,0.0,0.53271002,108.0145040666982,3.7070162,325.60306,-9.2977448,108.0145040666982,,,,,0.5092345328104575,109.93268491679403,0.5092268408369168,0.5092268408369168
2125,2125,155.3948,15.986321,6.2622442,0.0,0,3.2725446,0.0,0.53922629,107.79232277277784,3.6482079,324.86209,-9.2974348,107.79232277277784,,,,,0.515369888627451,109.94632461673042,0.5153621956995427,0.5153621956995427
2128,2128,155.3954,16.124569,6.3178968,0.0,0,3.2193007,0.0,0.5458774,107.9375401221842,3.5934618,324.12112,-9.2974195,107.9375401221842,,,,,0.5215052444444445,109.95980908354717,0.5214975505730299,0.5214975505730299
2131,2131,155.396,16.224142,6.3702159,0.0,0,3.1660566,0.0,0.55206275,107.8595637244005,3.5391419,323.38016,-9.2978992,107.8595637244005,,,,,0.5276406002614379,109.97314187939213,0.5276329054571296,0.5276329054571296
2134,2134,155.3966,16.313042,6.4252834,0.0,0,3.11395,0.0,0.55869502,107.6625255508387,3.4858384,322.63919,-9.2981939,107.6625255508387,,,,,0.5337759560784314,109.98632644444173,0.5337682603516011,0.5337682603516011
2137,2137,155.3972,16.446753,6.4791303,0.0,0,3.0632944,0.0,0.56527472,107.767953717138,3.4320295,321.89822,-9.2975578,107.767953717138,,,,,0.5399113118954249,109.99936610237887,0.5399036152562117,0.5399036152562117
2140,2140,155.3978,16.561272,6.530571,0.0,0,3.0126424,0.0,0.57157463,107.7707377925794,3.3799856,321.15726,-9.2976847,107.7707377925794,,,,,0.5460466677124183,110.0122640656548,0.5460389701707364,0.5460389701707364
2143,2143,155.3984,16.65654,6.5830135,0.0,0,2.9619906,0.0,0.57790643,107.62400839263913,3.3240163,320.41629,-9.2982798,107.62400839263913,,,,,0.5521820235294118,110.02502344037862,0.5521743250949585,0.5521743250949585
2146,2146,155.399,16.774815,6.6371546,0.0,0,2.9113381,0.0,0.58446527,107.59096285707274,3.2722375,319.67532,-9.2973528,107.59096285707274,,,,,0.5583173793464052,110.03764723101511,0.5583096800286672,0.5583096800286672
2149,2149,155.3996,16.921839,6.6870079,0.0,0,2.8606863,0.0,0.59062147,107.79327132366213,3.215193,318.93436,-9.2980213,107.79327132366213,,,,,0.5644527351633987,110.05013834473324,0.5644450349716592,0.5644450349716592
2152,2152,155.4002,17.009624,6.7385025,0.0,0,2.810034,0.0,0.59683013,107.58330967526642,3.1641006,318.19342,-9.2978992,107.58330967526642,,,,,0.5705880909803922,110.06249959563509,0.5705803899237378,0.5705803899237378
2155,2155,155.4008,17.141367,6.7899432,0.0,0,2.7593822,0.0,0.60302997,107.64213293284271,3.1112988,317.45245,-9.2967768,107.64213293284271,,,,,0.5767234467973856,110.07473370863018,0.5767157448847122,0.5767157448847122
2158,2158,155.4014,17.290125,6.8475394,0.0,0,2.7090683,0.0,0.60981953,107.70150517886398,3.0556715,316.71149,-9.2977066,107.70150517886398,,,,,0.5828588026143791,110.08684332325765,0.5828510998543978,0.5828510998543978
2161,2161,155.402,17.408928,6.9014068,0.0,0,2.6608074,0.0,0.6161834,107.61762403851525,3.0028269,315.97052,-9.2983036,107.61762403851525,,,,,0.5889941584313726,110.09883099714712,0.5889864548326156,0.5889864548326156
2164,2164,155.4026,17.520048,6.9528055,0.0,0,2.6126273,0.0,0.62230521,107.51323377040806,2.9499679,315.22955,-9.2983875,107.51323377040806,,,,,0.595129514248366,110.11069920943157,0.5951218098191919,0.5951218098191919
2167,2167,155.4032,17.678782,7.0025806,0.0,0,2.5644474,0.0,0.62837505,107.71393966679886,2.8984332,315.07703,-9.2967567,107.71393966679886,,,,,0.6012648700653594,110.1224503639352,0.6012571648139589,0.6012571648139589
2170,2170,155.4038,17.824432,7.0564179,0.0,0,2.5162673,0.0,0.6348896,107.7578348076718,2.8444877,315.04218,-9.2961588,107.7578348076718,,,,,0.607400225882353,110.13408679217872,0.6073925198167532,0.6073925198167532
2173,2173,155.4044,17.928274,7.1122923,0.0,0,2.4680872,0.0,0.64168751,107.50491379181386,2.7939506,315.00729,-9.2970705,107.50491379181386,,,,,0.6135355816993464,110.14561075627614,0.6135278748274166,0.6135278748274166
2176,2176,155.405,18.071409,7.1677279,0.0,0,2.4199073,0.0,0.64868975,107.48229097391354,2.74718,314.97244,-9.2975454,107.48229097391354,,,,,0.6196709375163398,110.1570244516733,0.6196632298457955,0.6196632298457955
2179,2179,155.4056,18.230413,7.2150993,0.0,0,2.3717272,0.0,0.65483594,107.66847213549173,2.6948941,314.93756,-9.2973452,107.66847213549173,,,,,0.6258062933333334,110.16833000974799,0.6257985848717408,0.6257985848717408
2182,2182,155.4062,18.335474,7.2628775,0.0,0,2.3235474,0.0,0.66095853,107.51838821136585,2.6425064,314.90271,-9.295826,107.51838821136585,,,,,0.6319416491503268,110.17952950025553,0.6319339399051075,0.6319339399051075
2185,2185,155.4068,18.477121,7.3154936,0.0,0,2.2771804,0.0,0.66769779,107.49370853259369,2.592736,314.86786,-9.2962971,107.49370853259369,,,,,0.6380770049673202,110.19062493375209,0.6380692949457551,0.6380692949457551
2188,2188,155.4074,18.64731,7.3682423,0.0,0,2.2313523,0.0,0.67481565,107.61832127805528,2.5405786,314.83298,-9.2966614,107.61832127805528,,,,,0.6442123607843138,110.20161826379355,0.644204649993547,0.644204649993547
2191,2191,155.408,18.778757,7.4181747,0.0,0,2.1855242,0.0,0.68160993,107.55174435575192,2.4884334,314.79813,-9.2973318,107.55174435575192,,,,,0.6503477166013072,110.21251138906808,0.6503400050483501,0.6503400050483501
2194,2194,155.4086,18.905771,7.4658327,0.0,0,2.1396964,0.0,0.68796432,107.48613929690562,2.4421301,314.76324,-9.2966299,107.48613929690562,,,,,0.6564830724183006,110.22330615548047,0.6564753601100354,0.6564753601100354
2197,2197,155.4092,19.077787,7.5135221,0.0,0,2.0938683,0.0,0.69469923,107.6631951886921,2.3904181,314.72839,-9.2964001,107.6631951886921,,,,,0.6626184282352942,110.23400435805183,0.6626107151784772,0.6626107151784772
2200,2200,155.4098,19.226151,7.5622654,0.0,0,2.0480404,0.0,0.70131761,107.6753610447752,2.3426011,314.69354,-9.2967262,107.6753610447752,,,,,0.6687537840522876,110.24460774280901,0.6687460702535534,0.6687460702535534
2203,2203,155.4104,19.342157,7.6103835,0.0,0,2.0022123,0.0,0.7079919,107.50548378859612,2.2950063,314.65866,-9.2970028,107.50548378859612,,,,,0.674889139869281,110.2551180085531,0.6748814253351451,0.6748814253351451
2206,2206,155.411,19.511688,7.6533418,0.0,0,1.9563841,0.0,0.71397269,107.70955338751608,2.2452416,314.62381,-9.296876,107.70955338751608,,,,,0.6810244956862745,110.26553680853858,0.6810167804231367,0.6810167804231367
2209,2209,155.4116,19.67374,7.6999874,0.0,0,1.9115355,0.0,0.72057736,107.79579014547188,2.201596,314.58893,-9.2971754,107.79579014547188,,,,,0.687159851503268,110.27586575209,0.6871521355174156,0.6871521355174156
2212,2212,155.4122,19.791658,7.7493815,0.0,0,1.8679364,0.0,0.72734541,107.58066324231008,2.1521487,314.55408,-9.2965221,107.58066324231008,,,,,0.6932952073202614,110.2861064061862,0.693287490617872,0.693287490617872
2215,2215,155.4128,19.959307,7.795146,0.0,0,1.8243403,0.0,0.73361564,107.6871335789562,2.1079397,314.41559,-9.2974005,107.6871335789562,,,,,0.6994305631372549,110.29626029688409,0.6994228457243993,0.6994228457243993
2218,2218,155.4134,20.154842,7.8392658,0.0,0,1.7807443,0.0,0.73965144,107.95851301027656,2.0602353,313.759,-9.2970371,107.95851301027656,,,,,0.7055659189542484,110.30632891078035,0.7055582008368932,0.7055582008368932
2221,2221,155.414,20.278038,7.8875661,0.0,0,1.7371484,0.0,0.74616325,107.7551965512576,2.0138855,313.10245,-9.294899,107.7551965512576,,,,,0.7117012747712418,110.3163136963478,0.7116935559552527,0.7116935559552527
2224,2224,155.4146,20.4272,7.9351249,0.0,0,1.6935524,0.0,0.75263739,107.69149235396948,1.9695027,312.44589,-9.2952242,107.69149235396948,,,,,0.7178366305882353,110.32621606522015,0.7178289110793791,0.7178289110793791
2227,2227,155.4152,20.623243,7.980051,0.0,0,1.6499563,0.0,0.7588172,107.90821781751988,1.9230325,311.78934,-9.2960587,107.90821781751988,,,,,0.7239719864052288,110.33603739344804,0.7239642662091755,0.7239642662091755
2230,2230,155.4158,20.780115,8.0264521,0.0,0,1.6063604,0.0,0.76503307,107.87887303132432,1.8778205,311.13278,-9.2959623,107.87887303132432,,,,,0.7301073422222222,110.34577902269204,0.7300996213445486,0.7300996213445486
2233,2233,155.4164,20.936705,8.0722885,0.0,0,1.5630548,0.0,0.7714988,107.84554999386668,1.8337039,310.4762,-9.2950239,107.84554999386668,,,,,0.7362426980392157,110.35544226136038,0.7362349764854068,0.7362349764854068
2236,2236,155.417,21.147926,8.1205282,0.0,0,1.5215132,0.0,0.77816308,108.03382507613723,1.7838771,309.81964,-9.2947721,108.03382507613723,,,,,0.7423780538562091,110.36502838568367,0.7423703316316606,0.7423703316316606
2239,2239,155.4176,21.311619,8.1671228,0.0,0,1.4800413,0.0,0.78488356,107.9941554713054,1.7405033,309.16309,-9.2952185,107.9941554713054,,,,,0.7485134096732026,110.37453864079609,0.7485056867832228,0.7485056867832228
2242,2242,155.4182,21.455767,8.2108173,0.0,0,1.4385693,0.0,0.79110426,107.89757166448015,1.697137,308.50653,-9.2946014,107.89757166448015,,,,,0.7546487654901961,110.38397424172547,0.7546410419400088,0.7546410419400088
2245,2245,155.4188,21.65531,8.2533779,0.0,0,1.3970973,0.0,0.79756242,108.08787641658792,1.6578432,307.84998,-9.2944698,108.08787641658792,,,,,0.7607841213071895,110.39333637433666,0.7607763971019352,0.7607763971019352
2248,2248,155.4194,21.847422,8.2977152,0.0,0,1.3556253,0.0,0.80433249,108.1920352982384,1.6156194,307.19339,-9.2946787,108.1920352982384,,,,,0.766919477124183,110.40262619631174,0.7669117522689212,0.7669117522689212
2251,2251,155.42,21.998535,8.3414021,0.0,0,1.3141534,0.0,0.81112456,108.09225662391476,1.5703037,306.53683,-9.2955551,108.09225662391476,,,,,0.7730548329411765,110.41184483798992,0.7730471074408878,0.7730471074408878
2254,2254,155.4206,22.195019,8.3837862,0.0,0,1.2726814,0.0,0.81783068,108.22743518738702,1.527298,305.88028,-9.2943516,108.22743518738702,,,,,0.7791901887581699,110.42099340324435,0.7791824626177575,0.7791824626177575
2257,2257,155.4212,22.41522,8.4248705,0.0,0,1.2312094,0.0,0.82440436,108.48830128435166,1.4860473,305.22372,-9.2946301,108.48830128435166,,,,,0.7853255445751635,110.4300729703021,0.785317817799455,0.785317817799455
2260,2260,155.4218,22.589079,8.4634314,0.0,0,1.1913006,0.0,0.8306455,108.56082019846195,1.444254,304.56717,-9.295949,108.56082019846195,,,,,0.7914609003921569,110.43908459256244,0.7914531729859066,0.7914531729859066
2263,2263,155.4224,22.782265,8.5046492,0.0,0,1.1518564,0.0,0.83722436,108.66021025093748,1.4021248,303.91058,-9.2945862,108.66021025093748,,,,,0.7975962562091503,110.44802929929926,0.7975885281770402,0.7975885281770402
2266,2266,155.423,23.008713,8.5477276,0.0,0,1.1124125,0.0,0.84404236,108.86508680864723,1.3593223,303.69409,-9.2939119,108.86508680864723,,,,,0.8037316120261438,110.45690809643516,0.8037238833727857,0.8037238833727857
2269,2269,155.4236,23.207676,8.5895786,0.0,0,1.0729684,0.0,0.8506915,108.9488011226404,1.3145632,303.91754,-9.2938938,108.9488011226404,,,,,0.8098669678431373,110.46572196724486,0.8098592385730738,0.8098592385730738
2272,2272,155.4242,23.399784,8.6272297,0.0,0,1.0335244,0.0,0.85674036,109.07259232120518,1.2737983,304.14102,-9.2941942,109.07259232120518,,,,,0.8160023236601307,110.47447187300385,0.8159945937778377,0.8159945937778377
2275,2275,155.4248,23.616362,8.664607,0.0,0,0.99408036,0.0,0.86263222,109.30249888257993,1.2317822,304.3645,-9.2946301,109.30249888257993,,,,,0.8221376794771242,110.48315875367446,0.8221299489870114,0.8221299489870114
2278,2278,155.4254,23.841711,8.7053699,0.0,0,0.95463634,0.0,0.86866605,109.48704493314568,1.1896653,304.58798,-9.2943459,109.48704493314568,,,,,0.8282730352941177,110.49178352852788,0.8282653042005307,0.8282653042005307
2281,2281,155.426,24.033861,8.7491941,0.0,0,0.91519243,0.0,0.87537634,109.43902801181896,1.1484821,304.81143,-9.2940836,109.43902801181896,,,,,0.8344083911111111,110.5003470967115,0.8344006594183325,0.8344006594183325
2284,2284,155.4266,24.256214,8.7900982,0.0,0,0.87659609,0.0,0.88169175,109.57498640011266,1.1116149,305.03491,-9.2937593,109.57498640011266,,,,,0.8405437469281046,110.50885033788923,0.8405360146403555,0.8405360146403555
2287,2287,155.4272,24.516983,8.8292685,0.0,0,0.83908135,0.0,0.88782233,109.9045112276407,1.068873,305.25839,-9.2944117,109.9045112276407,,,,,0.8466791027450981,110.51729411275454,0.8466713698665393,0.8466713698665393
2290,2290,155.4278,24.725996,8.8716707,0.0,0,0.8015694,0.0,0.89422435,109.91508990130852,1.0257753,305.48187,-9.2942219,109.91508990130852,,,,,0.8528144585620915,110.52567926361783,0.852806725096825,0.852806725096825
2293,2293,155.4284,24.936283,8.9116383,0.0,0,0.7640574,0.0,0.90056103,109.96919724035848,0.9878844,305.70532,-9.2935276,109.96919724035848,,,,,0.858949814379085,110.5340066148774,0.858942080331155,0.858942080331155
2296,2296,155.429,25.200998,8.9513292,0.0,0,0.72654539,0.0,0.90686572,110.25265584527664,0.94582438,305.9288,-9.2928543,110.25265584527664,,,,,0.8650851701960784,110.54227697358571,0.8650774355694727,0.8650774355694727
2299,2299,155.4296,25.429392,8.9930773,0.0,0,0.68903339,0.0,0.91367167,110.3136219054952,0.90449101,306.15228,-9.2930212,110.3136219054952,,,,,0.8712205260130719,110.55049112987005,0.8712127908117228,0.8712127908117228
2302,2302,155.4302,25.64093,9.0336685,0.0,0,0.65152138,0.0,0.92054355,110.3113902358728,0.86877096,306.37576,-9.2943974,110.3113902358728,,,,,0.8773558818300654,110.55864985745737,0.8773481460578514,0.8773481460578514
2305,2305,155.4308,25.907772,9.0712223,0.0,0,0.61400938,0.0,0.92691737,110.59942348468158,0.82883942,306.59921,-9.2924719,110.59942348468158,,,,,0.8834912376470588,110.5667539140862,0.8834835013078052,0.8834835013078052
2308,2308,155.4314,26.141127,9.1092491,0.0,0,0.57674509,0.0,0.93354946,110.71692309854625,0.79109168,306.82269,-9.2916088,110.71692309854625,,,,,0.8896265934640523,110.57480404196664,0.8896188565615324,0.8896188565615324
2311,2311,155.432,26.338919,9.1453562,0.0,0,0.54098594,0.0,0.93995047,110.71396213980395,0.7525962,307.04617,-9.2931662,110.71396213980395,,,,,0.8957619492810458,110.58280096822624,0.8957542118189822,0.8957542118189822
2314,2314,155.4326,26.593746,9.1809683,0.0,0,0.50528592,0.0,0.94622326,110.94789800606812,0.71456563,307.26965,-9.2935171,110.94789800606812,,,,,0.9018973050980392,110.59074540525053,0.9018895670801045,0.9018895670801045
2317,2317,155.4332,26.864101,9.2161827,0.0,0,0.4695859,0.0,0.95257163,111.23949447358773,0.67518473,307.69501,-9.2907801,111.23949447358773,,,,,0.9080326609150327,110.59863805114867,0.9080249223448507,0.9080249223448507
2320,2320,155.4338,27.056965,9.2533979,0.0,0,0.4338859,0.0,0.95931637,111.14790332405364,0.63757467,308.16077,-9.2929249,111.14790332405364,,,,,0.9141680167320262,110.6064795900992,0.9141602776131729,0.9141602776131729
2323,2323,155.4344,27.306023,9.2901077,0.0,0,0.39818591,0.0,0.96605498,111.28478480556724,0.60079986,308.6265,-9.2930803,111.28478480556724,,,,,0.9203033725490196,110.61427069272192,0.920295632885024,0.920295632885024
2326,2326,155.435,27.595095,9.3225718,0.0,0,0.36248589,0.0,0.97219229,111.6708383388383,0.56313521,309.09222,-9.2924376,111.6708383388383,,,,,0.926438728366013,110.62201201644038,0.9264309881603582,0.9264309881603582
2329,2329,155.4356,27.815386,9.3541002,0.0,0,0.32678592,0.0,0.97776091,111.78692629628512,0.53199774,309.55798,-9.2914829,111.78692629628512,,,,,0.9325740841830066,110.62970420581689,0.9325663434391304,0.9325663434391304
2332,2332,155.4362,28.052172,9.3860855,0.0,0,0.29108587,0.0,0.98363435,111.94521849275,0.49547279,310.02371,-9.2916698,111.94521849275,,,,,0.93870944,110.63734789291502,0.9387016987212962,0.9387016987212962