File: examples/hot axisymmetric compression example/data/12 fitted data ramberg/testID_0141.csv
level_0,index,Time(sec),Force(kN),Jaw(mm),PowAngle(deg),Power(W),Pram,PTemp,Strain,Stress(MPa),Stroke(mm),TC1(C),wedge(mm),uncorrected stress,sampled strain,sampled stress,fitting strain,fitting stress,model strain,ramberg stress,ramberg plastic strain,ramberg accumulated plastic strain
1972,1972,165.3446,0.17373385,0.041767292,0.0,0,9.0629702,0.0,0.0025008966,2.111644441082889,10.081654,359.45267,-9.2893105,2.111644441082889,0.0025008966,2.111644441082889,0.0,2.111644441082889,0.0,0.0,0.0,0.0
1974,1974,165.345,3.0217962,0.07847099,0.0,0,9.0044422,0.0,0.0050025117,36.632458383905785,10.005486,359.63733,-9.2893534,36.632458383905785,0.10992184,97.08243346591044,0.095393395,97.45408302104146,0.004202352202643172,90.29707435069513,0.0041963671608472395,0.0041963671608472395
1976,1976,165.3454,5.9221358,0.14450262,0.0,0,8.9459143,0.0,0.0092860721,71.4543801967296,9.9529362,359.82202,-9.2878704,71.4543801967296,0.19590795,98.06966223907328,0.19078679,98.00462442374858,0.008404704405286343,90.9201882521707,0.008398678062454128,0.008398678062454128
1978,1978,165.3458,6.506928,0.20908505,0.0,0,8.8873854,0.0,0.013261824,78.1468521030064,9.8744173,360.00671,-9.2854204,78.1468521030064,0.28330427,97.99771967143975,0.28618018500000003,97.9468610798702,0.012607056607929514,91.29176721309584,0.01260100563621948,0.01260100563621948
1980,1980,165.3462,6.9048162,0.35445711,0.0,0,8.8288574,0.0,0.023088818,82.05719763880003,9.7863255,360.19141,-9.2833652,82.05719763880003,0.37831873,96.18126822114282,0.38157358,96.11680074905995,0.016809408810572687,91.55865469766076,0.01680334014911178,0.01680334014911178
1982,1982,165.3466,7.1178908,0.42836994,0.0,0,8.7703295,0.0,0.028584333,84.13425651213406,9.6884098,360.37607,-9.2845488,84.13425651213406,0.47520834,94.2641512173404,0.476966975,94.23224158568085,0.02101176101321586,91.76755224821976,0.021005678505674332,0.021005678505674332
1984,1984,165.347,7.7319679,0.51553786,0.0,0,8.7136869,0.0,0.034118455,90.80958382573274,9.5913668,360.56076,-9.2853117,90.80958382573274,0.5697065,92.80883352750426,0.5723603700000001,92.79920830668688,0.02521411321585903,91.9394680804293,0.025208019313447308,0.025208019313447308
1986,1986,165.3474,8.2003727,0.59724092,0.0,0,8.6580172,0.0,0.04054711,95.73109141921977,9.5086136,360.74545,-9.2842531,95.73109141921977,0.6646291,92.67301355708902,0.667753765,92.6796229360735,0.0294164654185022,92.08569363921875,0.02941036182401477,0.02941036182401477
1988,1988,165.3478,8.0497246,0.60779721,0.0,0,8.6023531,0.0,0.04097141,93.89889013462204,9.4290409,360.93011,-9.2822275,93.89889013462204,0.76145047,92.92815414860657,0.76314716,92.94360592064932,0.033618817621145373,92.21301062091068,0.03361270558787449,0.03361270558787449
1990,1990,165.3482,7.7280664,0.70670503,0.0,0,8.546689,0.0,0.047617067,89.48526210751717,9.36831,361.11481,-9.2833853,89.48526210751717,0.85773385,94.16203608789122,0.858540555,94.17780552209858,0.037821169823788546,92.3258162840149,0.037815050313568785,0.037815050313568785
1992,1992,165.3486,8.4773407,0.7594291,0.0,0,8.491025,0.0,0.051861852,97.77442625985312,9.3044529,361.2995,-9.2837934,97.77442625985312,0.95393395,95.87259934845451,0.95393395,95.87259934845451,0.04202352202643172,92.42712671283206,0.042017395801186526,0.042017395801186526
1994,1994,165.349,8.5772409,0.81977403,0.0,0,8.4353609,0.0,0.05534387,98.47858276271778,9.2272921,361.48416,-9.2818966,98.47858276271778,,,,,0.04622587422907489,92.51910182014659,0.04621974190756506,0.04621974190756506
1996,1996,165.3494,8.6076345,0.92826355,0.0,0,8.3796968,0.0,0.063471228,98.01905336600424,9.1530218,361.66885,-9.2820511,98.01905336600424,,,,,0.05042822643171806,92.60334216638812,0.050422088526616546,0.050422088526616546
1998,1998,165.3498,8.2415075,1.0018117,0.0,0,8.3240328,0.0,0.068527594,93.3249336908427,9.0715761,361.85355,-9.2830315,93.3249336908427,,,,,0.05463057863436123,92.68106721695153,0.05462443557751278,0.05462443557751278
2000,2000,165.3502,8.7016525,1.0768085,0.0,0,8.2683687,0.0,0.073863521,97.9703541973865,8.9927044,362.03824,-9.2827959,97.9703541973865,,,,,0.0588329308370044,92.7532277234539,0.05882678299723634,0.05882678299723634
2002,2002,165.3506,8.63731,1.1234082,0.0,0,8.2127056,0.0,0.077873677,96.89733126934196,8.9195108,362.2229,-9.2831011,96.89733126934196,,,,,0.06303528303964757,92.82057946255969,0.06302913073569309,0.06302913073569309
2004,2004,165.351,8.8993797,1.1750528,0.0,0,8.1570406,0.0,0.080887631,99.43925239769752,8.8569288,362.40759,-9.2833319,99.43925239769752,,,,,0.06723763524229075,92.88373326742078,0.06723147875239598,0.06723147875239598
2006,2006,165.3514,8.6119099,1.2405235,0.0,0,8.1013775,0.0,0.085953295,95.73872062752991,8.7977896,362.59229,-9.2823458,95.73872062752991,,,,,0.07143998744493392,92.94318995481099,0.07143382701415,0.07143382701415
2008,2008,165.3518,8.9007788,1.2887301,0.0,0,8.0462675,0.0,0.089630365,98.57835115005943,8.7426109,362.75418,-9.2825842,98.57835115005943,,,,,0.07564233964757709,92.99936531397788,0.075636175493396,0.075636175493396
2010,2010,165.3522,9.1450205,1.3604411,0.0,0,7.993176,0.0,0.094095588,100.71518013013028,8.6790981,362.91357,-9.2827549,100.71518013013028,,,,,0.07984469185022026,93.05260837121293,0.07983852416699988,0.07983852416699988
2012,2012,165.3526,8.9315395,1.4416093,0.0,0,7.9402156,0.0,0.10057224,97.73587358588956,8.6143599,363.07294,-9.2830334,97.73587358588956,,,,,0.08404704405286344,93.10321499284288,0.08404087301535115,0.08404087301535115
2014,2014,165.353,8.9657755,1.5023921,0.0,0,7.8872552,0.0,0.10512144,97.63820853444726,8.5474548,363.2323,-9.2836571,97.63820853444726,,,,,0.08824939625550661,93.15143818644306,0.08824322202168003,0.08824322202168003
2016,2016,165.3534,8.9638863,1.5712762,0.0,0,7.8342953,0.0,0.10992184,97.08243346591044,8.4801531,363.39169,-9.283144,97.08243346591044,,,,,0.09245174845814978,93.1974960184081,0.09244557117153272,0.09244557117153272
2018,2018,165.3538,9.2185631,1.6050813,0.0,0,7.7813349,0.0,0.1131753,99.57054456205717,8.4198837,363.55106,-9.2819958,99.57054456205717,,,,,0.09665410066079295,93.24157778115762,0.09664792045236259,0.09664792045236259
2020,2020,165.3542,9.1152067,1.6494508,0.0,0,7.728375,0.0,0.1159337,98.10357250499528,8.3638859,363.71045,-9.2827482,98.10357250499528,,,,,0.10085645286343611,93.28384885508358,0.10085026985320796,0.10085026985320796
2022,2022,165.3546,9.0793772,1.7223979,0.0,0,7.675415,0.0,0.12134898,97.14372510323189,8.3126745,363.86981,-9.2829638,97.14372510323189,,,,,0.10505880506607929,93.324454583715,0.10505261936443522,0.10505261936443522
2024,2024,165.355,9.2727737,1.7555795,0.0,0,7.6224551,0.0,0.12442093,98.94615802265476,8.2590427,364.02921,-9.2829084,98.94615802265476,,,,,0.10926115726872246,93.36352339316755,0.10925496897753205,0.10925496897753205
2026,2026,165.3554,9.4423828,1.8175422,0.0,0,7.5694952,0.0,0.12835099,100.24863429781192,8.2007618,364.18857,-9.2830715,100.24863429781192,,,,,0.11346350947136563,93.40116932642754,0.11345731868493952,0.11345731868493952
2028,2028,165.3558,9.3441448,1.8866926,0.0,0,7.5165353,0.0,0.13403283,98.64526534992208,8.1436501,364.34793,-9.2830029,98.64526534992208,,,,,0.1176658616740088,93.43749411941171,0.11765966847991438,0.11765966847991438
2030,2030,165.3562,9.3284407,1.9379501,0.0,0,7.4635754,0.0,0.13809706,98.0647438646912,8.0864849,364.50732,-9.2822866,98.0647438646912,,,,,0.12186821387665198,93.472588914926,0.12186201835641555,0.12186201835641555
2032,2032,165.3566,9.351285,1.9965119,0.0,0,7.410615,0.0,0.1422285,97.82984801776152,8.0277033,364.66669,-9.2830429,97.82984801776152,,,,,0.12607056607929515,93.50653568789093,0.12606436830900958,0.12606436830900958
2034,2034,165.357,9.5070324,2.0365255,0.0,0,7.3593607,0.0,0.14581658,99.12920036341748,7.9745746,364.82608,-9.2828789,99.12920036341748,,,,,0.13027291828193832,93.53940843824672,0.13026671833279163,0.13026671833279163
2036,2036,165.3574,9.5381756,2.0856693,0.0,0,7.3089876,0.0,0.14930715,99.04724008881334,7.9218292,364.98544,-9.2816868,99.04724008881334,,,,,0.1344752704845815,93.57127419563706,0.13446906842331885,0.13446906842331885
2038,2038,165.3578,9.4358501,2.1410651,0.0,0,7.2586198,0.0,0.15350144,97.53110715273633,7.8752837,365.14484,-9.2813215,97.53110715273633,,,,,0.13867762268722467,93.60219387053586,0.13867141857655405,0.13867141857655405
2040,2040,165.3582,9.5685863,2.1796441,0.0,0,7.2082515,0.0,0.15700446,98.58275953549308,7.8265533,365.3042,-9.2830725,98.58275953549308,,,,,0.14287997488986784,93.63222297900126,0.14287376878881744,0.14287376878881744
2042,2042,165.3586,9.6788092,2.2358456,0.0,0,7.1578832,0.0,0.16081093,99.2462718113124,7.77531,365.46356,-9.2837687,99.2462718113124,,,,,0.147082327092511,93.66141226317342,0.14707611905674584,0.14707611905674584
2044,2044,165.359,9.7134304,2.2914979,0.0,0,7.1075149,0.0,0.16532119,99.13207913987644,7.7234912,365.62296,-9.2828226,99.13207913987644,,,,,0.15128467929515418,93.68980822477597,0.15127846937725695,0.15127846937725695
2046,2046,165.3594,9.6547127,2.3404891,0.0,0,7.0571475,0.0,0.16958387,98.12224093497092,7.6707911,365.78232,-9.282443,98.12224093497092,,,,,0.15548703149779736,93.7174535861079,0.15548081974751912,0.15548081974751912
2048,2048,165.3598,9.6955376,2.3952088,0.0,0,7.0067787,0.0,0.17329733,98.07656928706388,7.6155043,365.94171,-9.2816525,98.07656928706388,,,,,0.15968938370044053,93.74438768988914,0.15968317016492464,0.15968317016492464
2050,2050,165.3602,9.7959442,2.4316313,0.0,0,6.9564114,0.0,0.1766787,98.78247130146632,7.5686798,366.10107,-9.2830086,98.78247130146632,,,,,0.1638917359030837,93.7706468475239,0.16388552062706674,0.16388552062706674
2052,2052,165.3606,9.8120518,2.4795136,0.0,0,6.9060431,0.0,0.18056858,98.53695496396844,7.5222554,366.26047,-9.2835512,98.53695496396844,,,,,0.16809408810572687,93.79626464354462,0.16808787113171936,0.16808787113171936
2054,2054,165.361,9.7970638,2.5354304,0.0,0,6.8556757,0.0,0.18443464,97.91071850668702,7.4711804,366.41983,-9.2838421,97.91071850668702,,,,,0.17229644030837005,93.82127220276054,0.17229022167681948,0.17229022167681948
2056,2056,165.3614,9.9063482,2.5718167,0.0,0,6.8053074,0.0,0.18788038,98.6898495859038,7.4242039,366.57919,-9.2842512,98.6898495859038,,,,,0.17649879251101322,93.84569842534613,0.1764925722604516,0.1764925722604516
2058,2058,165.3618,9.9969778,2.6229005,0.0,0,6.7554412,0.0,0.19187994,99.1491740742398,7.3772025,366.64288,-9.2829952,99.1491740742398,,,,,0.1807011447136564,93.8695701945019,0.18069492288083377,0.18069492288083377
2060,2060,165.3622,9.9363823,2.6783426,0.0,0,6.7074018,0.0,0.19590795,98.06966223907328,7.3299274,366.68262,-9.2821674,98.06966223907328,,,,,0.18490349691629956,93.89291256040698,0.18489727353630572,0.18489727353630572
2062,2062,165.3626,9.9780512,2.7191498,0.0,0,6.6594815,0.0,0.19996467,98.12719709520968,7.2801785,366.72238,-9.2830696,98.12719709520968,,,,,0.18910584911894274,93.9157489035961,0.1890996242253177,0.1890996242253177
2064,2064,165.363,10.027951,2.7645967,0.0,0,6.6115613,0.0,0.20329946,98.2219758323755,7.2306404,366.76212,-9.2836237,98.2219758323755,,,,,0.1933082013215859,93.93810108052234,0.19330197494642104,0.19330197494642104
2066,2066,165.3634,10.1268,2.8122847,0.0,0,6.5636415,0.0,0.20700435,98.77057070611322,7.1839857,366.80188,-9.2833805,98.77057070611322,,,,,0.19751055352422908,93.95998955358772,0.19750432569825943,0.19750432569825943
2068,2068,165.3638,10.133085,2.8576128,0.0,0,6.5157218,0.0,0.21129417,98.4327354557702,7.1361961,366.84161,-9.283699,98.4327354557702,,,,,0.20171290572687223,93.98143350751944,0.2017066764795613,0.2017066764795613
2070,2070,165.3642,10.117955,2.9059219,0.0,0,6.467802,0.0,0.21476549,97.8609708887659,7.0896068,366.88138,-9.2831497,97.8609708887659,,,,,0.2059152579295154,94.0024509539065,0.2059090272891328,0.2059090272891328
2072,2072,165.3646,10.22543,2.9544773,0.0,0,6.4198813,0.0,0.21897995,98.46893239525204,7.043097,366.92111,-9.2832174,98.46893239525204,,,,,0.21011761013215857,94.02305882517598,0.21011137812585165,0.21011137812585165
2074,2074,165.365,10.303287,2.9982293,0.0,0,6.3719611,0.0,0.2228331,98.82683300487764,6.9951305,366.96085,-9.2823801,98.82683300487764,,,,,0.21431996233480174,94.04327305934638,0.2143137289886614,0.2143137289886614
2076,2076,165.3654,10.328493,3.0469935,0.0,0,6.3240414,0.0,0.22635587,98.63075356479588,6.9457507,367.00061,-9.2822361,98.63075356479588,,,,,0.21852231453744492,94.06310867664264,0.21851607987656654,0.21851607987656654
2078,2078,165.3658,10.309958,3.0998459,0.0,0,6.2761216,0.0,0.23124991,97.97999711926526,6.8957453,367.04034,-9.2822819,97.97999711926526,,,,,0.2227246667400881,94.08257984882181,0.2227184307886277,0.2227184307886277
2080,2080,165.3662,10.343328,3.1428103,0.0,0,6.2282019,0.0,0.23480307,97.910714786219,6.8495955,367.08011,-9.2841959,97.910714786219,,,,,0.22692701894273126,94.10169996204772,0.22692078172395766,0.22692078172395766
2082,2082,165.3666,10.435468,3.1894009,0.0,0,6.1802816,0.0,0.23842496,98.36011899690104,6.7998695,367.11984,-9.2843876,98.36011899690104,,,,,0.23112937114537443,94.12048167409834,0.2311231326817174,0.2311231326817174
2084,2084,165.367,10.484544,3.2344773,0.0,0,6.1339045,0.0,0.24288952,98.41166305252032,6.75387,367.15961,-9.2826233,98.41166305252032,,,,,0.2353317233480176,94.13893696641564,0.2353254836611128,0.2353254836611128
2086,2086,165.3674,10.507305,3.2789245,0.0,0,6.0883236,0.0,0.2460928,98.21909782007177,6.7037802,367.19934,-9.2824059,98.21909782007177,,,,,0.23953407555066078,94.15707719154405,0.23952783466139138,0.23952783466139138
2088,2088,165.3678,10.550919,3.3261223,0.0,0,6.042748,0.0,0.25015411,98.19360681100714,6.6575766,367.23907,-9.2816572,98.19360681100714,,,,,0.24373642775330395,94.17491311655317,0.24373018568183946,0.24373018568183946
2090,2090,165.3682,10.595968,3.3728328,0.0,0,5.9971714,0.0,0.25469816,98.18227622585628,6.6111145,367.27884,-9.2833099,98.18227622585628,,,,,0.24793877995594713,94.19245496270094,0.24793253672177962,0.24793253672177962
2092,2092,165.3686,10.650795,3.4256058,0.0,0,5.9515953,0.0,0.25850624,98.20126000181028,6.5605812,367.31857,-9.2838488,98.20126000181028,,,,,0.2521411321585903,94.20971244182823,0.2521348877805681,0.2521348877805681
2094,2094,165.369,10.698177,3.4736443,0.0,0,5.9060197,0.0,0.26300988,98.19092472859504,6.5169525,367.35834,-9.2836218,98.19092472859504,,,,,0.2563434843612335,94.22669478975234,0.25633723885759274,0.25633723885759274
2096,2096,165.3694,10.726142,3.515208,0.0,0,5.8604436,0.0,0.26697391,98.0596177612336,6.4695234,367.39807,-9.2839975,98.0596177612336,,,,,0.26054583656387664,94.24341079695779,0.26053958995227083,0.26053958995227083
2098,2098,165.3698,10.768418,3.5684133,0.0,0,5.814867,0.0,0.27078435,97.94745063223918,6.4222164,367.43784,-9.2831354,97.94745063223918,,,,,0.26474818876651984,94.25986883685613,0.26474194106404747,0.26474194106404747
2100,2100,165.3702,10.813875,3.6112723,0.0,0,5.7692914,0.0,0.27528778,97.95748772863128,6.3721585,367.47757,-9.2824841,97.95748772863128,,,,,0.268950540969163,94.27607689183714,0.2689442921923935,0.2689442921923935
2102,2102,165.3706,10.855525,3.6546071,0.0,0,5.7237153,0.0,0.27896544,97.9252518841144,6.3255782,367.5173,-9.2824459,97.9252518841144,,,,,0.27315289317180613,94.29204257730771,0.2731466433368042,0.2731466433368042
2104,2104,165.371,10.923186,3.7111659,0.0,0,5.6781397,0.0,0.28330427,97.99771967143975,6.2793322,367.55707,-9.2830658,97.99771967143975,,,,,0.27735524537444933,94.30777316391627,0.2773489944967977,0.2773489944967977
2106,2106,165.3714,10.962426,3.7511518,0.0,0,5.6325636,0.0,0.28767681,97.96807769302843,6.2307124,367.5968,-9.283514,97.96807769302843,,,,,0.2815575975770925,94.32327559808876,0.2815513456719135,0.2815513456719135
2108,2108,165.3718,10.986844,3.7972102,0.0,0,5.5874414,0.0,0.29131749,97.74561973137612,6.1825609,367.39999,-9.2832985,97.74561973137612,,,,,0.2857599497797357,94.3385565211215,0.2857536968617114,0.2857536968617114
2110,2110,165.3722,11.021204,3.8530791,0.0,0,5.5439734,0.0,0.296101,97.51503048055996,6.1370325,367.10175,-9.2831669,97.51503048055996,,,,,0.2899623019823788,94.35362228680528,0.2899560480657703,0.2899560480657703
2112,2112,165.3726,11.101121,3.8931537,0.0,0,5.5006132,0.0,0.30047756,97.83462775516097,6.0894318,366.80353,-9.2829952,97.83462775516097,,,,,0.294164654185022,94.36847897786656,0.29415839928368703,0.29415839928368703
2114,2114,165.373,11.166239,3.9429145,0.0,0,5.457253,0.0,0.30423504,97.92447425049242,6.0426011,366.50531,-9.2826939,97.92447425049242,,,,,0.29836700638766517,94.3831324211576,0.2983607505150753,0.2983607505150753
2116,2116,165.3734,11.17841,3.9931035,0.0,0,5.4138932,0.0,0.30906811,97.54241170075484,5.9956918,366.20709,-9.2816696,97.54241170075484,,,,,0.30256935859030837,94.39758820192314,0.30256310175956513,0.30256310175956513
2118,2118,165.3738,11.208585,4.0332031,0.0,0,5.370533,0.0,0.31301042,97.41408355581414,5.9459057,365.90884,-9.2829247,97.41408355581414,,,,,0.3067717107929515,94.41185167694417,0.3067654530168012,0.3067654530168012
2120,2120,165.3742,11.248676,4.0855227,0.0,0,5.3271732,0.0,0.31719488,97.24964763934474,5.8985777,365.61063,-9.2843199,97.24964763934474,,,,,0.3109740629955947,94.42592798693249,0.3109678042864429,0.3109678042864429
2122,2122,165.3746,11.334742,4.1314955,0.0,0,5.283813,0.0,0.32207957,97.5395687762228,5.8511376,365.31241,-9.2833672,97.5395687762228,,,,,0.31517641519823786,94.43982206797442,0.315170155568163,0.315170155568163
2124,2124,165.375,11.394669,4.1764226,0.0,0,5.2404532,0.0,0.32598802,97.60903863508584,5.8014731,365.01419,-9.2820272,97.60903863508584,,,,,0.31937876740088106,94.45353866229992,0.3193725068616473,0.3193725068616473
2126,2126,165.3754,11.400357,4.2256999,0.0,0,5.1970935,0.0,0.33022097,97.16802989163357,5.7545447,364.71594,-9.2819586,97.16802989163357,,,,,0.3235811196035242,94.46708232833255,0.3235748581665935,0.3235748581665935
2128,2128,165.3758,11.444669,4.2702861,0.0,0,5.1537333,0.0,0.33505666,97.10082481071808,5.7071404,364.41772,-9.2816582,97.10082481071808,,,,,0.3277834718061674,94.48045745009797,0.32777720948271116,0.32777720948271116
2130,2130,165.3762,11.510249,4.3181305,0.0,0,5.110373,0.0,0.3389878,97.17703973109124,5.6602812,364.11951,-9.2835255,97.17703973109124,,,,,0.33198582400881055,94.49366824604418,0.3319795608097205,0.3319795608097205
2132,2132,165.3766,11.575825,4.3652153,0.0,0,5.0670133,0.0,0.3432987,97.25535839408302,5.6133194,363.82129,-9.2837362,97.25535839408302,,,,,0.33618817621145375,94.50671877726168,0.3361819121473526,0.3361819121473526
2134,2134,165.377,11.606699,4.4086752,0.0,0,5.0250483,0.0,0.34806207,97.07480379588596,5.5704551,363.52307,-9.28304,97.07480379588596,,,,,0.3403905284140969,94.51961295526428,0.34038426349534795,0.34038426349534795
2136,2136,165.3774,11.637017,4.4602733,0.0,0,4.9838037,0.0,0.35211504,96.804616468099,5.5207591,363.22482,-9.2826424,96.804616468099,,,,,0.3445928806167401,94.53235454927307,0.34458661485345693,0.34458661485345693
2138,2138,165.3778,11.685396,4.5037637,0.0,0,4.9425635,0.0,0.35658416,96.76371681045256,5.4737554,362.92661,-9.2830534,96.76371681045256,,,,,0.34879523281938324,94.54494719304024,0.34878896622143846,0.34878896622143846
2140,2140,165.3782,11.729447,4.5453453,0.0,0,4.9013238,0.0,0.36092955,96.702955705572,5.4279008,362.62839,-9.2830973,96.702955705572,,,,,0.35299758502202644,94.55739439127956,0.35299131759906044,0.35299131759906044
2142,2142,165.3786,11.787486,4.5991602,0.0,0,4.8600836,0.0,0.36513385,96.62793249231196,5.3785844,362.33017,-9.283577,96.62793249231196,,,,,0.3571999372246696,94.56969952573333,0.3571936689860986,0.3571936689860986
2144,2144,165.379,11.837365,4.6383286,0.0,0,4.8188438,0.0,0.36969623,96.63218685729925,5.3367548,362.03192,-9.2833118,96.63218685729925,,,,,0.3614022894273128,94.58186586086423,0.3613960203823367,0.3613960203823367
2146,2146,165.3794,11.872477,4.6832809,0.0,0,4.7776036,0.0,0.37387863,96.45300820453608,5.2944012,361.7337,-9.2826109,96.45300820453608,,,,,0.36560464162995593,94.59389654926127,0.3655983717875656,0.3655983717875656
2148,2148,165.3798,11.90571,4.7354069,0.0,0,4.7363639,0.0,0.37831873,96.18126822114282,5.2436357,361.43549,-9.2828798,96.18126822114282,,,,,0.36980699383259913,94.6057946366446,0.3698007232015836,0.3698007232015836
2150,2150,165.3802,11.951527,4.775002,0.0,0,4.6951237,0.0,0.38309515,96.13827161240911,5.203403,361.13727,-9.2825356,96.13827161240911,,,,,0.3740093460352423,94.6175630667383,0.3740030746241954,0.3740030746241954
2152,2152,165.3806,12.008119,4.8191481,0.0,0,4.6538839,0.0,0.38702482,96.13064695074496,5.1559215,360.83902,-9.2836218,96.13064695074496,,,,,0.3782116982378855,94.62920468572563,0.3782054260552125,0.3782054260552125
2154,2154,165.381,12.084074,4.8701277,0.0,0,4.6126437,0.0,0.3917827,96.20075413665688,5.1109476,360.5408,-9.2829494,96.20075413665688,,,,,0.3824140504405286,94.64072224655233,0.38240777749445237,0.38240777749445237
2156,2156,165.3814,12.115498,4.9089842,0.0,0,4.5714035,0.0,0.39643887,96.03977964368411,5.0656905,360.24258,-9.2829199,96.03977964368411,,,,,0.3866164026431718,94.65211841294202,0.3866101289417385,0.3866101289417385
2158,2158,165.3818,12.124918,4.9551358,0.0,0,4.5305758,0.0,0.40020376,95.625686497798,5.0228338,359.9162,-9.2829161,95.625686497798,,,,,0.39081875484581496,94.66339576325524,0.3908124803969,0.3908124803969
2160,2160,165.3822,12.17924,5.003006,0.0,0,4.4912457,0.0,0.40532532,95.5448042598906,4.9786739,359.57101,-9.2832842,95.5448042598906,,,,,0.39502110704845816,94.67455679408916,0.39501483185977126,0.39501483185977126
2162,2162,165.3826,12.264888,5.0402117,0.0,0,4.4520135,0.0,0.40933427,95.81803110164734,4.9322371,359.22586,-9.2830877,95.81803110164734,,,,,0.3992234592511013,94.68560392369871,0.3992171833301921,0.3992171833301921
2164,2164,165.383,12.309346,5.0870132,0.0,0,4.4127812,0.0,0.41339323,95.66198243949428,4.8893104,358.88068,-9.2815857,95.66198243949428,,,,,0.40342581145374445,94.69653949527626,0.4034195348080072,0.4034195348080072
2166,2166,165.3834,12.331613,5.1335025,0.0,0,4.3735495,0.0,0.41876069,95.33404628315942,4.8473792,358.53552,-9.2817001,95.33404628315942,,,,,0.40762816365638765,94.7073657800158,0.40762188629306606,0.40762188629306606
2168,2168,165.3838,12.356467,5.1743879,0.0,0,4.3343177,0.0,0.4227646,95.0846522834944,4.8007035,358.19034,-9.2830095,95.0846522834944,,,,,0.4118305158590308,94.71808498004972,0.41182423778522265,0.41182423778522265
2170,2170,165.3842,12.438459,5.2201743,0.0,0,4.2950859,0.0,0.42696333,95.21778468350452,4.7590446,357.84518,-9.283926,95.21778468350452,,,,,0.416032868061674,94.72869923121353,0.41602658928433545,0.41602658928433545
2172,2172,165.3846,12.517095,5.2601585,0.0,0,4.2558532,0.0,0.43191278,95.38222701319545,4.7138996,357.5,-9.2832365,95.38222701319545,,,,,0.42023522026431714,94.73921060571587,0.420228940790267,0.420228940790267
2174,2174,165.385,12.543233,5.3030772,0.0,0,4.2166214,0.0,0.43568629,95.1107305795866,4.6702361,357.15485,-9.2843494,95.1107305795866,,,,,0.42443757246696034,94.74962111463249,0.4244312923028842,0.4244312923028842
2176,2176,165.3854,12.578712,5.3483138,0.0,0,4.1773891,0.0,0.44024456,94.88219700861514,4.6273732,356.80966,-9.282423,94.88219700861514,,,,,0.4286399246696035,94.75993271027181,0.42863364382205743,0.42863364382205743
2178,2178,165.3858,12.604307,5.385704,0.0,0,4.1381574,0.0,0.44491598,94.66312094591188,4.5849686,356.46451,-9.2824068,94.66312094591188,,,,,0.4328422768722467,94.77014728850546,0.43283599534766126,0.43283599534766126
2180,2180,165.3862,12.676683,5.4318438,0.0,0,4.0989256,0.0,0.4487696,94.69512443768576,4.5424981,356.11932,-9.2820396,94.69512443768576,,,,,0.43704462907488983,94.78026669086918,0.4370383468795734,0.4370383468795734
2182,2182,165.3866,12.746221,5.4733338,0.0,0,4.0596933,0.0,0.45350528,94.75197878536898,4.4994044,355.77417,-9.2828293,94.75197878536898,,,,,0.44124698127753303,94.79029270666086,0.44124069841767544,0.44124069841767544
2184,2184,165.387,12.790253,5.5107589,0.0,0,4.0217257,0.0,0.45785004,94.66053682680574,4.4604273,355.42899,-9.283309,94.66053682680574,,,,,0.4454493334801762,94.80022707490185,0.44544304996185197,0.44544304996185197
2186,2186,165.3874,12.822345,5.560833,0.0,0,3.9844091,0.0,0.46208951,94.3362728430468,4.4199176,355.08383,-9.284132,94.3362728430468,,,,,0.4496516856828194,94.81007148619254,0.449645401511991,0.449645401511991
2188,2188,165.3878,12.875946,5.5950556,0.0,0,3.9470971,0.0,0.46666837,94.34503198217332,4.3754072,354.73865,-9.2824097,94.34503198217332,,,,,0.4538540378854625,94.81982758451153,0.4538477530679836,0.4538477530679836
2190,2190,165.3882,12.930708,5.6341591,0.0,0,3.9097853,0.0,0.47069788,94.30377694852578,4.336391,354.39349,-9.2812605,94.30377694852578,,,,,0.4580563900881057,94.82949696890671,0.45805010462972373,0.45805010462972373
2192,2192,165.3886,13.002939,5.6839266,0.0,0,3.8724732,0.0,0.47520834,94.2641512173404,4.2956357,354.04831,-9.2818184,94.2641512173404,,,,,0.46225874229074887,94.83908119514304,0.46225245619710825,0.46225245619710825
2194,2194,165.389,13.045982,5.7157717,0.0,0,3.8351612,0.0,0.47976461,94.21251418993091,4.2547731,353.70316,-9.2820005,94.21251418993091,,,,,0.46646109449339207,94.84858177722708,0.46645480777003695,0.46645480777003695
2196,2196,165.3894,13.07993,5.7557626,0.0,0,3.7978492,0.0,0.48341486,93.99973337958929,4.2148943,353.35797,-9.2837391,93.99973337958929,,,,,0.4706634466960352,94.85800018893705,0.4706571593484119,0.4706571593484119
2198,2198,165.3898,13.122822,5.8023486,0.0,0,3.7605371,0.0,0.48825696,93.77270076678803,4.1757665,353.01279,-9.2832212,93.77270076678803,,,,,0.4748657988986784,94.86733786518681,0.47485951093213824,0.47485951093213824
2200,2200,165.3902,13.197958,5.8341084,0.0,0,3.7232251,0.0,0.49270847,93.94254895495332,4.1332755,352.66763,-9.2832508,93.94254895495332,,,,,0.47906815110132156,94.87659620340425,0.4790618625211232,0.4790618625211232
2202,2202,165.3906,13.27982,5.8766341,0.0,0,3.6859133,0.0,0.4963505,94.0306544834998,4.0960355,352.32245,-9.2805977,94.0306544834998,,,,,0.48327050330396476,94.8857765648535,0.4832642141152766,0.4832642141152766
2204,2204,165.391,13.318419,5.9194593,0.0,0,3.6486013,0.0,0.50143754,93.80438251429138,4.0555048,351.97729,-9.2813616,93.80438251429138,,,,,0.4874728555066079,94.89488027584925,0.48746656571451047,0.48746656571451047
2206,2206,165.3914,13.341702,5.9530292,0.0,0,3.611289,0.0,0.50561666,93.57602710736664,4.0162244,351.63211,-9.28234,93.57602710736664,,,,,0.4916752077092511,94.90390862895617,0.4916689173187393,0.4916689173187393
2208,2208,165.3918,13.405991,5.9949765,0.0,0,3.5743496,0.0,0.50942963,93.53426633931792,3.9782736,351.51627,-9.283453,93.53426633931792,,,,,0.49587755991189425,94.91286288410221,0.49587126892787936,0.49587126892787936
2210,2210,165.3922,13.475355,6.0312381,0.0,0,3.5387647,0.0,0.51417941,93.5900751393524,3.939728,351.62976,-9.2838688,93.5900751393524,,,,,0.5000799121145374,94.92174426973024,0.5000736205418493,0.5000736205418493
2212,2212,165.3926,13.555835,6.0667009,0.0,0,3.5032687,0.0,0.51803529,93.72776822152902,3.9012623,351.74326,-9.2829218,93.72776822152902,,,,,0.5042822643171806,94.930553983765,0.5042759721605699,0.5042759721605699
2214,2214,165.393,13.58469,6.1102409,0.0,0,3.4677725,0.0,0.5223437,93.4089015630686,3.8646202,351.85675,-9.2822084,93.4089015630686,,,,,0.5084846165198238,94.93929319470739,0.5084783237839635,0.5084783237839635
2216,2216,165.3934,13.625897,6.1473632,0.0,0,3.4322767,0.0,0.52747333,93.24887830867844,3.8239932,351.97025,-9.2817125,93.24887830867844,,,,,0.512686968722467,94.94796304250615,0.5126806754119546,0.5126806754119546
2218,2218,165.3938,13.691483,6.1860709,0.0,0,3.3967807,0.0,0.53107715,93.23313729439523,3.7860782,352.08374,-9.282114,93.23313729439523,,,,,0.5168893209251101,94.95656463953298,0.5168830270444694,0.5168830270444694
2220,2220,165.3942,13.768173,6.2245417,0.0,0,3.3612847,0.0,0.53548133,93.29098566678358,3.7459922,352.19724,-9.2825613,93.29098566678358,,,,,0.5210916731277533,94.96509907145737,0.5210853786814361,0.5210853786814361
2222,2222,165.3946,13.829482,6.257246,0.0,0,3.3257885,0.0,0.54009604,93.30983325302805,3.7100542,352.31073,-9.2836027,93.30983325302805,,,,,0.5252940253303965,94.97356739810624,0.5252877303227844,0.5252877303227844
2224,2224,165.395,13.87824,6.2985315,0.0,0,3.2902927,0.0,0.54367173,93.1363602932186,3.6728988,352.42422,-9.2831211,93.1363602932186,,,,,0.5294963775330397,94.98197065424107,0.5294900819684457,0.5294900819684457
2226,2226,165.3954,13.928039,6.333602,0.0,0,3.2547965,0.0,0.54821187,93.04216308759644,3.6361139,352.53772,-9.2829161,93.04216308759644,,,,,0.5336987297356828,94.99030985039472,0.5336924336183528,0.5336924336183528
2228,2228,165.3958,13.987903,6.3648243,0.0,0,3.2193005,0.0,0.55232519,93.0589982803801,3.5992787,352.65121,-9.2819834,93.0589982803801,,,,,0.537901081938326,94.9985859736085,0.5378947852724407,0.5378947852724407
2230,2230,165.3962,14.078149,6.4106393,0.0,0,3.1838045,0.0,0.55640799,93.09358611159948,3.5626509,352.76471,-9.2814426,93.09358611159948,,,,,0.5421034341409692,95.00679998814478,0.5420971369306452,0.5420971369306452
2232,2232,165.3966,14.142567,6.4447947,0.0,0,3.1483085,0.0,0.56128949,93.09576532457764,3.5259507,352.8782,-9.2822418,93.09576532457764,,,,,0.5463057863436123,95.01495283617093,0.5462994885929038,0.5462994885929038
2234,2234,165.397,14.192851,6.4805388,0.0,0,3.1139498,0.0,0.56538767,92.98163659389164,3.4906754,352.9917,-9.2823973,92.98163659389164,,,,,0.5505081385462555,95.02304543848172,0.5505018402591557,0.5505018402591557
2236,2236,165.3974,14.250753,6.5246897,0.0,0,3.0801783,0.0,0.5697065,92.80883352750426,3.4508421,353.10519,-9.2824697,92.80883352750426,,,,,0.5547104907488987,95.03107869508273,0.5547041919293412,0.5547041919293412
2238,2238,165.3978,14.299299,6.5506344,0.0,0,3.0464103,0.0,0.57409239,92.79939487879984,3.4152298,353.21869,-9.2815247,92.79939487879984,,,,,0.5589128429515419,95.03905348587081,0.5589065436034019,0.5589065436034019
2240,2240,165.3982,14.387031,6.5853992,0.0,0,3.0126421,0.0,0.57757133,92.92975125762612,3.3815615,353.33218,-9.2819204,92.92975125762612,,,,,0.563115195154185,95.04697067117934,0.5631088952812806,0.5631088952812806
2242,2242,165.3986,14.458733,6.6290874,0.0,0,2.9788742,0.0,0.58240443,92.83838626138112,3.3458242,353.44568,-9.2821522,92.83838626138112,,,,,0.5673175473568282,95.05483109240147,0.5673112469629219,0.5673112469629219
2244,2244,165.399,14.518862,6.6563783,0.0,0,2.9451063,0.0,0.586748,92.87660326459029,3.3105166,353.55917,-9.2816801,92.87660326459029,,,,,0.5715198995594714,95.06263557248171,0.571513598648271,0.571513598648271
2246,2246,165.3994,14.57298,6.6964831,0.0,0,2.9113381,0.0,0.59047842,92.70963306825874,3.2739329,353.67267,-9.2818222,92.70963306825874,,,,,0.5757222517621146,95.07038491654141,0.5757159503372747,0.5757159503372747
2248,2248,165.3998,14.629052,6.7372246,0.0,0,2.8775702,0.0,0.59577435,92.54296785812414,3.2392397,353.78616,-9.2815647,92.54296785812414,,,,,0.5799246039647576,95.07807991229797,0.5799183020298805,0.5799183020298805
2250,2250,165.4002,14.737682,6.7642875,0.0,0,2.8438022,0.0,0.59966755,92.87987808129571,3.2020869,353.89966,-9.2823477,92.87987808129571,,,,,0.5841269561674008,95.08572133064222,0.5841206537260377,0.5841206537260377
2252,2252,165.4006,14.832313,6.8028455,0.0,0,2.810034,0.0,0.60335422,92.97394149924894,3.1656373,354.01315,-9.2823296,92.97394149924894,,,,,0.588329308370044,95.09330992606549,0.588323005425696,0.588323005425696
2254,2254,165.401,14.868945,6.8383775,0.0,0,2.7762663,0.0,0.60854691,92.73946623072236,3.1341715,354.12665,-9.2815351,92.73946623072236,,,,,0.5925316605726872,95.10084643713373,0.5925253571288066,0.5925253571288066
2256,2256,165.4014,14.929197,6.8706903,0.0,0,2.7424982,0.0,0.61222345,92.69145940639288,3.0969436,354.24014,-9.2822638,92.69145940639288,,,,,0.5967340127753303,95.10833158694868,0.5967277088353214,0.5967277088353214
2258,2258,165.4018,15.005623,6.9106774,0.0,0,2.7090681,0.0,0.61659861,92.6387623057252,3.0634167,354.10953,-9.2832699,92.6387623057252,,,,,0.6009363649779735,95.11576608356185,0.6009300605451937,0.6009300605451937
2260,2260,165.4022,15.101566,6.944283,0.0,0,2.6768675,0.0,0.62187833,92.78512103592486,3.0263944,353.61276,-9.2826509,92.78512103592486,,,,,0.6051387171806167,95.12315062040054,0.6051324122583773,0.6051324122583773
2262,2262,165.4026,15.191176,6.9783459,0.0,0,2.6447473,0.0,0.62526363,92.88093605021928,2.9938955,353.116,-9.2809563,92.88093605021928,,,,,0.6093410693832599,95.13048587666648,0.6093347639748274,0.6093347639748274
2264,2264,165.403,15.233953,7.013351,0.0,0,2.6126273,0.0,0.62957132,92.6737784544704,2.9606237,352.61923,-9.2805061,92.6737784544704,,,,,0.613543421585903,95.1377725177276,0.6135371156944998,0.6135371156944998
2266,2266,165.4034,15.28942,7.0434089,0.0,0,2.580507,0.0,0.6343224,92.607235896014,2.9235456,352.12247,-9.2823772,92.607235896014,,,,,0.6177457737885462,95.14501119546745,0.6177394674173512,0.6177394674173512
2268,2268,165.4038,15.371442,7.0852189,0.0,0,2.5483871,0.0,0.63815618,92.53904592621836,2.8891721,351.6257,-9.2821856,92.53904592621836,,,,,0.6219481259911894,95.15220254868497,0.6219418191433395,0.6219418191433395
2270,2270,165.4042,15.479835,7.1174879,0.0,0,2.5162671,0.0,0.64300144,92.75240339729088,2.8548861,351.12891,-9.2820902,92.75240339729088,,,,,0.6261504781938326,95.15934720342351,0.6261441708724229,0.6261441708724229
2272,2272,165.4046,15.567628,7.1479592,0.0,0,2.4841471,0.0,0.64746076,92.86132718237587,2.8189652,350.63214,-9.2814322,92.86132718237587,,,,,0.6303528303964757,95.16644577330835,0.6303465226045609,0.6303465226045609
2274,2274,165.405,15.633365,7.1907582,0.0,0,2.4520271,0.0,0.6515885,92.66503932201977,2.7877769,350.13538,-9.2820377,92.66503932201977,,,,,0.6345551825991189,95.17349885987952,0.6345488743397136,0.6345488743397136
2276,2276,165.4054,15.688075,7.2179513,0.0,0,2.4199073,0.0,0.65609878,92.61411916623564,2.752151,349.63861,-9.2820625,92.61411916623564,,,,,0.6387575348017621,95.18050705291162,0.6387512260778421,0.6387512260778421
2278,2278,165.4058,15.776332,7.2503376,0.0,0,2.3877871,0.0,0.66005677,92.6857222954762,2.7183607,349.14185,-9.280817,92.6857222954762,,,,,0.6429598870044053,95.18747093069669,0.6429535778189077,0.6429535778189077
2280,2280,165.4062,15.876677,7.2934566,0.0,0,2.3556671,0.0,0.6646291,92.67301355708902,2.6848943,348.64508,-9.280756,92.67301355708902,,,,,0.6471622392070484,95.19439106037228,0.6471559295628729,0.6471559295628729
2282,2282,165.4066,15.962631,7.3189678,0.0,0,2.3235471,0.0,0.66938967,92.81645373094814,2.6506374,348.14832,-9.2814293,92.81645373094814,,,,,0.6513645914096916,95.20126799819224,0.6513582813097012,0.6513582813097012
2284,2284,165.407,16.014784,7.3527603,0.0,0,2.2924592,0.0,0.67308319,92.64352739010782,2.6171367,347.65155,-9.2815514,92.64352739010782,,,,,0.6555669436123348,95.20810228979765,0.6555606330593561,0.6555606330593561
2286,2286,165.4074,16.077284,7.3944225,0.0,0,2.261904,0.0,0.67819589,92.4156513083921,2.5812182,347.15479,-9.2815084,92.4156513083921,,,,,0.659769295814978,95.21489447051272,0.6597629848118021,0.6597629848118021
2288,2288,165.4078,16.172468,7.4182134,0.0,0,2.2313521,0.0,0.68258119,92.62417101496588,2.5479054,346.65802,-9.2806988,92.62417101496588,,,,,0.6639716480176211,95.22164506555745,0.6639653365670044,0.6639653365670044
2290,2290,165.4082,16.296284,7.4527726,0.0,0,2.2008002,0.0,0.6859569,92.83760310277796,2.5173252,346.16125,-9.2800627,92.83760310277796,,,,,0.6681740002202643,95.22835459036035,0.668167688324929,0.668167688324929
2292,2292,165.4086,16.370958,7.4916859,0.0,0,2.170248,0.0,0.69137478,92.70223864769248,2.4822161,345.66446,-9.2801189,92.70223864769248,,,,,0.6723763524229075,95.23502355072984,0.6723700400855424,0.6723700400855424
2294,2294,165.409,16.431763,7.5160613,0.0,0,2.1396961,0.0,0.69546819,92.6939444207737,2.4493353,345.16769,-9.2814617,92.6939444207737,,,,,0.6765787046255506,95.24165244316445,0.6765723918488113,0.6765723918488113
2296,2296,165.4094,16.515474,7.5524225,0.0,0,2.109144,0.0,0.69914901,92.63744741614674,2.4172473,344.67093,-9.2814283,92.63744741614674,,,,,0.6807810568281938,95.2482417550382,0.6807747436147038,0.6807747436147038
2298,2298,165.4098,16.624317,7.5866933,0.0,0,2.0785921,0.0,0.7048009,92.7462955326298,2.3836415,344.17416,-9.2809515,92.7462955326298,,,,,0.684983409030837,95.25479196483107,0.6849770953831882,0.6849770953831882
2300,2300,165.4102,16.728251,7.6159825,0.0,0,2.0480402,0.0,0.70850527,92.89467078872754,2.3508136,343.6774,-9.2809515,92.89467078872754,,,,,0.6891857612334802,95.26130354235754,0.6891794471542331,0.6891794471542331
2302,2302,165.4106,16.804489,7.652699,0.0,0,2.0174882,0.0,0.71266961,92.77463019029544,2.3167758,343.18063,-9.2806578,92.77463019029544,,,,,0.6933881134361233,95.26777694895405,0.6933817989278078,0.6933817989278078
2304,2304,165.411,16.868637,7.6841769,0.0,0,1.986936,0.0,0.71823752,92.6610805581288,2.2822466,342.68387,-9.2797852,92.6610805581288,,,,,0.6975904656387665,95.27421263768419,0.6975841507038828,0.6975841507038828
2306,2306,165.4114,16.966734,7.714694,0.0,0,1.9563839,0.0,0.72163486,92.74383248278862,2.254885,342.1871,-9.2811346,92.74383248278862,,,,,0.7017928178414097,95.2806110535792,0.7017865024824282,0.7017865024824282
2308,2308,165.4118,17.080908,7.7484121,0.0,0,1.9261372,0.0,0.72597438,92.860544429363,2.2215111,341.5928,-9.2815247,92.860544429363,,,,,0.7059951700440529,95.28697263375561,0.7059888542634152,0.7059888542634152
2310,2310,165.4122,17.178553,7.7741561,0.0,0,1.8970003,0.0,0.73082948,93.00174826294445,2.1917195,340.7709,-9.2815733,93.00174826294445,,,,,0.710197522246696,95.29329780766525,0.7101912060468152,0.7101912060468152
2312,2312,165.4126,17.274315,7.8103447,0.0,0,1.8679363,0.0,0.73435116,92.96935489556016,2.1587133,339.94897,-9.2811413,92.96935489556016,,,,,0.7143998744493392,95.2995869972307,0.7143935578326003,0.7143935578326003
2314,2314,165.413,17.345625,7.8424172,0.0,0,1.8388723,0.0,0.73948497,92.86289422738898,2.1267765,339.12708,-9.2800093,92.86289422738898,,,,,0.7186022266519824,95.30584061704624,0.718595909620743,0.718595909620743
2316,2316,165.4134,17.43655,7.8694386,0.0,0,1.8098083,0.0,0.7439158,92.93443715387052,2.096873,338.30518,-9.2798138,92.93443715387052,,,,,0.7228045788546256,95.31205907454866,0.7227982614112165,0.7227982614112165
2318,2318,165.4138,17.540346,7.9105668,0.0,0,1.7807442,0.0,0.74803078,92.85180732285102,2.063844,337.48328,-9.2800665,92.85180732285102,,,,,0.7270069310572687,95.3182427701559,0.7270006132039938,0.7270006132039938
2320,2320,165.4142,17.661314,7.9365239,0.0,0,1.7516803,0.0,0.75310624,93.08805604870771,2.0325353,336.66138,-9.2799511,93.08805604870771,,,,,0.7312092832599119,95.32439209746377,0.7312029649990492,0.7312029649990492
2322,2322,165.4146,17.753149,7.9647202,0.0,0,1.7226163,0.0,0.75699407,93.13080583516994,2.0039799,335.83945,-9.2799854,93.13080583516994,,,,,0.7354116354625551,95.33050744335073,0.7354053167963571,0.7354053167963571
2324,2324,165.415,17.834679,8.0048084,0.0,0,1.6935523,0.0,0.76145047,92.92815414860657,1.9727234,335.01755,-9.2802382,92.92815414860657,,,,,0.7396139876651983,95.33658918819827,0.739607668595892,0.739607668595892
2326,2326,165.4154,17.931683,8.0263338,0.0,0,1.6644882,0.0,0.76609278,93.09325876089916,1.9409657,334.19565,-9.2798414,93.09325876089916,,,,,0.7438163398678413,95.34263770596918,0.7438100203976292,0.7438100203976292
2328,2328,165.4158,18.043451,8.056263,0.0,0,1.6354243,0.0,0.76964062,93.19731262626968,1.9097973,333.37375,-9.2808533,93.19731262626968,,,,,0.7480186920704845,95.34865336439587,0.7480123722015445,0.7480123722015445
2330,2330,165.4162,18.171223,8.0965691,0.0,0,1.6063603,0.0,0.77492183,93.21136875318174,1.8792943,332.55185,-9.2805672,93.21136875318174,,,,,0.7522210442731277,95.3546365250961,0.7522147240076137,0.7522147240076137
2332,2332,165.4166,18.265162,8.118269,0.0,0,1.5772963,0.0,0.77960002,93.34366898404232,1.8495942,331.72992,-9.2787714,93.34366898404232,,,,,0.756423396475771,95.36058754371356,0.7564170758158134,0.7564170758158134
2334,2334,165.417,18.359474,8.1531477,0.0,0,1.5491643,0.0,0.78326243,93.26082916553958,1.8168877,330.90802,-9.2798433,93.26082916553958,,,,,0.760625748678414,95.36650677006251,0.7606194276261202,0.7606194276261202
2336,2336,165.4174,18.446646,8.1870813,0.0,0,1.5215131,0.0,0.78860414,93.15146054598452,1.7891268,330.08612,-9.2800074,93.15146054598452,,,,,0.7648281008810572,95.37239454823474,0.7648217794385116,0.7648217794385116
2338,2338,165.4178,18.569078,8.2078266,0.0,0,1.4938651,0.0,0.79243058,93.42987487373269,1.7558351,329.26422,-9.2810545,93.42987487373269,,,,,0.7690304530837004,95.37825121673063,0.769024131252965,0.769024131252965
2340,2340,165.4182,18.694897,8.2405462,0.0,0,1.4662172,0.0,0.79591179,93.52326066687242,1.7278996,328.44232,-9.2800255,93.52326066687242,,,,,0.7732328052863436,95.3840771085904,0.7732264830694583,0.7732264830694583
2342,2342,165.4186,18.792543,8.2723742,0.0,0,1.4385692,0.0,0.80177361,93.48399280917288,1.6973035,327.62039,-9.2798166,93.48399280917288,,,,,0.7774351574889867,95.38987255149222,0.7774288348879697,0.7774288348879697
2344,2344,165.419,18.885647,8.2985973,0.0,0,1.4109212,0.0,0.80562377,93.5101366666182,1.6678787,326.79849,-9.2787104,93.5101366666182,,,,,0.7816375096916299,95.39563786788436,0.781631186708478,0.781631186708478
2346,2346,165.4194,18.977129,8.3340902,0.0,0,1.3832732,0.0,0.80982488,93.36870036271918,1.6383059,325.97659,-9.2799158,93.36870036271918,,,,,0.7858398618942731,95.40137337509825,0.7858335385309622,0.7858335385309622
2348,2348,165.4198,19.108494,8.3610477,0.0,0,1.3556252,0.0,0.81543785,93.56040480612596,1.6111159,325.15469,-9.2802382,93.56040480612596,,,,,0.7900422140969163,95.40707938542458,0.7900358903554013,0.7900358903554013
2350,2350,165.4202,19.238588,8.3884258,0.0,0,1.3279773,0.0,0.81868404,93.73249083923174,1.5760827,324.33279,-9.2787256,93.73249083923174,,,,,0.7942445662995594,95.41275620626044,0.7942382421817753,0.7942382421817753
2352,2352,165.4206,19.347942,8.4175243,0.0,0,1.3003292,0.0,0.82282221,93.76832757726852,1.5511864,323.51086,-9.2796888,93.76832757726852,,,,,0.7984469185022026,95.41840414019559,0.798440594010064,0.798440594010064
2354,2354,165.421,19.432695,8.4406481,0.0,0,1.2726812,0.0,0.82774854,93.7824087948152,1.5206982,322.68896,-9.2792625,93.7824087948152,,,,,0.8026492707048458,95.42402348510073,0.8026429458402475,0.8026429458402475
2356,2356,165.4214,19.549858,8.4772482,0.0,0,1.2450333,0.0,0.83143336,93.71616405834658,1.4924772,321.86707,-9.2786293,93.71616405834658,,,,,0.8068516229074889,95.42961453424857,0.8068452976723064,0.8068452976723064
2358,2358,165.4218,19.675011,8.5059519,0.0,0,1.2176626,0.0,0.83664143,93.81750576206656,1.466114,321.0647,-9.2796555,93.81750576206656,,,,,0.8110539751101321,95.43517757637213,0.8110476495062219,0.8110476495062219
2360,2360,165.4222,19.820107,8.5294218,0.0,0,1.1913005,0.0,0.84126121,94.09865314907807,1.4395554,320.34042,-9.279952,94.09865314907807,,,,,0.8152563273127753,95.44071289580255,0.8152500013419748,0.8152500013419748
2362,2362,165.4226,19.923201,8.567112,0.0,0,1.1650044,0.0,0.8450231,93.92504885650924,1.4082495,319.61615,-9.2795181,93.92504885650924,,,,,0.8194586795154185,95.4462207725351,0.8194523531795467,0.8194523531795467
2364,2364,165.423,20.014389,8.5872068,0.0,0,1.1387082,0.0,0.84983838,93.99978530829672,1.3780422,318.89188,-9.2796412,93.99978530829672,,,,,0.8236610317180616,95.45170148230888,0.8236547050189191,0.8236547050189191
2366,2366,165.4234,20.133142,8.6114569,0.0,0,1.1124123,0.0,0.85345227,94.12635926160794,1.3515158,318.1676,-9.2790632,94.12635926160794,,,,,0.8278633839207048,95.45715529670709,0.8278570568600743,0.8278570568600743
2368,2368,165.4238,20.284256,8.6489019,0.0,0,1.0861163,0.0,0.85773385,94.16203608789122,1.3209572,317.44333,-9.2797527,94.16203608789122,,,,,0.832065736123348,95.46258248324828,0.8320594087029944,0.8320594087029944
2370,2370,165.4242,20.424253,8.6688662,0.0,0,1.0598202,0.0,0.86294299,94.45177609378229,1.2933129,316.71906,-9.2781973,94.45177609378229,,,,,0.8362680883259912,95.46798330543137,0.8362617605476621,0.8362617605476621
2372,2372,165.4246,20.520847,8.6984396,0.0,0,1.0335243,0.0,0.86652744,94.36243600412963,1.2651386,315.99478,-9.2785406,94.36243600412963,,,,,0.8404704405286343,95.47335802287068,0.8404641123940599,0.8404641123940599
2374,2374,165.425,20.62674,8.7334003,0.0,0,1.0072283,0.0,0.87173593,94.21236969358657,1.2363185,315.27051,-9.2782364,94.21236969358657,,,,,0.8446727927312775,95.47870689130595,0.8446664642421711,0.8446664642421711
2376,2376,165.4254,20.75341,8.7523661,0.0,0,0.98093224,0.0,0.87625796,94.44322480524012,1.2079455,314.54623,-9.2787361,94.44322480524012,,,,,0.8488751449339207,95.48403016275424,0.848868816091979,0.848868816091979
2378,2378,165.4258,20.907061,8.7820768,0.0,0,0.95463622,0.0,0.87952703,94.59368935328656,1.1814259,313.82196,-9.2800121,94.59368935328656,,,,,0.8530774971365639,95.48932808551135,0.8530711679434669,0.8530711679434669
2380,2380,165.4262,21.049047,8.8123045,0.0,0,0.92834032,0.0,0.88506281,94.67396785001444,1.1520203,313.09769,-9.2797766,94.67396785001444,,,,,0.857279849339207,95.49460090426335,0.8572735197966187,0.8572735197966187
2382,2382,165.4266,21.159452,8.8310575,0.0,0,0.9020443,0.0,0.88886869,94.81995525570488,1.1228515,312.37341,-9.27843,94.81995525570488,,,,,0.8614822015418502,95.49984886017468,0.8614758716514186,0.8614758716514186
2384,2384,165.427,21.263302,8.8635111,0.0,0,0.87659597,0.0,0.89248097,94.67559646681896,1.0966598,311.64914,-9.2784662,94.67559646681896,,,,,0.8656845537444934,95.50507219087818,0.8656782235078506,0.8656782235078506
2386,2386,165.4274,21.407084,8.8925228,0.0,0,0.85158527,0.0,0.89850819,94.76700674818102,1.0711476,310.92487,-9.278738,94.76700674818102,,,,,0.8698869059471366,95.51027113065004,0.8698805753658994,0.8698805753658994
2388,2388,165.4278,21.5597,8.9134302,0.0,0,0.82657719,0.0,0.90183443,95.04430129771336,1.0430071,310.20059,-9.2783318,95.04430129771336,,,,,0.8740892581497797,95.51544591039213,0.8740829272255494,0.8740829272255494
2390,2390,165.4282,21.702812,8.9435472,0.0,0,0.80156928,0.0,0.90559304,95.0975854497056,1.0138742,309.47632,-9.2783537,95.0975854497056,,,,,0.8782916103524229,95.52059675771717,0.8782852790867858,0.8782852790867858
2392,2392,165.4286,21.806618,8.9672489,0.0,0,0.77656126,0.0,0.91129863,95.09567310880036,0.98721862,308.75204,-9.2778339,95.09567310880036,,,,,0.8824939625550661,95.52572389703401,0.8824876309495936,0.8824876309495936
2394,2394,165.429,21.940243,8.9928684,0.0,0,0.75155324,0.0,0.91453654,95.18161815477336,0.96056002,308.02777,-9.2787504,95.18161815477336,,,,,0.8866963147577093,95.53082754957991,0.886689982813958,0.886689982813958
2396,2396,165.4294,22.082701,9.0222187,0.0,0,0.72654527,0.0,0.91904473,95.22679467181202,0.93565041,307.3035,-9.2785101,95.22679467181202,,,,,0.8908986669603524,95.53590793351933,0.8908923346798648,0.8908923346798648
2398,2398,165.4298,22.248308,9.0433798,0.0,0,0.70153725,0.0,0.92413163,95.52481815767152,0.90784705,306.57922,-9.2773647,95.52481815767152,,,,,0.8951010191629956,95.5409652639121,0.8950946865472996,0.8950946865472996
2400,2400,165.4302,22.387941,9.074111,0.0,0,0.67652929,0.0,0.92754519,95.51621676623046,0.88278872,305.85495,-9.2773485,95.51621676623046,,,,,0.8993033713656388,95.54599975289156,0.8992970384162484,0.8992970384162484
2402,2402,165.4306,22.503107,9.100275,0.0,0,0.65152127,0.0,0.9326061,95.4871304508883,0.85617751,305.13068,-9.2774696,95.4871304508883,,,,,0.903505723568282,95.55101160963723,0.9034993902866973,0.9034993902866973
2404,2404,165.431,22.633995,9.1204128,0.0,0,0.62651324,0.0,0.93706089,95.63961941538348,0.83350843,304.4064,-9.2778206,95.63961941538348,,,,,0.907708075770925,95.55600104044396,0.9077017421586326,0.9077017421586326
2406,2406,165.4314,22.777891,9.1531029,0.0,0,0.60150528,0.0,0.94058537,95.58942384937728,0.80742759,303.68213,-9.2781963,95.58942384937728,,,,,0.9119104279735682,95.56096824878884,0.9119040940320409,0.9119040940320409
2408,2408,165.4318,22.961382,9.1731911,0.0,0,0.57674497,0.0,0.94556123,95.9517061756176,0.77979475,303.0405,-9.276722,95.9517061756176,,,,,0.9161127801762114,95.56591343538331,0.9161064459069088,0.9161064459069088
2410,2410,165.4322,23.101204,9.1966639,0.0,0,0.55288589,0.0,0.9494611,96.05663045990649,0.75559515,303.14276,-9.2766972,96.05663045990649,,,,,0.9203151323788547,95.57083679820589,0.9203087977832233,0.9203087977832233
2412,2412,165.4326,23.226871,9.2310734,0.0,0,0.52908581,0.0,0.95393395,95.87259934845451,0.73040527,303.24503,-9.2772989,95.87259934845451,,,,,0.9245174845814977,95.57573853254695,0.9245111496609711,0.9245111496609711
2414,2414,165.433,23.369579,9.2459831,0.0,0,0.5052858,0.0,0.95864135,96.15360519067096,0.70408458,303.34732,-9.2783365,96.15360519067096,,,,,0.9287198367841409,95.58061883111526,0.92871350154014,0.92871350154014
2416,2416,165.4334,23.533064,9.2695246,0.0,0,0.48148578,0.0,0.96164495,96.33646684659378,0.6762889,303.44958,-9.2780361,96.33646684659378,,,,,0.9329221889867841,95.5854778839925,0.932915853420717,0.932915853420717
2418,2418,165.4338,23.70001,9.3048372,0.0,0,0.4576858,0.0,0.96715224,96.27996011660004,0.64979607,303.55185,-9.2774382,96.27996011660004,,,,,0.9371245411894273,95.59031587875681,0.9371182053026897,0.9371182053026897
2420,2420,165.4342,23.844109,9.3206463,0.0,0,0.43388578,0.0,0.97180617,96.53207560853694,0.62720907,303.65411,-9.2771368,96.53207560853694,,,,,0.9413268933920704,95.59513300048538,0.9413205571860459,0.9413205571860459
2422,2422,165.4346,23.9795,9.3474684,0.0,0,0.4100858,0.0,0.97490317,96.51153444138376,0.60065818,303.75638,-9.2770405,96.51153444138376,,,,,0.9455292455947136,95.59992943182895,0.9455229090707736,0.9455229090707736
2424,2424,165.435,24.127638,9.3771973,0.0,0,0.38628578,0.0,0.980483,96.47355378274848,0.57584476,303.85864,-9.2769861,96.47355378274848,,,,,0.9497315977973568,95.60470535300337,0.9497252609568607,0.9497252609568607
2426,2426,165.4354,24.293562,9.3895969,0.0,0,0.36248577,0.0,0.98382384,96.87065594275349,0.55096054,303.96091,-9.2767763,96.87065594275349,,,,,0.95393395,95.60946094189795,0.9539276128442955,0.9539276128442955