File: examples/hot axisymmetric compression example/data/12 fitted data ramberg/testID_0131.csv
level_0,index,Time(sec),Force(kN),Jaw(mm),PowAngle(deg),Power(W),Pram,PTemp,Strain,Stress(MPa),Stroke(mm),TC1(C),wedge(mm),uncorrected stress,sampled strain,sampled stress,fitting strain,fitting stress,model strain,ramberg stress,ramberg plastic strain,ramberg accumulated plastic strain
1773,1773,145.347,0.21278074,0.032323588,0.0,0,9.0337067,0.0,0.0022823047,2.587976465950603,10.074883,294.54654,-9.3237391,2.587976465950603,0.0022823047,2.587976465950603,0.0,2.587976465950603,0.0,0.0,0.0,0.0
1776,1776,145.3476,4.4924927,0.093186229,0.0,0,8.9459143,0.0,0.0059624389,54.40417076257257,9.9801044,295.27628,-9.3233767,54.40417076257257,0.15932438,121.82954229472573,0.14795868631578946,121.79979126637528,0.006124651503267974,108.53453679825454,0.006122721565517996,0.006122721565517996
1779,1779,145.3482,6.6644325,0.17576744,0.0,0,8.8581219,0.0,0.011389344,80.23047819911314,9.8775597,296.00604,-9.3205166,80.23047819911314,0.2960535,121.52904867226678,0.2959173726315789,121.53111363689699,0.012249303006535948,110.10022109460596,0.012247345228125135,0.012247345228125135
1782,1782,145.3488,7.7337279,0.3784554,0.0,0,8.7703304,0.0,0.025113115,91.74747512323484,9.7404509,296.73578,-9.3177395,91.74747512323484,0.44528168,119.30892983875388,0.4438760589473684,119.33586118289759,0.018373954509803923,111.04948494351817,0.018371979851787863,0.018371979851787863
1785,1785,145.3494,8.8252029,0.49924701,0.0,0,8.6858492,0.0,0.033287253,103.77369035828166,9.5773439,297.46552,-9.3184738,103.77369035828166,0.59329718,117.98340793026644,0.5918347452631578,117.99104737960005,0.024498606013071897,111.73842004914464,0.02449661910456022,0.02449661910456022
1788,1788,145.35,9.7688293,0.59692121,0.0,0,8.6023531,0.0,0.040763877,114.04394513753068,9.444088,298.19528,-9.3165674,114.04394513753068,0.74197954,118.74317696106051,0.7397934315789474,118.7217858542703,0.030623257516339868,112.28179645848077,0.030621260945625946,0.030621260945625946
1791,1791,145.3506,9.2993841,0.69526267,0.0,0,8.518857,0.0,0.047026142,107.77205039787708,9.339735,298.92502,-9.3166962,107.77205039787708,0.88942957,121.88745887436798,0.8877521178947368,121.8466147748746,0.036747909019607845,112.73169224080365,0.03674590444894405,0.03674590444894405
1794,1794,145.3512,10.072695,0.77454698,0.0,0,8.4353609,0.0,0.052816883,116.04282213132086,9.2327728,299.65479,-9.3168745,116.04282213132086,,,,,0.042872560522875816,113.11628241934916,0.042870549113512325,0.042870549113512325
1797,1797,145.3518,10.367243,0.9189201,0.0,0,8.3518648,0.0,0.06253469,118.1403870904139,9.1146126,300.38452,-9.3172121,118.1403870904139,,,,,0.048997212026143794,113.45257912915805,0.04899519463682466,0.04899519463682466
1800,1800,145.3524,10.247864,1.0519266,0.0,0,8.2683697,0.0,0.07214383,115.59970423942126,8.9862823,301.11429,-9.3160944,115.59970423942126,,,,,0.055121863529411765,113.75166249622767,0.055119840821856635,0.055119840821856635
1803,1803,145.353,10.490437,1.1489681,0.0,0,8.1848736,0.0,0.079291798,117.45431960671785,8.8639212,301.84402,-9.315114,117.45431960671785,,,,,0.061246515032679735,114.02116185183594,0.061244487532945126,0.061244487532945126
1806,1806,145.3536,10.772242,1.2218002,0.0,0,8.1013775,0.0,0.084315948,119.92988727507228,8.7700262,302.4259,-9.3161201,119.92988727507228,,,,,0.06737116653594771,114.26655947519393,0.06736913467260544,0.06736913467260544
1809,1809,145.3542,10.878234,1.3032954,0.0,0,8.0196619,0.0,0.090317078,120.34188633766908,8.6887569,302.92215,-9.3175945,120.34188633766908,,,,,0.07349581803921569,114.4919303250173,0.07349378216837751,0.07349378216837751
1812,1812,145.3548,10.982172,1.4175968,0.0,0,7.9402156,0.0,0.098276988,120.40402469941928,8.5962,303.41843,-9.3167992,120.40402469941928,,,,,0.07962046954248365,114.70038770217823,0.07961842996490132,0.07961842996490132
1815,1815,145.3554,10.943342,1.5332434,0.0,0,7.8607755,0.0,0.10689767,118.88148479902388,8.4912539,303.91467,-9.3145685,118.88148479902388,,,,,0.08574512104575163,114.89436501789487,0.08574307801890646,0.08574307801890646
1818,1818,145.356,11.212583,1.62054,0.0,0,7.7813354,0.0,0.11359464,120.95787715826218,8.3885994,304.41095,-9.3150864,120.95787715826218,,,,,0.09186977254901961,115.07580115564141,0.09186772629591612,0.09186772629591612
1821,1821,145.3566,11.217353,1.6818477,0.0,0,7.7018952,0.0,0.11813539,120.41312639645452,8.3034964,304.90723,-9.3172979,120.41312639645452,,,,,0.09799442405228759,115.24626653798606,0.0979923747680054,0.0979923747680054
1824,1824,145.3572,11.252187,1.7589794,0.0,0,7.6224551,0.0,0.12408672,120.03453402860336,8.2329378,305.40347,-9.3169851,120.03453402860336,,,,,0.10411907555555555,115.40705132782587,0.10411702341223286,0.10411702341223286
1827,1827,145.3578,11.622049,1.8346921,0.0,0,7.543015,0.0,0.12972176,123.21703300784382,8.1518202,305.89975,-9.3157406,123.21703300784382,,,,,0.11024372705882353,115.55922866198202,0.11024167220951628,0.11024167220951628
1830,1830,145.3584,11.506961,1.9279181,0.0,0,7.4635754,0.0,0.13694613,121.06645545241037,8.0673428,306.396,-9.3148632,121.06645545241037,,,,,0.1163683785620915,115.70370095703576,0.11636632114380903,0.11636632114380903
1833,1833,145.359,11.497,2.0098932,0.0,0,7.3846664,0.0,0.14352876,120.14409876436396,7.9785824,306.89227,-9.3161058,120.14409876436396,,,,,0.12249303006535947,115.84123445921625,0.12249097020148589,0.12249097020148589
1836,1836,145.3596,11.796378,2.0688422,0.0,0,7.3089881,0.0,0.14814019,122.66930876479074,7.8991346,307.38852,-9.3172836,122.66930876479074,,,,,0.12861768156862746,115.97248545186953,0.128615619370877,0.128615619370877
1839,1839,145.3602,11.770989,2.1453061,0.0,0,7.2334356,0.0,0.1542315,121.62431851915385,7.8296061,307.8848,-9.3153772,121.62431851915385,,,,,0.13474233307189543,116.0980204309703,0.13474026864190902,0.13474026864190902
1842,1842,145.3608,11.856318,2.2110498,0.0,0,7.1578832,0.0,0.15932438,121.82954229472573,7.754003,308.38107,-9.3151827,121.82954229472573,,,,,0.1408669845751634,116.21833184442704,0.14086491800582535,0.14086491800582535
1845,1845,145.3614,12.011025,2.2963433,0.0,0,7.0823312,0.0,0.16610028,122.53005790946511,7.6766715,308.87732,-9.3148193,122.53005790946511,,,,,0.14699163607843138,116.33385051791409,0.14698956745496516,0.14698956745496516
1848,1848,145.362,11.989952,2.3775072,0.0,0,7.0067792,0.0,0.17254911,121.4703020129263,7.596715,309.3736,-9.3162966,121.4703020129263,,,,,0.15311628758169935,116.44495557213895,0.153114216982587,0.153114216982587
1851,1851,145.3626,12.114168,2.437372,0.0,0,6.9312277,0.0,0.1774641,122.09909835261,7.5214529,309.86984,-9.3168945,122.09909835261,,,,,0.1592409390849673,116.55198241717757,0.15923886658272668,0.15923886658272668
1854,1854,145.3632,12.16877,2.5061371,0.0,0,6.8556757,0.0,0.18284796,121.92283175866142,7.4513264,310.36606,-9.3157244,121.92283175866142,,,,,0.1653655905882353,116.65522925456486,0.16536351625008164,0.16536351625008164
1857,1857,145.3638,12.287962,2.569732,0.0,0,6.7801232,0.0,0.18781085,122.4384096623322,7.3858266,310.02768,-9.3155394,122.4384096623322,,,,,0.17149024209150326,116.75496241080967,0.17148816597991612,0.17148816597991612
1860,1860,145.3644,12.382369,2.6471291,0.0,0,6.7074022,0.0,0.1939598,122.54668947592332,7.3149114,309.68927,-9.3151169,122.54668947592332,,,,,0.17761489359477123,116.85142074546619,0.17761281576798274,0.17761281576798274
1863,1863,145.365,12.366549,2.724699,0.0,0,6.6355219,0.0,0.20002927,121.55679340020554,7.2424264,309.35089,-9.3173199,121.55679340020554,,,,,0.18373954509803922,116.94481932059267,0.1837374656104574,0.1837374656104574
1866,1866,145.3656,12.524897,2.791178,0.0,0,6.5636415,0.0,0.20556475,122.3898392235176,7.1692867,309.01248,-9.3182268,122.3898392235176,,,,,0.18986419660130718,117.03535247561219,0.1898621155038843,0.1898621155038843
1869,1869,145.3662,12.596852,2.8590841,0.0,0,6.4917622,0.0,0.21096063,122.34964908950128,7.0955791,308.67407,-9.3165131,122.34964908950128,,,,,0.19598884810457518,117.12319641949783,0.19598676544513022,0.19598676544513022
1872,1872,145.3668,12.640128,2.9263315,0.0,0,6.4198818,0.0,0.21643113,122.0312365281709,7.0292559,308.33569,-9.3154068,122.0312365281709,,,,,0.20211349960784314,117.20851142909936,0.20211141543134506,0.20211141543134506
1875,1875,145.3674,12.783061,3.0012498,0.0,0,6.3480015,0.0,0.22246723,122.57870822729916,6.9589791,307.99728,-9.3159857,122.57870822729916,,,,,0.2082381511111111,117.29144372277987,0.20823606545992884,0.20823606545992884
1878,1878,145.368,12.827201,3.0758023,0.0,0,6.2761221,0.0,0.22870113,122.17059957971225,6.8862166,307.65887,-9.3162107,122.17059957971225,,,,,0.2143628026143791,117.37212706598791,0.214360715528503,0.214360715528503
1881,1881,145.3686,12.870502,3.1465251,0.0,0,6.2042422,0.0,0.23470522,121.79155722937352,6.8137612,307.3205,-9.3155241,121.79155722937352,,,,,0.22048745411764706,117.45068415322193,0.22048536563488577,0.22048536563488577
1884,1884,145.3692,13.001857,3.2105854,0.0,0,6.1339049,0.0,0.24015944,122.31022816592709,6.7416553,306.98209,-9.3169975,122.31022816592709,,,,,0.22661210562091502,117.5272278029819,0.22661001577707104,0.22661001577707104
1887,1887,145.3698,13.078543,3.2771158,0.0,0,6.065536,0.0,0.24579027,122.27482612312704,6.6719213,306.64368,-9.3163023,122.27482612312704,,,,,0.232736757124183,117.6018619950424,0.2327346659532099,0.2327346659532099
1890,1890,145.3704,13.159781,3.3514521,0.0,0,5.9971719,0.0,0.25220683,122.1833627764326,6.6040192,306.3053,-9.315237,122.1833627764326,,,,,0.23886140862745098,117.67468277496204,0.23885931616159445,0.23885931616159445
1893,1893,145.371,13.242862,3.4256947,0.0,0,5.9288077,0.0,0.25865623,122.09931971334102,6.5296516,305.96689,-9.3148947,122.09931971334102,,,,,0.24498606013071894,117.74577904524394,0.24498396640064385,0.24498396640064385
1896,1896,145.3716,13.331546,3.4963915,0.0,0,5.8604436,0.0,0.26490778,122.09683245951004,6.4571137,305.62851,-9.3172703,122.09683245951004,,,,,0.2511107116339869,117.81523326007874,0.25110861666889195,0.25110861666889195
1899,1899,145.3722,13.424427,3.5643573,0.0,0,5.792079,0.0,0.27092904,122.1533887525234,6.3883796,305.2901,-9.3180828,122.1533887525234,,,,,0.2572353631372549,117.88312203716234,0.25723326696497634,0.25723326696497634
1902,1902,145.3728,13.48239,3.6300826,0.0,0,5.7237153,0.0,0.27683142,121.90946112865178,6.3151288,304.95169,-9.3150568,121.90946112865178,,,,,0.2633600146405229,117.9495166989234,0.26335791728762875,0.26335791728762875
1905,1905,145.3734,13.597254,3.7019382,0.0,0,5.6553516,0.0,0.28321615,122.0974552685834,6.2463164,304.67795,-9.3157091,122.0974552685834,,,,,0.26948466614379085,118.01448375161165,0.2694825676356666,0.2694825676356666
1908,1908,145.374,13.685682,3.7722855,0.0,0,5.5874419,0.0,0.28966054,122.0531771346941,6.1750922,304.51581,-9.3173065,122.0531771346941,,,,,0.2756093176470588,118.0780853116976,0.2756072180079853,0.2756072180079853
1911,1911,145.3746,13.723404,3.8442867,0.0,0,5.5222936,0.0,0.2960535,121.52904867226678,6.1054263,304.35367,-9.3177433,121.52904867226678,,,,,0.2817339691503268,118.1403794858877,0.2817318684035517,0.2817318684035517
1914,1914,145.3752,13.860204,3.9115751,0.0,0,5.4572535,0.0,0.3021996,121.92812295346768,6.0376701,304.19153,-9.3155651,121.92812295346768,,,,,0.28785862065359474,118.20142071062715,0.28785651882139773,0.28785651882139773
1917,1917,145.3758,13.943125,3.9787388,0.0,0,5.3922133,0.0,0.30819789,121.84172606860024,5.964509,304.02942,-9.3148432,121.84172606860024,,,,,0.29398327215686276,118.26126005635734,0.2939811692606154,0.2939811692606154
1920,1920,145.3764,13.99034,4.0506949,0.0,0,5.3271737,0.0,0.31468758,121.37713631076583,5.8946199,303.86728,-9.3177013,121.37713631076583,,,,,0.3001079236601307,118.31994550099753,0.30010581972035144,0.30010581972035144
1923,1923,145.377,14.107494,4.1219416,0.0,0,5.2621331,0.0,0.32111841,121.517580514625,5.827086,303.70514,-9.3175774,121.517580514625,,,,,0.3062325751633987,118.3775221756988,0.3062304701998034,0.3062304701998034
1926,1926,145.3776,14.21911,4.1917224,0.0,0,5.1970935,0.0,0.32747975,121.61412967797231,5.7548513,303.543,-9.3163004,121.61412967797231,,,,,0.31235722666666665,118.43403258706898,0.31235512069821536,0.31235512069821536
1929,1929,145.3782,14.275371,4.2595863,0.0,0,5.1320534,0.0,0.33372253,121.25072911735651,5.6853065,303.38089,-9.3152189,121.25072911735651,,,,,0.3184818781699346,118.48951681778401,0.3184797712148747,0.3184797712148747
1932,1932,145.3788,14.376403,4.3302102,0.0,0,5.0670133,0.0,0.34000438,121.2235449394322,5.6130538,303.21875,-9.3160954,121.2235449394322,,,,,0.32460652967320264,118.54401270824454,0.32460442174910853,0.32460442174910853
1935,1935,145.3794,14.484818,4.4020195,0.0,0,5.0044241,0.0,0.34673747,121.23057880117382,5.5489516,303.05661,-9.3181114,121.23057880117382,,,,,0.3307311811764706,118.59755602178245,0.3307290723002808,0.3307290723002808
1938,1938,145.38,14.558764,4.4712749,0.0,0,4.942564,0.0,0.35310331,120.9699698315764,5.4736471,302.89447,-9.3154068,120.9699698315764,,,,,0.33685583267973856,118.65018059462567,0.33685372286779,0.33685372286779
1941,1941,145.3806,14.619015,4.5399075,0.0,0,4.8807039,0.0,0.35955301,120.595244948119,5.4056005,302.73236,-9.3157434,120.595244948119,,,,,0.34298048418300653,118.70191847277796,0.34297837345106613,0.34297837345106613
1944,1944,145.3812,14.74872,4.6095638,0.0,0,4.8188443,0.0,0.36613008,120.76875016684755,5.3383293,302.57022,-9.3159523,120.76875016684755,,,,,0.3491051356862745,118.75280003650454,0.3491030240495691,0.3491030240495691
1947,1947,145.3818,14.830111,4.6773858,0.0,0,4.7569842,0.0,0.37268609,120.55738571639289,5.2703934,302.40808,-9.3168306,120.55738571639289,,,,,0.35522978718954246,118.80285411460454,0.3552276746627862,0.3552276746627862
1950,1950,145.3824,14.922938,4.747942,0.0,0,4.6951241,0.0,0.37950516,120.39289357104298,5.2033572,302.24594,-9.3153009,120.39289357104298,,,,,0.3613544386928105,118.85210808876337,0.3613523252902307,0.3613523252902307
1953,1953,145.383,15.038627,4.8147297,0.0,0,4.6332641,0.0,0.38614157,120.44930961016364,5.1317563,302.0838,-9.3158684,120.44930961016364,,,,,0.36747909019607844,118.90058798930934,0.3674769759314395,0.3674769759314395
1956,1956,145.3836,15.132504,4.8810444,0.0,0,4.571404,0.0,0.39279756,120.3248964373649,5.065423,301.96478,-9.3166256,120.3248964373649,,,,,0.3736037416993464,118.94831858320667,0.37360162658597235,0.37360162658597235
1959,1959,145.3842,15.202382,4.948627,0.0,0,4.5108657,0.0,0.39964968,119.98317750274484,5.0022464,301.86139,-9.3165579,119.98317750274484,,,,,0.37972839320261437,118.99532345481776,0.3797262772534098,0.3797262772534098
1962,1962,145.3848,15.309772,5.0133257,0.0,0,4.4520135,0.0,0.40633109,119.96545850295976,4.9318571,301.75803,-9.3158894,119.96545850295976,,,,,0.38585304470588233,119.04162508054732,0.38585092793335224,0.38585092793335224
1965,1965,145.3854,15.424795,5.0765843,0.0,0,4.3931656,0.0,0.41288903,120.0142330234586,4.8673792,301.65463,-9.3161745,120.0142330234586,,,,,0.39197769620915035,119.08724489739818,0.3919755786254185,0.3919755786254185
1968,1968,145.386,15.493359,5.1405449,0.0,0,4.3343177,0.0,0.41956478,119.68172415290624,4.8013511,301.55127,-9.316206,119.68172415290624,,,,,0.3981023477124183,119.1322033665249,0.39810022932924466,0.39810022932924466
1971,1971,145.3866,15.607189,5.2036662,0.0,0,4.2754698,0.0,0.42607361,119.6999798576226,4.7380443,301.44788,-9.3155804,119.6999798576226,,,,,0.4042269992156863,119.17652003180596,0.4042248800444832,0.4042248800444832
1974,1974,145.3872,15.711905,5.265862,0.0,0,4.2166214,0.0,0.43254477,119.64883558581504,4.673799,301.34451,-9.3161192,119.64883558581504,,,,,0.41035165071895424,119.22021357416375,0.41034953077080205,0.41034953077080205
1977,1977,145.3878,15.806298,5.3279839,0.0,0,4.1577735,0.0,0.43893954,119.50912258770477,4.6111507,301.24112,-9.3164406,119.50912258770477,,,,,0.4164763022222222,119.26330186201227,0.41647418150788335,0.41647418150788335
1980,1980,145.3884,15.891936,5.3889799,0.0,0,4.0989256,0.0,0.44528168,119.30892983875388,4.5503769,301.13776,-9.3156719,119.30892983875388,,,,,0.42260095372549017,119.30580199775312,0.42259883225542305,0.42259883225542305
1983,1983,145.389,16.002893,5.4499683,0.0,0,4.0404716,0.0,0.45165837,119.28828873845156,4.4858031,301.03436,-9.3163671,119.28828873845156,,,,,0.4287256052287582,119.34773036129884,0.42872348301312996,0.42872348301312996
1986,1986,145.3896,16.119965,5.5127158,0.0,0,3.9844093,0.0,0.45808044,119.2761041629968,4.4252868,300.931,-9.3161325,119.2761041629968,,,,,0.43485025673202615,119.38910265042492,0.4348481337807248,0.4348481337807248
1989,1989,145.3902,16.19919,5.5739837,0.0,0,3.9284413,0.0,0.46442243,118.99391368717394,4.3649402,300.82761,-9.3149385,118.99391368717394,,,,,0.4409749082352941,119.42993391820768,0.4409727845579399,0.4409727845579399
1992,1992,145.3908,16.307287,5.6348147,0.0,0,3.8724735,0.0,0.47076687,118.91984298258626,4.30194,300.72424,-9.3150854,118.91984298258626,,,,,0.4470995597385621,119.47023860817106,0.44709743534451857,0.44709743534451857
1995,1995,145.3914,16.442797,5.6932511,0.0,0,3.8165054,0.0,0.47688806,119.06701975245066,4.2401156,300.62088,-9.3165751,119.06701975245066,,,,,0.45322421124183004,119.51003058692999,0.45322208614021414,0.45322208614021414
1998,1998,145.392,16.520172,5.7532253,0.0,0,3.7605371,0.0,0.48321268,118.75994602519336,4.1825728,300.51749,-9.3165703,118.75994602519336,,,,,0.459348862745098,119.5493231744668,0.4593467369447898,0.4593467369447898
2001,2001,145.3926,16.617435,5.814805,0.0,0,3.7045693,0.0,0.48965999,118.5631542919458,4.1198778,300.41412,-9.3160152,118.5631542919458,,,,,0.465473514248366,119.58812917289282,0.4654713877580179,0.4654713877580179
2004,2004,145.3932,16.770811,5.8764849,0.0,0,3.6486013,0.0,0.49630833,118.75156724367952,4.061801,300.31442,-9.3151073,118.75156724367952,,,,,0.471598165751634,119.6264608929381,0.47159603857967947,0.47159603857967947
2007,2007,145.3938,16.859478,5.9342046,0.0,0,3.5926332,0.0,0.5026409,118.52702862618057,4.0006337,300.24799,-9.3154068,118.52702862618057,,,,,0.47772281725490195,119.66433017904899,0.47772068940956397,0.47772068940956397
2010,2010,145.3944,16.959913,5.9911656,0.0,0,3.538765,0.0,0.50883031,118.3867848974685,3.9435627,300.18152,-9.3155651,118.3867848974685,,,,,0.4838474687581699,119.70174843258582,0.4838453402474686,0.4838453402474686
2013,2013,145.395,17.095659,6.051012,0.0,0,3.4855206,0.0,0.51554996,118.43786489298893,3.8861454,300.11505,-9.3159237,118.43786489298893,,,,,0.4899721202614379,119.73872663388022,0.48996999109319817,0.48996999109319817
2016,2016,145.3956,17.213484,6.1089554,0.0,0,3.432277,0.0,0.5221895,118.38003657928964,3.8310127,300.04861,-9.3156586,118.38003657928964,,,,,0.4960967717647059,119.77527536284349,0.49609464194656455,0.49609464194656455
2019,2019,145.3962,17.303873,6.1663566,0.0,0,3.3790326,0.0,0.52867901,118.1310203110276,3.772908,299.98215,-9.3152466,118.1310203110276,,,,,0.5022214232679738,119.81140481822264,0.5022192928073863,0.5022192928073863
2022,2022,145.3968,17.453001,6.2235255,0.0,0,3.3257887,0.0,0.53529167,118.27435384366176,3.7162352,299.91568,-9.3165359,118.27435384366176,,,,,0.5083460747712418,119.84712483586556,0.5083439436754886,0.5083439436754886
2025,2025,145.3974,17.588896,6.2791824,0.0,0,3.2725446,0.0,0.54185748,118.33689004486868,3.6604626,299.84924,-9.3147392,118.33689004486868,,,,,0.5144707262745098,119.88244490576216,0.5144685945507028,0.5144685945507028
2028,2028,145.398,17.685898,6.3322797,0.0,0,3.2193007,0.0,0.54816186,118.16594488324732,3.6021533,299.78278,-9.315177,118.16594488324732,,,,,0.5205953777777778,119.9173741881787,0.5205932454328657,0.5205932454328657
2031,2031,145.3986,17.82132,6.3873191,0.0,0,3.1660566,0.0,0.55460191,118.21037511399986,3.5475066,299.71634,-9.3159304,118.21037511399986,,,,,0.5267200292810458,119.95192152887958,0.5267178963218203,0.5267178963218203
2034,2034,145.3992,17.960251,6.441473,0.0,0,3.11395,0.0,0.56110197,118.27863919223428,3.4934506,299.64987,-9.3153944,118.27863919223428,,,,,0.5328446807843137,119.98609547341616,0.5328425472174145,0.5328425472174145
2037,2037,145.3998,18.060446,6.4963703,0.0,0,3.0632944,0.0,0.56783688,118.0685152379017,3.439425,299.5834,-9.3151808,118.0685152379017,,,,,0.5389693322875817,120.01990428053688,0.5389671981195017,0.5389671981195017
2040,2040,145.4004,18.190781,6.5489769,0.0,0,3.0126424,0.0,0.57411671,118.08074447242728,3.3847148,299.51697,-9.3164864,118.08074447242728,,,,,0.5450939837908496,120.05335593511197,0.5450918490279394,0.5450918490279394
2043,2043,145.401,18.350231,6.6022148,0.0,0,2.9619906,0.0,0.58038193,118.2582770503448,3.3314445,299.4505,-9.3149109,118.2582770503448,,,,,0.5512186352941176,120.08645816011408,0.5512164999425908,0.5512164999425908
2046,2046,145.4016,18.464008,6.6574707,0.0,0,2.9113381,0.0,0.58680016,118.09584207175548,3.276036,299.38406,-9.3147697,118.09584207175548,,,,,0.5573432867973857,120.11921842789666,0.5573411508633228,0.5573411508633228
2049,2049,145.4022,18.584484,6.7115822,0.0,0,2.8606863,0.0,0.59329718,117.98340793026644,3.2212119,299.3176,-9.3154106,117.98340793026644,,,,,0.5634679383006536,120.15164397110964,0.5634658017900067,0.5634658017900067
2052,2052,145.4028,18.755272,6.7654233,0.0,0,2.810034,0.0,0.59969211,118.18084048410664,3.1667924,299.25113,-9.31462,118.18084048410664,,,,,0.5695925898039216,120.18374179289998,0.5695904527225182,0.5695904527225182
2055,2055,145.4034,18.898577,6.8192892,0.0,0,2.7593822,0.0,0.60610098,118.1896800694215,3.1119001,298.93423,-9.3147707,118.1896800694215,,,,,0.5757172413071895,120.21551867642967,0.5757151036607364,0.5757151036607364
2058,2058,145.404,19.020187,6.8734083,0.0,0,2.7090683,0.0,0.61254597,118.04592107811943,3.0584614,298.33115,-9.3150387,118.04592107811943,,,,,0.5818418928104575,120.24698119428612,0.5818397546045447,0.5818397546045447
2061,2061,145.4046,19.18042,6.9297495,0.0,0,2.6608074,0.0,0.61910391,118.0908593074328,3.0069139,297.72806,-9.3147116,118.0908593074328,,,,,0.5879665443137255,120.27813571687585,0.5879644055538297,0.5879644055538297
2064,2064,145.4052,19.327635,6.9822946,0.0,0,2.6126273,0.0,0.62559325,118.10473884325933,2.9539876,297.12497,-9.3148861,118.10473884325933,,,,,0.5940911958169934,120.30898842088558,0.5940890565084814,0.5940890565084814
2067,2067,145.4058,19.454952,7.0354095,0.0,0,2.5644474,0.0,0.63210016,117.97445518285976,2.9014385,296.52188,-9.3149614,117.97445518285976,,,,,0.6002158473202615,120.3395452970195,0.6002137074683936,0.6002137074683936
2070,2070,145.4064,19.609945,7.0866952,0.0,0,2.5162673,0.0,0.63832742,118.03019913315052,2.8520038,295.91879,-9.3148823,118.03019913315052,,,,,0.6063404988235294,120.36981215741821,0.6063383584334628,0.6063383584334628
2073,2073,145.407,19.758144,7.1391611,0.0,0,2.4680872,0.0,0.64492679,118.01072979280627,2.8035903,295.31573,-9.315526,118.01072979280627,,,,,0.6124651503267974,120.39979464273519,0.6124630094035888,0.6124630094035888
2076,2076,145.4076,19.911154,7.1912289,0.0,0,2.4199073,0.0,0.65140146,118.01291714589011,2.749536,294.71265,-9.3140917,118.01291714589011,,,,,0.6185898018300654,120.42949822892828,0.618587660378674,0.618587660378674
2079,2079,145.4082,20.030159,7.2429404,0.0,0,2.3717272,0.0,0.65810049,117.80722720927048,2.7028697,294.10956,-9.3148146,117.80722720927048,,,,,0.6247144533333333,120.45892823346325,0.6247123113586239,0.6247123113586239
2082,2082,145.4088,20.212694,7.2923059,0.0,0,2.3235474,0.0,0.66467124,118.0030391105248,2.6509562,293.50647,-9.3150558,118.0030391105248,,,,,0.6308391048366013,120.48808982164016,0.6308369623433469,0.6308369623433469
2085,2085,145.4094,20.366344,7.3413744,0.0,0,2.2771804,0.0,0.67118287,118.02080207873534,2.5999241,292.90338,-9.3151445,118.02080207873534,,,,,0.6369637563398692,120.51698801216425,0.6369616133327534,0.6369616133327534
2088,2088,145.41,20.503633,7.3905215,0.0,0,2.2313523,0.0,0.67783093,117.92963770626928,2.5532587,292.30029,-9.3145332,117.92963770626928,,,,,0.6430884078431373,120.5456276828029,0.6430862643267569,0.6430862643267569
2091,2091,145.4106,20.685591,7.4370089,0.0,0,2.1855242,0.0,0.6843155,118.12987187491149,2.5024776,291.6972,-9.3138752,118.12987187491149,,,,,0.6492130593464053,120.57401357556111,0.6492109153252731,0.6492109153252731
2094,2094,145.4112,20.862011,7.4856577,0.0,0,2.1396964,0.0,0.69098526,118.24399790928663,2.4518921,291.09412,-9.3138552,118.24399790928663,,,,,0.6553377108496732,120.60215030180288,0.6553355663282198,0.6553355663282198
2097,2097,145.4118,21.004519,7.5314221,0.0,0,2.0938683,0.0,0.69744402,118.20545975438566,2.4041023,290.49103,-9.314538,118.20545975438566,,,,,0.6614623623529412,120.63004234692774,0.6614602173355175,0.6614602173355175
2100,2100,145.4124,21.17753,7.5771341,0.0,0,2.0480404,0.0,0.70367151,118.32672302872184,2.3550014,289.88797,-9.3142939,118.32672302872184,,,,,0.6675870138562091,120.65769407493248,0.6675848683470883,0.6675848683470883
2103,2103,145.413,21.375961,7.6251459,0.0,0,2.0022123,0.0,0.71037316,118.53164882804502,2.31001,289.28488,-9.3141747,118.53164882804502,,,,,0.6737116653594771,120.68510973290181,0.6737095193628571,0.6737095193628571
2106,2106,145.4136,21.525225,7.671083,0.0,0,1.9563841,0.0,0.71670628,118.4884380000984,2.2600312,288.96747,-9.3142862,118.4884380000984,,,,,0.679836316862745,120.71229345505327,0.6798341703827498,0.6798341703827498
2109,2109,145.4142,21.695028,7.7161579,0.0,0,1.9115355,0.0,0.72291583,118.5617307373008,2.2144289,288.70718,-9.314805,118.5617307373008,,,,,0.6859609683660131,120.73924926680128,0.6859588214066954,0.6859588214066954
2112,2112,145.4148,21.922777,7.7632523,0.0,0,1.8679364,0.0,0.72931921,118.89678057183686,2.167033,288.4469,-9.3142891,118.89678057183686,,,,,0.6920856198692811,120.76598108846854,0.692083472434624,0.692083472434624
2115,2115,145.4154,22.073404,7.8105946,0.0,0,1.8243403,0.0,0.73566395,118.7929109462708,2.1192355,288.18661,-9.3137655,118.7929109462708,,,,,0.698210271372549,120.79249273900089,0.6982081234664674,0.6982081234664674
2118,2118,145.416,22.234596,7.8574052,0.0,0,1.7807443,0.0,0.74197954,118.74317696106051,2.0750978,287.92633,-9.3128929,118.74317696106051,,,,,0.704334922875817,120.8187879394618,0.7043327745021598,0.7043327745021598
2121,2121,145.4166,22.461798,7.9008002,0.0,0,1.7371484,0.0,0.74791014,119.09743842893032,2.0264454,287.66605,-9.3130035,119.09743842893032,,,,,0.7104595743790849,120.84487031636301,0.7104574255416365,0.7104574255416365
2124,2124,145.4172,22.65287,7.9480581,0.0,0,1.6935524,0.0,0.75418961,119.16687879993825,1.9807509,287.40576,-9.3142862,119.16687879993825,,,,,0.7165842258823529,120.87074340475954,0.7165820765848349,0.7165820765848349
2127,2127,145.4178,22.826784,7.9962282,0.0,0,1.6499563,0.0,0.76089579,119.11236123934738,1.9334821,287.14545,-9.3137846,119.11236123934738,,,,,0.722708877385621,120.89641065146246,0.7227067276316934,0.7227067276316934
2130,2130,145.4184,23.037426,8.0422792,0.0,0,1.6063604,0.0,0.76726127,119.27607233360678,1.8876164,286.88516,-9.3128691,119.27607233360678,,,,,0.7288335288888889,120.92187541784202,0.7288313786821523,0.7288313786821523
2133,2133,145.419,23.263578,8.0881901,0.0,0,1.5630548,0.0,0.77372861,119.50509770714864,1.8419271,286.62488,-9.312109,119.50509770714864,,,,,0.7349581803921569,120.94714098274814,0.7349560297361536,0.7349560297361536
2136,2136,145.4196,23.425028,8.1349297,0.0,0,1.5215132,0.0,0.78034812,119.3688077629074,1.7963576,286.36459,-9.3136749,119.3688077629074,,,,,0.7410828318954248,120.97221054519018,0.7410806807936399,0.7410806807936399
2139,2139,145.4202,23.63513,8.178463,0.0,0,1.4800413,0.0,0.78669113,119.53184200710189,1.7539269,286.10431,-9.314043,119.53184200710189,,,,,0.7472074833986928,120.9970872267683,0.7472053318545561,0.7472053318545561
2142,2142,145.4208,23.878977,8.2229242,0.0,0,1.4385693,0.0,0.79327196,119.82844498596768,1.7117413,285.84402,-9.3128529,119.82844498596768,,,,,0.7533321349019608,121.0217740744461,0.7533299829188479,0.7533299829188479
2145,2145,145.4214,24.055965,8.2678337,0.0,0,1.3970973,0.0,0.79997265,119.76340019471098,1.668252,285.58374,-9.3121748,119.76340019471098,,,,,0.7594567864052287,121.04627406257603,0.7594546339864623,0.7594546339864623
2148,2148,145.422,24.271181,8.3119164,0.0,0,1.3556253,0.0,0.80671066,119.89072486998742,1.6267749,285.32346,-9.3130016,119.89072486998742,,,,,0.7655814379084968,121.07059009553204,0.7655792850573478,0.7655792850573478
2151,2151,145.4226,24.514652,8.35291,0.0,0,1.3141534,0.0,0.81306344,120.20649874723532,1.580205,285.06317,-9.3134289,120.20649874723532,,,,,0.7717060894117647,121.09472500973266,0.7717039361314539,0.7717039361314539
2154,2154,145.4232,24.720093,8.3956604,0.0,0,1.2726814,0.0,0.81972003,120.28112394075852,1.5367504,285.00403,-9.3123636,120.28112394075852,,,,,0.7778307409150327,121.1186815757142,0.7778285872087315,0.7778285872087315
2157,2157,145.4238,24.922283,8.4400778,0.0,0,1.2312094,0.0,0.82681733,120.28777035657072,1.4938568,285.74921,-9.3111401,120.28777035657072,,,,,0.7839553924183007,121.14246250023628,0.7839532382891322,0.7839532382891322
2160,2160,145.4244,25.166767,8.4790831,0.0,0,1.1913006,0.0,0.83303022,120.60117468775704,1.4493252,286.49438,-9.3126736,120.60117468775704,,,,,0.7900800439215686,121.16607042834795,0.790077889372609,0.790077889372609
2163,2163,145.425,25.406788,8.5181837,0.0,0,1.1518564,0.0,0.83929521,120.87428519286895,1.4082124,287.23956,-9.3126621,120.87428519286895,,,,,0.7962046954248366,121.18950794499024,0.7962025404591162,0.7962025404591162
2166,2166,145.4256,25.602743,8.5588722,0.0,0,1.1124125,0.0,0.84565157,120.88671468536492,1.3656386,287.98474,-9.3101435,120.88671468536492,,,,,0.8023293469281045,121.21277757706197,0.8023271915486085,0.8023271915486085
2169,2169,145.4262,25.836227,8.5998459,0.0,0,1.0729684,0.0,0.85236907,121.05431605830256,1.3223513,288.72995,-9.3114119,121.05431605830256,,,,,0.8084539984313726,121.23588179497041,0.8084518426410423,0.8084518426410423
2172,2172,145.4268,26.093445,8.6420431,0.0,0,1.0335244,0.0,0.85881722,121.28708022641874,1.2818286,289.47513,-9.3130169,121.28708022641874,,,,,0.8145786499346405,121.25882301450073,0.8145764937363744,0.8145764937363744
2175,2175,145.4274,26.297152,8.6794147,0.0,0,0.99408036,0.0,0.86493188,121.3659320093151,1.2419713,290.22031,-9.3109474,121.3659320093151,,,,,0.8207033014379085,121.28160359824535,0.820701144834563,0.820701144834563
2178,2178,145.428,26.518,8.7161732,0.0,0,0.95463634,0.0,0.8704254,121.52416801646858,1.2002928,290.96548,-9.3110142,121.52416801646858,,,,,0.8268279529411765,121.30422585720325,0.8268257959355668,0.8268257959355668
2181,2181,145.4286,26.776861,8.7576828,0.0,0,0.91519243,0.0,0.87671202,121.72857395060944,1.1588942,291.71066,-9.3105354,121.72857395060944,,,,,0.8329526044444444,121.32669205243494,0.8329504470393457,0.8329504470393457
2184,2184,145.4292,27.010702,8.8000317,0.0,0,0.87659609,0.0,0.88346267,121.78105681090662,1.1237166,292.45584,-9.3101473,121.78105681090662,,,,,0.8390772559477124,121.34900439629806,0.8390750981458605,0.8390750981458605
2187,2187,145.4298,27.235569,8.8377419,0.0,0,0.83908135,0.0,0.88942957,121.88745887436798,1.0835128,293.20102,-9.3113146,121.88745887436798,,,,,0.8452019074509803,121.37116505387785,0.8451997492550724,0.8451997492550724
2190,2190,145.4304,27.496931,8.8739624,0.0,0,0.8015694,0.0,0.89471805,122.17711551384065,1.0460123,293.9462,-9.3105946,122.17711551384065,,,,,0.8513265589542484,121.39317614446644,0.8513244003669439,0.8513244003669439
2193,2193,145.431,27.747305,8.913866,0.0,0,0.7640574,0.0,0.90087199,122.31120256970938,1.005186,294.69141,-9.3105326,122.31120256970938,,,,,0.8574512104575164,121.41503974274859,0.8574490514814381,0.8574490514814381
2196,2196,145.4316,27.97517,8.956378,0.0,0,0.72654539,0.0,0.90777063,122.26464839363348,0.96419525,295.43658,-9.3102312,122.26464839363348,,,,,0.8635758619607843,121.43675787999064,0.8635737025985187,0.8635737025985187
2199,2199,145.4322,28.227991,8.9933805,0.0,0,0.68903339,0.0,0.91391039,122.44648129476064,0.93080199,296.18176,-9.3105698,122.44648129476064,,,,,0.8697005134640523,121.45833254539053,0.8696983537181507,0.8696983537181507
2202,2202,145.4328,28.515461,9.0293283,0.0,0,0.65152138,0.0,0.91944307,122.78747212158672,0.89183271,296.92694,-9.3112354,122.78747212158672,,,,,0.8758251649673202,121.47976568713842,0.8758230048402992,0.8758230048402992
2205,2205,145.4334,28.742456,9.0663824,0.0,0,0.61400938,0.0,0.92573345,122.82355671524526,0.85402852,297.40674,-9.3097591,122.82355671524526,,,,,0.8819498164705882,121.50105921362791,0.8819476559649303,0.8819476559649303
2208,2208,145.434,29.010172,9.1050138,0.0,0,0.57674509,0.0,0.93217558,122.97695233585556,0.81542313,297.68365,-9.3102388,122.97695233585556,,,,,0.8880744679738563,121.52221499441991,0.8880723070920108,0.8880723070920108
2211,2211,145.4346,29.306408,9.1414995,0.0,0,0.54098594,0.0,0.938676,123.28752666243284,0.78142065,297.96054,-9.3091249,123.28752666243284,,,,,0.8941991194771242,121.54323486138446,0.8941969582215079,0.8941969582215079
2214,2214,145.4352,29.553436,9.1766119,0.0,0,0.50528592,0.0,0.94499606,123.40940574709845,0.74310863,298.23743,-9.3101139,123.40940574709845,,,,,0.9003237709803922,121.56412060969538,0.90032160935339,0.90032160935339
2217,2217,145.4358,29.801479,9.2116966,0.0,0,0.4695859,0.0,0.95115525,123.52085004226852,0.70595211,298.51434,-9.3101702,123.52085004226852,,,,,0.9064484224836601,121.58487399884565,0.9064462604876257,0.9064462604876257
2220,2220,145.4364,30.120682,9.243741,0.0,0,0.4338859,0.0,0.95722568,123.990571714971,0.66963255,298.79123,-9.3086824,123.990571714971,,,,,0.9125730739869281,121.6054967534183,0.9125709116241842,0.9125709116241842
2223,2223,145.437,30.391705,9.2773781,0.0,0,0.39818591,0.0,0.96359777,124.20242098735592,0.63138443,299.06815,-9.308816,124.20242098735592,,,,,0.918697725490196,121.62599056429933,0.9186955627630357,0.9186955627630357
2226,2226,145.4376,30.643164,9.3110838,0.0,0,0.36248589,0.0,0.96978641,124.31689655617394,0.59648573,299.34503,-9.3082142,124.31689655617394,,,,,0.924822376993464,121.6463570892646,0.9248202139041506,0.9248202139041506
2229,2229,145.4382,30.947805,9.3428659,0.0,0,0.32678592,0.0,0.97577041,124.68316868334784,0.56285536,299.62195,-9.3082113,124.68316868334784,,,,,0.930947028496732,121.66659795407573,0.9309448650474998,0.9309448650474998
2232,2232,145.4388,31.24165,9.3766966,0.0,0,0.29108587,0.0,0.98190469,124.93252367793563,0.52887118,299.89883,-9.3080816,124.93252367793563,,,,,0.93707168,121.68671475312698,0.9370695161930552,0.9370695161930552