File: examples/hot axisymmetric compression example/data/12 fitted data ramberg/testID_0138.csv
level_0,index,Time(sec),Force(kN),Jaw(mm),PowAngle(deg),Power(W),Pram,PTemp,Strain,Stress(MPa),Stroke(mm),TC1(C),wedge(mm),uncorrected stress,sampled strain,sampled stress,fitting strain,fitting stress,model strain,ramberg stress,ramberg plastic strain,ramberg accumulated plastic strain
1973,1973,165.3448,1.1929153,0.0049397689,0.0,0,9.0337067,0.0,0.0004131037,14.53724822282658,10.069327,366.05283,-9.2889547,14.53724822282658,0.0004131037,14.53724822282658,0.0,14.53724822282658,0.0,0.0,0.0,0.0
1975,1975,165.3452,4.1833806,0.046077829,0.0,0,8.9751787,0.0,0.0025571147,50.83122020481503,9.9994001,366.42032,-9.2891808,50.83122020481503,0.10816115,97.47638474954144,0.095690209,97.73628465992758,0.004224733289183223,89.31356117754386,0.004219395092519918,0.004219395092519918
1977,1977,165.3456,5.7447758,0.093895137,0.0,0,8.9166508,0.0,0.0062234914,69.56582105025068,9.9401598,366.78784,-9.2880239,69.56582105025068,0.19592471,96.91113471923596,0.191380418,96.94147138455294,0.008449466578366446,89.95633590375647,0.008444089963596713,0.008444089963596713
1979,1979,165.346,6.5363612,0.16673504,0.0,0,8.8581219,0.0,0.010415925,78.73973543668463,9.871666,367.15536,-9.2848864,78.73973543668463,0.28411111,96.62817090049109,0.28707062699999997,96.58181905779402,0.012674199867549668,90.33991284118984,0.012668800326708009,0.012668800326708009
1981,1981,165.3464,6.8610334,0.30044442,0.0,0,8.7995939,0.0,0.019280119,81.85743896263713,9.7890549,367.52286,-9.2844124,81.85743896263713,0.37879369,94.64279381856882,0.382760836,94.55834550352968,0.016898933156732892,90.6155389761983,0.016893517141948252,0.016893517141948252
1983,1983,165.3468,7.2679081,0.38466361,0.0,0,8.7416534,0.0,0.025764674,86.1822854411473,9.688344,367.88754,-9.2838135,86.1822854411473,0.47513938,92.90053488296029,0.478451045,92.84888588880804,0.021123666445916116,90.83134551614137,0.021118237532555536,0.021118237532555536
1985,1985,165.3472,7.5888481,0.48586982,0.0,0,8.6858492,0.0,0.032036178,89.32349280690593,9.5906782,368.19809,-9.2844925,89.32349280690593,0.57166028,91.41623996433646,0.5741412539999999,91.39155525740081,0.025348399735099336,91.00899207490863,0.025342960203952894,0.025342960203952894
1987,1987,165.3476,8.0880413,0.54053092,0.0,0,8.6301851,0.0,0.03646569,94.81664359340915,9.4997864,368.50867,-9.2828865,94.81664359340915,0.66549486,91.04085431140471,0.669831463,91.050281609876,0.02957313302428256,91.16012352071866,0.02956768446013632,0.02956768446013632
1989,1989,165.348,7.7894135,0.5831117,0.0,0,8.574522,0.0,0.039452024,91.0287978685088,9.43081,368.81921,-9.2831297,91.0287978685088,0.76129711,91.4566759513485,0.765521672,91.48425180295219,0.033797866313465784,91.2917354115692,0.033792409882987186,0.033792409882987186
1991,1991,165.3484,7.9901423,0.66412133,0.0,0,8.518857,0.0,0.044558004,92.81439332230148,9.3708715,369.12979,-9.2835369,92.81439332230148,0.85847414,92.53675391028196,0.861211881,92.6019833911681,0.038022599602649004,91.40836453885294,0.03801713620134526,0.03801713620134526
1993,1993,165.3488,8.2674894,0.70693135,0.0,0,8.4631929,0.0,0.04803383,95.7297598205596,9.3061762,369.44034,-9.2834911,95.7297598205596,0.95690209,94.66830145235171,0.95690209,94.66830145235171,0.04224733289183223,91.51312320326733,0.042241863229190955,0.042241863229190955
1995,1995,165.3492,8.5689278,0.78766358,0.0,0,8.4075298,0.0,0.053222623,98.62132788126236,9.2289286,369.75089,-9.2816095,98.62132788126236,,,,,0.04647206618101545,91.60824054249073,0.046466590833290564,0.046466590833290564
1997,1997,165.3496,8.2878599,0.90385705,0.0,0,8.3518648,0.0,0.061094727,94.5527727598712,9.1481209,370.06146,-9.2821465,94.5527727598712,,,,,0.05069679947019867,91.6953686271722,0.050691318914901216,0.050691318914901216
1999,1999,165.35,8.417222,0.97596925,0.0,0,8.2962017,0.0,0.066942707,95.50304434911664,9.0616188,370.37201,-9.2827816,95.50304434911664,,,,,0.0549215327593819,91.77576631440128,0.05491604739878209,0.05491604739878209
2001,2001,165.3504,8.4959488,1.0539738,0.0,0,8.2405376,0.0,0.072335072,95.82238864442292,8.9810848,370.68259,-9.2823067,95.82238864442292,,,,,0.05914626604856512,91.85041517131955,0.05914077622626573,0.05914077622626573
2003,2003,165.3508,8.6119232,1.1013557,0.0,0,8.1848736,0.0,0.075799398,96.7770189407666,8.9102192,370.99313,-9.2827272,96.7770189407666,,,,,0.06337099933774834,91.92009554655127,0.06336550535071135,0.06336550535071135
2005,2005,165.3512,8.6542311,1.1410048,0.0,0,8.1292095,0.0,0.078972541,96.95525851855272,8.8527775,371.30371,-9.2821417,96.95525851855272,,,,,0.06759573262693157,91.98543818954812,0.0675902347344196,0.0675902347344196
2007,2007,165.3516,8.5800495,1.2044305,0.0,0,8.0735455,0.0,0.083155915,95.65279857157935,8.7955008,371.61426,-9.2822351,95.65279857157935,,,,,0.0718204659161148,92.04696028962826,0.07181496434647848,0.07181496434647848
2009,2009,165.352,8.9477091,1.2601793,0.0,0,8.0196619,0.0,0.087237664,99.3194404780566,8.734458,371.92484,-9.2821941,99.3194404780566,,,,,0.07604519920529801,92.10509126247237,0.0760396941612222,0.0760396941612222
2011,2011,165.3524,8.9296608,1.3366531,0.0,0,7.9666953,0.0,0.092888452,98.5274540719332,8.6719694,372.23538,-9.2823687,98.5274540719332,,,,,0.08026993249448124,92.16019159936859,0.08026442415710448,0.08026442415710448
2013,2013,165.3528,8.8899527,1.4146684,0.0,0,7.9137359,0.0,0.098356552,97.48835125847646,8.6052771,372.54596,-9.28195,97.48835125847646,,,,,0.08449466578366446,92.21256690657087,0.08448915431585952,0.08448915431585952
2015,2015,165.3532,8.8107328,1.4838626,0.0,0,7.8607755,0.0,0.10384245,96.0912735146268,8.5333967,372.85651,-9.2824936,96.0912735146268,,,,,0.08871939907284768,92.26247853783413,0.08871388462186637,0.08871388462186637
2017,2017,165.3536,8.9796381,1.5425806,0.0,0,7.8078156,0.0,0.10816115,97.47638474954144,8.4641457,373.16708,-9.2820187,97.47638474954144,,,,,0.0929441323620309,92.31015176711662,0.09293861506166066,0.09293861506166066
2019,2019,165.354,9.0303326,1.5834581,0.0,0,7.7548552,0.0,0.11107834,97.70671615701978,8.4051723,373.47763,-9.2818947,97.70671615701978,,,,,0.09716886565121413,92.35578215486103,0.09716334562355387,0.09716334562355387
2021,2021,165.3544,9.055582,1.6427799,0.0,0,7.7018952,0.0,0.11577302,97.51422487500436,8.3464575,373.78821,-9.2833462,97.51422487500436,,,,,0.10139359894039734,92.39954056740827,0.10138807629733346,0.10138807629733346
2023,2023,165.3548,8.9811621,1.6982923,0.0,0,7.6489348,0.0,0.11963145,96.2805954312725,8.292346,374.09875,-9.2835131,96.2805954312725,,,,,0.10561833222958057,92.44157717758091,0.10561280707402375,0.10561280707402375
2025,2025,165.3552,9.2538357,1.7453718,0.0,0,7.5959754,0.0,0.12315945,98.8259851236926,8.2394962,374.40933,-9.2822132,98.8259851236926,,,,,0.1098430655187638,92.48202468561803,0.10983753794569333,0.10983753794569333
2027,2027,165.3556,9.2546692,1.8091917,0.0,0,7.543015,0.0,0.12840812,98.32272049873606,8.1844463,374.71988,-9.2814598,98.32272049873606,,,,,0.11406779880794703,92.52100093570493,0.11406226890529877,0.11406226890529877
2029,2029,165.356,9.2855453,1.874349,0.0,0,7.4900556,0.0,0.13266446,98.12604520396695,8.1238127,375.03046,-9.2813072,98.12604520396695,,,,,0.11829253209713024,92.55861105975742,0.1182869999465564,0.1182869999465564
2031,2031,165.3564,9.2067728,1.9333948,0.0,0,7.4370952,0.0,0.13758367,96.82209518181804,8.0637255,375.341,-9.2810154,96.82209518181804,,,,,0.12251726538631347,92.59494924732897,0.12251173106383663,0.12251173106383663
2033,2033,165.3568,9.282053,1.9800955,0.0,0,7.3846664,0.0,0.1414481,97.237754256963,8.0045385,375.604,-9.2824087,97.237754256963,,,,,0.12674199867549668,92.63010021730739,0.12673646225207585,0.12673646225207585
2035,2035,165.3572,9.3705244,2.0283029,0.0,0,7.3341722,0.0,0.14442633,97.77268664087497,7.9516344,375.43921,-9.2833996,97.77268664087497,,,,,0.13096673196467992,92.66414044990887,0.13096119350670293,0.13096119350670293
2037,2037,165.3576,9.4045095,2.0773652,0.0,0,7.2838039,0.0,0.1488719,97.7269717508824,7.8986254,375.27441,-9.2825565,97.7269717508824,,,,,0.13519146525386314,92.69713922429109,0.13518592482357705,0.13518592482357705
2039,2039,165.358,9.3902931,2.1236475,0.0,0,7.2334356,0.0,0.15233296,97.20214338028404,7.848958,375.10962,-9.2823458,97.20214338028404,,,,,0.13941619854304635,92.72915949758905,0.1394106561989354,0.1394106561989354
2041,2041,165.3584,9.4926281,2.181921,0.0,0,7.1830673,0.0,0.15644498,97.78142430689388,7.7974629,374.94482,-9.2826023,97.78142430689388,,,,,0.1436409318322296,92.76025865346219,0.14363538762934816,0.14363538762934816
2043,2043,165.3588,9.5652714,2.2317948,0.0,0,7.1326995,0.0,0.16100898,98.11568688185758,7.7430797,374.78003,-9.2826662,98.11568688185758,,,,,0.1478656651214128,92.79048914300914,0.14786011911168037,0.14786011911168037
2045,2045,165.3592,9.5592623,2.2849147,0.0,0,7.0823312,0.0,0.16464809,97.61331405646288,7.6950684,374.61523,-9.2819395,97.61331405646288,,,,,0.15209039841059602,92.8198990358275,0.15208485064305893,0.15208485064305893
2047,2047,165.3596,9.569911,2.347358,0.0,0,7.0319633,0.0,0.16963995,97.2033246794831,7.6431651,374.45044,-9.2805796,97.2033246794831,,,,,0.15631513169977926,92.84853249623018,0.15630958222084426,0.15630958222084426
2049,2049,165.36,9.6174345,2.3801398,0.0,0,6.981595,0.0,0.17279623,97.41232693762134,7.5896368,374.28564,-9.2820911,97.41232693762134,,,,,0.16053986498896247,92.87643019625027,0.16053431384260533,0.16053431384260533
2051,2051,165.3604,9.680624,2.4285603,0.0,0,6.9312277,0.0,0.17587763,97.64539279042262,7.5392528,374.12085,-9.2840509,97.64539279042262,,,,,0.16476459827814569,92.90362967545555,0.1647590455060985,0.1647590455060985
2053,2053,165.3608,9.6534948,2.481344,0.0,0,6.8808594,0.0,0.1805921,96.9293122426193,7.4944034,373.95605,-9.2847528,96.9293122426193,,,,,0.16898933156732893,92.93016565541564,0.16898377720924845,0.16898377720924845
2055,2055,165.3612,9.7009506,2.5222154,0.0,0,6.830492,0.0,0.18381432,97.06150478492484,7.4453359,373.79126,-9.2829056,97.06150478492484,,,,,0.17321406485651214,92.95607031570323,0.17320850895013185,0.17320850895013185
2057,2057,165.3616,9.828474,2.5783565,0.0,0,6.7801232,0.0,0.18785861,97.85822028012288,7.3943777,373.6265,-9.2821274,97.85822028012288,,,,,0.17743879814569535,92.98137353680825,0.17743324072696276,0.17743324072696276
2059,2059,165.362,9.8434916,2.6250005,0.0,0,6.7313671,0.0,0.19239147,97.60895598309304,7.347693,373.4617,-9.2811975,97.60895598309304,,,,,0.1816635314348786,93.00610311465314,0.18165797253807986,0.18165797253807986
2061,2061,165.3624,9.8165541,2.6755109,0.0,0,6.6834416,0.0,0.19592471,96.91113471923596,7.2943473,373.29691,-9.2812672,96.91113471923596,,,,,0.1858882647240618,93.03028495066229,0.18588270438193502,0.18588270438193502
2063,2063,165.3628,9.8342304,2.7272213,0.0,0,6.6355219,0.0,0.20007141,96.64385865707315,7.2469912,373.13211,-9.2827978,96.64385865707315,,,,,0.19011299801324502,93.05394322055417,0.19010743625708326,0.19010743625708326
2065,2065,165.3632,9.9336891,2.7615223,0.0,0,6.5876017,0.0,0.20355406,97.3252322594803,7.1961331,372.96732,-9.2826023,97.3252322594803,,,,,0.19433773130242826,93.07710052477508,0.19433216816217386,0.19433216816217386
2067,2067,165.3636,10.002175,2.8154166,0.0,0,6.5396819,0.0,0.20713684,97.52783485624695,7.1527452,372.80252,-9.2823439,97.52783485624695,,,,,0.19856246459161148,93.09977802284418,0.198556900095942,0.198556900095942
2069,2069,165.364,9.9986134,2.8618307,0.0,0,6.4917622,0.0,0.21135193,97.08982936542986,7.1036983,372.63773,-9.282074,97.08982936542986,,,,,0.2027871978807947,93.12199555359109,0.20278163205720204,0.20278163205720204
2071,2071,165.3644,10.00335,2.9046454,0.0,0,6.4438419,0.0,0.21516974,96.76360802989107,7.0579667,372.47293,-9.2812986,96.76360802989107,,,,,0.20701193116997793,93.14377174322647,0.20700636404484068,0.20700636404484068
2073,2073,165.3648,10.090338,2.962471,0.0,0,6.3959212,0.0,0.21913116,97.09791231537189,7.0114365,372.30814,-9.2815857,97.09791231537189,,,,,0.21123666445916114,93.165124102381,0.21123109605781132,0.21123109605781132
2075,2075,165.3652,10.168361,3.0013537,0.0,0,6.3480015,0.0,0.2230936,97.5050354657592,6.9615545,372.14334,-9.2821884,97.5050354657592,,,,,0.21546139774834439,93.1860691137623,0.21545582809512878,0.21545582809512878
2077,2077,165.3656,10.183341,3.0483174,0.0,0,6.3000817,0.0,0.2268541,97.2329204935687,6.9121528,371.97855,-9.2822638,97.2329204935687,,,,,0.2196861310375276,93.2066223112774,0.21968056015586462,0.21968056015586462
2079,2079,165.366,10.178814,3.1056979,0.0,0,6.252162,0.0,0.23115009,96.68188658792629,6.8642821,371.81375,-9.2828112,96.68188658792629,,,,,0.2239108643267108,93.22679835172329,0.2239052922391428,0.2239052922391428
2081,2081,165.3664,10.231557,3.1421869,0.0,0,6.2042422,0.0,0.23501733,96.85822854795012,6.8165674,371.64899,-9.2827826,96.85822854795012,,,,,0.22813559761589405,93.24661107972315,0.2281300243441359,0.2281300243441359
2083,2083,165.3668,10.278911,3.1910679,0.0,0,6.1568027,0.0,0.23865588,96.8695802361674,6.7671814,371.49091,-9.2829103,96.8695802361674,,,,,0.23236033090507727,93.26607358688659,0.23235475647006137,0.23235475647006137
2085,2085,165.3672,10.341702,3.2424533,0.0,0,6.1111121,0.0,0.24293886,96.99915540226482,6.7189617,371.37094,-9.2813377,96.99915540226482,,,,,0.23658506419426048,93.2851982655614,0.23657948861617858,0.23657948861617858
2087,2087,165.3676,10.376317,3.2825713,0.0,0,6.065536,0.0,0.24693874,96.9617469299724,6.6722112,371.25101,-9.2813454,96.9617469299724,,,,,0.24080979748344372,93.30399685791814,0.24080422078178573,0.24080422078178573
2089,2089,165.368,10.409492,3.3332376,0.0,0,6.0199599,0.0,0.25058722,96.81296376172696,6.624115,371.13104,-9.2822676,96.81296376172696,,,,,0.24503453077262694,93.32248050077813,0.2450289529662171,0.2450289529662171
2091,2091,165.3684,10.457788,3.382803,0.0,0,5.9743834,0.0,0.25524512,96.81118552003608,6.576292,371.01108,-9.2834139,96.81118552003608,,,,,0.24925926406181015,93.34065976666318,0.24925368516884083,0.24925368516884083
2093,2093,165.3688,10.487926,3.4284368,0.0,0,5.9288077,0.0,0.25922874,96.67375845906078,6.5296354,370.89111,-9.2836666,96.67375845906078,,,,,0.25348399735099336,93.35854470137558,0.2534784173890565,0.2534784173890565
2095,2095,165.3692,10.541587,3.4777844,0.0,0,5.8832321,0.0,0.26305869,96.7157176692144,6.4825187,370.77118,-9.2827263,96.7157176692144,,,,,0.2577087306401766,93.37614485848579,0.2577031496262931,0.2577031496262931
2097,2097,165.3696,10.595619,3.5260329,0.0,0,5.8376555,0.0,0.26789802,96.76653967918932,6.4334655,370.65121,-9.2812614,96.76653967918932,,,,,0.26193346392935984,93.39346933113904,0.26192788188000715,0.26192788188000715
2099,2099,165.37,10.621255,3.5730126,0.0,0,5.792079,0.0,0.27163619,96.5663643358259,6.3837967,370.53125,-9.2820778,96.5663643358259,,,,,0.26615819721854306,93.4105267812102,0.2661526141496809,0.2661526141496809
2101,2101,165.3704,10.664164,3.6213284,0.0,0,5.7465038,0.0,0.27569842,96.50797739446736,6.3374949,370.41129,-9.2833853,96.50797739446736,,,,,0.27038293050772627,93.42732546624092,0.27037734643482075,0.27037734643482075
2103,2103,165.3708,10.707494,3.6668818,0.0,0,5.7009277,0.0,0.28036034,96.47547344478576,6.2918038,370.29135,-9.2826462,96.47547344478576,,,,,0.2746076637969095,93.44387326427213,0.27460207873495596,0.27460207873495596
2105,2105,165.3712,10.777369,3.7177033,0.0,0,5.6553516,0.0,0.28411111,96.62817090049109,6.240623,370.17139,-9.2835464,96.62817090049109,,,,,0.2788323970860927,93.46017769689263,0.2788268110496369,0.2788268110496369
2107,2107,165.3716,10.820365,3.7639329,0.0,0,5.6097755,0.0,0.28851449,96.57809057580788,6.1939926,370.05142,-9.2821589,96.57809057580788,,,,,0.28305713037527597,93.47624595037098,0.28305154337843413,0.28305154337843413
2109,2109,165.372,10.836491,3.8079457,0.0,0,5.5656581,0.0,0.29289877,96.30667261828722,6.1473823,369.93146,-9.2819996,96.30667261828722,,,,,0.2872818636644592,93.49208489542757,0.2872762757209369,0.2872762757209369
2111,2111,165.3724,10.86016,3.8618393,0.0,0,5.5222936,0.0,0.29672062,96.00725613741024,6.0988269,369.81152,-9.2825918,96.00725613741024,,,,,0.2915065969536424,93.50770110552688,0.29150100807675233,0.29150100807675233
2113,2113,165.3728,10.927508,3.9055474,0.0,0,5.4789333,0.0,0.30137467,96.1865943189668,6.0516529,369.69156,-9.2824278,96.1865943189668,,,,,0.2957313302428256,93.52310087371866,0.2957257404455043,0.2957257404455043
2115,2115,165.3732,10.986647,3.9504681,0.0,0,5.4355736,0.0,0.30537739,96.27720788001308,6.0065298,369.57159,-9.2821512,96.27720788001308,,,,,0.2999560635320088,93.53829022854104,0.2999504728268325,0.2999504728268325
2117,2117,165.3736,11.030666,4.0037003,0.0,0,5.3922133,0.0,0.30953759,96.15135527920674,5.9581671,369.45163,-9.282403,96.15135527920674,,,,,0.30418079682119203,93.5532749485703,0.3041752052203916,0.3041752052203916
2119,2119,165.374,11.05323,4.0425668,0.0,0,5.3488536,0.0,0.31400561,95.97370059839902,5.9112048,369.3317,-9.2828197,95.97370059839902,,,,,0.3084055301103753,93.5680605761872,0.3083999376258503,0.3083999376258503
2121,2121,165.3744,11.090002,4.0883594,0.0,0,5.3054934,0.0,0.31764939,95.8504259280908,5.8625979,369.21173,-9.2832403,95.8504259280908,,,,,0.3126302633995585,93.58265243022343,0.31262467004289063,0.31262467004289063
2123,2123,165.3748,11.142904,4.1426592,0.0,0,5.2621331,0.0,0.32242784,95.78030786088664,5.8167152,369.09177,-9.2827959,95.78030786088664,,,,,0.31685499668874173,93.59705561794537,0.31684940247120735,0.31684940247120735
2125,2125,165.3752,11.203777,4.1810174,0.0,0,5.2187734,0.0,0.32679328,95.92894454679347,5.7690811,368.97183,-9.2820206,95.92894454679347,,,,,0.32107972997792494,93.61127504610172,0.3210741349105073,0.3210741349105073
2127,2127,165.3756,11.256859,4.2302623,0.0,0,5.1754136,0.0,0.33059216,95.90018646316751,5.7235017,368.85187,-9.2814941,95.90018646316751,,,,,0.32530446326710816,93.62531543133224,0.32529886736050845,0.32529886736050845
2129,2129,165.376,11.284446,4.2840872,0.0,0,5.1320534,0.0,0.33582932,95.60564188591012,5.6752048,368.7319,-9.2821865,95.60564188591012,,,,,0.32952919655629137,93.6391813098952,0.3295235998209397,0.3295235998209397
2131,2131,165.3764,11.318296,4.3239999,0.0,0,5.0886931,0.0,0.33992767,95.4985173210601,5.6290803,368.61194,-9.2825642,95.4985173210601,,,,,0.33375392984547464,93.65287704678306,0.3337483322915403,0.3337483322915403
2133,2133,165.3768,11.370773,4.3733873,0.0,0,5.0457683,0.0,0.34381714,95.45155509299398,5.5828195,368.42801,-9.2825193,95.45155509299398,,,,,0.33797866313465785,93.66640684426925,0.33797306477205885,0.33797306477205885
2135,2135,165.3772,11.425694,4.4161863,0.0,0,5.0044241,0.0,0.34869853,95.48608033667873,5.5372324,367.98822,-9.2826452,95.48608033667873,,,,,0.34220339642384107,93.67977474987227,0.3421977972622536,0.3421977972622536
2137,2137,165.3776,11.480114,4.4586115,0.0,0,4.9631839,0.0,0.35241067,95.51603277913128,5.4874387,367.54843,-9.2823181,95.51603277913128,,,,,0.3464281297130243,93.6929846639314,0.3464225297618913,0.3464225297618913
2139,2139,165.378,11.507144,4.5098696,0.0,0,4.9219441,0.0,0.356938,95.2263593336648,5.4417195,367.10864,-9.2824469,95.2263593336648,,,,,0.3506528630022075,93.70604034668385,0.3506472622707473,0.3506472622707473
2141,2141,165.3784,11.522997,4.5529237,0.0,0,4.8807039,0.0,0.36184144,94.9246915711651,5.3972144,366.66885,-9.2824268,94.9246915711651,,,,,0.3548775962913907,93.71894542487864,0.3548719947886048,0.3548719947886048
2143,2143,165.3788,11.594222,4.6013136,0.0,0,4.8394642,0.0,0.36564836,95.02186291715944,5.3507447,366.22906,-9.2816887,95.02186291715944,,,,,0.359102329580574,93.73170339806646,0.3590967273152547,0.3590967273152547
2145,2145,165.3792,11.657073,4.6463404,0.0,0,4.798224,0.0,0.37011924,95.07889537319788,5.3081694,365.78928,-9.2821894,95.07889537319788,,,,,0.3633270628697572,93.74431764448798,0.36332145985049497,0.36332145985049497
2147,2147,165.3796,11.705957,4.6864552,0.0,0,4.7569842,0.0,0.37468514,95.06775184323872,5.2629886,365.34949,-9.2820749,95.06775184323872,,,,,0.3675517961589404,93.756791426627,0.3675461923941307,0.3675461923941307
2149,2149,165.38,11.719223,4.7385273,0.0,0,4.715744,0.0,0.37879369,94.64279381856882,5.2193236,364.9097,-9.2828732,94.64279381856882,,,,,0.3717765294481236,93.76912789645417,0.37177092494597347,0.37177092494597347
2151,2151,165.3804,11.749196,4.7802906,0.0,0,4.6745043,0.0,0.38338432,94.45646777901376,5.1730194,364.46994,-9.2838755,94.45646777901376,,,,,0.37600126273730683,93.78133010042168,0.3759956575058412,0.3759956575058412
2153,2153,165.3808,11.819448,4.8224831,0.0,0,4.6332641,0.0,0.38771656,94.58582796878838,5.1278172,364.03015,-9.2828388,94.58582796878838,,,,,0.38022599602649004,93.79340098405528,0.3802203900735578,0.3802203900735578
2155,2155,165.3812,11.896065,4.8763885,0.0,0,4.5920238,0.0,0.3920376,94.63898057255844,5.0804043,363.59036,-9.2820692,94.63898057255844,,,,,0.3844507293156733,93.8053433964515,0.3844451226489531,0.3844451226489531
2157,2157,165.3816,11.921979,4.9133015,0.0,0,4.5507841,0.0,0.39685723,94.46079666825396,5.0373664,363.15057,-9.2826223,94.46079666825396,,,,,0.3886754626048565,93.8171600943883,0.38866985523186215,0.38866985523186215
2159,2159,165.382,11.942378,4.9570851,0.0,0,4.5108657,0.0,0.40072596,94.16571233971536,4.9913445,362.71078,-9.2820148,94.16571233971536,,,,,0.39290019589403974,93.82885374636739,0.3928945878221256,0.3928945878221256
2161,2161,165.3824,11.993333,5.0071869,0.0,0,4.4716296,0.0,0.40530765,94.04257828880898,4.9495397,362.271,-9.2814283,94.04257828880898,,,,,0.39712492918322295,93.84042693625827,0.397119320419589,0.397119320419589
2163,2163,165.3828,12.05731,5.0424705,0.0,0,4.4323978,0.0,0.40989378,94.17255626138638,4.9078693,361.83121,-9.2822323,94.17255626138638,,,,,0.40134966247240617,93.85188216691388,0.40134405302410264,0.40134405302410264
2165,2165,165.3832,12.123912,5.0914106,0.0,0,4.3931656,0.0,0.41378674,94.17429669905113,4.8622065,361.39142,-9.2826338,94.17429669905113,,,,,0.4055743957615894,93.86322186350911,0.4055687856355217,0.4055687856355217
2167,2167,165.3836,12.158972,5.1412091,0.0,0,4.3539338,0.0,0.41918826,93.91748943075191,4.8196235,360.95163,-9.2820225,93.91748943075191,,,,,0.40979912905077265,93.87444837675824,0.4097935182537057,0.4097935182537057
2169,2169,165.384,12.179654,5.1764436,0.0,0,4.314702,0.0,0.42331895,93.7021688569572,4.7761264,360.51184,-9.2817068,93.7021688569572,,,,,0.41402386233995586,93.88556398588966,0.4140182508785183,0.4140182508785183
2171,2171,165.3844,12.232708,5.2227974,0.0,0,4.2754698,0.0,0.42709121,93.61468842880764,4.7296886,360.07208,-9.2817669,93.61468842880764,,,,,0.4182485956291391,93.89657090158097,0.41824298350982736,0.41824298350982736
2173,2173,165.3848,12.311827,5.2647538,0.0,0,4.2362375,0.0,0.43225899,93.76859028939988,4.6881657,359.63229,-9.2815514,93.76859028939988,,,,,0.4224733289183223,93.90747126864756,0.4224677161475048,0.4224677161475048
2175,2175,165.3852,12.36078,5.3038464,0.0,0,4.1970053,0.0,0.43600461,93.71894314310404,4.6477103,359.1925,-9.281354,93.71894314310404,,,,,0.4266980622075055,93.91826716867139,0.4266924487914261,0.4266924487914261
2177,2177,165.3856,12.393806,5.349174,0.0,0,4.1577735,0.0,0.44013163,93.47811387005464,4.6025925,358.75272,-9.282217,93.47811387005464,,,,,0.43092279549668877,93.92896062241971,0.4309171814414706,0.4309171814414706
2179,2179,165.386,12.418296,5.3898082,0.0,0,4.1185417,0.0,0.44526383,93.2215334323514,4.5620508,358.31293,-9.282033,93.2215334323514,,,,,0.435147528785872,93.93955359228727,0.4351419140975209,0.4351419140975209
2181,2181,165.3864,12.487411,5.4334803,0.0,0,4.0793095,0.0,0.44911399,93.26338331721632,4.5210819,357.87314,-9.2822752,93.26338331721632,,,,,0.4393722620750552,93.95004798442949,0.4393666467594631,0.4393666467594631
2183,2183,165.3868,12.54425,5.4777293,0.0,0,4.0404716,0.0,0.45375222,93.20234603106076,4.4793315,357.45709,-9.2818918,93.20234603106076,,,,,0.4435969953642384,93.96044565096973,0.44359137942718646,0.44359137942718646
2185,2185,165.3872,12.602687,5.5141444,0.0,0,4.0030656,0.0,0.45853773,93.2350343200704,4.4353695,357.11224,-9.2816992,93.2350343200704,,,,,0.4478217286534216,93.97074839200694,0.44781611210058353,0.44781611210058353
2187,2187,165.3876,12.63735,5.560575,0.0,0,3.9657533,0.0,0.46222398,92.97808464981722,4.3936558,356.76736,-9.2819033,92.97808464981722,,,,,0.45204646194260484,93.98095795750822,0.45204084477954953,0.45204084477954953
2189,2189,165.388,12.688177,5.5994787,0.0,0,3.9284413,0.0,0.46691117,92.92009311419582,4.3534131,356.42252,-9.2813988,92.92009311419582,,,,,0.4562711952317881,93.99107604924868,0.45626557746398294,0.45626557746398294
2191,2191,165.3884,12.734859,5.6347389,0.0,0,3.8911293,0.0,0.47101706,92.86898609795928,4.3135839,356.07764,-9.2804413,92.86898609795928,,,,,0.4604959285209713,94.0011043224857,0.46049031015378467,0.46049031015378467
2193,2193,165.3888,12.815489,5.6843462,0.0,0,3.8538175,0.0,0.47513938,92.90053488296029,4.2710962,355.73279,-9.2806215,92.90053488296029,,,,,0.46472066181015453,94.0110443876893,0.46471504284885856,0.46471504284885856
2195,2195,165.3892,12.862727,5.7194881,0.0,0,3.8165054,0.0,0.48012045,92.84727697991588,4.2282867,355.38791,-9.2821589,92.84727697991588,,,,,0.46894539509933775,94.0208978121603,0.4689397755491108,0.4689397755491108
2197,2197,165.3896,12.903205,5.7605634,0.0,0,3.7791932,0.0,0.48412317,92.67545294238008,4.1860781,355.04306,-9.2828369,92.67545294238008,,,,,0.47317012838852096,94.03066612147947,0.4731645082544504,0.4731645082544504
2199,2199,165.39,12.942401,5.8100572,0.0,0,3.7418811,0.0,0.48896447,92.39609123431292,4.1488481,354.69818,-9.2824879,92.39609123431292,,,,,0.4773948616777042,94.04035080109868,0.4773892409647884,0.4773892409647884
2201,2201,165.3904,13.012091,5.8396964,0.0,0,3.7045693,0.0,0.49338469,92.55587881261444,4.1068358,354.35333,-9.2815447,92.55587881261444,,,,,0.48161959496688744,94.04995329767495,0.4816139736800385,0.4816139736800385
2203,2203,165.3908,13.079983,5.8788033,0.0,0,3.6672573,0.0,0.49676546,92.59081472768028,4.0685844,354.00848,-9.2817106,92.59081472768028,,,,,0.48584432825607066,94.05947502038966,0.48583870640011634,0.48583870640011634
2205,2205,165.3912,13.149238,5.9265547,0.0,0,3.6299453,0.0,0.50198019,92.53107901344488,4.0262728,353.6636,-9.2812061,92.53107901344488,,,,,0.49006906154525387,94.06891734229343,0.4900634391249399,0.4900634391249399
2207,2207,165.3916,13.183145,5.9590015,0.0,0,3.5926332,0.0,0.50630957,92.39496519556178,3.9856319,353.31876,-9.281826,92.39496519556178,,,,,0.4942937948344371,94.07828160151136,0.4942881718544292,0.4942881718544292
2209,2209,165.392,13.245503,6.0043654,0.0,0,3.5565166,0.0,0.51024044,92.3055725243347,3.9464488,352.97388,-9.2815218,92.3055725243347,,,,,0.4985185281236203,94.0875691023975,0.4985129045885063,0.4985129045885063
2211,2211,165.3924,13.296005,6.0455403,0.0,0,3.5210168,0.0,0.51566285,92.17780564245344,3.9112043,352.62903,-9.282053,92.17780564245344,,,,,0.5027432614128036,94.0967811167219,0.5027376373270952,0.5027376373270952
2213,2213,165.3928,13.359416,6.0790939,0.0,0,3.4855206,0.0,0.51943094,92.22459367575205,3.8695557,352.28415,-9.2821798,92.22459367575205,,,,,0.5069679947019867,94.10591888466332,0.5069623700701216,0.5069623700701216
2215,2215,165.3932,13.421166,6.1220884,0.0,0,3.4500248,0.0,0.52357453,92.145136381266,3.8294182,351.9393,-9.2818928,92.145136381266,,,,,0.51119272799117,94.11498361595895,0.5111871028175135,0.5111871028175135
2217,2217,165.3936,13.470981,6.1564302,0.0,0,3.4145288,0.0,0.52842969,92.0816433116883,3.7908542,351.59442,-9.2811556,92.0816433116883,,,,,0.5154174612803532,94.12397649078108,0.5154118355692,0.5154118355692
2219,2219,165.394,13.50957,6.1940632,0.0,0,3.3790326,0.0,0.53207797,91.89972981940151,3.7530615,351.24957,-9.2816153,91.89972981940151,,,,,0.5196421945695364,94.13289866080758,0.5196365683251127,0.5196365683251127
2221,2221,165.3944,13.572731,6.2364702,0.0,0,3.3435369,0.0,0.53664684,91.8247461751602,3.7155898,350.90472,-9.2820282,91.8247461751602,,,,,0.5238669278587197,94.1417512500264,0.5238613010851841,0.5238613010851841
2223,2223,165.3948,13.657862,6.2715187,0.0,0,3.3080409,0.0,0.54175162,91.9809487080215,3.6781151,350.55984,-9.2820444,91.9809487080215,,,,,0.5280916611479028,94.15053535570904,0.5280860338493486,0.5280860338493486
2225,2225,165.3952,13.729022,6.3150091,0.0,0,3.2725446,0.0,0.545479,91.93656686932026,3.6389222,350.215,-9.2809515,91.93656686932026,,,,,0.5323163944370861,94.15925204921217,0.5323107666175425,0.5323107666175425
2227,2227,165.3956,13.769493,6.3498211,0.0,0,3.2370486,0.0,0.55002111,91.78716165914712,3.6027167,349.87012,-9.2806902,91.78716165914712,,,,,0.5365411277262693,94.16790237678114,0.5365354993897028,0.5365354993897028
2229,2229,165.396,13.806307,6.3799095,0.0,0,3.2015526,0.0,0.55423278,91.66818092598967,3.5637994,349.52527,-9.2803183,91.66818092598967,,,,,0.5407658610154525,94.1764873603178,0.5407602321657687,0.5407602321657687
2231,2231,165.3964,13.869314,6.4270287,0.0,0,3.1660566,0.0,0.55820042,91.51321598652348,3.5273416,349.18039,-9.2806711,91.51321598652348,,,,,0.5449905943046358,94.18500799824032,0.5449849649456807,0.5449849649456807
2233,2233,165.3968,13.964731,6.4582891,0.0,0,3.1309152,0.0,0.56308734,91.75978797057256,3.4921262,348.93353,-9.2815914,91.75978797057256,,,,,0.549215327593819,94.1934652660366,0.54920969772938,0.54920969772938
2235,2235,165.3972,14.030474,6.4943228,0.0,0,3.0970623,0.0,0.56702316,91.74815055788255,3.453675,348.91528,-9.281311,91.74815055788255,,,,,0.5534400608830022,94.2018601170877,0.5534344305168101,0.5534344305168101
2237,2237,165.3976,14.068712,6.5414581,0.0,0,3.0632944,0.0,0.57166028,91.41623996433646,3.4203479,348.897,-9.281744,91.41623996433646,,,,,0.5576647941721854,94.21019348325956,0.557659163307915,0.557659163307915
2239,2239,165.398,14.116496,6.5675292,0.0,0,3.0295265,0.0,0.57611424,91.40371475056638,3.3808792,348.87872,-9.2806168,91.40371475056638,,,,,0.5618895274613687,94.21846627559653,0.5618838961026403,0.5618838961026403
2241,2241,165.3984,14.193636,6.6037722,0.0,0,2.9957583,0.0,0.57958454,91.45164779807118,3.3442905,348.86047,-9.2808113,91.45164779807118,,,,,0.5661142607505519,94.22667938491337,0.5661086289009329,0.5661086289009329
2243,2243,165.3988,14.2732,6.6462774,0.0,0,2.9619906,0.0,0.58444744,91.43169009933436,3.309288,348.84219,-9.2805662,91.43169009933436,,,,,0.5703389940397351,94.23483368240088,0.5703333617027406,0.5703333617027406
2245,2245,165.3992,14.333548,6.6729255,0.0,0,2.9282222,0.0,0.58877164,91.48291352706453,3.2748923,348.82394,-9.2804871,91.48291352706453,,,,,0.5745637273289184,94.2429300201838,0.5745580945080125,0.5745580945080125
2247,2247,165.3996,14.389856,6.7136025,0.0,0,2.8944542,0.0,0.59235913,91.32832582022786,3.2383006,348.80566,-9.2807512,91.32832582022786,,,,,0.5787884606181015,94.25096923189979,0.5787828273166987,0.5787828273166987
2249,2249,165.4,14.429812,6.7523212,0.0,0,2.8606863,0.0,0.59781247,91.09126873197992,3.2040048,348.78738,-9.280509,91.09126873197992,,,,,0.5830131939072848,94.25895213322579,0.5830075601287507,0.5830075601287507
2251,2251,165.4004,14.514577,6.7809772,0.0,0,2.8269184,0.0,0.60150963,91.26106230625751,3.1674647,348.76913,-9.280488,91.26106230625751,,,,,0.587237927196468,94.26687952236365,0.5872322929441205,0.5872322929441205
2253,2253,165.4008,14.603241,6.82026,0.0,0,2.7931502,0.0,0.60527861,91.31465458162594,3.1316686,348.75085,-9.2807512,91.31465458162594,,,,,0.5914626604856512,94.27475218057322,0.5914570257627616,0.5914570257627616
2255,2255,165.4012,14.657215,6.852921,0.0,0,2.7593822,0.0,0.61050767,91.23161153250472,3.0965729,348.73257,-9.2810888,91.23161153250472,,,,,0.5956873937748345,94.2825708726435,0.5956817585846281,0.5956817585846281
2257,2257,165.4016,14.701217,6.8854952,0.0,0,2.7256143,0.0,0.61405545,91.08476519544752,3.0587826,348.71432,-9.2807207,91.08476519544752,,,,,0.5999121270640176,94.2903363473291,0.5999064914096754,0.5999064914096754
2259,2259,165.402,14.763168,6.9253764,0.0,0,2.6929309,0.0,0.61839396,90.9512583906382,3.0259814,348.69604,-9.2806492,90.9512583906382,,,,,0.6041368603532009,94.29804933782857,0.6041312242378597,0.6041312242378597
2261,2261,165.4024,14.848374,6.954071,0.0,0,2.6608074,0.0,0.62330222,91.101770411454,2.992801,348.67776,-9.2806177,91.101770411454,,,,,0.6083615936423841,94.30571056217812,0.6083559570691379,0.6083559570691379
2263,2263,165.4028,14.944722,6.9894061,0.0,0,2.6286874,0.0,0.62646931,91.22880873278692,2.9590404,348.65952,-9.2808628,91.22880873278692,,,,,0.6125863269315673,94.31332072372543,0.6125806899034681,0.6125806899034681
2265,2265,165.4032,15.008615,7.0235696,0.0,0,2.5965672,0.0,0.63096291,91.16815569920976,2.9254458,348.64124,-9.2805576,91.16815569920976,,,,,0.6168110602207506,94.32088051144862,0.6168054227408093,0.6168054227408093
2267,2267,165.4036,15.055572,7.0541458,0.0,0,2.5644474,0.0,0.63565999,91.04872764021718,2.8908637,348.62299,-9.2803993,91.04872764021718,,,,,0.6210357935099338,94.32839060042765,0.6210301555811207,0.6210301555811207
2269,2269,165.404,15.122825,7.0972338,0.0,0,2.5323272,0.0,0.63965225,90.8825743543148,2.8558156,348.60471,-9.2804384,90.8825743543148,,,,,0.625260526799117,94.33585165215311,0.6252548884243632,0.6252548884243632
2271,2271,165.4044,15.210993,7.1256313,0.0,0,2.5002072,0.0,0.64423317,91.03263427796266,2.8221056,348.58643,-9.2802143,91.03263427796266,,,,,0.6294852600883002,94.34326431491547,0.6294796212704977,0.6294796212704977
2273,2273,165.4048,15.299659,7.1559625,0.0,0,2.4680872,0.0,0.64815909,91.15520818739948,2.7930138,348.56818,-9.2804842,91.15520818739948,,,,,0.6337099933774835,94.35062922418108,0.6337043541194866,0.6337043541194866
2275,2275,165.4052,15.370317,7.19946,0.0,0,2.4359674,0.0,0.65247798,90.98822029087982,2.7591729,348.5499,-9.2793827,90.98822029087982,,,,,0.6379347266666666,94.35794700287107,0.6379290869712921,0.6379290869712921
2277,2277,165.4056,15.428474,7.2242603,0.0,0,2.4038472,0.0,0.65715313,90.9959567651374,2.7261121,348.53162,-9.2795143,90.9959567651374,,,,,0.6421594599558499,94.36521826175118,0.6421538198258784,0.6421538198258784
2279,2279,165.406,15.502721,7.2556157,0.0,0,2.3717272,0.0,0.66053283,91.00628419058204,2.6929443,348.51337,-9.2795343,91.00628419058204,,,,,0.6463841932450332,94.37244359969112,0.6463785526832093,0.6463785526832093
2281,2281,165.4064,15.609646,7.2988076,0.0,0,2.3396072,0.0,0.66549486,91.04085431140471,2.6582158,348.49509,-9.280571,91.04085431140471,,,,,0.6506089265342163,94.3796236040275,0.6506032855432496,0.6506032855432496
2283,2283,165.4068,15.692349,7.3202529,0.0,0,2.3078089,0.0,0.66986859,91.2271266071351,2.6256886,348.3728,-9.2801962,91.2271266071351,,,,,0.6548336598233996,94.38675885080791,0.6548280184059652,0.6548280184059652
2285,2285,165.4072,15.756914,7.3567939,0.0,0,2.2771804,0.0,0.67326921,91.09585533419386,2.59062,348.05737,-9.2797232,91.09585533419386,,,,,0.6590583931125827,94.3938499051231,0.6590527512713219,0.6590527512713219
2287,2287,165.4076,15.813579,7.3963842,0.0,0,2.246628,0.0,0.67880839,90.87251831145082,2.5569725,347.74197,-9.2795229,90.87251831145082,,,,,0.663283126401766,94.40089732132942,0.6632774841392871,0.6632774841392871
2289,2289,165.408,15.900475,7.4207401,0.0,0,2.2160764,0.0,0.68263471,91.03103290479024,2.523416,347.42654,-9.2810688,91.03103290479024,,,,,0.6675078596909493,94.40790164338102,0.6675022170098279,0.6675022170098279
2291,2291,165.4084,16.002428,7.4587355,0.0,0,2.1855242,0.0,0.68651623,91.07955607044975,2.4905193,347.11115,-9.279705,91.07955607044975,,,,,0.6717325929801324,94.41486340507095,0.6717269498829124,0.6717269498829124
2293,2293,165.4088,16.084108,7.4914818,0.0,0,2.1549723,0.0,0.69215173,91.08081081256049,2.4580441,346.79572,-9.2792606,91.08081081256049,,,,,0.6759573262693157,94.4217831302515,0.6759516827585095,0.6759516827585095
2295,2295,165.4092,16.15695,7.519052,0.0,0,2.1244202,0.0,0.69527864,91.10114361000836,2.4260664,346.48032,-9.2784538,91.10114361000836,,,,,0.6801820595584989,94.42866133310442,0.6801764156365883,0.6801764156365883
2297,2297,165.4096,16.225451,7.5550075,0.0,0,2.0938683,0.0,0.69956177,90.97374029600716,2.3935683,346.16489,-9.2795,90.97374029600716,,,,,0.6844067928476821,94.4354985184018,0.6844011485171186,0.6844011485171186
2299,2299,165.41,16.311108,7.5837574,0.0,0,2.0633163,0.0,0.70475084,91.04108598868602,2.3614931,345.84949,-9.2812738,91.04108598868602,,,,,0.6886315261368654,94.44229518166725,0.6886258814000711,0.6886258814000711
2301,2301,165.4104,16.413067,7.6172638,0.0,0,2.0327644,0.0,0.70809138,91.12588284454417,2.3306932,345.53409,-9.281024,91.12588284454417,,,,,0.6928562594260486,94.44905180948253,0.6928506142854163,0.6928506142854163
2303,2303,165.4108,16.503361,7.6505432,0.0,0,2.0022123,0.0,0.71270829,91.14349112101424,2.2985716,345.21866,-9.2797031,91.14349112101424,,,,,0.6970809927152318,94.455768879664,0.6970753471731258,0.6970753471731258
2305,2305,165.4112,16.589661,7.6773715,0.0,0,1.9716601,0.0,0.71749175,91.22808434830588,2.267777,344.90326,-9.2788944,91.22808434830588,,,,,0.701305726004415,94.46244686143532,0.7013000800631717,0.7013000800631717
2307,2307,165.4116,16.671301,7.7166047,0.0,0,1.9411081,0.0,0.72115475,91.1008706707732,2.2342579,344.58783,-9.2794361,91.1008706707732,,,,,0.7055304592935983,94.4690862156992,0.7055248129555263,0.7055248129555263
2309,2309,165.412,16.769382,7.7439232,0.0,0,1.9115355,0.0,0.72608948,91.2332495943412,2.205934,344.27243,-9.2800388,91.2332495943412,,,,,0.7097551925827814,94.47568739519743,0.7097495458501625,0.7097495458501625
2311,2311,165.4124,16.868286,7.770782,0.0,0,1.8824685,0.0,0.73005736,91.37216331013336,2.1727366,343.957,-9.2802572,91.37216331013336,,,,,0.7139799258719647,94.48225084470275,0.7139742787470539,0.7139742787470539
2313,2313,165.4128,16.975977,7.8124633,0.0,0,1.8534043,0.0,0.73418969,91.33202472788952,2.1427481,343.6416,-9.2798281,91.33202472788952,,,,,0.718204659161148,94.48877700123636,0.7181990116461742,0.7181990116461742
2315,2315,165.4132,17.051796,7.836987,0.0,0,1.8243403,0.0,0.73914862,91.37142935104156,2.109005,343.32617,-9.2791462,91.37142935104156,,,,,0.7224293924503311,94.4952662941797,0.7224237445474978,0.7224237445474978
2317,2317,165.4136,17.122997,7.8673515,0.0,0,1.7952764,0.0,0.74284613,91.29473945332371,2.0775445,343.01077,-9.27948,91.29473945332371,,,,,0.7266541257395144,94.50171914556402,0.7266484774509995,0.7266484774509995
2319,2319,165.414,17.215063,7.9080157,0.0,0,1.7662123,0.0,0.74787027,91.168596168176,2.0502529,342.69534,-9.27985,91.168596168176,,,,,0.7308788590286975,94.50813597007865,0.7308732103566544,0.7308732103566544
2321,2321,165.4144,17.327343,7.9308295,0.0,0,1.7371484,0.0,0.75268626,91.41476297322014,2.0176518,342.37994,-9.2793446,91.41476297322014,,,,,0.7351035923178808,94.51451717540405,0.7350979432644384,0.7350979432644384
2323,2323,165.4148,17.44562,7.9630384,0.0,0,1.7080843,0.0,0.75601006,91.54341323476125,1.9842019,342.06451,-9.2795858,91.54341323476125,,,,,0.7393283256070641,94.52086316227334,0.7393226761743273,0.7393226761743273
2325,2325,165.4152,17.537104,7.9996963,0.0,0,1.6790204,0.0,0.76129711,91.4566759513485,1.9543368,341.74911,-9.2785025,91.4566759513485,,,,,0.7435530588962472,94.5271743246494,0.7435474090862977,0.7435474090862977
2327,2327,165.4156,17.616812,8.0206299,0.0,0,1.6499563,0.0,0.76543117,91.54719243945804,1.9251059,341.43369,-9.2789097,91.54719243945804,,,,,0.7477777921854305,94.53345104988138,0.7477721420003264,0.7477721420003264
2329,2329,165.416,17.716263,8.0582962,0.0,0,1.6208923,0.0,0.76931453,91.47556966202816,1.8917954,341.11829,-9.2790737,91.47556966202816,,,,,0.7520025254746137,94.53969371886174,0.7519968749163904,0.7519968749163904
2331,2331,165.4164,17.83976,8.0904646,0.0,0,1.5918283,0.0,0.77509302,91.60713649246613,1.8619317,340.80286,-9.2793865,91.60713649246613,,,,,0.7562272587637969,94.54590270613895,0.7562216078344677,0.7562216078344677
2333,2333,165.4168,17.955742,8.1161814,0.0,0,1.5630548,0.0,0.77881324,91.7954465930588,1.8319062,340.57077,-9.2786951,91.7954465930588,,,,,0.7604519920529801,94.55207838010266,0.760446340754536,0.760446340754536
2335,2335,165.4172,18.028851,8.1512785,0.0,0,1.5353373,0.0,0.78280324,91.6110855088491,1.8000036,340.46359,-9.2783012,91.6110855088491,,,,,0.7646767253421634,94.55822110307066,0.7646710736765738,0.7646710736765738
2337,2337,165.4176,18.099117,8.1778364,0.0,0,1.5076892,0.0,0.78828299,91.5441229966684,1.7711058,340.35641,-9.2785816,91.5441229966684,,,,,0.7689014586313466,94.56433123147083,0.7688958066005599,0.7688958066005599
2339,2339,165.418,18.217421,8.2064705,0.0,0,1.4800413,0.0,0.79148155,91.68231593101504,1.7401544,340.24927,-9.2781868,91.68231593101504,,,,,0.7731261919205298,94.5704091159294,0.773120539526473,0.773120539526473
2341,2341,165.4184,18.357042,8.2389622,0.0,0,1.4523933,0.0,0.79599506,91.85875927400456,1.7125008,340.14209,-9.2781773,91.85875927400456,,,,,0.777350925209713,94.57645510140892,0.7773452724542927,0.7773452724542927
2343,2343,165.4188,18.467155,8.262208,0.0,0,1.4247453,0.0,0.80083758,92.03099770905784,1.6854877,340.03491,-9.27771,92.03099770905784,,,,,0.7815756584988962,94.58246952733201,0.7815700053839988,0.7815700053839988
2345,2345,165.4192,18.545723,8.2992163,0.0,0,1.3970973,0.0,0.8045131,91.81691132930234,1.6523209,339.92773,-9.2786112,91.81691132930234,,,,,0.7858003917880795,94.58845272771022,0.7857947383155711,0.7857947383155711
2347,2347,165.4196,18.635208,8.3288012,0.0,0,1.3694494,0.0,0.80982,91.77340938170693,1.6234834,339.82056,-9.2781858,91.77340938170693,,,,,0.7900251250772627,94.59440503122366,0.7900194712489902,0.7900194712489902
2349,2349,165.42,18.740908,8.3532906,0.0,0,1.3418013,0.0,0.81430179,91.88890831059864,1.5954634,339.71338,-9.27808,91.88890831059864,,,,,0.7942498583664459,94.60032676136954,0.7942442041842366,0.7942442041842366
2351,2351,165.4204,18.883709,8.3899145,0.0,0,1.3141534,0.0,0.81785381,91.97866850748404,1.5691552,339.60623,-9.2781277,91.97866850748404,,,,,0.7984745916556292,94.60621823658724,0.7984689371212913,0.7984689371212913
2353,2353,165.4208,19.000782,8.4096451,0.0,0,1.2865053,0.0,0.82250226,92.2179942242,1.5381924,339.49905,-9.2786636,92.2179942242,,,,,0.8026993249448123,94.6120797702971,0.8026936700601355,0.8026936700601355
2355,2355,165.4212,19.085985,8.436347,0.0,0,1.2588574,0.0,0.82618141,92.1816491840954,1.5084271,339.39188,-9.2788057,92.1816491840954,,,,,0.8069240582339956,94.61791167106449,0.8069184030007509,0.8069184030007509
2357,2357,165.4216,19.198997,8.4777317,0.0,0,1.2312094,0.0,0.83122438,92.02604624418016,1.4776182,339.2847,-9.2773838,92.02604624418016,,,,,0.8111487915231788,94.62371424266203,0.8111431359431193,0.8111431359431193
2359,2359,165.422,19.328985,8.4980888,0.0,0,1.2044513,0.0,0.83649218,92.30171884283595,1.4511662,339.17752,-9.2766724,92.30171884283595,,,,,0.815373524812362,94.62948778420763,0.8153678688872228,0.8153678688872228
2361,2361,165.4224,19.471087,8.5284758,0.0,0,1.1781524,0.0,0.8398298,92.45789712792164,1.4206216,339.07034,-9.2775326,92.45789712792164,,,,,0.8195982581015453,94.63523259023528,0.8195926018330438,0.8195926018330438
2363,2363,165.4228,19.587252,8.5637283,0.0,0,1.1518564,0.0,0.84501582,92.39979159625273,1.3943204,338.9632,-9.2790041,92.39979159625273,,,,,0.8238229913907285,94.64094895078432,0.8238173347805648,0.8238173347805648
2365,2365,165.4232,19.671843,8.5805769,0.0,0,1.1255604,0.0,0.84926081,92.50615367038276,1.3640245,338.85602,-9.2783594,92.50615367038276,,,,,0.8280477246799117,94.64663715149031,0.8280420677297692,0.8280420677297692
2367,2367,165.4236,19.789438,8.6130524,0.0,0,1.0992644,0.0,0.85256183,92.49159186004503,1.3350537,338.74884,-9.2773724,92.49159186004503,,,,,0.8322724579690949,94.6522974737008,0.8322668006806396,0.8322668006806396
2369,2369,165.424,19.914505,8.6437197,0.0,0,1.0729684,0.0,0.85847414,92.53675391028196,1.3066056,338.64166,-9.2761478,92.53675391028196,,,,,0.8364971912582781,94.65793019453034,0.8364915336331599,0.8364915336331599
2371,2371,165.4244,20.078072,8.6648245,0.0,0,1.0466723,0.0,0.86208946,92.9225403725608,1.2772356,338.53448,-9.2768784,92.9225403725608,,,,,0.8407219245474614,94.66353558695116,0.8407162665873136,0.8407162665873136
2373,2373,165.4248,20.195126,8.7003727,0.0,0,1.0203763,0.0,0.86619306,92.83016670883944,1.2495279,338.42734,-9.2781839,92.83016670883944,,,,,0.8449466578366446,94.6691139198865,0.8449409995430844,0.8449409995430844
2375,2375,165.4252,20.303856,8.7273092,0.0,0,0.99408036,0.0,0.87225986,92.84685015975876,1.2231205,338.32016,-9.2790709,92.84685015975876,,,,,0.8491713911258278,94.67466545830412,0.8491657325004569,0.8491657325004569
2377,2377,165.4256,20.42914,8.7529306,0.0,0,0.96778435,0.0,0.87537855,92.95737092752572,1.194827,338.21298,-9.2782717,92.95737092752572,,,,,0.853396124415011,94.68019046323582,0.8533904654594151,0.8533904654594151
2379,2379,165.426,20.578804,8.7844505,0.0,0,0.94148839,0.0,0.87995142,93.06533981927431,1.1658703,338.1058,-9.2776527,93.06533981927431,,,,,0.8576208577041943,94.68568919192901,0.857615198419944,0.857615198419944
2381,2381,165.4264,20.735321,8.8059664,0.0,0,0.91519243,0.0,0.88507086,93.37901121621854,1.1367476,337.99863,-9.2763824,93.37901121621854,,,,,0.8618455909933775,94.69116189786156,0.8618399313820282,0.8618399313820282
2383,2383,165.4268,20.857821,8.836935,0.0,0,0.88916051,0.0,0.88842982,93.35996638836284,1.1076781,337.98575,-9.2763042,93.35996638836284,,,,,0.8660703242825607,94.69660883086132,0.8660646643456528,0.8660646643456528
2385,2385,165.4272,20.964359,8.8663836,0.0,0,0.86408949,0.0,0.89368165,93.29133123309084,1.0834889,338.08804,-9.2773199,93.29133123309084,,,,,0.870295057571744,94.70203023712364,0.8702893973108031,0.8702893973108031
2387,2387,165.4276,21.094738,8.88976,0.0,0,0.83908135,0.0,0.89858532,93.43578216072376,1.054765,338.19034,-9.2774544,93.43578216072376,,,,,0.8745197908609271,94.70742635933922,0.8745141302774646,0.8745141302774646
2389,2389,165.428,21.245407,8.9252462,0.0,0,0.81407332,0.0,0.90247709,93.43692500671368,1.0280242,338.29263,-9.2780161,93.43692500671368,,,,,0.8787445241501104,94.71279743673148,0.8787388632456231,0.8787388632456231
2391,2391,165.4284,21.392466,8.945632,0.0,0,0.78906536,0.0,0.90722507,93.69829470490671,0.99906868,338.39493,-9.2771215,93.69829470490671,,,,,0.8829692574392936,94.71814370508233,0.8829635962152642,0.8829635962152642
2393,2393,165.4288,21.517639,8.9673328,0.0,0,0.7640574,0.0,0.91072363,93.83387979149668,0.97009867,338.49725,-9.2760191,93.83387979149668,,,,,0.8871939907284768,94.72346539689788,0.8871883291863745,0.8871883291863745
2395,2395,165.4292,21.637888,9.003912,0.0,0,0.73904938,0.0,0.91525573,93.65873915709898,0.94501382,338.59955,-9.2764311,93.65873915709898,,,,,0.8914187240176601,94.72876274137487,0.8914130621589399,0.8914130621589399
2397,2397,165.4296,21.779057,9.0215712,0.0,0,0.71404135,0.0,0.9205097,93.92986059838998,0.91531616,338.70184,-9.2759018,93.92986059838998,,,,,0.8956434573068432,94.73403596450355,0.895637795132947,0.895637795132947
2399,2399,165.43,21.93919,9.0509405,0.0,0,0.68903339,0.0,0.92409593,94.05098226787688,0.8907817,338.80414,-9.2767868,94.05098226787688,,,,,0.8998681905960265,94.73928528912944,0.8998625281083824,0.8998625281083824
2401,2401,165.4304,22.104143,9.087018,0.0,0,0.66402543,0.0,0.9297232,94.05323601105472,0.86301404,338.90643,-9.27738,94.05323601105472,,,,,0.9040929238852097,94.74451093500876,0.9040872610852332,0.9040872610852332
2403,2403,165.4308,22.235271,9.1051006,0.0,0,0.63901734,0.0,0.9345206,94.25577929480242,0.83562785,339.00876,-9.2767706,94.25577929480242,,,,,0.908317657174393,94.74971311885089,0.9083119940634863,0.9083119940634863
2405,2405,165.4312,22.376045,9.1346884,0.0,0,0.61400938,0.0,0.93758953,94.26728571728589,0.81022453,339.11105,-9.2758112,94.26728571728589,,,,,0.9125423904635762,94.75489205437943,0.9125367270431289,0.9125367270431289
2407,2407,165.4316,22.516792,9.1627541,0.0,0,0.58900136,0.0,0.94334263,94.30159147948488,0.78538263,339.21335,-9.2763205,94.30159147948488,,,,,0.9167671237527594,94.76004795242042,0.9167614600241484,0.9167614600241484
2409,2409,165.432,22.669813,9.1797018,0.0,0,0.56478846,0.0,0.94691998,94.6028098023781,0.75702977,339.31564,-9.2755442,94.6028098023781,,,,,0.9209918570419426,94.76518102090591,0.9209861930065324,0.9209861930065324
2411,2411,165.4324,22.827164,9.2115002,0.0,0,0.54098594,0.0,0.95076257,94.61774761254632,0.73088235,339.41794,-9.2759991,94.61774761254632,,,,,0.9252165903311258,94.77029146493614,0.9252109259902687,0.9252109259902687
2413,2413,165.4328,22.96637,9.2374287,0.0,0,0.51718587,0.0,0.95690209,94.66830145235171,0.704826,339.52026,-9.2758055,94.66830145235171,,,,,0.9294413236203091,94.77537948687655,0.9294356589753451,0.9294356589753451
2415,2415,165.4332,23.10787,9.2603588,0.0,0,0.49338591,0.0,0.96035004,94.78312035847549,0.67963833,339.62256,-9.2763624,94.78312035847549,,,,,0.9336660569094922,94.78044528635633,0.9336603919617497,0.9336603919617497
2417,2417,165.4336,23.254652,9.290494,0.0,0,0.4695859,0.0,0.96459466,94.7656152901397,0.65109587,339.72485,-9.2771358,94.7656152901397,,,,,0.9378907901986755,94.78548906031989,0.9378851249494707,0.9378851249494707
2419,2419,165.434,23.418932,9.3085451,0.0,0,0.44578591,0.0,0.96994406,95.06132282156577,0.6281271,339.82715,-9.2745771,95.06132282156577,,,,,0.9421155234878588,94.79051100311435,0.9421098579384968,0.9421098579384968
2421,2421,165.4344,23.574181,9.3347263,0.0,0,0.42198589,0.0,0.97276819,95.14581179453864,0.60160476,339.92944,-9.2750835,95.14581179453864,,,,,0.9463402567770419,94.79551130649004,0.946334590928816,0.946334590928816
2423,2423,165.4348,23.717697,9.3626566,0.0,0,0.39818591,0.0,0.97769719,95.13934244033292,0.57576585,340.03174,-9.2763119,95.13934244033292,,,,,0.9505649900662252,94.80049015967903,0.9505593239204173,0.9505593239204173
2425,2425,165.4352,23.852461,9.3821173,0.0,0,0.37438589,0.0,0.98289603,95.26950675288845,0.55167931,340.13406,-9.2772884,95.26950675288845,,,,,0.9547897233554083,94.80544774940631,0.9547840569132895,0.9547840569132895
2426,2426,165.4354,23.924355,9.4005766,0.0,0,0.36248589,0.0,0.98502868,95.166184541548,0.53969985,340.18521,-9.2776518,95.166184541548,,,,,0.95690209,94.80791862817688,0.9568964234101989,0.9568964234101989