File: examples/hot axisymmetric compression example/data/12 fitted data ramberg/testID_0137.csv
level_0,index,Time(sec),Force(kN),Jaw(mm),PowAngle(deg),Power(W),Pram,PTemp,Strain,Stress(MPa),Stroke(mm),TC1(C),wedge(mm),uncorrected stress,sampled strain,sampled stress,fitting strain,fitting stress,model strain,ramberg stress,ramberg plastic strain,ramberg accumulated plastic strain
1872,1872,155.3437,0.20522638,0.017086202,0.0,0,9.0629654,0.0,0.0013593487,2.4987992144072364,10.074247,330.84628,-9.3046198,2.4987992144072364,0.0013593487,2.4987992144072364,0.0,2.4987992144072364,0.0,0.0,0.0,0.0
1875,1875,155.3443,4.6432962,0.09966214,0.0,0,8.975174,0.0,0.0064485879,56.204402636711855,9.9730473,331.06564,-9.30406,56.204402636711855,0.15009356,108.31482420229604,0.14194405649999997,108.06607351263958,0.006211993719912472,101.0572243518312,0.006208331057239315,0.006208331057239315
1878,1878,155.3449,6.5943432,0.18412398,0.0,0,8.8873816,0.0,0.011909558,79.33904430079298,9.870162,331.285,-9.2998056,79.33904430079298,0.28125128,109.75004441373255,0.28388811299999994,109.72016223372545,0.012423987439824945,101.8962925764426,0.012420294366422755,0.012420294366422755
1881,1881,155.3455,7.1899571,0.38703904,0.0,0,8.7995892,0.0,0.025849741,85.24317350337171,9.7328234,331.50436,-9.2992392,85.24317350337171,0.42443621,107.20564970162953,0.42583216949999997,107.18260909376541,0.018635981159737417,102.39888791886246,0.018632269870544994,0.018632269870544994
1884,1884,155.3461,8.1473179,0.48449156,0.0,0,8.7136831,0.0,0.032193612,95.90660049643198,9.5841265,331.72372,-9.2994576,95.90660049643198,0.56608886,105.25834383648562,0.5677762259999999,105.24125785954722,0.02484797487964989,102.76087552228059,0.02484425047077709,0.02484425047077709
1887,1887,155.3467,8.9572544,0.56998062,0.0,0,8.6301804,0.0,0.038997069,104.7782244751735,9.4595957,331.94308,-9.2983141,104.7782244751735,0.70841902,105.23258734033388,0.7097202825,105.23750249592551,0.031059968599562362,103.04478107348666,0.03105623390097231,0.03105623390097231
1890,1890,155.3473,8.4535379,0.67376447,0.0,0,8.5466843,0.0,0.045182262,98.1266960932357,9.361908,332.16245,-9.2984352,98.1266960932357,0.85337138,106.98538408250415,0.8516643389999999,106.94952603839518,0.037271962319474834,103.27879803033291,0.03726821913930241,0.03726821913930241
1893,1893,155.3479,9.1467056,0.74690092,0.0,0,8.4631882,0.0,0.050836183,105.59381693747316,9.2640343,332.36108,-9.2972784,105.59381693747316,,,,,0.0434839560393873,103.4781066624722,0.04348020563558201,0.04348020563558201
1896,1896,155.3485,9.3226376,0.89648885,0.0,0,8.3796921,0.0,0.060828574,106.41759773781908,9.1513319,332.51834,-9.2965765,106.41759773781908,,,,,0.04969594975929978,103.65183731996356,0.04969219305889572,0.04969219305889572
1899,1899,155.3491,9.2824078,0.9996618,0.0,0,8.2961969,0.0,0.068328343,105.12913027341254,9.0333776,332.6756,-9.297328,105.12913027341254,,,,,0.055907943479212255,103.80591720720888,0.05590418119442117,0.05590418119442117
1902,1902,155.3497,9.4003916,1.0881308,0.0,0,8.2127008,0.0,0.074880444,105.74515330555904,8.926259,332.83286,-9.2986622,105.74515330555904,,,,,0.062119937199124724,103.94441598790091,0.06211616989465971,0.06211616989465971
1905,1905,155.3503,9.6876993,1.1668932,0.0,0,8.1292048,0.0,0.080300532,108.31619322252224,8.8342619,332.99011,-9.2982054,108.31619322252224,,,,,0.06833193091903719,104.07025071602715,0.06832815905388724,0.06832815905388724
1908,1908,155.3509,9.7509375,1.2590724,0.0,0,8.0462637,0.0,0.087093696,108.2446146739663,8.7481556,333.14737,-9.2970467,108.2446146739663,,,,,0.07454392463894967,104.18558476447456,0.07454014859369565,0.07454014859369565
1911,1911,155.3515,9.8220215,1.3715775,0.0,0,7.966691,0.0,0.095036946,108.07629167770573,8.651063,333.30463,-9.2958431,108.07629167770573,,,,,0.08075591835886214,104.29206760911885,0.08075213845430225,0.08075213845430225
1914,1914,155.3521,9.8253422,1.4661344,0.0,0,7.8872514,0.0,0.10227906,107.30772874492658,8.5533848,333.46185,-9.2975588,107.30772874492658,,,,,0.0869679120787746,104.39098611465263,0.08696412858906659,0.08696412858906659
1917,1917,155.3527,10.013646,1.5505328,0.0,0,7.8078113,0.0,0.10867285,108.63179612879188,8.4584112,333.61911,-9.2971478,108.63179612879188,,,,,0.09317990579868708,104.48336386938108,0.09317611896089033,0.09317611896089033
1920,1920,155.3533,10.02853,1.6087232,0.0,0,7.7283711,0.0,0.11286505,108.28741040456268,8.3747797,333.77637,-9.2975559,108.28741040456268,,,,,0.09939189951859956,104.57002862606622,0.09938810953977284,0.09938810953977284
1923,1923,155.3539,10.077267,1.6984771,0.0,0,7.6489305,0.0,0.11987948,108.02953503812768,8.2972059,333.93362,-9.2977409,108.02953503812768,,,,,0.10560389323851203,104.65165941026653,0.10560010030110391,0.10560010030110391
1926,1926,155.3545,10.382428,1.7775227,0.0,0,7.5694909,0.0,0.12564366,110.58929392671492,8.2135344,334.09088,-9.2967472,110.58929392671492,,,,,0.11181588695842451,104.72882024237265,0.11181209122444145,0.11181209122444145
1929,1929,155.3551,10.258862,1.8671627,0.0,0,7.4900513,0.0,0.13263963,108.4756192455982,8.1230974,334.24814,-9.296689,108.4756192455982,,,,,0.11802788067833697,104.8019847980443,0.11802408229261785,0.11802408229261785
1932,1932,155.3557,10.305506,1.9500476,0.0,0,7.4106107,0.0,0.13901359,108.2279494495512,8.0389738,334.4054,-9.2972927,108.2279494495512,,,,,0.12423987439824945,104.87155478324188,0.12423607349107389,0.12423607349107389
1935,1935,155.3563,10.542717,2.008667,0.0,0,7.334168,0.0,0.14366929,110.18301913752316,7.9646387,334.56265,-9.2971983,110.18301913752316,,,,,0.13045186811816192,104.93787385550777,0.13044806480735424,0.13044806480735424
1938,1938,155.3569,10.43521,2.090914,0.0,0,7.258616,0.0,0.15009356,108.31482420229604,7.8924665,334.71991,-9.2967281,108.31482420229604,,,,,0.13666386183807439,105.00123832834106,0.13666005623071947,0.13666005623071947
1941,1941,155.3575,10.627229,2.1584139,0.0,0,7.1830635,0.0,0.15516526,109.68548255030572,7.8167443,334.87717,-9.2968941,109.68548255030572,,,,,0.14287585555798687,105.06190551246213,0.14287204775184378,0.14287204775184378
1944,1944,155.3581,10.70978,2.2401245,0.0,0,7.107511,0.0,0.16168536,109.7780478655828,7.7403903,334.77844,-9.2969961,109.7780478655828,,,,,0.14908784927789934,105.12010029436107,0.14908403936257644,0.14908403936257644
1947,1947,155.3587,10.692008,2.3178976,0.0,0,7.0319595,0.0,0.16771795,108.8741049922612,7.6588278,334.55176,-9.2969847,108.8741049922612,,,,,0.1552998429978118,105.1760203812683,0.1552960310557519,0.1552960310557519
1950,1950,155.3593,10.827108,2.3801432,0.0,0,6.9564075,0.0,0.17266743,109.66474239276596,7.586225,334.3251,-9.2976809,109.66474239276596,,,,,0.1615118367177243,105.22984052501232,0.1615080228250366,0.1615080228250366
1953,1953,155.3599,10.85794,2.4585426,0.0,0,6.8808551,0.0,0.17875524,109.2379437751752,7.516911,334.09842,-9.2954693,109.2379437751752,,,,,0.16772383043763675,105.28171595447887,0.1677200146648044,0.1677200146648044
1956,1956,155.3605,10.961103,2.5238006,0.0,0,6.8053036,0.0,0.18386936,109.65469424205692,7.4461908,333.87177,-9.2976017,109.65469424205692,,,,,0.1739358241575492,105.33178518840643,0.173932006570035,0.173932006570035
1959,1959,155.3611,11.016936,2.6013415,0.0,0,6.7313633,0.0,0.19002599,109.4713313511189,7.3758636,333.64508,-9.2978754,109.4713313511189,,,,,0.1801478178774617,105.38017235834793,0.18014399853622942,0.18014399853622942
1962,1962,155.3617,11.066596,2.6732986,0.0,0,6.6594777,0.0,0.1957528,109.27308513281366,7.2984548,333.41843,-9.2972622,109.27308513281366,,,,,0.18635981159737416,105.42698914072695,0.18635599055934007,0.18635599055934007
1965,1965,155.3623,11.175467,2.7396336,0.0,0,6.5875978,0.0,0.20101942,109.70406965056436,7.2245584,333.19174,-9.2961721,109.70406965056436,,,,,0.19257180531728665,105.47233637454752,0.19256798263571226,0.19256798263571226
1968,1968,155.3629,11.250187,2.8144615,0.0,0,6.515718,0.0,0.20710298,109.70611579651413,7.1549125,332.96509,-9.2982121,109.70611579651413,,,,,0.19878379903719912,105.51630542419126,0.19877997476203457,0.19877997476203457
1971,1971,155.3635,11.289022,2.8853211,0.0,0,6.4438381,0.0,0.21282372,109.3896629631146,7.0814576,332.7384,-9.29844,109.3896629631146,,,,,0.20499579275711158,105.55897933412466,0.20499196693529723,0.20499196693529723
1974,1974,155.3641,11.435444,2.9624519,0.0,0,6.3719578,0.0,0.21920715,110.04186920955108,7.0069423,332.51175,-9.2973261,110.04186920955108,,,,,0.21120778647702407,105.60043381259054,0.2112039591527563,0.2112039591527563
1977,1977,155.3647,11.47588,3.0354931,0.0,0,6.3000779,0.0,0.22521912,109.7023305485554,6.930819,332.28506,-9.296175,109.7023305485554,,,,,0.21741978019693653,105.64073807382249,0.2174159514119032,0.2174159514119032
1980,1980,155.3653,11.510918,3.1077266,0.0,0,6.2281981,0.0,0.23139374,109.31436525924757,6.8615856,332.05841,-9.2977571,109.31436525924757,,,,,0.22363177391684902,105.67995556249588,0.2236279437104385,0.2236279437104385
1983,1983,155.3659,11.634818,3.1783161,0.0,0,6.1567988,0.0,0.23737504,109.77682089610964,6.7852836,331.83173,-9.2983599,109.77682089610964,,,,,0.22984376763676148,105.71814457973022,0.22983993604624917,0.22983993604624917
1986,1986,155.3665,11.695992,3.2465341,0.0,0,6.0883203,0.0,0.24331538,109.66009573551293,6.7130847,331.60507,-9.2970324,109.66009573551293,,,,,0.23605576135667394,105.75535882629389,0.23605192841738887,0.23605192841738887
1989,1989,155.3671,11.765882,3.3211644,0.0,0,6.0199566,0.0,0.24971037,109.55157618504236,6.6403289,331.37839,-9.2963591,109.55157618504236,,,,,0.24226775507658643,105.79164787574418,0.2422639208220609,0.2422639208220609
1992,1992,155.3677,11.849575,3.393203,0.0,0,5.951592,0.0,0.25606057,109.5881951919994,6.5679274,331.1517,-9.2970552,109.5881951919994,,,,,0.2484797487964989,105.82705758823272,0.24847591325860316,0.24847591325860316
1995,1995,155.3683,11.937229,3.4659333,0.0,0,5.8832283,0.0,0.26248363,109.6433990484992,6.4933343,330.80429,-9.2974072,109.6433990484992,,,,,0.25469174251641136,105.86163047353203,0.2546879057254749,0.2546879057254749
1998,1998,155.3689,12.027963,3.5361748,0.0,0,5.8148637,0.0,0.2686972,109.74152931753837,6.4208584,330.45685,-9.2972469,109.74152931753837,,,,,0.26090373623632385,105.89540601071845,0.2608998982212453,0.2608998982212453
2001,2001,155.3695,12.090784,3.6067519,0.0,0,5.7465,0.0,0.27496108,109.57194500013745,6.3500581,330.10944,-9.2968616,109.57194500013745,,,,,0.26711572995623634,105.92842093053821,0.2671118907445832,0.2671118907445832
2004,2004,155.3701,12.194649,3.6786392,0.0,0,5.6781363,0.0,0.28125128,109.75004441373255,6.2749882,329.76199,-9.2982655,109.75004441373255,,,,,0.27332772367614877,105.96070946554607,0.2733238832942476,0.2733238832942476
2007,2007,155.3707,12.274203,3.750361,0.0,0,5.6097717,0.0,0.28768393,109.69950722350464,6.2020707,329.41458,-9.2982502,109.69950722350464,,,,,0.27953971739606126,105.9923035724443,0.27953587586908063,0.27953587586908063
2010,2010,155.3713,12.329753,3.8235502,0.0,0,5.5439701,0.0,0.29430139,109.41010941027274,6.1293249,329.06714,-9.2978601,109.41010941027274,,,,,0.28575171111597375,106.02323313001581,0.28574786846799916,0.28574786846799916
2013,2013,155.3719,12.428724,3.8928933,0.0,0,5.47893,0.0,0.30051675,109.53766583646276,6.0562811,328.71973,-9.2958193,109.53766583646276,,,,,0.2919637048358862,106.05352611615487,0.2919598610899892,0.2919598610899892
2016,2016,155.3725,12.497291,3.9646554,0.0,0,5.4138899,0.0,0.30675304,109.36067847487293,5.9862947,328.37228,-9.2978277,109.36067847487293,,,,,0.2981756985557987,106.08320876625224,0.2981718537341,0.2981718537341
2019,2019,155.3731,12.563145,4.0361462,0.0,0,5.3488498,0.0,0.31320527,109.15437799182104,5.9116516,328.02487,-9.298686,109.15437799182104,,,,,0.30438769227571116,106.11230571542023,0.3043838463994386,0.3043838463994386
2022,2022,155.3737,12.66039,4.1069193,0.0,0,5.2838097,0.0,0.31949306,109.21843640910744,5.8422246,327.67743,-9.2978544,109.21843640910744,,,,,0.3105996859956236,106.14084012652965,0.31059583908516547,0.31059583908516547
2025,2025,155.3743,12.762836,4.1778369,0.0,0,5.21877,0.0,0.3259109,109.313299162584,5.7700057,327.33002,-9.296196,109.313299162584,,,,,0.3168116797155361,106.1688338056168,0.3168078317904904,0.3168078317904904
2028,2028,155.3749,12.826608,4.248734,0.0,0,5.1537299,0.0,0.33243483,109.06673283000298,5.697464,326.98257,-9.2969265,109.06673283000298,,,,,0.3230236734354486,106.19630730611354,0.3230198245146684,0.3230198245146684
2031,2031,155.3755,12.891519,4.321197,0.0,0,5.0886898,0.0,0.33913761,108.80415071052354,5.6244493,326.63513,-9.2992506,108.80415071052354,,,,,0.329235667155361,106.2232800234532,0.3292318172569964,0.3292318172569964
2034,2034,155.3761,12.989186,4.3902125,0.0,0,5.0250454,0.0,0.34546474,108.84665977448785,5.5567646,326.28772,-9.2981234,108.84665977448785,,,,,0.3354476608752735,106.24977028057276,0.33544381001681056,0.33544381001681056
2037,2037,155.3767,13.060966,4.4600687,0.0,0,4.9631805,0.0,0.35208237,108.65232315467938,5.4870281,325.94028,-9.2967777,108.65232315467938,,,,,0.341659654595186,106.27579540597318,0.3416558027934826,0.3416558027934826
2040,2040,155.3773,13.125514,4.5285664,0.0,0,4.9013209,0.0,0.35860488,108.40492906216124,5.4167314,325.59286,-9.2969503,108.40492906216124,,,,,0.3478716483150984,106.30137180453926,0.3478677955864181,0.3478677955864181
2043,2043,155.3779,13.234514,4.5951586,0.0,0,4.8394608,0.0,0.36505094,108.53616145370232,5.3531337,325.22272,-9.2990608,108.53616145370232,,,,,0.3540836420350109,106.32651502233868,0.3540797883950536,0.3540797883950536
2046,2046,155.3785,13.314768,4.6637015,0.0,0,4.7776008,0.0,0.37160376,108.3978448511554,5.2824316,324.8071,-9.2988205,108.3978448511554,,,,,0.3602956357549234,106.35123980566122,0.3602917812188546,0.3602917812188546
2049,2049,155.3791,13.363415,4.7322874,0.0,0,4.7157407,0.0,0.37831932,107.9938509848228,5.2141323,324.39151,-9.2968149,107.9938509848228,,,,,0.3665076294748359,106.37556015522811,0.36650377405731366,0.36650377405731366
2052,2052,155.3797,13.478343,4.7994232,0.0,0,4.6538811,0.0,0.38503051,108.132617130505,5.1481643,323.97592,-9.2968254,108.132617130505,,,,,0.37271962319474833,106.39948937571734,0.3727157669099485,0.3727157669099485
2055,2055,155.3803,13.573401,4.8655682,0.0,0,4.5920205,0.0,0.39153174,108.11126357999412,5.0823712,323.5603,-9.2984524,108.11126357999412,,,,,0.3789316169146608,106.42304012133782,0.37892775977630067,0.37892775977630067
2058,2058,155.3809,13.608966,4.930398,0.0,0,4.5305729,0.0,0.39821947,107.62399835840014,5.0150046,323.14471,-9.2982731,107.62399835840014,,,,,0.3851436106345733,106.44622443768422,0.38513975265593353,0.38513975265593353
2061,2061,155.3815,13.704832,4.9934783,0.0,0,4.4716268,0.0,0.40450263,107.6269778019596,4.9510441,322.72913,-9.2969217,107.6269778019596,,,,,0.39135560435448574,106.46905380032608,0.39135174554843105,0.39135174554843105
2064,2064,155.3821,13.821118,5.0584822,0.0,0,4.4127784,0.0,0.4110631,107.75526661870148,4.8836875,322.31351,-9.2979059,107.75526661870148,,,,,0.39756759807439823,106.49153915026561,0.3975637384533968,0.3975637384533968
2067,2067,155.3827,13.884636,5.1250434,0.0,0,4.353931,0.0,0.41801023,107.442902648423,4.8200064,321.89792,-9.29778,107.442902648423,,,,,0.4037795917943107,106.5136909268317,0.4037757313704525,0.4037757313704525
2070,2070,155.3833,13.951997,5.1872473,0.0,0,4.295083,0.0,0.42443621,107.20564970162953,4.7571673,321.48233,-9.2973652,107.20564970162953,,,,,0.40999158551422316,106.53551909790217,0.40998772429923663,0.40998772429923663
2073,2073,155.3839,14.083235,5.2503691,0.0,0,4.2362342,0.0,0.43094751,107.4369874853966,4.6895185,321.06671,-9.2976828,107.4369874853966,,,,,0.41620357923413565,106.55703318805416,0.4161997172394042,0.4161997172394042
2076,2076,155.3845,14.133388,5.3114772,0.0,0,4.1773863,0.0,0.43715581,107.06448671652504,4.6275892,320.65112,-9.2972946,107.06448671652504,,,,,0.42241557295404814,106.57824230446877,0.4224117101906251,0.4224117101906251
2079,2079,155.3851,14.20689,5.3758516,0.0,0,4.1185384,0.0,0.44370788,106.82153944565316,4.5627007,320.23553,-9.2975578,106.82153944565316,,,,,0.42862756667396057,106.59915516115201,0.4286237031525834,0.4286237031525834
2082,2082,155.3857,14.32793,5.4404955,0.0,0,4.0596905,0.0,0.45036185,106.92155096710944,4.5041685,319.81992,-9.2981958,106.92155096710944,,,,,0.43483956039387306,106.61978010123877,0.43483569612497686,0.43483569612497686
2085,2085,155.3863,14.405054,5.5014462,0.0,0,4.0030627,0.0,0.45679817,106.72902736227712,4.4385796,319.40433,-9.2974596,106.72902736227712,,,,,0.44105155411378555,106.64012511786073,0.44104768910751574,0.44104768910751574
2088,2088,155.3869,14.481903,5.5635777,0.0,0,3.9470942,0.0,0.46314237,106.51115561348048,4.37816,318.98874,-9.2972841,106.51115561348048,,,,,0.44726354783369804,106.6601978735204,0.4472596820999223,0.4472596820999223
2091,2091,155.3875,14.572012,5.6242814,0.0,0,3.8911264,0.0,0.46940795,106.39979590808876,4.3167572,318.57315,-9.2976599,106.39979590808876,,,,,0.4534755415536105,106.68000571811457,0.45347167510193004,0.45347167510193004
2094,2094,155.3881,14.685023,5.6861873,0.0,0,3.8351583,0.0,0.47587425,106.42927464004347,4.2545886,318.00027,-9.2979031,106.42927464004347,,,,,0.45968753527352296,106.69955570580777,0.4596836681132835,0.4596836681132835
2097,2097,155.3887,14.747195,5.746851,0.0,0,3.7791903,0.0,0.48219171,106.09669784435783,4.196722,317.34879,-9.2974234,106.09669784435783,,,,,0.46589952899343545,106.71885461069428,0.46589566113373704,0.46589566113373704
2100,2100,155.3893,14.842999,5.8059607,0.0,0,3.7232223,0.0,0.48858789,106.01774690012677,4.1370287,316.6973,-9.2961521,106.01774690012677,,,,,0.4721115227133479,106.73790894152081,0.4721076541630547,0.4721076541630547
2103,2103,155.3899,14.969752,5.8661618,0.0,0,3.6672544,0.0,0.49501303,106.13388706727164,4.0766888,316.04581,-9.2963934,106.13388706727164,,,,,0.4783235164332604,106.75672495539574,0.47831964720100995,0.47831964720100995
2106,2106,155.3905,15.038777,5.9263902,0.0,0,3.6112862,0.0,0.501544,105.82991637556532,4.0171452,315.39432,-9.2974625,105.82991637556532,,,,,0.48453551015317287,106.77530867067279,0.48453164024738443,0.48453164024738443
2109,2109,155.3911,15.138988,5.9845934,0.0,0,3.5565138,0.0,0.50795454,105.76319323268542,3.9568601,314.74283,-9.2967463,105.76319323268542,,,,,0.4907475038730853,106.79366587892805,0.49074363330196824,0.49074363330196824
2112,2112,155.3917,15.25142,6.0412517,0.0,0,3.5032659,0.0,0.51432604,105.79151376132276,3.9011183,314.09134,-9.2969093,105.79151376132276,,,,,0.4969594975929978,106.81180215629556,0.4969556263645595,0.4969556263645595
2115,2115,155.3923,15.347212,6.1018701,0.0,0,3.450022,0.0,0.5213325,105.64067415981278,3.8453176,313.43985,-9.2967062,105.64067415981278,,,,,0.5031714913129103,106.82972287407978,0.5031676194349632,0.5031676194349632
2118,2118,155.3929,15.419878,6.1577716,0.0,0,3.3967779,0.0,0.52770752,105.3853059687234,3.7884169,312.78839,-9.2984896,105.3853059687234,,,,,0.5093834850328227,106.84743320858836,0.509379612512992,0.509379612512992
2121,2121,155.3935,15.537232,6.2113118,0.0,0,3.343534,0.0,0.53404909,105.45807596856103,3.7303505,312.1369,-9.2962246,105.45807596856103,,,,,0.5155954787527353,106.86493815067857,0.5155916055984651,0.5155916055984651
2124,2124,155.3941,15.655581,6.26612,0.0,0,3.2902899,0.0,0.54033846,105.50900647275212,3.6740994,311.48541,-9.2971449,105.50900647275212,,,,,0.5218074724726477,106.88224251437121,0.5218035986912076,0.5218035986912076
2127,2127,155.3947,15.737158,6.3217702,0.0,0,3.2370458,0.0,0.54697138,105.29075761129177,3.6210983,310.83392,-9.2969255,105.29075761129177,,,,,0.5280194661925601,106.89935094520919,0.5280155917910514,0.5280155917910514
2130,2130,155.3953,15.84629,6.3742037,0.0,0,3.1838019,0.0,0.55334693,105.29213861182131,3.56494,310.18243,-9.2959833,105.29213861182131,,,,,0.5342314599124727,106.91626792804003,0.5342275848978342,0.5342275848978342
2133,2133,155.3959,15.979112,6.4290695,0.0,0,3.1309123,0.0,0.55982798,105.40558277216633,3.5124457,309.53094,-9.2968683,105.40558277216633,,,,,0.5404434536323851,106.93299779441595,0.5404395780113984,0.5404395780113984
2136,2136,155.3965,16.069426,6.4817657,0.0,0,3.0801756,0.0,0.56608886,105.25834383648562,3.4533544,308.87946,-9.2971239,105.25834383648562,,,,,0.5466554473522975,106.94954472945626,0.5466515711315928,0.5466515711315928
2139,2139,155.3971,16.159645,6.5338826,0.0,0,3.0295236,0.0,0.57224059,105.11022672265676,3.398566,308.22797,-9.2961588,105.11022672265676,,,,,0.5528674410722101,106.96591277843982,0.5528635642582708,0.5528635642582708
2142,2142,155.3977,16.301271,6.5862665,0.0,0,2.9788716,0.0,0.57847553,105.28193864660794,3.3436506,307.57651,-9.2970028,105.28193864660794,,,,,0.5590794347921225,106.98210585294885,0.5590755573912903,0.5590755573912903
2145,2145,155.3983,16.403969,6.6412625,0.0,0,2.9282196,0.0,0.58497137,105.15325658412962,3.2898333,307.1633,-9.2968674,105.15325658412962,,,,,0.565291428512035,106.99812773679164,0.5652875505305144,0.5652875505305144
2148,2148,155.3989,16.497581,6.6962657,0.0,0,2.8775675,0.0,0.59143692,104.95660983211668,3.2399547,306.75006,-9.2959232,104.95660983211668,,,,,0.5715034222319475,107.013982091436,0.5714995436758104,0.5714995436758104
2151,2151,155.3995,16.640871,6.7483587,0.0,0,2.8269155,0.0,0.59736329,105.10696110122426,3.1866071,306.33685,-9.2960157,105.10696110122426,,,,,0.5777154159518599,107.02967246130666,0.5777115368270497,0.5777115368270497
2154,2154,155.4001,16.765158,6.8014154,0.0,0,2.7762637,0.0,0.60373986,105.1107259453097,3.1355109,305.92365,-9.2964087,105.1107259453097,,,,,0.5839274096717724,107.04520227873775,0.5839235299841079,0.5839235299841079
2157,2157,155.4007,16.847134,6.857408,0.0,0,2.7256117,0.0,0.61037612,104.79601931635182,3.0843301,305.51041,-9.2968102,104.79601931635182,,,,,0.5901394033916849,107.06057486861326,0.5901355231468647,0.5901355231468647
2160,2160,155.4013,16.991642,6.9085903,0.0,0,2.6768651,0.0,0.6165148,104.93081658024576,3.0306125,305.0972,-9.2959356,104.93081658024576,,,,,0.5963513971115973,107.07579345290449,0.5963475163152031,0.5963475163152031
2163,2163,155.4019,17.140308,6.9573636,0.0,0,2.6286848,0.0,0.62260658,105.11426845543916,2.9775653,304.68396,-9.2946939,105.11426845543916,,,,,0.6025633908315098,107.09086115480599,0.6025595094890099,0.6025595094890099
2166,2166,155.4025,17.230295,7.0129352,0.0,0,2.5805047,0.0,0.6292305,104.82456354366596,2.9255977,304.27075,-9.2966681,104.82456354366596,,,,,0.6087753845514223,107.10578100280166,0.6087715026681757,0.6087715026681757
2169,2169,155.4031,17.38121,7.0682693,0.0,0,2.5323246,0.0,0.63628376,104.89724014017985,2.8758681,303.85754,-9.2969055,104.89724014017985,,,,,0.6149873782713348,107.12055593441741,0.6149834958525936,0.6149834958525936
2172,2172,155.4037,17.529129,7.1187038,0.0,0,2.4841447,0.0,0.64262843,105.0126661035762,2.8246307,303.44431,-9.2953548,105.0126661035762,,,,,0.6211993719912472,107.13518879992574,0.6211954890421605,0.6211954890421605
2175,2175,155.4043,17.642242,7.1680412,0.0,0,2.4359648,0.0,0.64893121,104.9248980409496,2.7691004,303.0311,-9.294733,104.9248980409496,,,,,0.6274113657111597,107.14968236570841,0.6274074822367762,0.6274074822367762
2178,2178,155.4049,17.765678,7.2206759,0.0,0,2.3877847,0.0,0.65564358,104.83661691246812,2.7185409,302.61789,-9.2964363,104.83661691246812,,,,,0.6336233594310722,107.16403931752481,0.6336194754363431,0.6336194754363431
2181,2181,155.4055,17.926308,7.2729487,0.0,0,2.3396046,0.0,0.66250509,104.96023790395816,2.666075,302.20465,-9.2968884,104.96023790395816,,,,,0.6398353531509846,107.17826226365943,0.6398314686407669,0.6398314686407669
2184,2184,155.4061,18.047918,7.3213539,0.0,0,2.2924569,0.0,0.66900045,104.90369216936512,2.617121,301.79144,-9.2948523,104.90369216936512,,,,,0.6460473468708972,107.19235373787399,0.6460434618499558,0.6460434618499558
2187,2187,155.4067,18.17248,7.369348,0.0,0,2.2466257,0.0,0.67547363,104.86027613791202,2.5688813,301.3782,-9.2952814,104.86027613791202,,,,,0.6522593405908096,107.20631620224816,0.6522554550638203,0.6522554550638203
2190,2190,155.4073,18.330008,7.4188118,0.0,0,2.2007978,0.0,0.68203789,104.97134212360208,2.5203056,300.965,-9.2961779,104.97134212360208,,,,,0.658471334310722,107.2201520498283,0.6584674482822739,0.6584674482822739
2193,2193,155.4079,18.475023,7.4683781,0.0,0,2.1549697,0.0,0.6887691,104.99578628189026,2.471781,300.48953,-9.2961607,104.99578628189026,,,,,0.6646833280306346,107.2338636071887,0.6646794415052323,0.6646794415052323
2196,2196,155.4085,18.605297,7.5168843,0.0,0,2.1091418,0.0,0.69548041,104.94168246855048,2.4192307,299.88968,-9.2948313,104.94168246855048,,,,,0.670895321750547,107.24745313695792,0.6708914347326131,0.6708914347326131
2199,2199,155.4091,18.762363,7.5632262,0.0,0,2.063314,0.0,0.70181203,105.06206020707218,2.37433,299.28979,-9.2946606,105.06206020707218,,,,,0.6771073154704594,107.26092284004413,0.6771034279643371,0.6771034279643371
2202,2202,155.4097,18.935507,7.611145,0.0,0,2.0174859,0.0,0.70841902,105.23258734033388,2.3198712,298.68994,-9.2953548,105.23258734033388,,,,,0.683319309190372,107.27427485796025,0.6833154212003264,0.6833154212003264
2205,2205,155.4103,19.055798,7.6599922,0.0,0,1.9716576,0.0,0.71506494,105.0813034102524,2.2764022,298.09006,-9.2955503,105.0813034102524,,,,,0.6895313029102844,107.2875112748608,0.6895274144405054,0.6895274144405054
2208,2208,155.4109,19.212151,7.7090054,0.0,0,1.9261349,0.0,0.72169948,105.11404341062384,2.2241518,297.49017,-9.2932806,105.11404341062384,,,,,0.6957432966301969,107.30063411968028,0.6957394076848007,0.6957394076848007
2211,2211,155.4115,19.392435,7.7558613,0.0,0,1.8824661,0.0,0.72811681,105.29991365309036,2.1778045,296.89032,-9.2940197,105.29991365309036,,,,,0.7019552903501094,107.31364536795374,0.7019514009331407,0.7019514009331407
2214,2214,155.4121,19.527729,7.8034983,0.0,0,1.83887,0.0,0.73444438,105.21490701409157,2.131789,296.29044,-9.295372,105.21490701409157,,,,,0.7081672840700218,107.32654694382506,0.7081633941854554,0.7081633941854554
2217,2217,155.4127,19.685827,7.8487139,0.0,0,1.795274,0.0,0.74057001,105.28234202813714,2.0796306,295.69058,-9.2955742,105.28234202813714,,,,,0.7143792777899344,107.33934072169052,0.7143753874416773,0.7143753874416773
2220,2220,155.4133,19.87269,7.8977304,0.0,0,1.751678,0.0,0.7474193,105.42318495433229,2.0358582,295.0907,-9.2936954,105.42318495433229,,,,,0.7205912715098468,107.3520285279522,0.7205873807017398,0.7205873807017398
2223,2223,155.4139,20.044102,7.9476361,0.0,0,1.708082,0.0,0.75418937,105.45074379669876,1.9896902,294.49081,-9.2939186,105.45074379669876,,,,,0.7268032652297592,107.36461214267922,0.7267993739655786,0.7267993739655786
2226,2226,155.4145,20.189407,7.9951458,0.0,0,1.6644859,0.0,0.7606433,105.36954103065322,1.9413425,293.89096,-9.2952747,105.36954103065322,,,,,0.7330152589496718,107.37709330112637,0.7330113672331309,0.7330113672331309
2229,2229,155.4151,20.37318,8.0399952,0.0,0,1.6208899,0.0,0.76691771,105.52299413428663,1.8974191,293.29108,-9.294384,105.52299413428663,,,,,0.7392272526695842,107.38947369525965,0.7392233605043351,0.7392233605043351
2232,2232,155.4157,20.557009,8.0866547,0.0,0,1.577294,0.0,0.77338451,105.62927762105856,1.8561424,292.69122,-9.2945347,105.62927762105856,,,,,0.7454392463894967,107.40175497514731,0.7454353537791316,0.7454353537791316
2235,2235,155.4163,20.704073,8.1341619,0.0,0,1.5353351,0.0,0.78011608,105.51743893094016,1.806724,292.09134,-9.2939873,105.51743893094016,,,,,0.7516512401094092,107.41393875039584,0.7516473470574621,0.7516473470574621
2238,2238,155.4169,20.882439,8.1791601,0.0,0,1.493863,0.0,0.78655148,105.59759506773304,1.7632399,291.49146,-9.294322,105.59759506773304,,,,,0.7578632338293216,107.42602659143174,0.7578593403392694,0.7578593403392694
2241,2241,155.4175,21.107571,8.2251177,0.0,0,1.452391,0.0,0.79342651,105.88024763345946,1.7159702,290.8916,-9.2939672,105.88024763345946,,,,,0.7640752275492341,107.43802003074927,0.7640713336244982,0.7640713336244982
2244,2244,155.4181,21.272938,8.2717657,0.0,0,1.4109191,0.0,0.8003872,105.83420410061116,1.6729062,290.41272,-9.293787,105.83420410061116,,,,,0.7702872212691466,107.44992056416446,0.7702833269130943,0.7702833269130943
2247,2247,155.4187,21.439737,8.3155327,0.0,0,1.3694471,0.0,0.80718189,105.83601023846164,1.6272559,289.99432,-9.2942209,105.83601023846164,,,,,0.776499214989059,107.4617296519706,0.7764953202050047,0.7764953202050047
2250,2250,155.4193,21.659298,8.3563652,0.0,0,1.3279752,0.0,0.81348825,106.13934895017324,1.5837417,289.5759,-9.2947578,106.13934895017324,,,,,0.7827112087089715,107.47344872005172,0.7827073135001776,0.7827073135001776
2253,2253,155.4199,21.838697,8.3994045,0.0,0,1.2865031,0.0,0.82038295,106.18887649808572,1.5391138,289.1575,-9.2926607,106.18887649808572,,,,,0.788923202428884,107.48507916093685,0.7889193067985628,0.7889193067985628
2256,2256,155.4205,22.019207,8.4442205,0.0,0,1.2450311,0.0,0.82740915,106.19550511138208,1.4962076,288.73911,-9.293375,106.19550511138208,,,,,0.7951351961487965,107.4966223348792,0.7951313001001108,0.7951313001001108
2259,2259,155.4211,22.24198,8.4852657,0.0,0,1.2044492,0.0,0.83409905,106.46395450933596,1.4551324,288.32068,-9.2931995,106.46395450933596,,,,,0.8013471898687089,107.50807957084031,0.8013432934047734,0.8013432934047734
2262,2262,155.4217,22.468481,8.5248404,0.0,0,1.1650023,0.0,0.84036463,106.76305820900916,1.4126076,287.90228,-9.2933035,106.76305820900916,,,,,0.8075591835886214,107.51945216742125,0.8075552867125038,0.8075552867125038
2265,2265,155.4223,22.637613,8.5663023,0.0,0,1.1255583,0.0,0.84694839,106.73793745937148,1.3666052,287.48389,-9.2935667,106.73793745937148,,,,,0.8137711773085339,107.53074139379106,0.8137672800232557,0.8137672800232557
2268,2268,155.4229,22.864731,8.6070833,0.0,0,1.0861143,0.0,0.85337138,106.98538408250415,1.3213868,287.06546,-9.2928524,106.98538408250415,,,,,0.8199831710284463,107.54194849058648,0.8199792733369843,0.8199792733369843
2271,2271,155.4235,23.097612,8.6469145,0.0,0,1.0466702,0.0,0.85960966,107.26252721335727,1.2820146,286.64706,-9.2926493,107.26252721335727,,,,,0.8261951647483589,107.55307467074968,0.8261912666536456,0.8261912666536456
2274,2274,155.4241,23.275848,8.6876287,0.0,0,1.0072262,0.0,0.86606765,107.25321572163266,1.2400284,286.22867,-9.2931986,107.25321572163266,,,,,0.8324071584682713,107.56412112037924,0.8324032599731966,0.8324032599731966
2277,2277,155.4247,23.489464,8.7283258,0.0,0,0.9677822,0.0,0.87242216,107.39312029177276,1.1945156,285.81027,-9.2923794,107.39312029177276,,,,,0.8386191521881837,107.57508899946008,0.8386152532955953,0.8386152532955953
2280,2280,155.4253,23.729845,8.7703533,0.0,0,0.92833829,0.0,0.87899083,107.61110849952246,1.1545826,285.39185,-9.2923756,107.61110849952246,,,,,0.8448311459080963,107.58597944269013,0.8448272466208006,0.8448272466208006
2283,2283,155.4259,23.928181,8.8109407,0.0,0,0.88915849,0.0,0.88518244,107.65250923666686,1.1109911,284.97345,-9.2925806,107.65250923666686,,,,,0.8510431396280087,107.59679356017311,0.851039239948772,0.851039239948772
2286,2286,155.4265,24.119539,8.8477573,0.0,0,0.85158336,0.0,0.89092517,107.72883471766046,1.0717119,284.55505,-9.2924614,107.72883471766046,,,,,0.8572551333479211,107.6075324381676,0.8572512332794704,0.8572512332794704
2289,2289,155.4271,24.366053,8.8869867,0.0,0,0.8140713,0.0,0.89683527,107.98526286062338,1.0298579,284.13663,-9.2930565,107.98526286062338,,,,,0.8634671270678337,107.6181971396709,0.8634632266128573,0.8634632266128573
2292,2292,155.4277,24.57321,8.9273386,0.0,0,0.77655935,0.0,0.90346861,108.02710628982304,0.9915939,283.71826,-9.2915545,108.02710628982304,,,,,0.8696791207877461,107.62878870524024,0.8696752199488949,0.8696752199488949
2295,2295,155.4283,24.790443,8.969243,0.0,0,0.73904735,0.0,0.91004664,108.06403622224218,0.95365381,283.52014,-9.2915678,108.06403622224218,,,,,0.8758911145076586,107.63930815346151,0.8758872132875463,0.8758872132875463
2298,2298,155.4289,25.017996,9.0064697,0.0,0,0.70153534,0.0,0.91619474,108.23284790412087,0.91868311,283.32205,-9.293047,108.23284790412087,,,,,0.8821031082275711,107.64975648166798,0.8820992066287753,0.8820992066287753
2301,2301,155.4295,25.260681,9.0425835,0.0,0,0.6640234,0.0,0.92208725,108.47645205304777,0.87791753,283.12393,-9.2932491,108.47645205304777,,,,,0.8883151019474835,107.66013466648562,0.8883111999725465,0.8883111999725465
2304,2304,155.4301,25.453274,9.0802851,0.0,0,0.62651134,0.0,0.92828751,108.45528677164695,0.83960247,282.92584,-9.2915335,108.45528677164695,,,,,0.8945270956673961,107.67044366441188,0.8945231933188253,0.8945231933188253
2307,2307,155.4307,25.655397,9.118454,0.0,0,0.58899933,0.0,0.93494284,108.45093266981844,0.80749923,282.72775,-9.2906971,108.45093266981844,,,,,0.9007390893873085,107.68068441239562,0.9007351866675777,0.9007351866675777
2310,2310,155.4313,25.910992,9.1537209,0.0,0,0.5528841,0.0,0.94119722,108.72360233876869,0.76719224,282.52963,-9.2914581,108.72360233876869,,,,,0.906951083107221,107.69085782829585,0.9069471800187704,0.9069471800187704
2313,2313,155.4319,26.118696,9.187746,0.0,0,0.51718396,0.0,0.94720674,108.80951505573094,0.73095685,282.33154,-9.2917242,108.80951505573094,,,,,0.9131630768271335,107.70096481150958,0.9131591733723711,0.9131591733723711
2316,2316,155.4325,26.332935,9.2200489,0.0,0,0.48148397,0.0,0.95300549,108.95002462167731,0.69683075,282.13342,-9.2911348,108.95002462167731,,,,,0.9193750705470459,107.71100624333279,0.9193711667283473,0.9193711667283473
2319,2319,155.4331,26.595264,9.2551155,0.0,0,0.44578397,0.0,0.95932221,109.2108860881246,0.65958863,281.93533,-9.2910128,109.2108860881246,,,,,0.9255870642669584,107.72098298761104,0.9255831600866681,0.9255831600866681
2322,2322,155.4337,26.824476,9.2903004,0.0,0,0.41008398,0.0,0.96587169,109.31768599586132,0.62340492,281.73724,-9.2900448,109.31768599586132,,,,,0.9317990579868709,107.73089589095301,0.9317951534473028,0.9317951534473028
2325,2325,155.4343,27.051428,9.326416,0.0,0,0.37438396,0.0,0.97212082,109.37880324497722,0.58903402,281.53912,-9.2911987,109.37880324497722,,,,,0.9380110517067833,107.74074578348218,0.9380071468102211,0.9380071468102211
2328,2328,155.4349,27.300758,9.3545408,0.0,0,0.33868399,0.0,0.97752255,109.7080586098042,0.553949,281.34103,-9.2913113,109.7080586098042,,,,,0.9442230454266958,107.75053347905741,0.9442191401753937,0.9442191401753937
2329,2329,155.4351,27.393179,9.3722496,0.0,0,0.32678398,0.0,0.9787125,109.65054444169012,0.54212224,281.27499,-9.290761,109.65054444169012,,,,,0.94629371,107.75378236108224,0.9462898046309471,0.9462898046309471