File: examples/hot axisymmetric compression example/data/12 fitted data ramberg/testID_0142.csv
level_0,index,Time(sec),Force(kN),Jaw(mm),PowAngle(deg),Power(W),Pram,PTemp,Strain,Stress(MPa),Stroke(mm),TC1(C),wedge(mm),uncorrected stress,sampled strain,sampled stress,fitting strain,fitting stress,model strain,ramberg stress,ramberg plastic strain,ramberg accumulated plastic strain
2105,2105,178.6798,0.39999792,0.008381472,0.0,0,9.0629702,0.0,0.00064967287,4.873312610442149,10.073219,404.65091,-9.2641535,4.873312610442149,0.00064967287,4.873312610442149,0.0,4.873312610442149,0.0,0.0,0.0,0.0
2107,2107,178.6802,3.6657939,0.065122217,0.0,0,9.0044422,0.0,0.0036153095,44.481788739119615,10.006762,404.68454,-9.2648335,44.481788739119615,0.10943417,83.71953050318912,0.095467269,84.62498489942833,0.004205606563876652,76.45510369844946,0.00420216638518529,0.00420216638518529
2109,2109,178.6806,5.7659225,0.11932088,0.0,0,8.9459143,0.0,0.0077365818,69.69512471666594,9.9497671,404.7182,-9.2629423,69.69512471666594,0.19396617,84.69481900919261,0.190934538,84.6338354631176,0.008411213127753303,77.08221602894733,0.008407744731475774,0.008407744731475774
2111,2111,178.681,6.1532989,0.20483555,0.0,0,8.8873854,0.0,0.01295334,73.92245465859655,9.8671303,404.75183,-9.2607803,73.92245465859655,0.28442693,83.72844258026494,0.28640180699999995,83.69969825035793,0.012616819691629956,77.45632557581172,0.012613334461895548,0.012613334461895548
2113,2113,178.6814,6.2101603,0.36067301,0.0,0,8.8288574,0.0,0.023243081,73.76847800866935,9.7772284,404.78549,-9.2597857,73.76847800866935,0.38145095,82.24236563564894,0.381869076,82.2302801808202,0.016822426255506607,77.72508551215442,0.016818928932633072,0.016818928932633072
2115,2115,178.6818,6.5188756,0.42109522,0.0,0,8.7703295,0.0,0.028265491,77.09485825531767,9.6725283,404.81912,-9.2608261,77.09485825531767,0.47453991,79.80836079608909,0.477336345,79.77767906916525,0.021028032819383258,77.93547742469677,0.021024526029701892,0.021024526029701892
2117,2117,178.6822,6.8414464,0.52478838,0.0,0,8.7136869,0.0,0.03471091,80.29592233697889,9.573554,404.85278,-9.260457,80.29592233697889,0.56759536,79.20444932742114,0.5728036139999999,79.17244241896302,0.025233639383259912,78.10864077611525,0.02523012480190941,0.02523012480190941
2119,2119,178.6826,7.3528161,0.58900917,0.0,0,8.6580172,0.0,0.039825104,85.88909991377923,9.4886475,404.88641,-9.2594242,85.88909991377923,0.66540438,78.62899269498416,0.6682708829999999,78.63243404131991,0.029439245947136563,78.2559394326454,0.029435724737926376,0.029435724737926376
2121,2121,178.683,6.8489795,0.61021191,0.0,0,8.6023531,0.0,0.04125623,79.87805756569885,9.4142246,404.92007,-9.2587395,79.87805756569885,0.76189953,78.83390712137542,0.763738152,78.84958892910703,0.033644852511013214,78.38419942176753,0.03364132553060843,0.03364132553060843
2123,2123,178.6834,6.8954453,0.70410562,0.0,0,8.546689,0.0,0.047328934,79.8596427831751,9.3495541,404.95251,-9.2598715,79.8596427831751,0.85753506,79.6716596168004,0.859205421,79.70487409646968,0.03785045907488987,78.49784717259107,0.037846926980783686,0.037846926980783686
2125,2125,178.6838,7.5308414,0.74481136,0.0,0,8.491025,0.0,0.050651196,86.95315126594461,9.2895155,404.98376,-9.259654,86.95315126594461,0.95467269,81.48573655426101,0.95467269,81.48573655426101,0.042056065638766515,78.59991901763465,0.04205252895182912,0.04205252895182912
2127,2127,178.6842,7.5956473,0.82012355,0.0,0,8.4353609,0.0,0.055650756,87.2062330044135,9.2147932,405.01498,-9.2588301,87.2062330044135,,,,,0.04626167220264317,78.69258951552698,0.04625813134589818,0.04625813134589818
2129,2129,178.6846,7.3571715,0.92336518,0.0,0,8.3796968,0.0,0.062690906,83.81066528473394,9.134943,405.04623,-9.26017,83.81066528473394,,,,,0.050467278766519824,78.77747017286067,0.0504637340904794,0.0504637340904794
2131,2131,178.685,7.2372723,0.99806505,0.0,0,8.3240328,0.0,0.068469271,81.97668625074476,9.057951,405.07748,-9.2603645,81.97668625074476,,,,,0.05467288533039647,78.85578885725545,0.05466933713032356,0.05466933713032356
2133,2133,178.6854,7.578167,1.0699742,0.0,0,8.2683687,0.0,0.073657729,85.36608583286832,8.9806404,405.1087,-9.2596884,85.36608583286832,,,,,0.058878491894273126,78.92850291453298,0.05887494042235389,0.05887494042235389
2135,2135,178.6858,7.5358343,1.1152791,0.0,0,8.2127056,0.0,0.076803461,84.59352703285457,8.9091129,405.13995,-9.2595739,84.59352703285457,,,,,0.06308409845814977,78.99637339428779,0.06308054393232612,0.06308054393232612
2137,2137,178.6862,7.6885834,1.1688162,0.0,0,8.1570406,0.0,0.080950171,85.95167849558227,8.8503075,405.1712,-9.2597933,85.95167849558227,,,,,0.06728970502202643,79.06001541421026,0.06728614763256242,0.06728614763256242
2139,2139,178.6866,7.3649807,1.2332293,0.0,0,8.1013775,0.0,0.085382521,81.92313092524279,8.7903671,405.20245,-9.259057,81.92313092524279,,,,,0.07149531158590308,79.1199333211135,0.07149175150036914,0.07149175150036914
2141,2141,178.687,7.8305135,1.2820896,0.0,0,8.0462675,0.0,0.088838749,86.76994570525866,8.7355947,405.23367,-9.2605476,86.76994570525866,,,,,0.07570091814977974,79.17654584805965,0.07569735551690494,0.07569735551690494
2143,2143,178.6874,7.9394355,1.3546467,0.0,0,7.993176,0.0,0.094347596,87.47779371823057,8.6706238,405.26492,-9.2591944,87.47779371823057,,,,,0.07990652471365638,79.23020450275254,0.07990295966635336,0.07990295966635336
2145,2145,178.6878,7.7517266,1.4390546,0.0,0,7.9402156,0.0,0.10012966,84.84260223179757,8.6034889,405.29617,-9.259099,84.84260223179757,,,,,0.08411213127753303,79.2812072630832,0.08410856393530657,0.08410856393530657
2147,2147,178.6882,7.6694832,1.4992908,0.0,0,7.8872552,0.0,0.10475143,83.54206834958157,8.5386391,405.32739,-9.2600536,83.54206834958157,,,,,0.08831773784140969,79.32980894877248,0.0883141683122987,0.0883141683122987
2149,2149,178.6886,7.7206268,1.5560215,0.0,0,7.8342953,0.0,0.10943417,83.71953050318912,8.4727974,405.35864,-9.2591667,83.71953050318912,,,,,0.09252334440528634,79.37622919337554,0.09251977278744708,0.09251977278744708
2151,2151,178.689,7.9422092,1.5950336,0.0,0,7.7813349,0.0,0.1118403,85.85370585139518,8.4160814,405.38989,-9.2580814,85.85370585139518,,,,,0.096728950969163,79.42065865397416,0.09672537735217292,0.09672537735217292
2153,2153,178.6894,7.8558059,1.6459111,0.0,0,7.728375,0.0,0.11578475,84.57321827115969,8.360404,405.42114,-9.2591991,84.57321827115969,,,,,0.10093455753303965,79.46326390676991,0.10093098199898091,0.10093098199898091
2155,2155,178.6898,7.8221879,1.7007586,0.0,0,7.675415,0.0,0.12017086,83.83933802334359,8.3121967,405.45236,-9.2597198,83.83933802334359,,,,,0.10514016409691629,79.50419134922564,0.10513658672128376,0.10513658672128376
2157,2157,178.6902,8.0093012,1.7468596,0.0,0,7.6224551,0.0,0.12311648,85.52469388327992,8.256794,405.48361,-9.2595606,85.52469388327992,,,,,0.10934577066079294,79.54357034119553,0.10934219151326079,0.10934219151326079
2159,2159,178.6906,8.0941563,1.8058305,0.0,0,7.5694952,0.0,0.12793332,86.01688469364406,8.2022524,405.51486,-9.2608795,86.01688469364406,,,,,0.1135513772246696,79.58151575694691,0.11354779636974312,0.11354779636974312
2161,2161,178.691,8.0437918,1.8628995,0.0,0,7.5165353,0.0,0.13220221,85.08355114556713,8.1448393,405.54608,-9.2585306,85.08355114556713,,,,,0.11775698378854625,79.61813007573302,0.11775340128611957,0.11775340128611957
2163,2163,178.6914,8.0328026,1.9262706,0.0,0,7.4635754,0.0,0.13672091,84.52579511956544,8.0882349,405.57733,-9.2575989,84.52579511956544,,,,,0.1219625903524229,79.65350510790196,0.12195900625825902,0.12195900625825902
2165,2165,178.6918,8.037776,1.9718735,0.0,0,7.410615,0.0,0.14090414,84.26017529851853,8.0328569,405.60858,-9.257967,84.26017529851853,,,,,0.12616819691629955,79.68772343006131,0.12616461128244588,0.12616461128244588
2167,2167,178.6922,8.1573696,2.0104921,0.0,0,7.3593607,0.0,0.14342415,85.24059244900751,7.9788747,405.63983,-9.2587738,85.24059244900751,,,,,0.13037380348017621,79.72085958646474,0.13037021635532595,0.13037021635532595
2169,2169,178.6926,8.1138525,2.0715735,0.0,0,7.3089876,0.0,0.14799874,84.35588093356084,7.9305353,405.67105,-9.2594986,84.35588093356084,,,,,0.13457941004405286,79.75298110080726,0.1345758214738609,0.1345758214738609
2171,2171,178.693,8.0914164,2.1113508,0.0,0,7.2586198,0.0,0.15163822,83.84336062338399,7.8810205,405.7023,-9.258913,83.84336062338399,,,,,0.1387850166079295,79.78414933338887,0.13878142663528978,0.13878142663528978
2173,2173,178.6934,8.2487745,2.156707,0.0,0,7.2082515,0.0,0.15459745,85.14925734010511,7.8315115,405.65622,-9.2590723,85.14925734010511,,,,,0.14299062317180616,79.8144202110419,0.1429870318370961,0.1429870318370961
2175,2175,178.6938,8.3303251,2.2167246,0.0,0,7.1578832,0.0,0.15957797,85.55719110578094,7.7808194,405.51563,-9.2595282,85.55719110578094,,,,,0.1471962297356828,79.84384485203364,0.14719263707697974,0.14719263707697974
2177,2177,178.6942,8.2798367,2.2632937,0.0,0,7.1075149,0.0,0.1633255,84.70398991772556,7.7326131,405.37503,-9.2588167,84.70398991772556,,,,,0.15140183629955947,79.8724701033698,0.15139824235283278,0.15139824235283278
2179,2179,178.6946,8.2192602,2.3187346,0.0,0,7.0571475,0.0,0.16729726,83.68874652997575,7.6805806,405.23447,-9.2588043,83.68874652997575,,,,,0.1556074428634361,79.90033900515624,0.15560384766271854,0.15560384766271854
2181,2181,178.695,8.3121586,2.3639536,0.0,0,7.0067787,0.0,0.17148429,84.30835200489165,7.6291261,405.09387,-9.2594566,84.30835200489165,,,,,0.15981304942731275,79.9274911932062,0.1598094530048536,0.1598094530048536
2183,2183,178.6954,8.4290953,2.4042916,0.0,0,6.9564114,0.0,0.17429,85.19922574224388,7.5828733,404.95328,-9.2600164,85.19922574224388,,,,,0.16401865599118942,79.95396324989112,0.16401505837759195,0.16401505837759195
2185,2185,178.6958,8.3994503,2.4593186,0.0,0,6.9060431,0.0,0.17843166,84.49827761079118,7.5340791,404.81268,-9.2590294,84.49827761079118,,,,,0.16822426255506606,79.97978901076088,0.168220663779411,0.168220663779411
2187,2187,178.6962,8.3427439,2.5023301,0.0,0,6.8556757,0.0,0.18250398,83.61622266436528,7.4881873,404.67209,-9.2578707,83.61622266436528,,,,,0.17242986911894273,80.00499983358127,0.1724262692088999,0.1724262692088999
2189,2189,178.6966,8.456152,2.5521994,0.0,0,6.8053074,0.0,0.18587297,84.38665405378212,7.4370933,404.53152,-9.2586241,84.38665405378212,,,,,0.17663547568281937,80.02962483515272,0.17663187466474842,0.17663187466474842
2191,2191,178.697,8.5709352,2.6032393,0.0,0,6.7554412,0.0,0.19013332,85.1521731027377,7.3895283,404.39093,-9.2595043,85.1521731027377,,,,,0.180841082246696,80.05369110048818,0.18083748014573783,0.18083748014573783
2193,2193,178.6974,8.5566149,2.6456332,0.0,0,6.7074018,0.0,0.19396617,84.69481900919261,7.337811,404.25034,-9.2602768,84.69481900919261,,,,,0.18504668881057268,80.07722386803607,0.1850430856507326,0.1850430856507326
2195,2195,178.6978,8.5368299,2.70244,0.0,0,6.6594815,0.0,0.19788243,84.07771410692186,7.2898726,404.10974,-9.2609348,84.07771410692186,,,,,0.18925229537444932,80.10024669433729,0.1892486911786727,0.1892486911786727
2197,2197,178.6982,8.5470896,2.7421374,0.0,0,6.6115613,0.0,0.20169334,83.88398720789343,7.2398801,403.96915,-9.2595224,83.88398720789343,,,,,0.193457901938326,80.12278160056357,0.19345429672856732,0.19345429672856732
2199,2199,178.6986,8.678072,2.7860107,0.0,0,6.5636415,0.0,0.20534776,84.83868947555953,7.1921978,403.82858,-9.2582397,84.83868947555953,,,,,0.19766350850220263,80.14484920349946,0.19765990229948868,0.19765990229948868
2201,2201,178.699,8.6917772,2.8463204,0.0,0,6.5157218,0.0,0.20955093,84.51717351587259,7.1428652,403.68799,-9.2579966,84.51717351587259,,,,,0.2018691150660793,80.16646883285875,0.20186550789056715,0.20186550789056715
2203,2203,178.6994,8.7082052,2.884769,0.0,0,6.467802,0.0,0.21335885,84.3859460304147,7.0965528,403.54739,-9.2587662,84.3859460304147,,,,,0.20607472162995594,80.18765863645403,0.20607111350098603,0.20607111350098603
2205,2205,178.6998,8.7585936,2.9339402,0.0,0,6.4198813,0.0,0.21723907,84.49992468948909,7.0439401,403.4068,-9.2608833,84.49992468948909,,,,,0.21028032819383258,80.20843567494616,0.21027671912997772,0.21027671912997772
2207,2207,178.7002,8.8023567,2.9906905,0.0,0,6.3719611,0.0,0.22160347,84.48792884255165,6.993762,403.26624,-9.2609854,84.48792884255165,,,,,0.21448593475770925,80.22881600722724,0.21448232477681967,0.21448232477681967
2209,2209,178.7006,8.8331661,3.0324411,0.0,0,6.3240414,0.0,0.22574995,84.4630534202485,6.9447408,403.12564,-9.2596722,84.4630534202485,,,,,0.21869154132158589,80.2488147675116,0.21868793044083085,0.21868793044083085
2211,2211,178.701,8.8453207,3.0847149,0.0,0,6.2761216,0.0,0.22969361,84.17728269795091,6.8941998,402.98505,-9.2588024,84.17728269795091,,,,,0.22289714788546255,80.26844623523226,0.22289353612136872,0.22289353612136872
2213,2213,178.7014,8.9009705,3.1368461,0.0,0,6.2282019,0.0,0.23398119,84.30341349198346,6.8440065,402.84445,-9.2584972,84.30341349198346,,,,,0.2271027544493392,80.28772389841687,0.22709914181782642,0.22709914181782642
2215,2215,178.7018,8.9356651,3.1795533,0.0,0,6.1802816,0.0,0.23809889,84.30016268391796,6.7978587,402.70386,-9.2601824,84.30016268391796,,,,,0.23130836101321584,80.30666051122293,0.23130474752963004,0.23130474752963004
2217,2217,178.7022,8.9434891,3.2288449,0.0,0,6.1339045,0.0,0.24175915,83.99058463055157,6.7484374,402.56329,-9.2597036,83.99058463055157,,,,,0.2355139675770925,80.32526814641366,0.23551035325623637,0.23551035325623637
2219,2219,178.7026,8.9934874,3.2769251,0.0,0,6.0883236,0.0,0.24614491,84.08403127842287,6.6998711,402.4227,-9.2601213,84.08403127842287,,,,,0.23971957414096914,80.34355824316336,0.23971595899713066,0.23971595899713066
2221,2221,178.703,9.0592461,3.3210564,0.0,0,6.042748,0.0,0.25004569,84.35106722187429,6.6516109,402.2821,-9.2591286,84.35106722187429,,,,,0.2439251807048458,80.36154165079415,0.24392156475182478,0.24392156475182478
2223,2223,178.7034,9.094101,3.373543,0.0,0,5.9971714,0.0,0.25407287,84.26035227915482,6.6025434,402.08423,-9.2587862,84.26035227915482,,,,,0.24813078726872245,80.37922866870683,0.24812717051985525,0.24812717051985525
2225,2225,178.7038,9.1099005,3.4243858,0.0,0,5.9515953,0.0,0.25900322,84.0037487357122,6.5518198,401.80042,-9.2590914,84.0037487357122,,,,,0.2523363938325991,80.39662908307069,0.2523327763007817,0.2523327763007817
2227,2227,178.7042,9.1279602,3.4742022,0.0,0,5.9060197,0.0,0.26303136,83.77459478456592,6.4995298,401.51657,-9.259016,83.77459478456592,,,,,0.25654200039647573,80.41375220042956,0.2565383820941855,0.2565383820941855
2229,2229,178.7046,9.1853485,3.5218463,0.0,0,5.8604436,0.0,0.26698458,83.92044007475207,6.4520745,401.23276,-9.2599688,83.92044007475207,,,,,0.26074760696035243,80.43060687868116,0.260743987899668,0.260743987899668
2231,2231,178.705,9.2594776,3.5699027,0.0,0,5.814867,0.0,0.27182466,84.21041623932796,6.4047213,400.94894,-9.2590876,84.21041623932796,,,,,0.26495321352422907,80.44720155548612,0.2649495937168495,0.2649495937168495
2233,2233,178.7054,9.2781582,3.6192799,0.0,0,5.7692914,0.0,0.27556753,83.98152200898178,6.3530436,400.66513,-9.2582235,83.98152200898178,,,,,0.2691588200881057,80.46354427454729,0.26915519954536815,0.26915519954536815
2235,2235,178.7058,9.2809601,3.6680167,0.0,0,5.7237153,0.0,0.27978769,83.61310596517166,6.3066487,400.38129,-9.2578936,83.61310596517166,,,,,0.27336442665198235,80.47964270980202,0.27336080538487856,0.27336080538487856
2237,2237,178.7062,9.3355179,3.7142982,0.0,0,5.6781397,0.0,0.28442693,83.72844258026494,6.2564678,400.09747,-9.2587681,83.72844258026494,,,,,0.277570033215859,80.49550418783997,0.27756641123505116,0.27756641123505116
2239,2239,178.7066,9.3899593,3.7677057,0.0,0,5.6325636,0.0,0.28838417,83.78003252408955,6.2063475,399.81366,-9.2595415,83.78003252408955,,,,,0.2817756397797357,80.51113570859155,0.2817720170955709,0.2817720170955709
2241,2241,178.707,9.4283419,3.8136415,0.0,0,5.5874414,0.0,0.2929661,83.74532098695431,6.159699,399.52985,-9.2602911,83.74532098695431,,,,,0.2859812463436123,80.52654396452876,0.2859776229661367,0.2859776229661367
2243,2243,178.7074,9.4441605,3.8593485,0.0,0,5.5439734,0.0,0.29740408,83.50986120819324,6.1100988,399.246,-9.2601347,83.50986120819324,,,,,0.29018685290748897,80.5417353584268,0.2901832288464604,0.2901832288464604
2245,2245,178.7078,9.470665,3.9153464,0.0,0,5.5006132,0.0,0.30149701,83.28226347932971,6.0632224,398.96219,-9.2588663,83.28226347932971,,,,,0.2943924594713656,80.55671601997892,0.2943888347362663,0.2943888347362663
2247,2247,178.7082,9.5260868,3.958293,0.0,0,5.457253,0.0,0.30613056,83.41321547792163,6.0108414,398.67838,-9.2579823,83.41321547792163,,,,,0.29859806603524225,80.57149182106035,0.29859444063529006,0.29859444063529006
2249,2249,178.7086,9.5594387,4.0033779,0.0,0,5.4138932,0.0,0.31006378,83.3297471171376,5.9614959,398.39456,-9.2589722,83.3297471171376,,,,,0.30280367259911894,80.58606839006774,0.3028000465432785,0.3028000465432785
2251,2251,178.709,9.6161242,4.0589728,0.0,0,5.370533,0.0,0.31460011,83.35802742696838,5.9148407,398.11072,-9.2599344,83.35802742696838,,,,,0.3070092791629956,80.60045112525279,0.3070056524599887,0.3070056524599887
2253,2253,178.7094,9.6494904,4.1012163,0.0,0,5.3271732,0.0,0.31929132,83.29202095926371,5.8682499,397.8269,-9.2603245,83.29202095926371,,,,,0.3112148857268722,80.61464520708722,0.31121125838518754,0.31121125838518754
2255,2255,178.7098,9.6864624,4.1479378,0.0,0,5.283813,0.0,0.32318148,83.21670372588962,5.8197618,397.54309,-9.2609215,83.21670372588962,,,,,0.31542049229074887,80.62865560995199,0.3154168643186512,0.3154168643186512
2257,2257,178.7102,9.7067051,4.2038026,0.0,0,5.2404532,0.0,0.32813448,82.91791912034913,5.7684588,397.25928,-9.2595406,82.91791912034913,,,,,0.3196260988546255,80.64248711281314,0.31962247026016466,0.31962247026016466
2259,2259,178.7106,9.7597046,4.2441444,0.0,0,5.1970935,0.0,0.33259147,83.02740781831298,5.7214689,396.97546,-9.2587557,83.02740781831298,,,,,0.3238317054185022,80.65614430947755,0.32382807620952125,0.32382807620952125
2261,2261,178.711,9.8333836,4.2940173,0.0,0,5.1537333,0.0,0.33643723,83.22660774583463,5.6710758,396.69162,-9.2585154,83.22660774583463,,,,,0.32803731198237884,80.66963161800477,0.3280336821665221,0.3280336821665221
2263,2263,178.7114,9.8640394,4.3471184,0.0,0,5.110373,0.0,0.34162819,83.02931167309085,5.6236172,396.40781,-9.2591419,83.02931167309085,,,,,0.3322429185462555,80.68295328961617,0.332239288130976,0.332239288130976
2265,2265,178.7118,9.869236,4.3872581,0.0,0,5.0670133,0.0,0.34588984,82.72756241610392,5.5762792,396.12399,-9.2603664,82.72756241610392,,,,,0.3364485251101321,80.6961134169757,0.3364448941026987,0.3364448941026987
2267,2267,178.7122,9.8877735,4.4386244,0.0,0,5.0250483,0.0,0.35003093,82.43994680169848,5.5269938,395.84018,-9.2598133,82.43994680169848,,,,,0.34065413167400876,80.70911594206056,0.3406505000815129,0.3406505000815129
2269,2269,178.7126,9.9540157,4.4859447,0.0,0,4.9838037,0.0,0.35515353,82.58134901550724,5.483079,395.55634,-9.2595177,82.58134901550724,,,,,0.34485973823788546,80.72196466339638,0.3448561060672477,0.3448561060672477
2271,2271,178.713,10.015789,4.5278926,0.0,0,4.9425635,0.0,0.35909963,82.72728830798305,5.4360914,395.27252,-9.2579794,82.72728830798305,,,,,0.3490653448017621,80.7346632430785,0.34906171205973824,0.34906171205973824
2273,2273,178.7134,10.02865,4.5777512,0.0,0,4.9013238,0.0,0.36335802,82.39722893443219,5.3862476,394.98901,-9.2587767,82.39722893443219,,,,,0.35327095136563874,80.74721521311663,0.35326731805882566,0.35326731805882566
2275,2275,178.7138,10.046042,4.6219559,0.0,0,4.8600836,0.0,0.36828279,82.15259283583939,5.3407984,394.70612,-9.2588758,82.15259283583939,,,,,0.3574765579295154,80.75962398164232,0.35747292406435655,0.35747292406435655
2277,2277,178.7142,10.073727,4.6670842,0.0,0,4.8188438,0.0,0.37218609,81.98222344996826,5.2941446,394.42322,-9.2597771,81.98222344996826,,,,,0.361682164493392,80.77189283860403,0.36167853007618295,0.36167853007618295
2279,2279,178.7146,10.152826,4.7145281,0.0,0,4.7776036,0.0,0.37661484,82.20549608700424,5.2460032,394.14032,-9.2603159,82.20549608700424,,,,,0.3658877710572687,80.78402496120708,0.36588413609416187,0.36588413609416187
2281,2281,178.715,10.204501,4.7573571,0.0,0,4.7363639,0.0,0.38145095,82.24236563564894,5.2038245,393.85742,-9.2595196,82.24236563564894,,,,,0.37009337762114536,80.7960234189738,0.37008974211815515,0.37008974211815515
2283,2283,178.7154,10.21195,4.807117,0.0,0,4.6951237,0.0,0.38543403,81.85874553143675,5.1602497,393.57449,-9.259923,81.85874553143675,,,,,0.374298984185022,80.80789117866735,0.37429534814802934,0.37429534814802934
2285,2285,178.7158,10.230834,4.8497229,0.0,0,4.6538839,0.0,0.39014938,81.62949859611287,5.1143594,393.2916,-9.2577829,81.62949859611287,,,,,0.37850459074889864,80.8196311087142,0.3785009541836553,0.3785009541836553
2287,2287,178.7162,10.277773,4.8893199,0.0,0,4.6126437,0.0,0.39446941,81.64861072566202,5.0697994,393.0087,-9.2584372,81.64861072566202,,,,,0.3827101973127753,80.8312459836085,0.38270656022490834,0.38270656022490834
2289,2289,178.7166,10.319885,4.9406528,0.0,0,4.5714035,0.0,0.39851159,81.52047168223153,5.027113,392.7258,-9.2597637,81.52047168223153,,,,,0.386915803876652,80.84273848796863,0.3869121662716676,0.3869121662716676
2291,2291,178.717,10.363314,4.979835,0.0,0,4.5305758,0.0,0.40320703,81.50883680259112,4.9839697,392.4429,-9.2608156,81.50883680259112,,,,,0.3911214104405286,80.85411122034569,0.391117772323816,0.391117772323816
2293,2293,178.7174,10.383986,5.0196009,0.0,0,4.4912457,0.0,0.40713972,81.31068717283857,4.9399252,392.16,-9.2588148,81.31068717283857,,,,,0.39532701700440526,80.86536669692086,0.39532337838124054,0.39532337838124054
2295,2295,178.7178,10.404065,5.0708857,0.0,0,4.4520135,0.0,0.41155267,81.00172311256549,4.8958521,391.87708,-9.2589521,81.00172311256549,,,,,0.3995326235682819,80.87650735492817,0.3995289844438314,0.3995289844438314
2297,2297,178.7182,10.450939,5.1070261,0.0,0,4.4127812,0.0,0.41609067,81.03661956834621,4.8550787,391.59418,-9.2586803,81.03661956834621,,,,,0.4037382301321586,80.88753555595687,0.40373459051148247,0.40373459051148247
2299,2299,178.7186,10.505749,5.1489458,0.0,0,4.3735495,0.0,0.41997811,81.07674318124873,4.8094983,391.31128,-9.2583256,81.07674318124873,,,,,0.40794383669603523,80.89845358904331,0.4079401965840906,0.4079401965840906
2301,2301,178.719,10.554223,5.1982617,0.0,0,4.3343177,0.0,0.42467687,80.99590774700702,4.7698236,391.02838,-9.2584133,80.99590774700702,,,,,0.4121494432599119,80.9092636736307,0.412145802661556,0.412145802661556
2303,2303,178.7194,10.576309,5.2296462,0.0,0,4.2950859,0.0,0.42874974,80.87524809213541,4.7285395,390.74548,-9.2599745,80.87524809213541,,,,,0.4163550498237885,80.91996796233259,0.4163514087437818,0.4163514087437818
2305,2305,178.7198,10.58078,5.2703857,0.0,0,4.2558532,0.0,0.43218124,80.53259750969582,4.6843514,390.46255,-9.2602358,80.53259750969582,,,,,0.42056065638766515,80.93056854369267,0.420557014830674,0.420557014830674
2307,2307,178.7202,10.624486,5.3171911,0.0,0,4.2166214,0.0,0.43711463,80.43046138617879,4.6443353,390.17966,-9.2589712,80.43046138617879,,,,,0.42476626295154185,80.94106744459224,0.42476262092214145,0.42476262092214145
2309,2309,178.7206,10.69039,5.3504467,0.0,0,4.1773891,0.0,0.44116634,80.61849883162445,4.6065078,389.89676,-9.2589426,80.61849883162445,,,,,0.4289718695154185,80.95146663272969,0.42896822701809556,0.42896822701809556
2311,2311,178.721,10.731611,5.394383,0.0,0,4.1381574,0.0,0.44487429,80.51700666392722,4.5651894,389.61386,-9.2591667,80.51700666392722,,,,,0.43317747607929513,80.96176801890401,0.43317383311845037,0.43317383311845037
2313,2313,178.7214,10.744685,5.4362593,0.0,0,4.0989256,0.0,0.44989857,80.22155527710265,4.5245833,389.33096,-9.259347,80.22155527710265,,,,,0.43738308264317177,80.97197345918416,0.4373794392231224,0.4373794392231224
2315,2315,178.7218,10.768649,5.47158,0.0,0,4.0596933,0.0,0.45353341,80.06776168799968,4.485889,389.04807,-9.2600842,80.06776168799968,,,,,0.4415886892070484,80.98208475699403,0.44158504533203047,0.44158504533203047
2317,2317,178.7222,10.82709,5.5136471,0.0,0,4.0217257,0.0,0.45737979,80.10382826995254,4.4437199,388.76514,-9.2594404,80.10382826995254,,,,,0.4457942957709251,80.99210366503979,0.4457906514450957,0.4457906514450957
2319,2319,178.7226,10.894411,5.5520158,0.0,0,3.9844091,0.0,0.46232456,80.23617066779761,4.4047394,388.48224,-9.2589388,80.23617066779761,,,,,0.44999990233480175,81.00203188731423,0.44999625756224143,0.44999625756224143
2321,2321,178.723,10.92461,5.5896211,0.0,0,3.9470971,0.0,0.46581817,80.09909638822899,4.3647757,388.19934,-9.2589426,80.09909638822899,,,,,0.4542055088986784,81.01187108076007,0.4542018636833931,0.4542018636833931
2323,2323,178.7234,10.946791,5.630877,0.0,0,3.9097853,0.0,0.46997336,79.86649589387915,4.3264408,387.90332,-9.2587032,79.86649589387915,,,,,0.45841111546255503,81.02162285706571,0.4584074698084782,0.4584074698084782
2325,2325,178.7238,10.98445,5.6655025,0.0,0,3.8724732,0.0,0.47453991,79.80836079608909,4.2887392,387.57669,-9.2591028,79.80836079608909,,,,,0.46261672202643167,81.03128878430365,0.4626130759374262,0.4626130759374262
2327,2327,178.7242,11.043018,5.7066932,0.0,0,3.8351612,0.0,0.47798359,79.83572588206664,4.2497497,387.25006,-9.258276,79.83572588206664,,,,,0.46682232859030837,81.04087038846986,0.4668186820701684,0.4668186820701684
2329,2329,178.7246,11.103601,5.745049,0.0,0,3.7978492,0.0,0.4824039,79.9008716310964,4.2146115,386.92346,-9.2585373,79.9008716310964,,,,,0.471027935154185,81.05036915498428,0.47102428820663794,0.47102428820663794
2331,2331,178.725,11.14247,5.7793474,0.0,0,3.7605371,0.0,0.48680454,79.84596712785718,4.176065,386.59683,-9.2589617,79.84596712785718,,,,,0.47523354171806165,81.05978653011461,0.47522989434676977,0.47522989434676977
2333,2333,178.7254,11.186238,5.8264933,0.0,0,3.7232251,0.0,0.49077833,79.69780211366285,4.1364617,386.2702,-9.2588396,79.69780211366285,,,,,0.4794391482819383,81.06912392240261,0.4794355004905005,0.4794355004905005
2335,2335,178.7258,11.224271,5.860775,0.0,0,3.6859133,0.0,0.49519962,79.63179453933358,4.0976138,385.94357,-9.2589397,79.63179453933358,,,,,0.48364475484581493,81.07838270387471,0.48364110663776844,0.48364110663776844
2337,2337,178.7262,11.265972,5.894474,0.0,0,3.6486013,0.0,0.49905139,79.59513099763392,4.0566955,385.61697,-9.2588577,79.59513099763392,,,,,0.4878503614096916,81.08756421135958,0.48784671278851344,0.48784671278851344
2339,2339,178.7266,11.339179,5.9406624,0.0,0,3.611289,0.0,0.50301588,79.6535764930422,4.020762,385.29034,-9.2574272,79.6535764930422,,,,,0.49205596797356826,81.09666974767725,0.4920523189426768,0.4920523189426768
2341,2341,178.727,11.39083,5.9702425,0.0,0,3.5743496,0.0,0.50758052,79.72122754979775,3.9812398,384.96371,-9.2577305,79.72122754979775,,,,,0.4962615745374449,81.10570058275566,0.4962579251002014,0.4962579251002014
2343,2343,178.7274,11.403419,6.0071993,0.0,0,3.5387647,0.0,0.51119143,79.44009930959207,3.9462509,384.63708,-9.2593088,79.44009930959207,,,,,0.5004671811013216,81.11465795480196,0.5004635312610316,0.5004635312610316
2345,2345,178.7278,11.444193,6.0546393,0.0,0,3.5032687,0.0,0.51596236,79.24841589791029,3.9066801,384.31046,-9.2598867,79.24841589791029,,,,,0.5046727876651982,81.12354307125477,0.504669137425113,0.504669137425113
2347,2347,178.7282,11.49658,6.0851617,0.0,0,3.4677725,0.0,0.5205394,79.30366685869522,3.8696756,383.98386,-9.2594051,79.30366685869522,,,,,0.5088783942290749,81.13235710989615,0.5088747435923926,0.5088747435923926
2349,2349,178.7286,11.56765,6.1247568,0.0,0,3.4322767,0.0,0.52413684,79.3924742071012,3.8323233,383.65723,-9.2587585,79.3924742071012,,,,,0.5130840007929515,81.14110121972179,0.5130803497628187,0.5130803497628187
2351,2351,178.729,11.629387,6.1699195,0.0,0,3.3967807,0.0,0.52913469,79.35580862665883,3.7942333,383.3306,-9.2580338,79.35580862665883,,,,,0.5172896073568282,81.14977652196706,0.5172859559363409,0.5172859559363409
2353,2353,178.7294,11.655787,6.1964707,0.0,0,3.3612847,0.0,0.53306311,79.26464891719158,3.7563555,383.00397,-9.2578001,79.26464891719158,,,,,0.5214952139207049,81.15838411095366,0.52149156211291,0.52149156211291
2355,2355,178.7298,11.68609,6.2365208,0.0,0,3.3257885,0.0,0.53655785,79.06037561212679,3.7215488,382.67734,-9.2582264,79.06037561212679,,,,,0.5257008204845814,81.1669250548925,0.5256971682924777,0.5256971682924777
2357,2357,178.7302,11.758909,6.2761979,0.0,0,3.2902927,0.0,0.54164273,79.1439111695363,3.6828053,382.35074,-9.2587662,79.1439111695363,,,,,0.5299064270484581,81.17540039684421,0.5299027744749973,0.5299027744749973
2359,2359,178.7306,11.83245,6.3082132,0.0,0,3.2547965,0.0,0.54557782,79.30667164219547,3.6458433,382.02411,-9.2597466,79.30667164219547,,,,,0.5341120336123347,81.18381115539405,0.534108380660423,0.534108380660423
2361,2361,178.731,11.895963,6.3499298,0.0,0,3.2193005,0.0,0.54955572,79.29711439859152,3.6061306,381.69748,-9.2581968,79.29711439859152,,,,,0.5383176401762114,81.19215832539544,0.5383139868487099,0.5383139868487099
2363,2363,178.7314,11.910388,6.3866262,0.0,0,3.1838045,0.0,0.55477369,79.00988536398027,3.5707104,381.37085,-9.2581692,79.00988536398027,,,,,0.5425232467400881,81.200442878829,0.5425195930398142,0.5425195930398142
2365,2365,178.7318,11.956681,6.421792,0.0,0,3.1483085,0.0,0.55846423,78.94811583902673,3.5323145,381.04422,-9.2580223,78.94811583902673,,,,,0.5467288533039647,81.20866576539183,0.5467251992336933,0.5467251992336933
2367,2367,178.7322,12.03016,6.4615889,0.0,0,3.1139498,0.0,0.56262726,79.01323135570156,3.4962683,380.71762,-9.2591782,79.01323135570156,,,,,0.5509344598678414,81.21682791319499,0.5509308054303055,0.5509308054303055
2369,2369,178.7326,12.113177,6.4948969,0.0,0,3.0801783,0.0,0.56759536,79.20444932742114,3.459641,380.39099,-9.2596025,79.20444932742114,,,,,0.555140066431718,81.22493022944504,0.5551364116296097,0.5551364116296097
2371,2371,178.733,12.163353,6.5321393,0.0,0,3.0464103,0.0,0.57107282,79.13500052555653,3.4219244,380.06436,-9.259408,79.13500052555653,,,,,0.5593456729955947,81.23297360107024,0.5593420178315663,0.5593420178315663
2373,2373,178.7334,12.184426,6.5713396,0.0,0,3.0126421,0.0,0.57572538,78.85289233695991,3.386868,379.72769,-9.2594833,78.85289233695991,,,,,0.5635512795594714,81.24095889527443,0.5635476240361362,0.5635476240361362
2375,2375,178.7338,12.246223,6.6033907,0.0,0,2.9788742,0.0,0.58044541,78.90828557091592,3.3493891,379.36096,-9.2586403,78.90828557091592,,,,,0.567756886123348,81.2488869601417,0.5677532302432812,0.5677532302432812
2377,2377,178.7342,12.33418,6.6451159,0.0,0,2.9451063,0.0,0.5841772,79.02323551792274,3.3150725,378.9942,-9.2587814,79.02323551792274,,,,,0.5719624926872247,81.2567586252625,0.5719588364529639,0.5719588364529639
2379,2379,178.7346,12.404664,6.6801925,0.0,0,2.9113381,0.0,0.58905953,79.09279043349224,3.275847,378.62744,-9.2582617,79.09279043349224,,,,,0.5761680992511012,81.26457470213316,0.5761644426651478,0.5761644426651478
2381,2381,178.735,12.4494,6.7132039,0.0,0,2.8775702,0.0,0.5934062,79.0171607332768,3.2387288,378.26068,-9.2593222,79.0171607332768,,,,,0.5803737058149779,81.27233598481808,0.5803700488797974,0.5803700488797974
2383,2383,178.7354,12.492085,6.7575321,0.0,0,2.8438022,0.0,0.59762168,78.80178374850051,3.2053709,377.89392,-9.2599192,78.80178374850051,,,,,0.5845793123788546,81.2800432503523,0.5845756550968774,0.5845756550968774
2385,2385,178.7358,12.539669,6.7882786,0.0,0,2.810034,0.0,0.60240686,78.76332092327064,3.1697748,377.52719,-9.2597122,78.76332092327064,,,,,0.5887849189427312,81.28769725925602,0.5887812613163538,0.5887812613163538
2387,2387,178.7362,12.627095,6.8234129,0.0,0,2.7762663,0.0,0.60639024,78.92276168321807,3.1352639,377.16043,-9.2585487,78.92276168321807,,,,,0.5929905255066079,81.29529875604298,0.592986867538193,0.592986867538193
2389,2389,178.7366,12.709378,6.8682356,0.0,0,2.7424982,0.0,0.61105412,78.93659621393034,3.0992198,376.79367,-9.2568445,78.93659621393034,,,,,0.5971961320704845,81.30284846957997,0.5971924737623622,0.5971924737623622
2391,2391,178.737,12.75417,6.8956151,0.0,0,2.7090681,0.0,0.61583722,78.90798283464456,3.0643892,376.42691,-9.2572355,78.90798283464456,,,,,0.6014017386343612,81.31034711362884,0.6013980799888294,0.6013980799888294
2393,2393,178.7374,12.804595,6.9316206,0.0,0,2.6768675,0.0,0.61943102,78.8148440457293,3.0300057,376.06015,-9.2581291,78.8148440457293,,,,,0.6056073451982379,81.31779538713963,0.6056036862175631,0.6056036862175631
2395,2395,178.7378,12.876282,6.9752169,0.0,0,2.6447473,0.0,0.62469107,78.76276597489175,2.9881859,375.69342,-9.2579927,78.76276597489175,,,,,0.6098129517621145,81.3251939747838,0.6098092924485324,0.6098092924485324
2397,2397,178.7382,12.961167,7.0016804,0.0,0,2.6126273,0.0,0.62893575,78.98053496931466,2.9554577,375.32666,-9.2571936,78.98053496931466,,,,,0.6140185583259912,81.33254354725923,0.6140148986817072,0.6140148986817072
2399,2399,178.7386,13.051438,7.041986,0.0,0,2.580507,0.0,0.63286781,79.06821816240817,2.9183183,374.9599,-9.2577553,79.06821816240817,,,,,0.6182241648898678,81.33984476168345,0.6182205049170579,0.6182205049170579
2401,2401,178.739,13.089659,7.082664,0.0,0,2.5483871,0.0,0.63849717,78.83167418936313,2.8800931,374.59314,-9.2578697,78.83167418936313,,,,,0.6224297714537445,81.34709826197629,0.6224261111545557,0.6224261111545557
2403,2403,178.7394,13.131121,7.112371,0.0,0,2.5162671,0.0,0.64270389,78.73840731975342,2.8458393,374.22638,-9.2586164,78.73840731975342,,,,,0.6266353780176211,81.35430467923531,0.626631717394172,0.626631717394172
2405,2405,178.7398,13.201687,7.153286,0.0,0,2.4841471,0.0,0.64686704,78.68658508160692,2.8092422,373.85965,-9.2577047,78.68658508160692,,,,,0.6308409845814977,81.36146463197888,0.6308373236358789,0.6308373236358789
2407,2407,178.7402,13.293741,7.1870484,0.0,0,2.4520271,0.0,0.65217233,78.8405502267346,2.7726879,373.49289,-9.2582293,78.8405502267346,,,,,0.6350465911453744,81.36857872661474,0.6350429298796493,0.6350429298796493
2409,2409,178.7406,13.367547,7.2158456,0.0,0,2.4199073,0.0,0.65564543,78.93970358065023,2.7379553,373.12613,-9.2577858,78.93970358065023,,,,,0.639252197709251,81.37564755762904,0.6392485361254563,0.6392485361254563
2411,2411,178.741,13.410415,7.2540703,0.0,0,2.3877871,0.0,0.65992856,78.74196146859353,2.7046993,372.75937,-9.2572575,78.74196146859353,,,,,0.6434578042731277,81.38267170798885,0.6434541423732739,0.6434541423732739
2413,2413,178.7414,13.458322,7.2873716,0.0,0,2.3556671,0.0,0.66540438,78.62899269498416,2.6683595,372.39261,-9.2570705,78.62899269498416,,,,,0.6476634108370044,81.38965174938491,0.6476597486230762,0.6476597486230762
2415,2415,178.7418,13.54109,7.3233595,0.0,0,2.3235471,0.0,0.66907924,78.68381738071542,2.6340969,372.02588,-9.257287,78.68381738071542,,,,,0.651869017400881,81.39658824254167,0.6518653548748379,0.6518653548748379
2417,2417,178.7422,13.628839,7.3607736,0.0,0,2.2924592,0.0,0.67399567,78.74503289822147,2.6032104,371.65912,-9.2575693,78.74503289822147,,,,,0.6560746239647577,81.40348173749935,0.6560709611285345,0.6560709611285345
2419,2419,178.7426,13.711004,7.3898487,0.0,0,2.261904,0.0,0.6789251,78.86895875977312,2.5672598,371.29236,-9.2580347,78.86895875977312,,,,,0.6602802305286343,81.41033277390541,0.6602765673841414,0.6602765673841414
2421,2421,178.743,13.762789,7.4291768,0.0,0,2.2313521,0.0,0.68272924,78.69047660151632,2.5332313,370.9256,-9.2581434,78.69047660151632,,,,,0.664485837092511,81.41714188119175,0.6644821736416351,0.6644821736416351
2423,2423,178.7434,13.811892,7.4610267,0.0,0,2.2008002,0.0,0.68758929,78.58402700380151,2.4994743,370.43301,-9.2574883,78.58402700380151,,,,,0.6686914436563877,81.42390957892843,0.668687779900992,0.668687779900992
2425,2425,178.7438,13.900988,7.4882784,0.0,0,2.170248,0.0,0.69177568,78.75747713210771,2.4679391,369.43701,-9.2573681,78.75747713210771,,,,,0.6728970502202642,81.43063637702858,0.6728933861621892,0.6728933861621892
2427,2427,178.7442,13.983185,7.5277472,0.0,0,2.1396961,0.0,0.69559783,78.73729949244105,2.4350131,368.44104,-9.2569084,78.73729949244105,,,,,0.6771026567841409,81.43732277599554,0.6770989924252042,0.6770989924252042
2429,2429,178.7446,14.054851,7.5552907,0.0,0,2.109144,0.0,0.70050925,78.79999760600312,2.3985147,367.44507,-9.2579308,78.79999760600312,,,,,0.6813082633480175,81.44396926712022,0.6813045986900149,0.6813045986900149
2431,2431,178.745,14.113359,7.5874715,0.0,0,2.0785921,0.0,0.70445031,78.72810553265079,2.3673847,366.4491,-9.257987,78.72810553265079,,,,,0.6855138699118942,81.45057633275555,0.6855102049565996,0.6855102049565996
2433,2433,178.7454,14.183224,7.6293449,0.0,0,2.0480402,0.0,0.7092092,78.59481757413643,2.3350518,365.45313,-9.2586479,78.59481757413643,,,,,0.6897194764757709,81.45714444648057,0.6897158112249371,0.6897158112249371
2435,2435,178.7458,14.25666,7.6543608,0.0,0,2.0174882,0.0,0.71426123,78.68764720946533,2.3026195,364.45715,-9.2572832,78.68764720946533,,,,,0.6939250830396475,81.46367407336409,0.6939214174950061,0.6939214174950061
2437,2437,178.7462,14.357068,7.6876454,0.0,0,1.986936,0.0,0.71776742,78.82092085856644,2.2689052,363.46118,-9.2575693,78.82092085856644,,,,,0.6981306896035242,81.47016567015658,0.6981270237667865,0.6981270237667865
2439,2439,178.7466,14.430157,7.72579,0.0,0,1.9563839,0.0,0.72274649,78.73729980846176,2.2357841,362.46521,-9.2574463,78.73729980846176,,,,,0.7023362961674008,81.47661968545613,0.7023326300402578,0.7023326300402578
2441,2441,178.747,14.482532,7.7483296,0.0,0,1.9261371,0.0,0.72726065,78.73549735028482,2.2042632,361.46924,-9.2577925,78.73549735028482,,,,,0.7065419027312775,81.48303655991894,0.7065382363154005,0.7065382363154005
2443,2443,178.7474,14.537132,7.7818046,0.0,0,1.8970003,0.0,0.73053223,78.60357896486396,2.1737745,360.47327,-9.2574463,78.60357896486396,,,,,0.7107475092951542,81.48941672646242,0.7107438425921948,0.7107438425921948
2445,2445,178.7478,14.611658,7.8190002,0.0,0,1.8679363,0.0,0.73598528,78.52764338274781,2.1408441,359.47729,-9.2574749,78.52764338274781,,,,,0.7149531158590308,81.49576061043436,0.7149494488706215,0.7149494488706215
2447,2447,178.7482,14.703915,7.8422256,0.0,0,1.8388723,0.0,0.74006838,78.72251181963844,2.1086798,358.48129,-9.2568007,78.72251181963844,,,,,0.7191587224229075,81.50206862977797,0.7191550551506622,0.7191550551506622
2449,2449,178.7486,14.787512,7.8771296,0.0,0,1.8098083,0.0,0.74370897,78.71518748051278,2.0817342,357.48532,-9.2566566,78.71518748051278,,,,,0.723364328986784,81.50834119522298,0.723360661432298,0.723360661432298
2451,2451,178.749,14.851816,7.9077487,0.0,0,1.7807442,0.0,0.74909306,78.65666177513305,2.0476432,356.48935,-9.2571783,78.65666177513305,,,,,0.7275699355506607,81.51457871042868,0.7275662677155111,0.7275662677155111
2453,2453,178.7494,14.913383,7.9328542,0.0,0,1.7516803,0.0,0.75254321,78.65269139904919,2.0181384,355.49338,-9.2572165,78.65269139904919,,,,,0.7317755421145374,81.52078157215723,0.7317718740002834,0.7317718740002834
2455,2455,178.7498,14.992713,7.9684691,0.0,0,1.7226163,0.0,0.75652188,78.6003510325928,1.9915457,354.49741,-9.2574453,78.6003510325928,,,,,0.735981148678414,81.5269501704624,0.7359774802865974,0.7359774802865974
2457,2457,178.7502,15.10831,7.9964318,0.0,0,1.6935523,0.0,0.76189953,78.83390712137542,1.9608788,353.50143,-9.2575693,78.83390712137542,,,,,0.7401867552422907,81.53308488875967,0.7401830865744359,0.7401830865744359
2459,2459,178.7506,15.194688,8.0260639,0.0,0,1.6644882,0.0,0.76539797,78.88762395455971,1.932878,352.50546,-9.2564793,78.88762395455971,,,,,0.7443923618061673,81.53918610406889,0.7443886928637818,0.7443886928637818
2461,2461,178.751,15.254029,8.0607319,0.0,0,1.6354243,0.0,0.77004832,78.72938723205621,1.901464,351.50949,-9.256568,78.72938723205621,,,,,0.748597968370044,81.54525418710065,0.7485942991546186,0.7485942991546186
2463,2463,178.7514,15.314003,8.0862904,0.0,0,1.6063603,0.0,0.77505481,78.69375439092777,1.8701522,350.51352,-9.2568722,78.69375439092777,,,,,0.7528035749339207,81.55128950239444,0.7527999054469299,0.7527999054469299
2465,2465,178.7518,15.402235,8.118187,0.0,0,1.5772963,0.0,0.77816081,78.71386368684479,1.8423473,349.51755,-9.2567015,78.71386368684479,,,,,0.7570091814977973,81.55729240849305,0.7570055117406994,0.7570055117406994
2467,2467,178.7522,15.517645,8.1457586,0.0,0,1.5491643,0.0,0.78266013,78.92629807122931,1.811937,348.52158,-9.2571974,78.92629807122931,,,,,0.761214788061674,81.56326325802188,0.7612111180359113,0.7612111180359113
2469,2469,178.7526,15.600574,8.1702213,0.0,0,1.5215131,0.0,0.78715807,79.0114574416416,1.7854003,347.5256,-9.2572536,79.0114574416416,,,,,0.7654203946255506,81.56920239788532,0.76541672433255,0.76541672433255
2471,2471,178.753,15.657546,8.209507,0.0,0,1.4938651,0.0,0.79122823,78.75735867322562,1.7514683,346.5296,-9.2569418,78.75735867322562,,,,,0.7696260011894273,81.57511016933064,0.7696223306306003,0.7696223306306003
2473,2473,178.7534,15.738964,8.2361765,0.0,0,1.4662172,0.0,0.79631722,78.7965629808256,1.724535,345.62604,-9.2564669,78.7965629808256,,,,,0.773831607753304,81.58098690809155,0.7738279369300468,0.7738279369300468
2475,2475,178.7538,15.851192,8.2604389,0.0,0,1.4385692,0.0,0.80002815,79.01909909139627,1.6938174,345.24597,-9.2558203,79.01909909139627,,,,,0.7780372143171805,81.58683294452256,0.7780335432308748,0.7780335432308748
2477,2477,178.7542,15.970768,8.2980661,0.0,0,1.4109212,0.0,0.80400634,79.08493060998684,1.6663651,344.86591,-9.2565947,79.08493060998684,,,,,0.7822428208810572,81.59264860365758,0.7822391495330697,0.7822391495330697
2479,2479,178.7546,16.057251,8.3177948,0.0,0,1.3832732,0.0,0.80876499,79.23362774528468,1.637551,344.48584,-9.2576914,79.23362774528468,,,,,0.7864484274449338,81.598434205427,0.786444755836617,0.786444755836617
2481,2481,178.755,16.113394,8.3463593,0.0,0,1.3556252,0.0,0.81241703,79.10446405132912,1.6079895,344.10577,-9.2580061,79.10446405132912,,,,,0.7906540340088105,81.60419006467335,0.7906503621415026,0.7906503621415026
2483,2483,178.7554,16.204353,8.3848248,0.0,0,1.3279773,0.0,0.81736976,79.00087237409876,1.5813016,343.72571,-9.2569857,79.00087237409876,,,,,0.7948596405726872,81.60991649127276,0.7948559684477128,0.7948559684477128
2485,2485,178.7558,16.31566,8.4041672,0.0,0,1.3003292,0.0,0.82201421,79.26497100395608,1.5491769,343.34564,-9.2550955,79.26497100395608,,,,,0.7990652471365638,81.61561379028012,0.7990615747552333,0.7990615747552333
2487,2487,178.7562,16.443243,8.4362946,0.0,0,1.2726812,0.0,0.82553661,79.41847248892863,1.5199641,342.96558,-9.2543964,79.41847248892863,,,,,0.8032708537004405,81.62128226197878,0.803267181064051,0.803267181064051
2489,2489,178.7566,16.524258,8.4710827,0.0,0,1.2450333,0.0,0.83101493,79.30228831264552,1.4903696,342.58551,-9.256382,79.30228831264552,,,,,0.8074764602643172,81.62692220204839,0.8074727873741526,0.8074727873741526
2491,2491,178.757,16.604446,8.4892282,0.0,0,1.2176626,0.0,0.83509362,79.42112053350623,1.4600768,342.20544,-9.2570658,79.42112053350623,,,,,0.8116820668281938,81.63253390156062,0.8116783936855249,0.8116783936855249
2493,2493,178.7574,16.677507,8.5211105,0.0,0,1.1913005,0.0,0.8382681,79.30112043278928,1.4352988,341.82538,-9.257452,79.30112043278928,,,,,0.8158876733920705,81.63811764714636,0.815883999998155,0.815883999998155
2495,2495,178.7578,16.812313,8.5510979,0.0,0,1.1650044,0.0,0.84404105,79.49695875935367,1.4076637,341.44531,-9.2563124,79.49695875935367,,,,,0.820093279955947,81.64367372109793,0.8200896063120301,0.8200896063120301
2497,2497,178.7582,16.946678,8.5739422,0.0,0,1.1387082,0.0,0.84763145,79.79044916047853,1.3802602,341.06525,-9.2550793,79.79044916047853,,,,,0.8242988865198237,81.64920240139223,0.824295212627138,0.824295212627138
2499,2499,178.7586,17.041187,8.6070023,0.0,0,1.1124123,0.0,0.85156566,79.73790764663586,1.3498297,340.68518,-9.2555885,79.73790764663586,,,,,0.8285044930837004,81.6547039618307,0.828500818943466,0.828500818943466
2501,2501,178.759,17.119257,8.6355457,0.0,0,1.0861163,0.0,0.85753506,79.6716596168004,1.3235327,340.30511,-9.2561064,79.6716596168004,,,,,0.832710099647577,81.66017867210549,0.8327064252610022,0.8327064252610022
2503,2503,178.7594,17.223999,8.6603117,0.0,0,1.0598202,0.0,0.86082685,79.78236956654665,1.2959206,339.92505,-9.2559166,79.78236956654665,,,,,0.8369157062114537,81.66562679786995,0.8369120315797348,0.8369120315797348
2505,2505,178.7598,17.355461,8.6901093,0.0,0,1.0335243,0.0,0.86508709,79.93452619493132,1.2673277,339.54498,-9.2556171,79.93452619493132,,,,,0.8411213127753303,81.67104860083197,0.8411176378996515,0.8411176378996515
2507,2507,178.7602,17.485247,8.7121325,0.0,0,1.0072283,0.0,0.87009805,80.19213708911926,1.2381459,339.16492,-9.2547331,80.19213708911926,,,,,0.845326919339207,81.67644433884506,0.8453232442207412,0.8453232442207412
2509,2509,178.7606,17.570072,8.7450428,0.0,0,0.98093224,0.0,0.87346673,80.07037252555972,1.2103826,338.78485,-9.2556477,80.07037252555972,,,,,0.8495325259030837,81.68181426596114,0.8495288505429924,0.8495288505429924
2511,2511,178.761,17.65395,8.7746286,0.0,0,0.95463622,0.0,0.87867761,79.99120279228981,1.1779625,338.40479,-9.255167,79.99120279228981,,,,,0.8537381324669603,81.68715863252326,0.8537344568663935,0.8537344568663935
2513,2513,178.7614,17.772833,8.7959976,0.0,0,0.92834032,0.0,0.88351965,80.19433770922403,1.1550606,338.02472,-9.2561436,80.19433770922403,,,,,0.857943739030837,81.6924776851889,0.8579400631909337,0.8579400631909337
2515,2515,178.7618,17.895388,8.8303614,0.0,0,0.9020443,0.0,0.88710964,80.20400426731972,1.1255394,337.64465,-9.2549534,80.20400426731972,,,,,0.8621493455947136,81.697771667079,0.862145669516602,0.862145669516602
2517,2517,178.7622,18.023222,8.8540812,0.0,0,0.87659597,0.0,0.89213485,80.39920086438795,1.0957106,337.26459,-9.2541494,80.39920086438795,,,,,0.8663549521585903,81.70304081781688,0.8663512758433877,0.8663512758433877
2519,2519,178.7626,18.12385,8.8749924,0.0,0,0.85158527,0.0,0.89591515,80.51320889576476,1.0699338,336.88452,-9.2542887,80.51320889576476,,,,,0.870560558722467,81.70828537354835,0.87055688217128,0.87055688217128
2521,2521,178.763,18.219595,8.9104633,0.0,0,0.82657719,0.0,0.8997708,80.36747011940714,1.0441083,336.50446,-9.2553711,80.36747011940714,,,,,0.8747661652863435,81.71350556708005,0.8747624885002685,0.8747624885002685
2523,2523,178.7634,18.352518,8.9313555,0.0,0,0.80156928,0.0,0.90497416,80.61496769360483,1.016086,336.1991,-9.2558556,80.61496769360483,,,,,0.8789717718502202,81.71870162788653,0.8789680948303429,0.8789680948303429
2525,2525,178.7638,18.475046,8.9581289,0.0,0,0.77656126,0.0,0.90885067,80.71605137427012,0.98740166,336.56604,-9.255147,80.71605137427012,,,,,0.8831773784140968,81.72387378218296,0.8831737011614929,0.8831737011614929
2527,2527,178.7642,18.610804,8.9957876,0.0,0,0.75155324,0.0,0.91411197,80.68976059314747,0.96143979,336.93295,-9.2538452,80.68976059314747,,,,,0.8873829849779735,81.72902225305583,0.8873793074937086,0.8873793074937086
2529,2529,178.7646,18.720736,9.012804,0.0,0,0.72654527,0.0,0.91901976,80.88483639880143,0.933411,337.29987,-9.2548094,80.88483639880143,,,,,0.8915885915418502,81.73414726041128,0.8915849138269801,0.8915849138269801
2531,2531,178.765,18.823694,9.0390444,0.0,0,0.70153725,0.0,0.92203575,80.89310627959314,0.90711313,337.66681,-9.2555447,80.89310627959314,,,,,0.8957941981057268,81.7392490210968,0.8957905201612976,0.8957905201612976
2533,2533,178.7654,18.945206,9.0715914,0.0,0,0.67652929,0.0,0.92724216,80.87027816087077,0.88231903,338.03372,-9.2550802,80.87027816087077,,,,,0.8999998046696035,81.74432774895877,0.8999961264966515,0.8999961264966515
2535,2535,178.7658,19.084345,9.0864029,0.0,0,0.65152127,0.0,0.93129146,81.2143570727958,0.854141,338.40067,-9.2550259,81.2143570727958,,,,,0.9042054112334801,81.74938365490897,0.9042017328330323,0.9042017328330323
2537,2537,178.7662,19.23509,9.1152716,0.0,0,0.62651324,0.0,0.9344517,81.3650119348309,0.83010954,338.76758,-9.2555189,81.3650119348309,,,,,0.9084110177973568,81.75441694692626,0.9084073391704306,0.9084073391704306
2539,2539,178.7666,19.350483,9.1468267,0.0,0,0.60150528,0.0,0.94072354,81.31336418915937,0.80337971,339.13449,-9.2554331,81.31336418915937,,,,,0.9126166243612335,81.75942783014081,0.9126129455088373,0.9126129455088373
2541,2541,178.767,19.456026,9.1675463,0.0,0,0.57674497,0.0,0.94484454,81.40050817895234,0.77532494,339.50143,-9.2545633,81.40050817895234,,,,,0.9168222309251101,81.76441650690575,0.9168185518482431,0.9168185518482431
2543,2543,178.7674,19.584236,9.2003336,0.0,0,0.55288589,0.0,0.94880748,81.36926478258172,0.74858809,339.86835,-9.255312,81.36926478258172,,,,,0.9210278374889868,81.76938317682425,0.9210241581886391,0.9210241581886391
2545,2545,178.7678,19.713629,9.2244978,0.0,0,0.52908581,0.0,0.95467269,81.48573655426101,0.72514611,340.23526,-9.25564,81.48573655426101,,,,,0.9252334440528633,81.77432803679955,0.9252297645300166,0.9252297645300166
2547,2547,178.7682,19.863016,9.244648,0.0,0,0.5052858,0.0,0.95779908,81.74937613966267,0.69635284,340.6022,-9.2548828,81.74937613966267,,,,,0.92943905061674,81.77925128111126,0.9294353708723666,0.9294353708723666
2549,2549,178.7686,19.974628,9.2733183,0.0,0,0.48148578,0.0,0.96181393,81.70242823494311,0.66991347,340.96912,-9.2539654,81.70242823494311,,,,,0.9336446571806167,81.7841531013886,0.9336409772156807,0.9336409772156807
2551,2551,178.769,20.096024,9.295228,0.0,0,0.4576858,0.0,0.9673636,81.80970042585581,0.64807636,341.33603,-9.2540064,81.80970042585581,,,,,0.9378502637444933,81.78903368674712,0.9378465835599502,0.9378465835599502
2553,2553,178.7694,20.231371,9.3216839,0.0,0,0.43388578,0.0,0.9705857,81.88746702242582,0.62046212,341.70297,-9.2546892,81.88746702242582,,,,,0.94205587030837,81.79389322380092,0.9420521899051668,0.9420521899051668
2555,2555,178.7698,20.391554,9.3503323,0.0,0,0.4100858,0.0,0.9754675,82.01930834965843,0.59589362,342.06989,-9.2549219,82.01930834965843,,,,,0.9462614768722466,81.79873189666343,0.9462577962513222,0.9462577962513222
2557,2557,178.7702,20.545828,9.370471,0.0,0,0.38628578,0.0,0.98073888,82.2739959476664,0.56783175,342.4368,-9.2542219,82.2739959476664,,,,,0.9504670834361233,81.80354988705834,0.9504634025984082,0.9504634025984082
2559,2559,178.7706,20.65016,9.4011917,0.0,0,0.36248577,0.0,0.98415291,82.13087662720974,0.5449965,342.80374,-9.2531948,82.13087662720974,,,,,0.95467269,81.80834737432221,0.9546690089464169,0.9546690089464169