File: examples/hot axisymmetric compression example/data/02 screened data/testID_0140.csv
Time(sec),Force(kN),Jaw(mm),PowAngle(deg),Power(W),Pram,PTemp,Strain,Stress(MPa),Stroke(mm),TC1(C),wedge(mm)
0.0,0.86715209,0.24900196,0.0,0,11.076097,0.0015211719,0.01677762,10.855685,11.075704,27.299162,-9.119729
1.2,0.81161422,0.0013339808,0.0,0,11.076097,3.5159132,7.3827505e-05,10.33483,11.075376,27.300795,-9.4873524
2.4,0.78657269,0.001193993,0.0,0,11.076097,7.1159139,0.00011069176,10.010067,11.076336,27.3211,-9.4849024
3.6,0.77157253,0.0015646095,0.0,0,11.076097,10.715914,9.9475954e-05,9.8363132,11.076427,27.244659,-9.4834566
4.8,0.75017786,0.0011428164,0.0,0,11.076097,14.315914,0.00010248622,9.5463419,11.076061,27.195913,-9.4810381
6.0,0.74043983,0.0015946284,0.0,0,11.076097,17.915913,0.00011321737,9.4320374,11.076093,27.223562,-9.4790888
7.2,0.7269783,0.0013243459,0.0,0,11.076097,21.515913,0.00011665719,9.2575417,11.075766,27.095787,-9.476613
8.4,0.71770787,0.0015039851,0.0,0,11.076097,25.115913,0.00011334076,9.1386862,11.077464,27.059769,-9.4749098
9.6,0.71419901,0.0014498129,7.889555,0,11.076097,28.715914,0.00011162391,9.1010141,11.076367,27.007914,-9.4728184
10.8,0.71451443,0.0019279077,27.426605,0,11.076097,32.315914,0.00015183374,9.1038752,11.075955,27.338137,-9.4708014
12.0,0.72072411,0.00060047983,37.03149,0,11.076097,35.915913,5.4725395e-05,9.1796083,11.075738,28.913773,-9.4690742
13.2,0.73306578,-0.0020376558,42.389561,0,11.076097,39.515911,-0.0001284145,9.3509808,11.075793,31.905041,-9.4665089
14.4,0.74053919,-0.0057957349,45.548592,0,11.076097,43.115906,-0.00037046862,9.4312553,11.0762,36.165173,-9.4646168
15.6,0.75405908,-0.0093223937,46.896904,0,11.076097,46.715904,-0.00061244244,9.6171455,11.075142,41.221214,-9.4626417
16.8,0.75998539,-0.013266482,47.05444,0,11.076097,50.315907,-0.00088176801,9.6832981,11.076425,46.85112,-9.4607401
18.0,0.76236719,-0.016921664,46.264793,0,11.076097,53.915905,-0.0011125534,9.7242546,11.075783,52.256817,-9.4586115
19.2,0.77165979,-0.019707413,45.615238,0,11.076097,57.515907,-0.0013128442,9.8370647,11.075909,57.068989,-9.4563437
20.4,0.78103501,-0.023255974,44.607582,0,11.076097,61.11591,-0.0015395362,9.9534941,11.075982,61.521942,-9.454361
21.6,0.78099144,-0.025902161,43.936516,0,11.076097,64.715927,-0.0017270852,9.9448309,11.07691,65.605904,-9.452342
22.8,0.77312732,-0.027680891,43.500465,0,11.076097,68.315918,-0.0018400219,9.8670206,11.075893,69.261765,-9.4503021
24.0,0.77982122,-0.029437361,42.978844,0,11.076097,71.915924,-0.0019598003,9.9250908,11.075471,72.629379,-9.4483557
25.2,0.77505916,-0.031739946,43.527351,0,11.076097,75.515923,-0.0020994348,9.896759,11.075871,75.738632,-9.4461012
26.4,0.77799588,-0.034209516,44.076969,0,11.076097,79.115921,-0.0022744541,9.9342508,11.075916,78.840103,-9.4443455
27.6,0.77474558,-0.036530674,44.616024,0,11.076097,82.715927,-0.002427659,9.890172,11.075776,81.980789,-9.4418669
28.8,0.78416842,-0.039291386,45.615219,0,11.076097,86.315933,-0.0026085887,10.003641,11.076191,85.21447,-9.4406452
30.0,0.78747106,-0.042813379,46.109619,0,11.076097,89.915909,-0.0028314944,10.054154,11.076553,88.719986,-9.4383116
31.2,0.79488325,-0.044742402,46.582027,0,11.076097,93.515915,-0.0029899243,10.147603,11.076963,92.440369,-9.4364481
32.4,0.7873565,-0.047376081,46.652981,0,11.076097,97.115913,-0.0031390835,10.057554,11.075976,96.310204,-9.4339046
33.6,0.79236424,-0.050399624,47.05444,0,11.076097,100.71593,-0.0033480243,10.130364,11.075218,100.01705,-9.4315042
34.8,0.79828346,-0.053212296,47.05444,0,11.076097,104.3159,-0.0035262296,10.195346,11.076272,103.77627,-9.4297609
36.0,0.7945857,-0.056578159,47.083935,0,11.076097,107.91591,-0.0037525834,10.15737,11.07603,107.49899,-9.4279461
37.2,0.80714113,-0.059969805,47.504883,0,11.076097,111.51591,-0.0039718184,10.309977,11.075912,111.12394,-9.425971
38.4,0.80699599,-0.061738752,47.504883,0,11.076097,115.1159,-0.0040886747,10.318349,11.075462,114.71494,-9.4236393
39.6,0.81383079,-0.064446263,47.954857,0,11.076097,118.7159,-0.0042797811,10.416454,11.076586,118.18979,-9.4220457
40.8,0.81782508,-0.067325085,47.955318,0,11.076097,122.3159,-0.0044538509,10.471352,11.076314,121.74351,-9.4197063
42.0,0.82004529,-0.070387907,48.383785,0,11.076097,125.91591,-0.0046727001,10.485056,11.076645,125.35538,-9.4175825
43.2,0.83466238,-0.074778177,48.729443,0,11.076097,129.51604,-0.0049412115,10.688107,11.07608,128.87146,-9.4159813
44.4,0.83471942,-0.076198682,48.812252,0,11.076097,133.11589,-0.00507305,10.680305,11.07647,132.47948,-9.414135
45.6,0.83285213,-0.07927198,49.224781,0,11.076097,136.71591,-0.0052278447,10.672059,11.075974,136.10689,-9.4119692
46.8,0.83343464,-0.082175471,49.229733,0,11.076097,140.3159,-0.005470206,10.675327,11.075973,139.85692,-9.4098263
48.0,0.84083605,-0.085200988,49.229733,0,11.076097,143.91591,-0.0056242468,10.773629,11.075779,143.5377,-9.4075804
49.2,0.83075941,-0.087884821,49.229885,0,11.076097,147.5159,-0.0058533899,10.643712,11.075552,147.20793,-9.4054985
50.4,0.84852767,-0.09163627,49.635284,0,11.076097,151.11592,-0.0060524493,10.883478,11.076585,150.74477,-9.4038725
51.6,0.85860592,-0.094866507,49.636227,0,11.076097,154.71591,-0.0063319644,11.007088,11.076861,154.28896,-9.4021597
52.8,0.8590731,-0.097173125,50.042721,0,11.076097,158.3159,-0.0064255898,11.013346,11.075771,157.68936,-9.4001026
54.0,0.86373621,-0.099679209,50.438229,0,11.076097,161.91591,-0.0066557289,11.0779,11.076345,161.20059,-9.3980446
55.2,0.86119634,-0.10284813,50.822601,0,11.076097,165.51591,-0.0068151848,11.023917,11.075773,164.73999,-9.3959599
56.4,0.86921602,-0.10576298,50.956985,0,11.076097,169.11592,-0.0070506819,11.144314,11.07666,168.34738,-9.394001
57.6,0.87260395,-0.10918123,51.196285,0,11.076097,172.71593,-0.0072531938,11.193109,11.07516,172.0634,-9.3922815
58.8,0.8714689,-0.11192299,51.56797,0,11.076097,176.31592,-0.0074522481,11.181772,11.075616,175.65765,-9.3899298
60.0,0.87557751,-0.11535612,51.56982,0,11.076097,179.91591,-0.0076633417,11.226208,11.075476,179.32974,-9.3879185
61.2,0.87465185,-0.11824206,51.774666,0,11.076097,183.51591,-0.0078760851,11.229876,11.076506,182.99562,-9.3858576
62.4,0.88293141,-0.1212579,51.932369,0,11.076097,187.11592,-0.0080602812,11.339476,11.077782,186.61118,-9.3841591
63.6,0.88466585,-0.12453964,52.256851,0,11.076097,190.71591,-0.0082860598,11.343648,11.075153,190.03082,-9.3823814
64.8,0.88950199,-0.12862132,52.340626,0,11.076097,194.31592,-0.0085428692,11.424208,11.076032,193.64996,-9.3801489
66.0,0.90473223,-0.13182396,52.635494,0,11.076097,197.91591,-0.0087615391,11.615822,11.075809,197.26564,-9.3784952
67.2,0.90585643,-0.13435388,52.821785,0,11.076097,201.51591,-0.0089134611,11.632545,11.075989,200.88286,-9.3763332
68.4,0.90455204,-0.13739944,52.97607,0,11.076097,205.11592,-0.009122137,11.633194,11.076381,204.55125,-9.374402
69.6,0.90545779,-0.14051387,53.168087,0,11.076097,208.71591,-0.0093194731,11.651335,11.075703,208.19447,-9.3718138
70.8,0.9107492,-0.14378518,53.316647,0,11.076097,212.31592,-0.0095252236,11.714911,11.075308,211.88306,-9.3697615
72.0,0.90932357,-0.14726743,53.31665,0,11.076097,215.91591,-0.0097561218,11.694285,11.075506,215.40047,-9.3678284
73.2,0.91096497,-0.15086,53.316662,0,11.076097,219.5159,-0.0099793207,11.721365,11.076163,219.21251,-9.3658819
74.4,0.91611624,-0.1539212,53.316654,0,11.076097,223.11589,-0.010221792,11.788365,11.075961,223.01659,-9.3641911
75.6,0.92182845,-0.15770012,53.316654,0,11.076097,226.71591,-0.010426865,11.871257,11.075848,226.702,-9.3628578
76.8,0.91724724,-0.16061285,53.316654,0,11.076097,230.31589,-0.010668944,11.80913,11.076046,230.35979,-9.3604965
78.0,0.92713529,-0.16397175,53.316654,0,11.076097,233.91589,-0.01083875,11.949767,11.076571,233.9182,-9.358696
79.2,0.93397892,-0.16690734,53.318207,0,11.076097,237.5159,-0.011095411,12.019979,11.07561,237.35046,-9.3565826
80.4,0.93828207,-0.17080794,53.656994,0,11.076097,241.11589,-0.011301322,12.069949,11.076231,240.74774,-9.3545599
81.6,0.93909973,-0.1747763,53.866753,0,11.076097,244.7159,-0.011605132,12.089357,11.076203,244.24759,-9.3522396
82.8,0.9442389,-0.1783811,54.061104,0,11.076097,248.3159,-0.011826512,12.172699,11.0764,247.68849,-9.3504286
84.0,0.94909483,-0.18093233,54.305416,0,11.076097,251.91589,-0.012015291,12.240244,11.07587,251.19804,-9.3484278
85.2,0.94838977,-0.18365161,54.593544,0,11.076097,255.5159,-0.012180259,12.230132,11.075225,254.82951,-9.3465481
86.4,0.94164312,-0.18703586,54.624023,0,11.076097,259.11618,-0.012409331,12.135885,11.076603,258.49637,-9.3444824
87.6,0.95369321,-0.19057864,54.923355,0,11.076097,262.71591,-0.012626703,12.30317,11.076341,262.12936,-9.3427744
88.8,0.94832653,-0.19460796,54.931637,0,11.076097,266.31589,-0.012884722,12.225039,11.077205,265.98428,-9.3406687
90.0,0.95110577,-0.19811976,54.628185,0,11.076097,269.91592,-0.013103179,12.273141,11.075658,269.85406,-9.3385973
91.2,0.94821876,-0.20165737,54.624027,0,11.076097,273.5159,-0.013340877,12.232589,11.076252,273.59171,-9.3367958
92.4,0.95046967,-0.20505886,54.624023,0,11.076097,277.11591,-0.013565224,12.263369,11.075955,277.20963,-9.3350754
93.6,0.95731777,-0.20845531,54.624023,0,11.076097,280.71591,-0.013773717,12.359453,11.075353,280.66638,-9.3330822
94.8,0.94813287,-0.21189609,54.92683,0,11.076097,284.31592,-0.014047839,12.241648,11.075649,284.0282,-9.3305702
96.0,0.95652014,-0.21542165,55.239243,0,11.076097,287.91592,-0.014226474,12.351385,11.075945,287.21234,-9.3285189
97.2,0.95712447,-0.21868905,55.24707,0,11.076097,291.51593,-0.014502355,12.36578,11.075936,290.88904,-9.3263426
98.4,0.961658,-0.22218294,55.535885,0,11.076097,295.11594,-0.014691805,12.427531,11.075622,294.45184,-9.3243923
99.6,0.96343184,-0.22519498,55.835487,0,11.076097,298.71591,-0.01492616,12.450487,11.075932,298.06934,-9.3227558
100.8,0.96488971,-0.22896792,55.843506,0,11.076097,302.31592,-0.015157619,12.468655,11.076512,301.66983,-9.3212357
102.0,0.96600866,-0.23281127,56.125378,0,11.076097,305.91592,-0.015410949,12.510236,11.076032,305.30142,-9.3192682
103.2,0.9626559,-0.23640139,56.129147,0,11.076097,309.5159,-0.015625462,12.453072,11.077065,308.90164,-9.316968
104.4,0.96894789,-0.24033359,56.425777,0,11.076097,313.11594,-0.015883682,12.535119,11.076998,312.39041,-9.3153429
105.6,0.96538132,-0.2442811,56.685127,0,11.076097,316.71591,-0.016147055,12.49787,11.076489,316.07315,-9.3132668
106.8,0.96753961,-0.24845785,56.609695,0,11.076097,320.31589,-0.01638424,12.530695,11.076447,319.93414,-9.3106298
108.0,0.97356009,-0.25217614,56.665516,0,11.076097,323.91589,-0.016692828,12.612943,11.075257,323.69196,-9.3090219
109.2,0.9712798,-0.25607663,56.578667,0,11.076097,327.5159,-0.016912337,12.586368,11.076419,327.43253,-9.3070221
110.4,0.97507924,-0.25947759,56.42984,0,11.076097,331.11591,-0.017180435,12.633823,11.077082,331.17093,-9.3045521
111.6,0.97795188,-0.26300576,56.426094,0,11.076097,334.71591,-0.017387379,12.685414,11.075704,334.75278,-9.3028698
112.8,0.9755246,-0.26631436,56.71093,0,11.076097,338.31589,-0.017608259,12.647977,11.075855,338.15378,-9.3010035
114.0,0.97607952,-0.26988238,56.836075,0,11.076097,341.91589,-0.017825618,12.671863,11.075909,341.53302,-9.2993088
115.2,0.98136193,-0.27398005,56.986084,0,11.076097,345.5159,-0.018089248,12.730417,11.07635,345.00806,-9.2975054
116.4,0.98467213,-0.27721223,57.164413,0,11.076097,349.11591,-0.018298315,12.763588,11.07685,348.62958,-9.295598
117.6,0.98835081,-0.28110945,57.260738,0,11.076097,352.71591,-0.018530257,12.811582,11.075802,352.18423,-9.2934837
118.8,0.98368138,-0.28490859,57.535397,0,11.076097,356.31589,-0.018832523,12.760114,11.076359,355.70407,-9.2908449
120.0,0.98519504,-0.28880715,57.535397,0,11.076097,359.91431,-0.019049279,12.793811,11.076615,359.39142,-9.2885571
121.2,0.057635929,-0.30420345,55.751007,0,11.076097,359.99924,-0.020100925,0.74642318,11.076171,362.21921,-9.288909
122.4,0.037458502,-0.30413026,54.305901,0,11.076097,359.99924,-0.020072443,0.49858895,11.076546,363.25592,-9.2890902
123.6,0.032542739,-0.30284107,53.65723,0,11.076097,359.99924,-0.019999173,0.41560629,11.076001,362.91699,-9.2891617
124.8,0.027356014,-0.30172119,53.657223,0,11.076097,359.99924,-0.019910848,0.36032671,11.075458,361.5972,-9.2889538
126.0,0.024751283,-0.30046621,54.622562,0,11.076097,359.99924,-0.019822277,0.33454549,11.076017,359.90475,-9.2890902
127.2,0.022275561,-0.29949701,56.072227,0,11.076097,359.99924,-0.019761615,0.28882059,11.075179,357.99606,-9.2890453
128.4,0.018948358,-0.29903218,57.535034,0,11.076097,359.99924,-0.019706048,0.26461869,11.075554,356.4621,-9.2890911
129.6,0.017088918,-0.29839733,59.299442,0,11.076097,359.99924,-0.019723509,0.21618019,11.076091,355.28247,-9.2884874
130.8,0.02295739,-0.29867631,60.556328,0,11.076097,359.99924,-0.019696476,0.30208585,11.07625,354.74625,-9.2886496
132.0,0.035811175,-0.29882896,61.688145,0,11.076097,359.99924,-0.01976254,0.46255618,11.075823,354.78778,-9.2887592
133.2,0.051963124,-0.29993069,62.336418,0,11.076097,359.99924,-0.01980887,0.67053151,11.075888,355.61404,-9.2886276
134.4,0.050401006,-0.30180672,62.373703,0,11.076097,359.99924,-0.019935185,0.67579657,11.075984,357.17145,-9.288599
135.6,0.055710301,-0.30359927,61.930447,0,11.076097,359.99924,-0.020019816,0.72953582,11.076561,359.1185,-9.2885532
136.8,0.056963682,-0.30527014,61.135391,0,11.076097,359.99924,-0.020118549,0.74397963,11.076318,360.91422,-9.2887478
138.0,0.061736923,-0.30629864,60.085045,0,11.076097,359.99924,-0.02022505,0.80557442,11.075887,362.44388,-9.2889376
139.2,0.058936752,-0.30733159,58.719852,0,11.076097,359.99924,-0.02025081,0.77197278,11.075064,363.64975,-9.2880201
140.4,0.065207787,-0.30723026,57.535492,0,11.076097,359.99924,-0.020307712,0.86283046,11.075216,364.24789,-9.2884674
141.6,0.05380743,-0.30751622,56.14196,0,11.076097,359.99924,-0.0203015,0.71046531,11.075745,364.36475,-9.2884645
142.8,0.041524097,-0.307289,55.288921,0,11.076097,359.99924,-0.020291395,0.5468002,11.075783,363.83212,-9.2887096
144.0,0.025133507,-0.30707407,55.239262,0,11.076097,359.99924,-0.020253832,0.32471716,11.076026,362.49585,-9.2880583
145.2,0.020455392,-0.30702946,55.843395,0,11.076097,359.99924,-0.020238211,0.27846003,11.075904,360.66559,-9.2877693
146.4,0.022087656,-0.30583802,57.06741,0,11.076097,359.99924,-0.020198293,0.29009065,11.075982,358.7088,-9.2881784
147.6,0.01647477,-0.30568257,58.539871,0,11.076097,359.99924,-0.020146111,0.22451231,11.075485,357.07117,-9.2882433
148.8,0.022065615,-0.30504984,59.840408,0,11.076097,359.99924,-0.02015694,0.29352671,11.075534,355.98941,-9.2887859
150.0,0.029325273,-0.30549705,61.085812,0,11.076097,359.99924,-0.020171899,0.38933754,11.076631,355.41843,-9.2887363
151.2,0.045543287,-0.30615079,61.907413,0,11.076097,359.99924,-0.020216245,0.59176719,11.076672,355.74332,-9.2884073
152.4,0.060795452,-0.30714318,62.116692,0,11.076097,359.99924,-0.020257248,0.78563809,11.076519,357.11578,-9.2888756
153.6,0.065099038,-0.30959868,61.507664,0,11.076097,359.99924,-0.020389104,0.84770131,11.075765,359.13669,-9.2882423
154.8,0.064118907,-0.31103805,60.589706,0,11.076097,359.99924,-0.02054546,0.83185101,11.075757,361.121,-9.288065
156.0,0.055608038,-0.31263244,59.355446,0,11.076097,359.99924,-0.020620365,0.72052377,11.07616,362.82635,-9.2879715
157.2,0.06436938,-0.31311703,58.074509,0,11.076097,359.99924,-0.020677347,0.82778972,11.077085,363.91336,-9.2884483
158.4,0.05333811,-0.31360051,56.711521,0,11.076097,359.99924,-0.02067947,0.70515001,11.075259,364.42258,-9.2884665
159.6,0.04837466,-0.31381094,55.535927,0,11.076097,359.99924,-0.020682054,0.62557292,11.075697,364.32538,-9.2887087
160.8,0.028985843,-0.31345809,54.679352,0,11.076097,359.99924,-0.020689903,0.38379309,11.075904,363.58829,-9.2886524
162.0,0.019356038,-0.31341547,54.896915,0,11.076097,359.99924,-0.020653429,0.24949659,11.07605,362.14471,-9.2882853
163.2,0.015316297,-0.31251124,55.535469,0,11.076097,359.99924,-0.020644223,0.19175142,11.075809,360.33337,-9.2882681
164.4,0.010320277,-0.31232566,56.710205,0,11.076097,359.99924,-0.02061829,0.13816172,11.076406,358.50504,-9.2883205
165.2805,0.090697393,0.03228654,57.810059,0,11.076099,2.5657713,0.0021340225,1.0786568,11.077911,357.35544,-9.2892532
165.2829,0.1388911,0.031299923,57.810059,0,11.076099,1.1091822000000001e-16,0.0022587823,1.7505944,11.076146,357.34818,-9.2888107
165.2853,0.13326524,0.030003104,57.810059,0,11.076099,4.7949927999999995e-33,0.0021676996,1.7647785,11.076635,357.34091,-9.2881689
165.2877,0.12336647,0.032299232,47.982052,0,11.076099,0.0,0.002141474,1.529811,11.075965,357.34393,-9.2879448
165.2901,0.16114438,0.035132021,34.107639,0,11.076099,0.0,0.0021099411,1.9857202,11.07597,357.3512,-9.2892857
165.2925,0.11979986,0.037683763,20.233221,0,11.076099,0.0,0.0022760513,1.574353,11.079344,357.35846,-9.2887478
165.2949,0.13939147,0.03580017,6.3588095,0,11.076099,0.0,0.0024333242,1.8066638,11.076326,357.36575,-9.2872696
165.2973,0.13920498,0.031919967,0.0,0,11.076099,0.0,0.002381288,1.6482829,11.07505,357.37695,-9.2866583
165.2997,0.12202469,0.029520972,0.0,0,11.076099,0.0,0.0020602057,1.572185,11.075315,357.39151,-9.2871561
165.3021,0.11520926,0.030126955,0.0,0,11.076099,0.0,0.0019254873,1.4786755,11.078021,357.40604,-9.2877216
165.3045,0.1405019,0.032731682,0.0,0,11.076099,0.0,0.0020138791,1.7492961,11.076583,357.42059,-9.2871475
165.3069,0.1405879,0.033571724,0.0,0,11.076099,0.0,0.002175438,1.8488281,11.075607,357.42151,-9.288126
165.3093,0.12743649,0.032144673,0.0,0,11.076099,0.0,0.0022168607,1.7011507,11.07602,357.39969,-9.2879105
165.3117,0.13507433,0.030353844,0.0,0,11.076099,0.0,0.0021867636,1.6949506,11.078032,357.37787,-9.2872648
165.3141,0.13198502,0.030654993,0.0,0,11.076099,0.0,0.0020606485,1.6762437,11.075546,357.35605,-9.2889366
165.3165,0.1493018,0.034371953,0.0,0,11.076099,0.0,0.0020749224,1.8830633,11.075222,357.33423,-9.2882099
165.3189,0.1435789,0.037867118,0.0,0,11.076099,0.0,0.0022476607,1.8498557,11.07712,357.31241,-9.287199
165.3213,0.12750611,0.035906196,0.0,0,11.076099,0.0,0.0024030891,1.6064243,11.074119,357.29059,-9.287447
165.3237,0.13027084,0.032359608,0.0,0,11.076099,0.0,0.002451831,1.6054434,11.075872,357.26877,-9.2889032
165.3261,0.14851308,0.030184235,0.0,0,11.076099,0.0,0.0022123889,1.8662008,11.076849,357.24756,-9.2894764
165.3285,0.15149303,0.032309555,0.0,0,11.076099,0.0,0.0020718451,1.885442,11.076853,357.2403,-9.2894945
165.3309,0.14245968,0.033706851,0.0,0,10.976463,0.0,0.0020967163,1.9131899,11.073267,357.233,-9.2881451
165.3333,0.13667205,0.033634655,0.0,0,10.615489,0.0,0.0021837221,1.7778805,11.072474,357.22574,-9.2884808
165.3357,0.14382447,0.032453641,0.0,0,10.254517,0.0,0.0022543871,1.7274324,11.05852,357.21848,-9.2894697
165.3381,0.20798925,0.032637745,0.0,0,9.8935423,0.0,0.0023944455,2.5275698,10.929967,358.17853,-9.2889137
165.3405,0.14530824,0.033086155,0.0,0,9.5325689,0.0,0.0023052164,1.7883554,10.638535,359.27676,-9.2884645
165.3429,0.19508712,0.036894891,0.0,0,9.1800213,0.0,0.0022896107,2.3876395,10.228746,360.37503,-9.2878189
165.3453,6.9424734,0.39043668,0.0,0,8.8288536,0.0,0.025315521,86.336952,9.7645473,361.47327,-9.2825356
165.3477,8.6379719,0.7520079,0.0,0,8.4910212,0.0,0.05119225,104.38611,9.2893124,361.86569,-9.2823381
165.3501,9.0458469,1.1677152,0.0,0,8.1570368,0.0,0.080820203,106.36341,8.8558168,361.9675,-9.2800016
165.3525,9.1648827,1.5533683,0.0,0,7.8342915,0.0,0.10926408,104.31641,8.4837694,362.06934,-9.2800493
165.3549,9.4504337,1.8600278,0.0,0,7.516531,0.0,0.13199699,105.56492,8.1537437,362.17117,-9.2792606
165.3573,9.753932,2.1581726,0.0,0,7.2082477,0.0,0.15469356,106.1543,7.8384099,361.33139,-9.280158
165.3597,10.002891,2.4633989,0.0,0,6.9060392,0.0,0.1788628,106.45888,7.5325508,359.69492,-9.2802143
165.3621,10.204155,2.7484403,0.0,0,6.6115575,0.0,0.20221446,106.07921,7.2413669,358.05844,-9.2802601
165.3645,10.49384,3.0350168,0.0,0,6.324038,0.0,0.22606848,106.54327,6.9473524,356.422,-9.2807322
165.3669,10.740751,3.3204424,0.0,0,6.0427446,0.0,0.24995808,106.40837,6.657402,355.14282,-9.2807665
165.3693,11.017509,3.610029,0.0,0,5.7692881,0.0,0.27462664,106.54387,6.3689752,354.45914,-9.2816763
165.3717,11.305867,3.8975136,0.0,0,5.5006099,0.0,0.29985383,106.62439,6.0849323,353.77545,-9.2815256
165.3741,11.569389,4.1805959,0.0,0,5.2404499,0.0,0.32596865,106.20604,5.7941899,353.09174,-9.2802448
165.3765,11.815627,4.4531174,0.0,0,4.9838009,0.0,0.35208818,105.74702,5.5140963,352.24979,-9.2806501
165.3789,12.103669,4.7228737,0.0,0,4.7363605,0.0,0.37823701,105.51067,5.2428207,350.80649,-9.2810392
165.3813,12.39559,4.9883819,0.0,0,4.4912429,0.0,0.40390018,105.34688,4.9764814,349.36319,-9.2815027
165.3837,12.683419,5.2496114,0.0,0,4.2558503,0.0,0.42992023,105.00119,4.7173023,347.91989,-9.2798843
165.3861,12.971951,5.5008316,0.0,0,4.0217228,0.0,0.45602828,104.64311,4.4626918,346.47809,-9.2796907
165.3885,13.296914,5.744915,0.0,0,3.7978463,0.0,0.48245519,104.42208,4.218914,345.07114,-9.2807646
165.3909,13.67968,5.9803905,0.0,0,3.5743468,0.0,0.50870192,104.59024,3.9781563,343.66418,-9.2800474
165.3933,14.044254,6.2160888,0.0,0,3.3612819,0.0,0.53510493,104.65067,3.7426453,342.25723,-9.2807894
165.3957,14.411586,6.446928,0.0,0,3.1483059,0.0,0.56115997,104.61845,3.5168419,340.85028,-9.2801847
165.3981,14.773238,6.6709623,0.0,0,2.9451036,0.0,0.58710933,104.55341,3.2947209,339.61374,-9.2794333
165.4005,15.199747,6.8808932,0.0,0,2.7424955,0.0,0.61283457,104.81355,3.0877483,338.40152,-9.2790174
165.4029,15.662562,7.0809121,0.0,0,2.5483847,0.0,0.63864547,105.21195,2.8824201,337.18933,-9.2798996
165.4053,16.140276,7.2785392,0.0,0,2.3556647,0.0,0.6645112,105.64257,2.6805918,335.97714,-9.2807951
165.4077,16.609678,7.475955,0.0,0,2.1702456,0.0,0.68981194,106.0611,2.483248,333.85303,-9.2791996
165.4101,17.154661,7.6724119,0.0,0,1.9869336,0.0,0.71538788,106.73627,2.2884614,331.35352,-9.2791939
165.4125,17.744289,7.8624372,0.0,0,1.809806,0.0,0.74150944,107.53806,2.0975449,328.85397,-9.2785339
165.4149,18.371584,8.0489359,0.0,0,1.635422,0.0,0.76848948,108.42549,1.9168034,326.35443,-9.2785006
165.4173,19.01157,8.2288799,0.0,0,1.466215,0.0,0.79560196,109.17316,1.7306777,322.87122,-9.2775478
165.4197,19.68635,8.4083967,0.0,0,1.3003271,0.0,0.82253569,110.06351,1.5478009,318.55569,-9.2778044
165.4221,20.408875,8.5864134,0.0,0,1.1387062,0.0,0.84916699,111.10384,1.3713864,314.2402,-9.2763004
165.4245,21.195522,8.7594995,0.0,0,0.98093021,0.0,0.87551641,112.36021,1.1999631,309.92471,-9.2769995
165.4269,21.971323,8.9229479,0.0,0,0.82657528,0.0,0.90221786,113.41305,1.0343957,305.41293,-9.27707
165.4293,22.777182,9.0759106,0.0,0,0.67652738,0.0,0.92872494,114.47026,0.87541097,300.5741,-9.2769365
165.4317,23.590269,9.2175713,0.0,0,0.52908403,0.0,0.95390999,115.65961,0.72388071,295.73523,-9.2749662
165.4341,24.50054,9.361331,0.0,0,0.38628396,0.0,0.97851205,117.17184,0.57436228,290.89639,-9.2751007
165.4365,22.484341,9.4225378,0.0,0,0.24541834,0.0,0.98912334,106.41684,0.47000578,286.97821,-9.2772827
165.4389,20.737495,9.4374447,0.0,0,0.10962632,0.0,0.99117178,98.089119,0.42455381,286.55817,-9.2802734
165.4413,19.85343,9.4452333,0.0,0,-0.025518155,0.0,0.99310654,93.677223,0.39492324,286.13812,-9.2791147
165.4437,19.435709,9.4468908,0.0,0,-0.15795021,0.0,0.99446416,91.559723,0.36138514,285.71808,-9.2798872
165.4461,19.567553,9.4518394,0.0,0,-0.29038224,0.0,0.99570167,92.057076,0.30388579,285.43866,-9.2805452
165.4485,19.758694,9.4584103,0.0,0,-0.42281422,0.0,0.99590296,92.905685,0.24185677,288.39139,-9.2807913
165.4509,19.86389,9.4689445,0.0,0,-0.55524617,0.0,0.99667263,93.343987,0.17455165,291.34415,-9.2816982
165.4533,19.773739,9.4795876,0.0,0,-0.68767816,0.0,0.99842012,92.795547,0.11247447,294.29688,-9.2814255
165.4557,19.558792,9.4807014,0.0,0,-0.82011014,0.0,0.99981397,91.656502,0.060216546,297.24963,-9.2809677
165.4581,19.274157,9.4789,0.0,0,-0.95254219,0.0,1.0005116,90.274994,0.020246968,300.47549,-9.2819881
165.4605,18.909901,9.4796705,0.0,0,-1.0849742,0.0,1.0007138,88.559753,-0.0049390527,303.74039,-9.2826023
165.4629,18.393227,9.4857845,0.0,0,-0.72870082,359.99997,1.0004045,86.166954,-0.013199195,307.00528,-9.2818251
165.4653,17.837515,9.4875889,0.0,0,-0.2702145,359.99997,0.99999404,83.5924,-0.01173434,310.27017,-9.2821188
165.4677,17.356518,9.4884853,10.005439,0,0.18827185,359.99997,1.0005468,81.292458,-0.0091019077,313.13348,-9.2816944
165.4701,16.977079,9.4864826,24.130341,0,0.64675826,359.99997,1.0010465,79.46376,-0.003404127,315.83145,-9.2827482
165.4725,16.695845,9.4838161,38.255241,0,1.1052449,359.99997,1.0014925,78.096313,-0.0017414186,318.52942,-9.2830963
165.4749,16.118135,9.4825468,52.380146,0,1.5637312,359.99997,1.0006237,75.532318,0.007103004,321.22742,-9.2835541
165.4773,14.31079,9.4826651,58.85376,0,2.0222175,359.99997,0.99933285,67.30455,0.083222225,323.53,-9.2842627
165.4797,11.397517,9.4735107,58.85376,0,2.4807043,359.99997,0.99730664,53.794151,0.2171877,325.49802,-9.2867117
165.4821,7.2726555,9.4559488,58.85376,0,2.9391904,359.99997,0.99486142,34.670277,0.44453457,327.46606,-9.2905846
165.4845,0.28984818,9.3173933,58.85376,0,3.3976769,359.99997,0.97198284,1.2143285,0.85054857,329.43411,-9.2974615
165.4869,-0.37340558,9.1963854,56.962135,0,3.8561635,359.99997,0.95079225,-1.7955507,1.6027585,332.21469,-9.2971134
165.4893,0.16684568,9.0848722,51.918095,0,4.3146496,359.99997,0.9311074,0.68367428,2.4282596,336.34937,-9.296751
165.4917,-0.10643246,9.0193129,46.87405,0,4.7731361,359.99997,0.91862303,-0.35109463,3.1276326,340.48407,-9.2962437
165.4941,-0.10462993,8.9835749,41.830009,0,5.2316227,359.99997,0.91311824,-0.5733425,3.640352,344.61874,-9.2951698
165.4965,-0.015090556,8.9797688,37.836914,0,5.6901088,359.99997,0.91321981,-0.1040988,4.0778723,348.33707,-9.2939882
165.4989,-0.035066396,8.9900455,37.836914,0,6.1485953,359.99997,0.91558617,-0.18028168,4.4934573,350.47339,-9.2928753
165.5013,-0.055678874,9.0240479,37.836914,0,6.6070814,359.99997,0.92078257,-0.2387334,4.9108529,352.60971,-9.2916603
165.5037,0.01505122,9.0801687,37.836914,0,7.065568,359.99997,0.92912108,0.059263121,5.3438811,354.74603,-9.2916222
165.5061,-0.073229387,9.1569824,37.595753,0,7.5240545,359.99997,0.94142157,-0.33472568,5.7968769,356.8042,-9.2904415
165.5085,-0.090807833,9.2375326,31.810793,0,7.9825416,359.99997,0.95570219,-0.53445482,6.2682967,357.06604,-9.2908945
165.5109,0.094975516,9.3310089,26.025831,0,8.4410276,359.99997,0.97354156,0.42465353,6.7582092,357.32788,-9.2901411
165.5133,-0.12052717,9.4443474,20.24087,0,8.8995132,359.99997,0.99405432,-0.44036824,7.2477918,357.58972,-9.2895203
165.5157,-0.14632177,9.420249,14.455908,0,9.3579998,359.99997,0.98890001,-0.68874693,7.72576,357.85156,-9.2893038
165.5181,0.081365101,9.4355831,13.73291,0,9.8164864,359.99997,0.99060076,0.45390499,8.2039261,357.75064,-9.2888718
165.5205,-0.097784035,9.4398909,13.73291,0,10.274973,359.99997,0.99146199,-0.38398936,8.6730051,357.5979,-9.2887983
165.5229,-0.009211041,9.4391031,13.73291,0,10.733459,359.99997,0.99229246,-0.1082864,9.1347494,357.44516,-9.2887135
165.5253,-0.0014019972,9.4430037,13.73291,0,11.191946,359.99997,0.99399543,0.097457498,9.6116257,357.29242,-9.2882433
165.5277,-0.13544892,9.4435654,16.646572,0,11.650432,359.99997,0.99394268,-0.68842554,10.079775,356.39261,-9.2887392
165.5301,-0.013318683,9.4441566,20.759851,0,12.108919,359.99997,0.99296314,-0.13469483,10.557137,355.18524,-9.2868986
165.5325,0.044959366,9.4527006,24.873133,0,12.567405,359.99997,0.99348605,0.16890866,11.026483,353.97787,-9.2880135
165.5349,-0.12836716,9.452795,28.986414,0,13.025891,359.99997,0.99385917,-0.54744887,11.49682,352.77051,-9.2859488
165.5373,-0.033209749,9.4442987,30.871582,0,13.484378,359.99997,0.9937579,-0.17318121,11.961926,352.10666,-9.2883425
165.5397,-0.060750224,9.4401035,30.871582,0,13.942864,359.99997,0.99372047,-0.18725798,12.426026,351.90262,-9.2867336
165.5421,-0.027492033,9.4405413,30.871582,0,14.401351,359.99997,0.99305612,-0.1993686,12.880448,351.69861,-9.2878933
165.5445,-0.014679421,9.4409809,30.871582,0,14.859838,359.99997,0.99210364,-0.080107078,13.348217,351.49457,-9.2864008
165.5469,-0.017940015,9.4452829,30.962553,0,15.318324,359.99997,0.99251753,-0.096911751,13.82347,351.38617,-9.2857246
165.5493,-0.13341956,9.4468136,31.205133,0,15.77681,359.99997,0.99325371,-0.59662205,14.29807,351.43707,-9.2856693
165.5517,-0.013778648,9.4411592,31.447712,0,16.235298,359.99997,0.99358559,-0.18638995,14.775403,351.48801,-9.2864933
165.5541,0.0086039044,9.4374094,31.690289,0,16.693783,359.99997,0.993038,0.10909121,15.242017,351.53891,-9.2857447
165.5565,-0.092821404,9.4411869,31.882326,0,17.152269,359.99997,0.99263334,-0.47599089,15.690021,351.69144,-9.2854586
165.5589,0.01194148,9.4445372,31.882326,0,17.610756,359.99997,0.99233806,0.079550803,16.14925,352.23004,-9.2855825
165.5613,-0.11904386,9.44911,31.882326,0,17.999975,359.99997,0.99317122,-0.50837183,16.608831,352.76862,-9.2861156
165.5637,-0.07012143,9.4477434,31.882326,0,18.0,359.99997,0.99407083,-0.28880587,17.062553,353.30722,-9.2847366
165.5661,0.044216104,9.4388199,31.781113,0,18.0,359.99997,0.99343425,0.12101512,17.488991,353.84427,-9.2856245
165.5685,-0.056696553,9.4395132,29.352694,0,18.0,359.99997,0.9930743,-0.20003432,17.871805,354.34613,-9.2860556
165.5709,-0.044573557,9.4452286,26.924276,0,18.0,359.99997,0.99291039,-0.28653497,18.193747,354.84799,-9.2868891
165.5733,-0.044091091,9.4500694,24.495859,0,18.0,359.99997,0.9932133,-0.150497,18.417894,355.34985,-9.2902899
165.5757,-0.049767856,9.4544973,22.06744,0,18.0,359.99997,0.99451041,-0.25442439,18.525814,355.85172,-9.2960129
165.5781,0.053184655,9.4573879,21.763916,0,18.0,359.99997,0.9960984,0.33964676,18.499573,356.35992,-9.302702
165.5805,-0.17267446,9.4650812,21.763916,0,18.0,359.99997,0.9978838,-0.77182162,18.377209,356.86905,-9.312746
165.5829,-0.1005139,9.4773197,21.763916,0,18.0,359.99997,0.99947941,-0.501625,18.23814,357.3782,-9.3265133
165.5853,-0.052932762,9.4994345,21.763916,0,18.0,359.99997,1.0022248,-0.29839787,18.116945,357.88733,-9.3438416
165.5877,0.054341096,9.5196714,20.398623,0,18.0,359.99997,1.0055165,0.20156999,18.057745,358.01523,-9.3591223
165.5901,0.0080295885,9.5358849,18.471182,0,18.0,359.99997,1.0095521,0.080021158,18.044168,357.98611,-9.3776445
165.5925,-0.10841873,9.5522852,16.543739,0,18.0,359.99997,1.0138929,-0.42721424,18.047279,357.95703,-9.3970594
165.5949,-0.17150943,9.571394,14.6163,0,18.0,359.99997,1.0174994,-0.84480888,18.064577,357.92792,-9.4195385
165.5973,0.012483127,9.5892687,13.73291,0,18.0,359.99997,1.0195618,0.002040114,18.089085,357.71365,-9.4393959
165.5997,0.060318697,9.6117859,13.73291,0,18.0,359.99997,1.0226786,0.28406739,18.11562,357.34271,-9.4565163
165.6021,-0.04860175,9.6308641,13.73291,0,18.0,359.99997,1.0265522,-0.13933255,18.132187,356.97177,-9.4741869
165.6045,-0.16609745,9.6478138,13.73291,0,18.0,359.99997,1.0309997,-0.76044768,18.145601,356.60086,-9.4934368
165.6069,-0.061229657,9.6621857,15.07669,0,18.0,359.99997,1.0343552,-0.32659504,18.145369,356.08807,-9.5118122
165.6093,0.044601906,9.6763506,18.65999,0,18.0,359.99997,1.0364003,0.19880879,18.146029,355.33893,-9.529294
165.6117,0.030249767,9.6973133,22.243292,0,18.0,359.99997,1.0389624,0.166132,18.140526,354.58978,-9.5453014
165.6141,-0.1022187,9.7225523,25.826591,0,18.0,359.99997,1.0430872,-0.39794841,18.142355,353.84064,-9.5615797
165.6165,-0.14145795,9.7401543,28.66333,0,18.0,359.99997,1.0473632,-0.65486532,18.133755,353.0853,-9.5795727
165.6189,0.023921911,9.7496471,28.66333,0,18.0,359.99997,1.0508164,0.028064961,18.133051,352.3064,-9.5969429
165.6213,0.066734388,9.760623,28.66333,0,18.0,359.99997,1.0530338,0.304243,18.128435,351.5275,-9.614212
165.6237,-0.05516012,9.7796583,28.66333,0,18.0,359.99997,1.0552514,-0.16796467,18.127054,350.74863,-9.6311188
165.6261,-0.14459909,9.8017778,28.769157,0,18.0,359.99997,1.0586405,-0.59604686,18.122166,349.97729,-9.6481533
165.6285,-0.066832758,9.821456,31.308317,0,18.0,359.99997,1.0628302,-0.343431,18.122335,349.37946,-9.6645498
165.6309,0.055020813,9.8351192,33.847477,0,18.0,359.99997,1.0664076,0.20411022,18.116304,348.78165,-9.6838522
165.6333,0.043197285,9.8477116,36.386639,0,18.0,359.99997,1.0696299,0.23108511,18.116379,348.18384,-9.69979
165.6357,-0.10450615,9.8691807,38.925797,0,18.0,359.99997,1.0735145,-0.37491056,18.113848,347.586,-9.7195358
165.6381,-0.15954265,9.8914928,39.243164,0,18.0,359.99997,1.0765178,-0.6860761,18.110416,347.27518,-9.7376242
165.6405,0.023911336,9.912611,39.243164,0,18.0,359.99997,1.0799474,0.016584406,18.109648,347.00534,-9.7555342
165.6429,0.059758898,9.9288139,39.243164,0,18.0,359.99997,1.0835726,0.29987025,18.108547,346.73553,-9.7733278
165.6453,-0.057452235,9.9452591,39.243164,0,18.0,359.99997,1.0883442,-0.19472264,18.103317,346.4657,-9.7904692
165.6477,-0.14796084,9.9573717,39.779198,0,18.0,359.99997,1.0914923,-0.62449926,18.101923,346.13904,-9.8085279
165.6501,-0.075359367,9.9728098,40.535934,0,18.0,359.99997,1.0934398,-0.35230988,18.102877,345.789,-9.8256903
165.6525,0.065679431,9.9914885,41.292675,0,18.0,359.99997,1.0959657,0.24920531,18.107494,345.43893,-9.8436623
165.6549,0.033208519,10.011787,42.049412,0,18.0,359.99997,1.0999601,0.16139036,18.098566,345.0889,-9.8608894
165.6573,-0.12281232,10.033603,42.39624,0,18.0,359.99997,1.1052805,-0.46568137,18.098164,344.65985,-9.8789196
165.6597,-0.14656653,10.04733,42.39624,0,18.0,359.99997,1.1092527,-0.69254553,18.100437,344.16394,-9.896801
165.6621,0.02796944,10.060757,42.39624,0,18.0,359.99997,1.1118885,0.04859769,18.100433,343.66806,-9.9132557
165.6645,0.058968645,10.078965,42.39624,0,18.0,359.99997,1.1142174,0.23975632,18.099266,343.17215,-9.9304256
165.6669,-0.049399368,10.103689,42.772976,0,18.0,359.99997,1.1183388,-0.17487569,18.103376,342.72821,-9.9472189
165.6693,-0.14657411,10.125167,43.777561,0,18.0,359.99997,1.1228818,-0.62022519,18.099089,342.37085,-9.9639406
165.6717,-0.079280153,10.136399,44.782154,0,18.0,359.99997,1.1268232,-0.3848455,18.097633,342.01352,-9.9824629
165.6741,0.068795182,10.145922,45.786739,0,18.0,359.99997,1.1296326,0.2524288,18.094503,341.65619,-9.9994736
165.6765,0.02689429,10.1631,46.582031,0,18.0,359.99997,1.1323918,0.13494617,18.097776,341.29733,-10.019329
165.6789,-0.1242044,10.186603,46.582031,0,18.0,359.99997,1.136049,-0.44130144,18.09762,340.93271,-10.036545
165.6813,-0.15374392,10.208403,46.582031,0,18.0,359.99997,1.1400594,-0.67237526,18.095701,340.56805,-10.052888
165.6837,0.022961771,10.225109,46.582031,0,18.0,359.99997,1.1441734,0.048136339,18.096775,340.20343,-10.070839
165.6861,0.06032379,10.236765,46.60434,0,18.0,359.99997,1.1479619,0.26093218,18.095726,339.84305,-10.08737
165.6885,-0.049032282,10.251683,47.139591,0,18.0,359.99997,1.1514684,-0.13951841,18.094862,339.58054,-10.105814
165.6909,-0.13060649,10.274162,47.674847,0,18.0,359.99997,1.1551803,-0.50245607,18.09244,339.31799,-10.123081
165.6933,-0.082670353,10.297295,48.210102,0,18.0,359.99997,1.1586745,-0.3561919,18.092014,339.05548,-10.141314
165.6957,0.075427502,10.31545,48.745354,0,18.0,359.99997,1.1622595,0.26043439,18.092638,338.79294,-10.15891
165.6981,0.046883248,10.329844,48.812256,0,18.0,359.99997,1.1667136,0.22748853,18.090183,338.50488,-10.176226
165.7005,-0.12207685,10.342946,48.812256,0,18.0,359.99997,1.1709169,-0.4544867,18.088257,338.21317,-10.192932
165.7029,-0.12922053,10.358095,48.812256,0,18.0,359.99997,1.1738703,-0.51696366,18.089214,337.92148,-10.211309
165.7053,0.021963127,10.374849,48.812256,0,18.0,359.99997,1.1761019,-0.0052444167,18.087936,337.62976,-10.22807
165.7077,0.076020144,10.39432,49.217548,0,18.0,359.99997,1.1793966,0.29648927,18.085346,337.3277,-10.244624
165.7101,-0.033408534,10.416764,49.789715,0,18.0,359.99997,1.1848497,-0.081471607,18.085396,337.02142,-10.263619
165.7125,-0.14362025,10.433754,50.361885,0,18.0,359.99997,1.190152,-0.5464896,18.08313,336.71512,-10.2815
165.7149,-0.087531805,10.447733,50.934052,0,18.0,359.99997,1.1937302,-0.38580078,18.081125,336.40881,-10.298362
165.7173,0.085673176,10.463063,51.196289,0,18.0,359.99997,1.1961232,0.28671721,18.080675,336.09445,-10.31596
165.7197,0.047166426,10.486712,51.196289,0,18.0,359.99997,1.1997411,0.23854885,18.080904,335.77322,-10.334549
165.7221,-0.13631997,10.508054,51.196289,0,18.0,359.99997,1.2038672,-0.4700509,18.081852,335.45203,-10.351392
165.7245,-0.12962911,10.522175,51.196289,0,18.0,359.99997,1.2086942,-0.49787274,18.077414,335.1308,-10.369364
165.7269,0.0082866596,10.531943,51.356472,0,18.0,359.99997,1.2122707,-0.027621998,18.076498,334.80942,-10.387698
165.7293,0.075243466,10.545498,51.783623,0,18.0,359.99997,1.2154952,0.27560624,18.080009,334.48776,-10.404766
165.7317,-0.023838211,10.567909,52.210773,0,18.0,359.99997,1.2190208,-0.020618426,18.081575,334.16611,-10.422
165.7341,-0.16084279,10.59066,52.63792,0,18.0,359.99997,1.2230933,-0.5811671,18.078043,333.84445,-10.439618
165.7365,-0.082056016,10.608042,52.976074,0,18.0,359.99997,1.2272164,-0.37915525,18.078196,333.54105,-10.45738
165.7389,0.070690893,10.619263,52.976074,0,18.0,359.99997,1.2312793,0.24811812,18.074203,333.30698,-10.474298
165.7413,0.03236353,10.634922,52.976074,0,18.0,359.99997,1.2357601,0.17505516,18.077717,333.07294,-10.491612
165.7437,-0.11725868,10.652748,52.976074,0,18.0,359.99997,1.2392076,-0.43376988,18.076159,332.83887,-10.509848
165.7461,-0.12192029,10.674076,52.992561,0,18.0,359.99997,1.2426177,-0.48439109,18.074028,332.6051,-10.528168
165.7485,0.0020446924,10.696329,53.388069,0,18.0,359.99997,1.246474,-0.030112697,18.075777,332.37836,-10.544749
165.7509,0.08599139,10.713557,53.783573,0,18.0,359.99997,1.2517382,0.29130799,18.073807,332.15161,-10.56109
165.7533,-0.022925051,10.729394,54.179081,0,18.0,359.99997,1.2573673,-0.019282112,18.070145,331.9249,-10.578207
165.7557,-0.17057557,10.74331,54.574593,0,18.0,359.99997,1.2611297,-0.59174901,18.07655,331.69815,-10.59691
165.7581,-0.074644983,10.760487,54.624023,0,18.0,359.99997,1.2637682,-0.32354456,18.071398,331.43939,-10.616006
165.7605,0.080380417,10.778984,54.624023,0,18.0,359.99997,1.26676,0.26515785,18.06723,331.17609,-10.634149
165.7629,0.047491353,10.798244,54.624023,0,18.0,359.99997,1.271365,0.18685172,18.071802,330.91278,-10.650682
165.7653,-0.10833683,10.818645,54.624023,0,18.0,359.99997,1.2773439,-0.32624617,18.070108,330.64944,-10.668304
165.7677,-0.13058203,10.830989,54.831341,0,18.0,359.99997,1.2818607,-0.50281686,18.068235,330.39651,-10.686231
165.7701,0.0084440252,10.845267,55.124016,0,18.0,359.99997,1.2849674,-0.010133263,18.063555,330.14783,-10.703244
165.7725,0.096427269,10.867711,55.416691,0,18.0,359.99997,1.28882,0.33302855,18.065311,329.89914,-10.720527
165.7749,-0.016046103,10.893598,55.70937,0,18.0,359.99997,1.2933939,0.018185824,18.066956,329.65048,-10.739367
165.7773,-0.16741735,10.914928,55.84351,0,18.0,359.99997,1.2994113,-0.55761385,18.066547,329.4216,-10.756365
165.7797,-0.064113051,10.922857,55.84351,0,18.0,359.99997,1.3035251,-0.26691866,18.065092,329.20947,-10.774734
165.7821,0.075269327,10.930668,55.84351,0,18.0,359.99997,1.3063167,0.24374899,18.061756,328.99738,-10.789911
165.7845,0.037836365,10.948838,55.84351,0,18.0,359.99997,1.309562,0.19585393,18.061865,328.78525,-10.806333
165.7869,-0.10557469,10.97269,55.946342,0,18.0,359.99997,1.3136818,-0.31161907,18.060616,328.57861,-10.823561
165.7893,-0.13387343,10.993896,56.220562,0,18.0,359.99997,1.3189628,-0.46876141,18.065035,328.38113,-10.84266
165.7917,0.0097774193,11.00841,56.494781,0,18.0,359.99997,1.3236853,0.0010540455,18.061556,328.18365,-10.860105
165.7941,0.097509876,11.020807,56.768997,0,18.0,359.99997,1.3283319,0.32909328,18.063564,327.98618,-10.876676
165.7965,-0.015548514,11.038492,56.986084,0,18.0,359.99997,1.332613,0.018535519,18.060751,327.78564,-10.895443
165.7989,-0.15930192,11.05888,56.986084,0,18.0,359.99997,1.3365817,-0.51274979,18.059772,327.57352,-10.913521
165.8013,-0.075234532,11.083481,56.986084,0,18.0,359.99997,1.3410252,-0.30341193,18.06255,327.36142,-10.931707
165.8037,0.066114545,11.101762,56.986084,0,18.0,359.99997,1.3459358,0.20102341,18.057964,327.14929,-10.947928
165.8061,0.049497761,11.11587,56.999603,0,18.0,359.99997,1.3512609,0.16525623,18.05859,326.93655,-10.965491
165.8085,-0.094435476,11.129681,57.323921,0,18.0,359.99997,1.3563145,-0.25296485,18.056992,326.70981,-10.983541
165.8109,-0.14304243,11.141933,57.648239,0,18.0,359.99997,1.3590114,-0.47216901,18.060604,326.48306,-11.002853
165.8133,-0.0028155593,11.161528,57.972549,0,18.0,359.99997,1.3622713,-0.032428425,18.05751,326.25635,-11.0205
165.8157,0.095185645,11.182088,58.296867,0,18.0,359.99997,1.3667663,0.31624356,18.056089,326.0296,-11.037606
165.8181,-0.016847344,11.202666,58.337406,0,18.0,359.99997,1.3729763,0.0034577686,18.059135,325.80286,-11.05382
165.8205,-0.17298621,11.217257,58.337406,0,18.0,359.99997,1.3785934,-0.52897394,18.056139,325.57611,-11.07175
165.8229,-0.070700407,11.228379,58.337406,0,18.0,359.99997,1.3821907,-0.26928991,18.056713,325.34937,-11.090466
165.8253,0.069287933,11.246424,58.337406,0,18.0,359.99997,1.385775,0.1943671,18.055813,325.12262,-11.107228
165.8277,0.053151522,11.268883,58.509232,0,18.0,359.99997,1.3897238,0.21213327,18.055431,324.91141,-11.125053
165.8301,-0.089973971,11.29359,58.751812,0,18.0,359.99997,1.3956844,-0.23157839,18.052338,324.70663,-11.141973
165.8325,-0.14335777,11.309393,58.994389,0,18.0,359.99997,1.4019147,-0.46209964,18.053099,324.50183,-11.159291
165.8349,0.010869123,11.317841,59.236961,0,18.0,359.99997,1.406276,-0.032540765,18.054333,324.29703,-11.176712
165.8373,0.11389032,11.329522,59.348145,0,18.0,359.99997,1.4094175,0.35480976,18.050877,324.09222,-11.193434
165.8397,-0.013230545,11.352155,59.348145,0,18.0,359.99997,1.4134398,0.011309521,18.052343,323.88742,-11.211485
165.8421,-0.16055416,11.374978,59.348145,0,18.0,359.99997,1.41875,-0.48626122,18.04842,323.68262,-11.230921
165.8445,-0.070689432,11.392317,59.348145,0,18.0,359.99997,1.4240404,-0.2828939,18.052664,323.47781,-11.248755
165.8469,0.073319174,11.406532,59.435158,0,18.0,359.99997,1.4299631,0.2029269,18.05113,323.27576,-11.267569
165.8493,0.059816688,11.419615,59.667187,0,18.0,359.99997,1.4341691,0.18607791,18.049898,323.07828,-11.282808
165.8517,-0.079963915,11.438905,59.899223,0,18.0,359.99997,1.4386984,-0.17143393,18.051498,322.8808,-11.300356
165.8541,-0.14850861,11.464342,60.131252,0,18.0,359.99997,1.4439865,-0.46909577,18.051472,322.68332,-11.318251
165.8565,0.0073761018,11.483669,60.314941,0,18.0,359.99997,1.4483089,-0.023347875,18.049498,322.48126,-11.336732
165.8589,0.099323161,11.500038,60.314941,0,18.0,359.99997,1.4545559,0.31074193,18.049276,322.26184,-11.354338
166.0608,-0.036879148,11.619293,0.13466853,0,18.0,0.6838128,1.4898574,-0.10681691,18.025732,296.07834,-11.479951
167.2608,-0.048960868,11.618827,5.839716e-18,0,18.0,2.9561099e-17,1.489727,-0.14288008,18.000788,134.27304,-11.481655
168.4608,-0.045539774,11.618218,2.5322901e-34,0,18.0,1.2779218999999999e-33,1.4897487,-0.13293371,18.000473,67.200546,-11.481684
169.6608,-0.046108346,11.618594,7.9874012e-44,0,18.0,1.4012985e-45,1.4899491,-0.13081034,17.99951,40.512173,-11.482124
170.8608,-0.043599125,11.618282,7.9874012e-44,0,18.0,1.4012985e-45,1.4897027,-0.12436312,17.999542,30.833675,-11.482262
172.0608,-0.046291098,11.618649,7.9874012e-44,0,18.0,1.4012985e-45,1.489816,-0.13219678,18.002399,27.265604,-11.482081
173.2608,-0.043398384,11.618578,7.9874012e-44,0,18.0,1.4012985e-45,1.4895325,-0.12264782,18.000963,26.004744,-11.482262
174.4608,-0.04397539,11.618838,7.9874012e-44,0,18.0,1.4012985e-45,1.4898118,-0.12354178,17.999609,25.526913,-11.48226
175.6608,-0.039919741,11.618217,7.9874012e-44,0,18.0,1.4012985e-45,1.4897097,-0.11316112,17.999094,25.273827,-11.482391
176.8608,-0.039183233,11.618916,7.9874012e-44,0,18.0,1.4012985e-45,1.4899336,-0.1096913,17.99968,25.099253,-11.482536
178.0608,-0.045135833,11.618365,7.9874012e-44,0,18.0,1.4012985e-45,1.4898324,-0.12752286,18.000278,25.149136,-11.481992
179.2608,-0.043926686,11.618617,7.9874012e-44,0,18.0,1.4012985e-45,1.4895726,-0.12468185,18.000443,24.991167,-11.482015
180.4608,-0.039276693,11.618967,7.9874012e-44,0,18.0,1.4012985e-45,1.489809,-0.1121887,17.999758,25.004482,-11.482124
181.6608,-0.039514132,11.618994,7.9874012e-44,0,18.0,1.4012985e-45,1.4899164,-0.11735204,17.999933,24.965988,-11.482027
182.8608,-0.044013396,11.619175,7.9874012e-44,0,18.0,1.4012985e-45,1.4900125,-0.12709641,18.000114,24.872908,-11.482538
184.0608,-0.041719373,11.619446,7.9874012e-44,0,18.0,1.4012985e-45,1.4901891,-0.12225372,17.999472,24.827801,-11.482705
185.2608,-0.04448773,11.620332,7.9874012e-44,0,18.0,1.4012985e-45,1.4900736,-0.12893115,17.999706,24.834904,-11.482479
186.4608,-0.044341732,11.619713,7.9874012e-44,0,18.0,1.4012985e-45,1.4899989,-0.12855427,17.999838,24.761574,-11.481939
187.6608,-0.04631795,11.61961,7.9874012e-44,0,18.0,1.4012985e-45,1.4900916,-0.1360151,17.999174,24.750313,-11.481911
188.8608,-0.04504279,11.619618,7.9874012e-44,0,18.0,1.4012985e-45,1.4901861,-0.12801509,17.999441,24.693285,-11.481787
190.0608,-0.046365537,11.619183,7.9874012e-44,0,18.0,1.4012985e-45,1.4900537,-0.13103557,17.999098,24.692125,-11.481571
191.2608,-0.047088344,11.620598,7.9874012e-44,0,18.0,1.4012985e-45,1.4901406,-0.13725562,18.00012,24.603893,-11.482108
192.4608,-0.043280631,11.620313,7.9874012e-44,0,18.0,1.4012985e-45,1.4902021,-0.12498961,17.999901,24.623188,-11.48232
193.6608,-0.050015941,11.620357,7.9874012e-44,0,18.0,1.4012985e-45,1.4903387,-0.14366235,17.999975,24.65457,-11.482268
194.8608,-0.048977416,11.620885,7.9874012e-44,0,18.0,1.4012985e-45,1.490553,-0.13864446,18.000666,24.556129,-11.482065
196.0608,-0.048658863,11.620728,7.9874012e-44,0,18.0,1.4012985e-45,1.4905454,-0.13802798,17.999538,24.563583,-11.482022
197.2608,-0.046103779,11.620584,7.9874012e-44,0,18.0,1.4012985e-45,1.4901289,-0.13195179,17.999081,24.558695,-11.482106
198.4608,-0.047424886,11.620988,7.9874012e-44,0,18.0,1.4012985e-45,1.490416,-0.13259763,18.000906,24.663631,-11.482007
199.6608,-0.042850219,11.620969,7.9874012e-44,0,18.0,1.4012985e-45,1.490538,-0.12082384,17.999876,24.564556,-11.482292
200.8608,-0.041944645,11.621152,7.9874012e-44,0,18.0,1.4012985e-45,1.4906071,-0.11925173,17.99942,24.55818,-11.482287
202.0608,-0.044964429,11.620817,7.9874012e-44,0,18.0,1.4012985e-45,1.4904982,-0.12540743,17.998707,24.404118,-11.482267
203.2608,-0.044677433,11.621393,7.9874012e-44,0,18.0,1.4012985e-45,1.4904047,-0.12762247,18.000134,24.403118,-11.482156
204.4608,-0.040506039,11.62127,7.9874012e-44,0,18.0,1.4012985e-45,1.4906346,-0.11378255,18.000965,24.466324,-11.482396
205.6608,-0.0415949,11.621601,7.9874012e-44,0,18.0,1.4012985e-45,1.4907812,-0.12007815,18.000454,24.35854,-11.482404
206.8608,-0.042629901,11.621644,7.9874012e-44,0,18.0,1.4012985e-45,1.4906052,-0.12522484,17.998634,24.466919,-11.482226
208.0608,-0.037930239,11.62187,7.9874012e-44,0,18.0,1.4012985e-45,1.4906985,-0.108863,18.00004,24.401186,-11.48239
209.2608,-0.045796979,11.62256,7.9874012e-44,0,18.0,1.4012985e-45,1.4908252,-0.13331312,17.998821,24.396593,-11.482147
210.4608,-0.046932645,11.622553,7.9874012e-44,0,18.0,1.4012985e-45,1.4910492,-0.13777587,18.00033,24.438784,-11.482368
211.6608,-0.045704413,11.62239,7.9874012e-44,0,18.0,1.4012985e-45,1.4910834,-0.13251381,18.000887,24.380505,-11.482546
212.8608,-0.046149984,11.623118,7.9874012e-44,0,18.0,1.4012985e-45,1.4908926,-0.13438368,18.000114,24.31201,-11.482638
214.0608,-0.046066925,11.622511,7.9874012e-44,0,18.0,1.4012985e-45,1.4908768,-0.13148457,17.999861,24.217724,-11.482546
215.2608,-0.050924476,11.623064,7.9874012e-44,0,18.0,1.4012985e-45,1.4911637,-0.14558859,17.999735,24.313986,-11.482407
216.4608,-0.050548863,11.622967,7.9874012e-44,0,18.0,1.4012985e-45,1.491118,-0.1497585,18.000536,24.250654,-11.481998
217.6608,-0.053271472,11.623208,7.9874012e-44,0,18.0,1.4012985e-45,1.491155,-0.1532305,17.999987,24.396204,-11.482054
218.8608,-0.058277462,11.622994,7.9874012e-44,0,18.0,1.4012985e-45,1.4909141,-0.16703299,17.998903,24.315733,-11.48152
220.0608,-0.05411987,11.623171,7.9874012e-44,0,18.0,1.4012985e-45,1.4911975,-0.15373707,17.999544,24.277603,-11.48163
221.2608,-0.043086037,11.623496,7.9874012e-44,0,18.0,1.4012985e-45,1.4913684,-0.12061867,17.999325,24.325016,-11.481507
222.4608,-0.046337169,11.62445,7.9874012e-44,0,18.0,1.4012985e-45,1.4913468,-0.13007146,17.999794,24.279949,-11.48205
223.6608,-0.048353262,11.624244,7.9874012e-44,0,18.0,1.4012985e-45,1.491374,-0.13455601,17.999836,24.223345,-11.482228
224.8608,-0.0452036,11.624128,7.9874012e-44,0,18.0,1.4012985e-45,1.4915087,-0.12743029,17.999533,24.215885,-11.482725
225.8608,-0.043541897,11.624784,7.9874012e-44,0,18.0,1.4012985e-45,1.4914401,-0.12513725,17.999092,24.195448,-11.482307