File: examples/hot axisymmetric compression example/data/02 screened data/testID_0142.csv
Time(sec),Force(kN),Jaw(mm),PowAngle(deg),Power(W),Pram,PTemp,Strain,Stress(MPa),Stroke(mm),TC1(C),wedge(mm)
0.0,0.81025445,0.33585241,0.0,0,11.076097,0.0015935858,0.022644183,10.085557,11.076256,28.700827,-9.1164989
1.2,0.76039869,-0.0058469782,0.0,0,11.076097,3.5159006,-0.00040322013,9.6853065,11.077461,28.733355,-9.4844236
2.4,0.73799181,-0.0054260856,0.0,0,11.076097,7.1159005,-0.00038297346,9.4064617,11.076152,28.765102,-9.4817772
3.6,0.72260928,-0.0052758451,0.0,0,11.076097,10.715903,-0.00036212153,9.2070074,11.077077,28.698055,-9.4809055
4.8,0.7017433,-0.0055010109,0.0,0,11.076097,14.315904,-0.00037492302,8.9369946,11.076202,28.70174,-9.4783049
6.0,0.68663079,-0.0056024669,0.0,0,11.076097,17.915907,-0.00037041339,8.7616348,11.075665,28.634367,-9.4763126
7.2,0.67321062,-0.005930841,0.0,0,11.076097,21.515909,-0.000393725,8.5904675,11.076504,28.515013,-9.474021
8.4,0.66159195,-0.0054799258,0.0,0,11.076097,25.115906,-0.00034025888,8.4227686,11.077073,28.430025,-9.472084
9.6,0.65230298,-0.0057957568,0.0,0,11.076097,28.715908,-0.0003653194,8.3030844,11.07617,28.338024,-9.4698534
10.8,0.65154988,-0.0050937817,21.685682,0,11.076097,32.31591,-0.00034192594,8.3000364,11.076233,28.5159,-9.4680309
12.0,0.65392643,-0.005875994,32.824448,0,11.076097,35.91592,-0.00035636907,8.3434124,11.07559,29.9368,-9.4662428
13.2,0.66706103,-0.0082400683,38.547005,0,11.076097,39.515923,-0.00056820124,8.5107918,11.076806,32.987473,-9.4644241
14.4,0.67571217,-0.012228031,42.339191,0,11.076097,43.115917,-0.00078290724,8.6182547,11.076362,36.905781,-9.4626894
15.6,0.68570334,-0.015605773,43.799946,0,11.076097,46.715919,-0.0010790236,8.7461958,11.07548,41.760422,-9.4602289
16.8,0.69970149,-0.01986433,43.913239,0,11.076097,50.315918,-0.0013201272,8.9401903,11.076011,47.156914,-9.4581518
18.0,0.70417124,-0.023675581,43.383671,0,11.076097,53.91592,-0.0015962281,8.9882221,11.076471,52.385662,-9.4561081
19.2,0.7013194,-0.026408479,42.396248,0,11.076097,57.515919,-0.0017759005,8.9495459,11.076238,57.15937,-9.4539404
20.4,0.70771372,-0.029365836,41.672256,0,11.076097,61.115921,-0.00196715,9.0284233,11.076309,61.424541,-9.4520226
21.6,0.70352936,-0.031804789,40.933701,0,11.076097,64.715919,-0.0021155127,8.9768419,11.076599,65.312164,-9.4499998
22.8,0.7058391,-0.034430284,41.198021,0,11.076097,68.31591,-0.0022796721,9.0140142,11.076045,68.683197,-9.4478235
24.0,0.70395684,-0.037200745,41.198727,0,11.076097,71.915924,-0.0024615573,8.9927673,11.076241,71.949623,-9.4454575
25.2,0.71528685,-0.039308775,41.802975,0,11.076097,75.515915,-0.0025814187,9.1226559,11.076259,75.161446,-9.4439678
26.4,0.70304424,-0.041530583,42.396236,0,11.076097,79.115936,-0.0027875614,8.9804344,11.077067,78.47628,-9.4412575
27.6,0.7121585,-0.044219032,43.145618,0,11.076097,82.715919,-0.0029095293,9.0854053,11.076009,81.840508,-9.439085
28.8,0.71915823,-0.046405502,43.527828,0,11.076097,86.315926,-0.0031206163,9.1945124,11.075573,85.422745,-9.437315
30.0,0.72596699,-0.050696306,44.077145,0,11.076097,89.915924,-0.0033779806,9.2681503,11.076646,89.060295,-9.4354086
31.2,0.72296345,-0.05226871,44.077202,0,11.076097,93.515938,-0.0035125546,9.214592,11.076376,92.885429,-9.4337616
32.4,0.7271713,-0.055059046,44.604488,0,11.076097,97.115936,-0.0036713271,9.2914038,11.076305,96.458435,-9.4319534
33.6,0.7310037,-0.057997253,44.604496,0,11.076097,100.71593,-0.0038649535,9.3540316,11.075408,100.1357,-9.4299345
34.8,0.73381239,-0.061054457,44.848373,0,11.076097,104.31593,-0.0040455414,9.388401,11.076339,103.8843,-9.4273272
36.0,0.74003357,-0.065023944,45.117874,0,11.076097,107.91593,-0.0042934162,9.4594898,11.075433,107.47826,-9.4250507
37.2,0.73473179,-0.067086302,45.12085,0,11.076097,111.51593,-0.0044638263,9.4006548,11.07617,111.18098,-9.4228735
38.4,0.74046373,-0.070008025,45.185242,0,11.076097,115.11594,-0.0046153753,9.472806,11.076557,114.76193,-9.4211044
39.6,0.74274498,-0.072089352,45.617142,0,11.076097,118.71593,-0.0048329146,9.4971666,11.076197,118.11671,-9.4191742
40.8,0.749731,-0.076276161,46.109619,0,11.076097,122.31594,-0.0050897216,9.5917978,11.076398,121.75793,-9.4171648
42.0,0.74763834,-0.078620903,46.580902,0,11.076097,125.91595,-0.0052394751,9.5853167,11.075608,125.16054,-9.4151745
43.2,0.75117803,-0.081209131,46.78125,0,11.076097,129.51607,-0.0053867041,9.6223574,11.075859,128.84824,-9.4131231
44.4,0.75826669,-0.084559783,47.05444,0,11.076097,133.11594,-0.0056123086,9.7107143,11.076616,132.43028,-9.4110374
45.6,0.75593704,-0.088206023,47.473518,0,11.076097,136.71593,-0.0058559841,9.6900969,11.076371,136.09419,-9.4088669
46.8,0.75330746,-0.090585828,47.504883,0,11.076097,140.31592,-0.0059864041,9.6594353,11.075607,139.74294,-9.406662
48.0,0.75519943,-0.093342543,47.504883,0,11.076097,143.91594,-0.0062323697,9.6866102,11.077123,143.48746,-9.4046412
49.2,0.76324379,-0.095896952,47.504883,0,11.076097,147.51593,-0.0063662613,9.7860775,11.07573,147.16196,-9.4026279
50.4,0.78016549,-0.099599436,47.954216,0,11.076097,151.11594,-0.0066459505,10.002467,11.077893,150.73256,-9.4007998
51.6,0.76526487,-0.10225388,47.955318,0,11.076097,154.71594,-0.0068045054,9.8117428,11.076198,154.35632,-9.3986759
52.8,0.76969427,-0.10566813,48.383507,0,11.076097,158.31592,-0.0070218942,9.8782854,11.07595,157.79283,-9.3965969
54.0,0.78128862,-0.1079196,48.811241,0,11.076097,161.91592,-0.007149362,10.035019,11.076517,161.155,-9.3949509
55.2,0.78877383,-0.11212605,49.228867,0,11.076097,165.51595,-0.0074124997,10.119983,11.076344,164.68628,-9.3929701
56.4,0.77611601,-0.11485489,49.438293,0,11.076097,169.11594,-0.0076548024,9.9544296,11.077176,168.25282,-9.3906364
57.6,0.77621931,-0.11816605,49.636227,0,11.076097,172.71593,-0.0078294277,9.9660683,11.075787,171.98596,-9.3885965
58.8,0.78014934,-0.12136307,49.749062,0,11.076097,176.31595,-0.0080887908,10.024988,11.076578,175.66075,-9.3862057
60.0,0.78542376,-0.12453231,50.042721,0,11.076097,179.91594,-0.0082838256,10.088062,11.076612,179.37035,-9.3843794
61.2,0.79055256,-0.12937216,50.042721,0,11.076097,183.51593,-0.0085790297,10.145199,11.076666,183.17986,-9.3823853
62.4,0.77982748,-0.13141318,50.042721,0,11.076097,187.11595,-0.0087024989,10.011988,11.0758,186.86641,-9.3800726
63.6,0.7805565,-0.1347075,50.042721,0,11.076097,190.71594,-0.0089072045,10.032589,11.075783,190.47284,-9.3782587
64.8,0.77965003,-0.1376328,50.042721,0,11.076097,194.31595,-0.0091585219,10.011894,11.076752,194.09512,-9.3764029
66.0,0.79304403,-0.14180133,50.436413,0,11.076097,197.91595,-0.0093988813,10.19794,11.075983,197.62813,-9.3744583
67.2,0.78625464,-0.1442689,50.438229,0,11.076097,201.51596,-0.0095989415,10.106409,11.075861,201.1442,-9.3727388
68.4,0.78596711,-0.14767125,50.589397,0,11.076097,205.11595,-0.0097989263,10.091545,11.076379,204.75871,-9.3709135
69.6,0.78765249,-0.15071712,50.82275,0,11.076097,208.71597,-0.0099904481,10.139642,11.076196,208.36313,-9.3685522
70.8,0.78836071,-0.15381926,50.82275,0,11.076097,212.31595,-0.010186704,10.1428,11.076155,211.96039,-9.3666277
72.0,0.79035419,-0.15851872,51.196251,0,11.076097,215.91597,-0.010469305,10.155845,11.075303,215.44292,-9.3641701
73.2,0.77973765,-0.16097921,51.196285,0,11.076097,219.51596,-0.01070162,10.02287,11.07681,219.04379,-9.3623247
74.4,0.78838283,-0.16422147,51.569469,0,11.076097,223.11597,-0.010882449,10.139025,11.075727,222.60985,-9.3602352
75.6,0.78792357,-0.16688155,51.56987,0,11.076097,226.71596,-0.011077862,10.135095,11.075972,226.24113,-9.3581839
76.8,0.79265827,-0.17196158,51.932323,0,11.076097,230.31598,-0.011392659,10.203892,11.0765,229.74661,-9.3565836
78.0,0.77418679,-0.17444471,51.932369,0,11.076097,233.91595,-0.011539378,9.9633493,11.077994,233.44427,-9.3550472
79.2,0.79373294,-0.17733212,52.127007,0,11.076097,237.51599,-0.011764347,10.226446,11.076635,237.06781,-9.3531103
80.4,0.79480815,-0.18054743,52.283794,0,11.076097,241.11595,-0.011938234,10.251059,11.076728,240.76581,-9.3512487
81.6,0.79095525,-0.18545939,52.283936,0,11.076097,244.71597,-0.012319118,10.189728,11.075382,244.32509,-9.3488245
82.8,0.78026509,-0.18775712,52.634792,0,11.076097,248.31596,-0.012452141,10.069018,11.076262,247.85863,-9.3471165
84.0,0.78928673,-0.19079877,52.635754,0,11.076097,251.91597,-0.012656725,10.182865,11.076491,251.38812,-9.3449364
85.2,0.79751945,-0.19367291,52.962112,0,11.076097,255.51598,-0.012806483,10.295906,11.076114,255.01454,-9.3428955
86.4,0.80530035,-0.19867778,52.97607,0,11.076097,259.11624,-0.01312734,10.399304,11.076278,258.54321,-9.3405199
87.6,0.79512823,-0.20081758,53.31665,0,11.076097,262.71597,-0.013327454,10.261298,11.076186,262.1189,-9.3383732
88.8,0.78982568,-0.20412661,53.47868,0,11.076097,266.31595,-0.013510714,10.196972,11.076268,265.68765,-9.3365793
90.0,0.80018485,-0.207148,53.378265,0,11.076097,269.91599,-0.013718498,10.337528,11.075956,269.55283,-9.3353386
91.2,0.80778033,-0.21102451,53.657223,0,11.076097,273.51599,-0.013961313,10.446238,11.075583,273.17776,-9.3331814
92.4,0.80085403,-0.21549655,53.657223,0,11.076097,277.11597,-0.014227054,10.347973,11.076377,276.74805,-9.3316698
93.6,0.79312563,-0.21777771,53.837864,0,11.076097,280.71597,-0.014426778,10.264115,11.076502,280.31467,-9.3300772
94.8,0.79214627,-0.22191118,53.975826,0,11.076097,284.31595,-0.014668429,10.249035,11.07618,283.93152,-9.3280249
96.0,0.80060929,-0.22481845,53.975826,0,11.076097,287.91595,-0.014896682,10.350098,11.076593,287.60287,-9.325449
97.2,0.81239313,-0.23030229,53.975826,0,11.076097,291.51596,-0.015225953,10.506715,11.076661,291.1669,-9.3231335
98.4,0.8026616,-0.23344682,54.303329,0,11.076097,295.11597,-0.015424981,10.385069,11.07688,294.71613,-9.3210363
99.6,0.79108745,-0.23676935,54.305416,0,11.076097,298.71597,-0.015674261,10.253675,11.076273,298.29935,-9.3190231
100.8,0.79977369,-0.24027231,54.432804,0,11.076097,302.31595,-0.015870381,10.348103,11.076227,301.95621,-9.3164625
102.0,0.80943322,-0.24331032,54.620949,0,11.076097,305.91595,-0.016111474,10.480997,11.076826,305.55063,-9.3148642
103.2,0.81225497,-0.24897106,54.624023,0,11.076097,309.51599,-0.016467303,10.515592,11.076203,309.24854,-9.3136387
104.4,0.8006047,-0.25136948,54.624023,0,11.076097,313.11597,-0.016603444,10.344772,11.075974,312.77902,-9.3119001
105.6,0.79607242,-0.25479615,54.931503,0,11.076097,316.71594,-0.016852617,10.318848,11.076629,316.27737,-9.3102417
106.8,0.79898465,-0.25857168,54.931637,0,11.076097,320.31595,-0.01707178,10.353364,11.075624,319.82068,-9.3081741
108.0,0.8083387,-0.26141721,55.237434,0,11.076097,323.91595,-0.017297838,10.471733,11.076055,323.41141,-9.3069096
109.2,0.810067,-0.26710469,55.239254,0,11.076097,327.51599,-0.017648229,10.493453,11.075788,327.04526,-9.3041706
110.4,0.80221879,-0.26945898,55.488777,0,11.076097,331.11597,-0.017768562,10.395811,11.07741,330.61771,-9.3015594
111.6,0.78964704,-0.27297077,55.535885,0,11.076097,334.71597,-0.018060857,10.247214,11.075809,334.24939,-9.2991152
112.8,0.80242372,-0.27714831,55.587261,0,11.076097,338.31598,-0.018300921,10.410482,11.075482,337.9657,-9.2971182
114.0,0.80460626,-0.28043163,55.843506,0,11.076097,341.91599,-0.018527467,10.442804,11.076205,341.4563,-9.2952194
115.2,0.80712759,-0.2853851,55.843506,0,11.076097,345.51599,-0.018840374,10.472627,11.076599,345.20886,-9.2948256
116.4,0.80594218,-0.28878519,55.843506,0,11.076097,349.116,-0.019020587,10.453697,11.074366,348.85785,-9.2929773
117.6,0.80134243,-0.29188457,55.843887,0,11.076097,352.716,-0.019307451,10.410254,11.076037,352.49792,-9.2906179
118.8,0.80493861,-0.29581964,55.945026,0,11.076097,356.31601,-0.019542241,10.457472,11.076086,356.10153,-9.288559
120.0,0.8038848,-0.29936063,56.093746,0,11.076097,359.91599,-0.019750979,10.437936,11.076043,359.67438,-9.2863216
121.2,0.81308371,-0.30467167,56.090637,0,11.076097,363.51602,-0.020111153,10.569244,11.07586,363.36334,-9.2848415
122.4,0.80607325,-0.30673945,56.129147,0,11.076097,367.116,-0.020224236,10.467354,11.076461,366.95868,-9.2831554
123.6,0.79717249,-0.31030941,56.247082,0,11.076097,370.716,-0.020504858,10.372647,11.076424,370.37491,-9.2817507
124.8,0.79885048,-0.31423327,56.425758,0,11.076097,374.31601,-0.020719668,10.395893,11.076081,373.98978,-9.2787037
126.0,0.81319326,-0.31838182,56.425777,0,11.076097,377.91602,-0.020963192,10.586721,11.076145,377.58688,-9.2761021
127.2,0.80999988,-0.3225159,56.493416,0,11.076097,381.51602,-0.021298375,10.525735,11.075427,381.16782,-9.273715
128.4,0.80319571,-0.326222,56.706612,0,11.076097,385.11603,-0.021527058,10.443862,11.076366,384.7377,-9.2719097
129.6,0.80614954,-0.32977852,56.711304,0,11.076097,388.716,-0.021732192,10.503997,11.076554,388.47427,-9.2711782
130.8,0.81544805,-0.333648,56.711422,0,11.076097,392.31604,-0.022012791,10.630809,11.07555,392.07718,-9.2696104
132.0,0.81686932,-0.33831343,56.711422,0,11.076097,395.91602,-0.022290403,10.638817,11.076797,395.68448,-9.2675972
133.2,0.80414915,-0.34124839,56.77433,0,11.076097,399.51605,-0.022505494,10.486209,11.076083,399.23779,-9.2657146
134.4,0.04484278,-0.35296518,55.84351,0,11.076097,399.99893,-0.023246972,0.60276508,11.077127,401.27493,-9.265583
135.6,0.044661216,-0.35183913,55.538239,0,11.076097,399.99893,-0.023146084,0.58921337,11.076964,400.88651,-9.2653522
136.8,0.038577385,-0.35060292,55.843445,0,11.076097,399.99893,-0.023130935,0.50551009,11.076019,400.40567,-9.2652292
138.0,0.030788032,-0.35023004,56.129147,0,11.076097,399.99893,-0.023078017,0.41379628,11.075675,399.72675,-9.2649918
139.2,0.03167735,-0.34993067,56.628361,0,11.076097,399.99893,-0.023027809,0.42208847,11.076015,399.18399,-9.2648802
140.4,0.03927207,-0.35068598,57.118347,0,11.076097,399.99893,-0.023147443,0.51677245,11.076442,398.73932,-9.2641735
141.6,0.034257755,-0.3499155,57.768055,0,11.076097,399.99893,-0.023073073,0.45081252,11.076542,398.33157,-9.2643661
142.8,0.056258004,-0.35003975,58.073727,0,11.076097,399.99893,-0.02305338,0.73973626,11.0764,398.29306,-9.2648802
144.0,0.063231587,-0.350128,58.255627,0,11.076097,399.99893,-0.023084668,0.82937193,11.076149,398.87366,-9.2652035
145.2,0.068450198,-0.35223055,58.073738,0,11.076097,399.99893,-0.023199495,0.89243066,11.075418,399.66785,-9.2656403
146.4,0.061037004,-0.35233697,57.535561,0,11.076097,399.99893,-0.023226038,0.79933679,11.076488,400.47565,-9.2658844
147.6,0.06545037,-0.3528713,56.986191,0,11.076097,399.99893,-0.02324523,0.85477656,11.077596,401.10129,-9.265914
148.8,0.072251216,-0.35411003,56.426025,0,11.076097,399.99893,-0.023319362,0.93230689,11.077107,401.49579,-9.2658319
150.0,0.040918935,-0.35404813,55.851231,0,11.076097,399.99893,-0.023348903,0.54383802,11.076241,401.63504,-9.2650614
151.2,0.035460327,-0.35357526,55.843506,0,11.076097,399.99893,-0.023281805,0.45986488,11.075482,401.11505,-9.2644157
152.4,0.02972329,-0.35345399,56.129147,0,11.076097,399.99893,-0.02325931,0.38968128,11.07518,400.13281,-9.2639647
153.6,0.028706674,-0.35344085,57.154961,0,11.076097,399.99893,-0.023318371,0.37305233,11.076512,398.70786,-9.2639503
154.8,0.039628204,-0.35192746,58.441013,0,11.076097,399.99893,-0.02318237,0.51392359,11.076998,397.18872,-9.2653465
156.0,0.052606311,-0.35263926,59.576435,0,11.076097,399.99893,-0.023202712,0.68903571,11.077275,396.66873,-9.2655802
157.2,0.059712876,-0.35365343,59.842525,0,11.076097,399.99893,-0.023334738,0.78026342,11.076907,397.48822,-9.2657003
158.4,0.067634262,-0.3557972,59.600838,0,11.076097,399.99893,-0.023436094,0.88432467,11.076545,398.84061,-9.2654886
159.6,0.072437398,-0.35775441,58.893421,0,11.076097,399.99893,-0.023521716,0.95047015,11.075979,400.22766,-9.2651587
160.8,0.061310437,-0.35807288,58.096149,0,11.076097,399.99893,-0.023621531,0.79751313,11.076215,401.45578,-9.264823
162.0,0.061247036,-0.35866931,57.137882,0,11.076097,399.99893,-0.023628255,0.79767215,11.075987,402.3385,-9.2653389
163.2,0.061017107,-0.3591103,56.129673,0,11.076097,399.99893,-0.02362334,0.80387592,11.076092,402.93335,-9.2654705
164.4,0.071586192,-0.35960537,55.240719,0,11.076097,399.99893,-0.023726864,0.93544829,11.076631,403.00562,-9.265871
165.6,0.057121027,-0.35924143,54.624126,0,11.076097,399.99893,-0.023664448,0.74087846,11.07634,402.63004,-9.2657452
166.8,0.028536201,-0.3592689,54.624004,0,11.076097,399.99893,-0.023633877,0.36759567,11.075393,401.66623,-9.2652874
168.0,0.02369811,-0.35810381,55.239243,0,11.076097,399.99893,-0.023629358,0.30238751,11.075653,400.05148,-9.2650585
169.2,0.021019233,-0.35728091,56.705257,0,11.076097,399.99893,-0.023539502,0.28066975,11.075759,398.15009,-9.2651424
170.4,0.023949359,-0.35817143,58.316082,0,11.076097,399.99893,-0.023570256,0.32005364,11.076595,396.52911,-9.2652903
171.6,0.02047828,-0.35706913,59.739063,0,11.076097,399.99893,-0.02355716,0.2655859,11.076299,395.47385,-9.2653904
172.8,0.030322643,-0.35746267,61.080257,0,11.076097,399.99893,-0.023544714,0.40021402,11.075883,394.88574,-9.2655096
174.0,0.06503354,-0.3585721,61.898003,0,11.076097,399.99893,-0.0235801,0.86074251,11.07599,395.55957,-9.2657633
175.2,0.077607594,-0.36071315,61.543156,0,11.076097,399.99893,-0.023791794,1.0189584,11.075779,397.73358,-9.2658558
176.4,0.087432034,-0.36432746,60.604591,0,11.076097,399.99893,-0.023989147,1.1456559,11.075966,400.25964,-9.2661142
177.6,0.074824587,-0.36574507,59.348503,0,11.076097,399.99893,-0.024047323,0.9681111,11.075892,402.43277,-9.2657833
178.6164,0.15280035,0.003869208,38.540009,0,11.076099,65.879791,0.00033938271,1.9340314,11.075948,403.87332,-9.2645035
178.6188,0.19230406,0.0040653176,24.693285,0,11.076099,2.8481726e-15,9.6173753e-05,2.4773726,11.073974,403.88776,-9.2644072
178.6212,0.15767261,0.0070782416,10.846567,0,11.076099,1.2312644e-31,0.00034836706,2.0432396,11.074262,403.90216,-9.2659168
178.6236,0.15362653,0.0069486923,0.0,0,11.076099,0.0,0.00041499632,1.9877598,11.076884,403.91034,-9.2652416
178.626,0.16481151,0.0040026521,0.0,0,11.076099,0.0,0.00042023006,2.0224154,11.076511,403.8959,-9.265748
178.6284,0.16309409,0.0031674237,0.0,0,11.076099,0.0,0.00041496599,2.0586271,11.075229,403.8815,-9.265192
178.6308,0.16621272,0.0043393155,0.0,0,11.076099,0.0,0.00031967583,2.0944951,11.072844,403.8671,-9.2652035
178.6332,0.15929651,0.008073844,0.0,0,11.076099,0.0,0.00034259551,2.0056632,11.073624,403.85266,-9.2652302
178.6356,0.15629786,0.01036289,0.0,0,11.076099,0.0,0.00043808611,1.9746015,11.076117,403.83826,-9.2668009
178.638,0.1774013,0.0096147405,0.0,0,11.076099,0.0,0.00059929828,2.1618652,11.074558,403.82385,-9.2665577
178.6404,0.17291515,0.0061529665,0.0,0,11.076099,0.0,0.00057784386,2.2543507,11.075499,403.80942,-9.2656536
178.6428,0.16304529,0.003251764,0.0,0,11.076099,0.0,0.00043940372,2.1559925,11.075476,403.79501,-9.2657518
178.6452,0.16637297,0.0043024416,0.0,0,11.076099,0.0,0.00026767643,2.0914366,11.074628,403.81183,-9.2650671
178.6476,0.16371757,0.0073642842,0.0,0,11.076099,0.0,0.00030344256,2.1060209,11.075772,403.83347,-9.2640209
178.65,0.17699449,0.0061071878,0.0,0,11.076099,0.0,0.00034035294,2.2001579,11.075217,403.85507,-9.2646999
178.6524,0.18010554,0.005745213,0.0,0,11.076099,0.0,0.00041496655,2.3850327,11.076339,403.87671,-9.2660608
178.6548,0.16885456,0.0041184602,0.0,0,11.076099,0.0,0.00050820148,2.1554868,11.077648,403.90332,-9.2652845
178.6572,0.16676156,0.0059247576,0.0,0,11.076099,0.0,0.00050316413,2.0921679,11.076031,403.93216,-9.2657814
178.6596,0.18137023,0.0075289328,0.0,0,11.076099,0.0,0.00041361467,2.331816,11.077693,403.961,-9.2655468
178.662,0.18742518,0.010769185,0.0,0,11.076099,0.0,0.00037804485,2.3712718,11.077229,403.98984,-9.2650185
178.6644,0.18441232,0.01192376,0.0,0,11.076099,0.0,0.00064340053,2.3565962,11.077106,404.01495,-9.2658281
178.6668,0.17598742,0.0086179404,0.0,0,11.006544,0.0,0.00072455883,2.2983584,11.077365,404.03659,-9.2655821
178.6692,0.17559136,0.0071399137,0.0,0,10.645576,0.0,0.00071176398,2.1747377,11.076093,404.0582,-9.2653389
178.6716,0.18868412,0.0059218216,0.0,0,10.284602,0.0,0.0004671778,2.3365471,11.064222,404.07983,-9.2651472
178.674,0.21916264,0.00567524,0.0,0,9.9236288,0.0,0.00028491858,2.8353214,10.942823,404.16302,-9.2653933
178.6764,0.17352952,0.0071154502,0.0,0,9.5626545,0.0,0.00035407383,2.3113773,10.670422,404.3649,-9.2654934
178.6788,0.22262223,0.0092117423,0.0,0,9.2092896,0.0,0.00062565075,2.8251038,10.277122,404.56677,-9.2657089
178.6812,6.2929516,0.28557554,0.0,0,8.8581219,0.0,0.018249625,78.464783,9.8237629,404.76865,-9.2602673
178.6836,7.3319235,0.72580832,0.0,0,8.518857,0.0,0.049547177,87.87072,9.3200283,404.96814,-9.2599049
178.686,7.67062,1.1373376,0.0,0,8.1848736,0.0,0.078487761,90.003601,8.879282,405.15558,-9.2597361
178.6884,7.639421,1.5338416,0.0,0,7.860775,0.0,0.10709554,87.246223,8.5049849,405.34302,-9.2596893
178.6908,8.0684748,1.8431462,0.0,0,7.543015,0.0,0.13030975,90.216461,8.1729908,405.53049,-9.2598219
178.6932,8.1587658,2.1363621,0.0,0,7.2334356,0.0,0.1533007,88.974037,7.8560061,405.71793,-9.2591286
178.6956,8.4304867,2.4309371,0.0,0,6.9312272,0.0,0.17665111,89.899529,7.5585642,404.883,-9.2602968
178.698,8.5201721,2.7186103,0.0,0,6.6355214,0.0,0.19997193,88.83448,7.2667708,404.03946,-9.2606106
178.7004,8.8268757,3.0072913,0.0,0,6.3480015,0.0,0.22328006,89.771606,6.9705758,403.19592,-9.2605171
178.7028,9.0205536,3.2984784,0.0,0,6.0655355,0.0,0.24759662,89.627235,6.6759982,402.35239,-9.2596855
178.7052,9.2746906,3.5964384,0.0,0,5.792079,0.0,0.27355459,89.792297,6.3789597,400.80704,-9.2588234
178.7076,9.455534,3.8862078,0.0,0,5.5222936,0.0,0.29953584,89.219131,6.0873532,399.1041,-9.2592974
178.71,9.6961737,4.1712575,0.0,0,5.2621331,0.0,0.32591653,89.119781,5.7926888,397.40118,-9.259798
178.7124,9.9155693,4.4594059,0.0,0,5.0044241,0.0,0.35257968,88.665749,5.5056462,395.69824,-9.2603178
178.7148,10.19025,4.7378078,0.0,0,4.7569838,0.0,0.37875623,88.708443,5.2251062,393.99887,-9.2597733
178.7172,10.379126,5.0063481,0.0,0,4.5108657,0.0,0.40506858,88.112465,4.9616623,392.30145,-9.2603674
178.7196,10.571346,5.2566237,0.0,0,4.2754693,0.0,0.43070173,87.499062,4.7057366,390.60403,-9.2602654
178.722,10.790966,5.4945741,0.0,0,4.0404716,0.0,0.45609197,87.01712,4.4654503,388.90659,-9.2597237
178.7244,11.072188,5.7215066,0.0,0,3.8165052,0.0,0.48055109,87.132256,4.2320471,387.08676,-9.2585258
178.7268,11.371063,5.951036,0.0,0,3.5926332,0.0,0.50506389,87.218597,4.0012674,385.12701,-9.2575397
178.7292,11.642176,6.1818757,0.0,0,3.3790326,0.0,0.53040236,87.144928,3.7750967,383.1673,-9.257926
178.7316,11.921285,6.405664,0.0,0,3.1660566,0.0,0.55608654,87.07428,3.5508957,381.20755,-9.2580004
178.734,12.285914,6.6258202,0.0,0,2.9619904,0.0,0.58236074,87.320473,3.3325703,379.17758,-9.2586241
178.7364,12.670959,6.8423843,0.0,0,2.7593822,0.0,0.60908872,87.703285,3.1171381,376.97705,-9.2580318
178.7388,13.080674,7.0571747,0.0,0,2.5644472,0.0,0.63593483,88.106979,2.9000099,374.77652,-9.2573404
178.7412,13.435008,7.2688994,0.0,0,2.3717272,0.0,0.66231132,88.183647,2.6877995,372.57599,-9.2571621
178.7436,13.852224,7.4797597,0.0,0,2.185524,0.0,0.68933946,88.529022,2.4830472,369.935,-9.2575626
178.746,14.303779,7.6792135,0.0,0,2.002212,0.0,0.71610391,88.922295,2.2864904,363.95917,-9.2573986
178.7484,14.75081,7.8649144,0.0,0,1.8243402,0.0,0.7427572,89.295525,2.0930285,357.98331,-9.2571278
178.7508,15.225432,8.04177,0.0,0,1.6499562,0.0,0.76857173,89.857826,1.9174722,352.00748,-9.2571144
178.7532,15.694927,8.2174587,0.0,0,1.4800411,0.0,0.79394311,90.323517,1.7363789,346.03162,-9.2571793
178.7556,16.259497,8.390893,0.0,0,1.3141533,0.0,0.81883782,91.248428,1.5648191,343.53568,-9.2564631
178.758,16.882353,8.5641918,0.0,0,1.1518563,0.0,0.84486437,92.270493,1.3936145,341.25528,-9.2551346
178.7604,17.534336,8.7306671,0.0,0,0.99408025,0.0,0.87138933,93.366646,1.2247031,338.97488,-9.2552242
178.7628,18.167444,8.8910065,0.0,0,0.83908123,0.0,0.89827728,94.168137,1.056854,336.69449,-9.2547703
178.7652,18.884214,9.0502357,0.0,0,0.68903327,0.0,0.92532307,95.259537,0.89375198,337.85028,-9.2556238
178.7676,19.650204,9.2081671,0.0,0,0.54098582,0.0,0.95154709,96.50174,0.73757476,340.05182,-9.2556438
178.77,20.471117,9.3623505,0.0,0,0.39818579,0.0,0.9773255,97.984322,0.58314627,342.25336,-9.2544451
178.7724,18.323977,9.4409857,0.0,0,0.25673616,0.0,0.99128532,86.472076,0.46740401,344.4549,-9.255949
178.7748,16.697374,9.4506083,0.0,0,0.12094405,0.0,0.99396098,78.761696,0.41736954,345.8699,-9.2576189
178.7772,15.814635,9.4531975,0.0,0,-0.014479336,0.0,0.99560803,74.422134,0.38724223,346.74207,-9.2573557
178.7796,15.326469,9.4522152,0.0,0,-0.14691253,0.0,0.99583226,72.128693,0.35881972,347.61423,-9.2587624
178.782,15.325782,9.455265,0.0,0,-0.27934453,0.0,0.99543923,72.070313,0.31599164,348.48642,-9.2599039
178.7844,15.647684,9.4670486,0.0,0,-0.41177651,0.0,0.99646044,73.543327,0.25221872,349.72504,-9.2594681
178.7868,15.766218,9.4747658,0.0,0,-0.54420853,0.0,0.99801695,74.03421,0.1829665,351.47672,-9.2598724
178.7892,15.725729,9.4801798,0.0,0,-0.67664051,0.0,0.99976379,73.732262,0.11857924,353.22836,-9.2597132
178.7916,15.567834,9.4800644,0.0,0,-0.80907249,0.0,1.0007455,72.853226,0.061523952,354.98004,-9.2599592
178.794,15.30996,9.4836512,3.3914557,0,-0.94150448,0.0,1.0012347,71.632744,0.019343564,356.69418,-9.2600012
178.7964,14.958225,9.4898481,17.425011,0,-1.0739366,0.0,1.0014611,70.015526,-0.0097620571,358.29068,-9.2597437
178.7988,14.479076,9.4971447,31.458565,0,-0.76691389,400.0,1.0016245,67.758728,-0.02129727,359.88718,-9.2603359
178.8012,13.925753,9.5001621,45.492115,0,-0.30842754,400.0,1.0023383,65.108391,-0.020107001,361.48364,-9.2612839
178.8036,13.466377,9.4965248,58.590088,0,0.15005881,400.0,1.0030181,62.903103,-0.015104655,363.10806,-9.2621117
178.806,13.093189,9.4926882,58.590088,0,0.60854518,400.0,1.0031155,61.141605,-0.010073038,365.12344,-9.262496
178.8084,12.792933,9.4835443,58.590088,0,1.0670315,400.0,1.0010127,59.840984,-0.0065067695,367.13885,-9.2629147
178.8108,12.411053,9.4947433,58.590088,0,1.5255178,400.0,1.0019759,58.083061,0.0013290884,369.15427,-9.2629547
178.8132,10.780488,9.4881763,58.590088,0,1.9840043,400.0,1.0003934,50.640205,0.072202101,371.16968,-9.2620554
178.8156,8.143712,9.4792299,56.410297,0,2.4424911,400.0,0.99893099,38.375252,0.20376112,372.99545,-9.2642412
178.818,4.685595,9.4620838,53.965675,0,2.9009774,400.0,0.99702787,22.3356,0.41517895,374.79819,-9.2670975
178.8204,0.18502259,9.3738613,51.521053,0,3.3594637,400.0,0.98227823,0.80900764,0.81782246,376.60092,-9.2719612
178.8228,-0.30683044,9.3061485,49.076431,0,3.81795,400.0,0.96891373,-1.3582772,1.5414097,378.40366,-9.2707357
178.8252,0.14147934,9.2506084,48.383789,0,4.2764363,400.0,0.95855677,0.55507189,2.3763192,379.94095,-9.2715921
178.8276,-0.16773301,9.233408,48.383789,0,4.7349229,400.0,0.95460862,-0.64279759,3.0881906,381.37329,-9.2704268
178.83,-0.0728416,9.2243862,48.383789,0,5.1934094,400.0,0.95419353,-0.52099973,3.6104503,382.80563,-9.271966
178.8324,0.053677328,9.2447224,48.383789,0,5.6518955,400.0,0.95865315,0.33491978,4.0425992,384.23798,-9.2723188
178.8348,-0.039555158,9.2801056,46.817303,0,6.1103821,400.0,0.96532071,-0.2073952,4.4559026,385.43451,-9.2699156
178.8372,-0.017979002,9.330945,43.925331,0,6.5688682,400.0,0.97291523,-0.063692532,4.8711443,386.43155,-9.2688427
178.8396,-0.028639751,9.4035196,41.033367,0,7.0273547,400.0,0.98489064,-0.1025385,5.3041649,387.42856,-9.2688942
178.842,0.50010729,9.4585972,38.141396,0,7.4858418,400.0,0.99526864,2.6695292,5.7538958,388.4256,-9.2682514
178.8444,-0.047190219,9.4271421,36.309814,0,7.9443283,400.0,0.99024099,-0.2635597,6.2300014,389.34314,-9.2678766
178.8468,0.10997412,9.430336,36.309814,0,8.4028139,400.0,0.99169207,0.59639901,6.7159996,390.12341,-9.2660284
178.8492,0.1201416,9.446516,36.309814,0,8.8612995,400.0,0.99442095,0.56146288,7.1996899,390.90369,-9.26616
178.8516,0.054530863,9.4462385,36.309814,0,9.3197861,400.0,0.99312961,0.21065611,7.6794667,391.68396,-9.2664375
178.854,0.14047892,9.4546652,35.715172,0,9.7782726,400.0,0.9938699,0.64295542,8.1612253,392.45593,-9.266634
178.8564,0.031726062,9.4577465,32.612686,0,10.236759,400.0,0.99496752,0.13795848,8.627018,393.19281,-9.265317
178.8588,0.20442145,9.450243,29.510199,0,10.695246,400.0,0.99490547,0.87103975,9.0910158,393.92969,-9.2658463
178.8612,0.13918394,9.4455051,26.407711,0,11.153732,400.0,0.99462849,0.67742562,9.5736151,394.66656,-9.2659101
178.8636,0.024840714,9.4504814,23.356934,0,11.612218,400.0,0.99489397,0.11132257,10.039812,395.4025,-9.2665167
178.866,0.12022236,9.4502916,23.356934,0,12.070705,400.0,0.9936505,0.50587296,10.52065,396.08115,-9.2652082
178.8684,0.12251383,9.4496613,23.356934,0,12.529191,400.0,0.99325395,0.63390446,10.989486,396.7598,-9.264966
178.8708,0.11970451,9.4503021,23.356934,0,12.987678,400.0,0.99400228,0.54726708,11.467233,397.43845,-9.2647362
178.8732,0.10578492,9.4467325,23.356934,0,13.446164,400.0,0.99444926,0.51880831,11.930884,398.1171,-9.2657642
178.8756,0.12301407,9.4439754,18.648249,0,13.904651,400.0,0.99431312,0.55097097,12.378717,398.67358,-9.2659512
178.878,0.10819256,9.4514732,13.053774,0,14.363137,400.0,0.99487013,0.51796651,12.831407,399.20709,-9.2649841
178.8804,0.16500703,9.4548874,7.4592981,0,14.821624,400.0,0.99446386,0.79127514,13.301276,399.7406,-9.2639074
178.8828,0.099211931,9.4586134,1.8648245,0,15.28011,400.0,0.99441606,0.49594161,13.781616,400.27414,-9.263669
178.8852,0.043544509,9.4576435,0.0,0,15.738596,400.0,0.99538267,0.19201185,14.253669,400.81244,-9.2633018
178.8876,0.18604954,9.4494505,0.0,0,16.197083,400.0,0.99514019,0.87299967,14.739577,401.35318,-9.263586
178.89,0.10267862,9.444067,0.0,0,16.655569,400.0,0.99441111,0.55920219,15.208323,401.89389,-9.2629938
178.8924,0.10713498,9.4476185,0.0,0,17.114056,400.0,0.99368751,0.50785965,15.658825,402.4346,-9.2632504
178.8948,0.13683648,9.4510021,0.0,0,17.572542,400.0,0.99350333,0.67676222,16.117416,402.92215,-9.2628269
178.8972,0.054036148,9.4525738,0.0,0,17.999401,400.0,0.99397361,0.2780962,16.564373,403.35474,-9.2620926
178.8996,0.11560482,9.4521046,0.0,0,18.0,400.0,0.99481517,0.51810592,17.014048,403.78729,-9.2637749
178.902,0.14957057,9.448493,0.0,0,18.0,400.0,0.99501663,0.7146818,17.44379,404.21988,-9.2634306
178.9044,0.10917977,9.4464235,0.0,0,18.0,400.0,0.9941929,0.47899082,17.821978,404.64789,-9.2641487
178.9068,0.174181,9.4498205,0.0,0,18.0,400.0,0.99383646,0.86267912,18.141941,405.06604,-9.26583
178.9092,0.16726737,9.4584532,0.0,0,18.0,400.0,0.99447,0.77287501,18.362652,405.48422,-9.2679892
178.9116,0.25229961,9.4586,0.0,0,18.0,400.0,0.99497789,1.1685331,18.457504,405.90237,-9.2728109
178.914,0.21448207,9.4562616,0.0,0,18.0,400.0,0.995974,1.0830941,18.440617,406.31134,-9.2800817
178.9164,0.22650498,9.452693,0.0,0,18.0,400.0,0.99581265,1.0232135,18.334692,406.66461,-9.2898741
178.9188,0.2085641,9.4511108,0.0,0,18.0,400.0,0.99488252,0.98034555,18.219074,407.01788,-9.3025656
178.9212,0.26676932,9.450263,0.0,0,18.0,400.0,0.99368203,1.2045068,18.127586,407.37115,-9.3174448
178.9236,0.25216851,9.4524717,0.0,0,18.0,400.0,0.99371773,1.2136452,18.072527,407.72443,-9.3356838
178.926,0.21883379,9.4518595,0.0,0,18.0,400.0,0.99444789,1.0213469,18.058485,408.03589,-9.3568554
178.9284,0.19274664,9.448802,0.0,0,18.0,400.0,0.99482167,0.9026255,18.059427,408.34592,-9.3773069
178.9308,0.21480374,9.4471846,0.0,0,18.0,400.0,0.99488544,1.000231,18.075388,408.65591,-9.3975868
178.9332,0.24512456,9.444705,0.0,0,18.0,400.0,0.99357748,1.1742589,18.096815,408.96594,-9.4155703
178.9356,0.23048721,9.4501543,0.0,0,18.0,400.0,0.99336559,1.1217403,18.115431,409.27594,-9.434618
178.938,0.20940913,9.4562263,0.0,0,18.0,400.0,0.99416858,0.99048096,18.130667,409.58597,-9.4552279
178.9404,0.21019211,9.4534883,0.0,0,18.0,400.0,0.99484771,0.97096342,18.140881,409.89597,-9.4726267
178.9428,0.25668544,9.4465475,0.0,0,18.0,400.0,0.99466246,1.2031484,18.144619,410.20599,-9.4883633
178.9452,0.26331937,9.4447565,0.0,0,18.0,400.0,0.99428749,1.2386895,18.144781,410.50711,-9.5054426
178.9476,0.23720741,9.4460697,0.0,0,18.0,400.0,0.99343807,1.1750333,18.144457,410.8027,-9.5237093
178.95,0.22972313,9.4499235,0.0,0,18.0,400.0,0.99323261,1.0865872,18.140667,411.09827,-9.5404778
178.9524,0.2490554,9.4498291,0.0,0,18.0,400.0,0.9936741,1.1708417,18.138151,411.39386,-9.5571766
178.9548,0.28114742,9.446969,0.0,0,18.0,400.0,0.99398702,1.3105763,18.132511,411.67667,-9.5746813
178.9572,0.26776347,9.4424267,0.0,0,18.0,400.0,0.99403191,1.2646263,18.134497,411.9433,-9.5923386
178.9596,0.24207534,9.4465313,0.0,0,18.0,400.0,0.99421912,1.128202,18.129116,412.2099,-9.6121149
178.962,0.25090796,9.4486055,0.0,0,18.0,400.0,0.99340683,1.146015,18.122437,412.47653,-9.6314163
178.9644,0.28188518,9.4552116,0.0,0,18.0,400.0,0.99390668,1.3505551,18.122252,412.73926,-9.649004
178.9668,0.27951929,9.4541445,0.0,0,18.0,400.0,0.99429786,1.3307498,18.119911,412.99118,-9.6653881
178.9692,0.25912163,9.4501114,0.0,0,18.0,400.0,0.9949367,1.2393447,18.117043,413.24313,-9.681819
178.9716,0.24427316,9.4467573,0.0,0,18.0,400.0,0.99488294,1.1546593,18.115416,413.49509,-9.7008181
178.974,0.26778099,9.4462957,0.0,0,18.0,400.0,0.99399132,1.2197595,18.113375,413.74371,-9.7189665
178.9764,0.28905094,9.446599,0.0,0,18.0,400.0,0.99296838,1.3847704,18.111094,413.95959,-9.7358618
178.9788,0.28424945,9.4490652,0.0,0,18.0,400.0,0.99316394,1.3366969,18.112499,414.17545,-9.7534599
178.9812,0.25327048,9.4518309,0.0,0,18.0,400.0,0.99450582,1.1848491,18.111969,414.39133,-9.7715797
178.9836,0.24573231,9.4492493,0.0,0,18.0,400.0,0.99494189,1.1354634,18.117023,414.60721,-9.7893581
178.986,0.28997254,9.4449167,0.0,0,18.0,400.0,0.99422914,1.3582159,18.110704,414.80988,-9.8072767
178.9884,0.28008288,9.4452658,0.0,0,18.0,400.0,0.99339432,1.3072977,18.108286,415.01135,-9.8262129
178.9908,0.26085418,9.4537487,0.0,0,18.0,400.0,0.99388993,1.2781234,18.107225,415.21283,-9.8448734
178.9932,0.23773435,9.4559679,0.0,0,18.0,400.0,0.99412888,1.1237737,18.105774,415.41431,-9.8619509
178.9956,0.27539116,9.4527245,0.0,0,18.0,400.0,0.99477422,1.2254606,18.102352,415.61044,-9.8788042
178.998,0.29077002,9.4485321,0.0,0,18.0,400.0,0.99519569,1.3629773,18.102652,415.80472,-9.8954725
179.0004,0.28697947,9.446497,0.0,0,18.0,400.0,0.99449342,1.3641083,18.104446,415.99899,-9.9146595
179.0028,0.2631107,9.447566,0.0,0,18.0,400.0,0.99348801,1.2476945,18.101631,416.19327,-9.9323759
179.0052,0.25934234,9.4489079,0.0,0,18.0,400.0,0.99310738,1.2126162,18.100752,416.3631,-9.9494343
179.0076,0.29743645,9.449482,0.0,0,18.0,400.0,0.9935028,1.3805277,18.101048,416.51422,-9.9659948
179.01,0.29888162,9.4471693,0.0,0,18.0,400.0,0.99419206,1.4021991,18.104149,416.66531,-9.9824324
179.0124,0.29893062,9.4438114,0.0,0,18.0,400.0,0.99421591,1.3687413,18.098841,416.81644,-10.001085
179.0148,0.2586737,9.4462328,0.0,0,18.0,400.0,0.99405897,1.23482,18.097891,416.96191,-10.019625
179.0172,0.28886321,9.4503469,0.0,0,18.0,400.0,0.99374193,1.3260633,18.098396,417.0986,-10.037864
179.0196,0.31504676,9.4524002,0.0,0,18.0,400.0,0.99331504,1.4837505,18.099127,417.23532,-10.053833
179.022,0.3138569,9.4536514,0.0,0,18.0,400.0,0.99432737,1.4606861,18.093443,417.37204,-10.072253
179.0244,0.28517205,9.4519815,0.0,0,18.0,400.0,0.99535871,1.3810438,18.097197,417.51187,-10.090424
179.0268,0.28340065,9.4454498,0.0,0,18.0,400.0,0.99454629,1.352369,18.093851,417.66296,-10.109989
179.0292,0.31965631,9.4438019,0.0,0,18.0,400.0,0.99329722,1.4657812,18.091711,417.81409,-10.126797
179.0316,0.32430694,9.4470997,0.0,0,18.0,400.0,0.99296087,1.5068793,18.094349,417.96521,-10.143862
179.034,0.32386717,9.4509258,0.0,0,18.0,400.0,0.99340498,1.5389059,18.092649,418.11511,-10.162418
179.0364,0.28750479,9.4514036,0.0,0,18.0,400.0,0.994569,1.3864354,18.092138,418.23743,-10.180451
179.0388,0.31988037,9.4455042,0.0,0,18.0,400.0,0.99453276,1.4686567,18.090847,418.35977,-10.197444
179.0412,0.33956218,9.4436131,0.0,0,18.0,400.0,0.99399531,1.586288,18.090197,418.48209,-10.215398
179.0436,0.32593229,9.4466505,0.0,0,18.0,400.0,0.99362355,1.5715946,18.094303,418.60443,-10.23302
179.046,0.33153725,9.4526663,0.0,0,18.0,400.0,0.99374253,1.5836414,18.084671,418.68307,-10.251083
179.0484,0.2895458,9.4548588,0.0,0,18.0,400.0,0.99424905,1.3757625,18.08708,418.75504,-10.268346
179.0508,0.32909939,9.4532909,0.0,0,18.0,400.0,0.9950583,1.5288246,18.084465,418.827,-10.28615
179.0532,0.33932883,9.4473867,0.0,0,18.0,400.0,0.99493623,1.6043257,18.089094,418.89896,-10.304229
179.0556,0.32703575,9.4457464,0.0,0,18.0,400.0,0.99432766,1.5197421,18.085218,419.00076,-10.320891
179.058,0.3133772,9.4482374,0.0,0,18.0,400.0,0.99361372,1.4752791,18.087706,419.11591,-10.339555
179.0604,0.31893238,9.4501715,0.0,0,18.0,400.0,0.99329466,1.4952226,18.085489,419.23102,-10.357005
179.0628,0.33818612,9.4498911,0.0,0,18.0,400.0,0.99377292,1.6138773,18.081577,419.34616,-10.37448
179.0652,0.3329401,9.4476252,0.0,0,18.0,400.0,0.99421328,1.5601833,18.080374,419.45755,-10.391075
179.0676,0.33953661,9.444541,0.0,0,18.0,400.0,0.99442059,1.600881,18.085262,419.56549,-10.408809
179.07,0.30665097,9.4448643,0.0,0,18.0,400.0,0.99395818,1.448458,18.086813,419.67343,-10.427009
179.0724,0.33153817,9.4513426,0.0,0,18.0,400.0,0.99375713,1.5415603,18.083668,419.78137,-10.445304
179.0748,0.35023016,9.4551201,0.0,0,18.0,400.0,0.99379289,1.6423619,18.077808,419.8721,-10.462961
179.0772,0.32706901,9.4530582,0.0,0,18.0,400.0,0.99425268,1.5354507,18.080435,419.92966,-10.481068
179.0796,0.32199666,9.4495325,0.0,0,18.0,400.0,0.99503648,1.5008203,18.078663,419.98721,-10.499771
179.082,0.33102131,9.4442911,0.0,0,18.0,400.0,0.99435169,1.536369,18.078529,420.0448,-10.516786
179.0844,0.34735373,9.4421816,0.0,0,18.0,400.0,0.99301267,1.6033982,18.078932,420.10596,-10.533805
179.0868,0.35767108,9.4490795,0.0,0,18.0,400.0,0.99319845,1.6761614,18.077194,420.18512,-10.552191
179.0892,0.33726662,9.4514761,0.0,0,18.0,400.0,0.99383193,1.5984869,18.075937,420.26425,-10.569729
179.0916,0.32097423,9.4515858,0.0,0,18.0,400.0,0.99468166,1.5279506,18.074511,420.34341,-10.586617
179.094,0.3463943,9.4463396,0.0,0,18.0,400.0,0.99471068,1.6147716,18.074144,420.42255,-10.604853
179.0964,0.36696443,9.4433193,0.0,0,18.0,400.0,0.9939518,1.7222569,18.074886,420.48743,-10.622245
179.0988,0.36619416,9.4464092,0.0,0,18.0,400.0,0.99340266,1.7137766,18.073042,420.55222,-10.64181
179.1012,0.34506217,9.4536629,0.0,0,18.0,400.0,0.99382937,1.6561538,18.071802,420.61697,-10.660124
179.1036,0.34518933,9.4556103,0.0,0,18.0,400.0,0.99443519,1.6270642,18.070858,420.68173,-10.678134
179.106,0.36514071,9.4504356,0.0,0,18.0,400.0,0.99467254,1.6869594,18.06959,420.73474,-10.694955
179.1084,0.37669554,9.4446955,0.0,0,18.0,400.0,0.99446309,1.7790942,18.065237,420.7851,-10.712276
179.1108,0.36855593,9.4441299,0.0,0,18.0,400.0,0.99385798,1.7457943,18.065742,420.83548,-10.729311
179.1132,0.34792116,9.446702,0.0,0,18.0,400.0,0.99320465,1.6536093,18.06616,420.88586,-10.748129
179.1156,0.36873725,9.4496078,0.0,0,18.0,400.0,0.9933089,1.7163302,18.066114,420.93622,-10.764581
179.118,0.38367742,9.447197,0.0,0,18.0,400.0,0.9932974,1.7950624,18.066542,420.9866,-10.781946
179.1204,0.37329555,9.447628,0.0,0,18.0,400.0,0.99435246,1.7713217,18.063578,421.03696,-10.799621
179.1228,0.36984202,9.4457064,0.0,0,18.0,400.0,0.99454325,1.7222513,18.06439,421.08734,-10.818555
179.1252,0.36046797,9.4450455,0.0,0,18.0,400.0,0.99382377,1.6963773,18.06266,421.1377,-10.836535
179.1276,0.36254421,9.450882,0.0,0,18.0,400.0,0.99352551,1.7185807,18.064911,421.18808,-10.853375
179.13,0.38740456,9.454628,0.0,0,18.0,400.0,0.99384516,1.8149542,18.064095,421.23843,-10.870582
179.1324,0.36434072,9.4538355,0.0,0,18.0,400.0,0.99460018,1.7549388,18.063417,421.28882,-10.888494
179.1348,0.35974303,9.4474907,0.0,0,18.0,400.0,0.9947288,1.6832726,18.064432,421.34128,-10.906859
179.1372,0.36791712,9.4441957,0.0,0,18.0,400.0,0.99430221,1.6958426,18.063576,421.39883,-10.925737
179.1396,0.3919225,9.4465637,0.0,0,18.0,400.0,0.99354511,1.8393936,18.063881,421.45642,-10.943278
179.142,0.3812387,9.4529066,0.0,0,18.0,400.0,0.99365526,1.8277745,18.059849,421.51398,-10.960782
179.1444,0.36330822,9.4517775,0.0,0,18.0,400.0,0.99374264,1.7459855,18.05994,421.56735,-10.979809
179.1468,0.36394525,9.4485168,0.0,0,18.0,400.0,0.99417049,1.7208915,18.061808,421.58893,-10.997305
179.1492,0.36918902,9.4438934,0.0,0,18.0,400.0,0.99418497,1.7113711,18.059586,421.6105,-11.013549
179.1516,0.3949177,9.4442997,0.0,0,18.0,400.0,0.99401695,1.8463595,18.059017,421.63208,-11.030612
179.154,0.38195825,9.4488583,0.0,0,18.0,400.0,0.99361259,1.7962427,18.05868,421.65369,-11.049749
179.1564,0.36406589,9.4538927,0.0,0,18.0,400.0,0.99373245,1.7145809,18.058422,421.69559,-11.067196
179.1588,0.38825706,9.453125,0.0,0,18.0,400.0,0.99385518,1.8302823,18.058123,421.73877,-11.084385
179.1612,0.40278557,9.4507694,0.0,0,18.0,400.0,0.9948495,1.8921306,18.054989,421.78195,-11.101858
179.1636,0.40341154,9.44594,0.0,0,18.0,400.0,0.99473256,1.9190292,18.058235,421.82513,-11.119862
179.166,0.38469172,9.4437628,0.0,0,18.0,400.0,0.99363613,1.80507,18.055714,421.86279,-11.139111
179.1684,0.3699072,9.4453821,0.0,0,18.0,400.0,0.99284244,1.7498453,18.056175,421.89877,-11.155643
179.1708,0.38622141,9.4484539,0.0,0,18.0,400.0,0.9929179,1.7939698,18.055885,421.93475,-11.172336
179.1732,0.41959813,9.448452,0.0,0,18.0,400.0,0.99373055,1.9683105,18.057096,421.97073,-11.189637
179.1756,0.4034186,9.4498491,0.0,0,18.0,400.0,0.99501151,1.9078763,18.054596,421.98114,-11.208785
179.178,0.38163382,9.4464569,0.0,0,18.0,400.0,0.99456912,1.7898976,18.056433,421.97394,-11.227626
179.1804,0.402491,9.4443769,0.0,0,18.0,400.0,0.99338144,1.8881062,18.05278,421.96677,-11.244744
179.1828,0.4093363,9.4497042,0.0,0,18.0,400.0,0.9932847,1.9296808,18.051878,421.95956,-11.262193
179.1852,0.41952819,9.4537106,0.0,0,18.0,400.0,0.99378401,2.0014002,18.053486,421.97034,-11.280351
179.1876,0.39289761,9.4547377,0.0,0,18.0,400.0,0.99491477,1.8923911,18.050438,422.00632,-11.29938
179.19,0.39440534,9.447567,0.0,0,18.0,400.0,0.99482453,1.8474656,18.050123,422.0423,-11.316978
179.1924,0.41316846,9.441102,0.0,0,18.0,400.0,0.99376959,1.9123127,18.050478,422.07828,-11.333033
179.1948,0.41633496,9.445075,0.0,0,18.0,400.0,0.99331748,1.9713112,18.048639,422.11078,-11.351284
179.2969,0.40689501,9.448143,0.0,0,18.0,17.344154,0.99398398,1.9189961,18.038958,418.0531,-11.469373
180.4969,0.43606979,9.4579754,0.0,0,18.0,7.588628e-16,0.99580556,2.0536776,18.000645,387.42545,-11.481112
181.6969,0.47367939,9.4653034,0.0,0,18.0,3.2805517000000004e-32,0.99689198,2.2184343,18.000383,373.61005,-11.481745
182.8969,0.46832722,9.4711113,0.0,0,18.0,1.4012985e-45,0.99813622,2.1982574,17.998995,362.1069,-11.481992
184.0969,0.47689804,9.4763546,0.0,0,18.0,1.4012985e-45,0.99911135,2.2398982,17.999746,351.53998,-11.481776
185.2969,0.48940265,9.4818773,0.0,0,18.0,1.4012985e-45,0.99991006,2.2937813,17.999197,341.46143,-11.481595
186.4969,0.50149387,9.4864607,0.0,0,18.0,1.4012985e-45,1.0009441,2.3463051,18.000601,331.89594,-11.481441
187.6969,0.51520228,9.4913082,0.0,0,18.0,1.4012985e-45,1.0017911,2.4100726,18.000191,322.36954,-11.481874
188.8969,0.52533776,9.4963646,0.0,0,18.0,1.4012985e-45,1.0025718,2.4568622,18.0002,313.54095,-11.482342
190.0969,0.53557771,9.5013189,0.0,0,18.0,1.4012985e-45,1.0036072,2.5012012,18.000441,304.55704,-11.482711
191.2969,0.52628058,9.5051146,0.0,0,18.0,1.4012985e-45,1.0042248,2.4597516,17.999224,297.30829,-11.482706
192.4969,0.53418094,9.509573,0.0,0,18.0,1.4012985e-45,1.0050452,2.4909656,18.000473,289.81067,-11.482146
193.6969,0.54828954,9.5142555,0.0,0,18.0,1.4012985e-45,1.0058576,2.5574615,18.000854,282.54977,-11.482595
194.8969,0.56318259,9.5180531,0.0,0,18.0,1.4012985e-45,1.0065262,2.6244276,18.000286,275.103,-11.482737
196.0969,0.56809455,9.5222683,0.0,0,18.0,1.4012985e-45,1.0074401,2.6389978,18.001299,268.37982,-11.4822
197.2969,0.56292582,9.5266256,0.0,0,18.0,1.4012985e-45,1.0080543,2.6186774,17.999783,261.42657,-11.482184
198.4969,0.57215971,9.5300236,0.0,0,18.0,1.4012985e-45,1.0087692,2.655453,18.000057,254.72702,-11.482389
199.6969,0.58190185,9.5339346,0.0,0,18.0,1.4012985e-45,1.0096542,2.6933577,18.000589,248.96606,-11.482371
200.8969,0.5878979,9.5376854,0.0,0,18.0,1.4012985e-45,1.0100937,2.7290981,18.001133,243.32127,-11.482626
202.0969,0.59888422,9.5416431,0.0,0,18.0,1.4012985e-45,1.0110006,2.766541,18.000647,237.09891,-11.48283
203.2969,0.59299827,9.5454903,0.0,0,18.0,1.4012985e-45,1.0116504,2.745698,18.001009,231.14201,-11.482622
204.4969,0.60422367,9.549262,0.0,0,18.0,1.4012985e-45,1.0122552,2.7932947,18.000151,224.95792,-11.482361
205.6969,0.60106581,9.5532217,0.0,0,18.0,1.4012985e-45,1.0130588,2.7741807,18.000202,218.99803,-11.48235
206.8969,0.6058498,9.5567598,0.0,0,18.0,1.4012985e-45,1.0136321,2.797694,18.000132,213.46741,-11.482207
208.0969,0.60550505,9.5594501,0.0,0,18.0,1.4012985e-45,1.0142564,2.7937474,18.000002,208.04723,-11.481604
209.2969,0.61284947,9.5632963,0.0,0,18.0,1.4012985e-45,1.0147604,2.8263652,18.000027,202.56288,-11.482
210.4969,0.61927515,9.5667562,0.0,0,18.0,1.4012985e-45,1.0155077,2.8546109,18.000128,196.75609,-11.482214
211.6969,0.62496758,9.5692568,0.0,0,18.0,1.4012985e-45,1.0161362,2.8778677,17.999678,191.70193,-11.482412
212.8969,0.62917155,9.5730228,0.0,0,18.0,1.4012985e-45,1.0165572,2.8993387,18.000423,186.71367,-11.482423
214.0969,0.63551253,9.5760527,0.0,0,18.0,1.4012985e-45,1.0173211,2.9259362,18.000582,181.67389,-11.482576
215.2969,0.63364506,9.5789223,0.0,0,18.0,1.4012985e-45,1.0177497,2.920877,18.000109,177.1584,-11.482304
216.4969,0.63429117,9.5815849,0.0,0,18.0,1.4012985e-45,1.0182365,2.9221487,18.000387,172.73317,-11.481766
217.6969,0.64056766,9.5845242,0.0,0,18.0,1.4012985e-45,1.0187118,2.9481344,17.999947,168.81036,-11.481489
218.8969,0.63683707,9.5872469,0.0,0,18.0,1.4012985e-45,1.0192646,2.9312906,17.999945,164.66101,-11.481207
220.0969,0.63881671,9.5897255,0.0,0,18.0,1.4012985e-45,1.0198909,2.9412127,18.000334,160.96687,-11.480541
221.2969,0.64666718,9.5926285,0.0,0,18.0,1.4012985e-45,1.0201604,2.9715717,17.999609,157.26141,-11.48066
222.4969,0.67314303,9.5946827,0.0,0,18.0,1.4012985e-45,1.0207694,3.0897462,18.000038,153.63251,-11.481434
223.6969,0.68050557,9.5979729,0.0,0,18.0,1.4012985e-45,1.0212721,3.1255295,18.000813,149.99989,-11.482247
224.8969,0.68227637,9.600153,0.0,0,18.0,1.4012985e-45,1.0217206,3.1309071,18.000219,146.86816,-11.482347
226.0969,0.68211591,9.602561,0.0,0,18.0,1.4012985e-45,1.0220224,3.1286666,18.000616,143.59592,-11.482411
227.2969,0.6872803,9.6049767,0.0,0,18.0,1.4012985e-45,1.0225608,3.153265,18.000559,140.42482,-11.482375
228.4969,0.67905349,9.6068516,0.0,0,18.0,1.4012985e-45,1.023047,3.1110375,17.999498,137.29279,-11.481865
229.6969,0.68583208,9.6095047,0.0,0,18.0,1.4012985e-45,1.0233371,3.1381252,18.000032,134.27425,-11.482137
230.8969,0.69362563,9.6116209,0.0,0,18.0,1.4012985e-45,1.0238843,3.1716335,17.999783,131.28404,-11.48166
232.0969,0.68911189,9.6142111,0.0,0,18.0,1.4012985e-45,1.02422,3.1522684,18.000124,128.4483,-11.481102
233.2969,0.68747526,9.6157131,0.0,0,18.0,1.4012985e-45,1.024642,3.1390634,18.000769,125.65733,-11.481099
234.4969,0.69208229,9.6181774,0.0,0,18.0,1.4012985e-45,1.0248893,3.1592219,17.999319,122.85287,-11.480795
235.6969,0.69682461,9.6197281,0.0,0,18.0,1.4012985e-45,1.0253582,3.178401,17.999756,120.29589,-11.480538
236.8969,0.6991809,9.6217766,0.0,0,18.0,1.4012985e-45,1.0257812,3.1868236,18.000544,117.57735,-11.480965
238.0969,0.70454097,9.6238241,0.0,0,18.0,1.4012985e-45,1.0260293,3.2150087,18.000122,115.07719,-11.481596
239.1969,0.70626509,9.6254759,0.0,0,18.0,1.4012985e-45,1.0262923,3.2221482,18.000116,112.78572,-11.481895