File: examples/hot axisymmetric compression example/data/02 screened data/testID_0129.csv
Time(sec),Force(kN),Jaw(mm),PowAngle(deg),Power(W),Pram,PTemp,Strain,Stress(MPa),Stroke(mm),TC1(C),wedge(mm)
0.0,0.84061706,0.14502822,0.0,0,11.076097,0.0016473189,0.0097334338,10.588595,11.076447,39.324081,-9.1231451
1.1,0.79350352,-0.0015416552,0.0,0,11.076097,3.2158811,-0.00011718368,10.088099,11.076463,39.211082,-9.4924831
2.2,0.76841259,-0.0014677055,0.0,0,11.076097,6.5158839,-0.00010414964,9.7812881,11.075753,39.096256,-9.4899302
3.3,0.75020283,-0.0017866608,0.0,0,11.076097,9.8158817,-0.00013198919,9.5506239,11.076018,39.010956,-9.4886246
4.4,0.7372641,-0.0015424292,0.0,0,11.076097,13.115883,-9.8981654e-05,9.3863478,11.076169,38.859417,-9.4867058
5.5,0.7189132,-0.0014938955,0.0,0,11.076097,16.415884,-7.664338e-05,9.1580572,11.075934,38.789764,-9.4845715
6.6,0.70468593,-0.0017031648,0.0,0,11.076097,19.715883,-0.00013223852,8.9662447,11.076397,38.629681,-9.4827585
7.7,0.70307946,-0.0014765705,0.0,0,11.076097,23.015888,-8.9867361e-05,8.9334679,11.075886,38.584591,-9.4808064
8.8,0.68472511,-0.0017667144,0.0,0,11.076097,26.315884,-9.9716082e-05,8.7330189,11.075628,38.496197,-9.478507
9.9,0.68213987,-0.0012234629,0.0,0,11.076097,29.615881,-0.00010142117,8.6748171,11.07613,38.345463,-9.476697
11.0,0.67335409,-0.0014392788,0.0,0,11.076097,32.915894,-9.760051e-05,8.5648556,11.075363,38.30077,-9.4748077
12.1,0.67048681,-0.0013032579,0.0,0,11.076097,36.215893,-8.3496816e-05,8.533535,11.075956,38.124012,-9.4734707
13.2,0.67291427,-0.0012181647,7.6533031,0,11.076097,39.515896,-9.6989352e-05,8.5754795,11.075805,38.064011,-9.4717064
14.3,0.66297197,-0.00098627002,25.215849,0,11.076097,42.815891,-6.2181658e-05,8.4345398,11.075757,38.324375,-9.469492
15.4,0.67131424,-0.0018464806,34.469547,0,11.076097,46.115894,-0.00013091952,8.5420713,11.076058,39.874531,-9.468173
16.5,0.67013949,-0.0033694801,39.78363,0,11.076097,49.415886,-0.00022249727,8.5342245,11.07604,42.500656,-9.4659309
17.6,0.68640554,-0.0053543085,43.411797,0,11.076097,52.715885,-0.00034413568,8.7222528,11.075749,45.787537,-9.4641123
18.7,0.68920463,-0.0076268488,45.61462,0,11.076097,56.015884,-0.00052866497,8.7716684,11.074772,49.68145,-9.4618216
19.8,0.69505984,-0.010543069,47.054306,0,11.076097,59.315884,-0.00069732184,8.8566408,11.076677,54.039318,-9.4600849
20.9,0.69032729,-0.013679724,47.504883,0,11.076097,62.615883,-0.00088904623,8.8037958,11.075521,58.727715,-9.4576979
22.0,0.70424783,-0.016132958,47.505505,0,11.076097,65.915894,-0.0010975082,8.9691401,11.075543,63.46394,-9.4560232
23.1,0.70257699,-0.019351635,47.233688,0,11.076097,69.215889,-0.0012844249,8.9590988,11.075504,67.905785,-9.4539051
24.2,0.70280176,-0.021916274,46.640465,0,11.076097,72.515892,-0.0014457235,8.9622536,11.075558,72.06971,-9.4521112
25.3,0.70741534,-0.023876972,46.112183,0,11.076097,75.815887,-0.0016062187,9.0147219,11.076047,75.976089,-9.4505129
26.4,0.71631455,-0.025950851,45.615463,0,11.076097,79.115891,-0.0017328929,9.1264448,11.076123,79.678864,-9.4488678
27.5,0.71608299,-0.028041605,45.615238,0,11.076097,82.415886,-0.0018672235,9.1303005,11.075294,82.976952,-9.4469423
28.6,0.70718706,-0.03026901,45.465675,0,11.076097,85.715889,-0.0020226291,9.0279579,11.076408,86.16597,-9.4446878
29.7,0.71260285,-0.032746021,45.604362,0,11.076097,89.015877,-0.002179614,9.0939798,11.075959,89.240555,-9.4426823
30.8,0.71897376,-0.034956377,45.615231,0,11.076097,92.315887,-0.0023384935,9.1777754,11.075577,92.277443,-9.4406099
31.9,0.72206384,-0.037160955,46.109619,0,11.076097,95.615883,-0.002473345,9.2225981,11.075875,95.273697,-9.4390459
33.0,0.71905512,-0.038998026,46.582027,0,11.076097,98.915878,-0.0025833035,9.173358,11.075519,98.155815,-9.437067
34.1,0.71504539,-0.040962715,47.05444,0,11.076097,102.21589,-0.0027426218,9.1248245,11.075676,101.24261,-9.4352512
35.2,0.7202915,-0.043266263,47.73315,0,11.076097,105.51588,-0.002870139,9.2125664,11.07601,104.43371,-9.4335966
36.3,0.71585035,-0.045723487,48.313282,0,11.076097,108.8159,-0.0030178952,9.1525831,11.076262,107.63913,-9.4315386
37.4,0.72978032,-0.047560502,48.559074,0,11.076097,112.11589,-0.0031868441,9.3215857,11.075785,111.01088,-9.4301224
38.5,0.72576672,-0.050549757,48.846317,0,11.076097,115.41589,-0.0033486292,9.2668934,11.075352,114.30765,-9.4280386
39.6,0.73396087,-0.052893676,49.229733,0,11.076097,118.7159,-0.0035008518,9.3722172,11.076467,117.61389,-9.4262171
40.7,0.73737246,-0.054905817,49.636227,0,11.076097,122.0159,-0.0036738077,9.4316359,11.075693,121.05381,-9.4241505
41.8,0.73100811,-0.057511792,49.793591,0,11.076097,125.3159,-0.0038175886,9.3522148,11.076714,124.45277,-9.4222898
42.9,0.7386145,-0.060325403,50.042709,0,11.076097,128.61603,-0.0039957874,9.450304,11.076377,127.90796,-9.4205265
44.0,0.74017364,-0.063042819,50.042721,0,11.076097,131.91591,-0.0042177737,9.4639034,11.074825,131.31508,-9.4183064
45.1,0.7443096,-0.065776192,50.067696,0,11.076097,135.2159,-0.0043748571,9.5185862,11.075139,134.75139,-9.4164629
46.2,0.74697685,-0.067678303,50.438229,0,11.076097,138.51588,-0.0044843811,9.5557737,11.07581,137.97949,-9.4145298
47.3,0.74444246,-0.06980063,50.807083,0,11.076097,141.81589,-0.0046658693,9.5176859,11.07596,141.24574,-9.4126291
48.4,0.74834067,-0.07222975,50.82275,0,11.076097,145.11589,-0.0048025385,9.5761471,11.076491,144.46599,-9.4110365
49.5,0.75147027,-0.074733101,51.07497,0,11.076097,148.41589,-0.0049633686,9.616971,11.076249,147.85114,-9.4094763
50.6,0.75510925,-0.077339597,51.196285,0,11.076097,151.71588,-0.0051553333,9.6662836,11.075786,151.13062,-9.407589
51.7,0.75146395,-0.079895563,51.569405,0,11.076097,155.01588,-0.0053102663,9.6178474,11.075817,154.42319,-9.4057341
52.8,0.76505357,-0.082559191,51.56982,0,11.076097,158.31587,-0.0054946863,9.7994432,11.076091,157.69991,-9.4044294
53.9,0.7720558,-0.085223712,51.92535,0,11.076097,161.61589,-0.0056647607,9.882865,11.075962,160.99318,-9.4024601
55.0,0.77262175,-0.089123242,51.932369,0,11.076097,164.91589,-0.0059201168,9.8992929,11.075121,164.4147,-9.4002848
56.1,0.77207839,-0.091496579,52.272797,0,11.076097,168.2159,-0.006096377,9.8834457,11.075878,167.62039,-9.3984232
57.2,0.76723665,-0.093882568,52.288109,0,11.076097,171.51591,-0.0062341299,9.8173103,11.077014,170.93625,-9.3964949
58.3,0.76476419,-0.096484944,52.635494,0,11.076097,174.81592,-0.0063918191,9.8057661,11.076437,174.2101,-9.3945665
59.4,0.774598,-0.099036075,52.635494,0,11.076097,178.11591,-0.0065974873,9.9270744,11.076126,177.52774,-9.3928595
60.5,0.7761116,-0.10210852,52.97541,0,11.076097,181.41589,-0.0067709582,9.9499302,11.075184,180.78596,-9.3909855
61.6,0.7814585,-0.10488021,53.059772,0,11.076097,184.71591,-0.0069475188,10.017837,11.075585,184.07813,-9.3887424
62.7,0.77857023,-0.1072138,53.31665,0,11.076097,188.0159,-0.0071479371,9.9747295,11.075771,187.29691,-9.3872395
63.8,0.78519523,-0.11020616,53.657223,0,11.076097,191.31589,-0.0073116068,10.084568,11.07529,190.49026,-9.3850317
64.9,0.79658878,-0.11352841,53.900658,0,11.076097,194.61591,-0.0075230156,10.231968,11.075815,193.82222,-9.3831539
66.0,0.79874349,-0.11661237,53.975826,0,11.076097,197.91589,-0.0077641485,10.250961,11.076107,197.20724,-9.3816748
67.1,0.7979005,-0.11959315,54.152889,0,11.076097,201.2159,-0.0079438556,10.238461,11.075122,200.57372,-9.3796749
68.2,0.79887116,-0.12195235,54.305355,0,11.076097,204.51588,-0.008079174,10.239678,11.075204,204.01566,-9.3782082
69.3,0.80194259,-0.12436869,54.305412,0,11.076097,207.81589,-0.0082732495,10.285924,11.075113,207.53444,-9.3763227
70.4,0.79559112,-0.12712885,54.305416,0,11.076097,211.11589,-0.0084388778,10.212879,11.076635,210.84111,-9.3747797
71.5,0.79683077,-0.12974438,54.305416,0,11.076097,214.41588,-0.0086089931,10.237033,11.075592,214.0336,-9.3729315
72.6,0.80151165,-0.13251847,54.623146,0,11.076097,217.71588,-0.0088007366,10.285689,11.076286,217.33153,-9.3710718
73.7,0.80041057,-0.1353305,54.624023,0,11.076097,221.01588,-0.0089803617,10.290626,11.076308,220.57231,-9.3695765
74.8,0.80398381,-0.13839763,54.931618,0,11.076097,224.31589,-0.0091953743,10.327531,11.075485,223.85359,-9.367487
75.9,0.79756826,-0.14127509,54.931637,0,11.076097,227.61591,-0.0093772365,10.243802,11.075989,227.21289,-9.3653507
77.0,0.80391967,-0.14435032,54.931637,0,11.076097,230.91589,-0.0095623154,10.336436,11.076442,230.58394,-9.3638325
78.1,0.80683225,-0.14686163,55.184578,0,11.076097,234.21591,-0.0097546428,10.372381,11.076778,233.79588,-9.3621387
79.2,0.8069275,-0.14975539,55.239254,0,11.076097,237.5159,-0.0099339848,10.379658,11.074991,237.07883,-9.3599205
80.3,0.80584872,-0.15287288,55.239254,0,11.076097,240.8159,-0.010117968,10.365019,11.075686,240.40593,-9.3580093
81.4,0.80865347,-0.15533178,55.524158,0,11.076097,244.11591,-0.010322232,10.402225,11.07679,243.64842,-9.3561172
82.5,0.82014453,-0.15846206,55.535885,0,11.076097,247.41591,-0.010495877,10.546439,11.075583,246.93727,-9.3543882
83.6,0.80924463,-0.16167417,55.535885,0,11.076097,250.71591,-0.010697956,10.414701,11.076796,250.36275,-9.3524551
84.7,0.8173036,-0.16448945,55.613209,0,11.076097,254.0159,-0.010926324,10.521058,11.076075,253.67094,-9.3504381
85.8,0.81790024,-0.16777477,55.841839,0,11.076097,257.31619,-0.011115639,10.528535,11.076274,256.94901,-9.348196
86.9,0.82078564,-0.17149945,55.843506,0,11.076097,260.61618,-0.011346294,10.57072,11.076985,260.22647,-9.3466902
88.0,0.82136887,-0.1745186,55.849102,0,11.076097,263.91589,-0.0115964,10.580935,11.075993,263.56998,-9.3446636
89.1,0.82072222,-0.17739934,55.888874,0,11.076097,267.21588,-0.01174714,10.578594,11.076485,266.92825,-9.3430882
90.2,0.8190282,-0.17993215,56.129147,0,11.076097,270.5159,-0.011908307,10.549358,11.075293,270.2023,-9.3413343
91.3,0.82000762,-0.18220146,56.129147,0,11.076097,273.81589,-0.012093404,10.563488,11.076137,273.45795,-9.3396263
92.4,0.80588865,-0.18520853,56.245319,0,11.076097,277.11588,-0.012272034,10.381839,11.075551,276.78693,-9.3373079
93.5,0.80779213,-0.18858716,56.425777,0,11.076097,280.41589,-0.012489039,10.411163,11.075405,280.04956,-9.3355131
94.6,0.81779742,-0.19121626,56.44767,0,11.076097,283.71591,-0.012686017,10.547232,11.076728,283.36093,-9.3341856
95.7,0.81026089,-0.19423097,56.689316,0,11.076097,287.0159,-0.012856216,10.463762,11.076551,286.56967,-9.3321753
96.8,0.81668288,-0.19736426,56.711422,0,11.076097,290.31595,-0.013072961,10.542624,11.076042,289.90744,-9.3302221
97.9,0.81698084,-0.2005606,56.870239,0,11.076097,293.61591,-0.013293534,10.552847,11.075386,293.20135,-9.328517
99.0,0.81773674,-0.20391223,56.986084,0,11.076097,296.91592,-0.013501982,10.561319,11.07575,296.54614,-9.3267488
100.1,0.81824774,-0.20702596,56.802052,0,11.076097,299.99539,-0.013709188,10.560392,11.076684,299.91309,-9.3250551
101.2,0.070057727,-0.22155516,54.363533,0,11.076097,299.99905,-0.014659221,0.91031039,11.075668,303.27124,-9.3248749
102.3,0.065346323,-0.22181089,51.604984,0,11.076097,299.99905,-0.014661411,0.86142987,11.075636,305.39847,-9.3252192
103.4,0.053268354,-0.22152252,49.654591,0,11.076097,299.99905,-0.014678611,0.70137131,11.075567,305.48758,-9.3254232
104.5,0.043691877,-0.22113374,49.174442,0,11.076097,299.99905,-0.014634417,0.57427251,11.07598,304.17041,-9.3251152
105.6,0.039466675,-0.2204202,49.635143,0,11.076097,299.99905,-0.014569155,0.52285057,11.075812,302.12589,-9.3248568
106.7,0.037374515,-0.219276,51.188171,0,11.076097,299.99905,-0.014532148,0.48530543,11.075692,299.73691,-9.3248262
107.8,0.037096251,-0.21855535,53.250717,0,11.076097,299.99905,-0.014452756,0.48854315,11.077134,297.51559,-9.3246851
108.9,0.035461161,-0.21818434,55.331211,0,11.076097,299.99905,-0.014416778,0.4737204,11.076044,295.66702,-9.3246098
110.0,0.038531736,-0.21774676,57.244965,0,11.076097,299.99905,-0.014429765,0.50420183,11.075484,294.37555,-9.3251123
111.1,0.043786537,-0.21797663,58.851463,0,11.076097,299.99905,-0.01442259,0.56744164,11.076309,293.85538,-9.3252468
112.2,0.044136718,-0.21859278,60.083988,0,11.076097,299.99905,-0.014444577,0.5814442,11.076982,294.01968,-9.3249836
113.3,0.055949725,-0.21864204,61.079861,0,11.076097,299.99905,-0.014485813,0.72556698,11.075429,294.42117,-9.324625
114.4,0.071214803,-0.21953984,61.595642,0,11.076097,299.99905,-0.014518333,0.91553819,11.0762,295.60638,-9.324626
115.5,0.069798872,-0.22099969,61.237804,0,11.076097,299.99905,-0.014599235,0.90356427,11.076682,297.74438,-9.3245382
116.6,0.074591093,-0.2217723,60.557304,0,11.076097,299.99905,-0.014694138,0.96913636,11.076391,299.7449,-9.3246536
117.7,0.071774147,-0.22281891,60.084251,0,11.076097,299.99905,-0.014739228,0.92220336,11.076888,300.65396,-9.3241596
118.8,0.078801349,-0.22340414,59.399834,0,11.076097,299.99905,-0.014760867,1.0172366,11.076521,301.46161,-9.3244495
119.9,0.075217418,-0.22383353,58.64677,0,11.076097,299.99905,-0.014825935,0.96882999,11.075165,302.17072,-9.3244238
121.0,0.072877474,-0.22442746,57.84053,0,11.076097,299.99905,-0.014838662,0.92957205,11.075826,302.70618,-9.3246183
122.1,0.071888767,-0.22519822,56.99514,0,11.076097,299.99905,-0.014875568,0.92508626,11.076027,303.06494,-9.3247995
123.2,0.073693506,-0.2254851,56.130356,0,11.076097,299.99905,-0.014942068,0.94183576,11.075918,303.27124,-9.324996
124.3,0.063532658,-0.22596911,55.242855,0,11.076097,299.99905,-0.014942984,0.82023388,11.075126,303.25201,-9.3244886
125.4,0.059969008,-0.22607706,54.624096,0,11.076097,299.99905,-0.014938939,0.77360696,11.076168,302.93832,-9.3245077
126.5,0.051827822,-0.2257695,54.305424,0,11.076097,299.99905,-0.014956704,0.67425406,11.075821,302.45282,-9.3242397
127.6,0.047194283,-0.22616269,54.114368,0,11.076097,299.99905,-0.014957719,0.61080623,11.076077,301.68683,-9.3238211
128.7,0.044611052,-0.22632971,54.305416,0,11.076097,299.99905,-0.014945704,0.56586993,11.075835,300.77469,-9.3237629
129.8,0.042090841,-0.22570869,54.919811,0,11.076097,299.99905,-0.014954668,0.53785032,11.076218,299.86655,-9.3236418
130.9,0.045234397,-0.22572465,55.624199,0,11.076097,299.99905,-0.014932932,0.58196068,11.076626,298.78137,-9.3239641
132.0,0.043912522,-0.22600693,56.705948,0,11.076097,299.99905,-0.01492824,0.56466836,11.075563,297.87457,-9.3241634
133.1,0.043797374,-0.22568502,57.71714,0,11.076097,299.99905,-0.014953766,0.5510357,11.076218,297.14285,-9.3242636
134.2,0.049788199,-0.22562544,58.589214,0,11.076097,299.99905,-0.014924021,0.63300002,11.075516,296.71286,-9.3243418
135.3,0.056089949,-0.22623645,59.249298,0,11.076097,299.99905,-0.014947194,0.72431087,11.075767,296.85135,-9.3244305
136.4,0.068763964,-0.22614121,59.600826,0,11.076097,299.99905,-0.014990753,0.89217216,11.075408,297.45468,-9.3240604
137.5,0.07492324,-0.22728848,59.600826,0,11.076097,299.99905,-0.015028339,0.9684093,11.076289,298.35138,-9.3236179
138.6,0.080196865,-0.22879069,59.109093,0,11.076097,299.99905,-0.015115739,1.0347643,11.07615,299.57242,-9.3234138
139.7,0.08421582,-0.22902301,58.590122,0,11.076097,299.99905,-0.015177882,1.0765214,11.075954,300.76636,-9.323472
140.8,0.083587937,-0.23026356,57.669338,0,11.076097,299.99905,-0.015222463,1.0728883,11.076278,301.80374,-9.3232641
141.9,0.088853806,-0.23089783,56.715832,0,11.076097,299.99905,-0.015257142,1.1513979,11.075839,302.56458,-9.3234949
143.0,0.08341267,-0.23137228,55.843616,0,11.076097,299.99905,-0.015328301,1.0760995,11.075208,302.98956,-9.3236179
144.1,0.08571858,-0.23186649,54.932014,0,11.076097,299.99905,-0.015335299,1.1041414,11.075952,303.2244,-9.3239899
145.1321,0.093159497,-0.0094220731,54.141087,0,11.076097,299.99905,-0.00064394082,1.1987114,11.075783,303.07602,-9.324213
145.2881,0.18741322,0.04518126,4.3180189,0,11.076099,6.0865757e-10,0.0028467139,2.3614953,11.074843,302.96664,-9.3242702
145.2903,0.18255673,0.04227861,0.0,0,11.076099,6.079146e-25,0.0030848235,2.4061174,11.075253,302.98752,-9.3247108
145.2925,0.17111452,0.046268784,0.0,0,11.076099,6.0717282e-40,0.0027854175,2.274267,11.077544,303.02805,-9.3243685
145.2947,0.1603031,0.039819118,0.0,0,11.076099,0.0,0.0029288391,2.2561064,11.076111,303.06857,-9.3242903
145.2969,0.16919795,0.042698473,0.0,0,11.076099,0.0,0.0027502957,2.1411004,11.075868,303.10913,-9.3237982
145.2991,0.17747356,0.042754833,0.0,0,11.076099,0.0,0.003121603,2.2447138,11.077957,303.14536,-9.3239574
145.3013,0.19106992,0.04765112,0.0,0,11.076099,0.0,0.0028368651,2.4114213,11.076056,303.13861,-9.3234987
145.3035,0.20378238,0.040428136,0.0,0,11.076099,0.0,0.0028723681,2.5845733,11.074733,303.13184,-9.3232269
145.3057,0.20122601,0.042991348,0.0,0,11.076099,0.0,0.0026757321,2.57143,11.077826,303.12509,-9.3235559
145.3079,0.19281387,0.040832572,0.0,0,11.076099,0.0,0.0030489794,2.4311404,11.075194,303.11835,-9.3227758
145.3101,0.19045135,0.049234699,0.0,0,11.076099,0.0,0.0030037258,2.3845139,11.07392,303.10788,-9.3231468
145.3123,0.18123038,0.041860051,0.0,0,11.076099,0.0,0.0029644279,2.3216252,11.074724,303.09439,-9.3246078
145.3145,0.17386042,0.044031199,0.0,0,11.076099,0.0,0.0028059301,2.3234916,11.073813,303.08087,-9.3243027
145.3167,0.18511066,0.041199382,0.0,0,11.076099,0.0,0.0029785002,2.3940842,11.07637,303.06735,-9.3243561
145.3189,0.19819885,0.048967466,0.0,0,11.076099,0.0,0.0029890165,2.5287592,11.076033,303.05383,-9.3248892
145.3211,0.20006356,0.042114113,0.0,0,11.076099,0.0,0.0029563988,2.5047879,11.076245,303.06735,-9.3242445
145.3233,0.20194353,0.043098986,0.0,0,11.076099,0.0,0.0028051145,2.5698824,11.07516,303.08087,-9.324523
145.3255,0.19033378,0.039888311,0.0,0,11.076099,0.0,0.0028685729,2.472363,11.074895,303.09439,-9.323945
145.3277,0.19516766,0.048018109,0.0,0,11.076099,0.0,0.0029581923,2.5246906,11.078269,303.10788,-9.3237267
145.3299,0.19334413,0.042219397,0.0,0,11.076099,0.0,0.0029158618,2.4217458,11.074653,303.11218,-9.3235579
145.3321,0.19120437,0.043762784,0.0,0,11.076099,0.0,0.0028953596,2.4515901,11.074535,303.10544,-9.3238554
145.3343,0.18737346,0.042081036,0.0,0,11.076099,0.0,0.0029311804,2.3688626,11.070862,303.09869,-9.3256645
145.3365,0.19914696,0.048530396,0.0,0,11.063763,0.0,0.0030822684,2.5453153,11.076409,303.09192,-9.3250647
145.3387,0.21799961,0.043004997,0.0,0,10.735819,0.0,0.0030507487,2.727031,11.073633,303.08517,-9.3239536
145.3409,0.21673995,0.045593098,0.0,0,10.404927,0.0,0.0029313341,2.8233399,11.069743,303.05386,-9.3238497
145.3431,0.22765486,0.041480679,0.0,0,10.074035,0.0,0.0029139477,2.9400237,11.010997,303.02008,-9.3235178
145.3453,0.21307449,0.048440658,0.0,0,9.7431412,0.0,0.0030444777,2.6477664,10.821026,302.9863,-9.3237553
145.3475,0.23418939,0.042166922,0.0,0,9.4141388,0.0,0.0029116871,2.9330883,10.510538,302.95251,-9.3244076
145.3497,0.20277803,0.044818047,0.0,0,9.0922346,0.0,0.0029395621,2.5252302,10.116697,303.1954,-9.3250933
145.3519,7.2970009,0.34239709,0.0,0,8.7703304,0.0,0.022501944,90.170334,9.7477865,303.92242,-9.3193521
145.3541,9.9286718,0.66736537,0.0,0,8.4631929,0.0,0.045121055,120.06939,9.3469572,304.64948,-9.318553
145.3563,10.917842,1.0244187,0.0,0,8.1570415,0.0,0.070509739,129.08412,8.9568806,305.3765,-9.3152189
145.3585,11.448237,1.386282,0.0,0,7.8607755,0.0,0.096459992,132.40092,8.6050682,306.10355,-9.3142691
145.3607,11.95469,1.6770442,0.0,0,7.5694952,0.0,0.11820566,135.0724,8.2828207,306.50031,-9.3146029
145.3629,12.379287,2.0022688,0.0,0,7.2838039,0.0,0.14270529,136.65646,7.952199,306.82367,-9.3157425
145.3651,12.600059,2.3005154,0.0,0,7.0067792,0.0,0.16601445,135.80186,7.6517749,307.14703,-9.3134518
145.3673,13.049132,2.5806856,0.0,0,6.7313671,0.0,0.18833968,137.51151,7.3639436,307.4704,-9.3144665
145.3695,13.290393,2.8494861,0.0,0,6.467802,0.0,0.21028921,137.24442,7.0853338,307.69638,-9.3145323
145.3717,13.623414,3.127202,0.0,0,6.2042422,0.0,0.23342697,137.22913,6.8098426,307.66275,-9.3143673
145.3739,14.010098,3.3852589,0.0,0,5.9515953,0.0,0.25531119,137.9303,6.542418,307.62912,-9.3134699
145.3761,14.310921,3.6456411,0.0,0,5.7009277,0.0,0.27805081,137.98201,6.2733159,307.59549,-9.3138905
145.3783,14.640604,3.8988328,0.0,0,5.4572535,0.0,0.30053306,138.00813,6.0141706,307.56186,-9.3149023
145.3805,14.957016,4.1593256,0.0,0,5.2187734,0.0,0.32437912,137.6442,5.7552919,307.01782,-9.3157539
145.3827,15.256269,4.4061756,0.0,0,4.9838042,0.0,0.34720665,137.27454,5.5062675,306.28238,-9.3149776
145.3849,15.586214,4.6500311,0.0,0,4.7569842,0.0,0.37077555,136.9016,5.2616558,305.54697,-9.3151054
145.3871,15.913755,4.8870697,0.0,0,4.5305758,0.0,0.39365873,136.64792,5.0210438,304.81152,-9.3149786
145.3893,16.240744,5.125988,0.0,0,4.314702,0.0,0.4179076,136.05235,4.7865381,304.0567,-9.3149424
145.3915,16.62015,5.3531013,0.0,0,4.0989256,0.0,0.4407869,136.0919,4.5519967,303.21472,-9.3151884
145.3937,17.012495,5.579628,0.0,0,3.8911293,0.0,0.46493441,135.97627,4.3263822,302.37271,-9.3150082
145.3959,17.405281,5.7989025,0.0,0,3.6859133,0.0,0.48808435,136.0322,4.1063199,301.5307,-9.3154869
145.3981,17.823797,6.0199132,0.0,0,3.4855206,0.0,0.51285112,135.84525,3.886821,300.68869,-9.3152065
145.4003,18.246365,6.2343264,0.0,0,3.2902927,0.0,0.53644657,135.80092,3.6732466,300.51578,-9.3136549
145.4025,18.69245,6.4397545,0.0,0,3.0970623,0.0,0.56085855,135.74663,3.4679277,300.72516,-9.313839
145.4047,19.164169,6.6405816,0.0,0,2.9113381,0.0,0.58395833,136.03995,3.2649157,300.93457,-9.3145609
145.4069,19.646929,6.8443427,0.0,0,2.7256143,0.0,0.60936522,135.96562,3.0689101,301.14398,-9.3139763
145.4091,20.15873,7.0330005,0.0,0,2.5483873,0.0,0.63174671,136.39326,2.8760159,301.32822,-9.3142004
145.4113,20.708488,7.2146564,0.0,0,2.3717272,0.0,0.65573937,136.74515,2.6862776,301.26065,-9.3138762
145.4135,21.279488,7.3966999,0.0,0,2.2008004,0.0,0.67849439,137.3855,2.512032,301.19308,-9.3143482
145.4157,21.863144,7.568747,0.0,0,2.0327644,0.0,0.70252991,137.83873,2.3337073,301.12555,-9.3135433
145.4179,22.469118,7.7474041,0.0,0,1.8679364,0.0,0.7256732,138.40253,2.1611328,301.05798,-9.3132915
145.4201,23.104479,7.9131951,0.0,0,1.7080843,0.0,0.74989587,138.88776,1.9934746,300.78778,-9.3121653
145.4223,23.74542,8.0765781,0.0,0,1.5491644,0.0,0.77206403,139.61255,1.8287334,300.34869,-9.3112841
145.4245,24.442711,8.2338619,0.0,0,1.3970973,0.0,0.79664272,140.26523,1.6704865,299.90961,-9.3118095
145.4267,25.178329,8.394475,0.0,0,1.2450334,0.0,0.81889874,141.26346,1.5120621,299.47052,-9.3105307
145.4289,25.94441,8.5425911,0.0,0,1.0992644,0.0,0.84331298,142.03169,1.3561178,299.03143,-9.3102608
145.4311,26.767597,8.6951218,0.0,0,0.95463634,0.0,0.86544073,143.33821,1.2094115,296.70313,-9.310503
145.4333,27.605719,8.8356228,0.0,0,0.81407332,0.0,0.8899585,144.25075,1.058111,294.37482,-9.3092623
145.4355,28.450665,8.9771729,0.0,0,0.67652941,0.0,0.91097492,145.59729,0.91499358,292.04651,-9.3086157
145.4377,29.308443,9.1059084,0.0,0,0.54098594,0.0,0.93475485,146.47171,0.77885371,289.71823,-9.3096924
145.4399,30.251108,9.2446766,0.0,0,0.41008592,0.0,0.95664084,147.90231,0.64705962,288.71231,-9.3082428
145.4421,31.251162,9.3689737,0.0,0,0.27942541,0.0,0.9805339,149.21637,0.50902587,289.29324,-9.3072653
145.4443,29.142006,9.4027596,0.0,0,0.15489216,0.0,0.98407882,138.79086,0.43752265,289.87418,-9.3082514
145.4465,27.862373,9.3997269,0.0,0,0.030416148,0.0,0.98615849,132.40636,0.3963891,290.45511,-9.3120098
145.4487,27.537283,9.4139576,0.0,0,-0.09173242,0.0,0.9868772,130.73347,0.35670769,291.03607,-9.3133211
145.4509,27.414371,9.4181824,0.0,0,-0.21312842,0.0,0.98976076,129.76825,0.30610713,294.4483,-9.3136215
145.4531,27.386307,9.4327908,0.0,0,-0.33452442,0.0,0.98981851,129.59293,0.24965887,298.14365,-9.313653
145.4553,27.367676,9.4272509,0.0,0,-0.45592043,0.0,0.99116278,129.29947,0.19774134,301.83899,-9.3125048
145.4575,27.304747,9.4350595,0.0,0,-0.5773164,0.0,0.99061227,129.11258,0.14001632,305.53436,-9.3134518
145.4597,27.164129,9.4359665,0.0,0,-0.69871235,0.0,0.9929809,128.17369,0.09422674,308.5712,-9.3137007
145.4619,26.964474,9.4524765,0.0,0,-0.82010835,0.0,0.99339652,127.20048,0.056428708,310.45563,-9.3140621
145.4641,26.682423,9.4433813,0.0,0,-0.94150436,0.0,0.9940303,125.72964,0.022761066,312.34009,-9.3135977
145.4663,26.327232,9.45189,0.0,0,-1.0629004,0.0,0.99362081,124.14904,0.0015896835,314.22452,-9.3155174
145.4685,25.868217,9.4481096,0.0,0,-0.8433286,300.0,0.99511743,121.77529,-0.0059013246,316.10898,-9.3145018
145.4707,25.376604,9.4580278,0.0,0,-0.42304948,300.0,0.99449897,119.56525,-0.0047520925,317.33121,-9.3145657
145.4729,24.9202,9.4494572,0.0,0,-0.0027700011,300.0,0.99507689,117.32542,0.0023522673,318.40628,-9.3153934
145.4751,24.531916,9.454483,0.0,0,0.41750887,300.0,0.9941625,115.61585,0.0048138415,319.48135,-9.315877
145.4773,24.243589,9.449439,0.0,0,0.83778799,300.0,0.99528396,114.11983,0.0093460614,320.55646,-9.3167257
145.4795,23.979698,9.462182,0.0,0,1.2580678,300.0,0.995327,112.88245,0.010050133,321.49741,-9.3171606
145.4817,23.155655,9.4507713,0.0,0,1.6783465,300.0,0.99520862,109.07868,0.028372504,322.08075,-9.3179703
145.4839,21.206572,9.4498625,0.0,0,2.0986254,300.0,0.99343723,100.16107,0.1081925,322.66409,-9.3199091
145.4861,18.107605,9.4327698,0.0,0,2.5189049,300.0,0.99232942,85.792801,0.24398929,323.24741,-9.3207035
145.4883,12.470903,9.4253426,0.0,0,2.9391842,300.0,0.98896533,60.123875,0.45644063,323.83075,-9.3230791
145.4905,0.51442933,9.1915197,0.0,0,3.3594635,300.0,0.95038301,2.2872975,0.84793526,324.02884,-9.3357878
145.4927,-0.14125609,8.9988604,0.0,0,3.7797422,300.0,0.91587192,-0.50009161,1.5407503,324.08249,-9.3369675
145.4949,-0.040867671,8.8175802,0.0,0,4.2000217,300.0,0.887766,-0.31546894,2.3185232,324.13611,-9.3386526
145.4971,0.20061387,8.6539431,0.0,0,4.6203008,300.0,0.85976291,1.2217542,3.0068564,324.18976,-9.337347
145.4993,-0.26332906,8.5390215,0.0,0,5.0405803,300.0,0.84300768,-1.2437763,3.5100727,324.16537,-9.3343592
145.5015,-0.10994633,8.4488096,0.0,0,5.4608593,300.0,0.82822168,-0.79178494,3.9135373,323.78992,-9.3347607
145.5037,0.1612978,8.3681631,0.0,0,5.8811388,300.0,0.8167305,0.88967216,4.298068,323.41443,-9.3328037
145.5059,-0.03960463,8.3553295,0.0,0,6.3014183,300.0,0.81381595,-0.15108791,4.6750684,323.03897,-9.3320637
145.5081,0.03549267,8.3424559,0.0,0,6.7216969,300.0,0.81274462,0.21813153,5.0612512,322.66351,-9.3312521
145.5103,-0.061528888,8.370553,0.0,0,7.1419768,300.0,0.81597126,-0.24480774,5.461338,322.32645,-9.3292007
145.5125,-0.072207086,8.4108267,0.0,0,7.5622554,300.0,0.82285202,-0.48620006,5.8871946,322.01132,-9.3292294
145.5147,0.091523774,8.4712048,0.0,0,7.9825354,300.0,0.83101386,0.52285779,6.3357682,321.6962,-9.3278046
145.5169,-0.096354567,8.5432262,0.0,0,8.4028139,300.0,0.84289491,-0.48253682,6.7832003,321.38107,-9.3278866
145.5191,-0.08576858,8.6454315,0.0,0,8.8230925,300.0,0.85836285,-0.49087915,7.2280183,321.05246,-9.327734
145.5213,-0.052951533,8.7442417,0.0,0,9.243372,300.0,0.87451869,-0.29307842,7.6651959,320.58893,-9.3260946
145.5235,0.027833268,8.8813086,0.0,0,9.6636515,300.0,0.8959831,0.098874249,8.0977592,320.12543,-9.3246222
145.5257,0.063666582,9.0082073,0.0,0,10.083931,300.0,0.91740763,0.41675523,8.5312338,319.6619,-9.3254509
145.5279,-0.066318117,9.1631422,0.0,0,10.50421,300.0,0.94321924,-0.25456226,8.9514713,319.19836,-9.3250704
145.5301,0.017000206,9.3206415,0.0,0,10.924489,300.0,0.9709298,0.035888601,9.3826952,318.70169,-9.3260698
145.5323,-0.04598549,9.4065371,0.0,0,11.344769,300.0,0.98719049,-0.48891678,9.8264074,318.1774,-9.3245869
145.5345,-0.026037317,9.3639879,0.0,0,11.765047,300.0,0.97924852,-0.062979579,10.266783,317.65308,-9.3239508
145.5367,-0.0085563362,9.3647614,0.0,0,12.185327,300.0,0.97929525,-0.062216859,10.704115,317.12878,-9.3250866
145.5389,-0.11849107,9.3647051,0.0,0,12.605606,300.0,0.97880882,-0.580724,11.133112,316.60449,-9.3237705
145.5411,0.10333919,9.4122419,0.0,0,13.025885,300.0,0.98710328,0.40779519,11.569,316.16046,-9.3240356
145.5433,0.05913043,9.4193192,0.0,0,13.446164,300.0,0.98805362,0.36721376,11.982542,315.71643,-9.3233709
145.5455,-0.025952123,9.4211388,0.0,0,13.866444,300.0,0.9894321,-0.11140159,12.391196,315.2724,-9.3224096
145.5477,-0.0035570352,9.4216833,0.0,0,14.286723,300.0,0.98901761,0.055423882,12.808794,314.82837,-9.3227768
145.5499,-0.017778939,9.4181318,0.0,0,14.707002,300.0,0.98897821,0.00030383287,13.234826,314.39658,-9.3229513
145.5521,-0.019941479,9.4196358,0.0,0,15.127281,300.0,0.9885546,-0.12337612,13.675383,313.97946,-9.323164
145.5543,0.013392564,9.4189587,0.0,0,15.547561,300.0,0.98895919,0.065071598,14.115284,313.56235,-9.3228111
145.5565,-0.040905692,9.4115314,0.0,0,15.967839,300.0,0.98705828,-0.18061034,14.554032,313.14523,-9.3218803
145.5587,-0.01521262,9.4217844,0.0,0,16.388119,300.0,0.98967201,-0.047709737,14.984383,312.72812,-9.3223333
145.5609,0.01557441,9.4164076,0.0,0,16.808399,300.0,0.98779637,0.017616337,15.415134,313.12442,-9.322319
145.5631,0.041052274,9.4144421,0.0,0,17.228678,300.0,0.98835194,0.18661284,15.833265,313.60208,-9.323473
145.5653,0.00043431259,9.4161367,0.0,0,17.648958,300.0,0.98750859,0.036625911,16.247915,314.07974,-9.3235569
145.5675,-0.051868249,9.4155216,0.0,0,17.999975,300.0,0.98880798,-0.25437251,16.652102,314.55743,-9.321784
145.5697,0.025717165,9.4184828,0.0,0,18.0,300.0,0.98788428,0.090906978,17.065907,315.30124,-9.3205729
145.5719,0.007647159,9.4146671,0.0,0,18.0,300.0,0.98844087,0.04402132,17.463688,316.51086,-9.3217955
145.5741,-0.047418848,9.4147844,0.0,0,18.0,300.0,0.98721766,-0.24871856,17.816782,317.72046,-9.3236809
145.5763,-0.018301817,9.420763,0.0,0,18.0,300.0,0.98992682,-0.10877749,18.119242,318.93008,-9.3254862
145.5785,0.027250942,9.4218359,0.0,0,18.0,300.0,0.98840427,0.12520726,18.344883,320.13968,-9.3261309
145.5807,0.019475002,9.4217396,0.0,0,18.0,300.0,0.98994541,0.078125574,18.470257,320.35962,-9.3284531
145.5829,0.015730245,9.4273863,0.0,0,18.0,300.0,0.98916131,0.097527139,18.49052,320.35962,-9.333107
145.5851,-0.051412452,9.4325314,0.0,0,18.0,300.0,0.9920122,-0.11442,18.417789,320.35962,-9.3410845
145.5873,-0.09086924,9.44839,0.0,0,18.0,300.0,0.99314475,-0.40411869,18.308771,320.35962,-9.3508377
145.5895,-0.051414903,9.4550533,0.0,0,18.0,300.0,0.99606293,-0.27140239,18.190025,320.16367,-9.3623037
145.5917,-0.063075148,9.4717636,0.0,0,18.0,300.0,0.99733877,-0.31171978,18.10425,319.44519,-9.3772573
145.5939,-0.07474082,9.488039,0.0,0,18.0,300.0,1.0021973,-0.40222669,18.052328,318.72668,-9.3941565
145.5961,0.018549308,9.5044851,0.0,0,18.0,300.0,1.0029935,0.020534977,18.040016,318.00821,-9.4123154
145.5983,0.11870678,9.5177155,0.0,0,18.0,300.0,1.0074917,0.48911428,18.04224,317.28973,-9.4294138
145.6005,0.10283267,9.5392151,0.0,0,18.0,300.0,1.0093074,0.46799111,18.055571,316.05649,-9.4468527
145.6027,0.042558741,9.5510197,0.0,0,18.0,300.0,1.0136448,0.20223044,18.079838,314.63022,-9.4637356
145.6049,-0.0085028065,9.5796223,0.0,0,18.0,300.0,1.0164742,0.067445181,18.108089,313.20395,-9.4823523
145.6071,-0.10312787,9.5846062,0.0,0,18.0,300.0,1.019968,-0.37960565,18.126341,311.77768,-9.4984779
145.6093,-0.13569818,9.6047363,0.0,0,18.0,300.0,1.0215467,-0.63942444,18.1387,310.35382,-9.513813
145.6115,-0.080948055,9.6192722,0.0,0,18.0,300.0,1.0263593,-0.42807475,18.145426,308.94098,-9.5284729
145.6137,0.0079244766,9.6395054,0.0,0,18.0,300.0,1.0276825,-0.014258958,18.145071,307.52817,-9.5445423
145.6159,0.088080779,9.6437569,0.0,0,18.0,300.0,1.0310446,0.33978254,18.145391,306.11533,-9.560132
145.6181,0.11072214,9.6657066,0.0,0,18.0,300.0,1.0329232,0.50902623,18.141382,304.70248,-9.5746145
145.6203,0.081339985,9.6755772,0.0,0,18.0,300.0,1.0368787,0.38319448,18.139128,304.12872,-9.5892792
145.6225,-0.0037713607,9.7033453,0.0,0,18.0,300.0,1.0393347,0.065355167,18.136805,304.03439,-9.6056938
145.6247,-0.071800962,9.7083054,0.0,0,18.0,300.0,1.043156,-0.23980811,18.13139,303.94009,-9.6219072
145.6269,-0.12383442,9.7314444,0.0,0,18.0,300.0,1.0451443,-0.5356791,18.130585,303.84579,-9.6388988
145.6291,-0.10449031,9.7426596,0.0,0,18.0,300.0,1.0495549,-0.51003873,18.129591,303.75516,-9.6547642
145.6313,-0.016494932,9.7656422,0.0,0,18.0,300.0,1.0513804,-0.141867,18.125944,303.70111,-9.671093
145.6335,0.075567521,9.7724972,0.0,0,18.0,300.0,1.0552363,0.29049671,18.121563,303.64706,-9.6854668
145.6357,0.12348791,9.7939291,0.0,0,18.0,300.0,1.0572666,0.54579735,18.119051,303.59305,-9.7006407
145.6379,0.083243571,9.8014536,0.0,0,18.0,300.0,1.0608078,0.43781602,18.119127,303.539,-9.7169209
145.6401,0.034625534,9.8291063,0.0,0,18.0,300.0,1.0633725,0.19957234,18.112692,303.40021,-9.7333498
145.6423,-0.056585044,9.8344898,0.0,0,18.0,300.0,1.0669104,-0.1862095,18.114969,303.1908,-9.7490425
145.6445,-0.11099844,9.858283,0.0,0,18.0,300.0,1.0695832,-0.44811079,18.110672,302.98138,-9.765687
145.6467,-0.10745157,9.8676901,0.0,0,18.0,300.0,1.0736368,-0.51111603,18.111359,302.77197,-9.7822027
145.6489,-0.045925211,9.8895836,0.0,0,18.0,300.0,1.0756643,-0.24580458,18.109051,302.56256,-9.7972689
145.6511,0.048069697,9.8945313,0.0,0,18.0,300.0,1.0787917,0.16396841,18.107992,302.19104,-9.8124409
145.6533,0.10399558,9.9160595,0.0,0,18.0,300.0,1.0810846,0.41875952,18.107361,301.81949,-9.8288345
145.6555,0.10514893,9.9255495,0.0,0,18.0,300.0,1.0847813,0.45754731,18.108208,301.44797,-9.8435383
145.6577,0.061324537,9.9538059,0.0,0,18.0,300.0,1.0884119,0.32852209,18.109049,301.07645,-9.8595762
145.6599,-0.031835295,9.9601669,0.44165361,0,18.0,300.0,1.0913533,-0.037361071,18.102839,300.65271,-9.8749866
145.6621,-0.10646532,9.9833527,1.4132845,0,18.0,300.0,1.0946068,-0.36423779,18.099874,300.16632,-9.8917065
145.6643,-0.12102932,9.9944305,2.3849154,0,18.0,300.0,1.0982876,-0.50265461,18.098616,299.67996,-9.9079237
145.6665,-0.083608173,10.020385,3.3565462,0,18.0,300.0,1.101716,-0.39628482,18.100182,299.19357,-9.9239769
145.6687,0.012821609,10.024838,4.328177,0,18.0,300.0,1.1041629,-0.032081179,18.100409,298.70721,-9.9389277
145.6709,0.097691439,10.043712,4.4165039,0,18.0,300.0,1.1068606,0.36075059,18.098385,298.33752,-9.955781
145.6731,0.10256618,10.052509,4.4165039,0,18.0,300.0,1.1096812,0.44804356,18.098516,297.97949,-9.9706364
145.6753,0.071447223,10.078988,4.4165039,0,18.0,300.0,1.1136447,0.3458325,18.098389,297.62146,-9.9868155
145.6775,0.0084161405,10.086122,4.4165039,0,18.0,300.0,1.1164825,0.085896462,18.098394,297.26343,-10.003301
145.6797,-0.09418156,10.111946,5.6663203,0,18.0,300.0,1.1207342,-0.32517663,18.094002,296.93488,-10.01938
145.6819,-0.13526265,10.12124,9.1032829,0,18.0,300.0,1.1233948,-0.5591895,18.09687,296.6579,-10.035542
145.6841,-0.10096423,10.144632,12.540246,0,18.0,300.0,1.1273639,-0.45692751,18.097027,296.38095,-10.051371
145.6863,-0.01236635,10.152989,15.977209,0,18.0,300.0,1.1300126,-0.14058107,18.096512,296.10397,-10.068325
145.6885,0.075543292,10.172009,19.414173,0,18.0,300.0,1.1334083,0.22855313,18.095236,295.82703,-10.083333
145.6907,0.11256979,10.180195,20.039063,0,18.0,300.0,1.135336,0.47121218,18.0945,295.36215,-10.100051
145.6929,0.10441422,10.206013,20.039063,0,18.0,300.0,1.1402992,0.421455,18.095289,294.85553,-10.113969
145.6951,0.02357067,10.21573,20.039063,0,18.0,300.0,1.1429017,0.12366904,18.093418,294.34888,-10.129089
145.6973,-0.059898682,10.236876,20.039063,0,18.0,300.0,1.1470109,-0.18104085,18.092182,293.84225,-10.144777
145.6995,-0.13150865,10.247614,20.807676,0,18.0,300.0,1.1493428,-0.49924645,18.092506,293.31903,-10.161152
145.7017,-0.12103598,10.2701,23.625889,0,18.0,300.0,1.1541001,-0.51800191,18.092377,292.75159,-10.177633
145.7039,-0.040492631,10.2793,26.444101,0,18.0,300.0,1.1560215,-0.24771902,18.090406,292.18414,-10.192775
145.7061,0.04705571,10.29531,29.262314,0,18.0,300.0,1.1595844,0.1467291,18.09252,291.61673,-10.20866
145.7083,0.10501605,10.305633,32.080528,0,18.0,300.0,1.1615506,0.39780617,18.08816,291.04929,-10.224323
145.7105,0.11693338,10.327292,32.849121,0,18.0,300.0,1.1665592,0.47551227,18.088882,290.63416,-10.238522
145.7127,0.064324036,10.340691,32.849121,0,18.0,300.0,1.1688541,0.3129338,18.089245,290.27612,-10.255874
145.7149,-0.029434711,10.360347,32.849121,0,18.0,300.0,1.1737912,-0.066308528,18.088175,289.91809,-10.272091
145.7171,-0.10048705,10.375783,32.849121,0,18.0,300.0,1.1760676,-0.35170746,18.081793,289.56009,-10.287656
145.7193,-0.12838817,10.396454,33.048637,0,18.0,300.0,1.1817992,-0.49949321,18.084681,289.21793,-10.304412
145.7215,-0.079269484,10.409353,34.145954,0,18.0,300.0,1.1834122,-0.36677009,18.081818,288.94717,-10.320601
145.7237,0.017974457,10.42192,35.243267,0,18.0,300.0,1.187237,0.023294155,18.084183,288.67642,-10.336662
145.7259,0.09615197,10.43469,36.340584,0,18.0,300.0,1.1889,0.32929787,18.083176,288.4057,-10.35191
145.7281,0.13159463,10.454397,37.437897,0,18.0,300.0,1.1946821,0.46762216,18.080154,288.13495,-10.367238
145.7303,0.079141326,10.468794,37.836914,0,18.0,300.0,1.1959882,0.33179578,18.08073,287.77322,-10.382836
145.7325,-0.011095951,10.482732,37.836914,0,18.0,300.0,1.2009079,0.049726203,18.083601,287.3595,-10.399064
145.7347,-0.092541166,10.502644,37.836914,0,18.0,300.0,1.2035977,-0.28383791,18.076345,286.94577,-10.414131
145.7369,-0.12079713,10.519666,37.836914,0,18.0,300.0,1.209322,-0.45289621,18.077908,286.53204,-10.428994
145.7391,-0.095626928,10.536027,37.928104,0,18.0,300.0,1.2109288,-0.38591304,18.078863,286.12262,-10.445761
145.7413,-0.015348218,10.547161,38.931156,0,18.0,300.0,1.2152544,-0.13569953,18.07902,285.75604,-10.461423
145.7435,0.079322025,10.562448,39.934208,0,18.0,300.0,1.2170088,0.22394197,18.07654,285.38947,-10.476582
145.7457,0.13040115,10.578206,40.937263,0,18.0,300.0,1.2228535,0.47195446,18.077524,285.02289,-10.493183
145.7479,0.10984575,10.595825,41.940311,0,18.0,300.0,1.2244083,0.42350587,18.076565,284.65631,-10.508919
145.7501,0.023361122,10.610059,42.39624,0,18.0,300.0,1.2299229,0.17181504,18.076078,284.34528,-10.524558
145.7523,-0.066946708,10.629756,42.39624,0,18.0,300.0,1.2318383,-0.22659297,18.075075,284.08051,-10.540538
145.7545,-0.1346897,10.644495,42.39624,0,18.0,300.0,1.2377615,-0.48948097,18.071659,283.81577,-10.55654
145.7567,-0.10423698,10.663831,42.39624,0,18.0,300.0,1.239468,-0.42526805,18.073009,283.55099,-10.572485
145.7589,-0.032269906,10.670409,42.396244,0,18.0,300.0,1.2440968,-0.18782155,18.071486,283.28625,-10.588345
145.7611,0.044397507,10.689869,43.104424,0,18.0,300.0,1.2456828,0.12010063,18.06945,282.92645,-10.604374
145.7633,0.10007287,10.703829,43.812599,0,18.0,300.0,1.2518394,0.3238261,18.0707,282.56668,-10.619622
145.7655,0.11139642,10.724603,44.520779,0,18.0,300.0,1.253466,0.39837572,18.07118,282.20688,-10.635223
145.7677,0.058520198,10.733607,45.228958,0,18.0,300.0,1.2585404,0.26605588,18.072617,281.84711,-10.651017
145.7699,-0.036388166,10.753388,45.615234,0,18.0,300.0,1.2605056,-0.057530813,18.067459,281.48114,-10.667353
145.7721,-0.12236041,10.768764,45.615234,0,18.0,300.0,1.2670289,-0.38311869,18.066286,281.10776,-10.684952
145.7743,-0.13501495,10.793761,45.615234,0,18.0,300.0,1.2695878,-0.5240289,18.070168,280.73441,-10.700865
145.7765,-0.067925014,10.800368,45.615234,0,18.0,300.0,1.2746687,-0.29621533,18.066835,280.36105,-10.716687
145.7787,0.047087681,10.818537,45.615234,0,18.0,300.0,1.2760437,0.1057955,18.065531,279.98767,-10.730684
145.7809,0.092278287,10.829453,46.168949,0,18.0,300.0,1.2817278,0.28560811,18.066683,279.70071,-10.746595
145.7831,0.099905096,10.856091,46.77803,0,18.0,300.0,1.2844452,0.33651677,18.064827,279.42236,-10.763212
145.7853,0.091123126,10.859674,47.387112,0,18.0,300.0,1.2886467,0.35427213,18.069223,279.14404,-10.77829
145.7875,0.013193661,10.881255,47.996193,0,18.0,300.0,1.2910525,0.10364055,18.061632,278.86572,-10.793435
145.7897,-0.10083305,10.894423,48.383789,0,18.0,300.0,1.2972071,-0.27049252,18.067383,278.5701,-10.809519
145.7919,-0.14304709,10.921967,48.383789,0,18.0,300.0,1.3004204,-0.46143204,18.063398,278.24426,-10.827829
145.7941,-0.10707822,10.927014,48.383789,0,18.0,300.0,1.3053328,-0.39775878,18.061729,277.91843,-10.844076
145.7963,0.014779722,10.950349,48.383789,0,18.0,300.0,1.308068,-0.019049589,18.059536,277.59259,-10.860432
145.7985,0.091600388,10.953288,48.383789,0,18.0,300.0,1.3118312,0.2783809,18.06146,277.26672,-10.874923
145.8007,0.10828748,10.978803,48.890041,0,18.0,300.0,1.3145856,0.37699878,18.058764,276.91867,-10.891181
145.8029,0.09091799,10.987396,49.508789,0,18.0,300.0,1.3199836,0.32538593,18.061943,276.56567,-10.906041
145.8051,0.046196781,11.009713,50.127541,0,18.0,300.0,1.3229001,0.18441775,18.059847,276.21268,-10.920604
145.8073,-0.043748204,11.019923,50.746292,0,18.0,300.0,1.3283019,-0.11324419,18.058651,275.85965,-10.937526
145.8095,-0.12565126,11.046453,51.196289,0,18.0,300.0,1.3317226,-0.39765149,18.059572,275.50482,-10.953339
145.8117,-0.11789807,11.049841,51.196289,0,18.0,300.0,1.3356081,-0.42381486,18.060551,275.14502,-10.970057
145.8139,-0.045357317,11.071978,51.196289,0,18.0,300.0,1.3389021,-0.20820673,18.056324,274.78522,-10.98573
145.8161,0.067755029,11.079092,51.196289,0,18.0,300.0,1.3430958,0.15862611,18.057516,274.42545,-11.001338
145.8183,0.11859643,11.10468,51.196289,0,18.0,300.0,1.3466673,0.36486408,18.056877,274.06564,-11.015322
145.8205,0.10159633,11.111156,51.590038,0,18.0,300.0,1.3510734,0.34492913,18.061333,273.71045,-11.032158
145.8227,0.051443584,11.133048,52.131447,0,18.0,300.0,1.354388,0.18862863,18.05658,273.35696,-11.048719
145.8249,-0.0089471461,11.143675,52.672852,0,18.0,300.0,1.3595985,0.020539824,18.054548,273.00348,-11.065221
145.8271,-0.1089361,11.171759,53.214256,0,18.0,300.0,1.3641059,-0.31102821,18.055935,272.64999,-11.081366
145.8293,-0.14066149,11.1788,53.657227,0,18.0,300.0,1.3685472,-0.44942939,18.056805,272.29382,-11.097581
145.8315,-0.079750627,11.20199,53.657227,0,18.0,300.0,1.3724726,-0.27999774,18.050674,271.92554,-11.112381
145.8337,0.030158807,11.206061,53.657227,0,18.0,300.0,1.3754474,0.034332164,18.054752,271.55725,-11.127961
145.8359,0.10078803,11.232142,53.657227,0,18.0,300.0,1.3803999,0.29863659,18.05547,271.18893,-11.144176
145.8381,0.12203246,11.238816,53.657227,0,18.0,300.0,1.3840582,0.39093295,18.054878,270.82065,-11.158814
145.8403,0.077040233,11.2618,53.920238,0,18.0,300.0,1.388642,0.28722227,18.047861,270.51727,-11.173661
145.8425,0.013127757,11.269901,54.333549,0,18.0,300.0,1.3922725,0.062989578,18.050423,270.25098,-11.191223
145.8447,-0.068360731,11.295932,54.746853,0,18.0,300.0,1.3976458,-0.18442254,18.052326,269.98465,-11.207335
145.8469,-0.13822009,11.305686,55.160156,0,18.0,300.0,1.4019216,-0.40362704,18.048954,269.71835,-11.223759
145.8491,-0.11096936,11.327663,55.535889,0,18.0,300.0,1.4067628,-0.37110543,18.04776,269.46011,-11.239993
145.8513,0.014664488,11.335618,55.535889,0,18.0,300.0,1.4098523,-0.030086078,18.045134,269.28256,-11.254438
145.8535,0.10264644,11.358328,55.535889,0,18.0,300.0,1.4146833,0.28002793,18.051691,269.10504,-11.27067
145.8557,0.11211468,11.364243,55.535889,0,18.0,300.0,1.417631,0.36027244,18.050175,268.92749,-11.286275
145.8579,0.10753509,11.385074,55.535889,0,18.0,300.0,1.4226648,0.35268831,18.048515,268.74994,-11.301527
145.8601,0.041967828,11.39711,48.871544,0,18.0,300.0,1.4263047,0.15747869,18.048019,268.51654,-11.317191
145.8623,-0.04890037,11.423015,36.653652,0,18.0,300.0,1.4328085,-0.11286821,18.047762,268.23657,-11.332982
145.8645,-0.11038771,11.430017,24.435755,0,18.0,300.0,1.4354454,-0.31104946,18.047842,267.9566,-11.349489
145.8667,-0.11531217,11.448374,12.217859,0,18.0,300.0,1.440834,-0.3757638,18.04825,267.67664,-11.366288
146.767,-0.0071150213,11.559513,0.0,0,18.0,1.6216742e-10,1.4722762,-0.023896938,18.000778,145.31624,-11.482619
147.867,-0.00596915,11.558294,0.0,0,18.0,1.6196896e-25,1.4721534,-0.020057518,18.000874,74.649628,-11.482034
148.967,-0.0053129904,11.558515,0.0,0,18.0,1.6177150000000001e-40,1.47227,-0.015295734,18.000395,44.052635,-11.482609
150.067,-0.0059303222,11.559129,0.0,0,18.0,1.4012985e-45,1.4721807,-0.017930109,18.000191,32.284168,-11.482777
151.167,-0.006284357,11.559174,0.0,0,18.0,1.4012985e-45,1.472374,-0.022365011,18.000252,27.747408,-11.482774
152.267,-0.0066074012,11.559151,0.0,0,18.0,1.4012985e-45,1.4724579,-0.019389134,17.999605,26.326479,-11.482363
153.367,-0.0059712273,11.559435,0.0,0,18.0,1.4012985e-45,1.4722961,-0.020571647,18.000635,25.751534,-11.482434
154.467,-0.0044678655,11.558968,0.0,0,18.0,1.4012985e-45,1.4723511,-0.014160217,17.999287,25.453205,-11.482392
155.567,-0.0051540337,11.55892,0.0,0,18.0,1.4012985e-45,1.4723704,-0.017135885,18.000427,25.290401,-11.482246
156.667,-0.0034735994,11.55967,0.0,0,18.0,1.4012985e-45,1.4723754,-0.011217437,17.999668,25.238321,-11.482547
157.767,-0.0039452855,11.559861,0.0,0,18.0,1.4012985e-45,1.4726121,-0.010371058,18.000746,25.164278,-11.482836
158.867,-0.0021009559,11.559546,0.0,0,18.0,1.4012985e-45,1.4725701,-0.010635213,18.000532,25.033661,-11.483128
159.967,-0.0039903927,11.559971,0.0,0,18.0,1.4012985e-45,1.4724416,-0.014121524,17.999851,24.943417,-11.482713
161.067,-0.0045312094,11.559824,0.0,0,18.0,1.4012985e-45,1.4726028,-0.015442958,18.000727,24.97979,-11.482503
162.167,-0.0029207005,11.559918,0.0,0,18.0,1.4012985e-45,1.4726893,-0.010062712,18.000641,24.892202,-11.482545
163.267,-0.0067252195,11.560231,0.0,0,18.0,1.4012985e-45,1.4725206,-0.020098405,18.000444,24.900898,-11.482412
164.367,-0.0053785336,11.559772,0.0,0,18.0,1.4012985e-45,1.472621,-0.020372057,17.999792,24.774366,-11.482024
165.467,-0.0069009149,11.559735,0.0,0,18.0,1.4012985e-45,1.4726274,-0.021262733,17.999889,24.784307,-11.481891
166.567,-0.001346993,11.560599,0.0,0,18.0,1.4012985e-45,1.4726378,-0.0044536949,17.999216,24.764236,-11.482309
167.667,0.00037753562,11.560572,0.0,0,18.0,1.4012985e-45,1.4728366,0.0017670892,17.999611,24.723282,-11.482505
168.767,-0.0026272787,11.560438,0.0,0,18.0,1.4012985e-45,1.4727753,-0.0081195412,18.000664,24.715393,-11.482611
169.867,-3.715108e-05,11.560632,0.0,0,18.0,1.4012985e-45,1.4726945,-0.0012777308,17.99963,24.714624,-11.482864
170.967,-0.0014503624,11.560482,0.0,0,18.0,1.4012985e-45,1.4727929,-0.0042893542,18.000521,24.794329,-11.482462
172.067,-0.0060785892,11.560777,0.0,0,18.0,1.4012985e-45,1.4728354,-0.016683709,18.000072,24.651392,-11.48251
173.167,-0.0062454394,11.560715,0.0,0,18.0,1.4012985e-45,1.4726851,-0.018918311,17.99996,24.697113,-11.482059
174.267,-0.0063402816,11.560597,0.0,0,18.0,1.4012985e-45,1.4728063,-0.021918781,18.000532,24.652554,-11.482012
175.367,-0.0041015199,11.560468,0.0,0,18.0,1.4012985e-45,1.4727437,-0.010491388,17.999063,24.682581,-11.481935
176.467,-0.0027159711,11.560701,0.0,0,18.0,1.4012985e-45,1.4727439,-0.0084530748,18.000778,24.54365,-11.481681
177.567,-0.0012232462,11.56056,0.0,0,18.0,1.4012985e-45,1.4727895,-0.0015644141,18.000063,24.575228,-11.482198
178.667,-0.0039726128,11.5606,0.0,0,18.0,1.4012985e-45,1.4727155,-0.0094854785,18.000071,24.688648,-11.481966
179.767,-0.0025183279,11.560952,0.0,0,18.0,1.4012985e-45,1.4728863,-0.0048495126,17.99898,24.589987,-11.482246
180.867,-0.001205772,11.561709,0.0,0,18.0,1.4012985e-45,1.4731064,-0.0018913936,17.999784,24.580782,-11.482658
181.967,-0.0024733336,11.562108,0.0,0,18.0,1.4012985e-45,1.4731708,-0.008134,17.999931,24.529837,-11.482715
183.067,-0.001562763,11.561803,0.0,0,18.0,1.4012985e-45,1.4731169,-0.00064482819,17.999115,24.525682,-11.482588
184.167,-0.0047812057,11.561541,0.0,0,18.0,1.4012985e-45,1.472985,-0.015751643,17.999172,24.51972,-11.482141
185.267,-0.0041024769,11.561544,0.0,0,18.0,1.4012985e-45,1.4729701,-0.010702395,17.998829,24.549185,-11.481315
186.367,-0.0058976137,11.56152,0.0,0,18.0,1.4012985e-45,1.4730783,-0.017523754,17.999817,24.610231,-11.481215
187.467,-0.0065843253,11.561354,0.0,0,18.0,1.4012985e-45,1.4728917,-0.016649263,18.000444,24.53857,-11.481405
188.567,-0.0060554063,11.561494,0.0,0,18.0,1.4012985e-45,1.472954,-0.015738789,18.000145,24.544889,-11.480978
189.667,-0.0042874785,11.561384,0.0,0,18.0,1.4012985e-45,1.4731097,-0.012733223,18.000263,24.55369,-11.480786
190.767,-0.0054439195,11.561735,0.0,0,18.0,1.4012985e-45,1.4729682,-0.012433214,17.999792,24.549911,-11.480752
191.867,-0.00075537915,11.562122,0.0,0,18.0,1.4012985e-45,1.4732251,-0.0011424475,18.000032,24.481182,-11.481302
192.967,-0.0063322564,11.562016,0.0,0,18.0,1.4012985e-45,1.4732926,-0.013978819,17.999918,24.454933,-11.481533
194.067,-0.0032027797,11.562411,0.0,0,18.0,1.4012985e-45,1.4731816,-0.0077417931,17.99889,24.501318,-11.481998
195.167,-0.0058907885,11.563085,0.0,0,18.0,1.4012985e-45,1.4735421,-0.017586602,17.999784,24.528202,-11.481967
196.267,-0.00085880089,11.562793,0.0,0,18.0,1.4012985e-45,1.4735317,0.0011681773,17.999603,24.462078,-11.48229
197.367,-0.00734379,11.563648,0.0,0,18.0,1.4012985e-45,1.4735048,-0.019351309,17.999233,24.369177,-11.482159
198.467,-0.0033482211,11.563531,0.0,0,18.0,1.4012985e-45,1.4736946,-0.0059726601,18.001785,24.362171,-11.48221
199.567,-0.0059405603,11.563815,0.0,0,18.0,1.4012985e-45,1.4737905,-0.017047569,18.000223,24.38542,-11.482602
200.667,-0.0085868621,11.563821,0.0,0,18.0,1.4012985e-45,1.4735533,-0.024012813,17.999329,24.398191,-11.482433
201.767,-0.0074166628,11.563554,0.0,0,18.0,1.4012985e-45,1.4737042,-0.017779816,17.999588,24.449093,-11.482619
202.867,-0.0048513236,11.563841,0.0,0,18.0,1.4012985e-45,1.4737846,-0.012293762,17.99905,24.385454,-11.48245
203.967,-0.0030564701,11.564102,0.0,0,18.0,1.4012985e-45,1.4736518,-0.0087376982,17.998684,24.418863,-11.482753
205.067,-0.009838406,11.564577,0.0,0,18.0,1.4012985e-45,1.4739802,-0.027458671,17.999302,24.388237,-11.482157
205.867,-0.010498867,11.564475,0.0,0,18.0,1.4012985e-45,1.4738827,-0.032741085,17.999296,24.372684,-11.482004