File: examples/hot axisymmetric compression example/data/02 screened data/testID_0145.csv
Time(sec),Force(kN),Jaw(mm),PowAngle(deg),Power(W),Pram,PTemp,Strain,Stress(MPa),Stroke(mm),TC1(C),wedge(mm)
0.0,0.77438736,0.46658638,0.0,0,11.076097,0.0014409337,0.031559978,9.5611944,11.076703,29.910601,-9.1277428
1.2,0.7317006,-0.0026352161,0.0,0,11.076097,3.5158746,-0.00016808225,9.330493,11.076233,29.810951,-9.4946775
2.4,0.70165312,-0.0025086033,0.0,0,11.076097,7.1158757,-0.00013490723,8.9355268,11.076158,29.617197,-9.49154
3.6,0.68098414,-0.0025383115,0.0,0,11.076097,10.715877,-0.00014822799,8.6870708,11.0768,29.615324,-9.4899788
4.8,0.66458666,-0.0021213414,0.0,0,11.076097,14.315875,-0.00017774465,8.4707651,11.076284,29.50065,-9.4879036
6.0,0.65012205,-0.0023897165,0.0,0,11.076097,17.915874,-0.00016171199,8.2841511,11.07579,29.458931,-9.4856443
7.2,0.63809294,-0.0024594064,0.0,0,11.076097,21.515877,-0.00012706597,8.1250734,11.075973,29.360048,-9.4830351
8.4,0.62672955,-0.0021116929,0.0,0,11.076097,25.115879,-0.00013894823,7.9726901,11.075128,29.243311,-9.4807777
9.6,0.61475927,-0.0022834437,0.0,0,11.076097,28.715879,-0.00018069871,7.8303986,11.076078,29.120659,-9.4782772
10.8,0.61566132,-0.001815304,18.113125,0,11.076097,32.315876,-0.00012934059,7.8353515,11.07617,29.126459,-9.4767389
12.0,0.62225789,-0.0022220828,31.856241,0,11.076097,35.91589,-0.00012081779,7.9263306,11.076557,29.974319,-9.4746828
13.2,0.63501775,-0.0054050554,38.427498,0,11.076097,39.515888,-0.00035619119,8.0855865,11.075354,32.812153,-9.472599
14.4,0.63528931,-0.00871138,41.737305,0,11.076097,43.115891,-0.00061860139,8.0961599,11.075802,37.0294,-9.4703531
15.6,0.64165157,-0.012834154,42.964008,0,11.076097,46.715893,-0.00084615703,8.1738901,11.076389,42.015129,-9.4681416
16.8,0.66172189,-0.016770735,42.978512,0,11.076097,50.315887,-0.001090743,8.4321651,11.077497,47.413475,-9.4660225
18.0,0.65810025,-0.019917339,42.398159,0,11.076097,53.91589,-0.0013076901,8.385499,11.076242,52.309364,-9.4633598
19.2,0.66343647,-0.022628359,41.802982,0,11.076097,57.515884,-0.0015469618,8.4477911,11.0756,56.969761,-9.4611988
20.4,0.66073412,-0.02569476,41.20089,0,11.076097,61.115883,-0.0017074917,8.4220676,11.076202,61.152252,-9.458952
21.6,0.67208928,-0.029079935,40.634239,0,11.076097,64.715874,-0.0019165309,8.5718555,11.07596,65.016228,-9.4572954
22.8,0.66642708,-0.030785538,40.854809,0,11.076097,68.31588,-0.0020483241,8.486763,11.075418,68.519798,-9.4550571
24.0,0.66057289,-0.032895315,41.179882,0,11.076097,71.915871,-0.0022273315,8.421977,11.075674,71.937813,-9.4529057
25.2,0.67310655,-0.035293158,41.198727,0,11.076097,75.515884,-0.0023290082,8.5921106,11.075576,75.372528,-9.451004
26.4,0.66897094,-0.038620755,41.753593,0,11.076097,79.115883,-0.0025820795,8.5367279,11.07604,78.812752,-9.4484272
27.6,0.66763598,-0.040511928,41.802975,0,11.076097,82.715889,-0.0026892058,8.5168848,11.076145,82.374977,-9.4460173
28.8,0.66507125,-0.04322556,42.370178,0,11.076097,86.31588,-0.0029016284,8.4896545,11.076091,85.8265,-9.4440861
30.0,0.66354525,-0.046228003,42.396236,0,11.076097,89.915886,-0.0030319307,8.4740076,11.075974,89.428383,-9.4418697
31.2,0.67830187,-0.049719498,42.586662,0,11.076097,93.515884,-0.0033200982,8.6664696,11.076241,93.09079,-9.4394236
32.4,0.67332351,-0.051748935,42.978512,0,11.076097,97.115891,-0.0034677538,8.596694,11.076577,96.648529,-9.4372272
33.6,0.68302238,-0.054709226,43.23455,0,11.076097,100.7159,-0.0036389916,8.7264109,11.076517,100.21958,-9.4352627
34.8,0.68609971,-0.058126055,43.527828,0,11.076097,104.3159,-0.0038466386,8.7712889,11.075923,103.81614,-9.4333124
36.0,0.67994821,-0.060747307,43.945377,0,11.076097,107.91589,-0.0040252819,8.6920204,11.075235,107.32854,-9.4309378
37.2,0.68637234,-0.063455015,44.077145,0,11.076097,111.51589,-0.0042580152,8.7830048,11.075814,110.90719,-9.4290133
38.4,0.69667095,-0.066458672,44.448658,0,11.076097,115.1159,-0.0043782662,8.9160194,11.076308,114.59805,-9.4272203
39.6,0.70155454,-0.06981656,44.604488,0,11.076097,118.71589,-0.0046674088,8.977088,11.075369,118.10915,-9.4248867
40.8,0.69577253,-0.072249547,45.120846,0,11.076097,122.3159,-0.0048310296,8.9031992,11.076245,121.76296,-9.4227247
42.0,0.70597124,-0.075237498,45.12085,0,11.076097,125.91589,-0.005010766,9.0395355,11.076241,125.39371,-9.4207077
43.2,0.7142151,-0.079753891,45.610332,0,11.076097,129.51599,-0.0052815285,9.1551991,11.076395,128.97867,-9.4184103
44.4,0.71119887,-0.081854723,45.738026,0,11.076097,133.11589,-0.0054243417,9.1109324,11.075329,132.64383,-9.4168215
45.6,0.71163046,-0.084423043,45.890079,0,11.076097,136.71587,-0.0056443177,9.1079559,11.075351,136.22231,-9.4140892
46.8,0.72107673,-0.087985799,46.109619,0,11.076097,140.31589,-0.005813078,9.24084,11.075894,139.884,-9.4115238
48.0,0.72640157,-0.090818368,46.109619,0,11.076097,143.91586,-0.0060622785,9.3017607,11.076201,143.46614,-9.4100809
49.2,0.72432745,-0.094068848,46.581669,0,11.076097,147.51588,-0.0062694438,9.267848,11.075556,147.06264,-9.4080477
50.4,0.73672527,-0.096909873,46.582027,0,11.076097,151.11588,-0.0064442912,9.4341602,11.075708,150.77518,-9.4062014
51.6,0.73748851,-0.10165653,46.721142,0,11.076097,154.71588,-0.0067394674,9.4401646,11.07618,154.31645,-9.4034605
52.8,0.73305714,-0.10350269,47.054405,0,11.076097,158.31587,-0.0068570054,9.4025726,11.075542,157.93602,-9.4014082
54.0,0.73088109,-0.10674825,47.05444,0,11.076097,161.91588,-0.007121339,9.3532896,11.075765,161.43787,-9.3991184
55.2,0.75331402,-0.11048149,47.504883,0,11.076097,165.51587,-0.0072958251,9.6589031,11.076165,165.03801,-9.3974667
56.4,0.737279,-0.11339944,47.511269,0,11.076097,169.11588,-0.0075435536,9.4612865,11.074895,168.65633,-9.3955536
57.6,0.74462014,-0.11642637,47.955318,0,11.076097,172.71588,-0.0077661206,9.5427303,11.07581,172.18748,-9.3940201
58.8,0.74916399,-0.119639,47.955372,0,11.076097,176.31589,-0.0079299696,9.6120157,11.075144,175.83572,-9.3918839
60.0,0.74951583,-0.12454978,48.247345,0,11.076097,179.91588,-0.008282573,9.609313,11.076138,179.47876,-9.3895359
61.2,0.74277443,-0.12666014,48.383785,0,11.076097,183.51587,-0.0084202383,9.5342207,11.076541,183.15971,-9.3874588
62.4,0.74574268,-0.12971103,48.383785,0,11.076097,187.11589,-0.008617756,9.5793839,11.076667,186.85229,-9.385252
63.6,0.75253195,-0.13330966,48.383785,0,11.076097,190.71588,-0.0088127526,9.6573124,11.075109,190.34033,-9.3831005
64.8,0.73945498,-0.13597542,48.811314,0,11.076097,194.31589,-0.0090175746,9.4863863,11.075943,193.94978,-9.3813496
66.0,0.74160576,-0.13953161,48.812252,0,11.076097,197.91589,-0.0093072858,9.5295944,11.076104,197.46835,-9.3796959
67.2,0.7507779,-0.14242488,49.228447,0,11.076097,201.5159,-0.009414752,9.6477566,11.074964,201.05637,-9.377635
68.4,0.7593779,-0.14686473,49.228565,0,11.076097,205.11591,-0.0097512146,9.7639351,11.076416,204.80414,-9.3752832
69.6,0.74327451,-0.14902784,49.229733,0,11.076097,208.7159,-0.0099227158,9.5595484,11.076328,208.51443,-9.3731823
70.8,0.739007,-0.15273894,49.229733,0,11.076097,212.3159,-0.010104765,9.5176744,11.07521,212.09787,-9.3706856
72.0,0.75294632,-0.15581727,49.626286,0,11.076097,215.91589,-0.010349478,9.6990433,11.076396,215.60112,-9.368681
73.2,0.75220037,-0.15967001,49.636227,0,11.076097,219.5159,-0.01060304,9.6665697,11.0762,219.15147,-9.3670244
74.4,0.74520022,-0.16364573,49.661362,0,11.076097,223.11591,-0.010857912,9.6042671,11.075162,222.71059,-9.3651857
75.6,0.75607944,-0.16659151,50.042721,0,11.076097,226.7159,-0.011051298,9.7336664,11.07594,226.17795,-9.3633947
76.8,0.75990355,-0.17114095,50.389511,0,11.076097,230.3159,-0.011339345,9.7932348,11.076771,229.75543,-9.3615656
78.0,0.73657429,-0.17455542,50.438229,0,11.076097,233.91591,-0.011588113,9.4855528,11.076637,233.47978,-9.3593254
79.2,0.75254768,-0.17787227,50.438229,0,11.076097,237.5159,-0.011757622,9.697978,11.076432,237.18829,-9.3572674
80.4,0.76009935,-0.18083222,50.438229,0,11.076097,241.11591,-0.011965022,9.8191099,11.076286,240.81726,-9.3550739
81.6,0.7616576,-0.18562481,50.483898,0,11.076097,244.7159,-0.012322155,9.8133984,11.075982,244.46402,-9.3529692
82.8,0.74911666,-0.18856961,50.82275,0,11.076097,248.3159,-0.012453738,9.6594629,11.076214,247.96761,-9.3503885
84.0,0.7512058,-0.19147766,50.948082,0,11.076097,251.91591,-0.012666998,9.6983929,11.075913,251.55391,-9.3479834
85.2,0.76509756,-0.19533329,51.196281,0,11.076097,255.51588,-0.012973819,9.8706646,11.075385,255.16698,-9.3465376
86.4,0.75677115,-0.19876406,51.196285,0,11.076097,259.11615,-0.013124155,9.7364016,11.076016,258.76541,-9.3452883
87.6,0.75674546,-0.20220035,51.569801,0,11.076097,262.71591,-0.013383651,9.768239,11.075955,262.19928,-9.3432608
88.8,0.75951713,-0.20513166,51.56982,0,11.076097,266.31589,-0.013612363,9.8079576,11.076388,265.85825,-9.3413839
90.0,0.75826901,-0.21134114,51.602787,0,11.076097,269.91589,-0.013944536,9.7863302,11.076603,269.49802,-9.3389559
91.2,0.74438262,-0.21342789,51.932369,0,11.076097,273.51587,-0.014129823,9.6098833,11.074849,273.13467,-9.3365965
92.4,0.74659276,-0.21658026,51.932369,0,11.076097,277.11588,-0.014368458,9.6401653,11.076535,276.70047,-9.3343449
93.6,0.76400858,-0.2205137,52.279282,0,11.076097,280.71591,-0.014552574,9.873374,11.075837,280.19745,-9.331953
94.8,0.7633453,-0.22450899,52.283936,0,11.076097,284.31589,-0.01484759,9.8532848,11.07504,283.85538,-9.3304605
96.0,0.75312662,-0.22764724,52.50671,0,11.076097,287.91586,-0.015095519,9.7342243,11.075724,287.46213,-9.3288946
97.2,0.75746292,-0.23126821,52.634277,0,11.076097,291.5159,-0.01525894,9.7989178,11.077108,291.10733,-9.3270445
98.4,0.76820016,-0.23561077,52.635494,0,11.076097,295.11588,-0.015591738,9.9435606,11.076242,294.75009,-9.3255262
99.6,0.75571591,-0.2381494,52.975834,0,11.076097,298.71591,-0.015787236,9.7573223,11.074942,298.27057,-9.3230391
100.8,0.75436604,-0.24250057,52.97607,0,11.076097,302.31589,-0.015998043,9.7661867,11.07582,301.96356,-9.3210793
102.0,0.76234859,-0.24555284,52.97607,0,11.076097,305.91589,-0.016241619,9.8722553,11.076239,305.52405,-9.3190231
103.2,0.76865715,-0.25054723,53.31657,0,11.076097,309.5159,-0.016612334,9.9436312,11.075757,309.13898,-9.3164234
104.4,0.74868673,-0.25334787,53.31665,0,11.076097,313.11591,-0.016705636,9.686842,11.075638,312.60907,-9.3141022
105.6,0.75680566,-0.25653094,53.657223,0,11.076097,316.71591,-0.016955189,9.8076611,11.076175,316.21436,-9.3119268
106.8,0.76623952,-0.25957298,53.657223,0,11.076097,320.31589,-0.01718949,9.9296274,11.075949,319.81824,-9.3106632
108.0,0.77015227,-0.26486725,53.975826,0,11.076097,323.91592,-0.017465409,9.9703445,11.076783,323.33191,-9.3086863
109.2,0.76047266,-0.26817194,54.101353,0,11.076097,327.5159,-0.017707281,9.8502283,11.075216,326.93762,-9.3070288
110.4,0.75222176,-0.27199125,54.305416,0,11.076097,331.11591,-0.018001767,9.7500772,11.075329,330.64243,-9.3051291
111.6,0.75361365,-0.27577475,54.305416,0,11.076097,334.71591,-0.018178409,9.7633047,11.075768,334.35501,-9.302515
112.8,0.76805806,-0.27896667,54.305416,0,11.076097,338.31592,-0.018408282,9.9704847,11.07554,338.03354,-9.3005047
114.0,0.77514201,-0.28382799,54.305431,0,11.076097,341.91592,-0.018773621,10.049762,11.076486,341.6387,-9.2982092
115.2,0.77127188,-0.28800166,54.467579,0,11.076097,345.51593,-0.018976672,10.000713,11.075761,345.24643,-9.2957993
116.4,0.75270855,-0.29153803,54.624023,0,11.076097,349.11591,-0.019228695,9.7784328,11.075997,348.87558,-9.2935429
117.6,0.75986546,-0.29527649,54.62402,0,11.076097,352.71591,-0.01950651,9.8718491,11.075919,352.54208,-9.2917986
118.8,0.765127,-0.29908726,54.624023,0,11.076097,356.31592,-0.019721717,9.9424849,11.076441,356.04803,-9.290494
120.0,0.77086353,-0.30253643,54.663952,0,11.076097,359.91592,-0.019953897,10.0142,11.076447,359.63104,-9.2887859
121.2,0.77879113,-0.30858266,54.931637,0,11.076097,363.5159,-0.020371772,10.133468,11.076773,363.2359,-9.2871656
122.4,0.76730847,-0.31131113,54.965717,0,11.076097,367.11594,-0.020537751,9.9612713,11.076097,366.71793,-9.2845469
123.6,0.75173962,-0.31542504,55.239254,0,11.076097,370.71591,-0.020836527,9.7683277,11.075351,370.17502,-9.2828369
124.8,0.75304627,-0.31983346,55.440292,0,11.076097,374.31592,-0.021079205,9.7864256,11.076734,373.80228,-9.2801571
126.0,0.76350033,-0.32356471,55.535782,0,11.076097,377.91589,-0.021353358,9.9424553,11.07612,377.50818,-9.2777519
127.2,0.76522499,-0.32685503,55.535885,0,11.076097,381.51593,-0.021589326,9.9555864,11.076199,381.15475,-9.275919
128.4,0.77262861,-0.33187592,55.655167,0,11.076097,385.11591,-0.021853816,10.063344,11.076079,384.75668,-9.2746086
129.6,0.78151751,-0.3375423,55.843506,0,11.076097,388.71591,-0.022255423,10.170537,11.075802,388.37189,-9.272583
130.8,0.76921648,-0.33988836,55.843506,0,11.076097,392.31589,-0.022426657,10.004188,11.076196,391.96481,-9.2710752
132.0,0.74659377,-0.34448603,55.996181,0,11.076097,395.91589,-0.02265856,9.727335,11.076697,395.56998,-9.2683811
133.2,0.75617713,-0.34816676,56.12867,0,11.076097,399.5159,-0.022928204,9.853384,11.077208,399.18683,-9.2668295
134.4,0.75766116,-0.35210857,56.129147,0,11.076097,403.11588,-0.023219528,9.8805685,11.075802,402.77759,-9.2648869
135.6,0.76028168,-0.35619795,56.129147,0,11.076097,406.71591,-0.023452798,9.9149427,11.076089,406.55014,-9.2624636
136.8,0.76583493,-0.35975236,55.852066,0,11.076097,410.31589,-0.023722691,9.9816885,11.075718,410.57312,-9.2602119
138.0,0.77128607,-0.3639088,55.538368,0,11.076097,413.91589,-0.02395723,10.064103,11.076005,414.44727,-9.2578554
139.2,0.77102554,-0.36734197,55.535892,0,11.076097,417.5159,-0.024211364,10.063464,11.075404,418.1171,-9.2561226
140.4,0.77234524,-0.37181792,55.239304,0,11.076097,421.11591,-0.024527233,10.076462,11.075724,421.67783,-9.2540674
141.6,0.77972847,-0.37725314,55.288456,0,11.076097,424.71591,-0.024802618,10.196116,11.076148,424.98376,-9.252635
142.8,0.78065258,-0.38129678,55.53302,0,11.076097,428.31592,-0.025094327,10.191506,11.075891,428.34381,-9.2506771
144.0,0.78216439,-0.38559821,55.587894,0,11.076097,431.91589,-0.025393041,10.210945,11.075555,431.616,-9.2488737
145.2,0.775639,-0.38966128,55.843506,0,11.076097,435.5159,-0.025647739,10.138922,11.075435,435.1413,-9.2463388
146.4,0.77550513,-0.39341706,55.932865,0,11.076097,439.11591,-0.025903957,10.127421,11.076548,438.69815,-9.2439871
147.6,0.77612174,-0.39774296,56.128765,0,11.076097,442.71591,-0.026136136,10.130371,11.076319,442.24747,-9.2416811
148.8,0.77858859,-0.40162241,56.129147,0,11.076097,446.31592,-0.026407337,10.175211,11.076077,446.03168,-9.2396698
150.0,0.7763437,-0.40528068,56.129147,0,11.076097,449.91428,-0.02668087,10.139568,11.076299,449.68121,-9.237381
151.2,0.075060785,-0.41574651,54.932232,0,11.076097,449.9989,-0.02730426,0.97617239,11.07588,451.26672,-9.2377872
152.4,0.072613642,-0.41448972,54.931644,0,11.076097,449.9989,-0.027260389,0.96575981,11.07637,451.01004,-9.2381392
153.6,0.066798091,-0.41422454,54.755154,0,11.076097,449.9989,-0.027227003,0.87256736,11.075502,450.73517,-9.2378292
154.8,0.070728064,-0.41359609,54.81525,0,11.076097,449.9989,-0.027208537,0.93285328,11.075993,450.38162,-9.2381525
156.0,0.068692431,-0.41298333,54.931637,0,11.076097,449.9989,-0.027198168,0.90840673,11.075629,449.95291,-9.2381516
157.2,0.070249759,-0.41264135,55.239254,0,11.076097,449.9989,-0.027105574,0.9236508,11.075534,449.59586,-9.2379255
158.4,0.067666538,-0.41249895,55.685268,0,11.076097,449.9989,-0.027122637,0.89487457,11.076038,449.22421,-9.2378244
159.6,0.067743428,-0.41278884,56.122734,0,11.076097,449.9989,-0.027133396,0.88454163,11.074756,449.0705,-9.2372284
160.8,0.073176973,-0.41302809,56.169598,0,11.076097,449.9989,-0.027171466,0.96052057,11.075837,449.10034,-9.2373714
162.0,0.081921607,-0.41386682,56.424706,0,11.076097,449.9989,-0.02724437,1.0791916,11.075712,449.3504,-9.2369967
163.2,0.08223287,-0.41505268,56.129154,0,11.076097,449.9989,-0.027259391,1.073805,11.076059,449.84534,-9.2368736
164.4,0.082810633,-0.41561508,55.843533,0,11.076097,449.9989,-0.027324034,1.0878447,11.076218,450.32449,-9.2369099
165.6,0.078880258,-0.41654572,55.364292,0,11.076097,449.9989,-0.027379271,1.0234436,11.076487,450.80246,-9.2369661
166.8,0.07468085,-0.41700748,54.932076,0,11.076097,449.9989,-0.027421582,0.97642183,11.075319,451.01096,-9.237092
168.0,0.082526609,-0.417133,54.624027,0,11.076097,449.9989,-0.027463529,1.0703222,11.075368,451.05423,-9.2374001
169.2,0.087022416,-0.41743743,54.305935,0,11.076097,449.9989,-0.027419163,1.1293832,11.076071,450.99243,-9.2373228
170.4,0.088400163,-0.41858473,54.305424,0,11.076097,449.9989,-0.027528202,1.1554626,11.076063,450.78101,-9.2374811
171.6,0.094239034,-0.41953939,54.305416,0,11.076097,449.9989,-0.027565163,1.2298814,11.076378,450.52713,-9.2375631
172.8,0.090576798,-0.41896787,54.305271,0,11.076097,449.9989,-0.027552148,1.1844978,11.075618,450.2305,-9.2374868
174.0,0.076931268,-0.41883117,54.305428,0,11.076097,449.9989,-0.027560392,1.0139316,11.069283,450.02115,-9.2370863
175.2,0.066806629,-0.41897178,54.624023,0,11.076097,449.9989,-0.027554104,0.8739531,11.076805,449.76636,-9.2366333
176.4,0.066494785,-0.41881138,54.931637,0,11.076097,449.9989,-0.027567847,0.87462741,11.074638,449.38434,-9.2363653
177.6,0.06847699,-0.4197273,55.282478,0,11.076097,449.9989,-0.027555188,0.89222169,11.076715,449.0593,-9.2361469
178.8,0.089573458,-0.41972339,55.843159,0,11.076097,449.9989,-0.027577966,1.1718596,11.07668,448.87079,-9.2365522
180.0,0.084699586,-0.42108124,56.045269,0,11.076097,449.9989,-0.027686831,1.1219759,11.075399,448.9592,-9.2368784
181.2,0.082159095,-0.42192081,56.126457,0,11.076097,449.9989,-0.027757846,1.0840479,11.075164,449.27356,-9.2370968
182.4,0.08522971,-0.4228847,55.84351,0,11.076097,449.9989,-0.027841197,1.1210687,11.076932,449.80273,-9.2366524
183.6,0.086877868,-0.42377317,55.569954,0,11.076097,449.9989,-0.027827676,1.14081,11.076129,450.18927,-9.2363033
184.8,0.081012145,-0.42432466,55.317955,0,11.076097,449.9989,-0.027911142,1.0675105,11.076084,450.58289,-9.23629
186.0,0.087864324,-0.4250817,54.931854,0,11.076097,449.9989,-0.027910497,1.1576493,11.075963,450.7977,-9.2366982
187.2,0.087173492,-0.42520049,54.624027,0,11.076097,449.9989,-0.027937692,1.146426,11.076049,450.99634,-9.2368412
188.4,0.067313023,-0.42583165,54.305424,0,11.076097,449.9989,-0.02800153,0.87944877,11.076367,450.9501,-9.2360487
189.6,0.062722586,-0.42587861,54.305424,0,11.076097,449.9989,-0.028016698,0.82404506,11.075703,450.66025,-9.2358704
190.8,0.061482731,-0.42598531,54.41011,0,11.076097,449.9989,-0.028034948,0.80496114,11.076118,450.19162,-9.2359314
192.0,0.059132922,-0.42583311,54.750969,0,11.076097,449.9989,-0.027962349,0.76720017,11.07558,449.72595,-9.2355947
193.2,0.079150505,-0.42592251,55.232998,0,11.076097,449.9989,-0.027998857,1.0437248,11.074924,449.38269,-9.2361727
194.4,0.084973745,-0.42662668,55.274975,0,11.076097,449.9989,-0.028019546,1.1182147,11.076388,449.27231,-9.2363367
195.286,0.17141579,0.018759664,55.535889,0,11.076099,3.2081649,0.0013303411,2.1154714,11.075427,449.3931,-9.2361717
195.2884,0.17869045,0.017519413,55.535889,0,11.076099,1.3868889000000002e-16,0.0013583978,2.2117848,11.075326,449.37155,-9.2365484
195.2908,0.17710127,0.021786479,55.535889,0,11.076099,5.9955178e-33,0.00153837,2.2519534,11.073796,449.34998,-9.2350483
195.2932,0.18155329,0.021404361,50.537636,0,11.076099,0.0,0.0013625935,2.2322254,11.075312,449.33112,-9.2353668
195.2956,0.17070428,0.025186976,37.209019,0,11.076099,0.0,0.0013862839,2.1510792,11.075147,449.31674,-9.2359581
195.298,0.19164838,0.025822811,23.880407,0,11.076099,0.0,0.0015385078,2.435509,11.074016,449.30237,-9.2370844
195.3004,0.16755942,0.027378997,10.551796,0,11.076099,0.0,0.0018723491,2.1648901,11.075933,449.28799,-9.2381315
195.3028,0.17889424,0.021115633,0.0,0,11.076099,0.0,0.0017093153,2.2083406,11.076218,449.27512,-9.2369156
195.3052,0.17503206,0.020137191,0.0,0,11.076099,0.0,0.0015053501,2.267061,11.077765,449.26794,-9.2374401
195.3076,0.16036439,0.020654352,0.0,0,11.076099,0.0,0.0012889453,2.0634184,11.080508,449.26077,-9.2370892
195.31,0.1548205,0.021982623,0.0,0,11.076099,0.0,0.0013258364,1.9929832,11.072837,449.25357,-9.2371178
195.3124,0.16591938,0.023855861,0.0,0,11.076099,0.0,0.0014869705,2.0727108,11.074566,449.24701,-9.236043
195.3148,0.17479478,0.021488866,0.0,0,11.076099,0.0,0.0015458212,2.2637334,11.076928,449.25418,-9.236249
195.3172,0.18347551,0.021957472,0.0,0,11.076099,0.0,0.001671417,2.4316833,11.075991,449.26135,-9.2362537
195.3196,0.16543746,0.022059957,0.0,0,11.076099,0.0,0.0015528715,2.065233,11.069861,449.26852,-9.2362175
195.322,0.1739859,0.025528874,0.0,0,11.076099,0.0,0.0015434086,2.0723441,11.077001,449.27573,-9.2359962
195.3244,0.18393832,0.027591448,0.0,0,11.076099,0.0,0.0014739308,2.353292,11.077481,449.27032,-9.2358809
195.3268,0.1776358,0.026613234,0.0,0,11.076099,0.0,0.0016420998,2.2692125,11.075688,449.26315,-9.2374668
195.3292,0.18169974,0.023884105,0.0,0,11.076099,0.0,0.0018009985,2.2470145,11.075553,449.25598,-9.2361479
195.3316,0.17725676,0.022550931,0.0,0,11.076099,0.0,0.0017563606,2.1585333,11.076299,449.24881,-9.2359467
195.334,0.17870793,0.022993214,0.0,0,11.076099,0.0,0.0015900455,2.3331268,11.075188,449.26196,-9.2375021
195.3364,0.19676834,0.023767704,0.0,0,10.976469,0.0,0.0014460677,2.4784141,11.074331,449.28354,-9.2361517
195.3388,0.19133674,0.024549246,0.0,0,10.615495,0.0,0.0014902183,2.4585931,11.07576,449.30508,-9.2359571
195.3412,0.18128312,0.024919361,0.0,0,10.254521,0.0,0.0015990543,2.3181901,11.058377,449.32663,-9.2363358
195.3436,0.21775684,0.022036908,0.0,0,9.893548,0.0,0.0016116842,2.7296908,10.928177,449.77249,-9.2363396
195.346,0.19580327,0.022727586,0.0,0,9.5325737,0.0,0.0017358984,2.5295393,10.645766,450.57733,-9.2365265
195.3484,0.22827592,0.023513911,0.0,0,9.1800261,0.0,0.0016534412,2.8039908,10.24484,451.38217,-9.2365503
195.3508,5.069922,0.40917623,0.0,0,8.8288584,0.0,0.026674246,63.494564,9.7745342,452.18704,-9.2316484
195.3532,6.0727715,0.81336522,0.0,0,8.4910259,0.0,0.055235863,73.16256,9.2651358,453.1535,-9.231988
195.3556,6.0735517,1.2556498,0.0,0,8.1570415,0.0,0.086750299,71.095169,8.8154049,454.38937,-9.2315197
195.358,6.1907525,1.6346972,0.0,0,7.8342957,0.0,0.11531935,69.980385,8.4405842,455.62524,-9.2323656
195.3604,6.3910956,1.9330987,0.0,0,7.5165353,0.0,0.13784105,70.835327,8.1229267,456.86108,-9.2322254
195.3628,6.4780993,2.2203438,0.0,0,7.2082515,0.0,0.15976591,70.170746,7.8123374,457.54605,-9.2317524
195.3652,6.5866337,2.5183105,0.0,0,6.9060431,0.0,0.18314345,69.907257,7.5229888,456.13754,-9.2326918
195.3676,6.7335706,2.7910719,0.0,0,6.6115613,0.0,0.2053047,69.734009,7.2414637,454.72906,-9.2328281
195.37,6.9362602,3.0716083,0.0,0,6.3240418,0.0,0.22868218,70.262283,6.959166,453.32056,-9.2328243
195.3724,7.0933604,3.3541076,0.0,0,6.042748,0.0,0.25298044,70.083618,6.6661859,451.91089,-9.2319241
195.3748,7.2456708,3.6434746,0.0,0,5.7692914,0.0,0.27817196,69.881935,6.3777122,450.47382,-9.2332888
195.3772,7.4396996,3.9391007,0.0,0,5.5006137,0.0,0.30417287,69.836525,6.081758,449.03674,-9.2333651
195.3796,7.6672339,4.2343488,0.0,0,5.2404532,0.0,0.33084992,70.008553,5.7819381,447.59967,-9.2328568
195.382,7.8092175,4.5243435,0.0,0,4.9838042,0.0,0.35808784,69.505013,5.4965034,446.1626,-9.2330828
195.3844,7.9846473,4.8043547,0.0,0,4.7363639,0.0,0.38564417,69.192284,5.2140198,445.82568,-9.233367
195.3868,8.125494,5.0708241,0.0,0,4.4912457,0.0,0.41269425,68.459892,4.9415669,445.64594,-9.2326918
195.3892,8.3247643,5.3237906,0.0,0,4.2558532,0.0,0.43839052,68.300842,4.682683,445.46619,-9.232214
195.3916,8.509038,5.5699277,0.0,0,4.0217257,0.0,0.46362117,68.125145,4.4381866,445.28644,-9.2323074
195.394,8.6662722,5.809648,0.0,0,3.7978494,0.0,0.48896649,67.6819,4.2025189,443.48068,-9.2326756
195.3964,8.8644114,6.040823,0.0,0,3.5743496,0.0,0.5146172,67.439064,3.9670112,441.0054,-9.2321596
195.3988,9.1031818,6.2651,0.0,0,3.3612847,0.0,0.5404278,67.476608,3.7433727,438.53015,-9.231822
195.4012,9.3742056,6.4870863,0.0,0,3.1483088,0.0,0.56652254,67.742058,3.5219674,436.05487,-9.2308464
195.4036,9.6154451,6.7025747,0.0,0,2.9451065,0.0,0.59215742,67.709877,3.2998605,434.03931,-9.230216
195.406,9.8878355,6.9209571,0.0,0,2.7424984,0.0,0.61810243,67.758934,3.0905585,432.41269,-9.2311811
195.4084,10.157812,7.1359138,0.0,0,2.5483873,0.0,0.64449382,67.884758,2.8789341,430.7861,-9.2304955
195.4108,10.476517,7.3388219,0.0,0,2.3556671,0.0,0.67082828,68.126244,2.6717138,429.15952,-9.231245
195.4132,10.820259,7.5361595,0.0,0,2.1702483,0.0,0.69779676,68.494034,2.4739158,427.10388,-9.2316027
195.4156,11.140473,7.7291679,0.0,0,1.9869361,0.0,0.72455305,68.723793,2.2798278,424.33322,-9.2307911
195.418,11.491952,7.9172416,0.0,0,1.8098084,0.0,0.75053269,69.024033,2.0905857,421.56256,-9.2298384
195.4204,11.893366,8.1028862,0.0,0,1.6354244,0.0,0.77629292,69.619812,1.9080774,418.7919,-9.2290192
195.4228,12.35293,8.2895041,0.0,0,1.4662173,0.0,0.80322534,70.390915,1.7209387,416.05298,-9.2292929
195.4252,12.770358,8.467103,0.0,0,1.3003293,0.0,0.83032554,70.835762,1.5442082,413.43481,-9.2285862
195.4276,13.211158,8.6359243,0.0,0,1.1387084,0.0,0.85721415,71.335381,1.3729681,410.81665,-9.2289248
195.43,13.695964,8.7998466,0.0,0,0.98093235,0.0,0.88406146,71.977005,1.2004368,408.19849,-9.2283592
195.4324,14.211636,8.9631205,0.0,0,0.82657731,0.0,0.9103753,72.739464,1.0338235,405.82224,-9.2279005
195.4348,14.800985,9.1254816,0.0,0,0.67652941,0.0,0.93643463,73.832718,0.87371737,409.01053,-9.2274046
195.4372,15.350285,9.2821045,0.0,0,0.52908593,0.0,0.96257979,74.567032,0.72030061,412.19882,-9.2294188
195.4396,15.93614,9.4314556,0.0,0,0.3862859,0.0,0.98963273,75.380836,0.5688991,415.38712,-9.2279863
195.442,13.753071,9.4766779,0.0,0,0.24542016,0.0,0.99964666,64.625458,0.46506149,418.57541,-9.2306395
195.4444,12.301776,9.4880924,0.0,0,0.10962815,0.0,1.0023813,57.605583,0.41179848,422.63144,-9.2312508
195.4468,11.680897,9.493309,0.0,0,-0.025516368,0.0,1.0026636,54.632195,0.37658203,426.81146,-9.2315512
195.4492,11.272867,9.5035667,0.0,0,-0.15794842,0.0,1.0034301,52.669846,0.34561351,430.99146,-9.2331839
195.4516,11.220469,9.5092735,0.0,0,-0.29038045,0.0,1.0040652,52.337971,0.31013834,435.17148,-9.2332573
195.454,11.492284,9.5151443,0.0,0,-0.42281243,0.0,1.0055926,53.544376,0.24989612,437.86847,-9.233243
195.4564,11.666706,9.5173359,0.0,0,-0.55524439,0.0,1.0069712,54.270775,0.17757264,439.95486,-9.2316265
195.4588,11.691865,9.5211983,0.0,0,-0.68767637,0.0,1.0082425,54.291512,0.1131113,442.04123,-9.2315025
195.4612,11.554073,9.5299797,0.0,0,-0.82010835,0.0,1.0092891,53.658554,0.058363426,444.12759,-9.2319393
195.4636,11.311989,9.5384541,0.0,0,-0.9525404,0.0,1.0095003,52.508396,0.01177439,445.70288,-9.2327595
195.466,10.983474,9.5462999,0.0,0,-1.0849724,0.0,1.0103948,50.931259,-0.017255779,446.84567,-9.2327805
195.4684,10.53846,9.5458488,0.0,0,-0.72870702,450.0,1.0111371,48.836349,-0.031291712,447.98846,-9.2333307
195.4708,10.074511,9.5407314,0.0,0,-0.27022067,450.0,1.0116458,46.677338,-0.030485164,449.13129,-9.233387
195.4732,9.6521378,9.5382624,0.0,0,0.18826568,450.0,1.0116292,44.738083,-0.026552558,450.21201,-9.232873
195.4756,9.3106098,9.5381193,0.0,0,0.64675206,450.0,1.0104301,43.152046,-0.024209566,451.18936,-9.2339268
195.478,9.0690889,9.5390959,0.0,0,1.1052387,450.0,1.0095869,42.082233,-0.02032272,452.16669,-9.2328167
195.4804,8.6031914,9.5401754,0.0,0,1.563725,450.0,1.0098251,39.946507,-0.0051052151,453.14401,-9.2319498
195.4828,7.0860434,9.5374727,0.0,0,2.0222113,450.0,1.009982,32.988495,0.069638096,454.10635,-9.2351751
195.4852,4.5990138,9.5216303,0.0,0,2.4806981,450.0,1.0081142,21.597088,0.21303242,455.01169,-9.2352953
195.4876,1.5232691,9.4989843,0.0,0,2.9391842,450.0,1.0040762,7.3583388,0.44199648,455.91705,-9.2383795
195.49,0.087974444,9.4391689,0.0,0,3.3976707,450.0,0.99250561,0.58732545,0.88809335,456.82242,-9.2390795
195.4924,-0.40826759,9.4318972,0.0,0,3.8561573,450.0,0.99008596,-1.9381458,1.6223445,457.71756,-9.2392025
195.4948,0.15684693,9.4129038,0.0,0,4.3146434,450.0,0.98641646,0.5487231,2.4384854,458.3782,-9.2390738
195.4972,-0.0071861795,9.4255409,0.0,0,4.7731299,450.0,0.98939067,0.13242897,3.1375082,459.03888,-9.2381067
195.4996,-0.037398469,9.4453363,0.0,0,5.2316165,450.0,0.99436122,-0.28748393,3.6367674,459.69952,-9.238554
195.502,0.10718288,9.4759645,0.0,0,5.6901026,450.0,0.99999666,0.52999467,4.0712686,460.36017,-9.2389898
195.5044,-0.02986601,9.4876709,0.0,0,6.1485891,450.0,1.0012784,-0.12916881,4.487421,460.85092,-9.2375231
195.5068,-0.026364561,9.4927559,0.0,0,6.6070752,450.0,1.0012637,-0.15607497,4.9115987,461.31741,-9.2384539
195.5092,0.060683485,9.4944811,0.0,0,7.0655618,450.0,1.0015514,0.27645588,5.3492656,461.78387,-9.2376013
195.5116,0.025801675,9.4925776,0.0,0,7.5240483,450.0,1.0020055,0.22106996,5.8021603,462.25037,-9.2357006
195.514,-0.099554241,9.4906645,0.0,0,7.9825354,450.0,1.0025264,-0.49295607,6.2725163,462.67108,-9.2365274
195.5164,0.13078877,9.4838409,0.0,0,8.441021,450.0,1.0013736,0.57301551,6.7573037,463.073,-9.2355909
195.5188,-0.078558341,9.4898453,0.0,0,8.8995075,450.0,1.0012782,-0.25103647,7.23634,463.47488,-9.2347813
195.5212,-0.012041975,9.4941254,0.0,0,9.3579931,450.0,1.0011524,-0.11212022,7.7106042,463.87677,-9.2357702
195.5236,0.087981716,9.4944458,0.0,0,9.8164806,450.0,1.0012233,0.42554456,8.1863956,464.29031,-9.2343893
195.526,-0.06377475,9.4922934,0.0,0,10.274966,450.0,1.0020789,-0.22366263,8.6608887,464.71375,-9.2350187
195.5284,-0.061606042,9.4887209,0.0,0,10.733453,450.0,1.0024321,-0.3536061,9.1376276,465.13715,-9.2365999
195.5308,0.13650356,9.4815636,0.0,0,11.191939,450.0,1.0010793,0.65741342,9.6208134,465.56058,-9.236681
195.5332,-0.040245973,9.4870167,0.0,0,11.650426,450.0,1.0008413,-0.096815251,10.081587,465.94897,-9.2351294
195.5356,-0.091787972,9.4914646,0.0,0,12.108912,450.0,1.0006597,-0.4957239,10.5568,466.27911,-9.2354641
195.538,0.12060287,9.4899807,0.0,0,12.567399,450.0,1.0006912,0.55289751,11.039819,466.60922,-9.2358551
195.5404,-0.11864993,9.4898567,0.0,0,13.025885,450.0,1.0018542,-0.48762301,11.502801,466.93933,-9.2343826
195.5428,0.072397873,9.4849091,0.0,0,13.484371,450.0,1.0016106,0.2811718,11.950209,467.25153,-9.2340393
195.5452,0.055342115,9.4826155,0.0,0,13.942858,450.0,1.0008886,0.25219175,12.403163,467.49554,-9.2327385
195.5476,-0.05385118,9.4870262,0.0,0,14.401344,450.0,1.0005398,-0.3256444,12.864616,467.73953,-9.2332344
195.55,-0.0069521531,9.4912615,0.0,0,14.859831,450.0,1.0003713,-0.077830866,13.338436,467.98355,-9.2332773
195.5524,0.069596291,9.4941807,0.0,0,15.318317,450.0,1.0012748,0.36901262,13.833419,468.22638,-9.2339277
195.5548,-0.071020164,9.4900169,0.0,0,15.776803,450.0,1.0021547,-0.27025202,14.3064,468.44168,-9.2335405
195.5572,0.047477152,9.4841938,0.0,0,16.235291,450.0,1.0017526,0.12364657,14.778928,468.65698,-9.2335892
195.5596,-0.0071362411,9.4820967,0.0,0,16.693775,450.0,1.0007203,-0.0013037085,15.233715,468.87225,-9.2324457
195.562,-0.067313194,9.4856558,0.0,0,17.152262,450.0,1.0003151,-0.29255667,15.684203,469.08755,-9.2332869
195.5644,0.049485512,9.4906664,0.0,0,17.61075,450.0,1.0006242,0.22157946,16.139696,469.24634,-9.2340374
195.5668,-0.01266688,9.4861288,0.0,0,17.999975,450.0,1.0001833,0.039682001,16.588764,469.39706,-9.2326241
195.5692,-0.084562279,9.4854593,0.0,0,18.0,450.0,1.0011712,-0.44520131,17.047878,469.54776,-9.2339878
195.5716,0.080075055,9.4850397,0.0,0,18.0,450.0,1.0017499,0.33094591,17.474377,469.69849,-9.2335787
195.574,-0.03296918,9.4854412,0.0,0,18.0,450.0,1.001142,-0.12040909,17.858664,469.84918,-9.2341585
195.5764,0.054673798,9.4894829,0.0,0,18.0,450.0,1.0007522,0.29455033,18.181704,469.99988,-9.2374983
195.5788,0.0033279979,9.49895,0.0,0,18.0,450.0,1.0016694,0.058762535,18.414753,470.15057,-9.2397499
195.5812,0.068461545,9.5053959,0.0,0,18.0,450.0,1.0036591,0.31132817,18.52585,470.3013,-9.2437086
195.5836,0.2064705,9.5057898,0.0,0,18.0,450.0,1.0049922,0.93784386,18.507023,470.45587,-9.2501764
195.586,0.32005036,9.5052881,0.0,0,18.0,450.0,1.0055166,1.4644763,18.391729,470.61377,-9.260273
195.5884,0.22517407,9.5034275,0.0,0,18.0,450.0,1.0042077,1.1003615,18.249847,470.77164,-9.2743912
195.5908,0.2685937,9.5054102,0.0,0,18.0,450.0,1.00354,1.2754964,18.128124,470.92953,-9.2906227
195.5932,0.21793884,9.5093966,0.0,0,18.0,450.0,1.0039783,1.0479338,18.058969,471.0578,-9.3099556
195.5956,0.24607973,9.5085154,0.0,0,18.0,450.0,1.0045813,1.1074346,18.043602,471.13675,-9.3302565
195.598,0.27753255,9.5015106,0.0,0,18.0,450.0,1.004355,1.2949734,18.048168,471.2157,-9.3524027
195.6004,0.21987094,9.4983492,0.0,0,18.0,450.0,1.0039915,1.0672734,18.06571,471.29465,-9.3722296
195.6028,0.18854229,9.5002356,0.0,0,18.0,450.0,1.0035683,0.88472921,18.08889,471.3736,-9.3929615
195.6052,0.24625728,9.5060263,0.0,0,18.0,450.0,1.0036993,1.1044713,18.118103,471.45255,-9.411479
195.6076,0.26011732,9.5115366,0.0,0,18.0,450.0,1.0041461,1.2150604,18.136465,471.53146,-9.4291668
195.61,0.27015078,9.5117989,0.0,0,18.0,450.0,1.0050057,1.2470146,18.146687,471.61041,-9.4460773
195.6124,0.24030006,9.5061216,0.0,0,18.0,450.0,1.0053066,1.1213542,18.149139,471.68906,-9.4636288
195.6148,0.21558909,9.5017586,0.0,0,18.0,450.0,1.0046344,1.0074247,18.151415,471.76083,-9.4823847
195.6172,0.27630398,9.4997845,0.0,0,18.0,450.0,1.0033787,1.253499,18.148191,471.83258,-9.499445
195.6196,0.301476,9.5035095,0.0,0,18.0,450.0,1.0030897,1.4003053,18.145723,471.90436,-9.5183887
195.622,0.26144329,9.5062208,0.0,0,18.0,450.0,1.0035902,1.2275599,18.141157,471.9761,-9.5349855
195.6244,0.23315944,9.5056725,0.0,0,18.0,450.0,1.0044134,1.1398098,18.139174,472.02277,-9.5542393
195.6268,0.26446003,9.5015726,0.0,0,18.0,450.0,1.0044965,1.2405814,18.13419,472.06583,-9.5721817
195.6292,0.28351238,9.498682,0.0,0,18.0,450.0,1.0041353,1.3585867,18.130508,472.10889,-9.5900555
195.6316,0.30550247,9.5013447,0.0,0,18.0,450.0,1.0037605,1.4345251,18.130741,472.15192,-9.6097622
195.634,0.25487703,9.5075207,0.0,0,18.0,450.0,1.003796,1.2072369,18.127043,472.20517,-9.6279554
195.6364,0.25043273,9.5113716,0.0,0,18.0,450.0,1.0041496,1.1735014,18.11726,472.26257,-9.6460228
195.6388,0.29333839,9.508357,0.0,0,18.0,450.0,1.0047579,1.3114603,18.113945,472.32001,-9.6632977
195.6412,0.31197068,9.5024357,0.0,0,18.0,450.0,1.0049282,1.4476517,18.116638,472.37744,-9.6804094
195.6436,0.29777724,9.5029917,0.0,0,18.0,450.0,1.0048662,1.3819821,18.113319,472.41928,-9.697257
195.646,0.25160903,9.5050707,0.0,0,18.0,450.0,1.0041257,1.1806428,18.110643,472.448,-9.7151613
195.6484,0.26238587,9.5069618,0.0,0,18.0,450.0,1.0035648,1.2079297,18.114183,472.47668,-9.7332506
195.6508,0.30226156,9.5070543,0.0,0,18.0,450.0,1.0039797,1.419896,18.108206,472.50537,-9.7496223
195.6532,0.31461164,9.5053625,0.0,0,18.0,450.0,1.0044179,1.4557111,18.110168,472.52869,-9.7674522
195.6556,0.26898524,9.5017385,0.0,0,18.0,450.0,1.0046154,1.274025,18.105896,472.54306,-9.7849026
195.658,0.24668573,9.5017061,0.0,0,18.0,450.0,1.004575,1.1320441,18.104435,472.5574,-9.8034468
195.6604,0.3062335,9.5034389,0.0,0,18.0,450.0,1.0037657,1.3978628,18.101,472.57178,-9.8222733
195.6628,0.30829692,9.5073395,0.0,0,18.0,450.0,1.0034959,1.4259069,18.101154,472.58762,-9.8407145
195.6652,0.2947948,9.5110216,0.0,0,18.0,450.0,1.0042732,1.3666273,18.103502,472.60916,-9.8591452
195.6676,0.249127,9.5096684,0.0,0,18.0,450.0,1.0052176,1.1942775,18.103716,472.63068,-9.8775864
195.67,0.27145934,9.5038061,0.0,0,18.0,450.0,1.0051531,1.2329152,18.100676,472.65222,-9.8951693
195.6724,0.31530032,9.5007696,0.0,0,18.0,450.0,1.0042987,1.4802014,18.098366,472.67435,-9.9139872
195.6748,0.31344175,9.5028114,0.0,0,18.0,450.0,1.0035255,1.4355836,18.098679,472.71024,-9.931427
195.6772,0.28911904,9.5082817,0.0,0,18.0,450.0,1.0038216,1.3672287,18.100962,472.74612,-9.9496307
195.6796,0.25202343,9.5081978,0.0,0,18.0,450.0,1.0042082,1.1613927,18.099377,472.78198,-9.9679174
195.682,0.31926426,9.5036907,0.0,0,18.0,450.0,1.0044008,1.4683392,18.096125,472.81787,-9.9860697
195.6844,0.31635398,9.5032015,0.0,0,18.0,450.0,1.0049789,1.4737211,18.09837,472.82864,-10.005033
195.6868,0.31619564,9.5030375,0.0,0,18.0,450.0,1.0044025,1.4701415,18.099909,472.83582,-10.02098
195.6892,0.27569684,9.5070457,0.0,0,18.0,450.0,1.0041307,1.2649809,18.09754,472.84299,-10.038473
195.6916,0.28126794,9.5133896,0.0,0,18.0,450.0,1.0044218,1.3074254,18.095728,472.85016,-10.055665
195.694,0.33685547,9.5127831,0.0,0,18.0,450.0,1.0048114,1.6127003,18.096529,472.8421,-10.074058
195.6964,0.33057114,9.5091934,0.0,0,18.0,450.0,1.0055624,1.5474087,18.093712,472.82773,-10.091745
195.6988,0.31424031,9.5062885,0.0,0,18.0,450.0,1.005667,1.4770536,18.09359,472.81339,-10.111558
195.7012,0.27795774,9.5049906,0.0,0,18.0,450.0,1.0049033,1.3261379,18.091776,472.79904,-10.129956
195.7036,0.33884302,9.5055971,0.0,0,18.0,450.0,1.0036645,1.5596871,18.087963,472.78857,-10.147903
195.706,0.34317571,9.5081129,0.0,0,18.0,450.0,1.0038794,1.6307902,18.08927,472.78137,-10.16503
195.7084,0.33391067,9.5102062,0.0,0,18.0,450.0,1.004796,1.5551358,18.086433,472.7742,-10.183612
195.7108,0.30831051,9.5079384,0.0,0,18.0,450.0,1.00528,1.4636476,18.089136,472.76703,-10.201061
195.7132,0.31105837,9.5044193,0.0,0,18.0,450.0,1.0051931,1.4248259,18.089529,472.76254,-10.218654
195.7156,0.35310772,9.5047436,0.0,0,18.0,450.0,1.0044402,1.6266917,18.082727,472.76254,-10.235818
195.718,0.35465446,9.5078115,0.0,0,18.0,450.0,1.0039564,1.6519969,18.08345,472.76254,-10.253622
195.7204,0.3208763,9.512331,0.0,0,18.0,450.0,1.0042821,1.512431,18.083185,472.76254,-10.273142
195.7228,0.31170756,9.5150976,0.0,0,18.0,450.0,1.0055273,1.4470094,18.084166,472.75806,-10.289769
195.7252,0.34200421,9.5105562,0.0,0,18.0,450.0,1.0059884,1.5754054,18.081722,472.73654,-10.307395
195.7276,0.36555839,9.506278,0.0,0,18.0,450.0,1.0055525,1.7109121,18.082241,472.715,-10.326304
195.73,0.33964485,9.5045118,0.0,0,18.0,450.0,1.0044638,1.6162907,18.082272,472.69348,-10.343607
195.7324,0.32500303,9.5057535,0.0,0,18.0,450.0,1.0037049,1.5081053,18.080042,472.67166,-10.362682
195.7348,0.3153618,9.5097055,0.0,0,18.0,450.0,1.0041661,1.4588815,18.081099,472.64294,-10.381594
195.7372,0.36588973,9.5098314,0.0,0,18.0,450.0,1.0049027,1.7344112,18.08194,472.61423,-10.398353
195.7396,0.35829327,9.5053463,0.0,0,18.0,450.0,1.005031,1.6780015,18.079409,472.58551,-10.416713
195.742,0.33734426,9.5059538,0.0,0,18.0,450.0,1.0052687,1.5313413,18.076792,472.55682,-10.435659
195.7444,0.32315174,9.5072727,0.0,0,18.0,450.0,1.0048039,1.5441209,18.079607,472.52182,-10.454349
195.7468,0.3454937,9.5086718,0.0,0,18.0,450.0,1.0039074,1.5827433,18.078163,472.48596,-10.470017
195.7492,0.36264327,9.5095825,0.0,0,18.0,450.0,1.0037596,1.704687,18.072651,472.45007,-10.487245
195.7516,0.36148643,9.5097666,0.0,0,18.0,450.0,1.0047759,1.684124,18.076351,472.41422,-10.505323
195.754,0.34028259,9.5077105,0.0,0,18.0,450.0,1.0057766,1.5999076,18.074152,472.38849,-10.523852
195.7564,0.33724415,9.5049477,0.0,0,18.0,450.0,1.0053989,1.6204126,18.07262,472.36697,-10.542483
195.7588,0.38628674,9.5044765,0.0,0,18.0,450.0,1.0042654,1.768097,18.073389,472.34543,-10.560658
195.7612,0.38136917,9.5083027,0.0,0,18.0,450.0,1.0038711,1.8147674,18.07233,472.32388,-10.57886
195.7636,0.35692301,9.5081663,0.0,0,18.0,450.0,1.0039202,1.6934617,18.071436,472.31015,-10.595554
195.766,0.34659094,9.5074921,0.0,0,18.0,450.0,1.0046901,1.6515218,18.072411,472.30295,-10.615135
195.7684,0.36910245,9.5051432,0.0,0,18.0,450.0,1.0053281,1.6970967,18.067745,472.29578,-10.632358
195.7708,0.37860602,9.5038395,0.0,0,18.0,450.0,1.004952,1.7530726,18.07082,472.2886,-10.648882
195.7732,0.38333279,9.5050087,0.0,0,18.0,450.0,1.0042526,1.8090063,18.069885,472.27066,-10.667829
195.7756,0.35226366,9.51194,0.0,0,18.0,450.0,1.0044332,1.65848,18.068981,472.23477,-10.686224
195.778,0.36141655,9.5152464,0.0,0,18.0,450.0,1.0050033,1.68882,18.067221,472.19888,-10.705266
195.7804,0.38685662,9.5113611,0.0,0,18.0,450.0,1.0054135,1.7775769,18.068857,472.16299,-10.722323
195.7828,0.40614718,9.5053034,0.0,0,18.0,450.0,1.0054228,1.8977723,18.070242,472.12561,-10.739222
195.7852,0.38043728,9.5040903,0.0,0,18.0,450.0,1.0050312,1.7538908,18.066031,472.08255,-10.758716
195.7876,0.3530775,9.5046101,0.0,0,18.0,450.0,1.0040514,1.6220644,18.066717,472.03952,-10.777315
195.79,0.3734614,9.5097971,0.0,0,18.0,450.0,1.0041478,1.7693707,18.064602,471.99646,-10.795259
195.7924,0.3945168,9.509696,0.0,0,18.0,450.0,1.0043691,1.8342284,18.066525,471.9552,-10.813424
195.7948,0.39165938,9.5076084,0.0,0,18.0,450.0,1.0049412,1.8558688,18.063665,471.9552,-10.832051
195.7972,0.36909834,9.5054846,0.0,0,18.0,450.0,1.0053473,1.7300748,18.060968,471.9552,-10.850078
195.7996,0.37480521,9.5037327,0.0,0,18.0,450.0,1.0048248,1.7609142,18.064022,471.9552,-10.867452
195.802,0.39446262,9.5068483,0.0,0,18.0,450.0,1.0042372,1.8640331,18.063354,471.9552,-10.88303
195.8044,0.40129429,9.5110989,0.0,0,18.0,450.0,1.0040231,1.8656055,18.061357,471.94891,-10.90194
195.8068,0.38053635,9.5124702,0.0,0,18.0,450.0,1.0046293,1.802879,18.062605,471.94174,-10.920931
195.8092,0.36835691,9.5088272,0.0,0,18.0,450.0,1.0053777,1.7029067,18.06288,471.93457,-10.938183
195.8116,0.37735665,9.5029535,0.0,0,18.0,450.0,1.0051275,1.7546592,18.06028,471.9274,-10.955197
195.814,0.40884313,9.5003271,0.0,0,18.0,450.0,1.0041938,1.8936542,18.058027,471.88971,-10.973359
195.8164,0.40559959,9.5033693,0.0,0,18.0,450.0,1.0036597,1.9229056,18.058935,471.83945,-10.991618
195.8188,0.37947008,9.5097742,0.0,0,18.0,450.0,1.0040005,1.7737818,18.058922,471.78922,-11.010343
195.8212,0.39186224,9.5093079,0.0,0,18.0,450.0,1.0044054,1.7826593,18.059616,471.73898,-11.029062
195.8236,0.39793077,9.5061655,0.0,0,18.0,450.0,1.0047311,1.8302783,18.05868,471.70816,-11.0462
195.826,0.41803694,9.5028172,0.0,0,18.0,450.0,1.0048808,1.924942,18.057737,471.69382,-11.062987
195.8284,0.3978425,9.5045395,0.0,0,18.0,450.0,1.0044692,1.8402474,18.056095,471.67947,-11.08033
195.8308,0.38498157,9.5089512,0.0,0,18.0,450.0,1.0043445,1.7996362,18.052101,471.66513,-11.09885
195.8332,0.4092356,9.5128746,0.0,0,18.0,450.0,1.0042472,1.8617108,18.05374,471.65616,-11.118
195.8356,0.40954277,9.5123005,0.0,0,18.0,450.0,1.004833,1.8973706,18.053951,471.65616,-11.134294
195.838,0.43238249,9.508935,0.0,0,18.0,450.0,1.0055468,1.9991887,18.052402,471.65616,-11.152838
195.8404,0.39100817,9.5056887,0.0,0,18.0,450.0,1.0055808,1.8846158,18.053556,471.65616,-11.170419
195.8428,0.40282968,9.5057812,0.0,0,18.0,450.0,1.0048565,1.8835022,18.051222,471.64719,-11.18858
195.8452,0.41143453,9.5084019,0.0,0,18.0,450.0,1.0042022,1.8951738,18.050879,471.60413,-11.206209
195.8476,0.42607212,9.509449,0.0,0,18.0,450.0,1.0041709,1.9742584,18.046839,471.56107,-11.223693
195.85,0.41649514,9.5097666,0.0,0,18.0,450.0,1.0046916,1.976827,18.048779,471.51801,-11.242085
195.8524,0.39547452,9.5068817,0.0,0,18.0,450.0,1.0051337,1.8689537,18.048128,471.47556,-11.261735
195.8548,0.41915324,9.5022326,0.0,0,18.0,450.0,1.004884,1.9386951,18.04829,471.44684,-11.27939
195.8572,0.43378526,9.5023203,0.0,0,18.0,450.0,1.0041254,2.0135975,18.049747,471.41815,-11.298159
195.8596,0.43912446,9.5088091,0.0,0,18.0,450.0,1.0040724,2.0584126,18.04949,471.38943,-11.316118
195.862,0.40605134,9.5160522,0.0,0,18.0,450.0,1.0048518,1.9271942,18.050024,471.36075,-11.334011
195.8644,0.40348935,9.5139856,0.0,0,18.0,450.0,1.0053998,1.8861716,18.048656,471.35715,-11.35168
196.0663,0.4106518,9.5089607,0.0,0,18.0,0.85476661,1.0049736,1.9143505,18.026228,464.55325,-11.479373
197.2663,0.45818451,9.5205278,0.0,0,18.0,3.6951402e-17,1.0069909,2.1306767,18.000599,445.3158,-11.480421
198.4663,0.48154676,9.5290594,0.0,0,18.0,1.5974028e-33,1.0084648,2.2330966,18.000467,431.54166,-11.481453
199.6663,0.48604903,9.5354595,0.0,0,18.0,1.4012985e-45,1.0097317,2.2504578,18.000242,419.52982,-11.481124
200.8663,0.49057758,9.5420341,0.0,0,18.0,1.4012985e-45,1.0108676,2.2710035,18.000025,408.38327,-11.481177
202.0663,0.49729073,9.547761,0.0,0,18.0,1.4012985e-45,1.0121548,2.2943051,17.999393,398.00739,-11.480965
203.2663,0.50652415,9.5536146,0.0,0,18.0,1.4012985e-45,1.0131605,2.3389494,18.000198,388.05157,-11.48062
204.4663,0.51341254,9.5583944,0.0,0,18.0,1.4012985e-45,1.014101,2.3711157,18.000046,378.28696,-11.480659
205.6663,0.51898873,9.5642099,0.0,0,18.0,1.4012985e-45,1.0151255,2.3907447,17.999584,369.04623,-11.481091
206.8663,0.52636665,9.5694704,0.0,0,18.0,1.4012985e-45,1.0159944,2.4258173,17.998657,360.07632,-11.481608
208.0663,0.52701467,9.5749407,0.0,0,18.0,1.4012985e-45,1.0169398,2.4270442,17.999681,351.25769,-11.481781
209.2663,0.53618807,9.5799322,0.0,0,18.0,1.4012985e-45,1.0177991,2.4682202,18.000147,342.74051,-11.481544
210.4663,0.54205668,9.5852222,0.0,0,18.0,1.4012985e-45,1.0188849,2.4931438,17.99996,334.44528,-11.48084
211.6663,0.54781336,9.5901985,0.0,0,18.0,1.4012985e-45,1.0196974,2.5177782,18.000044,326.23425,-11.481141
212.8663,0.54990709,9.5943632,0.0,0,18.0,1.4012985e-45,1.0207033,2.5240834,17.999718,318.44559,-11.480987
214.0663,0.56442142,9.5994024,0.0,0,18.0,1.4012985e-45,1.0215254,2.5926058,17.999571,310.55368,-11.480789
215.2663,0.5631839,9.6031599,0.0,0,18.0,1.4012985e-45,1.0224133,2.5834296,17.999777,303.28809,-11.481296
216.4663,0.57756788,9.6086626,0.0,0,18.0,1.4012985e-45,1.0233819,2.6446834,17.999653,295.97363,-11.481629
217.6663,0.5805133,9.613348,0.0,0,18.0,1.4012985e-45,1.024223,2.6596076,18.000532,288.74234,-11.481837
218.8663,0.5844565,9.6176529,0.0,0,18.0,1.4012985e-45,1.0249995,2.6724105,17.999165,281.97253,-11.481829
220.0663,0.58434665,9.6217909,0.0,0,18.0,1.4012985e-45,1.0256499,2.670646,17.998941,275.32092,-11.481235
221.2663,0.58957273,9.6265621,0.0,0,18.0,1.4012985e-45,1.0265145,2.692641,17.999598,268.70425,-11.480997
222.4663,0.59573996,9.6309423,0.0,0,18.0,1.4012985e-45,1.027297,2.7168601,18.000031,262.2319,-11.481087
223.6663,0.59801829,9.6350374,0.0,0,18.0,1.4012985e-45,1.0280643,2.7244895,18.00061,256.06802,-11.480515
224.8663,0.60499376,9.6383705,0.0,0,18.0,1.4012985e-45,1.0286334,2.7534792,18.001101,250.12267,-11.48066
226.0663,0.6166867,9.6423349,0.0,0,18.0,1.4012985e-45,1.029518,2.8053925,18.000612,244.23775,-11.48042
227.2663,0.6160726,9.6469965,0.0,0,18.0,1.4012985e-45,1.0302664,2.7966058,17.999271,238.46877,-11.480978
228.4663,0.62020713,9.6502934,0.0,0,18.0,1.4012985e-45,1.0311279,2.8114009,18.001051,232.93127,-11.481161
229.6663,0.62212652,9.6540651,0.0,0,18.0,1.4012985e-45,1.0316852,2.8188069,18.00057,227.54982,-11.481292
230.8663,0.62358034,9.6569357,0.0,0,18.0,1.4012985e-45,1.0324409,2.8250334,18.000814,222.22549,-11.481207
232.0663,0.62733871,9.660614,0.0,0,18.0,1.4012985e-45,1.033024,2.8359027,17.999161,217.14719,-11.48173
233.2663,0.62969095,9.6635542,0.0,0,18.0,1.4012985e-45,1.033602,2.8514268,18.000198,212.24144,-11.481201
234.4663,0.63361043,9.6676302,0.0,0,18.0,1.4012985e-45,1.0343601,2.8679361,17.999836,207.32056,-11.480823
235.6663,0.63413739,9.6705666,0.0,0,18.0,1.4012985e-45,1.0348568,2.8708861,17.999496,202.49402,-11.479985
236.8663,0.63040495,9.6737289,0.0,0,18.0,1.4012985e-45,1.0354491,2.8498137,18.000025,197.9481,-11.479802
238.0663,0.64348298,9.677083,0.0,0,18.0,1.4012985e-45,1.0359615,2.9083924,17.999205,193.53529,-11.479885
239.2663,0.641949,9.6803102,0.0,0,18.0,1.4012985e-45,1.0365916,2.899961,17.999559,187.71349,-11.479949
240.4663,0.65657067,9.683279,0.0,0,18.0,1.4012985e-45,1.0371302,2.9675863,18.000425,183.33313,-11.479988
241.6663,0.66083342,9.6857691,0.0,0,18.0,1.4012985e-45,1.0375199,2.9815607,17.999208,179.15858,-11.480988
242.8663,0.65463269,9.6889563,0.0,0,18.0,1.4012985e-45,1.0381418,2.9562972,18.000633,175.19626,-11.481204
244.0663,0.67251641,9.6922522,0.0,0,18.0,1.4012985e-45,1.0387634,3.0382431,18.00033,171.38536,-11.48173
245.2663,0.66395336,9.6951008,0.0,0,18.0,1.4012985e-45,1.0392495,2.9960406,18.000191,167.55988,-11.48178
246.4663,0.66095883,9.6977606,0.0,0,18.0,1.4012985e-45,1.0398507,2.9788835,18.000574,163.86685,-11.482167
247.6663,0.66685402,9.7005701,0.0,0,18.0,1.4012985e-45,1.0402582,3.0018296,17.999905,160.18491,-11.480971
248.8663,0.6630525,9.7029133,0.0,0,18.0,1.4012985e-45,1.0408796,2.9860692,17.999313,156.83478,-11.480128
250.0663,0.66545802,9.7057896,0.0,0,18.0,1.4012985e-45,1.0412569,2.9936764,18.001343,153.31433,-11.479797
251.2663,0.67118967,9.7077465,0.0,0,18.0,1.4012985e-45,1.0417778,3.0207121,18.00045,149.93904,-11.479913
252.4663,0.6792354,9.711091,0.0,0,18.0,1.4012985e-45,1.0422716,3.0523844,17.998837,146.75244,-11.479826
253.6663,0.68767405,9.7125292,0.0,0,18.0,1.4012985e-45,1.0426862,3.0878246,18.00075,143.53189,-11.480814
254.8663,0.68028778,9.7152624,0.0,0,18.0,1.4012985e-45,1.0430768,3.0496781,18.000381,140.48097,-11.481287
255.8663,0.69060665,9.7173538,0.0,0,18.0,1.4012985e-45,1.0434763,3.0988321,17.999557,137.94791,-11.481704