File: examples/hot axisymmetric compression example/data/02 screened data/testID_0143.csv
Time(sec),Force(kN),Jaw(mm),PowAngle(deg),Power(W),Pram,PTemp,Strain,Stress(MPa),Stroke(mm),TC1(C),wedge(mm)
0.0,0.81408125,0.51498306,0.0,0,11.076097,0.0016262159,0.034906007,10.026862,11.076912,26.010845,-9.1466761
1.2,0.76137835,0.0036518914,0.0,0,11.076097,3.5159009,0.00021603795,9.6928787,11.077259,25.94544,-9.4880676
2.4,0.74233502,0.0035979974,0.0,0,11.076097,7.1159019,0.00022673681,9.4528027,11.075991,25.837187,-9.4855375
3.6,0.72068805,0.0036177214,0.0,0,11.076097,10.715903,0.00024258577,9.1704311,11.076276,25.854973,-9.4845123
4.8,0.70161521,0.0034323663,0.0,0,11.076097,14.315903,0.00024214633,8.9492683,11.076109,25.789597,-9.4820766
6.0,0.68953794,0.0034963249,0.0,0,11.076097,17.915903,0.00027401396,8.7843981,11.075435,25.755297,-9.4800463
7.2,0.67422777,0.0034083496,0.0,0,11.076097,21.515905,0.00026625095,8.5848742,11.075858,25.71809,-9.4774809
8.4,0.66522771,0.0033863054,0.0,0,11.076097,25.115908,0.00025318953,8.4767542,11.07514,25.771168,-9.4754658
9.6,0.6609059,0.0038939358,17.822039,0,11.076097,28.71591,0.00026275899,8.4098234,11.076468,25.717129,-9.4732523
10.8,0.66494215,0.0037941292,30.941643,0,11.076097,32.315907,0.00024260719,8.4781513,11.076664,26.628891,-9.4714184
12.0,0.67522442,0.0016181079,38.372337,0,11.076097,35.915916,9.9692807e-05,8.6160069,11.075683,29.113474,-9.4696178
13.2,0.67959511,-0.0022628433,41.787296,0,11.076097,39.515915,-0.00014281053,8.6566839,11.076213,33.127216,-9.4675903
14.4,0.68823481,-0.0060160551,43.52771,0,11.076097,43.115921,-0.00037928615,8.763485,11.076836,38.014473,-9.4654179
15.6,0.70822334,-0.00974409,43.527851,0,11.076097,46.715923,-0.00064733269,9.0230684,11.076678,43.458248,-9.463418
16.8,0.71080035,-0.012309146,42.978527,0,11.076097,50.315929,-0.00084070151,9.0658846,11.076283,48.787209,-9.461256
18.0,0.70482355,-0.015424558,41.804947,0,11.076097,53.915924,-0.0010587978,8.9865627,11.075633,53.687557,-9.4588785
19.2,0.70740587,-0.018007644,41.198734,0,11.076097,57.515926,-0.0012319838,9.0234833,11.077129,57.93906,-9.4569349
20.4,0.71177721,-0.020485159,40.271172,0,11.076097,61.115929,-0.0013887339,9.0668182,11.075534,61.80962,-9.4547033
21.6,0.71725559,-0.022593075,40.393147,0,11.076097,64.715904,-0.0015120006,9.1438665,11.076547,65.144188,-9.4529648
22.8,0.71001261,-0.024884822,40.572506,0,11.076097,68.315918,-0.0016429459,9.0704107,11.075243,68.209702,-9.4507484
24.0,0.71310228,-0.027211443,41.781853,0,11.076097,71.915916,-0.0017804798,9.0938396,11.076462,71.390854,-9.4486427
25.2,0.71434397,-0.029524326,42.396229,0,11.076097,75.515907,-0.0019296422,9.1037235,11.075825,74.631088,-9.4467058
26.4,0.72867781,-0.0323071,42.978512,0,11.076097,79.115921,-0.0021349839,9.2942238,11.075581,78.162712,-9.4444075
27.6,0.72087395,-0.034845803,43.527828,0,11.076097,82.715927,-0.002331072,9.1945038,11.076487,81.762733,-9.442235
28.8,0.71421641,-0.037818778,44.028461,0,11.076097,86.315926,-0.0025206141,9.1170444,11.076513,85.395126,-9.4401045
30.0,0.72817832,-0.040512424,44.077145,0,11.076097,89.915932,-0.0026844717,9.3022976,11.076144,89.169846,-9.4380198
31.2,0.73226798,-0.04402259,44.593693,0,11.076097,93.51593,-0.0029242539,9.3488054,11.075932,92.851967,-9.4358826
32.4,0.73679143,-0.045665625,44.604488,0,11.076097,97.115921,-0.0030648264,9.3985643,11.076781,96.479645,-9.4340677
33.6,0.73557031,-0.04853427,44.899067,0,11.076097,100.71593,-0.0032613736,9.3983135,11.076616,100.17155,-9.4319696
34.8,0.72941577,-0.051845584,45.12085,0,11.076097,104.31593,-0.0034711543,9.3199577,11.075994,103.89448,-9.4296894
36.0,0.72816128,-0.054655269,45.12085,0,11.076097,107.91594,-0.0036430955,9.3000946,11.076476,107.58873,-9.4274321
37.2,0.7386483,-0.058718298,45.12085,0,11.076097,111.51593,-0.0038946571,9.4505634,11.075517,111.16477,-9.4254961
38.4,0.73485357,-0.060315873,45.615231,0,11.076097,115.11594,-0.0039814766,9.3841124,11.075885,114.73094,-9.4234285
39.6,0.74226183,-0.063142993,45.615231,0,11.076097,118.71593,-0.0041695344,9.4835892,11.076437,118.3084,-9.4209833
40.8,0.74230355,-0.066385664,46.109619,0,11.076097,122.31594,-0.0044001709,9.4909172,11.076125,121.74807,-9.4189138
42.0,0.75052029,-0.068859093,46.581554,0,11.076097,125.91594,-0.0045938427,9.5946856,11.076812,125.25751,-9.4172382
43.2,0.74785286,-0.072269864,47.054306,0,11.076097,129.51607,-0.0047987043,9.5651798,11.076316,128.6906,-9.4152679
44.4,0.76278007,-0.075100385,47.252354,0,11.076097,133.11594,-0.0049755974,9.7633438,11.076359,132.30678,-9.4134836
45.6,0.76574963,-0.078970052,47.504883,0,11.076097,136.71593,-0.0052508814,9.8070049,11.077244,135.99048,-9.4112787
46.8,0.7774598,-0.081998847,47.504883,0,11.076097,140.31593,-0.005476648,9.9541216,11.076366,139.76469,-9.4094534
48.0,0.77642417,-0.084746391,47.873009,0,11.076097,143.91594,-0.0056670024,9.9456949,11.075464,143.46083,-9.4072571
49.2,0.78592467,-0.087628685,47.955318,0,11.076097,147.51593,-0.0058428319,10.067341,11.074918,147.11211,-9.4050884
50.4,0.78318465,-0.090857096,48.010075,0,11.076097,151.11594,-0.0060466714,10.037552,11.076224,150.67149,-9.403224
51.6,0.79103613,-0.093642011,48.383781,0,11.076097,154.71596,-0.0061946679,10.141577,11.075826,154.19525,-9.4011984
52.8,0.78290707,-0.0966129,48.812206,0,11.076097,158.31593,-0.0063838577,10.036793,11.077019,157.60707,-9.398119
54.0,0.80161667,-0.10002544,49.229721,0,11.076097,161.91595,-0.0066415523,10.275785,11.076442,161.03568,-9.3961096
55.2,0.80140465,-0.10314544,49.636215,0,11.076097,165.51595,-0.0068633994,10.28527,11.076051,164.4917,-9.3942957
56.4,0.8097921,-0.10683049,50.034752,0,11.076097,169.11595,-0.007099086,10.379189,11.076634,168.22571,-9.3925877
57.6,0.815382,-0.1104696,50.042721,0,11.076097,172.71594,-0.0073239906,10.45878,11.075458,171.94109,-9.3911085
58.8,0.81827074,-0.11337247,50.230587,0,11.076097,176.31595,-0.0075451946,10.495102,11.076399,175.70773,-9.389061
60.0,0.81871873,-0.11569595,50.257931,0,11.076097,179.91594,-0.0077110552,10.494471,11.076645,179.47531,-9.3868856
61.2,0.815512,-0.11914257,50.438229,0,11.076097,183.51593,-0.0079262275,10.483057,11.076112,183.07613,-9.384696
62.4,0.81967181,-0.12196174,50.494732,0,11.076097,187.11595,-0.008095786,10.532671,11.076113,186.75056,-9.3827744
63.6,0.82525164,-0.125489,50.764153,0,11.076097,190.71594,-0.0083121117,10.595839,11.076718,190.41273,-9.3806419
64.8,0.82955289,-0.12853159,50.82275,0,11.076097,194.31593,-0.0085017318,10.658778,11.07615,194.07632,-9.3784761
66.0,0.83693731,-0.1314196,50.82275,0,11.076097,197.91595,-0.0087154666,10.742838,11.076405,197.70073,-9.3763781
67.2,0.84571755,-0.13468672,50.82275,0,11.076097,201.51595,-0.0089517627,10.873605,11.076841,201.3185,-9.374198
68.4,0.84857011,-0.13894688,51.196278,0,11.076097,205.11594,-0.0091992775,10.904102,11.075689,204.73549,-9.3725481
69.6,0.84358674,-0.14078365,51.207142,0,11.076097,208.71596,-0.0093460297,10.822108,11.076344,208.31673,-9.3706226
70.8,0.8451395,-0.14395003,51.56982,0,11.076097,212.31595,-0.009576628,10.857664,11.075885,211.67535,-9.3686094
72.0,0.8457948,-0.14722586,51.982578,0,11.076097,215.91595,-0.0097919572,10.874245,11.076043,215.07292,-9.3668938
73.2,0.85374057,-0.15063247,52.574032,0,11.076097,219.51596,-0.0099987518,10.981476,11.076618,218.48004,-9.3649359
74.4,0.86275142,-0.15400149,52.635494,0,11.076097,223.11597,-0.01018288,11.104932,11.075468,222.24042,-9.3628016
75.6,0.86787277,-0.15763319,52.74437,0,11.076097,226.71594,-0.010420493,11.168146,11.074891,226.06621,-9.3606691
76.8,0.87505138,-0.16255598,52.967422,0,11.076097,230.31598,-0.010783846,11.268948,11.076554,229.79718,-9.3583775
78.0,0.86821026,-0.16574995,52.97607,0,11.076097,233.91595,-0.010982092,11.165301,11.075774,233.57016,-9.3561878
79.2,0.86213708,-0.16880286,52.974041,0,11.076097,237.51596,-0.011169028,11.095063,11.076589,237.21695,-9.354435
80.4,0.86363822,-0.17217536,52.97607,0,11.076097,241.11597,-0.011434451,11.127545,11.07508,240.90181,-9.3522873
81.6,0.87123251,-0.17525218,52.97607,0,11.076097,244.71597,-0.011638335,11.221139,11.076764,244.48706,-9.3509054
82.8,0.87516636,-0.17888199,53.31662,0,11.076097,248.31596,-0.011863489,11.268274,11.076024,247.96664,-9.3489161
84.0,0.88538551,-0.18186699,53.31665,0,11.076097,251.91599,-0.012029055,11.412227,11.076086,251.45499,-9.3469658
85.2,0.88274705,-0.18539165,53.657223,0,11.076097,255.51596,-0.012250651,11.382488,11.076274,254.93837,-9.3448372
86.4,0.88838834,-0.18870318,53.872143,0,11.076097,259.11621,-0.012506847,11.443897,11.07553,258.54645,-9.34266
87.6,0.89456338,-0.19255584,53.975826,0,11.076097,262.71597,-0.012763608,11.539968,11.076172,262.09906,-9.3407564
88.8,0.89942932,-0.19696735,54.304703,0,11.076097,266.31598,-0.013025901,11.606063,11.075672,265.73557,-9.3384266
90.0,0.90025777,-0.20098701,54.305416,0,11.076097,269.91599,-0.013330786,11.617903,11.075205,269.39941,-9.3361444
91.2,0.8948319,-0.20433348,54.571281,0,11.076097,273.51599,-0.01355429,11.558389,11.076251,272.99387,-9.3341827
92.4,0.90583545,-0.20741965,54.624023,0,11.076097,277.11597,-0.013733441,11.694763,11.076199,276.67841,-9.3327417
93.6,0.89718586,-0.21057223,54.624023,0,11.076097,280.716,-0.013912017,11.583372,11.077073,280.33142,-9.3308859
94.8,0.89993721,-0.21374612,54.823719,0,11.076097,284.31601,-0.014115917,11.611859,11.076033,283.93784,-9.3287992
96.0,0.9010973,-0.21753214,54.931637,0,11.076097,287.91602,-0.014406091,11.616636,11.075876,287.6265,-9.3270206
97.2,0.90354025,-0.22088264,54.931637,0,11.076097,291.51599,-0.014611276,11.659616,11.075899,291.15689,-9.3252048
98.4,0.89468956,-0.22425139,55.103035,0,11.076097,295.11597,-0.014836497,11.558237,11.076399,294.73813,-9.3227882
99.6,0.90701163,-0.2274632,55.239254,0,11.076097,298.71597,-0.01508914,11.71502,11.075928,298.23541,-9.3210983
100.8,0.90516841,-0.23119703,55.532936,0,11.076097,302.31601,-0.015314512,11.696009,11.075446,301.78241,-9.3185587
102.0,0.91338819,-0.23576027,55.535885,0,11.076097,305.91599,-0.015586601,11.817155,11.076036,305.34116,-9.316431
103.2,0.91939437,-0.23991853,55.843472,0,11.076097,309.51602,-0.01583036,11.894357,11.075682,308.91803,-9.3145866
104.4,0.92487389,-0.24260016,55.843506,0,11.076097,313.116,-0.016038151,11.962712,11.076668,312.60648,-9.3123827
105.6,0.9224242,-0.24501218,55.956089,0,11.076097,316.71597,-0.016205516,11.943619,11.076628,316.27219,-9.3104076
106.8,0.92379433,-0.24869868,56.012871,0,11.076097,320.31598,-0.016420972,11.969045,11.076213,320.02307,-9.3082304
108.0,0.92153203,-0.25249729,55.945992,0,11.076097,323.91599,-0.016707251,11.935961,11.076285,323.71155,-9.3062801
109.2,0.9131313,-0.25667468,55.867989,0,11.076097,327.51599,-0.016994182,11.822124,11.075494,327.47867,-9.3047628
110.4,0.91116375,-0.26034957,55.84351,0,11.076097,331.11597,-0.017211335,11.804493,11.075475,331.16089,-9.3029947
111.6,0.9133063,-0.26442418,55.84351,0,11.076097,334.71597,-0.017438887,11.829556,11.075101,334.73935,-9.3009224
112.8,0.92309493,-0.26791093,55.84351,0,11.076097,338.31601,-0.01768814,11.952744,11.075425,338.29037,-9.2991791
114.0,0.9303183,-0.27316913,56.129147,0,11.076097,341.91599,-0.018053412,12.056736,11.075412,341.72159,-9.2964125
115.2,0.93055636,-0.27508897,56.129147,0,11.076097,345.51599,-0.018160267,12.074548,11.076575,345.29367,-9.2944403
116.4,0.93001133,-0.27850696,56.129147,0,11.076097,349.116,-0.018415313,12.064824,11.076207,348.98822,-9.2923183
117.6,0.91469258,-0.28278667,56.129147,0,11.076097,352.716,-0.018693285,11.863053,11.075694,352.55087,-9.2900295
118.8,0.91766101,-0.28676203,56.129147,0,11.076097,356.31601,-0.018931918,11.907417,11.076323,356.13803,-9.2883329
120.0,0.92411137,-0.29048774,56.425545,0,11.076097,359.91599,-0.019144185,11.996204,11.076016,359.6369,-9.2863989
121.2,0.93186098,-0.29360312,56.425777,0,11.076097,363.51602,-0.019389318,12.083807,11.076371,363.29248,-9.2851
122.4,0.93649518,-0.29920524,56.425777,0,11.076097,367.116,-0.019738242,12.165249,11.075035,366.89847,-9.2828045
123.6,0.93902189,-0.30280018,56.479179,0,11.076097,370.716,-0.020000041,12.204496,11.076626,370.46985,-9.2809467
124.8,0.94028646,-0.30503058,56.697369,0,11.076097,374.31601,-0.020161688,12.227374,11.077308,374.02667,-9.27948
126.0,0.93195748,-0.30893677,56.711422,0,11.076097,377.91599,-0.020387072,12.121139,11.076407,377.59039,-9.2773046
127.2,0.93080395,-0.31310332,56.71172,0,11.076097,381.51599,-0.020622792,12.112009,11.074689,381.16687,-9.2750006
128.4,0.92656642,-0.31703365,56.986084,0,11.076097,385.11603,-0.020908862,12.056681,11.07614,384.73499,-9.2726326
129.6,0.92149127,-0.32094771,56.986084,0,11.076097,388.716,-0.021166598,11.994093,11.07606,388.38123,-9.2706499
130.8,0.92735583,-0.3251099,57.060863,0,11.076097,392.31601,-0.021444967,12.068571,11.075197,391.9454,-9.2686243
132.0,0.93738359,-0.32856807,57.260609,0,11.076097,395.91602,-0.021690648,12.198042,11.076402,395.58502,-9.2664537
133.2,0.9516294,-0.33438638,57.260738,0,11.076097,399.51602,-0.022047827,12.382414,11.075388,399.16302,-9.2644463
134.4,0.053109545,-0.3462072,55.844025,0,11.076097,399.99893,-0.022796908,0.70384216,11.076152,401.90182,-9.2642241
135.6,0.040402036,-0.34442407,55.228653,0,11.076097,399.99893,-0.022682277,0.52767903,11.076521,401.97849,-9.264101
136.8,0.033824716,-0.34335944,54.871502,0,11.076097,399.99893,-0.022634219,0.45222118,11.076061,401.67236,-9.264431
138.0,0.031539571,-0.34269887,54.809818,0,11.076097,399.99893,-0.022583559,0.41286284,11.076145,401.04407,-9.2648258
139.2,0.026582953,-0.3418079,54.992207,0,11.076097,399.99893,-0.022558048,0.34487832,11.076102,400.29642,-9.265173
140.4,0.032239944,-0.34203002,55.535881,0,11.076097,399.99893,-0.02254935,0.42484024,11.076446,399.50244,-9.2647429
141.6,0.041051794,-0.34218404,56.129147,0,11.076097,399.99893,-0.02252122,0.53383285,11.075974,398.8165,-9.2649193
142.8,0.033002105,-0.34121647,56.983334,0,11.076097,399.99893,-0.022481499,0.44558099,11.076748,398.228,-9.2649965
144.0,0.025308751,-0.34157628,57.535397,0,11.076097,399.99893,-0.022522653,0.33408925,11.077232,397.87775,-9.2642937
145.2,0.031581614,-0.34202239,58.337177,0,11.076097,399.99893,-0.02254929,0.42252982,11.076668,397.71213,-9.2640104
146.4,0.041002844,-0.34222668,58.843834,0,11.076097,399.99893,-0.022587942,0.52464128,11.075742,397.86633,-9.2634516
147.6,0.05986876,-0.34420609,58.936386,0,11.076097,399.99893,-0.02269428,0.78203481,11.075259,398.3801,-9.2634497
148.8,0.062540919,-0.34405065,58.853767,0,11.076097,399.99893,-0.022652527,0.81273675,11.075986,399.12241,-9.2644033
150.0,0.054414723,-0.34542677,58.590096,0,11.076097,399.99893,-0.022766382,0.70988584,11.077092,399.98914,-9.2648096
151.2,0.049754888,-0.34609735,58.077618,0,11.076097,399.99893,-0.022802683,0.66538298,11.075643,400.69492,-9.2643957
152.4,0.066600084,-0.34789047,57.535431,0,11.076097,399.99893,-0.022946129,0.87285942,11.07669,401.30777,-9.2640467
153.6,0.060681365,-0.3469204,56.986092,0,11.076097,399.99893,-0.022895729,0.79260653,11.076365,401.60583,-9.2641373
154.8,0.058847416,-0.34741327,56.425816,0,11.076097,399.99893,-0.02289054,0.77739322,11.075541,401.75076,-9.2647066
156.0,0.054326799,-0.34777465,56.008617,0,11.076097,399.99893,-0.022882951,0.70613462,11.076693,401.68356,-9.2651815
157.2,0.064482629,-0.34870675,55.836384,0,11.076097,399.99893,-0.022986889,0.83618444,11.075977,401.45514,-9.2650824
158.4,0.042321768,-0.34777123,55.607365,0,11.076097,399.99893,-0.022906253,0.54970813,11.07653,400.98184,-9.2645216
159.6,0.03018483,-0.34764189,55.843506,0,11.076097,399.99893,-0.022942524,0.40032014,11.076786,400.20331,-9.2638521
160.8,0.02531982,-0.34812084,56.678192,0,11.076097,399.99893,-0.02294801,0.31241131,11.075871,399.21021,-9.2635736
162.0,0.023311013,-0.34733716,57.665943,0,11.076097,399.99893,-0.022860851,0.30080435,11.076111,397.93625,-9.2636242
163.2,0.026328841,-0.34717932,58.852638,0,11.076097,399.99893,-0.022867138,0.34259254,11.076402,396.83524,-9.2640085
164.4,0.051370516,-0.34802929,59.600826,0,11.076097,399.99893,-0.022927115,0.65975887,11.076126,396.76035,-9.2646551
165.6,0.067722678,-0.35074192,59.600838,0,11.076097,399.99893,-0.023127884,0.87743282,11.076448,398.01874,-9.2643852
166.8,0.065509319,-0.35112137,59.111687,0,11.076097,399.99893,-0.023168195,0.84969091,11.076493,399.61627,-9.2645512
168.0,0.061638642,-0.35286969,58.337788,0,11.076097,399.99893,-0.023247076,0.8047179,11.075813,401.12222,-9.2648563
169.2,0.060110126,-0.35366356,57.104076,0,11.076097,399.99893,-0.023274483,0.78495091,11.075884,402.3927,-9.2651138
170.4,0.058677107,-0.35520157,56.129166,0,11.076097,399.99893,-0.02340664,0.76736432,11.076203,403.04266,-9.2649927
171.6,0.041622143,-0.35488099,55.239262,0,11.076097,399.99893,-0.02338103,0.55277723,11.076322,403.00977,-9.2647495
172.8,0.028474664,-0.35412878,54.624092,0,11.076097,399.99893,-0.023371082,0.37861076,11.075946,402.45151,-9.2642899
174.0,0.02002695,-0.35413846,54.931637,0,11.076097,399.99893,-0.02333181,0.25955757,11.07604,401.11313,-9.2638836
175.2,0.01319526,-0.35337368,56.109646,0,11.076097,399.99893,-0.023251917,0.1764711,11.075344,399.3125,-9.2636127
176.4,0.0089668073,-0.35250908,57.491329,0,11.076097,399.99893,-0.023238182,0.12133715,11.075689,397.48022,-9.2634621
177.6,0.02022923,-0.35302511,59.052711,0,11.076097,399.99893,-0.023252655,0.27428022,11.075457,396.06815,-9.2636757
178.64,0.13609242,0.017559307,50.040722,0,11.076099,65.880898,0.0011230373,1.7105002,11.076744,395.28549,-9.2649441
178.6424,0.14196995,0.018817285,35.536125,0,11.076099,2.8482205e-15,0.0011059133,1.6760201,11.072741,395.2637,-9.2649097
178.6448,0.15480171,0.018470824,21.03153,0,11.076099,1.2312851e-31,0.001188941,1.9950626,11.074883,395.24194,-9.2642164
178.6472,0.13652168,0.019243607,6.5269361,0,11.076099,0.0,0.001424663,1.7972136,11.076068,395.22018,-9.2634869
178.6496,0.15262362,0.016851211,0.0,0,11.076099,0.0,0.0013152256,1.8201113,11.076019,395.21439,-9.2641001
178.652,0.13935576,0.017407743,0.0,0,11.076099,0.0,0.0011986607,1.759376,11.075562,395.22162,-9.2627668
178.6544,0.12184486,0.021031991,0.0,0,11.076099,0.0,0.0011952268,1.6904136,11.076755,395.22888,-9.264226
178.6568,0.1411925,0.024855772,0.0,0,11.076099,0.0,0.0013903587,1.7537401,11.074761,395.23611,-9.264308
178.6592,0.14624211,0.021615511,0.0,0,11.076099,0.0,0.0014410539,1.7498176,11.076335,395.24338,-9.2648506
178.6616,0.13929914,0.019729372,0.0,0,11.076099,0.0,0.0014968176,1.7700846,11.076149,395.25064,-9.2639828
178.664,0.14560898,0.016421968,0.0,0,11.076099,0.0,0.0013679907,1.9674159,11.075124,395.25787,-9.262886
178.6664,0.13843441,0.018370794,0.0,0,11.076099,0.0,0.0012290393,1.7383525,11.077074,395.26514,-9.2637205
178.6688,0.13383792,0.019190719,0.0,0,11.076099,0.0,0.0011231628,1.7659345,11.076329,395.2673,-9.2647038
178.6712,0.16287807,0.020356869,0.0,0,11.076099,0.0,0.0012316735,1.965322,11.074712,395.25281,-9.2639465
178.6736,0.15296559,0.019633677,0.0,0,11.076099,0.0,0.0013799396,1.9610827,11.075117,395.23831,-9.2645235
178.676,0.14172317,0.019655084,0.0,0,11.076099,0.0,0.0015200439,1.9031276,11.073728,395.22382,-9.2649441
178.6784,0.1523774,0.020082243,0.0,0,11.076099,0.0,0.0014449885,1.9249543,11.073139,395.20984,-9.264163
178.6808,0.16063155,0.022148645,0.0,0,11.076099,0.0,0.0013333381,1.9708894,11.074077,395.20261,-9.2648735
178.6832,0.1648021,0.024800265,0.0,0,11.076099,0.0,0.0013383583,2.055126,11.072971,395.19534,-9.2646942
178.6856,0.15543738,0.024256233,0.0,0,11.076099,0.0,0.0014520552,2.0457137,11.074904,395.18808,-9.2649364
178.688,0.14898309,0.02172845,0.0,0,11.076099,0.0,0.0016209868,1.9500469,11.074013,395.18085,-9.2658243
178.6904,0.1508657,0.019273151,0.0,0,11.006544,0.0,0.0015716741,1.9714905,11.072511,395.20016,-9.2657003
178.6928,0.15772144,0.018994313,0.0,0,10.645576,0.0,0.0012606679,2.0552876,11.076962,395.22192,-9.265048
178.6952,0.16683607,0.020330835,0.0,0,10.284603,0.0,0.0012118963,2.1282556,11.062988,395.24368,-9.2647791
178.6976,0.20027348,0.021134805,0.0,0,9.9236288,0.0,0.0012584642,2.420269,10.942996,395.26544,-9.2642879
178.7,0.13864367,0.019862564,0.0,0,9.5626554,0.0,0.0013456004,1.7541276,10.670863,395.2652,-9.2638197
178.7024,0.21545355,0.018164705,0.0,0,9.2092905,0.0,0.0014284154,2.7435923,10.278268,395.25793,-9.2646732
178.7048,5.8561554,0.31763175,0.0,0,8.8581219,0.0,0.020450082,73.249069,9.8205853,395.2507,-9.2590733
178.7072,7.0778928,0.74948776,0.0,0,8.518857,0.0,0.051024765,84.75753,9.326642,395.24344,-9.260911
178.7096,7.2617078,1.1630371,0.0,0,8.1848736,0.0,0.079915278,85.026314,8.8888388,395.39719,-9.2580919
178.712,7.3181362,1.5640289,0.0,0,7.8607755,0.0,0.10935435,83.537346,8.5058327,395.65823,-9.2593222
178.7144,7.6887465,1.8742211,0.0,0,7.543015,0.0,0.13318361,85.699944,8.1692057,395.91928,-9.2585278
178.7168,7.7921095,2.1677539,0.0,0,7.2334356,0.0,0.15607327,84.74221,7.8498445,396.18036,-9.2592506
178.7192,8.0318403,2.472069,0.0,0,6.9312277,0.0,0.17981607,85.506523,7.5462508,396.25562,-9.2594185
178.7216,8.1411629,2.760375,0.0,0,6.6355219,0.0,0.20284297,84.662773,7.2527447,396.09604,-9.2594976
178.724,8.4216385,3.0419867,0.0,0,6.3480015,0.0,0.22600317,85.543137,6.9654341,395.93646,-9.2588844
178.7264,8.6149483,3.319783,0.0,0,6.065536,0.0,0.24970233,85.422424,6.6821585,395.77689,-9.259264
178.7288,8.8285923,3.601383,0.0,0,5.792079,0.0,0.27439368,85.457298,6.4015245,395.09729,-9.2595949
178.7312,9.0131102,3.8857987,0.0,0,5.5222936,0.0,0.29979196,84.956642,6.1123128,393.10236,-9.2599154
178.7336,9.2702007,4.1707706,0.0,0,5.2621331,0.0,0.32532373,85.203163,5.8235745,391.10739,-9.25877
178.736,9.5103407,4.4566669,0.0,0,5.0044241,0.0,0.35169294,85.145248,5.5390587,389.11246,-9.2593365
178.7384,9.7376871,4.735146,0.0,0,4.7569842,0.0,0.37835464,84.929413,5.2642975,386.92191,-9.2596006
178.7408,9.9593763,5.0053301,0.0,0,4.5108657,0.0,0.40554118,84.453087,4.99261,383.36224,-9.2593737
178.7432,10.192187,5.2621861,0.0,0,4.2754698,0.0,0.43214923,84.229912,4.730165,379.80258,-9.2586193
178.7456,10.451297,5.5139022,0.0,0,4.0404716,0.0,0.45822716,84.16021,4.4729056,376.24292,-9.257946
178.748,10.741591,5.7566161,0.0,0,3.8165054,0.0,0.48359162,84.252457,4.2274804,372.68326,-9.2590389
178.7504,10.995233,5.9937601,0.0,0,3.5926332,0.0,0.5091821,84.141068,3.99229,369.66623,-9.2586498
178.7528,11.243414,6.2248478,0.0,0,3.3790326,0.0,0.53539979,83.776123,3.7654777,366.66791,-9.2577162
178.7552,11.561522,6.4430699,0.0,0,3.1660566,0.0,0.56106955,83.946556,3.5434155,363.66956,-9.25809
178.7576,11.905659,6.6543941,0.0,0,2.9619906,0.0,0.58658075,84.27372,3.3263307,360.67123,-9.2573786
178.76,12.251677,6.8652744,0.0,0,2.7593822,0.0,0.61175871,84.596443,3.1179035,358.2926,-9.257288
178.7624,12.604875,7.0773106,0.0,0,2.5644474,0.0,0.63738525,84.807594,2.9070539,356.06088,-9.257062
178.7648,13.017118,7.2869277,0.0,0,2.3717272,0.0,0.66384506,85.291214,2.6998038,353.82919,-9.2584381
178.7672,13.460683,7.4911861,0.0,0,2.1855242,0.0,0.69122666,85.793968,2.4952269,351.59747,-9.257822
178.7696,13.954132,7.6861339,0.0,0,2.0022123,0.0,0.71843517,86.583832,2.2957926,348.55472,-9.2559414
178.772,14.400675,7.8771391,0.0,0,1.8243403,0.0,0.74518394,87.006042,2.0994291,345.07523,-9.2555008
178.7744,14.870378,8.0652895,0.0,0,1.6499563,0.0,0.77112335,87.508194,1.9163439,341.59573,-9.2552061
178.7768,15.385717,8.2465973,0.0,0,1.4800413,0.0,0.79684734,88.267921,1.7359889,338.11624,-9.2541504
178.7792,15.976054,8.4219208,0.0,0,1.3141534,0.0,0.82334453,89.246414,1.5604085,336.22537,-9.2549133
178.7816,16.574009,8.5894299,0.0,0,1.1518564,0.0,0.84976536,90.148903,1.3865159,335.97693,-9.2545891
178.784,17.199291,8.7507191,0.0,0,0.99408036,0.0,0.87599289,91.183548,1.2182313,335.72849,-9.2535658
178.7864,17.870144,8.9110117,0.0,0,0.83908135,0.0,0.9018361,92.332672,1.0547609,335.48001,-9.2541771
178.7888,18.645817,9.0744715,0.0,0,0.68903339,0.0,0.92809474,93.757629,0.89132529,336.35764,-9.2533512
178.7912,19.457239,9.2370825,0.0,0,0.54098594,0.0,0.95491683,95.245522,0.73465091,339.4873,-9.2523775
178.7936,20.236414,9.3867683,0.0,0,0.39818591,0.0,0.98171741,96.500313,0.57793403,342.617,-9.2538071
178.796,17.995672,9.4319124,0.0,0,0.25673628,0.0,0.99162805,85.248169,0.4735451,345.74667,-9.255456
178.7984,16.390177,9.4428396,0.0,0,0.12094415,0.0,0.9941864,77.361694,0.42592543,348.80731,-9.2562265
178.8008,15.687918,9.4478445,0.0,0,-0.014479235,0.0,0.99430728,73.946808,0.39333004,351.54248,-9.2563314
178.8032,15.322599,9.4568882,0.0,0,-0.14691243,0.0,0.99484742,72.147255,0.3636623,354.27768,-9.2571802
178.8056,15.432921,9.4637022,0.0,0,-0.27934441,0.0,0.99572045,72.557846,0.31329909,357.01288,-9.2586107
178.808,15.729514,9.4713669,0.0,0,-0.41177642,0.0,0.99789524,73.797539,0.2497585,359.73767,-9.2599449
178.8104,15.817513,9.4729118,0.0,0,-0.54420841,0.0,0.99908513,74.170242,0.18136963,361.84991,-9.258256
178.8128,15.782371,9.4751701,0.0,0,-0.67664039,0.0,0.999825,73.957031,0.12219454,363.96213,-9.2578802
178.8152,15.636853,9.4843607,0.0,0,-0.80907238,0.0,1.000537,73.223282,0.063915618,366.07434,-9.257966
178.8176,15.403417,9.4915953,0.0,0,-0.94150436,0.0,1.0007149,72.110405,0.022099825,368.18655,-9.2576017
178.82,15.054148,9.4973001,10.567695,0,-1.0739365,0.0,1.0017538,70.427185,-0.0037083095,369.80872,-9.2592707
178.8224,14.559731,9.4970703,22.879429,0,-0.76691425,400.0,1.0029006,68.023979,-0.019481966,371.34998,-9.259263
178.8248,14.044824,9.4908047,35.191158,0,-0.3084279,400.0,1.0028687,65.633713,-0.015585837,372.89127,-9.2604294
178.8272,13.628615,9.4892998,47.502895,0,0.15005845,400.0,1.0021695,63.716125,-0.012180057,374.43253,-9.2606211
178.8296,13.270193,9.4940443,51.196289,0,0.60854483,400.0,1.0019063,62.067516,-0.0080789505,376.22229,-9.2603645
178.832,12.97807,9.4996634,51.196289,0,1.0670311,400.0,1.0023364,60.701389,-0.0075487443,378.11856,-9.2608852
178.8344,12.519769,9.4941216,51.196289,0,1.5255175,400.0,1.0015978,58.580387,0.0019894389,380.0148,-9.260025
178.8368,10.968967,9.4933777,51.196289,0,1.9840039,400.0,1.0025482,51.415459,0.070482209,381.91104,-9.2613096
178.8392,8.3702927,9.4778767,49.15123,0,2.4424908,400.0,1.0003549,39.436497,0.2046033,383.67245,-9.2639914
178.8416,4.6805468,9.4617748,45.375809,0,2.9009769,400.0,0.99693924,22.290848,0.42378524,385.31973,-9.2669621
178.844,0.13917896,9.3876247,41.600388,0,3.3594635,400.0,0.98273784,0.60105664,0.80608422,386.96704,-9.271594
178.8464,-0.18855007,9.3278446,37.824966,0,3.8179498,400.0,0.97120601,-0.64275628,1.529735,388.61432,-9.2716999
178.8488,-0.077113613,9.2862053,35.49683,0,4.2764363,400.0,0.96515411,-0.59552163,2.3435464,390.14175,-9.272541
178.8512,0.075840116,9.2550364,35.49683,0,4.7349229,400.0,0.9606508,0.48339126,3.0697978,391.47635,-9.270484
178.8536,-0.1606784,9.2741861,35.49683,0,5.1934094,400.0,0.96406835,-0.79123676,3.5972567,392.81097,-9.268877
178.856,0.11000799,9.3054905,35.49683,0,5.651895,400.0,0.96847302,0.51523656,4.0319571,394.1456,-9.2676363
178.8584,-0.093067206,9.3537397,33.815052,0,6.1103816,400.0,0.97595048,-0.35910857,4.449286,395.39188,-9.2679014
178.8608,-0.034323454,9.4092894,26.340824,0,6.5688682,400.0,0.98588777,-0.17701523,4.8718252,396.33395,-9.2678576
178.8632,0.8049053,9.4613667,18.866598,0,7.0273547,400.0,0.99665105,3.8617263,5.3027973,397.27606,-9.2676497
178.8656,0.065417737,9.4325886,11.392372,0,7.4858413,400.0,0.99242973,0.37952268,5.7594423,398.21814,-9.2659216
178.868,-0.072584063,9.4344778,4.4165039,0,7.9443278,400.0,0.99212193,-0.35098282,6.2327299,399.15097,-9.2660227
178.8704,0.26595294,9.4487467,4.4165039,0,8.4028139,400.0,0.9935568,1.1673256,6.7143674,399.95447,-9.2656679
178.8728,0.055382043,9.4515467,4.4165039,0,8.8612995,400.0,0.9931823,0.3714751,7.2047701,400.75793,-9.2649965
178.8752,0.065198556,9.4511681,4.4165039,0,9.3197861,400.0,0.99381167,0.30058524,7.6778235,401.56143,-9.2654638
178.8776,0.077386104,9.4513521,4.4165039,0,9.7782726,400.0,0.99509519,0.33816975,8.1541815,402.3649,-9.2650547
178.88,0.14964014,9.4436579,3.4517658,0,10.236759,400.0,0.99434882,0.74539572,8.6247787,403.11578,-9.2648954
178.8824,-0.012954284,9.4440775,2.3896806,0,10.695246,400.0,0.99351656,-0.049298044,9.0927076,403.86136,-9.2644463
178.8848,0.17359619,9.4480867,1.3275954,0,11.153732,400.0,0.9932521,0.82749724,9.5675383,404.60693,-9.2644777
178.8872,0.088368036,9.4527397,0.26551008,0,11.612218,400.0,0.99401319,0.42921418,10.0369,405.35251,-9.2649088
178.8896,0.078099251,9.4497318,0.0,0,12.070705,400.0,0.99419934,0.34244701,10.512517,405.98404,-9.2647762
178.892,0.13232981,9.4465666,0.0,0,12.529191,400.0,0.99448085,0.59111995,10.995345,406.57761,-9.2642803
178.8944,0.072271228,9.4471006,0.0,0,12.987678,400.0,0.99468732,0.40120035,11.468918,407.17117,-9.2639389
178.8968,0.079223894,9.4481516,0.0,0,13.446164,400.0,0.99366647,0.32908487,11.920927,407.76471,-9.2641258
178.8992,0.16778976,9.4508228,0.0,0,13.904651,400.0,0.99325132,0.75729966,12.374441,408.31546,-9.2631664
178.9016,0.054867547,9.4548979,0.0,0,14.363137,400.0,0.99392766,0.31965399,12.826374,408.83664,-9.2626705
178.904,0.10482717,9.4525061,0.0,0,14.821624,400.0,0.99492395,0.49924737,13.290596,409.35782,-9.2635288
178.9064,0.12520415,9.4458475,0.0,0,15.28011,400.0,0.99469495,0.57812715,13.771503,409.879,-9.2640924
178.9088,0.10285076,9.446517,0.0,0,15.738596,400.0,0.99432552,0.5458225,14.251885,410.37817,-9.263341
178.9112,0.066745035,9.4481211,0.0,0,16.197083,400.0,0.99348193,0.35599667,14.727128,410.84857,-9.2628021
178.9136,0.13944618,9.4498768,0.0,0,16.655569,400.0,0.99321896,0.62593639,15.197865,411.31897,-9.2630119
178.916,0.099154599,9.4506445,0.0,0,17.114056,400.0,0.99386472,0.45113993,15.653017,411.7894,-9.2629156
178.9184,0.071341112,9.4454851,0.0,0,17.572542,400.0,0.99415696,0.35838789,16.10573,412.23978,-9.2612686
178.9208,0.16815104,9.4434948,0.0,0,17.999401,400.0,0.99415672,0.81219077,16.561811,412.63745,-9.2618523
178.9232,0.09046533,9.4489708,0.0,0,18.0,400.0,0.99436271,0.41986868,17.019522,413.0351,-9.2621527
178.9256,0.19331698,9.4543505,0.0,0,18.0,400.0,0.99405503,0.90917343,17.454718,413.43274,-9.2640495
178.928,0.12446696,9.456501,0.0,0,18.0,400.0,0.99394095,0.57610428,17.842453,413.81854,-9.2640667
178.9304,0.1588389,9.4547253,0.0,0,18.0,400.0,0.99477291,0.7245512,18.166714,414.11478,-9.2651224
178.9328,0.20183977,9.4494905,0.0,0,18.0,400.0,0.99518579,0.9506346,18.397738,414.41098,-9.2687159
178.9352,0.22601512,9.4468641,0.0,0,18.0,400.0,0.99473357,1.0692916,18.507858,414.70718,-9.2730494
178.9376,0.28278488,9.4495964,0.0,0,18.0,400.0,0.99404806,1.3092128,18.497036,415.00339,-9.2806025
178.94,0.19574298,9.4534578,0.0,0,18.0,400.0,0.99400771,0.96934444,18.378859,415.25806,-9.2891703
178.9424,0.24746518,9.4536867,0.0,0,18.0,400.0,0.9941256,1.1350955,18.241432,415.51089,-9.300437
178.9448,0.30103934,9.4505682,0.0,0,18.0,400.0,0.99467111,1.4378177,18.126789,415.76376,-9.3168726
178.9472,0.22579384,9.448328,0.0,0,18.0,400.0,0.99510193,1.1071694,18.054653,416.01663,-9.3346395
178.9496,0.2160759,9.4477692,0.0,0,18.0,400.0,0.99452686,0.99232286,18.042978,416.2637,-9.3545103
178.952,0.22797674,9.448657,0.0,0,18.0,400.0,0.99349678,1.0559893,18.047419,416.50934,-9.3746138
178.9544,0.26535872,9.4511194,0.0,0,18.0,400.0,0.99321377,1.2271291,18.061895,416.75497,-9.3949852
178.9568,0.24805169,9.4491587,0.0,0,18.0,400.0,0.99341536,1.1742872,18.09374,417.00061,-9.4144573
178.9592,0.20251164,9.4488716,0.0,0,18.0,400.0,0.99467969,0.96613455,18.120317,417.20453,-9.4331245
178.9616,0.2158045,9.4448318,0.0,0,18.0,400.0,0.99456686,0.98497182,18.136631,417.38513,-9.4526758
178.964,0.26459783,9.444623,0.0,0,18.0,400.0,0.99344909,1.2098336,18.143114,417.56573,-9.470665
178.9664,0.27941975,9.4466143,0.0,0,18.0,400.0,0.9927662,1.3324594,18.148443,417.74634,-9.4872885
178.9688,0.24260947,9.448185,0.0,0,18.0,400.0,0.99310964,1.2006272,18.150219,417.90601,-9.5051737
178.9712,0.22738333,9.4479904,0.0,0,18.0,400.0,0.99379623,1.0489565,18.142601,418.04327,-9.5230989
178.9736,0.26157677,9.4429932,0.0,0,18.0,400.0,0.99394131,1.1936997,18.142004,418.18051,-9.539753
178.976,0.28874648,9.4417582,0.0,0,18.0,400.0,0.99380004,1.359347,18.142538,418.31778,-9.5553379
178.9784,0.28177097,9.4466248,0.0,0,18.0,400.0,0.99338484,1.3518064,18.141962,418.45505,-9.5738955
178.9808,0.25171292,9.4507999,0.0,0,18.0,400.0,0.99323803,1.2179718,18.130121,418.59232,-9.5930157
178.9832,0.24853855,9.4528418,0.0,0,18.0,400.0,0.99383223,1.1471665,18.131247,418.72955,-9.6116266
178.9856,0.28527552,9.4481678,0.0,0,18.0,400.0,0.99430317,1.3305382,18.131039,418.86682,-9.6289692
178.988,0.2936919,9.4431067,0.0,0,18.0,400.0,0.99418944,1.4161116,18.122986,419.00287,-9.6455412
178.9904,0.28190446,9.4443617,0.0,0,18.0,400.0,0.99377191,1.2991484,18.124094,419.13293,-9.6636553
178.9928,0.2446508,9.4471951,0.0,0,18.0,400.0,0.99331701,1.1693047,18.11912,419.26297,-9.6820011
178.9952,0.26985651,9.4487829,0.0,0,18.0,400.0,0.99325222,1.2557471,18.11886,419.39301,-9.6987658
178.9976,0.30382884,9.4509544,0.0,0,18.0,400.0,0.99407041,1.401265,18.113464,419.52271,-9.7162361
179.0,0.2896252,9.447773,0.0,0,18.0,400.0,0.99450886,1.3749771,18.111998,419.60941,-9.7342911
179.0024,0.26720619,9.4451294,0.0,0,18.0,400.0,0.99446094,1.2952439,18.110207,419.69608,-9.7520714
179.0048,0.25239423,9.4446192,0.0,0,18.0,400.0,0.99352342,1.1588519,18.109949,419.78278,-9.7716951
179.0072,0.29769731,9.44839,0.0,0,18.0,400.0,0.99321294,1.3942603,18.109177,419.86948,-9.7886238
179.0096,0.3091149,9.4506283,0.0,0,18.0,400.0,0.99320978,1.4647549,18.108616,419.93774,-9.8069525
179.012,0.27969393,9.4515781,0.0,0,18.0,400.0,0.99435192,1.3332015,18.109039,420.00275,-9.8232269
179.0144,0.24922833,9.4448853,0.0,0,18.0,400.0,0.99437642,1.1529895,18.106127,420.06778,-9.8423643
179.0168,0.28221664,9.440527,0.0,0,18.0,400.0,0.99360156,1.3075832,18.107277,420.13278,-9.8595953
179.0192,0.30116734,9.4421616,0.0,0,18.0,400.0,0.99271226,1.4134517,18.107849,420.19281,-9.8781567
179.0216,0.29510128,9.447648,0.0,0,18.0,400.0,0.99279362,1.4019994,18.105173,420.25061,-9.8941765
179.024,0.28479001,9.4482365,0.0,0,18.0,400.0,0.99318635,1.3343084,18.103977,420.30841,-9.91224
179.0264,0.25814489,9.4466581,0.0,0,18.0,400.0,0.99384964,1.2202594,18.104275,420.36621,-9.9297733
179.0288,0.30563515,9.4401026,0.0,0,18.0,400.0,0.99360693,1.4346256,18.104567,420.42401,-9.9478903
179.0312,0.31788805,9.4401388,0.0,0,18.0,400.0,0.99295545,1.4794964,18.097055,420.48181,-9.9658518
179.0336,0.29708162,9.4466162,0.0,0,18.0,400.0,0.99308157,1.419198,18.093904,420.53961,-9.9840059
179.036,0.27377993,9.4546747,0.0,0,18.0,400.0,0.99366176,1.2782763,18.097672,420.59741,-10.002289
179.0384,0.29015186,9.4547701,0.0,0,18.0,400.0,0.99450099,1.3557912,18.093138,420.63626,-10.020213
179.0408,0.30726776,9.4475298,0.0,0,18.0,400.0,0.99452108,1.4353929,18.094381,420.64346,-10.037428
179.0432,0.3227593,9.4413366,0.0,0,18.0,400.0,0.99393374,1.5974164,18.095049,420.6507,-10.055773
179.0456,0.28981119,9.4443436,0.0,0,18.0,400.0,0.99332786,1.3799446,18.098614,420.65793,-10.072635
179.048,0.29399106,9.4469547,0.0,0,18.0,400.0,0.99288988,1.385941,18.094385,420.66357,-10.092246
179.0504,0.33356711,9.4475307,0.0,0,18.0,400.0,0.99310899,1.5371804,18.091875,420.66357,-10.108212
179.0528,0.33873498,9.446949,0.0,0,18.0,400.0,0.99382997,1.6119692,18.092293,420.66357,-10.123597
179.0552,0.32420006,9.4443235,0.0,0,18.0,400.0,0.99433774,1.5432405,18.092144,420.66357,-10.142397
179.0576,0.30371326,9.4442501,0.0,0,18.0,400.0,0.99403095,1.4369895,18.089123,420.66568,-10.160884
179.06,0.32348356,9.445734,0.0,0,18.0,400.0,0.99323541,1.5296543,18.092863,420.70181,-10.179068
179.0624,0.338884,9.4497595,0.0,0,18.0,400.0,0.99291199,1.5781692,18.092125,420.73792,-10.196446
179.0648,0.35923892,9.4519424,0.0,0,18.0,400.0,0.99367803,1.722175,18.086679,420.77405,-10.214571
179.0672,0.31695473,9.4512434,0.0,0,18.0,400.0,0.99483597,1.5107777,18.084181,420.81018,-10.231946
179.0696,0.31531385,9.4461098,0.0,0,18.0,400.0,0.99469602,1.4697486,18.0847,420.81378,-10.250723
179.072,0.3454667,9.4416733,0.0,0,18.0,400.0,0.99332368,1.6044216,18.083,420.81378,-10.268087
179.0744,0.34765318,9.4430313,0.0,0,18.0,400.0,0.99247646,1.6437806,18.081203,420.81378,-10.285087
179.0768,0.34841374,9.4494753,0.0,0,18.0,400.0,0.99313742,1.6541804,18.080671,420.81378,-10.302315
179.0792,0.32151353,9.4494171,0.0,0,18.0,400.0,0.99381018,1.5315678,18.085527,420.81915,-10.32184
179.0816,0.31823868,9.4462557,0.0,0,18.0,400.0,0.99423927,1.4861723,18.081699,420.82635,-10.337945
179.084,0.35282069,9.4417381,0.0,0,18.0,400.0,0.99374729,1.6447175,18.076679,420.83359,-10.355067
179.0864,0.36096618,9.4415455,0.0,0,18.0,400.0,0.99299258,1.7019536,18.078085,420.84079,-10.37253
179.0888,0.32730725,9.4487629,0.0,0,18.0,400.0,0.99302506,1.566776,18.080196,420.84381,-10.390478
179.0912,0.31914878,9.4536524,0.0,0,18.0,400.0,0.993738,1.5064416,18.079708,420.84381,-10.408299
179.0936,0.33715203,9.452075,0.0,0,18.0,400.0,0.9945063,1.5918467,18.07807,420.84381,-10.425879
179.096,0.36165932,9.4467754,0.0,0,18.0,400.0,0.99479842,1.6969246,18.079502,420.84381,-10.442745
179.0984,0.35765401,9.4434519,0.0,0,18.0,400.0,0.99396169,1.6821404,18.080051,420.83459,-10.461269
179.1008,0.32155809,9.4450588,0.0,0,18.0,400.0,0.99328434,1.542622,18.07641,420.81293,-10.480323
179.1032,0.33632389,9.4490185,0.0,0,18.0,400.0,0.99301159,1.5772722,18.07679,420.79126,-10.498854
179.1056,0.36011454,9.4477692,0.0,0,18.0,400.0,0.99315453,1.7047989,18.076921,420.76959,-10.515167
179.108,0.36571726,9.4445009,0.0,0,18.0,400.0,0.99371159,1.7298144,18.075186,420.75177,-10.533173
179.1104,0.35470176,9.4437551,0.0,0,18.0,400.0,0.99414337,1.6700164,18.073711,420.74454,-10.551332
179.1128,0.32219893,9.4441624,0.0,0,18.0,400.0,0.99376154,1.5484574,18.074158,420.7373,-10.570285
179.1152,0.36523014,9.4472218,0.0,0,18.0,400.0,0.99305362,1.6895267,18.072803,420.73007,-10.587577
179.1176,0.36822519,9.4531984,0.0,0,18.0,400.0,0.99349833,1.7444392,18.072693,420.72049,-10.604638
179.12,0.36670601,9.454627,0.0,0,18.0,400.0,0.994582,1.7511919,18.073399,420.69162,-10.622852
179.1224,0.35188851,9.4497128,0.0,0,18.0,400.0,0.99512237,1.6656582,18.073444,420.66272,-10.641034
179.1248,0.36141282,9.4452429,0.0,0,18.0,400.0,0.99461174,1.6653959,18.07045,420.63382,-10.658106
179.1272,0.37551364,9.4437284,0.0,0,18.0,400.0,0.9932723,1.7627894,18.070318,420.60492,-10.676811
179.1296,0.38756481,9.4451017,0.0,0,18.0,400.0,0.9924078,1.8508996,18.070133,420.58289,-10.693247
179.132,0.37338829,9.4492531,0.0,0,18.0,400.0,0.99327338,1.7820302,18.067884,420.56122,-10.709359
179.1344,0.36011341,9.4498034,0.0,0,18.0,400.0,0.99438876,1.685491,18.070513,420.53955,-10.727912
179.1368,0.37396801,9.4441748,0.0,0,18.0,400.0,0.99436283,1.7793351,18.068213,420.51788,-10.745874
179.1392,0.38350755,9.4435968,0.0,0,18.0,400.0,0.99401665,1.7996597,18.066254,420.50803,-10.764036
179.1416,0.38655707,9.4464798,0.0,0,18.0,400.0,0.99328774,1.8330702,18.065493,420.50131,-10.782225
179.144,0.36421865,9.4510765,0.0,0,18.0,400.0,0.99319714,1.7474104,18.062862,420.49457,-10.800633
179.1464,0.37319106,9.4524412,0.0,0,18.0,400.0,0.99396682,1.737707,18.062277,420.48782,-10.818534
179.1488,0.37880251,9.4499531,0.0,0,18.0,400.0,0.9946931,1.7878001,18.061544,420.47369,-10.835887
179.1512,0.40739387,9.4443007,0.0,0,18.0,400.0,0.99440557,1.8913969,18.062572,420.44479,-10.853456
179.1536,0.37287956,9.4439688,0.0,0,18.0,400.0,0.99361217,1.7801932,18.063084,420.41589,-10.87017
179.156,0.37321895,9.4486475,0.0,0,18.0,400.0,0.99335665,1.72732,18.06085,420.38699,-10.888123
179.1584,0.37762529,9.4494543,0.0,0,18.0,400.0,0.99333066,1.776186,18.062683,420.35938,-10.905015
179.1608,0.39813676,9.4490023,0.0,0,18.0,400.0,0.99380255,1.8617363,18.060659,420.33768,-10.923289
179.1632,0.40593004,9.445919,0.0,0,18.0,400.0,0.99420166,1.9480255,18.057899,420.31601,-10.94211
179.1656,0.37714359,9.4440365,0.0,0,18.0,400.0,0.99415123,1.7993727,18.058214,420.29434,-10.960329
179.168,0.37501934,9.4464235,0.0,0,18.0,400.0,0.99383765,1.7568225,18.058706,420.27252,-10.977726
179.1704,0.39710438,9.4499626,0.0,0,18.0,400.0,0.99321526,1.8634149,18.059086,420.24362,-10.99627
179.1728,0.40459666,9.451932,0.0,0,18.0,400.0,0.99336749,1.9260613,18.057976,420.21472,-11.0144
179.1752,0.38973814,9.449542,0.0,0,18.0,400.0,0.99431986,1.8532076,18.05731,420.18582,-11.03091
179.1776,0.37539193,9.4449997,0.0,0,18.0,400.0,0.99454564,1.7627413,18.057833,420.15692,-11.050956
179.18,0.39034063,9.4420443,0.0,0,18.0,400.0,0.99370682,1.8159456,18.055244,420.12802,-11.068378
179.1824,0.41097662,9.4414577,0.0,0,18.0,400.0,0.99246007,1.906626,18.058386,420.09915,-11.084494
179.1848,0.41815645,9.4485426,0.0,0,18.0,400.0,0.99287283,1.9962519,18.0557,420.07025,-11.102328
179.1872,0.38433072,9.4530668,0.0,0,18.0,400.0,0.99414265,1.8294013,18.056271,420.04135,-11.120495
179.1896,0.39927164,9.4476442,0.0,0,18.0,400.0,0.99431682,1.8663931,18.056831,420.01245,-11.137871
179.192,0.40356129,9.442481,0.0,0,18.0,400.0,0.99405026,1.9183667,18.054844,419.98355,-11.153678
179.1944,0.42400551,9.4442368,0.0,0,18.0,400.0,0.99384707,2.0020456,18.05481,419.95468,-11.171394
179.1968,0.41520223,9.4495287,0.0,0,18.0,400.0,0.99351573,1.9770687,18.055206,419.92578,-11.189959
179.1992,0.39612454,9.4547091,0.0,0,18.0,400.0,0.99370474,1.8822813,18.054644,419.89297,-11.209008
179.2016,0.40550095,9.4532108,0.0,0,18.0,400.0,0.99433863,1.8982785,18.054207,419.85684,-11.226317
179.204,0.42282835,9.4478559,0.0,0,18.0,400.0,0.99481195,1.9287361,18.05216,419.82074,-11.242857
179.2064,0.43315834,9.4433041,0.0,0,18.0,400.0,0.9942345,2.0678871,18.051142,419.78461,-11.262235
179.2088,0.40278855,9.4438581,0.0,0,18.0,400.0,0.99319988,1.9018799,18.049175,419.75677,-11.28167
179.2112,0.41602325,9.4479847,0.0,0,18.0,400.0,0.99302524,1.9105371,18.045858,419.74234,-11.297709
179.2136,0.41378832,9.4485579,0.0,0,18.0,400.0,0.99322176,1.9610333,18.047764,419.72787,-11.315351
179.216,0.44632006,9.446393,0.0,0,18.0,400.0,0.99380428,2.0730107,18.04891,419.71341,-11.332697
179.2184,0.43662462,9.4434128,0.0,0,18.0,400.0,0.99408758,2.0598614,18.047295,419.69083,-11.34996
179.3205,0.41890052,9.4475727,0.0,0,18.0,17.344156,0.99371862,1.9747185,18.038202,415.53882,-11.468603
180.5205,0.44716406,9.456871,0.0,0,18.0,7.5886285e-16,0.995588,2.0993736,18.000967,390.28662,-11.480411
181.7205,0.47546691,9.4632902,0.0,0,18.0,3.280552e-32,0.99664456,2.2343335,17.999954,376.81134,-11.480684
182.9205,0.49524108,9.4696035,0.0,0,18.0,1.4012985e-45,0.99783343,2.3239441,18.000195,365.06644,-11.482209
184.1205,0.48145387,9.474762,0.0,0,18.0,1.4012985e-45,0.99867761,2.256721,17.999285,354.63254,-11.481262
185.3205,0.48560649,9.4798126,0.0,0,18.0,1.4012985e-45,0.99956262,2.2738521,17.999638,345.01855,-11.480676
186.5205,0.50408047,9.4838448,0.0,0,18.0,1.4012985e-45,1.0004562,2.3579371,18.000126,335.86816,-11.480756
187.7205,0.52087784,9.4886789,0.0,0,18.0,1.4012985e-45,1.0012193,2.4397204,18.000164,327.06201,-11.481166
188.9205,0.52299243,9.4929876,0.0,0,18.0,1.4012985e-45,1.0020843,2.4426401,17.999828,318.47379,-11.481078
190.1205,0.52587807,9.4972849,0.0,0,18.0,1.4012985e-45,1.0027258,2.4557002,17.999838,310.2308,-11.481556
191.3205,0.5338583,9.5011492,0.0,0,18.0,1.4012985e-45,1.0034553,2.4948111,17.999662,302.1369,-11.481644
192.5205,0.52944058,9.5050888,0.0,0,18.0,1.4012985e-45,1.0043598,2.4732525,17.999983,294.26208,-11.481143
193.7205,0.54038125,9.5097284,0.0,0,18.0,1.4012985e-45,1.0050472,2.5218511,18.000376,286.6644,-11.481315
194.9205,0.54999232,9.5133839,0.0,0,18.0,1.4012985e-45,1.0058229,2.5657654,17.999693,279.25684,-11.481363
196.1205,0.56688863,9.5181103,0.0,0,18.0,1.4012985e-45,1.0065064,2.6396842,17.999783,272.37341,-11.48161
197.3205,0.56855446,9.5212622,0.0,0,18.0,1.4012985e-45,1.0071622,2.6469939,17.999945,265.4295,-11.481601
198.5205,0.57583213,9.5249109,0.0,0,18.0,1.4012985e-45,1.0079594,2.6803136,17.999451,258.82822,-11.481775
199.7205,0.57950807,9.5291758,0.0,0,18.0,1.4012985e-45,1.0085723,2.698894,18.000093,252.48155,-11.482035
200.9205,0.58682251,9.5328484,0.0,0,18.0,1.4012985e-45,1.0093375,2.7240622,17.999538,246.35161,-11.482124
202.1205,0.59812868,9.5367298,0.0,0,18.0,1.4012985e-45,1.0098798,2.7765217,17.999842,240.27817,-11.482409
203.3205,0.60038584,9.5393476,0.0,0,18.0,1.4012985e-45,1.0105432,2.7868817,17.999826,234.46587,-11.482265
204.5205,0.60524428,9.5432634,0.0,0,18.0,1.4012985e-45,1.0112472,2.8025429,17.999113,228.82794,-11.48269
205.7205,0.6118266,9.5466824,0.0,0,18.0,1.4012985e-45,1.0118476,2.829864,17.999498,223.42107,-11.482361
206.9205,0.60174763,9.5497913,0.0,0,18.0,1.4012985e-45,1.0123521,2.7784739,17.999752,217.99446,-11.481808
208.1205,0.60687619,9.553484,0.0,0,18.0,1.4012985e-45,1.0130042,2.8035736,17.999725,212.86914,-11.482143
209.3205,0.61699259,9.5562811,0.0,0,18.0,1.4012985e-45,1.0137194,2.8435049,18.000406,207.6217,-11.481798
210.5205,0.61975425,9.5596972,0.0,0,18.0,1.4012985e-45,1.0141717,2.8628495,18.000008,202.64981,-11.481803
211.7205,0.62704557,9.5624113,0.0,0,18.0,1.4012985e-45,1.0147949,2.887114,18.000048,197.96559,-11.481688
212.9205,0.62097126,9.5654507,0.0,0,18.0,1.4012985e-45,1.0151492,2.8560543,18.000395,193.39915,-11.48197
214.1205,0.63774747,9.5681887,0.0,0,18.0,1.4012985e-45,1.0158442,2.9353158,17.999563,188.88,-11.482
215.3205,0.64673066,9.5710764,0.0,0,18.0,1.4012985e-45,1.0163548,2.9764175,17.999189,184.49237,-11.482446
216.5205,0.64599901,9.5738821,0.0,0,18.0,1.4012985e-45,1.0168465,2.9709334,18.000069,180.28723,-11.482507
217.7205,0.65157932,9.5767088,0.0,0,18.0,1.4012985e-45,1.0172958,3.0015831,17.999641,176.06474,-11.482124
218.9205,0.65070242,9.5796413,0.0,0,18.0,1.4012985e-45,1.0178515,2.9928997,17.999203,172.13034,-11.482234
220.1205,0.65770918,9.5818939,0.0,0,18.0,1.4012985e-45,1.0184398,3.0287297,17.9998,168.06816,-11.482402
221.3205,0.64642549,9.5846949,0.0,0,18.0,1.4012985e-45,1.0187659,2.9776154,18.000044,164.2213,-11.48198
222.5205,0.64931595,9.5869837,0.0,0,18.0,1.4012985e-45,1.0192832,2.9847851,17.999727,160.45895,-11.48202
223.7205,0.65687352,9.5897188,0.0,0,18.0,1.4012985e-45,1.0196257,3.0206721,17.99934,156.80101,-11.482123
224.9205,0.66332161,9.5917511,0.0,0,18.0,1.4012985e-45,1.0202185,3.0494077,17.99963,153.22351,-11.481886
226.1205,0.66197824,9.5945749,0.0,0,18.0,1.4012985e-45,1.0205863,3.043395,17.999098,149.92957,-11.481369
227.3205,0.67436022,9.5970001,0.0,0,18.0,1.4012985e-45,1.0211657,3.1009622,18.000546,146.47797,-11.481917
228.5205,0.67694378,9.5993433,0.0,0,18.0,1.4012985e-45,1.0214385,3.1125519,17.999916,143.1815,-11.481586
229.7205,0.67499739,9.6012907,0.0,0,18.0,1.4012985e-45,1.02188,3.0954499,17.998941,140.03418,-11.481786
230.9205,0.67893887,9.6030846,0.0,0,18.0,1.4012985e-45,1.0223091,3.1097746,17.99943,136.91197,-11.481728
232.1205,0.68820715,9.6047068,0.0,0,18.0,1.4012985e-45,1.0225264,3.150053,18.000185,133.9706,-11.481874
233.3205,0.69495195,9.6073523,0.0,0,18.0,1.4012985e-45,1.0229845,3.1798072,17.998957,131.15424,-11.482173
234.5205,0.69920248,9.6094866,0.0,0,18.0,1.4012985e-45,1.0233363,3.1978645,17.999897,128.28587,-11.482159
235.7205,0.69338691,9.6116171,0.0,0,18.0,1.4012985e-45,1.0239536,3.1661811,18.000177,125.52945,-11.482006
236.9205,0.69750351,9.6135273,0.0,0,18.0,1.4012985e-45,1.0241299,3.1861572,18.00086,122.86275,-11.481919
238.1205,0.70055133,9.61516,0.0,0,18.0,1.4012985e-45,1.0245074,3.1987588,17.999748,120.23921,-11.482033
239.2205,0.70353216,9.6171713,0.0,0,18.0,1.4012985e-45,1.0248984,3.2090535,18.000179,117.90224,-11.482298