File: examples/hot axisymmetric compression example/data/02 screened data/testID_0133.csv
Time(sec),Force(kN),Jaw(mm),PowAngle(deg),Power(W),Pram,PTemp,Strain,Stress(MPa),Stroke(mm),TC1(C),wedge(mm)
0.0,0.95331275,0.36234385,0.0,0,11.076097,0.00064125459,0.02445866,11.864185,11.076462,22.893122,-9.1246071
1.1,0.88084716,0.0016399443,0.0,0,11.076097,3.2158816,0.0001223539,11.20831,11.075981,22.850109,-9.4947243
2.2,0.83268327,0.0015127588,0.0,0,11.076097,6.515883,0.00011270835,10.599185,11.076242,22.84667,-9.4920473
3.3,0.7953403,0.0013298707,0.0,0,11.076097,9.8158827,7.8015517e-05,10.127608,11.077394,22.837406,-9.4908829
4.4,0.76860809,0.0011073477,0.0,0,11.076097,13.115883,8.1361504e-05,9.7962322,11.076808,22.799198,-9.4890318
5.5,0.74908006,0.0012430233,0.0,0,11.076097,16.415886,7.2895426e-05,9.5481682,11.076301,22.863554,-9.4870205
6.6,0.73149878,0.00059276889,0.0,0,11.076097,19.715881,6.2422747e-05,9.3083534,11.076023,22.878712,-9.4848585
7.7,0.71277034,0.00065090053,0.0,0,11.076097,23.015886,5.8388312e-05,9.0762796,11.075683,22.81163,-9.4825163
8.8,0.70975173,0.0011333092,23.702824,0,11.076097,26.315886,6.7981782e-05,9.0345459,11.076238,22.850664,-9.4806738
9.9,0.70941049,0.00033963236,34.131985,0,11.076097,29.615885,2.5630887e-05,9.0370121,11.07708,23.701679,-9.47894
11.0,0.72436142,-0.0021408305,39.69569,0,11.076097,32.915894,-0.00016571097,9.2265444,11.076027,25.657604,-9.4771185
12.1,0.72750658,-0.0045110495,42.820313,0,11.076097,36.215893,-0.000277085,9.2662506,11.076168,28.577566,-9.4756584
13.2,0.72065866,-0.0070590661,45.10318,0,11.076097,39.515896,-0.00046921943,9.1757612,11.076114,31.881691,-9.4734716
14.3,0.73229426,-0.010561446,46.362495,0,11.076097,42.815891,-0.00069436181,9.3318396,11.076052,35.508385,-9.4718113
15.4,0.72912401,-0.013277904,47.560799,0,11.076097,46.115891,-0.00088241172,9.2725983,11.075456,39.130127,-9.4696188
16.5,0.73741049,-0.016754931,48.19685,0,11.076097,49.415886,-0.0011332892,9.3969307,11.076504,43.202904,-9.4676046
17.6,0.73735672,-0.020948231,48.762196,0,11.076097,52.715889,-0.0013885485,9.4111919,11.07503,47.182343,-9.4656868
18.7,0.73870325,-0.022848064,49.120964,0,11.076097,56.015884,-0.0015425022,9.420826,11.077265,51.189899,-9.4640884
19.8,0.74307811,-0.025899887,49.229733,0,11.076097,59.315884,-0.0017127309,9.4836025,11.076881,55.123531,-9.461977
20.9,0.7327829,-0.029030722,49.330135,0,11.076097,62.615879,-0.001924879,9.3339252,11.076919,59.010117,-9.4601345
22.0,0.73869711,-0.032306168,49.37233,0,11.076097,65.915894,-0.0021510564,9.416316,11.076733,62.927502,-9.4584675
23.1,0.74036425,-0.035462659,49.522785,0,11.076097,69.215889,-0.0023610576,9.4573708,11.075711,66.678307,-9.4567709
24.2,0.73432887,-0.038557086,49.634659,0,11.076097,72.515892,-0.0025922637,9.3808298,11.076733,70.335258,-9.4550238
25.3,0.73846203,-0.04189809,49.635429,0,11.076097,75.81588,-0.0027676017,9.4269428,11.07598,74.027405,-9.4527035
26.4,0.74736249,-0.044368323,49.520657,0,11.076097,79.115891,-0.0029639553,9.5401287,11.075485,77.623596,-9.4507704
27.5,0.73871922,-0.046437733,49.636227,0,11.076097,82.415886,-0.0030833611,9.4366503,11.075719,81.128029,-9.4488058
28.6,0.74857688,-0.048874628,49.695782,0,11.076097,85.715881,-0.0032387287,9.5600948,11.076127,84.491158,-9.4469442
29.7,0.74564958,-0.05160521,50.042679,0,11.076097,89.015892,-0.0034423065,9.5210619,11.07683,87.738525,-9.4448357
30.8,0.74523699,-0.054014694,50.192585,0,11.076097,92.31588,-0.0035938825,9.5342407,11.075973,91.139,-9.4427919
31.9,0.73571455,-0.05679005,50.486435,0,11.076097,95.615883,-0.0037927497,9.4105577,11.076407,94.408661,-9.4410257
33.0,0.74492198,-0.059395224,50.82275,0,11.076097,98.915878,-0.0039299214,9.520484,11.075956,97.675323,-9.4390821
34.1,0.75295031,-0.06320709,51.181198,0,11.076097,102.21589,-0.0041959751,9.6165113,11.076844,100.9519,-9.4374247
35.2,0.74668318,-0.064963147,51.196285,0,11.076097,105.51589,-0.0043267962,9.5448055,11.075359,104.29263,-9.4350281
36.3,0.7382645,-0.067389265,51.229481,0,11.076097,108.8159,-0.004483934,9.4491301,11.076149,107.70289,-9.4337797
37.4,0.74045265,-0.069641128,51.892212,0,11.076097,112.11591,-0.0046369173,9.4868917,11.077373,110.75758,-9.4315672
38.5,0.7511664,-0.072515979,51.950474,0,11.076097,115.41591,-0.0048057316,9.6161213,11.07614,114.13943,-9.4298944
39.6,0.74870837,-0.075190932,52.168587,0,11.076097,118.71591,-0.0049990295,9.5789413,11.075747,117.50347,-9.4274845
40.7,0.74634063,-0.077744901,52.530125,0,11.076097,122.0159,-0.0051569268,9.5463543,11.074716,120.72996,-9.426033
41.8,0.74969548,-0.081024088,52.760448,0,11.076097,125.3159,-0.0053761485,9.6043816,11.075378,123.93114,-9.4240332
42.9,0.75044048,-0.084456511,52.97607,0,11.076097,128.61601,-0.0056349728,9.5997801,11.076742,127.19955,-9.4220486
44.0,0.75613588,-0.085921876,53.316017,0,11.076097,131.91588,-0.0057119168,9.6848021,11.075315,130.53748,-9.4203053
45.1,0.74753261,-0.088364594,53.650223,0,11.076097,135.21588,-0.0058901114,9.5943108,11.076018,133.80928,-9.4180765
46.2,0.76262522,-0.091489941,53.746513,0,11.076097,138.51587,-0.0060590459,9.7713356,11.075389,137.11282,-9.4162741
47.3,0.75891173,-0.094795994,53.988323,0,11.076097,141.81589,-0.0062847398,9.7282562,11.076119,140.34885,-9.4146519
48.4,0.75045711,-0.097248368,54.223083,0,11.076097,145.11588,-0.0064655496,9.6013966,11.075475,143.71648,-9.4124756
49.5,0.75135988,-0.10047374,54.551647,0,11.076097,148.41588,-0.0066708373,9.6360283,11.076245,147.01012,-9.4108353
50.6,0.75378191,-0.10323447,54.924858,0,11.076097,151.71588,-0.0068841581,9.657836,11.075894,150.22009,-9.4092684
51.7,0.76514757,-0.10660075,54.931644,0,11.076097,155.01588,-0.0070548113,9.8147221,11.076208,153.57861,-9.4074755
52.8,0.76604265,-0.110667,55.23925,0,11.076097,158.31589,-0.0073499796,9.8198833,11.075193,156.89789,-9.4058094
53.9,0.75688934,-0.11312222,55.535469,0,11.076097,161.61591,-0.0075186845,9.7132483,11.076059,160.07515,-9.4038916
55.0,0.75692374,-0.11526383,55.689491,0,11.076097,164.91589,-0.0076558725,9.7200394,11.076541,163.41203,-9.402215
56.1,0.75693816,-0.11810841,56.08168,0,11.076097,168.21591,-0.0078605227,9.7153969,11.07589,166.65488,-9.4001627
57.2,0.75827271,-0.12161566,56.177193,0,11.076097,171.5159,-0.0080626663,9.7309818,11.076519,170.02158,-9.3984032
58.3,0.75092191,-0.12521589,56.425667,0,11.076097,174.8159,-0.0083312141,9.6451178,11.076391,173.31351,-9.3964577
59.4,0.7586419,-0.12865885,56.711395,0,11.076097,178.11591,-0.0085205743,9.7511711,11.075917,176.57945,-9.3945198
60.5,0.75475138,-0.13119033,56.981316,0,11.076097,181.41589,-0.0086915828,9.7053366,11.075481,179.81097,-9.3925924
61.6,0.74793702,-0.13474569,57.232391,0,11.076097,184.71591,-0.0089516286,9.6102238,11.07656,183.14549,-9.3903399
62.7,0.75841635,-0.13762867,57.3526,0,11.076097,188.0159,-0.0091316327,9.7458477,11.074906,186.43774,-9.3887329
63.8,0.76265252,-0.14056528,57.622025,0,11.076097,191.3159,-0.0093424898,9.8099184,11.075768,189.68466,-9.3865719
64.9,0.76586789,-0.14530274,57.810051,0,11.076097,194.61591,-0.0096122297,9.8545179,11.076581,193.04225,-9.3850784
66.0,0.77266252,-0.14872485,57.904984,0,11.076097,197.91589,-0.0098653054,9.9287586,11.07576,196.4325,-9.383029
67.1,0.76686257,-0.15106787,58.073727,0,11.076097,201.2159,-0.010023776,9.8753233,11.076958,199.86301,-9.3811846
68.2,0.7618624,-0.15305832,58.337399,0,11.076097,204.51588,-0.010153451,9.8130741,11.076613,203.11868,-9.3795614
69.3,0.77003992,-0.15587538,58.544003,0,11.076097,207.81589,-0.010362851,9.9113798,11.076508,206.40047,-9.3779964
70.4,0.76474357,-0.15925404,58.591755,0,11.076097,211.11589,-0.010544876,9.8418636,11.075638,209.76154,-9.3759527
71.5,0.76673317,-0.16294479,58.814419,0,11.076097,214.41588,-0.010807258,9.8757601,11.077038,213.03506,-9.3747253
72.6,0.76371425,-0.16615881,58.853767,0,11.076097,217.71588,-0.011003419,9.8462811,11.075146,216.45546,-9.3725357
73.7,0.76759881,-0.16938767,59.102406,0,11.076097,221.01588,-0.01122427,9.8953142,11.076241,219.78105,-9.3711414
74.8,0.7649892,-0.17272191,59.106438,0,11.076097,224.31589,-0.011465583,9.853652,11.07569,223.25169,-9.369257
75.9,0.76584464,-0.1757924,59.109077,0,11.076097,227.61591,-0.011647805,9.8621473,11.076633,226.67099,-9.3677425
77.0,0.77010423,-0.17870814,59.348137,0,11.076097,230.91589,-0.011860095,9.9135447,11.07627,229.89352,-9.365798
78.1,0.77285123,-0.18182324,59.426586,0,11.076097,234.21591,-0.012026151,9.9595947,11.076553,233.22684,-9.3640356
79.2,0.76810384,-0.18558492,59.596207,0,11.076097,237.5159,-0.012281555,9.8895226,11.07655,236.51782,-9.3621788
80.3,0.76538575,-0.18916136,59.785645,0,11.076097,240.8159,-0.012546879,9.8742599,11.077353,239.73476,-9.3603706
81.4,0.76808602,-0.19186634,59.842525,0,11.076097,244.11591,-0.012710906,9.90662,11.076402,243.00249,-9.3581181
82.5,0.77082437,-0.19406657,60.084225,0,11.076097,247.41591,-0.012872843,9.954155,11.075871,246.26088,-9.3563852
83.6,0.77195388,-0.19671635,60.314888,0,11.076097,250.7159,-0.013009612,9.9679565,11.076381,249.54201,-9.354393
84.7,0.77644086,-0.1993369,60.314934,0,11.076097,254.0159,-0.013192493,10.014323,11.076649,252.95786,-9.3528042
85.8,0.76783919,-0.20264077,60.521267,0,11.076097,257.31616,-0.013425257,9.918581,11.075641,256.18765,-9.3508568
86.9,0.76988029,-0.20578638,60.53043,0,11.076097,260.61615,-0.013627022,9.9451046,11.076464,259.54395,-9.3489971
88.0,0.76928133,-0.20926586,60.787327,0,11.076097,263.91589,-0.013873721,9.9208689,11.075747,262.76093,-9.346859
89.1,0.77321923,-0.21285081,61.012211,0,11.076097,267.21588,-0.0140653,9.9852324,11.07693,265.95181,-9.3452473
90.2,0.7623536,-0.21559921,61.019936,0,11.076097,270.5159,-0.014262093,9.8529739,11.075312,269.2894,-9.3432026
91.3,0.76014191,-0.21892098,61.356998,0,11.076097,273.81589,-0.014493584,9.8279572,11.07696,272.41357,-9.3410664
92.4,0.76834863,-0.2225035,61.468513,0,11.076097,277.11588,-0.014720279,9.9358263,11.075598,275.67154,-9.3394556
93.5,0.76511937,-0.22564045,61.694641,0,11.076097,280.41589,-0.014951571,9.8891993,11.075779,278.87778,-9.337739
94.6,0.76165879,-0.22929043,61.992935,0,11.076097,283.71588,-0.015152852,9.8457289,11.075255,282.11456,-9.3357344
95.7,0.77004147,-0.23257449,62.116692,0,11.076097,287.0159,-0.015385595,9.9559422,11.076097,285.53027,-9.3341331
96.8,0.77521497,-0.23643698,62.26725,0,11.076097,290.31589,-0.015635915,10.029272,11.077368,288.85269,-9.3319206
97.9,0.76336324,-0.23954895,62.464764,0,11.076097,293.61594,-0.015836138,9.8693304,11.075527,292.04773,-9.330267
99.0,0.76803458,-0.24311309,62.660854,0,11.076097,296.91589,-0.016093183,9.9410353,11.076994,295.35468,-9.3286009
100.1,0.76844645,-0.246158,62.694328,0,11.076097,299.99545,-0.016261201,9.9626513,11.076592,298.7128,-9.3264866
101.2,0.77179581,-0.24887525,60.682919,0,11.076097,299.99905,-0.016459616,10.002992,11.076294,301.8038,-9.3266087
102.3,0.76878935,-0.25050771,58.778362,0,11.076097,299.99905,-0.016543655,9.9473429,11.075299,304.02554,-9.3266106
103.4,0.77516341,-0.25142339,57.263409,0,11.076097,299.99905,-0.01661092,10.039185,11.076485,305.30505,-9.3267632
104.5,0.77001458,-0.25322333,55.85751,0,11.076097,299.99905,-0.016741542,9.9794645,11.076473,305.992,-9.3264685
105.6,0.77398938,-0.25335914,54.625278,0,11.076097,299.99905,-0.016754413,10.017552,11.075498,306.19385,-9.3268585
106.7,0.76296991,-0.25208065,53.657753,0,11.076097,299.99905,-0.016685728,9.8796587,11.076948,306.20749,-9.326438
107.8,0.74912983,-0.25209436,52.842743,0,11.076097,299.99905,-0.016647082,9.7002449,11.076531,305.83868,-9.3263617
108.9,0.74242836,-0.25193992,52.313976,0,11.076097,299.99905,-0.0166343,9.6151991,11.076495,305.35504,-9.3263197
110.0,0.73541552,-0.25183472,51.932377,0,11.076097,299.99905,-0.016654175,9.5272369,11.075992,304.83606,-9.3258572
111.1,0.73353159,-0.25183827,51.672241,0,11.076097,299.99905,-0.016649887,9.5047426,11.076084,304.29724,-9.3256044
112.2,0.73056692,-0.25148591,51.568905,0,11.076097,299.99905,-0.016644221,9.469121,11.07542,303.70477,-9.325798
113.3,0.73270679,-0.25163886,51.555641,0,11.076097,299.99905,-0.016624676,9.4800081,11.076955,303.11002,-9.3263063
114.4,0.73088616,-0.25154686,51.553791,0,11.076097,299.99905,-0.016624557,9.4582682,11.076487,302.59595,-9.3262777
115.5,0.72782087,-0.25167862,51.56982,0,11.076097,299.99905,-0.016638579,9.3984671,11.076236,302.08392,-9.3262777
116.6,0.73727798,-0.25186285,51.569828,0,11.076097,299.99905,-0.016637862,9.5459013,11.07665,301.62262,-9.3262339
117.7,0.72694898,-0.25230074,51.859318,0,11.076097,299.99905,-0.016683714,9.425168,11.07711,301.2771,-9.3257236
118.8,0.73303854,-0.25301063,51.932369,0,11.076097,299.99905,-0.016715962,9.4951649,11.076703,300.90628,-9.3258047
119.9,0.7361784,-0.25246477,52.120094,0,11.076097,299.99905,-0.016711049,9.5358839,11.07715,300.56134,-9.3253908
121.0,0.72008634,-0.25213706,52.14341,0,11.076097,299.99905,-0.016655071,9.3297071,11.076185,300.42435,-9.3250322
122.1,0.72851491,-0.2517769,52.283936,0,11.076097,299.99905,-0.016634433,9.4227858,11.076645,300.1825,-9.3252144
123.2,0.74567664,-0.25156951,52.440193,0,11.076097,299.99905,-0.016643167,9.6606417,11.076119,300.08652,-9.3257637
124.3,0.75894237,-0.25199854,52.455177,0,11.076097,299.99905,-0.016656777,9.8259029,11.077243,300.02695,-9.3254051
125.4,0.75737077,-0.2525211,52.597778,0,11.076097,299.99905,-0.016713986,9.8107586,11.075995,299.97192,-9.3256598
126.5,0.75834596,-0.2531808,52.635483,0,11.076097,299.99905,-0.016718345,9.8316212,11.076294,299.90332,-9.3253536
127.6,0.7713998,-0.253306,52.632446,0,11.076097,299.99905,-0.016741723,9.9927063,11.075885,299.94659,-9.3256321
128.7,0.76152253,-0.25412387,52.635273,0,11.076097,299.99905,-0.016796319,9.8605223,11.075576,299.95041,-9.3252897
129.8,0.75484461,-0.25444564,52.555233,0,11.076097,299.99905,-0.016816778,9.7783155,11.07513,300.02176,-9.325325
130.9,0.75677931,-0.25465521,52.519566,0,11.076097,299.99905,-0.01684778,9.8165941,11.075977,300.00186,-9.3249979
132.0,0.77011251,-0.25505489,52.390781,0,11.076097,299.99905,-0.016849441,9.9844761,11.076251,300.0686,-9.3249559
133.1,0.76273286,-0.25546053,52.283939,0,11.076097,299.99905,-0.016905962,9.8809986,11.077375,300.13522,-9.3249092
134.2,0.7570641,-0.25593734,52.414371,0,11.076097,299.99905,-0.016899006,9.7966223,11.075385,300.08606,-9.3247938
135.3,0.76021194,-0.25674707,52.418301,0,11.076097,299.99905,-0.016959202,9.8509312,11.076292,300.04266,-9.3244143
136.4,0.77820921,-0.25801632,52.283939,0,11.076097,299.99905,-0.017056739,10.084516,11.078168,300.15125,-9.3249216
137.5,0.77386296,-0.25898734,52.283939,0,11.076097,299.99905,-0.017119911,10.027551,11.076342,300.06259,-9.3247442
138.6,0.77946228,-0.25868258,52.283939,0,11.076097,299.99905,-0.017122792,10.081269,11.076458,300.1236,-9.3249931
139.7,0.77427071,-0.25913331,52.0998,0,11.076097,299.99905,-0.017116012,10.028799,11.075802,300.20706,-9.324852
140.8,0.77038431,-0.25910231,52.278168,0,11.076097,299.99905,-0.017123781,9.9749756,11.076913,300.17627,-9.3248549
141.9,0.78300679,-0.25961459,51.965919,0,11.076097,299.99905,-0.017162776,10.141973,11.076815,300.28082,-9.3250027
143.0,0.77621031,-0.25992602,51.932377,0,11.076097,299.99905,-0.017179606,10.049372,11.07574,300.26843,-9.3246145
144.1,0.77879936,-0.26018819,51.932377,0,11.076097,299.99905,-0.017211011,10.085136,11.076198,300.2124,-9.3251247
145.1322,0.77386546,-0.00076906168,51.932369,0,11.076097,299.99905,-6.9605405e-05,9.847537,11.075901,300.2854,-9.324789
145.3045,0.76981014,0.0033322328,51.932373,0,11.076099,6.0865757e-10,0.00050970662,9.8689346,11.074439,300.23511,-9.3240423
145.3067,0.78339577,0.010088968,43.103775,0,11.076099,6.079146e-25,0.00029337933,9.9501867,11.077549,300.20288,-9.3253803
145.3089,0.78534305,0.003870907,31.678654,0,11.076099,6.0717282e-40,0.00047804817,9.9217987,11.07111,300.1691,-9.3250113
145.3111,0.78691882,0.0061068661,20.253529,0,11.076099,0.0,0.00022552037,10.082514,11.069655,300.13531,-9.3251762
145.3133,0.768875,0.0041373861,8.8284073,0,11.076099,0.0,0.00057545543,9.8451738,11.072542,300.10153,-9.3240433
145.3155,0.76827961,0.0093373181,0.0,0,11.076099,0.0,0.0003519418,9.7907047,11.074445,300.08157,-9.3252697
145.3177,0.76764983,0.0029320288,0.0,0,11.076099,0.0,0.00036244313,9.6863661,11.072422,300.10858,-9.3264742
145.3199,0.75192016,0.0057416297,0.0,0,11.076099,0.0,0.00027536222,9.6135616,11.075593,300.13562,-9.3265381
145.3221,0.75792515,0.00278357,0.0,0,11.076099,0.0,0.00036596722,9.6409473,11.073277,300.16263,-9.3244467
145.3243,0.76259565,0.0102312,0.0,0,11.076099,0.0,0.00048952305,9.7242117,11.076793,300.18964,-9.3246927
145.3265,0.76018119,0.0026070345,0.0,0,11.076099,0.0,0.00034533301,9.6576529,11.077165,300.22128,-9.3234863
145.3287,0.75337344,0.0073037203,0.0,0,11.076099,0.0,0.00039845958,9.6438208,11.079124,300.25507,-9.3241901
145.3309,0.75180364,0.0029855731,0.0,0,11.076099,0.0,0.00033175503,9.5204935,11.07814,300.28885,-9.3244638
145.3331,0.73690337,0.0092180409,0.0,0,11.076099,0.0,0.00042124244,9.3874044,11.072591,300.32263,-9.3242226
145.3353,0.74024546,0.002973164,0.0,0,11.076099,0.0,0.00023994836,9.4238024,11.072684,300.35181,-9.3245621
145.3375,0.74322021,0.0057906532,0.0,0,11.076099,0.0,0.00037990115,9.4472437,11.073749,300.35181,-9.3244619
145.3397,0.74033016,0.0047961748,0.0,0,11.076099,0.0,0.00031078473,9.4169474,11.078209,300.35181,-9.3264465
145.3419,0.74722826,0.0092897164,0.0,0,11.076099,0.0,0.00056831818,9.5627737,11.0755,300.35181,-9.3249655
145.3441,0.75712907,0.0053213192,0.0,0,11.076099,0.0,0.00034420501,9.6591024,11.07484,300.35181,-9.323947
145.3463,0.75450122,0.005231238,0.0,0,11.076099,0.0,0.00038028558,9.7347403,11.076835,300.34381,-9.3232346
145.3485,0.76429558,0.0024370241,0.0,0,11.076099,0.0,0.00011041631,9.6543989,11.073637,300.33029,-9.3236666
145.3507,0.74945623,0.008225969,0.0,0,11.076099,0.0,0.00063887594,9.6270247,11.072478,300.3168,-9.3256969
145.3529,0.74779463,0.0054862057,0.0,0,11.063763,0.0,0.00030990175,9.5522184,11.075753,300.30328,-9.3264132
145.3551,0.74964184,0.0055928589,0.0,0,10.735819,0.0,0.0004613832,9.5209074,11.079201,300.29037,-9.3262329
145.3573,0.75643235,0.0031868902,0.0,0,10.404927,0.0,0.00011417121,9.6346989,11.075175,300.29037,-9.3247566
145.3595,0.77075791,0.0060768542,0.0,0,10.074035,0.0,0.00055603468,9.79984,11.01496,300.29037,-9.3248415
145.3617,0.77445179,0.007054104,0.0,0,9.7431412,0.0,0.00026814028,9.7355604,10.825174,300.29037,-9.3249197
145.3639,0.78390461,0.0043600239,0.0,0,9.4141388,0.0,0.00039461104,9.8823299,10.522347,300.29037,-9.3254995
145.3661,0.761011,0.0054662833,0.0,0,9.0922346,0.0,0.0001432955,9.5786896,10.121032,300.60739,-9.3255625
145.3683,7.6501145,0.33340281,0.0,0,8.7703304,0.0,0.021935046,94.859306,9.6963987,301.24136,-9.3197479
145.3705,9.8467646,0.69091201,0.0,0,8.4631929,0.0,0.046678092,119.30449,9.2593565,301.87537,-9.3184948
145.3727,10.751703,1.0816581,0.0,0,8.1570415,0.0,0.07492277,126.35678,8.8456907,302.50937,-9.3183184
145.3749,11.020861,1.4287258,0.0,0,7.8607755,0.0,0.09930484,127.18445,8.5160036,303.14337,-9.3167
145.3771,11.630391,1.7033873,0.0,0,7.5694952,0.0,0.12043664,131.11703,8.2095661,303.90585,-9.3148708
145.3793,11.894421,2.0020769,0.0,0,7.2838039,0.0,0.14246064,131.42714,7.9048223,304.67447,-9.3146276
145.3815,12.127222,2.2832994,0.0,0,7.0067792,0.0,0.16512182,130.86284,7.6275177,305.44305,-9.3152189
145.3837,12.483457,2.5395098,0.0,0,6.7313671,0.0,0.18475986,131.93797,7.3634763,306.21167,-9.3149948
145.3859,12.797793,2.7968121,0.0,0,6.467802,0.0,0.20642574,132.48228,7.0981159,306.65756,-9.3150129
145.3881,13.097267,3.0744374,0.0,0,6.2042422,0.0,0.22846657,132.65247,6.8257113,306.63739,-9.3164091
145.3903,13.490265,3.3308749,0.0,0,5.9515953,0.0,0.25107241,133.51057,6.5601735,306.61722,-9.3170128
145.3925,13.804158,3.5995421,0.0,0,5.7009277,0.0,0.27368799,133.69176,6.2894483,306.59702,-9.3166294
145.3947,14.115295,3.8597322,0.0,0,5.4572535,0.0,0.29757696,133.40039,6.0257769,306.57684,-9.316968
145.3969,14.431906,4.1236806,0.0,0,5.2187734,0.0,0.32052228,133.32719,5.7702818,306.03864,-9.3173819
145.3991,14.764081,4.3717084,0.0,0,4.9838042,0.0,0.34451923,133.10602,5.5120559,305.41864,-9.3158941
145.4013,15.086877,4.6250324,0.0,0,4.7569842,0.0,0.36802667,132.96913,5.2581434,304.79865,-9.316123
145.4035,15.427872,4.864747,0.0,0,4.5305758,0.0,0.39198211,132.70688,5.0174022,304.17868,-9.3154917
145.4057,15.786965,5.1146836,0.0,0,4.314702,0.0,0.416105,132.57675,4.7777338,303.47681,-9.3163385
145.4079,16.158813,5.3359432,0.0,0,4.0989256,0.0,0.43952942,132.47124,4.5442996,302.59955,-9.3169289
145.4101,16.586191,5.5657182,0.0,0,3.8911293,0.0,0.46306211,132.8512,4.3191314,301.72229,-9.3171387
145.4123,16.975269,5.7807612,0.0,0,3.6859133,0.0,0.48658738,132.79387,4.0963206,300.845,-9.3155775
145.4145,17.401482,6.00596,0.0,0,3.4855206,0.0,0.51066327,132.90134,3.8809466,299.96774,-9.3151798
145.4167,17.837444,6.2098413,0.0,0,3.2902927,0.0,0.53425729,133.12704,3.6661081,297.83832,-9.3157406
145.4189,18.292593,6.4217539,0.0,0,3.0970623,0.0,0.55829692,133.15991,3.4638808,295.34064,-9.3153667
145.4211,18.760427,6.6181879,0.0,0,2.9113381,0.0,0.5816521,133.46631,3.2607436,292.84296,-9.3161335
145.4233,19.269354,6.8201289,0.0,0,2.7256143,0.0,0.60583192,133.82893,3.0636551,290.34528,-9.3153172
145.4255,19.813995,7.0030346,0.0,0,2.5483873,0.0,0.6285069,134.4734,2.8722403,288.43521,-9.313653
145.4277,20.390867,7.1950431,0.0,0,2.3717272,0.0,0.65287256,135.06529,2.6876991,288.52304,-9.3141537
145.4299,20.988441,7.3710761,0.0,0,2.2008004,0.0,0.67557162,135.91917,2.5062566,288.61084,-9.3140068
145.4321,21.572294,7.5502739,0.0,0,2.0327644,0.0,0.69971609,136.36081,2.3337109,288.69867,-9.3148031
145.4343,22.212618,7.7184558,0.0,0,1.8679364,0.0,0.72196388,137.34778,2.1568,288.78647,-9.3143892
145.4365,22.883383,7.8867249,0.0,0,1.7080843,0.0,0.74603653,138.09937,1.9873912,290.74747,-9.3114204
145.4387,23.596394,8.0531816,0.0,0,1.5491644,0.0,0.7688573,139.24475,1.8225425,293.58258,-9.3124294
145.4409,24.337498,8.2145481,0.0,0,1.3970973,0.0,0.79348159,140.05281,1.6663116,296.41769,-9.3119774
145.4431,25.123898,8.369482,0.0,0,1.2450334,0.0,0.81539083,141.46881,1.5089447,299.25281,-9.3119888
145.4453,25.954029,8.519577,0.0,0,1.0992644,0.0,0.83949107,142.6694,1.3571594,301.76025,-9.3121653
145.4475,26.874985,8.6653461,0.0,0,0.95463634,0.0,0.86086172,144.57037,1.2072734,302.1926,-9.3099794
145.4497,27.786165,8.8106041,0.0,0,0.81407332,0.0,0.88563532,145.8524,1.0590447,302.62491,-9.3100033
145.4519,28.712351,8.953269,0.0,0,0.67652941,0.0,0.90694743,147.50786,0.91484618,303.05725,-9.310338
145.4541,29.658873,9.0814009,0.0,0,0.54098594,0.0,0.9305082,148.84729,0.77913135,303.48959,-9.3103294
145.4563,30.658142,9.2154398,0.0,0,0.41008592,0.0,0.95138735,150.64746,0.6477474,303.80957,-9.3104668
145.4585,31.710527,9.3372126,0.0,0,0.27942541,0.0,0.97489464,152.19604,0.51964384,304.05176,-9.3081808
145.4607,30.493406,9.3947153,0.0,0,0.15489216,0.0,0.98302674,145.17729,0.42655498,304.29398,-9.3095999
145.4629,29.065477,9.4031782,0.0,0,0.030416148,0.0,0.98709917,138.04285,0.38514048,304.53616,-9.3119049
145.4651,28.335583,9.4077702,0.0,0,-0.09173242,0.0,0.98580772,134.6187,0.35310116,304.81848,-9.3133888
145.4673,28.254122,9.4086685,0.0,0,-0.21312842,0.0,0.98816442,133.94257,0.30404776,305.94254,-9.3127909
145.4695,28.203569,9.4266586,0.0,0,-0.33452442,0.0,0.98859102,133.62375,0.24885674,307.06662,-9.3138218
145.4717,28.208286,9.420661,0.0,0,-0.45592043,0.0,0.99014336,133.37798,0.19627254,308.1907,-9.3140497
145.4739,28.14279,9.4339418,0.0,0,-0.5773164,0.0,0.99043745,133.07101,0.14303619,309.31476,-9.3156033
145.4761,28.045916,9.4300261,0.0,0,-0.69871235,0.0,0.99190837,132.44156,0.093526036,310.46213,-9.3153629
145.4783,27.886627,9.4467707,0.0,0,-0.82010835,0.0,0.99248815,131.63618,0.047001697,311.63275,-9.3145561
145.4805,27.628126,9.4396601,0.0,0,-0.94150436,0.0,0.99331993,130.32945,0.015175309,312.80338,-9.3141222
145.4827,27.295383,9.4488516,0.0,0,-1.0629004,0.0,0.99334931,128.73117,-0.0052813669,313.974,-9.3135366
145.4849,26.869999,9.4441776,0.0,0,-0.8433286,300.0,0.99417025,126.60397,-0.020871492,315.14462,-9.3143387
145.4871,26.367559,9.4541864,0.0,0,-0.42304948,300.0,0.99390686,124.31736,-0.019300127,315.92981,-9.3165007
145.4893,25.905807,9.4470634,0.0,0,-0.0027700011,300.0,0.99431366,122.04576,-0.014597282,316.69666,-9.3164968
145.4915,25.496689,9.4537926,0.0,0,0.41750887,300.0,0.99439543,120.1216,-0.010588866,317.46347,-9.3156509
145.4937,25.181427,9.4474802,0.0,0,0.83778799,300.0,0.99425411,118.66853,-0.010673434,318.23032,-9.3172321
145.4959,24.914543,9.4560652,0.0,0,1.2580678,300.0,0.99478185,117.3515,-0.0083142417,318.85107,-9.317174
145.4981,24.089554,9.445055,0.0,0,1.6783465,300.0,0.9937377,113.68821,0.013539275,319.26083,-9.3182974
145.5003,22.524458,9.4463568,0.0,0,2.0986254,300.0,0.99331313,106.35675,0.075431667,319.67062,-9.320179
145.5025,19.648706,9.4328251,0.0,0,2.5189049,300.0,0.99146068,93.196777,0.189318,320.08038,-9.3217859
145.5047,14.349575,9.4246235,0.0,0,2.9391842,300.0,0.98970103,68.610962,0.39293081,320.49014,-9.325057
145.5069,0.28685975,9.2064018,0.0,0,3.3594635,300.0,0.95238096,1.1543198,0.7770105,321.44934,-9.3392181
145.5091,0.45855349,9.0353203,0.0,0,3.7797422,300.0,0.92289746,2.6355987,1.4105359,322.49527,-9.3382673
145.5113,-0.23360036,8.954011,0.0,0,4.2000217,300.0,0.90837014,-1.0011213,2.1949208,323.54123,-9.3378763
145.5135,-0.085979283,8.9314966,0.0,0,4.6203008,300.0,0.90525025,-0.47887489,2.9069867,324.58716,-9.3382788
145.5157,-0.1289735,8.9776449,0.0,0,5.0405803,300.0,0.9116531,-0.57375222,3.4647744,325.13138,-9.3380499
145.5179,-0.13357879,9.099267,0.0,0,5.4608593,300.0,0.93324119,-0.77387357,3.8758693,324.60052,-9.3376675
145.5201,0.072664157,9.2704124,0.0,0,5.8811388,300.0,0.96138632,0.23669954,4.2659583,324.06964,-9.3360958
145.5223,-0.2027169,9.4026051,0.0,0,6.3014183,300.0,0.98773301,-1.2052302,4.6531773,323.53879,-9.3344202
145.5245,-0.091779731,9.3853102,0.0,0,6.7216969,300.0,0.98256564,-0.23745012,5.0327396,323.0079,-9.3321686
145.5267,-0.050000936,9.4066153,0.0,0,7.1419768,300.0,0.98801941,-0.41408727,5.4263697,321.71521,-9.3317947
145.5289,-0.076171227,9.4105291,0.0,0,7.5622554,300.0,0.98631942,-0.31404039,5.8455334,320.19846,-9.3304386
145.5311,-0.019950274,9.4050188,0.0,0,7.9825354,300.0,0.98671991,-0.04183672,6.278615,318.68167,-9.3296108
145.5333,-0.1180088,9.4136105,0.0,0,8.4028139,300.0,0.98626775,-0.42827398,6.7200074,317.16492,-9.3295126
145.5355,-0.18577847,9.4017582,0.0,0,8.8230925,300.0,0.98678541,-0.92569417,7.1618586,316.00055,-9.3281403
145.5377,-0.010537995,9.404398,0.0,0,9.243372,300.0,0.98507929,-0.15064591,7.6025801,316.03418,-9.3273468
145.5399,0.017670991,9.3974342,0.0,0,9.6636515,300.0,0.98608309,0.12609111,8.0359058,316.06781,-9.3267155
145.5421,-0.063773036,9.4047556,0.0,0,10.083931,300.0,0.98457313,-0.27518231,8.4673367,316.10144,-9.3274889
145.5443,-0.076062381,9.3980579,0.0,0,10.50421,300.0,0.98605311,-0.3543855,8.898634,316.13507,-9.3266172
145.5465,-0.046732493,9.4015303,0.0,0,10.924489,300.0,0.98450869,-0.24361633,9.3390818,316.19623,-9.3250523
145.5487,-0.047966909,9.3950653,0.0,0,11.344769,300.0,0.98566186,-0.2329945,9.7713137,316.27026,-9.3258343
145.5509,-0.090125516,9.4044628,0.0,0,11.765047,300.0,0.98443091,-0.38610005,10.211262,316.34427,-9.3259172
145.5531,-0.055705465,9.3935919,0.0,0,12.185327,300.0,0.98533094,-0.27242714,10.641199,316.41827,-9.3259153
145.5553,-0.13540174,9.4034843,0.0,0,12.605606,300.0,0.98513681,-0.67751408,11.074492,316.03793,-9.3266449
145.5575,0.0038860466,9.3936062,0.0,0,13.025885,300.0,0.98555273,-0.0043597384,11.494347,312.78033,-9.3250523
145.5597,0.0084822755,9.4032192,0.0,0,13.446164,300.0,0.98461783,0.069040127,11.906157,309.52271,-9.3248873
145.5619,-0.083057523,9.3917675,0.0,0,13.866444,300.0,0.98478031,-0.31426233,12.325365,306.26511,-9.3246565
145.5641,-0.14366163,9.3989725,0.0,0,14.286723,300.0,0.98427624,-0.69033873,12.755734,303.00751,-9.3237534
145.5663,-0.035294022,9.3916121,6.1171613,0,14.707002,300.0,0.98479027,-0.16366297,13.189588,299.57315,-9.3235826
145.5685,0.0019155144,9.4037495,16.469139,0,15.127281,300.0,0.98502398,0.077226624,13.632025,296.01642,-9.3241634
145.5707,-0.10363577,9.3955364,26.821117,0,15.547561,300.0,0.98502982,-0.49130726,14.060911,292.45969,-9.3228483
145.5729,-0.10738151,9.401206,37.173092,0,15.967839,300.0,0.98500896,-0.51676333,14.496387,288.90295,-9.3221731
145.5751,0.033455078,9.3928213,47.054443,0,16.388119,300.0,0.9843123,0.10707947,14.923504,285.5098,-9.3234529
145.5773,-0.01028671,9.4023933,47.054443,0,16.808399,300.0,0.98496336,-0.023802258,15.343805,285.55051,-9.3233643
145.5795,-0.036146447,9.3924065,47.054443,0,17.228678,300.0,0.98431367,-0.16393347,15.763747,285.59125,-9.3234596
145.5817,-0.11037696,9.3985338,47.054443,0,17.648958,300.0,0.98491955,-0.51052511,16.183954,285.63196,-9.3237076
145.5839,-0.050723523,9.3957281,47.054443,0,17.999975,300.0,0.98463851,-0.29320496,16.596142,285.6727,-9.3227911
145.5861,-0.031209311,9.4024687,47.103992,0,18.0,300.0,0.98567432,-0.13443215,17.01786,285.65912,-9.3220472
145.5883,-0.12807488,9.3956022,47.203091,0,18.0,300.0,0.9844287,-0.51083678,17.414631,285.59125,-9.3234186
145.5905,-0.10192651,9.3991404,47.302189,0,18.0,300.0,0.98527372,-0.54842842,17.776171,285.52335,-9.3230619
145.5927,-0.022008248,9.3964891,47.401283,0,18.0,300.0,0.98462039,-0.07973963,18.0835,285.45547,-9.3259211
145.5949,-0.051058695,9.404192,47.500381,0,18.0,300.0,0.9866119,-0.23476547,18.324945,285.3876,-9.3275194
145.5971,-0.012421058,9.4059563,47.504887,0,18.0,300.0,0.98591048,-0.090419777,18.478239,284.85724,-9.3323212
145.5993,0.0010287341,9.4084206,47.504887,0,18.0,300.0,0.98735142,0.063506745,18.520119,284.30484,-9.3372145
145.6015,-0.066705979,9.4141388,47.504887,0,18.0,300.0,0.98715007,-0.28525746,18.455244,283.75244,-9.3437004
145.6037,-0.095783882,9.4264355,47.504887,0,18.0,300.0,0.99069363,-0.42984974,18.332998,283.20004,-9.3507729
145.6059,-0.070400149,9.4399805,47.710217,0,18.0,300.0,0.99154699,-0.3352536,18.213612,282.82986,-9.3641148
145.6081,-0.13837034,9.4513578,48.355553,0,18.0,300.0,0.99527484,-0.6481083,18.118675,282.85025,-9.379281
145.6103,-0.10514927,9.4654732,49.000893,0,18.0,300.0,0.99611336,-0.53714591,18.067411,282.87061,-9.3946791
145.6125,-0.0081532309,9.4810467,49.646229,0,18.0,300.0,1.0009227,-0.12436448,18.051044,282.89096,-9.412219
145.6147,0.05750278,9.5008497,50.291565,0,18.0,300.0,1.0023035,0.20322764,18.050533,282.91132,-9.4281101
145.6169,0.03481086,9.511405,50.438232,0,18.0,300.0,1.00648,0.20799357,18.061098,282.94745,-9.4452209
145.6191,0.0028663024,9.5339823,50.438232,0,18.0,300.0,1.0083231,0.058151525,18.081015,282.98819,-9.4620886
145.6213,-0.064970076,9.549571,50.438232,0,18.0,300.0,1.0135475,-0.24407612,18.104343,283.0289,-9.4795036
145.6235,-0.13295469,9.5752077,50.438232,0,18.0,300.0,1.0156715,-0.52906662,18.122433,283.06964,-9.4974651
145.6257,-0.19075516,9.5805912,50.494812,0,18.0,300.0,1.0193366,-0.87061185,18.13405,283.03015,-9.513731
145.6279,-0.14190236,9.6024971,50.743759,0,18.0,300.0,1.0209771,-0.71971881,18.135927,282.7179,-9.5287924
145.6301,-0.020097174,9.6119547,50.99271,0,18.0,300.0,1.025317,-0.17531794,18.134951,282.40561,-9.5454245
145.6323,0.049976505,9.6375217,51.241661,0,18.0,300.0,1.0270886,0.20224571,18.137367,282.09335,-9.5599003
145.6345,0.052733537,9.6402102,51.490612,0,18.0,300.0,1.0301294,0.24669991,18.133158,281.78107,-9.5749674
145.6367,0.021193944,9.6615677,51.569824,0,18.0,300.0,1.0320997,0.1381329,18.13147,281.50583,-9.5900764
145.6389,-0.035450537,9.6728973,51.569824,0,18.0,300.0,1.0363522,-0.12401503,18.131067,281.24786,-9.6057758
145.6411,-0.12071598,9.7003088,51.569824,0,18.0,300.0,1.0390582,-0.49426222,18.128757,280.9899,-9.6216364
145.6433,-0.1600503,9.7062998,51.569824,0,18.0,300.0,1.0424706,-0.72345024,18.126501,280.73193,-9.6383848
145.6455,-0.15067096,9.7284107,51.632446,0,18.0,300.0,1.0448639,-0.69789749,18.127645,280.48508,-9.6552048
145.6477,-0.069775492,9.7351828,52.091675,0,18.0,300.0,1.047856,-0.391774,18.124285,280.30859,-9.6711473
145.6499,0.023636919,9.7623549,52.550903,0,18.0,300.0,1.0511502,0.075239561,18.120853,280.13208,-9.685174
145.6521,0.069311529,9.7675276,53.010132,0,18.0,300.0,1.0536691,0.30197719,18.115332,279.95557,-9.7019882
145.6543,0.042836539,9.7884226,53.469357,0,18.0,300.0,1.056444,0.20890568,18.113737,279.77905,-9.7182007
145.6565,-0.016363837,9.797637,53.657227,0,18.0,300.0,1.0592492,-0.032082606,18.115707,279.63065,-9.7349615
145.6587,-0.094363041,9.8266268,53.657227,0,18.0,300.0,1.0639518,-0.32787225,18.11434,279.50168,-9.7517805
145.6609,-0.16033424,9.8360338,53.657227,0,18.0,300.0,1.0664747,-0.68214864,18.110733,279.37268,-9.7680044
145.6631,-0.16421224,9.8528547,53.657227,0,18.0,300.0,1.0693928,-0.74303848,18.109016,279.24371,-9.7817278
145.6653,-0.10846964,9.8599987,53.666893,0,18.0,300.0,1.0710757,-0.52676207,18.107815,279.11536,-9.7959175
145.6675,-0.016972221,9.8825207,53.879589,0,18.0,300.0,1.0753958,-0.13946375,18.107059,278.99997,-9.8126373
145.6697,0.059055593,9.8893337,54.092285,0,18.0,300.0,1.0765463,0.1947628,18.102751,278.88455,-9.8286667
145.6719,0.071553752,9.9086161,54.304981,0,18.0,300.0,1.0807643,0.29412556,18.099943,278.76913,-9.8436365
145.6741,0.016752001,9.9256458,54.517677,0,18.0,300.0,1.083227,0.07156986,18.106207,278.65375,-9.8590698
145.6763,-0.066599123,9.9464598,54.624023,0,18.0,300.0,1.0884308,-0.21382412,18.100563,278.28378,-9.8752632
145.6785,-0.13434127,9.9612379,54.624023,0,18.0,300.0,1.0899699,-0.53329015,18.105455,277.65921,-9.8932419
145.6807,-0.16751806,9.975502,54.624023,0,18.0,300.0,1.0942683,-0.71810788,18.107067,277.03467,-9.9096441
145.6829,-0.14071809,9.9911051,54.624023,0,18.0,300.0,1.0959502,-0.62061042,18.102795,276.41013,-9.9246264
145.6851,-0.052459206,10.008965,54.624023,0,18.0,300.0,1.1012453,-0.29662341,18.099184,275.78558,-9.9394789
145.6873,0.034351151,10.022696,55.348461,0,18.0,300.0,1.1020921,0.10559814,18.101641,275.48505,-9.9547825
145.6895,0.065486372,10.035909,56.107399,0,18.0,300.0,1.1066211,0.27375481,18.10133,275.19995,-9.9713173
145.6917,0.038454279,10.052968,56.866333,0,18.0,300.0,1.1081055,0.19099385,18.10037,274.91483,-9.9863129
145.6939,-0.038736802,10.066842,57.625267,0,18.0,300.0,1.1134399,-0.090048388,18.097908,274.62973,-10.00175
145.6961,-0.11428522,10.088581,58.07373,0,18.0,300.0,1.1150528,-0.4353258,18.099831,274.41125,-10.01794
145.6983,-0.1542155,10.097197,58.07373,0,18.0,300.0,1.1196077,-0.63015509,18.102062,274.28906,-10.033844
145.7005,-0.15133424,10.118525,58.07373,0,18.0,300.0,1.121433,-0.65637553,18.098574,274.16687,-10.051003
145.7027,-0.081854813,10.129283,58.07373,0,18.0,300.0,1.1262475,-0.3948859,18.095789,274.04468,-10.066666
145.7049,0.017455444,10.15248,58.07373,0,18.0,300.0,1.1280136,0.0078122639,18.095541,273.92249,-10.081474
145.7071,0.067383662,10.159397,58.409805,0,18.0,300.0,1.1325326,0.25208846,18.095108,273.59497,-10.096942
145.7093,0.063401707,10.182603,58.798943,0,18.0,300.0,1.1344892,0.2854909,18.091391,273.23502,-10.113138
145.7115,0.0064859749,10.191054,59.188076,0,18.0,300.0,1.1390101,0.10066115,18.092207,272.87506,-10.130488
145.7137,-0.092828773,10.216703,59.577213,0,18.0,300.0,1.1409453,-0.29926601,18.092634,272.51511,-10.145773
145.7159,-0.16145363,10.223559,59.842533,0,18.0,300.0,1.1455498,-0.59855437,18.093002,272.22839,-10.161777
145.7181,-0.16006847,10.245244,59.842533,0,18.0,300.0,1.147802,-0.64685494,18.089844,272.09866,-10.176455
145.7203,-0.10146272,10.255314,59.842533,0,18.0,300.0,1.1524209,-0.48356834,18.087648,271.96893,-10.193046
145.7225,-0.021540325,10.279007,59.842533,0,18.0,300.0,1.154633,-0.16206264,18.089258,271.83917,-10.208881
145.7247,0.053491473,10.282907,59.842533,0,18.0,300.0,1.1579376,0.15660591,18.093075,271.70944,-10.22491
145.7269,0.067242533,10.303588,60.003151,0,18.0,300.0,1.1602362,0.2461161,18.086744,271.53223,-10.239484
145.7291,0.038022012,10.314811,60.211014,0,18.0,300.0,1.1645889,0.17921732,18.082092,271.34103,-10.255276
145.7313,-0.0447606,10.340665,60.418869,0,18.0,300.0,1.1678828,-0.10610809,18.08157,271.14981,-10.271042
145.7335,-0.13520966,10.345785,60.626732,0,18.0,300.0,1.1711234,-0.46784565,18.082253,270.95862,-10.288729
145.7357,-0.16318391,10.372186,60.787354,0,18.0,300.0,1.1752992,-0.64121002,18.082813,270.755,-10.306024
145.7379,-0.12757763,10.382003,60.787354,0,18.0,300.0,1.178511,-0.51403266,18.081896,270.50919,-10.32181
145.7401,-0.038139883,10.403943,60.787354,0,18.0,300.0,1.1822555,-0.21203773,18.078178,270.26337,-10.336358
145.7423,0.024115272,10.408044,60.787354,0,18.0,300.0,1.1842251,0.061196562,18.07955,270.01755,-10.350443
145.7445,0.069585219,10.427284,60.787354,0,18.0,300.0,1.1879195,0.24234287,18.07691,269.77173,-10.365768
145.7467,0.054780997,10.44152,61.019714,0,18.0,300.0,1.1908537,0.23407842,18.077681,269.51193,-10.381401
145.7489,-0.0099510048,10.466137,61.360508,0,18.0,300.0,1.196517,0.026862154,18.078663,269.24564,-10.397633
145.7511,-0.11474025,10.476182,61.701305,0,18.0,300.0,1.198413,-0.38656253,18.080843,268.97934,-10.41408
145.7533,-0.17798123,10.49477,62.042099,0,18.0,300.0,1.2031265,-0.67679632,18.076658,268.71301,-10.430921
145.7555,-0.13861984,10.507773,62.336426,0,18.0,300.0,1.2053531,-0.55493921,18.07658,268.45139,-10.447211
145.7577,-0.068921328,10.526751,62.336426,0,18.0,300.0,1.2104943,-0.31433102,18.075123,268.21921,-10.463327
145.7599,0.0067987568,10.539951,62.336426,0,18.0,300.0,1.2119846,-0.031111905,18.079172,267.98703,-10.479751
145.7621,0.055825051,10.55204,62.336426,0,18.0,300.0,1.216367,0.17807107,18.077404,267.75488,-10.49408
145.7643,0.069616243,10.568414,62.336426,0,18.0,300.0,1.2180985,0.26784417,18.074743,267.52271,-10.511039
145.7665,0.025148798,10.588118,62.47068,0,18.0,300.0,1.2248608,0.10283989,18.075758,267.31879,-10.525614
145.7687,-0.077773832,10.608181,62.69788,0,18.0,300.0,1.2268565,-0.23717724,18.077015,267.13443,-10.542773
145.7709,-0.15731977,10.616307,62.925072,0,18.0,300.0,1.231263,-0.56985289,18.075666,266.95007,-10.55897
145.7731,-0.16153708,10.632745,63.152271,0,18.0,300.0,1.2327087,-0.61509484,18.075562,266.76572,-10.574897
145.7753,-0.10204859,10.647916,63.369144,0,18.0,300.0,1.2388972,-0.42179665,18.07515,266.58353,-10.590051
145.7775,-0.0048917308,10.667859,63.369144,0,18.0,300.0,1.2402017,-0.083053738,18.072157,266.44693,-10.606063
145.7797,0.038773175,10.67472,63.369144,0,18.0,300.0,1.2450767,0.12103303,18.071802,266.31036,-10.621601
145.7819,0.077371337,10.696164,63.369144,0,18.0,300.0,1.246981,0.23073101,18.072395,266.1738,-10.63649
145.7841,0.056052264,10.706588,63.369144,0,18.0,300.0,1.2526623,0.22002767,18.070154,266.03723,-10.651174
145.7863,-0.031245239,10.731571,63.477909,0,18.0,300.0,1.2549051,-0.061849136,18.069571,265.88699,-10.666324
145.7885,-0.13255882,10.740392,63.695435,0,18.0,300.0,1.2605455,-0.39367798,18.064211,265.72311,-10.683842
145.7907,-0.17073508,10.762778,63.912964,0,18.0,300.0,1.2626197,-0.58447099,18.069988,265.55923,-10.700295
145.7929,-0.13546747,10.770304,64.130493,0,18.0,300.0,1.2678124,-0.51819944,18.06918,265.39532,-10.717335
145.7951,-0.03868724,10.797175,64.348022,0,18.0,300.0,1.2702149,-0.21166897,18.067207,265.23145,-10.731527
145.7973,0.039242625,10.803699,64.35791,0,18.0,300.0,1.2754461,0.11489423,18.066158,264.95026,-10.74736
145.7995,0.067317836,10.824775,64.35791,0,18.0,300.0,1.2775867,0.2419233,18.064085,264.66345,-10.762973
145.8017,0.051813971,10.829829,64.35791,0,18.0,300.0,1.2817177,0.2089781,18.063364,264.37668,-10.779334
145.8039,-0.00037521907,10.859344,64.35791,0,18.0,300.0,1.2854171,0.047362633,18.062969,264.08987,-10.79459
145.8061,-0.091069251,10.866336,64.458763,0,18.0,300.0,1.2901176,-0.25649315,18.063019,263.82822,-10.811217
145.8083,-0.17337298,10.892659,64.705299,0,18.0,300.0,1.2941833,-0.57864594,18.063753,263.60287,-10.827918
145.8105,-0.16717733,10.896974,64.951828,0,18.0,300.0,1.2974392,-0.5994215,18.057957,263.37756,-10.843476
145.8127,-0.080686696,10.923631,65.198364,0,18.0,300.0,1.3015196,-0.34712145,18.060787,263.15222,-10.859425
145.8149,0.022657892,10.927086,65.444901,0,18.0,300.0,1.3045309,0.0091023156,18.061771,262.92688,-10.875952
145.8171,0.050641935,10.949673,65.478516,0,18.0,300.0,1.3082802,0.16282198,18.06292,262.68384,-10.891008
145.8193,0.049354888,10.95752,65.478516,0,18.0,300.0,1.3115383,0.1907392,18.060276,262.43802,-10.906017
145.8215,0.030143792,10.980125,65.478516,0,18.0,300.0,1.315863,0.15395722,18.059017,262.1922,-10.921906
145.8237,-0.045515589,10.986501,65.478516,0,18.0,300.0,1.3187251,-0.13589369,18.060549,261.94638,-10.939207
145.8259,-0.1481261,11.00948,65.576958,0,18.0,300.0,1.3239918,-0.4646903,18.062893,261.6897,-10.954287
145.8281,-0.18941121,11.018976,65.88633,0,18.0,300.0,1.3264537,-0.62519681,18.058714,261.40973,-10.969267
145.8303,-0.10869394,11.043272,66.195702,0,18.0,300.0,1.3328618,-0.40468445,18.059355,261.12979,-10.984398
145.8325,-0.0089749144,11.053391,66.505074,0,18.0,300.0,1.3348494,-0.07179413,18.060547,260.84982,-11.000331
145.8347,0.052696805,11.067883,66.814453,0,18.0,300.0,1.3392648,0.12161285,18.060099,260.56985,-11.015784
145.8369,0.06610021,11.081104,66.884766,0,18.0,300.0,1.341812,0.21695663,18.061899,260.4007,-11.03209
145.8391,0.045316085,11.1053,66.884766,0,18.0,300.0,1.3492068,0.17319733,18.059706,260.26413,-11.047924
145.8413,-0.011276235,11.119985,66.884766,0,18.0,300.0,1.3510394,0.016504399,18.057777,260.12753,-11.06505
145.8435,-0.09368179,11.134181,66.884766,0,18.0,300.0,1.3567289,-0.27797595,18.055988,259.99097,-11.081814
145.8457,-0.17082343,11.151202,66.918274,0,18.0,300.0,1.3589159,-0.54530114,18.054888,259.84665,-11.097059
145.8479,-0.15821506,11.168515,67.065712,0,18.0,300.0,1.3660829,-0.5296331,18.055079,259.67593,-11.114946
145.8501,-0.050126962,11.184421,67.21315,0,18.0,300.0,1.3676404,-0.22555314,18.058413,259.50522,-11.130369
145.8523,0.02781702,11.19306,67.36058,0,18.0,300.0,1.3729279,0.069643736,18.052156,259.33453,-11.143628
145.8545,0.067122787,11.211785,67.508018,0,18.0,300.0,1.3745575,0.19383445,18.04994,259.16382,-11.158713
145.8567,0.062427506,11.226039,67.554932,0,18.0,300.0,1.3815604,0.22551639,18.0515,258.9838,-11.174252
145.8589,0.0098014008,11.247824,67.554932,0,18.0,300.0,1.3836238,0.055556949,18.047968,258.79944,-11.190029
145.8611,-0.075455815,11.256697,67.554932,0,18.0,300.0,1.3898028,-0.19962689,18.050903,258.61508,-11.20626
145.8633,-0.14657812,11.276362,67.554932,0,18.0,300.0,1.3917066,-0.42157221,18.051311,258.43069,-11.223415
145.8655,-0.172684,11.286288,67.578995,0,18.0,300.0,1.3980182,-0.53901029,18.05254,258.24448,-11.23957
145.8677,-0.1008196,11.312674,67.755432,0,18.0,300.0,1.4006625,-0.37159938,18.048456,258.04645,-11.25442
145.8699,0.021967845,11.316378,67.931877,0,18.0,300.0,1.4059821,-0.00016425803,18.049213,257.84842,-11.271133
145.8721,0.080426089,11.337289,68.108315,0,18.0,300.0,1.4081867,0.20640764,18.053316,257.65039,-11.286781
145.8743,0.064703621,11.34721,68.284752,0,18.0,300.0,1.4147235,0.21754004,18.048498,257.45239,-11.300997
145.8765,0.028659226,11.374054,68.356934,0,18.0,300.0,1.4176426,0.1258541,18.049156,257.25415,-11.317098
145.8787,-0.041968398,11.379952,68.356934,0,18.0,300.0,1.4231505,-0.10052823,18.047226,257.05582,-11.332496
145.8809,-0.12635753,11.400377,68.356934,0,18.0,300.0,1.4254283,-0.34928787,18.050299,256.85748,-11.348887
145.8831,-0.16874367,11.409352,68.356934,0,18.0,300.0,1.4317696,-0.48181999,18.05003,256.65912,-11.364644
146.7834,-0.058031082,11.528788,3.9132197e-11,0,18.0,1.6216742e-10,1.4634964,-0.16682686,18.001675,143.3179,-11.483285
147.8834,-0.056596495,11.52851,3.9487117e-26,0,18.0,1.6196896e-25,1.4634639,-0.16632967,18.000364,66.986626,-11.482457
148.9834,-0.049504012,11.528736,3.9823501e-41,0,18.0,1.6177150000000001e-40,1.463446,-0.14665323,17.999969,39.750519,-11.483032
150.0834,-0.051724069,11.528758,7.9874012e-44,0,18.0,1.4012985e-45,1.4636418,-0.15479089,17.999512,30.549578,-11.483076
151.1834,-0.063759126,11.528899,7.9874012e-44,0,18.0,1.4012985e-45,1.4636463,-0.18500547,18.000778,27.33054,-11.483143
152.2834,-0.055301607,11.52934,7.9874012e-44,0,18.0,1.4012985e-45,1.4637346,-0.16088164,17.999563,26.117605,-11.482866
153.3834,-0.056515578,11.529257,7.9874012e-44,0,18.0,1.4012985e-45,1.4636484,-0.16376184,17.999096,25.811623,-11.482494
154.4834,-0.062505499,11.529492,7.9874012e-44,0,18.0,1.4012985e-45,1.4636297,-0.18713154,18.000599,25.66304,-11.482788
155.5834,-0.063970797,11.529081,7.9874012e-44,0,18.0,1.4012985e-45,1.4636689,-0.18655618,18.000145,25.553244,-11.483118
156.6834,-0.050798535,11.529889,7.9874012e-44,0,18.0,1.4012985e-45,1.4638784,-0.14636111,17.999607,25.461617,-11.483319
157.7834,-0.053965848,11.530139,7.9874012e-44,0,18.0,1.4012985e-45,1.4640279,-0.15952809,18.000313,25.447311,-11.483292
158.8834,-0.065616995,11.530239,7.9874012e-44,0,18.0,1.4012985e-45,1.4640157,-0.19303502,18.000355,25.413195,-11.483132
159.9834,-0.062381785,11.530646,7.9874012e-44,0,18.0,1.4012985e-45,1.4639633,-0.18217584,17.999836,25.420195,-11.483019
161.0834,-0.059864312,11.530398,7.9874012e-44,0,18.0,1.4012985e-45,1.4639976,-0.17748882,18.000713,25.259502,-11.483282
162.1834,-0.058034483,11.531191,7.9874012e-44,0,18.0,1.4012985e-45,1.4641894,-0.16933027,18.000195,25.273329,-11.483131
163.2834,-0.063580215,11.531292,7.9874012e-44,0,18.0,1.4012985e-45,1.4643605,-0.18710168,17.999125,25.222925,-11.483206
164.3834,-0.065862566,11.531487,7.9874012e-44,0,18.0,1.4012985e-45,1.4644248,-0.18954007,18.000399,25.204727,-11.483347
165.4834,-0.061837029,11.531119,7.9874012e-44,0,18.0,1.4012985e-45,1.4642013,-0.1792506,18.001072,25.146404,-11.482802
166.5834,-0.056540541,11.531837,7.9874012e-44,0,18.0,1.4012985e-45,1.4643917,-0.16624369,18.000221,25.167654,-11.482953
167.6834,-0.059955403,11.532197,7.9874012e-44,0,18.0,1.4012985e-45,1.464412,-0.17829625,18.001152,25.154339,-11.483486
168.7834,-0.062225491,11.53216,7.9874012e-44,0,18.0,1.4012985e-45,1.4645585,-0.18241404,18.000607,25.123487,-11.483152
169.8834,-0.06492164,11.533011,7.9874012e-44,0,18.0,1.4012985e-45,1.4647896,-0.18981351,17.999475,25.073896,-11.482862
170.9834,-0.054026615,11.533008,7.9874012e-44,0,18.0,1.4012985e-45,1.4647981,-0.16033831,18.000744,25.115257,-11.483365
172.0834,-0.061714478,11.533336,7.9874012e-44,0,18.0,1.4012985e-45,1.4649168,-0.1808046,18.000031,25.027458,-11.483382
173.1834,-0.065894134,11.53405,7.9874012e-44,0,18.0,1.4012985e-45,1.4649689,-0.1927727,18.000546,25.071012,-11.48337
174.2834,-0.064496525,11.533663,7.9874012e-44,0,18.0,1.4012985e-45,1.4649369,-0.18987939,18.000113,25.10137,-11.483247
175.3834,-0.062055275,11.533546,7.9874012e-44,0,18.0,1.4012985e-45,1.4648255,-0.18278557,17.998363,24.979013,-11.482952
176.4834,-0.067923293,11.533931,7.9874012e-44,0,18.0,1.4012985e-45,1.4651458,-0.20032346,18.000444,24.938625,-11.482725
177.5834,-0.064071536,11.533689,7.9874012e-44,0,18.0,1.4012985e-45,1.4650272,-0.1887126,17.99996,24.898239,-11.482898
178.6834,-0.067056604,11.533876,7.9874012e-44,0,18.0,1.4012985e-45,1.4650002,-0.19233589,17.999504,24.898186,-11.48303
179.7834,-0.062243637,11.534099,7.9874012e-44,0,18.0,1.4012985e-45,1.4650658,-0.1836852,17.999155,24.859535,-11.482746
180.8834,-0.065225758,11.534617,7.9874012e-44,0,18.0,1.4012985e-45,1.4650719,-0.19200841,18.00074,24.92742,-11.4828
181.9834,-0.063168466,11.534638,7.9874012e-44,0,18.0,1.4012985e-45,1.4652593,-0.18561664,17.999283,24.940292,-11.483099
183.0834,-0.062957942,11.535219,7.9874012e-44,0,18.0,1.4012985e-45,1.4653941,-0.18435869,18.000116,24.936132,-11.482788
184.1834,-0.057448342,11.535856,7.9874012e-44,0,18.0,1.4012985e-45,1.4657238,-0.16841274,17.999266,24.883287,-11.483195
185.2834,-0.053227305,11.535416,7.9874012e-44,0,18.0,1.4012985e-45,1.4655309,-0.15915261,18.000582,24.910976,-11.483387
186.3834,-0.061532807,11.535954,7.9874012e-44,0,18.0,1.4012985e-45,1.4654937,-0.18313226,17.999802,24.871101,-11.483421
187.4834,-0.06199817,11.536243,7.9874012e-44,0,18.0,1.4012985e-45,1.4656714,-0.17909446,17.999943,24.790369,-11.483042
188.5834,-0.055850852,11.536322,7.9874012e-44,0,18.0,1.4012985e-45,1.4656125,-0.16326192,18.000383,24.826818,-11.483568
189.6834,-0.064655289,11.536691,7.9874012e-44,0,18.0,1.4012985e-45,1.4659412,-0.1901233,18.00112,24.902193,-11.483156
190.7834,-0.06982372,11.53717,7.9874012e-44,0,18.0,1.4012985e-45,1.4660388,-0.20142017,17.999989,24.828701,-11.483092
191.8834,-0.072769769,11.536966,7.9874012e-44,0,18.0,1.4012985e-45,1.4659001,-0.21059693,18.000166,24.805981,-11.48265
192.9834,-0.063694753,11.536903,7.9874012e-44,0,18.0,1.4012985e-45,1.4658554,-0.18670571,18.000338,24.766504,-11.48233
194.0834,-0.067327961,11.536914,7.9874012e-44,0,18.0,1.4012985e-45,1.4657736,-0.20016576,18.000498,24.700794,-11.482574
195.1834,-0.062654264,11.537292,7.9874012e-44,0,18.0,1.4012985e-45,1.4660571,-0.18892486,18.000124,24.80345,-11.482412
196.2834,-0.064184256,11.537265,7.9874012e-44,0,18.0,1.4012985e-45,1.4660212,-0.18563125,18.000834,24.808092,-11.482284
197.3834,-0.056850709,11.537595,7.9874012e-44,0,18.0,1.4012985e-45,1.466228,-0.16570945,18.000422,24.726767,-11.482684
198.4834,-0.065278143,11.538019,7.9874012e-44,0,18.0,1.4012985e-45,1.4662585,-0.19114465,18.000044,24.752737,-11.48269
199.5834,-0.068896562,11.538069,7.9874012e-44,0,18.0,1.4012985e-45,1.4661252,-0.20320712,18.000454,24.749464,-11.48314
200.6834,-0.064688742,11.538576,7.9874012e-44,0,18.0,1.4012985e-45,1.4663409,-0.18762825,18.0005,24.780083,-11.483121
201.7834,-0.057067413,11.539042,7.9874012e-44,0,18.0,1.4012985e-45,1.4664202,-0.16510949,18.000679,24.68829,-11.483232
202.8834,-0.056184225,11.538792,7.9874012e-44,0,18.0,1.4012985e-45,1.4665406,-0.1664665,17.998848,24.6716,-11.482932
203.9834,-0.063207202,11.539233,7.9874012e-44,0,18.0,1.4012985e-45,1.4666464,-0.18506743,18.000467,24.808584,-11.483104
205.0834,-0.06015427,11.539927,7.9874012e-44,0,18.0,1.4012985e-45,1.4668131,-0.17419398,18.000071,24.761059,-11.483438
205.8834,-0.061347254,11.539601,7.9874012e-44,0,18.0,1.4012985e-45,1.4668075,-0.18086451,17.999552,24.751322,-11.483218