File: examples/hot axisymmetric compression example/data/02 screened data/testID_0132.csv
Time(sec),Force(kN),Jaw(mm),PowAngle(deg),Power(W),Pram,PTemp,Strain,Stress(MPa),Stroke(mm),TC1(C),wedge(mm)
0.0,1.0190612,0.38541302,0.0,0,11.076097,0.0013276598,0.026010988,12.644778,11.076402,23.743334,-9.1279764
1.1,0.97358364,-0.0034492959,0.0,0,11.076097,3.2158828,-0.00023405851,12.39826,11.076489,23.798677,-9.4978523
2.2,0.94296348,-0.0036824981,0.0,0,11.076097,6.515883,-0.00022864435,12.004962,11.076226,23.72053,-9.4950714
3.3,0.92508852,-0.0034101726,0.0,0,11.076097,9.8158798,-0.00022555313,11.783453,11.076297,23.691555,-9.4935007
4.4,0.91042119,-0.003273238,0.0,0,11.076097,13.115883,-0.0002210961,11.600947,11.076634,23.68009,-9.4916496
5.5,0.90042877,-0.0034111724,0.0,0,11.076097,16.415884,-0.00024488577,11.467277,11.076785,23.6257,-9.4895706
6.6,0.88640726,-0.0038559171,0.0,0,11.076097,19.715883,-0.00025044882,11.277166,11.076642,23.605528,-9.4875917
7.7,0.86764973,-0.0035889603,0.0,0,11.076097,23.015884,-0.00022662354,11.044063,11.076339,23.58148,-9.4856396
8.8,0.86258858,-0.0035237537,19.433231,0,11.076097,26.315886,-0.0002244373,10.988629,11.076211,23.594742,-9.4834089
9.9,0.85554135,-0.0031288674,32.649239,0,11.076097,29.615887,-0.00021973206,10.904869,11.076786,24.0658,-9.4809151
11.0,0.8714478,-0.0045592743,39.215385,0,11.076097,32.915894,-0.00032324949,11.106006,11.075868,25.607735,-9.4799194
12.1,0.88004655,-0.0073765214,42.948292,0,11.076097,36.215889,-0.00047670948,11.206171,11.075805,28.278461,-9.4781456
13.2,0.893098,-0.010160604,45.114445,0,11.076097,39.515888,-0.00067155214,11.396732,11.075793,31.6231,-9.476388
14.3,0.88971961,-0.012989799,46.581894,0,11.076097,42.815884,-0.00085736963,11.341653,11.075424,35.178555,-9.4739923
15.4,0.90191394,-0.015738038,47.952991,0,11.076097,46.115887,-0.0010718901,11.49866,11.07624,38.893753,-9.4724016
16.5,0.90470332,-0.020091768,48.441147,0,11.076097,49.415882,-0.0013424545,11.524312,11.076145,42.900223,-9.4701338
17.6,0.91175759,-0.022260748,49.088451,0,11.076097,52.715881,-0.0014578841,11.629128,11.07692,46.859818,-9.4683704
18.7,0.91758597,-0.025304753,49.301769,0,11.076097,56.015877,-0.0016906871,11.698505,11.075756,50.946529,-9.4663095
19.8,0.92326415,-0.028888809,49.631123,0,11.076097,59.315876,-0.0019117238,11.777567,11.076369,54.8904,-9.4642992
20.9,0.93577552,-0.031944852,49.636227,0,11.076097,62.615879,-0.0021450084,11.937394,11.076521,58.882351,-9.4626379
22.0,0.93625122,-0.03461187,49.733356,0,11.076097,65.915886,-0.0023032059,11.952784,11.075732,62.727703,-9.4607792
23.1,0.93769062,-0.037568182,50.041561,0,11.076097,69.215881,-0.0024941326,11.975307,11.076202,66.451172,-9.4586039
24.2,0.94895589,-0.04017327,50.185261,0,11.076097,72.515884,-0.0026712199,12.122797,11.076667,69.997505,-9.4570894
25.3,0.94642925,-0.042778466,50.251495,0,11.076097,75.81588,-0.0028540795,12.070299,11.076307,73.697403,-9.4547205
26.4,0.95699221,-0.045777097,50.438229,0,11.076097,79.115875,-0.0030695042,12.227393,11.076433,77.21405,-9.4529238
27.5,0.95917314,-0.047882285,50.504818,0,11.076097,82.415886,-0.003183994,12.259316,11.075963,80.745155,-9.4511137
28.6,0.95472616,-0.051072709,50.438362,0,11.076097,85.715874,-0.0033887895,12.191089,11.075988,84.373672,-9.4487972
29.7,0.96048051,-0.053548284,50.765144,0,11.076097,89.015884,-0.0035462561,12.273534,11.075846,87.772644,-9.4471111
30.8,0.95765823,-0.056489758,50.82275,0,11.076097,92.315872,-0.0037668154,12.241473,11.075838,91.210091,-9.44489
31.9,0.97146547,-0.059644789,50.82275,0,11.076097,95.615891,-0.0039848629,12.425827,11.076805,94.60701,-9.4429922
33.0,0.97486717,-0.061050527,51.030182,0,11.076097,98.915894,-0.0040459819,12.46962,11.076275,97.874702,-9.4409752
34.1,0.97229266,-0.064001009,51.241142,0,11.076097,102.2159,-0.0042597172,12.42571,11.075999,101.12572,-9.4388714
35.2,0.97448587,-0.067030601,51.56982,0,11.076097,105.51591,-0.0044469987,12.473246,11.076096,104.35062,-9.436923
36.3,0.97285497,-0.069555745,51.882328,0,11.076097,108.8159,-0.0046462454,12.43153,11.07782,107.70877,-9.4353733
37.4,0.97944272,-0.073824041,51.99839,0,11.076097,112.11591,-0.0049273507,12.547285,11.07611,110.96964,-9.4331322
38.5,0.9841727,-0.075173989,52.283901,0,11.076097,115.4159,-0.0049778624,12.602724,11.076895,114.3198,-9.431613
39.6,0.98510802,-0.077930346,52.283939,0,11.076097,118.7159,-0.0051710354,12.602343,11.076693,117.66129,-9.4297571
40.7,0.98327553,-0.081115738,52.622177,0,11.076097,122.0159,-0.0053818342,12.582595,11.076094,120.97706,-9.4278383
41.8,0.98511326,-0.084259003,52.752769,0,11.076097,125.3159,-0.0056231255,12.619153,11.07611,124.22065,-9.4261618
42.9,0.99481302,-0.088254534,52.974884,0,11.076097,128.61601,-0.0058738063,12.743587,11.076827,127.63489,-9.4242592
44.0,0.99131,-0.089280747,52.985443,0,11.076097,131.91588,-0.0059230994,12.703103,11.076225,130.91713,-9.4219484
45.1,0.98895818,-0.092290759,53.31665,0,11.076097,135.2159,-0.0061326851,12.676335,11.076375,134.05833,-9.4202089
46.2,0.98431391,-0.095386572,53.657204,0,11.076097,138.51588,-0.006337448,12.616139,11.076092,137.2718,-9.4183397
47.3,0.98273712,-0.098263681,53.975826,0,11.076097,141.81589,-0.0065523018,12.597221,11.076801,140.48059,-9.4157534
48.4,0.99644619,-0.10220853,54.238979,0,11.076097,145.11589,-0.0067851972,12.759793,11.076543,143.76218,-9.4144697
49.5,0.9911505,-0.10398932,54.306763,0,11.076097,148.41589,-0.0068883486,12.720789,11.075834,147.07112,-9.4121208
50.6,0.98797303,-0.10656005,54.625256,0,11.076097,151.7159,-0.0070719421,12.675095,11.076465,150.29596,-9.4106426
51.7,0.99178982,-0.10974336,54.931637,0,11.076097,155.01588,-0.0072907005,12.720635,11.076653,153.56718,-9.408761
52.8,0.98638588,-0.11282879,55.239254,0,11.076097,158.3159,-0.0075192577,12.649072,11.076994,156.87643,-9.4067507
53.9,0.99237227,-0.11600056,55.535599,0,11.076097,161.61591,-0.0076880907,12.730595,11.076079,160.01569,-9.4050922
55.0,0.99676031,-0.11988562,55.83614,0,11.076097,164.91591,-0.0079533858,12.791549,11.076423,163.36612,-9.4033537
56.1,1.0002254,-0.120928,56.067348,0,11.076097,168.2159,-0.0080228839,12.846519,11.074967,166.64372,-9.4015169
57.2,0.99663585,-0.12482276,56.286457,0,11.076097,171.5159,-0.0082952911,12.793671,11.076094,169.94847,-9.3999205
58.3,0.99230844,-0.12787516,56.443344,0,11.076097,174.8159,-0.0085118599,12.738224,11.076645,173.32819,-9.397686
59.4,0.99034864,-0.13161919,56.707394,0,11.076097,178.11589,-0.0087269163,12.713114,11.076378,176.65239,-9.3953972
60.5,1.0000789,-0.13540034,56.712086,0,11.076097,181.41589,-0.0089711305,12.840248,11.076142,180.01738,-9.3939638
61.6,0.99882835,-0.1370942,56.986084,0,11.076097,184.71588,-0.0090987589,12.826783,11.075475,183.30583,-9.3915815
62.7,0.99580503,-0.13975547,57.175346,0,11.076097,188.0159,-0.0092816893,12.792598,11.076911,186.69415,-9.389987
63.8,0.98608452,-0.14327472,57.465195,0,11.076097,191.31589,-0.0095282374,12.686252,11.07683,189.90039,-9.3879232
64.9,0.99106401,-0.14677291,57.523273,0,11.076097,194.61589,-0.0097286059,12.745237,11.076533,193.29053,-9.3861732
66.0,0.99242258,-0.14965503,57.732555,0,11.076097,197.91589,-0.0099184364,12.74278,11.076221,196.60725,-9.3839569
67.1,1.0028205,-0.15408652,57.958881,0,11.076097,201.2159,-0.010217089,12.878741,11.076138,199.84021,-9.3823032
68.2,1.0031455,-0.15525366,58.092049,0,11.076097,204.5159,-0.01030888,12.895778,11.076075,203.1506,-9.3807688
69.3,1.0029503,-0.15827867,58.337341,0,11.076097,207.8159,-0.01050963,12.909253,11.075772,206.41199,-9.3788347
70.4,1.0032225,-0.16180915,58.467854,0,11.076097,211.11589,-0.010717255,12.902755,11.076376,209.74861,-9.3771591
71.5,0.99719054,-0.16541009,58.747379,0,11.076097,214.41589,-0.010958772,12.83459,11.075485,212.96954,-9.3753862
72.6,1.0012953,-0.16874726,58.866409,0,11.076097,217.7159,-0.011180135,12.876662,11.076354,216.28688,-9.3737907
73.7,1.0091516,-0.17365414,59.106438,0,11.076097,221.01591,-0.011513222,12.997466,11.077141,219.49336,-9.372261
74.8,1.008976,-0.17542312,59.348137,0,11.076097,224.3159,-0.011646085,13.007877,11.076717,222.80141,-9.3701439
75.9,1.002154,-0.17845005,59.600826,0,11.076097,227.61589,-0.01180879,12.910784,11.076938,226.05103,-9.3682775
77.0,0.9997189,-0.18175077,59.80183,0,11.076097,230.91591,-0.012041992,12.872283,11.076458,229.28285,-9.3663177
78.1,1.0018846,-0.18570223,60.043785,0,11.076097,234.2159,-0.012287665,12.919897,11.076199,232.6792,-9.3646145
79.2,0.99038899,-0.18931536,60.084225,0,11.076097,237.51588,-0.012557428,12.761007,11.076503,236.08354,-9.362896
80.3,0.99201035,-0.19278316,60.212578,0,11.076097,240.8159,-0.012780771,12.780223,11.075483,239.47037,-9.3606138
81.4,0.99376488,-0.1963122,60.314934,0,11.076097,244.11589,-0.012988644,12.800663,11.076281,242.79507,-9.3584547
82.5,1.002182,-0.2006274,60.555065,0,11.076097,247.41589,-0.013275089,12.935035,11.076395,246.10794,-9.3567486
83.6,1.0094768,-0.20448779,60.573788,0,11.076097,250.7159,-0.01353392,13.035657,11.075671,249.41508,-9.3550186
84.7,1.0104996,-0.20679165,60.796211,0,11.076097,254.0159,-0.013715097,13.032195,11.075249,252.64886,-9.3530388
85.8,0.9997856,-0.20914538,61.009258,0,11.076097,257.31616,-0.013862069,12.894306,11.07595,256.03909,-9.3508377
86.9,1.002558,-0.21260002,61.046154,0,11.076097,260.61615,-0.014050266,12.962285,11.077115,259.48801,-9.3493328
88.0,0.99842936,-0.21631972,61.018166,0,11.076097,263.91589,-0.014321816,12.906073,11.07553,262.9332,-9.3473167
89.1,1.0029012,-0.21983813,61.018425,0,11.076097,267.21585,-0.014538809,12.967955,11.075823,266.30771,-9.3456802
90.2,0.99758863,-0.22334056,61.237789,0,11.076097,270.5159,-0.014794024,12.896489,11.076867,269.561,-9.343152
91.3,0.9959783,-0.22636075,61.287495,0,11.076097,273.81589,-0.014985499,12.872941,11.076197,272.88141,-9.3415947
92.4,1.0119337,-0.22982164,61.468498,0,11.076097,277.11591,-0.015182462,13.079731,11.076514,276.15445,-9.3402405
93.5,1.0132116,-0.23440897,61.468582,0,11.076097,280.41592,-0.015501712,13.093167,11.076422,279.53314,-9.3383904
94.6,1.013184,-0.23727994,61.688229,0,11.076097,283.71591,-0.015693394,13.101799,11.076523,282.81342,-9.3372831
95.7,0.99816698,-0.23890911,61.701164,0,11.076097,287.01593,-0.015815707,12.916584,11.076677,286.09937,-9.3352251
96.8,0.99723995,-0.2424399,61.907955,0,11.076097,290.31592,-0.016042776,12.887373,11.076684,289.32181,-9.3328905
97.9,1.0030259,-0.24600786,62.112301,0,11.076097,293.61594,-0.016250556,12.971386,11.077357,292.49557,-9.3310442
99.0,1.0033376,-0.24912982,62.320267,0,11.076097,296.91592,-0.016480092,12.980789,11.07652,295.73447,-9.3291588
100.1,1.0008236,-0.25285548,62.262947,0,11.076097,299.99542,-0.016713757,12.949052,11.076238,299.01721,-9.3277178
101.2,1.0065458,-0.2558499,60.225899,0,11.076097,299.99905,-0.016920255,13.037502,11.076932,302.12784,-9.3278046
102.3,1.0128999,-0.25821254,57.955276,0,11.076097,299.99905,-0.017084504,13.103899,11.076394,304.70255,-9.3277931
103.4,1.0055324,-0.25720027,56.124138,0,11.076097,299.99905,-0.016983865,13.022448,11.07615,306.16928,-9.3277445
104.5,0.98669857,-0.25739229,54.363655,0,11.076097,299.99905,-0.01700327,12.783563,11.076369,306.96133,-9.3276949
105.6,0.97859567,-0.25772768,52.978451,0,11.076097,299.99905,-0.017028894,12.683843,11.075843,307.16711,-9.3273497
106.7,0.97210413,-0.25791305,51.933388,0,11.076097,299.99905,-0.017064998,12.601823,11.07657,306.89728,-9.3272791
107.8,0.96260774,-0.25742045,51.196293,0,11.076097,299.99905,-0.017029623,12.467531,11.0755,306.448,-9.3270283
108.9,0.95257163,-0.25733989,50.763676,0,11.076097,299.99905,-0.016997499,12.33836,11.076141,305.72318,-9.327117
110.0,0.94791722,-0.25716326,50.438236,0,11.076097,299.99905,-0.016996002,12.289135,11.07663,304.95737,-9.3271942
111.1,0.9578203,-0.25664765,50.541157,0,11.076097,299.99905,-0.01695746,12.412974,11.075288,304.02454,-9.327033
112.2,0.94154084,-0.25785556,50.82275,0,11.076097,299.99905,-0.017044634,12.197001,11.076674,303.18457,-9.3270607
113.3,0.88485336,-0.2569387,50.916634,0,11.076097,299.99905,-0.017004501,11.455007,11.076362,302.46133,-9.3270807
114.4,0.80042034,-0.2565656,51.196285,0,11.076097,299.99905,-0.016947657,10.362802,11.075686,301.85135,-9.3273621
115.5,0.69642997,-0.25791091,51.569683,0,11.076097,299.99905,-0.017035376,9.0210037,11.076648,301.24228,-9.3273745
116.6,0.62290609,-0.25879547,51.784222,0,11.076097,299.99905,-0.017105591,8.0487728,11.076201,300.80072,-9.3271828
117.7,0.57199723,-0.25948048,52.283787,0,11.076097,299.99905,-0.017159577,7.4070506,11.075147,300.33481,-9.326642
118.8,0.54057682,-0.25993231,52.635494,0,11.076097,299.99905,-0.017194478,7.0101843,11.076204,299.8573,-9.3268785
119.9,0.52598917,-0.26074758,52.97607,0,11.076097,299.99905,-0.017220886,6.8184185,11.0762,299.62747,-9.3264799
121.0,0.51628661,-0.26112837,53.31665,0,11.076097,299.99905,-0.017243255,6.6863408,11.076536,299.23605,-9.3263826
122.1,0.50681925,-0.26291353,53.65723,0,11.076097,299.99905,-0.017364014,6.560812,11.076313,299.11249,-9.3261566
123.2,0.50883359,-0.26186118,53.975826,0,11.076097,299.99905,-0.017319195,6.5896516,11.076564,298.91223,-9.3263988
124.3,0.50922799,-0.26177332,54.134098,0,11.076097,299.99905,-0.017321955,6.6015563,11.075018,298.88068,-9.3264256
125.4,0.49307162,-0.26269558,54.443855,0,11.076097,299.99905,-0.017364509,6.3819623,11.076445,298.85992,-9.326211
126.5,0.48810697,-0.26339141,54.513573,0,11.076097,299.99905,-0.017392166,6.3366365,11.075615,298.92871,-9.3262157
127.6,0.49386263,-0.26400566,54.623985,0,11.076097,299.99905,-0.017443512,6.4015484,11.076305,299.08621,-9.3263626
128.7,0.48789248,-0.26457107,54.604237,0,11.076097,299.99905,-0.017485771,6.3250237,11.075306,299.27328,-9.326519
129.8,0.48596832,-0.26494527,54.460571,0,11.076097,299.99905,-0.017525585,6.3100553,11.075633,299.46417,-9.3262939
130.9,0.48375899,-0.26566529,54.305855,0,11.076097,299.99905,-0.017556231,6.2474666,11.07666,299.6665,-9.3262386
132.0,0.48699951,-0.26709694,54.305424,0,11.076097,299.99905,-0.01763472,6.3109245,11.075921,299.82849,-9.3264513
133.1,0.48485008,-0.26793435,54.002182,0,11.076097,299.99905,-0.017700624,6.2859745,11.076645,300.02618,-9.3260899
134.2,0.48326948,-0.26742026,53.979889,0,11.076097,299.99905,-0.017679911,6.2561359,11.076854,300.07001,-9.325861
135.3,0.48862058,-0.26703009,54.067379,0,11.076097,299.99905,-0.017667465,6.3273048,11.074878,300.01382,-9.3257732
136.4,0.4821313,-0.26727185,54.097988,0,11.076097,299.99905,-0.017664058,6.2463856,11.075976,300.01239,-9.3256989
137.5,0.47573841,-0.26798058,53.975834,0,11.076097,299.99905,-0.017689379,6.1650567,11.076163,300.02194,-9.3257456
138.6,0.47975293,-0.27036956,58.575996,0,11.076097,299.99905,-0.017860746,6.2255306,11.075698,295.1022,-9.3250484
139.7,0.48247287,-0.27210632,58.590641,0,11.076097,299.99905,-0.017965436,6.2533851,11.075864,295.82956,-9.3250628
140.8,0.48100954,-0.27393785,58.118649,0,11.076097,299.99905,-0.018126005,6.2265253,11.076636,297.18408,-9.3253212
141.9,0.47976896,-0.27556163,57.262886,0,11.076097,299.99905,-0.018214475,6.2120671,11.076534,298.6257,-9.3252249
143.0,0.47954088,-0.27702028,56.460297,0,11.076097,299.99905,-0.018271549,6.2245359,11.075562,299.77869,-9.3252163
144.1,0.47323033,-0.27719659,55.843842,0,11.076097,299.99905,-0.018314088,6.12115,11.076624,300.63998,-9.3252029
145.13,0.48650768,-0.011954494,55.239906,0,11.076097,299.99905,-0.00079510314,6.186738,11.075976,301.1008,-9.3252649
145.2819,0.47412264,0.045431547,55.239258,0,11.076099,6.0810235e-10,0.0032481151,5.96768,11.072172,301.27234,-9.3268023
145.2841,0.46817294,0.04489959,43.638432,0,11.076099,6.0736003e-25,0.0028285594,5.9203839,11.076717,301.24716,-9.3250532
145.2863,0.53491533,0.047086406,31.485792,0,11.076099,6.066193e-40,0.0033180402,6.657958,11.077055,301.22012,-9.3239546
145.2885,0.46895584,0.050312798,19.333157,0,11.076099,0.0,0.0030811902,5.9221444,11.076746,301.19312,-9.3241682
145.2907,0.46992841,0.044162974,7.1805224,0,11.076099,0.0,0.0032298942,5.9450951,11.074509,301.16608,-9.3260069
145.2929,0.46754694,0.046879694,0.0,0,11.076099,0.0,0.0029155097,5.995451,11.076304,301.14182,-9.3259249
145.2951,0.46628729,0.045056317,0.0,0,11.076099,0.0,0.0032640682,5.9518962,11.077614,301.12155,-9.3254213
145.2973,0.46695703,0.049861949,0.0,0,11.076099,0.0,0.0029903317,5.8878312,11.077312,301.10129,-9.3240223
145.2995,0.46476185,0.04410864,0.0,0,11.076099,0.0,0.0031210987,5.901082,11.075256,301.08102,-9.3237782
145.3017,0.45836374,0.046291284,0.0,0,11.076099,0.0,0.0028770578,5.9075875,11.078133,301.06076,-9.3243761
145.3039,0.46652547,0.042468391,0.0,0,11.076099,0.0,0.0031851309,5.9667101,11.076517,301.09299,-9.3248138
145.3061,0.47463554,0.050001364,0.0,0,11.076099,0.0,0.0029391083,6.018991,11.077734,301.13354,-9.3251066
145.3083,0.47335351,0.043780547,0.0,0,11.076099,0.0,0.0031389671,5.9217591,11.076017,301.17407,-9.3255816
145.3105,0.4689467,0.04729943,0.0,0,11.076099,0.0,0.002995335,5.8413305,11.076443,301.2146,-9.3247929
145.3127,0.45980868,0.042141259,0.0,0,11.076099,0.0,0.0031293721,5.7436037,11.078444,301.24011,-9.3260736
145.3149,0.4694142,0.050145842,0.0,0,11.076099,0.0,0.003024614,5.8747039,11.077595,301.23334,-9.3254175
145.3171,0.45224819,0.042463724,0.0,0,11.076099,0.0,0.003013839,5.6500998,11.074946,301.22659,-9.324152
145.3193,0.46392229,0.045490131,0.0,0,11.076099,0.0,0.0028603175,5.8764315,11.075289,301.21985,-9.3247728
145.3215,0.45506728,0.042554859,0.0,0,11.076099,0.0,0.003036727,5.7690029,11.075702,301.21307,-9.3254271
145.3237,0.45053467,0.052140798,0.0,0,11.076099,0.0,0.0032162275,5.7829928,11.07683,301.19589,-9.3259163
145.3259,0.44952068,0.042504482,0.0,0,11.076099,0.0,0.003018135,5.6954594,11.076476,301.17563,-9.3248129
145.3281,0.45369282,0.045241933,0.0,0,11.076099,0.0,0.0029368482,5.8460279,11.074792,301.15533,-9.3253546
145.3303,0.45650142,0.042521272,0.0,0,11.06375,0.0,0.0029718766,5.7466354,11.076651,301.13507,-9.3252249
145.3325,0.4542495,0.048522569,0.0,0,10.735804,0.0,0.0030986951,5.7487636,11.077308,301.11633,-9.3252563
145.3347,0.46424088,0.043895967,0.0,0,10.404912,0.0,0.002996726,5.8589187,11.07027,301.10281,-9.3255548
145.3369,0.46124756,0.045653559,0.0,0,10.074019,0.0,0.0030910866,5.9388928,11.011808,301.08932,-9.3254976
145.3391,0.4742882,0.04368747,0.0,0,9.7431259,0.0,0.0029274481,5.9887276,10.820732,301.07581,-9.3257189
145.3413,0.48382688,0.048267186,0.0,0,9.4141245,0.0,0.0031336374,6.1462078,10.523113,301.06229,-9.3239536
145.3435,0.45231959,0.04406723,0.0,0,9.0922194,0.0,0.0029032207,5.6428761,10.122014,302.04971,-9.3250446
145.3457,7.5911856,0.36879843,0.0,0,8.7703152,0.0,0.024135502,94.177574,9.6949463,303.50412,-9.3195801
145.3479,9.6239338,0.71893162,0.0,0,8.4631796,0.0,0.048828773,116.25664,9.2569551,304.95856,-9.3188019
145.3501,10.396382,1.1235837,0.0,0,8.1570272,0.0,0.077765487,121.92096,8.838541,306.41299,-9.3175917
145.3523,10.6746,1.4624104,0.0,0,7.8607621,0.0,0.10185686,122.91405,8.5122957,307.84357,-9.3158455
145.3545,11.211329,1.7356064,0.0,0,7.5694823,0.0,0.12264469,125.99628,8.2005539,309.12314,-9.3161011
145.3567,11.420402,2.0355265,0.0,0,7.2837911,0.0,0.1451741,125.83624,7.8957944,310.40271,-9.317297
145.3589,11.655504,2.3138511,0.0,0,7.0067663,0.0,0.16739337,125.59298,7.6302166,311.68231,-9.3161316
145.3611,12.004824,2.5674047,0.0,0,6.7313552,0.0,0.18706438,126.7494,7.3615322,312.96188,-9.3167629
145.3633,12.305852,2.8322847,0.0,0,6.4677901,0.0,0.20904548,127.13562,7.0922656,313.34216,-9.3159285
145.3655,12.599799,3.0973668,0.0,0,6.2042303,0.0,0.23060182,127.30973,6.823247,313.09998,-9.3164768
145.3677,13.002533,3.3659596,0.0,0,5.9515843,0.0,0.25394735,128.26189,6.5534611,312.85776,-9.3168964
145.3699,13.323252,3.6356659,0.0,0,5.7009163,0.0,0.27670673,128.59283,6.2826467,312.61557,-9.3168621
145.3721,13.65076,3.8973558,0.0,0,5.4572425,0.0,0.30083707,128.62137,6.0164375,312.30865,-9.3163033
145.3743,13.994882,4.1582437,0.0,0,5.2187629,0.0,0.32385543,128.79176,5.7550721,310.64401,-9.3157072
145.3765,14.30256,4.4112978,0.0,0,4.9837937,0.0,0.34829763,128.50174,5.4937868,308.9794,-9.3172789
145.3787,14.625874,4.6675763,0.0,0,4.7569737,0.0,0.3717663,128.37032,5.2436962,307.31476,-9.3182554
145.3809,14.961765,4.905045,0.0,0,4.5305662,0.0,0.39605463,128.14487,4.9998174,305.65015,-9.3178186
145.3831,15.285192,5.1443114,0.0,0,4.314692,0.0,0.4191516,127.92776,4.7594519,304.05298,-9.3174438
145.3853,15.656432,5.3706508,0.0,0,4.0989161,0.0,0.44344744,127.82513,4.5284491,302.52325,-9.3181334
145.3875,16.046568,5.5985351,0.0,0,3.89112,0.0,0.46606255,128.09833,4.3091674,300.99353,-9.3174782
145.3897,16.416473,5.8053894,0.0,0,3.685904,0.0,0.48952711,128.05771,4.0970998,299.46384,-9.3176899
145.3919,16.784481,6.0179768,0.0,0,3.4855118,0.0,0.51197684,128.0024,3.887635,297.93411,-9.3157406
145.3941,17.202753,6.2191939,0.0,0,3.2902839,0.0,0.53575039,128.1411,3.680016,297.68408,-9.3154001
145.3963,17.633718,6.4310007,0.0,0,3.097054,0.0,0.55851436,128.35631,3.4752934,297.49493,-9.3156853
145.3985,18.110058,6.6221848,0.0,0,2.9113297,0.0,0.58265835,128.68848,3.275912,297.30579,-9.3156967
145.4007,18.604385,6.8262606,0.0,0,2.725606,0.0,0.60619026,129.09332,3.0814891,297.11664,-9.3157568
145.4029,19.136097,7.0149484,0.0,0,2.5483792,0.0,0.63066643,129.57671,2.8823757,296.41553,-9.3158092
145.4051,19.691189,7.2127824,0.0,0,2.3717194,0.0,0.65434653,130.20294,2.6969476,294.97504,-9.3159418
145.4073,20.284307,7.3885446,0.0,0,2.2007928,0.0,0.67842484,130.97147,2.5132267,293.53458,-9.3145638
145.4095,20.86581,7.57304,0.0,0,2.0327568,0.0,0.70208591,131.61195,2.3317711,292.09409,-9.3152256
145.4117,21.478121,7.7418361,0.0,0,1.8679291,0.0,0.72598487,132.24571,2.1561317,290.65359,-9.3151283
145.4139,22.112856,7.9217968,0.0,0,1.7080772,0.0,0.74989635,132.92326,1.9851698,289.18851,-9.3142776
145.4161,22.799774,8.0776434,0.0,0,1.5491575,0.0,0.77325404,133.91597,1.8193886,287.71948,-9.3141165
145.4183,23.518902,8.244647,0.0,0,1.3970906,0.0,0.79690272,134.88885,1.6593269,286.25049,-9.3138056
145.4205,24.269526,8.3963394,0.0,0,1.2450265,0.0,0.82029438,135.97523,1.5011209,284.78149,-9.3128405
145.4227,25.073507,8.5562353,0.0,0,1.0992578,0.0,0.84430546,137.13998,1.3462719,284.0191,-9.3122959
145.4249,25.923254,8.6962566,0.0,0,0.95462978,0.0,0.86672169,138.62756,1.1977643,284.77057,-9.3126278
145.4271,26.792923,8.8410664,0.0,0,0.81406713,0.0,0.88970971,140.05354,1.0560426,285.522,-9.3117924
145.4293,27.687052,8.9738874,0.0,0,0.67652315,0.0,0.91145897,141.57878,0.91218585,286.27347,-9.3111286
145.4315,28.613094,9.1158895,0.0,0,0.54098004,0.0,0.93560529,142.86008,0.77488047,287.02493,-9.3110609
145.4337,29.567839,9.2443647,0.0,0,0.41007999,0.0,0.95716745,144.47508,0.64024323,288.01767,-9.3106861
145.4359,30.561296,9.371995,0.0,0,0.27941972,0.0,0.98019707,145.95355,0.51165944,289.08136,-9.3106728
145.4381,29.108349,9.4239111,0.0,0,0.15488653,0.0,0.98921859,137.7794,0.42050806,290.14505,-9.3114243
145.4403,27.621395,9.4466162,0.0,0,0.030410519,0.0,0.99421734,130.26694,0.38177136,291.20874,-9.3120489
145.4425,26.79438,9.4437122,0.0,0,-0.091737911,0.0,0.99250132,126.45628,0.34907103,292.31012,-9.3131266
145.4447,26.70225,9.4463358,0.0,0,-0.2131339,0.0,0.99427772,125.77773,0.30879185,293.53955,-9.3139019
145.4469,26.692543,9.4553299,0.0,0,-0.33452991,0.0,0.99470806,125.69823,0.25423372,294.76901,-9.3133907
145.4491,26.715603,9.4665766,0.0,0,-0.45592591,0.0,0.99803793,125.36768,0.19663459,295.99844,-9.3163157
145.4513,26.684179,9.4728785,0.0,0,-0.57732189,0.0,0.99729258,125.29289,0.14317189,297.22791,-9.3153811
145.4535,26.576506,9.4706488,0.0,0,-0.69871783,0.0,0.99882543,124.61971,0.088867046,298.96674,-9.3161774
145.4557,26.387371,9.4798975,0.0,0,-0.82011384,0.0,0.99873292,123.77305,0.04640767,300.94327,-9.3162279
145.4579,26.123455,9.4834661,0.0,0,-0.94150984,0.0,1.0014777,122.23141,0.010143209,302.91977,-9.3157015
145.4601,25.768826,9.4895592,0.0,0,-1.0629059,0.0,1.0001211,120.76113,-0.013160163,304.89627,-9.3161631
145.4623,25.324476,9.4832449,0.0,0,-0.84330958,300.0,1.0013289,118.46613,-0.025090264,306.7886,-9.3169765
145.4645,24.789839,9.4880638,0.0,0,-0.42303047,300.0,1.0001175,116.14836,-0.025577122,308.14792,-9.3175335
145.4667,24.306274,9.4848604,0.0,0,-0.0027509974,300.0,1.0020101,113.65695,-0.024381757,309.50726,-9.3176661
145.4689,23.895243,9.49471,0.0,0,0.41752785,300.0,1.000857,111.8597,-0.016487092,310.86658,-9.317565
145.4711,23.563841,9.4864569,0.0,0,0.837807,300.0,1.0020493,110.20386,-0.014433511,312.22589,-9.3177013
145.4733,23.295275,9.4933205,0.0,0,1.2580868,300.0,1.0009794,109.03973,-0.014726139,313.38226,-9.3181295
145.4755,22.479031,9.4853945,0.0,0,1.6783655,300.0,1.001826,105.21545,0.0045192335,314.39816,-9.319665
145.4777,20.844439,9.4893818,0.0,0,2.0986445,300.0,1.0000315,97.827003,0.073972456,315.41403,-9.3214388
145.4799,17.524977,9.4704094,0.0,0,2.518924,300.0,0.99901503,82.60907,0.20352247,316.42993,-9.3236151
145.4821,12.059644,9.4567404,0.0,0,2.9392033,300.0,0.99454445,57.7341,0.40919358,317.44727,-9.3257761
145.4843,0.56224757,9.2185993,0.0,0,3.3594825,300.0,0.95530266,2.4577799,0.79435325,318.49472,-9.3385229
145.4865,-0.19454372,9.0561247,0.0,0,3.7797613,300.0,0.92487645,-0.47473365,1.4392083,319.54214,-9.3374453
145.4887,-0.1595521,8.9034243,0.0,0,4.2000408,300.0,0.90154397,-0.90948313,2.212954,320.5896,-9.339407
145.4909,0.13447638,8.7914581,0.0,0,4.6203198,300.0,0.88173151,0.79453075,2.9147902,321.63705,-9.3374071
145.4931,-0.22164525,8.7333088,0.0,0,5.0405993,300.0,0.87358081,-1.080881,3.4582679,322.44577,-9.3369856
145.4953,-0.16037859,8.7182379,0.0,0,5.4608784,300.0,0.86983335,-0.90349126,3.8752222,323.01578,-9.3362923
145.4975,0.023317058,8.7228661,0.0,0,5.8811579,300.0,0.87162721,0.11385686,4.2619081,323.58578,-9.334938
145.4997,-0.062182244,8.7829876,0.0,0,6.3014374,300.0,0.88003016,-0.31426197,4.6387177,324.15582,-9.3328943
145.5019,0.014977003,8.8503046,0.0,0,6.7217159,300.0,0.89188778,0.13538876,5.018847,324.72583,-9.3318052
145.5041,-0.11585188,8.9672403,0.0,0,7.1419959,300.0,0.90974492,-0.53887683,5.4129381,322.63434,-9.330637
145.5063,-0.082970165,9.0833073,0.0,0,7.5622745,300.0,0.93037122,-0.46115553,5.8260846,320.41629,-9.3309059
145.5085,0.019211115,9.2359619,0.0,0,7.9825544,300.0,0.95568693,0.067260921,6.2676978,318.19821,-9.3309641
145.5107,-0.064741582,9.4059486,0.0,0,8.402833,300.0,0.98581636,-0.17225599,6.7166634,315.98013,-9.3313951
145.5129,-0.16059901,9.4264174,0.0,0,8.8231115,300.0,0.99066573,-0.89600176,7.1605716,314.14456,-9.3293991
145.5151,-0.22815612,9.409586,0.0,0,9.243391,300.0,0.98779559,-1.0290391,7.5957665,312.86142,-9.3279858
145.5173,0.1124543,9.4226685,0.0,0,9.6636705,300.0,0.98964173,0.3094359,8.0357304,311.57828,-9.3284311
145.5195,0.0298809,9.4397945,0.0,0,10.08395,300.0,0.99172598,0.24796547,8.4734926,310.29514,-9.3273878
145.5217,-0.079950117,9.4433527,0.0,0,10.504229,300.0,0.99308342,-0.37610704,8.9034634,309.01199,-9.3272924
145.5239,-0.21915193,9.4413939,0.0,0,10.924508,300.0,0.99223918,-1.0065117,9.3344994,309.13339,-9.3268967
145.5261,0.021760719,9.4397516,0.0,0,11.344788,300.0,0.99299163,0.012516772,9.7681684,309.47653,-9.3272352
145.5283,0.04093042,9.4329424,0.0,0,11.765066,300.0,0.99069196,0.2618559,10.211851,309.81964,-9.3266487
145.5305,-0.10609891,9.4402952,0.0,0,12.185346,300.0,0.99317557,-0.439262,10.637737,310.16275,-9.3259516
145.5327,-0.16027234,9.4346104,0.0,0,12.605625,300.0,0.99067044,-0.86538565,11.063997,310.30673,-9.3246746
145.5349,0.054465,9.4333391,0.0,0,13.025904,300.0,0.99194813,0.17049628,11.486897,310.02417,-9.3265533
145.5371,0.077485248,9.437005,0.0,0,13.446183,300.0,0.99113744,0.33937505,11.909142,309.74161,-9.3244781
145.5393,-0.037623115,9.4357319,0.0,0,13.866463,300.0,0.99271393,-0.10435629,12.330284,309.45905,-9.3250599
145.5415,-0.16616443,9.4402924,0.0,0,14.286742,300.0,0.99124134,-0.77321774,12.752902,309.17648,-9.3249092
145.5437,-0.043563131,9.433774,0.0,0,14.707021,300.0,0.99226248,-0.23809381,13.190627,309.71017,-9.325633
145.5459,-0.055538796,9.4347229,0.0,0,15.1273,300.0,0.99055952,-0.19651872,13.626904,310.48386,-9.3248806
145.5481,-0.057864442,9.4304695,0.0,0,15.54758,300.0,0.99199337,-0.25985223,14.071534,311.25754,-9.3238335
145.5503,-0.16276693,9.4377556,0.0,0,15.967858,300.0,0.99079353,-0.69394517,14.505172,312.03122,-9.3232327
145.5525,-0.10396456,9.4349899,0.0,0,16.388138,300.0,0.99265438,-0.57906359,14.934068,312.74374,-9.3233948
145.5547,0.066903926,9.4335718,0.0,0,16.808418,300.0,0.99045163,0.29218143,15.354582,313.24832,-9.3240089
145.5569,0.032798756,9.4280634,0.0,0,17.228697,300.0,0.99158454,0.17174141,15.769987,313.7529,-9.3245668
145.5591,-0.027087571,9.4392653,0.0,0,17.648977,300.0,0.99090099,-0.036557622,16.178255,314.25748,-9.3229389
145.5613,-0.094352454,9.4308634,0.0,0,17.999975,300.0,0.99198961,-0.45114997,16.584608,314.76205,-9.3238087
145.5635,-0.077811874,9.4365444,0.0,0,18.0,300.0,0.99088496,-0.43190643,17.006765,314.89047,-9.3238573
145.5657,-0.0090127308,9.4299841,0.0,0,18.0,300.0,0.99189645,-0.062454566,17.40531,314.84335,-9.3239241
145.5679,-0.066433363,9.4435101,0.0,0,18.0,300.0,0.99159676,-0.336346,17.762613,314.79626,-9.3237972
145.5701,-0.074846067,9.4327011,0.0,0,18.0,300.0,0.99215037,-0.43034485,18.082691,314.74918,-9.3254337
145.5723,-0.045922365,9.4371338,0.0,0,18.0,300.0,0.99111229,-0.22290027,18.3288,314.63968,-9.3278761
145.5745,-0.016087122,9.4355707,0.0,0,18.0,300.0,0.99285161,-0.10902791,18.483873,314.1351,-9.3324194
145.5767,-0.00039541634,9.452816,0.0,0,18.0,300.0,0.99352241,-0.0030142199,18.534584,313.63052,-9.3366861
145.5789,-0.050174274,9.4510736,0.0,0,18.0,300.0,0.99529636,-0.20859562,18.476805,313.12595,-9.3424931
145.5811,-0.10278489,9.4672127,0.0,0,18.0,300.0,0.99649197,-0.4766182,18.360851,312.62137,-9.3507566
145.5833,-0.10051775,9.471097,0.0,0,18.0,300.0,0.99858981,-0.47479668,18.225056,312.13269,-9.3632393
145.5855,-0.10651758,9.4939928,0.0,0,18.0,300.0,1.0015312,-0.48505834,18.120146,311.65503,-9.378231
145.5877,-0.12176755,9.5008974,0.0,0,18.0,300.0,1.0040953,-0.59221888,18.054523,311.17737,-9.3944712
145.5899,-0.065949894,9.5216789,0.0,0,18.0,300.0,1.0068471,-0.39658847,18.033922,310.69971,-9.4121275
145.5921,0.035235062,9.5333662,0.0,0,18.0,300.0,1.0097911,0.083974548,18.030468,310.27744,-9.4297762
145.5943,0.059294879,9.5592241,0.0,0,18.0,300.0,1.0137222,0.28830531,18.048122,311.01749,-9.4478521
145.5965,0.0058076954,9.5698938,0.0,0,18.0,300.0,1.0162265,0.059943624,18.070141,311.75754,-9.465064
145.5987,-0.035316139,9.5887938,0.0,0,18.0,300.0,1.0194702,-0.093278259,18.097233,312.49759,-9.4810457
145.6009,-0.09483923,9.6026344,0.0,0,18.0,300.0,1.0221405,-0.36800241,18.116356,313.23761,-9.4981241
145.6031,-0.17392339,9.6282864,0.0,0,18.0,300.0,1.0267715,-0.77859598,18.135141,314.14914,-9.5136404
145.6053,-0.16073795,9.6375046,0.0,0,18.0,300.0,1.0282537,-0.73585474,18.139402,315.23209,-9.5293188
145.6075,-0.075786218,9.65413,0.0,0,18.0,300.0,1.0318987,-0.41808665,18.143961,316.31506,-9.5454636
145.6097,0.02238722,9.6626806,0.0,0,18.0,300.0,1.0331137,0.014645795,18.139906,317.39801,-9.5601053
145.6119,0.05888414,9.6859655,0.0,0,18.0,300.0,1.0381435,0.22297062,18.140368,318.48099,-9.5752134
145.6141,0.048856772,9.6999836,0.0,0,18.0,300.0,1.0395648,0.21285853,18.135328,318.20905,-9.5911856
145.6163,-0.0018793001,9.7127867,0.0,0,18.0,300.0,1.0431544,0.058666222,18.137531,317.87265,-9.6057558
145.6185,-0.076416709,9.7288036,0.0,0,18.0,300.0,1.0450567,-0.31074345,18.13154,317.53625,-9.6218863
145.6207,-0.14207806,9.7462597,0.0,0,18.0,300.0,1.0500292,-0.59547216,18.128706,317.19986,-9.638278
145.6229,-0.15883729,9.7635489,0.0,0,18.0,300.0,1.0513824,-0.69633669,18.127375,316.60757,-9.6544504
145.6251,-0.12245892,9.7750521,0.0,0,18.0,300.0,1.0554285,-0.59385478,18.123413,315.64572,-9.669322
145.6273,-0.0085821049,9.7910404,0.0,0,18.0,300.0,1.0566996,-0.13305615,18.120386,314.68387,-9.6861105
145.6295,0.056316145,9.8048449,0.0,0,18.0,300.0,1.0615302,0.21744356,18.119404,313.72202,-9.702035
145.6317,0.064822331,9.8250132,0.0,0,18.0,300.0,1.0629703,0.3212615,18.114777,312.76013,-9.7169905
145.6339,0.019883566,9.8359566,0.0,0,18.0,300.0,1.0673523,0.10826026,18.11338,313.05902,-9.7332773
145.6361,-0.059282538,9.8560705,0.0,0,18.0,300.0,1.0689584,-0.17550011,18.111261,313.55688,-9.7487125
145.6383,-0.121409,9.8679333,0.0,0,18.0,300.0,1.0736939,-0.45556977,18.107426,314.05472,-9.7655096
145.6405,-0.151012,9.8933668,0.0,0,18.0,300.0,1.0760285,-0.67286229,18.103094,314.55258,-9.7817469
145.6427,-0.14413193,9.8991671,0.0,0,18.0,300.0,1.0801899,-0.64761198,18.105448,314.91125,-9.7975273
145.6449,-0.065895014,9.9199457,0.0,0,18.0,300.0,1.0815845,-0.37976983,18.104784,314.97183,-9.813076
145.6471,0.043382768,9.9286661,0.0,0,18.0,300.0,1.0858812,0.13216394,18.10088,315.03238,-9.8298912
145.6493,0.073252276,9.9530067,0.0,0,18.0,300.0,1.087453,0.27802175,18.103519,315.09293,-9.8442593
145.6515,0.031419974,9.9582748,0.0,0,18.0,300.0,1.0915117,0.17489831,18.102062,315.15347,-9.8594246
145.6537,-0.033240885,9.9819098,0.0,0,18.0,300.0,1.0938406,-0.052161992,18.101236,315.81006,-9.8763075
145.6559,-0.10008767,9.9926624,0.0,0,18.0,300.0,1.0984787,-0.38737211,18.100868,316.64188,-9.8921833
145.6581,-0.16446759,10.020573,0.0,0,18.0,300.0,1.1013846,-0.63395143,18.102993,317.47369,-9.9080439
145.6603,-0.15523708,10.025812,0.0,0,18.0,300.0,1.1048335,-0.67467695,18.103531,318.30551,-9.9234991
145.6625,-0.093679979,10.044816,0.0,0,18.0,300.0,1.1068046,-0.46681067,18.101725,319.38785,-9.9397993
145.6647,-0.006841043,10.056277,0.0,0,18.0,300.0,1.1110139,-0.057368815,18.09967,321.32169,-9.9561148
145.6669,0.068389148,10.08159,0.0,0,18.0,300.0,1.1140548,0.27694848,18.101389,323.25552,-9.9725227
145.6691,0.065250702,10.084929,0.0,0,18.0,300.0,1.1166757,0.28383937,18.102215,325.18936,-9.987052
145.6713,-0.001078086,10.110784,0.0,0,18.0,300.0,1.1201639,0.0558897,18.100752,327.12317,-10.002569
145.6735,-0.081572652,10.122028,0.0,0,18.0,300.0,1.1240047,-0.28716716,18.097084,327.98526,-10.01949
145.6757,-0.15274741,10.150163,0.0,0,18.0,300.0,1.1282254,-0.56913579,18.09831,328.34732,-10.035624
145.6779,-0.16460811,10.15273,0.0,0,18.0,300.0,1.1300298,-0.69715571,18.098146,328.70938,-10.051631
145.6801,-0.11674568,10.170737,0.0,0,18.0,300.0,1.1329459,-0.56648743,18.095068,329.07144,-10.067184
145.6823,-0.030597908,10.180348,0.0,0,18.0,300.0,1.1353816,-0.1738372,18.0954,329.37952,-10.082659
145.6845,0.045716349,10.203275,0.0,0,18.0,300.0,1.1397767,0.15891017,18.091606,329.34601,-10.098511
145.6867,0.079227269,10.212671,0.0,0,18.0,300.0,1.142205,0.31894091,18.093441,329.31247,-10.112105
145.6889,0.038343791,10.235158,0.0,0,18.0,300.0,1.146955,0.21309555,18.091379,329.27896,-10.129641
145.6911,-0.04958462,10.247562,0.0,0,18.0,300.0,1.1491642,-0.14026971,18.08997,329.24542,-10.144286
145.6933,-0.13396546,10.267509,0.0,0,18.0,300.0,1.1536962,-0.49379268,18.091543,329.03757,-10.160051
145.6955,-0.16636337,10.278893,0.0,0,18.0,300.0,1.1553403,-0.6546973,18.09053,328.70905,-10.176747
145.6977,-0.13844275,10.296228,0.0,0,18.0,300.0,1.1601191,-0.58711118,18.088608,328.38052,-10.19268
145.6999,-0.064512447,10.308566,0.0,0,18.0,300.0,1.1615644,-0.30153701,18.088501,328.05197,-10.209495
145.7021,0.023815336,10.327911,0.0,0,18.0,300.0,1.167161,0.02784517,18.086323,327.68683,-10.22603
145.7043,0.065400623,10.341113,0.0,0,18.0,300.0,1.168272,0.25547618,18.086636,326.55347,-10.241426
145.7065,0.068683133,10.355033,0.0,0,18.0,300.0,1.1729729,0.26976129,18.084444,325.42014,-10.256838
145.7087,-0.0018397326,10.372099,0.0,0,18.0,300.0,1.1748822,0.044188395,18.084366,324.28677,-10.272614
145.7109,-0.10613448,10.390767,0.0,0,18.0,300.0,1.1810434,-0.36549699,18.084345,323.15341,-10.288292
145.7131,-0.16324471,10.411193,0.0,0,18.0,300.0,1.1830965,-0.60341412,18.08223,322.57672,-10.305156
145.7153,-0.14709593,10.419195,0.0,0,18.0,300.0,1.1874259,-0.58866692,18.078506,322.55661,-10.32068
145.7175,-0.090071708,10.438456,0.0,0,18.0,300.0,1.1891494,-0.37059581,18.082378,322.5365,-10.337136
145.7197,-0.0057972278,10.452568,0.0,0,18.0,300.0,1.1947997,-0.06490095,18.078423,322.51639,-10.352918
145.7219,0.064687915,10.471365,0.0,0,18.0,300.0,1.1961987,0.21453382,18.081614,322.49628,-10.369148
145.7241,0.066737078,10.478142,0.0,0,18.0,300.0,1.2005261,0.25892308,18.075977,323.38525,-10.383433
145.7263,0.038110122,10.499437,0.0,0,18.0,300.0,1.2024003,0.17758866,18.077209,324.31744,-10.399106
145.7285,-0.072439462,10.51089,0.0,0,18.0,300.0,1.2079898,-0.20135114,18.080881,325.24966,-10.412994
145.7307,-0.15734127,10.53847,0.0,0,18.0,300.0,1.2104783,-0.54194415,18.074492,326.18185,-10.431232
145.7329,-0.17189866,10.546717,0.0,0,18.0,300.0,1.2160815,-0.62985808,18.074253,326.78479,-10.447276
145.7351,-0.12507036,10.56672,0.0,0,18.0,300.0,1.2175723,-0.50184345,18.078302,326.91217,-10.462804
145.7373,-0.041638289,10.574542,0.0,0,18.0,300.0,1.2223339,-0.22365069,18.081215,327.03955,-10.478376
145.7395,0.030522203,10.59711,0.0,0,18.0,300.0,1.2239335,0.079815917,18.071136,327.16696,-10.493244
145.7417,0.063767567,10.599562,0.0,0,18.0,300.0,1.2276715,0.21128093,18.072279,327.29434,-10.509596
145.7439,0.047239095,10.624687,0.0,0,18.0,300.0,1.2308679,0.19201609,18.073124,327.26538,-10.526569
145.7461,-0.019868042,10.634319,0.0,0,18.0,300.0,1.2358929,-0.019979937,18.074451,327.21176,-10.54206
145.7483,-0.12141429,10.663705,0.0,0,18.0,300.0,1.2393121,-0.39410421,18.070047,327.15811,-10.558928
145.7505,-0.18531565,10.668991,0.0,0,18.0,300.0,1.2435317,-0.65866238,18.070591,327.10449,-10.574917
145.7527,-0.14816552,10.694059,0.0,0,18.0,300.0,1.2469308,-0.58483219,18.069256,326.91644,-10.590824
145.7549,-0.05500976,10.698932,0.0,0,18.0,300.0,1.2502227,-0.25611839,18.07011,326.4404,-10.605443
145.7571,0.022632848,10.72283,0.0,0,18.0,300.0,1.2536854,0.040016316,18.066795,325.96436,-10.621349
145.7593,0.062548645,10.727194,0.0,0,18.0,300.0,1.2566153,0.19727993,18.067396,325.48831,-10.637424
145.7615,0.065633088,10.750173,0.0,0,18.0,300.0,1.2604495,0.26414597,18.066685,325.01227,-10.651062
145.7637,0.020408873,10.759853,0.0,0,18.0,300.0,1.2640125,0.10881499,18.070972,324.6088,-10.666687
145.7659,-0.074998789,10.789346,0.0,0,18.0,300.0,1.2694527,-0.21998844,18.065859,324.22662,-10.683168
145.7681,-0.15994674,10.796616,0.0,0,18.0,300.0,1.2724893,-0.53214967,18.068228,323.84445,-10.700099
145.7703,-0.17560746,10.81903,0.0,0,18.0,300.0,1.2771877,-0.60745323,18.061865,323.46228,-10.717296
145.7725,-0.081537157,10.8241,0.0,0,18.0,300.0,1.2787769,-0.35057032,18.067917,323.03268,-10.733106
145.7747,0.0041577523,10.846576,0.0,0,18.0,300.0,1.2841541,-0.034711387,18.067322,322.44193,-10.749055
145.7769,0.046981145,10.858006,0.0,0,18.0,300.0,1.2867614,0.16366373,18.065647,321.85114,-10.763319
145.7791,0.054144509,10.875805,0.0,0,18.0,300.0,1.2916347,0.21138558,18.067886,321.26035,-10.777431
145.7813,0.048107002,10.887125,0.0,0,18.0,300.0,1.293294,0.17661598,18.066648,320.66959,-10.793794
145.7835,-0.03707492,10.909906,0.0,0,18.0,300.0,1.2999818,-0.060512222,18.063959,320.22562,-10.809923
145.7857,-0.14495607,10.92242,0.0,0,18.0,300.0,1.3018886,-0.44020432,18.061264,319.85016,-10.826994
145.7879,-0.17985825,10.940667,0.0,0,18.0,300.0,1.3076192,-0.61631888,18.06628,319.47467,-10.842863
145.7901,-0.13122703,10.952035,0.0,0,18.0,300.0,1.3090248,-0.51013196,18.065374,319.09921,-10.8578
145.7923,-0.022910571,10.969616,0.0,0,18.0,300.0,1.315454,-0.14551029,18.057398,318.79791,-10.874949
145.7945,0.048240319,10.986693,0.0,0,18.0,300.0,1.3171515,0.12642349,18.063761,318.96609,-10.890539
145.7967,0.06102721,10.997364,0.0,0,18.0,300.0,1.3222547,0.19734018,18.062761,319.13431,-10.907182
145.7989,0.050405193,11.015782,0.0,0,18.0,300.0,1.3245097,0.19344814,18.059732,319.30249,-10.922598
145.8011,0.0039784811,11.0302,0.0,0,18.0,300.0,1.3309872,0.056016844,18.057709,319.4707,-10.938956
145.8033,-0.107189,11.052011,0.0,0,18.0,300.0,1.3330553,-0.27664211,18.060064,319.72968,-10.954453
145.8055,-0.1780135,11.062842,0.0,0,18.0,300.0,1.3391246,-0.54650134,18.054001,320.05148,-10.970632
145.8077,-0.15429553,11.081413,0.0,0,18.0,300.0,1.3406978,-0.53349,18.054226,320.37332,-10.986435
145.8099,-0.072014607,11.093165,0.0,0,18.0,300.0,1.3473209,-0.28717044,18.057972,320.69513,-11.002546
145.8121,0.026423015,11.114145,0.0,0,18.0,300.0,1.3485702,0.043141495,18.056185,321.02368,-11.01784
145.8143,0.071076065,11.117367,0.0,0,18.0,300.0,1.3533998,0.21860451,18.056166,321.49319,-11.033584
145.8165,0.052819535,11.141132,0.0,0,18.0,300.0,1.3559836,0.17815414,18.051533,321.96271,-11.046432
145.8187,0.025659297,11.152498,0.0,0,18.0,300.0,1.3627795,0.10819189,18.050793,322.43222,-11.063024
145.8209,-0.072379284,11.179771,0.0,0,18.0,300.0,1.3653132,-0.14354344,18.052883,322.90173,-11.080763
145.8231,-0.1518482,11.184041,0.0,0,18.0,300.0,1.3704603,-0.45502961,18.052307,323.27728,-11.097072
145.8253,-0.17529088,11.210116,0.0,0,18.0,300.0,1.3741807,-0.57924104,18.053801,323.5589,-11.114484
145.8275,-0.10833303,11.219215,0.0,0,18.0,300.0,1.3799012,-0.41144955,18.050663,323.84052,-11.128189
145.8297,0.00045639236,11.244771,0.0,0,18.0,300.0,1.3826612,-0.049349274,18.051918,324.1221,-11.144619
145.8319,0.069041945,11.247176,0.0,0,18.0,300.0,1.3871349,0.20267621,18.052261,324.40372,-11.160381
145.8341,0.06701602,11.266627,0.0,0,18.0,300.0,1.3894377,0.22515373,18.051386,324.90933,-11.175726
145.8363,0.032404382,11.274718,0.0,0,18.0,300.0,1.3944328,0.10937727,18.05039,325.4256,-11.191995
145.8385,-0.03962411,11.306803,0.0,0,18.0,300.0,1.399826,-0.085112251,18.052153,325.94186,-11.207556
145.8407,-0.12705596,11.311996,0.0,0,18.0,300.0,1.4039725,-0.34446079,18.053238,326.4581,-11.22303
145.8429,-0.17612061,11.331838,0.0,0,18.0,300.0,1.4072585,-0.53423887,18.051163,326.7796,-11.240215
145.8451,-0.14480716,11.340346,0.0,0,18.0,300.0,1.4118646,-0.4919222,18.052244,326.81985,-11.254543
145.8473,-0.037836004,11.364582,0.0,0,18.0,300.0,1.4162605,-0.16460964,18.051378,326.86008,-11.271049
145.8495,0.050562944,11.371423,0.0,0,18.0,300.0,1.4200563,0.11609693,18.05088,326.9003,-11.286229
145.8517,0.082619287,11.391954,0.0,0,18.0,300.0,1.4242138,0.21908152,18.04842,326.94052,-11.300984
145.8539,0.056667086,11.398602,0.0,0,18.0,300.0,1.4271911,0.18674426,18.047499,326.37851,-11.315972
145.8561,-0.011239773,11.425406,0.0,0,18.0,300.0,1.4335315,0.0069389022,18.052612,325.72147,-11.333058
145.8583,-0.093435101,11.434292,0.0,0,18.0,300.0,1.4369757,-0.23604766,18.050297,325.06439,-11.348639
145.8605,-0.15144883,11.456509,0.0,0,18.0,300.0,1.4432405,-0.41365057,18.048203,324.40732,-11.365634
146.7608,-0.052848563,11.568454,0.0,0,18.0,1.6216689e-10,1.4751019,-0.14869063,18.001665,319.66013,-11.483859
147.8608,-0.047973987,11.568391,0.0,0,18.0,1.6196843e-25,1.4750684,-0.13814513,18.000252,309.67743,-11.482872
148.9608,-0.047967073,11.568833,0.0,0,18.0,1.617701e-40,1.4751741,-0.13984272,18.000677,301.90063,-11.483661
150.0608,-0.055112131,11.568723,0.0,0,18.0,1.4012985e-45,1.4751737,-0.1619681,18.000586,295.77145,-11.483885
151.1608,-0.050929967,11.569036,0.0,0,18.0,1.4012985e-45,1.4750525,-0.14775935,18.000349,289.07639,-11.483898
152.2608,-0.05079297,11.569146,0.0,0,18.0,1.4012985e-45,1.4752343,-0.14872758,17.999744,283.35242,-11.484097
153.3608,-0.051617198,11.568973,0.0,0,18.0,1.4012985e-45,1.4752609,-0.15270294,17.999729,276.89267,-11.483405
154.4608,-0.054983191,11.569107,0.0,0,18.0,1.4012985e-45,1.4752159,-0.16145164,17.999405,270.44086,-11.483405
155.5608,-0.057745267,11.569284,0.0,0,18.0,1.4012985e-45,1.4753072,-0.16977273,18.000685,264.28436,-11.483464
156.6608,-0.051307868,11.569859,0.0,0,18.0,1.4012985e-45,1.4753379,-0.14645596,18.000271,258.89224,-11.483608
157.7608,-0.048216809,11.56982,0.0,0,18.0,1.4012985e-45,1.4753904,-0.14090607,18.001745,252.93871,-11.484079
158.8608,-0.055879068,11.569859,0.0,0,18.0,1.4012985e-45,1.4755691,-0.16297495,18.001444,247.63373,-11.484006
159.9608,-0.059357546,11.570115,0.0,0,18.0,1.4012985e-45,1.4755036,-0.1699003,17.999666,241.75082,-11.483856
161.0608,-0.053774301,11.569889,0.0,0,18.0,1.4012985e-45,1.4755433,-0.15343882,18.000757,236.31633,-11.4834
162.1608,-0.052041698,11.57002,0.0,0,18.0,1.4012985e-45,1.4754305,-0.15080579,18.000635,230.57152,-11.483635
163.2608,-0.059253711,11.57035,0.0,0,18.0,1.4012985e-45,1.4754977,-0.17360391,18.000362,225.89149,-11.483232
164.3608,-0.057482395,11.570469,0.0,0,18.0,1.4012985e-45,1.4757252,-0.16612382,18.000343,220.80363,-11.483221
165.4608,-0.058330853,11.5705,0.0,0,18.0,1.4012985e-45,1.4756912,-0.16961396,17.999561,215.65173,-11.483073
166.5608,-0.053471155,11.571088,0.0,0,18.0,1.4012985e-45,1.47583,-0.15946305,17.999559,210.23062,-11.483344
167.6608,-0.055072401,11.571548,0.0,0,18.0,1.4012985e-45,1.4759383,-0.16525637,18.000698,205.15738,-11.483343
168.7608,-0.05934396,11.571467,0.0,0,18.0,1.4012985e-45,1.4758086,-0.16988584,17.999983,200.73219,-11.4835
169.8608,-0.057606153,11.571474,0.0,0,18.0,1.4012985e-45,1.4759705,-0.16470291,17.999922,196.40491,-11.483423
170.9608,-0.054832917,11.571773,0.0,0,18.0,1.4012985e-45,1.4760714,-0.16255035,18.000584,191.88855,-11.483096
172.0608,-0.061521444,11.572623,0.0,0,18.0,1.4012985e-45,1.4762563,-0.17938156,18.000357,187.44083,-11.483406
173.1608,-0.059199754,11.572616,0.0,0,18.0,1.4012985e-45,1.4763153,-0.16945048,18.000643,183.2216,-11.483664
174.2608,-0.057095144,11.572788,0.0,0,18.0,1.4012985e-45,1.4761994,-0.16231628,18.000822,179.02504,-11.483305
175.3608,-0.056768551,11.572929,0.0,0,18.0,1.4012985e-45,1.4763422,-0.16873647,18.000858,174.89381,-11.483784
176.4608,-0.060736883,11.572964,0.0,0,18.0,1.4012985e-45,1.476444,-0.18028337,17.999781,171.09349,-11.483497
177.5608,-0.068547979,11.572907,0.0,0,18.0,1.4012985e-45,1.4762987,-0.19955963,18.000116,167.05341,-11.483013
178.6608,-0.05977428,11.573242,0.0,0,18.0,1.4012985e-45,1.4765056,-0.1737626,17.999039,162.74236,-11.483189
179.7608,-0.059840009,11.573172,0.0,0,18.0,1.4012985e-45,1.4763283,-0.17106135,18.000086,159.13789,-11.482822
180.8608,-0.061589498,11.573239,0.0,0,18.0,1.4012985e-45,1.4763801,-0.1831914,18.000616,155.18004,-11.482924
181.9608,-0.061598089,11.573515,0.0,0,18.0,1.4012985e-45,1.4766383,-0.17753445,18.000088,150.72014,-11.482861
183.0608,-0.060608748,11.574016,0.0,0,18.0,1.4012985e-45,1.4766523,-0.17407171,18.000246,145.58763,-11.482906
184.1608,-0.056650963,11.573905,0.0,0,18.0,1.4012985e-45,1.4766881,-0.163277,18.000175,138.42656,-11.48273
185.2608,-0.063796096,11.574232,0.0,0,18.0,1.4012985e-45,1.4766773,-0.18621163,17.99979,133.75598,-11.482641
186.3608,-0.066144824,11.574481,0.0,0,18.0,1.4012985e-45,1.476693,-0.19186379,17.999632,130.4736,-11.482208
187.4608,-0.063881367,11.574126,0.0,0,18.0,1.4012985e-45,1.4767907,-0.18381871,18.00012,127.27754,-11.482542
188.5608,-0.057988986,11.574674,0.0,0,18.0,1.4012985e-45,1.4768955,-0.16905706,18.000347,124.07929,-11.482526
189.6608,-0.062434737,11.575117,0.0,0,18.0,1.4012985e-45,1.4769962,-0.17910144,17.999199,121.05758,-11.482451
190.7608,-0.061046049,11.575043,0.0,0,18.0,1.4012985e-45,1.4769831,-0.17348793,17.999374,117.02103,-11.482767
191.8608,-0.057638481,11.575618,0.0,0,18.0,1.4012985e-45,1.4770101,-0.16656466,17.999851,112.75311,-11.48249
192.9608,-0.062937133,11.57509,0.0,0,18.0,1.4012985e-45,1.4770226,-0.18573079,17.999308,110.6926,-11.482219
194.0608,-0.06333258,11.575079,0.0,0,18.0,1.4012985e-45,1.4770215,-0.18469806,18.000237,108.64272,-11.482457
195.1608,-0.066685908,11.575592,0.0,0,18.0,1.4012985e-45,1.4770942,-0.19761847,17.999744,106.78488,-11.482506
196.2608,-0.062645771,11.576145,0.0,0,18.0,1.4012985e-45,1.4773638,-0.18149246,18.0002,104.50928,-11.482454
197.3608,-0.058790114,11.576305,0.0,0,18.0,1.4012985e-45,1.4771992,-0.17045702,18.000431,102.50649,-11.482578
198.4608,-0.060042273,11.576385,0.0,0,18.0,1.4012985e-45,1.4773291,-0.17838445,18.000948,100.68982,-11.482757
199.5608,-0.06417226,11.576851,0.0,0,18.0,1.4012985e-45,1.477586,-0.18638307,17.99979,98.921349,-11.482717
200.6608,-0.062595792,11.576747,0.0,0,18.0,1.4012985e-45,1.4774522,-0.18051893,18.001276,97.153969,-11.482955
201.7608,-0.056904823,11.576912,0.0,0,18.0,1.4012985e-45,1.4776089,-0.16371748,17.999027,95.469925,-11.482852
202.8608,-0.065375671,11.577568,0.0,0,18.0,1.4012985e-45,1.4776169,-0.18908808,18.001137,93.947556,-11.482559
203.9608,-0.066877089,11.577465,0.0,0,18.0,1.4012985e-45,1.4775779,-0.19417486,18.000299,92.010803,-11.483069
205.0608,-0.06241817,11.578014,0.0,0,18.0,1.4012985e-45,1.4779562,-0.18209824,18.00001,90.406975,-11.482763
205.8608,-0.067669474,11.577885,0.0,0,18.0,1.4012985e-45,1.4778821,-0.19412494,17.999668,89.125275,-11.482938