File: examples/hot axisymmetric compression example/data/02 screened data/testID_0141.csv
Time(sec),Force(kN),Jaw(mm),PowAngle(deg),Power(W),Pram,PTemp,Strain,Stress(MPa),Stroke(mm),TC1(C),wedge(mm)
0.0,0.79622734,0.36634052,0.0,0,11.076097,0.0015928604,0.024736173,9.8791466,11.076263,23.755379,-9.1290522
1.2,0.74742913,-0.0026392504,0.0,0,11.076097,3.5159137,-0.00017397004,9.5065613,11.077005,23.751308,-9.4965134
2.4,0.71522361,-0.0028302209,0.0,0,11.076097,7.1159143,-0.00020104436,9.1088696,11.076461,23.676767,-9.4936028
3.6,0.69702941,-0.0028605207,0.0,0,11.076097,10.715916,-0.00018451635,8.8674374,11.075801,23.677906,-9.4921036
4.8,0.67882466,-0.0029067618,0.0,0,11.076097,14.315913,-0.00018333606,8.6516294,11.076559,23.601406,-9.4894457
6.0,0.66332078,-0.0027143057,0.0,0,11.076097,17.915913,-0.000173796,8.4489689,11.076177,23.582268,-9.4874916
7.2,0.65194839,-0.0024646781,0.0,0,11.076097,21.515915,-0.0001764312,8.3054695,11.075682,23.603251,-9.485095
8.4,0.6439355,-0.0026832072,7.7381783,0,11.076097,25.115915,-0.0002088225,8.1906033,11.075397,23.503319,-9.4826288
9.6,0.6397227,-0.0026560584,27.315762,0,11.076097,28.715918,-0.00019747698,8.1424847,11.076268,23.776402,-9.4805355
10.8,0.64629883,-0.0046968288,37.449112,0,11.076097,32.31591,-0.00032501866,8.2303877,11.075204,25.001741,-9.4787359
12.0,0.66143644,-0.0070844567,43.385151,0,11.076097,35.915916,-0.00047326848,8.4127884,11.075279,27.750679,-9.476778
13.2,0.66794503,-0.010343038,46.57235,0,11.076097,39.515923,-0.00066697045,8.4942741,11.07538,31.854183,-9.4745359
14.4,0.6779142,-0.014427494,48.318306,0,11.076097,43.115925,-0.00092870323,8.6474257,11.075872,36.914845,-9.4723978
15.6,0.68270636,-0.018725116,48.670418,0,11.076097,46.715923,-0.0012259041,8.7012854,11.075751,42.555138,-9.4705696
16.8,0.68974775,-0.022397149,47.779797,0,11.076097,50.315918,-0.0014982743,8.799819,11.074697,48.469669,-9.4680662
18.0,0.69231963,-0.025636544,46.582062,0,11.076097,53.915913,-0.0017198188,8.8215714,11.076026,53.861393,-9.4660721
19.2,0.69954848,-0.028555885,45.120861,0,11.076097,57.515911,-0.0018858935,8.9230776,11.075735,58.778961,-9.4640408
20.4,0.69555175,-0.030633079,43.527836,0,11.076097,61.115906,-0.0020269318,8.8668337,11.075999,62.950344,-9.4618092
21.6,0.68816763,-0.032709405,42.396751,0,11.076097,64.715919,-0.0021747062,8.7824631,11.077093,66.445419,-9.459589
22.8,0.68918157,-0.034512445,42.44355,0,11.076097,68.31591,-0.0023151743,8.7997446,11.077078,69.385551,-9.4576054
24.0,0.67782134,-0.036763951,43.407875,0,11.076097,71.915924,-0.0024762081,8.6519156,11.077066,72.104973,-9.455204
25.2,0.68453604,-0.03899391,44.39164,0,11.076097,75.515915,-0.0026090539,8.743391,11.075662,74.81044,-9.4529829
26.4,0.69756675,-0.041148391,45.61422,0,11.076097,79.115929,-0.0027421138,8.9056063,11.076547,77.751961,-9.4511576
27.6,0.69626141,-0.043663081,46.582008,0,11.076097,82.715919,-0.0028871146,8.8884583,11.076701,80.878372,-9.4493608
28.8,0.69752246,-0.046354428,47.686272,0,11.076097,86.315918,-0.0030594456,8.8960123,11.076632,84.27475,-9.446909
30.0,0.71010768,-0.049211066,48.580467,0,11.076097,89.915916,-0.00325924,9.0847445,11.07572,87.917564,-9.4443369
31.2,0.71404499,-0.052052494,49.089272,0,11.076097,93.515923,-0.0034731259,9.1112566,11.076502,91.801285,-9.4424829
32.4,0.71931946,-0.055236336,49.229733,0,11.076097,97.115921,-0.0036770757,9.2044039,11.076321,95.905769,-9.4405899
33.6,0.72264832,-0.058106773,49.229733,0,11.076097,100.71592,-0.0038544293,9.2373886,11.075969,99.918938,-9.4382849
34.8,0.72441757,-0.061397742,49.229733,0,11.076097,104.31593,-0.0040846509,9.2808533,11.075071,103.96124,-9.4359722
36.0,0.73516238,-0.065291472,48.821304,0,11.076097,107.91592,-0.0043660928,9.4085779,11.075808,107.87974,-9.4338503
37.2,0.73724061,-0.068609513,48.740726,0,11.076097,111.5159,-0.0046020453,9.4413061,11.075235,111.8088,-9.4317322
38.4,0.73031139,-0.070485659,48.55711,0,11.076097,115.11591,-0.0047119064,9.3315649,11.076451,115.31052,-9.4294462
39.6,0.73484975,-0.073366836,48.780155,0,11.076097,118.71591,-0.0048836935,9.3953075,11.075852,118.70782,-9.4276505
40.8,0.73457807,-0.076452635,48.874176,0,11.076097,122.31591,-0.0050644479,9.378109,11.075058,122.06205,-9.4254436
42.0,0.74109465,-0.079371616,49.229816,0,11.076097,125.9159,-0.0052498351,9.4839182,11.075321,125.49491,-9.423562
43.2,0.74900758,-0.082641952,49.908928,0,11.076097,129.51601,-0.0054940144,9.5929852,11.076373,128.68042,-9.4215174
44.4,0.74906653,-0.086437322,50.436222,0,11.076097,133.11591,-0.0057487208,9.586216,11.075521,132.08208,-9.4194412
45.6,0.74656868,-0.088317573,50.822605,0,11.076097,136.7159,-0.0058649946,9.5613508,11.075832,135.66432,-9.4170904
46.8,0.75086367,-0.091462933,51.192974,0,11.076097,140.31589,-0.0060732039,9.6058064,11.075481,139.23224,-9.4152374
48.0,0.75948554,-0.094174266,51.561661,0,11.076097,143.91589,-0.0062831766,9.7231236,11.075823,142.90497,-9.4132376
49.2,0.76161599,-0.098431908,51.599056,0,11.076097,147.5159,-0.0065731648,9.7549324,11.075644,146.66591,-9.4110279
50.4,0.75475717,-0.10111617,51.932369,0,11.076097,151.11589,-0.0067335847,9.6595879,11.076202,150.35034,-9.4088383
51.6,0.76720816,-0.10415313,52.003723,0,11.076097,154.7159,-0.0069110272,9.8259077,11.075925,154.05118,-9.4069099
52.8,0.76951265,-0.10746428,52.283936,0,11.076097,158.3159,-0.0071123876,9.8636618,11.076465,157.67998,-9.4052448
54.0,0.76954508,-0.11090053,52.283936,0,11.076097,161.91591,-0.0073364517,9.8631868,11.076455,161.42833,-9.4029875
55.2,0.77010536,-0.11392725,52.284134,0,11.076097,165.5159,-0.0075753639,9.8788023,11.075908,165.15958,-9.4004555
56.4,0.77888483,-0.11723153,52.328938,0,11.076097,169.11591,-0.0077792085,10.005,11.07558,168.83386,-9.3984594
57.6,0.77061033,-0.12035969,52.635494,0,11.076097,172.71591,-0.0079849847,9.8763924,11.075188,172.44035,-9.3964882
58.8,0.77874362,-0.12355442,52.391972,0,11.076097,176.31592,-0.0082201883,10.00625,11.076574,176.21436,-9.3948097
60.0,0.78220963,-0.12780647,52.632874,0,11.076097,179.91591,-0.0085095186,10.062567,11.075296,179.72771,-9.3924828
61.2,0.77585775,-0.12969586,52.635494,0,11.076097,183.51591,-0.0086256396,9.9726706,11.076603,183.44189,-9.3904438
62.4,0.78596252,-0.13239935,52.635662,0,11.076097,187.11592,-0.008782832,10.097601,11.07665,186.90262,-9.3881645
63.6,0.77862692,-0.13600996,52.97607,0,11.076097,190.71593,-0.0089977011,10.002977,11.075088,190.28677,-9.386178
64.8,0.7829873,-0.13886082,53.31665,0,11.076097,194.31592,-0.0091965813,10.07206,11.075663,193.58836,-9.384078
66.0,0.78767955,-0.14316164,53.790115,0,11.076097,197.91591,-0.0094992202,10.12435,11.07708,196.8739,-9.3823366
67.2,0.77992147,-0.14506398,54.305279,0,11.076097,201.51591,-0.009628539,10.03695,11.075611,200.37242,-9.3804684
68.4,0.78413928,-0.14829458,54.567642,0,11.076097,205.11592,-0.0098317247,10.085384,11.076515,204.12558,-9.3779068
69.6,0.77857524,-0.15207653,54.624023,0,11.076097,208.71591,-0.010097983,10.008961,11.075829,207.93839,-9.3758259
70.8,0.7907812,-0.15479368,54.628391,0,11.076097,212.31593,-0.010291444,10.167005,11.075611,211.74059,-9.3736191
72.0,0.79642516,-0.15974958,54.710625,0,11.076097,215.91592,-0.010596341,10.24702,11.076105,215.48814,-9.3722048
73.2,0.787817,-0.16244707,54.805458,0,11.076097,219.51591,-0.010755637,10.130623,11.076684,219.23402,-9.3703222
74.4,0.79307693,-0.16658103,54.931637,0,11.076097,223.11592,-0.011017586,10.204904,11.075688,222.79613,-9.3678131
75.6,0.78559303,-0.16906862,54.931637,0,11.076097,226.71591,-0.011210206,10.120589,11.076929,226.46658,-9.3657322
76.8,0.7921381,-0.17225857,54.931637,0,11.076097,230.3159,-0.011413123,10.194376,11.076353,230.12517,-9.363266
78.0,0.78777701,-0.17591985,54.941204,0,11.076097,233.91591,-0.011646871,10.152104,11.076095,233.66666,-9.3618135
79.2,0.79352438,-0.17903551,55.239136,0,11.076097,237.51593,-0.01188319,10.218113,11.075489,237.21527,-9.3598948
80.4,0.79797232,-0.18269651,55.239254,0,11.076097,241.11591,-0.012128166,10.281267,11.075866,240.84311,-9.3580761
81.6,0.79373246,-0.18617506,55.509701,0,11.076097,244.71591,-0.012345137,10.236019,11.075218,244.30942,-9.3557768
82.8,0.80380088,-0.19110285,55.535885,0,11.076097,248.3159,-0.012645951,10.357933,11.075954,247.832,-9.3534908
84.0,0.79722029,-0.19295022,55.843506,0,11.076097,251.91591,-0.012747372,10.283961,11.076486,251.30061,-9.3517542
85.2,0.80202305,-0.19663444,55.843506,0,11.076097,255.51591,-0.013028829,10.349374,11.075547,255.14105,-9.3503246
86.4,0.78662467,-0.19950518,55.843506,0,11.076097,259.11615,-0.013206547,10.153763,11.075974,258.80377,-9.3476954
87.6,0.79620773,-0.20263767,56.129147,0,11.076097,262.71591,-0.013413857,10.271451,11.076545,262.17117,-9.3455715
88.8,0.79340982,-0.20697072,56.425777,0,11.076097,266.31589,-0.013734191,10.230714,11.076757,265.7178,-9.3434591
90.0,0.79727215,-0.20982054,56.389767,0,11.076097,269.91592,-0.013915109,10.288337,11.076166,269.58408,-9.3412476
91.2,0.81122857,-0.21515483,56.192711,0,11.076097,273.5159,-0.014249668,10.481414,11.076392,273.38574,-9.3399162
92.4,0.78902179,-0.21738037,56.255627,0,11.076097,277.11591,-0.014361491,10.192103,11.076285,276.98608,-9.3376923
93.6,0.79998142,-0.22039618,56.416634,0,11.076097,280.71588,-0.014560485,10.352086,11.07581,280.60333,-9.3354979
94.8,0.7885018,-0.22441293,56.420948,0,11.076097,284.31589,-0.014855724,10.191563,11.075842,284.19083,-9.3332987
96.0,0.80005461,-0.22748758,56.425762,0,11.076097,287.91592,-0.015044445,10.34406,11.074465,287.79929,-9.3309984
97.2,0.81138796,-0.23203431,56.425777,0,11.076097,291.5159,-0.01535836,10.484423,11.076216,291.32202,-9.3295155
98.4,0.80129302,-0.23433164,56.625607,0,11.076097,295.11591,-0.015531746,10.356724,11.075545,294.7941,-9.3272791
99.6,0.80588436,-0.23913909,56.711414,0,11.076097,298.71591,-0.015836518,10.417493,11.075845,298.41318,-9.3250427
100.8,0.79623181,-0.24132779,56.711422,0,11.076097,302.31592,-0.015945965,10.295575,11.075603,302.10376,-9.3233051
102.0,0.80914038,-0.24468413,56.711422,0,11.076097,305.91592,-0.016155325,10.463602,11.076572,305.8078,-9.3207312
103.2,0.79776013,-0.24819218,56.711422,0,11.076097,309.51593,-0.016408814,10.321331,11.076742,309.33963,-9.3191519
104.4,0.80757785,-0.25118223,56.790062,0,11.076097,313.11594,-0.016602991,10.453505,11.075832,312.86743,-9.3173113
105.6,0.7827208,-0.2549502,56.985893,0,11.076097,316.71591,-0.016848281,10.13189,11.075101,316.41922,-9.3151484
106.8,0.80636853,-0.2579551,56.986084,0,11.076097,320.31592,-0.017074661,10.454787,11.076102,320.05096,-9.3128767
108.0,0.80106235,-0.26166615,57.218891,0,11.076097,323.91592,-0.017316543,10.353279,11.076369,323.54895,-9.3108177
109.2,0.8068952,-0.26533169,57.260738,0,11.076097,327.51593,-0.017516011,10.464574,11.076303,327.14816,-9.3090363
110.4,0.80238038,-0.26962402,57.394688,0,11.076097,331.11594,-0.017778011,10.397657,11.075287,330.66443,-9.3070869
111.6,0.80082595,-0.27298388,57.534306,0,11.076097,334.71591,-0.018044375,10.387367,11.076657,334.28046,-9.3050623
112.8,0.81369537,-0.2779229,57.535397,0,11.076097,338.31592,-0.01835187,10.551642,11.076129,337.93372,-9.3031282
114.0,0.80372155,-0.28083086,57.613659,0,11.076097,341.91589,-0.018543888,10.419125,11.075477,341.53738,-9.3009748
115.2,0.81241792,-0.2862516,57.810051,0,11.076097,345.5159,-0.018934315,10.537,11.07592,345.03122,-9.2987108
116.4,0.80043989,-0.28817114,57.999878,0,11.076097,349.11591,-0.01904192,10.407816,11.076167,348.63,-9.2970066
117.6,0.81762677,-0.29373753,57.844334,0,11.076097,352.71588,-0.01938786,10.610531,11.076464,352.42142,-9.2949533
118.8,0.80129033,-0.29630369,58.073727,0,11.076097,356.31589,-0.019530296,10.41096,11.07566,355.95084,-9.2929611
120.0,0.81205559,-0.30018252,58.07365,0,11.076097,359.91418,-0.019818671,10.565341,11.076447,359.7338,-9.2906532
121.2,0.042724721,-0.31249988,56.134441,0,11.076097,359.99924,-0.020613946,0.56116068,11.075162,362.68106,-9.290637
122.4,0.028236642,-0.31300557,53.627769,0,11.076097,359.99924,-0.020646321,0.36986804,11.074892,364.89737,-9.2903395
123.6,0.014661691,-0.31166559,52.283939,0,11.076097,359.99924,-0.02058973,0.18051063,11.076866,364.47748,-9.2907867
124.8,0.021666216,-0.31053707,52.283936,0,11.076097,359.99924,-0.020499727,0.2854037,11.076165,362.75961,-9.2909861
126.0,0.006182258,-0.30929974,53.271652,0,11.076097,359.99924,-0.020393288,0.094061971,11.075571,360.66705,-9.2905941
127.2,0.0059646894,-0.30847755,54.899487,0,11.076097,359.99924,-0.020334421,0.086850211,11.076129,358.2915,-9.2904491
128.4,0.00065914093,-0.30716234,56.899349,0,11.076097,359.99924,-0.020268245,0.018191475,11.075673,356.18835,-9.2901907
129.6,0.0084700948,-0.30749941,58.849525,0,11.076097,359.99924,-0.02029103,0.10725506,11.075493,354.6593,-9.2900448
130.8,0.0092876023,-0.30652192,60.684284,0,11.076097,359.99924,-0.020237952,0.12753689,11.076101,353.599,-9.2907591
132.0,0.02364504,-0.30700952,62.112007,0,11.076097,359.99924,-0.020285733,0.30385324,11.076749,353.53113,-9.2906532
133.2,0.042821266,-0.30762398,62.753696,0,11.076097,359.99924,-0.020295594,0.55172783,11.075627,354.75201,-9.2903566
134.4,0.037475772,-0.31022698,62.754192,0,11.076097,359.99924,-0.02044246,0.4878796,11.075949,356.63498,-9.2902842
135.6,0.055181079,-0.31325713,62.337704,0,11.076097,359.99924,-0.020660521,0.70093161,11.07559,358.68723,-9.2900801
136.8,0.042844687,-0.3137081,61.688255,0,11.076097,359.99924,-0.0206952,0.55616099,11.077127,360.64294,-9.2897596
138.0,0.042024422,-0.31528512,60.558746,0,11.076097,359.99924,-0.020796079,0.52503985,11.075574,362.36563,-9.2897797
139.2,0.051396593,-0.31622756,59.242664,0,11.076097,359.99924,-0.020890331,0.66917318,11.075411,363.56946,-9.2895918
140.4,0.04006334,-0.31704241,57.816807,0,11.076097,359.99924,-0.020930393,0.52391976,11.075245,364.34494,-9.2896824
141.6,0.044247642,-0.31727722,56.711967,0,11.076097,359.99924,-0.020905737,0.56365931,11.076622,364.47522,-9.2901793
142.8,0.036228355,-0.31718302,55.712166,0,11.076097,359.99924,-0.020901661,0.47384137,11.07702,364.06586,-9.2899618
144.0,0.020160835,-0.31680292,55.239307,0,11.076097,359.99924,-0.020908024,0.24985962,11.076409,363.09152,-9.2899227
145.2,0.012580914,-0.31663513,55.535793,0,11.076097,359.99924,-0.020879343,0.15773636,11.075639,361.59293,-9.2898369
146.4,0.014445941,-0.31592375,56.385292,0,11.076097,359.99924,-0.020865394,0.19485942,11.075926,359.9296,-9.2901697
147.6,0.0061500915,-0.31560081,57.530167,0,11.076097,359.99924,-0.02084133,0.082863778,11.077186,358.22525,-9.2898273
148.8,0.0068644811,-0.31570348,58.853096,0,11.076097,359.99924,-0.020807734,0.092347719,11.075878,356.70609,-9.2896347
150.0,0.0085532963,-0.31583917,60.313591,0,11.076097,359.99924,-0.020812066,0.1230901,11.076313,355.62515,-9.2892151
151.2,0.021503527,-0.31559539,61.554184,0,11.076097,359.99924,-0.020827832,0.27840218,11.075101,355.20114,-9.289587
152.4,0.045170881,-0.31634277,62.116692,0,11.076097,359.99924,-0.020854056,0.58501595,11.075488,355.84326,-9.2894411
153.6,0.058894616,-0.31784412,61.909176,0,11.076097,359.99924,-0.02099419,0.76083231,11.075873,357.81442,-9.2892876
154.8,0.052038573,-0.31994921,61.149837,0,11.076097,359.99924,-0.021123908,0.67445815,11.075042,360.11932,-9.2892408
156.0,0.058520664,-0.32272673,60.097572,0,11.076097,359.99924,-0.021267714,0.74991643,11.076858,361.91428,-9.2891951
157.2,0.05637056,-0.3223404,58.862026,0,11.076097,359.99924,-0.021237427,0.72652215,11.076546,363.24121,-9.2892408
158.4,0.046796851,-0.32294789,57.541687,0,11.076097,359.99924,-0.021305019,0.61314934,11.075869,364.00241,-9.2889347
159.6,0.045815725,-0.32301691,56.427608,0,11.076097,359.99924,-0.021293808,0.59988248,11.076627,364.05869,-9.2888222
160.8,0.028518211,-0.3229073,55.541138,0,11.076097,359.99924,-0.021327354,0.36243361,11.076763,363.7547,-9.2891502
162.0,0.022402078,-0.323304,55.239262,0,11.076097,359.99924,-0.021345595,0.27753571,11.075634,362.74673,-9.2884617
163.2,0.0062865233,-0.32266796,55.793037,0,11.076097,359.99924,-0.021256495,0.09164498,11.075691,361.10596,-9.2884789
164.4,0.0091900667,-0.32268238,56.710766,0,11.076097,359.99924,-0.021267014,0.10836256,11.076839,359.2587,-9.2887802
165.2814,0.13373412,0.032246031,0.0,0,11.076099,2.5664899,0.0022636214,1.843981,11.076865,358.00259,-9.2890596
165.2838,0.12848216,0.033720147,0.0,0,11.076099,1.1094927999999999e-16,0.0021454089,1.659959,11.074559,357.97363,-9.2893753
165.2862,0.13767551,0.034683384,0.0,0,11.076099,4.7963354e-33,0.0021645122,1.7063689,11.072963,357.94464,-9.2901611
165.2886,0.14891303,0.034644868,0.0,0,11.076099,0.0,0.0022784055,1.8651562,11.077291,357.91568,-9.2902622
165.291,0.13694274,0.032217681,0.0,0,11.076099,0.0,0.0023236806,1.7987069,11.072313,357.88669,-9.2893438
165.2934,0.12418357,0.032490451,0.0,0,11.076099,0.0,0.0023815911,1.66066,11.075178,357.89755,-9.2908239
165.2958,0.13941245,0.034901954,0.0,0,11.076099,0.0,0.002310293,1.7626879,11.076854,357.91205,-9.290616
165.2982,0.15307061,0.038335744,0.0,0,11.076099,0.0,0.0023177685,1.9773173,11.072814,357.92654,-9.2898607
165.3006,0.15456863,0.039061014,0.0,0,11.076099,0.0,0.0023800426,1.8974189,11.07321,357.94101,-9.2895384
165.303,0.14117955,0.036509786,0.0,0,11.076099,0.0,0.0025138985,1.7610399,11.070536,357.95551,-9.2887917
165.3054,0.13647532,0.033653606,0.0,0,11.076099,0.0,0.0025041625,1.7783751,11.075099,357.97,-9.2885475
165.3078,0.1472595,0.032342635,0.0,0,11.076099,0.0,0.0023591609,1.8976177,11.077765,357.9845,-9.2892075
165.3102,0.16080454,0.034118872,0.0,0,11.076099,0.0,0.0021826881,2.1936214,11.0741,357.99896,-9.2896051
165.3126,0.15681151,0.03680801,0.0,0,11.076099,0.0,0.0022227126,2.0320072,11.073254,357.99353,-9.2901011
165.315,0.14627181,0.036503725,0.0,0,11.076099,0.0,0.002388288,1.8885326,11.076451,357.9718,-9.2888727
165.3174,0.155094,0.035495769,0.0,0,11.076099,0.0,0.0024629887,1.9441365,11.073456,357.95007,-9.2897263
165.3198,0.16795893,0.034737512,0.0,0,11.076099,0.0,0.0024658372,2.0811415,11.074197,357.92834,-9.2900667
165.3222,0.15858254,0.034424026,0.0,0,11.076099,0.0,0.0023432027,1.9866419,11.079203,357.91193,-9.2906599
165.3246,0.15405318,0.038979974,0.0,0,11.076099,0.0,0.0023500405,1.9681239,11.074921,357.90469,-9.2906809
165.327,0.14870168,0.041467011,0.0,0,11.076099,0.0,0.002508234,1.8416522,11.075925,357.89743,-9.2905893
165.3294,0.17355388,0.039503004,0.0,0,11.076099,0.0,0.002683433,2.0744069,11.074409,357.8902,-9.2895861
165.3318,0.16613078,0.035855852,0.0,0,10.976468,0.0,0.0026199431,2.2044327,11.076548,357.88828,-9.2880888
165.3342,0.15428434,0.034055036,0.0,0,10.615494,0.0,0.0024370844,2.0251243,11.077192,357.91,-9.2887793
165.3366,0.15935495,0.034300964,0.0,0,10.254521,0.0,0.0021875929,2.023932,11.056134,357.93173,-9.2885885
165.339,0.20701738,0.036912631,0.0,0,9.8935471,0.0,0.0022937867,2.5923629,10.928646,357.95346,-9.2894459
165.3414,0.17137934,0.036011297,0.0,0,9.5325737,0.0,0.0023223709,2.2330954,10.643259,357.97519,-9.2887182
165.3438,0.20717627,0.034396574,0.0,0,9.1800261,0.0,0.0023646872,2.6937015,10.239683,359.08328,-9.2902222
165.3462,6.9048162,0.35445711,0.0,0,8.8288574,0.0,0.023088818,85.976791,9.7863255,360.19141,-9.2833652
165.3486,8.4773407,0.7594291,0.0,0,8.491025,0.0,0.051861852,102.04094,9.3044529,361.2995,-9.2837934
165.351,8.8993797,1.1750528,0.0,0,8.1570406,0.0,0.080887631,104.26102,8.8569288,362.40759,-9.2833319
165.3534,8.9638863,1.5712762,0.0,0,7.8342953,0.0,0.10992184,102.09029,8.4801531,363.39169,-9.283144
165.3558,9.3441448,1.8866926,0.0,0,7.5165353,0.0,0.13403283,104.19419,8.1436501,364.34793,-9.2830029
165.3582,9.5685863,2.1796441,0.0,0,7.2082515,0.0,0.15700446,103.97697,7.8265533,365.3042,-9.2830725
165.3606,9.8120518,2.4795136,0.0,0,6.9060431,0.0,0.18056858,104.31137,7.5222554,366.26047,-9.2835512
165.363,10.027951,2.7645967,0.0,0,6.6115613,0.0,0.20329946,104.1311,7.2306404,366.76212,-9.2836237
165.3654,10.328493,3.0469935,0.0,0,6.3240414,0.0,0.22635587,104.87312,6.9457507,367.00061,-9.2822361
165.3678,10.550919,3.3261223,0.0,0,6.042748,0.0,0.25015411,104.48589,6.6575766,367.23907,-9.2816572
165.3702,10.813875,3.6112723,0.0,0,5.7692914,0.0,0.27528778,104.45078,6.3721585,367.47757,-9.2824841
165.3726,11.101121,3.8931537,0.0,0,5.5006132,0.0,0.30047756,104.56747,6.0894318,366.80353,-9.2829952
165.375,11.394669,4.1764226,0.0,0,5.2404532,0.0,0.32598802,104.65922,5.8014731,365.01419,-9.2820272
165.3774,11.637017,4.4602733,0.0,0,4.9838037,0.0,0.35211504,104.18021,5.5207591,363.22482,-9.2826424
165.3798,11.90571,4.7354069,0.0,0,4.7363639,0.0,0.37831873,103.778,5.2436357,361.43549,-9.2828798
165.3822,12.17924,5.003006,0.0,0,4.4912457,0.0,0.40532532,103.33994,4.9786739,359.57101,-9.2832842
165.3846,12.517095,5.2601585,0.0,0,4.2558532,0.0,0.43191278,103.42848,4.7138996,357.5,-9.2832365
165.387,12.790253,5.5107589,0.0,0,4.0217257,0.0,0.45785004,103.01716,4.4604273,355.42899,-9.283309
165.3894,13.07993,5.7557626,0.0,0,3.7978492,0.0,0.48341486,102.686,4.2148943,353.35797,-9.2837391
165.3918,13.405991,5.9949765,0.0,0,3.5743496,0.0,0.50942963,102.49725,3.9782736,351.51627,-9.283453
165.3942,13.768173,6.2245417,0.0,0,3.3612847,0.0,0.53548133,102.55202,3.7459922,352.19724,-9.2825613
165.3966,14.142567,6.4447947,0.0,0,3.1483085,0.0,0.56128949,102.68231,3.5259507,352.8782,-9.2822418
165.399,14.518862,6.6563783,0.0,0,2.9451063,0.0,0.586748,102.77208,3.3105166,353.55917,-9.2816801
165.4014,14.929197,6.8706903,0.0,0,2.7424982,0.0,0.61222345,103.05173,3.0969436,354.24014,-9.2822638
165.4038,15.371442,7.0852189,0.0,0,2.5483871,0.0,0.63815618,103.35168,2.8891721,351.6257,-9.2821856
165.4062,15.876677,7.2934566,0.0,0,2.3556671,0.0,0.6646291,103.91651,2.6848943,348.64508,-9.280756
165.4086,16.370958,7.4916859,0.0,0,2.170248,0.0,0.69137478,104.40082,2.4822161,345.66446,-9.2801189
165.411,16.868637,7.6841769,0.0,0,1.986936,0.0,0.71823752,104.70287,2.2822466,342.68387,-9.2797852
165.4134,17.43655,7.8694386,0.0,0,1.8098083,0.0,0.7439158,105.45782,2.096873,338.30518,-9.2798138
165.4158,18.043451,8.056263,0.0,0,1.6354243,0.0,0.76964062,106.32847,1.9097973,333.37375,-9.2808533
165.4182,18.694897,8.2405462,0.0,0,1.4662172,0.0,0.79591179,107.30142,1.7278996,328.44232,-9.2800255
165.4206,19.347942,8.4175243,0.0,0,1.3003292,0.0,0.82282221,108.11942,1.5511864,323.51086,-9.2796888
165.423,20.014389,8.5872068,0.0,0,1.1387082,0.0,0.84983838,108.88924,1.3780422,318.89188,-9.2796412
165.4254,20.75341,8.7523661,0.0,0,0.98093224,0.0,0.87625796,109.95948,1.2079455,314.54623,-9.2787361
165.4278,21.5597,8.9134302,0.0,0,0.82657719,0.0,0.90183443,111.31428,1.0430071,310.20059,-9.2783318
165.4302,22.387941,9.074111,0.0,0,0.67652929,0.0,0.92754519,112.68694,0.88278872,305.85495,-9.2773485
165.4326,23.226871,9.2310734,0.0,0,0.52908581,0.0,0.95393395,113.84669,0.73040527,303.24503,-9.2772989
165.435,24.127638,9.3771973,0.0,0,0.38628578,0.0,0.980483,115.17865,0.57584476,303.85864,-9.2769861
165.4374,22.104376,9.424716,0.0,0,0.24542005,0.0,0.99098945,104.57014,0.47266304,304.47226,-9.2799377
165.4398,20.32391,9.4331961,0.0,0,0.10962804,0.0,0.99246407,96.048889,0.42816162,305.08588,-9.2814512
165.4422,19.539537,9.4423161,0.0,0,-0.025516469,0.0,0.99277419,92.242416,0.39860812,306.42105,-9.2830706
165.4446,19.183672,9.4530926,0.0,0,-0.15794852,0.0,0.99389249,90.399269,0.36184627,311.36407,-9.2833414
165.447,19.31357,9.4588833,0.0,0,-0.29038054,0.0,0.99528486,90.901093,0.3087548,316.3071,-9.2836456
165.4494,19.500509,9.4625149,0.0,0,-0.42281252,0.0,0.99689448,91.628586,0.24528974,321.25012,-9.2824612
165.4518,19.554863,9.463582,0.0,0,-0.55524451,0.0,0.99791652,91.782982,0.17596382,326.19315,-9.2823057
165.4542,19.495182,9.4699888,11.946348,0,-0.68767649,0.0,0.99842888,91.482048,0.11720927,328.48764,-9.2818689
165.4566,19.295729,9.4823961,24.095213,0,-0.82010847,0.0,0.99916446,90.497955,0.06561204,330.73724,-9.2822943
165.459,19.000933,9.4894857,36.24408,0,-0.95254052,0.0,1.0000521,89.016106,0.024544235,332.98682,-9.2815933
165.4614,18.60129,9.4926548,48.392944,0,-1.0849725,0.0,1.0014832,87.052063,-0.0011703352,335.23642,-9.2815361
165.4638,18.091785,9.4895096,50.822754,0,-0.72870666,359.99997,1.002288,84.608131,-0.0089778882,337.01794,-9.2823572
165.4662,17.566788,9.4826918,50.822754,0,-0.27022031,359.99997,1.0013716,82.224922,-0.0051583368,338.68243,-9.2839556
165.4686,17.119038,9.4820337,50.822754,0,0.18826602,359.99997,0.99995047,80.203377,-0.0037001278,340.34695,-9.2849216
165.471,16.702267,9.4904261,50.822754,0,0.64675242,359.99997,1.0004712,78.233833,0.0023953828,342.01144,-9.2859583
165.4734,16.39477,9.4903259,48.683411,0,1.105239,359.99997,1.0007634,76.771606,0.0016498645,343.57199,-9.2846756
165.4758,15.87756,9.4900923,45.21418,0,1.5637254,359.99997,1.0020609,74.250648,0.0088482657,345.0679,-9.2856369
165.4782,14.162569,9.4817314,41.744953,0,2.0222118,359.99997,1.0012605,66.498466,0.084105,346.56381,-9.2874556
165.4806,11.344248,9.4725637,38.275726,0,2.4806983,359.99997,0.99912566,53.445911,0.21891633,348.05972,-9.287961
165.483,7.1714473,9.4584656,36.309814,0,2.9391847,359.99997,0.9951961,34.144432,0.4322412,349.30511,-9.2915154
165.4854,0.13797712,9.338459,36.309814,0,3.3976712,359.99997,0.97375166,0.52568972,0.8219111,350.22287,-9.2990131
165.4878,-0.18357848,9.2229748,36.309814,0,3.8561575,359.99997,0.95379472,-0.70074719,1.5754286,351.14066,-9.2970886
165.4902,-0.10167328,9.1272602,36.309814,0,4.3146439,359.99997,0.93884867,-0.56912464,2.401639,352.05844,-9.2972412
165.4926,-0.065191045,9.0555286,34.863213,0,4.7731299,359.99997,0.92675561,-0.40051791,3.1138496,353.18045,-9.2985487
165.495,0.080749698,9.0259027,26.183575,0,5.2316165,359.99997,0.92078197,0.42150325,3.6347153,355.32373,-9.2969103
165.4974,-0.14699942,9.0437355,17.503937,0,5.6901031,359.99997,0.92273647,-0.63623601,4.0645804,357.46698,-9.2954626
165.4998,-0.061164148,9.0674753,8.8243008,0,6.1485891,359.99997,0.92688572,-0.45411009,4.4741845,359.61026,-9.2955408
165.5022,-0.038364165,9.111927,0.14466472,0,6.6070752,359.99997,0.93527013,-0.19536443,4.9009299,361.75351,-9.2941074
165.5046,-0.076229773,9.1724596,0.0,0,7.0655622,359.99997,0.9464938,-0.33560529,5.3351917,363.70444,-9.2945518
165.507,-0.094416827,9.2548752,0.0,0,7.5240488,359.99997,0.96002835,-0.41969499,5.7835841,365.65207,-9.2926989
165.5094,0.025511419,9.3534508,0.0,0,7.9825354,359.99997,0.97610211,0.10099408,6.2704291,367.5997,-9.2928886
165.5118,-0.14385061,9.4731255,0.0,0,8.441021,359.99997,0.99661154,-0.61459088,6.7516289,369.54736,-9.2920151
165.5142,-0.061068624,9.4430418,0.0,0,8.8995075,359.99997,0.99254966,-0.45294797,7.2412047,369.97159,-9.2917547
165.5166,0.041621946,9.435689,0.0,0,9.3579931,359.99997,0.99287206,0.24275039,7.7198653,370.01495,-9.2921171
165.519,-0.23498146,9.4473848,0.0,0,9.8164806,359.99997,0.99488562,-1.0606533,8.1920452,370.05829,-9.2916317
165.5214,-0.044352405,9.4451857,0.0,0,10.274966,359.99997,0.99345171,-0.23335189,8.6580725,370.10165,-9.2912321
165.5238,-0.026152028,9.4449711,0.0,0,10.733453,359.99997,0.99251366,-0.13905811,9.1329327,369.93558,-9.2901821
165.5262,-0.1041658,9.4492168,0.0,0,11.191939,359.99997,0.99341792,-0.44027248,9.5989189,369.63928,-9.2897682
165.5286,-0.027900869,9.4477901,0.0,0,11.650426,359.99997,0.99417973,-0.17676583,10.075985,369.34299,-9.2889509
165.531,-0.045251068,9.4445295,0.0,0,12.108912,359.99997,0.99426579,-0.17038696,10.556973,369.04669,-9.289773
165.5334,-0.16908292,9.4437008,0.0,0,12.567399,359.99997,0.99381435,-0.82618922,11.021764,368.64697,-9.2901506
165.5358,0.042335622,9.4451151,0.0,0,13.025885,359.99997,0.99280149,0.12020659,11.49823,368.11206,-9.2902451
165.5382,-0.034971155,9.4501162,0.0,0,13.484371,359.99997,0.99293393,-0.081630036,11.952073,367.57715,-9.2885103
165.5406,-0.089490138,9.453105,0.0,0,13.942858,359.99997,0.994111,-0.41872999,12.39686,367.04221,-9.2889118
165.543,-0.10603333,9.447957,0.0,0,14.401344,359.99997,0.99461609,-0.55558592,12.862311,366.56866,-9.2888861
165.5454,-0.034443595,9.4437599,0.0,0,14.859831,359.99997,0.99433494,-0.11758522,13.340122,366.27927,-9.2884645
165.5478,-0.19314779,9.4441681,0.0,0,15.318317,359.99997,0.99331951,-0.88809252,13.815552,365.98987,-9.2890205
165.5502,0.073345155,9.4418106,0.0,0,15.776803,359.99997,0.99187219,0.27708155,14.297419,365.70047,-9.2879753
165.5526,-0.17728429,9.4444342,0.0,0,16.235291,359.99997,0.99251902,-0.76337421,14.767341,365.34729,-9.2885284
165.555,-0.10338125,9.4453726,0.0,0,16.693775,359.99997,0.99350703,-0.50464153,15.222502,364.10126,-9.2893333
165.5574,0.0053215069,9.443367,0.0,0,17.152262,359.99997,0.99420208,-0.0078493934,15.67223,362.85522,-9.2893152
165.5598,-0.012257101,9.439043,0.0,0,17.61075,359.99997,0.99298245,0.0069743139,16.122913,361.60919,-9.2892637
165.5622,-0.17225769,9.4428797,0.0,0,17.999975,359.99997,0.99260557,-0.84338242,16.571453,360.36319,-9.288168
165.5646,0.032509241,9.4461594,0.0,0,18.0,359.99997,0.99238485,0.1289845,17.03664,358.82919,-9.2880144
165.567,-0.11289892,9.4515619,0.0,0,18.0,359.99997,0.99369156,-0.55597907,17.458502,357.25717,-9.287797
165.5694,0.02132022,9.446147,0.0,0,18.0,359.99997,0.99429858,0.057943702,17.846434,355.68515,-9.2898445
165.5718,-0.10114702,9.4435692,0.0,0,18.0,359.99997,0.99444169,-0.40799019,18.163263,354.11313,-9.2905722
165.5742,-0.069571994,9.4463682,4.7962456,0,18.0,359.99997,0.99385113,-0.37225991,18.388649,353.48938,-9.293376
165.5766,-0.043588746,9.4530983,11.648037,0,18.0,359.99997,0.99402028,-0.26011196,18.495844,353.27206,-9.2988358
165.579,-0.031467527,9.4608555,18.499828,0,18.0,359.99997,0.99553412,-0.15453091,18.475445,353.05472,-9.3055124
165.5814,-0.018507503,9.4720945,25.351622,0,18.0,359.99997,0.99813521,-0.10018465,18.359566,352.8374,-9.3153048
165.5838,-0.097735263,9.480011,28.66333,0,18.0,359.99997,1.0006971,-0.42182851,18.232821,352.73236,-9.3276587
165.5862,-0.10751431,9.4972706,28.66333,0,18.0,359.99997,1.0036908,-0.47657079,18.122456,352.73236,-9.3432798
165.5886,-0.12942666,9.5182467,28.66333,0,18.0,359.99997,1.0063457,-0.56982172,18.058943,352.73236,-9.361681
165.591,0.059594389,9.540761,28.66333,0,18.0,359.99997,1.0094616,0.15769646,18.043747,352.73236,-9.3812056
165.5934,0.042277377,9.5619345,29.070393,0,18.0,359.99997,1.0137554,0.20747615,18.045883,352.55832,-9.4000778
165.5958,-0.12231332,9.5777893,30.291582,0,18.0,359.99997,1.0180653,-0.5008626,18.06567,352.03622,-9.4204245
165.5982,-0.17420122,9.5926037,31.512772,0,18.0,359.99997,1.0215949,-0.77996516,18.0912,351.51413,-9.4406967
165.6006,-0.019682135,9.6085443,32.733959,0,18.0,359.99997,1.0236171,-0.1564157,18.11668,350.99203,-9.4590998
165.603,0.03720855,9.6289215,33.771973,0,18.0,359.99997,1.0261642,0.16697203,18.137526,350.38052,-9.4766293
165.6054,-0.0095911156,9.650528,33.771973,0,18.0,359.99997,1.0300635,0.016510826,18.149511,349.26233,-9.4932384
165.6078,-0.18355434,9.668046,33.771973,0,18.0,359.99997,1.0342926,-0.76383579,18.151278,348.1441,-9.5118961
165.6102,-0.09738224,9.6798391,33.771973,0,18.0,359.99997,1.0375675,-0.53394651,18.147232,347.02591,-9.5298767
165.6126,0.047757532,9.692215,33.771973,0,18.0,359.99997,1.0398295,0.1571587,18.149204,345.90768,-9.5458813
165.615,0.025902115,9.7121849,36.275101,0,18.0,359.99997,1.0423393,0.14373903,18.144621,345.18231,-9.5619001
165.6174,-0.108252,9.7371569,38.864548,0,18.0,359.99997,1.0460238,-0.41825497,18.138355,344.47049,-9.579649
165.6198,-0.15421341,9.7572374,41.453995,0,18.0,359.99997,1.0501701,-0.70299309,18.137554,343.75867,-9.5976934
165.6222,-0.036404908,9.7707233,44.043442,0,18.0,359.99997,1.0543072,-0.2157983,18.133505,343.04684,-9.6150713
165.6246,0.067549877,9.7806635,44.604492,0,18.0,359.99997,1.0568633,0.3087444,18.128159,342.86984,-9.6320219
165.627,-0.020236669,9.798502,44.604492,0,18.0,359.99997,1.0594727,-0.01051676,18.125757,342.84079,-9.6499176
165.6294,-0.17139576,9.8219757,44.604492,0,18.0,359.99997,1.0628302,-0.73607075,18.123835,342.81174,-9.6679478
165.6318,-0.094650231,9.8397436,44.604492,0,18.0,359.99997,1.0661788,-0.49656814,18.118412,342.78268,-9.6863394
165.6342,0.051152062,9.8554869,44.820366,0,18.0,359.99997,1.0698925,0.18424608,18.120966,342.5575,-9.7040491
165.6366,0.027864454,9.8690758,45.180157,0,18.0,359.99997,1.0735569,0.12161889,18.118279,342.2016,-9.721242
165.639,-0.092960879,9.8848286,45.539948,0,18.0,359.99997,1.076811,-0.31182209,18.116583,341.84567,-9.7383327
165.6414,-0.1593249,9.9055796,45.899742,0,18.0,359.99997,1.07965,-0.69936758,18.115349,341.48975,-9.7551804
165.6438,-0.024067756,9.9283705,46.109619,0,18.0,359.99997,1.0831693,-0.17801319,18.114279,341.03397,-9.7730494
165.6462,0.082373165,9.9472008,46.109619,0,18.0,359.99997,1.0869647,0.33589566,18.113518,340.43835,-9.7892246
165.6486,-0.033358529,9.9608431,46.109619,0,18.0,359.99997,1.0911186,-0.064726099,18.107801,339.84274,-9.8069038
165.651,-0.17318171,9.9757681,46.109619,0,18.0,359.99997,1.0950153,-0.70243007,18.106373,339.24713,-9.825901
165.6534,-0.097512975,9.991025,46.414173,0,18.0,359.99997,1.0975034,-0.4634923,18.105625,338.57504,-9.844697
165.6558,0.040784478,10.010412,47.719398,0,18.0,359.99997,1.1000642,0.13067479,18.103399,337.65161,-9.8616467
165.6582,0.04736457,10.030932,49.024628,0,18.0,359.99997,1.1035594,0.18012092,18.099171,336.72818,-9.8771448
165.6606,-0.09874703,10.051348,50.329853,0,18.0,359.99997,1.1084824,-0.33020106,18.100319,335.80478,-9.8973083
165.663,-0.1710152,10.065773,51.569824,0,18.0,359.99997,1.1126438,-0.72288746,18.102985,334.89078,-9.9150105
165.6654,-0.019647025,10.07771,51.569824,0,18.0,359.99997,1.1154124,-0.18123072,18.102428,334.15573,-9.9315195
165.6678,0.063909113,10.096679,51.569824,0,18.0,359.99997,1.1180298,0.25121588,18.102692,333.42072,-9.9478455
165.6702,-0.038203843,10.121243,51.569824,0,18.0,359.99997,1.1217369,-0.051838394,18.099274,332.6857,-9.9653912
165.6726,-0.17095914,10.141339,51.569824,0,18.0,359.99997,1.12617,-0.65760309,18.097551,331.95065,-9.9843855
165.675,-0.10166097,10.156235,52.266296,0,18.0,359.99997,1.1305957,-0.47131541,18.098394,331.55591,-10.002618
165.6774,0.030303027,10.166375,53.069916,0,18.0,359.99997,1.1337582,0.10615955,18.097313,331.2135,-10.019761
165.6798,0.04439285,10.18305,53.873539,0,18.0,359.99997,1.1366249,0.19835813,18.097164,330.87112,-10.037466
165.6822,-0.096458144,10.204025,54.677158,0,18.0,359.99997,1.1395481,-0.31089848,18.098053,330.52872,-10.053952
165.6846,-0.17864949,10.227079,54.931641,0,18.0,359.99997,1.1437845,-0.74040884,18.098875,329.98718,-10.071624
165.687,-0.0063876719,10.242332,54.931641,0,18.0,359.99997,1.1478186,-0.12375225,18.096437,329.35339,-10.089431
165.6894,0.079053067,10.252092,54.931641,0,18.0,359.99997,1.1512629,0.31790915,18.093365,328.71957,-10.107549
165.6918,-0.028294059,10.269542,54.931641,0,18.0,359.99997,1.1552483,-0.052118134,18.091105,328.08575,-10.123729
165.6942,-0.1616672,10.292588,55.275673,0,18.0,359.99997,1.1589789,-0.63741386,18.0954,327.47018,-10.142488
165.6966,-0.10888868,10.313976,55.963741,0,18.0,359.99997,1.1621448,-0.47402123,18.087477,326.8728,-10.161265
165.699,0.036534265,10.331797,56.65181,0,18.0,359.99997,1.1659311,0.10794742,18.08783,326.27542,-10.177707
165.7014,0.05496604,10.347767,57.339874,0,18.0,359.99997,1.1707397,0.23657787,18.089769,325.67804,-10.193617
165.7038,-0.10347939,10.36179,57.810059,0,18.0,359.99997,1.1750824,-0.33575293,18.089737,325.14066,-10.21067
165.7062,-0.16747648,10.377959,57.810059,0,18.0,359.99997,1.1780032,-0.67494702,18.084503,324.73267,-10.229438
165.7086,-0.015998932,10.393059,57.810059,0,18.0,359.99997,1.1798459,-0.11049155,18.084665,324.32471,-10.247066
165.711,0.078738235,10.412896,57.810059,0,18.0,359.99997,1.1834246,0.297663,18.084688,323.91675,-10.264209
165.7134,-0.028274229,10.435229,57.882542,0,18.0,359.99997,1.1890429,-0.051041521,18.083975,323.49033,-10.280623
165.7158,-0.16293296,10.449484,58.42617,0,18.0,359.99997,1.1935264,-0.59225869,18.081629,322.94394,-10.299443
165.7182,-0.10258149,10.464664,58.969799,0,18.0,359.99997,1.1974478,-0.44103467,18.085508,322.39755,-10.317779
165.7206,0.042481434,10.482253,59.51342,0,18.0,359.99997,1.2002933,0.13275693,18.083231,321.85117,-10.334184
165.723,0.064302877,10.505604,60.057049,0,18.0,359.99997,1.2038139,0.23501262,18.081829,321.30478,-10.353042
165.7254,-0.098523133,10.528929,60.084232,0,18.0,359.99997,1.2088289,-0.32278252,18.079115,320.75775,-10.37
165.7278,-0.17934123,10.543918,60.084232,0,18.0,359.99997,1.2137258,-0.71128768,18.079411,320.21072,-10.387615
165.7302,-0.01570441,10.551759,60.084232,0,18.0,359.99997,1.2171227,-0.11515517,18.079636,319.66367,-10.405535
165.7326,0.070713766,10.564789,60.084232,0,18.0,359.99997,1.2197256,0.24926603,18.073702,319.11661,-10.421719
165.735,-0.025899423,10.586062,60.456718,0,18.0,359.99997,1.2227206,-0.030998427,18.076744,318.61362,-10.438564
165.7374,-0.16095746,10.610597,60.942562,0,18.0,359.99997,1.2275159,-0.58873594,18.077427,318.12402,-10.457536
165.7398,-0.11308729,10.628114,61.428413,0,18.0,359.99997,1.2321105,-0.46776497,18.078897,317.63446,-10.477046
165.7422,0.03813098,10.638492,61.914257,0,18.0,359.99997,1.2360998,0.087738633,18.075569,317.14487,-10.494463
165.7446,0.055079609,10.653594,62.116699,0,18.0,359.99997,1.2401382,0.24458317,18.076273,316.72769,-10.511285
165.747,-0.10114271,10.675772,62.116699,0,18.0,359.99997,1.244047,-0.28987953,18.07449,316.36218,-10.527126
165.7494,-0.17825052,10.700678,62.116699,0,18.0,359.99997,1.2483597,-0.68709576,18.072216,315.99667,-10.546398
165.7518,-0.020182865,10.719631,62.116699,0,18.0,359.99997,1.2522924,-0.12516379,18.073326,315.63116,-10.562862
165.7542,0.051419389,10.731985,62.256409,0,18.0,359.99997,1.2568055,0.20732331,18.069881,315.26276,-10.579245
165.7566,-0.013260472,10.747055,62.605698,0,18.0,359.99997,1.2617266,-0.015339866,18.069994,314.88992,-10.597175
165.759,-0.15176193,10.760602,62.954987,0,18.0,359.99997,1.2648677,-0.51318157,18.070734,314.51712,-10.61494
165.7614,-0.12739763,10.778843,63.304272,0,18.0,359.99997,1.2677881,-0.48057586,18.069311,314.14432,-10.632571
165.7638,0.045057211,10.797335,63.577881,0,18.0,359.99997,1.271013,0.093869217,18.070999,313.75406,-10.650385
165.7662,0.070207343,10.816539,63.577881,0,18.0,359.99997,1.2759687,0.29192618,18.070705,313.30084,-10.668621
165.7686,-0.10792127,10.834551,63.577881,0,18.0,359.99997,1.2816386,-0.32158905,18.070631,312.84763,-10.686764
165.771,-0.17583452,10.847486,63.577881,0,18.0,359.99997,1.2859502,-0.61047518,18.065344,312.39438,-10.705625
165.7734,-0.0068220012,10.863475,63.590134,0,18.0,359.99997,1.2885305,-0.10983247,18.065977,311.94336,-10.723806
165.7758,0.057887655,10.886135,63.957802,0,18.0,359.99997,1.2922914,0.21797931,18.06988,311.55591,-10.739902
165.7782,0.010787234,10.907541,64.32547,0,18.0,359.99997,1.2970271,0.066366151,18.070637,311.16849,-10.756125
165.7806,-0.14669439,10.928596,64.693138,0,18.0,359.99997,1.3037212,-0.4437871,18.066292,310.78107,-10.773311
165.783,-0.12138674,10.939252,65.060814,0,18.0,359.99997,1.308198,-0.44719476,18.066862,310.39362,-10.791995
165.7854,0.0513588,10.949645,65.115967,0,18.0,359.99997,1.3108112,0.14468071,18.065126,310.01239,-10.809265
165.7878,0.057045199,10.971035,65.115967,0,18.0,359.99997,1.314238,0.2297806,18.061028,309.63226,-10.826346
165.7902,-0.098626189,10.994399,65.115967,0,18.0,359.99997,1.3186696,-0.28753844,18.062132,309.25214,-10.843552
165.7926,-0.16856536,11.012459,65.115967,0,18.0,359.99997,1.3238854,-0.58552349,18.063803,308.87201,-10.861058
165.795,-0.022703335,11.023795,65.343567,0,18.0,359.99997,1.3284179,-0.12592845,18.063347,308.46753,-10.880334
165.7974,0.066095479,11.037716,65.684982,0,18.0,359.99997,1.3329715,0.2187082,18.060633,308.05084,-10.896471
165.7998,0.017728403,11.05647,66.02639,0,18.0,359.99997,1.336513,0.10070617,18.061878,307.63419,-10.913288
165.8022,-0.15569571,11.081922,66.367798,0,18.0,359.99997,1.3411269,-0.45924106,18.063349,307.2175,-10.931428
165.8046,-0.13294698,11.104895,66.544189,0,18.0,359.99997,1.3462298,-0.47573698,18.057293,306.80438,-10.949702
165.807,0.060821209,11.11726,66.544189,0,18.0,359.99997,1.3510044,0.15857655,18.062407,306.39502,-10.967109
165.8094,0.055500172,11.126733,66.544189,0,18.0,359.99997,1.3553923,0.20239164,18.062651,305.98566,-10.984571
165.8118,-0.10041852,11.14262,66.544189,0,18.0,359.99997,1.3595694,-0.27094933,18.056862,305.57629,-11.003219
165.8142,-0.16498768,11.16473,66.627701,0,18.0,359.99997,1.3635185,-0.55177075,18.058443,305.16675,-11.022517
165.8166,-0.02739946,11.183162,66.906082,0,18.0,359.99997,1.3672765,-0.14355509,18.059761,304.75677,-11.039959
165.819,0.065133527,11.200135,67.184464,0,18.0,359.99997,1.3719543,0.2330457,18.061407,304.3468,-11.055168
165.8214,0.022838274,11.217841,67.462837,0,18.0,359.99997,1.3782941,0.091603152,18.054111,303.93686,-11.072837
165.8238,-0.14941783,11.234488,67.70874,0,18.0,359.99997,1.3837688,-0.45511609,18.054283,303.51822,-11.090243
165.8262,-0.1257349,11.251346,67.70874,0,18.0,359.99997,1.3873588,-0.43495208,18.05641,303.03406,-11.107783
165.8286,0.056343768,11.269467,67.70874,0,18.0,359.99997,1.3901877,0.12871817,18.054749,302.5499,-11.124553
165.831,0.056779139,11.292051,67.70874,0,18.0,359.99997,1.3952657,0.1838879,18.049068,302.06577,-11.141788
165.8334,-0.091446139,11.311922,67.70874,0,18.0,359.99997,1.402337,-0.24216039,18.053791,301.5816,-11.161033
165.8358,-0.15354499,11.324474,67.745506,0,18.0,359.99997,1.4078289,-0.48514301,18.053492,301.14514,-11.178433
165.8382,-0.024225207,11.336183,67.784904,0,18.0,359.99997,1.4113752,-0.13229841,18.052261,300.71207,-11.196735
165.8406,0.073288329,11.355328,67.824295,0,18.0,359.99997,1.414562,0.20869415,18.05567,300.27899,-11.2126
165.843,0.020348838,11.375825,67.863686,0,18.0,359.99997,1.418691,0.11270349,18.051767,299.84595,-11.230078
165.8454,-0.15605876,11.397976,67.873535,0,18.0,359.99997,1.4251257,-0.4217222,18.048695,299.46793,-11.248153
165.8478,-0.11871169,11.409017,67.873535,0,18.0,359.99997,1.4301531,-0.41405153,18.051525,299.10828,-11.266386
165.8502,0.061769869,11.419333,67.873535,0,18.0,359.99997,1.4344126,0.15201811,18.051247,298.74863,-11.284575
165.8526,0.061675876,11.436943,67.873535,0,18.0,359.99997,1.4383965,0.20757999,18.050848,298.38898,-11.29972
165.855,-0.069907643,11.464639,58.679596,0,18.0,359.99997,1.4439352,-0.15937537,18.052193,298.04596,-11.316857
165.8574,-0.1658915,11.48806,42.454849,0,18.0,359.99997,1.4492724,-0.49167967,18.051292,297.71567,-11.335908
165.8598,-0.033050258,11.501819,26.230099,0,18.0,359.99997,1.454836,-0.14044951,18.053648,297.38538,-11.354202
166.0617,-0.045612682,11.620531,0.0,0,18.0,0.68381345,1.4902869,-0.12941667,18.026327,246.07048,-11.481215
167.2617,-0.053140838,11.619679,0.0,0,18.0,2.9561129e-17,1.4901841,-0.15059233,18.000772,52.105785,-11.481972
168.4617,-0.047496893,11.619777,0.0,0,18.0,1.2779231999999999e-33,1.4899428,-0.13771829,17.999798,54.84919,-11.482107
169.6617,-0.048026767,11.619669,0.0,0,18.0,1.4012985e-45,1.4899517,-0.13536145,17.999371,30.970356,-11.482987
170.8617,-0.045246422,11.619048,0.0,0,18.0,1.4012985e-45,1.4900346,-0.12926315,18.000242,57.458118,-11.48286
172.0617,-0.049068075,11.619308,0.0,0,18.0,1.4012985e-45,1.4899663,-0.13924156,17.998976,44.971642,-11.482391
173.2617,-0.04729002,11.619039,0.0,0,18.0,1.4012985e-45,1.489902,-0.13749179,17.999866,218.60143,-11.482769
174.4617,-0.04804397,11.619557,0.0,0,18.0,1.4012985e-45,1.4901364,-0.13729224,18.000134,2964.8894,-11.483039
175.6617,-0.049862713,11.619128,0.0,0,18.0,1.4012985e-45,1.4897496,-0.1451882,17.999739,2806.8684,-11.482564
176.8617,-0.050704401,11.618994,0.0,0,18.0,1.4012985e-45,1.4898345,-0.14600827,18.000158,7960.1411,-11.482242
178.0617,-0.049362358,11.618707,0.0,0,18.0,1.4012985e-45,1.4899722,-0.14387268,18.000238,7999.8848,-11.482366
179.2617,-0.05053791,11.619452,0.0,0,18.0,1.4012985e-45,1.4899812,-0.14852731,17.999184,7999.7842,-11.482968
180.4617,-0.047652658,11.620091,0.0,0,18.0,1.4012985e-45,1.4902477,-0.13855852,18.000559,7999.9995,-11.483454
181.6617,-0.055786621,11.619876,0.0,0,18.0,1.4012985e-45,1.4901272,-0.16329631,17.999027,7932.8809,-11.483024
182.8617,-0.053395543,11.619708,0.0,0,18.0,1.4012985e-45,1.4899014,-0.15141228,17.999788,7999.5293,-11.482747
184.0617,-0.052486971,11.619898,0.0,0,18.0,1.4012985e-45,1.4901707,-0.15084282,17.999653,7999.9995,-11.48234
185.2617,-0.049130656,11.61944,0.0,0,18.0,1.4012985e-45,1.4901596,-0.14108053,17.99963,7999.9995,-11.482876
186.4617,-0.054879721,11.620009,0.0,0,18.0,1.4012985e-45,1.4900911,-0.1581019,17.999966,7999.9995,-11.483121
187.6617,-0.056125976,11.620035,0.0,0,18.0,1.4012985e-45,1.4903383,-0.16108085,17.999161,7999.9995,-11.482656
188.8617,-0.054888036,11.620359,0.0,0,18.0,1.4012985e-45,1.490188,-0.15324591,18.000845,7999.9995,-11.482671
190.0617,-0.054434765,11.619987,0.0,0,18.0,1.4012985e-45,1.4900286,-0.15581647,18.000761,7714.7983,-11.482378
191.2617,-0.044174865,11.620422,0.0,0,18.0,1.4012985e-45,1.4904308,-0.12523513,18.000296,7999.9995,-11.482564
192.4617,-0.046763841,11.62149,0.0,0,18.0,1.4012985e-45,1.4906799,-0.13205643,18.000721,7999.9995,-11.483461
193.6617,-0.046185277,11.621358,0.0,0,18.0,1.4012985e-45,1.490605,-0.13110696,18.000362,7999.9995,-11.483448
194.8617,-0.04879716,11.621438,0.0,0,18.0,1.4012985e-45,1.4906375,-0.14035285,17.999533,7999.9995,-11.482928
196.0617,-0.048541646,11.621711,0.0,0,18.0,1.4012985e-45,1.4905132,-0.13903569,17.999546,7999.9995,-11.482862
197.2617,-0.043105289,11.621598,0.0,0,18.0,1.4012985e-45,1.490671,-0.12113892,17.999817,7999.9995,-11.483066
198.4617,-0.051313516,11.62146,0.0,0,18.0,1.4012985e-45,1.4907908,-0.14864323,18.000465,2879.8076,-11.48346
199.6617,-0.045300685,11.621678,0.0,0,18.0,1.4012985e-45,1.4905705,-0.13094291,17.999043,7999.5205,-11.483535
200.8617,-0.049867716,11.622073,0.0,0,18.0,1.4012985e-45,1.4909381,-0.14271817,17.999092,7999.9995,-11.483207
202.0617,-0.04868437,11.622518,0.0,0,18.0,1.4012985e-45,1.4907798,-0.14037822,18.000452,7999.9995,-11.48323
203.2617,-0.05469403,11.622313,0.0,0,18.0,1.4012985e-45,1.4907699,-0.16138826,17.999559,7999.9995,-11.482757
204.4617,-0.053878564,11.622106,0.0,0,18.0,1.4012985e-45,1.4909575,-0.15744595,17.999592,7874.4819,-11.48243
205.6617,-0.056264859,11.622046,0.0,0,18.0,1.4012985e-45,1.4906836,-0.16145961,17.999521,7764.0757,-11.482519
206.8617,-0.051408716,11.622764,0.0,0,18.0,1.4012985e-45,1.4910834,-0.14649685,18.000105,7999.9995,-11.483041
208.0617,-0.051176261,11.623407,0.0,0,18.0,1.4012985e-45,1.4910644,-0.14687942,18.000469,7623.8311,-11.483603
209.2617,-0.05759028,11.623536,0.0,0,18.0,1.4012985e-45,1.4911268,-0.16311896,18.000168,7999.999,-11.483032
210.4617,-0.056481857,11.622937,0.0,0,18.0,1.4012985e-45,1.491233,-0.16416644,17.999546,7999.9995,-11.482854
211.6617,-0.050751217,11.623511,0.0,0,18.0,1.4012985e-45,1.4911203,-0.1451111,17.999689,7525.2979,-11.482369
212.8617,-0.052225154,11.623278,0.0,0,18.0,1.4012985e-45,1.4912884,-0.14859149,17.999563,7999.8516,-11.482747
214.0617,-0.048808817,11.623707,0.0,0,18.0,1.4012985e-45,1.4911774,-0.13815628,18.000153,4351.4341,-11.482903
215.2617,-0.043958146,11.624165,0.0,0,18.0,1.4012985e-45,1.4912648,-0.12614124,18.000845,7999.9995,-11.483069
216.4617,-0.042770814,11.624497,0.0,0,18.0,1.4012985e-45,1.4917134,-0.12028255,17.999537,6544.165,-11.483568
217.6617,-0.052061643,11.624308,0.0,0,18.0,1.4012985e-45,1.4913405,-0.15171054,18.0007,7999.9995,-11.48282
218.8617,-0.049209725,11.624517,0.0,0,18.0,1.4012985e-45,1.4916395,-0.13961604,18.001137,7991.2241,-11.48242
220.0617,-0.048211962,11.62493,0.0,0,18.0,1.4012985e-45,1.491505,-0.13973077,17.999544,7991.5718,-11.48255
221.2617,-0.050408084,11.624577,0.0,0,18.0,1.4012985e-45,1.4914453,-0.1445853,17.999264,6305.8501,-11.4825
222.4617,-0.047265142,11.624797,0.0,0,18.0,1.4012985e-45,1.4917665,-0.13856681,18.000439,6902.0742,-11.48311
223.6617,-0.052744061,11.625313,0.0,0,18.0,1.4012985e-45,1.4916517,-0.15280691,17.999683,7999.9995,-11.483081
224.8617,-0.05660399,11.624951,0.0,0,18.0,1.4012985e-45,1.4917928,-0.16333058,17.999594,7999.9995,-11.48317
225.8617,-0.056756809,11.625979,0.0,0,18.0,1.4012985e-45,1.4918443,-0.16562751,18.000862,7999.9995,-11.483014