File: examples/hot axisymmetric compression example/data/02 screened data/testID_0138.csv
Time(sec),Force(kN),Jaw(mm),PowAngle(deg),Power(W),Pram,PTemp,Strain,Stress(MPa),Stroke(mm),TC1(C),wedge(mm)
0.0,0.99854505,0.33611289,0.0,0,11.076097,0.0010873112,0.022655336,12.42939,11.077082,22.701584,-9.1480589
1.2,0.95274675,0.0010024941,0.0,0,11.076097,3.5156128,4.8494356e-05,12.139754,11.075588,22.703959,-9.4924946
2.4,0.92887622,0.00087929814,0.0,0,11.076097,7.1156144,6.6708031e-05,11.829254,11.076066,22.659225,-9.4900713
3.6,0.91016006,0.00053252914,0.0,0,11.076097,10.715615,3.6838344e-05,11.580657,11.076012,22.718719,-9.489069
4.8,0.89536053,0.00086180668,0.0,0,11.076097,14.315614,4.6089932e-05,11.389958,11.075152,22.726749,-9.4863586
6.0,0.87435383,0.00024798838,0.0,0,11.076097,17.915611,2.5975834e-05,11.126499,11.076358,22.764328,-9.4844542
7.2,0.86299324,0.00055549305,0.0,0,11.076097,21.515615,3.1467858e-05,10.986178,11.075335,22.670332,-9.4815207
8.4,0.85003471,0.00061756757,10.881953,0,11.076097,25.115616,3.5073241e-05,10.819244,11.075738,22.700184,-9.4796686
9.6,0.84228545,0.00096263312,30.920315,0,11.076097,28.715616,6.5234351e-05,10.727574,11.076124,22.746967,-9.4778347
10.8,0.86133975,-0.0010521582,43.007305,0,11.076097,32.315613,-6.9459289e-05,10.958819,11.07675,24.197048,-9.4759903
12.0,0.87760746,-0.0050776238,50.385105,0,11.076097,35.915615,-0.00033637488,11.183486,11.077031,27.645639,-9.474122
13.2,0.89743346,-0.01100741,54.583622,0,11.076097,39.515617,-0.0007322306,11.448034,11.075733,33.057259,-9.471817
14.4,0.91759712,-0.016808448,56.422886,0,11.076097,43.11562,-0.0011095359,11.680802,11.076212,39.563446,-9.4695082
15.6,0.94099069,-0.022050347,56.129166,0,11.076097,46.715622,-0.0014631533,12.007183,11.075011,46.816757,-9.4673271
16.8,0.95502979,-0.026802903,53.69558,0,11.076097,50.31562,-0.0018001089,12.17701,11.075662,53.745827,-9.4655256
18.0,0.95275468,-0.030455945,49.162899,0,11.076097,53.915619,-0.0020143308,12.156316,11.074704,59.950539,-9.4630775
19.2,0.94425416,-0.032161791,42.468636,0,11.076097,57.515621,-0.0021288579,12.06736,11.076829,64.617393,-9.4613199
20.4,0.91890103,-0.031981353,33.961864,0,11.076097,61.115623,-0.0021508636,11.721674,11.076455,67.256973,-9.4590616
21.6,0.8977738,-0.032057382,27.469444,0,11.076097,64.715607,-0.0021199244,11.462672,11.07625,68.393372,-9.4573116
22.8,0.88210684,-0.031016113,28.661892,0,11.076097,68.315605,-0.0020567703,11.254892,11.075178,68.158958,-9.4550943
24.0,0.86808652,-0.031470101,37.262287,0,11.076097,71.915604,-0.0021103867,11.065925,11.075368,67.738602,-9.4530916
25.2,0.88098598,-0.033060845,46.049999,0,11.076097,75.515617,-0.0021772755,11.252642,11.075785,68.222717,-9.4509401
26.4,0.89587575,-0.036839057,52.831596,0,11.076097,79.115601,-0.0024370097,11.438797,11.075503,70.57048,-9.4487162
27.6,0.92274863,-0.042079274,57.475899,0,11.076097,82.715622,-0.0028200755,11.795618,11.076031,74.802254,-9.4465723
28.8,0.95183778,-0.048751075,59.838463,0,11.076097,86.315605,-0.0032327683,12.14655,11.075252,81.090485,-9.4442434
30.0,0.96925324,-0.055297617,60.556637,0,11.076097,89.915627,-0.0036667839,12.393855,11.07618,88.168846,-9.4423323
31.2,0.97464091,-0.061415672,58.90797,0,11.076097,93.515602,-0.0041033626,12.461778,11.076305,96.183319,-9.4401093
32.4,0.96735853,-0.066192865,55.862057,0,11.076097,97.115623,-0.0043839877,12.36542,11.075706,102.57982,-9.4382496
33.6,0.96407092,-0.070042886,51.241966,0,11.076097,100.71561,-0.0046506231,12.347808,11.07616,107.91292,-9.4360924
34.8,0.94962198,-0.071406692,45.006775,0,11.076097,104.31562,-0.0047757025,12.150199,11.075965,111.83139,-9.4341431
36.0,0.92183745,-0.071918562,38.128063,0,11.076097,107.91561,-0.0047678519,11.793616,11.076757,113.88661,-9.4322376
37.2,0.90625823,-0.071212858,34.650887,0,11.076097,111.51563,-0.0047260467,11.610708,11.0761,114.32335,-9.4300518
38.4,0.88978356,-0.070808455,37.670036,0,11.076097,115.11562,-0.0047189523,11.377644,11.075507,113.73237,-9.4281063
39.6,0.88199872,-0.071405604,44.535629,0,11.076097,118.71563,-0.0047276318,11.294526,11.075494,113.32249,-9.4259272
40.8,0.90384287,-0.073676728,51.750416,0,11.076097,122.31562,-0.0048901406,11.559423,11.076133,113.98994,-9.4241619
42.0,0.91583788,-0.07765191,57.406414,0,11.076097,125.91563,-0.0051694652,11.718109,11.075218,116.6526,-9.4217377
43.2,0.95034224,-0.083430387,61.249825,0,11.076097,129.51575,-0.0055373125,12.176862,11.076012,121.21492,-9.4198694
44.4,0.97698277,-0.090389065,63.55069,0,11.076097,133.11562,-0.006010599,12.49653,11.07581,127.2846,-9.4174747
45.6,0.97349304,-0.097478643,63.973385,0,11.076097,136.71561,-0.0064803716,12.477625,11.076936,134.8239,-9.4155512
46.8,0.97735596,-0.10422575,63.059933,0,11.076097,140.31561,-0.0069271536,12.538937,11.076726,142.16518,-9.4137564
48.0,0.9745329,-0.10978413,60.670582,0,11.076097,143.91562,-0.0072925338,12.485396,11.07628,149.20227,-9.4115829
49.2,0.96890044,-0.1134991,57.027454,0,11.076097,147.51559,-0.0075401813,12.439888,11.076594,154.9052,-9.4098024
50.4,0.96548527,-0.11541052,51.991261,0,11.076097,151.11562,-0.0076641515,12.38666,11.075282,159.36162,-9.408
51.6,0.93968731,-0.11622812,46.246265,0,11.076097,154.71561,-0.0077105397,12.065405,11.076292,162.03987,-9.4060173
52.8,0.92445421,-0.11626067,41.828602,0,11.076097,158.3156,-0.0077161537,11.854454,11.075007,163.01355,-9.4037476
54.0,0.89270937,-0.11618473,41.198734,0,11.076097,161.9156,-0.0077247634,11.461304,11.075377,162.77882,-9.4016724
55.2,0.88293749,-0.11589146,45.526958,0,11.076097,165.51561,-0.0076872376,11.328471,11.076633,162.25471,-9.3995686
56.4,0.88928455,-0.11666299,51.437092,0,11.076097,169.1156,-0.0077376692,11.400402,11.076156,162.2699,-9.3975382
57.6,0.90448594,-0.12009057,57.132763,0,11.076097,172.71561,-0.007994039,11.609107,11.076653,163.69037,-9.3954849
58.8,0.93330193,-0.12506343,61.518929,0,11.076097,176.31561,-0.0082831625,11.973922,11.076099,166.97917,-9.3930883
60.0,0.96909791,-0.13059826,64.54287,0,11.076097,179.9156,-0.0086592073,12.451437,11.075281,171.98892,-9.3912287
61.2,0.99149108,-0.14037593,66.01593,0,11.076097,183.51561,-0.0093319863,12.735216,11.076213,178.85963,-9.3894138
62.4,0.99062687,-0.14603159,66.192642,0,11.076097,187.11562,-0.0096748229,12.710684,11.07577,186.27199,-9.3872108
63.6,0.97824025,-0.15318833,64.955559,0,11.076097,190.71562,-0.010161801,12.596662,11.075655,193.69304,-9.3856888
64.8,0.98041779,-0.15805386,62.34346,0,11.076097,194.31561,-0.010482052,12.612902,11.075369,200.83897,-9.383337
66.0,0.97843373,-0.16150548,58.382813,0,11.076097,197.91562,-0.01071013,12.588092,11.075248,206.47487,-9.3813744
67.2,0.96597141,-0.16475272,53.431614,0,11.076097,201.51561,-0.010918863,12.433953,11.077236,210.3152,-9.3793993
68.4,0.94116819,-0.16382632,48.40646,0,11.076097,205.11563,-0.010866423,12.117766,11.075685,212.35387,-9.3771896
69.6,0.91091406,-0.16319458,45.218037,0,11.076097,208.71562,-0.010825146,11.735434,11.076227,212.6545,-9.3750706
70.8,0.89727533,-0.16244906,46.103489,0,11.076097,212.31563,-0.010756435,11.539646,11.075545,211.96602,-9.3729076
72.0,0.88352704,-0.16417512,50.38736,0,11.076097,215.9156,-0.01087625,11.368375,11.076745,211.35796,-9.3710146
73.2,0.88886076,-0.16464531,55.692089,0,11.076097,219.51563,-0.010927318,11.463271,11.07543,211.79417,-9.3687525
74.4,0.91540158,-0.16883105,60.53669,0,11.076097,223.11562,-0.011173774,11.776136,11.076178,213.67381,-9.3669376
75.6,0.93975645,-0.17385954,64.164337,0,11.076097,226.71562,-0.011513294,12.117646,11.076022,217.61513,-9.364789
76.8,0.98419178,-0.18282583,66.53978,0,11.076097,230.31561,-0.012143144,12.683236,11.075744,223.26292,-9.3629322
78.0,0.98260337,-0.18832394,67.708405,0,11.076097,233.91562,-0.012464987,12.663633,11.076135,229.9808,-9.3609743
79.2,0.98716307,-0.19559407,67.708748,0,11.076097,237.51561,-0.012954085,12.734651,11.075576,237.16881,-9.3589382
80.4,0.98600185,-0.20116021,66.498398,0,11.076097,241.11563,-0.01333361,12.717607,11.076122,244.3132,-9.3571329
81.6,0.98738092,-0.20944615,64.382202,0,11.076097,244.71561,-0.013862014,12.750193,11.077395,250.51836,-9.3550491
82.8,0.96820366,-0.21157511,61.225391,0,11.076097,248.31561,-0.014011903,12.49102,11.075169,255.99084,-9.3527546
84.0,0.9658193,-0.21328864,57.557102,0,11.076097,251.9156,-0.014128805,12.471901,11.075562,259.75107,-9.350955
85.2,0.95071393,-0.21454817,53.832188,0,11.076097,255.51563,-0.01422142,12.268419,11.07574,262.05856,-9.348423
86.4,0.92464751,-0.21457963,51.570396,0,11.076097,259.11588,-0.014187633,11.935205,11.075806,263.02081,-9.3466501
87.6,0.90684688,-0.21410342,51.569805,0,11.076097,262.71561,-0.014162023,11.726992,11.076425,263.04971,-9.3442535
88.8,0.90341282,-0.21437021,54.061729,0,11.076097,266.31561,-0.014207573,11.676258,11.076262,262.99905,-9.3424768
90.0,0.91129345,-0.21803577,57.773941,0,11.076097,269.91559,-0.014405542,11.7781,11.075259,263.76852,-9.3402128
91.2,0.92441118,-0.22113574,61.408291,0,11.076097,273.51559,-0.014622554,11.952332,11.076881,265.86093,-9.3381739
92.4,0.95806676,-0.22520256,64.35437,0,11.076097,277.1156,-0.014920876,12.366588,11.07529,269.50714,-9.3359737
93.6,0.98342639,-0.2338829,66.535828,0,11.076097,280.71561,-0.015461971,12.712697,11.077,274.39862,-9.3340559
94.8,0.98454481,-0.23816608,67.708397,0,11.076097,284.31558,-0.015748128,12.741184,11.076426,280.27557,-9.3320742
96.0,0.98641318,-0.2440304,67.915161,0,11.076097,287.91559,-0.016157737,12.762418,11.075846,286.81973,-9.3299084
97.2,0.99870926,-0.25338662,67.276062,0,11.076097,291.51559,-0.016754491,12.942734,11.075027,293.13614,-9.3285379
98.4,0.98410821,-0.25708789,65.677956,0,11.076097,295.1156,-0.01699177,12.74004,11.07564,299.66623,-9.3262787
99.6,0.98209536,-0.26063186,63.369492,0,11.076097,298.71561,-0.017224997,12.740131,11.075577,305.00409,-9.32409
100.8,0.9824602,-0.26569265,60.567577,0,11.076097,302.31558,-0.017565688,12.73207,11.076681,309.00229,-9.321907
102.0,0.95116997,-0.26544261,58.077538,0,11.076097,305.91562,-0.017525582,12.314184,11.075999,311.32687,-9.320591
103.2,0.94767249,-0.26563022,56.434235,0,11.076097,309.51563,-0.017549409,12.279968,11.076719,312.7041,-9.3182783
104.4,0.948282,-0.26854789,56.425785,0,11.076097,313.1156,-0.017764691,12.28315,11.076476,313.51624,-9.3164139
105.6,0.92150998,-0.26885164,58.055065,0,11.076097,316.71561,-0.017746368,11.947171,11.076487,314.32388,-9.3141365
106.8,0.95601892,-0.27051121,60.296719,0,11.076097,320.31561,-0.01787119,12.395006,11.074743,315.6958,-9.3123741
108.0,0.96976978,-0.27694693,62.89706,0,11.076097,323.91562,-0.018318404,12.572359,11.076022,318.04446,-9.3105173
109.2,0.97719568,-0.27970996,65.1063,0,11.076097,327.51559,-0.018455692,12.68158,11.076028,321.41116,-9.3083153
110.4,0.99268883,-0.2844553,66.883224,0,11.076097,331.11563,-0.018786578,12.875221,11.075602,325.72568,-9.3057089
111.6,1.0005842,-0.29279527,68.038094,0,11.076097,334.71561,-0.019359501,12.986072,11.076122,330.97342,-9.3041077
112.8,0.98354083,-0.29731908,68.510742,0,11.076097,338.31564,-0.019617621,12.766387,11.07549,336.57297,-9.3017321
114.0,0.98580086,-0.30319747,68.356979,0,11.076097,341.91562,-0.020002773,12.79744,11.076886,342.20157,-9.2993832
115.2,0.99460202,-0.30798408,67.588257,0,11.076097,345.51563,-0.020330355,12.926398,11.076464,347.5434,-9.2974987
116.4,0.98942506,-0.31413811,66.545403,0,11.076097,349.1156,-0.020734403,12.870387,11.076322,352.45349,-9.2955551
117.6,0.98077631,-0.31690648,65.121193,0,11.076097,352.71564,-0.020891173,12.748734,11.076575,356.70663,-9.2935705
118.8,0.98197651,-0.31965435,63.651947,0,11.076097,356.31561,-0.021069298,12.76739,11.077234,360.25867,-9.2913685
120.0,0.98353648,-0.32148367,62.545937,0,11.076097,359.91449,-0.021233412,12.797059,11.076502,363.03674,-9.2892609
121.2,0.99058169,-0.32520685,60.114925,0,11.076097,359.99924,-0.021428488,12.898579,11.07638,365.35956,-9.2892666
122.4,0.98010409,-0.32463387,56.750401,0,11.076097,359.99924,-0.021399125,12.757924,11.076082,366.72595,-9.2895098
123.6,0.95817095,-0.32364094,52.685406,0,11.076097,359.99924,-0.021361545,12.469766,11.076424,366.76828,-9.2895136
124.8,0.94330835,-0.32113668,48.846039,0,11.076097,359.99924,-0.02117572,12.258634,11.076046,365.43707,-9.2896633
126.0,0.90992075,-0.31962344,46.583797,0,11.076097,359.99924,-0.021075612,11.826692,11.076706,362.96619,-9.2892761
127.2,0.88863742,-0.31550598,47.05444,0,11.076097,359.99924,-0.020821784,11.538514,11.075851,359.81638,-9.2891827
128.4,0.87951976,-0.31402749,50.030781,0,11.076097,359.99924,-0.020729655,11.432267,11.075562,357.00955,-9.289361
129.6,0.88956201,-0.31319505,53.636715,0,11.076097,359.99924,-0.020651866,11.554514,11.07629,354.99118,-9.2895422
130.8,0.91559017,-0.31572536,56.953461,0,11.076097,359.99924,-0.020828307,11.909505,11.076318,354.40222,-9.2891941
132.0,0.91835099,-0.31669962,59.486504,0,11.076097,359.99924,-0.020923132,11.920761,11.076692,354.96652,-9.2888546
133.2,0.94329476,-0.31974325,61.00124,0,11.076097,359.99924,-0.021067435,12.266586,11.076612,356.53867,-9.2888069
134.4,0.96892595,-0.32201797,61.340454,0,11.076097,359.99924,-0.021232404,12.610789,11.076298,358.69583,-9.2887259
135.6,0.98944515,-0.32534865,60.788193,0,11.076097,359.99924,-0.021485584,12.866701,11.075198,361.04218,-9.2887392
136.8,0.97024518,-0.32787126,59.184498,0,11.076097,359.99924,-0.021607645,12.631871,11.076426,363.18677,-9.2886791
138.0,0.94818878,-0.32823122,56.80621,0,11.076097,359.99924,-0.021648213,12.333057,11.076058,364.63187,-9.2887783
139.2,0.93368202,-0.32777086,54.010021,0,11.076097,359.99924,-0.021618912,12.142192,11.075326,364.79187,-9.2891588
140.4,0.91562206,-0.3266845,51.301804,0,11.076097,359.99924,-0.021556912,11.908896,11.075607,364.05716,-9.2885885
141.6,0.89397568,-0.32493302,49.651154,0,11.076097,359.99924,-0.021415316,11.627475,11.076168,362.37891,-9.2888632
142.8,0.88342357,-0.32400644,49.636234,0,11.076097,359.99924,-0.021364976,11.514621,11.076724,360.28363,-9.2884693
144.0,0.87174356,-0.32408023,51.196136,0,11.076097,359.99924,-0.021398084,11.341623,11.075747,358.24478,-9.2883644
145.2,0.87861544,-0.32322791,53.645554,0,11.076097,359.99924,-0.021293275,11.446488,11.075782,356.6749,-9.2881804
146.4,0.89784145,-0.32313845,56.119114,0,11.076097,359.99924,-0.021311412,11.672123,11.076143,355.96207,-9.2883997
147.6,0.9061175,-0.3241947,58.071102,0,11.076097,359.99924,-0.02138564,11.770848,11.076153,356.22253,-9.2885571
148.8,0.91736525,-0.32706612,59.348087,0,11.076097,359.99924,-0.021574672,11.937839,11.075158,357.15085,-9.2885818
150.0,0.9177717,-0.33022025,59.842525,0,11.076097,359.99924,-0.02176002,11.939609,11.076724,358.71948,-9.2889738
151.2,0.92472678,-0.33243892,59.602867,0,11.076097,359.99924,-0.021918572,12.039477,11.076126,360.38272,-9.2885618
152.4,0.92646623,-0.33263931,58.590805,0,11.076097,359.99924,-0.021951394,12.060198,11.076418,361.98294,-9.2890234
153.6,0.91221946,-0.3328208,56.987415,0,11.076097,359.99924,-0.021931348,11.873317,11.075905,363.08499,-9.2883997
154.8,0.90398377,-0.33286756,54.934322,0,11.076097,359.99924,-0.021940686,11.767733,11.076806,363.5209,-9.288455
156.0,0.8993113,-0.33303145,52.976879,0,11.076097,359.99924,-0.021969656,11.699873,11.076698,363.21811,-9.2884293
157.2,0.87851298,-0.33258799,51.569859,0,11.076097,359.99924,-0.02193105,11.444267,11.07499,362.1087,-9.2885132
158.4,0.86365378,-0.33187991,51.196293,0,11.076097,359.99924,-0.021886945,11.237166,11.075965,360.70261,-9.288084
159.6,0.87213999,-0.33010507,51.916409,0,11.076097,359.99924,-0.021765018,11.348617,11.075661,359.25949,-9.2882805
160.8,0.85704559,-0.32984009,53.225349,0,11.076097,359.99924,-0.02175946,11.151697,11.076526,358.12714,-9.2878418
162.0,0.87029171,-0.330073,54.659191,0,11.076097,359.99924,-0.021746075,11.333513,11.076503,357.53809,-9.2882891
163.2,0.88721454,-0.33215284,56.222939,0,11.076097,359.99924,-0.0218956,11.532049,11.075725,357.38788,-9.2882824
164.4,0.89842945,-0.3309553,57.519367,0,11.076097,359.99924,-0.021842279,11.69882,11.077404,357.86761,-9.2883654
165.2814,0.88854307,0.0017579293,57.810059,0,11.076099,2.5665329,-6.4395972e-05,11.323266,11.075606,358.51019,-9.2890224
165.2838,0.95084625,0.0045351353,57.810059,0,11.076099,1.1095114000000001e-16,0.00026025524,12.163003,11.081291,358.48831,-9.2891178
165.2862,0.90718895,0.0023645083,57.810059,0,11.076099,4.7964155e-33,0.00035421949,11.566729,11.076216,358.46646,-9.2884064
165.2886,0.90415275,0.0018433807,47.962475,0,11.076099,0.0,0.0003430263,11.501958,11.074064,358.47559,-9.2882652
165.291,0.98320061,0.0069539719,34.060253,0,11.076099,0.0,0.00039963762,12.552874,11.073414,358.49744,-9.2889128
165.2934,0.9116658,0.010336663,20.158037,0,11.076099,0.0,0.00031285861,11.645102,11.07494,358.51932,-9.2893229
165.2958,0.92406744,0.0095094414,6.2558184,0,11.076099,0.0,0.00050327514,11.786969,11.07491,358.5412,-9.2879143
165.2982,0.903552,0.0051641162,0.0,0,11.076099,0.0,0.00053387723,11.515948,11.075208,358.56705,-9.2872381
165.3006,0.90159309,0.00086673029,0.0,0,11.076099,0.0,0.00029044648,11.527292,11.077945,358.59622,-9.288518
165.303,0.90868461,0.0025753002,0.0,0,11.076099,0.0,7.188032e-05,11.511681,11.077355,358.62537,-9.2883444
165.3054,0.9123466,0.0032228376,0.0,0,11.076099,0.0,6.9720656e-05,11.611411,11.077684,358.65451,-9.2884874
165.3078,0.89846188,0.0036799472,0.0,0,11.076099,0.0,0.0002509804,11.534258,11.077435,358.66937,-9.2872143
165.3102,0.90278441,0.0022951441,0.0,0,11.076099,0.0,0.00032193257,11.374286,11.074676,358.66208,-9.2886925
165.3126,0.89971596,0.0014720111,0.0,0,11.076099,0.0,0.00023291349,11.471888,11.075992,358.65479,-9.2878656
165.315,0.90983832,0.0040201712,0.0,0,11.076099,0.0,0.00016647983,11.592441,11.077537,358.64749,-9.2888775
165.3174,0.90300775,0.0083168615,0.0,0,11.076099,0.0,0.0002408341,11.531047,11.073649,358.64529,-9.288825
165.3198,0.88987499,0.0078312857,0.0,0,11.076099,0.0,0.00044049218,11.439577,11.075715,358.65988,-9.2892704
165.3222,0.88550287,0.0030641095,0.0,0,11.076099,0.0,0.0004452579,11.284149,11.077609,358.67447,-9.2892437
165.3246,0.89970994,-0.00028333161,0.0,0,11.076099,0.0,0.00018352273,11.33158,11.077982,358.68903,-9.2888985
165.327,0.9070577,0.0028437092,0.0,0,11.076099,0.0,0.00011447696,11.595123,11.073089,358.70251,-9.2899399
165.3294,0.89174944,0.0039504864,0.0,0,11.076099,0.0,0.0001290184,11.305538,11.078296,358.70251,-9.2897406
165.3318,0.89407414,0.0062294221,0.0,0,10.976469,0.0,0.0003739135,11.330359,11.073076,358.70251,-9.2888241
165.3342,0.88552219,0.0029180124,0.0,0,10.615495,0.0,0.00041355027,11.280888,11.070009,358.70251,-9.2892609
165.3366,0.892564,0.002893111,0.0,0,10.254521,0.0,0.00031847769,11.352537,11.055861,358.70251,-9.2896738
165.339,0.91736507,0.0036271801,0.0,0,9.893548,0.0,0.00014184146,11.687139,10.928899,360.72388,-9.2889767
165.3414,0.86003929,0.007887735,0.0,0,9.5325737,0.0,0.00019274588,11.010999,10.647186,362.92896,-9.2884464
165.3438,0.90350431,0.0072058039,0.0,0,9.1800261,0.0,0.00038301732,11.547045,10.258209,365.13403,-9.2889528
165.3462,6.8444228,0.23548347,0.0,0,8.8288584,0.0,0.015098809,85.369682,9.8318949,367.33911,-9.2847662
165.3486,8.1856813,0.68216717,0.0,0,8.4910259,0.0,0.046483763,99.100845,9.3386583,369.28506,-9.2835903
165.351,8.7424917,1.112813,0.0,0,8.1570415,0.0,0.076655589,102.84069,8.880434,371.14844,-9.2819166
165.3534,8.9021034,1.5177938,0.0,0,7.8342957,0.0,0.10592543,101.68789,8.4975519,373.01178,-9.2820749
165.3558,9.2513237,1.8429265,0.0,0,7.5165353,0.0,0.13063005,103.35479,8.1555548,374.87515,-9.2814617
165.3582,9.4167509,2.146642,0.0,0,7.2082515,0.0,0.15440658,102.68462,7.8228102,375.02722,-9.2819977
165.3606,9.6694746,2.4522488,0.0,0,6.9060431,0.0,0.17824043,103.1189,7.5163174,374.03845,-9.2847996
165.363,9.8727398,2.746233,0.0,0,6.6115613,0.0,0.20163691,102.64795,7.221149,373.04971,-9.2833023
165.3654,10.188556,3.0311136,0.0,0,6.3240418,0.0,0.22486794,103.58719,6.9349275,372.06094,-9.2821569
165.3678,10.384303,3.3143523,0.0,0,6.042748,0.0,0.24920593,103.06771,6.6490211,371.19101,-9.2813768
165.3702,10.637112,3.5955944,0.0,0,5.7692914,0.0,0.27410457,102.96373,6.3619909,370.47128,-9.2828169
165.3726,10.893124,3.8780248,0.0,0,5.5006137,0.0,0.29900455,102.84406,6.0746946,369.75153,-9.282649
165.375,11.172927,4.1595335,0.0,0,5.2404532,0.0,0.32410389,102.83067,5.7945361,369.0318,-9.282198
165.3774,11.449938,4.4385114,0.0,0,4.9838042,0.0,0.3500897,102.73257,5.5120749,367.76831,-9.2823038
165.3798,11.715092,4.7136388,0.0,0,4.7363639,0.0,0.37681401,102.3661,5.2419653,365.12961,-9.2825928
165.3822,11.962615,4.9778399,0.0,0,4.4912457,0.0,0.40331429,101.73876,4.970202,362.49088,-9.2814217
165.3846,12.270844,5.2394032,0.0,0,4.2558532,0.0,0.42959964,101.57779,4.7077937,359.85217,-9.2818794
165.387,12.57796,5.4990363,0.0,0,4.0217257,0.0,0.45583004,101.43436,4.4571805,357.28467,-9.2815285
165.3894,12.885322,5.7481265,0.0,0,3.7978494,0.0,0.48210308,101.26534,4.2084761,355.21548,-9.2827349
165.3918,13.211504,5.987432,0.0,0,3.5743496,0.0,0.50884885,101.06539,3.9654391,353.1463,-9.2813826
165.3942,13.536359,6.2135286,0.0,0,3.3612847,0.0,0.53504151,100.87351,3.7340767,351.07715,-9.2818279
165.3966,13.916654,6.437367,0.0,0,3.1483088,0.0,0.56062913,101.1723,3.5096796,349.00797,-9.2812672
165.399,14.304292,6.6576266,0.0,0,2.9451065,0.0,0.58582145,101.3706,3.2927258,348.83307,-9.2805653
165.4014,14.675787,6.8715343,0.0,0,2.7424984,0.0,0.61176652,101.34976,3.0780604,348.72345,-9.2806377
165.4038,15.085714,7.0768089,0.0,0,2.5483873,0.0,0.63780862,101.48141,2.8727705,348.61383,-9.2803106
165.4062,15.556482,7.2725053,0.0,0,2.3556671,0.0,0.66351748,101.93621,2.6754394,348.50421,-9.280201
165.4086,16.048084,7.4702239,0.0,0,2.1702483,0.0,0.68929613,102.49457,2.4747429,346.95343,-9.2798557
165.411,16.550409,7.6665068,0.0,0,1.9869361,0.0,0.71456301,103.11428,2.2825913,345.06094,-9.2795286
165.4134,17.087881,7.8611417,0.0,0,1.8098084,0.0,0.74091959,103.63205,2.0916631,343.16846,-9.279459
165.4158,17.66497,8.0449305,0.0,0,1.6354244,0.0,0.76819879,104.26179,1.9094625,341.276,-9.2788801
165.4182,18.288067,8.2200632,0.0,0,1.4662173,0.0,0.79464972,105.09312,1.7287992,340.19568,-9.2780619
165.4206,18.94552,8.3939314,0.0,0,1.3003293,0.0,0.82003373,106.15035,1.5537158,339.55264,-9.2781286
165.423,19.629622,8.5701628,0.0,0,1.1387084,0.0,0.84602755,107.21928,1.3785228,338.90961,-9.2790813
165.4254,20.361753,8.7427454,0.0,0,0.98093235,0.0,0.87316811,108.18925,1.2091999,338.26657,-9.2784891
165.4278,21.172838,8.9082966,0.0,0,0.82657731,0.0,0.90096247,109.39858,1.0405772,338.24149,-9.2775011
165.4302,22.020876,9.0636892,0.0,0,0.67652941,0.0,0.92761779,110.78324,0.87785876,338.85529,-9.2773752
165.4326,22.894726,9.2197161,0.0,0,0.52908593,0.0,0.95362484,112.27222,0.71790701,339.46909,-9.2759647
165.435,23.785667,9.3753977,0.0,0,0.3862859,0.0,0.97954333,113.63143,0.56369019,340.08292,-9.276535
165.4374,21.531097,9.4257126,0.0,0,0.24542016,0.0,0.98853618,102.2555,0.46835268,341.00821,-9.2776022
165.4398,19.738575,9.4384995,0.0,0,0.10962815,0.0,0.99232507,93.307877,0.42996436,342.55646,-9.2792263
165.4422,18.953192,9.4392252,0.0,0,-0.025516368,0.0,0.99350274,89.448906,0.40656787,344.10474,-9.2801256
165.4446,18.601086,9.4461555,0.0,0,-0.15794842,0.0,0.99404693,87.644806,0.37868005,345.65302,-9.2817793
165.447,18.745977,9.4544334,0.0,0,-0.29038045,0.0,0.99423426,88.306252,0.3210215,347.37857,-9.2818537
165.4494,18.937914,9.4618559,0.0,0,-0.42281243,0.0,0.99556762,89.102959,0.26102492,349.93991,-9.2817249
165.4518,18.987921,9.4655342,0.0,0,-0.55524439,0.0,0.99722803,89.17173,0.19385479,352.50125,-9.2808189
165.4542,18.930126,9.466548,0.0,0,-0.68767637,0.0,0.99839747,88.809998,0.13440694,355.06262,-9.2807932
165.4566,18.780895,9.4740982,0.0,0,-0.82010835,0.0,0.99907124,88.080925,0.084471084,357.60992,-9.2822266
165.459,18.517019,9.4824591,0.0,0,-0.9525404,0.0,0.99903709,86.853607,0.043960653,359.32941,-9.2828255
165.4614,18.095373,9.4905062,0.0,0,-1.0849724,0.0,1.0002022,84.767113,0.018139511,361.04892,-9.2807665
165.4638,17.548843,9.4900932,0.0,0,-0.72870702,359.99997,1.001821,82.093613,0.010692844,362.7684,-9.2813396
165.4662,16.991673,9.4825878,0.0,0,-0.27022067,359.99997,1.0015548,79.494881,0.017334394,364.48792,-9.2827616
165.4686,16.50366,9.481699,0.0,0,0.18826568,359.99997,1.0003239,77.327126,0.020950191,365.82468,-9.2824726
165.471,16.139246,9.4894295,0.0,0,0.64675206,359.99997,1.0006597,75.551216,0.02261341,367.0983,-9.283597
165.4734,15.830029,9.4913092,0.0,0,1.1052387,359.99997,1.0008721,74.126282,0.022289671,368.37192,-9.2842617
165.4758,15.343075,9.4871807,0.0,0,1.563725,359.99997,1.0011102,71.810272,0.030775229,369.64551,-9.2833605
165.4782,14.040346,9.4797888,0.0,0,2.0222113,359.99997,1.0007521,65.836967,0.081253767,370.47034,-9.2850151
165.4806,11.599292,9.471736,0.0,0,2.4806981,359.99997,0.99863911,54.68409,0.19260417,371.10284,-9.287425
165.483,7.0812469,9.4578094,0.0,0,2.9391842,359.99997,0.99483311,33.790928,0.40245855,371.73535,-9.2897949
165.4854,0.37728283,9.3452806,0.0,0,3.3976707,359.99997,0.97486961,1.7607447,0.82734787,372.36786,-9.2972422
165.4878,-0.11044324,9.3109827,0.0,0,3.8561573,359.99997,0.96962237,-0.1579351,1.5308336,372.87433,-9.2949772
165.4902,-0.21502794,9.3648081,0.0,0,4.3146434,359.99997,0.98024058,-1.0606014,2.3583331,373.2742,-9.2958107
165.4926,0.69292313,9.4055271,0.0,0,4.7731299,359.99997,0.98678029,3.7002549,3.1001489,373.67407,-9.2949448
165.495,0.99175924,9.4252481,0.0,0,5.2316165,359.99997,0.98883939,4.4420843,3.6468759,374.07391,-9.2945604
165.4974,0.51736927,9.4210901,0.0,0,5.6901026,359.99997,0.98799366,2.395345,4.0702639,374.53232,-9.2940474
165.4998,0.37434715,9.4261818,0.0,0,6.1485891,359.99997,0.99032867,1.7618915,4.4850769,375.08484,-9.2929001
165.5022,0.56381387,9.4199944,0.0,0,6.6070752,359.99997,0.98996246,2.7091541,4.8983464,375.63736,-9.290844
165.5046,0.59013295,9.4195175,0.0,0,7.0655618,359.99997,0.98904824,2.783726,5.3239198,376.18991,-9.2908697
165.507,0.48232785,9.425869,0.0,0,7.5240483,359.99997,0.98885459,2.3155973,5.7765617,376.72281,-9.2907743
165.5094,0.57790262,9.4265566,0.0,0,7.9825354,359.99997,0.9890818,2.7079616,6.2567511,377.18808,-9.2912378
165.5118,0.51994687,9.4240294,0.0,0,8.441021,359.99997,0.9900195,2.4890668,6.7374234,377.65338,-9.2894096
165.5142,0.499428,9.4194489,0.0,0,8.8995075,359.99997,0.99005336,2.3673351,7.2354851,378.11868,-9.289794
165.5166,0.56486809,9.418169,0.0,0,9.3579931,359.99997,0.98867595,2.7115743,7.7180066,378.57623,-9.2903261
165.519,0.50246853,9.4234791,0.0,0,9.8164806,359.99997,0.98856133,2.3942118,8.1930285,378.9252,-9.289012
165.5214,0.5221805,9.4265594,0.0,0,10.274966,359.99997,0.98928201,2.4304156,8.6590176,379.27417,-9.2896557
165.5238,0.54638016,9.4217911,0.0,0,10.733453,359.99997,0.98953044,2.5771892,9.1303349,379.62314,-9.2895479
165.5262,0.52464914,9.4174032,0.0,0,11.191939,359.99997,0.98957777,2.5278282,9.5892382,379.97211,-9.2888584
165.5286,0.50743836,9.4197788,0.0,0,11.650426,359.99997,0.98923242,2.3262496,10.065653,380.30115,-9.2882929
165.531,0.55561292,9.4237499,0.0,0,12.108912,359.99997,0.98836774,2.6341732,10.540227,380.62817,-9.2877216
165.5334,0.52226108,9.4287596,0.0,0,12.567399,359.99997,0.98938787,2.4932902,11.006338,380.95517,-9.2879448
165.5358,0.51753962,9.4250908,0.0,0,13.025885,359.99997,0.99021196,2.4054799,11.479465,381.2822,-9.288106
165.5382,0.56097305,9.4181566,0.0,0,13.484371,359.99997,0.98973739,2.6314523,11.935598,381.61258,-9.2875547
165.5406,0.525626,9.4161863,0.0,0,13.942858,359.99997,0.98848462,2.5047364,12.391845,381.94409,-9.2883844
165.543,0.54340261,9.4233284,0.0,0,14.401344,359.99997,0.98843884,2.6024253,12.868616,382.2756,-9.2880898
165.5454,0.57637024,9.427043,0.0,0,14.859831,359.99997,0.98949045,2.7769756,13.339889,382.60712,-9.2869234
165.5478,0.44002208,9.4226255,0.0,0,15.318317,359.99997,0.9898147,2.1348071,13.812716,382.85577,-9.2873926
165.5502,0.54793704,9.4149227,0.0,0,15.776803,359.99997,0.98910475,2.5895126,14.289693,383.08792,-9.2866669
165.5526,0.57523835,9.4173927,0.0,0,16.235291,359.99997,0.9884575,2.7231214,14.757945,383.32004,-9.2868214
165.555,0.50398105,9.4244146,0.0,0,16.693775,359.99997,0.98847777,2.392029,15.214787,383.55215,-9.2868929
165.5574,0.53926814,9.4278555,0.0,0,17.152262,359.99997,0.98933589,2.5677726,15.684901,383.77448,-9.2872791
165.5598,0.56251186,9.4209347,0.0,0,17.61075,359.99997,0.98969924,2.6986008,16.146317,383.9921,-9.2872639
165.5622,0.46711069,9.4187613,0.0,0,17.999975,359.99997,0.98977703,2.203748,16.59495,384.20972,-9.2859306
165.5646,0.5505293,9.4175959,0.0,0,18.0,359.99997,0.98852551,2.5953486,17.049707,384.42731,-9.2857094
165.567,0.51619589,9.424366,0.0,0,18.0,359.99997,0.98859096,2.4708209,17.476425,384.63745,-9.2849941
165.5694,0.54703927,9.4250813,0.0,0,18.0,359.99997,0.98906749,2.5690651,17.855024,384.84055,-9.2860603
165.5718,0.59876376,9.4197989,0.0,0,18.0,359.99997,0.98943174,2.8107913,18.172096,385.04364,-9.2892838
165.5742,0.63420081,9.4156408,0.0,0,18.0,359.99997,0.98919392,2.9742706,18.396021,385.24677,-9.2929449
165.5766,0.63829511,9.4195461,0.0,0,18.0,359.99997,0.98890036,3.0506525,18.507292,385.44727,-9.297514
165.579,0.72536826,9.4256783,0.0,0,18.0,359.99997,0.98861253,3.4723511,18.486952,385.6431,-9.3038387
165.5814,0.60973781,9.4280653,0.0,0,18.0,359.99997,0.98940814,2.8718047,18.362928,385.83896,-9.3124857
165.5838,0.66897005,9.4210577,0.0,0,18.0,359.99997,0.98987895,3.1168301,18.227407,386.03482,-9.3253708
165.5862,0.69321126,9.4154921,0.0,0,18.0,359.99997,0.98929173,3.3108306,18.113962,386.22052,-9.340517
165.5886,0.71786606,9.4189415,0.0,0,18.0,359.99997,0.98873425,3.3496265,18.039213,386.3656,-9.3588858
165.591,0.638987,9.420928,0.0,0,18.0,359.99997,0.98799086,3.058831,18.019917,386.51065,-9.378809
165.5934,0.62468964,9.417655,0.0,0,18.0,359.99997,0.98774415,2.9639497,18.023312,386.65573,-9.4001532
165.5958,0.61555177,9.4129105,0.0,0,18.0,359.99997,0.98815143,2.9297888,18.043583,386.80051,-9.4187613
165.5982,0.71254039,9.4080677,0.0,0,18.0,359.99997,0.98782057,3.3531663,18.075018,386.93832,-9.4383106
165.6006,0.65991187,9.4136744,0.0,0,18.0,359.99997,0.98767656,3.1446376,18.101505,387.07614,-9.4559698
165.603,0.62975407,9.4209871,0.0,0,18.0,359.99997,0.98774129,3.0086687,18.119781,387.21396,-9.4741354
165.6054,0.62152928,9.4223652,0.0,0,18.0,359.99997,0.98854983,2.9555392,18.128229,387.35178,-9.4923124
165.6078,0.689807,9.4198093,0.0,0,18.0,359.99997,0.98965824,3.2607799,18.13159,387.46396,-9.5091982
165.6102,0.71077347,9.4150152,0.0,0,18.0,359.99997,0.98918176,3.3596292,18.134056,387.57278,-9.52635
165.6126,0.67077249,9.4138079,0.0,0,18.0,359.99997,0.98776507,3.1961603,18.133116,387.68158,-9.5444317
165.615,0.62848872,9.4187946,0.0,0,18.0,359.99997,0.98779613,3.02212,18.129499,387.79041,-9.5613708
165.6174,0.66033602,9.4192724,0.0,0,18.0,359.99997,0.98810595,3.0886631,18.127106,387.87817,-9.578269
165.6198,0.71001911,9.4164019,0.0,0,18.0,359.99997,0.98873657,3.3280005,18.125298,387.95795,-9.5957336
165.6222,0.6963352,9.4147205,0.0,0,18.0,359.99997,0.9887749,3.3029547,18.121861,388.03775,-9.614069
165.6246,0.63846099,9.4141512,0.0,0,18.0,359.99997,0.98761833,3.0162187,18.117006,388.11755,-9.6305618
165.627,0.63714373,9.4169483,0.0,0,18.0,359.99997,0.98713982,2.9998755,18.111448,388.20969,-9.6479607
165.6294,0.69701654,9.4200315,0.0,0,18.0,359.99997,0.9880721,3.2845271,18.111128,388.31122,-9.6640034
165.6318,0.71508563,9.4158068,0.0,0,18.0,359.99997,0.98906606,3.3701334,18.107645,388.41278,-9.6834564
165.6342,0.66714424,9.4136133,0.0,0,18.0,359.99997,0.98880345,3.2036202,18.107674,388.51431,-9.7010126
165.6366,0.63216853,9.4128065,0.0,0,18.0,359.99997,0.98742187,3.0001078,18.103592,388.60107,-9.7181273
165.639,0.65737373,9.4173956,0.0,0,18.0,359.99997,0.98742104,3.0886352,18.100723,388.66635,-9.7359962
165.6414,0.71157956,9.4214497,0.0,0,18.0,359.99997,0.98863482,3.3631532,18.10014,388.73163,-9.7543745
165.6438,0.68338525,9.4147377,0.0,0,18.0,359.99997,0.98859835,3.282505,18.097469,388.79694,-9.7731895
165.6462,0.63644564,9.4125557,0.0,0,18.0,359.99997,0.98852646,3.0344737,18.097317,388.85858,-9.7909632
165.6486,0.64012593,9.4141397,0.0,0,18.0,359.99997,0.98754781,3.0082643,18.095615,388.90936,-9.8085985
165.651,0.68489397,9.4205379,0.0,0,18.0,359.99997,0.98765981,3.2185318,18.09622,388.96014,-9.8253527
165.6534,0.70897299,9.42418,0.0,0,18.0,359.99997,0.98887002,3.3754003,18.094978,389.01093,-9.8426142
165.6558,0.66362596,9.4187164,0.0,0,18.0,359.99997,0.98963946,3.1916084,18.095551,389.06036,-9.8589344
165.6582,0.62779802,9.4125624,0.0,0,18.0,359.99997,0.98885608,2.9602494,18.094942,389.09662,-9.8755112
165.6606,0.64198035,9.4138842,0.0,0,18.0,359.99997,0.98750293,3.0449138,18.092812,389.1329,-9.893609
165.663,0.70641547,9.4172955,0.0,0,18.0,359.99997,0.98740232,3.3393934,18.094864,389.16916,-9.9118652
165.6654,0.69388467,9.4195242,0.0,0,18.0,359.99997,0.98828638,3.326025,18.095533,389.20544,-9.931263
165.6678,0.62793165,9.4139585,0.0,0,18.0,359.99997,0.98862946,2.9788506,18.089708,389.22141,-9.9485464
165.6702,0.63249344,9.4104109,0.0,0,18.0,359.99997,0.98823118,3.006067,18.092743,389.2359,-9.9663134
165.6726,0.68943757,9.4154406,0.0,0,18.0,359.99997,0.98781019,3.2410796,18.091543,389.25043,-9.9827538
165.675,0.71962434,9.4249125,0.0,0,18.0,359.99997,0.98825836,3.3800273,18.091599,389.26492,-9.9996185
165.6774,0.6809237,9.4243937,0.0,0,18.0,359.99997,0.98901451,3.2352445,18.089306,389.33002,-10.017943
165.6798,0.63831788,9.4156942,0.0,0,18.0,359.99997,0.9891156,3.0564435,18.090107,389.40982,-10.036188
165.6822,0.65207559,9.4106321,0.0,0,18.0,359.99997,0.98833227,3.072403,18.090315,389.48959,-10.053434
165.6846,0.72140449,9.4146328,0.0,0,18.0,359.99997,0.98758703,3.4031277,18.088104,389.5694,-10.070181
165.687,0.71982312,9.4206648,0.0,0,18.0,359.99997,0.98796999,3.4061775,18.081467,389.64023,-10.088366
165.6894,0.6598199,9.4235868,0.0,0,18.0,359.99997,0.98906052,3.1225705,18.084579,389.70554,-10.107272
165.6918,0.64413995,9.416503,0.0,0,18.0,359.99997,0.98905319,3.0417612,18.084114,389.77081,-10.123883
165.6942,0.68380028,9.4117174,0.0,0,18.0,359.99997,0.98840928,3.2393,18.081232,389.83609,-10.139157
165.6966,0.74765384,9.4189653,0.0,0,18.0,359.99997,0.98824179,3.5093668,18.083981,389.86813,-10.156968
165.699,0.6909734,9.4239655,0.0,0,18.0,359.99997,0.98816961,3.3056974,18.080929,389.8609,-10.17443
165.7014,0.64357013,9.4232006,0.0,0,18.0,359.99997,0.98886126,3.0550492,18.080416,389.85364,-10.191229
165.7038,0.66692913,9.4171104,0.0,0,18.0,359.99997,0.98942852,3.1132057,18.081675,389.84637,-10.210595
165.7062,0.72792286,9.4139223,0.0,0,18.0,359.99997,0.98880863,3.4351759,18.078251,389.84131,-10.228747
165.7086,0.7077803,9.4163227,0.0,0,18.0,359.99997,0.98783374,3.3826354,18.077108,389.84131,-10.246554
165.711,0.66480035,9.4207029,0.0,0,18.0,359.99997,0.9879567,3.1642857,18.075617,389.84131,-10.264235
165.7134,0.64218527,9.4207449,0.0,0,18.0,359.99997,0.98865747,3.0378013,18.074837,389.84131,-10.28026
165.7158,0.7014429,9.4157858,0.0,0,18.0,359.99997,0.98903477,3.2882848,18.077501,389.84131,-10.298547
165.7182,0.73680329,9.4133167,0.0,0,18.0,359.99997,0.98851556,3.4883635,18.077353,389.84131,-10.317311
165.7206,0.68781805,9.418396,0.0,0,18.0,359.99997,0.98821783,3.2940197,18.073774,389.84131,-10.335093
165.723,0.63020372,9.4245367,0.0,0,18.0,359.99997,0.98834711,3.0034492,18.073513,389.84131,-10.351748
165.7254,0.66589814,9.4240484,0.0,0,18.0,359.99997,0.98925668,3.1276746,18.074827,389.84131,-10.369423
165.7278,0.72047561,9.4201021,0.0,0,18.0,359.99997,0.98967463,3.3868175,18.074228,389.83417,-10.385766
165.7302,0.71756047,9.413806,0.0,0,18.0,359.99997,0.98878407,3.3921132,18.069218,389.8269,-10.403523
165.7326,0.67266595,9.4166765,0.0,0,18.0,359.99997,0.98770267,3.2152746,18.072449,389.81964,-10.421428
165.735,0.64187044,9.4200859,0.0,0,18.0,359.99997,0.98779082,3.0318568,18.069403,389.81241,-10.437043
165.7374,0.70012575,9.4212961,0.0,0,18.0,359.99997,0.98883903,3.307415,18.068975,389.79916,-10.45425
165.7398,0.72458994,9.4145794,0.0,0,18.0,359.99997,0.9888351,3.4672792,18.068205,389.78464,-10.472134
165.7422,0.69068837,9.4156876,0.0,0,18.0,359.99997,0.98875475,3.3128481,18.068811,389.77014,-10.491855
165.7446,0.64363742,9.4196682,0.0,0,18.0,359.99997,0.98812324,3.0731885,18.067194,389.75562,-10.509674
165.747,0.66798311,9.4262333,0.0,0,18.0,359.99997,0.98845267,3.1278441,18.065712,389.74112,-10.526955
165.7494,0.72331333,9.4242611,0.0,0,18.0,359.99997,0.98922449,3.387548,18.065332,389.72662,-10.543143
165.7518,0.73261917,9.419363,0.0,0,18.0,359.99997,0.98982167,3.4621005,18.063377,389.7121,-10.562312
165.7542,0.67311382,9.4170046,0.0,0,18.0,359.99997,0.98918241,3.1943345,18.065018,389.6976,-10.57883
165.7566,0.65267867,9.4182501,0.0,0,18.0,359.99997,0.98795891,3.0457926,18.062479,389.70151,-10.59717
165.759,0.70277613,9.4214172,0.0,0,18.0,359.99997,0.98808783,3.2616308,18.064014,389.72327,-10.616278
165.7614,0.74780285,9.4219627,0.0,0,18.0,359.99997,0.98885012,3.5475862,18.062607,389.74506,-10.633237
165.7638,0.69816661,9.4173231,0.0,0,18.0,359.99997,0.98954535,3.3487611,18.061132,389.76682,-10.650401
165.7662,0.65641046,9.4143877,0.0,0,18.0,359.99997,0.98866421,3.1274309,18.057791,389.79617,-10.66748
165.7686,0.67543566,9.4223442,0.0,0,18.0,359.99997,0.98858416,3.1865139,18.058943,389.83969,-10.6854
165.771,0.73415679,9.4274406,0.0,0,18.0,359.99997,0.98869258,3.4473221,18.060661,389.88324,-10.703756
165.7734,0.7394805,9.4256134,0.0,0,18.0,359.99997,0.98971069,3.4974844,18.058128,389.92676,-10.721388
165.7758,0.67919451,9.4198456,0.0,0,18.0,359.99997,0.98989147,3.2291403,18.05735,389.95776,-10.737159
165.7782,0.65534538,9.4148607,0.0,0,18.0,359.99997,0.98881853,3.124413,18.058073,389.936,-10.753489
165.7806,0.68688333,9.4175692,0.0,0,18.0,359.99997,0.98774707,3.2473867,18.061195,389.91425,-10.770321
165.783,0.75141716,9.4216356,0.0,0,18.0,359.99997,0.98822433,3.5308807,18.056211,389.89249,-10.78948
165.7854,0.69865918,9.4218607,0.0,0,18.0,359.99997,0.9892239,3.3507767,18.057343,389.87,-10.808965
165.7878,0.65941459,9.4166498,0.0,0,18.0,359.99997,0.9895156,3.1354902,18.057283,389.82648,-10.827157
165.7902,0.66866529,9.4147739,0.0,0,18.0,359.99997,0.98872876,3.1519859,18.056692,389.78296,-10.84301
165.7926,0.72507775,9.4207602,0.0,0,18.0,359.99997,0.98819983,3.4266491,18.053396,389.73944,-10.860381
165.795,0.73136204,9.4285545,0.0,0,18.0,359.99997,0.98907155,3.5342271,18.052685,389.69589,-10.877746
165.7974,0.68438619,9.4255943,0.0,0,18.0,359.99997,0.98972678,3.2800887,18.054594,389.69046,-10.894789
165.7998,0.65029335,9.4180336,0.0,0,18.0,359.99997,0.98979467,3.0867352,18.054678,389.69046,-10.913447
165.8022,0.69659823,9.4143343,0.0,0,18.0,359.99997,0.98852891,3.2779186,18.055565,389.69046,-10.930391
165.8046,0.74897933,9.4167318,0.0,0,18.0,359.99997,0.98759919,3.5477827,18.053015,389.69046,-10.947601
165.807,0.70984697,9.4205456,0.0,0,18.0,359.99997,0.98818099,3.3814311,18.05497,389.68005,-10.96505
165.8094,0.6693747,9.4206953,0.0,0,18.0,359.99997,0.98920482,3.1979475,18.05184,389.66556,-10.983587
165.8118,0.67085052,9.4165211,0.0,0,18.0,359.99997,0.98934972,3.1458116,18.049797,389.65103,-11.000147
165.8142,0.74350834,9.4171801,0.0,0,18.0,359.99997,0.98894626,3.4920044,18.052841,389.63654,-11.018122
165.8166,0.74421251,9.4220142,0.0,0,18.0,359.99997,0.98840469,3.5267322,18.053135,389.61392,-11.03589
165.819,0.69379181,9.427784,0.0,0,18.0,359.99997,0.98881805,3.3254383,18.049288,389.58493,-11.052843
165.8214,0.65908682,9.4245691,0.0,0,18.0,359.99997,0.9897384,3.1055474,18.051687,389.55591,-11.070229
165.8238,0.70511287,9.4187422,0.0,0,18.0,359.99997,0.98985785,3.3353324,18.05286,389.52689,-11.08611
165.8262,0.75541258,9.4180784,0.0,0,18.0,359.99997,0.98925418,3.5522325,18.050926,389.50079,-11.105369
165.8286,0.71534705,9.4224911,0.0,0,18.0,359.99997,0.9885546,3.4175549,18.049044,389.47903,-11.124722
165.831,0.67719162,9.423913,0.0,0,18.0,359.99997,0.98864973,3.2463939,18.050823,389.45728,-11.141613
165.8334,0.67243123,9.419836,0.0,0,18.0,359.99997,0.98898858,3.1741326,18.049454,389.43552,-11.158237
165.8358,0.73832417,9.4166679,0.0,0,18.0,359.99997,0.98930895,3.4808629,18.047052,389.41376,-11.17567
165.8382,0.75437152,9.416563,0.0,0,18.0,359.99997,0.98865426,3.5663621,18.049006,389.39197,-11.19418
165.8406,0.69704533,9.4214411,0.0,0,18.0,359.99997,0.98818809,3.3385963,18.047237,389.37021,-11.211741
165.843,0.66113514,9.4245024,0.0,0,18.0,359.99997,0.98828804,3.1453331,18.044973,389.34845,-11.228974
165.8454,0.71597743,9.4218044,0.0,0,18.0,359.99997,0.98921722,3.3579819,18.043221,389.32669,-11.245294
165.8478,0.76360667,9.4175224,0.0,0,18.0,359.99997,0.98965669,3.574784,18.04483,389.30493,-11.26305
165.8502,0.75021821,9.41681,0.0,0,18.0,359.99997,0.98881912,3.5592093,18.047615,389.28317,-11.281182
165.8526,0.67514265,9.4187698,0.0,0,18.0,359.99997,0.98779917,3.2486608,18.041126,389.26141,-11.299534
165.855,0.66469401,9.4216557,0.0,0,18.0,359.99997,0.98824841,3.1698146,18.042486,389.23965,-11.315325
165.8574,0.75055301,9.4198236,0.0,0,18.0,359.99997,0.98896861,3.4722612,18.043026,389.2179,-11.33432
165.8598,0.75460607,9.4177246,0.0,0,18.0,359.99997,0.98954237,3.586201,18.044092,389.19614,-11.35128
166.0617,0.67930567,9.4206686,0.0,0,18.0,0.68381345,0.98893893,3.2145929,18.022985,381.81241,-11.480019
167.2617,0.62560439,9.4303675,0.0,0,18.0,2.9561132e-17,0.99078435,2.9646537,18.000238,359.75763,-11.480916
168.4617,0.60296249,9.4369917,0.0,0,18.0,1.2779231999999999e-33,0.9919439,2.8431735,17.999859,346.36133,-11.481828
169.6617,0.5804159,9.4437504,0.0,0,18.0,1.4012985e-45,0.99305868,2.743016,18.000036,335.14658,-11.482038
170.8617,0.57908916,9.4483767,0.0,0,18.0,1.4012985e-45,0.99400568,2.7259202,17.999523,325.03763,-11.482085
172.0617,0.56045115,9.45438,0.0,0,18.0,1.4012985e-45,0.99501389,2.637815,18.000553,315.69797,-11.482055
173.2617,0.56759673,9.4594164,0.0,0,18.0,1.4012985e-45,0.99596071,2.6707942,17.999422,306.79105,-11.481643
174.4617,0.56343645,9.4642792,0.0,0,18.0,1.4012985e-45,0.99678284,2.6423984,17.999966,298.03448,-11.481776
175.6617,0.55371016,9.4692345,0.0,0,18.0,1.4012985e-45,0.99774224,2.6055632,17.999802,289.73083,-11.48166
176.8617,0.56503594,9.473424,0.0,0,18.0,1.4012985e-45,0.99853605,2.6547306,18.000103,281.5556,-11.482283
178.0617,0.55603766,9.4789476,0.0,0,18.0,1.4012985e-45,0.9993999,2.6039827,17.999739,273.79291,-11.48246
179.2617,0.55439878,9.4830961,0.0,0,18.0,1.4012985e-45,1.0002874,2.6012237,17.999674,266.11572,-11.482039
180.4617,0.55475831,9.487464,0.0,0,18.0,1.4012985e-45,1.0010234,2.5905623,17.999447,258.86322,-11.481922
181.6617,0.54917932,9.4917898,0.0,0,18.0,1.4012985e-45,1.001772,2.570261,18.000271,251.5696,-11.481775
182.8617,0.56616676,9.4964533,0.0,0,18.0,1.4012985e-45,1.00264,2.6440017,18.000526,244.71443,-11.48238
184.0617,0.55591732,9.5003309,0.0,0,18.0,1.4012985e-45,1.0033722,2.5911629,17.999735,237.92268,-11.481779
185.2617,0.55531055,9.5044184,0.0,0,18.0,1.4012985e-45,1.0041536,2.590786,17.9995,231.395,-11.48198
186.4617,0.56172514,9.5091801,0.0,0,18.0,1.4012985e-45,1.0048965,2.6093647,17.999565,225.22243,-11.481992
187.6617,0.55096996,9.5123672,0.0,0,18.0,1.4012985e-45,1.0055945,2.5669029,17.998972,219.14449,-11.482174
188.8617,0.56060529,9.5159645,0.0,0,18.0,1.4012985e-45,1.0061984,2.609478,17.999283,213.20294,-11.482169
190.0617,0.54758799,9.5198975,0.0,0,18.0,1.4012985e-45,1.0069,2.5440178,18.000578,207.30995,-11.482571
191.2617,0.55126554,9.5233517,0.0,0,18.0,1.4012985e-45,1.0075605,2.5679362,18.000086,201.86804,-11.482349
192.4617,0.55505502,9.5268421,0.0,0,18.0,1.4012985e-45,1.0082042,2.5791788,17.999893,196.45566,-11.482513
193.6617,0.5480088,9.530055,0.0,0,18.0,1.4012985e-45,1.0087813,2.5432298,17.999174,191.09692,-11.48215
194.8617,0.55598366,9.5332308,0.0,0,18.0,1.4012985e-45,1.0093164,2.5825021,17.999329,186.08064,-11.482379
196.0617,0.55218256,9.5371256,0.0,0,18.0,1.4012985e-45,1.0101157,2.5591176,17.999924,181.28938,-11.481925
197.2617,0.55366623,9.5401106,0.0,0,18.0,1.4012985e-45,1.0106443,2.571594,17.999344,176.43929,-11.481862
198.4617,0.56221098,9.5432377,0.0,0,18.0,1.4012985e-45,1.0111277,2.605521,17.999863,171.79131,-11.482349
199.6617,0.55073363,9.5455761,0.0,0,18.0,1.4012985e-45,1.0116739,2.5447433,18.000261,167.34911,-11.482644
200.8617,0.55215305,9.5484476,0.0,0,18.0,1.4012985e-45,1.0121534,2.5551474,18.000151,163.07234,-11.482181
202.0617,0.55296767,9.551774,0.0,0,18.0,1.4012985e-45,1.0127566,2.552139,17.999334,158.85156,-11.482247
203.2617,0.54574651,9.5542288,0.0,0,18.0,1.4012985e-45,1.0132074,2.5282159,17.999363,154.93243,-11.482389
204.4617,0.55447656,9.557025,0.0,0,18.0,1.4012985e-45,1.0137405,2.5559671,17.999605,150.98289,-11.482409
205.6617,0.54152548,9.5592241,0.0,0,18.0,1.4012985e-45,1.0141625,2.4975727,18.000473,147.24219,-11.48217
206.8617,0.54831332,9.5617285,0.0,0,18.0,1.4012985e-45,1.0145292,2.5310378,18.00065,143.48927,-11.482145
208.0617,0.54860443,9.5642672,0.0,0,18.0,1.4012985e-45,1.0150892,2.524693,17.999065,140.01773,-11.482368
209.2617,0.54550362,9.5663023,0.0,0,18.0,1.4012985e-45,1.0154163,2.5230448,17.999786,136.49463,-11.482203
210.4617,0.55322266,9.5690498,0.0,0,18.0,1.4012985e-45,1.0159072,2.5511103,17.998852,133.18333,-11.482065
211.6617,0.53727061,9.5709219,0.0,0,18.0,1.4012985e-45,1.0163022,2.4707398,18.000097,129.88081,-11.482107
212.8617,0.54881662,9.5734959,0.0,0,18.0,1.4012985e-45,1.0167623,2.5331953,17.99999,126.83039,-11.482047
214.0617,0.55181301,9.5750504,0.0,0,18.0,1.4012985e-45,1.0170636,2.5339768,18.000299,123.67245,-11.48213
215.2617,0.54334235,9.5773506,0.0,0,18.0,1.4012985e-45,1.0174154,2.5015402,18.000284,120.67204,-11.482027
216.4617,0.55102217,9.5787764,0.0,0,18.0,1.4012985e-45,1.0177898,2.5366497,18.000116,117.77664,-11.48198
217.6617,0.53707004,9.5813971,0.0,0,18.0,1.4012985e-45,1.0182371,2.4674406,18.00032,115.09396,-11.482071
218.8617,0.54736513,9.5830841,0.0,0,18.0,1.4012985e-45,1.01846,2.5225246,18.000164,112.32224,-11.482453
220.0617,0.54980862,9.5848598,0.0,0,18.0,1.4012985e-45,1.0188808,2.5237391,17.999315,109.77129,-11.482295
221.2617,0.53356099,9.5869255,0.0,0,18.0,1.4012985e-45,1.0192151,2.4493499,17.999279,107.07381,-11.482018
222.4617,0.55432999,9.5892286,0.0,0,18.0,1.4012985e-45,1.0196484,2.5476387,17.999245,104.75909,-11.48251
223.6617,0.54673713,9.5908661,0.0,0,18.0,1.4012985e-45,1.0199401,2.5063162,17.999424,102.3028,-11.482373
224.8617,0.5375089,9.5919542,0.0,0,18.0,1.4012985e-45,1.0201769,2.4741919,17.999891,100.05776,-11.482469
225.8617,0.5441063,9.5935516,0.0,0,18.0,1.4012985e-45,1.0203917,2.4998939,18.000118,98.281281,-11.482242