File: examples/hot axisymmetric compression example/data/02 screened data/testID_0131.csv
Time(sec),Force(kN),Jaw(mm),PowAngle(deg),Power(W),Pram,PTemp,Strain,Stress(MPa),Stroke(mm),TC1(C),wedge(mm)
0.0,1.1455164,-0.53460038,0.0,0,11.076097,0.00076342945,-0.034994554,15.088841,11.0767,23.204771,-9.1261549
1.1,1.0973643,-0.0022944289,0.0,0,11.076097,3.2158809,-0.00012868676,13.977462,11.076013,23.155493,-9.4942551
2.2,1.0581852,-0.0028210806,0.0,0,11.076097,6.5158839,-0.00015910306,13.476597,11.077367,23.165699,-9.4905882
3.3,1.0389175,-0.002750668,0.0,0,11.076097,9.8158808,-0.0001534943,13.214401,11.076257,23.163116,-9.4901533
4.4,1.0147426,-0.0027199795,0.0,0,11.076097,13.115883,-0.00015283197,12.936754,11.075129,23.169203,-9.4878531
5.5,0.99932718,-0.0027366888,0.0,0,11.076097,16.415886,-0.00015178458,12.717649,11.077425,23.19532,-9.486412
6.6,0.97749937,-0.0028566248,0.0,0,11.076097,19.715883,-0.00016758217,12.452922,11.07561,23.217529,-9.4838791
7.7,0.97865021,-0.0032417502,0.0,0,11.076097,23.015886,-0.00018013868,12.468969,11.076284,23.191154,-9.481431
8.8,0.97077686,-0.0022394962,18.044676,0,11.076097,26.315886,-0.0001202928,12.347442,11.076006,23.271812,-9.4795732
9.9,0.96669841,-0.0033409344,31.829962,0,11.076097,29.615883,-0.00019919657,12.316015,11.076332,23.5417,-9.4782019
11.0,0.99074095,-0.0062575391,39.88966,0,11.076097,32.915874,-0.0003912198,12.612193,11.076146,24.890614,-9.4763899
12.1,0.99698269,-0.0095857717,44.899036,0,11.076097,36.215878,-0.00060922932,12.699234,11.075415,27.508593,-9.4750376
13.2,1.018115,-0.013194072,47.934853,0,11.076097,39.515881,-0.00086258765,12.97674,11.075766,31.368601,-9.4729881
14.3,1.0302252,-0.017308503,49.606689,0,11.076097,42.81588,-0.0011237628,13.123491,11.075913,36.016415,-9.4707565
15.4,1.0423661,-0.021751476,50.042721,0,11.076097,46.115879,-0.0014314987,13.292868,11.075686,41.259686,-9.4686632
16.5,1.0602102,-0.026162917,49.538059,0,11.076097,49.415882,-0.00172262,13.533115,11.07521,46.801678,-9.4670534
17.6,1.0595073,-0.030211262,47.95644,0,11.076097,52.715893,-0.0020038784,13.517426,11.076379,52.496132,-9.465251
18.7,1.068869,-0.033303969,45.688789,0,11.076097,56.015896,-0.002208228,13.634921,11.075993,57.793621,-9.4634447
19.8,1.0599763,-0.036437042,43.11018,0,11.076097,59.315891,-0.0024100349,13.530334,11.074975,62.493885,-9.4607124
20.9,1.0583277,-0.038338117,40.573364,0,11.076097,62.615894,-0.0025410526,13.518376,11.076066,66.460159,-9.4592953
22.0,1.0475807,-0.039842363,38.551064,0,11.076097,65.915878,-0.0026436455,13.371819,11.076102,69.629982,-9.457324
23.1,1.0438728,-0.040800475,37.371578,0,11.076097,69.215881,-0.0027190149,13.322536,11.075517,72.163513,-9.4555559
24.2,1.0277092,-0.042091746,37.836914,0,11.076097,72.515877,-0.0028111946,13.129235,11.076552,74.114288,-9.4534369
25.3,1.0310384,-0.04383263,39.918404,0,11.076097,75.815887,-0.0029266581,13.150464,11.076061,75.750969,-9.4516668
26.4,1.0209491,-0.045629453,42.38343,0,11.076097,79.115883,-0.0030397854,13.049428,11.075574,77.46862,-9.4499474
27.5,1.0370173,-0.047927961,44.928181,0,11.076097,82.415878,-0.0032005624,13.258541,11.075646,79.428215,-9.4477758
28.6,1.0502374,-0.050477218,47.085686,0,11.076097,85.715889,-0.0033719894,13.415388,11.076407,81.860649,-9.4461613
29.7,1.0586988,-0.054374956,48.812168,0,11.076097,89.015892,-0.0036353294,13.53695,11.076895,84.914154,-9.4443445
30.8,1.0754282,-0.058020215,50.040478,0,11.076097,92.315887,-0.0038714143,13.752504,11.075689,88.58654,-9.4429026
31.9,1.0790373,-0.061331984,50.438229,0,11.076097,95.615883,-0.004100753,13.797343,11.075675,92.734833,-9.4408102
33.0,1.0872834,-0.0655673,50.438236,0,11.076097,98.915894,-0.0043801167,13.906141,11.075502,97.00209,-9.4390726
34.1,1.0914868,-0.069019511,50.042728,0,11.076097,102.21589,-0.0046159052,13.951711,11.076319,101.59067,-9.4369926
35.2,1.0925266,-0.072858974,48.921539,0,11.076097,105.51589,-0.0048650843,13.994462,11.076092,106.05844,-9.4349165
36.3,1.0979779,-0.075737365,47.955433,0,11.076097,108.81588,-0.0050638863,14.055783,11.076632,110.22366,-9.4330139
37.4,1.0885878,-0.078532815,46.648026,0,11.076097,112.11588,-0.0052465415,13.920019,11.075883,114.05019,-9.4304171
38.5,1.0929694,-0.080504358,45.615814,0,11.076097,115.41588,-0.0053744996,13.985206,11.076092,117.53722,-9.4288006
39.6,1.0840594,-0.082890391,45.070881,0,11.076097,118.71588,-0.005534539,13.861055,11.075562,120.74027,-9.4266777
40.7,1.0747851,-0.085087933,45.12085,0,11.076097,122.01588,-0.0056782207,13.764002,11.076022,123.15711,-9.4247637
41.8,1.0827397,-0.086676136,45.6152,0,11.076097,125.31588,-0.0057854392,13.872921,11.075607,125.60114,-9.4229755
42.9,1.087677,-0.089092374,46.582012,0,11.076097,128.61601,-0.0059494055,13.92086,11.075558,127.89321,-9.420929
44.0,1.08384,-0.091712043,47.955132,0,11.076097,131.91588,-0.0061138347,13.892409,11.076959,130.22516,-9.4192505
45.1,1.0956023,-0.094759509,49.810436,0,11.076097,135.21588,-0.0063140825,14.030455,11.077075,132.42578,-9.4174242
46.2,1.1009163,-0.098253511,51.195889,0,11.076097,138.51588,-0.0065390435,14.116645,11.076621,135.14125,-9.4158974
47.3,1.1051489,-0.10176083,52.283913,0,11.076097,141.81587,-0.0067670266,14.183969,11.075567,138.41676,-9.4139233
48.4,1.1088809,-0.1055698,52.97607,0,11.076097,145.11589,-0.0070184567,14.212837,11.076025,142.20967,-9.4127655
49.5,1.1125892,-0.109849,53.31665,0,11.076097,148.41588,-0.0072922618,14.283861,11.075169,146.25633,-9.4105511
50.6,1.1107227,-0.11422898,52.976231,0,11.076097,151.7159,-0.007572249,14.256272,11.074643,150.61838,-9.40874
51.7,1.1138219,-0.11742397,52.58577,0,11.076097,155.01588,-0.0077783526,14.285887,11.076907,154.90935,-9.4072943
52.8,1.11895,-0.12057166,51.932377,0,11.076097,158.31587,-0.0079950346,14.363853,11.075782,158.87041,-9.4054575
53.9,1.1075693,-0.12406972,51.213757,0,11.076097,161.61589,-0.0082197897,14.216904,11.076243,162.66902,-9.4034538
55.0,1.1179535,-0.12693596,50.823338,0,11.076097,164.91589,-0.0084152436,14.368085,11.076109,166.06438,-9.4019985
56.1,1.1216617,-0.12940291,50.439354,0,11.076097,168.21588,-0.0085713658,14.404075,11.076626,169.26399,-9.400053
57.2,1.1154194,-0.13230333,50.438217,0,11.076097,171.51588,-0.0087756161,14.327237,11.076845,172.45653,-9.3976202
58.3,1.1157856,-0.1348082,50.411938,0,11.076097,174.81589,-0.008939934,14.355618,11.076345,175.40045,-9.395956
59.4,1.1188616,-0.13747707,50.554996,0,11.076097,178.11589,-0.0091312854,14.371968,11.075699,178.2211,-9.3941507
60.5,1.115852,-0.13968305,51.039093,0,11.076097,181.41589,-0.0092746643,14.36247,11.076325,181.04224,-9.3920059
61.6,1.114282,-0.14270645,51.569748,0,11.076097,184.71588,-0.0094730761,14.314909,11.074607,183.96152,-9.3899193
62.7,1.1107637,-0.14582506,52.066032,0,11.076097,188.01588,-0.0096737277,14.269416,11.075024,186.87936,-9.3882856
63.8,1.1195619,-0.14921896,52.635494,0,11.076097,191.31589,-0.0098958239,14.403334,11.075663,189.95638,-9.3866568
64.9,1.1154538,-0.15262765,52.976753,0,11.076097,194.61591,-0.010113752,14.347225,11.075663,193.25783,-9.3841324
66.0,1.1146144,-0.15599555,53.359566,0,11.076097,197.91591,-0.01032442,14.332293,11.076218,196.60422,-9.3827801
67.1,1.1174023,-0.15880902,53.657223,0,11.076097,201.21591,-0.01050909,14.38913,11.076128,199.97014,-9.3810959
68.2,1.1233666,-0.16271497,53.975826,0,11.076097,204.5159,-0.010758845,14.449082,11.076235,203.41484,-9.3790417
69.3,1.1247526,-0.16634394,53.975826,0,11.076097,207.8159,-0.011003261,14.496132,11.07628,207.03973,-9.3773565
70.4,1.1182973,-0.16995351,53.975826,0,11.076097,211.11591,-0.011233848,14.399059,11.076047,210.67326,-9.3756819
71.5,1.1240133,-0.17303754,53.975826,0,11.076097,214.41591,-0.011441314,14.488184,11.074814,214.10669,-9.3736467
72.6,1.1276907,-0.1766022,53.975826,0,11.076097,217.71591,-0.011674993,14.537343,11.075859,217.59573,-9.3717279
73.7,1.1246167,-0.18019782,53.975555,0,11.076097,221.0159,-0.011919512,14.49672,11.075532,220.97581,-9.3697901
74.8,1.1213437,-0.1832784,53.657242,0,11.076097,224.3159,-0.012136585,14.461782,11.076135,224.52888,-9.3681507
75.9,1.1219399,-0.18637471,53.65723,0,11.076097,227.61591,-0.012340358,14.464626,11.076001,227.77235,-9.3660707
77.0,1.122184,-0.18944243,53.66325,0,11.076097,230.91589,-0.012556561,14.474958,11.07577,230.91121,-9.3645267
78.1,1.1281304,-0.19232395,53.975826,0,11.076097,234.2159,-0.012748206,14.554864,11.07605,234.04886,-9.3626766
79.2,1.1261693,-0.19590332,54.12233,0,11.076097,237.51588,-0.01298042,14.535351,11.075619,237.11993,-9.360652
80.3,1.1243911,-0.199093,54.346817,0,11.076097,240.81589,-0.013200575,14.509943,11.075436,240.21573,-9.3590403
81.4,1.1278595,-0.20237505,54.763607,0,11.076097,244.11589,-0.013420478,14.56064,11.075561,243.3107,-9.3571329
82.5,1.1227534,-0.20564036,55.089275,0,11.076097,247.41588,-0.013632725,14.487723,11.075967,246.42984,-9.3550949
83.6,1.1181867,-0.20915675,55.496166,0,11.076097,250.7159,-0.013871937,14.434552,11.076561,249.6611,-9.3532381
84.7,1.1258146,-0.2126741,55.696449,0,11.076097,254.01588,-0.014108745,14.54137,11.075347,252.96387,-9.3514395
85.8,1.1236696,-0.21684189,55.843506,0,11.076097,257.31616,-0.014375235,14.524348,11.075241,256.39194,-9.349596
86.9,1.1236712,-0.2197375,55.967251,0,11.076097,260.61618,-0.01456269,14.52387,11.077703,259.87964,-9.3481264
88.0,1.1202273,-0.22379534,55.908413,0,11.076097,263.91592,-0.014827071,14.481034,11.076629,263.44485,-9.3462343
89.1,1.1224377,-0.22697423,55.84351,0,11.076097,267.21591,-0.015024131,14.52354,11.076059,266.99771,-9.3442545
90.2,1.126307,-0.23056483,55.84351,0,11.076097,270.5159,-0.015265787,14.552773,11.076488,270.49527,-9.3427038
91.3,1.1209311,-0.23388647,55.778301,0,11.076097,273.81589,-0.015469091,14.480629,11.075915,273.88556,-9.3408651
92.4,1.1282873,-0.23727658,55.61853,0,11.076097,277.11591,-0.015677124,14.579395,11.076103,277.22787,-9.338603
93.5,1.1211305,-0.24109115,55.602909,0,11.076097,280.41589,-0.015930593,14.500199,11.075741,280.52008,-9.336771
94.6,1.130439,-0.24459498,55.72517,0,11.076097,283.71591,-0.016160537,14.629171,11.076623,283.6857,-9.3350468
95.7,1.1353899,-0.24701016,55.843506,0,11.076097,287.0159,-0.016326137,14.688029,11.075272,286.91135,-9.3335781
96.8,1.1274414,-0.24926274,55.994949,0,11.076097,290.31589,-0.016484145,14.59111,11.075972,289.95667,-9.331686
97.9,1.1313007,-0.25241297,56.160061,0,11.076097,293.61588,-0.016682832,14.652957,11.075695,293.04852,-9.329751
99.0,1.132454,-0.25568929,56.425777,0,11.076097,296.91589,-0.016903089,14.670832,11.076473,296.25119,-9.3278236
100.1,1.128924,-0.25950983,56.630501,0,11.076097,299.99545,-0.017154021,14.624095,11.075434,299.44797,-9.3262529
101.2,0.04178993,-0.27912611,53.749725,0,11.076097,299.99905,-0.018435216,0.54756284,11.076946,303.49274,-9.3262444
102.3,0.040260699,-0.27966878,49.309959,0,11.076097,299.99905,-0.018461088,0.53173345,11.075183,307.23645,-9.3263388
103.4,0.010302531,-0.2793062,44.17519,0,11.076097,299.99905,-0.018421791,0.13848792,11.075532,309.00735,-9.3265038
104.5,0.0055114855,-0.27809864,39.929211,0,11.076097,299.99905,-0.018341746,0.094234817,11.075807,308.90884,-9.3262987
105.6,0.0026471454,-0.27596658,37.089882,0,11.076097,299.99905,-0.018202392,0.012157092,11.07483,307.20547,-9.3261194
106.7,-0.010192928,-0.27397811,37.783649,0,11.076097,299.99905,-0.018070303,-0.11851213,11.076579,304.3392,-9.3260956
107.8,-0.013654869,-0.27192223,40.596092,0,11.076097,299.99905,-0.017944574,-0.17449613,11.076132,300.87277,-9.3259525
108.9,-0.021610633,-0.27030471,45.100353,0,11.076097,299.99905,-0.017847873,-0.27653137,11.075644,297.40649,-9.3255844
110.0,-0.022408765,-0.26916209,49.695152,0,11.076097,299.99905,-0.01777732,-0.28245175,11.075435,294.09995,-9.3256435
111.1,-0.019966111,-0.26813492,54.026329,0,11.076097,299.99905,-0.017724268,-0.26332241,11.075896,291.37839,-9.3260307
112.2,-0.023855442,-0.26731595,57.746613,0,11.076097,299.99905,-0.017672149,-0.30566138,11.075773,289.31528,-9.3260088
113.3,-0.020126052,-0.26739803,60.855503,0,11.076097,299.99905,-0.017681317,-0.26018962,11.076242,287.94144,-9.3255901
114.4,-0.019463178,-0.26769572,63.358734,0,11.076097,299.99905,-0.017714001,-0.26927203,11.075426,287.37323,-9.3257065
115.5,-0.007251964,-0.26775467,65.462692,0,11.076097,299.99905,-0.017717233,-0.07526283,11.076218,287.38959,-9.325779
116.6,0.0014176294,-0.26757991,67.045769,0,11.076097,299.99905,-0.017706454,0.015846251,11.075487,288.17813,-9.325737
117.7,0.0029272635,-0.2683734,68.297401,0,11.076097,299.99905,-0.017756304,0.04377434,11.075586,289.32306,-9.3255796
118.8,0.033276282,-0.27068388,68.972145,0,11.076097,299.99905,-0.017906088,0.43680242,11.075431,291.21695,-9.3253069
119.9,0.033637304,-0.27286682,69.120422,0,11.076097,299.99905,-0.018047685,0.42620757,11.076413,294.12683,-9.325408
121.0,0.032304291,-0.27652499,68.41404,0,11.076097,299.99905,-0.018273555,0.42057386,11.076536,297.91867,-9.3252916
122.1,0.043374307,-0.28055951,67.067703,0,11.076097,299.99905,-0.018522479,0.55731857,11.076574,302.0979,-9.3251724
123.2,0.050957598,-0.28323841,64.995361,0,11.076097,299.99905,-0.018702341,0.66837996,11.076521,306.18188,-9.3252907
124.3,0.048341192,-0.28468701,62.057178,0,11.076097,299.99905,-0.018791102,0.62400192,11.075954,309.93997,-9.3255024
125.4,0.047099058,-0.28597951,58.409504,0,11.076097,299.99905,-0.018878728,0.61406344,11.075345,312.83795,-9.3250866
126.5,0.04070222,-0.28613174,53.945557,0,11.076097,299.99905,-0.018882677,0.5121507,11.076183,314.62518,-9.3250113
127.6,0.019288665,-0.28597561,48.840431,0,11.076097,299.99905,-0.018878078,0.26039007,11.075831,315.0787,-9.3248425
128.7,0.0010473207,-0.28449625,44.079678,0,11.076097,299.99905,-0.018785419,0.023659067,11.075771,313.86447,-9.3251858
129.8,-0.0078167394,-0.2827388,40.151768,0,11.076097,299.99905,-0.018673042,-0.10038228,11.075721,311.42807,-9.3249302
130.9,-0.016047912,-0.28142762,39.243168,0,11.076097,299.99905,-0.018587843,-0.20727324,11.075523,308.0929,-9.3249302
132.0,-0.027284835,-0.27962139,40.57193,0,11.076097,299.99905,-0.01846486,-0.34516433,11.076183,304.21704,-9.3247128
133.1,-0.031423848,-0.27809268,44.211082,0,11.076097,299.99905,-0.018360563,-0.42106968,11.07609,300.23621,-9.3249207
134.2,-0.040162712,-0.27686989,48.596573,0,11.076097,299.99905,-0.018267667,-0.54090959,11.075797,296.49536,-9.3245525
135.3,-0.042225637,-0.27621043,52.930569,0,11.076097,299.99905,-0.018221507,-0.53884304,11.075726,292.9671,-9.3244572
136.4,-0.042483669,-0.2758266,56.983196,0,11.076097,299.99905,-0.018197102,-0.55004305,11.076308,290.13589,-9.324708
137.5,-0.049119048,-0.27469426,60.607471,0,11.076097,299.99905,-0.018122746,-0.62971854,11.076271,287.74792,-9.3246794
138.6,-0.041112818,-0.27434453,63.820004,0,11.076097,299.99905,-0.018102946,-0.53269106,11.076974,285.97345,-9.3244801
139.7,-0.042173896,-0.27508813,66.510246,0,11.076097,299.99905,-0.018166313,-0.54927623,11.075625,284.85068,-9.324707
140.8,-0.037079114,-0.27552688,68.809959,0,11.076097,299.99905,-0.018200828,-0.46706647,11.076686,284.43207,-9.3242683
141.9,-0.024482407,-0.27503523,70.712349,0,11.076097,299.99905,-0.018176034,-0.31889188,11.076547,284.6181,-9.3242016
143.0,-0.021328347,-0.27477616,72.259056,0,11.076097,299.99905,-0.018164076,-0.2745049,11.075646,285.47766,-9.3243437
144.1,-0.010629774,-0.27554661,73.321373,0,11.076097,299.99905,-0.018217219,-0.13376223,11.076374,287.19507,-9.3245153
145.1311,0.0092406245,-0.0084646624,73.935677,0,11.076097,299.99905,-0.0005383119,0.12475458,11.07612,289.32321,-9.324132
145.285,0.17898585,0.029935183,0.0,0,11.076099,6.0865757e-10,0.0018308362,2.23298,11.077684,289.79926,-9.3249388
145.2872,0.1696952,0.027668618,0.0,0,11.076099,6.079146e-25,0.0019695957,2.2390299,11.077435,289.81277,-9.3246422
145.2894,0.16266572,0.026762651,0.0,0,11.076099,6.0717282e-40,0.0016522105,2.1657839,11.076983,289.82632,-9.3238802
145.2916,0.1681565,0.030884532,0.0,0,11.076099,0.0,0.0022455961,2.1673007,11.075926,289.83984,-9.3229723
145.2938,0.16388589,0.032555591,0.0,0,11.076099,0.0,0.0019356125,2.0139227,11.077324,289.85339,-9.3230953
145.296,0.1587629,0.028530711,0.0,0,11.076099,0.0,0.002051082,1.9730321,11.076954,289.86694,-9.3252192
145.2982,0.17765333,0.028014421,0.0,0,11.076099,0.0,0.0017473547,2.283828,11.079531,289.88046,-9.3253641
145.3004,0.18778658,0.031747069,0.0,0,11.076099,0.0,0.0023161683,2.3840621,11.074836,289.89401,-9.3243523
145.3026,0.19600667,0.032595269,0.0,0,11.076099,0.0,0.0019894098,2.4372389,11.070539,289.90756,-9.325326
145.3048,0.19147193,0.028097453,0.0,0,11.076099,0.0,0.0020866084,2.4702644,11.072449,289.90289,-9.325242
145.307,0.19034733,0.028921388,0.0,0,11.076099,0.0,0.0018452947,2.504214,11.076508,289.88934,-9.3245258
145.3092,0.19072887,0.030900808,0.0,0,11.076099,0.0,0.0023011537,2.4007018,11.078079,289.87582,-9.3247414
145.3114,0.18772209,0.032933716,0.0,0,11.076099,0.0,0.0020021473,2.4133089,11.078592,289.86227,-9.3246899
145.3136,0.1800333,0.030698948,0.0,0,11.076099,0.0,0.0022712064,2.2666278,11.076295,289.85336,-9.3231745
145.3158,0.18178853,0.030572746,0.0,0,11.076099,0.0,0.0018825362,2.3713286,11.077456,289.87366,-9.3240976
145.318,0.19720612,0.031091413,0.0,0,11.076099,0.0,0.0023341926,2.4873507,11.075901,289.89395,-9.3237619
145.3202,0.20318478,0.034779858,0.0,0,11.076099,0.0,0.0021167763,2.6494684,11.075649,289.91428,-9.3239937
145.3224,0.20456456,0.030248189,0.0,0,11.076099,0.0,0.0022715072,2.5577531,11.075627,289.93457,-9.3238878
145.3246,0.2018138,0.031998318,0.0,0,11.076099,0.0,0.0019140679,2.6002369,11.077999,289.94675,-9.3235588
145.3268,0.20624596,0.031557884,0.0,0,11.076099,0.0,0.0023500915,2.6577392,11.077013,289.95352,-9.3241558
145.329,0.20494559,0.034530785,0.0,0,11.076099,0.0,0.0020504717,2.6187582,11.072821,289.9603,-9.3245964
145.3312,0.19791889,0.029346433,0.0,0,11.076099,0.0,0.0021820806,2.4997859,11.079052,289.96704,-9.3247585
145.3334,0.1952102,0.031537611,0.0,0,11.063763,0.0,0.0018697029,2.50319,11.075092,289.97339,-9.3238535
145.3356,0.19687478,0.029722458,0.0,0,10.735819,0.0,0.0023269856,2.4629266,11.075292,289.97339,-9.3235989
145.3378,0.23141029,0.035262033,0.0,0,10.404927,0.0,0.0020792035,2.8961775,11.071638,289.97339,-9.322505
145.34,0.24577835,0.031023327,0.0,0,10.074035,0.0,0.0023202423,3.1240642,11.012849,289.97339,-9.3249416
145.3422,0.2434673,0.033126563,0.0,0,9.7431412,0.0,0.0020017312,3.0203388,10.831194,289.97339,-9.3239908
145.3444,0.27578858,0.030900365,0.0,0,9.4141388,0.0,0.0022885443,3.4261777,10.534695,291.38428,-9.323328
145.3466,0.23416114,0.035235547,0.0,0,9.0922346,0.0,0.0021358326,2.900265,10.153285,294.06003,-9.3239136
145.3488,7.7337279,0.3784554,0.0,0,8.7703304,0.0,0.025113115,95.868149,9.7404509,296.73578,-9.3177395
145.351,9.978693,0.75428903,0.0,0,8.4631929,0.0,0.051113885,120.20262,9.2673731,299.41153,-9.3175125
145.3532,10.637715,1.1673982,0.0,0,8.1570415,0.0,0.081060797,124.39355,8.831377,302.08728,-9.3150978
145.3554,10.943342,1.5332434,0.0,0,7.8607755,0.0,0.10689767,125.42813,8.4912539,303.91467,-9.3145685
145.3576,11.534081,1.7971494,0.0,0,7.5694952,0.0,0.12747212,128.84369,8.1796598,305.73431,-9.3159294
145.3598,11.739275,2.0936892,0.0,0,7.2838039,0.0,0.14961028,128.91873,7.8740234,307.55396,-9.3167953
145.362,11.989952,2.3775072,0.0,0,7.0067792,0.0,0.17254911,128.41492,7.596715,309.3736,-9.3162966
145.3642,12.357078,2.6295531,0.0,0,6.7313671,0.0,0.19186524,129.81218,7.3369904,309.80206,-9.3151875
145.3664,12.599859,2.8800204,0.0,0,6.467802,0.0,0.21320237,129.69276,7.0743613,308.56128,-9.3165293
145.3686,12.870502,3.1465251,0.0,0,6.2042422,0.0,0.23470522,129.51691,6.8137612,307.3205,-9.3155241
145.3708,13.219688,3.3980954,0.0,0,5.9515953,0.0,0.25690734,130.13527,6.5529413,306.07968,-9.3146229
145.373,13.507151,3.6592071,0.0,0,5.7009277,0.0,0.27866542,130.10286,6.2936678,304.8389,-9.3148098
145.3752,13.860204,3.9115751,0.0,0,5.4572535,0.0,0.3021996,130.36104,6.0376701,304.19153,-9.3155651
145.3774,14.190267,4.1719031,0.0,0,5.2187734,0.0,0.32511896,130.37918,5.7791581,303.59705,-9.3170099
145.3796,14.505406,4.4211011,0.0,0,4.9838042,0.0,0.34939554,130.1983,5.5236883,303.00256,-9.3174229
145.3818,14.830111,4.6773858,0.0,0,4.7569842,0.0,0.37268609,130.08522,5.2703934,302.40808,-9.3168306
145.384,15.179521,4.917367,0.0,0,4.5305758,0.0,0.39730254,129.83353,5.0224199,301.89584,-9.3165627
145.3862,15.535028,5.1622367,0.0,0,4.314702,0.0,0.42092776,129.72015,4.7787414,301.51682,-9.3163252
145.3884,15.891936,5.3889799,0.0,0,4.0989256,0.0,0.44528168,129.57465,4.5503769,301.13776,-9.3156719
145.3906,16.266636,5.6242046,0.0,0,3.8911293,0.0,0.46873298,129.6244,4.3222485,300.7587,-9.3150988
145.3928,16.667126,5.8329253,0.0,0,3.6859133,0.0,0.49259877,129.61684,4.0995278,300.37964,-9.3159981
145.395,17.095659,6.051012,0.0,0,3.4855206,0.0,0.51554996,129.91417,3.8861454,300.11505,-9.3159237
145.3972,17.553288,6.2556434,0.0,0,3.2902927,0.0,0.5399009,130.21002,3.6778026,299.8714,-9.3151989
145.3994,17.997368,6.4681334,0.0,0,3.0970623,0.0,0.56299675,130.46822,3.4772153,299.62772,-9.3152199
145.4016,18.464008,6.6574707,0.0,0,2.9113381,0.0,0.58680016,130.65587,3.276036,299.38406,-9.3147697
145.4038,18.966944,6.8586636,0.0,0,2.7256143,0.0,0.61017752,131.10399,3.0766089,298.53217,-9.3147554
145.406,19.501947,7.0462289,0.0,0,2.5483873,0.0,0.63479644,131.56468,2.8888357,296.32086,-9.3149996
145.4082,20.030159,7.2429404,0.0,0,2.3717272,0.0,0.65810049,132.00217,2.7028697,294.10956,-9.3148146
145.4104,20.620388,7.4119849,0.0,0,2.2008004,0.0,0.68180114,132.70529,2.5192568,291.89825,-9.3144951
145.4126,21.24505,7.5956278,0.0,0,2.0327644,0.0,0.70480859,133.60484,2.3382428,289.68692,-9.3139639
145.4148,21.922777,7.7632523,0.0,0,1.8679364,0.0,0.72931921,134.50021,2.167033,288.4469,-9.3142891
145.417,22.600294,7.9421072,0.0,0,1.7080843,0.0,0.75234425,135.55411,1.996437,287.49252,-9.3140621
145.4192,23.315243,8.0993595,0.0,0,1.5491644,0.0,0.7768262,136.45377,1.8254454,286.53812,-9.3125772
145.4214,24.055965,8.2678337,0.0,0,1.3970973,0.0,0.79997265,137.52364,1.668252,285.58374,-9.3121748
145.4236,24.849306,8.4197922,0.0,0,1.2450334,0.0,0.82441151,138.67242,1.5093966,285.50082,-9.3114262
145.4258,25.674648,8.5822439,0.0,0,1.0992644,0.0,0.84743112,140.01854,1.3520839,288.23315,-9.3096027
145.428,26.518,8.7161732,0.0,0,0.95463634,0.0,0.8704254,141.3452,1.2002928,290.96548,-9.3110142
145.4302,27.402287,8.8654928,0.0,0,0.81407332,0.0,0.89298004,142.80182,1.056282,293.69781,-9.3111572
145.4324,28.324247,8.996582,0.0,0,0.67652941,0.0,0.9164747,144.1414,0.91844583,296.43015,-9.3105383
145.4346,29.306408,9.1414995,0.0,0,0.54098594,0.0,0.938676,145.86031,0.78142065,297.96054,-9.3091249
145.4368,30.307423,9.2583275,0.0,0,0.41008592,0.0,0.9606303,147.58687,0.6442613,298.97583,-9.3088083
145.439,31.289145,9.3920832,0.0,0,0.27942541,0.0,0.9826979,149.11674,0.51727188,299.99115,-9.3076248
145.4412,29.188057,9.4146099,0.0,0,0.15489216,0.0,0.9885143,138.31161,0.45275992,301.00644,-9.3100986
145.4434,27.751314,9.4319096,0.0,0,0.030416148,0.0,0.98971462,131.40187,0.41969654,301.89972,-9.311904
145.4456,27.365728,9.4276323,0.0,0,-0.09173242,0.0,0.99116361,129.35405,0.38346246,302.16937,-9.3129282
145.4478,27.249573,9.4439211,0.0,0,-0.21312842,0.0,0.99240214,128.57819,0.3331131,302.43903,-9.3141356
145.45,27.245419,9.444705,0.0,0,-0.33452442,0.0,0.99418432,128.34953,0.28259593,302.70868,-9.3126869
145.4522,27.211121,9.458497,0.0,0,-0.45592043,0.0,0.99478537,128.12585,0.22438131,302.97833,-9.3131247
145.4544,27.136417,9.4537678,0.0,0,-0.5773164,0.0,0.99572074,127.63502,0.16846372,303.59598,-9.3137474
145.4566,27.017982,9.4659605,0.0,0,-0.69871235,0.0,0.99642903,126.97179,0.12116335,304.42041,-9.3144064
145.4588,26.832355,9.461751,0.0,0,-0.82010835,0.0,0.99716163,126.05046,0.082413673,305.24484,-9.3146782
145.461,26.555265,9.475647,0.0,0,-0.94150436,0.0,0.99793792,124.69995,0.051752765,306.06927,-9.3141327
145.4632,26.185833,9.4701548,0.0,0,-1.0629004,0.0,0.99849993,122.89265,0.030985214,306.8157,-9.3145161
145.4654,25.701052,9.4800854,0.0,0,-0.8433286,300.0,0.99898708,120.56133,0.023807425,306.78198,-9.3151665
145.4676,25.173471,9.4682961,0.0,0,-0.42304948,300.0,0.99809116,118.16605,0.02970277,306.74826,-9.315258
145.4698,24.752546,9.4782066,0.0,0,-0.0027700011,300.0,0.99867851,116.1068,0.030546142,306.71457,-9.315464
145.472,24.412113,9.4725389,0.0,0,0.41750887,300.0,0.99871695,114.50243,0.033088084,306.68085,-9.3153782
145.4742,24.177885,9.4783802,0.0,0,0.83778799,300.0,0.99897641,113.40056,0.033633154,307.20416,-9.3167486
145.4764,23.954058,9.4731398,0.0,0,1.2580678,300.0,0.99899668,112.29446,0.03343806,308.1749,-9.3168144
145.4786,23.33712,9.4838495,0.0,0,1.6783465,300.0,0.99991888,109.43362,0.049536109,309.14563,-9.3171244
145.4808,21.954252,9.4685278,0.0,0,2.0986254,300.0,0.99812764,103.15913,0.10510985,310.11636,-9.3191252
145.483,19.468258,9.4704056,0.0,0,2.5189049,300.0,0.99764329,91.747581,0.21048127,311.0997,-9.3196878
145.4852,14.440317,9.4443254,0.0,0,2.9391842,300.0,0.99363226,68.631111,0.41505551,312.76404,-9.3238955
145.4874,0.11093466,9.2492485,0.0,0,3.3594635,300.0,0.95951146,0.36243457,0.81454122,314.42838,-9.339201
145.4896,0.72120613,9.0198946,0.0,0,3.7797422,300.0,0.92067194,3.6294522,1.4392161,316.09271,-9.3363752
145.4918,-0.16202207,8.8582125,0.0,0,4.2000217,300.0,0.89306861,-0.61654192,2.2001987,317.75705,-9.3368855
145.494,-0.16256773,8.725378,0.0,0,4.6203008,300.0,0.8721326,-1.0463473,2.89533,318.95032,-9.3370695
145.4962,-0.036164571,8.6574678,0.0,0,5.0405803,300.0,0.86042893,-0.201545,3.4475937,319.63702,-9.3368845
145.4984,-0.026846243,8.6439381,0.0,0,5.4608593,300.0,0.85885978,-0.22709295,3.8718865,320.32376,-9.3343945
145.5006,0.00024796298,8.6647072,0.0,0,5.8811388,300.0,0.86171532,0.023007715,4.2607241,321.01047,-9.3341951
145.5028,-0.10506935,8.7216187,0.0,0,6.3014183,300.0,0.87076271,-0.52044547,4.6378608,321.69717,-9.3331757
145.505,-0.089587562,8.8136864,0.0,0,6.7216969,300.0,0.88509887,-0.54720557,5.0210547,321.86801,-9.3309526
145.5072,0.058222104,8.930047,0.0,0,7.1419768,300.0,0.90433156,0.24576694,5.4203763,322.00909,-9.329875
145.5094,0.086992495,9.0893936,0.0,0,7.5622554,300.0,0.93090695,0.46345118,5.8486319,322.15018,-9.329217
145.5116,-0.066756174,9.2720613,0.0,0,7.9825354,300.0,0.96200728,-0.24542491,6.2828031,322.29123,-9.3298502
145.5138,0.25337538,9.4653845,0.0,0,8.4028139,300.0,0.99722445,1.5612857,6.7284527,321.69931,-9.3278122
145.516,0.024536021,9.4083977,0.0,0,8.8230925,300.0,0.98735929,-0.11538409,7.1758604,320.04861,-9.3282852
145.5182,-0.077759698,9.4212704,0.0,0,9.243372,300.0,0.98940945,-0.27082297,7.6198611,318.39792,-9.3262749
145.5204,0.12260059,9.4319019,0.0,0,9.6636515,300.0,0.99119985,0.63656425,8.0564919,316.74722,-9.3261623
145.5226,-0.02044094,9.4153948,0.0,0,10.083931,300.0,0.9881888,-0.1483735,8.4838238,315.09653,-9.3261194
145.5248,0.16603105,9.4163179,0.0,0,10.50421,300.0,0.98810136,0.7544148,8.9150543,313.54614,-9.3262787
145.527,0.263374,9.422616,0.0,0,10.924489,300.0,0.98948598,1.3055711,9.3520021,312.01038,-9.3259287
145.5292,0.11617744,9.4342699,0.0,0,11.344769,300.0,0.99112445,0.60056365,9.7808294,310.47461,-9.3254461
145.5314,0.025231577,9.4379435,0.0,0,11.765047,300.0,0.99227953,0.17701347,10.207893,308.93881,-9.3258133
145.5336,-0.0083707618,9.4320297,0.0,0,12.185327,300.0,0.99080253,-0.021233751,10.63562,307.89243,-9.3247128
145.5358,0.11556998,9.4294815,0.0,0,12.605606,300.0,0.99094146,0.42925876,11.071692,307.81155,-9.3249283
145.538,0.14417376,9.4270964,0.0,0,13.025885,300.0,0.98981321,0.66610718,11.500328,307.73065,-9.3240366
145.5402,0.059282314,9.4349346,0.0,0,13.446164,300.0,0.99185222,0.27994141,11.915501,307.64975,-9.3241329
145.5424,0.048895694,9.4275246,0.0,0,13.866444,300.0,0.98981601,0.24149382,12.333362,307.56885,-9.3243561
145.5446,0.098375857,9.430439,0.0,0,14.286723,300.0,0.99107581,0.39023209,12.764622,307.55807,-9.3238459
145.5468,0.21190289,9.4253693,0.0,0,14.707002,300.0,0.98945785,1.022712,13.196205,307.56482,-9.3230209
145.549,0.058046818,9.4326582,0.0,0,15.127281,300.0,0.99162126,0.31229904,13.639022,307.57153,-9.3232861
145.5512,0.010094872,9.4266939,0.0,0,15.547561,300.0,0.9896546,0.027466184,14.075912,307.57828,-9.3236809
145.5534,0.061462708,9.4255686,0.0,0,15.967839,300.0,0.99026221,0.28063217,14.507898,307.74142,-9.3229876
145.5556,0.10519519,9.4307232,0.0,0,16.388119,300.0,0.99027985,0.46158063,14.942513,308.3414,-9.3214579
145.5578,0.064874619,9.4291658,0.0,0,16.808399,300.0,0.99097097,0.34257635,15.366876,308.94138,-9.3211994
145.56,0.028706273,9.4301405,0.0,0,17.228678,300.0,0.99007761,0.15053099,15.780225,309.54135,-9.3219509
145.5622,0.039608669,9.4248962,0.0,0,17.648958,300.0,0.99022985,0.20071922,16.191549,310.14133,-9.3218241
145.5644,0.10623948,9.4252729,0.0,0,17.999975,300.0,0.98925489,0.45005813,16.603905,310.32455,-9.3206425
145.5666,0.10412022,9.4302511,0.0,0,18.0,300.0,0.99145728,0.56715405,17.027197,310.3515,-9.3208332
145.5688,-0.032160312,9.431838,0.0,0,18.0,300.0,0.99017483,-0.086480655,17.424034,310.37848,-9.3215122
145.571,0.011625393,9.429841,0.0,0,18.0,300.0,0.99112707,0.026743321,17.778006,310.40543,-9.3217134
145.5732,0.14386651,9.4275093,0.0,0,18.0,300.0,0.98963189,0.65201497,18.091196,310.39508,-9.3242111
145.5754,0.16611351,9.4317131,0.0,0,18.0,300.0,0.99184096,0.83320838,18.330584,310.22653,-9.3265266
145.5776,0.18684497,9.4360142,0.0,0,18.0,300.0,0.99080956,0.90688825,18.484356,310.05801,-9.3295221
145.5798,0.31159794,9.4371786,0.0,0,18.0,300.0,0.99275285,1.4191235,18.533295,309.88947,-9.334219
145.582,0.46231362,9.4450941,0.0,0,18.0,300.0,0.99269837,2.1425521,18.468637,309.72095,-9.3410912
145.5842,0.51760793,9.442584,0.0,0,18.0,300.0,0.99387443,2.4558468,18.345407,310.09073,-9.3508282
145.5864,0.43482226,9.444169,0.0,0,18.0,300.0,0.99229014,2.1358891,18.223719,310.74463,-9.3616991
145.5886,0.33386308,9.4417696,0.0,0,18.0,300.0,0.99351352,1.618523,18.118292,311.39853,-9.377079
145.5908,0.35155138,9.4434109,0.0,0,18.0,300.0,0.99219233,1.6281474,18.058239,312.05243,-9.3947268
145.593,0.32895353,9.4436884,0.0,0,18.0,300.0,0.99401629,1.5774069,18.03952,312.65851,-9.4119225
145.5952,0.31429368,9.4430132,0.0,0,18.0,300.0,0.99204159,1.4617895,18.040119,312.90793,-9.4305382
145.5974,0.35822147,9.4362907,0.0,0,18.0,300.0,0.99273038,1.6482201,18.04953,313.15735,-9.4494772
145.5996,0.4207387,9.437541,0.0,0,18.0,300.0,0.99113131,1.9545497,18.071472,313.40677,-9.468277
145.6018,0.44528908,9.4368534,0.0,0,18.0,300.0,0.9928149,2.0748382,18.095844,313.65619,-9.484827
145.604,0.41691378,9.4387751,0.0,0,18.0,300.0,0.9911148,1.9664942,18.116188,313.71344,-9.5009661
145.6062,0.40850601,9.4347744,0.0,0,18.0,300.0,0.99237037,1.9474818,18.130041,313.63254,-9.5157032
145.6084,0.37157688,9.4400749,0.0,0,18.0,300.0,0.9913736,1.790279,18.140799,313.55167,-9.5300608
145.6106,0.34512505,9.438077,0.0,0,18.0,300.0,0.99322832,1.6446013,18.143602,313.47076,-9.5472679
145.6128,0.36483148,9.4431696,0.0,0,18.0,300.0,0.99198598,1.6745322,18.139805,313.41672,-9.5622578
145.615,0.38993323,9.4370375,0.0,0,18.0,300.0,0.99304324,1.8057842,18.140455,313.92639,-9.5777206
145.6172,0.44278675,9.4411688,0.0,0,18.0,300.0,0.99190837,2.0768943,18.134983,314.43607,-9.5926037
145.6194,0.48802438,9.4366674,0.0,0,18.0,300.0,0.9931246,2.2900507,18.133888,314.94574,-9.608429
145.6216,0.48034456,9.4420166,0.0,0,18.0,300.0,0.99181324,2.2779222,18.131044,315.45541,-9.625289
145.6238,0.45201343,9.4371109,0.0,0,18.0,300.0,0.99295264,2.141875,18.128864,315.8121,-9.641387
145.626,0.39470553,9.4437895,0.0,0,18.0,300.0,0.99198318,1.9324352,18.129848,316.04129,-9.6561489
145.6282,0.37484244,9.4401894,0.0,0,18.0,300.0,0.99365479,1.7988826,18.126225,316.27048,-9.6732759
145.6304,0.37857798,9.4462185,0.0,0,18.0,300.0,0.99236,1.7828219,18.123583,316.49969,-9.688839
145.6326,0.40485552,9.4377193,0.0,0,18.0,300.0,0.9932397,1.8919228,18.117476,316.72736,-9.7039175
145.6348,0.44903931,9.4429102,0.0,0,18.0,300.0,0.99199599,2.0701058,18.113867,316.78802,-9.7196445
145.637,0.49264082,9.4384727,0.0,0,18.0,300.0,0.99339336,2.2772851,18.118528,316.84869,-9.7359734
145.6392,0.51264483,9.4442854,0.0,0,18.0,300.0,0.99196637,2.3996534,18.113077,316.90939,-9.7518091
145.6414,0.49794158,9.4372835,0.0,0,18.0,300.0,0.99306142,2.365227,18.110529,316.97006,-9.7663431
145.6436,0.44910446,9.4438543,0.0,0,18.0,300.0,0.99208033,2.1654174,18.110598,317.06577,-9.7825317
145.6458,0.40559784,9.4408274,0.0,0,18.0,300.0,0.99382371,1.9558138,18.107498,317.20059,-9.8001156
145.648,0.37220845,9.4462185,0.0,0,18.0,300.0,0.99230295,1.7616588,18.110165,317.33542,-9.8163052
145.6502,0.40685445,9.4378633,0.0,0,18.0,300.0,0.99340147,1.8924482,18.108259,317.47025,-9.8329878
145.6524,0.45320165,9.443325,0.0,0,18.0,300.0,0.99207997,2.1620443,18.105631,317.60507,-9.848177
145.6546,0.48840052,9.4372368,0.0,0,18.0,300.0,0.99311078,2.3002992,18.105612,317.56946,-9.8636894
145.6568,0.51030838,9.445508,0.0,0,18.0,300.0,0.99203897,2.3668306,18.102402,317.52228,-9.8773613
145.659,0.52012026,9.4350271,0.0,0,18.0,300.0,0.99266696,2.4410381,18.104002,317.4751,-9.8927174
145.6612,0.46437025,9.4425926,0.0,0,18.0,300.0,0.99185848,2.2541254,18.104834,317.42792,-9.9084749
145.6634,0.41649076,9.4392614,0.0,0,18.0,300.0,0.99367374,2.0062079,18.103216,317.44275,-9.9235077
145.6656,0.40252224,9.4480028,0.0,0,18.0,300.0,0.99254572,1.9378864,18.10194,317.5506,-9.9397697
145.6678,0.41621962,9.4389572,0.0,0,18.0,300.0,0.99340141,1.9189461,18.09741,317.65845,-9.9560804
145.67,0.42780101,9.4434795,0.0,0,18.0,300.0,0.99208921,2.0260098,18.100853,317.7663,-9.9723358
145.6722,0.48966169,9.4352188,0.0,0,18.0,300.0,0.99284589,2.2595294,18.100527,317.87415,-9.9900761
145.6744,0.51368773,9.4459095,0.0,0,18.0,300.0,0.99212497,2.4165735,18.099806,318.12753,-10.006366
145.6766,0.52085072,9.4380322,0.0,0,18.0,300.0,0.99333161,2.4537914,18.097586,318.4039,-10.021009
145.6788,0.5128305,9.4458065,0.0,0,18.0,300.0,0.99242353,2.4424834,18.098642,318.6803,-10.037451
145.681,0.46173814,9.4380178,0.0,0,18.0,300.0,0.99327797,2.222209,18.092232,318.95667,-10.053568
145.6832,0.41456547,9.4495764,0.0,0,18.0,300.0,0.99277407,2.0138063,18.099134,319.20645,-10.069107
145.6854,0.40404612,9.4388571,0.0,0,18.0,300.0,0.9933995,1.9181882,18.093975,319.40161,-10.084853
145.6876,0.44955143,9.4480858,0.0,0,18.0,300.0,0.9929055,2.0594146,18.094015,319.5968,-10.102643
145.6898,0.51403522,9.4405718,0.0,0,18.0,300.0,0.99374044,2.3408694,18.093555,319.79196,-10.117723
145.692,0.55079377,9.4485035,0.0,0,18.0,300.0,0.99266499,2.5463071,18.090866,319.98715,-10.133175
145.6942,0.54687053,9.4365358,0.0,0,18.0,300.0,0.9929809,2.5584056,18.094374,320.13422,-10.147689
145.6964,0.55118757,9.4436789,0.0,0,18.0,300.0,0.99205399,2.6240444,18.090176,320.26859,-10.162224
145.6986,0.52672595,9.4386778,0.0,0,18.0,300.0,0.99344403,2.4969549,18.090004,320.40292,-10.177931
145.7008,0.47908103,9.452404,0.0,0,18.0,300.0,0.99331057,2.3013186,18.086477,320.53729,-10.194317
145.703,0.44174623,9.4408541,0.0,0,18.0,300.0,0.9937436,2.1260848,18.087008,320.65967,-10.21071
145.7052,0.4557381,9.4456425,0.0,0,18.0,300.0,0.99261206,2.1004217,18.085623,320.74701,-10.227274
145.7074,0.50863534,9.4365501,0.0,0,18.0,300.0,0.99313211,2.3773816,18.085052,320.83435,-10.244946
145.7096,0.56670374,9.4484558,0.0,0,18.0,300.0,0.99277031,2.6419065,18.079689,320.92169,-10.260283
145.7118,0.57454753,9.4389105,0.0,0,18.0,300.0,0.99310505,2.7194669,18.080912,321.00903,-10.275272
145.714,0.57031828,9.4454937,0.0,0,18.0,300.0,0.9925527,2.7333357,18.085297,321.11087,-10.290708
145.7162,0.54678583,9.4381256,0.0,0,18.0,300.0,0.99326599,2.6375349,18.082737,321.21835,-10.305504
145.7184,0.51362205,9.450841,0.0,0,18.0,300.0,0.99322569,2.4462523,18.084763,321.32584,-10.321507
145.7206,0.4596929,9.4410534,0.0,0,18.0,300.0,0.99356216,2.2259367,18.080963,321.43332,-10.337221
145.7228,0.45496917,9.4474859,0.0,0,18.0,300.0,0.99292332,2.1400762,18.079832,321.54572,-10.353923
145.725,0.49449143,9.4386826,0.0,0,18.0,300.0,0.99341363,2.2728596,18.077217,321.68005,-10.370632
145.7272,0.558074,9.4480028,0.0,0,18.0,300.0,0.99282438,2.5972376,18.077353,321.81442,-10.386534
145.7294,0.58323395,9.4393549,0.0,0,18.0,300.0,0.99320376,2.7533772,18.076807,321.94879,-10.401025
145.7316,0.57527,9.4449902,0.0,0,18.0,300.0,0.99262059,2.7036498,18.08091,322.08316,-10.415545
145.7338,0.5670324,9.4390421,0.0,0,18.0,300.0,0.9931038,2.6907659,18.076117,322.2045,-10.431253
145.736,0.53682768,9.451211,0.0,0,18.0,300.0,0.99340737,2.5526321,18.074638,322.31873,-10.447801
145.7382,0.48792914,9.4417562,0.0,0,18.0,300.0,0.99347931,2.3234389,18.079481,322.43292,-10.465254
145.7404,0.45666569,9.4461508,0.0,0,18.0,300.0,0.99287623,2.16852,18.074659,322.54712,-10.480578
145.7426,0.49013603,9.4397411,0.0,0,18.0,300.0,0.99317467,2.2369738,18.072653,322.66205,-10.497622
145.7448,0.55865389,9.4525099,0.0,0,18.0,300.0,0.99382561,2.5820136,18.070894,322.78299,-10.512774
145.747,0.59007591,9.4401922,0.0,0,18.0,300.0,0.99324834,2.7931681,18.072098,322.90393,-10.527358
145.7492,0.60726595,9.4455624,0.0,0,18.0,300.0,0.99292046,2.8597255,18.068323,323.02484,-10.542126
145.7514,0.58848256,9.4387884,0.0,0,18.0,300.0,0.99276143,2.795716,18.07181,323.14578,-10.556916
145.7536,0.55222785,9.4498472,0.0,0,18.0,300.0,0.9934023,2.6350417,18.072744,323.25131,-10.574991
145.7558,0.52340734,9.4397278,0.0,0,18.0,300.0,0.99295634,2.488425,18.073917,323.34537,-10.591461
145.758,0.4932217,9.4479532,0.0,0,18.0,300.0,0.99340987,2.3184075,18.073462,323.43942,-10.607264
145.7602,0.49909189,9.4440899,0.0,0,18.0,300.0,0.99378157,2.3499026,18.073797,323.53348,-10.623457
145.7624,0.53191394,9.4528904,0.0,0,18.0,300.0,0.99413985,2.4738343,18.070528,323.62656,-10.639668
145.7646,0.60655445,9.4409256,0.0,0,18.0,300.0,0.99311316,2.8131936,18.072475,323.69376,-10.655556
145.7668,0.63400948,9.4449997,0.0,0,18.0,300.0,0.99279225,2.9734068,18.070066,323.76093,-10.671606
145.769,0.6188035,9.4385128,0.0,0,18.0,300.0,0.99264979,2.9345624,18.06601,323.82813,-10.687489
145.7712,0.59540427,9.4517574,0.0,0,18.0,300.0,0.99397117,2.8272159,18.069702,323.89529,-10.702195
145.7734,0.55848372,9.4440212,0.0,0,18.0,300.0,0.9935506,2.6639979,18.068544,323.97256,-10.717891
145.7756,0.53203762,9.4491749,0.0,0,18.0,300.0,0.99390554,2.527658,18.066465,324.05991,-10.733483
145.7778,0.51130289,9.4429951,0.0,0,18.0,300.0,0.99331063,2.4196186,18.067417,324.14722,-10.748188
145.78,0.53649151,9.4511862,0.0,0,18.0,300.0,0.99411666,2.4903691,18.064062,324.23456,-10.766293
145.7822,0.60377026,9.4428225,0.0,0,18.0,300.0,0.99328184,2.8010325,18.06547,324.3219,-10.781539
145.7844,0.65432692,9.4487143,0.0,0,18.0,300.0,0.99392045,3.0134339,18.062775,324.40924,-10.795431
145.7866,0.65717924,9.4412842,0.0,0,18.0,300.0,0.99279898,3.1205029,18.066351,324.49655,-10.812371
145.7888,0.62660682,9.4472551,0.0,0,18.0,300.0,0.99327081,3.0087838,18.063049,324.58389,-10.827157
145.791,0.58930773,9.4424524,0.0,0,18.0,300.0,0.99305719,2.7648258,18.059811,324.67123,-10.84349
145.7932,0.54345596,9.4493847,0.0,0,18.0,300.0,0.99416864,2.5996518,18.061321,324.76144,-10.860771
145.7954,0.52676719,9.4456015,0.0,0,18.0,300.0,0.99353099,2.4710975,18.061489,324.8555,-10.877842
145.7976,0.54151845,9.4536057,0.0,0,18.0,300.0,0.99476618,2.541296,18.062241,324.94955,-10.894312
145.7998,0.58441567,9.4439983,0.0,0,18.0,300.0,0.99329501,2.7147284,18.057898,325.04364,-10.908611
145.802,0.63921529,9.4463749,0.0,0,18.0,300.0,0.99364823,2.9790933,18.061773,325.1377,-10.922923
145.8042,0.67577076,9.4414835,0.0,0,18.0,300.0,0.99270755,3.1798491,18.062199,325.22577,-10.938706
145.8064,0.65235889,9.44981,0.0,0,18.0,300.0,0.99425393,3.1083705,18.060102,325.31308,-10.953593
145.8086,0.61955065,9.4469299,0.0,0,18.0,300.0,0.99376053,2.9384022,18.058212,325.40042,-10.968839
145.8108,0.56881917,9.4515438,0.0,0,18.0,300.0,0.99459219,2.7009652,18.061087,325.48776,-10.986315
145.813,0.53708655,9.4463987,0.0,0,18.0,300.0,0.99340785,2.5633841,18.058857,325.56793,-11.003555
145.8152,0.53704476,9.4511909,0.0,0,18.0,300.0,0.99461651,2.5252151,18.059689,325.63513,-11.020002
145.8174,0.57982701,9.4452076,0.0,0,18.0,300.0,0.99302101,2.6859989,18.055849,325.7023,-11.035939
145.8196,0.63218158,9.4477215,0.0,0,18.0,300.0,0.99419475,2.9060488,18.056032,325.76947,-11.052545
145.8218,0.67001694,9.4437408,0.0,0,18.0,300.0,0.99299198,3.1099629,18.055109,325.83667,-11.067462
145.824,0.68501264,9.4507809,0.0,0,18.0,300.0,0.99473292,3.2396309,18.052891,325.89285,-11.082521
145.8262,0.66081512,9.4468832,0.0,0,18.0,300.0,0.99344659,3.1294155,18.05439,325.94659,-11.097392
145.8284,0.60382879,9.4493666,0.0,0,18.0,300.0,0.99448568,2.8860509,18.052965,326.00037,-11.11347
145.8306,0.56356847,9.4441547,0.0,0,18.0,300.0,0.99296486,2.7072411,18.057945,326.05411,-11.128731
145.8328,0.5546056,9.4514809,0.0,0,18.0,300.0,0.99493223,2.5874853,18.054945,326.10785,-11.146445
145.835,0.58421016,9.4491348,0.0,0,18.0,300.0,0.99359089,2.67693,18.054255,326.16159,-11.160533
145.8372,0.64280456,9.4475965,0.0,0,18.0,300.0,0.99443001,2.9804792,18.05323,326.21533,-11.177464
145.8394,0.68908113,9.4446888,0.0,0,18.0,300.0,0.99287623,3.2279737,18.056267,326.26907,-11.191977
145.8416,0.69619179,9.4483042,0.0,0,18.0,300.0,0.99450165,3.3051183,18.053755,326.32281,-11.208467
145.8438,0.68909883,9.4483633,0.0,0,18.0,300.0,0.99347425,3.2297485,18.052618,326.39157,-11.223989
145.846,0.64769989,9.4484491,0.0,0,18.0,300.0,0.99436432,3.1052034,18.052128,326.46548,-11.238947
145.8482,0.59726459,9.4497156,0.0,0,18.0,300.0,0.99360275,2.8043699,18.052862,326.5394,-11.254749
145.8504,0.578143,9.4534483,0.0,0,18.0,300.0,0.99545634,2.7334723,18.05242,326.61331,-11.271852
145.8526,0.58799446,9.449707,0.0,0,18.0,300.0,0.99362373,2.7444792,18.050936,326.68298,-11.288349
145.8548,0.62635249,9.4483423,0.0,0,18.0,300.0,0.99472535,2.9347944,18.051704,326.73672,-11.304034
145.857,0.67912734,9.4503145,0.0,0,18.0,300.0,0.99366283,3.1768754,18.050901,326.79047,-11.320533
145.8592,0.70386332,9.4532671,0.0,0,18.0,300.0,0.99547482,3.2927096,18.045635,326.84421,-11.334841
145.8614,0.71006262,9.4473877,0.0,0,18.0,300.0,0.99289155,3.3342257,18.047699,326.89795,-11.351805
145.8636,0.68979019,9.445179,0.0,0,18.0,300.0,0.9940806,3.2760508,18.047373,326.95169,-11.36754
146.7639,0.72634941,9.4705591,0.0,0,18.0,1.6216742e-10,0.99798101,3.4084392,18.002171,202.81439,-11.482567
147.8639,0.76330018,9.4828081,0.0,0,18.0,1.6196895e-25,1.0002317,3.5763636,18.000355,190.59351,-11.48237
148.9639,0.77924943,9.4908638,0.0,0,18.0,1.6177150000000001e-40,1.0017267,3.6489305,18.000402,160.31853,-11.482235
150.0639,0.79876262,9.4969406,0.0,0,18.0,1.4012985e-45,1.0028628,3.7334931,17.999138,148.31598,-11.482585
151.1639,0.79712677,9.502058,0.0,0,18.0,1.4012985e-45,1.0037931,3.7130356,17.999609,134.83658,-11.483068
152.2639,0.81255728,9.5070858,0.0,0,18.0,1.4012985e-45,1.0046724,3.7871304,18.000132,126.50459,-11.483138
153.3639,0.81252152,9.5117426,0.0,0,18.0,1.4012985e-45,1.0054519,3.7835348,17.999668,120.39357,-11.482298
154.4639,0.81706655,9.5155096,0.0,0,18.0,1.4012985e-45,1.0061121,3.8072877,17.999693,114.96841,-11.482197
155.5639,0.82709616,9.5194063,0.0,0,18.0,1.4012985e-45,1.0068181,3.8516083,17.999601,106.80003,-11.482488
156.6639,0.8195262,9.5232992,0.0,0,18.0,1.4012985e-45,1.007471,3.8124568,17.999861,98.852676,-11.482177
157.7639,0.84250826,9.5260935,0.0,0,18.0,1.4012985e-45,1.0079455,3.9174924,17.999426,98.171616,-11.482699
158.8639,0.84111774,9.5294609,0.0,0,18.0,1.4012985e-45,1.0085608,3.9074168,18.000826,101.16463,-11.482997
159.9639,0.83981305,9.5325727,0.0,0,18.0,1.4012985e-45,1.0091574,3.8998539,18.000254,101.70747,-11.48299
161.0639,0.84686148,9.5354357,0.0,0,18.0,1.4012985e-45,1.009728,3.9279387,18.000589,101.962,-11.48287
162.1639,0.85766602,9.5386086,0.0,0,18.0,1.4012985e-45,1.0103446,3.9727213,17.999722,97.315193,-11.482826
163.2639,0.85312498,9.5407991,0.0,0,18.0,1.4012985e-45,1.0107853,3.9536202,18.000153,94.774406,-11.482549
164.3639,0.84581792,9.5435009,0.0,0,18.0,1.4012985e-45,1.0112957,3.9203718,17.999996,92.373459,-11.482242
165.4639,0.85980958,9.546155,0.0,0,18.0,1.4012985e-45,1.011767,3.9815373,17.99958,91.181061,-11.482141
166.5639,0.85721427,9.5488863,0.0,0,18.0,1.4012985e-45,1.0122726,3.9681165,17.99959,88.268089,-11.481956
167.6639,0.86191094,9.5511932,0.0,0,18.0,1.4012985e-45,1.0126449,3.98505,18.000151,85.731796,-11.482097
168.7639,0.86785108,9.5535002,0.0,0,18.0,1.4012985e-45,1.0130591,4.0161595,17.999384,76.690392,-11.482432
169.8639,0.86763901,9.5563841,0.0,0,18.0,1.4012985e-45,1.0135665,4.0078988,18.000732,73.922081,-11.482337
170.9639,0.86711687,9.5584526,0.0,0,18.0,1.4012985e-45,1.0139642,4.0049109,18.00017,71.885666,-11.482283
172.0639,0.87714696,9.5606375,0.0,0,18.0,1.4012985e-45,1.0144249,4.0496325,17.999525,70.633751,-11.482328
173.1639,0.8752147,9.5625505,0.0,0,18.0,1.4012985e-45,1.0148245,4.0437903,18.001019,72.794487,-11.482282
174.2639,0.88146305,9.5645733,0.0,0,18.0,1.4012985e-45,1.0151913,4.070498,17.999975,69.950569,-11.482227
175.3639,0.88230819,9.5666246,0.0,0,18.0,1.4012985e-45,1.0155877,4.0690265,17.99926,68.266197,-11.482233
176.4639,0.8805303,9.569253,0.0,0,18.0,1.4012985e-45,1.0160648,4.0599427,17.999788,64.95565,-11.481906
177.5639,0.88069063,9.5710211,0.0,0,18.0,1.4012985e-45,1.0163597,4.0567913,18.000044,63.62114,-11.482056
178.6639,0.88507187,9.5733118,0.0,0,18.0,1.4012985e-45,1.0167376,4.0720243,18.000179,60.630127,-11.482192
179.7639,0.88316023,9.5746126,0.0,0,18.0,1.4012985e-45,1.0169545,4.0662637,17.999151,58.341312,-11.481942
180.8639,0.88321531,9.5763397,0.0,0,18.0,1.4012985e-45,1.017213,4.0677476,17.999563,56.731812,-11.48243
181.9639,0.88059539,9.5781717,0.0,0,18.0,1.4012985e-45,1.017543,4.0560722,18.000206,55.853092,-11.482417
183.0639,0.88237453,9.5801516,0.0,0,18.0,1.4012985e-45,1.017917,4.0586939,17.998732,55.034153,-11.481871
184.1639,0.88245445,9.5820999,0.0,0,18.0,1.4012985e-45,1.018249,4.0626454,17.999363,53.786263,-11.482062
185.2639,0.8905853,9.5835781,0.0,0,18.0,1.4012985e-45,1.0185223,4.098505,17.999634,53.870399,-11.482247
186.3639,0.88443953,9.5848074,0.0,0,18.0,1.4012985e-45,1.0187902,4.0640202,18.000593,53.904476,-11.482089
187.4639,0.88552976,9.5865574,0.0,0,18.0,1.4012985e-45,1.0191392,4.0684619,17.999264,53.671635,-11.481833
188.5639,0.88489914,9.5879917,0.0,0,18.0,1.4012985e-45,1.0194739,4.06774,17.999674,52.308922,-11.481855
189.6639,0.88407934,9.5897131,0.0,0,18.0,1.4012985e-45,1.0198027,4.0620084,18.00045,50.456055,-11.48203
190.7639,0.89046055,9.5911417,0.0,0,18.0,1.4012985e-45,1.0200777,4.0891719,17.999466,49.106804,-11.481706
191.8639,0.8846857,9.5921001,0.0,0,18.0,1.4012985e-45,1.0202506,4.0635877,17.99966,48.978291,-11.481754
192.9639,0.8834585,9.5935116,0.0,0,18.0,1.4012985e-45,1.0204746,4.0518737,17.999769,50.22039,-11.481929
194.0639,0.89674807,9.5951424,0.0,0,18.0,1.4012985e-45,1.0207454,4.114284,17.999363,59.46188,-11.481593
195.1639,0.89441329,9.5966892,0.0,0,18.0,1.4012985e-45,1.0210109,4.1060638,17.999016,61.63887,-11.481652
196.2639,0.8975935,9.5973825,0.0,0,18.0,1.4012985e-45,1.0211221,4.1167946,17.999689,52.469723,-11.481887
197.3639,0.89606744,9.5984774,0.0,0,18.0,1.4012985e-45,1.021337,4.1079884,18.00009,50.416008,-11.481591
198.4639,0.89436847,9.6001196,0.0,0,18.0,1.4012985e-45,1.0216911,4.1009951,17.999332,50.259796,-11.481354
199.5639,0.89539701,9.6006451,0.0,0,18.0,1.4012985e-45,1.0218335,4.1072655,18.00029,48.910263,-11.481841
200.6639,0.88989663,9.6022472,0.0,0,18.0,1.4012985e-45,1.0221415,4.0768509,17.999624,48.167648,-11.481599
201.7639,0.8914482,9.6033697,0.0,0,18.0,1.4012985e-45,1.0223649,4.0799651,17.999935,48.197041,-11.481727
202.8639,0.90425521,9.6042767,0.0,0,18.0,1.4012985e-45,1.0225439,4.1420889,18.00021,49.338535,-11.481616
203.9639,0.89156973,9.6057196,0.0,0,18.0,1.4012985e-45,1.0227728,4.0813293,17.999142,52.207043,-11.481687
205.0639,0.90622318,9.6067467,0.0,0,18.0,1.4012985e-45,1.0229162,4.151875,17.999788,54.020676,-11.48187
205.8639,0.90235406,9.6071644,0.0,0,18.0,1.4012985e-45,1.0229461,4.1341767,17.999899,43.312645,-11.481473