File: examples/hot axisymmetric compression example/data/02 screened data/testID_0135.csv
Time(sec),Force(kN),Jaw(mm),PowAngle(deg),Power(W),Pram,PTemp,Strain,Stress(MPa),Stroke(mm),TC1(C),wedge(mm)
0.0,0.99416518,0.18000603,0.0,0,11.076097,0.0014914301,0.012091248,12.504846,11.076563,23.395477,-9.1291552
1.1,0.9321897,0.0035499856,0.0,0,11.076097,3.2158799,0.00020980914,11.849631,11.076498,23.399916,-9.4993649
2.2,0.89762741,0.0034615232,0.0,0,11.076097,6.5158815,0.00023705002,11.421058,11.07663,23.344275,-9.496397
3.3,0.88019198,0.0034084492,0.0,0,11.076097,9.8158798,0.00022772304,11.213606,11.076288,23.315529,-9.4948378
4.4,0.86544609,0.0031862436,0.0,0,11.076097,13.11588,0.00021419817,11.028971,11.077227,23.291763,-9.4930038
5.5,0.85306489,0.0033861864,0.0,0,11.076097,16.415878,0.00024216363,10.85423,11.07664,23.27039,-9.4910116
6.6,0.83738714,0.0033661369,0.0,0,11.076097,19.715883,0.00020037414,10.652864,11.076173,23.191612,-9.4884586
7.7,0.82495606,0.0035200855,0.0,0,11.076097,23.015884,0.00023393857,10.492567,11.076017,23.15184,-9.4863815
8.8,0.81777871,0.0036694056,21.513649,0,11.076097,26.31588,0.00023842331,10.413627,11.0769,23.245949,-9.4842644
9.9,0.82177299,0.0034677868,33.787895,0,11.076097,29.615883,0.00024181031,10.461471,11.075724,23.730019,-9.4823294
11.0,0.82834351,0.0011921487,40.523293,0,11.076097,32.915886,0.00010017077,10.542245,11.075152,25.156902,-9.480835
12.1,0.8388555,-0.0012916862,44.341438,0,11.076097,36.215893,-0.00010583481,10.67705,11.076165,27.668079,-9.4789333
13.2,0.8476162,-0.0043330584,46.515636,0,11.076097,39.515896,-0.00029409543,10.812414,11.07597,31.090359,-9.4769726
14.3,0.85328043,-0.0072932984,47.502396,0,11.076097,42.815895,-0.00049652619,10.864643,11.075537,34.962696,-9.4748049
15.4,0.85594976,-0.010494785,48.38269,0,11.076097,46.115894,-0.00069373677,10.905509,11.075613,38.978226,-9.4727421
16.5,0.8607614,-0.013743653,48.812252,0,11.076097,49.41589,-0.00089761941,10.977176,11.075376,43.075626,-9.4705877
17.6,0.86826974,-0.016728615,49.228561,0,11.076097,52.715889,-0.00113454,11.07333,11.075239,47.224422,-9.4685278
18.7,0.87526524,-0.019917747,49.602207,0,11.076097,56.015888,-0.0013320051,11.161593,11.075773,51.219383,-9.466238
19.8,0.87681437,-0.023209685,49.571335,0,11.076097,59.315884,-0.0015596092,11.185614,11.07669,55.246494,-9.4645081
20.9,0.88860309,-0.026633818,49.636223,0,11.076097,62.615883,-0.0017601952,11.335765,11.076877,59.239567,-9.4626446
22.0,0.89272064,-0.029321333,49.476807,0,11.076097,65.915878,-0.0019263994,11.38135,11.076029,63.170807,-9.4611158
23.1,0.89212835,-0.032202043,49.452991,0,11.076097,69.215897,-0.0021707711,11.384429,11.075468,66.903778,-9.4589205
24.2,0.8949911,-0.034399331,49.437481,0,11.076097,72.515892,-0.0022946491,11.408184,11.076074,70.612801,-9.4566593
25.3,0.88805509,-0.037313811,49.536976,0,11.076097,75.815903,-0.0024979305,11.327366,11.076565,74.139198,-9.4546518
26.4,0.8936106,-0.039610919,49.636227,0,11.076097,79.115891,-0.0026279984,11.426578,11.076589,77.654892,-9.4527111
27.5,0.89832991,-0.042121362,49.645164,0,11.076097,82.415894,-0.0027866373,11.473215,11.07492,81.142998,-9.4506559
28.6,0.90696049,-0.044970054,50.042721,0,11.076097,85.715889,-0.0030149617,11.580522,11.076128,84.444099,-9.4487267
29.7,0.90463126,-0.047779836,50.072571,0,11.076097,89.015884,-0.0031747997,11.558311,11.075052,87.823036,-9.4466162
30.8,0.90831345,-0.049967669,50.380398,0,11.076097,92.31588,-0.0033402077,11.617485,11.077243,91.149483,-9.4448442
31.9,0.90638781,-0.05272726,50.653591,0,11.076097,95.615883,-0.0034983363,11.587109,11.07539,94.461044,-9.442914
33.0,0.91853201,-0.055115614,51.105633,0,11.076097,98.915886,-0.0036448725,11.742197,11.076167,97.560722,-9.4410934
34.1,0.92294246,-0.057709843,51.331367,0,11.076097,102.21587,-0.0038584236,11.793227,11.07552,100.78798,-9.4392252
35.2,0.92168319,-0.060669634,51.56982,0,11.076097,105.51588,-0.0040368,11.775237,11.076335,104.1561,-9.4374495
36.3,0.9198432,-0.063045271,51.574047,0,11.076097,108.81587,-0.0042096623,11.764879,11.074963,107.56304,-9.4353266
37.4,0.92807323,-0.066029288,52.232105,0,11.076097,112.11589,-0.0043792278,11.873015,11.076721,110.67707,-9.4332943
38.5,0.93113887,-0.068679146,52.37756,0,11.076097,115.41589,-0.0045574494,11.905341,11.076953,113.93905,-9.4313383
39.6,0.92706966,-0.071632758,52.664963,0,11.076097,118.71589,-0.0047801654,11.860473,11.075441,117.18159,-9.4295568
40.7,0.92764413,-0.074463829,52.952099,0,11.076097,122.0159,-0.0049348818,11.868321,11.074615,120.70681,-9.4273882
41.8,0.93390059,-0.077398092,52.819668,0,11.076097,125.3159,-0.0051626917,11.947318,11.077168,124.17108,-9.4252119
42.9,0.93992418,-0.080172434,53.314529,0,11.076097,128.61601,-0.0053268187,12.028067,11.075544,127.27708,-9.4233494
44.0,0.9386906,-0.083518215,53.141228,0,11.076097,131.91589,-0.0055411789,12.022863,11.076705,130.91985,-9.4216461
45.1,0.9450615,-0.085867696,53.308441,0,11.076097,135.21588,-0.0057227504,12.100609,11.076815,134.31085,-9.4197969
46.2,0.94449162,-0.089049734,53.31665,0,11.076097,138.51588,-0.0059222216,12.102231,11.075996,137.73232,-9.4181013
47.3,0.9588272,-0.091336772,53.318481,0,11.076097,141.81587,-0.006088967,12.286517,11.076154,140.99509,-9.4162464
48.4,0.96038693,-0.093832344,53.655994,0,11.076097,145.11589,-0.0062266625,12.311233,11.076731,144.21042,-9.4138756
49.5,0.95800579,-0.097235084,53.657223,0,11.076097,148.41588,-0.0064549306,12.275289,11.075841,147.77542,-9.4120569
50.6,0.96501315,-0.10090376,53.975712,0,11.076097,151.71588,-0.0067051644,12.370644,11.076702,150.6926,-9.4101744
51.7,0.96242589,-0.10234234,54.32169,0,11.076097,155.01588,-0.0067898664,12.352639,11.076056,153.84822,-9.40833
52.8,0.96305281,-0.10488456,54.624023,0,11.076097,158.31589,-0.0069869519,12.357445,11.075824,156.9856,-9.4062023
53.9,0.95552039,-0.1080455,54.869392,0,11.076097,161.61589,-0.0071695596,12.275803,11.07576,160.33922,-9.4047079
55.0,0.95910585,-0.11075971,55.236473,0,11.076097,164.91588,-0.0073329704,12.325546,11.075918,163.47499,-9.4029007
56.1,0.96451449,-0.11317905,55.533009,0,11.076097,168.2159,-0.0075244806,12.37635,11.075752,166.57356,-9.4008741
57.2,0.96124601,-0.11757711,55.843506,0,11.076097,171.5159,-0.0078044333,12.341778,11.076203,169.91241,-9.3989162
58.3,0.96866697,-0.12056132,56.03788,0,11.076097,174.8159,-0.0080113942,12.434637,11.075971,173.3215,-9.3974571
59.4,0.96179163,-0.12317372,56.128532,0,11.076097,178.11589,-0.0081634428,12.356969,11.076181,176.74565,-9.3953924
60.5,0.95984858,-0.12613189,56.382282,0,11.076097,181.41589,-0.0083548659,12.339056,11.077842,179.95181,-9.3935223
61.6,0.96712875,-0.12908289,56.711422,0,11.076097,184.7159,-0.0085787326,12.421185,11.076398,183.16661,-9.3914576
62.7,0.972642,-0.13259657,56.898422,0,11.076097,188.0159,-0.0087884478,12.498743,11.07722,186.50824,-9.3897715
63.8,0.96393895,-0.13621099,57.157482,0,11.076097,191.31589,-0.0090473834,12.382665,11.076573,189.69449,-9.3875275
64.9,0.95941561,-0.13844292,57.488583,0,11.076097,194.61589,-0.0091700861,12.341912,11.07625,192.91776,-9.385519
66.0,0.96180516,-0.14177002,57.542439,0,11.076097,197.91589,-0.009399089,12.375175,11.076499,196.26907,-9.3832769
67.1,0.97457135,-0.14452882,57.751198,0,11.076097,201.2159,-0.0095893964,12.545102,11.076152,199.7753,-9.3815756
68.2,0.97199714,-0.14866039,57.812649,0,11.076097,204.5159,-0.0098575642,12.507983,11.077598,203.17192,-9.3798323
69.3,0.96027029,-0.15139779,57.815571,0,11.076097,207.81589,-0.010051753,12.34876,11.076326,206.61993,-9.3777304
70.4,0.96538335,-0.15441598,58.073727,0,11.076097,211.11589,-0.010237933,12.412299,11.075789,209.85231,-9.3762341
71.5,0.97039551,-0.15732224,58.279785,0,11.076097,214.41589,-0.010424072,12.489635,11.076242,213.24341,-9.3744221
72.6,0.97093737,-0.15976728,58.337902,0,11.076097,217.7159,-0.010600153,12.494391,11.076218,216.47345,-9.372674
73.7,0.97396547,-0.1653043,58.59008,0,11.076097,221.01588,-0.010949462,12.539146,11.076427,219.6965,-9.3706865
74.8,0.95828027,-0.16685238,58.853588,0,11.076097,224.3159,-0.011083943,12.333223,11.076203,223.02397,-9.3692579
75.9,0.96806765,-0.16997285,58.79763,0,11.076097,227.61589,-0.011263382,12.461379,11.076319,226.53897,-9.3673
77.0,0.97034681,-0.17269151,58.853752,0,11.076097,230.91589,-0.011439717,12.509719,11.076919,229.83798,-9.3650827
78.1,0.97259378,-0.17614122,59.106438,0,11.076097,234.2159,-0.011674579,12.525183,11.076221,233.09837,-9.3631821
79.2,0.96984959,-0.17941055,59.348137,0,11.076097,237.5159,-0.011868942,12.492948,11.075572,236.27155,-9.3613815
80.3,0.96592939,-0.18211159,59.599892,0,11.076097,240.8159,-0.012080599,12.454464,11.075582,239.49258,-9.3596954
81.4,0.96910655,-0.18538047,59.831337,0,11.076097,244.11589,-0.012272876,12.496874,11.076767,242.71725,-9.3575191
82.5,0.97861356,-0.18943276,59.99184,0,11.076097,247.41589,-0.012547656,12.62201,11.075272,245.94455,-9.3555613
83.6,0.96698236,-0.19183697,60.125488,0,11.076097,250.7159,-0.012703855,12.456269,11.076547,249.26494,-9.3537922
84.7,0.97049421,-0.19514365,60.39608,0,11.076097,254.0159,-0.012905701,12.51863,11.075796,252.44267,-9.3518162
85.8,0.97663832,-0.19761731,60.78286,0,11.076097,257.31619,-0.013101601,12.600792,11.075693,255.59291,-9.3499107
86.9,0.98155659,-0.20289837,60.787346,0,11.076097,260.61618,-0.013439078,12.660708,11.076293,259.08472,-9.3481493
88.0,0.9658699,-0.2049626,60.798016,0,11.076097,263.91589,-0.013570784,12.472636,11.075787,262.57062,-9.3465652
89.1,0.96977752,-0.20772904,61.018063,0,11.076097,267.21588,-0.013748487,12.52262,11.075431,265.85043,-9.3445683
90.2,0.97990167,-0.21091978,61.218605,0,11.076097,270.5159,-0.01395226,12.659351,11.076715,269.13571,-9.3429928
91.3,0.96947503,-0.21482579,61.237789,0,11.076097,273.81589,-0.014238629,12.511319,11.076033,272.63229,-9.3407927
92.4,0.96868759,-0.21743022,61.237789,0,11.076097,277.11588,-0.014387297,12.508397,11.075617,276.04825,-9.3388281
93.5,0.97290963,-0.22064382,61.468464,0,11.076097,280.41589,-0.014600094,12.582033,11.075698,279.33804,-9.3374186
94.6,0.98511881,-0.22642674,61.683773,0,11.076097,283.71585,-0.014974432,12.730387,11.075919,282.4165,-9.3353596
95.7,0.97275835,-0.22809049,61.896896,0,11.076097,287.0159,-0.015072187,12.573985,11.076574,285.702,-9.3333111
96.8,0.97527915,-0.23071276,61.932446,0,11.076097,290.31589,-0.015278533,12.610721,11.076646,289.00336,-9.3309736
97.9,0.98053628,-0.23700154,62.116692,0,11.076097,293.61588,-0.01567957,12.683532,11.076125,292.29379,-9.3293285
99.0,0.9692657,-0.23830478,62.179646,0,11.076097,296.91589,-0.015759485,12.530163,11.076563,295.68515,-9.3274288
100.1,0.97975278,-0.24145691,62.334465,0,11.076097,300.21591,-0.015965234,12.670252,11.076331,298.99988,-9.3255177
101.2,0.98156756,-0.2463963,62.384605,0,11.076097,303.5159,-0.016275862,12.711913,11.075604,302.39435,-9.323534
102.3,0.96947515,-0.24821809,62.545162,0,11.076097,306.81589,-0.016433164,12.550657,11.075938,305.70071,-9.3219719
103.4,0.97850502,-0.2513313,62.753868,0,11.076097,310.11591,-0.016612981,12.684829,11.075838,308.92099,-9.3200407
104.5,0.98284239,-0.25576299,62.962616,0,11.076097,313.41589,-0.016924236,12.72313,11.07512,312.06824,-9.3181
105.6,0.9708938,-0.25822029,63.171108,0,11.076097,316.71591,-0.017061396,12.577394,11.075756,315.31168,-9.3165979
106.7,0.9752506,-0.26119435,63.369137,0,11.076097,320.01587,-0.017236374,12.643292,11.07551,318.40033,-9.3144493
107.8,0.98072803,-0.26372045,63.577873,0,11.076097,323.31592,-0.017456573,12.704082,11.075624,321.62317,-9.312973
108.9,0.98099434,-0.26913154,63.775627,0,11.076097,326.61591,-0.017780481,12.711471,11.075771,324.93988,-9.3113775
110.0,0.96790147,-0.27160951,63.973351,0,11.076097,329.91437,-0.017947229,12.550739,11.075562,328.29602,-9.3092957
111.1,0.97636688,-0.27403137,62.137703,0,11.076097,329.99976,-0.018095206,12.660901,11.075475,331.46164,-9.3092651
112.2,0.98290092,-0.27635363,60.241455,0,11.076097,329.99976,-0.018243128,12.757381,11.076265,334.00006,-9.3094959
113.3,0.98125923,-0.27765945,58.522209,0,11.076097,329.99976,-0.018364368,12.709225,11.075554,335.6413,-9.3095245
114.4,0.96801424,-0.27825955,56.988342,0,11.076097,329.99976,-0.01836838,12.560266,11.075506,336.51123,-9.3093138
115.5,0.96241641,-0.27811307,55.67202,0,11.076097,329.99976,-0.01837034,12.45994,11.075654,336.85193,-9.3091116
116.6,0.95514798,-0.27793831,54.635288,0,11.076097,329.99976,-0.018357703,12.409196,11.076255,336.78445,-9.3087502
117.7,0.95404983,-0.27951556,53.796963,0,11.076097,329.99976,-0.018436201,12.375776,11.075273,336.48193,-9.3085289
118.8,0.94330239,-0.27802315,53.299927,0,11.076097,329.99976,-0.018377688,12.232147,11.076765,336.02664,-9.3084507
119.9,0.92760748,-0.27775019,52.761883,0,11.076097,329.99976,-0.018345878,12.046127,11.075921,335.38129,-9.3076944
121.0,0.93897015,-0.2770372,52.635502,0,11.076097,329.99976,-0.018304387,12.189378,11.076207,334.61945,-9.3081446
122.1,0.93349177,-0.27791911,52.621765,0,11.076097,329.99976,-0.01834777,12.117025,11.076649,333.91345,-9.3080664
123.2,0.94323957,-0.27706185,52.635494,0,11.076097,329.99976,-0.01827845,12.226834,11.075751,333.12714,-9.3087864
124.3,0.91901368,-0.27710623,52.856609,0,11.076097,329.99976,-0.01832347,11.910101,11.075521,332.46423,-9.3082523
125.4,0.91415077,-0.27683607,52.97607,0,11.076097,329.99976,-0.018290101,11.865925,11.076034,331.91156,-9.3075752
126.5,0.92016816,-0.27643773,53.253727,0,11.076097,329.99976,-0.018256629,11.935527,11.075617,331.36002,-9.3074245
127.6,0.93514204,-0.27658486,53.399788,0,11.076097,329.99976,-0.01825954,12.119314,11.075951,330.89316,-9.3078623
128.7,0.93518674,-0.27866623,53.657223,0,11.076097,329.99976,-0.01838458,12.137811,11.075756,330.6098,-9.3078585
129.8,0.93144941,-0.27699238,53.80645,0,11.076097,329.99976,-0.018318055,12.067847,11.076332,330.31357,-9.308176
130.9,0.92757946,-0.27736306,53.975826,0,11.076097,329.99976,-0.018326214,12.035588,11.076362,330.08768,-9.3080721
132.0,0.9254247,-0.27763349,53.975857,0,11.076097,329.99976,-0.018343132,12.013078,11.075729,330.04373,-9.307683
133.1,0.92923236,-0.27782652,54.099571,0,11.076097,329.99976,-0.018341484,12.050604,11.07579,329.92914,-9.3075266
134.2,0.9368549,-0.27805898,54.305054,0,11.076097,329.99976,-0.018344803,12.164035,11.07593,329.84311,-9.30758
135.3,0.94496322,-0.2780782,54.191803,0,11.076097,329.99976,-0.018375715,12.249223,11.075896,329.90741,-9.3072977
136.4,0.94502091,-0.27887094,54.301052,0,11.076097,329.99976,-0.018423697,12.261033,11.075559,329.89233,-9.3074503
137.5,0.95251459,-0.28045651,54.196445,0,11.076097,329.99976,-0.018533863,12.349114,11.075882,329.93115,-9.3075571
138.6,0.94779474,-0.28171298,54.129433,0,11.076097,329.99976,-0.018592963,12.299632,11.075505,329.99475,-9.3072481
139.7,0.94802815,-0.28122619,54.090996,0,11.076097,329.99976,-0.018551957,12.300146,11.075643,330.04465,-9.307662
140.8,0.94241673,-0.28080815,53.975834,0,11.076097,329.99976,-0.018564448,12.213244,11.075737,330.07098,-9.307826
141.9,0.93870693,-0.2815972,53.975842,0,11.076097,329.99976,-0.018589783,12.16538,11.075804,330.142,-9.3076305
143.0,0.93289828,-0.28206152,53.975834,0,11.076097,329.99976,-0.018634489,12.109473,11.07612,330.18414,-9.3071499
144.1,0.93445545,-0.28218314,53.846642,0,11.076097,329.99976,-0.018632613,12.122607,11.076006,330.22684,-9.3071604
145.2,0.9399547,-0.28265384,53.772968,0,11.076097,329.99976,-0.018649256,12.18882,11.075714,330.25879,-9.3070536
146.3,0.94338441,-0.28259861,53.657246,0,11.076097,329.99976,-0.018677767,12.25536,11.075525,330.30811,-9.3067884
147.4,0.92791265,-0.28336704,53.65723,0,11.076097,329.99976,-0.018706324,12.034545,11.075994,330.27841,-9.3062868
148.5,0.94204479,-0.28360507,53.65723,0,11.076097,329.99976,-0.018733226,12.23122,11.07471,330.27118,-9.3063726
149.6,0.95206928,-0.28372395,53.471268,0,11.076097,329.99976,-0.018728279,12.357242,11.0763,330.32059,-9.3063774
150.7,0.94093138,-0.28409496,53.325165,0,11.076097,329.99976,-0.018744187,12.203677,11.075521,330.35196,-9.3066988
151.8,0.95229805,-0.2846514,53.361076,0,11.076097,329.99976,-0.018823765,12.348541,11.07542,330.26184,-9.3068476
152.9,0.95392042,-0.28605664,53.46143,0,11.076097,329.99976,-0.018896192,12.382571,11.075112,330.25314,-9.3071871
154.0,0.95628726,-0.28694144,53.316666,0,11.076097,329.99976,-0.018949563,12.396947,11.076773,330.29919,-9.3067198
155.1,0.95638305,-0.04778092,53.316803,0,11.076097,329.99976,-0.0031436307,12.216859,11.076571,330.21075,-9.3071184
155.2826,0.93367279,0.032300066,32.523136,0,11.076099,1.5468613e-08,0.0023368734,11.840873,11.073837,330.22403,-9.3063269
155.2848,0.95143759,0.03545884,20.79347,0,11.076099,1.544973e-23,0.0020845209,12.095788,11.073962,330.25085,-9.3075132
155.287,0.93103904,0.036052845,9.0638094,0,11.076099,1.5430874000000001e-38,0.0026708986,11.846425,11.078656,330.27768,-9.308301
155.2892,0.93982172,0.039682675,0.0,0,11.076099,0.0,0.0023885639,11.899323,11.081247,330.29993,-9.3078203
155.2914,0.9402386,0.03584373,0.0,0,11.076099,0.0,0.0025788606,11.935054,11.075738,330.30661,-9.3075838
155.2936,0.93039858,0.036648694,0.0,0,11.076099,0.0,0.002218355,11.823867,11.077613,330.31332,-9.3068113
155.2958,0.93531507,0.034338184,0.0,0,11.076099,0.0,0.0025500727,11.897612,11.077212,330.32004,-9.3069487
155.298,0.92677635,0.039436452,0.0,0,11.076099,0.0,0.0022999048,11.855606,11.081607,330.32672,-9.308135
155.3002,0.9352755,0.033414096,0.0,0,11.076099,0.0,0.0024780349,11.921041,11.075201,330.3197,-9.3068581
155.3024,0.93096393,0.035902698,0.0,0,11.076099,0.0,0.0022148073,11.828715,11.075521,330.3063,-9.3068161
155.3046,0.92571604,0.033378955,0.0,0,11.076099,0.0,0.0025557464,11.836002,11.079288,330.29291,-9.3068466
155.3068,0.91536021,0.041420724,0.0,0,11.076099,0.0,0.0024251232,11.661209,11.07804,330.27948,-9.3074884
155.309,0.92275739,0.033698585,0.0,0,11.076099,0.0,0.0024191772,11.657811,11.07672,330.26517,-9.3068562
155.3112,0.91590905,0.035847437,0.0,0,11.076099,0.0,0.0022855822,11.715306,11.078827,330.24506,-9.3070841
155.3134,0.92350924,0.033971019,0.0,0,11.076099,0.0,0.0025503184,11.728036,11.077542,330.22495,-9.3064089
155.3156,0.93277341,0.041391965,0.0,0,11.076099,0.0,0.0024578858,11.793007,11.076072,330.20483,-9.3069773
155.3178,0.93049425,0.033542495,0.0,0,11.076099,0.0,0.0024137651,11.798563,11.077588,330.18472,-9.3076811
155.32,0.92307949,0.036216207,0.0,0,11.076099,0.0,0.0022859112,11.786094,11.077149,330.17648,-9.3069096
155.3222,0.91278291,0.034410585,0.0,0,11.076099,0.0,0.0024528098,11.57346,11.078139,330.17648,-9.3069706
155.3244,0.91087824,0.040160216,0.0,0,11.076099,0.0,0.0024993885,11.594994,11.07609,330.17648,-9.3073626
155.3266,0.91657609,0.033902302,0.0,0,11.076099,0.0,0.0023763608,11.619265,11.077394,330.17648,-9.3062258
155.3288,0.92348796,0.035229262,0.0,0,11.076099,0.0,0.0023575779,11.73584,11.077706,330.1777,-9.3070259
155.331,0.92219031,0.032367863,0.0,0,11.076099,0.0,0.002239648,11.66351,11.075612,330.20453,-9.3071346
155.3332,0.92824721,0.039831501,0.0,0,10.765901,0.0,0.0025989348,11.636041,11.075077,330.23135,-9.3072481
155.3354,0.92105389,0.035064116,0.0,0,10.435008,0.0,0.0023395699,11.691023,11.073338,330.25818,-9.3056583
155.3376,0.93409312,0.035716981,0.0,0,10.104116,0.0,0.0023998793,11.830537,11.023255,330.285,-9.3063679
155.3398,0.90173203,0.034076847,0.0,0,9.7732229,0.0,0.0021967941,11.533395,10.847696,330.60004,-9.3057079
155.342,0.93244261,0.037517253,0.0,0,9.4434071,0.0,0.0025614493,11.788771,10.556972,331.20328,-9.3070154
155.3442,0.91497684,0.03510863,0.0,0,9.1214981,0.0,0.0022481652,11.665577,10.164512,331.80652,-9.3067532
155.3464,7.1073799,0.29927117,0.0,0,8.7995939,0.0,0.019553082,88.414581,9.766923,332.40976,-9.3018894
155.3486,9.0286417,0.65956062,0.0,0,8.4910259,0.0,0.044568297,109.37731,9.3315182,333.013,-9.3003435
155.3508,9.5786724,1.0511856,0.0,0,8.1848736,0.0,0.072599664,112.99609,8.9315138,333.56516,-9.2991743
155.353,9.9314241,1.3972894,0.0,0,7.8872557,0.0,0.097035401,114.94881,8.594492,334.11487,-9.2989664
155.3552,10.417478,1.6920284,0.0,0,7.5959754,0.0,0.11943962,117.32692,8.2702274,334.66461,-9.2995443
155.3574,10.620845,2.000381,0.0,0,7.3089881,0.0,0.14244166,117.38868,7.9507747,335.21436,-9.299202
155.3596,10.908585,2.2992022,0.0,0,7.0319633,0.0,0.16621432,117.52422,7.659678,335.56107,-9.2990141
155.3618,11.269726,2.5757041,0.0,0,6.7554417,0.0,0.18761903,118.77718,7.3772302,335.61453,-9.2998543
155.364,11.547348,2.8412855,0.0,0,6.4917622,0.0,0.20990214,119.20971,7.0978374,335.66803,-9.2997026
155.3662,11.79831,3.1135094,0.0,0,6.2282019,0.0,0.23189203,119.08717,6.8230519,335.72153,-9.2990437
155.3684,12.115691,3.3769073,0.0,0,5.9743834,0.0,0.25510073,119.48695,6.5529079,335.77499,-9.2991962
155.3706,12.368779,3.6456797,0.0,0,5.7237153,0.0,0.27745619,119.30453,6.2851334,335.33069,-9.2986155
155.3728,12.632616,3.8968222,0.0,0,5.4789333,0.0,0.30091467,118.99057,6.0285873,334.80777,-9.2985888
155.375,12.914494,4.1545525,0.0,0,5.2404532,0.0,0.32348558,118.87961,5.7699676,334.28485,-9.2997913
155.3772,13.203218,4.4010959,0.0,0,5.0044241,0.0,0.34740645,118.66116,5.5214028,333.76193,-9.2999992
155.3794,13.500341,4.6530333,0.0,0,4.7776041,0.0,0.37034613,118.61994,5.2725387,332.92337,-9.3005705
155.3816,13.834229,4.8871007,0.0,0,4.5507841,0.0,0.3943108,118.73004,5.0316,331.40845,-9.2990932
155.3838,14.166578,5.1301508,0.0,0,4.3343177,0.0,0.41776314,118.74586,4.7913637,329.89352,-9.2987299
155.386,14.459109,5.3595209,0.0,0,4.1185417,0.0,0.44225121,118.27355,4.5579033,328.37857,-9.2991924
155.3882,14.781473,5.59552,0.0,0,3.9097853,0.0,0.46582839,118.06376,4.331882,326.86365,-9.2986603
155.3904,15.108071,5.8020015,0.0,0,3.7045693,0.0,0.48907685,117.92392,4.1134057,325.41003,-9.2986803
155.3926,15.456581,6.0186801,0.0,0,3.5032687,0.0,0.51213527,117.84888,3.8991838,323.97446,-9.2985764
155.3948,15.819256,6.2215466,0.0,0,3.3080409,0.0,0.53578651,117.74851,3.6934524,322.53891,-9.2985897
155.397,16.22463,6.4347997,0.0,0,3.11395,0.0,0.55931878,118.0321,3.4919317,321.10333,-9.2982264
155.3992,16.654881,6.625176,0.0,0,2.9282222,0.0,0.58272439,118.33855,3.2892148,319.42044,-9.2980556
155.4014,17.115332,6.8266115,0.0,0,2.7424984,0.0,0.60634571,118.74823,3.0970392,316.89664,-9.2984715
155.4036,17.584597,7.0116396,0.0,0,2.5644474,0.0,0.62993997,119.25124,2.9037111,314.37286,-9.2976418
155.4058,18.069876,7.2101197,0.0,0,2.3877873,0.0,0.65454036,119.53307,2.7172649,311.84909,-9.2979202
155.408,18.568743,7.3841949,0.0,0,2.2160764,0.0,0.67758417,120.02952,2.5305622,309.32529,-9.2972469
155.4102,19.108616,7.5694718,0.0,0,2.0480404,0.0,0.70194995,120.48503,2.3493211,309.29535,-9.2974224
155.4124,19.659235,7.745141,0.0,0,1.8824685,0.0,0.72599506,121.04961,2.1749551,310.4292,-9.2976923
155.4146,20.24332,7.9229813,0.0,0,1.7226164,0.0,0.75083053,121.59834,2.0008492,311.56305,-9.2974882
155.4168,20.873987,8.083622,0.0,0,1.5630548,0.0,0.7737267,122.53165,1.830716,312.6969,-9.2965002
155.419,21.547108,8.2488289,0.0,0,1.4109213,0.0,0.79804999,123.39888,1.673007,314.13916,-9.296608
155.4212,22.255777,8.4063005,0.0,0,1.2588574,0.0,0.82131332,124.57166,1.512779,317.53458,-9.2968454
155.4234,22.986305,8.5692635,0.0,0,1.1124125,0.0,0.84702361,125.4157,1.354113,320.92996,-9.2958622
155.4256,23.743843,8.7183685,0.0,0,0.96778435,0.0,0.86947954,126.6875,1.1973881,324.32538,-9.2947121
155.4278,24.5242,8.8642235,0.0,0,0.82657731,0.0,0.89400935,127.66582,1.0495564,327.72076,-9.2944422
155.43,25.352745,9.0076914,0.0,0,0.68903339,0.0,0.91646546,129.00584,0.90498447,329.75903,-9.294528
155.4322,26.188992,9.1452475,0.0,0,0.55288601,0.0,0.94123989,130.01106,0.76227111,330.85776,-9.2940388
155.4344,27.039337,9.2775612,0.0,0,0.42198589,0.0,0.96227229,131.48003,0.62856543,331.95645,-9.2937984
155.4366,27.457674,9.395237,0.0,0,0.29108587,0.0,0.98499382,130.99442,0.50228816,333.05518,-9.2924452
155.4388,25.553112,9.4274864,0.0,0,0.16620816,0.0,0.9891215,121.1596,0.44436845,334.17786,-9.2938318
155.441,23.955494,9.4356451,0.0,0,0.041732151,0.0,0.99293298,113.07127,0.41424266,335.80386,-9.2957172
155.4432,23.426779,9.4381523,0.0,0,-0.080696426,0.0,0.99091399,110.80322,0.38928604,337.42984,-9.2976484
155.4454,23.37817,9.4437456,0.0,0,-0.20209241,0.0,0.99423003,110.07894,0.34680384,339.05585,-9.2977381
155.4476,23.484627,9.4542713,0.0,0,-0.32348844,0.0,0.99399954,110.63917,0.2920101,340.68185,-9.297349
155.4498,23.513023,9.4562197,0.0,0,-0.44488442,0.0,0.9966166,110.48981,0.22998388,342.05304,-9.2981262
155.452,23.461615,9.4686546,0.0,0,-0.56628042,0.0,0.99614894,110.35534,0.17362969,343.1694,-9.2985573
155.4542,23.338104,9.4619894,0.0,0,-0.68767637,0.0,0.99747747,109.59031,0.12148179,344.2858,-9.299592
155.4564,23.180548,9.4740458,0.0,0,-0.80907238,0.0,0.99749905,108.83412,0.077295244,345.40219,-9.2982016
155.4586,22.933226,9.4726439,0.0,0,-0.93046838,0.0,0.99962986,107.45205,0.041210555,346.51855,-9.2974749
155.4608,22.601568,9.4839716,0.0,0,-1.0518645,0.0,0.99905193,105.98533,0.015011731,347.02875,-9.298399
155.463,22.162569,9.4777145,0.0,0,-0.88153589,330.0,1.0003411,103.79847,0.00616591,347.51004,-9.2981815
155.4652,21.636189,9.4850559,0.0,0,-0.46125633,330.0,0.9998762,101.40168,0.0072931587,347.99136,-9.2987309
155.4674,21.165659,9.4781065,0.0,0,-0.040977493,330.0,1.0001763,99.168831,0.010932209,348.47266,-9.3006849
155.4696,20.750113,9.4880276,0.0,0,0.37930161,330.0,1.0001137,97.261421,0.018601349,348.92105,-9.3005753
155.4718,20.438271,9.4801197,0.0,0,0.79958111,330.0,1.0006455,95.711197,0.019166632,349.3219,-9.299736
155.474,20.173689,9.4884729,0.0,0,1.2198603,330.0,1.0005054,94.48954,0.017763417,349.72272,-9.2993727
155.4762,19.556826,9.4773903,0.0,0,1.640139,330.0,0.99988371,91.742966,0.030703185,350.12357,-9.2999754
155.4784,18.155018,9.4807625,0.0,0,2.0604188,330.0,0.99918139,85.252747,0.088217981,350.52438,-9.3010979
155.4806,15.673153,9.4675484,0.0,0,2.4806981,330.0,0.99781448,73.851967,0.19280384,350.8327,-9.3036842
155.4828,11.296551,9.460309,0.0,0,2.9009769,330.0,0.99594218,53.592213,0.38484198,351.1264,-9.3053761
155.485,-0.061517376,9.3183756,0.0,0,3.3212562,330.0,0.97166461,-0.79992837,0.70619857,351.42014,-9.3183222
155.4872,0.35003638,9.2096548,0.0,0,3.7415352,330.0,0.95205325,1.5098706,1.3184712,351.71384,-9.3192205
155.4894,-0.11414844,9.1789579,0.0,0,4.1618147,330.0,0.94639742,-0.30836588,2.1074131,351.88226,-9.3165531
155.4916,-0.13031282,9.255785,0.0,0,4.5820937,330.0,0.95965558,-0.80072039,2.8406103,351.78226,-9.3171453
155.4938,0.7623387,9.3827887,0.0,0,5.0023732,330.0,0.98156357,2.9701426,3.4225457,351.68225,-9.3159056
155.496,-0.37504065,9.3805008,0.0,0,5.4226518,330.0,0.98215508,-1.7732548,3.8465481,351.58224,-9.3134995
155.4982,0.058147866,9.3701239,0.0,0,5.8429317,330.0,0.97966123,0.1567978,4.2348275,351.48224,-9.3134642
155.5004,1.6832993,9.4085827,0.0,0,6.2632103,330.0,0.98715413,7.8489642,4.6122856,351.38736,-9.3134565
155.5026,0.10683805,9.3982983,0.0,0,6.6834898,330.0,0.98443848,0.49882928,4.9980731,351.29404,-9.3132591
155.5048,0.76417464,9.3987875,0.0,0,7.1037693,330.0,0.98591381,3.682478,5.3884635,351.20068,-9.3106632
155.507,0.56946164,9.3968058,0.0,0,7.5240483,330.0,0.98393595,2.6712823,5.8056984,351.10736,-9.3103981
155.5092,0.55101216,9.3937273,0.0,0,7.9443278,330.0,0.98505884,2.6545477,6.2341118,351.08371,-9.3108482
155.5114,0.56889677,9.3956814,0.0,0,8.3646069,330.0,0.98371434,2.6858685,6.6863713,351.29706,-9.3098803
155.5136,0.59129661,9.398901,0.0,0,8.7848854,330.0,0.98607725,2.8509436,7.129673,351.51041,-9.3093939
155.5158,0.51561642,9.4004164,0.0,0,9.2051649,330.0,0.98421317,2.466615,7.5709591,351.72375,-9.3091536
155.518,0.58245045,9.3937035,0.0,0,9.6254444,330.0,0.98526716,2.7618973,8.0013704,351.93713,-9.3082027
155.5202,0.58404261,9.3950186,0.0,0,10.045724,330.0,0.98337328,2.7377102,8.4391632,352.13229,-9.3086138
155.5224,0.57572889,9.3918056,0.0,0,10.466002,330.0,0.98510623,2.7216773,8.8758469,352.31897,-9.3077269
155.5246,0.61009806,9.402113,0.0,0,10.886282,330.0,0.98450661,2.9224303,9.3063478,352.50568,-9.3069963
155.5268,0.5507338,9.3939295,0.0,0,11.306561,330.0,0.98541886,2.5962427,9.7257004,352.69235,-9.3072538
155.529,0.55382687,9.3997898,0.0,0,11.72684,330.0,0.98420817,2.6375427,10.160601,352.86722,-9.3068399
155.5312,0.55841088,9.3917208,0.0,0,12.14712,330.0,0.98517382,2.646378,10.602498,352.96722,-9.30688
155.5334,0.5681814,9.4010763,0.0,0,12.567399,330.0,0.98410517,2.6830473,11.034473,353.06723,-9.3057461
155.5356,0.57216221,9.3921194,0.0,0,12.987678,330.0,0.98511958,2.7141621,11.460176,353.16724,-9.3056412
155.5378,0.53878272,9.4001303,0.0,0,13.407957,330.0,0.98429918,2.5665843,11.875769,353.26724,-9.3067465
155.54,0.57774103,9.3907738,0.0,0,13.828236,330.0,0.9848485,2.763077,12.292588,353.39484,-9.3062353
155.5422,0.58709234,9.4027071,0.0,0,14.248516,330.0,0.9845165,2.8057981,12.712712,353.5415,-9.306839
155.5444,0.57103521,9.3916149,0.0,0,14.668795,330.0,0.9847548,2.7782249,13.144083,353.68817,-9.3068962
155.5466,0.55174977,9.3949652,0.0,0,15.089074,330.0,0.98371232,2.6193154,13.586692,353.83484,-9.3070393
155.5488,0.59073108,9.3909416,0.0,0,15.509354,330.0,0.98462206,2.8028634,14.031521,353.97818,-9.3062143
155.551,0.57693809,9.4012156,0.0,0,15.929632,330.0,0.98469007,2.7550218,14.471004,354.05154,-9.3055668
155.5532,0.54841924,9.3923397,0.0,0,16.349911,330.0,0.98449582,2.6214068,14.896156,354.12488,-9.3047571
155.5554,0.54112589,9.3977165,0.0,0,16.770191,330.0,0.98438311,2.6320164,15.309315,354.19821,-9.3041382
155.5576,0.54726708,9.3923016,0.0,0,17.19047,330.0,0.98424631,2.6281762,15.728739,354.27155,-9.3060141
155.5598,0.58903652,9.4002886,0.0,0,17.61075,330.0,0.98473424,2.7846024,16.142376,354.3649,-9.3051081
155.562,0.57560533,9.3911009,0.0,0,17.999401,330.0,0.98392236,2.7697823,16.560534,354.47824,-9.3045034
155.5642,0.56443298,9.3981285,0.0,0,18.0,330.0,0.98484272,2.7086332,16.982208,354.59158,-9.3049669
155.5664,0.5597471,9.3955336,0.0,0,18.0,330.0,0.98451203,2.667968,17.387245,354.70493,-9.3053322
155.5686,0.63417304,9.4012117,0.0,0,18.0,330.0,0.98548764,2.9932456,17.754446,354.81827,-9.306344
155.5708,0.6127606,9.3945866,0.0,0,18.0,330.0,0.98422283,2.9400387,18.074152,354.97617,-9.3068047
155.573,0.62265408,9.3951149,0.0,0,18.0,330.0,0.98478019,3.0224619,18.318178,355.13617,-9.3074894
155.5752,0.64637929,9.3945313,0.0,0,18.0,330.0,0.98382515,3.089293,18.486177,355.29617,-9.311553
155.5774,0.68840802,9.3986216,0.0,0,18.0,330.0,0.98555696,3.2386937,18.535723,355.45621,-9.3175735
155.5796,0.73009175,9.3953972,0.0,0,18.0,330.0,0.98383594,3.4503007,18.489359,355.58893,-9.322731
155.5818,0.66933489,9.3958254,0.0,0,18.0,330.0,0.98515129,3.2128491,18.36083,355.68228,-9.3319798
155.584,0.64777535,9.3967247,0.0,0,18.0,330.0,0.98397917,3.0911286,18.226612,355.77563,-9.344595
155.5862,0.67931277,9.3944016,0.0,0,18.0,330.0,0.98521715,3.2159235,18.114822,355.86896,-9.3594322
155.5884,0.68285352,9.3945007,0.0,0,18.0,330.0,0.98331857,3.2395303,18.057636,355.96231,-9.3756285
155.5906,0.68159819,9.3861132,0.0,0,18.0,330.0,0.98365378,3.2554116,18.040993,356.05563,-9.3924618
155.5928,0.68532598,9.3900547,0.0,0,18.0,330.0,0.98258477,3.2410331,18.036905,356.14899,-9.4097862
155.595,0.69027132,9.3905172,0.0,0,18.0,330.0,0.98467118,3.2642093,18.051228,356.24231,-9.42836
155.5972,0.66377288,9.3946657,0.0,0,18.0,330.0,0.98302495,3.2033739,18.07749,356.33566,-9.4464045
155.5994,0.65967262,9.3855915,0.0,0,18.0,330.0,0.98386145,3.1721628,18.095314,356.39929,-9.4637184
155.6016,0.66647154,9.3895979,0.0,0,18.0,330.0,0.98236644,3.1731014,18.114042,356.39929,-9.4809284
155.6038,0.65969133,9.3857346,0.0,0,18.0,330.0,0.98409665,3.1311364,18.133017,356.39929,-9.4970226
155.606,0.6590029,9.3944998,0.0,0,18.0,330.0,0.9828999,3.138339,18.134348,356.39929,-9.5114489
155.6082,0.69327915,9.3823414,0.0,0,18.0,330.0,0.9832828,3.2899866,18.136255,356.39929,-9.5253191
155.6104,0.70844811,9.386673,0.0,0,18.0,330.0,0.98204368,3.379673,18.135357,356.45081,-9.5420151
155.6126,0.71151686,9.3830633,0.0,0,18.0,330.0,0.98357666,3.4266477,18.135048,356.51749,-9.5581484
155.6148,0.70879418,9.3971739,0.0,0,18.0,330.0,0.98351091,3.3760128,18.135672,356.58417,-9.5751629
155.617,0.67935723,9.388401,0.0,0,18.0,330.0,0.98425919,3.2560077,18.132225,356.65085,-9.5913334
155.6192,0.66423583,9.3930569,0.0,0,18.0,330.0,0.98324913,3.1732695,18.131964,356.74023,-9.6058025
155.6214,0.67287207,9.3825531,0.0,0,18.0,330.0,0.98321134,3.227648,18.124502,356.90692,-9.622261
155.6236,0.6691643,9.3953838,0.0,0,18.0,330.0,0.98340917,3.1759815,18.123892,357.07361,-9.6383362
155.6258,0.69767809,9.3846111,0.0,0,18.0,330.0,0.98317313,3.2744732,18.123062,357.2403,-9.6543159
155.628,0.70558453,9.3908463,0.0,0,18.0,330.0,0.98294133,3.34236,18.119804,357.40698,-9.671339
155.6302,0.72828925,9.3874111,0.0,0,18.0,330.0,0.98357737,3.4599764,18.117893,357.43274,-9.6873178
155.6324,0.72097182,9.3954735,0.0,0,18.0,330.0,0.98384053,3.4600332,18.117504,357.39273,-9.7024155
155.6346,0.70143026,9.386364,0.0,0,18.0,330.0,0.98325449,3.3427868,18.112169,357.35272,-9.7178268
155.6368,0.69070005,9.3899813,0.0,0,18.0,330.0,0.98328072,3.3244035,18.113062,357.31271,-9.7329874
155.639,0.66992849,9.3854504,0.0,0,18.0,330.0,0.9829461,3.1930599,18.113222,357.27454,-9.7494841
155.6412,0.6617403,9.3956242,0.0,0,18.0,330.0,0.9844712,3.1774752,18.110149,357.24786,-9.7655478
155.6434,0.69201672,9.3870096,0.0,0,18.0,330.0,0.98296601,3.2644591,18.107384,357.22119,-9.781251
155.6456,0.69749725,9.3865824,0.0,0,18.0,330.0,0.983123,3.3038909,18.105476,357.19452,-9.7979259
155.6478,0.71118033,9.3846674,0.0,0,18.0,330.0,0.98221141,3.3831322,18.106981,357.16785,-9.8136587
155.65,0.7180137,9.3925667,0.0,0,18.0,330.0,0.98417538,3.4327877,18.099257,357.20419,-9.83039
155.6522,0.71890903,9.388895,0.0,0,18.0,330.0,0.98281479,3.414412,18.101774,357.28421,-9.8462524
155.6544,0.67883712,9.3848448,0.0,0,18.0,330.0,0.98303944,3.2517507,18.101505,357.36423,-9.8628159
155.6566,0.67105138,9.3840504,0.0,0,18.0,330.0,0.98187733,3.2071989,18.102541,357.44421,-9.8784132
155.6588,0.66128826,9.3909683,0.0,0,18.0,330.0,0.98437792,3.1650851,18.101072,357.51877,-9.8941679
155.661,0.66179806,9.3905258,0.0,0,18.0,330.0,0.98279774,3.1688836,18.097008,357.47879,-9.9088879
155.6632,0.69741416,9.3838482,0.0,0,18.0,330.0,0.98329765,3.3130596,18.099007,357.43878,-9.9229946
155.6654,0.71205872,9.3865032,0.0,0,18.0,330.0,0.98207182,3.3473003,18.102936,357.39877,-9.9404268
155.6676,0.71912336,9.3881903,0.0,0,18.0,330.0,0.98412639,3.4395902,18.100534,357.35876,-9.9576015
155.6698,0.70890933,9.3917513,0.0,0,18.0,330.0,0.9826622,3.3708146,18.097519,357.35211,-9.9749384
155.672,0.69131726,9.3864317,0.0,0,18.0,330.0,0.98398656,3.3295434,18.098009,357.37878,-9.9907675
155.6742,0.67576039,9.3917923,0.0,0,18.0,330.0,0.98299301,3.2338738,18.098412,357.40546,-10.007339
155.6764,0.67662519,9.386694,0.0,0,18.0,330.0,0.98417372,3.2063348,18.096359,357.43213,-10.022588
155.6786,0.67452389,9.3929653,0.0,0,18.0,330.0,0.98265219,3.1863623,18.0961,357.4588,-10.038128
155.6808,0.68745625,9.3850012,0.0,0,18.0,330.0,0.98381674,3.259201,18.097391,357.4473,-10.05316
155.683,0.72029108,9.3925114,0.0,0,18.0,330.0,0.98294592,3.4169583,18.097219,357.43396,-10.0694
155.6852,0.74281836,9.3868675,0.0,0,18.0,330.0,0.98406941,3.535342,18.094774,357.42062,-10.086342
155.6874,0.7277711,9.3954401,0.0,0,18.0,330.0,0.98299694,3.4840355,18.09218,357.40729,-10.101406
155.6896,0.72923017,9.3867559,0.0,0,18.0,330.0,0.98391831,3.4768655,18.094069,357.39395,-10.117852
155.6918,0.70014739,9.3925819,0.0,0,18.0,330.0,0.98308957,3.3142235,18.090918,357.38062,-10.134316
155.694,0.68786043,9.3849525,0.0,0,18.0,330.0,0.98370171,3.2903895,18.087955,357.36728,-10.149872
155.6962,0.68605733,9.39396,0.0,0,18.0,330.0,0.98307246,3.258636,18.085842,357.35394,-10.164876
155.6984,0.6923998,9.3841352,0.0,0,18.0,330.0,0.98334813,3.3043456,18.085424,357.34064,-10.18048
155.7006,0.71716309,9.3920326,0.0,0,18.0,330.0,0.9831844,3.3521454,18.085726,357.4079,-10.196108
155.7028,0.7460413,9.3838911,0.0,0,18.0,330.0,0.98304623,3.5032771,18.086439,357.48792,-10.212612
155.705,0.75205994,9.3951101,0.0,0,18.0,330.0,0.98353434,3.5706036,18.085703,357.5679,-10.22798
155.7072,0.7429356,9.3863859,0.0,0,18.0,330.0,0.98362941,3.5390713,18.084318,357.64792,-10.244266
155.7094,0.70878083,9.3929262,0.0,0,18.0,330.0,0.9837212,3.3892832,18.083591,357.68124,-10.261327
155.7116,0.70614928,9.3866587,0.0,0,18.0,330.0,0.98336375,3.3814161,18.080914,357.61456,-10.277686
155.7138,0.67532331,9.3944712,0.0,0,18.0,330.0,0.9839316,3.2305315,18.085213,357.54791,-10.294269
155.716,0.6869818,9.3869371,0.0,0,18.0,330.0,0.98305416,3.260819,18.082331,357.48123,-10.309546
155.7182,0.69904053,9.3901644,0.0,0,18.0,330.0,0.98342311,3.2961173,18.082388,357.41455,-10.324803
155.7204,0.74020064,9.3870859,0.0,0,18.0,330.0,0.98295063,3.488039,18.078938,357.42001,-10.340726
155.7226,0.74590975,9.3930416,0.0,0,18.0,330.0,0.98441148,3.5400395,18.080185,357.44669,-10.356096
155.7248,0.74214846,9.3892374,0.0,0,18.0,330.0,0.98291212,3.5685098,18.07984,357.47336,-10.373436
155.727,0.70299619,9.3902216,0.0,0,18.0,330.0,0.98389858,3.3586023,18.079576,357.50003,-10.38961
155.7292,0.69681478,9.3899145,0.0,0,18.0,330.0,0.98324257,3.3043547,18.080225,357.53275,-10.406515
155.7314,0.68934107,9.3956003,0.0,0,18.0,330.0,0.98502064,3.2542241,18.078072,357.58609,-10.42136
155.7336,0.68060565,9.3901653,0.0,0,18.0,330.0,0.98289776,3.2340987,18.077406,357.63943,-10.437084
155.7358,0.68601513,9.3883362,0.0,0,18.0,330.0,0.98379165,3.2448509,18.076586,357.69275,-10.453611
155.738,0.71881282,9.3898659,0.0,0,18.0,330.0,0.98255014,3.3866143,18.078722,357.74609,-10.470124
155.7402,0.74563634,9.3909731,0.0,0,18.0,330.0,0.98450685,3.5258198,18.07687,357.74487,-10.485064
155.7424,0.74149096,9.3947048,0.0,0,18.0,330.0,0.98318416,3.5512204,18.077013,357.7182,-10.499518
155.7446,0.73688132,9.3902483,0.0,0,18.0,330.0,0.9844892,3.5419855,18.068316,357.69156,-10.515109
155.7468,0.71286482,9.391984,0.0,0,18.0,330.0,0.98273098,3.3632824,18.071175,357.66489,-10.531522
155.749,0.68987489,9.3887377,0.0,0,18.0,330.0,0.98443431,3.3057866,18.071835,357.64731,-10.547748
155.7512,0.6879378,9.3929081,0.0,0,18.0,330.0,0.98279041,3.283814,18.07045,357.68732,-10.563167
155.7534,0.70025283,9.3868647,0.0,0,18.0,330.0,0.98417985,3.3160558,18.06941,357.72729,-10.580734
155.7556,0.71734643,9.3930731,0.0,0,18.0,330.0,0.98300308,3.3929756,18.065624,357.7673,-10.597046
155.7578,0.74433774,9.3866892,0.0,0,18.0,330.0,0.98417479,3.5182853,18.067978,357.80731,-10.612562
155.76,0.74759668,9.3962355,0.0,0,18.0,330.0,0.98311573,3.563587,18.06864,357.80002,-10.629243
155.7622,0.74597025,9.3858633,0.0,0,18.0,330.0,0.98389405,3.5931354,18.066311,357.76004,-10.645899
155.7644,0.72277921,9.393527,0.0,0,18.0,330.0,0.98325694,3.4472911,18.067413,357.72003,-10.660365
155.7666,0.71248698,9.3873606,0.0,0,18.0,330.0,0.98436934,3.4085209,18.065832,357.68002,-10.675316
155.7688,0.69543403,9.3974514,0.0,0,18.0,330.0,0.98347455,3.2892799,18.067034,357.63971,-10.692076
155.771,0.68858808,9.3859482,0.0,0,18.0,330.0,0.98381132,3.289861,18.065895,357.59305,-10.709314
155.7732,0.71097475,9.3918066,0.0,0,18.0,330.0,0.98300207,3.3803022,18.063086,357.54639,-10.724299
155.7754,0.74437726,9.3864202,0.0,0,18.0,330.0,0.98371565,3.5476389,18.066671,357.49969,-10.739456
155.7776,0.76234508,9.3982954,0.0,0,18.0,330.0,0.98415333,3.611402,18.063429,357.45303,-10.756283
155.7798,0.76165503,9.3889227,0.0,0,18.0,330.0,0.98393196,3.5972722,18.063131,357.43301,-10.772538
155.782,0.7279126,9.3939342,0.0,0,18.0,330.0,0.98368478,3.4802692,18.06538,357.4397,-10.787562
155.7842,0.71568692,9.3870583,0.0,0,18.0,330.0,0.98361534,3.4227767,18.063765,357.44635,-10.804832
155.7864,0.69151217,9.3981142,0.0,0,18.0,330.0,0.98435426,3.3345318,18.061298,357.45303,-10.819906
155.7886,0.69495445,9.389843,0.0,0,18.0,330.0,0.98378986,3.3137085,18.0599,357.45969,-10.836595
155.7908,0.69474351,9.394928,0.0,0,18.0,330.0,0.98407388,3.2955098,18.060211,357.40909,-10.852113
155.793,0.72476882,9.3868647,0.0,0,18.0,330.0,0.98291349,3.4290137,18.061144,357.35574,-10.86874
155.7952,0.75255215,9.39464,0.0,0,18.0,330.0,0.98416632,3.5669746,18.062029,357.3024,-10.884123
155.7974,0.76058733,9.392477,0.0,0,18.0,330.0,0.98392355,3.6088157,18.059586,357.24905,-10.899315
155.7996,0.74542654,9.3944998,0.0,0,18.0,330.0,0.98452014,3.5429327,18.058569,357.20389,-10.915492
155.8018,0.71392381,9.3893499,0.0,0,18.0,330.0,0.98302084,3.4173422,18.058973,357.17056,-10.931789
155.804,0.70415443,9.3922501,0.0,0,18.0,330.0,0.98425299,3.3505585,18.056988,357.13724,-10.947674
155.8062,0.68892694,9.3921719,0.0,0,18.0,330.0,0.98338032,3.2964239,18.057259,357.10391,-10.964314
155.8084,0.69408971,9.3930511,0.0,0,18.0,330.0,0.98448002,3.2922161,18.053692,357.07059,-10.98069
155.8106,0.72275394,9.3883781,0.0,0,18.0,330.0,0.98248804,3.4083948,18.055069,357.04877,-10.996664
155.8128,0.75057977,9.3889608,0.0,0,18.0,330.0,0.98421752,3.5333381,18.052505,357.02875,-11.013147
155.815,0.76139814,9.3930969,0.0,0,18.0,330.0,0.98313403,3.6225059,18.052532,357.00876,-11.03019
155.8172,0.74880213,9.3918142,0.0,0,18.0,330.0,0.9845975,3.5869169,18.055393,356.98874,-11.04684
155.8194,0.73565954,9.3929081,0.0,0,18.0,330.0,0.98306894,3.5015099,18.05357,356.95813,-11.061705
155.8216,0.71040982,9.3921156,0.0,0,18.0,330.0,0.98499155,3.3898497,18.052725,356.90479,-11.075225
155.8238,0.71217322,9.3977184,0.0,0,18.0,330.0,0.98355055,3.3804793,18.050243,356.85147,-11.091199
155.826,0.70096219,9.3887043,0.0,0,18.0,330.0,0.98437423,3.3219149,18.053856,356.79813,-11.106811
155.8282,0.71894497,9.392168,0.0,0,18.0,330.0,0.98272687,3.4013782,18.055906,356.74478,-11.123297
155.8304,0.75604719,9.3887005,0.0,0,18.0,330.0,0.98453468,3.5299618,18.05102,356.76874,-11.138528
155.8326,0.77621633,9.3990488,0.0,0,18.0,330.0,0.98367,3.6787159,18.04719,356.8154,-11.154132
155.8348,0.76644385,9.3904009,0.0,0,18.0,330.0,0.98475385,3.6685812,18.052528,356.86209,-11.171082
155.837,0.75562584,9.3966875,0.0,0,18.0,330.0,0.98366362,3.6147337,18.052101,356.90875,-11.18842
155.8392,0.72925466,9.3890972,0.0,0,18.0,330.0,0.98452038,3.472106,18.049816,356.93875,-11.203907
155.8414,0.6991002,9.3991785,0.0,0,18.0,330.0,0.98375255,3.3369429,18.049452,356.91211,-11.219588
155.8436,0.70552903,9.3877316,0.0,0,18.0,330.0,0.98413509,3.3561735,18.051081,356.88544,-11.23477
155.8458,0.71537304,9.3950033,0.0,0,18.0,330.0,0.98334455,3.403492,18.050583,356.85876,-11.251266
155.848,0.74426788,9.3867054,0.0,0,18.0,330.0,0.98407245,3.5120468,18.049719,356.83209,-11.267538
155.8502,0.76553357,9.3959684,0.0,0,18.0,330.0,0.98338425,3.6225865,18.051405,356.79178,-11.284266
155.8524,0.77472609,9.3862848,0.0,0,18.0,330.0,0.98372221,3.6901896,18.048876,356.74512,-11.300174
155.8546,0.75792295,9.3934202,0.0,0,18.0,330.0,0.98350513,3.6272798,18.046644,356.69843,-11.316254
155.8568,0.73723429,9.3877077,0.0,0,18.0,330.0,0.98372597,3.5216448,18.049192,356.65176,-11.332624
155.859,0.71620369,9.39993,0.0,0,18.0,330.0,0.98446411,3.4454832,18.047327,356.61237,-11.348722
155.8612,0.70069462,9.3890924,0.0,0,18.0,330.0,0.98374069,3.3638198,18.048738,356.61902,-11.36361
156.6617,0.6814602,9.3988056,0.0,0,18.0,4.1213597e-09,0.9851371,3.2420044,18.001831,329.33514,-11.48311
157.7617,0.65266991,9.4058933,0.0,0,18.0,4.116316e-24,0.98626798,3.0980825,17.99906,309.79782,-11.483047
158.8617,0.63679123,9.4110518,0.0,0,18.0,4.1112794e-39,0.9872418,3.0242298,17.999836,295.74945,-11.482986
159.9617,0.62136275,9.4158974,0.0,0,18.0,1.4012985e-45,0.98810834,2.9444251,18.000406,284.27548,-11.483499
161.0617,0.61077464,9.4205694,0.0,0,18.0,1.4012985e-45,0.98898607,2.8905721,17.999983,274.49924,-11.483339
162.1617,0.60777044,9.4249296,0.0,0,18.0,1.4012985e-45,0.98980641,2.8790216,17.99914,265.5188,-11.483086
163.2617,0.60763949,9.4296122,0.0,0,18.0,1.4012985e-45,0.9905324,2.8775597,17.999285,257.66919,-11.482676
164.3617,0.60970044,9.4335604,0.0,0,18.0,1.4012985e-45,0.99130493,2.8808742,17.998928,250.13229,-11.483418
165.4617,0.60378629,9.4377604,0.0,0,18.0,1.4012985e-45,0.99203318,2.8491194,17.99988,243.00578,-11.483365
166.5617,0.60077852,9.4412308,0.0,0,18.0,1.4012985e-45,0.99273223,2.835253,18.000061,235.96204,-11.483449
167.6617,0.59989023,9.4455547,0.0,0,18.0,1.4012985e-45,0.9935059,2.8293781,18.000273,229.2478,-11.484002
168.7617,0.60495174,9.4499207,0.0,0,18.0,1.4012985e-45,0.99417162,2.8503616,17.99968,223.03773,-11.483117
169.8617,0.60292333,9.4528646,0.0,0,18.0,1.4012985e-45,0.99473411,2.8351848,18.000031,216.77223,-11.483164
170.9617,0.59605908,9.4563141,0.0,0,18.0,1.4012985e-45,0.9953503,2.8037322,17.999006,210.81882,-11.483214
172.0617,0.59956563,9.4601946,0.0,0,18.0,1.4012985e-45,0.99614888,2.8240247,17.999809,205.20044,-11.483171
173.1617,0.60376829,9.4628983,0.0,0,18.0,1.4012985e-45,0.99663091,2.8334377,17.9993,199.771,-11.482885
174.2617,0.59720886,9.4660559,0.0,0,18.0,1.4012985e-45,0.99710459,2.8011882,17.999172,194.325,-11.482885
175.3617,0.59468442,9.4700651,0.0,0,18.0,1.4012985e-45,0.99786121,2.7893956,17.998959,189.19141,-11.483146
176.4617,0.60057378,9.4726543,0.0,0,18.0,1.4012985e-45,0.99828368,2.8229384,17.99827,184.28781,-11.483321
177.5617,0.59949923,9.4760714,0.0,0,18.0,1.4012985e-45,0.99900216,2.8147554,18.001425,179.49361,-11.483577
178.6617,0.60036433,9.4785461,0.0,0,18.0,1.4012985e-45,0.99947333,2.8098116,17.99929,174.8414,-11.483376
179.7617,0.59674555,9.4821177,0.0,0,18.0,1.4012985e-45,1.0000465,2.7933297,17.999783,170.39,-11.484036
180.8617,0.59636891,9.484479,0.0,0,18.0,1.4012985e-45,1.0005075,2.7967474,18.000082,166.05771,-11.483943
181.9617,0.59844893,9.4878378,0.0,0,18.0,1.4012985e-45,1.001027,2.7976537,18.000402,161.82671,-11.483525
183.0617,0.59798771,9.4903698,0.0,0,18.0,1.4012985e-45,1.0015887,2.7953627,18.000721,157.76213,-11.483377
184.1617,0.593481,9.4927702,0.0,0,18.0,1.4012985e-45,1.0020339,2.7735078,17.998772,153.76384,-11.483089
185.2617,0.59559286,9.4954014,0.0,0,18.0,1.4012985e-45,1.0024651,2.7839587,17.99943,149.99178,-11.483414
186.3617,0.59945697,9.4979353,0.0,0,18.0,1.4012985e-45,1.0029184,2.8001292,17.999638,146.40007,-11.483345
187.4617,0.59433889,9.4999819,0.0,0,18.0,1.4012985e-45,1.0032333,2.7730558,17.999908,142.74553,-11.483398
188.5617,0.59030259,9.5026016,0.0,0,18.0,1.4012985e-45,1.0038041,2.7505116,17.99958,139.02286,-11.483178
189.6617,0.59066355,9.504632,0.0,0,18.0,1.4012985e-45,1.0041949,2.7585168,17.999754,135.73135,-11.48302
190.7617,0.59300417,9.5069618,0.0,0,18.0,1.4012985e-45,1.0045565,2.7686832,18.000631,132.35277,-11.482824
191.8617,0.60062701,9.5097761,0.0,0,18.0,1.4012985e-45,1.0051103,2.7984734,17.999086,129.18219,-11.482985
192.9617,0.59395039,9.5116434,0.0,0,18.0,1.4012985e-45,1.0053513,2.7631762,17.999939,126.04841,-11.483318
194.0617,0.59170675,9.5136061,0.0,0,18.0,1.4012985e-45,1.0057919,2.7564068,17.998774,122.99511,-11.483162
195.1617,0.59438944,9.5154781,0.0,0,18.0,1.4012985e-45,1.0061677,2.773386,17.998121,120.10699,-11.483123
196.2617,0.5961048,9.5178232,0.0,0,18.0,1.4012985e-45,1.0065396,2.7794933,18.000221,117.32392,-11.483235
197.3617,0.59272236,9.5191154,0.0,0,18.0,1.4012985e-45,1.006801,2.7552314,18.000298,114.53082,-11.483498
198.4617,0.58648622,9.5220184,0.0,0,18.0,1.4012985e-45,1.0072378,2.7297189,18.000282,111.85429,-11.482934
199.5617,0.59111911,9.5235968,0.0,0,18.0,1.4012985e-45,1.007607,2.7516024,18.000252,109.27901,-11.48318
200.6617,0.59594923,9.5249281,0.0,0,18.0,1.4012985e-45,1.0079007,2.7673662,17.999319,106.75396,-11.48346
201.7617,0.59149355,9.5269451,0.0,0,18.0,1.4012985e-45,1.0082297,2.739146,17.999287,104.26397,-11.483346
202.8617,0.58865869,9.5289669,0.0,0,18.0,1.4012985e-45,1.0086228,2.736625,17.998835,101.88254,-11.483314
203.9617,0.59052002,9.5305691,0.0,0,18.0,1.4012985e-45,1.0087929,2.7397943,17.999617,99.732574,-11.483612
205.0617,0.59419626,9.5320959,0.0,0,18.0,1.4012985e-45,1.0091956,2.7626598,18.000568,97.513786,-11.483253
206.1617,0.59471422,9.5337334,0.0,0,18.0,1.4012985e-45,1.009459,2.7594743,17.999386,95.371773,-11.483477
207.2617,0.58737057,9.5348597,0.0,0,18.0,1.4012985e-45,1.0096916,2.723793,17.998924,93.242332,-11.48352
208.3617,0.58791012,9.5364552,0.0,0,18.0,1.4012985e-45,1.0099946,2.7317686,17.999983,91.257866,-11.48371
209.4617,0.59513241,9.5383539,0.0,0,18.0,1.4012985e-45,1.0102257,2.7598093,17.999615,89.229813,-11.483485
210.5617,0.59016806,9.5394287,0.0,0,18.0,1.4012985e-45,1.0104846,2.7298014,17.998932,87.415764,-11.483624
211.6617,0.58763963,9.5407753,0.0,0,18.0,1.4012985e-45,1.0107586,2.7240224,18.000715,85.61628,-11.483515
212.7617,0.59383947,9.5423183,0.0,0,18.0,1.4012985e-45,1.0110486,2.7523162,17.999596,83.798134,-11.483579
213.8617,0.58826464,9.5433102,0.0,0,18.0,1.4012985e-45,1.0112221,2.7255118,18.000065,82.066742,-11.483694
214.9617,0.59270465,9.5449219,0.0,0,18.0,1.4012985e-45,1.011427,2.7399399,18.000193,80.36705,-11.483405
215.8617,0.59056515,9.5456705,0.0,0,18.0,1.4012985e-45,1.0115901,2.7330017,17.999592,79.045265,-11.483418