File: examples/hot axisymmetric compression example/data/02 screened data/testID_0139.csv
Time(sec),Force(kN),Jaw(mm),PowAngle(deg),Power(W),Pram,PTemp,Strain,Stress(MPa),Stroke(mm),TC1(C),wedge(mm)
0.0,1.0511171,0.3390114,0.0,0,11.076097,0.00076457317,0.022843653,13.060088,11.076841,22.931246,-9.1101074
1.2,0.98269302,-0.0027062141,0.0,0,11.076097,3.5159154,-0.00018088991,12.506738,11.076376,22.924009,-9.4796371
2.4,0.94959247,-0.0027206044,0.0,0,11.076097,7.1159153,-0.00019965578,12.095202,11.076557,22.977961,-9.4769287
3.6,0.93768561,-0.0029571438,0.0,0,11.076097,10.715914,-0.00019245032,11.926119,11.077022,22.89924,-9.4757586
4.8,0.91118896,-0.0030878363,0.0,0,11.076097,14.315914,-0.00022294199,11.597435,11.075925,22.923037,-9.4736538
6.0,0.90001994,-0.0031533847,0.0,0,11.076097,17.915913,-0.00020516198,11.461637,11.075596,22.899422,-9.4713802
7.2,0.88512605,-0.0029066915,0.0,0,11.076097,21.515913,-0.00021279835,11.267782,11.075995,22.929615,-9.4694977
8.4,0.8744837,-0.0027963491,13.516448,0,11.076097,25.115911,-0.00018132391,11.153053,11.076102,22.923227,-9.4673958
9.6,0.87614805,-0.0027685026,33.715569,0,11.076097,28.715912,-0.00019953102,11.149848,11.076071,23.198978,-9.4652872
10.8,0.89112073,-0.005529555,44.539761,0,11.076097,32.31591,-0.00036778292,11.340329,11.076876,24.978115,-9.4640608
12.0,0.90891409,-0.0098227635,50.621571,0,11.076097,35.915913,-0.00067474309,11.588672,11.075979,28.863487,-9.4623575
13.2,0.93103021,-0.014971606,53.637466,0,11.076097,39.515911,-0.00099537708,11.870078,11.076689,34.191406,-9.460681
14.4,0.94467264,-0.020090641,54.305416,0,11.076097,43.11591,-0.0013540373,12.060054,11.076427,40.478848,-9.4582996
15.6,0.9654541,-0.025174865,53.067295,0,11.076097,46.715908,-0.0016699801,12.312995,11.07677,46.997952,-9.4565697
16.8,0.97011334,-0.02896418,49.886574,0,11.076097,50.31591,-0.0019411979,12.372633,11.075831,53.21928,-9.4546614
18.0,0.96764368,-0.032406591,45.253525,0,11.076097,53.915909,-0.0021504813,12.348669,11.075655,58.483418,-9.4525948
19.2,0.95360434,-0.033613916,39.593685,0,11.076097,57.515907,-0.0022481631,12.158453,11.07605,62.435886,-9.4506769
20.4,0.9390884,-0.034410633,35.496941,0,11.076097,61.115902,-0.002284233,11.980573,11.075428,64.893196,-9.4491844
21.6,0.92944509,-0.034583028,34.650375,0,11.076097,64.715927,-0.0023255527,11.872805,11.076149,66.325798,-9.447381
22.8,0.91833329,-0.035877623,38.52393,0,11.076097,68.315926,-0.0023814172,11.718721,11.076222,67.138809,-9.445179
24.0,0.92398113,-0.037609186,44.139206,0,11.076097,71.915909,-0.0025237326,11.795839,11.076187,68.357391,-9.4432697
25.2,0.9310295,-0.040726077,49.267353,0,11.076097,75.51593,-0.0027096379,11.890375,11.075964,70.610535,-9.4410553
26.4,0.95056784,-0.044864748,52.951797,0,11.076097,79.115913,-0.0029962086,12.136575,11.075653,74.175224,-9.439106
27.6,0.96529162,-0.049799163,54.732334,0,11.076097,82.715927,-0.0033082876,12.336693,11.07571,79.021629,-9.4373322
28.8,0.9842639,-0.054560486,55.239254,0,11.076097,86.31591,-0.0036459409,12.5828,11.077055,84.610413,-9.4353695
30.0,0.99106956,-0.059092063,54.306141,0,11.076097,89.915924,-0.0039216378,12.653322,11.075895,90.215622,-9.434207
31.2,0.99385154,-0.06257844,52.290882,0,11.076097,93.515923,-0.0041826814,12.706663,11.075786,95.676796,-9.4321918
32.4,0.99236524,-0.065982819,49.65123,0,11.076097,97.115921,-0.0043830075,12.677377,11.07613,100.21444,-9.4297762
33.6,0.98312259,-0.068061538,47.056618,0,11.076097,100.71591,-0.0045450693,12.576007,11.076739,103.92348,-9.4279356
34.8,0.97674316,-0.06983088,45.121471,0,11.076097,104.31591,-0.0046401354,12.486362,11.076602,106.74754,-9.4258604
36.0,0.97100538,-0.07105007,45.12085,0,11.076097,107.9159,-0.0047510648,12.416135,11.076233,108.7147,-9.423728
37.2,0.96279603,-0.073056415,46.998676,0,11.076097,111.5159,-0.0048514507,12.312661,11.077219,110.60968,-9.4216099
38.4,0.98196536,-0.074912935,49.608719,0,11.076097,115.11591,-0.0049961931,12.560898,11.076301,112.72881,-9.420146
39.6,0.99338597,-0.078307256,52.211319,0,11.076097,118.7159,-0.0051953057,12.715378,11.075716,115.54265,-9.418395
40.8,1.005738,-0.081402101,54.263355,0,11.076097,122.3159,-0.0054252362,12.870819,11.075522,119.18466,-9.4166965
42.0,1.004729,-0.086002484,55.535458,0,11.076097,125.9159,-0.0057119643,12.853077,11.076944,123.39381,-9.4144287
43.2,1.0100853,-0.089962952,56.123806,0,11.076097,129.51602,-0.0060004489,12.904708,11.07546,128.02693,-9.4126244
44.4,1.0096291,-0.094338894,55.732697,0,11.076097,133.11591,-0.0062716831,12.930344,11.075961,132.88329,-9.4105806
45.6,1.0120579,-0.097843245,54.93166,0,11.076097,136.7159,-0.0065107704,12.961644,11.0761,137.53174,-9.4085865
46.8,1.0071528,-0.10114766,53.975834,0,11.076097,140.3159,-0.0067116078,12.905609,11.076903,141.6438,-9.4065256
48.0,1.0024567,-0.1038034,52.766186,0,11.076097,143.91591,-0.006911132,12.847773,11.075988,145.41397,-9.4046545
49.2,1.003781,-0.10670009,52.207489,0,11.076097,147.51591,-0.0070788739,12.87416,11.076089,148.74431,-9.4023628
50.4,0.999089,-0.10906495,51.944061,0,11.076097,151.11589,-0.0072630625,12.82247,11.077193,151.57568,-9.4013577
51.6,1.006454,-0.11146715,52.635452,0,11.076097,154.71593,-0.0073948726,12.921431,11.075527,154.33145,-9.39923
52.8,0.99087155,-0.11405506,53.656799,0,11.076097,158.3159,-0.0075875223,12.713763,11.077023,157.11792,-9.3973885
54.0,1.0115602,-0.11711853,54.931499,0,11.076097,161.91592,-0.0077740215,12.991712,11.076433,160.12244,-9.3950462
55.2,1.0107489,-0.12058643,56.195389,0,11.076097,165.51591,-0.0080244262,12.98058,11.076422,163.53206,-9.393465
56.4,1.0080295,-0.12453838,57.075016,0,11.076097,169.11592,-0.0082491739,12.948664,11.076231,167.32834,-9.3909855
57.6,1.0136142,-0.12810917,57.535397,0,11.076097,172.71591,-0.0085229995,13.011223,11.076365,171.54376,-9.3894997
58.8,1.0076222,-0.13202398,57.535397,0,11.076097,176.31592,-0.0087531805,12.934696,11.075806,175.90065,-9.3872128
60.0,1.0124278,-0.13545072,57.260746,0,11.076097,179.91591,-0.0090108374,13.003749,11.076736,180.17416,-9.3858643
61.2,1.0145307,-0.13907062,56.828495,0,11.076097,183.51593,-0.0092131225,13.051748,11.076012,184.00941,-9.3839235
62.4,1.0155152,-0.14211699,56.425785,0,11.076097,187.11592,-0.0094475383,13.045052,11.076161,187.717,-9.382226
63.6,1.0011183,-0.14550641,56.425785,0,11.076097,190.71591,-0.009635983,12.894072,11.076687,191.02545,-9.3802462
64.8,1.006416,-0.14825167,56.425785,0,11.076097,194.3159,-0.0098507265,12.934086,11.076536,194.38936,-9.3779087
66.0,1.0117908,-0.15158516,56.71133,0,11.076097,197.91592,-0.010038055,13.010741,11.07702,197.72464,-9.3765898
67.2,1.0139383,-0.15463975,56.982944,0,11.076097,201.5159,-0.010265797,13.051828,11.076661,201.14192,-9.3744774
68.4,1.0157487,-0.15776546,57.260735,0,11.076097,205.11591,-0.010444477,13.076208,11.076367,204.60034,-9.372508
69.6,1.0094577,-0.1606645,57.567234,0,11.076097,208.71591,-0.010648091,12.981991,11.076035,208.04756,-9.3702526
70.8,1.0120518,-0.16431479,58.073727,0,11.076097,212.31593,-0.010879852,13.035415,11.076399,211.60071,-9.3687057
72.0,1.0180069,-0.16755818,58.337383,0,11.076097,215.91589,-0.011110147,13.097468,11.076203,215.28372,-9.3662081
73.2,1.0112989,-0.17164372,58.59008,0,11.076097,219.5159,-0.011361935,13.036352,11.077161,218.95796,-9.3648138
74.4,1.0197998,-0.17506105,58.853752,0,11.076097,223.11589,-0.01159355,13.132561,11.076472,222.68378,-9.3628159
75.6,1.0185243,-0.1783929,58.85833,0,11.076097,226.7159,-0.011811662,13.125712,11.075635,226.35005,-9.3609009
76.8,1.0182167,-0.18154372,59.006695,0,11.076097,230.3159,-0.01200766,13.130472,11.075853,230.08032,-9.3589344
78.0,1.0161706,-0.18514049,59.106407,0,11.076097,233.91589,-0.012260749,13.097729,11.076874,233.6691,-9.3571653
79.2,1.0173657,-0.18841195,59.106438,0,11.076097,237.5159,-0.012471429,13.11615,11.075062,237.29231,-9.3550186
80.4,1.0155343,-0.19199722,59.348137,0,11.076097,241.11589,-0.012712248,13.101019,11.076713,240.74556,-9.353447
81.6,1.0153037,-0.19491477,59.600826,0,11.076097,244.7159,-0.01290167,13.101521,11.075466,244.35397,-9.3509407
82.8,1.0103322,-0.19861503,59.842525,0,11.076097,248.3159,-0.013148169,13.036212,11.076328,247.78409,-9.349247
84.0,1.017354,-0.20202732,60.084225,0,11.076097,251.91591,-0.013363983,13.146101,11.076967,251.29927,-9.3472166
85.2,1.0174434,-0.20543978,60.447788,0,11.076097,255.5159,-0.013606015,13.129712,11.076739,254.89008,-9.3453665
86.4,1.0130329,-0.20931375,60.786507,0,11.076097,259.11618,-0.01384874,13.070158,11.075996,258.48651,-9.343668
87.6,1.0216064,-0.21261793,60.953655,0,11.076097,262.71588,-0.014087435,13.181655,11.075773,262.12469,-9.3417177
88.8,1.024399,-0.21653435,61.150883,0,11.076097,266.31589,-0.014321489,13.231508,11.076934,265.82587,-9.3395929
90.0,1.0316203,-0.22078139,61.237789,0,11.076097,269.91589,-0.014614704,13.338564,11.07643,269.62686,-9.3377724
91.2,1.0360219,-0.22503209,61.237789,0,11.076097,273.5159,-0.014885205,13.380148,11.076402,273.37534,-9.3359556
92.4,1.0274322,-0.22863057,61.237789,0,11.076097,277.11591,-0.015133009,13.27526,11.075786,277.15396,-9.333931
93.6,1.0252554,-0.23232703,61.030788,0,11.076097,280.71591,-0.015364789,13.259331,11.076296,280.83752,-9.3319092
94.8,1.0350929,-0.23554778,61.018078,0,11.076097,284.31592,-0.015588394,13.383191,11.075965,284.52704,-9.3299837
96.0,1.030364,-0.23853672,61.000858,0,11.076097,287.91592,-0.015772576,13.337008,11.075964,288.04465,-9.327919
97.2,1.0331823,-0.24083689,60.978264,0,11.076097,291.5159,-0.015936406,13.354386,11.076431,291.51108,-9.3258905
98.4,1.0278106,-0.24352053,61.237789,0,11.076097,295.11594,-0.016104637,13.288205,11.076688,294.78754,-9.3243427
99.6,1.0107151,-0.24714521,61.468498,0,11.076097,298.71591,-0.016358837,13.067265,11.075938,298.12494,-9.3221941
100.8,1.0241268,-0.25090972,61.893467,0,11.076097,302.31595,-0.016584504,13.269162,11.076042,301.58978,-9.3202038
102.0,1.0219598,-0.25478047,62.116692,0,11.076097,305.91592,-0.016856315,13.227013,11.075993,305.26605,-9.3187342
103.2,1.0216006,-0.25843841,62.336418,0,11.076097,309.5159,-0.017073294,13.22287,11.076524,308.89551,-9.3166904
104.4,1.030903,-0.26190743,62.571861,0,11.076097,313.11588,-0.017320905,13.360117,11.076802,312.48618,-9.3144817
105.6,1.0317625,-0.26569703,62.960793,0,11.076097,316.71591,-0.017546659,13.370159,11.075259,316.07858,-9.3128891
106.8,1.032338,-0.2702277,63.163021,0,11.076097,320.31589,-0.017876862,13.396535,11.076716,319.75809,-9.3110304
108.0,1.0376995,-0.27598965,63.171383,0,11.076097,323.91595,-0.018222468,13.457655,11.075434,323.43805,-9.3087072
109.2,1.0243295,-0.27823302,63.173054,0,11.076097,327.51587,-0.018387781,13.305243,11.076593,327.42126,-9.3069239
110.4,1.0241657,-0.28152135,63.171394,0,11.076097,331.11588,-0.018580448,13.308713,11.076188,331.14304,-9.304884
111.6,1.0239719,-0.28496325,63.171394,0,11.076097,334.71588,-0.018831709,13.276544,11.075958,334.84787,-9.3026981
112.8,1.025539,-0.28842342,63.171383,0,11.076097,338.31589,-0.019022658,13.293654,11.076186,338.31689,-9.3008614
114.0,1.0292498,-0.29122818,63.35112,0,11.076097,341.91589,-0.019236282,13.362971,11.076007,341.63898,-9.2989197
115.2,1.0280689,-0.29438534,63.577805,0,11.076097,345.5159,-0.019413447,13.353232,11.076246,345.09634,-9.2971821
116.4,1.0286328,-0.29749617,63.774673,0,11.076097,349.11588,-0.019648731,13.365918,11.074667,348.60202,-9.2950783
117.6,1.0344856,-0.3026005,63.934151,0,11.076097,352.71591,-0.01995955,13.441386,11.076686,352.23682,-9.2932568
118.8,1.0325149,-0.30818352,63.973385,0,11.076097,356.31589,-0.020348061,13.411288,11.076731,355.9538,-9.2913513
120.0,1.0393815,-0.30982688,64.014381,0,11.076097,359.9151,-0.020421758,13.503334,11.075947,359.71921,-9.2897482
121.2,1.0267774,-0.31249252,62.125202,0,11.076097,359.99924,-0.020636877,13.344169,11.076039,363.13403,-9.2897635
122.4,1.0230896,-0.31366417,59.223286,0,11.076097,359.99924,-0.020675475,13.319472,11.076777,365.31891,-9.2894258
123.6,1.0124836,-0.313647,55.690815,0,11.076097,359.99924,-0.020694295,13.161563,11.076084,366.22925,-9.2895851
124.8,0.9905051,-0.31287214,52.267899,0,11.076097,359.99924,-0.020617953,12.869155,11.076077,365.82584,-9.2891788
126.0,0.97694689,-0.31118533,49.988441,0,11.076097,359.99924,-0.020528344,12.701342,11.076415,364.19467,-9.2889843
127.2,0.96521002,-0.30973092,49.22974,0,11.076097,359.99924,-0.020423988,12.54972,11.076919,362.0256,-9.2892265
128.4,0.9466756,-0.30925825,50.436699,0,11.076097,359.99924,-0.020399451,12.289027,11.076188,359.74576,-9.2888842
129.6,0.94451034,-0.30797991,52.601818,0,11.076097,359.99924,-0.020310197,12.29508,11.076435,358.05807,-9.2890272
130.8,0.94566059,-0.30773714,54.72541,0,11.076097,359.99924,-0.020298846,12.278374,11.075008,357.11078,-9.2888193
132.0,0.9665482,-0.30809355,56.41695,0,11.076097,359.99924,-0.020325696,12.564992,11.076504,357.02185,-9.2885704
133.2,0.98291624,-0.30875498,57.530403,0,11.076097,359.99924,-0.020357959,12.776112,11.076158,357.63358,-9.2890339
134.4,0.99819666,-0.31089896,57.868176,0,11.076097,359.99924,-0.020520588,12.975521,11.077003,358.58862,-9.2890539
135.6,1.0081325,-0.31382349,57.690647,0,11.076097,359.99924,-0.020689402,13.11244,11.076453,359.74451,-9.2888975
136.8,1.0091729,-0.31357369,57.000767,0,11.076097,359.99924,-0.020685995,13.134331,11.076707,360.64597,-9.2892323
138.0,1.0107048,-0.31437486,56.134571,0,11.076097,359.99924,-0.020730499,13.134632,11.075803,361.34384,-9.2889519
139.2,1.0160203,-0.31414935,55.239342,0,11.076097,359.99924,-0.020731123,13.220018,11.075185,361.60788,-9.2895527
140.4,1.0142407,-0.31455705,54.30946,0,11.076097,359.99924,-0.020748695,13.195336,11.075864,361.43137,-9.2894945
141.6,1.0054467,-0.31650257,53.975834,0,11.076097,359.99924,-0.020890981,13.070028,11.076299,361.08643,-9.2896385
142.8,0.98829675,-0.31521961,53.825233,0,11.076097,359.99924,-0.020792387,12.869896,11.076506,360.45447,-9.2898922
144.0,0.99265993,-0.31453118,53.975826,0,11.076097,359.99924,-0.020759834,12.910144,11.075605,360.05356,-9.2895622
145.2,0.98995197,-0.31451389,54.305416,0,11.076097,359.99924,-0.020746347,12.869411,11.075727,359.57376,-9.2893
146.4,1.002298,-0.31453863,54.654804,0,11.076097,359.99924,-0.020761022,13.042455,11.076018,359.40915,-9.289257
147.6,1.0107021,-0.31695619,55.124825,0,11.076097,359.99924,-0.02090548,13.137027,11.076822,359.33441,-9.2888079
148.8,0.99648172,-0.31653559,55.240044,0,11.076097,359.99924,-0.020888984,12.974024,11.07521,359.54187,-9.2886581
150.0,1.0134162,-0.31662112,55.406246,0,11.076097,359.99924,-0.020885965,13.186223,11.076894,359.74777,-9.2885761
151.2,1.0153812,-0.31735057,55.255875,0,11.076097,359.99924,-0.020950064,13.206351,11.076117,359.92383,-9.2886934
152.4,1.029134,-0.31872657,55.239262,0,11.076097,359.99924,-0.021031048,13.387275,11.076767,360.13351,-9.2889357
153.6,1.0210854,-0.3187215,54.932865,0,11.076097,359.99924,-0.02104732,13.256134,11.076045,360.2872,-9.2882671
154.8,1.0140231,-0.31941766,54.783855,0,11.076097,359.99924,-0.021072581,13.187749,11.076186,360.34137,-9.288681
156.0,1.0233901,-0.31896746,54.624027,0,11.076097,359.99924,-0.02105548,13.315178,11.076116,360.31723,-9.2887707
157.2,1.0179672,-0.31940219,54.530426,0,11.076097,359.99924,-0.021066209,13.242972,11.076415,360.30624,-9.2888155
158.4,1.0296079,-0.32085752,54.341862,0,11.076097,359.99924,-0.021178326,13.39138,11.076163,360.14893,-9.2892351
159.6,1.0191449,-0.32044736,54.603481,0,11.076097,359.99924,-0.021126337,13.250214,11.075701,359.97162,-9.2890234
160.8,1.0265445,-0.32059327,54.624023,0,11.076097,359.99924,-0.021168405,13.349346,11.076228,359.92999,-9.2893934
162.0,1.0257311,-0.32058597,54.624023,0,11.076097,359.99924,-0.02112559,13.340652,11.07682,359.90701,-9.2892771
163.2,1.0260959,-0.32291934,54.624023,0,11.076097,359.99924,-0.021305526,13.351483,11.076015,359.89731,-9.2896013
164.4,1.0157251,-0.32205489,54.657669,0,11.076097,359.99924,-0.021221712,13.198219,11.07554,359.94116,-9.2892704
165.2805,1.0069159,0.012761286,54.624023,0,11.076099,2.5620368,0.00097111851,12.780856,11.074476,359.92679,-9.289197
165.2829,1.0026737,0.01110704,54.624023,0,11.076099,1.1075678000000001e-16,0.00059226051,12.819457,11.075536,359.91229,-9.2891483
165.2853,1.054389,0.016188642,54.624023,0,11.076099,4.7880132999999995e-33,0.00094384456,13.387222,11.077795,359.89777,-9.2894869
165.2877,1.0210598,0.015243334,53.532654,0,11.076099,0.0,0.0010485016,12.99064,11.075537,359.88507,-9.2902441
165.2901,0.99885339,0.012340459,40.449055,0,11.076099,0.0,0.0010713954,12.687317,11.07701,359.8923,-9.2902517
165.2925,1.0586785,0.014060079,27.365458,0,11.076099,0.0,0.0010606895,13.574031,11.077808,359.89957,-9.2899742
165.2949,1.0184511,0.01925463,14.281857,0,11.076099,0.0,0.0011125928,12.877452,11.076288,359.90683,-9.2906237
165.2973,1.0329254,0.020420169,1.1982584,0,11.076099,0.0,0.0010787244,13.100679,11.075406,359.91406,-9.2897987
165.2997,1.0111247,0.017669959,0.0,0,11.076099,0.0,0.0012137108,12.974064,11.073555,359.9411,-9.2900944
165.3021,0.99394464,0.014729065,0.0,0,11.076099,0.0,0.0012841385,12.662588,11.076799,359.97015,-9.2896585
165.3045,1.0105124,0.012958161,0.0,0,11.076099,0.0,0.00096912769,12.850389,11.075167,359.99921,-9.2902708
165.3069,1.0235466,0.013678433,0.0,0,11.076099,0.0,0.00074767519,13.001032,11.076811,360.02823,-9.2904768
165.3093,1.0029528,0.015377921,0.0,0,11.076099,0.0,0.00088104297,12.713614,11.077662,360.02002,-9.28901
165.3117,0.98837781,0.015413126,0.0,0,11.076099,0.0,0.0010900707,12.609957,11.078396,359.99823,-9.2889509
165.3141,1.0021023,0.013790428,0.0,0,11.076099,0.0,0.0011578244,12.716856,11.077175,359.97647,-9.2891073
165.3165,1.0098238,0.013910927,0.0,0,11.076099,0.0,0.0010246116,12.83435,11.077827,359.95468,-9.2894173
165.3189,1.0102338,0.017259395,0.0,0,11.076099,0.0,0.00095824531,12.814131,11.078299,359.93289,-9.2900763
165.3213,0.99856609,0.018845474,0.0,0,11.076099,0.0,0.00096187735,12.665732,11.076593,359.91113,-9.2899303
165.3237,0.98961699,0.017466344,0.0,0,11.076099,0.0,0.0012455563,12.566769,11.076214,359.88934,-9.2885046
165.3261,1.0001737,0.014353214,0.0,0,11.076099,0.0,0.0011834112,12.715619,11.078149,359.86755,-9.2880507
165.3285,1.0119562,0.012433693,0.0,0,11.076099,0.0,0.00091387687,12.905657,11.076502,359.86526,-9.2872906
165.3309,0.98941422,0.014973999,0.0,0,10.976439,0.0,0.00079491589,12.648427,11.077366,359.89429,-9.2896214
165.3333,0.99225897,0.016656706,0.0,0,10.615465,0.0,0.00095384044,12.60529,11.076752,359.92334,-9.2892876
165.3357,0.98806536,0.014109571,0.0,0,10.254493,0.0,0.0010158898,12.631801,11.0574,359.95236,-9.2891903
165.3381,1.0342621,0.012075773,0.0,0,9.8935184,0.0,0.0010310718,13.06623,10.92666,360.18854,-9.2892036
165.3405,0.98706394,0.013096656,0.0,0,9.5325451,0.0,0.00091353664,12.577323,10.639745,361.2114,-9.2893953
165.3429,0.99681813,0.017070986,0.0,0,9.1799984,0.0,0.00093099079,12.797763,10.24735,362.23428,-9.2894049
165.3453,6.7792959,0.27897361,0.0,0,8.8288298,0.0,0.017488703,84.657021,9.8028316,363.25714,-9.2839947
165.3477,8.2013712,0.70056087,0.0,0,8.4909992,0.0,0.04763839,99.129059,9.3145542,364.26282,-9.2834988
165.3501,8.7481346,1.1216658,0.0,0,8.1570148,0.0,0.077657342,103.03306,8.8665361,364.77094,-9.2838411
165.3525,8.8447132,1.5205263,0.0,0,7.8342705,0.0,0.10652275,100.87588,8.4878016,365.27905,-9.283843
165.3549,9.236762,1.8407034,0.0,0,7.51651,0.0,0.13025147,103.19847,8.1506901,365.7872,-9.2836027
165.3573,9.4719496,2.1479578,0.0,0,7.2082276,0.0,0.15391921,103.32417,7.8294449,366.29532,-9.2835398
165.3597,9.761548,2.4474723,0.0,0,6.9060192,0.0,0.17784378,104.13178,7.5234857,364.33588,-9.2822647
165.3621,9.9269533,2.7356856,0.0,0,6.6115384,0.0,0.20132951,103.2907,7.2301779,361.96945,-9.2825098
165.3645,10.261048,3.0228174,0.0,0,6.324019,0.0,0.22473121,104.30854,6.9379644,359.60303,-9.282814
165.3669,10.509563,3.3120468,0.0,0,6.0427265,0.0,0.24866982,104.291,6.6488538,357.2366,-9.2832232
165.3693,10.789203,3.5990839,0.0,0,5.7692699,0.0,0.27349806,104.48292,6.3616028,355.00815,-9.2831736
165.3717,11.042579,3.8791046,0.0,0,5.5005927,0.0,0.2990298,104.24685,6.0764904,352.84363,-9.2852068
165.3741,11.318838,4.1568313,0.0,0,5.2404327,0.0,0.32458159,104.18301,5.7900524,350.67908,-9.2843723
165.3765,11.611034,4.4372211,0.0,0,4.9837847,0.0,0.35036817,104.09796,5.5072236,348.51456,-9.2850704
165.3789,11.928674,4.7149534,0.0,0,4.7363443,0.0,0.37645867,104.14115,5.2377677,346.73636,-9.283947
165.3813,12.199394,4.9840746,0.0,0,4.4912271,0.0,0.40315181,103.78094,4.9662104,345.33167,-9.2830038
165.3837,12.48038,5.2453418,0.0,0,4.2558346,0.0,0.43007609,103.34848,4.7013683,343.927,-9.2826986
165.3861,12.80549,5.4985785,0.0,0,4.021708,0.0,0.45664817,103.21053,4.4446602,342.52234,-9.281724
165.3885,13.156265,5.7446094,0.0,0,3.7978315,0.0,0.48243305,103.35875,4.1928811,341.15891,-9.2830753
165.3909,13.476682,5.9856653,0.0,0,3.5743327,0.0,0.50812143,103.22092,3.9597654,339.87796,-9.2831783
165.3933,13.809322,6.215209,0.0,0,3.3612678,0.0,0.53409809,103.04487,3.7337537,338.59705,-9.282361
165.3957,14.163875,6.4283996,0.0,0,3.1482918,0.0,0.55959964,103.00195,3.5146928,337.3161,-9.2835121
165.3981,14.572481,6.640511,0.0,0,2.9450903,0.0,0.58485651,103.32961,3.3014617,336.24268,-9.2824345
165.4005,15.031834,6.8553219,0.0,0,2.7424822,0.0,0.61016911,103.92708,3.0901191,336.27179,-9.2814789
165.4029,15.476049,7.0666256,0.0,0,2.548372,0.0,0.63603109,104.34076,2.8791173,336.3009,-9.2822647
165.4053,15.920197,7.2728672,0.0,0,2.3556519,0.0,0.66249794,104.44629,2.6713896,336.33002,-9.2809782
165.4077,16.437534,7.4724236,0.0,0,2.1702335,0.0,0.68944895,104.99184,2.4726224,336.35913,-9.2811556
165.4101,16.980677,7.6613708,0.0,0,1.9869215,0.0,0.71526879,105.71687,2.2771306,335.29016,-9.2805967
165.4125,17.548361,7.8533835,0.0,0,1.8097944,0.0,0.74090546,106.46611,2.0860639,334.20267,-9.2791348
165.4149,18.111834,8.0418978,0.0,0,1.6354104,0.0,0.76678991,107.09207,1.9060591,333.11514,-9.279974
165.4173,18.725248,8.2211008,0.0,0,1.466204,0.0,0.79310673,107.81296,1.724668,332.02765,-9.2793684
165.4197,19.413481,8.3928843,0.0,0,1.3003161,0.0,0.82011044,108.80267,1.5504496,330.97601,-9.2788858
165.4221,20.153505,8.5585833,0.0,0,1.1386957,0.0,0.8458823,110.02319,1.3771396,329.93283,-9.2787046
165.4245,20.916698,8.7266788,0.0,0,0.98091978,0.0,0.87139434,111.36751,1.2105994,328.88968,-9.2786379
165.4269,21.710665,8.8984442,0.0,0,0.82656538,0.0,0.89812523,112.48359,1.0447857,327.84653,-9.278389
165.4293,22.57822,9.0577488,0.0,0,0.67651743,0.0,0.92503822,113.9183,0.88233292,326.73752,-9.2783909
165.4317,23.506536,9.2065592,0.0,0,0.52907455,0.0,0.95156479,115.43363,0.72128016,325.59039,-9.2774296
165.4341,24.448692,9.3541088,0.0,0,0.38627455,0.0,0.97775757,117.04205,0.56883657,324.44327,-9.2771616
165.4365,22.728188,9.4288845,0.0,0,0.24540935,0.0,0.9903264,107.49721,0.4634352,323.29614,-9.2791901
165.4389,20.981745,9.4478235,0.0,0,0.10961735,0.0,0.99251258,99.11895,0.42269263,323.11304,-9.2796116
165.4413,20.147362,9.4535446,0.0,0,-0.025526909,0.0,0.99417019,94.930717,0.39652529,324.06888,-9.2812595
165.4437,19.715673,9.4561911,0.0,0,-0.15795895,0.0,0.99613523,92.69767,0.36613363,325.02469,-9.281889
165.4461,19.896381,9.4560099,0.0,0,-0.29039097,0.0,0.99660552,93.492516,0.3141281,325.98053,-9.2807713
165.4485,20.094381,9.466012,0.0,0,-0.42282295,0.0,0.99695659,94.371162,0.24810566,327.67627,-9.2818823
165.4509,20.115824,9.475358,0.0,0,-0.55525494,0.0,0.99780244,94.445129,0.18154193,331.24277,-9.2822742
165.4533,20.0275,9.4798298,0.0,0,-0.68768692,0.0,0.99925172,93.923256,0.12623876,334.80927,-9.282506
165.4557,19.85939,9.4840107,0.0,0,-0.8201189,0.0,1.0011408,92.891991,0.071806245,338.37576,-9.2824755
165.4581,19.595182,9.4869909,0.0,0,-0.95255095,0.0,1.0017892,91.634575,0.032498151,341.75598,-9.2828007
165.4605,19.219023,9.4913702,0.0,0,-1.084983,0.0,1.0010744,89.968971,0.0088337772,343.60428,-9.2834034
165.4629,18.654184,9.4974241,0.0,0,-0.72867048,359.99997,1.0013845,87.311371,-0.00027712327,345.45258,-9.2858648
165.4653,18.085196,9.4996548,0.0,0,-0.27018416,359.99997,1.0025177,84.527176,0.0020760291,347.30084,-9.2862329
165.4677,17.62956,9.4941158,0.0,0,0.18830217,359.99997,1.0033495,82.317932,0.0084514739,349.14914,-9.2850637
165.4701,17.258774,9.4944811,5.2219605,0,0.6467886,359.99997,1.0032789,80.599571,0.011836554,350.53363,-9.2844038
165.4725,16.980045,9.4946594,10.816436,0,1.1052752,359.99997,1.0019386,79.403534,0.0085643707,351.88504,-9.2855806
165.4749,16.455109,9.4979105,16.410912,0,1.5637615,359.99997,1.0017185,76.992523,0.019088078,353.23645,-9.2852001
165.4773,15.030522,9.4933786,22.005384,0,2.022248,359.99997,1.0018964,70.381172,0.078255102,354.58786,-9.2871113
165.4797,12.301587,9.4788475,23.356934,0,2.4807346,359.99997,1.0005461,57.915199,0.19120935,356.3454,-9.2887011
165.4821,7.5758114,9.4604063,23.356934,0,2.9392209,359.99997,0.99707782,36.067272,0.41166225,358.2323,-9.2918587
165.4845,0.32520455,9.3346281,23.356934,0,3.3977075,359.99997,0.97366697,1.5476953,0.83774954,360.1192,-9.2984591
165.4869,-0.42441848,9.3291521,23.356934,0,3.8561938,359.99997,0.97082198,-1.7348249,1.5299067,362.0061,-9.298522
165.4893,0.17579941,9.3921347,20.09304,0,4.3146801,359.99997,0.98331201,0.53555441,2.3621931,363.59198,-9.2990551
165.4917,-0.19535419,9.3989334,14.498564,0,4.7731662,359.99997,0.98627448,-0.661632,3.0924945,364.96298,-9.2974157
165.4941,0.98628235,9.4128637,8.9040899,0,5.2316527,359.99997,0.98864782,4.7622948,3.6370208,366.33395,-9.2957449
165.4965,0.73417884,9.4297962,3.3096147,0,5.6901393,359.99997,0.99008673,3.4484284,4.0800891,367.70493,-9.2959938
165.4989,0.58726025,9.4215393,0.0,0,6.1486254,359.99997,0.98847675,2.7145581,4.4985733,368.77328,-9.2944756
165.5013,0.52037781,9.424778,0.0,0,6.6071115,359.99997,0.98972809,2.5377185,4.9102035,369.40326,-9.2937994
165.5037,0.68969029,9.4170933,0.0,0,7.0655985,359.99997,0.98949075,3.2193825,5.3388186,370.03323,-9.2920513
165.5061,0.64614731,9.4185877,0.0,0,7.524085,359.99997,0.98931789,3.101408,5.7840915,370.66321,-9.2917423
165.5085,0.5986979,9.4199371,0.0,0,7.9825716,359.99997,0.98815542,2.8617196,6.2502246,371.27966,-9.290329
165.5109,0.59191704,9.4249783,0.0,0,8.4410572,359.99997,0.98816037,2.7796812,6.7411203,371.85175,-9.2910471
165.5133,0.66928422,9.4268465,0.0,0,8.8995438,359.99997,0.9896881,3.2040801,7.2241526,372.4238,-9.2903919
165.5157,0.60639864,9.4216661,0.0,0,9.3580294,359.99997,0.99041069,2.9293962,7.7031798,372.99585,-9.291441
165.5181,0.6175133,9.4163809,0.0,0,9.8165169,359.99997,0.988904,2.8761029,8.1810408,373.55859,-9.2894955
165.5205,0.62084728,9.4198837,0.0,0,10.275002,359.99997,0.98807025,2.9304347,8.6475964,373.97134,-9.2902689
165.5229,0.61774576,9.4211035,0.0,0,10.733489,359.99997,0.98805821,2.9328523,9.1229906,374.38409,-9.2908468
165.5253,0.64374143,9.4209557,0.0,0,11.191976,359.99997,0.98913175,3.0221357,9.598443,374.79681,-9.2897158
165.5277,0.64471483,9.4181147,0.0,0,11.650462,359.99997,0.98974156,3.0492103,10.068195,375.20956,-9.2893715
165.5301,0.57881218,9.4198179,0.0,0,12.108949,359.99997,0.98936677,2.7348711,10.541278,375.60312,-9.2887774
165.5325,0.64666909,9.421278,0.0,0,12.567435,359.99997,0.98824918,3.0700154,11.019135,375.99414,-9.2892008
165.5349,0.64434409,9.4272175,0.0,0,13.025921,359.99997,0.98870569,3.07669,11.476943,376.38516,-9.2899647
165.5373,0.62545371,9.4253788,0.0,0,13.484407,359.99997,0.98986781,2.96099,11.931925,376.77618,-9.2903519
165.5397,0.63841379,9.4184608,0.0,0,13.942894,359.99997,0.98978335,3.0022044,12.389932,377.1467,-9.2890768
165.5421,0.62559873,9.4158621,0.0,0,14.401381,359.99997,0.9889214,2.999073,12.856681,377.50876,-9.289855
165.5445,0.61109871,9.4181328,0.0,0,14.859867,359.99997,0.98772424,2.86674,13.332839,377.87079,-9.2889347
165.5469,0.65811414,9.4211349,0.0,0,15.318354,359.99997,0.9880901,3.0950196,13.821373,378.23285,-9.2887497
165.5493,0.60121024,9.4211121,0.0,0,15.776839,359.99997,0.98917603,2.8832018,14.281949,378.53699,-9.288434
165.5517,0.64232767,9.4179144,0.0,0,16.235327,359.99997,0.98961782,3.0038004,14.753694,378.79041,-9.2878914
165.5541,0.66402447,9.4189339,0.0,0,16.693811,359.99997,0.98917699,3.1205602,15.206233,379.04385,-9.2890739
165.5565,0.6777882,9.4231653,0.0,0,17.152298,359.99997,0.98853993,3.2612555,15.66075,379.2973,-9.2882137
165.5589,0.6305716,9.4283209,0.0,0,17.610786,359.99997,0.98908973,2.9425476,16.124243,379.5144,-9.2889214
165.5613,0.64162147,9.4215174,0.0,0,17.999975,359.99997,0.98938847,3.0710318,16.582817,379.66647,-9.2893391
165.5637,0.59040791,9.4179754,0.0,0,18.0,359.99997,0.98970193,2.7802684,17.034975,379.81854,-9.2872705
165.5661,0.61704069,9.4178267,0.0,0,18.0,359.99997,0.98893785,2.9373291,17.470848,379.97061,-9.2873116
165.5685,0.65643001,9.4236689,0.0,0,18.0,359.99997,0.98879784,3.1023536,17.859797,380.12268,-9.2879467
165.5709,0.68417555,9.4246082,0.0,0,18.0,359.99997,0.98886162,3.277447,18.180811,380.27475,-9.290328
165.5733,0.6993438,9.4224567,0.0,0,18.0,359.99997,0.98958045,3.2872818,18.412537,380.42679,-9.2925186
165.5757,0.75863427,9.4165602,0.0,0,18.0,359.99997,0.98953301,3.5605457,18.53104,380.57886,-9.297267
165.5781,0.8027491,9.4195004,0.0,0,18.0,359.99997,0.98920423,3.7981362,18.517456,380.73019,-9.3039885
165.5805,0.79859006,9.4266882,0.0,0,18.0,359.99997,0.98895615,3.7754588,18.387527,380.79535,-9.3144789
165.5829,0.7050609,9.4297085,0.0,0,18.0,359.99997,0.98942679,3.3755198,18.242674,380.86053,-9.3269215
165.5853,0.73472404,9.4229298,0.0,0,18.0,359.99997,0.98966527,3.4642465,18.128307,380.92569,-9.3424826
165.5877,0.79774094,9.4171314,0.0,0,18.0,359.99997,0.98964107,3.7663903,18.063814,380.99084,-9.3597555
165.5901,0.80794847,9.4155817,0.0,0,18.0,359.99997,0.98840624,3.8220608,18.040985,381.04395,-9.3798628
165.5925,0.73034853,9.4191055,0.0,0,18.0,359.99997,0.98783249,3.5158999,18.040888,381.09464,-9.3994837
165.5949,0.67429662,9.4168425,0.0,0,18.0,359.99997,0.98770523,3.2323744,18.055658,381.14536,-9.4193201
165.5973,0.71966475,9.4145145,0.0,0,18.0,359.99997,0.98821348,3.335341,18.079817,381.19604,-9.4388762
165.5997,0.7927236,9.4098635,0.0,0,18.0,359.99997,0.98826081,3.730732,18.102791,381.27054,-9.4580278
165.6021,0.78326011,9.4139528,0.0,0,18.0,359.99997,0.98817819,3.7877381,18.123444,381.35739,-9.4758806
165.6045,0.73090982,9.4205379,0.0,0,18.0,359.99997,0.98798978,3.4764347,18.134161,381.44424,-9.4938545
165.6069,0.69683868,9.4233131,0.0,0,18.0,359.99997,0.98835564,3.2818024,18.136196,381.53113,-9.5102873
165.6093,0.77455306,9.4197302,0.0,0,18.0,359.99997,0.98943609,3.6727118,18.136141,381.63193,-9.527338
165.6117,0.80742776,9.4129419,0.0,0,18.0,359.99997,0.98909324,3.807117,18.129507,381.74765,-9.5436707
165.6141,0.78082228,9.4151688,0.0,0,18.0,359.99997,0.98833579,3.7338307,18.132082,381.86334,-9.5610571
165.6165,0.71277183,9.4208069,0.0,0,18.0,359.99997,0.98800963,3.3919415,18.126347,381.97906,-9.5783424
165.6189,0.74082774,9.4185219,0.0,0,18.0,359.99997,0.98790836,3.4930913,18.12855,382.08804,-9.5951548
165.6213,0.81830287,9.4159908,0.0,0,18.0,359.99997,0.98859632,3.8642862,18.123547,382.18198,-9.6128798
165.6237,0.81004858,9.4129,0.0,0,18.0,359.99997,0.98881066,3.8484378,18.122044,382.27591,-9.6312113
165.6261,0.73312581,9.4127159,0.0,0,18.0,359.99997,0.98771012,3.5180824,18.118771,382.36984,-9.6487007
165.6285,0.72783774,9.419055,0.0,0,18.0,359.99997,0.98760086,3.438334,18.119959,382.45605,-9.6663494
165.6309,0.77612448,9.4234076,0.0,0,18.0,359.99997,0.98839682,3.6675661,18.114298,382.49219,-9.6841049
165.6333,0.82784206,9.4213152,0.0,0,18.0,359.99997,0.98964798,3.9446714,18.111441,382.52829,-9.7016478
165.6357,0.78089726,9.416666,0.0,0,18.0,359.99997,0.98952174,3.7252781,18.106651,382.56442,-9.7205706
165.6381,0.71083677,9.4166708,0.0,0,18.0,359.99997,0.98842978,3.3916223,18.10848,382.60056,-9.7370548
165.6405,0.7458955,9.4187307,0.0,0,18.0,359.99997,0.9876951,3.4909115,18.107199,382.59512,-9.7540293
165.6429,0.80843073,9.4220591,0.0,0,18.0,359.99997,0.98838347,3.7907386,18.104864,382.58789,-9.7731371
165.6453,0.80949426,9.4179668,0.0,0,18.0,359.99997,0.98911434,3.8674707,18.103336,382.58066,-9.7899189
165.6477,0.73676115,9.4147139,0.0,0,18.0,359.99997,0.98909545,3.5391707,18.103825,382.57343,-9.8070307
165.6501,0.72202766,9.4156818,0.0,0,18.0,359.99997,0.98818427,3.4550471,18.101925,382.5379,-9.8241577
165.6525,0.76584721,9.4193201,0.0,0,18.0,359.99997,0.98750019,3.6200135,18.101112,382.49454,-9.8406248
165.6549,0.82540715,9.4201641,0.0,0,18.0,359.99997,0.98807269,3.9402809,18.10132,382.4512,-9.8584137
165.6573,0.77896047,9.416585,0.0,0,18.0,359.99997,0.98915493,3.7102296,18.100464,382.40784,-9.877821
165.6597,0.71755564,9.4110794,0.0,0,18.0,359.99997,0.9885956,3.4196815,18.093369,382.3645,-9.8963499
165.6621,0.72964722,9.4123697,0.0,0,18.0,359.99997,0.98755348,3.4111066,18.099344,382.32114,-9.9139147
165.6645,0.80088192,9.4189224,0.0,0,18.0,359.99997,0.98763609,3.8190858,18.096449,382.2778,-9.9310741
165.6669,0.81652075,9.420496,0.0,0,18.0,359.99997,0.98844969,3.8971653,18.090317,382.23447,-9.947628
165.6693,0.74412149,9.4137459,0.0,0,18.0,359.99997,0.98836625,3.5363512,18.090654,382.21304,-9.9656992
165.6717,0.71734238,9.4109383,0.0,0,18.0,359.99997,0.98829955,3.4263406,18.090755,382.22025,-9.9827385
165.6741,0.78263843,9.4127874,0.0,0,18.0,359.99997,0.98763025,3.6907792,18.090998,382.22748,-9.9998817
165.6765,0.82584953,9.4198866,0.0,0,18.0,359.99997,0.98753357,3.9029925,18.091499,382.23471,-10.0172
165.6789,0.79567719,9.4225721,0.0,0,18.0,359.99997,0.98866832,3.764143,18.08983,382.23257,-10.035665
165.6813,0.73035055,9.42099,0.0,0,18.0,359.99997,0.98988974,3.4703903,18.090088,382.2037,-10.052902
165.6837,0.73794633,9.4146538,0.0,0,18.0,359.99997,0.98908108,3.4592311,18.08968,382.1748,-10.070415
165.6861,0.83607858,9.4161539,0.0,0,18.0,359.99997,0.98795468,3.9195819,18.084774,382.1459,-10.087502
165.6885,0.82795584,9.4184036,0.0,0,18.0,359.99997,0.98751301,3.9370725,18.088015,382.11761,-10.106837
165.6909,0.75985664,9.4204102,0.0,0,18.0,359.99997,0.98838562,3.6244273,18.087757,382.09595,-10.124521
165.6933,0.73086143,9.4138594,0.0,0,18.0,359.99997,0.98863775,3.4784436,18.086899,382.07425,-10.139809
165.6957,0.79856008,9.4087849,0.0,0,18.0,359.99997,0.9878552,3.7408581,18.084663,382.05258,-10.157776
165.6981,0.84973949,9.4153652,0.0,0,18.0,359.99997,0.98766154,4.0211439,18.086231,382.03091,-10.175284
165.7005,0.82472503,9.4244385,0.0,0,18.0,359.99997,0.98832023,3.9734094,18.084785,382.01581,-10.194492
165.7029,0.73933959,9.4222469,0.0,0,18.0,359.99997,0.9887585,3.5256004,18.079546,382.00137,-10.211707
165.7053,0.75049031,9.4138069,0.0,0,18.0,359.99997,0.98858035,3.4861484,18.083294,381.98691,-10.228033
165.7077,0.83561718,9.4106083,0.0,0,18.0,359.99997,0.98829925,3.9320779,18.084198,381.97247,-10.245317
165.7101,0.84323859,9.4147511,0.0,0,18.0,359.99997,0.9875468,4.0402017,18.079609,381.95273,-10.264653
165.7125,0.76820052,9.4171858,0.0,0,18.0,359.99997,0.98729426,3.6511579,18.079052,381.93106,-10.28161
165.7149,0.73650676,9.4160271,0.0,0,18.0,359.99997,0.98795879,3.5043144,18.080765,381.90936,-10.29884
165.7173,0.78524643,9.4111319,0.0,0,18.0,359.99997,0.9882133,3.6680484,18.080734,381.8877,-10.317411
165.7197,0.83888698,9.4126406,0.0,0,18.0,359.99997,0.98848152,3.9523032,18.083241,381.866,-10.334015
165.7221,0.81689352,9.4188871,0.0,0,18.0,359.99997,0.98832786,3.8781796,18.077295,381.8443,-10.350899
165.7245,0.73482203,9.4209223,0.0,0,18.0,359.99997,0.98762822,3.5164089,18.077089,381.8226,-10.369398
165.7269,0.73963588,9.4201994,0.0,0,18.0,359.99997,0.98839092,3.5097809,18.082333,381.8009,-10.386541
165.7293,0.82909232,9.4159164,0.0,0,18.0,359.99997,0.98911357,3.8863056,18.077662,381.77646,-10.404347
165.7317,0.83278853,9.4108658,0.0,0,18.0,359.99997,0.98823202,3.9897654,18.075394,381.74753,-10.421478
165.7341,0.76417524,9.4136915,0.0,0,18.0,359.99997,0.98735529,3.6854217,18.075901,381.71863,-10.439383
165.7365,0.73217893,9.4177008,0.0,0,18.0,359.99997,0.98742211,3.4695926,18.076965,381.68973,-10.457128
165.7389,0.78101933,9.4179773,0.0,0,18.0,359.99997,0.98829597,3.6506505,18.075758,381.66382,-10.474035
165.7413,0.858814,9.4125538,0.0,0,18.0,359.99997,0.98856729,4.0328012,18.072432,381.64935,-10.492103
165.7437,0.81475335,9.4125786,0.0,0,18.0,359.99997,0.98833489,3.8514655,18.069887,381.63486,-10.509893
165.7461,0.73970383,9.4169998,0.0,0,18.0,359.99997,0.98767996,3.536742,18.073612,381.62039,-10.52785
165.7485,0.75290501,9.4223633,0.0,0,18.0,359.99997,0.98786074,3.5227938,18.070175,381.60614,-10.545062
165.7509,0.82981449,9.4214725,0.0,0,18.0,359.99997,0.98881966,3.9225292,18.071165,381.59888,-10.562514
165.7533,0.85715294,9.4160023,0.0,0,18.0,359.99997,0.98934984,4.0771537,18.072506,381.59164,-10.580635
165.7557,0.78327054,9.4126616,0.0,0,18.0,359.99997,0.98847216,3.762449,18.071159,381.58438,-10.599613
165.7581,0.74367094,9.4142847,0.0,0,18.0,359.99997,0.98735005,3.5379963,18.067144,381.57715,-10.616361
165.7605,0.79086065,9.417676,0.0,0,18.0,359.99997,0.98750675,3.7019732,18.067898,381.58234,-10.634223
165.7629,0.86182851,9.417716,0.0,0,18.0,359.99997,0.98831427,4.0986199,18.069027,381.58957,-10.650258
165.7653,0.82534766,9.4129848,0.0,0,18.0,359.99997,0.98884165,3.9699945,18.065561,381.5968,-10.666726
165.7677,0.76123208,9.4113598,0.0,0,18.0,359.99997,0.98799008,3.6323216,18.066751,381.60406,-10.685886
165.7701,0.75937515,9.4133577,0.0,0,18.0,359.99997,0.98693979,3.5797534,18.065456,381.60141,-10.701855
165.7725,0.83698052,9.4197836,0.0,0,18.0,359.99997,0.98731136,3.9303482,18.065325,381.59415,-10.720812
165.7749,0.85980314,9.4191895,0.0,0,18.0,359.99997,0.98867059,4.0563698,18.066166,381.58691,-10.737691
165.7773,0.79053777,9.4144354,0.0,0,18.0,359.99997,0.98904312,3.8139973,18.063251,381.57968,-10.756151
165.7797,0.73897839,9.4099913,0.0,0,18.0,359.99997,0.98764944,3.5363617,18.060829,381.5614,-10.7733
165.7821,0.80313641,9.4125328,0.0,0,18.0,359.99997,0.98694217,3.7755771,18.062521,381.53244,-10.790677
165.7845,0.86833477,9.4175615,0.0,0,18.0,359.99997,0.98756343,4.1152802,18.055639,381.50348,-10.808326
165.7869,0.83241576,9.4177961,0.0,0,18.0,359.99997,0.98852104,3.9771845,18.059481,381.47452,-10.825943
165.7893,0.7594288,9.4123383,0.0,0,18.0,359.99997,0.98857331,3.6224267,18.060369,381.4407,-10.844507
165.7917,0.75448781,9.4097548,0.0,0,18.0,359.99997,0.98748553,3.5320961,18.05797,381.39728,-10.861338
165.7941,0.84222811,9.4148798,0.0,0,18.0,359.99997,0.98701018,3.9406753,18.060383,381.35382,-10.880178
165.7965,0.86858755,9.4203815,0.0,0,18.0,359.99997,0.98762661,4.1226945,18.057262,381.31036,-10.897822
165.7989,0.79597116,9.418766,0.0,0,18.0,359.99997,0.98883885,3.8200428,18.057539,381.26923,-10.914913
165.8013,0.74381661,9.4119368,0.0,0,18.0,359.99997,0.98876834,3.4896574,18.056843,381.24026,-10.931225
165.8037,0.79304284,9.4119902,0.0,0,18.0,359.99997,0.98792756,3.6957967,18.05928,381.2113,-10.948851
165.8061,0.85999888,9.4136715,0.0,0,18.0,359.99997,0.98685038,4.1111898,18.056574,381.18234,-10.966896
165.8085,0.84143239,9.4165812,0.0,0,18.0,359.99997,0.98733991,4.008296,18.058716,381.15338,-10.984586
165.8109,0.76185918,9.4141722,0.0,0,18.0,359.99997,0.98804009,3.6200118,18.055231,381.14578,-11.002256
165.8133,0.76232976,9.4097424,0.0,0,18.0,359.99997,0.98818272,3.5701694,18.054399,381.13852,-11.018576
165.8157,0.8366043,9.4119043,0.0,0,18.0,359.99997,0.98783094,3.9256299,18.055607,381.13129,-11.035739
165.8181,0.87548602,9.4171648,0.0,0,18.0,359.99997,0.98745638,4.1197696,18.053467,381.12402,-11.05376
165.8205,0.79818952,9.4222431,0.0,0,18.0,359.99997,0.98784703,3.8207054,18.053665,381.1402,-11.071968
165.8229,0.74974525,9.4182262,0.0,0,18.0,359.99997,0.98906219,3.5931699,18.053942,381.16193,-11.089506
165.8253,0.79820043,9.412425,0.0,0,18.0,359.99997,0.98883742,3.7339461,18.053715,381.18365,-11.105515
165.8277,0.88291568,9.4112053,0.0,0,18.0,359.99997,0.9877246,4.1625218,18.050528,381.20538,-11.123857
165.8301,0.85036451,9.4165058,0.0,0,18.0,359.99997,0.98726004,4.055037,18.050587,381.20416,-11.143077
165.8325,0.7737959,9.4171457,0.0,0,18.0,359.99997,0.98751819,3.6790395,18.050884,381.1897,-11.159967
165.8349,0.75985867,9.4133549,0.0,0,18.0,359.99997,0.98800677,3.5958333,18.052774,381.1752,-11.178318
165.8373,0.84552759,9.4064646,0.0,0,18.0,359.99997,0.98774272,3.9511514,18.050543,381.16074,-11.193445
165.8397,0.8977676,9.4104853,0.0,0,18.0,359.99997,0.98752528,4.2428627,18.050093,381.12634,-11.21144
165.8421,0.8111881,9.4172363,0.0,0,18.0,359.99997,0.98743773,3.9140389,18.049393,381.06842,-11.229892
165.8445,0.74487078,9.4230881,0.0,0,18.0,359.99997,0.98835254,3.545603,18.049387,381.01047,-11.246642
165.8469,0.80052596,9.4194613,0.0,0,18.0,359.99997,0.98907965,3.7652566,18.049051,380.95255,-11.263785
165.8493,0.88382661,9.4121523,0.0,0,18.0,359.99997,0.98876941,4.1736422,18.046425,380.89462,-11.282745
165.8517,0.85901362,9.412262,0.0,0,18.0,359.99997,0.98760396,4.1254082,18.045889,380.8367,-11.300493
165.8541,0.79007357,9.4143534,0.0,0,18.0,359.99997,0.9869566,3.7732341,18.046638,380.77878,-11.316166
165.8565,0.76640499,9.4149265,0.0,0,18.0,359.99997,0.98717541,3.617384,18.046558,380.72083,-11.334374
165.8589,0.84762466,9.4111586,0.0,0,18.0,359.99997,0.98786986,3.9802313,18.047701,380.6637,-11.351211
166.0608,0.78210789,9.4149685,0.0,0,18.0,0.68380928,0.98791885,3.7139742,18.02496,371.17932,-11.481014
167.2608,0.72084516,9.4239407,0.0,0,18.0,2.956095e-17,0.98959112,3.4126534,18.001505,348.87259,-11.481887
168.4608,0.69345969,9.4306517,0.0,0,18.0,1.2779154e-33,0.99068797,3.2755079,17.999537,335.18881,-11.482207
169.6608,0.67433327,9.4363985,0.0,0,18.0,1.4012985e-45,0.99180371,3.1874671,17.999628,323.66235,-11.481884
170.8608,0.67444837,9.4419785,0.0,0,18.0,1.4012985e-45,0.99275309,3.1764669,18.000286,312.81238,-11.482578
172.0608,0.6581865,9.4468222,0.0,0,18.0,1.4012985e-45,0.99369365,3.1059911,18.000292,303.64542,-11.482385
173.2608,0.66254646,9.4519405,0.0,0,18.0,1.4012985e-45,0.99453932,3.126106,17.999989,294.57693,-11.482417
174.4608,0.668603,9.4566898,0.0,0,18.0,1.4012985e-45,0.99545628,3.1380703,17.999128,285.93213,-11.482194
175.6608,0.66215813,9.4611988,0.0,0,18.0,1.4012985e-45,0.99621427,3.1140079,18.000607,277.64624,-11.482635
176.8608,0.67495072,9.4660664,0.0,0,18.0,1.4012985e-45,0.99719054,3.1723633,18.00024,269.87927,-11.482205
178.0608,0.65869236,9.4711294,0.0,0,18.0,1.4012985e-45,0.99802846,3.0898881,18.000126,262.08765,-11.482594
179.2608,0.65176088,9.4749403,0.0,0,18.0,1.4012985e-45,0.9988085,3.0590706,18.000982,254.66808,-11.482621
180.4608,0.66216749,9.4795303,0.0,0,18.0,1.4012985e-45,0.99955446,3.1025736,18.000889,246.94151,-11.482399
181.6608,0.65295953,9.4833107,0.0,0,18.0,1.4012985e-45,1.000349,3.0571673,17.999166,240.00484,-11.482413
182.8608,0.65917224,9.4877005,0.0,0,18.0,1.4012985e-45,1.0010636,3.0923223,18.000422,233.67802,-11.482682
184.0608,0.65900373,9.4914055,0.0,0,18.0,1.4012985e-45,1.0017922,3.0715358,17.999722,227.38513,-11.482284
185.2608,0.65173012,9.4956961,0.0,0,18.0,1.4012985e-45,1.002535,3.0477111,18.000706,220.91516,-11.48258
186.4608,0.6627363,9.4992762,0.0,0,18.0,1.4012985e-45,1.0032231,3.0968499,18.000364,214.90067,-11.482656
187.6608,0.65517968,9.5032349,0.0,0,18.0,1.4012985e-45,1.0038967,3.0554712,18.000774,209.2123,-11.482867
188.8608,0.65718496,9.5070238,0.0,0,18.0,1.4012985e-45,1.0046378,3.0693419,18.000111,203.21889,-11.482913
190.0608,0.66975778,9.5108833,0.0,0,18.0,1.4012985e-45,1.005317,3.1164603,17.999294,197.89844,-11.483109
191.2608,0.65597308,9.5140667,0.0,0,18.0,1.4012985e-45,1.0058997,3.0527008,18.000437,192.51682,-11.483012
192.4608,0.65074843,9.5174971,0.0,0,18.0,1.4012985e-45,1.0065254,3.0325937,18.001087,187.33096,-11.482828
193.6608,0.65849388,9.5205393,0.0,0,18.0,1.4012985e-45,1.007061,3.0591824,17.999077,182.35408,-11.482679
194.8608,0.64384061,9.5241499,0.0,0,18.0,1.4012985e-45,1.0077441,2.9896638,18.000273,177.51064,-11.482265
196.0608,0.65697163,9.526783,0.0,0,18.0,1.4012985e-45,1.0081792,3.0594244,17.999245,172.88379,-11.482296
197.2608,0.6558851,9.5298491,0.0,0,18.0,1.4012985e-45,1.0087998,3.0437565,18.000883,168.35362,-11.482287
198.4608,0.64846265,9.5326672,0.0,0,18.0,1.4012985e-45,1.0092632,3.0165477,18.00005,163.93211,-11.482278
199.6608,0.65841103,9.5357389,0.0,0,18.0,1.4012985e-45,1.0098432,3.0565596,17.999769,159.75647,-11.482088
200.8608,0.65188295,9.5386829,0.0,0,18.0,1.4012985e-45,1.010343,3.0190604,17.999905,155.62344,-11.482081
202.0608,0.64627641,9.5412798,0.0,0,18.0,1.4012985e-45,1.0108328,2.9963973,17.999508,151.65244,-11.482366
203.2608,0.6571216,9.5439539,0.0,0,18.0,1.4012985e-45,1.0112934,3.0433748,18.000078,147.83362,-11.481924
204.4608,0.64648563,9.5466061,0.0,0,18.0,1.4012985e-45,1.0118239,2.9905097,17.999439,143.99165,-11.482259
205.6608,0.65363848,9.5493536,0.0,0,18.0,1.4012985e-45,1.0122722,3.0298402,17.999475,140.19754,-11.482381
206.8608,0.6594007,9.5513592,0.0,0,18.0,1.4012985e-45,1.0126543,3.0456543,18.000238,136.83725,-11.482618
208.0608,0.64266121,9.55373,0.0,0,18.0,1.4012985e-45,1.0130649,2.9708958,18.000767,133.35957,-11.482673
209.2608,0.64669901,9.5559521,0.0,0,18.0,1.4012985e-45,1.0134996,2.9925869,18.000751,129.99358,-11.482221
210.4608,0.64462399,9.5584822,0.0,0,18.0,1.4012985e-45,1.0139276,2.9742725,17.998634,126.77517,-11.48238
211.6608,0.65082204,9.5602465,0.0,0,18.0,1.4012985e-45,1.0143162,3.004132,18.00074,123.6675,-11.482496
212.8608,0.65126246,9.5626583,0.0,0,18.0,1.4012985e-45,1.0147301,3.0076859,18.000183,120.76304,-11.482189
214.0608,0.6464442,9.564949,0.0,0,18.0,1.4012985e-45,1.0152167,2.976074,17.999701,117.80486,-11.482177
215.2608,0.63650066,9.5668631,0.0,0,18.0,1.4012985e-45,1.0154995,2.9381027,18.00062,114.97433,-11.481881
216.4608,0.65012741,9.5684357,0.0,0,18.0,1.4012985e-45,1.0158763,2.9927163,18.000319,112.29868,-11.481594
217.6608,0.63445598,9.5709515,0.0,0,18.0,1.4012985e-45,1.0162868,2.9219186,18.000082,109.63994,-11.481681
218.8608,0.64606857,9.5726652,0.0,0,18.0,1.4012985e-45,1.0166408,2.9785745,18.000277,106.99957,-11.481732
220.0608,0.6364935,9.574297,0.0,0,18.0,1.4012985e-45,1.016948,2.923341,18.000198,104.50921,-11.481275
221.2608,0.63499016,9.5764551,0.0,0,18.0,1.4012985e-45,1.0173507,2.9259505,17.999691,102.15571,-11.481576
222.4608,0.65555614,9.5775433,0.0,0,18.0,1.4012985e-45,1.017547,3.0205767,17.999926,99.839935,-11.481732
223.6608,0.64686507,9.5793037,0.0,0,18.0,1.4012985e-45,1.0178404,2.9764283,18.000797,97.480293,-11.481391
224.8608,0.64519924,9.581419,0.0,0,18.0,1.4012985e-45,1.0182598,2.9699228,18.001308,95.383591,-11.482162
225.8608,0.64947486,9.5820122,0.0,0,18.0,1.4012985e-45,1.018364,2.992506,18.000118,93.58754,-11.481585