File: examples/hot axisymmetric compression example/data/02 screened data/testID_0137.csv
Time(sec),Force(kN),Jaw(mm),PowAngle(deg),Power(W),Pram,PTemp,Strain,Stress(MPa),Stroke(mm),TC1(C),wedge(mm)
0.0,0.77975363,0.29432628,0.0,0,11.076097,0.0005230183,0.019804098,9.7284269,11.076071,24.519331,-9.116848
1.1,0.72859317,0.0075859684,0.0,0,11.076097,3.2158797,0.00050257077,9.2912436,11.076005,24.497026,-9.4858427
2.2,0.69960207,0.0073424415,0.0,0,11.076097,6.5158815,0.00050584861,8.9122076,11.076761,24.457054,-9.4825621
3.3,0.69250321,0.0076804105,0.0,0,11.076097,9.8158808,0.00051285228,8.8251171,11.07799,24.436094,-9.4815435
4.4,0.67117971,0.0077069541,0.0,0,11.076097,13.115881,0.00049508479,8.5543518,11.075253,24.457144,-9.4796591
5.5,0.65617836,0.0077957278,0.0,0,11.076097,16.415882,0.00049774814,8.3495932,11.076131,24.423496,-9.4777975
6.6,0.64645582,0.007647112,0.0,0,11.076097,19.715883,0.00049309875,8.2266741,11.076111,24.35615,-9.4753151
7.7,0.6340006,0.0072858506,0.0,0,11.076097,23.015884,0.00047973881,8.0683231,11.076093,24.351368,-9.473175
8.8,0.62112331,0.0074441638,10.95277,0,11.076097,26.315884,0.00051127345,7.9029999,11.075755,24.320482,-9.4711065
9.9,0.62123817,0.0076106237,27.620062,0,11.076097,29.615883,0.00054015004,7.9013848,11.075999,24.521702,-9.468997
11.0,0.63974911,0.0067843152,37.041553,0,11.076097,32.915871,0.0004766639,8.1316833,11.076716,25.742176,-9.4683809
12.1,0.64640445,0.0036077916,42.359268,0,11.076097,36.215885,0.00024029406,8.2091017,11.076495,28.240839,-9.4665508
13.2,0.64988697,0.0010154704,45.611618,0,11.076097,39.515884,7.0015842e-05,8.2793493,11.075692,31.960037,-9.4643679
14.3,0.65480572,-0.0027229264,47.381241,0,11.076097,42.815884,-0.00017298189,8.3488169,11.076239,36.490509,-9.4627666
15.4,0.67401451,-0.0063482914,47.95433,0,11.076097,46.115891,-0.00042146357,8.5703096,11.076002,41.578537,-9.4611654
16.5,0.67690611,-0.0094717145,47.504887,0,11.076097,49.415894,-0.0006537115,8.6228704,11.075888,46.88549,-9.4593906
17.6,0.68415785,-0.013035954,46.327232,0,11.076097,52.715893,-0.00089380087,8.7162428,11.0762,51.970879,-9.4576321
18.7,0.68960726,-0.015647888,45.120941,0,11.076097,56.015896,-0.0010631954,8.7930079,11.075725,56.550377,-9.4554415
19.8,0.68989486,-0.018421834,43.546917,0,11.076097,59.315891,-0.0012366122,8.7933664,11.076233,60.772423,-9.453784
20.9,0.6761843,-0.020384267,42.647457,0,11.076097,62.615887,-0.0013329241,8.6157341,11.075237,64.278877,-9.4517422
22.0,0.68733501,-0.022643158,42.396244,0,11.076097,65.915871,-0.001473981,8.7859001,11.076461,67.203987,-9.450038
23.1,0.67956656,-0.024225116,42.396244,0,11.076097,69.215881,-0.0016003402,8.6842566,11.075974,69.89254,-9.4482336
24.2,0.67279828,-0.025938172,42.978512,0,11.076097,72.515892,-0.0017374642,8.5883665,11.07513,72.509712,-9.4461222
25.3,0.69390804,-0.028669372,44.077087,0,11.076097,75.815887,-0.0019029669,8.8482313,11.075674,75.105919,-9.4446754
26.4,0.69223481,-0.029942349,45.120838,0,11.076097,79.115891,-0.0019857343,8.8398724,11.076194,77.788322,-9.4427843
27.5,0.68635678,-0.032166306,46.109608,0,11.076097,82.415901,-0.0021586535,8.7534981,11.075667,80.718208,-9.4409189
28.6,0.69522911,-0.03448103,47.05444,0,11.076097,85.715889,-0.0023144737,8.8671799,11.076368,83.757408,-9.439167
29.7,0.69939554,-0.036885336,47.955318,0,11.076097,89.015892,-0.0024725136,8.9187517,11.077216,87.094368,-9.4377279
30.8,0.70095766,-0.039830245,48.383785,0,11.076097,92.31588,-0.0026508535,8.9467144,11.076142,90.49678,-9.4357872
31.9,0.70303363,-0.042655133,48.812252,0,11.076097,95.615891,-0.0028150221,8.9853449,11.075579,94.108696,-9.4337568
33.0,0.71553415,-0.045621458,49.226788,0,11.076097,98.915886,-0.0030140756,9.1214857,11.076234,97.639946,-9.431818
34.1,0.7132988,-0.04721069,49.229733,0,11.076097,102.21588,-0.0031387603,9.1168938,11.075877,101.28369,-9.4297781
35.2,0.71122694,-0.050365832,49.229733,0,11.076097,105.51588,-0.0033547964,9.0897131,11.07616,104.90948,-9.4277802
36.3,0.71839017,-0.053123999,49.229733,0,11.076097,108.81589,-0.0035171499,9.1676502,11.075914,108.43366,-9.4260759
37.4,0.71889043,-0.056084797,49.318352,0,11.076097,112.11589,-0.0037416467,9.1928682,11.076414,111.77575,-9.4238539
38.5,0.72406662,-0.057915982,49.636211,0,11.076097,115.41588,-0.0038829569,9.2568769,11.074873,115.00333,-9.421916
39.6,0.73003811,-0.060837202,49.636227,0,11.076097,118.71589,-0.0040606996,9.3186054,11.075532,118.43806,-9.4203224
40.7,0.73437887,-0.063265659,49.636227,0,11.076097,122.01588,-0.0042068129,9.3790464,11.075571,121.67601,-9.4192362
41.8,0.72959697,-0.066742301,50.042645,0,11.076097,125.3159,-0.0044068857,9.3283434,11.076121,124.89101,-9.4167337
42.9,0.74429512,-0.068022594,50.112247,0,11.076097,128.616,-0.0045020655,9.517972,11.076298,128.09937,-9.4151134
44.0,0.73775566,-0.070718937,50.438229,0,11.076097,131.91589,-0.0047116228,9.4465246,11.076815,131.36841,-9.4132891
45.1,0.73876584,-0.073371351,50.822712,0,11.076097,135.21591,-0.0048730955,9.4541273,11.075096,134.55568,-9.4113674
46.2,0.73712653,-0.076094523,50.929779,0,11.076097,138.5159,-0.005056282,9.4299908,11.076231,137.79984,-9.409667
47.3,0.75329828,-0.078864358,51.196301,0,11.076097,141.81589,-0.0052624848,9.6308155,11.075356,141.10953,-9.4081993
48.4,0.75396156,-0.081446402,51.56982,0,11.076097,145.11591,-0.0054422128,9.6498032,11.076684,144.3694,-9.406456
49.5,0.75745153,-0.083591081,51.891193,0,11.076097,148.41589,-0.0055652331,9.6865616,11.07583,147.63129,-9.4044828
50.6,0.75308144,-0.0866777,51.968655,0,11.076097,151.7159,-0.005740176,9.6389513,11.075025,150.90253,-9.4025631
51.7,0.75191307,-0.089645043,52.283936,0,11.076097,155.01588,-0.0059294584,9.6381273,11.076285,154.26018,-9.4012461
52.8,0.74477822,-0.092280097,52.635258,0,11.076097,158.3159,-0.0061370232,9.5409632,11.075489,157.44215,-9.3989859
53.9,0.76298851,-0.095387563,52.958431,0,11.076097,161.61589,-0.0063358573,9.7725344,11.076442,160.70207,-9.3972712
55.0,0.75943542,-0.099016957,52.97607,0,11.076097,164.91589,-0.0065689087,9.7275763,11.077361,164.06088,-9.3957605
56.1,0.76050276,-0.10079119,53.299965,0,11.076097,168.21588,-0.0067118858,9.7586308,11.076663,167.51793,-9.3938494
57.2,0.75788289,-0.10352651,53.31665,0,11.076097,171.51588,-0.0069037089,9.7221909,11.076789,170.86525,-9.3920355
58.3,0.76003283,-0.10672183,53.316654,0,11.076097,174.81589,-0.0071037402,9.742362,11.075603,174.23883,-9.3899717
59.4,0.75450516,-0.11008221,53.653526,0,11.076097,178.11589,-0.0072925501,9.6673651,11.076035,177.59262,-9.388072
60.5,0.76671326,-0.11263543,53.657715,0,11.076097,181.41589,-0.0074450057,9.8326626,11.077812,180.87857,-9.3867741
61.6,0.76811922,-0.11642215,53.975826,0,11.076097,184.7159,-0.0077307438,9.862278,11.076253,184.01768,-9.384903
62.7,0.76502472,-0.11813927,54.305325,0,11.076097,188.0159,-0.007841941,9.8223553,11.075967,187.24185,-9.3826656
63.8,0.76272726,-0.12099365,54.323513,0,11.076097,191.3159,-0.0080151511,9.7957392,11.076357,190.62007,-9.3814182
64.9,0.7644642,-0.1243065,54.623993,0,11.076097,194.61591,-0.0082642445,9.8335361,11.076642,193.97224,-9.3796701
66.0,0.76907074,-0.12775451,54.624023,0,11.076097,197.91589,-0.0085087512,9.869874,11.07629,197.3541,-9.3778954
67.1,0.77603805,-0.13075905,54.779526,0,11.076097,201.21591,-0.0086981123,9.9899874,11.076143,200.74117,-9.3764143
68.2,0.77016836,-0.13346422,54.931637,0,11.076097,204.5159,-0.0088408589,9.9032841,11.075905,204.01154,-9.3746462
69.3,0.75975257,-0.13661116,54.931637,0,11.076097,207.8159,-0.0090494482,9.7694111,11.076032,207.39378,-9.3727207
70.4,0.76332468,-0.13929254,55.00349,0,11.076097,211.11591,-0.0092514427,9.8038387,11.074939,210.70709,-9.3708744
71.5,0.77660167,-0.14337021,55.239254,0,11.076097,214.41589,-0.0095017357,9.9767933,11.075909,213.80264,-9.3689537
72.6,0.77339268,-0.14467579,55.535885,0,11.076097,217.7159,-0.0095983688,9.9403172,11.075356,217.02968,-9.3669453
73.7,0.77152789,-0.14796923,55.770229,0,11.076097,221.01588,-0.009836141,9.9333868,11.076019,220.33905,-9.3653059
74.8,0.76444346,-0.15132764,55.843506,0,11.076097,224.31589,-0.0100581,9.8377857,11.076646,223.64008,-9.3633509
75.9,0.77807778,-0.15588185,56.041134,0,11.076097,227.61589,-0.01033107,10.009243,11.075427,227.00842,-9.3612213
77.0,0.78165978,-0.15737388,56.129147,0,11.076097,230.91588,-0.010409065,10.060823,11.0769,230.40601,-9.3603983
78.1,0.7671079,-0.16066086,56.129147,0,11.076097,234.21588,-0.010654632,9.8715668,11.075577,233.88504,-9.3584089
79.2,0.77993488,-0.16432473,56.129147,0,11.076097,237.51588,-0.010892233,10.042591,11.076403,237.35985,-9.3566036
80.3,0.78174078,-0.16637616,56.129147,0,11.076097,240.81589,-0.011020281,10.057083,11.075336,240.59819,-9.3545904
81.4,0.77042758,-0.16937497,56.222622,0,11.076097,244.11589,-0.011254124,9.9212112,11.074827,243.83188,-9.3528204
82.5,0.78180075,-0.17379867,56.425777,0,11.076097,247.41589,-0.01154092,10.059777,11.075559,246.94585,-9.3509264
83.6,0.77824134,-0.17549221,56.711349,0,11.076097,250.71591,-0.011638875,10.044031,11.076497,250.0451,-9.3488674
84.7,0.77454764,-0.17864069,56.980614,0,11.076097,254.0159,-0.011808915,9.9795494,11.075248,253.27501,-9.3472767
85.8,0.77938062,-0.18168885,56.986084,0,11.076097,257.31616,-0.012034997,10.045994,11.076421,256.70093,-9.3458929
86.9,0.77533436,-0.18517181,57.259209,0,11.076097,260.61618,-0.012260746,10.00088,11.075521,260.03989,-9.3442154
88.0,0.78847235,-0.18957083,57.260738,0,11.076097,263.91589,-0.012543625,10.161239,11.076119,263.4465,-9.3423939
89.1,0.77718335,-0.19122048,57.143581,0,11.076097,267.21588,-0.012686722,10.019614,11.075626,267.02463,-9.3405199
90.2,0.76724976,-0.19499226,56.986095,0,11.076097,270.5159,-0.012937515,9.9131842,11.076076,270.62057,-9.3386745
91.3,0.78805375,-0.19914514,56.954845,0,11.076097,273.81586,-0.013183172,10.171108,11.075906,274.05853,-9.3370495
92.4,0.77307791,-0.20183855,56.71143,0,11.076097,277.11591,-0.01333882,9.9948139,11.076363,277.50452,-9.3351479
93.5,0.76886666,-0.20505613,56.71143,0,11.076097,280.41589,-0.013569107,9.925149,11.076838,280.73639,-9.3329525
94.6,0.78337014,-0.2088256,56.707745,0,11.076097,283.71588,-0.013825419,10.112304,11.075916,283.92581,-9.3309717
95.7,0.77665579,-0.21117361,56.711422,0,11.076097,287.01587,-0.013973776,10.031478,11.07664,287.14642,-9.32932
96.8,0.77557021,-0.21409605,56.711422,0,11.076097,290.31586,-0.014199764,10.012391,11.07525,290.37598,-9.3278389
97.9,0.78095764,-0.21893747,56.772396,0,11.076097,293.61588,-0.014508273,10.087477,11.075899,293.41772,-9.3263197
99.0,0.78117347,-0.22077903,56.986084,0,11.076097,296.91586,-0.014599216,10.102834,11.075763,296.63519,-9.3241062
100.1,0.7756449,-0.22456385,57.203568,0,11.076097,300.21591,-0.014833112,10.009892,11.075625,299.73126,-9.3225098
101.2,0.78025997,-0.22808146,57.260738,0,11.076097,303.51587,-0.015082641,10.08875,11.076569,302.96616,-9.320343
102.3,0.79210728,-0.23025355,57.519741,0,11.076097,306.81589,-0.015227657,10.246124,11.076457,306.18848,-9.3188782
103.4,0.78086936,-0.233178,57.535397,0,11.076097,310.11591,-0.015428241,10.104103,11.075751,309.60809,-9.3172703
104.5,0.77251446,-0.23728743,57.740902,0,11.076097,313.41589,-0.015717618,9.9929533,11.075918,312.85315,-9.3153458
105.6,0.79560655,-0.24156973,57.810051,0,11.076097,316.71594,-0.015981736,10.299156,11.076749,316.25851,-9.3133059
106.7,0.78914911,-0.243885,57.810051,0,11.076097,320.01593,-0.016107809,10.222006,11.075615,319.69699,-9.3115854
107.8,0.78198671,-0.24726267,57.810051,0,11.076097,323.31592,-0.016322155,10.126857,11.076234,323.0174,-9.3096838
108.9,0.77851373,-0.25066152,57.81023,0,11.076097,326.61591,-0.016576629,10.099168,11.076409,326.34225,-9.3078251
110.0,0.78105676,-0.25420749,57.960037,0,11.076097,329.91495,-0.016788678,10.122288,11.076025,329.63867,-9.3061228
111.1,0.048605543,-0.2684111,56.02713,0,11.076097,329.99976,-0.017757315,0.63154042,11.075192,332.62152,-9.3061342
112.2,0.030743819,-0.26753533,54.305779,0,11.076097,329.99976,-0.017701821,0.39375111,11.075595,334.14923,-9.3064423
113.3,0.015004619,-0.26784849,52.976082,0,11.076097,329.99976,-0.017705383,0.19321992,11.074685,334.23526,-9.3061514
114.4,0.0094694411,-0.26709521,52.283947,0,11.076097,329.99976,-0.017617822,0.11963863,11.076238,333.39194,-9.3061905
115.5,0.0149616,-0.26673099,52.479576,0,11.076097,329.99976,-0.01761754,0.18367127,11.076229,332.0018,-9.3062439
116.6,0.014743729,-0.26493478,53.109779,0,11.076097,329.99976,-0.017506599,0.18660052,11.076166,330.45108,-9.3060217
117.7,0.0054064365,-0.26429617,54.302162,0,11.076097,329.99976,-0.017464861,0.070006236,11.0762,328.92249,-9.306036
118.8,0.0061750952,-0.26362947,55.777782,0,11.076097,329.99976,-0.017446438,0.089160606,11.075444,327.32541,-9.306344
119.9,0.0034507979,-0.26372564,57.246986,0,11.076097,329.99976,-0.017439902,0.033842143,11.076193,326.16602,-9.3063679
121.0,0.0081850421,-0.26403296,58.589767,0,11.076097,329.99976,-0.017426688,0.098295294,11.075895,325.34244,-9.3062677
122.1,0.018812872,-0.26479536,59.840847,0,11.076097,329.99976,-0.017478671,0.25547388,11.07607,324.98236,-9.3056955
123.2,0.03400892,-0.26416162,60.786846,0,11.076097,329.99976,-0.017458912,0.44170845,11.07644,325.18369,-9.3058825
124.3,0.038766962,-0.26480249,61.237572,0,11.076097,329.99976,-0.017494757,0.50004858,11.075889,326.17178,-9.306056
125.4,0.037091333,-0.26627719,61.237789,0,11.076097,329.99976,-0.017621318,0.49489775,11.075888,327.36313,-9.3059311
126.5,0.036899008,-0.26783809,61.013336,0,11.076097,329.99976,-0.017716875,0.48147529,11.074201,328.94315,-9.3060236
127.6,0.042409595,-0.26905867,60.315063,0,11.076097,329.99976,-0.017765442,0.55340779,11.075946,330.46979,-9.3060741
128.7,0.052457575,-0.27115041,59.366627,0,11.076097,329.99976,-0.017886955,0.67653924,11.074949,331.75565,-9.3056927
129.8,0.049880516,-0.27140293,58.384239,0,11.076097,329.99976,-0.017945075,0.6479739,11.075814,332.70596,-9.3058968
130.9,0.044628847,-0.27126819,57.310028,0,11.076097,329.99976,-0.017902287,0.5754531,11.076262,333.39758,-9.3052769
132.0,0.045178279,-0.27149799,56.425831,0,11.076097,329.99976,-0.017964231,0.59261155,11.075927,333.60669,-9.3058147
133.1,0.040292524,-0.27179089,55.430607,0,11.076097,329.99976,-0.017971672,0.53222638,11.075026,333.65451,-9.3063231
134.2,0.033913761,-0.27186778,54.641361,0,11.076097,329.99976,-0.017944977,0.43913388,11.075307,333.28229,-9.3062468
135.3,0.011103114,-0.27204069,54.438927,0,11.076097,329.99976,-0.017958373,0.12332251,11.076328,332.53253,-9.3057775
136.4,0.0088884048,-0.27172509,54.623924,0,11.076097,329.99976,-0.01794962,0.10710778,11.076704,331.38388,-9.3053198
137.5,0.0089459075,-0.27242792,55.238438,0,11.076097,329.99976,-0.017988911,0.10415491,11.076632,330.0585,-9.3056831
138.6,0.0060777441,-0.27170604,56.128674,0,11.076097,329.99976,-0.017977865,0.086112827,11.076764,328.63229,-9.3051996
139.7,0.0083206249,-0.27097955,57.361084,0,11.076097,329.99976,-0.017925173,0.10824923,11.075289,327.42514,-9.3054724
140.8,0.015894109,-0.27123833,58.55666,0,11.076097,329.99976,-0.017902197,0.19723275,11.075316,326.57684,-9.3057556
141.9,0.023098642,-0.27149352,59.34742,0,11.076097,329.99976,-0.017918235,0.29581958,11.075744,326.47507,-9.3057194
143.0,0.04137307,-0.27175775,59.600826,0,11.076097,329.99976,-0.017959466,0.53685451,11.076923,327.17218,-9.3054085
144.1,0.046611626,-0.27307424,59.44474,0,11.076097,329.99976,-0.018027725,0.60855621,11.075926,328.59061,-9.3056231
145.2,0.048234873,-0.2740908,58.854588,0,11.076097,329.99976,-0.018124413,0.62236875,11.077084,330.15475,-9.3056269
146.3,0.044807542,-0.27507225,57.85191,0,11.076097,329.99976,-0.018188447,0.58532232,11.077228,331.4259,-9.3052092
147.4,0.049896106,-0.27610591,56.987076,0,11.076097,329.99976,-0.018215662,0.64596635,11.076705,332.32916,-9.3051157
148.5,0.051587146,-0.27622354,56.129715,0,11.076097,329.99976,-0.018230051,0.6609692,11.075687,332.81915,-9.3049841
149.6,0.046205241,-0.27644375,55.28756,0,11.076097,329.99976,-0.018263904,0.60722762,11.075625,332.83499,-9.3054914
150.7,0.038489223,-0.2761718,54.928307,0,11.076097,329.99976,-0.018240394,0.49198201,11.076133,332.5322,-9.3056345
151.8,0.028456777,-0.27624854,54.624027,0,11.076097,329.99976,-0.018279906,0.37794092,11.075199,332.02679,-9.3053932
152.9,0.01879604,-0.2764799,54.624027,0,11.076097,329.99976,-0.018272141,0.25796857,11.076659,331.22171,-9.305315
154.0,0.012561564,-0.27638748,55.205658,0,11.076097,329.99976,-0.018229075,0.1726177,11.076138,330.03024,-9.305232
155.1,0.026608473,-0.011350547,56.052841,0,11.076097,329.99976,-0.00074192614,0.34039828,11.075882,328.84274,-9.304987
155.2817,0.19177386,0.016496051,33.677261,0,11.076099,1.5464025e-08,0.00091389392,2.3482678,11.075349,328.52469,-9.3058348
155.2839,0.18318142,0.012333782,21.328848,0,11.076099,1.5445147e-23,0.0010549671,2.1675942,11.074743,328.53809,-9.3040886
155.2861,0.15939549,0.019020177,8.9804363,0,11.076099,1.5426296000000001e-38,0.0010282176,2.0127366,11.074889,328.55148,-9.3053761
155.2883,0.15042113,0.012075685,0.0,0,11.076099,0.0,0.001001698,1.9462063,11.076551,328.56125,-9.3049755
155.2905,0.15037696,0.013951859,0.0,0,11.076099,0.0,0.00075894513,1.9604156,11.074559,328.56125,-9.305275
155.2927,0.13574904,0.012775315,0.0,0,11.076099,0.0,0.0011088734,1.6940237,11.071866,328.56125,-9.3047209
155.2949,0.13756518,0.01875025,0.0,0,11.076099,0.0,0.00093963015,1.8234288,11.073325,328.56125,-9.3040876
155.2971,0.14135168,0.012158848,0.0,0,11.076099,0.0,0.001002421,1.7780641,11.07693,328.56125,-9.3043079
155.2993,0.15819299,0.013928311,0.0,0,11.076099,0.0,0.00080498197,2.0518234,11.075455,328.57101,-9.3053331
155.3015,0.17626292,0.011900961,0.0,0,11.076099,0.0,0.0010357748,2.2213943,11.075176,328.58441,-9.3047352
155.3037,0.17803828,0.019077929,0.0,0,11.076099,0.0,0.0010356578,2.245419,11.073626,328.59781,-9.3041315
155.3059,0.16204529,0.013513117,0.0,0,11.076099,0.0,0.0010623258,2.0628176,11.075011,328.61124,-9.304678
155.3081,0.14505492,0.015724143,0.0,0,11.076099,0.0,0.00091797224,1.9157121,11.075151,328.61975,-9.3046198
155.3103,0.15462354,0.012837531,0.0,0,11.076099,0.0,0.0011251784,2.0029125,11.07507,328.60635,-9.3055735
155.3125,0.14868456,0.018055668,0.0,0,11.076099,0.0,0.00090676866,2.0000117,11.075574,328.59293,-9.304718
155.3147,0.15540519,0.013078092,0.0,0,11.076099,0.0,0.0010504746,2.0615723,11.072109,328.57953,-9.3057508
155.3169,0.16114107,0.016565902,0.0,0,11.076099,0.0,0.00092986907,1.9967697,11.075294,328.56613,-9.3053808
155.3191,0.17150629,0.012985523,0.0,0,11.076099,0.0,0.0010869476,2.2107484,11.075178,328.56125,-9.3051014
155.3213,0.18791214,0.019458629,0.0,0,11.076099,0.0,0.0010456276,2.2534428,11.075944,328.56125,-9.3050108
155.3235,0.16843238,0.012775516,0.0,0,11.076099,0.0,0.0010177214,2.1963494,11.077335,328.56125,-9.3060684
155.3257,0.16395049,0.015446919,0.0,0,11.076099,0.0,0.0009122137,2.107409,11.0754,328.56125,-9.3060875
155.3279,0.15758768,0.012861514,0.0,0,11.076099,0.0,0.0011050917,1.9313633,11.075497,328.56308,-9.3059683
155.3301,0.16572122,0.01908108,0.0,0,11.076099,0.0,0.0010288855,2.0613968,11.076694,328.58319,-9.3050013
155.3323,0.16566549,0.012991391,0.0,0,10.765895,0.0,0.0010642688,2.0468199,11.076822,328.6033,-9.3047247
155.3345,0.17065722,0.016706783,0.0,0,10.435002,0.0,0.00096047361,2.0794377,11.072913,328.62341,-9.3053961
155.3367,0.20590697,0.013976967,0.0,0,10.104111,0.0,0.0011977277,2.5561543,11.023003,328.64352,-9.3062258
155.3389,0.17345063,0.020807113,0.0,0,9.7732182,0.0,0.0010994498,2.1594422,10.849793,329.0914,-9.3048468
155.3411,0.19979963,0.012756633,0.0,0,9.4434023,0.0,0.0010106965,2.5895202,10.550274,329.89572,-9.3044548
155.3433,0.17739654,0.015802573,0.0,0,9.1214933,0.0,0.0009918547,2.3922622,10.15823,330.70004,-9.3046227
155.3455,7.1899571,0.38703904,0.0,0,8.7995892,0.0,0.025849741,88.859322,9.7328234,331.50436,-9.2992392
155.3477,9.1361418,0.73943013,0.0,0,8.4910212,0.0,0.050093938,110.26447,9.298028,332.30865,-9.2981901
155.3499,9.5318165,1.1061682,0.0,0,8.1848688,0.0,0.076583222,112.06548,8.8953218,332.88525,-9.2992392
155.3521,9.8253422,1.4661344,0.0,0,7.8872514,0.0,0.10227906,113.0633,8.5533848,333.46185,-9.2975588
155.3543,10.300202,1.7390035,0.0,0,7.5959711,0.0,0.12311593,115.67014,8.2427902,334.03845,-9.29671
155.3565,10.527006,2.043251,0.0,0,7.3089838,0.0,0.14566109,115.99513,7.9378014,334.61508,-9.2961054
155.3587,10.692008,2.3178976,0.0,0,7.0319595,0.0,0.16771795,115.07864,7.6588278,334.55176,-9.2969847
155.3609,11.057557,2.5790231,0.0,0,6.7554379,0.0,0.18798266,116.66226,7.3979101,333.72064,-9.2984533
155.3631,11.229865,2.8335898,0.0,0,6.4917583,0.0,0.20935576,116.01806,7.1295915,332.88953,-9.2984619
155.3653,11.510918,3.1077266,0.0,0,6.2281981,0.0,0.23139374,116.25983,6.8615856,332.05841,-9.2977571
155.3675,11.823831,3.362401,0.0,0,5.97438,0.0,0.25369003,116.77374,6.592011,331.22726,-9.2968092
155.3697,12.123571,3.6303575,0.0,0,5.723712,0.0,0.27645633,116.96692,6.322999,329.99362,-9.2967339
155.3719,12.428724,3.8928933,0.0,0,5.47893,0.0,0.30051675,117.04155,6.0562811,328.71973,-9.2958193
155.3741,12.742561,4.161695,0.0,0,5.2404499,0.0,0.32398295,117.27839,5.7926111,327.4458,-9.2962065
155.3763,13.026667,4.4110336,0.0,0,5.0044208,0.0,0.34817293,117.08293,5.5337601,326.17191,-9.2980013
155.3785,13.314768,4.6637015,0.0,0,4.7776008,0.0,0.37160376,116.93629,5.2824316,324.8071,-9.2988205
155.3807,13.594893,4.9050512,0.0,0,4.5507808,0.0,0.39609677,116.55272,5.0373554,323.28323,-9.2983236
155.3829,13.898834,5.1538224,0.0,0,4.3343148,0.0,0.4199498,116.24419,4.7977719,321.7594,-9.2977505
155.3851,14.20689,5.3758516,0.0,0,4.1185384,0.0,0.44370788,116.06438,4.5627007,320.23553,-9.2975578
155.3873,14.543442,5.605546,0.0,0,3.9097824,0.0,0.46711659,115.99967,4.3382616,318.71167,-9.2978182
155.3895,14.875863,5.8189697,0.0,0,3.7045665,0.0,0.49104056,115.91015,4.1186252,316.48013,-9.2957478
155.3917,15.25142,6.0412517,0.0,0,3.5032659,0.0,0.51432604,116.00364,3.9011183,314.09134,-9.2969093
155.3939,15.623889,6.2406206,0.0,0,3.308038,0.0,0.53791678,116.1029,3.6944971,311.70258,-9.2969046
155.3961,16.017891,6.4488854,0.0,0,3.1139472,0.0,0.56119502,116.32384,3.4901545,309.31378,-9.296937
155.3983,16.403969,6.6412625,0.0,0,2.9282196,0.0,0.58497137,116.33638,3.2898333,307.1633,-9.2968674
155.4005,16.808878,6.8472948,0.0,0,2.7424955,0.0,0.60856235,116.45137,3.1018922,305.64816,-9.2964058
155.4027,17.276356,7.0279894,0.0,0,2.5644448,0.0,0.63222861,116.82994,2.9097881,304.13303,-9.2969532
155.4049,17.765678,7.2206759,0.0,0,2.3877847,0.0,0.65564358,117.34623,2.7185409,302.61789,-9.2964363
155.4071,18.279793,7.3985562,0.0,0,2.216074,0.0,0.6798684,117.84081,2.5359967,301.10272,-9.2957783
155.4093,18.814568,7.5870142,0.0,0,2.048038,0.0,0.70368528,118.49609,2.3576427,299.08984,-9.2947035
155.4115,19.392435,7.7558613,0.0,0,1.8824661,0.0,0.72811681,119.16208,2.1778045,296.89032,-9.2940197
155.4137,19.990149,7.9346395,0.0,0,1.722614,0.0,0.75193262,119.95593,2.0042696,294.6908,-9.2932186
155.4159,20.606949,8.0954094,0.0,0,1.5630525,0.0,0.77621311,120.68112,1.8401585,292.49124,-9.2946835
155.4181,21.272938,8.2717657,0.0,0,1.4109191,0.0,0.8003872,121.58057,1.6729062,290.41272,-9.293787
155.4203,21.950689,8.4219704,0.0,0,1.2588551,0.0,0.82456255,122.48152,1.5099963,288.87857,-9.2927027
155.4225,22.705549,8.5829611,0.0,0,1.1124103,0.0,0.84812546,123.76134,1.3508523,287.34442,-9.2929831
155.4247,23.489464,8.7283258,0.0,0,0.9677822,0.0,0.87242216,124.90973,1.1945156,285.81027,-9.2923794
155.4269,24.283419,8.8824644,0.0,0,0.82657528,0.0,0.89536387,126.23239,1.0452111,284.27609,-9.2931108
155.4291,25.115967,9.0138302,0.0,0,0.68903136,0.0,0.91898334,127.45441,0.90388328,283.25601,-9.2930269
155.4313,25.910992,9.1537209,0.0,0,0.5528841,0.0,0.94119722,128.63263,0.76719224,282.52963,-9.2914581
155.4335,26.754086,9.2737818,0.0,0,0.42198399,0.0,0.96360582,129.9187,0.63577276,281.80325,-9.2906227
155.4357,26.86161,9.3996115,0.0,0,0.29108396,0.0,0.98397607,128.492,0.50731808,281.0769,-9.2905092
155.4379,24.821182,9.4074526,0.0,0,0.16620633,0.0,0.98752403,117.90248,0.44873658,280.40298,-9.2929144
155.4401,23.580614,9.4142113,0.0,0,0.041730318,0.0,0.98715895,111.91541,0.41536686,280.25363,-9.2939615
155.4423,23.050486,9.4099064,0.0,0,-0.080698207,0.0,0.98810947,109.34264,0.38401335,280.10431,-9.2962551
155.4445,22.969587,9.4282961,0.0,0,-0.2020942,0.0,0.98924196,108.71623,0.34138054,279.95496,-9.2965298
155.4467,23.07902,9.4218102,0.0,0,-0.32349023,0.0,0.99005395,109.13168,0.2840541,279.8056,-9.2956238
155.4489,23.143076,9.4369631,0.0,0,-0.44488621,0.0,0.99111843,109.33051,0.22443141,281.06473,-9.2953558
155.4511,23.127987,9.43396,0.0,0,-0.56628221,0.0,0.99227577,109.15999,0.16906635,283.4975,-9.2966881
155.4533,23.039219,9.4510393,0.0,0,-0.68767816,0.0,0.99346483,108.62708,0.11383093,285.93027,-9.2962246
155.4555,22.860466,9.4435606,0.0,0,-0.80907416,0.0,0.99387395,107.7599,0.069067851,288.36304,-9.2963905
155.4577,22.593063,9.4518032,0.00021751122,0,-0.93047017,0.0,0.99383628,106.50515,0.033846039,290.79581,-9.2955732
155.4599,22.247728,9.4481421,11.874901,0,-1.0518663,0.0,0.99496156,104.74457,0.012759187,293.0795,-9.296916
155.4621,21.78627,9.4615021,23.749582,0,-0.88152969,330.0,0.99523556,102.63293,0.0013021238,295.36316,-9.2976961
155.4643,21.278278,9.4532661,35.624268,0,-0.46125016,330.0,0.99561024,100.14883,0.0015656215,297.64682,-9.2977705
155.4665,20.822966,9.4597502,47.498951,0,-0.040971313,330.0,0.99526042,97.999962,0.0022045367,299.93048,-9.2990131
155.4687,20.43997,9.4527998,53.97583,0,0.37930778,330.0,0.99563777,96.184669,0.0095040631,301.9942,-9.2992964
155.4709,20.15645,9.4652863,53.97583,0,0.79958731,330.0,0.99606544,94.810104,0.012432777,303.79398,-9.2993469
155.4731,19.93067,9.4508896,53.97583,0,1.2198665,330.0,0.99517965,93.853615,0.010696192,305.59378,-9.2997503
155.4753,19.328075,9.4626551,53.97583,0,1.6401452,330.0,0.99573088,91.01091,0.027520824,307.39355,-9.3001204
155.4775,17.484623,9.4483509,53.97583,0,2.060425,330.0,0.99474609,82.541466,0.10213075,309.19336,-9.3002653
155.4797,14.782108,9.4501448,51.02924,0,2.4807043,330.0,0.99327898,70.002243,0.22627814,310.89142,-9.3021193
155.4819,10.776608,9.4250374,47.788052,0,2.9009831,330.0,0.99058217,51.403431,0.41938165,312.57932,-9.3055925
155.4841,-0.22771776,9.3144941,44.546864,0,3.3212624,330.0,0.97022653,-1.3395433,0.71797675,314.26721,-9.3155203
155.4863,0.27516323,9.1403341,41.305679,0,3.7415414,330.0,0.94154847,1.0894575,1.368621,315.95508,-9.3169794
155.4885,0.013261491,9.0089998,39.243164,0,4.1618209,330.0,0.91714162,0.19413333,2.1217408,317.647,-9.3161221
155.4907,-0.052094825,8.8870821,39.243164,0,4.5820999,330.0,0.89868677,-0.2747283,2.839222,319.34598,-9.3159981
155.4929,-0.092981219,8.8098192,39.243164,0,5.0023794,330.0,0.88471001,-0.39801064,3.3957939,321.04495,-9.3161297
155.4951,-0.11613313,8.7635126,39.243164,0,5.422658,330.0,0.87845141,-0.58800226,3.8158898,322.7439,-9.3156433
155.4973,-0.079934768,8.7523556,39.243164,0,5.8429379,330.0,0.87495309,-0.47191328,4.2027435,324.44287,-9.314373
155.4995,-0.079080872,8.7551374,34.174618,0,6.2632165,330.0,0.87699401,-0.4483349,4.5868225,325.33871,-9.3128786
155.5017,-0.029035129,8.7851667,27.979866,0,6.683496,330.0,0.8804366,-0.22554909,4.9720201,326.05612,-9.3099632
155.5039,-0.052308314,8.8276358,21.785116,0,7.1037755,330.0,0.8886075,-0.29114699,5.3718295,326.77356,-9.309411
155.5061,-0.027302891,8.9034081,15.590366,0,7.5240545,330.0,0.89933234,-0.17175494,5.7904916,327.49097,-9.3094225
155.5083,0.059167277,8.9668322,11.085205,0,7.944334,330.0,0.91115093,0.36618999,6.225503,328.14252,-9.3088007
155.5105,-0.13117887,9.0751667,11.085205,0,8.3646135,330.0,0.92780554,-0.61918187,6.6669812,328.61856,-9.3093901
155.5127,-0.15233812,9.1806288,11.085205,0,8.7848921,330.0,0.94735259,-0.79691643,7.1085672,329.09457,-9.3092966
155.5149,-0.015605336,9.3175259,11.085205,0,9.2051716,330.0,0.96952313,-0.14708218,7.5559254,329.57062,-9.3088341
155.5171,-0.06326358,9.4471045,11.085205,0,9.6254511,330.0,0.99418658,-0.22550477,7.9934201,330.04663,-9.3090048
155.5193,-0.12835111,9.4051285,9.3115282,0,10.045731,330.0,0.98521346,-0.70481414,8.4213791,330.22034,-9.3071165
155.5215,-0.073868938,9.3984919,6.8727827,0,10.466009,330.0,0.9853673,-0.23579168,8.8506632,330.28067,-9.3055849
155.5237,-0.055502843,9.4076557,4.4340377,0,10.886289,330.0,0.98582131,-0.38308448,9.2845936,330.34103,-9.3055849
155.5259,0.048270572,9.4186306,1.9952928,0,11.306567,330.0,0.98968029,0.19310725,9.7252731,330.40137,-9.3049383
155.5281,-0.068708457,9.4213762,0.0,0,11.726847,330.0,0.9884789,-0.27018601,10.160618,330.44952,-9.3052616
155.5303,-0.17150803,9.420496,0.0,0,12.147126,330.0,0.98976952,-0.79574645,10.595791,330.44284,-9.3048944
155.5325,-0.065894708,9.4301157,0.0,0,12.567405,330.0,0.98983973,-0.39883262,11.026673,330.43613,-9.3047142
155.5347,-0.054948598,9.4171028,0.0,0,12.987684,330.0,0.98907661,-0.2542946,11.460268,330.42941,-9.3035069
155.5369,0.037362732,9.4222469,0.0,0,13.407964,330.0,0.98869127,0.21650606,11.879536,330.42273,-9.3043842
155.5391,-0.11783724,9.4170914,0.0,0,13.828242,330.0,0.98920262,-0.47949541,12.287687,330.71896,-9.3048935
155.5413,-0.11507566,9.4257841,0.0,0,14.248522,330.0,0.98902655,-0.63391948,12.701429,331.18829,-9.3054228
155.5435,-0.0055344235,9.4159565,0.0,0,14.6688,330.0,0.98881209,-0.076630726,13.129618,331.65762,-9.305541
155.5457,0.0382911,9.4212646,0.0,0,15.08908,330.0,0.9882651,0.22155239,13.563668,332.12695,-9.3050203
155.5479,-0.097689584,9.4134493,0.0,0,15.509359,330.0,0.98849684,-0.42733964,14.010198,332.58167,-9.3033667
155.5501,-0.10998484,9.4261665,0.0,0,15.929639,330.0,0.98911113,-0.45974329,14.446738,332.89008,-9.3036785
155.5523,-0.030076534,9.4152489,0.0,0,16.349918,330.0,0.98886859,-0.13506393,14.882444,333.19849,-9.3034372
155.5545,0.0038047694,9.4217014,0.0,0,16.770197,330.0,0.98855048,-0.016460571,15.31232,333.5069,-9.3035488
155.5567,0.020416604,9.4154015,0.0,0,17.190477,330.0,0.98884499,0.13769279,15.730274,333.81531,-9.3046551
155.5589,-0.1504207,9.424674,0.0,0,17.610756,330.0,0.98866677,-0.64523357,16.142303,334.18564,-9.3045778
155.5611,-0.1061932,9.415802,0.0,0,17.999401,330.0,0.98883885,-0.53770614,16.55069,334.60751,-9.3038845
155.5633,-0.03470578,9.4204578,0.0,0,18.0,330.0,0.98824334,-0.15209083,16.97168,335.02942,-9.3032722
155.5655,-0.031803913,9.4141254,0.0,0,18.0,330.0,0.98858374,-0.11281717,17.376705,335.45129,-9.3045235
155.5677,-0.11327727,9.425416,0.0,0,18.0,330.0,0.9890008,-0.52317268,17.745779,335.87317,-9.3046246
155.5699,0.010080777,9.4176445,0.0,0,18.0,330.0,0.98893815,0.010628253,18.067741,336.15399,-9.3057194
155.5721,-0.092629209,9.4238195,0.0,0,18.0,330.0,0.98879671,-0.3797121,18.324316,336.43481,-9.3078241
155.5743,-0.054289736,9.4204826,0.0,0,18.0,330.0,0.98972374,-0.32606268,18.492849,336.71567,-9.3109932
155.5765,-0.015854221,9.4343853,0.0,0,18.0,330.0,0.99070001,-0.10010792,18.549421,336.99649,-9.3151703
155.5787,-0.038331281,9.4356012,0.0,0,18.0,330.0,0.99221754,-0.21319367,18.502947,337.27728,-9.3223248
155.5809,-0.021724219,9.4506149,0.0,0,18.0,330.0,0.99364811,-0.079752304,18.378399,337.55804,-9.3313303
155.5831,-0.084775925,9.4546175,0.0,0,18.0,330.0,0.99564129,-0.33804274,18.238209,337.83881,-9.3428164
155.5853,-0.11819901,9.4812403,0.0,0,18.0,330.0,0.99874121,-0.52116442,18.124073,338.1196,-9.3572178
155.5875,-0.11794194,9.4877377,0.0,0,18.0,330.0,1.0015957,-0.55542129,18.054567,338.40036,-9.3741655
155.5897,-0.14255735,9.5090122,0.0,0,18.0,330.0,1.0042714,-0.66764808,18.033407,337.53055,-9.3912554
155.5919,-0.10004024,9.5169277,0.0,0,18.0,330.0,1.0071645,-0.50183731,18.030626,336.54575,-9.4097223
155.5941,0.012733987,9.5458317,0.0,0,18.0,330.0,1.010775,-0.029636171,18.044222,335.56091,-9.4266214
155.5963,0.038480498,9.5552349,0.0,0,18.0,330.0,1.0140444,0.19413595,18.068699,334.57608,-9.4455614
155.5985,0.015520154,9.5766926,0.0,0,18.0,330.0,1.0166864,0.11310239,18.095869,333.97128,-9.4642887
155.6007,-0.0057407222,9.5878534,0.0,0,18.0,330.0,1.0200955,0.00067128701,18.119383,334.03143,-9.4808102
155.6029,-0.084268287,9.6167269,0.0,0,18.0,330.0,1.0237018,-0.3202441,18.140516,334.09161,-9.4972792
155.6051,-0.17136474,9.6220741,0.0,0,18.0,330.0,1.0263329,-0.72919363,18.151312,334.15176,-9.5123844
155.6073,-0.1646648,9.6424217,0.0,0,18.0,330.0,1.0290886,-0.78239596,18.149778,334.21194,-9.5289345
155.6095,-0.071547054,9.6482735,0.0,0,18.0,330.0,1.0314577,-0.41925663,18.146645,335.22009,-9.5449343
155.6117,-0.013327428,9.6740217,0.0,0,18.0,330.0,1.0346637,-0.13341768,18.149366,336.43887,-9.5594196
155.6139,0.026645228,9.6826258,0.0,0,18.0,330.0,1.0375397,0.10537174,18.142952,337.65768,-9.5749407
155.6161,0.052277546,9.703805,0.0,0,18.0,330.0,1.0404099,0.23130894,18.140316,338.87646,-9.5910587
155.6183,0.016577808,9.7112026,0.0,0,18.0,330.0,1.0430512,0.10838321,18.13798,339.77014,-9.6061716
155.6205,-0.069297969,9.7396984,0.0,0,18.0,330.0,1.0470716,-0.2693035,18.132542,339.79688,-9.6210728
155.6227,-0.14999291,9.7455044,0.0,0,18.0,330.0,1.0497169,-0.60141784,18.132809,339.82364,-9.6382914
155.6249,-0.15787275,9.7665224,0.0,0,18.0,330.0,1.0524073,-0.72302842,18.128565,339.85037,-9.652812
155.6271,-0.11464699,9.7759962,0.0,0,18.0,330.0,1.0553918,-0.53782737,18.125095,339.87711,-9.6702108
155.6293,-0.027275227,9.8019991,0.0,0,18.0,330.0,1.0590432,-0.14790736,18.118565,340.08374,-9.685401
155.6315,0.024222994,9.8102226,0.0,0,18.0,330.0,1.0618173,0.075444467,18.119556,340.35782,-9.7013655
155.6337,0.047632214,9.8309813,0.0,0,18.0,330.0,1.0647825,0.19888295,18.119879,340.63187,-9.7174444
155.6359,0.028268967,9.8395233,0.0,0,18.0,330.0,1.0675584,0.17061806,18.114145,340.90594,-9.733572
155.6381,-0.040733602,9.8654957,0.0,0,18.0,330.0,1.0712061,-0.10652763,18.112549,341.17151,-9.7484169
155.6403,-0.13042259,9.8735085,0.0,0,18.0,330.0,1.0741031,-0.50942349,18.110703,341.3988,-9.7665682
155.6425,-0.16318561,9.8976974,0.0,0,18.0,330.0,1.0776356,-0.70720071,18.109053,341.6261,-9.7829714
155.6447,-0.13373949,9.9060631,0.0,0,18.0,330.0,1.0807389,-0.62257653,18.109396,341.85339,-9.7988329
155.6469,-0.055914845,9.9314289,0.0,0,18.0,330.0,1.084166,-0.28173211,18.107731,342.08069,-9.8141642
155.6491,0.022860816,9.9368439,0.0,0,18.0,330.0,1.0867093,0.051430892,18.104033,342.15057,-9.8297777
155.6513,0.046084225,9.9544935,0.0,0,18.0,330.0,1.0888621,0.16064346,18.106085,342.13052,-9.8442717
155.6535,0.033109985,9.9630871,0.0,0,18.0,330.0,1.0917137,0.15741836,18.104416,342.11047,-9.8605499
155.6557,-0.0040896316,9.9929314,0.0,0,18.0,330.0,1.0962356,0.047248062,18.105768,342.09039,-9.8777294
155.6579,-0.098628446,10.00059,0.0,0,18.0,330.0,1.099373,-0.34913161,18.103039,342.08252,-9.8937178
155.6601,-0.17201187,10.021812,0.0,0,18.0,330.0,1.1022877,-0.7086736,18.104452,342.19617,-9.9096794
155.6623,-0.16660801,10.029087,0.0,0,18.0,330.0,1.1050824,-0.70778537,18.097534,342.30978,-9.9257851
155.6645,-0.093633726,10.055115,0.0,0,18.0,330.0,1.10888,-0.43559897,18.099211,342.42343,-9.9422808
155.6667,0.0038956844,10.062056,0.0,0,18.0,330.0,1.1116289,-0.049076766,18.100233,342.53708,-9.9580402
155.6689,0.046830099,10.083746,0.0,0,18.0,330.0,1.1149592,0.18631814,18.096012,342.6398,-9.9728966
155.6711,0.049329203,10.093721,0.0,0,18.0,330.0,1.1179285,0.21987401,18.096804,342.7334,-9.9884949
155.6733,0.0067554945,10.117786,0.0,0,18.0,330.0,1.1215858,0.051501304,18.094191,342.82697,-10.004724
155.6755,-0.074862577,10.128284,0.0,0,18.0,330.0,1.1252584,-0.25286937,18.09577,342.92056,-10.021252
155.6777,-0.15522227,10.151553,0.0,0,18.0,330.0,1.1289003,-0.55916196,18.095194,343.01413,-10.037012
155.6799,-0.18918127,10.16175,0.0,0,18.0,330.0,1.1319013,-0.75850362,18.095118,340.79745,-10.054214
155.6821,-0.1113442,10.184393,0.0,0,18.0,330.0,1.1355791,-0.5186708,18.093479,338.58081,-10.069
155.6843,-0.017030695,10.189868,0.0,0,18.0,330.0,1.1379489,-0.13497761,18.093819,336.36414,-10.083783
155.6865,0.049005117,10.211095,0.0,0,18.0,330.0,1.1412394,0.13943572,18.093107,334.14749,-10.100046
155.6887,0.057862867,10.218745,0.0,0,18.0,330.0,1.1438379,0.22224514,18.092361,332.99011,-10.116296
155.6909,0.0162978,10.247332,0.0,0,18.0,330.0,1.1484312,0.12279833,18.090252,333.10376,-10.133061
155.6931,-0.041625846,10.256182,0.0,0,18.0,330.0,1.1515793,-0.12632097,18.090063,333.21741,-10.148167
155.6953,-0.11342225,10.277666,0.0,0,18.0,330.0,1.1551061,-0.38338041,18.087975,333.33105,-10.165077
155.6975,-0.16820987,10.286675,0.0,0,18.0,330.0,1.1581928,-0.63512683,18.089273,333.4447,-10.181467
155.6997,-0.14936988,10.314728,0.0,0,18.0,330.0,1.16298,-0.63814616,18.090046,335.63428,-10.197115
155.7019,-0.05204602,10.319532,0.0,0,18.0,330.0,1.1652064,-0.2716372,18.087585,338.03143,-10.213559
155.7041,0.042470843,10.338846,0.0,0,18.0,330.0,1.1682609,0.12001323,18.085455,340.42859,-10.230099
155.7063,0.066731274,10.346987,0.0,0,18.0,330.0,1.1709558,0.24165425,18.086357,342.82571,-10.24491
155.7085,0.040463336,10.372941,0.0,0,18.0,330.0,1.1755235,0.17482464,18.08363,344.3317,-10.260855
155.7107,-0.010739631,10.382167,0.0,0,18.0,330.0,1.1785696,0.017426332,18.080605,344.2782,-10.274815
155.7129,-0.10179483,10.403848,0.0,0,18.0,330.0,1.1823344,-0.34121799,18.078581,344.22473,-10.290868
155.7151,-0.15455961,10.414449,0.0,0,18.0,330.0,1.1855024,-0.56012678,18.079948,344.17123,-10.308901
155.7173,-0.16700308,10.440363,0.0,0,18.0,330.0,1.1899691,-0.68465787,18.083141,344.11777,-10.324688
155.7195,-0.10457202,10.447251,0.0,0,18.0,330.0,1.1928533,-0.47124034,18.077423,344.11899,-10.341531
155.7217,0.02029415,10.466722,0.0,0,18.0,330.0,1.1960467,-0.016462617,18.075151,344.13235,-10.357691
155.7239,0.06678585,10.476262,0.0,0,18.0,330.0,1.1991044,0.20270354,18.077547,344.14572,-10.373825
155.7261,0.049873725,10.499618,0.0,0,18.0,330.0,1.2029692,0.19557968,18.078001,344.15909,-10.388907
155.7283,-0.0058820047,10.507524,0.0,0,18.0,330.0,1.2062399,0.018532863,18.073456,343.99561,-10.403562
155.7305,-0.0610261,10.53173,0.0,0,18.0,330.0,1.2104771,-0.19346459,18.072685,343.36053,-10.419859
155.7327,-0.15037559,10.54424,0.0,0,18.0,330.0,1.2141372,-0.52596402,18.073132,342.72546,-10.435714
155.7349,-0.17586419,10.567576,0.0,0,18.0,330.0,1.2182631,-0.64984858,18.075214,342.09039,-10.453231
155.7371,-0.13008861,10.570848,0.0,0,18.0,330.0,1.2203698,-0.53802085,18.074665,341.45532,-10.470288
155.7393,-0.031399213,10.592112,0.0,0,18.0,330.0,1.2242441,-0.17507875,18.076925,341.29672,-10.485744
155.7415,0.054478373,10.603071,0.0,0,18.0,330.0,1.2276255,0.16222769,18.074667,341.31677,-10.501203
155.7437,0.07164076,10.627536,0.0,0,18.0,330.0,1.2320161,0.25949675,18.073792,341.33682,-10.514806
155.7459,0.018061949,10.635942,0.0,0,18.0,330.0,1.2350427,0.10710724,18.075211,341.35687,-10.530817
155.7481,-0.059899375,10.659673,0.0,0,18.0,330.0,1.2395216,-0.15541412,18.072521,341.22226,-10.546687
155.7503,-0.1117935,10.668925,0.0,0,18.0,330.0,1.2422823,-0.3849462,18.073009,340.39166,-10.562887
155.7525,-0.15907721,10.692708,0.0,0,18.0,330.0,1.2468837,-0.58743399,18.070108,339.56107,-10.579495
155.7547,-0.14427243,10.700607,0.0,0,18.0,330.0,1.2500957,-0.53091264,18.072628,338.73047,-10.596012
155.7569,-0.068036206,10.722084,0.0,0,18.0,330.0,1.2541453,-0.29265165,18.073753,337.8999,-10.612445
155.7591,0.028278166,10.728995,0.0,0,18.0,330.0,1.2566649,0.039439462,18.073462,336.94699,-10.629299
155.7613,0.072152004,10.753573,0.0,0,18.0,330.0,1.2613271,0.22855684,18.071896,335.92419,-10.643861
155.7635,0.055130497,10.76143,0.0,0,18.0,330.0,1.2641851,0.22516282,18.067045,334.9014,-10.659871
155.7657,-0.019261254,10.783466,0.0,0,18.0,330.0,1.2683671,-0.0067396383,18.070471,333.8786,-10.674893
155.7679,-0.11081535,10.79641,0.0,0,18.0,330.0,1.2724489,-0.33800009,18.071796,332.90979,-10.692008
155.7701,-0.14533608,10.824383,0.0,0,18.0,330.0,1.2780713,-0.50555825,18.069231,332.48068,-10.708015
155.7723,-0.15645768,10.828816,0.0,0,18.0,330.0,1.2803303,-0.55274552,18.06679,332.05157,-10.72536
155.7745,-0.096984722,10.848877,0.0,0,18.0,330.0,1.2844305,-0.37596029,18.066936,331.6225,-10.740983
155.7767,-0.0045700492,10.857234,0.0,0,18.0,330.0,1.2871664,-0.054833144,18.063097,331.19339,-10.756064
155.7789,0.059910912,10.883909,0.0,0,18.0,330.0,1.2922572,0.22239761,18.063168,330.7644,-10.772563
155.7811,0.06578628,10.889446,0.0,0,18.0,330.0,1.29478,0.24892481,18.068586,330.33551,-10.788565
155.7833,0.013577235,10.910912,0.0,0,18.0,330.0,1.2993432,0.10133848,18.064386,329.90662,-10.802666
155.7855,-0.07625284,10.923258,0.0,0,18.0,330.0,1.3030124,-0.19636767,18.0648,329.47775,-10.818011
155.7877,-0.14281408,10.948948,0.0,0,18.0,330.0,1.3085077,-0.46499667,18.061491,329.04889,-10.834937
155.7899,-0.15123543,10.956415,0.0,0,18.0,330.0,1.3112311,-0.50419027,18.059568,330.22836,-10.851999
155.7921,-0.11521795,10.976262,0.0,0,18.0,330.0,1.3153352,-0.43174171,18.060438,331.40784,-10.86876
155.7943,-0.022065757,10.986149,0.0,0,18.0,330.0,1.3186425,-0.14129016,18.061327,332.58731,-10.883987
155.7965,0.049193565,11.009014,0.0,0,18.0,330.0,1.3232789,0.10593317,18.056936,333.76678,-10.899778
155.7987,0.079074971,11.014472,0.0,0,18.0,330.0,1.3257972,0.25616801,18.055889,334.7388,-10.9142
155.8009,0.044360373,11.036707,0.0,0,18.0,330.0,1.3306913,0.17189702,18.056128,335.46182,-10.930388
155.8031,-0.033257648,11.048887,0.0,0,18.0,330.0,1.3343481,-0.041613173,18.057676,336.18484,-10.948027
155.8053,-0.12801512,11.07402,0.0,0,18.0,330.0,1.3397992,-0.39229938,18.057844,336.90787,-10.965014
155.8075,-0.16259323,11.083836,0.0,0,18.0,330.0,1.3433028,-0.53462934,18.057001,337.63089,-10.979164
155.8097,-0.13393468,11.101027,0.0,0,18.0,330.0,1.3469564,-0.46249497,18.058678,337.78775,-10.995066
155.8119,-0.055821609,11.111079,0.0,0,18.0,330.0,1.350401,-0.23627377,18.054747,337.88803,-11.012591
155.8141,0.020018874,11.138756,0.0,0,18.0,330.0,1.356481,0.028654197,18.056011,337.98831,-11.028886
155.8163,0.073101699,11.145151,0.0,0,18.0,330.0,1.3589915,0.21437065,18.057657,338.08859,-11.044017
155.8185,0.067369364,11.163519,0.0,0,18.0,330.0,1.3629586,0.25231686,18.056505,338.06003,-11.060505
155.8207,-0.0092304926,11.172778,0.0,0,18.0,330.0,1.3661355,0.039631955,18.056623,337.806,-11.076039
155.8229,-0.10343385,11.199835,0.0,0,18.0,330.0,1.3722944,-0.28189763,18.055006,337.55197,-11.092525
155.8251,-0.16794851,11.208281,0.0,0,18.0,330.0,1.3755662,-0.49463674,18.055822,337.29791,-11.109106
155.8273,-0.1459718,11.230667,0.0,0,18.0,330.0,1.380798,-0.49485609,18.054989,337.04388,-11.124131
155.8295,-0.078735843,11.239616,0.0,0,18.0,330.0,1.3837678,-0.30231854,18.056097,337.17273,-11.140504
155.8317,0.0082528247,11.259882,0.0,0,18.0,330.0,1.3881763,-0.013192108,18.053026,337.38666,-11.156929
155.8339,0.062831707,11.268753,0.0,0,18.0,330.0,1.3919364,0.1737714,18.055277,337.60059,-11.171307
155.8361,0.073108479,11.292497,0.0,0,18.0,330.0,1.3972775,0.22892778,18.055059,337.81448,-11.18617
155.8383,0.034617111,11.300656,0.0,0,18.0,330.0,1.4000866,0.13879107,18.051861,337.99924,-11.202401
155.8405,-0.075168267,11.326674,0.0,0,18.0,330.0,1.4063208,-0.16293463,18.051716,338.1062,-11.218451
155.8427,-0.14917332,11.335425,0.0,0,18.0,330.0,1.4095033,-0.42989269,18.052753,338.21317,-11.235005
155.8449,-0.15815234,11.356779,0.0,0,18.0,330.0,1.4149382,-0.47625569,18.052439,338.3201,-11.252055
155.8471,-0.097949833,11.368029,0.0,0,18.0,330.0,1.4185964,-0.3367933,18.049219,338.42706,-11.268264
155.8493,-0.0025256858,11.390701,0.0,0,18.0,330.0,1.4240419,-0.073393889,18.052118,338.05746,-11.284286
155.8515,0.050418735,11.395985,0.0,0,18.0,330.0,1.4263998,0.14824086,18.053343,337.50916,-11.299679
155.8537,0.074431144,11.416675,0.0,0,18.0,330.0,1.4315825,0.20831619,18.051872,336.96085,-11.314226
155.8559,0.049756043,11.427843,0.0,0,18.0,330.0,1.4349662,0.18560277,18.049852,336.41257,-11.332082
155.8581,-0.03571431,11.451952,0.0,0,18.0,330.0,1.441075,-0.031771652,18.04871,336.04175,-11.348162
155.8603,-0.12754802,11.461422,0.0,0,18.0,330.0,1.4446018,-0.32712764,18.049477,336.46957,-11.363058
156.6608,-0.052306045,11.578631,0.0,0,18.0,4.1213553e-09,1.4779414,-0.15534882,18.001619,312.80606,-11.481688
157.7608,-0.054269634,11.577612,0.0,0,18.0,4.1163117e-24,1.4775589,-0.16148095,18.000309,292.98035,-11.480515
158.8608,-0.051314447,11.576962,0.0,0,18.0,4.1112752e-39,1.4776024,-0.15302594,18.000288,281.78165,-11.481398
159.9608,-0.050006263,11.57742,0.0,0,18.0,1.4012985e-45,1.4777367,-0.1475368,18.000557,273.49197,-11.481552
161.0608,-0.048560821,11.576759,0.0,0,18.0,1.4012985e-45,1.4774299,-0.14238417,18.000118,262.90381,-11.48208
162.1608,-0.048938788,11.577882,0.0,0,18.0,1.4012985e-45,1.4778868,-0.14444634,17.999308,251.01793,-11.481687
163.2608,-0.052541286,11.578101,0.0,0,18.0,1.4012985e-45,1.4777237,-0.15433817,17.99976,242.70004,-11.481209
164.3608,-0.047897987,11.57798,0.0,0,18.0,1.4012985e-45,1.4777483,-0.14142141,17.999851,232.66635,-11.481351
165.4608,-0.050864283,11.577721,0.0,0,18.0,1.4012985e-45,1.47791,-0.14882636,17.999563,225.64658,-11.481357
166.5608,-0.051363856,11.578077,0.0,0,18.0,1.4012985e-45,1.477862,-0.14880162,18.000223,215.40683,-11.481767
167.6608,-0.049255006,11.577764,0.0,0,18.0,1.4012985e-45,1.477798,-0.14248593,18.000349,207.93701,-11.482043
168.7608,-0.05172636,11.578188,0.0,0,18.0,1.4012985e-45,1.47791,-0.14818099,17.999376,203.34171,-11.481855
169.8608,-0.051888272,11.578148,0.0,0,18.0,1.4012985e-45,1.4777161,-0.14835142,17.999773,195.01222,-11.481725
170.9608,-0.051887553,11.578422,0.0,0,18.0,1.4012985e-45,1.4779749,-0.14750054,18.000473,190.22011,-11.481943
172.0608,-0.0529515,11.577586,0.0,0,18.0,1.4012985e-45,1.4778692,-0.150732,17.999168,186.42558,-11.481983
173.1608,-0.053839821,11.57843,0.0,0,18.0,1.4012985e-45,1.4778885,-0.15459205,17.999809,181.1718,-11.48178
174.2608,-0.058481954,11.578025,0.0,0,18.0,1.4012985e-45,1.4779462,-0.16531466,18.000307,175.75066,-11.482018
175.3608,-0.054244842,11.578688,0.0,0,18.0,1.4012985e-45,1.4779352,-0.15624943,17.999794,170.41805,-11.482085
176.4608,-0.057989098,11.578918,0.0,0,18.0,1.4012985e-45,1.4779928,-0.16528536,18.000217,164.37231,-11.481876
177.5608,-0.060581304,11.578549,0.0,0,18.0,1.4012985e-45,1.4781603,-0.17232753,17.999388,160.01154,-11.481366
178.6608,-0.062418625,11.578334,0.0,0,18.0,1.4012985e-45,1.4779395,-0.17883235,18.00032,154.62926,-11.481367
179.7608,-0.054717459,11.578887,0.0,0,18.0,1.4012985e-45,1.4780921,-0.15607253,17.999182,150.28543,-11.481554
180.8608,-0.057819713,11.579707,0.0,0,18.0,1.4012985e-45,1.4783542,-0.1684002,18.000195,147.22905,-11.481963
181.9608,-0.056058653,11.579575,0.0,0,18.0,1.4012985e-45,1.4780698,-0.16424946,18.000305,142.1675,-11.481973
183.0608,-0.057073273,11.579342,0.0,0,18.0,1.4012985e-45,1.4782567,-0.16853821,17.999821,138.42491,-11.481986
184.1608,-0.056167305,11.579248,0.0,0,18.0,1.4012985e-45,1.4783326,-0.16491418,17.999557,133.54407,-11.481964
185.2608,-0.056986105,11.579439,0.0,0,18.0,1.4012985e-45,1.4781733,-0.16789693,17.999907,129.86116,-11.481871
186.3608,-0.058409031,11.579552,0.0,0,18.0,1.4012985e-45,1.4783975,-0.17045121,17.999569,126.7462,-11.481764
187.4608,-0.056053974,11.579991,0.0,0,18.0,1.4012985e-45,1.4782656,-0.16626407,17.99999,122.41759,-11.481886
188.5608,-0.052536987,11.579822,0.0,0,18.0,1.4012985e-45,1.4782883,-0.15134764,18.00012,119.68037,-11.481696
189.6608,-0.054725457,11.579917,0.0,0,18.0,1.4012985e-45,1.4785618,-0.15980282,18.000566,115.29522,-11.481751
190.7608,-0.055059079,11.579901,0.0,0,18.0,1.4012985e-45,1.4783733,-0.16119836,18.000654,112.24862,-11.481447
191.8608,-0.050835114,11.58008,0.0,0,18.0,1.4012985e-45,1.4785303,-0.14668953,17.999388,109.78996,-11.481589
192.9608,-0.049264234,11.579848,0.0,0,18.0,1.4012985e-45,1.4782976,-0.14420734,18.000235,106.77676,-11.481891
194.0608,-0.047603019,11.581072,0.0,0,18.0,1.4012985e-45,1.4786053,-0.13900892,17.999479,103.27552,-11.481995
195.1608,-0.047686264,11.580668,0.0,0,18.0,1.4012985e-45,1.4787875,-0.13480292,17.999245,101.60545,-11.48245
196.2608,-0.056295719,11.580497,0.0,0,18.0,1.4012985e-45,1.4785342,-0.16193847,18.000168,99.554604,-11.48207
197.3608,-0.055502731,11.580364,0.0,0,18.0,1.4012985e-45,1.4785517,-0.16003297,18.000393,96.935043,-11.481825
198.4608,-0.057264775,11.580844,0.0,0,18.0,1.4012985e-45,1.478677,-0.1633655,17.99938,94.397926,-11.48105
199.5608,-0.058989614,11.581,0.0,0,18.0,1.4012985e-45,1.4785404,-0.16754331,17.999939,92.171646,-11.480922
200.6608,-0.057035234,11.580565,0.0,0,18.0,1.4012985e-45,1.4786754,-0.16360876,18.000471,89.559227,-11.480803
201.7608,-0.060123015,11.580551,0.0,0,18.0,1.4012985e-45,1.4786676,-0.17432189,17.999752,86.793159,-11.480616
202.8608,-0.057458423,11.580509,0.0,0,18.0,1.4012985e-45,1.4785618,-0.16312931,17.999901,84.974663,-11.480639
203.9608,-0.058603037,11.580828,0.0,0,18.0,1.4012985e-45,1.4787571,-0.16450167,17.999226,82.721725,-11.480632
205.0608,-0.057837974,11.581077,0.0,0,18.0,1.4012985e-45,1.4785523,-0.16386116,18.000706,80.994331,-11.480741
206.1608,-0.057589095,11.581522,0.0,0,18.0,1.4012985e-45,1.4788915,-0.16746499,17.999939,79.262337,-11.4815
207.2608,-0.057843793,11.581697,0.0,0,18.0,1.4012985e-45,1.4790294,-0.1681592,17.998945,77.334,-11.481654
208.3608,-0.054596439,11.582218,0.0,0,18.0,1.4012985e-45,1.4790034,-0.15883133,17.999924,75.243202,-11.481874
209.4608,-0.05932042,11.582243,0.0,0,18.0,1.4012985e-45,1.4791199,-0.17415345,18.000563,73.400337,-11.482225
210.5608,-0.057198323,11.582534,0.0,0,18.0,1.4012985e-45,1.4789579,-0.16402917,18.000465,72.012344,-11.481974
211.6608,-0.059930637,11.582825,0.0,0,18.0,1.4012985e-45,1.4792826,-0.17275058,18.000446,69.728401,-11.48232
212.7608,-0.060319252,11.58271,0.0,0,18.0,1.4012985e-45,1.4793279,-0.17599316,17.999815,68.780533,-11.481992
213.8608,-0.053414352,11.582908,0.0,0,18.0,1.4012985e-45,1.4791729,-0.15652536,18.000244,67.262421,-11.482394
214.9608,-0.060270101,11.582811,0.0,0,18.0,1.4012985e-45,1.4792904,-0.17890671,18.000803,65.76136,-11.48225
215.8608,-0.05731535,11.583006,0.0,0,18.0,1.4012985e-45,1.479116,-0.16496298,17.999805,64.937683,-11.643204