File: examples/hot axisymmetric compression example/data/02 screened data/testID_0147.csv
Time(sec),Force(kN),Jaw(mm),PowAngle(deg),Power(W),Pram,PTemp,Strain,Stress(MPa),Stroke(mm),TC1(C),wedge(mm)
0.0,0.7796973,0.64416194,0.0,0,11.076097,0.0016076213,0.043846339,9.5102749,11.076338,27.651932,-9.1710911
1.2,0.73138946,-0.0045156213,0.0,0,11.076097,3.5156176,-0.00026231224,9.3168087,11.076718,27.721422,-9.5097332
2.4,0.68930763,-0.0044353269,0.0,0,11.076097,7.1156168,-0.00034489424,8.7785149,11.075819,27.678762,-9.5045643
3.6,0.68806905,-0.0047835149,0.0,0,11.076097,10.715614,-0.00026492384,8.7647457,11.076647,27.674992,-9.5053682
4.8,0.67165107,-0.0044664298,0.0,0,11.076097,14.315614,-0.00027779426,8.5518322,11.075997,27.701273,-9.5031738
6.0,0.64452958,-0.0044676047,0.0,0,11.076097,17.915613,-0.00026426828,8.2118673,11.076501,27.732635,-9.4993973
7.2,0.63293034,-0.0046703103,0.0,0,11.076097,21.51561,-0.00027523795,8.059021,11.076066,27.694494,-9.4969139
8.4,0.62574488,-0.0047552292,0.0,0,11.076097,25.11561,-0.00032632003,7.9752831,11.076189,27.609182,-9.4945412
9.6,0.61111671,-0.0048306123,3.5599182,0,11.076097,28.715611,-0.00030270001,7.7816772,11.075809,27.637653,-9.4919949
10.8,0.60290498,-0.0043805079,24.75042,0,11.076097,32.315609,-0.00029735922,7.6859503,11.076577,27.966991,-9.4892254
12.0,0.62374455,-0.0062072757,34.292736,0,11.076097,35.915615,-0.00043445773,7.9345946,11.076742,29.825335,-9.487011
13.2,0.63637769,-0.010188641,39.213821,0,11.076097,39.51561,-0.00070648803,8.1041765,11.076065,33.350414,-9.4848824
14.4,0.64978516,-0.01348173,41.198105,0,11.076097,43.115616,-0.00092613895,8.2868576,11.076086,38.006134,-9.4825764
15.6,0.6498394,-0.017102212,41.198727,0,11.076097,46.715611,-0.0011676444,8.2800827,11.076123,43.563374,-9.4799833
16.8,0.64996606,-0.020489614,39.925369,0,11.076097,50.315613,-0.0014004137,8.2845478,11.076348,49.093052,-9.4774456
18.0,0.65128922,-0.023754872,38.552029,0,11.076097,53.915619,-0.0016186025,8.2998581,11.076468,54.007172,-9.4748936
19.2,0.64427638,-0.02615504,37.094017,0,11.076097,57.515614,-0.0017605034,8.2217007,11.075465,58.202995,-9.4721203
20.4,0.65203637,-0.028076602,37.08984,0,11.076097,61.115612,-0.0019116524,8.3167706,11.076098,61.778015,-9.4704981
21.6,0.64202464,-0.030763915,37.08984,0,11.076097,64.715599,-0.0020535556,8.1859617,11.075655,64.979485,-9.4681864
22.8,0.63862991,-0.032652359,37.836914,0,11.076097,68.31559,-0.0022233839,8.1495008,11.076009,68.082497,-9.4660072
24.0,0.65810317,-0.03567582,38.679642,0,11.076097,71.915604,-0.0023664059,8.3940516,11.075765,71.235664,-9.4636717
25.2,0.65004861,-0.038596004,39.24316,0,11.076097,75.515594,-0.0026181897,8.3006029,11.076498,74.700264,-9.4610882
26.4,0.64946944,-0.041436046,39.924313,0,11.076097,79.115593,-0.0027507124,8.2966118,11.075717,78.24025,-9.4583731
27.6,0.65212405,-0.043806255,40.567692,0,11.076097,82.715599,-0.0029800767,8.3221102,11.076057,81.936478,-9.4557648
28.8,0.65871459,-0.046912901,40.629005,0,11.076097,86.315605,-0.003117596,8.4087067,11.075674,85.62738,-9.4540606
30.0,0.657381,-0.049551364,41.198727,0,11.076097,89.915604,-0.0033435705,8.4034395,11.075605,89.23217,-9.4516497
31.2,0.65548688,-0.052850127,41.198727,0,11.076097,93.515602,-0.0035303773,8.3708696,11.07591,93.030357,-9.4492426
32.4,0.67212301,-0.055778123,41.799175,0,11.076097,97.115608,-0.0037414718,8.5905409,11.075481,96.548454,-9.4471006
33.6,0.66691172,-0.059385747,41.802975,0,11.076097,100.71561,-0.0039787572,8.5218353,11.075285,100.18115,-9.4447794
34.8,0.66212237,-0.062061172,42.389545,0,11.076097,104.3156,-0.0041641025,8.4675856,11.07594,103.7833,-9.4426394
36.0,0.66946816,-0.065114819,42.396236,0,11.076097,107.9156,-0.0043681441,8.5733833,11.07565,107.51204,-9.4402618
37.2,0.66814679,-0.068318926,42.403164,0,11.076097,111.5156,-0.004569469,8.5416594,11.076543,111.05211,-9.4371328
38.4,0.6671924,-0.071169518,42.971619,0,11.076097,115.11561,-0.0047635981,8.5501671,11.076305,114.66057,-9.4351091
39.6,0.67659676,-0.074525751,42.978512,0,11.076097,118.7156,-0.0049828351,8.6549282,11.076498,118.2914,-9.4326992
40.8,0.68384004,-0.077403411,43.24197,0,11.076097,122.3156,-0.0051801233,8.7472534,11.076077,121.88741,-9.4309244
42.0,0.68635541,-0.08016704,43.527828,0,11.076097,125.91559,-0.0053491271,8.7849083,11.075307,125.49578,-9.4285517
43.2,0.69113272,-0.084056221,43.539169,0,11.076097,129.5157,-0.0056038136,8.8471384,11.076247,129.10951,-9.4264832
44.4,0.6951611,-0.087758131,43.770351,0,11.076097,133.1156,-0.005822673,8.901103,11.075646,132.77045,-9.4242954
45.6,0.69749421,-0.090349615,44.077145,0,11.076097,136.71558,-0.0059989216,8.9294443,11.076,136.30545,-9.4213476
46.8,0.69856668,-0.092975453,44.077145,0,11.076097,140.3156,-0.0061795223,8.9516935,11.076291,140.01814,-9.4190245
48.0,0.69958252,-0.095558144,44.566006,0,11.076097,143.91559,-0.0063274065,8.9726658,11.075747,143.49289,-9.4170685
49.2,0.70782954,-0.099269293,44.604488,0,11.076097,147.51558,-0.0065689036,9.0655146,11.076292,147.09737,-9.415451
50.4,0.70267206,-0.10215695,45.050205,0,11.076097,151.11557,-0.006770493,9.0042229,11.076086,150.65648,-9.4127903
51.6,0.71210533,-0.10594741,45.12085,0,11.076097,154.71558,-0.006994742,9.1284962,11.076075,154.34895,-9.4104586
52.8,0.71427029,-0.10866861,45.12085,0,11.076097,158.31558,-0.0072095431,9.161581,11.075932,157.94022,-9.4081545
54.0,0.70576674,-0.11221319,45.320278,0,11.076097,161.91557,-0.0073899934,9.0610514,11.076631,161.54593,-9.4063549
55.2,0.71989691,-0.11515366,45.582367,0,11.076097,165.51559,-0.007683944,9.2393723,11.075433,165.13043,-9.4042063
56.4,0.72389817,-0.11850061,45.615231,0,11.076097,169.11557,-0.0078545604,9.2769737,11.075965,168.81631,-9.4014606
57.6,0.73043793,-0.12133804,45.615231,0,11.076097,172.71558,-0.0081093013,9.3584661,11.075809,172.50606,-9.3995953
58.8,0.74000949,-0.12559615,45.615231,0,11.076097,176.31558,-0.0083497632,9.5000439,11.075833,176.21852,-9.3973808
60.0,0.73645914,-0.12913908,45.615231,0,11.076097,179.91559,-0.0086033111,9.453969,11.076425,179.71683,-9.3952026
61.2,0.74349642,-0.13203371,46.046619,0,11.076097,183.51558,-0.0087933792,9.5511923,11.076124,183.1983,-9.3931513
62.4,0.7441566,-0.13435254,46.109619,0,11.076097,187.11557,-0.0089181568,9.5674753,11.076451,186.78546,-9.3909016
63.6,0.73958248,-0.13736823,46.576683,0,11.076097,190.71558,-0.0091011422,9.5063047,11.076247,190.1927,-9.3885355
64.8,0.74136275,-0.14079192,46.582027,0,11.076097,194.31558,-0.0093265781,9.5252438,11.075336,193.7408,-9.3860006
66.0,0.74410641,-0.14445046,47.05444,0,11.076097,197.91557,-0.0095611177,9.5684156,11.075808,197.32054,-9.3840265
67.2,0.73184729,-0.14852661,47.05534,0,11.076097,201.51556,-0.0098001119,9.4035263,11.075954,201.02902,-9.3818617
68.4,0.74210322,-0.15121254,47.235493,0,11.076097,205.11559,-0.010069652,9.5448942,11.076022,204.70049,-9.3798532
69.6,0.73769742,-0.15519938,47.504883,0,11.076097,208.71558,-0.010266809,9.4946365,11.076064,208.26294,-9.3777227
70.8,0.74549466,-0.15820435,47.60817,0,11.076097,212.31558,-0.01053321,9.6019373,11.075625,211.85898,-9.375598
72.0,0.7302283,-0.16239639,47.768383,0,11.076097,215.91557,-0.010804974,9.4013548,11.075988,215.51466,-9.3728752
73.2,0.74155641,-0.16602117,47.955318,0,11.076097,219.51556,-0.011017494,9.5425596,11.07616,219.10886,-9.3708944
74.4,0.74619365,-0.16932076,48.072952,0,11.076097,223.11557,-0.011207086,9.5939865,11.076296,222.73415,-9.3687992
75.6,0.74786252,-0.17360079,48.382462,0,11.076097,226.71556,-0.011482134,9.6252089,11.075477,226.28288,-9.3665667
76.8,0.75424486,-0.17828989,48.477875,0,11.076097,230.31557,-0.011798843,9.7199945,11.075665,229.83629,-9.3644428
78.0,0.75618857,-0.1816456,48.812153,0,11.076097,233.91556,-0.01198214,9.7463493,11.075626,233.41415,-9.3627272
79.2,0.75415558,-0.18412068,48.812252,0,11.076097,237.51556,-0.012247187,9.7192211,11.076329,237.14894,-9.3602314
80.4,0.75911319,-0.18745472,48.81226,0,11.076097,241.11557,-0.012443557,9.7886744,11.076161,240.83313,-9.3584929
81.6,0.76062167,-0.19094129,48.910366,0,11.076097,244.71556,-0.012673487,9.8191481,11.076264,244.50485,-9.3561764
82.8,0.75832605,-0.19458444,48.940876,0,11.076097,248.31555,-0.012871539,9.7929134,11.075439,248.13663,-9.3536253
84.0,0.76299924,-0.19824305,49.229458,0,11.076097,251.91556,-0.013104415,9.8556738,11.075606,251.71649,-9.3516884
85.2,0.75759381,-0.20137395,49.218937,0,11.076097,255.51556,-0.013335145,9.7817907,11.076219,255.38034,-9.3493938
86.4,0.75729722,-0.20502384,49.214222,0,11.076097,259.11581,-0.013548804,9.7916975,11.076509,259.00409,-9.3474579
87.6,0.76585311,-0.20844784,49.229637,0,11.076097,262.71555,-0.01384892,9.8940239,11.076314,262.56558,-9.3452578
88.8,0.76335615,-0.21240929,49.229733,0,11.076097,266.31555,-0.014101116,9.8604012,11.07624,266.11868,-9.3433533
90.0,0.77047211,-0.21649998,49.636227,0,11.076097,269.91553,-0.014338256,9.9662247,11.075837,269.62231,-9.3414726
91.2,0.76710397,-0.22021161,49.636227,0,11.076097,273.51553,-0.014559159,9.9054041,11.075861,273.20624,-9.3395147
92.4,0.76595712,-0.22405903,49.707489,0,11.076097,277.11554,-0.014787452,9.9106693,11.075665,276.759,-9.3373032
93.6,0.76575494,-0.22799225,50.042721,0,11.076097,280.71555,-0.015133965,9.892827,11.076603,280.26236,-9.3353682
94.8,0.76491767,-0.23137,50.140198,0,11.076097,284.31555,-0.015334517,9.8855801,11.07607,283.88019,-9.3332224
96.0,0.76326251,-0.23518178,50.438229,0,11.076097,287.91556,-0.015559424,9.8574524,11.075632,287.41287,-9.3309908
97.2,0.76748794,-0.23891355,50.571625,0,11.076097,291.51556,-0.015786886,9.9330254,11.076018,291.0033,-9.3286819
98.4,0.77048284,-0.24283378,50.82275,0,11.076097,295.11557,-0.01602282,9.9664364,11.076151,294.54324,-9.3263302
99.6,0.77388626,-0.24626213,50.981987,0,11.076097,298.71558,-0.016331,10.011147,11.076138,298.18994,-9.3242884
100.8,0.77427584,-0.24976146,51.196285,0,11.076097,302.31555,-0.016535336,10.018918,11.076106,301.73975,-9.3222876
102.0,0.76949251,-0.25299048,51.555202,0,11.076097,305.91556,-0.016746275,9.9698057,11.075639,305.29251,-9.3195553
103.2,0.76551753,-0.25663128,51.56982,0,11.076097,309.51556,-0.016937496,9.9258442,11.075477,308.97018,-9.3177776
104.4,0.77090663,-0.26103339,51.833805,0,11.076097,313.11557,-0.017197607,9.9907351,11.075379,312.59906,-9.315896
105.6,0.76566756,-0.26502633,51.931366,0,11.076097,316.71558,-0.017555406,9.9274082,11.076072,316.35101,-9.3140574
106.8,0.76588804,-0.26933664,51.932369,0,11.076097,320.31552,-0.017831912,9.9360971,11.07568,319.97687,-9.3119698
108.0,0.76106977,-0.27352607,51.932369,0,11.076097,323.91556,-0.018070327,9.8603249,11.0767,323.64938,-9.3099585
109.2,0.75189388,-0.27746657,52.066311,0,11.076097,327.51556,-0.018300211,9.752799,11.07605,327.20084,-9.3076706
110.4,0.74718791,-0.28161457,52.245018,0,11.076097,331.11554,-0.018567203,9.6852694,11.075846,330.84879,-9.3055725
111.6,0.7696358,-0.28497812,52.076992,0,11.076097,334.71555,-0.018837811,9.981205,11.075858,334.62961,-9.303504
112.8,0.78235292,-0.2900598,51.932377,0,11.076097,338.31555,-0.01915165,10.156723,11.076478,338.37952,-9.3013802
114.0,0.76892591,-0.29195523,51.932377,0,11.076097,341.91556,-0.01923771,9.9832792,11.076495,341.86722,-9.2995405
115.2,0.77498275,-0.29492158,51.932377,0,11.076097,345.5155,-0.019508546,10.064462,11.076324,345.49121,-9.2974062
116.4,0.76282293,-0.2993679,51.932377,0,11.076097,349.11551,-0.019799039,9.9036884,11.07671,349.1431,-9.295207
117.6,0.7572608,-0.30339929,52.175785,0,11.076097,352.71552,-0.02001575,9.8510151,11.075606,352.59467,-9.2932615
118.8,0.76863492,-0.30639747,52.283913,0,11.076097,356.31552,-0.020205757,9.9844007,11.075851,356.07736,-9.2909288
120.0,0.78436476,-0.3124209,52.546654,0,11.076097,359.91553,-0.020605957,10.179404,11.076387,359.50195,-9.2890224
121.2,0.7751658,-0.31404668,52.635494,0,11.076097,363.5155,-0.020749191,10.094653,11.075975,363.02069,-9.2869291
122.4,0.7678591,-0.31899208,52.976013,0,11.076097,367.11551,-0.021019878,9.9827814,11.075895,366.59848,-9.2848177
123.6,0.76414567,-0.32360041,52.97607,0,11.076097,370.71552,-0.021278344,9.9421091,11.075801,370.20645,-9.2829819
124.8,0.77659851,-0.32845473,53.309929,0,11.076097,374.31552,-0.021691296,10.106257,11.076451,373.85538,-9.2804146
126.0,0.78363812,-0.33155793,53.307625,0,11.076097,377.9155,-0.021878218,10.201456,11.07585,377.58102,-9.2784567
127.2,0.77395868,-0.33571893,53.163101,0,11.076097,381.51553,-0.022095291,10.088401,11.075566,381.3916,-9.2759361
128.4,0.7644915,-0.33982751,53.087833,0,11.076097,385.11551,-0.022440875,9.965497,11.076141,385.03482,-9.274332
129.6,0.76605219,-0.34400189,53.283821,0,11.076097,388.71555,-0.022713138,9.9701548,11.075559,388.65717,-9.2723827
130.8,0.77725381,-0.35062951,53.31665,0,11.076097,392.31552,-0.023104684,10.125971,11.07671,392.17453,-9.2701254
132.0,0.77947152,-0.35137737,53.31665,0,11.076097,395.91556,-0.023187051,10.155145,11.075881,395.81418,-9.2681637
133.2,0.76951796,-0.35657832,53.526375,0,11.076097,399.51553,-0.023513572,10.026549,11.075986,399.18607,-9.2663174
134.4,0.75995177,-0.36166489,53.657223,0,11.076097,403.11557,-0.023815786,9.912199,11.075532,402.70346,-9.2639742
135.6,0.78511649,-0.36647999,53.889996,0,11.076097,406.71555,-0.024113912,10.241653,11.076214,406.22232,-9.2624502
136.8,0.78414232,-0.36929908,53.975826,0,11.076097,410.31555,-0.024313558,10.23742,11.075921,409.75201,-9.2601585
138.0,0.75645292,-0.37489989,54.204479,0,11.076097,413.91556,-0.02468764,9.8884449,11.075834,413.4111,-9.2570791
139.2,0.75464958,-0.37979627,54.305416,0,11.076097,417.51556,-0.024984237,9.8664322,11.076072,417.00562,-9.2541389
140.4,0.78680748,-0.38638139,54.327885,0,11.076097,421.11554,-0.025416233,10.283011,11.076618,420.7265,-9.2521391
141.6,0.77862287,-0.38781896,54.330936,0,11.076097,424.71555,-0.025521217,10.178775,11.076726,424.40887,-9.2504072
142.8,0.77307236,-0.39355493,54.517818,0,11.076097,428.31552,-0.025880285,10.123278,11.075865,428.08145,-9.2489681
144.0,0.77371532,-0.39772439,54.623211,0,11.076097,431.91553,-0.026168605,10.106804,11.075595,431.70398,-9.2463408
145.2,0.79101914,-0.40301287,54.511635,0,11.076097,435.5155,-0.026516961,10.334384,11.076012,435.45255,-9.2444286
146.4,0.77232707,-0.40732238,54.456673,0,11.076097,439.11548,-0.026785085,10.105259,11.07564,439.10306,-9.242197
147.6,0.76809263,-0.41282594,54.311344,0,11.076097,442.71552,-0.027159886,10.056649,11.075816,442.74423,-9.2404499
148.8,0.78758454,-0.41924834,54.612782,0,11.076097,446.31549,-0.027562432,10.307642,11.076479,446.26593,-9.2382488
150.0,0.78429937,-0.42058405,54.510906,0,11.076097,449.91553,-0.027678816,10.257985,11.07616,449.92346,-9.2366219
151.2,0.77809131,-0.42611742,54.618153,0,11.076097,453.51547,-0.028048612,10.20198,11.076388,453.45157,-9.2346783
152.4,0.77740657,-0.43001115,54.56102,0,11.076097,457.11551,-0.028249247,10.169435,11.075349,457.1026,-9.2320795
153.6,0.7954368,-0.43421534,54.624023,0,11.076097,460.71548,-0.0285827,10.433999,11.076213,460.59326,-9.2302847
154.8,0.77651513,-0.43938598,54.772106,0,11.076097,464.31549,-0.028881688,10.166297,11.075718,463.98944,-9.2283726
156.0,0.77183557,-0.44500041,54.931637,0,11.076097,467.9155,-0.029212076,10.125588,11.075642,467.59085,-9.2264643
157.2,0.79764682,-0.45033154,54.931637,0,11.076097,471.5155,-0.029646803,10.456666,11.075548,471.23795,-9.2246656
158.4,0.78444099,-0.45377734,54.931782,0,11.076097,475.11548,-0.029788686,10.295111,11.07571,474.92194,-9.2224054
159.6,0.77079523,-0.46009451,54.931644,0,11.076097,478.71552,-0.030153058,10.125832,11.074969,478.55203,-9.2202559
160.8,0.7931006,-0.46613401,55.085358,0,11.076097,482.31549,-0.030623429,10.393641,11.076382,482.10846,-9.2180471
162.0,0.78856063,-0.46799567,55.138767,0,11.076097,485.91553,-0.030697726,10.366586,11.076081,485.81079,-9.2163105
163.2,0.78443927,-0.47430831,55.23875,0,11.076097,489.5155,-0.031104801,10.305961,11.076359,489.33173,-9.2144203
164.4,0.76792526,-0.4788042,55.239254,0,11.076097,493.11554,-0.031444095,10.08383,11.07671,492.98703,-9.212121
165.6,0.79587382,-0.48555374,55.006386,0,11.076097,496.71552,-0.031870652,10.458746,11.07657,496.77148,-9.2100878
166.8,0.79013801,-0.48801717,54.937202,0,11.076097,499.99759,-0.032050472,10.398944,11.075732,500.3205,-9.2078228
168.0,0.10280056,-0.49918118,53.658081,0,11.076097,499.99884,-0.032708745,1.3536412,11.07599,501.66528,-9.2082939
169.2,0.095367886,-0.49629363,53.316654,0,11.076097,499.99884,-0.032598112,1.2485982,11.076083,501.52063,-9.2081757
170.4,0.10286572,-0.49581933,53.147213,0,11.076097,499.99884,-0.032521114,1.3634218,11.076674,501.10101,-9.2079735
171.6,0.092999704,-0.49452329,53.316387,0,11.076097,499.99884,-0.032376628,1.2282711,11.076347,500.52832,-9.2082529
172.8,0.089780875,-0.49399605,53.656845,0,11.076097,499.99884,-0.032418985,1.1719453,11.075711,499.92773,-9.2083902
174.0,0.088372447,-0.49320564,54.180264,0,11.076097,499.99884,-0.032340847,1.160596,11.077131,499.32129,-9.2079992
175.2,0.10964625,-0.49459833,54.624023,0,11.076097,499.99884,-0.032460343,1.4468275,11.075369,498.97675,-9.2081404
176.4,0.10734751,-0.49382421,55.227131,0,11.076097,499.99884,-0.032377236,1.4161177,11.075885,498.70917,-9.2082891
177.6,0.1101343,-0.49422759,55.239262,0,11.076097,499.99884,-0.032459803,1.4511379,11.076086,498.9212,-9.2082853
178.8,0.11092646,-0.49510637,55.535404,0,11.076097,499.99884,-0.03247489,1.4433345,11.075695,499.16617,-9.2082348
180.0,0.13100883,-0.49799562,55.535789,0,11.076097,499.99884,-0.032619081,1.7203745,11.075659,499.47766,-9.208478
181.2,0.12138425,-0.49666354,55.239525,0,11.076097,499.99884,-0.032592483,1.5974083,11.076479,499.90881,-9.2085371
182.4,0.11543027,-0.49835411,54.954487,0,11.076097,499.99884,-0.032687426,1.5269781,11.076175,500.20135,-9.2082939
183.6,0.11012138,-0.49947011,54.7519,0,11.076097,499.99884,-0.032787818,1.4585862,11.076164,500.54761,-9.2082319
184.8,0.13059382,-0.50180715,54.31736,0,11.076097,499.99884,-0.032875694,1.7076541,11.076109,500.79889,-9.20821
186.0,0.12919368,-0.49968201,54.222179,0,11.076097,499.99884,-0.032798007,1.7111626,11.075756,500.81003,-9.2080269
187.2,0.11260769,-0.50104403,53.727432,0,11.076097,499.99884,-0.03283583,1.4867623,11.075636,500.95941,-9.2078495
188.4,0.1170003,-0.50139272,53.65723,0,11.076097,499.99884,-0.032870684,1.5409036,11.076656,500.82358,-9.2082138
189.6,0.12492087,-0.50181746,53.316654,0,11.076097,499.99884,-0.032889999,1.6549058,11.076333,500.67758,-9.2081432
190.8,0.1320792,-0.50174707,53.316654,0,11.076097,499.99884,-0.032951124,1.7357785,11.076182,500.49063,-9.2082338
192.0,0.12306259,-0.50182563,53.316681,0,11.076097,499.99884,-0.032893635,1.6333292,11.076332,500.23123,-9.2080975
193.2,0.11602699,-0.50290245,53.317123,0,11.076097,499.99884,-0.032940798,1.53997,11.075194,500.20703,-9.2081118
194.4,0.11846189,-0.50373304,53.513493,0,11.076097,499.99884,-0.033020191,1.5658305,11.07634,500.01544,-9.2080507
195.6,0.13004039,-0.50464261,53.657223,0,11.076097,499.99884,-0.033123031,1.7059047,11.076086,499.87405,-9.2082024
196.8,0.13809946,-0.50542516,53.657223,0,11.076097,499.99884,-0.033158541,1.8262408,11.075824,499.91721,-9.2079344
198.0,0.12892047,-0.50516111,53.657223,0,11.076097,499.99884,-0.033068683,1.7084757,11.076647,499.94043,-9.2078981
199.2,0.12588635,-0.50605667,53.657223,0,11.076097,499.99884,-0.033185743,1.6689297,11.076184,500.05679,-9.207922
200.4,0.1246975,-0.50699031,53.514698,0,11.076097,499.99884,-0.033280645,1.6443597,11.076239,500.11188,-9.2080364
201.6,0.12012056,-0.50765729,53.316654,0,11.076097,499.99884,-0.033299346,1.5932407,11.075643,500.38452,-9.2074518
202.8,0.12469059,-0.50864857,52.976078,0,11.076097,499.99884,-0.033296868,1.6421794,11.075731,500.53232,-9.2079268
204.0,0.11593739,-0.50887042,52.638668,0,11.076097,499.99884,-0.033352774,1.5200171,11.076587,500.56354,-9.2077951
205.2,0.12011126,-0.50837761,52.635933,0,11.076097,499.99884,-0.033365872,1.5772066,11.077168,500.39276,-9.207736
206.4,0.14328426,-0.50964111,52.719048,0,11.076097,499.99884,-0.033413623,1.8808675,11.076676,500.10886,-9.2081194
207.6,0.1413921,-0.51113826,52.976059,0,11.076097,499.99884,-0.033463098,1.8569477,11.07518,499.92654,-9.2075424
208.8,0.14336219,-0.51120281,52.97607,0,11.076097,499.99884,-0.03351745,1.8948231,11.07548,499.87949,-9.2078075
210.0,0.13556181,-0.51034713,53.154324,0,11.076097,499.99884,-0.033497259,1.7889919,11.075769,499.73672,-9.2076921
211.2,0.13418505,-0.51036048,53.31665,0,11.076097,499.99884,-0.033438034,1.7743984,11.076063,499.71268,-9.207696
211.9477,0.19195224,0.082330041,50.11758,0,11.076099,0.0066778664,0.0055094813,2.5015128,11.076959,499.54672,-9.2086029
211.9501,0.18173203,0.083454877,37.321583,0,11.076099,2.8868396999999997e-19,0.0054268423,2.3429732,11.076294,499.53958,-9.208107
211.9525,0.23276199,0.081602313,24.525583,0,11.076099,1.2479803e-35,0.0054000579,2.976923,11.075356,499.53241,-9.2083559
211.9549,0.18981054,0.086641803,11.729589,0,11.076099,0.0,0.0057938937,2.3469682,11.07696,499.52524,-9.2087746
211.9573,0.2097066,0.082010381,0.0,0,11.076099,0.0,0.0056481496,2.5901144,11.073637,499.51151,-9.2081232
211.9597,0.20167108,0.082082704,0.0,0,11.076099,0.0,0.0056311619,2.5682511,11.07608,499.42557,-9.2074566
211.9621,0.18239775,0.083648883,0.0,0,11.076099,0.0,0.0056581795,2.3869128,11.075885,499.3396,-9.2086344
211.9645,0.1849874,0.087773152,0.0,0,11.076099,0.0,0.0056634545,2.371526,11.078917,499.25363,-9.2084131
211.9669,0.2017976,0.089345589,0.0,0,11.076099,0.0,0.0057292688,2.5455174,11.078256,499.16769,-9.2093229
211.9693,0.20484735,0.087254867,0.0,0,11.076099,0.0,0.0058158445,2.5003304,11.075227,499.16052,-9.2073479
211.9717,0.19441698,0.083652951,0.0,0,11.076099,0.0,0.005848737,2.5756629,11.07585,499.16052,-9.2075329
211.9741,0.190338,0.082224019,0.0,0,11.076099,0.0,0.005738643,2.5092583,11.0753,499.16052,-9.2095976
211.9765,0.20035936,0.082414709,0.0,0,11.076099,0.0,0.0054982607,2.5069504,11.076603,499.16052,-9.2089539
211.9789,0.20860086,0.082696393,0.0,0,11.076099,0.0,0.0053641396,2.6113684,11.074294,499.19812,-9.2088337
211.9813,0.20526004,0.084005676,0.0,0,11.076099,0.0,0.0054764869,2.6224368,11.075981,499.24826,-9.207736
211.9837,0.19616665,0.086648479,0.0,0,11.076099,0.0,0.0057256096,2.4331512,11.07435,499.2984,-9.2087021
211.9861,0.20492749,0.084656306,0.0,0,11.076099,0.0,0.0057605789,2.6366341,11.076574,499.34854,-9.2066994
211.9885,0.20793557,0.082635298,0.0,0,11.076099,0.0,0.005723848,2.5938723,11.077193,499.39035,-9.2072344
211.9909,0.21417813,0.083777606,0.0,0,11.076099,0.0,0.005683464,2.6951995,11.074137,499.42615,-9.2066422
211.9933,0.21826223,0.088307858,0.0,0,11.076099,0.0,0.0057173246,2.7166653,11.074821,499.46198,-9.206934
211.9957,0.20481268,0.092120528,0.0,0,11.076099,0.0,0.0058517819,2.596488,11.077008,499.49777,-9.2071295
211.9981,0.20380628,0.090150885,0.0,0,10.916306,0.0,0.0058976389,2.5640857,11.076294,499.50974,-9.2066517
212.0005,0.2273244,0.088943087,0.0,0,10.555332,0.0,0.0060694437,2.8089044,11.076744,499.48822,-9.2077913
212.0029,0.23895569,0.085137568,0.0,0,10.194359,0.0,0.0059591015,2.9386923,11.046735,499.46674,-9.2081642
212.0053,0.21000484,0.083987378,0.0,0,9.8333845,0.0,0.0057503982,2.705996,10.889957,499.44525,-9.2076778
212.0077,0.23000546,0.086523704,0.0,0,9.4727468,0.0,0.0056694429,2.8400908,10.589211,499.60999,-9.2083769
212.0101,0.19383211,0.087131739,0.0,0,9.1214981,0.0,0.0057301372,2.5786405,10.180746,500.33337,-9.208828
212.0125,4.764317,0.61606091,0.0,0,8.7703295,0.0,0.040981539,58.153465,9.6490374,501.05676,-9.2053814
212.0149,5.2419529,1.0717932,0.0,0,8.4353609,0.0,0.073335342,62.289967,9.1378469,501.78015,-9.2024746
212.0173,4.9852657,1.4789712,0.0,0,8.1013775,0.0,0.10374139,56.799969,8.6866627,502.50174,-9.2036495
212.0197,5.1550612,1.8349576,0.0,0,7.7813349,0.0,0.13025635,57.643852,8.3211689,503.20364,-9.2042732
212.0221,5.181375,2.137814,0.0,0,7.4635754,0.0,0.15322958,56.692913,8.0186186,503.90555,-9.203949
212.0245,5.3854914,2.3987231,0.0,0,7.1578832,0.0,0.17345303,57.709251,7.74471,504.60745,-9.2025995
212.0269,5.3833985,2.6612828,0.0,0,6.8556757,0.0,0.19475476,56.336819,7.4755731,505.30936,-9.2030296
212.0293,5.5673504,2.9217808,0.0,0,6.5636415,0.0,0.21633567,57.15411,7.2101612,506.03067,-9.2034101
212.0317,5.7122197,3.2002003,0.0,0,6.2761216,0.0,0.23993096,57.110676,6.929409,506.75372,-9.204484
212.0341,5.8821263,3.4827929,0.0,0,5.9971714,0.0,0.26400763,57.529049,6.6433663,507.47681,-9.2027607
212.0365,6.0073795,3.7811334,0.0,0,5.7237153,0.0,0.28987545,57.223824,6.3465695,508.19986,-9.2018957
212.0389,6.1482377,4.0791435,0.0,0,5.457253,0.0,0.31655434,57.062088,6.0448799,507.97772,-9.2019196
212.0413,6.3226824,4.3699732,0.0,0,5.1970935,0.0,0.34367943,57.062389,5.7501974,507.44055,-9.2029228
212.0437,6.4641747,4.6533599,0.0,0,4.9425635,0.0,0.37103236,56.813263,5.4629369,506.90338,-9.2037077
212.0461,6.5827727,4.9284139,0.0,0,4.6951237,0.0,0.39827272,56.244102,5.1845169,506.36621,-9.2035589
212.0485,6.7176394,5.1968241,0.0,0,4.4520135,0.0,0.4252412,55.881454,4.9183483,505.96701,-9.2034607
212.0509,6.8511376,5.4531555,0.0,0,4.2166214,0.0,0.45134476,55.519844,4.658668,505.66632,-9.2035265
212.0533,7.0159941,5.7052855,0.0,0,3.9844091,0.0,0.47767046,55.432259,4.4112077,505.36566,-9.2044144
212.0557,7.1802464,5.9465065,0.0,0,3.7605371,0.0,0.5039416,55.1908,4.1760912,505.06497,-9.2033443
212.0581,7.334198,6.1756325,0.0,0,3.5387647,0.0,0.53004062,54.940594,3.9387896,504.75827,-9.2041388
212.0605,7.5117588,6.3983431,0.0,0,3.3257885,0.0,0.55619824,54.830288,3.7099674,504.44312,-9.2033663
212.0629,7.7254677,6.621027,0.0,0,3.1139498,0.0,0.58243293,54.931232,3.4873445,504.12796,-9.202693
212.0653,7.9697599,6.8389201,0.0,0,2.9113381,0.0,0.60818237,55.158405,3.2724891,503.81277,-9.2025566
212.0677,8.1601095,7.0573025,0.0,0,2.7090681,0.0,0.63475919,55.11565,3.059443,503.11984,-9.2024574
212.0701,8.3977709,7.271503,0.0,0,2.5162671,0.0,0.66216004,55.161781,2.8483396,501.29361,-9.2019196
212.0725,8.6601391,7.4750748,0.0,0,2.3235471,0.0,0.68932825,55.260612,2.6418381,499.46738,-9.200017
212.0749,8.9358644,7.6701326,0.0,0,2.1396961,0.0,0.7161715,55.542995,2.442081,497.64114,-9.2005377
212.0773,9.2500315,7.8622351,0.0,0,1.9563839,0.0,0.74279904,55.974838,2.2459025,495.51102,-9.2019997
212.0797,9.5184498,8.0546312,0.0,0,1.7807442,0.0,0.76961267,56.112614,2.0546987,490.03836,-9.2015352
212.0821,9.8470984,8.2486258,0.0,0,1.6063603,0.0,0.79705876,56.423538,1.8704709,484.5657,-9.2000675
212.0845,10.199133,8.4363899,0.0,0,1.4385692,0.0,0.82510585,56.83934,1.6853698,479.09308,-9.1995773
212.0869,10.577381,8.6102495,0.0,0,1.2726812,0.0,0.8526479,57.352783,1.5093269,473.62042,-9.200202
212.0893,10.956311,8.7765808,0.0,0,1.1124123,0.0,0.88003385,57.820515,1.3392793,469.8187,-9.2003746
212.0917,11.376956,8.9380636,0.0,0,0.95463622,0.0,0.90666753,58.466957,1.1708558,466.16888,-9.2003574
212.0941,11.799471,9.1003084,0.0,0,0.80156928,0.0,0.9329378,59.087952,1.0031189,462.51904,-9.1991978
212.0965,12.292312,9.259881,0.0,0,0.65152127,0.0,0.95947719,59.900349,0.84270984,458.86923,-9.1982422
212.0989,12.804597,9.4169493,0.0,0,0.5052858,0.0,0.98701221,60.692101,0.69159985,458.61957,-9.1989775
212.1013,12.505018,9.5604944,0.0,0,0.36248577,0.0,1.0136958,58.530807,0.54147053,459.50327,-9.1996946
212.1037,10.153152,9.5775366,0.0,0,0.22278805,0.0,1.018379,46.947975,0.46768695,460.38696,-9.2018385
212.1061,9.2874832,9.5807571,0.0,0,0.086996041,0.0,1.0192763,42.718632,0.4185676,461.27066,-9.2026405
212.1085,8.7893953,9.5860453,0.0,0,-0.047588516,0.0,1.0194496,40.391727,0.38199151,462.76874,-9.2027445
212.1109,8.4898014,9.5920944,0.0,0,-0.18002053,0.0,1.0194954,39.027943,0.35151935,464.70569,-9.2037716
212.1133,8.4982576,9.599514,0.0,0,-0.31245255,0.0,1.0200058,38.981853,0.31756219,466.64264,-9.2045908
212.1157,8.7625837,9.6051178,0.0,0,-0.44488451,0.0,1.0218643,40.135876,0.25303352,468.57959,-9.2032719
212.1181,8.9285851,9.6067848,0.0,0,-0.57731652,0.0,1.0236039,40.846455,0.18422659,471.2067,-9.2034397
212.1205,8.9305744,9.6082497,0.0,0,-0.70974851,0.0,1.0245777,40.782528,0.11870176,474.80002,-9.2034893
212.1229,8.7977085,9.6137094,0.0,0,-0.84218049,0.0,1.0247468,40.204441,0.064636752,478.39334,-9.2041216
212.1253,8.5691929,9.6187277,0.0,0,-0.97461247,0.0,1.0247378,39.161339,0.02623504,481.98666,-9.2042398
212.1277,8.2255077,9.6253853,1.6479863,0,-1.0959824,239.06335,1.0253671,37.590263,0.0019743184,485.20477,-9.2033758
212.1301,7.792614,9.6283178,8.2397833,0,-0.65229225,500.0,1.0263948,35.592754,-0.006271923,487.2973,-9.2034702
212.1325,7.4058218,9.6251516,14.83158,0,-0.19380596,500.0,1.0266782,33.760559,0.00040320266,489.3898,-9.2036324
212.1349,7.0888834,9.6214409,21.423376,0,0.26468039,500.0,1.0267887,32.335403,0.0020214203,491.48233,-9.2049885
212.1373,6.8438258,9.6213608,27.46582,0,0.72316676,500.0,1.0262939,31.243885,0.00440954,493.52521,-9.2050524
212.1397,6.6585102,9.6260977,27.46582,0,1.1816531,500.0,1.0259438,30.397865,0.0054037715,495.02225,-9.2050819
212.1421,6.1757412,9.624671,27.46582,0,1.6401393,500.0,1.0250731,28.289761,0.021226974,496.51926,-9.2045012
212.1445,4.7481647,9.6224241,27.46582,0,2.0986257,500.0,1.0250524,21.849569,0.10745644,498.0163,-9.2060003
212.1469,2.5217316,9.6097202,27.46582,0,2.5571125,500.0,1.0238395,11.725106,0.25820342,499.51331,-9.2088346
212.1493,0.073021807,9.5777864,21.423302,0,3.015599,500.0,1.0190639,0.51875949,0.49712023,500.52444,-9.2102432
212.1517,-0.17427656,9.5249109,14.831507,0,3.4740856,500.0,1.0087731,-0.7074185,1.0001264,501.49136,-9.2099895
212.1541,0.0086552082,9.5021811,8.2397089,0,3.9325716,500.0,1.0036926,-0.087173678,1.740752,502.45831,-9.2103033
212.1565,0.072433412,9.4969263,1.6479124,0,4.391058,500.0,1.0018123,0.32362422,2.5262973,503.42526,-9.2097397
212.1589,0.10120419,9.5134459,0.0,0,4.8495445,500.0,1.0049967,0.44129854,3.194,504.16644,-9.2100716
212.1613,-0.098643132,9.539588,0.0,0,5.3080311,500.0,1.0106758,-0.39351892,3.6787775,504.83237,-9.209033
212.1637,0.10860232,9.5651684,0.0,0,5.7665176,500.0,1.0162498,0.41014165,4.1048846,505.49832,-9.2099571
212.1661,0.05395937,9.568553,0.0,0,6.2250037,500.0,1.0166874,0.30772024,4.5235858,506.16425,-9.2076006
212.1685,0.0018358021,9.5738726,0.0,0,6.6834898,500.0,1.0166918,-0.034007572,4.9424753,506.71317,-9.2095785
212.1709,0.014997794,9.5778141,0.0,0,7.1419768,500.0,1.0165657,0.039904401,5.385076,507.1785,-9.2083282
212.1733,0.13654624,9.5790987,0.0,0,7.6004629,500.0,1.0166293,0.60646713,5.8561907,507.64383,-9.2086954
212.1757,-0.030899836,9.5805492,0.0,0,8.0589485,500.0,1.0179175,-0.060914177,6.3356695,508.10916,-9.2077456
212.1781,0.022806592,9.5746298,0.0,0,8.5174351,500.0,1.0180199,0.091035336,6.8249574,508.44028,-9.2081366
212.1805,0.06622687,9.5720196,0.0,0,8.9759216,500.0,1.0175872,0.35116342,7.3130388,508.58344,-9.2068777
212.1829,-0.090850554,9.5754089,0.0,0,9.4344082,500.0,1.0171139,-0.42540297,7.7799487,508.72662,-9.2060394
212.1853,0.11470085,9.5722151,0.0,0,9.8928947,500.0,1.0156062,0.4960503,8.2507267,508.86978,-9.2063656
212.1877,0.049263436,9.5719862,0.0,0,10.351381,500.0,1.0158337,0.34378901,8.7196398,509.00043,-9.2057323
212.1901,-0.060419872,9.573802,0.0,0,10.809868,500.0,1.0169044,-0.29161096,9.18505,509.09351,-9.2066078
212.1925,0.11668061,9.5713549,0.0,0,11.268353,500.0,1.0173008,0.43676022,9.6662331,509.18655,-9.2074566
212.1949,0.085926935,9.5683651,0.0,0,11.72684,500.0,1.0167896,0.53432912,10.14634,509.27963,-9.2069902
212.1973,-0.1101304,9.5723028,0.0,0,12.185327,500.0,1.0169407,-0.48965418,10.621359,509.38043,-9.2069445
212.1997,0.10765178,9.5719833,0.0,0,12.643813,500.0,1.0155126,0.5385645,11.093928,509.56659,-9.2065096
212.2021,0.022585411,9.5753117,0.0,0,13.1023,500.0,1.0156192,0.13363473,11.558212,509.75272,-9.2061977
212.2045,-0.00052313821,9.5773849,0.0,0,13.560786,500.0,1.0169851,-0.049265329,12.01413,509.93884,-9.2043867
212.2069,0.10234302,9.5719204,0.0,0,14.019273,500.0,1.0172414,0.44622204,12.473614,510.125,-9.2053213
212.2093,-0.0010324038,9.5662985,0.0,0,14.477758,500.0,1.0166466,0.06939207,12.933434,510.38333,-9.2042475
212.2117,0.0060619176,9.5707378,0.0,0,14.936245,500.0,1.0165352,-0.048394687,13.401927,510.64819,-9.2068777
212.2141,0.089210548,9.5719585,0.0,0,15.394732,500.0,1.0159183,0.40814444,13.879981,510.91309,-9.2057114
212.2165,0.016517105,9.5737333,0.0,0,15.853217,500.0,1.0158161,0.1096475,14.363115,511.17798,-9.2045813
212.2189,0.013016819,9.5753784,0.0,0,16.311705,500.0,1.016789,0.052292541,14.83411,511.48044,-9.2050152
212.2213,0.096962221,9.5717859,0.0,0,16.770191,500.0,1.0169926,0.40207991,15.297038,511.79544,-9.2049398
212.2237,0.023112319,9.5664406,0.0,0,17.228678,500.0,1.0166622,0.10032126,15.745076,512.11041,-9.2050047
212.2261,0.00076651119,9.5662661,0.0,0,17.687164,500.0,1.0159323,-0.028082419,16.195339,512.42542,-9.2049398
212.2285,0.085633278,9.5736313,0.0,0,18.0,500.0,1.0160983,0.383138,16.657394,512.72369,-9.2037458
212.2309,0.0072680498,9.5766821,0.0,0,18.0,500.0,1.0159858,0.07053715,17.116385,513.01007,-9.2043591
212.2333,0.0033513617,9.5773726,0.0,0,18.0,500.0,1.0167404,-0.016421944,17.533278,513.29645,-9.2041092
212.2357,0.10979796,9.5743275,0.0,0,18.0,500.0,1.0174206,0.53953189,17.913244,513.58282,-9.2052546
212.2381,0.03987797,9.5710831,0.0,0,18.0,500.0,1.0174817,0.16010284,18.233957,513.82745,-9.2073336
212.2405,0.088440895,9.5701323,0.0,0,18.0,500.0,1.0168583,0.43594226,18.449842,514.01355,-9.2100277
212.2429,0.038035795,9.5800161,0.0,0,18.0,500.0,1.0176418,0.16376752,18.550423,514.19965,-9.2144489
212.2453,0.067114986,9.5903006,0.0,0,18.0,500.0,1.018844,0.4002659,18.518867,514.3858,-9.2243052
212.2477,0.15246516,9.6001616,0.0,0,18.0,500.0,1.0210226,0.62064415,18.389233,514.57013,-9.2344656
212.2501,0.47718093,9.6040611,0.0,0,18.0,500.0,1.0228243,2.1933827,18.243526,514.74908,-9.248105
212.2525,0.24908899,9.5996046,0.0,0,18.0,500.0,1.0227405,1.1541297,18.12676,514.9281,-9.264926
212.2549,0.30692253,9.6015253,0.0,0,18.0,500.0,1.0227334,1.4214828,18.060509,515.10706,-9.2845888
212.2573,0.23777504,9.6047268,0.0,0,18.0,500.0,1.0222851,1.1046422,18.042019,515.28784,-9.3071795
212.2597,0.31466889,9.6081753,0.0,0,18.0,500.0,1.0219005,1.395815,18.042147,515.48828,-9.330102
212.2621,0.28052175,9.6081667,0.0,0,18.0,500.0,1.0220726,1.3166106,18.064896,515.68872,-9.351594
212.2645,0.26932928,9.6049967,0.0,0,18.0,500.0,1.0228134,1.1965538,18.093157,515.88916,-9.3712959
212.2669,0.23820913,9.6022749,0.0,0,18.0,500.0,1.0231146,1.0732096,18.120441,516.0896,-9.3904152
212.2693,0.29286703,9.5976448,0.0,0,18.0,500.0,1.0223147,1.322932,18.139881,516.27039,-9.4102135
212.2717,0.30170742,9.5980968,0.0,0,18.0,500.0,1.0210707,1.371834,18.149708,516.44934,-9.4284248
212.2741,0.30880603,9.6024103,0.0,0,18.0,500.0,1.0210145,1.4198496,18.151632,516.62836,-9.4452972
212.2765,0.27503705,9.6033716,0.0,0,18.0,500.0,1.0214124,1.2766844,18.148525,516.80731,-9.4633055
212.2789,0.27603456,9.6035757,0.0,0,18.0,500.0,1.0223271,1.2778789,18.14904,516.95404,-9.4813089
212.2813,0.31953618,9.6012897,0.0,0,18.0,500.0,1.0228579,1.4523573,18.144997,517.09009,-9.4991808
212.2837,0.32647979,9.5988293,0.0,0,18.0,500.0,1.0224571,1.4964892,18.142136,517.22614,-9.5163736
212.2861,0.2878896,9.6014099,0.0,0,18.0,500.0,1.0219493,1.3062232,18.138126,517.36212,-9.5342855
212.2885,0.29257941,9.6073284,0.0,0,18.0,500.0,1.0220023,1.3533159,18.136299,517.48566,-9.5523338
212.2909,0.30686262,9.6105289,0.0,0,18.0,500.0,1.0223904,1.3833731,18.132809,517.60022,-9.5714102
212.2933,0.33472589,9.6067839,0.0,0,18.0,500.0,1.0227064,1.5141722,18.130585,517.71472,-9.5895805
212.2957,0.32087547,9.6012621,0.0,0,18.0,500.0,1.0228562,1.4823834,18.129351,517.82928,-9.6064243
212.2981,0.29510924,9.5971403,0.0,0,18.0,500.0,1.0222322,1.3485403,18.123032,517.95282,-9.6249619
212.3005,0.29544082,9.599473,0.0,0,18.0,500.0,1.02175,1.3620048,18.119013,518.08881,-9.6436892
212.3029,0.33457041,9.6006899,0.0,0,18.0,500.0,1.0209063,1.5056666,18.116198,518.22485,-9.6621714
212.3053,0.34065029,9.6036472,0.0,0,18.0,500.0,1.0215979,1.5705165,18.114256,518.3609,-9.6788578
212.3077,0.30941734,9.6057196,0.0,0,18.0,500.0,1.0224673,1.417658,18.113049,518.49329,-9.6983175
212.3101,0.29832691,9.5994968,0.0,0,18.0,500.0,1.0223781,1.3572384,18.11396,518.61499,-9.7145443
212.3125,0.31863272,9.5982971,0.0,0,18.0,500.0,1.0223882,1.4523134,18.113119,518.73669,-9.733984
212.3149,0.34726173,9.5982656,0.0,0,18.0,500.0,1.0216994,1.6034884,18.110199,518.8584,-9.7521181
212.3173,0.33616138,9.6032181,0.0,0,18.0,500.0,1.0214666,1.5407715,18.110966,518.9801,-9.7709208
212.3197,0.29455888,9.611413,0.0,0,18.0,500.0,1.0222425,1.3760688,18.113533,519.10181,-9.789463
212.3221,0.29995641,9.6105366,0.0,0,18.0,500.0,1.0229783,1.3484242,18.109386,519.22351,-9.807785
212.3245,0.34231374,9.6049042,0.0,0,18.0,500.0,1.0233333,1.5624382,18.104488,519.34521,-9.8258352
212.3269,0.33813152,9.5992069,0.0,0,18.0,500.0,1.0226588,1.5733385,18.107847,519.46692,-9.8452787
212.3293,0.32187596,9.5989752,0.0,0,18.0,500.0,1.0218911,1.469563,18.10655,519.56238,-9.8615417
212.3317,0.30673447,9.6015053,0.0,0,18.0,500.0,1.021361,1.4271764,18.106403,519.6554,-9.880373
212.3341,0.32412913,9.6036386,0.0,0,18.0,500.0,1.0213555,1.4575943,18.101097,519.74847,-9.8983984
212.3365,0.35401681,9.6022329,0.0,0,18.0,500.0,1.0216522,1.6280527,18.101681,519.84155,-9.9177475
212.3389,0.34457135,9.6009932,0.0,0,18.0,500.0,1.022284,1.5827237,18.10247,519.92383,-9.9356346
212.3413,0.31148869,9.6006527,0.0,0,18.0,500.0,1.0228398,1.4528445,18.098854,520.00256,-9.9536619
212.3437,0.31031302,9.6001177,0.0,0,18.0,500.0,1.0222169,1.4239935,18.096857,520.08124,-9.9700384
212.3461,0.3589443,9.6016684,0.0,0,18.0,500.0,1.0212823,1.6652887,18.09679,520.15997,-9.9879436
212.3485,0.36421046,9.6062031,0.0,0,18.0,500.0,1.0214251,1.6615205,18.098108,520.23865,-10.007099
212.3509,0.33308974,9.6092358,0.0,0,18.0,500.0,1.022401,1.5599258,18.095621,520.31738,-10.026236
212.3533,0.32514739,9.6059942,0.0,0,18.0,500.0,1.0233879,1.5493886,18.095819,520.39612,-10.044512
212.3557,0.35397965,9.5988035,0.0,0,18.0,500.0,1.0226461,1.616323,18.092501,520.47485,-10.062662
212.3581,0.37478623,9.5955658,0.0,0,18.0,500.0,1.0216886,1.7113833,18.092825,520.55951,-10.080356
212.3605,0.37404442,9.5986252,0.0,0,18.0,500.0,1.021085,1.708328,18.094036,520.65253,-10.099669
212.3629,0.34005612,9.6049585,0.0,0,18.0,500.0,1.0214239,1.5801654,18.092812,520.74554,-10.117161
212.3653,0.35215634,9.6052189,0.0,0,18.0,500.0,1.0219411,1.5916555,18.092283,520.83856,-10.136043
212.3677,0.3799783,9.6022215,0.0,0,18.0,500.0,1.0225346,1.7105891,18.091711,520.92798,-10.153464
212.3701,0.3839674,9.6001291,0.0,0,18.0,500.0,1.0228486,1.7383344,18.090679,521.00671,-10.171445
212.3725,0.37498373,9.5989819,0.0,0,18.0,500.0,1.0222929,1.7181507,18.09181,521.08545,-10.189927
212.3749,0.35205802,9.6024027,0.0,0,18.0,500.0,1.0218461,1.5881008,18.087925,521.16418,-10.208202
212.3773,0.37478778,9.6077785,0.0,0,18.0,500.0,1.0219117,1.7134157,18.085499,521.23694,-10.226678
212.3797,0.39782766,9.6078672,0.0,0,18.0,500.0,1.0220851,1.7994915,18.086191,521.24408,-10.242801
212.3821,0.38742241,9.6057405,0.0,0,18.0,500.0,1.0228646,1.758931,18.085085,521.25122,-10.261205
212.3845,0.36170968,9.6020737,0.0,0,18.0,500.0,1.0231816,1.6645284,18.086143,521.25836,-10.281659
212.3869,0.36029795,9.598444,0.0,0,18.0,500.0,1.0224895,1.6339282,18.089348,521.2655,-10.298591
212.3893,0.38131639,9.6001711,0.0,0,18.0,500.0,1.0216836,1.735443,18.080519,521.29236,-10.316772
212.3917,0.3948285,9.6034222,0.0,0,18.0,500.0,1.0214602,1.8069606,18.082346,521.32098,-10.334748
212.3941,0.3777397,9.6052084,0.0,0,18.0,500.0,1.0218682,1.7587981,18.087717,521.34961,-10.354472
212.3965,0.35592526,9.6072226,0.0,0,18.0,500.0,1.0230575,1.6392865,18.088146,521.37823,-10.372671
212.3989,0.37969106,9.6023293,0.0,0,18.0,500.0,1.0229535,1.7148129,18.079641,521.43903,-10.390244
212.4013,0.39134842,9.6006393,0.0,0,18.0,500.0,1.0226578,1.7717187,18.081593,521.51062,-10.410423
212.4037,0.38371405,9.6011753,0.0,0,18.0,500.0,1.0220132,1.8322897,18.080809,521.58221,-10.428703
212.4061,0.36626846,9.6057959,0.0,0,18.0,500.0,1.0217288,1.6944042,18.08246,521.65375,-10.445866
212.4085,0.36056554,9.6089935,0.0,0,18.0,500.0,1.0219138,1.6402383,18.081509,521.70447,-10.464014
212.4109,0.40189296,9.6084585,0.0,0,18.0,500.0,1.0228947,1.831742,18.07881,521.74023,-10.481496
212.4133,0.40697512,9.6040411,0.0,0,18.0,500.0,1.0232733,1.8680496,18.076105,521.776,-10.499819
212.4157,0.39818028,9.5998058,0.0,0,18.0,500.0,1.0226643,1.8022357,18.076769,521.81177,-10.518156
212.4181,0.37304944,9.6007309,0.0,0,18.0,500.0,1.0220321,1.7242535,18.075304,521.83862,-10.536453
212.4205,0.39300838,9.6021185,0.0,0,18.0,500.0,1.0213038,1.7952973,18.075172,521.85291,-10.554456
212.4229,0.41130888,9.6039352,0.0,0,18.0,500.0,1.02152,1.871951,18.073067,521.86725,-10.571412
212.4253,0.40519354,9.6036615,0.0,0,18.0,500.0,1.0219884,1.8832133,18.071775,521.88153,-10.590364
212.4277,0.39033905,9.5999212,0.0,0,18.0,500.0,1.0222862,1.8384115,18.073656,521.90302,-10.609269
212.4301,0.38595185,9.6008539,0.0,0,18.0,500.0,1.022761,1.7717314,18.070498,521.94592,-10.628314
212.4325,0.41828167,9.6019154,0.0,0,18.0,500.0,1.0224293,1.8951491,18.072086,521.98889,-10.645443
212.4349,0.42899522,9.6054077,0.0,0,18.0,500.0,1.0218773,1.9892417,18.068628,522.0318,-10.663055
212.4373,0.41863465,9.6076088,0.0,0,18.0,500.0,1.0216149,1.939267,18.068596,522.07654,-10.681539
212.4397,0.39747033,9.6097336,0.0,0,18.0,500.0,1.0227934,1.8196633,18.070929,522.14093,-10.70042
212.4421,0.39885247,9.60429,0.0,0,18.0,500.0,1.023319,1.8360181,18.071896,522.20532,-10.717719
212.4445,0.43282533,9.6001225,0.0,0,18.0,500.0,1.023104,1.9603654,18.068411,522.26971,-10.735499
212.4469,0.42395103,9.5991039,0.0,0,18.0,500.0,1.0221633,1.9880683,18.066677,522.33411,-10.753742
212.4493,0.41261557,9.6025934,0.0,0,18.0,500.0,1.0215148,1.888453,18.064674,522.35919,-10.771766
212.4517,0.40202844,9.6040459,0.0,0,18.0,500.0,1.0214102,1.8389748,18.066675,522.38062,-10.791231
212.4541,0.42976382,9.6040964,0.0,0,18.0,500.0,1.0219213,1.9575391,18.068541,522.4021,-10.809047
212.4565,0.43853366,9.6006851,0.0,0,18.0,500.0,1.0221802,1.9873079,18.063396,522.42358,-10.82689
212.4589,0.43112564,9.5987167,0.0,0,18.0,500.0,1.0226215,1.9779189,18.06167,522.43433,-10.845064
212.4613,0.39919892,9.5998793,0.0,0,18.0,500.0,1.022234,1.8360983,18.065056,522.44147,-10.863033
212.4637,0.41254228,9.6033592,0.0,0,18.0,500.0,1.0218242,1.8739208,18.060652,522.44861,-10.882679
212.4661,0.43436268,9.6084909,0.0,0,18.0,500.0,1.021836,1.9878769,18.060928,522.45575,-10.900916
212.4685,0.43744683,9.6074915,0.0,0,18.0,500.0,1.0221958,1.9982375,18.060419,522.46289,-10.91798
212.4709,0.42957625,9.6053867,0.0,0,18.0,500.0,1.0229961,1.9875817,18.058764,522.47009,-10.936134
212.4733,0.40474859,9.6007566,0.0,0,18.0,500.0,1.0229887,1.8328837,18.060848,522.47723,-10.955675
212.4757,0.43696463,9.5984955,0.0,0,18.0,500.0,1.0223188,1.9929383,18.060814,522.48444,-10.972795
212.4781,0.43897095,9.59863,0.0,0,18.0,500.0,1.0210631,2.0289567,18.062468,522.49457,-10.989493
212.4805,0.44437319,9.6028137,0.0,0,18.0,500.0,1.0211544,1.9874108,18.058865,522.50885,-11.00827
212.4829,0.41661236,9.603961,0.0,0,18.0,500.0,1.0216011,1.9189736,18.059887,522.52319,-11.027674
212.4853,0.42635119,9.602457,0.0,0,18.0,500.0,1.0223624,1.9415714,18.059372,522.53748,-11.0457
212.4877,0.4489418,9.6004906,0.0,0,18.0,500.0,1.0228865,2.0286343,18.058784,522.55719,-11.063322
212.4901,0.44754401,9.6005144,0.0,0,18.0,500.0,1.0225867,2.0404081,18.056309,522.59296,-11.080888
212.4925,0.44363979,9.6032305,0.0,0,18.0,500.0,1.0220749,2.0241623,18.056717,522.62872,-11.099144
212.4949,0.42402196,9.6067095,0.0,0,18.0,500.0,1.0218198,1.9331634,18.058517,522.66449,-11.118388
212.4973,0.44575986,9.6067123,0.0,0,18.0,500.0,1.0218333,2.014483,18.057739,522.69965,-11.139103
212.4997,0.46620414,9.6061602,0.0,0,18.0,500.0,1.0227875,2.1405313,18.052414,522.72827,-11.155588
212.5021,0.45611405,9.6029282,0.0,0,18.0,500.0,1.0233461,2.0981562,18.057659,522.7569,-11.172444
212.5045,0.44380108,9.6007223,0.0,0,18.0,500.0,1.0229006,2.0241468,18.053717,522.78552,-11.19148
212.5069,0.4523882,9.6007996,0.0,0,18.0,500.0,1.0218742,2.0443375,18.055799,522.81415,-11.208238
212.5093,0.45634639,9.6043968,0.0,0,18.0,500.0,1.0214978,2.1062462,18.054203,522.82312,-11.226557
212.5117,0.4763743,9.604991,0.0,0,18.0,500.0,1.0217447,2.1955383,18.05427,522.83026,-11.244831
212.5141,0.45367545,9.6022558,0.0,0,18.0,500.0,1.0220323,2.0958803,18.051901,522.8374,-11.264253
212.5165,0.43950331,9.5987797,0.0,0,18.0,500.0,1.0222887,2.028758,18.052513,522.8446,-11.281554
212.5189,0.46730202,9.5971069,0.0,0,18.0,500.0,1.0222205,2.1309648,18.055344,522.85712,-11.301395
212.5213,0.45939544,9.6001129,0.0,0,18.0,500.0,1.0217963,2.1155884,18.0536,522.8714,-11.317616
212.5237,0.46922237,9.6049461,0.0,0,18.0,500.0,1.0217018,2.157964,18.050188,522.88574,-11.336772
212.5261,0.45467302,9.6101418,0.0,0,18.0,500.0,1.0220824,2.0869803,18.051533,522.90002,-11.354794
212.9276,0.45423773,9.6071396,0.0,0,18.0,0.0017792438,1.0231349,2.078582,18.011494,512.33221,-11.480414
214.1276,0.51387888,9.6192026,0.0,0,18.0,7.691642999999999e-20,1.0250449,2.3502326,17.999443,497.32391,-11.480698
215.3276,0.52137715,9.6284237,0.0,0,18.0,3.3250839e-36,1.0270337,2.3813231,17.999643,484.67657,-11.480858
216.5276,0.53376931,9.6374741,0.0,0,18.0,1.4012985e-45,1.0284622,2.4291973,18.000221,472.97705,-11.481886
217.7276,0.53195125,9.6447515,0.0,0,18.0,1.4012985e-45,1.0301906,2.419924,18.000076,461.5932,-11.481236
218.9276,0.53176314,9.653079,0.0,0,18.0,1.4012985e-45,1.0314413,2.4132402,18.000427,449.85995,-11.480751
220.1276,0.54106337,9.6607037,0.0,0,18.0,1.4012985e-45,1.032889,2.4555588,18.000593,438.03357,-11.480523
221.3276,0.54431772,9.6687145,0.0,0,18.0,1.4012985e-45,1.0344257,2.4636238,17.999462,426.63962,-11.480552
222.5276,0.55458885,9.6753063,0.0,0,18.0,1.4012985e-45,1.0357976,2.5092878,18.000565,416.02429,-11.480977
223.7276,0.56002414,9.6820669,0.0,0,18.0,1.4012985e-45,1.036975,2.5254586,18.000805,405.05838,-11.480841
224.9276,0.57074255,9.6884871,0.0,0,18.0,1.4012985e-45,1.0379905,2.5721831,17.999046,395.21274,-11.480947
226.1276,0.57201421,9.6939278,0.0,0,18.0,1.4012985e-45,1.0393239,2.5806849,18.000565,385.34091,-11.481226
227.3276,0.57882428,9.699646,0.0,0,18.0,1.4012985e-45,1.0401728,2.6114058,18.000572,375.53949,-11.481128
228.5276,0.58612663,9.704998,0.0,0,18.0,1.4012985e-45,1.0414649,2.6339839,17.999548,365.62692,-11.481215
229.7276,0.5867117,9.7116938,0.0,0,18.0,1.4012985e-45,1.0424188,2.6398516,17.998899,356.60999,-11.48083
230.9276,0.58760524,9.7172012,0.0,0,18.0,1.4012985e-45,1.0435923,2.6377914,18.000448,347.5748,-11.480582
232.1276,0.59389764,9.7231646,0.0,0,18.0,1.4012985e-45,1.0446984,2.6607134,18.001247,339.23587,-11.480616
233.3276,0.59601068,9.728714,0.0,0,18.0,1.4012985e-45,1.0458112,2.6674161,17.999481,330.89398,-11.480466
234.5276,0.61152351,9.7338085,0.0,0,18.0,1.4012985e-45,1.0468502,2.7366221,18.00012,322.94147,-11.480706
235.7276,0.60731745,9.7401075,0.0,0,18.0,1.4012985e-45,1.047845,2.7139244,18.000061,314.97421,-11.480859
236.9276,0.61122066,9.744977,0.0,0,18.0,1.4012985e-45,1.0489492,2.7269914,18.000206,307.27148,-11.480943
238.1276,0.61846966,9.750803,0.0,0,18.0,1.4012985e-45,1.0498469,2.7626553,17.999594,300.03061,-11.481099
239.3276,0.6181699,9.7556105,0.0,0,18.0,1.4012985e-45,1.0509732,2.7542639,17.999943,292.73154,-11.480639
240.5276,0.62102497,9.7605467,0.0,0,18.0,1.4012985e-45,1.0518941,2.760926,17.99926,285.62506,-11.480584
241.7276,0.63573551,9.7661657,0.0,0,18.0,1.4012985e-45,1.0527349,2.8249483,18.000008,279.04343,-11.481073
242.9276,0.63764167,9.7705164,0.0,0,18.0,1.4012985e-45,1.0538652,2.8299229,18.000212,272.4827,-11.481549
244.1276,0.65071267,9.7755775,0.0,0,18.0,1.4012985e-45,1.0545871,2.8862746,17.999266,265.98346,-11.481037
245.3276,0.65032601,9.7796516,0.0,0,18.0,1.4012985e-45,1.0556214,2.8791976,17.999502,259.67072,-11.481341
246.5276,0.65194756,9.784111,0.0,0,18.0,1.4012985e-45,1.0563813,2.8867962,17.999632,253.91194,-11.481116
247.7276,0.65757781,9.7893333,0.0,0,18.0,1.4012985e-45,1.0571492,2.9094748,17.999825,247.93651,-11.480952
248.9276,0.65499067,9.793251,0.0,0,18.0,1.4012985e-45,1.0582135,2.8921623,17.999563,242.23669,-11.480929
250.1276,0.6525225,9.7976761,0.0,0,18.0,1.4012985e-45,1.0588385,2.8830161,17.999649,236.74834,-11.480991
251.3276,0.66286695,9.80163,0.0,0,18.0,1.4012985e-45,1.0598236,2.9237797,17.999504,231.20772,-11.480938
252.5276,0.67277914,9.8059511,0.0,0,18.0,1.4012985e-45,1.0606022,2.9656239,17.998804,225.95995,-11.481289
253.7276,0.67033166,9.8099079,0.0,0,18.0,1.4012985e-45,1.0611122,2.951261,18.000727,220.66508,-11.481469
254.9276,0.66869676,9.8134203,0.0,0,18.0,1.4012985e-45,1.0620729,2.9416518,17.99909,215.48849,-11.481192
256.1276,0.67499119,9.8175259,0.0,0,18.0,1.4012985e-45,1.0627329,2.9648561,18.000246,210.86075,-11.481292
257.3276,0.67259192,9.8215218,0.0,0,18.0,1.4012985e-45,1.0635651,2.9562287,17.999704,205.64999,-11.481204
258.5276,0.68145347,9.8242006,0.0,0,18.0,1.4012985e-45,1.064198,2.9877832,17.999651,201.11076,-11.480859
259.7276,0.67555547,9.8281202,0.0,0,18.0,1.4012985e-45,1.0646583,2.9667916,18.000595,196.61896,-11.480669
260.9276,0.67735177,9.8320379,0.0,0,18.0,1.4012985e-45,1.0654968,2.96889,17.999195,192.09285,-11.480506
262.1276,0.68555892,9.8349104,0.0,0,18.0,1.4012985e-45,1.0662246,3.0018559,17.999666,187.81808,-11.480974
263.3276,0.68063641,9.8383102,0.0,0,18.0,1.4012985e-45,1.0666491,2.9802265,18.000132,183.42682,-11.481155
264.5276,0.67619389,9.8409271,0.0,0,18.0,1.4012985e-45,1.0674932,2.956723,17.999578,179.50905,-11.480988
265.7276,0.68678218,9.8443317,0.0,0,18.0,1.4012985e-45,1.0679555,2.9932969,17.998613,175.45287,-11.481203
266.9276,0.68439114,9.8483744,0.0,0,18.0,1.4012985e-45,1.0685762,2.9914129,17.999872,171.62544,-11.481218
268.1276,0.68262905,9.8508739,0.0,0,18.0,1.4012985e-45,1.0693324,2.9748147,18.000793,167.82536,-11.481218
269.3276,0.6859526,9.8542757,0.0,0,18.0,1.4012985e-45,1.0698509,2.9930639,18.000086,164.29623,-11.481049
270.5276,0.67053831,9.8568544,0.0,0,18.0,1.4012985e-45,1.0704108,2.9311063,17.999384,160.35439,-11.480317
271.7276,0.67413998,9.858881,0.0,0,18.0,1.4012985e-45,1.0709649,2.9351885,17.999546,157.04346,-11.480099
272.5276,0.68936139,9.8614759,0.0,0,18.0,1.4012985e-45,1.0712434,3.0084202,17.999237,154.74173,-11.480704