File: examples/hot axisymmetric compression example/data/02 screened data/testID_0136.csv
Time(sec),Force(kN),Jaw(mm),PowAngle(deg),Power(W),Pram,PTemp,Strain,Stress(MPa),Stroke(mm),TC1(C),wedge(mm)
0.0,0.93568093,0.31036982,0.0,0,11.076097,0.00033741558,0.020913297,11.657312,11.077017,24.120577,-9.123805
1.1,0.86642867,0.0038688539,0.0,0,11.076097,3.2158802,0.00025510037,11.029135,11.077198,24.091749,-9.4935436
2.2,0.82380509,0.0035335112,0.0,0,11.076097,6.5158811,0.000238072,10.49497,11.075434,24.038294,-9.4906778
3.3,0.78830147,0.0034345428,0.0,0,11.076097,9.8158808,0.0002306282,10.024047,11.076637,24.018276,-9.48915
4.4,0.75336009,0.0030116427,0.0,0,11.076097,13.11588,0.00020054226,9.5860758,11.074632,23.996857,-9.4873505
5.5,0.73320746,0.003033781,0.0,0,11.076097,16.415882,0.00019927848,9.3404589,11.075956,23.975601,-9.4856462
6.6,0.72544479,0.0029612051,0.0,0,11.076097,19.715881,0.00019130346,9.2369003,11.076971,24.027927,-9.4836006
7.7,0.72048783,0.0029702778,0.0,0,11.076097,23.015884,0.00018595842,9.1535101,11.075673,23.955471,-9.4816017
8.8,0.70328951,0.0033339441,16.595245,0,11.076097,26.315886,0.00022201586,8.9470863,11.075733,24.019869,-9.4791336
9.9,0.69582337,0.0032316921,31.7654,0,11.076097,29.615883,0.00021951551,8.8701687,11.076601,24.338642,-9.4773045
11.0,0.71344799,0.0015261662,38.853695,0,11.076097,32.915886,8.9220972e-05,9.0958986,11.074949,25.723949,-9.4754543
12.1,0.72309399,-0.0010718562,42.928894,0,11.076097,36.215885,-7.2134171e-05,9.2327194,11.076234,28.116531,-9.4737225
13.2,0.718696,-0.0041081463,45.120613,0,11.076097,39.515881,-0.00026339793,9.1585007,11.07529,31.336226,-9.4722118
14.3,0.72223693,-0.0069584739,47.053013,0,11.076097,42.81588,-0.00047478674,9.1838989,11.076819,34.858055,-9.4702587
15.4,0.71719295,-0.010255047,48.382019,0,11.076097,46.115879,-0.00067909347,9.1321774,11.075374,38.470856,-9.4684944
16.5,0.72256976,-0.013692082,49.334896,0,11.076097,49.415878,-0.0009035418,9.2164459,11.076582,42.331894,-9.466547
17.6,0.72935581,-0.017299935,49.885998,0,11.076097,52.715878,-0.001172971,9.29774,11.075828,46.422962,-9.4642992
18.7,0.72381765,-0.020759962,50.042721,0,11.076097,56.015873,-0.0013829406,9.2195749,11.076186,50.615726,-9.4622965
19.8,0.7257756,-0.024181008,50.438076,0,11.076097,59.315884,-0.0016055886,9.2595444,11.075613,54.560928,-9.46031
20.9,0.7262224,-0.02702513,50.802853,0,11.076097,62.615887,-0.0018096964,9.2612667,11.076901,58.376633,-9.4586849
22.0,0.73153633,-0.030251613,50.828266,0,11.076097,65.915878,-0.0020068474,9.3321323,11.07652,62.202328,-9.4566488
23.1,0.73346066,-0.033032414,50.932747,0,11.076097,69.215874,-0.0021916432,9.3548422,11.076614,66.117004,-9.4546394
24.2,0.731264,-0.035939991,51.196163,0,11.076097,72.515869,-0.0024077578,9.3290119,11.077008,69.762062,-9.4528923
25.3,0.72665489,-0.038816202,51.196285,0,11.076097,75.815872,-0.0025779631,9.2753849,11.07693,73.440453,-9.4509239
26.4,0.73013926,-0.042373601,51.077267,0,11.076097,79.115875,-0.0028083434,9.3394966,11.076522,77.285957,-9.4491711
27.5,0.73939931,-0.044816591,51.181297,0,11.076097,82.415878,-0.0029933229,9.4349003,11.076188,80.932274,-9.4472847
28.6,0.73785412,-0.048487868,51.196285,0,11.076097,85.715889,-0.0032190341,9.4141235,11.076308,84.426132,-9.445261
29.7,0.74281615,-0.051045492,51.254005,0,11.076097,89.0159,-0.003397136,9.4744005,11.075408,87.761444,-9.4430437
30.8,0.73211879,-0.052793097,51.196293,0,11.076097,92.315887,-0.0035316132,9.3470116,11.076116,91.355804,-9.4410372
31.9,0.74075359,-0.055373218,51.313251,0,11.076097,95.615906,-0.0036732354,9.4692278,11.076353,94.737114,-9.4394512
33.0,0.74251306,-0.058466539,51.385056,0,11.076097,98.915901,-0.0038767862,9.4916487,11.07626,98.105446,-9.4373035
34.1,0.73765415,-0.06121318,51.569729,0,11.076097,102.2159,-0.0040806686,9.4363937,11.075054,101.46235,-9.4355421
35.2,0.73479772,-0.063801371,51.56982,0,11.076097,105.5159,-0.0042264899,9.4080057,11.076169,104.83559,-9.4339628
36.3,0.73985285,-0.066657759,51.932362,0,11.076097,108.8159,-0.0044185156,9.4549665,11.075839,108.02522,-9.432147
37.4,0.74301267,-0.069185838,52.281364,0,11.076097,112.11591,-0.0046152538,9.4902391,11.076719,111.15315,-9.4304237
38.5,0.73854619,-0.072095491,52.630611,0,11.076097,115.4159,-0.004779241,9.4547081,11.075877,114.22012,-9.4284773
39.6,0.73449129,-0.074762061,53.150871,0,11.076097,118.7159,-0.0049546878,9.3936987,11.076066,117.19087,-9.4262991
40.7,0.74439412,-0.078599781,53.66024,0,11.076097,122.01589,-0.0052319323,9.5360203,11.077628,120.16323,-9.4245424
41.8,0.7529946,-0.081531562,53.898903,0,11.076097,125.3159,-0.0054142005,9.6434288,11.076063,123.61991,-9.4220924
42.9,0.74185079,-0.083724596,54.172874,0,11.076097,128.61601,-0.0055613108,9.5008821,11.077215,126.95351,-9.4203367
44.0,0.7417689,-0.085822336,53.97612,0,11.076097,131.91588,-0.0057121576,9.4938021,11.076015,130.58218,-9.4184923
45.1,0.74087352,-0.088960305,54.587669,0,11.076097,135.21588,-0.0059033367,9.490181,11.076106,133.6205,-9.4165354
46.2,0.75043702,-0.092075936,54.931622,0,11.076097,138.51587,-0.0060987896,9.6060076,11.07568,136.75525,-9.4147673
47.3,0.74740195,-0.095150493,55.345898,0,11.076097,141.81587,-0.0063390769,9.5622921,11.076448,139.95595,-9.413003
48.4,0.74677336,-0.098560147,55.691654,0,11.076097,145.11588,-0.0065457444,9.5767984,11.076215,143.20374,-9.4109287
49.5,0.7484355,-0.10164195,55.843426,0,11.076097,148.41589,-0.0067370497,9.5860968,11.076721,146.59583,-9.4093695
50.6,0.74866444,-0.10468339,56.124611,0,11.076097,151.7159,-0.0069635129,9.5995731,11.076863,149.98938,-9.4074574
51.7,0.75459903,-0.10805956,56.129147,0,11.076097,155.01591,-0.0071721226,9.6819162,11.075836,153.53232,-9.4056549
52.8,0.75156486,-0.11117305,56.348076,0,11.076097,158.3159,-0.007378181,9.6390638,11.075885,156.81752,-9.4039402
53.9,0.7457372,-0.11432722,56.426933,0,11.076097,161.61589,-0.0076069161,9.5732651,11.076497,160.15703,-9.4017973
55.0,0.74170542,-0.11725844,56.69289,0,11.076097,164.91589,-0.0077784793,9.5220165,11.076352,163.55516,-9.3998013
56.1,0.74957156,-0.12079029,56.986084,0,11.076097,168.2159,-0.008017228,9.6187725,11.075705,166.74724,-9.3979168
57.2,0.75054544,-0.12376621,56.986084,0,11.076097,171.5159,-0.0082330359,9.6260653,11.076479,170.27931,-9.3961048
58.3,0.7549181,-0.12675072,56.986084,0,11.076097,174.8159,-0.0084043555,9.6923399,11.076173,173.67192,-9.3942804
59.4,0.74753994,-0.1303501,56.986084,0,11.076097,178.11591,-0.0086466232,9.6124058,11.075849,177.19064,-9.3922291
60.5,0.75037962,-0.13352461,56.939331,0,11.076097,181.41589,-0.0088540446,9.6464987,11.075875,180.76674,-9.39011
61.6,0.75719953,-0.1371202,57.207928,0,11.076097,184.7159,-0.0090970313,9.7324162,11.076041,183.83278,-9.3884964
62.7,0.75925797,-0.14055683,57.533176,0,11.076097,188.01588,-0.0093217557,9.7551699,11.076352,186.97701,-9.386713
63.8,0.76001281,-0.1429655,57.573784,0,11.076097,191.31589,-0.0094981082,9.7768917,11.076392,190.25706,-9.385108
64.9,0.75948232,-0.14499404,57.906487,0,11.076097,194.61589,-0.0096296966,9.7761269,11.076451,193.41336,-9.3834915
66.0,0.7646299,-0.14725906,58.336304,0,11.076097,197.91589,-0.0097637698,9.8451004,11.075593,196.40907,-9.3814363
67.1,0.75482845,-0.15079635,58.662479,0,11.076097,201.21588,-0.010005709,9.7078018,11.077503,199.49365,-9.3799372
68.2,0.76305664,-0.15366489,59.065319,0,11.076097,204.5159,-0.010199026,9.8274641,11.076243,202.66132,-9.3783264
69.3,0.75854486,-0.15733211,59.348042,0,11.076097,207.81589,-0.010424568,9.7496252,11.075863,205.92641,-9.376132
70.4,0.75752503,-0.16072679,59.582214,0,11.076097,211.11589,-0.010659369,9.756403,11.076972,209.20888,-9.3741474
71.5,0.75662762,-0.16430525,59.841015,0,11.076097,214.41588,-0.010901306,9.7395124,11.076945,212.4825,-9.3724051
72.6,0.75622016,-0.16778561,59.632893,0,11.076097,217.7159,-0.011118698,9.7302923,11.074944,216.31424,-9.3707476
73.7,0.75060135,-0.17080086,59.842472,0,11.076097,221.01588,-0.011325011,9.6786737,11.076242,219.57941,-9.368948
74.8,0.75696564,-0.17377897,60.074787,0,11.076097,224.31589,-0.011531289,9.7377033,11.075131,222.89334,-9.3666029
75.9,0.77304965,-0.17810261,60.314934,0,11.076097,227.61588,-0.01180293,9.9535217,11.076084,226.0042,-9.3648262
77.0,0.76436687,-0.18131955,60.555447,0,11.076097,230.91589,-0.012022911,9.8548326,11.077067,229.2769,-9.3627901
78.1,0.75853598,-0.18318009,60.787346,0,11.076097,234.2159,-0.012154412,9.783823,11.076631,232.45845,-9.3610516
79.2,0.7533226,-0.18667166,61.144447,0,11.076097,237.51588,-0.012368863,9.7119837,11.07701,235.61108,-9.3596067
80.3,0.76138192,-0.18991895,61.237789,0,11.076097,240.81589,-0.012578868,9.8146076,11.076799,239.05556,-9.3576546
81.4,0.75166839,-0.19358544,61.395088,0,11.076097,244.11589,-0.012829638,9.7023878,11.076456,242.38493,-9.3558264
82.5,0.76251405,-0.19834039,61.468758,0,11.076097,247.41588,-0.013136835,9.8303556,11.076629,245.8405,-9.354393
83.6,0.76625377,-0.2002078,61.587379,0,11.076097,250.7159,-0.013262102,9.9021168,11.075736,249.30661,-9.3527412
84.7,0.76279783,-0.2033435,61.679394,0,11.076097,254.01588,-0.013481104,9.8601007,11.076358,252.82539,-9.3501234
85.8,0.75901252,-0.20704164,61.681076,0,11.076097,257.31613,-0.013706138,9.8056231,11.076138,256.3277,-9.3479795
86.9,0.75736362,-0.2110409,61.472763,0,11.076097,260.61612,-0.013960854,9.7752876,11.075918,259.98148,-9.3463755
88.0,0.76272315,-0.21542087,61.347599,0,11.076097,263.91589,-0.014279638,9.8583813,11.076571,263.5885,-9.344224
89.1,0.76989859,-0.2164239,61.237614,0,11.076097,267.21588,-0.014326074,9.934495,11.076256,267.15952,-9.3423033
90.2,0.76755238,-0.21981767,61.250317,0,11.076097,270.51593,-0.014538554,9.9278383,11.076804,270.28708,-9.341157
91.3,0.75783861,-0.22369707,61.468498,0,11.076097,273.81592,-0.014821704,9.7828808,11.077473,273.41141,-9.3396187
92.4,0.7622624,-0.22684999,61.688229,0,11.076097,277.11594,-0.015011125,9.8587255,11.076165,276.4538,-9.337841
93.5,0.7746709,-0.2321565,61.907928,0,11.076097,280.41592,-0.015353484,10.013307,11.076095,279.65292,-9.3361979
94.6,0.77023965,-0.23279937,62.116684,0,11.076097,283.71591,-0.015416125,9.9789429,11.076551,282.72144,-9.3346643
95.7,0.7714417,-0.23621944,62.230701,0,11.076097,287.01593,-0.015627483,9.9794264,11.075352,285.93912,-9.3328228
96.8,0.76205009,-0.24008328,62.350899,0,11.076097,290.31592,-0.015869897,9.849473,11.076776,289.2634,-9.3303175
97.9,0.7597096,-0.24316175,62.362122,0,11.076097,293.61591,-0.016091578,9.8308487,11.075949,292.68213,-9.3285303
99.0,0.77156162,-0.24755627,62.400642,0,11.076097,296.91589,-0.016362937,9.9907417,11.075858,296.08051,-9.3265142
100.1,0.7736724,-0.24990596,62.282455,0,11.076097,300.21591,-0.016517336,10.00379,11.075736,299.80856,-9.3244228
101.2,0.76825565,-0.25183421,62.12336,0,11.076097,303.5159,-0.016656414,9.9503794,11.075735,303.22156,-9.3226185
102.3,0.75448006,-0.25540081,62.31535,0,11.076097,306.81589,-0.016880881,9.7712946,11.075959,306.48254,-9.3204851
103.4,0.76444876,-0.25861666,62.336418,0,11.076097,310.11584,-0.017077724,9.9061565,11.07555,309.67654,-9.3192225
104.5,0.76750511,-0.26165888,62.643021,0,11.076097,313.41586,-0.017306078,9.950552,11.077011,312.67276,-9.3173666
105.6,0.76778167,-0.26509133,62.959686,0,11.076097,316.71588,-0.017505143,9.9461336,11.075794,315.64035,-9.3156862
106.7,0.77401048,-0.26990226,63.166321,0,11.076097,320.0159,-0.017813554,10.012758,11.076779,318.80948,-9.3138905
107.8,0.77230108,-0.27098373,63.343994,0,11.076097,323.31592,-0.017919375,10.021002,11.07644,322.04401,-9.3120317
108.9,0.77141684,-0.27395478,63.369137,0,11.076097,326.61591,-0.018092763,10.005631,11.076188,325.47452,-9.3104877
110.0,0.77285779,-0.27738786,63.576653,0,11.076097,329.91562,-0.018296525,10.029965,11.075825,328.70825,-9.3086119
111.1,0.76932281,-0.27981484,61.691608,0,11.076097,329.99976,-0.018502245,9.9827166,11.076055,331.84766,-9.3084745
112.2,0.76460755,-0.28151384,59.883213,0,11.076097,329.99976,-0.018590687,9.922061,11.075286,334.05927,-9.308074
113.3,0.76167911,-0.28258651,58.206463,0,11.076097,329.99976,-0.018641021,9.8824129,11.077299,335.54819,-9.3088207
114.4,0.77060914,-0.28249243,56.731777,0,11.076097,329.99976,-0.018676937,9.9826727,11.077635,336.27557,-9.3085566
115.5,0.76590979,-0.28400773,55.84354,0,11.076097,329.99976,-0.018740287,9.9290485,11.075809,336.39523,-9.3085003
116.6,0.75768226,-0.28322193,54.931759,0,11.076097,329.99976,-0.018693794,9.8231592,11.075874,336.17133,-9.3084888
117.7,0.74362749,-0.28183448,54.460896,0,11.076097,329.99976,-0.018634876,9.6407499,11.076542,335.66348,-9.3084183
118.8,0.73338664,-0.28228176,53.977478,0,11.076097,329.99976,-0.018629862,9.5131998,11.077406,335.08841,-9.3082094
119.9,0.73652685,-0.28262946,53.721302,0,11.076097,329.99976,-0.018643837,9.5518236,11.076453,334.53461,-9.3076735
121.0,0.7256785,-0.2826412,53.65723,0,11.076097,329.99976,-0.018692574,9.4140759,11.076316,333.91406,-9.3078308
122.1,0.72709268,-0.28265586,53.655937,0,11.076097,329.99976,-0.018654002,9.4354181,11.075631,333.30597,-9.3073215
123.2,0.74511254,-0.28341267,53.420238,0,11.076097,329.99976,-0.018704157,9.6687613,11.076926,332.81168,-9.3080673
124.3,0.7334044,-0.28179714,53.631176,0,11.076097,329.99976,-0.018628858,9.5056801,11.076679,332.25574,-9.307641
125.4,0.73414916,-0.28214186,53.657223,0,11.076097,329.99976,-0.01862191,9.531703,11.076799,331.76898,-9.3076477
126.5,0.7260412,-0.28258669,53.658199,0,11.076097,329.99976,-0.018644953,9.4309578,11.075878,331.42682,-9.3075933
127.6,0.71958673,-0.28251642,53.952389,0,11.076097,329.99976,-0.0186745,9.3468571,11.075969,331.06186,-9.3070841
128.7,0.73048365,-0.28290814,53.808708,0,11.076097,329.99976,-0.018683409,9.46348,11.07739,330.90445,-9.3073149
129.8,0.74706763,-0.28378412,53.975826,0,11.076097,329.99976,-0.018715497,9.6826916,11.075527,330.57755,-9.3076839
130.9,0.74749929,-0.28358287,54.177647,0,11.076097,329.99976,-0.018752929,9.7111568,11.075734,330.34906,-9.3076124
132.0,0.75183111,-0.2828362,54.226753,0,11.076097,329.99976,-0.018674714,9.7671232,11.07549,330.24005,-9.3074341
133.1,0.75175077,-0.2830981,54.304642,0,11.076097,329.99976,-0.018673714,9.7484646,11.075946,330.12357,-9.3075666
134.2,0.758322,-0.2836532,54.305416,0,11.076097,329.99976,-0.018750036,9.8380156,11.075711,330.20135,-9.3072634
135.3,0.76057047,-0.28416035,54.2966,0,11.076097,329.99976,-0.018757692,9.866291,11.075347,330.06525,-9.3073292
136.4,0.74851167,-0.28515688,54.305416,0,11.076097,329.99976,-0.018816851,9.7231035,11.076629,330.05084,-9.3075438
137.5,0.76644206,-0.28485525,54.305416,0,11.076097,329.99976,-0.018829446,9.9339333,11.07657,330.07578,-9.3073463
138.6,0.75958949,-0.28576162,54.305367,0,11.076097,329.99976,-0.018860918,9.8485746,11.075336,330.09647,-9.3072414
139.7,0.76807255,-0.28713006,54.274933,0,11.076097,329.99976,-0.018936342,9.9618883,11.076542,330.07132,-9.3071203
140.8,0.75905871,-0.28746116,54.297253,0,11.076097,329.99976,-0.019003551,9.8451271,11.0766,330.08221,-9.3069592
141.9,0.76496202,-0.28671867,54.211586,0,11.076097,329.99976,-0.018931044,9.9301367,11.076868,330.08398,-9.3071623
143.0,0.77252221,-0.28660429,54.305248,0,11.076097,329.99976,-0.018905792,10.011126,11.075787,330.00214,-9.3068886
144.1,0.7742219,-0.28728026,54.302471,0,11.076097,329.99976,-0.018988233,10.041547,11.075772,330.00659,-9.3071833
145.2,0.76134086,-0.28775096,54.298264,0,11.076097,329.99976,-0.018990602,9.8832712,11.077578,330.02765,-9.3068314
146.3,0.74576157,-0.28815123,54.284416,0,11.076097,329.99976,-0.018997842,9.6716089,11.076242,329.94812,-9.3066101
147.4,0.75974572,-0.28821728,54.152382,0,11.076097,329.99976,-0.019046413,9.8670311,11.075064,330.0957,-9.3065825
148.5,0.77284652,-0.2887927,54.293678,0,11.076097,329.99976,-0.019065101,10.029291,11.075316,329.98099,-9.3073111
149.6,0.76804847,-0.28922024,54.253654,0,11.076097,329.99976,-0.019079108,9.966445,11.076909,330.02509,-9.3068295
150.7,0.77352566,-0.28962967,54.124722,0,11.076097,329.99976,-0.019144649,10.038032,11.076318,330.02988,-9.307126
151.8,0.77831626,-0.29109067,54.299595,0,11.076097,329.99976,-0.019213682,10.112537,11.075982,329.99219,-9.3064089
152.9,0.77373141,-0.29084337,54.125637,0,11.076097,329.99976,-0.019187342,10.038677,11.076663,330.06165,-9.3064613
154.0,0.7686035,-0.29012713,54.295055,0,11.076097,329.99976,-0.019169174,9.9879494,11.075743,329.95612,-9.3066616
155.1,0.76020259,-0.043010835,54.110516,0,11.076097,329.99976,-0.0028244043,9.7197409,11.076878,330.07574,-9.3064489
155.2822,0.78357744,0.0046677683,2.6986961,0,11.076099,1.5468613e-08,0.0005487345,9.9277792,11.079016,330.11554,-9.3058624
155.2844,0.78117317,0.0058260355,0.0,0,11.076099,1.544973e-23,0.00021848902,10.066537,11.076987,330.12073,-9.3057861
155.2866,0.76515347,0.0030847222,0.0,0,11.076099,1.5430874000000001e-38,0.00048509432,9.6771822,11.078193,330.12741,-9.3070173
155.2888,0.7513569,0.0076989522,0.0,0,11.076099,0.0,0.00014046745,9.5978308,11.077698,330.13412,-9.3077459
155.291,0.75199342,0.0019236073,0.0,0,11.076099,0.0,0.00036059716,9.623167,11.076777,330.14081,-9.3060627
155.2932,0.74097055,0.0057676914,0.0,0,11.076099,0.0,0.00022529693,9.5044928,11.078443,330.146,-9.3049908
155.2954,0.74693817,0.0024885691,0.0,0,11.076099,0.0,0.00044970217,9.5149488,11.077026,330.146,-9.3055773
155.2976,0.75423843,0.0092949811,0.0,0,11.076099,0.0,0.00035601549,9.6227407,11.07316,330.146,-9.3068523
155.2998,0.75933897,0.0029326787,0.0,0,11.076099,0.0,0.00038553274,9.6253653,11.078151,330.146,-9.3070955
155.302,0.76315343,0.007209694,0.0,0,11.076099,0.0,0.00039155598,9.6930342,11.078362,330.146,-9.3070116
155.3042,0.75419933,0.0030356045,0.0,0,11.076099,0.0,0.00043219907,9.6426506,11.075041,330.14142,-9.3070612
155.3064,0.74966037,0.010133791,0.0,0,11.076099,0.0,0.00040865756,9.5208435,11.075201,330.13474,-9.3056774
155.3086,0.73481321,0.0040850821,0.0,0,11.076099,0.0,0.00037647947,9.4345932,11.0762,330.12802,-9.3069401
155.3108,0.73995733,0.0049501136,0.0,0,11.076099,0.0,0.00027387452,9.4446888,11.078374,330.12134,-9.3064489
155.313,0.73469663,0.0018376595,0.0,0,11.076099,0.0,0.00022678652,9.4181671,11.075112,330.11462,-9.3057556
155.3152,0.74056846,0.0085803652,0.0,0,11.076099,0.0,0.00042515818,9.3094263,11.076468,330.10791,-9.3065195
155.3174,0.75551087,0.0033881143,0.0,0,11.076099,0.0,0.0002744357,9.5520954,11.078441,330.1012,-9.3062992
155.3196,0.75211734,0.0047846325,0.0,0,11.076099,0.0,0.00030683065,9.6120853,11.074894,330.09451,-9.3068304
155.3218,0.74512166,0.0030087584,0.0,0,11.076099,0.0,0.00017789686,9.4236479,11.078578,330.0878,-9.306983
155.324,0.75108856,0.00811294,0.0,0,11.076099,0.0,0.00055845088,9.4579449,11.072441,330.07712,-9.3071918
155.3262,0.74010581,0.0042660278,0.0,0,11.076099,0.0,0.00029362034,9.4070063,11.07173,330.06372,-9.3067942
155.3284,0.73257363,0.0052099158,0.0,0,11.076099,0.0,0.00034356207,9.3301334,11.072092,330.05032,-9.306325
155.3306,0.73788053,0.0024704586,0.0,0,11.076099,0.0,0.00016001068,9.3850403,11.073954,330.0369,-9.3064413
155.3328,0.73212165,0.0073244702,0.0,0,10.765901,0.0,0.00062098884,9.3075628,11.076056,330.02472,-9.3063583
155.335,0.7364983,0.0067325165,0.0,0,10.435008,0.0,0.0003548245,9.3873291,11.074396,330.03812,-9.3060179
155.3372,0.76593274,0.0036313697,0.0,0,10.104116,0.0,0.00036946704,9.8373051,11.025028,330.05154,-9.3070421
155.3394,0.74018115,0.0044953423,0.0,0,9.7732229,0.0,0.00012179041,9.4649143,10.848061,330.06494,-9.3073034
155.3416,0.76339591,0.0060569141,0.0,0,9.4434071,0.0,0.00058513467,9.6856337,10.552631,330.07834,-9.3080273
155.3438,0.74312299,0.0081939828,0.0,0,9.1214981,0.0,0.00035203196,9.5780621,10.166295,330.64075,-9.3077192
155.346,7.232254,0.27199197,0.0,0,8.7995939,0.0,0.017527811,89.94416,9.7653904,331.75214,-9.3023443
155.3482,9.1111498,0.66635519,0.0,0,8.4910259,0.0,0.044893779,110.2862,9.3154955,332.86353,-9.2994452
155.3504,9.747077,1.060209,0.0,0,8.1848736,0.0,0.073364787,114.96117,8.9104795,333.97488,-9.2981911
155.3526,10.194832,1.4030759,0.0,0,7.8872557,0.0,0.097426333,118.01726,8.5703135,335.08627,-9.2985516
155.3548,10.588933,1.6957351,0.0,0,7.5959754,0.0,0.11991721,119.31883,8.2443695,336.51028,-9.2977877
155.357,10.826219,2.0015326,0.0,0,7.3089881,0.0,0.14247122,119.49825,7.9308977,337.94916,-9.2987423
155.3592,11.041647,2.2903185,0.0,0,7.0319633,0.0,0.16559523,119.06969,7.6489959,339.38803,-9.2984791
155.3614,11.3484,2.5582352,0.0,0,6.7554417,0.0,0.18617009,119.83582,7.3752627,340.8269,-9.2999811
155.3636,11.629908,2.8086963,0.0,0,6.4917622,0.0,0.2072994,120.25204,7.1099911,341.79474,-9.2988729
155.3658,11.868679,3.0730858,0.0,0,6.2282019,0.0,0.22857413,120.10223,6.8490682,342.08221,-9.2993431
155.368,12.19345,3.3258924,0.0,0,5.9743834,0.0,0.25065634,120.66766,6.586328,342.36966,-9.2994175
155.3702,12.473477,3.5987163,0.0,0,5.7237153,0.0,0.2733427,120.81631,6.3198738,342.6571,-9.298912
155.3724,12.742992,3.8575056,0.0,0,5.4789333,0.0,0.29722518,120.53062,6.0580301,342.94458,-9.2990341
155.3746,13.034327,4.1196113,0.0,0,5.2404532,0.0,0.3203347,120.47849,5.7953467,342.48148,-9.298172
155.3768,13.315804,4.3730354,0.0,0,5.0044241,0.0,0.344598,120.07085,5.5357351,341.89987,-9.2990561
155.379,13.620211,4.6331878,0.0,0,4.7776041,0.0,0.3686375,119.85465,5.2812791,341.31827,-9.2997408
155.3812,13.916677,4.8726339,0.0,0,4.5507841,0.0,0.39267144,119.59677,5.0361247,340.73669,-9.299593
155.3834,14.231879,5.1176648,0.0,0,4.3343177,0.0,0.41654751,119.39478,4.7961621,339.4382,-9.2986202
155.3856,14.547789,5.3436604,0.0,0,4.1185417,0.0,0.44022363,119.27174,4.5580134,336.60358,-9.2988701
155.3878,14.886025,5.5803032,0.0,0,3.9097853,0.0,0.46448806,119.15746,4.3356762,333.76895,-9.2991867
155.39,15.229249,5.7973456,0.0,0,3.7045693,0.0,0.4883506,118.94501,4.1077962,330.93433,-9.2985611
155.3922,15.577224,6.0136461,0.0,0,3.5032687,0.0,0.51183462,118.82735,3.8942041,328.0997,-9.2987642
155.3944,15.92529,6.2159023,0.0,0,3.3080409,0.0,0.53476995,118.77878,3.6854987,325.35605,-9.2974424
155.3966,16.313042,6.4252834,0.0,0,3.11395,0.0,0.55869502,118.73829,3.4858384,322.63919,-9.2981939
155.3988,16.727686,6.6185355,0.0,0,2.9282222,0.0,0.5815621,118.96661,3.2903728,319.92233,-9.2976637
155.401,17.188469,6.8139853,0.0,0,2.7424984,0.0,0.60521859,119.39334,3.0914984,317.20544,-9.2968044
155.4032,17.678782,7.0025806,0.0,0,2.5644474,0.0,0.62837505,119.99361,2.8984332,315.07703,-9.2967567
155.4054,18.181515,7.2021923,0.0,0,2.3877873,0.0,0.65398341,120.28377,2.7114992,314.94919,-9.2975359
155.4076,18.689207,7.3830986,0.0,0,2.2160764,0.0,0.67697042,120.88338,2.5215588,314.82135,-9.2966967
155.4098,19.226151,7.5622654,0.0,0,2.0480404,0.0,0.70131761,121.31557,2.3426011,314.69354,-9.2967262
155.412,19.754614,7.7353926,0.0,0,1.8824685,0.0,0.72426599,121.86994,2.1666343,314.5657,-9.2960958
155.4142,20.321568,7.9090071,0.0,0,1.7226164,0.0,0.74925739,122.24792,1.9996924,312.88361,-9.2947969
155.4164,20.936705,8.0722885,0.0,0,1.5630548,0.0,0.7714988,123.12534,1.8337039,310.4762,-9.2950239
155.4186,21.589085,8.2312794,0.0,0,1.4109213,0.0,0.79589564,123.95412,1.6708468,308.06882,-9.2946892
155.4208,22.268593,8.3923397,0.0,0,1.2588574,0.0,0.81876874,124.99911,1.5136517,305.66144,-9.2944269
155.423,23.008713,8.5477276,0.0,0,1.1124125,0.0,0.84404236,125.89964,1.3593223,303.69409,-9.2939119
155.4252,23.774395,8.6994429,0.0,0,0.96778435,0.0,0.86600065,127.26029,1.2027893,304.51349,-9.2945919
155.4274,24.595871,8.8425541,0.0,0,0.82657731,0.0,0.8910045,128.4099,1.0565543,305.33289,-9.2943983
155.4296,25.429392,8.9930773,0.0,0,0.68903339,0.0,0.91367167,129.79062,0.90449101,306.15228,-9.2930212
155.4318,26.266468,9.1289368,0.0,0,0.55288601,0.0,0.93870944,130.74181,0.76462168,306.97168,-9.2922001
155.434,27.138191,9.2713938,0.0,0,0.42198589,0.0,0.96077907,132.12971,0.62670726,308.31601,-9.2929506
155.4362,28.052172,9.3860855,0.0,0,0.29108587,0.0,0.98363435,133.47002,0.49547279,310.02371,-9.2916698
155.4384,25.756109,9.4144487,0.0,0,0.16620816,0.0,0.98663831,122.37841,0.42754641,311.73141,-9.2927475
155.4406,24.224209,9.4196625,0.0,0,0.041732151,0.0,0.98994142,114.74242,0.39513248,313.43915,-9.2950058
155.4428,23.628584,9.4310904,0.0,0,-0.080696426,0.0,0.98939937,111.88122,0.36681125,315.01727,-9.2960825
155.445,23.395552,9.4328604,0.0,0,-0.20209241,0.0,0.99222088,110.43423,0.33195969,313.87494,-9.2973213
155.4472,23.487236,9.4466524,0.0,0,-0.32348844,0.0,0.99282032,110.80332,0.27879822,312.7326,-9.2984295
155.4494,23.554808,9.4424038,0.0,0,-0.44488442,0.0,0.994115,110.99956,0.21912238,311.5903,-9.29702
155.4516,23.546829,9.4594021,0.0,0,-0.56628042,0.0,0.99483275,110.88126,0.15943699,310.44797,-9.2976551
155.4538,23.43396,9.4545975,5.7513232,0,-0.68767637,0.0,0.99582624,110.22495,0.10558742,310.00464,-9.297411
155.456,23.268682,9.4677753,17.253788,0,-0.80907238,0.0,0.99679309,109.39441,0.05769657,310.26028,-9.2978191
155.4582,23.011808,9.4626541,28.756254,0,-0.93046838,0.0,0.9971596,108.15249,0.021976352,310.51596,-9.2979631
155.4604,22.702,9.4753094,40.258724,0,-1.0518645,0.0,0.9980644,106.55405,-0.0046266168,310.77161,-9.2985277
155.4626,22.275826,9.4692383,51.761185,0,-0.88153589,330.0,0.9981913,104.58245,-0.020192621,311.02725,-9.2995548
155.4648,21.755821,9.474719,52.283939,0,-0.46125633,330.0,0.998285,102.13737,-0.020713856,311.07742,-9.2999945
155.467,21.224796,9.4666424,52.283939,0,-0.040977493,330.0,0.99751842,99.684158,-0.015478206,311.11777,-9.2992821
155.4692,20.903481,9.481019,52.283939,0,0.37930161,330.0,0.99946874,98.014191,-0.0095049515,311.15814,-9.2995739
155.4714,20.526333,9.4723873,52.283939,0,0.79958111,330.0,0.99849957,96.319572,-0.0074081607,311.19849,-9.3012695
155.4736,20.23032,9.4762383,51.813274,0,1.2198603,330.0,0.99899817,94.891205,-0.0071746055,311.63519,-9.3004951
155.4758,19.466871,9.470336,50.662785,0,1.640139,330.0,0.99770743,91.528137,0.0083448775,312.64435,-9.300703
155.478,18.027182,9.4740877,49.512299,0,2.0604188,330.0,0.99870116,84.698326,0.068931311,313.65347,-9.3024731
155.4802,15.33676,9.4635267,48.361809,0,2.4806981,330.0,0.99638915,72.374504,0.17901687,314.66263,-9.3046827
155.4824,10.825109,9.4479876,47.211319,0,2.9009769,330.0,0.99423468,51.456715,0.37719083,315.67178,-9.3074226
155.4846,0.18231478,9.3002214,47.054443,0,3.3212562,330.0,0.96801293,0.68570077,0.71254051,318.96411,-9.3173561
155.4868,0.46241614,9.1717119,47.054443,0,3.7415352,330.0,0.94629025,2.2815137,1.3381225,322.61691,-9.3173075
155.489,-0.27378455,9.1284227,47.054443,0,4.1618147,330.0,0.93711001,-1.1603066,2.1205738,326.26971,-9.316577
155.4912,-0.063141651,9.1421356,47.054443,0,4.5820937,330.0,0.94077504,-0.4847995,2.8496797,329.92255,-9.3176756
155.4934,0.098504134,9.2271709,43.760551,0,5.0023732,330.0,0.95342177,0.57899368,3.4222975,333.49335,-9.314971
155.4956,-0.084731497,9.381341,33.408577,0,5.4226518,330.0,0.98238164,-0.46341878,3.841862,336.88849,-9.3160572
155.4978,-0.12553108,9.401474,23.056599,0,5.8429317,330.0,0.98499602,-0.30525023,4.2315512,340.28363,-9.313736
155.5,0.10842796,9.3721666,12.70462,0,6.2632103,330.0,0.98163772,0.41348207,4.619369,343.67877,-9.313282
155.5022,0.49755427,9.3939667,2.3526452,0,6.6834898,330.0,0.98309582,2.193135,5.0069423,347.07391,-9.3119745
155.5044,0.56846976,9.3937073,0.0,0,7.1037693,330.0,0.9854036,2.9265733,5.3919516,348.27411,-9.3116598
155.5066,0.1740987,9.3965721,0.0,0,7.5240483,330.0,0.98321319,0.80540031,5.7997518,348.82874,-9.3115015
155.5088,0.55098552,9.3939705,0.0,0,7.9443278,330.0,0.98546302,2.634624,6.2258453,349.38336,-9.3112841
155.511,0.3986558,9.3969936,0.0,0,8.3646069,330.0,0.98384035,1.9334439,6.6722159,349.93799,-9.3102112
155.5132,0.49660063,9.3939238,0.0,0,8.7848854,330.0,0.98548436,2.3867381,7.1189346,350.31949,-9.3095922
155.5154,0.38305649,9.4043007,0.0,0,9.2051649,330.0,0.98463947,1.8417236,7.5646071,350.11224,-9.3088665
155.5176,0.44486794,9.3934784,0.0,0,9.6254444,330.0,0.98514491,2.1531394,8.0003271,349.90503,-9.3086004
155.5198,0.44932622,9.3947039,0.0,0,10.045724,330.0,0.98347294,2.1380935,8.4348364,349.69778,-9.3070621
155.522,0.42319387,9.3885584,0.0,0,10.466002,330.0,0.98436683,2.0137098,8.8633032,349.49057,-9.3070631
155.5242,0.42039588,9.4004097,0.0,0,10.886282,330.0,0.98409599,2.0342226,9.2949419,348.87326,-9.307004
155.5264,0.36978856,9.3929863,0.0,0,11.306561,330.0,0.98490983,1.76679,9.7250347,348.06458,-9.3078823
155.5286,0.47088441,9.3988085,0.0,0,11.72684,330.0,0.98434764,2.2233372,10.156614,347.25592,-9.3072586
155.5308,0.41277176,9.390172,0.0,0,12.14712,330.0,0.98441654,2.0023682,10.585813,346.44727,-9.3065853
155.533,0.39381111,9.4040947,0.0,0,12.567399,330.0,0.9850809,1.88499,11.015136,345.70877,-9.3063087
155.5352,0.42614701,9.3908424,0.0,0,12.987678,330.0,0.98426086,2.0205481,11.447683,345.41461,-9.308054
155.5374,0.45689574,9.3977165,0.0,0,13.407957,330.0,0.98458838,2.2028599,11.872266,345.12048,-9.3064995
155.5396,0.44767937,9.3910017,0.0,0,13.828236,330.0,0.98410708,2.1360171,12.290783,344.82635,-9.3062859
155.5418,0.43896177,9.4012136,0.0,0,14.248516,330.0,0.98502147,2.0593417,12.71572,344.53223,-9.3068504
155.544,0.46695137,9.3921509,0.0,0,14.668795,330.0,0.98424917,2.2077315,13.148958,344.51459,-9.3046856
155.5462,0.37601146,9.398982,0.0,0,15.089074,330.0,0.985089,1.8374109,13.590959,344.68842,-9.3054447
155.5484,0.43076298,9.3925724,0.0,0,15.509354,330.0,0.98391169,2.0006044,14.033939,344.86221,-9.3055038
155.5506,0.43372867,9.398077,0.0,0,15.929632,330.0,0.98507768,2.1073635,14.466197,345.03604,-9.3051682
155.5528,0.42836979,9.3968287,0.0,0,16.349911,330.0,0.98452759,2.0573595,14.898504,345.21774,-9.3051453
155.555,0.44363594,9.3961906,0.0,0,16.770191,330.0,0.98504257,2.0852768,15.312324,345.56534,-9.3033981
155.5572,0.44154745,9.3945246,0.0,0,17.19047,330.0,0.98387235,2.1015882,15.730957,345.91296,-9.3037071
155.5594,0.4610135,9.3958979,0.0,0,17.61075,330.0,0.98511356,2.190881,16.145201,346.26056,-9.3053598
155.5616,0.4069429,9.3980341,0.0,0,17.999401,330.0,0.98409355,1.9416977,16.562069,346.60818,-9.3045273
155.5638,0.43119395,9.3967295,0.0,0,18.0,330.0,0.98535711,2.0402939,16.975069,346.88895,-9.3046379
155.566,0.46258089,9.3954086,0.0,0,18.0,330.0,0.98374438,2.1782031,17.37476,347.10287,-9.3047323
155.5682,0.42661569,9.3940191,0.0,0,18.0,330.0,0.98517895,2.0195539,17.738766,347.31677,-9.3051138
155.5704,0.44781458,9.3989573,0.0,0,18.0,330.0,0.9840973,2.1092434,18.056423,347.5307,-9.3071775
155.5726,0.49602273,9.3919954,0.0,0,18.0,330.0,0.98469794,2.3514507,18.296875,347.7446,-9.3084793
155.5748,0.52465981,9.3946762,0.0,0,18.0,330.0,0.98329753,2.5061674,18.456161,347.97128,-9.3109741
155.577,0.5465523,9.3958321,0.0,0,18.0,330.0,0.98576808,2.6436036,18.499624,348.19858,-9.3171558
155.5792,0.52628756,9.4039307,0.0,0,18.0,330.0,0.9847734,2.4837844,18.444313,348.42587,-9.3246775
155.5814,0.55591577,9.3947411,0.0,0,18.0,330.0,0.98555905,2.593236,18.326658,348.65317,-9.334033
155.5836,0.55684441,9.3985691,0.0,0,18.0,330.0,0.98411494,2.6334999,18.211584,348.90506,-9.3467722
155.5858,0.51411551,9.3932905,0.0,0,18.0,330.0,0.98543477,2.4563351,18.118135,349.1925,-9.3592978
155.588,0.51535171,9.4023476,0.0,0,18.0,330.0,0.98417133,2.4080279,18.061745,349.47995,-9.3750296
155.5902,0.53860301,9.3881931,0.0,0,18.0,330.0,0.98445034,2.560292,18.043779,349.76743,-9.3922968
155.5924,0.54910022,9.3910437,0.0,0,18.0,330.0,0.98283964,2.5849111,18.045101,350.05487,-9.4092693
155.5946,0.52950162,9.3878107,0.0,0,18.0,330.0,0.98439997,2.4950089,18.055382,350.09406,-9.4281063
155.5968,0.52736199,9.3990555,0.0,0,18.0,330.0,0.98379761,2.5113559,18.076532,350.09406,-9.4460449
155.599,0.51756436,9.388979,0.0,0,18.0,330.0,0.98428088,2.4485538,18.097086,350.09406,-9.4628754
155.6012,0.51308584,9.3946104,0.0,0,18.0,330.0,0.98347217,2.4377205,18.116369,350.09406,-9.4803591
155.6034,0.50239938,9.3864813,0.0,0,18.0,330.0,0.98396438,2.3747365,18.128716,350.12167,-9.4959726
155.6056,0.53381187,9.4006119,0.0,0,18.0,330.0,0.98466724,2.5252171,18.13995,350.2085,-9.511569
155.6078,0.5384621,9.3896666,0.0,0,18.0,330.0,0.98409247,2.5760515,18.142155,350.29532,-9.5273943
155.61,0.55918002,9.3941498,0.0,0,18.0,330.0,0.9836179,2.6275978,18.142506,350.38214,-9.5434542
155.6122,0.54994732,9.3866959,0.0,0,18.0,330.0,0.98331839,2.5909982,18.140276,350.46896,-9.560421
155.6144,0.55513334,9.3943491,0.0,0,18.0,330.0,0.98372114,2.6484561,18.137028,350.58163,-9.5761261
155.6166,0.52529538,9.3880043,0.0,0,18.0,330.0,0.98335207,2.5454874,18.13693,350.70187,-9.5903378
155.6188,0.51452136,9.3932581,0.0,0,18.0,330.0,0.9838661,2.4981306,18.130714,350.82211,-9.605422
155.621,0.53492409,9.3887863,0.0,0,18.0,330.0,0.98329413,2.5191491,18.128788,350.94232,-9.6207924
155.6232,0.53644174,9.3963528,0.0,0,18.0,330.0,0.98455703,2.5719075,18.127087,351.02191,-9.636734
155.6254,0.55311507,9.3881359,0.0,0,18.0,330.0,0.98308218,2.5929632,18.124292,350.96323,-9.6530647
155.6276,0.55619627,9.3904514,0.0,0,18.0,330.0,0.98387128,2.6245751,18.122492,350.90457,-9.6678457
155.6298,0.57054502,9.3889914,0.0,0,18.0,330.0,0.9829573,2.7373042,18.117653,350.84589,-9.6854858
155.632,0.55182314,9.3952084,0.0,0,18.0,330.0,0.98469204,2.612664,18.113703,350.78769,-9.700366
155.6342,0.54394472,9.391449,0.0,0,18.0,330.0,0.98292756,2.6150577,18.112976,350.73431,-9.7179756
155.6364,0.52968693,9.3899288,0.0,0,18.0,330.0,0.9838897,2.5551875,18.116596,350.68091,-9.7337608
155.6386,0.53208661,9.3909197,0.0,0,18.0,330.0,0.98303044,2.5081005,18.110104,350.62753,-9.7499542
155.6408,0.51971948,9.3942308,0.0,0,18.0,330.0,0.98521292,2.4901996,18.111023,350.57413,-9.767415
155.643,0.55291057,9.3954334,0.0,0,18.0,330.0,0.98354036,2.6022751,18.109247,350.66263,-9.7821741
155.6452,0.56610227,9.3889389,0.0,0,18.0,330.0,0.9841519,2.649224,18.110432,350.86935,-9.7966127
155.6474,0.54892099,9.3904133,0.0,0,18.0,330.0,0.98262405,2.6172917,18.108341,351.07611,-9.8135624
155.6496,0.56385154,9.3890057,0.0,0,18.0,330.0,0.98446286,2.6592906,18.106054,351.28284,-9.8305559
155.6518,0.54359162,9.3957939,0.0,0,18.0,330.0,0.98327267,2.6129835,18.106159,351.48956,-9.8451176
155.654,0.52698755,9.3870096,0.0,0,18.0,330.0,0.9842003,2.5372202,18.106491,351.8363,-9.8619766
155.6562,0.50181842,9.3940506,0.0,0,18.0,330.0,0.98323286,2.4163911,18.101429,352.18307,-9.8784389
155.6584,0.51406145,9.3880234,0.0,0,18.0,330.0,0.98443604,2.4395688,18.105286,352.52982,-9.8948765
155.6606,0.53573,9.3972721,0.0,0,18.0,330.0,0.98331612,2.564878,18.105955,352.87656,-9.9109507
155.6628,0.55163527,9.3875351,0.0,0,18.0,330.0,0.98419267,2.6196363,18.102348,353.1051,-9.9264746
155.665,0.5574733,9.3897219,0.0,0,18.0,330.0,0.98247153,2.6415319,18.096865,353.19177,-9.9416771
155.6672,0.54809111,9.3844185,0.0,0,18.0,330.0,0.98375088,2.6012518,18.094332,353.27844,-9.9572182
155.6694,0.54645407,9.3967295,0.0,0,18.0,330.0,0.98321432,2.60815,18.099091,353.36511,-9.9728212
155.6716,0.53151691,9.3860655,0.0,0,18.0,330.0,0.98384875,2.531074,18.099272,353.45178,-9.9896097
155.6738,0.52249086,9.3940573,0.0,0,18.0,330.0,0.98331869,2.4698205,18.097834,353.51422,-10.006974
155.676,0.51878303,9.386858,0.0,0,18.0,330.0,0.98396873,2.4486282,18.099512,353.57422,-10.021251
155.6782,0.53515029,9.3976107,0.0,0,18.0,330.0,0.98388362,2.5620828,18.095236,353.63422,-10.037472
155.6804,0.55447787,9.3858519,0.0,0,18.0,330.0,0.98359126,2.5989854,18.093315,353.69424,-10.05318
155.6826,0.5688374,9.3928528,0.0,0,18.0,330.0,0.98348176,2.6943772,18.091862,353.80029,-10.068133
155.6848,0.5616433,9.387887,0.0,0,18.0,330.0,0.98374486,2.6536796,18.093378,353.987,-10.08479
155.687,0.56791747,9.3984699,0.0,0,18.0,330.0,0.98422587,2.6877437,18.092455,354.17368,-10.100429
155.6892,0.55897754,9.3869972,0.0,0,18.0,330.0,0.98344558,2.6308784,18.088768,354.36035,-10.117927
155.6914,0.53438717,9.3948402,0.0,0,18.0,330.0,0.98404205,2.530632,18.089848,354.54706,-10.133679
155.6936,0.52426142,9.3916178,0.0,0,18.0,330.0,0.98382008,2.5075536,18.088587,354.55371,-10.149951
155.6958,0.53648394,9.4006557,0.0,0,18.0,330.0,0.98512387,2.5653405,18.090248,354.52039,-10.166472
155.698,0.55754435,9.3901615,0.0,0,18.0,330.0,0.98371911,2.6052995,18.088501,354.48703,-10.181303
155.7002,0.57570082,9.3935938,0.0,0,18.0,330.0,0.98427832,2.7398477,18.086855,354.4537,-10.196085
155.7024,0.57120168,9.3905993,0.0,0,18.0,330.0,0.98323202,2.7442741,18.088417,354.43671,-10.211991
155.7046,0.57868087,9.3929453,0.0,0,18.0,330.0,0.98429352,2.7417395,18.084902,354.46338,-10.228548
155.7068,0.56286597,9.3901815,0.0,0,18.0,330.0,0.98303401,2.6870003,18.082775,354.49005,-10.244244
155.709,0.55446362,9.3929453,0.0,0,18.0,330.0,0.98460358,2.662102,18.087196,354.51672,-10.259737
155.7112,0.53550899,9.393302,0.0,0,18.0,330.0,0.98357427,2.5542891,18.081709,354.5434,-10.276559
155.7134,0.53399974,9.3926134,0.0,0,18.0,330.0,0.9847492,2.5395927,18.085855,354.6525,-10.294085
155.7156,0.53956509,9.393034,0.0,0,18.0,330.0,0.98328966,2.5459421,18.08634,354.79251,-10.311292
155.7178,0.57384014,9.3883152,0.0,0,18.0,330.0,0.98409301,2.7020404,18.083447,354.9325,-10.325954
155.72,0.57269788,9.3896093,0.0,0,18.0,330.0,0.98257011,2.7388072,18.082817,355.07251,-10.341299
155.7222,0.56511253,9.391346,0.0,0,18.0,330.0,0.98490554,2.6668015,18.081182,355.19556,-10.356106
155.7244,0.5739674,9.3941364,0.0,0,18.0,330.0,0.98304999,2.7362466,18.078333,355.24225,-10.372525
155.7266,0.54876608,9.3874063,0.0,0,18.0,330.0,0.98418522,2.6018288,18.079027,355.28891,-10.388171
155.7288,0.53113288,9.3940573,0.0,0,18.0,330.0,0.98319358,2.5300417,18.08103,355.33557,-10.403702
155.731,0.53452593,9.3915901,0.0,0,18.0,330.0,0.98516726,2.5292296,18.081926,355.38226,-10.420394
155.7332,0.5328818,9.3972015,0.0,0,18.0,330.0,0.98340642,2.5226607,18.080713,355.42892,-10.43606
155.7354,0.55929214,9.3870735,0.0,0,18.0,330.0,0.98405194,2.610847,18.080208,355.47559,-10.453096
155.7376,0.57053524,9.3921156,0.0,0,18.0,330.0,0.9829219,2.7393239,18.076075,355.52228,-10.46894
155.7398,0.57062817,9.3865442,0.0,0,18.0,330.0,0.98420328,2.7291934,18.076372,355.56894,-10.482759
155.742,0.56846833,9.3988094,0.0,0,18.0,330.0,0.9836244,2.6960063,18.075018,355.61136,-10.498515
155.7442,0.56819594,9.3888721,0.0,0,18.0,330.0,0.9844889,2.689575,18.071701,355.61136,-10.514699
155.7464,0.5503971,9.394516,0.0,0,18.0,330.0,0.98322791,2.593349,18.075886,355.61136,-10.532105
155.7486,0.53865969,9.3889074,0.0,0,18.0,330.0,0.98442101,2.5682194,18.07494,355.61136,-10.548993
155.7508,0.54389066,9.4015236,0.0,0,18.0,330.0,0.98444897,2.5767951,18.075523,355.61136,-10.564263
155.753,0.55757719,9.3905487,0.0,0,18.0,330.0,0.98446304,2.6445341,18.071411,355.62592,-10.57993
155.7552,0.5781278,9.394825,0.0,0,18.0,330.0,0.98351985,2.7655361,18.070683,355.65259,-10.596726
155.7574,0.58517861,9.3866997,0.0,0,18.0,330.0,0.98370123,2.7649136,18.074059,355.67926,-10.613185
155.7596,0.5899052,9.3973522,0.0,0,18.0,330.0,0.98390239,2.8137345,18.072241,355.70593,-10.628593
155.7618,0.57013351,9.3889046,0.0,0,18.0,330.0,0.98380971,2.7269592,18.071001,355.7326,-10.64518
155.764,0.57004917,9.3952131,0.0,0,18.0,330.0,0.98406112,2.7056494,18.071102,355.7926,-10.660143
155.7662,0.54264951,9.3905373,0.0,0,18.0,330.0,0.98399389,2.5864797,18.07048,355.8526,-10.676801
155.7684,0.54338026,9.3976116,0.0,0,18.0,330.0,0.98430777,2.59917,18.071016,355.9126,-10.69257
155.7706,0.55135959,9.3890991,0.0,0,18.0,330.0,0.98355103,2.6222718,18.070694,355.97263,-10.708123
155.7728,0.57467288,9.3935242,0.0,0,18.0,330.0,0.98429734,2.7088947,18.070858,356.00534,-10.724098
155.775,0.57959604,9.3902302,0.0,0,18.0,330.0,0.98351717,2.751425,18.066483,356.00534,-10.739496
155.7772,0.58994865,9.3962469,0.0,0,18.0,330.0,0.9846698,2.7929723,18.064152,356.00534,-10.754539
155.7794,0.57562947,9.3898096,0.0,0,18.0,330.0,0.9831236,2.7344151,18.062288,356.00534,-10.769623
155.7816,0.56912744,9.3936577,0.0,0,18.0,330.0,0.98465782,2.7040093,18.061335,356.00534,-10.785386
155.7838,0.55447048,9.3935776,0.0,0,18.0,330.0,0.98375487,2.6589024,18.06424,355.99927,-10.803955
155.786,0.55679351,9.3960762,0.0,0,18.0,330.0,0.98514915,2.6203437,18.063099,355.99261,-10.81927
155.7882,0.55752736,9.3960743,0.0,0,18.0,330.0,0.98367906,2.6232443,18.062653,355.98593,-10.836447
155.7904,0.56264615,9.3912888,0.0,0,18.0,330.0,0.98444158,2.6729231,18.058701,355.97928,-10.851693
155.7926,0.580984,9.3925123,0.0,0,18.0,330.0,0.98316669,2.745152,18.061949,355.9823,-10.866832
155.7948,0.58376235,9.3939657,0.0,0,18.0,330.0,0.98510778,2.7750351,18.063616,356.00232,-10.881214
155.797,0.58644885,9.3961258,0.0,0,18.0,330.0,0.98338342,2.7846413,18.061653,356.02231,-10.898351
155.7992,0.57225072,9.3906088,0.0,0,18.0,330.0,0.98457247,2.7149711,18.06007,356.0423,-10.914826
155.8014,0.55171287,9.3962364,0.0,0,18.0,330.0,0.98365599,2.64994,18.059515,356.06232,-10.93111
155.8036,0.5491581,9.3926706,0.0,0,18.0,330.0,0.98526865,2.6601892,18.063965,356.09323,-10.94769
155.8058,0.54842734,9.3979759,0.0,0,18.0,330.0,0.98355192,2.6071198,18.058922,356.12656,-10.964782
155.808,0.56320721,9.3891783,0.0,0,18.0,330.0,0.98455232,2.6466165,18.060143,356.15988,-10.979974
155.8102,0.57357943,9.3964319,0.0,0,18.0,330.0,0.98354644,2.7042439,18.060726,356.19324,-10.995967
155.8124,0.58062196,9.3889399,0.0,0,18.0,330.0,0.98464084,2.7639592,18.056658,356.23019,-11.011812
155.8146,0.58516991,9.3976898,0.0,0,18.0,330.0,0.98344326,2.7655838,18.058043,356.27689,-11.029011
155.8168,0.57824451,9.38867,0.0,0,18.0,330.0,0.98421329,2.780349,18.059675,356.32355,-11.044482
155.819,0.55911356,9.3968325,0.0,0,18.0,330.0,0.98376292,2.6670749,18.056887,356.37021,-11.058535
155.8212,0.55252826,9.3898973,0.0,0,18.0,330.0,0.98470187,2.6340525,18.05666,356.4169,-11.07551
155.8234,0.55857283,9.3986015,0.0,0,18.0,330.0,0.98387247,2.65031,18.058451,356.42963,-11.092052
155.8256,0.5721342,9.3873634,0.0,0,18.0,330.0,0.98397869,2.6749268,18.053505,356.42963,-11.107966
155.8278,0.56406683,9.3941154,0.0,0,18.0,330.0,0.98350757,2.7056623,18.056326,356.42963,-11.123807
155.83,0.58213598,9.3887796,0.0,0,18.0,330.0,0.98411155,2.7487781,18.055517,356.42963,-11.140008
155.8322,0.58660734,9.4002104,0.0,0,18.0,330.0,0.98443145,2.7917256,18.05707,356.43085,-11.155106
155.8344,0.58818221,9.3917856,0.0,0,18.0,330.0,0.98448104,2.7822719,18.054512,356.4375,-11.171054
155.8366,0.58237791,9.3966007,0.0,0,18.0,330.0,0.98424351,2.8092506,18.056702,356.44415,-11.187073
155.8388,0.55029136,9.3905258,0.0,0,18.0,330.0,0.98403555,2.6419327,18.052729,356.45081,-11.204563
155.841,0.56254691,9.3999147,0.0,0,18.0,330.0,0.98469144,2.6762209,18.051935,356.45749,-11.220443
155.8432,0.56375134,9.3917198,0.0,0,18.0,330.0,0.9840647,2.6748064,18.0527,356.48535,-11.235013
155.8454,0.58871192,9.3953629,0.0,0,18.0,330.0,0.98441988,2.7805648,18.052818,356.52536,-11.251437
155.8476,0.57831365,9.3915787,0.0,0,18.0,330.0,0.98376906,2.7432272,18.054161,356.56537,-11.267058
155.8498,0.58500481,9.3982229,0.0,0,18.0,330.0,0.98487645,2.8355803,18.054461,356.60538,-11.283543
155.852,0.59783012,9.3915567,0.0,0,18.0,330.0,0.98353958,2.8137393,18.053846,356.64236,-11.299043
155.8542,0.58711821,9.3952684,0.0,0,18.0,330.0,0.98450047,2.7963054,18.046871,356.64902,-11.315614
155.8564,0.57653511,9.3922281,0.0,0,18.0,330.0,0.98361623,2.7370553,18.04924,356.6557,-11.332534
155.8586,0.56991398,9.3962564,0.0,0,18.0,330.0,0.98511857,2.6656313,18.047487,356.66235,-11.348226
155.8608,0.56671464,9.3964167,0.0,0,18.0,330.0,0.98394376,2.7092133,18.047001,356.66904,-11.363009
156.6613,0.52653635,9.4011307,0.0,0,18.0,4.1213597e-09,0.98546755,2.5000811,18.002419,325.95715,-11.482532
157.7613,0.49448177,9.4084415,0.0,0,18.0,4.116316e-24,0.98677963,2.3487968,17.999365,302.50815,-11.482193
158.8613,0.48019668,9.4150057,0.0,0,18.0,4.1112794e-39,0.98798388,2.2770097,18.000801,285.07474,-11.482775
159.9613,0.47555631,9.4211054,0.0,0,18.0,1.4012985e-45,0.98903328,2.2477727,17.999334,270.82611,-11.482988
161.0613,0.46973976,9.4265652,0.0,0,18.0,1.4012985e-45,0.9900068,2.2208002,18.000143,258.48761,-11.482658
162.1613,0.46638471,9.4309959,0.0,0,18.0,1.4012985e-45,0.9908576,2.2088711,18.000341,247.71774,-11.48266
163.2613,0.46449059,9.4358978,0.0,0,18.0,1.4012985e-45,0.99171877,2.1964722,17.999672,238.56195,-11.482486
164.3613,0.4654735,9.4396048,0.0,0,18.0,1.4012985e-45,0.99237543,2.2006559,18.000349,230.14337,-11.482747
165.4613,0.46472359,9.4439907,0.0,0,18.0,1.4012985e-45,0.99319828,2.1930051,18.000708,222.33006,-11.482665
166.5613,0.46338201,9.4482613,0.0,0,18.0,1.4012985e-45,0.99393636,2.1877258,18.000862,215.12674,-11.483014
167.6613,0.46184459,9.4521961,0.0,0,18.0,1.4012985e-45,0.99463975,2.1762106,18.000101,208.70921,-11.483521
168.7613,0.46131551,9.4553556,0.0,0,18.0,1.4012985e-45,0.99522871,2.1686051,18.00069,202.56268,-11.483434
169.8613,0.45915309,9.4591331,0.0,0,18.0,1.4012985e-45,0.99589914,2.1649351,18.000231,196.61801,-11.482916
170.9613,0.45807365,9.462635,0.0,0,18.0,1.4012985e-45,0.99652016,2.1576648,18.000113,190.99533,-11.482973
172.0613,0.45632944,9.4656448,0.0,0,18.0,1.4012985e-45,0.99707413,2.1375487,18.000656,185.54448,-11.482954
173.1613,0.45672384,9.4690351,0.0,0,18.0,1.4012985e-45,0.99769109,2.138921,18.000051,180.47923,-11.482962
174.2613,0.45902476,9.4724236,0.0,0,18.0,1.4012985e-45,0.99828565,2.1517234,18.000265,175.54843,-11.482739
175.3613,0.45306563,9.4759684,0.0,0,18.0,1.4012985e-45,0.99890882,2.1218567,17.999054,170.72087,-11.482202
176.4613,0.45331413,9.4786978,0.0,0,18.0,1.4012985e-45,0.99938846,2.1246717,17.999954,166.26181,-11.483088
177.5613,0.45493847,9.4820414,0.0,0,18.0,1.4012985e-45,1.000043,2.1322083,17.998987,161.75714,-11.482759
178.6613,0.45438391,9.4850464,0.0,0,18.0,1.4012985e-45,1.0005606,2.1237688,18.000399,157.72353,-11.482862
179.7613,0.45719793,9.4880972,0.0,0,18.0,1.4012985e-45,1.0011373,2.13715,18.000851,153.73619,-11.483188
180.8613,0.45236182,9.4908361,0.0,0,18.0,1.4012985e-45,1.0016574,2.1162322,18.000259,150.00391,-11.483171
181.9613,0.45451686,9.4934435,0.0,0,18.0,1.4012985e-45,1.0020789,2.1242349,17.999348,146.03693,-11.483439
183.0613,0.45225328,9.4961042,0.0,0,18.0,1.4012985e-45,1.0025768,2.1136899,17.999092,142.20465,-11.483161
184.1613,0.45162004,9.4984283,0.0,0,18.0,1.4012985e-45,1.00306,2.1069694,18.000313,138.67122,-11.48294
185.2613,0.44785941,9.5015297,0.0,0,18.0,1.4012985e-45,1.0035467,2.0926809,18.00082,135.24849,-11.482638
186.3613,0.45321733,9.5042448,0.0,0,18.0,1.4012985e-45,1.0040658,2.116879,17.999575,131.85989,-11.482641
187.4613,0.45762676,9.5060015,0.0,0,18.0,1.4012985e-45,1.0044274,2.1317022,17.999706,128.70654,-11.482692
188.5613,0.45249969,9.5087643,0.0,0,18.0,1.4012985e-45,1.0048581,2.109144,17.99951,125.76323,-11.482013
189.6613,0.4482722,9.5107775,0.0,0,18.0,1.4012985e-45,1.005259,2.0883434,17.999315,122.68663,-11.482742
190.7613,0.44649342,9.5128107,0.0,0,18.0,1.4012985e-45,1.0056688,2.0819187,17.999598,119.84775,-11.482639
191.8613,0.45051023,9.515233,0.0,0,18.0,1.4012985e-45,1.0060247,2.0976009,17.999428,117.04702,-11.482736
192.9613,0.44861984,9.5175533,0.0,0,18.0,1.4012985e-45,1.0064723,2.0851719,17.99976,114.33456,-11.4828
194.0613,0.44567144,9.519453,0.0,0,18.0,1.4012985e-45,1.0068949,2.078028,18.000765,111.64867,-11.483076
195.1613,0.45324057,9.5217609,0.0,0,18.0,1.4012985e-45,1.0072105,2.109935,18.000061,109.1632,-11.483263
196.2613,0.45592567,9.5231724,0.0,0,18.0,1.4012985e-45,1.0075269,2.1177995,18.000452,106.60751,-11.482931
197.3613,0.45100275,9.5255327,0.0,0,18.0,1.4012985e-45,1.008001,2.0959063,18.000177,104.22615,-11.483018
198.4613,0.4435128,9.5274019,0.0,0,18.0,1.4012985e-45,1.0082315,2.0597336,17.999121,101.8319,-11.483223
199.5613,0.44563246,9.5287619,0.0,0,18.0,1.4012985e-45,1.0085676,2.0741055,17.999857,99.674774,-11.482862
200.6613,0.44863799,9.5304899,0.0,0,18.0,1.4012985e-45,1.0089201,2.0844004,18.000626,97.51638,-11.482057
201.7613,0.4447026,9.5321226,0.0,0,18.0,1.4012985e-45,1.0090564,2.0628624,18.000343,95.441971,-11.482349
202.8613,0.44507068,9.533618,0.0,0,18.0,1.4012985e-45,1.0094652,2.0624931,18.000494,93.356651,-11.482092
203.9613,0.44556123,9.5353184,0.0,0,18.0,1.4012985e-45,1.0098058,2.0652781,18.000103,91.240036,-11.482055
205.0613,0.4451431,9.5369511,0.0,0,18.0,1.4012985e-45,1.0099657,2.0655901,18.000692,89.347389,-11.482311
206.1613,0.45281911,9.538765,0.0,0,18.0,1.4012985e-45,1.0104076,2.103682,17.999517,87.460152,-11.4824
207.2613,0.4504934,9.5396757,0.0,0,18.0,1.4012985e-45,1.0105907,2.0884888,17.999971,85.453941,-11.482838
208.3613,0.44826514,9.5415411,0.0,0,18.0,1.4012985e-45,1.0107991,2.0794883,17.999393,83.734894,-11.482597
209.4613,0.44274101,9.5429201,0.0,0,18.0,1.4012985e-45,1.0111963,2.0506206,17.99966,82.077438,-11.482953
210.5613,0.44209051,9.5439587,0.0,0,18.0,1.4012985e-45,1.011358,2.0457096,17.999855,80.249855,-11.482549
211.6613,0.44362679,9.5456791,0.0,0,18.0,1.4012985e-45,1.0115674,2.059238,17.999943,78.76413,-11.483164
212.7613,0.44445571,9.5472527,0.0,0,18.0,1.4012985e-45,1.0119759,2.0511196,18.000797,77.162727,-11.483205
213.8613,0.44692835,9.5486116,0.0,0,18.0,1.4012985e-45,1.0122072,2.0701628,18.000076,75.577255,-11.48282
214.9613,0.44226378,9.5496693,0.0,0,18.0,1.4012985e-45,1.0123158,2.0453181,18.000616,74.173485,-11.483278
215.8613,0.44258609,9.5506277,0.0,0,18.0,1.4012985e-45,1.0125518,2.051192,18.000185,73.054855,-11.482822