File: examples/hot axisymmetric compression example/data/02 screened data/testID_0146.csv
Time(sec),Force(kN),Jaw(mm),PowAngle(deg),Power(W),Pram,PTemp,Strain,Stress(MPa),Stroke(mm),TC1(C),wedge(mm)
0.0,0.94066703,8.4200306,0.0,0,11.076097,0.0016423148,0.82404876,5.253881,11.076062,22.136414,-9.136405
1.2,0.88003403,-0.0052339993,0.0,0,11.076097,3.5159171,-0.00037325182,11.208546,11.076087,22.124807,-9.4967928
2.4,0.84536666,-0.0057052653,0.0,0,11.076097,7.1159158,-0.00032001644,10.768711,11.076574,22.204458,-9.4946547
3.6,0.83033949,-0.0056945519,0.0,0,11.076097,10.715918,-0.00039899067,10.572601,11.076202,22.143394,-9.4932957
4.8,0.87936139,-0.0053041871,0.0,0,11.076097,14.315918,-0.00039427413,11.190402,11.076135,22.161493,-9.4983454
6.0,0.82480234,-0.0061158254,0.0,0,11.076097,17.915913,-0.00040542756,10.496899,11.075765,22.190113,-9.4942389
7.2,0.79954046,-0.0060018068,0.0,0,11.076097,21.515913,-0.00040426836,10.185089,11.076335,22.201176,-9.4907789
8.4,0.79964721,-0.0058452818,17.677067,0,11.076097,25.115911,-0.00037079118,10.178385,11.076271,22.13109,-9.4900379
9.6,0.79326814,-0.0063968403,30.834801,0,11.076097,28.715914,-0.00044583782,10.101851,11.076323,23.055065,-9.4881725
10.8,0.79599714,-0.008834484,38.24815,0,11.076097,32.31591,-0.00055371947,10.138345,11.076485,25.497919,-9.4853764
12.0,0.80892891,-0.011563885,41.802494,0,11.076097,35.915913,-0.00074364495,10.292678,11.076317,29.391895,-9.4831047
13.2,0.82296789,-0.014557499,43.734974,0,11.076097,39.515903,-0.0010105391,10.487335,11.076014,34.210854,-9.4810867
14.4,0.82141805,-0.018563965,44.17321,0,11.076097,43.115902,-0.0011872639,10.464193,11.07642,39.390076,-9.4782724
15.6,0.8331151,-0.021776775,44.077152,0,11.076097,46.7159,-0.0014635425,10.63739,11.075969,44.625923,-9.4760656
16.8,0.83919585,-0.024469126,43.029732,0,11.076097,50.315895,-0.0016751381,10.701708,11.076311,49.626102,-9.4741182
18.0,0.8209939,-0.027956795,42.396244,0,11.076097,53.915897,-0.0018256748,10.477116,11.075201,54.094585,-9.4710541
19.2,0.81955057,-0.029912587,41.802982,0,11.076097,57.5159,-0.0020267845,10.455144,11.076142,58.078617,-9.4682789
20.4,0.81386501,-0.032287665,41.198738,0,11.076097,61.115898,-0.0022029504,10.377638,11.075903,61.640709,-9.4658689
21.6,0.80602223,-0.034831315,41.728664,0,11.076097,64.715919,-0.0023226582,10.275651,11.075852,64.888496,-9.4629936
22.8,0.82142746,-0.036545828,42.113125,0,11.076097,68.315903,-0.0024695003,10.491352,11.077486,68.072365,-9.4616156
24.0,0.82469511,-0.038622588,42.978512,0,11.076097,71.915909,-0.0026044701,10.524122,11.075357,71.151146,-9.4590559
25.2,0.8255437,-0.04141362,43.605511,0,11.076097,75.515907,-0.0027434193,10.531284,11.076225,74.510994,-9.456686
26.4,0.83064497,-0.044104669,44.35218,0,11.076097,79.115906,-0.0029582893,10.61088,11.076604,78.099083,-9.4546404
27.6,0.8237257,-0.046684947,44.604488,0,11.076097,82.715904,-0.0031380032,10.517907,11.076694,81.728729,-9.4523258
28.8,0.83455759,-0.049725834,45.12085,0,11.076097,86.315903,-0.0033050771,10.657807,11.076243,85.425041,-9.4503508
30.0,0.84559584,-0.052180842,45.120953,0,11.076097,89.915894,-0.0035046784,10.80884,11.076305,89.234352,-9.4487314
31.2,0.83711481,-0.054793976,45.615231,0,11.076097,93.5159,-0.0036798022,10.685913,11.076056,92.974411,-9.4466238
32.4,0.84342146,-0.058193263,45.615231,0,11.076097,97.115891,-0.0038623889,10.782493,11.076507,96.626503,-9.4442415
33.6,0.84407222,-0.060708869,45.615231,0,11.076097,100.71589,-0.0040693395,10.780632,11.076833,100.37337,-9.4421835
34.8,0.857391,-0.064100713,45.782063,0,11.076097,104.31588,-0.0042967871,10.967342,11.07637,103.99949,-9.4393787
36.0,0.82194072,-0.067787223,46.109619,0,11.076097,107.91589,-0.0044739954,10.504661,11.07619,107.56368,-9.4359665
37.2,0.84457022,-0.069737621,46.109619,0,11.076097,111.51589,-0.004664626,10.794048,11.076396,111.16798,-9.4331732
38.4,0.8553288,-0.071704678,46.110142,0,11.076097,115.11588,-0.0048251087,10.929175,11.076523,114.81114,-9.4324732
39.6,0.84183282,-0.075151622,46.581757,0,11.076097,118.71589,-0.0049423501,10.772582,11.075887,118.35343,-9.4304037
40.8,0.83949375,-0.077933259,46.582027,0,11.076097,122.3159,-0.0051565915,10.743571,11.076056,121.88416,-9.4282179
42.0,0.82560623,-0.080812253,47.054436,0,11.076097,125.91589,-0.0053979256,10.577219,11.076168,125.42352,-9.4237652
43.2,0.84999204,-0.084030151,47.495399,0,11.076097,129.51601,-0.0055515594,10.870215,11.076436,128.84465,-9.4222059
44.4,0.85049176,-0.086723112,47.504883,0,11.076097,133.11588,-0.0057457327,10.892575,11.076187,132.40674,-9.4204903
45.6,0.85849017,-0.089775689,47.955318,0,11.076097,136.71588,-0.0059635397,10.997773,11.075951,136.05289,-9.4190168
46.8,0.86150533,-0.09270446,48.244381,0,11.076097,140.31589,-0.0061928113,11.016951,11.076013,139.60043,-9.4169598
48.0,0.84545463,-0.096390337,48.383785,0,11.076097,143.91588,-0.0064450386,10.824942,11.075987,143.24417,-9.4113798
49.2,0.86543387,-0.099774979,48.757122,0,11.076097,147.51588,-0.0065917023,11.087513,11.075615,146.94159,-9.4098587
50.4,0.84374511,-0.10209032,48.812252,0,11.076097,151.11588,-0.0067708851,10.807648,11.07662,150.63646,-9.4063635
51.6,0.86451405,-0.10505547,48.812252,0,11.076097,154.71588,-0.00701113,11.074561,11.076025,154.35663,-9.4043798
52.8,0.87281275,-0.10826238,49.052162,0,11.076097,158.31589,-0.007172714,11.194021,11.076097,157.98717,-9.4029388
54.0,0.87203997,-0.11138454,49.229427,0,11.076097,161.91588,-0.0073947161,11.184298,11.077038,161.63803,-9.4010458
55.2,0.88187987,-0.11473841,49.160881,0,11.076097,165.51587,-0.0076039904,11.314463,11.07644,165.39395,-9.3990326
56.4,0.8713026,-0.1179387,49.010387,0,11.076097,169.11588,-0.0078535564,11.196411,11.076043,169.06398,-9.3963032
57.6,0.882442,-0.12067384,48.933933,0,11.076097,172.71588,-0.0080581699,11.307785,11.075414,172.71259,-9.3942928
58.8,0.88334125,-0.12375446,49.207848,0,11.076097,176.31589,-0.008179035,11.339905,11.076046,176.26265,-9.3918552
60.0,0.89880717,-0.12735339,49.229733,0,11.076097,179.91588,-0.0084308609,11.541718,11.07542,179.76187,-9.3897886
61.2,0.89644927,-0.13127483,49.229733,0,11.076097,183.51588,-0.0087080514,11.523007,11.076473,183.26286,-9.3881321
62.4,0.90367854,-0.13410206,49.636227,0,11.076097,187.11589,-0.0089258207,11.611624,11.076722,186.7029,-9.3859797
63.6,0.90352035,-0.13636696,50.022835,0,11.076097,190.71587,-0.0090681501,11.611281,11.076123,190.11798,-9.383606
64.8,0.90185112,-0.13945311,50.042759,0,11.076097,194.31587,-0.0092170611,11.608033,11.076398,193.72591,-9.3814087
66.0,0.90482372,-0.14239959,50.438198,0,11.076097,197.91586,-0.0094658872,11.635029,11.077406,197.36526,-9.3794069
67.2,0.89722788,-0.14563049,50.438229,0,11.076097,201.51587,-0.0096256603,11.537422,11.07653,200.9904,-9.3772879
68.4,0.90047765,-0.14867315,50.817024,0,11.076097,205.11588,-0.0098609282,11.57866,11.076261,204.60106,-9.3754406
69.6,0.90536731,-0.15197924,50.82275,0,11.076097,208.71587,-0.010105652,11.644364,11.076215,208.33247,-9.373167
70.8,0.89781731,-0.15547003,50.822773,0,11.076097,212.31586,-0.010309692,11.551608,11.07643,211.98787,-9.37082
72.0,0.90895247,-0.15830864,51.178875,0,11.076097,215.91586,-0.010538157,11.700126,11.07632,215.54453,-9.3690853
73.2,0.89726752,-0.16259301,51.196285,0,11.076097,219.51587,-0.010732067,11.548902,11.076138,219.21191,-9.3671904
74.4,0.90487909,-0.16564098,51.196285,0,11.076097,223.11586,-0.010955614,11.64353,11.07585,222.8674,-9.3651371
75.6,0.90866655,-0.16906597,51.196285,0,11.076097,226.71587,-0.01120111,11.693032,11.075817,226.49489,-9.3628416
76.8,0.91383028,-0.1733388,51.196285,0,11.076097,230.31586,-0.011496753,11.765431,11.07564,230.09544,-9.3606529
78.0,0.91555619,-0.17680554,51.377754,0,11.076097,233.91586,-0.011738208,11.793857,11.076496,233.66176,-9.3584232
79.2,0.91761261,-0.17937478,51.569775,0,11.076097,237.51587,-0.011903831,11.829295,11.077075,237.21104,-9.3567266
80.4,0.91318911,-0.18257529,51.56982,0,11.076097,241.11588,-0.012142,11.780629,11.075538,240.8606,-9.3542109
81.6,0.91188872,-0.18649355,51.75256,0,11.076097,244.71587,-0.012307853,11.765352,11.07594,244.39162,-9.3523378
82.8,0.90783036,-0.18970399,51.911591,0,11.076097,248.31586,-0.012568891,11.708181,11.076549,248.01288,-9.3502483
84.0,0.91457337,-0.19335958,51.932369,0,11.076097,251.91586,-0.012771083,11.803562,11.076238,251.54092,-9.3484697
85.2,0.90720725,-0.19654602,52.093201,0,11.076097,255.51587,-0.013000465,11.692505,11.075703,255.14667,-9.34587
86.4,0.92165971,-0.20155105,52.1954,0,11.076097,259.11612,-0.013343451,11.89525,11.075562,258.85461,-9.344058
87.6,0.92114097,-0.20370711,52.283936,0,11.076097,262.71588,-0.013508453,11.892559,11.075509,262.44717,-9.3418093
88.8,0.9169758,-0.20675214,52.283936,0,11.076097,266.31586,-0.013707762,11.84866,11.075588,266.12402,-9.3396778
90.0,0.90718532,-0.21025716,52.283936,0,11.076097,269.91586,-0.013962706,11.70771,11.075987,269.8089,-9.3372574
91.2,0.91589886,-0.21351694,52.283924,0,11.076097,273.51587,-0.014158925,11.838304,11.076164,273.48157,-9.3355923
92.4,0.91347909,-0.21743572,52.152424,0,11.076097,277.11584,-0.014376118,11.804734,11.076186,277.10995,-9.3334246
93.6,0.92361051,-0.22153138,52.283936,0,11.076097,280.71582,-0.014706933,11.938409,11.076331,280.65961,-9.3315239
94.8,0.92965996,-0.22537009,52.250195,0,11.076097,284.31583,-0.014888329,12.018646,11.076876,284.28293,-9.3294325
96.0,0.92485267,-0.22742096,52.277256,0,11.076097,287.91583,-0.015083269,11.974272,11.076124,287.89304,-9.3275118
97.2,0.9186849,-0.23125292,52.283936,0,11.076097,291.51581,-0.015244869,11.88008,11.076226,291.44818,-9.3251848
98.4,0.91545242,-0.23445539,52.283936,0,11.076097,295.11581,-0.015524442,11.846899,11.076956,294.88965,-9.3232412
99.6,0.91290265,-0.23836258,52.635494,0,11.076097,298.71585,-0.01570704,11.817401,11.076884,298.31534,-9.3213778
100.8,0.91622907,-0.24175546,52.768723,0,11.076097,302.3158,-0.015974078,11.842804,11.076061,301.83688,-9.3193226
102.0,0.92407447,-0.24675751,52.97607,0,11.076097,305.91583,-0.016268088,11.962516,11.076812,305.47217,-9.3171158
103.2,0.93170077,-0.24998568,52.97607,0,11.076097,309.51584,-0.016510149,12.064996,11.076254,309.06708,-9.3150892
104.4,0.92681634,-0.25218037,53.198696,0,11.076097,313.11584,-0.016637929,12.015574,11.076053,312.71088,-9.3130875
105.6,0.92063689,-0.2557652,53.316551,0,11.076097,316.71579,-0.016892347,11.930931,11.076109,316.43481,-9.3108435
106.8,0.91996425,-0.25968975,53.31665,0,11.076097,320.31583,-0.0171367,11.922335,11.076591,320.0015,-9.3089485
108.0,0.92245108,-0.26294786,53.31665,0,11.076097,323.91583,-0.017352534,11.963172,11.076608,323.63321,-9.3068647
109.2,0.91160965,-0.26713556,53.329956,0,11.076097,327.51587,-0.017611356,11.80634,11.076086,327.28308,-9.3046484
110.4,0.93271059,-0.27082169,53.410622,0,11.076097,331.11584,-0.017866751,12.081067,11.076422,330.88541,-9.3027859
111.6,0.93363899,-0.27570283,53.657223,0,11.076097,334.71585,-0.018169338,12.118286,11.076352,334.42438,-9.3009872
112.8,0.92532331,-0.27699509,53.827019,0,11.076097,338.31586,-0.018283753,11.990318,11.076362,337.85971,-9.2985878
114.0,0.92012662,-0.28136659,54.129261,0,11.076097,341.91586,-0.018528104,11.935104,11.076408,341.23572,-9.2967749
115.2,0.91660392,-0.28495875,54.305416,0,11.076097,345.51587,-0.018813968,11.896549,11.076608,344.8089,-9.2948389
116.4,0.92903799,-0.28992617,54.614635,0,11.076097,349.11588,-0.01907731,12.058659,11.075806,348.54205,-9.2927685
117.6,0.93260789,-0.29156169,54.305424,0,11.076097,352.71585,-0.019291325,12.099205,11.075536,352.51422,-9.2907953
118.8,0.91660273,-0.29634446,54.228668,0,11.076097,356.31586,-0.019519007,11.897736,11.075843,356.43878,-9.2882214
120.0,0.91558307,-0.29961467,53.975834,0,11.076097,359.91586,-0.019816244,11.885499,11.076324,360.3147,-9.2864027
121.2,0.93422294,-0.30387655,53.696732,0,11.076097,363.51587,-0.020042565,12.13089,11.075831,363.94611,-9.2844524
122.4,0.92508501,-0.30659625,53.65723,0,11.076097,367.11588,-0.020280782,12.021433,11.076004,367.53564,-9.2824965
123.6,0.92307985,-0.31082276,53.592037,0,11.076097,370.71585,-0.020503264,11.992261,11.076015,370.99042,-9.2806902
124.8,0.93913728,-0.31540132,53.514442,0,11.076097,374.31586,-0.020846281,12.20805,11.075782,374.60342,-9.2783527
126.0,0.93142688,-0.31737411,53.631668,0,11.076097,377.91586,-0.020969376,12.107184,11.075736,378.05017,-9.2762251
127.2,0.92342812,-0.32163814,53.41515,0,11.076097,381.51587,-0.021231173,12.005433,11.076159,381.62497,-9.2743387
128.4,0.93190324,-0.32659313,53.649956,0,11.076097,385.11584,-0.021537479,12.123625,11.07624,385.11578,-9.2723618
129.6,0.93692631,-0.32802224,53.557247,0,11.076097,388.71585,-0.021631075,12.186425,11.076625,388.75461,-9.2704563
130.8,0.92178673,-0.33259758,53.407715,0,11.076097,392.31583,-0.02191136,11.996146,11.076283,392.3895,-9.2679844
132.0,0.92454749,-0.3358025,53.657223,0,11.076097,395.91583,-0.022108912,12.030332,11.076223,395.84091,-9.2665739
133.2,0.94160581,-0.33946225,53.657223,0,11.076097,399.51581,-0.022411902,12.268768,11.07556,399.34756,-9.2642813
134.4,0.92722529,-0.34323338,53.706268,0,11.076097,403.11584,-0.022591988,12.069669,11.076402,402.91748,-9.2620964
135.6,0.91604799,-0.34723964,53.814022,0,11.076097,406.71585,-0.022932652,11.939717,11.076645,406.55621,-9.260211
136.8,0.94090033,-0.35271555,53.88839,0,11.076097,410.31583,-0.023269946,12.255469,11.076446,410.17181,-9.2583408
138.0,0.93873435,-0.35337836,53.975826,0,11.076097,413.91583,-0.023300575,12.231917,11.076341,413.76904,-9.2563581
139.2,0.92376184,-0.35845214,53.975826,0,11.076097,417.51584,-0.023618393,12.033798,11.075791,417.38391,-9.2541208
140.4,0.92240697,-0.36182502,53.975826,0,11.076097,421.11581,-0.02381748,12.029567,11.076498,420.97443,-9.2524137
141.6,0.94028944,-0.36615705,53.975826,0,11.076097,424.71582,-0.024109995,12.258078,11.075987,424.59723,-9.2500982
142.8,0.93214571,-0.36973858,53.977032,0,11.076097,428.31583,-0.024291821,12.158687,11.076217,428.14841,-9.2483215
144.0,0.91313177,-0.37417501,54.291584,0,11.076097,431.91583,-0.024680598,11.92165,11.076695,431.67072,-9.246088
145.2,0.93728614,-0.37997189,54.028675,0,11.076097,435.51584,-0.025003392,12.222768,11.076484,435.45013,-9.2444811
146.4,0.93581426,-0.38159844,54.305412,0,11.076097,439.11584,-0.025144765,12.218021,11.076526,438.99042,-9.2423859
147.6,0.92789078,-0.38687578,53.97884,0,11.076097,442.71582,-0.025473457,12.115423,11.075602,442.76364,-9.2401791
148.8,0.91724867,-0.39096129,53.977272,0,11.076097,446.31583,-0.025720419,11.973936,11.076236,446.33066,-9.2381973
150.0,0.94566911,-0.39624599,54.292507,0,11.076097,449.91583,-0.026064755,12.351024,11.076197,449.83438,-9.236249
151.2,0.93548501,-0.39828512,54.305416,0,11.076097,453.51584,-0.026166992,12.225767,11.07627,453.36127,-9.2340956
152.4,0.92440885,-0.40307191,54.305416,0,11.076097,457.11584,-0.026562475,12.093956,11.076262,456.91672,-9.2324915
153.6,0.92811638,-0.40661004,54.305416,0,11.076097,460.71585,-0.02677168,12.128111,11.075704,460.63773,-9.2303457
154.8,0.94413674,-0.41187757,54.305416,0,11.076097,464.31583,-0.027103826,12.346036,11.076503,464.28604,-9.2282934
156.0,0.92713237,-0.41540915,54.305416,0,11.076097,467.91583,-0.027295688,12.141976,11.07652,468.02039,-9.2262993
157.2,0.9272064,-0.42020053,54.305416,0,11.076097,471.51584,-0.02758613,12.131117,11.076694,471.53116,-9.2246113
158.4,0.9385466,-0.42398652,54.305416,0,11.076097,475.11584,-0.027897535,12.289798,11.076355,475.11136,-9.2225037
159.6,0.94263619,-0.42656893,54.305416,0,11.076097,478.71585,-0.028066393,12.34699,11.075968,478.59995,-9.2202578
160.8,0.93383032,-0.43222705,54.621311,0,11.076097,482.31583,-0.02839624,12.247418,11.07629,482.07666,-9.2182465
162.0,0.91499096,-0.43733045,54.624023,0,11.076097,485.91583,-0.028739734,11.980551,11.076781,485.66022,-9.2164516
163.2,0.9442541,-0.44263846,54.624023,0,11.076097,489.51578,-0.029071644,12.374617,11.076928,489.35071,-9.214551
164.4,0.94006425,-0.44414967,54.467815,0,11.076097,493.11581,-0.029201083,12.33735,11.075936,493.17926,-9.2128
165.6,0.92752892,-0.44913876,54.305424,0,11.076097,496.71579,-0.02947668,12.167358,11.075643,497.09711,-9.2103462
166.8,0.93737143,-0.45300141,53.983482,0,11.076097,499.99759,-0.029696101,12.286329,11.076469,500.56201,-9.2084589
168.0,0.12136822,-0.46356747,53.31665,0,11.076097,499.99884,-0.03047709,1.5899848,11.07671,500.77914,-9.2086058
169.2,0.11402617,-0.46255255,54.305389,0,11.076097,499.99884,-0.030406153,1.4998112,11.07598,499.34839,-9.2086163
170.4,0.10819524,-0.46341574,54.92971,0,11.076097,499.99884,-0.030440357,1.4288871,11.07602,498.99988,-9.2084827
171.6,0.13997696,-0.46459043,55.143929,0,11.076097,499.99884,-0.030514522,1.8250611,11.075394,499.13135,-9.2083836
172.8,0.14413927,-0.46377864,54.931644,0,11.076097,499.99884,-0.030452857,1.8887622,11.07655,499.70743,-9.2086134
174.0,0.13233911,-0.46597424,54.432606,0,11.076097,499.99884,-0.030601891,1.7282884,11.07635,500.3403,-9.2086134
175.2,0.12852159,-0.46708006,53.975834,0,11.076097,499.99884,-0.030641977,1.6806171,11.076205,500.91959,-9.2087927
176.4,0.14399746,-0.46878576,53.317638,0,11.076097,499.99884,-0.03072832,1.8894421,11.076378,501.2417,-9.2084894
177.6,0.14613414,-0.46757519,52.639206,0,11.076097,499.99884,-0.030725216,1.935921,11.075533,501.56036,-9.2084475
178.8,0.13378683,-0.4687919,52.283939,0,11.076097,499.99884,-0.030758655,1.7500265,11.076137,501.56067,-9.208477
180.0,0.12279797,-0.4696033,51.932377,0,11.076097,499.99884,-0.030782603,1.6117797,11.076098,501.36011,-9.2080784
181.2,0.12759519,-0.46926704,51.880054,0,11.076097,499.99884,-0.030854639,1.6587317,11.075181,500.89948,-9.2082777
182.4,0.14207751,-0.47164437,51.886135,0,11.076097,499.99884,-0.030972959,1.8667879,11.076383,500.55298,-9.2082367
183.6,0.1453492,-0.46993226,51.932369,0,11.076097,499.99884,-0.030809339,1.9148217,11.07676,500.2919,-9.2083073
184.8,0.13954897,-0.47072101,51.932369,0,11.076097,499.99884,-0.030936802,1.8355163,11.076503,500.08871,-9.208292
186.0,0.13799737,-0.47155482,51.933632,0,11.076097,499.99884,-0.030976353,1.816471,11.075757,499.90878,-9.2082539
187.2,0.13754496,-0.47291237,52.283936,0,11.076097,499.99884,-0.031009983,1.8103318,11.075676,499.74014,-9.2082319
188.4,0.15069431,-0.47329193,52.635494,0,11.076097,499.99884,-0.031100387,1.9723374,11.07594,499.52899,-9.2082577
189.6,0.15679339,-0.47562712,52.635494,0,11.076097,499.99884,-0.03124848,2.0557499,11.076101,499.54211,-9.208252
190.8,0.14733525,-0.47509018,52.863014,0,11.076097,499.99884,-0.03115245,1.9378464,11.076135,499.55057,-9.2080183
192.0,0.15002796,-0.47597453,52.662182,0,11.076097,499.99884,-0.031282395,1.9824084,11.076618,499.80103,-9.2082157
193.2,0.14392996,-0.47753933,52.635502,0,11.076097,499.99884,-0.03135898,1.8898255,11.075904,500.03653,-9.2082243
194.4,0.13925953,-0.47886086,52.284069,0,11.076097,499.99884,-0.031390149,1.8326041,11.075788,500.3717,-9.2080498
195.6,0.13798931,-0.47979137,51.932518,0,11.076097,499.99884,-0.031532764,1.8119886,11.076693,500.69931,-9.2082548
196.8,0.14558734,-0.48022556,51.608097,0,11.076097,499.99884,-0.031504158,1.9027103,11.077073,500.67191,-9.2080755
198.0,0.15634203,-0.48276556,51.569828,0,11.076097,499.99884,-0.031623453,2.0542734,11.076481,500.677,-9.2079639
199.2,0.15665586,-0.48082131,51.196293,0,11.076097,499.99884,-0.031584725,2.0492253,11.076514,500.62979,-9.2083941
200.4,0.15464826,-0.48087925,51.196293,0,11.076097,499.99884,-0.031529684,2.0303295,11.07659,500.41843,-9.2081299
201.6,0.15118438,-0.4817889,51.196442,0,11.076097,499.99884,-0.031592239,1.9959699,11.076251,500.19128,-9.2081842
202.8,0.14862633,-0.48261523,51.569798,0,11.076097,499.99884,-0.031670835,1.9565395,11.075748,499.92856,-9.2080555
204.0,0.14667839,-0.48347512,51.56982,0,11.076097,499.99884,-0.03171866,1.9381326,11.076275,499.85168,-9.2082157
205.2,0.14520635,-0.4843407,51.575508,0,11.076097,499.99884,-0.031807672,1.907854,11.076214,499.78021,-9.2081633
206.4,0.14501843,-0.48573205,51.932369,0,11.076097,499.99884,-0.031862341,1.9041467,11.075377,499.73947,-9.2080479
207.6,0.15524325,-0.48604259,51.793976,0,11.076097,499.99884,-0.031929169,2.0202997,11.0759,499.9039,-9.2079887
208.8,0.16358346,-0.48850462,51.569828,0,11.076097,499.99884,-0.03205575,2.1544776,11.075914,500.07001,-9.2081261
210.0,0.15912308,-0.48903286,51.569828,0,11.076097,499.99884,-0.032028835,2.1055226,11.076172,500.10364,-9.2079382
211.2,0.15841247,-0.48812217,51.569828,0,11.076097,499.99884,-0.032054197,2.0815899,11.076332,500.07397,-9.2080765
211.96,0.31278163,0.081994072,51.569824,0,11.076099,0.1542871,0.0055661127,3.9541094,11.075259,500.17523,-9.2082834
211.9624,0.31402808,0.081129827,51.569824,0,11.076099,6.669826499999999e-18,0.0052414327,3.9384491,11.076567,500.17523,-9.2075901
211.9648,0.33307615,0.088648602,51.569824,0,11.076099,2.8833644e-34,0.0055355388,4.3015237,11.07495,500.17523,-9.2078724
211.9672,0.31419396,0.086257681,48.475616,0,11.076099,0.0,0.0056253998,4.0218139,11.075578,500.17343,-9.207387
211.9696,0.31417769,0.08463861,36.098858,0,11.076099,0.0,0.0057938234,3.9231811,11.074265,500.16629,-9.208395
211.972,0.39529896,0.080677249,23.722101,0,11.076099,0.0,0.0056742895,5.0894737,11.075114,500.15912,-9.2084398
211.9744,0.30480403,0.083572574,11.345343,0,11.076099,0.0,0.0057241386,3.852819,11.076994,500.15195,-9.2087221
211.9768,0.32282746,0.081860304,0.0,0,11.076099,0.0,0.0053896559,4.1948438,11.075496,500.12866,-9.2068758
211.9792,0.31770617,0.082479239,0.0,0,11.076099,0.0,0.0053766044,4.0652852,11.074631,499.92813,-9.2079945
211.9816,0.31490484,0.082520723,0.0,0,11.076099,0.0,0.0054491092,4.00629,11.078298,499.72757,-9.2077751
211.984,0.31549045,0.082056798,0.0,0,11.076099,0.0,0.0054937201,3.9685824,11.077316,499.52701,-9.2080803
211.9864,0.31241682,0.080986127,0.0,0,11.076099,0.0,0.0055817128,3.9261415,11.078012,499.32648,-9.2083979
211.9888,0.30858964,0.082037993,0.0,0,11.076099,0.0,0.0055864751,3.9393764,11.077813,499.38855,-9.2086926
211.9912,0.32185844,0.083218284,0.0,0,11.076099,0.0,0.0055271396,4.0201273,11.077493,499.47452,-9.2075491
211.9936,0.32710359,0.087485209,0.0,0,11.076099,0.0,0.0056210118,4.1331058,11.077259,499.56046,-9.2075882
211.996,0.32647675,0.088765845,0.0,0,11.076099,0.0,0.0056778137,4.1334782,11.074954,499.64642,-9.2071362
211.9984,0.32381788,0.08814384,0.0,0,11.076099,0.0,0.0058468655,4.1330819,11.077785,499.68939,-9.2085972
212.0008,0.32385796,0.085585274,0.0,0,11.076099,0.0,0.0059206476,4.1226144,11.073474,499.71805,-9.2076235
212.0032,0.3363376,0.082347259,0.0,0,11.076099,0.0,0.0057286434,4.1670146,11.078291,499.74667,-9.2084942
212.0056,0.3415356,0.082502671,0.0,0,11.076099,0.0,0.0054868013,4.3761449,11.075601,499.77533,-9.2083502
212.008,0.32829162,0.08269728,0.0,0,11.076099,0.0,0.0053873728,4.1210175,11.07499,499.79144,-9.2083664
212.0104,0.32140696,0.083682038,0.0,0,10.946387,0.0,0.0054935087,4.1334925,11.075657,499.79861,-9.2078934
212.0128,0.34127706,0.084788881,0.0,0,10.585414,0.0,0.0056435801,4.3338065,11.080042,499.80576,-9.2081451
212.0152,0.34996334,0.084040999,0.0,0,10.224441,0.0,0.0057532177,4.3555465,11.052872,499.81293,-9.2089062
212.0176,0.34408578,0.083082981,0.0,0,9.8634663,0.0,0.0058065192,4.5011044,10.908978,500.31241,-9.2084341
212.02,0.35842708,0.084500737,0.0,0,9.5024929,0.0,0.0057143248,4.4228649,10.619217,501.5011,-9.2096024
212.0224,0.33235022,0.087468907,0.0,0,9.1507626,0.0,0.0057300422,4.3038831,10.219775,502.68979,-9.2083197
212.0248,4.4508109,0.56700265,0.0,0,8.7995939,0.0,0.037605017,53.676464,9.7101793,503.87851,-9.204071
212.0272,5.0555577,1.0148721,0.0,0,8.4631929,0.0,0.069096476,59.814976,9.1416817,504.75391,-9.2036943
212.0296,4.6784902,1.495679,0.0,0,8.1292095,0.0,0.10479677,54.03093,8.6611557,504.68942,-9.203311
212.032,4.9283366,1.840879,0.0,0,7.8078156,0.0,0.13098441,55.037472,8.3016462,504.62497,-9.2042236
212.0344,5.0323477,2.1027398,0.0,0,7.4900556,0.0,0.15087384,55.235931,8.0207949,504.56049,-9.203516
212.0368,5.1207757,2.3517909,0.0,0,7.1830673,0.0,0.17009902,54.990688,7.7619662,504.42084,-9.2031775
212.0392,5.0842543,2.6028306,0.0,0,6.8808594,0.0,0.19007432,53.525497,7.516304,503.45419,-9.2029572
212.0416,5.3111048,2.8550892,0.0,0,6.5876017,0.0,0.21059312,54.74789,7.2571549,502.48755,-9.2039862
212.044,5.4506774,3.1364048,0.0,0,6.3000817,0.0,0.23421864,54.855732,6.9777279,501.5209,-9.203927
212.0464,5.6595116,3.4259846,0.0,0,6.0199599,0.0,0.25916022,55.497784,6.6796613,500.55426,-9.2035379
212.0488,5.7775354,3.7333333,0.0,0,5.7465038,0.0,0.2860401,55.258884,6.3705153,499.5676,-9.2042007
212.0512,5.9213905,4.0462251,0.0,0,5.4789333,0.0,0.31391671,55.089527,6.0610065,498.57913,-9.2026014
212.0536,6.0648746,4.3480639,0.0,0,5.2187734,0.0,0.34138599,54.840271,5.7562904,497.59067,-9.2040043
212.056,6.202107,4.6333928,0.0,0,4.9631839,0.0,0.36854485,54.603848,5.4670458,496.6022,-9.2037058
212.0584,6.329432,4.9100633,0.0,0,4.715744,0.0,0.39595813,54.220993,5.192111,495.33978,-9.2022715
212.0608,6.431056,5.1672096,0.0,0,4.4716296,0.0,0.42221612,53.68343,4.9306612,493.98602,-9.2025881
212.0632,6.552413,5.4104939,0.0,0,4.2362375,0.0,0.44751158,53.338268,4.6785431,492.63226,-9.2021093
212.0656,6.7013693,5.6554375,0.0,0,4.0030656,0.0,0.47303453,53.073849,4.430007,491.27847,-9.203577
212.068,6.8631878,5.8902664,0.0,0,3.7791932,0.0,0.49798125,53.044666,4.1992941,490.00778,-9.2018881
212.0704,7.0206623,6.1198754,0.0,0,3.5565166,0.0,0.52340961,52.976051,3.9683936,488.79645,-9.2024508
212.0728,7.1738095,6.3504767,0.0,0,3.3435369,0.0,0.54978251,52.738636,3.7437449,487.58511,-9.2034292
212.0752,7.3819313,6.5718222,0.0,0,3.1309152,0.0,0.57622057,52.825111,3.5222566,486.37375,-9.202467
212.0776,7.6132183,6.789413,0.0,0,2.9282222,0.0,0.60273576,53.010414,3.3010316,484.24771,-9.2028942
212.08,7.8553696,7.0120239,0.0,0,2.7256143,0.0,0.62991041,53.219627,3.0821683,480.84109,-9.2028828
212.0824,8.058794,7.2300844,0.0,0,2.5323272,0.0,0.65708631,53.156322,2.8673484,477.43451,-9.2021875
212.0848,8.2950783,7.4410639,0.0,0,2.3396072,0.0,0.6839875,53.270401,2.6562665,474.02789,-9.2018166
212.0872,8.5577297,7.6483016,0.0,0,2.1549723,0.0,0.71201485,53.41193,2.4509304,470.55063,-9.2024508
212.0896,8.8438845,7.8441682,0.0,0,1.9716601,0.0,0.73979461,53.643787,2.255698,466.86142,-9.2020903
212.092,9.1181736,8.0279274,0.0,0,1.7952764,0.0,0.76643139,53.869007,2.0668421,463.17221,-9.2017107
212.0944,9.3802538,8.2100363,0.0,0,1.6208923,0.0,0.79292971,53.996185,1.8814096,459.48303,-9.2009287
212.0968,9.6937513,8.3902349,0.0,0,1.4523933,0.0,0.81907755,54.385815,1.7022513,456.07974,-9.2010574
212.0992,10.036669,8.5667067,0.0,0,1.2865053,0.0,0.84535646,54.871056,1.5333608,455.82138,-9.2011528
212.1016,10.414113,8.7370949,0.0,0,1.1255604,0.0,0.87231958,55.366798,1.3616523,455.56302,-9.2006798
212.104,10.792274,8.9054174,0.0,0,0.96778435,0.0,0.90022796,55.835258,1.1917925,455.30466,-9.2005711
212.1064,11.187431,9.0647945,0.0,0,0.81407332,0.0,0.92738473,56.316849,1.0273491,455.0463,-9.2019186
212.1088,11.63026,9.2204828,0.0,0,0.66402543,0.0,0.95427817,56.971565,0.86874419,454.814,-9.2009315
212.1112,12.154937,9.3768024,0.0,0,0.51718587,0.0,0.98095345,57.990311,0.70900643,454.58405,-9.2005873
212.1136,12.4969,9.5325108,0.0,0,0.37438589,0.0,1.007717,58.268501,0.55401945,454.3541,-9.2003613
212.116,10.03247,9.5700951,0.0,0,0.23410416,0.0,1.0145574,46.475151,0.475265,454.12415,-9.2019234
212.1184,8.9613752,9.5730906,0.0,0,0.098312147,0.0,1.0161142,41.324062,0.42589265,455.42831,-9.2017851
212.1208,8.4689245,9.5704746,0.0,0,-0.036552414,0.0,1.0167638,39.035904,0.39185953,457.24384,-9.2035208
212.1232,8.1890688,9.5682621,0.0,0,-0.16898441,0.0,1.0169445,37.722664,0.36247113,459.05939,-9.2033529
212.1256,8.1760521,9.5752268,0.0,0,-0.30141643,0.0,1.0173693,37.611389,0.32237047,460.87491,-9.2031374
212.128,8.4835663,9.5816288,0.0,0,-0.43384844,0.0,1.0177057,39.040539,0.26199567,464.23956,-9.20403
212.1304,8.6287718,9.5911016,0.0,0,-0.56628042,0.0,1.01906,39.65728,0.1882643,468.71069,-9.2035723
212.1328,8.6215124,9.5987015,0.0,0,-0.69871235,0.0,1.0207126,39.54649,0.12740657,473.18185,-9.2033529
212.1352,8.4814978,9.6010466,0.0,0,-0.83114439,0.0,1.0223105,38.867477,0.071948715,477.65302,-9.2037745
212.1376,8.2608204,9.6013718,0.0,0,-0.96357638,0.0,1.0229995,37.856033,0.031138208,481.16904,-9.2033033
212.14,7.9227872,9.6056995,0.0,0,-1.0960084,0.0,1.0235523,36.302032,0.009463653,483.34796,-9.2031765
212.1424,7.4872875,9.6108084,0.0,0,-0.69049948,500.0,1.0233698,34.255493,0.0030440378,485.52689,-9.2029467
212.1448,7.0768428,9.6116562,0.0,0,-0.23201317,500.0,1.0227189,32.440773,0.010258717,487.70578,-9.2028913
212.1472,6.7855844,9.6172037,1.0889708,0,0.22647317,500.0,1.0236816,31.078918,0.011493703,489.74655,-9.2036285
212.1496,6.5659609,9.6169558,5.4448299,0,0.68495959,500.0,1.0249609,29.983551,0.014082198,491.37286,-9.2034369
212.152,6.393548,9.612381,9.8006897,0,1.1434462,500.0,1.0249006,29.250235,0.013558017,492.99921,-9.20366
212.1544,6.0129514,9.6064405,14.156549,0,1.6019324,500.0,1.0239241,27.55913,0.027153656,494.62555,-9.2035656
212.1568,4.6963425,9.598876,18.149414,0,2.0604188,500.0,1.021593,21.615067,0.10085126,496.22617,-9.2043018
212.1592,2.6111536,9.588172,18.149414,0,2.5189049,500.0,1.0187585,12.233376,0.2435966,497.54413,-9.2061434
212.1616,0.14584111,9.5671892,18.149414,0,2.9773915,500.0,1.0149701,0.81388956,0.47635689,498.86209,-9.2079897
212.164,-0.079797417,9.5136957,18.149414,0,3.4358778,500.0,1.0056167,-0.24851902,0.96772957,500.18002,-9.20718
212.1664,-0.055961628,9.5044785,18.149414,0,3.8943641,500.0,1.0049639,-0.3825897,1.6663688,501.49799,-9.2083178
212.1688,0.041838299,9.5149469,14.156538,0,4.3528504,500.0,1.0069441,0.20071816,2.4506485,502.54657,-9.2080545
212.1712,0.11701489,9.5649824,9.8006783,0,4.811337,500.0,1.0155464,0.56660342,3.1318314,503.57065,-9.208107
212.1736,-0.084680572,9.5624161,5.4448185,0,5.2698236,500.0,1.0141399,-0.41739407,3.6280844,504.59473,-9.2079973
212.176,0.063882343,9.557128,1.0889597,0,5.7283101,500.0,1.0125042,0.22601537,4.0497308,505.6188,-9.2074032
212.1784,0.078856491,9.5642033,0.0,0,6.1867967,500.0,1.0142268,0.41933069,4.4685483,506.3688,-9.2082167
212.1808,0.02509395,9.5575209,0.0,0,6.6452827,500.0,1.0143126,0.09727367,4.8906651,507.02747,-9.2076759
212.1832,0.012152827,9.5524263,0.0,0,7.1037693,500.0,1.0141654,0.073901922,5.3296003,507.68613,-9.207325
212.1856,0.15221399,9.5496063,0.0,0,7.5622554,500.0,1.0131825,0.6611892,5.7949591,508.34476,-9.2075195
212.188,-0.036432106,9.5519629,0.0,0,8.0207424,500.0,1.0125036,-0.11118285,6.2781963,508.89902,-9.206831
212.1904,0.0021465188,9.5569077,0.0,0,8.479228,500.0,1.0127459,0.0034925835,6.7725196,509.37866,-9.2055092
212.1928,0.11797493,9.5593195,0.0,0,8.9377146,500.0,1.0134168,0.54645139,7.2688079,509.85834,-9.2066765
212.1952,-0.035583947,9.556119,0.0,0,9.3962002,500.0,1.0137577,-0.099000014,7.7401757,510.33798,-9.2077265
212.1976,0.072164439,9.5505581,0.0,0,9.8546877,500.0,1.013586,0.25913996,8.205205,510.80573,-9.2073212
212.2,0.059257179,9.5492506,0.0,0,10.313173,500.0,1.0131437,0.34946364,8.6712351,511.25674,-9.2072649
212.2024,-0.017551102,9.5515251,0.0,0,10.77166,500.0,1.0127069,-0.092457339,9.1347885,511.70773,-9.2077036
212.2048,0.050516587,9.5551491,0.0,0,11.230146,500.0,1.0123541,0.21252705,9.6159325,512.15875,-9.2076721
212.2072,0.13919747,9.5606918,0.0,0,11.688633,500.0,1.0130941,0.61076975,10.098309,512.56683,-9.2071476
212.2096,-0.059992496,9.5586853,0.0,0,12.14712,500.0,1.0136514,-0.2656548,10.568698,512.84601,-9.2061443
212.212,0.081106275,9.5527372,0.0,0,12.605606,500.0,1.0138838,0.35192478,11.036806,513.12524,-9.2062283
212.2144,0.078054473,9.5515509,0.0,0,13.064093,500.0,1.0139328,0.42721507,11.504488,513.40448,-9.2052317
212.2168,-0.051659048,9.5501614,0.0,0,13.522579,500.0,1.0126315,-0.28443232,11.95787,513.67767,-9.2059584
212.2192,0.12143416,9.5519695,0.0,0,13.981066,500.0,1.0121713,0.4464196,12.409591,513.88531,-9.2060909
212.2216,0.04282508,9.5539522,0.0,0,14.439551,500.0,1.0122209,0.28436613,12.876781,514.0929,-9.2052298
212.224,0.0069630696,9.5559864,0.0,0,14.898038,500.0,1.0130852,0.00065128162,13.344432,514.30048,-9.2046766
212.2264,0.078797445,9.5522699,0.0,0,15.356524,500.0,1.0134197,0.27156886,13.821787,514.50812,-9.2045307
212.2288,0.061323743,9.5498629,0.0,0,15.81501,500.0,1.0134774,0.35288432,14.300709,514.72882,-9.2042627
212.2312,0.011613768,9.5510054,0.0,0,16.273499,500.0,1.013322,0.01992305,14.768357,514.95074,-9.2044125
212.2336,0.14030781,9.5518122,0.0,0,16.731983,500.0,1.012201,0.68027908,15.23667,515.17267,-9.2050352
212.236,0.0019348172,9.5567656,0.0,0,17.19047,500.0,1.0123119,-0.013558756,15.693773,515.39459,-9.2049713
212.2384,-0.0081771938,9.5578022,0.0,0,17.648958,500.0,1.0129812,-0.062162399,16.152014,515.53064,-9.2055464
212.2408,0.091866516,9.5523586,0.0,0,18.0,500.0,1.0131949,0.40501234,16.611738,515.638,-9.2051611
212.2432,0.012283368,9.5488091,0.0,0,18.0,500.0,1.0133314,0.14694013,17.060698,515.74542,-9.2041378
212.2456,0.054478206,9.5486994,0.0,0,18.0,500.0,1.0133729,0.25162122,17.482302,515.85284,-9.2059422
212.248,0.023037259,9.5500574,0.0,0,18.0,500.0,1.0121676,0.11901937,17.867519,515.97272,-9.2057838
212.2504,0.03568856,9.5534325,0.0,0,18.0,500.0,1.0121255,0.21552622,18.185402,516.10156,-9.2069445
212.2528,0.077679902,9.5578775,0.0,0,18.0,500.0,1.0131938,0.34762067,18.412462,516.23047,-9.2106104
212.2552,0.057248455,9.561924,0.0,0,18.0,500.0,1.0145725,0.32543471,18.533075,516.35931,-9.215127
212.2576,0.094746627,9.5679464,0.0,0,18.0,500.0,1.0164758,0.42323074,18.515217,516.4762,-9.2231007
212.26,0.10939983,9.5792761,0.0,0,18.0,500.0,1.0189209,0.5215472,18.400372,516.57642,-9.2340307
212.2624,0.54335761,9.5894279,0.0,0,18.0,500.0,1.0197196,2.4404874,18.266821,516.67664,-9.2480812
212.2648,0.40905315,9.591259,0.0,0,18.0,500.0,1.0191317,1.9185218,18.154808,516.77686,-9.2652731
212.2672,0.4278433,9.596343,0.0,0,18.0,500.0,1.019477,1.9364142,18.073421,516.86102,-9.2862339
212.2696,0.35134482,9.5941925,0.0,0,18.0,500.0,1.0198985,1.6208931,18.048115,516.89679,-9.3095207
212.272,0.375689,9.5883341,0.0,0,18.0,500.0,1.0203015,1.6816813,18.050201,516.93262,-9.3308973
212.2744,0.38026026,9.5825186,0.0,0,18.0,500.0,1.0196145,1.754975,18.066223,516.96838,-9.3532982
212.2768,0.3961899,9.5813446,0.0,0,18.0,500.0,1.0186219,1.7830302,18.092522,517.00836,-9.3735867
212.2792,0.37020168,9.5843792,0.0,0,18.0,500.0,1.0181893,1.7213268,18.119284,517.0943,-9.3915281
212.2816,0.36206463,9.588912,0.0,0,18.0,500.0,1.0185732,1.6625295,18.134731,517.18018,-9.4105024
212.284,0.38560137,9.5878973,0.0,0,18.0,500.0,1.0187877,1.8036288,18.145281,517.26605,-9.4291534
212.2864,0.40942401,9.5859995,0.0,0,18.0,500.0,1.0193655,1.8728634,18.149889,517.35199,-9.4444647
212.2888,0.41033402,9.5811396,0.0,0,18.0,500.0,1.0191926,1.8912386,18.152842,517.38538,-9.4619293
212.2912,0.38308474,9.5819035,0.0,0,18.0,500.0,1.0190405,1.7667161,18.15033,517.41406,-9.4792891
212.2936,0.40091619,9.5838928,0.0,0,18.0,500.0,1.0183026,1.8249034,18.143166,517.44269,-9.4965563
212.296,0.43541315,9.5888624,0.0,0,18.0,500.0,1.0183202,1.970059,18.139843,517.47137,-9.5138988
212.2984,0.41757995,9.5887928,0.0,0,18.0,500.0,1.0185651,1.9560277,18.140144,517.5,-9.5321236
212.3008,0.4125537,9.5890894,0.0,0,18.0,500.0,1.0195993,1.8778614,18.134226,517.52863,-9.5518274
212.3032,0.39027819,9.5846281,0.0,0,18.0,500.0,1.0199285,1.7646309,18.137348,517.55725,-9.570323
212.3056,0.42263305,9.5816078,0.0,0,18.0,500.0,1.0195314,1.9389752,18.13339,517.58588,-9.5886154
212.308,0.43938228,9.5810833,0.0,0,18.0,500.0,1.0183029,2.0087674,18.127115,517.6145,-9.6070757
212.3104,0.42043215,9.5854607,0.0,0,18.0,500.0,1.0181217,1.9283916,18.127766,517.64313,-9.6259422
212.3128,0.40996382,9.5897217,0.0,0,18.0,500.0,1.0188155,1.8932141,18.1245,517.67181,-9.6444454
212.3152,0.41530672,9.5880508,0.0,0,18.0,500.0,1.0191088,1.8974185,18.121235,517.70044,-9.6622696
212.3176,0.43591696,9.5854549,0.0,0,18.0,500.0,1.0197016,2.0233378,18.118582,517.72314,-9.6794901
212.32,0.43105811,9.5817308,0.0,0,18.0,500.0,1.0193781,2.0220494,18.118729,517.73743,-9.698288
212.3224,0.41992778,9.5838146,0.0,0,18.0,500.0,1.0190002,1.9309558,18.119066,517.75177,-9.7165918
212.3248,0.40753722,9.5880146,0.0,0,18.0,500.0,1.0186548,1.8907923,18.118414,517.76605,-9.7339325
212.3272,0.4299891,9.5937548,0.0,0,18.0,500.0,1.0190673,1.9624432,18.114679,517.78754,-9.7515011
212.3296,0.45175743,9.5929155,0.0,0,18.0,500.0,1.0194613,2.0295687,18.115839,517.83051,-9.7694654
212.332,0.43173537,9.5880156,0.0,0,18.0,500.0,1.0199492,1.9880782,18.111858,517.87347,-9.7881193
212.3344,0.4172771,9.5838318,0.0,0,18.0,500.0,1.0198914,1.9235765,18.111448,517.91644,-9.8071709
212.3368,0.41438738,9.5801888,0.0,0,18.0,500.0,1.0186908,1.8781083,18.113541,517.9552,-9.8263779
212.3392,0.44136631,9.5816345,0.0,0,18.0,500.0,1.0179551,2.0383394,18.108118,517.94806,-9.8437576
212.3416,0.43801525,9.5846119,0.0,0,18.0,500.0,1.0180025,2.0072086,18.106434,517.94086,-9.8617907
212.344,0.43513495,9.586031,0.0,0,18.0,500.0,1.0183194,2.0215662,18.10557,517.93365,-9.8808546
212.3464,0.41553262,9.5857897,0.0,0,18.0,500.0,1.0192562,1.9129062,18.108244,517.92651,-9.8991432
212.3488,0.43300986,9.5834017,0.0,0,18.0,500.0,1.0197052,1.9817657,18.106434,517.90619,-9.9182434
212.3512,0.45583138,9.5816889,0.0,0,18.0,500.0,1.0191169,2.0977588,18.102295,517.88477,-9.9353228
212.3536,0.44559434,9.5838585,0.0,0,18.0,500.0,1.0187066,2.0659885,18.102743,517.86328,-9.9530935
212.356,0.4401935,9.5904179,0.0,0,18.0,500.0,1.0187751,2.0224826,18.103292,517.8418,-9.9728765
212.3584,0.43853503,9.5934963,0.0,0,18.0,500.0,1.0192285,1.9850812,18.103899,517.84717,-9.9904308
212.3608,0.45588061,9.5913115,0.0,0,18.0,500.0,1.0198861,2.1003957,18.10062,517.86151,-10.007142
212.3632,0.46333122,9.5848646,0.0,0,18.0,500.0,1.0197991,2.1319494,18.101229,517.87579,-10.024683
212.3656,0.46239701,9.5818644,0.0,0,18.0,500.0,1.0195103,2.1201253,18.099415,517.89014,-10.042894
212.368,0.44106126,9.5813513,0.0,0,18.0,500.0,1.0183951,2.0218673,18.097359,517.90027,-10.060974
212.3704,0.45797163,9.5847063,0.0,0,18.0,500.0,1.0182592,2.097254,18.098906,517.90741,-10.078576
212.3728,0.48689538,9.5876493,0.0,0,18.0,500.0,1.0185212,2.2452993,18.100378,517.91461,-10.097842
212.3752,0.4803156,9.589242,0.0,0,18.0,500.0,1.0193642,2.2276711,18.095478,517.92175,-10.117081
212.3776,0.4682427,9.5846529,0.0,0,18.0,500.0,1.0194312,2.1438091,18.097633,517.914,-10.136168
212.38,0.46152237,9.5839214,0.0,0,18.0,500.0,1.0200405,2.1241286,18.097721,517.88538,-10.154286
212.3824,0.47044656,9.5837975,0.0,0,18.0,500.0,1.019161,2.1744807,18.096689,517.85675,-10.171261
212.3848,0.49806067,9.5857735,0.0,0,18.0,500.0,1.0184221,2.2650247,18.090698,517.82813,-10.189006
212.3872,0.48172605,9.5905466,0.0,0,18.0,500.0,1.0184977,2.2105401,18.092699,517.80664,-10.208402
212.3896,0.45917416,9.5929747,0.0,0,18.0,500.0,1.0196011,2.1410728,18.090662,517.80664,-10.226539
212.392,0.48874456,9.5900488,0.0,0,18.0,500.0,1.0202037,2.1826239,18.088148,517.80664,-10.243532
212.3944,0.4875477,9.5830345,0.0,0,18.0,500.0,1.0196142,2.2534704,18.087599,517.80664,-10.262562
212.3968,0.48336393,9.582448,0.0,0,18.0,500.0,1.0193188,2.2332976,18.089172,517.80786,-10.280256
212.3992,0.48429573,9.5842934,0.0,0,18.0,500.0,1.0186332,2.2127142,18.088083,517.82214,-10.299135
212.4016,0.4637548,9.5866756,0.0,0,18.0,500.0,1.018237,2.1459363,18.086983,517.83649,-10.317177
212.404,0.47245762,9.5885963,0.0,0,18.0,500.0,1.0188631,2.2122293,18.0853,517.85077,-10.334648
212.4064,0.49058425,9.5885553,0.0,0,18.0,500.0,1.0194345,2.2681653,18.085232,517.86505,-10.351761
212.4088,0.49922356,9.5855217,0.0,0,18.0,500.0,1.0199268,2.2383919,18.084066,517.85315,-10.371287
212.4112,0.47277966,9.585248,0.0,0,18.0,500.0,1.0198647,2.1734974,18.085863,517.83887,-10.390599
212.4136,0.4824526,9.5840626,0.0,0,18.0,500.0,1.0189068,2.2212136,18.085457,517.82452,-10.408947
212.416,0.50087833,9.5879545,0.0,0,18.0,500.0,1.0185696,2.3042316,18.083406,517.81024,-10.426432
212.4184,0.50909108,9.591012,0.0,0,18.0,500.0,1.0187856,2.3717577,18.079777,517.78516,-10.443722
212.4208,0.48443997,9.5903673,0.0,0,18.0,500.0,1.0194799,2.2350335,18.083305,517.75653,-10.461994
212.4232,0.48292804,9.5872135,0.0,0,18.0,500.0,1.0202222,2.2232304,18.080851,517.72791,-10.480149
212.4256,0.50018281,9.5835257,0.0,0,18.0,500.0,1.0198503,2.3093915,18.080664,517.69922,-10.498674
212.428,0.5226081,9.5813437,0.0,0,18.0,500.0,1.0185441,2.3818862,18.079779,517.67896,-10.516621
212.4304,0.51302457,9.5859766,0.0,0,18.0,500.0,1.0183842,2.3793118,18.077953,517.66467,-10.535596
212.4328,0.49682724,9.5890293,0.0,0,18.0,500.0,1.0187032,2.3030152,18.079048,517.65033,-10.554111
212.4352,0.5051741,9.5894537,0.0,0,18.0,500.0,1.0191182,2.2784245,18.078524,517.63605,-10.57333
212.4376,0.51837486,9.5884495,0.0,0,18.0,500.0,1.019815,2.381701,18.078873,517.62469,-10.590625
212.44,0.52818531,9.5849819,0.0,0,18.0,500.0,1.0200404,2.4297941,18.076191,517.61749,-10.608227
212.4424,0.50617367,9.5810652,0.0,0,18.0,500.0,1.0189134,2.3234932,18.073925,517.61035,-10.625912
212.4448,0.5041678,9.5827274,0.0,0,18.0,500.0,1.0183251,2.2762659,18.072767,517.60315,-10.644728
212.4472,0.52010775,9.5899277,0.0,0,18.0,500.0,1.0186177,2.3833048,18.072008,517.58881,-10.663436
212.4496,0.53718919,9.5925617,0.0,0,18.0,500.0,1.0190473,2.4610538,18.068552,517.55304,-10.680089
212.452,0.53503156,9.5921621,0.0,0,18.0,500.0,1.0202372,2.456656,18.068235,517.51727,-10.697859
212.4544,0.51138723,9.5846891,0.0,0,18.0,500.0,1.0199348,2.3643944,18.067743,517.48145,-10.717938
212.4568,0.51710129,9.5792074,0.0,0,18.0,500.0,1.0190617,2.3708205,18.070698,517.4469,-10.73602
212.4592,0.54084551,9.5808973,0.0,0,18.0,500.0,1.0182015,2.4696059,18.070955,517.42542,-10.755776
212.4616,0.5308215,9.5854588,0.0,0,18.0,500.0,1.0181074,2.4326332,18.071148,517.40393,-10.774302
212.464,0.52342308,9.5884485,0.0,0,18.0,500.0,1.0187062,2.4373069,18.069672,517.38245,-10.792044
212.4664,0.51180345,9.5890141,0.0,0,18.0,500.0,1.0194,2.3353822,18.06881,517.36096,-10.810537
212.4688,0.52961355,9.5859833,0.0,0,18.0,500.0,1.0197079,2.4029195,18.068302,517.36578,-10.826977
212.4712,0.5586074,9.5818596,0.0,0,18.0,500.0,1.0192705,2.5684462,18.068956,517.37292,-10.843757
212.4736,0.5368467,9.5822763,0.0,0,18.0,500.0,1.0187656,2.4949534,18.066818,517.38007,-10.862733
212.476,0.52115268,9.5893288,0.0,0,18.0,500.0,1.0189703,2.418328,18.065956,517.38727,-10.88216
212.4784,0.52806121,9.5919218,0.0,0,18.0,500.0,1.0187815,2.4360683,18.064692,517.39441,-10.901047
212.4808,0.54211926,9.5910645,0.0,0,18.0,500.0,1.0193466,2.4946363,18.066061,517.40155,-10.918569
212.4832,0.55401725,9.5896111,0.0,0,18.0,500.0,1.0202233,2.5184364,18.065142,517.40869,-10.936316
212.4856,0.54367298,9.5869446,0.0,0,18.0,500.0,1.020483,2.5187514,18.06377,517.41583,-10.954602
212.488,0.51874053,9.5856962,0.0,0,18.0,500.0,1.0195558,2.3980837,18.064438,517.3938,-10.972611
212.4904,0.53821743,9.5835104,0.0,0,18.0,500.0,1.0181735,2.4747372,18.062,517.35083,-10.989257
212.4928,0.55607468,9.5857553,0.0,0,18.0,500.0,1.0179732,2.5683374,18.0667,517.30786,-11.009105
212.4952,0.54470927,9.5877647,0.0,0,18.0,500.0,1.0187367,2.5391459,18.064541,517.26489,-11.02692
212.4976,0.53949875,9.5875568,0.0,0,18.0,500.0,1.0196238,2.4863667,18.060207,517.22498,-11.04627
212.5,0.54119349,9.583168,0.0,0,18.0,500.0,1.0198272,2.4789495,18.056623,517.18915,-11.062821
212.5024,0.55304831,9.5811644,0.0,0,18.0,500.0,1.0190741,2.5140963,18.059971,517.15332,-11.080746
212.5048,0.55656266,9.5826969,0.0,0,18.0,500.0,1.0184296,2.5692232,18.062157,517.11755,-11.099804
212.5072,0.55024469,9.5920639,0.0,0,18.0,500.0,1.0189272,2.5761259,18.05687,517.09247,-11.118396
212.5096,0.53251636,9.5936308,0.0,0,18.0,500.0,1.0192153,2.452949,18.05304,517.09967,-11.136491
212.512,0.56915522,9.5898848,0.0,0,18.0,500.0,1.0198036,2.6100049,18.05797,517.10681,-11.155502
212.5144,0.56537867,9.5847645,0.0,0,18.0,500.0,1.0196906,2.6251669,18.054871,517.11395,-11.174781
212.5168,0.56655711,9.5824881,0.0,0,18.0,500.0,1.019574,2.6000698,18.055946,517.12115,-11.192341
212.5192,0.55120158,9.5843115,0.0,0,18.0,500.0,1.0190538,2.5183537,18.054651,517.1283,-11.209381
212.5216,0.55328119,9.588376,0.0,0,18.0,500.0,1.0186822,2.5440238,18.052319,517.1355,-11.226785
212.524,0.57729417,9.5878019,0.0,0,18.0,500.0,1.0186212,2.621001,18.056736,517.14264,-11.245002
212.5264,0.58860928,9.5881519,0.0,0,18.0,500.0,1.0191287,2.6856995,18.054043,517.14978,-11.263253
212.5288,0.56666064,9.586772,0.0,0,18.0,500.0,1.0196995,2.6110411,18.054026,517.13068,-11.282036
212.5312,0.56713355,9.5851917,0.0,0,18.0,500.0,1.0201312,2.5836418,18.050602,517.10925,-11.300558
212.5336,0.57639611,9.5851088,0.0,0,18.0,500.0,1.0193141,2.6128399,18.050301,517.08777,-11.318774
212.536,0.58124107,9.5871334,0.0,0,18.0,500.0,1.0186907,2.694829,18.05249,517.06628,-11.336515
212.5384,0.57817507,9.5925407,0.0,0,18.0,500.0,1.0188632,2.6829259,18.052248,517.02332,-11.355227
212.8401,0.55720699,9.5890312,0.0,0,18.0,0.041107424,1.0197911,2.5589225,18.017477,507.26025,-11.480934
214.0401,0.64163315,9.603672,0.0,0,18.0,1.7770673e-18,1.0221575,2.9360526,18.00028,489.31842,-11.48202
215.2401,0.6489532,9.6133099,0.0,0,18.0,7.682231499999997e-35,1.02424,2.969599,17.999887,476.12509,-11.481983
216.4401,0.67042989,9.6223412,0.0,0,18.0,1.4012985e-45,1.025821,3.0638497,17.999464,464.1463,-11.481303
217.6401,0.67096001,9.6303663,0.0,0,18.0,1.4012985e-45,1.0273117,3.0645394,18.000191,452.98679,-11.482494
218.8401,0.67133719,9.6387367,0.0,0,18.0,1.4012985e-45,1.0287397,3.0581086,17.999853,442.13821,-11.482513
220.0401,0.67916268,9.6459255,0.0,0,18.0,1.4012985e-45,1.0300993,3.0877936,18.00032,431.65195,-11.482551
221.2401,0.67975396,9.6531391,0.0,0,18.0,1.4012985e-45,1.0317593,3.0883152,17.999979,421.50601,-11.482464
222.4401,0.69104093,9.6598635,0.0,0,18.0,1.4012985e-45,1.0326524,3.1355805,17.999435,411.44827,-11.482626
223.6401,0.69377649,9.665638,0.0,0,18.0,1.4012985e-45,1.0339979,3.1373456,18.000389,401.65591,-11.482621
224.8401,0.70464832,9.6714201,0.0,0,18.0,1.4012985e-45,1.0348265,3.1883895,17.999971,392.20694,-11.482873
226.0401,0.69759232,9.6773977,0.0,0,18.0,1.4012985e-45,1.0362771,3.1494975,18.00033,382.73987,-11.483106
227.2401,0.70479757,9.6834927,0.0,0,18.0,1.4012985e-45,1.0370905,3.1880875,17.999966,373.57446,-11.483013
228.4401,0.70716673,9.6887293,0.0,0,18.0,1.4012985e-45,1.0383677,3.1945333,18.000065,364.93631,-11.482936
229.6401,0.70463961,9.6945963,0.0,0,18.0,1.4012985e-45,1.0392457,3.1784966,18.000952,356.15823,-11.482157
230.8401,0.70763463,9.7004318,0.0,0,18.0,1.4012985e-45,1.0405712,3.1843529,18.000448,347.71426,-11.482202
232.0401,0.70701778,9.7068319,0.0,0,18.0,1.4012985e-45,1.0414329,3.1784465,18.000147,339.39087,-11.481932
233.2401,0.70339429,9.7112694,0.0,0,18.0,1.4012985e-45,1.0426173,3.1592793,18.000231,331.47955,-11.481918
234.4401,0.71545887,9.7174797,0.0,0,18.0,1.4012985e-45,1.0435765,3.2131083,17.999805,323.59348,-11.481957
235.6401,0.71338117,9.7218208,0.0,0,18.0,1.4012985e-45,1.0446312,3.1943369,17.99964,315.96301,-11.482257
236.8401,0.72221792,9.7277107,0.0,0,18.0,1.4012985e-45,1.0454227,3.2366831,18.000286,308.51492,-11.482538
238.0401,0.7163856,9.7325487,0.0,0,18.0,1.4012985e-45,1.0466768,3.2060137,17.999924,301.33704,-11.482475
239.2401,0.72627532,9.7372351,0.0,0,18.0,1.4012985e-45,1.0472292,3.2489083,18.000076,294.14969,-11.482443
240.4401,0.70996088,9.7419138,0.0,0,18.0,1.4012985e-45,1.0484742,3.170568,18.000214,287.40442,-11.482158
241.6401,0.71515352,9.747056,0.0,0,18.0,1.4012985e-45,1.0491483,3.1903584,17.999472,280.603,-11.482065
242.8401,0.72022682,9.7512283,0.0,0,18.0,1.4012985e-45,1.0500517,3.2086165,18.000338,274.07892,-11.482101
244.0401,0.72687423,9.7557106,0.0,0,18.0,1.4012985e-45,1.0508219,3.2358081,18.000389,267.77252,-11.482386
245.2401,0.7216326,9.7598705,0.0,0,18.0,1.4012985e-45,1.0518347,3.2103264,18.000202,261.5769,-11.482392
246.4401,0.7291168,9.7642784,0.0,0,18.0,1.4012985e-45,1.0525612,3.2400603,18.000454,255.54085,-11.482274
247.6401,0.73013413,9.7685976,0.0,0,18.0,1.4012985e-45,1.053148,3.2438073,17.999681,249.61601,-11.481988
248.8401,0.72942191,9.772213,0.0,0,18.0,1.4012985e-45,1.0542097,3.2368877,17.999653,243.81296,-11.481983
250.0401,0.71847028,9.776722,0.0,0,18.0,1.4012985e-45,1.0547931,3.1866415,18.000113,238.20665,-11.481842
251.2401,0.72290993,9.7799129,0.0,0,18.0,1.4012985e-45,1.0557398,3.2009401,17.999737,232.60831,-11.481955
252.4401,0.71959859,9.7841949,0.0,0,18.0,1.4012985e-45,1.056269,3.1848438,18.000137,227.25133,-11.481884
253.6401,0.73249876,9.788331,0.0,0,18.0,1.4012985e-45,1.0570309,3.2342639,18.000324,221.98459,-11.482207
254.8401,0.73321867,9.791893,0.0,0,18.0,1.4012985e-45,1.0580237,3.2400875,18.000082,216.86398,-11.482301
256.0401,0.73361087,9.7953253,0.0,0,18.0,1.4012985e-45,1.0583922,3.2401021,18.000195,211.83342,-11.482317
257.2401,0.7270503,9.7983437,0.0,0,18.0,1.4012985e-45,1.059225,3.207896,17.999626,206.9801,-11.482005
258.4401,0.72680289,9.8027697,0.0,0,18.0,1.4012985e-45,1.0598112,3.2071805,18.000113,202.12096,-11.481979
259.6401,0.72444338,9.8062096,0.0,0,18.0,1.4012985e-45,1.0605183,3.1882298,17.999611,197.51083,-11.482019
260.8401,0.7388792,9.8095007,0.0,0,18.0,1.4012985e-45,1.0613078,3.2534838,17.999699,193.07408,-11.482167
262.0401,0.73537201,9.8128128,0.0,0,18.0,1.4012985e-45,1.0617828,3.2350507,18.00045,188.65758,-11.482259
263.2401,0.73676997,9.8153973,0.0,0,18.0,1.4012985e-45,1.0625675,3.2370102,18.000214,184.40311,-11.482504
264.4401,0.7352491,9.819191,0.0,0,18.0,1.4012985e-45,1.0630661,3.2316504,17.999428,180.37543,-11.482377
265.6401,0.73436409,9.8225384,0.0,0,18.0,1.4012985e-45,1.0635502,3.2252228,17.999952,176.52325,-11.48243
266.8401,0.73019284,9.8250513,0.0,0,18.0,1.4012985e-45,1.0643617,3.2037654,18.00037,172.57614,-11.482368
268.0401,0.73146641,9.8285303,0.0,0,18.0,1.4012985e-45,1.0647876,3.2087216,18.000114,168.7659,-11.482289
269.2401,0.73531663,9.8310061,0.0,0,18.0,1.4012985e-45,1.0654584,3.222441,17.999624,164.99315,-11.482457
270.4401,0.73482275,9.8337612,0.0,0,18.0,1.4012985e-45,1.0660391,3.2176664,17.999483,161.4821,-11.482479
271.6401,0.72930527,9.8369732,0.0,0,18.0,1.4012985e-45,1.0663832,3.1931112,18.000591,158.01505,-11.482217
272.5401,0.74423909,9.8389406,0.0,0,18.0,1.4012985e-45,1.0667353,3.2572045,17.9995,155.51045,-11.482193