File: examples/hot axisymmetric compression example/data/02 screened data/testID_0144.csv
Time(sec),Force(kN),Jaw(mm),PowAngle(deg),Power(W),Pram,PTemp,Strain,Stress(MPa),Stroke(mm),TC1(C),wedge(mm)
0.0,0.76041979,0.49738246,0.0,0,11.076097,0.0015344591,0.033702087,9.3771744,11.075772,23.499479,-9.1162863
1.2,0.72246826,-0.0033986208,0.0,0,11.076097,3.5158741,-0.00022966876,9.2067204,11.076375,23.424517,-9.4825373
2.4,0.69797683,-0.0032089739,0.0,0,11.076097,7.1158748,-0.00021635805,8.8949413,11.076471,23.398294,-9.4792957
3.6,0.67506099,-0.003470757,0.0,0,11.076097,10.715875,-0.00020994384,8.592658,11.075664,23.353914,-9.4784479
4.8,0.65844887,-0.0039782682,0.0,0,11.076097,14.315877,-0.00022047204,8.3854532,11.076812,23.379618,-9.4759216
6.0,0.6443603,-0.0036513875,0.0,0,11.076097,17.91588,-0.00027813521,8.2000866,11.075475,23.375494,-9.4743805
7.2,0.63250959,-0.0037646336,0.0,0,11.076097,21.515877,-0.00025727777,8.0708771,11.075698,23.379755,-9.4713802
8.4,0.62167835,-0.0040453933,9.26052,0,11.076097,25.115875,-0.00023742497,7.9184723,11.075321,23.352621,-9.4693346
9.6,0.6277315,-0.003693941,27.350393,0,11.076097,28.715876,-0.00028040129,8.0034056,11.076407,23.86261,-9.4681005
10.8,0.63538975,-0.0063571888,35.487076,0,11.076097,32.31588,-0.00044971099,8.0946865,11.076139,25.966043,-9.4656191
12.0,0.64543092,-0.010656107,39.919601,0,11.076097,35.915886,-0.00071205822,8.2286854,11.076607,29.692808,-9.4637098
13.2,0.65904832,-0.014885022,42.06913,0,11.076097,39.515881,-0.00099090731,8.401103,11.077042,34.250912,-9.4620714
14.4,0.67041636,-0.019530144,42.97517,0,11.076097,43.115875,-0.001288595,8.5506172,11.076091,39.374134,-9.4601355
15.6,0.69089264,-0.023376198,42.396244,0,11.076097,46.715878,-0.0015726715,8.7978706,11.076468,44.632633,-9.4579945
16.8,0.70005167,-0.027335586,41.223824,0,11.076097,50.315872,-0.001801781,8.9258776,11.077034,49.763054,-9.4556513
18.0,0.70096469,-0.031355556,39.96764,0,11.076097,53.915878,-0.002045108,8.9521723,11.076962,54.355251,-9.4534693
19.2,0.70599198,-0.03316287,38.757923,0,11.076097,57.515877,-0.0022422615,9.0074682,11.077017,58.462917,-9.4516468
20.4,0.70224762,-0.03513116,38.551029,0,11.076097,61.115879,-0.0023260668,8.9549189,11.075995,62.013752,-9.4496222
21.6,0.70246845,-0.037493639,38.312904,0,11.076097,64.715897,-0.0024464815,8.9693451,11.075547,65.290176,-9.4475822
22.8,0.69943649,-0.039991163,38.551022,0,11.076097,68.315887,-0.0027069638,8.9280672,11.076267,68.379211,-9.4456997
24.0,0.69004011,-0.043039605,39.24316,0,11.076097,71.915894,-0.0028737737,8.8240957,11.077224,71.564865,-9.4434967
25.2,0.69456679,-0.046002347,39.924313,0,11.076097,75.515884,-0.0030277059,8.868042,11.075847,74.930977,-9.4411945
26.4,0.70756489,-0.048271202,40.572506,0,11.076097,79.115891,-0.0032418529,9.0332232,11.076445,78.454544,-9.4391155
27.6,0.70858663,-0.052326012,40.873726,0,11.076097,82.715889,-0.0035109464,9.0481844,11.075716,82.041229,-9.4369373
28.8,0.71020949,-0.054673091,41.198727,0,11.076097,86.315895,-0.0036172471,9.0913153,11.076577,85.714607,-9.4350157
30.0,0.71177804,-0.057353314,41.198727,0,11.076097,89.915901,-0.0038465236,9.1037693,11.076346,89.393936,-9.4329872
31.2,0.71598929,-0.060504682,41.731827,0,11.076097,93.515892,-0.0040536616,9.1562471,11.077077,93.056801,-9.4310007
32.4,0.71813565,-0.063857436,41.802975,0,11.076097,97.115883,-0.0042358246,9.1749573,11.076609,96.653465,-9.4286661
33.6,0.73058444,-0.067548372,41.984756,0,11.076097,100.71589,-0.0045103305,9.3448162,11.076694,100.2803,-9.4269581
34.8,0.72538263,-0.069578402,42.396236,0,11.076097,104.31589,-0.0046449299,9.2946367,11.076657,103.82726,-9.4247427
36.0,0.73027205,-0.072826944,42.396236,0,11.076097,107.91589,-0.0048402441,9.351182,11.076856,107.55056,-9.4228191
37.2,0.72904575,-0.075939871,42.937107,0,11.076097,111.51588,-0.0050590909,9.3331032,11.076846,111.0222,-9.4207067
38.4,0.73848206,-0.080321379,42.978512,0,11.076097,115.11588,-0.0053532594,9.4531755,11.075237,114.72771,-9.418437
39.6,0.74059153,-0.082042813,42.978512,0,11.076097,118.71588,-0.0054498632,9.4889393,11.076646,118.30932,-9.4163046
40.8,0.73686528,-0.085419923,43.274139,0,11.076097,122.31588,-0.0056952587,9.4440718,11.076116,121.97613,-9.4143782
42.0,0.7489816,-0.088505551,43.527828,0,11.076097,125.91588,-0.0058990349,9.5813904,11.07671,125.50398,-9.4127989
43.2,0.73579562,-0.091834076,43.652168,0,11.076097,129.51599,-0.006096621,9.4288502,11.076725,129.09566,-9.4105625
44.4,0.73988897,-0.095567934,44.077145,0,11.076097,133.11586,-0.0063685039,9.4830008,11.075805,132.73875,-9.4088478
45.6,0.73390383,-0.098468356,44.077145,0,11.076097,136.71587,-0.0065688509,9.4031887,11.075807,136.34241,-9.4067402
46.8,0.75029063,-0.10185323,44.385071,0,11.076097,140.31587,-0.0067563155,9.6289053,11.075808,139.91554,-9.4051542
48.0,0.73635548,-0.10526336,44.604488,0,11.076097,143.91586,-0.0070168595,9.4401293,11.076297,143.54445,-9.4028902
49.2,0.74072742,-0.10852628,44.604488,0,11.076097,147.51588,-0.0072299545,9.5008068,11.07727,147.36211,-9.4008036
50.4,0.74962938,-0.11170123,44.379749,0,11.076097,151.11588,-0.0074019195,9.636219,11.075913,151.05501,-9.398716
51.6,0.74331796,-0.115255,44.603912,0,11.076097,154.71588,-0.0076879226,9.5361462,11.07734,154.62552,-9.3971605
52.8,0.74594229,-0.11866044,44.604488,0,11.076097,158.31587,-0.0079035917,9.5664091,11.07612,158.179,-9.3952503
54.0,0.75382537,-0.12140592,44.70013,0,11.076097,161.91589,-0.0080323815,9.6939459,11.075373,161.59058,-9.3930302
55.2,0.74608636,-0.12490905,45.12085,0,11.076097,165.51588,-0.0083316965,9.5825911,11.075113,165.05765,-9.3908339
56.4,0.74965441,-0.12820148,45.124199,0,11.076097,169.11589,-0.0085179396,9.6326923,11.074982,168.73958,-9.3888474
57.6,0.74821383,-0.13143978,45.615231,0,11.076097,172.71588,-0.0086836452,9.6248064,11.076809,172.37064,-9.3867998
58.8,0.74612647,-0.13481376,45.615231,0,11.076097,176.31589,-0.0089923916,9.5921831,11.076981,175.94385,-9.3852558
60.0,0.74919862,-0.13819942,45.724434,0,11.076097,179.91589,-0.009164406,9.6274881,11.076838,179.60355,-9.3831139
61.2,0.74733186,-0.14129017,46.109524,0,11.076097,183.5159,-0.0093181767,9.6216936,11.07572,183.1869,-9.3809576
62.4,0.75085258,-0.1451228,46.108719,0,11.076097,187.11589,-0.0096632866,9.6494207,11.07644,186.86543,-9.3793325
63.6,0.74761575,-0.148828,46.109619,0,11.076097,190.7159,-0.0098649105,9.6106062,11.075501,190.54791,-9.37745
64.8,0.75065422,-0.15268978,46.109619,0,11.076097,194.31589,-0.010095373,9.6574574,11.076705,194.12378,-9.3749142
66.0,0.75579703,-0.15556875,46.176781,0,11.076097,197.91589,-0.010337619,9.7549973,11.075717,197.66824,-9.3727942
67.2,0.74899411,-0.15991564,46.580742,0,11.076097,201.5159,-0.010585019,9.651927,11.075904,201.17755,-9.3709726
68.4,0.75632817,-0.16391471,46.582027,0,11.076097,205.11589,-0.010853712,9.7302485,11.076948,204.81227,-9.3686447
69.6,0.7610094,-0.16647446,46.582027,0,11.076097,208.7159,-0.011034693,9.8020611,11.076126,208.47186,-9.3671598
70.8,0.752415,-0.1701846,47.05444,0,11.076097,212.3159,-0.011308208,9.6912928,11.076034,211.92741,-9.3649292
72.0,0.74683553,-0.1736344,47.169926,0,11.076097,215.91589,-0.011532851,9.6227388,11.075875,215.41872,-9.3630724
73.2,0.76085955,-0.17833544,47.503948,0,11.076097,219.5159,-0.011780855,9.7913694,11.077097,219.04466,-9.3610802
74.4,0.75793606,-0.18010111,47.504883,0,11.076097,223.11591,-0.011981334,9.7622471,11.076589,222.68312,-9.3587923
75.6,0.75945306,-0.18425696,47.656197,0,11.076097,226.7159,-0.012203811,9.7856846,11.075083,226.30411,-9.3571453
76.8,0.749479,-0.18820666,47.954262,0,11.076097,230.31589,-0.012413316,9.6811094,11.075697,229.96104,-9.3551846
78.0,0.7550776,-0.19129106,47.955318,0,11.076097,233.91591,-0.012699634,9.729516,11.077437,233.56436,-9.3532982
79.2,0.76679295,-0.19619358,47.955318,0,11.076097,237.51588,-0.012978991,9.9000483,11.076084,237.25467,-9.3512001
80.4,0.76712561,-0.19839144,48.189808,0,11.076097,241.11588,-0.013133113,9.9000082,11.076367,240.82068,-9.3495169
81.6,0.74575061,-0.20269904,48.383339,0,11.076097,244.71588,-0.013427783,9.6265078,11.076866,244.40057,-9.3473234
82.8,0.75070071,-0.20628156,48.383785,0,11.076097,248.31589,-0.013686176,9.7039833,11.077548,248.08794,-9.3455467
84.0,0.74430156,-0.21008767,48.392445,0,11.076097,251.91589,-0.013924546,9.6231699,11.076309,251.65617,-9.3434515
85.2,0.76723921,-0.21390685,48.752079,0,11.076097,255.51588,-0.014110509,9.9065619,11.07648,255.20831,-9.3415155
86.4,0.76810348,-0.21825005,48.812252,0,11.076097,259.11615,-0.014488941,9.9231253,11.076504,258.85065,-9.3395233
87.6,0.76534575,-0.22027133,48.812252,0,11.076097,262.71588,-0.014561309,9.8986692,11.077684,262.3743,-9.3376122
88.8,0.75686938,-0.22422028,49.228073,0,11.076097,266.31589,-0.014815815,9.7937326,11.075679,265.89215,-9.3353548
90.0,0.76328009,-0.22794822,49.229733,0,11.076097,269.91586,-0.015078023,9.8813963,11.076205,269.50653,-9.3336124
91.2,0.75263524,-0.23146732,49.6325,0,11.076097,273.5159,-0.015339118,9.7374763,11.076066,273.03836,-9.3317528
92.4,0.75566792,-0.23502766,49.636227,0,11.076097,277.11588,-0.015571672,9.7735338,11.07618,276.67151,-9.3299417
93.6,0.75434929,-0.23931001,49.995869,0,11.076097,280.71588,-0.015791129,9.7602081,11.075849,280.18658,-9.3279581
94.8,0.75467741,-0.24226047,50.042721,0,11.076097,284.31586,-0.016065298,9.7581434,11.076654,283.86713,-9.3259764
96.0,0.76333392,-0.24655992,50.042721,0,11.076097,287.91589,-0.016264714,9.8753328,11.076674,287.55093,-9.3241386
97.2,0.76969171,-0.25147054,50.305984,0,11.076097,291.51587,-0.016606102,9.969924,11.076266,291.13312,-9.322155
98.4,0.77190459,-0.25375521,50.438229,0,11.076097,295.11591,-0.016780932,10.005324,11.076734,294.6651,-9.320406
99.6,0.76553249,-0.25598049,50.661865,0,11.076097,298.71588,-0.016950633,9.9126987,11.077215,298.24384,-9.3182344
100.8,0.7653836,-0.25997806,50.82275,0,11.076097,302.31592,-0.017189048,9.9233294,11.07615,301.86249,-9.3161602
102.0,0.75745046,-0.2645396,51.196285,0,11.076097,305.91589,-0.017427979,9.8133402,11.076531,305.30511,-9.3144226
103.2,0.75585181,-0.26827502,51.201771,0,11.076097,309.5159,-0.017746586,9.8016872,11.076201,308.93387,-9.3123341
104.4,0.74767148,-0.27238345,51.56982,0,11.076097,313.11591,-0.017981257,9.6936989,11.076606,312.51208,-9.3107023
105.6,0.77282071,-0.27753416,51.757011,0,11.076097,316.71591,-0.018346114,10.03004,11.076133,316.16553,-9.3086815
106.8,0.77573359,-0.27973452,51.932331,0,11.076097,320.31592,-0.018445032,10.069886,11.075467,319.87378,-9.306901
108.0,0.76173896,-0.28336391,51.932369,0,11.076097,323.91589,-0.018748736,9.8923578,11.076427,323.55612,-9.3044043
109.2,0.76147842,-0.28790367,51.932369,0,11.076097,327.51593,-0.01899213,9.8948708,11.076326,327.22754,-9.3025331
110.4,0.75617641,-0.29236296,51.932369,0,11.076097,331.11591,-0.019307451,9.8226299,11.076829,330.87115,-9.3007364
111.6,0.77570188,-0.29802799,51.932369,0,11.076097,334.71591,-0.019653084,10.072632,11.076195,334.58054,-9.2988625
112.8,0.77645326,-0.29893246,51.932377,0,11.076097,338.31592,-0.01977076,10.092042,11.076914,338.12415,-9.2968655
114.0,0.76487416,-0.30367395,52.141506,0,11.076097,341.91592,-0.020016655,9.9413729,11.076619,341.72116,-9.2950506
115.2,0.75760919,-0.30787507,52.283936,0,11.076097,345.5159,-0.020304047,9.8483543,11.076503,345.33859,-9.293087
116.4,0.76064628,-0.31160259,52.283932,0,11.076097,349.11594,-0.020555237,9.8687792,11.076373,348.94211,-9.291194
117.6,0.77570248,-0.31704083,52.283936,0,11.076097,352.71588,-0.020966182,10.083114,11.075732,352.5683,-9.2891378
118.8,0.77045465,-0.31867865,52.295807,0,11.076097,356.31586,-0.021002701,10.022053,11.07585,356.03531,-9.2870464
120.0,0.76290798,-0.32378194,52.635494,0,11.076097,359.91589,-0.021340374,9.9311523,11.075862,359.45157,-9.2853441
121.2,0.74978238,-0.32804427,52.923321,0,11.076097,363.5159,-0.021618422,9.763937,11.076345,363.03668,-9.2830219
122.4,0.77333337,-0.33222824,52.97607,0,11.076097,367.11588,-0.021933351,10.066707,11.075753,366.6123,-9.2810764
123.6,0.78307402,-0.33589172,53.31665,0,11.076097,370.71591,-0.022128494,10.199038,11.075916,370.05618,-9.278944
124.8,0.77201396,-0.3398186,53.530663,0,11.076097,374.31589,-0.022404293,10.062489,11.07601,373.69489,-9.2771568
126.0,0.76216096,-0.3450124,53.657223,0,11.076097,377.91589,-0.022712801,9.9419622,11.076366,377.44608,-9.2753954
127.2,0.76261103,-0.34852603,53.657223,0,11.076097,381.51587,-0.023020567,9.9227982,11.075061,381.17755,-9.2733755
128.4,0.78592718,-0.3545166,53.655399,0,11.076097,385.11591,-0.023337262,10.243335,11.07491,384.99896,-9.2712917
129.6,0.77592587,-0.35608345,53.367161,0,11.076097,388.71588,-0.023481341,10.121506,11.076323,388.81372,-9.2694321
130.8,0.76523918,-0.36150879,53.316654,0,11.076097,392.31589,-0.023776637,9.9790363,11.076582,392.48285,-9.2673197
132.0,0.75659442,-0.36543989,52.984802,0,11.076097,395.91589,-0.024103744,9.8711843,11.075682,396.32782,-9.2656593
133.2,0.77837157,-0.37087986,52.975346,0,11.076097,399.5159,-0.02440824,10.153803,11.076634,400.02365,-9.2636557
134.4,0.78211021,-0.37214884,52.635502,0,11.076097,403.11591,-0.024536502,10.20974,11.076159,403.71509,-9.2619162
135.6,0.76680762,-0.37674031,52.496712,0,11.076097,406.71588,-0.024749191,10.009219,11.07678,407.24448,-9.2595253
136.8,0.76195192,-0.38053206,52.387199,0,11.076097,410.31589,-0.025061088,9.960844,11.076585,410.69473,-9.2578611
138.0,0.77112031,-0.38364288,52.635494,0,11.076097,413.91589,-0.025276657,10.059733,11.077196,414.00018,-9.2556763
139.2,0.78003722,-0.38737616,52.779377,0,11.076097,417.5159,-0.025501277,10.193057,11.076166,417.32288,-9.2535362
140.4,0.77126408,-0.39132002,53.014027,0,11.076097,421.11591,-0.025719067,10.075317,11.076271,420.59857,-9.2519751
141.6,0.76395541,-0.39600766,53.390194,0,11.076097,424.71591,-0.026049314,9.990325,11.075871,423.99469,-9.2501335
142.8,0.77707732,-0.39988139,53.687286,0,11.076097,428.31592,-0.026344728,10.140262,11.076624,427.5145,-9.2479458
144.0,0.78392065,-0.4038308,53.975826,0,11.076097,431.91592,-0.026554728,10.2399,11.075837,431.16296,-9.246172
145.2,0.7738356,-0.40864435,53.975826,0,11.076097,435.51593,-0.02689565,10.130363,11.075624,434.92288,-9.2438707
146.4,0.76451403,-0.41394299,54.063759,0,11.076097,439.11591,-0.027173532,9.9974804,11.075836,438.70093,-9.2418966
147.6,0.77535897,-0.41726732,53.99855,0,11.076097,442.71594,-0.027446443,10.13163,11.077683,442.53162,-9.2399931
148.8,0.78474182,-0.42245406,53.975834,0,11.076097,446.31592,-0.027812185,10.277353,11.077043,446.285,-9.2380209
150.0,0.77856058,-0.42567,53.975834,0,11.076097,449.91425,-0.027987789,10.200148,11.076164,450.00989,-9.2360077
151.2,0.081068143,-0.43705729,52.290897,0,11.076097,449.9989,-0.028693743,1.0637919,11.076364,451.79813,-9.2358952
152.4,0.071191326,-0.43582702,51.830612,0,11.076097,449.9989,-0.028634816,0.93591928,11.076081,451.7355,-9.2361193
153.6,0.078629568,-0.43463814,51.361664,0,11.076097,449.9989,-0.028593855,1.0390631,11.076653,451.4906,-9.2360497
154.8,0.082223028,-0.43461084,51.196293,0,11.076097,449.9989,-0.028546834,1.067206,11.076096,451.09616,-9.2359352
156.0,0.076695964,-0.43274885,51.196293,0,11.076097,449.9989,-0.028467922,0.98869252,11.076494,450.6337,-9.2359095
157.2,0.073976114,-0.43279216,51.569809,0,11.076097,449.9989,-0.028395684,0.98324466,11.075423,450.02554,-9.2359047
158.4,0.071459927,-0.43268624,51.932369,0,11.076097,449.9989,-0.02844465,0.94988346,11.076577,449.51556,-9.2361813
159.6,0.069367521,-0.43268207,52.539677,0,11.076097,449.9989,-0.028474852,0.90752709,11.07664,449.11142,-9.2361994
160.8,0.071505263,-0.43336761,52.97607,0,11.076097,449.9989,-0.028461404,0.94975626,11.07623,448.90607,-9.2360506
162.0,0.089074455,-0.43388712,53.31665,0,11.076097,449.9989,-0.028523926,1.1644626,11.077108,449.01373,-9.2359037
163.2,0.09937264,-0.43572003,53.541168,0,11.076097,449.9989,-0.02859473,1.2971743,11.076612,449.08344,-9.2360306
164.4,0.10597093,-0.43510512,53.651432,0,11.076097,449.9989,-0.028615659,1.3862216,11.076387,449.44891,-9.2361069
165.6,0.099395745,-0.43532339,53.316654,0,11.076097,449.9989,-0.028641218,1.2843729,11.074967,449.85941,-9.2359648
166.8,0.10029557,-0.43650916,53.075226,0,11.076097,449.9989,-0.028665496,1.3116846,11.076409,450.16577,-9.2360325
168.0,0.10122161,-0.43719706,52.773865,0,11.076097,449.9989,-0.028730677,1.3314875,11.07605,450.47333,-9.2362623
169.2,0.097856253,-0.43826932,52.615417,0,11.076097,449.9989,-0.028755248,1.2802442,11.075123,450.68683,-9.2360926
170.4,0.083194919,-0.43835449,52.283939,0,11.076097,449.9989,-0.028824046,1.0842996,11.075166,450.75162,-9.2359858
171.6,0.082950808,-0.43886909,51.932617,0,11.076097,449.9989,-0.028861141,1.0831168,11.075977,450.60944,-9.2359056
172.8,0.096055292,-0.43879917,51.932377,0,11.076097,449.9989,-0.028813107,1.2408082,11.076043,450.53662,-9.2365007
174.0,0.10147653,-0.44046327,52.013138,0,11.076097,449.9989,-0.028944952,1.3125838,11.077521,450.23358,-9.2360888
175.2,0.10916904,-0.4401266,52.094296,0,11.076097,449.9989,-0.028883092,1.4198966,11.075876,450.03845,-9.2360315
176.4,0.10570266,-0.43951228,52.283936,0,11.076097,449.9989,-0.028887706,1.3737733,11.07666,449.89267,-9.235899
177.6,0.10385783,-0.4399468,52.28635,0,11.076097,449.9989,-0.028945962,1.3584259,11.076083,449.84912,-9.2361574
178.8,0.10086457,-0.44080546,52.492283,0,11.076097,449.9989,-0.028940331,1.3264613,11.075217,449.81247,-9.2362337
180.0,0.097443491,-0.44163504,52.635101,0,11.076097,449.9989,-0.029032389,1.2743006,11.076888,449.77786,-9.2361755
181.2,0.091529481,-0.4426665,52.635494,0,11.076097,449.9989,-0.029032109,1.198791,11.075698,449.91125,-9.2360945
182.4,0.095278032,-0.44324011,52.609364,0,11.076097,449.9989,-0.029126113,1.2384014,11.076178,449.93454,-9.2358093
183.6,0.10334234,-0.44336244,52.286545,0,11.076097,449.9989,-0.029151566,1.3619281,11.077164,450.05359,-9.2361431
184.8,0.10971305,-0.44496661,52.283939,0,11.076097,449.9989,-0.029219886,1.4302953,11.076694,450.13092,-9.2359753
186.0,0.11459978,-0.4444553,52.283939,0,11.076097,449.9989,-0.029216569,1.5072122,11.076408,450.13226,-9.2359419
187.2,0.11038992,-0.44394773,52.283939,0,11.076097,449.9989,-0.029136045,1.4501393,11.07609,450.08102,-9.2359152
188.4,0.11278728,-0.44484192,52.239719,0,11.076097,449.9989,-0.029200122,1.4668492,11.07647,450.17184,-9.2362909
189.6,0.10227481,-0.44555759,52.234745,0,11.076097,449.9989,-0.029279778,1.3427237,11.076879,450.13977,-9.2360935
190.8,0.10101986,-0.44587386,51.970284,0,11.076097,449.9989,-0.029338652,1.3239391,11.076438,450.19699,-9.2359409
192.0,0.099932782,-0.44638771,52.029858,0,11.076097,449.9989,-0.029304363,1.3106805,11.075709,450.1059,-9.2359114
193.2,0.099979132,-0.44692999,52.283936,0,11.076097,449.9989,-0.029397227,1.3086598,11.075769,450.01608,-9.2359629
194.4,0.093480498,-0.44764858,52.217739,0,11.076097,449.9989,-0.029362431,1.2175171,11.076295,449.98987,-9.2361774
195.2805,0.1890619,0.014258694,52.283939,0,11.076099,3.208111,0.0010876937,2.348738,11.076851,449.96799,-9.23557
195.2829,0.16943197,0.016071875,52.283939,0,11.076099,1.3868656000000002e-16,0.0010906759,2.2093978,11.076366,449.98956,-9.2358246
195.2853,0.15969475,0.017951928,52.283939,0,11.076099,5.9954172e-33,0.00098599109,2.039427,11.075529,450.01111,-9.2362461
195.2877,0.22074252,0.022448691,52.283939,0,11.076099,0.0,0.0012832213,2.8562536,11.075185,450.03265,-9.2371845
195.2901,0.19815707,0.020143207,52.283939,0,11.076099,0.0,0.0013627951,2.5980995,11.07974,450.05423,-9.2351265
195.2925,0.1904403,0.017268592,40.258553,0,11.076099,0.0,0.0013412976,2.4034042,11.075856,450.03445,-9.2352953
195.2949,0.25075489,0.01652359,27.710409,0,11.076099,0.0,0.0012881202,3.2002025,11.078117,450.01291,-9.2361555
195.2973,0.18173312,0.01703022,15.162264,0,11.076099,0.0,0.0011384164,2.3330531,11.080136,449.99133,-9.2362623
195.2997,0.20336869,0.01876444,2.61412,0,11.076099,0.0,0.0010759273,2.504674,11.075303,449.96979,-9.2352285
195.3021,0.20601006,0.018397067,0.0,0,11.076099,0.0,0.0011018499,2.6676779,11.07408,449.98236,-9.2342577
195.3045,0.18097669,0.01656796,0.0,0,11.076099,0.0,0.0011117664,2.4310844,11.076204,450.00391,-9.2366266
195.3069,0.185123,0.016226215,0.0,0,11.076099,0.0,0.0012956734,2.3786967,11.077715,450.02548,-9.2357302
195.3093,0.1942011,0.016720096,0.0,0,11.076099,0.0,0.0012359999,2.4464693,11.074761,450.04703,-9.2349167
195.3117,0.20074816,0.017380944,0.0,0,11.076099,0.0,0.0011453244,2.6517117,11.072847,450.05063,-9.23528
195.3141,0.20231207,0.020475637,0.0,0,11.076099,0.0,0.0011261551,2.6094823,11.073017,450.04346,-9.2357607
195.3165,0.1991296,0.023310523,0.0,0,11.076099,0.0,0.001307857,2.4873824,11.07363,450.03629,-9.2361727
195.3189,0.19867767,0.020565281,0.0,0,11.076099,0.0,0.0013977364,2.5470603,11.073012,450.02908,-9.2368135
195.3213,0.20767006,0.017346403,0.0,0,11.076099,0.0,0.0013737931,2.6336672,11.073931,450.0318,-9.2353878
195.3237,0.20367049,0.015335171,0.0,0,11.076099,0.0,0.0011686898,2.652678,11.07399,450.04617,-9.2353525
195.3261,0.19865805,0.016923234,0.0,0,11.076099,0.0,0.0010646714,2.5453625,11.073709,450.06055,-9.2357101
195.3285,0.19393912,0.018879838,0.0,0,11.076099,0.0,0.0011032792,2.5768199,11.072557,450.07489,-9.2374001
195.3309,0.20237172,0.018368708,0.0,0,10.976468,0.0,0.0011120358,2.6013987,11.073727,450.0788,-9.2374926
195.3333,0.21552452,0.01806158,0.0,0,10.615494,0.0,0.0012673261,2.6545906,11.074957,450.05722,-9.2362595
195.3357,0.21307848,0.017623555,0.0,0,10.254521,0.0,0.001374888,2.7804902,11.054178,450.03568,-9.2358875
195.3381,0.23574652,0.018661926,0.0,0,9.8935471,0.0,0.0013880301,2.9868369,10.925193,450.0141,-9.2363949
195.3405,0.20564316,0.019495754,0.0,0,9.5325737,0.0,0.0012326192,2.5564082,10.647541,450.09225,-9.2371054
195.3429,0.2402298,0.02286162,0.0,0,9.1800261,0.0,0.0012941547,3.0766656,10.248414,450.86838,-9.2360764
195.3453,5.4645395,0.40028676,0.0,0,8.8288574,0.0,0.02583996,68.483704,9.7725,451.64447,-9.230896
195.3477,6.4199986,0.81641179,0.0,0,8.491025,0.0,0.055891309,77.118301,9.2453518,452.42059,-9.2313671
195.3501,6.3970532,1.2539908,0.0,0,8.1570406,0.0,0.087078415,74.765938,8.7932911,453.19672,-9.2312727
195.3525,6.4486856,1.633285,0.0,0,7.8342953,0.0,0.11518759,72.973907,8.4272861,453.74554,-9.2328272
195.3549,6.7330918,1.9255894,0.0,0,7.5165353,0.0,0.13690653,74.754234,8.1141281,454.28452,-9.2312555
195.3573,6.8250399,2.2097888,0.0,0,7.2082515,0.0,0.15875438,73.991211,7.8095107,454.82349,-9.2302837
195.3597,6.9336853,2.5092409,0.0,0,6.9060431,0.0,0.18243751,73.597969,7.5126801,455.36246,-9.2309027
195.3621,7.0590901,2.7806869,0.0,0,6.6115613,0.0,0.2047853,73.218445,7.2334185,455.66815,-9.230937
195.3645,7.287334,3.055197,0.0,0,6.3240414,0.0,0.22770737,73.846748,6.9549356,455.91248,-9.2324286
195.3669,7.465148,3.3345942,0.0,0,6.042748,0.0,0.25128761,73.903748,6.6689467,456.15683,-9.2302485
195.3693,7.614913,3.6202416,0.0,0,5.7692914,0.0,0.27570072,73.648354,6.3857489,456.40115,-9.2314301
195.3717,7.7906947,3.9101818,0.0,0,5.5006132,0.0,0.30113256,73.353752,6.0970345,455.22101,-9.2315865
195.3741,8.0072737,4.1983609,0.0,0,5.2404532,0.0,0.3275798,73.433502,5.8098583,453.18622,-9.2313843
195.3765,8.2130499,4.4805865,0.0,0,4.9838037,0.0,0.35446906,73.285927,5.5194378,451.15146,-9.2318211
195.3789,8.401763,4.7562857,0.0,0,4.7363639,0.0,0.38143742,73.000313,5.2391038,449.11667,-9.2316837
195.3813,8.5463476,5.0276856,0.0,0,4.4912457,0.0,0.40812922,72.33725,4.965508,446.55771,-9.2307405
195.3837,8.7220573,5.2858982,0.0,0,4.2558532,0.0,0.43399239,71.99234,4.7042823,443.37933,-9.2324095
195.3861,8.9387131,5.5401068,0.0,0,4.0217257,0.0,0.46008253,71.817902,4.4538436,440.20096,-9.2314291
195.3885,9.1483097,5.7818766,0.0,0,3.7978492,0.0,0.48619664,71.646957,4.2115951,437.02258,-9.2308664
195.3909,9.3435507,6.0132036,0.0,0,3.5743496,0.0,0.51207238,71.257362,3.9785953,434.64737,-9.2308283
195.3933,9.5553341,6.2401476,0.0,0,3.3612847,0.0,0.53807062,70.996269,3.7457192,434.22275,-9.2314653
195.3957,9.8055258,6.4619627,0.0,0,3.1483085,0.0,0.56352437,71.023041,3.5246668,433.7981,-9.2321291
195.3981,10.102072,6.6804986,0.0,0,2.9451063,0.0,0.58887571,71.281876,3.3119335,433.37344,-9.2315693
195.4005,10.376661,6.9025898,0.0,0,2.7424982,0.0,0.61528951,71.35482,3.0959485,432.87222,-9.2312851
195.4029,10.65788,7.116909,0.0,0,2.5483871,0.0,0.64221865,71.399452,2.8805246,431.83484,-9.2306833
195.4053,10.947817,7.320497,0.0,0,2.3556671,0.0,0.66925579,71.345871,2.6759322,430.79745,-9.231164
195.4077,11.321638,7.5160379,0.0,0,2.170248,0.0,0.69583005,71.818512,2.4779556,429.7601,-9.2318039
195.4101,11.673897,7.7107325,0.0,0,1.986936,0.0,0.72175384,72.186058,2.2784064,428.72272,-9.230998
195.4125,12.00759,7.9014745,0.0,0,1.8098083,0.0,0.74739552,72.37941,2.0863247,428.92783,-9.2308683
195.4149,12.395352,8.091958,0.0,0,1.6354243,0.0,0.77416617,72.740288,1.9029169,429.18692,-9.2285995
195.4173,12.818652,8.2754898,0.0,0,1.4662172,0.0,0.801337,73.201981,1.724702,429.44601,-9.2283831
195.4197,13.271713,8.4479198,0.0,0,1.3003292,0.0,0.82815313,73.779335,1.5447892,429.70511,-9.2289009
195.4221,13.746996,8.6184053,0.0,0,1.1387082,0.0,0.85501671,74.407715,1.3751788,424.77225,-9.2277813
195.4245,14.220405,8.7860928,0.0,0,0.98093224,0.0,0.88143802,74.939178,1.2028452,418.47314,-9.227046
195.4269,14.747192,8.9528437,0.0,0,0.82657719,0.0,0.90767473,75.685165,1.0346334,412.17401,-9.2267637
195.4293,15.345043,9.1153498,0.0,0,0.67652929,0.0,0.93406957,76.70977,0.87435132,405.87488,-9.2281733
195.4317,15.959925,9.2734165,0.0,0,0.52908581,0.0,0.96175796,77.60952,0.71495742,401.14685,-9.2272615
195.4341,16.5525,9.42272,0.0,0,0.38628578,0.0,0.98931777,78.334511,0.5636121,397.36139,-9.226819
195.4365,14.370209,9.5005388,0.0,0,0.24542005,0.0,1.0046241,66.869659,0.44527799,393.57596,-9.2298298
195.4389,12.975783,9.5140409,0.0,0,0.10962804,0.0,1.0066465,60.45575,0.39150184,389.79053,-9.2306213
195.4413,12.216141,9.5175409,0.0,0,-0.025516471,0.0,1.0061989,56.88464,0.36143115,390.36618,-9.2313938
195.4437,11.750399,9.5233135,0.0,0,-0.15794852,0.0,1.0064834,54.697819,0.33144242,396.0957,-9.2314434
195.4461,11.594787,9.5291204,0.0,0,-0.29038054,0.0,1.0080022,53.861214,0.29759255,401.82526,-9.2312155
195.4485,11.801879,9.5338326,0.0,0,-0.42281252,0.0,1.0099622,54.708664,0.24430907,407.55478,-9.2322559
195.4509,12.03771,9.5347214,0.0,0,-0.55524451,0.0,1.0107094,55.757519,0.17773534,412.42123,-9.2329941
195.4533,12.076397,9.5448399,0.0,0,-0.68767649,0.0,1.0120823,55.89994,0.1101198,415.19177,-9.2315311
195.4557,11.972736,9.5516624,0.0,0,-0.82010847,0.0,1.0121464,55.422634,0.051449306,417.96231,-9.2322893
195.4581,11.743983,9.5596666,0.0,0,-0.95254052,0.0,1.0130093,54.327324,0.0032086901,420.73285,-9.2318077
195.4605,11.404782,9.5655756,0.0,0,-1.0849725,0.0,1.0142913,52.695129,-0.028247375,423.33994,-9.2318258
195.4629,10.936135,9.5650444,0.0,0,-0.72870666,450.0,1.0156337,50.471195,-0.040008981,424.80295,-9.2326384
195.4653,10.445538,9.5563841,0.0,0,-0.27022031,450.0,1.0148048,48.233383,-0.040405083,426.26596,-9.2345057
195.4677,10.02345,9.5566921,0.0,0,0.18826602,450.0,1.0145077,46.326546,-0.034095995,427.72897,-9.2333908
195.4701,9.669528,9.5616131,0.0,0,0.64675242,450.0,1.0142379,44.655178,-0.033406593,429.19199,-9.2335491
195.4725,9.402606,9.5643396,9.7511969,0,1.105239,450.0,1.0140396,43.448322,-0.029015247,430.39798,-9.2333384
195.4749,8.8717499,9.5633535,19.926294,0,1.5637254,450.0,1.0142416,41.080257,-0.013182732,431.59283,-9.2339544
195.4773,7.3773942,9.5542288,30.101393,0,2.0222118,450.0,1.0136894,34.174911,0.065605313,432.78766,-9.2350264
195.4797,4.7093697,9.5377197,40.276493,0,2.4806983,450.0,1.0113844,22.042799,0.21045488,433.98248,-9.237381
195.4821,1.1911809,9.5151434,42.39624,0,2.9391847,450.0,1.0067255,5.9629078,0.44652465,435.44501,-9.2388659
195.4845,-0.15471359,9.4590864,42.39624,0,3.3976712,450.0,0.99547857,-0.51818788,0.92482102,436.978,-9.2393513
195.4869,-0.15553966,9.4431992,42.39624,0,3.8561575,450.0,0.99203938,-0.93697751,1.6581388,438.51096,-9.2418394
195.4893,0.20638768,9.4301271,42.39624,0,4.3146439,450.0,0.98979676,0.96960348,2.4646299,440.04391,-9.2416267
195.4917,-0.082570776,9.4458714,39.301365,0,4.7731299,450.0,0.99388999,-0.31570831,3.1448188,441.34705,-9.2409325
195.4941,-0.0068784924,9.4655838,34.349606,0,5.2316165,450.0,0.99813628,-0.037614595,3.6400015,442.5123,-9.2401676
195.4965,0.15197943,9.5035868,29.397848,0,5.6901031,450.0,1.0044624,0.66836929,4.0673208,443.67752,-9.2397833
195.4989,0.03321445,9.5034952,24.446089,0,6.1485891,450.0,1.0034887,0.20184289,4.4858093,444.84277,-9.239212
195.5013,-0.053776044,9.5164452,21.763916,0,6.6070752,450.0,1.0051982,-0.23846644,4.8999352,445.85272,-9.2388639
195.5037,0.1507787,9.5121679,21.763916,0,7.0655622,450.0,1.0049254,0.6393401,5.3354487,446.67911,-9.2379055
195.5061,-0.028341569,9.5112801,21.763916,0,7.5240488,450.0,1.0057579,-0.071067557,5.7926326,447.50552,-9.2363291
195.5085,-0.0078895772,9.5061064,21.763916,0,7.9825354,450.0,1.0055628,-0.056522805,6.2763557,448.33194,-9.2376976
195.5109,0.085476011,9.50245,20.24041,0,8.441021,450.0,1.0045789,0.34189835,6.7688999,449.09546,-9.2364254
195.5133,-0.047923911,9.5137777,15.017071,0,8.8995075,450.0,1.0052321,-0.18136333,7.2570515,449.7063,-9.2372904
195.5157,0.010274304,9.5193262,9.7937317,0,9.3579931,450.0,1.0053792,0.0051318132,7.7245631,450.31714,-9.2362604
195.5181,0.10460624,9.5149097,4.5703912,0,9.8164806,450.0,1.0052285,0.52447772,8.1988916,450.92795,-9.236166
195.5205,-0.0045158342,9.5112896,0.0,0,10.274966,450.0,1.0059568,-0.0027497818,8.6633005,451.50916,-9.2366476
195.5229,-0.02653762,9.5060139,0.0,0,10.733453,450.0,1.0055903,-0.12705997,9.1341982,451.88281,-9.2360001
195.5253,0.10932266,9.5019159,0.0,0,11.191939,450.0,1.0043023,0.45882419,9.6132784,452.2565,-9.2362051
195.5277,-0.039742816,9.5045843,0.0,0,11.650426,450.0,1.0036846,-0.097244814,10.082371,452.63019,-9.2350397
195.5301,0.05726869,9.5104485,0.0,0,12.108912,450.0,1.0042504,0.21141785,10.557933,453.00388,-9.2351141
195.5325,0.011138516,9.5087042,0.0,0,12.567399,450.0,1.0043288,0.097800463,11.034213,453.37756,-9.2345591
195.5349,-0.01892479,9.5061579,0.0,0,13.025885,450.0,1.0048575,-0.019243985,11.501789,453.75122,-9.2359009
195.5373,0.040716074,9.5066376,0.0,0,13.484371,450.0,1.0056673,0.056641582,11.956372,454.12491,-9.2359772
195.5397,0.073214278,9.5025835,0.0,0,13.942858,450.0,1.0044523,0.34020051,12.417456,454.4986,-9.2346249
195.5421,-0.057368878,9.5075722,0.0,0,14.401344,450.0,1.0039111,-0.32488608,12.879445,454.85522,-9.2355375
195.5445,0.00859972,9.5131254,0.0,0,14.859831,450.0,1.0044655,0.022857063,13.344819,455.20734,-9.2358742
195.5469,0.061442073,9.5129242,0.0,0,15.318317,450.0,1.0048504,0.28010759,13.82477,455.55948,-9.2352819
195.5493,-0.082803287,9.5088854,0.0,0,15.776803,450.0,1.0055474,-0.30241451,14.299018,455.91159,-9.2347593
195.5517,0.12533249,9.5041523,0.0,0,16.235291,450.0,1.0052789,0.51184785,14.775432,456.20084,-9.233778
195.5541,0.00011940674,9.5042219,0.0,0,16.693775,450.0,1.0046811,0.039573971,15.237374,456.45236,-9.2347822
195.5565,-0.003364082,9.5059433,0.0,0,17.152262,450.0,1.0038733,0.021964606,15.694729,456.70386,-9.2342701
195.5589,0.011218169,9.5125475,0.0,0,17.61075,450.0,1.0044416,0.02394711,16.149933,456.95538,-9.235754
195.5613,0.10570365,9.5080128,0.0,0,17.999975,450.0,1.0042362,0.51435339,16.604437,457.18384,-9.2349625
195.5637,-0.1033902,9.5055227,0.0,0,18.0,450.0,1.00482,-0.44435197,17.05146,457.38504,-9.2351847
195.5661,0.062410314,9.5042419,0.0,0,18.0,450.0,1.005247,0.28722674,17.484341,457.58627,-9.2363777
195.5685,-0.019265672,9.5059443,0.0,0,18.0,450.0,1.0048287,-0.12791434,17.872326,457.78748,-9.2373905
195.5709,0.098104693,9.5095911,0.0,0,18.0,450.0,1.0043877,0.41534761,18.190855,457.9761,-9.2378979
195.5733,0.041225471,9.5182266,0.0,0,18.0,450.0,1.0051688,0.18089114,18.420462,458.13416,-9.2397947
195.5757,0.079808168,9.5222006,0.0,0,18.0,450.0,1.00659,0.36471766,18.527815,458.29221,-9.2441826
195.5781,0.26547807,9.5236435,0.0,0,18.0,450.0,1.0082238,1.2577457,18.509491,458.45026,-9.2508545
195.5805,0.22914256,9.5226202,0.0,0,18.0,450.0,1.0086727,1.0669551,18.387384,458.61279,-9.2602739
195.5829,0.34130165,9.523345,0.0,0,18.0,450.0,1.0079703,1.568171,18.242994,458.80661,-9.2724304
195.5853,0.27260882,9.5249863,0.0,0,18.0,450.0,1.0072417,1.327531,18.127522,459.00046,-9.2891102
195.5877,0.24631493,9.5267563,0.0,0,18.0,450.0,1.0072421,1.1422117,18.056059,459.19427,-9.310092
195.5901,0.21792944,9.5263176,0.0,0,18.0,450.0,1.007884,0.97839969,18.042492,459.38809,-9.3319902
195.5925,0.29753795,9.5189419,0.0,0,18.0,450.0,1.0074276,1.339761,18.046976,459.62314,-9.3530626
195.5949,0.27696827,9.5151215,0.0,0,18.0,450.0,1.0073526,1.285208,18.069565,459.85995,-9.3723974
195.5973,0.27392349,9.5180159,0.0,0,18.0,450.0,1.0067865,1.2243042,18.096203,460.09677,-9.3923941
195.5997,0.20901899,9.5212831,0.0,0,18.0,450.0,1.0064344,0.98302889,18.121811,460.33359,-9.4132748
195.6021,0.27906922,9.5243158,0.0,0,18.0,450.0,1.0064304,1.2736644,18.139772,460.53064,-9.4316664
195.6045,0.27756405,9.5249891,0.0,0,18.0,450.0,1.0071784,1.2899039,18.149401,460.71725,-9.4477749
195.6069,0.30195916,9.5215054,0.0,0,18.0,450.0,1.0079508,1.3998568,18.151476,460.90384,-9.4659014
195.6093,0.2501674,9.5165997,0.0,0,18.0,450.0,1.0076782,1.1972649,18.151115,461.09042,-9.4831171
195.6117,0.25242689,9.5169916,0.0,0,18.0,450.0,1.0069102,1.1719747,18.145622,461.25012,-9.5018539
195.6141,0.3036226,9.5200005,0.0,0,18.0,450.0,1.0062073,1.3841825,18.146507,461.39365,-9.5196772
195.6165,0.32043988,9.5222569,0.0,0,18.0,450.0,1.0062062,1.5075235,18.139582,461.5372,-9.535656
195.6189,0.28068382,9.5247231,0.0,0,18.0,450.0,1.0075245,1.3323808,18.136307,461.68073,-9.5531712
195.6213,0.27140594,9.522892,0.0,0,18.0,450.0,1.0079575,1.2662567,18.135513,461.82755,-9.5724974
195.6237,0.27458701,9.518137,0.0,0,18.0,450.0,1.0076444,1.2749436,18.135492,461.97827,-9.5906334
195.6261,0.3269625,9.5180721,0.0,0,18.0,450.0,1.0070398,1.5455105,18.131504,462.12897,-9.6071081
195.6285,0.31456351,9.5235453,0.0,0,18.0,450.0,1.0068216,1.4812301,18.127813,462.27966,-9.6248007
195.6309,0.27258584,9.5292635,0.0,0,18.0,450.0,1.0071986,1.2873439,18.12365,462.422,-9.6432858
195.6333,0.27005929,9.5287104,0.0,0,18.0,450.0,1.0080788,1.2461721,18.119059,462.54401,-9.662405
195.6357,0.32020023,9.5234041,0.0,0,18.0,450.0,1.0082729,1.4597151,18.118824,462.66602,-9.6802607
195.6381,0.33345553,9.520256,0.0,0,18.0,450.0,1.0080322,1.548612,18.117764,462.78802,-9.6978788
195.6405,0.30142605,9.5189762,0.0,0,18.0,450.0,1.007136,1.4387493,18.11767,462.90555,-9.71665
195.6429,0.2695812,9.5206938,0.0,0,18.0,450.0,1.0064809,1.2726789,18.116261,462.99167,-9.7352571
195.6453,0.28205103,9.5243864,0.0,0,18.0,450.0,1.0067539,1.2998902,18.11496,463.07779,-9.7531261
195.6477,0.33199939,9.5220814,0.0,0,18.0,450.0,1.0071452,1.5169713,18.111813,463.16391,-9.7708874
195.6501,0.32626048,9.5193653,0.0,0,18.0,450.0,1.0073376,1.5626686,18.105894,463.25,-9.7877169
195.6525,0.2780866,9.5172453,0.0,0,18.0,450.0,1.0074813,1.2972374,18.106836,463.27423,-9.8056679
195.6549,0.28663474,9.5178862,0.0,0,18.0,450.0,1.0068684,1.3137865,18.107798,463.29578,-9.8245993
195.6573,0.31697029,9.5235987,0.0,0,18.0,450.0,1.0068306,1.4850836,18.11128,463.31729,-9.84237
195.6597,0.32349974,9.5277748,0.0,0,18.0,450.0,1.0069889,1.5044478,18.10647,463.33884,-9.8609238
195.6621,0.3097389,9.5259314,0.0,0,18.0,450.0,1.00765,1.4808005,18.107561,463.35468,-9.8772755
195.6645,0.28034022,9.5225677,0.0,0,18.0,450.0,1.0082496,1.329448,18.10611,463.36902,-9.895505
195.6669,0.29588011,9.5193739,0.0,0,18.0,450.0,1.0080007,1.3478177,18.102476,463.38339,-9.9152365
195.6693,0.33343908,9.5175009,0.0,0,18.0,450.0,1.0067763,1.5602334,18.103094,463.39774,-9.9327278
195.6717,0.32405469,9.5190773,0.0,0,18.0,450.0,1.0061653,1.5103087,18.105827,463.43451,-9.9510841
195.6741,0.29602402,9.5251188,0.0,0,18.0,450.0,1.0069646,1.3894781,18.101339,463.48474,-9.9690771
195.6765,0.29677105,9.5246744,0.0,0,18.0,450.0,1.0075405,1.3630265,18.100756,463.53497,-9.9879665
195.6789,0.33068353,9.5201893,0.0,0,18.0,450.0,1.0077199,1.5401864,18.102322,463.58521,-10.005477
195.6813,0.35073766,9.5167665,0.0,0,18.0,450.0,1.0075151,1.6255902,18.103668,463.63873,-10.023759
195.6837,0.32254916,9.5197773,0.0,0,18.0,450.0,1.0071795,1.5225233,18.09832,463.69614,-10.038878
195.6861,0.29381952,9.526557,0.0,0,18.0,450.0,1.0072696,1.3850247,18.097555,463.75354,-10.057854
195.6885,0.32299849,9.5308657,0.0,0,18.0,450.0,1.0076785,1.4918265,18.095695,463.81097,-10.076037
195.6909,0.35434818,9.5292568,0.0,0,18.0,450.0,1.0082331,1.6491603,18.096945,463.87674,-10.093391
195.6933,0.34877041,9.5245829,0.0,0,18.0,450.0,1.008608,1.6392415,18.095842,463.96286,-10.109707
195.6957,0.33236685,9.5202274,0.0,0,18.0,450.0,1.0080345,1.5337822,18.09745,464.04898,-10.128371
195.6981,0.32033947,9.5177116,0.0,0,18.0,450.0,1.0068344,1.5062331,18.09477,464.13513,-10.147611
195.7005,0.35293382,9.520895,0.0,0,18.0,450.0,1.0064603,1.6437366,18.092489,464.22394,-10.166229
195.7029,0.37125126,9.5236988,0.0,0,18.0,450.0,1.0066462,1.7324334,18.098099,464.33157,-10.183629
195.7053,0.34583592,9.5244055,0.0,0,18.0,450.0,1.0075427,1.6413926,18.094723,464.43921,-10.202577
195.7077,0.32997763,9.5233507,0.0,0,18.0,450.0,1.0082581,1.539634,18.092463,464.54688,-10.221241
195.7101,0.34516141,9.5198898,0.0,0,18.0,450.0,1.0079186,1.6241528,18.088793,464.65451,-10.237523
195.7125,0.36975759,9.5188141,0.0,0,18.0,450.0,1.0069194,1.7060788,18.087473,464.77591,-10.254481
195.7149,0.36564595,9.5255623,0.0,0,18.0,450.0,1.0070269,1.7157011,18.088829,464.89792,-10.27246
195.7173,0.34515542,9.5311613,0.0,0,18.0,450.0,1.0075027,1.6207755,18.087509,465.01993,-10.291785
195.7197,0.32728213,9.5296364,0.0,0,18.0,450.0,1.0084387,1.5237278,18.085592,465.14194,-10.310181
195.7221,0.36025986,9.5264549,0.0,0,18.0,450.0,1.0089848,1.6604426,18.086319,465.23553,-10.328167
195.7245,0.36902261,9.5203066,0.0,0,18.0,450.0,1.0081942,1.7345135,18.09169,465.32166,-10.346137
195.7269,0.3537038,9.5213861,0.0,0,18.0,450.0,1.0074248,1.6359729,18.081282,465.40778,-10.364051
195.7293,0.32780549,9.5236921,0.0,0,18.0,450.0,1.0067387,1.5466092,18.084579,465.4939,-10.381986
195.7317,0.3485015,9.5266132,0.0,0,18.0,450.0,1.0072304,1.6060268,18.083441,465.54861,-10.399688
195.7341,0.37552345,9.5278893,0.0,0,18.0,450.0,1.0083202,1.7988313,18.083054,465.5845,-10.416798
195.7365,0.3758657,9.5215969,0.0,0,18.0,450.0,1.008039,1.7344255,18.083149,465.62036,-10.435952
195.7389,0.34931645,9.5211487,0.0,0,18.0,450.0,1.0081482,1.6484274,18.083126,465.65625,-10.454176
195.7413,0.33408725,9.5229912,0.0,0,18.0,450.0,1.0077454,1.6005458,18.07983,465.68884,-10.471852
195.7437,0.36855227,9.5283298,0.0,0,18.0,450.0,1.0076916,1.7015539,18.079885,465.71756,-10.489669
195.7461,0.38968271,9.5297356,0.0,0,18.0,450.0,1.0072988,1.8244829,18.078772,465.74625,-10.508
195.7485,0.37087402,9.5302277,0.0,0,18.0,450.0,1.0084047,1.7369725,18.080112,465.77496,-10.527184
195.7509,0.34874544,9.5270205,0.0,0,18.0,450.0,1.0090821,1.6348962,18.07761,465.80786,-10.544378
195.7533,0.36842206,9.5217981,0.0,0,18.0,450.0,1.0086238,1.6711496,18.076498,465.85092,-10.562366
195.7557,0.39209864,9.5223455,0.0,0,18.0,450.0,1.0074933,1.8139077,18.076834,465.89398,-10.579181
195.7581,0.38765311,9.5240803,0.0,0,18.0,450.0,1.0068485,1.8355107,18.07551,465.93704,-10.597488
195.7605,0.37726951,9.5274334,0.0,0,18.0,450.0,1.0074632,1.7344813,18.070551,465.97922,-10.615572
195.7629,0.35735393,9.5289249,0.0,0,18.0,450.0,1.0084479,1.6552961,18.071491,466.01508,-10.634513
195.7653,0.37999237,9.5250587,0.0,0,18.0,450.0,1.008817,1.7389705,18.071743,466.05096,-10.651828
195.7677,0.40340438,9.521513,0.0,0,18.0,450.0,1.0082967,1.8855764,18.071005,466.08685,-10.669641
195.7701,0.38272879,9.522666,0.0,0,18.0,450.0,1.0075915,1.7730675,18.072546,466.12271,-10.687804
195.7725,0.36735424,9.531352,0.0,0,18.0,450.0,1.0080007,1.701205,18.069807,466.1586,-10.706719
195.7749,0.38458192,9.5319052,0.0,0,18.0,450.0,1.0080142,1.7830685,18.068075,466.19449,-10.72431
195.7773,0.39813909,9.5294752,0.0,0,18.0,450.0,1.0083408,1.8357152,18.068033,466.23038,-10.742174
195.7797,0.41270366,9.5266666,0.0,0,18.0,450.0,1.0089862,1.9130993,18.069885,466.26627,-10.759215
195.7821,0.38801903,9.5232086,0.0,0,18.0,450.0,1.0086564,1.8282795,18.069984,466.31351,-10.777577
195.7845,0.3671293,9.5245504,0.0,0,18.0,450.0,1.0078564,1.7236245,18.06706,466.36374,-10.797103
195.7869,0.39461541,9.5259867,0.0,0,18.0,450.0,1.007234,1.8502606,18.064566,466.41397,-10.814562
195.7893,0.41964695,9.5282078,0.0,0,18.0,450.0,1.0075876,1.9565693,18.065016,466.4642,-10.831513
195.7917,0.39313695,9.5271473,0.0,0,18.0,450.0,1.0082014,1.8354968,18.066431,466.51443,-10.850194
195.7941,0.38123548,9.5245543,0.0,0,18.0,450.0,1.0086395,1.7851357,18.067474,466.56467,-10.868403
195.7965,0.38547283,9.5213423,0.0,0,18.0,450.0,1.0082833,1.7613417,18.065517,466.61493,-10.886339
195.7989,0.40872639,9.5233784,0.0,0,18.0,450.0,1.0076714,1.8867209,18.066902,466.66516,-10.903384
195.8013,0.42386463,9.5262022,0.0,0,18.0,450.0,1.007081,1.9739743,18.065914,466.71213,-10.921113
195.8037,0.39047289,9.5323801,0.0,0,18.0,450.0,1.0080515,1.8355153,18.06274,466.75516,-10.939877
195.8061,0.37295735,9.531374,0.0,0,18.0,450.0,1.008919,1.7424778,18.063295,466.79822,-10.95741
195.8085,0.40210587,9.5256739,0.0,0,18.0,450.0,1.0089726,1.869189,18.062397,466.84128,-10.974592
195.8109,0.43462405,9.5212412,0.0,0,18.0,450.0,1.0082785,1.9873741,18.061916,466.86548,-10.991839
195.8133,0.41119477,9.5208712,0.0,0,18.0,450.0,1.0071813,1.8942558,18.063076,466.84396,-11.009535
195.8157,0.39751831,9.5251045,0.0,0,18.0,450.0,1.0068568,1.8595381,18.062527,466.82245,-11.028523
195.8181,0.38914913,9.5270176,0.0,0,18.0,450.0,1.0075003,1.8150554,18.05958,466.8009,-11.045393
195.8205,0.42899787,9.5269156,0.0,0,18.0,450.0,1.008231,1.9697804,18.058445,466.77731,-11.064878
195.8229,0.43709177,9.5237274,0.0,0,18.0,450.0,1.0086881,2.0303555,18.05385,466.73914,-11.081096
195.8253,0.40238783,9.5241718,0.0,0,18.0,450.0,1.0087224,1.9084744,18.059765,466.70096,-11.101195
195.8277,0.38934138,9.5279398,0.0,0,18.0,450.0,1.0084395,1.8093395,18.051804,466.66278,-11.119261
195.8301,0.42526931,9.5320473,0.0,0,18.0,450.0,1.0080851,1.955289,18.053946,466.63406,-11.137681
195.8325,0.44062927,9.5329475,0.0,0,18.0,450.0,1.0080712,2.0105209,18.054367,466.64124,-11.153857
195.8349,0.4317714,9.5341101,0.0,0,18.0,450.0,1.0093572,2.0009151,18.05526,466.64841,-11.17258
195.8373,0.40288582,9.5297832,0.0,0,18.0,450.0,1.009744,1.8753067,18.05414,466.65561,-11.19186
195.8397,0.40466025,9.5222578,0.0,0,18.0,450.0,1.0084755,1.8947122,18.056465,466.66309,-11.209101
195.8421,0.43023673,9.5240536,0.0,0,18.0,450.0,1.0077502,2.0003169,18.052217,466.67743,-11.225381
195.8445,0.45163766,9.5276184,0.0,0,18.0,450.0,1.0074979,2.098187,18.049587,466.69177,-11.243613
195.8469,0.43554503,9.5329237,0.0,0,18.0,450.0,1.0084268,1.9871362,18.048601,466.70615,-11.261858
195.8493,0.40088066,9.5317183,0.0,0,18.0,450.0,1.0091341,1.8917389,18.046793,466.72049,-11.281205
195.8517,0.42254689,9.5261612,0.0,0,18.0,450.0,1.009167,1.9684287,18.051968,466.74741,-11.298559
195.8541,0.45691875,9.5241766,0.0,0,18.0,450.0,1.0085109,2.0719564,18.048815,466.77609,-11.315722
195.8565,0.44592351,9.5264778,0.0,0,18.0,450.0,1.0080541,2.0488558,18.050707,466.80478,-11.334949
195.8589,0.42141151,9.5311232,0.0,0,18.0,450.0,1.0080246,1.970309,18.050585,466.8335,-11.354054
196.0608,0.42151353,9.5298338,0.0,0,18.0,0.85476655,1.0086093,1.9559535,18.028131,459.29678,-11.480061
197.2608,0.47722417,9.5413113,0.0,0,18.0,3.6951402e-17,1.0109584,2.2098205,18.001593,439.63281,-11.480964
198.4608,0.49459955,9.5504971,0.0,0,18.0,1.5974026e-33,1.0124551,2.2858975,17.998764,426.73126,-11.481192
199.6608,0.50300425,9.5576544,0.0,0,18.0,1.4012985e-45,1.0138911,2.3283343,18.000599,415.16986,-11.481292
200.8608,0.51020581,9.5643978,0.0,0,18.0,1.4012985e-45,1.0152093,2.3515024,18.000261,404.54071,-11.481968
202.0608,0.51714969,9.5706415,0.0,0,18.0,1.4012985e-45,1.0161656,2.3825083,18.000965,394.45743,-11.482043
203.2608,0.52419096,9.5767584,0.0,0,18.0,1.4012985e-45,1.0172297,2.408633,17.999916,384.97446,-11.481533
204.4608,0.52950847,9.5818911,0.0,0,18.0,1.4012985e-45,1.0184307,2.434294,17.999796,374.73636,-11.48175
205.6608,0.53490692,9.586977,0.0,0,18.0,1.4012985e-45,1.0191847,2.4571698,18.000088,364.90381,-11.481513
206.8608,0.54248255,9.5926924,0.0,0,18.0,1.4012985e-45,1.020306,2.4867401,17.999458,354.94434,-11.481078
208.0608,0.54871243,9.5974684,0.0,0,18.0,1.4012985e-45,1.0213418,2.5168152,18.000317,346.19168,-11.481907
209.2608,0.55040652,9.6034756,0.0,0,18.0,1.4012985e-45,1.0222669,2.5255945,17.9998,337.53616,-11.481661
210.4608,0.55707252,9.6083241,0.0,0,18.0,1.4012985e-45,1.0230324,2.5500836,18.00016,329.28891,-11.481677
211.6608,0.56599963,9.6136618,0.0,0,18.0,1.4012985e-45,1.0242631,2.5914407,17.999817,321.0993,-11.481513
212.8608,0.56724453,9.6184216,0.0,0,18.0,1.4012985e-45,1.0250924,2.5896752,18.000067,313.60208,-11.481295
214.0608,0.57254887,9.6234808,0.0,0,18.0,1.4012985e-45,1.0259266,2.6148393,17.999542,305.63824,-11.481221
215.2608,0.57432872,9.6279049,0.0,0,18.0,1.4012985e-45,1.0270076,2.618299,17.999636,297.58936,-11.481556
216.4608,0.5791682,9.6323071,0.0,0,18.0,1.4012985e-45,1.0277029,2.6364734,18.001102,289.89175,-11.481396
217.6608,0.58644277,9.6371984,0.0,0,18.0,1.4012985e-45,1.0284201,2.6705837,17.999701,282.10513,-11.481629
218.8608,0.59112519,9.6420784,0.0,0,18.0,1.4012985e-45,1.0293627,2.6898472,17.999989,274.84302,-11.481957
220.0608,0.5981431,9.6463308,0.0,0,18.0,1.4012985e-45,1.0303771,2.7179272,18.000862,267.64505,-11.481947
221.2608,0.59944755,9.6508083,0.0,0,18.0,1.4012985e-45,1.03105,2.7238431,18.000212,261.21085,-11.481723
222.4608,0.60761833,9.6553755,0.0,0,18.0,1.4012985e-45,1.0319448,2.7567959,18.000122,255.57068,-11.48178
223.6608,0.60817534,9.6590118,0.0,0,18.0,1.4012985e-45,1.0328153,2.763761,18.000456,250.71141,-11.481982
224.8608,0.61678547,9.6637945,0.0,0,18.0,1.4012985e-45,1.033548,2.7984321,17.99979,245.23924,-11.482253
226.0608,0.62166244,9.6677094,0.0,0,18.0,1.4012985e-45,1.0341212,2.817559,17.999495,239.86995,-11.482287
227.2608,0.62226003,9.6712618,0.0,0,18.0,1.4012985e-45,1.0348327,2.8198879,18.000355,235.80209,-11.482188
228.4608,0.63579798,9.675312,0.0,0,18.0,1.4012985e-45,1.0358185,2.8757768,18.000139,230.80963,-11.481694
229.6608,0.63442856,9.6791964,0.0,0,18.0,1.4012985e-45,1.0363709,2.8707895,17.99976,225.43181,-11.481858
230.8608,0.6390031,9.6826239,0.0,0,18.0,1.4012985e-45,1.0370194,2.8914914,18.000284,220.28119,-11.481965
232.0608,0.6465196,9.6856785,0.0,0,18.0,1.4012985e-45,1.0377913,2.9238389,18.000076,215.19621,-11.481529
233.2608,0.64751375,9.6893578,0.0,0,18.0,1.4012985e-45,1.0384438,2.922632,17.999359,210.29724,-11.481846
234.4608,0.64839363,9.6926842,0.0,0,18.0,1.4012985e-45,1.0388851,2.92485,17.999645,205.35995,-11.481595
235.6608,0.65051275,9.6967211,0.0,0,18.0,1.4012985e-45,1.0396017,2.9347787,18.00104,200.68729,-11.482159
236.8608,0.65360725,9.6994057,0.0,0,18.0,1.4012985e-45,1.0402029,2.9429297,18.000116,196.08278,-11.481763
238.0608,0.65745556,9.703228,0.0,0,18.0,1.4012985e-45,1.0411086,2.9568114,18.000711,191.71478,-11.482043
239.2608,0.65998805,9.7062387,0.0,0,18.0,1.4012985e-45,1.041389,2.9679883,18.000509,187.29689,-11.481953
240.4608,0.66517019,9.7094707,0.0,0,18.0,1.4012985e-45,1.0421181,2.987263,17.999496,183.08638,-11.482242
241.6608,0.66409141,9.7120886,0.0,0,18.0,1.4012985e-45,1.0427952,2.9834723,18.000465,178.99692,-11.482351
242.8608,0.66351402,9.7149143,0.0,0,18.0,1.4012985e-45,1.0432904,2.9763372,18.00028,174.99533,-11.482184
244.0608,0.6712206,9.7181969,0.0,0,18.0,1.4012985e-45,1.04373,3.0088365,18.001045,171.01599,-11.482224
245.2608,0.66324407,9.7213707,0.0,0,18.0,1.4012985e-45,1.0442168,2.971024,17.999245,167.24089,-11.48235
246.4608,0.67031389,9.7243862,0.0,0,18.0,1.4012985e-45,1.0448453,2.9944584,17.999174,163.63158,-11.481848
247.6608,0.66981024,9.7265558,0.0,0,18.0,1.4012985e-45,1.0454715,2.9930041,18.000269,160.05943,-11.482255
248.8608,0.67241836,9.7288046,0.0,0,18.0,1.4012985e-45,1.0458596,3.0043759,17.999992,156.65033,-11.48231
250.0608,0.67324281,9.731967,0.0,0,18.0,1.4012985e-45,1.0462717,3.005748,18.000233,153.21129,-11.482047
251.2608,0.66837239,9.7344503,0.0,0,18.0,1.4012985e-45,1.0468727,2.9854774,17.999842,149.85164,-11.482018
252.4608,0.67124349,9.7365818,0.0,0,18.0,1.4012985e-45,1.0474479,2.9949455,17.999861,146.64919,-11.482059
253.6608,0.67324215,9.7390556,0.0,0,18.0,1.4012985e-45,1.0478741,3.0034585,18.000675,143.50415,-11.482585
254.8608,0.66840601,9.7416115,0.0,0,18.0,1.4012985e-45,1.0482174,2.9825373,18.00025,140.33334,-11.482147
255.8608,0.68018496,9.743576,0.0,0,18.0,1.4012985e-45,1.0487262,3.0301299,17.99934,137.81633,-11.504778