File: example/data/02 processed data/test_ID_090.csv
Strain,Stress_MPa,Displacement(mm),Force(kN),True Stress (MPa),True Strain
1.22618083438845e-05,0.359368759073397,3.893124149183328e-05,0.07244874182919683,0.3593731655842455,1.2261733168436794e-05
-5.23172092556768e-05,1.09218067835886,-0.00016610713938677382,0.22018362475714615,1.092123538513765,-5.2318577848618615e-05
-0.0001129776435485,2.81023354389584,-0.0003587040182664875,0.5665430824494014,2.80991605033223,-0.00011298402600314273
-0.0002062584497213,6.27871791005443,-0.0006548705778651275,1.2657895306669733,6.277422871432065,-0.0002062797239207437
-0.000271978799331,10.7728130645082,-0.000863532687875925,2.171799113804853,10.769883087745498,-0.00027201579227237717
-0.0002662722284761,15.7419702269524,-0.0008454143254116174,3.1735811977536037,15.737778577459466,-0.0002663076852201492
-0.0002407182506383,20.5401135954198,-0.0007642804457766025,4.140886900836632,20.535169215207198,-0.00024074722792674646
-0.0001723373448467,25.7184902223481,-0.0005471710698882724,5.184847628825377,25.714057966029713,-0.00017235219663325752
-8.57789604403812e-05,31.1101829298205,-0.0002723481993982103,6.271812878651813,31.10751433066967,-8.57826396658034e-05
1.41432007258907e-05,36.7299408004785,4.490466230470297e-05,7.404756065376467,36.73046027940389,1.4143100711781986e-05
0.000127480716755,42.5000472940636,0.0004047512756971249,8.568009534483222,42.50546523055477,0.00012747259177899633
0.0002409833500785,48.335056444439,0.0007651221364992374,9.744347379198901,48.34670438826721,0.00024095431825501702
0.0003505683675128,54.1923989637904,0.00111305456685314,10.925187631100146,54.21139710462675,0.00035050693278038407
0.000473351627848,60.0252495360403,0.0015028914184173998,12.101090306465723,60.05366258562016,0.00047323963230688976
0.0005855403567604,65.8198276480437,0.00185909063271427,13.26927725384561,65.85836781340664,0.0005853689948954033
0.0007155512767795,71.6243591817221,0.0022718753037749124,14.439470811035177,71.6756100833831,0.0007152953920232299
0.0008476916171633,77.4492258173954,0.002691420884493477,15.613763924786912,77.5148788768766,0.000847332529540505
0.0009745780112257,83.286289221428,0.003094285185641597,16.790515907039886,83.3674582075398,0.0009741034184026095
0.0011030115353215,89.0775560921556,0.003502061624645762,17.95803530817857,89.1758096640635,0.001102403665048801
0.0012173248162093,94.7123755457332,0.003865006291464527,19.094014910019812,94.82767127088715,0.001216584477116397
0.0013282499595122,100.166799037006,0.004217193621451235,20.193626685860412,100.29984558377137,0.0013273686158781649
0.001441505963634,105.508285448229,0.004576781434537949,21.270470346362966,105.6603762709154,0.0014404679912881269
0.0015555196384755,110.815520756556,0.004938774852159712,22.34040898452169,110.98789647534072,0.001554311070940744
0.001673696507017,116.073575554935,0.005313986409778974,23.400432831874895,116.26784749289827,0.0016722974378787355
0.0017846148295474,121.265923995961,0.0056661520838129946,24.447210277585736,121.48233696224298,0.0017830242965472811
0.0019049384408092,126.342069788171,0.0060481795495692095,25.470561269295278,126.58274365360188,0.0019031263464980145
0.0020116090072252,131.302489070648,0.0063868585979400105,26.470581796642637,131.5666183403336,0.0020095884311119743
0.0021277055678456,136.199513425407,0.00675546517790978,27.45782190656205,136.4893058884601,0.002125445208039551
0.0022340374243412,141.030030403301,0.00709306882228331,28.431654129305482,141.34509676917796,0.002231545673154766
0.0023341218401132,145.769383361774,0.00741083684235941,29.38710768573364,146.10962686309855,0.0023314020091865684
0.0024372262533544,150.457403335511,0.00773819335440022,30.332212512439018,150.82410206893184,0.0024342610344116485
0.0025398811713087,155.098654610682,0.008064122718905123,31.26788876951349,155.49258676322296,0.0025366611243317952
0.0026455688967816,159.808963511014,0.00839968124728158,32.21748704382043,160.23174913430566,0.0026420755393100365
0.0027564225354378,164.618048111144,0.008751641550015015,33.18699849920663,165.0718050086973,0.002752630569416272
0.002860123780334,169.254569568834,0.00908089300256045,34.12172122507694,169.73865858818803,0.0028560414085213293
0.0029593022801796,173.84247677055,0.009395784739570229,35.046643316942884,174.35692920844917,0.002954932164725897
0.003061785188407,178.231225833918,0.009721167973192224,35.93141512811786,178.77693156128788,0.003057107469817742
0.0031558855593665,182.671217640964,0.010019936650988636,36.82651747641834,183.247707098829,0.003150916204932228
0.0032603612560902,187.099827482923,0.010351646988086384,37.71932522055727,187.70984051146948,0.0032550578026529576
0.0033518909140286,191.560121888149,0.010642253652040804,38.618520572650844,192.20221052019613,0.0033462858492304196
0.0034496747826199,195.913622402617,0.010952717434818182,39.49618627636759,196.589460685391,0.0034437383032647614
0.0035443452682909,200.262897878629,0.011253296226823606,40.373000212331604,200.9726987331393,0.0035380788790666125
0.0036352658521587,204.567943643952,0.011541969080603872,41.24089743862072,205.3116025039272,0.003628674243254654
0.0037315677473088,208.76678523958,0.01184772759770544,42.08738390429933,209.54581264208937,0.00372462272024656
0.0038290089392735,213.003008807658,0.012157103382193363,42.94140657562385,213.81859923247467,0.0038216969437321335
0.0039257378757711,217.035846565193,0.012464217755573243,43.754426667542916,217.88787240845403,0.003918052274706682
0.0040251174108313,220.833117465384,0.012779747779389379,44.51995648102141,221.72199669138206,0.004017038298074349
0.0041146880276132,224.384650211645,0.01306413448767191,45.23594548266763,225.30792304545105,0.004106245848862274
0.0042026934906144,227.856849538212,0.01334355183270072,45.935940866903536,228.81446203655813,0.004193886840139091
0.0043016924787783,231.203178562901,0.013657873620121103,46.610560798280844,232.19774353719464,0.004292466648015679
0.0043926855646234,234.425940404086,0.013946776667679293,47.26026958546374,235.4556998484723,0.00438306588192814
0.0044917076195411,237.528791512158,0.014261171692042992,47.88580436885105,238.59570139485356,0.004481650006862264
0.0045887077125941,240.674713895622,0.014569146987486266,48.5200223213574,241.77909981150123,0.004578211689896984
0.0046950396202236,243.698378158695,0.014906750794209929,49.12959303679291,244.8425516995343,0.004684052298890067
0.0048034128141381,246.669097225782,0.015250835684888466,49.72849000071765,247.8539507282482,0.004791913236914893
0.0049220069268978,249.581086553506,0.015627371992900516,50.31554704918681,250.80952639034504,0.004909933451748674
0.0050485699716803,252.239160124137,0.01602920966008495,50.85141468102602,253.51260717362155,0.005035868673293044
0.0051856802299649,254.864358949393,0.016464534730138557,51.38065476419763,256.1860040169195,0.0051722808933946755
0.0053479414295801,257.180063476431,0.016979714038916818,51.84750079684848,258.5554473927586,0.005333691971746721
0.0055632355538903,259.200986357124,0.0176632728836017,52.2549188495962,260.6429825000294,0.005547817913854097
0.0058589474525648,260.719659863345,0.01860215816189324,52.561083428450345,262.2472026503349,0.005841850567270375
0.0062305608425503,261.651527586271,0.019782030675097203,52.74894796139224,263.2817633484435,0.006211231146691788
0.0066786921966135,262.242772403291,0.021204847724247862,52.868142916503466,263.99421116095914,0.006656488537992702
0.007176382773625,262.500310656037,0.022785015306259374,52.920062628257064,264.38411336350026,0.00715075507517242
0.0077032162405204,262.738526613645,0.02445771156365227,52.96808696531083,264.7624582988656,0.007673697963828537
0.0082371508145981,262.888339041924,0.026152953836348965,52.99828915085188,265.05378993801156,0.008203410643120475
0.0087735808920776,262.979856881366,0.02785611933234638,53.01673914728339,265.2871319287017,0.008735316677822647
0.009304384654548,263.051385916119,0.029541421278189896,53.03115940068959,265.4989171945945,0.009261365506235639
0.0098386259503989,263.093715281313,0.031237637392516508,53.0396930007127,265.68219593586656,0.009790541800843603
0.0103689582472566,263.185834401886,0.0329214424350397,53.058264215420216,265.91479733006855,0.010315569340774062
0.0108990193731231,263.314755488714,0.03460438650966584,53.084254706524746,266.18462811001467,0.010840053124108379
0.0114268644652712,263.433590378706,0.03628029467723606,53.10821182034714,266.4438103115633,0.01136207097331174
0.0119422442724854,263.545821695448,0.037916625565141145,53.13083765380232,266.69315027512795,0.011871498359678694
0.0124452785059175,263.542238295843,0.039513759256288056,53.130115240441945,266.8220948495076,0.012368472617942288
0.012936419518619,263.541921395485,0.04107313197161532,53.13005135332978,266.9512102513999,0.012853458754439332
0.0134200561438302,263.583519022708,0.04260867825666088,53.13843743497793,267.12082464658107,0.013330804808999194
0.0138981175850601,263.707924776223,0.044126523332565816,53.16351763488657,267.37296852287517,0.013802424366586073
0.0143751476648105,263.78478584007,0.04564109383577333,53.179012825358114,267.5767310882514,0.0142728048589179
0.0148423722717527,263.949236118871,0.04712453196281482,53.21216600156439,267.86686894219207,0.014733302179297365
0.0153024486245132,263.987803431764,0.048585274382829405,53.21994117184362,268.02746323127667,0.015186547047250684
0.0157575031919404,264.109231261862,0.05003007263441077,53.24442102239138,268.2709333164917,0.015634642707483985
0.016203633343548,264.149704077334,0.0514465358657649,53.25258034199054,268.4298890300098,0.01607375559281888
0.0166410506247429,264.27393057886,0.052835335733558704,53.27762440469818,268.67172643642266,0.01650410552697314
0.0170811217565387,264.428089576109,0.054232561577010376,53.308702858543576,268.9448179700075,0.016936879624281663
0.0175064833439584,264.566409106829,0.055583084617067915,53.336588075936724,269.1980365412286,0.017355010151127122
0.017919601015116,264.643853772634,0.05689473322299329,53.35220092056301,269.38616604334226,0.01776093761762145
0.018330919140022,264.633623650612,0.05820066826956984,53.350138527963374,269.4846012074824,0.018164933222709522
0.0187303772023416,264.684427174872,0.059468947617434584,53.36038051845419,269.642066335443,0.018557123745554228
0.0191226629120534,264.754500114461,0.060714454745769544,53.374507223075334,269.817311174599,0.018942122768383998
0.0195139636773279,264.919197381243,0.06195683467551608,53.407710192058595,270.0888209763674,0.01932600753232504
0.0198975482933503,265.050535767724,0.0631747158313872,53.43418801077316,270.32439160334064,0.019702179401802345
0.0202741551622148,265.267708825584,0.06437044264003199,53.47797009923774,270.6457875138391,0.020071370752220784
0.0206562769181379,265.428516406215,0.06558367921508783,53.510388907492946,270.91128134307235,0.02044582914078897
0.021028846054276,265.50366281108,0.0667665862223263,53.52553842271373,271.0868984631806,0.020810791530024648
0.0214067381707366,265.566249685467,0.0679663936920887,53.53815593659016,271.25115685946827,0.021180832204689068
0.0217843811707721,265.601284743766,0.0691654102172014,53.54521900434322,271.38724437007096,0.021550492194653766
0.022153002587481,265.745740288021,0.07033578321525216,53.57434124206504,271.6328063602336,0.021911189565947654
0.0225185703190972,265.88470426481,0.07149646076313361,53.6023563797857,271.87204767456944,0.02226877045116698
0.0228831778103754,266.068714443048,0.07265408954794189,53.63945283171848,272.15721214542623,0.022625284759882625
0.0232496605469003,266.28923659233,0.07381767223640845,53.68391009701372,272.4803709503949,0.022983504650178954
0.0236098774078125,266.529588622997,0.07496136076980468,53.7323650663962,272.8223195359406,0.023335474932410148
0.023965863775981,266.64184481044,0.07609161748873966,53.7549959137847,273.03214694014326,0.023683189905385458
0.0243196394462244,266.694110690909,0.07721485524176247,53.76553271528726,273.1800153053434,0.02402862580600065
0.0246680916479271,266.683526449218,0.07832119098216854,53.763398932162346,273.2621001206597,0.024368747125200395
0.0250295502986669,266.787526384047,0.07946882219826741,53.78436531902388,273.4650981947334,0.024721441734482683
0.0253817446632835,266.875704216101,0.0805870393059251,53.80214196996596,273.64947519734807,0.025064977071949716
0.0257327345502132,267.010483039028,0.08170143219692691,53.82931338066804,273.88139292119547,0.025407220173358818
0.026083755931263,267.108112005533,0.08281592508176003,53.84899538031544,274.07529480634577,0.025749376878018093
0.0264255564345133,267.165415677515,0.08390114167957972,53.86054780058703,274.22541044685136,0.026082433107629907
0.026771787591318,267.321663655931,0.08500042560243465,53.89204739303569,274.4783424538853,0.026419693586846888
0.0271144935073681,267.321921115787,0.08608851688589371,53.89209929694266,274.5702196102582,0.026753408186709998
0.0274602321040258,267.493897502091,0.08718623693028191,53.92676973642155,274.8393420139089,0.027089963090857597
0.0278071102410818,267.622684063188,0.08828757501543472,53.952733107138705,275.0644975419472,0.027427513474890596
0.0281482196400913,267.829831279424,0.08937059735728987,53.99449398593189,275.36876419644585,0.027759339168943183
0.0284927257701486,267.967724885591,0.0904644043202218,54.02229333693515,275.6028557860068,0.02809435742679548
0.0288297570788432,267.951844919405,0.09153447872532716,54.01909193575205,275.6768315172593,0.028421998148674743
0.0291753255129381,267.953445255172,0.09263165850357846,54.01941456344268,275.7710742428049,0.028757826704459977
0.029524477728003,268.066499039843,0.09374021678640951,54.04220620643235,275.98102242036856,0.029097023529429698
0.0298634336919543,268.247377544212,0.0948164019719549,54.07867131291314,276.2581653165442,0.029426204802304463
0.030202995079751,268.506831314055,0.09589450937820942,54.13097719291349,276.61654181911297,0.029755865425019845
0.0305376134317208,268.600712185501,0.09695692264571354,54.149903576597,276.8031369017067,0.03008062085860379
0.0308834733037767,268.677289042056,0.09805502773949101,54.16534147087849,276.9749769255174,0.030416175663516322
0.0312298102600809,268.700079009975,0.09915464757575686,54.16993592841096,277.0915314943253,0.030752080545485082
0.0315780899649118,268.792187012067,0.10026043563859496,54.18850490163271,277.2801308753995,0.03108975591322267
0.0319272005098604,268.906987202531,0.10136886161880676,54.21164862003025,277.49243450144866,0.03142812242954888
0.0322710662575453,268.990730858296,0.10246063536770632,54.22853134103248,277.6713485564896,0.031761293672255546
0.0326086312983811,269.105297686832,0.10353240437235997,54.25162801366533,277.880453119543,0.0320882522299308
0.0329445548501074,269.220296543256,0.104598961649091,54.274811783120406,278.0896393694875,0.03241351478617065
0.0332808989112264,269.234168417194,0.10566685404314383,54.27760835290631,278.1945235597347,0.032739078546386025
0.033618404265726,269.432827864081,0.10673843354368005,54.31765809739873,278.4907295936734,0.03306565987231765
0.0339572866222417,269.496398148376,0.10781438502561738,54.3304738667126,278.64776458396216,0.03339346635702716
0.0342989257071952,269.720133144322,0.10889908912034475,54.37557884189531,278.97124395277393,0.03372383073453916
0.0346445408600959,269.878803579474,0.10999641723080447,54.407566801621954,279.2286308173569,0.03405792894621136
0.0349830281206181,269.957501621362,0.11107111428296246,54.42343232686658,279.40143249195387,0.03438502863179085
0.0353254798170456,270.039844711284,0.11215839841911977,54.440032693794855,279.5791317954306,0.03471585053416717
0.0356681566402139,270.114927291338,0.11324639733267913,54.45516934193375,279.74942882882544,0.03504678040306023
0.0360081618937445,270.177598476928,0.11432591401263878,54.467803852948684,279.9061971829483,0.03537502208207297
0.0363527939393195,270.366662391053,0.1154201207573394,54.50591913803629,280.19524595701654,0.03570762055897639
0.0366991242416798,270.437861230584,0.11651971946733336,54.520272824085744,280.3626938995394,0.036041746590789646
0.0370457930204028,270.554476824506,0.11762039283977888,54.54378252782041,280.5773819736901,0.03637608740490487
0.0373985977990595,270.663045619064,0.1187405480120139,54.56566999680331,280.78546400123986,0.036716231284990956
0.0377451195270305,270.655354185271,0.11984075449832184,54.56411940375063,280.8712728796248,0.03705020500285797
0.0380935187043029,270.77459481307,0.1209469218861617,54.58815831431492,281.08935190523175,0.03738587577622862
0.0384456475574054,270.839090785799,0.12206493099476214,54.601160702417076,281.2516750149179,0.03772502551363663
0.0388008780725058,271.008455748508,0.12319278788020589,54.63530467889922,281.52382179662396,0.03806704608190363
0.0391596021343436,271.121405808005,0.12433173677654093,54.658075410893815,281.73841218955044,0.038412311613965876
0.0395147348739444,271.186207278735,0.12545928322477345,54.67113938739298,281.90205836082475,0.03875400317837621
0.0398626359486082,271.236978724996,0.12656386913683101,54.68137491095919,282.0491996637109,0.039088623611195944
0.0402137805183222,271.281295080981,0.12767875314567298,54.690309088325776,282.1905415400938,0.03942625021978567
0.0405615387495303,271.402927522666,0.1287828855297587,54.714830188569465,282.4114478841126,0.03976050854284996
0.040917216108726,271.537299188405,0.12991216114520504,54.74191951638244,282.6478495408767,0.04010226304005744
0.0412680851389663,271.689919025187,0.131026170316218,54.7726876754777,282.9020417349173,0.0404392830289617
0.0416205566236941,271.767933982315,0.13214526728022877,54.78841549083471,283.0790666671303,0.040777727899248974
0.0419769728264606,271.826086380765,0.13327688872401242,54.80013901436222,283.2365226222935,0.04111984407207521
0.0423345214649462,271.919036091277,0.13441210565120418,54.81887767600145,283.43059836141066,0.04146292968377207
0.0426932230238105,271.942821975424,0.13555098310059832,54.82367291024548,283.55293752374513,0.04180700334260095
0.0430517251711304,271.958547434155,0.13668922741833903,54.826843162725645,283.66683207623004,0.042150767474606395
0.043404614967564,272.05025922406,0.1378096525220157,54.845332259570505,283.8584959775063,0.04248903460534831
0.043757583788121,272.176375709605,0.13893032852728418,54.87075734305637,284.0861562748651,0.04282726306131822
0.0441161508815048,272.274439511218,0.14006877904877774,54.89052700546156,284.28613976587206,0.04317073890562334
0.0444678407807745,272.313449497354,0.14118539447895903,54.89839141866656,284.42264061206583,0.04350751243639597
0.0448349579778709,272.447580767345,0.1423509915797401,54.92543228269676,284.6627566022215,0.043858937994331014
0.0451972510120789,272.507620216427,0.1435012719633505,54.93753623563168,284.8242155300531,0.04420562455378053
0.0455669786899795,272.625848967852,0.1446751573406849,54.96137115191897,285.0485852181077,0.04455930162219621
0.0459387384415729,272.694060831473,0.14585549455199395,54.97512266362495,285.22128196658036,0.04491479647211545
0.0463007726005074,272.780778483702,0.14700495300661098,54.99260494231433,285.4107392780653,0.04526086981662229
0.046667725322273,272.880248828328,0.14817002789821676,55.012658163790924,285.61494932652187,0.04561152270594167
0.0470260897836462,272.878038789773,0.14930783506307665,55.01221262001824,285.7104259418861,0.045953850186958474
0.0473845891971905,272.962903961172,0.15044607070107982,55.02932143857228,285.8971390314443,0.04629618936679884
0.0477520126855807,273.030148375029,0.15161264027671872,55.04287791240585,286.0678874837793,0.046646928780951225
0.0481168945186167,273.174765665579,0.152771140096608,55.07203275818073,286.3190870502575,0.04699512024986266
0.0484868851659557,273.282385131133,0.15394586040190933,55.09372884243642,286.53299675686475,0.047348063094633575
0.0488597374721008,273.391093892382,0.15512966647392004,55.115644528704216,286.7489109671742,0.04770360977065592
0.0492345531871577,273.459539906476,0.15631970636922568,55.12944324514556,286.92319816853706,0.048060901357323826
0.0496023121918692,273.480507105929,0.1574873412091847,55.13367023255529,287.045772597788,0.048411342131965726
0.0499787583806622,273.49255107009,0.15868255785860247,55.136098295730136,287.1613691989329,0.04876993385114538
0.0503598224313109,273.531906281111,0.1598924362194121,55.144032306271974,287.3069245107257,0.04913279349512008
0.0507285755134567,273.58329872212,0.161063227255225,55.154393022379395,287.4617897505657,0.049483804986395506
0.0511061124106239,273.675621791903,0.16226190690373088,55.173005353247646,287.66211888324733,0.04984305008154637
0.0514828956952119,273.765809451005,0.1634581938322978,55.191187185322605,287.86006606388634,0.05020144945219712
0.0518583798458117,273.860579406639,0.16465035601045214,55.21029280837842,288.06254535830254,0.050558485335013614
0.0522387841371928,274.004388943506,0.16585813963558713,55.23928481101081,288.3180450701692,0.05092006967820582
0.0526156796486217,274.003707120416,0.16705478288437386,55.239147355475865,288.42059839679854,0.05127818993966953
0.052984964925532,274.049910810909,0.1682272636385641,55.248462019479256,288.5704357230702,0.05162895472657085
0.0533656615610207,274.070623357726,0.1694359754562407,55.25263766891756,288.6965834876524,0.051990429815140474
0.0537320933339869,274.115286184496,0.1705993963354084,55.26164169479439,288.8440743260338,0.052338236912185504
0.0541100960269018,274.17529464377,0.1717995548854132,55.273739400184034,289.0109461651485,0.0526969000975749
0.0544872789493835,274.276401612991,0.1729971106642926,55.29412256517899,289.2209764169112,0.05305465727870474
0.0548644777746847,274.343911640257,0.1741947169346239,55.30773258667581,289.3956470830639,0.05341230159110487
0.0552478814463439,274.438680176511,0.17541202359214186,55.32683792358462,289.600835843194,0.05377569804646711
0.0556287884768926,274.487248775744,0.176621403414134,55.336629353189984,289.7566418774941,0.054136597420751206
0.056007996558246,274.573533280351,0.17782538907243103,55.35402430931877,289.9518467873024,0.054495757753737585
0.0564006868537677,274.655623121246,0.17907218076071243,55.370573621243196,290.1463889135338,0.05486755162405134
0.0567969157324725,274.726391809625,0.1803302074506002,55.384840588820396,290.3300035347225,0.055242555724816386
0.0571940001031164,274.807089837522,0.18159095032739456,55.40110931124445,290.5244065620264,0.05561822846053093
0.0575935083671683,274.860484598633,0.18285938906575933,55.41187369508441,290.6906642181683,0.055996052016991676
0.0579898329824104,274.907143310979,0.184117719719153,55.421280091493365,290.84896263725426,0.05637072373247754
0.0583917359235757,274.917341701961,0.18539376155735285,55.42333608711534,290.9702425194333,0.05675052570382453
0.0587934575701965,274.944039618727,0.18666922778537387,55.42871838713537,291.10895034622905,0.057130012252924044
0.0591818437376605,274.987964935378,0.18790235386707207,55.4375737309722,291.2622597059208,0.057496764567342096
0.0595813348799082,275.04545035115,0.18917073824370853,55.449162790791846,291.433025435717,0.0578738630095024
0.0599746212320688,275.062347350793,0.19041942241181842,55.45256922591987,291.5591074483606,0.058244965603458626
0.060371193069094,275.052773234906,0.19167853799437343,55.45063908415705,291.65803731206023,0.05861902896517491
0.0607824964340597,275.10518974319,0.19298442617813955,55.4612062522271,291.82676995774676,0.05900683996836252
0.0611870078660812,275.059117140374,0.1942687499748078,55.451918015499395,291.88916150447943,0.05938810033624406
0.0615892764911877,275.082684487233,0.19554595285952095,55.45666919262617,292.0248280000553,0.05976710271429582
0.0619959571329586,275.157100100381,0.19683716389714354,55.47167138023681,292.2157278830334,0.06015011596971262
0.0624022922374606,275.163660634858,0.19812727785393738,55.47299398398737,292.33450379892383,0.060532657340736096
0.0628118528790994,275.256446880047,0.1994276328911406,55.49169969101747,292.54581432550015,0.06091808734330795
0.0632223826890254,275.199653601529,0.20073106503765564,55.480250166068245,292.59843141741214,0.061304280385885035
0.0636360901238014,275.138842246007,0.20204458614306944,55.46799059679502,292.6476024077323,0.06169331185674398
0.0640595250431957,275.130643998743,0.20338899201214636,55.466337830146585,292.755382378131,0.062091333944082075
0.0644717089444265,275.150308695776,0.20469767589855412,55.470302233068445,292.8897193139792,0.06247862814940202
0.0648954130688999,275.177682032648,0.20604293649375716,55.47582069778184,293.0354513754991,0.06287659064791644
0.0653180378129825,275.264761642681,0.20738477005621941,55.49337594716449,293.24451575223924,0.0632733816356483
0.0657568671546601,275.343401663448,0.2087780532160458,55.509229775351116,293.44912114854355,0.06368522013729559
0.0661921004717548,275.422362968882,0.2101599189978215,55.52514837452661,293.65314769068635,0.0640935163298875
0.0666408634931504,275.460161024846,0.21158474159075252,55.532768462608956,293.81706401350397,0.06451433036980536
0.0670799013770413,275.454619574041,0.2129786868721061,55.53165130612666,293.93208828891807,0.0649258536556217
0.067529678949731,275.363634333482,0.2144067306653959,55.51330868162998,293.9588521544532,0.06534726802899596
0.0679723279090358,275.286159639894,0.21581214111118865,55.49768978340263,293.998000751756,0.06576183000479616
0.0684214374230008,275.230130161576,0.21723806381802754,55.48639424057373,294.06177128935065,0.06618226703084297
0.0688663712122876,275.201979571931,0.2186507285990131,55.480719081701295,294.154141255488,0.0665986206860846
0.0693059951898104,275.18057737966,0.220046534727648,55.47640439973946,294.252241151864,0.06700983541378923
0.069753371885016,275.072591887412,0.22146695573492578,55.454634524502254,294.25983268470986,0.06742812834068487
0.0701986152107771,274.984195391903,0.22288060329421727,55.436813791007644,294.28770511326434,0.06784425294055521
0.0706576482563089,274.876075058505,0.22433803321378074,55.415016731794616,294.2981720840636,0.06827308420811799
0.0711035304541834,274.757580078607,0.22575370919203228,55.391128143847176,294.293814041244,0.06868945388439036
0.0715663245526008,274.659349342074,0.22722308045450754,55.371324827362116,294.315709478495,0.06912143280501847
0.0720175616506523,274.54329497121,0.22865575824082104,55.34792826619594,294.3152336425723,0.06954244465122694
0.0724764979981735,274.426910720543,0.23011288114420086,55.32446520126147,294.3164121660254,0.06997045829151913
0.0729519162645063,274.29169955431,0.23162233413980748,55.29720663014891,294.30180465224515,0.07041365021622181
0.0734188580576005,274.044111253642,0.23310487433288157,55.247292828734224,294.1641169592944,0.07084874913393621
0.0738896698277393,273.825629432316,0.23459970170307226,55.203246893554905,294.05851478144274,0.07128726253018955
0.0743630202572112,273.558389130186,0.23610258931664554,55.1493712486455,293.9010171626041,0.07172794666322196
0.0748440565156565,273.297069111521,0.23762987943720937,55.09668913288264,293.75173039766696,0.07217558735050297
0.0753310310219568,272.951278414618,0.23917602349471284,55.026977728386996,293.5129796363524,0.07262855001149654
0.0758251126009686,272.525883070174,0.24074473250807527,54.941218026947084,293.1901888406484,0.0730879137719234
0.0763119172083793,272.129086603056,0.24229033713660428,54.86122385917609,292.8957789299003,0.07354030561219224
0.076805877080101,271.678165687074,0.24385865972932066,54.77031820251412,292.54464548618273,0.0739991378058586
0.0773073145954734,271.124203533179,0.24545072384062802,54.65863943228889,292.08408763016564,0.07446470064291599
0.0778076575620339,270.55133234467,0.2470393127594576,54.54314860068547,291.6022977646961,0.07492903129999379
0.0783083680622539,269.904567212668,0.24862906859765613,54.412760750073865,291.0403534036409,0.07539348729704622
0.0788114761042562,269.161532675677,0.25022643663101346,54.26296498741648,290.3745503763311,0.07585995006914062
0.0792920545436513,268.331405091852,0.2517522731760929,54.095611266517366,289.6079535001697,0.0763053211465834
0.079778095247302,267.520847895109,0.25329545241018386,53.932202935653976,288.863151579124,0.07675555266120843
0.0802601658319085,266.579682930123,0.2548260265163095,53.7424640787128,287.9754124895122,0.0772019064145621
0.0807491418994306,265.626441954518,0.2563785255306921,53.550290698030835,287.07554920814425,0.07765445057910395
0.0812501649440896,264.595379025994,0.25796927369748446,53.3424284116404,286.0937972152999,0.07811793181338736
0.0817322061462692,263.318002763241,0.2594997545144047,53.084909357069385,284.8395640471101,0.07856365085077108
0.0822173492929212,262.124361419178,0.26104008400502476,52.84427126210629,283.6755316001625,0.07901203760134085
0.0827073681390486,260.750949775743,0.2625958938414793,52.56739147478979,282.31697457145196,0.07946472664918623
0.08319547723028,259.32512930445,0.26414564020613895,52.27994606777712,280.89980719473783,0.07991544778890704
0.0837029704741035,257.797492362926,0.2657569312552786,51.971974460365885,279.3759082544779,0.08038385299141186
0.084188106860948,255.929824207922,0.2672972392835099,51.59545256031707,277.4760715972422,0.08083141827733872
0.0846614418895252,254.099561665938,0.2688000779992425,51.2264716318531,275.6119969400727,0.08126790317447224
0.0851394693649455,252.359774885761,0.27031781523370196,50.87573061696942,273.84555220859176,0.08170852192495259
0.0856252957987816,250.452393646594,0.27186031416113154,50.49120255915335,271.8974539360965,0.08215613048184832
0.0861305358931489,248.619404553484,0.2734644514607477,50.12167195798237,270.0331271011111,0.08262141308508508
0.0866427588953224,246.387039963079,0.2750907594926486,49.671627256556725,267.7346928615322,0.08309290545190626
0.0871381719737804,244.073362611073,0.2766636960167528,49.20518990239232,265.3414692564956,0.08354871319223565
0.0876245589747463,241.708440339006,0.2782079747448195,48.728421572343606,262.8880358241852,0.08399601441011464
0.0880868368979936,239.249884183474,0.27967570715112966,48.232776651388356,260.32464970940754,0.08442095857419873
0.0885186302219019,236.673581061579,0.2810466509545385,47.71339394201433,257.62360226686224,0.0848177170461361
0.0889621813446532,234.184123683119,0.2824549257692739,47.21151933451679,255.01765416225535,0.08522511547328193
0.0893871602122616,231.284680275591,0.2838042336739306,46.62699154355914,251.95856104602694,0.0856152997884352
0.0898326281604242,228.56009308282,0.2852185944093468,46.077714765496516,249.09224693704093,0.08602413230431477
0.0902822376514818,225.42580594501,0.2866461045434547,45.445842478514024,245.77775213011424,0.08643659634873961
0.0907289178310448,222.171496069193,0.2880643141135672,44.789773607549314,242.32887548045514,0.0868462046945617
0.0911963294668467,218.752709182909,0.2895483460572383,44.10054617127445,238.7021533213189,0.0872746443430149
0.0916795513561993,214.753171953364,0.29108257555593275,43.294239465798185,234.4416464103691,0.08771738311849087
0.0919309552326792,212.827420924322,0.29188078286375646,42.90600805834332,232.39284902960244,0.08794764751484933
0.092050841701765,211.72722011019,0.2922614224031039,42.684207574214305,231.21688893250783,0.08805743457385722