File: example/data/02 processed data/test_ID_084.csv
Strain,Stress_MPa,Displacement(mm),Force(kN),True Stress (MPa),True Strain
-1.78397466724974e-05,0.460337825503639,-5.6641195685179244e-05,0.09280410562153361,0.4603296131934483,-1.7839905802638807e-05
-4.5866116968477e-05,1.40775072489991,-0.00014562492137491447,0.28380254613982187,1.4076861568404992,-4.58671688509473e-05
-9.55491896828837e-05,2.85050511683206,-0.00030336867724315575,0.5746618315533434,2.8502327533779597,-9.555375479753078e-05
-0.0001906175593028,5.37912443272757,-0.00060521075078639,1.0844314856378783,5.378099077157017,-0.00019063572913881747
-0.0002985417881935,8.33550239967763,-0.0009478701775143624,1.6804372837750103,8.333013903885739,-0.0002985863606645846
-0.0003929706028295,11.3752811414576,-0.0012476816639836624,2.2932566781178525,11.370810990370087,-0.0003930478360110878
-0.0004176908945288,14.5829726114943,-0.00132616859012894,2.9399272784772514,14.576881436619317,-0.00041777815166901784
-0.0004226380224668,17.8024697860929,-0.00134187572133209,3.5889779088763287,17.79494578546748,-0.00042272735908805407
-0.0003937930965634,21.2375286332404,-0.001250293081588795,4.281485772461265,21.229165441076564,-0.0003938706534264232
-0.0003622169718296,24.8910556093455,-0.0011500388855589798,5.018036810844053,24.88203964655704,-0.0003622825882423255
-0.0003311005594229,28.6657651168057,-0.0010512442761677074,5.77901824754803,28.65627386593924,-0.0003311553853153515
-0.000272286516688,32.5086617984057,-0.0008645096904844,6.553746218558589,32.49981012812242,-0.00027232359339204285
-0.0002170089025938,36.4914774012558,-0.0006890032657353149,7.35668184409317,36.483558425790925,-0.0002170324524327766
-0.0001612964808823,40.5045758066087,-0.0005121163268013025,8.165722482612313,40.498042561071465,-0.00016130949055859054
-9.54860539822545e-05,44.5408259534444,-0.000303168221393658,8.97943051221439,44.53657292573299,-9.54906130657152e-05
-3.46154933644673e-05,48.6301420362601,-0.00010990419143218367,9.803836634510036,48.62845867990113,-3.46160924944926e-05
4.15024756149499e-05,52.7604343829832,0.00013177036007746594,10.636503571609412,52.76262407162461,4.1501614410938774e-05
0.0001207201184842,57.0694127931744,0.00038328637618733496,11.50519361910396,57.07630221944862,0.00012071283239717207
0.0001934589293765,61.442129929212,0.0006142321007703874,12.38673339372914,61.45401645788672,0.0001934402186110707
0.0002793216567735,65.8605633557733,0.0008868462602558625,13.277489572523896,65.87895963744587,0.0002792826537423661
0.0003737863783707,70.2761256311973,0.0011867717513269723,14.167666927249376,70.3023938896829,0.0003737165376454045
0.0004659475520089,74.7207773210431,0.0014793834776282574,15.06370870792229,74.75559328432004,0.00046583903215658036
0.0005434450800976,79.2349385438059,0.00172543812930988,15.97376361043127,79.27799838132937,0.0005432974672972975
0.0006342833161737,83.8170631764712,0.002013849528851497,16.897519936376593,83.8702269412547,0.0006340822435312569
0.000710617323581,88.4336642645545,0.0022562100023696746,17.828226715734186,88.49650675836862,0.0007103649546420381
0.0008146112307014,92.9960114626015,0.002586390657476945,18.747995910860464,93.07176705794939,0.0008142796150525539
0.0009020718210463,97.5353018239297,0.0028640780318220024,19.663116847704227,97.62328567126232,0.0009016651987778588
0.0009928886277158,102.010549455921,0.003152421392997665,20.56532677031367,102.11183457038281,0.0009923960398318557
0.0010878721632464,106.429388654768,0.00345399411830732,21.45616475280123,106.54517022403685,0.0010872808591279066
0.0011774427101487,110.840493027967,0.003738380604722122,22.34544339443815,110.97100135847207,0.001176750068125125
0.0012695008625814,115.22074377185,0.004030665238695945,23.22850194440496,115.36701660545563,0.0012686957277022366
0.0013549342303798,119.508445480955,0.0043019161814558645,24.092902608960532,119.67037156455663,0.001354017135304345
0.0014314675859504,123.743021686364,0.00454490958539252,24.946593171970985,123.92015581089558,0.0014304440129168628
0.0015177533012706,127.921132385482,0.004818866731534155,25.78890028891317,128.11528510646235,0.0015166026778234835
0.0015963489655552,132.113762496584,0.00506840796563776,26.634134519311335,132.32466216468103,0.0015950761549319286
0.0016745368143988,136.321133734232,0.0053166543857161895,27.48234056082117,136.54940849125057,0.0016731363408392125
0.0017581842277682,140.418872698262,0.005582234923164035,28.30844473596962,140.6657549455211,0.0017566404311333025
0.001841183720642,144.445290327044,0.00584575831303835,29.12017052993207,144.71124064411757,0.0018394908195382249
0.0019257743653907,148.431007937394,0.0061143336101154725,29.923691200178634,148.71685256750894,0.001923922439151007
0.0020083880423735,152.378921562562,0.006376632034535862,30.7195905870125,152.68495756653803,0.0020063739274079504
0.0020827578082171,156.318271101319,0.006612756041089293,31.513763454025913,156.6438442010223,0.0020805918750614262
0.0021594061689655,160.190897792581,0.006856114586465462,32.29448499498433,160.53681500548646,0.0021570780024998946
0.0022417440837584,163.988809917977,0.007117537465932919,33.060144079464166,164.3564308624132,0.0022392351244199865
0.0023195042649334,167.731683238665,0.007364426041163544,33.814707340914865,168.12073759330153,0.002316818367414495
0.0024015886679665,171.442820266477,0.007625044020793637,34.56287256572177,171.8545554008332,0.0023987094627577663
0.0024808040182549,175.06403653199,0.007876552757959307,35.292909764849185,175.4983360972705,0.002477731903793339
0.0025571571885737,178.686367281004,0.008118974073721497,36.02317164385041,179.14329640959673,0.002553893225257481
0.0026309157729655,182.275747661634,0.008353157579165462,36.74679072858542,182.75529980118608,0.002627460972263165
0.002719677779803,185.923507771131,0.008634976950874526,37.48217916666001,186.42915980395918,0.0027159861480412387
0.00280069777053,189.568081730839,0.00889221542143275,38.21692527693714,190.0990046347062,0.0027967831239868886
0.0028819605303977,193.205425609522,0.009150224684012697,38.95021380287964,193.76223602038735,0.0028778156438384267
0.0029676528528222,196.759050362153,0.009422297807710485,39.666624553010045,197.34296291927885,0.002963258063753435
0.0030370637617528,200.323117848384,0.00964267744356514,40.38514055823421,200.93151193024264,0.0030324612001003688
0.0031185052745603,203.801281524096,0.009901254246728951,41.08633835525776,204.43683689549104,0.003113652822633915
0.0031996177893319,207.262118510309,0.010158786481128782,41.7840430916783,207.92527807174918,0.0031945099049512705
0.0032802666589545,210.749917410847,0.010414846642180536,42.487183350026754,211.4412333383072,0.0032748983207944366
0.0033656928552754,214.196034974834,0.010686074815499394,43.181920650926536,214.91695303937712,0.003360041587814297
0.003450359155485,217.655325838032,0.010954890318664874,43.87931368894725,218.40631488427735,0.003444420323149852
0.0035437830182909,221.014834407634,0.011251511083073608,44.556590616579015,221.79806302459815,0.0035375186146796456
0.0036293244027435,224.243420274468,0.011523104978710612,45.20747352733275,225.0572723918248,0.0036227542968318358
0.0037276962173399,227.322014095461,0.011835435490054181,45.82811804164494,228.1694015075227,0.0037207655760060176
0.0038326813751172,230.247775130948,0.012168763365997108,46.41795146639912,231.1302414903546,0.0038253553647316398
0.0039413041229,232.988828726981,0.012513640590207499,46.97054787135938,233.9071085582323,0.003933557531582313
0.0040623645971151,235.565594645316,0.012898007595840442,47.49002388049571,236.5225479773015,0.004054135472995212
0.0042013112046048,237.937982892398,0.01333916307462024,47.96829735110744,238.9376344059249,0.004192510338194063
0.004356763623085,240.11018901193,0.013832724503294874,48.40621410480509,241.15629234894925,0.004347300404499576
0.0045598325909336,242.067081183704,0.014477468476214178,48.80072356663472,243.1708665496776,0.004549468049411114
0.0048012268565132,243.879548181894,0.01524389526942941,49.166116913469835,245.0504692183792,0.0047897377267854275
0.0051061641485304,245.262730267216,0.01621207117158402,49.44496642187075,246.51508202747715,0.005093171900639975
0.005457987794711,246.312966214088,0.017329111248207425,49.656693988760146,247.65733937736354,0.005443146955583197
0.0058409107535525,247.080048355859,0.018544891642529187,49.81133774854118,248.52322086728898,0.005823918768011896
0.0062416317985036,247.624299339434,0.01981718096024893,49.92105874682989,249.1698790402732,0.006222233490966569
0.0066785267134265,248.066898423041,0.021204322315129136,50.01028672208507,249.72361983087612,0.006656324152670913
0.0071236221541573,248.367545513397,0.022617500339449426,50.07089717550084,250.13682206298992,0.007098369016143687
0.0075827195670846,248.704748940051,0.024075134625493603,50.13887738631428,250.59060730626558,0.0075541152570389545
0.0080411780378362,248.964748493212,0.025530740270129935,50.19129329623154,250.96671836099102,0.008009020042800302
0.0085123679174947,249.25723715822,0.027026768138045672,50.25025901109715,251.37900646700902,0.00847634201317782
0.0089806723855271,249.534935822237,0.02851363482404854,50.306243061762984,251.77592732960002,0.008940585970493043
0.0094593873894916,249.760153359372,0.030033554961635827,50.35164691724939,252.12273140445714,0.009414927539986013
0.009938120477754,250.000653677733,0.031553532516868946,50.40013178143097,252.48519029349956,0.009889062122568827
0.0104167813708742,250.21345941,0.03307328085252558,50.44303341705601,252.8198783127241,0.010362900557230076
0.0108830070778658,250.452759206137,0.03455354747222392,50.49127625595722,253.1784383572484,0.01082421334014738
0.0113376461493752,250.689046042159,0.03599702652426626,50.538911682099254,253.53126973970944,0.011273856734347484
0.0117762773133907,250.944314275855,0.03738968047001547,50.59037375801237,253.89950411098613,0.011707476577304738
0.0122224075988423,251.227924777361,0.0388061441263243,50.647549635115986,254.29853487420118,0.012148317073894214
0.012653863680505,251.468011569623,0.04017601718560337,50.695951132435994,254.65005350803264,0.012574472582072305
0.0131009467613315,251.645193901825,0.04159550596722751,50.73167109060792,254.94198418987773,0.01301587159618882
0.0135294575847283,251.81851764752,0.04295602783151235,50.76661315774003,255.22548560108126,0.01343875169200072
0.0139791331385105,252.028251805296,0.044383747714770834,50.80889556394767,255.55138829194826,0.013882326198380377
0.0144173209896493,252.25067669865,0.045774994142136524,50.853736422447845,255.8874556744707,0.0143143796631391
0.0148362579372898,252.507769048621,0.047105118950895114,50.90556624020199,256.25403944139595,0.014727277250649082
0.0152590129244946,252.745270897601,0.04844736603527035,50.95344661295636,256.60191425283233,0.015143765086844289
0.0156654536128975,252.955804651449,0.049737815220949555,50.995890217732125,256.9184720753294,0.015544016992344254
0.0160802720370114,253.131166982616,0.051054863717511195,51.03124326369539,257.20158500874265,0.015952353945773927
0.0164766738957799,253.185606964163,0.052313439619101176,51.042218363975266,257.3572636452166,0.0163424063520177
0.0168878910710886,253.344604825418,0.0536190541507063,51.07427233280427,257.6230609151576,0.01674687605508974
0.0172894680246607,253.391965385068,0.054894060978297715,51.083820221629715,257.77297766829906,0.01714170589329763
0.0176867966851198,253.577147618454,0.05615557947525536,51.12115295988033,258.0621150723742,0.01753220545085858
0.0180743144065718,253.723980446294,0.057385948240865466,51.15075445797287,258.3098674413672,0.017912915863314432
0.0184628855577022,253.973623670025,0.05861966164570448,51.20108253187705,258.6627096185196,0.018294515723952895
0.0188448642730254,254.200244853861,0.059832444066855645,51.24676936253838,258.99061396630185,0.018669499542505453
0.0192142190021411,254.394126372826,0.06100514533179799,51.28585587676173,259.28211082981187,0.01903195687869398
0.0195967494157037,254.543978500476,0.06221967939485925,51.31606606569596,259.5322130624261,0.019407205417157635
0.0199722353880881,254.680547822196,0.06341184735717972,51.343598440954715,259.7670876720681,0.019775406717946285
0.0203429096326461,254.814610358432,0.06458873808365137,51.37062544825989,259.9982809500315,0.020138756712716366
0.0207049550622024,254.965369412085,0.06573823232249261,51.40101847347634,260.2444159281801,0.020493520988082953
0.0210625078055435,255.128757250257,0.06687346228260062,51.43395746165181,260.5024086912592,0.020843759449120855
0.021432129685029,255.284024796588,0.06804701174996707,51.46525939899214,260.75530512254466,0.02120569125225599
0.02180996330548,255.478319063092,0.069246633494899,51.504429123119344,261.05029182720375,0.02157552860638432
0.0221883164493011,255.685359040978,0.07044790472653098,51.546168382661165,261.35858669883237,0.021945737477780936
0.0225609996138758,255.844936356751,0.07163117377405566,51.57833916952101,261.61705386710776,0.022310264479476292
0.0229378050552693,255.999277115876,0.07282753105048002,51.609454266560604,261.8713386286498,0.02267868849888474
0.0233047421313133,256.099859164435,0.07399255626691972,51.62973160755009,262.0682003421278,0.02303733325532538
0.0236694496173974,256.270891245288,0.07515050253523674,51.66421167505007,262.33668219402387,0.023393671397167554
0.024031024596895,256.414079653927,0.07629850309514162,51.69307845823169,262.5759727090807,0.023746823616262708
0.0243832315423784,256.593587399124,0.07741676014705141,51.7292672196634,262.85016825296634,0.024090706156523874
0.0247413801312003,256.744834974771,0.07855388191656094,51.75975873091383,263.0970565336041,0.024440268687204943
0.025099606012895,256.834013960928,0.07969124909094162,51.777737214523086,263.2804465220577,0.024789784466978076
0.0254636789533155,256.926014286329,0.08084718067677671,51.79628448012393,263.4682958288711,0.02514488001259271
0.0258270132315149,257.06595461001,0.0820007670100598,51.824496449378024,263.70520042109473,0.0254991294452871
0.0261922886480219,257.203985414249,0.08316051645746954,51.852323459512604,263.94074644164067,0.025855145024702625
0.026551912535167,257.387683014899,0.08430232229915523,51.889356895803644,264.22181826193986,0.02620552856554223
0.0269167381226973,257.519877787882,0.08546064353956392,51.91600736203702,264.4514728996875,0.026560854751069302
0.0272726400118876,257.646072174198,0.08659063203774313,51.94144815031832,264.67276075108174,0.02690736797574059
0.0276287174885139,257.798071138811,0.08772117802603163,51.9720911415843,264.92070121538904,0.027253932037212936
0.0279965613608862,257.947977797375,0.08888908232081368,52.002312323950804,265.1696341856957,0.027611822047696154
0.0283610981544176,258.123014071173,0.09004648664027588,52.037599636748475,265.44366620915963,0.02796636815076654
0.0287248833128005,258.203182507004,0.09120150451814159,52.053761593412,265.6200387955114,0.02832005794832741
0.0290784558779964,258.268632346836,0.09232409741263857,52.06695628112214,265.77868537720394,0.028663698724821073
0.0294374223182844,258.348561081802,0.09346381586055297,52.08306991409128,265.9536767796881,0.029012461100403248
0.0297978692408203,258.481108700943,0.09460823483960444,52.109791514110114,266.183294979236,0.02936253952776362
0.0301566977449576,258.629272086264,0.09574751534024037,52.13966125259083,266.42867687256785,0.029710924403350214
0.0305210179892793,258.793302108572,0.09690423211596176,52.172729705088116,266.6919371377327,0.030064517054287938
0.0308858345578785,258.947462750436,0.09806252472126424,52.2038084904879,266.9452712441283,0.030418466175934755
0.0312591657718293,259.125326194728,0.09924785132555802,52.23966576085717,267.22536772192836,0.03078054664842327
0.0316357023754735,259.287423547378,0.10044335504212835,52.27234458715141,267.4901633084262,0.031145603165495243
0.0320124627716121,259.444224283109,0.1016395692998684,52.30395561547478,267.7496728542818,0.03151074331553418
0.0323867978405443,259.566246466607,0.10282808314372816,52.32855528766798,267.9727660171499,0.03187340094691114
0.0327636936242576,259.700339732093,0.10402472725701788,52.35558848998996,268.20908209719096,0.03223840658640862
0.0331469073168096,259.814660949319,0.10524143073087049,52.37863564738271,268.4267134353544,0.03260939427268366
0.0335156776364669,259.932904436006,0.1064122764957824,52.402473534298814,268.6447318681938,0.032966269484202074
0.0338943961282717,259.987165380741,0.10761470770726264,52.413412540757385,268.7992733524223,0.03333263946647778
0.0342553888865748,260.004742051263,0.10876085971487498,52.41695599753462,268.9113056025826,0.03368173677517857
0.034644265904425,260.109432317794,0.10999554424654936,52.438061555267275,269.1207326552607,0.03405766319725452
0.0350285549289308,260.152933019821,0.11121566189935528,52.44683129679591,269.26571432402824,0.034429015640069414
0.0354178229490632,260.272768945844,0.11245158786327565,52.470990219482154,269.4910637948303,0.03480503892555813
0.0358024934024189,260.359031544992,0.11367291655268001,52.48838075947038,269.68053405414173,0.03517648222856321
0.036161330464029,260.486600580655,0.11481222422329207,52.514098677060055,269.9061426257036,0.03552285609963603
0.0365491697334997,260.621960879557,0.11604361390386153,52.541387313318694,270.14747716402144,0.035897090006358844
0.0369283782342913,260.773707400357,0.11724760089387487,52.57197941191197,270.4036575007958,0.036262860550043886
0.0373021784029106,260.937813070008,0.11843441642924114,52.60506311491362,270.6713619252108,0.036623283523729
0.0376970820888218,261.050911075573,0.1196882356320092,52.627863672835524,270.8917686997506,0.037003913722686674
0.0380735689185171,261.121707630218,0.12088358131629177,52.64213625825195,271.06354296179796,0.037366657876180445
0.0384585655500817,261.169551357283,0.12210594562150939,52.651781553628254,271.2137576678425,0.037737465175124225
0.0388461698128068,261.220336178691,0.12333658915566159,52.66201977362411,271.36774571644696,0.038110645152645097
0.039223932337065,261.303046562277,0.12453598517018136,52.67869418695505,271.5523795801047,0.038474215686698184
0.0396161830677493,261.454458509226,0.12578138124010402,52.70921883545997,271.8122862014068,0.03885159029327113
0.0399984360689905,261.585155398081,0.12699503451904484,52.735567328253126,272.04815251286806,0.039219209372333745
0.0403899024530986,261.761293857324,0.12823794028858804,52.77107684163652,272.3338069822182,0.03959554909841266
0.0407832538800262,261.871266393042,0.12948683106908318,52.79324730483727,272.5512287342334,0.039973558424944954
0.0411782621367445,261.960917503785,0.13074098228416378,52.81132096876307,272.748012834338,0.04035301621839523
0.0415752321613538,262.018476170593,0.13200136211229832,52.82292479599155,272.9119551479495,0.040734213542517515
0.0419659377490559,262.084136570936,0.13324185235325248,52.8361619327007,273.082743131287,0.04110925349653821
0.042361000929098,262.149563880221,0.13449617794988616,52.84935207825256,273.2544817993137,0.041488333359146985
0.0427562271305114,262.219058302736,0.13575102113937368,52.86336215383159,273.43055591747657,0.04186742591166913
0.0431578184365378,262.323294859986,0.13702607353600751,52.884376243773175,273.6445959912276,0.04225247659181744
0.043566611023926,262.39128346978,0.13832399000096504,52.898082747507644,273.82278245277655,0.04264427973251608
0.0439645311731639,262.481869884211,0.13958738647479538,52.916344968656944,274.0217622351258,0.04302551491125339
0.0443675734678032,262.585751402628,0.14086704576027514,52.9372874827698,274.2360440195824,0.043411509359883235
0.0447691953751381,262.646202654781,0.14214219531606345,52.949474455203855,274.404661815971,0.04379599535263602
0.0451634946745814,262.708788938399,0.14339409559179594,52.962091849981235,274.5736359285841,0.04417332741313621
0.045567031504825,262.762131771302,0.14467532502781938,52.97284576509448,274.7354221079999,0.04455935213531048
0.0459719236526962,262.820532155817,0.14596085759731042,52.984619282612705,274.9028975944452,0.0449465236502666
0.0463826086667677,262.89436531335,0.14726478251698744,52.99950404717137,275.08809178037745,0.045339081424775454
0.0467929074126309,262.984958337589,0.14856748103510312,53.017767600857944,275.2907891439944,0.045731116156661325
0.047213879561688,263.101818022887,0.1499040676083594,53.04132651341403,275.5238755714808,0.046133189499830085
0.0476190685477502,263.151053416377,0.1511905426391069,53.05125236874161,275.68206146742415,0.046520035612290594
0.04802626216981,263.187400781061,0.15248338238914674,53.058579997461905,275.8273078907631,0.04690864490720862
0.0484297117620613,263.209532578361,0.15376433484454463,53.06304176779758,275.9566943741579,0.047293532166706106
0.0488414434738236,263.279021948186,0.15507158302938992,53.07705082475431,276.1379494165119,0.04768616782187526
0.0492652453889048,263.410496379235,0.15641715410977275,53.10355607005378,276.38747912137126,0.04809015292243738
0.0497004807165413,263.457427666827,0.1577990262750186,53.11301741763233,276.55138847021175,0.04850486701563217
0.0501159508859997,263.448060504662,0.15911814406304903,53.11112899773986,276.6510105659255,0.04890058748779071
0.0505246849796716,263.477551750907,0.16041587481045733,53.117074432982854,276.78967205233675,0.04928973934161248
0.0509422890792434,263.516329491062,0.16174176782659777,53.1248920253981,276.9404545250968,0.04968717990120619
0.0513425464859709,263.643396133669,0.1630125850929576,53.15050866054768,277.1795194553811,0.05006796313741894
0.0517654397397305,263.759501125098,0.16435527117364435,53.17391542681976,277.4131276863706,0.05047012342802592
0.0521877583012817,263.85185806234,0.1656961326065694,53.19253458536775,277.62169505824147,0.0508715758630101
0.0526130774447818,263.936164364944,0.16704652088718222,53.209530735972706,277.8226582211554,0.05127571780562595
0.0530396163123469,263.9670490254,0.1684007817917014,53.21575708352064,277.9677600248097,0.051680854773050906
0.0534762264149083,263.99186537388,0.16978701886733383,53.22076005937421,278.1091541383076,0.05209538771883511
0.0539077985012972,264.017888234722,0.1711572602416186,53.22600626811997,278.2505113544174,0.052504968590019144
0.0543349882838833,264.057019424814,0.17251358780132947,53.2338951160425,278.40455448153836,0.0529102253195669
0.0547721551152023,264.101009427394,0.1739015924907673,53.24276350056263,278.5663908818327,0.05332477688841243
0.0552075267082032,264.152523425,0.17528389729854515,53.25314872248001,278.735730917025,0.05373745536387863
0.0556460719086958,264.177563537717,0.17667627831010915,53.258196809203746,278.87800723500084,0.05415296992830837
0.0560883313620374,264.223241361066,0.17808045207446874,53.26740545839091,279.0430820760771,0.05457182890898578
0.0565248705125424,264.266151263858,0.17946646387732212,53.276056094793766,279.20376124489553,0.054985098272569
0.0569600507686853,264.306863723346,0.1808481611905758,53.28426372662655,279.3617960995398,0.055396911253027106
0.0574084347738185,264.337300823549,0.18227178040687372,53.29039984602748,279.51249151616497,0.05582104168716901
0.0578478430321626,264.381124579931,0.18366690162711624,53.299234715314086,279.6750023752974,0.0562365074340623
0.0582937477210855,264.378050955763,0.18508264901444643,53.29861507268183,279.7896383611705,0.056657939248900134
0.0587432831556501,264.402301561898,0.18650992401918906,53.30350399487864,279.9341608295542,0.05708262283710814
0.0591824524660443,264.426116413279,0.18790428657969063,53.30830506891704,280.0755024786885,0.05749733928282875
0.0596281799032631,264.407460262637,0.18931947119286033,53.30454398894763,280.17359587094245,0.05791807291233259
0.0600829994018243,264.45126258481,0.19076352310079214,53.3133745370977,280.34028763650485,0.05834720638106307
0.0605405415158329,264.512297708612,0.19221621931276944,53.32567921805617,280.52601544948857,0.05877872297255605
0.0609949225759477,264.597050459243,0.19365887917863395,53.34276537258339,280.73612706582867,0.059207074112334834
0.0614509026003112,264.649460657803,0.19510661575598803,53.35333126861308,280.91240888791054,0.05963674824202991
0.0619069559734206,264.656192762902,0.1965545852156104,53.35468846100105,281.0402520363681,0.06006630690382651
0.0623632682166502,264.654267799391,0.19800337658786438,53.354300388357224,281.15897288684556,0.0604959247980584
0.0628289383717068,264.686710722027,0.1994818793301691,53.36084088156065,281.316695757791,0.06093416295935586
0.0633005593930487,264.709634552254,0.2009792760729296,53.365462325734406,281.46590249614115,0.06137780576622435
0.0637658979763257,264.757089651222,0.2024567260748341,53.37502927368635,281.63956321843074,0.061815346012405833
0.0642373691555113,264.733346983392,0.20395364706874836,53.37024275185182,281.7391207213382,0.06225845734985727
0.0647046667568019,264.715754106129,0.20543731695284603,53.366696027795605,281.8440987608416,0.06269745249478137
0.0651703234092393,264.651871172073,0.20691577682433476,53.35381722828992,281.89931920721733,0.06313471445804858
0.065627372528542,264.620390183023,0.20836690777812086,53.347470660897436,281.9867311082124,0.06356370790701214
0.0660966495475862,264.633552264628,0.2098568623135862,53.35012413654901,282.124943427196,0.06400398725064689
0.0665699360266661,264.668700838984,0.21135954688466485,53.35721008913918,282.287679322096,0.06444783205043965
0.0670519505660253,264.698666910939,0.2128899430471303,53.363251249245295,282.44722883954404,0.06489965957488363
0.0675264976361732,264.659822357703,0.2143966299948499,53.35542018731292,282.53137322653043,0.06534428795419249
0.0679917613418111,264.617530376604,0.21587384226025025,53.34689412392337,282.6093423488295,0.06578002640882144
0.0684555483313745,264.59086755608,0.21734636595211404,53.34151889930573,282.70358047810555,0.06621419297567178
0.068924930260394,264.577768998542,0.21883665357675092,53.338878230106076,282.81377327521716,0.06665340531176876
0.069409250790889,264.614514286364,0.22037437126107257,53.34628608013099,282.9812094713755,0.06710639394476034
0.0698835982013558,264.63380837879,0.22188042428930466,53.35017576916406,283.1273711140279,0.06754985582840461
0.0703713954510256,264.641210362483,0.22342918055700625,53.35166800907657,283.26438162953934,0.06800568680140827
0.0708620927349096,264.636122717179,0.22498714443333798,53.350642339783285,283.38879218617063,0.06846401822129422
0.0713520530539433,264.622201969465,0.22654276844627,53.347835917044144,283.50353936364155,0.0689214517869725
0.0718684604541368,264.594580838038,0.22818236194188435,53.342267496948466,283.61058600737545,0.06940335031951489
0.0723646610178962,264.579174202361,0.2297577987318204,53.339161519195976,283.7253564559098,0.069866173664279
0.0728664276853784,264.52065768543,0.23135090790107643,53.3273645893827,283.79533305995415,0.07033397098390076
0.0733692864685244,264.475308302793,0.23294748453756497,53.318222153843074,283.879672961512,0.0708025670370104
0.0738709901417818,264.432628011377,0.23454039370015722,53.3096178070936,283.9665280683709,0.07126986796076083
0.0743779215881811,264.38124891105,0.236149901042475,53.299259780467686,284.04537671194146,0.07174181648873687
0.0748809468943727,264.293107982492,0.23774700638963334,53.28149056927039,284.0836261658777,0.07220990837171391
0.0753828694676113,264.199282603366,0.23934061055966588,53.26257537283858,284.1153826372921,0.07267675581483722
0.0758889462741864,264.125676514975,0.2409474044205418,53.24773638541896,284.169895789653,0.07314724663074185
0.0763937762492281,264.047034642847,0.24255023959129918,53.23188218399796,284.21858472662484,0.07361635784834986
0.076890303694876,264.03915972423,0.24412671423123128,53.23029460040477,284.3412109027659,0.07407753940732116
0.0773898389982648,263.961347573644,0.24571273881949074,53.214607670846625,284.3892737641333,0.07454130018052993
0.0778997128454262,263.900399457792,0.24733158828422816,53.20232053069087,284.4581647953473,0.07501443740354193
0.0784034591468025,263.796965022959,0.2489309827910979,53.18146814862854,284.47955959318705,0.07548166883656457
0.0789017193081523,263.666044989536,0.25051295880338353,53.15507466989045,284.46974926239096,0.07594359714896619
0.0793969192966957,263.60308158143,0.25208521876700885,53.142381246816285,284.5323541761111,0.07640247710966808
0.0799017506459032,263.528054988149,0.25368805830074265,53.12725588561084,284.5844079260119,0.07687006537379545
0.0804125512712691,263.485968514871,0.2553098502862794,53.11877125259799,284.67354746733304,0.07734296011363184
0.0809447008194444,263.414286134763,0.25699942510173596,53.104320084768226,284.73627671750893,0.07783538176989764
0.0814612571600778,263.31416078261,0.258639491483247,53.08413481377417,284.7640633480122,0.07831314252388809
0.0819818638523086,263.193676364533,0.2602924177310798,53.05984515508986,284.77078450703874,0.0787944185946324
0.0825063695724578,263.060415013266,0.2619577233925535,53.03297966667442,284.7645748342346,0.07927906500879708
0.0830295076709569,262.928034911441,0.26361868685528816,53.00629183814651,284.7588202030301,0.07976221388125218
0.0835626683984542,262.769334586869,0.2653114721650921,52.97429785271279,284.727041358234,0.08025437917580874
0.0840985139221794,262.617624642457,0.2670127817029196,52.94371312791933,284.7033766046603,0.08074877889012785
0.0846234443539143,262.454511953423,0.2686794358236779,52.91082960981007,284.66431674114716,0.08123287085957814
0.0851596887612946,262.30557005668,0.2703820118171103,52.880802923426685,284.6434307630608,0.08172715474455637
0.0856884038035419,262.171677707106,0.2720606820762455,52.853810225752575,284.63675029232456,0.08221425935082724
0.0862264025577607,261.9922364731,0.2737688281208902,52.81763487297696,284.5828845222376,0.0827096735941915
0.0867548606511885,261.762143567179,0.27544668256752347,52.77124814314328,284.47128185610603,0.08319606352565888
0.0872799807825568,261.534598599152,0.27711393898461784,52.72537507758904,284.3613333388597,0.08367914699016697
0.0877962172859527,261.2614867445,0.2787529898828998,52.670315727691204,284.1992570031712,0.08415383060221492
0.0882969719600433,261.051667803228,0.28034288597313745,52.628016229130765,284.1017395953721,0.08461406335824216
0.0888060578096158,260.827259188985,0.28195923354553015,52.582775452499384,283.99029984684563,0.08508173608837027
0.0893170157531072,260.641032764863,0.28358152501611533,52.54523220539638,283.9207119942284,0.08555090879864184
0.0898220810832859,260.458454859293,0.2851851074394327,52.50842449963346,283.8533753104918,0.08601445455389524
0.0903395155468023,260.221732602184,0.28682796186109727,52.46070129260029,283.7300378602148,0.08648912989358724
0.0908621844532221,260.037719367324,0.28848743563898016,52.42360422445251,283.66531458927295,0.08696837848066065
0.0913928355892367,259.742908292336,0.29017225299582655,52.36417031173494,283.4815492053676,0.08745471132590564
0.0919197910101536,259.465610363803,0.29184533645723765,52.308267049342696,283.3156350427658,0.08793742316911979
0.0924415573723255,259.110355297916,0.2935019446571334,52.23664762805986,283.0629200729519,0.08841515216069111
0.0929632567238185,258.799438043966,0.2951583400981237,52.173966709663546,282.8582766428272,0.0888925917252406
0.0934817324139821,258.478145393832,0.29680450041439316,52.109194111396526,282.64113021640054,0.08936685538378905
0.0940080555668859,258.113025046853,0.2984755764248627,52.03558584944557,282.37772864799456,0.08984806737933955
0.094531710351112,257.746835118577,0.3001381803647806,51.961761959905125,282.11208427992216,0.09032661001527816
0.0950509503722128,257.353825402733,0.3017867674317756,51.88253120119097,281.81555108918724,0.09080089220626197
0.0955878537738594,256.97000886493,0.30349143573200354,51.805153787169886,281.5332204965783,0.09129107197609072
0.0961256359215282,256.555343734614,0.30519889405085204,51.72155729689818,281.21688930017,0.09178181327141952
0.0966600925453594,256.065976797268,0.30689579383151605,51.62290092232923,280.81733781220976,0.09226928145171295
0.0971976932312552,255.569498930215,0.30860267600923524,51.52281098433134,280.41026468649966,0.09275937766500632
0.0977205568045754,255.025601269465,0.3102627678545269,51.41316121592415,279.94684502493874,0.09323580869673317
0.0982396197103236,254.440426662111,0.31191079258027743,51.29519001508158,279.4365574163293,0.09370855216536844
0.0987568287185645,253.923722274847,0.3135529311814423,51.19102241060916,279.0004238231244,0.09417938498639135
0.0992562224237402,253.242409030427,0.31513850619537515,51.05366966053409,278.3782939082748,0.0946337896711216
0.0997617137587807,252.723650915512,0.3167434411841287,50.94908802456722,277.9357954382193,0.09509353248233458
0.100261640699114,252.15064809438,0.3183307092196869,50.83357065582701,277.4316857756674,0.0955480067022787
0.100775961238771,251.492740751263,0.3199636769330979,50.70093653545462,276.8371634450446,0.09601535042104607
0.101301788172816,250.864170404357,0.3216331774486908,50.57421675351837,276.2771594548084,0.09649292388018435
0.101830263925657,250.074920222566,0.32331108796396096,50.415103916869306,275.5401153500175,0.09697267339177061
0.102361745932702,249.231165613601,0.3249985433363288,50.245002987701966,274.7429028666516,0.09745491996100607
0.10285863939204,248.446127643031,0.326576180069727,50.08673933283505,274.0009582946143,0.09790557194214522
0.103361818506942,247.562098680899,0.3281737737595408,49.90851909406924,273.15056739395175,0.09836171776549216
0.103887178824105,246.755079111378,0.32984179276653336,49.745823948853804,272.3897681407779,0.09883774953872569
0.104421924611126,245.788591589802,0.331539610640325,49.55098006450408,271.45430937106715,0.0993220529332471
0.104987519603466,244.836422087631,0.33333537474100455,49.35902269286641,270.54119075119866,0.09983404042943168
0.105545873495084,243.851002646606,0.3351081483468917,49.160362133555765,269.5884697235941,0.10033921615329609
0.106081574607715,242.72596372769,0.3368089993794951,48.933554287502304,268.4747161580985,0.10082365680677705
0.106626492614729,241.614708895534,0.3385391140517645,48.709525313339654,267.3772378691935,0.1013161917471986
0.107194831178662,240.436471637926,0.34034358899225187,48.47199268220589,266.2100186243466,0.10182963749849791
0.107762147494868,239.184100698977,0.34214481829620585,48.21951470091377,264.9590930369275,0.10234189695461757
0.108341825522859,237.927317856345,0.34398529603507727,47.966147279839156,263.70479781465895,0.10286504753624164
0.108910516621751,236.480544224622,0.3457908902740594,47.6744777156838,262.23576246711843,0.10337801676446425
0.109502870688111,235.026375520903,0.3476716144347524,47.38131730501404,260.76243832786383,0.10391205075815209
0.110103406357092,233.478553388395,0.3495783151837671,47.069276363100435,259.18533742778345,0.10445316986548686
0.110706121946779,231.915030722098,0.3514919371810233,46.75407019357496,257.5894443945096,0.10499595896721144
0.111284101469364,230.077498713189,0.3533270221652307,46.3836237405789,255.68146642580496,0.10551619486161776
0.111880627154935,228.116678122926,0.35522099121691864,45.98832230958188,253.63851513581943,0.10605284038518747
0.112516439342896,226.055145321736,0.3572396949136948,45.57271729686198,251.49006536847864,0.10662451188651488
0.113174648741378,223.671002723213,0.3593295097538751,45.09207414899975,248.98488989004446,0.10721597709136252
0.113915877491952,220.967451301548,0.3616829110369476,44.54703818239208,246.13915241372402,0.1078816247327241
0.1147147743161,217.522197652147,0.3642194084536175,43.852475046672836,242.47520746455513,0.1085985643994377
0.115126155109476,215.746639518633,0.3655255424725863,43.494522526956416,240.58472060420334,0.10896754210777078
0.115345889944265,214.753025393652,0.36622320057304136,43.29420991936025,239.5239042259061,0.10916457200194689