File: example/data/02 processed data/test_ID_061.csv
Strain,Stress_MPa,Displacement(mm),Force(kN),True Stress (MPa),True Strain
0.001057175141954723,44.7571054503344,0.0033565310757062454,18.04606491757483,44.80442154964234,0.0010566167258421885
0.0011410907024869228,49.1303117304952,0.0036229629803959796,19.809341689735668,49.18637387242115,0.001140440153334624
0.0012483194209700229,53.3548484060116,0.003963414161579823,21.512674877303876,53.42145229947973,0.0012475409180944695
0.0013549841580433228,57.6679518008491,0.004302074701787549,23.25171816610236,57.74609096196606,0.001354066995409496
0.0014624446444850229,61.8739865839942,0.0046432617462399475,24.947591390666464,61.96447386430691,0.0014613763137721726
0.0015502593271338287,66.1491368529208,0.004922073363649906,26.67133197909767,66.2516851693089,0.0015490589156158718
0.0016403675199549747,70.3947382908459,0.005208166875857044,28.383158478869063,70.51021153311393,0.0016390235866503712
0.0017356357609346013,74.5263016092988,0.0055106435409673585,30.049004808869277,74.6556521235021,0.0017341312857496916
0.001840174148683823,78.6898548771706,0.005842552922071138,31.727749486475187,78.83465791387925,0.0018384831024635614
0.001935735120880423,82.7864404783071,0.006145959008795342,33.37949280085342,82.94669309867363,0.0019338639999252273
0.002028425868180223,86.7711213910408,0.006440252131472208,34.986116144867644,86.94713017828138,0.002026371390197254
0.002128352788523823,90.8272588943704,0.006757520103563138,36.62155078621014,91.02057134411221,0.002126091054337946
0.002234468800820623,94.8255491944317,0.007094438442605477,38.23366143519486,95.03743392562734,0.0022319760879785325
0.002337757657587423,98.7500597294355,0.007422380562840068,39.8160240829084,98.9809134377552,0.0023350293534032352
0.002452756859100823,102.578284395668,0.007787503027645112,41.359564268333344,102.82988398631429,0.00244975376057386
0.002552226064746923,106.219021601467,0.008103317755571481,42.8275095097115,106.4901165569702,0.0025489746668308968
0.002647798376212823,109.921161338853,0.008406759844475711,44.32021225182553,110.21221041135743,0.0026442991335905116
0.002728285707146323,113.487350911073,0.008662307120189575,45.758099887344635,113.79697682850556,0.002724570691245468
0.002822232112615723,117.044699087272,0.00896058695755492,47.19242267198807,117.37502639564754,0.0028182570927630835
0.002909405204783223,120.553190048754,0.009237361525186732,48.60704622765761,120.90392812733508,0.002905181076610831
0.0030106102847342227,124.068485555651,0.009558687654031157,50.02441337603848,124.44200741427625,0.0030060874729330228
0.003117166082677823,127.546177430263,0.009897002312502089,51.426618739882045,127.94376004852383,0.0031123177931539608
0.003212137525669923,131.044325371606,0.010198536644002004,52.83707198983154,131.46525776665823,0.003206989632808813
0.0033162272481139232,134.379779956614,0.010529021512761706,54.18192727850676,134.82541384450167,0.0033107406929630302
0.003411776656658623,137.622097579844,0.010832390884891126,55.489229744193096,138.0916334398073,0.0034059697508432205
0.0035071390795053227,140.882824369461,0.0111351665774294,56.80395478576668,141.37692002843824,0.0035010034088259518
0.003601079411538823,144.160284251033,0.011433427131635763,58.12542661001651,144.67941688261098,0.003594611049148097
0.0037019106070499226,147.41069386269,0.011753566177383504,59.43599176543661,147.9563950738929,0.00369507539966944
0.003784810722762923,150.655915391576,0.012016774044772279,60.74446508588345,151.2261195155977,0.003777666347723333
0.0038813996569998233,153.780742015025,0.012323443910974438,62.004395180458076,154.3776265343353,0.0038738864602220714
0.003969079566515423,156.81765365392,0.012601827623686467,63.22887795326054,157.44007539870665,0.003961223550786095
0.004074501613984323,159.939928471405,0.012936542624400225,64.4877791596705,160.59160396810228,0.004066223311302899
0.004175274919723123,163.119657054343,0.013256497870120914,65.7698457243111,163.80072646735582,0.004166582646083741
0.004275334258601823,166.329889115211,0.013574186271060787,67.06421129125307,167.04100498837468,0.004266220982724147
0.004374133094081523,169.441858833146,0.013887872573708833,68.31895748152446,170.18302007539074,0.004364594379541447
0.004471737202955723,172.484420249689,0.014197765619384422,69.5457182446746,173.25572524864978,0.004461768692806849
0.004584526662778323,175.355897747547,0.014555872154321175,70.70349797181096,176.15982153624608,0.0045740497294008255
0.004685320291484923,178.119786934379,0.014875891925464629,71.81789809194161,178.9543351864176,0.004674378342746468
0.004816567839695723,180.926299596813,0.01529260289103392,72.94948399743501,181.79774339280615,0.004805005289824768
0.004942620051668223,183.696952927246,0.015692818664046607,74.06661142026559,184.60489717021457,0.004930445405135434
0.005072090526589523,186.382682021613,0.016103887421921734,75.14949739111435,187.32803185741517,0.005059270805684965
0.005219050314893723,188.959731472247,0.016570484749787572,76.18856372960998,189.94592181828946,0.005205478273429586
0.0053646002381919225,191.255692184123,0.017032605756259353,77.1142950886384,192.28170251596953,0.005350262026657172
0.005502788096919023,193.413772057875,0.017471352207717897,77.9844328937352,194.47808706053527,0.005487703072989853
0.005663793405620823,195.457410761547,0.01798254406284611,78.80842801905575,196.56444115569795,0.005647814433755849
0.0058384993457580225,197.358483733377,0.018537235422781722,79.57494064129762,198.51076111153412,0.005821521360371068
0.0060197953853431225,198.97049857232,0.019112850348464414,80.22490502435943,200.16826026144508,0.006001748805366167
0.006237252666279123,200.581654408486,0.01980327721543621,80.87452305750156,201.832732867252,0.006217881512659189
0.006449363861146723,201.939850702396,0.020476730259140843,81.42214780320607,203.2422342776414,0.006428655702650941
0.006691441484571923,203.185203125708,0.021245326713515852,81.92427390028546,204.54480502295456,0.006669153162092722
0.0069364135127751225,204.309751709823,0.022023112903061012,82.37769188940064,205.72692863237475,0.006912467266835337
0.007194792516533823,205.144875189622,0.022843466239994885,82.71441367645559,206.62085000244159,0.007169033477023209
0.007456071368118723,205.918775207282,0.023673026593776944,83.0264501635761,207.45412029126308,0.007428412268389397
0.0077213228024345226,206.641255374266,0.024515199897729607,83.31775416690405,208.236799211311,0.007691665951777238
0.007999756335998124,207.350801889456,0.02539922636679404,83.60384332182866,209.00955778064545,0.007967927918987084
0.008296518517212224,208.015433948071,0.02634144629214881,83.87182296786223,209.7412378476871,0.008262291586725813
0.008610120193501223,208.502793728751,0.02733713161436638,84.0683264314324,210.2980278434363,0.00857326451209305
0.008920165023636724,208.773302170597,0.028321523950046595,84.1773954351847,210.63559447848831,0.008880615370564011
0.009235124472739524,208.929727440815,0.029321520200947988,84.2404661041366,210.85921947978647,0.009192741452535009
0.009544682502413523,209.109726396369,0.030304366945162933,84.31304168301598,211.1056123429889,0.00949941980450837
0.009856257935769323,209.300788410705,0.0312936189460676,84.39007788719626,211.36371096744077,0.009808001849399983
0.010171807228636023,209.49364055774,0.03229548795091937,84.46783587288077,211.6245694851185,0.010120422553721014
0.010504994650983323,209.632626024185,0.033353358016872045,84.52387481295138,211.83481563924065,0.010450200601409805
0.010828547342383423,209.750117507726,0.03438063781206736,84.57124737911512,212.0214065852289,0.010770338458365702
0.011160144779222524,209.794960757862,0.03543345967403151,84.58932817756995,212.136302893871,0.01109832984734203
0.011486222058002024,209.895556637097,0.036468755034156426,84.62988843607751,212.30646360961865,0.011420756235810925
0.011822327708750224,210.012514751167,0.03753589047528196,84.67704594767054,212.495351523494,0.011752989946658812
0.012163468711197323,210.195180210763,0.0386190131580515,84.75069666097964,212.75188270850109,0.01209008816768495
0.012497791707479524,210.294440848317,0.03968048867124749,84.79071855004142,212.92265696728015,0.012420338966528882
0.012842525631812724,210.328424609253,0.0407750188810054,84.8044208024508,213.02957279339614,0.012760759709365077
0.013186860276119323,210.275209086039,0.04186828137667885,84.78296430349094,213.0480788877884,0.013100670522127206
0.013542046862295924,210.301717793761,0.042995998787789556,84.79365261444444,213.14963351134546,0.013451172839987159
0.013899304015001123,210.332120805539,0.044130290247628566,84.80591110879334,213.25559089673513,0.01380359453272626
0.014246769374985323,210.383376723792,0.0452334927655784,84.82657749503292,213.3806601723065,0.014146237863936541
0.014603812209691924,210.422437879954,0.046367103765771855,84.84232695319746,213.4954076474584,0.014498203495741326
0.014961789427349123,210.425301383797,0.047503681431833464,84.84348151794696,213.57364043328784,0.01485096590074139
0.015328346692955023,210.461840789573,0.048667500750132195,84.85821420635583,213.68787285083306,0.015212054459531539
0.01568938106017802,210.460237622543,0.04981378486606521,84.85756780940935,213.76222848861866,0.015567575109196225
0.016043291556699223,210.44460051364,0.05093745069252003,84.85126292709965,213.82082459621344,0.015915958048419256
0.016420844022428622,210.43628549597,0.05213617977121087,84.8479103119751,213.8918269167586,0.016287479949802897
0.01679690455852362,210.445351013596,0.053330171973312496,84.85156552868192,213.98018148935637,0.01665739659119137
0.01718209394600132,210.426080675311,0.05455314827855419,84.8437957282854,214.04164136216303,0.017036151133264368
0.01756172045836582,210.389205414837,0.05575846245531148,84.82892762326229,214.08400182779005,0.017409295422075505
0.01793012119566812,210.311635338649,0.05692813479624628,84.79765136854328,214.08254844913014,0.01777127254601776
0.01829819916475512,210.227905179799,0.0580967823480975,84.76389136849495,214.0746972587682,0.018132801721715327
0.018676786786366223,210.19789808706,0.05929879804671275,84.75179250870258,214.12371941257436,0.01850451725929574
0.01905480386622102,210.162160569101,0.060499002275251734,84.73738314146152,214.16675931884646,0.018875534802455178
0.019426907147238322,210.148447469742,0.06168043019248167,84.73185401979998,214.23098184587298,0.01924061365809548
0.019823837276766922,210.151760590052,0.06294068335373497,84.73318986990897,214.31777489541528,0.01962990382815103
0.02021575429574792,210.119696516025,0.06418501988899965,84.72026163526127,214.36742467349006,0.020014128747531564
0.020620889125872722,210.073934495269,0.06547132297464589,84.70181038849245,214.4058458067318,0.020411156933743884
0.02099440396772192,209.882354295303,0.0666572325975171,84.62456525186617,214.28870922707512,0.020777058234816556
0.02135125674844912,209.733341860444,0.06779024017632596,84.56448343813103,214.2114122912166,0.021126512091940376
0.021708859236891222,209.631694894262,0.06892562807712962,84.52349938136643,214.1825598503125,0.021476577652220392
0.02208778347140152,209.620337474957,0.07012871252169983,84.51892006990268,214.25038610030597,0.02184738190048438
0.022469179244796623,209.596873337989,0.07133964410222927,84.50945932987717,214.30634305416922,0.02222046593264788
0.02286088409360262,209.548429832218,0.07258330699718832,84.4899269083503,214.33889219860876,0.02260348954396223
0.023250239262481123,209.495847177107,0.07381950965837757,84.46872558180954,214.36667574847093,0.022984070216374042
0.023641927459916022,209.440982357949,0.07506311968523337,84.44660408672505,214.39257086998919,0.02336678525000764
0.02403144204720542,209.392896242026,0.07629982849987721,84.42721576478489,214.42490949316274,0.02374723127014741
0.02441509625553112,209.320664370447,0.0775179306113113,84.39809187416422,214.43124853932318,0.02412181191517565
0.02480599741285212,209.23158842287,0.07875904178580548,84.3621764521012,214.42178666397464,0.024503323859660333
0.025210143065867722,209.121816541329,0.08004220423413001,84.31791642946386,214.39380745453005,0.02489760920236703
0.02560779496549292,209.003118886556,0.08130474901544002,84.2700575350594,214.35522790215146,0.0252854075507571
0.02599904852906092,208.881765760603,0.08254697907976842,84.22112795467514,214.31249292544885,0.025666819388558002
0.026387396141205423,208.812627210365,0.08377998274832721,84.19325129121917,214.32264872385073,0.02604525456852876
0.026786954466599323,208.73811239448,0.08504858043145284,84.16320691745433,214.32957070663483,0.026434464895766275
0.027171824426247423,208.652683720947,0.08627054255333556,84.12876207628584,214.3221578090779,0.02680922408578264
0.02757335768098712,208.543081311669,0.0875454106371341,84.08457038486495,214.29331428457084,0.027200059176525383
0.02796435910966332,208.423759434062,0.08878684017318104,84.0364598038138,214.25219628986216,0.027580496305163873
0.028374500862811923,208.343553377565,0.09008904023942785,84.00412072183421,214.25519771263805,0.027979401141882215
0.028784178710914723,208.280497383451,0.09138976740715424,83.97869654500744,214.27568044213444,0.028377695991556554
0.029186369251691723,208.216394312922,0.09266672237412121,83.95285018697015,214.29347488159482,0.028768557314907996
0.02960487543237962,208.128676078486,0.09399547949780529,83.91748219484556,214.29029960769566,0.029175112557002524
0.03000906728405192,208.022759940599,0.09527878862686484,83.87477680804952,214.2653289402706,0.02956760539119641
0.030415832324426424,207.91599996817,0.09657026763005389,83.83173118716616,214.2399381607673,0.02996244147159537
0.030834105076245122,207.800708159691,0.09789828361707825,83.7852455299874,214.20805703000505,0.030368285275367456
0.031249049593729823,207.724089781053,0.09921573246009219,83.75435299972058,214.21527016443352,0.030770737060248885
0.03165799247837822,207.532721624282,0.10051412611885086,83.6771933589105,214.10279096448087,0.031167209496151163
0.032057577254154625,207.379865789467,0.10178280778194093,83.6155618863131,214.02796185796907,0.03155445741600071
0.032454080583665126,207.237827840441,0.10304170585313677,83.55829218526581,213.9635410051584,0.031938570853074465
0.032849732212646726,207.141858959705,0.10429789977515334,83.51959753255305,213.9464135565611,0.03232171219176782
0.03325189688673243,207.083865333026,0.10557477261537544,83.49621450227609,213.96979666998575,0.032711010252909296
0.03365046658025773,206.96882812307,0.10684023139231828,83.44983149922184,213.93342575698048,0.03309667888003989
0.034067061452266824,206.844544640679,0.10816292011094716,83.39972039912178,213.8911304540192,0.03349963031997129
0.03447821651743362,206.741603458836,0.10946833744285174,83.35821451460268,213.86968522605116,0.03389716096622796
0.03488404708181503,206.642521750285,0.1107568494847627,83.31826476971492,213.85104920812694,0.03428938863629135
0.035301396992216925,206.563997479717,0.11208193545028873,83.28660378382189,213.85599515904778,0.034692589148835405
0.035721928732591925,206.487845118591,0.11341712372597935,83.25589915181588,213.86398920606376,0.03509869924999272
0.03615736624360982,206.391101768342,0.11479963782346118,83.21689223299549,213.8536604244021,0.035519030220512955
0.03659153074375013,206.291100836621,0.11617811011140665,83.1765718573256,213.8396079950463,0.03593795651411358
0.037022850059522425,206.192801212911,0.1175475489389837,83.13693744904573,213.82664637556954,0.03635396377755248
0.03744640734447373,206.097682221527,0.11889234331870407,83.09858547171969,213.8152999827462,0.036762316216929804
0.037865128445992526,205.983695786413,0.12022178281602626,83.05262614108173,213.78329488514578,0.03716584224179823
0.038303102734163125,205.848289961159,0.12161235118096791,82.9980305123393,213.73291815919308,0.03758774860573334
0.038726311048019824,205.709730422516,0.12295603757746293,82.94216330635845,213.67610942846267,0.03799526167888022
0.039165758437944724,205.533784553731,0.12435128304047449,82.87122193206434,213.58367111039902,0.03841823590639663
0.03959248413606702,205.384806013324,0.12570613713201279,82.81115378457224,213.51650068719576,0.03882879418621653
0.040008310624985326,205.251899966362,0.1270263862343284,82.75756606643716,213.46368173658462,0.03922870410691636
0.04045254760946663,205.148418455137,0.12843683866005653,82.71584232111125,213.4471946197002,0.03965576043866567
0.04088260644646152,205.01453608565,0.12980227546751533,82.66186094973409,213.39606468024354,0.040069013289632326
0.041306847182626026,204.839060900325,0.13114923980483761,82.59110935501103,213.30031668596737,0.040476508142029764
0.041735969791561224,204.674463181367,0.13251170408820687,82.52474355472718,213.21675039380852,0.040888523307065
0.042155108266777826,204.491706431464,0.13384246874701958,82.45105603316628,213.11207645574052,0.04129078855526532
0.042576959623186326,204.376985101576,0.13518184680361658,82.40480039295544,213.07873574415436,0.04169549414661094
0.04298391363853943,204.240775047729,0.13647392580236267,82.34988049924434,213.01984288384895,0.04208575273434671
0.04342629882276532,204.163062574267,0.1378784987622799,82.31854682994447,213.02910873818806,0.04250981621736957
0.04387172051547163,204.016848148308,0.1392927126366224,82.25959317339779,212.967418290718,0.04293660884146142
0.04430877234666342,203.901477408824,0.14068035220065636,82.21307569123785,212.93610155247995,0.04335520468513252
0.04474656592912112,203.793491618241,0.14207034682495956,82.16953582047478,212.91255052686242,0.043774335361898446
0.045190663716604525,203.71554127501,0.14348035730021935,82.13810624208404,212.92158179461507,0.044199322091517126
0.04563422920527482,203.64465084037,0.14488867772674754,82.10952321883718,212.9378175132476,0.044623619216375775
0.04608394954587833,203.531333321327,0.14631653980816367,82.06383359515905,212.91086101711235,0.045053620114299114
0.04653592811108202,203.386407727242,0.1477515717526854,82.00539959562397,212.85118297600812,0.04548559400220667
0.04697528477513713,203.221226031213,0.14914652916106036,81.9387983357851,212.76760099638173,0.04590532585537369
0.04742821153315582,203.074195345066,0.15058457161776972,81.87951556313061,212.7056412388172,0.0463378373230807
0.047862959759939025,202.892764848261,0.1519648972378064,81.80636278681884,212.60381308777608,0.04675281376070255
0.04830281852101573,202.66906036948,0.15336144880422492,81.71616514097434,212.45854721233178,0.04717249313157135
0.04874573084623152,202.488556055754,0.1547676954367851,81.64338580168001,212.35900870868986,0.04759490808418216
0.04918933711693142,202.287377764555,0.15617614534625726,81.56227071466857,212.23775978391575,0.048017806089068304
0.049628167695102324,202.222306891929,0.15756943243194987,81.53603413882578,212.25822945005208,0.048435975447346874
0.050079494783643326,202.09468752127,0.15900239593806756,81.48457800857607,212.21548737079348,0.04886587062138185
0.05053624698907803,201.974746242831,0.16045258419032274,81.43621768510945,212.18179190451505,0.049300745218910494
0.050974392013115724,201.787218989186,0.16184369464164242,81.36060669643979,212.0731997931772,0.0497177262441356
0.051431934886730424,201.661747421968,0.1632963932653691,81.3100165605375,212.03360128451894,0.05015298262153884
0.05187374908741822,201.554569402354,0.16469915335255284,81.26680238302913,212.00996056295432,0.05057309674052042
0.052347607854713527,201.469243364094,0.16620365493871544,81.2323989244027,212.01567631050347,0.051023485454371555
0.05282498812003032,201.371077617229,0.16771933728109625,81.19281849526674,212.0085024000768,0.051477016223689116
0.053275650420160324,201.238993604371,0.16915019008400903,81.13956222128239,211.96013187854234,0.05190497517186235
0.053749800850990924,201.100967747303,0.17065561770189616,81.08391019571258,211.91010471466208,0.052355041343154336
0.05420588737747423,200.939545854276,0.17210369242348067,81.01882488844409,211.8316522465337,0.052787770110791415
0.05467400334463043,200.792272304703,0.1735899606192016,80.95944419325625,211.77038967226628,0.05323171760813735
0.055120436672635824,200.555225552472,0.17500738643561872,80.86386694275672,211.60991716190324,0.0536549183960442
0.05556032224465862,200.324832147061,0.17640402312679113,80.770972321695,211.45494437475884,0.054071737070808694
0.05599022988779152,200.150985050239,0.17776897989373808,80.70087717225637,211.35748471546978,0.054478933241072225
0.05646191391220773,200.014510348133,0.17926657667125953,80.64585057236722,211.3077124126017,0.05492550812196567
0.05693185535915132,199.964753884878,0.18075864076530543,80.62578876638281,211.34911832998017,0.05537023495093809
0.057396667155744326,199.889460698185,0.18223441821948821,80.5954305535082,211.36244954181998,0.05580991289041761
0.057861234731482525,199.783961983277,0.183709420272457,80.55289347165728,211.34370870317701,0.056249166735344365
0.058320350046708026,199.515511599477,0.18516711139829797,80.44465427690913,211.15132607570655,0.05668307592889487
0.058762551415725825,199.204664327299,0.1865711007449295,80.31932065676696,210.9104386570843,0.05710082185196954
0.059202135348741226,198.928041010999,0.18796677973225337,80.2077861356348,210.70500581959215,0.05751592220002974
0.059652742643708026,198.737956099448,0.18939745789377296,80.13114389929744,210.59322024818493,0.057941253171433414
0.06011558091153123,198.741577843416,0.19086696939411163,80.13260418646533,210.68904324674725,0.05837794077548438
0.060597854675848724,198.704417491896,0.1923981885958197,80.11762113273248,210.7454789065191,0.05883276297308854
0.06106431915376523,198.608429291946,0.1938792133132046,80.07891869051262,210.7363178048574,0.059272479051535064
0.061524121531971926,198.504184109993,0.19533908586401086,80.03688703314918,210.71697965778114,0.05970572590861339
0.06199291084277943,198.40045666112,0.19682749192582466,79.99506412576359,210.69987848207953,0.06014724750818238
0.06248591005035683,198.290540806183,0.19839276440988293,79.950746053053,210.68090570283474,0.060611360599429294
0.06297522052047302,198.177533783421,0.19994632515250185,79.90518162147535,210.65780767563544,0.06107178819485566
0.06346969414998982,198.049875867965,0.20151627892621765,79.85370994996349,210.6200409157482,0.061536858919253964
0.06395979820325923,197.908317107222,0.20307235929534803,79.79663345763191,210.56649313214652,0.061997606562079366
0.06445189065416342,197.751755478936,0.20463475282696883,79.733507809107,210.4972299997332,0.06246001001743392
0.06496272267052582,197.578930661896,0.20625664447891945,79.66382484287648,210.4141959400238,0.0629397963614979
0.06544803218698722,197.415434465829,0.20779750219368442,79.59790317662225,210.33588617495667,0.0633953981967305
0.06592264316715442,197.235947656701,0.20930439205571527,79.52553409518185,210.23826265380924,0.06384075572510413
0.06641061858496082,197.07249991472,0.2108537140072506,79.45963196561512,210.16020654014122,0.06429844724554118
0.06689688942532931,196.830081515978,0.21239762392542055,79.36188886724233,209.99740171473093,0.06475433168504584
0.06739434478909281,196.592753386734,0.21397704470536968,79.26619816553114,209.84199319151662,0.06522048678590278
0.06786691792048632,196.360760684378,0.21547746439754406,79.17265870794121,209.6871603125489,0.06566312408501217
0.06833591887231702,196.15434958596,0.21696654241960653,79.08943375305908,209.55873730571827,0.06610222186289019
0.06881486073373122,196.032258647063,0.21848718282959662,79.04020668649581,209.5221912251794,0.0665504278331964
0.06929500273104762,195.878227757747,0.22001163367107618,78.97810143192359,209.45161008517286,0.06699955536737236
0.06977792415425282,195.722692294933,0.2215449091897527,78.915389533317,209.37981547315502,0.067451079413458
0.07026123071824772,195.585134156341,0.2230794075304365,78.8599260918367,209.32718639235912,0.06790275953446072
0.07075972921546692,195.43223887163,0.22466214025910744,78.79827871304121,209.26097117415898,0.06836842382785709
0.07125480485097911,195.292904988315,0.22623400540185867,78.74209929128861,209.2084628220382,0.06883067619492005
0.07174739186708042,195.141900442903,0.22779796917798031,78.68121425857849,209.14282284366672,0.06929039296565492
0.07223487820771012,194.99064932003,0.2293457383094796,78.6202298058361,209.07577512530466,0.06974514145479567
0.07271802580834212,194.857839073272,0.23087973194148623,78.56668071434328,209.02751644396,0.0701956386269235
0.07321541423464702,194.7015865368,0.23245894019500427,78.50367969163777,208.95674384723478,0.0706592023385752
0.07370750571016692,194.572513980503,0.23402133062977995,78.45163763693881,208.91396866576244,0.07111761794312792
0.07421317482247482,194.419966925399,0.23562683006135754,78.39013066432088,208.8484899198134,0.07158846319009916
0.07472270146827412,194.248607996614,0.2372445771617703,78.32103874423477,208.76338874257277,0.0720626761817192
0.07521725454085541,194.061814685829,0.2388147831672159,78.24572368132625,208.6586115977133,0.07252273840803578
0.07573444340891741,193.869095947484,0.24045685782331278,78.16801948602556,208.55166402325668,0.07300363147366988
0.07623733020846102,193.697076888345,0.24205352341186373,78.09866140138071,208.4640248994954,0.07347100452647937
0.07675129245836462,193.530072413578,0.24368535355530765,78.03132519715466,208.38375560088102,0.07394844528418318
0.07725701061444662,193.381132870518,0.245291008700868,77.97127277339285,208.32118110532932,0.07441800537329935
0.07777227668705412,193.201899271052,0.24692697848139683,77.89900578608818,208.22765083762462,0.07489620405529661
0.07825687621572272,193.030834734001,0.24846558198491964,77.8300325647492,208.13682487359733,0.07534573372531682
0.07876094122139002,192.741290296868,0.2500659883779133,77.71328824769718,207.9217757328745,0.07581310586361635
0.07925725678307632,192.483284772616,0.2516417902862673,77.60926042031878,207.73898190028922,0.07627307934381758
0.07976709329270291,192.25220786029,0.25326052120433173,77.51609020926894,207.58760766040987,0.07674536352077496
0.08027300284522892,192.158417930936,0.2548667840336018,77.4782741097534,207.58355116024072,0.077213789604792
0.08076956462735811,192.094286537004,0.256443367691862,77.45241633172002,207.60965842800078,0.07767334722604612
0.08126354747878561,191.932172959947,0.2580117632451443,77.38705213745062,207.52926220998415,0.07813030864560765
0.08178408089771802,191.750175370875,0.2596644568502547,77.31367070953681,207.43228722555827,0.07861160496303658
0.08228641284679472,191.519927436958,0.2612593607885732,77.22083474258146,207.27941525442372,0.07907585227803954
0.08279401420834652,191.344389877725,0.2628709951115002,77.15005799869873,207.18656001194876,0.07954475067507735
0.08329135134228052,191.140500685745,0.26445004051174065,77.06784987649239,207.0608512841008,0.08000395431550915
0.08380288295620501,190.927444932593,0.2660741533859509,76.9819457968215,206.92771525340638,0.08047604419081661
0.08432419008957581,190.746623942935,0.26772930353440316,76.9090387737914,206.83117851924388,0.08095692665374746
0.08483355460223502,190.56862142057,0.26934653586209617,76.83726815677383,206.73523497132456,0.08142656932797716
0.08533827400156321,190.399406269089,0.2709490199549632,76.7690406076967,206.64776297101548,0.08189171167456533
0.08584186221362111,190.192909560649,0.272547912528247,76.68578113485368,206.51942309716196,0.08235559600427966
0.08635008283610301,189.95858964209,0.27416151300462704,76.59130334369068,206.36152959311377,0.08282352945087346
0.08686031682007042,189.750882907938,0.2757815059037236,76.5075559884806,206.23270471420958,0.0832930964964051
0.08738742041201891,189.60526052693,0.27745505980816004,76.44884104445818,206.1743751409272,0.08377795716177337
0.08790085047337262,189.455248705088,0.2790852002529581,76.38835627789148,206.10852619290958,0.08425001420153222
0.08840605703873722,189.270691288988,0.28068923109799065,76.31394272771996,206.0033668188435,0.08471429299667428
0.08892056385842692,189.033447505747,0.28232279025050544,76.21828603431719,205.8424082460604,0.08518689717496164
0.08940880008318422,188.800265033204,0.28387294026410986,76.12426686138785,205.68067018520995,0.08563516385218214
0.08992317225386012,188.556804239601,0.28550607190600585,76.02610346940713,205.512430226876,0.08610720958615584
0.09043789531056132,188.305509333181,0.28714031761103215,75.92478136313858,205.33546327265714,0.08657935438264878
0.09095341065133762,188.051563262612,0.2887770788179969,75.82239030748516,205.15549431966235,0.08705200259479155
0.09147450428011182,187.817981484705,0.29043155108935503,75.72821013463306,204.9985382359096,0.08752953831096476
0.09199580526878112,187.583868194343,0.29208668172838004,75.63381565595911,204.84079720431447,0.08800703598638028
0.09250261144812982,187.298754208459,0.29369579134781215,75.51885769685067,204.62437809372284,0.08847103832628885
0.09300937241949302,186.955267561662,0.29530475743189033,75.38036388086212,204.34385966809057,0.08893478410685268
0.09349740696533032,186.638587104147,0.29685426711492374,75.25267832039206,204.08881103805768,0.0893811898153035
0.09398185234748542,186.334257117217,0.29839238120326617,75.1299724696619,203.84629575688564,0.0898241155143817
0.09446540862246491,186.002991386794,0.29992767237632606,74.99640612715534,203.57383997314835,0.09026603275083804
0.09496099299372501,185.578894415689,0.3015011527550769,74.82541022840581,203.20165050808046,0.09071873979717496
0.09545259564353002,185.131497676984,0.3030619911682078,74.64501986335995,202.80277966562625,0.0911676072262388
0.09596116213060202,184.705077203708,0.3046766897646614,74.47308712853507,202.42959106359837,0.09163175188572904
0.09644576087754472,184.284245054878,0.30621529078620446,74.30340760612681,202.0576792869396,0.09207382196838472
0.09693633410341072,183.894387660436,0.30777286077832905,74.14621710468779,201.72043546243015,0.0925211432401036
0.09743076273554811,183.474201253984,0.3093426716853652,73.97679794560635,201.35023262445515,0.09297177763142019
0.09792031747176212,182.990679005711,0.3108970079728447,73.78184177510268,200.90918438832355,0.09341776984536944
0.09841190637090771,182.420996934374,0.31245780272763196,73.5521459639396,200.37339500476725,0.09386541515332232
0.09891738358099282,181.754549525088,0.3140626928696522,73.28343436851549,199.73323401805172,0.09432549842014369
0.09943362474446321,180.941146147261,0.31570175856367066,72.95547012657563,198.93278017410083,0.09479516060876114
0.09997331280357942,180.157146409835,0.3174152681513646,72.63936143244548,198.16805316166568,0.09528591842236478
0.10050230679396252,179.36042629662,0.319094824070831,72.3181238827972,197.38656288697882,0.09576671811481537
0.10103000311569202,178.288356671191,0.32077025989232216,71.8858654098242,196.30082990117305,0.096246108155525
0.10157563357414552,177.25973455293,0.322502636597912,71.47112497174139,195.26500439732874,0.09674154906471509
0.10211918808717661,175.961905792603,0.3242284221767857,70.94784041557753,193.93099274641588,0.09723486104122948
0.10267839059779361,174.590926265236,0.3260038901479947,70.39506147014316,192.5176415871285,0.09774212078063965
0.10323165344873762,173.168607846871,0.3277604996997419,69.8215826838584,191.04508956031952,0.09824373947904322
0.10376525800710562,171.596959100511,0.32945469417256035,69.18789390932604,189.40276183481026,0.09872729662948214
0.10432060773276162,170.162130367695,0.33121792955151813,68.60937096425462,187.91354722075437,0.09923031125041012
0.10487751444882362,168.737446531643,0.33298610837501497,68.03493844155847,186.434210518323,0.09973448217312363
0.10547781008638162,167.058011319673,0.3348920470242616,67.35779016409217,184.67892451105806,0.10027764882660539
0.10611604563125662,165.033169009342,0.3369184448792398,66.5413737445667,182.54583630260822,0.10085482131326509
0.10677325371120162,162.49328997557,0.33900508053306516,65.51729451814982,179.8432272524994,0.10144880321689032
0.10749625775159961,159.517613424674,0.34130061836132874,64.31750173282856,176.6651599132928,0.10210184392611718
0.10802922051893962,157.031219540429,0.34299277514763327,63.31498771870097,173.99517978452002,0.1025829602868612
0.10840436025278762,155.450424820032,0.34418384380260064,62.6776112874369,172.30192867367163,0.10292146782499316