File: example/data/02 processed data/test_ID_056.csv
Strain,Stress_MPa,Displacement(mm),Force(kN),True Stress (MPa),True Strain
0.002579387782559414,60.1030290851023,0.008189556209626138,24.233541327113247,60.258058104019234,0.0025760668712792815
0.002662828299018814,61.3904704240005,0.008454479849384734,24.752637674957,61.553942705935604,0.0026592892529330794
0.002728395638914514,62.6453931580635,0.00866265615355358,25.258622521331205,62.816314575554046,0.0027246803238985965
0.002768170774656614,63.8499958006792,0.008788942209534748,25.744318306833858,64.02674349301658,0.00276434644590875
0.0027996489511642143,65.0840480667906,0.00888888541994638,26.241888180529973,65.2662605536983,0.0027957372332963375
0.002852401041429814,66.2987959975855,0.00905637330653966,26.731674546226472,66.48790675233457,0.002848340664961509
0.002892860743087114,67.4837625607321,0.009184832859301587,27.209453064487185,67.67898368823985,0.002888684473752777
0.002931718853260314,68.6386480997049,0.009308207359101496,27.675102913801016,68.8398773184011,0.0029274297464683043
0.0029675418292259143,69.8161427180764,0.009421945307792277,28.14986874392841,70.0233250419475,0.0029631473686555967
0.003011232252476414,70.9253018877891,0.009560662401612614,28.59708172115657,71.13887444435025,0.0030067075736009315
0.003079636472172914,72.0393857419792,0.009777845799149,29.046280331166013,72.26124086174315,0.0030749041052630876
0.003113347461528114,73.1446435285268,0.009884878190351762,29.491920270702007,73.37236821878072,0.003108511031045662
0.003155561369786614,74.2673654594001,0.010018907349072499,29.944601753230117,74.50172068887962,0.003150593035186729
0.0032175096269872142,75.3521519812235,0.010215593065684404,30.381987678829315,75.5945982556373,0.0032123445191114385
0.003270431362618714,76.3520128600477,0.010383619576314417,30.785131585171232,76.60171687750426,0.0032650951333189557
0.003320356954643414,77.3313343895831,0.010542133330992838,31.17999402587991,77.58810202353541,0.003314856741241953
0.0033792763773046143,78.3402575366354,0.01072920249794215,31.586791838771397,78.60499091832092,0.0033735794535995874
0.003433864997199214,79.29841344522,0.010902521366107504,31.973120301112708,79.57071349148298,0.0034279827448503884
0.003547971390064414,80.1653718620345,0.011264809163454514,32.322677934772315,80.44979630787488,0.0035416921874764176
0.0036350723233344144,81.0167206023187,0.011541354626586765,32.6659417468549,81.31122224110752,0.0036284814153922395
0.003705194687431714,81.8527084077288,0.011763993132595692,33.003012029996256,82.15598862807302,0.0036983473621659373
0.0038155795924241136,82.7132040919228,0.01211446520594656,33.349963889863275,83.02880290547996,0.0038083187323433862
0.003921853777747714,83.5236207015267,0.01245188574434899,33.67672386685557,83.85118812890614,0.003914183357524339
0.004023706277053214,84.212648536972,0.012775267429643954,33.95453989010711,84.55149549949748,0.004015632820516826
0.004138720544694914,84.8416917755256,0.013140437729406353,34.208170123891925,85.19282782832366,0.004130179598438181
0.004238872096960714,85.4475589281769,0.013458418907850267,34.45245575984093,85.80976020147095,0.004229913386263308
0.004358052465983314,85.9389358805826,0.01383681657949702,34.65057894705091,86.31346227202097,0.004348583655748666
0.004475729627772914,86.386324277676,0.014210441568179001,34.830965948758966,86.77296610867998,0.004465743336129398
0.004599305199232414,86.7514526034635,0.014602794007562914,34.97818568971648,87.15044901046357,0.004588760714249335
0.004756227557696914,87.0500257965718,0.015101022495687701,35.09857040117775,87.46405552816368,0.004744952444608029
0.004904606298632414,87.3488504053051,0.015572124998157912,35.21905648341902,87.77726212718126,0.004892617900097287
0.005046144975806314,87.6529649532843,0.016021510298185045,35.34167546916423,88.09527452199784,0.005033455855771709
0.005200160960890614,87.9211509918734,0.016510511050827698,35.44980807992336,88.37835512889792,0.005186686815511186
0.005354854674755614,88.1788418432893,0.017001663592349073,35.55370903121425,88.65102672674838,0.005340568418319608
0.0055223399488733135,88.4008238104211,0.017533429337672768,35.64321216036179,88.8890032112627,0.005507147735000578
0.005665637573142714,88.6021719793042,0.017988399294728116,35.72439574205546,89.10415977393221,0.005649648213437707
0.005803643624893914,88.7852254628682,0.018426568509038177,35.79820290662846,89.30050327061053,0.0057868673628998545
0.005955555202563113,88.9470472581214,0.018908887768137882,35.86344945447455,89.47677630817213,0.00593789098247285
0.006124162330127014,89.0755701656514,0.019444215398153268,35.91526989079065,89.62108341699445,0.006105485861034752
0.006286987731486514,89.2053854758429,0.01996118604746968,35.96761142385986,89.76621863991205,0.006267307069101532
0.006460587499887414,89.287552943384,0.02051236531214254,36.00074134677243,89.86440299182556,0.006439807357729349
0.006629078075199014,89.3755633926148,0.021047322888756867,36.03622715990229,89.96804098035933,0.00660720236112773
0.006825129135403114,89.4410370534303,0.021669785004904886,36.0626261399431,90.05148368132434,0.006801943378948386
0.007000303371819814,89.508263430488,0.02222596320552791,36.08973181517276,90.13484842878619,0.0069759149993587925
0.007176270422378814,89.5620627463973,0.02278465859105273,36.11142369934739,90.2047843282515,0.007150643524450526
0.007356962778717114,89.5878358815853,0.023358356822426835,36.121815427455196,90.24693025559195,0.0073300323315895095
0.007532197248756314,89.6243090674931,0.023914726264801296,36.136521416013224,90.29937704167295,0.007503971895072613
0.007706908305775514,89.6752817949973,0.024469433870837255,36.15707361974292,90.36640096908593,0.007677361799005423
0.007892720399115115,89.7192483330686,0.025059387267190487,36.174800927893266,90.42737727458028,0.007861735809815624
0.008064903514433114,89.7711806244746,0.025606068658325137,36.195740027788155,90.49517653458773,0.008032555983508076
0.008233915440545215,89.8012292170025,0.026142681523731056,36.20785562029541,90.54064494483232,0.008200201696454157
0.008410868054653015,89.8358775833313,0.026704506073523322,36.22182584159918,90.59147529625866,0.008375693797006664
0.008582564120162015,89.8847287901701,0.027249641081514394,36.241522648196586,90.65617023843511,0.008545943301228912
0.008771153637612215,89.9077677843456,0.02784841279941878,36.250811970648144,90.69636262879686,0.008732910530961188
0.008958248065935214,89.9298760653363,0.0284424376093443,36.2597260295436,90.73549020366839,0.008918360996916756
0.009146655148952213,89.9363899942969,0.029040630097923275,36.262352445700515,90.75900713891642,0.009105077835337183
0.009336898389467514,89.944092103681,0.029644652386559354,36.26545793620418,90.78389095238597,0.009293578990816028
0.009529809121371914,89.9649481540927,0.030257143960355826,36.273867095730175,90.82229693761533,0.009484686934469728
0.009723454341906114,89.9830705169719,0.03087196753555191,36.281174032443076,90.8580167946882,0.009676485778756854
0.009919841926342614,89.9931674078778,0.0314954981161378,36.28524509885633,90.88588540301484,0.009870963274281408
0.010100920472341115,89.9980012086873,0.03207042249968304,36.28719408734272,90.9070638615659,0.010050247121115108
0.010288976247147415,89.9956931044146,0.03266749958469304,36.28626345969997,90.92165665311148,0.010236405026235141
0.010473924217721815,89.9957500239864,0.03325470939126676,36.28628640967132,90.93835868965468,0.010419452697041361
0.010676415162795315,89.989601646902,0.03389761814187513,36.28380738403089,90.9503679944189,0.010619824675122978
0.010866097723416115,89.9666146152916,0.034499860271846164,36.274539012885576,90.94420064154627,0.010807485889238666
0.011068299359568814,89.9451910736219,0.035141850466630986,36.26590104088435,90.94073137437836,0.011007493997432949
0.011267202148660114,89.9395974747154,0.03577336682199586,36.26364570180525,90.95296510063214,0.011204200023297022
0.011462418353743014,89.932414005836,0.03639317827313407,36.26074932715307,90.96325695873291,0.011397222564431821
0.011649078506759815,89.9011921195417,0.03698582425896241,36.24816066259922,90.94845816439354,0.011581750361180575
0.011814960142461615,89.8838391716652,0.03751249845231563,36.24116395401541,90.94581314892984,0.01174570843792909
0.011987497682955015,89.8703230876808,0.03806030514338217,36.235714268952904,90.94764337746079,0.011916216720735427
0.012182129210994014,89.8651429688064,0.03867826024490599,36.23362564502274,90.95989175201684,0.012108524248773464
0.012363852353926714,89.8636591975408,0.03925523122371732,36.23302738844845,90.97472021184278,0.012288044146148386
0.012539162102281015,89.8487747138843,0.03981183967474222,36.227025964638145,90.97540306471302,0.012461197870095435
0.012728275259794414,89.8371554120804,0.04041227394984726,36.222341062150825,90.9806274547223,0.012647951633647094
0.012923369481005814,89.827701993806,0.041031698102193453,36.21852944390258,90.98857857630163,0.012840575298551371
0.013141904837677614,89.8191929400312,0.04172554785962642,36.21509859342058,90.99958822624609,0.013056299204675466
0.013337874527808614,89.7951475484052,0.042347751625792344,36.205403491516975,90.99282395961188,0.013249708181895336
0.013546577980035314,89.7706221402697,0.04301038508661212,36.19551484695674,90.98670687340913,0.013455643406970481
0.013749461005326315,89.7456827829847,0.04365453869191105,36.18545929809943,90.97963754880574,0.013655794763325903
0.013960269066168615,89.7184317561351,0.04432385428508535,36.17447168407367,90.97092520364544,0.01386372202083761
0.014172197755232915,89.6931597321001,0.0449967278728645,36.16428200398276,90.96430892911512,0.014072711022594265
0.014379432366292414,89.680027651941,0.04565469776297841,36.158987149262614,90.96957554416933,0.014277028831126507
0.014587446763828915,89.6564638249119,0.046315143475156806,36.14948621420448,90.96432271799095,0.014482073477645789
0.014779241909067415,89.6321722874124,0.04692409306128904,36.13969186628468,90.95686784448327,0.014671093182049079
0.014961508776447315,89.5971706288075,0.04750279036522022,36.12557919753519,90.93767948351527,0.014850689386942196
0.015159427751924914,89.5630016691356,0.0481311831123616,36.111802272995476,90.9207255221844,0.015045671836059727
0.015356473951679314,89.5280905814537,0.04875680479658182,36.09772612244213,90.90292637241139,0.01523975669913092
0.015550555761875714,89.4821196144074,0.04937301454395539,36.07919062852906,90.87361630516207,0.015430884907313463
0.015751177700343514,89.448108841106,0.050009989198590656,36.06547748473394,90.85702189842195,0.015628415324203518
0.015955747065918815,89.4189529632575,0.05065949693429223,36.05372183478543,90.84569915963853,0.015829792170216954
0.016173086652596712,89.3961915927297,0.05134955012199456,36.04454445018862,90.84200394577105,0.016043695525063593
0.016365122892846414,89.3800984594959,0.051959265184787364,36.038055698868746,90.84281475496024,0.0162326575233367
0.016560699146986914,89.3454434317008,0.052580219791683445,36.02408279166176,90.82506644052734,0.01642506617162442
0.016764746333344314,89.3216990883154,0.05322806960836819,36.01450907240877,90.81915471559431,0.01662576910139482
0.016976914883949715,89.2981951362973,0.05390170475654034,36.00503227895507,90.81420299441656,0.016834417579636936
0.017176378232463315,89.2541285667698,0.05453500088807102,35.98726463812158,90.78719123784153,0.01703053195295155
0.017354049713111816,89.213755092304,0.05509910783913001,35.97098605321697,90.76197503326921,0.017205187960706195
0.017534947660304313,89.1602586854676,0.05567345882146619,35.949416301980534,90.72367915489647,0.017382984339675965
0.017758689149535614,89.1104296191504,0.05638383804977557,35.92932522244144,90.69291403873845,0.017602845971517154
0.017963773748310714,89.0753594068634,0.05703498165088652,35.91518491284732,90.67548900979776,0.01780433178621606
0.018158396519438316,89.0334368443597,0.057652908949216645,35.89828173564583,90.65014129406795,0.017995501819686805
0.018348059630415615,89.0054267856381,0.05825508932656957,35.88698807996928,90.63850366373157,0.018181765026417957
0.018539326113499916,88.9804015173291,0.05886236041036223,35.876897891787095,90.63003819876901,0.01836956773459431
0.018749560345255715,88.9400570343156,0.05952985409618689,35.860630996236054,90.60764400079098,0.018575954009903056
0.018962941561490015,88.9112639249137,0.060207339457730796,35.849021614525206,90.59728302688005,0.018785386122445576
0.019148500742842214,88.8835877839218,0.060796489858524025,35.83786259447727,90.5855752306287,0.01896747546065676
0.019353645907023216,88.8475879374199,0.06144782575479871,35.823347456367706,90.56711269405383,0.01916874595253295
0.019553180594098114,88.797264734161,0.06208134838626151,35.80305714081372,90.53353368776999,0.019364473079558474
0.019758617487709816,88.7490211906626,0.06273361052347866,35.78360534407516,90.50257915277756,0.019565949768409995
0.019962429571369913,88.708262461392,0.06338071388909947,35.76717142443326,90.47909490317612,0.019765792864241377
0.020164603947544813,88.6702833149679,0.06402261753345478,35.75185823259506,90.45828445993081,0.01996399069556757
0.020369343054614315,88.6384365643638,0.06467266419840044,35.73901762275148,90.443943286568,0.020164662787357554
0.020580468265179314,88.6005704908582,0.06534298674194432,35.72375002191403,90.4240117201221,0.020371551962335876
0.020777495350355515,88.5703294194817,0.06596854773737876,35.71155682193502,90.41059902717443,0.02056458727441701
0.021002013529682714,88.5456551291366,0.06668139295674261,35.70160814806788,90.40529217615335,0.020784511295846055
0.021195315702999016,88.5075027376752,0.06729512735702187,35.68622510383064,90.38344720028427,0.020973819323162078
0.021398293101718514,88.4700597454702,0.06793958059795628,35.67112808937358,90.36316801463032,0.02117256409403841
0.021609459658038815,88.4279712248853,0.06861003441427324,35.65415799787375,90.33885190171166,0.02137928534292941
0.021814771551489413,88.390413768047,0.06926189967597889,35.63901483127655,90.31863045173856,0.021580234211995123
0.022029305280458513,88.3658042940823,0.06994304426545578,35.62909229137398,90.31244157322989,0.02179016581312745
0.022259903754868016,88.3152051872727,0.07067519442170594,35.608690731508354,90.28109315483282,0.022015768408267508
0.022461394341524114,88.2629214487855,0.07131492703433906,35.587609928150314,90.24542973318165,0.022212852076829926
0.022682672328773416,88.2282870465164,0.07201748464385559,35.57364533715541,90.2295403717215,0.022429245622613697
0.022888470734600614,88.1852603694182,0.07267089458235694,35.55629698094942,90.20368612060678,0.02263045926137611
0.023111595314010615,88.1534088181799,0.0733793151219837,35.54345443549013,90.19077472833621,0.022848567348464712
0.023325862214276613,88.1080766795034,0.07405961253032824,35.52517651717577,90.16327353609442,0.02305797213653756
0.023536605209383315,88.0590246278899,0.07472872153979201,35.50539872996521,90.1316351256799,0.023263890217703524
0.023731388522226515,88.0222933492535,0.07534715855806919,35.490588678419016,90.11118459134204,0.023454176310220398
0.023940932402999115,87.9856931420046,0.07601246037952218,35.47583147485626,90.09215267394836,0.023658841753380084
0.024157746575700814,87.9444475627484,0.07670084537785007,35.45920125730015,90.06898723970927,0.023870564143259977
0.024391717388818516,87.8971930437214,0.07744370270949878,35.44014823522847,90.0411565357143,0.024098989981396562
0.024599866978515114,87.8370040367631,0.07810457765678548,35.41588002762288,89.99778265185877,0.024302162695233435
0.024828435541382813,87.7779210052314,0.07883028284389043,35.3920577493093,89.95730945886639,0.024525218621156225
0.025051221922508613,87.7206896267911,0.07953762960396485,35.368982057522175,89.91820008982734,0.02474258394910775
0.025274550098611414,87.6770326592589,0.08024669656309123,35.35137956821319,89.89303021370291,0.024960430478701806
0.025509132037601315,87.6346629653719,0.08099149421938417,35.334296107637954,89.87014715402626,0.025189203451742737
0.025722127120621014,87.5839151327251,0.08166775360797171,35.313834581514755,89.83675973149073,0.02539687880071589
0.025950435916766414,87.5409346793231,0.08239263403573335,35.296504862703074,89.81266009481271,0.025619437508378123
0.026179254518218814,87.5022726544101,0.08311913309534473,35.28091633425816,89.7930169211525,0.025842443494273983
0.026402986623738915,87.4569420638209,0.08382948253037105,35.26263904013259,89.76606653528508,0.02606044411994602
0.026604635793515713,87.4085874646086,0.08446971864441238,35.24314246573019,89.73406109933018,0.026256886810390352
0.026832335410859515,87.3573563472681,0.08519266492947895,35.2224860792185,89.70135823338397,0.026478660959263812
0.027037063785154615,87.2985461231125,0.0858426775178659,35.19877379683896,89.65884248299436,0.02667801966732324
0.027258998662401814,87.2324497559269,0.08654732075312575,35.17212374158973,89.61031898714174,0.026894088696678444
0.027486865512060813,87.1786279692967,0.08727079800079307,35.15042279722043,89.57489519181475,0.02711588434991812
0.027684904374742414,87.1273766799101,0.08789957138980715,35.129758277339754,89.53948977171558,0.027308606794043098
0.027896467387855915,87.0734408977638,0.08857128395644252,35.10801136997837,89.50248230211666,0.027514449303385386
0.028133425115311216,87.0077237494066,0.0893236247411131,35.08151421576074,89.4555490299642,0.027744949579055884
0.028353680238499816,86.9522526869096,0.09002293475723691,35.05914828336195,89.41766905561147,0.027959154787012167
0.028577239717815416,86.917648057955,0.09073273610406393,35.04519569696746,89.4015145222159,0.028176526676390593
0.028783201826847515,86.8802013440857,0.09138666580024085,35.03009718193536,89.38089171412967,0.028376746439112796
0.028990517240243315,86.8303914959426,0.09204489223777253,35.01001385116406,89.34764945758282,0.028578241299481916
0.029220913443045414,86.7688820331054,0.09277640018166919,34.9852132357481,89.3043480245446,0.02880212131523707
0.029445947352240515,86.7219299383965,0.09349088284336363,34.966282151161465,89.27553932164722,0.029020742321264736
0.029655597775751115,86.690165689897,0.09415652293800979,34.95347480616647,89.2610143747098,0.029224375235562736
0.029876578447389814,86.650499597483,0.09485813657046266,34.937481437705145,89.23932004621273,0.02943896831163881
0.030096937330335315,86.6007451208245,0.09555777602381461,34.91742043271644,89.20716231948629,0.02965291172605479
0.030341195642923216,86.5561079638644,0.09633329616628121,34.89942273103013,89.182323769686,0.02989000529350847
0.030572859528394915,86.5053928443342,0.09706882900265384,34.87897439483555,89.15011006821264,0.0301148219333545
0.030816845177808614,86.4687231451686,0.09784348343954234,34.86418917213198,89.13341639905605,0.030351541511409973
0.031045389824672514,86.4248760287373,0.09856911269333522,34.84651001478688,89.10796999559845,0.030573229113927864
0.03128638683941951,86.3786623403743,0.09933427821515695,34.827876655638924,89.08113858502685,0.030806942252202638
0.03152180583005931,86.3242200053137,0.10008173351043831,34.805925506142486,89.04531530675253,0.03103519322822494
0.031779703292084016,86.2636879328375,0.10090055795236674,34.78151897452008,89.00512234022399,0.03128517847005945
0.03202434555179411,86.2100222997357,0.1016772971269463,34.75988099125344,88.97084184389031,0.03152225743207925
0.03225401406197071,86.1606811623741,0.102406494646757,34.73998664466924,88.93970898417429,0.03174477442941599
0.03248619383779741,86.1043519591464,0.10314366543500678,34.71727470992783,88.90155462716916,0.031969674177981924
0.03271176380399241,86.0528928664112,0.1038598500776759,34.696526403736996,88.8678347725075,0.03218812293855463
0.03295686821423141,85.9940551832534,0.10463805658018473,34.67280304988777,88.82814992713521,0.032425435358940054
0.033184931212635015,85.9205900145607,0.10536215660011616,34.643181893870874,88.77185888394293,0.032646197553861264
0.033401264729513915,85.8663514797141,0.10604901551620667,34.621312916620724,88.73439621684551,0.03285556072302766
0.03362819517238471,85.8075994261099,0.10676951967232146,34.59762408860751,88.69315412688493,0.03307513228519911
0.033862364736245314,85.7494148324894,0.10751300803757886,34.57416406045973,88.65309279346677,0.03330165768696178
0.03410597098532011,85.6851130580881,0.10828645787839135,34.54823758502113,88.60748703792115,0.03353725728101142
0.03435516110338241,85.6274993802822,0.10907763650323914,34.52500775012979,88.56924591637157,0.03377819980142129
0.03458962269292101,85.5693813387763,0.10982205205002421,34.501574555794605,88.52919395335124,0.03400484827689402
0.03483758035162321,85.5196695205221,0.11060931761640369,34.48153075067451,88.49896787908754,0.03424448720647226
0.03509243108346171,85.453471573793,0.11141846868999092,34.45483973855334,88.45224163583889,0.03449072812449204
0.03534660174453731,85.3846055377742,0.11222546053890596,34.42707295283056,88.40266118483234,0.03473625156983141
0.035588499618140514,85.3328973593634,0.11299348628759612,34.406224215295325,88.36976714445194,0.03496986379123239
0.03581967150648011,85.2829555328726,0.11372745703307435,34.38608767085424,88.33776298516185,0.03519306643426692
0.03605545099313711,85.2133416299748,0.11447605690321032,34.35801934520585,88.2857470930758,0.03542066652957609
0.03628762886491911,85.1205197099203,0.11521322164611818,34.32059354703987,88.20934153794293,0.035644739343590595
0.036522965685111514,85.0458474397376,0.11596041605022905,34.2904856877022,88.15197400744037,0.035871809604445436
0.03674857297348371,84.9397763321963,0.11667671919081077,34.247717817141556,88.0611919010914,0.03608944370114328
0.03698079234877861,84.8713644174094,0.11741401570737207,34.22013413309947,88.00997472128714,0.036313406750660505
0.03721762963065431,84.7377477711463,0.11816597407732743,34.16625990132619,87.89148588342863,0.03654177186789841
0.03746593687529181,84.6418449072598,0.11895434957905149,34.12759186660715,87.81303092556344,0.03678114065630726
0.03770808272779941,84.5671023945726,0.11972316266076312,34.097455685491674,87.75596568771742,0.037014514678263076
0.03796507201092391,84.5198719099911,0.12053910363468341,34.07841235410841,87.72867493340797,0.03726213486244379
0.03819990382767911,84.4739446803191,0.12128469465288118,34.05989449510466,87.70084124305195,0.037488351777274165
0.03846143553488521,84.4557328254868,0.12211505782326053,34.052551475236285,87.70402154910575,0.037740228868287054
0.03870335830813471,84.4005063451388,0.1228831626283277,34.03028415835996,87.66708938360269,0.037973164430319
0.038956364259455215,84.3938716028234,0.1236864565237703,34.0276090302584,87.68155000624868,0.038216713409801116
0.03919736160068951,84.3546337207264,0.1244516230821892,34.011788316196885,87.66111280137143,0.038448647495634806
0.03945817799215791,84.2968384319571,0.12527971512510136,33.988485255765106,87.62303808698144,0.038699594694792366
0.03968751356440711,84.2332775345864,0.12600785556699257,33.962857501945244,87.57628687931476,0.03892020027727805
0.03995381605435791,84.1598249382387,0.12685336597258637,33.93324141509785,87.52233110298806,0.039176304527192465
0.040186399545646415,84.0885253246933,0.12759181855742735,33.90449341091634,87.46774040059563,0.0393999274257965
0.04045354360596031,84.0145792168936,0.128440000948924,33.8746783402515,87.41326666078061,0.039656717710594404
0.04069569175037531,83.9403899186597,0.1292088213074416,33.844765215203594,87.3564021521958,0.039889423891769644
0.04098721860430651,83.8648714702387,0.13013441906867318,33.81431617680025,87.30225929041144,0.0401695115596723
0.04123999607535921,83.7958078419921,0.1309369875392655,33.786469721891216,87.25154662852741,0.04041230684206247
0.041509733516023814,83.7271401800633,0.1317934039133756,33.758782920601526,87.20263145699649,0.040671327345909204
0.04176540976669571,83.6440278789052,0.13260517600925886,33.725272040774584,87.13745497780461,0.040916783403674876
0.04205715019606121,83.5708028044721,0.13353145187249432,33.69574769076315,87.08555261002519,0.04119678846444813
0.04231620224691091,83.4756777371516,0.13435394213394214,33.657393263619525,87.00805139897487,0.041445354348175284
0.04259994100813561,83.3769760566072,0.13525481270083056,33.61759674602403,86.92883031805542,0.041717536770374174
0.04284478640825161,83.2962571608933,0.13603219684619886,33.58505088727218,86.86506750755856,0.0419523503792145
0.04312182316579211,83.2162838021089,0.13691178855138994,33.55280562901031,86.80472167673781,0.04221796993218141
0.043403562674092414,83.1370810936695,0.13780631149024342,33.52087109696754,86.7455266034597,0.042488026085751016
0.04366590479495591,83.058629817401,0.138639247723985,33.48923954237608,86.68546003940712,0.04273942368064106
0.04391476562016061,82.9744839725351,0.13942938084400994,33.45531193772615,86.61828898864275,0.04297784400126424
0.04418600221610501,82.9179847924544,0.1402905570361334,33.43253146831761,86.58179905224875,0.04323763663354309
0.04445599467367021,82.8660580679076,0.1411477830889029,33.411594612980345,86.54995110400255,0.04349617060870132
0.04472093379254821,82.7894980069603,0.14198896479134057,33.38072559640639,86.49192166604787,0.04374980075049386
0.04498821407873941,82.7086500727007,0.1428375796999976,33.34812770931293,86.42956452833491,0.04400560695962198
0.04525953511977751,82.6310774063166,0.14369902400529358,33.316850410226856,86.37092155617285,0.04426521354708604
0.04555296744525141,82.557037928527,0.1446306716386732,33.28699769278209,86.31775598966158,0.04454590091339985
0.04583988493895811,82.4852784705182,0.145541634681192,33.25806427931294,86.26639414476466,0.04482028025363668
0.046115060235786313,82.3976574512367,0.14641531624862153,33.222735484338635,86.19743038788816,0.04508335981856707
0.04639595691374651,82.2952231446752,0.14730716320114517,33.181433971933046,86.1133887719027,0.04535183790766222
0.04668640299632261,82.1825237999125,0.14822932951332426,33.13599359612472,86.01933022529009,0.04562936744018653
0.04693546211258251,82.0761190873866,0.14902009220744947,33.093091216034274,85.92839966516046,0.04586728921735708
0.04720914686815531,81.9736106446466,0.1498890413063931,33.051759811921514,85.84351486888269,0.04612867017066579
0.047478365610085414,81.8847235870987,0.15074381081202118,33.0159205503182,85.77247643144777,0.04638571924534524
0.04774409784979571,81.7770181059853,0.1515875106731014,32.972493700333274,85.68138806030197,0.046639374640673664
0.04801013553027121,81.6821721947624,0.15243218030861108,32.9342518289282,85.60374435223989,0.046893257159594234
0.04827371319554071,81.6013301557441,0.15326903939584174,32.901656318796014,85.54052936405711,0.047144728511452176
0.048523620906631613,81.4945319788596,0.15406249637855537,32.85859529387619,85.44894175456514,0.04738309939089746
0.04882755810164261,81.4001977339302,0.15502749697271528,32.82055972632066,85.37477061826887,0.04767292896276954
0.04910209372195611,81.3055784220245,0.15589914756721066,32.782409219760275,85.2978525538206,0.047934649484849004
0.04937874556852921,81.2063733160148,0.15677751718008023,32.74240972101717,85.21624216252931,0.0481983181760241
0.04966846442147641,81.1103834464972,0.1576973745381876,32.703706605627666,85.13901164092185,0.0484743661404606
0.04996480726852731,81.0127652550212,0.1586382630775742,32.664346950824545,85.06055245727877,0.04875664672061169
0.05026941225585401,80.9144285008632,0.15960538391233647,32.62469757154804,84.98194926461991,0.049046714358431165
0.050583435587236214,80.86037157698,0.16060240798947498,32.60290181983834,84.95056697420415,0.04934566279172403
0.05088969191187091,80.7733851952866,0.16157477182019014,32.56782891073956,84.8839178825536,0.04963713102207668
0.05120090005861091,80.6757820468402,0.16256285768608963,32.52847532128597,84.80645470057074,0.04993322496798219
0.05151319562692441,80.5752980331116,0.163554396115485,32.48796016695059,84.725989123389,0.050230265417989625
0.05180741823193611,80.4832518924185,0.16448855288639713,32.450847163023134,84.65288138387528,0.050510035040359336
0.05211341623749101,80.3812447015668,0.16546009655403393,32.40971786367174,84.57018596438716,0.05080091861610914
0.05239611797076671,80.2599403216195,0.16635767455718428,32.36080793767698,84.46524962303778,0.051069581437903036
0.05270366163894071,80.1393986795712,0.16733412570363676,32.31220554760311,84.36303843152749,0.05136177059999484
0.052994366678842414,80.0285486892249,0.16825711420532466,32.267510831495485,84.26961094323728,0.05163788335485252
0.053300206264747414,79.9049368148574,0.16922815489057302,32.217670523750506,84.1638864286609,0.05192828868749982
0.05362354167862341,79.7360022623467,0.17025474482962932,32.14955611217819,84.01172910294846,0.052235215235487124
0.05393159550555311,79.5846534493787,0.17123281573013113,32.0885322707895,83.87678078766021,0.05252754811322616
0.05422998777057391,79.4374482874125,0.17218021117157215,32.02917914948472,83.74534013656447,0.05281063103189862
0.05454344989879841,79.3106973142989,0.17317545342868496,31.97807315712532,83.63657635970014,0.05310792435410564
0.05484259983284751,79.1650288087609,0.17412525446929084,31.919339615692394,83.50664480447561,0.05339156132619295
0.055146541385413514,79.0247608134283,0.1750902688986879,31.862783559974293,83.38270305609844,0.05367965906919163
0.05542269866883991,78.8771341026115,0.17596706827356673,31.803260470172958,83.24871773784223,0.05394134892969137
0.05570438478628061,78.7651022805631,0.17686142169644092,31.75808923952304,83.15266384573033,0.05420820744457647
0.056022661738069614,78.6301737007196,0.17787195101837103,31.703686036130144,83.03524532436067,0.05450964503304033
0.05632585819936321,78.478562010026,0.1788345997829782,31.642556202442485,82.89893436549266,0.05479671552402615
0.05663688808596341,78.3191878970944,0.17982211967293382,31.578296560108463,82.75494297700567,0.05509111720185347
0.05694472245481491,78.1776552864847,0.18079949379403734,31.521230611510628,82.62946016894176,0.05538240888370107
0.05724055250975991,78.0222577718665,0.1817387542184877,31.458574333616575,82.48829491478705,0.05566226142110994
0.05755335870169391,77.8655901845728,0.18273191387787815,31.39540596241975,82.34701642698461,0.05595808806649309
0.05786016779939441,77.6928079315591,0.18370603276307723,31.325740158004628,82.18812683528523,0.05624815816012557
0.05815373587738451,77.5035590809894,0.1846381114106958,31.24943502145493,82.01068058534253,0.0565256308925717
0.05847003138852301,77.3298212828458,0.18564234965856055,31.17938394124343,81.85129836052266,0.056824498852371036
0.05877769147508461,77.1581274602698,0.18661917043339363,31.11015699198078,81.69330407092478,0.05711512151820725
0.05907155861224281,76.9885350019505,0.1875521985938709,31.04177731278644,81.53636775978892,0.05739263620819953
0.05938122544862931,76.7895144838963,0.18853539079939804,30.961532239906987,81.34936995555532,0.057684988099090805
0.05967770347024021,76.5989811587484,0.18947670851801265,30.884709203207358,81.1702324424627,0.05796480856042814
0.059949281458066314,76.4281057739381,0.19033896862936053,30.815812248051845,81.00991579828677,0.05822105929816936
0.06027207773619571,76.2720061470198,0.19136384681242136,30.752872878478385,80.86907843060858,0.058525552297660974
0.06058010746012731,76.1004905421249,0.1923418411859042,30.68371778658476,80.71066643693523,0.05881602961451263
0.06085487350207281,75.904710545988,0.19321422336908117,30.60477929214236,80.52388210447555,0.059075067526065624
0.06117707396828131,75.702949678935,0.19423720984929313,30.523429310546593,80.33423463106028,0.05937873917348692
0.061502162638455114,75.5116551327009,0.19526936637709497,30.446299349505004,80.1557852277712,0.05968503950102496
0.06183844293086531,75.3122744732573,0.19633705630549733,30.365909067617345,79.9694682602655,0.06000178594701652
0.06219341372317121,75.0801298449672,0.1974640885710686,30.272308353490775,79.74961942280467,0.06033602838740039
0.062496637627710815,74.8468071379139,0.19842682446798182,30.178232638006886,79.52448092120326,0.06062145722574352
0.06280445198920771,74.6273564498155,0.19940413506573448,30.08975012056561,79.31428667504942,0.060911123819482244
0.06316333576742121,74.4153037423233,0.20054359106156233,30.004250468904758,79.11562255883432,0.06124874302866253
0.06345399538803412,74.1842511254002,0.2014664353570083,29.91109005376136,78.89153825417611,0.061522096977362745
0.06376320549958421,73.9469789662906,0.20244817746117985,29.815421919208372,78.66207538219162,0.061812814929059275
0.06408248618325542,73.7071738080509,0.20346189363183595,29.71873247940612,78.43051275521212,0.062112912522898245
0.06440047255305911,73.4800356001179,0.20447150035596268,29.627150353967536,78.2121846159811,0.06241170408321052
0.0647073114540049,73.2360937807249,0.20544571386646557,29.528793012388277,77.97500451066898,0.06269993646428101
0.0650249718535647,72.9496471929227,0.20645428563506793,29.413297748186434,77.69319594836998,0.06299824663632027
0.06533581862248641,72.645711785222,0.20744122412639435,29.290750991801517,77.39207883412269,0.06329007210787173
0.06566960100278561,72.3485555297943,0.2085009831838443,29.17093758961306,77.09965630456377,0.06360333492734163
0.06598848534272761,72.0814959357856,0.20951344096316016,29.063259161308753,76.83804467382608,0.06390252394303188
0.06628225974283052,71.803489081851,0.21044617468348686,28.951166797802323,76.56278659561575,0.06417807469345951
0.066596557342201,71.4678510207589,0.21144406956148817,28.815837531569986,76.22736385938674,0.06447279148573831
0.06691823893883,71.1116990365383,0.21246540863078525,28.672237051532242,75.87036870401154,0.06477434233472
0.06723538169999502,70.8114671070302,0.21347233689748416,28.551183537554575,75.57250312670801,0.06507154939651022
0.06753995271131871,70.5423249134588,0.2144393498584369,28.442665405106588,75.30675020226029,0.06535689184775617
0.06784819387855931,70.2548685036493,0.2154180155644258,28.3267629806714,75.0215344427976,0.0656455898719292
0.06815161691827641,69.9522152562147,0.2163813837155276,28.204733191305767,74.71957183294104,0.06592969386877803
0.06847657139791581,69.6448860972332,0.2174131141883827,28.080818074404423,74.4139291125701,0.06623386890861133
0.06876276017137621,69.3707796725918,0.21832176354411945,27.970298363989013,74.1409059581196,0.06650168053919818
0.06905640828281621,69.0546765649053,0.21925409629794146,27.842845590969816,73.82334450360922,0.06677639798735266
0.06935358762915302,68.7175105260559,0.22019764072256082,27.706900244105743,73.48331641398197,0.06705434220648573
0.06962442304401022,68.3303420194797,0.22105754316473242,27.550793902254217,73.08780265898586,0.06730758035568878
0.06995939846893431,67.9404320692974,0.22212109013886644,27.393582210340714,72.69350382858495,0.06762070239773549
0.07024208505149261,67.5356995276744,0.22301862003848902,27.230394049558317,72.27954787790935,0.0678848705953364
0.070514854512513,67.1274533283759,0.2238846630772288,27.06578918200117,71.86093593362183,0.0681397051890778
0.07080459747750431,66.7267411068034,0.22480459699107616,26.904222014263134,71.45130115185626,0.06841032615269937
0.07107713188545091,66.3525069317859,0.2256698937363066,26.753330794896073,71.06865281790674,0.0686648074395802
0.07134855103848112,65.9616329141754,0.22653164954717753,26.59573039099552,70.66789984673399,0.06891818300041817
0.07165061095835651,65.5114686558997,0.2274906897927819,26.414224162058762,70.20540540987415,0.06920008691081865
0.07188744695172401,65.090935632083,0.22824264407172373,26.244665246855867,69.77015681437246,0.06942106362122256
0.07218105906469861,64.6842495138058,0.22917486253041808,26.0806894039665,69.3532271485175,0.06969494676813309
0.0724424584631325,64.2767549030506,0.2300048056204457,25.91638757691,68.93312105025979,0.06993871859809954
0.07271475508807251,63.8659664160984,0.23086934740463022,25.750757658970876,68.50996452250806,0.07019258961947022
0.07298635101636822,63.4063121327578,0.23173166447696908,25.565425051927946,68.03410748673267,0.07044574317284588
0.07325758663083341,62.9395266558478,0.23259283755289606,25.377217147637836,67.55032448234222,0.07069849693596797
0.07350746845264121,62.5513262943861,0.23338621233713583,25.220694761896475,67.14931593864155,0.07093129541789273
0.0737587541602149,62.1056763523675,0.23418404445868232,25.041008705274578,66.68651366639565,0.07116534716804337
0.07401196265688362,61.6333467527941,0.23498798143560548,24.85056541072658,66.19495171108065,0.0714011344388718
0.07429957935839711,61.1065793216868,0.23590116446291082,24.63817278250412,65.64677246131866,0.07166889514080627
0.07457525161014061,60.6093077377712,0.23677642386219644,24.437672879869353,65.12926211223193,0.07192546871994904
0.07484738908470472,60.1956838273706,0.23764046034393746,24.27089971919583,64.70117359601768,0.0721786878596994