File: example/data/02 processed data/test_ID_073.csv
Strain,Stress_MPa,Displacement(mm),Force(kN),True Stress (MPa),True Strain
0.0008311687471325139,35.9240131779057,0.0026389607721457316,14.48456211333158,35.95387209493075,0.0008308235176721255
0.0008843811669336139,38.1542986524448,0.002807910205014224,15.383813216665745,38.188041595610585,0.0008839903323236699
0.0009349361425660139,40.3877158541772,0.002968422252647094,16.28432703240425,40.42547578944496,0.000934499361990882
0.000986656017953414,42.6215995918444,0.0031326328570020893,17.18502895543166,42.663652449576496,0.0009861695928344522
0.001039009566072714,44.8245663430166,0.0032988553722808666,18.073265149504294,44.87113949624205,0.0010384701692267408
0.001085871960812014,47.0363340576239,0.003447643475578144,18.965049892033957,47.08740949391646,0.0010852828282974455
0.0011323884056848139,49.2466087732997,0.003595333188049284,19.85623265739444,49.30237506209388,0.001131747737545363
0.0011806203094583139,51.4134073855821,0.0037484694825301464,20.7298858578667,51.47410709851997,0.001179923925357122
0.001230301416508814,53.6138106995433,0.003906206997415484,21.61708847405586,53.679771846791375,0.0012295452158938842
0.001285864792814714,55.7810268205277,0.004082620717186717,22.490910014036768,55.852753679023266,0.001285038776702839
0.0013338777909671139,57.9376099077981,0.004235061986320586,23.360444314824196,58.014891598915824,0.0013329889662876408
0.001390335852471714,60.0918208946391,0.004414316331597692,24.229022184718485,60.17536870766922,0.0013893702305025533
0.001455395902403614,62.22806899666,0.0046208819901314745,25.090357419453312,62.31863547329222,0.0014543378402622688
0.0015082652780301139,64.3564951099115,0.004788742257745612,25.94853882831632,64.4535617769015,0.0015071289883629398
0.001570023090812114,66.4948647822696,0.0049848233133284615,26.810729480211105,66.5992632553982,0.0015687918930635146
0.001620455666649314,68.5997279784036,0.005144946741611572,27.659410320892334,68.71089079633681,0.0016191441450160813
0.001670545337761814,70.690620915844,0.005303981447393759,28.5024583532683,70.80871280303845,0.0016691515289637606
0.0017225766995481138,72.7882535433501,0.0054691810210652616,29.348223828678762,72.91363689290468,0.0017210947658907265
0.001771663128828414,74.8430306179262,0.005625030434030214,30.176709945147845,74.97562725572176,0.0017700955848742555
0.001821237298636714,76.8476631393119,0.005782428423171566,30.98497777777056,76.9876209697343,0.0018195808568652577
0.001873657843500314,78.8467061053675,0.005948863653113497,31.79099190168418,78.99443785469599,0.0018719047361171253
0.0019219195106588139,80.8379810530253,0.006102094446341733,32.593873960579806,80.99334514601338,0.001920074986329466
0.001980156572399214,82.7519767860992,0.006286997117367504,33.3655970401552,82.91583865681122,0.0019781986466138853
0.0020280991165543137,84.6400206825184,0.006439214695059946,34.12685633919142,84.81167903368974,0.002026045299967857
0.002088947157357914,86.5023059288554,0.006632407224611376,34.8777297505145,86.6830046749304,0.0020867683410053833
0.002137202511258214,88.3483641248876,0.006785617973244829,35.62206041515468,88.53718247056086,0.002134921942750973
0.002193214268100614,90.2056652571407,0.006963455301219449,36.370924231679126,90.40350560924617,0.0021908126845050467
0.002248321370873114,92.0254615822257,0.007138420352522137,37.104666109953406,92.23236439416547,0.0022457976783863097
0.002305469366200914,93.7692780698411,0.0073198652376879015,37.807772917759934,93.98546026792191,0.002302815849320436
0.002365059073268414,95.5276875117491,0.007509062557627214,38.516763604737235,95.75361613584711,0.0023622667229074986
0.002431009810239214,97.2750940705612,0.007718456147509504,39.221317929250276,97.51157077853867,0.002428059686110192
0.002476955066295514,98.9668112267253,0.007864332335488257,39.90341828661564,99.21194757118845,0.0024738924693295077
0.002536998670257514,100.642624020069,0.008054970778067607,40.57910600489182,100.89795422337913,0.002533785921809474
0.002590466979379414,102.297601374213,0.00822473265952964,41.24639287408269,102.56259993264263,0.002587117503018808
0.002637720529840314,103.896598566549,0.008374762682242997,41.89110854203256,104.17064875756856,0.002634247850341723
0.002688404428650714,105.508541388828,0.008535684060966017,42.54104388797545,105.7921910187582,0.0026847971332643883
0.002733106439168814,107.039574525271,0.008677612944360985,43.15835644858927,107.33212507565192,0.002729378295163019
0.002779290430662614,108.547732353867,0.008824247117353799,43.766445685079184,108.84941802766825,0.002775435344298249
0.002842036919035114,110.055966956561,0.009023467217936487,44.37456587688539,110.36875007781165,0.0028380059677128324
0.002893829400719714,111.523980683805,0.009187908347285091,44.96646901171017,111.84671205799309,0.002889650336810209
0.002948103356558214,112.952608537458,0.009360228157072329,45.54249176230307,113.28560450181928,0.0029437662219807784
0.003005144403383514,114.389358527895,0.009541333480742657,46.121789358447266,114.73311506848174,0.003000637982979735
0.003056158661317514,115.774734273851,0.009703303749683107,46.680372859216725,116.12856023076377,0.003051498101628182
0.003111006557483214,117.184652564457,0.009877445820009203,47.248851913989064,117.54921478702143,0.003106177389705759
0.0031654304322319138,118.541818625123,0.010050241622336326,47.79606126964959,118.91705450529108,0.003160431004769535
0.003202090112522314,119.862830583549,0.010166636107258346,48.32869329128695,120.24664216821951,0.003196974339845498
0.003258066082897714,121.214102743865,0.01034435981320024,48.87352622632637,121.60902630078367,0.0032527700856191948
0.003302444563614014,122.53007677328,0.010485261489474493,49.404126954986495,122.93472555919914,0.0032970034695495834
0.003360977546472414,123.786950183428,0.010671103710049914,49.91089831395817,124.2029953435408,0.0033553420850145096
0.003426188534270414,125.036288524485,0.010878148596308564,50.41463153307235,125.4646864225953,0.0034203325223892828
0.0034859937073394138,126.260354477316,0.011068030020802639,50.90817492525382,126.70049727851037,0.003479931715234923
0.003554825041325914,127.482450853558,0.011286569506209775,51.40092418415459,127.93562866218184,0.003548521584828503
0.003633060261802214,128.699530736603,0.01153496633122203,51.891650792998334,129.16710388743476,0.0036264766393490065
0.003695681956261214,129.865010980468,0.011733790211129354,52.3615724273247,130.3449507582982,0.003688869702490373
0.0037689458316630137,130.967621819192,0.011966403015530067,52.80614511749822,131.46123169153026,0.0037618611509274997
0.003835027227474814,132.070654938768,0.012176211447232535,53.25088807131126,132.5771494964086,0.0038276922577816464
0.003908595804996414,133.182567210422,0.012409791680863614,53.699211099242156,133.70312403391932,0.0039009770902778693
0.003978868732859114,134.250030699524,0.012632908226827685,54.12961237804808,134.7841939490597,0.003970973969218904
0.004046445248949013,135.26069721198,0.012847463665413117,54.53711311587033,135.80802221758293,0.004038280407683595
0.004115922622165414,136.21519917422,0.01306805432537519,54.92196830704551,136.77585039398394,0.004107475383503963
0.004192529981586114,137.115160329647,0.01331128269153591,55.28483264491368,137.69001975025904,0.004183765815243727
0.004269069401680414,137.994504663185,0.013554295350335314,55.639384280196204,138.58361278064268,0.004259982776678178
0.004345040411672714,138.81211060663,0.013795503307060865,55.96904299659322,139.41525483684538,0.004335627978668244
0.0044137040918583136,139.549604093055,0.014013510491650144,56.26640037031977,140.16553475165773,0.00440399226621674
0.004495333774094714,140.282802769014,0.014272684732750717,56.56202607646645,140.91342079022624,0.004485259940106038
0.004577050592650414,141.006439004983,0.014532135631665064,56.85379620680915,141.65183261019828,0.004566607749410024
0.004667193550881114,141.718293626949,0.014818339524047536,57.14081599038584,142.37972033300656,0.004656335972898987
0.004755912997470714,142.3699653154,0.015100023766969516,57.40357001516928,143.047064483893,0.004744639373370747
0.004849179595349114,142.999564318751,0.015396145215233437,57.65742433332041,143.6929948881893,0.004837460195022794
0.004948705873629114,143.616291854787,0.015712141148772434,57.906088875850116,144.3270066418376,0.004936501276796096
0.005047125951735814,144.184706581477,0.016024624896761208,58.13527369365153,144.91242495590777,0.005034431905931733
0.005151061088466014,144.705194545534,0.016354618955879596,58.34513444075931,145.4505798424564,0.005137839756454062
0.005257266250867714,145.174615377042,0.01669182034650499,58.53440492002333,145.9378369829464,0.0052434950714029685
0.0053553425501122135,145.5562756742,0.01700321259660628,58.688290351837445,146.3357793907539,0.005341053694971839
0.0054643187872531135,145.916276629045,0.017349212149528635,58.833442736830946,146.71360968079512,0.005449443561395876
0.005577602700860314,146.251404346357,0.017708888575231497,58.96856623245114,147.06713657424385,0.005562105473130759
0.005696139679447714,146.553653381627,0.01808524348224649,59.090433043472004,147.3884434618221,0.005679978019494731
0.005815923397923914,146.839788841165,0.018465556788408426,59.20580286075772,147.6937978048325,0.0057990762051993
0.005934631030411614,147.092749123594,0.018842453521556873,59.307796446633105,147.96569031689143,0.0059170904712963065
0.006058088755383014,147.31382900487,0.019234431798341067,59.39693585476359,148.2062692558768,0.0060398123120984385
0.006191051628503014,147.532842032314,0.019656588920497067,59.485241907429,148.44622547423583,0.006171965802086553
0.006324313008292014,147.704569956966,0.020079693801327143,59.55448260664869,148.638699890129,0.006304398460564844
0.006455602059884614,147.846250592222,0.02049653654013365,59.61160823878391,148.80068715209137,0.006434853907577305
0.006581671942100514,147.9711637895,0.02089680841616913,59.661973239926404,148.9450614464533,0.006560107308504205
0.006714005640044714,148.082559693704,0.021316967907141965,59.706888068501456,149.0767868346798,0.006691567083248957
0.006846334671171914,148.173319205543,0.021737112580970826,59.743482303674945,149.18776333816257,0.006823004943509266
0.006983194343287614,148.264917247834,0.022171642039938173,59.780414634326675,149.3002799792671,0.0069589247622968125
0.0071220631960014135,148.339194251681,0.022612550647304486,59.81036312227778,149.3956753675854,0.007096821083667288
0.007259441159396114,148.421136276321,0.023048725681082658,59.843402146612625,149.49859078192964,0.007233218249060822
0.007404167066642714,148.481672721988,0.023508230436590616,59.86781044150556,149.58105583315614,0.0073768907777199
0.007553226332821514,148.530176106436,0.023981493606708305,59.88736700611499,149.65205814382173,0.007524843550258915
0.007693367542399814,148.561928716569,0.024426441947119407,59.900169658520625,149.70487023699337,0.007663924504649413
0.007845307566702913,148.580738463673,0.02490885152428175,59.90775374855295,149.74640005540834,0.007814693156689957
0.007994502923191914,148.577581772074,0.025382546781134326,59.90648097050024,149.76538568387164,0.007962716185092296
0.008151791373192415,148.561091398585,0.025881937609885917,59.89983205190947,149.77213042184002,0.008118744991895233
0.008309704050391714,148.551978069188,0.02638331035999369,59.89615755749661,149.78640104304324,0.008275368540503062
0.008461511681932614,148.549864053459,0.02686529959013605,59.895305186354676,149.80682046349685,0.008425913759160974
0.008618714310460815,148.542861195653,0.027364417935713085,59.89248163408729,149.82310967915674,0.0085817852280502
0.008788994148909515,148.49122022375,0.02790505642278771,59.871659994215996,149.79630868946094,0.008750595764600641
0.008946719621715215,148.447339124946,0.028405834798945803,59.85396713517824,149.77545584668658,0.008906934845135925
0.009117368313782013,148.400323050157,0.02894764439625789,59.835010253823306,149.75334345328952,0.009076056027653026
0.009271396831645315,148.360268205104,0.029436684940473874,59.81886014029794,149.73577512568286,0.009228681251120611
0.009424948994085315,148.278402488227,0.029924213056220873,59.78585188325313,149.675918868603,0.009380811276078276
0.009586459966565314,148.194641528378,0.03043701039384487,59.752079464242016,149.6153035266493,0.009540801429781883
0.009745775088651813,148.098269812929,0.030942835906469505,59.71322238857298,149.5416022415443,0.009698591336416673
0.009906481460574714,148.036977144735,0.031453078637324716,59.68850918475716,149.50350271429883,0.00985773395291507
0.010066194764670114,147.967148825982,0.031960168377827614,59.660354406635946,149.45661496483726,0.010015868076517817
0.010217475123322713,147.896266888057,0.032440483516549615,59.631774809264584,149.407393315818,0.010165629579013817
0.010382384333420813,147.805286613771,0.03296407025861108,59.59509156267246,149.33985790590657,0.010328857552818222
0.010549273429145915,147.751330278724,0.03349394313753828,59.57333636838152,149.3099994613543,0.010494018106826554
0.010715544640895113,147.689051516501,0.03402185423484198,59.5482255714532,149.27162014099753,0.010658540054309888
0.010883418370272313,147.615289764933,0.034554853325614594,59.518484833220995,149.22184872129375,0.010824620204561984
0.011047201599203414,147.538596871907,0.03507486507747084,59.48756225875291,149.16848549521455,0.01098662697934603
0.011218437571143014,147.44551288787,0.03561853928837907,59.450030796389186,149.09962116934773,0.011155977601768896
0.011390401537646713,147.359926821662,0.036164524882028315,59.41552249449412,149.03841555871895,0.011326019345474291
0.011557568399142813,147.253645138687,0.03669527966727843,59.372669719918605,148.9555392144005,0.011491289895543785
0.011723630573002113,147.134057847121,0.03722252706928171,59.32445212395919,148.85900318602737,0.011655441249608194
0.011889404195042514,147.008869124256,0.03774885831925998,59.27397603090002,148.7567169895304,0.011819280501049098
0.012054993566880515,146.89056471713,0.03827460457484563,59.22627569394681,148.66132952983045,0.011982910858079211
0.012223632268459414,146.768253040995,0.03881003245235864,59.17695962612918,148.56229419485234,0.012149526955109277
0.012389690117802015,146.66216146679,0.03933726612402139,59.13418350340973,148.47926019937057,0.012313566031488747
0.012555795259462214,146.54134757728,0.039864649948792526,59.0854713431593,148.381290734506,0.012477624909352092
0.012723666174252213,146.457739714836,0.040397640103250775,59.05176065302189,148.3212191036031,0.012643400466129526
0.012888835612866814,146.392016735103,0.04092205307085213,59.02526114759353,148.2788393738378,0.012806481449126031
0.013062548798898914,146.313637812018,0.04147359243650405,58.99365876580565,148.22486684588188,0.012977969459938433
0.013234191365210615,146.239310102136,0.042018557584543696,58.963689833181235,148.17466911714402,0.013147384495081082
0.013405892567680313,146.139519584371,0.04256370890238499,58.923454296418385,148.09865028381148,0.013316828694119522
0.013589321965783314,146.069095695105,0.04314609724136202,58.89505938426635,148.05407566575659,0.013497815207840342
0.013764113915001513,145.97784051701,0.043701061680129806,58.85826529645844,147.98709614295205,0.0136702488314581
0.013939085812272115,145.883111509204,0.04425659745396396,58.820070560511056,147.91658871909206,0.013842830201086929
0.014119936879595714,145.764721374371,0.04483079959271639,58.77233565814639,147.82291003944897,0.014021179120698654
0.014296414150646515,145.666883769531,0.04539111492830268,58.73288753587491,147.7493978679343,0.014195184098923662
0.014459705057121413,145.55714028826,0.045909563556360486,58.68863896422643,147.66185360578626,0.014356160477781075
0.014635327519570513,145.46901576479,0.046467164874636376,58.65310715636332,147.59800245445726,0.014529264704116598
0.014802589504790013,145.364862305183,0.04699822167770829,58.611112481449794,147.51663869030696,0.01469410047878618
0.014971057245471113,145.28187390509,0.04753310675437078,58.57765155853229,147.45689715605243,0.01486009705809697
0.015145504916184214,145.192582598767,0.048086978108884876,58.54164930382285,147.39159757231008,0.015031956816688055
0.015324138868864214,145.074786946334,0.04865414090864388,58.49415409676187,147.29793312787052,0.015207910152102629
0.015494116592457514,144.94459346634,0.0491938201810526,58.441660085628286,147.19038189695382,0.015375308414879817
0.015681572945453012,144.832125584954,0.04978899410181331,58.39631303585345,147.10332112715946,0.015559887577079407
0.015855956648143012,144.725525691301,0.05034266235785406,58.35333195873256,147.02028735254197,0.015731564152656495
0.016031950716068014,144.58702626126,0.050901443523515943,58.29748898854004,146.90503834046336,0.015904796217011193
0.016209517869637112,144.457571423006,0.05146521923609783,58.24529279775601,146.79915900839157,0.01607954627183075
0.01638446725951681,144.328958985776,0.05202068354896587,58.19343626306489,146.6937120888786,0.01625169023328268
0.016556507714206012,144.238498891362,0.05256691199260408,58.15696275299716,146.62658471094235,0.01642094301259875
0.01673835334196421,144.171135955354,0.05314427186073637,58.129802017198735,146.5843233706871,0.01659981094929202
0.016918580535495713,144.096371166293,0.05371649320019888,58.099656854249346,146.5342772267426,0.01677705539106676
0.01709458405190791,144.008662457179,0.05427530436480762,58.06429270273458,146.47043064175608,0.016950115742804653
0.01727469906586481,143.919479386944,0.05484716953412077,58.028334088815825,146.4056450830694,0.017127187836767314
0.017459732265614213,143.836371962906,0.05543464994332512,57.994825175443694,146.34771650743562,0.017309062382565868
0.017642974557355612,143.752287693795,0.05601644421960406,57.960922398138145,146.2885056481383,0.017489143998714516
0.01782453017671431,143.65520954473,0.05659288331106794,57.92178048843515,146.21579616230227,0.017667536057951964
0.01800541034375681,143.538589473317,0.05716717784142787,57.87475927564141,146.1230606769481,0.017845232793733484
0.018185593351771112,143.426591516559,0.05773925889187328,57.82960169947659,146.03488918570974,0.01802221325200843
0.018375456474743312,143.316408329094,0.05834207430731001,57.785175838290705,145.9499127524618,0.018208667886931776
0.01855579107531291,143.223827255033,0.05891463666411849,57.74784714922931,145.8814586705841,0.018385732872564058
0.018736495637678013,143.113847591208,0.05948837364962769,57.70350334877508,145.795299572292,0.01856312966930021
0.01891828431673691,143.009034890971,0.060065552705639694,57.66124286803951,145.71452047290055,0.018741558990428963
0.019098892192084414,142.902024452535,0.06063898270986801,57.61809625926211,145.63129481158458,0.018918797806570704
0.019279539663022514,142.792231337796,0.061212538430096476,57.57382767539935,145.54519982544454,0.01909604406132682
0.01947126945147251,142.685384007398,0.06182128050842522,57.53074683178287,145.46364956619286,0.019284129616616873
0.01964343089252371,142.584678480428,0.06236789308376278,57.49014236330858,145.385530758491,0.019452988623352773
0.019826647540109214,142.475254297949,0.06294960593984675,57.44602253293304,145.30006094810184,0.019632659460415657
0.020005398065101713,142.345374240939,0.06351713885669794,57.393654893946604,145.19305011535488,0.01980791950286402
0.020188380415702614,142.217773328478,0.0640981078198558,57.34220620604233,145.08891983830748,0.019987296925755356
0.020372582696844513,142.105106260358,0.06468295006248133,57.29677884417635,145.00015428929106,0.02016783775249095
0.020555520851569413,142.003580980645,0.06526377870373289,57.255843851396065,144.92253855049017,0.020347107325874324
0.020727473330757213,141.893180559325,0.06580972782515415,57.211330401519845,144.83426767518472,0.020515582231200705
0.020913041700365013,141.788595865256,0.06639890739865892,57.16916185287122,144.75382668322234,0.020697365820184888
0.021092953989690213,141.645204064546,0.06697012891726642,57.11134627882495,144.63291983673975,0.020873577143922805
0.021272188314065313,141.529877509985,0.06753919789715737,57.06484661202595,144.54052771644402,0.02104909357937579
0.021446998025030712,141.396839828709,0.06809421872947251,57.01120581893547,144.42937757326092,0.02122024751238927
0.021623825530413112,141.269658741074,0.06865564605906163,56.95992640440104,144.324449194432,0.021393347244209826
0.02178902663438251,141.136313497075,0.06918015956416447,56.906161602020646,144.21153639094135,0.02155503860692623
0.021966314542215613,141.011191708663,0.06974304867153457,56.85571249693293,144.10868789970814,0.02172853090779589
0.02214699808979701,140.889378465698,0.07031671893510551,56.80659739736944,144.00965526145052,0.021905315185786246
0.022328577539892914,140.807989466378,0.07089323368915999,56.773781352843606,143.95203157741443,0.022082944552199592
0.02251040042776901,140.719736203675,0.0714705213581666,56.73819763732177,143.88739381370976,0.022260780450589934
0.022695523093343512,140.635713459544,0.07205828582136564,56.70431966688814,143.82751454211393,0.02244181128367233
0.02288381493373151,140.549692008502,0.07265611241459755,56.66963581782801,143.76600514941754,0.022625907629797482
0.023076657981560812,140.458380559455,0.07326838909145557,56.632819041572255,143.69969056826946,0.022814418650370222
0.023256412153569113,140.324937245446,0.07383910858758193,56.57901469736383,143.58839182144982,0.02299010282915232
0.023436080430322814,140.191237245737,0.07440955536627493,56.52510685748116,143.47677035745457,0.023165672220124514
0.023614408632116512,140.077969974855,0.07497574740696993,56.47943749386153,143.38582839819858,0.02333990163283093
0.02379777989416891,139.972755030578,0.07555795116398628,56.437014828329055,143.30379584597614,0.023519026543359616
0.023977529087371812,139.880672420776,0.0761286548524055,56.39988712005688,143.23466531250628,0.023694582125924003
0.02415375234421501,139.773648085591,0.07668816369288266,56.35673490811028,143.1497061656978,0.02386666411976463
0.024339035087108312,139.671224133903,0.0772764364015689,56.31543757078969,143.07068695875742,0.024047560771717984
0.024528798787508212,139.61301862693,0.07787893615033857,56.291969110378176,143.0375582689466,0.0242327983920322
0.024713960574351414,139.546597374424,0.07846682482356573,56.265188061367766,142.9953464802204,0.024413510790796216
0.024900659288430212,139.459582896523,0.07905959324076592,56.230103823878075,142.9322184547359,0.024595690126156054
0.02508844042650651,139.384445615521,0.07965579835415816,56.19980847217806,142.88138397572766,0.02477889221111124
0.025274558590761713,139.269492299035,0.08024672352566843,56.15345929497091,142.78946724205258,0.02496043876150789
0.025462098444739813,139.158308079313,0.0808421625620489,56.10862981757901,142.7015706190319,0.025143338749039235
0.025644188173066414,139.063323769265,0.08142029744948585,56.070332143767644,142.6294898119761,0.025320891448275797
0.025824906627609213,138.898643112946,0.08199407854265925,56.00393290313982,142.48568760203943,0.025497075876760054
0.026019863461166113,138.729053577738,0.0826130664892024,55.93555440254396,142.33876460992755,0.025687106659775975
0.026203528317073312,138.568208128779,0.08319620240670776,55.87070151752369,142.19918409432756,0.025866097755124974
0.02638362804345291,138.412391499777,0.08376801903796299,55.80787625271009,142.06421255371188,0.02604158333807188
0.02656720693272271,138.311146673246,0.08435088201139461,55.76705433865278,141.98568752801629,0.026220427260324256
0.02675022136011721,138.235410883828,0.08493195281837214,55.73651766835945,141.93323872477714,0.026398689447511982
0.026939657368532113,138.144447723994,0.08553341214508946,55.69984132231439,141.86601181304349,0.026583173006509184
0.02711463614846091,138.11581728121,0.08608896977136339,55.68829752778388,141.86077741313733,0.026753547062252806
0.027245392583692813,138.086709359191,0.08650412145322468,55.67656121362581,141.84893596627245,0.02688084357657336
0.027427668208816813,138.037131696981,0.08708284656299338,55.65657150022274,141.82316834566254,0.027058269006516773
0.027612994157717213,137.969520236117,0.08767125645075215,55.62931055920238,141.77927179233996,0.027238631325177072
0.027801833279964713,137.886995744945,0.08827082066388796,55.59603668436183,141.72050701212117,0.027422379267692667
0.027991135835073913,137.777836890885,0.08887185627635967,55.552023834404835,141.63439503836042,0.027606544267270147
0.02818175466160961,137.647740983478,0.08947707105061051,55.499569164538336,141.52689584959919,0.02779195555049715
0.028380486938643413,137.518124715987,0.09010804603019283,55.44730788548596,141.42095605831582,0.02798522203534496
0.028618308222505114,137.407262561971,0.09086312860645374,55.40260826498671,141.33962595398017,0.02821645336662306
0.028813779890746113,137.305846761904,0.09148375115311891,55.3617174143997,141.26214720821403,0.028406468551044985
0.029010330207126813,137.201251279978,0.09210779840762763,55.319544516087134,141.18150488444115,0.028597495875502664
0.02920437420969591,137.086034655852,0.09272388811578451,55.273089173239526,141.08954651086484,0.028786051523004036
0.02939213637492511,136.958727922331,0.09332003299038723,55.22175909828387,140.98423753116043,0.02896846916996357
0.02958116544701491,136.804137906817,0.09392020029427234,55.15942840402862,140.8509637440748,0.029152084054579544
0.02978409110782841,136.658850863135,0.0945644892673552,55.100848668016035,140.72911052793376,0.02934915998448025
0.02997044158186261,136.502323043912,0.09515615202241379,55.03773665130532,140.59335794248813,0.029530104336426263
0.030158974947509014,136.355132720771,0.09575474545834112,54.97838951301486,140.46746375246101,0.029713134940872788
0.030347299990901713,136.201999796481,0.09635267747111294,54.916646317941144,140.33536274366557,0.029895929864826844
0.03053001064437441,136.046135228358,0.09693278379588875,54.853801724073946,140.19962518500577,0.030073243335171203
0.030726130635961312,135.913292272556,0.09755546476917716,54.800239444294576,140.08938184608616,0.0302635350589906
0.030911454759989514,135.830460047672,0.09814386886296671,54.766841491221356,140.0291771684642,0.0304433184756688
0.031088431685710512,135.732872351147,0.09870577060213087,54.72749413198247,139.95259448074088,0.030614974087600534
0.03126849530824311,135.610557115329,0.09927747260367187,54.678176628900644,139.85089518423788,0.030789593350283296
0.03146360743622362,135.498127628765,0.09989695361000998,54.63284505991805,139.76138752481978,0.030978771700979152
0.03164520939075632,135.395127226252,0.1004735398156513,54.59131529762481,139.6797343778148,0.031154818600222185
0.031836714336617014,135.303130623958,0.10108156801875902,54.55422226757986,139.6107377424829,0.03134043199882625
0.03202008752851351,135.206003603105,0.1016637779030304,54.515060652771936,139.53531167285692,0.03151813152934926
0.03221054167985882,135.107479477106,0.10226846983355174,54.475335725169145,139.459364576064,0.0317026595071739
0.03240655905056791,135.003798102806,0.10289082498555312,54.433531395051375,139.37880665807555,0.03189254204881205
0.03260762645550592,134.927999731385,0.10352921399623129,54.40296949169443,139.3276815450146,0.03208727911840182
0.03279539528705282,134.829662916151,0.10412538003639268,54.36332008779208,139.25145500790626,0.0322691020653884
0.03299478211371162,134.720186628636,0.10475843321103438,54.31917924866603,139.1652498327664,0.032462138927949906
0.03318841239686532,134.61113554433,0.10537320936004738,54.27520985147387,139.07866542398557,0.03264956692004185
0.03338236310455642,134.509692603632,0.10598900285696662,54.23430805778443,138.99994400320873,0.03283726986306205
0.033579462261588214,134.399080047041,0.10661479268054257,54.189709074966935,138.91212888347277,0.03302798374583459
0.03376732265545822,134.292385798504,0.10721124943107983,54.14668995395681,138.82708011993336,0.03320972431858974
0.03395933056619382,134.16990220062,0.10782087454766537,54.097304567289974,138.72622226148474,0.03339544317169667
0.03414854323918801,134.051629084496,0.10842162478442194,54.04961684686879,138.6292969365715,0.033578424606967625
0.034336231474773715,133.931331659732,0.10901753493240654,54.00111292520394,138.53002886532525,0.03375989873565861
0.034521783020880215,133.800510074666,0.10960666109129467,53.948365662105324,138.41954225154672,0.03393927455101556
0.03470917134242542,133.600945702799,0.1102016190122007,53.86790130736857,138.23812381870755,0.034120393359104544
0.03489987606126182,133.409216252693,0.11080710649450627,53.790595993085816,138.06518136534206,0.03430468393283903
0.035085436473777015,133.247930491307,0.11139626080424202,53.72556557409498,137.92299229182197,0.034483970628148924
0.035272034440519115,133.105529416876,0.11198870934864819,53.66814946088441,137.80043223469158,0.034664227390441275
0.035464045710475615,132.973569883932,0.11259834513076007,53.61494337720138,137.68935064458086,0.03484967958045943
0.035659762085112214,132.860045461017,0.11321974462023127,53.569170329882056,137.59780307277407,0.03503867492152264
0.035848950748938416,132.753636593255,0.11382041862787946,53.52626627440043,137.51271517322905,0.0352213327719869
0.03604570496502402,132.684280655155,0.11444511326395125,53.4983019601585,137.46697908914715,0.0354112596257818
0.036234250272185714,132.628926593183,0.11504374461418963,53.47598320237138,137.43463631269174,0.03559322857954743
0.03643541297791172,132.545671776558,0.11568243620486969,53.44241486030819,137.37502806617164,0.03578733834042663
0.036633863320929314,132.455518794078,0.11631251604395057,53.40606517777224,137.30787616568304,0.035978793923597666
0.036820267989868614,132.335435059032,0.11690435086783284,53.3576474158017,137.2080612424614,0.036158595026141084
0.037013146685927215,132.211815067717,0.1175167407278189,53.307803835303496,137.1053903724311,0.036344606781231685
0.037217784957788415,132.076783467225,0.1181664672409782,53.25335909398512,136.99238879222455,0.03654192162154506
0.03741495370074181,131.954148326382,0.11879247799985525,53.20391260519723,136.8912066766344,0.03673199742616627
0.03761102179193462,131.794246255271,0.1194149941893924,53.13944009012526,136.75116252322957,0.03692097635374787
0.03780410463212031,131.648443648422,0.12002803220698198,53.08065247904375,136.6252951867627,0.03710704307195229
0.03799997915093042,131.501133228768,0.12064993380420407,53.02125691783925,136.49817354978492,0.03729576465788788
0.03820382923051702,131.353156635655,0.12129715780689153,52.961592755496106,136.37135020065293,0.0374921327402684
0.038396764292832015,131.176741993564,0.12190972662974164,52.89046237180501,136.21350443659253,0.037677950912016964
0.03858818947861251,131.02152063973,0.12251750159459472,52.82787712193914,136.07740390395182,0.03786228078496557
0.03878063894230452,130.879049879476,0.12312852864181684,52.77043291140473,135.95462305796383,0.03804756272586083
0.03897136417129091,130.762949692591,0.12373408124384865,52.72362131605269,135.85896022517318,0.0382311507856836
0.03916790970584732,130.632550699266,0.12435811331606524,52.67104444194405,135.74915464969936,0.038420306091695035
0.039363489513761514,130.495720822155,0.1249790792061928,52.615874635492894,135.63248776032864,0.03860849647319703
0.039561270482275715,130.378601074015,0.1256070337812254,52.568651953042846,135.5365441762048,0.038798768841795075
0.03976695084595912,130.290592325697,0.12626006893592018,52.533166825721025,135.47185190640388,0.038996602317284426
0.03997531983358372,130.189562867686,0.1269216404716283,52.49243174825099,135.3939322823162,0.03919698194245191
0.04018189467437812,130.067829476622,0.12757751559115052,52.44334884497399,135.2942013011766,0.03939559658564597
0.040390197038941415,129.942811121059,0.12823887559863897,52.392941444010994,135.1912268660325,0.03959583224783597
0.04058056741023432,129.806831665914,0.12884330152749396,52.338114527696526,135.07446654864157,0.0397787952909276
0.040781917511233716,129.652254288047,0.12948258809816704,52.27578892894056,134.9397218275676,0.03997227442114735
0.040987240548614814,129.47573681934,0.13013448874185202,52.204617085557885,134.78258998956343,0.04016953263995815
0.041186684207701316,129.293191332667,0.13076772235945167,52.131014745331335,134.61834917429147,0.04036110516646525
0.04138627659763541,129.112694030925,0.13140142819749243,52.058238233268966,134.45618769835474,0.04055278382003614
0.04158271809197252,128.927378194708,0.13202512994201274,51.983518888106275,134.2885290165157,0.04074140064094934
0.041786482615496716,128.707422861984,0.13267208230420208,51.89483289795196,134.08565334989171,0.040937011216458236
0.041994534612488615,128.501360236634,0.13333264739465134,51.811748447410835,133.8977150568432,0.041136698223838614
0.04219613932226261,128.32877988478,0.1339727423481838,51.7421640495433,133.74375895985415,0.04133015913211733
0.042391542497874614,128.158702999603,0.1345931474307519,51.67358904943993,133.5915481042832,0.04151763330544053
0.042586022263480114,127.985136087386,0.13521062068654935,51.603606870434035,133.43551394219796,0.04170418664726681
0.04278352959809482,127.801668487688,0.13583770647395105,51.529632734235804,133.2694749541169,0.04189360855095653
0.042987226544368214,127.642083881123,0.13648444427836906,51.4652882208688,133.12906305751608,0.04208892910219281
0.043183327857617214,127.508998105281,0.13710706594793465,51.4116280360493,133.01526097525763,0.042276930330963663
0.043396819274418415,127.376890713416,0.13778490119627845,51.35836233564934,132.90464261944348,0.042481563177528124
0.04360293949713682,127.225287022199,0.1384393329034094,51.29723572735064,132.7726835147338,0.0426790909659452
0.043804339258092316,127.071715308839,0.13907877714444308,51.235315612523884,132.6380078363351,0.042872057392411234
0.044021859754405014,126.908032917862,0.1397694047202359,51.169318872481966,132.49476054467954,0.04308042770331428
0.044231160929582916,126.73936734547,0.14043393595142575,51.101312913693505,132.34519669864102,0.043280883465911586
0.04443608277221352,126.557586692954,0.14108456280177792,51.028018954599055,132.1813100906937,0.04347710605130041
0.04465074329996892,126.337435702089,0.1417661099774013,50.93925407508228,131.97849611279932,0.0436826126160176
0.04484811759217642,126.108171226381,0.14239277335516012,50.846814638476815,131.76388531887605,0.0438715328365438
0.04506254623841281,125.87059481601,0.14307358430696068,50.75102382981523,131.54264431496298,0.04407673648538863
0.04528235718011291,125.643150674512,0.1437714840468585,50.659318351963236,131.33256870059,0.04428704717828023
0.04548999654666151,125.403487373498,0.1444307390356503,50.5626861089944,131.10809158105772,0.04448567173619653
0.04569788287981902,125.146515796044,0.1450907781434254,50.45907516896494,130.86544661770904,0.04468449302421913
0.04591763206327522,124.855759309963,0.14578848180089882,50.34184215377709,130.58884012693875,0.04489461690472653
0.04613162599834972,124.588141921247,0.14646791254476035,50.23393882264679,130.3355954881873,0.04509919520038206
0.04635863213415302,124.282639367924,0.14718865702593584,50.110760193146966,130.0442125270432,0.04531616742838788
0.04656757449596671,123.966573171366,0.14785204902469432,49.98332230269477,129.7393958025333,0.045515832721742366
0.046785845743339716,123.648409451752,0.14854506023510358,49.8550386909464,129.43340486277097,0.04572437012976293
0.04700525169154802,123.311994544184,0.14924167412066494,49.71939620021499,129.10830588432017,0.045933947818081716
0.04723818848981472,122.937044169447,0.14998124845516173,49.56821620912104,128.74436743430402,0.046156402184902766
0.047462222620614315,122.53072615872,0.15069255682045044,49.404388787195906,128.34630676153068,0.046370307839826465
0.04769461062260191,122.048356635009,0.15143038872676107,49.20989739523563,127.86940548184421,0.046592141355345125
0.04793249703120272,121.520665087511,0.15218567807406863,48.99713216328444,127.3454540060479,0.04681917259458969
0.048183301502692115,120.922934609345,0.15298198227104745,48.756127234487906,126.74940082621738,0.047058476618595996
0.048432670301329916,120.175472568319,0.15377372820672247,48.454750539546225,125.99589160952692,0.047296354039323016
0.04869511457025202,119.382666321558,0.15460698876055015,48.13509106085219,125.19601893578844,0.04754664328939674
0.04896254294900262,118.498118494945,0.1554560738630833,47.778441377161826,124.30008771112975,0.04780162138769676
0.04923610120735432,117.525413921193,0.15632462133334996,47.38624689302502,123.31190709545308,0.04806237673673259
0.04950455016733252,116.348250428679,0.15717694678128075,46.911614572843376,122.10801822890691,0.048318195826400887
0.04978475270723511,115.143444126312,0.15806658984547148,46.425836671729,120.87583201799978,0.0485851457329076
0.05007014990286652,113.883712509322,0.1589727259416012,45.917912883758625,119.58588706615872,0.04885697136908289