File: example/data/02 processed data/test_ID_146.csv
Strain,Stress_MPa,Displacement(mm),Force(kN),True Stress (MPa),True Strain
1.03369997106148e-05,12.0791378455429,3.281997408120199e-05,2.435154189661449,12.079262707587315,1.0336946284233947e-05
1.40368949805761e-05,16.4348724575577,4.4567141563329115e-05,3.313270287443632,16.435103152136406,1.403679646429625e-05
4.17351741207153e-05,20.6555929782341,0.0001325091778332711,4.1641675444119945,20.65645504300361,4.173430323250112e-05
8.80727575829981e-05,24.6925434904941,0.00027963100532601894,4.978016767683611,24.694718230891045,8.806887940532749e-05
0.0001558846550905,32.572543096376,0.0004949337799123375,6.566624688229402,32.577620656022,0.0001558725063400945
0.0002420606454905,40.380167852758,0.0007685425494323374,8.140641839116013,40.38994230225345,0.00024203135353929222
0.0003896417940586,47.9347433993002,0.001237112696136055,9.663644269298922,47.953420778716044,0.00038956590340750503
0.000576864580105,54.969792037893,0.001831545041833375,11.081910074839229,55.001502163895395,0.0005766982576936825
0.0007902503542991,61.3039962768595,0.002509044874899642,12.358885649414876,61.35244178163724,0.0007899382708930949
0.0010451434275552,66.9553327522687,0.0033183303824877593,13.498195082857372,67.0253106782345,0.00104459764541036
0.001362929509128,71.8264118493833,0.0043273011914814,14.480204628835676,71.92430618562761,0.0013620015637582738
0.0017610494333339,75.8598122212739,0.005591331950835133,15.29333814380882,75.99340510059899,0.001759500603890876
0.0022480397180906,78.9533167172305,0.007137526104937654,15.916988650193671,79.13080690908583,0.0022455166573898165
0.0028100560607662,81.241192824713,0.008921927992932684,16.37822447346214,81.46948513099396,0.002806115234136862
0.0034371805491346,82.7766148472722,0.010913048243502354,16.687765553210077,83.06113301774846,0.0034312869451305276
0.0041643831878356,83.6552817413752,0.013221916621378029,16.864904799061243,84.00365439023263,0.00415573614226289
0.0049545411861686,84.0765276835305,0.015730668266085306,16.94982798099975,84.49308830272861,0.004942307837433447
0.0057850016450817,84.2252159662416,0.0183673802231344,16.979803538794307,84.71245897916369,0.005768332778449481
0.0066397464216087,84.1968289236335,0.021081194888607623,16.974080711004515,84.75587451719001,0.006617800395806584
0.0075130156995064,84.1182577950526,0.02385382484593282,16.958240771482604,84.75023958648197,0.007484933563697049
0.0084001503495884,83.9754246541256,0.02667047735994317,16.92944561027172,84.68083084689079,0.008365065428788645
0.0093147033963037,83.8040081347493,0.029574183283264246,16.89488803996546,84.58461761394591,0.009271589071262734
0.0102264457409863,83.5846493228216,0.032468965227631506,16.850665303480834,84.4394232039008,0.010174509427220447
0.0111535044443628,83.3330978985722,0.035412376610851885,16.79995253635216,84.26255397634644,0.01109176278009969
0.012084495387775,83.0807908061221,0.038368272856185624,16.749087426514215,84.08478023943138,0.012012060846069195
0.013025368572991,82.80258944838,0.04135554521924643,16.69300203279341,83.88112369474321,0.012941267966786824
0.0139795270241816,82.5037163523663,0.04438499830177658,16.632749216637045,83.65707928470961,0.013882714653706343
0.0149350931227071,82.2146857997168,0.04741892066459504,16.574480657222907,83.44256978818967,0.014824662786654109
0.0159022771395614,81.9021310233759,0.05048972991810744,16.51146961431258,83.2045614092303,0.015777160612565955
0.0168812753020495,81.5948781884795,0.053598049084007164,16.449527442797468,82.97230379041642,0.01674037013578636
0.0178631533042762,81.2810039952532,0.05671551174107693,16.386250405443047,82.73293903034589,0.017705482082658805
0.0188566319915444,80.9628310495162,0.05986980657315347,16.322106739582466,82.4895173596105,0.018681049535024637
0.019861105898833,80.6378784090685,0.06305901122879477,16.25659628726821,82.23943585160823,0.01966644733669124
0.0208677322569279,80.3089654686625,0.06625504991574607,16.19028743848236,81.98483145789343,0.020652983539753488
0.0218784308187404,79.9637587821732,0.06946401784950076,16.12069377048612,81.71324034669541,0.021642532473982484
0.0228992146749737,79.6429763124498,0.0727050065930415,16.05602402458988,81.46673792438244,0.022640962736834365
0.023923670167252,79.3117153802975,0.0759576527810251,15.989241820667976,81.2091426994547,0.02364198298671573
0.0249593089516605,78.9877249586295,0.07924580592152208,15.923925351659706,80.95920398926071,0.02465291321861595
0.0259985928481101,78.6469309436021,0.08254553229274957,15.855221278230184,80.69164047995824,0.02566637525456724
0.0270466040817331,78.3476935642989,0.0858729679595026,15.794895022562658,80.46673261284944,0.026687308769542225
0.0280983844834067,78.0229528280332,0.08921237073481628,15.729427290131493,80.21527175512597,0.02771086720396147
0.0291606459334492,77.6760681126932,0.09258505083870121,15.659495331518949,79.94115243242993,0.02874356316372343
0.0302215011042376,77.3476757426554,0.09595326600595437,15.59329142971933,79.68523861052226,0.029773828737454888
0.0312904518046006,77.0409167101125,0.0993471844796069,15.53144880875868,79.45156180141252,0.030810883889774605
0.0323578216426503,76.7171804336655,0.1027360837154147,15.466183575426967,79.19958127506507,0.03184533336158125
0.0334351716656587,76.4128695703765,0.10615667003846638,15.404834505387903,78.96774698192762,0.03288837119177184
0.0345131575702817,76.0983211726759,0.10957927528564439,15.34142154841146,78.72471452214236,0.03393093689520389
0.0356018143483503,75.8030026624811,0.11303576055601221,15.28188533675619,78.50172709031825,0.0349827208716466
0.0366976335761255,75.5381900778537,0.11651498660419846,15.228499119695305,78.3102628983345,0.036040308693726576
0.0377957962723835,75.2183602158425,0.1200016531648176,15.164021419513848,78.06129803450324,0.037099037328906084
0.0388943785924521,74.886019508051,0.12348965203103542,15.097021532823083,77.7986647020789,0.0381570501570532
0.0400008287550609,74.5873206821382,0.12700263129731834,15.03680384951906,77.57087532404321,0.039221510032829976
0.0411151411904841,74.2906331270001,0.13054057327978702,14.976991638403222,77.34510299714718,0.04029238984731924
0.0422307655835718,73.9820933304431,0.13408268072784046,14.91479001541733,77.10641377126298,0.04136338290334292
0.043354002254304,73.6899265196472,0.13764895715741518,14.855889186360876,76.88467976009947,0.04244052615511144
0.0444874563194367,73.3870310409445,0.14124767381421152,14.794825457854413,76.65183337879166,0.04352629267424006
0.0456292389908983,73.1141653507568,0.1448728337961021,14.739815734712572,76.45030907516654,0.04461884677669756
0.046777054344654,72.8024346321138,0.14851714754427645,14.676970821834143,76.2079180733233,0.045715971625294415
0.0479259444508021,72.518949458924,0.15216487363129666,14.619820210919078,75.9944886023229,0.046812919710071295
0.049069799777023,72.2090590452558,0.15579661429204802,14.557346303523568,75.75234311469374,0.047903866549441565
0.0502254600076618,71.9308080594558,0.15946583552432622,14.50125090478629,75.5435659829648,0.04900486493639343
0.0513866522771472,71.6601238115397,0.16315262097994235,14.446680960406404,75.34249767598061,0.05010991413254338
0.0525533739173266,71.3908498805562,0.16685696218751195,14.39239533592013,75.14267990860479,0.05121899684901695
0.053726361489147,71.1161482699469,0.17058119772804173,14.337015491221296,74.93696015961385,0.05233279733179732
0.0549016308795353,70.8925137085264,0.17431267804252457,14.29193076363892,74.78462832827431,0.05344752170835112
0.0560904059264275,70.597998127567,0.1780870388164073,14.232556422517508,74.5578685001354,0.05457379329235299
0.0572878646162061,70.3594603270763,0.18188897015645436,14.184467201938583,74.39020356476317,0.0557070109795182
0.0584923717310452,70.0924089514932,0.18571328024606848,14.13062964462103,74.19228019140839,0.05684560488853895
0.0596912354805586,69.8002826342694,0.18951967265077355,14.07173697906871,73.96674774160111,0.057977578409103156
0.0608858127123464,69.5483543131973,0.1933124553616998,14.020948229540576,73.78286238836253,0.059104231514367056
0.0620924363986067,69.3041674608059,0.19714348556557626,13.971720160098469,73.60743207102438,0.06024095895535115
0.0633085141023695,69.0411934654584,0.20100453227502316,13.918704602636415,73.4120888356108,0.061385286886680365
0.0645323340255083,68.820797436652,0.20489016053098885,13.874272763229044,73.26196412473588,0.06253557973791453
0.0657617281101446,68.5576209734435,0.20879348674970907,13.821216388246212,73.06608860377744,0.06368978116293748
0.0669903164155879,68.3112444815723,0.2126942546194916,13.771546887484977,72.88743636413541,0.06484189675414843
0.0682334678585265,68.0891396843851,0.21664126045082163,13.726770560372039,72.73509780855431,0.06600631951166756
0.0694919718938249,67.8468653073484,0.22063701076289405,13.677928045961437,72.56167776437077,0.06718374310151416
0.0707430268302532,67.5369812004467,0.2246091101860539,13.615455410010057,72.31475167354421,0.06835282507584337
0.072001426874735,67.3024153602839,0.22860453032728362,13.568166936633236,72.14828529834043,0.06952739368758924
0.0732576847975872,67.0499161894573,0.23259314923233934,13.517263103794594,71.96183781536921,0.07069858840212724
0.0745235661955034,66.81879195344,0.2366123226707233,13.470668457813504,71.79836661868576,0.07187736910329222
0.0758003579098468,66.587269565049,0.24066613636376355,13.423993544313879,71.63460843031916,0.07306490354875751
0.0770774939590991,66.3595771791352,0.24472104332013964,13.378090759313658,71.47440708828836,0.07425134912248785
0.0783629047047488,66.1159900097009,0.2488022224375774,13.3289835859557,71.29703103429121,0.07544406212798606
0.0796609540781698,65.9418654886394,0.2529235291981891,13.293880082509702,71.19485740715875,0.07664706044024616
0.0809639066525537,65.7128691270925,0.25706040362185795,13.24771441602185,71.03323972896989,0.07785314924909943
0.0822721209347719,65.480750534792,0.2612139839679008,13.200919307814065,70.86799076169002,0.07906264689523274
0.0835869797058348,65.2510448288014,0.26538866056602545,13.154610637486362,70.70518258869095,0.08027681538126677
0.0849065815225829,65.0211552575284,0.2695783963342007,13.108264899917726,70.54187927709427,0.08149388330642063
0.0862287829510812,64.756967408178,0.2737763858696828,13.055004629488685,70.34088189538802,0.08271186502565239
0.0875405065908497,64.5132650489076,0.2779411084259478,13.005874233859773,70.16078895311873,0.08391873072689521
0.0888589306278865,64.286660143373,0.2821271047435396,12.960190684903996,69.99910401735148,0.08513029527315015
0.0901930900996876,64.0600626407432,0.2863630610665081,12.914508628373829,69.83783764229139,0.0863548274328439
0.0915285566780328,63.8491330368955,0.2906031674527541,12.871985220238134,69.69315202890625,0.08757905944897766
0.0928702246165565,63.6271585530755,0.2948629631575669,12.82723516430002,69.53622705961288,0.08880746894886038
0.0942136823502751,63.3792984618674,0.2991284414621234,12.777266569912468,69.35049555473705,0.09003600700212218
0.0955414528640085,63.1627518165338,0.303344112843227,12.733610766213214,69.19741289197422,0.09124871855612827
0.096891460095566,62.9379557297989,0.307630385803422,12.68829187512746,69.0361061558892,0.09248023391443126
0.0982417024270678,62.6878589128231,0.31191740520594025,12.637872356825138,68.84642089392669,0.09371044857734626
0.0995931130244455,62.4491121788441,0.3162081338526144,12.589741015254972,68.668613666348,0.09494021412495776
0.100958447237547,62.2017425856885,0.3205430699792117,12.5398713052748,68.48153393260922,0.09618111609967774
0.102322469327965,61.9429072590043,0.32487384011628884,12.487690103415266,68.28105848709875,0.0974192898199915
0.103696974774948,61.7217815674808,0.3292378949104599,12.44311116400413,68.1221435937487,0.09866543080802871
0.105102807793568,61.4992623823645,0.3337014147445784,12.398251296284684,67.96300753598436,0.09993836936909312
0.10651490622436,61.2546167087283,0.33818482726234295,12.348930728479624,67.77914646326761,0.10121535192691238
0.107929023392174,61.0323817729206,0.34267464927015245,12.304128165420794,67.61954713297024,0.10249252796295853
0.109350500352299,60.7897807784476,0.3471878386185493,12.255219804935036,67.43717372287742,0.10377470924830728
0.110780343491373,60.554804490099,0.3517275905851093,12.207848585203958,67.26308653156511,0.10506278048134286
0.112221580836743,60.3285060425878,0.356303519156659,12.162226818185701,67.09866636020601,0.10635943932048257
0.113664317117703,60.0803054654113,0.36088420684870703,12.112189581826918,66.90929235836028,0.10765576496262277
0.11511834766346,59.8358892023974,0.3655007538314855,12.062915263203315,66.72409789835126,0.10896054068168835
0.116562374894055,59.5994496329853,0.37008554028862456,12.015249046009835,66.54650302458468,0.11025465718995893
0.118016557904299,59.3360475400372,0.3747025713461493,11.962147184071501,66.33868363035825,0.1115561849133069
0.119477947227027,59.0765171981373,0.3793424824458107,11.90982586714448,66.1348582022929,0.11286245809268675
0.120935279411709,58.8262825060288,0.38396951213217606,11.859378553215405,65.94045541764753,0.11416340773259702
0.122392024858645,58.5784778889495,0.38859467892619787,11.809421142412221,65.7480164109154,0.11546214434488054
0.123861946603712,58.330696274888,0.39326168046678556,11.759468369017421,65.55564986224552,0.1167709206217934
0.125343122720512,58.0605656880072,0.3979644146376256,11.705010042702252,65.33805829826143,0.11808798712774504
0.126837222351636,57.7957078916471,0.4027081809664443,11.651614710956055,65.12635494447015,0.11941479015537865
0.128352420819414,57.5494172798275,0.4075189361016394,11.601962523613224,64.93602430443998,0.12075853408428414
0.129871972020591,57.2890805455308,0.41234351116537643,11.549478637979009,64.72932641122536,0.12210432720859955
0.131397938690708,57.0139842615954,0.4171884553429979,11.494019227137633,64.5055042701135,0.12345398201497756
0.132922066210308,56.7083963654345,0.42202756021772786,11.432412707271597,64.24619358180118,0.12480019434051542
0.134454980552899,56.426601659882,0.42689456325545433,11.37560289463221,64.01343928872761,0.12615234225815614
0.135984870767859,56.1423801994873,0.4317519646879523,11.31830384821664,63.776894515514584,0.12750000222423485
0.137531967546257,55.8553514654056,0.4366639969593659,11.260438855425768,63.53724785043054,0.1288609747854458
0.13908014783645,55.5557416214911,0.44157946938072873,11.200037510892605,63.28244237937171,0.13022104883441046
0.140632647118092,55.2579076486835,0.4465086545999421,11.139994181974593,63.02897347552493,0.1315830620889563
0.142214696999181,54.9558581186723,0.4515316629723996,11.079100996724337,62.77138882934927,0.13296909443880825
0.143815991542412,54.6675822969458,0.4566157731471581,11.020984591064273,62.52965485020747,0.13437003346657625
0.145432662126857,54.3440655023325,0.4617487022527709,10.955763605270231,62.247467619133,0.13578243648414212
0.147051535370602,54.0048590609182,0.4668886248016613,10.887379586681108,61.946356503299185,0.1371947677138244
0.148683676874613,53.6659272577451,0.4720706740768963,10.819050935161412,61.64517464531216,0.13861665798260644
0.150316411052502,53.3044539267943,0.4772546050916939,10.746177911641732,61.31698813418347,0.14003704457673163
0.151956087547498,52.9509103461318,0.48246057796330616,10.674903525780172,60.997123514408315,0.14146144309882047
0.153591957398775,52.5841796659127,0.48765446474111057,10.600970620647999,60.660686749009095,0.14288051578254493
0.155249137355757,52.2049435094023,0.49291601110452843,10.524516611495503,60.30971595494303,0.14431602405145436
0.1568862698034,51.8241917749121,0.498113906625795,10.447757061822282,59.9546959080541,0.1457321458894454
0.158525712376285,51.4472489144364,0.5033191367947049,10.371765381150379,59.60296069839749,0.14714825918546184
0.160165984552918,51.0537564469616,0.5085270009555146,10.292437299707458,59.23083161341409,0.14856308501368268
0.161795549713029,50.6279995145063,0.513700870338867,10.20660470212447,58.81938452682681,0.14996669605856874
0.163424445505891,50.1949173917409,0.5188726144812039,10.119295346174965,58.397993933700164,0.15136776439848545
0.165052923510904,49.7593177570607,0.5240430321471202,10.031478459823438,57.972238624771606,0.1527665138922031
0.166665935837781,49.3071892943506,0.5291643462849547,9.940329361741082,57.525018141624166,0.15415005340230306
0.168249067639321,48.8262912367716,0.5341907897548441,9.843380313333155,57.04126921364437,0.15550610451489655
0.169821029097118,48.3450763316846,0.5391817673833496,9.746367388467617,56.55508694611001,0.1568507705254239
0.171406145434532,47.8436891620035,0.5442145117546391,9.645287735059906,56.04439150463041,0.1582048608903895
0.172990325624743,47.3547319939327,0.5492442838585591,9.546713969976834,55.54664250143555,0.15955632208808843
0.174550179657558,46.8405194821005,0.5541968204127466,9.44304872759146,55.01654057295448,0.16088524847625468
0.176108015306532,46.2779898301963,0.5591429485982391,9.329642749767574,54.42791477156804,0.1622106950089575
0.177647096182162,45.701282503335,0.5640295303783643,9.213378552672337,53.819982631853115,0.16351846155397262
0.179236470509228,45.1117025732879,0.5690757938667989,9.094519238774842,53.19736492118608,0.16486717015413624
0.180838245916307,44.5027506231375,0.5741614307842747,8.97175452562452,52.55054998427652,0.1662245641738024
0.182393750093057,43.8633592305896,0.579100156545456,8.842853220886864,51.863761812335746,0.16754098541726303
0.183924582486346,43.2009919376688,0.5839605493941485,8.709319974634031,51.14671634280054,0.1688348372086897
0.185470487715843,42.4848506900123,0.5888687984978015,8.56494589910648,50.36453666802365,0.1701397318362645
0.186983303777145,41.7872616622259,0.5936719894924354,8.424311951104741,49.60078190362893,0.1714150496289801
0.188484743644815,41.0684491096877,0.5984390610722875,8.27939934051304,48.80922521201731,0.1726791710885313
0.189938910017937,40.3193159266102,0.60305603930695,8.128374090804616,47.97752284637939,0.17390196968631363
0.191362133747595,39.5202329610895,0.6075747746486141,7.967278964955644,47.08290906672562,0.17509730271893897
0.192798282750677,38.7001869228046,0.6121345477333995,7.801957683637408,46.16151650365153,0.17630204478817763
0.194251171793143,37.8498886434777,0.616747470443229,7.630537550525104,45.20227386471321,0.17751935448330208
0.195657120443708,36.9680635843486,0.6212113574087729,7.4527616186046775,44.20112845364215,0.1786959258331922
0.197076643892323,36.0031688768974,0.6257183443581255,7.2582388455825155,43.09855256864488,0.17988245451123638
0.198481940764282,35.0154829286587,0.6301801619265953,7.059121358417594,41.96542393713746,0.18105570658042924
0.199915396487353,33.9615154683191,0.6347313838473457,6.84664151841313,40.750945298479486,0.1822510513813006
0.201311513176544,32.8590670190632,0.6391640543355271,6.624387911043141,39.47397552224028,0.1834138876304613
0.202707161619415,31.6845219646847,0.6435952381416425,6.3875996280804355,38.107201479413945,0.1845749839349932
0.204086515944416,30.3751045451466,0.6479746881235208,6.1236210763015535,36.57425380321296,0.18572120140172288
0.204794096398153,29.7601825281438,0.6502212560641357,5.99965279767379,35.85489221763911,0.18630867798355255
0.205480983028682,29.1387760663074,0.6524021211160653,5.874377254967572,35.12624041666488,0.18687864334143836
0.206184326958257,28.4444102561769,0.6546352380924659,5.734393107645263,34.30920184057128,0.1874619282165024