File: example/data/02 processed data/test_ID_067.csv
Strain,Stress_MPa,Displacement(mm),Force(kN),True Stress (MPa),True Strain
0.0017421257976895708,60.8121971062964,0.005531249407664387,24.51947787325871,60.91813960368946,0.0017406100566943476
0.0017976735889466706,62.6879799956375,0.005707613644905679,25.27579353424104,62.80067252162007,0.001796059707645527
0.0018491724465212708,64.5427688494582,0.0058711225177050345,26.02364440010155,64.66211955923681,0.0018474648319445966
0.0018961409947866707,66.393846548097,0.0060202476584476795,26.769998928192713,66.51973864233842,0.001894345588654435
0.0019418399473852708,68.2227084087316,0.006165341832948234,27.50739603040058,68.35518598923849,0.0019399570133714916
0.0019921363136631708,69.9907473368941,0.006325032795880567,28.2202693262357,70.13017844628436,0.0019901546415213704
0.002035161804353371,71.7291692849126,0.006461638728821953,28.92120105567676,71.87514975049926,0.0020330936680877814
0.002091224668381771,73.3894992936832,0.006639638322112122,29.59064611521307,73.54297322500634,0.0020890411017639135
0.0021359817870688705,75.0285515822726,0.006781742173943664,30.25151199797231,75.1888112019625,0.0021337038211906474
0.002178047276127971,76.6743108323112,0.0069153001017063075,30.91508212758788,76.8413111061685,0.002175678769681905
0.002215983083140671,78.2453361544359,0.0070357462889716295,31.548519537468557,78.4187264956888,0.0022135314138654084
0.002261640879820671,79.8041051661712,0.00718070979343063,32.17701520300023,79.98459339279252,0.0022590872196693104
0.002309401298252271,81.3604224254569,0.00733234912195096,32.804522321944226,81.54831629063261,0.00230673872957921
0.002347951920994471,82.8843093714689,0.0074547473491574446,33.41895353857626,83.07891774487796,0.002345199788956881
0.002391292600027871,84.4355200022774,0.0075923540050884895,34.04440166491825,84.63743003643835,0.002388438009746367
0.002433779693206171,85.9501308954215,0.007727250525929592,34.65509277703395,86.15931457862318,0.002430822847976762
0.002476784102103771,87.4194639622923,0.007863789524179472,35.247527869596254,87.63598310084855,0.0024737219275475677
0.002518576103423371,88.9031276123107,0.007996479128369201,35.845741053283675,89.12703690503467,0.0025154098058889564
0.002558766264275871,90.3825082757461,0.008124082889075889,36.44222733678083,90.61377598880271,0.002555498195507246
0.0025998056316934707,91.8318167051585,0.008254382880626769,37.02658849551991,92.07056157939721,0.002596431982987636
0.0026407083550445704,93.2648415467004,0.00838424902726651,37.6043841116296,93.51112679300468,0.0026372278107914273
0.0026852620210011707,94.7032412896949,0.008525706916678717,38.18434688800499,94.95754430679582,0.002681663146115536
0.0027310256637625707,96.1608355407259,0.008671006482446161,38.772048890020685,96.42345325043647,0.0027273031890834706
0.0027742036426504704,97.6063891840484,0.008808096565415244,39.354896119008316,97.87716918446876,0.002770362641897454
0.0028196619582361707,99.0635497910637,0.008952426717399842,39.94242327575689,99.3428755138574,0.002815694168257823
0.002866237696736971,100.474905894207,0.009100304687139881,40.51148205654426,100.76289085705707,0.0028621378696541875
0.002903701385867871,101.885782879724,0.00921925190013049,41.080347657104724,102.1816287686721,0.002899493788102567
0.0029535001177794706,103.291413511257,0.009377362873949819,41.64709792773883,103.59648471322811,0.0029491471052822413
0.0029862557140007706,104.692221305576,0.009481361891952447,42.211903630408244,105.0048590496612,0.002981805709439304
0.0030188615933097705,106.076323944556,0.009584885558758522,42.769973814444974,106.3965536848717,0.0030143139807597844
0.003062260282462771,107.444888406505,0.009722676396819297,43.32177900550281,107.7739126208259,0.0030575811135656913
0.003092170415585171,108.770912428595,0.009817641069482916,43.8564318912095,109.10725062608289,0.003087399489127204
0.0031232306949793708,110.058206839409,0.009916257456559502,44.375468997649705,110.40194400924422,0.0031183635415211242
0.0031594255048199705,111.381187480029,0.010031175977803406,44.908894791947695,111.73308804451054,0.0031544450076422675
0.003199264758521071,112.704328816405,0.0101576656083044,45.442385378774496,113.0648998037201,0.003194158000039563
0.0032436339536282706,114.040817753653,0.010298537802769759,45.98125771827289,114.4107244222183,0.0032383847210123036
0.0032909378401444708,115.342203805574,0.010448727642458694,46.50597657440744,115.72178782864341,0.0032855345555477303
0.003327389467242671,116.656214997539,0.01056446155849548,47.03578588700773,117.0443756586102,0.0033218659560998558
0.0033799815900378708,117.984652395155,0.01073144154837024,47.5714118457265,118.38343834815764,0.003374282291003248
0.0034337762600141707,119.350274824217,0.010902239625544992,48.12203080912429,119.76009696453454,0.0034278943113300792
0.003480723615914571,120.652144516758,0.011051297480528762,48.64694466915683,121.07210128548823,0.0034746799177045136
0.0035191718272560707,121.949810215218,0.011173370551538024,49.1701634787759,122.3789725516666,0.0035129940316547498
0.003571394705405671,123.211449819659,0.011339178189663004,49.678856567286516,123.65148653919029,0.0035650324189923544
0.003624605604684771,124.478770183547,0.011508122794874147,50.18984013800615,124.92995663161854,0.0036180525518376325
0.003672140204921271,125.763986377308,0.011659045150625035,50.70803930733058,126.22580936801529,0.0036654143585508367
0.0037318371541803707,127.012754924811,0.011848582964522677,51.2115427856838,127.48674584269422,0.0037248911255094606
0.0037864308855807705,128.258072427396,0.012021918061718945,51.71365480272607,128.74371275416016,0.0037792804003500364
0.0038541517365457707,129.475213607392,0.012236931763532822,52.20440612650045,129.97423072675656,0.0038467435225610796
0.003924432744524171,130.655376519236,0.012460073963864242,52.680247812555955,131.16812475709622,0.00391675224618269
0.003999490390205871,131.784378787806,0.01269838198890364,53.13546152724338,132.31144914434708,0.0039915136899324015
0.00407791328861737,132.885296701345,0.01294737469136015,53.579351629982305,133.42719141862526,0.004069621135698806
0.004165401169056671,133.929008570467,0.013225148711754928,54.000176255612296,134.486876619337,0.004156749901286956
0.0042513183039226705,134.963343190426,0.013497935614954479,54.41721997437977,135.53711532169007,0.004242306981235105
0.004348357845950671,135.905430329406,0.013806036160893381,54.79706950881649,136.49639577368617,0.004338931055465162
0.004458313230746171,136.796554664248,0.01415514450761909,55.156370840624795,137.4064365538281,0.004448404392534767
0.004580673658671271,137.606938960693,0.014543638866281284,55.48311778895141,138.23727144124064,0.0045702143015261135
0.004709741112425771,138.345776639389,0.014953428031951821,55.78101714100164,138.99734943135797,0.0046986849825019425
0.004832322919534171,139.022502834693,0.015342625269520993,56.05387314294821,139.6943044614721,0.004820684725084627
0.004977814337318671,139.61156861181,0.01580456052098678,56.29138446428179,140.30652907970142,0.004965465981126304
0.00512878257332007,140.123692021308,0.016283884670291224,56.49787262299138,140.84235597105615,0.005115675165571896
0.005279444455867771,140.525834978221,0.01676223614738017,56.66001666321871,141.26773331860295,0.00526555704608152
0.005432816571408171,140.865749067085,0.01724919261422094,56.797070023848676,141.6310468429605,0.0054181120573684625
0.005591185714882371,141.141466952747,0.017752014644751526,56.90823947534759,141.93061510655073,0.005575613055488275
0.0057475317508901705,141.36351199903,0.01824841330907629,56.9977680380089,142.17600327266177,0.005731077706931749
0.005925848865182371,141.527827780266,0.018814570146954028,57.06402016100325,142.3665002979094,0.005908360079385859
0.00610151286980867,141.636466822288,0.01937230336164253,57.10782342274653,142.50066354743845,0.006082974011992905
0.006278995706133571,141.692010643329,0.019935811366974088,57.130218691390255,142.5816941697519,0.006259364944054326
0.006463024088968871,141.748221156827,0.020520101482476162,57.15288277043265,142.66434332473204,0.006442228303131931
0.006650317581361271,141.767245283502,0.021114758320822033,57.16055329830802,142.71004248727203,0.006628301773567847
0.006845716453860471,141.780138833582,0.021735149741006994,57.16575197770026,142.75072546282567,0.0068223909297515815
0.007042376421333971,141.770050012282,0.022359545137735356,57.16168416495211,142.76844806973983,0.007017694699404208
0.0072414734338007705,141.738081729765,0.022991678152317445,57.148794553441256,142.76447428316897,0.007215379859943511
0.007438751674273171,141.702068793547,0.023618036565817315,57.13427413755815,142.75615529503295,0.007411220607913714
0.007641541872178571,141.642531990594,0.02426189544416696,57.1102688986075,142.7248993296815,0.007612493181755485
0.007848525325970671,141.592001322808,0.02491906790995688,57.089894933356184,142.7032897311449,0.00781788586305756
0.00805835014096997,141.546398465306,0.025585261697579655,57.07150786121138,142.68702890533268,0.008026055018399552
0.00825987486437527,141.479685116594,0.02622510269439148,57.0446090390107,142.64828961150826,0.008225948786731474
0.008469758577326271,141.402044791509,0.02689148348301091,57.013304459936435,142.5996859732334,0.008434091425415987
0.00867648720644797,141.320777009486,0.027547846880472304,56.98053729022476,142.54694492321408,0.008639062810388707
0.00888791284915307,141.247887321219,0.028219123296060997,56.9511481679155,142.50328623385698,0.008848647836247746
0.00909517985341207,141.171479367501,0.028877196034583323,56.920340480976414,142.45545936252068,0.009054067798126867
0.009311612735088771,141.094433717224,0.029564370433906847,56.88927567478472,142.40825044307545,0.009268526928269493
0.00951725874461177,141.010713421305,0.03021729651414237,56.85551965147019,142.35274886669788,0.009472254954096218
0.00973529988793797,140.930947166903,0.030909577144203056,56.82335789769529,142.30295220106393,0.009688217185508457
0.009950444194736471,140.858522707469,0.03159266031828829,56.7941563556515,142.2601275770227,0.009901264495707768
0.01016840861551657,140.769128291919,0.03228469735426511,56.75811252730175,142.2005263088413,0.010117058156880373
0.01038233021991757,140.673511941373,0.032963898448238285,56.71956001476159,142.13403079554385,0.010328803995367576
0.01060526854998477,140.586499042409,0.033671727646201646,56.68447641389931,142.0774566192559,0.010549427151202008
0.010823846193403371,140.477480403873,0.0343657116640557,56.64052009884159,141.99798704540135,0.0107656876598455
0.011049636271222471,140.379280753309,0.035082595161131346,56.60092599973418,141.9304207456489,0.010989035046035526
0.01127183008477227,140.299670961019,0.03578806051915196,56.56882733148285,141.88110501304106,0.011208776386015726
0.01149476987887547,140.222635407528,0.03649589436542962,56.53776659631529,141.83446233334698,0.011429206953743975
0.011711463484651071,140.143956362254,0.03718389656376715,56.506043205260816,141.78524718978505,0.011643415078482731
0.01192925810964507,140.046046411782,0.0378753944981231,56.4665659132305,141.71669184666348,0.011858665368231072
0.01215012143799557,139.947893270395,0.03857663556563593,56.426990566623275,141.64827716862195,0.012076901205677743
0.012368616734456071,139.845948793466,0.039270358131898025,56.38588655352549,141.57564973595873,0.012292750328917891
0.01259952305386877,139.733868361674,0.04000348569603334,56.34069572342696,141.49444845750318,0.012520809542172995
0.01281714725021337,139.626156716302,0.04069444251942745,56.29726638801297,141.41576572691622,0.012735702803764988
0.01303083610063447,139.515590497836,0.04137290461951444,56.25268608872748,141.33359529109651,0.012946665178997127
0.01324909991884347,139.39114697034,0.04206589224232802,56.2025104584411,141.23795420435223,0.013162098214851035
0.01347211721056727,139.280035038102,0.04277397214355108,56.157710127362726,141.15643199522722,0.013382175145747036
0.013690389846093571,139.182150474269,0.04346698776134709,56.118243071225265,141.08760837387942,0.01359752308712829
0.013909076894502971,139.105211152439,0.04416131914004693,56.08722113666341,141.04003623078435,0.013813233391697315
0.014120173210564971,139.018108539801,0.04483154994354378,56.052101363247765,140.9810683117881,0.014021412161124257
0.01435353991493497,138.929788068973,0.04557248922991853,56.01649054940992,140.92392232739448,0.014251503094903356
0.014577447840535671,138.849095758068,0.04628339689370075,55.98395540965302,140.87316120918675,0.014472218267435904
0.01480957695796317,138.779469524657,0.047020406841533066,55.955882112341705,140.83473475876772,0.014700985984587404
0.01504154012575477,138.713540984046,0.04775688989927139,55.929299724767354,140.8000062767431,0.01492953788856607
0.01526962158616037,138.627650945155,0.048481048536059175,55.8946688610865,140.74444271646584,0.015154214249181223
0.01549976123352237,138.513844678711,0.04921174191643352,55.848782174456275,140.66077619876822,0.015380866916189373
0.015729738915866272,138.420201404628,0.04994192105787541,55.811025206346,140.59751503340442,0.015607308766615221
0.01594358703084207,138.318529997791,0.05062088882292357,55.770031295109334,140.5238235187889,0.015817823038800884
0.01617560160427957,138.208230818756,0.051357535093587627,55.72555866612242,140.4438320989125,0.016046170446515254
0.016400588183847972,138.097155283681,0.05207186748371731,55.68077301038017,140.36202985684955,0.016267551156982803
0.01662307262274127,137.984341989695,0.05277825557720353,55.635286690245024,140.27806572739087,0.016486421644395684
0.016849630846275672,137.8777717837,0.05349757793692526,55.59231758318784,140.20096134016242,0.016709250526323143
0.01707678382925437,137.763890758398,0.05421878865788263,55.546400753786074,140.11645494035616,0.01693261454016741
0.017293706710280472,137.651160081401,0.0549075188051405,55.50094774482089,140.03165887217864,0.017145872531135267
0.01752093288529307,137.541087783088,0.0556289619108055,55.45656659414108,139.95093595110566,0.01736921098323343
0.01774168608896267,137.437340900407,0.05632985333245647,55.41473585104411,139.8757110595638,0.017586139454750984
0.01796348695067837,137.356059366653,0.05703407106840382,55.38196313663449,139.82345314668248,0.017804050049596246
0.01819479652058207,137.261853459448,0.05776847895284807,55.343979314849435,139.7593049531806,0.018031252004155764
0.01842877591445087,137.155810707729,0.05851136352838151,55.30122287735633,139.68342440862656,0.018261023865843964
0.018654538987936273,137.087849728253,0.05922816128669766,55.273821010431604,139.64516036578104,0.01848267712151413
0.018887658149612768,137.021541317008,0.05996831462502054,55.247085459017626,139.60955734853667,0.018711501008470816
0.01911886723370107,136.94489455831,0.06070240346700089,55.216181485910596,139.56312581570353,0.0189383983046282
0.019354368064987672,136.861345100619,0.061450118606335855,55.18249434456958,139.51020994756567,0.019169454399215444
0.019592123400127073,136.780963322993,0.06220499179540345,55.150084411830775,139.46079283520532,0.01940266830376095
0.01982158434367587,136.713593074031,0.06293353029117088,55.1229207274493,139.4234730900749,0.019627694686241273
0.02005514699793167,136.641279907677,0.06367509171843305,55.09376405877536,139.381640862211,0.01985669151893011
0.02028962956732077,136.569418979873,0.06441957387624345,55.064789732684794,139.34036190119886,0.02008653754604714
0.020531541625432068,136.482385856879,0.06518764466074681,55.02969797749362,139.2845796432378,0.02032361080132218
0.020769680975393473,136.392989187446,0.06594373709687427,54.99365324037823,139.22582806014955,0.020556931928459143
0.02100014234016187,136.299003505917,0.06667545193001394,54.95575821358573,139.16130198036348,0.020782678595018086
0.02122829095547807,136.197950637634,0.06739982378364287,54.915013697094025,139.08920036130954,0.02100610963979827
0.02147183999544037,136.077253154817,0.06817309198552317,54.86634847202221,138.99908216157624,0.02124456758810499
0.02170425409769857,135.965056419624,0.06891100676019296,54.82111074839241,138.91607655256345,0.02147207035101673
0.02193856317317127,135.8598172076,0.06965493807481878,54.778678298104325,138.84038639010444,0.021701375662609487
0.02216866905911767,135.762226257696,0.0703855242626986,54.739329627103025,138.7718941223319,0.021926516382518874
0.02240689239558017,135.648828126796,0.07114188335596704,54.69360750072415,138.68829682221966,0.022159546006888582
0.022646747716750168,135.546343799236,0.07190342400068178,54.65228581985196,138.6160276511852,0.022394117186407006
0.022884478923098674,135.446239785178,0.07265822058083829,54.61192388138377,138.54585640475486,0.02262655676427575
0.02311017298038097,135.364557380083,0.07337479921270958,54.57898953564946,138.4928557165494,0.022847177143696294
0.02333982410397927,135.30037294885,0.07410394153013418,54.55311037297632,138.45825985467894,0.023071615683498983
0.02357533865535117,135.209754339873,0.07485170023073996,54.51657294983679,138.39737008794236,0.023301732257645355
0.02380551134657357,135.083884500482,0.07558249852537108,54.46582223059434,138.29962544569744,0.02352657825265589
0.024039327007777868,134.978279306615,0.07632486324969473,54.42324221642717,138.2230663018139,0.02375493116088521
0.024271280417941174,134.873853182831,0.07706131532696323,54.381137603317455,138.14741429447972,0.023981413814750253
0.024510406891859474,134.767603348009,0.07782054188165383,54.33829766991723,138.07081214190944,0.024214846665585786
0.02474773614704017,134.669881749044,0.07857406226685254,54.29889632121454,138.00265644952245,0.024446471224012195
0.02499140471173357,134.575182546073,0.07934770995975408,54.26071360257664,137.93840539723735,0.02468422690812266
0.02523525314912487,134.479586282497,0.08012192874847146,54.222169189102786,137.87321268572538,0.02492210152321081
0.025481667960320774,134.433741300106,0.08090429577401845,54.20368449220274,137.85933725857893,0.02516242217385278
0.02572601225648847,134.3758951225,0.08168008891435088,54.180360913392,137.83285104739804,0.02540066650150432
0.02597608516760607,134.323051209457,0.08247407040714927,54.15905424765306,137.81223822764656,0.02564443767342056
0.02622391634621927,134.250993462855,0.08326093439924617,54.13000056422314,137.77158028482174,0.025885964990090594
0.026470538670141174,134.169126483029,0.08404396027769823,54.0969917979573,137.72065553393708,0.02612625630525042
0.02671491492226597,134.071078467003,0.08481985487819445,54.05745883789561,137.65277592178543,0.026364302267295716
0.02695304787390227,133.97264243286,0.0855759269996397,54.01776942892915,137.58361347814605,0.026596212154402443
0.02720078373291767,133.852868432856,0.0863624883520136,53.969476552127546,137.4937713591288,0.026837416933133837
0.02744180646298467,133.760240791892,0.08712773551997632,53.93212908729085,137.43086343214532,0.027072029738614202
0.027675741866613868,133.605929707302,0.08787048042649903,53.869910857984166,137.30357292973025,0.027299691075874148
0.02791490660547067,133.473183910934,0.08862982847236937,53.816387752888595,137.19907537414255,0.027532387931265893
0.02816411649625867,133.353487989696,0.08942106987562128,53.768126357445425,137.10927116062024,0.027774800687982274
0.02840778329258757,133.238507663489,0.09019471195396553,53.72176628991877,137.02351831542117,0.02801176473236509
0.028659429831758274,133.156739458557,0.09099368971583251,53.688797349690184,136.97293568969522,0.028256430087799694
0.028903830609985172,133.061912454336,0.09176966218670292,53.650563101588276,136.9079114325568,0.0284939934075529
0.02914929903559197,132.950526370752,0.0925490244380045,53.6056522326872,136.8259410208724,0.028732537712590416
0.02940128426703177,132.900274072728,0.09334907754782587,53.58539050612393,136.8077128099067,0.02897735582368495
0.029644111853256667,132.835022823915,0.09412005513408991,53.55908120260253,136.77279909853704,0.02921322006233481
0.029886160189430473,132.740579634624,0.09488855860144174,53.521001708680394,136.70768586122222,0.029448272045375735
0.03013675715843587,132.647014317477,0.09568420397803387,53.48327617280672,136.64456517575437,0.029691567368093964
0.030382846936329172,132.546523625448,0.09646553902284512,53.44275832578063,136.57366436470252,0.02993042923436723
0.03063174217962157,132.47011839771,0.09725578142029848,53.41195173795667,136.5279089109726,0.03017195614622584
0.03088700562815707,132.389417771804,0.09806624286939869,53.37941324559138,136.47853046363016,0.03041960215974046
0.031138159090447974,132.286975445656,0.09886365511217231,53.338108499688495,136.40614833267702,0.030663200994352272
0.03139913799751987,132.192237256603,0.09969226314212559,53.29991006186233,136.34295955642395,0.0309162668747444
0.03164893429827537,132.125637637602,0.10048536639702431,53.273057095481136,136.3072732623122,0.03115842924151683
0.03189710287777787,132.055480630007,0.10127330163694473,53.24476979001882,136.26766788123675,0.03139895557456503
0.03215064229528977,131.940261803399,0.10207828928754502,53.19831355913048,136.18222596498697,0.03164462762297567
0.03240097611374297,131.831781188021,0.10287309916113394,53.154574175010076,136.10325958132626,0.03188713434205972
0.03265136539424687,131.73569403485,0.10366808512673381,53.11583183485153,136.0370443162466,0.03212963597429256
0.03290299955889357,131.650411798112,0.10446702359948709,53.08144603699876,135.98210523943345,0.032373284042976874
0.03314210448649237,131.562201432508,0.10522618174461328,53.045879617587225,135.92244965885715,0.032604745522881666
0.033402171441932374,131.472227769064,0.10605189432813528,53.00960223648661,135.86368566085906,0.032856438128592805
0.033659943246445174,131.366616392248,0.10687031980746342,52.9670197293544,135.78840924448863,0.033105846991555776
0.03391818715030257,131.301863891162,0.10769024420221066,52.940911520916515,135.75538508380598,0.033355650277248836
0.034183021138212075,131.217730053425,0.10853109211382334,52.90698875754096,135.70314849354943,0.03361176345806986
0.03444170047413747,131.132789325627,0.10935239900538646,52.8727406560928,135.6492255779184,0.03386186134636359
0.034707665391010174,131.049272503551,0.1101968376164573,52.83906667343177,135.59768680333957,0.03411893792355515
0.034975196266276674,130.974649731657,0.11104624814542843,52.80897877180411,135.55551381192856,0.03437746147004908
0.03524270205006657,130.888515618573,0.11189557900896135,52.77424949740864,135.50138057629385,0.03463589396210332
0.03550422687268577,130.79157596467,0.11272592032077731,52.73516342895494,135.43522975075575,0.03488848380816987
0.035765554351698675,130.693645927228,0.11355563506664329,52.695678037858336,135.36797662405993,0.0351408193395124
0.03602432333321667,130.585593382074,0.11437722658296293,52.65211125165223,135.2898510207298,0.03539062168255009
0.03628350697654007,130.492982051303,0.11520013465051472,52.61477036308536,135.22772507595096,0.03564076178324752
0.03654714682383217,130.396009320146,0.11603719116566714,52.57567095788287,135.16161141801115,0.03589513842345225
0.036820225209406775,130.296974392779,0.1169042150398665,52.53574007516849,135.09453833402543,0.03615855376492731
0.03707635251184807,130.199834904749,0.11771741922511762,52.4965734335948,135.0271698806619,0.03640555480296837
0.037341936437515974,130.119224160036,0.11856064818911322,52.46407118132652,134.97812795791896,0.036661611094540685
0.037611870722992075,130.030346782168,0.11941768954549983,52.428235822570144,134.92103137540474,0.036921794512665175
0.037877388666634974,129.959291663171,0.12026070901656603,52.39958639859054,134.8818102643375,0.03717765509482943
0.038142875672408476,129.828681618784,0.1211036302598969,52.34692442869371,134.780720880482,0.03743342042793443
0.038401896984495774,129.684892694931,0.12192602292577408,52.28894873459618,134.6650385846471,0.037682893800087346
0.03866197862030357,129.557811043239,0.12275178211946383,52.23770941263397,134.56677236388603,0.03793332580674998
0.03892485976336627,129.442509447352,0.1235864297486879,52.191219809172324,134.48104097500837,0.038186389736121214
0.03919566355970487,129.349939798184,0.12444623180206296,52.1538957266278,134.4198965199817,0.03844701350152093
0.03945702580857477,129.248685740399,0.12527605694222488,52.11307009052887,134.3484544693823,0.038698486247866676
0.03971994481734827,129.161596422623,0.12611082479508076,52.077955677601594,134.2918879050502,0.038951393060407756
0.039989340883705274,129.108811582632,0.12696615730576424,52.05667283011722,134.27178786009995,0.03921046395047505
0.04026176639787967,129.062071367109,0.12783110831326794,52.037827175218354,134.25833833531803,0.03947237994203796
0.04053436512686947,128.971611352294,0.12869660927781057,52.001353697244944,134.19939373784857,0.0397343938187646
0.04080399126572967,128.86749547244,0.12955267226869172,51.95937417448781,134.12580363213388,0.039993483014464384
0.04106220441011047,128.766655717918,0.13037249900210074,51.91871558546455,134.0540984562135,0.040241542324175344
0.041332347949960574,128.653158477088,0.13123020474112482,51.87295349796188,133.9706955881244,0.04050099703803758
0.041615697419333575,128.506628557562,0.13212983930638408,51.813872634409,133.8545215279922,0.0407730628456805
0.041883299563452075,128.380772013033,0.13297947611396033,51.76312727565491,133.75778234544214,0.041029940478909614
0.04213823718836937,128.269514157109,0.13378890307307276,51.71826810814635,133.67456536869815,0.041274599779874674
0.04241027749486477,128.171618841647,0.13465263104619563,51.678796716952064,133.60741276368728,0.0415356062339087
0.04268367727375987,128.068551489417,0.13552067534418757,51.63723996053294,133.53498821010916,0.04179784840274395
0.04296067059867467,127.96238019023,0.13640012915079208,51.59443169270074,133.45972985460483,0.04206346734858777
0.04323244242105067,127.880211586054,0.13726300468683586,51.561301311496976,133.40878547023985,0.0423240106532485
0.04349518398550027,127.812913248138,0.13809720915396334,51.53416662164925,133.37215942558853,0.0425758322733902
0.04376762829057837,127.739292814499,0.1389622198225863,51.504482862806,133.33013870050533,0.04283688642049903
0.04405252656238067,127.630980935757,0.13986677183555862,51.46081151329722,133.2534481136121,0.04310980099401565
0.044321130472223476,127.516786803485,0.14071958924930952,51.41476843916516,133.16847494880096,0.04336703840018511
0.04459900608345507,127.425435926243,0.14160184431496986,51.37793576546118,133.10848371830443,0.0436330855390947
0.04487263597287947,127.330390676109,0.1424706192138923,51.33961352060715,133.04404094520257,0.04389499853708044
0.045144413562957175,127.23339272583,0.14333351306238903,51.30050394705466,132.97726962606302,0.04415507066584132
0.045420530784585474,127.14409181596,0.14421018524105886,51.264497820195075,132.91904395236497,0.04441922627026802
0.04570374267198407,127.032633227402,0.14510938298354942,51.21955771728849,132.8385000073717,0.04469009672280409
0.045984217582888676,126.960586049683,0.14599989082567152,51.190508295232185,132.7987692630427,0.04495827717602187
0.04626747544517057,126.889377773255,0.14689923453841655,51.16179711817642,132.76022894363206,0.04522904561650778
0.04654281694795617,126.810399509803,0.14777344380976085,51.12995308235258,132.71251272128498,0.0454921764940413
0.04682470490767277,126.721711534239,0.14866843808186103,51.09419409060517,132.65541828222499,0.04576149180392109
0.04710955340708077,126.621436377373,0.14957283206748143,51.0537631473568,132.58651569687413,0.04603356195133264
0.047389833916135375,126.516200942125,0.15046272268372982,51.0113322198648,132.5117826924727,0.0463011967975628
0.047664074583207976,126.403692744687,0.15133343680168532,50.96596891465781,132.42860778326266,0.04656299499523817
0.04795425288800757,126.273530857494,0.15225475291942403,50.913487641741575,132.32888368929588,0.04683993312166146
0.04823600630459067,126.151712174559,0.15314932001707537,50.86437034878219,132.23676695834592,0.04710875740137011
0.048515212984882976,126.036596219429,0.15403580122700344,50.81795559567377,132.1512885289043,0.047375080539159696
0.04879664748184327,125.919067193351,0.1549293557548524,50.770567892359125,132.0634955264275,0.04764345693463478
0.04908480137312987,125.817168327093,0.15584424435968733,50.729482269483896,131.992879043758,0.04791816634994121
0.04937204405201817,125.707327569556,0.1567562398651577,50.685194476044984,131.9137552839816,0.04819193198044126
0.04965941444376977,125.622648916555,0.157668640858969,50.651052043154976,131.8609961026264,0.04846574435460453
0.04992273567723887,125.527348840598,0.1585046857752334,50.61262705252911,131.79401749703175,0.04871657639262171
0.05020015598503897,125.436737480595,0.15938549525249873,50.57609255217591,131.73368126837525,0.04898077075049953
0.05048812827400747,125.274666658058,0.1602998072699737,50.510745596528984,131.59955009777354,0.049254940214793985
0.05078141517029737,125.121254126509,0.16123099316569414,50.44888966380843,131.47508847893553,0.049534092310354036
0.05105385127908587,124.998442471116,0.16209597781109764,50.39937200435397,131.38009436315372,0.04979332871642539
0.05132678248573877,124.88746647238,0.16296253439222058,50.354626481663615,131.29753829920284,0.0500529688632217
0.05161001126470077,124.77329483325,0.16386178576542496,50.3085924767664,131.21284598512787,0.0503223338593702
0.05189969485931417,124.67308584612,0.16478153117832248,50.26818821315558,131.14358095870273,0.050597762677788566
0.052184316183922476,124.563078940868,0.16568520388395386,50.22383342895798,131.06331803716114,0.050868304466852456
0.052459564541714174,124.487281956922,0.1665591174199425,50.19327208503095,131.01783055936372,0.05112986734870784
0.05271926067917497,124.376917826466,0.16738365265638053,50.1487732676311,130.93397697983178,0.051376588563710454
0.05299650620869047,124.236216554607,0.16826390721259224,50.09204251481754,130.82030197658744,0.05163991520586927
0.05327457843413747,124.105651374672,0.16914678652838647,50.03939863426775,130.71732763295168,0.05190395740735985
0.053544764105069476,123.978341182305,0.17000462603359556,49.988067164705384,130.61673221504935,0.05216044420426528
0.05382423130528357,123.849962816982,0.17089193439427533,49.93630500780714,130.51609186279399,0.052425672745124455
0.05410004412871567,123.726571152247,0.17176764010867224,49.886553488585996,130.42018411147825,0.0526873641428853
0.054390477347562374,123.638198415704,0.17268976557851054,49.85092160121185,130.36293904592677,0.05296285337817026
0.05467785360236447,123.575440448656,0.17360218518750717,49.8256175888981,130.3322802903553,0.05323536826293095
0.054969182478229975,123.504106655319,0.17452715436838015,49.79685580342463,130.293026430866,0.05351155558027346
0.055257619481240874,123.421136597812,0.17544294185293977,49.7634022762378,130.24109479987615,0.05378492620047352
0.055551225372312975,123.320111370052,0.1763751405570937,49.722668904404976,130.1706946697085,0.05406311898299997
0.05584462366687747,123.222507277574,0.17730668014233597,49.683314934317835,130.10382182377919,0.05434103777931335
0.056132838968754074,123.09862050483,0.17822176372579418,49.63336378754745,130.0084955469034,0.05461397185059469
0.05641642509745927,122.954616792032,0.17912214968443316,49.575301490547304,129.89127672066647,0.05488244950006993
0.05670769677632747,122.836889134914,0.1800469372648397,49.52783369919733,129.80268619692404,0.05515812822400075
0.056996131543829674,122.708270304657,0.1809627176516592,49.4759745868377,129.70216702045704,0.05543104703639828
0.05728922468891487,122.58194099297,0.1818932883873047,49.425038608365504,129.60456535331957,0.0557082973575044
0.05757148445337367,122.454458302419,0.1827894631394614,49.37363758753534,129.50434324482302,0.05597522724552445
0.05786285630501457,122.325574382034,0.18371456876842127,49.32167159083611,129.40368151493,0.056250699613415535
0.05815385141714157,122.226806950967,0.18463847824942448,49.2818485626299,129.33476652158518,0.05652574008251912
0.058439747976277275,122.106949724815,0.18554619982468035,49.233522129045404,129.24284909288514,0.05679588789072977
0.058726836391164175,121.970896507646,0.18645770554194624,49.17866547188287,129.13386139133414,0.05706708848379248
0.05901021481309937,121.84278926311,0.1873574320315905,49.12701263088596,129.03275843095332,0.057334712288613164
0.059293109873864776,121.695183312497,0.18825562384952066,49.067497911598785,128.91086918776497,0.05760180818479604
0.05958301300612627,121.546106353055,0.18917606629445088,49.007390081551776,128.78818958873308,0.05787544677172441
0.05985648262644677,121.364140491323,0.1900443323389685,48.93402144610143,128.6285710581155,0.058133505208779614
0.06013785955750027,121.204832122032,0.19093770409506336,48.86978831160331,128.49383129387715,0.05839895585372411
0.06041465174777427,121.073132142538,0.1918165192991833,48.81668687987133,128.38772325694168,0.05866001252680368
0.06069132567195577,120.940311572083,0.19269495900845957,48.763133625863865,128.28033940857208,0.05892088956802273
0.06096987955740427,120.809909067666,0.19357936759475855,48.71055533608293,128.17567467286256,0.05918347049881653
0.06124850595946357,120.689390113692,0.19446400642129683,48.661962093840614,128.0814349433145,0.059446050830380646
0.06153222388006687,120.5629342343,0.1953648108192123,48.61097508326976,127.98143969524273,0.059713358629348706
0.06181706934380797,120.484603794651,0.1962691951665903,48.57939225000329,127.93260890228618,0.05998165689413151
0.06209492269935507,120.370943132084,0.19715137957045234,48.53356427085627,127.8453675411192,0.060243299898336
0.06235582053829717,120.262781532504,0.1979797302090935,48.48995351390561,127.76186595518126,0.060488914291688525
0.06263495235133087,120.114735891987,0.1988659737154755,48.430261511649164,127.63811665127427,0.0607516277285656
0.06291692860846126,119.965803165819,0.1997612483318645,48.370211836458225,127.51368303905954,0.061016948242555845
0.06319895140054507,119.800123922516,0.2006566706967306,48.30340996555845,127.37136613207436,0.061282242149054277
0.06347228651911317,119.646884483079,0.2015245096981843,48.241623823577456,127.24114581610822,0.06153929656837341
0.06374524592466356,119.481316395797,0.2023911558108068,48.17486677078535,127.0976822928496,0.06179593172945629
0.06402743521879807,119.323382971192,0.20328710681968387,48.11118801398462,126.96335314446785,0.062061175567099225
0.06433430397510846,119.163165769327,0.20426141512096935,48.04658843819265,126.82944509856712,0.062349537035721554
0.06462256542404217,119.034360247516,0.2051766452213339,47.994654051798456,126.72666598032012,0.0626203376844699
0.06490221439874827,118.87503646654,0.20606453071602573,47.93041470330893,126.5902895699504,0.06288297747994286
0.06517950750274747,118.749727295737,0.20694493632122318,47.87989004564116,126.48977603695872,0.06314333660392804
0.06546449678061736,118.628926499803,0.2078497772784601,47.83118316472057,126.39490947673744,0.06341085128868668
0.06575111067738147,118.476026163134,0.20875977640068616,47.769533748975626,126.26595647200254,0.06367981881828716
0.06601952612958946,118.336420247885,0.20961199546144652,47.713244643947235,126.14893463652233,0.0639316427706319
0.06629778829598236,118.200360695477,0.21049547783974398,47.658385432416324,126.03678318537449,0.06419263785432783
0.06657634227363857,118.049740968449,0.21137988671880245,47.597655558478635,125.90906092847882,0.06445383843362831
0.06684903888712516,117.90932138626,0.2122456984666224,47.54103838294003,125.79144619676464,0.06470948047986991
0.06713205562719947,117.7478570105,0.2131442766163583,47.4759359466336,125.65251269731242,0.06497472813596313
0.06740252319483797,117.57548167921,0.21400301114361053,47.40643421305747,125.50036581023721,0.06522814878491355
0.06767613052518137,117.428098071095,0.21487171441745084,47.347009142265506,125.37517736347822,0.06548444597692972
0.06796378292411596,117.252928732197,0.21578501078406817,47.27638086482183,125.22188132776888,0.06575382884326648
0.06823821118487436,117.076686514603,0.21665632051197609,47.205320002687934,125.0657901738118,0.06601075984794184
0.06850993305956317,116.902902993855,0.21751903746411305,47.13525048712233,124.9119130524326,0.06626509199923952
0.06879088958615187,116.749354224225,0.21841107443603217,47.073339623207524,124.78064615991818,0.06652799979886241
0.06906055670344827,116.586087595001,0.21926726753344825,47.00751051830441,124.63758770818876,0.06678027843047159
0.06934299731341936,116.416518804734,0.22016401647010647,46.93914038206874,124.4891891554483,0.06704443868318248
0.06962104361643087,116.250027539217,0.221046813482168,46.87201110381229,124.34347577693612,0.06730442089817723
0.06989943741817976,116.084772726422,0.22193071380272072,46.80538036329335,124.19903303281616,0.06756466033574088
0.07017361809918357,115.915190504232,0.22280123746490782,46.73700481130634,124.04937881457009,0.06782089521687924
0.07044881002450916,115.732706264672,0.22367497182781657,46.663427165915756,123.8859377019342,0.06807800915086962
0.07071994658747617,115.547612881586,0.22453583041523684,46.58879751385548,123.71913389288214,0.06833126949158684
0.07100604987072497,115.356598441636,0.22544420833955175,46.511780491667636,123.5476148235,0.06859844025518949
0.07127729127443166,115.143673427748,0.22630539979632053,46.425929126068,123.35080257706564,0.06885166670749542
0.07154650980884136,114.933069639081,0.22716016864307131,46.34101367847746,123.15612963337377,0.06910294125063812
0.07180708877922506,114.727368593866,0.22798750687403957,46.25807501704678,122.96560693589261,0.0693460919578654
0.07207322708210037,114.507751116479,0.22883249598566865,46.169525250164334,122.76069426535761,0.06959436916091012
0.07234048668921626,114.309422522084,0.22968104523826163,46.08955916090427,122.57862178049483,0.06984363039887319
0.07261186123758817,114.100384618531,0.23054265942934243,46.0052750781917,122.38542591360721,0.07009666590344467
0.07285545173539426,113.904159308022,0.23131605925987678,45.92615703299447,122.20269828894827,0.0703237404408939
0.07312053658121466,113.735915465837,0.23215770364535654,45.858321115825476,122.05234663325467,0.07057079338893416
0.07338870245966607,113.562022144444,0.23300913030943976,45.78820732863982,121.8961915983206,0.07082065570023391
0.07365637389138066,113.377111371556,0.2338589871051336,45.71365130501138,121.72805827746403,0.07106999507000286
0.07391660605698737,113.182342891734,0.23468522423093488,45.635120653947155,121.54839754386916,0.0713123450802797
0.07417357246190487,112.974606087746,0.23550109256654794,45.55136117457919,121.35433621875057,0.07155159612170514
0.07443122565544266,112.737494260984,0.23631914145603045,45.45575768602875,121.12868413615247,0.07179142914730265
0.07469495586561826,112.432439881762,0.23715648487333799,45.33275976032643,120.83057601659398,0.07203685932610465
0.07494367237994996,112.165276836912,0.23794615980634112,45.22503962064292,120.57135459658392,0.07226826242072107
0.07518746238561927,111.906883695939,0.23872019307434117,45.12085550620261,120.32087830451928,0.07249502999110055
0.07543308573451676,111.667179051072,0.2395000472070907,45.02420659339223,120.09057894216313,0.07272345089982861
0.07568251907795157,111.410545705284,0.2402919980724962,44.9207320283705,119.84237645610914,0.07295536158282004
0.07593651240447806,111.173158371801,0.24109842688421781,44.825017455510164,119.61526029154625,0.07319145665726381
0.07619745950080356,110.961530665473,0.2419269339150513,44.73968916431872,119.41651740450254,0.07343395745044007
0.07645324258535517,110.804368632276,0.24273904520850265,44.676321432533676,119.27572190683652,0.07367160221603782
0.07670545719630277,110.615220925114,0.2435398265982613,44.60005707700597,119.10001201904491,0.0739058762731491
0.07693464405396357,110.408100664689,0.2442674948713343,44.51654618800261,118.90230859000103,0.07411871300329062
0.07718106813590797,110.165266396876,0.24504989133150779,44.4186354112204,118.66793932886375,0.0743475067320814
0.07742887699504807,109.935510269102,0.2458366844592776,44.325997740501926,118.44769337111613,0.07457753338798975
0.07767339119438277,109.645312724216,0.2466130170421653,44.208990090403894,118.16183599207446,0.07480444995152659
0.07791352413888997,109.381586972552,0.24737543914097562,44.10265586733297,117.90389188948802,0.075027250474013
0.07816000464676927,109.125452526779,0.24815801475349242,43.99938245879729,117.65469840335284,0.07525588878867362
0.07841433214058187,108.874900674718,0.24896550454634742,43.898359952046306,117.4122532979982,0.0754917512773005
0.07869838180009717,108.613635736722,0.2498673622153085,43.79301792904631,117.16135311062723,0.07575511225915499
0.07896221886719476,108.354207637109,0.25070504490334333,43.68841651928235,116.91009629573188,0.07599967071133318
0.07921663692374387,108.104685748597,0.25151282223288673,43.58780929383432,116.66837538929904,0.07623544177084941
0.07948091786317736,107.885243327854,0.2523519142155881,43.49933010979073,116.46006149144408,0.07648029398756485
0.07972996556141086,107.631027911044,0.2531426406574795,43.396830453732946,116.21244605973078,0.07671097798536199
0.07998558919358266,107.308304125802,0.25395424568962494,43.266708223523366,115.89142205666842,0.07694769770782978
0.08023240350946717,107.005365122243,0.25473788114255824,43.14456321728838,115.59066275440868,0.07717620642110999
0.08047537896110407,106.70578321628,0.2555093282015054,43.02377179280409,115.29297155795156,0.07740110999634794
0.08072226039146976,106.415980192268,0.25629317674291646,42.90692321352246,115.00611865516173,0.07762957723779226
0.08097000191699646,106.107593629991,0.2570797560864638,42.78258175161237,114.69912568961927,0.07785878796397301
0.08120915408118397,105.804230652791,0.2578390642077591,42.660265799205334,114.39650272231464,0.07808000197808387
0.08145390806196716,105.47235949921,0.2586161580967457,42.52645535008147,114.0634953729374,0.07830634697478037
0.08169523418270347,105.212421930697,0.2593823685300835,42.42164852245703,113.8077753792547,0.07852947178575584
0.08193394098171146,104.909408762209,0.26014026261693385,42.29947361292267,113.50505006815807,0.07875012586337367
0.08217091785655857,104.597203528446,0.26089266419457346,42.17359246266943,113.19205174760768,0.07896913269645435
0.08240680785195857,104.226690071092,0.26164161492996846,42.02420143666429,112.81567889282611,0.07918708744442408
0.08264950968653247,103.893730946936,0.2624121932547406,41.8899523178046,112.4804968692048,0.07941128654134773
0.08289843933559876,103.562872989842,0.2632025448905261,41.7565503895043,112.14807353381073,0.07964118646138876
0.08313887403564406,103.24560520015,0.26396592506316985,41.628628016700475,111.8293285656191,0.07986319067114875
0.08338645069151196,102.92384249797,0.26475198094555047,41.49889329518151,111.50629641540793,0.08009173787908586
0.08363025854995906,102.587063331724,0.26552607089612,41.36310393535112,111.1664459620371,0.08031675493450217
0.08387529272318096,102.239152222826,0.26630405439609955,41.222826176243444,110.81449104328539,0.0805428527861287
0.08412674596966876,101.936600948033,0.2671024184536983,41.100837502246904,110.51219548099968,0.08077482050860099
0.08436376965787376,101.593623847597,0.2678549686637492,40.96254913535111,110.16444492858436,0.08099342758798712
0.08458939750914607,101.213277445562,0.26857133709153874,40.809193466050594,109.77484760460813,0.08120147989220612
0.08481885188072906,100.856852004827,0.26929985472131474,40.66548272834625,109.41141439618104,0.08141301626163149
0.08503753182261826,100.467054478051,0.269994163536813,40.508316365550165,109.01052482035297,0.08161457793573289
0.08526330907485696,100.068724634062,0.27071100631267087,40.3477097724538,108.60091523126277,0.08182263872509316
0.08547802366908397,99.6837278777675,0.2713927251493416,40.192479080315856,108.20449592872583,0.0820204647780535
0.08569000140401657,99.3014313340498,0.2720657544577526,40.03833711388888,107.81057112448536,0.08221573085894462
0.08590967242166717,98.9264617827718,0.2727632099387932,39.88714939081359,107.4252017083643,0.08241804348686377
0.08613105314514836,98.5509827473659,0.273466093735846,39.73575624373793,107.03928267988587,0.08262188931870472
0.08636466929148007,98.1714151075443,0.2742078250004492,39.58271457136187,106.64995690718399,0.08283695639093823
0.08659228631850456,97.8007397361188,0.27493050906125194,39.4332582616031,106.26952939351034,0.08304645619466808
0.08681278153824987,97.4422785061527,0.2756305813839433,39.28872669368077,105.90151374269664,0.08324935920963089
0.08704637152330677,97.0806424994374,0.276372229586499,39.14291505577316,105.53116017416475,0.08346426732419482
0.08727566761476907,96.6570028454413,0.27710024467689176,38.97210354728193,105.09280729841981,0.08367518004842325
0.08751165385860256,96.2462322686214,0.2778495010010631,38.80648085070815,104.66889923210765,0.08389220011510251
0.08773868218390647,95.8535565943542,0.278570315933903,38.64815401884362,104.26362133258334,0.0841009377692168
0.08795505977547056,95.4284093668488,0.279257314787119,38.47673465671343,103.82182081698807,0.08429984222723351
0.08817898374774677,95.0081814823384,0.27996827339909597,38.307298773678845,103.38590637317249,0.08450564202502896
0.08841775228944847,94.5432713600992,0.2807263635189989,38.119847012392,102.90257490785056,0.08472503823996058
0.08864419084814466,94.0942851791259,0.28144530594285927,37.938815784223564,102.43519695226408,0.08493306039590007
0.08887229991079007,93.6990734754651,0.28216955221675843,37.779466425307525,102.02632563473979,0.08514257344845141
0.08908935665451026,93.2583229519878,0.28285870737807006,37.60175581424148,101.56664694645895,0.08534189444548056
0.08930850061696406,92.8187765654261,0.28355448945886086,37.424530711179806,101.10828232958531,0.08554309181855128
0.08952571663985097,92.3827993394264,0.28424415033152683,37.248744693656725,100.65343565548409,0.08574247919909272
0.08974633203473006,91.9222208449989,0.28494460421026796,37.06303944470356,100.17190299832396,0.08594494625295777
0.08996407006089717,91.4985166812205,0.2856359224433485,36.8922019258681,99.73009564639798,0.0861447324508693
0.09018990292362146,91.0463055593756,0.2863529417824981,36.70987040154024,99.25776301933006,0.0863519039317192
0.09041814899486847,90.5548798302595,0.2870776230587074,36.511727547560625,98.74268444696432,0.08656124560766118
0.09065151660590887,90.0760520727614,0.28781856522376065,36.3186641957374,98.24158280303006,0.08677523933341107