File: example/data/02 processed data/test_ID_108.csv
Strain,Stress_MPa,Displacement(mm),Force(kN),True Stress (MPa),True Strain
9.319451718141877e-05,-0.227943921794082,9.127452801447556e-05,-0.0459534946336869,-0.2279504746992396,2.8747469626666203e-05
0.00010112557923560043,0.169090236320396,0.0001164556500366,0.0340885916421918,0.1690964383718559,3.667827223729136e-05
0.00012115955652200044,0.714188874489251,0.000180063527921,0.143980477097033,0.7142293782273115,5.67113140628206e-05
0.00013881397459400045,1.3069106990248,0.0002361163052995,0.2634731969233997,1.3070078904974334,7.436457513834234e-05
0.00017085129152480044,2.39123008468137,0.0003378347865547,0.4820719850717642,2.3914845226987755,0.0001063989966085
0.00019203519543630043,3.69374414439594,0.0004050936814737,0.7446588195102214,3.694215423896373,0.0001275804223658
0.00020879758977290043,5.3022064006394,0.0004583142834924,1.068924810368903,5.302971779199223,0.0001443405378339
0.00025835626576990045,6.97378299594718,0.0006156630797829,1.4059146519829515,6.9751352796375805,0.000193890833385
0.00028637039188180043,8.64577524602088,0.0007046079301882,1.7429882895978095,8.64769394895032,0.0002218991361051
0.0003082463579050004,10.2893913767332,0.0007740641223118,2.074341301549413,10.291899927506476,0.0002437700092395
0.0003391791629925004,11.9580936486865,0.0008722757784647,2.410751679575198,11.96137892599244,0.0002746947965798
0.00036429834750490044,13.5306808263484,0.0009520291892915,2.7277852545918377,13.534738024174436,0.0002998067666224
0.00036300481571610046,15.178499257823,0.0009479222258621,3.059985450377117,15.183030922957402,0.0002985136217489
0.0003952609811914004,16.7919862492839,0.0010503355512462,3.3852644278556348,16.79754127924726,0.000330759639848
0.00042459439236810045,18.5220093098263,0.0011434691317322,3.734037076860982,18.52867996995337,0.000360082920389
0.00046748195921370044,20.3036937753785,0.001279637156467,4.093224665116305,20.311876881195342,0.0004029541279509
0.0005035980120893004,22.199184743324,0.001394305624347,4.475355644254119,22.208933545888893,0.0004390549790021
0.0005294754261910004,24.1934970150978,0.0014764664141199,4.877408998243717,24.20474768778533,0.0004649206994696
0.0005548226665759004,26.2527729580304,0.0015569439023419,5.292559028338928,26.26564668866869,0.0004902558371994
0.0006178274492680005,28.3859564547063,0.0017569840873894,5.72260882126879,28.40166469842165,0.0005532277562265
0.0006568160703331004,30.5968541761146,0.0018807729592711,6.168325801904704,30.614978817366,0.0005921940544735
0.0007001184713504005,32.8595437373243,0.002018258082501,6.624484017444579,32.88043162385506,0.0006354698832456
0.0007291032714177004,35.1702535991935,0.0021102848227147,7.0903231255974095,35.193629741675835,0.000664435850679
0.0007599597232546005,37.4839977760979,0.0022082540572968,7.556773951661337,37.51006838717594,0.0006952713317742
0.0007915940116091005,39.8173411661771,0.0023086929228224,8.027175979101305,39.84629424137583,0.000726883133701
0.0008272314904714005,42.1789691373716,0.0024218419182102,8.503280178094116,42.21114261627672,0.0007624940836159
0.0008649847928558004,44.4933358352253,0.0025417086532806,8.969856504381422,44.52895444836096,0.0008002178987507
0.0008997537731152004,46.8059507787683,0.0026521001656042,9.43607967699969,46.845048123590864,0.0008349584639185
0.0009278905146680004,49.0666178477677,0.0027414343200344,9.891830158109968,49.108984118676645,0.0008630713270957
0.0009389922022407005,51.3381952215828,0.0027766821780777,10.349780156671091,51.38309281267775,0.0008741633757366
0.0009751928046441004,53.6231436514014,0.0028916190907085,10.810425760122524,53.67198072412147,0.0009103316926454
0.0010156981205467004,55.9063895723711,0.0030202234686992,11.270728137790014,55.95957060854014,0.0009507993332275
0.0010580644113910005,58.2115193819488,0.0031547364421299,11.73544230740088,58.26935938243573,0.0009931244656537
0.0010964401192041005,60.5435244296841,0.0032765793144365,12.205574525024316,60.60600495244611,0.0010314613456635
0.0011314455457284004,62.878460511553,0.0033877215436511,12.676297639129084,62.94555176046848,0.0010664300726454
0.0011759133239561004,65.2838406725091,0.0035289067395241,13.161222279577837,65.35640148678665,0.0011108494678181
0.0012416892060438005,67.6912697266257,0.0037377451651525,13.646559976887744,67.77095877108043,0.0011765501650324
0.0012824579142569005,70.0854446706954,0.0038671858137291,14.129225645612191,70.17080953286214,0.0012172701059535
0.0013257278584552004,72.4875248570548,0.0040045678865587,14.613485011182249,72.57895201113942,0.001260486477146
0.0013641427914791004,74.8999309708865,0.0041265352989096,15.09982608373072,74.99727812333919,0.0012988522831938
0.0014013424247268005,77.282417358829,0.0042446441344711,15.580135339539924,77.38573589726676,0.0013360029408832
0.0014468184619917004,79.6513334501019,0.0043890305527871,16.057708823540544,79.76144120949805,0.0013814172313513
0.0014870386638918005,81.9978511706576,0.0045167296938199,16.530766796004574,82.11450066017318,0.001421581104151
0.0015301767812585004,84.3894455820439,0.0046536932164592,17.012912229340053,84.51313773651506,0.001464657012973
0.0015770102272350003,86.7547385113598,0.0048023894074346,17.489755283890137,86.88596057034302,0.00151142082078
0.0016143240455295004,89.1291213615262,0.0049208607805196,17.968430866483683,89.2672605734034,0.0015486775907488
0.0016636390028410004,91.4184918383657,0.0050774357699836,18.42996795461453,91.56468759285328,0.0015979150220169
0.0017042914085492005,93.7447423760741,0.0052065071581072,18.89894006301654,93.89846920196888,0.001638501696857
0.0017441471726578005,96.0650234314554,0.005333049209152,19.36670872378141,96.22638390302652,0.0016782914190779
0.0017813642824481004,98.3400415795951,0.0054512135327362,19.82535238244637,98.50888333249858,0.0017154454298782
0.0018192595631161003,100.586172138023,0.0055715310488571,20.27817230302544,100.76268205334668,0.0017532750434375
0.0018598015102671004,102.823893929728,0.0057002517310615,20.729297016233165,103.00849930905632,0.0017937451527545
0.0019024605155618004,105.056401117246,0.0058356940728722,21.1793704652368,105.24949624081046,0.001836326800641
0.0019272319944555005,107.305015447593,0.0059143435183597,21.63269111423475,107.50490165943548,0.0018610525270612
0.0019723378034122003,109.469484630972,0.0060575544617972,22.06904810160396,109.67834049398208,0.0019060734563449
0.0020133332327468005,111.607990610475,0.0061877149499346,22.50017090707176,111.8255019276506,0.0019469899827106
0.0020553655779940003,113.769422627259,0.0063211676460944,22.935915601655417,113.99592832597594,0.0019889396911172
0.0020918139455010005,115.90383322344,0.0064368912129291,23.366212777845504,116.1388128661552,0.0020253149754756
0.0021270271760091006,118.057690810813,0.0065486932197924,23.8004304674599,118.30119430667352,0.0020604563428075
0.0021671156758336003,120.097999449236,0.0066759742067351,24.21175668896598,120.35052579462295,0.0021004615268491
0.0022148916040578004,122.148750144069,0.006827662778847,24.62518802904432,122.41142430937336,0.0021481360724435
0.0022493723960640005,124.21882104786,0.0069371392934667,25.04251432324858,124.49022995005816,0.0021825422826147
0.0022829814364887006,126.287083134122,0.0070438479968151,25.459475959839,126.5672554231166,0.0022160774875663
0.0023234446338115003,128.281925299239,0.007172318648315,25.86163614032658,128.57171391185804,0.0022564502995997
0.0023613253145600005,130.241212240976,0.0072925898096915,26.256628387780765,130.54036050465805,0.0022942448866138
0.0023974747699868006,132.168031332589,0.0074073643306716,26.645075116649945,132.4763830683207,0.0023303108510174
0.0024297882897189003,134.097571740593,0.007509959755821,27.034070462903543,134.41475831291586,0.0023625486382294
0.0024650225642703005,136.01990078031,0.0076218285775217,27.421611997310496,136.34642688011442,0.0023976991505621
0.0025015460762934003,137.942441940768,0.007737790728195,27.809196295258825,138.27862138904322,0.0024341345313171
0.0025249718454509002,139.805833069893,0.0078121675452701,28.18485594689043,140.14982884682152,0.0024575030752972
0.0025615141326254002,141.665083366972,0.0079281893070491,28.55968080678156,142.01883064228923,0.0024939550055638
0.0026067292586715004,143.505483786099,0.0080717473322455,28.93070553127756,143.87031528402437,0.0025390564905307
0.0026444583472365005,145.344068098599,0.0081915371884394,29.301364128677555,145.71905749669307,0.0025766891962025
0.0026788481615316003,147.180151946346,0.0083007248488263,29.67151863238336,147.5649399603665,0.0026109899244226
0.0027078521565095004,148.945400074211,0.0083928125328811,30.02739265496093,149.33912316726858,0.0026399178706229
0.0027364891967217005,150.662989376563,0.0084837351355549,30.373658658315097,151.06556729675248,0.0026684790032281
0.0027874345207056003,152.399409973673,0.0086454865392037,30.723721050692475,152.81439172092024,0.0027192872711469
0.0028237416539756005,154.125911406981,0.008760761687336,31.071783739647373,154.55119026672273,0.0027554951534935
0.0028526561416064005,155.854715778515,0.0088525651855638,31.420310700948622,156.2892713788006,0.002784329661345
0.0028839728094259003,157.53647195865,0.0089519956058907,31.75935274686384,157.98065016486774,0.0028155587668822
0.0029282748774026005,159.181060022402,0.0090926546717167,32.09090170051624,159.63692723785445,0.0028597352994205
0.0029692703758887004,160.805704234847,0.0092228153794101,32.41842997374516,161.2728164622845,0.0029006128936049
0.0030079368958723005,162.476986398684,0.009345581580358,32.755360457974696,162.9552358258713,0.0029391666762798
0.0030464165943805003,164.056301124792,0.0094677546231216,33.073750306758065,164.5455120865011,0.0029775327065993
0.0030820329174496004,165.63990507615,0.0095808364488659,33.39300486335184,166.13973778164302,0.0030130425081465
0.0031192335992730005,167.171097197917,0.0096989486136552,33.70169319510006,167.68176928655038,0.0030501305836554
0.0031642398859441003,168.707092065843,0.009841843573836,34.01134976047395,169.23004917132607,0.0030949987978224
0.0032055679425647006,170.216612579943,0.0099730601536064,34.31566909611651,170.75128360873128,0.0031361982931835
0.0032476774785055004,171.70253670011,0.0101067579302184,34.615231398742175,172.24910551095485,0.0031781750911044
0.0032970105036096006,173.079192990461,0.0102633902849239,34.89276530687694,173.63868253624392,0.003227350366981
0.0033444759419558002,174.508744145264,0.0104140930516731,35.18096281968522,175.0811379404953,0.0032746617454557
0.0033879135202202005,175.8850087788,0.0105520073626626,35.45841776980608,176.4695567811987,0.0033179563757636
0.0034429134483694003,177.191671296077,0.0107266321345363,35.72184093328912,177.7903074772728,0.0033727726165209
0.0035030606766568006,178.413484475506,0.0109175995843488,35.96815847026201,179.02697958856177,0.0034327155269927
0.0035641349692087003,179.54167616884,0.0111115104632011,36.19560191563815,180.1700160785505,0.0034935786760975
0.0036360354222913006,180.616100388645,0.0113397944017383,36.41220583835084,181.2611868277162,0.0035652258108383
0.0037122615189759006,181.654296000639,0.0115818122587119,36.62150607372882,182.3169372454477,0.003641177743728
0.0037957305162785006,182.557550060234,0.0118468263251477,36.80360209214318,183.2387241042996,0.0037243399101588
0.0039008483211751006,183.345760345234,0.0121805753556944,36.96250528559917,184.0491483294961,0.0038290614652508
0.0040272852358391,184.065227137597,0.0125820125597526,37.10754979093955,184.7946479248912,0.0039550072394041
0.0041431586185339,184.628422556468,0.0129499105498086,37.22108998738395,185.38146871617147,0.0040704165871733
0.004271721570830301,185.147568662747,0.0133580979233497,37.3257498424098,185.92653538793348,0.0041984491017747
0.004402360007205801,185.552998971839,0.0137728749588419,37.407484592722746,186.3579118074539,0.0043285317479806
0.004543748915325401,185.807210293166,0.0142217847421216,37.45873359510227,186.6394969540553,0.0044693000640338
0.0046827755617163,185.991109107617,0.0146631943444127,37.49580759609559,186.8500772270431,0.0046076971677415
0.0048281070776346,186.127157321206,0.0151246219074533,37.52323491595513,187.0138038979595,0.0047523501176939
0.0049677180128071,186.213113160043,0.015567886626626,37.54056361306467,187.1261665880955,0.0048912894943503
0.005120095780360701,186.303945004473,0.0160516860386087,37.55887531290176,187.2458323849348,0.0050429122626462
0.005281147967470401,186.353649999748,0.016563026732682,37.5688958399492,187.3258013341349,0.0052031414847372
0.0054454131910895,186.37727707197,0.0170845688176726,37.57365905770916,187.3801669668319,0.0053665408824467
0.0056139999962335,186.402137747814,0.0176198319240048,37.578670969959305,187.4365863580161,0.0055342113254272
0.005784712579289501,186.42292051815,0.0181618443752076,37.58286077645904,187.4893092017476,0.0057039673490371
0.005961127594607601,186.424224049047,0.0187219620488426,37.58312356828788,187.52350822152928,0.0058793635804536
0.006136134232725601,186.390152533437,0.0192776081248672,37.5762547507409,187.52185531103507,0.0060533291768261
0.0063192644711915005,186.35739329564,0.0198590466319965,37.569650488401024,187.52302484325432,0.0062353376515709
0.006491628543260901,186.3177919344,0.0204063025608168,37.56166685397504,187.51529027603047,0.0064066156502936
0.0066708342468089,186.283231023991,0.0209752806695817,37.55469937443659,187.51389025383816,0.0065846610706329
0.0068456520110254,186.265337347444,0.0215303270709691,37.55109200924471,187.52844085455416,0.0067583164217084
0.007037498107024101,186.245168206961,0.022139438425765,37.54702591052334,187.5438653514064,0.0069488521794122
0.0072142485938246,186.228904244409,0.0227006212213566,37.543747095672856,187.560404028888,0.0071243633076963
0.0073949471271676,186.225425678919,0.0232743390647206,37.54304581687007,187.59055125363497,0.0073037629609048
0.0075759210072143,186.212715143291,0.0238489311338689,37.540483372887465,187.6114471809928,0.0074834037295516
0.0077650225089401,186.203613944364,0.0244493284018483,37.538648571183785,187.6374890016669,0.0076710777783025
0.0079511214744646,186.181578170193,0.0250401926173886,37.53420615911091,187.6499317384421,0.0078557375750813
0.0081382930214143,186.167983715372,0.0256344622789539,37.531465517018994,187.67107541808087,0.0080414272704069
0.0083191727669184,186.146452090413,0.0262087554709294,37.52712474142726,187.68304007297007,0.0082208422213771
0.0085108912385581,186.118493692397,0.0268174616183854,37.52148832838724,187.69053323919,0.0084109729903766
0.0086954650918568,186.095531257689,0.0274034836026088,37.5168591015501,187.7017252228351,0.008593984160938
0.0088819003774035,186.056484893123,0.0279954156342196,37.5089873544536,187.6970293422647,0.0087788070088533
0.0090633100395743,186.020914883288,0.0285713913116119,37.50181644047085,187.694891686839,0.0089586149141794
0.0092488997042575,185.994768474761,0.029160638496981,37.49654532451182,187.7030286970672,0.0091425324638799
0.0094359791577344,185.975844872795,0.0297546157617702,37.49273032635547,187.71872355158573,0.0093278921520411
0.0096197481793218,185.964481234188,0.0303380824053102,37.49043941681231,187.7414279290364,0.0095099383946229
0.0098051107692629,185.928989722324,0.0309266086283732,37.48328432802052,187.74006156415427,0.0096935296993272
0.0099938640700079,185.898415852017,0.0315259003582386,37.47712063576663,187.74427882364063,0.0098804446841229