File: example/data/02 processed data/test_ID_118.csv
Strain,Stress_MPa,Displacement(mm),Force(kN),True Stress (MPa),True Strain
-9.65386431783282e-06,-0.689072262341776,-3.06510192091192e-05,-0.13891696808810206,-0.6890656101316501,-9.653910916685918e-06
-7.36425926548794e-07,-0.686532327098689,-2.3381523167924206e-06,-0.13840491714309572,-0.6865318215184839,-7.364261977346758e-07
3.41773993412375e-05,-0.51095597626908,0.00010851324290842906,-0.10300872481584651,-0.5109734394155268,3.417681530730064e-05
8.18470693117009e-05,0.378688043774418,0.00025986444506465034,0.07634350962492267,0.37871903828098435,8.184372002317656e-05
0.0001145352089279,2.04086613566202,0.0003636492883460825,0.41143861294946327,2.0410998866912617,0.00011452865027154188
0.0001611864397836,4.77053584425344,0.00051176694631293,0.9617400262014936,4.771304789942036,0.00016117345064526746
0.0002103160641503,8.11219081567506,0.0006677535036772025,1.635417668440092,8.113896939719048,0.0002102939508272794
0.0002777581297742,11.8783174524673,0.0008818820620330849,2.3946687984174075,11.88161675170776,0.00027771956212631143
0.0003717678610004,16.0480480197084,0.00118036295867627,3.2352864807732136,16.05401416819392,0.00037169877245196156
0.0004514191535986,20.4277377919669,0.001433255812675555,4.118231938860528,20.436959264070886,0.000451317294625488
0.0005396600257232,25.1099982782671,0.00171342058167116,5.062175652898648,25.123549140583858,0.0005395144616193033
0.0006281975759433,29.911599460666,0.0019945273036199775,6.030178451270266,29.930389854939776,0.0006280003424427727
0.0007074580040404,34.8154973917735,0.0022461791628282696,7.018804274181538,34.84012789406796,0.0007072078735909839
0.0008021148982553,39.7044558474943,0.0025467148019605776,8.004418298854851,39.7363033830567,0.0008017933760206845
0.0008937744769696,44.5410551180481,0.0028377339643784797,8.979476711798496,44.580864776289914,0.0008933752983945664
0.0009790771595812,49.3526165820054,0.00310856998167031,9.94948750293229,49.400936601666416,0.0009785981761546853
0.0010842931039497,54.1332160043723,0.0034426306050402973,10.913256346481456,54.19191227718046,0.001083705682768149
0.0011918855239027,58.9412792267178,0.0037842365383910725,11.88256189210631,59.01153048418843,0.0011911757922414981
0.0012919172377888,63.7366403186669,0.00410183722997944,12.849306688243248,63.81898278297333,0.001291083430776623
0.0013994058987098,68.5664934324542,0.004443113728403615,13.823005075982767,68.66244578781742,0.001398427642820256
0.0014977632904207,73.2831157190681,0.004755398447085722,14.77387612896413,73.39287647959978,0.001496642761701979
0.0015850018540947,78.0602261641591,0.005032380886750672,15.736941594694477,78.18395176736034,0.0015837470643768998
0.0016832234787525,82.8173598446004,0.005344234545039187,16.695979744671444,82.95675996913913,0.0016818084457680803
0.0017666640751348,87.5735028250627,0.0056091584385529894,17.654818169532643,87.72821578643746,0.0017651053597053136
0.0018661283570736,92.212698985392,0.0059249575337086795,18.590080115455027,92.38477971785092,0.0018643893027473
0.0019499232970256,96.7782388307697,0.006191006468056279,19.51049294828317,96.96694897331093,0.0019480246643183545
0.002040223132213,101.250339579428,0.006477708444776274,20.412068459212687,101.45691286438237,0.0020381447034904855
0.0021237862072256,105.634373031017,0.006743021207941279,21.29588960305303,105.85871785546921,0.0021215341613109923
0.0022113329913088,110.018388948232,0.00702098224740544,22.179707211963574,110.26167624136386,0.002208891593010091
0.0023024033822979,114.395456613588,0.007310130738795832,23.06212405329934,114.65884109981462,0.0022997569130118562
0.0023934662769777,118.727760933757,0.007599255429404196,23.935516604245414,119.01193182569303,0.0023906064988476194
0.0024872009983071,123.034374682545,0.007896863169625042,24.803729936001073,123.34038590208151,0.0024841130331042616
0.0025773723234463,127.287754547665,0.008183157126942002,25.661211316809265,127.61582248334979,0.002574056595421296
0.0026655870584543,131.452584975692,0.008463238910592401,26.500841131099506,131.80298328500353,0.0026620406819899997
0.0027564468632492,135.551701339151,0.00875171879081621,27.327222989972842,135.92534240111542,0.002752654830354124
0.0028446542476834,139.446389021989,0.009031777236394796,28.112392026832985,139.84306578484453,0.0028406158754913364
0.0029297872598073,143.244223108515,0.009302074549888177,28.878035378676625,143.6638982084193,0.0029255037974961766
0.003029889207831,146.993640639738,0.009619898234863424,29.633917952971185,147.43901508513216,0.003025308344198885
0.0031241427088657,150.699392752155,0.009919153100648597,30.38099757883445,151.17019916125216,0.0031192727154330776
0.0032299911232023,154.475408601844,0.010255221816167302,31.14224237413175,154.97436280038102,0.003224785907396471
0.0033299395444121,158.080413334968,0.010572558053508417,31.86901132832955,158.60681155452914,0.0033244075730790583
0.0034302559647184,161.591596561055,0.010891062687980919,32.576865866708694,162.14589709900693,0.003424386056421736
0.0035424951426529,164.981200814883,0.011247422077922956,33.260210084280416,165.56564591739877,0.0035362352860533203
0.0036725176899941,168.254139066854,0.011660243665731268,33.92003443587777,168.87205536899177,0.0036657904624463698
0.0038188961002054,171.402285484376,0.012124995118152144,34.5547007536502,172.05685300397857,0.0038116226283677374
0.0039623765953638,174.365320497789,0.012580545690280064,35.152048612354264,175.05622156277255,0.003954547056794092
0.0041319057155442,177.071493467597,0.013118800646852835,35.69761308306756,177.80313618351573,0.004123392834680663
0.0043201420455319,179.492975844136,0.013716450994563782,36.18578393017782,180.26841099595788,0.004310837021609237
0.0045529736991349,181.502279650282,0.014455691494753307,36.59085957749685,182.32865475586277,0.004542640267738452
0.004795466434182,183.162948918033,0.01522560592852785,36.92565050187546,184.04130069155525,0.004784004812962088
0.0050616724910398,184.477357163912,0.016070810159051364,37.19063520424466,185.41112112788826,0.005048905290969913
0.0053369708174916,185.380670072257,0.01694488234553583,37.37274308656701,186.37004129855967,0.00532277965821432
0.0056325606917771,185.990182877984,0.017883380196392292,37.49562086820158,187.037783871119,0.005616757137020313
0.005945717494646,186.46201417525,0.01887765304550105,37.5907420577304,187.57066463501872,0.005928111468884619
0.0062687784966179,186.816025516352,0.01990337172676183,37.662110744096566,187.98713379993254,0.006249211436498774
0.0065911072340335,187.076612769905,0.02092676546805636,37.71464513441285,188.30965478565122,0.006569480862558318
0.0069117357320489,187.277263195549,0.02194476094925526,37.75509626022268,188.57167414737802,0.006887959181916697
0.0072546359673725,187.318272527698,0.023033469196407686,37.76336374158392,188.67719840492353,0.0072284476772607196
0.0075986869789664,187.351771340137,0.024125831158218317,37.77011710217162,188.77539880550557,0.007569962378127189
0.0079550138836045,187.414840113288,0.02525716908044429,37.78283176683886,188.9057277683827,0.007923539569543914
0.0083089730312482,187.430624410875,0.026380989374213033,37.7860138812324,188.98798041433497,0.008274643545587813
0.0086683617769299,187.494126966427,0.027522048641752433,37.798815996431685,189.1193938900216,0.008631007242177599
0.0090257318659114,187.498635951811,0.028656698674268694,37.7997250078851,189.1909483651362,0.008985243391100853
0.0093892325217344,187.44719218403,0.029810813256506717,37.789353944300444,189.2071774569921,0.009345427660605633
0.0097531543373489,187.461497549563,0.030966265021082757,37.792237905991904,189.28983846747442,0.009705899336029342
0.0101243460089295,187.422266606892,0.03214479857835116,37.78432894794943,189.31979448379803,0.010073438135481904
0.010505312435334,187.501104037158,0.03335436698218545,37.800222573891055,189.47086171703842,0.010450515082092559
0.0108881682002437,187.477173689581,0.03456993403577375,37.79539821581953,189.51845669041947,0.010829318885662163
0.0112680799799462,187.438064366964,0.035776153936329186,37.787513776379946,189.55013146753726,0.01120506807370273
0.0116479656202012,187.424539793972,0.03698229084413881,37.78478722246476,189.6076543898742,0.011580650288838834
0.0120126910510784,187.36927801506,0.03814029408717391,37.77364644783609,189.62008726431853,0.011941111350948396
0.0123807673817354,187.362254780475,0.03930893643700989,37.77223056374377,189.6819432730295,0.012304752453600269
0.0127531657029326,187.317217024716,0.040491301106811005,37.76315095218275,189.70610453244439,0.01267252894414327
0.0131306105864916,187.253055470285,0.04168968861211082,37.75021598280946,189.71180242279604,0.013045151394003418
0.0135071733588621,187.245102266835,0.042885275414387164,37.74861261699394,189.774254323751,0.013416764693318149
0.0138839696844642,187.1385526356,0.04408160374817383,37.727132211336965,189.73677862718716,0.013788470302502952
0.0142523117129308,187.115689548978,0.045251089688555284,37.72252301307397,189.78252068281,0.014151702335670506
0.0146262649341051,187.017808005954,0.046438391165783695,37.70279009400033,189.7531800132447,0.014520332799527101
0.014993258950831,186.941915450788,0.04760359716888842,37.68749015487886,189.74478399790604,0.0148819710439436
0.015363589031342,186.877419370187,0.048779395174510846,37.6744877450297,189.7485272406283,0.015246764144216319
0.0157418365747734,186.788071764004,0.04998033112490555,37.65647526762321,189.72845906383,0.0156192190084844
0.0161178730091148,186.753089931838,0.05117424680393949,37.64942293025854,189.76315251941912,0.015989359168123142
0.0164972528443552,186.740417693524,0.05237877778082776,37.646868207014435,189.82112158047457,0.016362651519262823
0.016874366928125,186.751303872058,0.05357611499679687,37.6490628606069,189.9026138979009,0.01673357642489892
0.0172562291733443,186.76490622128,0.05478852762536814,37.65180509421005,189.98776424457256,0.017109031423154064
0.017650693814886,186.713382641325,0.05604095286226305,37.641417940491124,190.0090033894687,0.017496729397962086
0.0180391107370435,186.67627476246,0.05727417659011311,37.633936992111934,190.04374875487875,0.017878336581927508
0.0184256082423725,186.603815803727,0.05850130616953268,37.619329266031365,190.04210461025832,0.01825791350891041
0.0188108175565719,186.560389269056,0.05972434574211578,37.610574476641695,190.06974271487925,0.01863608200610788
0.0191981058584841,186.523543111623,0.060953986100687016,37.603146291303204,190.10444183737945,0.019016147374933682
0.0196049821012614,186.441976679486,0.06224581817150494,37.58670249858438,190.0971682952111,0.019415279837094145
0.0199958929275759,186.410023306616,0.06348696004505347,37.58026069861379,190.13745817328203,0.019798600746480884
0.0203999403995714,186.384084460503,0.06476981076863919,37.575031427237406,190.18630867492595,0.020194648876630254
0.0207845316383945,186.34184836931,0.06599088795190253,37.566516631252895,190.21487641229882,0.020571480318023933
0.0211739711386316,186.28720348153,0.06722735836515532,37.55550022187645,190.23164335154434,0.02095291755529316
0.0215620667533252,186.167606240663,0.0684595619418075,37.53138941811766,190.18176459373092,0.021332893834326797
0.0219457310320001,186.089245947365,0.06967769602660032,37.51559198298878,190.17311048687358,0.02170838962015031
0.0223329898674459,185.980154968352,0.07090724282914074,37.49359924161976,190.1336478848062,0.022087260501228244
0.0227405954844608,185.926220277926,0.07220139066316304,37.48272600802988,190.15429324322108,0.02248588246312919
0.0231354235730144,185.89562737356,0.0734549698443207,37.476558478509695,190.19640145321853,0.022871857067433003
0.0235408613665123,185.852367833671,0.07474223483867655,37.467837355268074,190.22749265948147,0.023268048494269465
0.0239338769540387,185.796052571939,0.07599005932907286,37.4564841985029,190.24287243274188,0.023651951245300007
0.0243282034262705,185.706076774344,0.07724204587840884,37.43834507770776,190.22397198760484,0.024036986423054334
0.0247130109338657,185.591178682375,0.07846380971502359,37.4151816223668,190.17769551038157,0.024412584053226365
0.0251122584805592,185.467242007674,0.07973142067577545,37.39019598874708,190.12474332864713,0.024802127062281052
0.0255097869802946,185.431068643037,0.08099357366243534,37.38290343843626,190.16137570364924,0.025189842102792827
0.0259093453497385,185.306068147969,0.08226217148541973,37.35770333863055,190.10722706301692,0.025579385485907106
0.0262908321574989,185.208274261029,0.083473392100059,37.33798809102345,190.07755391380573,0.025951168722587122
0.0266875198280154,185.119142670118,0.08473287545394889,37.32001916229579,190.059513460672,0.02633761963189151
0.0270935794738167,185.079831725882,0.08602211482936802,37.312094075937814,190.09430685574782,0.026733046049273946
0.0274871400801958,185.05875450965,0.08727166975462167,37.30784490914544,190.1454904179233,0.02711615157289432
0.0278884216704024,185.040181394463,0.08854573880352762,37.30410056912374,190.20065999915954,0.027506621911038795
0.0282882621616043,184.866994610973,0.08981523236309365,37.269186113572154,190.0965606195561,0.02789553838829062
0.0286914551823847,184.74820115777,0.09109537020407141,37.24523735340643,190.04889589131437,0.028287562697081253
0.0290902842343142,184.669391757249,0.09236165244394759,37.229349378261404,190.04147685284528,0.028675192783677715
0.0294933853538558,184.603612431986,0.09364149849849215,37.216088266288374,190.0481979111564,0.029066822359534884
0.0299027629639509,184.588680011383,0.0949412724105441,37.21307789029481,190.10839155559196,0.0294643928957544
0.0303011705807163,184.480485037264,0.09620621659377425,37.19126578351242,190.07045968319144,0.02985115812345326
0.0307168718691207,184.41945402343,0.09752606818445822,37.17896193112349,190.0842427628409,0.030254552257303065
0.0311255860689637,184.352951969496,0.09882373576895974,37.165555117050395,190.09104564309007,0.030651007576789603
0.031538194694118,184.289204769192,0.10013376815382463,37.152703681469106,190.10135358922696,0.031051081146225318
0.0319658311933199,184.227742640201,0.10149151403879068,37.14031291626452,190.11673556256406,0.03146555720244725
0.0323832597346208,184.145569307263,0.10281684965742104,37.12374677234422,190.1088031071197,0.03186997382832175
0.0327945940067149,184.159390970302,0.10412283597131981,37.12653321961289,190.19882342969694,0.03226832622861342
0.0332051965106575,184.123171583854,0.10542649892133756,37.119231391304965,190.23701767846137,0.032665811757153385
0.0336283541624126,184.036197194325,0.10677002446566002,37.10169735437592,190.22503161227937,0.033075286102612685
0.0340510332296715,183.864378202425,0.10811203050420701,37.06705864560888,190.12515025434865,0.03348413002273302
0.0344810149962074,183.634462434376,0.10947722261295849,37.0207076267702,189.96636508739618,0.03389986617059468
0.0349028937299843,183.51683172634,0.11081668759270015,36.996993276030146,189.92210020174784,0.03430759983262089
0.0353075039426553,183.471849698638,0.11210132501793056,36.98792489924542,189.94978275523894,0.0346984878489093
0.0357177722849913,183.408695620998,0.11340392700484739,36.9751930371932,189.9596456462761,0.0350946861497335
0.0361328522891072,183.305124828834,0.11472180601791535,36.954313165492934,189.9284618281106,0.035495371416080376
0.0365527483610655,183.18743261634,0.11605497604638296,36.930586415454144,189.8834367436747,0.03590054244401722
0.0369760979587878,183.050236688493,0.11739911101915125,36.902927716400185,189.818720171666,0.036308879761683364
0.0373834708100473,182.935083456399,0.11869251982190018,36.87971282481004,189.77383180892488,0.03670164952313634
0.0378003491319538,182.821415248411,0.1200161084939533,36.85679731407966,189.73212857359886,0.03710342436689546
0.0382112574893726,182.732058235849,0.121320742528758,36.83878294034716,189.71447996466208,0.03749928762842476
0.0386321046567572,182.642066166483,0.12265693228520409,36.82064053916297,189.69791358135296,0.03790456342419778
0.0390680644620063,182.584122007247,0.12404110466687,36.808958996661,189.71733025556495,0.03832421955950247
0.0394984145479035,182.519688883094,0.1254074661895936,36.795969278831755,189.72892721775284,0.03873830310832548
0.0399311786875328,182.509183078934,0.12678149233291663,36.793851308713094,189.79698988057453,0.039154536624752274
0.0403624335515372,182.450390025608,0.1281507265261306,36.78199862916257,189.81453176946863,0.039569146242976326
0.0407991475038213,182.34675097407,0.12953729332463262,36.76110499637252,189.78634296390368,0.03998882913801884
0.0412377927973614,182.23021741907,0.13092999213162243,36.73761183168451,189.74498936641572,0.04041019082621887
0.041676191523309,182.124827849974,0.13232190808650607,36.716365294554755,189.7150970565992,0.04083113834082695
0.0421125447770005,182.050344894278,0.13370732966697657,36.70134953068644,189.71694819530668,0.041249945921910496
0.0425444820741454,181.960010170747,0.13507873058541164,36.6831380504226,189.7014045616677,0.04166434243679283
0.0429744799610111,181.859303336732,0.13644397387621024,36.66283555268517,189.67461232369982,0.042076707800797225
0.0434094058772304,181.698451456099,0.1378248636602065,36.63040781354956,189.58587328262104,0.04249362620730083
0.0438550805928726,181.539221449751,0.1392398808823705,36.5983070442698,189.50063863719717,0.04292066813256151
0.0442982707382329,181.439342203432,0.14064700959388945,36.57817138821189,189.47679130692651,0.043345148596826685
0.0447455676540075,181.379599153231,0.1420671773014738,36.56612718929137,189.49553227819868,0.04377337984251896
0.0451889588886852,181.277555193052,0.14347494447157552,36.54555512691928,189.46929918211217,0.04419769097351247
0.045622439442939,181.133408803792,0.1448512452313313,36.51649521484447,189.3971567780361,0.04461234392672546
0.0460577667484337,181.005617928656,0.14623340942627697,36.490732574417045,189.34233245937014,0.04502859045474781
0.0464925853442387,180.873573681734,0.14761395846795788,36.46411245423757,189.28285374264945,0.045444177684587556
0.0469325708120699,180.765933462988,0.14901091232832192,36.44241218613838,189.24974343564958,0.045864527533748256
0.047376230650446,180.648896019659,0.15041953231516605,36.418817437563256,189.20735978423477,0.0462882089361307
0.0478247525587242,180.570660313527,0.15184358937394932,36.40304511920704,189.20640746238684,0.04671635107497463
0.0482574448205274,180.495670028914,0.15321738730517448,36.38792707782906,189.2059298656784,0.04712920918568259
0.048698609715927,180.416426877556,0.15461808584806822,36.37195165851529,189.2024560364082,0.047549976135904684
0.0491409757217893,180.26723338231,0.15602259791668102,36.3418742498737,189.1257411213842,0.047971710967766625
0.0495862043864096,180.101801952672,0.15743619892685048,36.30852327365868,189.03236671465785,0.04839599543457998
0.0500479035066562,180.009292982642,0.15890209363363342,36.28987346530062,189.01838070813864,0.04883578551605408
0.0505049776722162,179.962536953,0.16035330410928642,36.280447449724804,189.05154086364666,0.04927097967552458
0.0509647058882665,179.923455644346,0.16181294119524614,36.27256865790016,189.09320164366068,0.04970850987353852
0.0514154218351061,179.78968482194,0.16324396432646185,36.245600460103105,189.03364730866082,0.05013727720043743
0.0518767266422645,179.664577715989,0.16470860708918977,36.22037886754338,188.98498790145922,0.05057592745155825
0.052327035423616,179.535594661298,0.16613833746998077,36.19437588371768,188.93016008293972,0.05100393617993724
0.0527852681160988,179.470044024665,0.16759322626861367,36.18116087537246,188.94341841731497,0.051439288440193985
0.0532434542753669,179.372940622719,0.1690479673242899,36.16158482954015,188.92337558500282,0.05187440707046295
0.0537014620484398,179.235385279677,0.17050214200379635,36.13385367238288,188.86058752001102,0.05230916716004925
0.0541578639614955,179.137773743906,0.1719512180777482,36.11417518677145,188.83949292469362,0.05274221495840695
0.0546120293564198,178.996335570947,0.17339319320663285,36.08566125110291,188.77168870383912,0.05317295460751283
0.0550694356173606,178.869633073769,0.1748454580851199,36.06011802767183,188.71988281622583,0.05360658051332106
0.0555232232545082,178.714242211339,0.17628623383306352,36.02879122980595,188.63703298039945,0.0540365902001571
0.0559761770781964,178.56466722116,0.17772436222327356,35.99863691178586,188.56003465344085,0.05446562544455713
0.0564314457145508,178.434539113501,0.17916984014369877,35.9724030852818,188.5038581210854,0.05489666786126784
0.0568844849380032,178.391290700285,0.18060823967816014,35.96368420517746,188.5389873891963,0.05532541514303616
0.0573552058364619,178.330442053402,0.1821027785307665,35.951417117965846,188.55862126428212,0.0557707013688984
0.0578207192800793,178.272514655195,0.18358078371425177,35.93973895448732,188.58035968042685,0.05621086660111908
0.0583003243742546,178.188052179056,0.18510352988825834,35.92271131929769,188.57647342071158,0.05666415362250714
0.0587819450785807,178.089766303802,0.1866326756244937,35.902896886846484,188.55822916572936,0.057119138976249685
0.0592697725122934,177.978131956849,0.18818152772653154,35.88039140250076,188.5268553500944,0.05757977687124269
0.0597518703675787,177.883580192881,0.18971218841706236,35.86132976688481,188.51245681708684,0.05803479616302113
0.0602286159533478,177.795698671786,0.19122585565187927,35.84361285223206,188.50408752524615,0.05848456029706092
0.0606992983338786,177.694880223832,0.19272027221006455,35.82328785312453,188.4808347709412,0.05892840601674527
0.0611647148012128,177.552856314424,0.19419796949385063,35.79465583298788,188.41282613303648,0.05936709244708877
0.0616437711255883,177.357738606946,0.19571897332374283,35.755320103160315,188.2907384529845,0.05981843446468837
0.062123791461395,177.206355650857,0.1972430378899291,35.72480129921277,188.21508633494466,0.060270480491228184
0.0626073764662955,177.092876233304,0.19877842028048817,35.70192384863409,188.18019660514153,0.060725676913768775
0.0630889799821313,177.054406654898,0.20030751144326686,35.694168381627435,188.224588572097,0.06117880233087275
0.063566259485445,176.967279790501,0.2018228738662879,35.676603605765,188.21642781809734,0.06162765694770881
0.064041685274581,176.831545718028,0.20333235074679465,35.64923961675444,188.15613591551966,0.06207456804166305
0.0645238450516572,176.672871240396,0.20486320803901162,35.61725084206384,188.07248420914271,0.06252760533692439
0.0650027258304322,176.541485550443,0.20638365451162224,35.590763486969315,188.01716333337566,0.06297735862330757
0.065478427410348,176.416118443354,0.20789400702785488,35.56548947818017,187.9675684488625,0.06342392590422209
0.0659642285018716,176.299304369948,0.20943642549344232,35.54193976098152,187.92875196812827,0.06387976842814667
0.0664435578683925,176.201686884168,0.21095829623214615,35.522260075848266,187.90915386316456,0.06432933476124457
0.0669366972496366,176.079825688993,0.21252401376759622,35.49769285890099,187.86602767290591,0.06479164277112166
0.0674364366087115,176.001165464795,0.214110686232659,35.481834957702674,187.870056902721,0.06525992018736101
0.0679453667217626,175.941529009695,0.21572653934159625,35.46981224835451,187.89594071984635,0.06573658447465013
0.0684506097114787,175.897377710409,0.21733068583394488,35.460911346418456,187.93766046133675,0.06620957076062775
0.0689577461651343,175.829315333995,0.21894084407430137,35.447189971333394,187.95410862918598,0.06668410475576042
0.0694573773807721,175.698635138207,0.2205271731839514,35.42084484386253,187.90220154428803,0.06715139589977455
0.0699554031993974,175.572634868215,0.22210840515808675,35.39544318943214,187.85488933120158,0.067616968352311
0.0704591594196675,175.40200052761,0.2237078311574443,35.36104330636618,187.76067804531348,0.06808767738071062
0.0709589759161987,175.190483020275,0.22529474853393083,35.318401376887444,187.6218202856579,0.06855448626530893
0.0714610105439402,175.026754350307,0.22688870847701015,35.28539367702189,187.5343430884059,0.06902314753630473
0.0719645728066857,174.912169635939,0.22848751866122707,35.2622933986053,187.4996492024799,0.06949301434756386
0.0724572129464417,174.830155185572,0.23005165110495238,35.24575928541132,187.49786096931246,0.06995247633558838
0.0729464002875617,174.691428353851,0.2316048209130084,35.21779195613636,187.4345392133569,0.07040850926718242
0.0734215653564768,174.520145351914,0.23311347000681382,35.183261302945866,187.33368760989137,0.0708512712579345
0.0739088489927127,174.407286913162,0.2346605955518628,35.160509041693466,187.2975287448556,0.07130512190089472
0.0744026155515195,174.303391159031,0.2362283043760744,35.13956365766065,187.27201936076253,0.07176480065386018
0.0749145930470435,174.176650152519,0.23785383292436307,35.11401267074783,187.2250230169922,0.0722412100951088
0.0754292524605581,174.018801068813,0.23948787656227194,35.0821902954727,187.1449091475161,0.072719886493227
0.0759403577508243,173.900238971485,0.24111063585886716,35.05828817665138,187.1062853319334,0.07319503060370988
0.0764568865318944,173.856229020396,0.24275061473876472,35.049415770511835,187.14873499547147,0.07367498735180349
0.0769733790831293,173.831660475293,0.24439047858893553,35.04446275181907,187.21207077370755,0.07415468021150362
0.0774873883912107,173.776513750909,0.24602245814209395,35.03334517218325,187.24200196519624,0.0746318384179502
0.0780119182125504,173.687073943279,0.24768784032484747,35.01531410696504,187.23673575031927,0.07511852828148811
0.0785436662197345,173.578882251922,0.24937614024765706,34.99350266198748,187.21240404231156,0.07561167394561942
0.0790824848698746,173.484535865811,0.2510868894618518,34.9744824305475,187.20412404857623,0.07611112901671122
0.0796086080929135,173.368150713792,0.25275733069500034,34.95101918390047,187.16974787975943,0.07659857553944108
0.0801321556195875,173.241143756134,0.2544195940921903,34.925414581236616,187.12333004731585,0.07708339996441446
0.0806622655251425,173.095439869464,0.2561026930423274,34.89604067768394,187.05771020140605,0.07757406202000186
0.0811932561042165,172.949843682671,0.2577885881308874,34.866688486426476,186.99220463398234,0.07806529798321897
0.0817330154737642,172.823132426198,0.2595023241292013,34.841143497121514,186.9484881830128,0.07856439902780366
0.0822701460731074,172.675121672563,0.261207713782116,34.8113045291887,186.88112915575635,0.07906082215686239
0.0828104947809896,172.567397254104,0.262923320929642,34.78958728642737,186.85778880378393,0.07955997097275862
0.083347425814017,172.440360862057,0.26462807695950397,34.76397674979069,186.8128210463496,0.08005571603263535
0.0838883748238849,172.353517025485,0.2663455900658346,34.74646903233777,186.81197346393373,0.08055492246042029
0.0844228858451304,172.249799866285,0.268042662558289,34.72555965304306,186.79162505724292,0.08104794303524991
0.0849638564953636,172.122318139035,0.2697602443727794,34.69985933682946,186.7464940770493,0.08154667445172639
0.0855043412771822,171.971580103823,0.2714762835550535,34.66947054893071,186.67589677899656,0.08204470966232762
0.0860390030430539,171.778993706444,0.2731738346616961,34.63064513121911,186.55868706868546,0.08253713527112218
0.0865748737248248,171.637423102408,0.2748752240763187,34.60210449744545,186.4969113339533,0.08303043111017377
0.0871145122807241,171.504038920034,0.27658857649129903,34.575214246278854,186.4445296247271,0.08352694967484087
0.087663304875021,171.397227393759,0.27833099297819164,34.553681042581815,186.4224747935114,0.08403163810932489
0.0882124327642218,171.33555598863,0.28007447402640423,34.54124808730781,186.4494822013976,0.08453638007722299
0.0887586545966271,171.252467553957,0.28180872834429105,34.52449745887773,186.45260617039872,0.08503819826584211
0.0892897969759217,171.096187899242,0.2834951053985514,34.49299148048719,186.37333178011949,0.08552592147460718
0.0898286059763332,170.917432571279,0.2852058239748579,34.456954406369846,186.2707072762109,0.08602044165365022
0.090380469280859,170.760743707537,0.2869579899667273,34.42536593143946,186.19417985857265,0.08652668972185168
0.090945483848591,170.69333862549,0.2887519112192764,34.41177706689878,186.21712689651656,0.08704473662773263
0.0915070697833191,170.651570738362,0.29053494656203815,34.40335666085378,186.26739593055032,0.08755937411315085
0.0920734573878559,170.582863583115,0.29233322720644245,34.389505298355985,186.28901760433337,0.08807814373047546
0.0926319302954518,170.489814567015,0.29410637868805944,34.37074661671023,186.2826151860712,0.08858940069254362
0.0931972418903532,170.382733017705,0.2959012430018714,34.349158976369324,186.26193380069552,0.08910665209965182
0.0937546572766344,170.250788500491,0.2976710368533142,34.32255896169899,186.2125928274313,0.08961641676211579
0.0943179997894024,170.080704070027,0.2994596493313526,34.288269940517445,186.1223758806852,0.09013133798595725
0.0948650051080699,169.901916482606,0.3011963912181219,34.252226362893374,186.0196626575993,0.09063107266216086
0.0954158868723127,169.783672308243,0.3029454408195928,34.22838833734179,185.98373197797216,0.09113409652350737
0.0959547114577551,169.580304764962,0.3046562088783724,34.18738944061634,185.8523339776021,0.0916258660094281
0.0965108907821212,169.47257550127,0.3064220782332348,34.16567122105603,185.82852472603787,0.09213322114031681
0.097081449390539,169.310929365612,0.30823360181496134,34.13308336010738,185.74787978608478,0.09265342593027293
0.0976682584678831,169.212365323545,0.31009672063552884,34.11321284922667,185.73904235592684,0.09318816489319527
0.0982547685460912,169.151940879078,0.31195889013383954,34.10103128122213,185.77192567927395,0.09372234581387383
0.0988424478858965,169.067065769106,0.31382477203772136,34.08392045905177,185.7780684066103,0.09425730562304861
0.0994368440227934,168.970225161804,0.31571197977236903,34.06439739261968,185.77209108571455,0.0947980887287899
0.100016864938925,168.841404603878,0.3175535461810869,34.03842716814181,185.72839256424245,0.09532551144945371
0.100587316787236,168.708182444794,0.31936473079947425,34.01156958087047,185.6780858369673,0.09584396166946661
0.101166971797824,168.592775461438,0.32120513545809115,33.9883035330259,185.64879602186218,0.09637050091772464
0.101743200165608,168.456119721704,0.3230346605258054,33.96075373589553,185.59538442967096,0.09689365287213463
0.102331414230322,168.295428144067,0.3249022401812723,33.92835831384391,185.5173373145469,0.09742740438384552
0.102931823793837,168.141354679659,0.32680854054543246,33.897297103419255,185.44845097200272,0.09797192856399595
0.103510801451818,168.021028444463,0.3286467946095221,33.87303933440374,185.4130197595081,0.09849673502362923
0.104088245617357,167.931052189176,0.33048017983510847,33.854900121337884,185.41070079622415,0.09901987728487921
0.10466170978554,167.768418178608,0.3323009285690895,33.82211310480737,185.32734767319658,0.09953914310731037
0.105245615754792,167.632296850585,0.33415483002146457,33.79467104507793,185.2748611530149,0.10006758697107956
0.105841521078919,167.461977465833,0.3360468294255678,33.76033465711193,185.1864078837004,0.1006066026694007
0.10643796801757,167.387612831646,0.3379405484557847,33.74534274685984,185.20401021275813,0.10114581749830656
0.107040490273316,167.288280528355,0.3398535566177783,33.72531735451636,185.19490009309013,0.10169022963692094
0.107619874586496,167.099948591754,0.34169310181212476,33.68734963609761,185.0832241026085,0.10221345598403146
0.108201589759931,166.954108202119,0.3435400474877809,33.657948213547186,185.01880812653977,0.10273851199252225
0.108777804094273,166.728839626931,0.34536952799931675,33.612534068789294,184.86523668073477,0.10325833130064442
0.109372025346995,166.624530465624,0.3472561804767091,33.5915053418698,184.84859283514135,0.10379411230069202
0.109979906610232,166.532539446144,0.3491862034874866,33.57295995234263,184.8477725819957,0.10434191300745271
0.110591254788303,166.484949720974,0.35112723395286205,33.56336586374835,184.89672921398403,0.10489253548165607
0.111210940961435,166.399721603508,0.3530947375525561,33.54618387526721,184.90519121875496,0.10545035848712997
0.11185365790798,166.287956861423,0.3551353638578365,33.523652103262876,184.88787310241756,0.1060285845672712
0.11247509031753,166.157407692068,0.3571084117581577,33.49733339072091,184.84597712916002,0.10658734408176646
0.113085196700303,165.989125293289,0.359045499523462,33.463407659127064,184.76003817719183,0.1071356162643851
0.113667268589259,165.8093117951,0.3608935777708973,33.42715725789216,184.65640337351383,0.10765841519357626
0.114272615734905,165.616374599778,0.36281555495832335,33.388261119315246,184.54179093382652,0.10820182946144026
0.114871281138228,165.498573566848,0.3647163176138739,33.364512431076555,184.5096067390211,0.10873895532267862
0.115473228955233,165.372595976329,0.36662750193286475,33.339115348827924,184.46870361442487,0.10927873545879324
0.116054933450535,165.258647897017,0.3684744137054486,33.31614341603863,184.4377292808307,0.10980008626966613
0.116670462227605,165.069026118663,0.3704287175726459,33.27791566552246,184.327705695388,0.1103514561728842
0.117300821522867,164.901323380064,0.3724301083351027,33.244106793420904,184.24438408275347,0.11091579584598289
0.117920160483285,164.773983316662,0.3743965095344299,33.21843503663906,184.2041578728329,0.11146995937724305
0.118539501680857,164.699717165363,0.37636291783672093,33.20346298053718,184.22313956512323,0.11202381798143106
0.119156625391913,164.611476560506,0.37832228561932374,33.18567367459801,184.22602460823586,0.11257538860733982
0.11976367275571,164.468921522149,0.38024966099937924,33.15693457886524,184.16632361781222,0.1131176565738903
0.120369339297114,164.287544718584,0.38217265226833697,33.12036901526653,184.062727931105,0.11365839817530703
0.120984973378527,164.019387445243,0.3841272904768232,33.066308508960994,183.86326866886805,0.11420773934230906
0.121596329369605,163.830168105217,0.38606834574849586,33.02816189001175,183.75131518681673,0.11475296461951398
0.122216659802596,163.68584859756,0.38803789487324225,32.9990670772681,183.69098627010723,0.11530588988716223
0.12283940733626,163.618086294088,0.3900151182926255,32.98540619688814,183.7168350439468,0.11586066226790696
0.123465052547675,163.560304300184,0.3920015418388681,32.97375734691709,183.75428586531993,0.11641770628288027
0.124099727491178,163.442553218912,0.3940166347844901,32.95001872893266,183.72572953384133,0.11698247306158167
0.12472905741627,163.272782955175,0.3960147572966572,32.91579304376328,183.6376432749052,0.11754216879808625
0.125346591103285,163.09796413346,0.39797542675292985,32.88054956930554,183.54173795347506,0.11809106918988065
0.125971330722007,162.896613690184,0.3999589750423722,32.83995731994109,183.41691688684517,0.11864606822284861
0.126589942904383,162.673969573493,0.401923068721416,32.795072266016184,183.26685809383082,0.11919532049418154
0.127218511333774,162.477437421313,0.4039187734847324,32.7554513841367,183.14757513537887,0.11975310387147411
0.127842014358991,162.336541172542,0.4058983955897964,32.72704670038447,183.08997160011108,0.12030608507441887
0.128453734184589,162.209146785726,0.40784060603607003,32.70136399200236,183.04551740924865,0.12084831881392825
0.129078241082916,162.181610985918,0.40982341543825823,32.69581277476107,183.11572806797406,0.12140158399120957
0.129702600877943,162.029231537668,0.411805757787469,32.66509307799387,183.04484428635797,0.12195441302121517
0.130338999927574,161.870636887993,0.41382632477004744,32.63312039661939,182.96869381761346,0.12251758766917252
0.130983824659527,161.647142788219,0.4158736432939982,32.588063986104956,182.8203037959046,0.12308789522757985
0.131599838859438,161.484295098192,0.4178294883787156,32.55523389179551,182.735602311444,0.12363241804462684
0.132214767072317,161.25532525513,0.41978188545460643,32.50907357143421,182.57566052290775,0.12417568534786977
0.132836435200158,161.073195657205,0.42175568176050166,32.472356244492524,182.4695847746057,0.12472460728202045
0.133460505398047,160.888536469474,0.42373710463879916,32.435128952245954,182.3608018594421,0.12527534730419795
0.134115885120592,160.749110393463,0.4258179352578796,32.40702065532214,182.30811961623004,0.1258533915487351
0.134756638307441,160.60874620481,0.42785232662612516,32.3787232348897,182.25184092614316,0.1264182123548997
0.135395590557782,160.488455685444,0.4298810000209578,32.354472666185515,182.21788492068112,0.12698112814450083
0.136045289034347,160.349026942188,0.43194379268405175,32.3263638315451,182.16375665891428,0.1275531866119875
0.136687591299739,160.239115887957,0.4339831023766713,32.304205763012135,182.14181467068158,0.12811841122597523
0.137332291909063,160.093878311451,0.43603002681127495,32.27492586758852,182.07993754057318,0.12868542528891924
0.137976865992372,159.838890599227,0.43807654952578107,32.223520344804164,181.89295978780595,0.12925200684405755
0.13861983777437,159.620342818305,0.44011798493362475,32.17946111217029,181.74688884526776,0.12981686033614045
0.139267032649957,159.421176043688,0.4421728286636134,32.1393090904075,181.62329017285884,0.1303851018071327
0.139910283767112,159.242459840578,0.4442151509605806,32.103279903860525,181.5221175846462,0.13094956085961687
0.140567073625941,159.119966997621,0.4463004587623627,32.078585346720395,181.4869951139329,0.13152557173283108
0.141205525193071,158.91327950779,0.4483275424880004,32.03691714877047,181.3527126008408,0.13208518190969282
0.141847671561024,158.725205047124,0.45036635720625123,31.9990013375002,181.24000580110464,0.13264771491225225
0.142492134308655,158.534500840819,0.45241252642997964,31.960555369509112,181.12442022718454,0.13321195913114928
0.143121031077101,158.371023270652,0.45440927366979567,31.92759829136344,181.03724741388325,0.13376226816317757
0.143766889474072,158.152825356503,0.45645987408017863,31.883609591871004,180.88996511954358,0.1343271042518536
0.144390067224696,157.88859398356,0.45843846343840977,31.830340547085697,180.686138682859,0.13487180269503296
0.145017047904187,157.568370574774,0.46042912709579376,31.76578350787444,180.4184705186007,0.1354195258946529
0.14564480168936,157.311779643197,0.462422245363718,31.71405477606852,180.22342259273077,0.13596762407946342
0.146285087784895,157.097572400885,0.46445515371704155,31.670870596018418,180.07860457034235,0.1365263550556005
0.146931996237601,157.013619747301,0.4665090880543832,31.65394574105588,180.08394433326353,0.13709054801785714
0.147577676136829,156.886712487785,0.4685591217344321,31.628361237537458,180.03968893347914,0.13765335228409764
0.148241862537789,156.680354031809,0.47066791355748006,31.586759372812693,179.90694153656455,0.1382319573602382
0.14889753598307,156.47571683261,0.47274967674624724,31.545504513454176,179.77456551017022,0.13880281820003673
0.14955182695366,156.225118805746,0.4748270505778705,31.494983951238396,179.58887073919792,0.13937215072379308
0.15021204651919,155.9752043827,0.47692324769842825,31.444601203552324,179.40455903927432,0.1399463136552862
0.150861594200231,155.724398184474,0.47898556158573335,31.394038673989964,179.2172291504553,0.14051087420371805
0.151500041208599,155.47425112717,0.4810126308373018,31.343609027237473,179.0286065798123,0.14106547606548794
0.152146140656971,155.23263112553,0.4830639965858829,31.294898434906845,178.85067685530657,0.1416264124370536
0.152782106666329,154.932312307957,0.4850831886655945,31.234354161284134,178.6031973730523,0.14217824395392198
0.153414953701487,154.651749236705,0.4870924780022212,31.17779264611973,178.3776401857081,0.1427270670028438
0.1540519102569,154.407284373757,0.48911481506565746,31.12850852974941,178.19402148911465,0.14327914996580235
0.154680138133127,154.142908354071,0.4911094385726782,31.075210324180716,177.98575471052067,0.14382336893843764
0.155304564651054,153.858839370906,0.4930919927670964,31.01794201717465,177.753819437121,0.1443640015516177
0.155949405067029,153.545543854537,0.4951393610878171,30.954781641074657,177.49088006934542,0.14492200204931743
0.156587951552253,153.261934158316,0.49716674617840323,30.897605926316505,177.26090647910297,0.14547424956188182
0.157227964322667,153.010466593834,0.4991987867244677,30.846910065316933,177.06799077644396,0.14602745933310474
0.157859612440873,152.797579258964,0.5012042694997717,30.803991978607144,176.9181459026876,0.14657313902161354
0.158481804959045,152.442523036512,0.5031797307449678,30.732412644160817,176.60188923984924,0.14711035907774378
0.159123648880574,152.129637802381,0.5052175851958225,30.669334980960013,176.337060872376,0.14766424450019552
0.159758966009215,151.848297047744,0.5072347170792576,30.612616684825195,176.10742397435172,0.14821219560428125
0.160402244190646,151.599101896999,0.509277125305301,30.562378942435,175.91593805856408,0.14876670724346072
0.161043843727345,151.336697902457,0.5113142038343204,30.50947829713533,175.7085414296727,0.14931946576443123
0.161678532918119,151.041572115997,0.5133293420150278,30.449980938585,175.4617519053577,0.14986597034281085
0.162305465681452,150.711159263547,0.51531985353861,30.383369707531074,175.17240415120847,0.1504055031269599
0.162915530222913,150.260690830237,0.5172568084577487,30.29255527137578,174.74049094850628,0.15093023996404678
0.16354268307019,149.868648364756,0.5192480187478532,30.213519510334812,174.37856922643107,0.15146938814980426
0.164175847112645,149.469404559017,0.5212583145826478,30.133031959097824,174.00867066991626,0.15201340930172696
0.164836158415797,149.182175948081,0.5233548029701555,30.07512667113313,173.77279273547217,0.15258044057445255
0.165495268984103,148.948374840695,0.5254474790245269,30.027992367884114,173.59862619970082,0.15314612026973723
0.166154401316734,148.62318491144,0.5275402241806304,29.96243407814631,173.31758122218656,0.15371149881573792
0.166805947587375,148.232158508438,0.5296088835899155,29.883603155301103,172.95816417135995,0.15427005634791924
0.16747751256069,147.82481372757,0.5317411023801907,29.80148244747811,172.58214582541075,0.15484544918542906
0.168128562610695,147.412313793622,0.5338081862889567,29.718322460794194,172.19653422286038,0.15540294907703192
0.168788572803149,147.003460804136,0.535903718649998,29.635897698113823,171.8159651503898,0.1559678045440923
0.16940419249948,146.520119855896,0.5378583111858489,29.538456162948638,171.34124244501112,0.15649438192444473
0.170033270906753,146.003275202637,0.5398556351289407,29.43426028085162,170.8286896484402,0.15703218507778863
0.170681525282998,145.485602346165,0.5419138427735186,29.329897432986865,170.31730686132417,0.15758607946413083
0.171338205515898,145.04187522439,0.5439988025129762,29.240442045237025,169.89308984999778,0.1581468606065554
0.172009229347569,144.586576915618,0.5461293031785315,29.14865390618859,169.45680258487647,0.15871956599375367
0.172645666104878,144.079432558562,0.5481499898829876,29.0464136038061,168.95412216464777,0.1592624491056133
0.173287070870841,143.550001634343,0.5501864500149202,28.93968032948355,168.42536094106273,0.159809271929504
0.173927773404869,142.998953005913,0.552220680560459,28.828588925992058,167.87044250145894,0.16035519771171622
0.174585632508719,142.534216485368,0.5543093832151827,28.73489804345019,167.41864282460065,0.16091543221529617
0.175276194926004,142.070139894871,0.5565019188900626,28.641340202805996,166.97165342824908,0.16150317948545656
0.175939365714589,141.551881301951,0.55860748614382,28.536859270473325,166.45642951392304,0.1620672883806787
0.1766007933495,140.997603965686,0.5607075188846624,28.425116959482303,165.89789268640476,0.16262959772089616
0.177256195658121,140.402705057861,0.5627884212145342,28.305185339664778,165.28995441652668,0.16318647295046115
0.17789524643116,139.777470405956,0.5648174074189329,28.17913803384073,164.64321794934773,0.16372915634423535
0.178521249932308,139.140409758363,0.5668049685350779,28.050706607285985,163.97992962451949,0.16426047456988926
0.179126831783991,138.453255126731,0.5687276909141714,27.912176233548966,163.2539480677629,0.16477419149795597
0.17974391634865,137.824005371658,0.5706869344069637,27.78531948292625,162.59703186401717,0.16529739488179923
0.180377626912006,137.137591460763,0.572698965445619,27.64693843848982,161.8741447688836,0.16583441008798216
0.181048813386378,136.504571594489,0.5748299825017501,27.519321633448982,161.2185623034871,0.16640286861033293
0.181727254076398,135.801219431701,0.5769840316925636,27.377525837430927,160.48000213925044,0.16697714284478804
0.182375686187994,135.037765119168,0.5790428036468809,27.22361344802427,159.66537019406942,0.1675257078982066
0.183017657442142,134.273883921191,0.5810810623788008,27.0696149985121,158.84837561210546,0.16806851087145344
0.183646800875197,133.511210543241,0.5830785927787504,26.915860045517384,158.03011724048207,0.16860018188688966
0.184299767732747,132.648865174948,0.5851517625514717,26.74201121926952,157.0960202167034,0.1691516866233197
0.184942563247387,131.82296164764,0.5871926383104537,26.575509068164223,156.2026380696165,0.1696943035789654
0.185614412416155,131.025716751328,0.5893257594212921,26.41478449706772,155.3459781775313,0.17026113170725235
0.186304526239929,130.175199604057,0.5915168708117745,26.243320240177894,154.42742849447905,0.17084303510369678
0.186982987175798,129.370707156286,0.5936709842831587,26.08113456270726,153.56082843341372,0.17141478290122736
0.18762764200859,128.462133446712,0.5957177633772732,25.897966102857136,152.5651806327114,0.17195773915747103
0.188275113062771,127.534882062795,0.5977734839742979,25.711032223859476,151.54652640261492,0.17250277078288342
0.188895941155306,126.584558000467,0.5997446131680966,25.51944689289415,150.49586721969362,0.17302509592692214
0.18956295124295,125.606579785258,0.6018623701963662,25.322286484708016,149.41693374488457,0.17358597180101154
0.190209127977999,124.561462881058,0.6039139813301467,25.111590916821292,148.25419011532793,0.17412902947999812
0.19088863455399,123.593729979612,0.6060714147089182,24.91649596388978,147.18636833485465,0.1746997801691379
0.191532761195089,122.552685011414,0.6081165167944075,24.706621298301062,146.02553916352213,0.17524051293618165
0.192203248172868,121.494863783049,0.6102453129488559,24.49336453866268,144.84657123847114,0.17580306432008158
0.192898673008243,120.407175488143,0.6124532868011715,24.27408657840963,143.63355986047642,0.17638620489693155
0.193579607384482,119.272007519539,0.6146152534457303,24.045236715939065,142.36063590713036,0.17695686535532554
0.194287089964746,118.125447148259,0.6168615106380685,23.81409014508901,141.07569652547863,0.1775494299249902
0.194955856893168,116.916883512925,0.6189848456358084,23.570443716205677,139.710514723466,0.1781092448628282
0.195603017074033,115.674006292857,0.6210395792100547,23.319879668639974,138.30019092078052,0.17865067490558675
0.19627074320664,114.316792317502,0.623159609681082,23.046265331208406,136.75383410665722,0.17920900382832597
0.196932147235907,112.898604461013,0.6252595674740047,22.76035865934022,135.1319690574576,0.17976173928485367
0.197586832911545,111.531604900749,0.6273381944941553,22.484771547991,133.56878148262973,0.18030855950000263
0.198228492953288,110.190188369815,0.6293754651266894,22.214341975354706,132.03302334860237,0.18084421018238878
0.198836609976507,108.807248912156,0.6313062366754097,21.935541380690648,130.4421134267191,0.18135159484667834
0.199483187021125,107.287079704722,0.6333591187920719,21.629075268471958,128.68904829040943,0.18189078654337557