File: example/data/02 processed data/test_ID_133.csv
Strain,Stress_MPa,Displacement(mm),Force(kN),True Stress (MPa),True Strain
-0.0001785675344473,0.47052067339809,-0.0005669519218701774,0.09485696775705496,0.4704366536815348,-0.0001785834795277281
-0.000220711282153,0.987044571248113,-0.0007007583208357749,0.19898818556361955,0.9868267193752507,-0.0002207356424724512
-0.0002545767592342,1.76743414201564,-0.0008082812105685849,0.35631472303035305,1.7669841943596059,-0.0002546091693981082
-0.0002780074877352,2.66794088572952,-0.0008826737735592599,0.5378568825630713,2.6671991781864524,-0.00027804613898055157
-0.0003236385572146,4.08295210984307,-0.001027552419156355,0.823123145344363,4.081630709113064,-0.00032369093947473164
-0.0003338528211206,5.81244102164662,-0.001059982707057905,1.1717881099639587,5.810500521813946,-0.0003339085623803208
-0.0003221844330218,7.91147186887018,-0.001022935574844215,1.5949527287642284,7.90892291579174,-0.00032223634557680653
-0.0002887987511271,10.1400812792897,-0.0009169360348285425,2.0442403859048035,10.137152836479913,-0.0002888404615172093
-0.0002631127265759,12.64659236909,-0.0008353829068784824,2.549553021608544,12.643264889689874,-0.0002631473468021225
-0.0001935310723887,15.2256943507384,-0.0006144611548341225,3.0694999811088617,15.22274770578284,-0.00019354980194326014
-0.0001206288673188,17.9108107931343,-0.00038299665373719,3.6108194558958746,17.908650232315562,-0.00012063614356575534
-4.87561648883906e-05,20.7167517738593,-0.00015480082352064013,4.176497157610035,20.715741704493862,-4.875735350886191e-05
2.41931275616695e-05,23.6809511594337,7.681318000830066e-05,4.774079753741835,23.681524075705884,2.4192834912754077e-05
9.88240358998483e-05,26.6925209429257,0.00031376631398201833,5.381212222093821,26.695158805573623,9.881915312654335e-05
0.0001797364872362,29.783279082907,0.000570663346974935,6.004309063114051,29.78863222486774,0.00017972033656902904
0.0002850955705008,32.9053145773098,0.0009051784363400399,6.633711418785656,32.91469573674173,0.00028505493848104475
0.0003596811806594,36.004889608886,0.001141987748593595,7.258585745151419,36.01783989009004,0.0003596165108901068
0.0004500446860318,39.0148781551407,0.0014288918781509648,7.865399436076365,39.0324365937306,0.0004499434462959104
0.0005377992181231,42.0503911832179,0.0017075125175408424,8.477358862536729,42.073005850718,0.000537654655951478
0.0006071552027004,45.0435032519048,0.00192771776857377,9.080770255584008,45.070851649252056,0.0006069709585531666
0.0006854332660917,47.9981038652284,0.0021762506198411474,9.676417739230047,48.031003362326956,0.0006851984639985688
0.0007529747565596,50.8992757133307,0.00239069485207673,10.261293983807471,50.937601583070006,0.0007526914132921772
0.0008347752642651,53.6755994593138,0.0026504114640416923,10.821000850997661,53.72040652203703,0.0008344270331770845
0.0008997953151012,56.3582063743996,0.0028568501254463098,11.36181440507896,56.40891722446278,0.0008993907419670389
0.0009688366348246,59.054245673871,0.003076056315568105,11.905335927852393,59.11145959052178,0.0009683676155230637
0.0010424717958607,61.6359647102551,0.0033098479518577223,12.425810485587428,61.700218465076205,0.0010419287994775177
0.0011197116558145,64.1499710456879,0.003555084507211037,12.932634162810682,64.22180051598794,0.0011190852462736134
0.0011876277377366,66.5795924922827,0.0037707180673137047,13.422445846444193,66.65866426309373,0.0011869230657849082
0.001258635295243,68.92049335846,0.003996167062396525,13.894371461065537,69.00723912396653,0.001257843877840823
0.0013268151853977,71.2052846059032,0.004212638213637697,14.354985376550085,71.29976085879889,0.0013259357439479181
0.001405755700989,73.4271114932852,0.004463274350640075,14.802905677046297,73.53033207387404,0.0014047685514626549
0.0014689783249962,75.5593326485269,0.0046640061818629345,15.232761461943024,75.67032767043877,0.0014679004318085293
0.0015264969605576,77.7287083506365,0.00484662784977038,15.670107603488319,77.8473609876818,0.0015253330483939165
0.0015993450521381,79.8219851135971,0.005077920540538468,16.092112198901177,79.94964801054037,0.0015980674618639263
0.0016580352562818,81.9019231786645,0.005264261938694715,16.511427712818765,82.03771945485201,0.0016566622332971266
0.0017292767466253,83.972606180209,0.005490453670535327,16.928877405930134,84.11781805542995,0.0017277832691014686
0.0017874172767015,86.0234628612337,0.005675049853527262,17.342330112824715,86.17722268495355,0.0017858217474090294
0.0018452618245254,88.0938959648162,0.005858706292868145,17.759729426506947,88.25645226801379,0.0018435614203975044
0.00190078228201,90.1835813241967,0.006034983745381749,18.181009994958053,90.35500067770595,0.0018989780812683648
0.0019512600868569,92.2178556358224,0.006195250775770657,18.5911196961818,92.39779665682012,0.0019493588516948169
0.0020006809458185,94.242807108404,0.0063521620029737364,18.999349913054246,94.43135689686622,0.0019986822490872472
0.0020651575751644,96.345397762735,0.006556875301146969,19.423232188967376,96.54436619075695,0.0020630280685997302
0.0020947887559098,98.419735795761,0.006650954300013614,19.841418736425418,98.62590435166557,0.0020925977452133015
0.002146452285402,100.442198867484,0.006814986006151349,20.249147291684775,100.6577932547939,0.0021441519478170397
0.0022011882664342,102.476622011855,0.006988772745928584,20.65928699758997,102.7021923498113,0.002198769200770877
0.0022583643506965,104.432343500367,0.007170306813461387,21.053560449673988,104.66818978198793,0.0022558180788121752
0.0023123713861681,106.407451599589,0.007341779151083716,21.45174224247714,106.65350514594296,0.0023097019697837272
0.0023755178825266,108.318602488726,0.007542269277021955,21.837030261727165,108.57591526594827,0.002372700800392161
0.0024232894641994,110.133479143388,0.007693944048833095,22.20290939530702,110.40036444305179,0.0024203580331345824
0.002496274997188,111.923309224525,0.0079256731160719,22.56373913966424,112.20270058294471,0.002493164478155703
0.0025585779873355,113.728481412541,0.008123485109790213,22.927661852768264,114.01946460161624,0.002555310399076478
0.0026176699494275,115.52800087666,0.008311102089432313,23.29044497673466,115.83041505287228,0.0026142498186610477
0.0026745089955214,117.354983500759,0.008491566060780444,23.658764673753016,117.66885045980105,0.0026709388604932434
0.0027373926171371,119.090300315133,0.008691221559410291,24.008604543530815,119.41629722398828,0.0027336527813448188
0.0027934149910663,120.956237956876,0.008869092596635502,24.384777572106202,121.2941189252477,0.002789520658049833
0.0028626354637059,122.727921550017,0.009088867597266232,24.74194898448343,123.07924685063298,0.002858545925519161
0.002945893514712,124.476521450007,0.0093532119092106,25.09446672432141,124.84321602728048,0.0029415628733994205
0.0030256493706727,126.175802720416,0.009606436751885822,25.437041828435866,126.55756645851115,0.0030210813055382493
0.0031209213952989,127.896259064407,0.009908925430074007,25.783885827384452,128.2954132356998,0.0031160614292104517
0.0032258930012156,129.486714564716,0.01024221027885953,26.10452165624675,129.90442485098075,0.003220700971346711
0.0033512448283005,131.027946659817,0.010640202329854086,26.41523404661911,131.46705338842352,0.0033456419216690947
0.0034826160716619,132.387664864691,0.011057306027526533,26.689353236721708,132.84872027403856,0.0034765658074064312
0.0036431503622872,133.740784501998,0.01156700240026186,26.9621421556028,134.22802228950903,0.00363653016405238
0.0037987792329892,135.028209620321,0.012061124064740709,27.221687059456716,135.5411519788944,0.0037915820922994423
0.0039853033400028,136.143092864089,0.01265333810450889,27.44644752140034,136.68566438679858,0.0039773830548323775
0.0041920106263315,137.009037768471,0.013309633738602512,27.621022014123753,137.5833811106999,0.004183248628177127
0.0044177137254169,137.778569159138,0.014026241078198658,27.77615954248222,138.3872354351806,0.004407984272238701
0.0046576185294758,138.394043652498,0.014787938831085663,27.9002392003436,139.03863031458295,0.00464680538695508
0.0049204386241577,138.892612548781,0.015622392631700698,28.00075068983425,139.57602512417617,0.004908372829179885
0.0051807108255647,139.231127959791,0.01644875687116792,28.068995396693865,139.95244417166785,0.0051673371135719315
0.005462877640708,139.375296264105,0.0173446365092479,28.098059726843566,140.13668645373323,0.005448010245910589
0.0057401337411504,139.442366021888,0.01822492462815252,28.111580990012623,140.2427838520361,0.005723721947444231
0.0060209454604199,139.448240759938,0.01911650183683318,28.112765337203502,140.28785101210508,0.006002891997999776
0.0063288457032068,139.400914277078,0.020094085107681587,28.103224318258924,140.2831611544236,0.006308902659309023
0.0066279330249184,139.344246158846,0.02104368735411592,28.091800025623357,140.26781048979458,0.0066060648508403895
0.0069284112813937,139.227242898533,0.021997705818424997,28.068212168344253,140.19186649890852,0.006904520128295498
0.0072436008876623,139.100370913411,0.0229984328183278,28.04263477614366,140.10795848363355,0.007217492016433389
0.0075606526914451,138.999691316668,0.02400507229533819,28.02233776944027,140.0506197069314,0.007532214209258333
0.0078830291468803,138.903829063535,0.025028617541344948,28.003011939208655,139.99881199665612,0.007852120402707996
0.008218278399858,138.792540912288,0.026093033919549147,27.980576247917263,139.93317665332884,0.008184692238074246
0.0085216474700882,138.672970663822,0.027056230717530032,27.95647088582652,139.85469283344898,0.008485543199199192
0.0088435370410161,138.520106432383,0.02807823010522612,27.92565345676841,139.74511412454325,0.00880466199447821
0.0091649848420159,138.361040981546,0.02909882687340048,27.89358586187968,139.62911782486742,0.009123241227650746
0.0094842057355962,138.21112427847,0.03011235321051793,27.863362654539557,139.52194701607507,0.009439513017450784
0.0098082738507693,138.072078688197,0.031141269476192526,27.835331063540515,139.4263274471158,0.009760484963051886
0.0101220375346706,137.952504897944,0.032137469172579154,27.81122498742551,139.34886533052284,0.01007115279615135
0.0104406190950744,137.815978046736,0.03314896562686122,27.783701174221978,139.2548621787371,0.01038649225073178
0.0107856100484325,137.676563302788,0.03424431190377319,27.755595161842063,139.16148902738018,0.010727860229965415
0.0111197937295285,137.565554176045,0.035305345091252986,27.73321572189067,139.09525476277088,0.011058423354743255
0.0114396216652213,137.476464892443,0.03632079878707763,27.715255322316512,139.04914363868463,0.011374683965852388
0.0117733247338524,137.35658450456,0.03738030602998137,27.691087436119297,138.97372817826505,0.01170455835920402
0.0121014700336905,137.216840498649,0.03842216735696733,27.662915044527637,138.8773659820611,0.012028832670601048
0.0124488358562304,137.07290714844,0.03952505384353151,27.63389808112551,138.77930526986725,0.01237198623407437
0.0127919226451986,136.937221533896,0.04061435439850555,27.606543861233437,138.68891187900604,0.012710797104643729
0.0131341938914303,136.809768850969,0.0417010656052912,27.58084940035535,138.60665488129936,0.013048688251506577
0.01348148507521,136.668393075213,0.042803715113791746,27.552348043962944,138.51088597670943,0.013391418440346772
0.0138417820802069,136.511808180485,0.04394765810465691,27.52078052918577,138.40137488069425,0.013746859543033424
0.0141926184428554,136.368263712328,0.045061563556065894,27.491841964405324,138.30368644691174,0.014092846145684589
0.0145573771619996,136.230938312314,0.046219672489348725,27.464157163762508,138.21410346245946,0.01445243576871833
0.0149072832013721,136.105664512194,0.04733062416435641,27.438901965658317,138.13463019838824,0.014797261721762569
0.0152600514978114,135.967971962412,0.04845066350555119,27.411143147622262,138.04285021661138,0.01514478805021863
0.0156133104135784,135.845344483376,0.04957226056311142,27.3864214478486,137.96634001503446,0.015492676723097207
0.0159743078819109,135.710040045944,0.0507184275250671,27.35914407326231,137.87791400830437,0.015848061318751355
0.0163307422176227,135.58017122705,0.05185010654095207,27.33296251937328,137.7942960531801,0.01619882986046096
0.0167010936210133,135.446238471095,0.05302597224671723,27.30596167577275,137.70833878041483,0.01656316395593222
0.017049591450065,135.309077018561,0.05413245285395637,27.278309926941898,137.61604150121283,0.016905878365344316
0.0174151675258227,135.162218944129,0.05529315689448707,27.248703339136405,137.51609163020294,0.017265261419859783
0.0177738813926934,135.023324640998,0.056432073421801544,27.220702247625194,137.42321319841423,0.017617773016535106
0.018126407420169,134.895788617325,0.05755134355903657,27.194990985252723,137.34096464106761,0.017964082738023954
0.0184718780932154,134.732791735774,0.05864821294595889,27.162130813932038,137.2215594398758,0.018303345202121415
0.0188376751836926,134.57522186684,0.059809618708224,27.130364728354945,137.11030618414088,0.01866244339985931
0.0191986761825831,134.437873367537,0.06095579687970134,27.10267527089546,137.01890256499547,0.019016706955977063
0.0195689948116342,134.30320061101,0.06213155852693858,27.07552524317962,136.93137924695273,0.01937998388879513
0.0199426872836819,134.156071512164,0.06331803212569004,27.045864016852267,136.83150409353834,0.019746436779955433
0.0203078886258479,133.988446042529,0.06447754638706708,27.01207072217385,136.7094684819111,0.020104433342121423
0.0206779901586001,133.820498876065,0.06565261875355531,26.978212573414705,136.5876378348432,0.020467102717403138
0.021049417165052,133.711352154776,0.0668318994990401,26.956208594402842,136.52589818598503,0.02083093876056632
0.0214099429106142,133.59211362267,0.06797656874120007,26.932170106330272,136.45231314863966,0.021183969774405797
0.021766865560991,133.415164071259,0.06910979815614642,26.896497076765815,136.31919401139567,0.021533349869684457
0.0221397565532988,133.270418455585,0.07029372705672368,26.867316360645937,136.22099307594792,0.021898230527548544
0.0225021621904894,133.126942089166,0.07144436495480384,26.838391525175865,136.1225861319803,0.022252723544309648
0.0228679278920063,133.024889723555,0.07260567105712,26.81781776826869,136.06689330959534,0.022610375890150854
0.0232388533668143,132.906971734486,0.0737833594396354,26.794045501672382,135.99557736205105,0.02297294296853472
0.0236157346986519,132.790097889223,0.07497995766821977,26.77048373446736,135.9260336115829,0.023341197106658888
0.023995068728296,132.662682659144,0.0761843432123398,26.74479682408343,135.84593284723027,0.023711710910697043
0.0243697552901127,132.580276511052,0.07737397304610782,26.728183744628087,135.81122540592182,0.024077550590818814
0.0247247400331005,132.45836500125,0.07850104960509409,26.703606384252,135.73336364111546,0.02442403021618432
0.0251078078209343,132.337304266085,0.07971728983146639,26.679200540042736,135.66000386913836,0.02479778542140259
0.0254883396614925,132.214260953237,0.08092547842523867,26.65439500817258,135.5841829445063,0.025168928072180866
0.0258696609382155,132.132162940656,0.08213617347883422,26.63784404883625,135.5503771949638,0.02554070255620906
0.0262546020392773,131.987151861796,0.08335836147470542,26.608609815338077,135.4524220082251,0.02591586610017335
0.0266300266749473,131.851217110464,0.08455033469295767,26.581205369469544,135.36241853923994,0.026281619376907983
0.0270133856768622,131.685214152318,0.08576749952403748,26.547739173107306,135.24247763015475,0.02665496462668413
0.0274121704907973,131.530546358807,0.08703364130828142,26.516558145935488,135.1360841203423,0.027043184893655047
0.0277931700556413,131.393168111596,0.08824331492666113,26.488862691297754,135.04500077707104,0.027413950346324926
0.028194924463046,131.246989951623,0.08951888517017105,26.459393174247197,134.94748891931116,0.027804764294702588
0.0285865246389665,131.049971731329,0.09076221572871863,26.41967430103593,134.7962349771625,0.028185553591322673
0.0289756864578592,130.904501835648,0.09199780450370296,26.390347570066638,134.69754963676,0.02856382825192284
0.029372569793474,130.757607706441,0.09325790909427994,26.360733713618508,134.59829466482614,0.028949461090610678
0.029771326726226,130.644421250306,0.09452396235576754,26.337915324061694,134.5338790003076,0.029336764705875953
0.0301696686684307,130.511323424149,0.09578869802226747,26.311082802308437,134.44880680933397,0.02972351553811866
0.0305580507352671,130.363933025271,0.09702181108447304,26.28136889789463,134.3476007047062,0.03010045235299037
0.0309369713436757,130.18801051456,0.09822488401617034,26.2459029197353,134.2156332651391,0.03046806964880497
0.0313249123253651,130.049373053159,0.09945659663303419,26.217953607516858,134.1231582620179,0.03084429828333241
0.0317136721720214,129.896785842318,0.10069090914616795,26.18719202581131,134.01628992472055,0.03122117911743724
0.0321104319009845,129.776694065645,0.10195062128562578,26.16298152363403,133.94387976277477,0.0316056689904528
0.0325076042204805,129.624585850493,0.10321164340002557,26.132316507459386,133.83837058456453,0.03199041068838125
0.0328999689242294,129.486851389559,0.10445740133442835,26.1045492401351,133.74696477637178,0.0323703499445071
0.0332934652425622,129.361781583971,0.10570675214513497,26.079335167328555,133.6686835628529,0.03275124005535863
0.0336994348770817,129.22266834245,0.1069957057347344,26.051289937837918,133.5773992388991,0.033144051892995775
0.034101722791509,129.088622187159,0.10827296986304107,26.024266232931254,133.49076659652332,0.033533149188943144
0.0345119612923285,128.975730149876,0.10957547710314298,26.001507198215005,133.42693555645835,0.033929780526494556
0.0349148863284482,128.852423362214,0.11085476409282302,25.976648549822343,133.3512910770508,0.034319187904363
0.0353157678352601,128.74121563129,0.11212756287695082,25.954229071268063,133.2878105133538,0.03470646988283825
0.0357279377018015,128.623827186053,0.11343620220321976,25.93056356070829,133.2192912707236,0.03510450095372415
0.0361511815466354,128.49586793431,0.11478000141056739,25.9047669755569,133.14114538399573,0.03551306132463481
0.0365647348663211,128.404240478415,0.11609303320056949,25.886294880448464,133.0993074872196,0.03591210619315619
0.0369828884766694,128.283068813844,0.11742067091342533,25.861866672870953,133.02734724123133,0.03631542812442919
0.0374012657740549,128.149324642539,0.1187490188326243,25.834903847935863,132.94227159226025,0.03671880307520787
0.0378353598092014,128.005541212465,0.12012726739421443,25.805917108432947,132.84867692181018,0.03713715926276379
0.0382536719910308,127.871978697576,0.12145540857152279,25.77899090543132,132.76355142751717,0.03754014023427611
0.0386848768225323,127.732164446214,0.12282448391154005,25.75080435235674,132.67346749409123,0.03795537142919355
0.0391090456019639,127.602838266445,0.12417121978623537,25.724732194515315,132.59326348714742,0.038363659066139706
0.0395390777578188,127.45698550043,0.12553657188107467,25.695328276886684,132.4965171609087,0.038777420449952006
0.0399695717100044,127.322215065132,0.12690339017926397,25.66815855713061,132.4112294704544,0.039191454754108866
0.040387641760461,127.173372548919,0.12823076258946367,25.638151905862074,132.3096051608944,0.039593376167775224
0.040796529627254,127.01968788105,0.12952898156653142,25.607169076819684,132.2016503409338,0.03998631387859908
0.0412181186449352,126.86021246831,0.13086752669766927,25.575018833611296,132.0891517571505,0.0403912956819627
0.0416381251790007,126.705389053628,0.13220104744332722,25.543806433211405,131.98116390389694,0.040794594316713735
0.0420640109427173,126.550696918095,0.1335532347431274,25.51262049868795,131.87392681806625,0.04120337229151546
0.0424954995527409,126.429943106776,0.13492321107995237,25.48827653032604,131.80264669752304,0.04161735770571319
0.042921503857243,126.299397930745,0.13627577474674651,25.461958622838193,131.72035802619695,0.04202591322216978
0.0433651137182264,126.182466313957,0.1376842360553688,25.438385208893727,131.65438331490802,0.042451175852847536
0.0438073084703791,126.065308053839,0.13908820439345362,25.414766103653943,131.5878898911669,0.04287490199455758
0.0442623619493376,125.947970296551,0.14053299918914688,25.391110811784685,131.52272494460138,0.043310762437922035
0.0447030958983718,125.82648679934,0.14193232947733045,25.366619738746945,131.45132030528612,0.043732726289854584
0.0451566438164753,125.706208597265,0.14337234411730906,25.342371653208627,131.38267908441122,0.044166772572104905
0.0455823063606981,125.55639342543,0.14472382269521647,25.312168914566687,131.2795434160923,0.044573961188424695
0.0460440678730522,125.403259256969,0.14618991549694074,25.28129706620495,131.17733543769884,0.04501549465304745
0.0464925767764269,125.234158089151,0.1476139312651554,25.24720627077284,131.05661679914203,0.04544416949741839
0.0469465514632088,125.073298489939,0.14905530089568794,25.214776975571706,130.94505853417022,0.04587788136204759
0.047401808173022,124.928448562409,0.15050074094934485,25.185575230181655,130.85028291651756,0.046312629206062286
0.0478543558651252,124.795449020855,0.1519375798717725,25.15876252260437,130.76745484864708,0.04674460283001106
0.0482795320398584,124.645963095449,0.1532875142265504,25.12862616004252,130.66381186435473,0.047150279378649046
0.0487570240686435,124.524364194996,0.15480355141794308,25.104111821711196,130.59580161718395,0.047605676339323215
0.0492078237266591,124.40530916787,0.15623484033214263,25.08011032824259,130.52702369206307,0.04803542583243542
0.049678036123162,124.305680487825,0.15772776469103936,25.06002518634552,130.4809425734134,0.04848348488449171
0.0501406601137506,124.197528915615,0.15919659586115814,25.038221829387986,130.42487499994056,0.04892411721041863
0.0506052309328598,124.068789600712,0.16067160821182985,25.012267983503538,130.34731935001642,0.04936640852100736
0.0510770235416481,123.927751257885,0.16216954974473272,24.983834653589614,130.2576119263475,0.04981537516732966
0.0515640867502714,123.767270831877,0.1637159754321117,24.951481799706404,130.14921712189624,0.05027866223515214
0.052027931760216,123.60165737715,0.1651886833386858,24.91809412723344,130.03239597261796,0.05071966506591067
0.052494413009797,123.435647024746,0.16666976130610547,24.884626440188796,129.91532885979456,0.051162978256079523
0.0529523729615796,123.282031856689,0.1681237841530152,24.853657622308504,129.81010798702573,0.051598002272887813
0.0534268280280262,123.134287247995,0.1696301789889832,24.823872309195796,129.7129616371472,0.052048495777806306
0.0538998682215955,122.994853381502,0.17113208160356572,24.795762441710803,129.6242597706994,0.052497443918933594
0.0543925969610138,122.871887708364,0.1726964953512188,24.770972562006182,129.55520877432397,0.05296486364985468
0.0548846357032298,122.777402092103,0.1742587183577546,24.751924261767968,129.51599507851702,0.05343141090454586
0.0553743318389526,122.672944060547,0.1758135035886745,24.730865522606273,129.465876372617,0.05389552090435609
0.0558683165756436,122.562438271514,0.17738190512766844,24.708587555537225,129.4097953731497,0.054363477295893005
0.0563662854535353,122.442216303083,0.17896295631497458,24.68435080670153,129.3438292187861,0.05483498636656085
0.056857497734406,122.302399271107,0.18052255530673905,24.656163693055174,129.2562076605764,0.055299880140353835
0.0573436813952801,122.156064573447,0.18206618843001432,24.626662618006918,129.160943020848,0.0557598020004337
0.0578248084101411,122.008221819957,0.18359376670219799,24.59685751890333,129.06332387115802,0.05621473221093734
0.0583193539508979,121.803502806083,0.1851639487941008,24.55558616570633,128.90700439869013,0.056682134724014156
0.0588151826834646,121.669732599533,0.18673820502000008,24.528618092065855,128.82576014942282,0.057150530787705156
0.0593212112704023,121.543212680515,0.1883448457835273,24.503111676391825,128.75330327841925,0.057628336275594556
0.0598310738499093,121.407699774714,0.18996365947346203,24.475792274582346,128.67165282588252,0.058109531131599196
0.0603499640333225,121.282733970298,0.19161113580579892,24.45059916841208,128.6021426032685,0.05859900838330716
0.0608655697441242,121.157396231593,0.19324818393759433,24.425331080289148,128.5317101819435,0.05908515013811336
0.0613777398841224,121.010659106097,0.1948743241320886,24.395748875789156,128.43801986391722,0.05956781878182433
0.061904631634337,120.90789199845,0.19654720543901996,24.37503102688752,128.39265051429825,0.06006411806645768
0.0624291111704115,120.726327715422,0.1982124279660565,24.338427667429077,128.2631650495636,0.06055790069219379
0.0629436648411241,120.553663183174,0.19984613587056899,24.303618497727875,128.14175255394545,0.061042101568927955
0.0634603530228095,120.389835566048,0.20148662084742017,24.270590850115276,128.0298170314274,0.06152807524797817
0.0639581103602268,120.232531610789,0.20306700039372008,24.238878372735062,127.92237713644128,0.06199602018224238
0.064492118317047,120.082639405077,0.20476247565662423,24.208660104063526,127.82702319341253,0.06249780120660467
0.0650300970141565,119.925306183469,0.20647055801994688,24.17694172658735,127.7240604790324,0.06300305886926824
0.0655575325198382,119.794433143549,0.20814516575048628,24.150557721739478,127.64786059005279,0.06349816689406357
0.0660866697762498,119.673830464031,0.2098251765395931,24.12624422154865,127.58267537876633,0.06399462616874924
0.0666058781442999,119.548087672218,0.21147366310815216,24.100894474719148,127.51069303209785,0.06448153027390398
0.0671364568416584,119.398216888106,0.21315825047226544,24.07068052464217,127.4141901231853,0.06497885246655526
0.0676974935094632,119.237331719674,0.21493954189254566,24.03824607468628,127.30940020985234,0.06550445463868526
0.0682387435516576,119.086213884615,0.21665801077651287,24.00778071913839,127.2125074944251,0.06601125820743235
0.0687775676414228,118.961798564072,0.21836877726151738,23.982698590516918,127.14370171155778,0.06651553522053834
0.0693163344851139,118.800448240884,0.22007936199023662,23.950170365362215,127.03525984813058,0.06701950453129547
0.0698768792893461,118.643494503164,0.22185909174367388,23.918528491837865,126.93393164702779,0.06754357576848169
0.0704449612934879,118.479226850011,0.22366275210682407,23.88541213296222,126.8254913995424,0.06807441370762737
0.0710069151297485,118.345431835414,0.22544695553695146,23.858439058019464,126.74877586974469,0.06859924814854745
0.0715672882042856,118.220439358853,0.22722614004860675,23.833240574744764,126.68115561408531,0.06912233209723166
0.0721223727775921,118.075134932998,0.22898853356885493,23.803947202492395,126.59099383040017,0.06964020984401169
0.0726815376528604,117.926306910152,0.23076388204783174,23.773943473086643,126.49737222610499,0.07016162337297575
0.0732412658731495,117.750561115995,0.23254101914724964,23.73851312098459,126.37476126940415,0.07068329007232112
0.0737955240385791,117.582792203968,0.23430078882248861,23.70469090831995,126.25987597257917,0.07119959065957321
0.0743622998679866,117.430542565863,0.23610030208085747,23.67399738127798,126.16294778580608,0.07172727613617251
0.0749330539611249,117.277253397597,0.23791244632657155,23.643094284955556,126.06519615485163,0.07225838425543366
0.07549029733838,117.104602442201,0.2396816940493565,23.608287852347722,125.94486370025552,0.07277664814927694
0.0760561642319492,116.911968302382,0.24147832143643871,23.56945280976021,125.80384416426841,0.0733026576189526
0.0766122291421122,116.724276136703,0.2432438275262062,23.531614069159325,125.66678312653528,0.07381928611987977
0.0771746791164594,116.568317237379,0.24502960619475855,23.500172755055612,125.56443971531937,0.07434157547448221
0.0777452703198546,116.405135017818,0.24684123326553836,23.467275219592107,125.45508370639745,0.07487114615935107
0.0783093588421103,116.234780181502,0.24863221432370017,23.432931684590805,125.33705129266905,0.07539440612456397
0.078859849390836,116.070836089277,0.2503800218159043,23.399880555598244,125.22416474194578,0.07590478848916893
0.0794282550576604,115.905953687448,0.2521847098080717,23.366640263389517,125.112161339636,0.07643150749280346
0.0799911330857564,115.701754213411,0.25397184754727653,23.325473649423657,124.95686863295143,0.07695283099664406
0.0805621964637331,115.514196262836,0.25578497377235254,23.287661966587738,124.82027363651281,0.0774814579770244
0.0811325843337676,115.366313912784,0.25759595525971213,23.257848884817253,124.72628110558884,0.07800918084367388
0.0816900058549049,115.214548194696,0.2593657685893231,23.227252916050713,124.62642531129092,0.07852463831670747
0.0822636832727782,115.043423299216,0.2611871943910708,23.19275413712195,124.50731903611884,0.07905485061671666
0.0828391835837479,114.844386586273,0.2630144078783995,23.152628335792638,124.35800181025618,0.07958646538046138
0.0834048918437113,114.639560806148,0.2648105316037834,23.111335458519438,124.20106097619534,0.08010875950164612
0.0839841158009356,114.516527807979,0.2666495676679705,23.086532006088568,124.13409714052537,0.08064324958992337
0.0845705504343222,114.351285200149,0.268511497628973,23.053219096350034,124.02203633239775,0.08118410258921631
0.0851540033329726,114.136337410809,0.270363960582188,23.009885622019098,123.85550346710231,0.0817219154758342
0.0857057086731192,113.927184249878,0.2721156250371535,22.967720344775405,123.69139431314682,0.08223019829943011
0.0862827229675393,113.718460002518,0.2739476454219373,22.92564153650763,123.53039838321047,0.08276152185492323
0.0868615124329351,113.514112456908,0.27578530197456896,22.88444507131265,123.37411994739729,0.08329419655700035
0.0874423104119921,113.323918033904,0.2776293355580749,22.846101875635046,123.23322325172778,0.08382843467659393
0.0880145068855786,113.112807382952,0.2794460593617121,22.803541968403124,123.06837534720596,0.08435448187939931
0.0885853709518706,112.88295337514,0.28125855277218914,22.757203400428224,122.88273167401951,0.08487902852225644
0.0891501012641287,112.665704076368,0.2830515715136086,22.71340594179579,122.70986300377056,0.08539766848759817
0.0897411258398722,112.411620374141,0.28492807454159425,22.662182667426823,122.49956574400072,0.08594016880416899
0.0902930481603921,112.143520529494,0.2866804279092449,22.60813373874599,122.26930082953952,0.08644651163025335
0.0908437657741326,111.862487350745,0.28842895633287097,22.551477449910195,122.02449695054794,0.0869514938229569
0.0913868999854191,111.562990911497,0.2901534074537056,22.491098967757793,121.75838680400018,0.08744927275258481
0.0919306323521071,111.251094052892,0.29187975771794006,22.428220561063025,121.47847747903812,0.08794735181792981
0.0924668818686605,110.962512299754,0.2935823499329971,22.370042479630406,121.22286981642513,0.08843833344909788
0.0930055982858423,110.655775281822,0.2952927745575493,22.308204296815315,120.94738186569157,0.08893133112624524
0.0935402014090679,110.346469442707,0.29699013947379055,22.24584823964973,120.66830041915736,0.08942032443610669
0.0940790233513418,110.008976303412,0.2987008991405102,22.17780962276786,120.3585133539179,0.08991293480181516
0.0946139504038911,109.66492388243,0.30039929253235426,22.10844865469789,120.04075555168873,0.09040174439696151
0.0951473711202706,109.266970162746,0.3020929033068591,22.028221184809595,119.66343512400833,0.09088893971061254
0.0956827822003275,108.874323128109,0.3037928334860398,21.949063542626774,119.29172127518392,0.09137771433324086
0.0961857869580814,108.454262068025,0.30538987359190845,21.86437923291384,118.88602061399598,0.09183668780789325
0.0966920573038952,108.018200268397,0.30699728193986725,21.776469174108833,118.46270227861247,0.09229842839789786
0.097196013016462,107.461890309752,0.3085973413272668,21.664317086446005,117.90675759907225,0.0927578462945977
0.0976933800315037,106.940652311397,0.3101764816000242,21.559235505977636,117.38804609847121,0.09321105092999303
0.0981874087496127,106.434177399804,0.3117450227800203,21.457130163800485,116.88467348108733,0.09366101044415998
0.0986936755435354,105.968904024375,0.3133524198507249,21.363331051314,116.42736465586071,0.09412190639934338
0.0991881234118617,105.448523884232,0.3149222918326609,21.258422415061172,115.90776508485985,0.09457183767126388
0.0997088993364083,104.895634748604,0.3165757553930963,21.146959965318565,115.35466303458121,0.09504550781488227