File: example/data/02 processed data/test_ID_143.csv
Strain,Stress_MPa,Displacement(mm),Force(kN),True Stress (MPa),True Strain
0.0004544635057861,-0.631055736098465,-1.404797274223356e-05,-0.1272208363974505,-0.6310529439555422,-4.424568132427684e-06
0.0004673550777176,-0.68923440341578,2.688276814025284e-05,-0.1389496557286212,-0.6892402391728387,8.46697774263029e-06
0.0004758868947306,-0.744001811273127,5.397128715655924e-05,-0.1499907651526624,-0.7440144584338833,1.6998686121984002e-05
0.0004840509923551,-0.795504145184601,7.98922971143261e-05,-0.1603736356692155,-0.795524162398309,2.516261164390768e-05
0.0005003519898078,-0.749707682417763,0.0001316479640267,-0.151141068775421,-0.7497387682413869,4.1463066073026864e-05
0.0005197009919134,-0.444021213427862,0.0001930810457117,-0.0895146766270569,-0.4440482156578484,6.081107875213047e-05
0.0005415995989687,0.0556364202480868,0.0002626091231125,0.0112163023220143,0.0556410220217984,8.270811442812585e-05
0.00054362253751,0.746681895492279,0.0002690319529812,0.1505310701312434,0.7467451651894759,8.473088361715958e-05
0.0005394593180558,1.83480859860552,0.000255813731214,0.3698974134788728,1.8349564314350235,8.056800823665729e-05
0.0005443265939907,3.20382431813098,0.0002712673323073,0.6458909825352055,3.2040980481706525,8.543488019722497e-05
0.0005426495385243,4.80037771931414,0.0002659426812016,0.9677561482137308,4.800779806029559,8.37579665978427e-05
0.0005544653945552,6.44365893007361,0.0003034580240995,1.29904164030284,6.444274797792316,9.557276320294588e-05
0.0005502008927245,8.04886173897199,0.0002899182307871,1.6226505265767532,8.04959670330434,9.13086598318648e-05
0.000546559434699,9.6782439794002,0.0002783566015562,1.95113398624708,9.679092484314577,8.76675276588632e-05
0.0005552957233242,11.3550398786956,0.0003060943179412,2.289176039545033,11.35613459151036,9.6403012274341e-05
0.0005774326448478,12.8872168775076,0.0003763790437786,2.598062922505532,12.88874458722896,0.0001185375548641
0.0005892843778722,14.3763828387003,0.0004140082961311,2.8982787802819803,14.37825746602741,0.0001303878128816
0.000641948108095,15.8997192070285,0.0005812156395885,3.205383392136945,15.90262981032557,0.0001830432905196
0.0006478922037362,17.4547072663838,0.0006000881432493,3.518868984902974,17.458006278312762,0.000188986280574
0.0006612897502596,19.0704654201602,0.0006426253534611,3.844605828704296,19.07432531451652,0.0002023812056717
0.0006807849483692,20.7116457027526,0.0007045226074591,4.175467773674924,20.716241552401502,0.0002218722687668
0.0007145339064475,22.3253756948171,0.0008116755493577,4.500795740075128,22.33108308429165,0.0002556131704871
0.0007249496428533,23.9179590013578,0.0008447455124461,4.821860534673733,23.924322651289536,0.000266026190618
0.0007419113553745,25.5174503500683,0.0008985989497009,5.144317990573771,25.52467238285054,0.0002829832477079
0.0007251931378189,27.1377277580661,0.0008455186089619,5.470965916026126,27.144954672656457,0.0002662696207867
0.0007546478956638,28.7464015375129,0.0009390374651194,5.795274549962601,28.75490356838883,0.0002957161032164
0.0007851249815717,30.2680212465511,0.001035802212877,6.102033083304702,30.277895792499628,0.0003261837137493
0.0008117044775971,31.8079925674587,0.0011201921127577,6.412491301599674,31.81921494931593,0.0003527541883917
0.0008246007359476,33.3637843246383,0.0011611377330205,6.726138919847082,33.37598588334561,0.000365645815238
0.0008509290012357,35.0118956994554,0.0012447299753102,7.058398173010208,35.02562179585526,0.0003919641091366
0.0008841368027447,36.6009393107291,0.0013501647451013,7.378749365042987,36.616503814003096,0.0004251583459949
0.0009210146698268,38.1361315666789,0.001467251973087,7.688244123842466,38.15375528771421,0.0004620198580829
0.0009467802092584,39.677883454939,0.0015490575607823,7.999061304515703,39.69724198261199,0.0004877731644539
0.0009804653594213,41.2725930188763,0.0016560079125495,8.320554752605462,41.294119866312734,0.0005214413211322
0.0010130205289124,42.8816943563274,0.0017593705756838,8.644949582235604,42.90545649531511,0.0005539789900821
0.0010509915691689,44.4522939731784,0.0018799286284981,8.961582464992766,44.47861433224694,0.0005919282809223
0.001090449874774,45.9615957298837,0.0020052087487943,9.265857699144554,45.99062331850294,0.0006313624594141
0.0011297005821085,47.5349337601027,0.0021298297445814,9.583042646036706,47.56682078871025,0.0006705876238301
0.0011677674849282,49.0223117998054,0.0022506921610339,9.88289805884077,49.05706270780024,0.000708628284458
0.0011979772600252,50.5670618969755,0.0023466081969669,10.19431967843026,50.60443546609172,0.0007388162039773
0.0012306171057004,52.0326708388964,0.0024502397069857,10.489786441121517,52.07282596209325,0.0007714314118299
0.0012618451759181,53.435178470404,0.0025493888299269,10.772531979633444,53.47808462697647,0.0008026349141886
0.0012963441036627,54.8521245833149,0.002658922925516,11.058188315996285,54.89806082632838,0.000837105568879
0.0013427967501314,56.27423602054,0.0028064100780541,11.344885981740866,56.32397730655664,0.0008835182687638
0.0013776267036868,57.6985023567922,0.0029169951805925,11.632018075129306,57.75151220035193,0.0009183168575312
0.0014143170080582,59.1125361704899,0.0030334868969717,11.917087291970766,59.16901399849619,0.0009549728122059
0.0014612046862054,60.4860762647829,0.003182355275089,12.193992974980231,60.54670246442721,0.0010018146381731
0.0014999082922901,61.9199965930444,0.0033052392244079,12.483071313157753,61.984456562025365,0.0010404787423682
0.0015404092683436,63.3062258260835,0.0034338298233778,12.762535126538433,63.37469285167313,0.0010809367814949
0.0015891767629839,64.7038070059939,0.0035886666188608,13.044287492408367,64.77694098782558,0.0011296504035091
0.0016189982907316,66.0192339007473,0.0036833499694597,13.309477554390655,66.09582348914795,0.0011594378187271
0.0016654334590822,67.2989664864878,0.0038307816289729,13.56747164367594,67.3801657445871,0.0012058181040046
0.001715834959471,68.6709691102161,0.0039908063927073,13.844067372619568,68.75728487163924,0.0012561575989253
0.0017678881007984,69.9797801682076,0.0041560751164218,14.107923681910652,70.07138370301382,0.0013081440430359
0.0018281301105125,71.2302510512351,0.0043473434972641,14.360018611928997,71.32778250594883,0.0013683054893097
0.001883111849869,72.4657394138264,0.004521910519721,14.609093065827402,72.56894684355073,0.001423210540987
0.0019460103681014,73.7099168265806,0.0047216133151088,14.85991923223865,73.81953248791729,0.0014860176326498
0.0020180273211476,74.958683266695,0.0049502671410305,15.111670546565714,75.07555429243045,0.0015579250613091
0.0020771510783746,76.1346480003872,0.0051379850702262,15.34874503687806,76.25785388534875,0.0016169550375629
0.0021254475391271,77.3699577820331,0.0052913263331154,15.597783488857871,77.49889941825485,0.0016651723057412
0.0021839522970789,78.5323736266485,0.0054770789396124,15.83212652313234,78.66784701552041,0.0017235780186094
0.0022436527085512,79.6464303195087,0.0056666277460369,16.056720352412952,79.78858045239731,0.0017831738445241
0.00231150828429,80.7778409838303,0.0058820691990076,16.28481274234019,80.9274916453778,0.0018509062359012
0.0023782861398902,81.8079331341301,0.0060940888905383,16.492479319840626,81.96495512356965,0.0019175583849633
0.0024556264659941,82.7898790683822,0.0063396444259182,16.690439620185852,82.95518879920373,0.0019947475694151
0.0025443799026834,83.7340918805661,0.0066214365874067,16.880792923122126,83.9087186457917,0.0020833202191878
0.002647495674279,84.5158746031389,0.0069488291622227,17.038400319992803,84.70084668947372,0.0021862160972665
0.0027535995381413,85.3007598296622,0.0072857089299855,17.1966331816599,85.4965004619852,0.0022920826444722
0.0028633526585764,86.1224586071809,0.007634175087367,17.36228765520767,86.32953700968854,0.002401578494877
0.0029834771959212,86.8838413474889,0.0080155704934367,17.515782415653764,87.10318734908303,0.0025214077100457
0.0030996398570556,87.6617231407782,0.0083843869425384,17.672603385180885,87.89321599333314,0.0026372711342666
0.0032159551139252,88.3625730031817,0.0087536878830994,17.813894717441432,88.60619454164389,0.0027532733118967
0.0033444669909333,89.0211553859637,0.0091617130926001,17.946664925810282,89.27803295598511,0.0028814236356263
0.0034908831554059,89.6090246525573,0.0096265844148006,18.06517936995555,89.88071877543787,0.0030274078641201
0.0036306666746924,90.1662134908819,0.0100703970885353,18.17750863976179,90.45220075822768,0.003166759131768
0.0037704705615906,90.628979656172,0.010514274429437,18.27080229868428,90.92910499896408,0.0033061112837314
0.0039238250935244,91.010893005913,0.0110011750683269,18.34779602999206,91.32624001916744,0.003458947965584
0.0040849597376142,91.2830656980369,0.011512777563312,18.40266604472424,91.61406463683336,0.0036195133248402
0.0042558040473705,91.5068567809363,0.0120552082467882,18.44778232703676,91.85430062802394,0.0037897258921161
0.0044199535575843,91.710040233549,0.012576382941717,18.48874411108348,92.0733097093214,0.0039532411286075
0.0045823121785382,91.8989268630714,0.0130918715632457,18.526823655595194,92.2778651141868,0.0041149460988396
0.0047535003717442,92.0254170094005,0.0136353940766747,18.552324069095143,92.4206304979024,0.0042854167782661
0.0049366743016431,92.1334616570515,0.0142169713041037,18.574105870061583,92.54601560367388,0.004467790779959
0.0051049761585583,92.2395176334932,0.0147513296998095,18.59548675491223,92.66807055820595,0.0046353283414395
0.0052824351501041,92.3299911499047,0.0153147619979674,18.61372621582079,92.77534920966384,0.0048119510571058
0.0054534109405045,92.4116280927636,0.0158576101324887,18.630184223501143,92.87318008331592,0.004982091621934
0.0056285035378027,92.4796942816618,0.0164135291289105,18.64390636718302,92.9577787402208,0.0051562988863068
0.0057559733753819,92.525183906718,0.0168182458632244,18.65307707559435,93.01529769931112,0.0052831051026944
0.0059511221078554,92.5644091589663,0.0174378430888278,18.660984886447608,93.0727945581865,0.0054772067235931
0.0061298624881386,92.5678234692284,0.0180053437962269,18.661673211396447,93.09277322860852,0.0056549549839045
0.0063195831993496,92.5650371324109,0.0186077070543219,18.66111148589404,93.10753259522424,0.0058435880684786
0.0065047035118996,92.560635422833,0.0191954640466681,18.66022410124313,93.12023994232774,0.0060276128351352
0.0066937669654019,92.5667322307071,0.0197957405115379,18.66145321771055,93.14387459645202,0.0062155224588666
0.0068899742977806,92.5634930370447,0.0204186987918403,18.66080019626821,93.15877684285384,0.0064104950339477
0.0071354891986164,92.5334910735402,0.021198208601994,18.654751800425707,93.1513002850198,0.0066544113466155
0.0073146186568501,92.5066247683826,0.0217669446318859,18.64933555330593,93.14082526583644,0.0068323369313043
0.0075119445797527,92.4915970443123,0.0223934544371017,18.64630596413336,93.14394550548604,0.0070283000501876
0.0077096068960373,92.4730606673363,0.0230210322913053,18.642569030535,93.14355682976108,0.0072245587469525
0.0079033748306927,92.4527830767599,0.0236362454838362,18.6384810682748,93.14104659690672,0.0074169133370804
0.0080946754145871,92.4278811771969,0.0242436248377009,18.63346084532289,93.13364082311926,0.007606782283669
0.0082857245432207,92.3826252891171,0.0248502058211126,18.62433725828601,93.10568899076412,0.0077963656844694
0.0084796906662536,92.3612100408253,0.0254660482617421,18.620019944230386,93.10202107465604,0.0079888069383332
0.0086809484204046,92.3497996103278,0.0261050416311715,18.617719601442086,93.1091052366138,0.0081884433596363
0.0088699444035845,92.3299411144198,0.0267051038777677,18.61371612866704,93.10653345095167,0.0083758805113605
0.0090681267346603,92.2869554060302,0.0273343327789333,18.60505020985569,93.08147583129728,0.0085723905139656
0.0092686670358303,92.2533974739504,0.0279710482351481,18.5982849307484,93.0661295150843,0.0087711992890162
0.0094728991995521,92.2217715527935,0.0286194853549648,18.591909145043168,93.05305962849872,0.0089736274350422
0.0096759707531466,92.1967695822607,0.0292642375376273,18.58686874778376,93.0465548311606,0.0091748646024818
0.0098760653943009,92.1591883595978,0.0298995380232922,18.57929237329492,93.02706777898474,0.0093731121461529
0.0100712019145832,92.1018924113754,0.0305190964751885,18.56774151013328,92.9872047074542,0.009566409491974
0.0102740057267227,92.0521385109837,0.0311629985787315,18.557711123814315,92.95564108156228,0.0097672622779238