File: example/data/02 processed data/test_ID_076.csv
Strain,Stress_MPa,Displacement(mm),Force(kN),True Stress (MPa),True Strain
4.202040312191429e-05,2.57205730032622,0.00013341477991207787,1.037053503491532,2.5721653792108325,4.201952028954817e-05
0.00011365143444111789,6.00726200859584,0.0003608433043505493,2.422128041865843,6.007944742540181,0.00011364497660610151
0.0001798461320863179,10.4581292015429,0.0005710114693740593,4.216717694062097,10.460010055628656,0.0001798299617094696
0.0002550317283305179,15.3432720715308,0.0008097257374493943,6.1864072992412185,15.347185092725448,0.00025499921326742705
0.00033003242347591787,20.4358952534492,0.0010478529445360392,8.239752966190718,20.442639761485594,0.00032997797475513903
0.0004302240199816179,25.563595519309,0.0013659612634416367,10.307241713385391,25.574593592138502,0.00043013150016313627
0.0005286968277683179,31.376095775022,0.0016786124281644092,12.650841816488871,31.392684217326007,0.0005285571168413722
0.0006265486574900179,37.3887489320215,0.001989291987530807,15.075143569391068,37.41217480247009,0.0006263524578281668
0.0007160251017187179,43.5400613887528,0.002273379697956929,17.555352751945126,43.57123716563751,0.000715768878046589
0.0008009272394926179,49.5548240567538,0.0025429439853890618,19.980505059683132,49.59451386518912,0.0008006066684291525
0.0009093263006673179,55.7095908213914,0.002887111004618734,22.462107019185016,55.760249017524714,0.0009089131139689306
0.0009958637753979178,61.8740331450987,0.0031618674868883886,24.947610164103793,61.935651253345675,0.0009953682320368788
0.001105465259724218,68.1116629889097,0.003509852199624392,27.462622517128395,68.18695806612598,0.0011048546829435033
0.0012049969378226178,74.4244695864252,0.0038258652775868115,30.00794613724664,74.51415084437593,0.001204271511711655
0.001300692420241818,80.7333553598052,0.004129698434267771,32.55168888107346,80.8383646231824,0.001299847252645195
0.001407680424153718,87.0079849455474,0.004469385346688054,35.08161953004471,87.13046438270031,0.0014066905708878393
0.0015100475378228178,93.2057821068164,0.004794400932587446,37.58057134546838,93.34652726859765,0.0015089085625000875
0.0016115552174522179,99.3623047632452,0.005116687815410792,40.062881280540466,99.52243260390449,0.0016102580557875831
0.001711338767317318,105.60813075714,0.005433500586232484,42.581198321278855,105.78886204544861,0.0017098760956424602
0.001820513859136618,111.806584452844,0.005780131502758762,45.080414851386706,112.01012988938312,0.0018188587322640038
0.001936868501052018,118.063240297554,0.006149557490840157,47.603098487973774,118.29191326881849,0.0019349951897719925
0.002043774947326218,124.270064000795,0.006488985457760742,50.10568980512055,124.52404404430247,0.0020416892805808304
0.002143441559694818,130.355132705158,0.006805426952031047,52.55918950671971,130.63454131411777,0.0021411476661346
0.0022502854678647178,136.452492073802,0.007144656360470478,55.01764480415697,136.7595491337696,0.002247757367442728
0.002366489610119218,142.566121532619,0.007513604512128517,57.48266020195199,142.90350277798095,0.0023636938834185354
0.0024741752700574177,148.705903519632,0.0078555064824323,59.958220299115624,149.07382798863182,0.002471119537664466
0.002605037415942418,154.796611338017,0.008270993795617175,62.41399369148845,155.1998623024136,0.0026016501872694474
0.002712253258382218,160.761914231451,0.008611404095363541,64.81920381812104,161.197941257149,0.0027085817367461977
0.002815620119462018,166.610629108623,0.008939593879291906,67.17740565659679,167.07974134805744,0.0028116636859360977
0.0029237757341565177,172.387904520581,0.009282987955946943,69.50680310269826,172.89192809268036,0.0029195098149226192
0.003029065363427818,178.137364003195,0.00961728252888332,71.82498516608823,178.67695372242937,0.0030244869880752413
0.003141292955342718,183.759604858611,0.00997360513321313,74.09187267899196,184.33684761082992,0.003136369402813041
0.003242939859501518,189.321844775711,0.01029633405391732,76.33456781356668,189.93580413240852,0.0032376928707543457
0.003356770709517618,194.744360913734,0.010657747002718437,78.52092632041754,195.39807308029296,0.0033511493309927227
0.0034752432297723177,200.071219616253,0.011033897254527109,80.6687157492732,200.76651576769663,0.0034692185261911953
0.003582503445652318,205.358919533584,0.011374448439946108,82.80071635594106,206.09461857040847,0.0035761015654657913
0.003705316378432618,210.38107809984,0.01176437950152356,84.82565068985551,211.16060655423567,0.0036984686039350334
0.0038075648626503178,215.23495978686,0.012089018438914759,86.78273578606195,216.0544808569584,0.0038003344352943794
0.003915894444528818,219.598826047615,0.012432964861378995,88.54224666239837,220.4587518705599,0.003908247287018452
0.004043044805274818,223.663195554463,0.012836667256747546,90.18100044755947,224.56747587538064,0.004034893662530015
0.004159458577384917,227.449249121153,0.013206280983197111,91.7075372456489,228.39531485132974,0.004150831942702901
0.004291703410398117,230.93518366882,0.013626158328014022,93.11306605526823,231.92628898415242,0.004282520316019827
0.004431793044579519,234.191873888455,0.014070942916539972,94.42616355182507,235.22976380625087,0.004422001568323164
0.004588771395325817,237.240695907629,0.01456934918015947,95.65544858995601,238.32933922681713,0.0045782750817400806
0.004779998085904418,239.943495138218,0.015176493922746526,96.7452172397295,241.09042458570391,0.004768610170112393
0.004995013919456719,242.412788714727,0.01585916919427508,97.74083640977793,243.6236439686114,0.004982580224559555
0.005250689621466518,244.411929755538,0.016670939548156193,98.54689007743293,245.69526093846804,0.005236952814873337
0.005522192808753119,245.894286861511,0.01753296216779115,99.14457646256123,247.25216252413114,0.0055070014029649705
0.005829027313637818,246.958704621445,0.01850716172080007,99.57374970336663,248.39823365602405,0.005812104265354372
0.006160673214591218,247.657339738449,0.019560137456327117,99.85543938254264,249.18307567777256,0.006141773849517592
0.006516967643245919,248.176333268356,0.02069137226730579,100.06469757380114,249.79369040208528,0.0064958240214316515
0.006875956680631217,248.531280445295,0.021831162461004115,100.20781227554295,250.24017076341863,0.0068524250970115235
0.007243898553656418,248.783759265869,0.022999377907859126,100.30961173599839,250.58592357978827,0.00721778754171628
0.007611128847040918,248.980974196861,0.024165334089354916,100.38912879617436,250.87600047193507,0.007582310341080648
0.007967440418982917,249.212332281517,0.02529662333027076,100.48241237590766,251.19791669064577,0.007935867955838843
0.008325460697138118,249.461108387265,0.026433337713413524,100.58271890174525,251.5379870406077,0.008290995211129686
0.008693902940668817,249.654363111795,0.027603141836623494,100.66063920667575,251.8248339134034,0.008656328587963565
0.009082131715792918,249.88774302547,0.028835768197642515,100.7547379878695,252.15725642178955,0.00904113718242286
0.009458030819419117,249.964685349158,0.030029247851655696,100.78576113278051,252.32885904695675,0.009413583681083948
0.009830684738289018,250.160184379377,0.03121242404406763,100.8645863417648,252.6194302860829,0.00978267792722042
0.010204052267134818,250.277041954581,0.03239786594815305,100.91170331608706,252.8308819719494,0.010152342395120643
0.010570129078054318,250.384955343746,0.033560159822822455,100.95521399459838,253.03155664093222,0.010514655827569991
0.010938377059492717,250.522966706807,0.034729347163889375,101.0108601761846,253.2632813787088,0.01087898571724762
0.011307420657959718,250.648648281953,0.0359010605890221,101.06153498728345,253.48283798542604,0.011243969640547608
0.011683879253864217,250.866165472109,0.03709631663101889,101.14923791835436,253.79725545836507,0.011616149788100837
0.012060045962002318,251.174538314716,0.03829064592935736,101.27357384849348,254.20371479127618,0.011987903059632158
0.012441021007948517,251.467349705562,0.03950024170023654,101.3916354012826,254.595860286062,0.01236426744556289
0.012813178232930118,251.683878183223,0.04068184088955312,101.47893968347552,254.9087485727397,0.012731784006506326
0.013180742635805417,251.827766841211,0.0418488578686822,101.53695559037628,255.14704382449463,0.01309463248608171
0.013546828369527118,251.933427174749,0.0430111800732486,101.57955783685881,255.34632607323206,0.013455890449845785
0.013923936680578617,252.090897257354,0.04420849896083711,101.64304977416512,255.60099494851562,0.013827889219841365
0.014294245399892618,252.37237664228,0.04538422914465906,101.7565422621673,255.97984932615887,0.014193045914225174
0.014666348074307818,252.626337139215,0.046565655135927315,101.85893913453148,256.3314429324362,0.01455983734406743
0.015038758241544218,252.934137355483,0.04774805741690289,101.98304418173075,256.7379526982057,0.014926797224354131
0.015416584532679817,253.166425748703,0.04894765589125842,102.07670286187705,257.06938735209434,0.015298956402186805
0.01578187254216952,253.346111876785,0.05010744532138822,102.14915230871972,257.3443879234786,0.015658633726827586
0.01615216365075722,253.477441498498,0.05128311959115417,102.20210441219439,257.57165061535693,0.016023105315069255
0.01650204915138652,253.580808176699,0.0523940060556522,102.24378185684503,257.76541113707924,0.016367369973446864
0.01686935290084942,253.659209076913,0.053560195460196906,102.27539309981132,257.9382757913818,0.01672864558997934
0.01722243040721522,253.691390144607,0.05468121654290832,102.28836850630555,258.0605724562822,0.017075805450521796
0.01758150570226342,253.844470802079,0.05582128060468635,102.35009062739826,258.3074388129738,0.017428739010756603
0.01793827633932952,254.012549947947,0.05695402737737122,102.41786013901223,258.569097262571,0.017779284010482926
0.01829513615038722,254.21958775652,0.05808705727747942,102.50133778342887,258.87056972662083,0.018129793743328276
0.018661233771580518,254.515278531124,0.05924941722476814,102.62056030374922,259.26484764223227,0.01848924928252509
0.01902919360662022,254.734348781912,0.06041768970101919,102.70888942886691,259.58173802313934,0.018850403100686364
0.01938428426866412,254.973880662463,0.06154510255300858,102.80546868310509,259.9163668463086,0.019198802156608914
0.01974619044584272,255.160581333862,0.06269415466555063,102.88074639381317,260.1990307671524,0.019553763435905248
0.02008763954180902,255.299885085507,0.06377825554524363,102.93691366647641,260.4282571521699,0.019888544724592373
0.02044554874122772,255.515339709977,0.064914617253398,103.02378497106272,260.7394910421487,0.02023934441277594
0.020800230087193918,255.723108161151,0.06604073052684069,103.10755721057609,261.0422076495153,0.02058685900725982
0.02116586956493402,255.953043886413,0.06720163586866551,103.20026729500172,261.3705126280606,0.020944983935690522
0.021543344246317517,256.169437417213,0.06840011798205811,103.28751716662028,261.6881837928775,0.021314566334524433
0.02191633997825122,256.290327024453,0.06958437943094761,103.33625985625946,261.9072729646581,0.021679629309787007
0.02227873290654892,256.487773471181,0.07073497697829281,103.41587026358019,262.2019960701409,0.02203418738196049
0.02264695771440502,256.653983676066,0.07190409074323593,103.48288621818982,262.46641559161145,0.02239432253359432
0.02299457688166002,256.849884016459,0.07300778159927056,103.56187323543627,262.7560384215209,0.022734185764489833
0.02334447033507292,257.001875268678,0.07411869331385652,103.62315610833099,263.0014479219458,0.02307615593536516
0.02369535056961562,257.059287032031,0.07523273805852959,103.64630453131491,263.15039695543044,0.023418973143311785
0.024036745728376118,257.147180396971,0.07631666768759417,103.6817431360587,263.32816178694185,0.023752410473850055
0.024392113744464518,257.280469974233,0.07744496113867484,103.73548549361074,263.5560844620737,0.024099376899371836
0.02473884637097142,257.516361926466,0.07854583722783424,103.8305971287511,263.8870196421763,0.024437796099086282
0.02507677124565172,257.697613030313,0.0796187487049442,103.90367757382221,264.1598371228246,0.024767508561843732
0.02542965847181522,257.85544987986,0.08073916564801331,103.96731739155953,264.41262590540106,0.025111703756292424
0.02577418452792632,258.040723367986,0.08183303587616605,104.04201966197195,264.69151258779203,0.02544762947184397
0.02612426967270552,258.173534635625,0.08294455621084001,104.095569165084,264.91812967680164,0.02578885995277693
0.02648413674352522,258.330670120622,0.08408713416069256,104.1589261926348,265.17233491314306,0.02613950362487907
0.02683205058904772,258.437030479589,0.0851917606202265,104.20181068937029,265.3714259555006,0.026478383580142244
0.02718751178910032,258.542355165528,0.08632034993039352,104.2442776027409,265.57147849457255,0.026824496353468934
0.027535718028043218,258.779010675344,0.0874259047390372,104.33969710429871,265.9046765448762,0.027163428855154013
0.027883976113164118,259.014497239172,0.08853162415929607,104.43464528683415,266.2368512931523,0.027502296960238665
0.02824004930043172,259.167677798103,0.0896621565288707,104.49640768819512,266.48658579619985,0.027848650766162948
0.02859616743887922,259.337281472199,0.09079283161844152,104.56479188959064,266.7533337963217,0.028194928354147566
0.02895740092196042,259.380306588434,0.09193974792722433,104.58213961645659,266.89128611757627,0.028546057474037597
0.02930926437827022,259.516591779056,0.09305691440100794,104.63708980531537,267.122832178056,0.028887960168833573
0.029660817798833818,259.696874820261,0.09417309651129736,104.70977992752921,267.3996965072313,0.02922944490144138
0.030004816477945718,259.819276431906,0.09526529231747764,104.7591322573445,267.61510613867796,0.02956347842279126
0.03035505484536772,259.919837514953,0.0963772991340425,104.79967848602905,267.8097184381184,0.02990345628362066
0.03070998470188902,260.051465364968,0.09750420142849762,104.85275083515512,268.03764188803,0.030247870315414416
0.03106096075653382,260.156096081956,0.09861855040199487,104.89493794024466,268.23679437293066,0.03058833108173581
0.031403158282119016,260.300258224944,0.09970502754572787,104.95306411629743,268.47450843485836,0.030920164761232584
0.031741133549417815,260.441339461704,0.10077809901940156,105.00994807095906,268.7080427993472,0.03124779600996308
0.03208904305096612,260.578497333043,0.10188271168681742,105.06525012468293,268.9402119521191,0.031584945363421074
0.032447633242846614,260.771020654107,0.103021235546038,105.14287552773597,269.2324230926543,0.03193232615796362
0.032798062973101116,260.930933369244,0.10413384993959604,105.20735233447917,269.4889625535185,0.03227168503837141
0.03313741232815172,261.051509196119,0.1052112841418817,105.2559685078752,269.7020806952371,0.032600203873697844
0.03347934203672412,261.184422952155,0.10629691096659907,105.30955933430889,269.9287055828346,0.032931111586480294
0.033819055916530616,261.297833310707,0.1073755025349847,105.35528639087707,270.13467934631007,0.03325976649493533
0.03417369536369171,261.37882849889,0.10850148277972119,105.38794365075246,270.3111089585297,0.03360274588924718
0.03451963167498411,261.492591289703,0.10959983056807455,105.43381280800824,270.5192192267607,0.03393719499293536
0.03487937431932291,261.621275736854,0.11074201346385024,105.48569837709952,270.7464621431785,0.034284873373876576
0.035242700860822714,261.772289263456,0.11189557523311211,105.54658703102547,270.99785174762076,0.03463589281334486
0.035592249855944315,262.01138647755,0.1130053932926232,105.64299102774817,271.3369612101613,0.03497348514374312
0.03595673649086131,262.194499431127,0.11416263835848466,105.71682217063041,271.6221579565253,0.03532538282135594
0.03630795035619271,262.350271432396,0.11527774238091186,105.77962944154207,271.8756720634971,0.03566434904601194
0.03666768269447412,262.428683045577,0.11641989255495531,105.81124500397664,272.0513347254209,0.03601141761368533
0.037022193064522015,262.523512021789,0.11754546297985739,105.84948004718532,272.24270816783604,0.03635333023779153
0.03737664723260132,262.596415663488,0.11867085496350918,105.87887479551837,272.41138925628775,0.036695071820599404
0.03773218214600271,262.659994793607,0.1197996783135586,105.90450990078234,272.5707295596275,0.03703773810570874
0.038089801848387714,262.783812571212,0.12093512086863098,105.9544332287127,272.79319592101336,0.03738229530635539
0.03844913315533772,262.873858785974,0.12207599776819725,105.99073986250471,272.9811307854934,0.03772838206107936
0.03879741776534012,262.982742961675,0.12318180140495487,106.03464196214736,273.1857943054342,0.03806371501720972
0.039160156215077215,263.01961321975,0.12433349598287015,106.0495080502032,273.31950236106456,0.03841284481462597
0.03951027582996131,263.130921295509,0.12544512576012715,106.09438746634922,273.52729657528636,0.03874971362537881
0.039863851772884616,263.247094990821,0.12656772937890864,106.14122870029902,273.7411381651776,0.03908979282674765
0.04020972812164242,263.406964230182,0.12766588678621468,106.20568797760939,273.9984866472248,0.03942235447772839
0.040564168853104016,263.515279857775,0.12879123610860524,106.24936083865488,274.20455816529875,0.0397630361206546
0.040919020853207116,263.62406668852,0.1299178912089326,106.29322368881125,274.4113053707548,0.04010399684067936
0.04127543200848502,263.720551502891,0.13104949662693993,106.33212636596565,274.60573119568875,0.040446338698586916
0.04163735756019071,263.904302425819,0.13219861025360552,106.40621473809024,274.89258022759554,0.040793857382192655
0.04199723829735921,264.023549783933,0.13334123159411548,106.4542952728818,275.1118097203235,0.04113929294125142
0.04235153323686321,264.160605775565,0.1344661180270407,106.50955624870781,275.3482124509387,0.041479250387677524
0.042703901090874116,264.25149568212,0.1355848859635253,106.54620305903077,275.5360654168448,0.04181724414224557
0.04305163767076672,264.277271369534,0.1366889496046843,106.55659581619612,275.65484070115406,0.04215068358579707
0.04341038531447931,264.351768656358,0.1378279733734718,106.58663312224355,275.8273807922946,0.04249456489616435
0.04377931886343082,264.448599389994,0.13899933739139284,106.62567527404559,276.02597894567623,0.042848086717449
0.04414950598482092,264.663068588903,0.1401746815018064,106.7121492550457,276.34781231952985,0.043202684173898186
0.04452011788968931,264.806872121413,0.14135137429976355,106.77013083935371,276.59610528625814,0.04355756261376399
0.044887799200874816,264.971041171329,0.14251876246277753,106.83632380027984,276.86500806147427,0.04390951046652485
0.04524076410263612,265.071706234068,0.14363942602586965,106.87691195357623,277.0637527660868,0.04424725515009485
0.04559977296863391,265.108373813157,0.14477927917541267,106.89169632146492,277.19725547112074,0.044590666197623884
0.04594750082065702,265.156469358349,0.14588331510558603,106.91108844528631,277.3397464517942,0.044923173963127803
0.046293435641139115,265.199537022105,0.14698165816061667,106.92845332731275,277.4765347212977,0.04525385750688789
0.04664678306086872,265.266555349369,0.14810353621825817,106.95547511686559,277.64038681005496,0.0455915139960025
0.047008076744613214,265.364474894785,0.14925064366414695,106.99495627757732,277.8387484959331,0.04593664603688185
0.04736290564555221,265.431777876535,0.15037722542462828,107.02209283981892,278.00339812743255,0.04627548658358283
0.047722060304636015,265.529689722005,0.15151754146721932,107.06157089591241,278.2013135875898,0.04661834109157561
0.048084638567921216,265.637499603215,0.15266872745314986,107.10503984001629,278.4105827617219,0.046964344630067545
0.04844290848324562,265.732676918241,0.15380623443430483,107.14341533343477,278.6055406671992,0.04730611921759039
0.04881168363539391,265.818726709408,0.15497709554237565,107.1781106092333,278.79378630191087,0.04765779340853975
0.049176423066220415,265.925973155517,0.1561351432352498,107.22135237630447,279.0032613157091,0.048005497414426127
0.04953399788108952,266.065121310448,0.1572704432724592,107.27745691237261,279.24439046567153,0.048346254114121544
0.04989378946447021,266.175567433675,0.1584127815496929,107.32198878925776,279.45607515579667,0.04868900616215255
0.05025191679104322,266.319052955416,0.1595498358115622,107.37984215162373,279.70209584440096,0.04903005614642507
0.05062407805060202,266.360024697204,0.1607314478106614,107.39636195791265,279.8442553770355,0.049384347655648385
0.050984106476121914,266.439177970298,0.16187453806168706,107.42827655762414,280.023341389346,0.04972696949324167
0.05134174793117432,266.484924012726,0.16301004968147845,107.44672136193114,280.16672580884557,0.050067203579934605
0.05171181440530442,266.575973289881,0.16418501073684152,107.48343243048002,280.3611005455607,0.05041913610754784
0.05207960139370882,266.683487179729,0.1653527344250255,107.52678203086674,280.57225689033356,0.05076877817699377
0.052439124711146014,266.715618745604,0.16649422095788857,107.53973747822752,280.7019523394152,0.05111044614741858
0.05280619462827082,266.739680190928,0.16765966794475984,107.54943905298218,280.82518765817287,0.05145916552702964
0.053143633540990914,266.844824217289,0.16873103649264615,107.59183312441091,281.0259277678027,0.05177962797214055
0.05350674204302491,266.863604672118,0.16988390598660408,107.59940540379799,281.1426067279808,0.05212435390278209
0.053880243598178314,267.007782519342,0.17106977342421614,107.6575379117987,281.39422688409354,0.05247882278923632
0.05426074643513232,267.1081597624,0.1722778699315451,107.6980100161997,281.60164789002243,0.052839807033539674
0.054642174329898416,267.257070717081,0.17348890349742746,107.75805091312705,281.8605781661017,0.053201538145170736
0.05500781391000232,267.460394017435,0.17464980916425735,107.84003086782981,282.172805599842,0.053548173450366686
0.05537991531477482,267.547637482675,0.17583123112441004,107.87520743301455,282.3644029891336,0.05390081140734089
0.055749878661363814,267.562280693176,0.1770058647498301,107.88111157548856,282.4788453761783,0.05425129990068857
0.05612030285108752,267.635062672702,0.17818196155220287,107.91045726963347,282.65482344346384,0.05460210194975889
0.05649409353263152,267.687351309648,0.17936874696610505,107.93154004805008,282.8101055720376,0.054955967459796445
0.05686886707846232,267.703756301029,0.18055865297411786,107.93815454057489,282.92776563451724,0.055310637771280514
0.05724696094926272,267.743393700185,0.1817591010139091,107.95413633991458,283.07088930376256,0.055668322879938205
0.05761242859882962,267.787266129925,0.18291946080128402,107.97182570358576,283.21514087951107,0.05601394174709409
0.057984219122818315,267.77464852233,0.18409989571494814,107.96673828420346,283.3013524177844,0.056365417561934944
0.058351886936152515,267.877408624434,0.18526724102228423,108.00817115737178,283.50856088523653,0.0567128744861735
0.05872924815032102,267.910813572507,0.18646536287726923,108.0216400324348,283.64501422496113,0.05706936646176278
0.059104254556623416,267.975592128831,0.18765600821727935,108.04775874634467,283.8140897409753,0.05742350800286353
0.05947905785872742,268.011516221933,0.18884600870145954,108.06224334068338,283.9525887021026,0.05777733247020244
0.05984646370365691,268.038825035339,0.1900125222591107,108.0732542542487,284.08000084898725,0.058124052070256345
0.060221579644373614,268.141702873558,0.1912035153708862,108.1147345986186,284.289619789136,0.05847792367905521
0.060594805698917814,268.167655751009,0.19238850809406405,108.12519879880684,284.4172227459757,0.05882988819703647
0.06096685642594411,268.222750743973,0.19356976915237256,108.14741309996991,284.57544867875254,0.05918062109109479
0.061340218993595215,268.340344820432,0.19475519530466479,108.19482703159818,284.80040033653415,0.059532467038203175
0.06171296033646732,268.383586372075,0.19593864906828373,108.21226202522064,284.94633199281367,0.05988360411788714
0.062092659779345916,268.459142873064,0.19714419479942327,108.24272640641942,285.128485096136,0.06024116927670181
0.06247204902158381,268.489981304708,0.1983487556435286,108.25516046205827,285.26310057857984,0.06059831466718955
0.06285677500014282,268.469925808997,0.19957026062545344,108.24707408618758,285.34507952987815,0.06096035368761107
0.06323426140884382,268.49268684623,0.20076877997307913,108.25625133639994,285.4706235926274,0.06131545269908647
0.06361407824092041,268.534024883224,0.2019746984149223,108.27291883291592,285.6165693524947,0.06167261670465609
0.06399874553129911,268.613007448843,0.20319601706187468,108.3047646033735,285.8039029589585,0.06203421190682071
0.06437511830664051,268.698723525006,0.20439100062358362,108.33932532528243,285.9962356407716,0.06238788358608659
0.06476722632937412,268.783972780593,0.20563594359576282,108.3736978251351,286.192365179382,0.0627562084452998
0.06514604769995481,268.810789862734,0.20683870144735653,108.38451047265436,286.3227504013942,0.06311192374995019
0.06552161491280832,268.826442176889,0.2080311273481664,108.39082148572164,286.44038479958346,0.06346445851952819
0.06589745837109852,268.818259463665,0.2092244303282378,108.38752221574974,286.532699526063,0.06381712821916312
0.06626850789413681,268.837564093006,0.21040251256388437,108.39530584230002,286.6530283313439,0.06416517760429974
0.06665238019105582,268.91238919053,0.2116213071066022,108.4254753216217,286.8360399929424,0.0645251274769914
0.06703695855448001,268.992382990222,0.21284234341047403,108.45772882165751,287.0248142202083,0.06488560954024705
0.06741698348912212,268.973643272058,0.2140489225779627,108.45017296729378,287.10703493953935,0.06524169587331041
0.06778869715525372,269.00686500405,0.21522911346793056,108.46356796963295,287.2424899084937,0.06558987185771918
0.06816644930079671,269.060203511749,0.21642847653002956,108.4850740559372,287.4010822332947,0.06594357979967494
0.06855412700967761,269.12058839732,0.2176593532557264,108.50942124179942,287.56991539522903,0.06630645149888825
0.06893842998667311,269.17424429188,0.21887951520768711,108.53105529848601,287.7306940862114,0.0666660344877304
0.06931450774763812,269.215542337856,0.220073562098751,108.54770667062354,287.8760851330179,0.06701779620703503
0.06969937568289152,269.271553167749,0.22129551779318055,108.5702902372364,288.03961231270364,0.06737765169220783
0.07008788518351922,269.368041147315,0.2225290354576735,108.6091941905974,288.2474774873575,0.067740780786396
0.07048362184311331,269.398444897284,0.22378549935188474,108.62145298258491,288.3866230125469,0.06811052939119959
0.07088089484604632,269.40102532231,0.22504684113619705,108.62249340995538,288.49641106959774,0.06848157598732538
0.07127256492002491,269.44789443062,0.22629039362107908,108.641391034426,288.6521369789904,0.0688472548107145
0.07167209716995772,269.478749753448,0.22755890851461574,108.65383190059025,288.7928568910159,0.06922013635229611
0.07206205374925312,269.54850953502,0.22879702065387864,108.68195904452007,288.9727287171637,0.06958394693340689
0.07245478441283701,269.579917549547,0.2300439405107575,108.69462275597736,289.1122723576298,0.06995021187568712
0.07283920340021001,269.580813314881,0.23126447079566675,108.69498392856003,289.2168650087177,0.07030859538272298
0.07323816173422532,269.555871823676,0.23253116350616537,108.68492751930617,289.2976483607085,0.07068039776514648
0.07362005042973081,269.551567341414,0.23374366011439532,108.68319195205814,289.3959673225019,0.07103616294551077
0.07400914637974261,269.517629316719,0.23497903975568277,108.66950814050111,289.4643989967413,0.07139851223266609
0.07440079083949681,269.55129129991,0.23622251091540236,108.68308065212372,289.6061205444309,0.07176310230210088
0.07479412083664481,269.635214034549,0.23747133365634726,108.71691829873016,289.8023428148636,0.07212912773739517
0.07518727922181592,269.648312645227,0.23871961152926555,108.72219965855552,289.92243561977523,0.07249485963585996
0.07558193592390311,269.710496594019,0.23997264655839237,108.74727222670846,290.09573806559223,0.07286185085345545
0.07597686418942992,269.679371864422,0.24122654380143999,108.73472273573496,290.168764875256,0.07322895982574215
0.07637462930256012,269.713124846963,0.24248944803562836,108.7483319382955,290.31236477518496,0.07359856963980958
0.07676451581691392,269.748812128714,0.24372733771870167,108.7627210502975,290.4559490839624,0.0739607260006735
0.07716779632752231,269.81570882424,0.24500775333988334,108.78969379793358,290.636792488755,0.0743351857857345
0.07756419772545892,269.845297719167,0.24626632777833204,108.80162404036814,290.77563174674174,0.07470312147657913
0.07796314967959711,269.881071495952,0.24753300023272082,108.81604802716785,290.921849868681,0.07507328793183109
0.07836097274608811,269.907291649752,0.24879608846882972,108.82661999317999,291.05748957468865,0.07544227056006139
0.07876367348894782,269.910547311253,0.2500746633274093,108.82793267589723,291.1696935308998,0.07581563864358014
0.07917580138668531,269.922258273159,0.25138316940272587,108.83265453573772,291.2935693840402,0.07619760292714448
0.07958229673802901,269.901388378924,0.2526737921432421,108.82423979438218,291.3807607589016,0.07657420404470494
0.08000286947030232,269.880831808536,0.25400911056820985,108.81595138520171,291.47207276825094,0.07696369804954532
0.08040777164778141,269.906572937501,0.255294674981706,108.82633020840039,291.6091590204948,0.07733853621643226
0.08081146847339342,269.944287952578,0.2565764124030241,108.84153690247946,291.7588822680304,0.0777121187043288
0.08119837442110492,269.993449361887,0.2578048387870081,108.86135878271284,291.9164785544191,0.07807003192393172
0.08159433763056471,270.004304564695,0.259062021977043,108.86573560048504,292.0351269530526,0.07843619111401727
0.08200658767232462,269.980697416121,0.2603709158596306,108.85621719818,292.1208931486115,0.07881726882749719
0.08240558487543861,269.971143351835,0.26163773197951756,108.85236499945988,292.21827331923384,0.07918595757605842
0.08281696466402672,269.976804226571,0.2629438628082848,108.85464746415343,292.3354636823098,0.07956594603833039
0.08322525017704091,270.054495742727,0.26424016931210487,108.88597268346754,292.5298487123501,0.07994293362892517
0.08362493113097702,270.079505620399,0.26550915634085204,108.89605666614489,292.6648856777932,0.08031183865237045
0.08403550355061201,270.061225357646,0.26681272377319315,108.88868606420287,292.7559564200711,0.08069065483407092
0.08442912078678341,270.036718228552,0.26806245849803734,108.87880478975217,292.83568092873696,0.08105369256692281
0.08483527917878872,269.978111421571,0.2693520113926542,108.85517452517743,292.8817798761821,0.08142815904206342
0.08524577755809251,269.940056817618,0.2706553437469437,108.83983090886358,292.9513068551115,0.08180648443495665
0.08565751171287932,269.980908860262,0.2719625996883918,108.85630245245764,293.10680172321366,0.08218580502630532
0.08607453907374901,270.003630210821,0.2732866615591531,108.86546370100301,293.24406822945633,0.08256985550421249
0.08650125083274511,270.09456780834,0.2746414713939657,108.90212974032269,293.45808576689114,0.08296267196333501
0.08691607374226332,270.149673209925,0.27595853413168603,108.92434823824176,293.6300221280872,0.08334439608954389
0.08734621399559492,270.182550833508,0.27732422943601387,108.93760449607043,293.7819737364873,0.08374006156317969
0.08775669798444291,270.183936199688,0.2786275161006062,108.9381630757142,293.894386289012,0.08411750025029667
0.08818589400933581,270.194377127198,0.2799902134796412,108.94237285768622,294.02170983045556,0.08451199230356893
0.08862266171273972,270.201135548432,0.2813769509379486,108.94509785312778,294.14707937853876,0.08491328410124858
0.08904671410060132,270.202696598139,0.2827233172694092,108.94572726836967,294.263358871325,0.08530273935825983
0.08946788682384922,270.205330740171,0.2840605406657213,108.94678935443696,294.3800306900334,0.08568939981792949
0.08989326604965892,270.195978624441,0.285411119707667,108.94301858137462,294.48477761647587,0.08607977039111406
0.09030063491716571,270.194413039984,0.28670451586200113,108.94238733772156,294.59314008856546,0.0864534700625671
0.09073384464738982,270.192397860917,0.28807995675546266,108.94157481752174,294.7079929133352,0.08685072167869698
0.09115463696170581,270.162407062342,0.28941597235341593,108.92948252753631,294.7889631988104,0.08723643554361701
0.09158433125228961,270.084598860064,0.2907802517260195,108.8981102603778,294.82011622820585,0.08763015582111432
0.09199921179771692,269.990040036268,0.2920974974577512,108.85998414262326,294.8289109128387,0.08801015552549023
0.09242633714220472,269.901981533378,0.2934536204265,108.824478954258,294.8480330739311,0.08840121975758414
0.09284715977243942,269.845653149234,0.2947897322774951,108.80176734977117,294.9000556210792,0.08878636389265993
0.09326717964306912,269.822746315218,0.2961232953667444,108.7925313142959,294.9883528675857,0.08917062547333297
0.09369623188326191,269.840648671978,0.2974855362293566,108.79974954454153,295.12370066147747,0.08956299806030553
0.09411902042160801,269.886815670092,0.2988278898386054,108.81836407818109,295.28829838566816,0.08994949188620203
0.09454591494782212,269.905848488334,0.3001832799593352,108.82603811049628,295.4243438834318,0.09033958771560821
0.09496279355927512,269.924687651438,0.3015068695506985,108.8336340610598,295.5574900414333,0.09072038420650215
0.09538273751404501,269.903923547751,0.3028401916070929,108.82526197445321,295.648098641517,0.09110383417269043
0.09581094258014572,269.893154976933,0.30419974269196265,108.82092008669937,295.75187255120227,0.09149467600054124
0.09624346721617422,269.873592399436,0.3055730084113531,108.8130324554526,295.8471626420423,0.09188930547662434
0.09668283747455152,269.850550040302,0.30696800898170107,108.80374177624975,295.9404669122668,0.09229002141798233
0.09712453925455931,269.844829863817,0.3083704121332258,108.801435401091,296.05338463456513,0.09269270197294965
0.09758040056863061,269.804933040429,0.30981777180540215,108.78534900190095,296.13260648190663,0.0931081212052625
0.09802103447859471,269.775670921426,0.3112167844695382,108.77355051551896,296.21936126230116,0.09350949998817469
0.09846261323389971,269.758864756827,0.31261879701763157,108.76677426995263,296.3200275237943,0.09391157788364535
0.09889265248444681,269.778242733469,0.3139841716381186,108.77458747013472,296.45732873997474,0.09430299320254872
0.09933491497539441,269.767052141756,0.31538835504687723,108.77007542355601,296.5643393294201,0.09470537419663821
0.09978077133646941,269.712588316017,0.31680394899329034,108.74811560901806,296.62471841734475,0.09511086115665503
0.10022397189847272,269.616890585148,0.31821111077765085,108.70953028393167,296.63896625050745,0.09551376989524922
0.10066345813185172,269.493218010853,0.3196064795686292,108.65966550197595,296.6213372789065,0.095913141742463
0.10111084550419772,269.457197470615,0.32102693447582775,108.64514202015197,296.7022425340604,0.09631952978847158
0.10155763537366072,269.511524706026,0.32244549231137276,108.6670467614697,296.88247786112,0.09672521033410905
0.10200474288255372,269.554790559669,0.323865058652108,108.68449155365856,297.05065766346866,0.09713101460762591
0.10243996036785172,269.521406733184,0.3252468741679292,108.67103119481979,297.13116895721896,0.09752586913975439
0.10289111752278972,269.401420286876,0.32667929813485735,108.6226526596684,297.1204334824194,0.09793502055085544
0.10334061534038172,269.303723978995,0.32810645370571195,108.58326150833078,297.13373652844064,0.09834250070547018
0.10378933849727971,269.23936697183,0.32953114972886305,108.55731276304186,297.18354276726257,0.09874911306855295
0.10425146802102171,269.194738532279,0.33099841096674393,108.5393185762149,297.2586852078042,0.09916770092175349
0.10470084012791371,269.169394802646,0.332425167406126,108.52909998442689,297.35165657520514,0.09957456539902913
0.10516755791819471,269.124267997093,0.33390699639026816,108.5109048564279,297.427410038869,0.09999695959918414
0.10562916179446771,269.091466916441,0.33537258869743497,108.49767946070901,297.5153730128684,0.10041455012559036
0.10607425797725471,269.017632509659,0.3367857690777837,108.4679094278945,297.55347826091884,0.1008170418745443
0.10653333791152171,268.961503045832,0.3382433478690814,108.44527802807947,297.6148697350044,0.10123200921146179
0.10698061106366372,268.894449247082,0.3396634401271323,108.41824193642346,297.6609417391621,0.1016361387254742
0.10744634119324072,268.801791061868,0.34114213328853926,108.38088215614518,297.6835600176557,0.10205677137354521
0.10790235805531471,268.731182749407,0.3425899868256242,108.3524128845609,297.72791105106177,0.10246845994308681
0.10835978157865171,268.653457405232,0.3440423065122192,108.32107402578956,297.76468737001255,0.10288124823347175
0.10881564967432372,268.562946485097,0.3454896877159778,108.2845800227911,297.78679798532346,0.10329246341804409
0.10927516732972271,268.52371736563,0.3469486562718696,108.26876284182201,297.8666915127584,0.10370679961965516
0.10973924841649671,268.436756150546,0.348422113722377,108.23370007990013,297.8948040178693,0.10412507639176351
0.11021549825536571,268.359220078931,0.3499342069607861,108.20243753582497,297.9365652313518,0.104554139053414
0.11068129299431172,268.302092528762,0.3514131052569397,108.17940370759683,297.99811504292484,0.10497360451224208
0.11115705037955771,268.235401555679,0.3529236349550957,108.15251390724978,298.05165759998454,0.10540186014473325
0.11162376904292372,268.224113482054,0.35440546671128276,108.14796255596417,298.1642999771178,0.10582180138783441
0.11209020260983671,268.190841806941,0.3558863932862315,108.13454741655862,298.2524076031837,0.10624130999343692
0.11256261069708572,268.114362529942,0.35738628896324715,108.10371097207262,298.2940151416972,0.10666601275291827
0.11304024575762571,268.007507883206,0.35890278028046163,108.06062717850868,298.3031424392124,0.10709523135001665
0.11351984517738871,267.916350532911,0.36042550843820914,108.02387253486972,298.33017316589803,0.10752602989808455
0.11400658939561271,267.841429596942,0.36197092133107034,107.99366441348702,298.37711748413454,0.10796305656445
0.11448265604792872,267.782127634063,0.36348243295217364,107.9697538620542,298.43853684777594,0.1083903116302137
0.11496354763769372,267.659833486867,0.3650092637496775,107.92044486190478,298.43095750463164,0.10882171167604414
0.11544127962756072,267.537751240329,0.36652606281750527,107.87122130010064,298.4226515921926,0.10925009309930218
0.11592759189299372,267.444114294723,0.36807010426025505,107.83346688363233,298.4482664308648,0.10968598003788914
0.11640573638282671,267.394759838968,0.3695882130154748,107.81356716707191,298.5210437629322,0.11011436095313044
0.11687533594219772,267.359382868041,0.37107919161647773,107.79930317239415,298.60710055804196,0.11053490771915221
0.11736715065587272,267.297304709797,0.37264070333239585,107.77427325899016,298.66922774158047,0.11097515959384245
0.11784776483385971,267.211180521336,0.37416665334750454,107.7395479862027,298.70142088439246,0.11140519804970918
0.11833777083346371,267.092922940926,0.37572242239624726,107.69186652978135,298.70010404714924,0.11184344970605085
0.11883443286822472,266.983786569202,0.37729932435661345,107.64786274470224,298.71065343116425,0.11228745847935741
0.11931794940688072,266.867784174838,0.37883448936684627,107.60109057929469,298.7099009453377,0.11271952606332288
0.11979689291688471,266.751010096863,0.3803551350111089,107.55400727105517,298.70695228890776,0.11314732325197546
0.12027453612023171,266.634897970676,0.3818716521817357,107.50719086177656,298.70428663756434,0.11357377680554914
0.12076285786410472,266.531500340522,0.3834220737185325,107.46550093729846,298.718606032451,0.11400957654089697
0.12125858924171272,266.476314317774,0.38499602084243784,107.44324993292646,298.78885625827843,0.11445179477777112
0.12175991220452871,266.42495387419,0.3865877212493786,107.42254140207342,298.864832867007,0.11489880221069294
0.12227483999181772,266.383960402123,0.3882226169740212,107.406012834136,298.95601653667933,0.11535773253324934
0.12278316692841872,266.293868002909,0.3898365549977294,107.3696875787729,298.9902724499245,0.11581057334513113
0.12329330723569572,266.179348030553,0.3914562504733339,107.32351312591896,298.9974801670811,0.11626482352041848
0.12380769833424672,266.060035633773,0.3930894422112333,107.27540636753727,299.0003162643181,0.11672264994322804
0.12430915721698872,265.954737060691,0.3946815741639392,107.23294998287062,299.01534628257133,0.1171687645567282
0.12481666306918472,265.847230855571,0.3962929052446615,107.18960348096624,299.02939509714656,0.11762005621523113
0.12532991811008773,265.757978967737,0.3979224899995285,107.15361711979156,299.0654047088659,0.11807625320621597
0.12583390742895273,265.6283508969,0.3995226560869249,107.10135108163007,299.0534042141659,0.11852401211346886
0.1263453492194137,265.518788776046,0.4011464837716385,107.05717563450175,299.0658528682713,0.1189781871510399
0.12686369325297273,265.444594860966,0.4027922260781884,107.02726064794149,299.1198765190672,0.11943828120616946
0.12739138984781573,265.351149455294,0.4044676627668149,106.98958346037453,299.15460118211934,0.11990645946020792
0.12790911399721572,265.248834123922,0.40611143694115986,106.94832991876535,299.1765774855073,0.1203655771322092
0.12841337357154972,265.084112534479,0.40771246108967035,106.88191417390193,299.1244577052518,0.12081255187585303
0.1289153521507117,264.882077407522,0.40930624307850966,106.80045361071286,299.0294436949248,0.12125730640514823
0.1294001234292317,264.728440132291,0.41084539188781066,106.73850706133973,298.9843329606374,0.12168662754403059
0.1299163998579387,264.595847247873,0.41248456954895535,106.68504561034239,298.97118713967774,0.12214364756081156
0.1304337741608407,264.547996487887,0.4141272329606692,106.66575218391606,299.053990116491,0.12260143000344745
0.13096428277276473,264.481383107727,0.415811597803528,106.63889366903554,299.1189977531793,0.12307061641671907
0.1315114294619607,264.430973987775,0.4175487885417252,106.61856871187089,299.2066693709259,0.12355428719992677
0.1320316063540137,264.319671025023,0.4192003501739935,106.57369135728928,299.2182217814212,0.12401390019864528
0.13255363338084772,264.188614142665,0.4208577859841915,106.52084922232254,299.2077748451261,0.1244749356473632
0.1330953039542427,264.051665600264,0.42257759005472056,106.46563157002646,299.19570229295516,0.12495309497274618
0.13362853303756572,263.891735674381,0.4242705923942711,106.40114782391042,299.15520119328556,0.12542357936476356
0.13415784609323272,263.687368392363,0.42595116134601385,106.31874693580076,299.06309777787516,0.12589038970470554
0.13468194856765572,263.502182449263,0.4276151867023069,106.24407996354284,298.99116983335966,0.1263523901376834
0.1352126601368937,263.298889187824,0.4293001959346375,106.16211212053064,298.90023240599885,0.12681999914197206
0.1357453246399417,263.163222062347,0.43099140573181494,106.10741113553831,298.88639907449334,0.12728910910911978
0.13628899619002072,263.067565996398,0.43271756290331576,106.06884260974768,298.9207804961991,0.1277676859998572
0.1368373259981267,262.975085762085,0.4344585100440523,106.03155457927267,298.95989330189667,0.12825013153171272
0.1373862193214027,262.845001005383,0.4362012463454536,105.97910440537042,298.9562819610428,0.1287328398697419
0.13792883713782572,262.651559732188,0.43792405791259664,105.9011088840182,298.87878393848484,0.12920980047804934
0.1384785933792757,262.450224904571,0.43966953397920033,105.81993068152302,298.7939628814305,0.12969280386730883
0.1390275547075257,262.221923424144,0.44141248619639406,105.72787952461486,298.6779962285068,0.1301748761895658
0.13958121888642872,262.067711118243,0.44317036996441117,105.66570112287559,298.64744166690383,0.13066084306217293
0.14012294959214072,261.869781690187,0.44489036495504675,105.5858959774834,298.56374790966595,0.13113610711037668
0.1406658163573097,261.593409712215,0.4466139669344583,105.47446279596511,298.39066024307596,0.1316121413521488
0.14120676664418172,261.352600660362,0.44833148409527696,105.37736858625796,298.2573563536597,0.13208626975093432
0.14176238569602673,261.170918648726,0.4500955745848848,105.30411439916632,298.1951311507923,0.13257302101714877
0.1423276936383857,261.037866034987,0.4518904273018746,105.25046758530677,298.1907834600326,0.13306801721630615
0.1429058717018457,260.925457993181,0.4537261426533601,105.20514466285059,298.2132380168998,0.133574029454675
0.14348898420027673,260.696760635151,0.4555775248358786,105.11293388809288,298.1038740029915,0.13408410102833015
0.14407404849659372,260.424709878451,0.457435103976685,105.00324302299146,297.9451521591903,0.13459561856967117
0.14465434806753172,260.151165545476,0.4592775551144132,104.89294994793592,297.7831627964653,0.13510271201443663
0.14524379242763172,259.874349390245,0.4611490409577307,104.7813376741468,297.6194854503476,0.1356175334929077
0.14583698509723472,259.558495198964,0.4630324276837202,104.65398526422229,297.411723595156,0.13613536131345186
0.1464387046409247,259.218924751194,0.46494288723493593,104.51707045968142,297.1786083101722,0.1366603588608275
0.1470279429556627,258.900075661765,0.46681371888422907,104.38851050682366,296.96562121737975,0.13717419962526173
0.1476017429723877,258.576198873506,0.46863553393733093,104.25792338579761,296.74249651841023,0.13767432392174755
0.14819329097049572,258.262061313428,0.4705136988313239,104.13126312157416,296.5347661122888,0.1381896556499318
0.14877315225087873,257.948488847134,0.47235475839653995,104.00483070316443,296.3242986512728,0.1386945487835798
0.14935860223441672,257.55565142811,0.47421356209427307,103.84643865581397,296.0238035229872,0.13920404959445368
0.1499307296805597,257.165026312831,0.476030066735777,103.68893860933346,295.7219663562341,0.13970170550057168
0.15050324706053672,256.665847723833,0.47784780941720406,103.48766980224946,295.29489121581514,0.14019945279311374
0.1510963351312457,256.275898149375,0.4797308640417051,103.330442133828,294.998247142214,0.14071482313678713
0.15168911477954772,255.918777442327,0.481612939425064,103.18645106474625,294.7388702480177,0.14122966021066077
0.1523151122349357,255.589827196871,0.4836004813459209,103.0538183257784,294.5200204124702,0.1417730597960018
0.15296309132138972,255.1988793839,0.4856578149454123,102.89618816758848,294.2348888762158,0.14233522977836635
0.15361956145389272,254.711131469682,0.48774210761610937,102.69952820857577,293.8397437834793,0.14290444428228885
0.15426324556033172,254.154288312617,0.4897858046540532,102.47500904764718,293.3609537007976,0.1434622578083251
0.15489369349904372,253.516431082721,0.4917874768594638,102.21782501255312,292.78452745581944,0.14400829947722393
0.15550695026637973,252.887918131656,0.49373456709575564,101.9644085906837,292.21374703952375,0.14453916565698646
0.15613766825708672,252.302844282994,0.4957370967162503,101.72850681490318,291.69682208397154,0.14508485334730356
0.15677598347374472,251.643500919793,0.49776374752913943,101.46265957086054,291.0951582612698,0.14563681103269832
0.15742156858871473,251.033213616654,0.4998134802691692,101.21659173023488,290.5512558720536,0.14619474536388083
0.1581006078781367,250.273038409298,0.501969430013084,100.91008908662896,289.84135791731626,0.14678125610067147
0.15879084723298373,249.552426021196,0.5041609399647233,100.61953817174623,289.1790671781482,0.14737708839462288
0.1595047805114767,248.798520349441,0.5064276781239385,100.3155634048946,288.48307372935875,0.14799300061264883
0.1602227504253417,247.872061894244,0.5087072326004599,99.9420153557592,287.5868054045403,0.1486120129123398
0.16090059066807672,246.952655416878,0.5108593753711436,99.57131066408522,286.6874835405037,0.1491960751635814
0.1615599890009387,245.882280060417,0.5129529650779804,99.13973532036015,285.6070185225037,0.14976391976456438
0.16224547393531172,244.696257754877,0.5151293797446147,98.6615311267664,284.3971180645142,0.15035388735452726
0.16293858973521572,243.499029929469,0.5173300224093099,98.17880886756191,283.1744184680698,0.1509500688192666
0.16366725188975273,242.251862802488,0.5196435247499649,97.67595108196316,281.90055945254466,0.15157644236765583
0.1644008090071827,241.01717745364,0.521972568597805,97.17812594930766,280.64059641164613,0.15220662767368498
0.16513339943259572,239.478038260246,0.5242985431984913,96.55754502653119,279.0238608076096,0.15283558641308378
0.16588404449798771,237.91109039615,0.526681841281111,95.92575164772768,277.37674430198973,0.15347963572579382
0.16663741157132173,236.043029946224,0.5290737817389465,95.17254967431752,275.37662947591474,0.15412560371684522
0.1674330221775557,233.972402936184,0.5315998454137394,94.3376728638694,273.14710946593414,0.15480734033074045
0.1683084570031337,231.508663515609,0.5343793509849495,93.34429312949355,270.4735294547788,0.1555569394403792
0.16901082039779772,229.353460602051,0.5366093547630078,92.47531531474696,268.11667713947764,0.15615793856154872
0.1694871859003687,227.725516092267,0.5381218152336706,91.81892808840205,266.3220729724544,0.1565653500777244