File: example/data/02 processed data/test_ID_075.csv
Strain,Stress_MPa,Displacement(mm),Force(kN),True Stress (MPa),True Strain
4.88825542336073e-05,0.0412864313283013,0.00015520210969170319,0.008323344555785542,0.041288449514519814,4.888135952039968e-05
7.4328300170382e-05,1.03534430520921,0.00023599235304096284,0.2087254119301767,1.0354212605915072,7.43255379590596e-05
0.0001188973971784,2.96080379794204,0.00037749923604141997,0.5968980456651153,2.961155829807171,0.00011889032944309808
0.000165396847184,6.61784281181902,0.0005251349898092,1.3341571108627144,6.618937382155254,0.00016538317063346286
0.0002261034250771,11.2838059251635,0.0007178783746197925,2.2748152745129615,11.286357232331085,0.0002260778675499479
0.0003211706322849,16.5567127479341,0.0010197167575045575,3.337833289983515,16.562030277835916,0.00032111906803778187
0.0003645753030566,21.9693818847479,0.0011575265872047049,4.429027387965177,21.977391378806498,0.00036450886162887045
0.0004694607943096,27.429335927221,0.00149053802193298,5.529754122927754,27.44221292505278,0.00046935063206750776
0.0005297404501253,33.0118392980403,0.0016819259291478274,6.655186802484925,33.0293270046495,0.0005296001871860818
0.0006091387874375,38.7631051160844,0.0019340156501140625,7.814641991402615,38.78671722693212,0.0006089533377121474
0.0007035938661928,44.6595154531394,0.00223391052516214,9.003358315352903,44.69093761427937,0.000703346460070666
0.0007785491347406,50.5803295346691,0.002471893502801405,10.19699443418929,50.6197088064632,0.0007782462225740518
0.0008729415768607,56.4983715149838,0.002771589506532722,11.390071697420735,56.547691292504155,0.0008725607849523263
0.0009694788781652,62.3626143631202,0.00307809543817451,12.572303055605033,62.423073600532405,0.000969009237031112
0.0010738974720924,68.259625617547,0.00340962447389337,13.761140524497476,68.33292945694365,0.0010733212566959585
0.001168410349586,74.1916230042351,0.00370970285993555,14.957031197653796,74.27830926440582,0.0011677282894458016
0.0012698840076419,80.0146757958728,0.004031881724263032,16.130958640447957,80.11628515304264,0.0012690783869033111
0.0013487401275974,85.7808375859124,0.004282249905121745,17.29341685731994,85.89653364374342,0.001347831394636076
0.0014462601262818,91.4460034724481,0.004591875900944714,18.435514300045536,91.57825818097814,0.0014452152993784768
0.0015434780376237,97.098879039025,0.004900542769455247,19.57513401426744,97.24874902629962,0.001542288099668839
0.0016420230588719,102.741356779209,0.005213423211918282,20.712657526688535,102.91006045614024,0.0016406764129564685
0.0017505773783123,108.314507351908,0.005558083176141552,21.836204682144654,108.50412027822128,0.0017490469036160598
0.0018475727966147,113.82491847713,0.005866043629251672,22.94710356498941,114.03521830008523,0.0018458681333320603
0.0019361384590009,119.204163583996,0.006147239607327857,24.031559378533593,119.434959349584,0.0019342665587173099
0.002027636611629,124.545226660454,0.006437746241922074,25.10831769474753,124.79775912183437,0.002025583731043399
0.0021138369719657,129.807587127016,0.006711432385991097,26.16920956480643,130.08197920392675,0.002111605962034725
0.0022005259276328,135.010452691701,0.00698666982023414,27.218107262646924,135.30754669335053,0.002198108316481395
0.002297554760984,140.136458255125,0.0072947363661242,28.251509984233202,140.4584294419765,0.002294919417835731
0.0023847191734471,145.175461249396,0.007571483375694542,29.267372987878236,145.52166395535147,0.002381880243150963
0.0025030360128587,150.104854639391,0.007947139340826371,30.261138695301224,150.4805724962583,0.00249990863575571
0.0026109402802205,154.97019836315,0.008289735389700088,31.241991990011037,155.3748162962901,0.002607537696988037
0.0027149155274955,159.800081919218,0.008619856799798212,32.21569651491435,160.23392564291552,0.0027112368011181203
0.0028157579349846,164.541578984955,0.008940031443576104,33.17158232336693,165.00488824161678,0.0028118011145025408
0.0029168129902413,169.182325120137,0.009260881244016127,34.10715674421962,169.67579832376663,0.002912567345062976
0.0030208369317777,173.616522401844,0.009591157258394196,35.00109091621175,174.14098960468232,0.00301628337196312
0.0031316972145115,177.92204456903,0.009943138656074012,35.86908418511645,178.479242540407,0.0031268036648717462
0.0032485506711753,182.101757755364,0.010314148380981577,36.711714363481384,182.69332454274237,0.003243285530080549
0.003372958216213,186.171413112301,0.010709142336476274,37.53215688343988,186.7993615097821,0.0033672825515877196
0.0035151271995411,190.062256811589,0.011160528858542991,38.316550973216344,190.7303498201136,0.0035089635796421072
0.0036647429794879,193.67987462697,0.011635558959874082,39.04586272479715,194.38966158777725,0.0036580441702226837
0.0038450597628388,196.913539734172,0.012208064747013189,39.697769610409075,197.670684062562,0.0038376864151467745
0.0040604915252785,199.726480123555,0.012892060592759236,40.26485839290869,200.5374678034704,0.004052269977733272
0.0043120403175225,202.0054358641,0.013690728008133937,40.72429587020257,202.87649144790473,0.004302770111121055
0.0046008753155297,203.701660199836,0.014607779126806797,41.06625469628694,204.63886613998187,0.0045903236409429015
0.0049068296005066,204.880844917701,0.015579183981608454,41.30397833540853,205.88616031211998,0.004894830348324467
0.0052383803525391,205.618552014291,0.016631857619311644,41.452700086081066,206.6956601972802,0.005224707765535374
0.0055830312437999,206.10063881545,0.01772612419906468,41.54988878519472,207.25130512132378,0.005567503891186484
0.0059532059015859,206.395592464324,0.018901428737535232,41.60935144080772,207.62430792344395,0.005935555587326976
0.0063172478382314,206.605995700272,0.020057261886384695,41.65176873317483,207.91117697997518,0.006297377667396281
0.0066999856075233,206.7247846786,0.021272454303886478,41.67571659120576,208.109837760665,0.006677640456551666
0.0070687258787375,206.823063813951,0.02244320466499156,41.69552966489252,208.28503935745243,0.007043859549371971
0.0074439270693818,206.880599591162,0.023634468445287216,41.70712887757826,208.42060368658858,0.007416357775614149
0.0078212636411087,206.928318997157,0.024832512060520118,41.71674910982685,208.54675993484523,0.007790836110153924
0.0082036595585843,206.989372803183,0.026046619098505152,41.729057557121685,208.6874431499052,0.00817019245407708
0.0085790054958805,207.028414802262,0.027238342449420586,41.736928424136025,208.80451271065405,0.008542414952944787
0.0089545404211024,207.085959161481,0.02843066583700012,41.748529366954564,208.94031875343524,0.008914686264436875
0.0093283109462678,207.086665312919,0.029617387254400263,41.748671727084464,209.0184341197836,0.009285070949799632
0.0096903131343043,207.158272819681,0.03076674420141615,41.76310780044769,209.16570135166535,0.009643663176337759
0.010083370336644,207.211050885713,0.0320147008188447,41.773747858559744,209.30043664963884,0.010032872334292718
0.0104499077826045,207.305697195833,0.03317845720976929,41.792828554679936,209.47202261433802,0.010395684918426322
0.0108293377021171,207.34999659112,0.03438314720422179,41.80175931276979,209.59545972673808,0.010771120351028658
0.0111926340654443,207.389421453844,0.03553661315778565,41.809707365094944,209.71065535722107,0.01113046003408734
0.0115958576211774,207.451132619215,0.036816847947238246,41.82214833603374,209.85670641641943,0.011529140927053951
0.0119741266891677,207.520268507555,0.03801785223810745,41.83608613112308,210.00514249323456,0.011903004025764859
0.0123468319084043,207.670576711742,0.039201191309183654,41.86638826508719,210.23465041472326,0.012271231427516517
0.0127283135820977,207.729262687006,0.040412395623160194,41.87821935770041,210.37330588266417,0.012647989474303411
0.0130818392279613,207.81572172896,0.041534839548777125,41.89564950055834,210.53433358966097,0.012997010974627044
0.0134657390662248,207.874550351989,0.04275372153526374,41.907509350960986,210.6737348055377,0.013375881766477686
0.0138448485483158,207.966434798233,0.04395739414090266,41.92603325532377,210.84569859114774,0.01374988414068345
0.0142165667194378,208.039041241132,0.04513759933421501,41.94067071421221,210.99664215118443,0.014116459011134782
0.0145867147192731,208.083848790959,0.04631281923369209,41.949703916257334,211.11910853096109,0.014481351957955899
0.0149524812464311,208.137531117824,0.04747412795741874,41.960526273353324,211.24970364854173,0.014841794891844527
0.0153257805884904,208.182572985409,0.04865935336845702,41.96960671385846,211.37313342133075,0.015209527092186974
0.0156848730512134,208.247941532768,0.04979947193760254,41.98278501300603,211.51428405888598,0.015563136725717209
0.0160516471000515,208.348208061984,0.05096397954266351,42.002998745295976,211.69253997172308,0.01592418162419165
0.0164243431011436,208.459928567119,0.05214728934613093,42.02552159913119,211.88374595674526,0.016290922493029665
0.0167885973688541,208.601509913379,0.05330379664611176,42.054064398537214,212.10363667384976,0.016649226598179852
0.0171651966029703,208.658926763882,0.054499499214430695,42.06563963559861,212.2405982647488,0.01701953907974735
0.0175389424649023,208.748164399806,0.055686142326064794,42.083629943000886,212.40938644486818,0.017386910295010948
0.0179014342903576,208.753380525233,0.056837053871885375,42.08468151388697,212.4903654495955,0.017743090543204075
0.0182686355846348,208.813032603218,0.05800291798121549,42.09670737280875,212.62776180116867,0.01810376895969856
0.018630486427268,208.87951788844,0.0591517944065759,42.11011080630951,212.77104491139485,0.018459064754693243
0.0189863001048163,208.977065254898,0.060281502832791746,42.12977635538744,212.94476653085127,0.01880830969958842
0.0193472728308365,209.066804697246,0.06142759123790588,42.14786782696479,213.11167720759485,0.019162493857261882
0.0197088752339374,209.156001062388,0.06257567886775124,42.16584981417742,213.27823059175586,0.01951717011984017
0.0200730445286365,209.229665599425,0.06373191637842089,42.18070058484408,213.429541993714,0.01987423701511961
0.0204462175090975,209.352030639587,0.06491674059138455,42.205369376940745,213.63248779401528,0.020239999781062522
0.0208129167651637,209.438389268828,0.06608101072939475,42.22277927659572,213.79741303211003,0.02059928709922175
0.0211864342882376,209.510144389349,0.06726692886515438,42.23724510889276,213.94891729617308,0.02096512220788331
0.0215512350917903,209.575126714188,0.0684251714164342,42.2503455455803,214.09172953939722,0.021322290739995087
0.0219262587404512,209.615231403762,0.06961587150093256,42.25843065099843,214.21130920346044,0.021689335303982763
0.0222802378772382,209.693617298976,0.07073975526023128,42.27423324747356,214.36564097373574,0.02203565955342699
0.0226537445932443,209.739970992438,0.07192563908355065,42.283578152075506,214.49136672629515,0.022400959092053932
0.023017008471508,209.793902117191,0.0730790018970379,42.2944506668257,214.62273013949311,0.02275611290313316
0.0233827422012372,209.897496697841,0.0742402064889281,42.31533533428475,214.80547575181166,0.0231135540467835
0.0237582367624954,209.970076044736,0.07543240172092289,42.32996733061878,214.95859482444598,0.023480401830426954
0.0241385933313987,210.077429384358,0.07664003382719087,42.35160976388657,215.14840302037263,0.023851862509195097
0.0245071346479054,210.117220702055,0.07781015250709963,42.35963169353428,215.2665917216439,0.02421165270175882
0.0248622537519046,210.137780896029,0.0789376556622971,42.36377662863944,215.3622797275282,0.024558216976177744
0.0252173801705688,210.126499219197,0.08006518204155594,42.36150224259011,215.42533903391822,0.024904668320154998
0.0255544464998536,210.152845229673,0.08113536763703517,42.36681359830208,215.5231848698867,0.02523338975852899
0.0259117818137228,210.171096236608,0.08226990725856988,42.370493001300176,215.61700382584195,0.025581760414161905
0.026256061456192,210.230185646623,0.0833629951234096,42.3824054263592,215.75000232090738,0.025917288179912675
0.0266246196522044,210.296795724532,0.08453316739574897,42.395834018065656,215.895867924775,0.026276352594482764
0.0269823001959103,210.38767453296,0.08566880312201519,42.41415518584474,216.0644179247278,0.02662469632459551
0.0273581231189733,210.500371008519,0.08686204090274023,42.436874795317436,216.25926607515962,0.02699057816481089
0.0277215157876397,210.549418857988,0.08801581262575604,42.44676284177038,216.38616789693805,0.02734423129393943
0.028083394801965,210.613235652872,0.08916477849623887,42.459628307619,216.5279703002309,0.02769628709086746
0.0284501576194606,210.64849419158,0.0903292504417874,42.46673642902253,216.64147705363249,0.028052967701258858
0.028830026059472,210.742783464436,0.0915353327388236,42.4857451464303,216.81850340356138,0.028422259591923123
0.0291926207185544,210.794174780764,0.09268657078141021,42.496105635802024,216.94780917481953,0.0287746314799603
0.0295480734062117,210.838728261357,0.09381513306472214,42.50508761748957,217.0686064808959,0.029119942273304632
0.0299138149636792,210.856639909323,0.09497636250968146,42.50869860571952,217.16416641943366,0.02947512394806927
0.0302737965276734,210.889613319545,0.09611930397536304,42.51534604522027,217.2740425629806,0.02982458878869811
0.030651715565661,210.904536725039,0.09731919692097367,42.51835460376787,217.3691225962424,0.03019133570895885
0.0310186091926615,210.945863032975,0.09848408418670025,42.52668598744776,217.48911031920355,0.030547254525335677
0.0313965004414094,210.99942995272,0.09968388890147485,42.53748507846836,217.6240736483677,0.03091370961113451
0.0317573144745734,211.057500819762,0.10082947345677055,42.549192165264024,217.7601202455127,0.0312634790119749
0.0321100465331208,211.102203183737,0.10194939774265854,42.55820416184138,217.8807047512111,0.03160529561186495
0.0324563616875794,211.126593042715,0.1030489483580646,42.563121157411345,217.97899410837576,0.03194078025050665
0.032814801455358,211.09265542617,0.10418699462076164,42.556279333915874,218.0196190026641,0.03228789183350281
0.033179218057904,211.119364034537,0.10534401733384519,42.561663789362655,218.12413945008493,0.032640667885014546
0.0335427228652875,211.125251228021,0.1064981450972878,42.56285064756903,218.20696701982672,0.0329924373262095
0.033878809504044,211.171996254639,0.10756522017533969,42.57227444493522,218.32625208833863,0.0333175637084736
0.0342369482040658,211.207216383234,0.10870231054790891,42.579374822859975,218.43830691087172,0.033663906704282175
0.0345950898138219,211.202609805401,0.10983941015888453,42.57844613676885,218.50918306053242,0.03401013260058716
0.0349580237803962,211.248024813569,0.11099172550275792,42.58760180241551,218.63283828856348,0.03436086916096905
0.0353410053690612,211.285626819135,0.11220769204676931,42.59518236673762,218.75267329095553,0.03473084623929585
0.0356983849302566,211.298712228424,0.1133423721535647,42.59782038525028,218.84173499282178,0.035075967212287965
0.0360512023176881,211.319769102117,0.11446256735865971,42.602065450986785,218.93810085174454,0.03541656570258223
0.0364102986241857,211.38248844455,0.11560269813178958,42.614709670421284,219.07898797273955,0.03576310657673419
0.0367774297797559,211.420619947179,0.11676833955072498,42.62239698135129,219.19612695127884,0.0361172772621747
0.0371485776348969,211.477122331651,0.11794673399079765,42.63378786206084,219.33319662859296,0.03647519539211414
0.0375193497992981,211.49100694449,0.11912393561277146,42.636587000009186,219.4260120134461,0.03683262335776157
0.0378946612793902,211.508032813476,0.12031554956206389,42.64001941519677,219.52305807481284,0.03719429720421331
0.0382709985664714,211.555851394703,0.12151042044854668,42.64965964117213,219.6523050801583,0.03755682828589088
0.0386347722882069,211.586290412486,0.1226654020150569,42.65579614715718,219.76087856187883,0.03790713182932603
0.0390074760591432,211.62078002574,0.12384873648777964,42.66274925318918,219.87557253621128,0.038265907528299774
0.0393542475552358,211.590148314548,0.12494973598787365,42.656573900212884,219.91711939156778,0.03859960449295261
0.039724480728871,211.570099312565,0.12612522631416542,42.6525320214131,219.9746116455123,0.03895575567906408
0.0400940647607342,211.552853959518,0.12729865561533107,42.64905535823883,220.03486778648903,0.039311155948529714
0.0404722246417564,211.574336108692,0.12849931323757657,42.65338615951231,220.13722016811343,0.039674672253790136
0.0408439926041759,211.576839756969,0.12967967651825849,42.653890895004956,220.21848263521755,0.04003191538992956
0.0412148423478358,211.602434825638,0.13085712445437866,42.65905086084862,220.32359581739487,0.040388149076851496
0.0415794745437593,211.631217033662,0.13201483167643577,42.66485335398627,220.43073183497793,0.040738286578852
0.0419492229259409,211.625381332227,0.13318878278986235,42.663676876576965,220.50290163051983,0.04109321174644114
0.0423176063368215,211.640260268775,0.13435840011940825,42.66667647018504,220.59636948785146,0.04144670143360082
0.0426865526599798,211.64627241566,0.13552980469543588,42.66788851899706,220.6807221684195,0.04180060607730815
0.0430623058777385,211.676902391165,0.13672282116181975,42.67406352205886,220.79219790918552,0.04216091141348087
0.0434422212302697,211.688430005215,0.13792905240610628,42.67638748905134,220.88464561339,0.04252507583468764
0.0437980940614668,211.692164528853,0.13905894864515708,42.67714036901676,220.96387786296322,0.042866074264085896
0.0441438549153973,211.668308329372,0.14015673935638642,42.67233095920139,221.0121634224514,0.04319727203254933
0.044492916010289,211.644131574198,0.14126500833266756,42.66745692535832,221.06079614439935,0.04353151980889833
0.0448675568054648,211.629619558688,0.14245449285735073,42.6645313030315,221.12492353595636,0.043890137485517934
0.0452374240361429,211.61477695907,0.14362882131475369,42.66153903494852,221.18768435668125,0.044244059645341595
0.0456399397856569,211.642990617073,0.14490680881946064,42.667226908401915,221.30236396489255,0.044629080557090056
0.046035794346705,211.660581709346,0.14616364705078838,42.67077327260416,221.40454472022137,0.04500758527396799
0.0464085088205957,211.708439954238,0.14734701550539134,42.680421494774386,221.5335129572488,0.045363833205889936
0.0467931236709574,211.730033990944,0.14856816765528974,42.684774852574314,221.63754365633824,0.04573132274795793
0.0471685746384884,211.697700245701,0.14976022447720067,42.67825636953332,221.6831790205367,0.04608992622371176
0.0475309807152265,211.641667300304,0.15091086377084412,42.666960127741284,221.7012033072931,0.04643594823858991
0.0479066876407431,211.62050046762,0.15210373325935933,42.66269289427219,221.75853768189998,0.04679454342394552
0.0482834349677302,211.567874306351,0.15329990602254337,42.65208346016037,221.7830980066826,0.047154002546455784
0.0486629252596437,211.594049078438,0.15450478769936873,42.6573602942131,221.89083447412742,0.04751594818631985
0.0490506988064341,211.61290625802,0.15573596871042825,42.661161901616836,221.9926671864363,0.0478856588529795
0.049428053078235,211.614632366693,0.15693406852339611,42.661509885125305,222.0743316474451,0.048245304406244555
0.0498112801516277,211.625363814644,0.15815081448141793,42.66367334503223,222.16669409880538,0.0486104148265608
0.0501952383289516,211.622093442664,0.15936988169442132,42.66301403804106,222.24451485869022,0.04897608815016575
0.0505648298276667,211.605968009572,0.16054333470284177,42.65976315072972,222.30578777249468,0.04932795270445775
0.0509333793723196,211.596753568212,0.16171347950711473,42.65790551935154,222.37409129165297,0.0496787020382597
0.0512799681627972,211.582767883741,0.1628138989168811,42.65508600536219,222.43272548461576,0.050008439069017405
0.0516585032045925,211.552900501646,0.16401574767458116,42.64906474113183,222.48140669015112,0.05036844489043117
0.0520442828447243,211.548894680473,0.16524059803199964,42.64825716758336,222.55880519071235,0.05073520738845568
0.0524639540954581,211.538846112895,0.16657305425307944,42.64623137635963,222.63701042476808,0.05113403809762597
0.052846053012729,211.509465494603,0.16778621831541457,42.64030824371197,222.68690592082478,0.05149702399535718
0.0532334608711189,211.496630184968,0.1690162382658025,42.637720645289555,222.75532777229301,0.0518649188067406
0.0536189308857473,211.492790154054,0.17024010556224767,42.636946495057295,222.83280745215808,0.052230839096588814
0.0540059268182776,211.517799283688,0.17146881764803137,42.6419883355915,222.94101407256596,0.05259807327060688
0.0543839599171603,211.515602787741,0.17266907273698395,42.641545522008585,223.01865885160348,0.05295667212873279
0.054766979029627,211.459376313233,0.1738851584190657,42.630210264747774,223.04036754139784,0.05331986957430624
0.0551488762688749,211.361358559501,0.1750976821536778,42.61044988559541,223.01769997072026,0.05368187191905325
0.0555256285320242,211.307914214622,0.17629387058917684,42.59967550566779,223.04091896517994,0.05403886895132291
0.055906646451064,211.241675059473,0.1775036024821282,42.58632169198976,223.05148870275352,0.05439977839434887
0.0562890079679178,211.26481286128,0.178717600298139,42.59098627283405,223.15669959576923,0.05476182962784176
0.0566802626156656,211.307896214904,0.17995983380473826,42.59967187692465,223.28488326512854,0.055132165967008144
0.0570814248123373,211.346962127894,0.18123352377917093,42.60754756498343,223.41094785591326,0.055511737802257294
0.0574761990719858,211.336685606744,0.1824869320535549,42.60547581831959,223.48351501989092,0.05588512489729421
0.0578688982000447,211.324077125698,0.1837337517851419,42.60293394854072,223.5531686321034,0.056256411013282
0.0582666363632897,211.283395721945,0.18499657045344478,42.59473257754411,223.59416851007663,0.056632320931557525
0.0586469113298254,211.279641125408,0.18620394347219563,42.59397565088226,223.67053950428712,0.05699159396001009
0.059040256515529,211.251194756765,0.18745281443680456,42.58824086296382,223.72351948441639,0.057363079603593034
0.0594329599581892,211.210696966207,0.1886996478672507,42.58007650838733,223.76357386174078,0.057733821555017675
0.0598353206934789,211.161622036805,0.18997714320179548,42.57018300261989,223.79654540953243,0.058113538218356464
0.0602338754950944,211.107852845229,0.19124255469692472,42.55934313359817,223.8236969695452,0.058489521046678324
0.0606281286559708,211.091007262705,0.1924943084827073,42.55594706416133,223.88906000914676,0.05886130682495728
0.0610251025287312,211.079446333105,0.19375470052872157,42.55361638075397,223.96059118729056,0.05923551866274296
0.0614178931428295,211.052589468132,0.19500181072848366,42.548202036775415,224.0149948556032,0.05960564932762645
0.0618108939415689,211.012996758038,0.19624958826448125,42.54022014642046,224.0558987209417,0.059975840995729425
0.0622089674196648,210.990490312412,0.19751347155743573,42.535682846982255,224.11599085011594,0.06035067127862663
0.0626116174797299,210.952135806134,0.19879188549814242,42.527950578516624,224.16019023975971,0.06072966804451485
0.063001595313886,210.919999061376,0.20003006512158802,42.5214718107734,224.20829548584604,0.06109660012433482
0.0634002948172895,210.891022874248,0.20129593604489412,42.515630211448396,224.2615758987951,0.06147159932831991
0.0638040261736462,210.839848518807,0.20257778310132665,42.50531346139149,224.29227973214856,0.061851188028117364
0.0642052304437803,210.881055594682,0.20385160665900245,42.51362080788789,224.42072236536623,0.06222825807481973
0.0646138012158587,210.873917452938,0.20514881886035138,42.5121817585123,224.49928283685156,0.06261210542963828
0.0650218764705692,210.880305472505,0.2064444577940572,42.51346958325701,224.59213864501413,0.06299534023733855
0.0654182815957134,210.803604399111,0.20770304406639004,42.49800664686078,224.59401395308342,0.0633674747262778
0.0658149440582644,210.715245969055,0.20896244738498942,42.480193587361484,224.58345809473178,0.06373971222929395
0.0662165885237229,210.627476194064,0.21023766856282022,42.46249920072331,224.57450911699658,0.06411648383334557
0.0666158715893117,210.583639230818,0.21150539229606466,42.45366166893291,224.6118519006281,0.06449089961866436
0.0670243204060863,210.568937077214,0.212802217289324,42.45069771476635,224.68217698344623,0.0648737653176668
0.0674302099099108,210.560506395004,0.2140909164639668,42.44899808923281,224.75864553995626,0.06525408684989169
0.0678332796802551,210.536705962507,0.21537066298480992,42.444199922041406,224.81810122102138,0.06563162318402277
0.0682338242641061,210.50159725538,0.21664239203853686,42.43712200668461,224.86492624981724,0.06600665315176663
0.0686314909341636,210.454841862854,0.21790498371596942,42.42769611955136,224.89867143421532,0.06637884944492553
0.069020295923903,210.356446661464,0.21913943955839202,42.40785964695114,224.87531085953896,0.06674261775968768
0.0694383591483283,210.34399948682,0.22046679029594235,42.40535029654291,224.94994166788157,0.0671336126744219
0.0698612219405556,210.358435148169,0.22180937966126404,42.40826052587087,225.05433247312322,0.06752894094118046
0.0702832898863091,210.380509921987,0.22314944538903136,42.41271080027258,225.16674428726353,0.06792337033498344
0.0706787636835616,210.264767845926,0.22440507469530807,42.38937719773869,225.12602168348712,0.06829280593622727
0.0710829968461856,210.166712951705,0.22568851498663928,42.36960933106373,225.10599274562426,0.06867028318404599
0.0714849526107479,210.114734282079,0.22696472453912458,42.35913043126713,225.13477610505333,0.06904549253913768
0.0719137395994493,210.099258076316,0.22832612322825152,42.35601042818531,225.2082814116537,0.06944559261942586
0.072331973137631,210.115248350811,0.2296540147119784,42.359234067523495,225.31329885032852,0.06983569114311756
0.0727508310545317,210.072965502504,0.23098388859813815,42.35070984530481,225.35594832490114,0.07022621958463553
0.073172641590273,210.064796217984,0.23232313704911675,42.349062917545574,225.43579226237625,0.07061934687603316
0.0735956433919608,210.015242930005,0.23366616776947552,42.33907297468901,225.4714498555577,0.0710134292836423
0.0740170603932619,209.983958954031,0.23500416674860652,42.33276612513265,225.52635432554777,0.07140588087043642
0.0744473373592077,209.927757823768,0.2363702961154844,42.32143597727163,225.55632043153608,0.07180642460031941
0.0748668608258693,209.871848080012,0.237702283122135,42.31016457293042,225.58429452148624,0.07219680351499257
0.0752878193881605,209.828388853705,0.23903882655740957,42.30140319290693,225.62591069623147,0.07258836470967624
0.0757018146560234,209.794478349235,0.24035326153287426,42.29456683520578,225.67630106508588,0.07297329940803308
0.0761318193402531,209.768544885868,0.2417185264053036,42.28933864899099,225.7386058483867,0.07337296291654977
0.0765609223382574,209.725970008207,0.24308092842396722,42.28075555365454,225.78278371032107,0.07377162919658103
0.076984075078106,209.673398697865,0.24442443837298655,42.27015717748958,225.81491136510306,0.07416461169362833
0.0774083749845662,209.580878733005,0.24577159057599765,42.25150515257381,225.80419398356435,0.07455850456299284
0.0778243317526773,209.482826394101,0.24709225331475043,42.23173780105077,225.78568737188402,0.07494450164996662
0.0782508266213386,209.429473076367,0.24844637452275004,42.22098177219559,225.8175024634641,0.07534012317787833
0.0786666117038888,209.425569114313,0.24976649215984695,42.220194733445496,225.90036904069459,0.07572565957376663
0.0790882035843955,209.392735973322,0.2511050463804557,42.213575572221714,225.9532313050737,0.07611642861099413
0.0795082161122088,209.359145687051,0.25243858615626297,42.20680377050949,226.00491788740445,0.07650558197869285
0.0799506143899589,209.269249229305,0.2538432006881195,42.18868064462789,226.00045427811335,0.07691531267389339
0.0803750048063311,209.216231268817,0.25519064026010124,42.17799222379351,226.03198686261067,0.07730820753942713
0.0808175900005305,209.187378267259,0.2565958482516843,42.17217545867941,226.09339803734824,0.07771778251340206
0.0812510884447859,209.168517744873,0.2579722058121952,42.16837317736639,226.16368748002643,0.0781187859175826
0.0816914774288602,209.14531922616,0.25937044083663113,42.163696355993864,226.23070935107563,0.07852599875541579
0.0821270090195437,209.119446801122,0.2607532536370512,42.1584804751062,226.2938014947197,0.07892855710242382
0.0825674717353125,209.051863742027,0.2621517227596172,42.14485573039265,226.31274759276118,0.07933550849973504
0.0830010417718126,209.027259798903,0.263528307625505,42.13989557545885,226.37674012091927,0.07973592994988911
0.0834375716358198,208.960049591109,0.26491428994372784,42.126345997567576,226.39516869789162,0.08013892301621783
0.0838733412453654,208.913443242677,0.26629785845403514,42.116950157723686,226.43571175851432,0.08054105232108863
0.0843194527394121,208.84173993563,0.2677142624476334,42.102494771023004,226.4511611561489,0.08095255770158755
0.0847660463966006,208.785608313207,0.2691321973092069,42.09117863594253,226.4835388744268,0.08136433830099413
0.0852177429737885,208.738103119927,0.2705663339417784,42.081601588977286,226.5262931404371,0.08178065162639722
0.085669691104006,208.680939229747,0.27200126925521906,42.070077348717,226.55857083285326,0.0821970234102606
0.0861277628076468,208.67641344172,0.27345564691427854,42.06916494985076,226.6492460821789,0.08261885990298555
0.0865824514665861,208.59128584855,0.27489928340641084,42.05200322706768,226.65163073188486,0.08303740505695008
0.0870289496327915,208.487760132893,0.276316915084113,42.031132442791225,226.63223090855203,0.0834482403812953
0.0874630904323705,208.401134031056,0.2776953121227763,42.013668620660894,226.6285412630228,0.08384754357243002
0.0879044573461998,208.260670049434,0.2790966520741843,41.985351081965895,226.56771123668545,0.08425332963863875
0.08834751966984,208.204251347579,0.280503374951742,41.973977071671925,226.59858053885355,0.08466050889402
0.0887878933728126,208.120405157549,0.28190156145868,41.95707367976188,226.598977499384,0.0850650530545166
0.0892333646856907,208.112513888318,0.2833159328770679,41.95548279988491,226.68309373577014,0.0854741136341061
0.0896793163369869,208.066772924542,0.2847318293699334,41.94626142158767,226.726058872858,0.0858834477587886
0.090122741682607,208.016708123147,0.28613970484227724,41.93616835762644,226.76374417499562,0.08629029694961783
0.0905648112877077,208.001447576506,0.28754327583847195,41.93309183142361,226.83905942384231,0.08669573752780098
0.0910074483712821,207.984431735935,0.28894864857882063,41.9296614379645,226.91256416917358,0.08710153393237911
0.091469430459081,207.965888555005,0.29041544170758216,41.92592313268901,226.98840993604801,0.08752488970689397
0.0919548400348371,207.939649530354,0.2919566171106078,41.92063334531937,227.0607067398178,0.08796952118810696
0.0924071928739239,207.878047552558,0.2933928373747084,41.908214386595695,227.08747438700195,0.08838369506472461
0.0928860881155502,207.828917306165,0.29491332976687185,41.89830972892287,227.13333243202484,0.08882198428975324
0.0933561107984567,207.774078706343,0.2964056517851,41.88725426719875,227.1710586190996,0.08925196655830663
0.0938219551339986,207.694739934985,0.29788470755044555,41.871259570892974,227.1810665067327,0.08967794407686563
0.0943014101024094,207.650634840225,0.29940697707514985,41.86236798378936,227.2323825143187,0.09011617802994264
0.0947692107934454,207.585642486972,0.30089224426918915,41.84926552537356,227.25836999751266,0.09054357465542538
0.0952453163052997,207.538999785538,0.30240387926932655,41.83986235676446,227.30611746579712,0.09097837133230915
0.095734628538121,207.477405939758,0.30395744560853416,41.82744503745521,227.34017832745369,0.09142503196204975
0.0961925670956549,207.405677899169,0.30541140052870425,41.812984664472474,227.35656248650463,0.09184287299719791
0.0966610630107856,207.313561208349,0.30689887505924424,41.79441393960315,227.35271041129957,0.0922701663795073
0.0971311880533269,207.216212288782,0.3083915220693129,41.774788397418455,227.3433691723018,0.09269876215881136
0.0976122417088484,207.143813051566,0.30991886742559366,41.76019271119571,227.36358499964797,0.09313713108768155
0.0980771949246829,207.035283703582,0.3113950938858682,41.73831319464213,227.34072357966522,0.09356064564764324
0.0985395067677514,206.961600363268,0.31286293398761067,41.723458633234834,227.35549438292892,0.09398157648144652
0.0990171733389338,206.927319402102,0.3143795253511148,41.71654759146376,227.41667765590086,0.09441630163145431
0.0994842137202144,206.905126987271,0.3158623785616807,41.71207360063383,227.48892086028073,0.09484117321994211
0.0999682517629418,206.894053817887,0.3173991993473402,41.70984124968602,227.57689067820917,0.09528131735411915
0.100445919059726,206.818089013315,0.31891579301463,41.6945267450843,227.59212204243363,0.09571547862304856
0.100916509018019,206.718162019851,0.3204099161322103,41.67438146320196,227.57943728151562,0.09614302291058546
0.101406986823505,206.629197079655,0.32196718316462836,41.65644613125845,227.582841345263,0.096588441410203
0.10189443483971,206.587635650402,0.3235148306160792,41.64806734712104,227.63776602987164,0.09703091198582645
0.102389077160174,206.553787148533,0.3250853199835524,41.64124348914425,227.7026387986103,0.09747971299175334
0.10288153696501,206.50284725549,0.3266488798639067,41.630974006706786,227.7481775687855,0.09792633374647391
0.103363712724391,206.461657231134,0.3281797878999414,41.62267009779662,227.80230065777462,0.09836343453309383
0.103859931931397,206.40962833908,0.32975528388218545,41.612181073158524,227.84731828836183,0.09881306655526578
0.104375964654095,206.368818317699,0.3313936877767516,41.603953772848115,227.9087628041345,0.0992804375756256
0.104877333772207,206.287441335414,0.3329855347267572,41.58754817321947,227.9223181733628,0.09973431864673363
0.105387275936385,206.239934068953,0.33460460109802237,41.57797070830093,227.9749989097796,0.10019574952789236
0.105882713247089,206.145745369521,0.33617761455950756,41.558982266495434,227.9730162135894,0.10064385158817227
0.106374939137685,206.045852173742,0.33774043176214985,41.53884379822639,227.9639671582962,0.10108885029633634
0.106875845500271,205.938663177974,0.3393308094633604,41.517234496679556,227.9485319263155,0.10154149341713872
0.107369901339497,205.869335206929,0.34089943675290296,41.503257977716885,227.97350541692484,0.10198774546312787
0.107875795604727,205.781784289223,0.3425056510450082,41.48560771270736,227.98065799038324,0.10244448421199195
0.10837790830704,205.739436400863,0.344099858874852,41.477070378413984,228.03704617425782,0.10289760265237428
0.108858078160403,205.651479027025,0.3456243981592795,41.45933817184824,228.03830380475137,0.10333072737504714
0.109366659326444,205.576285060377,0.34723914336145967,41.444179068172,228.05947659417117,0.10378927529975263
0.109866564493631,205.536461230689,0.3488263422672784,41.43615058410691,228.1180461042832,0.10423979593028097
0.110378743200733,205.484598096753,0.35045250966232727,41.4256949763054,228.16572978178033,0.10470116721606858
0.110940277824553,205.471210485056,0.35223538209295574,41.422996033787285,228.2662436612153,0.10520675387918754
0.111462807693205,205.372276529606,0.3538944144259259,41.40305094836857,228.2636470939412,0.10567699249763234
0.111993135004032,205.308786156394,0.35557820363780157,41.390251289129026,228.30196076192098,0.10615402225180894
0.112506551242013,205.207529465905,0.3572083001933913,41.369837940326455,228.2947208950077,0.10661562379778511
0.113005595718933,205.15265915765,0.35879276640761226,41.358776086182246,228.33605761908348,0.10706409988088902
0.113536779176013,205.045396861245,0.36047927388384127,41.337152007227,228.3255908057381,0.10754123741318711
0.114058002828809,204.990418956462,0.36213415898146856,41.32606846162275,228.37121674167688,0.10800920732092689
0.114603154774761,204.888331482558,0.3638650164098662,41.30548762688369,228.3691806469961,0.10849842655909148
0.115129634890641,204.826674187772,0.36553659077778516,41.29305751625484,228.40829440287447,0.10897066262980291
0.11564608500699,204.75830481421,0.36717631989719324,41.27927425054473,228.4378011386413,0.1094336855334228
0.116162377986536,204.681432261359,0.3688155501072518,41.26377674388998,228.45771416252853,0.10989635336295803
0.116679417123611,204.594833271597,0.37045714936746493,41.246318387553956,228.4668391642293,0.11035947542332847
0.117209084470409,204.482230201718,0.37213884319354856,41.22361760866635,228.4494051941288,0.11083368651877562
0.117747632270286,204.426698243115,0.37384873245815803,41.21242236581198,228.49745793407402,0.11131561782980862
0.118286940829275,204.313790865503,0.37556103713294814,41.1896602384854,228.48144415621562,0.11179799728488042
0.118822170821507,204.292241137031,0.37726039235828474,41.18531581322545,228.56668871092378,0.11227649875774715
0.119349478569943,204.197164585437,0.378934594459569,41.166148380424104,228.56798970416972,0.11274769385874457
0.11987818730895,204.122103398852,0.38061324470591623,41.151016045208564,228.59189114399646,0.1132199180607661
0.120407801596396,204.052072812028,0.3822947700685573,41.13689787890485,228.62153431051203,0.11369272760377541
0.120953772197363,203.93818179804,0.3840282267266275,41.11393745048486,228.60527418158455,0.11417990523557653
0.121502315155074,203.864149070343,0.3857698506173599,41.09901245258115,228.6341151595088,0.11466913931400148
0.122053593591913,203.735692957747,0.3875201596543238,41.0731157002818,228.6023664261786,0.11516057208443914
0.122612231907882,203.739252948405,0.3892938363075253,41.073833394398456,228.72017747965347,0.11565831951851728
0.123163383761626,203.639617164664,0.3910437434431625,41.05374682039626,228.7205614825861,0.11614915383069312
0.123728368000724,203.589255576848,0.39283756840229866,41.04359392429256,228.77902191185368,0.11665205678590886
0.124279059724096,203.484400469517,0.3945860146240048,41.02245513465463,228.77325042838996,0.11714199443255172
0.124866727251782,203.381863806222,0.3964518590244078,41.00178374333436,228.77749152207258,0.11766456397380817
0.125438564565077,203.295947359339,0.39826744249411944,40.98446298764275,228.79709917799195,0.11817279485935354
0.126022571999496,203.200687033838,0.40012166609839983,40.96525850602174,228.8085602459069,0.11869157569730139
0.126583860151798,203.120977998638,0.40190375598195865,40.94918916452542,228.832815471514,0.11918992121909948
0.127139763901573,203.001088707191,0.4036687503874942,40.92501948336971,228.81059919718555,0.11968324147817298
0.127686698528464,202.850933195254,0.40540526782787323,40.89474813216321,228.75229914837396,0.12016836496481861
0.128254034901159,202.717171392563,0.4072065608111798,40.8677817527407,228.716466567409,0.12067133596600525
0.128800723682418,202.571365207132,0.4089422976916771,40.83838722575781,228.662703643146,0.12115576266400266
0.129362350060992,202.472111001343,0.4107254614436496,40.81837757787075,228.66437910228674,0.12165318147018567
0.129930922781597,202.384246551049,0.4125306798315705,40.80066410469148,228.68021846188503,0.12215650057394482
0.130476335024395,202.294177954928,0.4142623637024541,40.78250627571348,228.68878089125974,0.12263907932297259
0.131046577384459,202.164340203263,0.4160728831956573,40.75633098497782,228.657285056088,0.12314337876563605
0.131633602690809,202.068401497318,0.41793668854331856,40.73698974185931,228.66739317638283,0.12366225485310946
0.132221907747729,201.964810275544,0.4198045570990395,40.71610575154967,228.66898278808455,0.12418199214857767
0.132821907242473,201.900478447658,0.4217095554948518,40.703136455047854,228.71728506824374,0.12471178279086649
0.133395758316586,201.727005972435,0.4235315326551606,40.6681644040429,228.63653290706245,0.1252182223046867
0.133956398052428,201.5852460754,0.4253115638164589,40.63958560880064,228.58887954017294,0.12571275487713524
0.134523297171538,201.395650738474,0.4271114685196331,40.601363188876356,228.488057711821,0.1262125602155781
0.135073221193807,201.234314958831,0.4288574772903372,40.568837895700334,228.41568209504942,0.12669716091758046
0.135663359243766,201.174516070645,0.430731165598957,40.55678243984204,228.4665267150277,0.12721693768810444
0.136253425510543,201.037207825299,0.43260462599597405,40.52910109758028,228.42921604657093,0.1277363812557601
0.136838048100803,200.947896213748,0.4344608027200495,40.5110958766916,228.44521410160002,0.128250766717091
0.137449334261409,200.794559605218,0.4364016362799736,40.48018321641195,228.39363814626802,0.1287883295423234
0.138032885650017,200.67023748143,0.438254411938804,40.45511987625629,228.36932942506598,0.12930123304584865
0.138630264242714,200.488138898488,0.4401510889706169,40.41840880193518,228.28186257151532,0.1298260174053046
0.139219142001022,200.281342822101,0.44202077585324484,40.37671871293556,228.16433952860646,0.13034306455496517
0.13979400583693,200.08680439297,0.4438459685322527,40.33749976562276,228.05774029417353,0.13084754944452845
0.140381436139085,199.916576929411,0.4457110597415948,40.30318190896926,227.9811531067716,0.13136279954707483
0.140966619489951,199.759371120782,0.4475690168805944,40.27148921794965,227.9187743791172,0.13187581496553016
0.141569242144815,199.605630450725,0.44948234380978763,40.24049509886616,227.8636482814721,0.13240384405720362
0.142176532418347,199.416535457746,0.45141049042825165,40.20237354828159,227.76888697600867,0.13293568108968826
0.142778315123432,199.243980486006,0.4533211505168966,40.16758646597881,227.69170031828392,0.13346241597869155
0.143355973506562,198.990528481607,0.45515521588333435,40.11649054189197,227.51700941067298,0.13396777421446684
0.143945570215083,198.725667130947,0.4570271854328885,40.06309449359892,227.3313466024839,0.13448331334239508
0.144543832252205,198.466998358273,0.45892666740075083,40.01094686902784,227.15417887656986,0.13500615784419248
0.145157522798905,198.257957797406,0.4608751348865234,39.96880429195705,227.0365918264473,0.13554220204056003
0.145771777714255,198.041030901158,0.46282539424275965,39.925071829673456,226.90982403598352,0.13607845161398183
0.146381267362629,197.825228231941,0.46476052387634703,39.88156601155931,226.78313585683387,0.1366102569958672
0.146983165348897,197.522116773368,0.4666715499827479,39.82045874151099,226.55454272313207,0.137135160924351
0.147587017527398,197.243655157199,0.4685887806494886,39.76432087969132,226.35425794805255,0.13766149234532696
0.148195079913327,196.930785713995,0.4705193787248132,39.70124639994139,226.11495924027474,0.13819121369895687
0.148810794890557,196.671968540076,0.4724742737775185,39.649068857679325,225.93888051121533,0.13872731593424553
0.149428189146938,196.333878920544,0.47443450054152814,39.58090999038168,225.67169491583508,0.139264591888157
0.150065970348581,195.968432252805,0.4764594558567446,39.50723594216549,225.37662519651232,0.13981930625032532
0.150684274358501,195.63002464897,0.4784225710882407,39.43901296923235,225.10839295593573,0.140356786601552
0.151311950109435,195.203144477582,0.4804154415974561,39.35295392668053,224.73971293597867,0.1409021183095865
0.151921637430355,194.835897741615,0.4823511988413771,39.27891698470959,224.43568635673435,0.14143153689609794
0.152558347655212,194.450013936903,0.4843727538052981,39.20112280967964,224.11498676464984,0.14198412163988341
0.153191222451518,194.039845635848,0.48638213128356966,39.11843288018696,223.7650467931074,0.1425330752820344
0.15380936892204,193.583654546862,0.488344746327477,39.02646475664738,223.358634286337,0.14306896286492138
0.154436754516259,193.115138681314,0.49033669558912224,38.932011958152906,222.9392139472134,0.14361256660223362
0.155054826105153,192.635948613345,0.49229907288386077,38.83540724045035,222.5050821271884,0.14414781133647372
0.155700055416562,192.136881054994,0.49434767594758433,38.73479522068679,222.05260408282194,0.14470626894990374
0.156363253040064,191.626382148941,0.49645332840220313,38.63187864122651,221.58970663004786,0.14527995362303994
0.157038596563155,191.058611932963,0.4985975440880171,38.51741616568534,221.06218821221995,0.1458638068281294
0.157713385890481,190.492099350854,0.5007400002022772,38.40320722913217,220.5352533248631,0.1464468406490798
0.158357317533455,189.878349530195,0.5027844831687196,38.27947526528732,219.94697561947643,0.1470028959185616
0.159002447519843,189.178100971777,0.5048327708755015,38.138305155910246,219.25788204344556,0.1475596761067594
0.159632998991514,188.48227187448,0.5068347717980569,37.99802600989517,218.57026219053714,0.14810357487977618
0.160259793883369,187.844713023244,0.5088248455796965,37.869494145485994,217.94866801442967,0.1486439402872052
0.160906592984373,186.991343081495,0.5108784327253842,37.69745476522939,217.07948301431034,0.1492012455466679
0.161571883363132,186.448599818085,0.512990729677944,37.58803772332594,216.57345124111188,0.14977415970172403
0.1622414029139,185.644098532184,0.5151164542516324,37.4258502640883,215.76325752073177,0.15035038462757938
0.162916179513872,184.836906465223,0.5172588699565436,37.263120343388955,214.94982909970005,0.15093079829417555
0.163565687527863,184.077696503713,0.5193210579009649,37.11006361514854,214.18649149088816,0.15148915900187493
0.164260153620126,183.157352086191,0.5215259877439,36.924522180576105,213.24280687652424,0.15208582401056261
0.16494152515029,182.377262821421,0.5236893423521708,36.76725618479848,212.45884670392144,0.15267089275390994
0.165633974786444,181.486484210362,0.5258878699469597,36.58767521680898,211.54681196014144,0.1532651233690938
0.166333198418756,180.606267271343,0.5281079049795503,36.41022348190275,210.64708536105817,0.1538648090433185
0.167007052641885,179.654062645803,0.5302473921379849,36.218259029393884,209.65755814341912,0.1544423966810891
0.16770770662193,178.554972398172,0.5324719685246277,35.99668243547148,208.5000173250114,0.15504260190812924
0.168414394899244,177.525574358737,0.5347157038050997,35.78915579072138,207.42343654350444,0.15564761163635374
0.169107631554388,176.408306758373,0.5369167301851818,35.563914642487994,206.2402977008014,0.15624074972670993
0.16979892899522,175.286981394793,0.5391115995598235,35.33785544919027,205.0505231024339,0.15683187848116492
0.170523708723227,174.199526373812,0.5414127751962458,35.1186245169605,203.90467566890402,0.15745126295362774
0.171218249279416,173.043172466135,0.5436179414621458,34.88550356917282,202.6713215055427,0.15804444579700724
0.17191566498597,171.806415168065,0.5458322363304547,34.6361732978819,201.34262928053855,0.15863973036260798
0.172574732777534,170.5388256548,0.5479247765686703,34.38062725200768,199.96951792037157,0.15920195728369368
0.173217089626453,169.188870428312,0.5499642595639882,34.1084762783477,198.49527416109126,0.15974962469291545
0.173915578912996,167.816488147811,0.5521819630487622,33.831804010598695,197.00238983518346,0.16034480988762137
0.174617566886177,166.42935365199,0.5544107748636119,33.55215769624118,195.49084244513955,0.16094261962715406
0.175380919358473,164.929810210035,0.5568344189631518,33.24984973834306,193.85535195428938,0.1615922817470343
0.176108160592074,163.41711728301,0.5591434098798349,32.944890844254815,192.1962052169801,0.16221081853973116
0.176821526170495,161.87640787525,0.5614083455913217,32.6342838276504,190.49964136674927,0.1628171822609182
0.177552663563922,160.226253560634,0.5637297068154523,32.301612717823815,188.67485165319292,0.16343827080335796
0.178240135489595,158.580921772254,0.5659124301794641,31.9699138292864,186.8464067550054,0.1640219146157207
0.178941883594555,156.80612889238,0.5681404804127121,31.612115584703812,184.86531295555307,0.16461732737554183
0.17963566497108,154.972642564145,0.570343236283179,31.242484740931634,182.81125626348066,0.16520563230276947
0.180360368532307,153.029721325327,0.5726441700900747,30.850791819185922,180.6302182599592,0.16581978891466032
0.181113346243816,150.909400715661,0.5750348743241158,30.423335184277256,178.24110725892328,0.16645750741418558
0.181922387287691,148.510755094831,0.5776035796384189,29.939768227117934,175.5281861995803,0.1671422546348954
0.182321898772621,147.304134618563,0.5788720286030716,29.696513539102302,174.1609041392772,0.16748021589472642
0.182521702276899,146.658811940117,0.5795064047291544,29.56641648712759,173.42722794933476,0.1676491940924092