File: example/data/02 processed data/test_ID_095.csv
Strain,Stress_MPa,Displacement(mm),Force(kN),True Stress (MPa),True Strain
0.0015755543870217157,78.5656891759014,0.005002385178793947,31.677685875723448,78.68947369215188,0.0015743145033737277
0.0016645950519078156,83.2352277374893,0.005285089289807314,33.56044382375568,83.37378068572555,0.0016632111491100938
0.0017535640202615155,87.9621507700463,0.005567565764330312,35.46633919048267,88.11639803278148,0.001752028321909737
0.0018425763099348157,92.6600868556074,0.005850179784043039,37.36054702018091,92.83082013652404,0.0018408808485643115
0.0019289810271920158,97.1930043566598,0.00612451476133465,39.18821935660523,97.3804878180396,0.0019271229323931424
0.0020181595756872156,101.717628777423,0.0064076566528069095,41.01254792305696,101.92291118395636,0.0020161258274766385
0.0021047786269464156,106.125631652254,0.00668267214055487,42.78985468218882,106.34900261352685,0.002102566683635684
0.0021931608374823157,110.52747980109,0.006963285659006352,44.56467985579949,110.76988434125536,0.0021907593708135973
0.002281877620074516,114.799444458998,0.007244961443736588,46.287136005868,115.06140274210598,0.00227927809112498
0.002371483592131516,118.914529965841,0.007529460405017563,47.94633848222709,119.19653382252103,0.002368676062714917
0.0024584015764137156,123.291492070694,0.007805425005113546,49.711129602903824,123.594592069159,0.0024553846507897855
0.0025464429789467157,127.477050095447,0.008084956458155821,51.39874659848423,127.8016631346394,0.002543206286561599
0.0026342466014806156,131.61398589783,0.008363732959700955,53.06675911400505,131.96068959288866,0.002630783055125325
0.0027203166366228156,136.006598864537,0.008637005321277438,54.83786066218132,136.3765798781187,0.002716623271885828
0.0028075998485628155,140.380333763192,0.008914129519186938,56.60135057331902,140.77446556700673,0.002803665901686911
0.0028905595514577154,144.930987130065,0.009177526575878246,58.436174010842215,145.349918779216,0.0028863899173154368
0.0029731707902409155,149.197139502792,0.009439817259014906,60.15628664752573,149.6407280799492,0.0029687596591681563
0.0030563207529158156,153.343287125017,0.009703818390507714,61.828013368806864,153.81195339577752,0.0030516596993449673
0.0031379381476787154,157.747456400216,0.009962953618879921,63.6037744205671,158.24245816135354,0.0031330250949899974
0.0032177282657086157,161.884096458845,0.010216287243624854,65.27166769220631,162.40499549178932,0.0032125624565930186
0.0032965703022981158,165.764210783502,0.010466610709796516,66.836129787908,166.31066415795476,0.0032911485266611056
0.0033735615098397158,169.676052045332,0.010711057793741097,68.41338418467787,170.2484646436537,0.003367883816990104
0.0034538167475699154,173.507613077898,0.01096586817353448,69.95826959300847,174.1068765777773,0.0034478660203848114
0.0035305789315331158,177.555993596253,0.011209588107617642,71.59057661800921,178.18286904641135,0.0035243610685435677
0.003608100727125416,181.361630702894,0.011455719808623194,73.12500949940686,182.01600173450575,0.003601607146670968
0.0036843138065937157,185.132885702446,0.011697696335935046,74.64557951522623,185.81497334929404,0.003677543347050207
0.0037618960442345156,189.237395558318,0.011944019940444587,76.30051788911383,189.9492869680901,0.0037548378093364594
0.003841689878668816,193.387891285278,0.01219736536477349,77.97399776622409,194.13082758988574,0.003834329433117043
0.003920011907947116,197.344621579808,0.012446037807732093,79.56935142097859,198.1182148463702,0.003912348681365888
0.003997855228074016,201.340924922803,0.012693190349135,81.18066092887418,202.14585679213087,0.003989885040237732
0.004079715694294916,205.318314725626,0.012953097329386359,82.7843444973724,206.15595507653833,0.004071416219562329
0.004159085666150816,209.320917354202,0.01320509699002884,84.39819387721425,210.19150098119542,0.004150460576083613
0.004239912591975616,213.153568273934,0.01346172247952258,85.94351872805021,214.05732077208322,0.004230949488833043
0.004318724028109416,216.803186234405,0.013711948789247396,87.41504468971209,217.73949936416622,0.004309425102875289
0.0043999800555459155,220.410439333674,0.01396993667635828,88.86948913933735,221.38024087077625,0.004390328444209733
0.0044821662795509155,224.192829419324,0.014230877937574157,90.39454882187144,225.1976989594644,0.004472151287028871
0.004564315429236116,227.601528876447,0.014491701487824667,91.76893644298343,228.64037404641547,0.00455393052954903
0.004644116226153616,231.400262846119,0.01474506901803773,93.30058597955518,232.4749125615389,0.004633365590344409
0.004723638915284215,235.137875237733,0.014997553556027382,94.80759129585395,236.2485816556632,0.004712517541467965
0.004802139243260716,238.84011139364,0.015246792097352772,96.30033291391565,239.98705486542815,0.004790645753476543
0.004883444856538316,242.298732302475,0.015504937419509151,97.69484886435792,243.48198480048327,0.004871559518261645
0.004962237352470415,245.741032033204,0.01575510359409357,99.08278411578786,246.9604573613938,0.004949966031428365
0.0050402640236009155,248.817521362675,0.016002838274932905,100.32322461343055,250.07162736404084,0.005027604413585814
0.005119128897198816,252.148330956721,0.016253234248606238,101.66620704174991,253.439110764102,0.005106070702295133
0.0052020669324757155,254.9613521171,0.016516562510610396,102.80041717361472,256.2876781360077,0.005188582925213572
0.005285538629930816,257.71730797603,0.01678158515003034,103.91161857593531,259.0794827629391,0.005271619196884356
0.005369772252837516,260.639305097977,0.017049026902759112,105.08976781550433,262.03887880649097,0.005355406430329998
0.005456905395023316,263.714538595541,0.017325674629199025,106.32970196172214,265.1536038839491,0.0054420704309711175
0.005548479447353116,266.650363804785,0.017616422245346142,107.51342668608932,268.12986786798507,0.005533143337173412
0.005654040390221716,269.649994933261,0.017951578238953946,108.72287795709083,271.1746068958367,0.005638116299293687
0.0057725209428131155,272.365690967974,0.01832775399343164,109.8178465982871,273.93792762319043,0.005755923784793002
0.005908528707903816,274.872795086284,0.018759578647594616,110.8287109787897,276.4968888870731,0.005891141805881932
0.006073785374209315,277.069705709249,0.019284268563114576,111.7145053419692,278.7525676354223,0.0060554142903071345
0.006271893592271016,278.78582820378,0.019913262155460475,112.4064459317641,280.53434325330727,0.006252307121168593
0.0064971831085024155,280.156752189107,0.020628556369495166,112.95920248264794,281.97698190716295,0.0064761673938447525
0.006754965163286416,281.256216806023,0.02144701439343437,113.40250661618848,283.1560927525054,0.006732252610407467
0.007034875136143016,282.020204485666,0.022335728557254072,113.71054644862053,284.0041814100922,0.007010245843919628
0.007336304462435815,282.6011206756,0.023292766668233714,113.94477185640191,284.67436853830174,0.0073095246775281945
0.007653613108728415,283.076454712473,0.02430022162021272,114.13642654006912,285.2430123770327,0.0076244728032220516
0.007983650445527415,283.46832536367,0.02534809016454954,114.29442878663174,285.7314373857526,0.0079519497215309
0.008318478780751315,283.802716535422,0.026411170128885424,114.42925530708214,286.1635234108415,0.008284070918496598
0.008664721683050516,284.090263227093,0.027510491343685387,114.5451941331639,286.55182629082026,0.008627398424269163
0.009012066258413715,284.323079525129,0.028613310370463545,114.63906566453201,286.8854179566057,0.008971699930705082
0.009363879234620915,284.5274229532,0.029730316569921405,114.72145693473026,287.1917033806717,0.009320309891654896
0.009718849758320816,284.738910045629,0.03085734798266859,114.80672853039762,287.50624473271046,0.009671925526081182
0.010077728136635216,284.934770386728,0.031996786833816813,114.88569941992874,287.8062655393601,0.010027286443134793
0.010436814908325015,285.103030261502,0.03313688733393192,114.95354180143761,288.07859781814386,0.010382727364563638
0.010798921556508816,285.276289155767,0.03428657594191549,115.02339978760527,288.35696542429207,0.010741029610585762
0.011158632770080616,285.426336576409,0.03542865904500595,115.08389890760813,288.61130424917457,0.011096834525082576
0.011519786615697716,285.570225083178,0.036575322504840246,115.14191475353736,288.859933139933,0.011453939090982707
0.011878283122655316,285.700164951236,0.03771354891443063,115.19430650833836,289.0937923987161,0.011808290037611012
0.012234705424928516,285.820375756147,0.038845189724148035,115.24277550487847,289.31730385796584,0.012160466332090298
0.012588936603331815,285.927076929453,0.03996987371557851,115.28579741795545,289.52659477409384,0.012510354761546057
0.012939601319213215,286.037751798277,0.04108323418850195,115.33042152506529,289.7389662687907,0.012856599914669658
0.013286411027933615,286.144018677534,0.04218435501368922,115.37326833078173,289.94584572286846,0.013198920771270876
0.013634062429925216,286.249105382839,0.043288148215012555,115.41563929036069,290.15184355613883,0.01354195485667587
0.013982284530661115,286.34695138463,0.044393753384849036,115.45509079828282,290.35073593337734,0.013885434139313903
0.014332281975001415,286.451451309354,0.04550499527062949,115.49722516793155,290.556954281668,0.014230545744381078
0.014684965684569416,286.552172188994,0.0466247660485079,115.53783582660239,290.7601810044282,0.014578185680440484
0.015037635187713215,286.652395044042,0.047744491720989456,115.57824568175775,290.9629691863986,0.014925690809014612
0.015391255510940815,286.747023770422,0.048867236247237086,115.61639998423416,291.16042048027435,0.015274011627756648
0.015745832442081317,286.835676390292,0.049993018003608176,115.65214472056574,291.3521428891446,0.015623152940615887
0.016101524857191817,286.931266065183,0.05112234142158401,115.69068647748179,291.5512969780371,0.01597327020455909
0.016453876249614516,287.032822037761,0.052241057092526084,115.73163384562523,291.7556245711479,0.016319977994920253
0.016803533244952217,287.124513899269,0.05335121805272329,115.76860400418528,291.9492202140161,0.01666391575425354
0.017149125682652318,287.200737914257,0.054448474042421105,115.79933752702843,292.1259794648991,0.017003739239828675
0.017490594299249918,287.278907532069,0.05553263690011849,115.83085551693023,292.3035863544441,0.01733939435994639
0.017832502320169218,287.369421540223,0.05661819486653726,115.86735076501793,292.49393741658474,0.017675368559525374
0.018172538799423116,287.474615662593,0.05769781068816839,115.9097650351575,292.69875926957076,0.018009391782010515
0.018505810229173417,287.595077570039,0.058755947477625595,115.95833527623972,292.9172574983946,0.018336661360816537
0.018839375139062618,287.725392907022,0.059815016066523806,116.01087842011128,293.14595952103156,0.018664111922719457
0.019169881198284416,287.868576579621,0.06086437280455302,116.06861007690318,293.38698299337153,0.018988453984554007
0.019497979994133618,288.025846237288,0.06190608648137423,116.13202120287453,293.6417684250161,0.019310329661242385
0.019828564252500517,288.19522683861,0.06295569150168914,116.20031546132756,293.9097244112433,0.019634538907863604
0.020153607485862316,288.370492726362,0.06398770376761286,116.27098266726917,294.18219844727383,0.0199532115321794
0.020474266224003418,288.53517100114,0.06500579526121085,116.33738094765964,294.4427169072057,0.020267486118850913
0.02079423438561122,288.684765121982,0.06602169417431561,116.39769729718316,294.6877437914836,0.020580985459219672
0.021111156343452016,288.82846993104,0.06702792139046014,116.45563907619533,294.9259729161942,0.020891403328553618
0.021426118761569416,288.961385901338,0.0680279270679829,116.5092307954195,295.1527068731678,0.02119980643527054
0.02174023669626292,289.09066926292,0.06902525151063477,116.56135784680936,295.37556883937697,0.021507287944379432
0.022050741824455416,289.215383792432,0.07001110529264594,116.61164274510858,295.5927975520997,0.021811140083707437
0.022359432891884218,289.320506853856,0.07099119943173239,116.65402836347474,295.7895493111007,0.02211312554004334
0.02267039003642622,289.426631511965,0.07197848836565324,116.6968178256243,295.9880461352703,0.02241723567423528
0.022979329040312118,289.529489474014,0.07295936970299097,116.73829015592244,296.18268287951093,0.022719280548637456
0.02328602633176772,289.633143139291,0.0739331336033625,116.78008331376213,296.3775481369852,0.02301904352214138
0.02359270896635472,289.748088119788,0.07490685096817623,116.82642912989854,296.5840304363559,0.023318702345688856
0.023901570340888616,289.853457656303,0.07588748583232136,116.86891412702138,296.78141046302494,0.023620399283256016
0.024209734142072416,289.953866453917,0.07686590590107992,116.90939895421933,296.9735724742323,0.023921324142988674
0.024518983038625316,290.053875664907,0.07784777114763537,116.94972266809052,297.1657017226224,0.024223217601413095
0.024825646481044118,290.147607748037,0.07882142757731507,116.98751544400852,297.3507096853104,0.024522497127453316
0.025134194021484316,290.241471436086,0.0798010660182127,117.02536128302987,297.5364568922417,0.024823525017535934
0.02544266631329402,290.322053807564,0.08078046554470851,117.0578520952098,297.70862094598004,0.025124388935493305
0.025752218042220016,290.390107599477,0.08176329228404855,117.08529138410914,297.86829696768245,0.025426214699234166
0.026059426256672517,290.46841012489,0.08273867836493523,117.11686296235564,298.03785023843244,0.02572566539940115
0.026368281143989817,290.540033723327,0.08371929263216767,117.14574159724543,298.20107501612796,0.026026630825403758
0.026673521026684518,290.611568956347,0.08468842925972334,117.17458460319911,298.3632027515019,0.02632398461977946
0.026981461735667418,290.685781962259,0.08566614101074405,117.20450728718282,298.5289092653762,0.026623879893207254
0.027287285918645116,290.753922437611,0.08663713279169824,117.23198152684476,298.68780785113364,0.0269216249526949
0.02759486769523632,290.820263602204,0.0876137049323753,117.25873028440867,298.84541029940056,0.027220991783388698
0.027900989776526018,290.883833161846,0.0885856425404701,117.2843615308563,298.99978001705136,0.027518848947576464
0.02820589441958512,290.940330437428,0.08955371478218274,117.30714123237097,299.1465626801453,0.027815433378704624
0.028510024840085916,291.000800097002,0.09051932886727278,117.33152259911121,299.29724013625247,0.028111177112556902
0.02881292241475142,291.066529632541,0.09148102866683575,117.35802474784055,299.4530069683744,0.028405635089860125
0.029112242947974418,291.131177981449,0.09243137135981877,117.38409096212024,299.60665956457495,0.028696530541620496
0.029411377969652017,291.212201020056,0.09338112505364515,117.41675945128658,299.77715313363115,0.028987161186558044
0.029707966653652017,291.30054602698,0.09432279412534515,117.45238015807834,299.9544929345401,0.02927523451929162
0.030004872888191318,291.388255602439,0.09526547142000742,117.48774465890341,300.13132317290206,0.0295635331897626
0.030300869785933316,291.486045494186,0.09620526157033828,117.5271735432558,300.31832620312196,0.02985086617500597
0.030592539364923316,291.600001132509,0.09713131248363152,117.57312045662763,300.520785645967,0.0301339177677204
0.030889789704152217,291.717327049068,0.09807508231068328,117.62042626618423,300.7284139346711,0.030422302816767336
0.031188360363187617,291.846206734517,0.09902304415312067,117.67239055535725,300.94841140078245,0.03071188511132002
0.03148584588493791,291.964637682351,0.09996756068467787,117.72014191352393,301.15739126826924,0.031000331559054545
0.031783867864821916,292.090258800246,0.10091378047080958,117.77079234825919,301.37401699055465,0.031289214762225306
0.03208223339155382,292.232131609599,0.10186109101818337,117.82799546499031,301.6075910604094,0.03157834740375552
0.032380047724813316,292.385533038106,0.10280665152628227,117.88984692096436,301.85299055192485,0.031866862566322984
0.03267846428968962,292.544028569086,0.10375412411976452,117.95375231905548,302.1039181598428,0.0321558776864441
0.032974206105183416,292.694735680323,0.10469310438395735,118.01451742630623,302.34611222054815,0.03244221993725244
0.033266000349646815,292.841725026688,0.10561955111012863,118.0737835307606,302.5833979538169,0.03272465974796908
0.03355751370700432,292.984717582861,0.10654510601973871,118.13143812940955,302.81655625909065,0.03300674804172809
0.03385372485086842,293.116232960938,0.10748557640150723,118.18446512985021,303.0393092609206,0.03329330075109377
0.03414767225095942,293.232557560554,0.10841885939679614,118.23136720841538,303.24576682944246,0.03357758237922297
0.03444177506123092,293.332203624933,0.10935263581940816,118.27154450157299,303.4350854003981,0.0338619334500797
0.03473474464330332,293.411262998886,0.11028281424248802,118.30342124115084,303.6028282946214,0.03414510850183596
0.035026986868808514,293.495773216751,0.11121068330846702,118.337495760994,303.7760458112649,0.03442750064678469
0.035320756255618216,293.574436368659,0.11214340111158783,118.3692127438433,303.9437074785169,0.03471128813104366
0.03561306454762882,293.652552858061,0.11307147993872149,118.40070931237018,304.1104201775711,0.034993584253706425
0.03589679030975572,293.730988344613,0.1139723092334744,118.43233450054797,304.27498804069694,0.03526751562143395
0.03618305676325872,293.810088492305,0.11488120522334642,118.46422768009738,304.4410356018401,0.035543823945872785
0.03646825280088572,293.879780141159,0.11578670264281216,118.49232735291531,304.59706225641554,0.03581902319247159
0.03675463933558172,293.953363741122,0.11669597989047195,118.52199626042041,304.75751360690805,0.0360952950179505
0.03703962258229552,294.018305845308,0.11760080169878827,118.54818091682819,304.9086329261042,0.03637013737212323
0.037324492269247014,294.080541260951,0.11850526295485926,118.57327423641546,305.05694814978136,0.0366447947350257
0.03761086261811842,294.145349540747,0.11941448881252598,118.5994049348292,305.2084098720825,0.03692082294960606
0.037900183593113215,294.205049030304,0.12033308290813445,118.62347576901857,305.3554744025734,0.037199617878109985
0.03818250298752922,294.26179645066,0.12122944698540526,118.6463563289061,305.49744837275296,0.037471591049488
0.03846724652871092,294.319430843003,0.12213350772865716,118.66959451589881,305.6410889474307,0.03774582462501775
0.038751071499067515,294.36936408533,0.12303465200953935,118.68972759920506,305.77649236013565,0.038019098714370377
0.03903764166529722,294.416357628495,0.12394451228731866,118.7086753958092,305.9096778979982,0.03829494020511601
0.039324293444823015,294.468504755023,0.12485463168731306,118.72970111722528,306.0482706462678,0.0385707841536611
0.039611911861847114,294.520671404776,0.1257678201613646,118.7507347104057,306.18719828195407,0.03884748183983834
0.03989713865704872,294.579743754892,0.12667341523612968,118.77455268197245,306.3326326370388,0.03912180312439259
0.04018832403408302,294.637670933369,0.12759792880821358,118.7979089203344,306.47866512548677,0.03940177756213473
0.04047948101060052,294.696479212702,0.12852235220865663,118.82162041856145,306.62563974688345,0.03968164634052609
0.040770340169618016,294.758107237514,0.12944583003853719,118.84646883816566,306.7754955373402,0.03996115066331422
0.04105800844492452,294.821450849226,0.13035917681263534,118.87200898240792,306.9262324679384,0.04023751185066083
0.041346152822336016,294.878969969464,0.13127403521091685,118.89520069168788,307.0710809259145,0.04051425388240462
0.04163125615058032,294.930690915881,0.1321792382780925,118.91605457728322,307.2090260560676,0.04078799984699984
0.041914521216604314,294.977971781897,0.1330786048627187,118.93511822246089,307.34183223858025,0.041059906584875516
0.042192874369686016,295.024010389222,0.13396237612375309,118.95368098893431,307.47192139561537,0.041327026365100154
0.042468393180040614,295.072946992215,0.13483714834662894,118.9734122272611,307.6042209218737,0.041591355938683836
0.04274442395677052,295.120131752741,0.13571354606274638,118.99243712270516,307.7348717825581,0.041856106640457386
0.04302303458779832,295.168625656444,0.13659813481625965,119.01198986467824,307.86767564729405,0.04212326071033555
0.043300273659854116,295.219960221509,0.1374783688700368,119.03268796131242,308.0030652889516,0.04238902879392248
0.04358189354181652,295.273716802097,0.13837251199526743,119.05436261460551,308.1423044934625,0.04265892413166409
0.04386401836169142,295.337170418149,0.13926825829837025,119.0799471125977,308.2918454842607,0.04292923036569274
0.044153012040739514,295.404914247006,0.14018581322934795,119.10726142439282,308.4479309826477,0.04320604197851551
0.044440796058574816,295.4710723443,0.14109952748597504,119.13393636922177,308.6020420115615,0.04348161879823078
0.044728472101651616,295.54725174258,0.14201289892274388,119.16465190260826,308.7666287468678,0.04375701634430738
0.045013489989353214,295.653612455479,0.14291783071619646,119.20753654204913,308.96201338005983,0.044029794414173706
0.04530045185279682,295.754478912986,0.14382893463262988,119.24820589771595,309.1522904452327,0.04430435782735498
0.04558267430401672,295.871933324315,0.14472499091525307,119.29556351636381,309.358567296737,0.044574313091141016
0.04586643264802032,296.011078264957,0.1456259236574645,119.35166675643066,309.58805044926453,0.04484566403609256
0.04614565945258932,296.157421939049,0.14651246876197108,119.41067252582457,309.8238014762052,0.0451126097265898
0.04642735134940882,296.326591757708,0.147406840534373,119.47888179670787,310.084250547416,0.045381839901180616
0.04670779684675832,296.511420826191,0.14829725498845767,119.55340487712022,310.36081603288443,0.04564980683037708
0.04699104087641582,296.683971583542,0.14919655478262023,119.62297734248413,310.6254602196016,0.04592037490471711
0.047274111794143515,296.860372977444,0.15009530494640566,119.69410238450543,310.8941834368308,0.04619070449415865
0.04755754885693652,297.020527405953,0.15099521762077345,119.75867665008023,311.1460956495746,0.04646131054794954
0.047840260428678914,297.15445301573,0.15189282686105554,119.81267545594234,311.37039943554413,0.04673115102616819
0.04812612395206012,297.282445907348,0.15280044354779088,119.86428218984273,311.5894977478566,0.04700392594019724
0.04841359229448432,297.391642920618,0.1537131555349877,119.90831042559317,311.78944067276365,0.047278157181321084
0.04870046516855492,297.478190879759,0.15462397691016186,119.94320656271883,311.9655171531034,0.04755174542497342
0.04898548834265472,297.545494791486,0.1555289254879287,119.97034349992717,312.12090615800383,0.04782349551738052
0.04927105191527592,297.608431761823,0.15643558983100103,119.99571968636702,312.27191225358365,0.048095686804675714
0.049557581571134414,297.664643045338,0.15734532148835176,120.01838407588028,312.4161828738999,0.048368724491571195
0.04984503634489012,297.713145599066,0.1582579903950261,120.03794030554342,312.552668161803,0.048642568844339894
0.05013025644877152,297.757919857038,0.15916356422484956,120.05599328635773,312.6846007391241,0.048914210236135354
0.050413809906478015,297.798464061134,0.16006384645306768,120.07234070944922,312.8116192187531,0.04918419120341943
0.05070190860877142,297.837667673353,0.16097855983284926,120.08814760589594,312.938605879977,0.04945842522257438
0.05098993355575892,297.877017386883,0.16189303903953456,120.10401341039122,313.0657467112278,0.04973251388106576
0.051276964510492615,297.923651119896,0.16280436232081405,120.12281613154208,313.2002716052073,0.05000558192659452
0.05156332484859632,297.978187785111,0.1637135563942933,120.14480531495676,313.3429338796707,0.050277937693528195
0.05185054996990342,298.040897379374,0.16462549615444333,120.17008982336358,313.49448182201803,0.05055104145739597
0.05213797763544592,298.106309059306,0.16553807899254078,120.19646381271218,313.64896913402544,0.050824263163274624
0.052426519977650715,298.171105930539,0.166454200929041,120.22258991119332,313.80317937236464,0.051098469389161225
0.05271260619281462,298.244780582987,0.1673625246621864,120.25229553106035,313.9660402509204,0.051370267308233235
0.05300105966225032,298.316847007231,0.16827836442764477,120.28135271331554,314.1279560137156,0.05164423947825549
0.053286045636219914,298.388358787636,0.16918319489499822,120.31018626317483,314.2882944913107,0.051914844539637385
0.05357272617456292,298.45557648488,0.17009340560423727,120.33728843870362,314.4446553591758,0.05218698479312569
0.053860408232873816,298.521514386594,0.17100679613937436,120.3638746006747,314.60000501775164,0.05246000134145731
0.054149641691378314,298.592525135907,0.17192511237012614,120.39250613479771,314.7612033837402,0.052734415080926834
0.05443872129396242,298.668725199616,0.17284294010833068,120.42323000048519,314.9278686899809,0.053008607625540806
0.05472866554795132,298.740249002928,0.17376351311474542,120.45206839798058,315.08990417632094,0.05328354479517867
0.05502086358337252,298.815885114935,0.17469124187720775,120.48256487834179,315.2569931663885,0.05356054264089901
0.05531617830830122,298.893488369067,0.17562886612885636,120.5138545104078,315.4271338668804,0.053840417107388655
0.055611365465724316,298.978248430301,0.17656608535367468,120.54802976709736,315.60483707006057,0.054120092419047514
0.05590638206423622,299.065669733879,0.17750276305395,120.58327803670004,315.785349328318,0.05439952800586827
0.056199872714213416,299.152651472839,0.17843459586762758,120.61834907384869,315.96499240773204,0.05467744077773018
0.056492095571669315,299.241811667551,0.17936240344005006,120.65429846435659,316.14660869131376,0.05495407633436218
0.05678471388522352,299.330841275668,0.18029146658558468,120.69019520234933,316.32825745453005,0.05523100959186539
0.05707501445661622,299.42233121921,0.18121317089975647,120.72708394758547,316.5118651021801,0.05550567358146257
0.05736536588320772,299.512062561359,0.1821350366791845,120.76326362473996,316.69368161662555,0.05578031024761424
0.05765787202384612,299.602401065095,0.1830637436757114,120.79968810944631,316.8768379637433,0.05605690876176845
0.05795058470154952,299.689156807994,0.1839931064274197,120.83466802498317,317.0563186737316,0.05633362601409439
0.05824397788084012,299.769924097403,0.18492462977166738,120.8672333960729,317.2297169258733,0.056610909763290265
0.05853859084743692,299.842990638235,0.1858600259406122,120.89669382533636,317.3953767856785,0.05688926897963258
0.058835799481238016,299.915033404808,0.1868036633529307,120.9257414688186,317.56077417162214,0.0571700021717507
0.05913331855359662,299.984583932185,0.18774828640766925,120.953784241457,317.72366789501507,0.057450949681119176
0.05943197360236622,300.04959922757,0.18869651618751274,120.97999840855624,317.88213908826356,0.05773289053217882
0.059729147075630616,300.114544977851,0.18964004196512718,121.00618453506952,318.040130774369,0.05801335384599924
0.060027321461514516,300.183202035366,0.19058674564030859,121.03386706065956,318.20239560128965,0.0582946827555001
0.06032551342315202,300.25371967006,0.19153350511850764,121.06229977096818,318.3666794663675,0.05857594911711435
0.060623977606758014,300.325537875506,0.1924811289014567,121.091256871404,318.5324665584082,0.05885739305233161
0.06091985383365882,300.396172817084,0.19342053592186673,121.11973687984826,318.69626375729126,0.05913631845036887
0.06121550476136812,300.463575799972,0.19435922761734375,121.1469137625487,318.8566052549728,0.059414953767785904
0.06150896664928512,300.528819234508,0.19529096911148022,121.17321991535363,319.0140363539524,0.05969144927508243
0.06180485030793122,300.58370003655,0.1962303997276816,121.19534785473695,319.16123062231304,0.05997014916220997
0.062098448003308014,300.637710147612,0.19716257241050295,121.21712473151716,319.30684535904703,0.06024661909140157
0.062392325590839216,300.686516597404,0.1980956337509145,121.2368034920733,319.4470476417245,0.06052327606074057
0.06268509535663322,300.739586434236,0.19902517775731046,121.25820125028396,319.5914760873805,0.06079881403856701
0.06298144886135501,300.793307392616,0.19996610013480215,121.27986154070277,319.73770570000187,0.061077647524889665
0.06327503443837061,300.85439389461,0.2008982343418267,121.30449161830676,319.89096602922655,0.06135380007862652
0.06357232340363601,300.920953919957,0.20184212680654434,121.33132862052668,320.0511981214872,0.061633358426907134
0.06386918890003691,300.988124783276,0.2027846747576172,121.35841191261689,320.21199218172694,0.06191244059824844
0.06416971951583411,301.05141995227,0.2037388594627733,121.38393252475528,320.3698051304508,0.06219488902210639
0.06447265179857131,301.113909005803,0.2047006694604639,121.40912811113978,320.52752121284084,0.06247951389743975
0.06477754290915382,301.166615229322,0.20566869873656335,121.43037926046263,320.675448570144,0.06276589744543605
0.06507885188855601,301.216180075279,0.20662535474616534,121.45036380635248,320.8189832448347,0.06304883575258995
0.06538498488881421,301.264716680741,0.2075973270219851,121.46993376567478,320.96290562844416,0.06333622199879642
0.06569252529712032,301.307172021205,0.208573767818357,121.48705175894986,321.10080104141184,0.06362484632988823
0.06600178334380641,301.34961074759,0.20955566211658533,121.5041630534283,321.23922246689284,0.06391499867265352
0.06630909498087931,301.390759529304,0.2105313765642918,121.52075424221538,321.37570802929196,0.06420324148220297
0.06661718008040711,301.432980379826,0.21150954675529257,121.53777768914584,321.5135955159627,0.06449212638673309
0.0669251970709304,301.481099247779,0.21248750070020403,121.5571792167045,321.65778122809735,0.06478086402415877
0.06723618754574372,301.531304072757,0.2134748954577363,121.57742180213562,321.80511938430556,0.06507230447402934
0.06754738150986021,301.580620905389,0.21446293629380617,121.59730634905286,321.95160216166585,0.06536385062496625
0.06785715072986952,301.630670724717,0.21544645356733572,121.6174864362059,322.09846861283575,0.06565397759388987
0.0681665121905087,301.68289750526,0.2164286762048651,121.63854427412082,322.24756841572025,0.06594363867599527
0.06847670697504911,301.732322449204,0.21741354464578092,121.65847241151906,322.3939582784592,0.06623399579686357
0.0687864907002897,301.782300737958,0.2183971079734198,121.67862365754468,322.5408461611816,0.06652388403126253
0.06909791832019381,301.831051979406,0.21938589066661535,121.69828015809651,322.6869493555772,0.06681522590250019
0.06940982533018131,301.877904844643,0.22037619542332565,121.71717123336006,322.8311974909508,0.06710693119384212
0.06971968650038611,301.918851781441,0.22136000463872588,121.73368103827701,322.9685394761996,0.06739663891902505
0.07003047626882021,301.961886023787,0.22234676215350416,121.75103244479091,323.10842071706395,0.06768713056242075
0.0703393950159981,302.004191744052,0.22332757917579396,121.76809011120177,323.24698388362407,0.06797578978292965
0.07065021762876351,302.045361591684,0.22431444097132414,121.784689793767,323.3849321218951,0.06826614393795537
0.0709579404345116,302.087888397034,0.22529146087957433,121.80183660168412,323.52342278789814,0.06855351939149681
0.07126595589283581,302.133310845695,0.2262694099597537,121.82015093298423,323.6651300501808,0.06884108546801668
0.07157409144752282,302.177354888112,0.22724774034588494,121.83790949088676,323.80542452024434,0.06912868094878372
0.07188471753579512,302.227121828106,0.2282339781761495,121.85797552109236,323.95263311237574,0.06941851725368009
0.07219450043491181,302.27272331854,0.22921753888084498,121.87636204203532,324.09515157362233,0.06970748316377885
0.07250828220840311,302.316282605917,0.23021379601167985,121.89392514670575,324.2367169413022,0.07000009412905528
0.07282195145576321,302.36482104024,0.2312096958720482,121.91349584342476,324.3836173599629,0.07029251461022251
0.07313954359710961,302.419577734882,0.232218050920823,121.93557374270443,324.5384076252419,0.07058850514350762
0.0734597906839198,302.467706084901,0.23323483542144538,121.95497909343209,324.68692046254324,0.07088688135566032
0.07378010853792812,302.513272564073,0.23425184460792176,121.97335149783424,324.8327346480142,0.07118523447074587
0.07410251774340922,302.551890413549,0.23527549383532426,121.98892221474296,324.971747241221,0.07148544566846914
0.07442686123527201,302.591923368513,0.23630528442198862,122.00506350218444,325.1128904599754,0.07178736706409926
0.07475069562593771,302.635309702492,0.23733345861235222,122.02255687204477,325.25750962372433,0.07208872363846182
0.07507655253944241,302.674672630152,0.23836805431272964,122.03842800447728,325.3984435922281,0.07239187070879342
0.0754038993211943,302.706294955544,0.2394073803447919,122.05117812607536,325.5315299442636,0.07269631131321468
0.07573421355716951,302.736403218856,0.2404561280440132,122.06331777784276,325.66390663176225,0.0730034178040474
0.0760665424751528,302.769938784218,0.24151127235861014,122.07683931779671,325.80060119294717,0.073312302276454
0.0763992554761982,302.806170902842,0.24256763613692928,122.09144810802589,325.9403369134176,0.07362144819088573
0.07673215451010121,302.844460471947,0.2436245905695713,122.10688646228904,326.08236840540866,0.07393067133909814
0.07706500030177481,302.883227934599,0.244681375958135,122.12251750323033,326.2249239867814,0.07423974946521571
0.07739772834525811,302.928293814339,0.2457377874961945,122.14068806594149,326.37425560707374,0.0745486228021311
0.07773184695841921,302.970899938902,0.24679861409298098,122.15786685536528,326.52138756580723,0.07485869104087352
0.07806244950418512,303.015874693942,0.24784827717578772,122.17600067659741,326.67003611120435,0.07516540170329623
0.07839133020926761,303.057624583439,0.24889247341442466,122.19283423204261,326.81471490459563,0.0754704216492151
0.0787192230392871,303.097240575271,0.24993353314973654,122.20880739994925,326.9568198587082,0.07577443280158838
0.07904876942512111,303.135011472186,0.2509798429247595,122.22403662558541,327.0974610987323,0.0760798839803502
0.0793799541151495,303.167997107877,0.25203135431559964,122.237336433896,327.233458807482,0.07638675970806391
0.07971285736024121,303.193165279396,0.2530883221187658,122.24748424065247,327.36155881591253,0.07669513297109416
0.08004538062950661,303.216735371152,0.2541440834986835,122.25698770164851,327.4878343671723,0.07700305935474573
0.0803807301976413,303.23977480767,0.25520881837751114,122.26627720245256,327.61440933167887,0.07731350697352551
0.08072081804674151,303.264362194931,0.2562885972984043,122.27619083699618,327.7441095957291,0.07762824262505831
0.08106133957140971,303.289301868598,0.25736975313922583,122.28624651341872,327.8743389557442,0.07794328040653364
0.08140348615703431,303.312086677614,0.25845606854858394,122.29543334841395,328.00274792673633,0.07825972170482334
0.08174543117400491,303.335821597811,0.2595417439774656,122.3050032682374,328.1321391248451,0.07857587656321445
0.08208652318032351,303.35754121178,0.26062471109752716,122.3137606165897,328.2591070503868,0.0788911431979062
0.0824289430070956,303.381653906492,0.26171189404752854,122.32348285509758,328.3890829657486,0.07920753717612224
0.08277116715321171,303.408334129687,0.26279845571144717,122.33424032108978,328.5217960696128,0.07952365035878821
0.08311370381851792,303.433517874741,0.2638860096237944,122.34439440709559,328.6530014079932,0.07983995218327844
0.08345776582933331,303.459041954362,0.26497840650813326,122.35468571599877,328.785055616583,0.08015756184308229
0.08380566674952561,303.490632274446,0.2660829919297438,122.36742293305663,328.92486706444106,0.08047861272960663
0.08415540828697711,303.520629449986,0.2671934213111523,122.37951779423436,329.06353194486985,0.0808012583199842
0.08451026119376241,303.552672653355,0.26832007929019563,122.39243761383274,329.2059883053547,0.08112851292169262
0.08486514366773451,303.587477604192,0.2694468311450571,122.40647097001022,329.3514725067969,0.08145568771711297
0.08522228878260792,303.620872354818,0.2705807668847801,122.41993573346262,329.49613801906764,0.08178484046253447
0.08558015692717541,303.65655366128,0.2717169982437819,122.43432243622809,329.6435291755776,0.08211455093297984
0.08593896583367781,303.69261300484,0.27285621652192704,122.44886156355149,329.7916420978033,0.08244501904261504
0.08629267427968071,303.722454352349,0.27397924083798625,122.46089359486712,329.9314771772015,0.0827706826989189
0.086645871111983,303.757867556631,0.275100640780546,122.47517219883363,330.0772325981937,0.08309576951387909
0.0869970709974603,303.794079185166,0.27621570041693644,122.48977272745896,330.223274260646,0.08341891356088851
0.08735024388047441,303.832835522005,0.2773370243205062,122.50539928247241,330.37270780374814,0.08374376772167805
0.08770386537053261,303.871817472213,0.278459772551441,122.52111680479629,330.52255044169505,0.08406892882150542
0.08806000978443981,303.914345000108,0.2795905310655964,122.53826390404356,330.67704519444914,0.08439630296458654
0.0884162609469421,303.959528111663,0.28072162850654114,122.55648173462254,330.8344930664932,0.0847236680459106
0.08878009656656641,304.009364737074,0.28187680659884834,122.57657586198825,330.99934549557196,0.08505789203242017
0.08914861202492841,304.059489156778,0.2830468431791477,122.59678602801289,331.1659705881135,0.0853963011460198
0.0895227544319921,304.112348845287,0.28423474532157494,122.61809905441972,331.3373239706999,0.0857397603904952
0.08989815566456641,304.161666665197,0.2854266442349983,122.63798399940742,331.5052395222588,0.08608425670559232
0.0902768416307403,304.21181155018,0.28662897217760047,122.6582024170326,331.6750930836962,0.08643164714026107
0.09065520685128271,304.255784902061,0.2878302817528226,122.675932472511,331.83815601805674,0.08677862285149593
0.09103956928874012,304.296619059697,0.28905063249174984,122.69239680486983,331.99965219491156,0.08713097501884537
0.09142494453914361,304.336678625208,0.29027419891178097,122.70854882168385,332.1606425897448,0.08748413105136466
0.0918116549358153,304.38494607443,0.2915020044212136,122.72801025721017,332.3310317110723,0.08783838528181218
0.09219649939336481,304.467620526287,0.29272388557393325,122.76134459619892,332.53846931743806,0.08819080563406215
0.09258432805529031,304.521240397452,0.2939552415755467,122.78296412825264,332.7151348182136,0.08854583316005153
0.09297372653586601,304.566442471555,0.29519158175137455,122.80118960453098,332.8831196059069,0.08890217096940711
0.09336348123497111,304.609663760364,0.2964290529210333,122.81861642817877,333.0490823868456,0.08925870764805706
0.09375166811416712,304.658203499654,0.2976615462624806,122.8381876510605,333.2204182824119,0.08961368382147682
0.0941398267600582,304.707011941395,0.2988939499631848,122.85786721477047,333.39207725813293,0.08996850822741556
0.09452658219299272,304.743333329536,0.30012189846275183,122.87251199846891,333.54967907527697,0.09032192475117465
0.09491538132776502,304.724666455311,0.3013563357156539,122.86498551478141,333.6477243718929,0.09067708295617573
0.09530546866164051,304.713962158924,0.3025948630007086,122.86066954247815,333.75486913022564,0.09103329117874116
0.09569474155975341,304.667953064046,0.30383080445221705,122.84211867542335,333.82307409404893,0.09138862925711531
0.09608899952197121,304.608165679464,0.3050825734822586,122.81801240195988,333.8776595658265,0.09174838917236638
0.0964875895918512,304.539676503294,0.30634809695412757,122.79039756612815,333.9239758241789,0.09211197061006833
0.0968871666839111,304.399230815032,0.30761675422141777,122.73376986462092,333.8916098294623,0.0924763197440565
0.0972905598360257,304.215823720855,0.3088975274793816,122.65982012424872,333.81315152163467,0.09284401389369973
0.09769731971321621,304.051771136399,0.31018899008946144,122.59367412219608,333.75681423048144,0.09321463997836889
0.09810500493368832,303.898358144859,0.3114833906644604,122.53181800400715,333.7123080700002,0.09358597142344519
0.09851608926641751,303.706527100779,0.31278858342087557,122.45447172703409,333.626506435433,0.09396025931370874
0.09892725067081751,303.463445666586,0.31409402087984556,122.35646129276748,333.4842500254743,0.09433447729851464
0.09934176844277351,303.216037056632,0.3154101148058059,122.25670614123403,333.33805439804735,0.09471160837143151
0.0997617475971715,302.999599676681,0.3167435486210195,122.16943858963778,333.22736926167005,0.0950935632511728
0.10018428778859541,302.9392978346,0.3180851137287904,122.14512488691071,333.28905563133657,0.09547770012528092
0.10060692279699551,302.916536637991,0.31942697988046076,122.13594757243797,333.3920372534626,0.09586177564463284
0.10103436408292452,302.615047847328,0.3207841059632853,122.01438729204266,333.1895667685066,0.09625006895458012
0.10146359519669151,302.318839416168,0.3221469147494955,121.89495605259894,332.99319575902365,0.09663983650682015
0.10189869043107151,302.04456250035,0.32352834211865206,121.78436760014112,332.8225078709616,0.09703477404648245
0.10233358626222651,301.726895206896,0.32490913638256913,121.65628414742048,332.6036904651847,0.09742937478016793
0.10276650988125151,301.408721769615,0.3262836688729735,121.52799661750876,332.38344415364753,0.09782203144491027
0.10320542663780251,300.853743142017,0.32767722957502293,121.30422923486125,331.90348205856867,0.0982199664821396
0.10364755492198151,300.18200660654,0.32908098687729126,121.03338506375694,331.295137622882,0.09862065315568676
0.10408877550875752,299.686089816098,0.3304818622403051,120.8334314138507,330.8800479420632,0.09902035722049621
0.1045266599320965,299.176682660744,0.3318721452844064,120.62803844881199,330.4486220288363,0.09941688114408169
0.10496534541504451,298.689946922873,0.3332649716927663,120.4317865993024,330.04204037363365,0.09981397286258609
0.10540767827172051,298.190038658457,0.3346693785127126,120.23022358708988,329.6215583171996,0.10021420654064911
0.1058595967713775,297.663071362914,0.3361042197491236,120.01775037352695,329.1735640711219,0.10062294818038599
0.10630406808433351,297.062826576574,0.3375154161677589,119.77573167567465,328.64181351829467,0.10102479125013544
0.10674394636606051,296.39100676513,0.3389120297122421,119.50485392770041,328.0289524946497,0.10142232287588203
0.10719532377159251,295.68590601132,0.34034515297480616,119.22055730376424,327.38205244090017,0.1018300824001604
0.1076446730063435,294.919979820317,0.3417718367951406,118.91173586355183,326.6665446111125,0.10223584465979985
0.1081007842394335,293.991291516639,0.34321998996020137,118.53728873950887,325.77198068915163,0.10264754469334005
0.1085614472422815,292.998745960435,0.34468259499424375,118.13709437124739,324.8071138620734,0.10306318132298743
0.10900808479109252,291.832040935419,0.3461006692117187,117.66667890516094,323.6440927984648,0.10346599850495046
0.10948412496039552,290.756997160962,0.34761209674925575,117.23322125529987,322.5902725712421,0.1038951550054932
0.1099417595602765,289.569533309231,0.34906508660387786,116.75443583028195,321.40531731629596,0.104307545083088
0.1104091515923605,288.292509092602,0.35054905630574457,116.23953966613713,320.12264043194904,0.1047285524442577
0.11090993908307852,286.996163318533,0.35213905658877426,115.7168530500325,318.8268903092687,0.10517944444019349
0.11140708063518051,285.52556145031,0.3537174810166981,115.123906376765,317.3351306982099,0.10562685275861418
0.11192437750621852,283.816052969582,0.35535989858224376,114.43463255733546,315.5819880244744,0.10609218767615704
0.11246087488024852,281.836720644191,0.357063277744789,113.63656576373782,313.53232482121695,0.10657456579285919
0.11299409142619551,279.5696292215,0.3587562402781707,112.7224745021088,311.15934546574175,0.10705376358766841
0.11358069524456652,276.756975489745,0.36061870740149865,111.58841251746519,308.1912251796537,0.10758067499927207
0.11386947632437351,275.536173845693,0.3615355873298859,111.0961852945834,306.9113336699236,0.10783996796583163
0.11414880420553052,274.058313634503,0.36242245335255935,110.50031205743163,305.34174241846574,0.10809070907066141
0.11444694341566451,272.465466272036,0.3633690453447348,109.85807600088492,303.64830607319436,0.10835826698216762