File: example/data/02 processed data/test_ID_114.csv
Strain,Stress_MPa,Displacement(mm),Force(kN),True Stress (MPa),True Strain
-4.05594430187721e-05,0.350109993739249,-0.00012877623158460142,0.0705821747378326,0.35009579347290765,-4.0560265575179074e-05
-6.65901999268364e-05,1.28982874090134,-0.00021142388476770555,0.26002947416571015,1.289742850947612,-6.659241715262439e-05
-6.23259745920535e-05,2.39209816731597,-0.00019788496932976986,0.48224699053089953,2.391949077466372,-6.232791693636394e-05
-5.08173459700587e-05,3.6938211462817,-0.00016134507345493636,0.7446743430903906,3.693633436094558,-5.08186372150822e-05
-5.69048780113452e-05,5.79936697299611,-0.000180672987686021,1.1691523817560159,5.799036960725969,-5.69064971553504e-05
-6.2414337065946e-05,8.35272951578366,-0.00019816552018437855,1.683910270381986,8.35220818570824,-6.24162849217824e-05
-5.44989363701796e-05,11.3104710845576,-0.00017303412297532022,2.280190970646812,11.309854675913645,-5.4500421491208855e-05
-3.10684138985656e-05,14.3797279081935,-9.864221412794578e-05,2.89895314629181,14.3792811528551,-3.106889653171707e-05
1.18882886249933e-05,17.5792933901958,3.7745316384353725e-05,3.543985547463474,17.57950237790945,1.1888217959940573e-05
4.59632480278734e-05,20.9522137480756,0.00014593331248849805,4.223966291612041,20.953176779872834,4.5962191750140104e-05
8.50507939660103e-05,24.3074823393309,0.0002700362708420827,4.9003884396091095,24.309549710003175,8.504717735232032e-05
0.0001442326560836,27.8849658882577,0.0004579386830654299,5.621609123072752,27.888987810952564,0.00014422225555416526
0.0002112312584498,31.5699431794795,0.000670659245578115,6.364500544983067,31.576611738306493,0.00021120895226875322
0.0002803790913619,35.3836776762538,0.0008902036150740325,7.133349419532766,35.39359851964971,0.00028033979249002857
0.0003536104982979,39.3694563526744,0.0011227133320958324,7.936882400699159,39.383377805752986,0.0003535479928403326
0.0004286730175086,43.4808487206188,0.001361036830589805,8.76573910207675,43.49948778724371,0.0004285811634800288
0.000505044441598,47.6500488393392,0.0016035161020736498,9.606249846010783,47.67411423164738,0.0005049169495782249
0.000581294238181,51.966869050494,0.001845609206224675,10.476520800579591,51.99707709204936,0.0005811253521305806
0.0006586879726248,56.2995996426309,0.0020913343130837397,11.34999928795439,56.336683511779086,0.0006584711329166342
0.000737848682303,60.7198348553973,0.0023426695663120245,12.241118706848097,60.76463690553502,0.000737576605790072
0.0008170232610127,65.1348350791666,0.0025940488537153222,13.131182751959988,65.18805175452852,0.0008166896791919272
0.000896464999825,69.5219993510081,0.002846276374444375,14.015635069163235,69.58432339014415,0.0008960634150636759
0.0009782335401981,72.5116080936063,0.0031058914901289673,14.61834019167103,72.58254138069715,0.0009777553815768683
0.0010612229665219,75.7743590298751,0.003369382918707032,15.27611078042282,75.85477251995108,0.0010606602674937892
0.0011386688417227,79.251125221097,0.003615273572469572,15.977026844573155,79.34136600805773,0.0011380210500573583
0.0012192482574555,82.8057160686238,0.003871113217421213,16.693632359434556,82.90667679364782,0.0012185055779114396
0.0012955823513455,86.3379543475976,0.004113473965521962,17.40573159647568,86.44981227750162,0.0012947438087200648
0.0013805943103841,89.8419125123515,0.0043833869354695165,18.112129562490065,89.96594774560009,0.0013796421663082893
0.0014641979805044,93.2717816141708,0.00464882858810147,18.803591173416834,93.40834996844832,0.0014631270878464181
0.0015472300117697,98.005631332817,0.004912455287368797,19.757935276695907,98.15726858693756,0.0015460342846326483
0.0016272438111169,102.359767011591,0.005166499100296157,20.635729029536748,102.52633130896798,0.0016259212844276832
0.001708666882082,106.35728572221,0.00542501735061035,21.441628801597535,106.53901489399168,0.0017072087715389265
0.0017900770821777,110.144704362214,0.005683494735914197,22.205172399422345,110.34187187321604,0.0017884768036609618
0.0018750878750216,113.869437704929,0.00595340400319358,22.956078641313688,114.08295290690504,0.001873332092240746
0.0019488164538271,117.589050261867,0.006187492240901042,23.70595253279239,117.81820973780722,0.0019469199745686236
0.0020263063788776,121.290756632958,0.0064335227529363805,24.452216537204333,121.53652886682225,0.002024256189181627
0.0020994308523094,124.942090370013,0.006665692956082344,25.188325418594623,125.20439764928784,0.0020972301269997695
0.0021779172819568,128.565831726479,0.00691488737021284,25.918871676058167,128.84583747326522,0.0021755490580204
0.0022510086058062,132.188836249202,0.007146952323434684,26.649269387839126,132.48639445719047,0.0022484788815107563
0.0023305687394826,135.802447359327,0.007399555747857255,27.377773387640325,136.11894429788788,0.002327857176330176
0.0024111626197343,139.351750686273,0.007655441317656402,28.09331293835264,139.68775041852226,0.002408260431307562
0.0024957777102013,142.867079519559,0.007924094229889126,28.8020032311431,143.22364399214547,0.0024926684293199693
0.0025757088274583,146.349695344613,0.008177875527180103,29.504098581473983,146.72664954680795,0.002572397374483297
0.002663526915297,149.812062141585,0.008456697956067974,30.202111727743535,150.21109060133526,0.0026599860136137976
0.0027467972072511,153.231261322801,0.008721081133022243,30.891422282676682,153.65215652346603,0.0027430316537007224
0.0028345890740778,156.615800316633,0.008999820310197014,31.573745343833213,157.05974175303848,0.00283057920224033
0.0029250275374336,159.928334970245,0.00928696243135168,32.24155233000139,160.39612975404887,0.0029207579680984664
0.003005682203278,163.21422172067,0.00954304099540765,32.90398709888707,163.7047918022177,0.0030011741714063003
0.0030866106578002,166.432283870723,0.009799988838515634,33.55274842833776,166.94599553192043,0.0030818568547047
0.0031781092252347,169.622984956266,0.010090496790120172,34.195993767183225,170.16206532956738,0.0031730697107063576
0.0032591424247694,172.730049719262,0.010347777198642844,34.822378023403225,173.2930015523346,0.00325384293151064
0.0033425539508573,175.79105413465,0.010612608793971927,35.43947651354544,176.37864521717316,0.003336980034690242
0.0034371988012293,178.814592366426,0.010913106193903028,36.049021821071484,179.4292136689502,0.0034313051347042373
0.0035211777401386,181.824289221574,0.011179739324940055,36.655776707069315,182.4645248613975,0.0035149929081426056
0.0036247586747887,184.743953693826,0.011508608792454121,37.24438106467532,185.41360594259245,0.0036182050691149067
0.0037326048549685,187.568291209894,0.011851020414524988,37.81376750791463,188.26840952430217,0.0037256559717224105
0.0038397251425491,190.306576298439,0.012191127327593393,38.36580578176531,191.03730124424456,0.0038323722141030124
0.0039735183701835,192.983452913963,0.01261592082533261,38.90546410745494,193.75027620925806,0.003965644796366053
0.0041182784115553,195.544323504154,0.013075533956688076,39.421735618437445,196.34962947014333,0.0041098215136401535
0.0042801705788627,197.923161465683,0.013589541587889071,39.90130935148169,198.7703063582639,0.004271036702528054
0.0044712691078856,200.064966309062,0.014196279417536779,40.3330972079069,200.95951061248988,0.0044613026815078045
0.004681152656439,202.009743144317,0.014862659684193823,40.72516421789431,202.95538159006358,0.0046702301347395425
0.0049203150827417,203.708445245981,0.015622000387704898,41.06762256158977,204.71075498160667,0.004908249892657916
0.005189572574004,205.159204501102,0.016476892922462696,41.36009562742217,206.22389308208543,0.0051761531496153776
0.0054709436996835,206.343144391786,0.01737024624649511,41.59877790938406,207.47203611756916,0.005456032448222845
0.0057845210271493,207.209062262829,0.018365854261199025,41.77334695218633,208.4076674405042,0.005767854924786313
0.0061083166447588,207.857856802362,0.019393905347109188,41.904143931356174,209.12751840881177,0.006089736502514851
0.006443128678451,208.340798868093,0.020456933554081923,42.001505051807555,209.6831654441714,0.00642246045604056
0.006785932051503,208.649018892635,0.021545334263522026,42.06364220875522,210.0648969574532,0.006763011248845706
0.007136863822847,208.873787815112,0.022659542637539224,42.10895562352658,210.3644915949107,0.007111516936963408
0.0074964365775174,208.96594897641,0.023801186133617744,42.12753531364426,210.5324489597724,0.007468477936681815
0.0078602241715863,209.009906890475,0.0249562117447865,42.136397229119765,210.65277161271655,0.007829493537647305
0.0082268556273736,209.063637924662,0.026120266616911175,42.14722940561186,210.78357429080174,0.008193199513944148
0.0085993004846555,209.076138955234,0.027302779038781214,42.14974961337518,210.8740474982816,0.008562537109439715
0.0089776237899086,209.089556853288,0.028503955532959802,42.15245466162286,210.96668423311553,0.008937564505060211
0.009361917855297,209.108431963805,0.029724089190567977,42.15625988390308,211.0660879267001,0.00931836670617951
0.0097452534612517,209.118224992797,0.030941179739474148,42.15823415854788,211.15613509871886,0.009698074743480346
0.0101296301047842,209.122759360372,0.03216157558268983,42.159148287050996,211.24109555918434,0.010078669255843145
0.0105213008031682,209.121790261757,0.03340513005005903,42.15895291677021,211.322023521598,0.010466337108116088
0.0109129833791033,209.120789947805,0.03464872222865298,42.1587512534775,211.40292165273036,0.010853866481593059
0.011312002214748,209.137978876701,0.0359156070318249,42.162216541542925,211.50374815694215,0.011248499960721903
0.0117203357104975,209.130763500748,0.03721206588082956,42.1607619217508,211.58184625636943,0.011652184561941508
0.0121232835564531,209.12350593507,0.03849142529173859,42.159298796510114,211.65876949584046,0.01205038514171345
0.0125373036654361,209.10223840781,0.039805939137759615,42.155011263014494,211.72381666785114,0.012459362446222534
0.0129467963184126,209.10142818482,0.041106078310960005,42.154847922059716,211.80862178541807,0.012863702977514607
0.013360522594691,209.067801250368,0.04241965923814392,42.14806873207419,211.8610563327959,0.013272057897980813
0.0137724199851475,209.03239216374,0.04372743345284331,42.14093026020999,211.91127405911908,0.013678442094570328
0.0141804536813993,208.981430280932,0.04502294043844278,42.13065634463589,211.9448817733033,0.014080851546048573
0.0145816231065531,208.905366460555,0.04629665336330609,42.11532187844789,211.9515457792192,0.014476333534767457
0.0149926317560907,208.837530253265,0.04760160582558797,42.10164609905823,211.96855444120362,0.014881353113796167
0.0154001809115262,208.749683102039,0.048895574394095684,42.08393611337107,211.96446598703417,0.015282801698884073
0.0158055163558991,208.690998459651,0.05018251442997964,42.07210528946565,211.9894674491339,0.015681909923421264
0.0162145597024731,208.636995153093,0.05148122705535209,42.06121822286355,212.01995216714744,0.016084507670282737
0.0166263025189129,208.602758902868,0.05278851049754846,42.05431619481819,212.07105147866693,0.016489598722634214
0.0170430836282279,208.557868102509,0.05411179051962358,42.045266209465815,212.11233728990496,0.016899479618702185
0.0174571684791112,208.525941154636,0.055426509921178056,42.038829736774616,212.1662136416377,0.017306542587775073
0.0178694947565668,208.474416383728,0.05673564585209958,42.028442342959565,212.19974887417533,0.01771171222520397
0.0182838972937377,208.46319502381,0.0580513739076172,42.0261801168001,212.27471467114975,0.018118756747989635
0.0187071174775177,208.407320947678,0.059395097991118695,42.01491590305188,212.30602118382095,0.018534291413386493
0.0191245337749821,208.337569899314,0.06072039473556816,42.000854091701704,212.3219287914511,0.018943958525039856
0.0195395496330697,208.222763671958,0.062038070084996295,41.97770915626674,212.29134269746118,0.019351103446263732
0.0199587487669253,208.127133702465,0.06336902733498782,41.95843015441694,212.28109087561276,0.019762184092997015
0.0203836566751082,208.059337486861,0.06471810994346852,41.94476243735118,212.30034759024363,0.02017869057072564
0.0208053350970983,207.987022574602,0.0660569389332871,41.93018375103977,212.31426227511434,0.020591859982954073
0.0212337788152415,207.923966978665,0.06741724773839176,41.91747174289886,212.33897850387754,0.02101148340888267
0.0216554528702218,207.854205888893,0.06875606286295421,41.90340790720083,212.35538284839728,0.02142430467635874
0.0220814954572962,207.814262102612,0.07010874807691543,41.89535523988658,212.40311178719216,0.021841229754309167
0.0225182555983118,207.778847370658,0.07149546152463997,41.88821562992465,212.45766456367312,0.022268462661320633
0.0229493532892868,207.707226485701,0.0728641966934856,41.87377685951732,212.47397300705927,0.022689977717814065
0.0233763406003572,207.574866834261,0.07421988140613411,41.84709315378702,212.42720762145245,0.02310729869320147
0.0238127015925895,207.486701789466,0.07560532755647166,41.82931908075635,212.42752070360916,0.023533601286511042
0.0242397765466397,207.381900346202,0.07696129053558104,41.80819110979433,212.40879127041146,0.023950655990723053
0.0246709816813062,207.29641316295,0.07833036683814719,41.79095689365072,212.4106191746936,0.024371567579284024
0.0251174292495714,207.191199389447,0.07974783786738919,41.769745796912524,212.3953096812453,0.02480717114982232
0.0255476543276566,207.101130462153,0.0811138024903097,41.751587901170055,212.39207855406698,0.025226766809632973
0.0259823170109622,207.036126311312,0.08249385650980498,41.7384830643605,212.41540457785408,0.025650511717952285
0.0264237080226537,207.001578271429,0.08389527297192549,41.73151817952009,212.47132753590174,0.026080632281927234
0.0268595726261426,206.907906439664,0.08527914308800276,41.712633938236266,212.4653643796033,0.02650518608231484
0.0273054121726541,206.800797733955,0.08669468364817677,41.69104082316533,212.4475787537143,0.026939269572990112
0.0277467325877225,206.697963046634,0.08809587596601894,41.670309350201414,212.43315615371588,0.027368767601035522
0.0281697061977999,206.590394017502,0.08943881717801468,41.64862343392841,212.40998472026277,0.02778023725813398
0.0286113627785122,206.469904732987,0.09084107682177624,41.62433279417018,212.37729008014736,0.028209701136582093
0.0290531496448207,206.338596535518,0.09224375012230572,41.59786106156044,212.3333826581667,0.028639107262245
0.0294868082557042,206.240041353778,0.09362061621186084,41.577992336921646,212.32140190782536,0.02906043366461506
0.0299307834347813,206.151513679758,0.09503023740543062,41.560145157839216,212.3217899904592,0.02949159943473033
0.0303702405925747,206.078497228909,0.09642551388142467,41.545425041348054,212.3371507707072,0.029918194538390418
0.0308176330528683,205.984433133906,0.09784598494285685,41.526461719795456,212.3323858088298,0.030352305832212673
0.031271100714145,205.852227803878,0.09928574476741038,41.49980912526181,212.2894535517642,0.030792119755989094
0.0317209982783717,205.722185772555,0.10071416953383014,41.4735926517471,212.2478988732691,0.031228280002631406
0.03216821047959,205.626033048967,0.10213406827269825,41.45420826267175,212.2406545601693,0.031661648427951626
0.0326176678618589,205.494848289651,0.103561095461402,41.42776141519364,212.1976109984859,0.032097003390499944
0.0330675941889845,205.357162391005,0.10498961155002579,41.400003938026614,212.14782970075214,0.0325326228360237
0.0335182364988391,205.220333933685,0.10642040088381415,41.3724193210309,212.098957620845,0.032968745362662234
0.0339724589707749,205.096946113858,0.1078625572322103,41.347544336553774,212.06459370074225,0.0334081403067256
0.03443458734915,205.021710243114,0.10932981483355125,41.33237678501178,212.08154823295266,0.03385498502898361
0.03489342412954,204.949479251722,0.1107866216112895,41.31781501714716,212.10086835638072,0.034298449559849994
0.0353568902188565,204.848085451039,0.11225812644486938,41.29737402692947,212.09087671987433,0.034746188747567554
0.0358257150877085,204.754508040131,0.11374664540347448,41.27850882089041,212.08998470810064,0.0351989010054418
0.0362913382647518,204.649702343106,0.11522499899058697,41.25737999237017,212.07671391662043,0.035648318845159864
0.0367563774371283,204.527021390932,0.11670149836288234,41.23264751241189,212.0446937852687,0.036096971499563
0.0372225093024322,204.38074572437,0.11818146703522223,41.20315833803299,211.98830993333337,0.036546476435348856
0.0376806926209566,204.202978654012,0.1196361990715372,41.16732049664883,211.89748832495758,0.036988119520719814
0.0381441271787612,204.050125786434,0.1211076037925668,41.136505358545094,211.83343973527397,0.03743462595140114
0.0386084420814527,203.899411248455,0.12258180360861232,41.106121307688525,211.7716498580833,0.03788178072303909
0.0390729596013482,203.747436047338,0.12405664673428052,41.075483107143334,211.7084513848939,0.038328930634723264
0.0395389943441781,203.616954091672,0.12553630704276544,41.04917794488107,211.6677636878814,0.03877734020896271
0.0400104860731247,203.502995754444,0.12703329328217092,41.026203944095904,211.64524953191633,0.03923079586507053
0.0404821430574616,203.385094164376,0.1285308042074406,41.00243498353821,211.61855864209355,0.039684204818135824
0.0409600425775875,203.284227972454,0.1300481351838403,40.98210035924672,211.61075860555775,0.04014340520508088
0.0414354026188286,203.174754127842,0.1315574033147808,40.96003043217294,211.59338186711062,0.04059995638568834
0.0419090622070636,203.056123088814,0.13306127250742691,40.9361144147049,211.56601478286828,0.04105466716865615
0.0423916628938661,202.931630334638,0.13459352968802488,40.911016675463024,211.5342395982866,0.04151774880521153
0.042876485703512,202.813915372431,0.1361328421086506,40.88728533908209,211.50986331537035,0.041982746861895834
0.0433561594634635,202.675846303161,0.13765580629649662,40.85945061471726,211.46309261487326,0.042442593724627414
0.04383354737747,202.509979075607,0.13917151292346724,40.82601178164237,211.38670983782808,0.04290003937105483
0.0443145410604129,202.352080535144,0.14069866786681096,40.794179435885034,211.31922011667862,0.04336072862399918
0.0447966902758113,202.20039172762,0.14222949162570087,40.76359897228819,211.2583000494899,0.04382231172855267
0.0452873917316566,202.029938217624,0.14378746874800968,40.729235544672996,211.1793471712079,0.04429186361795777
0.0457793002842323,201.894310665208,0.14534927840243755,40.701893030105936,211.13689093882866,0.04476234938823761
0.046269848401807,201.739446179525,0.1469067686757372,40.67067234979224,211.0738997709161,0.045231313634964854
0.0467666513868738,201.567459259621,0.14848411815332432,40.63599978673959,210.9940943577536,0.04570603349240356
0.0472664941369202,201.426183470801,0.1500711188847216,40.60751858771348,210.94689299084584,0.04618343067268038
0.0477587887218189,201.276831243469,0.151634154191775,40.57740917868335,210.88956890142302,0.04665339597380349
0.0482559184799667,201.108233606975,0.15321254117389427,40.54341989516616,210.8128961335633,0.047127753110479516
0.0487496999894954,200.931960413423,0.1547802974666479,40.507883219346084,210.72733320187857,0.047598692734394495
0.0492367749280767,200.74534966195,0.15632676039664353,40.47026249184912,210.62940326111348,0.048063018842456215
0.0497289018309083,200.565808425103,0.15788926331313385,40.434066978500766,210.53972582291172,0.04853194210051483
0.0502154770862208,200.381294920431,0.15943413974875104,40.396869055958895,210.44353724401518,0.048995359388044404
0.0507088572394692,200.209148634693,0.16100062173531468,40.362164364754115,210.3615257708453,0.049465038523325164
0.0512047743104009,200.041462710564,0.16257515843552287,40.328358882449706,210.2845406613809,0.04993691050958559
0.0516998928253037,199.834288943311,0.16414715972033922,40.2865926509715,210.16570026450094,0.050407800637692
0.0521948963602074,199.682969343321,0.1657187959436585,40.25608661961351,210.1054012330941,0.05087835985632038
0.0526947452720916,199.50276232162,0.16730581623889082,40.219756884038596,210.0155095632364,0.05135330059562905
0.0531904722039878,199.324594053543,0.16887974924766125,40.18383816119427,209.9267633331191,0.05182410207800703
0.053701247099221,199.170533829259,0.17050145954002666,40.15277961997862,209.86623988130782,0.0523089631656084
0.0542054248268518,199.021644439657,0.17210222382525445,40.122763519034855,209.80969722624724,0.05278733134382048
0.0547180014415113,198.839619338097,0.17372965457679837,40.086067258560355,209.7197259156686,0.05327343398592534
0.0552299666790858,198.69684415365,0.1753551442060974,40.057283781375844,209.6708642354956,0.0537587210691684
0.055750443874581,198.516592427918,0.17700765930179466,40.02094503346827,209.58398057224372,0.05425183526713991
0.0562666506769785,198.329287174747,0.17864661589940672,39.983184294429,209.48861189522265,0.05474066351953253
0.0567802985982552,198.084877606979,0.18027744804946025,39.93391132556697,209.33219610530213,0.055226831544876356
0.0572808269322785,197.851655369036,0.18186662550998423,39.88689372239766,209.18476179849455,0.05570035460183155
0.057789785975132,197.520771002097,0.18348257047104408,39.820187434022756,208.93545408395124,0.0561816236900325
0.0582936891351024,197.26793713616,0.1850824630039501,39.76921612664985,208.76741293989824,0.05665788388999368
0.0588005886375901,197.028393033591,0.18669186892434855,39.72092403557195,208.6137785222846,0.05713674731851086
0.0593026038418395,196.77771100176,0.1882857671978404,39.67038653795481,208.44714164220136,0.0576107706951169
0.059810311970809,196.554519876955,0.18989774050731856,39.62539120719413,208.31050703006827,0.05808994113940551
0.0603231215009768,196.348602060495,0.19152591076560133,39.583878175395796,208.1929626391372,0.05857369327695693
0.0608372106310373,196.116310969391,0.19315814375354343,39.53704829142923,208.04748028801785,0.05905841772926612
0.0613482458283144,195.917582500291,0.19478068050489822,39.49698463205867,207.9367825136079,0.05954002993294933
0.0618616812245071,195.675544807868,0.19641083788781002,39.44818983326619,207.7803629842041,0.0600236706692317
0.0623754342265313,195.421937247525,0.19804200366923688,39.39706254910104,207.61146544072932,0.06050737656844995
0.0628834809266074,195.188615575927,0.19965505194197847,39.35002490010688,207.4627551605867,0.060985479924357676
0.0633927273526002,194.85298102231,0.20127190934450562,39.2823609740977,207.20524292209868,0.06146448301318207
0.0639027186658655,194.566598165382,0.20289113176412293,39.22462619014101,206.99993274971894,0.061943956914177103
0.0644230391271864,194.295117389798,0.2045431492288168,39.16989566578328,206.81219933962225,0.06243290506488362
0.0649372859873074,194.058757283153,0.206175883009701,39.122245468283644,206.66040630319057,0.06291591103062205
0.0654534943839993,193.775925573961,0.20781484466919778,39.06522659571054,206.45923703027051,0.06340052485035004
0.0659702408514963,193.470038682325,0.20945551470350074,39.00355979835672,206.2333037317463,0.06388540870434772
0.0664917375164008,193.11991045592,0.21111126661457255,38.932973947913474,205.96078885114588,0.06437451161036978
0.0670153908045472,192.848219980957,0.21277386580443736,38.87820114816093,205.77201880894214,0.06486539658723293
0.0675327100271925,192.528107956979,0.21441635433633616,38.81366656412697,205.53005284372168,0.06535010736285067
0.0680523950924478,192.153812861527,0.21606635441852176,38.73820867288384,205.23034005289992,0.06583679840997174
0.068573357352133,191.774657329487,0.21772040959302227,38.66177091762458,204.92528943762477,0.06632444793812416
0.0690868625067915,191.393541635626,0.219350788459063,38.58493799374221,204.61632093129438,0.06680488459476892
0.0695887806448881,191.003250372364,0.22094437854751972,38.50625527506858,204.29493366498707,0.0672742574507404
0.0700849961015652,190.583719763729,0.22251986262246948,38.42167790436777,203.94077902039174,0.06773808092791339
0.0705720506548519,190.090069177274,0.2240662608291548,38.32215794613844,203.50511516823687,0.06819313239206949
0.0710636075607482,189.613561107855,0.22562695400537552,38.22609391934357,203.08818480261957,0.06865218051507078
0.0715475922750373,189.130907791891,0.22716360547324344,38.12879101084523,202.6627688691929,0.06910395144071306
0.0720304431216032,188.692280450177,0.22869665691109015,38.04036373875569,202.2838690246291,0.06955446067971371
0.0725136883701129,188.253311352715,0.23023096057510847,37.95186756870734,201.90425330678764,0.07000513478764434
0.0730010792812111,187.784061022919,0.23177842671784524,37.85726670222047,201.49250014940088,0.07045946950193348
0.0734945524908814,187.343451080396,0.23334520415854842,37.76843973780784,201.11217417964704,0.0709192637927393
0.0739786644122579,186.928733089111,0.2348822595089188,37.68483259076478,200.7574711033189,0.07137013035141569
0.0744631449091844,186.418588692175,0.23642048508666047,37.581987480342484,200.29990307572606,0.07182113675339186
0.0749446977618014,185.932040891403,0.23794941539371944,37.48389944370685,199.8666615002441,0.07226921631383075
0.0754325374028435,185.401369548688,0.2394983062540281,37.3769161010155,199.3866652917078,0.07272294102913536
0.0759178175827109,184.868700693278,0.24103907082510712,37.26953005976485,198.90352898926304,0.07317408111143152
0.0764009966798109,184.303020512858,0.2425731644583996,37.15548893539218,198.38395497114,0.07362306580832226
0.076887725298174,183.733665430285,0.24411852782170246,37.04070695074545,197.86052902591535,0.07407514510608193
0.0773857749604726,183.144800351413,0.24569983549950047,36.92199175084487,197.31760265658812,0.07453752805895406
0.0778768729790643,182.589279418817,0.24725907170852915,36.809998730833506,196.80876153945508,0.07499324794772073
0.0783709413908044,181.979335780905,0.24882773891580395,36.68703409343045,196.2412276397278,0.0754515147731702
0.078890972815307,181.31012862532,0.2504788386885997,36.552121930864516,195.61386105383997,0.07593363651383708
0.0793881450831224,180.578183166463,0.2520573606389136,36.40456172635894,194.9139501705288,0.07639434826560844
0.0798741481237429,179.884147436794,0.2536004202928837,36.264644123257675,194.25224047427366,0.07684450483098394
0.0803431187694366,179.145574269431,0.2550894020929612,36.11574777271729,193.5386884199788,0.0772786932436483
0.0808268608721053,178.408313363811,0.25662528326893436,35.9671159741443,192.8284972864947,0.07772636012344424
0.0813312160524104,177.595520326391,0.258226610966403,35.80325689780043,192.03957995999696,0.07819288955515938
0.0817963171195526,176.764061877832,0.2597033068545795,35.63563487457093,191.22271113853137,0.07862291604890703
0.0822539343797339,175.965357852382,0.2611562416556551,35.474616143040215,190.43920085027824,0.07904584270385448
0.0827146473055927,175.062773188649,0.2626190051952568,35.29265507483164,189.54302872928707,0.07947144974195253
0.0832037491525653,174.223152056167,0.2641719035593948,35.12338745452327,188.71917149641754,0.07992308435208934
0.0836982303005295,173.362171157796,0.26574188120418113,34.94981370541168,187.87227808476106,0.08037947892945028
0.084183644852343,172.464149104084,0.26728307240618904,34.768772459383335,186.9828097820237,0.08082730273893853
0.0846586057965257,171.570212701441,0.26879107340396907,34.5885548806105,186.09510770495837,0.08126528844456866
0.085176229510547,170.649211368839,0.2704345286959867,34.402881011957945,185.18446776218505,0.08174239731517721
0.0856733500433908,169.657828640489,0.2720128863877658,34.20301825392258,184.1929831812072,0.08220039361875872
0.0862027045442522,168.678929200256,0.2736935869280007,34.005672126771614,183.2195090969465,0.08268785652919994
0.0867232380386997,167.607261939575,0.27534628077287154,33.789624007018325,182.14270641377547,0.08316696490027123
0.0872509652965423,166.505662413147,0.2770218148165218,33.56754154249044,181.03344218603428,0.08365246032832059
0.0877914070140077,165.338508387678,0.27873771726947444,33.33224329095589,179.85380867262955,0.08414940855835763
0.088343210550669,164.135173162499,0.28048969349837405,33.0896509095598,178.63540132396415,0.08465654956336158
0.088917446098093,162.93100165411,0.2823128913614453,32.846889933468574,177.41841021139763,0.0851840340048639
0.0895297310619291,161.704380989897,0.28425689612162486,32.599603207563234,176.18173073145823,0.08574616375157398
0.0901458301395331,160.418996490589,0.2862130106930176,32.340469692502744,174.88010009938398,0.08631147641092399
0.0907835639931534,159.038516208857,0.28823781567826207,32.062164867705576,173.47659952247994,0.0868963040293812
0.0914470032171804,157.639580832083,0.2903442352145477,31.78013949574793,172.05524808758946,0.08750434174495139
0.0921058734723678,156.241226686768,0.29243614827476777,31.498231300052428,170.631961343147,0.08810782635227886
0.0927619699368832,154.828115404268,0.29451925454960415,31.213348065500433,169.190276390783,0.08870840865863255
0.0933936437440561,153.310529047971,0.29652481888737814,30.907402656070953,167.62875798008994,0.08928629416760459
0.0940193989085352,151.733392464141,0.2985115915345992,30.589451920770827,165.99927481797238,0.08985843593447464
0.0946532507538047,150.181025787274,0.3005240711433299,30.276494798714438,164.39614807958046,0.09043764714094539
0.0952849866751595,148.603665398655,0.3025298326936314,29.95849894436885,162.7633636760457,0.09101459121003475
0.0959260703501897,146.971457418768,0.3045652733618523,29.62944581562363,161.06985178259066,0.09159973219065042
0.0965658313334085,145.177320941581,0.30659651448357195,29.26774790182273,159.19648962906183,0.09218332476938255
0.0972335059105742,143.39455339347,0.30871638126607304,28.90834196412355,157.3373085483981,0.0927920172659527
0.0979012185770562,141.575734978375,0.31083636898215344,28.541668171640403,155.4361719537003,0.0934003741741886
0.0985905997192484,139.660195938795,0.31302515410861365,28.155495501261072,153.42937841330854,0.09402808528978275
0.0993248853053188,137.64935769527,0.31535651084438715,27.750110511366433,151.32136436070348,0.09469625075691884