File: example/data/02 processed data/test_ID_150.csv
Strain,Stress_MPa,Displacement(mm),Force(kN),True Stress (MPa),True Strain
-1.71158631614584e-05,0.0330069942876414,-5.4342865537630414e-05,0.006654210048388507,0.033006429344443804,-1.7116009639500485e-05
3.27961249054272e-06,0.0361162499730311,1.0412769657473135e-05,0.007281035994563071,0.03611636842033562,3.2796071125526444e-06
2.44789298402213e-05,0.050811899008724,7.772060224270263e-05,0.01024367884015876,0.05081314282963489,2.4478630236141048e-05
7.99005808712155e-05,0.0634996618056139,0.00025368434426610917,0.01280153182001176,0.06350473546547729,7.989738898975981e-05
0.0001464382031405,0.0826560015164489,0.0004649412949710875,0.0166634499057161,0.08266810551278975,0.0001464274821133829
0.0001801341527502,0.0897585516271517,0.0005719259349818849,0.01809532400803378,0.08977472020780115,0.00018011793054190393
0.0002294088318152,0.0903464322844297,0.00072837304101326,0.01821384074854103,0.09036715855391873,0.0002293825216328278
0.0002619046905388,0.118431591351293,0.00083154739246069,0.02387580881642067,0.11846260914057587,0.00026187039949250243
0.0003178050087976,0.800813796581522,0.00100903090293238,0.16144406139083484,0.8010682992171897,0.0003177545194826024
0.0003734980744957,2.27700543310787,0.0011858563865238475,0.4590442953145466,2.2778558902527517,0.0003734283414526759
0.0004364397414403,4.86902515427948,0.0013856961790729525,0.981595471102743,4.871150190358879,0.0004363445293181943
0.0005030177291081,8.06335032444975,0.0015970812899182174,1.6255714254090696,8.067406332618958,0.0005028912580998655
0.0005501354718786,11.3634219844792,0.001746680123214555,2.2908658720710067,11.369673405994787,0.0005499842028363795
0.0006186799734644,14.831584963108,0.00196430891574947,2.9900475285625725,14.840760967699412,0.000618488669909367
0.0006712870180825,18.1773092599556,0.0021313362824119373,3.6645455468070485,18.18951145168548,0.0006710618057346248
0.000737231188709,21.7561627713869,0.002340709024151075,4.386042414711599,21.772202093128598,0.000736959567286575
0.0008182996743401,25.2163298203526,0.0025981014660298174,5.083612091783084,25.236964334832642,0.0008179650496978635
0.0008781701344557,28.6843134994752,0.0027881901768968473,5.7827576014941995,28.709503206917805,0.0008777847686579199
0.0009525380651663,32.0310714376616,0.0030243083569030027,6.457464001832579,32.06158225247403,0.0009520846886662096
0.0010256323824858,35.3098093854687,0.003256382814392415,7.11845757211049,35.34602426939383,0.0010251067809457024
0.0010950550130655,38.4592102344858,0.003476799666482962,7.753376783272338,38.50132518545161,0.0010944558776756022
0.001170348675175,41.4568277525965,0.0037158570436806246,8.357696474923454,41.50534669603371,0.0011696643510441802
0.001249548463916,44.4125461129942,0.0039673163729333,8.95356929637963,44.46804174176828,0.0012487684279615925
0.0013344347081336,47.2932803364993,0.00423683019832418,9.53432531583826,47.356390131241824,0.0013335451414297045
0.0014373543139318,50.0953662630651,0.004563599946733465,10.099225838633926,50.167371053871314,0.0014363223090061213
0.0015272217944197,52.7476349488302,0.004848929197282547,10.633923205684168,52.82819228652816,0.0015260567772240302
0.0016201234818234,55.2646563132379,0.005143892054789294,11.141354712748763,55.35419188064588,0.001618812497555136
0.0017335477616637,57.6666728075605,0.005504014143282247,11.625601238004197,57.76664073912865,0.0017320469020336952
0.0018686791220286,59.9737491583006,0.0059330562124408045,12.090707830313402,60.08582085122249,0.001866935313272759
0.0020436034180655,62.2678124214153,0.006488440852357962,12.553190984157325,62.39506313571517,0.002041518101157571
0.0022124551153408,64.4361977066295,0.00702454499120704,12.990337457656508,64.57875990185865,0.002210011240500603
0.0024079904126253,66.4949983965361,0.007645369560085327,13.40539167674168,66.6551177151625,0.002405095849500572
0.0026289243732041,68.4189222376113,0.008346834884923016,13.79325472310244,68.5987904098701,0.002625474795986487
0.0028750045767404,70.1918825556399,0.00912813953115077,14.150683523217007,70.3936845392374,0.0028708796553030946
0.0031497920895255,71.8228544357386,0.010000589884243462,14.479487454244902,72.04908149448744,0.0031448418864384597
0.0034227924370197,73.251751646591,0.010867365987537547,14.767553131952745,73.5024771881254,0.00341694801535068
0.0037220852119493,74.4021450257835,0.011817620547939027,14.999472437197953,74.67907614952126,0.0037151753934346185
0.0040107471779985,75.3916160273813,0.012734122290145236,15.198949791120071,75.69399273860786,0.0040027255728024
0.0043282095463144,76.1418320261385,0.01374206530954822,15.350193336469522,76.4713898303879,0.004318869787300829
0.0046408542835865,76.7534205314852,0.014734712350387135,15.473489579147417,77.10962197193867,0.004630118721318815
0.0049571000101674,77.2750957200944,0.015738792532281495,15.578659297171033,77.65815609787417,0.0049448540428946655
0.005285515036917,77.6443876819,0.016781510242211473,15.653108556671041,78.0547782605249,0.005271595727916451
0.0056538405108402,77.9080393540809,0.017950943621917636,15.706260733782711,78.34851898310113,0.005637917543664687
0.0060071426311062,78.0411620880967,0.019072677853762186,15.733098276960295,78.50996647985717,0.005989171683262973
0.0063728371860796,78.1616902994681,0.02023375806580273,15.757396764372771,78.65980202593539,0.006352616522375468
0.006734174483681,78.2726113737048,0.021381003985687173,15.77975845293889,78.7997127959887,0.006711601215575869
0.0070738822768357,78.3677876647837,0.022459576228953348,15.798945993220396,78.92215216902044,0.007048979741038058
0.007433923619297,78.4128881674646,0.023602707491267975,15.808038254560863,78.99580358887002,0.007406428190968219
0.0077896222274544,78.4168132771086,0.024732050572167718,15.808829556665094,79.02765062881812,0.007759439758924883
0.0081493004644336,78.4291439998824,0.025874028974576677,15.811315430376292,79.06828665950576,0.008116274221265889
0.0085109296740353,78.4492394809904,0.027022201715062078,15.815366679367665,79.11691544119466,0.008474915908222901
0.0088837575005087,78.501374583899,0.02820593006411512,15.825877116114036,79.19876175915896,0.008844529086138055
0.0092543482152229,78.5099936998133,0.029382555583332703,15.82761472988236,79.23655251988633,0.009211789104498635
0.0096233394518673,78.5015324827351,0.030554102759678677,15.825908948519396,79.25697937730824,0.009577330061246099
0.00998817517773,78.4804989467982,0.03171245618929275,15.82166858767452,79.26437591831449,0.009938623039810107
0.0103720683176787,78.4408975974497,0.03293131690862987,15.813684955645861,79.25449194623049,0.01031864748921684
0.0107497828337527,78.3878894133432,0.03413056049716482,15.80299850572999,79.23054220133285,0.010692414682180526
0.0111241226081806,78.3440985245855,0.0353190892809734,15.794170262556438,79.21560788220037,0.011062704617371603
0.011517368782919,78.2750606874751,0.03656764588576782,15.780252234594982,79.17658342791813,0.01145154879105944
0.0119064838728643,78.2562918274453,0.03780308629634415,15.77646843241297,79.18804910403892,0.01183615935520896
0.0123052460590818,78.2048779853817,0.039069156237584717,15.766103401852952,79.16720825201229,0.012230151925728572
0.012689936517166,78.1742254387964,0.04029054844200205,15.759923848461353,79.16625139689334,0.012610094027341366
0.0130720934457665,78.1232471846161,0.041503896690308635,15.749646632418608,79.14448157210012,0.012987390992613111
0.0134635631789456,78.055518662229,0.04274681309315227,15.73599256230537,79.1064240692033,0.013373734787521279
0.0138593554516492,78.0064176200222,0.0440034535589862,15.726093792196478,79.08753628932789,0.013764192838475879
0.0142623273511636,77.9260849061081,0.04528288933994443,15.709898717071395,79.03749223823358,0.014161577185020842
0.0146625175205744,77.8215604118292,0.04655349312782372,15.688826579024767,78.96262040484608,0.014556062151393153
0.0150507117297507,77.7329663936449,0.04778600974195847,15.670966024958812,78.90290286273405,0.014938573540997634
0.0154273925978181,77.64891753763,0.048981971498072464,15.654021775586207,78.84683787327862,0.015309600316992683
0.0158269898205912,77.6060348781905,0.05025069268037705,15.645376631443206,78.83430480222407,0.01570304904639521
0.0162324322937322,77.5311263129059,0.05153797253259973,15.63027506468183,78.78964507143694,0.016102094934629413
0.0166516998809215,77.4345251371867,0.052869147121925766,15.61080026765684,78.7239416101928,0.01651458041424738
0.017066606963025,77.3423112090535,0.054186477107604374,15.592209939745187,78.66228203607038,0.01692260849410848
0.0174743300994206,77.241655133902,0.055480998065660404,15.571917674994642,78.59140131313741,0.017323409612853714
0.0178814742756426,77.1525889624511,0.056773680825165256,15.553961934830143,78.5321909972824,0.01772348136520017
0.018269615632801,77.026611879086,0.05800602963414317,15.52856495482374,78.43385847161386,0.018104731424474847
0.0186999685394812,76.928599235482,0.05937240011285281,15.508805605873173,78.36716162097187,0.01852727373087667
0.0191238765081663,76.8385692465119,0.06071830791342799,15.490655560096798,78.30802055584637,0.018943313592054704
0.0195635353618905,76.7680615502846,0.06211422477400234,15.476441208537377,78.26991623708739,0.019374629210114028
0.0199940746834179,76.7107340369805,0.06348118711985183,15.46488398185527,78.2444941823357,0.01979681814540267
0.0204015023839564,76.6146324621864,0.06477477006906157,15.44550990437678,78.17768606900964,0.02019617963249136
0.0208284441251682,76.5116296988471,0.06613031009740904,15.424744547287576,78.1052479029551,0.020614497762859736
0.0212455423512942,76.4362080686398,0.06745459696535909,15.409539546637784,78.06013676433443,0.021023002287855922
0.0216724145734913,76.3449603201307,0.06880991627083488,15.391144000538349,77.9995399507853,0.02144090671418157
0.0221049338955286,76.2753460034558,0.0701831651183033,15.37710975429669,77.96140748472075,0.021864161555339604
0.0225360558771974,76.1691670436917,0.07155197741010175,15.355704076008246,77.88571964830793,0.022285870784700148
0.0229564491190101,76.0700225109341,0.07288672595285707,15.335716538204313,77.81632011218831,0.02269691433211472
0.0233898799784869,75.9552236478874,0.07426286893169591,15.312573087414098,77.73180721275061,0.023120528712334894
0.0238203127652199,75.8397730171206,0.07562949302957318,15.289298240251515,77.6463001304317,0.023541035404418927
0.0242458389537821,75.7279432568921,0.07698053867825816,15.266753360589448,77.56403077339985,0.023956574906722695
0.024672306116383,75.6340289282077,0.07833457191951601,15.24782023192667,77.5000948427398,0.024372860125129913
0.0251021868832511,75.5423016724123,0.07969944335432223,15.229328017158318,77.43857864658412,0.02479230214144801
0.0255271861792724,75.4659894814311,0.08104881611918986,15.213943479456509,77.39242384512659,0.025206808348848763
0.0259726665178176,75.3272832669393,0.08246321619407088,15.185980306614963,77.2837336749247,0.025641105572864382
0.0264163476754672,75.1950331574479,0.08387190386960836,15.159318684541494,77.18141129680333,0.026073461389907657
0.0268610599040257,75.0427872004313,0.0852838651952816,15.128625899606952,77.05851600278714,0.026506634456411604
0.0273003281611991,74.9644389852934,0.08667854191180714,15.11283089943515,77.01099277001211,0.02693432068050418
0.0277470873871932,74.8576568226851,0.08809700245433841,15.091303615453317,76.93473876814467,0.027369112821699525
0.0281954011145336,74.7747670200297,0.08952039853864417,15.074593031237987,76.88307156940523,0.027805227875455408
0.0286398160475433,74.6880539616918,0.09093141595094997,15.057111678677067,76.82710608810366,0.028237362580479444
0.0290861218725679,74.6020352834457,0.09234843694540308,15.039770313142654,76.77191917364162,0.028671148075232102
0.0295257725963302,74.5238054412559,0.09374432799334838,15.02399917695719,76.72417837372758,0.029098281263015387
0.029978032965834,74.4073731826992,0.09518025466652295,15.00052643363216,76.63795986887126,0.029537474796479075
0.0304362583669855,74.3002864660378,0.09663512031517896,14.978937751553222,76.56170918165917,0.029982264381402505
0.0308993177521654,74.1883280025892,0.09810533386312513,14.956366925321984,76.48069672304308,0.030431545321714958
0.0313467986287202,74.1056109485358,0.09952608564618663,14.939691167224817,76.42858461219782,0.030865519598619346
0.0318054727628134,73.9987691349062,0.10098237602193252,14.91815185759709,76.35233497110818,0.03131015390701246
0.0322575210331055,73.824984844397,0.10241762928010996,14.883116944630434,76.20639584578383,0.03174817181526268
0.0327222559531407,73.7007751666241,0.10389316265122171,14.858076273591418,76.11243079557124,0.03219828269098234
0.0331685071728769,73.5744371536365,0.10531001027388415,14.832606530173118,76.01479140010727,0.03263030091250896
0.0336292160838862,73.5028470937209,0.10677276106633868,14.818173974094135,75.9746902214165,0.0330761199817443
0.034082951777566,73.4035413866751,0.10821337189377203,14.7981539435537,75.90535074805972,0.033514997024705284
0.0345368020771205,73.3043854685721,0.1096543465948576,14.778164110464134,75.83608452088511,0.033953792318998234
0.0350082248302878,73.2004868061019,0.11115111383616376,14.757218140110144,75.76310590589644,0.03440937338168788
0.0354772650050734,73.1185612933867,0.11264031639110804,14.74070195674676,75.7126078691819,0.03486244604035825
0.0359505955938245,72.9491402357308,0.11414314101039277,14.706546671523329,75.57170527526274,0.035319455049450506
0.0364257129460158,72.8515878718797,0.11565163860360016,14.686880114970947,75.50525889936223,0.035777979264920136
0.0369029964483736,72.7323456848777,0.11716701372358618,14.662840890071346,75.41638717936863,0.036238382392148466
0.0373794310371832,72.6368893268994,0.11867969354305664,14.643596888302918,75.35201492224974,0.03669775532119102
0.0378771175016491,72.5471696712656,0.12025984806773589,14.625509405727145,75.2950473413162,0.03717739382598939
0.0383541299383942,72.4425160328404,0.12177436255440159,14.604411232220626,75.22098570582817,0.03763689220385687
0.0388308954663968,72.3755763904867,0.12328809310580983,14.59091620032212,75.1859848316259,0.03809594186052558
0.0393097351809492,72.2883293232297,0.12480840919951369,14.573327191563108,75.12996440559911,0.0385567766240301
0.0397667170537203,72.1793319944321,0.12625932664556194,14.551353330077514,75.04966706698123,0.03899637746664383
0.0402389276291354,72.0824715383363,0.12775859522250488,14.5318262621286,74.98299289389664,0.03945042487246198
0.0407210979789065,71.9988400032605,0.12928948608302815,14.514966144657317,74.93071182140089,0.039913836329161165
0.0412113880693141,71.9132488030043,0.13084615712007225,14.497710958685666,74.87689360675004,0.040384831524977426
0.04170410301691,71.8014524586858,0.13241052707868925,14.475172815671058,74.79586762878661,0.04085793277070215
0.0421965909696535,71.6767673679416,0.13397417632864986,14.450036301377025,74.70128260259364,0.04133059249324403
0.0426869835073373,71.5482911776358,0.13553117263579592,14.42413550141138,74.60247190311371,0.041801019286117125
0.04317557964668,71.4095860654596,0.13708246537820898,14.396172550796658,74.49273633616531,0.04226950283523465
0.0436642517276727,71.2918142099954,0.13863399923536082,14.37242974473507,74.4047179317831,0.04273783977473321
0.0441539777256316,71.2276226404345,0.14018887927888032,14.359488724311596,74.37260550394994,0.0432069668280676
0.044652002083208,71.1303315726229,0.14177010661418538,14.339874845040775,74.30644328618293,0.043683817595278514
0.0451522726245738,71.0508617671085,0.14335846558302182,14.323853732249075,74.2589696478279,0.04416259023152648
0.0456588030733326,70.9377061574226,0.144966699757831,14.301041561336397,74.1766369133383,0.044647120340015174
0.046170497993482,70.8128267599327,0.14659133112930536,14.275865874802433,74.08229023576497,0.04513635235344427
0.0466834321367135,70.7027103445899,0.14821989703406535,14.253666405469327,74.00335552484329,0.045626529088779025
0.0472088141933123,70.5884101848683,0.14988798506376655,14.230623493269448,73.92080532548705,0.04612835249305875
0.0477303173334082,70.5090141085203,0.15154375753357102,14.214617244277692,73.87443172678574,0.046626221994869266
0.0482510169254416,70.4239950415556,0.15319697873827706,14.19747740037761,73.82202441826291,0.04712307718554707
0.0487699951128684,70.364916688888,0.15484473448335714,14.185567204479822,73.79661333192246,0.047618044279384514
0.0492731614398185,70.276987241032,0.15644228757142373,14.167840627792053,73.73975657886344,0.048097697269386605
0.0497899888306781,70.1835766075878,0.15808321453740296,14.1490090440897,73.67801610297663,0.04859013352718752
0.0502995226862532,70.0833586241508,0.1597009845288539,14.128805098628803,73.6085181111951,0.04907538319181286
0.050807631667476,69.958733656849,0.16131423054423627,14.103680705220759,73.51317122840923,0.0495590415241114
0.0513271139734223,69.8532529825233,0.1629635868656158,14.082415801276698,73.43861885977158,0.05005328416730868
0.0518583306965929,69.7402415242233,0.16465019996168245,14.059632691283417,73.35685403204673,0.050558438608932624
0.0523718282455417,69.6732145627266,0.16628055467959488,14.046120055845684,73.32212818912049,0.05104650076977531
0.0529027139165558,69.5884355328577,0.16796611668506467,14.029028603424113,73.26985262975316,0.05155083944070409
0.0534116541260984,69.4983230906806,0.1695820018503624,14.01086193508121,73.21034348594388,0.05203409134950636
0.053926793986135,69.3880200375592,0.1712175709059786,13.988624839571935,73.12989349923046,0.052522992285906824
0.0544110688293108,69.286478535275,0.1727551435330618,13.968154072711439,73.05642988779842,0.05298238246262735
0.0549308514137884,69.1912659937603,0.17440545323877818,13.948959224342078,72.99200114519546,0.053475221096335936
0.0554594769484013,69.0985158678241,0.17608383931117413,13.930260798953341,72.93068341576445,0.05397619528918025
0.0559966109378501,68.9457226426065,0.17778923972767405,13.899457684749471,72.80644944925345,0.05448497593976261
0.0565603755964698,68.7966948959865,0.17957919251879162,13.86941369103088,72.68786179909924,0.05501870324330653
0.0571130824066795,68.6248282724333,0.1813340366412074,13.834765379722555,72.54420374470101,0.05554168546718261
0.0576642449218822,68.5361325892558,0.18308397762697598,13.81688432999397,72.48821692488124,0.0560629342252051
0.0582212551089163,68.4962850770863,0.18485248497080925,13.808851071540598,72.4842247645724,0.05658943738418332
0.0587595536467579,68.4500614565344,0.18656158282845633,13.799532389637337,72.47215651481352,0.05709799045865321
0.059316936822466,68.383821044461,0.18833127441132955,13.786178322563337,72.44013983703411,0.05762430118546827
0.0598637789101547,68.3111414243108,0.19006749803974116,13.771526111141059,72.40050449163606,0.05814038940368052
0.0604127585109762,68.2236194710377,0.19181050827234944,13.7538816853612,72.34519651888623,0.05865822715116317
0.0609835914405773,68.1421098934934,0.19362290282383293,13.73744935452827,72.29766048313711,0.05919639432901403
0.0615445522850169,68.040515763513,0.19540395350492865,13.716967977924222,72.22803884342004,0.05972497234496047
0.062102540416542,67.9256809964725,0.19717556582252083,13.693817288888853,72.14403834587706,0.06025047222324398
0.0626520873130806,67.7739379473277,0.19892037721903089,13.663225890181264,72.02011662515498,0.06076775257328588
0.0631978315459663,67.6652183075774,0.20065311515844297,13.641308010807604,71.94151337570071,0.06128118886061082
0.0637568950232444,67.5645494140702,0.20242814169880097,13.62101316187655,71.87225529835588,0.061806882692425284
0.0643120736298147,67.4903338431091,0.20419083377466166,13.606051302770796,71.8307771625279,0.06232865019840691
0.0648843731648074,67.413123894808,0.20600788479826349,13.590485777193292,71.78718218180411,0.06286622346895838
0.065452853850744,67.3044173726133,0.20781281097611218,13.568570542318842,71.70968356641244,0.0633999236664868
0.066021833846971,67.197471374412,0.2096193224641329,13.547010229081462,71.63397166443002,0.06393380756670457
0.0665966049367945,67.0935855145501,0.21144422067432256,13.526066839733302,71.56179052285563,0.06447283610860176
0.0671704891578808,66.968416239552,0.21326630307627154,13.500832713893683,71.46671751649127,0.06501074320868971
0.0677376493210613,66.8734279877673,0.21506703659436963,13.48168308233389,71.40327680169993,0.06554206365878372
0.0683005042282989,66.7656413951835,0.21685410092484902,13.459953305268995,71.32576836760032,0.06606907196088686
0.0688702997326698,66.6682366313914,0.2186632016512266,13.440316504888505,71.25969807084388,0.06660229608767687
0.0694366375451073,66.5745623555502,0.22046132420571568,13.421431770878922,71.19727611155668,0.06713200285316188
0.0700254178908002,66.4911782273373,0.22233070180329065,13.4046215306312,71.14725076875827,0.06768240322979938
0.0706146408298012,66.3949105020874,0.2242014846346188,13.38521395722082,71.0833632601191,0.06823291423372228
0.0712067299579365,66.2979141619727,0.2260813676164484,13.365659495053697,71.01877183247873,0.06878579800945936
0.0717991946019207,66.1618881018853,0.22796244286109824,13.338236641340076,70.91225838094306,0.06933872663395724
0.0723876901440318,66.0693691315306,0.22983091620730098,13.31958481691657,70.85197815223552,0.06988764852231938
0.0729761706554681,65.9602048334143,0.2316993418311112,13.297577294416321,70.77372799780717,0.0704362552523465
0.0735789849256624,65.9094800803275,0.2336132771389781,13.287351184194025,70.75903272161615,0.07099791264509855
0.0741719782095918,65.826410206545,0.23549603081545395,13.270604297639473,70.70888527000051,0.07155011195421397
0.0747612892833395,65.7253738167639,0.23736709347460289,13.250235361459604,70.63908750193463,0.07209858044082108
0.0753619322228929,65.6395706884597,0.23927413480768497,13.232937450793475,70.58629556582319,0.0726572860528249
0.0759541208833386,65.527587375668,0.24115433380460002,13.210361614934671,70.50467766839301,0.07320782224628453
0.076561935216563,65.4281559574016,0.2430841443125875,13.190316241012162,70.43746219515135,0.0737725700423873
0.0771490443282312,65.3259052095125,0.24494821574213407,13.16970249023772,70.36573636630301,0.07431777701935648
0.0777621293126966,65.2318353283496,0.2468947605678117,13.15073800219528,70.30440174245726,0.07488678887330807
0.0783453291628064,65.1150691626501,0.2487464200919103,13.12719794319026,70.21653068965684,0.07542776363970038
0.0789604215984985,65.011177523505,0.25069933857523274,13.106253388738608,70.14448750937578,0.07599800497164204
0.0795707558804214,64.89248776984,0.2526371499203379,13.082325534399745,70.05603207264717,0.07656351387376602
0.080165919769409,64.7527658817536,0.25452679526787353,13.054157601761526,69.94373091627759,0.07711465875245745
0.0807801252898929,64.6862902670257,0.25647689779540994,13.040756117832382,69.91165689933442,0.07768311860681451
0.0814022546790975,64.6038787118675,0.2584521586061345,13.024141948312488,69.86278010002846,0.07825858292669502
0.0820220301673697,64.5405483657381,0.26041994578139877,13.011374550532803,69.83429517081126,0.07883154081532406
0.0826427207844769,64.4407664426054,0.26239063849071415,12.991258514829246,69.76632671085932,0.07940501588470368
0.0832456930109314,64.3341186050268,0.2643050753097072,12.969758310773404,69.6896568925497,0.07996180564191499
0.0838675589747407,64.2343075020254,0.2662794997448017,12.949636392408323,69.62148207465314,0.08053571748552393
0.0844898625677719,64.1448871093299,0.26825531365267574,12.931609241240908,69.56447980562243,0.08110970367796073
0.085107974500716,64.0170036341226,0.27021781903977327,12.905827932639118,69.46536114702775,0.08167949770992981
0.085725825428789,63.9141581239774,0.27217949573640504,12.885094277793844,69.3932520857415,0.08224872686489888
0.0863516118824598,63.8292349427227,0.27416636772680986,12.867973764452898,69.34099226525103,0.08282493695781339
0.0869720102188049,63.7525216663365,0.27613613244470553,12.852508367933439,69.2972066321757,0.08339585823882988
0.0875813525432261,63.653424328434,0.27807079432474285,12.832530344612294,69.22827732512614,0.08395628811910262
0.0881780919507636,63.5227259013717,0.27996544194367445,12.806181541716535,69.124038666866,0.08450482249316711
0.0888011527909113,63.3915987522775,0.28194366011114336,12.779746308459144,69.02084579873865,0.08507723112651999
0.0894372563765566,63.2930814685915,0.28396328899556716,12.759885224068048,68.9538410227602,0.0856612843697741
0.0900792414621708,63.1984967902956,0.2860015916423923,12.740816952923593,68.89136944271486,0.08625039218778542
0.090751868245616,63.0982866332994,0.28813718167983077,12.720614585273161,68.82457402836872,0.08686724582838104
0.0914042029553338,62.9918181109743,0.2902083443831848,12.699150531172421,68.74953503811525,0.08746512673869616
0.0920574534416732,62.8781416099249,0.29228241467731236,12.676233348560862,68.6665432036795,0.08806348898052099
0.0926905013653132,62.7589205086456,0.2942923418348694,12.652198374542955,68.5760763157378,0.08864300474568192
0.0933188517796296,62.6656362163166,0.296287354400324,12.633392261209426,68.51352143406324,0.089217888316713
0.0939516569821818,62.5542974904461,0.2982965109184272,12.610946374073935,68.43137739102986,0.08979651379323558
0.0945694737955042,62.4830880286127,0.30025807930072584,12.59659054656832,68.39208078459677,0.09036111133908123
0.0952047798500691,62.3854218113073,0.30227517602396936,12.576901037159553,68.32481216070651,0.09094135934531479
0.0958479468646144,62.285471375614,0.3043172312951507,12.556751029323783,68.25540592646131,0.09152844428870904
0.0964953682116878,62.1520642441732,0.30637279407210877,12.529856151625317,68.14945056853117,0.09211906470973659
0.0971541290933737,61.9974755200629,0.3084643598714615,12.498691064844682,68.02078626020237,0.09271967196472247
0.0977928325593336,61.850083200363,0.31049224337588416,12.46897677319318,67.89857803055695,0.09330164819936108
0.0984323105223099,61.7583309534981,0.3125225859083339,12.450479520225217,67.83734616325242,0.09388399102797555
0.0990630807277064,61.6506208931118,0.3145252813104678,12.42876517205134,67.75792132755936,0.0944580720706313
0.0997191856670491,61.5448972054382,0.31660841449288085,12.407451276616342,67.68210423672674,0.09505486145614113
0.100366793468588,61.4780468978902,0.3186645692627669,12.393974254614665,67.64840133374291,0.09564357283050041
0.101030903997437,61.3876139495785,0.32077312019186244,12.375742972235026,67.5896600811501,0.09624692637244359
0.101671140202145,61.234163492305,0.3228058701418104,12.344807360048687,67.45991071389221,0.0968282453251577
0.102308175696851,61.1098408901724,0.3248284578375019,12.319743923458757,67.36187722877077,0.09740632290315533
0.102940707132575,60.9827386575262,0.3268367451459256,12.294120113357282,67.26034489781296,0.09797998282698117
0.103582639579424,60.8702799317632,0.3288748806646712,12.271448434243462,67.17538419903367,0.0985618325190916
0.104251360522925,60.7897891615393,0.33099806966028683,12.255221494966323,67.12720738753153,0.09916760357245831
0.104927952483599,60.664462460126,0.3331462491354268,12.229955631961403,67.02986029458519,0.09978013147170575
0.105606144200121,60.5055787837403,0.33529950783538415,12.197924682802045,66.89533966168776,0.10039373136036427
0.106274128537608,60.350505875376,0.33742035810690535,12.166661984475802,66.76420329408538,0.10099772820958582
0.106945237254758,60.2148683972853,0.33955112828385664,12.139317468892717,66.654561784297,0.10160418299494627
0.10760024327393,60.1229466772705,0.3416307723947277,12.120786050137733,66.59219036609032,0.10219573195524694
0.108262557104118,60.0827079217995,0.3437336188055746,12.112673917034781,66.58741551915337,0.10279352514875921
0.108902841302971,60.00066652422,0.3457665211369329,12.096134371282753,66.53490958877961,0.10337109524534478
0.109553395739952,59.8740929778832,0.3478320314743476,12.070617144341254,66.43350318045992,0.10395758818107743
0.110204188660228,59.7423429732325,0.3498982989962239,12.044056343403673,66.32619940925866,0.10454395215477995
0.110847219767692,59.6069343201131,0.3519399227624221,12.0167579589348,66.21419726837306,0.10512298524063299
0.111505563159844,59.4471485086397,0.3540301630325047,11.984545139341762,66.07583628134245,0.1057154595016662
0.112165193101571,59.2972264376254,0.3561244880974879,11.954320849825281,65.94831129138923,0.10630873974265306
0.112830268499883,59.1205449152753,0.3582361024871285,11.918701854919503,65.7911318719252,0.10690656156260493
0.113497623044077,59.0092350700735,0.3603549531649444,11.896261790126818,65.70664298817603,0.1075060730422183
0.114153242225982,58.8715701658877,0.3624365440674928,11.86850854544296,65.59195077525817,0.10809469239101825
0.114816945791272,58.7822911057995,0.36454380288728855,11.850509886929181,65.53149423718085,0.1086902172557951
0.115485616547783,58.6437955910612,0.366666832539211,11.822589191157938,65.41631048159707,0.10928984063231563
0.116152707617305,58.5186239539582,0.3687848466849434,11.797354589117973,65.31572057224932,0.10988768938062564
0.11681636863294,58.393460143296,0.3708919704095845,11.772121564888474,65.21477210914814,0.11048210964576491
0.117480641414465,58.2670957377234,0.37300103649092636,11.746646500725037,65.11235151834919,0.11107672423649281
0.118139530234124,58.1235727662455,0.3750930084933437,11.717712269675093,64.99026434837866,0.11166617037505629
0.118798133865071,57.983231613002,0.3771840750216004,11.689419493181203,64.87153132409283,0.11225501436525524
0.119476003338642,57.8691068631872,0.37933631060018835,11.66641194361854,64.78307646797758,0.11286072166717014
0.120147308715394,57.7302808584844,0.38146770517137596,11.638424621070456,64.66641873501511,0.11346020229700926
0.120839638594118,57.5735971993221,0.3836658525363246,11.606837195383337,64.5307698774515,0.11407808175550536
0.121512841891433,57.4421440955047,0.3858032730052997,11.58033624965375,64.42210226888668,0.11467852555138472
0.122179297453941,57.291722234597,0.38791926941626265,11.550011202494757,64.2915846071464,0.11527259598593452
0.122839525776481,57.1830619466681,0.3900154943403271,11.52810528844829,64.20740215864394,0.11586076775068031
0.123481481885236,57.0233106534203,0.39205370498562425,11.495899427729533,64.06463355490682,0.11643232998425421
0.12414760052366,56.8957543927255,0.3941686316626205,11.470184085573461,63.95922578056585,0.11702506004201989
0.124823212035749,56.725769169945,0.39631369821350304,11.435915064660913,63.806461882936006,0.11762587845072478
0.125502491859123,56.5716118134241,0.39847041165271546,11.404836941586298,63.67149006449582,0.11822959536408524
0.12617418115744,56.4171669100049,0.400603025174872,11.373700849056988,63.535556748097385,0.11882620794731273
0.126852789628915,56.243190375655,0.4027576070718051,11.338627179732049,63.377795972436985,0.11942860507863474
0.127533980827543,56.0590906472481,0.404920389127449,11.301512674485217,63.208529639063734,0.12003293014679638
0.128198364360551,55.881765970987,0.4070298068447494,11.26576401975098,63.04571696604662,0.12062199254476794
0.128879217231628,55.6905032855746,0.4091915147104189,11.22720546237184,62.86785175625486,0.12122529736448799
0.129559574726497,55.5674440788469,0.41135164975662797,11.202396726295536,62.76673850234071,0.12182779987008878
0.130242398003352,55.4064339254356,0.41351961366064255,11.169937079367816,62.62270074469861,0.1224321212273367
0.130915448326613,55.2443126536461,0.4156565484369963,11.137253430975054,62.47664661219376,0.12302743600753292
0.131601787753312,55.0686051058661,0.41783567611676553,11.101830789342605,62.31573198687924,0.12363414028965454
0.132282224279245,54.9000544523559,0.41999606208660284,11.06785097759495,62.16235576836521,0.1242352634415528
0.132958661420262,54.7372027075125,0.4221437500093318,11.035020065834521,62.01498790939291,0.12483249543166365
0.133647834338547,54.5786635677414,0.42433187402488665,11.003058575256667,61.872983754662194,0.12544060534470977
0.134328901325418,54.4033869466245,0.42649426170820215,10.9677228084395,61.71133414354616,0.12604119969529
0.134998424556848,54.2268847395279,0.42861999796799233,10.932139963488824,61.54742874798995,0.12663126287676219
0.135691446043469,54.0431175324957,0.43082034118801404,10.895092494551134,61.376306299177195,0.12724166900673345
0.13637713941321,53.8665067473124,0.4329974176369417,10.85948776025818,61.21266684769324,0.12784525412291123
0.137068808957706,53.6579099286141,0.43519346844071655,10.817434641608605,61.0127357336891,0.12845373092996443
0.137741266965548,53.42204290852,0.4373285226156149,10.769883850357633,60.78046278262741,0.1290449521791994
0.138424584242017,53.175997279389,0.439498054968404,10.720281051524823,60.53686259444306,0.12964536299428492
0.139108550838417,52.9781660212902,0.44166964891197397,10.680398269892105,60.34788192258894,0.13024598355731976
0.139795712098979,52.7921759791017,0.4438513859142583,10.642902677386903,60.172295813354836,0.1308490464350049
0.140486250692842,52.6563523356534,0.44604384594977337,10.615520630867728,60.05384585045062,0.13145470716138838
0.141161983592054,52.4706899646509,0.44818929790477147,10.578091096873623,59.8775566405047,0.1320470271420186
0.141868504086246,52.2258636697954,0.450432500473831,10.528734115830753,59.6350688232415,0.132665959320594
0.142550020816133,51.9786539953899,0.45259631609122225,10.478896645470604,59.388212204427305,0.13326262472378234
0.14324406981568,51.7530216764494,0.45479992166478395,10.4334091699722,59.16633512664312,0.1338698964143697
0.143936775758783,51.5533322921844,0.456999263034136,10.393151790104376,58.973752721942574,0.13447562548526784
0.144676718514807,51.3658077321954,0.4593485812845122,10.355346838810592,58.79724423875193,0.13512225523175678
0.145415111358952,51.153231160494,0.46169297856467256,10.31249140195559,58.59168396606744,0.1357671139750619
0.146149238962621,50.9387486378767,0.46402383370632166,10.269251725395943,58.383407985010635,0.13640783578475574
0.14685183640154,50.7176175931973,0.4662545805748895,10.224671706788577,58.165592874669386,0.1370206549137617
0.147579319356436,50.4985392806298,0.4685643389566843,10.180505518974968,57.951079336159395,0.1376547841858022
0.148301865141522,50.254174037148,0.4708584218243323,10.131241485889037,57.706961778003695,0.13828421206196534
0.14900915114732,50.0198279606251,0.47310405489274093,10.083997316862021,57.473240065572824,0.1388999632799156
0.149726567756134,49.7837149666784,0.4753818526257254,10.036396937282365,57.237659738788835,0.13952414693548487
0.150430896181448,49.5367960988758,0.4776180953760974,9.98661809353336,56.98866072998734,0.14013656452721088
0.151197181520486,49.2919244988491,0.48005105132754305,9.937251978967979,56.744724554795674,0.14080242829101733
0.151922452541798,49.0390769840612,0.48235378682020863,9.886277919986737,56.48921382986581,0.1414322445059979
0.152672569030227,48.7998513500577,0.4847354066709707,9.838050032171633,56.250250023964206,0.14208321919603875
0.153374726053981,48.5512406797657,0.48696475522138966,9.787930121040766,55.99777391860566,0.1426921893996855
0.154050801848648,48.2758066553278,0.4891112958694574,9.732402621714085,55.71273338047134,0.14327818951612545
0.15475835222968,47.9881954606792,0.491357768329234,9.674420204872927,55.41476951664973,0.1438911032356785
0.15548068317284,47.6941325545454,0.493651169073767,9.615137122996353,55.1096488674621,0.14451643330380476
0.156175310545717,47.4270340202176,0.4958566109826515,9.561290058475867,54.83396578658737,0.14511741147328283
0.156878603894124,47.1122248100977,0.4980895673638437,9.497824521715696,54.50312486465193,0.14572551953828658
0.157577174464128,46.8130279320426,0.5003075289236064,9.437506431099788,54.18969260168417,0.14632917815881377
0.158298934544685,46.4938947157575,0.5025991171793748,9.373169174696711,53.853828712094675,0.1469524931117318
0.159013382409007,46.2159247197957,0.5048674891485972,9.317130423510813,53.56487523065045,0.1475691108043338
0.159733946808235,45.9317983384454,0.507155281116146,9.259850545030593,53.268665771045214,0.14819062261232033
0.160460059529037,45.6364904770721,0.5094606890046924,9.200316480177737,52.959324455719425,0.1488165295343483
0.161197861752404,45.3089402623118,0.5118032110638827,9.134282356882059,52.61264455086386,0.14945211175465814
0.161954627046886,44.9949381991695,0.5142059408738631,9.070979540952573,52.28207663421369,0.15010361037551775
0.1626894359735,44.6754358961265,0.5165389592158625,9.006567876659103,51.94365736393758,0.15073580087966945
0.163403606635346,44.3662145285029,0.5188064510672236,8.944228848946185,51.615813995217756,0.15134985257167338
0.164119299322693,44.0691158452045,0.5210787753495503,8.884333754393227,51.30170825949005,0.15196483488447593
0.164834924004305,43.740467172948,0.5233508837136683,8.818078182066317,50.950423755313686,0.15257938084417455
0.165563916144291,43.4301420567132,0.5256654337581239,8.755516638633381,50.62060645432551,0.15320501809665288
0.166299451181978,43.0877876174551,0.5280007575027801,8.686497983678949,50.25326305088351,0.15383587415141764
0.167052265759786,42.7328561508759,0.5303909437873204,8.614943800016581,49.87147659326672,0.15448113872808866
0.167812514867029,42.3136859828702,0.5328047347028171,8.530439094146631,49.4144520409494,0.15513235342833034
0.168607420915788,41.816730599546,0.5353285614076269,8.430252888868473,48.86734169706576,0.1558128013797071
0.169371602600704,41.405296450932,0.5377548382572351,8.34730776450789,48.41817786698359,0.15646651272993153
0.170103039238018,41.1036030957463,0.5400771495807072,8.286486384102455,48.095450905965954,0.1570918126567321
0.170842634604239,40.8475251821007,0.5424253648684588,8.234861076711502,47.82602400127379,0.15772369010616924
0.171629147030693,40.5771294013478,0.5449225418224503,8.180349287311715,47.54134750945517,0.15839521363287828
0.172409038465903,40.2179123679231,0.5473986971292419,8.107931133373297,47.151843968382664,0.15906063919532248
0.173160135772721,39.8057416520247,0.5497834310783891,8.02483751704818,46.698509281023156,0.15970107848889786
0.173883955372624,39.4018792462833,0.5520815583080811,7.943418856050713,46.253233858741545,0.16031787101152722
0.174568590747763,38.9509646251001,0.5542552756241474,7.85251446842018,45.75057962796979,0.16090092336714346
0.174929881562,38.7371944503188,0.55540237395935,7.809418401184271,45.51348728755723,0.16120847054909973