File: example/data/02 processed data/test_ID_087.csv
Strain,Stress_MPa,Displacement(mm),Force(kN),True Stress (MPa),True Strain
0.0024181879273480456,139.948060973625,0.0076777466693300446,56.427058184565595,140.28648168512717,0.002415268815948142
0.0025309842868977456,146.510600607148,0.008035875110900342,59.07307416480207,146.88141663514864,0.0025277867403244304
0.0026441366382896456,153.024416048495,0.008395133826569624,61.69944455075319,153.42903351352172,0.0026406470589382717
0.0027557726676433456,159.456009415549,0.008749578219767622,64.29266299634936,159.89543392798785,0.002751982487797999
0.002881495152389046,165.817561756351,0.009148747108835219,66.85764090016073,166.2953642567329,0.002877351603068836
0.0030056848563170457,172.128867273973,0.00954304941880662,69.40235928486591,172.6462324036734,0.0030011768164951223
0.0031218494589316456,178.345769669256,0.009911872032107975,71.90901433064401,178.90253831380068,0.0031169866050127955
0.0032390292427870457,184.565717326551,0.01028391784584887,74.41689722606537,185.1635310821877,0.0032337948873439014
0.0033561715081096457,190.701920278545,0.010655844538248124,76.89101425630935,191.34194862992564,0.0033505521340589303
0.0034680909315167457,196.726971167141,0.011011188707565667,79.32031477459124,197.40923819183053,0.0034620909724294943
0.003585922893729146,202.546466870001,0.011385305187590037,81.66673544198441,203.2727828825941,0.003579508801283219
0.0037031467438299456,208.21826736533,0.011757490911660076,83.95360540170107,208.98933016412985,0.0036963069765009525
0.003814747532690946,213.634265851743,0.012111823416293752,86.13733599142279,214.44922664029917,0.0038074898349890344
0.003937702838793645,218.843186521414,0.012502206513169823,88.23757280543413,219.70492595823004,0.003929970379075836
0.0040608263817699455,223.811531492222,0.012893123762119577,90.2408094976639,224.72039126384993,0.004052603479985788
0.004187496676659746,228.487531309983,0.013295301948394693,92.12617262418514,229.44432208800174,0.004178753511934984
0.004321982651138246,232.980815407088,0.01372229491736393,93.93786477213787,233.98775444932548,0.004312669708063178
0.004459271361885345,237.276157473484,0.014158186573985971,95.66974669330875,238.33423624736372,0.004449358270530226
0.0046020595249353455,241.379648033193,0.01461153899166972,97.32427408698342,242.49049154154972,0.004591502426206562
0.004760318065563646,245.323262337328,0.015114009858164575,98.91433937441064,246.49107909493537,0.004749023580897566
0.004928436242972746,249.117658802929,0.015647785071438467,100.44424002934096,250.34541930133784,0.004916331257213985
0.005119084653834745,252.79785794312,0.016253093775925317,101.928096322666,254.0919515782389,0.00510602668426405
0.005336515338801546,256.3075224107,0.016943436200694908,103.34319303599425,257.67531143549496,0.005322326597393643
0.005579396303422746,259.488298581101,0.017714583263367216,104.62568198789992,260.9360866349858,0.005563889125588882
0.005849940849604946,262.324960144269,0.018573562197495702,105.76942393016927,263.859545644488,0.005832896386064222
0.006149815706053846,264.736807656913,0.01952566486672096,106.74188084726734,266.36489023461206,0.006130982762757135
0.006473555892720446,266.746680584118,0.020553539959387416,107.55226161151637,268.47348013007695,0.006452692421928696
0.0068176665693558455,268.322603674766,0.02164609135770481,108.18767380166567,270.151937719642,0.006794531373141511
0.007176371496796446,269.429556415734,0.022784979502328714,108.63399714682396,271.3630830047904,0.00715074387869399
0.007539991953450845,270.207620859523,0.023939474452206434,108.94771273055967,272.2449841465649,0.007511708297506622
0.007911420753612945,270.746632235455,0.0251187608927211,109.16504211733547,272.8886227606934,0.00788028955133899
0.008286059942275544,271.177536809999,0.02630824031672485,109.33878284179161,273.42453013500534,0.008251919013791442
0.008668306893344645,271.521651417233,0.027521874386369247,109.47752985142834,273.8752844199053,0.008630952830253119
0.009051826566774647,271.835313404357,0.0287395493495095,109.60399836463675,274.2959195160181,0.009011104340553118
0.009432454782049845,272.133749081427,0.029948043933008255,109.72432762963138,274.7006383643073,0.009388246955240643
0.009815059523601444,272.397164245371,0.031162813987434583,109.8305366237336,275.0707586264996,0.009767204704025553
0.010197516311968646,272.660579409315,0.03237711429050045,109.93674561783581,275.44104011547233,0.010145872438585621
0.010581829376605047,272.928562466276,0.03359730827072102,110.04479638640248,275.81664594629626,0.01052623367900476
0.010961914139370147,273.182841844187,0.034804077392500216,110.1473218315762,276.17744870083214,0.010902267854335275
0.011336833691511845,273.42646280506,0.035994446970550105,110.2455498030002,276.5262531407393,0.011273053384256772
0.011715277896834346,273.685310075988,0.03719600732244905,110.34991702263837,276.8916095398095,0.011647185328331878
0.012097565718656045,273.919795250829,0.03840977115673294,110.44446144513427,277.2335579755167,0.012024975031144004
0.012476405794353045,274.1908235698,0.039612588397070915,110.55374006334335,277.61173954974464,0.012399216807882325
0.012855488854899746,274.394856124531,0.04081617711430669,110.6360059894109,277.9223361392817,0.012773558480943508
0.013230824499058744,274.649135502443,0.04200786778451151,110.73853143458503,278.28297001309403,0.013144061599175628
0.013606444123689644,274.862303843207,0.04320046009271462,110.82448090958106,278.60220242215814,0.013514707664102548
0.013985449082592846,275.113537959107,0.044403800837232284,110.92577850511196,278.96112433616605,0.01388855504886208
0.014354939748322644,275.325183668866,0.045576933700924395,111.01111405528677,279.2774600916284,0.014252883119092816
0.014721029395566545,275.545965164657,0.046739268330923775,111.1001331543897,279.60228541767566,0.014613726830006925
0.015072755772846846,275.791108756536,0.047855999578788735,111.19897505063533,279.9480407831459,0.014960290489202988
0.015435648248901347,276.051478658469,0.049008183190261775,111.30395619509471,280.3125121816302,0.015317730506884567
0.015795616826106345,276.264646999233,0.05015108342288764,111.38990567009074,280.62841750583243,0.015672164378756053
0.016152154227466846,276.459543767932,0.05128308967220723,111.46848804723018,280.9249609565268,0.016023096041565984
0.016496609041533546,276.659008429647,0.05237673370686901,111.54891219883366,281.22294392952915,0.016362018164845192
0.016846899362428946,276.866086246389,0.053488905475711904,111.63240597454404,281.5304213382515,0.016706564300717392
0.017200420795763848,277.092958266202,0.05461133602655022,111.72388077293265,281.85907374792373,0.017054168246201935
0.017560809170986846,277.26806083183,0.055755569117883236,111.79448212739386,282.1371123373073,0.0174083998618666
0.017910462711965048,277.478183910583,0.05686571911048902,111.87920375274707,282.4479465768973,0.017751960146157857
0.018260185810881745,277.660899631238,0.05797608994954954,111.95287473131518,282.731039250921,0.018095470747893833
0.018614569765449746,277.895384806079,0.05910125900530294,112.04741915381105,283.0682878340483,0.01844343908239619
0.018974218701353147,278.113121039859,0.06024314437679624,112.13521040327115,283.39010022218514,0.018796453333037783
0.019331398782847748,278.323244118612,0.061377191135541596,112.21993202862437,283.7036217412048,0.01914692097840647
0.019684660621054846,278.521186149322,0.06249879747184913,112.29974225540661,284.003781174445,0.019493423243665448
0.020042067032630347,278.722173442042,0.06363356282860134,112.38078033183135,284.3083419256478,0.019843868634597406
0.020396723617118646,278.929251258784,0.0647595974843517,112.46427410754171,284.6184941054393,0.020191496399453716
0.020753646658341646,279.154600647592,0.06589282814023473,112.55513498110909,284.9480765924826,0.020541223739544354
0.021102931991775247,279.349497416291,0.0670018090738864,112.63371735824855,285.2445908622036,0.02088334898035984
0.021456363859484746,279.56418838806,0.06812395525386407,112.7202807580658,285.5626193361958,0.021229416653356776
0.021803696109955546,279.734723060671,0.06922673514910885,112.78904033806255,285.8339739536884,0.02156939516184045
0.022150751176707846,279.952459294452,0.07032863498604741,112.87683158752304,286.15361656159087,0.021908986947311356
0.022496844634061847,280.156491849183,0.07142748171314636,112.95909751359059,286.4591289195379,0.022247522997600435
0.022843247010833647,280.360524403915,0.07252730925939682,113.04136343965853,286.7648691149605,0.02258624650035569
0.023183427895378746,280.538672231553,0.07360738356782752,113.11319264376218,287.0425203110985,0.022918774802016397
0.023528193699772746,280.742704786284,0.07470201499677846,113.1954585698297,287.34807352429374,0.023255672100118634
0.023864399605830346,280.936078923978,0.07576946874851134,113.27342702214794,287.6404497751149,0.02358409558878313
0.024206824746288946,281.155337788763,0.07685666856946739,113.36183219642925,287.96121577709926,0.02391848351394691
0.024552554707407047,281.342621402435,0.07795436119601737,113.43734494946179,288.2503015059436,0.02425598528976989
0.024896629432593746,281.54208606415,0.07904679844848514,113.51776910106528,288.5515350505686,0.024591758170680707
0.025238945964666748,281.749163880892,0.08013365343781692,113.60126287677565,288.86021580367185,0.02492570343689829
0.025581536655512247,281.976035900705,0.08122137888125137,113.69273767516427,289.18941619907497,0.025259804541247217
0.025916988527500646,282.178545824431,0.08228643857481455,113.77438967641059,289.4917639592696,0.025586835607426524
0.026262567796594548,282.364306807097,0.08338365275418769,113.84928850462153,289.7799185579569,0.02592362803993632
0.026606865498194646,282.57442988585,0.08447679795676799,113.93401012997472,290.09284973505186,0.026259058729530188
0.026946323718582847,282.781507702592,0.08555457780650054,114.0175039056851,290.401429750775,0.026589664457458313
0.027286463641509245,282.985540257324,0.08663452206179185,114.09976983175302,290.70721491262833,0.02692082451694915
0.027626368867872446,283.162165453957,0.08771372115549501,114.17098511103546,290.98490788621353,0.027251646558726965
0.027967882727116748,283.340313281595,0.08879802765859567,114.24281431513911,291.2647419353192,0.02758392406156741
0.028317261943688447,283.555004253365,0.08990730667121082,114.32937771495676,291.5845055842512,0.02792373998723234
0.028661112990110947,283.742287867036,0.09099903374360226,114.40489046798892,291.87465763966566,0.028258066350421548
0.028999434136585248,283.925003587691,0.09207320338365815,114.478561446557,292.158668028962,0.028586906935906486
0.029333966746095147,284.078789319242,0.09313534441885209,114.54056785351837,292.4119470784036,0.02891195885636986
0.029666659519399546,284.229529788782,0.09419164397409355,114.60134641083688,292.6616704743848,0.02923511832699422
0.029998054031558946,284.361998686257,0.09524382155019964,114.65475787029882,292.8923052873694,0.029556912950011123
0.030331669616249345,284.512739155798,0.09630305103159166,114.71553642761775,293.1424855614858,0.029880759743829654
0.030663511922786147,284.663479625338,0.09735665035484602,114.77631498493629,293.3922616268113,0.03020278117539497
0.030995452750083346,284.817265356889,0.09841056248151461,114.83832139189765,293.6453054476664,0.030524794501413953
0.031333033640043244,284.989322660506,0.0994823818071373,114.90769489671602,293.9189026944808,0.030852172894529108
0.031672916659956744,285.165947857139,0.10056151039536265,114.97891017599845,294.19798515787573,0.03118167560191512
0.03201039578504325,285.348663577794,0.10163300661751232,115.05258115456654,294.4827872356524,0.03150874044375374
0.03235362910631455,285.549650870514,0.1027227724125487,115.13361923099123,294.78821836621614,0.03184127222622564
0.03269684496349855,285.733889222175,0.10381248275910789,115.20790413438095,295.0764858988899,0.03217367655692264
0.033041941897486146,285.896810739759,0.10490816552451851,115.27359409027083,295.34339654889874,0.03250779134374162
0.03338042186941235,286.074958567397,0.1059828394353842,115.34542329437447,295.62426137065137,0.03283539133577454
0.033721072221468446,286.216563250905,0.1070644043031623,115.40251830276489,295.86809265126925,0.03316498362344284
0.03406286815639065,286.381007399494,0.1081496063965403,115.468822183476,296.1359658970373,0.03349557516287861
0.034406830460619944,286.527179976018,0.10924168671246831,115.52775896633045,296.38567207981237,0.03382815176057281
0.034748648367119946,286.673352552542,0.11032695856560581,115.58669574918493,296.63486407661367,0.03415854540484652
0.035088145318927046,286.81800249806,0.11140486138759337,115.6450186072178,296.88191424979635,0.03448658765038708
0.035427198676408145,286.993105063688,0.11248135579759586,115.71561996167901,297.16046681553854,0.034814093902871344
0.035772287132880644,287.13318711619,0.11357701164689604,115.77210104524782,297.40459793108954,0.03514731961292988
0.03611261614750075,287.291540740758,0.11465755626831486,115.83594922667363,297.6663898739531,0.03547584077464309
0.036450726466324745,287.420964376222,0.11573105653058106,115.88813283649272,297.89766732938693,0.03580211338100603
0.03679119729859625,287.567136952746,0.11681205142304309,115.94706961934719,298.1470762249669,0.03613055631998906
0.037130119874496145,287.722445315302,0.11788813060152525,116.00968995112979,298.40561420044236,0.036457398593233235
0.037466835092176444,287.88079893987,0.1189572014176602,116.07353813255557,298.6667813599541,0.03678200643557181
0.037803977836249746,287.976724693214,0.12002762963009293,116.1122153963039,298.86339041087206,0.037106920894869305
0.03813902847764545,288.127465162754,0.1210914154165243,116.17299395362241,299.1163667617881,0.037429714577822945
0.03847821308753275,288.288864049333,0.12216832655291647,116.23806998469105,299.381704390986,0.037756384901187774
0.038816956554291744,288.4472176739,0.12324383705987628,116.30191816611648,299.64386079055413,0.038082523886838034
0.03915332538078005,288.608616560479,0.12431180808397665,116.36699419718512,299.9086036323682,0.03840627137480796
0.039494467363099944,288.736517564937,0.1253949338778423,116.41856388218261,300.14001253444053,0.038734505899746245
0.039837024909787945,288.873554355428,0.12648255408857673,116.47381711610856,300.38141733606415,0.03906399405597344
0.040176846321590146,289.02734008698,0.1275614870710487,116.53582352307035,300.63954711239256,0.03939074323733776
0.040520061996255546,289.173512663504,0.12865119683811135,116.59476030592484,300.89084132430423,0.03972064777692378
0.04086141674427405,289.302936298967,0.1297349981630701,116.64694391574349,301.1242641444212,0.04004865564531848
0.04120385034319975,289.432359934431,0.1308222248396592,116.69912752556259,301.35808757764846,0.04037759211760527
0.04155289955587295,289.557215676879,0.13193045608989662,116.74946936091763,301.5891575755786,0.04071277212934497
0.04189336847134455,289.707956146419,0.13301144489651892,116.81024791823614,301.8447983023411,0.04103960457396057
0.04223723356681135,289.84499293691,0.134103216574626,116.86550115216211,302.08724360175705,0.0413695887872827
0.042582097023916646,289.977461834385,0.13519815805093535,116.91891261162404,302.3253102489658,0.041700421733035384
0.042927862651126546,290.106885469849,0.13629596391732676,116.97109622144312,302.56055400344474,0.042032010300880794
0.043266446751990546,290.219560164253,0.13737096843757,117.01652665822681,302.7763293104857,0.04235660528449358
0.043608451026300045,290.347461168711,0.13845683200850264,117.06809634322428,303.00906420969727,0.0426843722030907
0.043944495876373946,290.464703756132,0.13952377440748728,117.11536855447243,303.2290287325755,0.0430063231777716
0.044283221212196945,290.574333188525,0.1405992273487253,117.15957114161327,303.441900663699,0.0433307373554226
0.044619739871604544,290.683962620917,0.14166767409234443,117.20377372875373,303.65420541790957,0.04365293390412618
0.044955463743983744,290.79359205331,0.1427335973871484,117.24797631589459,303.8663528378454,0.04397426608177355
0.04528647869606655,290.919970426763,0.14378456986001129,117.29893207607084,304.0947114697549,0.04429099013952877
0.04562619347239655,291.053961955244,0.14486316427485904,117.35295746035439,304.3336463343215,0.044615934154495066
0.045965388306418345,291.172727173669,0.14594010787287823,117.40084359642333,304.55659464244553,0.044940275522045374
0.046305712410729546,291.326512905221,0.1470206369040663,117.46285000338513,304.8165946294309,0.04526559101982757
0.046646920666076744,291.45745917169,0.14810397311479365,117.5156475380254,305.0530521472081,0.045591645468435305
0.046985894889645045,291.580792283132,0.14918021627462302,117.56537544855883,305.2809767411867,0.04591545986799171
0.04733110977278845,291.716306442618,0.15027627352860332,117.6200147576636,305.52356296536595,0.04624512809443625
0.04767652144269865,291.819845350989,0.1513729555805682,117.66176164551877,305.73280046527043,0.04657487550718396
0.04802047690714885,291.935565307404,0.1524650141801976,117.70841993194529,305.9544503796236,0.04690312474150495
0.04836481155954505,292.054330525829,0.15355827670155553,117.75630606801425,306.1794831868598,0.047231627958339246
0.048711932275919044,292.173095744255,0.15466038497604295,117.80419220408363,306.40541179699477,0.047562679953040664
0.04906044052170055,292.279679914637,0.15576689865639923,117.84716694158163,306.6190497667907,0.04789494502956369
0.049414753776512846,292.399967764068,0.15689184324042826,117.89566700247222,306.8488401753897,0.048232631421227426
0.04975978794931535,292.498938779423,0.15798732673907623,117.93557211586335,307.05362394848686,0.048561364615205806
0.050108417686033246,292.605522949805,0.15909422615315555,117.97854685336137,307.26752271101395,0.04889341377808688
0.050459576741141446,292.684699762089,0.1602091561531241,118.01047094407429,307.4534458306921,0.049227760544591284
0.05080093745749595,292.80498761152,0.16129297642754964,118.05897100496486,307.67975547441574,0.0495526709657893
0.051144802822587446,292.858279696711,0.16238474896171512,118.08045837371388,307.8364586667614,0.049879858639162014
0.05148628327356564,292.95572808106,0.1634689493935709,118.1197495622834,308.0389296836551,0.050204671162137254
0.05182682087254885,293.050131203399,0.16455015627034258,118.15781290121049,308.2379878599545,0.050528481821888654
0.05217176539899765,293.149102218753,0.16564535514181752,118.19771801460122,308.4432084066366,0.05085637608169495
0.05251758200098865,293.245027972097,0.16674332285313895,118.2363952783495,308.6455477750038,0.05118499142393552
0.052862587731614945,293.342476356447,0.16783871604787745,118.27568646691941,308.84931874824883,0.051512728655124684
0.05321702226009205,293.441447371801,0.16896404567579223,118.31559158031018,309.05752740861976,0.051849310928787785
0.05356781439161055,293.546508911178,0.17007781069336347,118.35795239298697,309.27115381583724,0.05218232275672345
0.053916535651467146,293.633298878489,0.17118500069340817,118.39294610780675,309.46498910592896,0.05251325879715691
0.05426460330280904,293.697249380718,0.1722901154864187,118.41873095030552,309.6346141094889,0.0528434653890603
0.054611663168420345,293.774903561997,0.1733920305597346,118.4500411161972,309.81843964265994,0.05317260738213244
0.054955992888842245,293.851035112269,0.17448527742207412,118.48073735726686,309.9999105082778,0.05349905315645131
0.055300577381938346,293.948483496619,0.17557933318765423,118.5200285458368,310.2040043545272,0.053825633820635155
0.055643255622914646,294.007866105832,0.176667336602754,118.54397161387148,310.3674209547065,0.05415030209330887
0.055990862104725446,294.094656073143,0.17777098718250328,118.57896532869127,310.561269407071,0.05447953193671047
0.05634345879753615,294.190581826486,0.17889048168217725,118.61764259243915,310.7662967522498,0.054813377476781104
0.05669158892503855,294.298688627874,0.17999579483699737,118.6612312547588,310.98294890474335,0.055142884676415496
0.05704654003722635,294.393091750212,0.18112276461819365,118.69929459368548,311.18719904542337,0.0554787362283753
0.057398663888613644,294.472268562496,0.1822407578463483,118.7312186843984,311.3745833302323,0.055811801236623
0.057748445843714344,294.545354850758,0.18335131555379303,118.76068707582562,311.5548913238746,0.05614254131297957
0.05810081311042935,294.591033780922,0.18447008162561318,118.77910482046775,311.70701237863545,0.05647561539042752
0.058449936233306646,294.658029545162,0.1855785475407486,118.8061175126093,311.88077258270846,0.056805513576097734
0.058801644969609344,294.750910036495,0.18669522277850967,118.84356692671477,312.08274840293024,0.05713774498653597
0.059156547827506345,294.840745265817,0.18782203935233263,118.87978849117742,312.2825059146319,0.05747288178236662
0.05951354404026675,294.918399447095,0.1889555023278469,118.9110986570687,312.47003860087466,0.0578098820709056
0.05987058676409255,295.006712045412,0.19008911297599385,118.9467062967101,312.66893699491646,0.058146812712231044
0.060228637887778345,295.085888857696,0.19122592529369623,118.97863038742302,312.85851000349936,0.05848458098545769
0.060587518397894446,295.189427766067,0.19236537091331485,119.02037727527822,313.0742226517075,0.058823017216696166
0.060940669539321445,295.277740364383,0.19348662578734557,119.05598491491924,313.2721635622465,0.05915593868971455
0.061296474774569246,295.309715615498,0.19461630740925734,119.06887733616881,313.4111601494086,0.05949125016942804
0.06165473489512985,295.334077711585,0.19575378329203727,119.07870013331107,313.54282197839046,0.0598287615755591
0.062008592461850844,295.414777154874,0.19687728106637642,119.1112381488452,313.733031678679,0.06016201361738444
0.062364620951012945,295.484818181125,0.19800767151946608,119.13947869062959,313.9126168637698,0.06049719812286356
0.06271782735031305,295.554859207377,0.19912910183724392,119.1677192324144,314.09141783969136,0.060829614780706594
0.06307200983704894,295.602060768546,0.20025363123263037,119.18675090187776,314.24627685319166,0.06116283915107225
0.06342960873138324,295.658398115748,0.2013890077221418,119.20946612026961,314.41189462637743,0.06149916515673581
0.06378025688422405,295.742142821048,0.20250231560741133,119.24323198544654,314.60465266166534,0.061828844105376146
0.06413247067899555,295.801525430261,0.20362059440581087,119.26717505348124,314.7720080867194,0.06215988568751044
0.06448125281128024,295.836545943386,0.20472797767581474,119.28129532437325,314.9124570531774,0.062487593934015595
0.06483435107719734,295.89897381461,0.20584906467010156,119.30646624205075,315.08339176628886,0.06281924816930978
0.06519182529785784,295.943130113768,0.20698404532069864,119.32427006187127,315.23620295024597,0.06315490059272269
0.06554744746922794,296.013171140019,0.20811314571479872,119.35251060365565,315.41607892551895,0.06348870227293514
0.06590508748823465,296.061895332194,0.20924865277514498,119.37215619794063,315.57388044599486,0.06382428565234201
0.06627122894098934,296.103006369341,0.21041115188764115,119.3887321681183,315.7261164945588,0.06416772953503802
0.06663161049548115,296.189796336652,0.21155536332315264,119.42372588293809,315.92539947889173,0.06450565543701355
0.06699675065181915,296.256792100893,0.21271468331952578,119.45073857508005,316.10503453018435,0.06484792700271992
0.06735672936635764,296.28115419698,0.2138576157381855,119.46056137222234,316.2376837165781,0.0651852457470816
0.06772221787777845,296.345104699209,0.21501804176194655,119.48634621472107,316.4142524466619,0.06552761108721349
0.06809017065978634,296.399919415406,0.21618629184482163,119.50844750829168,316.58184051194786,0.06587216643076585
0.06845618148693434,296.44864360758,0.21734837622101652,119.52809310257626,316.742385755936,0.0662147855650157
0.06881441793307294,296.473005703668,0.21848577693750657,119.53791589971894,316.8746230240345,0.06655001354184797
0.06918410805487325,296.506503585788,0.21965954307422256,119.55142224578971,317.02004156883976,0.06689584177417932
0.06955596391876395,296.564363563995,0.22084018544207554,119.5747513890028,317.1921837356434,0.0672435753510741
0.06993237374178704,296.643540376279,0.22203528663017383,119.6066754797157,317.38852730995984,0.06759544436599778
0.07029889133058034,296.698355092475,0.22319897997459257,119.62877677328594,317.5559205150829,0.06793794715843693
0.07066459159080314,296.759260332694,0.22436007830079996,119.65333376614223,317.72963226489264,0.0682795692988391
0.07103249499911775,296.827778727939,0.22552817162219885,119.68096038310502,317.91219643603057,0.06862313180750292
0.07140817955002525,296.920659219272,0.22672097007133016,119.71840979721048,318.1232229649136,0.06897383888585618
0.07177472478326505,296.983087090496,0.22788475118686652,119.74358071488798,318.29896643170076,0.06931589577336918
0.07213738397759224,297.04551496172,0.22903619412885537,119.76875163256551,318.47360133333524,0.06965421113275769
0.07250248356423945,297.092716522889,0.23019538531646025,119.78778330202886,318.632676319645,0.06999468749496629
0.07287360925063555,297.164280180145,0.23137370937076784,119.81663776863446,318.81971381723923,0.07034066477264829
0.07324439098395015,297.234321206396,0.23255094137404173,119.84487831041886,319.0050680426863,0.07068620191176492
0.07361709923215774,297.283045398571,0.2337342900621008,119.86452390470384,319.16816085171564,0.07103341411306469
0.07398684164338165,297.342428007784,0.23490822221773672,119.88846697273851,319.34185514265454,0.07137774428292508
0.07436346666127625,297.4307406061,0.23610400664955206,119.92407461237954,319.54872156920044,0.07172836216893455
0.07474326108438714,297.488600584308,0.23730985394292917,119.94740375559299,319.7238687274099,0.07208180615769644
0.07512038827678964,297.566254765586,0.23850723277880712,119.97871392148427,319.91954736164695,0.07243264440400367
0.07549765957159345,297.62868263681,0.23970506913980918,120.0038848391618,320.09895159726574,0.07278349359272993
0.07587468636052384,297.685019984012,0.2409021291946632,120.02660005755365,320.2717775095252,0.0731339924670907
0.07625411599553045,297.765719427301,0.24210681828580916,120.05913807308777,320.471581136003,0.07348660113858167
0.07663926197011285,297.835760453552,0.2433296567551083,120.08737861487216,320.6616733230195,0.07384439496398232
0.07701827691827864,297.875348859694,0.2445330292155347,120.10334066022862,320.8171949652987,0.0741963682422169
0.07739673527481905,297.937776730918,0.24573463449755048,120.12851157790614,320.997187964929,0.07454770107112078
0.07777708667850634,298.006295126163,0.24694225020425764,120.15613819486893,321.18435657293116,0.07490066694678404
0.07816066178338404,298.065677735376,0.24816010116224432,120.18008126290363,321.3626883620859,0.07525649828671825
0.07854526249186064,298.126582975595,0.2493812084116575,120.20463825575992,321.5430136912146,0.07561315397002155
0.07892694936708805,298.181397691791,0.25059306424050454,120.22673954933015,321.71594576961854,0.07596698182199724
0.07929890585213954,298.217940835922,0.25177402608054306,120.24147374504375,321.86629724968867,0.07631166909171432
0.07967967379137565,298.319957113288,0.2529829642876177,120.28260670807774,322.08999398153196,0.0766643988008222
0.08006339585490495,298.380862353506,0.2542012818393232,120.30716370093364,322.27024745164266,0.07701973927901126
0.08044684069959675,298.444812855735,0.25541871922121967,120.33294854343237,322.4537551731613,0.07737469695727667
0.08082958390919745,298.52703493003,0.2566339289117019,120.3661004837881,322.6568509490708,0.07772887952202752
0.08121646252084154,298.581849646226,0.2578622685036719,120.38820177735832,322.83161124742225,0.07808676146113994
0.08160616310488625,298.668639613537,0.2590995678580138,120.42319549217811,323.0418413321538,0.07844712442724242
0.08200125968473895,298.753906949843,0.26035399949904614,120.45757528217669,323.2521036554674,0.0788123446424097
0.08238925338111884,298.782836938947,0.2615858794850523,120.46923985378344,323.3993317974394,0.07917086931546996
0.08277923881368465,298.868104275252,0.26282408323344875,120.5036196437816,323.60817845284635,0.07953110496289341
0.08317330350625625,298.922918991449,0.2640752386323636,120.52572093735226,323.78532565770087,0.0798949769215074
0.08356477981219304,298.970120552618,0.26531817590371287,120.54475260681558,323.95349284702235,0.08025632775870402
0.08395824231612575,299.049297364902,0.26656741935369926,120.57667669752847,324.1569507375316,0.08061938042687658
0.08434955361356955,299.05995578194,0.2678098327230833,120.58097417127821,324.2855295558405,0.08098031746951102
0.08474284974802504,299.151313642268,0.26905854794997947,120.61780966056247,324.5022484661791,0.08134295406180743
0.08514339309353315,299.206128358464,0.2703302730719677,120.63991095413269,324.6815533612829,0.08171213779333149
0.08554367032812615,299.260943074661,0.2716011532918005,120.66201224770332,324.860822531124,0.08208094013787492
0.08594002387538935,299.306622004824,0.27285957580436115,120.68042999234505,325.02904024598075,0.0824459933526172
0.08633919143180635,299.35839145901,0.27412693279598516,120.70130343627285,325.2047529259071,0.08281350371509454
0.08673463357518285,299.40863828219,0.27538246160120555,120.72156295537901,325.3777368128402,0.08317745098940324
0.08713688612424784,299.52588086961,0.2766596134444869,120.76883516662674,325.6256334422102,0.08354753040763088
0.08753627436964635,299.551765596703,0.27792767112362715,120.77927188859064,325.773411137888,0.08391483916661528
0.08793336489645374,299.644646088036,0.2791884335462406,120.81672130269612,325.993408091764,0.08427990105858575
0.08833140466322395,299.675098708145,0.28045220980573604,120.82899979912406,326.14582111962574,0.08464570192691413
0.08873456676303315,299.745139734396,0.28173224947263026,120.85724034090846,326.3428948480524,0.08501607389515872
0.08914106242072835,299.82431654668,0.2830228731858125,120.88916443162138,326.5509746632198,0.08538936946536353
0.08955036863140395,299.909583882985,0.2843224204047075,120.92354422161954,326.76659767579724,0.08576510529436371
0.08996204439548294,299.967443861193,0.2856294909556583,120.94687336483301,326.95312836303316,0.08614287397924418
0.09037522249095435,300.022258577389,0.28694133140878003,120.96897465840324,327.13683694855916,0.08652187782116573
0.09079284967605815,300.052711197499,0.2882672977214846,120.98125315483159,327.2953519001472,0.08690481684868626
0.09121513454410145,300.1090485447,0.28960805217752206,121.00396837322303,327.48353578560705,0.08729187764440219
0.09163446034983184,300.142546426821,0.29093941161071607,121.01747471929424,327.64594669666707,0.08767607801429417
0.09205497972276215,300.147114319837,0.2922745606197698,121.01931649375827,327.77715084239514,0.08806122378677594
0.09247553740482795,300.131888009782,0.2936098312603287,121.0131772455441,327.88674564581225,0.08844625634545548
0.09289308541862144,300.151682212853,0.29493554620412304,121.02115826822234,328.0336980671945,0.08882838686065879
0.09331677836345295,300.165385891902,0.29628077130396313,121.0266835916149,328.17585267955695,0.08921599187256113
0.09374167163442304,300.177566939946,0.2976298074392931,121.03159499018625,328.3167138520505,0.08960454415502628
0.09416134952334675,300.209542191061,0.2989622847366259,121.04448741143581,328.47767782355737,0.08998817897797078
0.09457944097656285,300.249130597203,0.300289725100587,121.06044945679227,328.64652552278545,0.0903702173263362
0.09499610773032334,300.268924800274,0.3016126420437766,121.06843047947048,328.7933039286692,0.09075080867796706
0.09541309714254005,300.29024163435,0.30293658342756463,121.07702542696994,328.94186363036505,0.091131549789104
0.09583312466454094,300.281105848317,0.3042701708099175,121.07334187804142,329.057982499485,0.09151491841556436
0.09625111400506314,300.319171623454,0.30559728696607547,121.08868999857665,329.2252264492892,0.09189628089992026
0.09666844204191265,300.361805291606,0.30692230348307264,121.10587989357555,329.39731305804185,0.09227689499106342
0.09708640151043314,300.358760029596,0.3082493247956252,121.10465204393311,329.5195112030052,0.09265793982367641
0.09751347428386545,300.366373184623,0.30960528085127276,121.10772166804,329.6561417918997,0.09304714314363817
0.09794491523537804,300.402916328754,0.3109751058723253,121.1224558637536,329.8258545050341,0.09344017355507839
0.09837912592893065,300.450117889923,0.3123537248243548,121.14148753321695,330.00813787317776,0.0938355712205153
0.09881562427812554,300.482093141038,0.3137396070830486,121.15437995446652,330.1744187591675,0.09423289453916615
0.09925045322418505,300.503409975114,0.3151201889867875,121.16297490196595,330.32850961055715,0.09462854138179969
0.09969127403405935,300.504932606119,0.31651979505813843,121.16358882678719,330.4626521911421,0.09502948044290811
0.10013856330222655,300.526249440196,0.31793993848456925,121.17218377428705,330.6205162937438,0.09543613850958177
0.10058578717179315,300.546043643267,0.3193598742704432,121.18016479696526,330.77670402449314,0.09584257185106478
0.10103348374064515,300.556702060305,0.3207813108765483,121.18446227071497,330.92299273105675,0.09624926939494786
0.10148371977466114,300.574973632371,0.3222108102845491,121.19182936857199,331.0784400277547,0.09665810710079525
0.10192792093817915,300.553656798294,0.3236211489787188,121.18323442107214,331.18846616611114,0.09706130109444402
0.10238121441867415,300.553656798294,0.3250603557792904,121.18323442107214,331.32470517927675,0.09747258051039695
0.10283053039016915,300.530817333212,0.32648693398878703,121.17402554875108,331.4345606781772,0.09788008421499161
0.10328028392188114,300.533862595223,0.3279149014519726,121.17525339839392,331.57308525219725,0.09828781852736175
0.10372756959404915,300.533862595223,0.32933503346110604,121.17525339839392,331.7075097429374,0.09869315073094165
0.10417272485284215,300.538430488239,0.33074840140777384,121.17709517285796,331.8463377151953,0.09909638928835703
0.10462175316479115,300.526249440196,0.3321740662982119,121.17218377428705,331.9678325286686,0.09950297154180202
0.10507763795667314,300.570405739354,0.3336215005124372,121.18998759410754,332.1536340141242,0.09991559309583052
0.10552998738724315,300.58867731142,0.33505770995449696,121.19735469196453,332.30979663684224,0.10032484658043583
0.10598601567265915,300.652627813649,0.3365055997606928,121.22313953446329,332.51760193713255,0.10073725896293602
0.10643803990863114,300.670899385714,0.33794077670990386,121.23050663231989,332.6737205738946,0.10114588247353413
0.10689527617936015,300.667854123703,0.33939250186946845,121.22927878267707,332.80782742851187,0.10155904778750653
0.10735861132120214,300.673944647725,0.3408635909448168,121.23173448196272,332.9538818055728,0.10197755006605734
0.10781836752694214,300.681557802753,0.3423233168980413,121.23480410607,333.10055251050375,0.10239264666261064
0.10828072285209214,300.678512540742,0.3437912950553925,121.23357625642718,333.2361992247454,0.10280991620968616
0.10874836542520515,300.661763599682,0.3452760602250263,121.22682308339178,333.35823893700683,0.10323178039046858
0.10921325561785915,300.632833610578,0.34675208658670276,121.21515851178506,333.4659241148114,0.10365098529920226
0.10968535889343414,300.635878872589,0.3482510144866534,121.2163863614279,333.6112331429719,0.10407651468536833
0.11016050472975315,300.649582551638,0.34975960251696625,121.22191168482044,333.769292312316,0.10450460372646939
0.11063961187435514,300.6389241346,0.3512807677010776,121.21761421107072,333.90149801517583,0.10493607628309685
0.11111575911555714,300.635878872589,0.3527925351918939,121.2163863614279,334.04126277088943,0.10536469885307817
0.11159468932468915,300.643492027616,0.35431313860588803,121.21945598553476,334.1937091179274,0.10579564136912195
0.11207078552410615,300.676989909736,0.355824744039037,121.23296233160556,334.3740963579438,0.10622384984928845
0.11255221717230915,300.681557802753,0.3573532895220815,121.23480410607,334.5239337962767,0.10665667074086004
0.11303436726476915,300.687648326774,0.358884116065642,121.23725980535528,334.67568639972234,0.10708994986230541
0.11351794728039415,300.652627813649,0.3604194826152514,121.22313953446329,334.7820969675108,0.10752432548426555
0.11399632526548015,300.646537289627,0.36193833271789944,121.22068383517762,334.91913774443566,0.10795384281516336
0.11448095854527314,300.645014658622,0.3634770433812422,121.2200699103564,335.06314411859876,0.10838878849843674
0.11496605296655314,300.608471514491,0.3650172181688062,121.20533571464277,335.1682409728205,0.10882395867869264
0.11545382267791615,300.544521012261,0.36656588700238374,121.17955087214364,335.24353484802975,0.10926133795823116
0.11594378785791914,300.536907857234,0.3681215264488933,121.17648124803675,335.3822953453081,0.10970049338760332
0.11643259551805114,300.511023130141,0.3696734907698124,121.16604452607284,335.5003015349684,0.1101384192423867
0.11692303354395915,300.504932606119,0.3712306315020703,121.16358882678719,335.6408809213494,0.11057761309705935
0.11741295169266715,300.450117889923,0.37278612162421815,121.14148753321695,335.7268530677887,0.11101614889453723
0.11790424153178815,300.369418446634,0.37434596686342736,121.10894951768282,335.78424690792866,0.11145571948301639
0.11839460744307115,300.316126361443,0.37590287863175087,121.08746214893382,335.8719362508298,0.11189427081471066
0.11887688738657215,300.268924800274,0.37743411745236655,121.06843047947048,335.9639599594433,0.11232540306851715
0.11934890544241014,300.162340629891,0.3789327747796522,121.02545574197205,335.9863874391004,0.11274718184021018
0.11982815542305915,300.039007518449,0.3804543934682128,120.97572783143863,335.99212834435014,0.11317524087702584
0.12029733661441115,299.9415591341,0.38194404375075536,120.93643664286911,336.0237298379061,0.11359412919366718
0.12076263568519215,299.885221786898,0.38342136830048507,120.91372142447729,336.1001515729222,0.11400937830187338
0.12122801764976615,299.796909188582,0.3848989560380075,120.87811378483626,336.14069418704076,0.11442452898108421
0.12168377120597715,299.649213981052,0.38634597357897743,120.81856307716018,336.1116603771732,0.11483092353012346
0.12213993532004715,299.436045640288,0.3877942946411497,120.73261360216414,336.00914488728347,0.11523751886025373
0.12259689708749914,299.268556229688,0.38924514825280976,120.6650818718102,335.9579526193035,0.11564465948107573
0.12303696630954415,299.09345366406,0.39064236803280267,120.594480517349,335.89300484593014,0.11603659267628734
0.12347774823265914,298.831561131121,0.39204185063869273,120.488885448068,335.7306094004421,0.11642900669068763
0.12392192259994615,298.540738609079,0.393452104254829,120.37162580718066,335.53648091192406,0.1168242851797209
0.12435611760772115,298.187488215813,0.39483067340451466,120.2291952486158,335.26892656952964,0.11721053190313148
0.12479568366005514,297.849464132601,0.3962262956206751,120.09290393826473,335.01979163681,0.11760140463807331
0.12522922147110915,297.46423848822,0.39760277817077155,119.93758095845031,334.71545348959614,0.11798676732044214
0.12565835117954813,296.949589208376,0.3989652649950653,119.73007436881721,334.26378497174466,0.11836806554151053
0.12610129042298512,296.380125212335,0.40037159709297776,119.50046648561347,333.7540414573363,0.11876148164238234
0.12632040578352913,296.133458989451,0.40106728836270494,119.40101066454665,333.5411576950786,0.11895604144581917
0.12653504159248014,295.815838161712,0.4017487570561244,119.27294594680228,333.24690754721865,0.1191465870130906
0.12675353103725914,295.525929218273,0.4024424610432978,119.15605466080768,332.98488425975626,0.11934051640865731