File: example/data/02 processed data/test_ID_074.csv
Strain,Stress_MPa,Displacement(mm),Force(kN),True Stress (MPa),True Strain
1.7096134916871e-05,-0.0829630011952768,5.4280228361065425e-05,-0.016725341040967803,-0.08296441954193834,1.709598877960073e-05
4.8771730902308e-05,0.764560501421374,0.0001548502456148279,0.154135397086549,0.7645977903604079,4.8770541600143445e-05
9.70841865910464e-05,2.53345260324623,0.0003082422924265723,0.5107440448144399,2.533698561431483,9.707947422639735e-05
0.0001786999124442,5.87788623789952,0.0005673722220103349,1.1849818655605433,5.87893661565559,0.00017868394751680765
0.0002545260435785,10.3333042443673,0.0008081201883617375,2.0831941356644474,10.335934339413711,0.0002544936573203357
0.0003705324838084,15.3810340395013,0.00117644063609167,3.100816462363462,15.386733212247497,0.0003704638536002069
0.0004349311317581,20.8077881076598,0.0013809063433319673,4.194850082504216,20.81683806249085,0.0004348365766291537
0.0005454163835787,26.5194835649222,0.0017316970178623725,5.346327886688316,26.533947725742557,0.0005452676981242058
0.0006384916978686,32.4486143399826,0.002027211140732805,6.541640650940492,32.469332510846016,0.0006382879487678958
0.0007401887125816,38.498398592524,0.0023500991624465797,7.761277156252839,38.526894672614645,0.0007399149080194413
0.0008601540965754,44.5524150325165,0.002730989256626895,8.981766870555326,44.590736974819045,0.000859784376036334
0.0009579801942635,50.6037365221525,0.0030415871167866126,10.201713282865944,50.652213899496445,0.0009575216240811742
0.0010586206216437,56.6643771108683,0.0033611204737187474,11.42353842555105,56.72436318899046,0.001058060677977117
0.001145983577357,62.7920590217865,0.003638497858108475,12.65887909879216,62.864017690213906,0.0011453274394116462
0.001234960214472,68.9350973441037,0.0039209986809486,13.897315624571306,69.0202294467044,0.0012341982783489105
0.0013284175524856,75.1383210226398,0.004217725729141779,15.147885518164186,75.23813608715058,0.0013275359865275805
0.0014280995426183,81.2570840831065,0.004534216047813102,16.38142815115427,81.3731272877201,0.0014270807782824546
0.001520434825859,87.3957124014862,0.004827380572102325,17.61897562013962,87.52859188625217,0.0015192801351024043
0.0016240530942826,93.5269106786542,0.005156368574347255,18.85502519281669,93.67880334734056,0.001622735746158738
0.0017282697207929,99.6642411046778,0.005487256363517457,20.092311006703046,99.83648779482482,0.0017267779811840343
0.0018237445084016,105.764801074623,0.00579038881417508,21.322183896643995,105.95768904976501,0.0018220835055754406
0.0019304216397781,111.840203823929,0.006129088706295467,22.546985090904087,112.05610257358792,0.0019285607703813717
0.0020232607384989,117.80871872158,0.0064238528447340066,23.750237694270528,118.04707647682223,0.002021216703104276
0.0021260635275844,123.769914309488,0.006750251700080469,24.95201472479278,124.03305701011365,0.0021238066527960605
0.0022277218547501,129.68649690721,0.007073016888831567,26.144797776493537,129.9754023506362,0.002225244161477768
0.0023248864618709,135.533500517905,0.007381514516440107,27.323553704409647,135.84860051838902,0.0023221880947959447
0.0024211067327888,141.33147118399,0.007687013876604439,28.492424590692387,141.6736497604285,0.0024181805759567127
0.0025355835476867,147.057775974646,0.008050477763905271,29.646847636488634,147.43065325196673,0.0025323743793214553
0.0026366360714907,152.698803060447,0.008371319526982971,30.784078696986118,153.10141423266964,0.00263316624437993
0.0027200326540344,158.271450047467,0.00863610367655922,31.90752432956935,158.7019535597975,0.0027163400596841446
0.0028051156308419,163.756192158888,0.008906242127923032,33.01324833923182,164.21554721316008,0.0028011886360596095
0.0028827532825258,169.196286162659,0.009152741672019415,34.10997129039205,169.68403731198555,0.002878606117539039
0.0029712459656094,174.554908151143,0.009433705940809846,35.19026948327043,175.0735537177644,0.002966840538563036
0.0030638741046818,179.803601138221,0.009727800282364715,36.248405989465354,180.35449673567695,0.003059190007634024
0.0031797904613142,184.962353082935,0.010095834714672585,37.2884103815197,185.55049460897035,0.0031747456191569164
0.0032770633048602,190.029515402891,0.010404675992931135,38.30995030522283,190.65225415465818,0.003271705435102737
0.0033660157029219,195.020787510515,0.010687099856777032,39.316190762119824,195.67723054367156,0.003360363352447823
0.0034683623576171,199.936012717948,0.011012050485434292,40.307100163938316,200.62946325839096,0.0034623614604161147
0.0035365011824875,204.713986890995,0.011228391254397813,41.27033975722459,205.43795814770672,0.003530262466671213
0.0036382616056079,209.309725156188,0.011551480597805083,42.1968405914875,210.07124869290408,0.003631659141334671
0.0037409642936747,213.822464410247,0.01187756163241717,43.106608825105795,214.62236661479128,0.003733984289300167
0.003812973710764,218.150542761503,0.012106191531675699,43.979149420719004,218.9823450460415,0.003805722752468576
0.0039058335515402,222.290201655973,0.012401021526140133,44.813704653844155,223.15843018377956,0.0038982255875335873
0.0040289176879864,226.286927691328,0.01279181365935682,45.61944462257173,227.1986190968637,0.004020823332828161
0.0042027472734586,230.003235156773,0.013343722593231055,46.368652207605436,230.9698806262148,0.004193940397895219
0.0044061541108424,233.363198690204,0.01398953930192462,47.04602085594512,234.39143290743218,0.004396475433898365
0.0046397510435199,236.033132828931,0.01473120956317568,47.58427957831249,237.1282678032793,0.004629020576974306
0.0049284508508363,237.944270584394,0.01564783145140525,47.96956494981383,239.11696722720725,0.0049163457934366175
0.0052457949695439,239.087315278414,0.01665539902830188,48.200002760128264,240.34151831418325,0.005232083717155252
0.0055941917863061,239.745431734418,0.017761558921521866,48.332679037658664,241.08661365943107,0.005578602408391706
0.005952608768983,240.102821662868,0.018899532841521027,48.404728847234196,241.53205982455594,0.005934961988363679
0.006298686477236,240.316946327802,0.0199983295652243,48.447896379684884,241.83062742788758,0.006278932656920742
0.0066756398924113,240.496696697811,0.021195156658405875,48.48413405427869,242.10216604028003,0.00665345647934944
0.0070456655083821,240.663258667133,0.022369987989113167,48.517712947294015,242.35889148785887,0.007020960780111511
0.007447206135026,240.826667640651,0.02364487947870755,48.55065619635524,242.6201534773823,0.0074196126071929755
0.0078231501221868,240.957338253534,0.02483850163794309,48.57699939191246,242.84238368373394,0.007792707949318745
0.0081920755077661,241.076483828471,0.026009839737157366,48.601019139819755,243.05140058714056,0.008158702595596392
0.0085675308818042,241.20470705781,0.02720191054972833,48.6268689428545,243.27123583436435,0.008531037877586668
0.0089421153233444,241.370333729859,0.028391216151618468,48.660259279939574,243.52869508970554,0.008902371364441582
0.0093151824633003,241.464673727244,0.029575704320978446,48.679278223412396,243.71396122145453,0.009272063716961654
0.0096923573653039,241.609870532036,0.030773234634839882,48.70854989925846,243.9516397402173,0.009645687786164764
0.0100686930470749,241.736863325564,0.031968100424462804,48.7341516464337,244.17083760055178,0.010018341458290295
0.0104404726945332,241.851794320242,0.03314850080514291,48.75732173496079,244.37684137496638,0.010386347362898826
0.0108081278745357,242.015587986677,0.03431580600165084,48.79034253811408,244.63132340926796,0.010750137530969883
0.0111748108739161,242.201971163625,0.035480024524683615,48.8279173865868,244.90853238466815,0.011112833967594556
0.0115415773524421,242.403786818272,0.036644508094003665,48.86860342256364,245.20150887435997,0.011475481429869013
0.0119129075537654,242.577169846108,0.03782348148320514,48.903557440975376,245.46696924513873,0.011842507432441973
0.0122905294833944,242.722585674677,0.03902243110977722,48.93287327201489,245.70577477019734,0.01221561413416993
0.012668317959341,242.842410548008,0.04022190952090768,48.957029966478416,245.91881541884297,0.012588746142069169
0.0130315573797608,242.955719581076,0.04137519468074054,48.97987306754492,246.1218109815379,0.012947377179899713
0.0133817175107868,243.070149287689,0.04248695309674809,49.0029420963981,246.32284536076165,0.013292973153682643
0.0137477516816003,243.24258466091,0.04364911158908095,49.037705067639465,246.58662331321884,0.013654108621697275
0.0141202852533558,243.425236647712,0.04483190567940466,49.07452770817874,246.86247042704332,0.014021522643873336
0.0144795300998095,243.60618682671,0.04597250806689516,49.111007264264735,247.13348994136717,0.01437570275124621
0.0148415832106485,243.792880504067,0.04712202669380899,49.148644709619916,247.4111528262318,0.014732524658144772
0.0151932578857082,243.940016199927,0.04823859378712353,49.17830726590528,247.6462597746963,0.015078996227457989
0.0155486414268035,244.105476863615,0.04936693653010111,49.21166413570479,247.90098539368623,0.015428999883603257
0.0159100849916194,244.308621828957,0.05051451984839159,49.25261816071773,248.1955927664411,0.0157848462160238
0.0162590962214956,244.410581362939,0.05162263050324853,49.273173202768504,248.38447652287073,0.016128332611284848
0.0166124225737291,244.496906243427,0.05274444167158989,49.29057629867488,248.55859216791225,0.016475945682277893
0.0169615748710324,244.592870948498,0.053853000215527864,49.309922783217196,248.7415512420117,0.016819333531623654
0.0173112492784598,244.77116433144,0.054963216459109863,49.34586672921831,249.00845897336038,0.017163116731910465
0.0176579117330556,244.915269441864,0.05606386975245153,49.37491831947978,249.23996165174597,0.01750382209943247
0.0180048538380004,245.065452070388,0.057165410935651265,49.40519513739022,249.47781971565885,0.017844686130716943
0.0183497407757139,245.223947490429,0.058260426962891625,49.437147814070485,249.72374335887562,0.018183415880361993
0.0187014867389005,245.419225513895,0.05937722039600908,49.47651586360123,250.00892990531435,0.018528764060055887
0.0190578793140912,245.614092094435,0.06050876682223956,49.515800966238096,250.2949758194108,0.018878552739486368
0.0194117352005498,245.759929429491,0.061632259261745606,49.545201772985386,250.53055610248208,0.019225730727809885
0.019765121733883,245.877538575003,0.06275426150507853,49.568911776720604,250.73733805656545,0.01957232796940678
0.0201198490286235,246.000570590292,0.06388052066587961,49.593715031002866,250.95006493152388,0.0199201194413773
0.0204753699381055,246.124701827427,0.06500929955348496,49.61873988840928,251.1641961482495,0.020268567688021027
0.0208217026971487,246.250579068034,0.06610890606344712,49.64411674011565,251.3779354143893,0.020607893861569287
0.0211470415035041,246.385574152669,0.06714185677362552,49.67133174917807,251.59590011514015,0.02092654595654596
0.0214859175939298,246.552256610106,0.06821778836072712,49.704934932597375,251.84965807822817,0.021258349173590346
0.0218380669896239,246.702624905663,0.06933586269205588,49.735249180981654,252.0901333548689,0.02160303205485394
0.0221947052264036,246.836490658537,0.07046818909383143,49.76223651676106,252.31495380782314,0.021951987556200436
0.0225374028257791,246.948821410168,0.07155625397184864,49.784882396289866,252.51440647564036,0.022287188046509056
0.0228763284755134,247.049238602585,0.07263234290975504,49.80512650228114,252.70081813448323,0.022618588630801052
0.0232162880037726,247.093554095839,0.07371171441197799,49.814060505721145,252.83014921160375,0.022950889845955662
0.0235470772131989,247.220787380996,0.0747619701519065,49.83971073600879,253.04211435016416,0.0232741213615553
0.023885584811251,247.36464560305,0.07583673177572192,49.86871255357488,253.27309482490668,0.023604786791891492
0.0242209078968395,247.500083371261,0.0769013825724654,49.89601680764622,253.4947600950564,0.023932233718873548
0.0245545468130575,247.616685869989,0.07796068613145755,49.919523871389785,253.6968013748778,0.024257929654365535
0.0248983703290619,247.729832755356,0.07905232579477152,49.94233428347977,253.89790187285544,0.02459345677612008
0.0252302855812668,247.87901901065,0.08010615672052208,49.97241023254705,254.13307744989297,0.024917256215875136
0.025571283190308,248.008777070229,0.08118882412922789,49.99856945735817,254.3506797423738,0.025249806782810982
0.0258990596356467,248.137549983181,0.08222951434317827,50.02453007660929,254.56407918803868,0.02556935948731301
0.0262345214661978,248.234467964246,0.083294605655178,50.04406874159199,254.74678044270422,0.02589629905560281
0.0265765405596965,248.362724534175,0.08438051627703638,50.069925266089676,254.96334655627422,0.026229519294903143
0.0269146094841338,248.525976206008,0.08545388511212482,50.10283680313121,255.21495580225582,0.02655878190456599
0.027260294146424,248.648783269227,0.0865514339148962,50.12759470707617,255.42702224029657,0.026895349803377797
0.0276100407252023,248.740184965477,0.0876618793025173,50.14602128904016,255.60791160236815,0.027235757250232532
0.027953750130441,248.841282877784,0.08875315666415018,50.16640262816126,255.79732992148797,0.027570175875400997
0.028293350765673,248.882656693845,0.08983138868101177,50.17474358947916,255.92438099917655,0.027900486992359436
0.0286117106591884,248.975849413056,0.09084218134292317,50.19353124167209,256.099474377588,0.02821003934071808
0.0289521025963261,249.078845687583,0.09192292574333537,50.21429529061673,256.2902019825044,0.028540908243106712
0.0292905444882801,249.164588496917,0.09299747875028931,50.23158104097846,256.46275496118994,0.028869773156564336
0.0296554426427505,249.303666124023,0.09415603039073284,50.25961909060304,256.6968766953914,0.02922422457060963
0.0299809213084525,249.379152113995,0.09518942515433668,50.27483706618139,256.8557688494933,0.0295402790684891
0.0303177493711769,249.411170001253,0.09625885425348665,50.28129187225261,256.97275534372295,0.02986724920201252
0.0306674583702823,249.503576551262,0.0973691803256463,50.29992103273442,257.1552170983844,0.030206610203875335
0.0310120390246437,249.545080628238,0.09846322390324373,50.30828825465278,257.2839824070888,0.03054088200315872
0.0313540810167467,249.670946157638,0.09954920722817076,50.333662745379826,257.49914923099243,0.030872580620504294
0.0316848981182644,249.740337975368,0.10059955152548947,50.34765213583419,257.65333514013844,0.03119328915553344
0.0320190385111832,249.79960995446,0.10166044727300666,50.35960136681914,257.7979532856704,0.03151711505895671
0.0323572431750205,249.89810843139,0.10273424708069008,50.379458659768225,257.9841222948821,0.03184477302505864
0.0326875122567267,250.017773095426,0.10378285141510726,50.40358305603789,258.19023211788226,0.032164639297838846
0.0330291218517104,250.183512065822,0.10486746187918052,50.436996032469715,258.4468537711329,0.032495381271309236
0.0333684442084217,250.268841849198,0.10594481036173889,50.454198516798314,258.61992373554926,0.03282380051195717
0.0337065095221888,250.370579984855,0.10701816773294943,50.474708924946775,258.80969832319045,0.03315089587554936
0.034052578928906,250.421981355252,0.10811693809927654,50.48507144121881,258.9494956408847,0.033485624821373954
0.0343851694894939,250.540128489326,0.10917291312914312,50.50888990344813,259.15499327135103,0.033807211065590016
0.0347259479380085,250.6051309633,0.11025488470317697,50.52199440220128,259.3076316941293,0.03413660705474258
0.0350761556280808,250.680754580131,0.11136679411915654,50.537240123354415,259.4736717407484,0.034475004327419886
0.0354264987515218,250.758039282076,0.1124791335360817,50.55282071926652,259.64151864763653,0.03481341792572517
0.0357751546904012,250.832282026601,0.1135861161420238,50.56778805656277,259.805845717449,0.03515008813028329
0.0361190317267371,250.904180850027,0.11467792573239027,50.58228285936544,259.96659691852005,0.035482032726438545
0.0364654496439881,250.952954096631,0.11577780261966222,50.59211554588081,260.10406640725176,0.035816318661309396
0.0368003798654163,250.964518419614,0.11684120607269675,50.59444691339419,260.2001080301971,0.03613941299834504
0.0371407024889597,250.956210603341,0.11792173040244704,50.592772057633546,260.27690055911637,0.03646760228924959
0.0374845643710428,251.056690600127,0.11901349187806087,50.613028824985605,260.46744127970845,0.03679909529738453
0.0378164441148533,251.088867404409,0.12006721006465922,50.61951566872886,260.5841555264696,0.03711893299348976
0.0381577215218355,251.190855626807,0.1211507658318277,50.640076494364294,260.77572634464633,0.03744772071706159
0.0384981297714273,251.276071334961,0.12223156202428168,50.65725598112814,260.9497301376687,0.037775563438260336
0.0388354746745365,251.341815281716,0.12330263209165337,50.67050996079395,261.10279398374115,0.038100349890809564
0.039173174128477,251.435966526771,0.12437482785791446,50.68949085179704,261.28551142568614,0.03842537207693758
0.0395113155025954,251.463513204908,0.12544842672074039,50.69504426210945,261.3991674125382,0.038750713781066023
0.0398590475391065,251.505148479694,0.12655247593666313,50.703437933506315,261.52990414927615,0.03908517275569902
0.0402079610327743,251.565134373888,0.12766027627905838,50.71553108977582,261.68005549399794,0.03942065569495286
0.0405561151875051,251.647274477116,0.1287656657203287,50.73209053458659,261.85311032743164,0.03975529638003445
0.0408976142010105,251.659858563434,0.12984992508820833,50.7346274863883,261.9521463688422,0.04008343148267719
0.0412385296326327,251.627589474851,0.1309323315836088,50.72812203812996,262.0043412797976,0.04041089847918309
0.0415671056739694,251.645980623107,0.13197556051485285,50.73182969361837,262.10617569209734,0.040726411399344874
0.0419044838643954,251.518130698547,0.1330467362694554,50.706055148827076,262.0578681480072,0.04105027297256605
0.0422424600517064,251.726561536788,0.1341198106641678,50.74807480581646,262.36011075645916,0.04137460345344722
0.0425960188414892,251.831866970324,0.1352423598217282,50.76930438121732,262.5589019206793,0.04171377485377535
0.0429425949871525,252.049118640263,0.13634273908420919,50.81310231787702,262.87276185890056,0.04204613614074041
0.0432892460421736,252.141908590917,0.1374433561839012,50.83180877192888,263.0569417094525,0.04237845880152431
0.0436359603808911,252.125324166715,0.13854417420932924,50.828465352009744,263.1270548230731,0.04271073169835865
0.0439828807574999,252.086573676892,0.13964564640506216,50.820653253261426,263.17406738748946,0.04304309158414431
0.0443187977652826,252.084905387367,0.14071218290477225,50.82031692609319,263.2570053289101,0.04336480469114852
0.0446660089775091,252.09118779503,0.1418145785035914,50.821583459478056,263.35109505223375,0.043697225697087
0.0450025612637576,252.154030771127,0.14288313201243039,50.8342526034592,263.5016079888081,0.044019336383873744
0.045350586060055,252.219321776904,0.1439881107406746,50.84741527022385,263.65761583515615,0.044352318205589825
0.0457066190651431,252.267778433272,0.14511851553182933,50.857184132147644,263.79808568453154,0.04469284739594968
0.0460464392979415,252.330688688227,0.14619744477096425,50.86986683954657,263.94961842791724,0.045017761691573004
0.0463907135186692,252.334379365679,0.14729051542177468,50.870610880120886,264.04035126974344,0.04534682698595546
0.0467359842935083,252.346220202344,0.14838675013188884,50.872997992792556,264.1398691862469,0.04567673609115347
0.0470955226984178,252.352648895082,0.1495282845674765,50.87429401724853,264.2373287991262,0.04602016239574641
0.0474361214675824,252.391856170389,0.1506096856595741,50.88219820395042,264.36434691711617,0.04634538906216184
0.0477878735815646,252.473532622944,0.1517264986214676,50.89866417678551,264.53870588262026,0.0466811547064252
0.04813077704399,252.504222976381,0.15281521711466825,50.904851352038406,264.6574474351231,0.04700836536928418
0.0484901524152532,252.62242168822,0.15395623391842891,50.92868021234516,264.87212141939216,0.04735117924635007
0.0488467494041751,252.598530456997,0.15508842935825592,50.92386374013059,264.9371475740928,0.04769122665794971
0.0491997613947042,252.634035182114,0.15620924242818582,50.93102149271418,265.0635694332553,0.04802774159414716
0.0495293672223028,252.619163582325,0.15725574093081138,50.92802337819672,265.1312309027849,0.04834184199501751
0.0498746373701421,252.647764931266,0.15835197365020115,50.93378941014323,265.2484805895898,0.04867076406070576
0.0502219325710043,252.707350302224,0.15945463591293865,50.94580182092835,265.39880180929947,0.04900150618847153
0.0505755798780296,252.673564491348,0.16057746611274398,50.938990601455764,265.45267653534665,0.049338185290831726
0.0509104540968064,252.639301557874,0.1616406917573603,50.9320831940674,265.50128312288535,0.0496568875959599
0.0512579965846424,252.626934879995,0.16274413915623961,50.92959007180699,265.5760854452625,0.049987539015345285
0.0516064451576916,252.628940096871,0.1638504633756708,50.92999432352919,265.6662216392259,0.050318942760942495
0.0519675337339729,252.689344460714,0.16499691960536395,50.94217184327995,265.82098649319164,0.05066225236968565
0.0523223619821555,252.777920331864,0.16612349929334372,50.96002873890379,266.0038581805643,0.050999495115818666
0.0526745530618132,252.823874957779,0.1672417059712569,50.96929319148825,266.14125957453575,0.051334118962938685
0.053013519121221,252.909359829825,0.16831792320987668,50.986526941692716,266.31697501309924,0.05165607174104839
0.0533596229457399,252.916676248111,0.16941680285272417,50.98800193161918,266.4122147294,0.051984697112044016
0.0537152998928965,252.906371840871,0.17054607715994638,50.985924563119596,266.4913134491278,0.05232229967821732
0.0540651083243208,252.90644747103,0.17165671892971854,50.98593981015964,266.5798619494704,0.05265422081504186
0.0544239352348951,252.899488640277,0.17279599437079193,50.98453690987984,266.6632740309736,0.05299458484504195
0.0547821521662767,252.924565788575,0.17393333312792852,50.98959246297672,266.7803178381942,0.0533342547682092
0.0551388991757212,252.882636021386,0.1750660048829148,50.981139421911415,266.8263061922598,0.05367241624834328
0.0554957984344736,252.880246612349,0.17619916002945368,50.98065771704956,266.91403780640786,0.05401060765830932
0.0558513077606617,252.90743087309,0.17732790214010088,50.98613806401494,267.0326416297412,0.0543473683249992
0.0562105652344952,252.924925766809,0.17846854461952225,50.9896650345887,267.1419788060541,0.05468756430305448
0.0565633826449954,252.929215621853,0.1795887398978604,50.99052986936557,267.2357476271704,0.05502154931279374
0.0569135867022367,252.894454097929,0.18070063777960152,50.983521946142496,267.28758453774634,0.05535295018966699
0.0572628433418523,252.912648820996,0.18180952761038102,50.98719000231279,267.39514620960557,0.055683345172629975
0.057609960219273,252.893723383305,0.18291162369619177,50.98337463407429,267.46292072712106,0.05601160782743668
0.0579718230621748,252.930412248624,0.18406053822240498,50.99077110932261,267.5932493545442,0.056353700815087164
0.0583273221775938,252.940957292874,0.18518924791386032,50.9928969902434,267.69432600080444,0.05668966382822007
0.0586863127890472,252.907538680796,0.18632904310522486,50.986159798048476,267.74974960252524,0.05702881196497737
0.0590507702930215,252.944124229051,0.18748619568034325,50.993535444576686,267.88066960587014,0.05737300720099976
0.0594052808722259,252.974673127276,0.18861176676931724,50.99969410245885,268.00270463796136,0.05770769489236695
0.0597676903243667,252.998046400138,0.18976241677986425,51.004406154267826,268.1191552900512,0.05804972403354574
0.0601294975019552,252.981235279299,0.19091115456870775,51.001017032306684,268.19286983406715,0.058391068116814805
0.0604848044156395,252.930236192857,0.1920392540196554,50.990735616479974,268.22867205978343,0.05872616622181923
0.0608403650813145,252.867905262981,0.1931681591331735,50.97816970101697,268.252480936528,0.05906139127276144
0.0611983999369972,252.870631130921,0.1943049197999661,50.97871923599368,268.345909147192,0.05939883549384
0.0615621875381234,252.903882490827,0.19545994543354178,50.98542271015072,268.4731987338468,0.059741585031243376
0.0619206885675099,252.958528963642,0.19659818620184394,50.99643943907023,268.6218952560951,0.06007923883276593
0.0622906623922871,252.96780431935,0.19777285309551154,50.99830935078096,268.7253364143248,0.060427578773941025
0.0626503193130039,252.947749356057,0.19891476381878737,50.994266270181086,268.79500662271965,0.060766088809982105
0.0630097665637494,252.912335606818,0.20005600883990435,50.98712685833451,268.8482828344963,0.06110428705396274
0.0633696051127826,252.875744776405,0.20119849623308475,50.97975014692325,268.90038086548657,0.06144273893819479
0.0637252271880413,252.876427127788,0.20232759632203112,50.97988770896206,268.99103489700644,0.06177711244441732
0.0640859501267235,252.872177656213,0.20347289165234708,50.979031015492545,269.077731421925,0.06211616785119742
0.0644450718038341,252.906989158717,0.20461310297717328,50.98604901439735,269.205598234742,0.06245360402367326
0.0647925288818267,252.832286284957,0.20571627919979976,50.970988915047336,269.2139294963334,0.06277997162207084
0.0651510196197816,252.777338115328,0.2068544872928066,50.95991136405013,269.2460394303159,0.06311659156825873
0.0655164120252376,252.740109629955,0.20801460818012937,50.95240610139893,269.29873478777483,0.06345957555873159
0.0658654855188234,252.712110366216,0.20912291652226428,50.94676144982915,269.3571162119733,0.06378713158903207
0.0662278761860874,252.790095995939,0.2102735068908275,50.962483352781305,269.5318471746272,0.06412707042779292
0.0665938022936559,252.80421874085,0.21143532228235748,50.96533049815535,269.6394129026803,0.06447020845461535
0.0669679937506403,252.847613975634,0.21262338015828294,50.974078977487814,269.78031140821855,0.0648209753848395
0.0673377885331961,252.826405822028,0.21379747859289758,50.96980341372085,269.8511768728797,0.0651675000387347
0.0677158415815988,252.814453963132,0.21499779702157618,50.96739391896741,269.9339974772378,0.06552163920135008
0.0680791542621829,252.784848099653,0.21615131478243071,50.96142537689005,269.9942267685717,0.06586185226936014
0.0684460483837392,252.756016839552,0.21731620361837195,50.95561299485368,270.05616739743317,0.0662053016466093
0.0688070672832532,252.751880134773,0.2184624386243289,50.95477903517023,270.1429957571751,0.06654313613172595
0.0691804834165385,252.704987933957,0.21964803484750972,50.94532556748573,270.1872411609987,0.06689245167096769
0.0695450928757844,252.688481385235,0.22080566988061548,50.94199784726337,270.26172529181207,0.06723341122821029
0.0699124595741721,252.643160246706,0.2219720591479964,50.93286110573593,270.3060649741449,0.06757683164482711
0.0702747859131714,252.612523587129,0.2231224452743192,50.926684755165205,270.36481460120046,0.06791542476860628
0.0706385507336855,252.54626887027,0.22427739857945145,50.913327804246435,270.3857712964656,0.06825524686022301
0.0709988866693415,252.499917888693,0.22542146517515924,50.903983446360506,270.4271309428903,0.06859175194064694
0.0713684204345131,252.460521893363,0.22659473487957907,50.896041213701984,270.4782305629651,0.06893672898320279
0.0717268220936885,252.468457228681,0.22773266014746096,50.89764097730209,270.57721734459057,0.06927120003740918
0.072097736538056,252.473840231897,0.22891031350832777,50.89872619075043,270.67663264768754,0.06961723063639187
0.0724694788370234,252.462597781308,0.23009059530754927,50.896459712711696,270.75843066836046,0.06996391345428227
0.0728473128112986,252.424545812408,0.23129021817587303,50.88878843578146,270.81299566245445,0.07031615418595653
0.0732212021804688,252.314075914831,0.23247731692298845,50.866517704429924,270.788815880369,0.07066459541263803
0.073585261258675,252.333769752999,0.2336332044962931,50.870487982204594,270.9018161246597,0.07100375880523634
0.0739572272200394,252.320505415238,0.23481419642362508,50.867813891711975,270.98143036650794,0.07135016961394423
0.0743333413124272,252.327352916847,0.23600835866695638,50.86919434803635,271.08368816367624,0.07170032159220988
0.0747161924056143,252.344796572022,0.2372239108878254,50.872710988919636,271.1990389452528,0.07205661965908129
0.075094202333965,252.296616267802,0.23842409241033885,50.86299783958888,271.242629417991,0.07240828781844201
0.0754671702660192,252.249622332954,0.23960826559461096,50.85352386232353,271.2861875310941,0.07275514417003984
0.0758343432271508,252.227254075385,0.24077403974620376,50.849014421597616,271.35474223217955,0.07309649377853863
0.0762106259154563,252.220224266648,0.24196873728157373,50.84759721215624,271.442085426546,0.07344619157531827
0.0765884092495312,252.186588730734,0.24316819936726153,50.840816288115974,271.5011583956867,0.07379716101722347
0.0769717221903601,252.178005337675,0.24438521795439327,50.83908587607528,271.58858070704565,0.07415314173889517
0.0773511652182854,252.125482146842,0.24558994956805613,50.82849720080335,271.6276819721222,0.07450540372716703
0.077736770346611,252.113041938744,0.24681424585048992,50.825989254850796,271.7114955813216,0.07486325931725878
0.078111415841163,252.087809863309,0.24800374529569252,50.820902468443094,271.77874560802996,0.07521082135870849
0.0784899572211843,252.041708806939,0.24920561417726017,50.81160849547891,271.82445174914983,0.07556187500138636
0.0788714478094528,251.995376401757,0.2504168467950126,50.802267882594215,271.87061657985157,0.07591553905726055
0.0792473724569188,251.925944378246,0.2516104075507172,50.788270386654396,271.89041352394986,0.07626392084953063
0.079621871694013,251.811859126462,0.25279944262849124,50.76527079989474,271.86159066486,0.07661086102839075
0.0799866364261842,251.704630486797,0.2539575706531348,50.74365350613827,271.83763725233143,0.07694866738011455
0.0803609122511332,251.629681193115,0.2551458963973479,50.72854372853199,271.85087192325557,0.0772951633214023
0.0807352445961674,251.555513755682,0.2563344015928315,50.71359157314549,271.8649096882615,0.07764159154264705
0.0811078959931162,251.610462086845,0.25751756977814394,50.724669156707954,272.0180572765647,0.07798634495573532
0.081479995616311,251.615091906075,0.25869898608178743,50.72560252826473,272.1166884915797,0.07833046935253843
0.0818541934564517,251.66118640417,0.25988706422423413,50.73489517908067,272.26070984157707,0.07867641483406658
0.0822329074837244,251.703572100713,0.261089481260825,50.74344013550375,272.4018886585939,0.07902641371440215
0.0826056488020334,251.707098385143,0.26227293494645604,50.74415103444483,272.499526555325,0.07937077317798445
0.0829910560777448,251.675649904784,0.26349660304683975,50.73781102080446,272.56247787943477,0.07972670951544908
0.0833784679777572,251.588916182065,0.2647266358293791,50.720325502304306,272.5660145735099,0.08008436955436714
0.0837652147184581,251.529912559195,0.26595455673110446,50.70843037193371,272.599369692831,0.0804412879699708
0.0841532639238756,251.503040252668,0.267186612958305,50.70301291493787,272.66784197670785,0.08079928040684942
0.0845388485538379,251.436855722277,0.26841084415843536,50.68967011361104,272.69303798903576,0.0811548722696194
0.0849304774334915,251.447959738338,0.2696542658513355,50.69190868324894,272.8035550085924,0.08151590884129756
0.0853194081559425,251.367795517434,0.2708891208951174,50.67574757631469,272.8143470604454,0.08187432906672609
0.0857091998423255,251.358488291093,0.27212670949938345,50.673871239484356,272.9022231960991,0.08223341387024753
0.0861024409148353,251.282812595742,0.27337524990460205,50.658615019301585,272.91887612018047,0.08259554571393742
0.0864888875771614,251.245862417077,0.2746022180574874,50.65116586328272,272.97583756589455,0.08295129293738791
0.0868815460167389,251.198285635711,0.27584890860314604,50.64157438415934,273.0227810484959,0.08331262889538235
0.0872684405348005,251.117975000506,0.2770772986979916,50.625383760102004,273.0326490690572,0.08366853306440356
0.0876356845892224,251.047956108284,0.2782432985707811,50.61126795143006,273.0487156065585,0.08400624363625799
0.0880221071165167,250.966643979224,0.2794701900949405,50.59487542621156,273.0572567982359,0.08436146726823796
0.0884089292900867,250.837282776063,0.28069835049602526,50.56879620765431,273.01353837232944,0.08471693194519997
0.0887967993170219,250.850472759782,0.2819298378315445,50.57145530837205,273.1251918480125,0.08507323270809278
0.0892105621725593,250.836632456847,0.28324353489787574,50.568665103300354,273.21390945179394,0.08545317895421725
0.0895966373749753,250.86256736616,0.28446932366554656,50.573893581017856,273.3390098454211,0.08580757029874461
0.0899821779386241,250.833545625316,0.2856934149551315,50.56804279806371,273.4040943607491,0.08616134559235741
0.0903652912989256,250.766660167147,0.28690979987408877,50.55455868969683,273.4272624612099,0.08651276972970229
0.0907540154055548,250.711932765862,0.2881439989126365,50.54352564559778,273.46504737445144,0.08686921434009108
0.0911485173136955,250.630671568432,0.2893965424709832,50.527143388195896,273.47528567523034,0.08723082711291079
0.0915350553837204,250.625608208441,0.2906238008433123,50.52612261482171,273.56663713637926,0.08758501319732627
0.0919251119834995,250.578460493346,0.2918622305476109,50.51661763545855,273.6129135348497,0.08794229620139277
0.0923234234970062,250.546550930703,0.29312686960299467,50.51018466762973,273.67786625799255,0.0883070088350074
0.0927213080066871,250.506599178086,0.2943901529212315,50.50213039430214,273.733898718185,0.08867119773086103
0.0931271206575265,250.485135477894,0.2956786080876466,50.49780331234343,273.81209491246074,0.08904250678429797
0.093523463506875,250.465393260332,0.2969369966343281,50.49382328128293,273.88978432664976,0.0894050181581398
0.0939186884083806,250.368874364852,0.29819183569660834,50.47436507195416,273.8831906634815,0.08976637619950371
0.0943177706867075,250.353104943648,0.29945892193029633,50.47118595663944,273.9658516864282,0.0901311286293362
0.094724030281873,250.280410178221,0.30074879614494676,50.45653069192936,273.9879793309024,0.0905023043644455
0.0951294545858273,250.193187476318,0.30203601831000165,50.43894659522571,273.99392894202975,0.090872579646685
0.0955279216930317,250.11358272798,0.30330115137537567,50.42289827796077,274.00641347318214,0.09123636735343806
0.0959202961569162,250.007595443815,0.30454694029820895,50.4015312414731,273.9883980402642,0.09159446339685011
0.0963156393789428,249.946824834224,0.3058021550281434,50.389279886579565,274.0206130788689,0.09195513919812133
0.0967176718563642,249.924532982177,0.3070786081439563,50.384785849206885,274.0966519520023,0.09232178431916484
0.0971205763770656,249.892851069219,0.30835782999718325,50.37839877555455,274.16258879756975,0.09268908990840365
0.0975316059787661,249.858760347006,0.30966284898258234,50.37152608595641,274.22788651151313,0.09306366371085938
0.0979328739118041,249.814312686738,0.310936874669978,50.36256543764638,274.2793462724523,0.0934292063476742
0.098338750610155,249.757411201067,0.3122255331872421,50.35109409813511,274.3182429742066,0.09379881154444455
0.0987498146337632,249.793150344139,0.31353066146219816,50.35829910937842,274.4601776374065,0.09417300131076295
0.0991528609312567,249.753023472651,0.31481033345674003,50.35020953208644,274.51675027619564,0.09453975667849779
0.0995562475923518,249.62717492046,0.3160910861057169,50.32483846396474,274.4791197526206,0.09490668713242388
0.0999522625203033,249.567752650253,0.31734843350196296,50.31285893429101,274.5126141797532,0.09526678115380188
0.100355515773552,249.494577402323,0.3186287625810276,50.29810680430832,274.53273440023753,0.09563332374547177
0.100777842705122,249.441537529246,0.3199696505887623,50.28741396589599,274.57971756249214,0.09601705963782521
0.101189467138234,249.380701869965,0.32127655816389294,50.27514949698495,274.61540220674556,0.09639092934612349
0.101602555592208,249.326406232566,0.3225881140052604,50.26420349648531,274.65860628241575,0.09676598832087344
0.102013003837669,249.250058604767,0.32389128718459903,50.24881181472103,274.6768057897543,0.09713851087677133
0.102426967557674,249.153095620365,0.3252056219956149,50.22926407706558,274.6730916623662,0.09751408356665396
0.102838378672333,249.118652140483,0.3265118522846573,50.222320271521376,274.7376104236472,0.0978872006794181
0.103264798459031,249.071699251391,0.3278657351074234,50.21285456908043,274.79203807643427,0.09827378259129668
0.103674151932833,249.061983457428,0.3291654323867447,50.210895865017484,274.88327337108615,0.09864475205415742
0.104088167948989,248.992145450837,0.33047993323804004,50.19681652288874,274.9092817045028,0.09901980693871693
0.104504045319226,248.918532333039,0.3318003438885425,50.181976118340664,274.93152591676613,0.09939640645097998
0.10491332396265,248.84988933788,0.3330998035814137,50.16813769051661,274.95755839605465,0.09976689204034464
0.105343171539793,248.738145761874,0.33446456963884275,50.145610185593796,274.9410109193571,0.10015584923462216
0.105758159575243,248.788229694317,0.3357821566513965,50.155707106374315,275.0996149907708,0.1005312169615399
0.106185685384325,248.723401693078,0.33713955109523186,50.142637781324524,275.1342665729783,0.10091777814425706
0.106609775103293,248.609445716852,0.3384860359529553,50.11966425651736,275.11364281327997,0.10130108489965593
0.107034290116315,248.516589941144,0.33983387111930013,50.100944532134626,275.1163867276217,0.10168462896159068
0.107443408999192,248.459501819237,0.3411328235724346,50.08943556675818,275.1548376929368,0.10205412366248111
0.107865615292129,248.437180358031,0.34247332855250956,50.08493556017905,275.2350096787916,0.10243529513194133
0.108290471774905,248.364970081146,0.34382224788532334,50.07037796835903,275.26052986359343,0.10281871260913095
0.108730754589347,248.282893573803,0.3452201458211767,50.05383134447869,275.2788799437091,0.10321589673618795
0.109159239894357,248.173536030776,0.34658058666458347,50.03178486380444,275.26397058579033,0.10360228678385193
0.109592559130864,248.104287283597,0.3479563752404932,50.01782431637315,275.29467105834544,0.10399288409375063
0.110015735401204,248.07739284693,0.3492999598988227,50.01240239794109,275.3698096573984,0.10437419126088433
0.110452172461398,248.066049469977,0.35068564756493864,50.01011557314737,275.4654835478526,0.10476729495247021
0.110884668589286,247.997439314655,0.35205882277098305,49.99628376583445,275.49655318405206,0.10515669661849433
0.11131336657634,247.911347398317,0.3534199388798795,49.9789276355007,275.5071940897002,0.10554252901109684
0.111749221561774,247.768627489307,0.3548037784586324,49.95015530184429,275.45657873866617,0.10593465021663044
0.112182705089815,247.69533031561,0.3561800886601626,49.93537859162698,275.4824625085304,0.10632448547043113
0.112615542827141,247.564903198886,0.3575543484761726,49.90908448489541,275.44455915757715,0.10671358838634021
0.113033173604752,247.502504004796,0.3588803261950876,49.896504807366874,275.478497507581,0.10708887742403016
0.113468645937547,247.414786072348,0.3602629508517117,49.87882087218535,275.48860683290513,0.10748004920258024
0.113907525382063,247.358526909966,0.36165639308805003,49.86747902504914,275.53452459243266,0.10787412673276747
0.114348578252225,247.322061688292,0.36305673595081434,49.860127636359664,275.60298781275725,0.10826999942909045
0.114794512035899,247.279135887094,0.3644725757139793,49.85147379483815,275.6654236279117,0.10867009378962353
0.115243747962681,247.262250573748,0.36589889978151213,49.8480697156676,275.75767905955433,0.10907298905910572
0.115683653065059,247.186243556272,0.3672955984815623,49.83274670094443,275.7816511982909,0.10946735877985646
0.116127273877481,247.05253466894,0.3687040945610021,49.805790989258306,275.74207202456586,0.10986490214960092
0.116553421236103,246.947432881157,0.370057112424627,49.78460246884125,275.7300010489288,0.11024663820772118
0.117004614442447,246.806733260133,0.3714896508547692,49.756237425242816,275.6842599270347,0.11065065118188522
0.117447395358546,246.721054854354,0.37289548026338354,49.73896465863777,275.69780012711084,0.11104697289293781
0.11787530150024,246.671942418926,0.374254082263262,49.729063591655475,275.74847200320676,0.11142983139253816
0.118319325316106,246.610682991684,0.37566385787863654,49.716713691123495,275.7894926190042,0.11182695587926829
0.118767941132623,246.534027108796,0.377088213096078,49.70125986513328,275.814365927642,0.1122280272449309
0.119236624854535,246.424256555965,0.37857628391314857,49.67913012168255,275.8070531899863,0.11264686797107289
0.119701455291888,246.334164608657,0.38005212055174437,49.660967585105254,275.82072260042474,0.11306209199906496
0.120148709881375,246.233639624687,0.3814721538733656,49.640701748336895,275.81829375498853,0.11346145317275907
0.12059108998911,246.063343573762,0.38287671071542423,49.60637006447042,275.7363903816869,0.11385630501009264
0.121022003689176,245.910088377149,0.38424486171313377,49.57547381683324,275.67061999993393,0.11424077252287547
0.12146334370552,245.777051228425,0.385646116265026,49.54865352765048,275.6299536767124,0.11463438938423409
0.121916124328615,245.720723640295,0.3870836947433526,49.537297885883476,275.67804193374246,0.11503804880582984
0.122379996096146,245.711947020418,0.3885564876052635,49.535528519316266,275.78217413755317,0.11545142720978907
0.122853886024472,245.646731951715,0.3900610881276986,49.522381161465745,275.82538756119504,0.1158735568944841
0.123328290101683,245.560685200248,0.39156732107284353,49.50503413637,275.84526462219225,0.11629596616235839
0.123798948645095,245.423737591086,0.3930616619481766,49.47742549836294,275.80693827741214,0.11671486415992519
0.124279149249505,245.247970743285,0.3945862988671784,49.44199090184626,275.72717990242796,0.11714207406171918
0.124748366517775,245.149327774307,0.3960760636939356,49.422104479300295,275.73130596708245,0.11755933643115524
0.125218929176889,244.998128451591,0.3975701001366226,49.391622695840745,275.6765317466411,0.11797762043632742
0.12568873440822,244.874553472498,0.3990617317460985,49.3667099800556,275.6525261872343,0.11839505669615587
0.126155898251092,244.706132232154,0.4005449769472171,49.33275625800225,275.5772541514519,0.11880997328746823
0.126631258891438,244.546136097827,0.4020542469803156,49.30050103732193,275.5133211689318,0.11923199331354488
0.127119857224614,244.445868889611,0.4036055466881494,49.28028716814558,275.5197928420051,0.11966558009012965
0.127614436682013,244.367503219146,0.40517583646539124,49.264488648979835,275.55232448584735,0.12010428319290145
0.128123345463706,244.269147635079,0.40679162184726647,49.24466016323193,275.56572802365326,0.12055549591306351
0.128628878180416,244.099416322725,0.40839668822282077,49.210442330661365,275.4976504088114,0.12100351383888559
0.129130008742287,243.898678728987,0.4099877777567612,49.16997363176378,275.39331724549334,0.12144743242824725
0.129638780453736,243.708145407642,0.41160312794061177,49.13156211418063,275.3021721649305,0.12189791830576292
0.13014350448817,243.510181576637,0.4132056267499397,49.09165260585002,275.2014499855712,0.12234461978332567
0.130637888194798,243.324852278977,0.4147752950184836,49.05429021944177,275.11229712601374,0.12278197627971989
0.1311414227722,243.144053489524,0.416374017301735,49.01784118348804,275.0303106027401,0.12322723155575799
0.131649958743381,242.927632523677,0.41798861901023465,48.974210716773285,274.9090453230463,0.12367670823654854
0.132178459290638,242.755909611752,0.4196666082477757,48.9395913777292,274.8430117279308,0.12414361690564042
0.13271128779851,242.557207199423,0.4213583387602692,48.89953297140368,274.74728653166846,0.12461412856598635
0.133260207587137,242.362908232757,0.42310115908915996,48.86036229972381,274.66023969527646,0.12509861815509388
0.133809270258461,242.135623548636,0.4248444330706137,48.81454170740501,274.53561463925644,0.12558299914775858
0.134373668310367,241.865951859549,0.4266363968854152,48.76017589488508,274.36636705029525,0.12608066452911532
0.134953193486449,241.602774074424,0.4284763893194755,48.70711925340388,274.20783999095255,0.12659141086401832
0.135521214066773,241.287210402257,0.43027985466200425,48.64350161709501,273.98674609475574,0.12709176496647806
0.136098906079508,240.976655620859,0.4321140268024379,48.58089377316517,273.7733148415562,0.12760038171983856
0.136672576452578,240.630978836548,0.4339354302369351,48.51120533344808,273.51863468844476,0.12810520183894175
0.137266883487792,240.29973545909,0.4358223550737396,48.444426668552545,273.28493124850013,0.1286279132472404
0.13785835733891,239.973189680477,0.4377002845510392,48.37859503958416,273.0554994152062,0.12914786164729283
0.138453839814653,239.555082335539,0.4395909414115233,48.29430459884467,272.7224033320097,0.12967106096070113
0.13906455432092,239.17069767404,0.44152995996892097,48.216812651086464,272.43086415270386,0.13020735917236603
0.13967122416344,238.734489957971,0.443456136718922,48.128873175526955,272.07882842043523,0.1307398209545362
0.140283900369897,238.315350508511,0.44540138367442295,48.04437466251582,271.747157395864,0.1312772668144235
0.140905512510643,237.853129700734,0.4473750022212915,47.951190947667975,271.3679468434764,0.13182225632964903
0.141537032175039,237.40393722973,0.4493800771557488,47.86063374551357,271.00538593189526,0.13237562813914475
0.142180515516716,236.875169813387,0.45142313676557333,47.75403423437882,270.554203570564,0.13293916837147943
0.142839861938049,236.343347290767,0.45351656165330556,47.646818813818626,270.1025983877566,0.13351627170599506
0.143521383194294,235.847448980576,0.4556803916418834,47.546845714484114,269.69660108111395,0.13411243408224324
0.144215421532931,235.2021615447,0.45788396336705584,47.41675576741152,269.12194041732545,0.134719180766123
0.144928994374116,234.593197552219,0.46014955713781824,47.29398862652735,268.5925537604705,0.1353426214362171
0.145645626140861,233.881221745653,0.4624248629972336,47.150454303923645,267.94499872938815,0.13596834371892147
0.146356198428789,233.180475709266,0.46468093001140504,47.00918390298803,267.3078836818907,0.13658838887165745
0.147086718796888,232.443799919839,0.4670003321801194,46.86067006383954,266.6331957547285,0.13722544016891733
0.147819996962515,231.722357759914,0.46932849035598506,46.715227324398654,265.9755559801313,0.1378644885324488
0.148556329898768,230.916909182862,0.4716663474285884,46.552848891264986,265.22107772263513,0.138505788438632
0.149311291249762,230.033409603329,0.47406334971799435,46.37473537603113,264.37999502178747,0.13916288580247518
0.150055147539744,229.156516726861,0.47642509343868716,46.19795377213518,263.54263165400397,0.13980989560777016
0.150817041340656,228.226884511085,0.47884410625658275,46.010539917434734,262.6473879874424,0.14047216084131156
0.151577351707803,227.249174064344,0.4812580916722745,45.813433491371754,261.6950020468028,0.14113261275787253
0.152348690811023,226.276476207497,0.483707093324998,45.617337603431395,260.7494011190408,0.14180219947012276
0.153113263628008,225.263050508545,0.4861346120189254,45.41303098252268,259.75381134670914,0.1424654703113896
0.153852175247736,224.128874864082,0.4884806564115618,45.18438117259893,258.61158979774865,0.1431060621750946
0.154585918020516,223.017072129365,0.49081028971513824,44.96024174127999,257.49237095873053,0.1437417671564236
0.155329552224184,221.86142572568,0.4931713283117841,44.727263426297085,256.3230616394689,0.1443856298768886
0.156088699939656,220.711161679077,0.49558162230840774,44.49537019450193,255.16167996773535,0.14504249735819144
0.156863386615078,219.508681582146,0.4980412525028727,44.25295020696064,253.94155676653222,0.14571236571291746
0.157630519486813,218.208360515758,0.5004768993706312,43.99080547997681,252.6046577402227,0.14637526043716315
0.158417320404087,216.852980580578,0.5029749922829762,43.71756088504452,251.20624868579267,0.14705469454382536
0.159195535590701,215.473943783671,0.5054458255004756,43.43954706678807,249.77643367015312,0.14772626073215495
0.15997346622784,214.069844586508,0.507915755273392,43.156480668640015,248.3153396398667,0.14839713091514348
0.160753368849711,212.612844903847,0.5103919460978324,42.86274953261555,246.79107598286149,0.1490692502179778
0.161541964960839,211.133920277175,0.5128957387506639,42.564598327878485,245.24090862863497,0.14974840254624397
0.162368276328279,209.625511858172,0.5155192773422858,42.26050319060747,243.66204489301657,0.15045954137388223
0.163194566101671,207.924200884367,0.5181427473728054,41.91751889828839,241.85630062972794,0.15117015627801422
0.164023551624249,206.19228494393,0.5207747764069905,41.56836464469629,240.01267583795254,0.15188258245872033
0.164845131929611,204.433354417931,0.5233832938765149,41.2137642506549,238.13319769776777,0.1525881442151619
0.165673762004382,202.612660769771,0.5260141943639128,40.846712411185834,236.18026250921662,0.1532992563300187
0.166514583417338,200.753477444377,0.5286838023500481,40.47190105278641,234.18185911060942,0.15402031425918378
0.167364238611379,198.780430120144,0.5313814575911283,40.07413471222103,232.0491654580443,0.15474841995478159
0.168195722566373,196.781587258022,0.5340214191482342,39.67116799121724,229.8794085146428,0.1554604410580233
0.169043027699774,194.66310937333,0.5367116129467824,39.24408284966333,227.56955076324996,0.15618548908353908
0.169881087851572,192.422062817108,0.539372453928741,38.792287863928976,225.11093217512183,0.15690210932965204
0.170737194962043,190.073905702481,0.5420905940044866,38.31889938962017,222.5265911976025,0.1576336315560093
0.171593644327488,187.627985671565,0.5448098207397744,37.8258019113875,219.82375551077453,0.15836491117650178
0.172458797023858,185.007873683488,0.5475566805507491,37.29758733459118,216.9141090188842,0.15910307958979544
0.173366233882025,182.121529934746,0.5504377925754294,36.71570043484479,213.6952536883654,0.15987674078913805
0.173828758925791,180.660119256329,0.5519063095893864,36.42108004207593,212.06404357404207,0.16027084954547904
0.174056407727465,179.884054997435,0.5526290945347013,36.264625487482895,211.19402741773825,0.1604647677196901