File: example/data/02 processed data/test_ID_091.csv
Strain,Stress_MPa,Displacement(mm),Force(kN),True Stress (MPa),True Strain
0.0010929616782865983,62.8521211497185,0.0034701533285599493,25.3419752475665,62.92081610953417,0.001092364830519789
0.0011923066930245984,68.9279641781177,0.0037855737503530995,27.79175515661706,69.01014745114384,0.001191596459887257
0.0012979977382716983,75.1631293978154,0.004121142819012642,30.305773773199167,75.26069096977518,0.0012971560674532021
0.0014029216907978984,81.4951298597403,0.0044542763682833275,32.858836359447295,81.60946114511492,0.0014019385156003369
0.0015073556478449983,87.8347776591011,0.004785854181907869,35.41498235214957,87.96717590728277,0.0015062207276629732
0.0016131418573854983,94.1827452479552,0.005121725397198957,37.97448288397553,94.33467537655815,0.0016118421416223203
0.0017213647389584983,100.48244773515,0.005465333046193232,40.51452292681248,100.65541467756553,0.0017198848886742027
0.0018276112032679984,106.835795792529,0.005802665570375894,43.076192863547696,107.03105008982948,0.0018259431539673617
0.0019369886708251983,113.149356122243,0.006149939029870004,45.62182038848838,113.36852514316296,0.001935115127234714
0.002048936981466698,119.509108103231,0.006505374916156766,48.18607238722274,119.7539747344458,0.0020468407729340994
0.0021530453313362984,125.844052635593,0.006835918926992747,50.7403220226711,126.1150005855965,0.0021507308507626066
0.0022647459483566986,132.159754344127,0.007190568386032517,53.28681295155201,132.4590626123137,0.0022621852767031065
0.0023746629169803983,138.487665025126,0.007539554761412764,55.838226538130804,138.81652654772037,0.0023718478606547834
0.0024817562249940983,144.791759050131,0.007879576014356262,58.380037249012815,145.1510968994815,0.0024786817536889103
0.0025970651748486984,150.965889474483,0.008245681930144617,60.86944663611155,151.3579577286272,0.0025936986285876916
0.0026997770481533984,157.051887243739,0.00857179212788704,63.323320936675564,157.47589232428882,0.002696139196220316
0.0028042118397872983,163.051852127593,0.008903372591324671,65.7425067778455,163.50908406182845,0.00280028737274548
0.0029098217533079984,168.979534434934,0.009238684066752894,68.1325482841654,169.47123476009662,0.002905596416656398
0.003011823560404698,174.876553278744,0.009562539804284917,70.51022628198959,175.4032506020713,0.0030072971061354294
0.0031218630104665984,180.656817975281,0.00991191505823145,72.8408290076333,181.2208038129066,0.0031170001143735184
0.0032312784884408986,186.376346935153,0.010259309200799852,75.14694308425369,186.9785808157588,0.0032260691270211217
0.0033375993605945986,191.93280380166,0.01059687796988785,77.38730649282931,192.57339860490555,0.0033320419380488183
0.0034439501997198985,197.525626995991,0.010934541884110678,79.64233280478356,198.20589541853363,0.003438033384151272
0.0035495986796763982,202.978882234814,0.011269975807972564,81.841085317077,203.69937580719687,0.0035433137226087564
0.0036594748179560985,208.387168392179,0.011618832547010611,84.02170629572659,209.14975598729538,0.003652795230878473
0.003765139110719098,213.579703757721,0.011954316676533136,86.11533655511312,214.383861053595,0.003758068716246209
0.0038774664674868986,218.346672622901,0.012310956034270902,88.0373784015537,219.19330452428366,0.003869968470289
0.003987282937084299,222.823187737303,0.012659623325242649,89.84230929568058,223.71164683175468,0.0039793547919916615
0.004105126918051498,226.93727874275,0.013033777964813507,91.50111078907682,227.8688850744262,0.004096723873737075
0.004234009899485299,230.764191836328,0.013442981430865824,93.04412214840744,231.74124970900974,0.004225071700304885
0.004377776746223999,234.379718110044,0.013899441169261197,94.50190234196974,235.4057801897727,0.004368222156694838
0.004548316183643498,237.669561731691,0.014440903883068106,95.82836729021781,238.75055804567472,0.004538003850933621
0.004747814533744399,240.68947348489,0.015074311144638466,97.04599570910764,241.83222246522087,0.0047365792104405845
0.004996977576322498,243.245961282141,0.01586540380482393,98.07677158895926,244.46145589619888,0.004984534119773155
0.005286065039449398,245.260288556672,0.01678325650025184,98.88894834605014,246.55675039357672,0.00527214283853699
0.005624996891019699,246.760644535973,0.017859365128987545,99.49389187690431,248.1486723943139,0.005609235672920599
0.0059945331325061985,247.814930609749,0.01903264269570718,99.9189800218508,249.30046542201887,0.005976637400859539
0.006381239336130898,248.498957909288,0.0202604348922156,100.19477982902492,250.0846892344863,0.0063609654311163055
0.006788568599182698,249.01442094766,0.021553705302405066,100.40261452609651,250.70487242644893,0.00676563002225477
0.007201564513000998,249.410680943732,0.022864967328778168,100.56238655651273,251.2068280527798,0.007175757075825938
0.007617287040127799,249.722134837203,0.02418488635240576,100.68796476636024,251.62434001853148,0.007588421998735428
0.008032568383404898,250.086857451889,0.02550340461731055,100.83502092460165,252.0956972361621,0.008000479031394616
0.008448230114678098,250.381985373259,0.02682313061410296,100.95401650249804,252.49727000226224,0.008412743544371864
0.008867545088591998,250.626210392201,0.02815445565627959,101.05248803013545,252.84864961323677,0.008828459304003573
0.009286689668117198,250.912888773666,0.029485239696272102,101.16807675354214,253.24303890543783,0.009243833489319163
0.009693441263108298,251.125199862053,0.030776676010368844,101.25368058437977,253.55946723660213,0.009646761278713969
0.010098053892011198,251.355953433717,0.032061321107135554,101.3467204244747,253.89415939756853,0.010047409202309928
0.010487582766359098,251.611075641051,0.033298075283190134,101.44958569847176,254.24986762176917,0.010432969578575448
0.010879963992151997,251.796643707004,0.03454388567508259,101.52440674266401,254.5361821238809,0.010821203011283505
0.011270124519846898,252.054165042516,0.0357826453505139,101.62823934514245,254.8948468682912,0.011207089830222498
0.011655172025334098,252.268081340567,0.03700517118043576,101.71449039651661,255.2083092250923,0.01158777369511348
0.012038629674364597,252.486906079471,0.038222649216107595,101.8027205312427,255.52650243938783,0.01196674175174107
0.012413323495111197,252.670327906683,0.03941230209697805,101.8766762119746,255.80680642460447,0.012336909909536474
0.012793269964837498,252.832461151762,0.040618632138359055,101.94204833639044,256.06701508315075,0.012712127406270795
0.013167611120897697,253.032985828308,0.04180716530885019,102.02289988597379,256.36482578645473,0.013081671718616695
0.013548609211609698,253.240500064668,0.04301683424686079,102.10656962607415,256.6715566365968,0.013457647488068726
0.013912178340328098,253.415433078137,0.04417116623054171,102.17710261710485,256.9409937773116,0.013816292286377768
0.014282281840418899,253.563761529569,0.04534624484333,102.23690864872222,257.1852306362511,0.014181250885234907
0.014648058924552999,253.776650254227,0.04650758708545577,102.32274538250432,257.49398558082663,0.014541812389735762
0.015006687526918498,253.949601650873,0.047646232897966226,102.392479385632,257.7605439704331,0.0148952011685168
0.015391342729086297,254.094404009047,0.04886751316484899,102.45086369644774,258.00525806669316,0.01527409752384978
0.0157632083895747,254.34521122232,0.050048186636899666,102.55198916483941,258.3545077897078,0.01564025938429344
0.016140077453209698,254.561753581592,0.051244745913940785,102.6392990440979,258.6704000010238,0.016011211161951765
0.016503226043551398,254.747795505577,0.052397742688275684,102.71431114784865,258.9519559589019,0.016368527759094736
0.0168516443454401,254.942865883831,0.05350397079677231,102.79296352436066,259.23907238811256,0.016711230658989478
0.017194916055401098,255.166108448298,0.05459385847589848,102.88297492635375,259.55366826324985,0.01704875657398349
0.0175345131789682,255.315439305679,0.05567207934322403,102.94318512804978,259.7922712409785,0.017382557345566325
0.0178703845232579,255.588773465643,0.05673847086134382,103.05339346134726,260.1562431273019,0.01771258637096323
0.018220798775666597,255.769783020801,0.05785103611274144,103.12637651398697,260.4301127701189,0.018056789281660532
0.0185721083195395,255.894944909506,0.058966443914537904,103.17684178751283,260.64745354478794,0.01840175272505528
0.0189266775459702,256.116435598849,0.060092201208455376,103.26614683345593,260.9638687896517,0.018749796348413037
0.019280277118870096,256.247679346754,0.06121487985241255,103.31906431261123,261.18820561562677,0.019096767568031338
0.019634543546008697,256.384166917365,0.06233967575857761,103.37409610108158,261.4181530072112,0.019444272453584457
0.0199853370265097,256.619741451311,0.06345344505916829,103.46907975316859,261.7483734718712,0.01978825172864559
0.0203348297020815,256.791046186959,0.06456308430410876,103.53814982258187,262.0128483801902,0.020130837843010563
0.020693915269313697,257.02077641399,0.06570318098007098,103.63077705012078,262.33954258355436,0.020482705078415032
0.021045971647579997,257.221948832738,0.06682095998106649,103.71188976935997,262.63543467500705,0.02082756426837474
0.021400224420628798,257.386009825259,0.06794571253549643,103.77803916154444,262.89412819824975,0.021174454950032073
0.021754319165838597,257.575799442256,0.06906996335153755,103.85456233511763,263.1791855927189,0.021521070677037683
0.022107466604885898,257.772064366889,0.07019120647051272,103.93369635272965,263.47075167155253,0.021866639487042525
0.022460273301614497,257.994093734243,0.07131136773262602,104.02321859364679,263.78871158971646,0.022211755663282838
0.0228085763901673,258.119032461077,0.07241723003878117,104.07359388830625,264.00636013072153,0.02255234960717658
0.0231545104790869,258.336133348296,0.0735155707711009,104.16112896603296,264.31778005503594,0.022890512201053592
0.0235044769908488,258.490373577488,0.07462671444594493,104.22331862644316,264.566054615596,0.02323250030685465
0.0238460184525848,258.658958035727,0.07571110858695673,104.29129188000512,264.8269443219733,0.023566142705324727
0.024185006394212,258.879009904568,0.0767873953016231,104.38001679352183,265.1400004144373,0.023897180605249292
0.024519930266908296,259.078653799411,0.07785077859743383,104.4605132119225,265.431244324217,0.024224142160021517
0.024849188654303998,259.303301070261,0.07889617397741519,104.55109099152924,265.74677771723975,0.024545468745055705
0.025187617736379397,259.428469365226,0.07997068631300458,104.60155884805914,265.96285448153134,0.024875637534313304
0.0255294658612063,259.569998566915,0.08105605410932999,104.65862342218011,266.19668198392236,0.025209031282995047
0.0258767346802186,259.737127573626,0.08215863260969404,104.72600983768602,266.45827631045086,0.02554759789377943
0.026224176454198698,259.962099449299,0.08326176024208086,104.81671849795735,266.7793914166613,0.025886218451291673
0.026572494409724198,260.131906934945,0.08436766975087433,104.88518487616983,267.0442605777647,0.02622557788597131
0.026922909560739797,260.341366922545,0.08548023785534885,104.96963914317014,267.35051399912004,0.026566864410147956
0.027268313314311097,260.454641619173,0.08657689477293773,105.01531150085054,267.5568003910112,0.026903156137013634
0.0276127594149236,260.668521767621,0.08767051114238242,105.10154797670477,267.86629894623405,0.027238402890132175
0.0279563042095588,260.831142835114,0.08876126586534919,105.16711679111798,268.1230176115393,0.027572660496858404
0.028297686508845198,260.957767212765,0.0898451546655835,105.21817174018686,268.34226830140005,0.027904703429262514
0.0286411295053448,261.134136553659,0.09093558617946973,105.28928385843533,268.61331317695874,0.028238639467629206
0.028985579067118697,261.370696247148,0.09202921353810185,105.38466472685006,268.94667722904757,0.028573442241676038
0.029327381933417,261.538429966829,0.09311443763859897,105.45229496262547,269.2086673927325,0.02890556167726852
0.0296688064868679,261.749821315254,0.09419846059580557,105.5375279543104,269.51562611182857,0.0292372034340629
0.030008971860818696,261.841118678024,0.09527848565809936,105.57433905097928,269.6987014404381,0.029567512748092047
0.030344888291890998,261.933587281644,0.09634502032675392,105.61162239195886,269.8819327275998,0.029893589195973503
0.030676158651773797,262.134247483702,0.0973968037193818,105.69252858542865,270.1755192475754,0.030215051573300285
0.031009348725526,262.287238208388,0.09845468220354504,105.75421444562204,270.420594644247,0.030538272622738435
0.0313419512847911,262.464330273116,0.09951069532921174,105.82561796612038,270.69047452653126,0.030860819574023438
0.0316740892436859,262.652154083811,0.10056523334870272,105.90134852659261,270.971421852308,0.031182812186043598
0.0320169966842744,262.79997719818,0.10165396447257122,105.96095080630617,271.2140431967615,0.031515136579052444
0.0323555186534892,263.046625297765,0.10272877172482821,106.06039932005885,271.5576352893242,0.03184310255392751
0.0326968953341548,263.22187176033,0.10381264268594148,106.13105869376504,271.8284097509378,0.03217372533276167
0.0330400388704038,263.381188350097,0.10490212341353206,106.1952951427591,272.0833130509173,0.03250594918345943
0.033384231744457496,263.588148129483,0.10599493578865254,106.27874132580756,272.38783595173004,0.03283907813682232
0.033727116800037996,263.777377782647,0.10708359584012063,106.35503872196328,272.6738282123301,0.03317083100438478
0.0340715001825469,263.960734663648,0.1081770130795864,106.42896821638287,272.9542728829257,0.0335039228082623
0.0344208964214476,264.098582049495,0.10928634613809612,106.4845482823564,273.18909198727187,0.033841749761648575
0.034762680895085295,264.268921948904,0.11037151184189581,106.55322932979809,273.45561815310197,0.034172106604311525
0.035105516813483596,264.390925378405,0.11146001588281042,106.60242111257288,273.67250545460905,0.034503370132987175
0.035445424886662795,264.515719191245,0.11253922401515437,106.65273797790998,273.89159124717986,0.03483169634741351
0.035789654759358996,264.669910426758,0.11363215386096481,106.71490788406884,274.14235514612216,0.035164087276138484
0.036135187448322795,264.853013140226,0.11472922014842486,106.78873489813913,274.4235264163012,0.03549762513921947
0.0364769231524852,265.027489321164,0.1158142310091405,106.85908369429333,274.69487668242823,0.03582738844177987
0.0368191338857493,265.20944332614,0.11690075008725401,106.93244754909965,274.9742253277302,0.03615750119650199
0.0371577441872846,265.441979573462,0.11797583779462859,107.02620616401988,275.3052047470191,0.03648403357796086
0.0375092767111397,265.525501915429,0.11909195355786853,107.05988237230099,275.48517144063914,0.03682291449106967
0.0378570361499918,265.628721057762,0.12019608977622397,107.10150033048964,275.6846371533218,0.03715804515205384
0.0382030683478668,265.714299935066,0.12129474200447708,107.1360057338186,275.86540149649085,0.03749139985631285
0.038531888459890896,265.885333114764,0.12233874586015359,107.20496631187285,276.13039711346306,0.037808070131153754
0.0388620363917716,266.02558355775,0.12338696554387481,107.26151529048481,276.3638794671135,0.03812591830689997
0.0391972363041466,266.188510421542,0.12445122526566545,107.32720740196574,276.62236436598397,0.038448526925130004
0.039540564269091,266.362425549899,0.12554129155436392,107.39732998171928,276.8945461562257,0.03877885042044667
0.039887715178837796,266.473392194524,0.12664349569281,107.44207173283209,277.1024069651179,0.03911274115031986
0.040230760401685696,266.691203450647,0.12773266427535207,107.52989323130087,277.42039335790713,0.039442573542065845
0.0405737720913726,266.823472294649,0.128821726390108,107.58322402920247,277.64950704816073,0.03977226495463022
0.040917231030002096,266.982937380235,0.12991220852025664,107.64752035171075,277.9071399100907,0.04010227737479596
0.0412672200591954,267.105136421538,0.1310234236879454,107.69679100516413,278.12782286518706,0.04043845223414275
0.0416169995424322,267.229272156956,0.13213397354722223,107.74684253368466,278.3505526540365,0.04077431294424182
0.0419663227270483,267.382197777641,0.13324307465837834,107.80850214394486,278.603245381045,0.04110962296919304
0.042315397530764895,267.537356484479,0.13435138716017853,107.87106213454194,278.8583060784497,0.04144458230178948
0.0426620636417867,267.660801117105,0.13545205206267277,107.92083501041674,279.07976324877455,0.0417771193394047
0.0430094069008604,267.818084287715,0.13655486691023178,107.9842515848067,279.33678125025426,0.042110195058366814
0.043357533952540495,267.92921416571,0.13766017029931607,108.02905915161428,279.54596416577726,0.04244391109660934
0.0437052731651405,268.089441248967,0.13876424229932108,108.09366271158349,279.80636351144295,0.04277714420740202
0.0440540823892345,268.251314709202,0.13987171158581954,108.15893009075026,280.0688802284217,0.043111291173537465
0.044399067694026496,268.272038025771,0.14096703992853413,108.16728573199087,280.18306640249165,0.04344166517107336
0.044748665055539996,268.379725849263,0.14207701155133948,108.21070546242285,280.38936030898935,0.04377634458057268
0.0450965937233871,268.513522428223,0.14318168507175402,108.2646522430595,280.62256765840414,0.04410931533005775
0.045443876945351395,268.67412572929,0.14428430930149067,108.32940749404972,280.8837196373317,0.04444155785779765
0.045783576944558,268.873886988058,0.14536285679897165,108.409951233585,281.18389528135816,0.04476643882812222
0.046113862835962395,268.966393618979,0.1464115145041806,108.44724990717233,281.36947300180805,0.04508221520211449
0.0464503497530014,269.045981729035,0.14747986046577943,108.47933983314692,281.5432616799883,0.04540381768189971
0.0467867804658288,269.222101162717,0.14854802797900643,108.55035118880751,281.8181365063662,0.04572526307465291
0.0471391518939685,269.329604640587,0.14966680726335,108.59369659108467,282.0255737832821,0.04606182840012158
0.0474948557038718,269.522000105952,0.15079616685979294,108.67127044271983,282.322908610003,0.04640146177953977
0.0478494215929461,269.685543706284,0.15192191355760384,108.73721122237372,282.5898409846089,0.04673989388952801
0.0482001782809531,269.763146601915,0.1530355660420261,108.76850070989214,282.76577836175824,0.04707457746886908
0.048545189891970895,269.876381077968,0.15413097790700758,108.8141568506367,282.97758124475587,0.04740366999423583
0.0488965812559532,269.995673965681,0.15524664548765138,108.86225574296259,283.1975393764998,0.04773873661882923
0.0492487577383286,270.136635708531,0.1563648058191933,108.9190915176797,283.44052943678753,0.04807443927882848
0.049607410982598896,270.265770030016,0.1575035298697515,108.97115847610245,283.6729551584235,0.04841619995124252
0.0499678437081295,270.425058896145,0.15864790377331114,109.03538374692567,283.9376159738293,0.048759538660599185
0.0503305193144685,270.548849861225,0.15979939882343747,109.08529626404592,284.1657139746726,0.04910489493600175
0.0506942253360034,270.716200941059,0.1609541654418108,109.152772219435,284.43994903367184,0.0494511126815033
0.051059478393788195,270.79690942059,0.1621138439002775,109.18531387838189,284.6236583662552,0.04979868248553268
0.0514149745693716,270.885478995166,0.16324254425775483,109.22102513085095,284.8130490089145,0.05013685180642046
0.0517742941773554,271.017000531712,0.16438338401310337,109.27405461438626,285.0487144443053,0.05047854203546382
0.0521287104328714,271.047410348416,0.16550865562436667,109.28631585248134,285.17676231604827,0.05081545515179275
0.0524830236761991,271.17704670916,0.16663360017193213,109.33858523313332,285.4092380720386,0.0511521569205159
0.0528402685694602,271.346643403642,0.16776785270803612,109.40696662034847,285.684672916512,0.05149152987858437
0.0532059621139932,271.428844257475,0.1689289297119284,109.44011000461393,285.8704770616832,0.051838809575373845
0.0535702192305038,271.581416808089,0.17008544605684955,109.50162725702148,286.13009284542915,0.05218460532089816
0.053936400108560996,271.68757893211,0.17124807034468115,109.54443182542674,286.34142889391853,0.05253210684557363
0.054300290188735896,271.717321251352,0.17240342134923645,109.55642392854514,286.4716506446064,0.052877314843767974
0.0546593979519307,271.782641013393,0.17354358849737997,109.58276085660006,286.6381165449708,0.05321786925899447
0.0550189486047322,271.831661548675,0.17468516182002472,109.60252593642578,286.7875537645605,0.0535587275295165
0.0553857453891116,272.028567178093,0.17584974161042932,109.6819182862071,287.09507213838367,0.05390633553959791
0.0557434141280232,272.182696449619,0.17698533985647366,109.7440632084864,287.3550892162922,0.05424517671444639
0.056108134332495195,272.35092125796,0.17814332650567224,109.81189145120949,287.63202333348045,0.05459057997762914
0.0564671431574239,272.477282253164,0.17928317952482087,109.86284020447573,287.8632959572992,0.05493045788135176
0.056832708176672,272.576999570283,0.1804438484609336,109.90304622673811,288.06828864253373,0.05527642395205726
0.0572041745739787,272.660712032973,0.18162325427238238,109.93679909169471,288.2580430035725,0.05562785244808843
0.0575774468844716,272.723620453919,0.1828083938581973,109.96216376702014,288.42635022474536,0.05598086508124338
0.0579531913052851,272.756629412934,0.18400138239428018,109.97547297929499,288.5637465370865,0.05633608983477006
0.0583287793093858,272.901997226019,0.1851938743072999,110.03408528153086,288.8200375953061,0.056691040652533754
0.0587049508628663,272.993295235726,0.18638821898960048,110.07089663904473,289.01935321843126,0.05704641671676757
0.0590820003946781,273.153117935724,0.18758535125310294,110.13533715168393,289.29155055741006,0.057402495533451045
0.0594631166954347,273.178719776233,0.18879539550800517,110.14565981377714,289.42277786899655,0.057762286129170136
0.059841838751411795,273.250591373881,0.18999783803573245,110.17463844194882,289.60240920160464,0.05811968826616323
0.0602231255734029,273.31886128126,0.19120842369555419,110.20216486860403,289.7789773857808,0.05847938179680327
0.0606017242726613,273.365649976928,0.19241047456569962,110.22103007069738,289.93207972244664,0.05883641147165599
0.060979185915328,273.461505377123,0.1936089152811664,110.259678968056,290.1369653542,0.059192242017487844
0.0613623692800845,273.588526942826,0.19482552246426826,110.31089406334745,290.376567163886,0.0595533369298332
0.0617430387857902,273.705413018007,0.19603414814488387,110.35802252886042,290.60481694985856,0.059911933830711375
0.0621330243086485,273.769964533908,0.19727235217995898,110.38404970007173,290.7801203952711,0.06027917326997784
0.0625221130119495,273.870789407984,0.19850770881293966,110.42470228929915,290.99376985402176,0.06064543384640379
0.0629072540631473,273.949593587611,0.19973053165049268,110.45647613452475,291.18301027192274,0.061007846318330027
0.0632895072470687,273.999979113627,0.2009441855094431,110.4767915786144,291.34130277743554,0.061367411524143156
0.0636759851056757,274.07690045274,0.20217125271052033,110.50780626254476,291.5290170837784,0.06173081926559434
0.0640714912835895,274.156433304869,0.20342698482539662,110.53987390852318,291.7220448317019,0.062102579718239986
0.0644676022101854,274.288324337386,0.20468463701733863,110.59305237283402,291.97103492166684,0.062474770139716536
0.0648666198787434,274.313126484281,0.20595151811501028,110.6030525984621,292.1068917876865,0.06284955176778532
0.06526202996361549,274.41795430765,0.20720694513447918,110.64531917684448,292.3270270642299,0.06322080642364199
0.0656549131955924,274.527902940931,0.20845434939600585,110.6896504657834,292.55200857828584,0.06358955212974741
0.0660445735042602,274.654138114686,0.2096915208760261,110.74054848784141,292.79355352765066,0.06395513866334568
0.06643608769622379,274.756516222523,0.21093457843551053,110.78182734092127,293.01026422939145,0.06432232998515776
0.0668302413216027,274.808077817753,0.21218601619608857,110.802616976118,293.17356797543914,0.06469186061947436
0.0672256739373723,274.885155983976,0.21344151475115705,110.83369489273913,293.3644958503785,0.06506245317749296
0.0676367465146344,274.94808772623,0.2147466701839642,110.85906897121595,293.5446818404525,0.0654475576960834
0.06803892847972899,275.027655008056,0.21602359792313955,110.89115049924818,293.74024195709666,0.06582418976110872
0.06845653915219929,275.114465859439,0.21734951180823273,110.9261526345258,293.9478500628821,0.06621512031454597
0.0688854601936565,275.175798009339,0.21871133611485938,110.9508817573655,294.13140948936905,0.06661647961721871
0.0693033619338366,275.245578610395,0.22003817413993118,110.97901729571127,294.32102256551946,0.067007372826627
0.0697249467553489,275.289173786003,0.22137670594823275,110.99659487051642,294.48369677055604,0.06740155632130877
0.070143046616181,275.36794511383,0.22270417300637466,111.02835546989625,294.68309172455133,0.06779232796465087
0.0705653668997611,275.453666112252,0.2240450399067415,111.06291817646002,294.8911551253473,0.06818688921025765
0.070997570010705,275.521074046451,0.22541728478398837,111.09009705552906,295.0824007904886,0.06859052256547013
0.0714294190688367,275.574126469644,0.2267884055435565,111.11148779256045,295.2582262337728,0.06899366261755277
0.07186070944751209,275.669369014924,0.22815775249585088,111.14988958681735,295.4791654452844,0.0693961189894256
0.072293715480051,275.695419546019,0.2295325466491619,111.16039316095487,295.6264657658322,0.06980001344160792
0.0727258114732911,275.721429998548,0.23090445142769925,111.17088057541456,295.7734947357686,0.07020289648640574
0.0731692927509356,275.810616814591,0.23231250448422053,111.2068406996431,295.99148458011393,0.07061622636733526
0.0736131586434718,275.86309956989,0.23372177869302296,111.22800174657965,296.17025368240814,0.07102974372078015
0.0740586690428819,275.949028535042,0.23513627421115002,111.26264830532894,296.3854463120234,0.07144462126404082
0.0745046334757492,276.013787875662,0.23655221128550372,111.28875927146692,296.5780939755914,0.07185974930681159
0.0749451225748608,276.066375024579,0.23795076417518302,111.30996240991024,296.7562033395935,0.07226961150902204
0.07539048377699929,276.108806959271,0.23936478599197275,111.32707096597808,296.92478349102055,0.07268383634647615
0.0758367869192059,276.182043863233,0.2407817984684787,111.35660008565554,297.12680267459973,0.07309876521493121
0.0762936589953373,276.236763791435,0.2422323673101959,111.37866316070661,297.3118772501143,0.07352334178635792
0.0767527198029593,276.32536153146,0.24368988537439573,111.41438576948467,297.5340845795356,0.07394977088616637
0.07722519723657159,276.355208891257,0.24519000122611478,111.42642022495482,297.6967944052383,0.07438847310075486
0.0776940449186684,276.399021138057,0.24667859261677214,111.44408532286458,297.8735791018332,0.07482361487342372
0.078160948430697,276.416147466488,0.24816101126746296,111.45099065848795,298.0210957140281,0.07525676415365726
0.078631129818809,276.425332069374,0.24965383717471856,111.4546938903716,298.16096824052835,0.07569276482363539
0.0790994957338292,276.432067477434,0.2511408989549077,111.45740960690138,298.29770461955883,0.07612689308490174
0.0795745096953116,276.453131004221,0.2526490682826143,111.46590242090191,298.45175335761564,0.07656699100423066
0.08005030618167029,276.494648958272,0.25415972212680316,111.4826424599753,298.62813026497514,0.077007619849166
0.080534531729387,276.558874480801,0.2556971382408037,111.50853819065897,298.83141393271865,0.07745585548178517
0.0810236291289446,276.564711103361,0.2572500224843991,111.51089151687515,298.9729876859534,0.07790839700184336
0.0815189016550603,276.583725605596,0.25882251275481644,111.5185581641763,299.13052713262874,0.07836644351674409
0.0820132228136255,276.566981143844,0.26039198243326095,111.51180679719789,299.2491305912858,0.07882340106461323
0.0824997077087237,276.553960406859,0.2619365719751977,111.50655683604555,299.3695813061148,0.07927291087943558
0.0829863021828856,276.60343932101,0.26348150943066173,111.52650673423123,299.5577359213288,0.07972231990829001
0.0834790258111215,276.602923822296,0.2650459069503108,111.52629888514976,299.69346643948916,0.08017718399530274
0.0839831173128438,276.590347247334,0.26664639746827906,111.52122801012509,299.8192668278071,0.08064232846152576
0.0844824524409491,276.553597175135,0.2682317865000134,111.50641038101443,299.9175232958567,0.08110287083203498
0.0849854135800716,276.489610624998,0.26982868811672733,111.4806110039992,299.98719453455647,0.08156654319705234
0.0854744636158517,276.499413889457,0.27138142198032916,111.48456368022906,300.1330529817557,0.08201718506258016
0.08597816879187,276.49500404805,0.2729806859141872,111.48278563217377,300.26753817620204,0.08248111890809465
0.0864819002532283,276.483514517394,0.2745800333039998,111.47815305341327,300.39433424154925,0.08294486181187773
0.0869907929207054,276.388668229207,0.2761957675232396,111.43991103001626,300.4319376327635,0.08341313792905623
0.0875037450565061,276.2852442286,0.27782439055440683,111.39821047297151,300.4612378024539,0.08388492770489309
0.08801550718147849,276.216767427461,0.2794492353011942,111.37060062675228,300.52812630461744,0.08435540125633201
0.0885442399792297,276.063764190057,0.28112796193405426,111.30890972143098,300.5076203760709,0.0848412439342932
0.0890638306796341,275.916752666639,0.28277766240783825,111.24963467518884,300.490955607815,0.08531845626397352
0.089597424908471,275.76993222646,0.2844718240843954,111.19043667370869,300.4782080211344,0.08580829307374604
0.09012238676713309,275.625364438347,0.28613857798564757,111.1321469415415,300.46538013509166,0.08628997137570023
0.0906521118981054,275.466386686028,0.28782045527648464,111.06804711180648,300.4379963960566,0.08677578514664738
0.0911679583315111,275.278850020897,0.28945826770254773,110.99243232842566,300.3754607491484,0.0872486439768103
0.09167754040594239,274.973053406295,0.2910761907888671,110.86913513341813,300.18190662049597,0.08771554104669753
0.0921934743827872,274.715686846629,0.29271428116534937,110.76536493656081,300.0426804844735,0.08818803597240475
0.09270691208297689,274.43660666691,0.2943444458634516,110.65283980809811,299.87877703352973,0.08865802326594098
0.0932301148113134,274.076367281587,0.29600561452592,110.50759128793588,299.6285384703171,0.08913672208652966
0.0937482839431981,273.722176572305,0.29765080151965395,110.36478159395338,299.3831609031556,0.08961058972223734
0.0942660357267386,273.307673460151,0.299294663432395,110.19765393913289,299.0713043709374,0.09008385151814956
0.0947825991212078,272.869455576766,0.30093475220983473,110.02096448855204,298.73273179712083,0.0905558039415304
0.0953033072322638,272.385677973789,0.30258800046243756,109.82590535903171,298.34493392739347,0.09103131781918869
0.095802868092844,271.87395606438,0.3041741061947797,109.61957908515802,297.9202608150955,0.09148730746940462
0.096309385585031,271.264747083792,0.3057822992324734,109.37394602418493,297.3900882063108,0.09194943480832311
0.0968200826674696,270.736004486108,0.30740376246921597,109.16075700879875,296.94868682151343,0.09241515933490696
0.0973325250269743,270.054466459961,0.3090307669606434,108.88596087665628,296.33954957532137,0.0928822575367592
0.0978559792260918,269.343642915545,0.3106927340428414,108.59935682354774,295.70052884136845,0.09335916802351209
0.0983831752330332,268.658951274335,0.3123665813648804,108.32328915381186,295.0904719554808,0.09383925783157954
0.0989095123482861,267.838899627195,0.31403770170580836,107.99264432968504,294.33071457722247,0.09431833567887289
0.0994419393827457,266.950787932882,0.3157281575402176,107.63455769453803,293.49689200467986,0.09480272323614963
0.0999681704077207,265.992548342541,0.3173989410445132,107.24819549171254,292.58333674243204,0.09528124339268972
0.1004814712948289,264.935812269212,0.31902867136108176,106.8221195069463,291.55695248471307,0.09574778521822466
0.1010100150348249,263.89119096794,0.32070679773556904,106.40092819827342,290.5468441351695,0.0962279540069147
0.1015405369218749,262.850074915916,0.32239120472695276,105.98115020609734,289.5400126528332,0.09670968814630904
0.1020661157315699,261.627916157133,0.32405991744773444,105.48837579455602,288.33126132623636,0.09718670505767855
0.1025908069370339,260.380871686069,0.3257258120250826,104.98556746382302,287.09355542331105,0.09766268951582731
0.1031195991528209,259.100633594788,0.32740472731020637,104.46937546541852,285.81898707132444,0.09814216517542226
0.10364251719712189,257.786567442755,0.329064992100862,103.93954399291881,284.5042161921277,0.09861608853146872
0.1041656349731869,256.404518071318,0.3307258910398684,103.38230168635542,283.11305750621085,0.09908996827988825
0.1046523725304559,254.993569103485,0.33227128278419743,102.81340706252514,281.67925109017347,0.0995306904792673
0.1051357666893829,253.514017181706,0.3338060592387907,102.21685172766388,280.16740774461005,0.09996819320458104
0.10560295965941789,252.089996605511,0.3352893969186518,101.64268663134204,278.7114463475856,0.10039085099893885
0.1060704651530329,250.52106037819,0.3367737268608794,101.0100915444862,277.0939457831356,0.10081361278224112
0.1065430447199599,249.02194165892,0.33827416698587265,100.40564687687655,275.5534975253376,0.10124078144229359
0.1070031758664059,247.340400693951,0.3397350833758387,99.72764955980105,273.80660908827315,0.10165652261706011
0.1074847561455889,245.492967382702,0.3412641007622447,98.98276444870545,271.87971911728874,0.10209145863979766
0.1079468883449069,243.645191794192,0.3427313704950794,98.2377413314182,269.94593210857306,0.10250865246942452
0.1084020202280359,241.456870843626,0.34417641422401396,97.35541032415,267.631283441015,0.1029193566575296
0.10883857173872989,239.238371853541,0.3455624652704674,96.46091153134773,265.2767345511796,0.10331313577010476
0.10904410219179189,238.077639138955,0.34621502445893926,95.99290410082665,264.0386015508037,0.1034984751084441
0.10914650495242789,237.449158709922,0.34654015322395854,95.73950079184056,263.3659044870043,0.10359080510062685