File: example/data/02 processed data/test_ID_134.csv
Strain,Stress_MPa,Displacement(mm),Force(kN),True Stress (MPa),True Strain
4.08148613107188e-05,0.0516702948657722,0.00012958718466153218,0.010416731444939676,0.05167240378169103,4.081402840690082e-05
4.44722918854109e-05,0.276829630454757,0.0001411995267361796,0.05580885349967901,0.27684194170288506,4.447130302225645e-05
5.29222186809864e-05,0.722957343231554,0.00016802804431213182,0.14574820039548128,0.7229956037381695,5.2920818349707994e-05
5.48248116724324e-05,1.19296616737537,0.00017406877705997286,0.24050197934287462,1.193031571520828,5.48233088474562e-05
6.58403238779207e-05,2.23002347238746,0.00020904302831239823,0.44957273203331194,2.2301702978551377,6.583815649902845e-05
6.83082488621485e-05,3.58286305577724,0.00021687869013732147,0.7223051920446916,3.583107794878493,6.830591595997574e-05
7.46242113948814e-05,5.16212618560651,0.00023693187117874843,1.0406846390182725,5.162511405202232,7.462142714697555e-05
8.55906045761079e-05,7.00407314827232,0.0002717501695291426,1.4120211466916996,7.004672631127575,8.558694190922055e-05
0.0001021887010646,8.94036923084659,0.000324449125880105,1.8023784369386726,8.941282835565328,0.0001021834801549613
0.000124712101448,10.9109287980297,0.0003959609220974,2.1996432456827875,10.912289522888852,0.0001247043255404128
0.0001568471212287,13.0062165191687,0.0004979896099011224,2.62205325026441,13.00825650678781,0.0001568348220050943
0.0001899310641783,14.9073911320599,0.0006030311287661025,3.0053300522232758,14.910222508721732,0.00018991302955714527
0.0002316675704203,16.8129869050475,0.0007355445360844524,3.3894981600575758,16.8168819288753,0.00023164073963257862
0.0002693771872593,18.8773732113895,0.0008552725695482774,3.8056784394161234,18.88245834508803,0.00026934091173915636
0.0003096774302876,20.96000001455,0.00098322584116313,4.22553600293328,20.966490853493333,0.00030962949012918926
0.0003509620202457,23.0406519720787,0.0011143044142800974,4.644995437571065,23.0487383658426,0.0003509004474819787
0.0003886240159714,25.1423373939171,0.001233881250709195,5.068695218613688,25.15210831004603,0.0003885485212172498
0.0004238648801584,27.3495990962217,0.00134577099450292,5.513679177798294,27.361191630765,0.0004237750748161172
0.0004627965160671,29.5464961429663,0.0014693789385130424,5.956573622422006,29.560170158443256,0.0004626894587886404
0.0005060352586549,31.7061557052557,0.0016066619462293073,6.391960990179549,31.722200137958964,0.0005059072659908813
0.0005485923570182,33.791532662187,0.001741780733532785,6.8123729846969,33.810070438737405,0.0005484419352419837
0.0005967311061748,35.9178955169909,0.00189462126210499,7.241047736225367,35.93932884251423,0.0005965531329661278
0.0006385734853293,38.064105732829,0.0020274708159205273,7.673723715738326,38.08841246149276,0.0006383696840380657
0.0006802879956833,40.2143900006054,0.0021599143862944775,8.10722102412205,40.24174736737654,0.0006800567046951571
0.0007327524297194,42.2812050439314,0.0023264889643590946,8.52389093685657,42.3121866996588,0.0007324840977303548
0.0007817863453985,44.3737580072893,0.0024821716466402375,8.945749614269522,44.40844880539341,0.0007814809096335419
0.0008333625461751,46.5266414508341,0.002645926084105942,9.379770916488154,46.56541501121855,0.0008330154924095031
0.0008851906129179,48.6905925079124,0.0028104801960143326,9.81602344959514,48.733692963337816,0.0008847990627546358
0.0009321320694938,50.8176206546602,0.002959519320642815,10.244832323979496,50.86498938856778,0.0009316979041748936
0.0009886526284415,53.0086988961938,0.0031389720953017624,10.686553697472672,53.06110608568778,0.0009881642333072196
0.001034389955302,55.1549002448207,0.0032841881080838495,11.119227889355855,55.21195191961963,0.0010338553426457603
0.0010775440855992,57.3134307992579,0.00342120247177746,11.554387649130392,57.375188547641045,0.0010769639516802125
0.0011220775868169,59.4419976347077,0.003562596338143657,11.983506723157072,59.50869616796922,0.0011214485282857423
0.0011646227952668,61.5368714532628,0.0036976773749720897,12.40583328497778,61.60853869650667,0.0011639451482236606
0.001209625475655,63.6308840223544,0.0038405608852046247,12.827986218906647,63.70785356070629,0.0012088944681968314
0.0012480734928347,65.7454431752392,0.003962633339750173,13.254281344128223,65.82749832014089,0.001247295296543008
0.0012886040056977,67.792859303003,0.004091317718090197,13.667040435485406,67.88021745305855,0.001287774468109719
0.0013425704431031,69.8525578051467,0.004262661156852342,14.082275653517575,69.94633978463105,0.0013416700012534432
0.0013872573328575,71.8701720836858,0.004404542031822563,14.489026692071059,71.96987450692262,0.0013862959803965038
0.0014330827060996,73.8728736748252,0.0045500375918662295,14.892771332844761,73.97873961253846,0.0014320568230781327
0.0014793080970483,75.8730607759864,0.0046968032081283525,15.296009052438858,75.98530040914017,0.001478214998712021
0.0015249530203318,77.8558083955333,0.004841725839553465,15.695730972539513,77.97453484569645,0.0015237914602078688
0.0015814751587017,79.7632719013807,0.005021183628877897,16.08027561531835,79.8894155344695,0.0015802259437578156
0.0016280050333956,81.6866376126164,0.0051689159810310295,16.468026142703465,81.8196238698109,0.0016266812697358019
0.0016733328136661,83.6655175743737,0.005312831683389867,16.866968342993736,83.80551783030324,0.0016719343521570229
0.0017191908658687,85.5997712635695,0.005458430999133123,17.25691388673561,85.74693360844627,0.0017177147488278463
0.001768701113233,87.5508150249449,0.005615626034514774,17.650244309028892,87.70566624894397,0.0017671388033206308
0.0018096740598892,89.4454146243019,0.005745715140148209,18.032195588259267,89.60728167092354,0.0018080385726229836
0.0018528517871619,91.3226805992824,0.005882804424239032,18.410652408815334,91.4918879912392,0.001851137374664133
0.0018906903331411,93.2257684110701,0.006002941807722992,18.794314911671734,93.40202947020457,0.001888905227873153
0.0019346958708225,95.0757643060952,0.006142659389861437,19.167274084108794,95.25970699471348,0.001932826757155498
0.0019726917944956,96.8111299173746,0.006263296447523529,19.51712379134272,97.00210843897845,0.0019707485931760456
0.0020243490489617,98.623109567086,0.006427308230453397,19.88241888872454,98.82275716514378,0.00202230281548758
0.0020580465794241,100.399145089637,0.006534297889671517,20.240467650070823,100.60577120676585,0.002055931702742049
0.0021036615940578,102.153691059341,0.006679125561133515,20.594184117563145,102.36858785591377,0.0021014519962945723
0.0021492614331178,103.961224485353,0.006823905050149014,20.95858285624717,104.18466433567907,0.002146955074817263
0.0021832783090822,105.73767110123,0.006931908631335984,21.31671449400797,105.9685258649982,0.002180898420338296
0.0022168834476073,107.476609994582,0.007038604946153177,21.667284574907733,107.71487311228394,0.0022144297871475194
0.0022630160250847,109.18883731673,0.007185075879643922,22.012469603052768,109.43593340533813,0.002260459260925443
0.002296921690001,110.893738125273,0.0072927263657531745,22.356177606055038,111.14845235765824,0.0022942877978343727
0.0023495596407329,112.526700238405,0.007459851859326958,22.68538276806245,112.79108843178999,0.0023468037414025303
0.0023921502030311,114.174715596003,0.007595076894623742,23.017622664154207,114.447838665097,0.0023892935664962573
0.0024324019778128,115.716025680978,0.00772287627955564,23.32835077728517,115.99749357070905,0.0024294484765539507
0.0024813364325319,117.279836463367,0.007878243173288781,23.64361503101479,117.57084719438495,0.0024782630003825153
0.0025346488398887,118.880768640369,0.008047510066646621,23.96636295789839,119.1820896426884,0.0025314420351242777
0.0025739600137913,120.519594867806,0.008172323043787377,24.29675032534969,120.82980748587407,0.0025706530521574706
0.0026157152370555,122.096115769425,0.008304895877651212,24.614576939116077,122.41548443982836,0.002612300207821104
0.0026532895559128,123.723682459214,0.00842419434002314,24.942694383777543,124.05195721370211,0.0026497757971530225
0.0026887514520872,125.3126057486,0.00853678586037686,25.263021318917765,125.64954019927139,0.0026851432262029796
0.002729040531446,126.853563263842,0.00866470368734105,25.573678353990548,127.19975177954737,0.002725323461488799
0.0027680107989123,128.381868728317,0.008788434286546552,25.881784735628703,128.73723112734152,0.0027641869117695237
0.0028075319933811,129.880156909572,0.008913914078984992,26.18383963296972,130.244799605401,0.0028035982364797447
0.0028572017060844,131.371272976556,0.009071615416817969,26.48444863207369,131.7466272018351,0.0028531276636854547
0.0029002051843722,132.840171955635,0.009208151460381736,26.780578666256016,133.2254357110336,0.0028960077030628518
0.0029490024871053,134.279861038535,0.009363082896559327,27.070819985368654,134.67585268270577,0.0029446627091879317
0.0030025311029145,135.779738945961,0.009533036251753536,27.373195371505737,136.18742183529184,0.002998032508931909
0.0030472662832756,137.281234782,0.009675070449400028,27.675896932051202,137.69956726007766,0.0030426327780048827
0.0031058959927501,138.728123538148,0.009861219776981567,27.96758970529064,139.15899866112687,0.0031010826616863765
0.0031499845045691,140.14171216548,0.010001200802006891,28.252569172560765,140.58315638724503,0.003145033697299129
0.0031914378867996,141.549120691905,0.01013281529058873,28.536302731488046,142.0008659185243,0.003186356058263092
0.0032149074177114,142.946820657925,0.010207331051233694,28.81807904463768,143.40638145199642,0.003209750652252298
0.003246882811666,144.352655011109,0.01030885292703955,29.101495250239573,144.82135116548292,0.0032416230697715574
0.0032920820907081,145.641776211882,0.010452360637998216,29.36138208431541,146.12124089500804,0.0032866750521554147
0.0033378293753941,146.945031025312,0.010597608266876267,29.6241182547029,147.4355084664365,0.003332271187678465
0.0033781985779364,148.300938789316,0.010725780484948069,29.89746925992611,148.80192880984072,0.003372505283569925
0.0034237663495477,149.631694826571,0.010870458159813948,30.16574967703671,150.14399878814402,0.0034179186052783602
0.0034776741076596,150.890521992969,0.01104161529181923,30.419529233782555,151.41527005439522,0.0034716409825093567
0.0035550516323045,152.138146120763,0.011287288932566787,30.671050257945822,152.67900508546538,0.0035487473731433913
0.0036107974459991,153.334459856529,0.011464281891047142,30.912227107076248,153.88811953256263,0.003604294166882086
0.003666100819523,154.595163167867,0.011639870101985524,31.166384894641993,155.161924622251,0.003659397051377548
0.0037276905812455,155.74988547725,0.011835417595454463,31.399176912213598,156.3304728583736,0.0037207599608433646
0.0037807023193242,156.79608428059,0.012003729863854333,31.610090590966948,157.38888360009057,0.0037735734268078253
0.0038477896442605,157.843323968967,0.012216732120527086,31.82121411214375,158.45067187635047,0.003840405836519034
0.0039075507618222,158.81814726251,0.012406473668785485,32.01773848812201,159.43873723483682,0.00389993611531011
0.0039768887792667,159.693873868512,0.012626621874171772,32.19428497189202,160.32895864361728,0.003969001860436123
0.004058602799012,160.525477890935,0.0128860638868631,32.3619363428125,161.1769870448159,0.004050388887839913
0.004136386641449,161.26638548807,0.013133027586600576,32.511303314394915,161.93344561071763,0.0041278553120516715
0.004228346089747,162.001846906886,0.013424998834946723,32.65957233642821,162.68684678278652,0.004219431754182473
0.0043257370391253,162.703024140471,0.013734215099222827,32.80092966671895,163.4068346383731,0.004316407932491628
0.004435433030002,163.326450716095,0.01408249987025635,32.92661246436475,164.05087425027418,0.004425625486694064
0.0045514213490381,163.94598879206,0.014450762783195965,33.051511340479294,164.69217606553735,0.004541094952223003
0.0046787127347526,164.528111458661,0.014854912932839503,33.16886727006606,165.29789122896742,0.004667801578532666
0.0048133666386655,165.044372184589,0.015282439077762963,33.272945432413145,165.83879125956182,0.004801819428612099
0.0049541593441288,165.49288140638,0.01572945591760894,33.36336489152621,166.31275951118624,0.004941927877846562
0.0050957566829959,165.865329652608,0.01617902746851198,33.43845045796577,166.7105390146626,0.005082817253749301
0.0052553677134075,166.17245109828,0.016685792490068813,33.500366141413245,167.04574843263967,0.005241606461077363
0.0054112221890281,166.415984768292,0.017180630450164217,33.549462529287666,167.31649863767913,0.005396634128732911
0.005568390624963,166.586421167207,0.017679640234257523,33.58382250730893,167.51403943308063,0.005552944451576034
0.0057340171318972,166.721001859967,0.01820550439377361,33.61095397496935,167.6769829408791,0.005717640229465724
0.0059035377652469,166.828668306892,0.018743732404658906,33.63265953066943,167.8135476505676,0.005886180166830134
0.006068588094735,166.893991058351,0.019267767200783624,33.64582859736356,167.90680194557052,0.006050248374075099
0.0062506896031567,166.930758470756,0.019845939490022523,33.65324090770441,167.9741908271762,0.00623123507030849
0.0064211430506119,166.955090490534,0.02038712918569278,33.658146242891654,168.02713300960156,0.006400615338961543
0.0066010138095212,166.946164897028,0.02095821884522981,33.65634684324085,168.0481788369599,0.006579322521865689
0.0067881103382445,166.922811503477,0.021552250323926287,33.65163879910096,168.0559019659326,0.006765174851172508
0.0069668755595999,166.859746720641,0.02211982990172968,33.63892493888123,168.02223781195008,0.006942719014267688
0.0071656571991977,166.769760237235,0.022750961607452696,33.62078366382658,167.9647751702874,0.00714010586643353
0.00737207484449,166.657870627976,0.02340633763125575,33.59822671859996,167.88648492366877,0.007345033917898201
0.0075638342458581,166.56550646075,0.024015173730599464,33.5796061024872,167.82538034269652,0.007535371884561929
0.007769040627304,166.451405729994,0.0246667039916902,33.556603395166796,167.7445734635822,0.0077390170339202355
0.0079865286518286,166.337288944093,0.025357228469555803,33.53359745112915,167.66574646811247,0.007954805127162309
0.0081973509820485,166.219879676369,0.026026589368003988,33.50992774275599,167.5824423702701,0.008163935190266088
0.0084104835932499,166.094280150204,0.026703285408568433,33.48460687828113,167.49121336833997,0.008375312542213974
0.008609500276482,165.977949763125,0.027335163377830346,33.461154672245996,167.40693696750054,0.008572649886880446
0.0088163967943296,165.852964303104,0.027992059821996478,33.43595760350576,167.31518984591594,0.008777759297712524
0.0090316980947888,165.705236251286,0.028675641450954435,33.40617562825926,167.20183591783328,0.008991156234599583
0.0092477182655216,165.547221983416,0.029361505493031077,33.37431995185666,167.0781560519584,0.009205219926481347
0.0094482093831427,165.390405197101,0.029998064791478072,33.34270568773556,166.95304837536602,0.009403854218584914
0.0096632292467296,165.238420821149,0.030680752858366477,33.31206563754364,166.83515756191133,0.009616838861518321
0.0098928493668553,165.097928241003,0.03140979673976558,33.2837423333862,166.7312171758711,0.00984423548946719
0.0101087470420933,164.908261968528,0.032095271858646225,33.24550561285525,166.5752778739191,0.010057995395839441
0.0103296927051275,164.736698288121,0.03279677433877981,33.210918374885196,166.4383777586946,0.010276706007920832
0.0105522318789376,164.569624414149,0.03350333621562688,33.17723628189244,166.30620125119674,0.010496945668637599
0.0107742956333039,164.40488572416,0.034208388635739884,33.14402496199066,166.17623256651166,0.010716666482902168
0.0110001076658144,164.203699359275,0.03492534183896072,33.10346579082984,166.00995773135205,0.01094004653270494
0.0112255695509795,164.008342393173,0.03564118332435991,33.06408182646368,165.84942944764842,0.011163030434689261
0.0114440452484755,163.81207480372,0.03633484366390971,33.024514280429955,165.68674760002042,0.01137905750776832
0.0116721463077231,163.657581697555,0.03705906452702084,32.99336847022709,165.56781693549704,0.011604552277832747
0.0119040347086494,163.493240698062,0.037795310199961844,32.9602373247293,165.4394699099613,0.01183373900588052
0.0121358354610825,163.327874225217,0.03853127758893694,32.92689944380375,165.3099944330226,0.012062786621851732
0.0123663800012056,163.166687488912,0.039263256503827774,32.894404197764665,165.18446874993782,0.012290540920522005
0.012603137001723,163.039058171794,0.04001495998047053,32.86867412743367,165.09386175856503,0.012524378516207637
0.0128392276327016,162.875387439301,0.04076454773382757,32.83567810776308,164.96658161439865,0.012757503522547155
0.0130677342467644,162.69515140666,0.041490056233476964,32.79934252358265,164.82120840847932,0.012983088032923541
0.013296927030475,162.519126232116,0.04221774332175812,32.763855848394584,164.68013119468102,0.013209298832063182
0.0135336989140824,162.33931841515,0.04296949405221162,32.72760659249424,164.53636987249797,0.013442936395709214
0.0137704543172452,162.1392384585,0.04372119245725351,32.687270473233596,164.37196943472568,0.013676503129010448
0.0140097807981467,161.900964645513,0.044481054034115765,32.63923447253542,164.16916167120513,0.013912550880012567
0.0142433990374486,161.674633239598,0.045222791943899304,32.59360606110295,163.97742955506274,0.0141429148628305
0.0144867030273498,161.475319268745,0.04599528211183561,32.553424364578994,163.81456426523783,0.014382773275558832
0.0147353479724576,161.276848514744,0.046784729812552876,32.51341266057239,163.6533189975101,0.014627837581093732
0.0149857505552804,161.07875708905,0.04757975801301527,32.473477429152474,163.4926431625411,0.0148745735334122
0.0152166194917889,160.89216072355,0.048312766886429756,32.43585960186768,163.340395512492,0.015102007941833556
0.0154631679325501,160.715665163072,0.049095558185846565,32.40027809687532,163.20083848288007,0.015344831496290044
0.0157047058124323,160.565066457577,0.04986244095447255,32.36991739784752,163.08669359004688,0.015582663025769007
0.0159407231222768,160.401867225304,0.05061179591322884,32.33701643262128,162.95878897903876,0.015815004070662907
0.0161781260167707,160.219508021345,0.05136555010324697,32.30025281710316,162.8115594124593,0.016048654672028498
0.0164189414782211,160.06408935097,0.05213013919335199,32.268920413155556,162.69217226678833,0.016285608140503335
0.0166572756672445,159.858365846007,0.05288685024350128,32.22744655455501,162.52117071361914,0.01652006485993681
0.0169116614861536,159.67165739268,0.05369452521853768,32.18980613036429,162.3719704114381,0.016770251431523622
0.0171491877236078,159.455780915244,0.05444867102245476,32.14628543251319,162.190318035774,0.017003800234772316
0.0173983314869112,159.273170777056,0.05523970247094305,32.10947122865449,162.04425819920667,0.01724871342770227
0.0176541811615445,159.098683663447,0.05605202518790379,32.074294626550916,161.90744064740474,0.017500156252288863
0.0179033607023897,158.943633602255,0.05684317023008729,32.043036534214615,161.78925880598464,0.017744983074390618
0.0181473001260947,158.788543850485,0.05761767790035067,32.01177044025778,161.67012721232533,0.017984603266132788
0.0184089269700383,158.65703257818,0.05844834312987159,31.98525776776109,161.5777383041947,0.018241533904140038
0.0186642881310065,158.456628379791,0.05925911481594563,31.944856281365865,161.4141085481392,0.018492247683510096
0.018917441548537,158.299820947207,0.060062876916604974,31.91324390295693,161.29444855711964,0.018740731869587773
0.0191804208942698,158.149108929739,0.060897836339306614,31.882860360235384,161.1824754030651,0.018998795382668743
0.0194304523848104,157.957642629093,0.061691686321773014,31.844260754025147,161.02683108301446,0.01924409132911095
0.0196806939269371,157.758457083707,0.06248620321802529,31.804104948075327,160.86325299195727,0.01948953311764288
0.0199396052234246,157.555754127525,0.0633082465843731,31.763240032109042,160.69735366550682,0.019743414977895033
0.0201924054813851,157.369919541782,0.06411088740339768,31.725775779623252,160.54759676774262,0.019991242332132793
0.0204446300454799,157.209115884693,0.06491170039439868,31.693357762354115,160.42319809873254,0.02023844412352251
0.0207016216309548,157.050286131585,0.06572764867828149,31.66133768412754,160.30148173211427,0.020490255170008534
0.0209566778238479,156.869409258531,0.06653745209071708,31.62487290651985,160.15687092877937,0.020740107159725008
0.0212236970152479,156.718899287925,0.06738523802341208,31.594530096445684,160.0450537229751,0.021001611183768663
0.0214924291924484,156.589021967989,0.06823846268602367,31.56834682874658,159.95450043495075,0.02126472378693745
0.021756124768388,156.440130993198,0.0690756961396319,31.53833040822872,159.84366200186898,0.02152283783468017
0.022016294431502,156.282879305488,0.06990173482001885,31.50662846798638,159.72364919088054,0.02177743532515942
0.0222833733545944,156.097863940196,0.07074971040083722,31.469329370343512,159.57625092223006,0.02203872668945443
0.0225458457397089,155.925075847022,0.07158306022357576,31.43449529075963,159.44053855402137,0.022295444838926416
0.0228019437493062,155.753880917046,0.07239617140404718,31.399982392876474,159.3053721484526,0.02254586485282483
0.0230575579860649,155.575292992923,0.07320774660575605,31.36397906737328,159.16247933230636,0.02279574930273154
0.0233145257606083,155.38826684233,0.07402361928993136,31.32627459541373,159.01107059252178,0.02304689402654306
0.0235773306871755,155.207906904146,0.07485802493178222,31.289914031875835,158.86729505048942,0.023303678406415024
0.0238548762330481,155.043751927758,0.0757392320399277,31.25682038863601,158.74230144070208,0.0235747941450798
0.0241227063265004,154.915464349688,0.07658959258663876,31.2309576128971,158.65244460162896,0.023836349835200554
0.0243915492865052,154.77204739469,0.077443168984654,31.202044754769506,158.5471774168909,0.02409882588174177
0.0246692418273453,154.610674494032,0.07832484280182132,31.16951197799685,158.42480261221425,0.024369869614308814
0.024940371785505,154.461555011995,0.07918568041897837,31.139449490418194,158.31388362056137,0.024634437030406436
0.0252237991820748,154.294150351811,0.08008556240308749,31.1057007109251,158.18603501525394,0.024910929422956234
0.0254858734292174,154.148598721661,0.08091764813776524,31.076357502286857,158.07721039797246,0.02516652313480103
0.0257506738013993,153.994640598671,0.08175838931944276,31.045319544692074,157.9601063558911,0.025424709226512767
0.0260268087178888,153.848899367144,0.08263511767929693,31.015938112416233,157.85309524243038,0.025693875761879557
0.0263058901368675,153.655257115656,0.0835212011845543,30.976899834516253,157.6972954282926,0.025965840849074957
0.0265806213972517,153.486028305347,0.08439347293627414,30.942783306357956,157.56578231349928,0.02623349447773944
0.0268586210092119,153.30759760551,0.08527612170424778,30.906811677270817,157.42522826742916,0.026504259356404967
0.0271195698072421,153.136489997946,0.08610463413799366,30.872316383585915,157.28948572848134,0.02675835046662315
0.0274047308537049,152.957765879738,0.08701002046051305,30.83628560135518,157.14953228565622,0.027035943725755813
0.0276777811089637,152.776229961023,0.08787695502095974,30.799687960142236,157.0047370125369,0.0273016753985973
0.0279443365909659,152.545127775786,0.08872326867631673,30.75309775959846,156.80790017166447,0.027561018281903635
0.0282066273319177,152.360403349186,0.08955604177883869,30.715857315195894,156.65797646659715,0.02781614618542492
0.0284670639800414,152.116118320352,0.09038292813663144,30.66660945338296,156.44641759297303,0.028069406243756995
0.0287475019426518,151.91116671789,0.09127331866791946,30.625291210326626,156.27823327822304,0.028342044760898327
0.0290262280276417,151.721874798669,0.09215827398776238,30.587129959411673,156.12578853335648,0.02861294537804102
0.0292812979438412,151.543226326403,0.09296812097169581,30.55111442740284,155.98060868783736,0.028860789700900308
0.0295553831370915,151.372188134193,0.0938383414602655,30.51663312785331,155.84605115079898,0.029127042189393573
0.0298278368297906,151.247189287037,0.09470338193458515,30.49143336026666,155.75856577005518,0.029391639561700975
0.030116467966785,151.108126101329,0.09561978579454238,30.463398222027926,155.65896914058055,0.029671871544877472
0.0304036673285913,151.024598196343,0.09653164376827737,30.44655899638275,155.61629983833876,0.029950635492626998
0.0306806503979094,150.911277309344,0.09741106501336234,30.42371350556375,155.54133344957393,0.03021940962147105
0.0309615009196666,150.789763197703,0.09830276541994144,30.399216260656928,155.45844058962498,0.030491862843593162
0.0312524541999299,150.606352515136,0.09922654208477742,30.362240667051417,155.31317064933378,0.030774038494156997
0.0315308942847758,150.416893578461,0.10011058935416314,30.324045745417738,155.15967274852784,0.03104400391417217
0.0318197352590683,150.240079708644,0.10102765944754186,30.28840006926263,155.02067927027437,0.03132397666533088
0.0321038801735327,150.070833305161,0.10192981955096633,30.254279994320456,154.88868935513207,0.03159932107646599
0.0323901808142807,149.906409189296,0.10283882408534123,30.221132092562076,154.76190488815686,0.03187667778869256
0.0326724376722523,149.731528732478,0.10373498960940104,30.185876192467568,154.62362277256094,0.032150041760518284
0.0329571311133386,149.539919850215,0.10463889128485006,30.147247841803345,154.46832659539666,0.03242568987012226
0.0332562220546944,149.391211618445,0.1055885050236547,30.117268262278515,154.35939892504786,0.03271519622045752
0.0335524455870926,149.240530738229,0.10652901473901899,30.08689099682697,154.24791552521225,0.03300184446135592
0.0338378742046516,149.067003260892,0.10743525059976881,30.05190785739583,154.11111376529846,0.03327796901958775
0.0341184771413343,148.905721888687,0.1083261649237364,30.0193935327593,153.98615835716004,0.03354935089689107
0.0344109463056986,148.730897161898,0.10925475452059306,29.98414886783864,153.84886807813444,0.03383213069494272
0.0346971221362634,148.564588959839,0.11016336278263629,29.950621134303542,153.7193526481023,0.034108748274038106
0.0349800511428813,148.388560520906,0.11106166237864813,29.91513380101465,153.5791999569458,0.034382152273495774
0.035268246146168,148.208193269234,0.11197668151408338,29.87877176307757,153.43523631033216,0.03466056815774087
0.0355603086793404,148.025547960392,0.11290398005690577,29.841950468815032,153.28938213829204,0.03494264127714838
0.0358607402022165,147.817118496465,0.11385785014203739,29.799931088887348,153.117949780307,0.03523271414779422
0.0361592667849707,147.613913389331,0.11480567204228197,29.758964939289132,152.95152426474937,0.035520864439599405
0.0364432224244732,147.413174214384,0.11570723119770239,29.718495921619812,152.7853853105764,0.0357948732210784
0.0367445573741152,147.221579660907,0.11666396966281575,29.679870459638853,152.63117144146506,0.03608557043114319
0.0370533089591781,147.029956308611,0.11764425594539045,29.641239191815977,152.4779027059684,0.03638333482984034
0.037348375710288,146.843213139761,0.11858109288016438,29.603591768975818,152.32756863461069,0.036667818548958536
0.0376480883909335,146.659128768865,0.11953268064121385,29.566480359803187,152.18056461209255,0.03695669873542167
0.0379399546084964,146.502797011153,0.12045935588197605,29.534963877448444,152.0611064797739,0.03723793587250288
0.0382379417686111,146.320804846959,0.12140546511534024,29.49827425714693,151.91581126223332,0.03752498946524261
0.0385315543671532,146.146452232465,0.1223376851157114,29.463124770064947,151.77770220222678,0.037807748433962604
0.0388231908452206,145.958273579833,0.12326363093357541,29.42518795369433,151.62483949046177,0.03808852520611043
0.0391092252119148,145.740555829923,0.1241717900478295,29.38129605531248,151.4403560503851,0.038363831916078936
0.0394036011557547,145.48457807271,0.12510643366952115,29.329690939458338,151.21719436140032,0.038647088234802306
0.0396865499561037,145.230363917479,0.12600479611062923,29.278441365763765,150.99405601023315,0.03891927345192202
0.0399699510699606,144.985327686765,0.12690459464712492,29.229042061651825,150.78038414026722,0.03919181953390384
0.0402597154607735,144.753212960178,0.12782459658795584,29.182247732771884,150.5809361259875,0.03947040838142296
0.0405531159847755,144.527284863277,0.1287561432516622,29.136700628436643,150.38831660930214,0.0397524140683472
0.0408465488866425,144.292413422752,0.12968779271508993,29.089350546026804,150.18626054159606,0.04003437135772654
0.0411337168445329,144.101974933892,0.13059955098139195,29.050958146672627,150.0294247675607,0.04031023176278246
0.0414253630029758,143.917438068426,0.13152552753444816,29.01375551459468,149.87927018286882,0.04059031616775475
0.0417230395744999,143.718497367927,0.13247065064903718,28.973649069374083,149.71486992119668,0.040876111047449315
0.0419953846708194,143.517920392321,0.13333534632985158,28.933212751091915,149.54501066635257,0.041137514022728014
0.0422877491441373,143.313171464488,0.13426360353263592,28.89193536724078,149.373562908429,0.041418056018671066
0.0425853405049463,143.075644490398,0.1352084561032045,28.844049929264234,149.16856952898624,0.041703532735990236
0.0428809025937684,142.808261035646,0.13614686573521467,28.79014542478624,148.932008166701,0.0419869821485895
0.0431858730781751,142.546499471242,0.13711514702320593,28.737374293402386,148.7024945051452,0.042279370187300436
0.0434842250091261,142.308511292312,0.13806241440397535,28.689395876530103,148.49668661806066,0.04256533003620758
0.0437843404893438,142.04787250517,0.13901528105366656,28.63685109704227,148.26734492072327,0.04285289770933478
0.0441088195195502,141.789760983069,0.14004550197457188,28.584815814186708,148.04393995999135,0.04316371728481277
0.0444083605658793,141.531829237788,0.1409965447966668,28.532816774338063,147.81702574212815,0.0434505629485585
0.0447082783100234,141.289577578179,0.14194878363432428,28.48397883976089,147.6063913348499,0.04373768693256533
0.0450049460781708,141.048283514599,0.14289070379819227,28.43533395654316,147.39615390859208,0.0440216184947319
0.0452983323739256,140.786805261514,0.1438222052872138,28.38261994072122,147.16421276011317,0.044302330198823583
0.0455856072523129,140.466420335554,0.14473430302609344,28.31803033964769,146.86966740510886,0.04457711817222616
0.0458994066774401,140.185353895108,0.1457306162008723,28.26136734525377,146.6197784637604,0.04487719149371008
0.0461951996405329,139.894591653624,0.14666975885869193,28.202749677370598,146.35705024369398,0.04515996356737309
0.0464831262817038,139.577602414407,0.14758392594440956,28.138844646744456,146.06560573353335,0.04543513881950917
0.0467614659077411,139.256521545771,0.14846765425707797,28.074114743627433,145.76836063046417,0.045701079673928495
0.0470459283096382,138.983584831317,0.14937082238310126,28.019090701993505,145.52219659950765,0.045972797506650794
0.0473361785078323,138.699418931757,0.15029236676236754,27.961802856642212,145.26491938524327,0.0462499677509032
0.0476405236677257,138.449901290994,0.15125866264502907,27.911500100264394,145.0457270902419,0.04654051528942081
0.0478969415154278,138.149645154086,0.15207278931148327,27.850968463063737,144.76659062840835,0.04678524281469022
0.0481939908453064,137.854198545429,0.1530159209338478,27.791406426758485,144.49794252811446,0.04706867453731368
0.0485088779433605,137.546020489153,0.15401568747016958,27.729277730613244,144.21822360865627,0.04736903860425785
0.0488121304389237,137.217856853209,0.15497851414358274,27.663119941606936,143.91575278047742,0.04765821941774762
0.0491161170383157,136.836512738249,0.15594367159665234,27.586240968031003,143.5573909130158,0.047948016365650784
0.0494138305472162,136.445022823056,0.15688891198741142,27.507316601128093,143.18729405984556,0.048231751664487434
0.0496899051055458,136.03158914978,0.15776544871010792,27.423968372595645,142.79098590598915,0.04849479208048232
0.0500075742720427,135.624493868901,0.15877404831373557,27.341897963970442,142.40674581915826,0.04879737773583581
0.0503017336125187,135.199315786314,0.15970800421974685,27.256182062520903,142.00007575359197,0.04907748823317544
0.0505821819694442,134.747933886297,0.16059842775298533,27.165183471477476,141.56377839814033,0.04934446953234332
0.0508808355885163,134.232182169678,0.16154665299353924,27.061207925407086,141.06202776134114,0.0496287035336912
0.0511761211040164,133.716194318442,0.16248418450525207,26.95718477459791,140.5592704724508,0.04990965264546712
0.0514664775382585,133.159467752652,0.16340606618397072,26.844948698934644,140.01271650875032,0.05018583504210946
0.0517804335246342,132.612525393211,0.16440287644071358,26.73468511927134,139.47925944886802,0.050484379152224264
0.052075985215076,132.040943753353,0.1653412530578663,26.619454260675962,138.9171059880373,0.05076534099900581
0.0523771348572209,131.394798550944,0.16629740317167635,26.48919138787031,138.27688163418415,0.05105154328246659
0.0526694015727552,130.739843860566,0.16722534999349775,26.357152522290107,137.62583319841744,0.05132922523614723
0.0529605852769627,130.081377848732,0.16814985825435658,26.22440577430437,136.9705637532346,0.05160580156521013
0.0532544571040964,129.414011762127,0.16908290130550607,26.0898647712448,136.30588470018222,0.05188485363076604
0.0535572153140139,128.667112896449,0.17004415862199412,25.939289959924118,135.55816516567663,0.052172262530161315
0.0538468940741408,127.908829802868,0.17096388868539703,25.786420088258186,134.79632301241034,0.0524471777784148
0.0541324664372583,127.141127047331,0.1718705809382951,25.631651212741932,134.02358984001583,0.052718121953878795
0.0544268607850527,126.392738364623,0.1728052829925423,25.480776054308,133.27189833983593,0.05299735938951232
0.0547222138369511,125.619532790476,0.17374302893231972,25.32489781055996,132.49371172593433,0.05327742783738346
0.0550144105577252,124.860453342862,0.1746707535207775,25.17186739392098,131.72957758548992,0.05355442613116453
0.0553143653955522,124.063069834385,0.17562311013087822,25.011114878612016,130.92553981129808,0.05383869922004504
0.0556161908276803,123.32013260324,0.17658140587788496,24.861338732813184,130.17872863099663,0.05412466356244854
0.0559292962294609,122.512771881402,0.17757551552853834,24.698574811290648,129.3648249918493,0.054421228714366575
0.0562358953667737,121.656519836905,0.1785489677895065,24.525954399120053,128.497983157139,0.05471154610117527
0.0565288391943147,120.760852332561,0.17947906444194917,24.3453878302443,127.58732313503671,0.054988854619843916
0.056841925232476,119.783269531516,0.18047311261311128,24.148307137553626,126.59198118232794,0.0552851453093166
0.057159158013573,118.79340840519,0.18148032669309427,23.9487511344863,125.58353960719317,0.055585270778496884
0.0574635058188227,117.750774958363,0.18244663097476208,23.73855623160598,124.51714730035377,0.055873121478819426
0.0577707836157613,116.716048631294,0.18342223798004212,23.52995540406887,123.45882622125916,0.05616365931723756
0.0580692743985589,115.676819879669,0.1843699462154245,23.32044688774127,122.39408887481417,0.056445808039819134
0.058382563273413,114.626125196247,0.18536463839308626,23.108626839563396,121.31829220330305,0.05674185907350282
0.0587020720614886,113.55752591852,0.1863790787952263,22.89319722517363,120.22358798811332,0.05704369754058032
0.0590227971179014,112.555356600889,0.18739738084933694,22.691159890739222,119.19868857807631,0.05734659341108041
0.0593493655490109,111.44939734564,0.1884342356181096,22.468198504881027,118.06384836892335,0.05765491358206059
0.0596739258041692,110.364923107619,0.1894647144282372,22.249568498495993,116.9508313405259,0.05796124363423195
0.0600043989025105,109.161432455164,0.1905139665154708,22.006944782961064,115.71159859297312,0.05827305802339373
0.0603460703757343,107.958925717877,0.1915987734429564,21.764519424724003,114.47382264693668,0.05859533632703416
0.0606761501278696,106.719401575606,0.19264677665598598,21.51463135764217,113.19472400716388,0.05890658224573236
0.0610072271195894,105.466875779036,0.19369794610469632,21.26212215705366,111.90111742328118,0.05921867121994725
0.0613353697003511,104.097726789088,0.19473979879861472,20.98610172068014,110.48259934666287,0.05952789799970299
0.0616548194724198,102.641273780512,0.19575405182493286,20.69248079415122,108.96960298586868,0.059828841241088476
0.0619824028835357,101.205597714888,0.19679412915522584,20.40304849932142,107.47856384652123,0.060137352892952134
0.0623057603191085,99.7585948620578,0.19782078901316946,20.111332724190856,105.97412996330422,0.060441791286642316
0.0626264738819333,98.3197807296399,0.19883905457513823,19.821267795095405,104.4772019095821,0.06074364897424123
0.0629534902214166,96.8880352083813,0.1998773314529977,19.532627898009668,102.9874751854444,0.06105134508314891
0.0632851599012673,95.4853334761112,0.2009303826865237,19.249843228784016,101.52813807337273,0.061363322934291586
0.0636074812060648,94.164560725866,0.20195375282925573,18.983575442334587,100.15413125251386,0.06166641421500338
0.0639335370121161,92.9337022344147,0.2029889800134686,18.735434370458005,98.87528252589162,0.06197292375424333
0.0642544106293498,91.5761085389202,0.2040077537481856,18.461743481446312,97.46027742081789,0.06227447007210571
0.0645756201847295,90.2560617857034,0.20502759408651614,18.195622055997806,96.08440295094644,0.06257624104786959
0.0648894637365788,88.78466620801,0.2060240473636377,17.898988707534816,94.54585558627892,0.06287100385613684
0.065200486423458,87.3314700240801,0.20701154439447916,17.60602435685455,93.02552434972577,0.06316303160742141
0.06550304458141,85.7767812635426,0.20797216654597675,17.29259910273019,91.39542159069829,0.06344702997282775
0.0658335180880824,84.148532175155,0.20902141992966158,16.96434408651125,89.68832609019366,0.06375713914573752
0.0661323426654845,82.4779174194498,0.20997018796291328,16.62754815176108,87.93237531656838,0.06403746687974102
0.0664331950356446,80.8149528070143,0.21092539423817158,16.292294485894082,86.18374832863908,0.06431961752584044
0.0667354537409375,79.1443094251266,0.21188506562747658,15.955492780105521,84.42604082562558,0.06460300694044598
0.0670468567170835,77.4486925395856,0.21287377007674013,15.613656415980456,82.64138393121264,0.06489488580440554
0.0671991564492079,76.5811329934124,0.2133573217262351,15.438756411471939,81.72732053049431,0.06503760574525898
0.0673576321169302,75.7087046912492,0.21386048197125337,15.262874865755839,80.80826376989167,0.06518609152822102
0.0674719577123935,74.8257116952583,0.21422346573684936,15.084863477764074,79.87434895056052,0.06529319665372346