File: example/data/02 processed data/test_ID_058.csv
Strain,Stress_MPa,Displacement(mm),Force(kN),True Stress (MPa),True Strain
-0.00042581637871039955,0.692567965330976,2.818443890036925e-05,0.1396217018107247,0.6925741132489297,8.876949229716283e-06
-0.00042113241559799954,0.661545473243425,4.30560217822816e-05,0.1333675674058745,0.6615544444296632,1.3560859793555856e-05
-0.00042020630341579955,0.640853625956701,4.599642796088122e-05,0.1291960909928709,0.6408629100441466,1.4486958988209235e-05
-0.00041875106492939956,0.626947291466446,5.061681015512946e-05,0.1263925739596355,0.6269572864497623,1.59421753339347e-05
-0.00041921073797799956,0.585522871435372,4.9157348225870825e-05,0.1180414108813709,0.5855319368689738,1.5482509507904283e-05
-0.0004221628479006996,0.551422589639122,3.978439922117259e-05,0.111166794071247,0.5514294992506011,1.2530440933532174e-05
-0.00042280185699579957,0.620802622309918,3.775554534434503e-05,0.1251538086576794,0.6208100045907232,1.1891439641192909e-05
-0.00042199447456769956,0.704549739984115,4.0318984553533e-05,0.1420372275807976,0.704558686985716,1.2698812142410564e-05
-0.00042309744680559956,0.790455036141389,3.68170476982821e-05,0.159355735286104,0.7904642021951745,1.1595853302734658e-05
-0.0004145787009528996,0.876401427667913,6.38640657803725e-05,0.1766825278178512,0.8764190561902522,2.011446409043808e-05
-0.00039928800284589954,0.962042977902852,0.00011241203227,0.1939478643452149,0.962077039385144,3.540473773929912e-05
-0.00037021895993409956,1.04546069300641,0.0002047062435153,0.2107648757100922,1.0455280984650583,6.447232902104137e-05
-0.0003289612071014996,1.12749514117911,0.0003356996087588,0.2273030204617085,1.127614353676046,0.000105726570988
-0.00029009402911729957,1.13854821245606,0.0004591028988586,0.2295313196311417,1.1387128457741162,0.0001445888847465
-0.00025218463056729957,1.20386976560035,0.0005794652392549,0.2427001447450305,1.2040894823505093,0.0001824920840799
-0.00020356076575109956,1.50109981103061,0.0007338460100463,0.3026217219037709,1.5014467641351787,0.0002311058945647
-0.00015018912868299957,2.17506010897609,0.0009033009577375,0.4384921179695798,2.1756789227964286,0.000284463775001
-9.581046855342659e-05,3.14409894187225,0.0010759532036493,0.6338503466814457,3.1451644232357454,0.0003388254909469
-4.5889706805926525e-05,4.49330403189412,0.0012344516221976,0.9058500928298548,4.495051044949616,0.0003887280959772
-3.5638146926265588e-06,6.17616635849575,0.0013688363296574,1.2451151378727432,6.178829086334968,0.0004310366430055
4.685679235657343e-05,8.27277803000261,0.0015289217570386,1.6677920508485264,8.2767617875841,0.000481434251628
0.00010480859671990044,10.6749827025533,0.0017129187358927,2.152076512834745,10.68074187668764,0.0005393564851977
0.00016478950490260043,13.2239387947805,0.0019033581193727,2.665946061027749,13.231866319591564,0.0005993032541679
0.00020965841449860045,15.7862483875089,0.00204581690734,3.182507674921794,15.796420284785947,0.0006441442763628
0.0002569007743623004,18.4603432051076,0.0021958113999073,3.721605190149692,18.47311027032208,0.0006913551006813
0.00031056813718410045,21.1656102834292,0.0023662052768665,4.266987033139326,21.18138419799321,0.0007449839350691
0.00037436912126420044,23.9411610927847,0.0025687734013208,4.826538076305396,23.96053098815852,0.0008087353739753
0.00042998606985820043,26.7167659817272,0.0027453572131068,5.386100021916203,26.73986741990005,0.0008643058172931
0.00047928224554260045,29.4999386069027,0.0029018725709047,5.947187623151584,29.526900831370963,0.0009135581914954
0.0005270676087109005,32.3453725234083,0.0030535910989641,6.520827100719114,32.37648104045717,0.0009612987802883
0.0005903185807671005,35.2190159803605,0.0032544129352425,7.100153621640677,35.25511589254098,0.0010244869820613
0.0006491122851005005,38.0911895502981,0.0034410829465011,7.679183813340096,38.13247299684093,0.0010832187591091
0.0007009566766967004,41.0018533628833,0.003605688889819,8.265973637957273,41.04841711946048,0.0011350056813272
0.0007427211776405004,43.9379022647663,0.0037382911803156,8.857881096576888,43.9896353899688,0.001176721936081
0.0007951232154281004,46.8848965424742,0.0039046676502912,9.4519951429628,46.94255636572354,0.0012290609777954
0.0008541283038180004,49.8960397161654,0.0040920088059291,10.059041606778944,49.9603468134566,0.0012879918534236
0.0009088193515336005,52.8715443780074,0.0042656528824262,10.658903346606293,52.94257797034578,0.0013426110132064
0.0009555219956104004,55.8650873005123,0.00441393377737,11.26240159978328,55.942751803130086,0.0013892499082632
0.0010014361954183003,58.8662190665992,0.0045597113617601,11.8674297638264,58.9507585840486,0.0014350993149602
0.0010486053561601005,61.8541380158654,0.0047094734471153,12.469794223998464,61.94588617982759,0.0014821997225795
0.0011013937518402003,64.8280624088509,0.0048770766033996,13.069337381624342,64.92764396047859,0.001534908544137
0.0011504896376662004,67.7910739505178,0.0050329560408972,13.666680508424388,67.89853520883534,0.0015839279286028
0.0011922848455404003,70.7136816444676,0.0051656558258978,14.255878219524668,70.82873126385577,0.0016256561176478
0.0012405175781937004,73.6296747589044,0.005318794752072,14.843742431395128,73.75301999597666,0.001673809344778
0.0012860611625052005,76.501786333999,0.005463395632261,15.422760124934198,76.63342712937454,0.0017192757279637
0.0013302357797050004,79.3205219802693,0.0056036500418704,15.991017231222292,79.46051708147117,0.0017633734897464
0.0013784570120258005,82.0918415816241,0.0057567524544889,16.54971526285542,82.24068643533072,0.0018115086064387
0.0014278389006667004,84.8159188259624,0.0059135399509238,17.098889235314022,84.97389121161646,0.0018607999055032
0.0014679818300974005,87.484271661052,0.0060409937518662,17.636829166868086,87.65072581490745,0.0019008674037177
0.0015108709975150004,90.1317411566935,0.0061771668584171,18.170559017189408,90.30709826043037,0.0019436742057273
0.0015481985086800004,92.769363402342,0.006295681706366,18.702303661912147,92.95331501937612,0.0019809285408838
0.0015883591173283004,95.3605497516172,0.0064231916388243,19.22468682992603,95.55346914873162,0.0020210088697539
0.0016298376456955004,97.9645922354927,0.0065548859663902,19.74966179467533,98.16684317434232,0.0020624027975588
0.0016715225319476005,100.538902507544,0.0066872354802406,20.26864274552087,100.7506591425024,0.0021040009361629
0.0017072700740753005,103.096699412978,0.0068007339264961,20.784294601656367,103.31752877405128,0.0021396727082518
0.0017477079146440003,105.66942434721,0.0069291240703017,21.30295594839753,105.90003743437197,0.0021800233034808
0.0017891925348143005,108.224120199279,0.0070608377393424,21.817982632174648,108.46479829446332,0.0022214167279989
0.0018324344948354005,110.707793754977,0.0071981309624094,22.31869122100337,110.95878247875896,0.0022645618054584
0.0018731575660390005,113.16935421229,0.0073274267134808,22.814941809197663,113.43053221203884,0.0023051919356755
0.0019137961700046004,115.606526518784,0.0074564542810716,23.30627574618685,115.8780272367622,0.0023457361458233
0.0019533759269492004,118.050317850127,0.0075821200093707,23.79894407858561,118.33223018936606,0.0023852223883177
0.0019978423613420003,120.489991217596,0.0077233009385678,24.29078222946736,120.78308742618148,0.0024295819028685
0.0020484248455928003,122.914595232969,0.0078839003260641,24.77958239896655,123.21980670302736,0.0024800403689513
0.0020941849553164004,125.317821581173,0.0080291886744366,25.26407283076448,125.63473510361224,0.0025256860905834
0.0021317894201269005,127.751071326677,0.0081485828502099,25.754615979458087,128.07894225231746,0.0025631949946926
0.0021767173685555002,130.207115330309,0.0082912290864707,26.24975445059029,130.54713958917264,0.0026080069274207
0.0022217467351731005,132.67763347478,0.0084341973254816,26.74781090851565,133.03008366104908,0.002652918001626
0.0022645060377532006,135.137263984818,0.0085699581111734,27.24367241933931,135.50202640737183,0.0026955631083034
0.0023007514684139003,137.588013577686,0.0086850373535211,27.7377435372615,137.96437799888884,0.0027317103153627
0.0023331269797049006,140.036780550849,0.00878782960187,28.23141495905116,140.4243772013924,0.0027639969856023
0.0023768551396424003,142.515899860162,0.0089266665096716,28.73120541180866,142.91659022563522,0.0028076034971408
0.0024233092893434006,144.972468189536,0.0090741584349723,29.226449587010457,145.38679988876774,0.0028539263320089
0.0024624216571635005,147.428246720281,0.0091983402028011,29.72153453880865,147.85536330889067,0.0028929264746287
0.0025022105146239003,149.850323834167,0.0093246698252379,30.20982528496807,150.29041983194924,0.0029325996051974
0.0025418646363904005,152.280144882681,0.0094505716618465,30.699677208348486,152.73341556674086,0.0029721368260447
0.0025865744739534003,154.731591817593,0.009592525396109,31.19388891042675,155.19907739998376,0.0030167129836003
0.0026287321872733005,157.189958796936,0.0097263761358997,31.68949569346229,157.67149853364324,0.0030587428275693
0.0026632381717878006,159.634331699711,0.0098359326367333,32.18228127066174,160.12886793061125,0.0030931428367172
0.0027013155538444006,162.096980288846,0.009956828324763,32.67875122623136,162.605317865129,0.0031311019015033
0.0027416598121803005,164.575882944011,0.0100849213449794,33.178498001512615,165.0986340730727,0.003171319226685
0.0027820944686258006,167.067241605596,0.0102133013791939,33.68075590768815,167.60466147618138,0.0032116250427531
0.0028221413716069004,169.506243631437,0.0103404502961589,34.1724587160977,170.0582974541644,0.0032515427396875
0.0028593485759812005,171.942834686308,0.0104585831700473,34.66367547275969,172.50922159561838,0.0032886284720365
0.0029020543104841005,174.335674555708,0.010594173877094,35.14607199043074,174.91738871294382,0.0033311930880389
0.0029426595416396006,176.711440578419,0.0107230954860127,35.625026420609274,177.30825747630664,0.0033716624614779
0.0029845456772375004,179.070157331709,0.0108560839665361,36.10054371807254,179.68244100537635,0.0034134067376759
0.0030246037162739003,181.407437557107,0.0109832682404766,36.571739411512766,182.0349797767943,0.0034533274785884
0.0030659992386111003,183.726060516847,0.0111146990238972,37.03917380019636,184.36922897841905,0.0034945794443035
0.0031081831341220004,186.038852523403,0.0112486328921443,37.50543266871804,186.69796520236727,0.0035366152985983
0.0031509463597108006,188.327614324604,0.0113844061333888,37.96684704784017,189.0028893002272,0.0035792266463514
0.0031923896789156003,190.656121951911,0.011515988671864,38.436274185505255,191.34764753950776,0.0036205210430444
0.0032340639395851004,192.947593520996,0.0116483044494897,38.8982348538328,193.65547141457992,0.0036620438319006
0.0032773444003450004,195.243446336155,0.0117857199124024,39.361078781368846,195.968197382848,0.0037051651578323
0.0033216861634649004,197.539533714728,0.011926505010308,39.82396999688917,198.2815671756989,0.0037493419555792
0.0033635239893781005,199.839408839093,0.0120593401075825,40.28762482196115,200.5984423503021,0.0037910223422386
0.0034071788791337006,202.150447880299,0.0121979443825565,40.75353029266828,202.9270840756228,0.0038345111029869
0.0034529232823954006,204.434577705702,0.0123431828629124,41.214010865469525,205.22934097377245,0.0038800793964472
0.0034934816999474005,206.696207320737,0.01247195583864,41.66995539586058,207.50814620883733,0.0039204799329156
0.0035401128840738005,209.001211451002,0.0126200098482413,42.134644228522,209.83195077283068,0.0039669275796084
0.0035852925185287004,211.219399455022,0.0127634551876356,42.58183093013244,212.06849845965303,0.0040119273322367
0.0036305113926079005,213.391331550791,0.0129070251128371,43.01969244063947,214.25881100754307,0.0040569641407321
0.0036768671834567002,215.500901343772,0.013054204748782,43.44498171090444,216.3869463483984,0.0041031311830541
0.0037239947693634002,217.574410142121,0.0132038348340358,43.8630010846516,218.47923426042945,0.0041500646930696
0.0037741147392338003,219.595422596462,0.0133629657383743,44.27043719544674,220.51965759125264,0.0041999758472528
0.0038284646078274006,221.520217647267,0.013535526571159,44.65847587768903,222.4645933297909,0.0042540964618541
0.0038840653510470004,223.377680302139,0.0137120589308812,45.032940348911225,224.3423946064371,0.0043094596439793
0.003943425182059401,225.206097613507,0.0139005263943456,45.40154927888301,226.1920766069068,0.0043685624699972
0.0040093926666634,226.95294311142,0.0141099731579633,45.75371333126228,227.96154151627763,0.0044342402432488
0.004078632283714001,228.693275680895,0.0143298089420989,46.10456437726844,229.7254429082493,0.0045031711391206
0.004154510149681,230.317466548579,0.0145707211665442,46.43200125619352,231.3744402760953,0.0045787052294934
0.004242567057988901,231.901485605474,0.0148503018504217,46.75133949806355,232.9861492466717,0.0046663560313602
0.004342693713157901,233.403105440825,0.0151682039805833,47.05406605687032,234.51816242130627,0.0047660115825578
0.0044521876348149,234.844670854146,0.0155158471818443,47.34468564419584,235.9923288146006,0.0048749789593521
0.0045736492720828,236.253480571785,0.0159014878801699,47.628701683271856,237.4367189522449,0.0049958426103397
0.0047073302298499,237.614419573018,0.0163259249210804,47.90306698592043,238.8362385254952,0.0051288485388607
0.0048577324281498,238.835488806017,0.0168034519006826,48.14923454329303,240.0995079078525,0.0052784701279912
0.005014796323483801,239.991033791357,0.0173021297683681,48.38219241233757,241.29886245589336,0.0054346949467448
0.005172120369305,241.023203954121,0.0178016336138504,48.59027791715079,242.37457616490136,0.0055911540631545
0.00533425367228,241.964572155572,0.018316406850796,48.78005774656332,243.360452957802,0.0057523703873121
0.0055056475716279,242.763612973775,0.0188605824812256,48.94114437551304,244.20571160241505,0.0059227666774588
0.005679695757157601,243.414944274543,0.0194131854702824,49.07245276574787,244.9032779625556,0.0060957720966089
0.0058534019321925,243.929489063108,0.0199647025760182,49.176184995122576,245.46334093670328,0.0062684077167801
0.006023282172804501,244.38613508164,0.0205040723399613,49.26824483245862,245.96437476434787,0.0064372121610929
0.006198582098440401,244.77952541284,0.0210606496038553,49.34755232322855,246.40321543328656,0.0066113721014249
0.006379603877741601,245.099655173192,0.0216353937531366,49.41209048291551,246.7698370782093,0.0067911848586503
0.0065628847077321,245.393027674664,0.0222173103883564,49.47123437921226,247.110184544896,0.0069732086442309
0.006740440301241801,245.655448023489,0.0227810493977497,49.52413832153538,247.41805869947305,0.0071495148695456
0.0069208438084635004,245.855382687477,0.0233538305331786,49.56444514979537,247.6637810947064,0.0073286171391857
0.007108128256527001,246.03188870556,0.0239484586557802,49.60002876304089,247.88766335584933,0.0075145167879545
0.007296269104577901,246.194474874587,0.0245458058483418,49.63280613471674,248.0977951206361,0.0077012317148118
0.007480221024719501,246.344262474511,0.0251298531947914,49.66300331486142,248.294056222972,0.0078837557610878
0.007666978818757501,246.46651854362,0.0257228091908621,49.68765013839379,248.4633094817093,0.0080690298266045
0.0078501106987314,246.580185664565,0.0263042529097792,49.71056542997631,248.6230541893716,0.0082506734575594
0.0080390453344108,246.708909936917,0.0269041203780613,49.73651624328247,248.7994567751164,0.0084380381144834
0.0082240534057436,246.829148335329,0.0274915210045429,49.76075630440233,248.96637942698067,0.0086214748229632
0.008404621055601,246.969666131164,0.0280648232928402,49.78908469204266,249.1527086630263,0.0088004763831753
0.0085869312758464,247.10710732298,0.0286436582421193,49.81679283631277,249.3364148919117,0.0089811728991858
0.0087736608009784,247.217148936894,0.0292365244844134,49.83897722567784,249.49361200078704,0.0091662157611245
0.0089526738814976,247.346431146844,0.0298048910150619,49.86504051920375,249.6683629337089,0.0093435797365746
0.0091359581118666,247.459473714119,0.0303868184464834,49.88782990076639,249.8278220922649,0.0095251429282529
0.0093189501284661,247.537311221752,0.0309678180991869,49.9035219423052,249.9517019073196,0.0097063837696135
0.0095001443146351,247.675661644616,0.0315431096402734,49.931413387554585,250.13627914083125,0.0098858116252889