File: example/data/02 processed data/test_ID_103.csv
Strain,Stress_MPa,Displacement(mm),Force(kN),True Stress (MPa),True Strain
0.0002620711293975004,0.639597558328552,-2.502191841926332e-05,0.1289428677590361,0.6395925177118825,-7.88095024173774e-06
0.0002527798663640004,1.70613062128685,-5.45216785508768e-05,0.343955933251429,1.7061013233009288,-1.71723296643573e-05
0.00025760576875700044,3.10406705493072,-3.919943845311736e-05,0.6257799182740332,3.104028731250256,-1.2346356043653084e-05
0.00026604526187540045,4.5403389147142,-1.2404047802044644e-05,0.9153323252063826,4.540321176578472,-3.906794340762336e-06
0.00027913967519600043,6.9192568927562,2.9170714490849244e-05,1.3949221895796502,6.919320464304959,9.187584405301612e-06
0.00029885749352160046,10.0002657553785,9.177478767446064e-05,2.016053576284306,10.000554817509649,2.8905027182620865e-05
0.00033079397368150046,13.6635626971047,0.0001931731121822,2.754574239736308,13.664394014562872,6.084007430184511e-05
0.0003746463596907004,17.6486461764449,0.0003324044377615,3.5579670691712915,17.650493889298296,0.0001046888310391
0.0004333378770197004,21.6996773079528,0.0005187500052811,4.374654945283285,21.70322272770653,0.0001633724824241
0.0004965402117366004,25.7490867666357,0.0007194174180072,5.191015892153757,25.75492120490899,0.0002265624959311
0.0005664390169995004,29.9205011226317,0.0009413461247169,6.031973026322551,29.929372161303,0.0002964430248391
0.0006393103114695004,34.2008841301523,0.0011727124846592,6.894898240638704,34.21351650930374,0.0003692900669135
0.0007174350631139004,38.3486338332981,0.0014207585711302,7.731084580792898,38.3657941955689,0.0004473829238631
0.0007946799430238004,42.5301794569664,0.0016660110648441,8.574084178524426,42.55249622848297,0.000524590272898
0.0008821254564654004,46.6751433431488,0.0019436505700212,9.409708897978796,46.7037166247125,0.0006119861061769
0.0009593357551001005,50.8330550718029,0.0021887932681863,10.247943902475466,50.8680985517218,0.0006891461907213
0.0010366343382707003,54.9497637411968,0.002434216269753,11.077872370225275,54.9918927518796,0.0007663885389519
0.0011118127592251005,59.0581542883651,0.0026729077562832,11.906123904534404,59.10787302810342,0.0008415065446706
0.0011873619478914004,63.0826502289084,0.0029127764302987,12.717462286147937,63.1405228767029,0.0009169893360447
0.0012635924059978005,67.0897381743863,0.0031548081347865,13.52529121595628,67.15640124580464,0.0009931470236037
0.0013342398510919004,70.9955314309131,0.0033791137729603,14.312699136472082,71.07109110904753,0.0010637218497659
0.0014054654926013005,74.8417389246548,0.0036052551847527,15.08809456721041,74.92672272537733,0.0011348692362506
0.0014814837806968004,78.5987487252477,0.0038466132494559,15.845507743009938,78.69397360343265,0.0012107984197709
0.0015509944963680005,82.3281950234837,0.0040673097717119,16.597364116734315,82.43366093595817,0.0012802226129942
0.0016233973852328005,86.0571253797814,0.0042971889438577,17.34911647656393,86.17359899481201,0.0013525302550907
0.0016966883747201005,89.773604578602,0.0045298878354798,18.098358683046165,89.9016878413824,0.0014257195049054
0.0017674640161083005,93.4842574316353,0.0047546004968874,18.84642629821768,93.62425122591422,0.0014963918146325
0.0018371278508783004,97.2234516135741,0.0049757831722821,19.600247845296536,97.37581785435836,0.0015659490638053
0.0019057151965429003,100.967782902538,0.0051935479947672,20.355105033151663,101.13294228094102,0.0016344267445812
0.0019737905182785004,104.715708737425,0.0054096871412778,21.110686881464883,104.89412739035308,0.0017023885836093
0.0020478418893703004,108.449067407334,0.0056448002444942,21.86333198931853,108.64187790252018,0.0017763112653878
0.0021159282069314004,112.157243541636,0.0058609743027507,22.61090029799382,112.36428313919976,0.0018442744382594
0.0021851205768937004,115.911472351253,0.006080660077381,23.367752826012605,116.13346235517008,0.0019133369312349
0.0022522083021170006,119.608564116687,0.006293663604965,24.1130865259241,119.84565894088333,0.0019802941760706
0.0023239864667473006,123.283530531263,0.0065215592776662,24.85395975510262,123.5367591461668,0.0020519277737205
0.0023914453127421003,126.933909620583,0.0067357411136997,25.58987617950953,127.20319905483622,0.0021192460750255
0.0024612421264957004,130.511957905803,0.0069573459973674,26.31121071380989,130.79794746421072,0.0021888927033981
0.0025286214784908004,134.121287944406,0.0071712754399518,27.03885164959225,134.42422359738566,0.0022561224705477
0.0025976357394872003,137.710396202189,0.0073903957186154,27.762415874361302,138.03094244549655,0.0023249788317778
0.0026646471575628005,141.240787719653,0.0076031569710054,28.47414280428205,141.5790163431935,0.0023918323959514
0.0027358238355471003,144.745902077684,0.0078291429236056,29.18077385886109,145.10282691389577,0.002462836513833
0.0028027166409456006,148.233766460404,0.0080415275807458,29.88392731841745,148.6092076954872,0.0025295625496614
0.0028726199394316005,151.737831510864,0.0082634705534389,30.590346832590185,152.13275469276405,0.0025992868160444
0.0029413172222838005,155.280340847953,0.0084815844264946,31.30451671494733,155.69515134265436,0.0026678034195075
0.0030094932710798003,158.730172014766,0.0086980433814219,32.00000267817683,159.1650198642542,0.002735795518887
0.0030820650045690003,162.191640470732,0.0089284586352501,32.69783471889958,162.6477416842521,0.0028081663634571
0.0031482172488556002,165.573410312526,0.0091384920108601,33.37959951900524,166.0499744975187,0.0028741309261143
0.0032181128227404005,168.959753451251,0.0093604104579443,34.0622862957722,169.457873968787,0.0029438234708012
0.0032865999700741003,172.355494949966,0.0095778571507288,34.746867781913146,172.87543079556409,0.0030121069691592
0.0033499948050229006,175.640658408662,0.0097791357516912,35.409156735186265,176.18163914632964,0.0030753091420797
0.0034145217730951003,178.94031321106,0.0099840088753205,36.0743671433497,179.50300350247792,0.0031396359055868
0.0034800256091471003,182.246223590095,0.0101919835547856,36.74083867576316,182.831247373954,0.0032049322740972
0.0035421472265840005,185.456408751813,0.0103892196901477,37.3880120043655,186.06325831825976,0.0032668531975208
0.0036097252673345003,188.728210680628,0.0106037799695306,38.0476072732146,189.35852010428167,0.0033342085625246
0.0036703880277197004,192.019204057596,0.0107963842337536,38.71107153801135,192.6721530677584,0.00339466756975
0.0037382009353730005,195.232189028507,0.0110116902155528,39.358809308147016,195.9093028507704,0.0034622483817786
0.0038025035724170006,198.536942565061,0.0112158510881675,40.02504762111629,199.2382845440562,0.0035263267190197
0.0038678040674582003,201.763879606905,0.0114231801599233,40.67559812875205,202.4897961884845,0.0035913952317073
0.003932463891354401,204.999039348039,0.0116284751007937,41.32780633256466,205.7498507574076,0.0036558211777209
0.0039950814577612,208.255043438053,0.0118272858741353,41.98421675711149,209.03082042497343,0.0037182082973187
0.0040590823008147,211.424432553016,0.0120304885508302,42.623165602688026,212.2255472664632,0.003781969580973
0.004126604690944901,214.609381419507,0.0122448721394936,43.26525129417261,215.43705525743383,0.0038492348234087
0.0041915537926786005,217.749284800546,0.0124510855374981,43.89825581579007,218.60321077559504,0.0039139323084168
0.0042581052746805004,220.832557772079,0.0126623864928541,44.519843646851136,221.7132718497847,0.00398022162432
0.004329650894279601,223.895222915127,0.0128895438350813,45.1372769396896,224.80417009315207,0.0040514805034903
0.0044080576232413005,226.917563062274,0.0131384851995347,45.74658071335444,227.85657189496948,0.0041295671629109
0.004487275030920201,229.834886085878,0.0133900004689152,46.334713034913,230.80417403311043,0.0042084549997883
0.0045702392824645,232.699384602214,0.0136534119675683,46.91219593580634,233.70005879515057,0.0042910674211776
0.0046565851088871,235.375077387751,0.0139275599664601,47.451615601370605,236.4075814837913,0.0043770398299223
0.004748503641794301,238.083460832987,0.0142194013084404,47.99762570393018,239.1497298958174,0.0044685527235435
0.004850680933023601,240.537999262055,0.0145438142080935,48.49246065123029,241.6398386230798,0.0045702692754743
0.004957148519042,242.826356800888,0.0148818487937019,48.95379353105902,243.96453164341912,0.00467624577047
0.005067529880009301,245.007205580759,0.0152323096147731,49.39345264508102,246.18264671879257,0.0047861061311853
0.005201671767841401,247.038401396496,0.01565821010864,49.8029417215336,248.2567255520768,0.0049195986251193
0.0053512547392922,248.811847439425,0.0161331360429963,50.16046844378809,250.07613574929889,0.0050684364386651
0.005513785465271001,250.342379280907,0.016649171097979,50.46902366303086,251.65513301499297,0.0052301323986008
0.005691552002955201,251.556853799729,0.0172135798551263,50.71386172602537,252.9206944268112,0.0054069559866499
0.005885264238682301,252.507117378902,0.0178286162035598,50.90543486358664,253.92502367320617,0.0055996050973215
0.0060995941318688005,253.319207247673,0.018509113614427,51.06915218113088,254.79596755874823,0.0058127154720721
0.006330942776415901,253.851059730338,0.019243645560864,51.17637364163614,255.3896486496137,0.0060426968058423
0.0065711714687928,254.259280832546,0.0200063716591607,51.25867101584127,255.8614243506962,0.0062814497423728
0.0068214154572686005,254.63193918573,0.0208008963225713,51.33379893984318,256.3001510179875,0.0065300958473757
0.007085068178585801,254.974940560778,0.0216379937127534,51.40294801705285,256.7126243909399,0.0067919982008804
0.007359265372589201,255.105925022644,0.0225085698037142,51.42935448456503,256.9144508559395,0.0070643022801478
0.007638346424548,255.350864634645,0.0233946521436834,51.47873431034444,257.2323905095163,0.0073413803768262
0.0079192121213438,255.441346761238,0.0242864007310101,51.49697550706559,257.3952840559506,0.0076201528213203
0.0082041475911781,255.523379429802,0.025191070847734,51.513513293048085,257.5507518879023,0.0079028853183931
0.0084973345871306,255.62051013764,0.0261219395598832,51.53309484374822,257.7235978592406,0.0081937221255286
0.0087935769627625,255.715707912127,0.0270625091025145,51.5522867150848,257.8953326910334,0.0084875039326707
0.0090930345344727,255.71722530915,0.0280132868926943,51.55259262232464,257.973439481115,0.0087843865387306
0.0093952464637984,255.812355629494,0.0289728097683034,51.57177089490599,258.14671868966246,0.0090839104859677
0.0097018635995702,255.837460917962,0.0299463191743789,51.576832121061145,258.2504972207689,0.0093877088001536