File: example/data/02 processed data/test_ID_111.csv
Strain,Stress_MPa,Displacement(mm),Force(kN),True Stress (MPa),True Strain
6.25605360924668e-05,-0.22511482092346,0.00019862970209358208,-0.04538314789816954,-0.22512890422733933,6.25585792637125e-05
3.01039855498901e-05,0.749159059003007,9.558015412090106e-05,0.15103046629500624,0.7491816116764939,3.0103532434043706e-05
-2.04982418762035e-05,2.70946548259445,-6.508191795694612e-05,0.5462282412910411,2.7094099433156327,-2.04984519680522e-05
-0.0001010951790928,6.21444820882568,-0.00032097719361964,1.2528327588992572,6.213819958071046,-0.00010110028955489668
-0.0001629551785242,10.6834217321432,-0.000517382691814335,2.153777821200069,10.68168081324759,-0.00016296845716183211
-0.0002008059143445,15.5231260341548,-0.0006375587780437875,3.1294622084856076,15.520008898638027,-0.00020082607855151732
-0.0002015407646033,20.3668108069113,-0.0006398919276154774,4.1059490586733185,20.362706064288744,-0.0002015610766724094
-0.0001935324956381,25.4955842827772,-0.0006144656736509675,5.1399097914078835,25.490650058723205,-0.00019355122546816468
-0.0001542630170762,30.8016987931062,-0.000489785079216935,6.20962247669021,30.796947230119304,-0.00015427491683924716
-0.0001051269652423,36.2181810105007,-0.0003337781146443025,7.3015852917169415,36.21437350304447,-0.000105132491469059
-4.69006725784214e-05,41.6868273167635,-0.00014890963543648793,8.404064387059522,41.684872176524685,-4.6901772449332326e-05
2.36569781070333e-05,47.1805774098654,7.511090548983072e-05,9.511604405828866,47.18169355975227,2.3656698285240423e-05
0.0001125265236801,52.7773752711273,0.0003572717126843175,10.639918854659264,52.78331412569552,0.00011252019304574027
0.0002222502743693,58.465138286,0.0007056446211225274,11.7865718784576,58.47813217902511,0.0002222255804359214
0.0003211662031008,64.1172888068544,0.00101970269484504,12.926045423461849,64.13788111305362,0.00032111464027570865
0.0004306861824743,69.7920168057751,0.0013674286293559024,14.070070588044262,69.82207526306037,0.00043059346380125207
0.0005469498669414,75.4085926861372,0.001736565827538945,15.202372285525259,75.44983740587313,0.0005468003443814201
0.0006732384831266,80.9839659531001,0.002137532183926955,16.326367536144982,81.03848747549593,0.0006730119597627177
0.0008054938401659,86.5807451383348,0.002557442942526732,17.454678219888297,86.6504853952207,0.000805169604104295
0.000932538482886,92.2257225299647,0.0029608096831630496,18.59270566204088,92.31172656533586,0.0009321039390065699
0.0010515954617071,97.9040780090412,0.0033388155909200427,19.737462126622706,98.00703349315813,0.0010510429225308471
0.0011826864985188,103.586057199637,0.00375502963279719,20.882949131446818,103.7085670309218,0.0011819876757797009
0.0012994949741093,109.194486472358,0.004125896542797027,22.01360847282737,109.33638415872926,0.0012986513612833221
0.0014160026237362,114.64458628319,0.004495808330362435,23.112348594691102,114.80692331816414,0.0014150010374087473
0.0015362226349964,119.944007557653,0.004877506866113569,24.180711923622844,120.12826825699524,0.0015350438520985053
0.0016477187079485,125.017949980624,0.005231506897736487,25.203618716093796,125.22394439563644,0.001646362708810597
0.0017570425534406,130.069670043574,0.005578610107173905,26.22204548078452,130.29820798875255,0.0017555007599069682
0.0018516046389395,135.069830731914,0.005878844728632912,27.230077875553867,135.31992665707799,0.0018498925321740417
0.0019837767521185,140.039219254034,0.006298491187976237,28.231906601613254,140.31702580157497,0.0019818116654503376
0.0021054992351562,144.949110193445,0.006684960071620934,29.221740614998513,145.25430043409386,0.002103285778051803
0.0022360822851549,149.664118279006,0.0070995612553668075,30.172286245047612,149.998779562613,0.0022335859737743265
0.0023652725135957,154.26275509738,0.007509740230666347,31.09937142763181,154.62762855188336,0.002362479659604098
0.002481976523612,158.803863324246,0.0078802754624681,32.014858846167996,159.19801078487566,0.002478901506908576
0.0025892131830217,163.193208452714,0.008220751856093897,32.89975082406714,163.61575045941936,0.002585866945405192
0.0027046860733322,167.386578141755,0.008587378282829735,33.745134153377805,167.83930628851772,0.002701034991825727
0.0028054451111382,171.545299515171,0.008907288227863784,34.583532382258475,172.02656043703456,0.0028015171946567836
0.0029233159573357,175.62086476089,0.009281528164540847,35.40516633579542,176.13426003728657,0.0029190513783620836
0.0030512410042,179.628521145497,0.009687690188335,36.21310986293219,180.17661105473994,0.0030465954158414195
0.0031965711853625,183.544811776472,0.010149113513525937,37.002634054136756,184.13152583301945,0.0031914730132485557
0.0033523906813567,187.179749882314,0.010643840413307522,37.73543757627451,187.80724953155814,0.0033467839468649834
0.0035126754558505,190.665089485371,0.011152744572325337,38.43808204025079,191.33483406549382,0.003506520420970095
0.0036990959196104,193.812674915784,0.011744629544763019,39.07263526302205,194.52960659073375,0.003692271089588477
0.0039078967600637,196.589504858617,0.012407572213202246,39.63244417949719,197.3577563477165,0.0039002807667488848
0.0041637310200563,198.808138773253,0.013219845988678751,40.07972077668781,199.6359223877029,0.004155086678886363
0.0044319852399517,200.463908762226,0.014071553136846647,40.41352400646476,201.3523618470032,0.00442219291566524
0.0047447744209204,201.609100057845,0.015064658786422271,40.64439457166156,202.56568975882425,0.004733553458725091
0.0050520627530286,202.332121477422,0.016040299240865804,40.79015568984828,203.35431605207933,0.00503934390362879
0.0053951230463476,202.833695651184,0.01712951567215363,40.891273043278694,203.92800839716756,0.005380621505022013
0.0057435653168845,203.17988465621,0.018235819881108287,40.96106474669194,204.34686159480998,0.005727133932075898
0.0061102925632594,203.438253556672,0.019400178888348593,41.01315191702508,204.68132080446185,0.006091700422828037
0.0064787196142525,203.638175229993,0.020569934775251687,41.05345612636659,204.95748987006613,0.006457822917663505
0.0068408825033983,203.763698571063,0.0217198019482896,41.0787616319263,205.15762209144552,0.006817589834621239
0.0072100775194205,203.834155471393,0.022891996124160086,41.09296574303283,205.30381553344736,0.00718420917791073
0.0075779369628309,203.925355450591,0.024059949856988106,41.11135165883915,205.47068893931845,0.007549368633747903
0.0079635889991925,203.954775967841,0.025284395072436187,41.11728283511674,205.57898797807124,0.007932046972150188
0.0083295032505002,204.047888849375,0.026446172820338135,41.136054392034005,205.74750640280357,0.008295004378225035
0.0087086644249413,204.031528376082,0.02765000954918863,41.13275612061813,205.8083704888172,0.008670962736359663
0.0090931669999296,204.075355146048,0.02887080522477648,41.14159159744327,205.93104643096098,0.009052073084912439
0.0094573815233087,204.11335922007,0.03002718633650512,41.14925321876612,206.04373713221838,0.009412940468291114
0.0098381204458531,204.150784367644,0.03123603241558359,41.15679812851703,206.15924437336827,0.009790041221187299
0.0102197038381012,204.201500175437,0.03244755968597131,41.1670224353681,206.2883790305259,0.010167835749838344
0.0105899163725956,204.168628969651,0.03362298448299103,41.160395600281646,206.33075767634708,0.010534235963825404
0.0109696886803076,204.196784957265,0.03482876155997663,41.16607184738463,206.43676011776594,0.010909958065939538
0.0113505088221707,204.20565912457,0.036037865510391974,41.16786087951331,206.5234972600006,0.01128657512869204
0.0117447505445217,204.241096908838,0.03728958297885639,41.17500513682174,206.63985764297175,0.01167631626966513
0.0121551386332005,204.262576072391,0.03859256516041158,41.17933533619403,206.74541600212555,0.012081858160840406
0.0125578173050502,204.199343998473,0.03987106994353438,41.166587750092155,206.76364205421694,0.01247962187937445
0.0129585721746633,204.175380543409,0.041143466654555975,41.161756717551256,206.8212019484701,0.012875328255213984
0.0133411199716358,204.120293603109,0.04235805590994366,41.150651190386775,206.8434869287136,0.013252910903032772
0.0137292574332164,204.10312966555,0.04359039235046207,41.14719094057488,206.90531407565348,0.013635865013211242
0.0141275473717543,204.081580858195,0.0448549629053199,41.14284670101211,206.96475305947166,0.014028683621227138
0.0145217496960943,204.06928058967,0.0461065552850994,41.14036696687747,207.03272360305522,0.01441731888693948
0.0149176430065036,204.027156012689,0.04736351654564892,41.1318746521581,207.07076028971852,0.014807469306661013
0.0153177618529684,203.953621290932,0.04863389388317467,41.11705005225189,207.077734290917,0.01520162936385162
0.0157215218584753,203.84838266827,0.049915831900659076,41.09583394592323,207.05318947220402,0.015599218927050879
0.0161242575749645,203.797133476789,0.05119451780051228,41.085502108920664,207.08321095000818,0.015995642440921908
0.0165170121065447,203.693559391135,0.05244151343827942,41.064621573252815,207.05796837762358,0.016382089909372354
0.0169138054028787,203.692326530207,0.053701332154139865,41.06437302848973,207.13753890319856,0.016772359691804718
0.017300118398991,203.605384806762,0.05492787591679642,41.04684557704322,207.12778207059108,0.0171521752030802
0.0176905008716133,203.500423953913,0.056167340267372225,41.025685469108865,207.10044838124338,0.017535845254150074
0.0181020824816703,203.451879078513,0.057474111879303194,41.015898822228216,207.13478177464305,0.017940190587785818
0.0184973991102392,203.411862461219,0.05872924217500946,41.00783147218175,207.17445286492125,0.01832840303417697
0.0189090400878191,203.428114859732,0.06003620227882564,41.011107955721975,207.27474523860414,0.01873248635821225
0.0193145028207662,203.350145257759,0.06132354645593268,40.995389283964215,207.2777522119432,0.019130345307203592
0.0197309261296316,203.224108728641,0.06264569046158032,40.969980319694024,207.23390860572604,0.0195387945832643
0.020147529115262,203.097946649208,0.06396840494095685,40.94454604448033,207.18986844257284,0.01994725322485762
0.0205585566428797,203.026971728464,0.06527341734114304,40.93023750045835,207.20091322677595,0.020350081967364292
0.0209759674469669,202.972701351482,0.0665986966441199,40.91929659245877,207.23025012765362,0.02075900065571204
0.021391930305757,202.932274606201,0.06791937872077847,40.91114656061012,207.2733876813656,0.021166334579241875
0.0218182255979929,202.864092047836,0.06927286627362744,40.89740095684374,207.29022657386767,0.021583614512184348
0.0222477110973072,202.784847233358,0.07063648273395036,40.881425202244976,207.29634592951732,0.022003841177013893
0.0226822284125389,202.676120250987,0.072016075209811,40.85950584259898,207.2732663042871,0.022428811552160765
0.0231227360731659,202.55885596882,0.07341468703230172,40.83586536331411,207.24257093466946,0.022859456383981736
0.0235398407419005,202.434367285732,0.07473899435553408,40.81076844480358,207.19964005232555,0.023267051342949867
0.0239607885475065,202.263084942901,0.07607550363833313,40.77623792448884,207.10946795218422,0.02367823345006649
0.0243749221284877,202.107427733287,0.07739037775794844,40.74485743103067,207.03378054587483,0.024082594497394274
0.0247988409222046,201.939387360334,0.0787363199279996,40.71098049184334,206.94725010341037,0.024496340571454143
0.0252208544971392,201.864787527577,0.08007621302841696,40.695941165559525,206.95598996190594,0.024908057182605668
0.0256562091997064,201.821682846673,0.08145846420906781,40.68725126188928,206.99966216282405,0.025332611844425885
0.026093322659203,201.777557336254,0.08284629944296952,40.67835555898881,207.04260424521473,0.02575870036967964
0.0265237306023414,201.688207286685,0.08421284466243395,40.660342588995704,207.03773096242622,0.02617807518561287
0.0269586013272484,201.566867877164,0.08559355921401367,40.63588056403626,207.00082870904663,0.026601619839147276
0.0274029605221119,201.416148508828,0.08700439965770528,40.605495539379724,206.93554727493125,0.027034220614050218
0.0278542463091774,201.299941526856,0.08843723203163824,40.582068211814175,206.90699968016804,0.027473373234771427
0.0282992048800616,201.201506767789,0.08984997549419559,40.56222376438626,206.89534942998776,0.0279061800153868
0.0287343523178074,201.047696311817,0.09123156860903849,40.53121557646231,206.8246716503243,0.028329262509801157
0.0291697090465857,200.831940756225,0.09261382622290959,40.48771925645496,206.69015003534523,0.028752369440242214
0.0295987501803646,200.640586957285,0.0939760318226576,40.44914233058866,206.57929756667536,0.029169163410508233
0.0300450560557475,200.497932806191,0.09539305297699831,40.420383253728104,206.52190443641447,0.02960254502825891
0.0304886276781542,200.450128863037,0.09680139287813957,40.41074597878826,206.56157820998018,0.03003308555546331
0.0309371692135685,200.406982575167,0.09822551225307999,40.40204768715367,206.60700730667563,0.030468261580881523
0.0313758669287116,200.340517755414,0.09961837749865933,40.388648379491464,206.62637518093706,0.030893703998275967
0.0318395376964824,200.211433690729,0.10109053218633161,40.362625032050964,206.58607318099175,0.031343168241841766
0.0323069415609755,200.066600614084,0.10257453945609721,40.33342668379934,206.53014058842624,0.0317960468308167
0.0327597552766862,199.848520690912,0.10401222300347869,40.28946177128786,206.39550932115407,0.03223459317284171
0.033205171782764,199.666716845771,0.10542642041027568,40.25281011610743,206.29668447793532,0.03266578782396577
0.0336578836986921,199.469063177635,0.1068637807433474,40.21296313661122,206.1827697075549,0.0331038545086135
0.0341178035435177,199.365927834256,0.10832402625066868,40.19217105138601,206.16785539337627,0.03354869952274883
0.0345947773038518,199.259882875262,0.10983841793972945,40.170792387652824,206.15323414892327,0.03400983054037018
0.0350566161660733,199.14505630851,0.11130475632728272,40.147643351795615,206.12640810888848,0.03445612683098651
0.0355309628892695,199.007542730083,0.11281080717343064,40.11992061438473,206.0784723455103,0.03491430279639123
0.03599640929249,198.834888101955,0.11428859950365573,40.085113441354125,205.9922301156994,0.03536367789739503
0.0364634998137624,198.658848949181,0.11577161190869562,40.04962394815489,205.90264585084168,0.03581443742922353
0.0369363522403533,198.477672551689,0.11727291836312172,40.01309878642051,205.8087137769037,0.03627055054635344
0.0374151939797239,198.325137019496,0.11879324088562337,39.982347623130394,205.74551049213574,0.03673222903932488
0.0378966013257886,198.216012871424,0.12032170920937879,39.96034819487908,205.72772608759973,0.03719616641566377
0.038376508858253,198.093834712255,0.12184541562495327,39.93571707799061,205.69598451485516,0.03765844427174818
0.0388487111574442,197.971330414035,0.12334465792488532,39.911020211469456,205.66226144674482,0.03811309146433472
0.0393383798029806,197.765995838443,0.1248993558744634,39.86962476103011,205.54578969485033,0.03858433744283974
0.0398202528099885,197.553880436568,0.12642930267171348,39.82686229601211,205.42052589914636,0.039047864379243055
0.0403054084669244,197.337367536925,0.12796967188248498,39.78321329544408,205.29113074128833,0.03951433203046678
0.040791105744647,197.185435017025,0.12951176073925422,39.75258369943224,205.2288469481087,0.03998110258457074
0.0412763069304854,197.083236088734,0.13105227450429113,39.731980395488776,205.21810423238588,0.04044717893893634
0.0417621187361163,196.892334890926,0.13259472698716926,39.69349471401068,205.11497595887204,0.040913624308789524
0.0422491858825904,196.685544664143,0.13414116517722452,39.65180580429123,204.99534880107691,0.04138105666317551
0.0427292047067303,196.51235002682,0.13566522494386868,39.61688976540692,204.9091664585166,0.04184151115497024
0.043219744828229,196.304435880067,0.13722268982962707,39.5749742734215,204.78866350745292,0.04231183918543401
0.0437025015238416,196.195314467297,0.13875544233819706,39.552975396607074,204.76954049677465,0.04277448862536165
0.0442003501072462,196.081981359673,0.14033611159050666,39.53012744211008,204.74887358549304,0.0432513772817957
0.0447033969951603,195.949221126475,0.14193328545963393,39.50336297909736,204.70881694938427,0.04373301450259769
0.0452122838411413,195.838898931778,0.1435490011956236,39.481122024646446,204.69322281741813,0.04422000721785862
0.0457213151978631,195.674501706176,0.14516517575321533,39.44797954396508,204.62099727486884,0.044706901079061924
0.0462168957481043,195.470424882751,0.14673864400023115,39.4068376563626,204.50446113139478,0.04518070145893852
0.0467199142747704,195.279839308282,0.148335727822396,39.368415604549654,204.4032966603559,0.04566138346896638
0.0472201257854499,195.092560636696,0.14992389936880343,39.33066022435791,204.3048558897663,0.04613915409336308
0.0477477844947182,194.924729894169,0.15159921577073027,39.29682554666447,204.23195388984695,0.04664289328462904
0.0482747791373086,194.733976706536,0.1532724237609548,39.25836970403766,204.13471642257383,0.04714574536536408
0.0487902799120319,194.560184603503,0.15490913872070128,39.2233332160662,204.05283047004448,0.04763738560597775
0.0493082662788024,194.385787239151,0.15655374543519762,39.18817470741284,203.9706133971537,0.04813115304910861
0.0498349691346171,194.225573048526,0.1582260270024093,39.15587552658284,203.90479848655264,0.048632979563833556
0.0503617309346417,194.042980524942,0.15989849571748738,39.119064873828314,203.81532089989508,0.04913461049302527
0.0508856799343182,193.859674330944,0.16156203379146028,39.08211034511831,203.72435567111958,0.04963331331861858
0.0514089356513125,193.68008937714,0.16322337069291717,39.045906018431424,203.63697662886986,0.0501311081794533
0.0519251429430676,193.489616983347,0.1648623288442396,39.00750678384276,203.5365930032067,0.05062195488552122
0.0524519352444597,193.266301694132,0.16653489440115954,38.962486421537015,203.40349323552883,0.05112261830545334
0.052966947191956,193.066346847689,0.1681700573344603,38.92217552449411,203.2924818457144,0.05161184347775953
0.0534957159538545,192.826906807339,0.16984889815348803,38.873904412359536,203.14232024216477,0.052113887764853664
0.0540134287304607,192.711474204266,0.1714926362192127,38.85063319958003,203.12048168174016,0.05260519076899561
0.0545434737586817,192.602065949602,0.1731755291838144,38.82857649543977,203.107251679592,0.053107946979899685
0.0550859574585744,192.477795224412,0.1748979149309737,38.80352351724146,203.08061886386417,0.05362223987307093
0.0555955155826084,192.290317012621,0.17651576197478164,38.76572790974439,202.98079632848086,0.054105077421456954
0.056149679019317,192.047800533691,0.17827523088633146,38.716836587592105,202.83122289002358,0.05462991673525842
0.0566909345065788,191.817108517684,0.17999371705838768,38.6703290771651,202.69139965390133,0.05514226536736698
0.0572456423796618,191.629570889077,0.18175491455542622,38.632521491237924,202.59952877356116,0.05566707570640943
0.0578065632110226,191.474771712984,0.18353583819499675,38.601313977337576,202.5432702073267,0.056197484216448476
0.0583636718081212,191.319179740298,0.1853046579907848,38.56994663564408,202.48526955725973,0.05672400954106566
0.0589006162079783,191.1106475219,0.18700945646033107,38.527906540415046,202.36718242484568,0.05723121538627575
0.059438482712599,190.894690769727,0.1887171826125018,38.48436965917696,202.24118154697035,0.05773903447572518
0.059980783930607,190.657609485771,0.1904389889796772,38.43657407233143,202.09340236506307,0.05825077959230307
0.0605210054447178,190.460274130686,0.192154192286979,38.3967912647463,201.9871214183517,0.05876030194074432
0.0610952575213655,190.29016287657,0.19397744263033545,38.36249683591652,201.91598938129664,0.059301636489027046
0.0616742010671336,190.094883160943,0.19581558838814916,38.323128445246105,201.81883320684426,0.05984709709736593
0.0622200176506035,189.921356032592,0.1975485560406661,38.28814537617055,201.73826615716644,0.06036107429140463
0.0627236283740459,189.60697313755,0.1991475200875957,38.224765784530085,201.4998104577574,0.06083507343374766
0.0632627290151046,189.319796852746,0.2008591646229571,38.166871045513595,201.29668385823595,0.06134222687877319
0.0638306922036422,189.068072074302,0.20266244774656395,38.116123330179285,201.1364179884128,0.06187625438914935
0.0644017177591627,188.854566440518,0.20447545388534158,38.07308059440843,201.01712492594928,0.06241287394869566
0.0649709936797866,188.77234884017,0.20628290493332246,38.05650552617827,201.03707592358316,0.06294756280906137
0.0655445266772997,188.660045755712,0.2081038722004265,38.03386522435154,201.02567915768782,0.06348596115057743
0.0661127033890131,188.516222354633,0.20990783326011656,38.00487042669401,200.9795394471821,0.06401904566074633
0.0666838613402551,188.330533743889,0.21172125975530992,37.96743560276803,200.88914094220274,0.06455464101413448
0.0672640258294079,188.139689075635,0.21356328200837005,37.92896131764802,200.7947219811553,0.06509838859760206
0.0678243138247028,187.92987257265,0.21534219639343138,37.88666231064624,200.6760872270538,0.06562322684223112
0.0684088743536645,187.709818248459,0.21719817607288475,37.842299358889335,200.550835619967,0.06617050842814318
0.0689822814922667,187.48392191406,0.21901874373794677,37.7967586578745,200.41699059080983,0.0667070570620142
0.0695570940075123,187.263050996159,0.22084377347385153,37.75223108082565,200.2885246384324,0.06724463194669832
0.070133887645258,187.030380780103,0.22267509327369417,37.70532476526876,200.14754849198457,0.06778376928630747
0.0707017625089068,186.771911509292,0.2244780959657791,37.653217360273274,199.97701484015653,0.06831428630841228
0.071280071569637,186.494522420058,0.22631422723359748,37.59729571988369,199.787865325505,0.06885426201276341
0.0718518826955016,186.230159137929,0.2281297275582176,37.54400008220649,199.6111466866721,0.06938788397504651
0.0724383982200438,186.03535434653,0.22999191434863905,37.50472743626045,199.5114574276909,0.06993493261336665
0.0730193030124974,185.823283712415,0.23183628706467924,37.46197399642286,199.3919703725891,0.07047645324676392
0.0735918499429752,185.649702789812,0.23365412356894624,37.426980082426105,199.31200785947783,0.07100989587168141
0.0741634346231588,185.402746613498,0.23546890492852918,37.3771937172812,199.15285109092224,0.07154215827399998
0.0747367298090699,185.129709509664,0.2372891171437969,37.32214943714826,198.96569858891937,0.07207572908292027
0.0753058380567689,184.841762447441,0.23909603583024122,37.26409930940411,198.7614262764357,0.0726051216349525
0.0758609198949808,184.485604486096,0.24085842066656402,37.192297864396956,198.48085214979287,0.07312119678206042
0.0764469843212582,184.282564903992,0.24271917521999475,37.15136508464479,198.37041125388876,0.07366578841749875
0.0770263251596233,184.074126871124,0.24455858238180395,37.1093439772186,198.25268042097295,0.0742038409206721
0.0776193582658636,183.93319512385,0.2464414624941169,37.08093213696816,198.20997169315308,0.07475431019344121
0.0782036333238857,183.717027814287,0.2482965358033371,37.037352807360264,198.08436689282965,0.07529635383487855
0.0787918470232356,183.466588049843,0.25016411429877305,36.986864150848355,197.92225938934124,0.07584175480515419
0.0793903110257739,183.169921790311,0.2520642375068321,36.927056232926695,197.71183885181048,0.07639635490287622
0.079973366043748,182.901679486711,0.25391543718889986,36.872978584520936,197.52894245031803,0.07693637976143547
0.0805591067125902,182.615051812104,0.2557751638124739,36.815194445320174,197.32635725836047,0.07747859858071156
0.0811262619055437,182.331461704411,0.25757588155010125,36.75802267960926,197.12333162026366,0.07800333285906753
0.0817071269959983,182.075055336801,0.2594201282122946,36.706331155899086,196.95188500600844,0.0785404663316696
0.0823026486257499,181.786869087705,0.26131090938675594,36.64823280808133,196.7484098990056,0.07909085353554779
0.0829207480868621,181.514342467012,0.26327337517578714,36.59329144134962,196.5656475328715,0.07966178721272918
0.083508589729876,181.240638724745,0.2651397723923563,36.5381127669086,196.3757888663904,0.08020446972462046
0.0841151393073919,180.928820128766,0.26706556730096925,36.47525013795923,196.14767303861922,0.08076411445006042
0.0846967186997251,180.575046848389,0.2689120818716272,36.403929444635224,195.8691607954967,0.08130042598314798
0.0852800310685129,180.142501094421,0.27076409864252843,36.31672822063528,195.50505918451285,0.08183804684281838
0.0858349202463457,179.668975319769,0.2725258717821476,36.221265424465436,195.09084748708403,0.08234920281784275
0.0864039988133792,179.261644724978,0.2743326962324789,36.139147576555565,194.75056766307938,0.08287315860839527
0.0869777026647225,178.93623479842,0.27615420596049395,36.073544935361475,194.49969742466195,0.08340109520073732
0.0875319215102613,178.657990684497,0.27791385079507963,36.017450921994595,194.29626790227337,0.08391083666279181
0.0880953646340543,178.417046942836,0.2797027827131224,35.96887666367574,194.13476175019633,0.08442879591066318
0.0886442442024739,178.054588656412,0.2814454753428546,35.895805073132664,193.83810309464204,0.08493310940578644
0.0892273833475269,177.761452196399,0.2832969421283979,35.83670876279404,193.62264143594018,0.08546862229057921
0.0898039705878858,177.400591371325,0.2851276066165374,35.76395922045912,193.33186886110903,0.085997836569919
0.0903910664025615,177.053796649097,0.28699163582813275,35.69404540445796,193.05787813883114,0.08653640841225943
0.0909673384179177,176.710854887001,0.28882129947688867,35.6249083452194,192.78577102562636,0.08706476911400282
0.0915477066236139,176.278739563032,0.2906639685299741,35.53779389590725,192.41665389652889,0.08759660344952723
0.0921201178460229,175.86207302135,0.2924813741611227,35.453793921104165,192.06250791272265,0.08812086930086739
0.0927056946451414,175.430129079182,0.29434058049832396,35.36671402236309,191.69350105715438,0.08865690911675772
0.0932740445944229,174.993112095889,0.2961450915872927,35.27861139853122,191.3154274372378,0.08917690475247736
0.0938546631436021,174.514392698926,0.2979885554809366,35.182101568103484,190.89338223939401,0.0897078461285058
0.0944324874967011,173.997406061596,0.299823147802026,35.077877062017755,190.42841393396608,0.09023595265818067
0.0950166601296776,173.537177238354,0.3016778959117264,34.98509493125216,190.02610022787428,0.09076957788302047
0.0955992971199657,173.044880688788,0.30352776835589107,34.88584794685966,189.58784965284445,0.09130151685853875
0.0961755337140735,172.595486559817,0.30535731954218337,34.795250090459106,189.1949495963476,0.09182733420006299
0.0967544908570978,172.01621982448,0.30719550847128546,34.67846991661517,188.65956159276018,0.09235535575112822
0.0973342305310139,171.332232471699,0.3090361819359691,34.54057806629452,188.0087234844926,0.09288381176273472
0.0978984365520976,170.712904047387,0.31082753605290986,34.415721455953225,187.42543045289446,0.09339784022264878
0.0984554576388736,170.078674554415,0.31259607800342365,34.287860790170065,186.82384829228297,0.09390506367164904
0.0990106218987412,169.473502193958,0.3143587245285033,34.165858042301934,186.25317904153948,0.09441034043277723
0.0995673019222126,168.881123246398,0.31612618360302497,34.04643444647384,185.6961610336345,0.09491674052834459
0.100130837462721,168.213801428948,0.31791540894413917,33.911902368075914,185.05719023881642,0.0954291158790777
0.100713347580054,167.613295750268,0.3197648785666714,33.79084042325403,184.49419186420312,0.09595846742053979
0.101298128802112,166.908448977151,0.3216215589467056,33.648743313793645,183.8159625397992,0.09648960110633349
0.101876672524642,166.146791051577,0.3234584352657383,33.495193075997925,183.07327327455863,0.09701479205848107
0.1024376105394,165.361048314753,0.32523941346259494,33.336787340254205,182.30023898040656,0.09752373765773235
0.102981970084092,164.589360238099,0.3269677550169921,33.18121502400076,181.53909681029876,0.09801739388580745
0.103544889788257,163.794890326005,0.328755025077716,33.02104988972261,180.75501419269082,0.09852762535102508
0.10408494973312,162.978798832354,0.330469715402656,32.856525844602565,179.94243891638382,0.09901689211664691
0.10465077057334,162.137617836213,0.3322661965703545,32.68694375578054,179.10544448169838,0.09952924028704623
0.105213099990714,161.26074508311,0.3340515924705169,32.510166208754974,178.22748798011628,0.10003816704674541
0.105768495009229,160.392347538471,0.335814971654302,32.335097263755756,177.3568047486123,0.10054056383869793
0.106324904771438,159.42421000993,0.3375815726493156,32.13992073800189,176.37497395749753,0.10104362557560154
0.106872889704125,158.429274327564,0.33932142481059685,31.939341704436902,175.3610686886783,0.1015388230181914
0.107430773197126,157.311944670783,0.34109270490087507,31.71408804562985,174.21208851990872,0.10204271371227472
0.107992513186662,156.218962642087,0.34287622936765183,31.49374286864474,173.08944102521923,0.10254983125051392
0.108555624778505,155.051929086908,0.34466410867175334,31.258468903920654,171.88368812204973,0.103057929039425
0.109112599882215,153.943895107311,0.3464325046260326,31.035089253633895,170.74111373846472,0.10356023602044909
0.1096543242993,152.762295223524,0.34815247965027746,30.79687871706244,169.51334148466972,0.10404854727292474
0.110187574382418,151.550816629185,0.3498455486641771,30.552644632443695,168.2498335092295,0.10452898697783501
0.110715345368914,150.279760900467,0.35152122154630194,30.29639979753415,166.91803653052003,0.10500426303941988
0.111237102429422,148.741266651532,0.3531778002134148,29.98623935694885,165.28681416553044,0.10547390141589814
0.111773941223388,147.17782325144,0.3548822633842569,29.671049167490306,163.62846861693265,0.10595688489538609
0.112307401267423,145.435902071393,0.356575999024068,29.31987785759283,161.76943028401456,0.10643659761458701
0.112838517900626,143.589064335176,0.35826229433448753,28.947555369971482,159.7914415414949,0.10691397452610911
0.113237108894634,142.142207860489,0.3595278207404629,28.655869104674586,158.2379805305109,0.10727208544873003
0.113479760021737,141.170321234739,0.36029823806901495,28.459936760923384,157.1902954106487,0.10749003064998192