File: example/data/02 processed data/test_ID_100.csv
Strain,Stress_MPa,Displacement(mm),Force(kN),True Stress (MPa),True Strain
0.00038637783004529956,-0.168061371096594,-0.0003100301990263,-0.0338811724130733,-0.1680449603563326,-9.76520745886078e-05
0.0003606210267369996,0.110917017976476,-0.0003918080495303,0.0223608708240575,0.1109033303605789,-0.0001234117250019
0.0003501640623074996,0.494669820881306,-0.000425008911594,0.0997254358896713,0.4946036038475513,-0.0001338700347111
0.00033768325663739956,0.952535782355566,-0.0004646354695965,0.1920312137228821,0.95239638647823,-0.0001463525892056
0.00030554819411189956,1.70300629292273,-0.000566664293115,0.3433260686532224,1.7027023455661474,-0.0001784928716183
0.0002732539578669996,2.80350792700641,-0.0006691984931926,0.5651871980844922,2.802917028335416,-0.0002107933943248
0.00025135504514609957,4.30245130598119,-0.0007387275410814,0.8673741832858081,4.301450254241383,-0.0002326971635642
0.0002451429837590996,5.79873069571229,-0.0007584508359851,1.1690241082555977,5.797345482438647,-0.0002389106899524
0.0002481533262080996,7.44268741800733,-0.0007488929987096,1.500445783470278,7.440931897850187,-0.0002358996327478
0.00024194155872319956,9.17995854242529,-0.0007686153604741,1.8506796421529383,9.177736225214511,-0.0002421128850613
0.00024827335773949956,11.03906419636,-0.0007485118985974,2.225475341986176,11.036461717336266,-0.0002357795729047
0.00026928579652429956,13.0435931132256,-0.0006817974054556,2.6295883716262813,13.040792140645312,-0.0002147624000944
0.00029801052687689956,15.0626846913234,-0.0005905963865861,3.0366372337707976,15.059882811905767,-0.0001860319128116
0.0003403680840285996,16.9921437694086,-0.0004561111426295,3.4256161839127737,16.989702728113986,-0.0001436673724594
0.0003743953136832996,19.2707097390644,-0.0003480746884758,3.8849750833953833,19.268597094563887,-0.0001096358329302
0.0004177914970405996,21.5700206257467,-0.0002102918063163,4.348516158150535,21.568591964770427,-6.623583332901852e-05
0.00046788415691869956,24.0370144435026,-5.12476112034569e-05,4.845862111810124,24.03662646253545,-1.6141110173671574e-05
0.0005146453606633995,26.5310022407595,9.721921068602369e-05,5.348650051737114,26.53181462598676,3.0619755048556074e-05
0.0005720131846962996,29.0540014655843,0.0002793620519904,5.857286695461795,29.0565578704561,8.79841771497895e-05
0.0006243167253295995,31.5708515319033,0.0004454257935011,6.364683668831706,31.575280656815146,0.0001402817485596
0.0006768033748312996,34.140235564627,0.000612070905669,6.882671489828803,34.146817059084256,0.0001927596586692
0.0007301684362062996,36.6773464618707,0.0007815049755346,7.394153046713133,36.68637434494136,0.0002461130110891
0.0007671523023491996,39.2644503544229,0.0008989287505383,7.915713191451656,39.2755671869576,0.0002830870925916
0.0008171668093960995,41.7919465840672,0.0010577248104122,8.425256431347947,41.8058692230522,0.000333086193205
0.0008746853533368996,44.3466367031673,0.0012403461874243,8.940281959358527,44.36396116986332,0.0003905839286769
0.0009165384436854995,46.9102167452331,0.0013732297492811,9.457099695838991,46.93050603820311,0.0004324197999408
0.0009712033953581995,49.4513949072047,0.0015467909708419,9.96940121329247,49.47548655165762,0.0004870596257338
0.0010172537283611996,52.0164152132701,0.0016930007781264,10.486509306995252,52.044151853091016,0.0005330864756883
0.0010618396294209997,54.5604461545673,0.0018345610139913,10.999385944760768,54.591971971077896,0.0005776476220787
0.0011156199103761995,57.119953729029,0.0020053134060241,11.515382671772247,57.15603039326973,0.0006313954015157
0.0011658673437521996,59.6631006185761,0.0021648490069929,12.028081084704944,59.703781438773966,0.00068160985814
0.0012139291773999995,62.2436131664347,0.0023174453288246,12.548312414353235,62.28904503118484,0.0007296377901706
0.0012786143044467996,64.7606687682274,0.0025228206071982,13.055750823674646,64.81212689411856,0.0007942736487763
0.0013262249353995996,67.3008651605625,0.0026739843604734,13.567854416369398,67.3575459356446,0.0008418453473225
0.0013773176447299995,69.7661339406426,0.0028362037125974,14.06485260243355,69.82845550539724,0.0008928937596005
0.0014319757402754996,72.2008799231795,0.0030097431659543,14.555697392512986,72.26932279087231,0.0009475015820212
0.0014926353125238995,74.6103781980389,0.003202337307843,15.041452244724642,74.68563098470216,0.0010081018702146
0.0015530087243222997,77.0380723157495,0.0033940228903029,15.530875378855102,77.12042475066745,0.0010684126314008
0.0016057712670068996,79.3309596905763,0.0035615439633265,15.993121473620182,79.41994888761279,0.0011211174430988
0.0016437455004404996,81.6516544133212,0.0036821121544782,16.460973529725553,81.7463474996672,0.0011590484074248
0.0016886891579816995,83.9119221877445,0.0038248082671715,16.91664351304929,84.01300786135015,0.0012039389956708
0.0017360869239454995,86.1388229110207,0.0039752961741066,17.365586698861772,86.2466740395751,0.0012512786114154
0.0017874350922845996,88.2680648596325,0.0041383266085832,17.794841875701913,88.38311433411967,0.0013025612540936
0.0018365134616400995,90.357178276892,0.0042941504312869,18.21600714062143,90.47938530557472,0.0013515745363131
0.0018791889531161996,92.3734809675677,0.0044296451167236,18.622493763061648,92.50235710579848,0.0013941914795279
0.0019245267150261995,94.3946778888214,0.0045735925107878,19.0299670623864,94.530653571294,0.0014394650510956
0.0019762716191457997,96.3454281422203,0.0047378825813675,19.42323831347161,96.4891992684532,0.001491134188945
0.0020296884563958993,98.3135045128474,0.0049074810396366,19.82000250979004,98.46546409059134,0.0015444700114985
0.0020830853308483996,100.255711614256,0.0050770161160233,20.21155146143401,100.4160265319218,0.0015977830585673
0.0021314944225742996,102.241939595999,0.005230714982253,20.6119750225534,102.41038005119884,0.0016461136968818
0.0021795183187656997,104.222568699915,0.0053831908526607,21.011269849902867,104.39927735455002,0.0016940574559886
0.0022299818581902994,106.158746032068,0.0055434125903338,21.401603200064912,106.34409460823436,0.0017444343107129
0.0022791544223373997,108.117290398161,0.0056995354815009,21.79644574426926,108.31137491242497,0.0017935199666053
0.0023198097255480994,110.050112501794,0.0058286160691948,22.186102680361675,110.252140802312,0.0018341015956218
0.0023627222266743996,111.977763150444,0.0059648632602708,22.57471705112951,112.18813544820254,0.0018769345456504
0.0024096296374730994,113.899489107536,0.0061137942895567,22.96213700407926,114.11881447638297,0.0019237529008861
0.0024534927169613994,115.82670669325,0.0062530595669321,23.3506640693592,116.05482363699628,0.001967530721498
0.0024944593863571994,117.68161917868,0.0063831287422637,23.724614426421887,117.9182103364172,0.0020084160311403
0.0025406292099669995,119.538013842598,0.0065297179322248,24.09886359066776,119.78385620876196,0.0020544921580713
0.0025922505231263998,121.377668390554,0.0066936156015059,24.469737947535688,121.63355987238502,0.0021060061976473
0.0026474231313497994,123.261719227501,0.0068687886326152,24.849562596264207,123.52838338367944,0.002161061218727
0.0026990952885594995,125.057868927176,0.007032847731756,25.21166637571868,125.33488087987608,0.0022126205006114
0.0027425990123525995,126.928235645713,0.0071709720547991,25.588732306175743,127.21491244280917,0.0022560271315037
0.0027942762621176996,128.726630889299,0.0073350473228033,25.95128878728268,129.0240217331661,0.0023075865981901
0.0028505858286182995,130.508825600372,0.0075138301964427,26.310579241035,130.81768265696994,0.0023637647972729
0.0028996482498280995,132.286956384137,0.0076696033837838,26.66905040704202,132.6065118135273,0.0024127101855708
0.0029437316306101997,134.065183719878,0.007809568117767,27.02754103792741,134.39494472286424,0.0024566863671699
0.0029861464697698995,135.804511175483,0.0079442352320991,27.378189452977374,136.14431054000528,0.0024989962391858
0.0030298993704645995,137.595103911819,0.0080831506918047,27.73917294862271,137.945403741543,0.002542638985692
0.0030819647800483995,139.290912921709,0.0082484583672333,28.081048045016537,139.65278230632907,0.0025945708314133
0.0031265375851636996,141.070425994567,0.0083899770234744,28.439797880504702,141.44320635135003,0.0026390271509296
0.0031774629248816997,142.867436762978,0.008551664977079,28.802075251416365,143.25224131583815,0.0026898169846458
0.0032264806102405997,144.639194314784,0.0087072961280935,29.15926157386045,145.03586086490293,0.0027387018036853
0.0032755880723339998,146.385713121851,0.0088632123202401,29.511359765365164,146.79435805288998,0.0027876737599348
0.0033212626629735994,148.142852063287,0.0090082291455208,29.86559897595866,148.56316852239158,0.0028332201647701
0.0033697909525671997,149.881029508349,0.0091623064649805,30.21601554888316,150.31355105973242,0.0028816099868166
0.0034155074138044997,151.624174738376,0.0093074562294089,30.567433627256605,152.06865831938316,0.0029271938617071
0.0034649843490188997,153.307048829467,0.0094645454987146,30.906701044020547,153.76405088896942,0.0029765249633057
0.0035108475081397994,154.959105380802,0.0096101610289235,31.23975564476968,155.4281390676075,0.0030222507671136
0.0035559899357324996,156.62391269535,0.0097534882365303,31.57538079938256,157.10505584181723,0.0030672559561791
0.0036018764543519995,158.261271427261,0.0098991779331472,31.90547231973581,158.75470654089395,0.0031130008984162
0.0036547433244187998,159.886666167039,0.0100670302456093,32.233151899275065,160.39362172740854,0.0031657020610331
0.0037105499983371994,161.517439194349,0.0102442164353002,32.56191574158076,162.03857922747733,0.0032213307996852
0.0037705635614547995,163.109013416606,0.0104347594981986,32.88277710478777,163.64507745660308,0.003281149561131
0.0038212693867452994,164.684241848458,0.010595750493496,33.200343156649126,165.2338333876192,0.003331688008586
0.0038701467506701997,166.331583559142,0.0107509361239575,33.532447245523024,166.89480252929664,0.0033804016128287
0.0039185978040044995,167.900394687613,0.0109047682182939,33.84871956902278,168.47706079401567,0.0034286879928543
0.003975475195189499,169.409458651966,0.0110853539353063,34.15294686423635,170.00094331626386,0.0034853690967478
0.0040341912642249,170.97843831282,0.0112717774544937,34.469253163864515,171.58544017303385,0.0035438791630848
0.0040855461734481,172.492076042635,0.0114348292912773,34.77440253019522,173.11330988315328,0.0035950510895144
0.0041311604305299,173.998745751173,0.0115796545575121,35.078147143436475,174.63334271786243,0.0036405006225814
0.004185808996710099,175.489993318296,0.0117531637551342,35.378782652968475,176.13961934313295,0.0036949491199723
0.004240599583256099,176.956329236912,0.0119271238674177,35.67439597416146,177.6210788614576,0.0037495361417483
0.004299875592628899,178.458319242432,0.0121153251971764,35.97719715927429,179.13928950125518,0.0038085885661141
0.0043571332537869,179.97678614501,0.012297118271353,36.28332008683402,180.6738556962929,0.0038656269444236
0.0044074745666631,181.43160269152,0.012456951939735,36.57661110261044,182.14344040965457,0.0039157727748837
0.004474132866547499,182.863649046761,0.0126685920418679,36.86531164782701,183.5932947063077,0.0039821683621552
0.004548147847127199,184.289616489613,0.0129035896052085,37.15278668430598,185.03859210526127,0.0040558864714486
0.0046224688428278,185.670546436339,0.0131395587665579,37.43118216156594,186.4389335406285,0.0041299039007433
0.0047029221978064,187.001609451845,0.0133949981686149,37.69952446549196,187.79054999236013,0.0042100224666862
0.004789598815865699,188.295218637047,0.0136701964309532,37.96031607722868,189.10593757429984,0.0042963312165928
0.004882641633753999,189.54508259234,0.0139656073777486,38.21228865061575,190.3788187195424,0.0043889708580191
0.004983021494824999,190.667238655774,0.014284313436649,38.43851531300404,191.52504986807625,0.0044889061265089
0.0050784256681545,191.773613958251,0.0145872216869702,38.6615605739834,192.6546987521157,0.0045838784892163
0.0051799397588278995,192.802750478366,0.0149095289248582,38.86903449643859,193.7081357334997,0.0046849232113197
0.0052977745809983,193.761311993011,0.0152836544852492,39.062280497791015,194.6940304009196,0.0048022004002901
0.0054217987933807,194.628657919589,0.0156774313595633,39.23713743658914,195.58969017947507,0.004925622834471
0.005546828927953799,195.373111660805,0.0160744020368329,39.38721931081829,196.36224739120587,0.0050500308929931
0.0056776260959078995,196.030951313515,0.0164896830450872,39.519839784804624,197.0490578502668,0.0051801607289976
0.0058144636024025,196.606812946533,0.0169241421282076,39.63593349002106,197.65481346485777,0.0053162819630866
0.0059598402829428,197.071149425494,0.017385713088923,39.72954372417959,198.1502746103809,0.0054608773765257
0.0061118521019828,197.457838499557,0.017868350614375,39.807500241510695,198.5690970475465,0.0056120499129844
0.0062657510079398,197.775583618855,0.0183569796407885,39.87155765756117,198.9190678273389,0.0057650758405389
0.0064164997196653,197.984867553562,0.018835606800517,39.9137492987981,199.15940774811045,0.0059149467436459
0.006577610734971099,198.194634714512,0.0193471342741129,39.956038358445625,199.4023506862381,0.0060750947843087
0.0067438586687356,198.344146636631,0.0198749714638152,39.986179961944806,199.58574797660512,0.0062403221569584
0.0069130691614169,198.497913578814,0.0204122147780783,40.01717937748891,199.77406540400176,0.0064084658725288
0.0070850414364227,198.612853510277,0.0209582267512217,40.040351267671845,199.92390019360784,0.0065793249956125
0.007253032161634799,198.712337182865,0.0214915973037701,40.06040717606559,200.05742238917213,0.0067462001588024
0.0074274777650932995,198.810134278254,0.0220454620947509,40.08012307049601,200.19056302763465,0.0069194578680237
0.007611270986024999,198.882508327578,0.022629005571209,40.094713678839724,200.29999285953417,0.0071019670734661
0.007785460360933699,198.891614935038,0.0231820568365441,40.09654957090366,200.3438091781045,0.0072749087883844
0.0079597525317821,198.939134144851,0.0237354344789878,40.106129443601965,200.42634887990667,0.0074479226328105
0.0081362892681405,198.973425005302,0.0242959386169257,40.11304248106888,200.49602220855505,0.0076231340710441
0.0083165925075407,199.010714631665,0.0248684014020213,40.12056006974367,200.5694794615117,0.0078020520535195
0.0084948425800372,198.992083831272,0.0254343453821977,40.11680410038444,200.58617308748865,0.0079789011820817
0.0086660532972882,198.993931143827,0.0259779394094697,40.11717651859553,200.62210509220705,0.0081487368384634
0.008834370078345,199.033854125132,0.026512345189325,40.12522499162661,200.69585546211687,0.0083156736887642
0.0090136420142599,199.100845529333,0.0270815335858548,40.13873045871353,200.79909946167152,0.0084934452366807
0.0091898274764582,199.164289475495,0.0276409224283344,40.15152075825979,200.89817441278208,0.0086681253567775
0.0093686400378065,199.216434771011,0.0282086523106153,40.162033249835815,200.98639607589783,0.0088453789363826
0.0095425840059823,199.250397646221,0.0287609244095734,40.16888016547816,201.0553191030022,0.0090177762277113
0.0097165257852986,199.323283544894,0.0293131895589027,40.18357396265064,201.16353588947808,0.0091901416345011
0.0098970774097398,199.36393013407,0.0298864409665035,40.19176831502851,201.24055322975568,0.0093690255645318