File: example/data/02 processed data/test_ID_086.csv
Strain,Stress_MPa,Displacement(mm),Force(kN),True Stress (MPa),True Strain
-7.2150064906212e-06,-0.725571269952307,-2.290764560772231e-05,-0.1462751680223851,-0.7255660349508849,-7.215032518875229e-06
-5.85838037503157e-06,-0.833304605418451,-1.8600357690725232e-05,-0.1679942084523597,-0.8332997236031041,-5.8583975354118305e-06
-2.043930402471e-06,-1.04736021579366,-6.489479027845424e-06,-0.21114781950400183,-1.0473580750622724,-2.0439324913129976e-06
5.19975053228411e-06,-1.25461631591996,1.650920794000205e-05,-0.25293064928946396,-1.2546228396118166,5.199737013713825e-06
1.31490214941929e-05,-0.551045976217399,4.174814324406246e-05,-0.11109086880542765,-0.5510532219327846,1.3148935046671091e-05
2.72709522975424e-05,0.362094411483457,8.65852735446971e-05,0.07299823335506493,0.36210428614287976,2.727058045182754e-05
3.47669902009558e-05,0.802415958620929,0.00011038519388803466,0.16176705725797927,0.8024438562086994,3.47663858432001e-05
3.39261452839295e-05,0.8049962030455,0.00010771551127647616,0.16228723453397279,0.8050235134636375,3.392556980531788e-05
2.76083990704666e-05,0.811681022074982,8.765666704873145e-05,0.1636348940503164,0.8117034312885574,2.7608017965620478e-05
1.37297233571057e-05,0.82043661705481,4.35918716588106e-05,0.16540002199824969,0.8204478814225942,1.3729629105325278e-05
-3.8306959506663e-06,0.828715171748469,-1.2162459643365502e-05,0.16706897862449135,0.8287119971926163,-3.8307032878028985e-06
-7.22002837505802e-06,0.84889357622692,-2.292359009080921e-05,0.17113694496734705,0.8488874471912122,-7.220054439584859e-06
1.73803856240604e-05,1.74936161878735,5.518272435639177e-05,0.35267130234752975,1.7493920233668805,1.7380234586891816e-05
7.86182267700782e-05,5.48696041428288,0.00024961286999499827,1.1061712195194287,5.487391789381008,7.861513651919735e-05
0.0001102407920891,12.0464040288207,0.0003500145148828925,2.4285550522102533,12.04773203394266,0.00011023471601941868
0.0001391659412728,19.4044634227043,0.00044185186354114,3.911939826017187,19.407163863121415,0.00013915625859155147
0.0001947096060829,27.0486839326014,0.0006182029993132075,5.4530146808124424,27.053950571194974,0.00019469065262769965
0.0002737165875937,35.4655727116078,0.0008690501656099975,7.149859458660132,35.47528022714747,0.00027367913404279626
0.0003708066158526,44.2105251644804,0.001177311005332005,8.91284187315925,44.22691871970171,0.0003707378840696319
0.0004665966211029,53.0609821980462,0.0014814442720017076,10.697094011126115,53.0857402730522,0.0004664877987488552
0.0006039534069219,62.0838279058008,0.0019175520669770323,12.516099705809443,62.12132364517927,0.0006037711004624986
0.0007352925598699,71.3224744385639,0.0023345538775869324,14.378610846814484,71.37491732337008,0.0007350223647357178
0.0008801610266358,80.5711583721816,0.0027945112595686647,16.24314552783181,80.64207396565169,0.0008797739120515179
0.0010213529754518,89.5130937447044,0.0032427956970594645,18.045839698932408,89.60451820934244,0.0010208317493751418
0.0011676834962809,98.3115814872953,0.0037073951006918572,19.81961482783873,98.42637829849129,0.001167002284148955
0.0013158914478247,107.270894419738,0.004177955346843423,21.62581231501918,107.41205127230543,0.001315026421444117
0.0014738846249627,116.131397636464,0.004679583684256573,23.412089763511144,116.30256191791581,0.0014727995230979399
0.0016313299318213,124.683406287686,0.005179472533532627,25.136174707597498,124.88680606036455,0.0016300007584986033
0.0017852107884757,132.98984603238,0.005668044253410347,26.810752960127807,133.22726094027473,0.001783619193636054
0.001912846149524,141.082402037676,0.006073286524738699,28.442212250795478,141.35227096717935,0.0019110189890083065
0.002057590279588,149.032111100601,0.0065328491376919,30.044873597881164,149.3387581237481,0.0020554763399598364
0.0022094111623396,156.798991918927,0.007014880440428231,31.61067677085568,157.14542536191627,0.002206974002629247
0.0023481351014037,164.425426286371,0.007455328946956747,33.148165939332394,164.81151940139728,0.002345382540257938
0.0024927158642273,171.880921454871,0.007914372868921677,34.65119376530199,172.30937175453957,0.0024896142013444093
0.0026286523068989,179.274482938401,0.008345971074404006,36.14173576038164,179.74573322154512,0.002625203443010763
0.0027817025133387,186.360210330006,0.008831905479850372,37.57021840252921,186.87860899546732,0.00277784073878341
0.0029281608179439,193.34158337017,0.009296910596971882,38.977663207426275,193.9077186190738,0.002923882105526443
0.0030803641802492,200.14201552419,0.00978015627229121,40.3486303296767,200.75852581977358,0.0030756295788803524
0.0032391226863551,206.709010483801,0.010284214529177441,41.672536513534276,207.3785663291331,0.0032338880292182895
0.0033908954837913,213.047973742055,0.010766093161037377,42.95047150639829,213.77039715404783,0.003385159361104472
0.0035622089362687,218.873725337018,0.011310013372653123,44.12494302794283,219.65339927732796,0.0035558792972267823
0.0037205359064273,223.806718331784,0.011812701502906676,45.11943441568766,224.63939926343707,0.003713631831984267
0.0039148756490435,228.008026000531,0.012429730185713113,45.96641804170705,228.90064906930695,0.003907232464952287
0.0041679749483611,231.696809458301,0.013233320461046492,46.71007678679348,232.66251595573843,0.00415931300095475
0.0045043200429001,234.541813626819,0.014301216136207818,47.28362962716671,235.5982650188364,0.004494205953400054
0.0049028949273141,236.361671014726,0.015566691394222266,47.65051287656876,237.52052745255557,0.004890914879964869
0.0053652972747632,237.326792113557,0.017034818847373158,47.8450812900931,238.60012090451212,0.005350955343618333
0.0058711959717786,237.862614800886,0.018641047210397055,47.95310314385862,239.25915282674168,0.005854027666921601
0.0064050270593754,238.312434079383,0.020335960913516894,48.04378671040361,239.83883166824705,0.006384602042357919
0.0069474199436249,238.730318637443,0.022058058321009058,48.12803223730851,240.38887841429266,0.006923397818704193
0.0074974247143694,239.044389003218,0.023804323468122845,48.19134882304875,240.83660631316204,0.007469458720664218
0.0080535228087388,239.226502848357,0.02556993491774569,48.22806297422877,241.15311894550106,0.008021266264069161
0.0086128415164778,239.434324522619,0.02734577181481701,48.26995982375999,241.49653441333726,0.008575962600532849
0.0091654838815058,239.593175573469,0.02910041132378091,48.30198419561135,241.78916296230645,0.009123735734866177
0.0097114542622428,239.852706449791,0.03083386728262089,48.35430562027786,242.18202503815326,0.00966460118707004
0.0102655019200688,240.134524557931,0.03259296859621844,48.41112015087889,242.59962598085525,0.010213169496252344
0.0108165954087622,240.479915862101,0.03434269042281998,48.480751037799564,243.08108981591454,0.010758514490480696
0.011371775432004,240.757908423373,0.0361053869966127,48.536794338152006,243.49575329144258,0.011307602839712681
0.0119220797194496,240.971864379857,0.037852603109252474,48.579927858979175,243.8447501571381,0.011851571576250181
0.012465043075242,241.09560813411,0.039576511763893346,48.60487459983658,244.10087527475335,0.012387994044757579
0.0130126039695188,241.302452508396,0.04131501760322219,48.646574425692634,244.4424257597614,0.012928667409792953
0.0135804275005285,241.528913030083,0.043117857314177985,48.69222886686474,244.80897892276948,0.01348903995331895
0.0141320785503938,241.837894223749,0.04486934939750031,48.7545194755078,245.25556634138084,0.014033151667212482
0.0146877625650226,242.06210600144,0.04663364614394675,48.799720569890304,245.61745674037846,0.014580942079414716
0.0152355225364017,242.276448426739,0.04837278405307539,48.84293200283059,245.96765671678392,0.01512062748397591
0.0157721370582116,242.566288317716,0.05007653515982183,48.90136372485154,246.39207706276466,0.01564904945398822
0.0163166426987352,242.869400435823,0.05180534056848426,48.96247112786192,246.83221366519035,0.01618495680112722
0.0168492000371875,243.051635543115,0.05349621011807031,48.99920972549199,247.14686116974656,0.016708826855835027
0.0173805191606655,243.173543369104,0.05518314833511295,49.02378634321137,247.40002579899766,0.017231205553330027
0.0179149577276021,243.405888161633,0.05687999078513666,49.070627053385216,247.76649435869808,0.017756376060795644
0.0184509967847362,243.694260902185,0.05858191479153743,49.12876299788049,248.19066292654986,0.01828284240475242
0.0189839807547627,243.882117869464,0.06027413889637157,49.16663496248394,248.51197130152866,0.018806033562320516
0.0195220757570865,244.107000466794,0.06198259052874964,49.21197129410567,248.87247582274188,0.019333964311510646
0.0200628222047281,244.387582670821,0.06369946050001171,49.26853666643751,249.29068729098896,0.019864215796361356
0.0206036274889353,244.54910343188,0.06541651727736958,49.30109925186701,249.5877020617436,0.02039424391237138
0.0211231359060572,244.743103637436,0.06706595650173161,49.340209693307095,249.91284547763985,0.020903135148600746
0.0216558553534196,244.97148765771,0.06875734074710722,49.38625191179433,250.27655476013737,0.02142469862827029
0.0221732065790882,245.162819716812,0.07039993088860502,49.424824454909306,250.59886556390467,0.021930955483458622
0.0226922504580462,245.377484591712,0.07204789520429668,49.46810089368915,250.94565192883252,0.022438611269142546
0.0232217698565028,245.659112979947,0.07372911929439638,49.52487717675732,251.36375236471991,0.022956247303719066
0.0237394370466377,245.890705795492,0.0753727126230747,49.57156628837119,251.72801272607742,0.023462038228750023
0.0242666440961491,246.052387291691,0.07704659500527339,49.6041612780049,252.02325300310633,0.023976887345665582
0.0247951797980621,246.251211920763,0.07872469585884716,49.64424432322582,252.35705499582903,0.02449276803552214
0.0253076561144836,246.410286414939,0.08035180816348543,49.676313741251704,252.64635320659968,0.024992719860492812
0.0258192641033712,246.666746690932,0.08197616352820356,49.72801613289189,253.03550056926454,0.025491575386647217
0.0263407652333097,246.879896934097,0.0836319296157583,49.770987221913956,253.38290234006172,0.025999821462693164
0.026870749263111,247.043773453751,0.08531462891037743,49.804024728276204,253.68202474723955,0.026516070312682726
0.0273893340525937,247.231341220984,0.086961135616985,49.84183839015038,254.00284301395632,0.02702095750268419
0.0279120932577226,247.433596635465,0.08862089609326924,49.88261308170974,254.33998625984782,0.027529650981368566
0.0284389818752285,247.635729840063,0.09029376745385048,49.9233631357567,254.6782378726435,0.028042101054128698
0.0289647856405262,247.853717680202,0.09196319440867068,49.96730948432872,255.03274748301655,0.028553234342642266
0.0294860306015867,247.987231922732,0.09361814716003777,49.99422595562277,255.29939103200846,0.0290596782839681
0.0300170006175261,248.170924782117,0.09530397696064537,50.031258436074786,255.6202715845538,0.029575307559239625
0.0305361459949383,248.276772441351,0.09695226353392909,50.05259732417636,255.85818821177216,0.03007919690492351
0.0310398350569353,248.416235984851,0.09855147630576956,50.08071317454596,256.1270349752855,0.030567841589037695
0.0315550916461704,248.519322604219,0.10018741597659102,50.101495437010556,256.36137260483935,0.03106746135759499
0.0320684336048784,248.663129297751,0.1018172766954889,50.1304868664266,256.63736634961725,0.03156497649348601
0.0325767048727986,248.88641378406,0.10343103797113555,50.1755010188665,256.99431303275253,0.03205733352735632
0.0330897799376598,249.067078817366,0.10506005130206984,50.211923089580985,257.3086536451484,0.032554098207603785
0.0336024195292405,249.180486398638,0.10668768200533858,50.23478605796542,257.5535536411053,0.03305019491927377
0.0341317315034028,249.377181050177,0.10836824752330387,50.274439699715685,257.88885603685713,0.03356216787813767
0.0346533622028906,249.483955669088,0.11002442499417765,50.29596546288815,258.12941354869884,0.03406645487452904
0.0351721438566145,249.527794898986,0.11167155674475103,50.30480345163558,258.304222397397,0.03456773545404516
0.0356924614690878,249.707773111799,0.11332356516435375,50.34108705933868,258.6204581821236,0.03507024790424044
0.0362209160194725,249.82749690801,0.11500140836182518,50.365223376654825,258.87647769287,0.03558036050603695
0.0367561302179624,249.977116302915,0.11670071344203062,50.39538664666767,259.1653077412557,0.03609673304509032
0.0372814999059083,250.136589791748,0.11836876220125886,50.4275365020164,259.4620570405333,0.03660334844256629
0.0378030438602919,250.21443734543,0.12002466425642679,50.44323056883869,259.6733046948776,0.037106020940351765
0.0383332543227469,250.254996542295,0.12170808247472141,50.451407302926675,259.84808497028894,0.0376167874776411
0.0388523799397645,250.457568246127,0.12335630630875229,50.4922457584192,260.188440846415,0.03811662304290094
0.0393793039491508,250.641882737924,0.1250292900385538,50.52940355996548,260.5119856206481,0.03862371185764889
0.0399207631790102,250.795146726303,0.12674842309335738,50.56030158002268,260.80708038520885,0.03914452099978112
0.040452509617344,250.912908009009,0.1284367180350672,50.584042254616215,261.06296483335916,0.03965572392366714
0.0409730398789401,250.983904685434,0.13008940161563481,50.5983551845835,261.2674782210824,0.040155891006341454
0.0415041878128018,251.002245250392,0.1317757963056457,50.60205264247903,261.4198895786992,0.040666002654446316
0.0420386395617972,251.129450496532,0.1334726806087061,50.627697220100856,261.68659094930786,0.041179024756699656
0.0425616501675824,251.3054326973,0.1351332392820741,50.66317523177569,262.00140660897546,0.04168080979370289
0.0430847526552506,251.515392799695,0.13679408968042064,50.70550318841852,262.3518712874581,0.042182431255451104
0.0436221585184504,251.6616528365,0.13850035329608001,50.7349892118384,262.63967734954906,0.042697506824716104
0.0441629339806518,251.800182786208,0.14021731538856944,50.762916849699536,262.92041763491136,0.043215544314530424
0.0447007208403939,251.856033713918,0.14192478866825062,50.77417639672587,263.1141799689327,0.04373045285859269
0.0452253869296063,251.906593808206,0.1435906035015,50.78436931173433,263.29916698330123,0.04423254343326298
0.0457505395982505,251.953208025408,0.1452579632244453,50.793766737922255,263.4802032460807,0.04473484733167089
0.0462874186044144,252.061611035338,0.1469625540690157,50.815620784724146,263.72889233943374,0.045248106678467126
0.0468327001749245,252.166825010184,0.14869382305538528,50.8368319220531,263.97647831994857,0.045769129411900526
0.0473776999316232,252.286722667606,0.15042419728290365,50.86100328978937,264.23948731088444,0.046289611755961434
0.0479110146706857,252.390091268472,0.1521174715794271,50.88184239972396,264.48235663397145,0.04679867262844437
0.0484580810874748,252.421883892474,0.1538544074527325,50.88825179272276,264.65376401038867,0.04732059067266143
0.0490031365492365,252.45654863039,0.15558495854382587,50.89524020388662,264.82771135567396,0.04784031944709368
0.0495546647426012,252.529489971391,0.1573360605577588,50.90994517823243,265.0435041845434,0.048365945384795675
0.050090175369003,252.650116907645,0.15903630679658454,50.93426356858124,265.3054055705481,0.0488760417856564
0.050631030524248,252.685073957322,0.16075352191448739,50.94131090979612,265.4787796498771,0.04939096510406555
0.0511697807227144,252.645686297857,0.1624640537946182,50.93337035764797,265.5735106662581,0.049903620925095614
0.0517011117077699,252.686774849746,0.1641510296721694,50.9416538097088,265.75096202332884,0.05040895960116465
0.0522164501875285,252.764547832812,0.16578722934540296,50.9573328430949,265.9630152538972,0.05089884428048684
0.0527570292170709,252.82783367687,0.16750356776420008,50.97009126925699,266.1662790850494,0.051412465042663315
0.0533103244363585,252.954806286696,0.16926028008543823,50.995688947397916,266.439909077576,0.051937894802596675
0.0538694162332469,253.067590055775,0.17103539654055888,51.01842615524424,266.70019339963426,0.05246854892689134
0.0544213540297555,253.152246028376,0.17278779904447372,51.0354927993206,266.929134032914,0.052992136865426975
0.054985475349663,253.191407148594,0.17457888423518,51.04338768115656,267.11325702510953,0.05352699939218003
0.055544199937293,253.241749027871,0.17635283480090527,51.0535366040188,267.30785936834485,0.054056463258265075
0.0561061953068166,253.279583988415,0.17813717009914268,51.06116413206447,267.4901377948983,0.05458874396539188
0.0566628690426669,253.286879319815,0.17990460921046741,51.06263487087471,267.63884059293946,0.055115705248690895
0.0572144138043857,253.236539320204,0.1816557638289246,51.05248632695313,267.7253194712608,0.055637537597910194
0.0577742902411794,253.276552213458,0.1834333715157446,51.06055292623313,267.9094252523235,0.05616697442071739
0.0583331713986337,253.327486266515,0.18520781919066198,51.07082123132942,268.1048819428846,0.05669519066736856
0.0588808122910548,253.304550913208,0.186946579024099,51.066197464102736,268.21932862799855,0.05721251287367691
0.0594390316509712,253.290346103199,0.18871892549183353,51.06333377440492,268.3456790021125,0.05773955261645618
0.0600058456115943,253.328486738508,0.19051855981681187,51.07102292648321,268.52967680275776,0.058274422836688954
0.0605625934225008,253.374658065323,0.19228623411644005,51.08033106596911,268.71968446529826,0.05879951583859389
0.0611136310752529,253.377491954094,0.19403577866392796,51.08090237794535,268.8623105201494,0.059318951988916464
0.0616770356230709,253.419871094163,0.1958245881032501,51.08944601258326,269.0500575112317,0.05984976698625508
0.0622480803450592,253.458819006549,0.19763765509556294,51.09729791172028,269.23614393623245,0.060387492851875044
0.0628238644222699,253.48740111357,0.19946576954070694,51.103060064495715,269.41245923388243,0.0609293889441165
0.0634055762592788,253.469585812599,0.20131270462321016,51.09946849981996,269.5409709652476,0.06147656587657063
0.0639721050883939,253.436281858123,0.20311143365565063,51.0927544225976,269.6491343143627,0.06200917355359433
0.064539151578689,253.424857042595,0.20491180626233757,51.09045117978715,269.78068230507466,0.06254198398805529
0.0651137923527433,253.408719462031,0.20673629071995994,51.08719784354545,269.9091222014563,0.06308164073319569
0.065695673385413,253.355569251122,0.20858376299868628,51.0764827610262,269.9999339790191,0.06362780035609017
0.0662749570057683,253.317849439868,0.21042298849331434,51.068878447077395,270.106479020289,0.06417122588583565
0.066844255172665,253.258046222093,0.21223051017321135,51.05682211837395,270.18689168829314,0.0647049965041517
0.0674095276182195,253.182863845308,0.2140252501878469,51.041665351214085,270.24980109814817,0.06523471088332279
0.0679827144891118,253.191213369241,0.21584511850292998,51.04334861523899,270.4038393388739,0.0657715554717371
0.0685654981061137,253.256493538967,0.217695456486911,51.056509097455745,270.621151167074,0.06631709301497606
0.0691430374031225,253.252657630242,0.21952914375491392,51.05573577825679,270.76331560921,0.06685742795911559
0.0697405236311118,253.192962501162,0.22142616252877995,51.04370124023426,270.85077228570543,0.06741611778629028
0.0703217656376072,253.15915471721,0.22327160589940284,51.036885590989534,270.9617534642484,0.06795931881712214
0.0709150794354111,253.126198548338,0.22515537720743023,51.03024162734494,271.0766630255771,0.06851349741194113
0.0715055158326527,253.018024431185,0.22703001276867232,51.008433725326896,271.11020878309563,0.06906468368553635
0.0720958228246809,252.940912743064,0.22890423746836183,50.9928880090017,271.176895973301,0.06961544561715538
0.0726856812460072,252.946967178967,0.23077703795607285,50.99410858327975,271.33258980748167,0.07016548620178224
0.0732833737693472,252.968763896928,0.23267471171767734,50.99850280162069,271.50716837355634,0.0707225236272735
0.0738771533362197,252.908849289196,0.23455996184249756,50.98642401670191,271.59303512822083,0.07127560717600043
0.0744628064427876,252.760649279083,0.23641941045585063,50.956546894663134,271.5819165827047,0.0718208217435643
0.075054476923475,252.648983311068,0.23829796423203312,50.934035035511315,271.611420598728,0.0723713365035143
0.0756436564963443,252.617616186592,0.24016860937589316,50.92771142321694,271.7265363703359,0.07291923262938406
0.0762419710627796,252.601046219658,0.24206825812432523,50.92437091788305,271.859847875965,0.07347531662770689
0.0768464522909538,252.603176528896,0.2439874860237783,50.924800388225435,272.01483448256715,0.07403681817822345
0.077455434642582,252.605528828274,0.24592100499019784,50.92527461178004,272.1711998567872,0.07460218217993829
0.0780796398552577,252.56267577543,0.2479028565404432,50.916635436326686,272.2826785408558,0.07518134717475455
0.0786987703862736,252.505743550086,0.24986859597641867,50.90515789969734,272.3776350829495,0.07575547249526261
0.0793160061261847,252.44168912796,0.2518283194506364,50.892244528196734,272.46435568933765,0.07632751283850811
0.0799384383287871,252.3918252367,0.253804541693899,50.88219196771872,272.56763359307394,0.07690403796405904
0.0805653744033016,252.316507334414,0.25579506373048255,50.86700787861787,272.6444812159445,0.07748439897839002
0.0811803921903461,252.219715290132,0.25774774520434884,50.84749460249061,272.69501069552234,0.07805340002665549
0.0818097499474612,252.152782309524,0.2597459560831893,50.83400091360004,272.7813383788228,0.07863533312252621
0.0824328807188589,252.011975231285,0.261724396282377,50.805614206627055,272.78604832524957,0.07921117501731853
0.0830391334938222,251.873156697556,0.2636492488428855,50.77762839022729,272.78848538007475,0.07977110170935013
0.0836505344635255,251.782802572641,0.2655904469216934,50.75941299864443,272.84456857656676,0.0803354658589309
0.0842725342415315,251.809991957696,0.2675652962168625,50.764894378671514,273.03065812731074,0.08090928676987756
0.0849016378581931,251.853272847803,0.2695627001997631,50.77361980611709,273.23602821252786,0.08148932653099163
0.0855217828624597,251.774018940626,0.2715316605883096,50.7576422184302,273.30618191887504,0.08206077725827575
0.0861514712489785,251.693191184336,0.2735309212155067,50.74134734276214,273.376929908217,0.08264068807402447
0.0867929897946401,251.6764772413,0.27556774259798233,50.737977811846086,273.5202311620551,0.08323114823147527
0.0874472262526735,251.619205080723,0.2776449433522383,50.72643174427376,273.62260663693485,0.08383295521945235
0.0881049732415703,251.537900758012,0.27973329004198566,50.71004079281522,273.69964077353745,0.0844376265383852
0.0887585940502748,251.43733593967,0.2818085361096225,50.689766925437475,273.75456036942177,0.0850381426553966
0.0894056860862711,251.339588882881,0.2838630533239107,50.67006111878881,273.8107772675963,0.08563230541982549
0.0900645665792125,251.270523555413,0.28595499888899967,50.65613754877127,273.9010943535631,0.08623692988047868
0.090720197741906,251.153797336874,0.2880366278305515,50.6326055431138,273.9385194949058,0.08683820992716001
0.0913707326468948,251.033377795705,0.29010207615389094,50.608328963614134,273.9704814437233,0.08743445907076988
0.0920192033498106,250.904753812388,0.29216097063564866,50.58239836857742,273.9928093748843,0.08802846265326503
0.092668761318747,250.832570434871,0.2942233171870217,50.567846199669994,274.07691403546784,0.08862310866091615
0.0933228183865214,250.773426284874,0.2962999483772054,50.555922739030606,274.176309202223,0.08922151635229465
0.0939754166294189,250.700319991331,0.298371947798405,50.541184510252336,274.25998701164497,0.08981823265902822
0.0946344695804771,250.659236146505,0.3004644409180148,50.53290200713541,274.38024000467703,0.0904204898041973
0.0952958352603653,250.558617765579,0.30256427695165977,50.512617341540725,274.43581052723243,0.09102449596688936
0.0959643908466024,250.480753294902,0.3046869409379626,50.49691986425224,274.51798620364536,0.09163469789454394
0.0966505280503809,250.467382882863,0.3068654265599593,50.494224389185185,274.67518769788865,0.09226055993740603
0.0973283973380024,250.397110809798,0.30901766154815763,50.48005753925528,274.76786030298183,0.092878495963452
0.0980181158156851,250.301944913573,0.3112075177148002,50.46087209457632,274.83606993900287,0.09350684187262226
0.0987078535291296,250.207114419269,0.31339743495498645,50.44175426692464,274.9045216213124,0.09413481071874685
0.0993959711559199,250.100192064926,0.3155822084200457,50.42019872028908,274.9591435415014,0.09476091185331666
0.100099198841502,249.947389589845,0.3178149563217688,50.38939374131275,274.96692304031325,0.09540035650328603
0.100790372357172,249.817098232183,0.3200094322340211,50.3631270036081,274.99625658419296,0.09602844211688202
0.101474748786949,249.760503320018,0.32218232739856306,50.35171746931563,275.10488765131873,0.09664996260979343
0.102177184786422,249.72267837383,0.3244125616968898,50.344091960164135,275.238638627393,0.09728748254891097
0.102876658299088,249.623411678128,0.3266333900996044,50.32407979431061,275.3038341047914,0.09792191017372473
0.1035779274571,249.483330277344,0.32885991967629247,50.29583938391255,275.3242965625665,0.09855756266904601
0.104292176490894,249.38043134026,0.3311276603585884,50.27509495819641,275.38885929897367,0.09920456545914029
0.105013998649451,249.325701799195,0.33341944571200693,50.264061482717715,275.5083907112091,0.09985800335051344
0.105729788524244,249.216949297746,0.3356920785644747,50.2421369784256,275.56660464365393,0.10050555907719566
0.106429422986711,249.04001317436,0.3379134179828074,50.20646665595098,275.54519807711006,0.10113809445905561
0.107148147144458,248.945407055318,0.3401953671836541,50.187394062352105,275.6194461614182,0.10178747236448944
0.107873152099286,248.915179340169,0.342497257915233,50.181300154978075,275.7664443409521,0.10244209810643272
0.108607787794703,248.876533185263,0.344829726248182,50.173509090149025,275.9064628885294,0.10310498287038022
0.109351812713089,248.722220501189,0.34719200536405753,50.1423996530397,275.92044617501864,0.10377589224683964
0.110080042516158,248.54333281059,0.3495041349888016,50.10633589461494,275.90299345348734,0.10443212309933188
0.11081872531701,248.432768958694,0.3518494528815067,50.084046222072715,275.96377174167174,0.10509733381383188
0.111581996940526,248.378590096597,0.35427284028617,50.07312376347396,276.09316917684765,0.10578422312761054
0.112347129608178,248.327492165093,0.3567021365059651,50.062822420482746,276.2263731126385,0.10647231402826633
0.11309589652073,248.253265274681,0.35907947145331776,50.047858279375696,276.3296908751197,0.10714522897779792
0.113865245565366,248.131254051264,0.361522154670037,50.02326081673482,276.3847802262534,0.10783616970478556
0.114632112036794,247.966833455167,0.36395695571682096,49.99011362456167,276.39179528920874,0.10852440610684548
0.115391761943931,247.812338712012,0.3663688441719809,49.95896748434162,276.4078411074373,0.10920569920454172
0.116165062895074,247.70548337803,0.3688240746918599,49.93742544901085,276.4802064340936,0.1098987588420907
0.116937171718991,247.601844515938,0.3712755202077964,49.91653185441311,276.5557039260372,0.11059027116312715
0.117715481237798,247.495819362525,0.37374665293000864,49.89515718348505,276.6299088431278,0.11128685329122526
0.118512489322512,247.403158524083,0.37627715359897557,49.87647675845514,276.72352270702413,0.11199966802116643
0.119300206696545,247.257250648239,0.37877815626153033,49.847061730684985,276.7550917577933,0.1127036745789705
0.120066334936692,247.041447327539,0.3812106134239971,49.803555781231864,276.7028084856124,0.1133879111751632
0.120852741356966,246.89215208815,0.383707453808367,49.77345786097104,276.7297454875239,0.1140897718187499
0.121660650209718,246.8545748314,0.3862725644158546,49.76588228601024,276.88706291263156,0.1148103105595611
0.122474860197771,246.809774144425,0.3888576811279229,49.75685046751608,277.0377667282069,0.11553594412313467
0.123273847849788,246.689280348549,0.3913944669230769,49.73255891826748,277.0996171604097,0.1162474998576344
0.124097271393751,246.535691146355,0.3940088366751594,49.70159533510517,277.1300977187902,0.11698028811299557
0.124925760637085,246.405003747797,0.3966392900227449,49.67524875555588,277.1873362657743,0.11771704293409836
0.125751785886459,246.258752793412,0.3992619201895073,49.645764563151864,277.22623074735554,0.11845106659531782
0.126594467081282,246.116506459625,0.40193743298307033,49.6170877022604,277.2734944347881,0.11919933630121343
0.127438196651491,245.999731211814,0.4046162743684839,49.59354581230171,277.3494933341991,0.11994797639254054
0.128279180054157,245.857482982566,0.4072863966719485,49.56486856928531,277.3958793097484,0.12069362250079446
0.129111823415747,245.6928151551,0.4099300393449967,49.53167153526816,277.41466251992307,0.121431326689454
0.129950384254629,245.520254467775,0.412592470008447,49.49688330070344,277.42570587815663,0.12217372402100984
0.130775526977007,245.389869758632,0.41521229815199723,49.470597743340214,277.4808592911362,0.12290370438255636
0.131609915639607,245.253950601871,0.4178614821557522,49.44319644133719,277.53180235086353,0.12364132290211871
0.132481558786598,245.242541281741,0.42062894914744864,49.440896322398984,277.73265543153263,0.12441129461032917
0.133360889634073,245.179781981106,0.42342082458818175,49.428244047390976,277.87717582639436,0.12518745704142178
0.134238639957773,245.014524633507,0.4262076818659292,49.394928166115015,277.9049411902093,0.1259616240458548
0.135105833666978,244.783541714307,0.42896102189265517,49.34836200960429,277.85522618557394,0.12672589210783902
0.135981245929497,244.629739272689,0.431740455826153,49.3173554373741,277.8947960103972,0.1274968112978073
0.136872344663368,244.548303357559,0.4345696943061934,49.3009379568839,278.0202030215567,0.12828093464232615
0.137768586232317,244.429794015156,0.43741526128760644,49.27704647345545,278.1045411696805,0.1290689637357584
0.138691460949388,244.258002869426,0.4403453885143069,49.242413378476286,278.13450213596656,0.12987976185960098
0.139595264634549,244.085635203269,0.443214965214693,49.20766405697903,278.15883404296136,0.13067316834564446
0.140508263598748,243.971481900037,0.44611373692602485,49.18465075104746,278.25149118942454,0.13147400830899644
0.14139807818144,243.839920614726,0.448938898226072,49.158127995928766,278.3184167735632,0.13225389538104732
0.142295626160758,243.592070077946,0.45178861306040663,49.108161327713916,278.25415621748255,0.13303994477447126
0.143184788558797,243.383525901127,0.4546117036741804,49.0661188216672,278.2323445959743,0.1338180415257478
0.144103685010253,243.333744730968,0.45752919990755325,49.05608293776315,278.39903403404475,0.13462152260083718
0.145029147480431,243.262844265011,0.46046754325036837,49.04178940382622,278.5430471824304,0.13543009299698344
0.145972284777122,243.108167320614,0.4634620041673624,49.01060653183578,278.59522195238293,0.13625343368694562
0.146918932003542,242.920847716686,0.46646760911124585,48.972842899683904,278.6105192246166,0.1370791573612994
0.147880069292273,242.753298534932,0.4695192200029667,48.93906498464229,278.6516731432056,0.13791682318247983
0.148815377126697,242.561868259331,0.472488822377263,48.90047264108114,278.6588041608995,0.13873130460411331
0.149760742966119,242.38605211679,0.4754903589174278,48.865028106744866,278.6859673664249,0.13955387113516035
0.150712281559759,242.247493008566,0.4785114939522348,48.8370945905269,278.75716538201874,0.14038112591081822
0.151646494651682,242.000799587881,0.4814776205190903,48.78736119691681,278.6993725482874,0.1411926529003095
0.152584139628863,241.792854155775,0.48445464332164,48.74543939780424,278.68660877554106,0.14200649940940907
0.153534295943668,241.659307643012,0.48747138962114583,48.71851642083122,278.7622993002161,0.14283053026048229
0.15445706730753,241.487330220798,0.49040118870140775,48.68384577251288,278.7867550386275,0.1436301618602568
0.155365586033966,241.296734785442,0.493285735657842,48.645421732745106,278.78594339346466,0.1444168185951131
0.156289020485584,241.02723777762,0.49621764004172914,48.59109113596819,278.69714868023016,0.1452157567220572
0.157224259332143,240.876052241812,0.49918702337955406,48.560612131949306,278.74761114638153,0.14602425771979333
0.158166747299727,240.808639425112,0.5021794226766332,48.547021708102584,278.89655864465476,0.14683836472542544
0.159115112275467,240.610893566391,0.5051904814746078,48.507156142984435,278.89572291090775,0.14765687976689013
0.160044333876106,240.399118670129,0.5081407600566366,48.464462323898005,278.87363548209277,0.14845822324666333
0.161000958975405,240.179672130166,0.5111780447469109,48.420221901441465,278.8488296695211,0.14928252870628747
0.161961081693224,239.929085463044,0.5142264343759863,48.36970362934967,278.7882596743046,0.15010916535009244
0.162879879852638,239.619498622026,0.5171436185321256,48.30729092220044,278.648693767931,0.15089958346681293
0.163795837182881,239.371244051821,0.5200517830556471,48.257242800847116,278.57925736879673,0.15168693631607771
0.164698169669932,239.191721871262,0.5229166887020341,48.22105112924642,278.58616066365823,0.1524619716217844
0.165593930376503,238.950253337733,0.5257607289453969,48.172371072886975,278.5189649523893,0.15323076858991827
0.16644038518133,238.55909647768,0.5284482229507227,48.09351384990028,278.26496438393514,0.1539567054565865
0.167275166575774,238.179559665696,0.5310986538780824,48.01699922860431,278.0210851837198,0.15467211520686175
0.168098797373412,237.833868357348,0.5337136816605831,47.947307860841356,277.8134556028846,0.15537746762107915
0.168912946581906,237.532494298507,0.5362986053975516,47.88655085057901,277.6548078194176,0.1560742114380801
0.169710233172567,237.218417188049,0.5388299903229002,47.82323290511068,277.4768100818601,0.1567560541808119
0.170489076527793,236.856052847045,0.5413028179757428,47.750180253964274,277.2374225669558,0.15742167559241826
0.171261257528264,236.394448757484,0.5437544926522382,47.65712086950878,276.87965932439147,0.15808116607458295
0.17204317477299,235.894377255041,0.5462370799042432,47.55630645461627,276.4783948290957,0.15874852901980524
0.172795770571565,235.205583222802,0.5486265715647188,47.41744557771688,275.84811321852044,0.15939044587802864
0.173515455062345,234.562812766149,0.5509115698229453,47.28786305365564,275.263085963971,0.16000390627960487
0.174240885632492,233.992471212467,0.553214811883162,47.17288219643335,274.76352662786263,0.16062188403194597
0.174957375071021,233.264944228978,0.5554896658504916,47.02621275656196,274.0763665673681,0.16123187040281153
0.175627634224077,232.351171404735,0.5576177386614445,46.84199615519457,273.1584579477416,0.1618021617716167
0.176300499263186,231.460334865733,0.5597540851606155,46.662403508931774,272.26690746218594,0.16237434341941975
0.176992813304135,230.602926354962,0.5619521822406286,46.48954995316034,271.417987046693,0.16296272231568776
0.177646478160213,229.53069255006,0.5640275681586763,46.273387618092094,270.3060117112528,0.16351793675998863
0.178270235745888,228.509089666528,0.5660079984931944,46.06743247677205,269.24545895145826,0.16404746108193793
0.178892504796913,227.210532887267,0.5679837027301987,45.805643430073026,267.85679423171155,0.16457544250195405
0.179530724465962,226.046414324861,0.5700100501794293,45.57095712789198,266.6286908515363,0.16511666824694282
0.180159470967695,224.86148588496,0.5720063203224316,45.332075554407936,265.3724122230042,0.16564957423420285
0.180773654336615,223.344747470413,0.5739563525187525,45.02630109003527,263.71959364752803,0.16616986290836488
0.18143145024664,221.872421362769,0.576044854533082,44.72948014673423,262.12705654034977,0.16672679670361537
0.182061097298633,220.364182561118,0.5780439839231598,44.425419204321386,260.48392744351145,0.16725960740999357
0.182718008176671,218.76915120681,0.5801296759609303,44.10386088329289,258.7422147658193,0.16781518648578495
0.183371921279804,216.929085355564,0.5822058500633777,43.7329036076817,256.70778851868437,0.1683679238197642
0.184006821574776,215.118562262844,0.5842216584999137,43.36790215218935,254.70184516656545,0.1689042979103991
0.184590959642614,213.073051456576,0.5860762968652994,42.95552717364573,252.40441049892544,0.1693975332619753
0.185223330118856,211.119439023544,0.5880840731273678,42.56167890714647,250.22368457230957,0.169931221065263
0.185872044925863,209.047167475056,0.590143742639615,42.14390896297129,247.90319197960403,0.1704784068343559
0.186502681290573,206.820339802049,0.5921460130975693,41.69498050409308,245.39288772055858,0.17101005672304773
0.187211095927601,204.510735775094,0.5943952295701331,41.229364332258946,242.79741474850937,0.17160693968750554
0.187988076893139,201.945285743848,0.5968621441357164,40.71216960595976,239.9085916484694,0.17226118460485282
0.18872926610944,199.321663997563,0.599215419897472,40.18324746190871,236.93949536353546,0.17288489296673334
0.189408652189753,196.479838976139,0.6013724707024658,39.61033553758963,233.6948204590692,0.17345625267936202
0.190124007259422,193.450964580421,0.6036437230486648,38.99971445941287,230.23063717465112,0.1740575094752112
0.190921919961577,190.196419580824,0.6061770958780069,38.343598187494116,226.5090851770126,0.1747277298375329
0.191719230879768,186.673254871989,0.6087085580432634,37.63332818219298,222.46210772186961,0.17539699633422728
0.192491004402163,182.722578666439,0.6111589389768675,36.8368718591541,217.8950313608951,0.17604440027363707
0.19327354025111,178.265594810961,0.6136434902972742,35.93834391388974,212.71961742504536,0.17670040455433103
0.193661706234587,175.966401693457,0.6148759172948137,35.47482658140093,210.04435528537257,0.17702564671368165