File: example/data/02 processed data/test_ID_066.csv
Strain,Stress_MPa,Displacement(mm),Force(kN),True Stress (MPa),True Strain
0.0011229982093415112,47.3625404782615,0.003565519314659298,19.096576320835037,47.41572852640845,0.0011223681185354947
0.001206492981502911,51.5259789398413,0.003830615216271742,20.77527470854401,51.588144671797295,0.0012057657537171602
0.0012969753549084112,55.5999118529696,0.004117896751834205,22.417884459117342,55.67202356837797,0.0012961350088996357
0.0013935487087272111,59.6097084366486,0.004424517150208895,24.034634441656717,59.69277746886811,0.0013925786208640668
0.0015013150123430112,63.7421425539308,0.0047666751641890605,25.7008318777449,63.83783958946593,0.0015001891656527576
0.0015896280539061112,67.7438657736245,0.0050470690711519025,27.314326679925404,67.8515533231383,0.0015883659325897758
0.001689193496045111,71.8014437609451,0.005363189349943227,28.95034212441307,71.92273029275273,0.0016877684133127621
0.0017789028800473112,75.7931388809781,0.005648016644150213,30.559793596810373,75.92796751402129,0.0017773225062623185
0.0018633304455475113,79.8223965611536,0.005916074164613348,32.184390293457135,79.97113206290257,0.001861596598858329
0.0019568636674186114,83.7031982686327,0.006213042144054091,33.74912954191271,83.86699401617132,0.001954951503867992
0.0020411314767103113,87.5028968532155,0.0064805924385552376,35.281168011216494,87.68150177028595,0.002039051198124855
0.002131339074406211,91.1965105458242,0.0067670015612397195,36.770433052076314,91.39088123220002,0.0021290709934091976
0.002247436524562911,94.7858175387026,0.007135610965487243,38.21764163160489,94.99884264704963,0.0022449148166424145
0.0023443606367401114,98.3776840186648,0.0074433450216498534,39.66588219632565,98.60831678861182,0.002341616910694785
0.002455105625896711,101.839701818964,0.007794960362222057,41.06176777340628,102.0897290438394,0.0024520967777667147
0.0025554942567575113,105.329052629505,0.008113694265205099,42.46867402021641,105.59822041856943,0.0025522345335976097
0.002660387811222711,108.700371245808,0.008446731300632107,43.827989686309785,108.98955638854574,0.002656855243516075
0.002776288650287611,112.038827107695,0.008814716464663164,45.17405508982262,112.34987923178562,0.002772441879139299
0.0029166158954365114,115.254894504062,0.009260255468010924,46.47077346403779,115.5910487613994,0.002912370823455687
0.0030814060514968112,118.33626926328,0.009783464213502376,47.7131837669545,118.70091135949943,0.003076668250101146
0.003271096152226011,121.282219663711,0.010385730283317584,48.90099096840828,121.6789454657864,0.003265757755645229
0.003500325561656511,124.09640809604,0.011113533658259423,50.03567174432333,124.53078592540832,0.003494213680368157
0.003771843743793011,126.629468206867,0.01197560388654281,51.05700158100877,127.10709477430291,0.00376474817782637
0.0040715490684906114,128.787850264855,0.012927168292457691,51.92726122678953,129.31221631663377,0.004063282742819198
0.004410445840998711,130.530480346754,0.014003165545170905,52.629889675811214,131.1061779609229,0.004400748327856408
0.004779759912772512,131.762225279708,0.015175737723052724,53.12652923277827,132.39201708211766,0.004768373130003548
0.005179315302773211,132.57308623201,0.016444326086304945,53.453468368746435,133.25972404626734,0.00516594878235445
0.005568555336996111,133.05707108243,0.017680163194962652,53.648611060435776,133.79800674573116,0.005553108251493742
0.0059665637733084115,133.23456893847,0.018943839980254205,53.7201781959911,134.02952149085064,0.00594883431933613
0.00634969439522871,133.309917226322,0.020160279704851153,53.75055862565303,134.15639446056238,0.006329620018397701
0.006746349258569812,133.269012281501,0.021419658895959152,53.734065751901205,134.16809158369662,0.00672369447870434
0.007169193092232712,133.14757362445,0.02276218806783886,53.68510168537824,134.10213428952594,0.007143616596573085
0.0075907665449710116,132.907324651776,0.02410068378028296,53.588233299596084,133.91619312532433,0.007562101644257701
0.00802007916473121,132.788825895641,0.025463751348021594,53.54045460112245,133.85380279151573,0.007988089257061052
0.008449065964979411,132.635112182273,0.02682578443880963,53.47847723189247,133.75575499437346,0.00841357239203113
0.008899801531747312,132.513683382165,0.02825686986329771,53.429517139688926,133.69302886450708,0.008860431714710074
0.009344726756414512,132.380795462849,0.029669507451616076,53.375936730620715,133.61785782424613,0.009301334911164885
0.009788899631825212,132.169626358806,0.031079756331045046,53.290793347870576,133.46342156560817,0.009741298741958863
0.010222174888149112,131.983165145115,0.03245540526987343,53.21561218651037,133.33232014151983,0.010170281798966441
0.010671116251156812,131.808764740778,0.033880794097422874,53.1452939434817,133.21531139224822,0.010614581725500267
0.011112926218453112,131.656978804752,0.03528354074358863,53.084093854076,133.12007309635362,0.011051631346081094
0.011577827817997512,131.46834230031,0.0367596033221421,53.008035615485,132.99046013098055,0.011511317639503074
0.012028269291499912,131.293000469909,0.03818975500051222,52.937337789467314,132.8722280356501,0.011956504557634383
0.012479183271786811,131.123629365613,0.03962140688792312,52.86904736021516,132.75994516772832,0.012401960055634348
0.012921719718671412,130.924190582901,0.04102646010678173,52.788633643025676,132.61595627800716,0.01283894658336175
0.013372372209841311,130.743341446893,0.04245728176624616,52.71571527138725,132.49169007267923,0.013283751215024169
0.013832822360307011,130.544702903581,0.04391921099397476,52.63562421072386,132.3505045889253,0.013738022109373981
0.014299025826183611,130.415162946531,0.04539940699813296,52.583393700041306,132.2799727296294,0.014197758959820717
0.014743125702401712,130.212311370126,0.04680942410512543,52.501603944434805,132.13204784465606,0.014635502338365136
0.015197388371811312,130.0120481945,0.048251708080500916,52.420857832022406,131.98789178392647,0.015083064888935294
0.01564125119328921,129.761509744926,0.04966097253869324,52.319840729154166,131.79114211406684,0.01552018758287882
0.016093748831078312,129.538453746443,0.051097652538673634,52.22990455056582,131.62321308500452,0.015965617370981355
0.01656023746046661,129.372640917886,0.052578753936981484,52.16304881809164,131.51508257237387,0.016424612006294623
0.01702299643432291,129.22109327943,0.054048013678975236,52.101944810266176,131.42082348956504,0.016879728840590857
0.01749567496234281,129.071146728823,0.05554876800543841,52.04148636106144,131.32933355900735,0.017344387674318736
0.01795297781838811,128.900855531129,0.057000704573382244,51.97282495015122,131.2150097312506,0.017793726313360163
0.01839947706820141,128.702986053639,0.05841833969153948,51.893043976827244,131.07105369414197,0.018232254777229374
0.01884437416524261,128.528798158549,0.05983088797464528,51.82281141752696,130.95084292205763,0.01866901849978946
0.01929602788982251,128.332124416213,0.06126488855018647,51.74351256461708,130.8084246681084,0.01911222028462969
0.01975624507424211,128.122717140288,0.0627260781107187,51.659079550964115,130.6539409396893,0.019563623319594912
0.02021728020009771,127.911257777366,0.06418986463531022,51.57381913583397,130.49727551659794,0.020015624414700218
0.02067774476007521,127.736219749121,0.06565183961323878,51.50324380284559,130.3775166977102,0.020466862290396088
0.02114168717087511,127.592609977767,0.06712485676752847,51.44534034303565,130.29013302323244,0.020921302493607873
0.02160611201244851,127.499872875126,0.06859940563952402,51.40794874325081,130.25464941003892,0.021376008502603103
0.02206625554753251,127.376796395089,0.07006036136341572,51.35832430649989,130.18752533516906,0.021826318983053736
0.02252250826584841,127.239776510014,0.07150896374406869,51.30307788883764,130.10553542820549,0.02227262166647272
0.02297659458075401,127.093947917091,0.07295068779389398,51.24427980017109,130.01413403204947,0.02271660751005774
0.02342763927919821,126.927411492863,0.07438275471145431,51.177132313922364,129.90102110396015,0.023157424332350143
0.02389188667815061,126.753917654674,0.07585674020312819,51.10717959836455,129.7823078912911,0.023610941627548596
0.02436168530119261,126.555643593811,0.07734835083128654,51.0272354970246,129.6387523561333,0.024069672555894005
0.02482414374489521,126.376219579212,0.07881665639004229,50.95489173433828,129.5134010199828,0.02452103079290581
0.02529351576329751,126.169456335681,0.0803069125484696,50.87152479454659,129.36072546835422,0.02497892844031776
0.02575668117570641,126.019206479773,0.08177746273286784,50.81094405264447,129.26504300308804,0.025430565773205186
0.02622999794632331,125.913891599245,0.08328024347957651,50.768481092815584,129.2166127173068,0.025891891164668106
0.02669875985071071,125.815440195225,0.0847685625260065,50.72878548671471,129.17455641850876,0.026348567423650524
0.02716502591931601,125.680139665268,0.08624895729382832,50.67423231303606,129.09424391681824,0.026802605398170337
0.02762887483858701,125.545120034102,0.08772167761251375,50.619792397749926,129.01379044211959,0.027254085156776908
0.02809817308389231,125.3721320253,0.08921169954135807,50.55004363260097,128.8948598908435,0.027710661582068405
0.02857678164921501,125.219260495425,0.09073128173625765,50.488405831755365,128.79762396087895,0.028176081334334892
0.02905028966200021,125.032338441671,0.09223466967685066,50.41303885968175,128.66456409051878,0.028636328021157356
0.02952807461068121,124.851730456137,0.09375163688891283,50.34021771991445,128.5383616683185,0.029100517255390278
0.03000403422601321,124.716652003873,0.09526280866759194,50.2857540879616,128.458654699151,0.029562718958158794
0.03047495827638351,124.621640912845,0.09675799252751764,50.2474456160591,128.41948021999838,0.03001982049647432
0.03096511711452801,124.507453598943,0.09831424683862643,50.20140529109381,128.36284148126592,0.030495370431913433
0.03143312390077251,124.368698940248,0.09980016838495272,50.145459412708,128.27799566341469,0.03094921759389261
0.031906062064237115,124.194545712743,0.10130174705395284,50.07524083137798,128.1571045962935,0.03140763778477906
0.03235938043909331,123.997757982491,0.10274103289412126,49.99589601854037,128.01024860664106,0.03184684329857549
0.032838066884676616,123.819423664793,0.10426086235884825,49.92399162164454,127.8854141807196,0.03231041781516817
0.033311131454530116,123.676828581421,0.10576284236813312,49.866497284028945,127.7966436761761,0.032768336903005645
0.03379867599862201,123.51480913669,0.10731079629562489,49.80117104391341,127.68944615173262,0.03324005306571225
0.034285270145524016,123.393706048394,0.10885573271203874,49.75234227871246,127.62429259452057,0.03371062792490851
0.03477427501984031,123.252719040881,0.11040832318799298,49.69549631728322,127.53874298975171,0.03418331116359414
0.03526932541669031,123.13766756972,0.11198010819799173,49.6491075641111,127.48065003828867,0.03466161066045815
0.03575802653137741,123.046632015592,0.11353173423712327,49.612402028686695,127.44653674780218,0.03513355143255677
0.03625188184247701,122.930169286851,0.1150997248498645,49.56544425645832,127.38661925871362,0.03561024347775933
0.036742008420999415,122.766903395807,0.11665587673667313,49.499615449189385,127.27760599419578,0.036083111815632736
0.037241624727064215,122.641163810595,0.11824215850842888,49.44891724843191,127.20852000931959,0.03656490570035184
0.03774586161361401,122.455111764155,0.11984311062322449,49.3739010633073,127.07728546668443,0.037050920097830925
0.03824765918427491,122.302225456881,0.12143631791007284,49.31225730421442,126.97999929363414,0.03753434894807196
0.038747053229351416,122.182493765655,0.12302189400319075,49.2639814863121,126.91670535528773,0.03801523034051409
0.039250776574813816,122.073087949888,0.12462121562503385,49.219869061394846,126.86455145080666,0.038500046395761225
0.03975430982641202,121.941954518074,0.12621993369885814,49.166996061687435,126.78967275882374,0.0389844446925596
0.04026519796222661,121.82527383072,0.1278420035300695,49.1199504085463,126.73059259831639,0.039475678687409387
0.040790913404173915,121.657194642888,0.12951115005825217,49.052180880012436,126.61970273456078,0.03998091778236613
0.04129709443242751,121.536319370147,0.13111827482295735,49.00344397004327,126.55541622814563,0.040467142222755596
0.041806044468970516,121.405240800627,0.1327341911889814,48.95059309081281,126.48071369630408,0.04095578825968529
0.042302805258623816,121.273355484523,0.13431140669613062,48.89741693135968,126.40355862464463,0.04143250117141817
0.04281267608751892,121.090315190491,0.13593024657787256,48.82361508480597,126.27451563207705,0.04192155882181591
0.04334433414530441,120.901471241507,0.1376182609113415,48.74747320457562,126.14186500965778,0.04243125973760295
0.04385590546995091,120.719918367959,0.13924249986709414,48.67427108596107,126.0141996962444,0.042921458354085396
0.044380463704174415,120.596561806537,0.14090797226075377,48.624533720395725,125.94869314064024,0.04342385190780376
0.04490045745831661,120.490914690985,0.14255895243015523,48.58193680340515,125.90101188018123,0.0439216248588819
0.04540934011841782,120.41262714332,0.14417465487597655,48.55037126418662,125.88048508382325,0.04440852174923229
0.04594145038853301,120.246207223332,0.1458641049835923,48.48327075244746,125.77049238689195,0.04491738930412809
0.04647172682078882,120.100929288846,0.1475477326560045,48.42469468926271,125.68222686568014,0.04542424564529835
0.04700433255477261,119.951733035803,0.14923875586140303,48.36453876003578,125.5899841859392,0.04593306994552347
0.047537975062531115,119.847063087745,0.15093307082353627,48.32233583697878,125.54434978412782,0.04644262520001918
0.04808594080116231,119.773858436239,0.15267286204369032,48.29281972149156,125.53329710253077,0.04696558711792023
0.048641606816994414,119.640082061904,0.15443710164395724,48.238881087359694,125.45956789311207,0.04749561881371411
0.04920057854471771,119.501342020333,0.15621183687947873,48.182941102598264,125.38087718460358,0.04802852042552467
0.04976734719773311,119.332382968246,0.15801132735280263,48.11481681279679,125.27123910335955,0.04856856552086799
0.050299381609775116,119.220705231646,0.15970053661103598,48.06978834939967,125.21743297987908,0.04907524887156946
0.05083999254991421,119.093636369757,0.16141697634597763,48.018554184286025,125.14835595553762,0.049589837250348136
0.05137818666747462,118.976491043811,0.1631257426692319,47.97132118886459,125.08928740970103,0.05010186224817109
0.05191652014761551,118.843062803827,0.16483495146867924,47.91752292250305,125.01298106828621,0.050613757695016415
0.05247077184731571,118.675356865513,0.16659470061522738,47.84990388817484,124.90234443950209,0.05114051597247265
0.05301466150609711,118.494894971071,0.16832155028185833,47.777141652335835,124.77686171816286,0.05165715661245375
0.05355490034772621,118.332288453316,0.1700368086040307,47.71157870437701,124.66956236935174,0.052170065241967344
0.05410677358856241,118.148633262439,0.17178900614368564,47.63752893141541,124.54127461216787,0.052693748203301166
0.05467009286558181,117.976210529197,0.17357754484822224,47.568008085372234,124.42598091475764,0.05322800984034773
0.055236683299104916,117.839331654482,0.1753764694746581,47.51281852308715,124.3483854972588,0.05376508612593833
0.05582251412922611,117.718915635076,0.1772364823602929,47.46426678406265,124.29028146639222,0.05432009741683251
0.05638704864192971,117.628620553625,0.17902887943812684,47.4278598072216,124.26135130246536,0.054854641465961224
0.05695796842483401,117.535450418715,0.18084154974884797,47.390293608825885,124.23003089246282,0.055394941125678325
0.057518020467071815,117.403740588224,0.182619714982953,47.33718820517191,124.15657134228825,0.055924672423906814
0.05808751166494151,117.241734959239,0.1844278495361893,47.271867535565164,124.05201560630178,0.056463044254548754
0.05866269185569401,117.084152997372,0.18625404664182849,47.20833048854039,123.95262458584178,0.05700650016536169
0.05922274366045891,116.911726449574,0.18803221112195703,47.13880810446823,123.83555965599882,0.05753537845918004
0.059790470703016615,116.780868996094,0.18983474448207774,47.0860463792251,123.76325212247778,0.05807121943675725
0.06036462351048781,116.593694171895,0.1916576796457988,47.01057749010806,123.63182862427838,0.05861283341874721
0.06096682464161391,116.430429867579,0.19356966823712415,46.94474932260785,123.52882346826341,0.05918059113320276
0.06155311828403391,116.274793794182,0.19543115055180765,46.88199685781419,123.43186993004693,0.05973304168546777
0.06212592774121281,116.172958510164,0.19724982057835067,46.840936871298126,123.39031133604935,0.060272491817672906
0.06270456984666281,116.054489949927,0.19908700926315442,46.793170347810566,123.33163682101103,0.06081713960996606
0.0632742909691574,115.980982794497,0.20089587382707474,46.763532262741194,123.31959724672484,0.061353100852698204
0.0638569428835673,115.765089266414,0.20274579365532616,46.67648399221813,123.15749395961046,0.06190092970285007
0.0644528358101859,115.586728086547,0.20463775369734025,46.60456876449575,123.03662049374581,0.06246089794446119
0.06503851606384241,115.420949588995,0.20649728850269963,46.53772687428278,122.92775687294281,0.06301096382560104
0.06562823231755201,115.22047182054,0.2083696376082276,46.456894238041734,122.78218771291637,0.06356451474501718
0.06622196361680041,115.16803112881,0.21025473448334128,46.43575015113619,122.7946842960406,0.06412152509755657
0.06682211754266201,115.001213966067,0.21216022319795189,46.36848947111822,122.68583860325634,0.06468424571547471
0.0674303814258238,114.853506415711,0.21409146102699056,46.30893378681468,122.59812216141567,0.06525424753102796
0.0680350864724223,114.705562955889,0.2160113995499408,46.249282983814446,122.50956585046079,0.06582059250063962
0.06864827565242461,114.54433721132,0.21795827519644811,46.184276763604224,122.40760844662698,0.06639455606277109
0.0692581043979653,114.406642822951,0.21989448146353982,46.12875838621384,122.33023003540366,0.06696504761260755
0.0698947310544965,114.30086521111,0.2219157710980264,46.08610885311955,122.2898934443368,0.06756026144191027
0.0705206604434916,114.159392873442,0.22390309690808582,46.02906720657182,122.20998865470516,0.06814512866845318
0.0711360319788529,114.025980067986,0.22585690153285795,45.97527516341195,122.1373358325223,0.0687197973858755
0.07177713928248301,113.870125587204,0.22789241722188355,45.91243463676066,122.04339745159058,0.06931814857560699
0.07238708735667171,113.710862271533,0.22982900235743267,45.848219667882105,121.94206039218493,0.06988708642380297
0.07300671321173911,113.550005481099,0.23179631444727167,45.783362209979124,121.83991816644901,0.07046472011709698
0.07362035859133481,113.398703897547,0.233744638527488,45.72235741149095,121.747157142277,0.07103644997588027
0.07423747954509881,113.222833206173,0.23570399755568872,45.65144634872895,121.6282109703544,0.0716110885388133
0.07487330620082701,113.016323999265,0.23772274718762573,45.56818183650365,121.47822983175385,0.0722027999373106
0.0755052620408842,112.832293347069,0.23972920697980732,45.49398067753822,121.35172522291336,0.07279056235978218
0.0761199926784802,112.676386552373,0.24168097675417463,45.431119057916796,121.25331227177723,0.07336197288117649
0.07672913179646741,112.56424542733,0.243614993453784,45.385903756299456,121.20120225029349,0.0739278640319475
0.07733246556469521,112.390942509282,0.24553057816790727,45.3160280197425,121.08241120066468,0.07448804651209975
0.07794286020085811,112.1682783683,0.2474685811377245,45.22624983809856,120.91099480813133,0.07505446570243265
0.0785614234329077,111.962670646808,0.24943251939948194,45.143348804792986,120.75861742417106,0.0756281378752247
0.0791769400761261,111.74715815763,0.2513867847417004,45.05645416915642,120.59495620275406,0.07619865807389514
0.0798130517231464,111.58424626702,0.2534064392209898,44.99076809486247,120.49012548581797,0.07678792589620384
0.08044962774420321,111.461779587069,0.25542756808784517,44.941389529506225,120.42883826255515,0.07737727648354933
0.0810758987741567,111.307070450832,0.2574159786079475,44.87901080577546,120.33139122755158,0.07795674782431727
0.0817045727791964,111.193863157327,0.2594120185739486,44.83336562503425,120.27891024226481,0.07853810504574114
0.0823447928381104,110.997650559577,0.2614447172610005,44.75425270562145,120.13772910042235,0.07912979217429206
0.0829957684138122,110.810554430634,0.26351156471385373,44.678815546431636,120.00736154396505,0.07973106072942167
0.0836372141641246,110.628104511301,0.26554815497109563,44.60525173895657,119.88073098088384,0.08032317372152604
0.08428976682741261,110.481162532762,0.26762000967703503,44.54600473320964,119.79359396146997,0.08092517986722857
0.08493213504983761,110.31917328393,0.2696595287832344,44.48069066808058,119.68881620786718,0.08151743669503025
0.0855696882367285,110.134846955544,0.271683760151613,44.40637029247534,119.55905147352972,0.08210490748025329
0.0862024699665649,109.941581086444,0.27369284214384354,44.32844549405422,119.41881692812485,0.08268764056793265
0.0868301687998729,109.739585829827,0.2756857859395965,44.24700100658625,119.26829259145903,0.08326535747799489
0.0874534803128328,109.529823415513,0.2776647999932441,44.16242480113484,119.10858767124962,0.08383870634192009
0.08809821401251261,109.2997804643,0.2797118294897275,44.06967148320576,118.92889591516455,0.08443141459172745
0.08874306375677951,109.096321940713,0.2817592274277749,43.98763700649548,118.77786379432783,0.08502387833239136
0.0893872223783463,108.895690916852,0.2838044310512495,43.906742577674734,118.62957425688032,0.08561535685362306
0.09001751292225821,108.721744973613,0.2858056035281698,43.83660757336076,118.50860605670567,0.0861937630131354
0.09064755444000201,108.50419091151,0.28780598534700635,43.74888977552083,118.33983046412948,0.0867716064836478
0.091266696841692,108.271538547404,0.2897717624723721,43.655084342313295,118.1531242325935,0.08733912871138345
0.09188338651128221,107.967561915677,0.291729752173321,43.532520964400966,117.88798713785594,0.08790408271128959
0.09253583066504491,107.746289670997,0.29380126236151755,43.443303995346,117.71668208677927,0.08850144439720965
0.0931697955461907,107.567394677645,0.2958141008591555,43.37117353402647,117.58942684719759,0.0890815452958133
0.09380818262641141,107.387475315674,0.2978409798388562,43.29863004727976,117.461299211876,0.08966535281900195
0.0944311478931733,107.217552767591,0.2998188945608252,43.23011727589269,117.34222934973151,0.09023472864083577
0.09503175891243701,106.924379856613,0.3017258345469875,43.11190995818636,117.08559174500849,0.09078336642087047
0.0956545367292677,106.696890173796,0.3037031541154249,43.020186118074555,116.90293177382401,0.09135193512451986
0.096297016511698,106.406815660146,0.30574302742464116,42.90322807417087,116.65347454472828,0.09193815227870794
0.0969581511073934,106.156598001928,0.307842129765974,42.80234031437737,116.44934547204575,0.0925410320762628
0.09760097379165171,105.952410641663,0.30988309178849416,42.72001197071852,116.29346909586226,0.09312686518993898
0.0982485624719904,105.715875235631,0.3119391858485695,42.62464089500642,116.10230800800004,0.09371669494686787
0.0988823144572913,105.522369017434,0.31395134840189987,42.54661918782939,115.95666509289424,0.09429358548127494
0.09951550252108,105.251922975956,0.315961720504429,42.437575343905465,115.72612098221829,0.09486963052317576
0.1001513884087168,104.973522174341,0.31798065819767585,42.32532414069429,115.48676616625447,0.0954477961608659
0.10077734504835491,104.682769182566,0.3199680705285268,42.20809253441062,115.23242073309476,0.09601660754217038
0.1014172578396269,104.353248855959,0.32199979364081543,42.07522993872267,114.93646920158653,0.09659776672623471
0.1020614900807389,104.026621357361,0.324045231006346,41.94353373128796,114.64373334115807,0.09718250779539768
0.1026963002951009,103.727047108169,0.32606075343694535,41.822745394013744,114.37943108671361,0.09775836264410308
0.10332977224093591,103.414833567366,0.3280720268649715,41.69686089436197,114.10066476621623,0.09833267313946215
0.1039646208818499,103.150746246853,0.33008767129987343,41.590380886731126,113.87477447408698,0.09890790103873763
0.1046236852689799,102.77478026841,0.33218020072901117,41.43879140422291,113.5274565328007,0.09950472064957903
0.1052645023967889,102.431900227975,0.33421479510980473,41.300542171919524,113.21434323503031,0.1000846750104802
0.10589819290312191,102.128100364065,0.33622676246741207,41.17805006679101,112.94328163724816,0.1006578490469533
0.1065256835983899,101.81758154404,0.3382190454248879,41.05284887855692,112.66376902035366,0.10122509180613513
0.10715953300498991,101.537277134626,0.34023151729084294,40.9398301406812,112.41796433497076,0.10179775626553365
0.1078054441753619,101.118300400026,0.342282285256774,40.770898721290486,112.01940368890848,0.1023809810075368
0.10845111630896791,100.727271572514,0.34433229428097306,40.61323589803765,111.65125661730971,0.10296365014736969
0.1090732343662899,100.328380832447,0.3463075191129704,40.45240315164263,111.27152182857488,0.10352474258674166
0.1096852604432459,99.9734611390208,0.3482507019073057,40.30929953125319,110.93907626146702,0.1040764259663528
0.11030952368541891,99.586555365953,0.350232737701205,40.15329912355225,110.57190085384289,0.10463882661980514
0.1109410047574529,99.1641519898599,0.35223769010491296,39.98298608231151,110.16552264753572,0.10520740821918813
0.11160382294509491,98.6832445406819,0.3543421378506763,39.789084198802946,109.69667189204766,0.1058038580176627
0.11227011978561391,98.2146234725552,0.35645763031932415,39.60013618413426,109.24119101451795,0.1064030798059607
0.11293019612522691,97.8113258942939,0.3585533726975954,39.4375266005793,108.857178110805,0.10699635345800362
0.1135760384469069,97.4365810867212,0.3606039220689294,39.28642949416599,108.5030419663618,0.10757649316726244
0.1142002064390329,97.0463720361899,0.36258565544392946,39.129097204991766,108.12908775688196,0.10813684388461191
0.1148267800249009,96.5520519662513,0.3645750265790603,38.92978735279252,107.63881319833284,0.10869903860560556
0.1154728031971879,96.0551245670006,0.3666261501510716,38.72942622541465,107.14687906220723,0.10927835377493456
0.1161354031667489,95.4945574037658,0.36872990505442776,38.50340554519837,106.5848563280824,0.1098721856018143
0.11680024448496791,94.9688653336259,0.3708407762397731,38.291446502517964,106.06125202305338,0.11046767194157008
0.11748527893093391,94.4626839171583,0.3730157606057152,38.08735415539823,105.56065868573029,0.1110808742026528
0.11815583100938791,93.9574911278802,0.3751447634548066,37.8836604227613,105.05911657165208,0.11168074874922532
0.11882962377157591,93.4426536338964,0.37728405547475347,37.67607794518703,104.54640900943,0.11228316016064024
0.1194796741052129,92.8710263572411,0.37934796528405096,37.44559782723962,103.9672263202209,0.1128640006660426
0.12015190442026591,92.2728816961899,0.38148229653434423,37.20442589990377,103.35964415833301,0.11346430505689513
0.1208288917997659,91.6506780520867,0.3836317314642567,36.953553390601364,102.72472791381747,0.11406849354546776
0.1214892991299749,91.0299340367007,0.3857285247376703,36.70326940359772,102.08909692266731,0.11465753336325578
0.12213423380201291,90.3947463484472,0.387776192321391,36.44716172769391,101.4350394334421,0.11523243791416182
0.1227463343015929,89.75705876353,0.38971961140755745,36.190046093455294,100.77440870444596,0.1157777680519395
0.12338624235619991,89.0690919458612,0.39175131948093467,35.91265787257124,100.05899251113989,0.11634755460734561
0.12403711697320291,88.3849281766305,0.39381784638991923,35.63680304081742,99.34793985154334,0.1169267731444299
0.1246830691886939,87.7226385953646,0.3958687446741031,35.36976788165101,98.66016641276524,0.11750127969018243
0.12533338502888092,87.02506791118,0.3979334974666969,35.08850738178778,97.93221425485643,0.11807933400358653