File: example/data/02 processed data/test_ID_125.csv
Strain,Stress_MPa,Displacement(mm),Force(kN),True Stress (MPa),True Strain
0.0005139275507933,0.186586857639528,-0.0003028718459999,0.0376159105001288,0.1865690586140122,-9.539725757523762e-05
0.000485736621195,0.188764862656211,-0.0003923780474746,0.0380549963114921,0.1887415344079461,-0.0001235912740868
0.0004628644935992,0.184009741589485,-0.0004649970525913,0.0370963639044401,0.1839827923020874,-0.0001464664902884
0.0004436892458843,0.171629017053201,-0.0005258784640861,0.0346004098379253,0.1716005899653646,-0.0001656447306415
0.0003856173694114,0.180348227077576,-0.0007102566718876,0.0363582025788393,0.1803078826581917,-0.0002237279140069
0.0003437165121278,0.405589036674557,-0.000843291893763,0.0817667497935906,0.4054813107070524,-0.000265639024989
0.0003252346926665,0.859568507754168,-0.0009019716705526,0.1732890111632403,0.8593243167485323,-0.0002841259254766
0.0003142774535391,1.46044227542051,-0.0009367609047821,0.2944251627247748,1.460011382435532,-0.0002950863383471
0.0003123878483161,2.3691502489673,-0.0009427604013651,0.4776206901918077,2.368446771474509,-0.0002969765030355
0.000314145305338,3.55426418753037,-0.0009371804753206,0.7165396602061226,3.553215057766375,-0.0002952185255579
0.0003222334240397,5.0741608253326,-0.0009115006984427,1.022950822387052,5.07270410056526,-0.0002871280514692
0.0003628881587817,6.81884602343444,-0.0007824219156369,1.3746793583243833,6.817165640893309,-0.0002464624687924
0.0004052916904493,8.64059852792744,-0.0006477907025922,1.7419446632301716,8.638835598985322,-0.0002040493844053
0.0004365265265967,10.614136663923,-0.0005486200978242,2.139809951446877,10.612302607641148,-0.0001728086621549
0.0004743230894992,12.7864093642647,-0.0004286160106088,2.5777401278357632,12.78468323520274,-0.0001350062816336
0.00050896901164,14.9374076755378,-0.0003186152078118,3.0113813873884205,14.93590868805726,-0.0001003562820781
0.0005570162441912,17.2164559749972,-0.0001660652444615,3.470837524559436,17.215555485242792,-5.230538190621761e-05
0.000606047569621,19.498957297293,-1.0390786221871958e-05,3.930989791134269,19.49889348327825,-3.2726939290646264e-06
0.0006486368110191,21.9068394281588,0.0001248300552169,4.416418828716815,21.90770072956839,3.9315779948892606e-05
0.0006948681300289,24.3064722606546,0.000271614493073,4.900184807747968,24.30855162762829,8.554421282350424e-05
0.0007378845291777,26.6913693983741,0.0004081915603703,5.380980070712219,26.69480095482233,0.0001285560073051
0.0007741149766815,29.0976280348809,0.0005232232311949,5.866081811831989,29.10242317030153,0.0001647811413286
0.000821531066651,31.5095629714517,0.0006737693168481,6.352327895044663,31.51624964128397,0.0002121882949275
0.0008646838582309,33.8523672025569,0.0008107794301142,6.824637228035471,33.86101186491548,0.0002553310003016
0.0009197558137733,36.1934915063097,0.0009856328889614,7.296607887672035,36.20472725295378,0.0003103873804311
0.0009610433605306,38.4661966475517,0.0011167208499158,7.754785244146423,38.47972609757164,0.0003516612622653
0.0009925533550538,40.8226276595023,0.001216765082527,8.229841736155665,40.838272241522176,0.0003831596818118
0.0010367696121774,43.0830030170953,0.0013571516988944,8.685533408246412,43.10141881890258,0.0004273580235324
0.0010831585479866,45.2309048543456,0.0015044365700886,9.118550418636074,45.25233698894752,0.0004737260638792
0.0011229982093415,47.3625404782615,0.0016309274948904,9.54828816041752,47.38686957101547,0.0005135460637909
0.0011664866360809,49.4395531637403,0.001769003249788,9.967013917810045,49.46709922050085,0.0005570112183301
0.0012064929815029,51.5259789398413,0.0018960233965028,10.387637354272004,51.55674884900592,0.0005969944866325
0.001247513514182,53.6157475654198,0.002026263587759,10.808934709188632,53.64996477393076,0.000637989697273
0.0012969753549084,55.5999118529696,0.0021833049320653,11.208942229558671,55.63814541573211,0.0006874187702819
0.0013439668094117,57.5875150270592,0.0023325028001133,11.609643029455135,57.62982149636697,0.0007343768305306
0.0013935487087272,59.6097084366486,0.00248992533044,12.01731722082836,59.656456065932566,0.0007839211040771
0.0014553973109776,61.6908494175794,0.002686294642585,12.436875242584009,61.74304462963829,0.0008457193313521
0.001501315012343,63.7421425539308,0.0028320833444202,12.85041593887245,63.79900021070706,0.0008915971632425
0.0015409852114082,65.7340728932772,0.0029580362264522,13.251989095284683,65.79531502522384,0.0009312312227942
0.0015896280539061,67.7438657736245,0.003112477251383,13.657163339962702,67.810275613354,0.0009798276078196
0.0016416111657892,69.7880495388403,0.0032775236316119,14.069270787030206,69.86009110783799,0.0010317584617299
0.0016891934960451,71.8014437609451,0.0034285975301743,14.475171062206536,71.87898021850157,0.0010792905941618
0.0017365008355107,73.825329022382,0.0035787983329776,14.88318633091221,73.90854349936997,0.0011265457862602
0.0017789028800473,75.7931388809781,0.0037134248243813,15.279896798405186,75.88178521906893,0.0011688991929301
0.0018240332515928,77.8229727665322,0.0038567137540383,15.689111309732892,77.91750534273656,0.0012139758264735
0.0018633304455475,79.8223965611536,0.0039814823448445,16.092195146728567,79.92249465962018,0.0012532245732877
0.0019097045047554,81.7919605867005,0.0041287199828295,16.48925925427882,81.89832156374274,0.0012995394792348
0.0019568636674186,83.7031982686327,0.0042784503242852,16.874564770956354,83.81599196179053,0.0013466362874362
0.0019998378285367,85.5995527222173,0.0044148932858352,17.256869828799008,85.71858040429093,0.001389551696058
0.0020411314767103,87.5028968532155,0.0045460006187863,17.640584005608247,87.62818448258254,0.0014307871542273
0.0020830666566823,89.3818601039053,0.0046791448151974,18.01938299694731,89.51358629832352,0.001472661500043
0.0021313390744062,91.1965105458242,0.0048324097414708,18.38521652603816,91.33531335084776,0.001520861719506
0.0021920181292827,92.9879039910945,0.0050250657407037,18.74636144460465,93.13507574877812,0.0015814467247626
0.0022474365245629,94.7858175387026,0.0052010191457183,19.10882081580245,94.94108772823373,0.0016367760173729
0.002293233297634,96.5715748970247,0.0053464239002191,19.46882949924018,96.73419303123296,0.0016824968474833
0.0023443606367401,98.3776840186648,0.005508753201881,19.832941098162824,98.54837327278494,0.0017335369347602
0.0024023353542151,100.097560384922,0.0056928229298641,20.17966817360028,100.27703682176696,0.0017914095633292
0.0024551056258967,101.839701818964,0.0058603685424532,20.53088388670314,102.02767605043256,0.0018440839991424
0.0025093405675951,103.586502028213,0.0060325644823456,20.88303880888774,103.78331848584634,0.0018982175539655
0.0025554942567575,105.329052629505,0.0061791024454362,21.23433701010821,105.53404129302578,0.0019442826554705
0.0025995931524224,107.020758562211,0.0063191164391723,21.575384926141737,107.23375907709703,0.0019882949251615
0.0026603878112227,108.700371245808,0.0065121394808632,21.91399484315489,108.92332305027236,0.0020489669857541
0.0027209866802613,110.394109856151,0.0067045408900608,22.25545254700004,110.62722539112816,0.0021094399883
0.0027762886502876,112.038827107695,0.0068801246448943,22.58702754491131,112.28161170472453,0.0021646239024322
0.0028454983445959,113.654655715274,0.0070998654243231,22.91277859219924,113.90880776580197,0.0022336815612745
0.0029166158954365,115.254894504062,0.007325663648242,23.23538673201889,115.52082161932196,0.0023046379179737
0.0029922990516131,116.827287304935,0.0075659576691027,23.55238112067489,117.10568425307524,0.0023801440020585
0.0030814060514968,118.33626926328,0.0078488723937335,23.85659188347725,118.6288066733581,0.0024690352157091
0.0031714228958427,119.835809842381,0.0081346758745317,24.15889926422401,120.14284148686284,0.0025588260481307
0.003271096152226,121.282219663711,0.0084511384635487,24.45049548420414,121.60504575238645,0.0026582396423257
0.0033871487912409,122.739166299047,0.008819605592421,24.744215925887875,123.08011465731477,0.0027739774973958
0.0035003255616565,124.09640809604,0.0091789418384905,25.017835872161665,124.45517146998618,0.0028868343844615
0.0036286176259806,125.402839234902,0.0095862691427195,25.28121238975624,125.78146769731678,0.0030147484435579
0.003771843743793,126.629468206867,0.0100410120667739,25.528500790504385,127.02993687404002,0.0031575332266389
0.0039139661999428,127.765844378051,0.0104922508650495,25.757594226615083,128.18806525716892,0.0032991975992765
0.0040715490684906,128.787850264855,0.0109925764726888,25.963630613394766,129.23374327045804,0.0034562490942502
0.0042374300712399,129.699050489926,0.0115192486564178,26.147328578769084,130.16961288775113,0.0036215440986004
0.0044104458409987,130.530480346754,0.012068573725402,26.314944837905607,131.0266430949357,0.0037939195598486
0.0045909907160744,131.232754779443,0.0126418037037674,26.456523363535712,131.75528036225447,0.0039737645868289
0.0047797599127725,131.762225279708,0.0132411459032838,26.563264616389134,132.31173168898988,0.0041617674739644
0.0049750240502245,132.200573917504,0.0138611095396939,26.651635701768807,132.7777224643641,0.0043562017525848
0.0051793153027732,132.57308623201,0.0145097342665361,26.726734184373218,133.17894457913476,0.0045595843231383
0.0053747159886744,132.863357724214,0.0151301314442724,26.785252917201547,133.49650420185014,0.0047540771762619
0.0055685553369961,133.05707108243,0.0157455713751938,26.824305530217888,133.71693237682456,0.0049469785777288
0.005766722376479,133.138035599098,0.016374751725552,26.84062797677816,133.82468198592096,0.0051441482707285
0.0059665637733084,133.23456893847,0.0170092481604853,26.86008909799555,133.94833896890455,0.0053429445320953
0.0061537591844465,133.305024448927,0.0176035935908488,26.87429292890369,134.04412601554657,0.0055291251030435
0.0063496943952287,133.309917226322,0.0182256878850823,26.87527931282652,134.07516602737812,0.0057239609712701
0.0065463840557183,133.289526195513,0.0188501775571367,26.87116848101542,134.0808746160774,0.0059195088830847
0.0067463492585698,133.269012281501,0.0194850670761903,26.867032875950603,134.08688807472387,0.0061182741315669
0.0069602823721117,133.22160855098,0.0201643047116858,26.857476283877567,134.06769393964234,0.0063308797374561
0.0071691930922327,133.14757362445,0.02082759624807,26.84255084268912,134.02100477558704,0.0065384505023841
0.0073725486563391,133.021365089236,0.0214732501641078,26.81710720198998,133.92101896316746,0.0067404603682359
0.007590766544971,132.907324651776,0.0221660919605141,26.79411664979804,133.8352099999515,0.006957188826644
0.0078059465922558,132.831703575073,0.0228492886106433,26.778871440734715,133.7876437110195,0.0071708541932055
0.0080200791647312,132.788825895641,0.0235291595282527,26.770227300561224,133.7728918698356,0.0073834341478414
0.0082347130484568,132.702275057558,0.0242106221090815,26.75277865160369,133.71418202903325,0.0075964664394523
0.0084490659649794,132.635112182273,0.0248911926190407,26.739238615946235,133.67493773357285,0.0078091745763845
0.0086743938313378,132.585088076017,0.0256066085947287,26.72915375612503,133.6543965660517,0.0080327246816691
0.0088998015317473,132.513683382165,0.0263222780435288,26.714758569844463,133.6122855927343,0.0082563040011068
0.0091259964868349,132.457818917872,0.027040447025932,26.703496293843,133.58591927554733,0.0084806139508156
0.0093447267564145,132.380795462849,0.0277349156318472,26.68796836531036,133.53719552377467,0.0086974735811116
0.0095711006116542,132.26149694814,0.0284536526222332,26.663917784745028,133.446795433009,0.0089218619161548
0.0097888996318252,132.169626358806,0.0291451645112762,26.645396673935288,133.3828879347497,0.0091377031107933
0.0100099716770899,132.068166071308,0.0298470682549916,26.62494227997569,133.3096928640771,0.0093567402763973
0.0102221748881491,131.983165145115,0.0305208134501045,26.607806093255185,133.2519001252562,0.0095669451226797
0.0104490278025955,131.920623059752,0.0312410714534719,26.595197608846004,133.21868340973506,0.0097916128565496