File: example/data/02 processed data/test_ID_086.csv
Strain,Stress_MPa,Displacement(mm),Force(kN),True Stress (MPa),True Strain
0.0008960826996215404,55.4581964877506,0.0028450625712983903,22.36074482386104,55.507891618175485,0.0008956814571990275
0.0010042444951574403,62.2896618685079,0.0031884762721248725,25.115191665382387,62.352215918544566,0.0010037405789962333
0.0011195719767681405,69.3117261365403,0.003554641026238846,27.94648797825305,69.3893256027842,0.0011189457234426579
0.0012276483563402403,76.3850119556188,0.003897783531380263,30.7984368205055,76.47878588999514,0.0012268954122675484
0.0013393923177637405,83.5102792894087,0.004252570608899876,33.67134460948959,83.62213231594325,0.0013384961320136524
0.0014577179486101404,90.6659451698135,0.004628254486837196,36.5565090924688,90.79811054541524,0.0014566565091956257
0.0015697815759281404,97.8029159440501,0.004984056503571845,39.434135708641,97.95644515957112,0.0015685507567398998
0.0016857172213139405,104.973021134097,0.005352152177671761,42.3251221212679,105.14997596359608,0.0016842979947579613
0.0018031037628823403,112.145710200606,0.00572485444715143,45.21715035288434,112.34792055265983,0.0018014801227272251
0.0019178938460023404,119.279337134715,0.00608931296105743,48.09342873271709,119.5081022413609,0.001916057035763071
0.00203609439687404,126.391533093461,0.006464599710075077,50.96106614328348,126.64887818580492,0.0020340243660533913
0.0021568177214288404,133.484577967839,0.006847896265536568,53.82098183663268,133.77247987113748,0.0021544951290930897
0.0022759013175921404,140.54464041914,0.0072259866833550455,56.66759901699725,140.86450615145043,0.0022733153770089203
0.0023957377487258402,147.537826067888,0.007606467352204542,59.487251470572446,147.89128800716378,0.0023928725443186022
0.0025154217502052403,154.515812443329,0.007986464056901637,62.300775577150254,154.90448487869958,0.0025122633722408872
0.0026362371187980405,161.390443760279,0.008370052852183778,65.0726269241445,161.81590723873913,0.002632768340735001
0.0027597465240176405,168.242276167269,0.008762195213756008,67.83528575064287,168.70658220411445,0.002755945415370869
0.0028796313059321404,175.046990827005,0.009142829396334545,70.57894670144843,175.55106162179965,0.002875493110118339
0.0030017163937660404,181.758989919566,0.009530449550207178,73.28522473556902,182.30457885932194,0.002997220238320435
0.0031239407419692404,188.413231773558,0.009918511855752337,75.96821505109858,189.00182354462152,0.0031190713775245643
0.0032469779749873403,194.985397551691,0.010309155070584804,78.61811229284181,195.61851084298547,0.003241717925104118
0.0033730054102677405,201.528684710539,0.010709292177600076,81.25636567528933,202.20844205439178,0.0033673295869928177
0.0034938662857344404,207.947337828267,0.011093025457206848,83.84436661235726,208.6738780211134,0.003487776914433913
0.0036185642497623405,214.245916686866,0.01148894149299543,86.38395360814437,215.02117930164667,0.003612032997243475
0.0037448420018822404,220.435060777651,0.011889873355976112,88.87941650554889,221.2605552519386,0.0037378475377428375
0.0038710012536917406,226.526929519269,0.012290428980471276,91.33565798216927,227.40381554743306,0.00386352820757763
0.00399664053431144,232.450086327174,0.01268933369643882,93.72387480711656,233.3791057643934,0.003988675182576242
0.004130474078345341,238.225810183997,0.013114255198746457,96.0526466661876,239.20979571775484,0.004121967087514162
0.004263278478999941,243.752265958579,0.013535909170824811,98.28091363449904,244.7914497482477,0.004254216454132645
0.004408297233874141,249.182966311323,0.013996343717550395,100.47057201672544,250.28143889244177,0.004398609153147818
0.004562533969371141,254.344639526526,0.014486045352753373,102.55175865709529,255.50509558429323,0.004552157162311922
0.004730455441059241,259.217526548888,0.015019196025363089,104.51650670451163,260.44374350776906,0.004719301996802492
0.004919837915681241,263.716511447888,0.015620485382287939,106.33049741578846,265.0139539399005,0.004907775061801523
0.00513742403362844,267.794476476271,0.016311321306770297,107.97473291523245,269.1702502557931,0.005124272494900582
0.00537845809973804,271.361745921525,0.017076604466668276,109.41305595555889,272.8212537018357,0.005364045848005024
0.00565262476203624,274.38032160038,0.01794708361946506,110.63014566927323,275.9312906004738,0.005636708629135905
0.005954441365562141,276.795486128931,0.018905351335659796,111.60394000718497,278.44364862133796,0.005936783739104134
0.00627953956248644,278.695395292359,0.019937538110894448,112.36998338187915,280.44547405298016,0.006259905406697584
0.006626237655091641,280.111967564612,0.021038304554915958,112.94114532205154,281.9680560317304,0.006604380642406661
0.00698733853171064,281.127279021548,0.02218479983818128,113.35051890148816,283.0916104905703,0.006963040203268219
0.007357527533052341,281.84772457632,0.023360149917441182,113.64100254917223,283.92142697001844,0.007330592961235062
0.00773383277200344,282.376659287419,0.02455491905111092,113.85426902468733,284.56051314906483,0.007704079990893394
0.00811909932465824,282.800719012696,0.025778140355789913,114.02524990591903,285.0968061394448,0.008086316761454812
0.00850486889222374,283.162461717413,0.027002958732810372,114.17110456446093,285.57072132951896,0.008468906255927802
0.00889291970044864,283.489246093523,0.028235020048924427,114.30286402490847,286.01029319497337,0.008853610566802825
0.00928324673721984,283.779552213695,0.029474308390672988,114.41991545256184,286.4139478158725,0.009240422231839124
0.00967370685160754,284.069858333866,0.03071401925385394,114.53696688021479,286.8178668687655,0.009627216134068263
0.01006642719333844,284.317606488778,0.03196090633884954,114.63685893627527,287.1796689742815,0.010016098188804294
0.01045663081067214,284.575994135004,0.033199802823884045,114.74104083523362,287.5517002432538,0.010402338395902122
0.01084338062158634,284.8131027986,0.03442773347353663,114.83664304839553,287.90143967826026,0.01078501272771477
0.01122969714293254,285.069970517495,0.03565428842881081,114.940212112654,288.2712199509512,0.011167112198099407
0.01161558592309854,285.30555925376,0.03687948530583786,115.03520149111604,288.61955049160974,0.01154864289456682
0.01199987793364574,285.55026755401,0.03809961243932522,115.13386787777685,288.976835908578,0.011928450246339307
0.01238476556743324,285.785856290275,0.039321630676600536,115.22885725623888,289.3252471229182,0.01230870173625329
0.01276870091187194,286.026004808533,0.04054062539519341,115.32568513880051,289.6781853169508,0.012687868407217796
0.01315550543286614,286.358868893965,0.04176872974934999,115.45989593804669,290.1260645494489,0.013069723290517732
0.01353602137638974,286.498702208394,0.04297686787003742,115.51627673042445,290.3767547657947,0.013445227843589978
0.01391662730419074,286.711492034698,0.044185291690805595,115.60207358839023,290.7015490131733,0.013820680195110544
0.01429612645861394,286.909082587694,0.04539020150609926,115.68174209935822,291.01077111449257,0.01419490046184339
0.01467176594315584,287.129472050652,0.04658285686951979,115.77060313082289,291.3421684599611,0.014565176886857852
0.01504716984820494,287.345301731618,0.04777476426805068,115.8576256581884,291.6690352918573,0.01493508417077763
0.015414122198967239,287.570250976567,0.04893983798172098,115.94832519375183,292.0028939659075,0.015296531449969425
0.01577798327295904,287.675125962389,0.05009509689164495,115.99061078803526,292.21405928787,0.015654804876597712
0.01614433033615634,287.979111428537,0.051258248817296376,116.11317772798613,292.62834133335207,0.016015396484567443
0.01650578456065734,288.197980964164,0.05240586598008705,116.20142592475094,292.9549147487749,0.01637104473476244
0.01686468763666504,288.465488174375,0.0535453832464115,116.30928483190802,293.3303685263939,0.016724057709665063
0.01722150249015564,288.676758073348,0.05467827040624416,116.39446885517393,293.64820558135824,0.017074893243461547
0.01757366634311164,288.853069643714,0.05579639063937946,116.46555768034548,293.9292771118162,0.017421035068315705
0.01792599168265684,289.059779760696,0.056915023592435464,116.54890319951265,294.24146296847687,0.017767215763237088
0.01827788056037364,289.27408951433,0.0580322707791863,116.63531289217786,294.5614067716837,0.018112848031220378
0.01862852953868634,289.492959049957,0.059145581285329124,116.72356108894266,294.88578718886083,0.01845714365524905
0.01898041203111494,289.555276070518,0.06026280819878993,116.74868731163286,295.0511545161197,0.01880253131894439
0.01933164214499404,289.742227132199,0.061377963810356075,116.82406597970262,295.3434201814122,0.019147159725213893
0.01968831198488004,289.958056813165,0.06251039055199412,116.91108850706813,295.6668414982322,0.01949700411276036
0.02004898842709254,290.189085767438,0.0636555382560188,117.004239381431,296.00708338965785,0.019850654012576997
0.02041523697590634,290.407955303065,0.06481837739850263,117.09248757819581,296.3367025302655,0.020209639529879787
0.02077188553878684,290.620745129369,0.0659507365856482,117.17828443616159,296.6574859823932,0.020559091633095633
0.02112924821271884,290.832015028342,0.0670853630753823,117.26346845942751,296.97707686208105,0.02090912099707768
0.02148860970980614,291.149679840467,0.0682263358286345,117.39155091167629,297.4060816776938,0.02126098466007387
0.02184942177748714,291.350310248125,0.06937191414352167,117.47244509204403,297.7161460617381,0.02161414411374339
0.02220890293526084,291.628456949651,0.07051326681945316,117.5845938420993,298.10520504320573,0.0219658768966426
0.02256357926755454,291.845806557947,0.07163936417448566,117.67222920416424,298.4308925481206,0.02231278721447768
0.02291470786010744,292.031237692298,0.07275419745584112,117.74699503753456,298.7230481900427,0.022656108967841353
0.02327338495389234,292.224268463302,0.07389299722860818,117.82482504440337,299.025316356118,0.023006689736753252
0.02362892924921374,292.409699597653,0.07502185036625363,117.8995908777737,299.3190277012298,0.02335408716400715
0.02397875437046484,292.616409714634,0.07613254512622586,117.98293639694045,299.63298672794855,0.023695778716986894
0.02432303820437734,292.797281066993,0.07722564629889805,118.05586372621157,299.91900052052324,0.024031943864527887
0.02466574074332934,292.920395180783,0.07831372686007065,118.10550333689169,300.14549370674575,0.024366452814180175
0.02500551043778914,292.958393364051,0.07939249563998052,118.12082420438537,300.2839675271537,0.024697988612788074
0.02534442956952624,293.063268349873,0.0804685638832458,118.1631097986688,300.49078971398154,0.02502858499364072
0.02568306787393694,293.206141518962,0.08154374049974979,118.22071626044549,300.73657475264866,0.025358798321263146
0.02602281161324834,293.394612507975,0.08262242687206348,118.29670776321552,301.0295652376121,0.025689980042594034
0.02636501374472484,293.58916320631,0.08370891863950136,118.3751506047842,301.3296455295466,0.026023447363360184
0.02671093700849354,293.782193977314,0.08480722500196698,118.45298061165302,301.6293916548591,0.026360427850531297
0.02705467321888344,293.940266419711,0.08589858746995492,118.51671542042749,301.8927242735678,0.026695165380352458
0.02740028161996324,294.250331595183,0.08699589414338328,118.64173369917779,302.31287354765857,0.027031613160359434
0.02774635533005214,294.508719241409,0.08809467817291554,118.74591559813611,302.6802628132797,0.02736840052836313
0.02809358693786774,294.716949285721,0.08919713852773006,118.82987395200271,302.99660552254255,0.027706200766580594
0.02844040797020034,294.868942018795,0.09029829530538608,118.89115742197815,303.25513502755086,0.02804348771294684
0.02878644083088104,295.055893080476,0.0913969496380473,118.96653609004792,303.5495020884399,0.028379894817633262
0.02913436660972314,295.223085086858,0.09250161398587096,119.03394790702116,303.82422267943207,0.028718028122762546
0.02948080730521094,295.396356802563,0.09360156319404474,119.1038110627934,304.10487987612066,0.029054604577796916
0.02983050367594844,295.589387573567,0.0947118491711363,119.18164106966222,304.4069678861517,0.029394229162223996
0.03017771421566604,295.776338635249,0.09581424263473967,119.25701973773239,304.7021924543396,0.0297313254320251
0.03052677428218124,295.954170132946,0.09692250834592543,119.32872139760383,304.98869628246473,0.030070102847032498
0.03087059636479894,296.169999813911,0.09801414345823663,119.41574392496891,305.31294433352883,0.03040368441718664
0.03121351785359524,296.343271529616,0.09910291918516488,119.48560708074118,305.5931875262985,0.030736281414169363
0.03155254884941364,296.448146515437,0.10017934259688831,119.52789267502419,305.80184113968346,0.03106499634151265
0.03189472113303635,296.622938158473,0.1012657395973904,119.59836866549631,306.08364405269936,0.03139664744957495
0.032234934371385346,296.782530528201,0.10234591662914846,119.66271630897064,306.3492959223512,0.031726290735811846
0.03257432726406304,296.974041371874,0.10342348906340015,119.73993348113962,306.64777098445285,0.03205503092701528
0.03291370425055564,297.159472506225,0.10450101099551415,119.81469931450991,306.940091499546,0.032383647684283805
0.03325331541540704,297.300825747984,0.10557927644391735,119.87169294158716,307.1870638798427,0.032712383129847915
0.03359461757281904,297.474097463689,0.10666291079370045,119.94155609735941,307.46762600580115,0.033042646576003545
0.03393875919626854,297.709686199954,0.10775556044815261,120.03654547582144,307.8135835502909,0.03337554724933202
0.03428308091291314,297.846479659721,0.10884878189849921,120.0917005987995,308.05757462152155,0.03370851126039525
0.03462872393629864,298.012151738772,0.10994619849774818,120.15849958107287,308.3319322709962,0.034042641527128756
0.03497582221936774,298.153504980531,0.11104823554649258,120.21549320815011,308.5816689648114,0.03437806626995529
0.035322055691581346,298.310057495597,0.11214752682077077,120.27861518222471,308.8469819598153,0.03471254323497156
0.03567095081061254,298.48028935664,0.11325526882369481,120.34725266859725,309.1273650762181,0.035049478339277976
0.036020727762031544,298.630762162384,0.11436581064445014,120.40792330387322,309.38765954760316,0.03538715112945248
0.03636346902947294,298.791874459443,0.11545401416857658,120.47288378204743,309.65698353260717,0.03571792113927695
0.03670697819504654,298.978825521124,0.11654465576927277,120.5482624501172,309.9534347503086,0.03604932248569763
0.03704912721172694,299.136897963521,0.11763097889723304,120.61199725889166,310.2196589498929,0.03637930248565322
0.037391623283760646,299.29801026058,0.11871840392594005,120.67695773706586,310.4892487098227,0.03670950818091228
0.037731930309483346,299.4621624123,0.11979887873260961,120.74314388463938,310.7614478547681,0.037037495425993966
0.03807275179209414,299.582236671429,0.12088098693989889,120.79155782592015,310.9881568095407,0.037365870719307546
0.038410866066476444,299.72814969518,0.1219544997610627,120.85038995709658,311.24096750947433,0.03769153115261165
0.038752907330668045,299.810225771041,0.12304048077487104,120.88348303088375,311.42874366713284,0.03802086605789339
0.039093139287960245,299.902941338216,0.12412071723927377,120.9208659475687,311.62708879681986,0.03834835130242022
0.039434611473599245,299.969818140769,0.1252048914286776,120.94783067435807,311.79901137295644,0.038676922512100656
0.03977549249908744,300.07469312659,0.12628718868460262,120.99011626864109,312.0103118322126,0.039004817252407044
0.04011665569218054,300.175008330419,0.1273703818226732,121.03056335882495,312.21702578700786,0.039332875797605756
0.040457039449866346,300.247964842294,0.12845110025332565,121.05997942441294,312.39510860066076,0.03966007762805996
0.04079756849195934,300.302682226201,0.1295322799619709,121.08204147360425,312.5543014726435,0.039987312021999184
0.041139933650069946,300.428836194653,0.13061928933897207,121.1329067536841,312.7884585822688,0.040316202933320555
0.04148592231817074,300.559549945097,0.1317178033601921,121.18561053786311,313.02854008610365,0.04064846489030365
0.04183158576584344,300.719142314825,0.1328152848065529,121.24995818133743,313.2987009079984,0.0409803043238065
0.04217685861958114,300.845296283276,0.1339115261171701,121.3008234614169,313.53400581098174,0.04131165888988535
0.04252318556221464,300.980569815713,0.13501111416003148,121.35536574969548,313.77922243660765,0.04164391479095463
0.042871621650007546,301.197919424009,0.13611739873877396,121.44300111176042,314.1107626673246,0.041978082776633306
0.043221085779853244,301.410709250313,0.13722694735103405,121.5287979697262,314.43800736978716,0.04231312458169784
0.043571472336662545,301.612859585302,0.13833942466890356,121.61030498479377,314.7545759531046,0.04264893808528665
0.04391988104698534,301.799810646983,0.13944562232417845,121.68568365286356,315.05482243060123,0.04298274422344704
0.044265486005988244,301.971562435357,0.14054291806901267,121.75493397393593,315.3384804065457,0.04331375407306232
0.04461362769667594,302.128114950423,0.1416482679369461,121.81805594801057,315.60714618751973,0.04364708278665551
0.044960034487783344,302.267948264852,0.1427481094987121,121.87443674038833,315.8579256433913,0.04397864017613626
0.045305779887982546,302.388022523981,0.1438458511443446,121.92285068166916,316.0879477132148,0.0443094549471328
0.04564926760713824,302.497457291794,0.1449364246526639,121.96697478005133,316.30624467018595,0.044638001199389106
0.045990144852745544,302.603852204946,0.1460187099074671,122.00987320903424,316.5206472008503,0.04496394385144904
0.04633149474163405,302.710247118098,0.1471024958046881,122.05277163801712,316.73526534068884,0.04529023201427958
0.046673965266147144,302.818161958581,0.14818983972001717,122.09628290169987,316.95188633179436,0.04561748441195684
0.04701291639416334,302.926076799064,0.1492660095514686,122.13979416538261,317.1675151212303,0.04594126838743695
0.047354744789362746,303.037031494208,0.1503513147062267,122.18453109846467,317.38727278234234,0.046267694739953846
0.047700744994228245,303.147986189352,0.15144986535667468,122.22926803154675,317.6083709740841,0.04659799645243675
0.04804987115600514,303.260460811827,0.1525583409203163,122.27461779932865,317.832086880546,0.04693117174754688
0.04840331289632134,303.371415506971,0.15368051844582026,122.3193547324107,318.0555970555548,0.04726835241664397
0.048751470552266744,303.482370202115,0.1547859190034469,122.36409166549278,318.27758203615554,0.04760038099354415
0.04910122266868174,303.59332489726,0.15589638197306452,122.40882859857524,318.5001283437658,0.04793381919994039
0.04945479302268645,303.704279592404,0.15701896784702946,122.4535655316573,318.72391187975046,0.048270784574899694
0.049808488586072744,303.815234287548,0.15814195126078096,122.49830246473935,318.9478119168343,0.04860775571123287
0.050160816847468745,303.926188982692,0.15926059349071325,122.54303939782142,319.171374883402,0.048943311344155964
0.05051021142978864,304.037143677837,0.16036992128957892,122.58777633090388,319.39412408751355,0.049275961798071435
0.050856713016307745,304.148098372981,0.1614700638267771,122.63251326398596,319.61607092639144,0.049605748648362646
0.05120515057889234,304.260572995456,0.16257635308798318,122.67786303176787,319.84028145090844,0.049937268449763685
0.05155820968161874,304.3715276906,0.16369731573913948,122.7225999648499,320.0643787363866,0.050273073336529736
0.051911514805195645,304.484002313075,0.16481905950649617,122.76794973263185,320.2902281070954,0.050608999376050484
0.05225819049579644,304.594957008219,0.1659197548241537,122.8126866657139,320.5125382956134,0.0509385124308808
0.05260208561868524,304.705911703364,0.16701162183932564,122.85742359879636,320.7340781593039,0.05126527533277151
0.052948999889368145,304.816866398508,0.16811307464874384,122.90216053187844,320.95661462372016,0.0515947988254189
0.053297350702819046,304.927821093652,0.16921908848145045,122.9468974649605,321.1796661135268,0.051925577622048295
0.05365163134319215,305.038775788796,0.17034392951463506,122.99163439804255,321.40460373279507,0.05226187493795963
0.05400235783941544,305.149730483941,0.17145748614014403,123.03637133112503,321.62853542413603,0.05259468715596209
0.054348266934189246,305.274364525061,0.17255574751605085,123.08662377650461,321.865497176434,0.052922819577403676
0.054702642154463445,305.272844597731,0.17368088884042143,123.08601094180514,321.9720757752358,0.05325887142146492
0.05505701125314334,305.321482272314,0.17480601072873012,123.10562165219699,322.1315705576072,0.053594804570475746
0.05541184857067144,305.367080092237,0.1759326192118818,123.12400669318997,322.28803449277615,0.05393106854254982
0.055765208690172846,305.433956894789,0.17705453759129877,123.15097141997893,322.46654524209214,0.05426582030729248
0.05611560129830025,305.494753988019,0.17816703412210327,123.17548480796927,322.637775801533,0.054597650218985744
0.056464167163538845,305.563150717903,0.17927373074423583,123.2030623694585,322.8165195390563,0.05492764094748309
0.056818128080692844,305.567710499895,0.18039755665619978,123.20490087355766,322.9294958124021,0.05526262782667142
0.05716961062364204,305.734902506277,0.18151351373006347,123.2723126905309,323.21364783661807,0.05559515818127376
0.05752707390077654,305.845857201421,0.1826484596349655,123.31704962361295,323.44027443089345,0.05593323340800014
0.05788452875173784,305.950732187242,0.18378337878676765,123.35933521789599,323.66054614114967,0.05627118641337764
0.058240189136795344,306.026728553779,0.1849126005093252,123.38997695288369,323.84978310566584,0.056607329538969416
0.05859698546188504,306.098165138324,0.186045428841485,123.41878018377226,324.0345948708441,0.056944432772746606
0.05895683470970734,306.154402449562,0.1871879502033208,123.4414550676634,324.20429695043003,0.05728430536333519
0.059316367290422944,306.251677798729,0.18832946614709284,123.48067648844754,324.4174148023467,0.05762376354448814
0.059675849785936944,306.304875255305,0.1894708230703498,123.50212570293898,324.5838789797407,0.0579630592682437
0.06003205325190844,306.35503285722,0.19060176907480927,123.52234924803112,324.7461545036948,0.05829914658368378
0.06039019046071224,306.405190459134,0.19173885471276136,123.54257279312284,324.90905826911194,0.058636944598462366
0.06075366178402274,306.455348061049,0.1928928761642722,123.56279633821497,325.07363262905494,0.05897965716506494
0.06111693826815604,306.505505662963,0.19404627900139543,123.58301988330668,325.23818373141626,0.059322068702953916
0.061479458160884445,306.555663264878,0.1951972796608081,123.6032434283988,325.4025393385532,0.0596636502649156
0.06184178314055194,306.605820866792,0.1963476614712524,123.62346697349052,325.56687155046706,0.06000493162746842
0.062204942216786546,306.655978468707,0.19750069153829727,123.64369051858269,325.7314958897851,0.06034688180722457
0.06256944469888703,306.706136070621,0.19865798691896633,123.6639140636744,325.896568690301,0.060689979397181085
0.06293113010730314,306.753253817874,0.19980633809068746,123.6829119393668,326.0575827447252,0.06103030902700514
0.06329396467877654,306.795811783135,0.20095833785511552,123.70007131096003,326.2141350577333,0.061371603630182334
0.06365713000961995,306.833809966404,0.20211138778054333,123.71539217845408,326.3659696987824,0.06171309275541865
0.06402031238081374,306.86724836768,0.2032644918090836,123.72887454184858,326.51298546761967,0.06205448132070143
0.06438317026223024,306.894607059633,0.204416565582581,123.73990556644404,326.6534547985136,0.062395448517843184
0.06474364130220345,306.917405969595,0.20556106113449593,123.7490980869407,326.78835641109316,0.0627340577932132
0.06510352032630755,306.935645097564,0.20670367703602646,123.75645210333782,326.9182361070416,0.06307199662188852
0.06546664252333075,306.952364298202,0.2078565900115751,123.76319328503506,327.04750500340356,0.06341286519019099
0.06582451513830714,306.967563571509,0.20899283556412518,123.76932163203243,327.1735546067911,0.06374869224699958
0.06618594668438435,306.984282772147,0.2101403807229203,123.77606281372968,327.3023281446483,0.06408774456968899
0.06654431872831394,306.999482045455,0.21127821196239677,123.78219116072745,327.42855342811504,0.06442381336668064
0.06690841499613895,307.140835287214,0.21243421761274114,123.83918478780468,327.6911417568717,0.06476513451769976
0.06727318242970964,307.251789982358,0.2135923542143281,123.88392172088675,327.921595701696,0.06510696806884893
0.06763784062807124,307.346025476864,0.21475014399412617,123.92191747227156,328.13424696573924,0.06544858249490182
0.06800319896216345,307.461539954001,0.21591015670486893,123.96849290945322,328.3699082287061,0.06579073581644182
0.06837559476860214,307.595293559106,0.21709251339031177,124.02242236303154,328.62730470423264,0.06613935920785843
0.06874463489018834,307.707768181581,0.21826421577634797,124.06777213081347,328.8610263580985,0.06648472127044407
0.06912055392215144,307.824802586048,0.2194577587028308,124.11496040269456,329.1018234517726,0.06683639829648369
0.06949354885349064,307.820242804056,0.22064201760983276,124.11312189859538,329.2117638854531,0.06718521759458618
0.06987184433529825,307.84912142334,0.22184310576457192,124.1247657578907,329.35910731418994,0.06753886965136398
0.07025264556011544,307.899279025255,0.2230521496533665,124.14498930298282,329.5300179428313,0.06789473794840366
0.07063377817790764,307.929677571869,0.22426224571485676,124.15724599697758,329.679914111875,0.06825078917801838
0.07100976830861494,307.946396772508,0.2254560143798524,124.16398717867524,329.8135990587967,0.0686019121603533
0.07139610256807004,307.987434810438,0.22668262565362235,124.1805337155686,329.97653729584084,0.06896256675796651
0.07178612984023884,308.028472848368,0.22792096224275832,124.19708025246197,330.14064479475144,0.06932653699864576
0.07217709627376795,308.069510886298,0.22916228066921324,124.21362678935537,330.30507363255094,0.06969125075222209
0.07256626541281254,308.110548924228,0.2303978926856798,124.23017332624873,330.4689807939509,0.0700541558440552
0.07295376948507894,308.151586962158,0.2316282181151256,124.2467198631421,330.63240680385655,0.07041537743152776
0.07333942987092604,308.194144927419,0.23285268984019017,124.26387923473534,330.7969278059535,0.07077475087604441
0.07372983430460535,308.236702892679,0.23409222391712198,124.28103860632817,330.96294392355406,0.07113841351562102
0.07411031197410205,308.27926085794,0.23530024051777398,124.29819797792142,331.1259330552675,0.07149270214751542
0.07448911752613474,308.321818823201,0.2365029481454778,124.31535734951466,331.2884390213941,0.0718453091069669
0.07486638583867744,308.364376788462,0.23770077503780085,124.33251672110788,331.4505032000103,0.07219636161161452
0.07524628627597604,308.406934753723,0.23890695892622393,124.34967609270112,331.6134112556979,0.07254973885195991
0.07562850682387694,308.446452864322,0.24012050916580926,124.36560979489462,331.773797529572,0.07290514824459447
0.07601274776590325,308.481411192929,0.2413404741567428,124.37970499298898,331.92993089240696,0.07326230903549419
0.07639609645666294,308.513329666875,0.24255760624990483,124.392574521684,332.08254375827187,0.07361851338379181
0.07678418124292564,308.555887632136,0.2437897754462889,124.40973389327723,332.24809883165375,0.07397898927564771
0.07717355004931635,308.603005379388,0.2450260214065794,124.42873176896923,332.4189948604036,0.07434052729932852
0.07756633231947745,308.645563344649,0.2462731051143409,124.4458911405625,332.5860676799724,0.07470510241832619
0.07795772321085945,308.683561527918,0.24751577119447873,124.46121200805653,332.7478291772538,0.07506825391708041
0.07834869803106674,308.720039783856,0.2487571162486369,124.47592004085074,332.9078529570203,0.07543088774373914
0.07874123670979255,308.756518039794,0.2500034265535913,124.49062807364496,333.0683881124568,0.07579483982263656
0.07913796213702044,308.791476368401,0.2512630297850399,124.50472327173928,333.2286045334782,0.0761625392118422
0.07953422239432294,308.8112354237,0.2525211561019753,124.51269012283585,333.3722968997542,0.07652967254926403
0.07992896206426264,308.821874915015,0.25377445455403386,124.51697996573405,333.5056868397117,0.07689526310637773
0.08032503682112824,308.830994479,0.25503199190708215,124.52065697393282,333.63785548203134,0.07726195587630935
0.08071957556415635,308.838594115654,0.2562846524161964,124.5237211474317,333.76791435050035,0.07762709294488306
0.08111686229573405,308.840114042984,0.2575460377889556,124.52433398213115,333.89225504520755,0.07799463854555166
0.08151740347690904,308.824914769677,0.2588177560391862,124.51820563513377,333.9995199506788,0.07836505826200031
0.08191425874017974,308.824914769677,0.26007777150007066,124.51820563513377,334.12207874353425,0.07873193397585146
0.08231280491351535,308.841633970315,0.2613431556004112,124.52494681683102,334.2632551364849,0.0791002374542932
0.08270879452036504,308.841633970315,0.262600422602159,124.52494681683102,334.3855532136996,0.07946604406921938
0.08310569805620704,308.8507535343,0.26386059132845735,124.52862382502975,334.51801100195354,0.07983256072301918
0.08350705912680804,308.844673824977,0.2651349127276155,124.52617248623073,334.6353842630791,0.08020305708778172
0.08391076184713095,308.862912952946,0.26641666886464077,124.53352650262781,334.77983528515176,0.08057557660947677
0.08431285817966154,308.89179157223,0.2676933247204254,124.54517036192313,334.93534138792097,0.08094647593316852
0.08471771405025494,308.900911136214,0.2689787421095594,124.54884737012149,335.07029019571496,0.0813197817597238
0.08512344524108374,308.887231790237,0.2702669386404409,124.54333185782357,335.18077715120324,0.0816937549363504
0.08553184442474954,308.885711862907,0.27156360604857976,124.5427190231241,335.3052765149931,0.08207004608716453
0.08594342561950034,308.870512589599,0.2728703763419136,124.53659067612632,335.41590251440016,0.08244912588177006
0.08635272966270574,308.867472734938,0.2741699166790907,124.535365006727,335.53902210962127,0.08282596588772764
0.08676554914270124,308.841633970315,0.2754806185280764,124.52494681683102,335.6384479398785,0.0832058987141988
0.08717982250897864,308.820354987685,0.2767959364660072,124.51636713103458,335.74325872267116,0.08358702454808048
0.08759553730919244,308.803635787047,0.27811583095668596,124.50962594933738,335.85345618684556,0.08396933052133909
0.08801432306424735,308.791476368401,0.2794454757289853,124.50472327173928,335.96954912897536,0.08435431292820827
0.08843464913730695,308.783876731747,0.28078001101094957,124.5016590982404,336.09107052977646,0.08474056234976951
0.08885286562371954,308.782356804416,0.2821078483553095,124.50104626354054,336.2185540605342,0.08512472520260422
0.08927287869154614,308.785396659078,0.283441389845659,124.50227193294026,336.35155791674487,0.08551038987245063
0.08968890313591324,308.791476368401,0.2847622674565245,124.50472327173928,336.4866451816021,0.08589224553682416
0.09011021615704855,308.796036150393,0.2860999362986291,124.50656177583846,336.6217137163447,0.08627880686961202
0.09052612157913105,308.797556077724,0.28742043601374107,124.50717461053831,336.7518011825546,0.08666026013619138
0.09095302899881665,308.817315133023,0.2887758670712428,124.51514146163487,336.90518535165353,0.08705165276079868
0.09138465624454234,308.821874915015,0.2901462835764219,124.51697996573405,337.0434557949187,0.08744721688845165
0.09181861882881634,308.894831426891,0.29152411478149187,124.54639603132246,337.25712821186823,0.08784476355297359
0.09226189397010855,308.903950990876,0.2929315133550946,124.55007303952121,337.40401456414384,0.08825067821113838
0.09270740042560785,308.906990845537,0.29434599635130493,124.55129870892051,337.5449549401238,0.08865847017674247
0.09315113909081985,308.903950990876,0.295754866613353,124.55007303952121,337.67870589533095,0.08906447876630641
0.09360746471207905,308.887231790237,0.297203700460851,124.54333185782357,337.80138244005343,0.08948183222003397
0.09405296913689934,308.8507535343,0.2986181770096554,124.52862382502975,337.8990839243696,0.08988912068590896
0.09449983021352344,308.820354987685,0.3000369609279369,124.51636713103458,338.0038261005012,0.09029748285379127
0.09494702197743525,308.716999929194,0.3014567947783569,124.47469437145102,338.02875970627906,0.09070598034226242
0.09539161409024524,308.672922036603,0.3028683747365286,124.45692216515832,338.117730295627,0.09111193776966182
0.09584007664874014,308.634923853334,0.3042922433597499,124.44160129766426,338.2145186119156,0.09152126241264848
0.09629020505200914,308.603005379388,0.305721401040129,124.42873176896923,338.3184520470355,0.09193193910769062
0.09674195454137924,308.58476625142,0.30715570566887906,124.42137775257254,338.437859680277,0.09234392531024917
0.09719407030791805,308.563487268789,0.3085911732276398,124.41279806677572,338.5540285448481,0.0927560756809237
0.09764211208395385,308.549807922812,0.31001370586655347,124.4072825544778,338.6772628514937,0.09316434467690035
0.09809405313886894,308.530048867513,0.3114486187159089,124.39931570338126,338.7950118760607,0.09357599801527065
0.09854352739634945,308.505730030221,0.3128756994834095,124.38951034818511,338.9069728893849,0.09398523645108403
0.09899293976337295,308.472291628945,0.3143025837487091,124.37602798479064,339.00887061283873,0.09439425116369947
0.09944416391179735,308.428213736353,0.31573522041995655,124.35825577849752,339.0995995781737,0.09480474655972997
0.09989653143131075,308.385655771092,0.3171714872944116,124.3410964069043,339.19231312579427,0.0952161130450139
0.10035004133369595,308.350697442485,0.3186113812344846,124.32700120880996,339.29370267611233,0.09562834857754125
0.10080877035373795,308.308139477224,0.320067845873118,124.30984183721672,339.3883039079717,0.09604515541968951
0.10126955254494995,308.241262674672,0.32153082933021604,124.28287711042775,339.45671742162637,0.09646365297551715
0.10173612946751394,308.186545290765,0.32301221105935674,124.26081506123647,339.5402515626121,0.09688723511454637
0.10220821735442294,308.145507252835,0.32451109010029283,124.24426852434307,339.6405102349217,0.09731563785058643
0.10268257087950194,308.102949287574,0.32601716254241864,124.22710915274983,339.73975221597897,0.0977459117987826
0.10315692048307694,308.048231903667,0.32752322253376925,124.20504710355854,339.825538867106,0.09817599713612839
0.10363756436310595,307.978315246453,0.32904926685286134,124.17685670736986,339.8964377152482,0.09861160080555012
0.10412492795161894,307.903838807247,0.3305966462463901,124.14682780708199,339.96430383907847,0.09905310082933076
0.10461244827446295,307.852161278002,0.33214452327141986,124.1259914272904,340.0573295758786,0.09949454790765583
0.10510287854781294,307.782244620787,0.3337016393893061,124.09780103110134,340.13104449633886,0.09993843339412511
0.10559344546540794,307.694088835604,0.3352591893526702,124.06225661851555,340.18456782509475,0.10038224552726933
0.10608691785002494,307.605933050421,0.33682596417382915,124.02671220592977,340.23889840012134,0.10082848758013646
0.10658408178170495,307.5208171199,0.3384044596569132,123.99239346274369,340.29764104138417,0.10127786657966167
0.10708712383817694,307.441780898701,0.3400016181862118,123.96052605835625,340.3648369628298,0.10173235328378817
0.10758823977548194,307.350585258856,0.34159266128715515,123.92375597637073,340.4178937208205,0.10218489450413154
0.10809007498319094,307.248750127697,0.3431859880716312,123.88269605148744,340.4592905674915,0.10263788013200681
0.10859350523224294,307.149954851198,0.3447843791123713,123.84286179600304,340.5044450804147,0.10309209945514393
0.10909937201125994,307.042040010716,0.3463905061357503,123.7993505323207,340.5401337569412,0.1035483094136838
0.10960623589666894,306.931085315571,0.3479997989719239,123.75461359923824,340.5726462566901,0.10400520995282717
0.11011731920627894,306.817090765766,0.3496224884799356,123.70865099675686,340.60296628756174,0.10446570271776315
0.11061555533842894,306.681817233329,0.3512043881995119,123.65410870847826,340.6055967587923,0.10491441597474307
0.11112417574279894,306.545023773563,0.3528192579833866,123.59895358550061,340.6095868684569,0.10537227375721867
0.11163505448116795,306.39607089515,0.35444129797770824,123.53889578492448,340.60061296234585,0.1058319535465708
0.11214937391346294,306.251677798729,0.3560742621752448,123.48067648844754,340.59761172380405,0.10629451586592001
0.11267091528246795,306.096645210993,0.3577301560218357,123.41816734907239,340.58483439180844,0.10676335497269279
0.11320042404938695,305.940092695927,0.35941134635680355,123.35504537499776,340.5726409228146,0.10723913159782911
0.11373296504316795,305.76226119823,0.3611021640120582,123.28334371512634,340.5375097626083,0.10771740455070754
0.11428031080676095,305.575310136549,0.362839986811466,123.20796504705655,340.4965515538262,0.10820873535249119
0.11482411097794995,305.344281182276,0.3645665523549911,123.1148141726937,340.40516681123205,0.10869664446671881
0.11537744678540594,305.120851864656,0.36632339354366383,123.02472747182931,340.32491671378807,0.10919286492435763
0.11593537386276394,304.856384509107,0.36809481201427546,122.91809423407194,340.2000234216208,0.10969295355722236
0.11649384252279794,304.613196136188,0.36986795000988343,122.820040682111,340.0987578372432,0.11019327730104791
0.11705505703931295,304.321370088686,0.37164980609981857,122.70237641975821,339.94372542269906,0.11069580897020968
0.11760742847620194,303.996105639907,0.37340358541194113,122.5712297940105,339.7483058909963,0.11119017574972931
0.11816533904491394,303.628283225867,0.37517495146760177,122.42292379666956,339.50662225687677,0.11168925203189634
0.11872136096089894,303.304538704419,0.3769403210508541,122.29239000562173,339.31326632502527,0.11218639113816863
0.11928117538763694,302.942795999702,0.37871773185574725,122.14653534707986,339.07816878176357,0.11268667157067168
0.11984759206888794,302.549134821039,0.38051610481871917,121.98781115984292,338.80892011186586,0.11319259753756125
0.12040298869569094,302.085556985163,0.3822794891088187,121.80089657641773,338.4575608879791,0.11368843192586638
0.12095166195693194,301.596140384663,0.3840215267132589,121.60356380309611,338.07469480398413,0.11417802269370039
0.12151422419823694,301.038327054281,0.3858076618294023,121.3786534682861,337.6187658202171,0.11467975808827632
0.12208129583461294,300.304202153532,0.38760811427489605,121.0826543083041,336.9657282970147,0.11518526065626424
0.12264921737491194,299.66583267462,0.3894112651653454,120.82526373440679,336.4196125261634,0.11569126487287239
0.12322213486292895,298.910428791241,0.3912302781897994,120.52068488862837,335.7428099596912,0.11620146106008837
0.12376638137250194,298.123106433916,0.39295826085769364,120.20323651415494,335.020724520771,0.11668588411457526
0.12432400417861295,296.680695397041,0.3947287132670961,119.62165638408693,333.5652274112965,0.11718196987796889
0.12489671384571495,295.086291627091,0.3965470664601449,118.9787927840431,331.94159975223295,0.11769122152667513
0.12547297257734094,293.552684950372,0.39837668793305747,118.36044257198999,330.38561293915484,0.1182033673733762
0.12604538724540892,291.943081907115,0.4001941045041733,117.71145062494878,328.7411607197155,0.1187118372936001
0.12662778284230192,290.094850272932,0.4020432105243086,116.96624363004618,326.8289179769629,0.1192289079611094
0.12690321606374594,289.03064782019,0.4029177110023933,116.5371572011006,325.70956656956,0.11947335387549823
0.12720784073930794,287.696100959553,0.4038848943473027,115.99906790689178,324.2933007517357,0.11974363752145892
0.12751796863915194,286.984318990566,0.4048695504293074,115.71207741699622,323.5799763795334,0.12001872897649052