File: example/data/02 processed data/test_ID_068.csv
Strain,Stress_MPa,Displacement(mm),Force(kN),True Stress (MPa),True Strain
0.001305101309399858,49.7365635738737,0.004143696657344549,20.053782432985876,49.80147482811901,0.0013042504049498498
0.001358768159863358,51.8108075916907,0.004314088907566162,20.89011762096969,51.8812064673831,0.0013578458697650862
0.0014091445537967582,53.8483231714824,0.004474033958304707,21.711643902741702,53.92420324281058,0.0014081526413326458
0.001461840272836858,55.8295991337134,0.004641342866257024,22.510494370713246,55.9112130901434,0.0014607728245111615
0.0015127572433400582,57.8228314908318,0.004803004247604685,23.31416565710338,57.91030339799999,0.0015116141787423116
0.0015668757536053581,59.7941185985166,0.0049748305176970115,24.108988618921895,59.887808553156816,0.0015656494845654504
0.0016153247323710581,61.7488162829597,0.005128656025278109,24.89712272528935,61.84856067309621,0.0016140214986173549
0.001665141670777458,63.6856542219461,0.005286824804718429,25.67805578228867,63.79169985862178,0.0016637568594437262
0.001715868351369258,65.6030455006339,0.005447882015597394,26.45114794585559,65.71561169016186,0.0017143979310610378
0.0017599504165704582,67.5064952133948,0.005587842572611204,27.218618870040782,67.62530329776682,0.0017584035185459485
0.0018050863389767581,69.4035230202701,0.005731149126251207,27.983500481772904,69.52880237155084,0.0018034591285070985
0.001858490350486158,71.2592398666369,0.005900706862793551,28.731725514228003,71.39167447631202,0.001856765494050082
0.001909570187993258,73.0888540233042,0.006062885346878594,29.469425942196253,73.22842232002168,0.0019077492765786953
0.001953674441291958,74.8947943317564,0.006202916351101967,30.197581074564184,75.04111437722817,0.0019517685013677568
0.0020029185538704584,76.666845641354,0.006359266408538705,30.912072162593933,76.82040308895579,0.0020009153868446026
0.002041938221867658,78.3948243391295,0.0064831538544298135,31.608793173537016,78.55490172734417,0.0020398562996394006
0.0020887771035698584,80.0931965802804,0.0066318673038343,32.29357686116906,80.260493415449,0.002086598641695683
0.002135801029419058,81.7399120303314,0.0067811682684055085,32.95753253062962,81.9144922185904,0.002133523448796535
0.0021785489951360584,83.3567026376634,0.006916893059556985,33.60942250350588,83.53829929843253,0.0021761793981719155
0.002212934535407458,84.9646752360085,0.0070260671499186795,34.25775705515863,85.15269650012795,0.0022104896020989045
0.002256778446314958,86.5525632315527,0.007165271567049992,34.89799349496205,86.74789319072698,0.0022542357466583925
0.0023021652904434585,88.1325966141847,0.00730937479715798,35.535062954839276,88.33549241906653,0.002299519368053439
0.002353998885612358,89.7093692143526,0.007473946461819237,36.17081766722697,89.92054496951218,0.0023512325706532187
0.0023998482855995583,91.3039999032996,0.007619518306778597,36.8137727610104,91.52311565093592,0.0023969732485523997
0.002447240266373058,92.9090028080902,0.007769987845734459,37.460909932221966,93.13637346087073,0.002444250650457981
0.002490794751631158,94.5088949837939,0.007908273336428927,38.1059864574657,94.74429724340197,0.002487697863792339
0.002543841192960258,96.0938524684909,0.008076695787648818,38.74504131529553,96.3382999687905,0.0025406111056792487
0.0025941397034353582,97.6396379307667,0.008236393558407261,39.36830201368513,97.89292879215193,0.0025907807308767654
0.002637899109552258,99.179365819459,0.008375329672828419,39.989120298405865,99.44099098024012,0.0026344259602338292
0.002682111589360758,100.697876408975,0.008515704296220407,40.60138376809872,100.96795935031552,0.0026785211466176747
0.002730384303698458,102.193048999881,0.008668970164242604,41.20423735675202,102.47207529681737,0.0027266635756152094
0.002779926589257258,103.662377585989,0.008826266920891793,41.79667064267077,103.95055138574591,0.0027760697395223543
0.002827756871118958,105.108768405538,0.008978128065802692,42.37985542111293,105.40599044761161,0.002823766287820755
0.0028729899488621584,106.552250296647,0.009121743087637352,42.961867319608075,106.85837384077792,0.002868870800866945
0.002920769478629558,108.023185981707,0.009273443094648845,43.55494858782426,108.33869680630669,0.0029165123188961825
0.0029670841930635582,109.456969939992,0.009420492312976796,44.13305027980478,109.7817379853216,0.002962691086425496
0.003014478873976858,110.883350768033,0.009570970424876524,44.7081670296709,111.21760628639899,0.0030099444428816225
0.003056214628080558,112.288723828627,0.009703481444155771,45.27481344770241,112.63190226896054,0.003051553897867463
0.003104761693829558,113.686986671753,0.009857618377908847,45.838593026050816,114.03995767305838,0.0030999518742327033
0.003160206372576158,115.089556618495,0.010033655232929302,46.404109228577184,115.45326336873774,0.003155223415772086
0.0032108748358372578,116.473933812366,0.010194527603783293,46.962290113145976,116.8479170354751,0.003205730985130917
0.0032654899621564586,117.837277461494,0.010367930629846756,47.51199027247438,118.22207390821235,0.0032601698285590073
0.003329455832850858,119.180089554419,0.010571022269301473,48.053412108341746,119.57689439874565,0.003323925466786018
0.0033930964095519583,120.519581619653,0.010773081100327467,48.593495309044094,120.92851617932733,0.003387352846571192
0.0034621313187344583,121.835085660668,0.010992266936981904,49.123906538381334,122.25689472645449,0.003456151939057706
0.0035267858363255584,123.125489332384,0.011197545030333647,49.64419729881723,123.5597265642521,0.0035205813109000705
0.0035817748351052578,124.401273993787,0.011372135101459192,50.15859367429492,124.84685134643298,0.0035753755555871865
0.0036521416052730585,125.65304923095,0.01159554959674196,50.66330944991904,126.11195195987578,0.0036454887293635853
0.003725896615577258,126.862754962006,0.011829721754457793,51.15106280068082,127.33543247136174,0.0037189726560910336
0.0038106242505261583,128.039261951247,0.012098731995420551,51.62543041874279,128.5271714678579,0.0038033822138934356
0.0038991028688397577,129.150168486017,0.01237965160856623,52.073347933562054,129.65373827847196,0.003891521069003473
0.003994296166192158,130.214317177609,0.0126818903276601,52.50241268601195,130.73443172549483,0.00398634014402944
0.004102582766645358,131.204352933585,0.013025700284099011,52.901595102821474,131.74262965083918,0.004094190120486628
0.0042269225687486586,132.114109052419,0.01342047915577699,53.26840876993534,132.67254516162276,0.004218014225974974
0.0043491044426120585,132.945990695744,0.013808406605293285,53.60382344852398,133.5241866945063,0.004339674419436491
0.004478707564977658,133.625770966757,0.014219896518804063,53.87791085379642,134.2242417180618,0.004468707999886523
0.004611417828171458,134.243080247457,0.01464125160444438,54.12680995577466,134.86213118101878,0.004600817815876866
0.004751636671378358,134.75608359602,0.015086446431626287,54.33365290591527,135.3963955445262,0.0047403832797889576
0.004898786536526558,135.175205527628,0.01555364725347182,54.50264286873961,135.83740000453898,0.004886826525551349
0.005049830484149058,135.52829525024,0.016033211787173256,54.64500864489677,136.21269016705943,0.00503712285315664
0.0052138730235480575,135.791798606804,0.01655404684976508,54.75125319826338,136.4997998023791,0.005200327849075162
0.005374756726937758,135.999453990493,0.01706485260802738,54.83497984896678,136.73041797068828,0.005360364269606473
0.0055478048513540575,136.197737518084,0.017614280403049132,54.91492776729147,136.95333598703027,0.005532472463278086
0.005704076529543858,136.323507381589,0.01811044298130175,54.96563817625668,137.10110710046942,0.005687869885103911
0.0058761495236269575,136.41973349904,0.018656774737515588,55.00443654681293,137.22135625105372,0.005858952293127359
0.006056450492007558,136.504178221483,0.019229230312123993,55.03848465890194,137.33090901883358,0.0060381839123791895
0.006237564800911358,136.566989894645,0.019804268242893563,55.06381032552086,137.41883534377826,0.006218191712448676
0.006413473313158858,136.634308263087,0.02036277776927937,55.09095309167668,137.51060875279424,0.006392994506737569
0.006607909973119158,136.634507702763,0.020980114164653323,55.09103350575404,137.53737622888428,0.006586173438843561
0.006789286160629458,136.644981355918,0.021555983559998527,55.095256482706134,137.57270323675718,0.006766342745077987
0.006997848942444458,136.652645572486,0.022218170392261153,55.098346694826354,137.60892014378766,0.006973477629322004
0.007189168888577158,136.660030904845,0.022825611221232476,55.1013244608335,137.64250294733813,0.007163450005287529
0.007381167191033458,136.637624673444,0.02343520583153123,55.092290268332626,137.64616982574438,0.007354059684780029
0.007581329519348858,136.609441105371,0.024070721223932622,55.08092665368559,137.64512229384488,0.0075527356693707096
0.007777863973301958,136.56047181026,0.024694718115233712,55.06118223389684,137.62262058413015,0.007747772321110773
0.007972253294884659,136.522267272411,0.02531190421125879,55.04577816423612,137.61065736749862,0.00794064277714608
0.008174243450391158,136.492978289948,0.025953222954991924,55.033968846507044,137.608705123759,0.00814101527637494
0.008364984445817758,136.46145525482,0.02655882561547138,55.02125875874343,137.60295320548025,0.00833019185509645
0.008569558529512558,136.417688201239,0.02720834833120237,55.00361188273957,137.5867275647403,0.008533048298909864
0.008773537527482458,136.401108885251,0.027855981649756802,54.99692710253321,137.597829132846,0.00873527369038027
0.008966164224174159,136.372553583023,0.02846757141175295,54.985413604674875,137.59529229411837,0.008926206839100682
0.009170347752701058,136.347858567798,0.029115854114825857,54.97545657453616,137.5982158462008,0.009128555419597444
0.00937966902549336,136.313694302066,0.029780449155941413,54.96168154259301,137.59227163826165,0.009335953078117375
0.009586844990144559,136.274647533597,0.030438232843708973,54.94593788554631,137.5810914555882,0.009541182797323041
0.00980079259776176,136.252606105664,0.031117516497893585,54.93705078180373,137.58798963901012,0.009753076348056187
0.010012743445863259,136.233210695982,0.03179046044061584,54.92923055261994,137.5972788834871,0.009962948046702868
0.010224810093190859,136.191126264577,0.032463772045880974,54.912262109877446,137.58365466701008,0.010172890335652952
0.010442257250460359,136.152823876353,0.033154166770211636,54.896818586945535,137.5745666886465,0.01038811347817171
0.010651024396223658,136.097147301224,0.033817002458010115,54.87436979185352,137.54672133738578,0.010594701811725265
0.010857564735473259,136.059028834621,0.034472768035127596,54.85900042611918,137.5362985480385,0.010799044589271316
0.011062666139709559,135.989517587274,0.035123964993577846,54.83097349118888,137.49392421884218,0.01100192242966076
0.01126752793198136,135.892160414926,0.035774401184040815,54.79171907929816,137.42332912813848,0.011204522176797144
0.011472848856288558,135.838867890189,0.03642629511871617,54.77023153332421,137.39732669030246,0.011407534809924414
0.01167390185237556,135.78196996363,0.0370646383812924,54.747290289335616,137.36707535430762,0.011606287566419602
0.011879069495374858,135.727044106677,0.03771604564781517,54.72514418381216,137.33935509602202,0.011809067178920338
0.012079262163058858,135.643811525144,0.03835165736771187,54.69158480693807,137.28228868535274,0.012006890093755575
0.01228835696828356,135.593605527735,0.0390155333743003,54.67134174878275,137.25982815507643,0.012213467993927671
0.01249968824566556,135.577057415044,0.03968651017998815,54.66466954974575,137.27172836599678,0.012422212092994302
0.012714770364577658,135.536316123678,0.040369395907534064,54.64824266106697,137.25962925925137,0.012634616383123845
0.012920843105556759,135.484172573314,0.04102367686014271,54.627218381560205,137.23474231041996,0.012838081152719852
0.013134310466766358,135.443012963232,0.041701435731983184,54.61062282677514,137.22196354604534,0.013048803315562303
0.01335220427315936,135.38551718881,0.04239324856728096,54.587440530528205,137.19321226994234,0.013263849214607626
0.01356684833480276,135.354536373651,0.043074743462998756,54.57494906585608,137.1908708400599,0.013475642637901648
0.013773858385350758,135.308105032769,0.04373200037348866,54.55622794921246,137.17181970988054,0.013679860952643987
0.01398684533051196,135.24004529346,0.04440823392437547,54.528786262323074,137.13162688947105,0.013889932038008241
0.014197135550749659,135.191188910812,0.04507590537363017,54.5090873688394,137.1105165450458,0.014097300031221636
0.014418158601784659,135.137578911913,0.04577765356066629,54.48747181728332,137.08601395772615,0.014315205370441494
0.014630245427016058,135.065701092884,0.04645102923077598,54.45849068065083,137.0417454486449,0.0145242559042608
0.014833360476143859,134.989131623429,0.04709591951175675,54.427617870566564,136.99147407316096,0.014724422144458777
0.01505246947639846,134.933565407353,0.04779159058756511,54.40521357224473,136.9646487819888,0.01494030522307573
0.01526785701414396,134.867428280502,0.04847544601990707,54.378547082698404,136.92656489135402,0.015152476214759422
0.015482564505616959,134.798969525052,0.04915714230533384,54.350944512500966,136.8860032660143,0.015363932521745928
0.01569038936902616,134.734982796243,0.049816986246658056,54.32514506344518,136.8490271379451,0.015568567842177887
0.015893982424758958,134.63317668435,0.050463394198609686,54.284096839129916,136.7730340283605,0.015768995704531157
0.01610208701692496,134.569586570259,0.05112412627873674,54.258457305128424,136.73643776304493,0.015973823455945835
0.01631574797893046,134.509960460315,0.051802499833104206,54.23441605759901,136.7045910758414,0.01618407644537889
0.016519848035660957,134.458908903732,0.052450517513223535,54.21383206998475,136.68014964586246,0.01638487975462485
0.016731795971490757,134.384853723853,0.05312345220948315,54.18397302145753,136.63335367801915,0.01659336151065557
0.016940969616788357,134.325603573353,0.05378757853330303,54.16008336077593,136.60120954224593,0.016799071740516192
0.017157983326834457,134.292691862347,0.054476597062699396,54.14681335889831,136.59688363023687,0.017012447506287515
0.017375731222999655,134.266146140556,0.0551679466330239,54.13611012387218,136.5991186082423,0.017226499399789524
0.017595126442641457,134.204531394229,0.05586452645538662,54.11126705815314,136.5658770932859,0.017442124325979958
0.017812517491006357,134.167834752256,0.05655474303394518,54.09647097210962,136.557701655511,0.01765573367331582
0.018037402230323157,134.119326287122,0.05726875208127602,54.07691235896758,136.53849052222276,0.01787665834762792
0.018249841364454157,134.076716795281,0.05794324633214194,54.059732211857295,136.5235956074617,0.018085311754036968
0.01847706726587406,134.025527780047,0.058664688569150136,54.03909280091496,136.50192647218321,0.018308440246521538
0.018694743567410656,133.954534687701,0.05935581082652883,54.01046838608105,136.4587803633794,0.01852214465889123
0.018913699464118656,133.894679591462,0.06005099579857673,53.98633481127747,136.42712332109934,0.01873705925477389
0.019135421622720857,133.822879560291,0.06075496365213872,53.95738503870933,136.38363678344376,0.01895464199817585
0.019353607265754757,133.751973451123,0.06144770306877135,53.9287956954928,136.3405566163157,0.019168708044914436
0.019568010414760757,133.649981016186,0.0621284330668654,53.887672345726195,136.2652452366433,0.019379018385377922
0.01979135885710046,133.566425078525,0.06283756437129395,53.85398259166128,136.20988612851409,0.01959805623284885
0.020009720793656458,133.49630494893,0.06353086351985925,53.82571015540858,136.16752873794292,0.01981215744062704
0.020229915128738157,133.432528663784,0.06422998053374364,53.799995557237715,136.1318573940653,0.020028008884800243
0.020446497292093857,133.367136084365,0.064917628902398,53.773629269215974,136.0940268711683,0.020240273958136403
0.020664233270832656,133.276681117644,0.06560894063489368,53.73715782663406,136.03074154582137,0.020453624440601035
0.020888551217284158,133.190292671501,0.0663211501148772,53.70232600514921,135.9724449216147,0.020673376728230816
0.021113255857462758,133.158602463914,0.06703458734744425,53.68954851345013,135.97001410735677,0.02089345943364971
0.021339616591839358,133.10536962517,0.06775328267908996,53.66808503286855,135.94578717928619,0.021115115206820117
0.021557568700956056,133.04369925095,0.06844528062553547,53.64321953798304,135.9117979377817,0.021328490712462594
0.021780255197561556,132.967630098157,0.06915231025225793,53.612548455576906,135.86369901470985,0.021546454178789722
0.022002671533194757,132.898022505123,0.06985848211789335,53.5844826740656,135.82213404171435,0.021764105802748467
0.022229444777040558,132.877582734944,0.07057848716710377,53.57624135872943,135.8313776224571,0.02198597223657151
0.022452804784173656,132.816013205278,0.07128765518975136,53.5514165243681,135.79810522198835,0.022204451179272243
0.022681802714039658,132.74891447582,0.07201472361707591,53.524362316650624,135.75989916446346,0.022428395295208105
0.022909077775075358,132.688666245406,0.07273632193586425,53.500070230147706,135.72844122029304,0.022650604989373872
0.023136273480314856,132.622570429106,0.07345766829999967,53.47342039701554,135.69096248821612,0.022872687756047578
0.023364499431580157,132.563560253689,0.074182285695267,53.4496274942874,135.66084148188457,0.023095727937837263
0.02359500528115146,132.48903640121,0.07491414176765587,53.419579476967876,135.61511591479123,0.02332094573038756
0.023820189260817557,132.424224935689,0.07562910090309574,53.393447494069804,135.5785950363742,0.02354091477347601
0.024047486544325355,132.370380828474,0.076350769778233,53.37173755004072,135.55355578031396,0.02376289912053769
0.024273131500491058,132.286394352199,0.07706719251405911,53.337874202806645,135.49739939803575,0.02398322103214729
0.024496915419905757,132.21051694845,0.07777770645820077,53.307280433615034,135.4492667997582,0.02420167787716114
0.02471787313471036,132.119817021413,0.07847924720270538,53.27071022303373,135.38553789712947,0.024417328981081624
0.024941718836939356,132.02177156788,0.07918995730728245,53.23117829616922,135.3146214746807,0.02463575130252049
0.025167069741600056,131.942873067971,0.07990544642958017,53.199366421005905,135.26348855637968,0.02485559417800462
0.025392939501005657,131.858944347433,0.08062258291569295,53.16552636088499,135.20723054391385,0.025075894739120776
0.025618672347922256,131.806419563614,0.08133928470465315,53.14434836804917,135.18312503976702,0.02529601328601147
0.025844954238737256,131.72848569089,0.08205772970799079,53.11292543056686,135.13300237550922,0.025516618602917988
0.026072160653747355,131.657687812932,0.08277911007564785,53.084379726174184,135.09028820089168,0.02573807629659334
0.026302467027415555,131.625534206757,0.08351033281204438,53.071415392164425,135.0876104801962,0.02596250547392638
0.026527876024199856,131.571851997989,0.08422600637683454,53.04977072558917,135.06217377606603,0.026182113488249857
0.026760529927361158,131.49400690191,0.08496468251937167,53.01838358285012,135.01285620887722,0.02640872939226286
0.027002177445971855,131.413675862163,0.08573191339096063,52.98599410762412,134.96213125662055,0.026644051144730407
0.027233180468946155,131.325092105295,0.08646534798890404,52.95027713685495,134.90149203869947,0.02686895529026354
0.027463890814699757,131.261555491254,0.08719785333667172,52.92465917407361,134.86650851943347,0.027093524011315127
0.02769668084404696,131.157833393614,0.08793696167984909,52.88283842430516,134.79047004531358,0.027320065950230163
0.027927772325831258,131.059487640651,0.08867067713451424,52.84318541671048,134.71968717261922,0.02754490418116444
0.028164051626954158,130.987220593558,0.08942086391557945,52.814047343322585,134.6763514368262,0.027774737595616376
0.028392915127804657,130.949863545141,0.09014750553077978,52.79898498140086,134.66791190677577,0.02799730716747357
0.028617212812721657,130.877112611373,0.09085965068039126,52.7696518049056,134.6224507952872,0.02821538843285894
0.028850089926400257,130.789674971489,0.09159903551632081,52.73439694850436,134.56296885586113,0.028441761036071884
0.02908581027613206,130.726482080072,0.09234744762671929,52.70891757468503,134.52876773591916,0.028670845285721547
0.029316552043683056,130.684020032546,0.0930800527386937,52.69179687712254,134.51522490710784,0.02889504029515358
0.029552280091746857,130.619886315388,0.09382848929129627,52.66593816236444,134.48000178133248,0.02912402821843898
0.029786081975232158,130.537230181697,0.09457081027136209,52.63261120926023,134.42542282070877,0.029351093268842048
0.030020772802165557,130.452680374212,0.09531595364687565,52.59852072688228,134.36897065315975,0.029578969807270428
0.030257075910384658,130.396419949387,0.09606621601547129,52.575836523592834,134.341834326238,0.029808359362085028
0.030498064474143056,130.332763203416,0.0968313547054042,52.55017012361733,134.307660218687,0.03004224310706212
0.030731607633142758,130.268672453486,0.09757285423522825,52.52432873324556,134.27203818221693,0.030268848771786823
0.030969330088373256,130.213973606974,0.09832762303058508,52.50227415833192,134.2466131377271,0.030499456860413682
0.031210600862131357,130.124697784399,0.09909365773726705,52.46627814666967,134.18596778925334,0.030733452712315597
0.031450723425079256,130.079515213722,0.09985604687462664,52.44806053417271,134.17061006997716,0.030966280623718374
0.03169842830328866,130.002398387077,0.10064250986294149,52.41696702966944,134.12327009160532,0.03120640371825292
0.03193907514249676,129.926050517262,0.10140656357742721,52.38618356856005,134.07576840770068,0.031439629602059746
0.03217901089826336,129.863592339603,0.10216835960198617,52.36100043132793,134.04247429278672,0.03167211218963053
0.032420411534983054,129.798555809098,0.10293480662357118,52.334777702228315,134.0066784050754,0.0319059596228874
0.032667272330123655,129.737021267249,0.1037185896481426,52.3099669749548,133.97517587228523,0.03214503983071112
0.032914971014072356,129.675552886116,0.10450503296967972,52.28518292368198,133.94381995059632,0.03238487408174059
0.03316507276482146,129.589089372715,0.10529910602830812,52.25032083507868,133.88692095128803,0.032626976756052466
0.03341660810697996,129.528750237812,0.10609773073966136,52.22599209588581,133.85716172309586,0.03287040806653871
0.033667156404234656,129.448787466876,0.10689322158344503,52.19375110664441,133.80696004086184,0.03311282523683737
0.03391697700076566,129.38948349715,0.10768640197743096,52.169839746050876,133.77798363306377,0.033354479826569035
0.034175039286868054,129.32281755574,0.10850574973580607,52.14296003847437,133.74242992639586,0.03360404540238419
0.03442819456835586,129.216362578262,0.10930951775452984,52.10003739155523,133.6650486505216,0.03384880503401228
0.034679666547463656,129.142714105157,0.1101079412881971,52.070342327199306,133.62134036735827,0.03409187789171276
0.03492793629725606,129.068261991382,0.11089619774378798,52.040323234925225,133.57635002421455,0.034331797527340474
0.03517365659742526,128.994758971538,0.1116763596968252,52.01068681732412,133.53197632647053,0.03456919679524747
0.035424420456998555,128.913463015828,0.11247253495097041,51.977908287981855,133.48014773226842,0.03481141073679226
0.03567693580154066,128.809818706045,0.11327427116989158,51.93611890227735,133.40535833862867,0.03505525717630182
0.03593064893616456,128.727571391772,0.11407981037232247,51.90295678516247,133.3528365678548,0.03530020041532214
0.036184666594745556,128.651072764287,0.11488631643831713,51.872112538560515,133.30626893931907,0.035545377561545195
0.036433871314260256,128.587440731691,0.11567754142277631,51.84645610301782,133.2723789999395,0.035785850872149604
0.03669142582424026,128.530404738525,0.11649527699196281,51.823459190573274,133.24636855014816,0.03603432066957155
0.036946265126965756,128.43412028778,0.11730439177811627,51.78463730003289,133.17928134728095,0.03628011028375587
0.03720334713659606,128.38431646788,0.11812062715869248,51.764556399849226,133.16064276032915,0.03652800176605456
0.03745619818307696,128.299837821541,0.11892342923126933,51.73049460964533,133.10546197384127,0.03677175361276437
0.037711624297914755,128.186910888272,0.11973440714587934,51.68496247015127,133.02104751160078,0.03701792754950392
0.03796534249203456,128.112960626247,0.12053996241220971,51.655145724502795,132.976813054091,0.037262395450283085
0.038221497698926556,128.026541280785,0.1213532551940918,51.62030144441252,132.91990743375007,0.03750915089948747
0.03847576711216936,127.92144604052,0.12216056058113771,51.57792704353767,132.843321807027,0.037754029552550604
0.03873173206088336,127.837877898161,0.12297324929330465,51.544232368538516,132.7892603321445,0.038000480569226995
0.03898919668872726,127.725243558491,0.12379069948670904,51.49881820278357,132.7051482017086,0.03824831426585024
0.03924297530276986,127.687052426053,0.12459644658629429,51.48341953818457,132.69787227089208,0.03849253973663665
0.039498993103776754,127.576967667753,0.1254093031044912,51.43903336363801,132.61612943386234,0.03873885968032608
0.03975751259598446,127.496109166147,0.12623010249225064,51.40643121579047,132.56503733225907,0.03898752500163783
0.04001438936143126,127.397760692585,0.12704568622254422,51.366777111250265,132.49550429271255,0.03923454898201896
0.040275555774283656,127.327218034184,0.1278748895833506,51.33833431138299,132.45539250570417,0.03948563553352129
0.04053167788739056,127.261859667439,0.128688077292465,51.3119818179114,132.41999637082992,0.039731811258265894
0.04078677417212256,127.222931404622,0.1294980079964891,51.296285942343594,132.41194437733776,0.03997694076812732
0.04105112648617266,127.113214915134,0.13033732659359817,51.25204825378202,132.3313555786792,0.04023090128579029
0.04130993305652296,127.052652219936,0.1311590374544604,51.227629375078195,132.30118877779523,0.04047947160023882
0.04157313030923226,126.971702981029,0.13199468873181242,51.19499064195089,132.25031413464444,0.040732195585314324
0.041837231783444756,126.908294356739,0.1328332109124371,51.169424284637174,132.21778608298354,0.04098572362802021
0.042098368343149055,126.841373955716,0.13366231948949825,51.14244197894469,132.18118883765484,0.041236342275789595
0.04236203395284026,126.764578509344,0.1344994578002678,51.111478054967506,132.13458388817432,0.04148932440085856
0.042635587484769956,126.674561452692,0.1353679902641446,51.075183177725414,132.07540579960312,0.041751726171188254
0.04290122435168086,126.602202452388,0.13621138731658672,51.046008028802845,132.03359194321482,0.04200646813195331
0.04317138427296126,126.578515624331,0.137069145066652,51.03645749973026,132.04308536305004,0.04226548109408497
0.043448723606773154,126.502616212607,0.13794969745150476,51.00585485692314,131.99899341996226,0.042531307474649054
0.043723663095124654,126.438301765592,0.13882263032702077,50.97992327188669,131.96664747431043,0.0427947639018167
0.044000936191915856,126.352618957754,0.13970297240933283,50.94537596376642,131.91225248219558,0.04306038619559645
0.04428093343588526,126.279058972515,0.1405919636589357,50.91571657771805,131.87081357722317,0.043328546590722924
0.044557167965982955,126.17821716863,0.14146900829199588,50.87505716239161,131.80036118466091,0.0435930328920044
0.044835320577942754,126.077220396985,0.14235214283496825,50.83433526406435,131.72993299105977,0.04385928503479543
0.045110006910244756,125.978198400347,0.1432242719400271,50.79440959501991,131.66107580072685,0.04412214964687004
0.04538064764444396,125.88586061183,0.14408355627110955,50.75717899868985,131.59864249567306,0.04438107521070514
0.04565634532476176,125.795160076839,0.1449588964061186,50.72060854298148,131.53850734549084,0.0446447699065353
0.045930115743794055,125.70417614357,0.14582811748654612,50.68392382108742,131.47778350332246,0.044906552458384395
0.04620532348322846,125.627010315742,0.14670190205925035,50.65281055930717,131.43164696561175,0.04516964034061387
0.04647851599136156,125.563793151717,0.14756928827257296,50.627321398772295,131.3998119196551,0.045430733301272196
0.04675644306146646,125.510227472746,0.148451706720156,50.60572371701119,131.37863927720716,0.04569628119931008
0.047036141378586256,125.411954826386,0.14933974887701135,50.566100185998835,131.31084926416474,0.04596345027886659
0.047321171261390856,125.32816854973,0.15024471875491596,50.53231755925113,131.2588442775482,0.04623563868038152
0.04760224417589716,125.224629765757,0.15113712525847348,50.490570721553226,131.1856031687029,0.04650397585597635
0.047883937746697254,125.147366862696,0.15203150234576376,50.45941831903903,131.13991558671242,0.04677283334110515
0.04816308473631926,125.058310055952,0.15291779403781364,50.423510614559845,131.0815040401577,0.04703918899847167
0.04844301339949396,124.968619668783,0.1538065675433933,50.38734745045331,131.02247618591412,0.04730621928621812
0.048724284626223156,124.873770919244,0.15469960368825852,50.34910443463917,130.95815607586303,0.047574458475986695
0.04900827035050736,124.783084868783,0.15560125836286084,50.31253981909331,130.8984880272026,0.04784521341597668
0.04927972792417506,124.709004352375,0.1564631361592558,50.282670554877605,130.8546301565548,0.04810395537647534
0.04956115905725736,124.632143322845,0.1573566800067921,50.2516801877711,130.8090568017154,0.048372133051605135
0.04983905068587606,124.531723758986,0.15823898592765648,50.21119101962316,130.73826665140965,0.04863686735900599
0.050122831530897555,124.45804739594,0.15913999011059973,50.18148471004301,130.69623713823114,0.048907139737901964
0.05040345264813316,124.337067018038,0.16003096215782278,50.13270542167292,130.60408448788945,0.049174330985180134
0.050691336088205856,124.238732725029,0.16094499208005358,50.09305703473169,130.5365600807662,0.049448362831260945
0.05097239842866406,124.16781755733,0.16183736501100837,50.06446403911546,130.4969490258799,0.04971582935077863
0.051257571999172455,124.099258565279,0.16274279109737252,50.0368210535205,130.4602852462327,0.04998713513203858
0.05154712276223126,124.040886210774,0.16366211477008424,50.01328532018408,130.43483699981672,0.050262529956494016
0.051841772057266255,123.982184466186,0.16459762628182034,49.9896167767662,130.40964061244392,0.050542696213611654
0.05213851199849856,123.885894726233,0.16553977559523292,49.95079275361715,130.34512093486143,0.05082477104620266
0.052429414866360054,123.822352397414,0.16646339220069317,49.92517248663732,130.31428588098663,0.05110122006550089
0.052713987642664856,123.754949462415,0.1673669107654609,49.89799562324573,130.27856633909533,0.05137157958371613
0.053005392515318356,123.660859577651,0.16829212123613577,49.860058581708884,130.21555197834607,0.05164835423589419
0.05330441633823016,123.538801979278,0.16924152187388075,49.81084495804489,130.1239657139076,0.051932285710422445
0.053588611336902355,123.44977502313,0.17014384099466498,49.77494928932602,130.06527703647257,0.05220206210311334
0.05388410608446416,123.344170878837,0.1710820368181737,49.732369698347085,129.99046126737252,0.052482487796936546
0.054174791137085156,123.236637328187,0.17200496186024536,49.689012170725,129.91295641587823,0.05275827236334168
0.05447682146996376,123.185581561515,0.17296390816713492,49.66842648560285,129.8963404959153,0.053044740107124864
0.05478390519530036,123.119625787676,0.17393889899507864,49.64183311759097,129.86459969450888,0.05333591674889702
0.055086859341565354,123.03785813479,0.17490077840947,49.60886439994732,129.81562731954867,0.0536230946684543
0.055384869854608956,122.979023126441,0.17584696178838344,49.58514212458102,129.7902003171459,0.05390550595205642
0.05569513744775326,122.86226364412,0.17683206139661659,49.53806470130919,129.70509430492137,0.05419944800475464
0.05599152276237176,122.763576752343,0.17777308477053033,49.4982741465447,129.637296354462,0.0544801575646997
0.05629303730072386,122.683689975797,0.17873039342979824,49.46606379824135,129.58992751179497,0.05476564423264266
0.05659245878518146,122.552246948728,0.17968105664295111,49.413065969727135,129.48777993320525,0.05504906847595035
0.05688739475800016,122.441140719441,0.18061747835665048,49.36826793807861,129.40649822616768,0.055328168344575934
0.05717965883459316,122.31681470374,0.18154541679983327,49.318139688547966,129.310848438234,0.055604662959974516
0.05748124275341436,122.201889649987,0.18250294574209058,49.27180190687476,129.22620613388386,0.055889894431970205
0.05778301091236226,122.121598856869,0.18346105964675016,49.23942865908958,129.1781525362506,0.05617521874591554
0.05808918622381596,122.045181786562,0.18443316626061565,49.2086172963418,129.13468707908106,0.056464626881251076
0.05839610422177436,121.966103134354,0.1854076309041336,49.176732783771534,129.08844840451144,0.056754652993405354
0.05870099987740586,121.899219818593,0.1863756746107636,49.1497654308567,129.05482590622012,0.05704268480559675
0.05901076287268946,121.815543733803,0.187359172120789,49.11602723346937,129.00397189928617,0.05733522980906828
0.05933498049401046,121.754616235137,0.1883885630684832,49.09146126600724,128.97892401450457,0.057641334348299225
0.05964883185482866,121.662232318026,0.18938504113908097,49.05421207062808,128.91924235664703,0.057937562532095935
0.05996094628938746,121.598700841206,0.19037600446880518,49.02859617917426,128.88987401120485,0.05823206432203193
0.06026813160630606,121.473641738027,0.1913513178500217,48.97817234877249,128.79463116499167,0.05852183048199121
0.060573556927130456,121.347291657358,0.1923210432436392,48.92722799624675,128.69772873651806,0.05880985322747673
0.06088206431556706,121.190376982801,0.1933005542019254,48.86395999946536,128.5686973086957,0.05910069823740496
0.06118791405300346,121.043279917033,0.19427162711828597,48.804650462547706,128.44966572529006,0.05938895427294752
0.061480191886466355,120.958747740246,0.19519960923953067,48.77056708886718,128.39531476166297,0.05966434149386273
0.06178432859908046,120.843837748582,0.19616524330208043,48.724235380228265,128.31009312921435,0.059950821780948876
0.06208085968906936,120.689505636961,0.1971067295127952,48.66200867282268,128.18201390235234,0.060230058988235795
0.062378509695393054,120.600469789469,0.19805176828287294,48.6261094191139,128.12334736350036,0.06051027146258167
0.06267706836011976,120.518995809302,0.19899969204338022,48.59325911031056,128.0727731483346,0.06079126050566749
0.06298387324982976,120.440007012861,0.1999737975682095,48.56141082758556,128.02578514876765,0.06107992826620717
0.06329376787986256,120.335297991283,0.2009577130185636,48.51919215008531,127.95177241009736,0.06137141854596426
0.06361517777339555,120.25947983276,0.20197818943053086,48.48862226856883,127.90980802125709,0.061673650474262216
0.06393135057394576,120.196898498593,0.2029820380722778,48.4633894746327,127.88124855440753,0.0619708687006701
0.06425023315296416,120.14174306259,0.2039944902606612,48.44115080283628,127.86087806576492,0.0622705448033515
0.06457869350272495,120.030692917163,0.2050373518711517,48.39637538420012,127.78211824598017,0.06257912793866552
0.06491195608859426,119.922697624602,0.20609546058128678,48.352831682239525,127.70711450683592,0.06289212540465945
0.06523725092391866,119.85453553605,0.20712827168344172,48.32534872813536,127.67351594518502,0.06319754517223469
0.06556555652357215,119.80205371946,0.20817064196234158,48.304188059686275,127.6569420442433,0.06350569719935227
0.06588742434056986,119.670016309873,0.2091925722813093,48.250950576140795,127.55476545532451,0.06380771448271144
0.06620825922473546,119.554183761519,0.21021122303853507,48.20424689264446,127.46965815140331,0.06410867178876518
0.06653475821578565,119.422465011606,0.21124785733511944,48.151137892679536,127.36820984668631,0.0644148493178259
0.06685911485522375,119.319752149856,0.2122776896653354,48.10972406682194,127.29736516334006,0.06471892504058076
0.06718282507057806,119.201520777802,0.21330546959908533,48.06205317760977,127.20981569636396,0.0650223026001131
0.06750431937829375,119.087149555961,0.21432621402608265,48.01593870096348,127.12604653343723,0.06532351236846944
0.06782199708158566,118.969461619786,0.21533484073403447,47.968486925097714,127.03820809856094,0.06562105724785092
0.06815010140336665,118.858180983375,0.2163765719556891,47.9236185724968,126.95837807001172,0.06592827504774114
0.06847607866332675,118.773583390618,0.21741154975606242,47.889508823097174,126.90673262999915,0.06623340775231092
0.06880487027897576,118.662388536674,0.21845546313574804,47.84467505798696,126.82693878693328,0.06654108056285606
0.06913010788267836,118.568592902186,0.21948809252750376,47.806856658161394,126.76525252101148,0.06684533453646474
0.06945538084578445,118.470673462549,0.22052083418536564,47.767375540099756,126.69909920694691,0.06714952903074974
0.06978794329942296,118.34905467098,0.22157671997566789,47.71833884333913,126.60839178789867,0.06746044500048914
0.07012053131926485,118.22327742082,0.2226326869386659,47.667625456074624,126.51315644787273,0.06777128822249093
0.07044507015954196,118.096691119191,0.22366309775654572,47.61658585925781,126.41602081069217,0.06807451540930526
0.07077094096458136,117.930694461535,0.22469773756254582,47.54965600689091,126.27676067718437,0.0683788946086595
0.07110144365293396,117.804207043806,0.2257470835980653,47.498656280062576,126.18025623300974,0.068687505610276
0.07143757579254956,117.688324886314,0.22681430314134482,47.45193259416181,126.09569351527827,0.06900127552468373
0.07177401593138666,117.568623585181,0.22788250058215262,47.40366902954498,126.00699584741498,0.06931523439174081
0.07209512844526945,117.460729608341,0.2289020328137305,47.36016617808309,125.92907599672942,0.069614797932852
0.07242735167528636,117.345932513942,0.22995684156903418,47.31387998962142,125.84498763579371,0.06992463216005576
0.07276395457997376,117.184181602033,0.23102555579141665,47.2486620219397,125.71096606961473,0.07023845303604791
0.07310271603351055,117.056623590543,0.232101123406396,47.19723063170694,125.613780704724,0.07055418696396615
0.07343043110956586,116.922702903194,0.2331416187728716,47.14323381056782,125.50838738387122,0.0708595305632838
0.07375492496835866,116.754847544362,0.23417188677453873,47.07555452988676,125.36609256468857,0.0711617810050955
0.07407578086162135,116.576212822146,0.23519060423564778,47.00352900988927,125.21168681683702,0.07146055305894354
0.07440691369493606,116.41275682412,0.23624195098142198,46.93762355148519,125.07467077412188,0.07176880114190531
0.07472786382294926,116.267234301307,0.23726096763786386,46.87894887028698,124.95563635324599,0.07206747959963301
0.07503925611423645,116.10990597409,0.23824963816270073,46.81551408875309,124.82270694587963,0.07235717822845388
0.07535617897235156,115.930935539058,0.23925586823721617,46.743353209348186,124.66704786597141,0.07265193597880881
0.07568584291595856,115.782210719064,0.24030255125816843,46.683387361926606,124.5452849320095,0.07295845155854504
0.07601150816878986,115.672210375332,0.2413365384359078,46.63903522333387,124.46462953917852,0.07326115700655216
0.07633696705887186,115.570261956345,0.24236987041191813,46.597929620798304,124.39254523629171,0.07356357912481826
0.07666775893708745,115.425141626239,0.24342013462525264,46.53941710369956,124.27452855971866,0.07387086305859175
0.07700732180625555,115.279061046227,0.24449824673486137,46.480517413838726,124.15639279773677,0.07418619648564198
0.07734653385333455,115.182458513366,0.2455752449843372,46.441567272589175,124.09142244008036,0.07450110487359432
0.07768466553134466,115.091248755169,0.2466488130620193,46.404791498084144,124.03207392029908,0.07481491163507538
0.07801721541586695,114.940230789272,0.24770465894537755,46.343901054234465,123.90754753470809,0.0751234421328214
0.07835109967022916,114.87781708353,0.24876474145297756,46.3187358480793,123.87862037974003,0.07543311488649215
0.07869071472577176,114.712603988826,0.2498430192543253,46.25212192829465,123.73942078476115,0.07574800452477569
0.07902788698625746,114.537162353272,0.2509135411813674,46.18138386083927,123.588792275453,0.07606053115634158
0.07936730878185155,114.369912532935,0.2519912053823787,46.11394873327939,123.44714469628981,0.07637504427150929
0.07970884213662316,114.207930537286,0.25307557378377854,46.04863759263372,123.31131244323296,0.0766914141758084
0.08004879986412286,114.03721101071,0.2541549395685901,45.97980347951827,123.16575289196906,0.07700622517468728
0.08039139887903886,113.889908927278,0.25524269144094835,45.92041127947849,123.0456780241482,0.077323381852282
0.08074133583440386,113.613818452792,0.25635374127423227,45.809091600165736,122.78714992391787,0.07764722772514529
0.08107914958033846,113.443334250441,0.2574262999175746,45.74035236977781,122.64122331702484,0.0779597548299289
0.08142017079408166,113.281174671104,0.25850904227120924,45.67496962738913,122.50454726057947,0.07827515027385532
0.08175320137768875,113.093187836132,0.2595664143741618,45.59917333552842,122.33891799574408,0.07858305956168454
0.08209559331777685,112.893599454475,0.2606535087839415,45.51869930004432,122.16166648346957,0.07889952524430076
0.08243318900567725,112.699674752282,0.2617253750930253,45.4405088601201,121.98986834201521,0.07921145982645533
0.08276325795611025,112.487544180586,0.26277334401065006,45.35497781361228,121.79737981645317,0.07951634574426923
0.08310211729111265,112.294848034092,0.26384922239928266,45.27728272734589,121.62678766660878,0.07982925470125242
0.08344871978635325,112.10594677383,0.26494968532167157,45.20111773920826,121.46104451254315,0.08014921257370648
0.08378837274123435,111.931007582781,0.26602808345341905,45.1305822573773,121.30952456742898,0.08046265585947623
0.08413149143682405,111.697029885607,0.26711748531191637,45.036242449876745,121.09426759894663,0.08077919772444492
0.08447329799006656,111.503074116908,0.26820272111846133,44.9580394839373,120.92210652359405,0.08109442948796358
0.08482033746207165,111.307797200945,0.2693045714420775,44.87930383142103,120.748962121689,0.08141438568872324
0.08517616661224106,111.102501883818,0.2704343289938654,44.796528759555414,120.5657870953109,0.08174233935380097
0.08551875360813875,110.887088673672,0.2715220427058405,44.709674153224555,120.37001428827959,0.0820579866569304
0.08586622515766326,110.663047364517,0.27262526487558086,44.619340697373254,120.16526550615175,0.08237803266985608
0.08621622208400656,110.425515668127,0.2737365051167208,44.52356791738881,119.94598645071119,0.08270030121893165
0.08656536797210845,110.231162068798,0.2748450433114443,44.44520454613936,119.77336317527663,0.08302168270771546
0.08691208324200135,109.984739241619,0.27594586429335427,44.34584686222078,119.5437420539364,0.08334072468594265
0.08725561437198445,109.721452803441,0.2770365756310506,44.23968977034741,119.29526557759193,0.08365673631027037
0.08759809895453886,109.467978411262,0.2781239641806609,44.13748889542084,119.05716521648505,0.08397168584759952
0.08794517597191195,109.219160696892,0.27922593371082044,44.03716559298686,118.8244590038847,0.08429075743244706
0.08828697394971295,108.970350080398,0.2803111422903386,43.936845152416474,118.59101253923721,0.08460487647588079
0.08863424980795696,108.698777153192,0.28141374314026335,43.82734694816701,118.33321172120745,0.084923928775431
0.08897854421432466,108.44234361548,0.2825068778804808,43.72395294576154,118.09138548157497,0.0852401414742008
0.08932884610353016,108.190963689472,0.28361908637870825,43.62259655959512,117.85553763468147,0.08556176907715733
0.08967463792360386,107.932684126447,0.28471697540744223,43.518458239783435,117.61150849560883,0.08587915436406582
0.09002083489566226,107.667481261754,0.2858161507937277,43.41152844473922,117.35979781605019,0.08619681064154751
0.09036606937895615,107.399538449745,0.2869122702781858,43.303493902937184,117.10481259256251,0.08651348332519089
0.09071863528819336,107.117845197699,0.28803166704001393,43.18991518371224,116.83542992904621,0.08683677742885754
0.09106938080330206,106.867577920747,0.289145284050484,43.08900741764519,116.59994206993807,0.08715829859914839
0.09141573716247196,106.598312760763,0.2902449654908485,42.980439705139645,116.34307610206389,0.08747569490964457
0.09175759676063015,106.30739839509,0.2913303697150007,42.86314303290029,116.06190978969833,0.08778887169285303
0.09210959936848155,105.994364965616,0.2924479779949289,42.73692795413637,115.7574634579155,0.08811123800846386
0.09246165951702126,105.692132770712,0.29356576896654246,42.61506793315109,115.4646027645854,0.08843355310819406
0.09280473679949176,105.394689605445,0.2946550393383863,42.495138848915424,115.17581603434245,0.08874754437797003
0.09315016599781135,105.085145184785,0.29575177704305106,42.370330538505314,114.87384390265183,0.08906358859347767
0.09349943432945365,104.75959262197,0.29686070399601533,42.23906774517831,114.55455527270821,0.08938304383181161
0.09385755734404566,104.438432793248,0.29799774456734496,42.1095761022376,114.24076898806253,0.08971049199793636
0.09421471482740545,104.134229744648,0.2991317195770123,41.98692143304207,113.94520650381153,0.09003695058074855
0.09457445755212845,103.853960445074,0.3002739027280078,41.873916851453835,113.67589241880707,0.09036566449481731
0.09493456138406846,103.565553879056,0.3014172323944173,41.75763132403539,113.39750431106228,0.09069460018959871
0.09530420770578106,103.255477330482,0.30259085946585484,41.632608459650335,113.09615878874583,0.09103213994137276
0.09567123110149765,102.919280780687,0.30375615874725503,41.497054010773,112.76569507705602,0.0913671719026159
0.09603573569755786,102.594408686834,0.3049134608397462,41.366065582531476,112.44713820353003,0.09169979355773916
0.09640478307653826,102.263385576696,0.30608518626800896,41.23259706452382,112.12206507988977,0.09203644796574312
0.09677571380971565,101.898760331324,0.30726289134584717,41.08558016558984,111.76008559871302,0.09237470625067754
0.09714429205658946,101.557649908309,0.30843312727967154,40.94804444303019,111.42339591158265,0.09271070596749119
0.09751254949932506,101.19779019511,0.309602344660357,40.802949006668356,111.06584472073297,0.09304630052534528
0.09788296729048386,100.820112928539,0.31077842114728627,40.65066953278693,110.68868474454608,0.09338375023938647
0.09825052206830875,100.469153982216,0.3119454075668803,40.50916288562949,110.34030081273002,0.09371847923745294
0.09862443328842085,100.067496397256,0.3131325756907362,40.34721454737362,109.93659652002646,0.09405888206539798
0.09898624231162086,99.6876651305101,0.3142813193393962,40.19406658062167,109.55537250659847,0.09438815697335706
0.09935517845371225,99.3183715953878,0.3154526915905364,40.04516742726036,109.18616612897966,0.09472380651538936
0.09972668215364505,98.9000685185253,0.31663221583782303,39.87650762666941,108.763044216646,0.0950616781609354
0.10009795063323415,98.489843143705,0.3178109932605184,39.711104755541854,108.34847460057857,0.0953992218701754
0.10046540540973706,98.0988731361059,0.31897766217591517,39.553465648477896,107.95441619596315,0.09573318615155733