File: example/data/02 processed data/test_ID_123.csv
Strain,Stress_MPa,Displacement(mm),Force(kN),True Stress (MPa),True Strain
2.66841698880831e-06,0.23158282538816,8.472223939466383e-06,0.046687097598253055,0.23158344334770556,2.668413428486512e-06
-7.31404159538754e-05,0.440652849784344,-0.00023222082065355436,0.08883561451652375,0.4406206202516195,-7.314309084450617e-05
-0.000133031332605,1.37299308454774,-0.000422374481020875,0.27679540584482437,1.372810433448045,-0.00013304018205757712
-0.0002120405224912,3.71285494541227,-0.0006732286589095599,0.7485115569951137,3.7120676697097106,-0.0002120630062612003
-0.0002343556528326,7.11855552323199,-0.000744079197743505,1.4351007934835693,7.116887249505118,-0.0002343831184098185
-0.0002024518640719,10.9891766467189,-0.0006427846684282824,2.2154180119785303,10.986951867422157,-0.0002024723602168636
-0.0001429688955695,15.0543649095065,-0.00045392624343316247,3.03495996575651,15.052212603581888,-0.00014297911659628292
-6.36139193655391e-05,19.0102537971111,-0.00020197419398558666,3.832467165497598,19.009044480358934,-6.361594281667263e-05
1.50544329437714e-05,23.4330202431094,4.779782459647419e-05,4.724096881010856,23.43337301394132,1.505431962696791e-05
0.0001046800887253,28.0881032870658,0.00033235928170282747,5.662561622672465,28.091043552210014,0.00010467461014705844
0.0002019896270727,32.9290305778618,0.0006413170659558225,6.638492564496939,32.93568190046809,0.00020196922991453712
0.000288671450099,37.6650511493062,0.000916531854064325,7.593274311700131,37.675923974239524,0.00028862979251258067
0.0003648290596412,42.4239301689182,0.00115833226436081,8.552664322053909,42.43940765146801,0.00036476252570166365
0.000458408358626,47.0761865726451,0.00145544653863755,9.490559213045252,47.097766690062244,0.00045830332161313594
0.0005374961316911,51.540690897461,0.0017065502181192425,10.390603284928138,51.56839381944307,0.0005373517323856768
0.0006511946029095,55.8535504608796,0.0020675428642376622,11.260075772913329,55.88992199149306,0.0006509826677064749
0.000738315988464,60.238688216824,0.0023441532633732,12.14411954451172,60.28316340345858,0.0007380435672949124
0.0008289035691673,64.422710882978,0.0026317688321061774,12.987618514008364,64.47611109796433,0.0008285602183272181
0.0009067473577485,68.5846360133347,0.0028789228608514877,13.826662620288275,68.64682495082194,0.0009063365107005951
0.0009948048420052,72.8989168571485,0.0031585053733665094,14.696421638401139,72.97143705261493,0.000994310351588833
0.0010950627246825,76.9963680352133,0.003476824150866937,15.522467795898999,77.08068388778459,0.0010944635808570655
0.0011801173866519,81.1662311790574,0.0037468727026197823,16.363112205697973,81.26201685968081,0.001179421595485143
0.0012773726692589,85.1329090144374,0.0040556582248970074,17.162794457310582,85.24165546566695,0.0012765575228808569
0.0013803642990642,88.9845351779545,0.004382656649528835,17.939282291875628,89.10736625348297,0.0013794124720764324
0.0014635743032771,92.8447826136629,0.004646848412904792,18.717508174914443,92.98066785168962,0.0014625043222771085
0.0015713418308976,96.5310551654126,0.00498901031309988,19.46066072134718,96.68273845037469,0.0015701085650752335
0.0016608916711538,100.249967361872,0.005273331055913315,20.210393420153395,100.41647169769676,0.0016595139159059948
0.0017435238506133,103.918628030938,0.005535688225697227,20.949995411037097,104.09981263743296,0.0017420056772959915
0.0018347734627473,107.556387546238,0.005825405744222677,21.68336772932158,107.7537291518568,0.0018330923219450803
0.0019127241827104,111.151777116182,0.006072899280105519,22.408198266622293,111.36437980822336,0.0019108972550456868
0.0020028395228092,114.690325434313,0.006359015484919211,23.1215696075575,114.92003175097668,0.002000836513756606
0.0020879800005922,118.381101727179,0.006629336501880235,23.86563010819929,118.62827910003342,0.002085803199901642
0.0021700696772004,121.832493644233,0.00688997122511127,24.56143071867737,122.09687864438807,0.002167718476896414
0.0022574131353259,125.288880937433,0.007167286704659732,25.258238396986496,125.57170970297145,0.0022548690063415307
0.0023471926695295,128.615520119052,0.007452336725756162,25.928888856000885,128.91740552506317,0.0023444423157150457
0.0024451361103441,131.952864575841,0.007763307150342517,26.60169749848955,132.27550728987873,0.0024421516290304333
0.0025378735209506,135.351240978371,0.008057748429018154,27.2868101812396,135.69474530887783,0.00253465855824351
0.002620493906608,138.624625821459,0.008320068153480398,27.946724565606136,138.98789080872993,0.00261706639898674
0.0026946451251793,142.003042487386,0.008555498272444277,28.62781336545702,142.38569029358527,0.0026910210778916706
0.0027807369014051,145.363066430269,0.008828839661961192,29.305194192342228,145.767282873193,0.002776877804980135
0.002850421124186,148.618215354585,0.00905008706929055,29.961432215484336,149.04183985507055,0.0028463663772235123
0.0029423376647831,151.890040045079,0.00934192208568634,30.621032073087928,152.33695183080903,0.002938017461572699
0.0030266438713584,155.173482924707,0.009609594291562919,31.282974157620934,155.6431377957984,0.0030220728057988883
0.0031147277654408,158.537107549585,0.00988926065527454,31.961080881996338,159.03090748032236,0.003109887049983656
0.0032170402409206,161.902862411001,0.010214102764922904,32.6396170620578,162.42371043449742,0.003211876638345816
0.0032913728010221,165.474688942705,0.010450108643245167,33.359697290849326,166.01932783314862,0.003285968089597595
0.0033793456647577,168.752031752618,0.010729422485605697,34.020409601327785,169.32230319954027,0.003373648507697422
0.0034604540076909,171.979727423912,0.010986941474418607,34.671113048660665,172.57485536091767,0.003454480413652713
0.0035522064824183,175.039278270746,0.011278255581678102,35.28791849938239,175.66105392969715,0.003545912298062444
0.0036492251984442,178.246468462332,0.011586290005060335,35.93448804200613,178.8969299665784,0.0036425829306856623
0.0037491632049574,181.479884854268,0.011903593175739744,36.58634478662043,182.1602825610035,0.0037421526097021463
0.0038558530713163,184.689808891512,0.012242333501429252,37.23346547252882,185.40194565836714,0.003848438323868365
0.0039608949014056,187.861525672109,0.01257584131196278,37.87288357549718,188.60562543131394,0.003953071209604882
0.0040670879121763,191.02291747779,0.012913004121159753,38.51022016352246,191.79982447641257,0.004058839666796243
0.0041714177783078,194.101654456069,0.013244251446127266,39.130893538343514,194.91133354826604,0.004162741534955685
0.0042856458407895,196.950054116072,0.01360692554450666,39.70513090980012,197.79411229633783,0.004276488614416837
0.0044183878137305,199.636532783809,0.014028381308594335,40.2467250092159,200.51860440743638,0.004408655395495692
0.0045691111310221,202.194912856649,0.014506927840995167,40.76249443190044,203.11876388361839,0.004558704430299217
0.0047428268362409,204.620018655366,0.015058475205064856,41.25139576092179,205.5904959710768,0.004731615069378164
0.0049449861593216,206.650616650931,0.01570033105584608,41.66076431682769,207.67250109008512,0.004932799872764421
0.0051758593293306,208.324325756521,0.016433353370624654,41.99818407251463,209.40258316151437,0.005162510610347464
0.0054434231507474,209.581996691195,0.017282868503622994,42.25173053294491,210.7228401839637,0.005428661268831452
0.0057459945234635,210.413856865804,0.01824353261199661,42.41943354414609,211.62289373501574,0.005729549263109678
0.0060559374983544,211.013761578782,0.01922760155727522,42.540374334282454,212.29164773019576,0.006037674006813105
0.0063906247766963,211.258512961226,0.02029023366601075,42.589716212983156,212.60858684844402,0.006370291317206824
0.006742989477238,211.331962991235,0.021408991590230648,42.60452373903298,212.75697219388894,0.006720357206172342
0.0071108844662052,211.270836863137,0.022577058180201507,42.59220071160842,212.77315937514922,0.007085721344871565
0.007483936254535,211.15610394554,0.023761497608148625,42.569070555420865,212.73638276722437,0.007456070547358125
0.0078697109017252,211.025289780104,0.02498633211297751,42.542698419668966,212.6859978036262,0.00783890623720967
0.008256950698438,210.834290702021,0.026215818467540647,42.50419300552743,212.57513904588774,0.008223048571965
0.0086545194865833,210.633385323909,0.02747809936990198,42.463690481300056,212.45631606171978,0.008617283816467808
0.0090554203267622,210.410505813838,0.028750959537469985,42.41875797206974,212.31586138514893,0.009014665855921452
0.0094554295179058,210.187008925934,0.03002098871935091,42.37370099946829,212.17441737441263,0.009411006748922753
0.0098577996090313,209.984693837511,0.03129851375867437,42.332914277642224,212.05468087032494,0.009809528474672684
0.0102636924005145,209.743087225839,0.032587223371633535,42.28420638472914,211.89582575625926,0.010211378361969795
0.0106658160255641,209.435297376818,0.03386396588116601,42.222155951166506,211.66909572789845,0.01060933744830133
0.0110563381537129,209.144328200706,0.035103873638038456,42.16349656526233,211.45669861622414,0.010995663662512912
0.011445510288314,208.779427229992,0.036339495165396946,42.08993252956639,211.16901431234118,0.011380505970275376
0.0118481846252083,208.537129765774,0.037617986185036346,42.041085360780045,211.00791618044994,0.011778544419387442
0.0122649431976119,208.36117900143,0.03894119465241778,42.005613686688285,210.91671702646997,0.01219033817988846
0.0126875131313772,208.26232628976,0.04028285419212261,41.98568498001562,210.90465728933253,0.012607701005942683
0.0131176395768698,208.145198380285,0.04164850565656161,41.96207199346545,210.87557207229364,0.013032348412314404
0.0135365998305149,208.005595285586,0.04297870446188481,41.93392800957414,210.821283791475,0.013445798572155884
0.0139561080736629,207.785692904807,0.04431064313387971,41.889595689609095,210.68557249114744,0.01385961830871952
0.0143660795871723,207.575277104432,0.04561230268927205,41.84717586425349,210.5573200556436,0.014263865248960388
0.0147887545151395,207.333864268284,0.04695429558556791,41.79850703648605,210.40007388962292,0.014680467202617998
0.0152059030588791,207.085757920005,0.04827874221194114,41.74848879667301,210.23468387981112,0.01509145207694257
0.0156269365291732,206.841076893654,0.04961552348012491,41.699161101760644,210.07336927389696,0.015506093270564163
0.0160462567853831,206.648536359111,0.05094686529359134,41.66034492999678,209.9644718378529,0.01591887645197716
0.0164757437542155,206.489073448429,0.05231048641963421,41.628197207203286,209.8911345106107,0.01634149128725144
0.0168931789555713,206.406169458793,0.05363584318393888,41.61148376289267,209.89302581699434,0.016752076107898445
0.0173249284611735,206.268568534454,0.055006647864225856,41.58374341654593,209.84215672810205,0.017176563050091114
0.0177555590896716,206.136765017651,0.05637390010970733,41.55717182755844,209.79683852947565,0.01759977052277817
0.018198557088698,205.988640696126,0.05778041875661615,41.527309964339004,209.73733673345774,0.01803494536537142
0.018633016663986,205.803965183743,0.05915982790815555,41.49007938104259,209.6387138965261,0.018461548710955462
0.0190676842864579,205.603153052402,0.06053989760950383,41.44959565536425,209.52352906310549,0.01888817429817919
0.019500747028809,205.342766275791,0.06191487181646857,41.397101681199466,209.3471036151311,0.019313043772476217
0.01993647023459,205.086698571145,0.06329829299482326,41.34547843194284,209.17540343271898,0.01974034127271044
0.0203684592183877,204.892450326448,0.06466985801838095,41.30631798581192,209.0657938450778,0.020163796594527033
0.0208125995506616,204.730642353013,0.06608000357335057,41.27369749836742,208.99161922805598,0.020598976352221906
0.0212421075722574,204.627479862868,0.06744369154191725,41.25289994035419,208.97419880235495,0.02101963895879285
0.0216800415697153,204.509845146272,0.06883413198384607,41.22918478148844,208.94362709045922,0.021448371893476748
0.0221218036788846,204.359342049699,0.0702367266804586,41.198843357219324,208.88013929446848,0.02188066636182347
0.0225563532571998,204.204151805901,0.07161642159160936,41.16755700406964,208.81025279062175,0.02230572062611789
0.0229891904881545,203.932834901535,0.07299067979989053,41.112859516149456,208.62108568987574,0.022728920430921343
0.0234256922377022,203.709804762063,0.07437657285470448,41.0678966400319,208.4818479542215,0.023155521859451057
0.0238604101227091,203.523074795636,0.07575680213960138,41.03025187880022,208.37921882969468,0.02358019908559848
0.024304958199791,203.383178472585,0.07716824228433643,41.00204878007314,208.3263981239018,0.024014293022482806
0.0247441551620774,203.307829872809,0.07856269263959574,40.9868585023583,208.33851036084704,0.024442976714004375
0.0251884028811555,203.158361425576,0.07997317914766872,40.95672566339612,208.2755960818388,0.024876403388740188
0.0256289669099015,203.016065292377,0.08137196993893726,40.9280387629432,208.2191573119337,0.025306050652326644
0.0260756504122868,202.877157509853,0.08279019005901059,40.90003495398636,208.16731134571836,0.025741477375717036
0.0265365351128961,202.734801530314,0.08425349898344511,40.871335988511305,208.1146807097292,0.026190548770308592
0.0269923670928593,202.576840017405,0.08570076551982828,40.83949094750885,208.04486844766623,0.026634498682053528
0.0274441212723297,202.391550822754,0.08713508503964679,40.80213664586721,207.94600908802855,0.02707428271948662
0.0278968768898402,202.203348539697,0.08857258412524263,40.76419506560292,207.84419046062237,0.027514847691662556
0.0283355584225775,202.022557051631,0.08996539799168356,40.72774750160881,207.74697901964598,0.02794153246898557
0.0287920477457131,201.792017443994,0.09141475159263909,40.68127071670919,207.60202284494525,0.028385344830707485
0.0292382884733184,201.636895108172,0.09283156590278592,40.64999805380748,207.532412814209,0.028819002903424224
0.0297040977873482,201.475325179087,0.09431051047483052,40.61742555610394,207.4599679399444,0.02927147726607302
0.0301666948096792,201.365901448886,0.09577925602073145,40.59536573209542,207.4404451429705,0.02972062876797356
0.0306308005485837,201.249383042725,0.09725279174175323,40.571875621413355,207.41381275523224,0.030171042501293873
0.0310979931588384,201.104498906186,0.09873612827931191,40.5426669794871,207.3584452373822,0.030624247228973972
0.031559282448623,200.959800343197,0.10020072177437803,40.513495749188515,207.30194744304686,0.03107152395587383
0.0320227333812155,200.797929420393,0.10167217848535921,40.48086257115123,207.22802797772238,0.031520695286917894
0.0324847360572034,200.628556311406,0.1031390369816208,40.44671695237945,207.14592200871977,0.031968262264067876
0.0329568289316457,200.431357071462,0.10463793185797508,40.406961585606744,207.0369390190038,0.03242539732967902
0.0334207617219319,200.257877408946,0.10611091846713379,40.371988085643515,206.95064821277026,0.03287442736192462
0.0338881319110029,200.090462856403,0.1075948188174342,40.33823731185085,206.87115485581444,0.03332658059211961
0.0343338792593616,200.020152794488,0.10901006664847307,40.32406280336878,206.887620569973,0.033757624602726514
0.0347916975166366,199.811438825666,0.1104636396153212,40.281986067254266,206.7632179656525,0.03420014802410304
0.0352481276799885,199.50704074221,0.11191280538396348,40.220619413629535,206.53929038734807,0.03464113487391429
0.0357019535728441,199.255090443895,0.11335370259378001,40.16982623348923,206.36888643207578,0.03507941284519736
0.0361732864477357,199.09085579339,0.11485018447156084,40.13671652794743,206.29262634912916,0.03553439476101765
0.0366241677388303,199.089057300176,0.1162817325707862,40.136353951715485,206.38052832970325,0.03596944093235994
0.0370858697925624,198.976137252636,0.11774763659138561,40.11358927013141,206.3553403706143,0.03641473179077784
0.0375449237712097,198.767183274731,0.1192051329735908,40.07146414818577,206.22988201899886,0.036857272205740636
0.0380064975942841,198.585238988364,0.12067062986185202,40.03478418005419,206.13276839623563,0.03730204444884884
0.0384755284802234,198.408509519917,0.12215980292470928,39.99915551921527,206.04238177866924,0.03775379976194696
0.0389500024567127,198.295580194479,0.12366625780006281,39.976388967206965,206.0191935302092,0.0382105901283631
0.0394285672208404,198.208684229454,0.12518570092616826,39.95887074065793,206.02376865934934,0.03867110755244296
0.0399128524954619,198.101601975594,0.12672330667309153,39.93728295827975,206.0084019943606,0.03913691396478694
0.0403990825235835,197.961219100867,0.1282670870123776,39.90898177073478,205.95867072779214,0.039604372742281624
0.0408831785865111,197.814960089014,0.12980409201217274,39.879495953945224,205.90226442941673,0.04006956295766287
0.0413856351544401,197.642562993452,0.1313993916153473,39.84474069947993,205.82212599648747,0.04055216786858067
0.0418768127318963,197.502530090389,0.13295888042377074,39.81651006622242,205.77330655705993,0.04102371439605329
0.0423622027849342,197.365954365969,0.1344999938421661,39.78897640017935,205.72681094766224,0.0414894863715316
0.0428528678384915,197.19172723234,0.13605785538721052,39.753852210039746,205.64195825827133,0.0419600997576764
0.0433414183483702,197.001905246617,0.1376090032560754,39.71558409771799,205.54024723733664,0.04242846506961747
0.0438252357024586,196.735661652738,0.13914512335530604,39.66190938919198,205.3576483957484,0.04289207669527776
0.0443049264829062,196.429115400674,0.14066814158322719,39.60010966477588,205.13189291760318,0.043351521989994216
0.0447833358166419,196.210329470667,0.142187091217838,39.556002421286465,204.99728254604582,0.04380952977332452
0.0452551870072486,196.072516511278,0.1436852187480143,39.52821932867364,204.94581491297774,0.04426105369833406
0.0457273925398981,195.964485463717,0.14518447131417644,39.50644026948535,204.92543041439552,0.04471271268898808
0.0461884296040054,195.79445894123,0.14664826399271713,39.47216292255197,204.83789752489133,0.045153492443786566
0.0466763972465958,195.578868989754,0.14819756125794165,39.42869998833441,204.70778597175968,0.04561980794125431
0.0471652396845115,195.287667835009,0.149749635998324,39.36999383553781,204.49845749587644,0.046086741484054526
0.0476545071786092,195.135361302207,0.1513030602920842,39.33928883852493,204.43444077818353,0.046553862823469995
0.0481393941305874,194.985950689803,0.15284257636461498,39.309167659064286,204.3724562199867,0.04701658672044008
0.0486291704667578,194.880389636959,0.154397616231956,39.28788655081094,204.35726132524286,0.04748375925759827
0.0491241249245828,194.802085722645,0.15596909663555036,39.27210048168523,204.3715677172535,0.04795564932026398
0.049624725232146,194.697367539534,0.15755850261206353,39.25098929597006,204.35917090710552,0.04843269574439365
0.0501289193830606,194.608780268303,0.15915931904121738,39.23313010208989,204.36430812560852,0.04891293699735947
0.050640316944379,194.479495630602,0.16078300629840334,39.20706631912936,204.32799892851867,0.04939980396263764
0.0511447643801731,194.318987233372,0.16238462690704958,39.174707826247804,204.25738605001666,0.049879822067212115
0.0516478550659819,194.093693084109,0.16398193983449252,39.12928852575637,204.11821601373822,0.05035831974763507
0.0521550810331326,193.862634771813,0.165592382280196,39.0827071699975,203.97355619763348,0.050840518881665644
0.0526599670114252,193.663297732676,0.167195395261275,39.042520822907484,203.86160060260252,0.051320262684756646
0.0531608416239086,193.49631345629,0.16878567215590978,39.008856792788066,203.78274033075004,0.051795967568928195
0.0536803834245084,193.361122368467,0.17043521737281417,38.98160226948295,203.74082155659957,0.052289162599435425
0.0541717413647014,193.131323090301,0.17199527883292695,38.93527473500468,203.59358317417139,0.05275537931674167
0.0546623435014815,192.920709491381,0.17355294061720375,38.892815033462405,203.46620758214837,0.05322066214686248
0.0551614495599909,192.700932073751,0.1751376023529711,38.84850790606821,203.33059481850043,0.05369378797799688
0.0556311369316311,192.593672900513,0.17662885975792875,38.82688445674342,203.30787788980723,0.05413882211578775
0.0561331760452281,192.398002923221,0.1782228339435992,38.787437389321354,203.19791389206048,0.05461429101160156
0.0566404142933637,192.231573231232,0.17983331538142974,38.75388516341637,203.11964917931405,0.055094454395127945
0.0571429439352937,191.999966805678,0.18142884699455747,38.70719330802469,202.97141014443312,0.05556993325576093
0.0576420026051711,191.800802366627,0.18301335827141824,38.66704175711201,202.85658471631805,0.05604190434668238
0.0581437817285271,191.624766682231,0.18460650698807352,38.63155296313777,202.7665552899826,0.05651622375697316
0.0586517212962715,191.480850846367,0.186219215115662,38.60253953062759,202.71153234378102,0.0569961374536599
0.0591706057473603,191.359729246261,0.18786667324786893,38.578121416046216,202.6826003414131,0.05748615444408033
0.0596812427525332,191.202217001912,0.1894879457392929,38.54636694758546,202.61340292962566,0.05796814851593622
0.060184433625323,190.984345716705,0.1910855767604005,38.50244409648773,202.47863039496778,0.05844288697493154
0.0606838371055627,190.773133436086,0.19267118281016157,38.45986370071494,202.3499791896392,0.05891382946236634
0.0611919665747128,190.571369236493,0.19428449387471314,38.41918803807699,202.23280609290973,0.05939277311965476
0.0616969284827977,190.377454278837,0.1958877479328827,38.38009478261354,202.1231584602155,0.059868504015213396
0.0622262943321777,190.16153721519,0.1975684845046642,38.33656590258231,201.99458500060177,0.06036698329606026
0.0627311060580758,189.952715622752,0.19917126173439068,38.29446746954681,201.86865957250237,0.060842109748291226
0.0632367525790957,189.740548810169,0.2007766894386288,38.251694640130076,201.7391249494995,0.061317795707982875
0.0637299601052928,189.554255138838,0.20234262333430464,38.21413783598974,201.6345402566246,0.06178156181404891
0.0642352047424824,189.349266986683,0.2039467750573816,38.1728122245153,201.51215591941155,0.062256423578733726
0.0647470982834863,189.144187427743,0.20557203705006902,38.131468185432986,201.39072472087722,0.06273730456129606
0.0652588712806191,188.960673227497,0.20719691631596562,38.0944717226634,201.29203347874935,0.06321784124926172
0.0657746009352008,188.775166571395,0.2088343579692625,38.05707358079324,201.19177781910454,0.06370185961065698
0.0662727359582932,188.573071564065,0.21041593666758088,38.016331227315504,201.07032494467458,0.06416914288672373
0.0667691632089585,188.361577640772,0.21199209318844323,37.973694052379635,200.9383225605656,0.06463460702957252
0.0672523802667833,188.099383872703,0.21352630734703698,37.92083578873692,200.74951516485766,0.06508747693387201
0.0677655738605575,187.857429597147,0.21515569700727002,37.87205780678483,200.58769611776694,0.06556821631375961
0.0682777227195766,187.661016951419,0.2167817696346557,37.83246101740607,200.47408383210174,0.06604774673306614
0.0687967619346523,187.479497343284,0.21842971914252104,37.795866664406056,200.3774796896382,0.06653349416864549
0.0693178961245184,187.345833787278,0.2200843201953459,37.76892009151524,200.33225283310583,0.06702096493942147
0.0698407015814807,187.193621452427,0.2217442275212012,37.738234084809285,200.26735530624262,0.06750976036387657
0.0703630782990559,187.020747254611,0.22340277359950247,37.703382646529576,200.18010273723513,0.0679979164290694
0.070879889007362,186.841761370216,0.22504364759837434,37.66729909223555,200.08508467807695,0.06848063672399408
0.0713889502857152,186.591730973035,0.22665991715714573,37.61689296416386,199.91231877919455,0.06895589106985181
0.0718883093862542,186.296214613415,0.2282453823013571,37.55731686606447,199.68873452703218,0.06942186821519883
0.0723834931671152,186.032140379176,0.22981759080559075,37.50407950044188,199.49779654117592,0.06988373483963907
0.0728997799685673,185.793579085447,0.23145680140020114,37.45598554362612,199.3378901203487,0.07036505757951657
0.0734268694091564,185.622804935916,0.23313031037407153,37.42155747508067,199.25250639330685,0.07085621250352395
0.0739646694817729,185.441047470547,0.23483782560462893,37.38491517006228,199.15713325505976,0.07135709934611446
0.0744802810007122,185.21241538312,0.23647489217726123,37.338822941237,199.0070881256754,0.07183708514116374
0.0749875826054766,184.9699193407,0.23808557477238818,37.28993573908512,198.8403664467891,0.07230911044823919
0.0754782944414294,184.564525023711,0.2396435848515383,37.20820824478014,198.49514058689323,0.07276548769161467
0.0759608305850621,184.201905371135,0.24117563710757217,37.13510412282082,198.19403509847743,0.0732140582750077
0.0764371626566077,183.877970108646,0.24268799143472944,37.06979877390304,197.9330804188074,0.07365666422503857
0.0769188370497728,183.59035479126,0.24421730763302862,37.01181552591802,197.71191137535894,0.07410403512076087
0.0774153934083797,183.40557195153,0.24579387407160555,36.97456330542845,197.60398645744658,0.07456501871409552
0.0779158799248312,183.199373306582,0.24738291876133905,36.93299365860693,197.47351367944196,0.07502943597713005
0.078414048499632,183.025764813827,0.2489646039863316,36.89799418646753,197.3775560126207,0.07549148826059282
0.0789171809646734,182.876331170406,0.250562049562838,36.867868363953846,197.30841569153645,0.07595792796840559
0.0794253361221948,182.676040363367,0.25217544218796845,36.827489737254794,197.18514627069905,0.07642880333956445
0.0799360715580118,182.403468104844,0.25379702719668745,36.77253916993655,196.98408478370231,0.07690184638231248
0.0804542083143379,182.123106762585,0.2554421113980228,36.71601832333714,196.7756771329164,0.07738151597820717
0.0809567587512581,181.809051510149,0.2570377090352445,36.652704784446044,196.5277230320512,0.07784653670183077
0.0814561943566841,181.457689424954,0.258623417082472,36.581870188070724,196.23854224226787,0.07830846106608201
0.0819527671980363,181.13643588037,0.2602000358537653,36.51710547348259,195.98106804115596,0.07876752623489412
0.082441495333444,180.849067245915,0.2617517476836847,36.459171956776466,195.7585347793268,0.07921913355263158
0.0829352718958458,180.591430251115,0.2633194882693104,36.40723233862479,195.56882962105092,0.07967519882351949
0.0834307108707263,180.37278305297,0.26489250701455597,36.36315306347875,195.4214125648106,0.08013259059153952
0.0839206315363979,180.053763641787,0.2664480051280633,36.29883875018425,195.16398919711105,0.08058468219702122
0.0844199801789562,179.645675834097,0.26803343706818594,36.21656824815396,194.81136022724667,0.0810452635731094
0.0849208885549491,179.246029899919,0.2696238211619634,36.13599962782367,194.4677620289671,0.08150707055984392
0.08541612394821,178.90510074071,0.27119619353556673,36.06726830932714,194.18648100054548,0.0819634378419787
0.0859072051039067,178.596460131844,0.27275537620490375,36.005046362579755,193.93918286322202,0.0824157713636603
0.0863907596730493,178.30254802212,0.27429066196193147,35.945793681259396,193.7062405973913,0.08286097233053515
0.0868813083972134,177.958126256732,0.27584815416115255,35.876358253357175,193.41936110583333,0.08331241027031465
0.0873657816038147,177.569015788803,0.27738635659211164,35.79791358302269,193.08247164181188,0.08375805714904105
0.0878464010379567,177.308848625492,0.2789123232955125,35.74546388289919,192.88479284942534,0.08419996295096574
0.0883335623572713,176.988544794602,0.2804590604843364,35.68089063059177,192.62257345273872,0.08464768449573398
0.0887978181802987,176.567422460397,0.28193307272244833,35.595992368016034,192.2462243365993,0.08507416847755919
0.0892711502447992,176.012770171915,0.28343590202723745,35.48417446665807,191.72563262293534,0.08550880308170956
0.0897391897426418,175.571647590218,0.28492192743288774,35.39524415418795,191.32730498674482,0.08593839214464473
0.0902242438648712,175.163491282016,0.28646197427096604,35.312959842454426,190.96748483566685,0.08638340339827988
0.0907033732996011,174.84656716322,0.28798321022623347,35.24906794010515,190.70574061477927,0.08682278473186206
0.0911971256717454,174.430018271314,0.2895508740077916,35.165091683496904,190.33753456852787,0.08727537400511759
0.0916854513931809,173.993886434609,0.29110130817334934,35.077167505217176,189.94659445201998,0.08772278765412667
0.0921792758187044,173.547920493954,0.29266920072438646,34.98726077158113,189.54544212492874,0.08817503584311655
0.0926807819119527,173.119852397948,0.2942614825704498,34.900962243426314,189.16473568267165,0.08863410973234023
0.0931734928768958,172.622245054019,0.2958258398841442,34.80064460289023,188.70606257395343,0.08908492750090866
0.0936529899254947,172.068722065029,0.29734824301344565,34.68905436830985,188.1834723590779,0.08952345983079771
0.0941522912090465,171.481301940916,0.29893352458872263,34.570630471288666,187.62665941816357,0.08997990016991361
0.0946516191802426,170.956704069376,0.30051889089727024,34.464871540386206,187.13803291926,0.09043615664632818
0.0951523890431167,170.428383468604,0.30210883521189547,34.35836210727057,186.6450513163981,0.09089352166139153
0.0956435478802403,169.813277348775,0.303668264519763,34.23435671351304,186.05482167158306,0.09134190559078854
0.0961096852150733,169.061320816376,0.3051482505578577,34.082762276581406,185.30975114208243,0.0917672612693591
0.0965817252821985,168.239763926673,0.3066469777709802,33.91713640761728,184.48865058778085,0.09219781895947234
0.0970548481397922,167.535027824637,0.3081491428438402,33.77506160944682,183.79511450825302,0.0926291783474969
0.0975342249866644,166.879071853357,0.30967116433265945,33.64282088563677,183.15549279306808,0.0930660499790627
0.0980175450293878,166.381926922977,0.3112057054683062,33.54259646767216,182.6902749372262,0.09350632203926297
0.0985087044967728,165.675657737978,0.31276513677725365,33.40021259997637,181.99615214839696,0.09395353679545071
0.0989889480872359,164.79889387868,0.314289910176974,33.22345700594189,181.11216302967054,0.09439061903537391
0.0994670717957127,163.948767456708,0.3158079529513878,33.05207151927233,180.25627128014298,0.09482558222016427
0.0999573525992791,163.028146927395,0.3173645945027111,32.86647442056283,179.32400889342372,0.09527140868844321
0.100454167835889,162.142077274161,0.31894198287894754,32.68784277847086,178.42992471791928,0.09572297444370136
0.100943657359031,161.155243818226,0.3204961121149234,32.488897153754365,177.42284353182413,0.09616768237028037
0.101426032170055,160.171379757403,0.3220276521399246,32.29055015909245,176.41692727339947,0.09660573309448983
0.101891637260557,159.002033350129,0.3235059483022685,32.05480992338601,175.20301085593132,0.09702837310132362
0.10237057343159,157.808815987558,0.3250265706452983,31.814257303091697,173.9637949727646,0.09746292773483929
0.102842247160202,156.601576150483,0.32652413473364134,31.570877751937374,172.70683415062817,0.09789070842920167
0.103317500830204,155.310716257173,0.3280330651358977,31.31064039744608,171.35703131301307,0.09832155091718252
0.103818748551946,154.079447537825,0.32962452665242853,31.06241662362552,170.07578295877718,0.09877575734009784
0.104361652021515,152.769025843968,0.3313482451683101,30.798235610143948,168.71225375876202,0.09926747756401341
0.104948521555975,151.199183210464,0.3332115559402206,30.481755335229547,167.06731394887322,0.09979874705734436
0.105603413833066,149.164318722885,0.3352908389199845,30.071526654533617,164.91658000210518,0.10039126179157537
0.106315179443886,146.328758426088,0.337550694734338,29.499877698699343,161.88572663595858,0.10103483487563943
0.107063389944159,142.675783267431,0.3399262630727048,28.76343790671409,157.9511362869803,0.10171091490923229
0.107946561893487,138.551420603209,0.34273033401182124,27.931966393606935,153.50757010278386,0.10250835782401198
0.108943494327774,133.396724770411,0.34589559449068247,26.89277971371486,147.9294300987799,0.10340775515649787
0.109473272904531,130.812609321408,0.3475776414718859,26.371822039195848,145.13309380100426,0.10388537378492978
0.109774842672549,129.415850940447,0.34853512548534304,26.09023554959412,143.6224556167686,0.10415715030938189