File: example/data/02 processed data/test_ID_079.csv
Strain,Stress_MPa,Displacement(mm),Force(kN),True Stress (MPa),True Strain
-6.767761366725966e-05,0.10279082704252,3.144647460122838e-05,0.020722630731772,0.1027918451241363,9.904352400952058e-06
-6.0220570239391455e-05,0.106506255965614,5.5122587484709946e-05,0.0214716612026677,0.106508105068106,1.736129416893337e-05
-6.576643537075695e-05,0.109258493657584,3.751446569262449e-05,0.0220265123213689,0.1092597846100287,1.1815509942309483e-05
-6.475456096199225e-05,0.113485546528222,4.0727166940452406e-05,0.0228786861800895,0.1134870022588672,1.2827371883342828e-05
-6.109552051532276e-05,0.119770556677971,5.234462035862807e-05,0.0241457442262789,0.119772531274607,1.6486358700306116e-05
-5.663275740079786e-05,0.126340133456693,6.651389324724462e-05,0.0254701709048693,0.1263427801887086,2.094903828303968e-05
-4.0671314486112754e-05,0.139489156006562,0.0001171914745013,0.0281210138509229,0.1394943046490405,3.691001944723955e-05
-2.8672637458680554e-05,0.290983877213421,0.0001552872740634,0.0586623496462256,0.290998109053764,4.890818163327711e-05
-1.9568997269788458e-05,0.685852357413888,0.0001841913316631,0.1382678352546398,0.6858921457789388,5.801133515665046e-05
4.218742001785446e-06,1.41092854458705,0.0002597174038504,0.2844431945887493,1.4110439596102369,8.179741161867583e-05
3.097850263613454e-05,2.51464738683258,0.0003446796438645,0.5069529131854481,2.51492037825486,0.000108554625486
6.561829182213455e-05,4.01383758295543,0.00045466097453,0.8091896567238148,4.014412365729311,0.0001431900547533
0.00010500964672339956,5.96145007431289,0.000579728526342,1.201828334981479,5.962538585388936,0.0001825749940115
0.00013501438258449957,8.22298039519074,0.0006749935627009,1.6577528476704533,8.224728571201124,0.0002125738022893
0.00017398660173809956,10.6982949607779,0.0007987303585136,2.1567762640928247,10.700986316043888,0.0002515369787762
0.00022069440252359956,13.2855561188765,0.0009470276260076,2.678368113565502,13.289518886961996,0.0002982319420733
0.00027023195954409957,16.0025489633756,0.0011043093695477,3.226113871016521,16.008114873535252,0.000347753501402
0.00031717714084079956,18.7972423077654,0.0012533603201647,3.7895240492455047,18.80466269127314,0.0003946812590614
0.0003567645722600996,21.6013045782479,0.001379050414921,4.3548230029747765,21.610687031174344,0.0004342522862029
0.00040133500408009955,24.3844666618542,0.0015205615359495,4.915908479029808,24.3961447979426,0.000478802375043
0.0004508692723814996,27.2706875412811,0.0016778328378064,5.49777060832227,27.285098771223247,0.0005283117062889
0.0005014207166503995,30.1942788184435,0.0018383336733602,6.08716660979821,30.21176138836311,0.0005788351743595
0.0005493385031491995,33.1841755139918,0.0019904726454939,6.689929783620747,33.20497935450326,0.0006267240856918
0.0005911353795359995,36.1458152335283,0.002123177728022,7.286996351079306,36.16998656891887,0.0006684939028054
0.0006347952654723996,39.1266603167241,0.00226179786587,7.887934719851578,39.15453326059906,0.0007121236603358
0.0006886840489372996,42.1196860916725,0.0024328947533711,8.491328716081176,42.15196097775316,0.0007659726321018
0.0007332260381677996,45.0628480454248,0.0025743155691779,9.08467016595764,45.099385365523965,0.0008104795260045
0.0007776551663626996,48.0324911172905,0.0027153780511967,9.683350209245765,48.07357028961308,0.000854871674543
0.0008246272783400995,51.0216711733904,0.002864514506725,10.285968908555503,51.06770339929073,0.0009018025472805
0.0008688621908030995,54.0240315572532,0.003004960353795,10.891244761942248,54.07516228890099,0.0009459966099963
0.0009208110201585996,57.0702426300868,0.0031698978869987,11.5053609142255,57.12722116285015,0.0009978949724295
0.0009744455645170995,60.0654996784831,0.0033401875653369,12.109204735182193,60.12869024072935,0.0010514745864283
0.0010193377873964995,63.1087402647023,0.003482720372979,12.722722037363985,63.1779654916103,0.0010963186255748
0.0010714303340843996,66.2343515951398,0.0036481142087131,13.352845281580183,66.31045568306394,0.0011483527397296
0.0011196720508332995,69.3417039598409,0.0038012816593909,13.979287518303924,69.42472359684672,0.0011965379288424
0.0011679388850570995,72.4936386006396,0.0039545288580514,14.614717541888943,72.58393094264633,0.0012447458824842
0.0012235305608797997,75.6434827453221,0.0041310324287885,15.249726121456936,75.7419034320142,0.001300266862528
0.0012764031426080995,78.7786826189758,0.0042989028757759,15.88178241598552,78.885347785987,0.001353069346391
0.0013241101948272996,81.9422714984571,0.0044503727665718,16.51956193408895,82.0571293420816,0.0014007107564415
0.0013810252233068996,85.0702337478546,0.0046310779819946,17.150159123567487,85.19431780657361,0.0014575445041679
0.0014338667818950997,88.1762133773643,0.0047988499305121,17.776324616876643,88.30948720899856,0.0015103077079323
0.0014877403533411996,91.2900897388386,0.0049698985198535,18.404082091349864,91.43298815832532,0.0015640985283688
0.0015381612051198995,94.3984536752632,0.0051299847242508,19.03072826093306,94.55097733678984,0.0016144393114919
0.0015902347393727996,97.5467561583645,0.0052953181955038,19.665426041526285,97.70944627263152,0.0016664274926011
0.0016400467701776996,100.655877251578,0.0054534713933094,20.292224853918125,100.82876668375437,0.0017161553479432
0.0016958854314766995,103.751321299105,0.0056307591429337,20.916266373899568,103.93532088997,0.001771896710027
0.0017412569644804996,106.840164128197,0.0057748137602207,21.538977088244515,107.03448918329993,0.0018171868949274
0.0017879869698685996,109.916505282967,0.005923181527328,22.15916746504615,110.12156210616084,0.0018638309724187
0.0018354591228902995,112.952987499864,0.0060739056131719,22.771322279972583,113.169071211612,0.0019112136052014
0.0018876404810708996,116.002439351148,0.0062395814253953,23.38609177319144,116.2304099545735,0.0019632939726961
0.0019357841618385997,119.016200536045,0.0063924376118327,23.99366602806668,119.255823728714,0.002011342071662
0.0019779519103861995,122.038332436902,0.0065263202134713,24.602927819279444,122.28918636943784,0.002053424206215
0.0020219837992150997,125.056873194056,0.0066661214605031,25.21146563592169,125.31943832986144,0.0020973648062631
0.0020752396155785994,128.105558836635,0.0068352086774572,25.826080661465618,128.3813472547108,0.0021505076306994
0.0021318233202938996,131.150637586778,0.0070148619399283,26.439968537494448,131.44040250520473,0.0022069681885457
0.0021862838386847994,134.213891864812,0.0071877740858194,27.057520599946105,134.51773411171055,0.002261307170449
0.0022356718025938996,137.231597746861,0.0073445808712308,27.66589010576718,137.54904926425945,0.0023105823651365
0.0022837619011406994,140.243643921966,0.0074972669341169,28.27311861466835,140.5748073973349,0.0023585603248617
0.0023420941477580995,143.264709458966,0.0076824718171271,28.882165426927543,143.61136366142503,0.0024167534602213
0.0023964249542436995,146.236234864905,0.0078549721277189,29.481224948764844,146.59802432913378,0.0024709516523309
0.0024461060506861996,149.172857585826,0.0080127096089238,30.07324808930252,149.54932334625704,0.0025205089127464
0.0024926915234342994,152.101086552458,0.0081606184848991,30.66357904897553,152.49202795040864,0.0025669760346355
0.0025416059059080996,154.956123033953,0.0083159216492534,31.239154403644925,155.36198223969234,0.0026157638259376
0.0025955281329434997,157.876525344875,0.0084871247200908,31.827907509526803,158.29854668691488,0.0026695437433097
0.0026471218174775996,160.72585903871,0.0086509346684865,32.40233318220394,161.16378940282976,0.0027209985561011
0.0027001841679779996,163.54051155514,0.0088194076313253,32.96976712951623,163.99478885770384,0.0027739153201601
0.0027481076520767997,166.358003794035,0.008971564693339,33.537773564877455,166.82807988641073,0.0028217049108374
0.0027969657405346997,169.153677869547,0.0091266891241928,34.10138145850068,169.63991819462709,0.0028704241437077
0.0028468062917056994,171.923868091834,0.0092849328741608,34.659851807313736,172.42664024134544,0.0029201206015982
0.0028954887051888998,174.737751371572,0.0094394995369699,35.227130676508914,175.25725906390684,0.0029686598858707
0.0029419626077747995,177.463311190402,0.0095870541776801,35.776603535985046,177.99916957746748,0.0030149949543437
0.0029903292571930996,180.175318687744,0.0097406182895832,36.32334424744919,180.7280805789381,0.0030632148355714
0.0030341119654881997,182.874154765051,0.0098796283884202,36.86742960063428,183.4432031716416,0.0031068626806471
0.0030820995924474995,185.559090366526,0.010031989104016,37.408712617891645,186.14539801147345,0.0031547003037646
0.0031345407019299997,188.205298551766,0.0101984896266229,37.94218818803603,188.80983706671265,0.0032069748716002
0.0031809224905518995,190.838999679596,0.0103457518054974,38.47314233540655,191.46084941990924,0.0032532070845228
0.0032330827792032995,193.423467832733,0.0105113607219656,38.99417111507897,194.0638280980821,0.0033051966091913
0.0032798745390245996,195.985700072524,0.0106599245593983,39.51071713462084,196.64371354575044,0.0033518328808616
0.0033275940529590995,198.539618471231,0.0108114340161403,40.02558708380017,199.21568082861413,0.0033993915837872
0.0033779827176206997,201.058016235396,0.0109714180264409,40.53329607305584,201.7527852255332,0.0034496079875941
0.0034298438563725997,203.547786135279,0.0111360771419782,41.035233684872246,204.26171490645424,0.0035012891984646
0.0034818592892302998,205.985039089154,0.0113012261413014,41.52658388037344,206.71823074536545,0.0035531214853905
0.0035366322465712995,208.382052363916,0.011475130280859,42.009821756565465,209.13518974944947,0.0036076986837338
0.0035880126627274994,210.761401295755,0.011638263102155,42.489498501224205,211.53396716663968,0.0036588927583601
0.0036478652701908997,213.057063943483,0.0118282951308513,42.95230409100617,213.85079680396683,0.0037185249936644
0.0037078046060545996,215.310451880998,0.0120186025222185,43.40658709920919,216.12548518494663,0.003778240074519
0.0037675494931295995,217.4891852806,0.0122082925386816,43.84581975256896,218.3254597996252,0.0038377578857428
0.0038291701182325997,219.563720416284,0.0124039380233837,44.26404603592286,220.4215014494264,0.003899140595055
0.0038875629494972996,221.578020300893,0.0125893352626491,44.67012889266003,222.4566092723582,0.0039573044962139
0.0039510188868209,223.472312885154,0.0127908078636515,45.05201827764705,224.3725936464012,0.0040205078179128
0.0040200497279355,225.230121613854,0.0130099807841904,45.40639251735297,226.1530317096704,0.0040892593137298
0.0040870230117612,226.875449847166,0.013222620960337,45.73809068918867,227.82029648607468,0.0041559570612891
0.004163699435442999,228.385992861154,0.0134660686055267,46.04261616080865,229.35464213624363,0.0042323125671512
0.0042523448850545,229.770714889138,0.0137475179080432,46.32177612165022,230.765605288408,0.0043205797386614
0.004355251978908799,230.998440569081,0.0140742479310306,46.56928561872672,232.0224183090025,0.0044230379243144
0.0044660585549132995,232.100697358549,0.0144260588098449,46.79150058748348,233.1552795033996,0.0045333493963698
0.0045906738921597,233.009295005794,0.0148217125056022,46.97467387316807,234.0970420236551,0.0046573933935457
0.0047313985218633,233.777944588884,0.0152685132049111,47.12963362911902,234.9021781743872,0.0047974543281823
0.0048800909526047,234.419259961827,0.0157406116725151,47.25892280830433,235.58143399005297,0.0049454241740878
0.005037876614829299,234.908250672954,0.0162415811500782,47.35750333566752,236.1099141111045,0.0051024191212552
0.0052009948404786,235.270157295215,0.0167594815165147,47.43046371071535,236.51204890232577,0.0052646940018288
0.005359947857418699,235.580350509319,0.0172641573452995,47.49299866267871,236.86132570259576,0.005422799879371
0.0055275078144654995,235.77939466085,0.0177961602089231,47.53312596362736,237.10095934788853,0.0055894397663559
0.0056978592548652,235.989975456252,0.0183370260321922,47.575579051980405,237.35292169980403,0.005758827346849
0.005869116819008299,236.131717498159,0.0188807687983465,47.60415424762885,237.5359217073052,0.005929087007607
0.006047497503539199,236.274026029844,0.0194471274717321,47.63284364761655,237.7212232274697,0.0061063974663268
0.006226539644213,236.424662068605,0.0200155862683714,47.66321187303077,237.91511190155137,0.0062843338042028
0.006409815070977,236.552329966049,0.0205974857483471,47.68894972115548,238.0869388621794,0.0064664444953138
0.0065994026683115995,236.662999148864,0.0211994263698845,47.71126062841098,238.24319436931515,0.0066547923516656
0.0067957047406386,236.779066189903,0.0218226854495227,47.73465974388445,238.40651660958616,0.0068497734015389
0.0069885759249595,236.855263318621,0.0224350514597416,47.750021085034,238.52892001816872,0.0070413096321028
0.007178442807121399,236.960848800798,0.0230378788106056,47.77130711824088,238.6802426015952,0.0072298265281078
0.0073712323319395,237.026838635721,0.0236499855519031,47.78461066896135,238.7924075519881,0.007421208929796
0.0075639369278107,237.109953976192,0.0242618226437941,47.80136672160031,238.9218341810577,0.0076124704263901
0.0077524433772905,237.185111736593,0.0248603306208925,47.81651852609716,239.04227718419145,0.0077995298275106
0.007944287645352,237.257464908784,0.0254694361719878,47.83110492561085,239.16071336825544,0.0079898655055547
0.0081296010600212,237.336068581692,0.0260578062635625,47.84695142606911,239.2839291468754,0.0081736872939965
0.0083193161246062,237.444905656556,0.0266601515936198,47.86889298036169,239.4387063431502,0.0083618403052018
0.0085100455057719,237.566562664728,0.0272657173788209,47.89341903320917,239.6066958163105,0.0085509636021905
0.0086959262577869,237.67172642371,0.0278558887664686,47.91462004701994,239.75694128172367,0.0087352446902347
0.0088853500928353,237.761299337509,0.0284573094427472,47.93267794644182,239.8923377213695,0.0089230034399048
0.0090735630358339,237.85351762191,0.0290548855367678,47.951269152577055,240.0301496625469,0.0091095270320788
0.0092585849794597,237.943180622307,0.0296423302077797,47.96934521345709,240.1646578918175,0.0092928543614506
0.0094468781345632,238.016027660667,0.0302401609752333,47.98403117639047,240.2830018311061,0.0094793884422264
0.0096363381026023,238.067827983247,0.0308416963737575,47.9944741214226,240.38039984687515,0.0096670433228454
0.009822458272989,238.129476166431,0.0314326279147352,48.006902395152494,240.48696757426413,0.0098513559435366