File: example/data/02 processed data/test_ID_138.csv
Strain,Stress_MPa,Displacement(mm),Force(kN),True Stress (MPa),True Strain
6.33660602213563e-05,-2.56490623460703,0.00020118724120280626,-0.5170850968967773,-2.5650687626099544,6.33640526774049e-05
8.37134481112684e-05,-2.32468704447286,0.00026579019775327715,-0.4686569081657286,-2.3248816520411326,8.370994433615446e-05
0.00010035011438,-1.54327556245028,0.0003186116131565,-0.31112435338997646,-1.5434304303294917,0.00010034507964401463
0.0001490999248655,-0.317082417319471,0.00047339226144796245,-0.06392381533160536,-0.3171296942840695,0.00014908881057639647
0.0001736024241044,1.50460191896753,0.0005511876965314699,0.30332774686385405,1.5048631215079749,0.00017358735694730164
0.0002167406797526,3.81603209768376,0.000688151658214505,0.7693120708930461,3.81685918707457,0.00021671719488486249
0.000278019783837,6.64055063614316,0.0008827128136824749,1.338735008246461,6.642396840595579,0.0002779811434985976
0.000340670319282,10.1026372685968,0.0010816282637203499,2.036691673349115,10.106078937260683,0.00034061230432447703
0.0004044675895728,13.9595691438377,0.00128418459689364,2.8142491393976803,13.965215337120783,0.00040438581460687506
0.0004755120572179,17.8306604356369,0.0015097507816668324,3.5946611438243994,17.839139129662204,0.0004753990371865231
0.0005158352386143,21.6207887302455,0.0016377768826004023,4.358751008017493,21.631941494959197,0.000515702241352101
0.0006098312328691,25.4993210060943,0.0019362141643593923,5.140663114828611,25.514871288460768,0.0006096453613657642
0.0006913276241728,29.4014515754883,0.0021949652067486396,5.927332637618441,29.421777611153214,0.0006910887673101523
0.0007591168878532,33.3422793595803,0.00241019611893391,6.72180351889139,33.36759004692168,0.0007588289043612888
0.0008122637706723,37.1555220445516,0.002578937471884552,7.490553244181604,37.18570212898881,0.0008119340629833152
0.0008815681353474,40.8025131643138,0.002798978829727995,8.225786653925663,40.838483359761554,0.0008811797823816875
0.000954975157337,44.3104220107334,0.003032046124544975,8.932981077363854,44.35273736296477,0.0009545194586589706
0.0010396044899523,47.6795631004887,0.0033007442555985523,9.612199921058522,47.72913098836693,0.001039064475439832
0.0011101906653388,50.8962174154075,0.0035248553624506896,10.260677430946153,50.952721920883135,0.00110957485941461
0.0011870909010244,53.9702896616759,0.00376901361075247,10.880410395793861,54.03435730145892,0.00118638686573484
0.0012773467743735,56.9308587258361,0.004055576008635862,11.47726111912856,57.003579174591856,0.0012765316610301742
0.001383977509659,59.7741963430718,0.004394128593167324,12.050477982763276,59.85692248646855,0.0013830206954897398
0.001494289321441,62.5035457331586,0.004744368595575175,12.600714819804775,62.596944114099855,0.0014931739821076812
0.0016158703203899,65.1564495779934,0.005130388267237933,13.13554023492347,65.26173395104846,0.0016145662066072372
0.0017506966521876,67.6500495263124,0.00555846187069563,13.638249984504581,67.76848424153845,0.0017491659690511449
0.0019181952228986,69.9832569305311,0.006090269832703055,14.10862459719507,70.11749847965812,0.0019163578357117013
0.002114267359777,72.1417465273474,0.006712798867291974,14.543776099913234,72.29427346730746,0.002112035441903047
0.0023539572682251,73.997373592949,0.0074738143266146915,14.91787051633852,74.1715602483477,0.002351191051002474
0.0025962198184584,75.555143397399,0.00824299792360542,15.231916908915636,75.75130115807379,0.0025928554616006993
0.0028721240080034,76.8797569199977,0.009118993725410795,15.498958995071536,77.1005651155771,0.002868007340347689
0.0031699477399592,77.9047862351403,0.010064584074370459,15.705604905004286,78.15174033619839,0.0031649340482550535
0.0034975581499493,78.6602879372757,0.011104747126089026,15.85791404815478,78.93540686842807,0.003491455917911295
0.0038432477345623,79.1736469663433,0.012202311557235302,15.96140722841481,79.47793090568373,0.0038358813259107894
0.0041919596801484,79.539262222127,0.013309471984471168,16.035115263980803,79.8726876023509,0.004183197894667972
0.0045381329310936,79.7673245930961,0.01440857205622218,16.081092637968176,80.12931931565727,0.0045278666539459635
0.0049142719719196,79.9218534507813,0.01560281351084473,16.11224565567751,80.31461117513834,0.004902236352179373
0.0052794016468139,80.0120212277207,0.01676210022863413,16.130423479508494,80.43443682435523,0.005265514461847848
0.0056619748247465,80.0617703735135,0.017976770068570135,16.140452907300322,80.51507810179295,0.0056460060933039334
0.0060394861096634,80.096784312607,0.019175368398181295,16.147511717421573,80.58052772889168,0.006021321513289737
0.0064216932996333,80.11669544823,0.020388876226335725,16.15152580236317,80.63118029457866,0.006401162077148471
0.0068121886958319,80.1138523355588,0.02162869910926628,16.150952630848657,80.65960301481864,0.0067890905782411115
0.0071902205108144,80.1378546348388,0.02282895012183572,16.155791494383504,80.71406348092688,0.007164494120653883
0.0075844966006641,80.145734222926,0.024080776707108516,16.157380019341883,80.75359927169751,0.007555878915722326
0.0079866027849241,80.1066695908916,0.025357463842134016,16.149504589523747,80.7464497413372,0.00795487867288004
0.0083763536743223,80.0736807698969,0.026594922915973304,16.142854043211216,80.74440624003033,0.008341466705559065
0.0087777789355959,80.0390695152451,0.02786944812051698,16.135876414273415,80.7416347736607,0.008739478201144174
0.0091782700109161,80.0175531064622,0.029141007284658616,16.13153870626278,80.75197581448614,0.00913640565730716
0.0095818649480642,79.9766371308312,0.030422421210103835,16.12329004557557,80.74296246681915,0.009536250032610522
0.0099995761795234,79.9116691850896,0.03174865436998679,16.11019250771406,80.71075200873877,0.009949911228845679
0.0104063795761361,79.8420014489711,0.03304025515423211,16.096147492112575,80.6728676221675,0.010352605945668489
0.0108129817425155,79.8011307724851,0.03433121703248671,16.087907963732995,80.66401894256008,0.010754939487139304
0.0112278789047939,79.7516914454399,0.03564851552272063,16.077940995400684,80.64713377944179,0.011165314149863189
0.0116333223181075,79.6763434868906,0.03693579835999131,16.062750846957144,80.60324407180185,0.011566175482808546
0.0120520592874672,79.5996004223348,0.038265288237708354,16.047279445142696,80.55893952588347,0.011980011525843487
0.012457620058138,79.5002441779063,0.03955294368458815,16.027249226265912,80.49062801440385,0.012380662389836568
0.0128670053132303,79.415172562941,0.0408527418695062,16.010098788688904,80.43700801025946,0.0127849287040257
0.013277708575044,79.3388161641879,0.0421567247257647,15.994705338700284,80.39225384390498,0.013190332389777772
0.0137005180697282,79.2481042755157,0.043499144871387035,15.976417821943965,80.33384436013411,0.013607514474181674
0.0141243375140239,79.1537998726517,0.04484477160702588,15.957406054326585,80.27179485757054,0.014025518474181622
0.0145545737586653,79.0699675489887,0.04621077168376232,15.940505457876123,80.22079722377572,0.014449672586200883
0.0149700707595253,78.9803187792147,0.04752997466149283,15.922432265889684,80.1626597399494,0.014859125122574101
0.0153970032201298,78.9076437149072,0.04888548522391211,15.907780972925291,80.12258495927848,0.015279672197404266
0.0158305008336835,78.7935870415169,0.05026184014694512,15.884787147569808,80.04092898686655,0.01570650535052956
0.0162697017237807,78.6813920863205,0.05165630297300372,15.862168644602214,79.96151486677678,0.016138768382030984
0.016700773747313,78.5651972182476,0.053024956647718766,15.838743759198717,79.87729680140258,0.016562849336667504
0.0171338429879303,78.4747246304244,0.0543999514866787,15.82050448549356,79.81929824076316,0.016988714098333784
0.017576535955418,78.3748828678997,0.05580550165845214,15.80037638616858,79.75244181462902,0.01742385511796433
0.0180089256288296,78.2293337460292,0.05717833887153398,15.771033683199487,79.63815999945433,0.01784868589817455
0.0184527133935128,78.1074694868659,0.05858736502440314,15.746465848552164,79.54876423519958,0.01828452791277924
0.0188911594198534,78.0176692903855,0.059979431158034544,15.728362128941717,79.49151351851556,0.018714937367913204
0.0193209392818337,77.8922464954672,0.061343982219822,15.70307689348619,79.39719786053175,0.019136659786913455
0.0197547624056884,77.7475655446798,0.06272137063806067,15.67390921380745,79.28345022963563,0.019562169374459756
0.0201978308366647,77.6032542623206,0.06412811290641042,15.644816059283835,79.17067166428562,0.01999656029061242
0.0206517050052292,77.479437539863,0.0655691633916027,15.61985460803638,79.07952002790734,0.020441349745274725
0.0211001066017987,77.3842169426235,0.06699283846071087,15.600658135632898,79.01703216940956,0.020880581978329923
0.0215474440464662,77.2685391568692,0.06841313484753019,15.57733749402483,78.93347868090402,0.021318579665867518
0.0219981783050841,77.1407335323104,0.06984421611864201,15.55157188011378,78.83768914313914,0.021759709299575727
0.022462895662811,77.0433324916358,0.07131969372942493,15.531935830313776,78.77394883091067,0.022214320416067898
0.0229387450269409,76.9590293635348,0.07283051546053736,15.514940319688614,78.72437291562578,0.022679607392716895
0.0234064431255087,76.8583344861426,0.07431545692349012,15.494640232406349,78.65731472101382,0.023136713172738032
0.023862994974251,76.7378392823072,0.07576500904324693,15.470348399313135,78.56903395543578,0.023582723695646388
0.0243427020382461,76.6163107294475,0.07728807897143136,15.445848243056616,78.48135875280413,0.024051140587041567
0.0248196843478227,76.4908374643979,0.07880249780433707,15.420552832822617,78.38931590576487,0.024516679405595113
0.0252970747683821,76.3610235723046,0.08031821238961316,15.394382352176608,78.29273409500338,0.024982399640372105
0.0257810178168267,76.2226020433513,0.08185473156842477,15.366476571939623,78.18769830467583,0.025454291041459753
0.0262549431859137,76.0845796590795,0.08335944461527599,15.338651259270426,78.08217597535274,0.025916198519223065
0.0267349833796237,75.9513741872087,0.08488357223030525,15.311797036141275,77.98193291376332,0.0263838483564162
0.0272065676346204,75.8209772133941,0.08638085223991976,15.285509006220252,77.88380575807332,0.026843047658412427
0.0276792249863245,75.7012427480997,0.08788153933158029,15.2613705380169,77.79659447786872,0.02730308038795584
0.0281605711410801,75.5608252347435,0.08940981337292932,15.23306236732429,77.68866122924523,0.027771352443451764
0.0286427953578921,75.4357763331287,0.09094087526130741,15.207852508758748,77.59646783730223,0.028240258935440243
0.0291177066589401,75.2900905145223,0.09244871864213482,15.178482247727699,77.48236528444922,0.028701839677236482
0.0296073252417302,75.1824265830644,0.09400325764249337,15.156777199145784,77.40837713937168,0.029177491922615924
0.0300906611774482,75.0545148472565,0.09553784923839803,15.13099019320691,77.31295482336306,0.029646818928591574
0.030579932090634,74.9322011364031,0.09709128438776295,15.106331749098864,77.22362275855602,0.030121684658202228
0.0310862999883375,74.7962211612252,0.09869900246297156,15.078918186103001,77.12135893023708,0.030612906661072293
0.0315843761056369,74.6870359484323,0.10028039413539715,15.056906447203952,77.0459793820428,0.03109584960756663
0.0320921215909534,74.5491768009428,0.10189248605127703,15.02911404307007,76.94161804734414,0.03158792818299126
0.0325956000868005,74.4511114598061,0.10349103027559158,15.009344070296908,76.87789011496774,0.032075632449879196
0.0331014823727379,74.3280006340726,0.10509720653344282,14.984524927829037,76.78836763686219,0.03256542575050039
0.0336148936555124,74.1932772575046,0.10672728735625187,14.957364695112929,76.68727638246956,0.03306226343881673
0.0341251107338502,74.0678669251528,0.10834722657997439,14.932081972110804,76.59544108579372,0.03355576560795786
0.0346337033575543,73.9403334380217,0.1099620081602349,14.906371221105173,76.50116101247279,0.034047454277015
0.035152191898294,73.8103219881517,0.11160820927708345,14.880160912811382,76.40491659075407,0.0345484612195915
0.0356635754907622,73.6935996957875,0.11323185218316997,14.85662969867076,76.32177695172422,0.035042357017485884
0.0361824204119796,73.5594201047072,0.11487918480803523,14.829579093108972,76.22097796819715,0.03554320981551208
0.0366915230432396,73.426659712841,0.11649558566228574,14.802814598108746,76.12079568968282,0.03603441444771259
0.0372023883005373,73.3028049828184,0.11811758285420591,14.77784548453619,76.02984439730777,0.03652707732196689
0.0377169534523459,73.1601653155791,0.11975132721119823,14.749089327620748,75.91954386535274,0.037023063023196655
0.0382421572499487,73.0312169846072,0.12141884926858712,14.72309334409681,75.82408826868767,0.037529049683628087
0.03876449113651,72.9001793304826,0.12307725935841925,14.696676153025292,75.72611768598908,0.03803201764280964
0.039282130625977,72.7763621186573,0.12472076473747697,14.671714603121314,75.6351726818858,0.038530215801361616
0.0398015830449496,72.6467300756345,0.12637002616771498,14.645580783247915,75.5381849356839,0.03902990941770394
0.0403324114172368,72.510560649873,0.12805540624972683,14.618129027014398,75.43508641409818,0.039540288446384915
0.0408660961382358,72.3873972334144,0.12974985523889868,14.593299282256345,75.34558756795178,0.040053151328766884
0.0414079275733832,72.2759102465991,0.13147017004549166,14.570823505714378,75.26870590339061,0.040573574136914516
0.0419303142348766,72.1467777991525,0.1331287476957332,14.544790404309145,75.17191486330478,0.041075064160913694
0.0424595817572874,72.0194046452215,0.1348091720793875,14.519111976476655,75.07731844486645,0.0415829034426176
0.0429984041660243,71.8909025361124,0.13651993322712716,14.493205951280261,74.98209661922043,0.04209964597530217
0.0435475755034977,71.7750205698041,0.1382635522236052,14.469844146872505,74.90064869733274,0.04262603873683741
0.0440854960834733,71.6616900040277,0.13997145006502773,14.446996704811987,74.82093115803535,0.04314137890767649
0.0446234620164206,71.5437122222873,0.14167949190213538,14.423212384013121,74.73624034715226,0.04365649705542667
0.0451831436599248,71.41585694321,0.14345648112026121,14.397436759751136,74.6426498670717,0.04419212715188164
0.0457446245014163,71.298317944942,0.14523918279199674,14.373740897700307,74.55983272691597,0.04472919099840685
0.0462931819553093,71.1555501285908,0.146980852708107,14.344958905923907,74.44956695782379,0.045253615045402616
0.0468465332802077,71.0271785828079,0.14873774316465943,14.319079202294075,74.35455566808668,0.04578234357103475
0.047405770916467,70.9035158970182,0.1505133226597827,14.29414880483887,74.26475172880431,0.046316412602193276
0.0479585967216931,70.7817644045059,0.1522685445913756,14.269603703948391,74.1763584988315,0.0468440781734812
0.0485175113751643,70.6498634403516,0.15404309861614665,14.243012469574882,74.07761899347267,0.0473772725796126
0.0490484533173232,70.5177272371008,0.15572883928250114,14.21637381099952,73.97651268953346,0.04788351835441574
0.0495876697537334,70.3834049463731,0.15744085146810355,14.189294437188819,73.87355398699714,0.04839739157173827
0.0501442921570021,70.2566321977831,0.15920812759848166,14.163737051073074,73.77960128867578,0.04892757582992411
0.0507012020614904,70.1330846928587,0.160976316545232,14.138829874080313,73.68891639106694,0.04945775276969988
0.0512463286327394,69.9645664576099,0.1627070934089476,14.104856597854157,73.54999362294372,0.04997643991627255
0.0518151616835944,69.8155479627958,0.16451313834541223,14.074814469299634,73.43305186851681,0.0505173970564665
0.0523798582987759,69.6980785363151,0.1663060500986135,14.051132632921124,73.34885401374424,0.05105413117414626
0.05295880070964,69.5787740948096,0.16814419225310698,14.027080857513615,73.26358252571768,0.051604106754540094
0.053537965784102,69.4361219650039,0.16998304136452383,13.998322188144787,73.15359068694701,0.05215399137650385
0.0541133608067304,69.3360229418322,0.171809920561369,13.97814222507337,73.0880281681873,0.052699997283329
0.0547053113718292,69.2160310690806,0.1736893636055577,13.95395186352665,73.00251560063685,0.05326140219543052
0.0552990806737818,69.1378425915094,0.17557458113925722,13.938189066448295,72.96110172658851,0.053824215542989925
0.055888106663823,69.0155028299773,0.17744473865763802,13.913525370523423,72.87264861359644,0.05438222007130245
0.0565006717159477,68.8953988267528,0.17938963269813393,13.889312403473363,72.78803513860245,0.05496219386738107
0.0570849874410573,68.7687503286445,0.1812448351253569,13.863780066254732,72.69441357749237,0.055515108046623476
0.0576704016752586,68.6780327796182,0.18310352531894605,13.845491408371032,72.63872251628536,0.05606875529317291
0.0582679122886653,68.5528926435352,0.1850006215165123,13.820263156936697,72.547326579223,0.05663352660559331
0.0588730950862774,68.3958864756014,0.18692207689893073,13.788610713481242,72.42256400358973,0.057205224770228644
0.0594654770076809,68.2237791191109,0.18880288949938684,13.753913870412758,72.28073868769549,0.05776451396474054
0.0600583989503681,68.1232984543124,0.19068541666741873,13.733656968389381,72.21467469069648,0.058323999955796735
0.0606444388021511,67.9915795023513,0.19254609319682972,13.707102427674021,72.11489068454324,0.05887668452458046
0.0612495087102595,67.8953608231929,0.19446719015507388,13.68770474195569,72.05391831731927,0.05944699570833956
0.0618506648369219,67.732606312832,0.19637586085722702,13.654893432666931,71.92191304441816,0.060013296017875736
0.06245035364078,67.6015461641014,0.19827987280947648,13.628471706682845,71.82328662871305,0.06057789473959365
0.0630272915785061,67.4869661118602,0.20011165076175685,13.605372368151016,71.74048680274117,0.06112077313983786
0.0636278469634891,67.3975174771998,0.20201841410907787,13.58733952340348,71.68587640495814,0.061685561844938994
0.0642272854844939,67.2569329915538,0.2039216314132681,13.558997691097245,71.57666322761379,0.0622489822843488
0.0648134250557258,67.1286724343855,0.20578262455192942,13.53314036277212,71.47951161430191,0.06279959607312108
0.0654032635749736,66.9767418912909,0.20765536185054118,13.502511165284245,71.35723939459997,0.06335337873520414
0.066004481072496,66.8798547031075,0.20956422740517477,13.482978708146472,71.29422480699004,0.06391752936755303
0.0666129255546246,66.7676213814764,0.21149603863593308,13.460352470505644,71.21520797402005,0.06448813757580142
0.0672279785448362,66.6630042538759,0.21344883187985492,13.439261657581381,71.14462327358979,0.06506461261296376
0.0678360971410055,66.5468490245939,0.21537960842269244,13.41584476335813,71.06112753945408,0.06563426166428646
0.068431228947605,66.4206045159081,0.21726915190864587,13.390393870407072,70.96584811037452,0.06619143146670549
0.069057232151283,66.287683301474,0.2192567120803235,13.36359695357716,70.86532723599463,0.06677716863719203
0.0696648946642181,66.1648043055746,0.22118604055889246,13.33882454800384,70.77416842800108,0.06734541686511072
0.070285584711187,66.0530189838426,0.2231567314580187,13.316288627142669,70.69559404506111,0.06792551446115955
0.0709034336980802,65.9008580627049,0.22511840199140465,13.285612985441308,70.57345518300049,0.0685026227862344
0.0715164152582265,65.7918726587804,0.2270646184448691,13.26364152801013,70.4970715444621,0.0690748557004986
0.0721300688771802,65.6653522934717,0.2290129686850471,13.238135022363895,70.40179867724412,0.0696473881961857
0.0727643487132314,65.5539903727511,0.23102680716450968,13.215684459146624,70.32398378777778,0.07023882043577596
0.0733777374338271,65.4266321119132,0.232974316352401,13.1900090337617,70.22749034420076,0.07081044031244399
0.0740165655261954,65.2813132212753,0.23500259554567038,13.1607127454091,70.11321181895391,0.07140542010756896
0.0746571587178714,65.1323904957376,0.23703647892924168,13.1306899239407,69.99498971065226,0.07200168859024038
0.075279817615729,65.0254821318343,0.23901342092993955,13.109137197777793,69.92058856709363,0.07258092316513338
0.075900731725795,64.8874726831844,0.24098482322939913,13.081314492929977,69.81247933967562,0.07315820072326235
0.0765328951453786,64.7493139121096,0.24299194208657704,13.053461684681295,69.70476636448028,0.073745594852278
0.0771651005361254,64.6095822150858,0.24499919420219812,13.025291774561296,69.59518712230995,0.07433268311643866
0.0777942440333299,64.475165117505,0.24699672480582244,12.998193287689007,69.49096184674542,0.07491658602547976
0.0784116537306698,64.3654031195231,0.2489570005948766,12.976065268895857,69.41240082116612,0.07548926761850777
0.0790149049163815,64.2182946761281,0.25087232310951124,12.946408206707424,69.29249712385453,0.07604849981949799
0.0796282249642219,64.086594320143,0.2528196142614045,12.91985741494083,69.18969606985819,0.07661674572902721
0.0802519825428898,63.9458362394298,0.2548000445736751,12.891480585869049,69.07761637300702,0.07719433109125291
0.0808809535639374,63.8044808363927,0.2567970275655012,12.86298333661677,68.96504808809212,0.07777640637991078
0.081502908123538,63.6748607665684,0.25877173329223313,12.83685193054019,68.86454709340511,0.07835165537965712
0.0821329935493474,63.5521838469416,0.260772254519178,12.812120263543427,68.77191495288939,0.07893408742668859
0.0827681483852922,63.4226364156096,0.26278887112330274,12.786003501386897,68.67201059744322,0.079520862353142
0.083405887308527,63.3126519673429,0.2648136922045732,12.763830636616328,68.59329988253509,0.0801096783311307
0.0840459436752767,63.1779779516726,0.2668458711690035,12.736680355057198,68.48783072811675,0.08070028558357825
0.0846794352517138,63.0503977136054,0.2688572069241913,12.71096017906285,68.38946978438945,0.08128449195715592
0.0853025431427389,62.9340365257331,0.270835574478196,12.687501763587793,68.30246989161616,0.08185878972953863
0.0859394700968312,62.7919935283272,0.27285781755743904,12.658865895310763,68.18830417847529,0.0824454833993167
0.0865610070298426,62.6537944496588,0.27483119731975025,12.631004961051215,68.07716999146203,0.08301766918846859
0.0871970074621924,62.5036321065734,0.27685049869246087,12.600732232685198,67.95376178178441,0.0836028313327898
0.0878289094025313,62.3541270986152,0.2788567873530369,12.570592023080824,67.8306220784334,0.08418388368091854
0.0884664106566238,62.2104687960098,0.28088085383478056,12.541630509275576,67.71400567565868,0.08476974283932477
0.0890994379946549,62.073942131762,0.2828907156330293,12.514106733763219,67.60469548981472,0.08535115107205885
0.0897346138445547,61.9169366163186,0.28490739895646117,12.48245442184983,67.47302901402172,0.08593419305945307
0.090363307274821,61.7755058343297,0.28690350059755665,12.453941976200868,67.35774485009473,0.08651095013224679
0.0909896743728155,61.6376057593807,0.28889221613368915,12.42614132109115,67.24599143654673,0.08708524243659141
0.0916069809197747,61.4931791330334,0.29085216442028466,12.397024913219534,67.12638362056948,0.08765090495781126
0.092230726524023,61.3582590306141,0.292832556713773,12.369825020571803,67.01737583925683,0.08822214303020412
0.0928588177194294,61.1944231316242,0.2948267462591883,12.336795703335438,66.87686491464932,0.08879703133568304
0.0934870355821327,61.0266096675536,0.2968213379732713,12.302964508978805,66.7318064970011,0.08937170517243555
0.0941128828572169,60.8772970300734,0.2988084030716637,12.272863081262797,66.6066349541287,0.0899438822756466
0.0947014383137777,60.73210594599,0.30067706664624416,12.243592558711585,66.48352373089998,0.09048166701604496
0.095338028308783,60.5694928302958,0.302698239880386,12.210809754587633,66.34406885239918,0.09106301728176966
0.0959772799089838,60.4077645405017,0.30472786371102356,12.178205331365143,66.20553746648142,0.09164645830090284
0.0966150385107201,60.2547291517487,0.30675274727153634,12.147353396992537,66.07624212919791,0.09222819765514984
0.0972436716392432,60.1245667645402,0.3087486574545972,12.121112659731304,65.9713003924429,0.09280128209565623
0.0978813573399824,59.9737150164253,0.3107733095544441,12.09070094731134,65.8440236469543,0.093382283824723
0.0985100341692294,59.8150760728618,0.31276935848730336,12.05871933628894,65.70746126063446,0.09395474722887413
0.099179868747626,59.6417341229997,0.3148960832737125,12.02377359919674,65.55699348519961,0.09456432786010835
0.0998099550093444,59.489341192593,0.3168966071546685,11.993051184426749,65.42696966056124,0.09513739670486145
0.100434940576133,59.3086462796342,0.31888093632922226,11.956623089974256,65.26530664438015,0.09570550217789468
0.10105663909986,59.1353358776822,0.3208548291420555,11.921683712940732,65.11135417352213,0.09627029974150397
0.101677560423368,58.9577964897914,0.3228262543441934,11.885891772341946,64.9524814048108,0.09683407301935887
0.102298860436708,58.7886024702498,0.3247988818865479,11.851782258002359,64.80260950962298,0.0973978721815615
0.102925260617512,58.6116136537468,0.32678770246060057,11.816101312595356,64.64422926427162,0.09796597788262906
0.103549025549552,58.4318559779785,0.32876815611982757,11.779862165160466,64.48241772554994,0.09853137304954053
0.104159117438595,58.2136987862508,0.3307051978675391,11.735881675308162,64.2771862746629,0.09908406558411408
0.104789422848341,58.0446993882791,0.3327064175434827,11.701811396677067,64.12716993658232,0.09965474925134941