File: example/data/02 processed data/test_ID_088.csv
Strain,Stress_MPa,Displacement(mm),Force(kN),True Stress (MPa),True Strain
1.76512283924362e-05,0.294927271013058,5.604265014598493e-05,0.0594573378362325,0.29493247684167784,1.765107261138028e-05
1.99709351236517e-05,0.295586828983401,6.340771901759415e-05,0.05959030472305364,0.295592732128786,1.9970735707155628e-05
2.54003458639262e-05,0.545929137272872,8.064609811796568e-05,0.11005931407421099,0.5459430040617759,2.540002328063481e-05
5.64036711744182e-05,1.29939969774433,0.0001790816559787778,0.26195897906525695,1.2994729886576057,5.640208054707122e-05
8.67584643429719e-05,2.6827210291001,0.00027545812428893577,0.5408365594665802,2.682953777856845,8.675470104501371e-05
0.0001361824125107,5.02414828769044,0.0004323791597214724,1.0128682947983927,5.024832488325069,0.00013617314052782715
0.0001802284231297,7.83792843100181,0.0005722252434367975,1.580126371689965,7.839341048483532,0.0001802121839384861
0.0002041185384606,11.0590669421672,0.0006480763596124049,2.2295078955409076,11.061324302748176,0.0002040977091062142
0.0002498927282178,14.6403285311533,0.000793409412091515,2.951490231880505,14.643987042791954,0.00024986151023058666
0.0002869241039557,18.5490117496495,0.0009109840300593474,3.7394807687293397,18.554333908225036,0.00028688294910711855
0.0003354626796652,22.9049518881268,0.00106509400793701,4.617638300646363,22.912635644664793,0.00033540642464111996
0.0003955490954088,27.6238671432002,0.00125586837792294,5.5689716160691605,27.634793738860388,0.00039547088648836864
0.0004534191495139,32.5395278457009,0.0014396057997066323,6.5599688136933025,32.55428189074228,0.00045331638611331677
0.0005301919812789,37.6069155841168,0.0016833595405605073,7.581554181757947,37.626854469200126,0.0005300514791701548
0.0006088873432808,42.8416116119652,0.0019332173149165398,8.636868900972186,42.867697327041476,0.0006087020465951138
0.0006912896239247,48.1833180137349,0.0021948445559609223,9.713756911568955,48.21662664152405,0.0006910507933136223
0.0007785295117814,53.521459265557,0.0024718311999059445,10.789926187936292,53.56312730110884,0.0007782266148803769
0.0008696684561013,58.9278764821944,0.0027611973481216274,11.879859898810391,58.979124197556004,0.0008692905135968434
0.0009607384215534,64.4094696234975,0.0030503444884320448,12.984949076097095,64.47135027567667,0.0009602772077762102
0.0010545504003827,69.9011562299753,0.0033481975212150726,14.092073095963022,69.97487052226484,0.001053994752713912
0.0011451353742562,75.4847102961174,0.003635804813263435,15.217717595697268,75.57115050809297,0.0011444802068660497
0.0012352845589161,80.9177954382368,0.003922028474558617,16.313027560348537,81.01775194148318,0.0012345222226822037
0.0013243713588816,86.4638397349506,0.00420487906444908,17.43111009056604,86.57834996787449,0.0013234951526630413
0.0014129128063022,91.933753180932,0.0044859981600094846,18.53384464127589,92.06364755813277,0.0014119155842179049
0.0015057651312344,97.3916603745414,0.00478080429166922,19.634158731507547,97.53830934080642,0.001504632603657055
0.001595433097916,102.793852520281,0.0050655000858833,20.723240668088653,102.95785323485416,0.0015941617465887188
0.0016814544930688,107.981737031322,0.00533861801549344,21.769118185514518,108.16330340822269,0.0016800424311196583
0.0017671117004948,113.207247730777,0.00561057964907099,22.82258114252464,113.40729758282286,0.00176555219555635
0.0018554758500681,118.360292568447,0.005891135823966217,23.861434981798915,118.57990723291475,0.001853756581132565
0.0019338727084996,123.548157236585,0.00614004584948623,24.907308498895535,123.78708364605025,0.0019320051839888175
0.0020262115082764,128.644642711624,0.00643322153877757,25.934759970663396,128.90530396716437,0.002024161510423932
0.0021030620506592,133.695962475549,0.00667722201084296,26.953106035070682,133.9771333805577,0.0021008537113058937
0.0021918501538035,138.678766910855,0.006959124238326112,27.957639409228367,138.9827299874378,0.002189451554529065
0.0022813836886077,143.565019587428,0.007243393211329447,28.942707948825486,143.8925464813694,0.0022787852840618432
0.0023605958237487,148.45357060615,0.007494891740402122,29.928239834199843,148.80400948494346,0.0023578139944168417
0.002450674298789,153.302231128558,0.007780890898655074,30.905729795517292,153.67792496633177,0.0024476762936201982
0.0025294415390613,158.04504278163,0.008030976886519627,31.86188062477661,158.44480847788458,0.002526247886116848
0.0026172500043357,162.711249914663,0.008309768763765848,32.80258798279606,163.13710593420763,0.0026138309698891327
0.0027042136967022,167.227751208986,0.008585878487029484,33.71311464373158,167.67997078427405,0.0027005638892689484
0.0027923918807082,171.671223796241,0.008865844221248535,34.60891871732218,172.15059712772089,0.002788500397181927
0.0028759181094206,176.088931801899,0.009131039997410405,35.49952865126284,176.59534914973662,0.002871790568687041
0.0029581139495863,180.477055709037,0.009392011789936502,36.38417443094186,181.01092740511015,0.002953747339683881
0.0030375576887154,184.861794582338,0.009644245661671394,37.26813778779934,185.4233229478213,0.0030329536313961764
0.0031244222032956,189.095470103177,0.00992004049546353,38.12164677280049,189.68628418850997,0.0031195513393630437
0.0031998387086389,193.187595405958,0.010159487899928507,38.94661923384113,193.80576455176686,0.0031947301196312084
0.0032930080834541,197.171165133114,0.010455300664966766,39.74970689083578,197.8204513737214,0.0032875980060341923
0.0033753730393966,201.043150127269,0.010716809400084204,40.53029906565743,201.72174575596395,0.0033696892541582694
0.0034619802225034,205.016012117906,0.010991787206448295,41.331228042969855,205.7257734971547,0.0034560013641254366
0.0035529270554792,208.887376502229,0.011280543401146459,42.11169510284936,209.62953811375183,0.0035466303203014957
0.0036459673753605,212.693255355401,0.011575946416769588,42.87896027964884,213.468728025386,0.0036393369476378475
0.0037428707417868,216.342209112561,0.01188361460517309,43.6145893570923,217.1519500372619,0.0037358836302350943
0.0038454669802738,219.690756315025,0.012209357662369314,44.28965647310905,220.5355698643058,0.003838092072721666
0.0039644921948389,222.782049860366,0.012587262718613507,44.91286125184978,223.66526755818762,0.003956654304331884
0.0041032693227844,225.597676673883,0.013027880099840468,45.48049161745481,226.5233646998704,0.0040948738712468765
0.0042730633974286,228.09822069356,0.013566976286835805,45.98460129182169,229.07289885142424,0.004263959786353917
0.0044761117105926,230.34137743266,0.014211654681131504,46.43682169042426,231.3724111696204,0.004466123716397322
0.0047247253228688,232.137450045842,0.01500100290010844,46.798909929241745,233.2342357344598,0.004713598840797568
0.0050100110323776,233.623485458093,0.015906785027798877,47.09849466835155,234.79394169766056,0.004997502687672794
0.0053251742053608,234.699064683361,0.01690742810202054,47.315331440165586,235.94887808863515,0.005311045601192334
0.0056634502074559,235.427806895809,0.017981454408672482,47.46224587019509,236.76114055761397,0.005647473168389047
0.0060200573911752,235.904473402922,0.01911368221698126,47.55834183802907,237.3246318716426,0.0060020092433806325
0.0063786015316205,236.258110520981,0.020252059862895085,47.629635081029775,237.7651068666079,0.0063583443489019075
0.0067515217215143,236.46408558816,0.0214360814658079,47.67115965457306,238.0605779983665,0.00672883226704689
0.007126041890392,236.623535416518,0.0226251830019946,47.70330473997003,238.30972464214875,0.007100771634128846
0.0075034598684136,236.793778769557,0.02382348508221318,47.73762579994269,238.5705513856444,0.007475448945373783
0.0078801553638005,236.96184177625,0.025019493280066585,47.771507302092,238.82913790473918,0.007849269092492776
0.008259439522853,237.121998002603,0.026223720485058277,47.80379479732476,239.08049280464357,0.008225517011524503
0.0086354742207511,237.317101672243,0.02741763065088474,47.843127697124196,239.36644738587702,0.008598401785731366
0.009028602141896,237.476177873249,0.0286658118005198,47.87519745924699,239.62025580144467,0.00898808798843015
0.0094209533640508,237.68551613302,0.029911526930861285,47.91740005241684,239.92474029581953,0.009376852945202251
0.0098082872731894,237.872988621671,0.031141312092376344,47.955194506128876,240.2061152286045,0.009760498255100034
0.0101865456018371,238.027004070477,0.03234228228583279,47.98624402060817,240.4516770019096,0.010135012414158987
0.0105627093605727,238.148297213286,0.03353660221981832,48.01069671819846,240.66378846146523,0.010507313690189953
0.0109439041236897,238.279719447947,0.034746895592714794,48.037191440706124,240.887429852205,0.010884452963534347
0.0113142824116379,238.37383613428,0.03592284665695033,48.05616536467085,241.07086503584873,0.011250754649991299
0.0116931150958073,238.512005034165,0.03712564042918817,48.08402021488767,241.30095336076127,0.011625278924162845
0.0120614436925686,238.695297367759,0.038295083723905304,48.12097194934021,241.57430725664113,0.011989284133419795
0.0124349822463987,238.883462172344,0.039481068632315874,48.15890597394455,241.85397378341534,0.012358302871396363
0.0128146230108796,239.091382843229,0.04068642805954273,48.200822781194965,242.1552487795149,0.012733210505440249
0.0131878073982607,239.245091250036,0.04187128848947772,48.23181039600726,242.40020943442082,0.013101605316818919
0.0135593086661903,239.403195492238,0.0430508050151542,48.26368421123519,242.64933731558955,0.013468203861990685
0.0139265197576609,239.547436585977,0.04421670023057335,48.29276321573297,242.88349869448862,0.013830436820996104
0.0142826212692499,239.711757948604,0.04534732252986843,48.32589040243857,243.13547020117002,0.01418158553445468
0.0146391790133638,239.823102381078,0.04647939336743006,48.348337440025325,243.33391570837486,0.014533060635895007
0.0149886717105941,239.972081385631,0.04758903268113626,48.378371607343205,243.56894413322817,0.01487745155520558
0.015344914120544,240.150456816366,0.048720102332727194,48.41433209417938,243.83554495222253,0.015228371636606754
0.0157002931050291,240.26046726243,0.049848430608467394,48.43651020010589,244.03262702000143,0.015578318537687711
0.0160547646961984,240.438443836755,0.05097387791042992,48.472390277489815,244.2986264764742,0.015927249963653304
0.0164079912847507,240.610790303377,0.05209537232908347,48.50713532516081,244.55873005369182,0.01627483477530039
0.0167658478008537,240.795101806584,0.05323156676771049,48.54429252420733,244.83223583466426,0.016626852406964557
0.0171291339099366,240.995861577974,0.0543850001640487,48.58476569411956,245.12391196268368,0.016984084335076
0.0174831803975875,241.119983700575,0.0555090977623403,48.60978871403592,245.3355278730755,0.01733210787620435
0.0178429494331698,241.266908082544,0.05665136445031411,48.639408669440876,245.57182132335805,0.01768563258564168
0.0181955063155424,241.456140204275,0.05777073255184712,48.67755786518183,245.84955692828834,0.018031949115077352
0.0185447118787826,241.580358637554,0.05887946021513475,48.70260030133089,246.06039678406046,0.018374855454867434
0.0188981414937045,241.728230967007,0.06000159924251179,48.73241136294862,246.29644527884435,0.01872178996434992
0.0192503493610949,241.840275006238,0.06111985922147631,48.75499944125758,246.49578478969136,0.019067405480075923
0.0196022455772101,241.998408989378,0.062237129707642065,48.78687925225861,246.7421212316819,0.019412595927372545
0.019950071391359,242.175425064137,0.06334147666756482,48.82256569293002,247.00684208339922,0.0197536764817934
0.0202901639025964,242.32945165994,0.06442127039074357,48.8536174546439,247.24635595254645,0.02008706125531574
0.0206386878227578,242.447398455549,0.06552783383725601,48.87739552863868,247.45119462571284,0.0204285958690821
0.0209831758358832,242.552329883326,0.06662158327892916,48.89854970447852,247.64184807067096,0.020766060923239876
0.0213333675422097,242.685335241338,0.06773344194651579,48.925363584653745,247.86263069514584,0.021108996704565165
0.0216740965276602,242.827723029753,0.06881525647532113,48.95406896279821,248.09079453829182,0.021442552988232413
0.022014393786927,242.995523879062,0.06989570027349322,48.987897614018905,248.3449230301963,0.021775575622576662
0.0223581291421574,243.105774485145,0.07098706002634975,49.010124136205235,248.54116478628808,0.022111850303061148
0.0227034913710983,243.193883876877,0.0720835851032371,49.027886989578406,248.7152341209796,0.02244960270011347
0.0230551791526688,243.319748147074,0.07320019380972344,49.05326122645011,248.92952853198702,0.022793424080515903
0.0233991323505451,243.48398450214,0.07429224521298068,49.08637127563143,249.18129848074366,0.023129569577810153
0.0237414898050564,243.680731666892,0.07537923013105408,49.12603550404543,249.46607527345017,0.02346404338385712
0.0240801341940125,243.844439226537,0.07645442606598968,49.159038948069856,249.7162460455757,0.02379477960431147
0.024422987958818,243.968448926834,0.07754298676924715,49.18403930364973,249.92688741730555,0.024129515504197837
0.0247702339467755,244.058199971458,0.07864549278101221,49.20213311424594,250.10357868137993,0.024468425459168545
0.0251140040301702,244.148052744137,0.07973696279579037,49.22024743321802,250.27958792471148,0.024803829849571406
0.0254596860807482,244.26542710867,0.08083450330637552,49.24391010510787,250.4843482032366,0.02514098628098328
0.0258083868318819,244.457162605477,0.08194162819122502,49.28256398126417,250.7662076218234,0.025480971833429907
0.0261585465143507,244.620294158889,0.08305338518306346,49.315451302432024,251.01920550199847,0.0258222635766616
0.0265145669073546,244.782660784766,0.08418374993085086,49.34818441420883,251.27296702190395,0.026169148225995996
0.0268596112847255,244.905292222908,0.08527926582900346,49.372906912138255,251.4833531735874,0.026505223729704108
0.0272093278176602,244.996505600525,0.08638961582107113,49.39129552906585,251.6626958355909,0.0268457347317025
0.0275459780595182,245.074584990027,0.08745848033897029,49.407036333989446,251.82540413110783,0.02717341389029369
0.0278882066393983,245.17246592666,0.0885450560800896,49.426769130814655,252.00988631871357,0.027506412714182332
0.0282321252066491,245.294656387107,0.08963699753111089,49.45140272764077,252.2198458387498,0.02784094427357728
0.0285820527505842,245.44368634936,0.09074801748310482,49.48144716803098,252.45897073989528,0.028181205976419918
0.0289228226719927,245.58129566688,0.09182996198357682,49.50918920644301,252.68419993301137,0.028512451776704407
0.0292611843761433,245.697157193468,0.09290426039425496,49.53254689020315,252.8865470108003,0.02884124813897343
0.0295959663841622,245.788982203994,0.09396719326971498,49.551058812325195,253.0633446589009,0.0291664596388058
0.0299269026350783,245.837216742677,0.0950179158663736,49.56078289532368,253.19436319221373,0.029487831407716446
0.0302598242696003,245.913582788799,0.09607494205598095,49.57617829022188,253.3548845894959,0.029811027002632433
0.0305954373199372,246.053152416567,0.0971405134908006,49.60431552717991,253.58125621870107,0.030136729694673927
0.0309407080023392,246.207918242485,0.09823674790742695,49.63551631768498,253.8257655486895,0.03047169416901857
0.0312920027754326,246.415109753021,0.09935210881199849,49.67728612620904,254.1259320513211,0.030812387801367126
0.0316418448751055,246.52719386836,0.10046285747845995,49.69988228386138,254.3277690942377,0.031151557284116123
0.0319892182344025,246.61631871404,0.10156576789422793,49.71784985275047,254.5053819535484,0.03148821955751173
0.032335792436895,246.697631700587,0.10266614098714162,49.734242550838346,254.67479511393077,0.03182399440300071
0.0326788784099568,246.784859870696,0.10375543895161284,49.75182774993232,254.8495122998287,0.032156278702053974
0.033030398743115,246.920322126739,0.10487151600939013,49.779136940750575,255.07619882436362,0.032496617335800004
0.0333761913175564,247.069112850084,0.10596940743324156,49.80913315057694,255.3153388292273,0.03283129743151029
0.0337298016384952,247.225940886039,0.10709212020222225,49.840749682625464,255.56482283201547,0.03317342824201851
0.0340929056032209,247.353314419023,0.10824497529022634,49.86642818687504,255.78630761815458,0.03352462273000436
0.0344506851675358,247.45666303569,0.10938092540692616,49.8872632679951,255.98171462654153,0.03387054685698809
0.0348043001077394,247.501875489253,0.11050365284207259,49.896378098633406,256.1160050410093,0.034212326817565454
0.0351583515201078,247.55973339896,0.11162776607634227,49.908042253230334,256.2635255280248,0.03455441165232568
0.0355074952016967,247.559747340512,0.11273629726538702,49.908045063847226,256.3499738813385,0.03489164007133936
0.035855316189822,247.644882794658,0.11384062890268483,49.92520837140305,256.5242683700519,0.0352274778970275
0.0362068388785386,247.764770260568,0.11495671343936005,49.94937768453051,256.7355493771705,0.03556677533675829
0.0365569841424947,247.891959228009,0.11606842465242066,49.97501898036661,256.9541416505593,0.035904628847513144
0.036906972785502,248.055046037313,0.11717963859396885,50.0078972811223,257.21000687071853,0.036242217205547426
0.0372589859413701,248.159415228677,0.11829728036385007,50.02893811010128,257.4055833919009,0.03658164342914987
0.0376149397404986,248.277446579097,0.11942743367608305,50.05273323034596,257.6163877710946,0.03692475227852585
0.0379769521915785,248.390384501317,0.12057682320826173,50.075501515465504,257.8234942583713,0.03727358044282724
0.0383341673042565,248.424504725028,0.12171098119101437,50.08238015256564,257.9476512516343,0.037617666753253766
0.0386941265105271,248.452044270729,0.12285385167092354,50.08793212497897,258.0656791035397,0.03796427658129155
0.0390399989036195,248.496777013125,0.1239519965189919,50.096950245846,258.19809091527037,0.038297208877157964
0.0393854914979092,248.5476370911,0.1250489355058617,50.10720363756576,258.33680793857695,0.0386296649590022
0.0397293960017746,248.572130555975,0.12614083230563436,50.11214152008456,258.44775116583816,0.03896048314424962
0.0400733023823095,248.599958580959,0.12723273506383265,50.11775164992134,258.56217989340337,0.03929119372938006
0.040427068177407,248.674403487442,0.12835594146326723,50.13275974306831,258.7275805512048,0.03963127134100955
0.0407892972520946,248.806133997454,0.12950601877540033,50.15931661388672,258.9547613552206,0.03997936496967988
0.0411438363277298,248.981348926717,0.1306316803405421,50.19463994362616,259.22539679561527,0.04031995139231179
0.0415047224019822,249.087726919328,0.13177749362629348,50.21608574693653,259.42604387885547,0.04066651593998999
0.0418572930716656,249.153219085596,0.13289690550253827,50.229288967656146,259.5820983966107,0.0410049791263499
0.0422206814186713,249.231771223296,0.13405066350428138,50.245125078616475,259.7545064355259,0.04135370729788303
0.0425784266828811,249.271524364878,0.1351865047181475,50.2531393119594,259.88511368917796,0.04169690129324782
0.0429381208835735,249.34503802876,0.13632853380534588,50.26795966659802,260.0514454133581,0.04204184624674511
0.0432967538837287,249.406803257506,0.13746719358083861,50.28041153671321,260.2053082350738,0.04238565509399001
0.0436541773828662,249.470305513097,0.13860201319060017,50.293213591440356,260.3607264817236,0.04272818686824232
0.0440192552934753,249.565299393148,0.13976113555678407,50.31236435765864,260.5509780195276,0.04307793305805941
0.0443786139761179,249.620253057417,0.14090209937417433,50.32344301637527,260.69805390847296,0.043422080781515174
0.0447435293559694,249.726012766389,0.14206070570520282,50.34476417370403,260.89963594955117,0.043771428841155945
0.0451027124688366,249.797235691186,0.14320111208855618,50.35912271534309,261.06376858807573,0.04411517003054618
0.0454652379417891,249.859310459858,0.14435213046518036,50.37163698870737,261.21922346188677,0.04446199011502618
0.0458299447163565,249.919055912093,0.14551007447443187,50.38368167187795,261.37283242810827,0.04481077567269314
0.0461934433955369,249.960665153553,0.14666418278082965,50.39207009495629,261.50720899043444,0.0451582848687222
0.0465584696151585,250.029610016242,0.1478231410281282,50.40596937927438,261.6706060170731,0.045507132929549644
0.046925151646485,250.062803540456,0.14898735647758987,50.41266119375593,261.7970385177371,0.04585744093420978
0.0472922479141645,250.101927095283,0.15015288712747227,50.420548502409055,261.9298094352834,0.046208021797033566
0.0476581584759895,250.210401503911,0.15131465316126663,50.442416943188455,262.1349684711253,0.046557348028747544
0.0480332117485242,250.239929227352,0.15250544730156432,50.44836973223417,262.25975673586515,0.046915275996450866
0.048401661676568,250.30269395454,0.1536752758231034,50.46102310123526,262.41776026406114,0.047266777430154144
0.0487739362123395,250.335242685871,0.1548572474741779,50.46758492547159,262.5450778443322,0.047621802102438555
0.0491332514828886,250.376874096429,0.1559980734581713,50.47597781784009,262.6787040169084,0.04796434849931459
0.0494885305995752,250.39751536838,0.15712608465365124,50.48013909826541,262.78932046974563,0.04830293177631465
0.0498489387318887,250.411391209433,0.1582703804737466,50.482936467821695,262.8941333075991,0.048646285945065024
0.0502138971465689,250.446173867634,0.15942912344035626,50.48994865171501,263.0220522829751,0.048993854991208806
0.0505783885746307,250.509441240077,0.16058638372445247,50.50270335399952,263.17980510073124,0.04934085877087484
0.0509504136587017,250.638937058228,0.16176756336637788,50.528809710938766,263.40909458032206,0.04969491062832444
0.0513224761809158,250.733087669526,0.16294886187440766,50.54779047417644,263.60133058921275,0.050048872787944086
0.0516999961678524,250.830909139897,0.16414748783293134,50.567511282603235,263.7988661812086,0.050407898900080704
0.0520800662473723,250.896594848631,0.16535421033540704,50.58075352148401,263.96330612958786,0.05076922001956941
0.052457481564858,250.901933557599,0.16655250396842414,50.58182980521195,264.06361711178397,0.051127888195315586
0.0528427643650221,250.941107742273,0.16777577685894518,50.58972732084224,264.20152956819555,0.05149390041158743
0.0532254277201258,250.951313801483,0.16899073301139939,50.59178486237897,264.30830481549447,0.051857291645311894
0.0536011258270829,250.999671128865,0.1701835745009882,50.601533699579186,264.4535360835998,0.05221393999902372
0.0539837732280492,251.070090252146,0.17139847999905622,50.61573019483263,264.62380106866374,0.0525770545813518
0.0543626270803175,251.084322531695,0.17260134098000804,50.61859942238971,264.7339259231997,0.052936439411368774
0.0547460616636074,251.06877824749,0.17381874578195347,50.61546569469399,264.81380506323364,0.05330003811025088
0.0551335248419358,251.043729212544,0.17504894137314617,50.61041580924887,264.884654893496,0.053667322750722606
0.0555157283119752,251.063440803097,0.17626243739052125,50.614389665904355,265.0014105717914,0.05402948948557529
0.0559022618566571,251.122332448452,0.17748968139488627,50.626262221607924,265.1606388350399,0.05439562594060209
0.0562887996282913,251.161647687911,0.17871693881982487,50.63418817388286,265.2992353489273,0.054761632390489666
0.0566709373947914,251.17389814382,0.1799302262284627,50.63665786579411,265.4081584007341,0.055123340911452615
0.0570516390864666,251.162321253785,0.18113895409953143,50.634323964763055,265.4915433580751,0.055483560081203455
0.0574248128765949,251.127620980322,0.1823237808831888,50.62732838963292,265.54857762326145,0.05583653047598483
0.0578049553271602,251.148389365506,0.1835307331637336,50.63151529608601,265.66601079326733,0.05619596419838449
0.058186241055547,251.13497326782,0.1847413153513617,50.628810610792506,265.7475733598597,0.05655634918785439
0.0585760591663556,251.19472832146,0.18597898785317904,50.64085722960634,265.90872558989446,0.056924664624287226
0.0589696722589022,251.262805747957,0.18722870942201447,50.65458163878813,266.0796910537662,0.057296428115614556
0.0593643353152986,251.325116633129,0.18848176462607302,50.667143513238805,266.2448651300946,0.0576690445769957
0.0597571101716562,251.334486058703,0.1897288247950084,50.66903238943453,266.3535086320495,0.058039740519592056
0.0601473895589188,251.319104998381,0.19096796184956719,50.66593156767361,266.43529311031745,0.058407945211568967
0.0605424010879779,251.313520103147,0.19222212345432982,50.66480565279444,266.5286440360633,0.05878047639021604
0.0609363954345729,251.342151617406,0.19347305550476895,50.670577766069044,266.6580363577406,0.05915191008238463
0.0613351108310667,251.383278368756,0.19473897688863676,50.678868919141216,266.8018996085805,0.059527654090639544
0.0617296022710947,251.402613069041,0.19599148721072565,50.68276679471867,266.9215963837068,0.0598992786031978
0.0621321256334064,251.383941099874,0.19726949888606532,50.679002525734596,267.0029597105122,0.06027832716539242
0.0625369901912441,251.372226714598,0.19855494385720002,50.676640905662964,267.092289191,0.06065943550807269
0.0629425459417964,251.359809194244,0.19984258336520352,50.674137533559595,267.1810355323739,0.06104104892620234
0.0633459375975012,251.347755247089,0.2011233518720663,50.67170745781315,267.26961446624307,0.061420481598360624
0.0637487598097884,251.334176097252,0.20240231239607817,50.668969901206005,267.35641812126676,0.061799235038528286
0.0641536344882444,251.32827315353,0.20368778950017596,50.667779867751655,267.4518953259832,0.06217977381176026
0.0645563844103922,251.309823999404,0.20496652050299521,50.66406051827985,267.53347760361754,0.06255817192458726
0.064956635293818,251.312786306021,0.20623731705787213,50.664657719293835,267.6372193107744,0.06293408029841309
0.0653577792895087,251.239816128492,0.2075109492441901,50.64994693150399,267.6602925797547,0.06331068574001902
0.0657562852184026,251.207491757795,0.20877620556842824,50.64343033837147,267.7259632348201,0.06368467410617516
0.0661617009600251,251.132443586456,0.2100634005480797,50.62830062702953,267.74779322038347,0.06406500369590402
0.0665708015541013,251.168527695574,0.21136229493427164,50.63557518342772,267.88901790943186,0.06444864355567231
0.0669846687859566,251.186986294984,0.2126763233954122,50.63929643706877,268.0126633752961,0.0648366036933858
0.067392277981913,251.219588919078,0.21397048259257376,50.645869126086126,268.1498492900144,0.06521855047324483
0.0678068224326786,251.219769003965,0.21528666122375456,50.645905431199346,268.25418327239544,0.06560684630560422
0.0682256900062587,251.214596922305,0.21661656576987134,50.644862739536684,268.3538861369734,0.06599903844360765
0.0686432844935147,251.20530599407,0.21794242826690916,50.64298968840451,268.44886327970136,0.06638988551711131
0.0690737661568372,251.177547489502,0.2193092075479581,50.6373935738836,268.5273266686397,0.06679263448616729
0.0694954873499824,251.149271211612,0.2206481723361941,50.63169307626098,268.6030122120559,0.06718703012981564
0.0699217188831351,251.128234174435,0.22200145745395394,50.6274520095661,268.687551967998,0.06758548587519356
0.0703440818839037,251.116478464088,0.22334245998139424,50.62508205836014,268.78103658756334,0.0679801686347834
0.0707607811304086,251.03938711379,0.22466548008904727,50.60954044214007,268.8031302404608,0.06836940622791958
0.0711816930718101,250.983036593426,0.22600187550299708,50.59818017723468,268.84843407045014,0.0687624251365869
0.0716070364689601,250.918863988041,0.2273523407889483,50.58524297998907,268.8864202323827,0.06915942498717655
0.0720365494871766,250.903614381099,0.22871604462178569,50.58216865922956,268.97784501497455,0.0695601567382739
0.0724659912133988,250.920740539692,0.2300795221025412,50.58562129280191,269.1039607189008,0.069960661492931
0.0728995141948684,250.89697656302,0.23145595756870715,50.58083047510483,269.18724426742546,0.07036480986417848
0.0733309137436697,250.845447103198,0.2328256511361513,50.57044213600472,269.2401729477149,0.07076681660958227
0.0737648176333737,250.786666787304,0.23420329598596148,50.55859202432049,269.2858995277511,0.07117099411249449
0.0741923406710867,250.739281418726,0.23556068163070024,50.54903913401516,269.3422156053676,0.07156906820043032
0.0746238121321551,250.698373126658,0.23693060351959244,50.54079202233425,269.40644142469864,0.07197065813291885
0.075057431368534,250.677446497831,0.23830734459509545,50.53657321396273,269.4926517339813,0.07237408468145558
0.0754931146418687,250.675137945408,0.2396906389879331,50.53610780979426,269.59938487218693,0.07277926769852407
0.075936596822024,250.666870074185,0.2410986949099262,50.534441006955696,269.70165912364706,0.07319153511685857
0.0763850934864663,250.684369563501,0.2425226718195305,50.5379689040018,269.8329185682049,0.07360829128574652
0.0768395772074814,250.674672784663,0.24396565763375344,50.53601403338806,269.93640865806026,0.07403043369749769
0.07729753544192,250.647996335007,0.245419675028096,50.530636061137415,270.0224687151585,0.07445562319787703
0.0777562072111295,250.602696391569,0.24687595789533615,50.52150359254031,270.0886115798596,0.07488129404501846
0.0782164167870558,250.553421450898,0.24833712329890217,50.51156976450104,270.1508122905243,0.07530821002511338
0.0786750260550729,250.495029796751,0.24979320772485644,50.499798007025,270.2027327926766,0.07573346024013937
0.0791331132418107,250.436052534967,0.25124763454274895,50.48790819104935,270.2538370400486,0.07615804589748042
0.0795932397597543,250.388990632255,0.2527085362372199,50.47842051146261,270.31826159685096,0.07658434034121288
0.0800612061560686,250.333849139527,0.2541943295455178,50.46730398652864,270.37587904332884,0.0770177118970406
0.0805270608022675,250.285548796094,0.2556734180471993,50.45756663729255,270.4403084019259,0.07744894135481585
0.0810053251997772,250.238254914073,0.2571919075092926,50.44803219067711,270.5088861308122,0.0778914648241949
0.0814828724863036,250.186004193593,0.25870812014401395,50.437498445428346,270.5718784711574,0.07833312947216887
0.0819614367476529,250.213602268834,0.26022756167379796,50.443062217396935,270.7214686045934,0.07877553907533011
0.0824353817757883,250.148874561738,0.2617323371381278,50.43001311164639,270.76999253701865,0.07921348560311507
0.0828935183460718,249.980038103337,0.2631869207487779,50.395975681632734,270.70176297800765,0.07963664217493546
0.0833460408135103,249.790354122319,0.2646236795828952,50.357735391059514,270.60939117181897,0.08005443758644251
0.0838039878867373,249.638599094015,0.2660776615403909,50.32714157735342,270.5593092285519,0.08047706368429328
0.0842720537948053,249.626614058406,0.26756377079850685,50.32472539417465,270.6631615069511,0.08090884366464576
0.0847480374265215,249.678742614669,0.26907501882920576,50.33523451111727,270.8385260383838,0.08134773645432819
0.0852383514341822,249.701183783153,0.27063176580352843,50.33975865068364,270.9853010399927,0.08179964160776311
0.0857341487668422,249.696600556435,0.27220592233472396,50.33883467217729,271.10412605511516,0.08225639298645045
0.0862279583184127,249.667229218802,0.27377376766096034,50.332913410510486,271.1955246533544,0.08271110585502962
0.0867255066647737,249.610353009811,0.2753534836606565,50.3214471667779,271.25793734335986,0.08316905248211959
0.0872293146826893,249.540572606329,0.2769530741175385,50.307379437435934,271.3078257403049,0.08363254695954633
0.0877300679662186,249.464005102437,0.278542965792744,50.2919434286513,271.3494992251989,0.08409301835627418
0.0882400065690972,249.375480414816,0.2801620208568836,50.27409685162691,271.38037444479113,0.08456171837947904
0.0887511748037747,249.297513135376,0.28178498000198465,50.258378648091806,271.4229603018001,0.08503132822305172
0.0892595516344372,249.216321095307,0.2833990764393381,50.24201033281389,271.461258176258,0.08549815497805692
0.0897799750530826,249.140986146397,0.28505142079353724,50.22682280711364,271.5088576673209,0.08597581811556919
0.0902961663043574,249.069217549562,0.2866903280163347,50.212354257991706,271.55921303871344,0.0864493715398086
0.0908225743326054,248.977960801696,0.28836167350602215,50.19395689762192,271.59078015378856,0.08693206698289598
0.0913534266746061,248.893103132587,0.29004712969187435,50.17684959152954,271.63034097942494,0.08741860184738667
0.0918810632106779,248.794455394975,0.29172237569390236,50.15696220762696,271.65395447758686,0.08790195491714527
0.0924085730699683,248.676946501489,0.29339721949714936,50.13327241470019,271.65682828308843,0.08838495850859558
0.0929350918322979,248.555932408291,0.2950689165675458,50.108875973511466,271.65550081211796,0.08886682209918205
0.0934645168014242,248.433257756021,0.29674984084452183,50.084144763613835,271.6529521495912,0.08935111140968427
0.0939997425018306,248.36274322756,0.29844918244331214,50.0699290346761,271.70877713799894,0.08984046862666362
0.0945349394816579,248.271062378616,0.30014843285426385,50.05144617552898,271.74135223562536,0.09032956025029827
0.0950752782225072,248.18061964254,0.3018640083564604,50.03321291993606,271.77646110448876,0.09082310814064773
0.0956212652795277,248.0804287484,0.30359751726250045,50.01301443567744,271.8021932364097,0.09132156792956246
0.0961627886634578,247.984216707668,0.3053168540064785,49.99361808826587,271.83107053080056,0.09181570729878975
0.0967057295198078,247.801291350698,0.30704069122538974,49.95674033630072,271.76509600671767,0.09231089509773209
0.0972451724580175,247.641563737304,0.30875342255420557,49.924539249440485,271.7235103107113,0.09280264990281387
0.0977927468174321,247.507551605639,0.3104919711453469,49.897522403696826,271.71199493521175,0.09330157009545807
0.0983598237878891,247.428728630262,0.31229244052654787,49.881631691860825,271.765774778396,0.09381799777052072
0.098931472085356,247.373068864627,0.3141074238710053,49.8704106831088,271.8460507216767,0.09433831868694867
0.0995137545650286,247.251558027526,0.3159561707439658,49.84591409834924,271.8564888888981,0.09486804077074674
0.10009690182617,247.103530701735,0.31780766329808974,49.81607178946978,271.83782855528653,0.09539826849364773
0.100682661999916,246.933553846227,0.3196674518497333,49.78180445539936,271.7954813845647,0.0959305891287591
0.101270198726978,246.749742771365,0.32153288095815513,49.74474814270719,271.7381382576518,0.0964642397363488
0.101865486169014,246.587406183053,0.3234229185866194,49.71202108650348,271.7061521970458,0.09700463991288275
0.102467115616621,246.404826726451,0.32533309208277167,49.67521306805253,271.65321859512375,0.09755050078892141
0.103065155631068,246.198799655565,0.3272318691286409,49.63367801056191,271.5733172582479,0.09809280981509184
0.103658464417803,245.938128756966,0.32911562452652454,49.58112675740435,271.431697525701,0.09863053805223114
0.104251216258058,245.669130677001,0.3309976116193341,49.5268967444834,271.2804363471381,0.09916747292749692
0.104852140768263,245.41602974458,0.332905546939235,49.475871596507325,271.1484258421469,0.09971151675696797
0.105459820461293,245.228127862368,0.33483492996460523,49.43799057705339,271.0898421987924,0.10026137552713252
0.106075359244812,245.045467269992,0.33678926560227807,49.40116620163039,271.03875324196923,0.10081803752831817
0.106698317103064,244.809936611879,0.3387671568022282,49.35368322095481,270.93074485847427,0.10138109364324652
0.107318483031938,244.509583184957,0.3407361836264031,49.29313197008734,270.74998073913804,0.10194131156485926
0.107941755825195,244.17862303964,0.3427150747449941,49.22641040479142,270.53569234551713,0.1025040199986319
0.108570101411813,243.829928225229,0.34471007198250625,49.15611353020617,270.3025682598772,0.10307098795903187
0.109202545051884,243.521381240396,0.3467180805397317,49.09391045806384,270.1145358463974,0.1036413292500776
0.109843532825752,243.181630173664,0.34875321672176257,49.02541664301066,269.89355955026474,0.10421904397000696
0.110478427972125,242.824755586774,0.35076900881149686,48.95347072629364,269.6516528567162,0.10479093865454986
0.111125360912186,242.446958867326,0.35282302089619055,48.87730690765292,269.3889646735195,0.10537334039655644
0.111769473275758,242.0557215549,0.35486807765053163,48.798433465467845,269.1101620564747,0.10595286613182071
0.11242164357346,241.651573069401,0.3569387183457355,48.71695713079124,268.8184400859751,0.10653929983479878
0.113076252224046,241.192252429127,0.359017100811346,48.624358089712004,268.46536839928876,0.10712758048040244
0.113743183814017,240.740431953598,0.36113460860950397,48.53327108184536,268.12301515676194,0.10772657975184662
0.114418102116978,240.263846738381,0.36327747422140516,48.43719150245761,267.7543800895111,0.10833238717509198
0.115104529519368,239.768892583701,0.3654568812239934,48.33740874487412,267.36737815792776,0.10894814896583464
0.115780701104078,239.222230429905,0.3676037260054476,48.22720165466885,266.9195479887607,0.10955434026257552
0.11646799721282,238.643229511109,0.3697858911507035,48.11047506943958,266.4375285006672,0.11017012839673689
0.11714461378605,238.101407324036,0.37193414877070874,48.001243716525664,265.99370472692516,0.11077597794342578
0.117847819171675,237.434679024526,0.3741668258700681,47.86683129134445,265.415838143293,0.1114052466590241
0.118560613768703,236.863384068394,0.376429948715632,47.751658228188234,264.9460522628748,0.11204269249464642
0.119262689708888,236.188152686659,0.37865903982571936,47.61553158163046,264.3565870534435,0.1126701557640909
0.119966253504462,235.468951148257,0.3808928548766668,47.47054055148861,263.7172790341386,0.11329855405347411
0.120681034509173,234.770835590778,0.38316228456662427,47.32980045510085,263.1032229024561,0.11393656703550956
0.12137520452889,234.026432815647,0.3853662743792257,47.17972885563444,262.4314389638127,0.11455579328845661
0.122089043658507,233.106632231811,0.3876327136157597,46.9942970579331,261.5663980314481,0.11519216550101483
0.122789390298548,232.325713299955,0.3898563141978899,46.83686380127093,260.8528459867317,0.11581611613653123
0.123471029068008,231.433070750386,0.39202051729092535,46.65690706327782,260.00835015630526,0.11642302598946362
0.124208287131272,230.494061845732,0.39436131164178856,46.467602868099576,259.12333446151985,0.1170790431395891
0.124942150535271,229.724096415136,0.3966913279494854,46.312377837291415,258.426319051015,0.11773161258781437
0.125670435570259,228.773081851368,0.39900363293557234,46.12065330123579,257.5230946943799,0.11837880088215202
0.126371516843954,227.826982957107,0.40122956597955395,45.92991976415277,256.6178243713783,0.1190014192091256
0.12707543995063,226.699064600374,0.4034645218432502,45.702531423435396,255.5069479708628,0.11962617154904594
0.127803893843979,225.642575106864,0.4057773629546333,45.489543141543784,254.48057482250368,0.1202722849864909
0.128587044261598,224.521742071738,0.40826386553057364,45.263583201662385,253.39232925720765,0.12096644700942828
0.129342355198474,223.571177181571,0.41066197775515495,45.07194931980471,252.48839979273072,0.12163547675431742
0.130120608892251,222.24694971833,0.4131329332328969,44.80498506321533,251.1658581401246,0.1223243605615965
0.130877073894354,221.043813940128,0.4155347096145739,44.5624328903298,249.97338151105998,0.12299350324678177
0.131638433432477,219.737037194189,0.41795202614811444,44.29898669834851,248.66287653752596,0.12366652366533434
0.13240337958732,218.492936936185,0.42038073018974104,44.0481760863349,247.4221402024951,0.1243422586977454
0.133157355056493,217.297574299257,0.42277460230436525,43.80719097873021,246.23234455313786,0.1250078559474497
0.133946562862097,215.868510313832,0.42528033708715796,43.519091679268534,244.78335530053093,0.12570408149868773
0.13469743082305,214.640369167561,0.4276643428631837,43.2714984241803,243.55187544534246,0.12636603462175247
0.135448815415611,213.086145623834,0.43004998894456486,42.95816695776494,241.94841163006072,0.12702800485494287
0.136217601342948,211.68641057374,0.43249088426385984,42.675980371665986,240.52182565899332,0.12770485243345633
0.137018510945017,210.045468749146,0.43503377225042894,42.34516649982784,238.8255861079021,0.1284094951503997
0.137848798306383,208.461748284534,0.437669934622766,42.02588845416205,237.1979497784047,0.1291394607135405
0.138644069879417,206.812129787438,0.4401949218671489,41.6933253651475,235.4854051615986,0.12983814210762637
0.139432558949506,205.05854083049,0.4426983746646816,41.33980183142678,233.65037791293696,0.1305303831776568
0.140195749609103,203.362605374804,0.445121505008902,40.997901243560484,231.87317827778486,0.13119995784932167
0.140957668578297,201.563922412845,0.44754059773609295,40.63528675842955,229.97590298565635,0.13186796990975777
0.141736125687502,199.716197395021,0.4500121990578188,40.262785394836236,228.02319745083167,0.13255002121365003
0.142519504694529,197.713199472205,0.45249942740512955,39.85898101359653,225.89118673255425,0.13323591558319364
0.143304151409742,195.553070483728,0.45499068072593085,39.42349900951957,223.5766373049681,0.1339224486356769
0.144120141311874,193.385607926589,0.45758144866519995,38.98653855800034,221.25636906865165,0.13463590607279646
0.14489790669967,191.137509992296,0.4600508537714523,38.533322014446874,218.83293508196695,0.13531546857638008
0.14567250433751,188.655729116102,0.4625102012715942,38.03299498980617,216.13768163406348,0.13599180462231392
0.14626946457543,186.788693448343,0.4644055500269902,37.65660059918595,214.11017562777624,0.13651272553524804
0.146661606930811,185.552796505775,0.46565060200532493,37.407443775564246,212.76626781181776,0.13685477014712275