File: example/data/02 processed data/test_ID_092.csv
Strain,Stress_MPa,Displacement(mm),Force(kN),True Stress (MPa),True Strain
-3.89875325494454e-05,-0.847834930057492,-0.00012378541584448914,-0.1709235218995904,-0.8478018750655598,-3.89882925830966e-05
-9.59720092044713e-05,-0.383965922108705,-0.0003047111292241964,-0.07740752989711493,-0.38392907212769417,-9.597661481247646e-05
-0.0001988258949893,0.887906983218378,-0.0006312722165910274,0.17900204781682502,0.8877304443177724,-0.000198845663477946
-0.000322181527444,3.64071084763231,-0.0010229263496346998,0.7339673068826736,3.639537877850438,-0.0003222334390625987
-0.0003890350699632,7.56498766026021,-0.0012351863471331598,1.5251015123084586,7.56204461475653,-0.0003891107637383954
-0.0004026797126272,12.0429029931039,-0.00127850808759136,2.4278492434097463,12.03805356038744,-0.0004027608098742186
-0.0003356912474956,16.8658538908899,-0.00106581971079853,3.400156144403404,16.860192171357188,-0.0003357476044150761
-0.0002578031858512,21.6734552611097,-0.00081852511507756,4.3693685806397164,21.667867775294983,-0.0002578364228050595
-0.0001753349956973,27.002210035361,-0.0005566886113389275,5.443645543128778,26.997475602980632,-0.00017535036867466098
-7.54851831598588e-05,32.3424501781496,-0.00023966545653255166,6.520237955914959,32.340008802374065,-7.54880323096252e-05
1.06751099948379e-05,37.775543844021,3.389347423361033e-05,7.615549638954634,37.77594710210665,1.0675053016280898e-05
0.0001133255298859,43.0952502605584,0.00035980855738773247,8.688002452528574,43.10013405262975,0.00011331910903319704
0.0002140617229135,48.4975578711888,0.0006796459702503625,9.777107666831663,48.507939341983814,0.00021403881497208108
0.0003274243126389,54.0730620068567,0.0010395721926285074,10.90112930058231,54.090766842016585,0.000327370720996556
0.0004302157088981,59.9503809353551,0.0013659348757514675,12.085996796567589,59.97617253098791,0.0004301231926535928
0.000542542989798,65.7302293827934,0.0017225739926086498,13.251214243571148,65.76589085796284,0.0005423958665615484
0.0006503282249974,71.5018912696109,0.002064792114366745,14.414781279953557,71.54839096764422,0.000650116853233047
0.0007546318080282,77.1506554174012,0.002395955990489535,15.553572132148082,77.2088757559894,0.0007543472166109075
0.0008543483730344,82.8505526861792,0.0027125560843842197,16.702671421533726,82.92133592107163,0.000853983625196108
0.0009591921320409,88.5113635067363,0.0030454350192298573,17.84389088295804,88.59626291020817,0.000958732401224426
0.0010649133888934,93.945786250827,0.0033811000097365446,18.939470508166725,94.04583037643562,0.0010643467708608485
0.0011749900755355,99.2642195369072,0.0037305934898252124,20.011666658640493,99.38085400971886,0.0011743003149517833
0.0012857071938767,104.579901871682,0.004082120340558522,21.08330821733109,104.71436100385334,0.001284881380143231
0.001395667137984,109.866966556093,0.0044312431630992,22.14918045770835,110.02030427086532,0.0013946940998569835
0.0015015302208293,115.2973993886,0.004767358451133027,23.243955716741763,115.47052191816499,0.0015004040515044228
0.0016098238708434,120.614650370762,0.005111190789927795,24.31591351474562,120.80881871410227,0.0016085294933560492
0.0017125763877622,125.854165441099,0.005437430031144984,25.372199752925557,126.06970031313493,0.0017111116009545732
0.001813500214121,130.930248721116,0.005757863179834175,26.395538142176985,131.16769075520665,0.001811857807977237
0.0019177826277359,135.891646773166,0.006088959843061482,27.395755989470267,136.152257412602,0.0019159460303870514
0.0020076145664828,140.765695472257,0.006374176248582889,28.37836420720701,141.04829873294818,0.0020056020015454196
0.0021045853486715,145.645171702645,0.006682058482032013,29.362066615253234,145.95169439711512,0.0021023738112956832
0.0021993495203376,150.490849028603,0.00698293472707188,30.338955164166368,150.82183100522926,0.0021969344915280576
0.0022982192298779,155.263966374444,0.007296846054862332,31.301215621087913,155.62079700767288,0.002295582363355749
0.0023905042351329,160.028096270519,0.0075898509465469575,32.26166420813663,160.41064411239392,0.002387651525255969
0.002479866048968,164.783378814562,0.0078735747054734,33.220329169015706,165.19201952111848,0.002476796255228347
0.0025782591469049,169.392380620088,0.008185972791423057,34.14950393300974,169.82911807483774,0.0025749411386901846
0.0026806633752971,174.036890185388,0.008511106216568292,35.08583706137422,174.50342450285856,0.002677076805392596
0.0027842132038876,178.54042719979,0.00883987692234313,35.99375012347767,179.03752181462738,0.002780344461577183
0.002886319321576,183.075397471507,0.009164063846003798,36.90800013025581,183.6038115285342,0.002882161899806284
0.0029775678267216,187.591288517068,0.00945377784984108,37.818403765040905,188.1498543023297,0.002973143651652174
0.0030755715601354,192.087123431544,0.009764939703429894,38.72476408379927,192.67790112543827,0.003070851665031775
0.0031644904786404,196.617389603456,0.01004725726968327,39.63806574405673,197.23958346079124,0.003159494016708069
0.0032587281550548,201.03009263105,0.01034646189229899,40.52766667441968,201.6851950539201,0.0032534300074887742
0.0033516962489978,205.311680149183,0.010641635590568015,41.3908347180753,205.99982253741447,0.003346091834496996
0.0034384808736293,209.468116775071,0.010917176773773025,42.22877234185431,210.1883688882372,0.003432582814645037
0.0035318565104656,213.64916788108,0.011213644420728279,43.07167224482572,214.40374608561635,0.0035256341519413373
0.0036223261935762,217.677681421218,0.011500885664604435,43.88382057451755,218.466180988387,0.0036157813702780333
0.0037171839769768,221.460348464234,0.011802059126901339,44.646406250389575,222.2835573230809,0.0037102923217046
0.0038140941212491,225.005997607929,0.012109748834965892,45.36120911775849,225.86419166065116,0.0038068389064625204
0.0039193243782742,228.376753811077,0.012443854901020585,46.04075356831312,229.2718363897199,0.003911663836059247
0.0040241944938042,231.850081252598,0.012776817517828333,46.740976380523755,232.78309107296275,0.004016119080581478
0.0041297938161366,235.13752782095,0.013112095366233704,47.40372560870352,236.10859732928662,0.00412128962332323
0.0042429347855273,238.306501215975,0.013471317944049176,48.042590645140564,239.31762015960157,0.004233958918120016
0.0043636324515503,241.267992547804,0.013854533033672201,48.63962729763729,242.320797389606,0.004354139413531191
0.0045035958833366,244.058621744657,0.014298916929593704,49.20221814372285,245.15776314883902,0.004493485040796689
0.0046653718882328,246.698710110801,0.014812555745139141,49.73445995833748,247.8496513378152,0.004654522771162633
0.0048763705310112,249.133559142701,0.01548247643596056,50.22532552316852,250.34842668879043,0.004864519547143902
0.0051308872888051,250.799857246534,0.016290567141956192,50.56125122090126,252.0866830461144,0.00511776913931724
0.0054404092950208,252.112285392865,0.01727329951169104,50.825836735201584,253.4838794137053,0.0054256637254846765
0.0057828747780649,252.749761894418,0.018360627420356056,50.954351997914664,254.21138211763912,0.005766218142357029
0.0061485255851077,253.127384708161,0.019521568732716946,51.030480757165265,254.68374490933053,0.006129700526500611
0.0065381602759076,253.481259972276,0.020758658876006628,51.10182201041084,255.13856107691376,0.00651687921497157
0.0069430195314532,253.639080106003,0.02204408701236391,51.13363854937021,255.40010119311881,0.0069190277575675125
0.0073631255219653,253.844811112898,0.023377923532239827,51.17511392036024,255.71390232022182,0.0073361500481735325
0.007785080636226,254.080213975271,0.024717631020017547,51.22257113741463,256.0582489291381,0.0077549332613765865
0.0082127645978942,253.953082409424,0.026075527598314083,51.19694141373988,256.03873929416227,0.008179223365748722
0.0086350065064399,253.932967716636,0.02741614565794668,51.19288629167382,256.12568054506875,0.00859793807566816
0.0090562447081771,253.898211133908,0.02875357694846229,51.185879364595856,256.19757546490507,0.00901548283887556
0.0094773909678667,253.845874655763,0.030090716322976774,51.17532833060182,256.25167125545573,0.009432762252363811
0.0099035232468767,253.932757483433,0.03144368630883352,51.19284390866009,256.4475864503137,0.00985480475294962
0.0103265562795274,254.127978625269,0.03278681618749949,51.23220049085423,256.75224549874537,0.010273601644571842
0.0107465527072605,254.136993096244,0.034120304845552084,51.23401780820279,256.86808968741747,0.010689218904443736
0.0111679070006738,254.284193107039,0.03545810472713932,51.26369333037906,257.1240153273998,0.011106006367918982
0.0115861405663141,254.296969116281,0.03678599629804726,51.26626897384225,257.2432895460498,0.011519535212024663
0.012010726719224,254.390309603772,0.0381340573335362,51.28508641612044,257.4457220924417,0.011939170334024122
0.0124347554173074,254.472252966818,0.03948034844995099,51.301606198110505,257.63655319295157,0.012358078828252185
0.0128617818592725,254.634566998641,0.04083615740319018,51.33432870692603,257.90962125320783,0.012779771593171669
0.0132866538930198,254.794587691856,0.04218512611033786,51.36658887867818,258.1799551923324,0.013199160451833565
0.0137021535494282,254.940480339028,0.043504337519434534,51.39600083634805,258.43371394659835,0.013609127848498267
0.014116016577015,255.061813304339,0.04481835263202262,51.42046156215474,258.6622700891065,0.014017313394352459
0.0145211018369975,255.196573086943,0.04610449833246706,51.44762913432771,258.90230851319126,0.014416680301020682
0.0149382315954187,255.174806179425,0.04742888531545437,51.44324092577208,258.9866665314493,0.014827755070959243
0.0153499085653727,255.165127011874,0.04873595969505832,51.4412896055938,259.081888380578,0.015233290588261169
0.0157687536373105,255.220395102365,0.05006579279846083,51.45243165263678,259.24490263595123,0.015645718562725824
0.0161749080618454,255.241391417247,0.05135533309635914,51.456664509716994,259.36989745699844,0.01604548794373746
0.0165791424488324,255.368593575219,0.05263877727504287,51.482308464764145,259.6023858650605,0.016443208850714864
0.0169804770851228,255.335464406286,0.05391301474526488,51.47562962430726,259.67118240865614,0.016837920309032344
0.0173777047152415,255.405054698717,0.055174212470891756,51.489659027261354,259.8434083220514,0.01722843918493203
0.0177669841177883,255.535580182102,0.056410174573977845,51.515972964711764,260.0756767767272,0.017610996169140997
0.0181469480199458,255.709940713478,0.057616559963327915,51.55112404783716,260.35029571578895,0.017984257435809666
0.0185304065892935,255.912833942171,0.05883404092100686,51.59202732274168,260.65500280653777,0.01836081052411378
0.0189243946621455,255.964764362072,0.06008495305231196,51.602496495393716,260.80874258246297,0.01874755586690212
0.0193176730795504,256.046743029054,0.06133361202757252,51.61902339465729,260.9929703039729,0.019133455489434244
0.0196999957769763,256.187834262272,0.06254748659189975,51.64746738727404,261.2347335153515,0.01950846224660561
0.0200822668795954,256.406986134236,0.06376119734271539,51.691648404661976,261.5562196595764,0.019883277847361543
0.0204721254229203,256.514129043291,0.06499899821777196,51.71324841512747,261.76551846581646,0.02026538826748957
0.0208568253797759,256.562283390789,0.06622042058078847,51.72295633158306,261.91335813450723,0.02064229955487275
0.0212444291176243,256.50488969475,0.06745106244845715,51.711385762461596,261.95418964219414,0.021021912212814707
0.0216110935270171,256.580044592857,0.06861522194827929,51.72653698991997,262.12501993371944,0.021380884650430292
0.0219904555498878,256.753104468674,0.06981969637089376,51.76142586088468,262.3992221997881,0.021752152745622002
0.0223647086139958,256.946239985646,0.07100794984943666,51.800361981106235,262.6927677723868,0.022118285866568117
0.0227385109277439,257.060068423947,0.07219477219558687,51.82330979426771,262.9052315988915,0.022483844254368723
0.0231218232675674,257.19501951231,0.07341178887452648,51.8505159336817,263.1418372987722,0.022858564207536576
0.0234922423500356,257.320325965474,0.07458786946136303,51.87577771463956,263.3653574246451,0.023220546559496215
0.0238675090666253,257.543949076138,0.07577934128653532,51.92086013374942,263.69088161576724,0.023587132569143597
0.0242441323202155,257.662641536977,0.07697512011668421,51.94478853385456,263.90944871237576,0.02395490867101698
0.024612644913051,257.783390239477,0.07814514759893691,51.96913147227857,264.1281212879237,0.024314633763472614
0.0249779434529729,257.905583899617,0.07930497046318896,51.99376571416279,264.3475349904676,0.024671093776378005
0.0253509910669993,257.933626514693,0.08048939663772277,51.999419105362115,264.47249957634574,0.02503498428376165
0.0257217475421441,258.064671132844,0.08166654844630751,52.02583770038135,264.70254545326947,0.025396508740894552
0.0260913154314998,258.202309918316,0.08283992649501186,52.05358567953251,264.9391478315367,0.02575674418341267
0.0264538580275247,258.141924788501,0.08399099923739092,52.04141203736181,264.97077461780793,0.026110005689646935
0.0268204457339803,258.240981726382,0.08515491520538744,52.06138191603862,265.16711996306424,0.026467081906574326
0.0271863182765403,258.251362122681,0.08631656052801544,52.063474603932484,265.2722658486983,0.02682333443002304
0.027562655156266,258.390166142729,0.08751143012114454,52.091457494374175,265.51208518789133,0.02718964378342792
0.0279288410415942,258.500870844101,0.08867407030706158,52.11377556217076,265.7205005750195,0.027545943860445406
0.0282965998232461,258.582451562351,0.08984170443880636,52.13022223496997,265.89945571552477,0.027903646647566404
0.0286569844031799,258.712750876947,0.09098592548009618,52.156490576792514,266.1266781437314,0.028254052788361083
0.0290260760377473,258.854578973528,0.09215779141984767,52.18508312106326,266.3681116655327,0.028612797675386284
0.0294012634357577,258.953703369955,0.09334901140853069,52.205066599382924,266.5672694204001,0.028977335587383937
0.0297725968654182,259.052479183322,0.09452799504770278,52.22497980335772,266.7651442130342,0.02933799812379678
0.03014330038109,259.269618856938,0.09570497870996075,52.2687551615587,267.0848608578334,0.02969791914792139
0.030519708594942,259.34563353657,0.09690007478894085,52.284079720972514,267.26078669747676,0.03006324643957345
0.0308941932140389,259.495365966994,0.09808906345457351,52.31426577894598,267.51226594132606,0.030426574369872044
0.0312664418834162,259.601858256957,0.09927095297984644,52.33573462460253,267.71868467097494,0.03078760218417984
0.031633039607458,259.700207384,0.10043490075367915,52.355561808614404,267.9153143302431,0.031143022049461996
0.0320017361088061,259.867109006343,0.10160551214545936,52.38920917567875,268.1833076521223,0.031500349333930845
0.0323663628193189,259.973064966224,0.10276320195133751,52.41056989719076,268.38744751017117,0.03185360679270868
0.0327231353800875,259.889062527125,0.1038959548317778,52.393635005468404,268.39344750400414,0.032199134252539494
0.033088090725444,259.938219367819,0.10505468805328469,52.40354502455231,268.5390787532718,0.032552463099378454
0.0334491192567016,260.0327044933,0.10620095364002756,52.422593225849276,268.73056943653904,0.03290186743934068
0.0338172417304999,260.157156644764,0.10736974249433719,52.44768277958442,268.9549540989395,0.0332580116543642
0.0341867525239947,260.339664858342,0.10854293926368318,52.48447643544175,269.23983255303386,0.033615371503236735
0.034553681557527,260.458118679064,0.10970793894514821,52.50835672569931,269.4579055709729,0.03397010816457425
0.0349204029412084,260.585886676294,0.11087227933833665,52.53411475394088,269.6856508398223,0.03432451838914966
0.0352842287793236,260.615976462974,0.11202742637435242,52.540180854935564,269.8116102000404,0.03467600619502752
0.0356529346515875,260.723077360031,0.11319806751879032,52.561772395782256,270.018620199309,0.03503208254796597
0.036025803177288,260.870507885683,0.11438192508788939,52.5914943897537,270.2685774575318,0.03539205006891232
0.0363961065439404,260.938719277571,0.11555763827701075,52.60524580635832,270.43587270583686,0.03574941298700959
0.0367626157090523,261.086777196042,0.11672130487624105,52.63509428272208,270.6850100528151,0.036102988586404046
0.0371340915918677,261.184583127475,0.11790074080417995,52.65481195849896,270.8834353597144,0.036461228112490696
0.0375006076941739,261.262640317709,0.11906442942900211,52.670548288050135,271.0601480974075,0.03681455885186907
0.0378700670027035,261.420833725205,0.1202374627335836,52.70244007900133,271.3208582142811,0.0371706006105167
0.0382355875738423,261.467059709392,0.1213979905469493,52.711759237413425,271.4644063685855,0.037522721972076296
0.0386083508666571,261.441251855475,0.12258151400163629,52.70655637406376,271.5350674381292,0.037881692898989114
0.038989606726652,261.502456455453,0.12379200135712008,52.718895221419324,271.69833439070453,0.03824870891657916
0.0393639864447111,261.523950820369,0.12498065696195773,52.72322848538639,271.8185760754293,0.03860897458392126
0.039738684419652,261.608598099549,0.1261703230323951,52.740293376869076,272.0045796208945,0.03896941659984319
0.0401080300363754,261.639947017935,0.12734299536549187,52.7466133188157,272.133809871646,0.03932458279361979
0.0404806095104563,261.602899616059,0.12852593519569874,52.739144562597495,272.1927444422198,0.03968273093591158
0.0408536274831939,261.643241290823,0.12971026725914062,52.74727744422992,272.3323168040137,0.040041172141654736
0.0412287655020149,261.730501281679,0.13090133046889732,52.76486905838649,272.52132674374616,0.04040152101559391
0.0416066468498425,261.887295790416,0.13210110374824993,52.79647883134786,272.78354802082805,0.040764373836064086
0.0419772513774663,262.081505652439,0.1332777731234555,52.8356315395317,273.08296689659625,0.041120111401369286
0.042353991205306,262.230455648765,0.13447392207684655,52.86565985879103,273.3369620610761,0.041481608484218224
0.0427239755197581,262.331784494096,0.13564862227523197,52.88608775400975,273.5396412328762,0.04183649623828768
0.0431018205278418,262.402629981577,0.1368482801758977,52.90037020428592,273.7126610450766,0.04219879400345343
0.0434721072131443,262.41863108878,0.13802394040173313,52.90359602749805,273.826521954198,0.04255371714733703
0.0438520911846514,262.464297028467,0.1392303895112682,52.91280228093895,273.97390531447473,0.04291780431309334
0.0442296813650511,262.485080181274,0.14042923833403723,52.91699216454484,274.0947116407716,0.043279466571228366
0.0446029174194913,262.460818016163,0.14161426280688488,52.91210091205846,274.16733620799005,0.043636829874184734
0.0449741615778532,262.439837794332,0.14279296300968392,52.90787129933733,274.24284946375985,0.04399215934826768
0.0453527387500644,262.499353789126,0.14399494553145448,52.91986972388781,274.404418403585,0.0443543775030368
0.0457298922909706,262.55357299686,0.14519240802383165,52.93080031616698,274.5601196106159,0.0447151031285067
0.0461183183004652,262.655473775393,0.146425660603977,52.95134351311923,274.76870251832605,0.04508647425571578
0.0465066151648345,262.67656770361,0.14765850314834952,52.95559604904777,274.8927657506214,0.04545758411168294
0.0468886406674119,262.683544498197,0.14887143411903278,52.95700257083652,275.00041882541507,0.04582256583766497
0.0472721493980844,262.793758030811,0.15008907433891797,52.9792216190115,275.2165838213275,0.04618883067919875
0.0476501159459067,262.82708524506,0.15128911812825377,52.9859403854041,275.3508263307118,0.046549671325342115
0.0480352901773007,262.87005866917,0.15251204631292972,52.99460382770468,275.49709821626766,0.0469172591652018
0.0484175673134842,262.933751188814,0.15372577622031233,53.00744423966491,275.6643637859853,0.04728194863489762
0.0488001732647958,263.004305096021,0.15494055011572666,53.021667907357845,275.83896075409405,0.04764681867023393
0.0491893416029382,263.132153353804,0.15617615958932876,53.04744211612689,276.07545073184093,0.04801781036475669
0.0495791901074456,263.197423905823,0.15741392859113978,53.060600659413915,276.24653902143973,0.04838931251289832
0.0499626654556993,263.27565819836,0.15863146282184526,53.076372692789384,276.4296118315537,0.04875460682841941
0.0503522342845799,263.356871122666,0.15986834385354115,53.09274521832947,276.6174779978884,0.049125569138305694
0.0507462044045622,263.3712682628,0.16111919898448498,53.095647681780484,276.73636047635284,0.04950058262396149
0.051140041053497,263.444351629272,0.16236963034485297,53.110381288461234,276.9169065869049,0.04987532854981256
0.0515345118506885,263.440831534021,0.16362207512593596,53.109671637258636,277.0171261886662,0.050250537163313375
0.0519215691661781,263.472055975329,0.16485098210261545,53.11596648462633,277.1519385530072,0.050618557511683135
0.0523073072483031,263.590034846319,0.16607570051336232,53.13975102501791,277.3777197866163,0.05098518881379053
0.0526977075213785,263.653457956938,0.16731522138037672,53.1525371241187,277.5473907713528,0.05135611455963186
0.053086530046602,263.7141116927,0.16854973289796135,53.16476491724832,277.71377880678745,0.05172540455877365
0.0534741348678947,263.631067262579,0.16978037820556566,53.14802316013593,277.72851050874516,0.05209340234029747
0.0538481358843681,263.591925354741,0.1709678314328687,53.14013215151579,277.78585916926534,0.05244835613696256
0.0542330165216588,263.624736741016,0.17218982745626668,53.146746926988826,277.92190144420954,0.0528135039787598
0.0546136531281481,263.699943193575,0.1733983486818702,53.16190854782472,278.10156042106127,0.05317449429266049
0.0550062735317452,263.7909511806,0.174644918463291,53.18025575800896,278.3011083964393,0.05354671338593742
0.0553924856068807,263.800695775382,0.1758711418018462,53.18222026831702,278.41327201920495,0.05391272201608329
0.0557835494909489,263.893876497606,0.17711276963376274,53.20100550191737,278.6148136175686,0.05428319220145833
0.0561774908594354,263.978921111399,0.1783635334787074,53.218150496058044,278.8085945392183,0.05465624962584152
0.0565714186245073,264.01832085449,0.17961425413281065,53.226093484265185,278.9542118080888,0.05502915505522629
0.0569680153816653,264.118110876544,0.18087344883678733,53.24621115271127,279.16439547953536,0.05540444662105368
0.0573714648453527,264.087352629844,0.18215440088399482,53.24001029017655,279.23843089734936,0.05578607830542313
0.0577784609688934,264.178389637901,0.18344661357623654,53.25836335100084,279.44221041241957,0.05617091734079982
0.0581927729451094,264.273911159063,0.18476205410072233,53.27762048966711,279.65274286645837,0.056562521890871555
0.0586089035552046,264.371683833623,0.1860832687877746,53.2973314608584,279.8662183541549,0.05695569109521918
0.0590085021974923,264.525324954534,0.18735199447703804,53.32830551083406,280.13456817340597,0.05733309510214229
0.059413633134649,264.5021477477,0.18863828520251058,53.32363298593632,280.2171813173086,0.0577155787774579
0.0598233271673765,264.447113604832,0.18993906375642036,53.31253810273414,280.2672198004822,0.058102221748966724
0.0602310698875448,264.381519617115,0.19123364689295472,53.29931435481038,280.3055014021487,0.058486874827455765
0.0606403128688028,264.349072623513,0.1925329933584489,53.29277304090022,280.37928309398075,0.05887279449204705
0.0610415884986756,264.409388106002,0.19380704348329503,53.30493264217,280.5493571699552,0.059251056317628704
0.0614453589391034,264.464091160312,0.1950890146316533,53.31596077791891,280.71418216816113,0.05963152550806188
0.0618515948770245,264.505092681691,0.19637881373455277,53.324226684628904,280.86515451714877,0.060014171884629874
0.0622641542302614,264.489122815794,0.19768868968107994,53.32100715966408,280.9573143510232,0.06040262468772979
0.0626775863747746,264.418962306543,0.19900133673990933,53.30686280099907,280.9921046556396,0.060791747967516546
0.0630794636802147,264.419636057429,0.20027729718468168,53.30699862917769,281.0990848864492,0.06116985073350998
0.0634927537913371,264.383900727416,0.2015894932874953,53.299794386647065,281.1703626426951,0.061558542086599305
0.0638967606634108,264.449925306621,0.20287221510632927,53.3131049418148,281.3474188913951,0.061938356760109364
0.0643085648202184,264.478448178042,0.20417969330419342,53.31885515269327,281.4866776062504,0.06232535340654759
0.0647176651979375,264.546761230147,0.20547858700345153,53.332627063997634,281.6676099526384,0.06270966091482166
0.0651207835612771,264.659485955939,0.20675848780705477,53.3553523687173,281.8943190583145,0.06308820452538338
0.0655356898060966,264.73256214195,0.2080758151343567,53.37008452781712,282.081993216058,0.06347766782484084
0.0659514351276531,264.772783559732,0.20939580653029857,53.37819316564197,282.2349286182398,0.06386776666425249
0.0663837073055005,264.837501704365,0.21076827069496407,53.391240343599996,282.41839690102756,0.0642732115450002
0.0668107401883912,264.839817513408,0.21212410009814203,53.39170721070305,282.53396175283723,0.06467358094320183
0.0672426416121907,264.893915834294,0.21349538711870547,53.40261343219367,282.7060824819892,0.06507835191414345
0.0676707720070961,264.896062650547,0.21485470112253013,53.40304623035028,282.8217837117496,0.06547942710334163
0.0680965841455639,264.85963872058,0.21620665466216535,53.39570316606893,282.8956753954796,0.06587817104226637
0.0685255996169342,264.867378124263,0.2175687787837661,53.39726342985142,283.0175740291934,0.06627975395233474
0.0689666377058988,264.846140681297,0.21896907471622867,53.39298196134948,283.1116885134695,0.06669242267460888
0.0693994240868344,264.867629566386,0.2203431714756992,53.39731412058342,283.2492905175381,0.06709720499376141
0.0698315493014779,264.907767873476,0.22171516903219232,53.40540600329277,283.4066877260771,0.06750120552095702
0.0702612336599423,264.902861996405,0.2230794168703168,53.404416978475254,283.5152638803219,0.06790276228303703
0.0706717721645261,264.888704913585,0.22438287662237033,53.40156291057874,283.60885911619425,0.06828627592732077
0.0711003429129793,264.867606781019,0.22574358874870926,53.39730952705343,283.6997844496896,0.0686864779386891
0.0715234846220569,264.909913319773,0.22708706367503065,53.40583852526623,283.85719343133024,0.06908145321072784
0.0719557284291886,264.894749791353,0.22845943776267377,53.40278155793676,283.95544446965744,0.06948476368871967
0.0723868934619289,264.915359416341,0.22982838674162426,53.40693645833435,284.0917593148403,0.06988690561711243
0.0728117949634717,264.878124157217,0.23117744900902265,53.399429830094945,284.16437582366126,0.07028304748442935
0.0732431351220445,264.880457476508,0.23254695401249129,53.39990022726402,284.2811326146488,0.07068503175643857
0.0736797964770324,264.911025173287,0.2339333538145779,53.40606267493466,284.4296155925768,0.07109181055094696
0.0741322187947143,264.947327570794,0.23536979467321786,53.41338123827208,284.5884608273469,0.07151309725681913
0.0745783770747111,264.996627154653,0.23678634721220773,53.42332003437805,284.75964553811934,0.07192837727383627
0.0750159543903094,264.97615466703,0.23817565518923234,53.41919278087325,284.85359380005156,0.07233550276280638
0.0754575453068713,264.958775462362,0.23957770634931636,53.415689133212176,284.95191426626633,0.07274619456889546
0.0758901345911253,264.878066682032,0.2409511773268228,53.39941824309766,284.9796988127685,0.07314835112789923
0.0763366327056061,264.849481816144,0.24236880884029935,53.39365553413463,285.0671994318131,0.07356326848481619
0.0767888228297522,264.849418089548,0.24380451248446322,53.393642686852886,285.1868931317893,0.07398329986722521
0.07723518074579,264.902373173895,0.24522169886788323,53.404318431857234,285.3621558459695,0.07439774085923447
0.0777027585517163,264.957306270664,0.2467062584016992,53.41539294416586,285.54521986632653,0.07483170028306503
0.0781623965441961,265.002305939113,0.24816560902782261,53.424464877325185,285.7155212610523,0.07525810728570864
0.078630327542109,264.999974052765,0.24965128994619604,53.42399476903743,285.8370088111843,0.07569202103182728
0.0790926041506886,264.917016150354,0.2511190181784363,53.407270455911366,285.8699928415155,0.07612050664400893
0.0795422879213623,264.814168149281,0.2525467641503253,53.386536298895045,285.8780929578671,0.07653714382413628
0.0799978875765131,264.701289893885,0.2539932930554291,53.363780042607225,285.87683392417404,0.07695908518654235
0.0804445982573638,264.673699899827,0.25541159946713005,53.358217899805126,285.96526935755867,0.07737262147843253
0.0808943357150821,264.652468865737,0.2568395158953857,53.35393772333258,286.0613545299872,0.07778878708498342
0.0813494431883695,264.675482701327,0.25828448212307314,53.35857731258752,286.20668584469286,0.07820974561375643
0.0818074009206819,264.686065331543,0.259738497923165,53.36071077083907,286.33934439623835,0.0786331617339528
0.0822813594722782,264.713041380402,0.2612433163244833,53.36614914228904,286.4939902952229,0.0790711831015127
0.0827594794212493,264.729826653832,0.2627613471624665,53.36953305341253,286.6387292949807,0.07951285602347752
0.0832315102015456,264.713519920365,0.26426004488990723,53.36624561594558,286.74602595410386,0.079948712672956
0.0837038955515716,264.693751810816,0.26575986837623977,53.362260365060514,286.8496499655422,0.08038470661745013
0.0841784113090387,264.675819726363,0.26726645590619785,53.358645256834784,286.95580974284576,0.08082247555310079
0.0846530928338916,264.658650707658,0.2687735697476058,53.35518398266386,287.0628240353059,0.08126020576084214
0.0851346153548008,264.608837752299,0.2703024037514925,53.34514169086348,287.1362093738218,0.08170404874787426
0.085620406921866,264.576658120659,0.2718447919769245,53.33865427712485,287.22981925097724,0.08215162718965122
0.0861080861049656,264.527997456149,0.2733931733832658,53.32884428715965,287.30599703827727,0.08260074335943288
0.086601735380971,264.487607848656,0.2749605098345829,53.32070174228906,287.39269367511133,0.08305515220834396
0.0870921324743323,264.439560200295,0.27651752060600504,53.31101533637947,287.4701654087132,0.08350636303332118
0.0875818044094275,264.387345396329,0.27807222899993234,53.30048883189993,287.542866169158,0.08395670359708633
0.0880652206608921,264.325632762957,0.2796070755983324,53.28804756501214,287.60352793855674,0.0844010920974723
0.0885476398118059,264.225546767322,0.2811387564024837,53.26787022829211,287.6220953115523,0.08484436721320272
0.0890264071570276,264.124023781839,0.2826588427235626,53.24740319441875,287.6380366629935,0.0852840926531736
0.0894925585738419,264.044108080327,0.28413887347194805,53.23129218899393,287.67409088878355,0.08571204524964987
0.0899668738857623,264.01372294993,0.2856448245872953,53.2251665467059,287.766212266677,0.08614730484874544
0.090455771044073,263.971015958731,0.28719707306493175,53.21655681728017,287.84871774056535,0.0865957474180249
0.0909497199735601,263.944072064483,0.2887653609160533,53.21112492819978,287.9497115074289,0.08704861960521167
0.0914410047847426,263.907523185039,0.2903251901915577,53.203756674103865,288.03949227533167,0.08749884587671088
0.0919391228900296,263.88764371535,0.291906715175844,53.199748973014565,288.14924222005595,0.08795512749951721
0.0924348842048266,263.861112587409,0.2934807573503244,53.19440029762166,288.2510839755829,0.08840904365279396
0.0929428814304166,263.802124624223,0.29509364854157266,53.18250832424336,288.3206542142641,0.08887394930226827
0.093449972947221,263.729616466251,0.29670366410742666,53.167890679596205,288.3751419904031,0.08933781061143926
0.093953745083603,263.65725793272,0.2983031406404395,53.15330319923635,288.4288447339725,0.08979842256078936
0.0944629489258838,263.581016170995,0.2999198628396811,53.13793286007259,288.4796562393882,0.09026378535286102
0.09497722806908,263.475118316163,0.30155269911932897,53.11658385253846,288.499254719005,0.09073356676827317
0.0954943418267186,263.404643110592,0.30319453529983154,53.102376051095355,288.55829613853973,0.09120571511692283
0.0960205149933892,263.330391832617,0.3048651351040107,53.08740699345559,288.61551166979586,0.09168590641030483
0.0965399336099965,263.273104505038,0.3065142892117389,53.075857868215664,288.6894725352521,0.09215970737360789
0.0970546223976825,263.208366063004,0.3081484261126419,53.062806598301606,288.75395464315983,0.09262897257644244
0.0975691233580842,263.106511374845,0.3097819666619173,53.042272693168755,288.77758303949247,0.09309784654249016
0.0980894229494487,263.00870605753,0.3114339178644996,53.02255514119805,288.8070782653943,0.09357178143731099
0.0986073371010219,262.906799657452,0.31307829529574455,53.00201081094232,288.8313390774252,0.09404332049594535
0.0991293631790549,262.787545105051,0.31473572809349926,52.97796909317828,288.83750710270186,0.09451837839326674
0.0996474396809143,262.70651318821,0.3163806209869029,52.96163305874314,288.8845446149155,0.09498961904922874
0.100170898636665,262.600369182121,0.31804260317141136,52.940234427115605,288.90528414541404,0.09546553013380568
0.100697973868487,262.507353547523,0.3197160670324462,52.92148247518064,288.94131217533715,0.09594450027917246
0.101230682092598,262.467929113722,0.32140741564399866,52.913534509326354,289.03773660533574,0.09642835631425511
0.101747836201371,262.389927682291,0.3230493799393529,52.897809420749866,289.08753506499835,0.09689786077285813
0.102278579260879,262.26443192319,0.3247344891532908,52.872509475715106,289.08846541095534,0.09737947303126236
0.102799276762588,262.165931156138,0.3263877037212169,52.85265172107743,289.1163992707794,0.09785174434809121
0.103333009095303,262.058266136206,0.328082303877587,52.83094645305913,289.1375353343579,0.09833560684949215
0.103867872617153,262.028827913416,0.32978049555946076,52.82501170734468,289.2452048331486,0.09882026009220407
0.104404565606015,261.965066061378,0.3314844957990976,52.812157317973806,289.31541498746725,0.09930633508018064
0.104950857279675,261.892849956079,0.3332189718629681,52.79759855114552,289.37872907438674,0.09980086093069276
0.105498377958372,261.819263847079,0.33495735001783106,52.78276359157113,289.44077150120086,0.10029625406722469
0.106047051208914,261.727276498651,0.3366993875883019,52.764218942128046,289.48268239227303,0.10079244397547876
0.106599186939113,261.628297191636,0.33845241853168373,52.74426471383383,289.517660952529,0.10129151674376846
0.107151358502028,261.51513798494,0.3402055632439389,52.7214518177639,289.53684028887164,0.10179037292745476
0.107712181662338,261.394881553461,0.3419861767779231,52.69720812117774,289.5502945209527,0.10229679073796609
0.108269776907876,261.272641330548,0.34375654168250624,52.67256449223848,289.56057191953795,0.10280003965219973
0.108838551733468,261.204404964512,0.3455624017537609,52.658808040845614,289.63351410725176,0.1033131177284686
0.109407191061272,261.090268380488,0.3473678316195386,52.63579810550638,289.6554212574308,0.10382581055531769
0.109971303703447,260.963985022395,0.3491588892584442,52.61033938051482,289.6625346749546,0.1043341624706436
0.110533723535871,260.803830010461,0.3509445722263904,52.578052130108944,289.6314484539336,0.10484073177587064
0.111085516790452,260.613362491568,0.3526965158096851,52.539653878300115,289.56373254644126,0.10533748050392606
0.111641908139886,260.489786655587,0.35446305834413805,52.514740989766345,289.57136348876855,0.10583811891312958
0.112205863468217,260.405389117895,0.35625361651158893,52.49772644616763,289.6244006556455,0.1063453077123094
0.112779497716671,260.315447366409,0.35807490525043045,52.47959418906806,289.6736927682831,0.10686093740693173
0.11334561098679,260.245986243551,0.3598723148830582,52.46559082669988,289.74372656118607,0.10736954609213945
0.11391429765794,260.099006433574,0.3616778950639595,52.43595969700852,289.7280020729826,0.10788020646123314
0.114480871607387,259.913809767049,0.3634767673534537,52.398624049037075,289.66896925197733,0.10838871049092236
0.115047942680166,259.723638678391,0.365277218009527,52.36028555756363,289.6043089737467,0.10889740190712947
0.115620395667317,259.512306360437,0.36709475624373145,52.31768096226409,289.5172219023687,0.10941065884441303
0.116191674664054,259.399438419081,0.36890856705837144,52.29492678528673,289.53949357590915,0.10992260070260836
0.116747761629377,259.232943972993,0.37067414317327196,52.26136150495539,289.49780992243365,0.11042067688665586
0.117316646230482,259.065526963582,0.37248035178178035,52.22761023585813,289.4582257408819,0.11092995908228047
0.117883773498935,258.914505262409,0.3742809808591186,52.197164260901666,289.4363241563517,0.1114374100254864
0.118466303495952,258.755625128807,0.37613051359964755,52.165134025967504,289.4094475466011,0.11195837498189869
0.119045915636782,258.658078134892,0.37797078214678287,52.14546855199423,289.4502658833105,0.11247646122861354
0.119633076876232,258.504935363199,0.37983501908203654,52.114594969220924,289.43067616839,0.11300102169921016
0.12022830738609,258.263011130155,0.3817248759508357,52.065823043839245,289.31353581876846,0.11353251041369217
0.120821474607466,257.951412895616,0.38360818187870455,52.00300483975619,289.1174829787436,0.11406187592800958
0.121406476166987,257.631341826797,0.3854655618301837,51.93847851228227,288.9094551881609,0.11458367976387078
0.121986140736108,257.312617173232,0.3873059968371429,51.87422362212357,288.7011903049022,0.11510045473910577
0.122562427383015,257.064634142403,0.3891357069410726,51.82423024310845,288.5710996972226,0.11561395368295167
0.123151513652688,256.843282797469,0.3910060558472844,51.77960581196975,288.4739218455027,0.11613858531338347
0.123748956768784,256.591501050589,0.3929029377408892,51.728846611798744,288.34443162133573,0.11667037845512765
0.124360351487391,256.341884401794,0.3948441159724664,51.67852389540167,288.22065124694126,0.11721429749984226
0.124956255264477,255.946377609541,0.39673611046471446,51.59878972608347,287.928478504137,0.11774415069101918
0.125554573022428,255.563389447928,0.3986357693462089,51.52157931270228,287.65054169022704,0.11827586799228887
0.126144915742073,255.202027607956,0.4005101074810818,51.44872876576394,287.39446587776786,0.11880022102973184
0.126761988707708,254.806947328814,0.40246931414697285,51.36908058148891,287.1067827087547,0.119348022609857
0.127369746642037,254.381687145051,0.4043989455884675,51.28334812844228,286.78221818709005,0.11988726167874089
0.127963487068422,253.817679629094,0.4062840714422398,51.16964421322535,286.29707499404844,0.12041378293176651
0.128563756332213,253.284295899397,0.4081899263547763,51.06211405331844,285.8474764001832,0.12094581220790808
0.129166055780329,252.786649357814,0.41010222710254457,50.96178851053531,285.43810380928784,0.12147935653121247
0.129769059272323,252.299461315795,0.4120167631896255,50.863571401264274,285.0401250656596,0.12201323951200185
0.130352485887249,251.562415150473,0.4138691426920155,50.71498289433536,284.3542013211373,0.12252951849631967
0.130942467717062,250.967615816009,0.41574233500167185,50.59507134850741,283.8299347480248,0.1230513273317922
0.13156005580681,250.342144447623,0.4177031771866217,50.468976320640806,283.2771709419488,0.12359726095941528
0.132200807680709,249.791995269498,0.41973756438625104,50.35806624633079,282.81469879630146,0.12416335599299004
0.132807973381519,249.014491723204,0.4216653154863228,50.20132153139792,282.0856017115918,0.12469948258148694
0.133393677922943,248.036452627537,0.423524927405344,50.004148849711456,281.12294730248396,0.12521638676265545
0.133975422489883,247.266070650309,0.4253719664053785,49.8488398431023,280.3936469330974,0.12572953178134644
0.134599386924036,246.493303059244,0.4273530534838143,49.69304989674359,279.6711505318989,0.12627962556471933
0.135256649594355,245.769535346505,0.42943986246207705,49.54713832585541,279.01149926983464,0.12685874836203706
0.13591119628349,244.771743887915,0.4315180482000807,49.345983567803664,278.03896441611755,0.12743514495768704
0.136524404216194,243.702532993074,0.4334649833864159,49.130430651403714,276.97387611593075,0.12797483721339106
0.137144125027614,242.675841657344,0.43543259696267445,48.923449678120555,275.95740762678025,0.12851996577438915
0.137768778299527,241.678743475456,0.43741587110099817,48.72243468465194,274.97452870503434,0.1290691325461791
0.138424122180568,240.656494010968,0.4394965879233033,48.51634919261115,273.96915794148936,0.12964495711624147
0.139083644570929,239.492693354317,0.4415905715126996,48.2817269802303,272.8022099941433,0.13022411861761965
0.139746292823192,238.248855479441,0.4436944797136346,48.030969264655305,271.5432498020613,0.13080568748334884
0.140406057020783,237.02121159219,0.44578923104098594,47.78347625698551,270.3004253421381,0.13138438935478194
0.141070409895297,235.756662117176,0.44789855141756796,47.52854308282268,269.0149510775931,0.13196677791142553
0.141730615288414,234.441177865675,0.4499947035407144,47.26334145772008,267.6686702535176,0.13254519486869895
0.142410136739298,233.140357517899,0.45215218414727115,47.00109607560844,266.34190771147183,0.13314018575998057
0.143090769586495,231.718182332748,0.4543131934371216,46.714385558282004,264.8749153699247,0.13373579512109196
0.143764977861824,230.342529892698,0.45645380471129116,46.43705402636792,263.4577186033583,0.13432543292016608
0.144409555974299,228.839382155487,0.4585003402183993,46.134019442546176,261.8859757219938,0.13488883236369065
0.145047389627106,227.371754854083,0.46052546206606154,45.83814577858314,260.351434370602,0.1354460244703467
0.145689691588017,225.817655318282,0.46256477079195396,45.52483931216565,258.7169598767316,0.13600680639771015
0.146375034490222,224.277240293309,0.4647407345064548,45.2142916431311,257.10582907661393,0.13660481998330545
0.147029665219933,222.697661976581,0.46681918707328723,44.89584865447873,255.4408246622595,0.13717570112571592
0.147690451764697,220.916036922532,0.46891718435291296,44.536673043582454,253.54322621768725,0.1377516202176675
0.148336947916473,219.377156185809,0.4709698096348018,44.226434687059104,251.91889397700731,0.13831476347018343
0.148945666969696,217.45569038535,0.47290249262878475,43.83906718168656,249.8447732261517,0.13884471051590166
0.149610550250952,215.806945801336,0.47501349704677254,43.506680273549335,248.09394171065125,0.13942323306394178
0.150255480934535,213.798011194015,0.4770611519671486,43.10167905671343,245.9223341888188,0.13998407503625043
0.150943636688853,211.844992509124,0.4792460464871082,42.707950489839405,243.82164609277402,0.14058215954754807
0.151629325719653,209.848474399827,0.4814231091598983,42.30545243900513,241.66765707637066,0.14117774462759858
0.152320520148429,207.670029237679,0.48361765147126207,41.866277894316084,239.30243611040171,0.14177775287061822
0.153017420478722,205.478175996721,0.4858303100199423,41.424400280938954,236.9199164524121,0.14238235000081775
0.153742816348839,203.198983433405,0.48813344190756375,40.964915060174455,234.43936742567777,0.14301128046567238
0.15445069657254,200.782218141714,0.4903809616178145,40.47769517736954,231.7931715930814,0.14362464346312576
0.155142678540473,198.233971577933,0.49257800436600174,39.96396867011129,228.98852090624953,0.14422386754827876
0.155863344191035,195.509303076222,0.4948661178065361,39.41467550016636,225.9820368741406,0.14484754889469995
0.156390922702745,193.461702124915,0.4965411795812153,39.00187914838286,223.71735622787406,0.14530388151211038
0.156755200502144,192.136194279914,0.4976977615943072,38.73465676683066,222.2545419379808,0.14561884458232557