File: example/data/02 processed data/test_ID_103.csv
Strain,Stress_MPa,Displacement(mm),Force(kN),True Stress (MPa),True Strain
-7.88091918716955e-06,0.639597558328552,-2.502191841926332e-05,0.1289428677590361,0.6395925177118825,-7.88095024173774e-06
-1.71721822207486e-05,1.70613062128685,-5.45216785508768e-05,0.343955933251429,1.7061013233009288,-1.71723296643573e-05
-1.23462798277535e-05,3.10406705493072,-3.919943845311736e-05,0.6257799182740332,3.104028731250256,-1.2346356043653084e-05
-3.9067867093054e-06,4.5403389147142,-1.2404047802044644e-05,0.9153323252063826,4.540321176578472,-3.906794340762336e-06
9.1876266112911e-06,6.9192568927562,2.9170714490849244e-05,1.3949221895796502,6.919320464304959,9.187584405301612e-06
2.8905444936838e-05,10.0002657553785,9.177478767446064e-05,2.016053576284306,10.000554817509647,2.8905027182620865e-05
6.0841925096784e-05,13.6635626971047,0.0001931731121822892,2.7545742397363076,13.664394014562872,6.0840074301845106e-05
0.000104694311106,17.6486461764449,0.00033240443776154995,3.5579670691712915,17.650493889298296,0.00010468883103914166
0.000163385828435,21.6996773079528,0.000518750005281125,4.374654945283285,21.70322272770653,0.000163372482424105
0.0002265881631519,25.7490867666357,0.0007194174180072825,5.191015892153757,25.75492120490899,0.0002265624959311429
0.0002964869684148,29.9205011226317,0.00094134612471699,6.031973026322551,29.929372161303,0.0002964430248391414
0.0003693582628848,34.2008841301523,0.0011727124846592398,6.894898240638704,34.21351650930374,0.0003692900669135554
0.0004474830145292,38.3486338332981,0.0014207585711302098,7.731084580792898,38.3657941955689,0.0004473829238631158
0.0005247278944391,42.5301794569664,0.0016660110648441427,8.574084178524426,42.55249622848297,0.000524590272898005
0.0006121734078807,46.6751433431488,0.0019436505700212222,9.409708897978797,46.7037166247125,0.00061198610617697
0.0006893837065154,50.8330550718029,0.002188793268186395,10.247943902475466,50.8680985517218,0.0006891461907213953
0.000766682289686,54.9497637411968,0.0024342162697530497,11.077872370225275,54.9918927518796,0.0007663885389519807
0.0008418607106404,59.0581542883651,0.00267290775628327,11.906123904534404,59.10787302810342,0.0008415065446706855
0.0009174098993067,63.0826502289084,0.002912776430298772,12.717462286147935,63.1405228767029,0.0009169893360447144
0.0009936403574131,67.0897381743863,0.0031548081347865923,13.52529121595628,67.15640124580464,0.0009931470236037199
0.0010642878025072,70.9955314309131,0.0033791137729603598,14.312699136472082,71.07109110904753,0.0010637218497659693
0.0011355134440166,74.8417389246548,0.003605255184752705,15.08809456721041,74.92672272537733,0.0011348692362506856
0.0012115317321121,78.5987487252477,0.0038466132494559173,15.845507743009938,78.69397360343265,0.0012107984197709228
0.0012810424477833,82.3281950234837,0.004067309771711977,16.597364116734315,82.43366093595817,0.0012802226129942807
0.0013534453366481,86.0571253797814,0.004297188943857717,17.34911647656393,86.17359899481201,0.0013525302550907012
0.0014267363261354,89.773604578602,0.004529887835479895,18.098358683046165,89.9016878413824,0.001425719504905456
0.0014975119675236,93.4842574316353,0.00475460049688743,18.84642629821768,93.62425122591422,0.0014963918146325928
0.0015671758022936,97.2234516135741,0.004975783172282179,19.600247845296536,97.37581785435836,0.0015659490638053988
0.0016357631479582,100.967782902538,0.005193547994767285,20.355105033151663,101.13294228094102,0.0016344267445812161
0.0017038384696938,104.715708737425,0.005409687141277815,21.110686881464883,104.89412739035309,0.0017023885836093345
0.0017778898407856,108.449067407334,0.005644800244494279,21.863331989318535,108.64187790252018,0.001776311265387821
0.0018459761583467,112.157243541636,0.005860974302750772,22.61090029799382,112.36428313919976,0.001844274438259403
0.001915168528309,115.911472351253,0.0060806600773810745,23.367752826012605,116.13346235517007,0.0019133369312349326
0.0019822562535323,119.608564116687,0.006293663604965053,24.1130865259241,119.84565894088333,0.0019802941760706707
0.0020540344181626,123.283530531263,0.006521559277666255,24.85395975510262,123.5367591461668,0.0020519277737205974
0.0021214932641574,126.933909620583,0.006735741113699744,25.589876179509535,127.20319905483622,0.0021192460750255548
0.002191290077911,130.511957905803,0.006957345997367424,26.31121071380989,130.79794746421072,0.0021888927033981717
0.0022586694299061,134.121287944406,0.007171275439951867,27.03885164959225,134.42422359738566,0.00225612247054775
0.0023276836909025,137.710396202189,0.007390395718615436,27.762415874361306,138.03094244549655,0.00232497883177789
0.0023946951089781,141.240787719653,0.007603156971005467,28.474142804282046,141.5790163431935,0.0023918323959514092
0.0024658717869624,144.745902077684,0.00782914292360562,29.180773858861098,145.10282691389577,0.0024628365138330624
0.0025327645923609,148.233766460404,0.008041527580745857,29.88392731841745,148.6092076954872,0.0025295625496614335
0.0026026678908469,151.737831510864,0.008263470553438908,30.590346832590182,152.13275469276405,0.0025992868160444123
0.0026713651736991,155.280340847953,0.008481584426494642,31.304516714947326,155.69515134265436,0.0026678034195075236
0.0027395412224951,158.730172014766,0.008698043381421942,32.00000267817683,159.1650198642542,0.002735795518887019
0.0028121129559843,162.191640470732,0.008928458635250151,32.69783471889958,162.6477416842521,0.0028081663634571554
0.0028782652002709,165.573410312526,0.009138492010860108,33.37959951900524,166.0499744975187,0.0028741309261143375
0.0029481607741557,168.959753451251,0.009360410457944347,34.0622862957722,169.457873968787,0.0029438234708012603
0.0030166479214894,172.355494949966,0.009577857150728845,34.746867781913146,172.87543079556409,0.003012106969159246
0.0030800427564382,175.640658408662,0.009779135751691285,35.409156735186265,176.18163914632964,0.003075309142079774
0.0031445697245104,178.94031321106,0.009984008875320518,36.0743671433497,179.50300350247792,0.003139635905586886
0.0032100735605624,182.246223590095,0.010191983554785618,36.74083867576316,182.83124737395394,0.0032049322740972845
0.0032721951779993,185.456408751813,0.010389219690147777,37.3880120043655,186.06325831825976,0.0032668531975208422
0.0033397732187498,188.728210680628,0.010603779969530614,38.0476072732146,189.35852010428175,0.00333420856252465
0.003400435979135,192.019204057596,0.010796384233753623,38.71107153801135,192.67215306775833,0.0033946675697500194
0.0034682488867883,195.232189028507,0.011011690215552853,39.358809308147016,195.9093028507704,0.0034622483817786554
0.0035325515238323,198.536942565061,0.011215851088167552,40.02504762111629,199.2382845440562,0.0035263267190197567
0.0035978520188735,201.763879606905,0.01142318015992336,40.67559812875205,202.48979618848446,0.0035913952317073792
0.0036625118427697,204.999039348039,0.011628475100793798,41.32780633256466,205.74985075740761,0.003655821177720902
0.0037251294091765,208.255043438053,0.011827285874135387,41.98421675711149,209.03082042497343,0.0037182082973187323
0.00378913025223,211.424432553016,0.012030488550830248,42.623165602688026,212.2255472664632,0.0037819695809730228
0.0038566526423602,214.609381419507,0.012244872139493634,43.265251294172614,215.43705525743383,0.0038492348234087778
0.0039216017440939,217.749284800546,0.01245108553749813,43.89825581579007,218.60321077559504,0.003913932308416868
0.0039881532260958,220.832557772079,0.012662386492854165,44.519843646851136,221.7132718497847,0.003980221624320013
0.0040596988456949,223.895222915127,0.012889543835081306,45.1372769396896,224.80417009315212,0.004051480503490317
0.0041381055746566,226.917563062274,0.013138485199534703,45.74658071335444,227.85657189496948,0.004129567162910917
0.0042173229823355,229.834886085878,0.013390000468915213,46.334713034913,230.80417403311043,0.004208454999788388
0.0043002872338798,232.699384602214,0.013653411967568365,46.91219593580634,233.70005879515057,0.004291067421177671
0.0043866330603024,235.375077387751,0.01392755996646012,47.451615601370605,236.40758148379135,0.004377039829922363
0.0044785515932096,238.083460832987,0.01421940130844048,47.99762570393018,239.1497298958174,0.004468552723543578
0.0045807288844389,240.537999262055,0.014543814208093506,48.49246065123029,241.6398386230798,0.004570269275474393
0.0046871964704573,242.826356800888,0.014881848793701927,48.95379353105902,243.96453164341912,0.004676245770470052
0.0047975778314246,245.007205580759,0.015232309614773105,49.39345264508102,246.18264671879257,0.004786106131185321
0.0049317197192567,247.038401396496,0.015658210108640023,49.8029417215336,248.25672555207674,0.004919598625119398
0.0050813026907075,248.811847439425,0.01613313604299631,50.16046844378809,250.07613574929886,0.005068436438665141
0.0052438334166863,250.342379280907,0.016649171097979,50.46902366303086,251.65513301499297,0.005230132398600803
0.0054215999543705,251.556853799729,0.017213579855126337,50.71386172602537,252.9206944268112,0.005406955986649907
0.0056153121900976,252.507117378902,0.01782861620355988,50.90543486358664,253.92502367320617,0.0055996050973215975
0.0058296420832841,253.319207247673,0.018509113614427017,51.069152181130875,254.79596755874823,0.005812715472072146
0.0060609907278312,253.851059730338,0.01924364556086406,51.17637364163614,255.38964864961372,0.006042696805842309
0.0063012194202081,254.259280832546,0.020006371659160718,51.25867101584127,255.8614243506962,0.00628144974237286
0.0065514634086839,254.63193918573,0.02080089632257138,51.33379893984318,256.3001510179875,0.006530095847375744
0.0068151161300011,254.974940560778,0.02163799371275349,51.40294801705285,256.7126243909399,0.0067919982008804
0.0070893133240045,255.105925022644,0.022508569803714285,51.42935448456503,256.9144508559395,0.0070643022801478265
0.0073683943759633,255.350864634645,0.023394652143683477,51.478734310344436,257.2323905095163,0.007341380376826221
0.0076492600727591,255.441346761238,0.02428640073101014,51.496975507065585,257.3952840559506,0.007620152821320399
0.0079341955425934,255.523379429802,0.025191070847734046,51.513513293048085,257.5507518879023,0.007902885318393126
0.0082273825385459,255.62051013764,0.026121939559883234,51.53309484374822,257.7235978592406,0.008193722125528657
0.0085236249141778,255.715707912127,0.027062509102514513,51.552286715084804,257.8953326910334,0.008487503932670731
0.008823082485888,255.71722530915,0.028013286892694396,51.55259262232464,257.973439481115,0.00878438653873061
0.0091252944152137,255.812355629494,0.028972809768303492,51.57177089490599,258.14671868966246,0.009083910485967722
0.0094319115509855,255.837460917962,0.029946319174378958,51.576832121061145,258.2504972207689,0.009387708800153643
0.0097431536602837,255.868368610305,0.030934512871400748,51.58306311183749,258.3613334424813,0.009695995205949368
0.0100512752792239,256.007204812844,0.03191279901153588,51.61105249026935,258.5804037018826,0.010001097167728902
0.0103555934829084,255.962367737977,0.03287900930823417,51.60201333597616,258.61300996519424,0.010302341645453735
0.0106653163832631,255.937190341734,0.03386237951686034,51.59693757289358,258.666841450972,0.010608843078731616
0.0109738971687877,256.008281775832,0.03484212351090095,51.61126960600774,258.817690334398,0.010914120880876007
0.0112809265512845,255.988041020106,0.03581694180032829,51.60718906965337,258.875823308861,0.011217771421109347
0.0115911679227311,255.897079475526,0.03680195815467124,51.588851222266044,258.8632254946633,0.01152450497557043
0.0119023656168588,255.8848362429,0.03779001083352669,51.586382986568644,258.9304711196731,0.011832089547918246
0.0122159812799858,255.844992216197,0.03878574056395491,51.578350430785314,258.9703898516882,0.012141968331554892
0.0125295479795875,255.904948780912,0.03978131483519031,51.590437674231865,259.1113221148763,0.012451702762452202
0.0128429124721808,255.945761781298,0.04077624709917404,51.59866557510967,259.2328507974808,0.012761141644645535
0.0131559107088325,255.934406389357,0.04177001650054318,51.59637632809438,259.3014565871335,0.013070123304023391
0.0134706917344134,256.023814342007,0.042769446256762544,51.61440097134861,259.47263222167686,0.013380768617504117
0.0137848172248333,256.225163550799,0.04376679468884573,51.654992971841075,259.7571805987498,0.013690670839050212
0.0141018258626586,256.442013612135,0.04477329711394105,51.69870994420641,260.05831423196287,0.014003320110140514
0.0144197708360059,256.539668519364,0.04578277240431873,51.71839717350378,260.23891174975813,0.01431679468834397
0.0147350311797164,256.598461096629,0.04678372399559957,51.73024975708041,260.3794474215551,0.014627525388568404
0.0150516122530816,256.769650735155,0.04778886890353408,51.76476158820725,260.6344479563797,0.01493946071138324
0.015375439475408,256.89318484376,0.0488170203344204,51.78966606450203,260.8430304589701,0.015258435209675568
0.0156966347368061,256.846774277598,0.04983681528935936,51.78030969436376,260.87840427676036,0.015574716712586088
0.0160175292061942,256.986650919174,0.050855655229666584,51.80850882530548,261.10294210587386,0.015890602163159073
0.016335470660748,257.00727024855,0.0518651193478749,51.812665682107685,261.2056049712941,0.016203482314558263
0.016656532405764,257.10196760887,0.052884490388300696,51.83175666994819,261.3843948639328,0.016519333776050363
0.0169803502054249,257.195781014366,0.05391261190222406,51.850669452496184,261.56305544734766,0.016837795547831286
0.0173004554781048,257.174508359095,0.05492894614298274,51.84638088519355,261.62374449106505,0.017152506549800814
0.0176122396793008,257.226014086929,0.05591886098178004,51.856764439924895,261.7563402987792,0.017458941518119282
0.0179245892806181,257.507161986459,0.05691057096596246,51.91344385647013,262.12287210188384,0.017765838056983167
0.0182388741429255,257.537908525291,0.05790842540378846,51.91964235869867,262.2351100259161,0.018074541037317465
0.0185520797233918,257.604809121968,0.05890285312176896,51.93312951898876,262.3839140779279,0.018382089126472524
0.0188610440983607,257.757483953395,0.05988381501229521,51.96390876500443,262.6190592249225,0.018685379974778996
0.0191744534364749,257.976549346695,0.0608788896608078,52.00807234829371,262.92310867984565,0.01899294021204052
0.0194846822415275,258.161854701004,0.061863866116849804,52.04542990772241,263.19205640673647,0.01929728614414668
0.0198007372601856,258.327461831463,0.06286734080108929,52.07881630522294,263.4425360302784,0.019607252584514612
0.0201196346827889,258.401082365057,0.06387984011785475,52.093658204795496,263.6000177438792,0.019919909323069005
0.0204343690551452,258.559132547471,0.064879121750086,52.12552112157016,263.8426252845242,0.020228388661793176
0.0207513455227888,258.763883137335,0.06588552203485444,52.16679884048673,264.1335818851363,0.02053896938742512
0.021069884316367,258.742782979781,0.06689688270446521,52.16254504872385,264.19446348485985,0.020850983770964032
0.0213888407184997,258.751165594748,0.06790956928123654,52.164234983901196,264.2855530613802,0.021163309695415678
0.0217098786544369,258.687678976852,0.06892886472783714,52.151436081733365,264.3037570968374,0.021477575409094018
0.0220248117500031,258.698355863152,0.06992877730625983,52.15358854201145,264.3961384510732,0.021785769128697154
0.0223399619424156,258.726306008586,0.07092937916716953,52.15922329133094,264.50624183831957,0.02209408024710854
0.0226608964929766,258.752219414932,0.0719483463652007,52.16444743405029,264.6157766764217,0.022407952539016857
0.0229757467465825,258.756307527761,0.07294799592039942,52.16527159759662,264.7014269185997,0.022715778718346017
0.0232931995694954,258.802225310456,0.07395590863314788,52.17452862258792,264.83055719364194,0.023026053500193374
0.0236091553107463,258.793321770875,0.0749590681116195,52.1727336690084,264.90321349794755,0.02333476949048664
0.0239335713587477,258.716262877861,0.07598908906402393,52.157198596176784,264.9082670171168,0.02365165279308199
0.0242563008131932,258.664566774222,0.0770137550818884,52.14677666168316,264.93881231561187,0.02396678906194199
0.0245813661792465,258.647667419438,0.07804583761910763,52.143369751758705,265.00558044368313,0.024284105923123956
0.0249012993341587,258.583077405304,0.07906162538595386,52.130348404909284,265.02213201852135,0.02459631462134275
0.0252246710335827,258.55347481354,0.08008833053162506,52.124380522409666,265.0754011603012,0.02491177982375444
0.0255477053280261,258.536833586413,0.08111396441648286,52.121025651020865,265.1418564273196,0.02522681653951946
0.0258680352423438,258.613951221722,0.08213101189444155,52.13657256629916,265.30378602608727,0.02553911785473896
0.026183004121269,258.809903628953,0.08313103808502907,52.17607657159692,265.58632440229513,0.025846097433079643
0.0265057450558972,258.896744422614,0.0841557405524736,52.19358367559899,265.7589955260816,0.02616055420341766
0.0268216496771958,258.946326210982,0.08515873772509666,52.20357936413398,265.89169385780986,0.02646825440222803
0.0271458681214282,259.061340634038,0.08618813128553453,52.226766271822065,266.09378562225,0.02678395408502804
0.0274732348968466,259.107697440579,0.08722752079748795,52.23611180402072,266.226224075945,0.027102618286784536
0.0277960669721699,259.176838376611,0.08825251263663943,52.25005061672478,266.38093513376253,0.027416768921628278
0.0281185851575988,259.069061540308,0.08927650787537618,52.228322806526094,266.35371700892836,0.02773051559174465
0.0284397037960287,258.922126030205,0.09029605955239112,52.198700607689325,266.285794600742,0.028042803011716456
0.0287596895784246,258.851744643025,0.09131201441149811,52.18451172003383,266.296240465792,0.028353891753048036
0.0290853765982496,258.819450106021,0.09234607069944246,52.178001141373834,266.34731128330645,0.028670423865107694
0.0294039476536324,258.679607026996,0.09335753380028287,52.149808776642395,266.28580865107995,0.028979943136519894
0.0297225075018403,258.671289515853,0.09436896131834295,52.148131966395965,266.35964885899864,0.029289355751711103
0.0300446493723695,258.708411591584,0.09539176175727315,52.15561577686334,266.4812151075358,0.029602150207220766
0.0303701706363902,258.744855177343,0.09642529177053888,52.16296280375235,266.602980580367,0.02991812664416731
0.030695815840964,258.793288051637,0.0974592152950607,52.17272687121002,266.7371591625476,0.030234123520948748
0.0310257628047594,258.838031740512,0.09850679690511109,52.18174719888722,266.8686791181439,0.030554192894068372
0.0313529008075496,258.846448090386,0.09954546006396997,52.18344393502181,266.96203510175036,0.030871436290061182
0.0316827941569463,258.98410443299,0.1005928714483045,52.21119545369079,267.18944450366155,0.03119124980857077
0.0320096400214036,259.005346628132,0.10163060706795643,52.21547788023141,267.2960145373173,0.03150800812175438
0.0323392687845013,258.977177981412,0.10267717839079163,52.209799081052665,267.3523105492045,0.03182736185550839
0.0326667842535158,259.041387713997,0.10371704000491266,52.22274376314179,267.50343683918146,0.03214456719374835
0.0329926480979412,259.125141661888,0.10475165771096331,52.23962855903662,267.67436627406784,0.032460073072428125
0.0333165904988703,259.174097466401,0.1057801748339132,52.24949804922644,267.80889473960343,0.032773619948696334
0.0336380268091144,259.077616652993,0.10680073511893821,52.23004751724339,267.79247646760786,0.03308464401293418
0.0339625434178695,258.997122048586,0.10783107535173565,52.21381980499494,267.79332305126434,0.03339855049573634
0.03429127222698,258.983146505805,0.1088747893206615,52.211002335570285,267.8640080848354,0.03371643102799212
0.0346158667981469,259.04277672095,0.10990537708411639,52.223023786943514,268.00976697494445,0.034030214636456266
0.0349442996050699,259.094247476042,0.11094815124609693,52.23340029117008,268.14811448579496,0.0343476084624604
0.0352742837575054,259.135986376605,0.11199585093007965,52.241814853523564,268.27682269183435,0.03466640007015045
0.0356055128254978,259.058837043332,0.11304750322095551,52.22626154793573,268.2827597882369,0.03498629219654383
0.0359406339205037,259.139386049779,0.11411151269759924,52.242500227635446,268.45301985817815,0.03530983902986526
0.036275359322386,259.229140079008,0.11517426584857554,52.260594639928016,268.6327702822071,0.03563289937288439
0.0366078992951019,259.257912177863,0.11623008026194853,52.26639509505718,268.7487997183286,0.03595374713330349
0.0369464903572784,259.255607189078,0.11730510688435891,52.265930409318116,268.83419198015963,0.036280327489117165
0.0372806325444567,259.221708230588,0.11836600832865002,52.25909637928654,268.88565748267894,0.03660251225507595
0.037615177395968,259.163228026333,0.11942818823219839,52.247306770108736,268.91169882305525,0.03692498131863814
0.0379490608660951,259.203710007848,0.12048826824985193,52.255467937582154,269.04024737565345,0.03724670922939318
0.0382803353271962,259.282440306428,0.12154006466384792,52.27133996577588,269.20785906581176,0.03756582085021853
0.0386097748313214,259.187696801519,0.12258603508944543,52.25223967518623,269.19487541407443,0.037883063929452204
0.038938604406473,259.170479793343,0.12363006899055178,52.24876872633796,269.26221657985184,0.03819961932829027
0.0392664941903854,259.119732137269,0.12467111905447364,52.23853799887343,269.2944555938513,0.038515170268719014
0.039596919978059,259.141172166562,0.12572022093033733,52.2428603087789,269.4023644238618,0.03883306108175108
0.0399261665296358,259.199789895792,0.12676557873159366,52.254677642991666,269.54864387161797,0.039149716911603696
0.0402563580404473,259.21841549691,0.12781393677842015,52.258432564177056,269.65360484183105,0.03946718089342711
0.0405870961504008,259.220221779426,0.12886403027752252,52.258796710732284,269.7412178449158,0.03978506940356237
0.0409187801266455,259.309388683401,0.12991712690209947,52.27677275857364,269.92001254371195,0.04010376557716647
0.0412535436885257,259.305887210094,0.1309800012110691,52.27606686155496,270.00317395680753,0.04042531779542981
0.041590011934519,259.260597119152,0.13204828789209783,52.26693637922104,270.04324844748805,0.04074840326962365
0.0419212209606214,259.250229487773,0.13309987654997293,52.26484626473504,270.1183156422218,0.04106633678844823
0.0422564298830096,259.224554027682,0.13416416487855548,52.259670091980695,270.1784582189072,0.04138800699265847
0.042594629068283,259.244504644411,0.13523794729179853,52.26369213631326,270.2869281577305,0.041712441859876236
0.0429371774043526,259.24975986278,0.1363255382588195,52.26475158833646,270.381212794044,0.04204094161047875
0.0432755129883,259.23931670783,0.1373997537378525,52.26264624829854,270.45803112509776,0.04236529548721604
0.0436136092625194,259.25103824807,0.13847320940849908,52.26500931081092,270.55791173112385,0.04268931488390809
0.0439516424192757,259.301784352933,0.13954646468120033,52.275239725551295,270.69852365749324,0.04301316886589816
0.0442940569843126,259.22803514723,0.14063363092519252,52.26037188568157,270.7102965079728,0.04334111357872927
0.0446382277681548,259.222261479917,0.14172637316389147,52.259207914351265,270.7934838304337,0.04367063195466562
0.0449808868862697,259.21262363813,0.1428143158639063,52.25726492544702,270.87223734148995,0.04399859518852326
0.0453237903993084,259.203287295214,0.14390303451780417,52.25538271871515,270.95136275939404,0.044326684696087186
0.0456727872293755,259.164331265882,0.1450110994532672,52.24752918320181,271.001088625232,0.04466049378696903
0.0460215167545515,259.140266886514,0.14611831569570102,52.24267780432122,271.0662950208106,0.044993935942204556
0.0463680052151729,259.097893149229,0.14721841655817394,52.234135258884564,271.11174561001275,0.045325125197503806
0.0467153866584026,259.137832285493,0.14832135264042826,52.24218698875539,271.2435563185301,0.04565705793154393
0.0470639811512049,259.103607604183,0.14942814015507555,52.2352872930033,271.29805490867545,0.045990039048257964
0.0474089367935786,259.025455577991,0.15052337431961205,52.21953184452299,271.3055770294159,0.0463194351865774
0.047755383333771,258.973685345302,0.15162334208472292,52.209094965612884,271.3410729623263,0.046650145804376424
0.0480979341081378,258.909158586076,0.1527109407933375,52.19608637095292,271.3621542357425,0.046977030109271546
0.04844146691848,258.83887354629,0.153801657466174,52.18191690693207,271.37740827639925,0.04730474425883494
0.0487844347164051,258.808461128749,0.15489058022458618,52.175785763555794,271.4342856047377,0.047631812316419955
0.0491252900808943,258.732748686254,0.1559727960068394,52.16052213514882,271.44307001889337,0.04795675991874965
0.0494667463104521,258.696237505332,0.1570569195356854,52.15316148107494,271.49309865747676,0.04828217450781689
0.049809633245123,258.674433521371,0.1581455855532655,52.14876579790839,271.55891218496043,0.04860884606098581
0.0501488632169723,258.643067078175,0.15922264071388706,52.142442322960086,271.61372287109657,0.04893192861273293
0.0504860607968194,258.660551066875,0.16029324302990158,52.145967095082,271.71930337377603,0.04925297210190724
0.0508312525781791,258.652788058564,0.16138922693571864,52.1444020726065,271.8004332584191,0.049581520086800016
0.0511784036716316,258.65042138175,0.16249143165743032,52.143924950560795,271.8877370570628,0.049911824084763634
0.0515321021383865,258.651390966515,0.16361442428937714,52.144120418849425,271.9802408640372,0.05024824554564811
0.0518827673775632,258.630869864787,0.16472778642376315,52.139983364741056,272.04935512263853,0.05058167025183181
0.052234344847292,258.644492640416,0.1658440448901521,52.14272971630787,272.1546182618483,0.05091585076959667
0.0525935341284277,258.607756737699,0.16698447085775794,52.13532375832012,272.2088526175593,0.05125715115639804
0.0529546661824232,258.577432598125,0.16813106512919365,52.129210411782,272.27031422366673,0.05160018016659446
0.0533104097697539,258.570291672141,0.16926055101896864,52.12777080110364,272.3547798754676,0.051937975817080276
0.0536688901284297,258.525844045065,0.1703987261577643,52.118810159485115,272.4006391644792,0.052278254776775945
0.054023819004275,258.486062019765,0.1715256253385731,52.11079010318462,272.45046624944854,0.052615048539607086
0.0543813437280316,258.443184922582,0.17266076633650032,52.102146080392544,272.4976725960242,0.05295419087667108
0.054737386731178,258.392921369464,0.17379120287149014,52.09201294808394,272.5366746350632,0.05329181341198559
0.0550934230014752,258.373565038626,0.17492161802968373,52.088110711787,272.60824914969817,0.05362931561551247
0.0554526628797418,258.358124636277,0.1760622046431802,52.08499792667345,272.6847706239748,0.05396973924723421
0.0558161557680085,258.323446014434,0.177216294563427,52.0780067165099,272.7420677157044,0.054314075211132073
0.0561764788619746,258.259566971675,0.17836032038676933,52.06512870148968,272.767680076562,0.05465529145550128
0.0565387008591273,258.233873006743,0.17951037522772917,52.0599487981594,272.83408070436514,0.054998188599592226
0.0569020682024883,258.170858661865,0.18066406654290032,52.04724510623198,272.8613144693374,0.05534205188855748
0.0572627850586754,258.088883482093,0.18180934256129438,52.03071890998996,272.8677717429616,0.055683290046150385
0.0576245532277251,257.999988055585,0.18295795649802718,52.01279759200594,272.86712210004646,0.05602540583267869
0.0579863260103967,257.888299019966,0.1841065850830095,51.99028108242515,272.84229400120444,0.05636740897678072
0.0583428358714631,257.816333721746,0.18523850389189533,51.975772878304,272.85806976505614,0.05670432241242187
0.0587022876482688,257.798796584508,0.18637976328325342,51.97223739143682,272.93217569698936,0.05704390117365514
0.0590641927635802,257.737793344578,0.18752881202436714,51.959939138266925,272.96086805314195,0.057385681178374066
0.059423212988742,257.720476557543,0.18866870123925583,51.956448074000676,273.035055327582,0.057724621336926775
0.0597866046395996,257.709244243952,0.18982246973072872,51.95418363958073,273.1168049415352,0.058067571479377515
0.060145758829782,257.700175664999,0.19096278428455785,51.952355414063796,273.1997482809385,0.05840640700055501
0.0605079107122837,257.683894052286,0.19211261651150074,51.94907304094086,273.2758081055953,0.058747954412302274
0.0608766931347151,257.633822269497,0.19328350070272043,51.93897856953059,273.3177174089209,0.05909563528589549
0.0612434760277318,257.554008803089,0.19444803638804845,51.92288817470275,273.32751156706723,0.05944131118304677
0.0616068077738159,257.459699496038,0.19560161468186546,51.90387541840127,273.32096971239486,0.059783616763806925
0.0619738915979456,257.373622994647,0.19676710582347726,51.88652239572084,273.32406800628775,0.06012933833482563
0.062339080793835,257.29780782756,0.1979265815204261,51.8712380580361,273.3375166577989,0.060473156975706835
0.062711167625633,257.217700320627,0.19910795721138477,51.85508838463841,273.3481226417137,0.06082334806966077
0.0630812155378671,257.1568938337,0.20028285933272802,51.84282979687392,273.378663280672,0.06117149864062199
0.0634436470955772,257.102750860377,0.2014335795284576,51.831914573452,273.4142870532649,0.06151236609774698
0.0638118833072822,257.057515939246,0.20260272950062097,51.822795213351995,273.460840149621,0.06185857388531196
0.0641823597424625,257.031267643838,0.20377899218231843,51.81750355699774,273.52814092881596,0.06220676696913556
0.0645531036245911,256.985513819368,0.20495610400807673,51.80827958598459,273.5747263229685,0.06255509008608204
0.0649266445478679,256.919458318914,0.20614209643948056,51.794962797093056,273.60037666661685,0.06290591843035576
0.0652971898464063,256.838664236913,0.20731857776233997,51.77867471016167,273.60950725548815,0.06325381173273366
0.0656682741048752,256.739971209628,0.20849677028297875,51.758778195861005,273.59964201269963,0.06360208979589091
0.0660458455775695,256.628990826404,0.20969555970878315,51.73640455060305,273.57826952525215,0.06395633192728772
0.0664171185145044,256.508853116197,0.21087435128355145,51.712184788225315,273.54543201363504,0.06430454237402292
0.0667872283493528,256.409445858429,0.21204945000919512,51.69214428505929,273.534322069907,0.06465154132806718
0.0671574466168113,256.324328835433,0.21322489300837588,51.674984693223294,273.53841626578856,0.06499852152442917
0.0675279830702522,256.225255542269,0.21440134624805074,51.65501151732143,273.5276302606984,0.06534567942601908
0.0679030268714966,256.142453912135,0.2155921103170017,51.63831870868642,273.5353018430618,0.06569693760608157
0.068277968969679,256.085354175342,0.2167825514787308,51.62680740174895,273.57034204131526,0.06604797724435446
0.0686483983109019,256.048106514254,0.21795866463711353,51.61929827327361,273.62539891699674,0.066394670841855
0.0690224383686344,256.010741995325,0.21914624182041423,51.611765586257526,273.6812276564057,0.06674462187746984
0.069397647393381,255.952270017185,0.22033753047398466,51.59997763546449,273.71475540137305,0.06709554359869319
0.0697779590656259,255.865105662998,0.2215450200333622,51.582405301660394,273.71885053227265,0.06745111204768194
0.0701586456935515,255.809880759681,0.222753700077026,51.57127196115169,273.7571555488091,0.06780690448666812
0.0705371699313459,255.763812243219,0.22395551453202323,51.56198454823295,273.80466772970783,0.06816055047315223
0.0709172170546846,255.677567600036,0.22516216414862358,51.54459762816726,273.8095091575415,0.06851549347790471
0.071301289019132,255.584532165664,0.22638159263574412,51.525841684597864,273.80803876242766,0.06887406751456221
0.0716893368439942,255.493265095335,0.22761364447968158,51.50744224321954,273.8094078381264,0.0692362229289818
0.0720843370746313,255.403695989173,0.22886777021195437,51.48938511141728,273.81430210096323,0.06960473219832573
0.072474129261132,255.314262089005,0.2301053604040941,51.471355237143406,273.8179409218541,0.06996824962805478
0.0728672984192714,255.208246471778,0.2313536724811867,51.44998248871045,273.804581926496,0.07033478257937731
0.0732612888737803,255.089082858947,0.23260459217425244,51.42595910436371,273.777237846824,0.07070194646812829
0.0736546083892792,254.955456341271,0.23385338163596145,51.399019998400234,273.7341006347973,0.07106835068582566
0.0740488499311621,254.815907898184,0.23510509853143968,51.3708870322739,273.6847328222094,0.0714354791595295
0.0744391542410419,254.693984885971,0.23634431471530803,51.34630735301175,273.65318971116335,0.07179880845288886
0.0748290485501957,254.548102867007,0.23758222914687135,51.316897537988616,273.59569521480245,0.07216162432940389
0.0752155924126208,254.432155696512,0.23880950591007102,51.29352258841682,273.56942101604534,0.07252119255345403
0.0755992554784575,254.312859980108,0.24002763614410255,51.26947257198977,273.53872285320136,0.07287795322049352
0.0759847206023089,254.18633741007,0.24125148791233075,51.24396562187011,273.5006152390984,0.0732362614550414
0.0763779371402616,254.072726941993,0.24249995042033057,51.22106175150579,273.47827770942337,0.07360164276372812
0.0767614545484744,253.980143583569,0.2437176181914062,51.202396946447514,273.47602883147414,0.07395788297163039
0.0771535899369139,253.879999845634,0.24496264804970164,51.182207968879815,273.4677532469078,0.0743219970473233
0.0775389697903891,253.79579039033,0.24618622908448537,51.16523134269053,273.4748545143337,0.07467970920059042
0.0779340426332316,253.653853992212,0.2474405853605103,51.13661696482994,273.4221242633245,0.0750462856735869
0.0783324037101662,253.531300342513,0.24870538177977766,51.11191014905062,273.3910165141061,0.07541577719180106
0.0787221883564046,253.412358646764,0.2499429480315846,51.08793150318762,273.36153407599534,0.07577718172176945
0.0791171481110802,253.319565624252,0.2511969452526796,51.0692244298492,273.3614872171804,0.07614325138452081
0.079519505646253,253.203161097428,0.25247443042685325,51.045757277241485,273.33775129596404,0.07651603995839419
0.0799201230098449,253.04864997775,0.25374639055625753,51.0146078355144,273.27232921144696,0.07688707822487016
0.0803251109773122,252.896738811841,0.2550322273529662,50.983982544467146,273.2106974227025,0.07726202451878175
0.0807324180926613,252.790050141711,0.2563254274441996,50.96247410856894,273.1984021594164,0.07763897618683588
0.081137862143608,252.634704345556,0.2576127123059554,50.93115639606409,273.13294415943693,0.07801406257329202
0.0815515021043502,252.486214914478,0.25892601918131186,50.90122092675877,273.0768450013955,0.07839658627052194
0.0819574313714139,252.321497645978,0.2602148446042391,50.86801392542917,273.0011194728306,0.07877183711006891
0.0823719950789175,252.141905947515,0.26153108437556305,50.83180823901903,272.9113377834126,0.07915492455277247
0.0827787794258618,251.984136894542,0.2628226246771112,50.80000199793966,272.8430761813515,0.07953068069550456
0.0831903622727123,251.802877080959,0.26412940021586157,50.76346001952134,272.7504496466353,0.0799107256775689
0.0835942948004899,251.613027793033,0.2654118859915554,50.72518640307546,272.6464414140077,0.08028356617294369
0.0839994852592338,251.437451645229,0.2666983656980673,50.68979025167817,272.55806815832176,0.0806574281642364
0.0844077133897629,251.240314113349,0.2679944900124972,50.650047325251165,272.4469345389826,0.08103395166554771
0.0848086147506033,250.998433362658,0.26926735183316547,50.601284165911856,272.2852628007166,0.08140357949860802
0.0852075314798257,250.783536917477,0.27053391244844655,50.55796104256336,272.15218303399496,0.08177124195532204
0.0856111227190083,250.568927978936,0.2718153146328513,50.514695880553504,272.02041522171106,0.08214307517414211
0.0860149359952091,250.377727586862,0.27309742178478885,50.47614988151138,271.9139517998718,0.0825149746355937
0.0864190478045884,250.165628600556,0.2743804767795681,50.43339072587209,271.78470401765236,0.08288701062568941
0.0868220634757068,249.951192770814,0.27566005153536904,50.39016046259611,271.65247109539024,0.08325789968502714
0.0872241499463818,249.734980178557,0.2769366760797622,50.34657200399709,271.51790153650813,0.08362779658305722
0.0876344408402016,249.568009816306,0.2782393496676401,50.31291077896729,271.43876280815994,0.08400510010101965
0.088048063625765,249.377214415464,0.2795526020118039,50.274446426157546,271.3343952571328,0.08438532358463678
0.0884590237026678,249.193727298959,0.2808574002559702,50.23745542347014,271.2371611286538,0.08476295624586659
0.0888675475060735,248.94138147268,0.28215446333178335,50.186582504892286,271.0641915169309,0.08513820891912319
0.0892712986805178,248.676415093627,0.283436373310644,50.13316528287521,270.8760816202506,0.08550893935237867
0.0896859274779589,248.4218820922,0.2847528197425195,50.08185142978752,270.7018289934591,0.0858895147922891
0.0900969264377703,248.196207587338,0.2860577414399207,50.036355449607335,270.55792304446794,0.08626661562501062
0.0905162363196731,247.951877475625,0.28738905031496204,49.987098499085995,270.3955482131153,0.08665119542507088
0.0909274321721074,247.700857887123,0.28869459714644097,49.936492950044,270.2236608416272,0.08702818967272762
0.091344218607974,247.436231082101,0.2900178940803174,49.88314418615156,270.0381002655976,0.08741016452062085
0.0917637852408641,247.149507960491,0.29135001813974354,49.82534080483499,269.82888233136276,0.08779454004149854
0.0921919104036002,246.913928319944,0.2927093155314306,49.777847949300714,269.67739507701725,0.0881866040097136
0.0926157152276741,246.677858058224,0.29405489584786526,49.73025618453796,269.52410431311705,0.08857456020724565
0.0930402221765924,246.392822183327,0.29540270541068087,49.67279295215872,269.3172651019814,0.08896300831290717
0.0934611605705777,246.100550586263,0.2967391848115842,49.61387099819063,269.1013936611133,0.08934804204991471
0.0938878685051203,245.768249412677,0.29809398250375696,49.546879081595684,268.84290649626803,0.089738201950583
0.0943144809966639,245.404089607842,0.29944847716440787,49.473464464940946,268.5492489536644,0.09012812246871586
0.0947372282476583,245.058624425148,0.3007906996863151,49.40381868410984,268.27479926137045,0.09051436026699604
0.0951520431199807,244.664877571989,0.3021077369059387,49.32443931851298,267.9452405526637,0.09089320579376048
0.0955756423185807,244.286244614921,0.3034526643614937,49.24810691436807,267.634059353586,0.09127992588379716
0.0960060486648001,243.916094521743,0.3048192045107403,49.17348465558339,267.3335149625254,0.0916727073653395
0.0964354830541248,243.537954833872,0.30618265869684624,49.0972516945086,267.02365515029004,0.09206444816079856
0.0968670239087276,243.185259679456,0.30755280091021014,49.02614835137833,266.741892043076,0.09245795599549222
0.0972974240078733,242.770179564144,0.3089193212249977,48.94246820013144,266.39109266166406,0.09285026943861124
0.0977315771690647,242.390639807155,0.3102977575117804,48.86595298512245,266.07985932652696,0.09324584796319585
0.0981734566853518,241.998801820085,0.31170072497599194,48.78695844692914,265.75666070847615,0.09364830573385434
0.0986081571384381,241.542013891091,0.31308089891454094,48.69487000044394,265.3600267523985,0.09404406692925456
0.0990434354618906,241.096881912781,0.31446290759150264,48.60513139361665,264.97594537657255,0.09444019735375865
0.0994759412817453,240.636519164871,0.31583611356954133,48.512322263638,264.5740634155593,0.09483364926508542
0.0999036248480543,240.144813743321,0.3171940088925724,48.41319445065352,264.1361511247396,0.0952225621915178
0.100335841006854,239.60607675443,0.31856629519676144,48.30458507369309,263.6471539759386,0.09561544321294005
0.100765512322688,239.104735214661,0.3199305016245344,48.20351461927566,263.198246357347,0.09600585805743758
0.101194769919106,238.620802437727,0.3212933944931615,48.10595377144577,262.76797963832524,0.09639574483724693
0.101613575700907,238.140096836252,0.3226231028503797,48.009043522188406,262.3383635935438,0.09677599197738491
0.102055007566148,237.623575654147,0.32402464902251993,47.904912851876034,261.8742514654261,0.09717662560668594
0.102493387431207,237.083257088867,0.3254165050940822,47.79598462911559,261.3827232111287,0.09757433052605363
0.10293319304907,236.536199016349,0.32681288793079727,47.68569772169596,260.8836252527921,0.09797317003183058
0.103374697323473,236.050098180192,0.32821466400202676,47.58769979312671,260.4517056327455,0.09837339003940322
0.103812381736068,235.470402267468,0.32960431201201584,47.47083309712155,259.9151455552039,0.09876998933312375
0.104036903673658,235.178231277097,0.33031716916386417,47.41193142546276,259.6454462706136,0.09897337453685799
0.104278590695088,234.872588717016,0.3310845254569044,47.350313885350424,259.36477126133343,0.09919226266494603
0.104487143053147,234.54028713134,0.33174667919374173,47.28332188567814,259.04673166455854,0.09938110329706223