File: example/data/02 processed data/test_ID_147.csv
Strain,Stress_MPa,Displacement(mm),Force(kN),True Stress (MPa),True Strain
9.02702473293207e-06,0.803703121883699,2.8660803527059323e-05,0.1620265493717537,0.803710376931658,9.026983989479117e-06
3.08581003487265e-05,0.756766803201139,9.797446860720663e-05,0.15256418752534961,0.7567901555870927,3.08576242473676e-05
5.40982425379225e-05,0.669628851190107,0.00017176192005790393,0.13499717639992556,0.669665076934109,5.40967792807311e-05
0.0001064762291361,0.507802273702006,0.0003380620275071175,0.10237293837832441,0.5078563425732565,0.00010647056094472814
0.000147693749085,0.327406874109411,0.000468927653344875,0.06600522582045726,0.3274552300581244,0.00014768284343698977
0.0001912924591618,0.119648915900832,0.0006073535578387149,0.024121221445607733,0.11967180383619072,0.00019127416509233765
0.000250251537225,-0.0292746453685922,0.0007945486306893749,-0.005901768506308188,-0.029281971393597405,0.00025022022953205856
0.0002946579194594,0.501372616567108,0.0009355388942835948,0.10107671949992897,0.5015203499791795,0.0002946145163404626
0.0003638079961085,1.73948282232606,0.0011550903876444874,0.35067973698093374,1.7401156600859158,0.00036374183402593875
0.0004220507649974,4.29056864087198,0.0013400111788667449,0.8649786379997911,4.292379478649134,0.0004219617266249385
0.0004773396194183,7.4449605436189,0.0015155532916531023,1.5009040455935705,7.448514318251375,0.0004772257291035363
0.0005592709874114,10.7198627681556,0.0017756853850311948,2.1611243340601693,10.72585807639086,0.0005591146536785938
0.000630827813572,13.9837033558763,0.0020028783080910995,2.8191145965446616,13.992524664889928,0.0006306289253452768
0.0007110815732062,16.9872625830926,0.002257683994929685,3.4246321367514687,16.999341912494653,0.0007108288744900572
0.0007940729246538,20.2924214503355,0.0025211815357758147,4.0909521643876365,20.308535112784877,0.0007937578155510357
0.0008648388755314,23.88231639693,0.002745863429812195,4.814674985621088,23.90297075258781,0.0008644651178690585
0.000938366200165,27.7151462716029,0.0029793126855238747,5.587373488355145,27.741153228096803,0.0009379262098286851
0.0010200307358676,31.6982820741845,0.00323859758637963,6.390373666155596,31.73061529617437,0.001019510858014151
0.0011209620825172,35.5705780341677,0.0035590546119921096,7.171028531688209,35.61045130339723,0.0011203342736448249
0.0012018073700519,39.3818540412451,0.0038157383999147822,7.939381774715011,39.42918344367818,0.0012010857776600826
0.0012755541851029,43.0868710364167,0.004049884537701707,8.686313200941608,43.14183067509019,0.0012747413569940422
0.0013556429119188,46.6497841562797,0.00430416624534219,9.404596485905989,46.7130246055137,0.001354724857675312
0.0014274002950394,50.0936657688534,0.004531995936750095,10.098883019000846,50.16516948215146,0.0014263825276308155
0.0015281369575865,53.4454292545098,0.004851834840337137,10.774598537709176,53.52710119016769,0.001526970544447492
0.0016186786718905,56.7413341392101,0.005139304783252337,11.439052962464757,56.833180126595856,0.001617370023566262
0.0017172316034065,59.9712269139009,0.005452210340815637,12.090199345842422,60.074211400052505,0.0017157588470180392
0.0018159555676128,62.9529198931295,0.00576565892717064,12.691308650454907,63.0672395985069,0.0018143087137418264
0.0019189737510023,65.9496915625905,0.006092741659432303,13.295457819018246,66.07624728958581,0.0019171348730037691
0.0020428003002898,68.7203120659013,0.006485890953420115,13.854014912485702,68.86069394002553,0.002040716620967547
0.0021866434276335,71.3946732399268,0.006942592882736362,14.393166125169245,71.55078793293492,0.002184256202267326
0.0023484843430971,73.862384357068,0.007456437789333291,14.890656686384908,74.03584901027439,0.0023457309637452397
0.0025473216720848,76.1865506204218,0.008087746308869239,15.359208605077036,76.38062227193859,0.002544082747456865
0.0027636454241338,78.4714933727416,0.008774574221624814,15.81985306394471,78.68836075632612,0.0027598335775650905
0.0030362177584394,80.6254472016818,0.009639991383045094,16.25409015585905,80.87024361625765,0.0030316177580175722
0.0032979359831156,82.5197897455856,0.01047094674639203,16.635989612710055,82.79193472950669,0.003292509719282003
0.003573941731729,84.2428952309457,0.011347264998239575,16.983367678558654,84.54397442981326,0.0035675703780301687
0.0038768446856731,85.7202461903459,0.012308981877012092,17.281201631973733,86.05257027124354,0.003869349089909279
0.0041889483929163,86.9609374673579,0.01329991114750925,17.53132499341935,87.32521234660828,0.004180199173439433
0.0045194845079844,87.9353357254364,0.01434936331285047,17.72776368224798,88.33275811295191,0.004509302305220528
0.0048662109123144,88.6191133513663,0.01545021964659822,17.865613251635445,89.05035264779633,0.004854409178989407
0.0052192203569798,89.0796809175214,0.016571024633410866,17.958463672972314,89.5446074015594,0.005205647432650905
0.0055726118194597,89.4227249307903,0.017693042526784546,18.027621346047326,89.92104306466791,0.005557142262163643
0.0059176997268252,89.6667577517511,0.01878869663267001,18.076818362753023,90.19737869960393,0.005900258914299761
0.0062863074845705,89.833931825561,0.019959026263511336,18.1105206560331,90.39865554356442,0.006266631071941333
0.0066628753700832,89.9769040004089,0.021154629300014157,18.139343846482433,90.57640889794956,0.006640776522917453
0.0070259883340874,90.0549376248085,0.022307512960727492,18.155075425161396,90.68766256598737,0.007001421083737811
0.0074006463261496,90.1014749668861,0.023497052085524977,18.164457353324238,90.76828411658045,0.007373395907676166
0.0077776766782836,90.0967959807309,0.024694123453550428,18.16351406971535,90.79753972961831,0.0077475864715872995
0.0081370517951767,90.0502519031142,0.02583513944968602,18.15413078366782,90.78299546701855,0.008104124489415263
0.008551154460522,89.9693176013854,0.02714991541215735,18.137814428439295,90.7386591329026,0.008514800438112488
0.0089313665962896,89.9102128658348,0.02835708894321948,18.125898913752295,90.71323393768999,0.008891717845129023
0.0093200594919278,89.8580720927587,0.029591188886870762,18.115387333900156,90.69555467049315,0.009276895722790404
0.0097048988980012,89.8157321457867,0.030813054001153806,18.1068516005906,90.68738474571153,0.009658108851568054
0.0100951648410815,89.767920031774,0.03205214837043376,18.097212678405636,90.67414198193578,0.01004454902942841
0.0104895255961715,89.6965638722679,0.033304243767844514,18.08282727664921,90.63743827489468,0.010434892242423865
0.0108924217950112,89.6223882729917,0.03458343919916056,18.06787347583513,90.5985931283374,0.010833526656563295
0.0112931715316113,89.5436160318981,0.03585581961286587,18.05199299203066,90.55484744730707,0.011229879734311391
0.0116953367103885,89.4351494865622,0.03713269405548349,18.03012613649094,90.48112367355147,0.011627474858986141
0.0121080447611639,89.3260638250133,0.03844304211669538,18.008134467122684,90.40762780414515,0.012035328764434526
0.0125179075822006,89.1885172534436,0.039744356573486905,17.980405078294233,90.30497086981572,0.012440206343091719
0.0129355943961555,89.064344110677,0.04107051220779371,17.955371772712482,90.21644434125234,0.012852644169452917
0.013348468527497,88.9214516080868,0.04238138757480297,17.9265646441903,90.10841680629669,0.013260162685350978
0.0137627457649118,88.8148419528669,0.043696717803594964,17.905072137697967,90.03717804281504,0.013668899256153454
0.0141795591917646,88.7069315006004,0.0450201004338526,17.883317390521043,89.96475668653298,0.014079969562940142
0.0146015675957112,88.5991675067828,0.04635997711638306,17.861592169367412,89.89285424005683,0.014495991187413126
0.0150268095788813,88.473339318719,0.04771012041294812,17.83622520665375,89.80281134146914,0.014915025523131651
0.0154358476322068,88.3479139823034,0.049008816232256586,17.810939458832365,89.71163892115754,0.015317926859342933
0.0158590788637335,88.2091531637843,0.05035257539235386,17.782965277818914,89.6080690803119,0.01573463763051726
0.0162797366061544,88.0836306205736,0.05168816372454022,17.75765993310764,89.51760892639034,0.016148642564852385
0.0167157755094624,87.9337473240302,0.05307258724254312,17.727443460524487,89.40362810400448,0.0165776045644197
0.0171337267654759,87.7549431560351,0.054399582480385976,17.691396540256676,89.25851237439046,0.0169885998336657
0.0175418937508946,87.5845043063146,0.05569551265909035,17.657036068153023,89.12090237508075,0.017389810706571748
0.0179641838579242,87.4511051034517,0.05703628374890933,17.630142788855864,89.02209283410875,0.017804734658637796
0.0183889329988961,87.3032195109016,0.05838486227149512,17.600329053397765,88.9086325650755,0.018221901154581867
0.0188272728603745,87.165961476548,0.059776591331689034,17.57265783367208,88.80705881740386,0.018652233356909773
0.0192481565786977,86.9790225322887,0.061112897137365195,17.5349709425094,88.65320837705227,0.01906525410994656
0.0196789069603629,86.7867633658979,0.0624805295991522,17.496211494565017,88.49463200756644,0.01948778063948896
0.0201074410184209,86.6296913517414,0.06384112523348635,17.464545776511066,88.37159276104056,0.019907956080693814
0.0205573491415056,86.4802138951487,0.06526958352428028,17.434411121261977,88.25801784602335,0.020348898789700958
0.0209981695735417,86.3620249468875,0.0666691883959949,17.41058422929252,88.17546939143669,0.020780746402803675
0.021452076054165,86.2023157477961,0.06811034147197387,17.378386854755696,88.05153438126297,0.021225218907402112
0.021899632295167,86.0169917043882,0.06953133253715522,17.34102552760466,87.90073219385073,0.021663279811288925
0.0223441441852449,85.8695171220267,0.07094265778815255,17.311294651800583,87.78819799371864,0.02209817109206289
0.0228022150170929,85.7124576619032,0.07239703267926996,17.279631464639685,87.6668915511534,0.022546130073039346
0.0232488110337067,85.5934609548994,0.07381497503201877,17.25564172850772,87.58340715436081,0.022982674438766275
0.0237000909148022,85.4509655170858,0.07524778865449698,17.2269146482445,87.47616116859837,0.023423603753589182
0.024156179524701,85.3108203081034,0.07669586999092567,17.198661374113648,87.37160379886545,0.023869034054556402
0.0246147219777212,85.1544205829724,0.0781517422792648,17.16713118952724,87.25047297079622,0.024316660932057046
0.0250782185205829,84.995952430687,0.0796233438028507,17.1351840100265,87.12749949910884,0.024768920430642393
0.0255512678559648,84.8388844958006,0.08112527544268824,17.1035191143534,87.00662555815406,0.025230290314296036
0.0260063391801849,84.6652696022017,0.08257012689708705,17.068518351803863,86.86710332025835,0.025673925267682515
0.0264618780181924,84.5143440837465,0.08401646270776086,17.038091767283294,86.75075234767814,0.026117818957894647
0.0269013635952123,84.3423207379676,0.08541182941479905,17.003411860774268,86.61124417460367,0.026545883096595568
0.027355588072393,84.1752355859234,0.08685399212984778,16.969727494122157,86.47789865650856,0.02698811062243123
0.0278088513575417,84.0337989875138,0.08829310306019489,16.941213875882784,86.3706824125671,0.027429207484367484
0.0282602611856775,83.8813606764511,0.08972632926452606,16.910482312372544,86.25186983777762,0.02786830734986808
0.0287298015521444,83.7045148585597,0.09121711992805846,16.874830195485636,86.10932895946465,0.02832483884520956
0.0291932144653204,83.5129002168592,0.09268845592739226,16.836200683718815,85.95091022351087,0.028775208385179742
0.0296738594516312,83.2958191024371,0.09421450375892906,16.79243713105132,85.76752753139131,0.029242110791004375
0.0301486291871588,83.1414382523954,0.09572189766922919,16.761313951682915,85.64803864435395,0.029703092012982293
0.030632928759,83.0132620332467,0.09725954880982499,16.735473625902536,85.55620137516334,0.03017310745822865
0.0311137896487604,82.9095552214801,0.09878628213481426,16.71456633265039,85.48918568251351,0.030639567178218658
0.0315932014088645,82.7859428676871,0.10030841447314479,16.68964608212572,85.40141583452868,0.031104404666834222
0.0320663509250619,82.606972319226,0.10181066418707153,16.653565619555962,85.25587648247117,0.0315629585246671
0.0325410273298547,82.4610997990824,0.10331776177228866,16.624157719495013,85.14446870129423,0.03202278097629256
0.0330284862742418,82.3076942266503,0.1048654439207177,16.5932311560927,85.0261927756797,0.03249476601502
0.0335093166813472,82.1966947549363,0.10639208046327735,16.57085366259516,84.95104982963949,0.03296011478831088
0.0340015688520653,82.0661902527975,0.10795498110530734,16.544543954963977,84.85656947110469,0.03343629335013992
0.0344726563323899,81.9081823623543,0.10945068385533792,16.51268956425063,84.73177498374245,0.0338917860826416
0.0349601082867035,81.7452770234449,0.1109983438102836,16.479847847926493,84.6031007601111,0.034362883256381864
0.0354564305858106,81.5991485686246,0.11257416710994865,16.450388351434718,84.49236311570928,0.034842325242374246
0.0359467781090484,81.4350435922451,0.11413102049622867,16.41730478819661,84.3623710345562,0.03531577003606662
0.0364402667149721,81.2565896090416,0.11569784682003642,16.381328465182786,84.21760140674411,0.03579202143561468
0.0369193398959975,81.1106891822628,0.11721890416979205,16.35191493914418,84.10524228538137,0.03625414405826405
0.0374083200910125,80.9759171943023,0.11877141628896468,16.324744906371343,84.00509022437008,0.036725603040858264
0.0378957581205769,80.8240491905102,0.12031903203283165,16.294128316806855,83.88693780895939,0.03719535399797872
0.038382152470652,80.6756677294649,0.1218633340943201,16.264214614260126,83.77217350892889,0.03766387929171855
0.0388902371037267,80.5276695300841,0.12347650280433227,16.234378177264954,83.65940969151961,0.038153063710436926
0.0393890015228954,80.345242559069,0.12506007983519288,16.197600899908313,83.50996144058558,0.038633041972716775
0.0398988553964709,80.1762625860205,0.1266788658837951,16.163534537341732,83.37520369316962,0.0391234539972927
0.0404067938541978,79.9782179393404,0.128291570487078,16.123608736571025,83.20988130444144,0.03961178461159808
0.0409086150326001,79.8314656724032,0.1298848527285053,16.094023479556487,83.09726036908377,0.04009400002785233
0.0414242781774612,79.7448550345794,0.1315220832134393,16.076562774971208,83.04822809275313,0.04058927449341294
0.0419579310009058,79.6562565589042,0.1332164309278759,16.058701322275088,82.99846827539315,0.04110156919648256
0.0424659976761097,79.5336215065446,0.13482954262164829,16.03397809571939,82.91109609261412,0.041589058020877395
0.0429715935699284,79.3857355977721,0.13643480958452267,16.004164296510854,82.79706716312936,0.042073940336077774
0.0434593837284419,79.2289581132479,0.13798354333780302,15.972557955630778,82.67219980629618,0.042541523661582585
0.043976422209355,79.0857008638203,0.13962514051470212,15.943677294146173,82.56360703573043,0.043036905114766474
0.0445000541312847,78.9365041021258,0.14128767186682892,15.91359922698856,82.44918280760477,0.04353835383955128
0.0450207121159715,78.7958082865342,0.1429407609682095,15.885234950565293,82.34325168734755,0.044036705427028
0.0455575575161901,78.6103649007565,0.14464524511390356,15.84784956399251,82.1916611210914,0.044550290993105236
0.0460771646641621,78.4686896176073,0.14629499780871466,15.819287826909632,82.0843043500988,0.045047134111218204
0.0465913439778749,78.3296614329681,0.1479275171297528,15.791259744886368,81.979145632462,0.04553854431014524
0.047101022937551,78.2221014500935,0.14954574782672442,15.769575652338851,81.9064424447178,0.046025415235213404
0.0475953854886228,78.1248732783263,0.15111534892637737,15.749974452910584,81.84325673825806,0.046497428800770416
0.0481115750932638,77.9949751960672,0.15275425092111256,15.72378699952715,81.74743630211003,0.04699004501552612
0.0486175624213185,77.861967887743,0.15436076068768623,15.69697272616899,81.64742697177205,0.04747268946284556
0.0491481808633242,77.6855818731713,0.15604547424105433,15.661413305631333,81.50368690154652,0.04797857860229867
0.0496826498058781,77.5082770425165,0.15774241313366297,15.625668651771326,81.35909362787682,0.04848788020612179
0.0502250695521076,77.3653194455257,0.15946459582794162,15.596848400217983,81.25099799559825,0.04900449315372241
0.0507744806543455,77.1746628156866,0.16120897607754694,15.55841202364242,81.09316623982733,0.04952749289896963
0.0513171368795615,77.058870517719,0.16293190959260775,15.53506829637215,81.0133111238612,0.05004379412270709
0.0518513509700087,76.9417138936056,0.16462803932977763,15.51144952095089,80.93124570493693,0.05055180297223322
0.052394645325352,76.8261629366466,0.1663529989079926,15.488154448027954,80.8514424954199,0.05106818211076762
0.052929547645006,76.7452996743013,0.16805131377289403,15.471852414339141,80.80739366994248,0.0515763245934785
0.0534938464629272,76.6400005399696,0.16984296251979386,15.450624108857873,80.7397689617734,0.05211211320368759
0.0540594739907921,76.5126267512144,0.1716388299207649,15.424945553044823,80.64885910703885,0.05264887546346622
0.0546505752723345,76.3928159926404,0.17351557648966204,15.400791704116305,80.5677273333118,0.053209503793787104
0.0552094646001594,76.2408278717334,0.17529005010550608,15.370150898941453,80.45004315920471,0.05373929186535109
0.0557687189532852,76.1038174554049,0.17706568267668052,15.342529599009627,80.34802986234749,0.05426914515380946
0.0563306625326804,76.0162560314037,0.17884985354126026,15.324877215930986,80.29830209690654,0.054801263668289114
0.0569135683799722,75.8993391988087,0.18070057960641173,15.301306782479836,80.21904143029481,0.05535293285403521
0.0574433094500191,75.8256026744675,0.18238250750381063,15.28644149917265,80.18127623313113,0.05585402241624289
0.0579679077064414,75.6625808391908,0.18404810696795143,15.253576297180864,80.04858234210818,0.056349999995374316
0.0585029734327071,75.5162247041737,0.18574694064884503,15.224070900361417,79.93414839178031,0.0568556206891747
0.0590140579759959,75.3829660147767,0.18736963407378696,15.197205948578983,79.83162074157526,0.05733834129602915
0.0595712504158173,75.2658503256653,0.18913872007021992,15.173595425654124,79.74953114317492,0.057864345559781274
0.0601307218481585,75.0971038513075,0.19091504186790323,15.13957613642359,79.61274691459275,0.05839222301864444
0.0607037564515535,74.9124266726364,0.19273442673368235,15.1023452172035,79.45989237656698,0.05893260900652128
0.0612751922746648,74.7656883511112,0.19454873547206072,15.072762771584017,79.3469702803732,0.059471196665242046
0.0618409970963997,74.5942028839861,0.19634516578106903,15.038191301411599,79.20718276794294,0.06000419136234076
0.0624220489438955,74.4906185610031,0.19819000539686818,15.017308701898227,79.14047559867909,0.06055125342517726
0.0630041237454885,74.3953046737349,0.20003809289192598,14.998093422224956,79.08251565548221,0.06109897869893589
0.0635880156311706,74.3134139412572,0.20189194962896664,14.98158425055745,79.0388564685595,0.0616481125827146
0.0641589842750809,74.2276647093224,0.20370477507338186,14.964297205399395,78.9900362821838,0.06218480106836672
0.0647488589945604,74.0891477457806,0.20557762730772924,14.936372185549367,78.88633552619929,0.06273895820244813
0.0653286881185489,73.9522657632187,0.20741858477639274,14.908776777864892,78.78347026892406,0.06328337888712769
0.0659288551813293,73.8286302145056,0.2093241152007205,14.883851851244328,78.69606728415364,0.06384658353644995
0.0665144334730792,73.7290601147476,0.21118332627702643,14.863778519133117,78.63310677878263,0.06439579233331169
0.0670993119575546,73.6223050762354,0.21304031546523583,14.842256703369058,78.56231109157999,0.06494404386232282
0.067675998227276,73.4812219513313,0.2148712943716013,14.813814345388392,78.45413699784768,0.06548432206490273
0.0682603066880423,73.3592017778032,0.21672647373453427,14.789215078405123,78.36672338954601,0.06603144369394871
0.0688513576937206,73.1839286924934,0.21860306067756288,14.75388002440667,78.22274154433201,0.06658457438019093
0.0694402873292327,73.0546141197941,0.22047291227031382,14.727810206550489,78.12754751499882,0.06713541565740802
0.0700279528327033,72.9282140117249,0.22233875024383296,14.70232794476374,78.03522754271127,0.06768477227529865
0.0706297215276945,72.8542037019471,0.22424936585043004,14.687407466312536,77.99987582153756,0.0682470001532546
0.0712236472896913,72.7425598636539,0.22613508014476985,14.664900068512624,77.92355029033203,0.06880159066431975
0.0718184621435949,72.6062614064629,0.2280236173059138,14.637422299542923,77.82073144267092,0.06935670329282084
0.0723708730326494,72.4541522355846,0.22977752187866182,14.606757090693858,77.69772248771434,0.0698719664668455
0.0729446313819159,72.3334187555798,0.23159920463758296,14.582417221124889,77.60975332329933,0.07040686062275488
0.0735422972849542,72.222666917702,0.2334967938797296,14.560089650608722,77.53408775887587,0.0709637388506179
0.0741618300300018,72.1422273776896,0.2354638103452557,14.543873039342223,77.49242698245955,0.07154066446560568
0.0747839022816186,72.0083881512241,0.23743888974413904,14.516891051286777,77.3934564141821,0.07211962023879188
0.075387808326984,71.8822408314179,0.23935629143817416,14.49145975161385,77.30128542533095,0.07268134845637153
0.0759817274595583,71.7359585501647,0.24124198468409758,14.461969243713204,77.18658060177347,0.07323347968048961
0.0765902009668965,71.6074390398748,0.2431738880698964,14.43605971043876,77.09186718666359,0.07379882527058047
0.0772001988290278,71.5244759811036,0.24511063128216326,14.419334357790488,77.04617974798683,0.07436526653478089
0.0778251959385742,71.3846596277055,0.2470949971049731,14.391147380945428,76.94018475024012,0.0749453034369788
0.0784561360245643,71.2786715868561,0.24909823187799165,14.369780191910191,76.87092074052474,0.07553051474001622
0.0790851008889615,71.1508921162614,0.2510951953224527,14.344019850638299,76.77786759761555,0.07611355331323404
0.0797143781335564,71.0465844026977,0.2530931505740416,14.322991415583859,76.71001869687197,0.0766965414680234
0.0803260003970378,70.9460385826186,0.255035051260595,14.30272137825591,76.64485010597429,0.07726284780739227
0.080941496402142,70.8341416556512,0.2569892510768008,14.28016295777928,76.5675630776209,0.07783241730552712
0.0815517306366747,70.7151225126613,0.2589267447714422,14.256168698552518,76.4820631357533,0.07839679757095452
0.0821719404684986,70.621340723384,0.26089591098748305,14.237262289834215,76.42443332911147,0.07897007765943569
0.0827956356778629,70.5235055309144,0.2628761432772147,14.217538715032346,76.36254400157775,0.0795462481605465
0.0833999376085665,70.4041937556272,0.2647948019071986,14.193485461134443,76.27589912222794,0.0801041866531113
0.0840009961236805,70.2436832171099,0.26670316269268557,14.161126536569357,76.1442225787434,0.08065882195031684
0.0846316627399657,70.0930926731441,0.26870552919939106,14.130767482905851,76.02518765265879,0.08124044800993233
0.085268094820974,69.9711766316838,0.27072620105659245,14.106189208947455,75.93748555544934,0.08182704847111995
0.0859275127469369,69.8485558409588,0.2728198529715246,14.081468857537294,75.85046851333793,0.08243447227387596
0.086567032993419,69.7593379486594,0.27485032975410534,14.063482530449734,75.79819685846006,0.08302321507758822
0.0872074679987821,69.6481879234152,0.2768837108961331,14.041074685360504,75.7220300429196,0.0836124528514244
0.0878390057818904,69.5552474598984,0.27888884335750197,14.022337887915517,75.66491124368922,0.08419316485778254
0.0884660257231902,69.4666260897145,0.2808796316711289,14.004471819686442,75.6120624202704,0.08476938919175434
0.0890954914864068,69.3178566552894,0.28287818546934157,13.974479901706344,75.49376516277671,0.08534752742185696
0.0897260763397311,69.1905444982986,0.28488029237864626,13.948813770857,75.39874057594051,0.08592635854804202
0.0903648893830126,69.0685003392942,0.28690852379106496,13.924209668401712,75.3098677323051,0.08651240112296997
0.0909824139561884,68.9782987262445,0.28886916431089815,13.90602502321089,75.2541108549493,0.08707858752412383
0.0916127635821941,68.8575360905256,0.2908705243734662,13.881679275849962,75.16576526523933,0.08765620232875519
0.0922406189884174,68.7366606898647,0.2928639652882252,13.857310795076726,75.07697281909464,0.08823120010885585
0.0928852351394673,68.5541938748151,0.2949106215678087,13.820525485162722,74.92186629267393,0.0888212038091295
0.0935369347245596,68.4167338533424,0.2969797677504767,13.792813544833828,74.81622542185005,0.08941733717566282
0.0941743859594253,68.3032892702373,0.29900367542117534,13.76994311687984,74.7357095962709,0.09000009345331149
0.0948002181485147,68.1699040444087,0.30099069262153416,13.743052655352795,74.63242581898196,0.09057189744314935
0.0954563888691607,68.0827592751677,0.3030740346595852,13.72548426987381,74.58169361982357,0.09117106992200347
0.0960993625285039,67.983130531948,0.3051154760279999,13.705399115240718,74.51626603876028,0.09175784365785873
0.0967842467930228,67.8432229009266,0.30728998356784737,13.677193736826803,74.40937812940395,0.09238248628264437
0.0974408594760473,67.74500160079,0.3093747288364502,13.657392322719266,74.34613278197719,0.09298097793306619
0.0980944518872285,67.6044576194296,0.31144988474195046,13.629058656077007,74.2360798347409,0.09357636114289702
0.0987585150477253,67.4538305201434,0.3135582852765278,13.59869223286091,74.11547065659369,0.09418091974624232
0.099416412554688,67.3578957932497,0.31564710986113437,13.579351791919139,74.05437615024708,0.09477950498015197
0.100055033826267,67.2578487983463,0.3176747323983977,13.559182317746616,73.98733513494679,0.0953602093039803
0.10068730090694,67.1707165831384,0.3196821803795345,13.541616463160702,73.93395473587964,0.09593480369251008
0.101362547623416,67.0816299389857,0.32182608870434576,13.523656595699517,73.8811948483325,0.09654809293125392
0.102023053024884,66.9654841675126,0.32392319335400666,13.50024160817054,73.79750730957177,0.09714762977224839
0.102699910143415,66.8335818038323,0.3260722147053426,13.473650091652592,73.69738464964846,0.09776163629470333
0.103341047053716,66.6732985028003,0.32810782439554825,13.44133697816454,73.56338698060463,0.09834289198377874
0.104009374865744,66.498520321507,0.3302297651987372,13.40610169681581,73.41498984964392,0.09894843954506648
0.104679664396369,66.3776010133527,0.33235793445847156,13.381724364291903,73.32598601086654,0.09955539646773642
0.10535013150456,66.2682326014594,0.334486667526978,13.359675692454216,73.24959962059792,0.1001621458699423
0.106015783146414,66.1833665473324,0.3366001114898644,13.342566695942212,73.19984798311401,0.10076417347428272
0.106671678220884,66.0728654580824,0.33868257835130666,13.320289676349413,73.12096890135874,0.10135702276288086
0.107322805542081,65.9457723642254,0.3407499075961071,13.294667708627841,73.0232576679935,0.10194521514072523
0.107959881889382,65.8307858011764,0.34277262499878786,13.271486417517163,72.93786966095662,0.10252037998851507
0.108601204628437,65.7218804971279,0.34480882469528745,13.249531108220985,72.85935588956217,0.10309904462433449
0.109259193334706,65.5913924701811,0.34689793883769154,13.223224721988512,72.7578551011732,0.10369239912597768
0.109921878652142,65.4389663653067,0.3490019647205508,13.19249561924583,72.63214048523555,0.10428963325481824
0.110591041843589,65.327991527325,0.3511265578533951,13.17012309190872,72.55268217188102,0.1048923437416855
0.111267585123418,65.1774445588192,0.35327458276685214,13.139772823057951,72.42958141939447,0.10550133235376612
0.111942015401459,64.9900864300198,0.3554158988996323,13.102001424291991,72.26520768611122,0.10610805004567454
0.112625046044134,64.8212980719925,0.3575845211901254,13.06797369131369,72.12179975199119,0.1067221296802935
0.113311352686468,64.7175798287826,0.35976354477953587,13.047064093482573,72.05081634177644,0.10733877502961502
0.113977297768251,64.6158078559772,0.3618779204141969,13.026546863765002,71.98054302851399,0.10793676227432311
0.114643486864918,64.5598982799549,0.36399307079611465,13.015275493238908,71.96127013041334,0.10853461106143232
0.115302250886438,64.4284349912096,0.3660846465644406,12.988772494227856,71.85717856678662,0.10912544520553855
0.115949869530418,64.3054794157286,0.36814083575907713,12.963984650210884,71.76169136407331,0.10970594317458472
0.11661169741819,64.164992797129,0.37024213930275324,12.935662547901206,71.64738152202816,0.11029882976455102
0.117267007475105,64.0220584266804,0.3723227487334584,12.90684697881877,71.52973363077353,0.11088553133816549
0.117933461060208,63.8619679897484,0.37443873886616036,12.874572746733277,71.39343090489565,0.11148185691543175
0.118608919388925,63.7077188621872,0.37658331905983683,12.84347612261694,71.26402255316466,0.1120858770808064
0.119274820975271,63.5399465428492,0.3786975565964854,12.8096532230384,71.11866229152582,0.11268099432839926
0.119939948471674,63.4032878766135,0.3808093363975649,12.782102835925283,71.00787495746924,0.11327506643353182
0.120574742556986,63.291148027525,0.3828248076184305,12.759495442349039,70.92246190707992,0.11384171668120875
0.121224205077681,63.1167399530405,0.3848868511216372,12.724334774532965,70.76801658094254,0.11442112862138289
0.12188978934253,63.0071491734885,0.38700008116253276,12.702241273375282,70.68707731331837,0.11501457530847793
0.12255982763333,62.8611519826261,0.3891274527358227,12.672808239697423,70.56540393444931,0.11561163777371396
0.123232887816307,62.7140931379794,0.3912644188167747,12.643161176616648,70.44253194215344,0.11621103432398144
0.123912743949331,62.5890869861039,0.3934229620391259,12.617959936398547,70.3446724958354,0.11681611851982214
0.124574139374349,62.4322949079115,0.39552289251355804,12.586350653434959,70.20974431523013,0.11740442121262322
0.125237736428269,62.2968098698459,0.39762981315975404,12.559036869760934,70.09872132464766,0.11799433460076161
0.125909690275535,62.1685360960573,0.3997632666248236,12.533176876965152,69.9961572207953,0.11859132248280943
0.126571962913335,62.0418378850415,0.4018659822498386,12.507634517624368,69.89459508890212,0.11917936070806764
0.127267544837686,61.9067699760697,0.404074454859653,12.48040482717565,69.78549259975546,0.11979660248064523
0.12794957162103,61.7417253287336,0.4062398898967702,12.447131826272694,69.64155263568836,0.12040144606679848
0.128621512105338,61.5469966069528,0.4083733009344482,12.407874515961685,69.46326437608118,0.12099698724785288
0.129271898567322,61.3749743521415,0.4104382779512473,12.373194829391728,69.30903381116353,0.12157308749855372
0.129926523668316,61.2279656920049,0.41251671264690326,12.343557883508188,69.18310242565002,0.12215260730776743
0.130584519750792,61.0880058368383,0.41460585020876456,12.315341976706602,69.0651537415754,0.12273477309985714
0.131233627444141,60.9750568060059,0.4166667671351476,12.29257145209079,68.97703469427061,0.12330874294970938
0.13189242914098,60.7920511636351,0.4187584625226115,12.255677514588836,68.81006246406967,0.12389094800499661
0.132530385733954,60.6322848705721,0.42078397470530393,12.223468629907336,68.6679049724,0.12445440868527403
0.133156176741253,60.4261038665154,0.42277086115347823,12.181902539489505,68.47221283275043,0.1250068160955285
0.133801592102248,60.2495131769334,0.4248200549246374,12.146301856469773,68.31099396339245,0.12557622712497413
0.134467274363989,60.0805730321082,0.42693359610566506,12.112243523273012,68.15944392996236,0.12616317895479792
0.135145000806755,59.8335289982449,0.42908537756144716,12.062439446046172,67.91973132298371,0.12676039678827888
0.135832742178553,59.633738487167,0.43126895641690577,12.022161679012868,67.73395271223761,0.12736607546121792
0.136511282899993,59.4122812012514,0.4334233232074778,11.977515890172283,67.52272792804938,0.12796329202184353
0.137167184467776,59.2309420672432,0.4355058106851888,11.94095792075623,67.3554836239809,0.12854024394832825
0.137863463576806,59.1711600305405,0.43771649685635905,11.928905862156965,67.32870109620829,0.12915234922380517
0.138545474240651,59.0330569231898,0.4398818807140669,11.901064275715065,67.21181979048846,0.12975154796434812
0.139264595307584,58.8765731461195,0.4421650901015792,11.86951714625769,67.0759952784112,0.13038296240968644
0.139926288173597,58.7106214936106,0.4442659649511705,11.836061293111898,66.92578083557653,0.13096360081904396
0.140608754106462,58.5502875179236,0.44643279428801685,11.803737963613399,66.78297049839396,0.13156211471213056
0.141295545569814,58.3681810858411,0.4486133571841594,11.767025306905566,66.61534507628271,0.13216406062562655
0.141980942674089,58.1785558314823,0.4507894929902326,11.72879685562683,66.43880203185327,0.13276442341864858
0.142655549885162,57.9813286673865,0.4529313708853893,11.689035859345118,66.25268699150483,0.13335498321481445
0.143318494050939,57.7809251431899,0.45503621861173127,11.648634508867083,66.06200031958191,0.13393499346131818
0.143990016312366,57.5639721463119,0.457168301791762,11.60489678469648,65.85260943466393,0.13452216591984556
0.144630234529224,57.3505270055768,0.45920099463028613,11.561866244324284,65.64514717676798,0.13508164557429908
0.145291169574621,57.1258373881787,0.4612994633994216,11.516568817456825,65.42571711523681,0.1356589012500317
0.14594457167328,56.9022536482809,0.463374015062664,11.471494335493428,65.20682868422358,0.13622925034559485
0.14655507949334,56.6409581464223,0.4653123773913545,11.418817162318735,64.94197827015017,0.1367618635865014
0.147201340279724,56.3879064227221,0.4673642553881237,11.367801934820776,64.68828182371445,0.13732535916773522
0.147868046311356,56.1672976882511,0.46948104703855525,11.323327213951421,64.47264626400113,0.13790634905351465
0.148569649586319,55.9017226208715,0.47170863743656277,11.269787280367696,64.20702196192597,0.1385173852667294
0.149273457820215,55.6856404216905,0.47394322857918264,11.226225109012805,63.99802851836938,0.1391299669122183
0.149976444360727,55.4280884566008,0.47617521084530817,11.17430263285072,63.74099608103364,0.1397414590007906
0.15063835650249,55.1802397787865,0.47827678189540573,11.124336339403358,63.492500410476225,0.1403168809791057
0.151294865073003,54.9162396259236,0.4803611966067845,11.071113908586199,63.224784690444416,0.14088727857549077
0.15196821086679,54.6966679431267,0.4824990695020582,11.026848257334343,63.00882271081856,0.14147196715926852
0.152634150678385,54.4673059328125,0.4846134284038724,10.980608876055001,62.7808769136071,0.14204988883568612
0.153313308051051,54.3041087837843,0.4867697530620869,10.947708330810915,62.62965134219041,0.14263893728926869
0.153995182390272,54.0921418409157,0.48893470408911355,10.904975795128605,62.42207108958797,0.1432299933720567
0.154654257779822,53.8256733659306,0.4910272684509348,10.851255750571609,62.15004292983773,0.14380095524785044
0.155331109430605,53.5176413492556,0.4931762724421708,10.789156496009928,61.830595954144684,0.14438697772207137
0.155977530291112,53.2190438307349,0.49522865867428056,10.728959236276156,61.520018851907366,0.14494633259683973
0.156593328146189,52.9422107681806,0.4971838168641501,10.673149690865209,61.232607751787015,0.14547889821954066
0.15721488674838,52.6681049507279,0.49915726542610644,10.617889958066744,60.94831510580838,0.14601615849300742
0.157872123392744,52.4387882550973,0.5012439917719622,10.571659712227616,60.717411105071996,0.14658394420399082
0.158546407560028,52.0960011093615,0.5033848440030889,10.502553823647279,60.355634933494,0.14716612240479404
0.159206940633919,51.7952965687308,0.5054820365126927,10.441931788256129,60.041467274664946,0.14773609944077856
0.1598138495463,51.5170632887774,0.5074089723095025,10.385839959017524,59.750203490277286,0.1482595177118066
0.160455883340738,51.2323886988902,0.5094474296068431,10.328449561696264,59.45292688322666,0.1488129307928152
0.161116253895215,51.0264619060976,0.5115441061173076,10.286934720269276,59.247654297934936,0.14938183025684287
0.16179170733677,50.7349433127396,0.5136886707942447,10.228164571848303,58.943436412941985,0.1499633887790618
0.162455347607226,50.3796322066905,0.5157957286529425,10.156533852868805,58.564072869152604,0.1505344470812152
0.163073011068597,49.9765748399634,0.5177568101427955,10.07527748773662,58.12640538201131,0.15106564978497142
0.16367844923861,49.6212743906124,0.5196790763325867,10.00364891714746,57.74320763211139,0.15158606478760991
0.164310128718347,49.2502138864178,0.5216846586807516,9.928843119501828,57.34252286950123,0.1521287474289432
0.164951450152354,48.9293474105612,0.5237208542337239,9.864156437969138,57.00031422094159,0.152679412460325
0.165549020913338,48.6136753793386,0.5256181413998482,9.800516956474663,56.66162174138696,0.15319223859488246
0.166150732896677,48.291981064611,0.5275285769469494,9.735663382625578,56.31572911152856,0.15370835306949465
0.166751545004501,48.0017686124596,0.5294361553892907,9.677156552271855,56.0061376915358,0.1542234300418981
0.167374258363632,47.6978482313495,0.5314132703045316,9.61588620344006,55.68124020461269,0.15475700314494703
0.168011178490568,47.3582772739378,0.5334354917075533,9.547428698425861,55.314997250015175,0.15530245498572348
0.168663911051747,46.9275838477584,0.5355079175892967,9.460600903708094,54.842573675730115,0.15586113991464515
0.169273623948225,46.5200251644853,0.5374437560356143,9.378437073160237,54.39463841024035,0.1563827217800056
0.169926437969414,46.1472147166227,0.5395164405528894,9.303278486871136,53.98884653562812,0.15694087330262618
0.17057381210702,45.7818227378274,0.5415718534397884,9.229615463946002,53.59100276742646,0.15749406628271148
0.17120023158308,45.4652450769998,0.543560735276279,9.165793407523159,53.24890556316365,0.15802906195634547
0.171841070912553,45.0555260881262,0.5455954001473557,9.083194059366242,52.79791594163828,0.1585760769362095
0.172512021238671,44.6375905952845,0.5477256674327804,8.998938264009356,52.338111572101326,0.15914847394132225
0.173147610460392,44.205481741404,0.5497436632117446,8.911825119067046,51.85955527417859,0.15969040187382097
0.173815430728069,43.7830402677344,0.551863992561619,8.826660917975255,51.39320827045505,0.16025949501587802
0.174426061283464,43.2936658441484,0.5538027445749981,8.728003034180317,50.84520945586564,0.16077956977925803
0.175033569187237,42.832605065767,0.5557315821694775,8.635053181258627,50.329748808015516,0.16129671670907397
0.175651315369851,42.3577121462306,0.5576929262992769,8.53931476868009,49.79790000077351,0.16182230497561959
0.17625444478492,41.8938893382732,0.559607862192121,8.445808090595877,49.277873543471415,0.16233519068601515
0.176913030485363,41.3986004946754,0.5616988717910275,8.34595785972656,48.72255236604127,0.1628949347115123
0.17756893517563,40.8939896016428,0.5637813691826252,8.24422830369119,48.1554917902898,0.1634520888683929
0.178211417322456,40.3888554078134,0.5658212499987977,8.142393250215182,47.58661057407157,0.16399754053758092
0.178762923888734,39.9067752252873,0.5675722833467304,8.04520588541792,47.04062704753015,0.16446551896797804
0.17932211650453,39.364591202236,0.5693477199018827,7.935901586370777,46.42353301195656,0.16493979586359392
0.179932736319703,38.770761784459,0.571286437815057,7.816185575746934,45.746891041536074,0.16545743373393806
0.180632820429233,38.1672852247106,0.5735092048628148,7.694524701301656,45.06154960297707,0.1660505832256387
0.181482239622017,37.5319090566583,0.576206110799904,7.566432865822313,44.34328396955051,0.16676978547261065
0.182435188470757,36.7892434182651,0.5792317233946535,7.416711473122245,43.50089597497285,0.1675760309776656
0.183416591692104,36.1098636092584,0.5823476786224302,7.279748503626493,42.73301171893531,0.1684056715205499
0.184306279652441,35.3636791101794,0.5851724378965002,7.1293177086121675,41.88142724179931,0.1691571851482444
0.185078875564886,34.5257182416452,0.5876254299185131,6.9603847975156725,40.91569935187897,0.1698093340300973
0.185762331953013,33.5210219315247,0.5897954039508163,6.75783802139538,39.74796513497282,0.17038588585051634
0.186430227352684,31.8577936974607,0.5919159718447716,6.422531209408077,37.7970494194332,0.17094898973067915
0.186922663676813,30.1263623847453,0.5934794571738813,6.0734746567646525,35.75766228859484,0.1713639607474689
0.187267644094002,28.8453032520501,0.5945747699984564,5.815213135613301,34.247095235238575,0.17165456964978618