File: example/data/02 processed data/test_ID_102.csv
Strain,Stress_MPa,Displacement(mm),Force(kN),True Stress (MPa),True Strain
2.8208412569231e-05,-0.0491197758968568,8.956170990730843e-05,-0.009902546820806333,-0.04912116148776061,2.820801471955354e-05
-3.5743546758938e-05,0.961693922815084,-0.00011348576095962813,0.19387749483952096,0.9616595484633861,-3.5744185574738284e-05
-0.0001728416387348,2.78968568046829,-0.0005487722029829899,0.5624006331824073,2.789203506623723,-0.00017285657757220026
-0.0001965304351557,4.69729010284688,-0.0006239841316193475,0.946973684733931,4.696366942378916,-0.0001965497497922838
-0.0002646208743927,7.19682449373746,-0.0008401712761968224,1.450879817937472,7.194920063747077,-0.00026465589267414866
-0.0003101063242348,9.75093543005751,-0.00098458757944549,1.965788582699594,9.747911603313444,-0.0003101544171438147
-0.0002934687268386,12.3838629334283,-0.000931763207712555,2.4965867673791453,12.380228656939885,-0.0002935117972121134
-0.0003248630859217,15.3539040797919,-0.0010314402978013975,3.095347062486047,15.348916163131593,-0.0003249158653650581
-0.0002628687384824,18.5153094449297,-0.0008346082446816199,3.7326863840978275,18.5104423488933,-0.0002629032945251286
-0.0002193437963143,21.7148603864856,-0.0006964165532979024,4.377715853915497,21.710097366571993,-0.00021936785568301253
-0.0002106916080865,24.9823871516898,-0.0006689458556746375,5.036449249780664,24.97712357236697,-0.0002107138066814629
-0.0001678086961928,28.4143074850908,-0.0005327926104121399,5.728324388994305,28.409539317198504,-0.00016782277764742517
-6.60144195933083e-05,32.1262966079638,-0.00020959578220875383,6.476661396165503,32.124175809139544,-6.601659864100436e-05
-1.56472058604737e-05,35.7883400218093,-4.967987860700399e-05,7.214929348396754,35.787780034285575,-1.5647328279249953e-05
4.44747623564421e-05,39.3905547259012,0.00014120737048170366,7.941135832741682,39.39230661146172,4.4473773383551745e-05
0.0001013692844562,42.9696497934672,0.00032184747814843496,8.662681398362988,42.9740055961201,0.0001013641469375267
0.0001791195475984,46.6316564770088,0.0005687045636249199,9.400941945764973,46.640009118220725,0.00017910350760760583
0.0002576291284065,50.38756920142,0.0008179724826906375,10.158133951006272,50.40055050695588,0.0002575959477212835
0.0003551084496884,54.0945044877782,0.0011274693277606698,10.905452104736087,54.11371390340352,0.00035504541360558155
0.0004217251433915,57.619443381911,0.0013389773302680125,11.616079785793257,57.643742949933376,0.0004216362423369378
0.0004749419362544,61.2409387566499,0.00150794064760772,12.346173253340622,61.27002464668102,0.000474829187031151
0.0005425831016515,64.7512373632503,0.0017227013477435122,13.05384945243126,64.78637029045461,0.0005424359566635349
0.0006192165729138,68.0830208188408,0.0019660126190013147,13.725536997078304,68.12517895366585,0.0006190249374368259
0.0007034050371458,71.2752363070598,0.002233310992937915,14.369087639503254,71.32537166730194,0.0007031577637713438
0.0007675414004962,74.7698925062781,0.002436943946575435,15.073610329265664,74.82728149428732,0.0007672469912333369
0.0008172713879206,78.0941363862002,0.002594836656647905,15.743777895457962,78.15796048943302,0.0008169376035091438
0.0008972235875756,81.5213014909586,0.00284868489055253,16.434694380577255,81.59444432554615,0.0008968213230885822
0.0009800087159099,85.0093285510863,0.0031115276730139326,17.137880635899,85.09263843400002,0.0009795288208769627
0.0010351894577788,88.4995960489325,0.00328672652844769,17.841518563464792,88.59120989778003,0.0010346540186607085
0.0010974125385947,91.9542828379881,0.003484284810038172,18.5379834201384,92.055194620952,0.0010968108216357336
0.0011875024272055,95.1392071708833,0.003770320206377462,19.180064165650073,95.25218521032112,0.0011867979038917395
0.0012649223276121,98.3604379843772,0.004016128390168417,19.829464297650443,98.48485629853734,0.0012641229873624293
0.0013442249383364,101.791863804397,0.00426791417921807,20.521239742966436,101.92869496624262,0.001343322276823519
0.0014198280029875,105.141570777567,0.004507953909485312,21.196540668757507,105.29085372403509,0.001418821000276271
0.0015018509816207,108.405327208732,0.004768376866645723,21.854513965280372,108.56813585581335,0.0015007243313346955
0.0015792948787281,111.685023626069,0.005014261239961717,22.515700763015513,111.86140721191228,0.0015780491040290367
0.0016454888587902,114.882627133241,0.005224427126658885,23.160337630061385,115.0716652162573,0.0016441365252945876
0.0016974229321185,118.091381311587,0.005389317809476237,23.807222472415937,118.29183233031084,0.0016959839379709033
0.0017828989767464,121.240341499816,0.005660704251169819,24.442052846362905,121.4565007806164,0.0017813114989606233
0.0018071897755153,124.420750696766,0.005737827537261078,25.083223340468027,124.64560260528712,0.0018055587727981415
0.0018879529285615,127.443171773893,0.005994250548182763,25.69254342961683,127.6837784832687,0.0018861729853785411
0.0019451534643234,130.533894181156,0.006175862249226795,26.315633066921052,130.7878026376341,0.0019432641029918751
0.0020092985123128,133.637710150184,0.006379522776593139,26.941362366277094,133.90622820237766,0.002007282572022544
0.002118473224363,136.64907412342,0.006726152487352525,27.548453343281473,136.93856152808448,0.002116232424120731
0.0021586566449193,139.703696230579,0.006853734847618777,28.164265160084728,140.0052685427669,0.00215633009321315
0.0022119338044829,142.525471166964,0.007022889829233207,28.73313498725994,142.84072807463804,0.002209491080337996
0.0022925180893948,145.220390415024,0.0072787449338284895,29.276430707668844,145.55331078699945,0.0022898942791229763
0.0023667373329945,148.022568404347,0.0075143910322575365,29.841349790316354,148.3728989431153,0.0023639410214137506
0.0024200186803367,150.994208237192,0.007683559310069022,30.44043238061791,151.35961704174866,0.0024170951508441247
0.0024695135513344,153.826415118195,0.00784070552548672,31.01140528782811,154.20629153488258,0.0024664693135718467
0.00253587125267,156.678036023014,0.008051391227227249,31.58629206223962,157.07535135048954,0.002532661356608456
0.0025932602678508,159.314814904574,0.00823360135042629,32.11786668476212,159.72795968414607,0.0025899035703835682
0.0026659638447626,162.26626439013,0.008464435207121255,32.71287890105021,162.6988603842188,0.002662416466541144
0.0027234429748448,165.234041382398,0.008646931445132238,33.31118274269144,165.6840468716061,0.002719741123690049
0.0027773951035929,167.973331629263,0.008818229453907457,33.86342365645942,168.4398599380643,0.002773545268506918
0.0028276484239227,170.535628309625,0.008977783745954572,34.3799826672204,171.01784311023738,0.002823658146416157
0.0028894399144343,173.157545176106,0.009173971728328902,34.90856110750297,173.6578734986233,0.002885273506718447
0.0029456955057835,175.911705274904,0.009352583230862611,35.46379978342065,176.429887594547,0.0029413654460514536
0.0030186354652372,178.689328707714,0.009584167602128109,36.023768667475146,179.22872665261053,0.003014088533256614
0.0030901028202392,181.467125200418,0.009811076454259458,36.58377244040427,182.02787727578053,0.0030853382653058124
0.0031574750949139,184.311907175949,0.010024983426351632,37.15728048667132,184.89386743255312,0.003152500738613338
0.0032160492715091,187.020854613691,0.010210956437041391,37.703404290120105,187.62232289692838,0.0032108888462120057
0.0032696483801607,189.749321722369,0.01038113360701022,38.25346325922959,190.36973528477512,0.003264314702899563
0.0033408671781702,192.47152257786,0.010607253290690384,38.80225895169657,193.1145443703728,0.003335298879935763
0.0034103376826912,195.292044884224,0.010827822142544559,39.370876248659556,195.9580567040225,0.0034045356686123796
0.0034494934538643,198.057281702795,0.010952141716019152,39.928347991283474,198.74047899951893,0.0034435575978676632
0.0035002249451051,200.718526845649,0.011113214200708692,40.46485501208284,201.42108684025888,0.003494113414773801
0.0035888188307828,203.553473997314,0.01139449978773539,41.036380357858505,204.28399053786683,0.0035823943866719918
0.003630342205225,206.369202809024,0.011526336501589374,41.60403128629923,207.11839363584025,0.0036237684182218685
0.0036948514604504,208.820576583661,0.011731153386930019,42.09822823926606,209.59213759602324,0.00368804226428444
0.0037640987985961,211.390893959177,0.011951013685542616,42.61640422217009,212.18659016916288,0.003757032305813456
0.0038156523034567,214.082499801346,0.012114696063475022,43.159031959951356,214.89936418484277,0.00380839116699311
0.0038982975770999,216.805692565029,0.012377094807292183,43.70802762110985,217.6508656710567,0.0038907189046618125
0.0039540971782424,219.161655812879,0.01255425854091962,44.1829898118764,220.0282422977076,0.003946300282359361
0.0040158070920138,221.703380277448,0.012750187517143814,44.695401463933514,222.5936982842896,0.004007765261151728
0.0040854015957001,224.59035905527,0.012971150066347817,45.27741638554243,225.50790086653328,0.004077079002324883
0.0041611916371167,226.939124984224,0.013211783447845522,45.75092759681956,227.88346217324295,0.004152557822214759
0.0042397475851051,229.116814076188,0.013461198582708693,46.189949717759504,230.08821153537448,0.0042307851786098595
0.0043297308079882,231.465104743506,0.013746895315362535,46.663365116290805,232.46728633848818,0.004320384491863692
0.0044085404055436,233.514746074629,0.01399711578760093,47.0765728086452,234.54420526798924,0.004398851257519815
0.0044842656135834,235.32021158015,0.014237543323127292,47.440554654558234,236.37544991312004,0.004474241251300334
0.004613121982034,237.105271786945,0.014646662292957947,47.80042279224811,238.1990673282815,0.004602514145807847
0.0047561879331103,238.711093144917,0.015100896687625202,48.12415637801527,239.84644796563242,0.004744913007592169
0.0049371831909329,239.864322589045,0.015675556631211958,48.35664743395148,241.04857669063614,0.004925035269935669
0.0051548001549471,240.627825760275,0.016366490491957042,48.51056967327144,241.86821411378864,0.005141559654558316
0.0053765660017356,240.815508351861,0.017070597055510527,48.54840648373518,242.11026882675628,0.005362163870359991
0.0056402957618016,241.10099190058,0.01790793904372008,48.605959967156934,242.460872803363,0.005624448853238441
0.0059017766807357,240.727458229687,0.018738140961335845,48.530655579104895,242.14817792907974,0.0058844294163984835
0.0061804902255236,240.539042488569,0.01962305646603743,48.49267096569552,242.0256916895264,0.006161469327891863
0.0064927210020683,240.561872731462,0.020614389181566852,48.49727354266273,242.12377385484243,0.0064717340815613495
0.0067756284226843,240.520156874506,0.02151262024202265,48.488863625900414,242.1498320856534,0.006752777016110094
0.007086873780632,240.37558263003,0.022500824253506597,48.45971745821406,242.0790940440749,0.00706187990678442
0.0073907544350187,240.318156842094,0.023465645331184372,48.448140419366155,242.0942893255902,0.007363576636929608
0.007696847761311,240.023898091282,0.024437491642162423,48.388817855202454,241.87132549396705,0.0076673781474078774
0.0080089255827139,239.945228366287,0.02542833872511663,48.37295803864347,241.86693184419988,0.007977024354729629
0.0083199182185505,239.899922597077,0.026415740343897834,48.36382439557072,241.89587033372126,0.0082854984801272
0.008651797199683,239.848747562773,0.027469456108993526,48.35350750865504,241.92387028528407,0.008614584883858684
0.0089575832303469,240.008883186313,0.028440326756351404,48.3857908503607,242.15878273347698,0.008917702063993936
0.0092515422230855,239.952815818007,0.02937364655829646,48.37448766891021,242.17274942509553,0.009209008838014572
0.0095664586280286,239.786932123542,0.030373506143990803,48.34104551610607,242.08084388924377,0.009520989816354089
0.0098813805118138,239.626902004634,0.031373383125008814,48.308783444134214,241.9947466042089,0.00983287891815154
0.0101995899996027,239.67463099232,0.03238369824873857,48.31840560805172,242.11921396174776,0.010147925191113898
0.010542322243721,239.679843624072,0.03347187312381417,48.31945647461292,242.20662577088163,0.010487139462197355
0.0108390810840196,239.7218968932,0.03441408244176223,48.32793441366913,242.32026197124037,0.010780759302512433
0.0111603471036709,239.886213201102,0.035434102054155106,48.361060581342166,242.56342660581151,0.011098529938721551
0.0114854788803874,239.820544373016,0.03646639544523,48.34782174560002,242.57499817049526,0.011420021497292895
0.011797788626638,239.699185707154,0.037457978889575645,48.32335583856225,242.52710603410426,0.011728737289833355
0.0121160171083635,239.629318937796,0.03846835431905411,48.309270697859674,242.53267186571182,0.012043205705875675
0.0124512527300504,239.652780276973,0.039532727417910016,48.31400050383776,242.63675761166084,0.012374373387725646
0.0127682195811156,239.525493751681,0.040539097170042025,48.288339540338896,242.58380785117762,0.012687393144830333
0.0130630619975376,239.457917544241,0.04147522184218188,48.27471617691899,242.5859711669227,0.012978476041204631
0.0133943040747324,239.508133933443,0.04252691543727537,48.28483980098211,242.71617870771925,0.01330539343477108
0.0137098833330754,239.527989180035,0.04352887958251439,48.288842618695064,242.81188996669943,0.013616753120033185
0.0140125515690783,239.557606708143,0.0444898512318236,48.29481351236163,242.91442002590583,0.013915283365634013
0.0143384467709161,239.500580251438,0.04552456849765861,48.2833169786899,242.93464657297676,0.014236623414677503
0.0146491075255104,239.615893441739,0.04651091639349552,48.30656411785458,243.12605242958827,0.014542845851936109
0.0149658151807075,239.647724208142,0.047516463198746306,48.31298120036143,243.2342477571182,0.014854932301660632
0.0153110002461034,239.742263245138,0.04861242578137829,48.33204027021982,243.4129570966857,0.01519496974492857
0.0156203915083043,239.596583212696,0.04959474303886615,48.302671175679514,243.33917564653035,0.015499648933847003
0.0159177644648552,239.574105042432,0.05053890217591526,48.2981395765543,243.3875892183759,0.01579240539308485
0.0162202546016756,239.478659194392,0.05149930836032003,48.278897693589435,243.36306401819297,0.01609011168686656
0.0165380736393292,239.463498048985,0.05250838380487021,48.27584120667538,243.4237630136505,0.016402809006393276
0.0168304312587217,239.575072474309,0.05343661924644139,48.298334610820696,243.60722426289112,0.016690368905843737
0.0171421251124197,239.674589385752,0.05442624723193255,48.31839722016761,243.7831211832704,0.01699685667546636
0.0174543429357618,239.767002767229,0.05541753882104371,48.337027757873365,243.951978258208,0.017303765520238282
0.0177721639581705,239.83550684231,0.05642662056719133,48.35083817940969,244.09790279290246,0.01761608557298477
0.0180982694601294,239.759883880198,0.05746200553591084,48.33559259024792,244.09912286439118,0.017936445355606578
0.0184130020505734,239.651617968668,0.05846128151057054,48.31376618248347,244.06432370174835,0.018245535314844803
0.0187245296469773,239.650608613582,0.05945038162915292,48.31356269649813,244.13795353948316,0.0185513836868717
0.0190327531657179,239.77727411176,0.06042899130115433,48.33909846093082,244.34089578467783,0.018853896183027005
0.0193493409087301,239.72580575748,0.06143415738521807,48.32872244070797,244.36434209770152,0.01916452268085404
0.0196300846709356,239.691674534143,0.06232551883022053,48.32184158608323,244.39684240016658,0.019439899431063026
0.0199346331610208,239.69154325497,0.06329246028624104,48.32181512020195,244.46970624155676,0.01973854010638556
0.0202634637729306,239.865676607372,0.06433649747905465,48.3569204040462,244.726186055675,0.020060891759640594
0.0205705431546343,239.901388136206,0.06531147451596389,48.364119848259136,244.8362899937185,0.020361826948861093
0.0208934041407987,239.947124140765,0.06633655814703587,48.373340226778225,244.9604363778604,0.020678130344063173
0.0211994653511732,239.994457707731,0.06730830248997491,48.38288267387857,245.08221189837963,0.020977882835478783
0.0214974534807866,239.997589108633,0.06825441480149745,48.38351396430042,245.15692611599678,0.02126964235102911
0.0218409014769532,239.999291130757,0.0693448621893264,48.38385709196061,245.24109200288245,0.02160580596149293
0.0221529734265519,239.982150839414,0.07033569062930228,48.38040160922586,245.29846904980633,0.02191116103701965
0.0224524803168183,240.014461822878,0.07128662500589811,48.386915503492204,245.40338180270788,0.022204133837087456
0.0227632148989362,240.059635837954,0.07227320730412243,48.39602258493153,245.52416491709374,0.022507998691279493
0.0230802402244204,239.87936057711,0.07327976271253477,48.35967909234538,245.41583384411004,0.022817920085536413
0.0234128961602858,239.928421465781,0.07433594530890741,48.36956976750145,245.54584068346063,0.023143018599556257
0.0237036119062879,239.877132567533,0.07525896780246408,48.359229925614656,245.563087023107,0.023427043223275455
0.0240074000814233,239.846489963136,0.07622349525851897,48.35305237656822,245.60458060580606,0.023723753233218847
0.0243298916125202,239.908877587675,0.07724740586975164,48.365629721675276,245.7458345762645,0.0240386345128493
0.0246553853583931,239.956990834503,0.07828084851289809,48.3753293522358,245.87322291296806,0.024356346652872018
0.0249565211013145,239.956337937517,0.07923695449667353,48.37519772820343,245.94481334864878,0.0246501932529422
0.025266256626904,239.957967385628,0.08022036479042019,48.375526224942604,246.02080696926353,0.0249523414207516
0.0255840041302745,239.973333413304,0.08122921311362154,48.37862401612209,246.11281216650568,0.02526221046579402
0.0258907325141935,239.981024849781,0.08220307573256436,48.38017460971585,246.1943093726487,0.02556124255302942
0.0262023238106591,239.931241640685,0.08319237809884264,48.3701383147621,246.2179977264477,0.025864924004413693
0.0265093537747371,239.772668559106,0.08416719823479028,48.33816998151577,246.12888705545214,0.026164069734152955
0.0268032529621117,239.682525917848,0.08510032815470464,48.31999722503816,246.10679729062196,0.026450338067983116
0.0271186236680601,239.750203402768,0.08610163014609082,48.333641005998025,246.2518989431885,0.026757429308419477
0.0274259290628532,239.843312886834,0.0870773247745589,48.352411877985745,246.421238572268,0.027056576286445623
0.0277586386488882,239.910149342786,0.08813367771022003,48.36588610750566,246.5697284865932,0.02738035215958971
0.0280488520144514,239.855749783593,0.08905510514588319,48.354919156372354,246.58342821408831,0.0276626873187028
0.0283746577165316,239.799578810498,0.09008953824998782,48.3435950881964,246.6038097798143,0.027979553667744607
0.0286942586232362,239.825460835028,0.09110427112877492,48.34881290434165,246.7070746326651,0.028290287942845962
0.029004868876925,239.891136423389,0.09209045868423688,48.36205310295522,246.84914738008595,0.028592188499537638
0.0293120478718621,239.842663773704,0.09306575199316217,48.352281016778726,246.87294341595373,0.02889066439964599
0.0296150877807797,239.876677808373,0.09402790370397554,48.359138246167994,246.98064667822976,0.029185031214147037
0.029928282538277,239.862328988469,0.09502229705902947,48.35624552407535,247.04099654072502,0.029489171213746043
0.030250583132351,239.83138005017,0.09604560144521442,48.35000621811427,247.08641915012413,0.029802057247161853
0.0305630015212417,239.738937442769,0.09703752982994239,48.331369788462226,247.0660789525332,0.030105256326991896
0.0308657360230871,239.733374669896,0.09799871187330153,48.33024833345104,247.13292172838084,0.030398969612838823
0.0311752885850068,239.664997029388,0.09898154125739658,48.31646340112462,247.13662247550394,0.030699208609590935
0.0314967022055648,239.629817203368,0.10000202950266825,48.30937114819899,247.1773661953964,0.031010856437839456
0.0317989147018802,239.676053167525,0.10096155417846962,48.31869231857304,247.29749153828243,0.03130379797854763
0.0321332445128469,239.747270804636,0.10202305132828891,48.333049794214624,247.45112847868907,0.03162777162506326
0.0324469020184738,239.680951106064,0.10301891390865431,48.3196797429825,247.45785544229707,0.03193161791416681
0.0327610473477749,239.656824156784,0.1040163253291853,48.314815750007654,247.50823272020176,0.03223584425788228
0.0330827570584072,239.676019397811,0.10503775366044285,48.3186855105987,247.60516292027484,0.03254730024748491
0.0334097157264146,239.739826537774,0.10607584743136636,48.33154903001524,247.749465990701,0.0328637385360746
0.033701762523918,239.612150275459,0.10700309601343966,48.30580949553253,247.68750206188787,0.03314630365413368
0.0340236972026622,239.652823925873,0.10802523861845248,48.314009303456,247.80669904088984,0.03345769381459347
0.0343381997608037,239.543846538856,0.10902378424055173,48.29203946223337,247.76935099277853,0.03376180167988242
0.0346608669496977,239.551130633095,0.11004825256529019,48.29350793563195,247.85418049961837,0.03407370824059729
0.0349665075778983,239.512377550115,0.11101866155982709,48.28569531410319,247.8872889147215,0.03436906636562419
0.0353013796938748,239.416201513132,0.11208188052805249,48.26630622504741,247.8679237476123,0.03469257244032686
0.0356409890245101,239.431106559661,0.11316014015281955,48.269311082427656,247.9646680006802,0.03502054808929656
0.0359542219121727,239.427125786311,0.11415465457114832,48.268508558520296,248.0355417986257,0.03532295551753923
0.0362689704744755,239.373522467281,0.1151539812564597,48.25770212940385,248.05535368601798,0.03562673415092156
0.0365486062570618,239.159809315083,0.1160418248661712,48.21461755792074,247.90076701825393,0.03589654639819479
0.0368516951489487,239.036222307171,0.1170041320979121,48.18970241712567,247.84511230119116,0.036188905663157016
0.0371440891447937,239.081424424097,0.11793248303472,48.19881516389796,247.9618861657699,0.03647086766134088
0.0374704685638013,239.187122159105,0.11896873769006912,48.220123827275565,248.14957570083382,0.03678550868271758
0.0377941284050539,239.20257141575,0.11999635768604613,48.2232383974152,248.2430241146559,0.03709743020284523
0.038100955387589,239.10408428271,0.12097053335559507,48.20338339139434,248.21417833095586,0.037393039539911556
0.0384083075642212,239.185188245272,0.1219463765164023,48.21973395024684,248.37188652020257,0.03768906728643817
0.0387370523640244,239.123573017863,0.12299014125577747,48.20731232040118,248.3865153873286,0.03800560247833201
0.0390582351374755,239.051314963228,0.1240098965614847,48.19274509658677,248.38823743298448,0.03831475976436614
0.0393628145683729,239.140203755398,0.12497693625458395,48.210665077088244,248.55343525166464,0.03860784708959385
0.0396780061746561,239.073781512784,0.1259776696045331,48.19727435297726,248.5597524918466,0.03891105576693502
0.0400120833811397,239.029207626545,0.12703836473511854,48.18828825751148,248.59326421262608,0.039232331721496726
0.0403371636889722,239.01620167922,0.12807049471248674,48.185666258530745,248.6574373306711,0.03954485646794137
0.0406700998387858,239.000469472577,0.1291275669881449,48.182494645671525,248.72064242754342,0.039864832431975146
0.0409921973679189,238.976084524575,0.1301502266431425,48.177578640154316,248.7722393476188,0.04017429428093658
0.0413221762806638,238.981343338351,0.13119790969110756,48.17863881701156,248.85657253556815,0.04049122905282584
0.0416283705196131,238.918778110127,0.13217007639977157,48.166025667001605,248.86457752938855,0.04078522954326012
0.0419474928074687,238.888020755194,0.13318328966371312,48.15982498424711,248.90877428761294,0.04109155128173675
0.0422093431104976,238.920129326185,0.13401466437582987,48.166298072158895,249.00479104091838,0.04134282824889566
0.0425498869907286,238.930601499985,0.13509589119556328,48.16840926239697,249.09707159243615,0.041669526774406884
0.0428729678784192,238.804681373665,0.13612167301398095,48.14302376493087,249.04294680741427,0.04197937366183411
0.0431986947150279,238.819763058127,0.13715585572021358,48.146064232518405,249.1364650943903,0.0422916609577085
0.0435439180637273,238.723731630883,0.13825193985233417,48.12670429678601,249.1186982408854,0.042622533917061514
0.0438610822941827,238.533065699517,0.13925893628403008,48.08826604502263,248.99538412404723,0.04292641767018244
0.0441840220736803,238.410722645676,0.14028427008393496,48.06360168536828,248.94466727765462,0.04323574028145829
0.0445235647957084,238.395103020582,0.14136231822637416,48.06045276894934,249.00930283689846,0.04356086259839105
0.0448668747905289,238.467646874978,0.14245232745992925,48.07507760999556,249.16694492890971,0.043889484756706516
0.0452023099501449,238.398654128535,0.14351733409171005,48.061168672312654,249.1748239841504,0.04421046471750856
0.0455185236452746,238.231046627076,0.14452131257374687,48.02737900001853,249.0749721560091,0.04451295722866527
0.0458400266186664,238.185202093968,0.1455420845142658,48.01813674214395,249.10361809812795,0.04482041572341638
0.046211453424298,238.289771749515,0.14672136462214613,48.039217984702226,249.30148843820436,0.04517549953763169
0.0465236602575862,238.170511888053,0.14771262131783616,48.01517519663148,249.2510758665082,0.045473871590131984
0.0468832118507158,238.185385175535,0.14885419762602264,48.01817365138786,249.35228104846396,0.04581738015643667
0.0471757440101028,238.099716491117,0.1497829872320764,48.00090284460919,249.33224776518,0.04609677263530757
0.0474942908288746,237.998609711633,0.15079437338167687,47.98051971786522,249.30218489814516,0.0464009225166057
0.0478363484081662,238.077202492974,0.1518804061959277,47.996364022583556,249.46594649946948,0.04672741760613941
0.0481854712804865,238.068136329879,0.15298887131554464,47.99453628410361,249.53956167580134,0.04706054665305054
0.048496875990646,238.102680515824,0.15397758127030103,48.00150039199012,249.6499166858403,0.047357591851961464
0.048821813005012,238.084363334879,0.1550092562909131,47.9978076483116,249.70807360103177,0.04766745131077508
0.0491824625356705,238.033027811311,0.15615431855075382,47.9874584067603,249.740078283893,0.048011253788601736
0.0494934221413166,238.034589419183,0.1571416152986802,47.987773226907294,249.81573583754158,0.04830759264701443
0.0498164241649857,237.952356142261,0.1581671467238296,47.97119499827982,249.80629164690163,0.048615314755579044
0.0500784585923591,237.808901950408,0.15899910603074013,47.94227463320225,249.71800519962588,0.04886488384676076
0.0504113800397927,237.780773345334,0.16005613162634183,47.93660390641934,249.76763027660147,0.049181877953657555
0.0507457698628161,237.660582924786,0.1611178193144411,47.912373517636865,249.72085217134995,0.04950016906849591
0.0510732873817636,237.659325323507,0.16215768743709943,47.912119985219014,249.79736834471055,0.049811820559588285
0.0514311657870313,237.646461500293,0.16329395137382438,47.90952663845906,249.8688960604159,0.05015225114291904
0.0517799159248387,237.596295805243,0.16440123306136287,47.89941323433699,249.89901202609155,0.050483887034376916
0.0521154487084861,237.53067580313,0.16546654964944335,47.88618424191102,249.90969355464006,0.05080285041262512
0.0524505179129287,237.512695147763,0.1665303943735486,47.88255934178902,249.9703590191587,0.05112127160976309
0.0528004149360464,237.340691678031,0.1676413174219473,47.84788344229105,249.87237867983927,0.05145367571502189
0.0531436580866511,237.296027691723,0.16873111442511723,47.838879182651354,249.9068066526924,0.05177965127917969
0.0534957893581679,237.143248704773,0.16984913121218306,47.80807893888224,249.82941398519517,0.05211395744174921
0.0538355265722687,236.953748865566,0.1709277968669531,47.76987577129811,249.71027870901688,0.052436391047206356
0.0541579385482901,236.986705969907,0.17195145489082106,47.77651992353325,249.82141742858695,0.052742285713266966
0.0545049502590308,236.870278822314,0.17305321707242277,47.7530482105785,249.780881587367,0.05307141533916891
0.0548422113976993,236.886536145647,0.17412402118769527,47.756325686962434,249.87791763821534,0.05339119308621134
0.0551843189835646,236.938774268939,0.1752102127728176,47.76685689261811,250.01407916777094,0.05371546160505416
0.055504893986835,236.933597433402,0.17622803840820112,47.76581324257385,250.08457164086244,0.054019224948103885
0.055836920689506,236.9460867975,0.17728222318918155,47.768331098376,250.1764266537008,0.05433374219310895
0.0561693271866613,236.924193668151,0.17833761381764962,47.76391744349924,250.23206622073326,0.054648520144390346
0.0565514679562375,236.86885618798,0.17955091076105406,47.75276140749676,250.26413771852518,0.05501027241626862
0.056921915113185,236.819693736853,0.18072708048436237,47.742850257349566,250.29992424087263,0.05536083009417338
0.0572703741363883,236.773259112413,0.18183343788303286,47.73348903706246,250.3333522472729,0.05569046806336894
0.057610996751117,236.628166194882,0.18291491468479645,47.704238304888214,250.2605507087581,0.056012587897003877
0.0579636828170712,236.377512457717,0.18403469294420105,47.65370651147575,250.07882361490437,0.05634600658709091
0.0583149691444326,236.342108276034,0.1851500270335735,47.64656902844846,250.1243910276811,0.05667799153648534
0.0586356033888071,236.269850648864,0.18616804075946253,47.63200189081099,250.1236759042435,0.056980912399151096
0.0589863443486455,236.292287845841,0.18728164330694944,47.63652522972155,250.23030610364506,0.057312171681215586
0.0593576088952461,236.249930237646,0.18846040824240634,47.627985935909436,250.27316119822137,0.05766269506985918
0.0597295801847564,236.226587306203,0.18964141708660157,47.62328000093053,250.3363021944802,0.058013762543861674
0.0600533606513276,236.201523401699,0.19066942006796514,47.61822711778252,250.38621867293423,0.05831924709405007
0.060413996696311,236.167441954256,0.19181443951078742,47.61135629797801,250.43526101225666,0.05865939479517925
0.0607874086086752,236.108717100961,0.19300002233254376,47.59951736755374,250.46115416344722,0.05901147066622814
0.0611624088724183,236.103327372149,0.1941906481699281,47.598430798225245,250.54397561702282,0.05936491942788843
0.0615044225553353,236.025011572131,0.19527654161318958,47.58264233294162,250.5415936174913,0.05968716847876442
0.0618576213967939,235.756497772153,0.19639794793482063,47.528509950866045,250.33983395317694,0.06001984735067135
0.0622247437819948,235.610703432473,0.1975635615078335,47.499117811986565,250.27151908585418,0.06036552357761526
0.0625562008660337,235.524939597569,0.19861593774965697,47.48182782286991,250.25848502799496,0.06067751535028476
0.0629231958428443,235.476624302405,0.19978114680103062,47.47208745936485,250.2935660497971,0.06102284448499755
0.0632745012097146,235.478688719641,0.20089654134084386,47.472503645879634,250.37848529389396,0.06135329858205007
0.063634688484226,235.450605964119,0.20204013593741754,47.46684216236639,250.43343192806796,0.061691994074739555
0.0640172903762532,235.363277988219,0.20325489694460389,47.44923684242495,250.43059729909766,0.062051641141038553
0.0643839248645819,235.357592406308,0.20441896144504754,47.4480906291117,250.5108379521046,0.06239615747501698
0.0647348726205959,235.393054074083,0.205533220570392,47.45523970133513,250.6311934453418,0.062725822273061
0.0651127495551396,235.367799694455,0.20673297983756822,47.45014841840212,250.6932442893043,0.0630806616846454
0.0654824481508731,235.361706485329,0.2079067728790221,47.44892002744233,250.77376722695556,0.06342769954509116
0.0658701305548307,235.193566473623,0.20913766451158744,47.4150230010824,250.68579740289678,0.06379148957411442
0.0662377636323536,235.058923929191,0.2103048995327227,47.38787906412491,250.62870137208816,0.06413634368038994
0.0665899539573751,234.86539167256,0.21142310381466595,47.3488629611881,250.50506729021666,0.06446660038637511
0.0669538890086241,234.798676553268,0.2125785976023815,47.33541319313883,250.51936108258732,0.06480775583624188
0.0673354711866631,234.78728075481,0.21379012101765532,47.3331158001697,250.5967929330705,0.06516532889003798
0.0677099863843414,234.736224429048,0.21497920677028395,47.32282284489608,250.63021098905054,0.06551615533281124
0.0681218985067135,234.694330018485,0.21628702775881536,47.31437693172658,250.68215334810537,0.06590187120342168
0.0684700000564599,234.60292049838,0.21739225017926014,47.295948772473416,250.66618247814975,0.06622771869265022
0.0688483855650854,234.545774082402,0.2185936241691461,47.28442805501224,250.69387196908863,0.06658179370096357
0.0692451491748079,234.463429648814,0.21985334863001507,47.267827417200905,250.69888481088321,0.06695293145319943
0.0696203582281978,234.375482387324,0.221044637374528,47.250097249284515,250.69278743103618,0.06730378012128084
0.069987380888551,234.203405916113,0.2222099343211494,47.215406632688385,250.5946888913599,0.06764685484216829
0.0703788544509792,233.977926021052,0.22345286288185895,47.16994988584409,250.4450244212296,0.06801265538632735
0.0707624886675966,233.930879457082,0.2246709015196192,47.160465298547734,250.48441066366468,0.06837100092195085
0.0711077542826773,233.865878629736,0.2257671198475004,47.14736113175478,250.49555606244166,0.06869339731286911
0.0715142012502659,233.755780414326,0.22705758896959424,47.12516533152812,250.47263833828907,0.06907278946033994
0.0718993204182584,233.707977000278,0.22828034232797043,47.11552816325604,250.51142172292393,0.06943214071780235
0.072270122269466,233.584347736685,0.22945763820555454,47.090604503715696,250.46551710784868,0.0697780106360298
0.0726277299851415,233.659735197387,0.23059304270282424,47.105802615793216,250.62991135370245,0.07011146028596357
0.0730309136232126,233.662962223736,0.2318731507537,47.10645318430518,250.72758183484166,0.07048727369320566
0.073418747028717,233.612786301195,0.23310452181617644,47.09633771832091,250.76434436131618,0.07084864569911362
0.0737674322302519,233.445803737361,0.23421159733104976,47.06267403345198,250.66650124399345,0.07117342909048237
0.0742102990528214,233.373027611287,0.23561769949270792,47.04800236643546,250.69170978118296,0.07158578609250806
0.0746277600049505,233.409703294769,0.2369431380157178,47.05539618422543,250.82854661507773,0.07197433185157191
0.0750128307722892,233.219457086286,0.23816573770201818,47.01704254859526,250.71390875350477,0.07233259711052693
0.0753867947327355,232.924150983522,0.2393530732764352,46.95750883827804,250.48355614201347,0.07268040591757914
0.0757327938022197,232.723148368847,0.24045162032204753,46.91698671115956,250.34792257726826,0.0730020980023075
0.0761035905989984,232.745439230394,0.24162890015181993,46.921480548847434,250.45820285136796,0.0733467308964594
0.0764974215106878,232.750050593402,0.24287931329643372,46.92241019962984,250.55482932027937,0.07371264256691575
0.0768926457838096,232.664625769705,0.24413415036359545,46.90518855517253,250.55482442543752,0.07407971426800898
0.0773042447273851,232.612819480796,0.2454409770094477,46.894744407328474,250.59477780466648,0.07446185106376552
0.0776920792479849,232.566050563094,0.24667235161235201,46.88531579351975,250.63459059383277,0.07482179091189635
0.0780863046122077,232.502976588496,0.24792401714375942,46.8726000802408,250.65827484163032,0.07518752921929266
0.0785156992468264,232.356486146227,0.2492873451086738,46.84306760707937,250.60011813053353,0.07558574329822279
0.0789437979252944,232.324453901441,0.25064655841280975,46.836609906530505,250.66502864334075,0.07598259773247552
0.0793449531403645,232.185628471995,0.25192022622065724,46.80862269995419,250.6083862829715,0.07635433225547802
0.0797862848434079,231.994761109742,0.25332145437782005,46.770143839723985,250.50476120182225,0.07676313715017433
0.0801728410481977,231.820757754119,0.2545487703280277,46.7350647632304,250.40648651721273,0.07712106633900295
0.0805841853302335,231.570498171112,0.25585478842349135,46.68461243129618,250.2314181127474,0.077501807238589
0.0809905131114921,231.430518966825,0.25714487912898737,46.656392623711916,250.17419544760705,0.07787776258848957
0.0813783118313976,231.315937517007,0.25837614006468734,46.633293003428605,250.14003801183807,0.07823644212510679
0.08183396802964,231.311639390664,0.25982284849410703,46.63242650115786,250.24078869344322,0.07865771950895256
0.0822685963962283,231.275648854008,0.26120279355802484,46.625170808968015,250.30237186585424,0.07905939027962348
0.082687158955832,231.106395534122,0.26253172968476657,46.591049339678996,250.2159267973613,0.07944606105918463
0.083050200248857,230.719440926796,0.26368438579012093,46.51303929084208,249.88073669707072,0.0797813198982884
0.0834456280979893,230.498107138949,0.264939869211116,46.46841839921211,249.73216646455626,0.08014635900738767
0.0838564079627559,230.598490046468,0.26624409528174997,46.48865559336795,249.93565110340012,0.08052542926418685
0.0842762800627346,230.628928465206,0.26757718919918233,46.494791978585525,250.06547663110808,0.08091274144996435
0.084692479693474,230.504570611703,0.2688986230267799,46.46972143531933,250.0265742774876,0.0812965179649332
0.0851126347878582,230.2860363063,0.2702326154514498,46.425664919350076,249.88628761118153,0.08168379246883335
0.0855654705916392,230.302103138677,0.27167036912845444,46.428903992757284,250.00801097198212,0.08210102228216025
0.0859632247250188,230.151070582689,0.2729332385019347,46.3984558294701,249.93559878389235,0.08246735788590874
0.0863554025245618,230.006400554446,0.2741784030154837,46.36929035177632,249.8686958575508,0.08282842628433267
0.0867778615101206,229.831970573176,0.2755197102946329,46.33412526755228,249.77629748617318,0.08321722801855884
0.0872276249051111,229.73953409277,0.27694770907372773,46.31549007310243,249.77916799848913,0.08363099275302487
0.0876935541355962,229.566512180368,0.2784270343805179,46.280608855562186,249.69801554397708,0.08405944895833727
0.0881187739188533,229.247934105309,0.2797771071923592,46.2163835156303,249.44898098209893,0.08445030968027367
0.0885622873133928,229.080487235602,0.2811852622200221,46.182626226697366,249.3683791640534,0.0848578231268474
0.0890274280649183,228.901661333555,0.2826620841061156,46.14657492484469,249.28018752186838,0.0852850301028125
0.0894719601340694,228.741929410886,0.2840734734256703,46.11437296923462,249.20791820012693,0.08569313861799405
0.0899159330613243,228.572370675356,0.28548308746970463,46.080189928151775,249.12466865666954,0.08610056763490538
0.0903293505980987,228.276700293469,0.28679568814896333,46.020582779163355,248.89678638765486,0.08647980711298398
0.09076999470554,228.050840398082,0.2881947331900895,45.97504942425333,248.75101397360984,0.08688386400693997
0.0912014924999511,227.815538898898,0.2895647386873447,45.92761264201784,248.59265606115818,0.08727937586634436
0.0916601842911743,227.711435417403,0.2910210851244784,45.90662538014845,248.58350755297002,0.08769964234758919
0.0921007754888586,227.557162156193,0.29241996217712607,45.87552389068851,248.5153532588223,0.08810315831089938
0.0925741688079997,227.382380292278,0.293922985965399,45.84028786692325,248.43211514942013,0.08853653475235691
0.093033712987217,227.192000778123,0.29538203873441393,45.8019073568696,248.32851617150646,0.08895705317180162
0.0935102618573827,226.931629389928,0.29689508139719006,45.74941648500949,248.15206547790268,0.08939294550526818
0.0939760804671398,226.72003120663,0.29837405548316887,45.70675829125661,248.02629110281674,0.08981883947112794
0.0944150704548855,226.390076014906,0.29976784869426143,45.64023932460505,247.7647109921402,0.09022003830932364
0.0948633744591182,225.987869497158,0.30119121390770026,45.55915449062705,247.42584138448524,0.0906295833003141
0.0953656117673044,225.793737238347,0.3027858173611915,45.52001742725076,247.32669512330799,0.09108819956386237
0.0958172349145516,225.570879222044,0.3042197208537013,45.47508925116407,247.18445714634456,0.09150041815559345
0.0962861426707794,225.302963065276,0.3057085029797246,45.421077353959646,246.9965163111285,0.09192823352978993
0.096765084284559,224.867415342367,0.30722914260347484,45.33327093302119,246.6267297408221,0.0923650145912693
0.0972153885421174,224.399851254195,0.3086588586212227,45.23901001284571,246.2149699826649,0.09277550526742494
0.0976522240386194,224.202077724033,0.31004581132261655,45.199138869165054,246.0959092478642,0.09317355706769376
0.0981021661267688,224.063470111622,0.3114743774524909,45.171195574503,246.0445818794526,0.0935833862329796
0.0985880302114378,223.88901153771,0.313016995921315,45.13602472600233,245.96178817119866,0.0940257463740699
0.0990690809809423,223.475209484645,0.3145443321144918,45.05260223210444,245.61469311031234,0.09446353148143503
0.0995582079829184,222.857582473014,0.3160973103457659,44.92808862655962,245.04488401943271,0.09490847002331598
0.100039716612026,222.572881248106,0.31762610024318255,44.87069285961817,244.83900921368863,0.0953462851634512
0.100557472099267,222.377242793518,0.3192699739151727,44.83125214717323,244.73893618123913,0.09581684424573195
0.101066368963478,221.953777709919,0.3208857214590426,44.745881586319676,244.38584010078748,0.09627913654451868
0.101497237418395,221.371439179513,0.32225372880340414,44.628482138589824,243.8400286995678,0.09667037923931712
0.101993445859597,220.977600854093,0.3238291906042205,44.549084332185146,243.51586782298858,0.09712076321720785
0.102434302750178,220.491699794942,0.32522891123181513,44.451126678660316,243.07761332563845,0.0975207372211064
0.102959410965324,220.071932835504,0.3268961298149037,44.366501659637606,242.73040941024783,0.09799694083210211
0.103448582390054,219.590978398377,0.32844924908842144,44.269541245112805,242.30735381933405,0.09844035060420032
0.103913193842194,219.041377160442,0.32992439044896593,44.15874163554511,241.80266624477613,0.09886131599737145
0.104436196132992,218.375121711973,0.3315849227222496,44.024424537133754,241.18138875365062,0.09933497501432802
0.104930138926907,217.936320095764,0.33315319109292973,43.93596213130603,240.8044084406314,0.09978211028049574
0.105419006077963,217.232263449142,0.3347053442975325,43.79402431134703,240.13267275001675,0.1002244541157509
0.105928246540305,216.758049165283,0.3363221827654683,43.69842271172106,239.7188492368587,0.10068502444973265
0.106476861885862,216.31783264077,0.33806403648761185,43.60967506037923,239.3506766303103,0.10118096920660592
0.107007381771951,215.57964383672,0.33974843712594444,43.460856197482755,238.64825708701713,0.10166032197161212
0.107471716531226,214.840639461602,0.34122269998664256,43.31187291545896,237.92993176520662,0.10207968449026113
0.108015637879851,214.129679196027,0.3429496502685269,43.168543325919046,237.25903308339372,0.10257070183546976
0.108560034261991,213.475780692578,0.3446781087818214,43.03671738762373,236.65071875866957,0.10306190671507592
0.10906615122055,212.567904881911,0.3462850301252462,42.85368962419326,235.751868140397,0.10351835602168989
0.109560176003529,211.974130672171,0.34785355881120456,42.73398474350967,235.1980537368091,0.10396369896663017
0.110126183538426,211.092707836444,0.34965063273450253,42.55628989982711,234.33954212326356,0.10447368772673722
0.110646227221943,210.226942939318,0.351301771429669,42.38175169656651,233.48776103595625,0.10494203260575603
0.111126698484109,209.255972271609,0.35282726768704603,42.18600400995638,232.50989760823518,0.10537454419512406
0.111654981635906,208.556517251298,0.3545045666940015,42.04499387786168,231.8428913550402,0.105849879372185
0.112264486592552,207.772313118227,0.3564397449313526,41.886898324634565,231.09776517859171,0.10639801520229404
0.112779768496396,206.75600023598,0.35807576497605725,41.68200964757357,230.07389407783464,0.10686118074327347
0.113344993099141,205.504701972644,0.35987035308977267,41.42974791768503,228.79763099957438,0.10736899110919937
0.113840319166481,204.32729735488,0.36144301335357715,41.19238314674381,227.58798210018398,0.10781379116492766
0.114322407930696,203.80716995357,0.3629736451799598,41.08752546263972,227.1068963762027,0.1082465142922601
0.114932207563553,202.932728788692,0.36490975901428074,40.91123812380031,226.25623529527218,0.10879360267223111
0.115508628896439,201.622811018372,0.3667398967461938,40.647158701303795,224.91198547335,0.10931047031229242
0.116006476330498,200.458663238075,0.36832056234933114,40.41246650879592,223.713166410246,0.10975666710580957
0.116562671613738,199.540018957211,0.37008648237361813,40.227267821773744,222.79893666071945,0.11025492293386209
0.117129391699416,198.257750224019,0.3718858186456458,39.96876244516223,221.4795599074531,0.11076235196326695
0.117690821665351,196.887294643263,0.3736683587874894,39.69247860008182,220.05912212529668,0.11126479057053229
0.118238054996897,195.721310173614,0.375405824615148,39.457416131000585,218.86301720998654,0.11175428140200233
0.118761418737164,194.554015002067,0.3770675044904957,39.2220894244167,217.65952584472393,0.1122221972472772
0.119294126724568,192.964293787057,0.3787588523505034,38.90160162747069,215.98380070340693,0.11269824262384917
0.119787113526981,191.645315521508,0.38032408544816465,38.635695609136015,214.60195468879698,0.11313859003198855
0.120383814353438,190.571939008956,0.38221861057216566,38.41930290420554,213.51371593558486,0.11367131798871943
0.120901985950076,188.997824563435,0.38386380539149123,38.10196143198849,211.84803689339833,0.1141337057893293
0.121419137235214,187.305024452426,0.3855057607218044,37.760692929609085,210.04743892126024,0.11459497004712012
0.122043008744777,185.985021902189,0.3874865527646669,37.49458041548131,208.6831935565954,0.1151511385804403
0.122598817421996,184.456155138168,0.3892512453148373,37.18636087585467,207.07026162431563,0.11564637009764654
0.123133651994605,182.489979908123,0.3909493450828709,36.7899799494776,204.96063758663226,0.11612268202705406
0.123736304372104,180.858572362888,0.3928627663814302,36.461088188358225,203.23734372108652,0.11665911929637024
0.124334554436512,179.478565193239,0.39476221033592557,36.18287874295698,201.79395262744484,0.11719135347945765
0.124861605897055,177.606686738503,0.3964355987231496,35.8055080464822,199.78294286272768,0.11766001110877863
0.125401886069196,175.438154083856,0.3981509882696973,35.36833186330537,197.43842949446974,0.11814020392570998
0.125975132194802,173.658250590091,0.3999710447184963,35.009503318962345,195.53487166489575,0.11864944438907422
0.126527236978648,171.619854653164,0.4017239774072074,34.59856269807786,193.33444067310603,0.1191396590076765
0.127147604835727,169.738712942422,0.4036936453534332,34.21932452919228,191.32058374094998,0.11969019794189871
0.127832539434094,167.553380622505,0.40586831270324847,33.778761533497004,188.97215475824711,0.12029768410639692
0.128426275635549,165.529979974664,0.40775342514286805,33.370843962892266,186.7883788088371,0.120823985620385
0.129072474960432,163.344172994728,0.4098051079993716,32.930185275737166,184.4274096735225,0.12139647704910583
0.129677442481691,160.55234345191,0.4117258798793689,32.367352439905055,181.37236073519574,0.12193214284464436
0.130275923251474,158.06116339399,0.4136260563234299,31.865130540228385,178.65272738534415,0.12246178278575831
0.130370806248721,157.709535623351,0.4139273098396891,31.794242381667566,178.27025493567865,0.12254572601851951