File: example/data/02 processed data/test_ID_076.csv
Strain,Stress_MPa,Displacement(mm),Force(kN),True Stress (MPa),True Strain
0.0004539727745318,0.19725495406488,8.025119746147889e-05,0.0397665987394798,0.1972599398747284,2.52756482725188e-05
0.0004602510090943,0.78815230645981,0.0001001845921975,0.1588915049822977,0.7881771759771051,3.155370444349102e-05
0.0004665006620779,1.47853793811746,0.0001200272404204,0.2980732483244799,1.4785938325516552,3.780314070292347e-05
0.000473460357448,2.27639217767751,0.0001421242732206,0.458920663019786,2.276494077073988,4.476254876282901e-05
0.0004946014072984,3.6320989602147,0.0002092471064954,0.7322311503792835,3.632338332245544,6.590242885818697e-05
0.0005144777126026,5.43611008844988,0.0002723543758363,1.0959197938314955,5.436576402897161,8.57772268037589e-05
0.0005214701976317,7.54211315903313,0.0002945555158039,1.5204900128610792,7.542812866444725,9.276908761961497e-05
0.0005267606310068,9.86922633812785,0.0003113526417696,1.9896360297665745,9.87019415220426,9.805901623694308e-05
0.0005425746570953,12.2485083229864,0.0003615621746005,2.4692992779140583,12.249903156783208,0.0001138713666776
0.0005667382513587,14.7673744910801,0.0004382815863868,2.977102697401748,14.769413000786784,0.0001380319176878
0.0005756859961589,17.3486292774302,0.0004666906761275,3.497483662329928,17.3511793383837,0.0001469783874791
0.0005805005851196,19.9816491068734,0.0004819769960777,4.028300459945678,19.984682396704333,0.0001517922572645
0.0005908282235175,22.5800967616731,0.000514767247991,4.552147507153298,22.58375770475008,0.0001621182748125
0.0006120387279126,25.3179409665392,0.0005821105994455,5.104096898854303,25.32258280647393,0.0001833251160092
0.0006410908067401,28.1100335148517,0.0006743509497228,5.666982756594102,28.1160039173076,0.0002123714475004
0.0006696188477831,30.9680555931326,0.0007649274800343,6.243160007575532,30.975516480290526,0.0002408930239011
0.0006854742740197,33.8651854639563,0.0008152684583355,6.827221389533591,33.87388128050573,0.0002567445055008
0.000723596367474,36.8408148008536,0.0009363061050529,7.4271082638520864,36.85167914095224,0.000294856086318
0.0007559436730614,39.8498920480483,0.0010390088002929,8.033738236886537,39.86293280034079,0.0003271933326571
0.0007901287105162,42.863381816737,0.0011475462942119,8.641257774254179,42.87887401042556,0.0003613666029124
0.0008334174723456,45.8879484364465,0.0012849881130202,9.251010404787614,45.90652023747696,0.0004046387882005
0.0008749649947743,48.9404803139532,0.0014169014967314,9.866400831292966,48.96232089342016,0.0004461686399147
0.000917701437884,52.0041505422202,0.0015525897036047,10.484036749311592,52.02958081266952,0.0004888851072555
0.0009747185875384,55.0641228220095,0.0017336191537574,11.100927160917117,55.094189032406064,0.0005458727650598
0.0010214553640107,58.1179818144609,0.0018820084190569,11.716585133795318,58.152431745507634,0.0005925829452232
0.001071948265516,61.1999430538849,0.0020423233813363,12.337908519663197,61.239310006525976,0.0006430446611462
0.0011223256801532,64.3099485460434,0.0022022716728094,12.96488562688235,64.35455578319703,0.0006933884240007
0.0011714599907391,67.4566799314588,0.0023582731089196,13.599266674182092,67.5067842698208,0.0007424874718553
0.0012196078185499,70.5869880271185,0.0025111424622189,14.23033678626709,70.64281605323347,0.0007905984064261
0.0012605563793217,73.6898272407343,0.0026411541426694,14.855869171732037,73.75112682891996,0.0008315137690801
0.0012959178912095,76.786453171376,0.0027534269429131,15.4801489593494,76.85304400256113,0.0008668452654405
0.0013335275656223,79.9012621211185,0.0028728376591738,16.10809444361749,79.97355924075222,0.0009044216462103
0.0013854220423149,82.9934292318019,0.0030376026226728,16.731475333131264,83.0728311399276,0.0009562678655942
0.0014383726822303,86.0830832372935,0.0032057209044042,17.354349580638367,86.16999924971847,0.0010091664955596
0.0014854329577069,89.1364168568723,0.0033551372790424,17.96990163834546,89.23061053092482,0.0010561781982711
0.0015393645662338,92.2090226887308,0.0035263701361153,18.58933897404813,92.31143627735754,0.0011100514242906
0.0015803686395505,95.3088841647658,0.0036565580688958,19.214271047616787,95.41864872206664,0.0011510091674511
0.0016338403876232,98.4052351639482,0.0038263308690266,19.83849540905196,98.52382760142274,0.0012044179781823
0.0016996595558551,101.47332418161,0.0040353067281629,20.457022155012577,101.60229299666484,0.0012701557595696
0.001748382156654,104.558597861295,0.0041900009856994,21.079013328837075,104.69658231109096,0.0013188153304656
0.0017965016649894,107.646446000521,0.0043427804246643,21.70152351370504,107.7936853323244,0.0013668702652271
0.0018462784414289,110.723475274237,0.0045008216898597,22.32185261528618,110.88043483930502,0.001416577814309
0.0018956309290599,113.780391645382,0.0046575158380881,22.938126955709013,113.94729998432756,0.0014658592254463
0.0019696131377495,116.792685198099,0.0048924093506776,23.54540533593676,116.972652954053,0.0015397303375407
0.0020180044331498,119.819653538523,0.0050460517135736,24.15564215336624,120.01008382767507,0.0015880460135072
0.0020605795121444,122.846437298957,0.0051812275893814,24.765841759469733,123.04690827539498,0.0016305526315546
0.0021131206271104,125.830816706347,0.0053480456293985,25.36749264799955,126.04276913133285,0.0016830067695328
0.0021606405578932,128.816247974135,0.0054989214096339,25.96935559158561,129.03935046984955,0.0017304456659707
0.0022082914934992,131.781968664282,0.0056502131301829,26.56724488271925,132.01648715551613,0.001778013084177
0.0022541770663439,134.719372076453,0.0057958998239648,27.15942541061293,134.96529963075304,0.0018238160953856
0.0022897968185523,137.672564153408,0.0059089925372265,27.75478893332705,137.9287865641681,0.0018593703108629
0.0023386076725086,140.607922178264,0.0060639669985378,28.346557111138026,140.87647077663314,0.0019080893049008
0.0023878878908916,143.515838234279,0.0062204316919038,28.93279298803064,143.7970131849696,0.0019572743722736
0.0024303443111536,146.407084242324,0.0063552308262356,29.51566818325252,146.70013961711334,0.0019996468772158
0.0024856808768476,149.277186471946,0.0065309244223141,30.09428079274432,149.58424726653624,0.0020548713749786
0.0025398080276124,152.107179676466,0.0067027781259923,30.664807422775542,152.4282948502429,0.0021088859567945
0.0025849348177329,154.923301127701,0.0068460556846249,31.232537507344524,155.2573526383675,0.0021539166660414
0.0026344452094555,157.721897915595,0.0070032511783442,31.79673461978396,158.0697927399818,0.0022033193109411
0.002685176230353,160.511187856003,0.0071643221696937,32.359055471770205,160.87337804864572,0.0022539373971331
0.0027361554757887,163.292549644815,0.0073261812739521,32.91977800839471,163.66934045406973,0.0023048005743837
0.0027876770774691,166.061810152352,0.0074897623592873,33.478060926714164,166.45354668620843,0.0023562022446974
0.0028321099422653,168.825512857196,0.0076308367050153,34.035223392010714,169.231270312394,0.0024005295574499
0.002883506931817,171.561594134149,0.0077940221468419,34.58681737744444,171.98274527248884,0.0024518020005251
0.002933374555714,174.299448597049,0.0079523518527149,35.13876883716508,174.73601254759325,0.0025015462713785
0.002986865689476,176.979439785403,0.0081221862024093,35.67905506073725,177.4321830811306,0.0025549023383611
0.0030369726088296,179.617083161058,0.0082812756713569,36.21080396526929,180.0855740526932,0.0026048801539155
0.0030715733049454,182.218888908407,0.0083911328815246,36.73532800393485,182.7004709274161,0.0026393902411725
0.0031287730545674,184.814327728436,0.0085727420865744,37.2585684700527,185.3133405049776,0.0026964375901652
0.0031827314575899,187.35248471866,0.0087440600161709,37.77026091928186,187.8684599534816,0.0027502492458317
0.0032235674129863,189.886496590906,0.0088737141745545,38.28111771272665,190.41720477873443,0.0027909722172787
0.0032721328029683,192.389881431368,0.0090279092877473,38.78580009656379,192.93692974552323,0.0028394010788851
0.0033172544110675,194.876580990276,0.0091711703934623,39.28711872763965,195.4394932201837,0.0028843937381744
0.0033672185731918,197.379186817884,0.0093298066082069,39.79164406248542,197.95918985457567,0.0029342127506392
0.0034388771326754,199.853993390144,0.0095573225345673,40.29056506745304,200.4555899490892,0.0030056588045081
0.0034876684446137,202.276350264213,0.0097122349499715,40.77891221326534,202.8951078826661,0.0030543025034555
0.0035411937191117,204.673168462796,0.0098821776965026,41.26211076209968,205.31021306766388,0.0031076631212788
0.0035987568626414,207.047005612567,0.0100649406772094,41.7406763314935,207.7033570547353,0.0031650460091932
0.0036597566720342,209.353289846025,0.0102586150720315,42.20562323295864,210.0297228584955,0.0032258512079204
0.0037132581914685,211.633421117396,0.0104284823962354,42.66529769726704,212.32854408009769,0.0032791789955342
0.0037906710373989,213.848238114663,0.0106742681820645,43.11180480391606,214.5671903804576,0.0033563354300082
0.0038434647800736,216.052396287901,0.0108418883150566,43.55616309164084,216.790165091288,0.0034089508919842
0.003898772310744,218.241498187656,0.0110174897249352,43.99748603463145,218.99881266445504,0.0034640686839832
0.0039558512187353,220.351356695805,0.0111987152578075,44.42283350987429,221.12856995574447,0.0035209485910962
0.0040192972207657,222.427340785614,0.0114001563142541,44.841351902379785,223.22598848751,0.0035841695973366
0.0040889299929663,224.470618790587,0.011621240365991,45.25327674818234,225.29223359879745,0.0036535508336652
0.0041632330752477,226.463495392474,0.0118571526522344,45.65504067112276,227.3092315294904,0.0037275802009287
0.0042236348192428,228.364984690062,0.0120489281894188,46.0383809135165,229.2316156511669,0.0037877554011309
0.0043050490979491,230.200051619738,0.012307418524311,46.40833040653918,231.0923881172505,0.0038688585968025
0.00439728478977,231.922051205763,0.0126002668458424,46.75548552308182,232.8424542711576,0.0039607339105139
0.0044958049169299,233.520226405454,0.0129130682495751,47.077677643339534,234.4699784121406,0.0040588597829082
0.00461260239468,234.932417265858,0.0132839002414316,47.36237532079697,235.91535231922435,0.0041751773916982
0.0047372739617912,236.188206809392,0.01367973246701,47.61554249277343,237.2058419215228,0.004299321811797
0.0048766156450673,237.252712971867,0.0141221423114116,47.83014693512839,238.30799378331807,0.0044380560822548
0.0050204595848807,238.150673801348,0.0145788468203192,48.01117583835176,239.24420520087736,0.004581252795964
0.005174716717471,238.831986233911,0.0150686132162931,48.14852842475646,239.9654875958757,0.0047347930660192
0.0053460731657264,239.336265164363,0.0156126699395043,48.25019105713558,240.51317165650943,0.0049053255531898
0.0055241677491579,239.729123690601,0.0161781202418993,48.32939133602517,240.9506564743968,0.0050825329617263
0.0056980791569863,240.020603264564,0.0167302889617545,48.3881536181361,241.28536359508075,0.0052555477336243
0.0058757693303298,240.233036530405,0.0172944552621201,48.43098016452965,241.54160330292729,0.0054322908774677
0.0060522474437675,240.397657585499,0.0178547732722844,48.4641677692366,241.7495459859328,0.0056077975074769
0.0062308391084011,240.526691760635,0.0184218018074964,48.49018105894402,241.92226185355696,0.005785374701335
0.0064302339508519,240.637791581101,0.0190548804322777,48.51257878274996,242.081988225531,0.0059835996525476
0.0066137991277609,240.750195448052,0.0196376998689638,48.53523940232729,242.2392600406829,0.0061660530828784
0.0068043313331144,240.846338312187,0.0202426396209612,48.5546218037369,242.38188654226,0.0063553961446151
0.0069999289670431,240.927194008231,0.0208636621086848,48.570922312059366,242.5103825337684,0.0065497357347764
0.0071913145790521,240.990067290312,0.0214713114268131,48.5835975657269,242.61979100229908,0.0067398538441917
0.0073903419830887,241.079109252697,0.0221032234346296,48.60154842534372,242.75741647072343,0.0069375248047564
0.0075928280926657,241.153782762955,0.0227461168325366,48.616602605011735,242.8814401227453,0.0071385908083055
0.0077764045744464,241.211249802772,0.02332897216219,48.62818796023883,242.98359957658488,0.0073208448697907
0.0079698357893092,241.242693180191,0.0239431162693793,48.63452694512651,243.06193785797103,0.007512846742022
0.0081649536345247,241.307463180793,0.0245626154279386,48.64758457724787,243.1742796903997,0.0077064854403282
0.0083571366100717,241.403087569978,0.0251727963753003,48.666862454107566,243.31703741809383,0.0078971748704208
0.0085505016523526,241.498996987112,0.0257867303845421,48.68619779260178,243.4604047110314,0.0080890004892388
0.0087399744469966,241.555988183397,0.0263883065075368,48.69768721777284,243.5636270668346,0.00827692916076
0.0089288963809519,241.612861614225,0.0269881336478449,48.70915290142776,243.66661915762128,0.0084642763041519
0.0091220640656855,241.680568336427,0.0276014410468741,48.72280257662368,243.7815862763051,0.0086557975230375
0.0093118815669017,241.797525881878,0.0282041116132355,48.746381217786606,243.9454579788155,0.0088439613888261
0.0094898511100751,241.840436707166,0.0287691649128111,48.75503204016466,244.0317902209344,0.0090203483586643
0.009675635426815,241.897002186973,0.0293590301184603,48.76643564089376,244.13380891855493,0.0092044474245267
0.0098590690619935,241.951773496289,0.029941431910152,48.77747753685187,244.23346878815664,0.0093861838860157