File: example/data/02 processed data/test_ID_063.csv
Strain,Stress_MPa,Displacement(mm),Force(kN),True Stress (MPa),True Strain
-3.15076412964791e-06,,-1.0003676111632113e-05,,,-3.150769093267974e-06
-2.81400866561085e-06,,-8.934477513314449e-06,,,-2.8140126249712225e-06
-2.84537495951044e-06,,-9.034065496445646e-06,,,-2.8453790076239707e-06
-2.81679657911919e-06,,-8.943329138703428e-06,,,-2.816800546275992e-06
-2.22961187659672e-06,0.361330458222076,-7.079017708194585e-06,0.07284422037757052,0.36132965259539496,-2.229614362157925e-06
-7.00554019697274e-07,0.355902880902802,-2.2242590125388447e-06,0.07175002079000488,0.35590263157360813,-7.005542650716898e-07
8.44789248419195e-07,0.345903036017836,2.6822058637309442e-06,0.06973405206119575,0.3459033282330018,8.447888914989637e-07
6.06979919938891e-06,0.344990099011353,1.9271612458059788e-05,0.06955000396068878,0.3449921930319798,6.069780778325187e-06
3.38802273885927e-05,0.353487085800929,0.0001075697219587818,0.07126299649746728,0.35349906202377485,3.387965346654215e-05
6.38949169402344e-05,0.366210576638791,0.0002028663612852442,0.07382805225038026,0.36623397563316795,6.389287574699679e-05
9.16556668855088e-05,0.380314088532964,0.00029100674236149043,0.07667132024824555,0.38034894647437445,9.165146676152045e-05
0.0001279802992419,0.395410912286352,0.0004063374500930325,0.07971483991692857,0.39546151709322996,0.0001279721104621559
0.0001741481884143,0.433561670213419,0.0005529204982154025,0.08740603271502527,0.4336371741928526,0.00017413302637882925
0.0002373241518344,0.692967716133622,0.00075350418207422,0.1397022915725382,0.6931321741091019,0.00023729599491257447
0.0003110400783888,1.31140216317317,0.00098755224888444,0.2643786760957111,1.3118100618048028,0.0003109917154518793
0.0003650371753404,2.3274752707757,0.0011589930317057698,0.46921901458838106,2.3283248857742183,0.0003649705654801772
0.0004124417285245,3.75437913033553,0.0013095024880652873,0.7568828326756429,3.755927592953582,0.0004123566978141287
0.0004652714537424,5.57291931711671,0.0014772368656321198,1.123500534330729,5.575512237388974,0.00046516324854137015
0.0005262083459952,7.82241126615755,0.0016707114985347598,1.5769981112573621,7.826527484251608,0.0005260699469324848
0.0005944030265005,10.480880796023,0.0018872296091390875,2.112945568478237,10.487110663288547,0.0005942264389942778
0.0006591489945106,13.3562380747143,0.0020927980575711548,2.6926175958624032,13.365041825611693,0.0006589318512268241
0.0007126674781567,16.3111664576085,0.0022627192431475224,3.2883311578538734,16.32279089547364,0.000712413651278529
0.0007634389541411,19.3420869889992,0.0024239186793979925,3.8993647369822386,19.35685349166099,0.000763147682858556
0.0008249263867637,22.4412654849444,0.002619141277974747,4.524159121764791,22.4597778769953,0.0008245863219979723
0.0008962985617438,25.6257778103826,0.002845747933536565,5.166156806573132,25.648746158177612,0.0008958971260408093
0.0009636610746946,28.8565435888071,0.0030596239121553548,5.817479187503511,28.88435151661386,0.0009631970514446495
0.0010252764769804,32.1294682522486,0.0032552528144127696,6.477300799653318,32.16240984026552,0.0010247512400314187
0.0010813371307835,35.4375758700927,0.0034332453902376123,7.144215295410689,35.47589583670599,0.001080752906912241
0.0011410359873911,38.7992161728685,0.003622789259966742,7.8219219804502895,38.843487474804306,0.0011403855006010676
0.0012053295579153,42.1792062061733,0.0038269213463810775,8.503327971164536,42.230046050143,0.0012046037314252464
0.0012718606122051,45.572086546048,0.004038157443751193,9.187332647683277,45.63004788794192,0.0012710524826428358
0.0013381100389662,48.9834682671172,0.004248499373717685,9.875067202650827,49.04901353774881,0.0013372155675732183
0.0014022459381669,52.4066787400977,0.0044521308536799075,10.565186434003698,52.48016579249382,0.00140126370944157
0.0014666765410629,55.8552148742215,0.004656698017874708,11.260411318643055,55.937136407573554,0.0014656020215449315
0.0015301562526581,59.3537957279697,0.004858246102189467,11.965725218758692,59.44461630962184,0.0015289867564353742
0.0015929903213676,62.8698164082538,0.005057744270342129,12.674554987903967,62.96996741729831,0.0015917228581448606
0.0016599703550803,66.3670324060123,0.005270405877379952,13.37959373305208,66.47719971236094,0.0016585941270784571
0.0017290154207059,69.876077155682,0.005489623960741232,14.087017154585492,69.99689397062261,0.0017275223942728084
0.0017968733591793,73.4263708863756,0.005705072915394277,14.802756370693318,73.55830877608254,0.0017952609135296635
0.0018639804053868,76.9921329849531,0.00591813778710309,15.521614009766544,77.135644812206,0.0018622453496496797
0.001926545355952,80.5506158515852,0.0061167815051476,16.239004155679577,80.70580026647316,0.0019246919475162754
0.0019897468805209,84.1171362034903,0.006317446345653856,16.958014658623647,84.28450801284956,0.0019877699561484385
0.0020564948460032,87.6991249232794,0.00652937113606016,17.680143584533127,87.8794777216831,0.002054383155102664
0.0021240642270543,91.3158416454745,0.0067439039208974025,18.40927367572766,91.50980235807702,0.0021218115918978874
0.0021898990987765,94.9360463329769,0.006952929638615387,19.139106940728144,95.14394669528289,0.0021875047646746867
0.002251792238721,98.5574642258034,0.007149440357939174,19.869184787921967,98.77939515881509,0.0022492607541172204
0.0023152736113248,102.192075726531,0.007350993715956239,20.60192246646865,102.42867834274715,0.0023125974952084983
0.0023799986068782,105.824715768607,0.0075564955768382845,21.334262698951175,106.07657844470957,0.002377170895937184
0.0024437702397362,109.430665293549,0.007758970511162435,22.061222123179476,109.6980886967079,0.0024407890890875725
0.0025075411567511,113.028425682553,0.007961443172684742,22.786530617602686,113.31184911183477,0.002504402521168278
0.0025701603444316,116.595704287786,0.00816025909357033,23.505693984417658,116.89537394327756,0.0025668631307039246
0.0026352396522443,120.131591205254,0.008366885895875652,24.218528786979206,120.44816673788527,0.002631773496330787
0.0027012649520597,123.625622539037,0.008576516222789547,24.922925503869862,123.95956810037826,0.0026976230928326583
0.0027646017736088,127.121170379474,0.00877761063120794,25.62762794850196,127.4726097925683,0.0027607872908586148
0.0028241553024905,130.618234726567,0.008966693085407337,26.33263612087591,130.987120906772,0.0028201748683859217
0.0028887681799427,134.084968940555,0.009171838971318071,27.031529738415887,134.4723093322391,0.0028846037073469357
0.0029546470174854,137.506207954883,0.009381004280516145,27.721251523704414,137.91249026210264,0.0029502906269412293
0.0030210999349516,140.922897449246,0.00959199229347133,28.410056125767994,141.3486396055631,0.0030165455830057433
0.0030804484182867,144.359301530127,0.009780423728060272,29.102835188473605,144.80399291219044,0.0030757135582272777
0.0031392130672047,147.768408491214,0.009967001488374923,29.790111151828743,148.23228501006966,0.0031342960256041242
0.0031995104562392,151.141119292573,0.010158445698559459,30.47004964938272,151.62469688411727,0.00319440291418246
0.0032627009352372,154.49866502738,0.01035907546937811,31.14693086951981,155.00274796625777,0.0032573898756713816
0.0033234513705991,157.841045695633,0.010551958101652142,31.820754812239613,158.36562273528693,0.003317940911878376
0.0033812096384128,161.153096230781,0.01073534060196064,32.48846420012545,161.69798863301656,0.003375506201830442
0.0034397120002948,164.440882659444,0.010921085600935989,33.15128194414391,165.00651193686673,0.0034338097218583135
0.0035018255361525,167.681657381794,0.011118296077284187,33.80462212816967,168.26884929155793,0.0034957084216619065
0.0035656662462963,170.905750530935,0.011320990331990752,34.454599307036496,171.5151433969011,0.0035593243293748095
0.0036280993013346,174.099513546971,0.011519215281737355,35.09846193106936,174.73116387043348,0.003621533624889815
0.0036899672721567,177.265979443211,0.011715646089097522,35.73682145575134,177.92008510582323,0.0036831760440677293
0.0037507941415104,180.421829792864,0.01190877139929552,36.373040886241384,181.09855493505168,0.0037437774531270986
0.0038156755099284,183.56403158262,0.012114769744022669,37.0065087670562,184.26445236243353,0.0038084142852532325
0.0038783959405687,186.695617825789,0.012313907111305622,37.63783655367906,187.41969735208647,0.0038708943528616923
0.0039429019300714,189.827204068957,0.012518713627976694,38.269164340301735,190.57567411826057,0.0039351490647659935
0.0040025106412342,192.937559218952,0.012707971285918584,38.89621193854072,193.70979385281962,0.003994521905090391
0.0040629141144371,196.035782315704,0.012899752313337794,39.52081371484593,196.8322588626092,0.004054682766859488
0.0041256108796287,199.124906372525,0.013098814542821122,40.14358112470104,199.94641825266052,0.004117123881756413
0.0041892982429448,202.179150776274,0.01330102192134974,40.75931679649684,203.02613953738114,0.004180547564016844
0.0042499433099811,205.196999020296,0.01349357000918999,41.36771500249168,206.06907463351052,0.00424093780714707
0.0043103605821431,208.163286038038,0.013685394848304343,41.965718465268466,209.06054486082573,0.004301097586331225
0.0043726266009956,211.035549643153,0.013883089458161028,42.54476680805964,211.95832930127835,0.004363094446233713
0.0044395375512489,213.841086955435,0.014095531725215257,43.1103631302157,214.79044249097353,0.004429711874654488
0.0045065470968085,216.520754215328,0.014308287032366987,43.65058404981012,217.49651519163586,0.004496423018469065
0.00457189835671,219.151893262251,0.014515777282554248,44.1810216816698,220.15383344292658,0.004561478974917683
0.0046348884802968,221.796680869073,0.01471577092494234,44.71421086320512,222.8246837502011,0.004624180458926186
0.0047030663137112,224.477864635621,0.01493223554603306,45.25473751054119,225.53359891896258,0.004692041450928947
0.0047742394278725,226.860296591078,0.015158210183495186,45.73503579276133,227.94338196368196,0.0047628788910809555
0.0048399633381354,229.203299373497,0.015366883598579894,46.207385153697,230.31263493944437,0.0048282883713640845
0.0049059731113259,231.496257436292,0.015576464628459732,46.669645499156466,232.63197185064703,0.004893978040906051
0.0049729201511819,233.784665979121,0.01578902148000253,47.130988661390795,234.9472584556059,0.004960596024810623
0.0050417889339289,235.951753989526,0.016007679865224257,47.567873604288444,237.1413729317315,0.00502912167535706
0.0051188666244316,237.985389414267,0.016252401532570328,47.977854505916234,239.20360488124203,0.00510580976526393
0.0051943397224805,239.835527533718,0.016492028618875585,48.35084235079755,241.08131474124846,0.005180895675107414
0.0052719412746463,241.890394051632,0.016738413547002003,48.76510344080901,243.16562600397324,0.00525809324160009
0.0053548781040427,243.85730318354,0.017001737980335573,49.16163232180166,245.16312931686844,0.0053405917228141085
0.0054468780418019,245.769618075858,0.017293837782721033,49.54715500409298,247.10829521189746,0.0054320974493655486
0.005546867471011,247.644020301793,0.017611304220459922,49.92503449284147,249.01766886239542,0.005531540254212245
0.0056569437461592,249.433498155032,0.01796079639405546,50.28579322805445,250.8445294225027,0.005641003327665079
0.0057749319053973,251.206294435063,0.018335408799636427,50.6431889581087,252.65699367963265,0.0057583209070489125
0.0059056112126061,252.977574208439,0.018750315600024367,51.000278960421305,254.47156140722225,0.005888241443229235
0.0060510705266427,254.707908302122,0.019212148922090572,51.349114313707794,256.2491638189518,0.006032836320057633
0.0062110679352545,256.407912262699,0.019720140694433036,51.69183511216013,258.00047922489944,0.006191858751470261
0.0063795208388645,258.066970543584,0.020254978663394787,52.02630126158653,259.71331415998935,0.006359257829000354
0.0065597404543577,259.627455891875,0.020827175942585693,52.340895107802,261.33054461735094,0.006538318985430044
0.0067503924225876,261.125764467299,0.02143249594171563,52.642954116607484,262.88846584910146,0.006727710540845506
0.0069469546249272,262.475455390505,0.02205658093414386,52.915051806725806,264.2988604692599,0.006922935710359834
0.0071490310368764,263.679561674803,0.02269817354208257,53.15779963364028,265.5646150450061,0.007123597857611872
0.0073549325656139,264.710786200399,0.02335191089582413,53.36569449800044,266.6577161822936,0.007328016943575094
0.0075646162276376,265.635855260124,0.02401765652274938,53.552188420441,267.64528856146717,0.007536147995662309
0.0077791225561309,266.416856187597,0.024698714115715607,53.70963820741955,268.4893455628994,0.007749021189624518
0.0079871259152775,267.075020075992,0.025359124781006062,53.842324047319984,269.2081818901642,0.007955397658168424
0.0082019499481235,267.67404020483,0.026041191085292112,53.96308650529373,269.86948928500203,0.008168496753119973
0.0084192037440825,268.180553427696,0.026730971887461936,54.06519957102351,270.43842014720457,0.008383959926658316
0.0086367221787505,268.64915398418,0.027421592917532836,54.15966944321069,270.9694020906977,0.008599639058521435
0.008852385977614,269.06770982104,0.028106325478924447,54.24405029992167,271.4496010424885,0.008813433322701677
0.0090646469677868,269.419539365066,0.028780254122723087,54.314979135997305,271.86173237563406,0.009023809653829566
0.0092728757228612,269.757720349195,0.029441380420084307,54.383156422397704,272.25915016527546,0.009230146555831577
0.0094913630083727,270.083769280082,0.030135077551583317,54.44888788686453,272.64723237698877,0.009446603021794849
0.009704291073348,270.402235677693,0.0308111241578799,54.513090712622905,273.02629767959337,0.009657506868912636
0.0099130917681492,270.711603035371,0.031474066363873704,54.575459171930795,273.3951919989634,0.009864279396539905
0.0101233995686553,270.986090739978,0.03214179363048057,54.63079589317957,273.7293912140867,0.010072501180817582
0.010331275289337,271.256028924619,0.03280179904364497,54.68521543120319,274.0584496333316,0.010278272410434195
0.0105448105988657,271.536582655848,0.0334797736513986,54.74177506341896,274.3998844906172,0.010489601854940517
0.0107605302446853,271.785289747315,0.03416468352687583,54.791914413058706,274.7098435777016,0.010703047732987475
0.0109685387382818,272.05067841199,0.034825110494044714,54.84541676785719,275.0346768169278,0.010908820600897104
0.0111717084341608,272.266022357041,0.03547017427846054,54.888830107179466,275.30769897534253,0.011109765809169971
0.0113786405362568,272.482882808747,0.03612718370261534,54.9325491742434,275.5833675845107,0.011314390730298373
0.0115809310096202,272.673962647313,0.03676945595554413,54.971070869698295,275.83178099685125,0.01151438530941206
0.0117853830699467,272.892339605675,0.03741859124708077,55.01509566450408,276.1084803647819,0.011716476309543627
0.0119850864311592,273.101617524104,0.038052649418930454,55.05728609285936,276.37476401461976,0.011913834028583653
0.0121845049958341,273.29269736267,0.03868580336177326,55.09580778831428,276.62263359901044,0.012110871437074068
0.0123817885394803,273.448897548165,0.03931217861284995,55.12729774571007,276.8346839739604,0.012305761122732402
0.0125817571649928,273.600548213694,0.03994707899885214,55.15787051988072,277.04292387152765,0.01250326455590456
0.0127792382509893,273.764330932465,0.04057408144689103,55.19088911598494,277.26283054207363,0.012698272840421897
0.0129766432752041,273.947828237755,0.041200842398773016,55.227882172731405,277.50275148081323,0.01289316801672613
0.0131733893259465,274.084313836731,0.041825511109880135,55.255397669484964,277.69493321103715,0.013087374811084962
0.0133708791240696,274.222315942362,0.04245254121892098,55.283218893980184,277.88890938194976,0.01328227783079486
0.0135672808346962,274.325438394921,0.04307611665016044,55.30400838041607,278.047288657726,0.01347606934858372
0.0137650016218808,274.458890980587,0.04370388014947153,55.33091242168634,278.2368180600744,0.013671124485348874
0.0139620209870012,274.612058152771,0.04432941663372881,55.36179092359864,278.4461974719836,0.013865449819620847
0.0141582794101581,274.731862178538,0.04495253712725197,55.38594341519326,278.6215926461348,0.014058987080434125
0.0143559724297717,274.853182710961,0.04558021246452515,55.410401634529734,278.79896742419453,0.014253901185730918
0.0145543571734542,274.974503243384,0.04621008402571708,55.434859853866215,278.97658037718134,0.014449459108050155
0.0147532464731457,275.08520822922,0.046841557552237595,55.45717797901075,279.14360810734223,0.014645476015463312
0.0149511390261608,275.238375401404,0.047469866408060536,55.48805648092305,279.35350261736505,0.014840472444555053
0.015150009987406,275.3232997741,0.04810128171001404,55.505177234458564,279.4944505154432,0.015036394664468131
0.0153455146998704,275.424905720005,0.04872200917208852,55.525660993153004,279.6514426594417,0.015228963139199142
0.015539638034221,275.553808785704,0.04933835075865167,55.551647851197934,279.8358152331848,0.015420134298907909
0.0157325003879912,275.667546784851,0.04995068873187206,55.574577431825965,280.00448657160024,0.01561002747048411
0.0159242188351981,275.790383823929,0.05055939480175396,55.59934137890409,280.1821302485845,0.015798758613852926
0.0161160329740543,275.893506276489,0.051168404692622405,55.62013086534019,280.3398151209684,0.01598754831844201
0.016306065518301,276.022409342188,0.05177175802060568,55.646117723385096,280.52324883344096,0.016174549379827128
0.0164970520000455,276.160411447819,0.05237814010014446,55.673938947880316,280.71624411582764,0.016362453934538508
0.016687760410194,276.263533900379,0.052983639302365944,55.6947284343164,280.87375356418204,0.016550049680428097
0.016881498579696,276.368172859594,0.053598757990534804,55.71582364849415,281.03368177719636,0.016740589706769993
0.0170746900034279,276.466745792187,0.05421214076088358,55.735695951704905,281.18732977284515,0.01693055586769074
0.0172721777558976,276.566835231436,0.05483916437497488,55.755873982657505,281.3437467709394,0.017124709338978958
0.0174685606074986,276.671474190651,0.05546267992880805,55.776969196835246,281.5045266059164,0.017317739191390433
0.017662841876937,276.770047123245,0.05607952295927497,55.796841500046185,281.65859270185524,0.017508666686088047
0.017857529932522,276.900466695599,0.05669765753575735,55.823134085832756,281.84522506794497,0.017699957383911724
0.0180523513389953,277.021787228022,0.05731621550131007,55.847592305169236,282.0226818596186,0.017891342482888775
0.0182444730876282,277.132492213858,0.057926202053219536,55.869910430313766,282.18862850976103,0.018080039677618318
0.0184365726552183,277.320539039114,0.058536118180318106,55.90782067028538,282.4333793058929,0.018268679492930914
0.0186237122148922,277.417595465053,0.05913028628228273,55.92738724575469,282.58414092634155,0.018452414418784983
0.0188114462137549,277.517684904301,0.05972634172867181,55.94756527670708,282.73819390724407,0.018636699055886097
0.0189941883923209,277.602609276998,0.06030654814561885,55.9646860302428,282.8754455358051,0.0188160509783191
0.0191719577382218,277.684500636383,0.06087096581885421,55.98119532829482,283.008256147143,0.018990491464134604
0.0193510292682512,277.787623088943,0.06143951792669756,56.00198481473092,283.1630995136951,0.01916617899047734
0.0195309290693599,277.887712528192,0.06201069979521767,56.02216284568352,283.31511773082684,0.01934264806053788
0.0197085230167195,277.936240741161,0.0625745605780844,56.03194613341806,283.41395353898866,0.019516824710197063
0.0198834496802986,278.084858393379,0.06312995273494805,56.06190745210522,283.61414468209676,0.01968835574812
0.0200561268693756,278.169782766075,0.06367820281026752,56.079028205640725,283.74879122045803,0.019857652124811085
0.0202372514184864,278.259256658737,0.06425327325369432,56.09706614240138,283.890459195261,0.02003519967901487
0.0204187800522998,278.357829591331,0.06482962666605187,56.11693844561233,284.04155688959196,0.020213111714647434
0.0206000751110378,278.480666630409,0.06540523847754501,56.14170239269046,284.21738927996734,0.02039076324271249
0.0207814774171916,278.56710750976,0.06598119079958333,56.15912887396761,284.3561435636464,0.02056848828035333
0.0209618525483219,278.658097909078,0.06655388184092204,56.17747253847012,284.4992878688439,0.020745175652318686
0.0211430650492343,278.761220361637,0.0671292315313189,56.19826202490603,284.6550869769471,0.020922651843504052
0.0213235484759417,278.914387533821,0.06770226641111489,56.22914052681832,284.86183199703606,0.021099382690394776
0.0215048484471883,279.04025758621,0.06827789381982285,56.254515929379934,285.0409760362658,0.021276881663872496
0.0216880781161655,279.150962572046,0.06885964801882546,56.27683405452448,285.2052104545113,0.02145623787354438
0.0218693907095689,279.246502491329,0.06943531550288125,56.29609490225192,285.35345335859245,0.02163368587453778
0.0220521090112098,279.35569097051,0.07001544611059111,56.31810729965482,285.51607312069353,0.021812477772516898
0.0222311176559088,279.434549316585,0.07058379855751044,56.33400514222353,285.64669165956786,0.02198760873560608
0.0224135121847414,279.492176569486,0.07116290118655394,56.34562279640838,285.756577874566,0.02216602069693593
0.0225990980124578,279.571034915561,0.0717521361895535,56.36152063897709,285.88908813506197,0.022347521610231538
0.0227819195100999,279.665058328189,0.07233259444456717,56.3804757589629,286.0363651768092,0.022526286834473788
0.0229626984082894,279.762114754127,0.07290656744631883,56.40004233443201,286.1862078212913,0.022703023360701447
0.0231453145776152,279.847039126823,0.07348637378392825,56.41716308796752,286.3241868810275,0.022881524367150567
0.023323039729149,279.944095552761,0.07405065114004807,56.436729663436616,286.47324281527875,0.02305521398380805
0.0235065108347059,280.06996560515,0.07463317190019123,56.46210506599824,286.6534332861232,0.023234487442115967
0.0236879941662828,280.165505524433,0.07520938147794788,56.481365913725696,286.80206438488943,0.02341178699192332
0.0238694875022189,280.27924352358,0.075785622819545,56.50429549435374,286.9693654239975,0.023589064883300044
0.0240502600709275,280.364167896276,0.0763595757251948,56.52141624788925,287.10699904875065,0.023765607513344382
0.0242345039061953,280.452125282283,0.07694454990217008,56.539148456908265,287.2487434079373,0.023945508119944493
0.0244164335529037,280.556764241498,0.07752217653046924,56.560243671086,287.4069598334182,0.024123117339612126
0.0246009441093041,280.658370187402,0.07810799754704051,56.58072742978025,287.56283106619065,0.02430321396437522
0.0247841603841274,280.735712026821,0.07868970921960448,56.59631954460711,287.6935109392459,0.02448201518129617
0.024966720172707,280.829735439449,0.07926933654834471,56.61527466459292,287.8411328603411,0.02466014393908232
0.0251462625482697,280.91011029218,0.07983938359075629,56.63147823490349,287.97394967805053,0.02483529757942787
0.0253259390041186,281.01929877136,0.08040985633807655,56.65349063230617,288.13637639102365,0.025010551314809087
0.0255015379021284,281.120904717265,0.08096738283925767,56.67397439100062,288.28992012399294,0.0251817981899523
0.0256807015477143,281.186114503442,0.0815362274139929,56.68712068389391,288.40717118936635,0.025356491245104328
0.025857115458584,281.25739031624,0.08209634158100419,56.701489887753986,288.529895131227,0.025528473364899724
0.0260353858428694,281.352930235524,0.08266235005111035,56.720750735481644,288.6780623322278,0.02570223527944534
0.0262135604301148,281.449986661462,0.08322805436561448,56.74031731095074,288.82779289486723,0.0258758736560337
0.026391425431671,281.525811994226,0.08379277574555542,56.755603698035955,288.95567946856227,0.026049180262250247
0.02656990931797,281.59557130037,0.08435946208455475,56.76966717415459,289.0775400941628,0.026223059705304152
0.0267510270533937,281.686561699687,0.08493451089452499,56.7880108386569,289.22196653229275,0.02639947414951999
0.0269316687003534,281.794233672212,0.08550804812362203,56.80971750831794,289.38342261514197,0.026575393874411282
0.0271104762045211,281.903422151393,0.08607576194935448,56.831729905720834,289.5459581696014,0.02674949692781062
0.0272866425519752,281.979247484157,0.08663509010252125,56.847016292806046,289.6735144173321,0.026920998675235595
0.0274639512050361,282.067204870164,0.0871980450759896,56.86474850182506,289.8138848212591,0.02709358278742887
0.0276385917782612,282.150612736205,0.0877525288959793,56.88156352761893,289.9488583416072,0.02726354080168143
0.0278178265568261,282.227954575624,0.08832159931792286,56.897155642445796,290.07892286549645,0.027437939808559353
0.0279954325933634,282.325011001563,0.0888854984839288,56.916722217915094,290.2288218164778,0.027610724020538362
0.0281709612140381,282.422067427501,0.08944280185457097,56.936288793384215,290.37816853498964,0.02778145788879908
0.028347432861419,282.488793720334,0.09000309933500532,56.949740814019336,290.49662583442444,0.027953079643627456
0.0285305884608211,282.585850146272,0.09058461836310698,56.969307389488435,290.64819074164654,0.028131170515315045
0.0287092257935093,282.669258012313,0.09115179189439203,56.986122415282296,290.78447356547224,0.02830483751504878
0.0288901458327985,282.776929984838,0.09172621301913524,57.00782908494333,290.946396730251,0.0284806929728705
0.029068672946636,282.911899077159,0.0922930366055693,57.03503885395525,291.13577254414463,0.02865419218253029
0.0292444873419562,282.977108863336,0.09285124731071093,57.04818514684854,291.2526293415532,0.028825025658348945
0.0294234873818541,283.045351662824,0.09341957243738676,57.061942895225314,291.37353299596754,0.02899892455078508
0.0296000651773219,283.140891582107,0.09398020693799702,57.081203742952766,291.52188042730234,0.029170440603314984
0.0297743206368663,283.234914994735,0.0945334680220505,57.10015886293858,291.66804216934383,0.02933967205647935
0.0299485128349757,283.318322860776,0.09508652825104784,57.11697388873244,291.8032852893557,0.029508813453267183
0.0301234126625945,283.398697713506,0.09564183520373754,57.13317745904281,291.9356336327718,0.02967861318295064
0.0302974528727311,283.457841473063,0.09619441287092124,57.14510084096951,292.0458920664992,0.029847549746797146
0.0304739145506267,283.550348379035,0.09675467869823977,57.16375023321345,292.1912374663381,0.030018807637038094
0.030647061633898,283.618591178523,0.09730442068762614,57.17750798159023,292.31066762289055,0.03018682017553464
0.0308267774351795,283.691383497977,0.0978750183566949,57.192182913192156,292.43667463734727,0.030361176791981394
0.0310059557923301,283.762659310775,0.09844390964064806,57.20655211705224,292.5609917808789,0.030534981732327948
0.0311847128349774,283.861232243369,0.09901146325105324,57.22642442026319,292.7133632558613,0.03070834789658662
0.0313650036899606,283.956772162652,0.09958388671562489,57.24568526799064,292.86307736932287,0.030883171178661226
0.0315452000904929,284.056861601901,0.10015601028731495,57.265863298943245,293.01749213821046,0.031057872336918556
0.0317282769522267,284.129653921355,0.10073727932331977,57.28053823054516,293.1445982713121,0.031235334863579406
0.0319110924713141,284.249457947123,0.10131771859642226,57.304690722139995,293.3201686845946,0.03141251264209485
0.0320924800275141,284.355613412993,0.10189362408735726,57.3260916640594,293.48129025716105,0.031588275474178876
0.0322716578857483,284.451153332276,0.10246251378725085,57.34535251178685,293.63086363782173,0.031761866804693985
0.0324570929402512,284.533044691661,0.10305127008529756,57.361861809838864,293.76816016779094,0.03194148851522362
0.032641511891635,284.6301011176,0.10363680025594112,57.38142838530816,293.9208579479474,0.03212009398369134
0.0328233631190944,284.687728370501,0.10421417790312472,57.393046039493015,294.0321370543561,0.03229618143996273
0.0330032586991352,284.778718769818,0.10478534636975426,57.41138970399531,294.17734449738657,0.03247034472994601
0.0331834140413703,284.854544102582,0.10535733958135068,57.42667609108054,294.30699038110373,0.03264472911163669
0.0333603922110124,284.94856751521,0.10591924526996435,57.44563121106634,294.45456348748354,0.03281600849080043
0.0335351161388946,285.019843328009,0.10647399374099036,57.46000041492662,294.57801687590336,0.03298507744236818
0.0337077054594375,285.10325119405,0.10702196483371405,57.476815440720486,294.71342761082707,0.03315205281569217
0.0338803690653233,285.173010500193,0.10757017178240148,57.49087891683891,294.83477734340886,0.03331907216390245
0.0340543320376872,285.257934872889,0.10812250421965686,57.507999670374424,294.9722033034353,0.033487320196764814
0.0342277573819359,285.333760205653,0.10867312968764646,57.52328605745964,295.1000949228475,0.03365502009180553
0.0344029488933865,285.376222392001,0.10922936273650213,57.531846434227404,295.19400598634076,0.033824399296453436
0.0345786306707314,285.415651565039,0.10978715237957219,57.53979535551187,295.28493396815264,0.03399422369653734
0.0347578573565873,285.492993404458,0.11035619710716467,57.55538747033873,295.4161181455152,0.034167445100925564
0.0349343872219815,285.571851750533,0.11091667942979126,57.571285312907456,295.5481293992844,0.03433803071942481
0.0351110961387001,285.662842149851,0.11147773024037282,57.58962897740996,295.6927776638287,0.03450876022133021
0.035283211019388,285.738667482615,0.1120241949865569,57.60491536449519,295.82044518380286,0.034675023121580016
0.0354584315612184,285.822075348656,0.1125805202068684,57.62173039028906,295.95687784609174,0.03484425769787436
0.035631662352352,285.925197801215,0.1131305279687176,57.64251987672495,296.11318790729734,0.03501154234864527
0.0358090424664998,286.023770733809,0.11369370983113687,57.6623921799359,296.26600808644434,0.035182804904381214
0.0359881570958059,286.114761133126,0.11426239877918372,57.6807358444382,296.4115041042139,0.03535571239724786
0.0361712735256898,286.173904892683,0.11484379344406512,57.692659226364896,296.525179482471,0.035532452109120066
0.0363470853481718,286.219400092341,0.11540199598044545,57.701831058615944,296.6226410557998,0.03570211219647312
0.0365271814060035,286.307357478348,0.11597380096406111,57.71956326763496,296.76535826283316,0.035875876771752364
0.0366974263327363,286.401380890976,0.11651432860643775,57.738518387620765,296.9115744678165,0.036040108786440844
0.0368814728608058,286.499953823569,0.11709867633305841,57.75839069083151,297.06649409513506,0.03621762460570816
0.0370639949123291,286.563647103091,0.11767818384664487,57.771231255983146,297.1848406613784,0.03639363892703982
0.0372457426346844,286.601559769474,0.11825523286512296,57.778874449525965,297.27624770334694,0.0365688757487455
0.0374214551029857,286.645538462477,0.1188131199519796,57.78774055403537,297.37223161052174,0.03673826433204505
0.0376041353018775,286.703165715378,0.11939312958346106,57.79935820822021,297.4843903504157,0.03691433946115042
0.0377875600255973,286.775958034832,0.11997550308127142,57.81403313982213,297.61252176297137,0.03709110100896845
0.0379795040519401,286.84723384763,0.12058492536490982,57.8284023436822,297.74154952783385,0.037276038934048496
0.038159122334689,286.954905820156,0.12115521341263757,57.850109013343456,297.9048531758865,0.03744907004181194
0.0383403598342946,287.039830192852,0.12173064247388536,57.867229766878964,298.04504056922076,0.03762363064403894
0.0385202411273039,287.13688661879,0.12230176557918988,57.88679634234807,298.19746872788915,0.0377968548781314
0.0387032740453122,287.202096404967,0.12288289509386623,57.89994263524135,298.3177578485166,0.0379730833072291
0.0388853831035876,287.34919755053,0.12346109135389062,57.92959822618685,298.5228811817908,0.038148391405985985
0.0390666520840314,287.444737469813,0.12403662036679969,57.9488590739143,298.67424102193195,0.03832286028479949
0.0392483236903822,287.519046295923,0.12461342771696347,57.96383973325808,298.80368689209536,0.038497686149917235
0.0394300121283341,287.526628829199,0.12519028850746075,57.96536837196653,298.86380729115336,0.0386724976494012
0.0396075576784875,287.593355122032,0.12575399562919778,57.97882039260165,298.9842255229776,0.038843293553393894
0.039787345307272,287.652498881588,0.1263248213505886,57.99074377452814,299.09742818308933,0.03901621657919741
0.0399675327930856,287.7707864007,0.12689691661804675,58.01459053838112,299.272274743062,0.03918949419778777
0.0401483469217188,287.769269894045,0.12747100147645718,58.014284810639474,299.32273037516086,0.03936334425186595
0.0403294190101532,287.799600027151,0.12804590535723642,58.020399365473644,299.4063906876005,0.03953741204711647
0.04051373588696,287.845095226809,0.12863111144109798,58.0295711977247,299.5067753911848,0.03971456800128345
0.0406940444927555,287.913338026297,0.1292035912644987,58.04332894610148,299.6296962139969,0.0398878410477773
0.0408771708243469,287.98309733244,0.12978501736730141,58.05739242221991,299.7550315966227,0.040063791148082666
0.0410572878612408,288.068021705137,0.13035688895943953,58.07451317575563,299.895313395903,0.04023681968564469
0.0412365224635472,288.14081402459,0.13092595882176233,58.089188107357344,300.02273917477976,0.040408970802706404
0.0414146784555314,288.228771410597,0.1314916040963122,58.10692031637635,300.1656733001997,0.04058005657294019
0.0415945782701949,288.300047223396,0.1320627860078688,58.12128952023664,300.29176610293047,0.04075278726487545
0.041771885220424,288.345542423054,0.1326257355748462,58.130461352487686,300.3902793249707,0.04092299923071473
0.041948170358626,288.425917275784,0.13318544088863754,58.14666492279805,300.52485678951155,0.041092201555326884
0.0421279481662594,288.491127061962,0.1337562354278736,58.15981121569155,300.6446663092541,0.04126472673949003
0.0423078577954686,288.541171781586,0.1343274485006128,58.16990023116774,300.7487306454592,0.04143734863472078
0.0424907924969861,288.55936986145,0.13490826617793086,58.17356896406833,300.820486169294,0.04161284251463238
0.0426738120820129,288.594249514521,0.13548935336039095,58.180600702127435,300.9096662862532,0.041788387011306494
0.0428596630279706,288.66855834063,0.13607943011380663,58.19558136147101,301.04079547787944,0.04196661569827566
0.0430457661194307,288.758032233292,0.13667030742919248,58.21361929823167,301.18784295391333,0.042145054365104524
0.0432313967523985,288.814142979538,0.13725968468886524,58.22493122467487,301.2999817823904,0.04232300831749508
0.0434138952391898,288.893001325613,0.1378391173844276,58.24082906724359,301.4349718204983,0.04249792878716671
0.0435993202575499,288.968826658377,0.13842784181772094,58.2561154543288,301.567671076304,0.04267562293636637
0.0437834019591011,289.082564657524,0.13901230122014596,58.279045034956845,301.7395827852922,0.04285199854786206
0.0439691207561511,289.162939510254,0.13960195840077974,58.295248605267204,301.87717971578394,0.043029911203235904
0.0441536757219103,289.234215323053,0.14018792041706518,58.30961780912749,302.00496907410826,0.04320667759508905
0.044337119439091,289.279710522711,0.1407703542191139,58.318789641378544,302.1055395994621,0.04338234867592637
0.0445253568729178,289.331271748991,0.141368008071514,58.329184384596594,302.21384987811,0.04356257828555465
0.0447111331035492,289.397998041824,0.1419578476037687,58.342636405231715,302.3373104521727,0.04374041955150263
0.0448957307437077,289.517802067592,0.14254394511127194,58.36678889682655,302.5159153547287,0.04391710124587529
0.0450830612040577,289.596660413666,0.1431387193228832,58.38268673939506,302.652564379586,0.04409636666385327
0.0452710039086318,289.689167319639,0.14373543740990596,58.401336131639226,302.80368674565466,0.044276185679413375
0.0454572393996413,289.755893612472,0.14432673509386112,58.414788152274355,302.9273966358711,0.04445433938456205
0.0456451742613719,289.846884011789,0.14492342827985577,58.43313181677666,303.07699554162275,0.0446340865466416
0.0458353474330882,289.922709344553,0.14552722810005503,58.44841820386189,303.2114174561028,0.04481594162037305
0.046026377650172,289.960622010935,0.1461337490392961,58.456061397404504,303.30645910328906,0.04499858296355954
0.046215335426693,289.963655024246,0.14673368997975025,58.456672852888,303.36442260274146,0.04517921006400763
0.0464014903195236,289.989435637386,0.1473247317644874,58.46187022449702,303.44537762787826,0.04535712595480168
0.0465895953949011,290.019765770492,0.147921965378811,58.46798477933118,303.5316693142632,0.04553687356784021
0.0467763609898928,290.066777476805,0.14851494614290964,58.477462339323885,303.6350457712349,0.04571530925407801
0.0469594126197128,290.107723156498,0.14909613506758815,58.485716988350006,303.7310114323694,0.04589016573080605
0.0471435734834657,290.165350409399,0.1496808458100036,58.497334642534845,303.8447819287801,0.04606605093363497
0.0473285974366427,290.219944648989,0.15026829686134058,58.508340841236176,303.9556475773657,0.046242729293201716
0.0475207675139808,290.276055395235,0.15087843685688904,58.51965276767938,304.07019633854736,0.04642619840663056
0.0477142881819983,290.336715661447,0.1514928649778446,58.531881877347715,304.18992538233215,0.046610922949150674
0.0479026305410445,290.398892434313,0.1520908519678163,58.5444167147575,304.30976328812244,0.04679067179338903
0.0480900700058651,290.456519687214,0.15268597226862168,58.556034368942335,304.424594052632,0.04696952686790454
0.0482833501487533,290.526278993358,0.15329963672229172,58.57009784506097,304.55386104940874,0.04715392163419739
0.0484727877076214,290.571774193016,0.15390110097169796,58.57926967731203,304.656598117301,0.047334617477613056
0.0486614640940445,290.630917952572,0.15450014849859128,58.59119305923852,304.7734439311403,0.04751455482475252
0.0488474889138137,290.667314112299,0.15509077730135848,58.59853052503948,304.8656825160075,0.047691931726996595
0.0490314144124975,290.69612773875,0.15567474075967955,58.604339352132,304.94937004601695,0.04786727597481124
0.0492178254468672,290.735556911787,0.15626659579380336,58.61228827341626,305.04492880306907,0.0480449584267516
0.0494079558094051,290.793184164688,0.15687025969486118,58.6239059276011,305.1606809575731,0.048226153535242434
0.0495955660798329,290.834129844381,0.15746592230346945,58.6321605766272,305.25821314934865,0.04840491480836162
0.0497841602783617,290.888724083971,0.1580647088837984,58.64316677532855,305.37037494693556,0.04858458139908685
0.0499764412849434,290.947867843528,0.1586752010796953,58.655090157255245,305.4884068777896,0.04876772704623925
0.0501627247544551,291.034308722879,0.15926665109539495,58.67251663853241,305.6333826454479,0.04894512811852297
0.0503525376252369,291.126815628851,0.15986930696012716,58.69116603077636,305.78578956651813,0.049125857937246976
0.0505422608096018,291.213256508203,0.1604716780704857,58.70859251205373,305.9318328698541,0.04930646972706331
0.05073403602332,291.263301227827,0.161080564374041,58.718681527529924,306.0402640445907,0.04948900185245746
0.0509263308153058,291.310312934141,0.1616911003385959,58.728159087522826,306.14567830053534,0.049671995066353156
0.0511199142276131,291.346709093868,0.16230572767267157,58.73549655332379,306.24032787324387,0.049856180750479775
0.0513123886724912,291.374006213663,0.16291683403515955,58.74099965267447,306.3251024695593,0.050039277676026665
0.0515080118580602,291.389171280216,0.16353793764934113,58.74405693009154,306.3980481698277,0.05022533558766198
0.051705562579156,291.413435386701,0.1641651611888203,58.74894857395893,306.48113100649493,0.05041319166093753
0.0519067505714455,291.428600453254,0.16480393306433944,58.752005851376005,306.5557121263665,0.05060447024553708
0.052104931334851,291.458930586359,0.16543315698815192,58.758120406209976,306.6453781514903,0.050792853956232106
0.0523016865551641,291.492293732776,0.166057854812646,58.76484641652763,306.73783231283346,0.050979847495611734
0.052497328769844,291.527173385847,0.16667901884425468,58.77187815458676,306.8315712524271,0.051165748585282333
0.052694317186417,291.577218105472,0.16730445706687397,58.78196717006316,306.9416805206548,0.05135289393855809
0.052892849988314,291.613614265199,0.16793479871289693,58.78930463586411,307.03788941907817,0.051541471078066114
0.0530919110821044,291.630295838407,0.16856681768568146,58.79266764102285,307.1135055739075,0.051730514320983204
0.0532873065975457,291.662142478168,0.1691871984472076,58.79908792359868,307.2040324872992,0.05191604170784846
0.0534841547654646,291.70005514455,0.16981219138035009,58.80673111714128,307.30138603899564,0.05210291358465314
0.0536860058144248,291.737967810932,0.17045306846079872,58.81437431068389,307.4002140471182,0.052294498539066286
0.0538903434046328,291.78042999728,0.17110184030970912,58.82293468745166,307.5045775685848,0.0524884061912601
0.0540933748755039,291.798628077144,0.17174646522972487,58.82660342035222,307.5830006538787,0.05268103715869913
0.054299196655182,291.825925196939,0.17239994938020284,58.832106519702904,307.671838498288,0.052876277630621756
0.0545060755265358,291.879002929874,0.17305678979675115,58.842806990662595,307.7881819081797,0.053072482443599564
0.0547164867376905,291.919948609567,0.17372484539216734,58.85106163968871,307.8927826061297,0.053271997862803906
0.0549280739792588,291.947245729362,0.17439663488414667,58.856564739039385,307.98334564082523,0.053472588280941244
0.055136144937891,291.973026342502,0.1750572601778039,58.86176211064841,308.0712934408769,0.05366980593663276
0.0553422362563522,292.007905995573,0.17571160011391823,58.86879384870752,308.1682765179027,0.053865108879276154
0.0555500994830511,292.065533248474,0.1763715658586872,58.880411502892365,308.2898026759971,0.05406205234612323
0.0557548125299918,292.107995434822,0.17702152978272395,58.88897187966011,308.3944219588022,0.05425597322076092
0.0559575568375134,292.132259541307,0.17766524295910502,58.89386352352749,308.4792670586609,0.05444799208761572
0.056162997086174,292.145908101205,0.17831751574860244,58.89661507320293,308.55369788663063,0.054642526674125634
0.0563680331889598,292.174721727655,0.17896850537494735,58.902423900295254,308.64403613897457,0.054836640843802936
0.0565821807845359,292.192919807519,0.17964842399090147,58.90609263319583,308.72583242002946,0.055039340931001546
0.0567906078419868,292.195952820829,0.18031017989830808,58.90670408867913,308.7899385904924,0.055236586830303726
0.0570021767768926,292.192919807519,0.180981911266634,58.90609263319583,308.8485522753436,0.055436766277553055
0.0572186355532201,292.205051860761,0.1816691678814738,58.90853845512942,308.92462622999165,0.05564153086583191
0.0574340517278397,292.229315967245,0.18235311423589104,58.913430098996585,309.01322961689897,0.05584526756137584
0.0576477987989725,292.267228633628,0.18303176118673767,58.921073292539404,309.1157910254327,0.05604738463009086
0.0578640111080422,292.277844180215,0.18371823526803396,58.92321338673135,309.1902126024936,0.056251791250569116
0.0580761323760224,292.306657806665,0.18439172029387113,58.929022213823664,309.28269795983755,0.056452289614706705
0.0582973287531415,292.358219032945,0.18509401879122425,58.939416957041715,309.40192224159154,0.05666132302207749
0.058516131291427,292.374900606153,0.1857887168502807,58.94277996220045,309.4835486763406,0.05686805124182368
0.0587352649406537,292.394615192672,0.1864844661865755,58.94675442284268,309.56849038323406,0.05707504947585387
0.0589571267094717,292.400681219293,0.18718887730257264,58.94797733380947,309.6397852318747,0.05728458110613654
0.0591802765458161,292.408263752569,0.1878973780329661,58.94950597251791,309.7130656657279,0.05749528494133338
0.0594032192766294,292.414329779191,0.18860522120329834,58.950728883484906,309.78468233069293,0.05770574889715661
0.0596243602727699,292.424945325778,0.18930734386604442,58.95286897767686,309.86059561862726,0.057914468216411906
0.0598482108722975,292.432527859054,0.19001806951954453,58.954397616385286,309.9340914522817,0.05812570057997957
0.0600725475363797,292.423428819122,0.19073033842800555,58.952563249935004,309.99004914760985,0.058337346854048774
0.0602982513070341,292.441626898986,0.19144694789983324,58.95623198283558,310.0753456103789,0.058550237704677266
0.0605263268904189,292.43707737902,0.19217108787707998,58.95531479961044,310.1372195193413,0.0587653196936439
0.0607517800111366,292.424945325778,0.19288690153535867,58.95286897767686,310.1902812739783,0.058977883167365845
0.0609779761882261,292.421912312467,0.19360507439761784,58.95225752219335,310.25320871837215,0.059191101818125265
0.0612077776052709,292.421912312467,0.1943346938967351,58.95225752219335,310.3204076881965,0.05940767232099682
0.0614400690989884,292.402197725948,0.19507221938928815,58.94828306155111,310.3674089589263,0.05962654187583663
0.0616739879143269,292.400681219293,0.1958149116279879,58.94797733380947,310.43419729895265,0.05984689632689612
0.0619080325374687,292.361252046256,0.1965580033064631,58.940028412525216,310.46076195063074,0.06006732070592693
0.062143622490324,292.350636499668,0.19730600140677867,58.937888318333066,310.5183640891093,0.06028915142578127
0.0623833689819467,292.332438419805,0.19806719651768076,58.934219585432686,310.5691207911399,0.06051484542129427
0.0626236310275319,292.309690819976,0.1988300285124138,58.92963366930717,310.61518504365813,0.06074097366144404
0.0628674778933229,292.264195620317,0.19960424231130022,58.92046183705591,310.6381084774871,0.06097042356677408
0.0631083927688465,292.230832473901,0.20036914704108763,58.91373582673844,310.67305062883094,0.06119706289968407
0.0633520311799119,292.206568367416,0.20114269899622025,58.90884418287107,310.7184479976036,0.06142621215577887
0.0635964323101556,292.183820767587,0.20191867258474402,58.904258266745536,310.7656693471555,0.061656026028107914
0.0638396764712244,292.141358581239,0.2026909727961375,58.89569788997778,310.7915683969292,0.06188469955783191
0.0640885536168167,292.09586338158,0.203481157733393,58.88652605772653,310.81586478316075,0.06211861453974548
0.0643403980857715,292.048851675266,0.20428076392232447,58.87704849773363,310.83939105254507,0.062355262767940865
0.0645815895171337,292.004872982263,0.2050465467168995,58.868182393224224,310.86301182620633,0.06258184827346776
0.0648234121571363,291.93511367612,0.20581433359890774,58.8541189171058,310.8593438730876,0.06280897523226793
0.0650658159835585,291.877486423219,0.20658396574779822,58.842501262920955,310.86873324457576,0.06303659629750086
0.0653110956375836,291.80317759711,0.20736272864932792,58.827520603577376,310.8611628365056,0.06326686508587431
0.0655568861770987,291.724319251035,0.20814311361228838,58.81162276100866,310.84885724326676,0.06349756031683462
0.0658008796686421,291.628779331752,0.20891779294793866,58.79236191328121,310.8182095484736,0.06372651624016107
0.0660439992847164,291.468029626291,0.20968969772897456,58.759954772660265,310.7177439664475,0.0639546000182338
0.0662950515206827,291.351258613834,0.21048678857816755,58.73641373654893,310.66640531425384,0.06419007123659506
0.0665521753753496,291.257235201206,0.21130315681673498,58.717458616563135,310.6410377976561,0.06443117979108515
0.0668077768580169,291.155629255302,0.21211469152420367,58.696974857868895,310.6070895655457,0.06467080319230517
0.0670638783862504,291.047957282777,0.21292781387634502,58.675268188207845,310.5667620945558,0.0649108378062276
0.0673205218027794,290.902372643869,0.21374265672382461,58.645918325004,310.4860721639209,0.06515132252654612
0.0675743752099157,290.791667658033,0.21454864129148235,58.62360019985946,310.441732916274,0.06538913602142846
0.0678310580535541,290.734040405132,0.21536360932003426,58.61198254567462,310.4548379779969,0.06562954268226806
0.0680916585750103,290.605137339433,0.2161910159756577,58.58599568762969,310.3929231312936,0.06587355949122874
0.0683481553820526,290.456519687214,0.21700539333801702,58.556034368942335,310.3086870265259,0.06611367560084169
0.0686075827015616,290.265439848648,0.21782907507745808,58.51751267348744,310.1798500184692,0.06635647643771446
0.0688652268526144,290.074360010082,0.2186470952570507,58.47899097803253,310.0503966163032,0.06659755005619424
0.0691245585164682,289.916643317932,0.21947047328978653,58.447195292895096,309.95700329386045,0.06684014397960795
0.0693823140205745,289.730112999332,0.22028884701532403,58.40959078066533,309.8322586806682,0.06708120516923016
0.0696402766720352,289.536000147455,0.22110787843371177,58.370457629726936,309.6993673042382,0.06732240192314363
0.0698955275636992,289.338854282268,0.22191830001474494,58.330713023305236,309.56234614700344,0.06756100591600009
0.0701499088463004,289.128059857183,0.22272596058700375,58.28821686720809,309.4103669010721,0.06779874038599908
0.0703996569973038,288.965793645067,0.22351891096643955,58.255503998845505,309.30888640163334,0.06803208994830007
0.070647929051978,288.785329353088,0.22430717474003015,58.219122397582545,309.187414812477,0.068264006377813
0.0708920517975369,288.577567941313,0.22508226445717963,58.1772376969687,309.0354238354158,0.06849199441333831
0.0711398561248631,288.357674476296,0.2258690431964403,58.13290717442127,308.8713979510398,0.06872336755723514
0.0713835104938884,288.127165464693,0.22664264581809565,58.08643655768211,308.6946940042163,0.06895081373016564
0.0716252553764585,287.842062213499,0.22741018582025574,58.0289597422414,308.4588234276273,0.06917642632442607
0.071865201907201,287.538760882441,0.22817201605536316,57.96781419390011,308.20279198940403,0.06940031025255783
0.0721020688220365,287.209678938244,0.22892406850996588,57.901471273949994,307.91809097540425,0.06962127156948926
0.0723224095281184,286.860882407528,0.22962365025177592,57.831153893357644,307.6073526226026,0.06982677258767093
0.0724398788551522,286.692297417682,0.2299966153651082,57.7971671594047,307.46025271132413,0.06993631323726883
0.072553784562163,286.500863727562,0.23035826598486753,57.75857412747649,307.28758567132513,0.07004251933853681
0.0726644806825466,286.282714245199,0.23070972616708546,57.71459519183212,307.08529900421627,0.07014572200306311