File: example/data/02 processed data/test_ID_123.csv
Strain,Stress_MPa,Displacement(mm),Force(kN),True Stress (MPa),True Strain
0.000866300493522,0.23158282538816,8.472223939466383e-06,0.046687097598253,0.2315834433477055,2.668413428486512e-06
0.0008281507786499,0.24459653978552,-0.0001126531207793,0.0493106624207608,0.2445878611828306,-3.54819273593615e-05
0.0007904916605793,0.440652849784344,-0.0002322208206535,0.0888356145165237,0.4406206202516195,-7.314309084450617e-05
0.0007707404735825,0.783556709499316,-0.0002949308393682,0.1579650326350621,0.783483923660568,-9.289591764271276e-05
0.0007306007439282,1.37299308454774,-0.0004223744810208,0.2767954058448243,1.372810433448045,-0.0001330401820575
0.000694296335903,2.3074948927932,-0.0005376409765008,0.4651909703871091,2.3071041514365285,-0.0001693500795454
0.000651591554042,3.71285494541227,-0.0006732286589095,0.7485115569951137,3.712067669709711,-0.0002120630062612
0.0006241843451274,5.29967491575787,-0.0007602465472134,1.0684144630167869,5.298405920622104,-0.0002394764035909
0.0006292764237006,7.11855552323199,-0.0007440791977435,1.4351007934835691,7.116887249505118,-0.0002343831184098
0.0006494238558928,9.01552537473401,-0.0006801111005332,1.817529915546376,9.013594175085348,-0.0002142311664981
0.0006611802124613,10.9891766467189,-0.0006427846684282,2.2154180119785303,10.986951867422157,-0.0002024723602168
0.0006856718996241,13.0281837390867,-0.0005650235616863,2.6264818417998788,13.025865241203688,-0.0001779760137002
0.0007206631809637,15.0543649095065,-0.0004539262434331,3.03495996575651,15.052212603581888,-0.0001429791165962
0.0007651491152799,16.9299520755474,-0.0003126834019789,3.413078338430356,16.928284763733124,-9.848781101849856e-05
0.0008000181571676,19.0102537971111,-0.0002019741939855,3.832467165497598,19.00904448035893,-6.361594281667263e-05
0.0008381356960533,21.2000686597434,-8.095100802371202e-05,4.273933841804269,21.19952813472665,-2.5496705518117223e-05
0.0008786865094769,23.4330202431094,4.779782459647419e-05,4.724096881010856,23.43337301394132,1.505431962696791e-05
0.000923705539567,25.7176794380762,0.0001907332451324,5.184684174716161,25.71922438814124,6.007165869560842e-05
0.0009683121652585,28.0881032870658,0.0003323592817028,5.662561622672465,28.091043552210014,0.000104674610147
0.0010122329824233,30.4419927369732,0.000471807876201,6.1371057357737975,30.44651644467102,0.0001485898658692
0.0010656217036059,32.9290305778618,0.0006413170659558,6.638492564496939,32.93568190046809,0.0002019692299145
0.0011121619000985,35.2981930537547,0.0007890821898198,7.116115719636948,35.30696570744652,0.0002484989451447
0.0011523035266322,37.6650511493062,0.0009165318540643,7.593274311700131,37.67592397423952,0.0002886297925125
0.0011839533745353,40.0502384415881,0.0010170201211566,8.07412806982416,40.063067385951,0.000320270006088
0.0012284611361744,42.4239301689182,0.0011583322643608,8.552664322053909,42.43940765146801,0.0003647625257016
0.001275492458186,44.743808809962,0.0013076567117476,9.02035185608834,44.76223701213507,0.0004117755904463
0.0013220404351592,47.0761865726451,0.0014554465386375,9.490559213045252,47.09776669006224,0.0004583033216131
0.0013553051833901,49.302399034046,0.0015610621142706,9.939363645263674,49.326639697754565,0.0004915522752397
0.0014011282082243,51.540690897461,0.0017065502181192,10.390603284928138,51.56839381944307,0.0005373517323856
0.0014552837369681,53.7117333293344,0.0018784940218808,10.828285439193817,53.74351196554354,0.0005914767035969
0.0015148266794427,55.8535504608796,0.0020675428642376,11.260075772913329,55.88992199149306,0.0006509826677064
0.0015599156880656,58.0561936935774,0.0022107004666153,11.704128648625204,58.096617269794194,0.0006960413185618
0.0016019480649972,60.238688216824,0.0023441532633732,12.14411954451172,60.28316340345858,0.0007380435672949
0.0016388210224609,62.3796810344313,0.0024612249033204,12.575743696541352,62.42803707361969,0.0007748886421615
0.0016925356457005,64.422710882978,0.0026317688321061,12.987618514008364,64.47611109796433,0.0008285602183272
0.0017397151584368,66.4701720738513,0.0027815637850439,13.400386690088425,66.52840546705643,0.0008756995451108
0.0017703794342817,68.5846360133347,0.0028789228608514,13.826662620288277,68.64682495082194,0.0009063365107005
0.0018129439981822,70.8176595121041,0.0030140653512355,14.276840157640184,70.88488756054223,0.0009488616100549
0.0018584369185384,72.8989168571485,0.0031585053733665,14.69642163840114,72.97143705261493,0.0009943103515888
0.001903949985272,74.9310999230908,0.0033030093602456,15.106109744495104,75.0090520882623,0.0010397771530692
0.0019586948012157,76.9963680352133,0.0034768241508669,15.522467795899,77.08068388778459,0.001094463580857
0.0020023632975881,79.088294760099,0.0036154716268493,15.94420022363596,79.17835507056232,0.0011380833584389
0.0020437494631851,81.1662311790574,0.0037468727026197,16.363112205697973,81.26201685968081,0.0011794215954851
0.002093281243545,83.2503219785185,0.0039041361052624,16.78326491086933,83.35269066759285,0.0012288937676622
0.0021410047457921,85.1329090144374,0.004055658224897,17.162794457310582,85.24165546566695,0.0012765575228808
0.0021909961115897,87.0602172333362,0.0042143808113043,17.55133979424058,87.17577783457592,0.0013264838661991
0.0022439963755974,88.9845351779545,0.0043826566495288,17.939282291875628,89.10736625348297,0.0013794124720764
0.0022863440476979,90.9224609608043,0.0045171105084479,18.32996812969815,91.051817434461,0.0014217008753733
0.0023272063798103,92.8447826136629,0.0046468484129047,18.717508174914443,92.98066785168962,0.0014625043222771
0.0023799615232655,94.7292371111026,0.004814345993375,19.097414201598287,94.87287784280063,0.0015151809800593
0.0024349739074308,96.5310551654126,0.0049890103130998,19.46066072134718,96.68273845037469,0.0015701085650752
0.002480520780999,98.3893066494505,0.0051336216366789,19.83528422052922,98.54839120801223,0.0016155829472444
0.002524523747687,100.249967361872,0.0052733310559133,20.210393420153395,100.41647169769676,0.0016595139159059
0.0025627444992908,102.132606198088,0.0053946819422553,20.58993340953454,102.3061409780478,0.0016976705642671
0.0026071559271465,103.918628030938,0.0055356882256972,20.949995411037097,104.09981263743296,0.0017420056772959
0.0026514783691334,105.724593336783,0.0056764119790056,21.31407801669545,105.91361265901683,0.0017862499977539
0.0026984055392805,107.556387546238,0.0058254057442226,21.68336772932158,107.7537291518568,0.001833092321945
0.0027362330047052,109.316822667595,0.0059455079469461,22.03827144978716,109.52152945118716,0.0018708497968265
0.0027763562592436,111.151777116182,0.0060728992801055,22.408198266622293,111.36437980822336,0.0019108972550456
0.0028177245947826,112.924306468596,0.0062042437454418,22.76554018406896,113.14497101099478,0.0019521857630443
0.0028664715993424,114.690325434313,0.0063590154849192,23.1215696075575,114.92003175097668,0.0020008365137566
0.0029074653917357,116.593603242815,0.0064891707757679,23.505270413751504,116.83190113346215,0.0020417475294077
0.0029516120771254,118.381101727179,0.0066293365018802,23.86563010819929,118.62827910003342,0.0020858031999016
0.002991469583003,120.090430694206,0.0067558840830416,24.21023082795193,120.34596361680524,0.0021255768665244
0.0030337017537336,121.832493644233,0.0068899712251112,24.56143071867737,122.09687864438808,0.0021677184768964
0.003074450971997,123.541956696376,0.0070193499930975,24.906058469989404,123.8150855886229,0.0022083786313622
0.0031210452118591,125.288880937433,0.0071672867046597,25.258238396986496,125.57170970297145,0.0022548690063415
0.003162118530961,127.013182763162,0.0072976944928082,25.60585764505346,127.3051208432769,0.0022958489751376
0.0032108247460627,128.615520119052,0.0074523367257561,25.928888856000885,128.91740552506317,0.002344442315715
0.0032662311606804,130.273883690715,0.0076282520921673,26.263214952048145,130.5868796043586,0.0023997174576401
0.0033087681868773,131.952864575841,0.0077633071503425,26.60169749848955,132.27550728987873,0.0024421516290304
0.0033510147260039,133.656676047174,0.0078974399120694,26.94518589111028,133.98913134415966,0.0024842942335694
0.0034015055974838,135.351240978371,0.0080577484290181,27.2868101812396,135.69474530887783,0.0025346585582435
0.0034497524768641,137.013625435041,0.0082109322710506,27.62194688770427,137.36795916690184,0.0025827821451495
0.0034841259831412,138.624625821459,0.0083200681534803,27.946724565606136,138.98789080872993,0.0026170663989867
0.0035248843436336,140.323036558272,0.0084494759480437,28.28912417014764,140.6964715574391,0.0026577174053361
0.0035582772017125,142.003042487386,0.0085554982724442,28.62781336545702,142.38569029358527,0.0026910210778916
0.0035964878330654,143.658194315889,0.0086768170269897,28.961491974083224,144.0507914391982,0.0027291282957699
0.0036443689779383,145.363066430269,0.0088288396619611,29.305194192342228,145.767282873193,0.0027768778049801
0.0036813930282031,146.975753803603,0.0089463910215519,29.630311966806367,147.38989634351304,0.0028137985050193
0.0037140532007192,148.618215354585,0.0090500870692905,29.961432215484336,149.04183985507055,0.0028463663772235
0.003759579385385,150.304405197543,0.0091946327056044,30.301368087824667,150.7396788352834,0.0028917621315324
0.0038059697413163,151.890040045079,0.0093419220856863,30.621032073087928,152.33695183080903,0.0029380174615726
0.0038455887629126,153.511919382678,0.0094677124792545,30.948002947547884,153.9696852771201,0.0029775194724043
0.0038902759478916,155.173482924707,0.0096095942915629,31.28297415762093,155.6431377957984,0.0030220728057988
0.0039282355815225,156.833764214471,0.009730116128341,31.61768686563736,157.3143975179833,0.0030599171797126
0.003978359841974,158.537107549585,0.0098892606552745,31.96108088199633,159.03090748032236,0.0031098870499836
0.004025006648747,160.181994873236,0.0100373642667788,32.29269016644438,160.68839015875474,0.0031563879346097
0.0040806723174538,161.902862411001,0.0102141027649229,32.6396170620578,162.42371043449742,0.0032118766383458
0.0041105477209193,163.760872934777,0.0103089571709258,33.014191983651045,164.29259067504728,0.0032416557962321
0.0041550048775553,165.474688942705,0.0104501086432451,33.359697290849326,166.01932783314862,0.0032859680895975
0.0041951573556716,167.163738530056,0.0105775927612644,33.70020968765929,167.72064875072417,0.0033259880436805
0.0042429777412909,168.752031752618,0.0107294224856056,34.020409601327785,169.32230319954027,0.0033736485076974
0.0042805599690761,170.34364125452,0.0108487460588237,34.34127807691124,170.9256931936399,0.0034111034584413
0.0043240860842241,171.979727423912,0.0109869414744186,34.671113048660665,172.57485536091767,0.0034544804136527
0.0043624298171165,173.583550241421,0.0111086828263519,34.994443728670475,174.19088397480812,0.0034926911873531
0.0044158385589515,175.039278270746,0.0112782555816781,35.28791849938239,175.66105392969715,0.0035459122980624
0.004463004963992,176.605988514405,0.0114280089176816,35.603767284504045,177.24165932122662,0.0035929106469006
0.0045128572749774,178.246468462332,0.0115862900050603,35.93448804200613,178.8969299665784,0.0036425829306856
0.0045601832565778,179.851963266189,0.0117365499966416,36.2581557944637,180.516795253234,0.0036897357253523
0.0046127952814906,181.479884854268,0.0119035931757397,36.58634478662043,182.1602825610035,0.0037421526097021
0.0046676812496768,183.068087917493,0.0120778561247309,36.90652652416659,183.7644879259645,0.0037968320750947
0.0047194851478495,184.689808891512,0.0122423335014292,37.23346547252882,185.4019456583672,0.0038484383238683
0.004772634321562,186.272769116005,0.0124110821279664,37.55259025378661,187.0009097886672,0.0039013819478034
0.0048245269779388,187.861525672109,0.0125758413119627,37.87288357549718,188.605625431314,0.0039530712096048
0.0048777346877274,189.420860673057,0.0127447757905415,38.187245511688296,190.18121544449937,0.0040060675963795
0.0049307199887095,191.02291747779,0.0129130041211597,38.51022016352246,191.79982447641257,0.0040588396667962
0.0049838763067569,192.561291072212,0.0130817754309602,38.82035628015794,193.3546906207167,0.0041117792678076
0.005035049854841,194.101654456069,0.0132442514461272,39.13089353834352,194.91133354826604,0.0041627415349556
0.0050881422124577,195.515836386184,0.0134128196815602,39.41599261545469,196.3417950187312,0.0042156119445108
0.0051492779173227,196.950054116072,0.0136069255445066,39.70513090980012,197.79411229633783,0.0042764886144168
0.0052116399462605,198.3405387669,0.0138049249863841,39.98545261540704,199.20292499034448,0.0043385825944141
0.0052820198902637,199.636532783809,0.0140283813085943,40.2467250092159,200.5186044074364,0.0044086553954956
0.0053594660179953,200.951253746388,0.0142742727641421,40.51177275527182,201.8546972135604,0.0044857578689922
0.0054327432075553,202.194912856649,0.0145069278409951,40.76249443190044,203.1187638836184,0.0045587044302992
0.005517309380881,203.427439082003,0.0147754254413042,41.010971718931806,204.3741247383405,0.0046428824257531
0.0056064589127741,204.620018655366,0.0150584752050648,41.25139576092179,205.5904959710768,0.0047316150693781
0.0057031881192948,205.687989620369,0.015365590435768,41.46669870746639,206.68342817345976,0.0048278830377079
0.0058086182358548,206.650616650931,0.015700331055846,41.66076431682769,207.67250109008512,0.0049327998727644
0.0059212281320759,207.557054455393,0.016057867476348,41.84350217820723,208.60679419530663,0.0050448493769147
0.0060394914058638,208.324325756521,0.0164333533706246,41.99818407251463,209.4025831615144,0.0051625106103474
0.0061728940466044,209.027613040738,0.016856906754976,42.13996678901278,210.13739539735,0.0052952175272235
0.0063070552272806,209.581996691195,0.0172828685036229,42.25173053294491,210.7228401839637,0.0054286612688314
0.0064578815381661,210.020706333349,0.0177617420406844,42.34017439680316,211.1956145566861,0.005578659762865
0.0066096265999967,210.413856865804,0.0182435326119966,42.41943354414609,211.6228937350157,0.0057295492631096
0.0067656391223748,210.747665994663,0.018738872370547,42.48672946452406,211.99150020425816,0.0058846584298914
0.0069195695748876,211.013761578782,0.0192276015572752,42.54037433428245,212.29164773019576,0.0060376740068131
0.0070834335266346,211.162015666132,0.0197478696040719,42.57026235829221,212.4754014773785,0.0062005383190318
0.0072542568532295,211.258512961226,0.0202902336660107,42.58971621298316,212.608586848444,0.0063702913172068
0.0074313937422163,211.305875507154,0.0208526432885438,42.59926450224225,212.69368213604352,0.006546287890844
0.0076066215537712,211.331962991235,0.0214089915902306,42.60452373903298,212.7569721938889,0.0067203572061723
0.0077899965277313,211.305814273028,0.0219912071325539,42.59925215744244,212.76939535334017,0.0069024873797376
0.0079745165427384,211.270836863137,0.0225770581802015,42.59220071160842,212.7731593751492,0.0070857213448715
0.0081606949818189,211.199774558618,0.023168174724282,42.5778745510174,212.7409125991544,0.007270568152941
0.0083475683310682,211.15610394554,0.0237614976081486,42.56907055542087,212.7363827672244,0.0074560705473581
0.0085418047727573,211.0915382746,0.0243781983105115,42.55605411615936,212.712335560184,0.0076488455518383
0.0087333429782584,211.025289780104,0.0249863321129775,42.542698419668966,212.6859978036262,0.0078389062372096
0.0089284669878435,210.939150252228,0.0256058508434102,42.52533269084916,212.6403396753443,0.0080324879292341
0.0091205827749712,210.834290702021,0.0262158184675406,42.50419300552743,212.5751390458877,0.008223048571965
0.0093204618358641,210.736571016595,0.0268504344858756,42.48449271694555,212.51873432174747,0.0084212711095249
0.0095181515631165,210.633385323909,0.0274780993699019,42.463690481300056,212.4563160617197,0.0086172838164678
0.0097229228592173,210.524072476283,0.028128248235022,42.44165301121866,212.38916645110527,0.0088202775166959
0.0099190524032954,210.410505813838,0.0287509595374699,42.41875797206974,212.3158613851489,0.0090146658559214