File: example/data/02 processed data/test_ID_055.csv
Strain,Stress_MPa,Displacement(mm),Force(kN),True Stress (MPa),True Strain
0.0003610820172781996,0.147058556774808,5.5463706333147794e-05,0.0296470050458012,0.1470611257236605,1.7468731305366435e-05
0.00036457516419499957,0.148082943835747,6.655444779413607e-05,0.0298535214772865,0.1480860479549768,2.096181110107729e-05
0.00036233174288519956,0.167631981723558,5.943158513532231e-05,0.0337946075154693,0.1676351195611621,1.871843430055704e-05
0.00035996264387119954,0.192969697445978,5.190969576602821e-05,0.0389026910051091,0.1929728524060682,1.6349376825675022e-05
0.0003631241032546996,0.221216993897371,6.194732930855594e-05,0.0445973459697099,0.2212213100554716,1.951077952436196e-05
0.00036516500519429956,0.25691428591391,6.842719296680816e-05,0.0517939200402442,0.2569198228976637,2.155163956227692e-05
0.0003676168519804996,0.293612184970729,7.62118065128417e-05,0.0591922164900989,0.2936192327549907,2.4003430502152905e-05
0.0003687884970727996,0.329596998491792,7.993177968107836e-05,0.0664467548959452,0.3296052962160966,2.5175046784925667e-05
0.00036282059970909957,0.365590622434757,6.098370555111147e-05,0.073703069482847,0.3655976445043226,1.9207281854210623e-05
0.0003563977405303996,0.384506456838913,4.059112765887963e-05,0.0775165016987248,0.3845113726029052,1.27845254143244e-05
0.0003485717255902996,0.394041652314453,1.574353022418741e-05,0.0794387971065937,0.3940436062063153,4.958579902846777e-06
0.00033005054458179955,0.403683916866552,-4.306121947793395e-05,0.0813826776402968,0.4036784418675775,-1.356268078464987e-05
0.0003134806805100996,0.409946092672834,-9.567053790543254e-05,0.0826451322828433,0.4099337399915117,-3.0132906875113865e-05
0.00030177119812599954,0.450615345241751,-0.0001328481444751,0.090844053600737,0.4505964906236447,-4.184281066598703e-05
0.0002886277223492996,0.614013137913863,-0.0001745786800661,0.1237850486034348,0.6139793761490882,-5.498692279755847e-05
0.00028159241444949956,0.990953560257275,-0.0001969157826481,0.1997762377478666,0.9908921006050276,-6.202264230854866e-05
0.00027607596671759955,1.64084373490912,-0.0002144305041967,0.3307940969576786,1.640732916972306,-6.753944741331085e-05
0.00027872594136799957,2.59359019336549,-0.0002060168346816,0.5228677829824828,2.593421902580577,-6.48892972906014e-05
0.00029114790698119957,3.89339922502937,-0.0001665770938597,0.784909283765921,3.8931949569575135,-5.246660276068866e-05
0.0003059636107886996,5.52538000349883,-0.000119537234271,1.1139166087053642,5.525171975579487,-3.7650231366053696e-05
0.00032033074254979955,7.50820431625458,-7.39215909294933e-05,1.5136539901569233,7.508029507307153,-2.328266188299481e-05
0.00034245377220449956,9.76211401340587,-3.6809717757920734e-06,1.968042185102624,9.76210269558976,-1.1593618613332142e-06
0.00036626010566429956,12.2135472996604,7.190413695911531e-05,2.4622511356115364,12.21382389952742,2.26467158318076e-05
0.00039437273272909955,14.8102833575851,0.0001611617278898,2.985753124889156,14.811035121634372,5.075831111044559e-05
0.0004213634041491996,17.5199640205492,0.0002468571096487,3.5320247465427186,17.521326202495423,7.774724835976473e-05
0.00044900267296489957,20.3206153297892,0.0003346117881385,4.096636050485503,20.32275691008261,0.0001053839864839
0.0004788560391627996,23.2225873619238,0.0004293962258168,4.681673612163839,23.225728052118104,0.0001352337612717
0.0005150099758116995,26.1785984029967,0.0005441849746771,5.277605438044135,26.1830853321019,0.0001713821556573
0.0005505698997696996,29.1847400875646,0.0006570877332438,5.883643601653023,29.190780067000645,0.0002069353537787
0.0005852957001640995,32.2167871641982,0.000767342149496,6.494904292302358,32.22457340001314,0.0002416533662435
0.0006235080337644996,35.2891455659088,0.0008886663086772,7.114291746087214,35.29902281779114,0.0002798557371007
0.0006613182832734995,38.4074800194281,0.0010087138508683,7.742947971916704,38.419682273624176,0.0003176546922853
0.0007044590309259996,41.5471228453016,0.001145685724665,8.375899965612803,41.5621149541346,0.0003607808083091
0.0007459088108805995,44.7015935993965,0.0012772887760209,9.011841269638335,44.71957685727832,0.000402214778277
0.0007877440349421996,47.8795942004791,0.0014101156124164,9.652526190816586,47.90085900781714,0.0004440323046119
0.0008343086457369995,51.1080901543093,0.0015579582516899,10.303390975108757,51.133168664792464,0.0004905751606695
0.0008820229046035996,54.3839967806562,0.0017094510235914,10.96381375098029,54.41327765592035,0.0005382648806737
0.0009298842792574996,57.6609020726713,0.0018614108881175,11.624437857850536,57.69470699580098,0.0005860993560758
0.0009808982087614996,60.9636729830996,0.0020233801142927,12.29027647339288,61.002524222031326,0.0006370820954669
0.0010273175773415995,64.2870922813771,0.0021707616095345,12.960277803925624,64.33104565205836,0.0006834708245428
0.0010741086196936996,67.6479813750658,0.0023193231690025,13.637833045213265,67.6973979201176,0.0007302288043377
0.0011224760385465996,71.0139967033423,0.0024728897238604,14.316421735393808,71.06930687112119,0.0007785597488415
0.0011674653215589996,74.3707347253824,0.0026157306974248,14.993140120637094,74.43200521792139,0.000823513008228
0.0012168122807078995,77.73565003267,0.0027724072927225,15.671507046586273,77.80352873599443,0.0008728181307247
0.0012694959000226996,81.1088767541977,0.002939677784047,16.351549553646255,81.18397406540504,0.0009254544015703
0.0013223833639847997,84.4437455056709,0.0031075954821267,17.023859093943255,84.52639652993146,0.0009782915473306
0.0013728076462194995,87.773270119212,0.0032676925782219,17.69509125603314,87.86360588719147,0.0010286652552613
0.0014256133656804996,91.0933893209124,0.0034353507375105,18.36442728709594,91.19195238931742,0.0010814152919345
0.0014742189558180996,94.4234888839346,0.0035896734861974,19.035775359001214,94.5302446302404,0.0011299671689929
0.0015246083524083996,97.7559440054167,0.0037496598203716,19.707598311492006,97.87139330791736,0.0011802983927394
0.0015753988662041995,101.030436287347,0.0039109197016733,20.36773595552916,101.15488413734538,0.0012310277071843
0.0016266326888139996,104.302857174281,0.0040735870884594,21.02745600633505,104.4366797797218,0.0012821971891633
0.0016756471423160996,107.604228612178,0.0042292079783286,21.69301248821509,107.7475611041933,0.0013311476386515
0.0017298217959706996,110.904289094843,0.0044012125036819,22.358304681520348,111.05802558110322,0.0013852487623279
0.0017826814231473997,114.178792120351,0.0045690418199679,23.01844449146277,114.34310319945376,0.0014380338233086
0.0018308176853978997,117.438193694686,0.0047218744526133,23.675539848848697,117.6128483109279,0.001486099758548
0.0018820092316265997,120.686113252501,0.0048844076118894,24.330320431704205,120.87177629823957,0.0015372139791783
0.0019346190235175996,123.948222993824,0.0050514437011433,24.98796175555492,124.14542534667756,0.0015897415810904
0.0019835654197601998,127.215949067175,0.0052068485092136,25.646735331942484,127.42457715371002,0.0016386090329962
0.0020341057996622995,130.455263987453,0.0053673142154028,26.29978121987053,130.67579765449997,0.0016890653918461
0.0020838650137890995,133.652052369257,0.0055252997202553,26.94425375764221,133.88464060471134,0.0017387393965728
0.0021325843863678998,136.837755118448,0.005679983728193,27.58649143187912,137.08255392867642,0.0017873729498305
0.0021891184917559995,140.010326410038,0.0058594795128003,28.226081804263664,140.2687162176538,0.0018438045056488
0.0022382759978761997,143.137784939564,0.0060155545947319,28.856577443816104,143.40898278519327,0.0018928702547011
0.0022861832722721994,146.22007265748,0.0061676601909392,29.47796664774797,146.50411540432904,0.0019406857894322
0.0023344902695504994,149.27407450921,0.0063210349072978,30.09365342105674,149.57126085117136,0.0019888979666912
0.0023830578403360994,152.326227074935,0.0064752369445421,30.70896737830689,152.6368879924715,0.0020373678628459
0.0024346943753978997,155.377212411562,0.0066391829433633,31.3240460221709,155.70211878587074,0.002088897974687
0.0024866443451764995,158.406047302999,0.0068041240974103,31.9346591362846,158.74551640650446,0.0021407381958141
0.0025342475729769995,161.398391479763,0.0069552643456769,32.53791572232022,161.75195635463191,0.0021882384984087
0.0025848505426309997,164.373999574955,0.0071159287743284,33.13779831431093,164.74240073190836,0.0022387295830652
0.0026368511310592996,167.370173457097,0.0072810306425882,33.741826968950754,167.7539930985447,0.0022906125405079
0.0026910737785719994,170.339609923968,0.0074531875484411,34.34046536067195,170.73947545457955,0.0023447096638105
0.0027444924086757997,173.254223154617,0.0076227916990206,34.92805138797079,173.670185628344,0.0023980017694107
0.0027962201538866997,176.134369351097,0.0077870272900652,35.50868886118116,176.56635774191764,0.0024496042885733
0.0028453738901672997,179.005689474721,0.0079430904027561,36.08754699810376,179.45351888388808,0.0024986365629038
0.0028984894961436997,181.895747966131,0.0081117324517312,36.67018278997202,182.36046911309444,0.0025516182143998
0.0029501147710509997,184.745757016066,0.0082756426995619,37.24474461443891,185.2272971342786,0.0026031106034763
0.0029991238286136996,187.581700578084,0.0084312464573234,37.81647083654173,188.07982579019665,0.002651991056276
0.0030492445335299997,190.392481500369,0.0085903796954327,38.38312427047439,190.9076133766663,0.0027019777682699
0.0030974127759236998,193.205397558862,0.0087433138650327,38.95020814786658,193.73744651359445,0.0027500148830151
0.0031513498933481996,196.012135842829,0.0089145642128555,39.51604658591433,196.56248632203213,0.0028038024297531
0.0032053615900957994,198.805249884603,0.0090860513500291,40.07913837673596,199.37418050164456,0.0028576614500541
0.0032569768428096996,201.540058626422,0.0092499297773958,40.63047581908668,202.12721811921784,0.0029091280899702
0.0033088320090724995,204.28575033164,0.0094145699302801,41.18400726685863,204.8915022945556,0.0029608312854921
0.0033616716470325995,206.957297758593,0.0095823357808035,41.72259122813235,207.58190699305305,0.003013513317858
0.0034153444947595995,209.620971667458,0.0097527470723367,42.25958788815953,210.26487098012893,0.0030670232335264
0.0034714776232969997,212.23020727269,0.0099309697554429,42.7856097861743,212.89403460170303,0.0031229828984252
0.0035249444769568997,214.830950114422,0.0101007270158131,43.30991954306747,215.5143985495885,0.003176281616074
0.0035830055309346996,217.393985588057,0.0102850708621926,43.8266274945523,218.09821001224208,0.003234156869561
0.0036411350800286996,219.897277181989,0.0104696321805661,44.33129107988899,220.6223932795019,0.0032920970436935
0.0037037342331635997,222.375665992428,0.0106683844917694,44.83093426407349,223.1228751598045,0.0033544885068035
0.0037684952033572995,224.826368023743,0.0108740005721344,45.32499579358659,225.59637182044256,0.003419030518144
0.0038342320162697997,227.247203390896,0.0110827149531316,45.81303620360463,228.04043677013303,0.0034845408128273
0.0039058355404938995,229.641449478052,0.0113100561425431,46.29571621477528,230.45948339498167,0.0035558927202424
0.003979726161581999,231.966383790584,0.0115446588644978,46.76442297218173,232.80983978078663,0.0036295183503728
0.004061368440629499,234.237564495558,0.0118038731004736,47.2222930023045,235.1084024441153,0.0037108615359271
0.0041565390680144,236.475107110724,0.0121060398424207,47.67338159352195,237.37676917951867,0.0038056751578013
0.004259584949267299,238.631413764283,0.0124332105153986,48.10809301487945,239.565887654966,0.0039083243565641
0.004372889904074199,240.72701363776,0.0127929537469105,48.530565949372416,241.6969694018859,0.0040211809745489
0.0045007073320813,242.665327698739,0.0131987740808331,48.92133006406578,243.67411032473808,0.0041484773550319
0.0046403556888064,244.468177731051,0.0136421576134353,49.28478463057988,245.51859455375225,0.0042875379143483
0.004791426876153899,246.084361911837,0.0141218086332636,49.61060736142634,247.17889931862683,0.0044379514521558
0.0049513224264973,247.490584501575,0.0146294770056039,49.894101835517525,248.6309491677385,0.0045971262970993
0.0051162920620842,248.709011357487,0.0151532555985923,50.13973668966938,249.8960196153684,0.0047613258054897
0.0052856723365823,249.695010995204,0.0156910379701238,50.33851421663313,250.92901852228312,0.0049298873149271
0.005459849513533399,250.503407490878,0.0162440505069435,50.50148695016101,251.78504213763185,0.0051031929128492
0.00563752664299,251.142040420514,0.0168081753929682,50.63023534877562,252.4715646611237,0.0052799500088367
0.0058168882261623,251.648000749841,0.0173776484195403,50.73223695116794,253.02533948449013,0.0054583511531011
0.0059963025404561,252.060041828653,0.0179472888674231,50.81530443265645,253.4848589570415,0.0056367729107997
0.0061783146953714,252.404009929976,0.0185251774592791,50.88464840188317,253.8767120009639,0.005817745614113
0.006361237105760099,252.686637984363,0.0191059561122633,50.94162621764758,254.20721115459435,0.0059995903833051
0.0065488650091927,252.948466941618,0.0197016747056618,50.99441093543019,254.518075890588,0.0061860785762665
0.0067357728857136995,253.154021380283,0.020295107213616,51.03585071026506,254.772222326888,0.0063718165445045
0.0069194289281422,253.368399454222,0.0208782151483264,51.07906932997116,255.0345033772432,0.0065542894354487
0.0071045196304092995,253.544474174261,0.0214658781280245,51.11456599353102,255.25866465698817,0.0067381540625021
0.007290008020088499,253.717792242965,0.0220548037652559,51.14950691618174,255.48021621766503,0.0069223798336223
0.007477706540419699,253.869082530057,0.0226507465673075,51.18000703805949,255.68020827798244,0.0071087661493287
0.0076685799364029,253.994436996012,0.0232567695995542,51.20527849839602,255.8549378151568,0.0072982695255198
0.0078579321866132,254.138325060819,0.0238579629939719,51.23428633226111,256.0480015189768,0.007486227197476
0.008050550557494,254.270630548158,0.0244695263215184,51.26095911850865,256.2302783865792,0.0076773906946339
0.0082417299559251,254.385019381995,0.0250765209115371,51.2840199074102,256.3941819829759,0.0078670899599751
0.0084320500090735,254.500712676356,0.0256807870802833,51.30734367555337,256.5592256256542,0.0080559007964012
0.0086257381357237,254.603805876196,0.0262957468823977,51.32812726464112,256.7124664225316,0.0082480164034308
0.0088155383819858,254.72406451755,0.0268983626642799,51.35237140673809,256.8820677511602,0.0084362398973159
0.0090036423299191,254.833253824579,0.0274955926989681,51.37438397103513,257.0401172429454,0.008622746236739
0.0091898355052969,254.925488403437,0.0280867560307926,51.392978462132895,257.1806159621198,0.0088073237821734
0.0093730626213717,255.040187824702,0.0286685021243301,51.41610186545992,257.34306031806955,0.0089889277522627
0.009561153232376,255.143423981642,0.0292656898142688,51.43691427469903,257.4952187231844,0.0091753178348635
0.0097496232139784,255.254446224687,0.0298640820058564,51.4592963588969,257.65537211899044,0.0093620490182317
0.0099362089216401,255.339528253698,0.0304564916276823,51.47644889594552,257.78889713699726,0.0095468789707146