File: example/data/02 processed data/test_ID_118.csv
Strain,Stress_MPa,Displacement(mm),Force(kN),True Stress (MPa),True Strain
-7.979700170034482e-06,-0.689072262341776,-3.06510192091192e-05,-0.138916968088102,-0.6890656101316501,-9.653910916685918e-06
-3.826625911056552e-06,-0.688863073007799,-1.7465008436864274e-05,-0.1388747955183722,-0.6888592837166551,-5.500805188299926e-06
9.377382212495444e-07,-0.686532327098689,-2.3381523167924206e-06,-0.1384049171430957,-0.6865318215184839,-7.364261977346758e-07
1.6092098610904037e-05,-0.669301262220542,4.5776941920360594e-05,-0.1349311344636612,-0.6693109121622767,1.4417830525577725e-05
3.585156348903584e-05,-0.51095597626908,0.0001085132429084,-0.1030087248158465,-0.5109734394155268,3.417681530730064e-05
5.440777756644824e-05,-0.154360248472792,0.0001674292226042,-0.0311190260921148,-0.1543683884464621,5.273222305050782e-05
8.352123345949924e-05,0.378688043774418,0.0002598644450646,0.0763435096249226,0.3787190382809843,8.184372002317656e-05
9.781096071639404e-05,1.11533725534047,0.0003052343291052,0.2248519906766387,1.115444480291292,9.613217572293922e-05
0.0001162093730756,2.04086613566202,0.000363649288346,0.4114386129494632,2.0410998866912617,0.0001145286502715
0.0001422366641382,3.25597667352147,0.0004462859374698,0.6564048973819284,3.2564343417426107,0.0001405526220078
0.0001628606039313,4.77053584425344,0.0005117669463129,0.9617400262014936,4.771304789942036,0.0001611734506452
0.0001846457827742,6.40136309231431,0.0005809348891391,1.290514799410565,6.402534360080727,0.0001829548813615
0.000211990228298,8.11219081567506,0.0006677535036772,1.635417668440092,8.113896939719048,0.0002102939508272
0.000236565262579,9.94207761195185,0.0007457792375193,2.004322846569493,9.944412917482811,0.0002348635158364
0.0002794322939219,11.8783174524673,0.000881882062033,2.3946687984174075,11.88161675170776,0.0002777195621263
0.000328585531596,13.9419275641172,0.0010379435916483,2.810692596926028,13.94648533872205,0.00032685794357
0.0003734420251481,16.0480480197084,0.0011803629586762,3.2352864807732136,16.05401416819392,0.0003716987724519
0.000414287925334,18.1909654702013,0.0013100486917665,3.6672986387925817,18.19847131288357,0.000412528659537
0.0004530933177463,20.4277377919669,0.0014332558126755,4.118231938860528,20.43695926407089,0.0004513172946254
0.0004933448503945,22.7052890211749,0.0015610544288335,4.57738626666886,22.71645254620937,0.0004915498558191
0.0005413341898709,25.1099982782671,0.0017134205816711,5.062175652898648,25.12354914058385,0.0005395144616193
0.0005860963590038,27.493979728208,0.0018555404686681,5.542786313206733,27.510047820186088,0.0005842514867123
0.000629871740091,29.911599460666,0.0019945273036199,6.030178451270266,29.930389854939776,0.0006280003424427
0.0006726959870277,32.3663618093032,0.002130494287644,6.525058540755525,32.38808034440447,0.0006707967883997
0.0007091321681881,34.8154973917735,0.0022461791628282,7.018804274181538,34.84012789406796,0.0007072078735909
0.0007574422059642,37.2567498925045,0.0023995635327673,7.510960778328908,37.28490735341521,0.0007554825929629
0.000803789062403,39.7044558474943,0.0025467148019605,8.004418298854851,39.7363033830567,0.0008017933760206
0.0008443601716044,42.103978007699,0.002675528073675,8.488161966352118,42.13945844082435,0.0008423311469463
0.0008954486411173,44.5410551180481,0.0028377339643784,8.979476711798496,44.58086477628992,0.0008933752983945
0.0009344781902849,46.9625155726752,0.0029616527829856,9.46764313945132,47.006322396278925,0.0009323692348239
0.0009807513237289,49.3526165820054,0.0031085699816703,9.94948750293229,49.400936601666416,0.0009785981761546
0.0010347504541393,51.7228751200989,0.0032800172207233,10.427331624211938,51.776308796035664,0.0010325430339122
0.0010859672680974,54.1332160043723,0.0034426306050402,10.913256346481456,54.19191227718046,0.0010837056827681
0.0011384367240136,56.5749568950041,0.0036092211275742,11.405511310032828,56.63926918782837,0.0011361169345426
0.0011935596880504,58.9412792267178,0.003784236538391,11.88256189210631,59.01153048418843,0.0011911757922414
0.0012436187345424,61.3351182613975,0.0039431740110031,12.365159841497738,61.41129307849676,0.0012411739951784
0.0012935914019365,63.7366403186669,0.0041018372299794,12.849306688243248,63.81898278297333,0.0012910834307766
0.0013435895724253,66.1397159750656,0.0042605814212813,13.333766740573228,66.22846987903165,0.0013410158444652
0.0014010800628575,68.5664934324542,0.0044431137284036,13.823005075982769,68.66244578781742,0.0013984276428202
0.0014499043426208,70.9116407436954,0.004598130816652,14.295786773928992,71.01433712182546,0.0014471825045414
0.0014994374545684,73.2831157190681,0.0047553984470857,14.77387612896413,73.39287647959978,0.0014966427617019
0.0015417330311293,75.687082535129,0.0048896869026665,15.258515839082008,75.80364509770318,0.001538874192481
0.0015866760182424,78.0602261641591,0.0050323808867506,15.736941594694477,78.18395176736034,0.0015837470643768
0.0016373676436607,80.444088329858,0.0051933267974537,16.217528207299374,80.57567020060452,0.0016343571899085
0.0016848976429002,82.8173598446004,0.0053442345450391,16.695979744671444,82.95675996913913,0.001681808445768
0.0017238264494395,85.1851819412875,0.0054678335058014,17.17333267936356,85.33188379704067,0.0017206710813734
0.0017683382392825,87.5735028250627,0.0056091584385529,17.654818169532643,87.72821578643746,0.0017651053597053
0.0018150923592068,89.9117239483984,0.0057576027693126,18.12620354799712,90.07477150455556,0.0018117759373842
0.0018678025212213,92.212698985392,0.0059249575337086,18.590080115455027,92.38477971785092,0.0018643893027473
0.0019082678946358,94.5177666019158,0.0060534350942997,19.054781746946222,94.69797358313876,0.0019047784875824
0.0019515974611733,96.7782388307697,0.0061910064680562,19.51049294828317,96.96694897331092,0.0019480246643183
0.0019947092672889,99.0256669063628,0.0063278864524733,19.963574448322746,99.22302853661915,0.0019910516436457
0.0020418972963607,101.250339579428,0.0064777084447762,20.412068459212687,101.45691286438236,0.0020381447034904
0.0020851235247807,103.462655759156,0.0066149517200097,20.85807140104585,103.6782149631468,0.0020812819898965
0.0021254603713733,105.634373031017,0.0067430212079412,21.29588960305303,105.8587178554692,0.0021215341613109
0.0021663780212285,107.833469098234,0.0068729347462315,21.739227370203977,108.06689662471337,0.0021623642614325
0.0022130071554565,110.018388948232,0.0070209822474054,22.17970721196357,110.26167624136386,0.00220889159301
0.0022591006743829,112.207836549024,0.0071673291699967,22.62109984828324,112.46113749390592,0.0022548823511261
0.0023040775464456,114.395456613588,0.0073101307387958,23.06212405329934,114.65884109981462,0.0022997569130118
0.0023475421605457,116.560756920362,0.0074481308885636,23.49864859514497,116.8341930696574,0.0023431207436922
0.0023951404411254,118.727760933757,0.0075992554294041,23.93551660424541,119.01193182569304,0.0023906064988476
0.0024417346903083,120.874420655096,0.0077471921705599,24.36828320406736,121.16936155755904,0.0024370884122516
0.0024888751624548,123.034374682545,0.007896863169625,24.80372993600108,123.34038590208152,0.0024841130331042
0.0025326594855412,125.181244311322,0.0080358783954243,25.236538853162514,125.49807620318774,0.0025277877722085
0.002579046487594,127.287754547665,0.008183157126942,25.661211316809265,127.6158224833498,0.0025740565954212
0.0026219156377597,129.37461752669,0.0083192666787181,26.081922893380707,129.71361026516612,0.0026168146257294
0.002667261222602,131.452584975692,0.0084632389105924,26.500841131099502,131.8029832850035,0.0026620406819899
0.0027078268334407,133.497219218175,0.0085920347250052,26.91303939438408,133.85848307430547,0.0027024976307349
0.0027581210273969,135.551701339151,0.0087517187908162,27.32722298997284,135.92534240111542,0.0027526548303541
0.0028012388758927,137.529404464271,0.0088886179597903,27.725927939997035,137.9144269318365,0.0027956532290559
0.0028463284118311,139.446389021989,0.0090317772363947,28.112392026832985,139.84306578484453,0.0028406158754913
0.0028872798621222,141.350543547816,0.009161798091069,28.4962695792397,141.75842548168936,0.0028814503297691
0.002931461423955,143.244223108515,0.0093020745498881,28.878035378676625,143.6638982084193,0.0029255037974961
0.0029814903195147,145.134883426908,0.0094609162932902,29.259192498864653,145.5673586972508,0.0029753853031081
0.0030315633719787,146.993640639738,0.0096198982348634,29.633917952971185,147.43901508513216,0.0030253083441988
0.003076423872633,148.853504396201,0.0097623303244408,30.008866486274123,149.31119166545025,0.0030700323329594
0.0031258168730134,150.699392752155,0.0099191531006485,30.38099757883445,151.17019916125216,0.003119272715433
0.003178459542782,152.594778371071,0.0100862935771639,30.76310731960791,153.07953923185613,0.0031717500572351
0.00323166528735,154.475408601844,0.0102552218161673,31.14224237413175,154.97436280038102,0.0032247859073964
0.0032880309138182,156.28944566623,0.0104341826802038,31.50795224631197,156.8030685408975,0.0032809684812816
0.0033316137085598,158.080413334968,0.0105725580535084,31.86901132832955,158.60681155452914,0.003324407573079
0.0033794576844513,159.84235029994,0.0107244626769639,32.2242178204679,160.3822631566297,0.0033720916232777
0.0034319301288661,161.591596561055,0.0108910626879809,32.576865866708694,162.14589709900693,0.0034243860564217
0.0034847868039934,163.326856010903,0.01105888263151,32.92669417179805,163.89574184750083,0.0034770606521133
0.0035441693068006,164.981200814883,0.0112474220779229,33.260210084280416,165.56564591739877,0.0035362352860533
0.0036067472127755,166.614127326718,0.0114461069293932,33.58940806906635,167.2147834266642,0.0035985903485181
0.0036741918541418,168.254139066854,0.0116602436657312,33.92003443587777,168.87205536899177,0.0036657904624463
0.0037472152744933,169.822362273676,0.0118920930253472,34.23618823437308,170.45843891302803,0.0037385440376804
0.0038205702643531,171.402285484376,0.0121249951181521,34.5547007536502,172.05685300397857,0.0038116226283677
0.0038851298724988,172.925518851152,0.0123299718740147,34.86178460039224,173.59706744445407,0.0038759345599742
0.0039640507595115,174.365320497789,0.01258054569028,35.152048612354264,175.05622156277255,0.003954547056794
0.0040470485139082,175.763797556557,0.0128440635604895,35.43398158740189,176.4748279148088,0.0040372138237973
0.0041335798796919,177.071493467597,0.0131188006468528,35.69761308306756,177.80313618351573,0.0041233928346806
0.0042212292884725,178.317880340034,0.0133970875197312,35.948884676550854,179.0703024657815,0.0042106777651773
0.0043218162096796,179.492975844136,0.0137164509945637,36.18578393017782,180.26841099595788,0.0043108370216092
0.0044294023174678,180.551374365305,0.0140580368867913,36.39915707204549,181.3508067687029,0.0044179546041462
0.0045546478632826,181.502279650282,0.0144556914947533,36.59085957749685,182.3286547558628,0.0045426402677384
0.0046806170168502,182.378325834903,0.0148556435573304,36.76747048831645,183.23166359905608,0.0046680306248145
0.0047971405983297,183.162948918033,0.0152256059285278,36.92565050187546,184.04130069155525,0.004784004812962
0.004930891588393,183.858699622264,0.0156502653219788,37.06591384384842,184.76497912804112,0.0049171086070637
0.0050633466551875,184.477357163912,0.0160708101590513,37.19063520424466,185.41112112788824,0.0050489052909699
0.0051967351216259,184.965296947389,0.0164943185399932,37.28900386459362,185.9262029400488,0.0051816131828673
0.0053386449816393,185.380670072257,0.0169448823455358,37.37274308656701,186.37004129855967,0.0053227796582143
0.0054831449277368,185.700280803843,0.0174036696743953,37.43717661005475,186.7181914638596,0.00546650217772
0.0056342348559248,185.990182877984,0.0178833801963922,37.49562086820158,187.037783871119,0.0056167571370203
0.0057962279080351,186.240383611619,0.0183977081368424,37.54606133610239,187.3195635237388,0.0057778298910843
0.0059473916587937,186.46201417525,0.018877653045501,37.5907420577304,187.57066463501872,0.0059281114688846
0.0061063715780284,186.628662831293,0.0193824142890712,37.62433842678868,187.76797434663524,0.0060861392383556
0.0062704526607656,186.816025516352,0.0199033717267618,37.662110744096566,187.9871337999325,0.0062492114364987
0.0064320471732869,186.948786352546,0.0204164343040169,37.68887532867327,188.1509367823988,0.006409786366684
0.0065927813981812,187.076612769905,0.0209267654680563,37.71464513441285,188.3096547856512,0.0065694808625583
0.0067523578345941,187.185222098151,0.0214334206536673,37.73654077498724,188.44885032031783,0.0067279998358075
0.0069134098961966,187.277263195549,0.0219447609492552,37.75509626022268,188.571674147378,0.0068879591819166
0.0070833312574257,187.332508702688,0.0224842612711576,37.7662337544619,188.659133291744,0.0070566999158609
0.0072563101315202,187.318272527698,0.0230334691964076,37.76336374158392,188.6771984049236,0.0072284476772607
0.0074271824111006,187.330597093008,0.0235759886840754,37.76584837395042,188.7216219866288,0.0073980748813417
0.0076003611431141,187.351771340137,0.0241258311582183,37.77011710217162,188.7753988055056,0.0075699623781271
0.0077774509711515,187.386427721078,0.024688091362237,37.77710382856933,188.84350275969885,0.0077457012610744
0.0079566880477522,187.414840113288,0.0252571690804442,37.78283176683886,188.9057277683827,0.0079235395695439
0.0081340830621562,187.419175806666,0.0258203982511769,37.78370584262387,188.9433451796536,0.0080995190562044
0.0083106471953959,187.430624410875,0.026380989374213,37.7860138812324,188.98798041433497,0.0082746435455878
0.0084882448445507,187.493535106363,0.0269448619102795,37.798696677442784,189.0847122441617,0.0084507621909978
0.0086700359410776,187.494126966427,0.0275220486417524,37.798815996431685,189.1193938900216,0.0086310072421775
0.0088495493960203,187.535587283919,0.0280920038611955,37.80717439643807,189.19487876174307,0.0088089621474452
0.0090274060300591,187.498635951811,0.0286566986742686,37.7997250078851,189.1909483651362,0.0089852433911008
0.0092051361278229,187.457678733523,0.0292209917346687,37.79146803267824,189.18293834954585,0.0091613681828405
0.0093909066858821,187.44719218403,0.0298108132565067,37.78935394430045,189.2071774569921,0.0093454276606056
0.0095711379983819,187.463325401441,0.0303830476736935,37.79260640093051,189.2572489141154,0.0095239665413702
0.0097548285014966,187.461497549563,0.0309662650210827,37.792237905991904,189.2898384674744,0.0097058993360293
0.0099380891780206,187.465106458164,0.0315481176690464,37.79296546196586,189.3278375565522,0.0098873734395827