File: example/data/02 processed data/test_ID_102.csv
Strain,Stress_MPa,Displacement(mm),Force(kN),True Stress (MPa),True Strain
0.0008849360165372,-0.0491197758968568,8.956170990730843e-05,-0.0099025468208063,-0.0491211614877606,2.820801471955354e-05
0.0008755228635151,0.216544673388316,5.967494906213521e-05,0.0436554061550845,0.2165487434016559,1.8795082918499885e-05
0.0008536856400092,0.639383843055183,-9.658235568889327e-06,0.1288997827599249,0.6393818980725766,-3.0419685855093244e-06
0.0007915280969153,1.32465726133686,-0.000207008434892,0.2670509038855109,1.324570894336407,-6.520163263288953e-05
0.0007354033210495,2.06071585024417,-0.0003852045982659,0.4154403154092246,2.0604658353713403,-0.0001213316433045
0.0006838859652331,2.78968568046829,-0.0005487722029829,0.5624006331824073,2.789203506623723,-0.0001728565775722
0.0006706876130178,3.48458506650848,-0.0005906769712665,0.7024923494081097,3.483936794334242,-0.0001860572985358
0.0006644039458442,4.25579772272717,-0.0006106276145427,0.8579688209017975,4.254979232140901,-0.00019234215469
0.0006475564575153,5.15268566295915,-0.000664118389987,1.0387814296525646,5.151607869791719,-0.0002091930257879
0.0006161394061322,6.10164074058571,-0.0007638675281283,1.2300907733020792,6.100172757836091,-0.0002406171438189
0.0005921067295752,7.19682449373746,-0.0008401712761968,1.450879817937472,7.194920063747077,-0.0002646558926741
0.0005560134059165,8.19009401816695,-0.0009547675788131,1.6511229540624572,8.187631140612313,-0.0003007594216323
0.0005495354282862,9.22303007023962,-0.0009753351577893,1.859362862160308,9.220196827565966,-0.0003072393688632
0.0005501353350928,10.264988778996,-0.0009734304536784,2.0694217378455937,10.261841612796273,-0.0003066392778933
0.0005642670748992,11.2954102301287,-0.0009285621797931,2.277154702393946,11.29210676847675,-0.0002925033039894
0.0005632588771293,12.3838629334283,-0.0009317632077125,2.4965867673791453,12.380228656939885,-0.0002935117972121
0.0005483595919437,13.5275543408787,-0.0009790684381768,2.7271549551211463,13.523382875839054,-0.0003084155672161
0.0005332083992731,14.7222036622077,-0.0010271734749059,2.9679962583010724,14.717440746587547,-0.0003235715483224
0.0005405514278597,15.9877409820014,-0.0010038593591435,3.223128581971482,15.9826860391931,-0.0003162261703336
0.0005520960336198,17.2534228007108,-0.0009672052358552,3.4782900366232976,17.24816686342914,-0.0003046779799703
0.0005938588654855,18.5153094449297,-0.0008346082446816,3.732686384097828,18.5104423488933,-0.0002629032945251
0.0006108827269174,19.8094857152068,-0.0007805574846353,3.9935923201856913,19.804615654626712,-0.0002458751018561
0.000632329175794,21.0757249637751,-0.0007124650094521,4.248866152697061,21.07099560422061,-0.0002244236092683
0.0006359200713341,22.3600569901294,-0.0007010639161123,4.507787489210087,22.35511972111586,-0.0002208319142061
0.0006419164663285,23.6681752288666,-0.000682025362005,4.771504126139506,23.66309104121984,-0.0002148342128564
0.0006460359958814,24.9823871516898,-0.0006689458556746,5.036449249780664,24.97712357236697,-0.0002107138066814
0.0006530849578294,26.3365812136258,-0.0006465654014897,5.309454772666961,26.331217962537213,-0.0002036633841176
0.0006712926325007,27.723292265368,-0.0005887560344083,5.589015720698188,27.718151397457795,-0.0001854521666572
0.0007069576047397,29.1526674333586,-0.0004755197475495,5.877177754565095,29.14830123837961,-0.0001497812158745
0.0007512720961921,30.6417807202411,-0.0003348212371881,6.177382993200606,30.63854937569609,-0.0001054610685988
0.0007907131843746,32.1262966079638,-0.0002095957822087,6.476661396165503,32.124175809139544,-6.601659864100436e-05
0.000814052652011,33.6296919669228,-0.0001354929724633,6.779745900531637,33.62825682143378,-4.267586255864696e-05
0.0008364232132395,35.0761805434735,-6.446644056293574e-05,7.071357997564258,35.07546834299848,-2.0304596865463382e-05
0.0008517791851696,36.505828924764,-1.5711229684775027e-05,7.359575111232423,36.5056482786339,-4.9484310418541685e-06
0.0008733962841488,37.9396837174611,5.292305957439464e-05,7.648640237440158,37.94031612191515,1.6668541260114342e-05
0.0009012023663244,39.3905547259012,0.0001412073704817,7.941135832741682,39.39230661146172,4.447377338355175e-05
0.0009261410528414,40.8165580836507,0.0002203877001731,8.22861810966398,40.819391301718426,6.941103987149176e-05
0.0009417457459312,42.2478071937533,0.0002699326007333,8.517157930260666,42.25139902382293,8.501452812575066e-05
0.0009747080142805,43.671790891409,0.0003745878027425,8.804233043708054,43.676943307217456,0.0001179734511713
0.0010048571373908,45.1344424165764,0.0004703112686177,9.099103591181802,45.14112816047287,0.0001481185633268
0.0010358471515663,46.6316564770088,0.0005687045636249,9.400941945764972,46.640009118220725,0.0001791035076076
0.0010683332919672,48.1409136125138,0.0006718480593977,9.705208184282782,48.15110050365969,0.0002115833026735
0.0010995200911,49.6470851808364,0.0007708661466444,10.008852372456618,49.65913912012631,0.0002427630178059
0.0011392489349954,51.1425275265589,0.0008970052260123,10.310333549354276,51.15697638150782,0.0002824814293915
0.0011744095996958,52.6436948759411,0.001008640336436,10.612968886989728,52.66041882999178,0.000317631545487
0.0012118360536563,54.0945044877782,0.0011274693277606,10.905452104736089,54.11371390340352,0.0003550454136055
0.0012414816812961,55.5156959698904,0.001221594195517,11.191964307529904,55.53705586027053,0.0003846800784585
0.0012664442736473,56.9027399058444,0.001300850426232,11.47159236501823,56.92605390693426,0.0004096327587238
0.0012918857348414,58.3459700453036,0.0013816270655233,11.762547561133204,58.37135976857252,0.0004350634770326
0.0013106593279792,59.7745517595681,0.0014412332237358,12.05054963472893,59.80168532490032,0.0004538287281738
0.0013316695402223,61.2409387566499,0.0015079406476077,12.346173253340622,61.27002464668102,0.0004748291870311
0.0013558238165649,62.6715553614188,0.0015846304749954,12.634585560862028,62.70283449733724,0.0004989717055079
0.0013761141448469,64.0640355090176,0.0016490522672908,12.915309558617947,64.09730950681538,0.000519251706375
0.0014091288222493,65.4494611426089,0.0017538738680434,13.194611366349957,65.48561550467993,0.000552248700893
0.0014436093185156,66.7931533298608,0.0018633494436889,13.465499711299938,66.83235301020709,0.0005867095668246
0.0014759441768817,68.0830208188408,0.0019660126190013,13.725536997078304,68.12517895366585,0.0006190249374368
0.0015138123533985,69.3331476862886,0.0020862440794421,13.97756257355578,69.37870544026327,0.0006568689637676
0.0015410056062843,70.6082354709013,0.0021725826573545,14.234620270933704,70.65655113321642,0.0006840439908706
0.0015736610211684,71.9649888750872,0.0022762635996115,14.50814175721758,72.01658298048022,0.0007166765432052
0.0016040831905928,73.3615672380163,0.002372853987534,14.789691955184088,73.41639441513519,0.0007470764555032
0.0016242690044641,74.7698925062781,0.0024369439465754,15.073610329265664,74.82728149428732,0.0007672469912333
0.0016462080153882,76.1132704911108,0.0025066003062594,15.344435331007938,76.17336042721267,0.0007891689356855
0.0016621909062449,77.4238493119098,0.0025573459847294,15.608648021281017,77.48621138125156,0.0008051390907932
0.0016880112276733,78.7754579404146,0.0026393255052646,15.881132320787584,78.84094268855036,0.0008309382988359
0.0017164586780014,80.1419807030328,0.0027296461600563,16.156623309731412,80.21088125417779,0.0008593617169569
0.0017539511915435,81.5213014909586,0.0028486848905525,16.434694380577255,81.59444432554615,0.0008968213230885
0.0017972716181612,82.9386874444344,0.0029862272450637,16.720439388797974,83.0166949304553,0.0009401019798186
0.0018304828494997,84.3198378922911,0.0030916729045634,16.998879319085887,84.40194477674112,0.0009732814534394
0.0018480113198486,85.706021167562,0.0031473257979212,17.2783338673805,85.79098015069833,0.0009907927186296
0.0018776698060666,87.0965750956937,0.0032414914916633,17.558669539291852,87.18549566486716,0.0010204213950545
0.0018919170617467,88.4995960489325,0.0032867265284476,17.841518563464792,88.59120989778003,0.0010346540186607
0.0019216169387278,89.8922395038958,0.0033810236378626,18.1222754839854,89.98796479102118,0.0010643227423155
0.0019486536606342,91.2826304254715,0.0034668652299155,18.40257829377505,91.3823043081541,0.0010913303390232
0.0019753126030753,92.6010314869593,0.0035515073721659,18.668367947771,92.70461361168248,0.0011179598490527
0.0020154943373023,93.8950015609092,0.0036790843783367,18.929232314679293,94.00380396514436,0.0011580958813538
0.0020442300311734,95.1392071708833,0.0037703202063774,19.18006416565008,95.25218521032112,0.0011867979038917
0.0020831412605469,96.3882700310858,0.0038938633596383,19.431875238266898,96.50648192178592,0.0012256622256644
0.0021082975749005,97.6883834225282,0.003973734657711,19.693978097981685,97.8106472697288,0.0012507874101215
0.002140258488304,99.0353739435811,0.0040752105577671,19.96553138702595,99.16248890467948,0.0012827078627444
0.0021755452872547,100.416173743691,0.0041872461444355,20.243900626728102,100.5486043693122,0.0013179488070882
0.0022009525423043,101.791863804397,0.004267914179218,20.52123974296644,101.92869496624262,0.0013433222768235
0.0022294304248957,103.16166618736,0.0043583314564457,20.79739190337178,103.303276497547,0.0013717615257244
0.00226046395472,104.481375100981,0.0044568629136379,21.06344522035777,104.62803940518684,0.0014027520339208
0.002293351589391,105.811561998758,0.0045612811537183,21.331610898949613,105.96357342666047,0.0014355930284655
0.0023208245172916,107.077989680118,0.0046485076998027,21.58692271951179,107.23476223429356,0.0014630261684267
0.0023585785855886,108.405327208732,0.0047683768666457,21.85451396528037,108.56813585581337,0.0015007243313346
0.0023708171059605,109.724648744303,0.0048072341688265,22.120489186851483,109.89078168307655,0.0015129444241702
0.002421152673799,111.023716208675,0.0049670495967137,22.38238118766888,111.19740449365766,0.0015632026317072
0.0024413313179178,112.340577003864,0.0050311167917909,22.647860323978986,112.5185922994116,0.0015833495542074
0.0024781708252716,113.590234356702,0.0051480822276392,22.899791246311125,113.77441447220598,0.0016201301014849
0.0025022164627581,114.882627133241,0.0052244271266588,23.160337630061385,115.0716652162573,0.0016441365252945
0.0025139146137135,116.186282845861,0.0052615687559422,23.42315462172558,116.3788252445038,0.001655815390497
0.0025339600836476,117.443489051936,0.005325213122983,23.67660739287029,117.6404690863008,0.0016758274960542
0.0025807838691936,118.717185438805,0.0054738786420915,23.933384584463088,118.92186054615073,0.0017225717861948
0.0026106872655252,119.949100503283,0.0055688219254444,24.181738661461853,120.15948638700584,0.0017524232705595
0.0026396265807143,121.240341499816,0.0056607042511698,24.442052846362905,121.4565007806164,0.0017813114989606
0.0026425894162457,122.485145972065,0.005670111253982,24.693005427968306,122.70388751682776,0.0017842690570832
0.0026556953261365,123.792698754105,0.0057117225178853,24.956608068827567,124.01539782340376,0.0017973515177786
0.0026809896910226,125.026762699687,0.0057920321263986,25.205395360256897,125.25484428274724,0.0018226001418823
0.0027188540730848,126.209139223223,0.0059122515394461,25.44376246740176,126.44415660201504,0.0018603948609391
0.0027446805325294,127.443171773893,0.0059942505481827,25.69254342961683,127.6837784832687,0.0018861729853785
0.0027772839021846,128.655090734231,0.006097766246838,25.936866292020973,128.9021800790383,0.0019187143879206
0.002798134540257,129.91082104703,0.0061639670227178,26.19002152308125,130.1630308161097,0.0019395248413906
0.0028065620394933,131.140472574862,0.0061907243327931,26.437919271092177,131.39617478417952,0.0019479359757499
0.002831980665621,132.383621840292,0.0062714284707485,26.688538163002868,132.64511299464473,0.0019733048144232
0.0028660261162807,133.637710150184,0.0063795227765931,26.94136236627709,133.90622820237766,0.0020072825720225
0.0029130688612388,134.842889115574,0.0065288834918351,27.18432644569972,135.12017211171195,0.0020542298815649
0.0029575330427182,136.034129722205,0.0066700572680322,27.424480551996528,136.31991096178106,0.0020986018326966
0.0029797893089693,137.234722291694,0.0067407209133794,27.66652001400551,137.526080075188,0.0021208111942523
0.0030054560474642,138.444833091994,0.0068222128081007,27.910478351346,138.74231344271388,0.0021464232281315
0.0030153842488872,139.703696230579,0.0068537348476187,28.164265160084728,140.0052685427669,0.0021563300932131
0.0030316072606972,140.862098583901,0.0069052429101155,28.39779907451444,141.16845669651534,0.0021725180295188
0.0030575752587133,141.982401226188,0.0069876913038166,28.6236520871995,142.29488286094178,0.0021984293371282
0.0030778159751218,143.041611082145,0.0070519555784136,28.83718879416044,143.3593191411107,0.0022186254006868
0.0031117827748184,144.12477500164,0.0071598001674503,29.05555464033062,144.4497843207551,0.0022525163500096
0.0031492456933627,145.220390415024,0.0072787449338284,29.276430707668844,145.55331078699945,0.0022898942791229
0.00318366735782,146.301794715479,0.0073880337184804,29.494441814640563,146.64223017766236,0.0023242366220808
0.0032148603061126,147.45997046499,0.0074870713293094,29.72793004574198,147.80770064360078,0.0023553566705349
0.0032356982826762,148.590351158584,0.0075532319048988,29.95581479357054,148.94384324712925,0.0023761454079003
0.0032537450371695,149.784210319248,0.007610530350415,30.1964968003604,150.14324568260156,0.0023941491695183
0.0032767462843046,150.994208237192,0.007683559310069,30.44043238061791,151.35961704174866,0.0024170951508441
0.0032958915769602,152.104662851702,0.0077443456142505,30.664300030903124,152.475671065454,0.0024361940410025
0.0033153479394069,153.255497195034,0.0078061195650188,30.89630823451885,153.63229427695555,0.0024556028733126
0.003343806702149,154.375136396206,0.0078964761367249,31.12202749747513,154.75907957121584,0.0024839914354087
0.0033632276235301,155.524837023876,0.0079581375621099,31.3538071440134,155.91466003091872,0.0025033639876043
0.0033925988566379,156.678036023014,0.0080513912272272,31.58629206223962,157.07535135048954,0.0025326613566084
0.003415307993639,157.723058324099,0.0081234927372057,31.79696855813836,158.12660544812596,0.002555312795281
0.0034357197968932,158.770557371745,0.0081883002125378,32.0081443661438,159.18002539967316,0.0025756722993211
0.0034668767912269,159.871966246476,0.0082872236695473,32.23018839528957,160.28925592923974,0.0026067486638328
0.0034893775887189,161.029925303026,0.0083586637015844,32.46363294109004,161.45386073341948,0.0026291906319598
0.0035226914487305,162.26626439013,0.0084644352071212,32.71287890105021,162.6988603842188,0.0026624164665411
0.0035435419113262,163.470558661819,0.0085306354258626,32.95566462622271,163.90977369766347,0.0026832112741418
0.0035696506150091,164.648895865167,0.0086135305600558,33.193217406417666,165.09557564350212,0.0027092496775567
0.0035880209622727,165.779253143192,0.0086718564126177,33.421097433667505,166.23204491624674,0.0027275701545006
0.0036160757670399,166.877634253473,0.0087609304177536,33.64253106550016,167.33810774700814,0.0027555481506959
0.0036341227075608,167.973331629263,0.0088182294539074,33.86342365645942,168.4398599380643,0.0027735452685069
0.0036561959400396,169.011572012191,0.0088883119670276,34.07273291765771,169.48471455646884,0.0027955571224348
0.0036770460384569,170.033137992852,0.0089545110295025,34.278680619358965,170.51268558640726,0.0028163487984599
0.0036992411878649,171.043532245741,0.0090249806288729,34.482376100741384,171.52972580958723,0.0028384812816017
0.0037284515454208,172.071727365492,0.0091177235141129,34.689660236883185,172.56586986461463,0.0028676084194675
0.0037461675184022,173.157545176106,0.0091739717283289,34.90856110750297,173.6578734986233,0.0028852735067184
0.0037739571457378,174.271704516733,0.0092622037951194,35.133175630573376,174.7800950814438,0.002912982685036
0.0037918731896842,175.35962364904,0.0093190872346492,35.352500127646465,175.87432967430635,0.0029308464562377
0.003818091564571,176.480648595922,0.0094023305749148,35.57849875693788,177.00327202841785,0.0029569877599029
0.0038469206750194,177.579523697127,0.0094938630005885,35.80003197734081,178.11052075844677,0.0029857313358373
0.0038753630692051,178.689328707714,0.0095841676021281,36.023768667475146,179.22872665261053,0.0030140885332566
0.0039024902568718,179.800851746606,0.0096702964229698,36.247851712115775,180.3484824658161,0.0030411337145516
0.0039313868804449,180.896371376222,0.0097620432028144,36.46870846944636,181.4525660825549,0.0030699421781505
0.0039624139081176,182.041962326173,0.0098605540156752,36.69965960495648,182.60732755535,0.0031008736223185
0.0039932518337877,183.18916152515,0.0099584644296778,36.93093496347024,183.763738768914,0.0031316155990456
0.0040142026988818,184.311907175949,0.0100249834263516,37.15728048667132,184.89386743255312,0.0031525007386133
0.0040417176452941,185.390208193182,0.0101123433812106,37.37466597174549,185.98067416003664,0.0031799287045683
0.0040642519423408,186.46182193612,0.0101838897743339,37.59070330232179,187.05990276815743,0.0032023912056853
0.0040814495194986,187.58118572334,0.0102384920818099,37.81636704182535,188.18608288388333,0.00321953365063
0.0041055105674534,188.658686684892,0.0103148859090664,38.03359123567423,189.27159781210744,0.0032435170701941
0.0041263759841286,189.749321722369,0.0103811336070102,38.25346325922959,190.36973528477512,0.0032643147028995
0.0041500635980702,190.814327082004,0.0104563417812748,38.46816833973201,191.4427427735736,0.0032879248403607
0.004185314226843,191.909139938246,0.0105682625276284,38.6888826115504,192.54792613425192,0.0033230591408277
0.0042164607797278,193.037472838233,0.0106671528330376,38.91635452418777,193.68602723989247,0.0033541018818254
0.0042388724010208,194.175389798601,0.0107383097306429,39.14575858339796,194.8321190829241,0.0033764382087242
0.0042670652866591,195.292044884224,0.0108278221425445,39.37087624865956,195.9580567040225,0.0034045356686123
0.004282687876746,196.437009313347,0.0108774238660704,39.60170107757076,197.1099947033579,0.0034201050402678
0.0042994636745563,197.537357948855,0.0109306870241181,39.82353136248917,198.21742693635423,0.0034368234213369
0.00431534205565,198.592565990697,0.0109811008840906,40.03626130372452,199.27942110942908,0.0034526471997104
0.0043334002677433,199.681503755658,0.0110384357074868,40.255791157140656,200.37573098122687,0.0034706430087528
0.004356952549073,200.718526845649,0.0111132142007086,40.46485501208284,201.42108684025888,0.0034941134147738
0.0043946405650348,201.817871303144,0.0112328736513874,40.68648285471383,202.5318853658023,0.003531669269099
0.0044267643710906,202.980329616115,0.0113348667356145,40.92083445060879,203.70497685584724,0.0035636793122688
0.0044562197527811,204.130801073543,0.0114283875724819,41.152769496426274,204.86556828933817,0.0035930294805214
0.0044789026365061,205.297575862176,0.0115004057283087,41.38799129381468,206.04119961570456,0.0036156307548071
0.0044870698091929,206.369202809024,0.0115263365015893,41.60403128629923,207.11839363584025,0.0036237684182218
0.0045087820909679,207.324189556685,0.0115952729962249,41.7965566146277,208.08134879341915,0.0036454019280972
0.0045381688697744,208.319572815116,0.0116885760189356,41.997225879527385,209.0864890869528,0.0036746813466601
0.0045656521277394,209.323810894906,0.0117758353629745,42.19968027641305,210.10017711054343,0.0037020634228472
0.0045940932282009,210.34663700997,0.0118661358569397,42.40588202120996,211.1327793003041,0.0037303990257502
0.004620826402564,211.390893959177,0.0119510136855426,42.61640422217009,212.18659016916288,0.0037570323058134
0.0046449601925537,212.464881635489,0.0120276384687599,42.83292013771458,213.2697480240306,0.0037810753054539
0.004662801678313,213.526428472868,0.0120842851860456,43.046927980130185,214.33912587646608,0.0037988493006286
0.0046969475340941,214.622689722153,0.0121926982781506,43.26793424798605,215.4468880526813,0.0038328651089773
0.0047269542381116,215.71817038915,0.0122879695634062,43.48878315045264,216.5530485976589,0.0038627565747224
0.0047550251810678,216.805692565029,0.0123770948072921,43.70802762110985,217.6508656710567,0.0038907189046618
0.0047863526409248,217.787867162853,0.0124765594923381,43.90603402003117,218.6436918184016,0.0039219242280929
0.0047954616275332,218.710010622619,0.0125054805248198,44.09193814151999,219.5714511827526,0.003930997518747
0.0048167586357653,219.611472894747,0.0125730985259567,44.273672935581,220.4811411423489,0.0039522107478236
0.0048412125683969,220.589787010967,0.012650739762062,44.47090106141095,221.4687237006188,0.0039765679274549
0.0048725346959817,221.703380277448,0.0127501875171438,44.69540146393352,222.5936982842896,0.0040077652611517
0.0048903936258897,222.866296310168,0.0128068896196017,44.929845336129866,223.76526451702588,0.0040255526017004
0.0049195523366523,224.037611011869,0.0128994685262729,45.16598237999279,224.9478365589396,0.0040545937467837
0.004958006858528,225.108874297044,0.0130215616332283,45.38194905828407,226.03210865321583,0.0040928919334748
0.0049812096400382,226.083127878159,0.0130952304645232,45.57835858023685,227.01560367775107,0.0041159996756008
0.0050179192410846,226.939124984224,0.0132117834478455,45.75092759681956,227.8834621732429,0.0041525578222147
0.0050441380029926,227.754791994873,0.0132950280169034,45.9153660661664,228.70849477930005,0.0041786675940769
0.0050772945447869,228.632897815006,0.0134003000371003,46.09239219950521,229.59785826510767,0.0042116853296879
0.0051126716433068,229.564395121641,0.013512622324901,46.280182056522825,230.54140834070336,0.0042469131238194
0.0051373674736827,230.488302142623,0.0135910315863444,46.4664417119528,231.4749395582776,0.0042715039931868
0.0051864584119561,231.465104743506,0.0137468953153625,46.663365116290805,232.4672863384881,0.0043203844918636
0.005212103726742,232.307716709352,0.0138283191898077,46.83323568860536,233.3195041918441,0.0043459189220229
0.0052452729494383,233.141362839662,0.0139336314718685,47.00129874847587,234.16451428238864,0.004378943761421
0.0052788519770622,233.88922157701,0.0140402448845744,47.15206706992522,234.92350880434967,0.0044123755109961
0.0053006846300611,234.622340015909,0.0141095635578459,47.299863747207255,235.66499161230115,0.0044341118061151
0.0053409932175513,235.32021158015,0.0142375433231272,47.44055465455824,236.37544991312004,0.0044742412513003
0.0053937541553378,236.041063031609,0.0144050593005994,47.58587830717238,237.111987601797,0.0045267652718315
0.0054471818119458,236.762484182749,0.0145746921103298,47.7313168112422,237.84933152455704,0.0045799502062194
0.0054993167060275,237.469670029622,0.0147402203990392,47.8738854779718,238.5721441317712,0.0046318455244523
0.0055647971520086,238.114010690527,0.0149481208150292,48.00378455521025,239.23506801322088,0.004697021252464
0.0056129155370782,238.711093144917,0.0151008966876252,48.12415637801527,239.8464479656324,0.0047449130075921
0.0056878988551784,239.15121736871,0.0153389687225933,48.21288542153194,240.30659785475373,0.0048195385945737
0.0057599114086258,239.604799290903,0.0155676085797888,48.30432753704605,240.77962566230445,0.0048912023478423
0.0058396053751109,240.071262625693,0.015820636923379,48.39836654533971,241.2675083837208,0.0049705043222681
0.0059269256146065,240.401758291175,0.0160978786837775,48.46499447150089,241.6206428078169,0.0050573878385322
0.006011527758915,240.627825760275,0.016366490491957,48.51056967327144,241.86821411378864,0.0051415596545583
0.0060928884305799,240.672145558304,0.0166248106244931,48.519504544554096,241.93234361893303,0.0052224998033039
0.0061882332455644,240.772107159737,0.0169275304120688,48.53965680340298,242.05578500739824,0.005317343480188
0.0062814343992344,240.917760958509,0.0172234440749711,48.569020609235416,242.224669173481,0.0054100460695522
0.0063886749133464,241.077204120827,0.0175639327072767,48.60116435075872,242.41083051151568,0.0055167022861293
0.0064970233657695,241.10099190058,0.01790793904372,48.60595996715693,242.460872803363,0.0056244488532384
0.0065999091165798,241.028353196506,0.0182346013025427,48.59131600441561,242.41262277859943,0.0057267523195465
0.0067067714950864,240.869610997209,0.0185738893543012,48.55931357703734,242.2787087935793,0.0058329988282915
0.0068048242121403,240.673803108263,0.0188852067309473,48.51983870662583,242.10535414020725,0.0059304765176856
0.0069070205994996,240.587579827919,0.0192096802608131,48.50245609330848,242.0432051769638,0.0060320634652451
0.0070372178294915,240.539042488569,0.0196230564660374,48.49267096569552,242.0256916895264,0.0061614693278918
0.0071587417743458,240.600517792518,0.0200088949909498,48.505064386971625,242.11678566504668,0.0062822395156937
0.0072832459170467,240.587400672695,0.0204041956440251,48.50241997561531,242.13354000901407,0.0064059562920501
0.0074033005363607,240.637808645264,0.0207853690603471,48.51258222288522,242.2131616098514,0.0065252371905167
0.0075122324229475,240.610223047071,0.0211312278002602,48.50702096628951,242.2116055460565,0.006633454729031
0.0076323560266522,240.520156874506,0.0215126202420226,48.488863625900414,242.1498320856534,0.00675277701611
0.0077548603808031,240.465131079462,0.0219015715664517,48.47777042561954,242.1238914818472,0.0068744495100983
0.0078758740648273,240.391117775425,0.0222857900132285,48.46284934352568,242.0784582389804,0.0069946269229617
0.0080073295365034,240.371991451215,0.0227031611358002,48.45899347656495,242.0907958778135,0.0071251576013892
0.0081283605989885,240.374655063199,0.0230874347591904,48.45953046074092,242.1225713361233,0.0072453221433925
0.0082474820389866,240.318156842094,0.0234656453311843,48.44814041936616,242.0942893255902,0.0073635766369296
0.0083802956498847,240.156655389535,0.0238873285457858,48.415581726530256,241.96349032803792,0.0074954071665045
0.008501826369054,240.059846704729,0.0242731885791483,48.39606509567336,241.89512794231808,0.0076160230944099
0.0086198517672622,240.030999420595,0.0246479192184594,48.39024948319196,241.8943898721367,0.0077331461635732
0.0087375168121387,239.966068159178,0.0250215057359422,48.37715934089029,241.857190159454,0.007849897980925
0.0088656531866818,239.945228366287,0.0254283387251166,48.37295803864347,241.86693184419988,0.0079770243547296
0.0089959457459133,239.971538932139,0.0258420176006766,48.37826224871922,241.924719635366,0.0081062733484788
0.0091198130387109,239.910990846716,0.026235296255309,48.366055754697946,241.89339586081627,0.0082291330503684
0.0092385281365293,239.852552743104,0.0266122166908824,48.35427463300977,241.8629489974224,0.0083468683033934
0.0093705032605026,239.813328261503,0.0270312377094976,48.34636697751901,241.8550451377684,0.0084777378691953
0.0095085248036509,239.848747562773,0.0274694561089935,48.35350750865504,241.92387028528407,0.0086145848838586
0.0096385649540205,239.865453344119,0.027882333586417,48.3568753941744,241.9719127412837,0.0087435012936208
0.0097545071527566,239.938764434404,0.0282504500674041,48.371654909975845,242.07368666555007,0.0088584275662488
0.0098664688135991,240.061163691943,0.028605928340579,48.396330600295705,242.22405265129032,0.0089693956456138
0.0099914134697687,240.071810160535,0.0290026276239175,48.398476928363856,242.26479073158563,0.0090932169684615