File: example/data/02 processed data/test_ID_129.csv
Strain,Stress_MPa,Displacement(mm),Force(kN),True Stress (MPa),True Strain
-8.66503569119101e-05,1.49361916070233,-0.00027511488319531454,0.30111362279758974,1.4934897380689647,-8.665411127096612e-05
-0.0001869703783894,2.79096841016737,-0.000593630951386345,0.5626592314897418,2.790446581747648,-0.00018698785952964118
-0.0002844884363183,5.25805936038012,-0.0009032507853106025,1.0600247670526322,5.2565635032946165,-0.00028452891083007714
-0.0003913314470981,8.68121877038926,-0.0012424773445364674,1.7501337041104748,8.677821536485267,-0.0003914080372309451
-0.0004300848937991,12.4428671889314,-0.0013655195378121424,2.5084820252885702,12.437515699717892,-0.00043017740683367017
-0.0003864219905582,16.3607125896014,-0.001226889820022285,3.2983196580636416,16.354390450475574,-0.00038649667077489294
-0.0003291301257351,20.3844402518395,-0.0010449881492089425,4.109503154770843,20.37773111845637,-0.00032918430094238765
-0.0002435332639106,24.7396314489205,-0.000773218112916155,4.987509700102373,24.733606525725797,-0.00024356292295129992
-0.0001661709879841,29.1602053072252,-0.0005275928868495176,5.8786973899366,29.15535972709948,-0.00016618479591240084
-7.78189949559823e-05,33.5653609586858,-0.0002470753089852438,6.766776769271058,33.562748936030665,-7.782202301104069e-05
1.05607566321846e-05,37.8682785203877,3.3530402307186106e-05,7.63424494971016,37.868678438061224,1.05607008676854e-05
9.75063995877519e-05,41.93735770856,0.0003095828186911123,8.454571314045696,41.94144686931839,9.750164614784332e-05
0.0001813532455774,45.9340698857387,0.000575796554708245,9.260308488964922,45.94240017839506,0.00018133680306550698
0.0002726427481053,49.8225595397907,0.0008656407252343274,10.044228003221805,49.836143299341266,0.00027260558782535397
0.0003648819300473,53.6236713657818,0.0011585001279001775,10.810532147341613,53.64323767448597,0.0003648153768246942
0.0004565157155509,57.3936078859317,0.0014494373968741074,11.570551349803832,57.4198089699038,0.0004564115439544448
0.0005512972596269,61.0134019390722,0.0017503687993154075,12.300301830916956,61.047038460361726,0.0005511453511212434
0.0006385169650763,64.4580185307642,0.0020272913641172525,12.994736535802065,64.4991760691313,0.0006383131998526283
0.0007278842636851,67.9030168969098,0.0023110325372001925,13.689248206417018,67.9524424343658,0.0007276194844124123
0.0008162775042734,71.2796219063135,0.002591681076068045,14.3699717763128,71.33780585818874,0.00081594453097825
0.0009118279133615,74.6732544682161,0.0028950536249227623,15.054128100792367,74.74134362602177,0.0009114124508241146
0.0010032550031904,78.03603694542,0.00318533463512952,15.732065048196672,78.11432698991464,0.0010027520792355905
0.0011030898793069,81.2145876176457,0.0035023103667994075,16.372860863717374,81.30417460729882,0.0011024819227121513
0.0011970315944571,84.3192942394571,0.003800575312401292,16.998769718674552,84.42022709868405,0.0011963157233613633
0.0012802377156994,87.2855408351075,0.0040647547473455945,17.59676503235767,87.39728707651982,0.0012794189101642578
0.001372489960359,90.3424714572686,0.004357655624139824,18.21304224578535,90.46646559233773,0.0013715489569268958
0.0014703608444061,93.3909257519274,0.004668395680989367,18.827610631588563,93.52824411237586,0.0014692809223534064
0.0015710237488602,96.4481146658919,0.004988000402631134,19.443939916643806,96.5996369445648,0.00156979098201889
0.0016770259810815,99.4665960699842,0.0053245574899337626,20.052465767708817,99.6334041358433,0.0016756213432010335
0.0017752183610354,102.341629778538,0.005636318296287394,20.632072563353262,102.52330851881915,0.0017736445232491972
0.0018796979419433,105.161558780282,0.005968040965669977,21.200570250104853,105.35923074589284,0.0018779335204737824
0.0019807715488957,107.916483568591,0.006288949667743847,21.755963087427943,108.13024146890055,0.0019788124075789675
0.0020847960397651,110.710607025151,0.006619227426254192,22.31925837627044,110.94141606023705,0.0020826258682214017
0.0021842811245975,113.296576657794,0.006935092570597062,22.84058985421127,113.54404823166915,0.002181899050697308
0.0022812509228607,115.821292812992,0.007242971680082722,23.349572631099186,116.08551024410855,0.0022786528205061825
0.0023837575854096,118.218709270669,0.00756843033367548,23.83289178896687,118.50051401563027,0.002380920942315193
0.0024968237545454,120.615354765727,0.007927415420681644,24.316055520770565,120.91651004866898,0.002493711868924952
0.0026115877594333,122.882415318415,0.008291791136200728,24.773094928192464,123.20333353011017,0.002608183489865023
0.0027379673074098,125.068980390915,0.008693046201026114,25.213906446808465,125.4114151703964,0.0027342259025949596
0.0028718202811622,127.098896656766,0.009118029392689984,25.623137566004026,127.46390184589823,0.0028677044833034506
0.0030238190277198,129.028012902771,0.009600625413010365,26.012047401198632,129.41817026329528,0.0030192564821910767
0.0031798766221726,130.781259265694,0.010096108275398006,26.365501867963907,131.1971275346513,0.0031748315069066173
0.0033640337217876,132.28331289732,0.010680807066675629,26.668315880099712,132.72831842273635,0.003358388018361513
0.0035638156004234,133.447869215198,0.011315114531344294,26.90309043378392,133.9234528133504,0.003557480257141573
0.0037860890360577,134.430545157748,0.012020832689483197,27.101197903802,134.93951117088102,0.003778939840275876
0.0040203748381191,135.23206294402,0.012764690111028144,27.26278388951443,135.77574652718707,0.004012314727089112
0.0042763177409339,135.850592654604,0.013577308827465133,27.387479479168164,136.43153295408925,0.004267200277761205
0.0045374884407862,136.302574368737,0.014406525799496184,27.47859899273738,136.92104572438456,0.0045272250750024055
0.0048162449062452,136.680000902291,0.01529157757732851,27.554688181901867,137.33828526042225,0.004804683904297643
0.0051123509711475,136.909272984055,0.01623171433339331,27.60090943358549,137.60920123875414,0.005099327273869891
0.0054217504119076,137.101155454034,0.01721405755780663,27.639592939533255,137.8444837000899,0.005407105632853892
0.0057606530117932,137.166186518411,0.01829007331244341,27.652703202111656,137.9563533238945,0.005744123898841599
0.0061011739267759,137.179821141542,0.01937122721751348,27.655451942134864,138.01677908957058,0.00608263712442688
0.0064433786344928,137.157658833532,0.02045772716451464,27.650984020840053,138.04141756201705,0.006422708811862864
0.0067889568663766,137.137266454067,0.021554938050745705,27.64687291713991,138.06828544079644,0.006766015671368392
0.0071370467858521,137.078453149029,0.022660123545080416,27.635016154844248,138.05678848248584,0.007111698603422974
0.0074952809824234,136.993425657571,0.023797517119194294,27.617874612566315,138.02022987561924,0.007467330939318015
0.0078625443740078,136.91363392552,0.02496357838747476,27.601788599384832,137.99012344766606,0.00783179564233921
0.0082340237924908,136.790714828472,0.02614302554115829,27.577008109419957,137.91705282896146,0.008200309163519026
0.0086089778130275,136.717457902812,0.027333504556362312,27.562239513206897,137.89445546455084,0.008572131883044794
0.0089880660452904,136.584893551419,0.028537109693797018,27.535514539966066,137.8125275954481,0.008947913794381042
0.0093570781935425,136.415290899944,0.029708723264497434,27.501322645428715,137.69173944368964,0.00931357192120553
0.0097286026450488,136.272039746963,0.03088831339802994,27.47244321298774,137.5977762732915,0.009681584491672456
0.0101055957341825,136.10326290056,0.03208526645602944,27.438417800752894,137.47866745353622,0.010054875620037321
0.0104757924854844,135.980344738147,0.03326064114141297,27.413637499210438,137.40484661172846,0.01042130159782999
0.0108488060791649,135.868295947886,0.034444959301348554,27.391048463093817,137.3423047429312,0.010790379971664406
0.0112270244571404,135.746680460105,0.03564580265142077,27.36653078075717,137.27071176160624,0.0111644691889673
0.0116045418651931,135.621456617612,0.03684442042198809,27.341285654110585,137.19528148874957,0.011537725587296144
0.0119888138350892,135.490118395865,0.03806448392640821,27.314807868606387,137.11448420180724,0.011917517281544047
0.0123662705735833,135.306759682132,0.03926290907112697,27.27784275191781,136.97999968279603,0.012290432829587366
0.012752107140195,135.163913115024,0.04048794017011912,27.24904488398884,136.8875378165548,0.012671483710885514
0.0131225500465355,134.955606407072,0.041664096397750205,27.207050251665716,136.72656810620936,0.013037195290479127
0.0135143471309581,134.815545050936,0.042908052140791964,27.178813882268702,136.63748912540368,0.013423842834347662
0.0138849542102448,134.654552094561,0.04408472961752724,27.1463577022635,136.52422438459502,0.013789441345868967
0.0142718277669207,134.516829114873,0.04531305315997322,27.1185927495584,136.43663013175276,0.014170943964212902
0.014661628578449,134.426736949654,0.046550670736575574,27.100430169050252,136.39765183782274,0.014555186054662179
0.0150475995723919,134.317461426051,0.047776128642344276,27.078400223491887,136.33861680117045,0.014935507524596965
0.0154468750247745,134.197589760412,0.04904382820365904,27.05423409569906,136.27052315806705,0.015328786563298101
0.0158429203592005,134.053891772908,0.05030127214046158,27.025264581418256,136.17769690410708,0.01571873125789018
0.0162353398194283,133.916783291677,0.051547203926684854,26.997623511602082,136.09096777594212,0.016104956013890892
0.0166237868748241,133.733602903049,0.05278052332756651,26.96069434525468,135.95676181571162,0.01648712421730706
0.0170201031518614,133.593395110272,0.054038827507159944,26.93242845423084,135.8671684754562,0.016876883982030876
0.0174130692877539,133.408132292492,0.05528649498861863,26.89507947016639,135.731177343651,0.01726319909535407
0.0178037995476292,133.234467370736,0.05652706356372271,26.860068621940382,135.60654712063973,0.017647168264103598
0.0181930544993099,133.096413989812,0.057762948035308924,26.8322370603461,135.51784430319134,0.018029541110750807
0.0185863295599458,132.94830775883,0.05901159635282791,26.80237884418013,135.4193288212727,0.018415714565373612
0.0189733735443187,132.821371649992,0.06024046100321187,26.776788524638388,135.34144114897606,0.018795623913245466
0.0193726250369606,132.678711898906,0.061508084492349895,26.748028318819447,135.24904683491042,0.01918736456770308
0.0197694034318375,132.565095853227,0.06276785589608407,26.725123324010564,135.18582871412966,0.019576526670533518
0.0201723919354825,132.42595238743,0.06404734439515693,26.697072001305887,135.0973006014188,0.019971624716764686
0.020581168769762,132.302538219211,0.06534521084399435,26.672191704992933,135.02547908696843,0.020372238340690095
0.0209749322456955,132.126410329469,0.06659540988008321,26.63668432242095,134.89775283399658,0.02075798672215318
0.0213755130269233,131.930187179001,0.06786725386048147,26.5971257352866,134.75026261369015,0.02115026101307294
0.0217724332048821,131.779117110959,0.06912747542550067,26.566670009569336,134.6482691360557,0.021538798890307072
0.0221679900336064,131.634489779882,0.07038336835670032,26.537513139624213,134.5525618374013,0.021925852083409303
0.0225699751818639,131.542372388315,0.07165967120241788,26.518942273484303,134.51128046848277,0.022319041978911634
0.0229631917278892,131.393766381306,0.07290813373604821,26.48898330247129,134.4109866305694,0.02270350560651711
0.0233679653302107,131.250987202933,0.07419328992341896,26.460199020111297,134.31805572144708,0.02309911470058248
0.0237616774255948,131.071739297113,0.0754433258262635,26.424062642297983,134.18622368590266,0.023483762640815857
0.0241581457101798,130.928592332122,0.07670211262982086,26.395204214155797,134.09158434331013,0.02387095386291262
0.0245506290817523,130.781056925234,0.07794824733456356,26.365461076127175,133.99181414472494,0.024254105808375354
0.0249439689571611,130.644866635326,0.07919710143898649,26.33800511368172,133.90366813309,0.024637946664179042
0.0253447527046942,130.54879882864,0.08046958983740408,26.318637843853825,133.85752585084674,0.025028900141514664
0.0257491970463975,130.424143576622,0.08175370062231205,26.293507345046994,133.78246054918407,0.025423269543261674
0.0261561198781657,130.313893910354,0.08304568061317609,26.271281012327368,133.72239974126379,0.025819898796810983
0.0265626043184168,130.162384231404,0.08433626871097334,26.240736661051045,133.6198361408845,0.026215943750045764
0.0269814475118018,130.043392120246,0.08566609584997072,26.216747851441596,133.55215107899508,0.02662386604303929
0.0273905224011866,129.915602088092,0.08696490862376745,26.190985380959347,133.4740582973495,0.027022114170235832
0.0277976972493231,129.806558639001,0.08825768876660084,26.169002221622602,133.41488205702444,0.027418355107752628
0.0281943525738402,129.65904789696,0.08951706942194262,26.139264056027137,133.31470080775532,0.02780420808755625
0.0286094690150605,129.519948422351,0.09083506412281708,26.111221601945964,133.22544537357248,0.028207860047455867
0.0290198867214092,129.394095317343,0.09213814034047421,26.085849615976343,133.1490973058715,0.028606782925035584
0.0294389587935409,129.200321764836,0.09346869416949236,26.046784867790933,133.00384471338322,0.02901395363805189
0.0298432909821068,129.042165693635,0.09475244886818908,26.014900603836818,132.8932085933914,0.02940664598880255
0.0302502719761747,128.855294464835,0.09604461352435466,25.977227364110735,132.75320216796635,0.029801755227218122
0.0306562230100893,128.695907242307,0.09733350805703353,25.94509490004909,132.64123767521292,0.03019570909184262
0.0310693268874367,128.636789468182,0.09864511286761152,25.933176756785493,132.63344792991933,0.030596445148003214
0.0314849273618761,128.542593259271,0.09996464437395662,25.914186801069036,132.58974747094632,0.030999441073281557
0.0319005310138879,128.404718979674,0.10128418596909408,25.886391346302275,132.50089769981463,0.03140227773760425
0.0323146616559249,128.228250312668,0.10259905075756155,25.85081526303387,132.3719028362531,0.03180352529073142
0.0327170227246765,128.034470170196,0.10387654715084788,25.811749186311513,132.2233768402962,0.032193215266809516
0.0331214324143878,127.871116216048,0.10516054791568126,25.778817029155277,132.10639074955014,0.032584736388774564
0.0335288571919266,127.731597074683,0.10645412158436696,25.750689970256094,132.01429155189675,0.03297902156112907
0.0339405334622901,127.613041596274,0.10776119374277106,25.72678918580884,131.94429630479698,0.033377263274080624
0.0343678609389857,127.519439751574,0.1091179584812796,25.70791905391732,131.90201012397347,0.03379047774822056
0.0347869265652628,127.38249670066,0.11044849184470938,25.680311334853055,131.81374225908567,0.03419553747070975
0.0352040304026459,127.220348615183,0.11177279652840072,25.647622280820894,131.69901763566713,0.03459853811341724
0.0356244928362532,127.073606649665,0.1131077647551039,25.618039100572464,131.60053943943285,0.03500461948101166
0.0360421307734711,126.923550755162,0.11443376520577073,25.58778783224066,131.49814596971285,0.03540780978018037
0.0364636428276647,126.85062614753,0.1157720659778354,25.573086231342046,131.47606207183915,0.03581457541178891
0.0368923977569933,126.7482447577,0.11713336287845373,25.55244614315232,131.4242914183018,0.03622816085205823
0.037312981242868,126.624899087106,0.11846871544610589,25.527579655960572,131.34965157162324,0.03663369783108363
0.0377346596990442,126.472061134042,0.11980754454446534,25.496767524622864,131.24444132237178,0.03704012557149854
0.0381593284301772,126.308252488104,0.1211558677658126,25.463743701601768,131.1280905782393,0.037449268561926166
0.038585978043185,126.14402842087,0.12251048028711235,25.430636129647393,131.0114191317966,0.037860151511973424
0.0390075424106169,125.981699333114,0.12384894715370866,25.397910585555785,130.895935812812,0.03826597138873684
0.0394288658959118,125.822029755903,0.12518664921951994,25.365721198790048,130.78304969389993,0.038671394897853775
0.0398522075080217,125.686976345962,0.1265307588379689,25.33849443134594,130.6958798083571,0.039078594889595454
0.0402785661293573,125.57869883781,0.1278844474607094,25.316665685702496,130.63682876338737,0.039488529334784854
0.0406979382008213,125.435648821353,0.1292159537876076,25.287826802384767,130.54062110526434,0.03989158249398074
0.041122490733963,125.266502287381,0.13056390808033252,25.253726861136013,130.41777286696976,0.04029944912179017
0.0415416975598195,125.099957284929,0.1318948897524269,25.22015138864169,130.29682187520586,0.04070201698066469
0.0419555600439779,124.947593983648,0.13320890313962983,25.189434947103436,130.1898402653795,0.04109929371149905
0.0423755663145988,124.85433716167,0.1345424230488512,25.170634371792673,130.14511040572964,0.04150230671744071
0.0427965584680835,124.785801930571,0.1358790731361651,25.156817669203114,130.12620479887934,0.0419061027918283
0.0432254559163911,124.68170970011,0.13724082253454173,25.13583267554218,130.0711334463324,0.04231731365287762
0.0436531763726316,124.539529305662,0.13859883498310532,25.10716910802146,129.97607534380657,0.04272722772800559
0.044085919302841,124.392606955676,0.13997279378652017,25.07754956226428,129.87656938779395,0.04314178425693511
0.0445132193233661,124.22861228578,0.14132947135168736,25.04448823681325,129.75842775069435,0.04355095806016476
0.0449474395457963,124.099209898131,0.14270812055790325,25.01840071546321,129.67715163270833,0.043966587066471094
0.0453850327214157,123.985226224247,0.14409747889049482,24.995421606808197,129.6122997734066,0.044385269919861636
0.0458303080978418,123.843892212673,0.1455112282106477,24.96692867007488,129.5196959488157,0.0448111231301587
0.046264503229641,123.723210488177,0.14688979775411015,24.942599234416484,129.44720335938882,0.04522620483265359
0.0466922040392228,123.523107796405,0.14824774782453237,24.902258531755248,129.29067394919366,0.04563490971799598
0.0471256171138663,123.392703955752,0.14962383433652549,24.875969117479602,129.20766127701543,0.04604890283282682
0.0475447266228022,123.249446672202,0.150954507027397,24.847088449115923,129.1093079206435,0.04644907034919221
0.0479808042006716,123.164044756637,0.15233905333713232,24.82987142293802,129.07355467266794,0.04686526912868674
0.048412579467277,123.058898749478,0.15370993980860445,24.808673987894768,129.0164974643427,0.04727719112393294
0.0488454373948712,122.890868200847,0.15508426372871603,24.774799029290755,128.89352640995284,0.04768997575058387
0.0492752017838002,122.677109848747,0.15644876566356564,24.731705345507393,128.72204919079743,0.04809964179829766
0.0496947030979304,122.475265837753,0.157780682335929,24.691013592891004,128.56163781040024,0.04849936293649983
0.0501242948574627,122.336056060425,0.15914463617244407,24.66294890178168,128.46806460609682,0.048908533218266124
0.0505424426508782,122.268646414473,0.16047225541653828,24.649359117157758,128.44840246387702,0.049306642819824574
0.0509738637507841,122.153703219409,0.16184201740873952,24.626186569032853,128.38034944396887,0.04971722360347334
0.0514125529588389,122.043585399978,0.1632348556443135,24.603986816635565,128.31815769764094,0.05013454861179242
0.0518643863175722,121.92110055949,0.16466942655829173,24.579293872793183,128.24446361917097,0.05056419566135248
0.0523098989924774,121.819437174935,0.16608392930111573,24.558798534466895,128.1917996288763,0.050987651726444386
0.0527580007161674,121.714082015573,0.1675066522738315,24.53755893433952,128.13547364171825,0.05141338785640028
0.0532052710210377,121.598822676411,0.16892673549179468,24.51432265156446,128.06852099274857,0.05183815339490497
0.0536423265708112,121.397783734276,0.17031438686232556,24.47379320083004,127.90984329432276,0.05225304392285998
0.0540852915212229,121.213492065163,0.1717208005798827,24.436640000336862,127.76935911981278,0.05267336859207342
0.0545270968188332,121.082928766351,0.1731235323997954,24.41031843929636,127.68522934630171,0.05309241697338662
0.0549710746814508,120.969023015642,0.17453316211360628,24.387355039953427,127.618820213977,0.05351334918861339
0.0554145852736716,120.90611854586,0.17594130824390733,24.37467349884538,127.6060809621282,0.05393366155821074
0.0558619598039627,120.793153908783,0.17736172237758155,24.35189982801065,127.54089621702931,0.05435745685687015
0.0563098060367236,120.668240063977,0.17878363416659743,24.32671719689776,127.46304525677233,0.054781519186189176
0.0567660254556634,120.534788617662,0.18023213082173128,24.299813385320657,127.37706949662521,0.05521332520018013
0.0572178849475074,120.402165336769,0.181666784708336,24.27307653189263,127.29132258043902,0.05564082088404204
0.0576545914823606,120.20175766899,0.1830533279564949,24.232674346068386,127.13194090285731,0.05605380705311579
0.0580934891895286,120.059836199995,0.18444682817675329,24.204062977918994,127.03453099637599,0.05646869360551135
0.058528984600998,119.845202554714,0.18582952610816864,24.160792835030342,126.85962056954234,0.05688019393021003
0.0589601233392138,119.697466042984,0.1871983916020038,24.131009154265577,126.7548434042697,0.05728741089539488
0.0593992557193878,119.544152028265,0.18859263690905625,24.100101048898225,126.6449856843493,0.05770200757885223
0.0598438354477429,119.472818849819,0.19000417754658372,24.08572028012351,126.62253056154556,0.05812157222127551
0.0602886687407523,119.378818391402,0.19141652325188854,24.066769787706644,126.57600842806366,0.05854120004987399
0.0607398277891878,119.286168210614,0.19284895323067125,24.04809151125978,126.53158952535877,0.05896661541414447
0.0611864665744594,119.141519208689,0.19426703137390858,24.018930272471703,126.43136779138177,0.05938759025483919
0.0616341311172374,119.026306078494,0.19568836629722874,23.995703305424392,126.36238903373633,0.05980935415698037
0.0620689407716869,118.832623518205,0.19706888695010588,23.956656901270126,126.20843858910062,0.06021883669366867
0.0625146328463432,118.690868287431,0.19848395928713966,23.928079046746088,126.11078434063344,0.06063839381227651
0.0629580148289879,118.575832389293,0.19989169708203658,23.90488780968147,126.04113140321769,0.06105560171148037
0.063404410758708,118.496436752198,0.20130900415889788,23.888881649243118,126.00963350147761,0.06147546986839119
0.0638635885461876,118.418075248634,0.2027668936341456,23.87308397012461,125.98067848274424,0.061907176446745295
0.0643196516947126,118.311690201199,0.20421489413071248,23.85163674456172,125.92145690635287,0.0623357703261471
0.0647809160210022,118.175001988693,0.20567940836668194,23.824080400920508,125.83048686830429,0.06276906534330179
0.0652509165083637,118.083359724145,0.20717165991405476,23.80560532038763,125.78840717053225,0.06321037376678312
0.0657150070661462,117.974403291116,0.2086451474350142,23.78363970348899,125.72709203701609,0.06364594203184615
0.0661787221671556,117.839213820561,0.21011744288071904,23.756385506225097,125.63766241238795,0.06408096850803853
0.066645364331073,117.699264969079,0.21159903175115677,23.728171817766324,125.54337536444275,0.06451854999853017
0.0671006644620791,117.482232449564,0.21304460966710115,23.6844180618321,125.36536830941817,0.06494531132042357
0.0675512898379545,117.321379957674,0.21447534523550552,23.65199019946708,125.24659049938361,0.06536751165304587
0.0679922198802084,117.164951249542,0.21587529811966166,23.620454171907667,125.13125637715474,0.06578045575510988
0.0684526888275588,117.039964804226,0.21733728702749916,23.59525690453196,125.0516650953581,0.06621151667561734
0.0689159191868721,116.94484411501,0.2188080434183189,23.576080573586015,125.00420554136137,0.0666449752422204
0.0693770035760125,116.809863131326,0.22027198635383965,23.54886840727532,124.91378142350152,0.06707623925790165
0.0698383098114229,116.702716721079,0.2217366336512677,23.527267690969524,124.85303720728042,0.06750752472942388
0.0702910643574595,116.562977607928,0.2231741293349339,23.499096285758288,124.75631336866398,0.06793063424631175
0.0707439728251477,116.428241260878,0.22461211371984394,23.471933438193005,124.66483759671729,0.06835370856931756
0.0711927768293818,116.25256210661,0.2260370664332872,23.436516520692575,124.52890481650974,0.06877277230766046
0.0716421699740865,116.106957670552,0.22746388966772463,23.407162666383282,124.42511206715977,0.06919221026013878
0.0721040133978958,116.004120955282,0.22893024253831915,23.386430784584856,124.3684836468528,0.06962308536516457
0.072569670331773,115.918693281822,0.23040870330337926,23.369208565615317,124.33087463857375,0.07005733039248714
0.0730420840981968,115.817975763276,0.23190861701177484,23.348903913876445,124.27756208906013,0.07049768384700406
0.0735135503733108,115.696702304219,0.23340552243526178,23.324455184530553,124.20197765708616,0.07093696086840899
0.0739832295581786,115.568697813038,0.23489675384721703,23.298649479108462,124.11884331307976,0.07137438102823956
0.0744507795631008,115.448752770666,0.236381225112845,23.27446855856627,124.04400241402979,0.07180962829235689
0.0749298687524725,115.314059955409,0.23790233328910015,23.247314487010453,123.95452733318253,0.07225542108171802
0.0753985121140397,115.153887465601,0.23939027596207602,23.21502371306516,123.83631924465489,0.0726913018273354
0.0758620861941061,115.024127651521,0.24086212366628687,23.188864134546634,123.75009793782256,0.07312228084271505
0.0763294969189711,114.87839768929,0.24234615271773324,23.159484974160865,123.647007991771,0.0735566387650127
0.0767978863636083,114.742638962927,0.24383328920445635,23.132116014926083,123.5546311110624,0.07399171701970621
0.0772714675070491,114.600380962128,0.24533690933488086,23.103436801965003,123.45572057593853,0.07443142537934672
0.0777291670493996,114.403173308809,0.2467901053818437,23.063679739055896,123.29563667791084,0.0748562044182882
0.0781906156542917,114.28436974037,0.2482552047023761,23.03972893965859,123.22033497003224,0.07528428028237266
0.0786478063151876,114.158068390966,0.2497067850507206,23.014266587618746,123.13635004309464,0.07570822550060183
0.0791126585165398,114.091779435209,0.2511826907900139,23.000902734138137,123.11788342121108,0.07613909094291578
0.0795860836988987,113.989217058942,0.2526858157440034,22.980226159082708,123.06117242856689,0.07657771184048769
0.0800636094097763,113.858071942199,0.2542019598760398,22.95378730354732,122.97396014232945,0.07701993700337752
0.0805439538082575,113.708137502664,0.25572705334121754,22.923560520537063,122.86664047730156,0.07746457527510463
0.0810215120853856,113.591667906802,0.25724330087109926,22.900080250011282,122.79503660091207,0.07790643863056004
0.0815018152303231,113.465073208878,0.25876826335627584,22.874558758909803,122.71268264064305,0.07835064484722208
0.0819806432671189,113.327420469353,0.2602885423731025,22.846807966621565,122.61807529923381,0.07879329049265671
0.0824564558646759,113.157668086254,0.261799247370346,22.81258588618881,122.48824835055785,0.07923295455627177
0.0829290834071555,113.008635980936,0.2632998398177187,22.7825410137567,122.38033857992791,0.07966948425633041
0.083398259373859,112.856922044733,0.2647894735120023,22.751955484218175,122.26899290155501,0.080102637607418
0.0838642010471458,112.722389812365,0.2662688383246879,22.724833786172784,122.1757629741039,0.08053261938302177
0.0843327040576865,112.590245587125,0.26775633538315463,22.6981935103644,122.08528544800625,0.08096477848880147
0.084804687727124,112.499423773303,0.2692548835336187,22.679883832697882,122.03990227587934,0.0813999594770357
0.0852808020424975,112.386763953821,0.27076654648492954,22.657171613090313,121.97119732276371,0.08183875723431987
0.0857574435522025,112.252705105935,0.27227988327824293,22.630145349356493,121.87921012763925,0.08227784808712293
0.0862306216454144,112.103616890861,0.2737822237241907,22.600089165197577,121.77038146405931,0.08271355775632355
0.0867082407067576,111.972387070881,0.2752986642439554,22.57363323348961,121.68131576153318,0.08315316429777789
0.0871842313032958,111.830807329626,0.2768099343879642,22.545090757652602,121.58069030268642,0.08359107979753096
0.0876589770892928,111.726914318897,0.2783172522585046,22.524145926689634,121.52078134143457,0.08402765912582978
0.088145806165162,111.58620031854,0.2798629345743893,22.49577798421766,121.42205590252497,0.08447515247425884
0.0886334207333556,111.492192478095,0.28141111082840403,22.47682600358395,121.37412688249027,0.08492316720200353
0.0891352716820078,111.372108095967,0.2830044875903747,22.452616992146947,121.29929120889895,0.0853840526571791
0.0896272352793041,111.243235360968,0.28456647201179047,22.426636248771153,121.21365898989649,0.08583565176822086
0.0901000499381173,111.085283562862,0.2860676585535224,22.39479316627298,121.09407315926579,0.08626948096275842
0.0905707800309848,110.884173604342,0.2875622265983767,22.354249398635346,120.92703970077838,0.08670121058807356
0.0910484807310504,110.721537528739,0.289078926321085,22.321461965793784,120.80256530493666,0.08713914283068987
0.0915333174755623,110.553126441273,0.29061828298491027,22.287510290560636,120.67242086173802,0.08758342102716829
0.0920266300548127,110.46633404295,0.2921845504240303,22.27001294305872,120.63217849943192,0.08803526352244875
0.0925221371985208,110.340961561881,0.2937577856053035,22.244737850875207,120.54994314612607,0.08848891066425994
0.0929990876624541,110.205092865466,0.29527210332829174,22.217346721677945,120.45406595771036,0.08892537448449597
0.093487570637093,110.03484007269,0.2968230367727702,22.183023758654304,120.32172995652684,0.08937219448306477
0.0939748508121205,109.871071188324,0.29837015132848255,22.150007951566117,120.19618871181461,0.08981771544681662
0.0944648708759408,109.7266779436,0.299925965031112,22.120898273429756,120.09199440718811,0.09026554141812705
0.0949611724405983,109.5965701128,0.3015017224988996,22.09466853474048,120.00398890617971,0.09071890368142271
0.0954518342912668,109.443965945105,0.30305957387477206,22.06390353453317,119.89059324667623,0.09116691221439566
0.0959411146850071,109.293835263995,0.3046130391248975,22.033637189221395,119.77960764742222,0.09161345960526789
0.0964160885261751,109.096913577167,0.3061210810706059,21.993937777156866,119.61561125455562,0.09204675929557712
0.0968980449887011,108.923598573084,0.30765129283912596,21.958997472333735,119.47808232794992,0.09248623712770215
0.0973732157423211,108.784114013197,0.3091599599818695,21.930877385060516,119.37677301634128,0.09291933833041233
0.097853943772559,108.632260420414,0.3106862714778748,21.900263700755463,119.26235552347917,0.09335731399579057
0.0983384918230314,108.513575138691,0.31222471153812464,21.876336747960103,119.18463646015508,0.09379857592756055
0.0988390681395481,108.390651954597,0.3138140413430652,21.851555434046755,119.10388298882746,0.09425422988498221
0.0993386964597702,108.274686522792,0.31540036125977033,21.828176802994868,119.0305527415564,0.0947088139835681
0.0998416925868176,108.181593895511,0.31699737396314587,21.80940932933502,118.98262733677855,0.09516625361728219
0.100333598454596,108.032236394797,0.31855917509334225,21.779298857191076,118.87149942138456,0.095613405149233
0.100825967046694,107.887725338596,0.3201224453732534,21.750165428260953,118.76560957832805,0.09606077716898725
0.101317775223418,107.661279322422,0.32168393633435216,21.704513911400277,118.56928062107677,0.09650744027772115
0.101803668841739,107.501272595597,0.3232266485725213,21.672256555272355,118.44529655098466,0.09694853591274215
0.102293149248865,107.327757722291,0.32478074886514635,21.637275956813866,118.30665206152334,0.09739269100716025
0.102799684606352,107.189720816281,0.32638899862516757,21.60944771656225,118.2087903092376,0.09785211417394896
0.103287829285559,107.039879396646,0.32793885798164985,21.579239686363834,118.0957961865136,0.09829465753100068
0.103775859911278,106.775076548653,0.3294883552183076,21.525855432208445,117.85575193458199,0.09873690179976538
0.104261080572209,106.566484983098,0.33102893081676354,21.483803372592558,117.67722186021788,0.09917640592204288
0.104740085352577,106.348043763373,0.33254977099443195,21.439765622695997,117.4869469442283,0.0996100904263923
0.105230322318266,106.245474464474,0.33410627336049453,21.419087652037962,117.4257199872277,0.1000537497369682
0.105722778874953,106.127834341802,0.33566982292797576,21.395371403307287,117.34796390439799,0.10049921966988087
0.106212865970695,105.965820748653,0.3372258494569566,21.362709462928446,117.22075426530436,0.10094234929248401
0.106708327752007,105.815044171701,0.3387989406126222,21.332312905014923,117.10639058626799,0.10139013911075379
0.107196590266384,105.574226501765,0.3403491740957692,21.28376406275582,116.89142360276513,0.10183122627607817
0.107687169475885,105.413767744483,0.3419067630859349,21.251415577287773,116.7654780166747,0.1022742104420557
0.108181342368284,105.254870587286,0.3434757620193017,21.21938191039686,116.64148377821863,0.1027202413305767
0.108689007520862,105.129910533515,0.3450875988787368,21.194189963556624,116.55637617015977,0.10317824300079394
0.109196273048309,104.998506332905,0.34669816692838107,21.167698876713647,116.46395190009748,0.10363567471805747
0.109701864298754,104.821531442479,0.34830341914854396,21.132020738803767,116.3206488603694,0.10409138852545145
0.110197815854345,104.567492210361,0.34987806533754534,21.080806429608778,116.09060146130902,0.10453821192767687
0.110696093878763,104.301820975978,0.3514600980650725,21.027247108757166,115.84762514246079,0.10498693037442007
0.111195804860241,104.090181012698,0.35304668043126514,20.984580492159917,115.66457246845313,0.10543673712711325
0.111701437904518,103.884708528587,0.3546520653468446,20.943157239363142,115.48877984752191,0.10589166868514487
0.112213414690845,103.790346398281,0.35627759164343287,20.924133833893453,115.43701557957775,0.10635209710017529
0.112723329205757,103.579740901198,0.3578965702282785,20.881675765681518,115.25559413385075,0.10681046026509539
0.113228199965824,103.351468244756,0.3594995348914912,20.835655998142812,115.05376895793475,0.1072640826931743
0.113732636508778,103.139308719711,0.36110112091537017,20.792884637893735,114.86961422809654,0.10771710956577965
0.114234889328962,102.934189590827,0.3626957736194543,20.751532621510723,114.69286534690151,0.10816797145929227
0.114741580070427,102.675760364367,0.3643045167236057,20.699433289456387,114.45693934350699,0.10862261129703736
0.115259465400523,102.422013973848,0.36594880264666046,20.648278017127755,114.2271205497186,0.10908708223570192
0.115760123788016,102.163818833741,0.3675383930269508,20.596225876882187,113.99031514859129,0.10953589801331615
0.11626940827928,101.930483388649,0.369155371286714,20.54918545115164,113.7818803778682,0.10999224009372817
0.116772687450901,101.70232635759,0.37075328265661067,20.50318899369014,113.57838032637439,0.11044299664785188
0.117275730703856,101.445784886993,0.3723504449847428,20.451470233217787,113.34291343644128,0.1108933389567909
0.117783005169901,101.197049927748,0.37396104141443565,20.401325265433996,113.11634258256666,0.11134726391778926
0.118281951136242,100.942213499879,0.3755451948575683,20.34995024157561,112.8818554646558,0.11179353536729683
0.118791867498371,100.72360336476,0.37716417930732793,20.305878438335615,112.68874830962504,0.11224941336891885
0.119309838253761,100.47805820236,0.37880873645569113,20.256376533595777,112.46607907453556,0.1127122795231302
0.119820203436478,100.221327697964,0.38042914591081767,20.204619663909543,112.22986757140796,0.11316813977425692
0.12033603681632,99.9218096870409,0.382066916891816,20.14423683290745,111.94600425629397,0.11362867317785633
0.12084856206796,99.6439191355438,0.383694184565773,20.08821409772563,111.68574348189036,0.11408604314267731
0.121356463408096,99.3365315808809,0.3853067713207048,20.02624476670559,111.39166174076324,0.11453908052601382
0.121869593357006,99.1056158888086,0.386935958908494,19.979692163183813,111.18357699657334,0.11499657339108856
0.122376119802308,98.7928093705242,0.3885441803723279,19.91663036909768,110.88269004565805,0.11544797356615227
0.122884820706303,98.4803900285642,0.390159305742512,19.853646629758543,110.58213510031109,0.11590110656599312
0.123397696098981,98.1246041818918,0.39178768511426465,19.781920203069387,110.2329542685617,0.11635775028534132
0.123895590540771,97.7272803400441,0.3933684999669479,19.70181971655289,109.83525944971736,0.11680085617890354
0.124404819451496,97.3744697995068,0.3949853017584998,19.63069311158057,109.48832313409959,0.11725384628393534
0.124911614978064,97.0531811716589,0.39659437755535315,19.565921324206435,109.17625077056945,0.11770446810609121
0.125426113526531,96.7601173667772,0.3982279104467359,19.506839661142283,108.89636283246304,0.11816173152119065
0.125934317168224,96.4010094170263,0.3998414570091112,19.434443498472504,108.54120471228705,0.11861319512816915
0.126439562632142,95.9718948204041,0.40144561135705087,19.34793399579347,108.10653922647393,0.11906182888025024
0.126934057293551,95.6076224286144,0.40301563190702444,19.274496681608664,107.74348585166835,0.11950072162752863
0.127438938175752,95.2339190989349,0.4046186287080126,19.19915809034528,107.37042862721863,0.11994863409956097
0.127943766316431,94.9312444310909,0.4062214580546684,19.138138877307927,107.07710538471038,0.12039629927683158
0.128460965596214,94.5790156768018,0.40786356576797944,19.067129560443245,106.72872735578323,0.12085472704160809
0.128983639684338,94.2318324441853,0.40952305599777306,18.997137420747755,106.38619716696101,0.12131779408320112
0.129516589635229,93.8694889955441,0.41121517209185204,18.92408898150169,106.02714508104864,0.12178974441011688
0.130053020502093,93.4646439593435,0.41291834009414524,18.84247222220365,105.62000321640883,0.12226455242181546
0.130585443762435,92.9782485890513,0.4146087839457311,18.744414915552742,105.11985444130656,0.1227355903861805
0.131112364438571,92.4860189922529,0.4162817570924629,18.645181428838185,104.61207961983776,0.1232015418353606
0.131633306189638,91.9643711233688,0.41793574715210063,18.54001721847115,104.06994534598871,0.12366199284143971
0.132148123529705,91.5013549235934,0.41957029220681336,18.44667315259643,103.5930872771718,0.1241168223953741
0.132675512383637,91.0485829046588,0.4212447518180475,18.355394313579215,103.12850029333846,0.12458254418942595
0.13319875322556,90.5854061219939,0.42290604149115296,18.262017874193972,102.6512692778745,0.12504438874908697
0.133709445312101,89.9875905586223,0.4245274888659206,18.141498256618256,102.01978137718815,0.12549495141016861
0.134209221351179,89.4018483509618,0.4261142777899933,18.0234126275539,101.40040080550057,0.12593568683380993
0.134703553170956,88.8837139317796,0.4276837813177853,17.91895672864677,100.8566660174211,0.12637143018467784
0.135227046198477,88.3740135439258,0.42934587168016447,17.81620113045544,100.32457035617509,0.12683267163139636
0.135769426678355,87.9802716652452,0.4310679297037771,17.73682276771343,99.92530270824147,0.12731033022458949
0.136311858400283,87.4258073672904,0.4327901504208985,17.625042765245748,99.3429816416709,0.1277878058640356
0.136844359120511,86.8283934116344,0.43448084020762234,17.504604111785493,98.71036926151311,0.1282563180814224
0.137377462252535,86.1997202389637,0.4361734426517986,17.377863600175083,98.04161905227102,0.12872514054788392
0.137903815109642,85.5173510596938,0.43784461297311333,17.24029797363427,97.31052002889616,0.12918781113875413
0.138436731941068,84.8840971321841,0.4395366239128909,17.112633981848315,96.63517413293184,0.12965603355991373
0.138966121180618,84.2681479317631,0.4412174347484621,16.988458623043442,95.97856558891472,0.1301209396685184
0.139503489423875,83.6810138156323,0.4429235789208031,16.870092385231473,95.35480724144048,0.1305926319401374
0.139771572983984,83.3668820330738,0.44377474422414914,16.806763417867675,95.01920226960674,0.13082786775328406