File: example/data/02 processed data/test_ID_115.csv
Strain,Stress_MPa,Displacement(mm),Force(kN),True Stress (MPa),True Strain
-1.17018330470818e-05,-0.15376223302263,-3.715331992448471e-05,-0.030998466177362214,-0.15376043372265022,-1.1701901514088827e-05
7.93386440391947e-06,-0.110953320040616,2.5190019482444318e-05,-0.022368189320188185,-0.11095420032921237,7.933832930961596e-06
2.14038125276001e-05,0.682851093628574,6.79571047751303e-05,0.13766278047552052,0.6828657092453664,2.140358346936031e-05
6.25650691519322e-05,2.68036098370839,0.0001986440945573847,0.5403607743156115,2.680528680678688,6.256311203961266e-05
0.0001297361358393,6.19438279048449,0.00041191223128977743,1.2487875705616733,6.195186425771637,0.00012972772083456118
0.000175266807461,10.4410568604493,0.000556472113688675,2.104917063066579,10.442886831151752,0.00017525145002855684
0.000205440532211,14.9700993438725,0.000652273689769925,3.0179720277246957,14.973174809048956,0.00020541943219462187
0.000236901416762,19.4587087267879,0.00075216199821935,3.9228756793204407,19.463318522453637,0.00023687336005242214
0.0002636677647393,24.1352383727465,0.0008371451530472775,4.865664055945695,24.141602057099693,0.0002636330105032382
0.0003195537065374,29.2522364904333,0.001014583018256245,5.897250876471353,29.26158415102833,0.00031950266012621047
0.0003923613226754,34.4837177543542,0.001245747199494395,6.951917499277807,34.49724783146307,0.00039228436910015237
0.0004552588573383,39.6610825152154,0.0014454468720491024,7.995674235067424,39.679138574322074,0.0004551552584664097
0.0005369196940395,44.8943922076891,0.0017047200285754123,9.050709469070123,44.91849689101734,0.0005367756042346668
0.0006211972049314,50.0835988835936,0.001972301125657195,10.096853534932471,50.114710675233,0.0006210043418143241
0.0007079202932931,55.3068818558661,0.0022476469312055925,11.149867382142606,55.34603471989064,0.0007076698359179143
0.0007948292196694,60.6596086444675,0.002523582772450345,12.228977102724649,60.707822673871824,0.0007945135102041111
0.0008884169368726,65.9784792801912,0.0028207237745705048,13.301261422886546,66.03709567865282,0.000888022528128041
0.0009926022497498,71.2371287164624,0.0031515121429556148,14.36140514923882,71.30783885069206,0.0009921099458843094
0.0011097247862934,76.3746117284673,0.003523376196481545,15.397121724459007,76.45936652814592,0.0011091094969019845
0.0012030914663624,81.4302686426653,0.0038198154057006196,16.416342158361324,81.52823670397288,0.001202368331764041
0.0012979977139464,86.4484937125792,0.004121142741779819,17.428016332455964,86.56070365979224,0.0012971560431595266
0.0014070656252293,91.4974348761106,0.004467433360103027,18.445882871023898,91.62617777152144,0.0014060766359990263
0.0015190551323637,96.5573887109983,0.004823000045254747,19.465969564137257,96.70406470788737,0.0015179025352074762
0.0016197571998426,101.563406278657,0.005142729109500255,20.475182705777254,101.7279143372174,0.0016184468079697017
0.0017112481955135,106.442938995528,0.005433213020755362,21.458896501498444,106.62508928280924,0.0017097856785687744
0.0018188833514958,111.225512731506,0.005774954640999165,22.42306336667161,111.42781896487493,0.0018172311862665032
0.0019233510862562,115.879830396539,0.006106639698863435,23.361373807942265,116.10270799420738,0.0019215038148107917
0.0020334179366942,120.521406571944,0.006456101949004085,24.297115564903912,120.76647696182299,0.002031353340758651
0.0021524481031933,125.018207955332,0.006834022727638727,25.203670723794932,125.2873031599101,0.002150134905538791
0.0022513278942313,129.355192234304,0.007147966064184378,26.078006754435687,129.64641318684477,0.002248797452778266
0.0023560527030281,133.664465854113,0.007480467332114217,26.94675631618918,133.97938638018738,0.0023532815626401524
0.0024586958259481,137.845377056688,0.007806359247385218,27.789628014628303,138.1842969098835,0.002455678178671487
0.0025514533321764,142.04413762755,0.00810086432966007,28.636098145714076,142.40655661581593,0.002548203901130811
0.0026562778041068,146.036831054839,0.00843368202803909,29.441025140655547,146.4247454477521,0.00265275613319953
0.0027588642665282,149.937648961872,0.008759394046227035,30.227430030713396,150.35130658380012,0.002755065585600392
0.0028612049480973,153.780593151777,0.009084325710208927,31.002167579398243,154.2205909458242,0.0028571194922489456
0.0029688495230802,157.454775694613,0.009426097235779635,31.742882780033984,157.92223523034065,0.0029644511925055964
0.0030701939137733,161.136468439695,0.009747865676230226,32.48511203744251,161.63118864438547,0.003065490492922993
0.0031772389796743,164.613545714118,0.010087733760465902,33.18609081596619,165.1365622881433,0.0031722022217430678
0.0032951058620737,167.984430468079,0.010461961112083997,33.86566118236473,168.5379569496515,0.0032896888971392503
0.0034184890506152,171.190172001891,0.01085370273570326,34.51193867558123,171.7753837304524,0.0034126592991038695
0.0035453625553824,174.270986100421,0.011256526113339119,35.133030797844874,174.88883992903098,0.0035390925727620047
0.0036787040087951,177.130404891653,0.011679885227924442,35.70948962615725,177.78201522220743,0.0036719541260186953
0.0038389857777257,179.627508231428,0.012188779844279097,36.212905659455885,180.31709568081678,0.003831635677106984
0.004039312836884,181.844206640047,0.0128248182571067,36.65979205863348,182.57873227824115,0.004031176714988929
0.0042546552216023,183.657646450749,0.013508530328587303,37.025381524471,184.43904641520788,0.004245629767150105
0.0044956440197901,185.163061416575,0.014273669762833566,37.32887318158152,185.99548862631846,0.004485568797337141
0.0047597852282135,186.286290856073,0.015112318099577861,37.55531623658432,187.17297359150842,0.00474849326786497
0.0050197967804674,187.024834011001,0.015937854777983994,37.7042065366178,187.96366067063687,0.005007239606052704
0.0053271894814153,187.558865690311,0.016913826603493578,37.8118673231667,188.5580273067626,0.00531305020038698
0.0056311069091328,187.945930801877,0.01787876443649664,37.8898996496584,189.00427443135885,0.005615311495986084
0.0059486979976216,188.235625194162,0.01888711614244858,37.94830203914306,189.35538208083554,0.005931074350984781
0.0062727282892517,188.499063920542,0.019915912318374147,38.00141128638127,189.68146733129385,0.006253136615304096
0.0066152469969346,188.709319398476,0.021003409215267353,38.043798790732765,189.9576781569203,0.0065934622719667265
0.0069619839239899,188.896391798494,0.02210429895866793,38.081512586576395,190.2114854414948,0.006937861210490655
0.0073189194159525,189.040117362203,0.023237569145649187,38.11048766022013,190.42368674755915,0.007292266095238108
0.0076697559893086,189.095457387736,0.024351475266054804,38.12164420936758,190.54577340458664,0.007640492942548717
0.0080381149914301,189.148481641012,0.02552101509779057,38.13233389882802,190.6688788868969,0.008005981425800798
0.0084016306206992,189.202741220659,0.02667517722071996,38.14327263008485,190.7923527648187,0.0083665333679037
0.0087734725115623,189.310313097287,0.027855775224210302,38.16495912041306,190.9712219254013,0.008735209239916534
0.0091567205010526,189.369868115244,0.029072587590842004,38.17696541203319,191.10387506889649,0.009115051907839622
0.0095287376594267,189.436034841166,0.03025374206867977,38.19030462397907,191.24112112040947,0.009483625586400254
0.0098832897560828,189.449013139544,0.03137944497556289,38.19292104893207,191.32139263040605,0.009834769479261962
0.0102635047794248,189.445151120207,0.03258662767467374,38.19214246583373,191.38952233416808,0.010211192646984304
0.0106388721583347,189.466556051317,0.03377841910271267,38.19645769994551,191.4822665194269,0.010582677571253925
0.0110447947363027,189.488419046745,0.035067223287761067,38.200865279823795,191.5812797400228,0.010984246412185759
0.0114220740404204,189.527593467274,0.03626508507833477,38.20876284300244,191.69239167255992,0.011357334658345637
0.0118039274077518,189.528440551846,0.037477469519611964,38.20893361525216,191.76562050582436,0.011734804472980156
0.0121907607415127,189.484295625879,0.03870566535430282,38.20003399817721,191.79425333812816,0.012117051858050834
0.0125733032899313,189.458896957912,0.03992023794553188,38.19491362671506,191.84102113033967,0.012494915688969214
0.0129514590640206,189.436471474181,0.0411208825282654,38.19039264919489,191.88995017971135,0.012868306116488109
0.0133273024974241,189.417651930338,0.04231418542932151,38.186598629156144,191.9420782759654,0.013239275249505317
0.0137140899294319,189.40160731926,0.04354223552594628,38.18336403556281,191.99907799481528,0.013620902815816667
0.0140821927822643,189.303122442286,0.04471096208368915,38.16350948436486,191.96892550680286,0.013983959854646486
0.014468895338851,189.3012007264,0.04593874270085192,38.16312206644224,192.0401799872291,0.014365219723855974
0.014815008632637,189.313515528153,0.04703765240862247,38.16560473047565,192.11819689497747,0.014706338378042227
0.0152051419692512,189.37793972549,0.048276325752372555,38.178592648658785,192.25745818486035,0.01509070238674575
0.0155912844278122,189.435404262006,0.04950232805830373,38.19017749922041,192.3889455305525,0.015470989113859619
0.0159833570011675,189.398281527334,0.05074715847870681,38.18269355591054,192.42550187639304,0.01585696811775907
0.016390796141857,189.3803818773,0.05204077775039598,38.179084986463685,192.48447710991786,0.016257917072475547
0.0167903579191218,189.357200975876,0.053309386393211707,38.1744117167366,192.53657615482402,0.016650958077808902
0.0171795463390893,189.346426431876,0.05454505962660852,38.17223956866621,192.5993121389034,0.01703364655702637
0.0175712204392557,189.320243384567,0.055788624894636846,38.1669610663287,192.64683111469077,0.01741863140273712
0.017970197028492,189.259091901333,0.0570553755654621,38.15463292730873,192.66011507223342,0.01781064169633448
0.01835543602586,189.235838063576,0.0582785093821055,38.149944953616924,192.70934438295197,0.018189008491615737
0.0187532670723852,189.246544230757,0.059541622954823,38.15210331692061,192.79553521724233,0.018579592510011702
0.0191601619990069,189.23275460901,0.060833514346846904,38.14932332917641,192.85848484283696,0.01897891755122722
0.0195540192891106,189.214529088783,0.062084011242926146,38.14564906429865,192.91443364036505,0.019365295689583683
0.0199657416503228,189.1131837127,0.06339122973977489,38.12521783648032,192.88896868137778,0.019769040114805986
0.0203590226714825,189.074501370144,0.06463989698195693,38.11741947622103,192.923873430138,0.020154548375949072
0.0207588190089755,188.966270238668,0.0659092503534972,38.09560008011547,192.88898684135367,0.02054629091471082
0.0211584353062885,188.900464953501,0.06717803209746599,38.082333734625806,192.89730322054749,0.020937703741621776
0.0215493979158712,188.859671206578,0.06841933838289105,38.07410971524613,192.92948341166917,0.02132049232058344
0.021941651612885,188.812358514759,0.06966474387090987,38.064571476575416,192.955213505497,0.021704397796383678
0.022338430307478,188.803882426396,0.07092451622624264,38.062862697161435,193.02146479575933,0.022092582080019428
0.022741119788521,188.759737023825,0.07220305532855417,38.05396298400313,193.05234481473354,0.02248639510917853
0.023153462266305,188.687152329554,0.07351224269551837,38.03932990963809,193.05591319115288,0.022889487709338886
0.0235545887534624,188.583193510104,0.07478581929224312,38.01837181163697,193.02519307904913,0.023281460069142213
0.0239707577401283,188.565020003284,0.07610715582490735,38.01470803266205,193.08506641604515,0.02368796931515416
0.0243856877493475,188.510749700042,0.07742455860417831,38.00376713952847,193.10771397962264,0.024093103895913633
0.0247873818041474,188.403261022624,0.07869993722816798,37.982097422161004,193.07328458673823,0.024485158687100713
0.0251955031350915,188.346463795567,0.07999572245391551,37.97064710118631,193.0919477146116,0.024883329168751536
0.0255573406340321,188.266252321658,0.08114455651305191,37.95447646804625,193.07783706213525,0.025236211773590957
0.0259710215485697,188.255537019563,0.0824579934167088,37.952316263143906,193.14472562813566,0.025639502244997742
0.0263965533241629,188.253109833126,0.0838090568042172,37.951826942358196,193.22234308527558,0.026054176289647936
0.0268262428670999,188.203299671632,0.08517332110304217,37.94178521380101,193.2520870970128,0.026472727603228923
0.0272371690590183,188.133767897484,0.0864780117623831,37.927767608132775,193.25799913941788,0.026872838130503257
0.0276444078009162,188.059024678576,0.08777099476790894,37.91269937520092,193.25780504743312,0.027269200384966302
0.0280543498150082,187.960942865794,0.08907256066265103,37.89292608174407,193.23406490850974,0.027668035105284434
0.0284799123657986,187.881842261008,0.09042372176141054,37.87697939981921,193.2327006637263,0.028081898919460373
0.0288897872367354,187.781672508674,0.09172507447663489,37.856785177748684,193.2066450744079,0.028480344445744227
0.0293005181754769,187.722090880314,0.09302914520713916,37.8447735214713,193.22244541609115,0.028879462975370765
0.0297164209903506,187.655018431615,0.09434963664436315,37.831251715813586,193.23145396028087,0.029283444907349066
0.0301368072087485,187.582479904407,0.09568436288777649,37.81662794872845,193.23561693702504,0.029691615954178283
0.0305517464708309,187.537764419638,0.0970017950448881,37.80761330699902,193.2673706518932,0.030094335003546076
0.0309870836351073,187.469548978692,0.09838399054146567,37.793861074104306,193.27868357193057,0.030516676959360813
0.0314138894916596,187.397556449281,0.09973909913601924,37.779347380175054,193.28444257858575,0.030930569183236188
0.0318426657522073,187.331824132222,0.10110046376325818,37.76609574505596,193.29696879281565,0.03134619977035877
0.0322522275665059,187.228701673747,0.10240082252365622,37.745306257427394,193.26724436711012,0.031743043753645804
0.0326719537613046,187.104141684435,0.1037334531921421,37.7201949635821,193.21719955009743,0.03214957315978539
0.0330872265178762,186.988218335561,0.10505194419425692,37.696824816449094,193.17513987180376,0.03255162657058949
0.0335042918286431,186.904449916679,0.10637612655594182,37.67993710320249,193.1665511507594,0.03295525284382878
0.0339391166053902,186.87321063872,0.10775669522211388,37.67363926476595,193.21552232501116,0.03337589292653648
0.034373121039563,186.793067716385,0.10913465930061252,37.65748245162322,193.2137284423516,0.0337955630639978
0.0348077448871399,186.70698096747,0.11051459001666918,37.640127363041955,193.2058299296338,0.03421565573073925
0.0352484460664959,186.61117444736,0.11191381626112448,37.62081276858778,193.18892836527326,0.034641442419950756
0.0356728520065737,186.4837648414,0.11326130512087149,37.59512699202624,193.13617258621593,0.035051314051880125
0.0360879146060317,186.37024680283,0.11457912887415064,37.57224175545053,193.0959603545556,0.03545199989524603
0.0365101841695041,186.244923102911,0.1159198347381755,37.54697649754686,193.04475954603342,0.03585947838281637
0.0369466300323524,186.179242926354,0.11730555035271886,37.533735373952965,193.05793853445746,0.036280462187547456
0.0373717606608491,186.132515742822,0.1186553400981959,37.52431517375292,193.08861557236446,0.03669036130077564
0.037801337986882,186.089501210863,0.12001924810835034,37.51564344410998,193.12393334194513,0.03710437720378541
0.0382186198259949,186.047495888346,0.1213441179475338,37.50717517109055,193.15797440328103,0.037506378969868644
0.0386620735693576,185.995323310929,0.12275208358271038,37.496657179483286,193.1862881843326,0.03793341722152379
0.0391031553077019,185.935368406142,0.12415251810195352,37.484570270678226,193.20602799412214,0.03835799044937445
0.0395475124567159,185.845923408554,0.125563352050073,37.466538159164486,193.19566737958368,0.03878553430046391
0.0399843049904517,185.744580081869,0.12695016834468414,37.44610734450479,193.17144802218584,0.039205621684070845
0.040433870200069,185.653774792281,0.12837753788521908,37.42780099812386,193.16047542438494,0.03963780904137826
0.040896435499505,185.568316604902,0.12984618271092838,37.41057262754825,193.1573992956861,0.040082299092558504
0.0413377077672426,185.472832316907,0.13124722216099524,37.39132299508845,193.13985405798607,0.04050614410131561
0.0417756393513596,185.380681700694,0.1326376549405667,37.37274543085991,193.12507820213136,0.04092660282592068
0.0422198125679638,185.264220901125,0.13404790490328508,37.3492669336668,193.08604158312033,0.041352873644238425
0.0426703902513063,185.165067141899,0.1354784890478975,37.32927753580684,193.06613281775316,0.04178510522146793
0.0431302452992079,185.062747348482,0.13693852882498508,37.30864986545397,193.04454903736737,0.042226043868733125
0.0435989298432193,184.962626273326,0.13842660225222128,37.288465456702525,193.02679883983436,0.042675248832631255
0.0440570716498616,184.863163213847,0.13988120248831057,37.268413703911556,193.00769284097953,0.04311415429758261
0.0444990924568067,184.762163693561,0.14128461855036126,37.2480522006219,192.98391229828044,0.04353743313598888
0.0449406572707964,184.623660600056,0.14268658683477856,37.22012997697129,192.92076925516298,0.04396009650364126
0.0453857217157953,184.503810493105,0.14409966644765007,37.19596819540997,192.8776490916489,0.04438592900156927
0.0458389863486043,184.398795788773,0.14553878165681866,37.17479723101663,192.85144967163365,0.0448194210487501
0.0463023885681213,184.308405049538,0.14701008370378513,37.15657445798686,192.8423244365124,0.04526241427344423
0.0467638118426129,184.250663049931,0.14847510260029595,37.14493367086609,192.86692638867464,0.0457033208074812
0.0472204927165736,184.178966587064,0.14992506437512118,37.1304796639521,192.8759881373345,0.046139504479161056
0.0476737295061982,184.074276815603,0.15136409118217928,37.10937420602557,192.8497840975591,0.046572210619536494
0.0481174436874461,183.938501709348,0.15277288370764136,37.082001944604556,192.78915220730076,0.046995644207341356
0.0485770591214257,183.829703323526,0.1542321627105266,37.06006819002284,192.75960969014704,0.04743406329102355
0.0490410356364744,183.750425453742,0.1557052881458062,37.044085771474386,192.76173661663628,0.0478764474636001
0.0495100493822842,183.708621830132,0.15719440678875232,37.03565816095461,192.8040447688932,0.04832343563269173
0.0499778531819753,183.63864918119,0.15867968385277156,37.021551674927906,192.81651462850377,0.048769071739345624
0.0504522416659258,183.509076300438,0.16018586728931442,36.9954297821683,192.76752056583854,0.04922077779057807
0.0509260397435965,183.353039890792,0.16169017618591888,36.96397284198366,192.69048408737967,0.0496717180995086
0.0514059623713868,183.244183692878,0.1632139305291531,36.94202743248421,192.66402730456957,0.05012828027488726
0.0518873724620148,183.14015524155,0.16474240756689698,36.92105529669648,192.64281668931952,0.05058604818682037
0.0523572940887805,183.05752257053,0.16623440873187809,36.90439655021885,192.6419191149188,0.05103268981747059
0.0528241885067163,182.928658606786,0.16771679850882426,36.87841757512806,192.5917165523116,0.05147625673030068
0.0532911275039563,182.813900173953,0.16919932982506125,36.85528227506892,192.55625903761864,0.05191966930257624
0.0537665233490964,182.69674780577,0.17070871163338106,36.831664357643234,192.51971676247294,0.05237091073207808
0.0542328835758949,182.578960743744,0.1721894053534663,36.80791848593879,192.48074426516737,0.05281337787213038
0.0546947542627636,182.399283986203,0.17365584478427443,36.77169565161852,192.3755680015324,0.05325139261096364
0.0551681832861338,182.259414611373,0.17515898193347482,36.743497985652795,192.31433540227664,0.053700169659832854
0.0556399761859991,182.121600735234,0.17665692439054712,36.715714708223175,192.25484226309848,0.054147195511618486
0.0561275314974806,182.101269656985,0.1782049125045009,36.71161596284818,192.32216440538863,0.05460894645566913
0.0566100730820676,182.025690553705,0.17973698203556462,36.69637921562693,192.33017819876406,0.05506573918935426
0.0570907012041895,181.970603414373,0.18126297632330166,36.68527364833759,192.359432761849,0.05552051323897612
0.0575617474181319,181.81288041359,0.18275854805256878,36.653476691379744,192.27834751332006,0.05596602022717192
0.0580481668970985,181.696856548886,0.18430292989828773,36.63008628025541,192.2440260025139,0.05642585876758193
0.0585384011318337,181.612226381909,0.185859423593572,36.61302483859286,192.2435157402986,0.05688908975553828
0.0590420011119979,181.604230233998,0.1874583535305933,36.611412815174,192.32650739741723,0.057364726939490934
0.0595497107660656,181.500209011168,0.18907033168225826,36.590442136651475,192.30849396176353,0.05784401670631146
0.0600451072202756,181.458270683317,0.190643215424375,36.58198736975671,192.35395200250258,0.058311461199972936
0.0605397853795516,181.26215668814,0.1922138185800763,36.54245078832903,192.23572875147465,0.05877800999976404
0.0610401446851625,181.040227568226,0.19380245937539092,36.49770987775436,192.09094925282525,0.05924969556559864
0.0615257440165912,180.902618361827,0.19534423725267705,36.46996786174432,192.03278655108787,0.05970725435563261
0.0620328193046055,180.785854235444,0.19695420129212243,36.44642821386551,192.00051046406006,0.060184825642255205
0.0625312759742743,180.750316813511,0.19853680121832087,36.43926386960382,192.05286475661416,0.0606540575942797
0.0630363346923358,180.660530058921,0.20014036264816615,36.42116285987848,192.04870769740992,0.061129280047832385
0.0635429450435336,180.506989720909,0.20174885051321917,36.390209127735254,191.9769354487184,0.061605735701857796
0.0640344357507959,180.287347252735,0.20330933350877697,36.345929206151375,191.8319458070717,0.06206775482317554
0.0645265781798221,180.092149831024,0.20487188572093518,36.30657740593443,191.71288001666778,0.06253017279905218
0.0650176718808513,179.960970682834,0.20643110822170285,36.280131689659335,191.66161402605,0.06299139233907422
0.0655233504001059,179.876969045619,0.20803663752033622,36.2631969595968,191.66311071730408,0.06346608728600255
0.0660168361626106,179.872815217404,0.20960345481628864,36.262359547828645,191.74744938971887,0.06392911939248834
0.0665250996702988,179.820572499732,0.2112171914531987,36.251827415945975,191.7831540080469,0.06440579327052269
0.0670288692534033,179.758046076863,0.21281665987955548,36.23922208909558,191.8070246445963,0.06487802842351542
0.0675552134750259,179.690034829052,0.2144878027832072,36.22551102153688,191.82903349126343,0.06537118700794305
0.0680611680754419,179.593023850637,0.216094208639528,36.20595360828842,191.81633483211206,0.06584501237681824
0.0685922784345363,179.48259684464,0.21778048402965275,36.183691523879425,191.79371710156119,0.06634215464469567
0.0691139129776825,179.354101264186,0.21943667370414194,36.1577868148599,191.7499650111494,0.0668301866816474
0.0696446446077729,179.239987772187,0.22112174662967893,36.1347815348729,191.72309302008253,0.06732648547058917
0.0701812067144692,179.104610995853,0.2228253313184397,36.10748957676397,191.67438872366753,0.0678279862049692
0.0707045666748611,178.970007573418,0.22448699919268397,36.08035352680107,191.62400440669313,0.06831690530315056
0.0712366802619425,178.841607949281,0.22617645983166745,36.054468162575056,191.5816903922956,0.06881375702472677
0.0717733190866245,178.726787128955,0.22788028810003277,36.03132028519733,191.55460185088873,0.06931458421271212
0.0723073723962497,178.636352446811,0.22957590735809277,36.0130886532771,191.5530777066903,0.06981274953157468
0.0728222753690687,178.544814457666,0.2312107242967931,35.99463459466547,191.54685410182142,0.07029281653661017
0.0733442722418731,178.434952958465,0.2328680643679471,35.97248651642654,191.52213472571648,0.07077926236596942
0.0738808289053824,178.302721595246,0.23457163177458912,35.945828673601596,191.47587446278843,0.0712790298792968
0.0744195644176955,178.064143450666,0.23628211702618318,35.89773131965426,191.3155994446746,0.07178057568292885
0.0749630823121876,177.803817966616,0.2380077863411956,35.845249702069786,191.13254020826867,0.07228631895475063
0.075473727306552,177.599671410965,0.2396290841983026,35.80409375645054,191.0037805807694,0.07276124107445983
0.0759695466780595,177.488258787435,0.24120331070283887,35.7816329715469,190.97196134819453,0.07322215899526285
0.0764921453079946,177.456637590625,0.24286256135288284,35.775258138270004,191.0306764990752,0.07370774128659881
0.077039316521674,177.449116680672,0.24459982995631496,35.77374192282348,191.11967534712576,0.07421590309909375
0.0775732559350169,177.389857602163,0.24629508759367866,35.76179529259606,191.15056642621178,0.07471152763140945
0.0781070414472373,177.332771060457,0.24798985659497844,35.75028664578813,191.18370915962956,0.07520676389049513
0.0786462258447446,177.245285096865,0.24970176705706407,35.732649475527985,191.1849578185092,0.07570676026645257
0.0791971973339947,177.141191096569,0.25145110153543315,35.71166412506831,191.17027696382283,0.0762174289232284
0.07976509900988,177.019501551508,0.253254189356369,35.68713151278401,191.13947961944362,0.07674351656259579
0.0803469476360509,176.889755822291,0.25510155874446155,35.660974773773866,191.10230777069845,0.07728223735825684
0.0809103180510782,176.754622177659,0.2568902598121733,35.63373183101606,191.05589487505154,0.07780357319062754
0.0814639783064461,176.627814475172,0.25864813112296636,35.608167398194674,191.0166189218924,0.07831565869626782
0.0820128634889664,176.49719943574,0.2603908415774683,35.58183540624518,190.9722401592482,0.07882306897558583
0.0825706471235506,176.356146255455,0.2621618046172731,35.55339908509973,190.91798737598344,0.07933844169666181
0.0831317315950962,176.241058997482,0.2639432478144304,35.53019749389237,190.89228341009618,0.07985659644369689
0.0836732159183278,176.083295803076,0.26566246054069076,35.49839243390012,190.81675143241756,0.08035639623889758
0.0842496087719715,175.974717703726,0.26749250785100953,35.47650308907116,190.80051882402304,0.08088814290502493
0.0847938247394383,175.831888410145,0.2692203935477166,35.44770870348524,190.74134673959935,0.08138994565408801
0.0853745303476112,175.684295187284,0.2710641338536655,35.417953909756456,190.68325937834945,0.08192511668878814
0.0859780930434304,175.523065968104,0.2729804454128915,35.385450099169766,190.6142044651778,0.08248104915674573
0.086542823228987,175.335935120521,0.2747734637520337,35.34772452029703,190.51000195934537,0.08300093386215539
0.08711170963193,175.180971451659,0.27657967808137773,35.31648384465446,190.44128536979534,0.08352437160935172
0.0876715049111361,175.035245087537,0.27835702809285706,35.28710540964746,190.3808484368509,0.0840391772118834
0.0882538830721335,174.931643625933,0.28020607875402387,35.266219354988095,190.3700404481122,0.08457446962413233
0.0888421624500665,174.846464808061,0.2820738657789611,35.2490473053051,190.3802028383586,0.08511489538390599
0.0894072283460681,174.755432305355,0.2838679499987662,35.230695152759566,190.3798311461957,0.08563372110796169
0.0899556909225518,174.517546507842,0.28560931867910194,35.18273737598095,190.21639298206352,0.0861370448850282
0.0905097403730325,174.317310966441,0.28736842568437815,35.14236989083451,190.09472552453877,0.0866452386444456
0.0910792649771834,174.154594138388,0.2891766663025573,35.109566178299026,190.0164665649121,0.08716735771975465
0.0916553222597732,174.108015703034,0.2910056481747799,35.10017596573166,190.06594199030522,0.0876951885420016
0.0922477371913336,174.090908153332,0.29288656558248416,35.096727083711734,190.15040049606117,0.08823771715244283
0.0928302575870556,174.012273937551,0.2947360678389015,35.08087442581028,190.16587815048314,0.08877089757979065
0.0934238844925869,173.904050987781,0.2966208332639634,35.05905667913665,190.15084296005642,0.0893139514807021
0.0940191133011021,173.771801497714,0.2985106847309992,35.032395181939144,190.1096721912642,0.08985817487194632
0.0946073308914463,173.626097216255,0.30037827558034197,35.00302119879701,190.05239884698366,0.09039569702979819
0.0951842815848821,173.475658952147,0.30221009403200066,34.972692844752835,189.9878149219711,0.09092264279349437
0.0957792334691945,173.322414839546,0.3040990662646925,34.94179883165248,189.92310287590746,0.09146573891978597
0.0963790171562241,173.174324311952,0.3060033794710115,34.91194378128952,189.86469548583116,0.09201294731756024
0.0969821154150807,173.001819304111,0.3079182164428812,34.87716677170878,189.77990171088123,0.09256287798342261
0.0975999231658053,172.830019575199,0.3098797560514318,34.84253194636012,189.69821620648307,0.09312590798748177
0.0981968686137943,172.631558431319,0.3117750578487969,34.802522179753915,189.5834368931938,0.09366962447794207
0.0987957151772976,172.465565743576,0.3136763956879199,34.76905805390492,189.50442465466983,0.09421477568396092
0.0993800964589358,172.345465435295,0.31553180625712113,34.74484583175548,189.4731744145148,0.09474647227739245
0.0999267715321282,171.89097366277,0.317267499614507,34.65322029041443,189.06748371640467,0.09524360625392626
0.100461051960738,171.477627021575,0.3189638399753431,34.56988960754952,188.70444981989348,0.09572923013659418
0.101000318680918,171.268957634833,0.32067601181191463,34.52782185918233,188.56717693609977,0.0962191471872931
0.101561574793669,171.183251740352,0.32245799996989905,34.51054355085496,188.56889236540323,0.09672878655457867
0.102151147244582,171.57303821437,0.32432989250154787,34.58912450401699,189.0994209042064,0.09726385853477224
0.102750675362151,171.659821726885,0.3262333942748294,34.60662006014002,189.2979843418689,0.09780767243723007
0.103366339529603,171.554142254982,0.3281881280064895,34.585315078604374,189.28706597102027,0.09836581525493095
0.103981376968935,171.389885502799,0.3301408718763686,34.552200917364274,189.21124179592815,0.09892307902506683
0.104596311314264,171.191083078523,0.3320932884227882,34.512122348630236,189.09703889843024,0.09947993909341026
0.105207186143223,171.040331367704,0.334032816004733,34.48173080372913,189.0350033479046,0.10003281616616588
0.105815709674272,170.851744732524,0.33596487821581356,34.443711738076836,188.9305433504836,0.10058326143524449
0.106421357385424,170.658214218195,0.3378878096987212,34.40469598638811,188.8198930242678,0.10113080467579624
0.1070461587223,170.465724607489,0.3398715539433025,34.36589008086978,188.71342562053414,0.1016953499866476
0.107681618463106,170.297467350668,0.3418891386203615,34.33196941789467,188.63537425515588,0.10226919907527178
0.108284418467989,170.174624391615,0.34380302863586504,34.307204277349584,188.60188463186947,0.10281325075269415
0.108899026498219,170.012881329536,0.3457544091318453,34.27459687603446,188.5271185984797,0.10336765507802664
0.109525614928332,169.872379485015,0.3477438273974541,34.24627170417902,188.47775630745022,0.10393255003553334
0.110140266127892,169.682427537605,0.3496953449560571,34.207977391581174,188.37129526382358,0.10448637322173124
0.110788116139679,169.497119446985,0.3517522687434808,34.17061928051218,188.27538600161864,0.10506977792341801
0.111398022218293,169.341528185683,0.35368872054308026,34.139252082233696,188.20583950499142,0.10561870232124485
0.112048626717223,169.199837801439,0.355754389827183,34.1106873007701,188.1584472678671,0.1062039239345539
0.112676498998247,169.074646422739,0.3577478843194342,34.08544871882418,188.1253856510197,0.10676837325949444
0.113322579272,168.915791915872,0.3597991891886,34.0534236502398,188.05776513555108,0.10734885893732078
0.113970769153014,168.743918456286,0.36185719206081945,34.01877396078726,187.9757926326424,0.10793090162134486
0.114609210750461,168.527966239287,0.36388424413271364,33.97523799384026,187.84282343935203,0.10850385984646571
0.115250128277169,168.327488694149,0.36591915728001156,33.93482172074044,187.72725335872337,0.10907871004722933
0.115877670505021,168.106751895019,0.3679116038534416,33.89032118203583,187.58657070077933,0.10964124370822637
0.116497642569659,167.934639068906,0.3698800151586673,33.85562323629145,187.49862862622012,0.11019668084905654
0.117111441926429,167.734098786766,0.37182882811641205,33.81519431541203,187.37768095591426,0.11074628406877919
0.11771630860145,167.54962264059,0.37374927980960376,33.77800392434294,187.2729457254062,0.11128759351837582
0.118342271964815,167.362055636596,0.37573671348828763,33.740190416337754,187.16806154133258,0.11184747453862887
0.118967301340321,167.190639764725,0.37772118175551916,33.705632976568566,187.0808589868961,0.11240620758051438
0.119561047548538,167.013120451519,0.3796063259666081,33.66984508302623,186.98138408705276,0.11293668665390698
0.120204986707391,166.835788983923,0.3816508327959664,33.63409505915888,186.89028278105258,0.11351169240606736
0.120847519582507,166.612075711989,0.3836908746744597,33.588994463536984,186.74673179427572,0.11408511305633634
0.121536272546723,166.357175953956,0.3858776653358455,33.53760667231753,186.57560703079915,0.11469941734117213
0.122159360788865,166.106958196938,0.3878559705046463,33.4871627725027,186.39847803285863,0.1152548298034527
0.122762983537018,165.798925154471,0.3897724727300321,33.42506331114135,186.15289587366462,0.11579259696874092
0.123365716281177,165.581800141573,0.3916861491927369,33.38129090854112,186.00891751916487,0.11632928283066402
0.123964526666817,165.39986307262,0.39358737216714396,33.344612395440194,185.9035788091737,0.11686219106850798
0.124590805810105,165.257505696653,0.39557580844708334,33.31591314844524,185.84707149756701,0.117419241322453
0.125226567935678,165.091448413151,0.3975943531957776,33.282436000091245,185.76528389345995,0.11798440909999326
0.125853482779914,164.879388924687,0.39958480782622696,33.2396848072169,185.63003425948284,0.11854139938582907
0.126479161770247,164.649954495664,0.40157133862053424,33.193430826325866,185.4747427257849,0.11909698251245206
0.127124715756556,164.395921982562,0.4036209725270653,33.1422178716845,185.29470683613215,0.11966989065341133
0.127780933953515,164.153859511605,0.4057044653024101,33.09341807753957,185.12959299207196,0.12025192672713235
0.128422337182433,163.86103754709,0.4077409205542248,33.03438516949335,184.90445496202574,0.12082049539681085
0.129041169209805,163.540640406106,0.40970571224113084,32.96979310587097,184.64411585743022,0.12136874970180446
0.129656951537131,163.244931300306,0.4116608211303909,32.91017815014169,184.41077144659207,0.12191400392318624
0.130273520315437,162.924065863899,0.41361842700151247,32.845491678162034,184.14875746809324,0.12245965681055006
0.130903739046585,162.685219216387,0.41561937147290734,32.79734019402362,183.9813226994254,0.12301708214715938
0.131519200395464,162.411074799431,0.4175734612555982,32.74207267956529,183.77124949242005,0.12356115492270581
0.132144303662428,162.163387127702,0.41955816412820884,32.69213884494472,183.59235499923292,0.1241134483901164
0.132771754180806,161.886839322746,0.421550319524059,32.63638680746559,183.38083895841328,0.12466750913091663
0.13338729431309,161.61988840453,0.4235046594440607,32.58256950235325,183.17792802599382,0.12521075444975785
0.134003141719979,161.337177153767,0.42545997496093335,32.525574914199424,182.9568657686046,0.1257539757778945
0.134643499486167,161.047188569583,0.42749311086858016,32.46711321562793,182.73114562100028,0.12631850422543972
0.13527839710206,160.681849048446,0.42950891079904047,32.39346076816672,182.41863203111492,0.12687790464657644
0.135888954503219,160.384800271723,0.4314474305477203,32.33357573477936,182.17932309885504,0.12741556420339922
0.136491806260998,160.061367574898,0.4333614848786686,32.26837170309943,181.90843274780133,0.12794615465930453
0.137083141104621,159.75402910365,0.4352389730071716,32.20641226729584,181.65361321729736,0.12846633531808796
0.137709725850675,159.42309217802,0.4372283795758931,32.139695383088835,181.377202496122,0.12901722922232217
0.138344846262554,159.098465905353,0.4392448868836089,32.07425072651917,181.10891871163727,0.1295753181505451
0.138974871588644,158.774817799306,0.44124521729394467,32.00900326834009,180.84052771447492,0.13012862240310547
0.139569904013029,158.408117191831,0.443134445241367,31.93507642587313,180.51712290317948,0.1306509140379093
0.14017933528211,157.99572669814,0.4450693895206992,31.851938502345025,180.14346264409917,0.13118556168519743
0.140779651946523,157.596362242684,0.4469753949302105,31.771426628125095,179.7827232672472,0.13171193386605207
0.141414088750715,157.22713691966,0.44898973178352014,31.69699080300346,179.46126921403763,0.1322679224389954
0.142045689806897,156.878983572036,0.45099506513689797,31.626803088122458,179.1629670097307,0.13282111902097168
0.142669902891282,156.444017400736,0.45297694167982033,31.539113907988376,178.76387017122101,0.1333675442319795
0.143294177636282,155.982714254851,0.4549590139951953,31.446115193777963,178.33412901947503,0.13391372495794707
0.143869447533643,155.535245960453,0.4567854959193165,31.35590558562733,177.91201586879268,0.13441676715673112
0.144490829837654,155.126504904729,0.4587583847345514,31.273503388793365,177.54086232822817,0.13495984800412028
0.145120138855114,154.655507962579,0.4607564408649869,31.17855040525593,177.09913675281666,0.1355095562662766
0.14573848659059,154.116712671724,0.4627196949251232,31.069929274619557,176.57744913481787,0.13604939555939105
0.146406627640083,153.564578706153,0.4648410427572635,30.958619067160445,176.04745079949095,0.1366323787782705
0.14702510177138,153.046145536369,0.4668046981241315,30.854102940131995,175.54777065957109,0.13717172262562194
0.147633928042286,152.569979408367,0.468737721534258,30.75810784872679,175.09448476975493,0.13770236903302469
0.148240649143411,152.054449918036,0.4706640610303299,30.65417710347606,174.59510027902994,0.13823090061857182
0.148867627360825,151.466490788675,0.4726547168706194,30.53564454299688,174.0149478970553,0.13877678540719623
0.149484143500513,150.877552698354,0.4746121556141288,30.41691462398817,173.43135443692097,0.13931327086803058
0.150129489345911,150.312865072879,0.4766611286732674,30.303073598692404,172.87925874839115,0.1398745354675456
0.150771193347691,149.717744615564,0.47869853887891894,30.1830973144977,172.2908676365774,0.14043232053253685
0.151411404582458,149.069835792289,0.4807312095493041,30.052478895725468,171.64070901047586,0.14098849818051823
0.152040456072811,148.280120928812,0.4827284480311749,29.8932723792485,170.82469814136016,0.14153467977583237
0.152656263820064,147.512047328592,0.4846836376287032,29.738428741444146,170.03068534222328,0.1420690735262921
0.15327525968648,146.802613904523,0.486648949504574,29.59540696315184,169.30382267339283,0.14260594626078044
0.153906621420934,146.095660283999,0.4886535230114654,29.452885113254197,168.5807497625698,0.14315324749904323
0.154564239021137,145.426245839029,0.49074145889210996,29.31793116114825,167.90394286083932,0.1437229905521274
0.155210192813134,144.654225320373,0.4927923621817004,29.162291824587196,167.10603552358262,0.14428231253607027
0.155853599792995,143.896304994662,0.4948351793427591,29.00949508692386,166.3230621249908,0.14483911845249944
0.156472096499518,142.934193217182,0.4967989063859696,28.815533352583895,165.2994060913417,0.14537407485787499
0.157099010687017,142.027433142039,0.49878935893127896,28.632730521435064,164.33980237906977,0.14591601990628558
0.157740662031221,141.12520867098,0.5008266019491266,28.450842068069566,163.38639251603456,0.14647040072859474
0.158363200875959,140.266337041444,0.5028031627811699,28.27769354755511,162.47936315047315,0.14700797494510567
0.159021109689719,139.486582237124,0.5048920232648578,28.1204949790042,161.6678933312977,0.14757577790159945
0.159656491285439,138.498184370502,0.5069093598312687,27.921233969093205,160.6103185365002,0.14812383306145152
0.160322291952983,137.53049467139,0.509023276950721,27.72614772575222,159.57969879053474,0.1486978044189768
0.160972063532265,136.554210050595,0.5110863017149414,27.529328746199955,158.5356230264576,0.14925764000787334
0.161632255109326,135.548948226689,0.51318240997211,27.3266679625005,157.45803040626603,0.14982613253115218
0.162297471665556,134.527994764792,0.5152944725381403,27.120843744582068,156.3615481833549,0.150398625379567
0.162946704587326,133.410305738174,0.51735578706476,26.89551763681588,155.1490754161971,0.15095704668023857
0.163637713400241,132.325990413865,0.5195497400457652,26.676919667435183,153.97951290861204,0.15155105807986022
0.164298398208181,131.230636919875,0.5216474143109747,26.4560964030468,152.79162036164982,0.1521186723046528
0.164973278756481,130.03761255715,0.5237901600518271,26.21558269152144,151.49034386236798,0.15269815006489815
0.165637225767244,128.839446889921,0.5258981918109996,25.97403249300807,150.18005544215367,0.15326791238892068
0.166275473813283,127.595900001258,0.5279246293571735,25.723333440253615,148.81196873059946,0.1538153154388645
0.166921051972477,126.368063973623,0.5299743400126145,25.4758016970824,147.46155414782544,0.15436870060683835
0.167563416170851,125.136001165553,0.5320138463424519,25.227417834975487,146.10421700681266,0.15491902700510904
0.168221291859729,123.824054469543,0.5341026016546395,24.962929381059872,144.65389687571897,0.1554823286690098
0.168926892454403,122.471007840171,0.5363428835427295,24.690155180578472,143.1596546103699,0.15608614200087087
0.169618658885542,121.0803364689,0.5385392419615959,24.40979583213024,141.61782075816498,0.15667776310563836
0.169956999346981,120.373956568651,0.5396134729266646,24.267389644240044,140.83235302658272,0.15696699543937984