File: example/data/02 processed data/test_ID_064.csv
Strain,Stress_MPa,Displacement(mm),Force(kN),True Stress (MPa),True Strain
3.33591405803446e-05,0.597086982510476,0.00010591527134259408,0.12037273567411197,0.5971069008190643,3.335858417657967e-05
4.0383731219268e-05,0.596464121383339,0.0001282183466211759,0.12024716687088116,0.5964882088300989,4.038291581836347e-05
5.29199194749591e-05,0.612221828201362,0.00016802074433299515,0.12342392056539458,0.6122542269312112,5.291851926544124e-05
5.28346458114158e-05,0.64506724353386,0.00016775000045124517,0.1300455562964262,0.6451013254331968,5.283325011077865e-05
5.83848368697475e-05,0.734863900358963,0.0001853718570614483,0.14814856231236695,0.734906805267907,5.838313254156757e-05
3.22928592793798e-05,0.943845091826614,0.00010252982821203086,0.19027917051224538,0.9438755712833459,3.2292337876148516e-05
4.182481635692e-05,1.38930151871499,0.00013279379193322101,0.280083186172942,1.3893596259958747,4.182394172370598e-05
6.10314077430944e-05,2.34073191914581,0.0001937747195843247,0.47189155489979534,2.3408747773099847,6.102954540256997e-05
9.69551156537664e-05,4.0718168447158,0.0003078324922007083,0.8208782758947052,4.0722116281889,9.695041581032841e-05
0.0001326100332028,6.81095533061962,0.00042103685541889003,1.3730885946529157,6.811858531632157,0.00013260124126966642
0.0001769825662918,10.5850679489926,0.0005619196479764649,2.133949698516908,10.586941321482588,0.00017696690672507295
0.000230396256959,14.8915452181599,0.000731508115844825,3.002135515981036,14.894976174438499,0.00023036971981732582
0.00028731765871,19.5394766691745,0.0009122335664042499,3.9391584965055797,19.545090705863505,0.0002872763908958844
0.0003637467407613,24.3414170410342,0.0011548959019171273,4.907229675472495,24.35027115214839,0.0003636806009539056
0.0004298043727762,29.4357955001479,0.0013646288835644348,5.934256372829817,29.44844713377001,0.0004297120333343979
0.0005155949168774,34.8762937157234,0.0016370138610857451,7.031060813089838,34.894275755482745,0.0005154620434888057
0.0006044861415811,40.5231975417432,0.0019192434995199926,8.169476624415429,40.54769325306974,0.0006043035134271107
0.0006789853849803,46.2759959221109,0.0021557785973124527,9.329240777897558,46.30741664701742,0.0006787549786928289
0.0007700775378657,51.9812573938816,0.002444996182723597,10.47942149060653,52.02128699259064,0.0007697811802942381
0.000864316412907,57.6446031274631,0.002744204610979725,11.62115199049656,57.69442630406167,0.000863943106563866
0.0009565665968535,63.4062707161491,0.0030370989450098623,12.78270417637566,63.46692303674721,0.0009561093785762079
0.0010688641890943,69.1055074703282,0.003393643800374402,13.931670306018166,69.17937187253243,0.0010682933604896155
0.001174013259389,74.9573401346784,0.0037274920985600753,15.111399771151167,75.04534104588504,0.0011733246447314476
0.0012733481314407,80.7862825851129,0.004042880317324222,16.28651456915876,80.8891516470887,0.0012725381112609275
0.0013727120215226,86.6391629856978,0.004358360668334255,17.466455257916675,86.75809360626292,0.0013717707137067773
0.001456909114149,92.6615061426464,0.004625686437423075,18.680559638357515,92.7965055354764,0.0014558488517445723
0.0015564594401851,98.5357929974782,0.004941758722587692,19.864815868291604,98.68915996268525,0.0015552494126005022
0.0016561470183223,104.440226006895,0.005258266783173302,21.05514956299003,104.61319437578923,0.0016547771191435365
0.0017638036423568,110.246959021844,0.00560007656448284,22.225786938803754,110.4414130097255,0.0017622499673625816
0.0018688673899106,116.119652031253,0.005933653962966155,23.409721849500606,116.33666426226196,0.0018671232299809913
0.0019802517048201,122.049653663834,0.006287299162803817,24.605210178628933,122.29134269857451,0.00197829359102562
0.0020805121259938,127.817953013955,0.006605626000030315,25.76809932761333,128.08387981512024,0.00207835085781777
0.0021881724608841,133.711361011399,0.006947447563307017,26.95621037989804,134.00394452927148,0.0021857818981986057
0.0022873077369233,139.563701607476,0.007262202064731477,28.136042244067163,139.88292674195642,0.002284695830645565
0.0023944721669507,145.318636146941,0.007602449130068472,29.296237047223308,145.6665975765341,0.002391609986501932
0.0025093948115776,151.023288065701,0.00796732852675888,30.44629487404532,151.40226512120046,0.002506251537795789
0.0026105107762614,156.610011716928,0.008288371714629945,31.572578362132685,157.01884384018547,0.002607109311426095
0.0027169879831463,162.295102388275,0.008626436846489503,32.71869264147624,162.73605623118746,0.0027133036433252705
0.0028136016932174,167.849094696005,0.008933185375965245,33.83837749071461,168.3213551930467,0.002809650924830868
0.0029108911644165,173.246369547752,0.009242079447022386,34.9264681008268,173.75067087413578,0.002906662724429241
0.0030110390935344,178.486834834835,0.009560049121971718,35.98294590270274,179.02426567220394,0.0030065149945406574
0.0031072015734061,183.541507417681,0.009865364995564367,37.00196789540449,184.11180787831455,0.0031023841990530845
0.0032083706731443,188.492526339197,0.010186576887233153,38.00009330998212,189.09728023281056,0.0032032348341409474
0.0033050868808522,193.34092499525,0.010493650846705734,38.9775304790424,193.97993354998363,0.0032996370859361634
0.0034169005603484,198.248020384042,0.01084865927910617,39.96680090942287,198.9254141559802,0.0034110762193205416
0.0035251453886902,203.161268267398,0.011192336609091386,40.957311682707434,203.87744127539125,0.0035189466271036366
0.0036388026556067,208.044038881346,0.011553198431551271,41.941678238479355,208.8010700825106,0.0036321982298426173
0.0037554685133879,212.725969329506,0.011923612530006582,42.88555541682841,213.52485500930285,0.0037484343470699064
0.0038658291256023,217.200940991075,0.012274007473787303,43.78770970380072,218.04060271486654,0.0038583760103263554
0.003981790451655,221.32620670825,0.012642184684004623,44.6193632723832,222.20748128482194,0.00397388410471648
0.0040999806089426,225.16841290749,0.013017438433392753,45.393952042149984,226.09159903415707,0.004091598591374647
0.0042240713093912,228.658583305038,0.013411426407317061,46.097570394295666,229.62445346642286,0.004215174963910849
0.0043611011305984,231.984474092215,0.01384649608964992,46.768069976990546,232.99618184445984,0.004351619087167263
0.0045180645269308,235.086473230094,0.014344854873005288,47.39343300318695,236.14860908555613,0.0045078887118764795
0.004695440318863,237.864177858516,0.014908023012390024,47.95341825627683,238.98105490964608,0.004684451124945412
0.0048897158756235,240.509948967569,0.015524847905104612,48.486805711861905,241.68597428328113,0.004877800042523678
0.0051151649158072,242.870116771038,0.016240648607687858,48.96261554104126,244.1124374714432,0.005102126901909496
0.0053721393541826,244.959652216748,0.017056542449529755,49.383865886896395,246.27560960460846,0.005357760885997824
0.0056589955851196,246.65591402658,0.01796731098275473,49.725832267758534,248.05173875510008,0.0056430436226981885
0.0059726442549196,247.914778998425,0.01896314550936973,49.97961944608248,249.39548577891958,0.005954878718279059
0.0062943882416241,248.870648671972,0.019984682667156514,50.17232277226955,250.43713715665825,0.00627466131596675
0.0066325217557104,249.645253084639,0.02105825657438052,50.32848302186322,251.30103065693268,0.006610623357695398
0.0069855278471409,250.314451388935,0.022179050914672357,50.4633934000093,252.06302995965422,0.006961242081158369
0.007345079070266,250.934654545422,0.023320626048094546,50.588426356357076,252.77778942452804,0.007318235343047921
0.0077126578835064,251.463987947201,0.02448768878013282,50.69513997015572,253.40344365625995,0.0076830673878837885
0.0080781418973795,251.860778419526,0.025648100524179908,50.77513292937644,253.89534552598337,0.008045688368114048
0.0084520737818296,252.182390390725,0.02683533425730898,50.839969902770164,254.3138545607856,0.00841655500410961
0.0088173818435792,252.433996112555,0.02799518735336396,50.890693616291095,254.65980304658,0.008778735737798088
0.0091847903044891,252.688319818604,0.029161709216752894,50.94196527543057,255.00920904853152,0.009142866629271091
0.0095510927011579,253.06751983577,0.03032471932617633,51.01841199889123,255.48459117737357,0.009505769378236594
0.0099296160504534,253.417974242593,0.03152653096018954,51.089063607306755,255.93431742710564,0.009880641346151782
0.010296697153889,253.742625657303,0.03269201346359757,51.15451333251229,256.3553366287288,0.010244047272583
0.0106662687998684,253.974420501317,0.03386540343958217,51.201243173065514,256.6833799386749,0.010609785444261688
0.0110275288315232,254.071307731969,0.035012404040086154,51.220775638764955,256.8730864032461,0.010967168976746242
0.0113944933782183,254.25988249948,0.0361775164758431,51.25879231189517,257.1570450469669,0.011330065095056461
0.0117658298500351,254.510405960201,0.03735650977386144,51.30929784157653,257.5049320917921,0.011697150660864795
0.0121272662951265,254.802779952519,0.038504070487026636,51.36824043842783,257.8928411177417,0.012054320167121843
0.0124787848998855,255.110225846949,0.03962014205713646,51.43022153074492,258.2936914810543,0.012401566593737848
0.0128444443717627,255.353973920217,0.04078111088034657,51.479361142315746,258.6338538333438,0.012762654118499804
0.0131840904313519,255.633518158024,0.04185948711954228,51.53571726065764,259.003813578704,0.013097936723790251
0.0135346684542257,255.928467270821,0.042972572342166594,51.59517900179752,259.3923742233297,0.013443892989141275
0.0138866372687055,256.108855355333,0.04409007332813996,51.63154523963514,259.66534613095587,0.01379110135379853
0.0142483984833114,256.446613581112,0.04523866518451369,51.69963729795218,260.10056712111145,0.014147844087458346
0.0146133376200147,256.626081182295,0.04639734694354667,51.73581796635068,260.3762447487132,0.014507591756946984
0.014974793694168,256.835626745878,0.047544969978983394,51.77806235196901,260.68168726970987,0.014863778386537492
0.0153208031957868,257.131469249348,0.04864355014662309,51.83770420066856,261.07092988516075,0.015204624818454745
0.0156774653416712,257.309250721739,0.04977595245980606,51.87354494550258,261.3432075820204,0.015555843384295795
0.016032847742447,257.563070402739,0.050904291582269216,51.92471499319218,261.69253989458326,0.015905679088836572
0.0163954442958404,257.836778618701,0.052055535639293264,51.97989456953012,262.0641271599628,0.01626249025768414
0.0167473756319818,258.051952451413,0.05317291763154221,52.02327361420487,262.37364543168314,0.01660868466784243
0.0170943025641937,258.364492178177,0.054274410641314996,52.086281623120485,262.781052979315,0.01694983898609233
0.017447599776597,258.649857938651,0.05539612929069547,52.14381136043204,263.16267714223824,0.017297138017435015
0.0178060210750956,258.837615225747,0.05653411691342853,52.1816632295106,263.44648325748415,0.01764935092941001
0.0181622514670825,259.113780726602,0.05766514840798693,52.237338194482966,263.81987037074504,0.017999288008908064
0.0185187148716948,259.280856454763,0.05879691971763098,52.271020661280225,264.0824047071376,0.018349331451296448
0.0188627881491968,259.511640088397,0.059889352373699835,52.317546641820826,264.406753177635,0.01868709173847177
0.0192090891783839,259.630377641849,0.06098885814136888,52.34148413259676,264.61764071938876,0.019026923749670428
0.0195487757458516,259.778741094652,0.06206736299307883,52.37139420468184,264.857097447851,0.0193601526989785
0.019893468265985,260.029611884501,0.06316176174450237,52.4219697559154,265.2025027167417,0.019698178965157437
0.0202321235076988,260.255721129673,0.06423699213694369,52.467553379742085,265.52124702315376,0.02003017347195626
0.0205761963872638,260.478661915657,0.06532942352956256,52.512498242196465,265.83832201792524,0.020367366220016715
0.0209226258753754,260.644712394806,0.0664293371543169,52.54597401879289,266.09808419863737,0.02070675362270255
0.0212654008449871,260.801578812758,0.06751764768283404,52.57759828865202,266.3476289272168,0.021042447465135942
0.0216087914032373,261.010947305344,0.06860791270527843,52.61980697675735,266.6510784196266,0.02137863122308573
0.0219609465922542,261.2514398132,0.06972600543040708,52.66829026634113,266.9887687300872,0.02172327832365211
0.022303481799351,261.557764554425,0.07081355471293942,52.730045334172075,267.39141339564355,0.02205839662395156
0.0226602811344758,261.840393464282,0.07194639260196066,52.78702332239925,267.7737703925444,0.02240735081591581
0.0230003849475414,262.079115738593,0.07302622220844394,52.83514973290035,268.10703628729186,0.022739863262225383
0.023344668195913,262.247348510582,0.07411932152202377,52.86906545973334,268.3694258468195,0.02307634928259746
0.0236826856720866,262.384802563686,0.07519252700887495,52.89677619683909,268.59877936793424,0.023406601322080035
0.0240224074025107,262.482090975282,0.07627114350297147,52.916389540616855,268.7875427005531,0.023738408606917824
0.0243665908084323,262.683301767341,0.07736392581677255,52.95695363629595,269.0839982937137,0.024074461387382264
0.0247084981165855,262.910745587882,0.07844948152015896,53.00280631051701,269.40687525007024,0.024408180061894776
0.0250577648998918,263.214461970098,0.07955840355715646,53.064035533171754,269.81002807639624,0.024748967002326195
0.0254071394462793,263.463447994023,0.08066766774193677,53.11423111559504,270.1573005562047,0.025089742939556917
0.0257523878621804,263.628729206885,0.08176383146242278,53.14755180810802,270.4177984930344,0.02542638025573336
0.026094835781997,263.730312884441,0.08285110360784047,53.1680310775033,270.61231208989517,0.025760175013013614
0.0264263582403569,263.877013537358,0.08390368741313316,53.19760592913137,270.85032202849175,0.026083214270497024
0.0267598745186041,264.063880911678,0.08496260159656802,53.23527839179428,271.13019722977015,0.026408091065265354
0.0270923861660826,264.297314321466,0.08601832607731225,53.282338567207546,271.45775922372167,0.02673188421898775
0.027431934078648,264.472653897467,0.0870963906997074,53.31768702572935,271.7276503047874,0.027062420988312914
0.0277679723631622,264.610617819757,0.08816331225303999,53.34550055246302,271.95831814237533,0.02738943373919486
0.0281075519930445,264.794521517894,0.08924147757791628,53.38257553800743,272.23724729893155,0.027719784121742218
0.0284470147291745,265.051202666203,0.09031927176512904,53.434322457506525,272.59111813243385,0.02804991174850779
0.0287859591710722,265.253203385478,0.09139542036815423,53.47504580251237,272.8887712681285,0.028379426635022603
0.0291304186372101,265.432749739582,0.09248907917314206,53.51124234749973,273.16491685952184,0.028714191908353757
0.0294780016756998,265.632390491549,0.09359265532034686,53.55148992309628,273.46270254357904,0.02905187928820013
0.0298194938388959,265.77401301825,0.09467689293849448,53.5800410244792,273.6992595619863,0.02938353818359549
0.0301603718033454,266.008092046361,0.09575918047562164,53.62723135654638,274.0309950051778,0.02971449090138302
0.0305001116100278,266.142328171564,0.09683785436183825,53.6542933593873,274.25969888494933,0.030044229655045097
0.0308438222806771,266.392588931978,0.09792913574114978,53.70474592868677,274.6091546018854,0.030377711776280254
0.0311863906482794,266.61435310898,0.09901679030828708,53.74945358677038,274.92909247747497,0.030709974968745685
0.0315283378242268,266.769058371446,0.1001024725919201,53.78064216768352,275.17984336483187,0.031041525594103368
0.031865386203284,267.014149976858,0.1011726011954267,53.83005263533457,275.5226589876122,0.03136821882587019
0.0322030642339459,267.093786315765,0.10224472894277822,53.84610732125822,275.6950246729794,0.03169541537170462
0.0325449435604788,267.256832622673,0.10333019580452019,53.87897745673088,275.9546911565302,0.0320265737778313
0.032888662466257,267.399041087626,0.10442150333036596,53.907646683265405,276.19343789375773,0.03235940356035083
0.0332329724762413,267.595261066145,0.10551468761206613,53.947204630934834,276.48824701192876,0.03269269469611794
0.0335757944522511,267.865256317694,0.10660314738589723,54.00163567364711,276.8590451047164,0.03302443509188107
0.0339068793972048,268.107581581831,0.10765434208612523,54.050488446897134,277.1982730160024,0.03334471342066391
0.0342439159735242,268.23867036932,0.10872443321593932,54.07691594645491,277.42421285829687,0.0336706437929147
0.0345773870100939,268.327347588067,0.10978320375704813,54.09479327375431,277.6054061310116,0.033993021601937456
0.0349219136900404,268.475937405892,0.11087707596587826,54.124748981027835,277.85163091983327,0.034325978161055856
0.0352528788731059,268.637017065436,0.11192789042211124,54.1572226403919,278.1072452888763,0.03464572428787966
0.0355945966834231,268.755272938134,0.11301284446986834,54.18106302432781,278.32150848491017,0.034975751310586264
0.0359323727335027,268.912405566052,0.11408528342887107,54.21274096211608,278.57506635551425,0.03530186442237297
0.036264750162891,269.02243143291,0.11514058176717891,54.23492217687466,278.778462697038,0.035622661540143354
0.036620133708604,269.22272884036,0.1162689245248177,54.275302134216574,279.0817011678892,0.03596554941776757
0.036968809845675,269.475983688701,0.11737597126001811,54.32635831164212,279.4381900876648,0.03630185150062841
0.0373261186339008,269.715643121189,0.11851042666263503,54.374673653231696,279.78308121374937,0.036646362579409036
0.0376832921817397,269.880203091325,0.11964445267702355,54.407848943211114,280.0501776384826,0.03699062468203332
0.0380319558166196,269.982828549813,0.12075145971776721,54.4285382356423,280.2508035564655,0.03732657022031978
0.0383798000858887,270.057708126512,0.12185586527269661,54.443633958304815,280.42246897606077,0.037661613856567897
0.038719485650539,270.186559816496,0.12293436694046132,54.4696104590056,280.64804444227934,0.03798869072767501
0.0390614360133135,270.355597618348,0.12402005934227035,54.50368847985896,280.91607549555823,0.03831784031442528
0.0393995864722318,270.505717790128,0.12509368704933596,54.533952706489806,281.1635312094333,0.03864322573974108
0.0397420338713738,270.624951650557,0.12618095754161182,54.5579902527523,281.38013764549237,0.0389726380307442
0.0400857702296447,270.759600787905,0.1272723204791219,54.58513551884165,281.6132079325593,0.039303181127362766
0.0404266804691827,270.964094698577,0.12835471048965505,54.626361491233126,281.9182735735777,0.039630898697593675
0.0407607546577803,271.17566566851,0.12941539603845245,54.66901419877162,282.22899044598444,0.03995194060456324
0.0410912032652039,271.404477906419,0.1304645703670224,54.715142745934074,282.5568144751582,0.04026939700096181
0.0414122164895321,271.624199811655,0.13148378735426441,54.75943868202965,282.8727599780512,0.04057769251090003
0.0417438427435074,271.789314069594,0.13253670071063597,54.79272571643015,283.13484445548085,0.040896080809565215
0.0420794626166071,271.966108105175,0.13360229380772753,54.82836739400328,283.41029578417084,0.04121820013238729
0.0424378810798187,272.09101860767,0.13474027242842435,54.85354935130626,283.63798489822904,0.04156208642129511
0.0427872828158655,272.179590600191,0.13584962294037298,54.871405464998496,283.8254157199078,0.04189720777448657
0.0431346033081961,272.264071617452,0.1369523655035226,54.88843683807831,284.00807434174504,0.04223022167865121
0.0434752659812129,272.396757696498,0.13803396949035096,54.915186351614004,284.2392791897733,0.042556744313339626
0.0438272918407516,272.529948769323,0.1391516515943863,54.94203767189553,284.4741983693812,0.04289404650420509
0.0441701792169711,272.692263765074,0.14024031901388323,54.974760375038926,284.7371299266589,0.043222483089071305
0.0445186173958463,272.864417270073,0.141346610231812,55.00946652164671,285.0119638634599,0.04355612607377303
0.0448595900491621,273.010739737455,0.14242919840608967,55.03896513107094,285.25788960109577,0.04388251279986011
0.0452003967751536,273.173487262863,0.14351125976111268,55.07177503219317,285.5210372755967,0.044208634280736576
0.0455510956860455,273.287989548043,0.14462472880319444,55.094858692885474,285.7365569097929,0.044544110701961716
0.0459044386403089,273.386732085722,0.14574659268298076,55.114765188481556,285.93639655382555,0.04488200261677986
0.0462565628709401,273.528088418338,0.1468645871152348,55.14326262513694,286.1805576372289,0.045218615557850624
0.0466032602652398,273.68516087388,0.14796535134213637,55.17492843217421,286.4397816568195,0.045549930052627884
0.0469535520718279,273.844403965749,0.14907752782805359,55.207031839494995,286.70237144693345,0.04588456803120361
0.0472975375314572,273.949013873985,0.1501696816623766,55.228121196995374,286.9061276393955,0.046213072539980575
0.0476368129724925,274.038499282876,0.15124688118766366,55.2461614554278,287.09282002047684,0.046536973328489516
0.0479887899873727,274.084857390939,0.15236440820990832,55.25550725001331,287.2378580509918,0.04687288926470726
0.0483308561761296,274.158458467398,0.15345046835921147,55.27034522702744,287.4087714930552,0.04719923853345425
0.0486796621144043,274.284270856797,0.15455792721323364,55.29570900473027,287.6363364854016,0.047531908244406375
0.0490237412535793,274.474398052587,0.15565037848011426,55.33403864740154,287.9301599234489,0.0478599614302936
0.0493766660588213,274.701639472244,0.1567709147367576,55.37985051760439,288.2654905902757,0.048196336516135134
0.0497363287727696,274.91587282769,0.15791284385354348,55.423039962062305,288.5891790635009,0.048539017180161834
0.0500951250261619,275.046584557181,0.15905202195806403,55.449391446727695,288.8250775985918,0.048880755328940304
0.0504480085662603,275.127878217095,0.16017242719787644,55.46578024856635,289.00753177420796,0.04921674799462253
0.0508012650409884,275.197841143622,0.16129401650513817,55.47988477455419,289.1782396102669,0.04955298271221966
0.051153091135295,275.227924473735,0.16241106435456162,55.48594957390498,289.3066835773181,0.04988774364226417
0.0515133190628042,275.260379872331,0.16355478802440332,55.49249258226193,289.439955646043,0.05023038280678989
0.0518658070385154,275.325212710642,0.1646739373472864,55.505562882465426,289.6051770659304,0.05056554632974865
0.0522206659106507,275.44837516508,0.16580061426631595,55.530392433280134,289.8324727402072,0.05090285078948644
0.0525712110781397,275.634500191082,0.16691359517309354,55.567915238522126,290.1249396810449,0.051235943267239265
0.0529278798443363,275.851559424949,0.16804601850576775,55.61167438006973,290.4517976170655,0.05157474062996035
0.0532786207546816,276.057793506798,0.16915962089611408,55.65325117097048,290.7657719934209,0.05190779526015714
0.0536284705048902,276.210840987713,0.17027039385302636,55.68410554312295,291.0236059267535,0.052239893201139254
0.0539830674938521,276.36958902719,0.17139623929298042,55.7161091478815,291.288867204893,0.05257638499378196
0.0543362613320008,276.419727529572,0.17251762972910253,55.72621706996172,291.4393420819393,0.05291143276062042
0.0546925584933852,276.516604040679,0.17364887321649802,55.74574737460089,291.6400045815661,0.05324931070844622
0.0550499685052985,276.5445367284,0.17478365000432272,55.751378604445435,291.76830476561076,0.053588129318545404
0.0554121865052456,276.583256120705,0.17593369215415477,55.75918443393414,291.9093390930936,0.05393138873463452
0.0557794453539611,276.659467588916,0.17709973899882647,55.774548665925465,292.09137924294794,0.05427930490375721
0.0561377006698363,276.709788625293,0.17823719962673026,55.784693386859075,292.2436399115534,0.05461857514452975
0.0565001884774763,276.828505057271,0.17938809841598724,55.808626619545834,292.46936776894484,0.05496173647194828
0.0568704190845871,276.94860569214,0.18056358059356403,55.832838907535425,292.69878896274406,0.055312106264708144
0.0572440915476581,277.077979066631,0.18174999066381448,55.858920579832805,292.93905626616134,0.055665608844708635
0.0576075538018428,277.189683836512,0.18290398332085087,55.88144026144082,293.1579034614397,0.056009332489402396
0.057967530095356,277.328995864618,0.18404690805275528,55.90952556630698,293.40507277871507,0.05634964307419538
0.0583282440094464,277.513335522666,0.18519217472999233,55.946688441369474,293.7002010729074,0.05669053485501097
0.058696033524838,277.631361917705,0.18635990644136063,55.970482562609334,293.9272216443731,0.0570379938076502
0.0590645652091186,277.744240279215,0.18752999453895153,55.99323884028974,294.14908307064377,0.0573860328524987
0.0594279724857103,277.821435881029,0.1886838126421302,56.00880147361545,294.3318005285073,0.05772911386287759
0.0597925616570479,277.90951977695,0.1898413832611271,56.026559187033115,294.52644187329383,0.05807319242295249
0.0601555089346058,278.024779370169,0.1909937408673734,56.04979552102606,294.74950146961294,0.05841560390570432
0.0605155228937662,278.091716860056,0.1921367851877077,56.06329011898729,294.92058251826745,0.05875513225047408
0.060851623494825,278.146301670752,0.19320390459606937,56.074294416823605,295.07195569649866,0.059072003947524133
0.0612133791857707,278.202576088136,0.19435247891482196,56.08563933936823,295.23229586867734,0.05941295080258562
0.0615827447259944,278.309156280441,0.1955252145050322,56.10712590613691,295.4481980065663,0.05976094987775887
0.0619550808733888,278.424355542474,0.19670738177300942,56.13035007736276,295.67415900722915,0.060111625195826184
0.0623529862503315,278.544459480551,0.1979707313448025,56.154563031279075,295.91253833264784,0.06048624636095223
0.0627246277416625,278.616977041317,0.19915069307977842,56.16918257152951,296.0931232087409,0.060836013816665535
0.0631033020255257,278.700404494088,0.20035298393104412,56.186001546008136,296.2873202935146,0.06119227434233264
0.0634786732299838,278.815293143419,0.20154478750519852,56.20916309771327,296.5141180283922,0.06154530207671986
0.063853328896705,278.898563392082,0.20273431924703839,56.22595037984374,296.70716508917513,0.06189753263614378
0.0642232704893025,278.997130160991,0.20390888380353542,56.245821440455785,296.91523831705945,0.06224520959141012
0.0646106131008098,279.0461772708,0.2051386965950711,56.25570933779328,297.0755218677036,0.06260911080396367
0.0649869847722657,279.136044168434,0.20633367665194358,56.27382650435629,297.2762540201985,0.06296257821560099
0.0653834875367805,279.26795105569,0.20759257292927807,56.30041893282711,297.5274636529619,0.06333481654151368
0.0657659808054702,279.367389315638,0.2088069890573679,56.32046568603262,297.7402596790446,0.06369377144212351
0.0661447498232827,279.4764296355,0.21000958068892253,56.3424482145168,297.96232815524445,0.06404910435203964
0.0665409589936955,279.556050554143,0.2112675448049832,56.35849979171523,298.15797825050566,0.06442066324919252
0.0669224115206316,279.620482243272,0.2124786565780053,56.37148922024364,298.3333592255537,0.06477825320013586
0.0673071560165951,279.715212860348,0.2137002203526894,56.39058691264616,298.5420483325546,0.0651387996998974
0.0676794123320167,279.801264886432,0.214882134154153,56.4079350011047,298.7380500637007,0.06548751975716868
0.0680637036321625,279.909187515104,0.21610225903211594,56.42969220304497,298.9608434980515,0.06584738635481378
0.0684452234051778,279.949894358631,0.2173135843114395,56.43789870270001,299.1111274202634,0.06620452951695315
0.0688225783231733,280.049004664036,0.21851168617607522,56.457879340269656,299.3226992218533,0.0665576485052348
0.069203395849702,280.11760420741,0.21972078182280386,56.47170900821386,299.5026936558456,0.06691388134352225
0.0695952106898651,280.149870767332,0.22096479394032167,56.47821394669413,299.646960048123,0.06728026913089806
0.0699738087030698,280.182857474203,0.2221668426322466,56.48486406679933,299.7883191449824,0.06763417032662919
0.0703636367053879,280.28997461247,0.22340454653960656,56.50645888187396,300.01219655826424,0.06799843812698454
0.0707575780508151,280.343822934865,0.22465531031133795,56.51731470366878,300.1802728672426,0.06836641481803546
0.0711558456767924,280.428142190227,0.22591981002381584,56.53431346554976,300.3822437993444,0.06873829505012628
0.071559668917694,280.479981638193,0.22720194881367842,56.544764298259715,300.551036262263,0.06911522165837841
0.0719570936853776,280.551404503179,0.22846377245107388,56.55916314784089,300.7390682005785,0.0694860373003842
0.0723621534982364,280.595325796709,0.22974983735690055,56.56801768061654,300.8998078328981,0.0698638353528046
0.0727640022759103,280.691879895675,0.2310257072260152,56.587482986968084,301.1161444832335,0.0702384974968403
0.0731715829462497,280.774573353431,0.2323197758543428,56.604153988051685,301.3192933367595,0.07061836041355338
0.073577555884439,280.849707308895,0.2336087399330938,56.61930099347324,301.51394234354353,0.07099658154399233
0.0739777950469999,280.976970187673,0.2348794992742247,56.64495718983488,301.7630269011437,0.0713693208701488
0.0743911309522326,281.02194852359,0.2361918407733385,56.65402482235575,301.92748909665994,0.07175411130844866
0.074794841607122,281.061520032351,0.23747362210261236,56.66200243852196,302.08347190502764,0.07212979834976795
0.0752036320644047,281.095447375295,0.2387715318044849,56.66884219085948,302.2348459746859,0.07251006881713319
0.0755998220050992,281.149672136337,0.24002943486618994,56.67977390268555,302.40453730663614,0.07287847992827036
0.0760135614455532,281.286864108485,0.2413430575896314,56.707431804270584,302.66848043722234,0.07326306523410257
0.0764261247610511,281.311129346185,0.24265294611633723,56.7123236761909,302.81064881426875,0.0736464100713066
0.0768422799939034,281.412300360973,0.2439742389806433,56.732719752772155,303.0366631390394,0.074032943619205
0.0772490030290098,281.421704768364,0.24526558461710612,56.73461568130219,303.16125089244446,0.07441057203555412
0.0776632012805668,281.494910158639,0.24658066406579957,56.749373887981626,303.3567060257444,0.07479499443181638
0.0780852737933312,281.541297884407,0.24792074429382654,56.75872565349646,303.5255272138408,0.07518657306266133
0.0785143697106094,281.618784073226,0.24928312383118484,56.77434686916236,303.7299054034035,0.07558451055118227
0.0789432907520357,281.684782800975,0.2506449481377133,56.78765221267656,303.9219065100564,0.07598212766778921
0.0793645948166297,281.626693397933,0.2519825885427993,56.7759413890233,303.9778818090072,0.07637252986458608
0.0798011113075921,281.706593262949,0.2533685284016049,56.79204920181053,304.1870924680082,0.07677686798061982
0.0802358962148671,281.754687619629,0.254748970482203,56.80174502411721,304.3615274935298,0.07717943970659744
0.0806771990006584,281.838477170678,0.2561501068270904,56.818636997608685,304.5764160794193,0.07758788074284578
0.0811126835227056,281.883021404739,0.2575327701845903,56.82761711519538,304.74730971036564,0.07799077330096041
0.0815460464679988,281.890493324382,0.2589086975358962,56.82912345419542,304.8775485918992,0.07839154198913485
0.0819820631845133,281.933239438202,0.2602930506108297,56.83774107074152,305.0467080876392,0.07879460282340096
0.0824191846520184,282.001085135554,0.2616809112701584,56.851418763327686,305.24338464341076,0.07919852189698767
0.08285653527417,282.017618580087,0.26306949949548974,56.854751905745545,305.38462134190536,0.07960248950635435
0.0833027366132619,282.088723447795,0.2644861887471065,56.86908664707548,305.587486078738,0.08001446414847208
0.0837518577468592,282.108054868171,0.26591214834627797,56.87298386142327,305.7351285487332,0.0804289632950985
0.0842016169792155,282.205825706919,0.2673401339090092,56.89269446251487,305.9680125523962,0.08084387924606505
0.0846415673947701,282.2655730662,0.26873697647839506,56.90473953014592,306.1569735921061,0.0812495797824235
0.0850928335389245,282.229866834672,0.27016974648608527,56.89754115386988,306.24560591294755,0.081665544197669
0.0855353277718872,282.285530920885,0.27157466567574184,56.908763033650416,306.43091633346404,0.08207325496727864
0.0859925079152138,282.284083893523,0.2730262126308038,56.908471312934246,306.55840021207564,0.08249432269900932
0.0864476076960947,282.362311795427,0.2744711544351007,56.92424205795808,306.77185815368045,0.08291329837918386
0.0869145103708845,282.385757837584,0.2759535704275583,56.928968780056934,306.9291777157488,0.08334295773331667
0.0873853547716246,282.379716556311,0.27744850139990807,56.9277508577523,307.055568267895,0.08377605752387293
0.0878588983188087,282.369485838775,0.2789520021622176,56.92568834509704,307.1781577834182,0.08421145097818687
0.0883281083581468,282.357606328226,0.2804417440371161,56.923293435770354,307.2977195757325,0.08464267315272378
0.0888083565007169,282.394579895787,0.28196653188977616,56.93074730699066,307.47357842104225,0.08508384728958766
0.0892952994794425,282.453728564529,0.2835125758472299,56.94267167860905,307.67551884578376,0.08553097292155758
0.0897835778853094,282.510381945608,0.2850628597858573,56.95409300023457,307.87517482643,0.08597912412811645
0.0902826208428775,282.552103143912,0.28664732117613606,56.96250399381266,308.06164754041146,0.08643694780941205
0.0907772734744426,282.587277320768,0.28821784328135525,56.96959510786684,308.2397798745135,0.08689053704034949
0.0912740067022076,282.576265219891,0.2897949712795091,56.96737506833003,308.3681331454561,0.08734582719861324
0.0917739540860401,282.581503345236,0.2913823042231773,56.968431074399575,308.5151252588059,0.0878038541421828
0.0922851099561354,282.583676188997,0.2930052241107299,56.96886911970179,308.6619418179076,0.08827193294814893
0.0927938917012756,282.593173991413,0.29462060615155,56.97078387666886,308.8160943742919,0.08873762023355046
0.09331438951299,282.622139614456,0.2962731867037432,56.97662334627433,308.99485203543395,0.08921380691288609
0.0938307551767408,282.587733147568,0.29791264768615205,56.96968700254971,309.1031535524876,0.08968598926859157
0.0943468726304627,282.605810158888,0.299551320601719,56.97333132803182,309.2687845345773,0.09015772196225783
0.0948488279053792,282.605735503215,0.3011450285995789,56.97331627744814,309.41055827503254,0.09061629703034345
0.0953544028997756,282.602029478714,0.3027502292067875,56.972569142908746,309.54937725792155,0.09107796651951726
0.0958500444933975,282.544581914364,0.304323891266537,56.960987713935786,309.62649266222417,0.09153035844731244
0.0963724000995681,282.514634222223,0.3059823703161287,56.95495025920015,309.74124758547015,0.09200691192603878
0.0969134778888136,282.532245497119,0.3077002922969832,56.95850069221919,309.9134280239809,0.09250030661357352
0.0974639647125003,282.560619210728,0.3094480879621884,56.964220832882766,310.10009743062466,0.09300203145319992
0.0980079018844193,282.548526436822,0.31117508848303127,56.961782929663315,310.2405146934293,0.09349753967749011
0.0985541324477017,282.480096691035,0.31290937052145285,56.94798749291265,310.31967755416287,0.09399489014244797
0.0990947917533432,282.438397995834,0.31462596381686464,56.93958103596014,310.42657222837903,0.09448692443472753
0.0996490957131905,282.357007320071,0.3163858788893798,56.92317267572631,310.4936277677988,0.09499112501465863
0.100211210689128,282.262379388292,0.31817059393798136,56.90409568467967,310.5482341587867,0.09550217109020745
0.100772647583181,282.181651656812,0.31995315607659963,56.8878209740133,310.61784379366384,0.09601234012585944
0.101358907875597,282.048984634734,0.32181453250502046,56.86107530236237,310.63716168473167,0.09654478815768862
0.101932007992667,281.902093570942,0.3236341253767177,56.83146206390191,310.63694002596486,0.09706501009104068
0.102531550669493,281.748098529922,0.32553767337564027,56.80041666363228,310.636167970376,0.09760894531668966
0.103105834046193,281.575356418697,0.32736102309666276,56.765591854009315,310.60741838910087,0.09812968675284503
0.103699009219091,281.396341039371,0.32924435427061394,56.7295023535372,310.57686280303125,0.09866727410588526
0.104287356618541,281.201123616191,0.3311123572638676,56.69014652102411,310.5268454762871,0.09920020077833006
0.104885625358984,280.950964604107,0.3330118605147742,56.639714464187975,310.4186822218186,0.09974182315009471
0.105474509909135,280.700160450124,0.3348815689615036,56.589152346744996,310.3068723050163,0.10027466352726923
0.106062270142982,280.405656936887,0.33674770770396784,56.52978043847642,310.1461174725475,0.10080620363366692
0.106664404855203,280.074245237371,0.33865948541526947,56.462967839853995,309.9481979208853,0.10135045045265946
0.107264099086994,279.758810010729,0.34056351460120593,56.39937609816297,309.7668867281794,0.10189219716705436
0.107885011542088,279.388520904879,0.34253491164612937,56.3247258144236,309.5303547074287,0.10245280274288333
0.10850209320281,279.017650132716,0.34449414591892175,56.24995826675555,309.29164921264504,0.10300963839252743
0.109134909781898,278.607233054632,0.34650333855752613,56.167218183813816,309.0130082986335,0.10358035090806786
0.10975917139273,278.113618192007,0.34848536917191775,56.067705427508606,308.6391384777957,0.10414302907517696
0.110380328277484,277.579089828917,0.35045754228101167,55.95994450950967,308.21836088719806,0.10470259472504181
0.110983838409837,276.985844358011,0.35237368695123245,55.84034622257502,307.7267965500527,0.10524596366585064
0.111584813494538,276.351959155868,0.3542817828451581,55.71255496582298,307.1886409771257,0.10578675694918327
0.112205445191582,275.728678426052,0.35625228848327284,55.58690157069208,306.6669375409337,0.10634493163380856
0.112850130554156,275.009664841437,0.3582991645094453,55.4419484320337,306.0445414224478,0.1069244096366429
0.113517929309176,274.333413442018,0.36041942555663375,55.30561614991083,305.47517447627393,0.10752430934512879
0.114205638927248,273.499532472471,0.36260290359401237,55.13750574645015,304.7347213247932,0.1081417195568119
0.114891638736433,272.571067195722,0.36478095298817476,54.95032714665756,303.8872037779769,0.10875721519956873
0.115584911588786,271.527886703933,0.36698209429439554,54.740021959512895,302.91241348249696,0.10937885175035617
0.116273462021896,270.436844032861,0.3691682419195198,54.52006775702478,301.88147214683727,0.10999587159632526
0.116960259756817,269.275512243488,0.37134882472789393,54.28594326828718,300.77004610163624,0.11061094179688259
0.117638814220391,268.115188980637,0.37350323514974143,54.05202209849643,299.6559418867952,0.11121825833283956
0.118325099953924,266.820387473802,0.3756821923537087,53.79099011471848,298.39193649138434,0.11183211954118316
0.118997702027294,265.37523206147,0.3778177039366584,53.499646783592354,296.95427485174486,0.11243337573276811
0.119679494358646,263.846916502109,0.37998239458870103,53.19153836682518,295.4239820571693,0.11304247860256264
0.120404795818285,262.143070590614,0.38228522672305487,52.84804303106778,293.70635348025513,0.1136900448465341
0.120981912206358,260.618874539029,0.38411757125518664,52.540765107068246,292.1490443378296,0.11420500855070927
0.121389270382579,259.63921718482,0.3854109334646883,52.34326618445971,291.15663232158926,0.11456833660617582