File: example/data/02 processed data/test_ID_145.csv
Strain,Stress_MPa,Displacement(mm),Force(kN),True Stress (MPa),True Strain
-0.00018511062309409956,0.161415559719561,5.636592012715704e-06,0.0325413768394634,0.161415846281342,1.7753029950543945e-06
-0.00018605304379549958,0.182951374366642,2.644406285668072e-06,0.036882997072315,0.1829515267438906,8.328835225806807e-07
-0.00018189440116589956,0.17727135484344,1.5848096634784103e-05,0.0357379051364375,0.1772722396981052,4.991514041615896e-06
-0.00017029434112059957,0.15931068276378,5.267828727847412e-05,0.032117033645178,0.1593133259807605,1.6591448905584777e-05
-0.00013252646351099957,0.138039736561759,0.0001725912986889,0.0278288108908506,0.1380472403278704,5.435798673186629e-05
-0.00011571295053819956,0.109651349880532,0.0002259742023775,0.0221057121359152,0.1096591540935489,7.117044445061143e-05
-9.571273343244044e-05,0.0754282316583619,0.0002894748916895,0.0152063315023257,0.0754351086911775,9.11690382099552e-05
-6.612416962015396e-05,0.233952165293788,0.0003834185817935,0.0471647565232276,0.2339804177685673,0.000120754466931
-4.127843897445397e-05,0.597693110961658,0.0004623037765936,0.1204949311698702,0.597780139554553,0.0001455968889495
6.115746400946046e-06,1.15192453505944,0.0006127803151605,0.2322279862679831,1.1521468584231045,0.0001929830516393
3.678419777734604e-05,1.86507731227821,0.0007101526482805,0.3759995861552871,1.865494474354608,0.0002236451150095
4.259805181144607e-05,2.8233299786424,0.0007286116348388,0.5691833236943079,2.823977887641275,0.000229457652056
7.856808440184602e-05,4.13615468368464,0.0008428164883133,0.8338487842308234,4.137252642539955,0.0002654187853848
0.00012828712985440044,5.61124040058898,0.0010006744576256,1.1312260647587384,5.613008912382513,0.0003151234009251
0.00017150921265390043,7.0472414964756,0.001137904570514,1.420723885689481,7.049767193580594,0.0003583309321219
0.00022080872696840043,8.48387455371334,0.0012944305284626,1.7103491100286097,8.487333384019474,0.0004076115697495
0.00024490659091600046,9.94517625932399,0.0013709412464962,2.0049475338797165,9.94947051202874,0.0004316993230184
0.00028255753879790046,11.4794792437658,0.0014904830060212,2.3142630155431854,11.484868210295188,0.000469333312352
0.00032064146965150045,13.0038461053247,0.0016113994864814,2.62157537483346,13.010445913493646,0.0005073986488478
0.00037242346254530044,14.4158355942914,0.0017758073139192,2.906232455809146,14.42389850650702,0.0005591530350116
0.00040429031798910046,15.8628308659533,0.0018769845799533,3.197946702576185,15.872208594750088,0.0005910015698172
0.00043229975424400046,17.4934140570474,0.0019659145400626,3.526672273900756,17.504245728559237,0.0006189940655485
0.0004549749350522004,19.1221945164818,0.0020379082391286,3.855034414522732,19.13446830475121,0.0006416549581374
0.00046819331040340046,20.7657117449976,0.0020798765808687,4.186367487791516,20.779314931625468,0.0006548647673232
0.0005105209926377004,22.4766297606908,0.0022142669719626,4.531288559755265,22.492305117830995,0.0006971638451052
0.0005601712002801004,24.2709093941944,0.0023719063812272,4.893015333869592,24.289041150059056,0.0007467782196676
0.0005761526681225004,26.0201642052051,0.0024226475416269,5.2456651037693485,26.04001859476241,0.0007627476298413
0.0006106795527023004,27.7886720631918,0.0025322704001677,5.602196287939468,27.810835348774663,0.0007972475940322
0.0006459940991315004,29.4570366954077,0.0026443940850804,5.938538597794193,29.48157087291993,0.0008325333746938
0.0006925194755483004,31.1185066359581,0.0027921121552038,6.273490937809153,31.145872418833704,0.0008790189528299
0.0007526339910591004,32.8365077301658,0.0029829757419506,6.619839958401425,32.86735828323964,0.0009390788461284
0.0007851489960231004,34.5028281274593,0.0030862108827113,6.955770150495796,34.536366081365216,0.0009715628036621
0.0008137176891409004,36.0543561672148,0.0031769164833603,7.268558203310504,36.09043228639734,0.0010001033466943
0.0008574311955930004,37.6130803048794,0.0033157068663457,7.582796989463686,37.65236028870028,0.0010437722034779
0.0008864948107998004,39.1587386153852,0.0034079838446273,7.894401704861656,39.20077085115755,0.0010728050772593
0.0009168648888400004,40.668591599719,0.0035044088424049,8.19878806650335,40.71347959090332,0.0011031421314229
0.0009517916973075005,42.1463634305036,0.0036153014592892,8.496706867589525,42.1943545515159,0.0011380298233178
0.0009853080798856004,43.5789532669779,0.0037217159739747,8.785516978622745,43.6300362548528,0.0011715075245638
0.0009986201078218005,44.9705504874574,0.0037639816626721,9.066062978271413,45.023863346479466,0.0011848038780936
0.0010281633074316005,46.3491857454588,0.0038577813214332,9.343995846284496,46.40550228814619,0.0012143116601746
0.0010665365015013004,47.7147001685493,0.0039796162126045,9.61928355397954,47.77450684394152,0.0012526375510611
0.0010950404507571005,49.0773753905977,0.0040701162514917,9.893998878744496,49.140288972694655,0.0012811054123398
0.0011277502774707003,50.3673371828172,0.0041739699513074,10.154055176055948,50.43355190783404,0.0013137728275623
0.0011547764942284003,51.6433782787769,0.0042597781895131,10.411305061001425,51.71266625875318,0.0013407631970808
0.0011784873195227004,52.8931346650444,0.0043350600598225,10.663255948472951,52.965353536075966,0.0013644419727311
0.0012369408397664005,54.103419580053,0.0045206499865962,10.907249387338684,54.180453477060674,0.0014228140872401
0.0012718648191652005,55.2843602195534,0.0046315336211874,11.145327020261966,55.365006321311725,0.0014576878035472
0.0012950391527755004,56.4423741016371,0.0047051121304001,11.37878261889004,56.52601747141795,0.0014808281130841
0.0013318008142629003,57.5554413577432,0.0048218304056226,11.60317697772103,57.64285004345904,0.0015175347034611
0.0013718202927174004,58.7188616865097,0.0049488922497157,11.837722516000357,58.81038714147427,0.0015574926986944
0.0014090981510064004,59.9134837282176,0.0050672494497832,12.07855831960867,60.0091046943456,0.0015947118495406
0.0014521309764953005,61.0673872549685,0.0052038786707105,12.31118527060165,61.16747773497234,0.0016376751818251
0.0014849251273167004,62.1534818627696,0.0053080000995684,12.530141943534352,62.257390740853424,0.0016704151344741
0.0015226442537196005,63.2349230626891,0.0054277583258976,12.748160489438124,63.343025072182336,0.0017080705978959
0.0015655877427663005,64.265972711541,0.0055641039036209,12.956020098646666,64.37859713662266,0.0017509398801389
0.0016116543982154004,65.2338191208418,0.0057103655346718,13.151137934761708,65.35114477514186,0.0017969248888913
0.0016562096714802005,66.1838737567086,0.0058518285272875,13.342668949352456,66.30585696316402,0.0018413991825707
0.0017045198008134004,67.1091245055542,0.0060052131879205,13.529199500319727,67.23605508807721,0.0018896192729175
0.0017641500151120003,67.9781070444726,0.0061945391183185,13.704386380165674,68.11073477463833,0.0019491351441019
0.0018120854757273004,68.8567578832085,0.0063467342057721,13.881522389254837,68.99440057314737,0.0019969761186259
0.0018691412159768004,69.7176987687668,0.0065278861810643,14.055088071783388,69.86104024982765,0.0020539164124864
0.0019365216104142004,70.5994369076518,0.006741818933403,14.232846480582603,70.74934828416569,0.0021211562946015
0.0020058215330480004,71.4463035647677,0.0069618461877653,14.40357479865717,71.60296440763457,0.0021903069860947
0.0020655041855113005,72.236766455436,0.0071513386093363,14.562932117415896,72.39947183400808,0.0022498572851307
0.0021245466745990005,73.0199085628976,0.0073387985121897,14.720813566280157,73.18868916016424,0.0023087653512502
0.0021900948829878006,73.8010669741621,0.0075469140738242,14.87829510199108,73.97649069416542,0.0023741602604777
0.0022761226672484004,74.5431850598739,0.0078200522888516,15.02790610807058,74.72678556536864,0.0024599803606035
0.0023572009365972002,75.21517573174,0.008077475794034,15.163379427518786,75.40652967231235,0.0025408561535885
0.0024338954588838005,75.8227037869225,0.008320980902294,15.285857083443576,76.0214185176851,0.0026173531275165
0.0025139532102983002,76.4297866623494,0.008575164263035,15.40824499112964,76.63621122147329,0.0026971984257844
0.0026307688105423003,76.9840002697208,0.0089460537938097,15.519974454375712,77.20091460284696,0.0028136925899946
0.0027444787116688006,77.4342738290495,0.0093070827298864,15.610749603936378,77.66126192122451,0.0029270765679
0.0028520418597097006,77.8273625150306,0.0096485957249162,15.689996283030167,78.06387424959566,0.0030343195799726
0.0029581897448199006,78.1979451789927,0.0099856152601411,15.764705748084928,78.44388363401349,0.0031401402674331
0.0030733019015116003,78.5361074563922,0.0103510963576372,15.832879263208667,78.79214991807248,0.0032548849393218
0.0032013117289094004,78.8339897550653,0.0107575275596253,15.892932334621166,79.10109489441186,0.0033824706474082
0.0033367270893968006,79.1013316417348,0.0111874713291728,15.946828458973735,79.38005412357458,0.0035174196371674
0.0034481680194256006,79.3262364701906,0.0115412962820142,15.992169272390424,79.61459161917944,0.0036284631057056
0.0035867472427648004,79.5206845664505,0.0119812853161162,16.031370008596422,79.82076645946579,0.0037665308787991
0.0037304881561643004,79.6814226534933,0.0124376627161596,16.06377480694425,79.99356459355879,0.0039097211537227
0.0038579216222990004,79.831998260992,0.0128422639711372,16.094130849415986,80.1549033302868,0.0040366493075208
0.004016205893625301,79.9701598537904,0.0133448165325982,16.121984226524145,80.30628177861918,0.0041942835036812
0.0041771035801001,80.1002981026567,0.0138556666871557,16.14822009749559,80.44985496314558,0.0043544949183904
0.0043356165131431,80.2380443320943,0.0143589452495673,16.175989737350214,80.60092108343191,0.0045123066553972
0.0045081017123205,80.3426581257643,0.0149065857569555,16.197079878154085,80.71986591262839,0.0046840005615598
0.004671711550650201,80.4209887832085,0.0154260469936523,16.212871338694832,80.81172199651425,0.004846832585451
0.0048353599967967,80.4995557308143,0.0159456308101674,16.22871043533216,80.90384429650439,0.0050096765142791
0.005028909996631701,80.5675883363003,0.0165601520596436,16.242425808598142,80.98781243517523,0.0052022407742361
0.005194472736412801,80.6173386123668,0.0170858137584486,16.252455464253146,81.05116942598339,0.0053669308910778
0.0053425002881661,80.6601571487847,0.0175558012352653,16.261087681194997,81.10615830989,0.005514155279229
0.005509705895223401,80.6379227325081,0.0180866790376722,16.256605222873635,81.09728406376085,0.0056804276019497
0.005673492539495201,80.6567832711213,0.0186067016332352,16.260407507458055,81.12946254703382,0.0058432732454516
0.0058436076267901,80.6785865575852,0.0191468170353965,16.264803050009178,81.1651182538033,0.006012382902507
0.0060264659089048,80.6943175349649,0.0197273920811107,16.267974415048922,81.19569972102155,0.0061941285523069
0.0061645135513045,80.7078291458361,0.0201656933457297,16.27069835580056,81.22043680982176,0.0063313143422556
0.006346876279955801,80.7256251628615,0.0207446950091976,16.27428603283288,81.25306720173722,0.006512509705629
0.006531187999165801,80.7247341993933,0.0213298847176893,16.27410641459769,81.26704893146864,0.0066956082295362
0.006706818356744901,80.7388278180287,0.021887511103003,16.276947688114586,81.29541742127611,0.0068700513470477
0.006883000125697401,80.735335691976,0.0224468882194272,16.276243675502364,81.30612531579828,0.0070450115799408
0.0070574714541743,80.7284069562179,0.0230008346873413,16.274846842373528,81.31323238707533,0.0072182430699943
0.007233061432398,80.7289441917089,0.0235583328682016,16.274955149048516,81.3279487080449,0.0073925549672719
0.0074400055475656,80.7251859908869,0.0242153804338587,16.2741974957628,81.34086822375724,0.0075979537817378
0.0076139390258329,80.7218921851837,0.0247676192273574,16.273533464533035,81.35158953603549,0.0077705558326884
0.007806961696847201,80.7316837557683,0.0253804662078278,16.27550744516289,81.37704053418226,0.0079620660834397
0.0079935273253632,80.7468751454041,0.0259728120783661,16.278570029313467,81.40741795298423,0.0081471350357309
0.0081802770649982,80.7445246407963,0.0265657425017072,16.278096167584533,81.42012723923098,0.0083323523272727
0.0083700995297233,80.7594992735058,0.0271684288272094,16.28111505353877,81.45055713433518,0.0085205819792718
0.0085578400080914,80.7540710684836,0.0277645048460281,16.280020727406292,81.46024328817413,0.0087067122718798
0.0087464385023985,80.7359315748535,0.0283633050654531,16.276363805490465,81.4571718447751,0.008893658345682
0.0089321988729392,80.7251505163701,0.0289530942419199,16.274190344100212,81.46129000947046,0.0090777570045826
0.0091222199815589,80.7066960592549,0.0295564112617874,16.27046992554579,81.45800324045408,0.0092660432265604
0.0093140513723296,80.6870509807239,0.0301654759274844,16.26650947771394,81.45365359301326,0.0094560872497644
0.0095064412554278,80.6764822607458,0.0307763138063212,16.264378823766354,81.45850579928023,0.0096466482939041
0.0097078194550947,80.64260231715,0.0314156895902636,16.25754862713744,81.4405371083773,0.0098460733222636