File: example/data/02 processed data/test_ID_081.csv
Strain,Stress_MPa,Displacement(mm),Force(kN),True Stress (MPa),True Strain
-2.7951924122117e-06,-0.302812223282182,-8.874735908772148e-06,-0.06104694421368789,-0.30281137686375315,-2.7951963187547575e-06
5.10305863883695e-06,-0.142323573629056,1.6202211178307316e-05,-0.02869243244361769,-0.1423242999145979,5.103045618207372e-06
1.36513777181992e-05,0.0395325081401714,4.3343124255282456e-05,0.007969753641058555,0.03953304781337218,1.3651284539040193e-05
6.55145777017468e-06,0.260373084986028,2.080087842030461e-05,0.052491213933183255,0.26037479080929876,6.5514363093596595e-06
7.24307623181206e-06,0.466844027952845,2.2996767036003287e-05,0.09411575603529355,0.4668474093397279,7.2430500009498035e-06
6.7421358362329e-06,0.471865995070824,2.1406281280039457e-05,0.09512818460627813,0.4718691764554593,6.742113108195026e-06
1.60711208262371e-05,0.473956925731111,5.102580862330279e-05,0.09554971622739197,0.4739645427501308,1.6070991687054568e-05
2.49881985149304e-05,0.475831779672297,7.933753028490402e-05,0.09592768678193508,0.47584366985126725,2.4987886315209654e-05
2.16364367624319e-05,0.476698868456647,6.869568672072128e-05,0.09610249188086004,0.4767091825215691,2.16362026981294e-05
2.20343627277291e-05,0.479627183813121,6.995910166053989e-05,0.0966928402567252,0.47963775209246323,2.2034119974736366e-05
1.61339535675318e-05,0.485412199398472,5.122530257691346e-05,0.09785909939873197,0.4854200310163583,1.6133823416758547e-05
2.89038225559432e-05,0.493192891899781,9.176963661511965e-05,0.09942768700699585,0.4932071470596144,2.8903404848617542e-05
7.53164086855034e-05,0.843196466735084,0.00023912959757647328,0.16998840769379292,0.8432599732647748,7.531357254721744e-05
0.0001627867053922,2.51099541630226,0.0005168477896202349,0.5062166759265356,2.511404172973335,0.0001627734570741804
0.0002707912191288,5.94577456652893,0.0008597621207339399,1.1986681526122323,5.947384630072466,0.0002707545618042006
0.0004066788062705,11.0387173229167,0.0012912052099088374,2.2254054123000064,11.04320653530034,0.00040659613485774634
0.0005076712368644,17.0574201536044,0.0016118561770444698,3.4387759029666474,17.066079715191496,0.0005075424154194299
0.0006415447149677,23.3868577089734,0.0020369044700224476,4.714790514129038,23.401861423936296,0.0006413390131302878
0.0007500594494717,29.8961584587044,0.0023814387520726473,6.027065545274807,29.91858235485925,0.0007497782954620891
0.0008611547509525,36.6876808816003,0.0027341663342741874,7.39623646573062,36.71927465229292,0.0008607841699364278
0.0009819303535947,43.5833370206128,0.003117628872663172,8.786400743355541,43.62613282214429,0.000981448575341074
0.0010910859091616,50.499781658455,0.00346419776158808,10.180755982344527,50.554881258638275,0.001090491107544723
0.0012215814113166,57.3238630151355,0.0038785209809302046,11.556490783851318,57.39388878061965,0.0012208358878276508
0.0013491582126426,64.2653741941751,0.004283577325140254,12.9558994375457,64.35207835155772,0.0013482489164656013
0.0014728692883265,71.2123813592052,0.004676359990436637,14.356416082015768,71.31726788865777,0.0014717856802345514
0.0015880940587079,78.2776156596548,0.0050421986363975825,15.780767316986408,78.40192787601372,0.0015868343708304107
0.0017108684703888,85.4393487678577,0.0054320073934844395,17.22457271160011,85.58552425579518,0.0017094066020661059
0.0018239355068534,92.6132803599992,0.005790995234259545,18.67083732057584,92.78220101045397,0.001822274156310945
0.0019484305576249,99.7877690634114,0.006186267020459057,20.11721424318374,99.98219860193177,0.00194653482887048
0.0020571924355397,106.95458672406,0.006531585982838547,21.562044683570495,107.174612890815,0.0020550793127518106
0.0021800704516268,114.107388341972,0.006921723683915089,23.004049489741558,114.35615048760864,0.0021776975461480635
0.0023035473748407,121.32386115931,0.007313762915119222,24.458890409716897,121.60333642118907,0.002300898277021562
0.002429607002509,128.524097910561,0.007714002232966074,25.9104581387691,128.83636095883566,0.0024266602793699566
0.0025568867636381,135.825151203526,0.008118115474550968,27.38235048263084,136.17244073480742,0.002553623490040802
0.0026767160384217,143.13026240329,0.008498573421988896,28.855060900503265,143.5133814722484,0.0026731400139599145
0.0028025507143273,150.474640917838,0.008898098517989178,30.335687609036142,150.89635373023043,0.002798630891035219
0.0029330279110252,157.841326685738,0.00931236361750501,31.82081145984478,158.3042797024205,0.002928734976810445
0.0030553914051261,165.204067920989,0.009700867711275367,33.30514009287138,165.70883101020664,0.003050733182856398
0.0031731214440436,172.560822247105,0.01007466058483843,34.78826176501637,173.10837869257907,0.0031680977186493878
0.0033018043110459,179.900184069519,0.010483228687570732,36.267877108415036,180.49417927283773,0.0032963653242168074
0.0034145264866138,187.194371294429,0.010841121594998815,37.73838525295689,187.83355143335888,0.0034087102271375463
0.0035436360094625,194.406346237865,0.011251044330043437,39.19231940155358,195.09525156686152,0.003537372124968186
0.0036681530636496,201.459633687831,0.011646385977087479,40.614262151466725,202.19861846034473,0.0036614417971618323
0.0037882033490325,208.130359510875,0.012027545633178186,41.9590804773924,208.91879963580942,0.0037810461762483177
0.0039049030506532,214.345712769425,0.012398067185823909,43.21209569431608,215.1827119971128,0.003897298706458548
0.0040300342062229,219.980966514152,0.012795358604757707,44.34816284925304,220.86749733392202,0.004021935370137104
0.0041426039140372,225.06319907695,0.01315276742706811,45.37274093391312,225.9955467663519,0.004134046954365664
0.0042677376666948,229.591274071227,0.013550067091755989,46.285600852759366,230.57110939952523,0.004258656701914764
0.0043972081644609,233.504539366957,0.013961135922163357,47.07451513637853,234.53130743390008,0.004387568692153984
0.0045257277125468,236.838345474145,0.014369185487336091,47.746610447587635,237.91021133765108,0.004515517401351252
0.0046835562677328,239.774337558812,0.014870291150051639,48.3385064518565,240.89733416032703,0.004672622543925494
0.004860746202202,242.301909163653,0.015432869191991348,48.84806488739245,243.4796772484065,0.004848970917743926
0.0050679198824406,244.411962780798,0.016090645626748907,49.27345169660888,245.65062302648116,0.005055121200058158
0.0053155657348001,246.102768869192,0.016876921207990316,49.614318204029104,247.4109443146325,0.0053014879807085176
0.005591604836002,247.375154111547,0.01775334535430635,49.870831068887874,248.75837821958388,0.0055760298461666555
0.0058920937835478,248.241715503915,0.018707397762764262,50.045529845589265,249.70437897265288,0.00587480328389051
0.0062267977938616,248.771152688759,0.019770082995510578,50.15226438205382,250.3202003534978,0.006207491391737469
0.0065852191436461,249.10658792852,0.020908070781076368,50.219888126389634,250.7470094001553,0.006563631309978019
0.0069464839538546,249.421553251116,0.022055086553488354,50.283385135424986,251.1541560685204,0.006922468286350654
0.0073066675336351,249.728811472558,0.02319866941929144,50.3453283928677,251.5534968715578,0.007280103157968904
0.0076680930186178,249.947134726744,0.024346195334111514,50.38934236091159,251.86375260556565,0.007638842627995503
0.0080344259809808,250.035148472024,0.025509302489614038,50.40708593196004,252.044037365066,0.008002321824894213
0.0084200112452936,250.158421973262,0.02673353570380718,50.431937869809616,252.2647586993818,0.008384760685791944
0.0088008642464495,250.285915765675,0.02794274398247716,50.45764061836008,252.488648133127,0.00876236237562988
0.0091790334375717,250.633744435754,0.02914343116429015,50.52776287824801,252.93431995651358,0.009137162140467147
0.0095522559829171,250.811450040077,0.030328412745761788,50.563588328079526,253.20726521430643,0.009506921653834472
0.0099171649702009,250.942937831415,0.031486998780387854,50.59009626681326,253.43158034399605,0.009868312608774731
0.0102897437231508,251.102636860059,0.03266993632100379,50.6222915909879,253.6864186415564,0.010237164685827546
0.0106595904682822,251.151669325418,0.033844199736795984,50.63217653600427,253.82884326585238,0.010603177571952938
0.0110329228613357,251.33863287617,0.03502953008474084,50.669868387835876,254.11163262476637,0.010972504158301359
0.0114033778763818,251.444116896962,0.036205724757512214,50.691133966427536,254.31142917673117,0.011338849460800264
0.011770469347408,251.604355098891,0.0373712401780204,50.723437987936435,254.56585644825688,0.01170173619498622
0.0121328517969676,251.80281528709,0.03852180445537213,50.76344756187735,254.85790152702748,0.012059838728487902
0.0125024596630179,251.974671785532,0.03969530943008183,50.79809383196325,255.12497495563278,0.012424949292414203
0.0128720101436213,252.258994939325,0.040868632205997624,50.85541337976792,255.5060752810037,0.012789869943102236
0.0132451101018824,252.425299205551,0.042053224573476614,50.88894031983909,255.76870008602916,0.013158160560411844
0.0136135490723422,252.66596739806,0.043223018304686486,50.937459027448895,256.10564794414427,0.013521717212820892
0.0139814017064631,252.859603575453,0.04439095041802034,50.97649608081133,256.3949352683784,0.013884563488419925
0.0143440528130977,253.081764600869,0.04554236768158519,51.0212837435352,256.71198279833584,0.014242150195909133
0.0147039748442173,253.219474212945,0.046685120130389925,51.04904600132971,256.94280699183804,0.014596919555715791
0.0150606332481519,253.36884616081,0.04781751056288228,51.07915938601929,257.1847414293454,0.014948347899853283
0.0154298853070643,253.506545222918,0.04898988584992915,51.10691951694027,257.4181221402977,0.015312055151483761
0.0157936567773462,253.831849970061,0.05014486026807419,51.1725009539643,257.84078308764697,0.015670234806882788
0.0161711257557964,254.081352286083,0.051343324274653566,51.22280062087433,258.190133786104,0.016041765835409356
0.0165364410486062,254.251802522456,0.052503200329324685,51.257163388527125,258.45622246637043,0.016401202975024273
0.0168956173314883,254.40355835261,0.05364358502747535,51.28775736388618,258.7018635223046,0.01675447397332224
0.01725475707682,254.56118257958,0.0547838537189035,51.31953440804333,258.95357394617866,0.01710758429749666
0.0176175147222439,254.824794565503,0.05593560924312438,51.372678584405406,259.31417413535354,0.01746412525025736
0.0179791376867263,255.096550442533,0.057083762155356,51.427464569214656,259.6829664463482,0.017819424486831093
0.0183342767905074,255.240829401018,0.05821132880986099,51.456551207245234,259.92048541549497,0.01816823042687655
0.0186763204082045,255.40070755109,0.059297317296049284,51.48878264229974,260.1706529977963,0.018504059431774335
0.019018759309426,255.512639715274,0.06038456080742754,51.51134816659924,260.37217311053485,0.01884016359952111
0.0193691721619354,255.551584374341,0.06149712161414489,51.51919940986714,260.50140700834294,0.019183977306962186
0.019719254320441,255.716065806784,0.06260863246740017,51.55235886664766,260.7585959422506,0.01952734854814884
0.0200801744906916,255.835288013955,0.06375455400794583,51.57639406361333,260.97250523815154,0.019881226649024107
0.0204358851729455,256.240881786473,0.06488393542410195,51.65816176815295,261.4773910232757,0.02022987441797711
0.0207995057935622,256.447759359252,0.06603843089455999,51.69986828682521,261.7817460157908,0.020586149471870478
0.0211612232978899,256.633286031746,0.06718688397080043,51.737270464000005,262.06396030313505,0.020940433962221297
0.021529527679144,256.799324952599,0.0683562503812822,51.77074391044396,262.32809312715153,0.021301041053695204
0.0218901159965595,256.878535479387,0.0695011182890764,51.78671275264442,262.50163641805705,0.02165396740660973
0.0222471730890096,257.131748328554,0.07063477455760547,51.837760463036496,262.852202840299,0.022003314877533632
0.0225967760932278,257.242687199583,0.07174476409599825,51.86012573943593,263.0555426038522,0.022345251002062028
0.0229428531634436,257.253540182578,0.07284355879393344,51.86231370080772,263.1556703807629,0.022683623398830247
0.0232976266955354,257.373350269226,0.07396996475832489,51.88646741427597,263.36953850517773,0.02303037984230649
0.023645655224295,257.505871455758,0.07507495533713662,51.91318368548081,263.59476651043246,0.023370426911697467
0.0240091130962154,257.736207277301,0.07622893408048388,51.95961938710388,263.9242250268113,0.023725426085738556
0.0243570400108566,257.943303465481,0.0773336020344697,52.00136997864097,264.22603882852223,0.024065137731002172
0.0247037910366288,258.11035104839,0.07843453654129644,52.03504677135542,264.4866552250803,0.02440358647183813
0.0250386242341112,258.183092195035,0.07949763194330306,52.04971138651906,264.64764162410734,0.024730294060036673
0.0253770409162849,258.248831112153,0.08057210490920455,52.062964352210045,264.80242226586887,0.025060389748436218
0.0257135574899298,258.448231068381,0.0816405450305271,52.103163383385606,265.0938545161285,0.02538852403653254
0.0260556453890909,258.57279142247,0.08272667411036361,52.128274750769954,265.31007238304124,0.025721980549917117
0.0264101716036642,258.69959483046,0.08385229484163384,52.153838317820735,265.53189552373084,0.02606744425037336
0.0267542616507007,258.871992295986,0.08494478074097471,52.18859364687078,265.79792131191095,0.02640262446749062
0.0270993536576319,259.037614158672,0.08604044786298128,52.22198301438828,266.05736607538705,0.026738667900777738
0.0274415758140771,259.185263527852,0.08712700320969478,52.251749127214964,266.2977155868431,0.027071805250052452
0.0277643367613511,259.388233948921,0.08815176921728975,52.292667964102485,266.589976228211,0.027385896356887585
0.028103097251819,259.535658059565,0.08922733377452532,52.32238866480831,266.8294138983278,0.027715451159818206
0.0284482595581933,259.708827785779,0.09032322409726372,52.35729968161305,267.097091928183,0.028051122144617226
0.0287947772819994,259.823155735169,0.09142341787034809,52.38034819621007,267.3047056372694,0.02838799797394609
0.0291421167097778,259.944885763949,0.09252622055354452,52.40488897001212,267.5202299629919,0.028725558792346978
0.0294846177163102,260.066528489465,0.09361366124928489,52.42941214347614,267.73449066278476,0.02905830586491229
0.0298327734088123,260.218060870084,0.09471905557297905,52.459961071408934,267.9810873169018,0.02939643314662196
0.0301839999143449,260.386206090498,0.09583419972804506,52.4938591478444,268.2457033128302,0.029737426980734533
0.030534913504705,260.530009965993,0.09694835037743837,52.522850009144186,268.4852712856845,0.03007800093428725
0.0308834041735897,260.656919664148,0.09805480825114729,52.548435004292244,268.70689266477876,0.030416108604347156
0.031229091347218,260.803192460145,0.09915236502741714,52.57792359996523,268.9478391811289,0.03075138340396875
0.0315713405201517,260.973317486919,0.10023900615148165,52.61222080536287,269.21259495997214,0.03108321305727584
0.0319107635609939,261.147851883397,0.10131667430615562,52.64740693969283,269.4812792393095,0.03141219390303378
0.03225898225075,261.331542283821,0.10242226864613126,52.684438924418316,269.76183186791593,0.031749587369599125
0.0325890889889105,261.441555235553,0.10347035753979082,52.70661753548749,269.96169734452354,0.032069326865759355
0.0329252757823647,261.470625717575,0.10453775060900791,52.71247814466312,270.0796181783136,0.032394850427499455
0.0332717152060903,261.570318854932,0.1056376957793367,52.73257628115429,270.27321201023955,0.032730190599306194
0.0335956149418502,261.658808914539,0.10666607744037437,52.750415877171065,270.449397504975,0.03304361152738098
0.0339371835255239,261.750411837931,0.10775055769353838,52.768883026526886,270.6334836023563,0.03337402329839087
0.0342690064270019,261.924294112622,0.10880409540573102,52.8039376931046,270.9001794309554,0.03369490320479198
0.0346077291506629,262.093628302252,0.10987954005335471,52.838075465734,271.16409360265084,0.03402234922500429
0.0349578569837095,262.282929294152,0.11099119592327765,52.87623854570104,271.45177842568535,0.03436070799820081
0.0352985125337704,262.372668187201,0.11207277729472101,52.89432990653972,271.6340331037257,0.034689803039907964
0.0356535515574063,262.549020917765,0.11320002619476499,52.92988261702142,271.9098259714031,0.035032678216277716
0.0360001170875226,262.698390007713,0.11430037175288424,52.959995425554936,272.1555628066943,0.03536725685612914
0.036342243102724,262.779264647514,0.11538662185114869,52.97629975293883,272.32925256568905,0.035697439768838865
0.0366776722257297,262.853322335897,0.1164516093166918,52.99122978291685,272.4941703359771,0.03602105376159662
0.0370125680858113,262.902660704719,0.11751490367245086,53.00117639807135,272.6333633339934,0.03634404883239653
0.0373555971338461,262.97011180257,0.11860402089996136,53.01477453939811,272.79351735730927,0.03667477995034668
0.0377044666809318,263.182135281787,0.11971168171195846,53.05751847280826,273.10527733253565,0.03701103002470007
0.0380530769676479,263.339583701295,0.12081851937228207,53.08926007418108,273.36046514850875,0.03734691731660492
0.0384091690634511,263.483141081503,0.12194911177645723,53.118201242031,273.6033095926716,0.03768989692047164
0.0387534840976462,263.603084593321,0.12304231201002669,53.142381854013514,273.81862254019876,0.038021421307187026
0.0390953542718358,263.573946114171,0.12412774981307867,53.136507536616875,273.87846291433027,0.038350482951096256
0.0394385999511402,263.704215353819,0.12521755484487013,53.16276981532991,274.1043404085876,0.038680759665342124
0.0397753957054976,263.809110461419,0.1262868813649549,53.18391666902207,274.30222222073724,0.039004724161547516
0.0401248181451859,263.945450143448,0.12739629761096521,53.21140274891912,274.53621333070305,0.039340723399057774
0.0404709231757168,264.143529331871,0.12849518108290084,53.25133551330519,274.8336618148238,0.03967342141131424
0.0408208831092026,264.338022975383,0.12960630387171826,53.29054543183722,275.1285345125788,0.040009712493350016
0.041161860603266,264.517564243709,0.13068890741536954,53.32674095153173,275.405599350224,0.04033726323616172
0.0415071823883488,264.631145866483,0.13178530408300743,53.34963900668298,275.61523910360086,0.04066887789131725
0.0418588925426935,264.658024995529,0.13290198382305188,53.35505783909865,275.7363168243783,0.041006514336412475
0.0422042534336429,264.690728542922,0.1339985046518162,53.36165087425307,275.86180313188305,0.04133794469136841
0.0425548285228334,264.730039577745,0.13511158055999603,53.36957597887339,275.99558101681885,0.04167426661511424
0.0429078328587232,264.943300443538,0.13623236932644614,53.41256936941727,276.31144329600784,0.04201280476858784
0.0432586939179205,265.011649094346,0.13734635318939759,53.426348457420154,276.4757069072017,0.04234917394909389
0.0436142335005478,265.108886399849,0.13847519136423925,53.44595149820955,276.6714072743622,0.0426899130342543
0.0439667758445412,265.208172588158,0.1395945133064183,53.465967593772646,276.8685208644819,0.04302766505035967
0.0443158028363401,265.306654713859,0.1407026740053798,53.48582159031398,277.06393211532736,0.04336193685687867
0.0446709583394584,265.429496411298,0.14183029272778042,53.51058647651767,277.2864863875505,0.04370196343161888
0.0450330511534578,265.462891103198,0.1429799374122285,53.51731884640471,277.4174950575931,0.044048512814668636
0.045383275407586,265.513343086494,0.14409189941908554,53.52748996623719,277.56320826017725,0.04438358889779625
0.0457345355259854,265.601325014652,0.14520715029500364,53.54522712295384,277.74847824928344,0.04471954330444579
0.04607561492139,265.754564893887,0.14629007737541325,53.57612028260762,277.99936988953925,0.04504565262976309
0.0464211129865854,265.975343782304,0.14738703373240863,53.620629306512484,278.32221526766824,0.04537587830106502
0.0467697043049741,266.115979459887,0.14849381116829274,53.64898145911322,278.5621451300545,0.04570895001027728
0.0471236484975275,266.191108562873,0.1496175839796498,53.664127486275206,278.735004795957,0.04604702281178906
0.0474787206460372,266.289894631019,0.1507449380511681,53.68404275761343,278.9329981490679,0.04638605818875757
0.0478213721551765,266.387692057726,0.15183285659268536,53.70375871883756,279.1267170171771,0.04671312495439285
0.0481728092182763,266.452635790019,0.15294866926802722,53.71685137526782,279.2884077796384,0.04704846659752927
0.0485211465170609,266.519972464804,0.15405464019166837,53.730426448904495,279.45182709849183,0.04738073950844859
0.048873055802465,266.586738316401,0.15517195217282637,53.743886444586444,279.61564685433564,0.04771630760367565
0.0492334446121483,266.732071344368,0.15631618664357083,53.7731855830246,279.86421000518453,0.048059844800816404
0.0495860518178714,266.767260838149,0.15743571452174168,53.780279784970844,279.9951960573811,0.048395850073914316
0.0499311229347563,266.828926297146,0.15853131531785125,53.79271154150463,280.1519942186378,0.04872456481284728
0.050278259147564,266.875427119859,0.1596334727935157,53.80208610736358,280.2934590047081,0.049055137772791496
0.0506255053477618,266.959447930332,0.1607359794791437,53.81902470275492,280.47440488916453,0.04938570617790207
0.0509881679894406,267.028155143232,0.1618874333664739,53.83287607687557,280.64343157558557,0.04973083397172992
0.0513440106344551,267.128614050158,0.16301723376439495,53.85312859251185,280.8440684507166,0.05006935578291741
0.051717502879635,267.201627185311,0.16420307164284112,53.867848040558705,281.02062810871047,0.05042454486959557
0.0520703585534004,267.271744095861,0.16532338840704625,53.88198360972558,281.1886796421251,0.05075999283328305
0.0524215682342037,267.290351350833,0.16643847914359675,53.885734832327934,281.30213074251503,0.0510937643052411
0.0527593046160643,267.331169814925,0.16751079215600415,53.893963834688876,281.4353764365594,0.05141462641178393
0.0531068509414146,267.406104731615,0.16861425173899136,53.90907071389359,281.6072008764212,0.05174470088265035
0.0534567506596938,267.481232633667,0.1697251833445278,53.92421649894726,281.77991019271246,0.052076900414846784
0.0538115001993125,267.553324698861,0.17085151313281718,53.93875025929037,281.95077048422047,0.052413591809333845
0.0541723437992078,267.693768135964,0.17199719156248477,53.96706365621034,282.19536697633083,0.05275595079320108
0.0545294993523502,267.788517534062,0.17313116044371188,53.98616513486691,282.39089132750246,0.05309469527499444
0.0548865124211333,267.86723066179,0.1742646769370982,54.00203370141687,282.56952874472296,0.05343318997703455
0.0552423363098751,267.900885560895,0.17539441778385342,54.008818529076436,282.70035637876333,0.05377044321380099
0.0556106734483461,268.023183539745,0.17656388819849886,54.033473801612594,282.9281332761599,0.054119436858082993
0.0559751224042061,268.085687325943,0.17772101363335435,54.046074564910114,283.0918164888284,0.05446462667721754
0.0563476865649807,268.207385689618,0.17890390484381372,54.070608955026984,283.32025139286947,0.054817379734710625
0.0567183493306447,268.247835968953,0.1800807591247969,54.07876373134093,283.4624104366295,0.05516820906343871
0.0570869294404202,268.301897181381,0.18125100097333413,54.08966247176641,283.61842865450535,0.05551694517192759
0.0574427817140422,268.382743318026,0.18238083194208396,54.10596105291404,283.79939465825913,0.055853523348251354
0.0577964738440722,268.419071752284,0.18350380445492923,54.11328486526046,283.93274761206504,0.056187946163445426
0.0581577449335163,268.461418912799,0.18465084016391425,54.12182205282028,284.0745296384194,0.056529419612869336
0.0585271484543907,268.482729695844,0.18582369634269047,54.126118306682145,284.19625827419276,0.05687845930770424
0.0588958959639279,268.624131431828,0.18699446968547107,54.15462489665652,284.44499033003746,0.0572267576926084
0.0592596394766829,268.67210336699,0.1881493553384682,54.16429603878518,284.5935153499599,0.05757021076793222
0.0596189699797226,268.778134253118,0.18929022968561926,54.185671865428596,284.80240977036055,0.05790938121864218
0.0599760200401884,268.800393408345,0.19042386362759817,54.19015931112234,284.9219711902144,0.058246285264485
0.0603405671042202,268.85597532111,0.19158130055589911,54.20136462473578,285.078897341344,0.05859014624244833
0.0607023422995566,268.940140258738,0.1927299368010922,54.21833227616158,285.26543671081464,0.058931275785128266
0.0610691756452499,268.974895212416,0.1938946326736684,54.22533887482307,285.40097033230575,0.05927705604115108
0.061427499584384,268.947134796214,0.1950323111804192,54.21974237491675,285.46788480712974,0.05961469986101662
0.0617872065193145,268.919309240802,0.1961743806988235,54.21413274294569,285.5350821378949,0.059953532233774726
0.0621316397454351,268.983053119474,0.19726795619175644,54.22698350888596,285.69541127352034,0.06027786970057159
0.0624981994392946,269.083728680782,0.19843178321976035,54.247279702045645,285.9009772217425,0.060622927169629116
0.0628619482865271,269.276344278,0.19958668580972352,54.2861110064448,286.2035799067887,0.06096522101679035
0.0632327320014853,269.334712339985,0.2007639241047158,54.29787800774098,286.3654820240764,0.06131401424989984
0.0636170295918737,269.376230248703,0.20198406895419896,54.306248018138525,286.5131458597821,0.06167539153334519
0.0639869946168272,269.377722157053,0.20315870790842636,54.306548786861875,286.6143930146095,0.062023167740264194
0.0643512966780099,269.423657568377,0.20431536695268143,54.3158093657848,286.7614192886342,0.062365502477397486
0.0647299322903281,269.551697770076,0.2055175350217917,54.34162227044732,286.999760915476,0.06272118229943348
0.0650997240589612,269.654542505106,0.20669162388720178,54.36235576902937,287.2089788134339,0.06306843239170883
0.0654840867573091,269.741982402063,0.2079119754544564,54.37998365225591,287.4057897797682,0.06342923744482729
0.0658523634930878,269.765472179117,0.20908125409055375,54.38471919130999,287.5301661109407,0.06377482036713016
0.0662296181628012,269.752108957445,0.21027903766689376,54.38202516582091,287.6176881323069,0.06412870420170717
0.0666055814812325,269.720008217581,0.21147272120291316,54.37555365666432,287.6848662020358,0.06448125213638872
0.0669805824823114,269.72851772436,0.21266334938133866,54.37726917323098,287.79509095362806,0.06483277391814198
0.0673557402712603,269.751381936966,0.21385447536125146,54.38187859849235,287.92068595652586,0.06518431906949719
0.0677179969988876,269.702410095917,0.2150046404714681,54.372005875336875,287.9661170933851,0.06552365791740668
0.0680865199363121,269.79506210264,0.2161747007977909,54.39068451989222,288.16446897720994,0.06586874843309715
0.0684607846746169,269.846708664573,0.21736299134190865,54.401096466777915,288.3206260816124,0.06621909381634718
0.0688295730184384,269.922412664798,0.2185338943335419,54.416358393223284,288.5010570766228,0.06656419278350838
0.0692016363931121,270.048247041518,0.2197151955481309,54.441726603570025,288.7360276418824,0.0669122357650996
0.0695692665981901,270.079684835996,0.22088242144925355,54.44806446293679,288.8689304331066,0.06725601284583749
0.0699423401291366,270.157963894873,0.22206692991000868,54.463845521206395,289.0534440942032,0.06760475929204003
0.0703323195769701,270.187093800273,0.22330511465688005,54.469718110135034,289.18997882700654,0.06796917929802455
0.0707102115185838,270.180082069694,0.22450492157150354,54.468304545250305,289.28457282095036,0.06832217737260686
0.0710958994668997,270.237609554629,0.22572948080740654,54.47990208621321,289.4503954757002,0.06868232944286819
0.071480123483561,270.321000726603,0.22694939206030618,54.49671374648317,289.64357923874036,0.0690409855807734
0.0718622803597529,270.393739912231,0.22816274014221544,54.51137796630577,289.82485065732584,0.0693975845819935
0.0722447386017977,270.460599086958,0.2293770450607077,54.52485677593073,289.99995437008084,0.06975433752643044
0.072618864532317,270.412228822102,0.23056489489010645,54.51510533053576,290.0492578348161,0.07010319507967239
0.072985966102862,270.359116741941,0.23173044237658683,54.50439793517531,290.09153807206803,0.07044538444174472
0.0733617476773677,270.383740929371,0.23292354887564243,54.509362171361204,290.2195647074943,0.07079554352914026
0.0737461744798265,270.394399422037,0.23414410397344912,54.51151092348266,290.33495198018244,0.0711536315438128
0.0741247276385704,270.493504223866,0.23534601025246102,54.53149045153139,290.54376155246257,0.07150612308535764
0.0745128895349268,270.584758542269,0.23657842427339257,54.549887322121435,290.74681076536393,0.07186743287298922
0.0748976727734191,270.602704052788,0.23780011105560564,54.55350513704206,290.87021683253613,0.07222546893120013
0.0752828310276409,270.614604750962,0.23902298851275983,54.55590431779394,290.9872383140405,0.07258372560561463
0.0756672148187688,270.627210776815,0.24024340704959093,54.5584456926059,291.10481807046847,0.07294113399449076
0.0760496775499691,270.625861505854,0.24145772622115186,54.55817367958017,291.2068710100568,0.07329662940058684
0.0764187604012063,270.709615146753,0.24262956427383,54.5750584135854,291.3969083649555,0.07363956855671758
0.0767971460413469,270.727170323662,0.24383093868127637,54.57859753725026,291.51824436036884,0.07399102949744658
0.0771763168114246,270.79435200209,0.2450348058762731,54.59214136362135,291.6932627029477,0.07434309583487687
0.0775737331062183,270.807372821059,0.2462966026122431,54.5947663607255,291.814911683476,0.07471197045150837
0.0779698423343656,270.83479428534,0.24755424941161078,54.600294527924554,291.9517404944283,0.07507949652439234
0.0783579181546441,270.971277501657,0.24878639014099502,54.62780954433406,292.2040226863912,0.07543943793179732
0.0787487878160886,271.009516224979,0.2500274013160813,54.635518470955766,292.3511871143207,0.07580183972178808
0.0791415193929472,271.058819310695,0.25127432407260736,54.645457973036116,292.51082611580176,0.07616583559301726
0.079531089144168,271.034836223833,0.25251120803273336,54.640622982724736,292.5905319447256,0.07652677013576302
0.0799323699296091,271.043795624414,0.2537852745265089,54.64242919788186,292.70896856339,0.07689841873983982
0.0803122808227069,271.085102761801,0.2549914916120944,54.650756716779085,292.8565656616591,0.07725014825055253
0.0807100835644004,271.083678257713,0.25625451531697124,54.65046953675495,292.96286458283805,0.07761830986955516
0.0811091223728262,271.089579839801,0.2575214635337232,54.65165929570388,293.07741774502546,0.07798747932818692
0.0815118213546708,271.072200926403,0.25880003280107977,54.64815570676285,293.1677897425334,0.07835989686873372
0.0819059216885887,271.072634539203,0.26005130136126914,54.64824312310333,293.2750885156904,0.07872422811224362
0.0822903693481487,271.072130360192,0.26127192268037214,54.648141480614704,293.3787560875217,0.07907950795926687
0.0826818435303199,271.060507822409,0.26251485320876566,54.64579837699767,293.47229031743046,0.07944115157215854
0.0830622350014404,271.03116112581,0.2637225961295733,54.6398820829633,293.5436151239553,0.07979243174307345
0.083444418832545,270.969332659169,0.26493602979333036,54.627417464088474,293.5802111443559,0.08014524287743345
0.0838247907586628,270.971641460346,0.26614371065875436,54.62788291840576,293.68578260729095,0.08049625781211728
0.0842150653906456,271.002465897327,0.26738283261529977,54.63409712490113,293.82495628389665,0.08085628314568431
0.084604504287498,271.086279402452,0.26861930111280613,54.65099392753433,294.02139969043867,0.08121540836428948
0.0850065028151535,271.176744738317,0.2698956464381123,54.66923173924471,294.22853145331885,0.08158598035248425
0.0853968071778301,271.226113267277,0.2711348627896106,54.67918443468305,294.387957363555,0.08194564103406084
0.0857991371613658,271.245505613157,0.27241226048733636,54.68309393161245,294.5181359536642,0.08231624783183933
0.0862045242200419,271.215336733544,0.273699364398633,54.67701188548247,294.59532579783763,0.0826895317913384
0.0865989019260524,271.280142951415,0.27495151361521636,54.69007681900526,294.77270544535,0.08305254457527979
0.0870064347484462,271.291495142471,0.27624543032631665,54.692365420722155,294.8956009123928,0.08342752785333214
0.0874160343020265,271.282781188261,0.27754590890893416,54.69060868755342,294.9972460941632,0.08380427116265217
0.0878212221572977,271.260777755741,0.27883238034942015,54.68617279555739,295.08323078158924,0.08417681706195972
0.0882266281124546,271.229402242558,0.28011954425704333,54.6798474920997,295.15905784737555,0.08454942464023259
0.0886328324017561,271.243747751366,0.28140924287557556,54.68273954667539,295.28484938583705,0.08492262677053466
0.0890372645746045,271.266635465773,0.28269331502436923,54.68735370989984,295.41947465800183,0.08529406244213596
0.089449592466721,271.234006269811,0.28400245608183916,54.6807756639939,295.4957775937616,0.0856726076655854
0.0898597235398944,271.25657962862,0.2853046222391647,54.68532645312979,295.6316208824251,0.08604899395917202
0.0902660122856317,271.263990905028,0.2865945890068807,54.68682056645365,295.74990964071077,0.08642171443466065
0.0906756349120088,271.255285843801,0.28789514084562795,54.68506562611028,295.8515311109261,0.08679735275741904
0.0910846325912666,271.247684303132,0.28919370847727144,54.68353315551141,295.9541799691147,0.08717227725314917
0.0914867196851096,271.209361149664,0.29047033500022296,54.675807207772266,296.021415949141,0.08754072990233522
0.0918846059325107,271.160629327985,0.29173362383572143,54.66598287252178,296.0761168981985,0.08790519951603502
0.0922863008108099,271.110936334307,0.29300900507432137,54.65596476499629,296.13076175795516,0.08827302318916239
0.0926966287302866,271.123281803316,0.29431179621865994,54.6584536115485,296.25549599677487,0.08864861232421027
0.0930996719960152,271.150715337733,0.29559145858734825,54.66398421208697,296.3947579971608,0.08901739624992415
0.0935047625891106,271.178417850725,0.29687762122042616,54.66956903870616,296.5348914311477,0.08938791648789918
0.093910718301799,271.142826090015,0.29816653060821185,54.662393739747024,296.60604365050807,0.08975909034206236
0.0943210908653077,271.144170238009,0.29946946349735193,54.662664719982615,296.71878415662667,0.09013416264162429
0.0947319528927069,271.106153307239,0.3007739504343444,54.65500050673939,296.78856865126335,0.0905095414232352
0.0951453649713836,271.146691786737,0.3020865337841429,54.66317306420618,296.94504273756934,0.09088710785603535
0.0955553411284315,271.150988101528,0.30338820808277,54.664039201268054,297.0609132668808,0.09126139555375014
0.0959750404091989,271.164777091931,0.30472075329920645,54.666819061733285,297.18982753088045,0.09164441491723596
0.0963998901142756,271.176290755262,0.306069651112825,54.66914021626082,297.3176553856661,0.09203198522236929
0.0968233489633841,271.195878944421,0.3074141329587445,54.673089195195274,297.45397216888836,0.0924181372992081
0.0972508875815938,271.250179279319,0.3087715680715603,54.68403614271071,297.62949997089925,0.09280785850052381
0.0976791369934177,271.256164075419,0.3101312599541012,54.68524267760448,297.7522320864509,0.0931980754208477
0.0980972294679658,271.246191148244,0.3114587035607914,54.683232135485994,297.854691003625,0.09357889059491252
0.0985152261510364,271.185795485809,0.31278584302954054,54.671056369939095,297.90172545704223,0.09395947360312293
0.0989323769927222,271.095317046094,0.31411029695189296,54.65281591649256,297.9154211530597,0.0943391421295532
0.0993622908376769,271.018452868641,0.31547527340962417,54.637320098318035,297.9474672049522,0.09473027609055218
0.0997822380292554,270.978882979563,0.3168086057428859,54.6293428086799,298.01776238193156,0.09511219477863345
0.100206199519075,270.950540566936,0.31815468347306314,54.6236289782943,298.10146449478765,0.0954976163452489
0.100615677383821,270.950271877192,0.3194547756936317,54.62357481044191,298.2121170194461,0.09586972993950951
0.101044042861526,270.911897600465,0.32081483608534506,54.61583855625375,298.28593099330374,0.09625885953948482
0.101468510485224,270.847104927294,0.32216252079058616,54.60277635334248,298.3295572335017,0.09664429900343523
0.101891589891281,270.808325525721,0.32350579790481715,54.594958425985354,298.40141636933225,0.09702833011227145
0.102316303377182,270.820480882485,0.32485426322255284,54.59740894590898,298.5298313652117,0.09741369620451198
0.102723559177233,270.830312525221,0.3261473003877148,54.599391005084556,298.6509661608941,0.09778308254677058
0.103151633709017,270.832556035172,0.32750643702612897,54.59984329669067,298.7693766517889,0.0981712047202627
0.103578594805176,270.773566497992,0.3288620385064338,54.587951005995194,298.8199120262399,0.09855816738200514
0.104009503805173,270.726048257053,0.3302301745814243,54.57837132862188,298.88413020340437,0.09894855633702886
0.104442374050411,270.691114774812,0.33160453761005493,54.5713287386021,298.9627374362456,0.09934056872826266
0.104874675180548,270.683330935562,0.33297709369823986,54.5697595166093,299.0711573442179,0.0997319124114201
0.105293147352387,270.630967447068,0.3343057428438287,54.559203037328906,299.12655378059117,0.10011059150770707
0.105715135428028,270.556024260663,0.3356455549839889,54.544094490949654,299.1578910062478,0.10049230702098781
0.106137927070496,270.428397179895,0.3369879184488248,54.51836487146683,299.13110667756587,0.10087460334508434
0.10656286713738,270.390923618075,0.3383371031611815,54.51081020140393,299.2045556867414,0.10125869510590478
0.106995453380004,270.39606272936,0.3397105644815127,54.511846246238974,299.32721205325583,0.10164954656359745
0.107422746237566,270.405644684456,0.34106721930427203,54.51377796838633,299.45336163459973,0.10203546541392042
0.107862610584309,270.452453523667,0.34246378860518106,54.52321463037127,299.6241611996612,0.10243258296915457
0.10829400430703,270.39221285759,0.3438334636748202,54.51107011209014,299.6740683213772,0.10282189997434364
0.108721557698573,270.314360798781,0.34519094569296926,54.49537513703425,299.70335917311854,0.10320760172959578
0.10915165668644,270.282616948824,0.346556509979447,54.48897557688292,299.78441236233465,0.10359544986308608
0.109596843299485,270.260736087472,0.3479699774758649,54.484564395234365,299.88045963045414,0.10399674511491114
0.11005083434531,270.227811842049,0.34941139904635926,54.47792686735708,299.9666079985739,0.104405810983092
0.110489150508512,270.211095129155,0.3508030528645256,54.47455677803765,300.06648948795004,0.1048005943888262
0.110932770269594,270.135724805867,0.3522115456059609,54.4593621208628,300.1026291073665,0.10519999601787274
0.111371530169387,270.003443182654,0.3536046082878037,54.432694145623046,300.0741398009093,0.10559486534824065
0.11181015899322,269.935716767126,0.3549972548034735,54.419040500252606,300.1172721768072,0.10598946092417831
0.112262090701234,269.851526944343,0.35643213797641793,54.40206783197955,300.1456235380353,0.10639586113379025
0.112707238455451,269.813805063035,0.3578454820960569,54.39446310070785,300.22377392884704,0.10679599946767482
0.113155002618662,269.76217718397,0.3592671333142518,54.38405492028835,300.2871170496381,0.10719832820212054
0.113605044152519,269.653323649382,0.3606960151842478,54.36211004771542,300.2873013884435,0.10760254017874282
0.114048831517129,269.563894125779,0.36210504006688454,54.344081055757044,300.30734127003115,0.10800097494037983
0.114499047892578,269.515104872143,0.36353447705893516,54.334245142224034,300.37432777267173,0.10840501955232965
0.114957049457115,269.467447170966,0.36498863202634013,54.324637349666745,300.44462982248126,0.10881588350387764
0.115413926752003,269.431886330479,0.3664392174376095,54.31746828422457,300.5280783240789,0.10922557077666911
0.115863405631457,269.309444650121,0.367866312879876,54.292784041464394,300.51255407600036,0.10962846008048668
0.116308519190142,269.161189053033,0.3692795484287008,54.26289571309146,300.46692837524915,0.11002727664083788
0.116742562242965,268.988435594499,0.37065763512141386,54.228068615851,300.39083477952755,0.11041602104699852
0.117186756409845,268.800188200829,0.37206795160125783,54.19011794128713,300.30001037844,0.11081370074888092
0.117627320606189,268.690866986471,0.37346674292465004,54.168078784472556,300.29625374144354,0.11120797444402386
0.118073895398397,268.639384465897,0.37488461788991045,54.157699908324844,300.3586830472131,0.11160746861162586
0.118516847541502,268.578816173153,0.3762909909442688,54.14548934050764,300.4099307824236,0.11200356445552971
0.118972566955273,268.510602604498,0.37773790008299174,54.1317374850668,300.45599825106234,0.11241091335034017
0.119412652541785,268.407430531633,0.37913517182016737,54.11093799517721,300.45867377334014,0.11280413037871319
0.119876264749011,268.309046259164,0.3806071405781099,54.09110372584746,300.4729325230822,0.11321820130120146
0.120333320786779,268.212877631961,0.3820582934980233,54.07171613060335,300.4878238751929,0.11362624887591116
0.120810290519198,268.053670408158,0.38357267239845366,54.03961995428465,300.4373122049049,0.11405189740393437
0.121263061237867,267.915603009276,0.3850102194302277,54.01178556667005,300.4038691835699,0.11445578314163225
0.121723441622792,267.773793579361,0.38647192715236456,53.983196785599176,300.36814131023186,0.11486628975039068
0.122167962220678,267.600048940706,0.3878832800506526,53.948169866446335,300.2922016099458,0.11526249484564585
0.122648552456131,267.519865627834,0.3894091540482159,53.932004910571344,300.33078990034653,0.11569067259616873
0.123113936753187,267.381291480856,0.39088674919136873,53.90406836254058,300.2996548892156,0.11610512809264617
0.123581880071304,267.201488895603,0.3923724692263902,53.86782016135356,300.2227512511733,0.11652168944588262
0.124030110061205,266.991369244734,0.39379559944432585,53.82546003973838,300.10633815755017,0.11692053942337946
0.124487441373162,266.802464925545,0.39524762635978933,53.78737692898987,300.0160211361789,0.11732732416737379
0.124939335873423,266.590833011272,0.396682391398118,53.74471193507244,299.89851463764296,0.11772911053438175
0.12540403020104,266.404535583058,0.39815779588830197,53.7071543735445,299.8127380090099,0.11814210913826392
0.125857625292691,266.205502306621,0.39959796030429395,53.66702926501479,299.7094946667803,0.11854507882122571
0.126315580351773,265.978952555385,0.4010519676168793,53.621356835165614,299.57623830877515,0.11895175719236155
0.126782710914202,265.834463266417,0.4025351071525914,53.592227794509675,299.53767717375524,0.11936641337574519
0.127251931961541,265.67475879557,0.40402488397789266,53.56003137318692,299.4823851257227,0.11978275218899263
0.127733397742471,265.520051741124,0.4055535378323454,53.5288424310106,299.4358301187745,0.12020977562183192
0.128205036089619,265.337192538312,0.4070509895845403,53.49197801572371,299.3547568836045,0.12062790614077368
0.128685243541596,265.108444654149,0.40857564824456727,53.44586244227645,299.2239894194019,0.12105345404051668
0.12914914369909,264.843936148983,0.4100485312446107,53.39253752763498,299.0483037165206,0.12146437892202558
0.129612852045544,264.382866161001,0.4115208052446022,53.29958581805781,298.65028347610365,0.1218749652111893
0.130060881237242,264.09970818579,0.4129432979282433,53.24250117025527,298.44874896693227,0.12227150847402396
0.130507287314511,263.704723302847,0.4143606372235724,53.16287221785396,298.1201113931253,0.12266645881375013
0.1309719187074,263.428783162631,0.41583584189599493,53.107242685586414,297.93055633619645,0.1230773680966562
0.131441777978734,263.206691624107,0.4173276450824804,53.06246903141998,297.80304714708,0.12349272915885039
0.13192225189901,262.906143562261,0.4188531497793567,53.001878542151815,297.58931405907884,0.12391729535425756
0.132409011359752,262.775762879077,0.42039861106721255,52.97559379642192,297.5696418512002,0.12434723197716976
0.132898036643035,262.482341761365,0.42195126634163616,52.916440099091176,297.3657296349165,0.12477898385937992
0.133397083804975,262.09429018352,0.4235357410807956,52.838208900997635,297.05690417593644,0.12521939178816505
0.133896139783744,261.619467993207,0.4251202438133872,52.74248474743054,296.6493048497742,0.12565961361888053
0.13438446535187,261.099272306572,0.4266706774921873,52.63761329700492,296.186958419253,0.12609018254810794
0.134865316085967,260.570450729074,0.4281973785729452,52.531002866981325,295.7123669293135,0.12651397965076908
0.135346433812522,260.101757781251,0.42972492735475737,52.43651436870021,295.3056031253118,0.1269378323894217
0.135837933449708,259.615779547194,0.4312854387028228,52.338541156714314,294.8814505318198,0.12737064590464586
0.136336179893529,259.168246308092,0.43286737116195456,52.24831845571135,294.5022549594425,0.12780920952429198
0.136839155685655,258.593774563647,0.43446431930195456,52.13250495203124,293.97952834050307,0.12825174098454659
0.137343198726555,258.072054102623,0.43606465595681215,52.0273261070888,293.5164955150098,0.12869501506780157
0.1378436823572,257.43282965023,0.43765369148410993,51.89845845748638,292.9183188488515,0.12913496454437315
0.138344714978433,256.772684763603,0.4392444700565248,51.76537324834237,292.2958286514707,0.12957520282158383
0.138840731316416,256.081684671789,0.44081932192962076,51.62606762983266,291.63625304836,0.13001084265639365
0.139329581657856,255.340989929314,0.44237142176369276,51.4767435697497,290.9175432362681,0.13044000315081228
0.139804677353469,254.562182044618,0.44387985059726404,51.31973590019499,290.1511657717608,0.13085691207192215
0.140313418682245,253.805873775368,0.4454951043161279,51.167264153114196,289.41824360642426,0.13130315328907913
0.140832748059346,252.978624314722,0.4471439750884236,51.000490661847955,288.6062991772372,0.13175847648900815
0.141352744859736,252.104937665608,0.4487949649296618,50.82435543338657,287.74066259733434,0.1322141772293748
0.141866656540007,251.11255229447,0.4504266345145222,50.62429054256515,286.73705050371416,0.13266434131665839
0.142365608566335,249.988843477388,0.45201080719811365,50.39775084504142,285.5786573138406,0.13310120760375652
0.142887248773057,248.829259449018,0.45366701485445593,50.16397870492203,284.38378774592536,0.13355773495398532
0.143449620237912,247.647137785794,0.4554525442553706,49.92566297761608,283.17202565417205,0.13404967600066034
0.144020560449897,246.416099767663,0.45726527942842293,49.67748571316087,281.90508456007956,0.13454886521734274
0.144613817273631,244.957130758197,0.45914886984377845,49.38335756085252,280.38131650553584,0.13506730262507938
0.145231647427949,243.340845401443,0.46111048058373805,49.057514432930915,278.6816372656044,0.13560692870800442
0.145879645945709,241.472320148825,0.4631678758776261,48.68081974200312,276.6982167178245,0.13617259178767482
0.146638375254593,239.459903398213,0.4655768414333328,48.27511652507974,274.57391457114875,0.13683450966973265
0.147306851790235,237.683174766296,0.4676992544339961,47.916928032885274,272.69553496462726,0.1374173279050445
0.147769031612074,236.479179689278,0.4691666753683349,47.67420262535845,271.4234790683803,0.13782008568000892