File: example/data/02 processed data/test_ID_082.csv
Strain,Stress_MPa,Displacement(mm),Force(kN),True Stress (MPa),True Strain
0.000558242918370003,36.4292608004567,0.0017724212658247595,14.688277954744143,36.44959717732001,0.0005580871587570718
0.000646593607510329,42.5915873102486,0.0020529347038452947,17.17292800349224,42.619126758337124,0.0006463846559300865
0.000734888681360929,48.9394886754054,0.0023332715633209494,19.732401833923458,48.97545375170455,0.0007346187828960838
0.000824931766354629,55.3361995960319,0.0026191583581759467,22.311555677120065,55.381848184908016,0.000824591697154844
0.000935050798304829,61.8767486433341,0.002968786284617832,24.94870505299231,61.93460654654956,0.000934613910627336
0.0010336318965716291,68.5002100695586,0.0032817812716149225,27.619284700046027,68.57101407160836,0.0010330980669466525
0.001136117102604329,75.2323223460231,0.0036071718007687444,30.333672369916513,75.31779507410906,0.0011354722099717071
0.0012520086144016292,82.0074645910808,0.003975127350725172,33.06540972312378,82.11013864319408,0.0012512255051879025
0.0013447140491141289,88.7861735372194,0.004269467105937359,35.79858517020686,88.90556555214198,0.0013438107308895854
0.001434107761900429,95.5581595703871,0.004553292144033862,38.52904993878008,95.69520026873992,0.0014330804114676032
0.001539461606949829,102.249879519597,0.004887790602065707,41.22715142230151,102.40728928343266,0.0015382778506725938
0.001645745648845629,108.964718625063,0.0052252424350848715,43.9345745496254,109.14404683661789,0.0016443928934661428
0.001771310291409529,115.590404178709,0.005623910175225255,46.60605096485547,115.79515065121892,0.0017697433713966904
0.001885710779457729,122.167097092043,0.005987131724778289,49.25777354751173,122.3974689039245,0.0018839350588656346
0.0020010847841112293,128.704896858146,0.0063534441895531524,51.89381441320447,128.96244626888944,0.0019990852809604843
0.002111450205229429,135.170923710138,0.006703854401603437,54.50091643992764,135.45633038474682,0.0021092242270556063
0.0022173815339495287,141.624283449291,0.007040186370289753,57.10291108675413,141.93831852017027,0.0022149267716092933
0.002323562981090029,147.972113434166,0.007377312464960842,59.66235613665574,148.31593595917528,0.0023208676829490557
0.002424252548227029,154.217221531817,0.007697001840620816,62.180383721628615,154.59108302409598,0.0024213187885111956
0.0025279934938931287,160.368876018169,0.008026379343110684,64.66073081052575,160.77428749336588,0.002524803493409769
0.002646107833224629,166.472860380865,0.008401392370488196,67.12185730556477,166.91336552073813,0.0026426130535771955
0.002749483423825929,172.53965052145,0.008729609870647324,69.56798709024865,173.01404543051146,0.00274571050840706
0.002856518931595829,178.554463475125,0.009069447607816757,71.99315967317041,179.06450768036265,0.0028524468342316024
0.002969770915100629,184.480357285103,0.009429022655444496,74.38248005735353,185.02822168457567,0.0029653698567269947
0.003068056411651229,190.30546296165,0.009741079106992652,76.73116266613728,190.88933085746174,0.0030633595309896918
0.0031755615769019294,196.017963258863,0.010082408006663626,79.03444278597357,196.64043037137046,0.003170530130202863
0.003297524041527029,201.653112822058,0.010469638831848316,81.3065350898538,202.31806880963748,0.003292099131700375
0.003409427498730729,207.253520277212,0.010824932308470064,83.56461937577187,207.96013612845385,0.003403628577725159
0.003538765372205429,212.827022703757,0.011235580056752237,85.81185555415483,213.58016760197063,0.003532518674752363
0.003661934724870329,218.336345829498,0.011626642751463294,88.0332146384536,219.13587927599232,0.0036552461656440484
0.0037795947678506293,223.651506241568,0.012000213387925748,90.17628731660021,224.49681830438055,0.0037724700462767103
0.003914663910446629,228.800310951366,0.012429057915668047,92.25228537559076,229.69598727134627,0.003907021552030939
0.004069974890178929,233.705076537441,0.0129221702763181,94.22988685989621,234.65625033065572,0.004061714946632602
0.004253016051116729,238.37505262594,0.013503325962295613,96.112821218779,239.3888655509439,0.0042439975398910175
0.004483437720994729,242.750588997389,0.014234914764158264,97.87703748374724,243.8389461448936,0.004473417054288773
0.004755969838161929,246.604182765988,0.015100204236164124,99.43080649124637,247.7770248211876,0.004744695945010386
0.005075588069980129,249.79252759059,0.016114992122186908,100.7163471245259,251.060371563599,0.005062750692688223
0.005422921836301029,252.127423380718,0.017217776830255768,101.6577771071055,253.49469069049962,0.005408270739646728
0.005787059581369329,253.71378850794,0.01837391417084762,102.2973995264014,255.18204531865038,0.0057703788759542836
0.00616520227003953,254.713923439874,0.019574517207375505,102.7006539309572,256.2842862988762,0.006146275163647314
0.006547262304787529,255.373977765927,0.020787557817700406,102.96678783522177,257.0459781841775,0.006525922079002973
0.00693807407958253,255.856449887214,0.02202838520267453,103.1613205945247,257.63160089027053,0.006914116393250736
0.0073335539286679295,256.240170906248,0.023284033723520677,103.31603690939919,258.11932201828006,0.007306794171826325
0.0077253832060670295,256.57000624993,0.024528091679262818,103.44902651997177,258.5521078673937,0.007695695235826829
0.00811681786714303,256.857061690545,0.025770896728179116,103.56476727362774,258.9419236781767,0.008084053675577135
0.008502540359289629,257.100457308004,0.02699556564074457,103.66290438658721,259.28646432265714,0.00846659735718646
0.00888971888061183,257.350513435277,0.028224857445942556,103.76372701710369,259.63828715349774,0.008850437955664701
0.00927336329636103,257.565222671198,0.029442928465946268,103.85029778102704,259.95371855353613,0.00923062964954563
0.00965154055069793,257.781276890854,0.030643641248465928,103.93741084239232,260.2692633379767,0.009605261968003057
0.01002835816863233,258.000374016514,0.03184003718540764,104.02575080345845,260.58769417479266,0.009978407853690795
0.01040424589924663,258.197429467474,0.03303348073010805,104.10520356128552,260.883779014207,0.010350494241719098
0.010773837029466929,258.40902962546,0.034206932568557495,104.19052074498548,261.1930863975874,0.0107162127674259
0.011149270998917429,258.615484887458,0.03539893542156283,104.27376350662307,261.4988590129847,0.011087576022808224
0.011521365026160529,258.845765182784,0.03658033395805968,104.36661252169851,261.8280217289307,0.011455499524354512
0.01189497447981823,259.05410907032,0.03776654397342288,104.45061677715303,262.1355510866035,0.011824785321458196
0.01226091457829933,259.236570674599,0.03892840378610037,104.52418529599832,262.41504812321153,0.012186358364765702
0.012628113695924129,259.444073332652,0.04009426098455911,104.60785036772529,262.7203625884304,0.012549044039410241
0.012994696061276529,259.622425192521,0.04125815999455298,104.67976183762447,262.99613969858933,0.01291098938045664
0.01337502042531993,259.827274179809,0.04246568985039077,104.76235694929899,263.3024692790192,0.013286364481470999
0.01375125841781423,260.034089788493,0.04366024547656018,104.84574500272038,263.60988575461573,0.013657567795977127
0.014124889278297829,260.225178523983,0.044846523458595605,104.92279198086996,263.9008303580596,0.014026062553545006
0.01449753867547713,260.409258809199,0.04602968529463988,104.99701315186904,264.1845521102377,0.01439345413537489
0.01486767067784593,260.577160841625,0.04720485440216082,105.06471125134321,264.4513362551864,0.01475823027795096
0.015233260056339829,260.779763654964,0.048365600678878955,105.14640070568149,264.7522896121509,0.015118398954208656
0.01559962916029853,260.97677336302,0.04952882258394783,105.22583501996968,265.0479142469344,0.01547920570485613
0.01596414909465483,261.163008174625,0.05068617337552908,105.30092489600881,265.3322533751333,0.015838062209554638
0.01632954005270853,261.353717104903,0.051846289667349575,105.3778187366969,265.6215030962918,0.016197647011635168
0.01668989351716553,261.545528798265,0.05299041191700055,105.45515721146046,265.91069582379885,0.01655214777270071
0.017053087638119628,261.746648266905,0.05414355325102982,105.53624858121611,266.21023679878465,0.016909315938177356
0.01740036103378493,261.913307994508,0.05524614628226715,105.60344578338561,266.47069411316534,0.017250708265698904
0.01774052439908213,262.079292706943,0.05632616496708576,105.67037081943943,266.7287167937047,0.01758499801526824
0.01807544345583293,262.269589142329,0.05738953297226955,105.74709834218706,267.0102282710557,0.017914024867459962
0.018416628091491128,262.457175359145,0.05847279419048433,105.82273310480727,267.29075154767764,0.01824909579026589
0.01876265593152893,262.664745596354,0.05957143258260435,105.90642542444994,267.593033843321,0.018588808496044485
0.01911571909540243,262.858717639107,0.060692408127902706,105.98463495208794,267.88345104727387,0.01893530922124218
0.01947028857253693,263.026512965048,0.06181816621780475,106.05229002750737,268.1477150747056,0.01928316747139817
0.01981759618951633,263.236472363221,0.06292086790171435,106.13694565685071,268.4531864748681,0.019623784039497816
0.020172659573289328,263.394995612111,0.06404819414519361,106.20086223080317,268.7083731919022,0.01997188706239746
0.02052596756582233,263.565634923886,0.06516994702148589,106.26966400131084,268.97557459779904,0.020318148868393008
0.02087455937483843,263.764637149516,0.066276726015112,106.34990169868485,269.2706077286763,0.020659671081015248
0.02122346458944743,263.947114362671,0.06738450007149559,106.42347651102895,269.54898659783396,0.021001383588357653
0.021577798967882828,264.140599084975,0.06850951172302798,106.50148955106194,269.84017183128674,0.02134829387112507
0.021936406831872028,264.322400927114,0.06964809169119368,106.57479205381239,270.12068464862836,0.021699265610545693
0.022290231677780128,264.500897148872,0.0707714855769519,106.64676173042521,270.3966834253011,0.02204543549481996
0.02263970238203183,264.681932732659,0.07188105506295106,106.7197552778081,270.67425291562733,0.022387227848516756
0.02298612530796463,264.854224239974,0.07298094785278769,106.7892232135575,270.94219662669775,0.022725924128701835
0.02332466484557903,265.057868416092,0.07405581088471341,106.8713325453683,271.2402543615809,0.023056802060179217
0.02365985320542093,265.232375833927,0.07512003392721145,106.94169393623937,271.5077349114827,0.023384296831030625
0.02398785827333183,265.436831558401,0.07616145001782855,107.0241304843473,271.8040926543462,0.02370466939207015
0.02432291606503063,265.607604637439,0.07722525850647224,107.0929861898154,272.06795611126927,0.02403182462543108
0.02465413551373333,265.77800248879,0.07827688025610333,107.16169060348012,272.3305293787179,0.024355126881386024
0.02499799511981373,265.979938325937,0.07936863450540858,107.24311113301779,272.6289035261771,0.024690656607789126
0.025328572149832928,266.116727111934,0.08041821657571954,107.29826437153179,272.857083834866,0.0250131194175295
0.02566749835191383,266.319186339784,0.0814943072673264,107.37989593220091,273.1549336162434,0.0253436185443105
0.02600886780259503,266.482720927675,0.08257815527323921,107.44583307803858,273.4136347879587,0.025676389793677763
0.02635399788928863,266.683378955869,0.0836739432984914,107.52673839500638,273.7115521619803,0.026012714422929514
0.02669779044474463,266.852447076512,0.0847654846620642,107.59490666124964,273.97681778822806,0.026347623226129782
0.027044913720578028,267.023083379737,0.08586760106283524,107.66370721870996,274.24469963114467,0.026685662921593755
0.02738031656502173,267.162525238024,0.08693250509394398,107.71993017597129,274.4775197533517,0.027012180375214617
0.02771784169029803,267.344186082673,0.08800414736669625,107.79317582853375,274.7543899093341,0.027340656294435682
0.028050331737022528,267.493922731012,0.08905980326504652,107.85354964514403,274.99721600125434,0.027664126668110273
0.02838558370490283,267.687894773765,0.09012422826306647,107.93175917278204,275.2863719176549,0.02799017813252297
0.028728593377189828,267.857703062482,0.0912132839725777,108.00022587479276,275.55287809671216,0.028323664410812733
0.02906224787964623,268.035302703901,0.09227263701787677,108.07183405021287,275.8250111115778,0.028647948588476305
0.02940540451094683,268.204719751679,0.09336215932225618,108.14014300387699,276.0913880277223,0.028981358379085245
0.02974036973938493,268.358484929745,0.09442567392254715,108.20214112367317,276.33956549425676,0.02930670225282309
0.03006923679616683,268.521588372968,0.09546982682782967,108.2679044319807,276.5958275986376,0.029626020172821843
0.03039449271492013,268.682782535175,0.09650251436987141,108.33289791818257,276.8492594115649,0.029941731550602056
0.03071951586972693,268.849288648788,0.097534462886383,108.40003318319133,277.1082086379992,0.03025711745952998
0.031050768696634028,268.993202797971,0.09858619061181303,108.4580593681419,277.3456485190175,0.030578446011247786
0.03138713316582643,269.135889296882,0.0996541478014989,108.51559056450282,277.5832932939463,0.030904627441361167
0.03173015378675933,269.310393285617,0.10074323827296086,108.58595057276078,277.8556534809423,0.031237153979006903
0.03206503371393233,269.455618726006,0.10180648204173515,108.64450547032563,278.09572222486383,0.03156168223853598
0.03240131818426623,269.642999617351,0.10287418523504528,108.72005744571592,278.3797882441128,0.03188746567695235
0.03274080320867263,269.779586879004,0.10395205018753559,108.77512942961441,278.61238724272647,0.03221624210734693
0.03307795363943493,269.918436344032,0.10502250280520589,108.83111353391371,278.84678586784867,0.03254265063920684
0.03341646598695853,270.100647446061,0.10609727950859332,108.90458105025178,279.1264565444977,0.032870270542107435
0.03375539902756143,270.247057042143,0.10717339191250753,108.96361339939207,279.3693542886247,0.03319819010155609
0.03409054581615653,270.427857797257,0.10823748296629698,109.03651226385402,279.6468910734594,0.03352234073991997
0.03442623930425093,270.5711194307,0.10930330979099669,109.09427535445825,279.88586553704033,0.03384691484389273
0.03476417069310943,270.706867031844,0.11037624195062243,109.14900878723951,280.1177667651359,0.034173546351781256
0.03510433149915723,270.851620615086,0.1114562525098242,109.20737343200268,280.35968569224195,0.03450222501784128
0.03544402315554293,271.008351512048,0.1125347735188488,109.27056732965777,280.61397779838654,0.03483034259951434
0.03578676242479693,271.164579253235,0.11362297069873023,109.33355835490434,280.86868162899054,0.03516129487655517
0.03612562990488343,271.33702858004,0.11469887494800489,109.40308992347212,281.13924965401327,0.035488400872312906
0.03645291746557743,271.471066645263,0.11573801295320835,109.45713407137006,281.36697903197506,0.03580422732321373
0.03679403932517543,271.61191162024,0.11682107485743198,109.51392276528077,281.60561097758114,0.036133297491684334
0.03712756332509673,271.735982940619,0.11788001355718211,109.56394832165759,281.82487785495425,0.036454933567387875
0.03747352672475023,271.879961466309,0.11897844735108198,109.6220004632158,282.0682624682408,0.03678845638728779
0.03781192811389283,272.028431159121,0.12005287176160973,109.68186344335759,282.31435064304475,0.03711458153923068
0.03813881641515103,272.168260036672,0.12109074211810451,109.73824244678616,282.5484353402417,0.03742951030603439
0.03846924370946563,272.332500711909,0.12213984877755338,109.80446428704172,282.80892605180367,0.03774774782369421
0.03880299787501833,272.425587943246,0.12319951825318318,109.84199705871679,282.9965174533084,0.03806908670431214
0.039142684009783726,272.587854168385,0.12427802173106332,109.90742280069283,283.2576744090031,0.03839603089804393
0.03947916646960123,272.707818364704,0.1253463535409839,109.95579236464866,283.4740957234859,0.03871978623880401
0.03980733472755253,272.860388760101,0.1263882877599793,110.01730874807272,283.7222335893644,0.03903544092178023
0.04014367388696393,273.007350813364,0.12745616459111048,110.07656384794836,283.96686887315957,0.03935885157996394
0.04047747089337213,273.112986449203,0.1285159700864565,110.11915613631865,284.16790940880253,0.03967971442432128
0.04082100625587643,273.254465516593,0.12960669486240767,110.17620049629029,284.408987762892,0.040009830810217674
0.04116587013331303,273.372736012318,0.13070163767326887,110.22388716016661,284.62636256098955,0.040341114243846926
0.04151015208849243,273.523929559228,0.13179473288096347,110.28484839828074,284.87794947507365,0.04067172923594547
0.041848332495726226,273.635490583408,0.13286845567393077,110.32982980323011,285.0866795759736,0.04099637851038038
0.04219387209682973,273.754557196538,0.1339655439074344,110.3778374616441,285.30532196881296,0.04132798369909346
0.04253850302178243,273.879994948702,0.13505974709415922,110.42841396331666,285.53043994143314,0.041658607363027664
0.04287822105584633,274.010588644382,0.13613835185231207,110.48106934141482,285.75967523591834,0.04198441086613243
0.04321961693228193,274.141389881507,0.13722228375999512,110.53380840022362,285.98967573746904,0.042311716588104314
0.04355859447825653,274.239253429071,0.1382985374684645,110.57326698260144,286.1847298592078,0.042636597830492964
0.04390059114569443,274.364875479204,0.13938437688757982,110.62391779321504,286.4096557023559,0.042964265717705355
0.04423999777831233,274.464840013903,0.14046199294614164,110.66422349360568,286.6071639263429,0.04328934597083308
0.04458184961533043,274.587628333153,0.1415473725286741,110.7137317439273,286.82925268573194,0.04361666142906306
0.04491554448137553,274.69664318563,0.14260685372836732,110.75768653244603,287.03479248151876,0.0439360634726595
0.045250199381911826,274.829237599609,0.14366938303757004,110.81114860016234,287.2653153969701,0.044256282004972995
0.04557938419851793,274.928674538104,0.14471454483029442,110.85124157376355,287.45975422206556,0.044571166414406574
0.04591087407244223,275.028601967349,0.14576702518000406,110.89153231323512,287.65540547859183,0.044888155580757434
0.04624487760018973,275.119143010808,0.1468274863806024,110.92803846195778,287.84199410481193,0.04520744684797596
0.04658958227030463,275.221895177634,0.1479219237082172,110.96946813562204,288.04436830560155,0.0455368610274933
0.04693450446958033,275.359149221378,0.14901705169091753,111.02480896605961,288.2829944412486,0.0458663745063029
0.04727718028201063,275.483112654496,0.15010504739538374,111.07479102229277,288.50717743611204,0.04619363446572702
0.04761616082156063,275.608453178726,0.151181310608455,111.12532832166232,288.73186960906577,0.04651726005167683
0.04795832912653433,275.697219695107,0.1522676949767465,111.16111898106715,288.91919769651537,0.04684382282446865
0.04829758347600363,275.790768366891,0.1533448275363115,111.19883780553045,289.11079602400207,0.047167499290105726
0.04864509185129333,275.88733466315,0.15444816662785632,111.23777333618207,289.30789939844743,0.04749894218795869
0.048992954492935926,275.973229146245,0.15555263051507157,111.27240599176598,289.49397300307555,0.04783061298830274
0.04933879255877703,276.072554590455,0.15665066637411706,111.31245401087146,289.6936410925651,0.04816024443905726
0.04968244428577263,276.187910092089,0.15774176060732809,111.35896534913029,289.9096005476432,0.0484876844134929
0.05003184180251413,276.289694265944,0.15885109772298237,111.40000472802862,290.1129765411227,0.04882048923582641
0.05038062975834793,276.396063049906,0.15995849948275467,111.4428926217221,290.3210707690883,0.04915260301229877
0.05072893089855783,276.470504855458,0.1610643556029211,111.47290755772066,290.49555799175994,0.049484143213649724
0.05108301183573723,276.569832920018,0.1621885625784657,111.51295663335124,290.69785296847914,0.049821072444405146
0.05141865236666813,276.624779804875,0.1632542212641713,111.5351112173256,290.84845319366804,0.050140349750575054
0.05176208089535533,276.718721917398,0.16434460684275315,111.57298867709487,291.0422587865457,0.050466929893030886
0.05210705232170433,276.807633232394,0.16543989112141125,111.60883771930125,291.2312630602815,0.05079486990031945
0.05246059771150573,276.87685573695,0.16656239773403067,111.63674823313825,291.40198108139276,0.05113084901994673
0.05280613471743053,277.000551861991,0.16765947772784193,111.68662251075479,291.6278803204179,0.05145910862116957
0.05315238078236223,277.087768861743,0.16875880898400006,111.72178840505478,291.8156434624175,0.05178793377655911
0.05349496365462583,277.192080589875,0.169846509603437,111.7638468938376,292.02046086638046,0.05211317366655606
0.05383463388384613,277.287966064142,0.17092496258121145,111.80250791706204,292.2156621976014,0.05243554396169982
0.05418108135722733,277.358795846258,0.17202493330919677,111.83106648521121,292.3863953291467,0.052764239306801644
0.05452912972327893,277.444994936983,0.1731299868714106,111.86582195859155,292.5738290569762,0.053094344759303455
0.05487593465721293,277.555935099902,0.17423109253665103,111.9105530322805,292.78707645816587,0.05342316253158915
0.05521929511745413,277.618760763345,0.17532126199791687,111.9358843397807,292.948673044078,0.0537486079981508
0.055565870614769426,277.691595905987,0.1764216392018929,111.96525146929396,293.1217711949079,0.05407699338388906
0.055915770975225626,277.715697467142,0.17753257284634136,111.97496921875165,293.24438480293975,0.05440841976881893
0.05624827614540323,277.82187795791,0.17858827676165526,112.0177811926293,293.44887966852104,0.05472326763622556
0.05660567876869633,277.917657162416,0.17972303009061083,112.05639936788613,293.6493747879004,0.05506158030177514
0.05695834908084243,278.034848769358,0.1808427583316747,112.10365102380514,293.8712547422024,0.055395301268608615
0.05733625169432213,278.106499740132,0.18204259912947277,112.13254069522122,294.05208400705914,0.05575277521511097
0.05769268439790413,278.157302185201,0.1831742729633456,112.15302424107304,294.20494363314424,0.05608982280899866
0.05805159653301923,278.226700948749,0.18431381899233604,112.1810058225356,294.3782051369388,0.05642910023660914
0.05840962034429773,278.262349245081,0.18545054459314528,112.19537921561667,294.5155474205985,0.05676742329383164
0.058765495779828626,278.324844631166,0.18658044910095586,112.22057735528614,294.6807421137603,0.057103602796577925
0.05911689375606353,278.376161861836,0.1876961376755017,112.24126846269228,294.8328958468429,0.057435441789333734
0.05946730689524703,278.434389489921,0.1888086993924093,112.26474584233614,294.99213277990884,0.05776624114323345
0.05982470141982593,278.516421495855,0.18994342700794734,112.29782114712874,295.1785832523629,0.05810351842882193
0.06018588384048673,278.587856675932,0.19109018119354537,112.32662381173579,295.35491305719984,0.05844425486350438
0.06055028026255293,278.673997019051,0.19224713983360553,112.36135559808137,295.54778564044034,0.058787905744571295
0.06091699012000133,278.73031795412,0.1934114436310042,112.38406419910118,295.7097299790759,0.05913361917246189
0.06127735671767403,278.779503109303,0.19455560757861504,112.40389565367097,295.86237416690767,0.05947323613701889
0.061634745561596926,278.822820038599,0.19569031715807023,112.42136103956311,296.00799360844496,0.059809932929048425
0.06199471398318003,278.873808787337,0.19683321689659658,112.44191970305428,296.162510800508,0.06014894539039174
0.06235870825966873,278.899931139968,0.1979888987244482,112.45245223563508,296.29177057956696,0.06049163251226117
0.06272499486491882,278.962951340155,0.19915185869611726,112.47786198035048,296.4609010304688,0.060836359271342566
0.06309287340519103,279.018751504873,0.2003198730614815,112.50036060676481,296.62284627124444,0.06118246469216469
0.06344451841343483,279.095934407073,0.20143634596265558,112.53148075293184,296.8030415566774,0.06151318543359338
0.06380553920115242,279.133909720012,0.20258258696365894,112.54679239910885,296.9441993390232,0.061852610307403015
0.06416637232002492,279.173136136976,0.20372823211607913,112.56260849042872,297.0866635320902,0.06219174365815562
0.06453891399639122,279.215620441889,0.20491105193854212,112.57973816216963,297.2358933560371,0.06254176080948642
0.06489793814362453,279.261878989329,0.20605095360600786,112.59838960849744,297.3853991378508,0.06287896184014803
0.06525729642982783,279.290784331863,0.20719191616470337,112.61004424260716,297.5165458351265,0.06321636287438244
0.06562240039764633,279.304090761641,0.20835112126252708,112.61540939509366,297.632695638302,0.06355904197722895
0.06599396941541882,279.36342150866,0.20953085289395476,112.63933155229172,297.7997226034893,0.06390766851885035
0.06636886345397904,279.435722002799,0.21072114146638343,112.66848311152857,297.9815532805668,0.06425929164474992
0.06674144572180232,279.482813773097,0.21190409016672238,112.68747051331272,298.13590081871075,0.06460862404449462
0.06711984364113073,279.559595794058,0.21310550356059005,112.71842902416418,298.32359215213285,0.0649632843264736
0.06749377843155863,279.581080191426,0.21429274652019864,112.72709153318296,298.4510636715219,0.06531363793650048
0.06787537374822424,279.634409171747,0.21550431165061193,112.7485937780484,298.6146992071432,0.06567104248206881
0.06825801058391893,279.64566173217,0.2167191836039426,112.75313081041095,298.7337182704315,0.06602929430528706
0.06864522541480493,279.683114851356,0.21794859069200564,112.76823190806674,298.8820253150421,0.06639170176351991
0.06903771672219362,279.717675669979,0.21919475059296475,112.78216683013552,299.02874532507343,0.06675891366764522
0.06942428883045614,279.752696521823,0.22042211703669823,112.79628723759903,299.17432852625296,0.06712045585214006
0.06981094264548093,279.7835318332,0.22164974289940195,112.80872003514625,299.31548392715763,0.06748194374608099
0.07019506839641512,279.791580465478,0.222869342158618,112.81196524368072,299.4315695929933,0.06784093877046662
0.07058099491989803,279.81776096724,0.22409465887067623,112.82252122199118,299.56757693256606,0.06820148701675613
0.07096670254037384,279.829083516895,0.22531928056568692,112.82708647401206,299.68763084898393,0.06856170091729512
0.07135807734871223,279.884207275394,0.22656189558216133,112.84931237343886,299.8562061868345,0.06892707484786473
0.07174459028928673,279.903214875641,0.22778907416848534,112.85697623785848,299.9847563475481,0.06928777893414292
0.07213301254188643,279.936863246248,0.22902231482048943,112.87054326088719,300.1295525137259,0.06965013381516476
0.07252144110211194,279.950403501849,0.2302555754992054,112.87600269194553,300.2528102009208,0.07001236332380448
0.07292062802688994,279.975731548676,0.23152299398537554,112.88621496042616,300.3917377254934,0.0703844888965509
0.07332678738412234,279.977950467747,0.23281254994458842,112.8871096285956,300.5078341139378,0.07076297215916502
0.07373543627192312,280.025258028742,0.23411001016335592,112.90618403718877,300.6730425966491,0.07114363079889406
0.07414525859109122,280.029339483074,0.23541119602671462,112.90782967957544,300.792187272139,0.07152523702601986
0.07455211271327083,280.062250095683,0.23670295786463488,112.92109923857939,300.9414825315486,0.07190393542485013
0.07496168478477493,280.098208822645,0.23800334919166038,112.93559779729047,301.0948424611882,0.07228501888375831
0.07537366210592643,280.11414344756,0.2393113771863164,112.9420226380562,301.22737224686745,0.07266819383996953
0.07579108816346133,280.131971485814,0.24063670491898972,112.9492109030802,301.3634784340996,0.07305628690696676
0.07620722706073253,280.130818224374,0.24195794591782577,112.94874590806762,301.4788110955077,0.07344303340162169
0.07662794947336213,280.135619207478,0.24329373957792474,112.95068166445513,301.60183728179766,0.0738338876784112
0.07705628658750713,280.165326506592,0.2446537099153351,112.9626596474579,301.75382619776644,0.07423165919256414
0.07747857596728043,280.185897679544,0.24599447869611535,112.97095394439214,301.8943020378692,0.07462365970508332
0.07792190443146653,280.197545104106,0.24740204656990622,112.97565018597554,302.03107143563966,0.0750350249937797
0.07836365908644183,280.203234450649,0.2488046175994528,112.97794413050167,302.160985190058,0.07544476168972539
0.07880993547719893,280.193007029478,0.2502215451401066,112.97382043428554,302.2749998346335,0.07585852199000774
0.07925246954127413,280.20270062707,0.2516265907935453,112.97772889283462,302.40945662389964,0.07626864365215151
0.07970139510160502,280.180225591728,0.2530519294475959,112.96866695858473,302.51098045127117,0.07668451688979037
0.08016049880038643,280.157530770464,0.2545095836912269,112.95951640665109,302.615098179709,0.07710964009511384
0.08063127065087904,280.154901168102,0.25600428431654093,112.95845615097873,302.7441468283575,0.07754538023870103
0.08110464559345162,280.156138458675,0.2575072497592089,112.95895502653777,302.8781027791958,0.0779833384060997
0.08158450380273663,280.179061088662,0.2590307995736888,112.96819743094854,303.03733076349715,0.07842709909847075
0.08205548473128073,280.12747714839,0.2605261640218163,112.94739878623086,303.1134730723519,0.07886245889814066
0.08253593748777363,280.10592376464,0.2620516015236813,112.93870846190286,303.2247287784334,0.0793063789464706
0.08301602528892733,280.069650191271,0.26357588029234424,112.92408295712049,303.31991935421064,0.07974976503673391
0.08351024623461273,280.056088487618,0.2651450317948954,112.91861487820759,303.4436413967215,0.0802059985574199
0.08401243641868864,280.047174945654,0.2667394856293364,112.9150209380877,303.57462042500913,0.08066937566261087
0.08453715842638562,279.975430548071,0.26840547800377434,112.88609359698223,303.64375787580883,0.08115331388490002
0.08506909730738144,279.921916477207,0.27009438395093605,112.86451672360987,303.73462122847525,0.08164366911894191
0.08560967775744763,279.831068399868,0.2718107268798962,112.82788677882678,303.78731599210295,0.08214174416113731
0.08614094609839673,279.705738923163,0.2734975038624096,112.77735393381933,303.79985590315545,0.08263099771143997
0.08666698569831133,279.590253261291,0.27516767959213845,112.73079011495254,303.8214977420746,0.08311520029786655
0.08719762925053773,279.440364195912,0.2768524728704573,112.67035484379174,303.80690147070237,0.08360340325136865
0.08772450213237543,279.274058830245,0.27852529427029193,112.6033005203548,303.7732365996159,0.08408790141757119
0.08824992616752973,279.086842196041,0.28019351558190686,112.52781477344374,303.7162354141707,0.0845708336051307
0.08877892833322823,278.836817124771,0.2818730974579996,112.42700466470768,303.59165092895654,0.08505681905729096
0.08930489877937273,278.568665004167,0.2835430536245084,112.31888572968013,303.4462114354691,0.08553978527725094
0.08984222165711282,278.232811217359,0.2852490537613332,112.18346948283914,303.2298651150306,0.08603293499035711
0.09037121409668283,277.868646260526,0.28692860475696796,112.0366381722441,302.97997318249145,0.08651820165395585
0.09091492311776743,277.405053002648,0.28865488089891156,111.84971737066768,302.625312068864,0.08701672316662581
0.09144665758379612,276.869181086884,0.2903431378285527,111.63365381423162,302.18794228524234,0.08750402507044695
0.09199180911196753,276.244142986624,0.2920739939304969,111.38163845220681,301.6563414565486,0.08800337648136555
0.09253137416202292,275.583815933868,0.2937871129644228,111.11539458453558,301.0839651190428,0.08849736534370291
0.09305584866752672,274.876864358085,0.2954523195193973,110.8303517091799,300.45576424999524,0.08897730456561355
0.09358901491417063,274.047540597319,0.29714512235249174,110.49596836883904,299.6953799614733,0.08946496149252446
0.09413447123547602,273.219379317743,0.2988769461726364,110.16205374091398,298.93874112110365,0.08996361348036565
0.09468248041852073,272.255040683405,0.3006168753288033,109.7732324035489,298.03282324175507,0.09046434899786164
0.09523231881499973,271.24501941256,0.3023626122376241,109.36599182714419,297.0763115782377,0.0909665040663834
0.09577262250872293,270.177848173113,0.3040780764651953,108.93570838339916,296.0534892364156,0.09145970578810034
0.09632680746507423,269.050409492303,0.30583761370161067,108.48112510729658,294.96717648586747,0.09196532607208942
0.09687016653728063,267.86901175016,0.30756277875586596,108.0047855376645,293.8175275285748,0.09246082108668603
0.09741848611196673,266.649102881974,0.30930369340549435,107.51291828201191,292.62565480784997,0.09296059087352501
0.09796256791996093,265.343546587669,0.3110311531458759,106.98651798414814,291.3372817923868,0.09345625135864595
0.09850593133425734,264.014138183083,0.312756331986267,106.45050051541907,290.0210967502189,0.09395101231293687
0.09907459939693233,262.613158841632,0.31456185308526013,105.88562564494603,288.63145235022967,0.09446855245985374
0.09964553796192553,261.170087633157,0.31637458302911353,105.3037793336889,287.1945215149261,0.09498788965800321
0.10020746238052503,259.684744675464,0.31815869305816696,104.7048890531471,285.7070939583268,0.0954987641852864
0.10077438824030913,258.137626847132,0.31995868266298144,104.08109114476363,284.151288274457,0.09601392142946084
0.10132707685873013,256.534747771138,0.32171346902646814,103.43481030132284,282.528663875479,0.09651588615614179
0.10189815537874013,254.854618213786,0.32352664332749986,102.75738206379853,280.8238336995239,0.09703428847329329
0.10245836975658613,253.130177093938,0.32530532397716094,102.06208740427579,279.0654823751788,0.0975425677679709
0.10302691549496312,251.345261347131,0.3271104566965079,101.34240937516321,277.2405883480013,0.0980581420542952
0.10359033779765213,249.520655543115,0.3288993225075455,100.60672831498398,275.36858453831786,0.09856880815562499
0.10418016148351013,247.680155826663,0.3307720127101446,99.86463882931052,273.48351445694567,0.09910312429046106
0.10478394704093313,245.779133362622,0.3326890318549627,99.0981465718092,271.5328410566574,0.09964979281271508
0.10541020379516713,243.842339073763,0.33467739704965566,98.31723111454123,269.5458097294186,0.10021649123670398