File: example/data/02 processed data/test_ID_076.csv
Strain,Stress_MPa,Displacement(mm),Force(kN),True Stress (MPa),True Strain
2.52759677044028e-05,0.19725495406488,8.025119746147889e-05,0.03976659873947981,0.19725993987472848,2.52756482725188e-05
3.78038552505427e-05,1.47853793811746,0.00012002724042047306,0.29807324832447996,1.4785938325516552,3.780314070292347e-05
6.59046004709985e-05,3.6320989602147,0.00020924710649542023,0.7322311503792835,3.632338332245544,6.590242885818697e-05
9.27733908043828e-05,7.54211315903313,0.00029455551580391537,1.5204900128610792,7.542812866444725,9.276908761961495e-05
0.0001138778502679,12.2485083229864,0.0003615621746005825,2.4692992779140583,12.249903156783208,0.00011387136667766998
0.0001469891893315,17.3486292774302,0.0004666906761275125,3.497483662329928,17.3511793383837,0.00014697838747913726
0.0001621314166901,22.5800967616731,0.0005147672479910674,4.552147507153298,22.583757704750074,0.00016211827481250814
0.0002123939999127,28.1100335148517,0.0006743509497228224,5.666982756594102,28.1160039173076,0.000212371447500472
0.0002567774671923,33.8651854639563,0.0008152684583355525,6.827221389533591,33.87388128050573,0.00025674450550081205
0.000327246866234,39.8498920480483,0.0010390088002929499,8.033738236886537,39.862932800340786,0.0003271933326571694
0.0004047206655182,45.8879484364465,0.0012849881130202851,9.251010404787614,45.90652023747696,0.00040463878820055585
0.0004890046310566,52.0041505422202,0.001552589703604705,10.484036749311592,52.029580812669515,0.0004888851072555543
0.0005927585571833,58.1179818144609,0.0018820084190569774,11.716585133795318,58.152431745507634,0.0005925829452232259
0.0006936288733258,64.3099485460434,0.002202271672809415,12.96488562688235,64.35455578319703,0.0006933884240007073
0.0007909110117225,70.5869880271185,0.0025111424622189372,14.23033678626709,70.64281605323347,0.000790598406426129
0.0008672210843821,76.786453171376,0.0027534269429131675,15.480148959349401,76.85304400256113,0.0008668452654405325
0.0009567252354875,82.9934292318019,0.0030376026226728125,16.731475333131264,83.0728311399276,0.0009562678655942562
0.0010567361508795,89.1364168568723,0.0033551372790424127,17.96990163834546,89.23061053092482,0.001056178198271112
0.0011516718327231,95.3088841647658,0.0036565580688958424,19.214271047616787,95.41864872206664,0.0011510091674511425
0.0012709627490277,101.47332418161,0.004035306728162947,20.457022155012577,101.60229299666483,0.0012701557595696626
0.001367804858162,107.646446000521,0.00434278042466435,21.701523513705034,107.79368533232439,0.00136687026522711
0.0014669341222325,113.780391645382,0.0046575158380881875,22.938126955709013,113.94729998432757,0.0014658592254463824
0.0015893076263224,119.819653538523,0.00504605171357362,24.15564215336624,120.01008382767509,0.001588046013507291
0.001684423820283,125.830816706347,0.005348045629398525,25.36749264799955,126.04276913133285,0.0016830067695328018
0.0017795946866718,131.781968664282,0.0056502131301829645,26.56724488271925,132.01648715551613,0.001778013084177057
0.0018611000117249,137.672564153408,0.005908992537226558,27.75478893332705,137.9287865641681,0.0018593703108629887
0.0019591910840642,143.515838234279,0.006220431691903835,28.93279298803064,143.7970131849696,0.0019572743722736955
0.0020569840700202,149.277186471946,0.006530924422314135,30.094280792744318,149.58424726653624,0.002054871374978656
0.0021562380109055,154.923301127701,0.006846055684624962,31.232537507344524,155.2573526383675,0.002153916666041417
0.0022564794235256,160.511187856003,0.00716432216969378,32.359055471770205,160.87337804864572,0.0022539373971331455
0.0023589802706417,166.061810152352,0.007489762359287397,33.478060926714164,166.45354668620843,0.0023562022446974936
0.0024548101249896,171.561594134149,0.007794022146841979,34.58681737744444,171.98274527248884,0.0024518020005251263
0.0025581688826486,176.979439785403,0.008122186202409305,35.67905506073725,177.4321830811306,0.0025549023383611563
0.002642876498118,182.218888908407,0.00839113288152465,36.73532800393485,182.70047092741618,0.0026393902411725244
0.0027540346507625,187.35248471866,0.008744060016170938,37.77026091928186,187.86845995348162,0.002750249245831775
0.0028434359961409,192.389881431368,0.009027909287747356,38.78580009656379,192.93692974552323,0.002839401078885164
0.0029385217663644,197.379186817884,0.009329806608206969,39.79164406248542,197.95918985457567,0.0029342127506392026
0.0030589716377863,202.276350264213,0.009712234949971503,40.77891221326534,202.89510788266614,0.003054302503455538
0.003170060055814,207.047005612567,0.01006494067720945,41.7406763314935,207.7033570547353,0.003165046009193282
0.0032845613846411,211.633421117396,0.010428482396235492,42.665297697267036,212.32854408009769,0.0032791789955342924
0.0034147679732462,216.052396287901,0.010841888315056685,43.55616309164084,216.790165091288,0.003408950891984241
0.0035271544119079,220.351356695805,0.011198715257807582,44.42283350987429,221.12856995574452,0.0035209485910962903
0.0036602331861389,224.470618790587,0.011621240365991006,45.253276748182344,225.29223359879742,0.003653550833665286
0.0037949380124154,228.364984690062,0.012048928189418894,46.0383809135165,229.23161565116695,0.0037877554011309556
0.0039685879829425,231.922051205763,0.012600266845842437,46.75548552308182,232.84245427115758,0.0039607339105139855
0.0041839055878525,234.932417265858,0.013283900241431687,47.36237532079697,235.91535231922433,0.004175177391698295
0.0044479188382399,237.252712971867,0.01412214231141168,47.83014693512839,238.30799378331807,0.004438056082254837
0.0047460199106435,238.831986233911,0.01506861321629311,48.14852842475646,239.9654875958757,0.004734793066019284
0.0050954709423305,239.729123690601,0.016178120241899335,48.32939133602517,240.95065647439682,0.0050825329617263095
0.0054470725235024,240.233036530405,0.01729445526212012,48.43098016452965,241.54160330292729,0.005432290877467757
0.0058021423015737,240.526691760635,0.018421801807496495,48.49018105894402,241.92226185355696,0.005785374701335037
0.0061851023209335,240.750195448052,0.01963769986896386,48.53523940232729,242.23926004068292,0.006166053082878429
0.0065712321602157,240.927194008231,0.020863662108684847,48.570922312059366,242.5103825337684,0.0065497357347764525
0.0069616451762613,241.079109252697,0.022103223434629626,48.601548425343715,242.75741647072343,0.006937524804756456
0.0073477077676189,241.211249802772,0.023328972162190008,48.62818796023883,242.98359957658488,0.007320844869790735
0.0077362568276972,241.307463180793,0.024562615427938608,48.64758457724787,243.17427969039974,0.0077064854403282035
0.0081218048455251,241.498996987112,0.02578673038454219,48.68619779260178,243.4604047110314,0.00808900048923883
0.0085001995741244,241.612861614225,0.02698813364784497,48.709152901427764,243.66661915762126,0.008464276304151985
0.0088831847600742,241.797525881878,0.028204111613235584,48.746381217786606,243.9454579788155,0.008843961388826102
0.0092469386199875,241.897002186973,0.029359030118460312,48.76643564089376,244.13380891855493,0.009204447424526734
0.0096196086744432,242.035591082463,0.030542257541357157,48.79437516222454,244.3638787539638,0.009573634837323123
0.0099927620269942,242.207338514771,0.031727019435706584,48.82899944457784,244.62765880974072,0.009943164517583201
0.0103713105471067,242.367415810157,0.03292891098706377,48.86127102732766,244.88108354602386,0.01031789749732772
0.0107535861409117,242.604258026955,0.034142635997394644,48.909018418234126,245.2131238137998,0.0106961775323616
0.0111315141878888,242.785874543928,0.035342557546546936,48.945632308055885,245.4884489510327,0.011070014850137058
0.0115021318100162,242.954179283179,0.036519268496801434,48.979562543488896,245.74867027708842,0.011436485196369646
0.0118808545397473,243.056647283242,0.03772171316369768,49.00022009230159,245.94436795453285,0.01181083126600531
0.0122533081335138,243.193703483098,0.03890425332390631,49.02785062219255,246.17363086800682,0.012178844024090717
0.012631100628983,243.379863420538,0.040103744497021025,49.06538046558046,246.45401896647093,0.012551993719172481
0.0129998901045655,243.529020433191,0.04127465108199546,49.09545051933131,246.694870936095,0.012916116781412697
0.0133546879577354,243.632845659971,0.042401134265809895,49.11638168505016,246.886486290015,0.013266300170476506
0.0137094214584596,243.716853916338,0.043527413130609226,49.133317749533745,247.05807098320693,0.013616297491920566
0.014057416383181,243.879362284953,0.044632297016599674,49.16607943664653,247.30767602785724,0.013959527217985249
0.0144228125677582,244.019854942275,0.045792429902632284,49.19440275636264,247.53930757291897,0.014319793178002197
0.0147914250784283,244.24192156801,0.04696277462400985,49.23917138811082,247.85460765189458,0.014683098843698833
0.0151620566721291,244.417239393781,0.04813952993400989,49.27451546178625,248.12310742911484,0.015048261495110635
0.0155236926198287,244.549138015804,0.04928772406795612,49.30110622398609,248.34544366480543,0.015404432755630677
0.0158725477008639,244.747658819313,0.050395338950242875,49.341128017973496,248.6324277085973,0.015747896111070858
0.0162249090682685,244.862023343835,0.05151408629175249,49.36418390611714,248.83488740686096,0.016094691851365972
0.0165564675443747,244.963653205999,0.05256678445338967,49.3846724863294,249.0193859798556,0.016420903497006915
0.0169031675653351,245.111973211561,0.05366755701993894,49.4145737994507,249.25514196702593,0.01676189873323743
0.0172486834315666,245.256303682015,0.05476456989522395,49.44367082229422,249.48665202382222,0.01710161365607872
0.017616732938351,245.432484006496,0.05593312707926442,49.47918877570959,249.75620253163453,0.01746335700071178
0.0179633952410128,245.613886623272,0.05703377989021564,49.51575954325163,250.02594594536714,0.017803959958280647
0.0183153537807245,245.82257515754,0.05815124825380028,49.55783115176007,250.3249025888391,0.018149647937773464
0.0186535749905032,246.008275260442,0.05922510059484765,49.59526829250511,250.59720907129702,0.01848173077724114
0.0190084641251093,246.184303846795,0.06035187359722203,49.630755655513866,250.86388935463182,0.018830060511399106
0.0193538285282513,246.325033456619,0.06144840557719788,49.6591267448544,251.09236591635417,0.019168925106463005
0.0196973383524109,246.448113739723,0.0625390492689046,49.68393972992816,251.30248562236775,0.01950585615850199
0.0200432952768232,246.577863957924,0.06363746250391365,49.71009737391748,251.520096893961,0.01984507274518561
0.0203933203147489,246.706359142042,0.06474879199932776,49.736002003035665,251.73752094771112,0.020188161120177888
0.0207490547112208,246.837112676718,0.06587824870812604,49.76236191562635,251.958749432407,0.02053672514435004
0.0211043403499388,246.981527263049,0.06700628061105568,49.79147589623068,252.19390947455605,0.020884728231312964
0.0214441256700669,247.144390365781,0.0680850990024624,49.824309097741455,252.44418573143685,0.021217435463395995
0.0217912092535967,247.277845381918,0.06918708938016953,49.85121362899468,252.66632865441395,0.021557174680838006
0.0221141043212736,247.41740265195,0.07021228122004368,49.87934837463312,252.88881690509376,0.02187313361319996
0.0224634770817174,247.556184430783,0.07132153973445274,49.90732678124585,253.11715710618128,0.022214889061388434
0.0228272718332099,247.669904847711,0.07247658807044143,49.93025281729854,253.32353309057493,0.022570627975791714
0.0231703779255922,247.731951219191,0.07356594991375523,49.942761365788904,253.47199415318403,0.022906020438866286
0.0235024077600223,247.821385894648,0.0746201446380708,49.96079139636104,253.64578515759786,0.023230478593257223
0.0238355167294415,247.916574002387,0.07567776561597676,49.97998131888122,253.8257936495267,0.023555885521321283
0.024147277043139,248.032268371945,0.07666760461196633,50.00330530378412,254.02157227196057,0.023860341512898627
0.0245056310125578,248.189041401188,0.07780537846487101,50.034910746479504,254.27107047112594,0.02421018503364785
0.0248512433866403,248.336686395818,0.07890269775258295,50.06467597739691,254.50816183127225,0.024547473654948058
0.0251950977181929,248.519161534449,0.07999443525526245,50.10146296534492,254.78062609415284,0.024882933715418568
0.0255267599028264,248.633537270114,0.08104746269147381,50.124521113654986,254.98034587979865,0.025206392683091425
0.025852907661451,248.752679922146,0.08208298182510691,50.148540272304636,255.18365998671175,0.025524371618468177
0.026196452186681,248.8624776185,0.08317373569271216,50.1706754878896,255.38179161449204,0.02585920228595761
0.0265385293573713,249.011748535714,0.08425983070965387,50.200768504799946,255.62015413455939,0.026192491460578057
0.0268809075981158,249.168857236899,0.08534688162401766,50.23244161895884,255.86674226461218,0.026525962779448
0.0272256147289854,249.27447165862,0.08644132676452863,50.2537334863778,256.06112238576895,0.026861590099996918
0.0275674982710661,249.351578956045,0.08752680701063487,50.26927831753868,256.22557817780336,0.02719435697864042
0.0279115742292999,249.413180225786,0.08861924817802717,50.281697133518456,256.37469471942376,0.027529146046601158
0.0282471007468997,249.52243332555,0.08968454487140654,50.303722558430884,256.57071863830834,0.027855508525004482
0.0285929483624447,249.630743186993,0.09078261105076192,50.32555782649779,256.7684221366174,0.02819179876687744
0.0289392869198781,249.74282596941,0.09188223597061296,50.34815371543306,256.97020526631997,0.028528453089726395
0.0292809615342448,249.850870010467,0.09296705287122724,50.36993539411014,257.1667437245411,0.028860462861529913
0.0296214125350259,249.938299975347,0.09404798479870723,50.38756127502996,257.3418254672198,0.029191174028967152
0.0299633967633074,249.983322840937,0.095133784723501,50.396637884732904,257.47367232743,0.029523264487083464
0.030299776267267,250.013224379341,0.09620178964857272,50.402666034875146,257.58856914189306,0.029849804815864522
0.030638627642652,250.086470633629,0.09727764276542009,50.41743247973961,257.7487768858378,0.03017863694184706
0.0309811330126042,250.154782353662,0.09836509731501833,50.43120412249826,257.9048609394998,0.03051090517058622
0.03131019633268,250.293959753356,0.09940987335625899,50.45926228627657,258.1307127741175,0.030830029164549765
0.0316483741149428,250.401722304274,0.10048358781494338,50.480987216541635,258.32652969078566,0.03115788624334558
0.0319918559219001,250.464479743269,0.1015741425520328,50.49363911624303,258.47730329276936,0.031490775479686164
0.0323437466375311,250.568764659196,0.10269139557416122,50.514662955293915,258.6730972986122,0.03183169942500113
0.0326765595928651,250.640595999463,0.10374807670734668,50.52914415349174,258.83066837103064,0.03215403326085871
0.03301136535847,250.717642572559,0.10481108501314224,50.54467674262789,258.99417427333606,0.03247819236010368
0.0333499834214028,250.80770547585,0.10588619736295389,50.56283342393136,259.1721382954297,0.03280593568163242
0.0336865955960535,250.927115062922,0.10695494101746986,50.58690639668508,259.37999531213103,0.03313163110574168
0.0340177611396722,251.039615371545,0.10800639161845922,50.60958645890348,259.5794210438494,0.03345195305638371
0.0343596212764162,251.158868584181,0.10909179755262144,50.633627906570894,259.7885921889466,0.03378251182458832
0.0346966111990023,251.214973098644,0.11016174055683231,50.644938576686634,259.9312813476155,0.03410825447022232
0.0350449446296896,251.285110377136,0.11126769919926448,50.65907825203061,260.09138315656816,0.03444485053748984
0.0353990735956727,251.364141968615,0.11239205866626083,50.67501102087278,260.2621997294751,0.03478693075440855
0.035748736982703,251.432036630919,0.11350223992008202,50.688698584793265,260.42041437746303,0.035124582551703275
0.0361012183098196,251.496012578936,0.11462136813367722,50.7015961359135,260.5753250330973,0.03546484013610684
0.0364490682461131,251.555521516722,0.11572579168140909,50.71359313777116,260.72448588817156,0.03580051347712663
0.0367907826887514,251.594989648951,0.11681073503678568,50.72154991322853,260.85136623870426,0.03613015642275935
0.0371351704959368,251.611465666616,0.11790416632459934,50.72487147838979,260.9551003428783,0.036462268386373085
0.0374791545677489,251.67226742359,0.11899631575260274,50.73712911259575,261.10473123477453,0.03679388093797706
0.0378101611533895,251.675338565818,0.12004726166201164,50.73774825486891,261.19122367532543,0.0371128789552077
0.0381411512304182,251.760189887171,0.12109815515657776,50.75485428125368,261.3626133634564,0.03743175934306553
0.0384816434691819,251.844036470464,0.12217921801465252,50.771757752445545,261.53540889176,0.03775968817316808
0.0388225562943856,251.927045562033,0.12326161623467427,50.78849238530586,261.70749747044323,0.03808791436970017
0.0391774183526464,251.968520634144,0.1243883032696523,50.79685375984344,261.83999677872526,0.038429456300441145
0.0395250506296752,252.016305447056,0.12549203574921874,50.80648717812649,261.97726267935457,0.03876392675540706
0.0398713988552645,252.080870190056,0.12659169136546478,50.819503430315294,262.1316871091859,0.03909705056051707
0.0402193419609986,252.166225576649,0.12769641072617055,50.83671107625244,262.3081852341306,0.039431596647523534
0.0405555358457004,252.252917237723,0.12876382631009878,50.85418811512496,262.48316946494,0.039754739618166855
0.0408928446815543,252.275861906862,0.12983478186393488,50.85881376042338,262.59213954472455,0.04007884935056518
0.0412289060395093,252.283820170229,0.13090177667544203,50.860418146318175,262.6852060873158,0.040401655988319865
0.0415782166576028,252.295105445111,0.1320108378878889,50.862693257734385,262.7850860009606,0.04073707890632518
0.0419324737651755,252.329676359712,0.13313560420443218,50.86966275411795,262.9104838938408,0.04107713678326795
0.0422650128081721,252.429952177574,0.13419141566594642,50.88987835899892,263.0989073395254,0.04139624190450599
0.042625993777269,252.541129700627,0.13533753024282907,50.91229174764641,263.30594632375045,0.04174252472846554
0.0429712715030751,252.653262480861,0.13643378702226344,50.93489771614158,263.51009441906376,0.04207363153869046
0.0433153821473167,252.72667441451,0.1375263383177305,50.949697561965216,263.67362689559496,0.042403510126333324
0.0436717771472875,252.740844975434,0.1386578924426378,50.95255434704749,263.77848683321827,0.042745050323979454
0.0440175985750571,252.738155642069,0.13975587547580628,50.95201217744111,263.8630823217219,0.043076346191031505
0.0443638208995199,252.749193690259,0.1408551313559757,50.95423744795621,263.9621136516317,0.043407916204445854
0.0446866597328712,252.728130683754,0.14188014465186605,50.949991145844805,264.0217066645435,0.043716993308052926
0.0450415502703024,252.779599164668,0.14300692210821012,50.96036719159707,264.1651841877503,0.0440566456505385
0.0453872265626259,252.836916727972,0.14410444433633723,50.971922412359156,264.3124831509002,0.04438736851400578
0.0457354711416777,252.902875723536,0.14521012087482668,50.98521974586486,264.4695078978371,0.044720438001179925
0.0461033220153335,252.949945931122,0.14637804739868385,50.99470909971419,264.6117787421457,0.045072138981820345
0.0464534556663879,252.982902441216,0.14748972174078157,51.00135313214914,264.73483248412316,0.045406785724079614
0.0467888747355933,252.994609264745,0.14855467728550872,51.0037132277726,264.83194234641354,0.0457272637377379
0.0471483081508546,253.042699120888,0.14969587837896334,51.01340814277103,264.9732342743636,0.04607057243078668
0.0474954264610925,253.092055852277,0.15079797901396869,51.02335845981905,265.1127709788955,0.0464020066576957
0.0478548799945093,253.133954718495,0.151939243982567,51.031805271248594,265.24764974408413,0.046745103022857615
0.0482289211022939,253.182425737325,0.15312682449978313,51.04157702864472,265.39314097269784,0.04710199821145566
0.0485738505556672,253.160992116945,0.15422197551424335,51.03725601077612,265.45799631455793,0.04743100336267637
0.0489240306907726,253.12244929167,0.155333797443203,51.02948577720067,265.50621976933917,0.047764906096490575
0.0492831395251203,253.139536542758,0.15647396799225693,51.03293056702001,265.615047641519,0.04810720674530324
0.0496348030115262,253.166194070871,0.15759049956159568,51.0383047246876,265.7320482427565,0.0484422970149794
0.0499841200289144,253.24475922067,0.1586995810918032,51.054143458887076,265.9029756622495,0.04877504027308017
0.0502959011310168,253.294026069067,0.15968948609097833,51.064075655523915,266.033677361314,0.04907193506925169
0.0506362318913544,253.25938242743,0.1607700362550502,51.057091497369896,266.0834832446866,0.04939591579948579
0.0509848332881016,253.241227129251,0.16187684568972258,51.05343138925701,266.1526888761101,0.04972766104673323
0.0513301806003723,253.237878971648,0.16297332340618204,51.05275640068424,266.23662503411794,0.050056201073413964
0.0517214676818165,253.241291876022,0.16421565988976738,51.053444442206036,266.33930316948914,0.050428314698182895
0.0520695969865966,253.291626933054,0.1653209704324442,51.063591989703696,266.4804198675375,0.05075926895861698
0.052421306215266,253.362093017876,0.16643764723346954,51.0777979524038,266.6436648793068,0.05109351533754775
0.0527845674647047,253.415847214874,0.16759100170043742,51.0886347985186,266.7922930988128,0.05143862291831751
0.0531269939099031,253.466461209652,0.16867820566394234,51.09883857986584,266.9323723507019,0.05176382788370806
0.0534886556209825,253.48567814163,0.16982648159661942,51.1027127133526,267.04428628459885,0.05210718592788973
0.0538537056566997,253.496730454142,0.17098551546002155,51.10494085955503,267.1484687609551,0.052453641298480014
0.054222116756087,253.51888333231,0.1721552207005762,51.109406879793696,267.2652138242273,0.05280316487749086
0.0545841039125973,253.520997472683,0.17330452992249643,51.10983309049289,267.35921394275726,0.05314647490428977
0.0549295682904044,253.493615097365,0.17440137932203395,51.10431280362878,267.41790993903714,0.05347400478517883
0.0552800070776672,253.467239737875,0.17551402247159334,51.098995531155595,267.47891054454146,0.05380614126543647
0.0556345151986016,253.461879164054,0.17663958575556007,51.09791483947329,267.56310793267266,0.05414202234496496
0.0560103642332103,253.472607839639,0.1778329064404427,51.10007774047123,267.66970092787886,0.05449799985068927
0.0563754684674737,253.508048296261,0.178992112384229,51.107222536526216,267.7996832792377,0.05484367934943146
0.0567533299947992,253.515113626059,0.18019182273348744,51.108646907013494,267.9029405283477,0.055201311625919014
0.0571140980698275,253.522025650754,0.1813372613717023,51.11004037119201,268.0017074866325,0.05554264625621929
0.0574697378386458,253.532674200594,0.1824664176377004,51.11218711883975,268.1031305204329,0.05587901482778616
0.0578262833450051,253.523113083105,0.18359844962039118,51.11025959755397,268.1834124547564,0.05621612651916687
0.0581870036631135,253.521478162529,0.18474373663038535,51.10992999756585,268.27313334105,0.05655706986183622
0.0585400270782292,253.508176804385,0.1858645859733777,51.107248443764014,268.3485523390662,0.05689062578403289
0.0589035524631304,253.490756579137,0.187018779070439,51.10373652635403,268.42226265821483,0.057233988310416296
0.0592710104882007,253.51893942033,0.18818545830003722,51.10941818713854,268.5452631376699,0.05758094557747393
0.059629553916983,253.534588026607,0.189323833686421,51.11257294616397,268.6527424131597,0.057919369605696484
0.0600181579967455,253.566560298554,0.19055765163966695,51.119018556188486,268.78515817724394,0.05828603816286487
0.0603600136129819,253.557598896412,0.19164304322121753,51.11721193751666,268.8623390174744,0.05860848594484583
0.0607139521603531,253.541545881289,0.1927667981091211,51.113975649667864,268.93505516858755,0.05894222117178052
0.061073936521467,253.502618193972,0.1939097484556577,51.10612782790476,268.98502100557636,0.05928154289803623
0.0614548617062021,253.492018656532,0.19511918591719166,51.10399096115685,269.07033560669515,0.05964047813523335
0.0618379896659842,253.508378814955,0.19633561718949982,51.10728916909493,269.1848273243546,0.06000135907889836
0.0621986377522319,253.523056494298,0.1974806748633363,51.11024818925048,269.2918452470255,0.06034094652768156
0.0625584920554344,253.549086909229,0.1986232122760042,51.11549592090057,269.4107354483026,0.06067967164745618
0.0629284577647939,253.521901617394,0.19979785340322062,51.11001536606664,269.47564389577445,0.0610277948981092
0.0632906257751981,253.495020754924,0.20094773683625397,51.10459618419268,269.5388792494,0.061368463474278566
0.0636713492319272,253.472290922936,0.20215653381136886,51.100013850063895,269.6112136789069,0.061726460904668864
0.064032219629451,253.45449082735,0.20330229732350694,51.096425350793766,269.68374445007754,0.062065672067600865
0.0643993492360285,253.469337206923,0.20446793382439046,51.09941838091568,269.7925975743363,0.06241064873078214
0.0647668876213489,253.454042672433,0.20563486819778273,51.09633500276249,269.86947217137504,0.06275589034001756
0.0651372863713416,253.387959498119,0.20681088422900956,51.08301263482079,269.89296357899786,0.06310369824447569
0.0654952415889319,253.334481686475,0.20794739204485876,51.07223150799336,269.9266847673375,0.06343970665161362
0.0658577112700423,253.318586467374,0.20909823328238428,51.0690270318226,270.00156879427755,0.06377983772574539
0.0662243699602431,253.328027913188,0.2102623746237718,51.0709304272987,270.1045169550098,0.06412378198290448
0.066586598446102,253.374562328324,0.21141245006637382,51.080311765390114,270.24591256653696,0.06446345436335203
0.0669726913574481,253.384280159492,0.2126382950598977,51.08227088015359,270.35410734944276,0.064825378137775
0.0673637891904092,253.41530613994,0.2138800306795492,51.0885257178119,270.4863214003739,0.06519186003123752
0.0677430586874051,253.412174273383,0.21508421133251118,51.087894333514015,270.57909006728767,0.06554712984020458
0.0681145191428991,253.413386175261,0.21626359827870462,51.08813865293262,270.6745171189627,0.06589496245141885
0.068474132811273,253.388422369681,0.21740537167579177,51.08310594972769,270.7389748558615,0.06623158660360726
0.0688465860072971,253.349334123942,0.21858791057316826,51.075225759386704,270.7915708455974,0.06658011005777568
0.0692330091365281,253.327174218617,0.21981480400847672,51.07075832247318,270.86577678582535,0.06694157754880466
0.0696384784968376,253.286951288955,0.22110216922745937,51.062649379853326,270.92546919982044,0.06732072081899272
0.0700137021759955,253.257136580365,0.22229350440878573,51.056638734601584,270.9886063148481,0.06767145416377997
0.0703872640154139,253.209071569665,0.2234795632489391,51.046948828444464,271.0317653413369,0.06802051197968645
0.0707479633175052,253.157805616262,0.224624783533079,51.036613612238426,271.06820476154144,0.06835743540320388
0.0711120387230269,253.107231199724,0.2257807229456104,51.02641780986436,271.10620242587686,0.06869739731358203
0.0714877587190558,253.058009373594,0.22697363393300216,51.016494689716545,271.14855928961805,0.0690481114323164
0.0718662846556086,253.046434256757,0.2281754537815573,51.014161146162216,271.23194133213985,0.0694013204055685
0.0722625855410238,253.068969412265,0.22943370909275054,51.01870423351263,271.3563874621975,0.06977098185216951
0.0726404398370067,253.05295931934,0.23063339648249626,51.015476598778946,271.434837586353,0.07012330948229635
0.0730099193933845,253.04672519721,0.23180649407399576,51.01421979975754,271.5216462066182,0.07046770814766168
0.0733853883219474,252.982863492997,0.23299860792218297,51.0013452801882,271.5481091692288,0.07081756814879295
0.0737606010297934,252.931587120016,0.23418990826959402,50.99100796339523,271.5879730054079,0.07116706717077481
0.0741405805796983,252.938700848348,0.2353963433405421,50.99244209102695,271.6917229803192,0.0715208819152542
0.0745249263369805,252.942316425622,0.2366166411199131,50.9931709914054,271.7928239247467,0.07187863491137587
0.0749034454117337,252.957506182779,0.23781843918225448,50.99623324644825,271.90489493862907,0.072230839324085
0.0753010254218468,252.95475323345,0.23908075571436357,50.995678251863524,272.002505537259,0.07260064602855168
0.0756900980180967,252.928694629119,0.24031606120745702,50.99042483723039,272.0728923171863,0.07296240726155095
0.0760880010524583,252.905680253813,0.2415794033415551,50.985785139168705,272.1487679191378,0.07333224376009025
0.0764685950339085,252.86787413306,0.24278778923265948,50.978163425224906,272.20432519722635,0.07368586418160045
0.0768506883853055,252.853659987609,0.24400093562334493,50.97529785350198,272.28563781840074,0.07404075196656512
0.0772371434209772,252.802216190594,0.24522793036160262,50.96492678402376,272.32793721964777,0.07439956281365459
0.077626574827566,252.770111097302,0.24646437507752206,50.95845439721609,272.3917890405689,0.07476100693425547
0.0780241638904282,252.717044414728,0.24772672035210952,50.94775615400917,272.43508050604737,0.07512988771835423
0.0784369195581269,252.690056997941,0.24903721959705288,50.942315490784914,272.51028667182703,0.07551269608518009
0.0788362140938395,252.694010007986,0.25030497974794036,50.94311241760998,272.6154490812064,0.07588288058712714
0.0792338408420536,252.646569994244,0.25156744467352016,50.93354851083959,272.6647281104587,0.07625138276045033
0.0796393919029546,252.589316353837,0.25285506929188084,50.922006176933536,272.7053759094396,0.07662708899416533
0.0800303641538536,252.480925106608,0.25409640618848517,50.900154501492175,272.6870654847917,0.07698915569818214
0.0804203097890253,252.360675943897,0.2553344835801553,50.87591227028964,272.655599681873,0.0773501411574748
0.0807926633405486,252.287007979418,0.2565167061062418,50.86106080865068,272.66994728029346,0.07769471946589435
0.0811644916479255,252.223409833977,0.25769726098216345,50.84823942252976,272.6949946748581,0.07803869326776643
0.081549800769903,252.209673615973,0.258920617444442,50.84547020098017,272.77732225159787,0.07839501321941697
0.0819402691223655,252.180995529833,0.26016035446351043,50.839688698814335,272.84477417109355,0.0787559747621908
0.082326737350458,252.156520717452,0.26138739108770415,50.834754576638325,272.915744369763,0.07911311020901357
0.0827304704612318,252.172516077579,0.26266924371441097,50.83797924123993,273.03486697006963,0.07948606397115607
0.0831171804306933,252.198191936092,0.2638970478674512,50.84315549431615,273.1601945595388,0.07984316200934155
0.0835074929676578,252.218920724549,0.2651362901723135,50.847334418069075,273.2810904732645,0.08020345749196846
0.0839161567073517,252.222149840497,0.2664337975458416,50.8479854078442,273.38766329157727,0.08058055381515182
0.0843269156802021,252.18996767464,0.26773795728464167,50.84149748320743,273.45636981413224,0.0809594402813375
0.0847486703039979,252.15035903158,0.2690770282151933,50.83351238076653,273.5197666761821,0.08134831988685812
0.08515243206491,252.089659822635,0.2703589718060892,50.82127542024322,273.5557074549482,0.08172046750697881
0.0855555373297868,252.03489990216,0.27163883102207304,50.81023582027546,273.5978811891483,0.08209187192912491
0.0859650000733823,251.980337695189,0.27293887523298876,50.7992360793501,273.64182744364683,0.08246899269901459
0.0863674473871393,251.929826862306,0.2742166454541673,50.789053095440885,273.68836292908736,0.08283951362810334
0.086781067674146,251.884252179116,0.27552988986541355,50.779865239309785,273.7430365135235,0.08322017817001996
0.0871920436453695,251.827486271868,0.27683473857404817,50.76842123240859,273.7848394459884,0.08359826562103698
0.0875988269374161,251.795369660501,0.2781262755262961,50.761946523557,273.85234867103395,0.0839723551965386
0.0880077705346491,251.729573452663,0.2794246714475109,50.74868200805686,273.88373198987006,0.08434829044376978
0.0884247596799556,251.643457469214,0.28074861198385903,50.73132102579355,273.8949697209624,0.0847314763634984
0.0888337864039196,251.583649562245,0.2820472718324447,50.7192637517486,273.93277775017606,0.08510720273693402
0.0892462736327419,251.48476767386,0.2833569187839555,50.69932916305018,273.9288460641479,0.08548596497007858
0.0896394846574148,251.431774186799,0.28460536378729195,50.68864567605868,273.9699888514032,0.0858468935111418
0.0900519819446074,251.417859495162,0.2859150426741285,50.68584047422466,274.05853603897214,0.08622538496136511
0.090458741941987,251.404637584277,0.2872065056658087,50.68317493699025,274.1463848185318,0.08659847186953018
0.0908785388736253,251.426574316789,0.2885393609237603,50.687597382264656,274.27585402469975,0.08698337056494336
0.0912950091433542,251.378740022999,0.2898616540301496,50.6779539886366,274.32836439184354,0.08736507281329468
0.091701626181296,251.316519975738,0.2911526631256148,50.66541042710878,274.36265354373734,0.08773760388921528
0.0921219488797009,251.23708289307,0.2924871876930504,50.64939591124292,274.3815326000306,0.08812254588580815
0.0925405799668633,251.171210872708,0.29381634139479096,50.63611611193794,274.4147403978477,0.0885057914322105
0.092966971631662,251.127770183629,0.2951701349305268,50.62735846901961,274.47435847021296,0.08889599065151478
0.0933890143014444,251.094139292626,0.29651012040708596,50.62057848139341,274.54357345803396,0.08928206014590638
0.0938006910176639,251.025318531802,0.29781719398108286,50.60670421601129,274.5716668730142,0.08965850368903373
0.0942223384459122,251.018284589973,0.2991559245657712,50.605286173338555,274.66981435672176,0.09004391776172853
0.0946545003449502,251.006499094594,0.3005280385952169,50.60291021747015,274.76539384972796,0.09043878868090917
0.0950851945307071,250.984023710307,0.30189549263499504,50.59837917999789,274.8488884289012,0.09083216346634039
0.0955256610319915,251.016396061725,0.303293973776573,50.60490544604376,274.99490322538946,0.09123430381555091
0.0959588984727792,250.92661707173,0.30466950265107395,50.58680600166077,275.0052588434341,0.09162968642917939
0.0964049177996508,250.832620721353,0.3060856140138913,50.567856337424764,275.01411890346606,0.09203657084290169
0.0968503428901252,250.713900732621,0.3074998386761475,50.5439223876964,274.9956279858962,0.09244274800301772
0.0972793516440322,250.624240477348,0.3088619414698022,50.52584688023336,275.0048040972624,0.09283379941665357
0.09773881914283,250.518153556053,0.31032075077848525,50.50445975690029,275.0035020584638,0.09325244515874677
0.0981479586443758,250.480587586371,0.31161976869589314,50.496886457412394,275.0647459380171,0.09362508687271759
0.0985729593239351,250.416219587611,0.31296914585349395,50.48390986886238,275.10048741507416,0.09401202786407026
0.098998569431432,250.37174946042,0.31432045794479657,50.47494469122067,275.1581944830465,0.09439937372039317
0.0993998398980806,250.329645352755,0.3155944916764059,50.46645650311541,275.21237202256214,0.09476443081778022
0.0998462944762747,250.297360315781,0.31701198496217214,50.459947839661446,275.2886242605047,0.09517043774656267
0.100278977810687,250.298351774937,0.3183857545489312,50.460147717827304,275.39801463862744,0.09556376384070875
0.100727003264525,250.263227136519,0.31980823536486686,50.45306659072223,275.47149203328973,0.09597087355679157
0.101164200424069,250.232641120716,0.32119633634641903,50.44690044993635,275.5472261796962,0.09636798415386087
0.101609789935795,250.160951115154,0.3226110830461491,50.43244774481504,275.5797528081035,0.09677255540788327
0.102031752831404,250.094036377776,0.3239508152397077,50.41895773375965,275.6115692820814,0.09715552413721337
0.102493303931599,250.011969878352,0.3254162399828268,50.40241312747577,275.6365226936317,0.09757425478899051
0.102938805780492,249.955047257426,0.3268307083530621,50.39093752709709,275.6851213209119,0.09797825893220655
0.103402123300031,249.878682577027,0.3283017414775984,50.37554240752865,275.7166689229061,0.09839824617918422
0.103853474510847,249.810725284177,0.3297347815719392,50.36184221729009,275.75443707501347,0.09880721668314811
0.104298189852421,249.73419526366,0.3311467527814366,50.346413765153855,275.78101977391077,0.0992100108886039
0.104750267749305,249.650377354398,0.3325821001040434,50.329516074646634,275.8013212259862,0.09961930739057934
0.105201940740506,249.592149572335,0.3340161618511065,50.31777735378273,275.8497281009393,0.10002807007400287
0.105647894901208,249.535870574371,0.3354320663113354,50.3064315077932,275.8988100028936,0.10043149337264663
0.10610176529051,249.515030417592,0.33687310479736926,50.302230132186544,275.98901561141383,0.10084191088403315
0.106572917057676,249.429618603736,0.3383690116581213,50.28501111051318,276.0120606589197,0.10126777716979603
0.10702898559039,249.381869863564,0.3398170292494882,50.2753849644945,276.0729584196959,0.10167983729553202
0.107489839708114,249.29858596977,0.34128024107326194,50.258594931505634,276.09565101512004,0.10209604881661925
0.107954290232399,249.255427610858,0.3427548714878668,50.249894206348976,276.16362038516127,0.10251533317122082
0.108407527980551,249.203111557886,0.3441939013382494,50.239347290069816,276.21860484693786,0.10292432573799899
0.108867630831361,249.130557147396,0.34565472788957113,50.22472032091503,276.25281067172995,0.10333934221043402
0.109335595798216,249.049596173233,0.34714051665933576,50.20839858852377,276.27958215413855,0.10376127377033768
0.109797682821278,248.969233153589,0.34860764295755764,50.192197403763544,276.3054780476436,0.10417773098288337
0.110259670545475,248.911546753393,0.35007445398188314,50.18056782548403,276.3564518933867,0.10459392539350525
0.110729293411036,248.839951428675,0.35156550658003927,50.16613420802088,276.3938234228087,0.10501682067140283
0.111206315342727,248.784387666057,0.3530800512131582,50.154932553477096,276.45078273319575,0.10544619579563272
0.111679984160086,248.725005168634,0.354583949708273,50.142961041996614,276.50260980608437,0.10587237038192092
0.112166380328771,248.669738614372,0.3561282575438479,50.13181930465739,276.56212309204767,0.10630980723386171
0.112654413397592,248.619629783332,0.35767776253735456,50.12171736431973,276.6277283356997,0.10674852398626261
0.113131823978131,248.553072494006,0.3591935411305659,50.10829941479161,276.6723349406215,0.10717750551184085
0.113614324964184,248.479065497472,0.36072548176128416,50.09337960429036,276.70984679169857,0.10761087416846464
0.114087297493417,248.387504985869,0.36222716954159895,50.07492100515119,276.72536416083943,0.10803550243247599
0.114575582674657,248.269139876641,0.363777474992036,50.05105859913082,276.71472123814306,0.1084736891079018
0.115067325422295,248.160673963849,0.3653387582157866,50.02919187111196,276.71585899186323,0.10891478463384911
0.115545319274808,248.062505404593,0.3668563886975154,50.00940108956595,276.72496679167546,0.10934336093638712
0.116019408982796,247.963167704112,0.36836162352037727,49.98937460914898,276.731707870645,0.10976825536953286
0.116494513106055,247.896010230961,0.36987007911172465,49.97583566256174,276.77453524375045,0.11019387791614334
0.116977331956592,247.817070622544,0.3714030289621796,49.959921437504875,276.80605035726757,0.1106262261985945
0.117474422720646,247.76914260102,0.37298129213805103,49.95025914836563,276.87567959606423,0.11107115929792308
0.11794802953222,247.718615436055,0.3744849937647985,49.94007287190869,276.93653800518746,0.11149488843975303
0.11844157902625,247.672697391436,0.3760520134083437,49.9308157941135,277.0074427521683,0.11193626904727687
0.118928427941718,247.621346352893,0.3775977587149546,49.92046342474323,277.07056379945425,0.11237146655295153
0.11942705064976,247.488043042574,0.379180885812988,49.893589477382925,277.04481009422943,0.11281699249470538
0.119940016239687,247.371057453112,0.3808095515610062,49.87000518254739,277.04074610126685,0.11327512694392884
0.120435029307351,247.242920524766,0.3823812180508394,49.84417277779283,277.0196289042012,0.11371702891628231
0.120919757606225,247.149768047094,0.38392023039976436,49.825393238294154,277.03505809178336,0.11414956044521404
0.12141943141658,247.115527828885,0.3855066947476415,49.81849041030322,277.12015471207627,0.11459523237662528
0.121920435183012,247.022761505606,0.38709738170606306,49.79978871953017,277.1398840884789,0.11504189120190698
0.122430807294017,246.955815057172,0.38871781315850396,49.786292315525884,277.19081486057354,0.11549669712545672
0.122939335978201,246.838076414951,0.39033239173078815,49.76255620525412,277.1841856235415,0.11594965468740011
0.123455639497467,246.748594326378,0.3919716554044577,49.74451661619781,277.21109983404205,0.11640932766031353
0.123979075299804,246.647900481524,0.39363356407687766,49.72421673707524,277.2270791078614,0.11687513501690105
0.124500513709798,246.489540590998,0.39528913102860863,49.6922913831452,277.17761501866937,0.11733894925109793
0.125004678293729,246.339457172892,0.39688985358258955,49.66203456605503,277.13304176784123,0.11778719413105172
0.125510180757658,246.217949292898,0.3984948239055641,49.63753857744824,277.1208086144295,0.1182364268658609
0.126008067064984,246.081736674969,0.40007561293132415,49.61007811367375,277.0900206533762,0.11867869404794835
0.126516510235443,245.996987723947,0.4016899199975315,49.59299272514772,277.1196681392119,0.11913013700596803
0.127032608679608,245.881537883297,0.40332853255775536,49.56971803727268,277.1165110667661,0.11958816869372312
0.127563357005287,245.781922505112,0.4050136584917862,49.54963557703058,277.1346896310774,0.12005898328184535
0.128103415996361,245.685355200694,0.40672834578844613,49.53016760845992,277.1584884621822,0.12053782972127283
0.128647312393122,245.538957534506,0.40845521684816233,49.50065383895642,277.1268845091291,0.12101984698658234
0.12916983108417,245.359454511731,0.4101142136922397,49.464466029564974,277.0524938059154,0.12148269996994811
0.129700068870751,245.193674395748,0.4117977186646344,49.4310447581828,276.995310851549,0.12195217171449653
0.130211697804185,245.000593160997,0.4134221405282874,49.39211958125699,276.9025363595228,0.12240495836724953
0.130702263665009,244.842238262176,0.41497968713640354,49.360195233654686,276.8436730438499,0.12283891196025024
0.131220749300081,244.659507076561,0.4166258790277572,49.3233566266347,276.7639109185358,0.12329735872539745
0.131751575251991,244.477167973997,0.41831125142507136,49.2865970635578,276.6874199677167,0.12376649920571763
0.132348975294744,244.332105758416,0.42020799656081215,49.25735252089667,276.66920958714934,0.12429421433433474
0.132908772505176,244.22025225517,0.4219853527039338,49.234802854642275,276.6792662033091,0.12478846027378367
0.133482170458392,244.042559589579,0.4238058912053946,49.19898001325913,276.6178901278175,0.12529446120643858
0.134033818034448,243.841809610329,0.42555737225937235,49.158508817442325,276.5248583488304,0.1257810267607623
0.13460747184284,243.570888848395,0.427378723101017,49.10389119183643,276.35735041079084,0.12628675133095155
0.135154709383776,243.245731600333,0.42911620229348874,49.03833949062713,276.12153776362,0.1267689494714136
0.135723739313014,242.950803081565,0.4309228723188195,48.978881901243504,275.92499454489473,0.1272701034996921
0.136270926764443,242.668665458566,0.43266019247710646,48.9220029564469,275.7373493972954,0.12775178373440277
0.136826611668295,242.410169647142,0.4344244920468366,48.86989020086383,275.578331793897,0.12824070680569744
0.137386617536784,242.188721152751,0.43620251067928917,48.8252461843946,275.4622103574868,0.12873318998415761
0.13796704930797,241.916835537931,0.4380453815528047,48.770434044446894,275.29338751502075,0.1292433803710271
0.138581211448921,241.596328749283,0.4399953463503241,48.705819875855454,275.07704066897037,0.1297829359485982
0.13918504211034,241.221803074057,0.44191250870032944,48.63031549972989,274.79626989285174,0.13031313141937634
0.139814151262865,240.793379137037,0.44390993025959635,48.54394523402666,274.4597010707991,0.1308652239083373
0.140415693186461,240.349286723849,0.44581982586701363,48.454416203527956,274.0980984260497,0.13139283908626773
0.141038389777518,239.854385138616,0.4477968875436196,48.354644043944994,273.68306139964307,0.13193871604357266
0.141644456794896,239.35650403882,0.44972115032379484,48.25427121422611,273.260026033724,0.13246972895456843
0.142261661219439,238.890073052821,0.45168077437171883,48.160238727448714,272.8749716941484,0.13301021039966773
0.14287841771887,238.349548708952,0.45363897625741223,48.05126901972472,272.4045550924938,0.13355000795526753
0.143488110125518,237.840168450232,0.4555747496485196,47.94857795956678,271.9674047330907,0.13408333663522737
0.144119878870391,237.182107361632,0.4575806154134914,47.815912844105014,271.3647639448145,0.1346356766899689
0.144736392012017,236.550221996646,0.4595380446381539,47.68852475452383,270.7876476580822,0.13517438518327068
0.145337853954747,235.863749902334,0.46144768630632166,47.55013198031053,270.14368113885837,0.135699662438031
0.145951082348064,235.14853227733,0.4633946864551032,47.405944107109725,269.468715075765,0.13623493182133986
0.146551246613088,234.490740369228,0.46530020799655436,47.27333325843637,268.85565068956436,0.1367585206274694
0.147176602400407,233.673166128637,0.4672857126212922,47.10851029153322,268.06438879159566,0.13730379525809522
0.147796717735049,233.050704261945,0.4692545788087805,46.983021979208104,267.49483341770207,0.13784420707403486
0.148429009133762,232.156536368718,0.4712621039996943,46.80275773193355,266.615301025853,0.13839492942445117
0.149097635632941,231.34745679781,0.4733849931345877,46.639647290438496,265.84081561605745,0.1389769696976972
0.149772925916588,230.422876112239,0.47552903978516686,46.45325182422738,264.93398446568455,0.1395644671535045
0.150445732618489,229.416690328756,0.4776652010637026,46.25040477027721,263.93145238017473,0.14014946086146488
0.151102231080706,228.456403043087,0.47974958368124154,46.05681085348634,262.9766752475704,0.14071994515323413
0.151747776228177,227.472069407762,0.481799189524462,45.858369192604826,261.9904500944114,0.14128059405553473
0.152443263726963,226.339923999946,0.48400736233310754,45.63012867838911,260.8439207262105,0.14188426580657187
0.153150773989924,225.37168279644,0.48625370741800866,45.43493125176231,259.88753045212644,0.14249799942454194
0.153878568525309,224.171427695317,0.48856445506785606,45.19295982337591,258.6666060933472,0.14312893596801468
0.154594617482011,222.97040206239,0.4908379105053849,44.95083305577783,257.4404260790354,0.14374930183061752
0.155255532348413,221.758254911572,0.49293631520621123,44.70646419017292,256.18745083052323,0.14432155963226487
0.155929510309679,220.451975051223,0.49507619523323076,44.443118170326564,254.82694356776176,0.14490479115023605
0.15664425296165,219.258018770536,0.4973455031532387,44.20241658414007,253.60352732669807,0.14552292725995147
0.157405745609775,217.907329830411,0.4997632423110356,43.93011769381086,252.207195556202,0.14618107438389633
0.15820670231473,216.621941239311,0.5023062798492677,43.6709833538451,250.89298421179762,0.14687286262990937
0.158973447162674,215.024862114567,0.50474069474149,43.349012202296706,249.20810567059837,0.14753465396805895
0.159743284520528,213.467580057617,0.5071849283526764,43.03506413961559,247.5675924346695,0.1481986741785671
0.160492942126008,211.868999318273,0.5095650912500754,42.71279026256384,245.87247836415582,0.1488448649611748
0.161266437645033,210.211627138103,0.5120209395229798,42.37866403104157,244.11170739823083,0.14951116617600432
0.162047244236832,208.579260247973,0.5145000004519416,42.04957886599135,242.378954576114,0.15018331529412324
0.162820236358271,206.758709179175,0.5169542504375104,41.68255577052169,240.4232110768593,0.15084829268003908
0.163593941017821,205.017576130874,0.5194107627315816,41.3315433479842,238.55720938804487,0.15151344052482063
0.164370225326859,203.083233178154,0.5218754654127773,40.94157980871585,236.46406997575423,0.15218036173351784
0.165169185095541,201.044662835268,0.5244121626783426,40.53060402759004,234.25104596357704,0.15286629973176247
0.165991830768949,198.84185983714,0.527024062691413,40.08651894316742,231.8479841850096,0.15357208170216957
0.166853018883685,196.510159491507,0.5297583349556999,39.616448153487816,229.29847284397937,0.15431039754343476
0.167789120234952,193.767699106829,0.5327304567459725,39.06356813993673,226.27981086991474,0.15511232036128134
0.16848662828163,191.524440165513,0.5349450447941753,38.61132713736742,223.79374732252708,0.15570943144103733
0.16897325292664,190.018482676801,0.536490078042082,38.30772610764308,222.12652381088444,0.1561258019258977