File: example/data/02 processed data/test_ID_080.csv
Strain,Stress_MPa,Displacement(mm),Force(kN),True Stress (MPa),True Strain
-4.266830942590931e-05,0.0924937358465878,-7.796490641946635e-05,0.018646737146672,0.092491464581876,-2.455617753812825e-05
-5.0759027502397406e-05,0.0938924255182696,-0.0001036529363123,0.0189287129844831,0.0938893602503633,-3.264712702571295e-05
-5.640222713934311e-05,0.0952036383879744,-0.0001215700951596,0.0191930534990156,0.0951999930602961,-3.829052682395516e-05
-5.0445528444252206e-05,0.0969955368057349,-0.0001026575768027,0.0195543002200361,0.0969924006398233,-3.233361778179966e-05
-4.587296902244911e-05,0.171776549862032,-8.813970063848022e-05,0.0346301524521856,0.1717717812529984,-2.7760920964936632e-05
-3.526215917165981e-05,0.396723502103557,-5.44503793622242e-05,0.079979458024077,0.3967166984042841,-1.714987284160049e-05
-2.8209212094456107e-05,0.842209385935084,-3.2057272392102446e-05,0.1697894122045129,0.8422008823332899,-1.0096829679038837e-05
5.10088171604259e-06,1.55336129603757,7.370227545623091e-05,0.3131576372811741,1.553397354702806,2.3213045679523846e-05
4.202040312191429e-05,2.57205730032622,0.0001909217559198,0.518526751745766,2.572211965427355,6.013102860364759e-05
7.97275237406274e-05,4.02681870146583,0.0003106418638842,0.8118066502155113,4.027212685234948,9.783517111254337e-05
0.0001136514344411,6.00726200859584,0.0004183502803583,1.2110640209329215,6.008053548673157,0.0001317551877333
0.0001451620547356,8.16965054069632,0.0005183964997933,1.647001549004378,8.170984436206504,0.0001632611602953
0.0001798461320863,10.4581292015429,0.0006285184453818,2.1083588470310484,10.460199477797184,0.0001979389742631
0.0002255602406099,12.8422296742363,0.0007736607399442,2.588993502326038,12.84535897468112,0.0002436429906341
0.0002550317283305,15.3432720715308,0.0008672327134571,3.093203649620609,15.3474629967188,0.0002731068646437
0.0002876586631293,17.8873676609457,0.0009708232314433,3.6060933204466528,17.8928371009692,0.000305724358063
0.0003300324234759,20.4358952534492,0.0011053599205438,4.119876483095359,20.443009905277105,0.0003480842685055
0.0003783343479698,22.8957278954406,0.0012587185308119,4.615778743720825,22.9048048330716,0.0003963682170966
0.0004302240199816,25.563595519309,0.0014234682394494,5.153620856692696,25.57505661105951,0.0004482359806114
0.0004854096751328,28.4729592248999,0.0015986826945544,5.74014857973982,28.48729598936465,0.0005033953838014
0.0005286968277683,31.376095775022,0.0017361194041722,6.325420908244436,31.39325251477072,0.000546659815449
0.0005719583796651,34.3490395085517,0.0018734748314445,6.924766364924023,34.36930787422211,0.0005898967897251
0.00062654865749,37.3887489320215,0.0020467989635386,7.537571784695534,37.4128520036946,0.0006444533861786
0.0006783829889959,40.4843436123696,0.0022113729660698,8.161643672253712,40.512540772373846,0.0006962529820134
0.0007160251017187,43.5400613887528,0.0023308866739647,8.777676375972563,43.572025782099146,0.000733868187964
0.0007548746281355,46.5937147581596,0.002454233920338,9.393292895244976,46.62973109681599,0.0007726884608915
0.0008009272394926,49.5548240567538,0.0026004509613968,9.990252529841566,49.59541142363892,0.0008187044429199
0.0008549218605492,52.6263538374543,0.0027718838832515,10.609472933630787,52.672298449119296,0.0008726534211589
0.0009093263006673,55.7095908213914,0.0029446179806265,11.231053509592508,55.76125805377755,0.0009270089284779
0.000953425703158,58.8363808699613,0.0030846335835345,11.8614143833842,58.89354265779284,0.0009710664988221
0.0009958637753979,61.8740331450987,0.0032193744628961,12.473805082051896,61.93677194264948,0.0010134624821519
0.001047949034867,64.9854686512972,0.0033847451617105,13.101070480101514,65.05474715542286,0.0010654936282607
0.0011054652597242,68.1116629889097,0.0035673591756321,13.731311258564196,68.18819173408482,0.0011229469521096
0.001153727159356,71.2373910994214,0.0037205907069631,14.361458045643356,71.3208698947955,0.0011711535246508
0.0012049969378226,74.4244695864252,0.0038833722535946,15.00397306862332,74.51549885262376,0.0012223619823074
0.0012508021892997,77.6025535029678,0.0040288039270344,15.644674786198308,77.70102451786565,0.0012681102309259
0.0013006924202418,80.7333553598052,0.0041872054102755,16.27584444053673,80.83982690070356,0.0013179359943291
0.0013573640080607,83.877718280535,0.0043671377016005,16.90974800535586,83.99309010599238,0.0013745313402722
0.0014076804241537,87.0079849455474,0.0045268923226958,17.540809765022356,87.1320403090319,0.0014247773800315
0.0014616501836749,90.1005017479059,0.0046982463091756,18.16426115237783,90.23382910217109,0.001478668847242
0.0015100475378228,93.2057821068164,0.0048519079085952,18.79028567273419,93.34821545211746,0.0015269935229574
0.0015603027049363,96.2792635344299,0.0050114680641806,19.409899528541068,96.4312321814994,0.0015771707504186
0.0016115552174522,99.3623047632452,0.0051741947914185,20.03144064027024,99.52423229703082,0.0016283411834528
0.001664267155303,102.444774278758,0.0053415551940948,20.65286649459761,102.61712527597268,0.0016809659734206
0.0017113387673173,105.60813075714,0.0054910075622402,21.290599160639427,105.7907748656822,0.0017279574220079
0.001768066891892,108.69872337978,0.0056711193577649,21.913662633363653,108.89287879216532,0.001784586004012
0.0018205138591366,111.806584452844,0.0058376384787665,22.54020742569336,112.01215497869642,0.0018369380882043
0.001877897583312,114.945593796641,0.0060198318030234,23.173031709402828,115.163531793855,0.0018942148584424
0.001936868501052,118.063240297554,0.0062070644668479,23.801549243986887,118.29405168139397,0.0019530724461806
0.001986497008118,121.177671721459,0.0063646349767825,24.42941861904614,121.42058562629158,0.0020026028931161
0.0020437749473262,124.270064000795,0.0065464924337685,25.05284490256028,124.52629487755884,0.0020597646083733
0.0021020177694323,127.292992474702,0.0067314133939554,25.66226728289993,127.56287019265504,0.0021178858983674
0.0021434415596948,130.355132705158,0.0068629339280388,26.279594753359856,130.63690236277571,0.0021592211962898
0.0021958224985086,133.397653917216,0.0070292434087726,26.892967029710743,133.6929876430564,0.0022114877891664
0.0022502854678647,136.452492073802,0.0072021633364782,27.508822402078486,136.76202062044297,0.0022658289709044
0.002300128411478,139.527092336893,0.0073604146824505,28.128661815117624,139.8505497413138,0.0023155578702796
0.0023664896101192,142.566121532619,0.0075711114881363,28.741330100976,142.9060849973606,0.0023817633918618
0.0024180685833304,145.630425462818,0.0077348747280818,29.35909377330412,145.98520754078717,0.0024332183385168
0.0024741752700574,148.705903519632,0.00791301345844,29.97911014955781,149.07652141440374,0.0024891871051008
0.0025473958348322,151.768725027824,0.0081454887516,30.59657496560932,152.15808894674015,0.0025622229696574
0.0026050374159424,154.796611338017,0.0083285007716249,31.206996845744225,155.2026660457252,0.0026197153965099
0.0026589889238352,157.771691775831,0.0084997968091846,31.80677306200753,158.19406258601552,0.0026735243040521
0.0027122532583822,160.761914231451,0.0086689110713713,32.40960190906052,161.2008530466119,0.0027266450143663
0.0027605454471768,163.692780672403,0.0088222387707941,33.00046458355644,164.14762690740997,0.0027748045471695
0.002815620119462,166.610629108623,0.0089971008552997,33.588702828298395,167.08275907197896,0.0028297251016711
0.0028728217648838,169.51232112777,0.0091787160795139,34.17368393935843,170.00237009394678,0.0028867634842424
0.0029237757341565,172.387904520581,0.0093404949319547,34.75340155134913,172.89505045711792,0.0029375692829265
0.0029727035403349,175.279979536763,0.0094958407165711,35.33644387461142,175.80420969943543,0.00298635238127
0.0030290653634278,178.137364003195,0.0096747895048911,35.91249258304411,178.6801802235689,0.0030425445603641
0.0030840845510352,180.943993856494,0.0098494754255446,36.47830916146919,181.5053177685852,0.0030973950997236
0.0031412929553427,183.759604858611,0.0100311121092209,37.04593633949598,184.3401759444324,0.0031544249549081
0.0031955612724814,186.558857647273,0.0102034140161362,37.61026570169023,187.1583969426911,0.0032085208932133
0.0032429398595015,189.321844775711,0.0103538410299251,38.16728390678334,189.93923321171096,0.0032557465935075
0.003293934971307,192.047282331366,0.0105157505099075,38.716732118003385,192.6833520343904,0.0033065746563617
0.0033567707095176,194.744360913734,0.0107152539787262,39.26046316020877,195.4016003745577,0.003369201005569
0.0034182394083144,197.420401603069,0.010910417097406,39.79995296317871,198.09880756370737,0.0034304610760175
0.0034752432297723,200.071219616253,0.0110914042305349,40.3343578746366,200.77013954433488,0.0034872680695661
0.0035287290376086,202.7525548699,0.0112612216704151,40.87491506177184,203.4716860398632,0.0035405662625224
0.0035825034456523,205.358919533584,0.0114319554159539,41.40035817797053,206.09833812015924,0.0035941491797711
0.0036410523410132,207.894136173451,0.0116178481587247,41.91145785256772,208.6548550733415,0.0036524863177358
0.0037053163784326,210.38107809984,0.0118218864775313,42.41282534492776,211.1644170674989,0.0037165140099621
0.0037601382879961,212.843229901334,0.0119959460403954,42.90919514810894,213.6474049882505,0.003771131059737
0.0038075648626503,215.23495978686,0.0121465254149225,43.391367893030974,216.0583792858304,0.0038183780032214
0.0038644017621929,217.491865477837,0.0123269825709703,43.84636008033194,218.3362807329781,0.0038749966889434
0.0039158944445288,219.598826047615,0.0124904718373867,44.27112333119919,220.4627293396688,0.0039262889079352
0.003983346912303,221.683977040748,0.0127046334225698,44.6914897714148,222.57103646246773,0.0039934748000462
0.0040430448052748,223.663195554463,0.0128941742327553,45.090500223779735,224.5715269601115,0.0040529329987061
0.0041030255916463,225.599115619115,0.0130846132294848,45.48078170881359,226.5288407129071,0.0041126693946805
0.0041594585773849,227.449249121153,0.0132637879592049,45.85376862282445,228.39943451070368,0.0041688691875695
0.0042280164219868,229.228415106777,0.0134814591158159,46.21244848552624,230.20174849463376,0.0042371394879379
0.0042917034103981,230.93518366882,0.0136836653040218,46.55653302763412,231.9304717822836,0.0043005551857688
0.0043690702482082,232.585321388013,0.0139293050140688,46.88920079182343,233.60571568200004,0.0043775870506096
0.0044317930445795,234.191873888455,0.0141284498925477,47.213081775912535,235.2340055909668,0.0044400339227442
0.0045088225199202,235.720614580124,0.0143730184767544,47.52127589935299,236.7877064694821,0.0045167192023634
0.0045887713953258,237.240695907629,0.0146268561561672,47.827724294978005,238.3336362331188,0.0045963046184271
0.0046856586439889,238.640855386192,0.0149344731706726,48.109996445856304,239.7633673396381,0.0046927429153143
0.0047799980859044,239.943495138218,0.0152340008987543,48.37260861986475,241.0947705462765,0.0047866362755035
0.0048855250958998,241.242850072431,0.0155690491554897,48.63455857460209,242.4258175657186,0.0048916538585303
0.0049950139194567,242.412788714727,0.0159166761702828,48.87041820488896,243.62803465409945,0.0050006024733513
0.0051246773487792,243.45606262369,0.0163283575583818,49.0807422249359,244.70810597495785,0.0051296108039603
0.0052506896214665,244.411929755538,0.0167284465241639,49.27344503871647,245.69968783326505,0.0052549704799232
0.0053838177508865,245.220552788176,0.0171511283350724,49.43646344209628,246.5452170940869,0.0053873920917564
0.0055221928087531,245.894286861511,0.0175904691437989,49.572288231280616,247.25661626802247,0.0055250142030706
0.0056702209288554,246.499455131692,0.0180604584251237,49.69429015454911,247.9016262060925,0.0056722158861893
0.0058290273136378,246.958704621445,0.0185646686968078,49.78687485168332,248.4027066791112,0.0058301115705909
0.005995028454263,247.360743079019,0.0190917223182928,49.86792580473024,248.84815807722725,0.0059951341048095
0.0061606732145912,247.657339738449,0.0196176444323349,49.92771969127132,249.18756135484173,0.0061597752193254
0.0063364933906418,247.978453037773,0.0201758734912955,49.99245613241504,249.5542583596808,0.0063345004459902
0.0065169676432459,248.176333268356,0.0207488792433135,50.03234878690057,249.79818547939016,0.0065138190190366
0.0066909698716828,248.373492656266,0.0213013363186007,50.07209611950322,250.0398508608949,0.0066866765711621
0.0068759566806312,248.531280445295,0.0218886694370119,50.10390613777148,250.24467226968065,0.0068704136787829
0.0070610578201665,248.643600789902,0.0224763655550364,50.12654991924425,250.40379117235065,0.0070542305601975
0.0072438985536564,248.783759265869,0.0230568848838669,50.1548058679992,250.59042965905604,0.0072357695523948
0.0074279470761335,248.933342900523,0.0236412389427317,50.18496192874544,250.78691538566449,0.0074184744570749
0.0076111288470409,248.980974196861,0.0242228410653627,50.19456439808718,250.8805101232452,0.00760028579816
0.0077776028531999,249.093266176454,0.0247513960349175,50.21720246117313,251.035126359372,0.0077654857040112
0.0079674404189829,249.212332281517,0.0253541303062785,50.24120618795383,251.20243053241373,0.0079538370587387
0.0081503151741584,249.338302893726,0.0259347576539607,50.266601863375165,251.375004770702,0.0081352465715531
0.0083254606971381,249.461108387265,0.0264908446894213,50.29135945087263,251.5425053883163,0.0083089579339016
0.0085077091729438,249.535238602802,0.0270694836001044,50.30630410232489,251.66273153162305,0.0084896820569186
0.0086939029406688,249.654363111795,0.0276606488126312,50.33031960333788,251.8293557614254,0.008674284749611
0.0088784426491954,249.777269267658,0.0282465623872032,50.35509748435985,251.99942650207507,0.0088572138982509
0.0090821317157929,249.88774302547,0.0288932751736503,50.37736899393475,252.16178249688963,0.009059086435776
0.009268858309494,249.936585069672,0.0294861321086512,50.38721555004588,252.25773882278992,0.0092441119778088
0.0094580308194191,249.964685349158,0.0300867548276634,50.392880566390254,252.3333865156696,0.0094315262506053
0.0096470020372675,250.038233747115,0.0306867384443321,50.40770792341839,252.45488189832147,0.009618706040704
0.009830684738289,250.160184379377,0.0312699310200754,50.4322931708824,252.62396129575885,0.009800613875524