File: example/data/02 processed data/test_ID_137.csv
Strain,Stress_MPa,Displacement(mm),Force(kN),True Stress (MPa),True Strain
-6.47587691128302e-06,-7.28185570038747,-2.0560909193323587e-05,-1.4680221091981138,-7.281808543986268,-6.475897879853017e-06
3.49499290908434e-05,-6.8893197415539,0.00011096602486342779,-1.3888868598972661,-6.889560522790351,3.4949318356268946e-05
8.13476610202269e-05,-5.76449299291441,0.00025827882373922036,-1.162121787371545,-5.764961920936351,8.134435247864255e-05
0.0001223617925968,-4.49250587265798,0.00038849869149483994,-0.9056891839278488,-4.493055583729809,0.00012235430700320953
0.0001438728345958,-3.34811731288043,0.0004567962498416649,-0.6749804502766946,-3.348599016008793,0.00014386248589203423
0.0001297859343,-2.92994393800308,0.0004120703414024999,-0.590676697901421,-2.93032420351452,0.0001297775128341882
0.0001383369199574,-2.92192907077902,0.000439219720864745,-0.5890609006690505,-2.9223332814470058,0.000138327352288113
0.0001373078116948,-2.91362809286959,0.00043595230213098996,-0.5873874235225093,-2.9140281567671145,0.0001372983858400963
0.0001355439522336,-2.9069302508202,0.00043035204834168,-0.5860371385653523,-2.907324267635264,0.0001355347669821971
0.0001617743622764,-2.90144701489566,0.0005136336002275699,-0.5849317182029651,-2.9019163946361735,0.0001617612782153254
0.0001608064939489,-2.89684895826628,0.0005105606182877574,-0.5840047499864821,-2.8973147903907583,0.00016079356597056374
0.0001304323760267,-2.88901513530935,0.0004141227938847725,-0.582425451278365,-2.8893919564178256,0.0001304238704639579
0.0001315749632052,-2.87097937775882,0.00041775050817651,-0.5787894425561781,-2.8713571267648113,0.00013156630797887779
0.0001445979749861,-2.80447980611473,0.00045909857058086745,-0.5653831289127296,-2.8048853282155832,0.00014458752170660077
0.0001408287836029,-1.98008891312176,0.0004471313879392075,-0.3991859248853469,-1.9803677666348205,0.00014081886816064986
0.0001332941756036,0.0018592484507459,0.00042320900754142996,0.00037482448767037343,0.0018594962777353844,0.00013328529272431695
0.0001085026423271,3.29383052266496,0.00034449588938854247,0.6640362333692559,3.2941879119800466,0.00010849675634115424
5.22234158312192e-05,7.28413882825025,0.00016580934526412095,1.4684823877752504,7.28451923086125,5.222205223600333e-05
5.57527789504727e-05,11.3785324503388,0.00017701507316775081,2.293912141988302,11.379166835143284,5.575122482200822e-05
4.97569754551458e-05,15.1897446433402,0.0001579783970700879,3.0622525200973842,15.190500439091588,4.975573761793029e-05
5.5545147052536e-05,19.0002206730283,0.0001763558418918018,3.830444487682505,19.001276043079613,5.554360447796788e-05
8.613497095515e-05,22.8437905455466,0.0002734785327826012,4.605308173982195,22.845758194781745,8.613126155150358e-05
0.0001049610459044,26.6659139567326,0.00033325132074647,5.375848253677292,26.668712838951492,0.00010495553787913158
0.0001732331043427,30.3761848999142,0.0005500151062880725,6.123838875822703,30.3814470607225,0.00017321810122114244
0.0002256521964541,34.0130340365078,0.0007164457237417674,6.857027661759973,34.0207091523462,0.00022562674082655373
0.0002903949204883,37.5494461413917,0.0009220038725503524,7.569968342104566,37.560350309818304,0.00029035276404443743
0.0003421263910544,40.9401900971519,0.00108625129159772,8.253542323585823,40.95419681663892,0.0003420678791658862
0.0004166500855262,44.3992576126585,0.001322864021545685,8.950890334711955,44.41775656714012,0.0004165633109816309
0.0005016793895743,47.6897789573078,0.0015928320618984024,9.614259437793253,47.71370393650403,0.0005015535905413732
0.0005934030209625,50.9071652232324,0.0018840545915559375,10.262884509003653,50.9373736888645,0.0005932270270099229
0.0006899399688442,53.9907399935669,0.002190559401080335,10.884533182703088,54.02799036303594,0.0006897020696817557
0.00080048817503,56.7732969744529,0.0025415499557202496,11.445496670049705,56.81874332733842,0.0008001679552476131
0.0009352867175724,59.4427427692305,0.0029695353282923696,11.983656942276868,59.49833877699864,0.0009348496094768127
0.0011057856011699,61.812173233899,0.0035108692837144324,12.461334123954039,61.88052424503806,0.001105174670602602
0.001285332544575,64.061345705964,0.004080930829025625,12.914767294322344,64.14368583844914,0.0012845072118422122
0.0015256853386844,65.8314594390811,0.0048440509503229695,13.27162222291875,65.93189753157151,0.0015245226632424815
0.0017574342156485,67.2094191734033,0.005579853634683987,13.549418905358108,67.32753530627251,0.0017558917350783887
0.002058674075629,68.1304573658806,0.0065362901901220745,13.73510020496153,68.27071577222048,0.0020565579099866746
0.0023164573986156,68.7379313865793,0.007354752240604529,13.857566967534387,68.89715987630528,0.0023137785473414632
0.0026720784648285,69.1592691462865,0.008483849125830487,13.94250865989136,69.34406814001557,0.0026685148099992975
0.0030073928160949,69.4224592084111,0.009548472191101307,13.995567776415678,69.63123981351012,0.0030028796566179917
0.0034194990578964,69.6410142008079,0.010856909508821068,14.039628462882872,69.87915158325852,0.003413665864942396
0.0037753380314115,69.7799645308078,0.011986698249731512,14.067640849410852,70.0434074847315,0.0037682293290043764
0.0041430545609592,69.9441894006033,0.01315419823104546,14.100748583161627,70.23397199351206,0.00413449574203698
0.0045333824503494,70.0780276459833,0.014393489279859345,14.127730373430234,70.3957181466687,0.004523137622940598
0.0048974292790805,70.0295064993103,0.015549337961080587,14.117948510260959,70.37247105483958,0.0048854758836946975
0.0052497935027179,70.1088120090781,0.016668094371129333,14.133936501030144,70.47686879484661,0.005236061376391941
0.0055850407041257,70.1822723080778,0.017732504235599095,14.148746097308486,70.57424315562645,0.005569502192923611
0.0059684484348569,70.1963998027613,0.018949823780670658,14.15159420023668,70.6153633952967,0.005950707800872228
0.0063560713668438,70.4794180532577,0.02018052658972906,14.208650679536754,70.92739026429783,0.006335956733603157
0.0067567020749606,70.5079710258642,0.021452529087999904,14.214406958814223,70.98437237999592,0.006733977866538363
0.0071500402059065,70.5447287940754,0.022701377653753137,14.2218173248856,71.04912644126782,0.007124599862770418
0.0075065416435469,70.5762211251979,0.023833269718261406,14.228166178839897,71.10600446811837,0.007478507764070461
0.0079431598127353,70.5701958284125,0.025219532405434574,14.22695147900796,71.1307461718936,0.007911778984585872
0.0083222627161769,70.5722398729224,0.026423184123861656,14.227363558381155,71.15956059361392,0.00828782362997148
0.0087164862867937,70.6149222567123,0.02767484396057,14.2359683269532,71.23043625820594,0.008678717038272398
0.0090907521274139,70.6565271290807,0.02886313800453913,14.244355869222671,71.29884810339507,0.00904967997049621
0.0094781246405707,70.723494651512,0.030093045733811972,14.257856521744818,71.39382074883576,0.009433489036781052
0.009873699900528,70.7479821108169,0.0313489971841764,14.262793193540688,71.44652645474703,0.00982527343037692
0.0103212811143081,70.6968908241912,0.032770067537928216,14.252493190156947,71.42657330829522,0.010268380383230108
0.0107383341064352,70.7153545946216,0.034094210787931754,14.256215486275714,71.47471969871368,0.010681087653125356
0.0111336357114359,70.6912712893979,0.035349293383808975,14.251360291942618,71.47832215191235,0.011072113015698966
0.0114918639290957,70.6292439675389,0.036486667974878845,14.238855583855841,71.44090562862876,0.011426334023462445
0.0118620867775262,70.5897235648334,0.03766212551864569,14.230888270670414,71.42706499136104,0.011792283690778659
0.0122363697824623,70.5320760460054,0.038850474059317804,14.21926653087469,71.39513261002908,0.012162110571471315
0.0126341510400124,70.5567666542915,0.040113429552039365,14.224244157505167,71.44819150109672,0.012555006076222319
0.0130408501655582,70.5771059634211,0.041404699275647286,14.228344562225695,71.4974914274088,0.012956550381965706
0.01345136996545,70.5524780311758,0.04270809964030375,14.22337957108504,71.50150551515242,0.013361703484878498
0.0138636732941891,70.5156313406211,0.04401716270905039,14.215951278269213,71.49323701566095,0.013768451647473489
0.0142736055510969,70.4716447949435,0.04531869762473266,14.20708359066061,71.47752925528353,0.014172696731636195
0.0146861176621187,70.3994301883455,0.04662842357722687,14.192525125970453,71.43332450343766,0.014579320985421229
0.0151005324511907,70.3389700760956,0.04794419053253047,14.180336367340875,71.40112597631303,0.014987654338886866
0.0155127779151028,70.2712138490212,0.04925306988045138,14.166676711962673,71.36131558328576,0.015393684839594232
0.0159423214056176,70.2485956429458,0.05061687046283588,14.162116881617875,71.36852133297891,0.015816577274735937
0.0163507589007992,70.2535906099368,0.05191365951003746,14.163123866963259,71.40229013191532,0.01621852471493389
0.0167614584143332,70.1683373079357,0.053217630465507905,14.145936801279838,71.34446097572557,0.016622535389428508
0.0171776936851624,70.0948828071601,0.054539177450390615,14.131128373923477,71.29895123291885,0.017031825191643254
0.0175789135551718,69.998267877033,0.05581305053767046,14.111650804009853,71.22876137705512,0.01742619164685633
0.0179737840212421,69.9242639092617,0.05706676426744367,14.096731604107159,71.1810675266111,0.017814165361802248
0.0183790061344792,69.8788067910423,0.05835334447697145,14.087567449074127,71.16310980972496,0.01821215349091703
0.0187661921257614,69.8051324287573,0.05958265999929244,14.072714697637473,71.11510895527958,0.018592279557802162
0.0191837632304584,69.7509002587868,0.06090844825670541,14.06178149217142,71.08898501446268,0.019002074812531685
0.0196048269648549,69.6901799898068,0.0622453256134143,14.04954028594505,71.05644390965655,0.01941512768364167
0.0200302296519342,69.6623934709556,0.06359597914489108,14.04393852374465,71.05774721028224,0.019832263770675974
0.0204522319810896,69.5958863307614,0.06493583653995948,14.030530684281498,71.01927754292768,0.02024589372644086
0.020874731602747,69.5341430081897,0.06627727283872172,14.018083230451044,70.98564958071267,0.020659839787240973
0.0212976545611341,69.4495243924604,0.06762005323160077,14.001024117520018,70.92863637240607,0.02107402907635164
0.0217446543726541,69.3591491634759,0.06903927763317677,13.982804471356742,70.86733988961704,0.02151161161362745
0.0221784927098718,69.3090414797803,0.07041671435384296,13.972702762323708,70.84621155096782,0.02193612693295569
0.022633952687442,69.2822957340234,0.07186279978262836,13.967310819979119,70.85042793774466,0.022381605427697383
0.0230614010033116,69.2423088097849,0.07321994818551432,13.959249456052637,70.8391334596425,0.022799505699425873
0.0234818289326652,69.1354669493589,0.074554806861212,13.937710136990754,70.75889415744368,0.023210372109788636
0.0239145419948128,69.0387278202984,0.07592867083353064,13.91820752857216,70.68975737602538,0.0236330680515562
0.0243365061452786,68.9284978318089,0.07726840701125955,13.895985162892673,70.60597664287754,0.024045091916324507
0.0247770585614339,68.9282098046237,0.07866716093255263,13.895927096612139,70.63604809548768,0.024475085090476863
0.0252231584178844,68.8787862626402,0.08008352797678296,13.885963310548266,70.61612680017437,0.024910304423428203
0.0256657027418481,68.8241542750753,0.08148860620536771,13.87494950185518,70.59057456015847,0.02534186786815044
0.0261051358646875,68.7600362143251,0.08288380637038281,13.86202330080794,70.55502630176089,0.02577021310173102
0.0265596899043627,68.684248358774,0.08432701544635157,13.84674446912884,70.50848069649727,0.026213104743268337
0.0270060411423602,68.5860591214918,0.08574418062699364,13.826949518892748,70.43829705591916,0.02664781324884803
0.0274668043943683,68.4807284374174,0.08720710395211935,13.805714852983346,70.36167521019179,0.0270963597075994
0.0279185688339232,68.4070482606669,0.08864145604770615,13.790860929350448,70.31687514625783,0.027535950698869643
0.0283570561265126,68.3287352217013,0.0900336532016775,13.77507302069498,70.2663370014367,0.027962437589939194
0.0287971534284722,68.2389458569677,0.09143096213539924,13.75697148476469,70.204033250608,0.02839030761215688
0.0292610923212695,68.1829883011866,0.09290396812003066,13.74569044151922,70.17809701660765,0.028841158701152166
0.0297057645248601,68.1135940027342,0.0943158023664308,13.731700550951217,70.13696038712135,0.029273095921535937
0.0301518711304795,68.0467717769759,0.09573219083927241,13.718229190238342,70.09850927044043,0.029706239071695513
0.0306118717640156,67.9717147737597,0.09719269285074952,13.703097698389957,70.05245618999427,0.030152676119864837
0.0310707458589673,67.8929819238838,0.09864961810222117,13.687225155854975,70.00246751084826,0.030597821360559743
0.0315442170872829,67.8303303915359,0.1001528892521232,13.674594606933637,69.96998505850863,0.0310569193940146
0.0320099990394684,67.7708563022033,0.10163174695031216,13.662604630524186,69.94020134734077,0.031508356004165995
0.0324871192031129,67.6949687561783,0.10314660346988347,13.647305701245546,69.89418327561127,0.031970570427158264
0.0329714173343685,67.6044553280668,0.10468425003661999,13.629058194138267,69.83347003835117,0.032439520184864665
0.0334450590163613,67.5143647480306,0.10618806237694713,13.610895933202968,69.77238666148062,0.0328979386070056
0.0339312695802646,67.4223143845105,0.1077317809173401,13.592338579917316,69.71003910961669,0.03336830345170486
0.0343960245466905,67.3465223386463,0.10920737793574234,13.577058903471093,69.66297497414061,0.0338177052224666
0.0348629748796523,67.269180169256,0.11068994524289605,13.561466722122011,69.61438390767158,0.034269026532188884
0.0353462379392494,67.1802593849801,0.11222430545711685,13.54354029201199,69.5548288180221,0.034735900184747974
0.0358054576072565,67.0926688789624,0.11368232790303938,13.52588204599882,69.49495259026578,0.03517934397162241
0.0362686136151377,67.0007477005236,0.1151528482280622,13.507350736425558,69.43077193079922,0.03562638978144872
0.0367123308407666,66.901247707295,0.11656165041943393,13.487291537790673,69.3573484467853,0.03605448559544266
0.037199326377752,66.8134229660193,0.1181078612493626,13.469586069949491,69.29883729334703,0.03652412521990907
0.0376911941993672,66.7351152217905,0.11966954158299085,13.453799228712965,69.25044140953214,0.03699823971024096
0.038179840133702,66.6848401691909,0.12122099242450385,13.443663778108887,69.23085670619207,0.03746902612739139
0.0386896956284312,66.6073393201119,0.12283978362026905,13.428039606934561,69.18435700502668,0.03796001075227268
0.039166060711434,66.515543623687,0.12435224275880294,13.409533594535299,69.12069544350635,0.03841852678727171
0.0396394265424858,66.4163564584506,0.1258551792723924,13.389537462023641,69.0490627415049,0.03887394778951163
0.040101026767745,66.3377634480956,0.12732075998759035,13.373693111136074,68.99797587584003,0.03931784955821976
0.0405873501118387,66.2750668130358,0.12886483660508785,13.36105346950802,68.964996153462,0.0397853134594495
0.0410962400363942,66.219017102848,0.13048056211555156,13.349753847934158,68.94036972468072,0.04027423496231475
0.0415944548258759,66.1277494508487,0.13206239407215598,13.331354289291099,68.87829713811887,0.0407526687501204
0.0421028806206056,66.0267445829797,0.13367664597042275,13.310991707928709,68.80666072792411,0.041240672258279355
0.0425968301155526,65.9240808545821,0.1352449356168795,13.290294700283752,68.73223772726868,0.04171455298234402
0.0430629995128152,65.8308878998543,0.13672502345318824,13.271507000610628,68.66576339341391,0.04216157641195907
0.0435692718087284,65.7726852782217,0.13833243799271266,13.259773352089494,68.6383532806985,0.042646829432154115
0.0440757163642867,65.7071934606538,0.13994039945661027,13.246570201667806,68.60328508271888,0.04313201208376608
0.0445827876793676,65.6551533604422,0.14155035088199214,13.236078917465148,68.58224312276711,0.04361755945693541
0.04509390107763,65.5740994181413,0.14317313592147524,13.219738442697288,68.53109137055763,0.044106738870386776
0.0455868905082526,65.4170852652376,0.144738377363702,13.188084389471902,68.39924676859302,0.04457834547981663
0.0460802215337054,65.2628224914519,0.14630470336951462,13.156985014276705,68.27014780977291,0.04505005632879482
0.0465593471364579,65.1578898546457,0.14782592715825382,13.135830594696575,68.19159866706724,0.04550797141202051
0.0470467913956546,65.1209458448797,0.14937356268120333,13.128382682327747,68.18467739953148,0.0459736218120966
0.0475638659177802,65.0799609764454,0.15101527428895214,13.120120132851394,68.17541551426342,0.04646734080547946
0.0480903763249642,65.0458713008176,0.15268694483176132,13.113247654244827,68.1739517300591,0.04696981913196008
0.0486133802627965,64.9669353344436,0.15434748233437887,13.097334163423833,68.12519766636542,0.0474687011958056
0.0491288492614908,64.8987509645572,0.15598409640523328,13.08358819445473,68.08715191795395,0.04796015243496562
0.0496435553304843,64.831708519976,0.15761828817428764,13.070072437627164,68.05018502905727,0.04845063542224542
0.0501754143235091,64.7528754923806,0.1593069404771414,13.054179699263928,68.00187784884939,0.048957211476738524
0.0507393237698636,64.6744182936486,0.16109735296931693,13.038362727999559,67.95595454307762,0.049494034270802525
0.0512550429930362,64.6014240289364,0.16273476150288993,13.02364708423358,67.9125727949509,0.04998472943314476
0.0518023531181567,64.523539977342,0.16447247115014751,13.007945659432146,67.86601117968176,0.05050521940026439
0.0523320907616601,64.4075786636502,0.1661543881682708,12.984567858591882,67.7781619160151,0.05100874012940447
0.0528762377558145,64.3159295469786,0.16788205487471103,12.966091396670887,67.71671392919085,0.05152569324886688
0.0534315389796413,64.2298897979063,0.16964513626036112,12.948745783257909,67.6617916583012,0.05205296779328588
0.0539858163894717,64.1664565122876,0.17140496703657263,12.93595763287718,67.63053505192298,0.05257899309264015
0.0545434826556847,64.0940440839282,0.1731755574317989,12.921359287319925,67.58995646575262,0.053107955416728816
0.055089832384336,64.003744410513,0.17491021782026678,12.90315487315942,67.52969996205805,0.053625912482509676
0.0556274816427777,63.8928446215771,0.17661725421581917,12.880797475709942,67.44704266286872,0.054135359452501294
0.0561679081922746,63.7803627782792,0.17833310851047185,12.858121136101087,67.36277233927954,0.054647176614235314
0.0566922464440189,63.6208240916218,0.17999788245976,12.825958136870954,67.2276315299956,0.05514350691925598
0.0572047193947126,63.5152350049019,0.18162498407821248,12.804671376988225,67.14860620064654,0.05562836778902879
0.057758924153743,63.3994595916928,0.18338458418813403,12.78133105368527,67.06134416963769,0.056152447503974176
0.0583044499169046,63.3694065681786,0.1851166284861721,12.775272364144806,67.06412495969693,0.0566680518870297
0.0588542531362545,63.3116311473496,0.18686225370760803,12.763624839305681,67.03778991336489,0.05718743026987504
0.0593971902563268,63.2525678386399,0.1885860790638376,12.751717676269806,67.00959264475281,0.05770005792194682
0.0599488327003277,63.1616735955171,0.19033754382354043,12.733393396856247,66.94814219896746,0.05822063592146505
0.0605042958106028,63.0797249888711,0.19210113919866387,12.716872557756416,66.89631932924922,0.05874454575518114
0.0610954085460107,63.0109542512466,0.19397792213358395,12.703008377051315,66.86063424410051,0.05930177881803419
0.0616606357122974,62.9510999965635,0.19577251838654425,12.690941759307202,66.83270484114,0.05983431969212439
0.0622300626903518,62.8975967624281,0.19758044904186695,12.680155507305505,66.81171815202647,0.0603705308936955
0.0627814254512732,62.815970647481,0.1993310258077924,12.663699682532169,66.7596468258352,0.06088945775726412
0.0633485148927881,62.7148570263679,0.20113153478460222,12.643315176515769,66.68775008070185,0.061422905355364314
0.0639241618806292,62.6206669395205,0.2029592139709977,12.624326455007333,66.62364059003536,0.06196411195118728
0.0645298180989926,62.5257129650786,0.2048821724643015,12.605183733759846,66.56048584922495,0.06253321632497867
0.0651288646011249,62.4487925230985,0.20678414510857152,12.589676572656659,66.51601147583912,0.06309579146699369
0.0657262368033032,62.3774361835905,0.20868080185048762,12.575291134611843,66.4772703253761,0.06365647925607341
0.0663056365512717,62.2902926767941,0.21052039605028763,12.55772300364169,66.42049018369396,0.06419999811193412
0.0668677400320419,62.1837488320905,0.21230507460173303,12.536243764549445,66.34183558321251,0.06472700965253414
0.0674132611528072,62.0922960916846,0.21403710416016283,12.517806892083616,66.27814026369076,0.06523820862993422
0.0679926790608237,61.9847502748873,0.2158767560181152,12.496125655417279,66.199259506993,0.06578088570254587
0.068577714104217,61.9299794385345,0.21773424228088895,12.485083854808556,66.17699586295036,0.06632852509686335
0.0691739129679304,61.8269873877308,0.21962717367317902,12.46432065736653,66.10380203235901,0.06688630633919347
0.0697698804584659,61.760847858189,0.22151937045562922,12.450986928210902,66.06989483026835,0.0674435603519351
0.0703662088479616,61.6456903862405,0.2234127130922781,12.427771181866085,65.98346391053548,0.0680008411789894
0.070962742733974,61.5583803388578,0.22530670818036744,12.410169476313733,65.9267318459643,0.0685580034972812
0.0715529356591407,61.472641366567,0.2271805707177717,12.392884499499909,65.87118931906639,0.06910893803283394
0.0721280368540172,61.3892139691681,0.2290065170115046,12.376065536184287,65.8170974567754,0.06964549288035815
0.0727142207855447,61.3069455831577,0.2308676509941044,12.359480229564593,65.7648323599788,0.07019209153490645
0.0732748226654382,61.1140768694293,0.23264756196276626,12.320597896876945,65.5922000143987,0.07071455635769451
0.0738605097103817,61.0193924068354,0.2345071183304619,12.301509509218018,65.52631583222205,0.07126010842480313
0.0744462718750144,60.9444457647742,0.23636691320317071,12.28640026617848,65.48153254345065,0.07180543294192505
0.0750736636808372,60.922014092601,0.2383588821866581,12.281878041068362,65.49565288934815,0.0723891835862069
0.0756811542323399,60.9134001405256,0.24028766468767918,12.280141468329962,65.52339657137695,0.07295409276376487
0.0762958099493996,60.8490191782277,0.24223919658934373,12.267162266330704,65.49154438105712,0.07352534026687939
0.0769140468288398,60.7457642421179,0.24420209868156637,12.246346071210969,65.41796679768981,0.07409958703106098
0.0774522544158811,60.6776753886337,0.2459109077704225,12.232619358348554,65.3772981401984,0.07459923056700654
0.078101699953347,60.5980878285615,0.2479728973518767,12.216574506237999,65.33090150189439,0.07520180936657751
0.0787181855828721,60.5099940789251,0.24993023922561888,12.1988148063113,65.27323102244841,0.07577347105279247
0.079351642729868,60.4518444533851,0.2519414656673309,12.187091841802438,65.24879761681166,0.07636053005976073
0.0800278533938678,60.3329634334211,0.25408843452553026,12.163125428177693,65.16128098588851,0.07698683098307464
0.0806587863056671,60.2350503020456,0.25609164652049304,12.143386140892394,65.09353635246941,0.0775708424895462
0.0812870688161374,60.1328989774861,0.2580864434912362,12.122792433861198,65.02092607478285,0.0781520619744549
0.0819199643939512,60.0192718144044,0.26009588695079505,12.099885197783927,64.93604842439129,0.07873720762732665
0.0825450646364126,59.9472960881402,0.26208058022061,12.085374891369066,64.89564951851389,0.07931481017710813
0.0831792320126772,59.901934177734,0.26409406164025007,12.076229930231175,64.88453105871186,0.07990045018250598
0.0837929701993542,59.8139082527015,0.26604268038294954,12.058483903744623,64.82589328442702,0.08046689787616913
0.0844233152208589,59.7925147874619,0.268044025826227,12.05417098115232,64.84039711121166,0.0810483389837762
0.0850764487799809,59.6515228491806,0.2701177248764393,12.025747006394809,64.72646257750678,0.08165044421530596
0.0857100412784009,59.5540886153794,0.27212938105892287,12.006104264860488,64.65847200890111,0.08223418888048926
0.0863762224552427,59.4837268255886,0.27424450629539554,11.991919328038662,64.62170644634253,0.08284759103569182
0.0870203803291965,59.3669291383809,0.2762897075451989,11.96837291429759,64.53306189097925,0.08344035711620384
0.0876446379597668,59.2728780789783,0.2782717255222596,11.949412220722026,64.46782801904375,0.08401447555970414
0.0882794728785081,59.1679691060725,0.2802873263892632,11.928262571784217,64.39128623004844,0.084597983903209
0.0889256747669189,59.0732870634656,0.2823390173849675,11.909174671994665,64.32641897628417,0.08519159071888714
0.089558658469283,58.9682732027983,0.2843487406399735,11.888003877684136,64.24939264309108,0.08577271375981999
0.0901794996781694,58.8485962669547,0.28631991147818786,11.863877007418068,64.15553323507127,0.08634236128684476
0.0908131927823854,58.7711099377981,0.2883318870840736,11.848255763460097,64.10830207461413,0.08692346650947004
0.0914629762845125,58.7263886743029,0.2903949497033272,11.839239956739465,64.09767896889574,0.08751897640005163
0.0921389853597075,58.6687434130467,0.2925412785170713,11.827618672070214,64.07442190345384,0.08813814519424222
0.0927948706223925,58.5920807078097,0.2946237142260962,11.812163470694436,64.02912525658768,0.08873851602980794
0.0934864830212463,58.4926362930759,0.296819583592457,11.792115476684101,63.96090714275647,0.0893711998522918
0.0941318946509117,58.3885847751839,0.2988687655166446,11.771138690677073,63.88481288605734,0.08996125857092288
0.0947847125354532,58.3054938859191,0.3009414623000639,11.754387567401292,63.83196336313357,0.09055773438160789
0.0954139820116313,58.1449727169968,0.3029393928869294,11.722026499746555,63.692816097883124,0.09113235758365772
0.0960352558774247,58.0691159161766,0.3049119374108234,11.706733768701204,63.645798321762456,0.091699355779825
0.096745911459259,57.9896830078952,0.3071682688831473,11.690720094391672,63.599947745727526,0.0923475331878592
0.0974209537079617,57.990904061905,0.30931152802277834,11.69096625888005,63.6404332420027,0.09296283941704062
0.0981207769357822,57.9123645348883,0.31153346677110844,11.67513269023348,63.59477073723977,0.09360033424736282
0.098784572015702,57.7909066184977,0.31364101614985385,11.650646774289138,63.49975659520539,0.09420463438294843
0.0994563354313582,57.668342215807,0.3157738649945623,11.625937790706692,63.40382420299266,0.09481581711027526
0.10015427378586,57.5592457719965,0.3179898192701055,11.603943947634496,63.32405023195265,0.09545041886660428
0.100843130155041,57.4836261136671,0.3201769382422551,11.588699024515288,63.280454903631345,0.0960763681661713
0.10153537211066,57.3799470301601,0.3223748064513455,11.567797321280278,63.20604130355737,0.09670499941888593
0.102203574845182,57.2762573246965,0.32449635013345285,11.546893476658816,63.130095577033025,0.09731142583424948
0.102882218677254,57.1512458440798,0.3266510443002814,11.521691162166489,63.031092816687924,0.09792695186547441
0.103545965334082,57.0415103937522,0.32875843993571036,11.499568495380442,62.94792865158734,0.0985285999786192
0.104207425572724,56.9517305465516,0.3308585761933987,11.481468878184803,62.8865237687192,0.09912781568917658
0.104860294200551,56.8606577928393,0.3329314340867494,11.463108611036402,62.823083097433276,0.099718896388959
0.105533376842503,56.787872280434,0.335068471474947,11.448435051735494,62.78088820588898,0.10032791248556985
0.1062182063831,56.6853915290448,0.3372428052663425,11.427774932255431,62.706412145383716,0.10094717693432283
0.106885157990215,56.532921478428,0.3393603766189326,11.397036970051087,62.5754517222982,0.10154990669204007
0.107560633717231,56.3952936632378,0.3415050120522084,11.369291202508741,62.461207188325,0.1021599697159309
0.108252579787137,56.299413938174,0.34370194082415995,11.349961849935879,62.39397073748523,0.10278452244283129
0.108973349669951,56.2204659043477,0.3459903852020944,11.334045926316497,62.34699839394974,0.10343467712362168
0.109699387031636,56.1984987884832,0.34829555382544425,11.329617355758215,62.36343965767795,0.10408915615118708
0.11040278813264,56.1251928164438,0.35052885232113196,11.314838871795072,62.32157058786121,0.10472282169361945
0.111084742879464,56.0194176830673,0.3526940586422982,11.293514604906369,62.24232029264813,0.10533678396774948
0.111776935244635,55.8948694756789,0.35489176940171613,11.268405686296868,62.14262668156918,0.1059595779043733
0.112489991332597,55.7729617990079,0.3571557224809955,11.243829098679994,62.046861788371565,0.10660073846281996
0.113181340586213,55.73659467193,0.35935075636122626,11.23649748586109,62.044937176609416,0.10722198856919178
0.113871553030014,55.5983088151567,0.36154218087029444,11.208619057135591,61.92937458578091,0.10784183237072718
0.114576388392742,55.5023553210912,0.36378003314695584,11.189274832731988,61.861614741072515,0.10847441199992117
0.115275889852128,55.3821031429533,0.3660009502805064,11.165031993619385,61.76632436463957,0.1091018091500874
0.115990852488811,55.2079870551583,0.3682709566519749,11.129930190319913,61.611608537877345,0.10974266723091224
0.116698764307652,55.1040533045563,0.37051857667679505,11.108977146198551,61.534628233541014,0.11037680091186633
0.117384672148984,54.9610627493075,0.37269633407302416,11.080150250260392,61.4126490810947,0.1109908405235393
0.118056882208061,54.8396462325614,0.3748306010105937,11.05567268048438,61.31384388817064,0.11159225197894339
0.118762749502673,54.7236849188695,0.37707172967098673,11.032294879644091,61.22282020275241,0.11222338674549849
0.119442881408549,54.6278037320685,0.37923114847214306,11.012965232385008,61.15270601484745,0.11283113423519935
0.120183765074116,54.538231678925,0.3815834541103183,10.994907506471279,61.09284170258263,0.11349274780704732
0.120858560089914,54.4023639089574,0.3837259282854769,10.96751656404581,60.97735527648149,0.11409496314998346
0.121560682811085,54.2734481608887,0.38595516792519485,10.941527149235162,60.87096557783835,0.11472118212873915
0.122244993871873,54.1683924458142,0.38812785554319673,10.920347917076143,60.79020724840197,0.11533113787411907
0.122953062996831,54.0655133223264,0.39037597501493837,10.899607485781003,60.7130337878024,0.11596187879808008
0.123678263806622,53.9802134558763,0.39267848758602486,10.882411032704663,60.65639253600994,0.11660746833146446
0.124358509394395,53.8597285042176,0.39483826732720406,10.858121266450269,60.55764405738891,0.11721265915097798
0.125080037850154,53.7305986603805,0.39712912017423896,10.832088689932709,60.451223974532326,0.11785417788140778
0.125784570680521,53.6190404887894,0.3993660119106542,10.809598562539943,60.363488476973245,0.1184801887491473
0.12654299451744,53.501902769037,0.40177400759287196,10.785983598237861,60.27219375781186,0.11915364662206329
0.127245076784353,53.3730417873868,0.4040031187903208,10.760005224337181,60.164498587837315,0.1197766708527464
0.127978801968057,53.2521566933033,0.4063326962485809,10.735634789369945,60.0673039091275,0.12042736031777462
0.128692750517121,53.1218881399827,0.40859948289185916,10.709372649020514,59.958290037379896,0.12106010509811073
0.129409384370687,52.9669805289729,0.41087479537693117,10.678143274640936,59.821404871201445,0.12169482738684455
0.130115309916156,52.8134708421683,0.41311610898379525,10.647195721781129,59.6853119685449,0.12231967169168612
0.130843960538556,52.6756236202315,0.41542957470991526,10.619405721838671,59.5679108385409,0.12296422169057189
0.131556975224078,52.5573077078509,0.41769339633644764,10.595553233902743,59.47158813581689,0.12359453853482144
0.132278883564153,52.3991725649661,0.4199854553161857,10.563673189097168,59.330476611545215,0.12423231301104305
0.132990690462407,52.2566212942148,0.4222454422181422,10.534934852913706,59.20626544136495,0.12486076529755492
0.13373461866901,52.0790618084505,0.42460741427410675,10.49913886058362,59.04383528004343,0.12551715558032644
0.134438178605874,51.9701081113937,0.42684121707364997,10.47717379525697,58.95687478783982,0.12613753155897667
0.135193698273226,51.8169850215831,0.4292399920174925,10.446304180351154,58.822314860019276,0.12680329564429388
0.135922914731375,51.6531003629891,0.4315552542721156,10.413265033178602,58.673940319238824,0.12744546124603595
0.136632518776102,51.4968394757232,0.4338082471141238,10.381762838305796,58.532982362299855,0.1280699600435802
0.137362431690561,51.3271186366484,0.4361257206175312,10.347547117148318,58.37753646424834,0.12871192535610382
0.13808296314166,51.1823006988188,0.43841340797477046,10.318351820881869,58.24970443971915,0.12934523563181338
0.13881462292771,51.039486688935,0.44073642779547917,10.289560516489296,58.12451378808339,0.12998791698534481
0.139530812290962,50.8821656686783,0.44301032902380433,10.257844598805546,57.981795575552276,0.13061660952315826
0.140266049697475,50.7351862926039,0.4453447077894831,10.228213556588946,57.85161045453293,0.1312616121058548
0.140992174923073,50.552667408786,0.44765015538075675,10.191417749611258,57.68019793491349,0.13189821276971972
0.14175844584212,50.3737610784091,0.45008306554873095,10.155350233407276,57.51466716010665,0.13256957033357955
0.14249044579789,50.2062021810663,0.4524071654083007,10.121570359702966,57.36010631166543,0.1332104812111164
0.143255354203667,50.0242461472599,0.4548357495966427,10.084888023287597,57.19048724785704,0.13387976686337874
0.143977057751002,49.9098509387535,0.45712715835943135,10.061825949252706,57.095724429706316,0.13451083834305394
0.144688061875996,49.7224379153252,0.45938459645628726,10.02404348372956,56.916681089043145,0.13513216484623697
0.145389196859106,49.4870915584575,0.4616107000276615,9.976597658185032,56.681980055034686,0.1357444891705302
0.146052220549553,49.2715803250925,0.4637158002448307,9.933150593538649,56.467804041557926,0.13632318492414003
0.146720755605564,49.0904361725837,0.46583839904766566,9.896631932392875,56.293022060831895,0.1369063521909479
0.147386189414999,48.9391122538268,0.46795115139262183,9.866125030371483,56.15206152227122,0.13748647669607758
0.148095254879358,48.7661748296642,0.4702024342419617,9.831260845660303,55.98821392055465,0.13810426908875723
0.148819705908191,48.5922019433856,0.4725025662585064,9.796187911786536,55.82367914603167,0.13873507263631835
0.149497177836055,48.3179395634006,0.47465353962947465,9.740896615981562,55.54133516698206,0.1393246100950362
0.150169948617489,48.1055076742462,0.4767895868605276,9.698070347128034,55.32950928990597,0.13990971286307452
0.150846062488054,47.9282908196705,0.4789362483995714,9.662343429245572,55.15808477160014,0.14049737838713844
0.151543122800798,47.7588137171451,0.48114941489253366,9.628176845376453,54.99633348910286,0.14110288881821206
0.152245045890369,47.6417752331038,0.48337802070192154,9.604581886993726,54.894999489766334,0.14171225309990293
0.152970896779772,47.4012136904224,0.48568259727577606,9.556084679989157,54.65221985709592,0.14234199966720323
0.153683139745272,47.1752498507836,0.48794396869123857,9.510530369917975,54.425290366119704,0.14295955477244035
0.154427390179067,46.9673332027281,0.4903069638185377,9.468614373669986,54.22037589289604,0.1436044549623923
0.155149993227687,46.7459801530734,0.49260122849790616,9.423989598859597,53.99861865724432,0.14423019980851864
0.155849431490297,46.5176879448069,0.49482194498169296,9.37796588967307,53.767443165248096,0.1448355121911054
0.156536307997659,46.2485321922898,0.4970027778925673,9.323704089965625,53.48810667198172,0.1454295969199933
0.157239565472143,46.0004118118929,0.49923562037405395,9.27368302127761,53.23349657673458,0.14603748423025859
0.157949051021878,45.7915930771159,0.5014882369944627,9.231585164346566,53.02433174842635,0.14665038079245638
0.158675112914364,45.5560246011671,0.5037934835031057,9.18409455959529,52.78463194868684,0.14727720833536312
0.159342974012815,45.3323303033563,0.5059139424906876,9.13899778915663,52.555718632824345,0.14785344293913738
0.160081679824123,45.0338913755588,0.5082593334415905,9.078832501312654,52.24299235597534,0.14849041628083445
0.160775688848434,44.7392969464054,0.5104628120937779,9.01944226439533,51.93228823155837,0.14908847892299848
0.161514604360996,44.4578721680623,0.5128088688461623,8.962707029081361,51.638467802018624,0.14972484685655008
0.162222388509189,44.1560141558568,0.515056083516675,8.901852453820732,51.31910823926545,0.1503340243772872
0.162969102406542,43.8964854529526,0.5174269001407709,8.849531467315243,51.05025628602211,0.1509763060353273
0.163644412472884,43.6440352284524,0.5195710096014067,8.798637502056005,50.786137731358345,0.15155681507216348
0.164336131656485,43.3526895913286,0.5217672180093399,8.739902221611846,50.477102895671905,0.15215108052313753
0.165002082662861,43.080066906874,0.5238816124545836,8.6849414884258,50.188367667763615,0.15272287470950896
0.165646602923064,42.8198316489548,0.5259279642807282,8.632478060429289,49.91279129934167,0.15327595701712485
0.166374401250203,42.5857153601427,0.5282387239693945,8.585280216604769,49.67088825499802,0.15390013522947
0.167085858791622,42.3421279565889,0.5304976016633998,8.536172996048322,49.416898769280294,0.15450992282743994
0.167769395467638,42.0598191520989,0.5326678306097506,8.47925954106314,49.11616958472472,0.15509542952580727
0.168494010596754,41.7735685297535,0.534968483644694,8.421551415598305,48.81216462827002,0.15571574926413034
0.169178910616205,41.4711323842625,0.5371430412064508,8.360580288667322,48.48717338305245,0.1563017166446248
0.169906434453519,41.1387195666612,0.5394529293899227,8.293565864638898,48.128452726215826,0.1569237750593018
0.170630202095087,40.8079841574089,0.5417508916519012,8.226889606133636,47.77105874128069,0.15754223806760154
0.171325571037129,40.4547763097584,0.5439586880428846,8.155682904047294,47.38571396220708,0.1581360741856481
0.172074547181024,40.1187954404917,0.5463366872997512,8.087949160803127,47.02221899936244,0.15877529594174086
0.172778564392719,39.7758647744151,0.5485719419468827,8.018814338522084,46.648281587617454,0.15937577469188036
0.173505477710768,39.444163660392,0.5508798917316884,7.951943393935028,46.287942119190035,0.1599954041384968
0.174203785105135,39.0914728941385,0.5530970177088036,7.8808409354583215,45.90135543763221,0.16059028820359
0.174895002385953,38.7274751200039,0.5552916325754008,7.807458984192786,45.50071697351892,0.16117878393177962
0.175618366577775,38.3346900080726,0.5575883138844355,7.7282735056274365,45.066965650555666,0.16179427859282652
0.176312478294407,37.9258127942414,0.5597921185847422,7.645843859319067,44.61260683932383,0.16238452701641198
0.177025939988328,37.5377098375503,0.5620573594629413,7.5676023032501405,44.18285820655176,0.1629908671077791
0.177647581702213,37.1277195108772,0.5640310719045263,7.484948253392844,43.7233690961026,0.163518873833638
0.178299146398817,36.7368537410352,0.566099789816244,7.406149714192696,43.287003404439965,0.16407199730238572
0.178933354090604,36.2372763865335,0.5681133992376677,7.305434919525155,42.721333793484185,0.16461009246860964
0.179586232051794,35.8576544937691,0.5701862867644459,7.228903145943851,42.297195554520165,0.16516372618164066
0.179982038060086,35.6917272524024,0.571442970840773,7.195452214084325,42.1155970651745,0.1654992163787399