File: example/data/02 processed data/test_ID_109.csv
Strain,Stress_MPa,Displacement(mm),Force(kN),True Stress (MPa),True Strain
6.33654282442129e-05,-0.150530972510061,0.00020118523467537597,-0.0303470440580283,-0.15054051096959814,6.336342074031078e-05
3.62652512541823e-05,0.324889210375194,0.0001151421727320288,0.06549766481163911,0.3249009925640381,3.6264593685893026e-05
2.05977093406127e-05,1.47273547487719,6.539772715644531e-05,0.2969034717352415,1.472765809854437,2.059749721069523e-05
-9.71335767811806e-06,4.13712758391816,-3.083991062802484e-05,0.8340449209179011,4.137087398518177,-9.713404853040305e-06
-2.99803458190926e-05,7.72323572888868,-9.518759797561901e-05,1.557004322943958,7.723004183610685,-2.9980795238686355e-05
-2.39376331953832e-05,11.4105162564021,-7.600198539534165e-05,2.3003600772906636,11.410243115649385,-2.393791970512817e-05
-2.54706305469071e-05,15.1313452036017,-8.086925198643003e-05,3.050479193046103,15.130959798698342,-2.5470954928938277e-05
9.68900247544931e-06,18.7060221243627,3.076258285955156e-05,3.7711340602715206,18.70620336705737,9.688955537362391e-06
4.61576011365649e-05,22.6798464778095,0.00014655038360859355,4.572257049926396,22.68089332511706,4.615653590728356e-05
8.63700907260364e-05,26.9261979040709,0.00027422503805516553,5.4283214974606935,26.928523522226783,8.636636104456331e-05
0.0001448603333059,31.250200324037,0.00045993155824623246,6.300040385325859,31.254727238471816,0.00014484984206093366
0.0002008562094595,35.672207448917,0.0006377184650339124,7.191517021701667,35.67937243328824,0.00020083604055174813
0.0002816856559115,40.1271102239688,0.0008943519575190126,8.08962542115211,40.13841345533207,0.00028164598995591793
0.0003591724940455,44.615868393164,0.0011403726685944623,8.994559068061863,44.63189318588878,0.0003591080070460927
0.0004399141248127,49.1129449578638,0.0013967273462803225,9.901169703505344,49.13455043606191,0.00043981739096267045
0.0005277630889048,53.6228237294478,0.0016756478072727397,10.810361263856677,53.65112387653506,0.0005276238709464721
0.0006147870810229,58.1712160786893,0.0019519489822477072,11.727317161463764,58.20697899082187,0.0006145981768653449
0.000702941790826,62.6252095348764,0.0022318401858725497,12.625242242231081,62.6692314118177,0.0007026948429651991
0.0007916162812121,67.1778812381993,0.0025133816928484174,13.543060857620981,67.23106034272479,0.0007913031183027159
0.0008858302422164,71.6622016774457,0.00281251101903707,14.44709985817305,71.72568222291538,0.000885438126155746
0.0009637368122319,76.0856947080819,0.0030598643788362825,15.338876053149312,76.15902129295633,0.0009632727160640885
0.0010578533513172,80.5120365328455,0.00335868439043211,16.231226565021654,80.59720646051315,0.0010572942187462386
0.0011567726109209,84.924904499845,0.003672753039673857,17.120860747168752,85.0231433033555,0.0011561040650049986
0.0012427915866647,89.39117095575,0.003945863287660422,18.0212600646792,89.5022655509359,0.0012420199604482303
0.0013280418124876,93.8157484948299,0.00421653275464813,18.91325489655771,93.94033973150087,0.0013271607449365955
0.0014113114264748,98.2279241183837,0.00448091377905749,19.802749502266153,98.36655431009088,0.0014103164625296068
0.0014870102126888,102.531482363281,0.00472125742528694,20.67034684443745,102.68394772467731,0.001485905707806842
0.001573759766061,106.649705276602,0.004996687257243675,21.500580583762968,106.81754629182859,0.0015725227038827488
0.0016622689811972,110.788291902805,0.00527770401530111,22.33491964760549,110.97245184391485,0.0016608889412343102
0.0017460013700069,114.813661614475,0.005543554349771907,23.146434181478156,115.01412642494937,0.0017444788815351264
0.0018291730052401,118.927534713203,0.005807624291637317,23.975790998181726,119.14507374928013,0.001827502105564543
0.0019076704429408,122.902614469082,0.0060568536563370395,24.77716707696693,123.13707215406481,0.0019058531505110475
0.0019954432394527,126.804257125663,0.006335532285262321,25.56373823653366,127.05728782327822,0.0019934549871154944
0.0020784909418589,130.588151836889,0.006599208740402008,26.326571410316824,130.85957812759608,0.002076333868016429
0.0021590432453731,134.355088485384,0.006854962304059593,27.085985838653414,134.64516693165987,0.002156715860852575
0.0022456493182864,138.038560026005,0.00712993658555932,27.828573701242608,138.34854622422463,0.0022431316164017653
0.0023075894790409,141.570399151749,0.007326596595954857,28.5405924689926,141.8970855153752,0.0023049310833109563
0.0023884196485903,144.943368176841,0.007583232384274202,29.220583024451148,145.28955376532744,0.002385571907880047
0.0024583009003029,148.164461380931,0.007805105358461707,29.869955414395687,148.52869420973664,0.0024552842215693027
0.0025311985175517,151.358205295868,0.008036555293226647,30.51381418764699,151.7413229607322,0.002528000430110156
0.0026068302605405,154.682847979087,0.008276686077216086,31.184062152583937,155.08607990798546,0.0026034383719765247
0.002678324658555,157.958507640008,0.008503680790912125,31.844435140225617,158.3815718060488,0.002674744338481682
0.0027533867354392,161.043190640513,0.00874200288501946,32.46630723312742,161.4866048254554,0.002749603109780358
0.0028314397040389,164.150684911,0.008989821060323507,33.092778078057606,164.6154676777022,0.0028274387292068623
0.0029157440128968,167.146951157538,0.00925748724094734,33.696825353359664,167.63430887964955,0.0029115014760893285
0.0030066145352201,170.215412484592,0.009546001149323817,34.31542715689375,170.72718461788668,0.0030021037090204117
0.0031162533481475,173.20536547893,0.00989410438036831,34.918201680552286,173.7451172790208,0.003111407894513493
0.003223450771522,176.022253400566,0.01023445619958235,35.48608628555411,176.5896524690951,0.003218266591728636
0.0033599561164151,178.637583772211,0.010667860669617942,36.01333688847774,179.23779821442804,0.003354324075942805
0.0035183732291227,181.079201270419,0.011170835002464572,36.50556697611647,181.71630548451975,0.003512198233753144
0.0037031767453728,183.177263156701,0.011757586166558639,36.92853625239092,183.85560093790394,0.003696336867353098
0.0039407276561466,184.877175982529,0.012511810308265455,37.27123867807785,185.6057265829136,0.003932983327775197
0.0042172785114149,186.115177040302,0.013389859273742305,37.52081969132488,186.90007657708225,0.004208410715627511
0.0045171648418643,186.886010225915,0.014341998372919152,37.67621966154446,187.73020514074378,0.004506993072961547
0.0048519939152627,187.26925708056,0.01540508068095907,37.7534822274409,188.17788637643065,0.004840260929729679
0.0051850205957453,187.387923561066,0.016462440391491327,37.7774053899109,188.35953380412408,0.005171624661965121
0.0055338693545445,187.450289031598,0.017570035200678787,37.78997826877016,188.48761444157049,0.00551861375531177
0.0058926696885745,187.39637181805,0.018709226261224038,37.77910855851888,188.50063673801108,0.005875375815343411
0.0062460614196804,187.365094483617,0.019831245007485267,37.77280304789719,188.5353883716659,0.006226635625888123
0.0066073264970161,187.226562178049,0.02097826162802612,37.74487493509468,188.46362920327326,0.006585593792820207
0.0069682626955235,187.119275727287,0.02212423405828711,37.72324598662106,188.4231719959508,0.006944096552101066
0.007344789639571,187.061836626182,0.023319707105637924,37.71166626383829,188.4357664657931,0.007317948022702034
0.0077099408840823,187.011994036936,0.0244790623069613,37.7016179978463,188.45384545557513,0.007680371179727964
0.0080875123899608,187.018536381967,0.025677851838125536,37.70293693460455,188.5310511121085,0.008054983727909084
0.0084614416334485,186.921855921136,0.026865077186198988,37.68344615370102,188.50348429502856,0.00842584429841731
0.0088384567139328,186.832014136986,0.028062100066736637,37.66533405001638,188.48332080671264,0.008799626188936033
0.0092202991409218,186.768675907484,0.029274449772426714,37.652565062948774,188.4907389695049,0.00917805167376203
0.0095918737331128,186.721769851409,0.03045419910263314,37.643108802044054,188.51278149104706,0.009546163775897787
0.0099766385259216,186.715251981628,0.03167582731980108,37.6417947994962,188.57804255792507,0.009927200413306747
0.010360987132752,186.647557430034,0.0328961341464876,37.62814757789486,188.58141037092616,0.010307679999080537
0.0107527822793047,186.579401054346,0.03414008373679242,37.614407252556155,188.58564873168646,0.010695382222864293
0.0111544278640946,186.493997769504,0.03541530846850035,37.59718995033201,188.57423161471058,0.011092676013655529
0.0115427798709742,186.415745056497,0.03664832609034308,37.5814142033898,188.56750096616778,0.011476670227091226
0.0119337971710908,186.345144489659,0.03788980601821329,37.567181129115255,188.5689496478162,0.011863150910307629
0.0123271622538441,186.269868076094,0.03913874015595501,37.55200540414056,188.56604696287016,0.012251801480159488
0.0127114626534092,186.190318639636,0.04035889392457421,37.535968237750616,188.5570699214501,0.01263135019538086
0.0131001993556026,186.118409103708,0.04159313295403825,37.52147127530753,188.55659736671416,0.01301513385528852
0.0134859483149236,186.031470946581,0.042817885899882425,37.50394454283073,188.5402817487158,0.013395822299668908
0.0138584354851556,185.962365197247,0.044000532665369026,37.490012823765,188.53951263800002,0.01376328544742002
0.0142452578063865,185.87828585195,0.045228693535277135,37.47306242775312,188.52616995452024,0.014144747526702302
0.0146277368218637,185.817926614649,0.04644306440941724,37.46089400551324,188.53602234195247,0.014521783468351498
0.0150066389585153,185.727901530588,0.047646078693286076,37.44274494856654,188.51505309338023,0.014895153318187282
0.0153949305019128,185.614296874874,0.048878904343573136,37.41984224997459,188.47181607542407,0.015277630906829251
0.0157731347755113,185.579542980984,0.05007970291224837,37.412835864966375,188.50671412400084,0.015650031679010225
0.0161661391757175,185.548516329535,0.05132749188290306,37.406580892034256,188.54811946836617,0.01603685859863826
0.0165752863653007,185.56086261075,0.052626534209829726,37.409069902327204,188.63658704671542,0.016439415647919297
0.0169679868779641,185.509071313926,0.053873358337536016,37.398628776887485,188.65678680172402,0.01682563857487831
0.0173527908954286,185.411168356812,0.0550951110929858,37.3788915407333,188.62856959098485,0.01720395061519963
0.0177432826372775,185.319908530829,0.056334922373356064,37.360493559815126,188.60809204620588,0.017587708170157083
0.0181279844581851,185.235363049819,0.057556350654737694,37.343449190843515,188.5933068322924,0.01796563169774379
0.0185384589476749,185.173966828054,0.05885960715886781,37.33107171253569,188.606806810274,0.018368716352451436
0.0189393502913305,185.146845990601,0.06013243717497433,37.325604151705164,188.65340696215202,0.018762233618760806
0.0193464736419931,185.105872305668,0.06142505381332809,37.31734385682267,188.68701818520773,0.01916170983676353
0.0197552728492282,185.05313641164,0.06272299129629953,37.306712300586625,188.7089116130574,0.01956266992952549
0.0201584543965651,184.974205844791,0.06400309270909418,37.290799898309864,188.70299993785406,0.01995796267862739
0.0205549842204235,184.887798962484,0.0652620748998446,37.273380270836775,188.6881647527067,0.02034658150314752
0.0209558341955496,184.800300743667,0.06653477357086998,37.255740629923274,188.672945205339,0.020739280847830287
0.0213580123696371,184.681255113162,0.06781168927359779,37.23174103081346,188.625679644309,0.02113312646559616
0.0217487599189129,184.577719931297,0.06905231274254846,37.210868338149474,188.59205644846313,0.021515629778041636
0.0221396764009326,184.456183210766,0.07029347257296101,37.186366535290425,188.53998341720347,0.021898152111295845
0.0225218659167548,184.327240571176,0.07150692428569648,37.16037169914908,188.47863396812542,0.0222719934658314
0.0229204561867419,184.293349578125,0.07277244839290552,37.15353927495,188.51743722263834,0.022661728508198763
0.0233356090601254,184.280260752755,0.07409055876589815,37.15090056775541,188.58055287517925,0.023067496765779395
0.0237496503517671,184.239748090499,0.07540513986686054,37.1427332150446,188.615377688546,0.023472014648348395
0.0241635968864198,184.197159728256,0.07671942011438286,37.13414740121641,188.64802564355304,0.023876276441027775
0.0245787625524659,184.030208098669,0.07803757110407923,37.10048995269167,188.55344288600705,0.024281564758337357
0.0249832301656275,183.933457850516,0.07932175577586731,37.08098510266403,188.52870976315518,0.0246762516425099
0.0253890458066045,183.861049929889,0.08061022043596928,37.066387665865626,188.52910654860932,0.025072097461370877
0.0257906219075877,183.807810890748,0.08188522455659095,37.05565467557479,188.54832864509262,0.02546365370818316
0.0261891665357783,183.651634878843,0.08315060375109609,37.024169591574754,188.46131812925296,0.025852102595883417
0.0265872114889343,183.526224609332,0.0844143964773664,36.998886881241326,188.40567515678595,0.026239913915621766
0.0270016880041954,183.419313638082,0.0857303594133204,36.97733362943733,188.37194471888117,0.026643574571356157
0.0274209998839656,183.414010635102,0.08706167463159077,36.97626454403656,188.44340619944478,0.027051778674693553
0.0278373400636757,183.408310049551,0.08838355470217034,36.97511530598948,188.51390954690444,0.027456925003320757
0.0282737613160369,183.358165566826,0.08976919217841715,36.96500617827212,188.5423905754088,0.027881436362285936
0.0286845445131741,183.281259986347,0.09107342882932776,36.94950201324756,188.538599446856,0.02828084475227028
0.0291007248179129,183.160448162788,0.09239480129687344,36.92514634961806,188.49054996229887,0.02868533818179961
0.0295165081905403,183.030553793388,0.09371491350496544,36.89895964474702,188.43297663354966,0.029089282510656986
0.0299220663596972,182.927315568278,0.0950025606920386,36.87814681856485,188.40087884371331,0.029483135650450874
0.0303486616541914,182.786678471316,0.09635700075205769,36.84979437981731,188.33400953113545,0.029897251421538776
0.0307689151658169,182.701204597736,0.09769130565146865,36.83256284690358,188.32272246269628,0.03030504331286555
0.0312043927771765,182.633896809594,0.09907394706753539,36.81899359681415,188.33287666006692,0.030727432503023153
0.0316264130419487,182.577060694031,0.10041386140818712,36.80753543591665,188.35131822752538,0.03113659865418738
0.0320520001815212,182.537326671716,0.1017651005763298,36.799525057017945,188.38801309933223,0.03154905356274168
0.0324631211715321,182.452327509001,0.10307040971961441,36.782389225814605,188.37529952495376,0.03194732722147448
0.0328789504847046,182.357514508174,0.1043906677889371,36.76327492484788,188.35323819820206,0.032350000778071264
0.0333009783033763,182.241958163614,0.10573060611321974,36.739978765784585,188.31079365838528,0.03275851101346792
0.0337274097231966,182.090833333694,0.1070845258711492,36.70951200007271,188.2322854763778,0.03317111437038375
0.0341549540389166,181.969635371786,0.1084419790735602,36.68507849095206,188.18479990438777,0.033584623696933956
0.0345772222086798,181.856710012462,0.10978268051255836,36.66231273851234,188.14480988470234,0.0339928623084624
0.0350060031551991,181.800252566048,0.11114406001775713,36.65093091731527,188.16435278099107,0.034407226850462394
0.0354376279840517,181.70701704079,0.11251446884936414,36.63213463542326,188.14628271277329,0.034824166320452196
0.0358729446110503,181.610315278317,0.1138965991400847,36.612639560108704,188.12521205909147,0.03524449597952634
0.0363148341297871,181.509121914698,0.11529959836207404,36.59223897800312,188.10059557007358,0.03567099161854954
0.0367397894094689,181.408343780835,0.11664883137506374,36.571922106216334,188.07324812846343,0.03608097144330553
0.0371680201793538,181.319665829303,0.1180084640694483,36.55404463118749,188.05895882776022,0.03649394136799642
0.0376005575279335,181.154346668465,0.11938177015118887,36.52071628836254,187.9658511018078,0.0369108913444838
0.0380321924387195,181.023005630645,0.1207522109929344,36.49423793513803,187.9077074166251,0.03732679817290989
0.0384617798620057,180.912960529048,0.12211615106186809,36.47205284265608,187.87119499109997,0.03774056044252922
0.0389138211013528,180.830331170033,0.12355138199679513,36.45539476387865,187.86713032688206,0.03817576459749509
0.0393296888954482,180.81312814643,0.12487176224304804,36.45192663432029,187.9244522246419,0.03857597544636399
0.0397583602158333,180.742154648583,0.12623279368527074,36.43761837715434,187.92816633928723,0.03898834021046605
0.0401981488794558,180.70060120315,0.12762912269227217,36.42924120255504,187.9644308729214,0.03941122277387861
0.0406437548195024,180.614448369775,0.12904392155192013,36.41187279134664,187.95529772617581,0.03983951667363732
0.0411054982911357,180.518123689647,0.13050995707435584,36.39245373583284,187.9384111144908,0.04028312771710518
0.0415729333124545,180.428937335713,0.13199406326704302,36.37447376687974,187.92989751520764,0.040732006451406726
0.0420357499711201,180.337302479009,0.1334635061583063,36.356000179768216,187.91791623648288,0.04117625173603257
0.0424936799069975,180.237042124118,0.13491743370471704,36.33578769222219,187.8959772995243,0.04161561223311185
0.0429486233825206,180.123901985255,0.13636187923950288,36.312978640227406,187.85997561380978,0.04205191630349785
0.0434045671133381,179.983873435663,0.13780950058484845,36.284748884629664,187.7959955495198,0.04248898874181049
0.0438552494511767,179.834093846929,0.13924041700748602,36.25455331954089,187.7207628924124,0.042920829896673895
0.0443075799022454,179.727029789159,0.14067656618962915,36.23296920549445,187.6902995221354,0.04335406283405315
0.044757592571496,179.608232934267,0.1421053564144998,36.20901975954823,187.64706504642527,0.04378488967673931
0.0452083781378948,179.499049451243,0.14353660058781598,36.18700836937059,187.6139103542275,0.04421627045490232
0.0456523551948926,179.349158241262,0.144946227743784,36.15679030143842,187.53686971719708,0.04464095398986246
0.0461270422310375,179.262426432776,0.14645335908354407,36.13930516884765,187.53127194727892,0.04509481355543369
0.0465936531316883,179.164996263128,0.14793484869311033,36.1196632466466,187.51294795235242,0.045540750664401254
0.0470617119063981,179.133839429633,0.14942093530281397,36.11338202901401,187.56418457355738,0.045987871800308854
0.0474972776633185,179.017552433934,0.15080385658103623,36.08993857068109,187.5203988284962,0.046403773921345176
0.0479578243728724,178.889195309011,0.15226609238386987,36.06406177429662,187.468331919845,0.046843341170027336
0.0484291557096412,178.785558395375,0.1537625693781108,36.043168572507604,187.4439920415398,0.04729300179966163
0.0489023893832901,178.711070174632,0.15526508629194605,36.02815174720581,187.45046851541633,0.04774427397242523
0.0494044622868128,178.641482277291,0.15685916776063064,36.014122827101865,187.46716865131978,0.04822282448824214
0.0498809053192143,178.522098497239,0.1583718743885054,35.990055057043385,187.42694238976722,0.04867673423098947
0.0503675947680176,178.382828231616,0.15991711338845588,35.96197817149379,187.36754223755892,0.049140193157392376
0.0508199337302859,178.236253666506,0.16135328959365772,35.93242873916761,187.29420826617226,0.04957074870098011
0.0513120636351618,178.147180039773,0.16291580204163872,35.91447149601824,187.28827947839847,0.050038968503051034
0.0517926603668822,178.079742229869,0.16444169666485098,35.90087603354159,187.30296583740252,0.05049600398454755
0.0522999103988846,177.995705792394,0.16605221551645857,35.883934287746634,187.30486525672242,0.05097815961674461
0.0527982643482573,177.88436680436,0.16763448930571692,35.86148834775898,187.276352626319,0.05145163298217815
0.0532777286630044,177.767935297293,0.16915678850503896,35.83801575593427,187.23900711904471,0.05190694829332671
0.0537693019637931,177.611921924789,0.1707175337350431,35.80656346003746,187.1619909871326,0.05237354756952889
0.0542534667201863,177.455291734301,0.1722547568365915,35.77498681363508,187.08285649872886,0.05283290196749784
0.0547486960391416,177.316098725199,0.17382710992427458,35.74692550300012,187.02392391715136,0.053302535746734464
0.0552303985470652,177.205832015997,0.175356515386932,35.724695734425,186.99298074310482,0.05375913033340904
0.055717129868853,177.139636401186,0.17690188733360826,35.7113506984791,187.0093485274723,0.054220279958268426
0.0561982547514735,176.954600863377,0.17842945883592834,35.674047534056804,186.89914060214238,0.05467590890481382
0.0566701659488533,176.781973428027,0.17992777688760922,35.63924584309024,186.80023719895905,0.05512261083911664
0.0571624707877822,176.612910162952,0.18149084475120847,35.605162688851124,186.70854048088697,0.05558840443059981
0.0576480700478667,176.500052202729,0.18303262240197676,35.58241052407016,186.67493957556405,0.05604764109435028
0.0581341970188282,176.498264563778,0.18457607553477953,35.582050136057646,186.75884944940995,0.05650716567500555
0.0586495936302378,176.435604668966,0.186212459776005,35.56941790126355,186.78348118470615,0.05699412766316047
0.0591576499350185,176.410627106912,0.18782553854368372,35.56438242475346,186.84666523011978,0.05747392233387076
0.0596692020045266,176.313746981252,0.18944971636437194,35.5448513914204,186.83424756605132,0.05795678583824734
0.0601811666859443,176.179963162774,0.19107520422787316,35.51788057361524,186.7826788925964,0.05843980548806123
0.0606987878460971,176.037278976384,0.19271865141135827,35.48911544163901,186.72252842597575,0.05892792474188724
0.0612216251746832,175.908568763516,0.19437865992961914,35.463167462724826,186.67797722537094,0.059420721112531945
0.0617434386831581,175.816516144582,0.19603541781902695,35.44460965474774,186.6720324286415,0.059912310472966586
0.0622737783802272,175.748735745285,0.19771924635722135,35.430945126249455,186.69327356569198,0.06041168468126363
0.0627866389843718,175.636427364229,0.19934757877538045,35.40830375662857,186.6640483216517,0.06089436330057351
0.0633028027139738,175.448201885449,0.20098639861686682,35.37035750010652,186.55456479592502,0.061379915535224996
0.0638129586443182,175.243820048637,0.20260614369571028,35.32915412180522,186.426646690073,0.0618595847186268
0.0643344995626139,175.106036025365,0.20426203611129914,35.30137686271358,186.3713952234499,0.06234972080080984
0.0648536561931049,174.992453953559,0.20591035841310806,35.278478717037494,186.34135439865088,0.06283737769423763
0.0653703736924966,174.928546910902,0.20755093647367667,35.265595057237846,186.3636913919531,0.06332250742921065
0.0658874003785127,174.834263133269,0.20919249620177782,35.24658744766703,186.3536382282129,0.06380769200185939
0.0663980323550139,174.660618268011,0.21081375272716912,35.21158064283102,186.25773965091713,0.06428664475220308
0.0669267710948803,174.523605415481,0.2124924982262449,35.18395885176097,186.20390680577609,0.06478233931295417
0.0674469039673728,174.399832743783,0.21414392009640862,35.15900628114665,186.16256151477882,0.06526972621138354
0.0679746986784919,174.264064025773,0.2158196683042118,35.131635307595836,186.10961126841434,0.06576404988143782
0.0685111016513437,174.137023355167,0.21752274774301625,35.10602390840167,186.06734266351526,0.06626618566351489
0.0690429396258699,174.0265722401,0.2192113333121369,35.08375696360416,186.04187836057028,0.06676379926787805
0.0695943553540833,173.98088866428,0.22096207824921446,35.07454715471885,186.0889764548011,0.067279469448817
0.0701348307392966,173.93026105582,0.2226780875972667,35.064340628853316,186.12883047541163,0.06778465057194281
0.0706791629132845,173.861691357747,0.22440634224967826,35.0505169777218,186.1500901656004,0.06829317881151178
0.0712439790850892,173.734759743857,0.22619963359515818,35.024927564361576,186.11231533340134,0.06882057045673133
0.0718120437423761,173.596376068935,0.2280032388820441,34.997029415497295,186.06268662071534,0.06935071494622741
0.0723706553902314,173.437410888267,0.22977683086398468,34.964982035074634,185.98918998343575,0.06987176351239623
0.0729385370536869,173.302713134767,0.2315798551454559,34.93782696796903,185.94315949825167,0.07040118060408579
0.073492976820332,173.181418201501,0.23334020140455408,34.9133739094226,185.90903615509615,0.07091779599609133
0.0740666781462812,173.136579254231,0.23516170311444282,34.90433437765297,185.96023054520222,0.07145207809463003
0.0746334867571837,173.04899616544,0.23696132045405824,34.886677626952704,185.9642461290973,0.07197966089404335
0.0752061214682993,172.935383880244,0.23877943566185028,34.86377339025719,185.9411833665086,0.07251238410043256
0.0757787556763627,172.775741166301,0.24059754927245158,34.83158941912628,185.86847184294461,0.07304482319628677
0.0763475293130722,172.612004113218,0.24240340556900425,34.79858002922475,185.79050415704006,0.07357339222489703
0.0769094018566227,172.472413521545,0.24418735089477708,34.77043856594347,185.73716368225513,0.07409527379710494
0.0774563935615271,172.237748250629,0.24592404955784852,34.72313004732681,185.57866306528095,0.07460307216432892
0.0780029855818486,172.007155055512,0.24765947922236928,34.676642459191214,185.42422669128192,0.07511024203941612
0.078560553510614,171.764227504254,0.24942975739619944,34.62766826485761,185.2581202903112,0.07562733131694653
0.0791090974915245,171.623184073256,0.2511713845355903,34.59923390916841,185.20013927391307,0.07613579098080075
0.0796826338238907,171.566129042846,0.25299236239085293,34.587731615037754,185.2369700799495,0.07666714038106064
0.0802577688251454,171.497657742652,0.2548184160198366,34.57392780091864,185.26167711181566,0.07719968749591798
0.0808441169905247,171.469391024304,0.2566800714449159,34.56822923049969,185.33168253256687,0.07774232565991727
0.0814329812329995,171.391378383529,0.2585497154147734,34.552501882119444,185.34828928293283,0.07828699614411795
0.0820240294741219,171.312884684674,0.26042629358033703,34.53667755243028,185.36465778734654,0.0788333885641215
0.0826149615448156,171.18562415355,0.2623025029047895,34.511021829355684,185.32811791002078,0.0793793752970827
0.0832175866703968,171.039451306319,0.2642158376785098,34.481553383353905,185.2729416694597,0.0799358588919288
0.0838108389282899,170.875893257556,0.2660994135973204,34.44858008072329,185.19714522409268,0.08048338495638256
0.0844152366450028,170.739576707468,0.2680183763478839,34.421098664225546,185.1525984798965,0.08104088930445438
0.0850158495990548,170.617705507877,0.26992532247699896,34.396529430388,185.12291469827048,0.08159459481112423
0.0856131088058547,170.471577331584,0.27182162045858865,34.367069990047334,185.06617902997857,0.08214490463681803
0.086222201210829,170.326563091737,0.27375548884438206,34.337835119294176,185.0124942861817,0.08270580574947045
0.0868206123130179,170.167907113463,0.2756554440938318,34.305850074074144,184.94198900507863,0.08325656444929123
0.0874084061729016,170.00605563239,0.27752168959896256,34.27322081548983,184.86601399495888,0.08379725622481823
0.0880069696381459,169.868189415873,0.2794221286011132,34.24542698624,184.8177740042825,0.0843475543306465
0.088607492948529,169.738906895677,0.2813287901115796,34.21936363016848,184.77904589152672,0.08489935009966545
0.0892179933134031,169.587483842764,0.28326712877005483,34.18883674270122,184.71773884228458,0.08546000143258159
0.0898250348523649,169.476523219341,0.28519448565625855,34.16646708101915,184.69975782417592,0.08601716487251268
0.0904397939618199,169.290605690959,0.2871463458287782,34.12898610729734,184.60121318932104,0.08658109556352105
0.0910218794581385,169.051047565841,0.2889944672795897,34.08069118927355,184.43839163965103,0.0871147611485971
0.0916173596084318,168.860945106233,0.2908851167567709,34.042366533416576,184.3315390378504,0.08766041262815404
0.0922303923332021,168.73131095667,0.29283149565791666,34.01623228886467,184.29346596509922,0.08822183705925513
0.092849959033553,168.686529727394,0.2947986199315308,34.00720439304263,184.34906710209475,0.08878892532817584
0.0934718667962955,168.605357823861,0.2967731770782382,33.99084013729038,184.36521537151467,0.0893578331368697
0.0940893919057483,168.429282295357,0.2987338193007508,33.95534331074398,184.2766910456488,0.08992241172720572
0.0946968906292579,168.233411225992,0.3006626277478938,33.915855703159984,184.16459216904673,0.09047751273816895
0.0953225531435423,168.042202635732,0.30264910623074676,33.87730805136357,184.06041442683446,0.09104888897237104
0.0959450494867541,167.932481514643,0.30462553212044424,33.85518827335203,184.04477176399885,0.09161704993930203
0.0965649892321138,167.838791009387,0.30659384081196134,33.83630026749242,184.04614205593947,0.09218255682495645
0.0971968826440588,167.718254055552,0.30860010239488667,33.81200001759929,184.01994551225593,0.0927586388852031
0.0978332244894195,167.578424048806,0.3106204877539069,33.78381028823929,183.97316162835597,0.09333844128619923
0.0984783103166754,167.43895395807,0.31266863525544436,33.755693117946905,183.92805922505232,0.09392586782891206
0.0991336080810787,167.301312987588,0.31474920565742487,33.72794469829774,183.88649578074944,0.09452224044442203
0.0997818589085238,167.177751569197,0.31680740203456303,33.70303471635012,183.85905838891884,0.09511185005512007
0.100412819910651,167.003578939321,0.3188107032163169,33.66792151416711,183.77287923578922,0.09568540022820085
0.101017053117897,166.754511898921,0.3207291436493229,33.61770959882248,183.5995612850633,0.09623434637435987
0.101634720359915,166.479952049971,0.3226902371427301,33.562358333274155,183.40009542210186,0.09679518605464495
0.102265549716912,166.265638102045,0.3246931203511956,33.51915264137227,183.26888498158377,0.09736765240694756
0.102914344665386,166.044683074613,0.32675304431260055,33.47460810784198,183.13306281840852,0.09795608056090184
0.103557919123341,165.933007075042,0.32879639321660764,33.45209422632847,183.11668400161196,0.09853943208248453
0.104186527618291,165.794421811893,0.33079222518807394,33.424155437277626,183.06796691895636,0.09910888975940452
0.104820225390096,165.630456162856,0.3328042156135548,33.391099962431774,182.991877909311,0.09968262977928029
0.105451417371472,165.466499425568,0.33480825015442356,33.358046284194515,182.91517631749,0.10025377405523501
0.106111565870805,165.318875502128,0.3369042216398059,33.32828530122901,182.86112024965948,0.10085077131368239
0.106756691644611,165.135149253975,0.3389524959716399,33.29124608960136,182.7644314625684,0.10143383882336524
0.10740621503131,164.991126365954,0.34101473272440924,33.26221107537633,182.7121987626737,0.10202053766415238
0.108071481932875,164.789370593683,0.3431269551368781,33.221537111686494,182.59840208052805,0.10262110062398001
0.108695964341692,164.603429712033,0.3451096867848721,33.18405142994585,182.49515823853235,0.10318451779828591
0.10933476610515,164.419809507271,0.34713788238385124,33.147033596665835,182.39661092280178,0.10376052585115124
0.109955669188227,164.178141814318,0.3491092496726207,33.09831338976651,182.23045926359097,0.10432007685844896
0.110551471619269,163.967539721641,0.351000922391179,33.055856007882824,182.09439253565938,0.10485671322803387
0.111208520029623,163.729114446392,0.35308705109405303,33.00778947239263,181.937186949736,0.10544817984187004
0.111860237309473,163.504840722464,0.3551562534575768,32.96257588964874,181.7945310069264,0.10603450205648339
0.1124971841379,163.338619711959,0.35717855963783246,32.92906573393094,181.71375449052567,0.10660720394305485
0.113130067478958,163.148562884989,0.3591879642456916,32.890750277613776,181.6055708132628,0.10717592753111924
0.113750540039977,162.951608573418,0.36115796462692695,32.85104428840107,181.48744204902727,0.10773318468714334
0.114389497846811,162.711296139354,0.3631866556636249,32.802597301693766,181.32375959873846,0.10830671939634859
0.115022436219658,162.480153220817,0.36519623499741416,32.75599888931671,181.16901628161867,0.10887452687973072
0.115658927179847,162.230033135573,0.3672170937960142,32.70557468013152,180.99338472438438,0.10944519644097413
0.11629836255251,161.989763144511,0.3692473011042192,32.657136249933416,180.82890734848655,0.110018178184934
0.116940024876555,161.744424308251,0.3712845789830621,32.6076759405434,180.65882131050196,0.11059282560754186
0.11758933656872,161.523280595391,0.37334614360568597,32.56309336803082,180.5166960010062,0.11117398754852462
0.118244583311588,161.322923630964,0.37542655201429187,32.52270140400234,180.39848551431447,0.1117601194215595
0.118892474789257,161.152373322121,0.377483607455891,32.488318461739595,180.3121778045502,0.11233933426531387
0.119537439973024,160.897703308662,0.3795313719143512,32.436976987026256,180.1310028597186,0.11291559997491858
0.120178118675358,160.617294868619,0.38156552679426164,32.380446645513594,179.9199791926549,0.1134877071939224
0.120809801227005,160.304982915618,0.38357111889574086,32.317484555788596,179.67139603735225,0.11405146085164346
0.121439575059253,159.977071941459,0.38557065081312825,32.251377703398134,179.40461957725333,0.11461319484561275
0.122081451502625,159.648432864665,0.38760860852083434,32.18512406551647,179.13854527890268,0.11518539938774636
0.122717157323375,159.307270105168,0.38962697450171563,32.11634565320187,178.85700543342128,0.11575178056354044
0.123355270609991,159.029584684996,0.3916529841867214,32.06036427249519,178.64672213880814,0.11631998423840709
0.123994315718188,158.764983666376,0.3936819524052469,32.0070207071414,178.4509391760976,0.11688869426848748
0.124606928289437,158.489935145891,0.39562699731896245,31.951570925411627,178.23887912921256,0.1174335775269475
0.125237666985668,158.164998403521,0.3976295926794958,31.886063678149835,177.97321380236988,0.11799427288704468
0.125849836568377,157.751421215898,0.39957323110459697,31.80268651712504,177.60441179434795,0.11853816076064623
0.126467413443185,157.364184158133,0.4015340376821123,31.724619526279618,177.2656254972091,0.11908655321315892
0.127091289259353,156.982172510232,0.4035148433984458,31.64760597806277,176.93323920529156,0.11964023378190378
0.127713568326899,156.696321171999,0.40549057943790434,31.589978348274997,176.7085674925728,0.12019219204228355
0.12832033126053,156.321303980059,0.40741705175218274,31.514374882379897,176.38050548985822,0.12073009437466609
0.128941844868978,155.904883415881,0.40939035745900515,31.43042449664161,176.00754670760762,0.12128077353876718
0.129570550444363,155.499345939297,0.4113864976608525,31.34866814136228,175.64748178639013,0.12183751663473523
0.130195512145968,155.144112234918,0.4133707510634484,31.27705302655947,175.34317938377467,0.12239063735628648
0.130826740278982,154.748541859279,0.41537490038576785,31.197306038830643,174.99378915365406,0.12294899378001163
0.131442712222725,154.337137359029,0.4173306113071518,31.114366891580243,174.62362929019102,0.12349355486957057
0.132047969268253,153.864886344407,0.4192523024267032,31.019161087032455,174.18243212787652,0.12402835456183622
0.132663259997075,153.329415196972,0.42120585049071313,30.91121010370956,173.67059527044736,0.1245717269229654
0.133271265301484,152.797274687134,0.4231362673322117,30.803930576926213,173.16076081930677,0.12510837554384352
0.133896398066841,152.280759741358,0.42512106386222015,30.699801163857774,172.67060496560785,0.12565984140258898
0.134503377884709,151.814183089949,0.4270482247839511,30.605739310933725,172.23370352635482,0.12619500265484196
0.135112603260381,151.338503536729,0.4289825153517096,30.50984231300457,171.78624272310685,0.12673185593342787
0.135707345537012,150.700575512912,0.4308708220800131,30.38123602340306,171.1517505866693,0.12725566874434188
0.136306701360253,150.088887794552,0.43277377681880325,30.257919779381684,170.54700900065652,0.1277832674517202
0.136918451813187,149.499200425189,0.43471608450686866,30.139038805718105,169.96839949471521,0.12832148995629503
0.137529048612231,148.991526093735,0.4366547293438334,30.036691660496974,169.48218892869073,0.1288584087584203
0.13814440173296,148.432974400479,0.438608475502148,29.924087639136566,168.93815884647694,0.1293992184564319
0.138747966072607,147.760516158031,0.4405247922805272,29.78852005745905,168.2619872407964,0.12992938348515118
0.139355535719654,147.036068717045,0.44245382590990145,29.642471453356272,167.52635884322066,0.13046278300889919
0.139951688777681,146.275081955127,0.44434661186913715,29.489056522153607,166.74652670084072,0.130985883243228
0.140550780709022,145.515459203564,0.4462487287511448,29.335916575438507,165.96777059985678,0.13151128670420945
0.141170365358698,144.81781610475,0.4482159100138661,29.195271726717603,165.2618001147063,0.13205437205534637
0.141782055198373,144.100354720883,0.4501580252548343,29.050631511730014,164.53119916802436,0.13259024818557577
0.142424781315025,143.441700375414,0.45219868067520436,28.917846795683463,163.87135318283768,0.13315300469548566
0.143032776693276,142.653764327192,0.45412906600115127,28.75899888836191,163.05792834465845,0.13368506042363804
0.143664954486467,141.795393509114,0.45613623049453267,28.585951331437386,162.16642226399154,0.13423797810985147
0.144266540502636,140.932733447479,0.45804626609586924,28.41203906301177,161.26461134552693,0.13476385576951957
0.144898546017709,139.993984945339,0.46005288360622604,28.222787364980345,160.27890981514366,0.13531602698238004
0.145509225122605,139.097703038266,0.46199178976427085,28.042096932514426,159.3377020236983,0.13584927623787207
0.146134023632748,138.286433196708,0.4639755250339749,27.878544932456336,158.49478609356416,0.1363945605232541
0.146779433423282,137.382841909169,0.46602470111892036,27.69638092888847,157.54781760667714,0.13695752098353084
0.147421408216003,136.443991819514,0.46806297108580946,27.507108750814023,156.55875723615955,0.13751717103493466
0.148065104579311,135.439783594964,0.47010670703931234,27.30466037274475,155.4936893171516,0.13807800759536928
0.148703437018815,134.380492721417,0.4721334125347376,27.091107332637666,154.36333385737356,0.13863386025912572
0.14930794168953,133.386630250934,0.4740527148642577,26.890744658588293,153.30231346260334,0.13915997139178543
0.14993142492509,132.22007169579,0.47603227413716076,26.655566453871266,152.04401544883737,0.13970231009726805
0.150550466261255,131.079632608572,0.4779977303794846,26.425653933888118,150.81373241514652,0.1402404941651177
0.151144446167717,129.903661292061,0.47988361658250145,26.188578116479498,149.53787823320826,0.14075661810182205
0.151786493388168,128.755953824828,0.48192211650743333,25.957200291085325,148.29936855874752,0.1413142094963862
0.152409220207317,127.647552904516,0.4838992741582315,25.733746665550427,147.10221690406553,0.1418547250703332
0.153039987861491,126.460467997088,0.4859019614602339,25.49443034821294,145.81397648432082,0.14240192226531392
0.153664744060086,125.194961870884,0.4878855623907731,25.239304313170216,144.43301364438562,0.14294360946543613
0.154272233422901,123.771390025458,0.48981434111771066,24.952312229132335,142.86587879854238,0.1434700444441825
0.154898073070073,122.310265756838,0.49180138199748175,24.657749576578546,141.25589023926076,0.14401209165545642
0.155511819242809,120.796550410095,0.4937500260959185,24.35258456267515,139.58184172262455,0.14454337936264164
0.156112028415549,119.242354970649,0.49565569021936806,24.03925876208284,137.85752087816394,0.1450626759487504
0.156711672592537,117.617446237165,0.4975595604813049,23.711677161412464,136.04947296305392,0.14558121455604917
0.157315777554254,115.931729633597,0.4994775937347564,23.371836694133158,134.16961982411587,0.14610333885099006
0.157928998276511,114.182100906394,0.5014245695279224,23.01911154272903,132.2147657236483,0.1466330631747403
0.158533669081166,112.32937768006,0.503344399332702,22.645602540300096,130.13736606928396,0.14715512711896814
0.159130090333563,110.39206877368,0.5052380368090625,22.255041064773888,127.9587686497446,0.14766980165977653
0.159726073514137,108.322441133787,0.507130283407385,21.83780413257146,125.62435932955304,0.14818383370970586
0.160322432355258,106.086329715049,0.5090237227279442,21.387004070553882,123.09434813460756,0.14869792542179439
0.160964655253047,103.604482678896,0.5110627804284242,20.886663708065434,120.28114251597478,0.1492512588871839
0.161684401907107,100.757131389194,0.5133479760550648,20.31263768806151,117.04798791573164,0.14987102249277862
0.162317483111826,98.4690719273116,0.5153580088800476,19.85136490054602,114.45232384691018,0.15041584237821806
0.162758375402706,96.8498011700744,0.5167578419035915,19.524919915887,112.6129174665908,0.15079509219456275