File: example/data/02 processed data/test_ID_075.csv
Strain,Stress_MPa,Displacement(mm),Force(kN),True Stress (MPa),True Strain
0.00013985446475349957,0.0412864313283013,0.0001552021096917,0.0083233445557855,0.0412884495145198,4.888135952039968e-05
0.00015598293505109958,0.469315355166253,0.0002064100028865,0.0946139756015166,0.4693458658383206,6.50089114061981e-05
0.00016530021069019956,1.03534430520921,0.0002359923530409,0.2087254119301767,1.0354212605915072,7.43255379590596e-05
0.00017464426922249958,1.72433023649778,0.0002656597388809,0.3476249756779524,1.7244745152758498,8.366885836599424e-05
0.00020986930769829957,2.96080379794204,0.0003774992360414,0.5968980456651153,2.961155829807171,0.000118890329443
0.00024553319127589956,4.6018837957879,0.0004907320664003,0.9277397732308408,4.602595068841268,0.0001545493373919
0.00025636875770389955,6.61784281181902,0.0005251349898092,1.3341571108627144,6.618937382155254,0.0001653831706334
0.0002828314105063996,8.8603010223519,0.0006091539124571,1.786236686106143,8.862000955275779,0.0001918410973064
0.00031707533559699957,11.2838059251635,0.0007178783746197,2.274815274512961,11.286357232331085,0.0002260778675499
0.0003681060292378996,13.8572227812276,0.0008799008269296,2.793616112695484,13.861063090450957,0.0002770957241515
0.0004121425428047996,16.5567127479341,0.0010197167575045,3.337833289983515,16.562030277835916,0.0003211190680377
0.00043411528091839954,19.2722258064786,0.0010894802010152,3.8852807225860855,19.27883894299692,0.0003430845101767
0.0004555472135764996,21.9693818847479,0.0011575265872047,4.429027387965177,21.97739137880649,0.0003645088616288
0.0005103234396958996,24.6924473517614,0.0013314411051338,4.977997386115098,24.70280216731745,0.0004192636258974
0.0005604327048294996,27.429335927221,0.0014905380219329,5.529754122927754,27.44221292505278,0.0004693506320675
0.0005986432860607996,30.2141419055739,0.0016118566173423,6.091171008163699,30.22948076055589,0.0005075425540256
0.0006207123606451996,33.0118392980403,0.0016819259291478,6.655186802484925,33.0293270046495,0.000529600187186
0.0006520520340584996,35.8648000836743,0.001781429392235,7.230343696868738,35.88492311013593,0.0005609227769392
0.0007001106979573995,38.7631051160844,0.001934015650114,7.814641991402615,38.78671722693212,0.0006089533377121
0.0007494494848760996,41.7008028045801,0.0020906662985809,8.40688184540335,41.72826184805956,0.0006582608731215
0.0007945657767126996,44.6595154531394,0.0022339105251621,9.003358315352903,44.69093761427937,0.0007033464600706
0.0008307023255794996,47.6149301676502,0.0023486440678142,9.59916992179828,47.65015237970615,0.0007394569493683
0.0008695210452604996,50.5803295346691,0.0024718935028014,10.19699443418929,50.6197088064632,0.000778246222574
0.0009176411429632996,53.5589293806024,0.0026246748130077,10.797480163129444,53.60320489964396,0.0008263277296271
0.0009639134873805996,56.4983715149838,0.0027715895065327,11.390071697420735,56.54769129250416,0.0008725607849523
0.0010140926088398996,59.4281108210133,0.002930908217166,11.980707141516282,59.48297014017423,0.0009226948844397
0.0010604507886850995,62.3626143631202,0.0030780954381745,12.572303055605031,62.423073600532405,0.0009690092370311
0.0011127582465421996,65.2913398993173,0.0032441716168708,13.162734123702366,65.358053698287,0.0010212646676894
0.0011648693826122995,68.259625617547,0.0034096244738933,13.761140524497476,68.33292945694365,0.0010733212566959
0.0012124670451562995,71.229479496924,0.0035607470524705,14.359863066579878,71.30936301162248,0.00112086672876
0.0012593822601058996,74.1916230042351,0.0037097028599355,14.957031197653796,74.27830926440582,0.0011677282894458
0.0013124663424589995,77.1289137544631,0.0038782448214066,15.54918901289976,77.22312629315569,0.0012207490145691
0.0013608559181617996,80.0146757958728,0.004031881724263,16.130958640447957,80.11628515304264,0.0012690783869033
0.0014063298191683996,82.8862959409734,0.0041762613599589,16.70987726170024,82.99532108585794,0.0013144935832829
0.0014397120381172996,85.7808375859124,0.0042822499051217,17.29341685731994,85.89653364374342,0.001347831394636
0.0014845863854816995,88.6261251399702,0.0044247259580037,17.867026828217995,88.74963579082504,0.0013926442955754
0.0015372320368016996,91.4460034724481,0.0045918759009447,18.435514300045536,91.57825818097814,0.0014452152993784
0.0015859051557679995,94.2680838936422,0.0047464130536627,19.00444571295827,94.40900838622063,0.0014938169449353
0.0016344499481435995,97.098879039025,0.0049005427694552,19.57513401426744,97.24874902629962,0.0015422880996688
0.0016798924274095996,99.9400067939649,0.0050448226411247,20.147905369663324,100.09880352121792,0.0015876595182595
0.0017329949693917995,102.741356779209,0.0052134232119182,20.71265752668853,102.91006045614024,0.0016406764129564
0.0017967671272088996,105.515306838346,0.0054158998129875,21.27188585861056,105.69529434403832,0.0017043420003866
0.0018415492888321995,108.314507351908,0.0055580831761415,21.83620468214465,108.50412027822128,0.001749046903616
0.0018889120109656997,111.085593511268,0.0057084598189154,22.39485565187163,111.28531875442371,0.0017963257408682
0.0019385447071345995,113.82491847713,0.0058660436292516,22.94710356498941,114.03521830008523,0.001845868133332
0.0019831201179298995,116.511612974649,0.0060075705585267,23.48874117568924,116.73207021428142,0.0018903603498961
0.0020271103695207997,119.204163583996,0.0061472396073278,24.0315593785336,119.434959349584,0.0019342665587173
0.0020733353067283996,121.901472370587,0.0062940037829619,24.57533682991033,122.14312538735838,0.0019804011067771
0.0021186085221488998,124.545226660454,0.006437746241922,25.10831769474753,124.79775912183436,0.0020255837310433
0.0021691837480644995,127.181733154936,0.0065983225842041,25.6398374040351,127.44604373829804,0.0020760553425758
0.0022048088824855997,129.807587127016,0.006711432385991,26.16920956480643,130.08197920392675,0.0021116059620347
0.0022475000800835994,132.402481503754,0.0068469769383647,26.692340271156805,132.68801118483697,0.0021542062003527
0.0022914978381526996,135.010452691701,0.0069866698202341,27.218107262646924,135.30754669335053,0.0021981083164813
0.0023433126176628997,137.593190621384,0.007151181745179,27.73878722927101,137.90309736564623,0.0022498079901273
0.0023885266715038996,140.136458255125,0.0072947363661242,28.2515099842332,140.4584294419765,0.0022949194178357
0.0024289937071614994,142.673463176265,0.007423219204337,28.76297017633502,143.00703684297343,0.0023352928763697
0.0024756910839669995,145.175461249396,0.0075714833756945,29.26737298787824,145.52166395535147,0.0023818802431509
0.0025382361590274996,147.650044884146,0.0077700639890116,29.76624904864384,148.01138356028153,0.0024442745740454
0.0025940079233785994,150.104854639391,0.0079471393408263,30.261138695301224,150.4805724962583,0.0024999086357557
0.0026512363944764996,152.543991654451,0.0081288397365622,30.75286871753732,152.93454461852485,0.0025569925902616
0.0027019121907403995,154.97019836315,0.0082897353897,31.24199199001104,155.3748162962901,0.002607537696988
0.0027517677860209996,157.392894821484,0.0084480269047159,31.73040759601117,157.8116851868582,0.0026572622249828
0.0028058874380153995,159.800081919218,0.0086198567997982,32.21569651491435,160.23392564291552,0.0027112368011181
0.0028587902618949996,162.185940685011,0.0087878232656159,32.69668564209822,162.634841907974,0.0027639949954402
0.0029067298455044996,164.541578984955,0.0089400314435761,33.17158232336693,165.00488824161678,0.0028118011145025
0.0029568247879267996,166.889569879704,0.0090990828857669,33.64493728774833,167.36785083375293,0.0028617541500816
0.0030077849007611995,169.182325120137,0.0092608812440161,34.10715674421962,169.67579832376663,0.0029125673450629
0.0030589185997026997,171.415037608347,0.0094232307381553,34.557271581842755,171.92378830169284,0.0029635510306469
0.0031118088422975995,173.616522401844,0.0095911572583941,35.00109091621175,174.14098960468232,0.0030162833719631
0.0031681662535421994,175.788907453006,0.0097700920390958,35.43904374252601,176.32984408458648,0.0030724694709282
0.0032226691250313994,177.92204456903,0.009943138656074,35.86908418511645,178.479242540407,0.0031268036648717
0.0032794673550776998,180.02565396728,0.010123473036471,36.29317183980365,180.5996649448582,0.0031834229724671
0.0033395225816951995,182.101757755364,0.0103141483809815,36.71171436348138,182.6933245427424,0.0032432855300805
0.0034005134450934994,184.1468375509,0.0105077943722711,37.12400245026144,184.7562791582351,0.0033040770552839
0.0034639301267328994,186.171413112301,0.0107091423364762,37.53215688343988,186.7993615097821,0.0033672825515877
0.0035357073807505994,188.143982570577,0.0109370351179824,37.92982688622833,188.7920888208484,0.0034388159592053
0.0036060991100609996,190.062256811589,0.0111605288585429,38.31655097321634,190.7303498201136,0.0035089635796421
0.0036781194887663994,191.906286956786,0.0113891935609326,38.68830745048806,192.5946831292933,0.0035807291091235
0.0037557148900077995,193.67987462697,0.011635558959874,39.04586272479715,194.38966158777723,0.0036580441702226
0.0038391631733018998,195.347966576644,0.0119005072593328,39.38215006185143,196.0801681181688,0.0037411842974169
0.0039360316733587,196.913539734172,0.0122080647470131,39.69776961040908,197.670684062562,0.0038376864151467
0.0040416280104649,198.365025809355,0.0125433331173253,39.99038920316597,199.14869780858444,0.0039428727509569
0.0041514634357984,199.726480123555,0.0128920605927592,40.26485839290869,200.5374678034704,0.0040522699777332
0.0042680387033947,200.949885487941,0.0132621870673774,40.51149691436891,201.78926658164468,0.0041683670671881
0.004403012228042399,202.0054358641,0.0136907280081339,40.72429587020257,202.87649144790475,0.004302770111121
0.0045436126708012,202.919909689662,0.0141371344138931,40.90865379343586,203.8234391506188,0.0044427570835254
0.0046918472260496,203.701660199836,0.0146077791268067,41.06625469628694,204.63886613998187,0.0045903236409429
0.0048394529659752,204.36104118599,0.0150764273510705,41.19918590309559,205.3314457185348,0.0047372425823633
0.0049978015110265,204.880844917701,0.0155791839816084,41.30397833540853,205.88616031212,0.0048948303483244
0.0051634887701958,205.293245585569,0.0161052410294709,41.38711831005071,206.3345990349794,0.0050596949871939
0.005329352263058999,205.618552014291,0.0166318576193116,41.452700086081066,206.6956601972802,0.0052247077655353
0.0054960195348418995,205.887501583047,0.0171610262072223,41.506920319142274,207.000333334356,0.0053904927772838
0.0056740031543198,206.10063881545,0.0177261241990646,41.54988878519472,207.25130512132367,0.0055675038911864
0.0058598456436478995,206.269356938369,0.0183161741026814,41.583902358775184,207.45929881356,0.0057522975012923
0.006044177812105799,206.395592464324,0.0189014287375352,41.60935144080772,207.62430792344395,0.0059355555873269
0.0062266364372371,206.525282136166,0.0194807348723271,41.63549687865107,207.79245198363915,0.0061169179797272
0.0064082197487513,206.605995700272,0.0200572618863846,41.65176873317483,207.9111769799752,0.0062973776673962
0.0065970049162566,206.66589500117,0.020656654793214,41.66384443223588,208.01047013520773,0.0064849601241927
0.006790957518043199,206.7247846786,0.0212724543038864,41.67571659120576,208.109837760665,0.0066776404565516
0.0069777256853572,206.779285976564,0.0218654432351084,41.68670405287531,208.2033240048213,0.0068631484003583
0.0071596977892574,206.823063813951,0.0224432046649915,41.69552966489252,208.28503935745243,0.0070438595493719
0.0073465051319668,206.859637071348,0.0230363179780939,41.70290283358376,208.36051404029564,0.007229338468569
0.0075348989799017,206.880599591162,0.0236344684452872,41.70712887757826,208.4206036865885,0.0074163577756141
0.007719611562090799,206.899288923373,0.0242209308937376,41.710896646952,208.4776490427357,0.0075996887243421
0.0079122355516286,206.928318997157,0.0248325120605201,41.71674910982685,208.54675993484523,0.0077908361101539
0.0080997545667545,206.966385315093,0.0254278849335448,41.724423279522746,208.62393411222808,0.0079768825638329
0.0082946314691042,206.989372803183,0.0260466190985051,41.729057557121685,208.6874431499052,0.008170192454077
0.0084911139169578,206.999515419288,0.0266704508704403,41.73110230852846,208.73834074407387,0.0083650571551381
0.0086699774064004,207.028414802262,0.0272383424494205,41.736928424136025,208.80451271065405,0.0085424149529447
0.0088530930311534,207.059949649306,0.0278197345580113,41.743285849300094,208.8742340073655,0.0087239565106316
0.0090455123316223,207.085959161481,0.0284306658370001,41.74852936695456,208.94031875343524,0.0089146862644368
0.009230972726003,207.085789257,0.0290195025891588,41.7484951142112,208.978553539684,0.0090984837933565
0.0094192828567877,207.086665312919,0.0296173872544002,41.748671727084464,209.0184341197836,0.0092850709497996
0.0096003205512867,207.109220357784,0.0301921819344345,41.753218824129256,209.0786941408836,0.0094644193923298
0.0097812850448242,207.158272819681,0.0307667442014161,41.76310780044769,209.1657013516653,0.0096436631763377
0.0099844807325958,207.194164000264,0.0314118905100909,41.77034346245323,209.24404128968328,0.0098448884844911