File: example/data/02 processed data/test_ID_101.csv
Strain,Stress_MPa,Displacement(mm),Force(kN),True Stress (MPa),True Strain
6.79217888830218e-05,3.90913195025773,0.00021565167970359422,0.7880810011719583,3.9093974654927717,6.791948230278237e-05
9.37919534540975e-05,5.83056302395084,0.00029778945221675955,1.1754415056284895,5.831109883846594,9.378755526378907e-05
0.0001165838116795,7.83748907322377,0.0003701536020824125,1.580037797161912,7.838402797573922,0.00011657701631502432
0.0001552850709453,9.98634009184483,0.0004930301002513274,2.0132461625159177,9.987890821374476,0.0001552730154665777
0.0002088528475127,13.961927225838,0.0006631077908528225,2.814724528728941,13.96484321409588,0.00020883104079285104
0.00028107034558,18.59501907865,0.0008923983472165,3.74875584625584,18.600245587088505,0.0002810308527104309
0.0003669462459159,23.5320241377496,0.0011650543307829824,4.744056066170319,23.540659125665748,0.0003668789376074215
0.000454790985643,28.4225518518943,0.001443961379416525,5.7299864533418905,28.435478172265512,0.0004546875995674769
0.0005518323170769,33.5909180178126,0.0017520676067191575,6.7719290723910195,33.60945457193511,0.0005516801136152055
0.0006610320066042,38.9272914162717,0.002098776620968335,7.847741949520375,38.95302360182827,0.0006608136211819373
0.0007549293474267,44.3617308476618,0.0023969006780797724,8.94332493888862,44.39522082018135,0.0007546445316017797
0.0008641752127487,49.7588131171905,0.0027437563004771223,10.031376724425604,49.80181345010217,0.0008638020283319049
0.0009649047332014,55.1496930023525,0.003063572527914445,11.118178109274263,55.20290720216507,0.0009644395118681488
0.0010681826510777,60.5000666933981,0.0033914799171716973,12.196813445389058,60.56469181502903,0.0010676125499349486
0.0011783525545624,65.8782308610884,0.00374126936073562,13.281051341595422,65.95585864271361,0.0011776588420960043
0.0012742203694686,71.2256532755208,0.004045649673062804,14.359091700344994,71.31641045375318,0.0012734092396593203
0.0013712893106057,76.5217475384286,0.004353843561173097,15.426784303747207,76.62668099285692,0.001370349952075827
0.00147237047485,81.7706707557973,0.00467477625764875,16.484967224368738,81.89106747712682,0.0014712876002405293
0.0015732967713431,86.9920382951862,0.004995217249014342,17.53759492030954,87.12890258816857,0.0015720604365555579
0.0016749010563121,92.1706752452213,0.005317810853790917,18.581608129436617,92.32505200655054,0.001673499973769556
0.0017752960369075,97.3219016871492,0.005636564917181312,19.62009538012928,97.49467687351869,0.0017737220614710892
0.0018722300418199,102.437169392163,0.005944330382778183,20.65133334946006,102.62895533809801,0.001870479603629942
0.0019787964702512,107.531322495733,0.00628267879304756,21.678314615139772,107.74410509712898,0.0019768412314373385
0.0020850715231189,112.644963653948,0.0066201020859025074,22.709224672635916,112.87983645988561,0.002082900778405556
0.0021966341013267,117.740491133428,0.006974313271712272,23.736483012499086,117.99912391135862,0.002194225027895952
0.0023070055916087,122.893156936831,0.007324742753357622,24.77526043846513,123.17667213705474,0.002304348539979567
0.0024139394851986,128.047523263623,0.007664257865505554,25.814380689946397,128.35662223601094,0.002411030613565679
0.0025216303886993,133.195675118983,0.008006176484120277,26.852248103986973,133.53154538100634,0.002518456413399288
0.0026299637849159,138.335532620811,0.008350135017107982,27.8884433763555,138.6993500617708,0.0026265114817909485
0.0027343483386539,143.461281546838,0.008681555975226131,28.92179435984254,143.85355466369677,0.002730616808889152
0.0028352417583452,148.503117986497,0.00900189258274601,29.938228586077795,148.9241602278568,0.0028312300414337884
0.002933034848896,153.510914577266,0.0093123856452448,30.947800378776826,153.96116743940703,0.002928741894391906
0.0030286287514908,158.447044176346,0.00961589628598329,31.942924105951352,158.92692144992722,0.003024051694575849
0.003122678181003,163.365017455777,0.009914503224684524,32.934387519084645,163.87515383132532,0.0031178127476489434
0.0032170268686774,168.21453261691,0.010214060308050745,33.91204977556905,168.7556832880406,0.0032118633089835095
0.0033113323768937,173.000818886832,0.010513480296637496,34.87696508758533,173.57368209964108,0.0033058619886943857
0.0034125779489836,177.773606735369,0.01083493498802293,35.839159117850386,178.38027302562537,0.0034067683183143576
0.0035101039025221,182.479400798677,0.011144579890507668,36.787847201013285,183.11992245555032,0.0035039578657714695
0.0036097812276527,187.077720026238,0.011461055397797322,37.71486835728958,187.7530296681008,0.0036032816041800505
0.0037068440965378,191.676642700127,0.011769230006507514,38.642011168345604,192.38715813156412,0.0036999906811000646
0.0038036479122875,196.163970490944,0.012076582121512813,39.54665645097431,196.91010916776793,0.0037964323347902517
0.0039024345039702,200.621927949102,0.012390229550105384,40.44538067453897,201.4048418829836,0.003894839758693098
0.0040024334409894,205.010867296648,0.012707726175141345,41.33019084700424,205.83140964768234,0.003994445012605548
0.0040985514525038,209.266392904411,0.013012900861699563,42.18810480952926,210.1240819830096,0.0040901752695108665
0.0041962683069284,213.500636271115,0.013323151874497669,43.04172827225679,214.3965422246085,0.00418748852605088
0.004294032857472,217.623858272689,0.0136335543224736,43.87296982777411,218.55834227068178,0.004284839805829837
0.0044014999410015,221.560498131219,0.013974762312679762,44.66659642325375,222.53569665067184,0.004391841670350643
0.0045177830582395,225.34205384681,0.014343961209910413,45.428958055516894,226.360100359988,0.004507608509119937
0.0046337043765628,228.890973168586,0.014712011395586888,46.14442019078693,229.95158627271297,0.004623001817366603
0.0047568285735514,232.218666770642,0.015102930721025695,46.815283220961426,233.32329116004857,0.004745550615247015
0.0048881456131739,235.265260133397,0.01551986232182713,47.42947644289284,236.4152709826503,0.004876237419629165
0.0050444203757115,237.91036494799,0.016016034692884012,47.96272957351478,239.11048484052657,0.005031739913092625
0.0052213668030128,240.225829996817,0.01657783959956564,48.42952732735831,241.48013717078857,0.005207782731795404
0.0054138255115943,242.225876892412,0.0171888959993119,48.832736781510256,243.53724552430043,0.005399223436608465
0.0056286307460854,243.858809007588,0.017870902618821145,49.161935895929744,245.23140019767186,0.005612849195368083
0.0058752644045701,245.156162448758,0.018653964484510066,49.42348234966961,246.5965197235542,0.005858072344391338
0.0061433114530906,246.282499353479,0.019505013863562654,49.65055186966137,247.79548945245304,0.006124518244367294
0.0064428231861166,247.150808287049,0.020455963615920204,49.82560295066907,248.74315724514827,0.006422156919385604
0.0067552853480836,247.777762628533,0.021448030980165428,49.95199694591225,249.45157211799847,0.0067325706468289465
0.0070808086415399,248.251380322709,0.022481567436889182,50.04747827305813,250.00920084177224,0.00705585742996184
0.0074169967428634,248.556327027782,0.02354896465859129,50.108955528800855,250.39986849576516,0.007389626077955336
0.007765310451245,248.803561421892,0.024654860682702874,50.158797982653425,250.7355983177084,0.007735315607489915
0.0081162278568739,249.053605534789,0.02576902344557463,50.209206875813464,251.0749813458853,0.008083468415583942
0.008477937925383,249.185694357117,0.026917452913091024,50.235835982394796,251.2982752057701,0.008442202045310458
0.0088372971894783,249.19054050399,0.0280584185765936,50.236812965604386,251.3927113672305,0.008798476822441234
0.0091977278181683,249.223367408871,0.02920278582268435,50.243430869628405,251.51565610822516,0.009155686313907943
0.0095627661681616,249.257725336774,0.030361782583913078,50.25035742789364,251.64131867977744,0.009517332338841866
0.0099299545468326,249.316252766251,0.031527605686193505,50.26215655767621,251.7919518240065,0.009880976514382361
0.0103019084602468,249.387886889879,0.032708559361283585,50.27659799699961,251.9570580717129,0.010249205453275899
0.0106775501891743,249.51847044261,0.0339012218506284,50.30292364123018,252.18271643388698,0.010620947710868661
0.0110513792883429,249.545833947202,0.03508812924048871,50.30844012375593,252.30365960797835,0.010990759012451647
0.0114241244615437,249.523896768603,0.036271595165401245,50.30401758855037,252.3744888214169,0.011359361921836683
0.0117997374398259,249.634495524281,0.037464166371447234,50.326314297695056,252.5801170273909,0.011730663377568522
0.0121593961536875,249.782881947738,0.03860608278795781,50.35622900066398,252.82009096175028,0.01208606454321221
0.0125444587994419,249.815110378717,0.03982865668822803,50.36272625234935,252.94890573834084,0.012466428959919298
0.0129209110957054,249.886427971354,0.04102389272886464,50.37710387902497,253.11518829119527,0.012838148275582219
0.0132956895141117,249.874432474081,0.04221381420730465,50.37468558677473,253.19668534577124,0.013208077554186928
0.0136704231304914,249.928782485675,0.04340359343931019,50.385642549112085,253.34541469474271,0.013577825837901542
0.0140464914234344,250.030618369414,0.04459761026940422,50.40617266327386,253.54267130593595,0.01394875364794804
0.0144216904378524,250.086434715558,0.045788867140181364,50.4174252386565,253.69310385973196,0.014318687001650092
0.0148061581206906,250.197366905356,0.04700955203319265,50.43978916811977,253.90182868113715,0.014697617034284615
0.0151704333573285,250.293324065994,0.048166125909517986,50.45913413170439,254.0903822585214,0.015056513035427967
0.0155423522503336,250.430966230135,0.049346968394809176,50.486882791995214,254.32325252167513,0.01542280697891346
0.0159169752185727,250.535823504847,0.05053639631896832,50.50802201857716,254.52359599893833,0.015791628512694788
0.0162891974685294,250.620097508605,0.05171820196258085,50.525011657734765,254.70249776650473,0.01615795183079296
0.0166612848584672,250.731525033519,0.05289957942563335,50.54747544675744,254.90903439510038,0.016524008355364064
0.0170295909105904,250.835880155572,0.05406895114112451,50.568513439363315,255.10751258031928,0.016886212917068082
0.0174044652382063,250.835869460161,0.055259177131304994,50.56851128316846,255.20153363067564,0.01725474226873295
0.0177753965869926,250.903268169885,0.056436884163701496,50.58209886304881,255.3631732665773,0.01761926174914969
0.0181441409100793,250.931548102297,0.057607647389501776,50.58780009742308,255.48448546984943,0.017981500354681317
0.0185146003367473,250.984497531098,0.05878385606917267,50.59847470226935,255.6313751936056,0.018345291718694427
0.0188846032249761,251.00644557711,0.059958615239299115,50.602899428345374,255.74660270874526,0.018708502710089295
0.0192607619098661,251.079608237545,0.06115291906382486,50.61764902068907,255.9155927922308,0.019077621317226606
0.0196387673184647,251.152655359399,0.06235308623612542,50.63237532045484,256.0849839194168,0.01944841488258945
0.0200171752708044,251.231965660586,0.06355453148480397,50.648364277174146,256.2609199508427,0.019819465655202463
0.0203990500628908,251.330608760961,0.06476698394967828,50.66825072620975,256.4575144314127,0.020193776339271344
0.0207876168582647,251.3995789455,0.06600068352499042,50.6821551154128,256.62557707094817,0.020574502714144023
0.0211605432699455,251.510390624289,0.06718472488207695,50.70449474985666,256.83248712793517,0.020939768026073984
0.0215409065319748,251.554975131738,0.06839237823901999,50.71348298655838,256.97369733870397,0.021312180026331905
0.0219075296296809,251.615755665186,0.06955640657423685,50.72573634210149,257.1280352877156,0.021671007873565108
0.022276503198493,251.646897401786,0.07072789765521527,50.73201451620006,257.2527103166477,0.022032006264016996
0.022644172117123,251.678509673909,0.07189524647186551,50.73838755026005,257.377561165146,0.022391598620855126
0.0230053568993951,251.867657245679,0.07304200815557944,50.77651970072889,257.66196259203036,0.02274472341657598
0.023365965545428,251.975523683569,0.07418694060673389,50.79826557460751,257.86317508825044,0.023097160577720967
0.0237346960217505,252.0342145777,0.07535765986905783,50.81009765886432,258.0161700477824,0.023457407132502644
0.0241015304671067,252.12495353503,0.07652235923306377,50.82839063266205,258.20155078417235,0.023815672548979525
0.0244689112770769,252.271224581382,0.07768879330471914,50.857878875606616,258.44402679342335,0.02417434297243433
0.0248373546280032,252.442479012535,0.07885860094391016,50.89240376892705,258.7124823869416,0.02453392158791618
0.0252074853736951,252.613979094129,0.08003376606148194,50.92697818537641,258.9817422773352,0.02489501686006962
0.0255764578418101,252.714489606955,0.08120525364774707,50.94724110476213,259.1780310964018,0.025254852398393375
0.0259408110087813,252.792818213297,0.08236207495288062,50.96303215180068,259.35046893494535,0.025610056009237214
0.0263096749810038,252.905238456834,0.08353321806468707,50.98569607289774,259.5590930816266,0.02596952867469671
0.0266790377429679,253.0647259973,0.08470594483392309,51.01784876105569,259.81624937359584,0.026329357994419895
0.0270512338674534,253.138736347215,0.08588766752916455,51.032769247598544,259.98645150505513,0.02669181662270735
0.027426439106255,253.126853605215,0.08707894416235963,51.030373686811345,260.06922184177637,0.027057072714714494
0.0277997436423044,253.184774179592,0.08826418606431646,51.04205047460575,260.2232459959194,0.02742034615224469
0.0281788235101738,253.156888960998,0.08946776464480181,51.036428814537196,260.29055225541464,0.02778910473584246
0.0285552774760571,253.309351211573,0.09066300598648129,51.067165204253115,260.54267002269944,0.028155174389578156
0.0289334556279899,253.327209295011,0.09186372161886792,51.07076539387422,260.6568408645107,0.028522785788957308
0.0293043932697549,253.412484382955,0.0930414486314718,51.087956851603735,260.8385834847788,0.02888322775243565
0.0296803817970723,253.452888063749,0.09423521220570455,51.0961022336518,260.9754665490517,0.029248445150883266
0.0300486106446624,253.52466626269,0.09540433879680311,51.11057271855831,261.14273024803555,0.02960599592854801
0.0304199002195471,253.567421526544,0.09658318319706204,51.11919217975127,261.28091718830933,0.029966389282725117
0.0307891207527083,253.692883478667,0.09775545838984885,51.14448530929927,261.5038643021944,0.03032464556178605
0.0311622174716686,253.728682316064,0.0989400404725478,51.151702354918505,261.6354306931971,0.030686532591916876
0.0315424677062879,253.806416936199,0.10014733496746409,51.16737365433772,261.81209764605774,0.0310552235069655
0.0319215616801376,253.783680432017,0.10135095833443687,51.16278997509463,261.88485184034,0.031422658046861514
0.0322980891072631,253.842810525995,0.10254643291556034,51.17471060204059,262.04144823960166,0.03178747138555616
0.0326724926235184,253.8698367186,0.10373516407967091,51.180159082469764,262.1643970861223,0.03215009497319516
0.0330436998290625,253.906793600025,0.10491374695727344,51.187609589765046,262.29681347230394,0.03250949304626625
0.0334212756579672,253.882522523322,0.10611255021404586,51.18271654070171,262.367600293314,0.03287492467717754
0.0337974658386136,253.824528441452,0.10730695403759817,51.17102493379673,262.4031542704542,0.03323888246959443
0.0341722168603798,253.816817535081,0.10849678853170586,51.16947041507233,262.4903008667012,0.03360131624123398
0.034547656454352,253.936791287322,0.1096888092425676,51.19365712352412,262.7097123138369,0.033964284280490704
0.0349225362804696,254.026092743928,0.11087905269049099,51.21166029717589,262.8973281839638,0.034326579742908266
0.0353048474015765,254.143285173384,0.11209289050000538,51.23528629095421,263.11577507456565,0.03469592190161629
0.0356861470358125,254.244564911404,0.11330351683870468,51.25570428613906,263.3175738378886,0.035064151062987506
0.0360636825567522,254.35288202638,0.11450219211768822,51.27754101651821,263.5257836211744,0.03542861159748453
0.0364470531608535,254.413076172992,0.11571939378570985,51.28967615647519,263.68568308508526,0.0357985692549932
0.0368168953679089,254.49691454204,0.11689364279311075,51.30657797167526,263.86670081618996,0.03615534216974045
0.0371910418305295,254.524662205769,0.11808155781193115,51.31217190068303,263.9906995647651,0.03651613776745126
0.0375725887298726,254.549739894695,0.11929296921734549,51.31722756277051,264.11383258305443,0.036883935716118026
0.0379510546079324,254.632966436215,0.12049459838018535,51.334006033540945,264.29655605041563,0.03724863007502784
0.0383341968976143,254.619726674892,0.12171107514992541,51.33133689765823,264.38036941126404,0.03761769525405656
0.038713283786072,254.642179828874,0.12291467602077859,51.335863453501,264.50021480049315,0.037982720027146595
0.0390900306332944,254.764911323959,0.12411084726070971,51.36060612291014,264.7236795119011,0.03834535959821348
0.0394785368434373,254.796577104409,0.12534435447791342,51.36698994424886,264.85557316120713,0.03871918052550559
0.0398641957583079,254.7591732674,0.12656882153262758,51.35944933070784,264.9149428217563,0.039090123625213025
0.0402443516660883,254.764316102463,0.12777581653983033,51.36048612625654,265.017140831661,0.03945563908110926
0.0406329760535669,254.725614508715,0.12900969897007492,51.35268388495695,265.0758743032777,0.0398291588333984
0.0410190711938257,254.738537739045,0.1302355510403966,51.35528920819147,265.1876759543739,0.04020010953593938
0.0414073107617087,254.702679967433,0.13146821166842512,51.34806028143449,265.2492329886846,0.04057298185041396
0.0417960297400383,254.665775828143,0.1327023944246216,51.34062040695363,265.30979416842604,0.04094617535993233
0.0421770063716661,254.693212683862,0.13391199523003985,51.34615167706657,265.4354099380493,0.04131180066243872
0.0425671012911146,254.732734853286,0.13515054659928885,51.35411934642246,265.57596897994847,0.0416860383663062
0.0429570972759729,254.777676687526,0.13638878385121395,51.36317962020524,265.72218612873843,0.042060041209018156
0.0433420963835239,254.856005903694,0.13761115601768836,51.37897079018472,265.90199947549183,0.04242911493831945
0.0437279816313483,254.909446477012,0.13883634167953085,51.389744409765626,266.05612207021596,0.042798901517396584
0.0441135597539878,254.975963503363,0.14006055221891126,51.40315424227798,266.2238609051993,0.04316825725573224
0.0444935591216395,255.000794916385,0.1412670502112054,51.408160255143216,266.34668786106226,0.043532135525044195
0.0448821094561186,254.992079814153,0.14250069752317654,51.40640329053325,266.4366622508152,0.043904065135215935
0.0452643378689768,255.054736579075,0.14371427273400134,51.41903489434152,266.59962035067315,0.04426980832762052
0.045647273134985,255.14936263018,0.14493009220357736,51.43811150624429,266.79623527637716,0.04463609379686215
0.0460307198005602,255.150169086037,0.14614753536677863,51.43827408774506,266.89491502630193,0.04500273404566304
0.046424343262714,255.189991493151,0.14739728985911696,51.44630228501925,267.0370192554381,0.04537896527159975
0.0468155602842256,255.206368965855,0.14863940390241628,51.449603983516376,267.1539981170943,0.04575275618338546
0.0472127046403389,255.217988997921,0.149900337233076,51.45194658198088,267.26752053138114,0.04613206754945191
0.0476106788429089,255.286285355951,0.15116390532623575,51.46571512775972,267.4406387010324,0.0465120272257623
0.0480094173943976,255.275919970614,0.15242990022721237,51.46362546607578,267.53156816322206,0.04689257192183256
0.0484107681289448,255.226668589514,0.15370418880939973,51.453696387646026,267.58238766292396,0.04727546342633334
0.0488117909215236,255.250414230712,0.15497743617583742,51.45848350891154,267.7096440827738,0.04765789570156882
0.049207280667857,255.26809599624,0.15623311612044596,51.46204815284198,267.8291448414764,0.04803490824294513
0.0496122500841349,255.298498295301,0.1575188940171283,51.46817725633269,267.96443123883154,0.04842081033254363
0.0500149934365477,255.331559232655,0.15879760416103894,51.47484234130325,268.1019654918197,0.04880444353086019
0.0504136922770679,255.349154137062,0.16006347297969056,51.4783894740317,268.2222478169374,0.04918407921953702
0.0508143292730098,255.350249681739,0.16133549544180611,51.47861033583859,268.32570134901215,0.049565415273204676
0.0512130265741368,255.363733076386,0.16260135937288434,51.481328588199425,268.44168272449775,0.049944760770111805
0.0516128218409882,255.315326460727,0.16387070934513753,51.471569814482564,268.4928709186182,0.05032500649704132
0.0520124645247369,255.313786603047,0.16513957486603964,51.47125937917427,268.5932858714142,0.05070496265287082
0.0524165294729972,255.276589340702,0.1664224810767661,51.463760411085524,268.65730220964514,0.051088976515422976
0.0528141706065331,255.26027127131,0.16768499167574258,51.46047068829609,268.7416307873029,0.05146674142095053
0.0532087503149409,255.210090296401,0.16893778224993736,51.45035420375444,268.78950026883575,0.051841456918208524
0.0536054029563081,255.240124401259,0.1701971543862782,51.45640907929382,268.9223741204067,0.05221799952443482
0.0539998353545887,255.223302146454,0.1714494772508191,51.45301771272512,269.005318441017,0.05259229390909077
0.0543997841351861,255.282889750697,0.17271931462921586,51.46503057374051,269.17022384654143,0.05297168003845407
0.0548028261647145,255.264991653288,0.17399897307296852,51.46142231730286,269.25423461680043,0.053353854830449556
0.0552018729715475,255.289387728695,0.1752659466846633,51.46634056610491,269.38184008107856,0.05373209741138221
0.0556099545856883,255.314056755986,0.17656160580956035,51.47131384200678,269.5120598572742,0.054118755865629344
0.056022016019783,255.33717307234,0.17786990086281101,51.47597409138374,269.64167627264476,0.054509033570325154
0.0564367352154264,255.318293889912,0.17918663430897883,51.47216804820626,269.7276248378314,0.05490167480010435
0.0568610118357091,255.299121897163,0.1805337125783764,51.46830297446806,269.81568828900373,0.055303205182252416
0.0572812608193601,255.263330190039,0.1818680031014683,51.46108736631186,269.88513558427303,0.05570076498191366
0.0577011291182442,255.24721123667,0.18320108495042534,51.45783778531268,269.97526352930885,0.056097806873512776
0.0581142104331794,255.237696355394,0.18451261812534459,51.45591958524743,270.0706335518713,0.05648827697972842
0.0585285439589543,255.178081934442,0.18582812706967988,51.44390131798351,270.1132835203036,0.05687977765239254
0.0589501038490579,255.18427129355,0.1871665797207588,51.44514909277969,270.22741058695095,0.05727794921942066
0.0593705692468016,255.146852570531,0.18850155735859506,51.43760547821905,270.2950664491732,0.0576749291560335
0.0597862410209226,255.135899109608,0.18982131524142926,51.43539726049698,270.38951546686485,0.058067228373758197
0.0601974422717533,255.078281571867,0.1911268792128167,51.42378156488839,270.4333417015675,0.058455157072670356
0.0606015964166109,255.038914501535,0.1924100686227396,51.41584516350946,270.49467986868757,0.058836290921165456
0.0610206665764691,254.981118925862,0.1937406163802894,51.40419357545378,270.54023676713206,0.05923133783655481
0.0614334791491616,254.969545881675,0.19505129629858806,51.40186044974568,270.6332121622681,0.05962033335735714
0.0618353765188648,254.925606836006,0.19632732044739573,51.393002338138814,270.68902771901054,0.05999889810993678
0.062244935984252,254.913864135085,0.1976276717500001,51.39063500963314,270.78096128967167,0.060384532747245
0.0626546662689839,254.883415160876,0.19892856540402387,51.384496496432604,270.8530504752796,0.060770179475566156
0.0630791427433709,254.896840106042,0.20027627821020258,51.387202965378066,270.97551426792523,0.06116954883990449
0.0635064749361479,254.874846151074,0.20163305792226957,51.38276898405652,271.0610491800217,0.06157144396698146
0.0639251402333112,254.876404772633,0.20296232024076302,51.383083202162815,271.16941468988574,0.061965031520708494
0.0643522811617099,254.830218220883,0.20431849268842894,51.373771993330024,271.22912407233315,0.06236642743821415
0.0647863999216448,254.763428539742,0.20569681975122223,51.36030719361199,271.26863390652704,0.0627742155919945
0.0652127529150263,254.701091714583,0.2070504905052085,51.34774008965993,271.31085107575353,0.06317454720574939
0.0656361933837497,254.649492800293,0.20839491399340526,51.33733774853907,271.3637161548068,0.06357198548970905
0.0660606108597616,254.606667906814,0.20974243947974308,51.32870425001371,271.4261399177066,0.06397018234469808
0.0664869904601812,254.574181722691,0.21109619471107527,51.32215503529451,271.500052914296,0.06437006050529553
0.0669150658836729,254.513987576079,0.21245533418066143,51.310019895337525,271.5448078230486,0.06477136829251144
0.0673445767438608,254.492266729362,0.21381903116175802,51.305640972639374,271.6309407168366,0.06517385996447835
0.0677741732434122,254.48421711935,0.21518300004783372,51.304018171260964,271.731674538111,0.06557626990570647
0.0682054985873305,254.457955179512,0.2165524580147743,51.29872376418962,271.8133868820432,0.06598013643633795
0.068646062431245,254.388654953988,0.2179512482192029,51.28475283872398,271.8514344437599,0.06639248501327619
0.0690761674044313,254.285931820259,0.21931683150906936,51.26404385496422,271.851029415267,0.06679488058458762
0.0695047003727933,254.210598570008,0.2206774236836187,51.24885667171361,271.87943005520486,0.06719564445613857
0.0699354311754139,254.15831990295,0.2220449939819391,51.23831729243472,271.9329915921816,0.06759830195712553
0.0703648443330443,254.080162360632,0.22340838075741562,51.222560731903414,271.95847343325244,0.06799956636689634
0.0707931535569465,254.014517526258,0.22476826254330512,51.20932673329361,271.99700627118807,0.06839963887909516
0.0712255597605126,253.964978150898,0.2261411522396275,51.19933959522103,272.0537758792621,0.06880337597695652
0.0716628915380648,253.963875945044,0.2275296806333557,51.19911739052087,272.16366164148025,0.06921154634472236
0.0720980706457684,253.96638447231,0.22891137430031464,51.1996231096177,272.276870801645,0.06961754227557264
0.0725440408304982,253.940741803006,0.23032732963683178,51.19445354748601,272.3626293448903,0.07003343468836415
0.0729924103383307,253.904977084594,0.23175090282419997,51.18724338025415,272.4381133588971,0.07045139031350872
0.0734373918642899,253.881376300537,0.2331637191691204,51.18248546218826,272.52576241896475,0.07086601513084728
0.0738840241254527,253.843065667832,0.2345817765983123,51.17476203863494,272.598012855713,0.07128200527026271
0.0743333195617945,253.772835551404,0.23600828960869752,51.16060364716304,272.63661283254925,0.07170030134650772
0.0747841325758863,253.695415445144,0.23743962092843898,51.144995753741036,272.6678070276882,0.07211983450906752
0.0752445214888928,253.61368671458,0.23890135572723462,51.12851924165933,272.69672721445255,0.07254809756423455
0.0756986449893003,253.546385561388,0.24034319784102845,51.114951329175824,272.7395033903198,0.07297035280020014
0.0761476421604426,253.439547509126,0.24176876385940527,51.0934127778398,272.7383714821554,0.07338766623038306
0.0766030151667984,253.346878639994,0.24321457315458492,51.07473073382279,272.7540134269145,0.07381072777873088
0.0770599163474558,253.234841461034,0.24466523440317217,51.052144038544455,272.74909716028253,0.07423502926140618
0.0775131835846032,253.152723614543,0.24610435788111515,51.03558908069187,272.7753971550194,0.07465577826625401
0.0779613340946513,253.070124552753,0.24752723575051785,51.01893710983501,272.79980908238514,0.07507160365674667
0.0784066361390543,253.007163813001,0.24894106974149738,51.00624422470101,272.8446044466611,0.07548461484674754
0.0788533911298667,252.91046332132,0.25035951683732677,50.98674940557811,272.8533110064319,0.0758988022803921
0.079311488600019,252.864283274381,0.2518139763050603,50.97743950811521,272.91932599464906,0.07632332728432924
0.0797624498109176,252.820211959007,0.25324577814966337,50.968554730935814,272.9857714265728,0.07674106306394617
0.0802053138825468,252.78932752209,0.2546518715770861,50.96232842845334,273.0643748821571,0.07715112851518019
0.0806609571012147,252.736034276491,0.25609853879635663,50.95158451014059,273.1219646951982,0.0775728512580814
0.0811215813481954,252.689364461053,0.2575610207805204,50.94217587534828,273.1879252960041,0.07799900351508138
0.0815841403108447,252.631154500762,0.2590296454869319,50.930440747353614,273.24185005644284,0.07842676302491204
0.0820460136019354,252.593171876287,0.2604960931861449,50.92278345025946,273.31743469180486,0.07885370595438769
0.0825113878398831,252.523022241262,0.26197365639162884,50.90864128383841,273.35904726791017,0.07928370078363839
0.0829862300702578,252.450241394479,0.26348128047306846,50.89396866512697,273.40013520813335,0.07972225332145495
0.0834703767156518,252.371688997613,0.26501844607219444,50.878132501918785,273.43724895060905,0.08016920125656432
0.0839469809308274,252.306888303218,0.266531664455377,50.865068681928754,273.4872898443246,0.08060899124087541
0.0844241452991481,252.228681302445,0.2680466613247952,50.84930215057291,273.52287214133514,0.08104910443944269
0.0849012321919818,252.15757230159,0.2695614122095422,50.83496657600055,273.5660608965337,0.08148895261111448
0.0853838078778865,252.069089857002,0.27109359001228966,50.81712851517161,273.591708597306,0.08193366442080606
0.0858585130256181,251.988489554812,0.27260077885633743,50.8008794942501,273.62384656755967,0.08237093035904347
0.0863384104786477,251.878099250186,0.2741244532697064,50.778624808837506,273.62485397383017,0.08281278482964378
0.0868151991486379,251.784964974323,0.2756382572969253,50.75984893882352,273.6437268512017,0.08325158370288327
0.0872978457696448,251.667377393225,0.27717066031862225,50.73614328247416,273.63739729014975,0.08369557775375717
0.0877805390608909,251.573316322498,0.27870321151832855,50.7171805706156,273.6565576426229,0.08413941766549246
0.0882649142584298,251.465304417642,0.2802411027705146,50.69540537059663,273.6608679510351,0.08458460616539246
0.0887492524010531,251.365261969763,0.28177887637334353,50.67523681310422,273.67374104917434,0.08502956252629441
0.0892297085291867,251.255600719995,0.28330432458016774,50.653129105150995,273.6750647385658,0.08547075699561271
0.0897116082818335,251.179770258239,0.28483435629482134,50.63784168406098,273.71351141596705,0.08591308167575516
0.0901968316915975,251.086559066111,0.2863749406208221,50.619050307727974,273.7337711742194,0.08635825947210665
0.0906805679858493,251.026502646367,0.2879108033550715,50.60694293350759,273.78972848584084,0.08680187569946216
0.0911612137762025,250.922832546605,0.2894368537394429,50.58604304139557,273.79726252571635,0.08724246291540609
0.0916467130042068,250.837567372244,0.2909783137883566,50.568853582244394,273.8260059198815,0.0876873020879726
0.0921364313715685,250.76453823244,0.29253316960472997,50.5541309076599,273.86908789971625,0.08813580667216811
0.0926335815872572,250.697678296211,0.29411162153954157,50.54065194451614,273.920702132399,0.08859091198881086
0.0931284000007908,250.621697082328,0.29568267000251075,50.52533413179733,273.96169473708807,0.08904367713538651
0.0936328010667121,250.536847074413,0.29728414338681086,50.508228370201664,273.9953138364128,0.0895049996379263
0.0941385604563049,250.435783981006,0.2988899294487681,50.48785405057082,274.01144817172406,0.08996735087580932
0.0946480013590658,250.356954144562,0.3005074043150339,50.471961955543705,274.0527394806881,0.09043285164308154
0.0951567470588146,250.255240632583,0.30212267191173636,50.45145651152873,274.0687152656005,0.09089750102268446
0.0956691100956491,250.136036746636,0.30374942455368587,50.427425008121816,274.0663287850392,0.09136523609574132
0.0961871742733883,249.998361698797,0.3053942783180078,50.39966971847747,274.04499768358073,0.09183795339119627
0.0967031399395389,249.86692843947,0.30703246930803596,50.37317277339716,274.0298449866148,0.09230853385965657
0.0972202997719867,249.727054124355,0.3086744517760578,50.344974111469966,274.0055931874999,0.09277998134288742
0.0977327546292514,249.58054316618,0.3103014959478732,50.3154375023019,273.9727371516756,0.09324692059295314
0.0982528744239548,249.450736750747,0.3119528762960565,50.2892685289506,273.95998866368114,0.09372062114686205
0.0987748330608771,249.307524169663,0.3136100949682848,50.26039687260406,273.932833250342,0.09419577095490878
0.0992932327926159,249.186408197598,0.31525601411655546,50.23597989263576,273.92893223551795,0.09466745765961421
0.0998119882032123,249.087630325667,0.316903062545199,50.21606627365447,273.94956194529857,0.09513924538060703
0.100335512725857,248.965353385536,0.318565252904596,50.19141524252405,273.9454197684479,0.09561514486671358
0.100859178112871,248.833707328191,0.3202278905083654,50.1648753973633,273.930870536091,0.09609094593880656
0.101388934068888,248.711743979378,0.3219098656687194,50.140287586242614,273.92836259186134,0.09657205064567854
0.101913626112736,248.570224337949,0.32357576290793677,50.11175722653052,273.90291724388567,0.09704832845086857
0.102439362039277,248.400427875784,0.32524497447470446,50.07752625975805,273.8464092376627,0.09752532640839617
0.102970883786456,248.223617147507,0.3269325560219978,50.04188121693742,273.7834223818567,0.09800734263052649
0.103499027677391,248.039736627675,0.3286094128757164,50.00481090413928,273.7116081939955,0.09848606558820427
0.104024394778214,247.881241024004,0.3302774534208294,49.97285819043921,273.6669370983986,0.09896204433017142
0.104562943118067,247.702905324057,0.3319873443998627,49.9369057133299,273.6034501236363,0.09944973013845816
0.105099873133195,247.543017972253,0.3336920971978941,49.904672423206215,273.559757756145,0.09993571381139382
0.105642749334132,247.367463907821,0.3354157291358691,49.86928072381671,273.5000428908549,0.1004268394687472
0.106177710271803,247.218676906834,0.33711423011297453,49.83928526441773,273.4677899572263,0.10091056855785924
0.106720805700539,247.019649527626,0.3388385580992113,49.7991613447694,273.38178554907904,0.10140141387744366
0.107269165757637,246.82888982597,0.3405796012804974,49.760704188915554,273.3060189224855,0.10189677300316709
0.107825744954314,246.576045939141,0.34234674022994693,49.709730861330826,273.16329178041804,0.10239930606005661
0.108377773217923,246.380284381695,0.3440994299669055,49.67026533134971,273.0824309677817,0.10289748077235103
0.108923565970195,246.152229407703,0.34583232195536906,49.624289448592926,272.9640080063035,0.10338978441520658
0.10947297329504,245.908767334979,0.34757669021175197,49.57520749473177,272.8291312544573,0.10388510373828803
0.110030984744654,245.642909478831,0.3493483765642764,49.52161055093233,272.6712407043286,0.10438792911902205
0.110586877916029,245.39641173895,0.35111333738339207,49.47191660657232,272.53403476495686,0.1048885944449517
0.111158447842506,245.142592505722,0.35292807189995656,49.42074664915356,272.392262588746,0.10540311780859724
0.11173496704544,244.872156185063,0.35475852036927197,49.3662266869087,272.23293848674683,0.10592182843322655
0.112303324967641,244.583839764682,0.3565630567722602,49.3081020965599,272.05141820360853,0.10643293288373422
0.112881554212927,244.189265455523,0.3583989346260432,49.22855591583344,271.75372926225543,0.1069526463365003
0.113460977963032,243.827615467048,0.3602386050326266,49.15564727815688,271.49253517233336,0.10747316261359005
0.114042021911597,243.489876601542,0.36208341956932044,49.087559122870864,271.2579544441871,0.1079948624378114
0.114609006060616,243.134174965793,0.36388359424245575,49.015849673103865,270.9995410979904,0.10850367620374869
0.115164581452672,242.703672786299,0.3656475461122336,48.92906043371788,270.6545396797594,0.1090020007032982
0.115717299329224,242.309729381279,0.36740242537028617,48.849641443265845,270.3491568664757,0.10949751585595832
0.116293570777204,241.86995456218,0.3692320872176227,48.76098283973549,269.99787524193596,0.1100138856178647
0.116870287502825,241.474490219723,0.37106316282146934,48.68125722829616,269.6956833163001,0.11053038756312389
0.117436850231507,240.988237445843,0.37286199948503473,48.58322866908195,269.2891369943253,0.11103753604889563
0.117998447525914,240.437099618299,0.37464507089477694,48.47211928304908,268.8083041008918,0.11153998611469278
0.118563112500296,239.869363623568,0.37643788218843977,48.35766370651131,268.3090219682435,0.11204492637341104
0.119119578711925,239.324778220542,0.3782046624103618,48.247875289261266,267.8330449774978,0.11254228574012139
0.119681503284141,238.721571240278,0.37998877292714767,48.12626876204005,267.2921277526666,0.11304427279786831
0.120221460691585,238.082792621912,0.38170313769578235,47.99749099257746,266.70545371645,0.1135263985208013
0.120767423421878,237.42324850406,0.38343656936446263,47.8645268984185,266.0962424863476,0.11401365014883483
0.121313424034791,236.726584509226,0.3851701213104614,47.72407943705996,265.44469703610156,0.11450069826248843
0.121864602431132,236.018243877959,0.3869201127188441,47.58127796579654,264.78051333464043,0.11499212462359792
0.122416775352343,235.265261822146,0.388673261743689,47.42947678334463,264.0656765268378,0.11548419566051756
0.122970362555702,234.408472111706,0.3904309011143538,47.25674797771993,263.23376691341065,0.11597728409522823
0.123514806410493,233.476725695143,0.39215951035331525,47.06890790014083,262.3145582707343,0.11646199138194574
0.124048856389308,232.453249166284,0.39385511903605286,46.86257503192285,261.28880888934043,0.11693721706538703
0.124579282492753,231.368180237869,0.39553922191449076,46.643825135954394,260.1918621235567,0.11740899459419342
0.125114502986516,230.146382445819,0.39723854698218825,46.39751070107711,258.94103269967223,0.11788481090956528
0.125649164158084,228.708046588695,0.39893609620191667,46.10754219228092,257.4450214787926,0.11835990404300203
0.12619739817429,226.982854907121,0.4006767392033707,45.7597435492756,255.62750062657202,0.11884682356603551
0.126780037908443,224.725277236242,0.4025266203593065,45.30461589082639,253.2159564032381,0.11936404112694886
0.127383433096544,221.904147821695,0.4044424000815272,44.73587620085372,250.1710599895855,0.11989940176984284
0.128017196334228,218.520980298639,0.4064545983611739,44.05382962820562,246.49542353667783,0.12046139793681618
0.12868213316352,214.389836922526,0.408565772794176,43.22099112358124,241.9779784662958,0.12105069828342717
0.129446287017583,209.496137065282,0.41099196128082605,42.23442123236086,236.6146341529094,0.12172750114052146