File: example/data/02 processed data/test_ID_058.csv
Strain,Stress_MPa,Displacement(mm),Force(kN),True Stress (MPa),True Strain
0.0008208543378776712,26.3712347951603,0.0026062125227616063,10.632881869408633,26.392881737637097,0.0008205176212065516
0.0009123499618977713,29.6033590675728,0.0028967111290254238,11.936074376045353,29.630367691090143,0.0009119340236394974
0.0009967495223617714,32.7157739857946,0.003164679733498624,13.191000071072382,32.74838341788863,0.0009962530974034053
0.0010795151239058713,35.7574814347195,0.0034274605184011413,14.417416514478903,35.796082176721065,0.0010789328664539103
0.0011690422727712712,38.7168876628935,0.0037117092160487857,15.61064910567866,38.76214934124155,0.0011683594749480326
0.0012475366135616713,41.5453889512782,0.003960928748058306,16.75110082515537,41.59721834511957,0.0012467590863557505
0.0013342719551890712,44.2754206319457,0.004236313457725301,17.851849598800506,44.3344960839991,0.0013333826053655664
0.0014253220552306713,46.9177843319792,0.004525397525357381,18.91725064265401,46.98465728477013,0.0014243072479205316
0.0015139597965157714,49.3974119566863,0.004806822353937574,19.917036500935914,49.47219765244064,0.0015128149147739134
0.0016119402974691713,51.7861136852212,0.005117910444464619,20.88016103788119,51.86958980871974,0.0016106425161514387
0.0017149887494086714,53.9579202868696,0.005445089279372531,21.755833459665823,54.05045751310307,0.0017135198354107845
0.0018298021255727713,55.8743676181919,0.005809621748693548,22.528545023654974,55.97660665482469,0.0018281300770312712
0.0019580375792109714,57.6629384882342,0.006216769313994834,23.24969679845603,57.77584468872189,0.001956123122275251
0.0021023033932996713,59.2321362212051,0.006674813273726456,23.8823973243899,59.35666014217533,0.00210009664581482
0.0022454914362782714,60.5729293999486,0.007129435310183512,24.423005134059277,60.708945394186465,0.002242974088134442
0.0024381813617607713,61.7170858403467,0.0077412258235904485,24.884329010827788,61.86756328874481,0.0024352138202084483
0.002663940799303971,62.5858483040395,0.008458012037790109,25.234614036188727,62.752573298795674,0.0026603987980727034
0.0029011594919318715,63.3134328909628,0.00921118138688369,25.527976141636202,63.497115257761216,0.0028969592504856905
0.0031690585150272715,63.9004983318654,0.010061760785211586,25.764680927408133,64.10300275021848,0.003164047632819638
0.0034625827248834715,64.2788141843104,0.01099370015150502,25.917217879113956,64.501384895881,0.0034566017876703297
0.003788936550397171,64.537366164471,0.012029873547511017,26.021466037514706,64.78189414999792,0.003781776610312505
0.004138162555294372,64.7555109195794,0.013138666113059631,26.109422002774412,65.02347975011575,0.004129623908726887
0.004488957578790272,64.8282581909396,0.014252440312659112,26.138753702586847,65.11926949186558,0.0044789122595075585
0.004841271819133272,64.875942130733,0.015371038025748138,26.157979867111546,65.19002420111023,0.004829590549018039
0.005221002964485771,64.900513332527,0.016576684412242325,26.16788697567489,65.23935910503276,0.005207420783069536
0.005609688971260872,64.8670021466427,0.017810762483753267,26.154375265526337,65.23088585318348,0.005594013262660075
0.005994388832367472,64.8377668590392,0.01903218454276672,26.142587597564606,65.22642964461468,0.005976493960568043
0.006381021382815672,64.8124859386987,0.020259742890439757,26.13239433048332,65.22605579734697,0.006360748859771117
0.006789960508008772,64.7077073688288,0.02155812461292785,26.090147611111774,65.14707014642694,0.006767012544769862
0.007153043560636971,64.6627887473187,0.02271091330502238,26.0720364229189,65.12532449198055,0.00712758189139826
0.0075493423548946715,64.6128960187148,0.02396916197679058,26.05191967474581,65.1006808913013,0.007520988681541867
0.007945921746647872,64.5310851867687,0.02522830154560699,26.018933547305142,65.04384413988903,0.007914519149149223
0.008336452806153371,64.4632330341342,0.02646823765953695,25.991575559362914,65.00062773405533,0.008301896501962558
0.00874186338874707,64.3630902432218,0.027755416259271946,25.951197986067033,64.92574358540566,0.008703874536030706
0.00914792691111697,64.2696585136153,0.02904466794279638,25.913526312689687,64.8575926523003,0.009106338069770743
0.00955714293644427,64.1995504209507,0.030343928823210558,25.885258729727326,64.81311470077918,0.009511762355908178
0.009994013778426571,64.1013447633432,0.031730993746504364,25.84566220857998,64.74197448612374,0.009944403883550841
0.01040337935394167,64.0005630854943,0.0330307294487648,25.805027036071305,64.66638522213859,0.010349636618960734
0.010807514729729071,63.8749986782258,0.0343138592668898,25.754399467060644,64.56532866730215,0.010749530942067636
0.01122368608307557,63.7702391300445,0.035635203313764935,25.712160417233946,64.48597627548278,0.011161167873343293
0.01163208239219507,63.6834294144492,0.03693186159521934,25.677158739905916,64.42420031241562,0.011564949814728123
0.01205181521688517,63.5689771713908,0.038264513313610415,25.63101159550477,64.3350987377868,0.01197977036175597
0.01247591957910997,63.458538440151,0.039611044663674155,25.586482699068885,64.25024206233819,0.012398736583990766
0.01288986542074697,63.3495544812087,0.04092532271087163,25.542540366823346,64.16612171293576,0.012807498152361737
0.013309608789526571,63.2362796000755,0.042258007906746865,25.49686793475044,64.07792974285762,0.01322181409718996
0.01374296055329827,63.1485916466686,0.04363389975672201,25.46151215193678,64.01644025066511,0.013649382456222908
0.01416327158633927,63.0482523681608,0.04496838728662718,25.421055354842437,63.941221889495125,0.014063909550620262
0.014600864035213771,62.9553284370401,0.04635774331180372,25.38358842581457,63.87453062784155,0.014495297751917043
0.015018934155080571,62.8351576618199,0.04768511594238081,25.335135569245786,63.77887475736688,0.014907266659741503
0.015447124059026271,62.7213772390115,0.04904461888740841,25.289259302769437,63.69024213437551,0.015329031809236096
0.01588106811387717,62.6189246347779,0.050422391261560014,25.247950412742448,63.61338004212055,0.015756283361323137
0.01632071144215537,62.5113249389248,0.0518182588288433,25.20456621537448,63.5315542351198,0.01618896021414322
0.01675865108939777,62.406805692703,0.053208717208837915,25.16242405529785,63.452659574910854,0.016619774339835452
0.017201719461058872,62.288251019492,0.05461545928886192,25.114622811059178,63.35971603924932,0.01705544495081149
0.01763204855968077,62.1678991029878,0.05598175417698645,25.066096918324686,63.26404651882502,0.017478407368479453
0.01807183504625017,62.074750844902,0.05737807627184429,25.02853954066449,63.196555502708144,0.01791048051718529
0.01850378819089167,61.9629778872862,0.05874952750608105,24.983472684153796,63.109527705789446,0.018334676060125277
0.01895231261757577,61.8623671144735,0.06017359256080307,24.942906420555715,63.034802035290234,0.01877495492920273
0.019390007478305372,61.7509008251663,0.06156327374361955,24.89796321270705,62.94825125395836,0.019204416519772387
0.019835490183848573,61.6483689262834,0.06297768133371921,24.85662235107747,62.871194542970976,0.019641330155013518
0.02028313728538567,61.5360208688682,0.0643989608810995,24.81132361432766,62.78416442814782,0.020080174350340103
0.02073812964413077,61.4237864902226,0.06584356162011519,24.76607071285775,62.69760093769023,0.020526022096910967
0.02118562243470127,61.3071564733783,0.06726435123017653,24.719045490066133,62.60598674296845,0.020964327197460497
0.021632859996702572,61.1997906798149,0.06868433048953067,24.67575560210137,62.523717183418846,0.02140219044668515
0.02207472981179187,61.0792977448937,0.07008726715243918,24.62717285074114,62.42760673970621,0.0218346102548593
0.02253354606030257,60.9503398361354,0.07154400874146065,24.575177021929793,62.323767126224055,0.022283416279589532
0.02297973955431247,60.8239627514008,0.07296067308494208,24.524221781364805,62.221681574089196,0.02271968184112336
0.02343480415368247,60.7245292115526,0.07440550318794184,24.48413017809801,62.14759666094991,0.02316442516868616
0.023885083150389372,60.6003821780075,0.07583513900248626,24.434074094172626,62.047827345274584,0.02360429683384163
0.02435008805341647,60.499805789315,0.07731152956959729,24.39352169425181,61.97298138749941,0.024058351053350736
0.02480588910465157,60.3975779795288,0.07875869790726873,24.352303441346013,61.89579360107854,0.024503218173114388
0.02527443607827727,60.2831989538516,0.08024633454853033,24.30618581819297,61.806822812404796,0.024960319269133217
0.02573949232270957,60.2022092785311,0.08172288812460288,24.27353078110374,61.75178358206601,0.02541380839074532
0.02621094838225857,60.0920648837425,0.08321976111367095,24.22912056112498,61.66713489459361,0.02587332832698991
0.02667524204780847,59.9832350488382,0.08469389350179189,24.185240371691567,61.58330236257655,0.02632566092645956
0.02714874133495337,59.8862392189871,0.08619725373847695,24.1461316530956,61.51207523706652,0.026786751360075033
0.027618573884800372,59.7776712708229,0.08768897208424117,24.102357056395796,61.428645301477424,0.027244061104643107
0.02809190674199227,59.6606162965588,0.08919180390582546,24.05516049077251,61.336596765731514,0.02770456648224126
0.02856396524280137,59.55292737609,0.09069058964589434,24.01174031803949,61.2539951237677,0.028163620926428202
0.02904058544759677,59.436647503397,0.09220385879611974,23.96485627336967,61.16272254393809,0.028626897714147285
0.02952045751237817,59.3488103909351,0.09372745260180068,23.929440349625033,61.10081442649089,0.02909311859704474
0.03001044648787497,59.2410444165073,0.09528316759900302,23.885989108735743,61.01889460985472,0.029568944411350277
0.03051631213609927,59.1390007946991,0.09688929103211517,23.84484512042268,60.94370500236715,0.03005995056428677
0.031009396414218772,59.0305116737022,0.0984548336151446,23.80110230683673,60.86101221072621,0.030538318877112103
0.031508604246927675,58.9255015873137,0.10003981848399536,23.758762240004884,60.782161896880076,0.031022394984372346
0.03200467827359368,58.8070094277539,0.10161485351865993,23.71098620127037,60.689108844721346,0.03150320025994259
0.032502135248751673,58.697855982342,0.10319427941478655,23.666975532080297,60.605661636291835,0.031985113888444376
0.03299659728165187,58.5869219295545,0.10476419636924468,23.622246921996375,60.52009099843559,0.032463896116250404
0.033486491190902974,58.4725595236747,0.10631960953111694,23.576135999945638,60.43060037307378,0.032938029121413845
0.033962139450346575,58.3728771865875,0.10782979275485037,23.535944081632085,60.35534498171634,0.033398159797249
0.034467922202975274,58.2742280173537,0.10943565299444649,23.49616873659701,60.282819575094294,0.03388720970237857
0.034970364685846876,58.176274977443,0.11103090787756383,23.45667407090502,60.21072052946828,0.03437279315362462
0.035481794528038874,58.0791805088523,0.11265469762652341,23.417525581169247,60.139934058024274,0.03486682036436483
0.035978282348093776,57.9618439813565,0.11423104645519773,23.37021549328294,60.047211569533914,0.0353461806330995
0.036499513659176676,57.8529001614012,0.11588595586788594,23.326289345076965,59.96450288106524,0.035849183679092775
0.03700944526732487,57.7482056899631,0.11750498872375646,23.284076534193122,59.885434747732006,0.03634103746755434
0.037529113643881576,57.641313471966,0.119154935819324,23.24097759189669,59.804540875838015,0.03684203407250448
0.03801842960642057,57.5314280945441,0.1207085140003853,23.196671807720183,59.718682643713365,0.037313539505560475
0.03852676765016967,57.4205666304548,0.1223224872892887,23.15197246539938,59.63279545936742,0.037803139302930784
0.039032569034605676,57.3173977468042,0.12392840668487301,23.110374771511452,59.55464303124028,0.03829005814611183
0.039555294187289376,57.1855693201524,0.12558805904464376,23.057221549885448,59.44756133787867,0.03879301996259533
0.040070028996396174,57.0620844992925,0.12722234206355784,23.007432470114736,59.34856387977396,0.03928804645980124
0.04059772178723067,56.9506781605447,0.12889776667445738,22.962513434331623,59.2627459481006,0.03979528054554097
0.041114516111906176,56.8429937214567,0.1305385886553021,22.91909506849134,59.18006590266651,0.040291789453817194
0.04165837102149087,56.7297453900872,0.1322653279932335,22.873433341283164,59.09301417150216,0.04081403066917495
0.042194699595062474,56.5982643832941,0.13396817121432333,22.82042019934418,58.986411146549116,0.041328777695226276
0.042723290543904176,56.5023522416117,0.13564644747689575,22.78174842381784,58.91631865284409,0.04183583932802657
0.043256490713904874,56.4343611500499,0.13733935801664796,22.754334415700125,58.87551356908219,0.042347062098644014
0.04378402275062367,56.3364944492615,0.13901427223323015,22.71487456194224,58.80313280391835,0.04285259329897312
0.04430901777611397,56.2313954606588,0.14068113143916186,22.67249864973763,58.72295336170083,0.04335543970127736
0.04487735376127437,56.1226022505652,0.14248559819204612,22.62863322742789,58.64123612576711,0.04389951370723765
0.045419622242966175,56.0235456947934,0.1442073006214176,22.588693624140696,58.568113976962465,0.04441835720180484
0.04595517675998927,55.944236698503,0.14590768621296593,22.55671623683641,58.51516398468538,0.04493051267865666
0.046504626619402877,55.8411234613516,0.14765218951660414,22.51514097961697,58.437994057929735,0.04545568393514117
0.047052280994749174,55.7370036061106,0.14939099215832863,22.473159853983795,58.35955676159066,0.04597886473414055
0.04758462439068788,55.6471420540171,0.151081182440434,22.436927676179693,58.295090407072756,0.04648715655887777
0.048144905271657774,55.5546248485114,0.15286007423751344,22.399624738919798,58.22929699924547,0.04702184472964425
0.04865988238485287,55.4658954092923,0.15449512657190786,22.363849029026657,58.164859356279024,0.04751304651111781
0.04919864986243507,55.3301281228899,0.15620571331323135,22.30910765914921,58.05229572325163,0.048026682184014985
0.04974612960631707,55.1919833833313,0.15794396150005668,22.25340770015918,57.937570941948195,0.048548353608297595
0.05029109423436508,55.0738551183468,0.15967422419410912,22.20577838371743,57.84357955595335,0.04906735835173183
0.05083395582942048,54.9849624472473,0.16139780975841,22.16993685873011,57.78006559957301,0.04958409257192323
0.05138490741611568,54.8494634472548,0.16314708104616726,22.115303661933137,57.66789804831561,0.050108254550432905
0.05193059346959297,54.7389473396545,0.16487963426595767,22.070743567348696,57.58157336090356,0.05062713634965978
0.05249390673333367,54.6278000182733,0.1666681538783344,22.025928967367797,57.49542665747974,0.051162497230642305
0.05305863792673037,54.5532678193574,0.1684611754173689,21.995877584764905,57.447789904304635,0.05169891814150546
0.053618774858614174,54.492388614769,0.17023961017609998,21.971331089474862,57.41420373141241,0.05223069100970446
0.05417909402251747,54.4119156684558,0.17201862352149297,21.938884397521377,57.35990396340236,0.052762354112105676
0.05476108538055537,54.3065512789367,0.1738664460832633,21.896401475667282,57.280436970246065,0.05331428192731437
0.05535312943342278,54.2431665471953,0.17574618595111732,21.870844751829146,57.245695565960915,0.05387543076394768
0.055949547956855174,54.168811346704,0.17763981476301516,21.84086473499105,57.19953185491226,0.05444040758672544
0.056518431373489476,54.0130167046767,0.17944601961082907,21.778048335325646,57.06574768257511,0.05497900361369727
0.057089145944901075,53.9115448135722,0.1812580383750609,21.73713486883231,56.98930886354929,0.05551904197408769
0.057655107541346874,53.8172476454938,0.1830549664437763,21.6991142506631,56.92008684607405,0.05605429498071019
0.05824740178692257,53.727009093204,0.18493550067347916,21.662730066379854,56.8564677786655,0.056614145218076735
0.05882652624722048,53.6377301528648,0.186774220834925,21.626732797635086,56.79305149354363,0.057161244180540347
0.059410897713901276,53.5396364330588,0.18862960024163655,21.58718140980931,56.720474296822715,0.05771299676020438
0.059987512331879475,53.440048430651,0.19046035165371733,21.547027527238484,56.6457839949009,0.058257127235599664
0.06058955120768467,53.4016752366753,0.19237182508439882,21.531555455427483,56.637258773003985,0.058824933897598866
0.061199435041673876,53.3232825215737,0.19430820625731454,21.49994751269852,56.586637286461574,0.059399810904443594
0.061829451570635276,53.2374645452387,0.196308508736767,21.465345704640246,56.52910778108195,0.059993318182114605
0.06243659679165237,53.1604907836278,0.19823619481349627,21.434309883958733,56.47965091193153,0.06056494642803778
0.06304806776368498,53.0603655797173,0.20017761514969978,21.393939401742013,56.40571910435321,0.06114031730612347
0.06365490222682317,52.9859790256799,0.20210431457016356,21.363946743154138,56.35879633995206,0.06171099829747064
0.06426624197808797,52.863188593175,0.2040453182804293,21.314437640768162,56.26050706303729,0.0622855870408076
0.06487176014691498,52.7504453198786,0.20596783846645506,21.26897955297505,56.17245955631272,0.06285437890356854
0.06546303132459487,52.6233666733555,0.2078451244555887,21.217741442696937,56.068251774299014,0.06340947587257986
0.06603854156026047,52.5214117925608,0.20967236945382697,21.176633234760516,55.989849228027374,0.06394948039987815
0.06663097224133117,52.4021891195576,0.21155333686622646,21.128562653005623,55.89379792816783,0.06450505705390296
0.06722362785459428,52.3160403592816,0.21343501843833682,21.09382747286234,55.83291438721989,0.06506053597779544
0.06780989751623477,52.2018965255001,0.21529642461404538,21.047804679081644,55.741701779047354,0.06560972611407107
0.06840627652621767,52.1331961989941,0.21718992797074108,21.02010470743442,55.69943403437805,0.06616807693335931
0.06901190608372237,52.0650516281973,0.21911280181581852,20.992628816489155,55.65816008140661,0.0667347695708973
0.06963562026643427,52.0195284877508,0.2210930943459288,20.974273886261123,55.641940619962774,0.06731804866921548
0.07027550674621617,51.9246351186948,0.22312473391923635,20.936012879857746,55.57366516427345,0.06791609827116053
0.07090470587388098,51.8429386103212,0.2251224411495721,20.903072847681507,55.51884692412369,0.06850381073185585
0.07153825175303018,51.7563752739538,0.2271339493158708,20.86817051045817,55.458935878126205,0.06909523455050237
0.07218578237251287,51.6847046462895,0.22918985903272834,20.839272913383926,55.41560548787416,0.06969935208509954
0.07282403176590688,51.5814425563647,0.23121630085675432,20.797637638726247,55.3378111676207,0.07029445370936538
0.07346367840179077,51.4657799858276,0.2332471789256857,20.751002490285693,55.24664549540376,0.07089050301980154
0.07412360929535848,51.3783515333897,0.23534245951276317,20.715751338262727,55.18670038869026,0.07150508191782354
0.07475323672964418,51.2846056396396,0.23734152661662025,20.677952993902686,55.118295905606026,0.07209108800139069
0.07540164063755737,51.1801047703034,0.23940020902424464,20.63581824338633,55.03916863798635,0.07269421099908116
0.07605545101666628,51.0820721133418,0.2414760569779154,20.596291476099413,54.96714214678788,0.07330199481384715
0.07670617889458067,50.9764348109512,0.24354211799029363,20.553698515775523,54.886642338967945,0.07390654655677319
0.07734802777767368,50.8821556973569,0.24557998819411392,20.5156851771743,54.817790089623976,0.07450249154283804
0.07798979088795817,50.822758927115,0.24761758606926718,20.491736399412765,54.7864152681898,0.07509800202262684
0.07861944862662358,50.7105952188786,0.24961674938952985,20.446511992251853,54.69743425451473,0.07568193512002827
0.07928791422487858,50.6106572335204,0.2517391276639895,20.406216996555425,54.623470683116494,0.07630148499612094
0.07991682514101127,50.524681618971,0.25373591982271076,20.371551628769108,54.562453765219566,0.07688402441209358
0.08054938822079738,50.4158412254176,0.2557443076010317,20.32766718208838,54.47680639276184,0.07746960459284309
0.08115113402941987,50.3235002123326,0.2576548505434081,20.290435285612503,54.407309322893134,0.0780263383475621
0.08180710538768027,50.245406492384,0.25973755960588485,20.25894789772923,54.35583775655329,0.07863288854942685
0.08245483779665137,50.1496252940717,0.2617941100043681,20.22032891856971,54.284704513257225,0.07923145974396312
0.08308962144469058,50.0570137700065,0.26380954808689255,20.18298795206662,54.216232094808,0.07981771754486988
0.08375112687062128,49.9604862444571,0.26590982781422257,20.144068053765103,54.14473326643456,0.08042828890042115
0.08442203427070427,49.8777324203577,0.26803995880948606,20.110701711888225,54.08851205609416,0.0810471577560276
0.08507729781887208,49.8007087832344,0.2701204205749188,20.07964578140011,54.03761851597655,0.08165122668419096
0.08576744699739858,49.7127471109523,0.2723116442167405,20.04417963513597,53.97648251388598,0.08228706137796715
0.08642147608519618,49.6296647274821,0.27438818657049785,20.010680818120786,53.918733610844505,0.08288924574656573
0.08708983590387788,49.5480735637993,0.27651022899481226,19.97778326092388,53.86320715982385,0.08350425044984117
0.08776216797361767,49.4795172862845,0.2786448833162361,19.95014136982991,53.82194699361691,0.08412252892576377
0.08846637001658347,49.4190544148757,0.2808807248026525,19.925762740077882,53.79097876861177,0.08476970550235177
0.08913814192774547,49.3435597346357,0.28301360062059183,19.895323285005112,53.74195296548184,0.08538668799737086
0.08981288776734117,49.2710073549834,0.2851559186613082,19.866070165529308,53.69617880874036,0.08600601890657247
0.09048872505933198,49.1817667965431,0.287301702063379,19.83008837236618,53.63216217012768,0.08662596736660261
0.09115864639562317,49.1018129972486,0.28942870230610357,19.79785100049064,53.57786780564879,0.08724011002422243
0.09181713712235608,49.0090428677645,0.2915194103634805,19.760446084282645,53.50891287698946,0.08784340645259074
0.09251001453653228,48.9271313175891,0.29371929615348996,19.727419347251924,53.453380947010096,0.08847781456942311
0.09313600649583477,48.8515226361779,0.2957068206242754,19.69693392690693,53.40135836575239,0.08905063557556554
0.09378814711973688,48.748802712739,0.29777736710516456,19.655517253776367,53.32086259347239,0.08964703544810244
0.09445850711899377,48.6610385113768,0.29990576010280523,19.620130727787128,53.25748756402132,0.09025972690948691
0.09514611478971807,48.5835678323309,0.30208891445735486,19.588894549995818,53.206105554199915,0.09088779253051038
0.09583058290466448,48.5036151453215,0.3042621007223097,19.55665762659363,53.151744857681166,0.09151259893573925
0.09653820216750038,48.4346834796178,0.3065087918818137,19.528864378981897,53.11048074529204,0.09215812836694322
0.09721487936179088,48.3239777354539,0.30865724197368605,19.484227822935015,53.02178740128792,0.09277504120134454
0.09788879762930468,48.2257648882929,0.31079693247304235,19.444628402959697,52.94652702796142,0.09338906075381587
0.09860177061548428,48.1454335890796,0.31306062170416254,19.412238823116894,52.892658588013056,0.09403825362678112
0.09929650535425187,48.0677542679016,0.3152664044997497,19.380918520817925,52.84071428693115,0.0946704346239647
0.09997636928305888,47.9896060137389,0.31742497247371193,19.349409144739525,52.78743258631696,0.09528869710362681
0.10066033280185638,47.8962248044479,0.319596556645894,19.31175784115339,52.71747473321614,0.09591030224196939
0.10133332101864237,47.8080629530731,0.3217332942341895,19.27621098267907,52.65261274357632,0.09652155580900183
0.10201595987664337,47.7460511520081,0.3239006726083427,19.251207824489665,52.61691039059952,0.09714119327253215
0.10270282997971737,47.6793822934864,0.32608148518560265,19.224326940733715,52.576189786712284,0.09776428418866791
0.10337958988696337,47.5945194638414,0.3282301978911087,19.190110247820854,52.51482136688042,0.09837782421090904
0.10407447578024938,47.5010723879234,0.33043646060229176,19.152432386810716,52.44472159569621,0.09900740552546185
0.10477450658095437,47.4157932250988,0.3326590583945301,19.11804782835984,52.38375956440309,0.09964124770275139
0.10547893894429937,47.3246849141568,0.33489563114815046,19.081312957388022,52.31644246477535,0.10027866997540742
0.10619309354812638,47.2378302719122,0.3371630720153012,19.046293165635,52.254161600987885,0.10092447515642501
0.10689833938981437,47.1582851165215,0.3394022275626606,19.014220558981467,52.199427483949044,0.10156181517325798
0.10760812899412638,47.0697393977984,0.3416558095563512,18.978518925192315,52.134825986636606,0.10220285157459755
0.10831689761733437,46.9940786001844,0.3439061499350366,18.94801249159435,52.08433140054154,0.10284255611231112
0.10901481073866437,46.9000444311313,0.34612202409525933,18.91009791463214,52.01284389842603,0.10347206331842498
0.10971685858828438,46.8054561183765,0.3483510260178029,18.871959906929405,51.94080372847656,0.10410490043230891
0.11042611873741237,46.739139322295,0.35060292699128426,18.845220974749346,51.900361070783205,0.1047438324114654
0.11112361374308237,46.6487447115581,0.3528174736342865,18.80877386770023,51.83252180048495,0.10537176796329308
0.11183561721470937,46.5702466356457,0.35507808465670226,18.777123443492346,51.77845891198439,0.10601235865524938
0.11253805334182537,46.4811125503014,0.35730831936029556,18.741184580281523,51.71200647387461,0.106643939724351
0.11325654169707837,46.3879839587072,0.3595895198882238,18.703635132150744,51.641726598169925,0.10728954141806518
0.11398124809407037,46.3279208006807,0.3618904626986734,18.67941766683446,51.608435035145526,0.10794030841374899
0.11470613840211037,46.2604312691356,0.3641919894267004,18.652205887715475,51.566786700834385,0.10859081717329458
0.11541743017221137,46.1724408063993,0.3664503407967711,18.6167281331402,51.50154526905245,0.10922871168662406
0.11614015054947738,46.0932715550399,0.36874497799459066,18.584807090992086,51.44655105276018,0.10987643900388253
0.11685124068634438,45.9954806508446,0.37100268917914336,18.545377798420542,51.37010963086054,0.11051333367682648
0.11757438752406338,45.903027877279,0.3732986803889012,18.508100840118892,51.30004826545009,0.11116061130722678
0.11830521663234538,45.8158900859152,0.3756190628076965,18.472966882641007,51.236148887733115,0.11181433982905833
0.11900359241152438,45.7218404093499,0.37783640590658985,18.43504605304988,51.16290366972895,0.1124386397013324
0.11971247307984037,45.6130019340854,0.38008710202849316,18.391162379823236,51.07344720021031,0.11307193188423574
0.12042307254753037,45.5125077255357,0.3823432553384089,18.350643114935995,50.99326374518792,0.11370635732595635
0.12110930591443238,45.4269869711455,0.38452204627832276,18.316161146765868,50.9286178330049,0.11431864684265906
0.12182585629628738,45.336190422456,0.3867970937407124,18.27955197833426,50.85931064188324,0.11495758676237208
0.12254173943724438,45.2578926868369,0.38907002271325086,18.247982331332636,50.80387357994603,0.11559552429684386
0.12323861044100838,45.1802753957079,0.39128258815020156,18.216687039549427,50.748229754817025,0.116216129091225
0.12396308646217638,45.0821405697104,0.39358279951741,18.177119077707232,50.670661859053396,0.11686090970639272
0.12468180342094137,45.0023632852382,0.39586472586148885,18.14495287660804,50.61333909784606,0.11750015424560202
0.12540925981704337,44.9123116452192,0.3981743999191127,18.108644055352382,50.544731405318515,0.11814675600615523
0.12616188246932136,44.8300942327388,0.4005639768400953,18.075493994640286,50.48594331241819,0.11881528711865194
0.1269062127609374,44.7442610712931,0.4029272255159762,18.04088606394538,50.42258578663755,0.11947601310404965
0.12763040447545038,44.6448163279928,0.4052265342095549,18.000789943446698,50.34285229366671,0.12011844377817017
0.12838479703707836,44.5612210520931,0.4076217305927238,17.96708432820394,50.28220437259046,0.12078722702860253
0.12913645071446336,44.4543038963398,0.41000823101842115,17.923975331004208,50.19497492049527,0.12145313766480106
0.12987331833155838,44.36763487676,0.4123477857026978,17.88903038230963,50.1298068447278,0.12210551876852722
0.13059846870539937,44.2970066859923,0.41465013813964297,17.860553095792095,50.08212792741573,0.12274711084932613
0.13133118336133937,44.1857931594628,0.4169765071722525,17.8157118018954,49.98876566285442,0.12339497775438135
0.13203306429941739,44.087562564099,0.4192049791506502,17.776105225844717,49.90857854692928,0.1240151880994925
0.13280893059819737,43.9968856102467,0.42166835464927666,17.73954427805147,49.840064937794786,0.12470032757578114
0.13353085246388938,43.9073746697867,0.42396045657284875,17.703453466857997,49.7703638388947,0.12533740935451954
0.13424450964215837,43.8175813862113,0.4262263181138528,17.6672488149204,49.6998511131086,0.1259667990319562
0.13498578042743836,43.7312006258144,0.42857985285711675,17.632420092328367,49.63429087131884,0.12662012259712316
0.13571380383006137,43.6238989417897,0.4308913271604448,17.589156053329607,49.544264205078164,0.1272613553102623
0.13642867921011936,43.5456360577729,0.43316105649212894,17.557600458494036,49.4865096704994,0.12789060757677492
0.13717886470586338,43.4627305115266,0.4355428954411162,17.524172942247528,49.42489854011471,0.12855051524199682
0.13785895462855538,43.3888234652432,0.4377021809456633,17.494373621186057,49.37036131072456,0.12914838657158123
0.13859195037169336,43.2811236798437,0.4400294424301264,17.450949067712983,49.27953902491172,0.1297923677502306
0.13934976946764438,43.2121109462822,0.4424355180597709,17.423123133540987,49.233708644856904,0.13045772201922531
0.14007784070452337,43.1038859527158,0.4447471442368617,17.37948681613501,49.14178522294626,0.13109654139509822
0.14082713055076437,43.0032166801506,0.44712613949867686,17.338896965436724,49.05923628966898,0.13175355243469639
0.14158393298118938,42.8994818206632,0.44952898721527623,17.297071070091402,48.97335917968773,0.13241671295845367
0.14231643187917536,42.792001236045,0.45185467121638173,17.253734898373345,48.88200616492819,0.1330581585612232
0.14308133238439338,42.6865090949306,0.454283230320449,17.21120046707602,48.7941516910718,0.13372753922286498
0.14382372617216338,42.592959704896,0.4566403305966187,17.17348135301407,48.718837878354954,0.13437679557137053
0.14456024158827438,42.4976579982176,0.45897876704277113,17.135055704881335,48.64112970537579,0.13502049475115718
0.14527773526086238,42.4060372462082,0.46125680945323805,17.098114217671146,48.5666902987251,0.1356471711390269
0.14600331075297537,42.3113403647476,0.4635605116406968,17.059932435066234,48.48893614039676,0.13628050725257673
0.14674760171767237,42.2020636491214,0.46592363545360976,17.015872063325748,48.395115277166525,0.13692976311966096
0.14751610167440737,42.1026625589845,0.4683636228162434,16.97579354378255,48.31348320979892,0.13759969481438394
0.14826232310640738,41.9993457897649,0.4707328758628434,16.934136222433207,48.226266365504756,0.13824977624229964
0.14899614036954736,41.8875338215673,0.47306274567331286,16.889053636855937,48.12861469057971,0.13888863973960813
0.14973827079815738,41.7681009105447,0.47541900978414964,16.840898287131626,48.022384115412606,0.1395343258621876