File: example/data/02 processed data/test_ID_122.csv
Strain,Stress_MPa,Displacement(mm),Force(kN),True Stress (MPa),True Strain
0.000824713759432,0.0139376530512361,-9.71426186062627e-06,0.0028098308551291,0.0139376104074529,-3.05961471549975e-06
0.0007860610528908,0.0064561755770675,-0.0001324366051287,0.0013015649963368,0.0064559062750279,-4.171318655888453e-05
0.0007446816705893,0.0303960806114643,-0.0002638161439361,0.0061278498512712,0.030393554949487,-8.30951511839977e-05
0.0007152696490909,0.224756795929141,-0.0003571993121934,0.0453109700593148,0.2247315099534192,-0.0001125100493941
0.0006736593438009,0.662874034255029,-0.0004893120314892,0.1336354053058138,0.6627718760691006,-0.0001541259024526
0.0006311983050045,1.32835404926376,-0.0006241258296678,0.267796176331574,1.3280929279808973,-0.0001965943878726
0.0005727365452529,2.35220559949051,-0.0008097419168791,0.4742046488572868,2.3516057004445177,-0.0002550693516353
0.0005257714870245,3.81699419495042,-0.0009588559767543,0.7695060297020047,3.8158414555182736,-0.0003020474941942
0.0005077998160938,5.50538495648604,-0.0010159160319592,1.1098856072275856,5.503623378898827,-0.0003200247558329
0.0005071384804547,7.49591662249867,-0.0010180157726134,1.511176791095732,7.493513170104371,-0.0003206863033686
0.0005177092307153,9.61635669734649,-0.000984453640536,1.9386575101850525,9.6133750099892,-0.0003101122185753
0.0005265724054675,11.834846182302,-0.0009563130606977,2.3859049903520835,11.831281515223107,-0.0003012463341202
0.000535454891319,14.2063711865537,-0.0009281111681192,2.864004431209226,14.202218401748445,-0.0002923612115221
0.0005598092975397,16.5436965565597,-0.0008507859283685,3.335209225802436,16.539263440265678,-0.0002679999807139
0.0005868144309708,18.8305068704783,-0.0007650446297248,3.796230185088425,18.82596949153145,-0.0002409879737652
0.0006255696948487,21.2732706541378,-0.0006419966669124,4.288691363874181,21.26896912064039,-0.0002022241205373
0.0006644635035896,23.7367424732121,-0.0005185088241601,4.785327282599559,23.73286602898244,-0.0001633232023853
0.0006969407914381,26.2642209472047,-0.0004153934352411,5.294866942956467,26.26078473146826,-0.000130841137357
0.0007331497080699,28.8130349728367,-0.0003004301249353,5.808707850523879,28.81030857797161,-9.46281384980854e-05
0.0007817120930407,31.3896165914112,-0.000146244552653,6.328146704828498,31.38817074560448,-4.6062337279315175e-05
0.0008322554071251,33.9661982099857,1.4230469565176888e-05,6.847585559133117,33.96635044776519,4.482027614047986e-06
0.0008816572030136,36.5239543418195,0.000171081171511,7.363229195310811,36.52592239249572,5.388238186526401e-05
0.000925478872607,39.0200570045777,0.00031021497247,7.866443492122864,39.02386947887989,9.770073026836024e-05
0.0009679358336157,41.5432997440536,0.0004450158236727,8.375129228401205,41.5491225553146,0.0001401526423084
0.0010093411103384,44.0232438640259,0.0005764775772673,8.875085962987622,44.03123706496013,0.0001815512594443
0.0010555473253874,46.4849900134823,0.0007231823100479,9.371373986718032,46.49557808354861,0.0002277480193715
0.0011029802201001,48.8358226702248,0.0008737817507607,9.84530185031732,48.84926262317996,0.0002751689881745
0.0011552545904579,51.2379547783357,0.0010397528766467,10.329571683312476,51.2547342463276,0.0003274276107198
0.0012108353356248,53.5782765383146,0.0012162217425516,10.801380550124222,53.59880033826872,0.000382988616654
0.0012549034293558,55.9046360622943,0.0013561379401475,11.27037463015853,55.928514612843664,0.0004270388658119
0.0013005247441788,58.1684008428612,0.0015009856147106,11.72674960992082,58.19590003432447,0.0004726396629874
0.0013566861701337,60.4290280423046,0.0016792981421174,12.182492053328607,60.460989728768034,0.0005287729755929
0.0014143952346398,62.6924790647591,0.0018625244219242,12.638803779455436,62.72925584376039,0.0005864498698276
0.0014616846487718,65.0296632436146,0.0020126683117933,13.109980109912708,65.07088628063414,0.0006337104424206
0.0015102559788693,67.2810345787439,0.0021668822848529,13.563856571074773,67.3269527147865,0.000682249824055
0.0015508654138426,69.5537414655126,0.0022958172408931,14.02203427944734,69.60403522262288,0.0007228307392808
0.0015998519229681,71.8032302519677,0.0024513494073666,14.47553121879669,71.85866798611737,0.0007717806541794
0.001655359994905,74.0740545900624,0.0026275875357662,14.93332940535658,74.13535728693311,0.0008272443644475
0.0017006071661903,76.3456633234378,0.0027712473045971,15.391285726005062,76.41230039861976,0.0008724530988129
0.001750836354776,78.6001722396905,0.0029307249783567,15.845794723521603,78.67272514932388,0.0009226372246542
0.0017995017372253,80.8247172562143,0.0030852375676332,16.294262998852805,80.90325692678823,0.0009712565453789
0.0018535056949331,83.0625969925128,0.0032567001333555,16.745419553690578,83.14779698328519,0.0010252066215215
0.001912677661019,85.2937309293958,0.0034445711256782,17.195216155366197,85.38626646412361,0.0010843162081955
0.0019691574276597,87.540552771896,0.0036238943847624,17.648175438814235,87.64047016327524,0.0011407331746337
0.0020274490146086,89.7727848621723,0.0038089701733252,18.098193428213936,89.880483085768,0.0011989566093307
0.00208559152802,92.0177241559985,0.0039935726534064,18.5507731898493,92.13346572035064,0.0012570277680021
0.0021369137006541,94.2314445176464,0.0041565205515196,18.99705921475752,94.35480670213047,0.0013082841541397
0.0021960740809574,96.4172404072956,0.0043443547589826,19.43771566611079,96.54916818594486,0.0013673654411289
0.0022454600147702,98.5506386921832,0.0045011550988382,19.867808760344133,98.69035261654324,0.0014166826763549
0.002297906331289,100.680271879723,0.0046676721537854,20.29714281095216,100.8282852660186,0.0014690533743215
0.0023485783820923,102.788098878454,0.0048285559150859,20.722080733896323,102.9444195344666,0.00151964975981
0.002390948261941,104.909731234129,0.0049630802836055,21.149801816800405,105.0737234919704,0.0015619544063253
0.0024376793043181,106.96923948356,0.0051114513431528,21.564998679885697,107.14144989705112,0.0016086114254644
0.0024837429260604,109.053534623865,0.0052577033421846,21.985192580171184,109.23412395724104,0.0016545999508159
0.0025339677277404,111.100492548802,0.0054171670875186,22.397859297838483,111.2900515823902,0.0017047404621975
0.0025841320038397,113.187454633063,0.0055764386641339,22.8185908540255,113.38625239631048,0.0017548180401735
0.0026243085831628,115.2573169002,0.0057039993034848,23.235875087080323,115.46438072864731,0.001794923374504
0.0026746282502461,117.311020624553,0.0058637642464742,23.649901757909884,117.52767705556263,0.0018451515411955
0.0027245659621191,119.297109475694,0.006022316481671,24.05029727029991,119.52339134927232,0.0018949959531254
0.0027707641196366,121.306730185262,0.0061689956317891,24.455436805348818,121.5424280399453,0.0019411055851526
0.00281883732155,123.278699921348,0.0063216280478641,24.85298590414376,123.52415569682108,0.0019890844114118
0.0028553712546378,125.228706589571,0.0064376232854179,25.24610724845752,125.4826200502147,0.0020255450829489
0.0028937242633624,127.150475027682,0.0065593940881185,25.63353576558069,127.41316166522468,0.0020638197520657
0.0029373860592578,129.062830722423,0.0066980202900864,26.01906667364048,129.33510330789537,0.0021073905815835
0.0029745126396182,130.976755207725,0.0068158971827306,26.404913849877364,131.25792815160642,0.0021444383178456
0.0030231124642362,132.889110902466,0.0069702016258928,26.79044475793715,133.18084756289932,0.0021929328589243
0.0030684639309295,134.752834089793,0.007114192532644,27.16617135250227,135.05477349326836,0.0022381839580167
0.003103775639959,136.604006952627,0.0072263072088127,27.539367801649604,136.91491798260952,0.0022734161006667
0.0031477739267559,138.453611024899,0.0073660017693928,27.91224798261964,138.77482347963547,0.0023173135111594
0.003197589045511,140.348710023461,0.0075241647714403,28.29429994072974,140.68131059658717,0.0023670120913206
0.0032393850783637,142.17791981843,0.0076568671757476,28.66306863539549,142.52079775461073,0.0024087084401473
0.0032911025523764,143.993010498344,0.0078210701557379,29.02899091646615,144.3477126832396,0.0024603001608771
0.0033216616088118,145.770450204777,0.0079180951599203,29.387322761283045,146.13398541618673,0.0024907836606467
0.003356680944517,147.554165073456,0.0080292815507843,29.74691967880873,147.9273159192405,0.002525715269187
0.0034041311134559,149.406906726852,0.0081799358371653,30.12043239613336,149.79183236800316,0.0025730446236785
0.0034443133598763,151.195327967216,0.0083075144695501,30.480978118190748,151.59093658920528,0.0026131228091451
0.003479185136892,152.856677172081,0.008418232361575,30.81590611789153,153.26196316466456,0.0026479029760437
0.0035174925912615,154.582346789977,0.0085398585291981,31.163801112859364,154.99812989948816,0.00268610840033
0.0035440485598067,156.312722779558,0.0086241737293291,31.51264491235889,156.73731115037856,0.0027125927816679
0.0035854950455703,158.054080303071,0.0087557663216286,31.86370258909912,158.4899494663194,0.0027539261381056
0.0036286838740452,159.825244847257,0.0088928908520364,32.22076936120701,160.2729010544465,0.0027969952638729
0.0036604550040034,161.508557119986,0.0089937641896537,32.56012511538918,161.96605944356028,0.0028286771524147
0.0037014935823274,163.229520366196,0.0091240616758324,32.90707130582511,163.69859633820786,0.0028695989725694
0.0037438366762731,164.972446680271,0.00925850099911,33.25844525074263,165.4535167786694,0.0029118198416754
0.0037741310773254,166.687134764235,0.009354685722451,33.60412636846978,167.17825468854846,0.0029420257029918
0.0038127959653213,168.398685267075,0.009477446741838,33.94917494984232,168.9013591477094,0.0029805762619795
0.003851363190318,170.15102432452,0.0095998976812025,34.302446503823234,170.66549122967504,0.003019027966287
0.0038878493380048,171.851593293428,0.0097157412001081,34.64528120795509,172.37747222422018,0.0030554034657868
0.0039284383465166,173.517648869979,0.0098446113021331,34.98115801218777,174.05566896673017,0.0030958678290742
0.0039595453751399,175.216649048325,0.009943376118012,35.32367644814232,175.7653876447424,0.0031268782225386
0.0039974338868989,176.940749875659,0.0100636721428469,35.67125517493286,177.5015919844647,0.0031646477332903
0.0040531916089956,178.619355776703,0.0102407029105039,36.00966212458332,179.19547790475806,0.0032202277361536
0.0040975412274095,180.296392887185,0.010381512948968,36.3477528060565,180.8859202375505,0.0032644337912973
0.0041326789989262,181.924797490254,0.0104930753735335,36.67603917403521,182.52604177761785,0.0032994564316052
0.004181236307928,183.534376606582,0.0106472448296143,37.00053032388693,184.14985233646576,0.0033478526207842
0.0042226621304202,185.178469115269,0.010778771816027,37.33197937363823,185.80712941883897,0.0033891391353219
0.004272992691345,186.77236032598,0.0109385713469632,37.65330784171757,187.41583207056783,0.0034392981497173
0.0043185796312401,188.358407583882,0.0110833098811302,37.97305496891062,189.01593029253348,0.003484727539914
0.0043592357713574,189.985243396389,0.0112123931260026,38.30102506871202,190.6561691403573,0.0035252414303252
0.0043963476620987,191.565015492045,0.0113302233791062,38.61950712319627,192.24862948169755,0.0035622220392307
0.0044458734903902,193.124393310398,0.0114874678839317,38.93387769137624,193.8231367011876,0.0036115705417222
0.0044821818176738,194.708871777738,0.0116027468230572,39.25330855039199,195.42041752370343,0.003647747321041
0.0045262010262524,196.197654020814,0.0117425078102942,39.553447050596105,196.92327685064103,0.0036916052893999
0.0045726948741588,197.70526175063,0.0118901257773971,39.85738076892701,198.44565243695072,0.0037379267439349
0.0046223706089369,199.267777150106,0.0120478462353175,40.17238387346137,200.0239181071952,0.0037874159164512
0.0046717396672849,200.750284230935,0.0122045929955724,40.471257300956495,201.5219615577961,0.0038365971378667
0.0047312241005387,202.268873494683,0.0123934560711532,40.77740489652809,203.05842007679888,0.0038958520349385
0.0047889806109383,203.793737920678,0.012576832991672,41.084817564808695,204.601007151096,0.0039533823173569
0.0048494236595297,205.263694677013,0.0127687396709497,41.38116084688583,206.0891934742502,0.0040135850709642
0.0049158241116942,206.758752082336,0.0129795611065719,41.682564419798936,207.6039923522482,0.0040797173665798
0.004983879856153,208.17380116901,0.0131956380952286,41.96783831567242,209.03899365440665,0.00414749373156
0.0050525327949029,209.463347010747,0.0134136111757596,42.2278107573666,210.34827926031403,0.0042158601852959
0.0051248215880911,210.768580758101,0.0136431280941321,42.49094588083316,211.6742635125896,0.0042878422697763
0.0052010356599922,212.025181998041,0.0138851077724181,42.744276690805066,212.95242373111483,0.0043637273680317
0.005284155468713,213.222169196636,0.0141490131651066,42.98558931004182,214.1723686546064,0.004446481830562
0.0053753059028436,214.346992029392,0.0144384157934713,43.21235359312543,215.3217419490771,0.0045372237485137
0.0054744786767313,215.398081705746,0.0147532893505647,43.4242532718784,216.39897311518268,0.0046359426997235
0.0055784188202617,216.419364361428,0.0150832993062738,43.63014385526389,217.4474960301956,0.0047393967463648
0.0056930253286056,217.457903713289,0.0154471749702656,43.839513388599066,218.5158912053603,0.0048534548692288
0.0058182068031216,218.369371029651,0.0158446261518539,44.02326519957765,219.45912883972355,0.0049780224942456
0.0059556621428255,219.116115337031,0.0162810468554138,44.17380885194545,220.23971840492976,0.0051147859259298
0.0060900088928859,219.784420116325,0.0167075977868556,44.30853909545112,220.9409774993552,0.0052484383435742
0.0062231457762124,220.455862476743,0.0171303073914172,44.44390187531138,221.6453039540553,0.0053808695272786
0.0063561369779309,221.045727727951,0.0175525544568735,44.562818709954925,222.2677488849287,0.0055131382946421
0.0064949914050769,221.541465545455,0.017993417263062,44.66275945396373,222.7969893346297,0.0056512197707887
0.0066370261865578,221.90071858409,0.0184443776942639,44.735184866552544,223.1897959586392,0.0057924441736342
0.0067799583770243,222.21918306812,0.018898187398995,44.79938730653299,223.5418727579697,0.0059345407344089
0.0069216114375484,222.565885782261,0.019347935866159,44.86928257370382,223.92216624969723,0.0060753457250835
0.0070720567273497,222.871799941797,0.0198255996612782,44.93095486826629,224.26347461311497,0.0062248685994751
0.0072282240223872,223.083586667629,0.0203214308230222,44.97365107219401,224.5114221555717,0.0063800547510219
0.0073849526885128,223.271841535036,0.020819044337971,45.01160325346326,224.7358750368749,0.006535774537776
0.007548280256685,223.45695882132,0.0213376093669177,45.04892289837812,224.9587028520756,0.006698024951268
0.0077048740092173,223.632663364233,0.0218347945312078,45.08434493422938,225.17060769652429,0.0068535612433878
0.0078646833131131,223.79424879209,0.022342189071077,45.11692055648535,225.3690687667459,0.0070122664347627
0.008033326130192,223.924458408713,0.0228776300153021,45.14317081519655,225.5379579081938,0.0071797167994487
0.0081950502569611,224.032704957472,0.023391104117794,45.16499331942636,225.683215926748,0.0073402710616093
0.0083678481284686,224.134676343984,0.0239397373598303,45.18555075094718,225.8246685597023,0.0075117904833733
0.0085386304826244,224.246060473866,0.024481971334275,45.20800579153138,225.97518980436843,0.0076812803983645
0.0087093179442687,224.333912745323,0.025023904024996,45.22571680945712,226.102010478265,0.0078506474409368
0.0088794976503463,224.401370739477,0.0255642245917924,45.23931634107856,226.2081887049227,0.0080194821033841
0.0090540917816401,224.478241477002,0.0261185609586499,45.254813481763605,226.3248709679965,0.0081926666821308
0.009215317746952,224.581781654075,0.0266304533985151,45.27568718146152,226.4654713140732,0.0083525643885091
0.0093936747184693,224.6586523916,0.0271967367830829,45.29118432214656,226.58305624518627,0.0085294221859563
0.0095570771359501,224.708853689575,0.0277155394585844,45.30130490381832,226.6704055324496,0.0086914236792666
0.0097347313137234,224.738660710248,0.0282795914730147,45.307313999186,226.7403985096428,0.008867524973245
0.0099067053966949,224.75905498755,0.0288256091864489,45.31142548549008,226.799627170286,0.0090379662872723