File: example/data/02 processed data/test_ID_085.csv
Strain,Stress_MPa,Displacement(mm),Force(kN),True Stress (MPa),True Strain
4.51480162169036e-05,0.763519162794752,0.00014334495148866892,0.153925463219422,0.7635536341702958,4.514699707590208e-05
6.2619078393366e-05,1.88758838927651,0.00019881557389893703,0.3805378192781444,1.8877065883218327,6.261711790079736e-05
8.76222436180531e-05,3.62086269641244,0.00027820062348731856,0.729965919596748,3.6211799645257328,8.761840501357654e-05
0.0001255196046365,6.69490467831517,0.00039852474472088753,1.3496927831483385,6.695745020103472,0.00012551172771013957
0.000172840857787,10.2339301050654,0.0005487697234737249,2.063160309181185,10.235698946323293,0.00017282592252687926
0.0002325788546157,14.2635247926042,0.0007384378634048475,2.875526598189007,14.266842186863247,0.00023255181234689069
0.0002743630401097,18.7047277485564,0.0008711026523482974,3.77087311410897,18.70985963452592,0.0002743254094535652
0.0003216296239876,23.2744018079902,0.00102117405616063,4.692119404490824,23.28188754509224,0.0003215779122678329
0.0003601152351081,28.1657826312096,0.0011433658714682176,5.678221778451855,28.17592555864384,0.0003600504091794959
0.0004111823790664,33.1833472065012,0.00130550405353582,6.689762796830642,33.19699161415096,0.0004110978667578819
0.0004861856557333,38.2756558086233,0.0015436394569532275,7.716372211018458,38.29426488344123,0.0004860675057809543
0.0005414254937964,43.5074827386462,0.00171902594280357,8.771108520111074,43.53103879897181,0.0005412789758969537
0.0006317781767785,48.7577813612479,0.0020058957112717374,9.829568722427577,48.788585463460066,0.0006315786889630137
0.000703265828193,54.155546944505,0.002232869004512775,10.917758264012207,54.19363269007817,0.0007030186526603078
0.0007799783582012,59.6583169360725,0.00247643128728881,12.027116694312218,59.70484913216935,0.0007796743331599382
0.000867226837924,65.1724377581397,0.0027534452104086998,13.138763452040962,65.22895704525648,0.0008668510139971116
0.0009488275230903,70.7079145859132,0.003012527385811702,14.2547155805201,70.77500420137262,0.0009483776707882787
0.0010354734891744,76.1736823788285,0.00328762832812872,15.356614367571826,76.25255820750458,0.001034937756293943
0.0011122393477492,81.6873504097509,0.0035313599291037097,16.468169842605782,81.77820629509,0.001111621267825258
0.001195905169501,87.2031575086774,0.003796998913165675,17.580156553749365,87.30744421553884,0.001195190644526417
0.0012720746196906,92.6920191685606,0.004038836917517655,18.686711064381818,92.8099303335928,0.0012712662182635585
0.0013624283516826,98.1289144076335,0.004325710016592255,19.782789144578913,98.2626080227423,0.0013615010883003147
0.0014512770788053,103.574598135535,0.004607804725206827,20.88063898412386,103.72491357575558,0.0014502249940136094
0.0015382581561198,109.027271557817,0.004883969645680365,21.979897946055907,109.19498364753031,0.0015370762489394158
0.0016275561399184,114.385822444552,0.00516749074424092,23.06018180482169,114.57199179219126,0.0016262331057711249
0.0017155449490558,119.810763295057,0.005446855213252165,24.15384988028349,120.01630404487035,0.0017140750826608116
0.0018028098826001,125.159332370633,0.005723921377255317,25.23212140591961,125.38497085193042,0.0018011867713449918
0.0018917659812337,130.49464830445,0.006006356990416998,26.307721098177122,130.74151364084543,0.0018899788455098451
0.0019816863973521,135.758225805647,0.006291854311592917,27.368858322418433,136.02725603505468,0.0019797254470949486
0.0020648683191445,140.918363878491,0.006555956913283787,28.409142157903783,141.20934174364936,0.002062739408666205
0.0021534910872147,146.028209864354,0.0068373342019066715,29.439287108653772,146.3426803127788,0.0021511756488714106
0.0022317809090876,151.067595306076,0.00708590438635313,30.45522721370492,151.40474508126186,0.0022292941852691634
0.0023222748578775,155.960731754827,0.007373222673761062,31.441683521773125,156.32291544099743,0.002319582545007754
0.0024041606260883,160.803026515718,0.0076332099878303515,32.41789014556875,161.1896228206229,0.002401275255601006
0.0024901450336669,165.549834878578,0.007906210481892407,33.37484671152132,165.96207797772527,0.0024870497599114453
0.0025802680029321,170.25409738843,0.008192350909309417,34.32322603350749,170.69339858828945,0.0025769448266780453
0.0026700917231539,174.922913599721,0.008477541221013631,35.26445938170376,175.38997382351357,0.0026665333609438243
0.0027635423649684,179.421371840908,0.00877424700877467,36.171348563127054,179.91721040317108,0.002759730802428407
0.0028469374394171,183.885732855641,0.009039026370149292,37.07136374369723,184.4092440330824,0.002842892588165549
0.0029325685121814,188.187823198732,0.009310905026175945,37.93866515686437,188.73969688342058,0.002928276921351044
0.0030119801952788,192.474851276081,0.00956303712001019,38.802930017257935,193.0545817162138,0.0030074532706573943
0.0030954707879171,196.708044188397,0.009828119751636792,39.656341708380836,197.3169481929305,0.003090689682192212
0.0031844034075717,200.90674877559,0.010110480819040146,40.50280055315894,201.5465169109951,0.003179343933133537
0.0032738761270642,205.163432680421,0.010394556703428835,41.36094802837288,205.83511234481995,0.0032685286627283146
0.0033724916050974,209.379525782663,0.010707660846184245,42.21091239778486,210.0856564756443,0.0033668175089331415
0.0034632530059613,213.554826933202,0.010995828293927127,43.05265310973353,214.29442132951596,0.0034572697556299018
0.0035576679831022,217.626930901182,0.011295595846349484,43.873589269678284,218.40117526550992,0.0035513544522299046
0.0036453575598228,221.602551710525,0.01157401025243739,44.675074424841846,222.410372247679,0.0036387293472060927
0.0037342881319309,225.342621641508,0.011856364818880607,45.42907252292802,226.1841159191221,0.003727332987635713
0.0038326502480253,228.812344998107,0.012168664537480327,46.12856875161837,229.68930268891523,0.0038253243564838756
0.0039362955242242,232.018754343067,0.012497738289411834,46.774980875562306,232.9320487273237,0.0039285685833748175
0.0040459269174989,235.049959758027,0.012845817963059007,47.38607188721824,236.000954717169,0.00403776416504716
0.0041601542525983,238.014982749037,0.013208489751999602,47.98382052220586,239.00516179170248,0.004151524736029988
0.0042765619806042,240.809583293395,0.013578084288418335,48.54721199194844,241.83942040187267,0.00426744347740283
0.0044121036389114,243.351420948105,0.014008429053543695,49.05964646313797,244.42511263800435,0.004402398844884835
0.0045662898840284,245.657884702773,0.01449797038179017,49.524629556079034,246.7796298166231,0.0045558960113222
0.0047429073269531,247.683436144693,0.015058730763076093,49.93298072677011,248.8581757287486,0.004731695180135806
0.0049509638629878,249.377517086667,0.015719310264986266,50.274507444672075,250.61217616200474,0.004938748144530662
0.005183051067735,250.771200510827,0.016456187140058625,50.555474022982715,252.07096044939183,0.0051696652914020895
0.0054401425052475,251.7681667436,0.017272452454160814,50.75646241550976,253.1378214489701,0.00542539837926792
0.0057266597748932,252.550844125514,0.01818214478528591,50.91425017570363,253.99711688568294,0.0057103247923922
0.0060337031079113,253.139145089947,0.019157007367618377,51.03285165013332,254.66651153641024,0.006015573211704169
0.0063543501314816,253.565953087595,0.02017506166745408,51.11889614245916,255.17719993493643,0.006334246367974942
0.0066962932627223,253.897887815523,0.021260731109143303,51.18581418360944,255.59806253112154,0.006673972679035858
0.0070445942590989,254.189360061213,0.022366586772639006,51.24457498834054,255.98002096782423,0.0070198970251203075
0.0073979966196584,254.401929700921,0.02348863926741542,51.28742902770568,256.28399431688297,0.0073707656632094175
0.0077560775060362,254.606459244823,0.024625546081664933,51.328662183756315,256.58120667626326,0.007726153764540436
0.0081152345840888,254.776090493365,0.02576586980448194,51.36285984346239,256.84365823413566,0.00808248313903843
0.0084770391073571,255.033132911057,0.02691459916585879,51.41467959486909,257.1950587524159,0.008441310782951088
0.0088453325407757,255.247697748749,0.028083930816962845,51.4579358661478,257.50544851560414,0.00880644175327733
0.0092169545582395,255.454558414082,0.029263830722410407,51.49963897627893,257.8090714706797,0.009174737641902742
0.0095891613424542,255.626899828962,0.03044558726229208,51.53438300551874,258.0781474148933,0.0095434771513588
0.0099556174445005,255.768516112368,0.031609085386289086,51.56293284825339,258.3148496131303,0.009906386763383856
0.0103256498530437,255.956365370859,0.03278393828341374,51.600803258765175,258.59928117733625,0.010272704482278502
0.0106934355057341,256.187578666971,0.03395165773070576,51.64741585926134,258.92710401681643,0.01063666507959779
0.01106997775882,256.436840508543,0.0351471793842535,51.69766704652228,259.2755906295146,0.01100915402164606
0.0114424868502757,256.603727106235,0.03632989574962535,51.73131138461697,259.5399118793798,0.01137751674097286
0.0118091138303179,256.676068163626,0.03749393641125933,51.745895341787,259.70718507008866,0.011739930376461111
0.0121760997606803,256.802255680521,0.03865911674015995,51.77133474519304,259.92910556445474,0.012102567348233412
0.0125341982334747,256.940952834096,0.03979607939128217,51.79929609135375,260.16150167121646,0.012456295461221316
0.0129013795615442,257.219068373759,0.04096188010790283,51.85536418414981,260.53754920531566,0.012818865701536309
0.0132621590765311,257.412524481848,0.04210735506798624,51.89436493554055,260.82637032981773,0.013174986529810936
0.0136329018931921,257.551756319376,0.04328446351088491,51.92243407398621,261.06293414569734,0.013540809929289806
0.0140007343252332,257.710709185419,0.04445233148261541,51.95447897178047,261.3188483574915,0.01390362935534981
0.0143636856427257,257.83228518965,0.0456047019156541,51.97898869423344,261.5357070826597,0.014261505206250207
0.0147303552944236,258.055422624138,0.04676887805979493,52.02397320102622,261.85667068504415,0.014622917391483152
0.0150995465965031,258.261161198224,0.04794106044389734,52.06545009756195,262.16078763580356,0.014986683149201832
0.0154651512426694,258.428614006306,0.049101855195475344,52.0992085836713,262.425251607347,0.015346784603251546
0.0158291266166946,258.583535522068,0.050257477008005355,52.13044076124891,262.6766870468394,0.01570515254815036
0.0161815840145656,258.72511118335,0.05137652924624578,52.15898241456336,262.9116933066412,0.016052057610768066
0.0165512521511831,258.887949489056,0.05255022558000634,52.19181061699369,263.1728692199521,0.016415773032800573
0.0169162117845937,259.057700626645,0.053708972416084994,52.22603244633163,263.4399755548752,0.01677472604660789
0.0172800494016809,259.197532890162,0.054864156850336854,52.25422263065666,263.6764790632978,0.017132447302820226
0.0176406957274524,259.369184124409,0.05600920893466136,52.288827519480854,263.9446369826253,0.01748690467459818
0.0180000106113074,259.522512091849,0.05715003369090099,52.31973843771676,264.19392006337546,0.01783992855201209
0.0183549807060726,259.719450582085,0.0582770637417805,52.359441237348335,264.48659608651093,0.018188561378679417
0.018709809940233,259.832750667062,0.05940364656023977,52.3822825344797,264.6941720482907,0.01853693442933379
0.0190628250009765,260.011427709517,0.06052446937810038,52.418303826238635,264.9679800541976,0.018883405922985163
0.0194142130780487,260.162989089148,0.061640126522804616,52.44885860037224,265.21384879434686,0.019228161418375755
0.0197653458684177,260.284874489061,0.0627549731322262,52.473430696994704,265.429495057655,0.019572547759734278
0.0201174496569117,260.429780816452,0.06387290266069465,52.50264381259672,265.6689638211875,0.01991776738976712
0.0204699663629465,260.590281436015,0.06499214320235513,52.535000737500624,265.92455573152097,0.020263272519098072
0.0208302106109147,260.758823068863,0.06613591868965417,52.56897873068279,266.19048427204166,0.020616228204667183
0.0211812916619689,261.004637202624,0.06725060102675126,52.618534860048996,266.5330525483392,0.02096008626239389
0.0215325296920868,261.09351530815,0.06836578177237558,52.63645268612305,266.7155191789341,0.021303979792566936
0.0218857245425917,261.265289705891,0.06948717542272864,52.67108240470763,266.98326986893454,0.021649670013636685
0.0222412193343421,261.41879417709,0.07061587138653616,52.70202890610134,267.2330669165019,0.02199749067751413
0.022597635580074,261.593529133533,0.07174749296673495,52.73725547332026,267.5049243749981,0.02234609149609179
0.0229498474385154,261.771135985515,0.07286576561728639,52.773061014679826,267.77874362018946,0.02269046078093709
0.0233062506976083,261.91586644189,0.07399734596490636,52.80223867468502,268.02014328686596,0.023038807464445022
0.0236550362216057,262.036266381866,0.0751047400035981,52.826511302584194,268.23474375450337,0.02337959117110499
0.0240090077667429,262.175282817738,0.0762285996594087,52.85453701605598,268.4698512191571,0.023725323225835704
0.0243594267561442,262.350385366433,0.07734117995075783,52.88983768987289,268.74109036321283,0.02406746772182945
0.0247110023500102,262.566978494586,0.07845743246128238,52.93350286450854,269.05527171720075,0.024410623908480658
0.0250654808973223,262.742752083428,0.0795829018489983,52.96893882001908,269.32852551668503,0.024756494352153966
0.0254216729450926,262.829397158561,0.080713811600669,52.9864064671659,269.5109601334818,0.02510391623254533
0.0257710587414299,262.888984783258,0.08182311150403992,52.99841933230482,269.66391225258224,0.02544458222099092
0.0261235506634365,262.901414710093,0.08294227335641088,53.00092520555475,269.76933313676125,0.02578815924863985
0.0264700571022935,263.026973090271,0.08404243129978185,53.026237774998634,269.9893120874139,0.02612578715592521
0.0268192876285995,263.107840459281,0.08515123822080341,53.042540636591056,270.16420530989814,0.02646595405015249
0.0271654006940557,263.227049750268,0.08625014720362685,53.06657322965403,270.37771803024816,0.02680297026132461
0.027508696321566,263.391119975649,0.08734011082097204,53.09964978709084,270.6366663088563,0.02713713092573708
0.0278467006289029,263.469788656413,0.0884132744967667,53.11550939313286,270.80655298588846,0.027466032011053392
0.0281882034253927,263.644299099695,0.08949754587562181,53.150690698498515,271.07595823466227,0.02779822753843165
0.0285312818628872,263.792939609451,0.09058681991466686,53.18065662526533,271.3192903228878,0.028131844682753555
0.0288826452675174,263.961686614973,0.09170239872436774,53.21467602157856,271.5855983736889,0.0284734029889485
0.0292305581891564,264.163927114877,0.09280702225057157,53.25544770635921,271.88558615788446,0.028811492190619712
0.0295792004011348,264.254454007218,0.09391396127360298,53.273697927855146,272.07088945918997,0.02915017546512473
0.0299279618039076,264.332147772839,0.09502127872740662,53.289360991004344,272.2430701949294,0.029488859799422673
0.0302729632890306,264.442724071677,0.09611665844267216,53.311653172850086,272.4481889495501,0.02982378003379965
0.0306260769357716,264.61219121823,0.09723779427107483,53.34581774959517,272.7162245446226,0.03016645926582833
0.0309800727361064,264.750712484971,0.0983617309371378,53.37374363697016,272.95270881469145,0.03050987675502267
0.0313383249752707,264.85045066525,0.09949918179648447,53.3938508541144,273.1504201580445,0.030857303460002317
0.0316970574222008,265.005072671944,0.10063815731548754,53.42502265066391,273.4049536776011,0.03120507495593155
0.0320569178947047,265.11808848115,0.10178071431568743,53.44780663779984,273.6169572759913,0.03155381853724521
0.0324170466134095,265.252171606906,0.10292412299757517,53.474837795952254,273.8508636181952,0.031902700362396626
0.0327719903286247,265.264396335072,0.10405106929338341,53.477302301150516,273.95763856629344,0.03224644005146235
0.0331299383056007,265.272851099236,0.10518755412028222,53.479006781605975,274.06132429030447,0.03259296955085108
0.0334750564931352,265.305727684665,0.10628330436570427,53.48563470122846,274.1868519068615,0.032926964863560865
0.0338275889458001,265.431077860642,0.1074025949029153,53.51090529670543,274.4099712559525,0.033268020351357924
0.0341777175803142,265.638013347876,0.10851425331749759,53.5526234909318,274.7169143466754,0.03360663518639201
0.0345269743476011,265.76925153296,0.10962314355363349,53.57908110904475,274.9454596630197,0.03394429263162141
0.0348776677831705,265.907778146383,0.11073659521156634,53.60700807431082,275.1820212935336,0.03428322435312904
0.0352252946612741,266.010804962793,0.11184031054954527,53.62777828049906,275.38111395069006,0.03461907903058014
0.0355718588855223,266.142084418562,0.1129406519615333,53.6542442187821,275.60925308899783,0.03495379479633265
0.0359273048326681,266.219291493814,0.11406919284372122,53.669809165152905,275.7838331316492,0.03529697229488996
0.0362801686775161,266.33591251647,0.11518953555111361,53.69331996332035,275.9986243474477,0.03563754036326094
0.0366332239691428,266.447740792947,0.11631048610202839,53.71586454385812,276.2085805574871,0.035978177165833514
0.03698528360347,266.521795113702,0.11742827544101724,53.73079389492233,276.37917929248823,0.03631773782892024
0.0373346149152309,266.617321074012,0.1185374023558581,53.750051928520826,276.57137608604074,0.036654553105399806
0.0376788899611662,266.621843654597,0.11963047562670269,53.75096368076675,276.6678587629018,0.036986382318352135
0.0380318813205208,266.732813124337,0.12075122319265354,53.77333512586633,276.8771638173704,0.03732649845364526
0.0383851581480684,266.862696400257,0.12187287712011717,53.799519594291816,277.1062632054008,0.03766677386483796
0.0387449472214486,267.017735131725,0.1230152074280993,53.83077540255576,277.36332318659436,0.03801320288827601
0.0391054485871062,267.136289865529,0.12415979926406218,53.85467603689065,277.5827743146158,0.03836019742647971
0.0394628884950302,267.23911036015,0.12529467097172087,53.875404648606235,277.78513757380364,0.038704126375141513
0.0398219755611605,267.280948458078,0.12643477240668458,53.883839209148526,277.9246038555394,0.03904952115572936
0.0401763028794571,267.389008336594,0.12755976164227628,53.90562408065735,278.13171012216264,0.03939022078552877
0.0405330816979045,267.483407618267,0.12869253439084677,53.92465497584262,278.3253344320921,0.03973316038544475
0.0408894443254305,267.535701942502,0.12982398573324183,53.93519751160841,278.4750881321449,0.04007558257656872
0.0412503307611136,267.61997260074,0.13096980016653567,53.95218647630919,278.6593849888007,0.040422232156597106
0.0416085931727272,267.70935622075,0.13210728332340885,53.9702062141032,278.8483659122719,0.04076624241195338
0.0419693570273613,267.830082023555,0.13325270856187213,53.99454453594869,279.0707383586691,0.04111253505553283
0.0423269864919582,267.899868427106,0.1343881821119673,54.00861347490457,279.2392625392175,0.04145570071834121
0.0426862792541975,267.979552993145,0.13552893663207705,54.02467788341803,279.4186030266254,0.04180034386445292
0.0430452155039196,268.022896782979,0.13666855922494472,54.033415991448564,279.5600001349871,0.042144526472969394
0.0434079258624236,268.097154119439,0.1378201646131949,54.04838627047889,279.73469550938233,0.04249220776517444
0.0437722117068804,268.164963516379,0.13897677216934526,54.06205664490201,279.90313707178575,0.04284127763374846
0.0441283375836578,268.223774828254,0.1401074718281135,54.073913005376006,280.06004411183824,0.04318241062530983
0.0444900507612825,268.286254580459,0.14125591116707192,54.08650892342053,280.22232366529795,0.04352877660892774
0.0448509229158707,268.409627148717,0.14240168025788946,54.11138083318135,280.4480466458417,0.04387421774345131
0.0452080473800603,268.534014020391,0.14353555043169144,54.13645722651083,280.6739124493826,0.04421595400327992
0.0455701569700339,268.682837946627,0.14468524837985763,54.16646013004001,280.926757047009,0.04456234138463003
0.0459244898245952,268.781028863761,0.14581025519308974,54.186255418934216,281.124660488859,0.04490117357671262
0.0462865315019021,268.843546596387,0.14695973751853916,54.19885899383162,281.28738188500375,0.04524725882072495
0.0466402486161639,268.862139886419,0.14808278935632038,54.20260740110208,281.4019369341954,0.04558527075787412
0.046998059893852,268.821291130183,0.1492188401629801,54.19437229184489,281.45537027146196,0.04592707887221494
0.0473578677857716,268.835814630775,0.1503612302198248,54.19730022956424,281.5673055961395,0.046270676529809
0.0477193017258038,268.944820128416,0.15150878297942705,54.219275737888665,281.7786791477159,0.04661570815812088
0.0480806142553709,269.094813206186,0.1526559502608026,54.2495143423671,282.0330571180737,0.046960504939904855
0.0484425365065829,269.258060675383,0.1538050534084007,54.28242503215721,282.3016041093419,0.04730576442790582
0.048803516938525,269.375913934086,0.15495116627981687,54.30618424911174,282.5224059125988,0.04765000675933279
0.0491723553153972,269.428109724362,0.1561222281263861,54.31670692043138,282.67652446768415,0.04800162031747714
0.0495423250447407,269.449490660157,0.15729688201705172,54.321017317087644,282.79864490958226,0.04835418823596377
0.0499082780399285,269.477877156372,0.15845878277677297,54.3267400347246,282.9270539751019,0.048702806106140334
0.0502798170331277,269.504250563786,0.15963841908018045,54.332056913659265,283.05487497178336,0.04905662107913904
0.0506515549588762,269.639333091853,0.16081868699443194,54.35928955131757,283.29698459102974,0.04941050025347432
0.0510259573272418,269.691935103363,0.1620074145139927,54.369894116837976,283.45322427544846,0.04976678933221026
0.0513986461790224,269.74131295529,0.1631907016183961,54.37984869178648,283.6056512597439,0.050121321765918186
0.0517719212489558,269.746146323592,0.16437584996543464,54.380823098836146,283.7114225682663,0.050476285913509236
0.0521412253527136,269.760956298739,0.16554839049486567,54.38380878982579,283.8266231124751,0.05082734993737091
0.052515088046345,269.804213181273,0.16673540454714536,54.39252937734464,283.97300519176235,0.051182621907605266
0.0528850321436892,269.891689301528,0.1679099770562132,54.41016456318805,284.16491996555385,0.05153404594107408
0.0532598392261197,270.000101127716,0.16909998954293004,54.43202038734755,284.3802631048142,0.051889963609874704
0.0536287158514838,270.063366936991,0.17027117282846105,54.44477477449738,284.5465185043499,0.052240126059848
0.0540016749984066,270.077343525865,0.17145531811994094,54.447592454814384,284.6619724553818,0.05259403930045688
0.054371263890217,270.059362272661,0.17262876285143897,54.443967434168464,284.7428311248116,0.052944630876338834
0.0547433962407813,270.125907258554,0.1738102830644806,54.45738290332448,284.91351683450955,0.0532975110316575
0.0551061373967408,270.21900372166,0.17496198623465203,54.476151150286654,285.1097292679562,0.05364136603529672
0.0554768670715561,270.319633990976,0.17613905295219062,54.49643821258076,285.3161203927251,0.05399267150666969
0.0558457177825893,270.402574511952,0.17731015395972102,54.513159021609525,285.5034003758321,0.054342074025670435
0.0562263191941856,270.436821398028,0.17851856344153927,54.52006319384245,285.6424884398145,0.05470247974010895
0.0566069831812286,270.484102718123,0.1797271716004008,54.52959510797359,285.79539177147745,0.055062814832076507
0.0569906741251244,270.539255318096,0.18094539034726997,54.540713872128165,285.9574698559835,0.05542588388335442
0.0573617639569832,270.560609741944,0.18212360056342164,54.54501892397592,286.08044357401883,0.055776903731309065
0.057739007483011,270.587825488949,0.18332134875855993,54.550505618572124,286.21129796966716,0.05613361820574163
0.0581154591916648,270.656407576255,0.18451658293353573,54.564331767373005,286.38572898571545,0.05648945715265901
0.0584993626142929,270.71700558136,0.18573547630037995,54.576548325202175,286.55377785671953,0.05685220943321831
0.0588893570596804,270.767631835926,0.18697370866448526,54.58675457812268,286.712963587316,0.05722058246380455
0.0592731499546952,270.787388298068,0.18819225110615725,54.5907374808905,286.83780977049963,0.05758296532908882
0.0596584186598838,270.816605206663,0.18941547924513105,54.59662760966326,286.97309562013055,0.05794660964412075
0.0600469601107362,270.867992224383,0.19064909835158741,54.606987232435614,287.1327917487557,0.058313209133932196
0.0604205532257591,270.874408336913,0.19183525649178512,54.60828072072166,287.24078994332945,0.05866557776635755
0.0607979143936751,270.885692492082,0.19303337819991845,54.610555606403736,287.354977634687,0.05902137437821738
0.0611777968133174,270.904213459549,0.19423950488228273,54.61428943344509,287.47753638644883,0.05937942034612774
0.0615573250066868,270.938053839657,0.19544450689623058,54.62111165407486,287.616275676544,0.05973700447757422
0.0619452426205248,270.989903234583,0.19667614532016625,54.63156449209193,287.77643853816176,0.06010236086947772
0.062325068495425,271.018054998833,0.19788209247297436,54.637239887764736,287.90927384013213,0.060459966845478566
0.0627021038881347,271.075765242359,0.19907917984482765,54.64887427285958,288.07278603614105,0.06081481915190171
0.0630822165028012,271.119095538941,0.2002860373963938,54.65760966065051,288.2218890217721,0.06117244020975912
0.0634636682383768,271.184893254932,0.20149714665684634,54.67087448019429,288.39528135172264,0.06153119262832111
0.0638549898408986,271.196666441621,0.20273959274485304,54.673247954630796,288.5139268221363,0.06189909388791792
0.064241303285915,271.247000874952,0.20396613793278012,54.68339537639033,288.67226172355464,0.062262154009311385
0.0646320430523952,271.275049248937,0.20520673669135475,54.6890499285857,288.80810991103493,0.06262923998137263
0.0650238992600722,271.339795630207,0.2064508801507292,54.702102799049726,288.98336716651414,0.06299723952938763
0.0654197708957509,271.415986994187,0.2077077725940091,54.717462978028095,289.1719586807908,0.06336887258008068
0.0658154074347137,271.455379143584,0.208963918605216,54.72540443534654,289.3213255222637,0.06374014699177412
0.0662070597115757,271.49037377412,0.21020741458425282,54.73245935286259,289.4649531617011,0.06410754676105669
0.0666074537376527,271.483730332721,0.2114786656170473,54.73112003507656,289.56657034138306,0.06448300747576571
0.0669999790315128,271.407266620181,0.2127249334250531,54.7157049506285,289.59154779273337,0.06485095266780054
0.0673933732574495,271.330223520371,0.21397396009240216,54.7001730617068,289.61608255010657,0.06521957659550293
0.0677851149358715,271.30411336583,0.215217739921392,54.694909254551334,289.6944938729075,0.06558651705034896
0.0681771467567031,271.327566852484,0.2164624409525323,54.699637477460776,289.82590619692496,0.0659535945331909
0.0685706999704974,271.407337218521,0.21771197240632925,54.71571918325383,290.0179283087238,0.06632196108504887
0.0689658375290702,271.417073303798,0.2189665341547979,54.71768197804568,290.1355790838835,0.06669167412259629
0.0693600345134462,271.45605375873,0.2202181095801917,54.72554043775997,290.2842550163194,0.0670603709559418
0.0697524923226358,271.443525614308,0.22146416312436867,54.723014763844496,290.3773880507492,0.06742730612991651
0.0701438837182098,271.438806930738,0.2227068308053161,54.72206347723678,290.4785790406973,0.06779311019811401
0.0705335066281758,271.452400535878,0.22394388354445816,54.724803948033006,290.5988902283096,0.06815712853737939
0.070932882531263,271.444161521379,0.22521190203676,54.72314296271001,290.6984783443721,0.06853012146385172
0.0713280271525965,271.496271353471,0.22646648620949386,54.733648304859756,290.86156476840006,0.0688990257593356
0.0717301538989712,271.549325365197,0.22774323862923354,54.744343993623716,291.02760026480433,0.06927430885211375
0.0721371236888146,271.611353117186,0.22903536771198635,54.756848788424705,291.20461489228677,0.06965396835714598
0.0725419451589106,271.657851543928,0.23032067587954116,54.766222871255884,291.36444051261515,0.07003148076054841
0.0729438866994001,271.6542858453,0.23159684027059532,54.765504026412486,291.469805293406,0.0704061665675795
0.0733466358120309,271.648626588733,0.2328755687031981,54.76436312028857,291.5731394719752,0.07078146442510047
0.0737536780457848,271.629441509659,0.23416792779536671,54.76049540834725,291.6631118865187,0.07116061973144835
0.0741693134260092,271.646528933782,0.2354875701275792,54.763940233050455,291.7943654793592,0.07154763117186078
0.0745849449464066,271.628334936443,0.23680720020484097,54.76027232318692,291.88771934356174,0.07193448930043596
0.0749918570155691,271.613793703218,0.23809914602443186,54.75734081056875,291.98261648406594,0.0723130866816985
0.0754028608655661,271.608443383594,0.23940408324817233,54.75626218613255,292.08849704996015,0.07269534567032442
0.0758120571472063,271.606263693467,0.24070328144238,54.75582276060294,292.1972932781353,0.07307577840454269
0.0762292195055974,271.619369516754,0.24202777193027172,54.7584648945776,292.3247020576186,0.0734634683323725
0.0766492362950874,271.63627605537,0.24336132523690246,54.76187325276259,292.45698916505563,0.07385365923579981
0.0770622591057232,271.628804843295,0.24467267266067116,54.76036705640827,292.5611341827069,0.07423720440104689
0.0774746102875919,271.62675693779,0.24598188766310425,54.75995419865846,292.6709340752277,0.07461997917994344
0.0778844212688711,271.543507796243,0.24728303752866573,54.74317117172259,292.69251675027255,0.07500025084718567
0.0782889879129055,271.431770334255,0.24856753662347497,54.72064489938582,292.68188892113204,0.07537551440164665
0.0786983849885031,271.335603800392,0.24986737233849732,54.70125772615903,292.68927760936316,0.07575511521494487
0.0791060951809953,271.336358441754,0.2511618521996601,54.7014098618576,292.800718238712,0.07613300876469971
0.0795183830052238,271.405030584258,0.2524708660415856,54.71525416578641,292.98671975580146,0.07651500001274511
0.079936621264371,271.463034847802,0.2537987725143779,54.726947825316884,293.1628726517075,0.07690235539968295
0.0803600891251313,271.492360651529,0.2551432829722919,54.73285990734825,293.30951095027814,0.07729440142201639
0.0807795840769764,271.483886604511,0.25647517944440007,54.73115153946941,293.41424204802445,0.07768261784533738
0.0811953020148044,271.469867352916,0.25779508389700395,54.728325258347866,293.51194522055494,0.07806719025237675
0.0816180429194243,271.485690081258,0.25913728626917215,54.73151512038161,293.6438207863196,0.07845810786067932
0.0820457143694488,271.524108248808,0.26049514312299993,54.73926022295969,293.801497678609,0.0788534294111315
0.0824772497632764,271.499418919471,0.26186526799840254,54.73428285416536,293.89194430427665,0.0792521642886965
0.0829072979147508,271.443346310659,0.2632306708793338,54.72297861622886,293.9479806902137,0.07964936686187409
0.0833294159698209,271.369343906497,0.2645708957041813,54.7080597315498,293.9823928463389,0.08003909163914086
0.0837592772477515,271.325910836575,0.26593570526161103,54.699303624653524,294.05197302683445,0.08043580939685324
0.0841893619262857,271.323834362707,0.2673012241159571,54.69888500752173,294.1664148530965,0.08083257588514062
0.0846296885721477,271.30223675977,0.26869926121656895,54.69453093076964,294.2624605656764,0.08123862788086701
0.0850644123451401,271.258055012092,0.2700795091958198,54.685623890437746,294.33246205558123,0.08163935144703773
0.085501654350897,271.211769804043,0.27146775256409794,54.67629279249507,294.40082480172333,0.0820422343800938
0.0859331406126768,271.12803571217,0.2728377214452488,54.65941199957348,294.4269193290628,0.08243965480317975
0.0863675215740157,271.049309293575,0.2742168809974998,54.64354075358472,294.45916636160985,0.08283958191703618
0.086810135265779,270.966467132554,0.2756221794688483,54.62683977392288,294.48910279682127,0.08324692431400088
0.0872455089181902,270.882078657503,0.27700449081525386,54.609827057352604,294.5153234667941,0.0836474418070981
0.0876739019693855,270.820124794118,0.27836463875279893,54.597337158494184,294.5639818666542,0.08404138105339003
0.0881024129451876,270.771392229684,0.2797251611009706,54.5875126735043,294.62700524164694,0.08443527354905234
0.0885291066597946,270.760495614002,0.28107991364484786,54.585315915782814,294.7306804094729,0.08482734149094304
0.0889622695316218,270.752344598285,0.2824552057628992,54.583672671014256,294.8390876547562,0.08522519645586016
0.0894033023811394,270.757679384059,0.2838554850601176,54.58474816382629,294.9643100660476,0.08563011733895713
0.0898461410628291,270.654575072406,0.28526149787448235,54.56396233459704,294.9718442036614,0.08603653128951917
0.0902878322081506,270.588937851767,0.28666386726087817,54.55072987091623,295.01982646990905,0.08644172762770759
0.0907192591504604,270.513787334787,0.2880336478027118,54.53557952669306,295.0545977117841,0.08683734940229629
0.0911560266274177,270.493976266893,0.2894203845420512,54.53158561540563,295.15113237003396,0.08723770911638098
0.0916049473163207,270.490898666489,0.2908457077293182,54.53096517116418,295.269203188377,0.08764904201136271
0.0920631956546341,270.450342680602,0.29230064620346324,54.52278908440936,295.34886549366905,0.0880687471268265
0.0925251262783938,270.412973332618,0.2937672759339003,54.51525542385579,295.43296783753436,0.08849164660496284
0.0929807490470297,270.358611329648,0.29521387822431927,54.504296044057035,295.49675752239347,0.0889085960905541
0.0934347924437458,270.304106073582,0.2966554660088929,54.49330778443413,295.55991412125934,0.08932392738931832
0.0938855907669778,270.251544241275,0.2980867506851545,54.48271131904104,295.6242701280551,0.08973611970743951
0.0943448277168219,270.182288298115,0.29954482800090954,54.46874932089999,295.67258973973736,0.09015585334490955
0.0948009342570422,270.089968116194,0.30099296626610894,54.450137572224705,295.69474942706387,0.09057255154266568
0.0952654502342513,269.96159712853,0.3024678044937479,54.42425798111165,295.679610224937,0.0909967541946623
0.0957166362793246,269.860742978796,0.3039003201868556,54.40392578452527,295.69090556056574,0.09140861155691854
0.0961738468391799,269.756336940058,0.30535196371439616,54.382877527115696,295.69984157282937,0.09182579532591409
0.0966256981145297,269.719133892846,0.3067865915136318,54.37537739279776,295.78093350008857,0.09223791806899381
0.0970837756175452,269.694745638616,0.308240987585706,54.37046072074499,295.8777298094263,0.09265554630569373
0.0975407771075664,269.648822217398,0.30969196731652326,54.36120255902743,295.950577882623,0.09307201981690044
0.0980094730163206,269.585226163547,0.31118007682681786,54.34838159457109,296.00713211282186,0.0934989705695397
0.0984702418412855,269.514466584897,0.31264301784608145,54.33411646351523,296.05362128923684,0.0939185226633806
0.0989361979638549,269.451960004374,0.3141224285352393,54.32151513688179,296.11051246111543,0.09434261910827374
0.0993965615277739,269.407896405699,0.3155840828506821,54.31263191538891,296.18611495685616,0.094761448849732
0.0998740105321727,269.326858512354,0.3170999834396483,54.296294676090575,296.2256120160139,0.0951956373647471
0.100344152776551,269.243772381314,0.3185926850655494,54.2795445120729,296.26081061127945,0.09562299703241446
0.100819269172519,269.164099916492,0.3201011796227478,54.263482543164784,296.30102775755154,0.09605469274260929
0.101288318187508,269.100736838745,0.32159041024533785,54.25070854669099,296.3574978961606,0.09648069283885777
0.101765308996346,269.044191823744,0.32310485606339856,54.23930907166679,296.42355713835946,0.09691371980688597
0.102228650967869,268.921186230814,0.32457596682298406,54.2145111441321,296.4126363158691,0.0973341764748856
0.102704740287355,268.819347738061,0.3260875504123521,54.19398050399311,296.4283690317148,0.09776601657379562
0.103174341129453,268.74344803713,0.32757853308601326,54.17867912428541,296.4708762212183,0.09819178864185518
0.103652245546839,268.704406063724,0.3290958796112138,54.170808262446755,296.5562211405586,0.09862490325787626
0.10413334904523,268.642753576,0.33062338321860524,54.1583791209216,296.61742320260134,0.0990607277393701
0.104617979587162,268.556462615686,0.33216208518923934,54.1409828633223,296.65229713961423,0.09949955536421558
0.105105604269874,268.463553650255,0.33371029355684995,54.12225241589141,296.68057768110276,0.09994089987824382
0.10559357535607,268.335667771102,0.3352596017555222,54.096470622654174,296.6701903266112,0.10038236301227696
0.106073769976071,268.264680215021,0.3367842196740254,54.082159531348225,296.72052619685337,0.10081660067334301
0.106563920736521,268.169498166543,0.33834044833845417,54.06297083037507,296.7466913131151,0.10125964724217353
0.107051961375497,268.1290207832,0.33988997736720294,54.05481058989312,296.83275835973296,0.10170059153682498
0.107542927645893,268.06913505729,0.34144879527571026,54.04273762754967,296.89807465285327,0.10214398304005064
0.108037227380251,267.986889082876,0.3430181969322969,54.026156839107806,296.9394495536488,0.10259018647930586
0.108531750257582,267.851005944642,0.3445883070678228,53.99876279843983,296.921344428068,0.10303639220583635
0.109028845090114,267.717769271309,0.34616658316111193,53.971902285095894,296.90672846506146,0.1034847180300786
0.109529374998006,267.612729714105,0.347755765618669,53.95072631036357,296.9241847412012,0.10393593892827474
0.110029434943203,267.526673469938,0.3493434559446695,53.9333773715395,296.96248218407004,0.10438653293949719
0.110530999893006,267.456073595711,0.350935924660294,53.919144436895344,297.01826083770237,0.10483827921981831
0.111035858691695,267.312768678477,0.3525388513461316,53.89025416558098,296.9940714879462,0.10529278618676302
0.111539862455071,267.195614205716,0.3541390632948504,53.86663582387235,296.9985762628198,0.10574631743631246
0.112050066769609,267.097046600644,0.3557589619935086,53.84676459468983,297.0252885062115,0.10620521888822679
0.112563038319872,267.017194800537,0.3573876466655936,53.83066647178826,297.0734615309346,0.1066663971112456
0.113072674946997,266.920530281834,0.3590057429567155,53.81117890481774,297.10194863907185,0.10712436661002264
0.11358255809286,266.796096175868,0.36062462194483047,53.786092989054985,297.0994792687118,0.10758234784322782
0.114100075039798,266.625135090618,0.3622677382513586,53.75162723426859,297.0470830119538,0.10804697143776577
0.114611090795494,266.494776592801,0.36389021327569343,53.725346961108684,297.0380336294034,0.10850554657525754
0.115124913917017,266.313244754696,0.365521601686529,53.68875014254671,296.9725341320418,0.10896642905599264
0.115626452264597,266.143721910909,0.3671139859400955,53.654574337239254,296.9169762679629,0.1094160877347985
0.116130577115584,266.040464775918,0.3687145823419792,53.633757698825065,296.93589748644354,0.10986786169847344
0.11663267175683,265.931628268208,0.3703087328279352,53.61181625887073,296.9479445777732,0.11031761350262287
0.117157390330609,265.903365884601,0.37197471429968354,53.60611856233556,297.0559103117659,0.110787414664635
0.117680463638329,265.800762389314,0.37363547205169456,53.5854336976857,297.0803193427098,0.11125552318207646
0.118217075449472,265.657875430703,0.3753392145520736,53.556627686829714,297.06317253424083,0.11173551997268494
0.118752380476357,265.495855942354,0.37703880801243345,53.52396455797857,297.02412084211653,0.11221411840476
0.119293607573093,265.33046831367,0.37875720404457025,53.490622412035876,296.98269707786596,0.11269777880331897
0.119830703599109,265.13671128866,0.380462483927171,53.45156099579386,296.908229952334,0.1131775163807613
0.120367966364765,264.912083680297,0.38216829320812884,53.40627606994787,296.7990124583468,0.11365717274620792
0.120895439297821,264.732734822585,0.38384301977058166,53.37011934023313,296.7377150954749,0.11412786525067825
0.121436584245924,264.562847819179,0.3855611549808087,53.33587012034649,296.6904563767143,0.11461052790092514
0.121982504698902,264.419212024626,0.38729445241901383,53.306913144164604,296.6737297978999,0.11509721401895275
0.122541638765377,264.234521800609,0.389069703080072,53.26967959500277,296.6142531204414,0.11559543461476945
0.123072257688632,264.002593251408,0.3907544181614066,53.222922799483854,296.49398843851236,0.1160680171312638
0.123614912999883,263.746471143107,0.39247734877462853,53.17128858245037,296.3494682274883,0.11655108867667821
0.124145852956738,263.521063014179,0.3941630831376431,53.125846303658484,296.2361101541406,0.11702350547011191
0.124688197747357,263.319591439819,0.39588502784785845,53.08522963426752,296.15243672802046,0.11750583968322445
0.125235867162421,263.124870003206,0.3976238782406866,53.045973792646336,296.0775412700568,0.11799267338078985
0.12577913766096,262.89606595651,0.39934876207354797,52.999846896832416,295.9629064269787,0.11847536275240488
0.126333819313586,262.682596081193,0.40110987632063555,52.95681136996852,295.8682917113382,0.11896795053502392
0.126899973464591,262.473879231592,0.40290741575007644,52.91473405308894,295.7818075412293,0.11947047642890482
0.127471015152362,262.252278714895,0.40472047310874937,52.87005938892284,295.68184290870283,0.11997708488232045
0.128034601132101,262.008865968714,0.4065098585944206,52.820987379292745,295.5550666160924,0.1204768273679071
0.128608464861022,261.701590135168,0.40833187593374487,52.75904057124986,295.3586298941403,0.12098542684466017
0.129175453689373,261.386725604925,0.41013206546375924,52.695563881952886,295.15147447332083,0.12148767937255842
0.129759988029326,261.043540320501,0.41198796199311005,52.626377728613,294.9165469876221,0.12200521019013244
0.130330265697795,260.716784138194,0.4137985935904991,52.560503682259906,294.6960718867995,0.1225098605505605
0.130917776157107,260.39681243578,0.41566393929881473,52.49599738705325,294.4873840382716,0.12302949436485894
0.131492001646803,260.074509327201,0.4174871052285995,52.43102108036372,294.2722271359448,0.12353711726117092
0.132081757900253,259.752191459883,0.41935958133330326,52.366041798312416,294.0607175263475,0.1240582014664523
0.132666999970334,259.313113081637,0.4212177249058104,52.277523597258025,293.7154058471458,0.12457502884615532
0.133253217919591,258.873200035812,0.42307896689470137,52.1888371272197,293.3688869737259,0.12509245038439618
0.133844393924602,258.397375356144,0.4249559507106114,52.09291087179863,292.982415452395,0.125613977128831
0.134435366973053,258.007644901063,0.42683229013944324,52.0143412120543,292.6929973251905,0.12613505311955328
0.135041577871925,257.584836901263,0.42875700974336184,51.929103119294616,292.36949971229194,0.12666928274869035
0.135636432810689,257.096493315226,0.4306456741739375,51.83065305234956,291.96814455664037,0.12719322753484993
0.136240183121628,256.577158355129,0.4325625814111689,51.725955124394005,291.5332773942587,0.12772472675528992
0.13684398167036,256.039508290615,0.43447964180339294,51.617564871387984,291.0769740700239,0.1282559860656889
0.13745515109667,255.52508265966,0.4364201047319272,51.513856664187465,290.6483215056326,0.12879344345835678
0.138053264898461,254.897088644728,0.4383191160526137,51.38725307077717,290.0864639452451,0.1293191403192087
0.138654847326581,254.304586137869,0.4402291402618947,51.26780456539439,289.5651497032646,0.12984760722183047
0.139264768015451,253.72445833517,0.44216563844905693,51.15085080037027,289.0593361650634,0.1303831140055973
0.139885168512146,253.103674462404,0.4441354100260635,51.02570077162065,288.50912461562075,0.1309275279575494
0.140517777760318,252.420459606127,0.4461439443890097,50.88796465659521,287.89002165121804,0.13148235031070749
0.141128465432446,251.536732414415,0.44808287774801603,50.70980525474607,287.0357254599532,0.1320176547546219
0.141744043688008,250.74922087327,0.45003733870942536,50.55104292805123,286.29142939146476,0.13255695624256963
0.142365336602425,249.983313357408,0.45200994371269937,50.39663597285346,285.57227190852484,0.1331009695329144
0.143005351414907,249.163792373964,0.4540419907423297,50.23142054259114,284.7955480622736,0.1336610667045193
0.14365688025722,248.267806096123,0.4561105948166735,50.0507897089784,283.93318458819647,0.13423091812456706
0.144285423624816,247.27951629333,0.45810622000879075,49.85155048473533,282.95834605545275,0.13478035801414984
0.144910044047865,246.240388915509,0.46008938985197134,49.642062405366616,281.9230945196188,0.13532606976954223
0.145531699777761,245.178806187858,0.4620631467943912,49.42804732747217,280.86009460185915,0.13586889583952325
0.146147739263482,244.05817604015,0.46401907216155536,49.20212828969424,279.7267267171868,0.13640652731630393
0.146774583544709,242.894647205921,0.466009302754451,48.96756087671367,278.54540789480905,0.13695329184522662
0.147397312257997,241.696285169804,0.46798646641914043,48.72597109023249,277.3216679865755,0.13749617071992773
0.148018073605322,240.266993037682,0.46995738369689727,48.437825796396694,275.830850498063,0.13803704133208905
0.148673027320798,238.941902346735,0.47203686174353365,48.170687513101775,274.4661183224146,0.13860738684609078
0.14933431847273,237.377473729356,0.4741364611509177,47.85529870383817,272.8260769895078,0.13918292127281595
0.149982098939124,235.734987518928,0.4761931641317187,47.524173483815886,271.09101574040506,0.13974637611411297
0.150621482728613,234.018479953673,0.47822320766334625,47.178125558660476,269.2666903901914,0.1403022161649985
0.15125360490609,231.886358300917,0.4802301955768357,46.74828983346487,266.96000592247594,0.14085143987984075
0.151931294731021,229.59400856698,0.4823818607709916,46.28615212710317,264.4765235510464,0.14143992050473136
0.152678539802559,226.723671332198,0.48475436387312476,45.70749214057111,261.3395104098733,0.14208839912052748
0.153286688302039,224.380707526641,0.48668523535897384,45.23515063737083,258.7752831022682,0.1426158559149036
0.153711017636183,222.735467665906,0.488032480994881,44.903470281446644,256.97236306450355,0.14298371873317783