File: example/data/02 processed data/test_ID_067.csv
Strain,Stress_MPa,Displacement(mm),Force(kN),True Stress (MPa),True Strain
4.31021241420472e-06,0.0345559955879448,1.3684924415099987e-05,0.006966488710529672,0.034556144531625976,4.310203125376892e-06
-1.73989398798588e-06,0.0375716223060733,-5.524163411855169e-06,0.0075744390569043776,0.03757155693543353,-1.739895501612645e-06
-5.49618483308665e-06,0.174234399890878,-1.7450386845050114e-05,0.03512565501800101,0.1742334422664119,-5.496199937110695e-06
-1.14377028750952e-05,0.351984526261713,-3.631470662842726e-05,0.07096008049436135,0.35198050036728495,-1.14377682861723e-05
-1.9396265207122e-05,0.530340312340583,-6.158314203261234e-05,0.10691660696786154,0.5303300257192348,-1.939645331706779e-05
-2.2063911737193e-05,0.649001694405181,-7.005291976558776e-05,0.1308387415920845,0.6489873748890783,-2.2064155148883335e-05
-2.29003240751412e-05,0.654740518953732,-7.270852893857332e-05,0.13199568862107236,0.6547255251836628,-2.290058629157258e-05
-2.21719025319459e-05,0.658981651690397,-7.039579053892823e-05,0.13285070098078403,0.6589670408134454,-2.2172148332217525e-05
-2.62222561798642e-05,0.660652580734841,-8.325566337106884e-05,0.13318756027614395,0.6606352569336231,-2.622259998924518e-05
-1.147129190298e-05,0.684596793864476,-3.64213517919615e-05,0.13801471364307838,0.6845889406548178,-1.1471357698703528e-05
9.78798284085635e-06,1.23560890446108,3.107684551971891e-05,0.24909875513935376,1.235620998579835,9.787934938911627e-06
4.25922580324895e-05,3.13819563935793,0.00013523041925315416,0.6326602408945587,3.138329302196358,4.2591351008024796e-05
9.07348651142105e-05,6.58945606227781,0.0002880831967376183,1.3284343421552067,6.590053955684796,9.073074895534977e-05
0.0001307326308841,11.4445303480643,0.00041507610305701746,2.3072173181697626,11.446026521625935,0.00013072408611846775
0.0001921416630477,16.8456890690394,0.0006100497801764474,3.3960909163183426,16.848925827752307,0.00019212320620254892
0.0002456874197771,22.3464172424731,0.0007800575577922924,4.505037716082576,22.351907476066664,0.0002456572435655427
0.0003079522745248,27.8772143438993,0.0009777484716162398,5.620046411730099,27.88579919546392,0.0003079048669557511
0.0003767237616661,33.578227258971,0.0011960979432898676,6.769370615408554,33.59087697505407,0.00037665281908639593
0.000444367307352,39.3458904971219,0.0014108662008426,7.932131524219775,39.36337452453747,0.00044426860543890967
0.0005242670636995,45.166455595603,0.0016645479272459124,9.105557448073565,45.19013488065582,0.000524129683736291
0.0006002467041641,50.9994902245615,0.0019057832857210175,10.281497229271597,51.03010250048284,0.0006000666281676247
0.0006875076840277,56.8574185499571,0.0021828368967879474,11.462455579671353,56.89650846210419,0.0006872714588848783
0.0007834577679747,62.8521211497185,0.0024874784133196723,12.67098762378325,62.90136313226693,0.000783151025140431
0.0008828027827127,68.9279641781177,0.0028028988351128225,13.89587757830853,68.98881397670088,0.0008824133415192093
0.0009884938279598,75.1631293978154,0.0031384679037723645,15.152886886599584,75.23742768731529,0.0009880055896564323
0.001093417780486,81.4951298597403,0.0034716014530430496,16.429418179723648,81.58423808375196,0.0010928204346573672
0.0011978517375331,87.8347776591011,0.003803179266667592,17.707491176074786,87.9399907001359,0.0011971348855383385
0.0013036379470736,94.1827452479552,0.00413905048195868,18.987241441987766,94.30552544862,0.0013027889489025267
0.0014118608286466,100.48244773515,0.004482658130952955,20.25726146340624,100.6243149670738,0.0014108650902660614
0.0015181072929561,106.835795792529,0.004819990655135617,21.538096431773848,106.99798399327041,0.0015169561329886993
0.0016274847605133,113.149356122243,0.005167264114629727,22.81091019424419,113.33350497499386,0.0016261618423487488
0.0017394330711548,119.509108103231,0.00552270000091649,24.09303619361137,119.71698619816998,0.0017379220094570589
0.0018435414210244,125.844052635593,0.005853244011752469,25.37016101133555,126.07605135921631,0.001841844184169796
0.0019552420380448,132.159754344127,0.00620789347079224,26.643406475776004,132.41815865155834,0.00195333304029461
0.0020651590066685,138.487665025126,0.006556879846172487,27.919113269065402,138.77366407386512,0.0020630294971535667
0.0021722523146822,144.791759050131,0.006896901099115984,29.190018624506408,145.10628328387452,0.0021698963857872187
0.0022875612645368,150.965889474483,0.00726300701490434,30.434723318055774,151.31123319551116,0.002284948779654844
0.0023902731378415,157.051887243739,0.0075891172126467624,31.661660468337782,157.42728415106504,0.002387420979059685
0.0024947079294754,163.051852127593,0.007920697676084394,32.87125338892275,163.45861887601137,0.0024916013113127325
0.0026003178429961,168.979534434934,0.008256009151512617,34.0662741420827,169.41893493342633,0.0025969428659630652
0.0027023196500928,174.876553278744,0.00857986488904464,35.255113140994794,175.34912562500966,0.002698674948968979
0.0028123591001547,180.656817975281,0.008929240142991172,36.42041450381665,181.16488982131878,0.002808411817353245
0.002921774578129,186.376346935153,0.009276634285559575,37.573471542126846,186.92089660759268,0.002917514490778901
0.0030280954502827,191.93280380166,0.009614203054647573,38.693653246414655,192.51399465161177,0.003023520003520585
0.003134446289408,197.525626995991,0.009951866968870399,39.82116640239178,198.14476046459157,0.003129544153620476
0.0032400947693645,202.978882234814,0.010287300892732287,40.9205426585385,203.63655304943447,0.003234856973228239
0.0033499709076442,208.387168392179,0.010636157631770334,42.010853147863294,209.08525934381913,0.0033443722551673677
0.0034556352004072,213.579703757721,0.01097164176129286,43.05766827755656,214.31775730011873,0.0034496782125945143
0.003567962557175,218.346672622901,0.011328281119030625,44.01868920077685,219.12572537530323,0.0035616124788488707
0.0036777790267724,222.823187737303,0.01167694841000237,44.92115464784029,223.6426821838418,0.0036710325338345754
0.0037956230077396,226.93727874275,0.01205110304957323,45.75055539453841,227.7986470992598,0.003788437806535265
0.0039245059891734,230.764191836328,0.012460306515625545,46.52206107420372,231.66982728927644,0.003916825204509207
0.0040682728359121,234.379718110044,0.012916766254020919,47.25095117098487,235.3332387505198,0.004060019790167365
0.0042388122733316,237.669561731691,0.01345822896782783,47.914183645108906,238.67699838695665,0.0042298538151469296
0.0044383106234325,240.68947348489,0.014091636229398187,48.52299785455382,241.75772813200635,0.004428490369008865
0.0046874736660106,243.245961282141,0.014882728889583655,49.03838579447963,244.38617032001446,0.004676521672776673
0.0049765611291375,245.260288556672,0.01580058158501156,49.44447417302507,246.48084137522417,0.004964218979506242
0.0053154929807078,246.760644535973,0.016876690213747266,49.74694593845216,248.07229900991888,0.005301415611297938
0.0056850292221943,247.814930609749,0.0180499677804669,49.9594900109254,249.22376573196152,0.005668930429485217
0.006071735425819,248.498957909288,0.019277759976975322,50.09738991451246,250.00777783530495,0.006053376715619859
0.0064790646888708,249.01442094766,0.02057103038716479,50.20130726304826,250.6278014894416,0.0064581657709723295
0.0068920606026891,249.410680943732,0.021882292413537893,50.28119327825637,251.12963447175417,0.006868418917471692
0.0073077831298159,249.722134837203,0.02320221143716548,50.34398238318012,251.5470500413079,0.0072812106613727445
0.007723064473093,250.086857451889,0.02452072970207027,50.417510462300825,252.01829437586315,0.007693394275981647
0.0081387262043662,250.381985373259,0.025840455698862685,50.47700825124902,252.41977579871758,0.008105785382441695
0.0085580411782801,250.626210392201,0.027171780741039316,50.526244015067725,252.77107982109376,0.0085216287424732
0.0089771857578053,250.912888773666,0.028502564781031824,50.58403837677107,253.16538038521475,0.008937130370359885
0.0093839373527964,251.125199862053,0.02979400109512857,50.62684029218988,253.481743005267,0.009340181733012558
0.0097885499816993,251.355953433717,0.03107864619189528,50.67336021223735,253.81636374710058,0.009740952481283363
0.0101780788560472,251.611075641051,0.03231540036794986,50.72479284923588,254.1719930099805,0.01012663101043873
0.0105704600818401,251.796643707004,0.033561210759842315,50.762203371332006,254.4582500780502,0.010514983369144991
0.010960620609535,252.054165042516,0.03479997043527362,50.81411967257122,254.81683511860012,0.010900988349494694
0.0113456681150222,252.268081340567,0.036022496265195485,50.857245198258305,255.13023126747046,0.011281788737929394
0.0117291257640527,252.486906079471,0.03723997430086732,50.90136026562135,255.44835675465364,0.01166087274884456
0.0121038195847993,252.670327906683,0.03842962718173777,50.9383381059873,255.7286039700976,0.012031154125960179
0.0124837660545256,252.832461151762,0.03963595722311878,50.97102416819522,255.98876244777054,0.012406486343624339
0.0128581072105858,253.032985828308,0.040824490393609913,51.01144994298689,256.286511087903,0.012776143600272452
0.0132391053012978,253.240500064668,0.04203415933162051,51.053284813037074,256.5931777115775,0.013152234236842262
0.0136026744300162,253.415433078137,0.04318849131530143,51.088551308552425,256.86256070984047,0.013510988567104669
0.013972777930107,253.563761529569,0.04436356992808972,51.11845432436111,257.1067516605443,0.013876058585851064
0.0143385550142411,253.776650254227,0.045524912170215495,51.16137269125216,257.4154407152271,0.014236730127895128
0.0146971836166066,253.949601650873,0.04666355798272595,51.196239692816,257.68194557569996,0.014590226716715058
0.0150818388187744,254.094404009047,0.047884838249608715,51.22543184822387,257.926614855064,0.014969238621479862
0.0154537044792628,254.34521122232,0.049065511721659384,51.275994582419706,258.27578695226543,0.015335512106199932
0.0158305735428978,254.561753581592,0.05026207099870051,51.31964952204895,258.59161214287445,0.015706576926655464
0.0161937221332395,254.747795505577,0.05141506777303541,51.357155573924324,258.87311052004964,0.016064002371794617
0.0165421404351282,254.942865883831,0.05252129588153204,51.39648176218033,259.1601665742154,0.01640680963142603
0.0168854121450892,255.166108448298,0.05361118356065821,51.44148746317688,259.47469335490604,0.01674443829470077
0.0172250092686563,255.315439305679,0.05468940442798376,51.47159256402489,259.7132501141504,0.017078340646458315
0.017560880612946,255.588773465643,0.05575579594610355,51.52669673067363,260.07713740248244,0.017408470070895743
0.0179112948653547,255.769783020801,0.05686836119750117,51.563188256993485,260.3509510221343,0.017752777657206092
0.0182626044092276,255.894944909506,0.05798376899929763,51.588420893756414,260.5682530587094,0.018097845971345724
0.0186171736356583,256.116435598849,0.0591095262932151,51.63307341672797,260.8845997513387,0.01844599536517256
0.0189707732085582,256.247679346754,0.060232204937172275,51.659532156305616,261.10889595686064,0.018793071992708646
0.0193250396356968,256.384166917365,0.06135700084333733,51.68704805054079,261.3388011050082,0.01914068241164136
0.0196758331161978,256.619741451311,0.06247077014392802,51.73453987658429,261.66894865842875,0.019484766113271625
0.0200253257917696,256.791046186959,0.06358040938886848,51.769074911290936,261.9333705472622,0.019827456195557217
0.0203844113590018,257.02077641399,0.06472050606483071,51.81538852506039,262.2599936482228,0.020179430178430623
0.0207364677372681,257.221948832738,0.06583828506582622,51.855944884679985,262.5558234760253,0.020524393953347774
0.0210907205103169,257.386009825259,0.06696303762025616,51.88901958077222,262.81446622174917,0.020871389799658586
0.0214448152555267,257.575799442256,0.06808728843629727,51.92728116755882,263.0994648755898,0.021218110571519625
0.021797962694574,257.772064366889,0.06920853155527244,51.96684817636483,263.39097020966176,0.021563784072852647
0.0221507693913026,257.994093734243,0.07032869281738574,52.011609296823394,263.7088614088683,0.021909004767182386
0.0224990724798554,258.119032461077,0.0714345551235409,52.036796944153124,263.92647128084894,0.02224970182424256
0.022845006568775,258.336133348296,0.07253289585586062,52.08056448301648,264.2378240115898,0.022587966760457174
0.0231949730805369,258.490373577488,0.07364403953070466,52.11165931322158,264.4860508341958,0.02293005833115544
0.0235365145422729,258.658958035727,0.07472843367171646,52.14564594000256,264.74688836302397,0.02326380163551307
0.0238755024839001,258.879009904568,0.07580472038638282,52.190008396760916,265.05987634857416,0.023594939620350423
0.0242104263565964,259.078653799411,0.07686810368219356,52.23025660596125,265.3510584677877,0.023921999995079248
0.0245396847439921,259.303301070261,0.07791349906217492,52.27554549576462,265.66652233160164,0.0242434236654883
0.0248781138260675,259.428469365226,0.0789880113977643,52.30077942402957,265.88256035581657,0.024573692179197658
0.0252199619508944,259.569998566915,0.08007337919408972,52.32931171109006,266.11634405436627,0.02490718659298635
0.0255672307699067,259.737127573626,0.08117595769445377,52.36300491884301,266.3778866538136,0.02524585539642348
0.0259146725438868,259.962099449299,0.08227908532684058,52.40835924897868,266.6989321303489,0.02558457812826026
0.0262629904994123,260.131906934945,0.08338499483563405,52.442592438084915,266.96374873537144,0.025924039925494507
0.0266134056504279,260.341366922545,0.08449756294010857,52.48481957158507,267.2699373280416,0.026265429358463925
0.0269588094039992,260.454641619173,0.08559421985769745,52.50765575042527,267.4761886609712,0.0266018224536727
0.0273032555046117,260.668521767621,0.08668783622714214,52.55077398835238,267.7856210194518,0.026937170226212982
0.0276468002992469,260.831142835114,0.08777859095010891,52.58355839555899,268.04228935290075,0.02727152852058169
0.0279881825985333,260.957767212765,0.08886247975034323,52.60908587009343,268.2615008520214,0.027603671440180718
0.0283316255950329,261.134136553659,0.08995291126422945,52.64464192921766,268.5324911405795,0.027937708002319227
0.0286760751568068,261.370696247148,0.09104653862286158,52.69233236342503,268.86578197651806,0.028272611527344706
0.0290178780231051,261.538429966829,0.0921317627233587,52.726147481312736,269.1277202259609,0.028604830873097252
0.029359302576556,261.749821315254,0.0932157856805653,52.7687639771552,269.434613518608,0.02893657236323806
0.0296994679505068,261.841118678024,0.09429581074285907,52.78716952548964,269.61766059032675,0.029266980977032352
0.0300353843815791,261.933587281644,0.09536234541151364,52.80581119597943,269.80086325809407,0.029593155419990556
0.0303666547414619,262.134247483702,0.09641412880414152,52.846264292714324,270.09438767295245,0.029914714374453862
0.0306998448152141,262.287238208388,0.09747200728830477,52.87710722281102,270.33941571839654,0.030238032498081963
0.0310324473744792,262.464330273116,0.09852802041397145,52.91280898306019,270.6092407899944,0.03056067628982003
0.031364585333374,262.652154083811,0.09958255843346245,52.95067426329631,270.8901299835672,0.030882765544700347
0.0317074927739625,262.79997719818,0.10067128955733094,52.980475403153086,271.13270557618876,0.031215189648913778
0.0320460147431773,263.046625297765,0.10174609680958793,53.030199660029425,271.47622133020025,0.03154325399479424
0.0323873914238429,263.22187176033,0.1028299677707012,53.06552934688252,271.74694155234835,0.03187397590886253
0.0327305349600919,263.381188350097,0.10391944849829178,53.09764757137955,272.0017955432204,0.03220629934184727
0.0330747278341456,263.588148129483,0.10501226087341227,53.13937066290378,272.3062543891721,0.03253952811557317
0.0334176128897261,263.777377782647,0.10610092092488035,53.17751936098164,272.5921880824546,0.03287138035810996
0.033761996272235,263.960734663648,0.10719433816434612,53.214484108191435,272.8725760033785,0.03320457190486153
0.0341113925111357,264.098582049495,0.10830367122285585,53.2422741411782,273.1073524434197,0.033542499985101525
0.0344531769847734,264.268921948904,0.10938883692665553,53.27661466489904,273.37382588838483,0.03387295568543415
0.0347960129031717,264.390925378405,0.11047734096757014,53.30121055628644,273.59067542935344,0.034204318310303794
0.0351359209763509,264.515719191245,0.1115565490999141,53.32636898895499,273.8097225977512,0.0345327427098418
0.0354801508490471,264.669910426758,0.11264947894572454,53.35745394203442,274.0604387739032,0.0348652330063786
0.0358256835380109,264.853013140226,0.11374654523318459,53.39436744906956,274.34155337307635,0.03519887054694114
0.0361674192421733,265.027489321164,0.11483155609390022,53.429541847146666,274.61284963814313,0.03552873236627106
0.0365096299754374,265.20944332614,0.11591807517201373,53.466223774549825,274.8921419679691,0.0358589437096185
0.0368482402769727,265.441979573462,0.11699316287938831,53.51310308200994,275.2230494163802,0.036185573578396996
0.0371997728008278,265.525501915429,0.11810927864262825,53.529941186150495,275.4029902595087,0.0365245556318544
0.0375475322396799,265.628721057762,0.11921341486098368,53.55075016524482,275.6024240254632,0.036859786280197954
0.0378935644375549,265.714299935066,0.1203120670892368,53.5680028669093,275.7831618816352,0.03719324040870616
0.038222384549579,265.885333114764,0.12135607094491331,53.602483155936426,276.04810456316943,0.0375100051009037
0.0385525324814597,266.02558355775,0.12240429062863453,53.630757645242404,276.28154350875946,0.037827948015135185
0.0388877323938347,266.188510421542,0.12346855035042517,53.66360370098287,276.5399779811284,0.03815065275996126
0.0392310603587791,266.362425549899,0.12455861663912364,53.69866499085964,276.8121059439579,0.038481074648512886
0.0395782112685259,266.473392194524,0.1256608207775697,53.721035866416045,277.01993240823964,0.03881506480115646
0.0399212564913738,266.691203450647,0.1267499893601118,53.76494661565044,277.3378513875934,0.03914499537462206
0.0402642681810607,266.823472294649,0.1278390514748677,53.791612014601235,277.5669241401226,0.03947478489457351
0.0406077271196902,266.982937380235,0.12892953360501638,53.82376017585538,277.82450764698496,0.039804895485252935
0.0409577161488835,267.105136421538,0.1300407487727051,53.848395502582065,278.0451527810002,0.04014117031497115
0.0413074956321203,267.229272156956,0.13115129863198194,53.87342126684233,278.2678441493541,0.04047713086845661
0.0416568188167364,267.382197777641,0.13226039974313805,53.90425107197243,278.520489545285,0.04081254053963327
0.042005893620453,267.537356484479,0.13336871224493826,53.93553106727097,278.77550222046324,0.04114759938087359
0.0423525597314748,267.660801117105,0.13446937714743248,53.96041750520837,278.9969211841916,0.041480235174549886
0.0426999029905485,267.818084287715,0.1355721919949915,53.99212579240335,279.253890505915,0.041813409776625204
0.0430480300422286,267.92921416571,0.13667749538407578,54.01452957580714,279.4630390263062,0.04214722485504325
0.0433957692548286,268.089441248967,0.13778156738408082,54.046831355791745,279.7233887810631,0.04248055682970447
0.0437445784789226,268.251314709202,0.13888903667057925,54.07946504537513,279.98585539757283,0.04281480289774694
0.0440895637837146,268.272038025771,0.13998436501329384,54.08364286599544,280.10003515769534,0.04314527484563637
0.0444391611452281,268.379725849263,0.14109433663609922,54.105352731211426,280.3062957343906,0.043480053448971656
0.0447870898130752,268.513522428223,0.14219901015651376,54.13232612152975,280.53946167324096,0.0438131228529233
0.0451343730350395,268.67412572929,0.1433016343862504,54.16470374702486,280.80056394481886,0.0441454637866229
0.0454740730342461,268.873886988058,0.14438018188373136,54.2049756167925,281.10067776195456,0.044470440950887986
0.0458043589256505,268.966393618979,0.14542883958894032,54.22362495358617,281.2862268512405,0.04478631079308887
0.0461408458426895,269.045981729035,0.14649718555053917,54.23966991657346,281.4599908965895,0.045108008435239294
0.0464772765555169,269.222101162717,0.14756535306376614,54.275175594403755,281.73481121331395,0.04542954891328917
0.0468296479836566,269.329604640587,0.1486841323481097,54.29684829554233,281.94221521748307,0.04576621376385381
0.0471853517935599,269.522000105952,0.14981349194455268,54.335635221359915,282.2394904970552,0.04610594754165621
0.0475399176826342,269.685543706284,0.15093923864236358,54.36860561118686,282.5063722542772,0.046444479661001015
0.0478906743706412,269.763146601915,0.1520528911267858,54.38425035494607,282.68228561302686,0.046779262108688144
0.048235685981659,269.876381077968,0.15314830299176732,54.40707842531835,282.89405344951143,0.04710845181848751
0.0485870773456413,269.995673965681,0.15426397057241112,54.431127871481294,283.1139746596401,0.04744361735886367
0.0489392538280167,270.136635708531,0.155382130903953,54.45954575883985,283.35692109171725,0.0477794190891691
0.049297907072287,270.265770030016,0.1565208549545112,54.48557923805122,283.5893068457758,0.048121280585521
0.0496583397978176,270.425058896145,0.15766522885807088,54.51769187346284,283.85391836065463,0.04846472054965642
0.0500210154041566,270.548849861225,0.1588167239081972,54.54264813202296,284.0819780477102,0.0488101786397666
0.0503847214256915,270.716200941059,0.1599714905265705,54.5763861097175,284.35616131089574,0.04915649841864778
0.0507499744834763,270.79690942059,0.16113116898503724,54.592656939190945,284.5398456638892,0.049504170618983365
0.0511054706590597,270.885478995166,0.16225986934251455,54.61051256542547,284.7292088939188,0.04984243953257091
0.0514647902670435,271.017000531712,0.1634007090978631,54.63702730719313,284.9648336228798,0.050184230357029354
0.0518192065225595,271.047410348416,0.1645259807091264,54.64315792624067,285.0928720826655,0.050521242628706844
0.0521735197658872,271.17704670916,0.16565092525669187,54.66929261656666,285.32530771569526,0.0508580434571983
0.0525307646591483,271.346643403642,0.16678517779279584,54.703483310174235,285.6006900693286,0.05119751622715995
0.0528964582036813,271.428844257475,0.16794625479668812,54.720055002306964,285.78646877301406,0.05154489802619748
0.0532607153201919,271.581416808089,0.16910277114160926,54.75081362851074,286.04603733495895,0.05189079540244401
0.0536268961982491,271.68757893211,0.17026539542944089,54.77221591271337,286.25734052585585,0.05223839902376908
0.053990786278424,271.717321251352,0.17142074643399619,54.77821196427257,286.38755307117964,0.052583708409637386
0.0543498940416188,271.782641013393,0.17256091358213968,54.79138042830003,286.5539987548222,0.0529243628114801
0.0547094446944203,271.831661548675,0.17370248690478446,54.80126296821289,286.70342080236463,0.053265321123729656
0.0550762414787997,272.028567178093,0.17486706669518903,54.84095914310355,287.01087823312554,0.05361303112145962
0.0554339102177113,272.182696449619,0.17600266494123337,54.8720316042432,287.27084760742173,0.053951971677654635
0.0557986304221833,272.35092125796,0.17716065159043196,54.905945725604745,287.54772965837407,0.0542974762121667
0.056157639247112,272.477282253164,0.17830050460958058,54.931420102237865,287.7789631729707,0.054637453733048576
0.0565232042663601,272.576999570283,0.1794611735456933,54.951523113369056,287.9839249953057,0.05498352117055958
0.0568946706636668,272.660712032973,0.1806405793571421,54.968399545847355,288.1736534470099,0.05533505259795823
0.0572679429741597,272.723620453919,0.18182571894295704,54.98108188351007,288.3419411977804,0.0556881685900428
0.0576436873949732,272.756629412934,0.1830187074790399,54.987736489647496,288.47932729371973,0.05604349731335358
0.0580192753990739,272.901997226019,0.18421119939205963,55.01704264076543,288.7355733600327,0.05639855198382924
0.0583954469525544,272.993295235726,0.18540554407436022,55.03544831952237,288.9348607260669,0.056754031988262385
0.0587724964843662,273.153117935724,0.18660267633786268,55.067668575841964,289.207008599295,0.05711021491363368
0.0591536127851228,273.178719776233,0.18781272059276488,55.07282990688857,289.33822798701186,0.057470110665617115
0.0595323348410999,273.250591373881,0.18901516312049216,55.08731922097441,289.5178370750794,0.05782761722333517
0.059913621663091,273.31886128126,0.19022574878031392,55.101082434302015,289.6943841294523,0.058187415806483206
0.0602922203623494,273.365649976928,0.19142779965045933,55.11051503534869,289.8474719848339,0.05854454971846293
0.0606696820050161,273.461505377123,0.1926262403659261,55.129839484028,290.052327948966,0.05890048411429562
0.0610528653697726,273.588526942826,0.193842847549028,55.155447031673724,290.29189044498077,0.05926168437527851
0.0614335348754783,273.705413018007,0.19505147322964358,55.17901126443021,290.5201040542559,0.059620385858353483
0.0618235203983366,273.769964533908,0.1962896772647187,55.192024850035864,290.69538752072197,0.0599877323614773
0.0622126091016376,273.870789407984,0.19752503389769938,55.212351144649574,290.90900577377977,0.06035409967722029
0.0625977501528354,273.949593587611,0.1987478567352524,55.228238067262374,291.09822180147904,0.060716617728526254
0.0629800033367568,273.999979113627,0.1999615105942028,55.2383957893072,291.25649871247447,0.06107628764642456
0.0633664811953638,274.07690045274,0.20118857779528004,55.25390313127238,291.44418921136213,0.061439801180718574
0.0637619873732776,274.156433304869,0.20244430991015636,55.26993695426159,291.6371923435568,0.061811669818006496
0.0641580982998735,274.288324337386,0.20370196210209834,55.29652618641701,291.8861416127316,0.06218396850895659
0.0645571159684315,274.313126484281,0.20496884319977,55.30152629923105,292.0219908023897,0.0625588591195528
0.0649525260533036,274.41795430765,0.2062242702192389,55.32265958842224,292.2420936343119,0.06293022169205643
0.0653454092852805,274.527902940931,0.2074716744807656,55.3448252328917,292.46704111883594,0.0632990745458419
0.0657350695939483,274.654138114686,0.20870884596078584,55.370274243920704,292.7085469979208,0.06366476727014025
0.0661265837859119,274.756516222523,0.20995190352027024,55.390913670460634,292.9252260132369,0.06403206520970825
0.0665207374112908,274.808077817753,0.21120334128084828,55.401308488059,293.0885138007693,0.06440170310149566
0.0669161700270604,274.885155983976,0.2124588398359168,55.416847446369566,293.27941781971475,0.06477240318540177
0.0673272426043225,274.94808772623,0.21376399526872394,55.429534485607974,293.4595843321685,0.06515761939824098
0.0677294245694171,275.027655008056,0.21504092300789926,55.44557524962409,293.6551198224278,0.06553436065858785
0.0681470352418874,275.114465859439,0.21636683689299246,55.4630763172629,293.8627010599152,0.06592540450934384
0.0685759562833446,275.175798009339,0.21772866119961912,55.47544087868275,294.0462415038619,0.06632688008565356
0.0689938580235247,275.245578610395,0.21905549922469092,55.48950864785564,294.2358329826435,0.0667178864918139
0.069415442845037,275.289173786003,0.2203940310329925,55.49829743525821,294.39849369480277,0.06711218409125204
0.0698335427058691,275.36794511383,0.22172149809113437,55.51417773494813,294.59786426876406,0.06750306880731785
0.0702558629894492,275.453666112252,0.22306236499150123,55.53145908823001,294.80590113857585,0.06789774417736374
0.0706880661003931,275.521074046451,0.22443460986874808,55.54504852776453,294.99712594069786,0.06830149423446948
0.0711199151585248,275.574126469644,0.22580573062831621,55.55574389628023,295.1729349640497,0.06870475079879525
0.0715512055372002,275.669369014924,0.2271750775806106,55.574944793408676,295.3938446976211,0.0691073234384639
0.0719842115697391,275.695419546019,0.2285498717339216,55.580196580477434,295.54113695542765,0.06951133452684892
0.0724163075629792,275.721429998548,0.22992177651245896,55.58544028770728,295.6881578750273,0.0699143338688401
0.0728597888406237,275.810616814591,0.23132982956898024,55.60342034982155,295.9061201157043,0.07032778301387599
0.0733036547331599,275.86309956989,0.23273910377778267,55.614000873289825,296.08487297438046,0.07074141963618802
0.07374916513257,275.949028535042,0.23415359929590973,55.63132415266447,296.30003900864506,0.0711564167910618
0.0741951295654373,276.013787875662,0.23556953637026343,55.64437963573346,296.4926666289439,0.07157166446799305
0.0746356186645489,276.066375024579,0.23696808925994275,55.65498120495512,296.6707597170178,0.07198164473809521
0.0750809798666874,276.108806959271,0.23838211107673246,55.66353548298904,296.83932673559514,0.07239598885100237
0.075527283008894,276.182043863233,0.23979912355323843,55.67830004282777,297.04132325206615,0.07281103714809832
0.0759841550850254,276.236763791435,0.24124969239495564,55.689331580353304,297.2263808915489,0.07323573587375623
0.0764432158926474,276.32536153146,0.24270721045915547,55.707192884742334,297.4485607996232,0.07366228760857634
0.0769156933262597,276.355208891257,0.24420732631087452,55.71321011247741,297.61126138745135,0.07410111593317338
0.0773845410083565,276.399021138057,0.24569591770153187,55.72204266143229,297.78803252398455,0.0745363827377039
0.0778514445203851,276.416147466488,0.2471783363522227,55.72549532924398,297.93554383551384,0.07496965642324717
0.0783216259084971,276.425332069374,0.2486711622594783,55.7273469451858,298.0754135193436,0.07540578226306312
0.0787899918235173,276.432067477434,0.2501582240396674,55.72870480345069,298.21214781373897,0.07584003510239726
0.0792650057849997,276.453131004221,0.25166639336737406,55.732951210450956,298.36619003255186,0.07628025925764834
0.0797408022713584,276.494648958272,0.25317704721156287,55.74132122998765,298.54255408994226,0.07672101443513397
0.0802250278190751,276.558874480801,0.25471446332556347,55.754269095329484,298.74581787963535,0.07716937852412364
0.0807141252186327,276.564711103361,0.2562673475691588,55.755445758437574,298.8873898264127,0.07762204967612898
0.0812093977447484,276.583725605596,0.25783983783957615,55.75927908208815,299.04492338802515,0.0780802273401575
0.0817037189033136,276.566981143844,0.25940930751802066,55.755903398598946,299.16353202915866,0.07853731566549707
0.0821902037984118,276.553960406859,0.2609538970599574,55.753278418022774,299.2839867739566,0.07898695406799963
0.0826767982725737,276.60343932101,0.26249883451542144,55.76325336711562,299.47212607525324,0.07943649159791812
0.0831695219008096,276.602923822296,0.2640632320350705,55.76314944257488,299.6078567529624,0.07989148568696923
0.0836736134025319,276.590347247334,0.2656637225530388,55.76061400506254,299.7336610337795,0.08035676303224956
0.0841729485306372,276.553597175135,0.2672491115847731,55.75320519050722,299.83192887612023,0.08081743690622593
0.0846759096697597,276.489610624998,0.26884601320148704,55.7403055019996,299.9016199189074,0.0812812416072654
0.0851649597055398,276.499413889457,0.2703987470650889,55.74228184011453,300.04747533195797,0.08173201203099857
0.0856686648815581,276.49500404805,0.27199801099894694,55.741392816086886,300.18196189126746,0.08219607816610269
0.0861723963429164,276.483514517394,0.27359735838875954,55.73907652670663,300.3087615126693,0.08265995324368967
0.0866812890103935,276.388668229207,0.27521309260799937,55.71995551500813,300.3463942591806,0.08312836276450729
0.0871942411461942,276.2852442286,0.2768417156391666,55.69910523648576,300.3757264390037,0.08360028688178536
0.0877060032711666,276.216767427461,0.2784665603859539,55.68530031337614,300.44263613500493,0.08407089433675353
0.0882347360689178,276.063764190057,0.28014528701881397,55.65445486071549,300.4221775615586,0.08455687522639652
0.0887543267693222,275.916752666639,0.28179498749259796,55.62481733759442,300.4055582939442,0.08503422324723896
0.0892879209981591,275.76993222646,0.28348914916915513,55.595218336854344,300.3928561487639,0.08552419927048566
0.0898128828568212,275.625364438347,0.2851559030704073,55.56607347077075,300.3800730070169,0.08600601440073477
0.0903426079877935,275.466386686028,0.28683778036124435,55.53402355590324,300.35273847221777,0.08649196610796063
0.0908584544211992,275.278850020897,0.28847559278730744,55.49621616421283,300.2902608686408,0.08696495913177028
0.0913680364956305,274.973053406295,0.2900935158736268,55.43456756670906,300.0968013852363,0.08743198864114028
0.0918839704724753,274.715686846629,0.2917316062501091,55.38268246828041,299.95765490517044,0.08790461753125664
0.092397408172665,274.43660666691,0.29336177094821136,55.326419904049054,299.7938378306336,0.08837473801542678
0.0929206109010015,274.076367281587,0.2950229396106797,55.25379564396794,299.5437107629193,0.08885357243107393
0.0934387800328862,273.722176572305,0.29666812660441366,55.18239079697669,299.2984428191674,0.08932757422943806
0.0939565318164267,273.307673460151,0.29831198851715474,55.098826969566446,298.98671457728324,0.08980096995302297
0.0944730952108959,272.869455576766,0.2999520772945945,55.01048224427602,298.6482776336151,0.09027305587041627
0.0949938033219519,272.385677973789,0.30160532554719727,54.912952679515854,298.26062949494764,0.09074870418574102
0.0954933641825321,271.87395606438,0.3031914312795394,54.80978954257901,297.83611476258164,0.09120482269367115
0.0959998816747191,271.264747083792,0.3047996243172331,54.686973012092466,297.3061307063586,0.09166708056479532
0.0965105787571577,270.736004486108,0.3064210875539757,54.58037850439938,296.86489296946274,0.09213293657861236
0.0970230211166624,270.054466459961,0.3080480920454031,54.44298043832814,296.25596666195486,0.09260016659401463
0.0975464753157799,269.343642915545,0.30971005912760113,54.29967841177387,295.6171659306685,0.0930772115997849
0.0980736713227213,268.658951274335,0.3113839064496401,54.16164457690593,295.0073209595211,0.09355743675884085
0.0986000084379742,267.838899627195,0.31305502679056807,53.99632216484252,294.24781739045414,0.0940366496070439
0.0991324354724338,266.950787932882,0.3147454826249773,53.817278847269016,293.4142696919538,0.09452117359571344
0.0996586664974088,265.992548342541,0.3164162661292729,53.62409774585627,292.5010110086062,0.0949998284661562
0.100171967384517,264.935812269212,0.3180459964458415,53.41105975347315,291.474953814834,0.09546650157136524
0.100700511124513,263.89119096794,0.31972412282032875,53.20046409913671,290.46516877966803,0.0959468054102455
0.101231033011563,262.850074915916,0.32140852981171253,52.99057510304867,289.45865952682095,0.09642867497492702
0.101756611821258,261.627916157133,0.32307724253249415,52.74418789727801,288.250286463139,0.09690582592118802
0.102281303026722,260.380871686069,0.3247431371098423,52.49278373191151,287.0129665253538,0.09738194406039155
0.102810095242509,259.100633594788,0.3264220523949661,52.23468773270926,285.7387944120626,0.09786155431721667
0.10333301328681,257.786567442755,0.3280823171856217,51.96977199645941,284.4244302414783,0.09833561064844212
0.103856131062875,256.404518071318,0.3297432161246281,51.69115084317771,283.0336993052461,0.09880962329679079
0.104342868620144,254.993569103485,0.3312886078689572,51.40670353126257,281.6003295834315,0.09925046904051389
0.104826262779071,253.514017181706,0.3328233843235504,51.10842586383194,280.08894416497344,0.09968809435382406
0.105293455749106,252.089996605511,0.3343067220034115,50.82134331567102,278.6334235078857,0.1001108705257004
0.105760961242721,250.52106037819,0.33579105194563913,50.5050457722431,277.01640853533314,0.10053375066559124
0.106233540809648,249.02194165892,0.3372914920706324,50.20282343843827,275.47642426064067,0.10096103886515824
0.106693671956094,247.340400693951,0.33875240846059845,49.863824779900526,273.7300562670803,0.10137689633251898
0.107175252235277,245.492967382702,0.3402814258470045,49.491382224352726,271.8037380839297,0.10181195396535035
0.107637384434595,243.645191794192,0.3417486955798391,49.1188706657091,269.87052296898406,0.10222926439456985
0.108092516317724,241.456870843626,0.34319373930877367,48.677705162075,267.5565515953172,0.10264008332098823
0.108529067828418,239.238371853541,0.3445797903552271,48.23045576567387,265.20268933959426,0.10303397239926901
0.10873459828148,238.077639138955,0.34523234954369897,47.996452050413325,263.9649155905324,0.10321936347998896
0.108837001042116,237.449158709922,0.34555747830871825,47.86975039592028,263.29241304388336,0.10331171924495279