File: example/data/02 processed data/test_ID_119.csv
Strain,Stress_MPa,Displacement(mm),Force(kN),True Stress (MPa),True Strain
6.55833953033422e-05,0.961504177334777,0.00020822728008811146,0.19383924215069104,0.961567236043325,6.558124480653562e-05
9.46036002756702e-05,2.33456128711275,0.00030036643087525284,0.47064755548193044,2.334782145015575,9.45991256371944e-05
0.0001523481209405,4.586151233234,0.0004837052839860875,0.9245680886199744,4.5868499247567325,0.00015233651714400108
0.0002074882519485,8.01740760833081,0.0006587751999364874,1.6163093738394916,8.019071126220622,0.0002074667292382354
0.0002986293894367,11.6990628875168,0.0009481483114615224,2.3585310781233866,11.70255657152388,0.00029858480855580213
0.0003639779382348,15.6292660146208,0.00115562995389549,3.1508600285475534,15.634954722640924,0.00036391171433383863
0.0004237242244805,19.6411209250033,0.0013453244127255874,3.959649978480665,19.64944334373517,0.0004236344787219823
0.0005122850913556,23.9368409495499,0.0016265051650540298,4.82566713542926,23.949103436302508,0.0005121539181450975
0.0005777558903166,28.346715081474,0.0018343749517552048,5.7146977604251585,28.36309256308345,0.0005775890536397025
0.0006921298622592,32.9479160511433,0.00219751231267296,6.642299875910489,32.970720287741514,0.0006918904508490115
0.0007639394881299,37.6024683809716,0.0024255078748124325,7.580657625603875,37.63119439141898,0.0007636478348865442
0.0008424395521869,42.181217330295,0.0026747455781934073,8.503733413787472,42.21675245613343,0.0008420848991558523
0.0009473680464425,46.8056474817799,0.0030078935474549375,9.436018532326827,46.84998965659719,0.0009469195765564313
0.0010246917311343,51.3496394646053,0.003253396246351402,10.352087316064429,51.40225701556141,0.0010241670929267272
0.0011351751806689,55.9648346265747,0.0036041811986237573,11.28251066071746,56.02836451783303,0.0011345313565129694
0.0012073758081887,60.5309728237923,0.0038334181909991227,12.203044121276529,60.60405645602587,0.0012066475161734789
0.0012923796958976,65.0558941976175,0.00410330553447488,13.11526827023969,65.13997111437698,0.0012915452920921509
0.0013810131136831,69.488049451364,0.004384716635943842,14.008790769394984,69.5840133589006,0.0013800603921194662
0.0014627537779852,73.899497313963,0.004644243245103009,14.898138658494942,74.0075940828502,0.0014616849957942222
0.0015548508112002,78.2568423267916,0.004936651325560635,15.776579413081185,78.37852004156538,0.0015536432822005851
0.0016180132391208,82.5599991747067,0.005137192034208539,16.644095833620874,82.69358234639319,0.0016167056659569367
0.0016967578903458,86.7101469501559,0.005387206301847915,17.48076562515143,86.85727307616662,0.0016953200229220039
0.0017705624879936,90.6920479141272,0.00562153589937968,18.283516859488042,90.85262385212327,0.0017689968899519879
0.0018456023944549,94.5256044627657,0.005859787602394307,19.056361859693567,94.70006114469948,0.0018439013629859054
0.0019417435633456,98.2802416321712,0.00616503581362228,19.813296713045712,98.4710766587645,0.0019398608161268697
0.002008235477581,101.99129639612,0.006376147641319675,20.561445353457795,102.19611893594717,0.0020062216683989316
0.0020904301184757,105.665208556845,0.006637115626160347,21.302106045059954,105.88609429128724,0.0020882482096583567
0.0021600863099018,109.301137443825,0.006858274033938214,22.035109308675118,109.5372373344741,0.002157756677669986
0.0022344512132052,112.921618435997,0.00709438260192651,22.764998276696996,113.17393628330841,0.002231958539574154
0.0023131437221246,116.571910972291,0.007344231317745604,23.500897252013864,116.84155855633263,0.002310472523636007
0.002390198242574,120.220575325802,0.0075888794201724495,24.236467985681685,120.50792633366697,0.00238734626238261
0.0024656118072405,123.872236722821,0.007828317487988587,24.972642923320713,124.17765757227409,0.0024625771735774194
0.0025448057505957,127.378631045551,0.008079758258141346,25.679532018783085,127.70278491833872,0.002541573215396232
0.0026225934414246,130.804446974788,0.008326734176523104,26.370176510117258,131.14749385953323,0.0026191604441724997
0.002706284614103,134.213890790758,0.008592453649777024,27.057520383416815,134.57711177840395,0.002702629219437154
0.0027643823396249,137.606977640962,0.008776913928309057,27.741566692417937,137.98737593976182,0.0027605684618258654
0.0028442891665304,141.092099618096,0.00903061810373402,28.444167283008156,141.49340634852277,0.0028402518298557607
0.0029163750872528,144.465013342133,0.00925949090202764,29.124146689774015,144.88632750802364,0.0029121307155454868
0.0030134730531324,147.766451894712,0.00956777694369537,29.78971670197394,148.2117421156537,0.003008941644447608
0.0030865645971798,150.981699368229,0.009799842596045865,30.437910592634964,151.447714136321,0.0030818109358169417
0.0031671047871076,154.115390030143,0.010055557699066629,31.069662630076834,154.60348961967443,0.0031621000749224083
0.0032532955340388,157.240510520046,0.01032921332057319,31.699686920841273,157.75206037069083,0.0032480150177433553
0.0033378151165282,160.253044511131,0.010597562994977034,32.30701377344401,160.78793954556994,0.0033322569762478287
0.003435838209701,163.181736879441,0.010908786315800674,32.897438154895305,163.74240292613675,0.003429949202860777
0.0035251609386585,166.034436981065,0.011192385980240737,33.472542495382704,166.61973509278278,0.0035189621224483753
0.003617753332993,168.749720753009,0.011486366832252775,34.01994370380662,169.36021561770485,0.003611225003922324
0.0037202324367944,171.385804412037,0.01181173798682222,34.55137816946666,172.02339944081677,0.003713329487190075
0.0038350933450948,173.838416711524,0.01217642137067599,35.04582480904324,174.50510326657619,0.0038277581228053554
0.0039588867136925,176.075227014826,0.012569465315973687,35.49676576618892,176.7722888916654,0.003951070942730281
0.0041002722833757,178.022502999283,0.013018364499717846,35.889336604655455,178.75244373414813,0.004091889074788969
0.0042694485821015,179.696626671371,0.013555499248172263,36.226839936948394,180.4638321793215,0.004260360345161598
0.0044475589811036,181.043240056382,0.01412099976500393,36.49831719536661,181.84844054466282,0.004437697818581804
0.0046829955502574,182.121042639472,0.014868510872067245,36.71560219611756,182.9739146717609,0.004672064440203868
0.0049170227240949,182.960123574276,0.015611547149001308,36.884760912574045,183.85974265949392,0.004904973648770022
0.005165738846189,183.529107463428,0.016401220836650077,36.99946806462709,184.47717090325824,0.0051524421889898205
0.0054443719352267,183.937346482947,0.017285880894344772,37.081769050962116,184.9387698099788,0.005429604916191114
0.0057293555354675,184.292125222308,0.018190703825109313,37.15329244481729,185.3480003300935,0.00571300519957367
0.0060222356406512,184.559177352035,0.01912059815906756,37.20713015417026,185.6706362076937,0.00600417445579535
0.0063506418018756,184.785019364294,0.02016328772095503,37.25265990384167,185.95852283262926,0.0063305614468156845
0.0066682367584516,184.885774307921,0.02117165170808383,37.27297210047687,186.11863642427588,0.006646102411278379
0.0070266912099511,184.934600888651,0.02230974459159474,37.28281553915205,186.2340792231311,0.007002119055415387
0.007370047344086,184.977519738896,0.02339990031747305,37.291467979361435,186.34081281696328,0.007343021252970334
0.0077324981475738,185.015511501553,0.024550681618546816,37.29912711871308,186.44614360151115,0.00770275560813476
0.0080785340039637,185.102506218655,0.025649345462584745,37.31666525368085,186.59786310936133,0.008046077332512499
0.0084358374698828,185.123888446748,0.026783783966877885,37.3209759108644,186.68556348147746,0.008400454642897974
0.0087910904564802,185.129834819139,0.027911712199324635,37.32217469953842,186.75732794322732,0.00875267380609883
0.0091656691112984,185.118832826304,0.02910099942837242,37.319956697782885,186.81557079425966,0.009123919282340378
0.0095277645980181,185.097822595588,0.030250652598707465,37.31572103527054,186.86139107688447,0.009482661709057077
0.0098917472463824,185.104177272023,0.03140629750726412,37.31700213803984,186.93518100784743,0.009843144164704408
0.0102575785805311,185.094391102818,0.032567811993186244,37.31502924632811,186.99301136437072,0.01020532663653516
0.0106281058402985,185.072746775623,0.03374423604294773,37.3106657499656,187.03971951650908,0.010572024532191521
0.0110152177350307,185.033601025853,0.03497331630872247,37.30277396681196,187.07178642944956,0.010954992086308565
0.0113926047530038,184.96960480675,0.036171520090787064,37.2898723290408,187.0768904056326,0.011328197745579683
0.0117682825489814,184.922961485821,0.03736429709301594,37.280469035541515,187.09918714638053,0.011699574834424447
0.0121435099042707,184.873946003132,0.038555643946059474,37.27058751423141,187.11896459746262,0.01207036901724164
0.0125075226627317,184.832659075212,0.039711384454173146,37.26226406956274,187.1444577474082,0.0124299497613088
0.0128714255340691,184.786934560665,0.040866776070669394,37.253046007430065,187.1654058285315,0.012789292762851465
0.0132345773841902,184.676740578062,0.04201978319480388,37.230830900537306,187.1208591923024,0.01314776547206491
0.013604652621654,184.659646670597,0.04319477207375144,37.227384768792355,187.17187701678785,0.013512940209259305
0.0139744788100546,184.646031970531,0.044368970221923355,37.22464004525905,187.22636403166385,0.013877736025875108
0.0143611737530507,184.699755470075,0.04559672666593597,37.235470702767124,187.3522607505267,0.014259028882599618
0.0147474702797787,184.72323815163,0.04682321813829737,37.240204811368606,187.44743861625565,0.014639783784542396
0.015136834553545,184.683631838938,0.04805944970750537,37.2322201787299,187.47915741883182,0.015023415775404603
0.0155244370669228,184.607907967035,0.04929008768747988,37.21695424615426,187.47384181632552,0.015405165822546314
0.0159147944236542,184.552870516457,0.05052947229510209,37.20585869611774,187.48999151102169,0.015789481883282833
0.0162963273375039,184.534518719491,0.05174083929657488,37.202158973849386,187.54175364161256,0.016164967396817186
0.0166961299672089,184.516343122673,0.053010212645888254,37.198494773530875,187.59705196852323,0.01655828182690514
0.0170919197872404,184.488992163846,0.054266845324488264,37.192980820231355,187.64226321953927,0.016947496253723857
0.0174843077771996,184.490786227545,0.05551267719260873,37.19334250347307,187.71647991600491,0.01733321588369701
0.0178920829517461,184.496200670196,0.05680736337179386,37.194434055111515,187.79722199686915,0.017733903620726597
0.0182842775417945,184.448480993096,0.05805258119519753,37.18481376820816,187.82098821173616,0.0181191301683949
0.0186833908049729,184.359836192448,0.059319765805788946,37.16694297639752,187.80430306077227,0.018511000176434592
0.0190826546008995,184.176354198099,0.06058742835785591,37.12995300633676,187.69092795091427,0.018902864396506368
0.0194850587093398,184.080184750134,0.061865061402153865,37.110565245627015,187.6669979572165,0.019297655416730473
0.019874802111964,183.975913677075,0.0631024967054857,37.089544197298316,187.63239855477462,0.019679876735151484
0.0202532468800882,183.948481489774,0.06430405884428003,37.08401386833844,187.67403549860373,0.02005087773447808
0.0206551741234769,183.954487331886,0.06558017784203915,37.08522464610822,187.75409929852103,0.020444748664156572
0.0210265368922735,183.910565322613,0.06675925463296836,37.07636996903878,187.7775676092478,0.020808529924368126
0.0214333530310182,183.897636252087,0.06805089587348279,37.07376346842074,187.83917921144777,0.02120688892875454
0.0218435407814447,183.819206736723,0.06935324198108692,37.05795207812336,187.83446907548944,0.02160838884996343
0.0222550408587991,183.719117068181,0.07065975472668715,37.03777400094529,187.80779352507585,0.022011011391370412
0.0226636212168776,183.63031138845,0.07195699736358638,37.01987077591152,187.7920392096951,0.02241061688286778
0.0230781823331059,183.573977832488,0.07327322890761123,37.00851393102958,187.8105315645197,0.02281590861732185
0.0234875674398277,183.489697373988,0.07457302662145295,36.99152299059598,187.79942401557312,0.0232159789421844
0.0238862871822576,183.379660357364,0.07583896180366788,36.969339528044586,187.75991958804485,0.023605472777490078
0.0242681708314535,183.288325392107,0.07705144238986485,36.950926399048775,187.73639778413371,0.02397837790886546
0.0246531503965547,183.236607232343,0.07827375250906117,36.94050001804035,187.7539668685964,0.024354165466584768
0.0250586060600068,183.224411190411,0.07956107424052158,36.93804129598686,187.8157595310082,0.024749787599758644
0.0254679384500016,183.232382152531,0.08086070457875508,36.93964824195025,187.89893318323882,0.025149033731468456
0.0258898302782532,183.189384882412,0.08220021113345391,36.93097999229426,187.93212696579525,0.025560363086719263
0.0262975168627278,183.239087840743,0.08349461603916075,36.94100010869379,188.05782084314578,0.025957682162295697
0.0267209746572193,183.209107417762,0.08483909453667128,36.93495605542082,188.10463333404377,0.026370204311750987
0.0271450831461097,183.09697851548,0.08618563898889829,36.91235086872077,188.06716122108418,0.026783189855094553
0.0275701857237473,182.928547204286,0.08753533967289767,36.878395116384056,187.97192122488343,0.027196972329137092
0.0279771455646343,182.708583021976,0.0888274371677139,36.834050337230366,187.8202476450899,0.02759293484482285
0.0283749512259776,182.606842323168,0.09009047014247888,36.81353941235067,187.78830256761768,0.02797983907871034
0.0287878060920379,182.55419033575,0.09140128434222033,36.8029247716872,187.80952496842457,0.028381221876580306
0.0292081314325673,182.513183541925,0.09273581729840118,36.79465780205208,187.84405259499385,0.028789702125457332
0.0296283941727551,182.482287783865,0.09407015149849744,36.78842921722718,187.88894493587148,0.029197954787383698
0.0300544699467926,182.420502374081,0.0954229420810665,36.77597327861473,187.90305388036163,0.029611684286752378
0.0304589537617859,182.356204751268,0.09670717819367022,36.76301087785563,187.91058395996163,0.030004289173995283
0.0308778252627867,182.293365659229,0.09803709520934777,36.75034251690057,187.92218835061993,0.030410696812987935
0.0312919774205591,182.180804201124,0.09935202831027513,36.7276501269466,187.88160181264487,0.03081236321582416
0.0317079229490507,182.065015646838,0.10067265536323597,36.70430715440254,187.83791913468565,0.031215606603333074
0.0321143711338306,181.938944669127,0.10196312834991215,36.67889124529601,187.7817994619288,0.031609485660846794
0.0325566181173902,181.854909931494,0.10336726252271387,36.661949842189195,187.77549078690603,0.03203788029866127
0.0329930644293429,181.824313715264,0.10475297956316369,36.65578164499723,187.82325501249275,0.0324604761065818
0.0334305255549002,181.74058413666,0.10614191863680812,36.638901761950656,187.81626737900308,0.03288387538852268
0.0338542190787675,181.652645288449,0.1074871455750868,36.62117329015132,187.8023537382818,0.03329377879529774
0.0342420517602931,181.557542997703,0.1087185143389306,36.60200066833692,187.77444578250197,0.03366884130233928
0.0346690363722081,181.432228684999,0.1100741904817607,36.57673730289579,187.72230922037002,0.03408160395843078
0.035090344453945,181.286819808011,0.11141184364127538,36.54742287329502,187.64823676003437,0.034488712235323814
0.0355057336105559,181.14287572592,0.11273070421351498,36.51840374634547,187.57448641689456,0.034889938883615176
0.0359191492986819,181.053760642703,0.11404329902331503,36.50043814556892,187.55705770231606,0.035289099574428544
0.0363455784498213,180.998455744062,0.11539721157818263,36.4892886780029,187.5769493166043,0.03570065814747023
0.0367866454969057,180.959768695333,0.11679759945267558,36.48148936897913,187.61667155553027,0.03612616603224917
0.0372130051137599,180.913885179362,0.11815129123618767,36.47223925215938,187.64623451369175,0.03653731327881175
0.0376417682195325,180.873001853449,0.11951261409701569,36.46399717365532,187.6813814663876,0.0369506078547854
0.038072583652152,180.813714140339,0.1208804530955826,36.45204477069234,187.69775939740336,0.037365708746116826
0.0385009704371855,180.734218083123,0.12224058113806395,36.4360183655576,187.69266087052915,0.03777829879405119
0.038927429918337,180.649860482818,0.12359458999071998,36.41901187333611,187.6820952665203,0.03818886359336661
0.0393717126981851,180.552846893028,0.1250051878167377,36.39945393363445,187.66152170773972,0.038616408192222056
0.039820599040741,180.49364148134,0.12643040195435268,36.38751812263814,187.6810064081717,0.039048197350921514
0.0402626472905093,180.3976177334,0.12783390514736703,36.36815973505344,187.66090338824802,0.03947322674068518
0.0407149126380253,180.29247214462,0.12926984762573032,36.34696238435539,187.63306439728183,0.03990789298922688
0.0411715058916746,180.144876236734,0.13071953120606686,36.317207049325575,187.5617120700697,0.04034652715956985
0.0416115651982904,179.998402884897,0.13211671950457202,36.287678021595234,187.48841816213005,0.04076909571149665
0.0420600374164174,179.894079537181,0.13354061879712525,36.266646434695694,187.4604312535068,0.04119955915351832
0.0424761955717427,179.820786066023,0.13486192094028307,36.25187047091024,187.4588889428279,0.041598840446180285
0.0429235785383165,179.731717308913,0.13628236185915488,36.233914209476865,187.4464457926486,0.04202790251762695
0.0433709284699931,179.642200485571,0.13770269789222808,36.21586761789112,187.43344951302285,0.042456748912064406
0.0437875582629566,179.394328200416,0.13902549748488718,36.165896565203866,187.24956779853565,0.04285598050003014
0.0442096923706113,179.003468208509,0.14036577327669086,36.08709919083541,186.91715647127967,0.04326032405295191
0.04462413445365,178.819283086102,0.14168162689033875,36.049967470158165,186.7989388174415,0.04365714076776655
0.0450494406425227,178.682363341994,0.14303197404000956,36.02236444974599,186.7319038632348,0.04406419591725379
0.0454740001693765,178.924183443152,0.1443799505377704,36.071115382139446,187.06058179135147,0.044470371255355697
0.0459132831328775,179.057079364088,0.14577467394688606,36.09790719980014,187.27817774587749,0.04489045889141272
0.0463672135150521,179.060045292106,0.1472159029102904,36.09850513088857,187.36256064417998,0.045324368579931065
0.046832001576505,178.929765186795,0.14869160500540338,36.07224066165787,187.30940423210666,0.04576846206681994
0.0472877848324938,178.797737659465,0.15013871684316782,36.04562391214815,187.25268660644247,0.04620376024426317
0.0477414135012379,178.686470413306,0.15157898786643034,36.02319243532249,187.21721508438438,0.04663681261049677
0.0481964127557588,178.641785490683,0.15302361049953417,36.01418395492169,187.25167871961767,0.0470709850902033
0.0486580279491688,178.567694030241,0.15448923873861092,35.99924711649658,187.2564458771831,0.047511278123335506
0.0491218913189916,178.467409542747,0.15596200493779833,35.97902976381779,187.2340662382878,0.047953520298620315
0.0495885129019457,178.341867985972,0.1574435284636776,35.95372058597195,187.18557600755148,0.048398194885170776
0.0500591453911361,178.228064716806,0.15893778661685712,35.930777846908086,187.1500093212454,0.04884649152695575
0.0505291573661081,178.122790642506,0.1604300746373932,35.90955459352921,187.12318516137154,0.049293996620837215
0.0510003059571072,177.980227807377,0.16192597141381534,35.8808139259672,187.05727387986886,0.049742383005244716
0.0514646920674589,177.834641941308,0.163400397314182,35.851463815367694,186.98684702774423,0.050184136963898
0.0519257267327174,177.724754380026,0.16486418237637773,35.829310483013245,186.95324140960255,0.05062250985798448
0.0523867433302187,177.623575811289,0.16632791007344436,35.80891288355586,186.92869648671063,0.05106067349711684
0.0528490613799945,177.551465438847,0.1677957698814825,35.794375432471554,186.93489373393263,0.05149988135798766
0.0533029281226248,177.402004889376,0.16923679678933373,35.7642441856982,186.85805120480393,0.051930872807719596
0.0537882974838013,177.293539867775,0.17077784451106912,35.74237763734344,186.82985753213907,0.05239157366761871
0.0542554522182496,177.143929705174,0.17226106079294248,35.71221622856308,186.75495371904606,0.05283478528707545
0.0547195156955903,177.109572427578,0.17373446233349918,35.70528980139973,186.80092245586812,0.05327486968057522
0.0551996296936288,177.033303640107,0.17525882427727144,35.689914013845566,186.80547644448063,0.05372997148613441
0.0556671712416915,176.978440527798,0.1767432686923705,35.678853610404076,186.83032968274642,0.05417295685641088
0.056147208770867,176.883484221092,0.1782673878475027,35.65971041897215,186.81499813777202,0.05462757781361885
0.0566332993963177,176.812830659552,0.17981072558330868,35.64546666096568,186.8263246354048,0.055087720864114044
0.0571105764697991,176.72017360148,0.18132608029161212,35.62678699805837,186.8127645897035,0.05553931491677284
0.0575910708150454,176.576786663408,0.18285164983776914,35.59788019134305,186.7460328884335,0.055993747204308164
0.0580811222776536,176.445756946144,0.18440756323155016,35.57146460034263,186.69392453070614,0.05645700561737641
0.0585677749655772,176.299967630203,0.1859526855157076,35.54207347424893,186.6254644608073,0.05691683879720383
0.0590588804702392,176.234613027397,0.18751194549300945,35.52889798632323,186.6428319729009,0.05738066513996899
0.0595370166931438,176.069747958617,0.18903002800073154,35.49566118845719,186.5524154819868,0.05783203600466524
0.06002559958311,175.955392421034,0.19058127867637423,35.47260711208045,186.51722035098797,0.05829305838245975
0.0605076138786015,175.856825155229,0.19211167406455976,35.452735951294166,186.49750202963833,0.05874767451460361
0.0610055755717775,175.81823465604,0.19369270244039355,35.44495610665766,186.54412725724558,0.05921711463385149
0.0614945311166206,175.755237667083,0.1952451362952704,35.43225591368394,186.5632235987105,0.059677850114572356
0.0619851266981906,175.629749805042,0.19680277726675513,35.40695756069646,186.51618209867902,0.06013991772938866
0.0624785354958623,175.430210986347,0.19836935019936278,35.366730534847555,186.3908336505041,0.06060441972612679
0.0629898265566218,175.233655625747,0.1999926993172742,35.32710497415059,186.27159320049557,0.06108552881224642
0.0634859275202406,175.07524004729,0.2015678198767639,35.29516839353367,186.190054047521,0.06155212333764203
0.0639665846609676,174.923459610714,0.2030939062985721,35.26456945751994,186.11271589909208,0.0620039850324655
0.0644574172916341,174.845169215679,0.20465229990093825,35.24878611388088,186.1152372492404,0.06246520200701296
0.0649462549324523,174.786341592131,0.20620435941053605,35.236926464973614,186.1380598918842,0.06292433303583739
0.0654452958277032,174.73255906467,0.20778881425295764,35.22608390743748,186.16798308338895,0.06339282992243157
0.0659567948220844,174.713843554116,0.20941282356011795,35.222310860509786,186.23740868599262,0.0638727947366208
0.0664420208550254,174.610107519191,0.21095341621470565,35.201397675868904,186.2115559244793,0.06432789350871573
0.0669616108813018,174.528934475836,0.21260311454813322,35.18503319032854,186.21567307373516,0.0648149931168916
0.067479569615538,174.410880013198,0.21424763352933313,35.16123341066072,186.18005113275584,0.06530032740404455
0.0680071651993701,174.311518529206,0.21592274950800006,35.14120213548794,186.1659507659748,0.06579444950367219
0.0685163282406513,174.142684089364,0.2175393421640679,35.107165112415785,186.0743013931389,0.06627107712090516
0.0690291486079995,174.018051461537,0.21916754683039838,35.082039174645864,186.03036939634993,0.066750898844224
0.0695423831250699,173.867748947694,0.22079706642209693,35.05173818785511,185.958926558108,0.0672308776705649
0.0700678430795722,173.748825286739,0.22246540177764174,35.027763177806584,185.92303071219024,0.06772205121108257
0.0705857316989968,173.659352943402,0.22410969814431483,35.00972555338984,185.9172254372864,0.0682059115008842
0.0711077993736779,173.561960476745,0.2257672630114273,34.990091232111794,185.90356954122763,0.06869343941040747
0.0716260957361452,173.451396832005,0.227412853962261,34.967801601332205,185.87504318706232,0.0691772105158708
0.0721577807133107,173.34544732117,0.22910095376476147,34.94644217994788,185.85367009662176,0.06967323531940409
0.0726744228375912,173.176992073768,0.23074129250935202,34.91248160207163,185.7625300214792,0.0701549906132844
0.0731871573865469,172.86768184041,0.23236922470228638,34.850124659026655,185.51937607831158,0.07063287284337659
0.0736898624256649,172.634342572565,0.23396531320148606,34.803083462629104,185.35574352668243,0.07110118569377899
0.0741926984841247,172.487691742508,0.23556181768709591,34.773518655289614,185.28501904818256,0.071569401299974
0.0747047845551451,172.484105634777,0.2371876909625857,34.77279569597105,185.3694935854099,0.07204600484644892
0.0752215671698669,172.525907435721,0.2388284757643274,34.781222939041356,185.50357657043932,0.07252674933731024
0.0757427366556681,172.485840244535,0.2404831888817462,34.77314539329826,185.55038981900844,0.07301134082501932
0.0762759206070311,172.39971658763,0.24217604792732375,34.75578286406621,185.54966368274273,0.07350686065750178
0.0767932767382883,172.291104004124,0.24381865364406533,34.7338865672314,185.52190243345794,0.07398743614653132
0.0773233506983325,172.192769268237,0.24550163846720569,34.714062284476576,185.5072911540819,0.07447958588809285
0.0778664785871169,172.098345695984,0.24722606951409615,34.69502649231037,185.49903784599857,0.0749836045066869
0.0784243278015702,171.995533926853,0.24899724076998536,34.67429963965356,185.4841680599386,0.07550102008462851
0.0789764486413399,171.874783035484,0.25075022443625417,34.649956259953576,185.44884301062737,0.0760128590140034
0.0795235906884289,171.749433205046,0.25248740043576173,34.62468573413727,185.40756483221372,0.0765198240812612
0.0800574872773446,171.608906052035,0.2541825221055691,34.59635546009025,185.3474838649748,0.07701426868002166
0.0806058722015079,171.491273825985,0.2559236442397876,34.57264080331857,185.31447752767613,0.07752187661767901
0.081165294844149,171.39247836939,0.25769981113017304,34.552723639269026,185.30359941031097,0.07803943616667902
0.0817164417619967,171.26087258951,0.2594497025943395,34.52619191404522,185.25570171057942,0.0785490774664773
0.0822566599745866,171.150952303315,0.2611648954193124,34.5040319843483,185.22925799125548,0.07904836114369009
0.0828020133207961,171.02130773034,0.2628963922935276,34.47789563843654,185.18221633116758,0.07955213812162591
0.0833369827935853,170.877135031435,0.26459492036963334,34.448830422337295,185.11751989336682,0.0800460764004025
0.0838865611784075,170.742399509626,0.26633983174144377,34.4216677411406,185.06539225183835,0.08055324918203012
0.0844565198724491,170.569451734349,0.2681494505950259,34.38680146964476,184.9751540243838,0.0810789581550697
0.085016057504032,170.416240127172,0.2699259825753016,34.35591400963787,184.90435699744455,0.08159478642579732
0.0855679538888561,170.275095287475,0.2716782535971181,34.32745920995497,184.84518678945426,0.08210330984052859
0.0861198592634887,170.158733636959,0.2734305531615766,34.30400070121094,184.81277983022736,0.08261158306762113
0.0866750738322524,170.090004833649,0.27519335941740136,34.29014497446364,184.8325685607337,0.08312264333602579
0.0872067484521978,170.015525581405,0.276881426335728,34.27512995721125,184.84202675375082,0.08361179102114488
0.0877662917011331,169.833212437654,0.2786579761510976,34.23837562743105,184.73884370099762,0.08412631993800922
0.0883221346049707,169.675589515298,0.2804227773707819,34.20659884628407,184.66169977164589,0.08463718421099282
0.0888844930934707,169.521605290902,0.2822082655717695,34.175555626645846,184.58944724557523,0.08515377137718243
0.0894595615306023,169.432737632647,0.2840341078596623,34.157639906741636,184.59011605019316,0.08568175817455735
0.0900173258351115,169.374815024944,0.285805009526479,34.145962709028716,184.62148293730615,0.08619359137629425
0.0905985545917639,169.264687549337,0.28765041082885034,34.123761009946335,184.59982358473346,0.086726678175885
0.0911817801093887,169.134418410185,0.2895021518473091,34.0974987514933,184.5563957585918,0.08726131085383215
0.0917501261016987,169.009474832567,0.2913066503728934,34.07231012624551,184.5161154608369,0.08778202888771588
0.0923343105638603,168.876104258378,0.2931614360402564,34.045422618489006,184.46916291578594,0.0883169756748326
0.092913110965995,168.749553783369,0.2949991273170341,34.01991004272719,184.42859979950532,0.0888467101204312
0.0934883869359291,168.570880426305,0.2968256285215749,33.98388949394309,184.33030012172964,0.08937294099226462
0.0940696046582249,168.428031666318,0.2986709947898641,33.95509118392971,184.27199001853154,0.08990432597790232
0.094651531376498,168.262769385882,0.3005186121203811,33.92177430819381,184.18909818190625,0.09043607643473693
0.0952453926372992,168.142391580617,0.30240412162342495,33.89750614265239,184.15717968568737,0.09097844102628144
0.0958309132289472,167.987173860508,0.30426314950190736,33.86621425027841,184.0855381423104,0.09151290037305829
0.0963999751918833,167.857790345244,0.30606992123422944,33.84013053360119,184.0392771702899,0.09203206281960849
0.0969732933248921,167.754156981974,0.3078902063065324,33.81923804756596,184.02183005345697,0.0925548358052147
0.0975487585793366,167.62360662,0.3097173084893937,33.792919094592,183.9750813543721,0.09307929193190116
0.098148147850679,167.48409529627,0.3116203694259058,33.76479361172803,183.92234904404552,0.0936252591685228
0.0987263071346785,167.328945803029,0.31345602515260423,33.73351547389065,183.8487146989008,0.09415160631233462
0.0993222239798508,167.191819484878,0.31534806113602626,33.70587080815141,183.79768282735384,0.09469382988141156
0.0999016758072562,167.080326588292,0.3171878206880384,33.68339384019966,183.77193120888603,0.09522079017942427
0.100492473096498,166.941024347411,0.3190636020813811,33.65531050843806,183.717340745345,0.09575778243031992
0.101081315177754,166.761510919412,0.3209331756893689,33.61912060135346,183.61798376417556,0.0962927107606204
0.101662741663385,166.589676769469,0.3227792047812474,33.584478836724955,183.52564004267035,0.0968206218425533
0.102262380939633,166.43674982486,0.32468305948333476,33.55364876469177,183.4569681378042,0.09736477761707989
0.102872109668329,166.34432909936,0.3266189481969446,33.535016746430976,183.45652116517397,0.09791778583207239
0.103470026076015,166.158931750854,0.32851733279134765,33.497640640972165,183.3514007518777,0.09845978375037938
0.104058143413002,166.007763667782,0.33038460533628133,33.46716515542485,183.28222334719578,0.09899261260305686
0.104649922751363,165.836827307063,0.33226350473557753,33.432704385103904,183.19163847407827,0.09952847278447909
0.10525613021405,165.725705745151,0.33418821342960875,33.410302278222446,183.16935220887794,0.10007710015900369
0.105858861059059,165.633861208496,0.33610188386251233,33.391786419632794,183.16767310884163,0.10062228289469737
0.106467172745498,165.473289130823,0.3380332734669561,33.359415088773915,183.09076238948006,0.1011722124190754
0.107053805159933,165.329241935275,0.33989583138278723,33.33037517415144,183.02836638865335,0.10170225702585796
0.107661976308723,165.116859503205,0.3418267747801955,33.28755887584613,182.8936669192098,0.1022514662464412
0.108277646212208,164.944601396801,0.3437815267237604,33.25283164159509,182.8044145914575,0.10280714015837425
0.108877005815246,164.796618170472,0.345684493463406,33.22299822316715,182.73918052535134,0.10334779673105836
0.109481535816062,164.635736862879,0.3476038762159968,33.190564551556406,182.66031018483605,0.10389282135573975
0.110090976180946,164.494499086952,0.3495388493745035,33.162091015929526,182.60385906783029,0.10444197248903744
0.110687118514635,164.34293210391,0.3514316012839661,33.131535112148256,182.53357770673807,0.10497884949573341
0.111290575747067,164.186255363888,0.35334757799693767,33.09994908135982,182.45863825309007,0.10552202078753102
0.111898418485352,164.009230228491,0.3552774786909926,33.064260814063786,182.3616037080591,0.10606884137274257
0.112505195163735,163.837064300941,0.3572039946448586,33.02955216306971,182.26958519517177,0.1066144048574536
0.113123181144953,163.659569214327,0.35916610013522576,32.993769153608326,182.17326030866428,0.10716974105255099
0.113742169362381,163.528065175162,0.3611313877255597,32.96725793931266,182.12810205981776,0.10772566890263759
0.114352474524382,163.336740846222,0.3630691066149129,32.928686954598355,182.01470134273518,0.10827349588022038
0.114962374109938,163.115284145932,0.3650055377990531,32.88404128381989,181.86740446496546,0.10882065914981946
0.115574215564322,162.891358418769,0.3669481344167223,32.83889785722383,181.71739939022504,0.10936926388695924
0.11619365438418,162.746543607833,0.3689148526697715,32.80970319133913,181.6566592480214,0.10992437433917555
0.116824085193739,162.599940050602,0.37091647049012133,32.780147914201365,181.59552929957036,0.11048901904856141
0.117448436042376,162.475254374965,0.3728987844345438,32.75501128199295,181.55771889689186,0.1110479041970419
0.118069390002417,162.284561665256,0.37487031325767395,32.71656763171561,181.4454008678824,0.11160343899866726
0.118684768422234,162.03923635349,0.3768241397405929,32.667110048863584,181.2708255954196,0.11215368135143151
0.119295295882658,161.806988478865,0.3787625644274391,32.620288877339185,181.10980104533306,0.11269928717277655
0.119910729735799,161.505456550349,0.3807165669111618,32.55950004055036,180.87169370161476,0.11324897653730706
0.120524160657238,161.302020058764,0.3826642100867306,32.51848724384682,180.74281063866349,0.11379657641570409
0.12113223534893,161.110027030772,0.38459484723285275,32.47978144940363,180.62564474213593,0.11433909908571709
0.121742520529655,160.93076118552,0.38653250268165457,32.44364145500084,180.52287768300116,0.11488329817145465
0.122356169393711,160.769554680017,0.3884808378250324,32.411142223491424,180.44070154579663,0.11543019825397478
0.122973260586819,160.580316288184,0.3904401023631503,32.3729917636979,180.32740136820468,0.11597986477542627
0.123591527083929,160.396302032742,0.39240309849147453,32.33589448980079,180.21992593958367,0.11653027535437932
0.124221343831646,160.197421294069,0.394402766665476,32.29580013288431,180.09736024558256,0.11709065720141637
0.124836762745673,159.999214114271,0.39635672171751174,32.25584156543704,179.9729980461484,0.11763792534676773
0.125466741586955,159.734028693132,0.39835690453858214,32.20238018453541,179.77533679381645,0.11819783102751434
0.126100871971558,159.467187224118,0.40037026850969665,32.148584944382186,179.57613858393097,0.11876111004925091
0.126728929907031,159.204130926244,0.4023643524548234,32.09555279473079,179.37990007530576,0.11931868253095412
0.127352347357405,158.956839737093,0.40434370285976085,32.04569889099795,179.20036640612662,0.11987182803866736
0.127970601193827,158.739280899038,0.4063066587904007,32.001839029246064,179.05324210876367,0.12042008996479733
0.128589612066831,158.395606177242,0.4082720183121884,31.93255420533199,178.7636357286641,0.12096872224581788
0.129202014541336,158.122038823349,0.4102163961687418,31.877403026787157,178.55172478270902,0.1215112014385884
0.129810193780087,157.838317389543,0.41214736525177625,31.820204785731868,178.32733995580244,0.1220496485095734
0.130420576954097,157.633254750617,0.414085331829258,31.77886415772439,178.1918747823446,0.12258975547276615
0.13103732873073,157.376499134648,0.4160435187200678,31.727102225545035,177.9986951862463,0.12313520165628665
0.131652184192045,157.086528488882,0.41799568480974286,31.668644143358616,177.76731307158923,0.12367867478676894
0.132268186185806,156.734181838582,0.419951491139934,31.59761105865813,177.46512778368754,0.1242228653130993
0.132891692211106,156.457325741336,0.4219311227702615,31.54179686945334,177.2492045179264,0.12477338366457973
0.133507171578817,156.175453454484,0.42388526976274393,31.484971416423974,177.02599651523133,0.12531651787866235
0.13413733319688,155.943841901128,0.425886032900094,31.438278527267403,176.86173298222118,0.12587230308481542
0.134774470651336,155.690726387419,0.42790894431799176,31.38725043970367,176.6738616216054,0.126433926917106
0.135399104943014,155.41806171413,0.4298921581940694,31.33228124156861,176.4615281622013,0.1269842234355361
0.136045761747862,155.095948686756,0.4319452935494619,31.26734325525001,176.19609516985307,0.12755360271636398
0.136650483255774,154.660610646064,0.43386528433708244,31.179579106246504,175.79505783148173,0.12808576492106916
0.137263610917528,154.265490040834,0.4358119646631514,31.09992279223214,175.44052824380086,0.1286250356685296
0.137866466558975,153.918392725424,0.4377260313247456,31.029947973445484,175.13857766891488,0.1291549883613664
0.138477756745738,153.550093184725,0.43966687766771817,30.95569878604056,174.81336563704477,0.12969206899723765
0.139104705136368,153.262127263371,0.44165743880796837,30.897644856295596,174.58161028491475,0.13024260748878122
0.139733434710037,152.89436154585,0.44365365520436745,30.82350328764336,174.2588158324498,0.13079440586237198
0.140366332213059,152.557551829263,0.4456631047764623,30.75560244877942,173.97149583094028,0.1313495548330072
0.140987746414421,152.214999805524,0.44763609486578665,30.68654396079364,173.67544959857634,0.13189433148346422
0.141613189220243,151.862008234593,0.4496218757742715,30.615380860093946,173.3676715420845,0.1324423403900676
0.142244578975667,151.410387577119,0.4516265382477427,30.524334135547193,172.94769441056886,0.13299525553242186
0.142880401582214,150.899079186282,0.4536452750235294,30.42125436395445,172.45960021880427,0.1335517438018733
0.143508415807922,150.340212612795,0.45563922019015235,30.30858686273947,171.9152983570834,0.13410109414572138
0.144131324093884,149.871683036712,0.45761695399808167,30.21413130020114,171.47288715697218,0.13464568015766354
0.144739292894772,149.426437410128,0.4595472549409011,30.1243697818818,171.05431430065482,0.13517691928553177
0.145340130340219,149.074718308169,0.4614549138301953,30.05346321092687,170.74125729750972,0.13570164995918213
0.145936043375432,148.64912355032,0.4633469377169966,29.967663307744516,170.34238849247947,0.13622180816226998
0.146543963102626,148.166483509089,0.4652770828508375,29.870363075432344,169.87938720149077,0.1367521680692056
0.14714140669415,147.653320006968,0.4671739662539262,29.766909313404746,169.37923721585472,0.13727311450144297
0.147791499414286,147.128160788616,0.46923801064035797,29.661037214984983,168.87245227763168,0.13783966068307146
0.148440420353137,146.595809489485,0.47129833462120996,29.553715193080176,168.35655307211255,0.1384048657484135
0.149114102879857,146.046081813555,0.4734372766435459,29.442890093612686,167.82361228230144,0.13899130018486722
0.149770409529611,145.481734905789,0.47552105025651487,29.329117757007065,167.27059392170736,0.13956227855637027
0.150401348171185,144.846699707681,0.47752428044351236,29.201094661068492,166.631838621863,0.1401108798991054
0.151031989648549,144.201020108211,0.47952656713414304,29.07092565381534,165.97998708450453,0.14065892227146967
0.151680633591582,143.581028382416,0.4815860116532728,28.945935321895067,165.35948973919176,0.1412222960538883
0.152309232670666,142.961225085221,0.48358181372936454,28.820982977180556,164.7355395796094,0.14176795739023862
0.152920947692136,142.312445455013,0.4855240089225317,28.69018900373062,164.074999482379,0.142298676657268
0.153521773175797,141.502204541492,0.4874316298331554,28.52684443556479,163.22587389098618,0.14281967420194183
0.154105694210839,140.765208769134,0.4892855791194138,28.378266087857416,162.45792898723508,0.14332575332932015
0.154717758321659,140.085122915148,0.49122888267126724,28.24116077969384,161.75877910679375,0.14385594902227075
0.1553451443863,139.451149982879,0.4932208334265025,28.11335183654841,161.11420901180492,0.14439912564255325
0.155985798353134,138.809107661291,0.49525490977120046,27.983916104516265,160.46135713852362,0.14495348501307379
0.156620353669227,137.983636866524,0.4972696228997957,27.81750119229124,159.59468287312518,0.14550226443361036
0.157275355476791,137.117159751292,0.4993492536388114,27.642819405860468,158.68230979314438,0.14606841080094243
0.157945620189898,136.355836366621,0.5014773441029261,27.489336611510794,157.89264350805917,0.1466474179357922
0.158584300449897,135.6014003455,0.5035051539284229,27.337242309652797,157.10565355931755,0.1471988291396721
0.159215161668838,134.859061781327,0.5055081382985607,27.187586855115523,156.3306691053488,0.14774319136326405
0.159814242471795,134.011028168556,0.5074102198479491,27.016623278780894,155.42789911818016,0.14825985649499032
0.160427198337117,133.111824135966,0.5093563547203465,26.835343745810746,154.46658114764207,0.14878821175043971
0.161077009039944,132.191296571849,0.5114195037018222,26.64976538888476,153.48427524475463,0.14934803043845482
0.161727825762208,131.219077466546,0.5134858467950104,26.453766017255674,152.4408535637332,0.1499084018734918
0.162416540462112,130.247550854493,0.5156725159672056,26.25790625226579,151.40190746794275,0.15050106275125139
0.163099219668974,129.266652325827,0.5178400224489924,26.060157108886724,150.34994244938997,0.15108818345640973
0.163757235311604,128.202188537386,0.5199292221143427,25.845561209137017,149.19622449316535,0.1516537668285702
0.164391711270692,127.230669877771,0.5219436832844471,25.649703047358635,148.1463374250943,0.15219881440873206
0.165030159576993,126.123124450786,0.5239707566569527,25.42642188927846,146.93724380524816,0.15274697473149512
0.165674323619587,124.991140298257,0.5260159774921888,25.19821388412861,145.69896292561162,0.15329973812440065
0.166315089278314,123.80253010099,0.5280504084586469,24.958590068359587,144.39275894761732,0.15384928236444648
0.166964747979018,122.623095581306,0.5301130748333821,24.720816069191294,143.0968298314458,0.1544061454608641
0.167587395608143,121.394165134916,0.532089981055854,24.473063691199062,141.7382971119014,0.15493956481120869
0.16818366481185,120.172607229687,0.5339831357776237,24.2267976175049,140.38367672357077,0.1554501193143987
0.168766421859656,118.913664471671,0.5358333894044078,23.972994757488873,138.98229813477462,0.15594885231105884
0.169366556498733,117.60390980047,0.5377388168834772,23.708948215774754,137.5220790341632,0.15646219749528134
0.169957451759206,116.25875183784,0.5396149093354791,23.437764370508543,136.01779304490518,0.1569673821306324
0.170559790605509,114.845736132098,0.5415273351724911,23.152900404230955,134.43380083872415,0.1574820878962624
0.171174591458959,113.419274116008,0.5434793278821948,22.86532566178721,132.83377202638735,0.15800716953855667
0.171771205017483,111.915198072356,0.5453735759305085,22.562103931386968,131.1390065050149,0.15851645453551788
0.172408947533444,110.377139367742,0.5473984084186846,22.25203129653679,129.40714579788667,0.15906056163496649
0.173068187886389,108.698282953659,0.5494914965392851,21.91357384345766,127.51049781081072,0.1596226991722286
0.17374655660798,106.663301155825,0.5516453172303365,21.50332151301432,125.19568244808957,0.16020081786870982
0.174643836778827,104.073262049638,0.5544941817727757,20.98116962920702,122.24901584007507,0.16096498401164547