File: example/data/02 processed data/test_ID_059.csv
Strain,Stress_MPa,Displacement(mm),Force(kN),True Stress (MPa),True Strain
0.002073183985773557,100.149071170775,0.006582359154831043,40.38010549605648,100.35669862131634,0.002071037905488368
0.002148194186465957,103.841082401882,0.006820516542029412,41.868724424438824,104.06415321141407,0.002145890116471157
0.002222968053019857,107.506668991179,0.007057923568338045,43.34668893724337,107.74565288183298,0.002220500915106874
0.002291066967222157,111.098274460112,0.007274137620930348,44.794824262317164,111.35280804684295,0.0022884464750169624
0.0023704992865660568,114.743603870391,0.00752633523484723,46.264621080541644,115.01560350150378,0.0023676940854092036
0.002450527847243757,118.423845051472,0.007780425914998928,47.74849432475351,118.71404598154831,0.00244753020009182
0.002520090215820357,122.049942516087,0.008001286435229632,49.21053682248628,122.35751938206324,0.002516920113318385
0.002601363834096357,125.650398590921,0.008259330173255933,50.66224071185935,125.9772609935552,0.002597986143663994
0.002673453181044257,129.098517874093,0.008488213849815516,52.0525224068343,129.4436567173716,0.0026698858617148825
0.002761606464046657,132.521458507859,0.008768100523348135,53.43265207036875,132.88743062429918,0.0027578002348432325
0.002826180251559957,135.913573835222,0.008973122298702863,54.80035297036151,136.29769009351403,0.0028221941127511206
0.002903605494000557,139.35128018978,0.009218947443451768,56.1864361725193,139.75590133253505,0.0028993981738658393
0.002973098366103957,142.786417512402,0.009439587312380064,57.57148354100049,143.21093557701,0.0029686874497196545
0.003055567325781457,146.121644333016,0.009701426259356124,58.91624699507205,146.56812885502944,0.0030509085676272262
0.003148482344049157,149.396752915668,0.009996431442356072,60.23677077559734,149.86712595448125,0.0031435362525821095
0.003225445077611357,152.544455299958,0.010240788121416058,61.50592437694307,153.0364790624222,0.003220254487950172
0.003303754262719957,155.678033144547,0.010489419784135862,62.76938296388135,156.19235511016012,0.0032983088568314524
0.003388278894052157,158.766907605496,0.010757785488615598,64.01481714653598,159.30485416760962,0.0033825516105631956
0.0034800139185473568,161.713312798691,0.011049044191387858,65.20280772043222,162.27607737804485,0.0034739726817790213
0.003577390125047457,164.633119485169,0.011358213647025675,66.38007377642015,165.22207638107102,0.0035710064849780827
0.0036637134106969568,167.405236507041,0.011632290078962836,67.49779135963894,168.01856131705273,0.003657018360233679
0.003763216714050457,170.07219212993,0.0119482130671102,68.57310786678777,170.71221064594855,0.0037561535286841866
0.003867906037526957,172.625647465228,0.012280601669148088,69.60266105797994,173.29334724929075,0.0038604449220431517
0.003993494986625656,174.987359864087,0.012679346582536458,70.55490349719989,175.6861710084271,0.00398554215156156
0.004119250398867457,177.086177333291,0.013078620016404176,71.40114670078295,177.81563963990507,0.004110789513986974
0.004276276392933857,178.901024223857,0.013577177547564996,72.13289296705915,179.66605445041716,0.004267159105824503
0.004452722380135457,180.396941365926,0.014137393556930075,72.73604675874137,181.20019886405404,0.004442838341563269
0.004656432805060457,181.612010176428,0.01478417415606695,73.22596250313576,182.4576742984065,0.004645625158892142
0.004889583949899757,182.575306835652,0.015524429040931728,73.61436371613489,183.4680241256036,0.00487766875873156
0.005134819106639157,183.283638487082,0.016303050663579323,73.89996303799145,184.2247668159198,0.005121680878766882
0.005403472889057657,183.73610970829,0.01715602642275806,74.08239943438254,184.72892279583968,0.0053889265065543085
0.005678500970351757,184.125712710078,0.018029240580866825,74.23948736470345,185.1712707483689,0.005662439060078653
0.005972937244650657,184.422600004563,0.018964075751765834,74.35919232183981,185.52414462088558,0.005955169968433971
0.0062881193780411565,184.675362628836,0.019964779025280672,74.46110621194669,185.83662335522916,0.006268431644825903
0.006599111830130457,184.864589281356,0.0209521800606642,74.53740239824275,186.0845313794548,0.00657743301334994
0.0069378950237618565,184.905479344752,0.022027816700443893,74.553889271804,186.18833414976427,0.0069139385711570606
0.007303751684087457,184.95014217727,0.023189411596977672,74.57189732587527,186.30097208966947,0.007277208454834464
0.007649407226069857,184.991887017299,0.024286867942771795,74.58872884537496,186.40696529461343,0.007620298857551192
0.008002404633369858,185.062150593805,0.025407634710949298,74.61705911942218,186.54309280517825,0.007970555195309396
0.008343160314591858,185.124912386253,0.026489533998829147,74.64236467413721,186.66943920851625,0.008308548533742756
0.008711586469099059,185.133067248502,0.02765928703938951,74.645652714596,186.74586997212683,0.008673859548916647
0.009074765360572955,185.116771156756,0.02881238001981913,74.63908213040402,186.79666241931042,0.009033837100619772
0.009445995107232055,185.110128977597,0.029991034465461773,74.6364040037671,186.85867835021847,0.009401660665395545
0.009802773005078758,185.101384593547,0.031123804291125053,74.63287826811816,186.9158914496433,0.009755037532271502
0.010168502799392957,185.102581167227,0.03228499638807264,74.63336072662592,186.98479728200078,0.010117151392692623
0.010536227390876056,185.083496010315,0.033452521966031476,74.62566559135901,187.03357781057798,0.01048110817474818
0.010918647094738658,185.044531020722,0.03466670452579524,74.6099549075551,187.0649669517487,0.010859469040728075
0.011299781991044956,184.998719471159,0.035876807821567734,74.59148369077131,187.0891646698056,0.011236416352984101
0.011675386179453958,184.933329035047,0.037069351119766315,74.56511826693095,187.09249706898316,0.011607754764482872
0.012057052510715257,184.915609772474,0.03828114172152094,74.55797386026153,187.14514698955165,0.011984945274937459
0.012413110557076057,184.834671610054,0.03941162601871648,74.52533959317377,187.12904482353042,0.012336699582338425
0.012789458210749158,184.80678027991,0.04060652981912857,74.51409380885971,187.17035887336297,0.01270836379391831
0.013148077504123355,184.728924002784,0.04174514607559165,74.48270215792252,187.1577542128259,0.013062391784216964
0.013510140582809558,184.678865472648,0.04289469635042034,74.46251855857167,187.17390290785724,0.01341969236830842
0.013883676010886456,184.624595006313,0.044080671334564496,74.4406367065454,187.18786306702177,0.013788180650403707
0.014263258051470457,184.672713741169,0.0452858443134187,74.46003818043934,187.30674831232463,0.014162494797609752
0.014645831098347557,184.712457454317,0.046500513737253495,74.47606284558061,187.4177249079536,0.014539616723335279
0.015041071310869358,184.702830759894,0.04775540141201021,74.47218136238926,187.480959208673,0.014929076020775135
0.015428278299696757,184.649562190295,0.0489847836015372,74.45070347512694,187.49838702368405,0.015310472562018678
0.01581701383229756,184.57969517852,0.050219018917544746,74.42253309597928,187.49919477031992,0.015693228439757623
0.016201726745574057,184.530663743618,0.051440482417197626,74.40276362142677,187.5203791337715,0.016071879394289407
0.016589975269633756,184.522739738751,0.052673171481087175,74.39956866266441,187.58396742770194,0.016453864944895102
0.016990676690667356,184.50781471674,0.053945398492868855,74.39355089378957,187.64272734349368,0.016847949561930798
0.01738415219936946,184.494206454362,0.055194683232998025,74.38806404239875,187.70148181926652,0.01723477652028755
0.017783706056031457,184.493028657272,0.05646326672789987,74.38758915461207,187.77399844829992,0.017627426060397747
0.018171778013181757,184.4694214033,0.05769539519185208,74.37807070981056,187.82155877926087,0.018008644574148802
0.018575265010839857,184.419055994262,0.05897646640941654,74.35776337688644,187.84468883240436,0.018404851854103756
0.018984492478696456,184.276801931473,0.06027576361986124,74.30040653876992,187.77520349173926,0.018806535752555933
0.019370037637928057,184.125041202427,0.06149986950042158,74.23921661281858,187.69155018060306,0.019184826337567466
0.019769419878233958,184.025368437291,0.0627679081133928,74.19902855391574,187.6634432141745,0.01957654279809753
0.020162525915754556,183.947529532455,0.06401601978252071,74.16764390748587,187.65637636379216,0.01996195373614103
0.020547423025045457,183.961377693379,0.06523806810451932,74.17322748597041,187.74130994111505,0.020339172570257892
0.020928012885416358,183.931760053046,0.06644644091119693,74.16128565338815,187.78108629747345,0.020712030218295478
0.021323057578207558,183.906850887148,0.06770070781080899,74.15124227769807,187.82830725764148,0.021098902041678757
0.021741061818086157,183.855653548957,0.06902787127242355,74.13059951093946,187.85287067836953,0.021508095509218818
0.02213361083078026,183.750813923918,0.07027421438772731,74.08832817412373,187.81788292914914,0.021892217904563263
0.022562203593343856,183.680693554411,0.07163499640886674,74.06005564113852,187.82493475855222,0.02231144189457406
0.02297235890299226,183.592655158716,0.07293723951700042,74.02455855999429,187.81021152497533,0.022712466959283334
0.023377601344403358,183.532031893605,0.07422388426848066,74.00011525950154,187.82257056914202,0.023108530638107437
0.023787005062977158,183.435957906454,0.07552374107495247,73.96137822788226,187.79934996590688,0.02350850211353285
0.024180832819466758,183.334526295558,0.07677414420180695,73.92048100236899,187.767707825947,0.023893105576594506
0.024555334966219956,183.25183021832,0.07796318851774836,73.88713794402663,187.75164029250374,0.024258698918297666
0.024951714439504457,183.237078445851,0.07922169334542664,73.88119002936713,187.80915770196094,0.024645503616863077
0.02535706678799736,183.237699730069,0.08050868705189161,73.88144053116383,187.8840703202034,0.02504090976981495
0.025772466542128857,183.208332165509,0.08182758127125911,73.86959952913323,187.93006277648382,0.02544595465173056
0.02618980847308286,183.220767490619,0.08315264190203807,73.87461345221759,188.01928429948958,0.02585272815024006
0.02660149411145766,183.244748603848,0.08445974380387807,73.88428263707151,188.1193327047888,0.026253826540880824
0.027028262023757157,183.154437104738,0.08581473192542897,73.84786904063037,188.10478322161862,0.026669449578254536
0.027448551749942957,183.037465435958,0.08714915180606889,73.80070606377828,188.0615787781553,0.02707859484505055
0.027864956034965558,182.798835193374,0.08847123541101565,73.7044903499684,187.8925166992803,0.02748379267899911
0.028274327553368058,182.645530791976,0.08977098998194358,73.64267801532473,187.80971035574711,0.027881987030013388
0.028670783173254857,182.58534227592,0.09102973657508416,73.61841000565094,187.82020703492742,0.02826746705349928
0.029090982747141857,182.520682974964,0.09236387022217539,73.59233937550549,187.83038901438522,0.028675871550741635
0.029512728550580958,182.495056922028,0.09370291314809454,73.58200695096168,187.88098399879064,0.029085611227227113
0.029940988352291857,182.4568322981,0.09506263801852664,73.56659478259392,187.91977018873348,0.029501507738393145
0.03035156886859276,182.38936420867,0.096366231157782,73.53939164893575,187.9251675573483,0.029900073000687605
0.030768003837872957,182.334057274584,0.09768841218524664,73.51709189311228,187.94411224858337,0.03030415918807945
0.03118059675219536,182.241078158552,0.09899839468822026,73.47960271352817,187.92346372829914,0.030704356282915835
0.03160001639335426,182.117122071765,0.10033005204889978,73.42962361933566,187.87202611474328,0.03111101091624515
0.03200579070726576,181.993755822352,0.10161838549556879,73.37988234757233,187.81860988123142,0.031504278194079825
0.03242320037470956,181.89463267482,0.10294366118970286,73.33991589448742,187.7922387971199,0.03190866088288637
0.03288402048036686,181.844030333622,0.10440676502516477,73.31951303051639,187.82379315134526,0.03235490937187748
0.03330301630804866,181.769781591629,0.1057370767780545,73.28957593774481,187.82326359228549,0.032760483335865336
0.03374254448292456,181.694607810689,0.10713257873328548,73.25926586926981,187.8254461970487,0.03318575522134016
0.03414383888492996,181.61064928392,0.10840668845965261,73.22541379127654,187.81153403285768,0.03357387558450002
0.03455375207301806,181.50424485892,0.10970816283183232,73.18251152711655,187.7758975359755,0.03397017632487378
0.03498081605602276,181.367517440738,0.11106409097787226,73.12738303210557,187.71190120686995,0.034382891333981036
0.03538913544432436,181.211577626636,0.11236050503572982,73.06450809905964,187.6244986913447,0.03477733233067309
0.03580588771267466,181.088974274797,0.11368369348774203,73.01507442759815,187.5730257536838,0.0351797592091805
0.03623879067608816,181.024418434429,0.1150581603965799,72.98904551276178,187.58452444133488,0.0355976102084639
0.03665844552625046,180.990556606342,0.11639056454584519,72.9753924236771,187.62538906646134,0.03600250713105745
0.037093657231541954,180.944960261743,0.1177723617101457,72.95700797753477,187.65687059546707,0.03642224072515697
0.037529670770569755,180.879717718887,0.11915670469655897,72.93070218425524,187.6680739739504,0.03684257104687099
0.037952136520504956,180.844170131734,0.12049803345260322,72.91636939711515,187.70759276551098,0.03724967242861836
0.038381251671687655,180.780494424284,0.1218604740576083,72.89069535187132,187.71907607811457,0.03766301178898568
0.03881380099503836,180.698912745534,0.12323381815924679,72.8578016189993,187.71252438485894,0.03807948623518411
0.03924371283027236,180.605320629073,0.12459878823611473,72.82006527764223,187.69294396745957,0.03849324941402512
0.039688404827017756,180.509028801924,0.12601068532578136,72.78124041293574,187.67314421194658,0.038921057517763466
0.04013444548084936,180.454768512816,0.1274268644016967,72.75936266436742,187.6972205814529,0.03934997929886985
0.04058393022156226,180.348972686001,0.12885397845346017,72.7167057869956,187.6682428090201,0.03978202695409663
0.04104568261659996,180.229895498814,0.13032004230770486,72.66869386512181,187.62755458748128,0.04022567206729391
0.04148224265477416,180.062987363509,0.13170612042890795,72.60139650496683,187.5324038984656,0.0406449317941589
0.04192773682087296,179.943006911906,0.13312056440627165,72.5530203868805,187.48760994846492,0.041072590466506104
0.04236435568369326,179.850019196512,0.1345068292957261,72.51552774003365,187.46924937947207,0.041491551773106976
0.04279768879159586,179.791499714158,0.13588266191331685,72.4919326847485,187.48616036629883,0.04190718672607299
0.04324142782532216,179.684937045109,0.13729153334539784,72.44896661658795,187.45477028164262,0.042332623657609314
0.04366474274308286,179.583876611101,0.13863555820928808,72.40821904959593,187.42536038413027,0.042738310247199825
0.04409544868597136,179.160464197892,0.14000304957795906,72.23749916459006,187.06062525348494,0.043150911225766954
0.04451199303718576,178.900641118312,0.1413255778930648,72.13273849890341,186.86386521011838,0.043549784032993505
0.044923728419902755,178.724715533696,0.14263283773319124,72.06180530318623,186.75369611625612,0.04394389559509422
0.045356359768096155,178.775237766705,0.1440064422637053,72.08217586753547,186.88383176847861,0.04435784141682013
0.04578253052710496,179.011703668086,0.14535953442355823,72.17751891897227,187.2073124559792,0.04476543822149603
0.046236012879633456,179.058838541199,0.14679934089283622,72.19652369981144,187.3378053062021,0.045198973919409045
0.04669755841875406,178.988763708866,0.14826474797954414,72.16826952741478,187.34710195846134,0.045640025229333
0.04715689610102236,178.860787396439,0.149723145120746,72.11666947824422,187.29530696423996,0.046078773671131695
0.04760917703978356,178.751580099956,0.1511591371013128,72.07263709630226,187.26179572307583,0.04651059367393604
0.048064595732103255,178.655748520155,0.15260509144942783,72.0339978033265,187.24276484799256,0.04694522114831295
0.048519317546872255,178.608505373968,0.1540488332113194,72.0149493667839,187.2744681627798,0.04737899517378268
0.048987998563323455,178.519204386735,0.15553689543855195,71.97894320873155,187.26450291475803,0.04782588851298731
0.049447410256421756,178.419949156151,0.15699552756413906,71.9389234997601,187.2423535800051,0.04826374969137509
0.049916567250520155,178.287940405411,0.15848510102040148,71.88569757146172,187.18746237261445,0.04871070125092857
0.05038628974849476,178.174374068405,0.15997646995147086,71.8399076243809,187.15191970597235,0.049157991511226705
0.050861924869049654,178.04443075831,0.16148661145923265,71.78751448175059,187.10011321889186,0.04961070825870048
0.05132808512605456,177.90829333529,0.1629666702752232,71.73262387278893,187.03998536023485,0.05005420790661934
0.051789056663384056,177.781847709389,0.16443025490624436,71.68164099642566,186.9890018941317,0.05049257772972809
0.05224851319149046,177.668050877911,0.1658890293829822,71.63575811397372,186.95094237791196,0.05092931568725531
0.052709092220038355,177.590651250602,0.16735136779862175,71.60455058424273,186.95129326478667,0.05136692928547136
0.05317347973019896,177.465426292375,0.1688257981433817,71.5540598810856,186.90188054014374,0.051807967664223985
0.05363641203061286,177.353697867928,0.17029560819719583,71.50901098034856,186.86631388192498,0.05224743048398247
0.05411390402678256,177.207148131661,0.17181164528503462,71.44992212668572,186.79651873851756,0.052700512616814466
0.05458208791418006,177.111449281837,0.17329812912752168,71.41133635043668,186.77856197714607,0.05314456324988802
0.05505972415991646,177.075618120843,0.17481462420773475,71.39688922632389,186.8253528100233,0.05359737590383137
0.055520354220260255,176.993574632658,0.1762771246493263,71.3638092918877,186.82032059097324,0.05403387208076007
0.05600664460806116,176.938994447264,0.17782109663059417,71.34180256113684,186.84875382657964,0.054494477506755803
0.05648625560846716,176.854456717928,0.17934386155688323,71.30771694866857,186.84430276559345,0.05494854862680296
0.05696804326558626,176.784522094651,0.18087353736823636,71.27951930856328,186.8555903980251,0.05540447300209849
0.05744627459113066,176.638594747108,0.18239192182683983,71.22068140203395,186.7858239643418,0.055856826478576836
0.057933109223785355,176.516318013257,0.18393762178551848,71.17137942294524,186.74245714449947,0.05631710764135512
0.058419663181643856,176.381688429283,0.18548243060171923,71.11709677468691,186.68584725873137,0.05677691185998519
0.05891597906476086,176.266001899728,0.1870582335306157,71.07045196597034,186.65088597748147,0.05724572358950454
0.05938998817554666,176.147416753862,0.18856321245736063,71.02263843515715,186.60880975202693,0.057693259616903685
0.05987492588326496,176.000409279051,0.19010288967936623,70.96336502131336,186.53842074005848,0.05815090671233297
0.06036675466056596,175.896420201967,0.1916644460472969,70.9214366254331,186.51471624597096,0.058614843244319766
0.06085848297066966,175.834446237354,0.19322568343187616,70.89644872290113,186.53546388934717,0.05907846993533631
0.06134847424015346,175.809553039447,0.19478140571248723,70.88641178550503,186.59520087526042,0.059540245142062395
0.06183492886365706,175.683554690846,0.19632589914211115,70.83560925134911,186.54693479766885,0.0599984765235854
0.06233287393068776,175.533994278319,0.19790687472993362,70.77530649301822,186.47553261421953,0.060467314320200936
0.06284169321905335,175.33628209045,0.19952237597049438,70.69558893886945,186.35471093974746,0.060946163734223915
0.06333930981477275,175.165085808082,0.20110230866190346,70.62656259781866,186.25992144681138,0.06141424862830875
0.06382568909204585,175.005848793273,0.20264656286724556,70.56235823344768,186.17571768764205,0.06187155145719066
0.06430112097426625,174.857883412593,0.20415605909329534,70.5026985919575,186.1014413272103,0.062318359314580615
0.06480190367342105,174.826220054923,0.20574604416311182,70.48993192614496,186.15529192651044,0.06278877591968836
0.06529186923483406,174.765435910729,0.20730168482059813,70.46542375920593,186.1761978989811,0.06324881723456938
0.06579586707205445,174.737037044633,0.20890187795377288,70.45397333639603,186.23401190658635,0.06372181310238864
0.06628649507386535,174.6570591391,0.21045962185952247,70.42172624488512,186.23446342933974,0.06418204673987088
0.06680090066426415,174.570005583425,0.21209285960903868,70.38662625123696,186.23143918536343,0.06466435759258009
0.06731747063855956,174.465189910371,0.21373296927742658,70.34436457186159,186.20974520961312,0.06514846380836463
0.06784056653120575,174.361897555216,0.21539379873657824,70.30271709426309,186.1907074668179,0.06563844712014352
0.06835802314101795,174.235474634788,0.21703672347273198,70.25174337274653,186.1458672418591,0.06612291202189437
0.06886749540000925,174.0710536718,0.21865429789502935,70.18544884046976,186.05889115981745,0.06659967244256294
0.06938488036192055,173.931551578578,0.22029699514909773,70.12920159648264,185.99977147602084,0.0670836050015755
0.06989940574680414,173.804194514923,0.22193061324610314,70.07785122841696,185.9530044278181,0.06756463073354173
0.07041900927754255,173.717272726727,0.2235803544561976,70.04280436341632,185.9502709665398,0.06805016927518948
0.07094430695895355,173.603304523366,0.22524817459467752,69.99685238382118,185.91947064856035,0.06854078914148207
0.07146336283952136,173.505144599107,0.2268961770154803,69.95727430235995,185.9044057021166,0.06902534294330129
0.07198210352007466,173.395322440316,0.22854317867623702,69.91299400793541,185.87668249011156,0.06950936803171368
0.07251640971722625,173.279062041377,0.23023960085219333,69.8661178150832,185.84463749978613,0.07000767213862663
0.07302577685694304,173.025103490348,0.23185684152079417,69.76372172730831,185.66039608848362,0.07048248652584681
0.07353514266199275,172.748200751421,0.23347407795182698,69.65207454297294,185.45126433827932,0.07095707432811087
0.07403856878493226,172.537635404095,0.23507245589215991,69.5671745949311,185.31207499095066,0.07142590678725061
0.07454082401578994,172.454120383531,0.23666711625013306,69.5335013386397,185.30899262183763,0.07189342987873047
0.07505668615083885,172.52402524828,0.23830497852891333,69.5616869801065,185.47310686481956,0.07237339149248571
0.07558138403993545,172.513548005901,0.23997089432679503,69.55746255597928,185.55236072982683,0.07286133775064962
0.07610007653784005,172.441456883409,0.24161774300764216,69.5283954153905,185.56426495053307,0.07334346534941853
0.07662700758641945,172.344534857106,0.24329074908688175,69.48931645438513,185.5507808370794,0.07383301282897493
0.07715158405625415,172.225639376814,0.24495627937860692,69.4413777967314,185.5131202698364,0.07432013484072043
0.07768123964001525,172.149949144986,0.2466379358570484,69.41085949525835,185.52277059853412,0.0748117326933272
0.07823393980168795,172.061371798052,0.24839275887035925,69.37514510897456,185.52241080149665,0.07532446174598334
0.07879467717274845,171.934878741539,0.2501731000234763,69.32414310858853,185.4824320067142,0.07584437824526286
0.07933975943233115,171.810453334681,0.2519037361976514,69.27397478454338,185.44185337021435,0.07634952033643938
0.07988874203570705,171.680301099524,0.2536467559633699,69.22149740332807,185.3956243866764,0.07685801919594591
0.08041809503912475,171.552404753278,0.25532745174922106,69.1699295965217,185.3483223429175,0.07734809125879136
0.08097371082354016,171.447987191262,0.25709153186474,69.12782843551685,185.3307669273653,0.07786221904917824
0.08153799788936625,171.318623998895,0.25888314329873785,69.07566919635447,185.28760160092602,0.07838410022684761
0.08209243147163665,171.199197993163,0.26064346992244636,69.02751663084334,185.25335642241592,0.07889660327439424
0.08262161461684515,171.088138409775,0.26232362640848333,68.98273740682129,185.22371664698093,0.07938552065053092
0.08315974691590385,170.955192565201,0.2640321964579947,68.92913364228905,185.1717831128827,0.07988246121867025
0.08370622453343765,170.810784811795,0.26576726289366454,68.87090843611574,185.10871071798383,0.08038685570944196
0.08427492475650306,170.664153089679,0.26757288610189717,68.81178652575858,185.04686174994401,0.08091149148526124
0.08482430342878465,170.487583057791,0.2693171633863912,68.74059348890134,184.94907353392517,0.0814180415562677
0.08539212650944895,170.352771135774,0.2711200016675004,68.68623732194408,184.89955651983522,0.08194132862182353
0.08593595694206975,170.215512734571,0.27284666329107143,68.63089473457903,184.84314570780143,0.08244224826463281
0.08649118053713155,170.139549737275,0.27460949820539265,68.60026645406928,184.85512025010792,0.08295340336629038
0.08703502724295525,170.039638951252,0.27633621149638293,68.5599824251448,184.83904355975648,0.08345383139446552
0.08757700577194245,169.934493835832,0.27805699332591727,68.51758791460746,184.8168479833448,0.08395229137903358
0.08813962617563514,169.751974118037,0.27984331310764154,68.44399596439251,184.71384965937685,0.08446947308180858
0.08869905774135285,169.6033193525,0.2816195083287953,68.384058362928,184.64697396887252,0.08498345841491291
0.08926679494131345,169.453296041811,0.2834220739386702,68.3235689640582,184.57984867170504,0.08550480470886022
0.08983149375266765,169.408999068776,0.2852149926647198,68.3057084245305,184.62726251026845,0.08602309140287934
0.09040378206852435,169.316782250729,0.2870320080675648,68.26852660349394,184.6236597338677,0.08654806990895812
0.09098260633838115,169.205688553906,0.28886977512436013,68.2237336249349,184.60046310582075,0.08707876386259952
0.09156248458511346,169.076122874165,0.2907108885577352,68.17149274286334,184.5571527685415,0.08761014189715974
0.09213456555340065,168.939078399855,0.292527245632047,68.11623641082153,184.50420699321754,0.08813409825945707
0.09271333245435395,168.809374530725,0.2943648305425738,68.06393981078831,184.46025419300364,0.08866389890600888
0.09328910241058795,168.658517555232,0.2961929001536167,68.00311427826955,184.39251927186,0.08919067779734545
0.09387623458202485,168.503298572831,0.2980570447979289,67.94052998456546,184.32175375749904,0.0897275665049431
0.09444807635848415,168.3444591957,0.2998726424381872,67.87648594770624,184.2442695323432,0.09025019634240965
0.09503679660633925,168.186119528313,0.3017418292251271,67.8126433938158,184.16998956193473,0.09078796691055793
0.09563096427216874,168.060505373983,0.3036283115641357,67.76199576678995,184.132293558965,0.09133042039529897
0.09620927952159565,167.914200885224,0.3054644624810662,67.70300579692231,184.06910517383588,0.09185811876609452
0.09678156137205216,167.803654155193,0.30728145735626555,67.65843335537382,184.0439538082684,0.09238003783002835
0.09734770500143165,167.674671890917,0.3090789633795455,67.60642770641773,183.99741638636587,0.09289609096383435
0.09794278742172455,167.557075482396,0.31096835006397544,67.55901283450207,183.96808250737413,0.09343823555647225
0.09853474923874575,167.403567946699,0.31284782883301776,67.49711859610905,183.89863653599835,0.09397724569563659
0.09911861278501455,167.255502245383,0.31470159559242117,67.43741850533843,183.83363560860627,0.09450859751853566
0.09970960062422565,167.139606632979,0.31657798198191645,67.39068939441714,183.80503005884353,0.09504614551781819
0.10029104814341955,167.029065236131,0.31842407785535704,67.34611910320803,183.78058525907818,0.09557473402806058
0.10088212598021655,166.847799841864,0.32030074998718755,67.27303289623957,183.6797606050329,0.09611179113738084
0.10146630861879255,166.683209100636,0.32215552986466633,67.20666990937643,183.59593903681187,0.09664229997340282
0.10205311649389255,166.507898062756,0.32401864486810883,67.13598449890321,183.5005479809076,0.09717490965433785
0.10265861967852555,166.39666494581,0.3259411174793186,67.09113530615059,183.47871688825694,0.09772419071446238
0.10326726657026256,166.251495998925,0.3278735713605836,67.03260318676656,183.41983355395092,0.0982760196865746
0.10386293134713155,166.081331498051,0.32976480702714267,66.96399286001416,183.33102542947324,0.09881578375839335
0.10444918492575755,165.914683442182,0.3316261621392802,66.89680036388778,183.24433689493299,0.09934673550935152
0.10505300656221656,165.768761869623,0.33354329583503756,66.837964785832,183.18326869812304,0.09989330355876752
0.10565169407464355,165.685616164065,0.33544412868699325,66.80444043735102,183.1905821955996,0.1004349295180286
0.10626208888054155,165.542575535732,0.3373821321957194,66.74676645600715,183.1334754108237,0.10098684508191362
0.10686307722087955,165.399839766635,0.33929027017629254,66.68921539390723,183.07497561593806,0.10152995792913656
0.10745368113940255,165.217324924442,0.3411654376176031,66.61562540953503,182.97053467557805,0.10206339916359242
0.10805713796613454,165.016331645863,0.34308141304247713,66.53458491961196,182.84752416118545,0.10260815555697282
0.10867126417805856,164.877111406609,0.3450312637653359,66.47845131914475,182.79451553719178,0.10316223897742406
0.10927495536045854,164.702249681474,0.34694798326945586,66.40794707157032,182.7000806631842,0.1037066085315549
0.10988055694861755,164.567003830892,0.3488707683118607,66.35341594461565,182.6497178671957,0.10425240318166713
0.11047832925411055,164.426296264833,0.350768695381801,66.29668265398067,182.59183876161316,0.10479084975771374
0.11107927893102255,164.279771269484,0.3526767106059966,66.23760377585594,182.5278498050516,0.10533186628535733
0.11168368592087854,164.102524680779,0.3545957027987894,66.1661379512901,182.43009950605034,0.10587570025623917
0.11229761196247555,163.920113898761,0.35654491798085985,66.09258992398044,182.32795124220885,0.1064277966769919
0.11290702361175856,163.749316689929,0.35847979996733337,66.02372448937938,182.23776465584817,0.10697553206705586
0.11352287411238955,163.603721593351,0.3604351253068368,65.96502054643912,182.1764862841114,0.10752875003899122
0.11414088653420355,163.436384026395,0.36239731474609627,65.89755003944246,182.09115779111224,0.10808360256977874
0.11475767811430355,163.232989790025,0.36435562801291377,65.81554148333808,181.9652286899841,0.10863705224723527
0.11536401151580156,162.992146844685,0.3662807365626699,65.718433607777,181.7955747502605,0.10918081936026562
0.11597969786255755,162.815511694322,0.3682355407136202,65.64721431515063,181.69880554796717,0.10973267191421625
0.11659999628570356,162.676042326013,0.3702049882071088,65.59098026584844,181.64406825699908,0.11028835056768885
0.11723351743216055,162.540858122604,0.37221641784710974,65.53647399503393,181.59609464675864,0.1108555559207748
0.11785946752093256,162.386039444472,0.37420380937896086,65.47405110401111,181.52477158623063,0.11141566694018258
0.11847262232519755,162.153723500765,0.3761505758825022,65.38038131550846,181.36450034369565,0.11196402451409868
0.11908097499240555,161.930414197997,0.3780820956008876,65.29034300463239,181.21324580161857,0.11250779042247935
0.11970197164555856,161.657818224937,0.3800537599746484,65.1804323082946,181.00857779838125,0.11306255315194548
0.12031016999023356,161.387149802928,0.3819847897189915,65.07129880054057,180.80366522995757,0.11360558445817451
0.12092307824724956,161.210370845977,0.3839307734350173,65.00002152509794,180.70442513405317,0.11415252286610392
0.12153491418839354,160.99958781644,0.3858733525481495,64.91503380758861,180.56665890607775,0.11469820618181381
0.12213916684849856,160.863775749117,0.3877918547439829,64.86027438204397,180.51154329521785,0.11523683403317685
0.12275697264166055,160.674303864869,0.3897533881372722,64.78387931831517,180.39819498862659,0.11578724329077343
0.12337935280470655,160.476517817154,0.3917294451549433,64.7041319838765,180.2760067257874,0.11634142174550334
0.12399928881248155,160.292810456392,0.3936977419796289,64.63006117601725,180.1690049547385,0.11689311874219013
0.12461971568243856,160.09891051582,0.3956675972917424,64.55188071997863,180.05039122536965,0.11744494800669508
0.12524395912686154,159.874086652302,0.39764957022778535,64.46123173820817,179.89735022642722,0.11799986470447649
0.12588050900287756,159.588256749481,0.39967061608413623,64.34598512139073,179.67730773998758,0.11856540419551218
0.12650695717755156,159.345172305354,0.4016595890387262,64.24797347351873,179.50344519463698,0.1191216567943503
0.12713475771131755,159.071544408793,0.4036528557334332,64.13764670562533,179.29506666596998,0.11967879996920196
0.12775528546231354,158.862910998982,0.4056230313428455,64.05352571478954,179.15848754303104,0.12022918402765213
0.12837422869939255,158.568072104203,0.4075881761205713,63.93464667241465,178.9241260569297,0.12077786108605801
0.12899259811911756,158.271169330865,0.40955149902819826,63.814935474204766,178.68697867020407,0.1213257290070764
0.12960602932632756,157.980675686073,0.41149914311109,63.69780843662464,178.45592377203522,0.12186892531901881
0.13021459144757355,157.737018477067,0.413431327846046,63.599565849953414,178.27667989421667,0.12240751863068518
0.13082352740583256,157.515659588609,0.41536469951351834,63.51031394612715,178.12241379764717,0.12294615260408322
0.13144522544361456,157.249536442491,0.4173385907834762,63.40301309361237,177.9192372110781,0.1234957761204311
0.13205759366638556,156.907529949686,0.41928285989077413,63.265116075713394,177.62836078297784,0.12403685628392028
0.13267837208775954,156.59748416315,0.42125383137863653,63.14010561458208,177.37458343495544,0.12458506892001416
0.13329760437307156,156.30901949455,0.42321989388450215,63.023796660202564,177.14463733507725,0.12513161690389318
0.13391302594054955,156.04534175467,0.4251738573612448,62.91748179548295,176.94184565296504,0.1256745056627624
0.13455236437326454,155.823009323704,0.42720375688511486,62.827837359317456,176.78936365196563,0.12623818051746638
0.13518274012776954,155.558865845508,0.42920519990566824,62.72133470890883,176.58773958167188,0.1267936424913884
0.13581706602470855,155.24859690157,0.43121918462844966,62.59623427071303,176.33400583719393,0.1273522739027312
0.13644490365228254,154.89115412704,0.43321256909599704,62.452113344022536,176.02526272849482,0.12790488416680254
0.13705140076147856,154.45460747356,0.43513819741769444,62.27609773333939,175.6228277818757,0.1284384211005602
0.13766609429685756,154.087080849875,0.4370898493925227,62.127910998669606,175.29964745208142,0.12897887814779946
0.13826388805374154,153.715015703558,0.4389878445706294,61.97789433167459,174.96825142697386,0.12950419639156527
0.13889339572430956,153.421236108233,0.4409865314246828,61.85944239883954,174.73043256752652,0.13005708546171293
0.13951716579965054,153.078114901367,0.44296700141389045,61.72109592823118,174.43513963835898,0.1306046339162884
0.14015012000036256,152.709389400319,0.4449766310011511,61.57242580620862,174.1116286499558,0.13115993794764383
0.14077627863685355,152.396428729687,0.44696468467201,61.446240063809796,173.8502308437988,0.1317089768404327
0.14140227725456656,152.042190203857,0.44895223028324877,61.30341109019514,173.54130213745432,0.13225757426003168
0.14202814693304655,151.637875933386,0.4509393665124228,61.14039157634124,173.17472245706801,0.13280575798178929
0.14266066472037056,151.180297306216,0.4529476104871765,60.9558958738663,172.74777901254402,0.13335945947518996
0.14328727949425155,150.614333797192,0.4549371123942486,60.72769938702782,172.19545193983072,0.13390769137273717
0.14392140854493354,150.097878427546,0.456950472130164,60.51946458198655,171.7001765104446,0.13446219177337512
0.14453462817456555,149.656863340185,0.45889744445424563,60.341647298762595,171.28746243683042,0.1349981161122916
0.14513536369988056,149.242606423669,0.46080477974712075,60.17461891002335,170.90298638648636,0.13552285159053185
0.14573260763315254,148.871494023604,0.4627010292352593,60.024986390317125,170.56692504990707,0.13604426439500295
0.14633970276961455,148.419304498577,0.4646285562935262,59.84266357382624,170.13894140417165,0.13657399912274568
0.14693394910206956,147.917159257076,0.4665152883990708,59.64019861245305,169.65121160667795,0.13709225070189807
0.14755935070650256,147.386843340268,0.4685009384931456,59.42637523479606,169.13515024623894,0.13763738336362571
0.14821645420396054,146.865583372671,0.4705872420975747,59.21620321586095,168.63347938476446,0.1382098290824077
0.14887493747953856,146.328129827196,0.47267792649753493,58.99950194632543,168.1127210067176,0.1387831482772806
0.14954583495250254,145.779199036044,0.4748080259741955,58.77817305133294,167.57987107459624,0.13936693824303878
0.15018007981958656,145.169344664796,0.4768217534271873,58.53227976884575,166.97088843391214,0.13991852126351123
0.15081797001974956,144.518816665851,0.47884705481270484,58.26998687967112,166.314851225051,0.14047296781469268
0.15145144942924055,143.886550809601,0.4808583519378387,58.01505728643113,165.67837748308912,0.14102327649718335
0.15209469251730356,143.271632218547,0.48290064874243877,57.76712211051816,165.0624870672791,0.14158175726131375
0.15271387757511454,142.649825759026,0.48486656130098865,57.51640974603928,164.4344337861013,0.14211905574305464
0.15331668449700855,141.926325415942,0.4867804732780021,57.224694407707815,163.68599907155775,0.14264186489011377
0.15390245825685356,141.115005621667,0.48864030496551003,56.89757026665613,162.83295188377124,0.1431496396060706
0.15450450968181956,140.427822200998,0.49055181823977706,56.6204979114424,162.12455401584896,0.1436712559821937
0.15512630448904355,139.773666628038,0.49252601675271324,56.356742384424926,161.4562389969291,0.14420969253095398
0.15575378265435355,139.171763795396,0.4945182599275725,56.114055162303664,160.84829244520714,0.14475275678099636
0.15639151567193554,138.418500711543,0.49654306225839534,55.81033948689414,160.0659798348581,0.1453043942877012
0.15704001974667656,137.539693435881,0.49860206269569807,55.45600439334722,159.13892960900358,0.1458650368498855
0.15770897422927554,136.736842278025,0.5007259931779499,55.13229480649968,158.30146941304253,0.14644302997394626
0.15835558549999956,135.988954521558,0.5027789839624985,54.83074646309218,157.52356503635212,0.1470014006677232
0.15899729987247554,135.237246234004,0.5048164270951099,54.527657681550416,156.73960322739975,0.1475552346503932
0.15961794738791454,134.449917572398,0.5067869829566286,54.21020676519087,155.91053744177844,0.14809059516869905
0.16021504958788654,133.560515187866,0.5086827824415397,53.851599723747576,154.95891975167362,0.14860537551188438
0.16084299566079954,132.648734043246,0.5106765112230385,53.483969566236794,153.98435379737438,0.14914646158210915
0.16149567043093455,131.737704530244,0.5127487536182171,53.116642466594385,153.0127734443881,0.14970854565438368
0.16217136992831355,130.72789259381,0.5148940995223955,52.70948629382419,151.92821402358962,0.15029012597952365
0.16286577894745555,129.753464856641,0.5170988481581713,52.31659703019765,150.88586398164912,0.15088745754484942
0.16352236475881654,128.72808594395,0.5191835081092425,51.90316425260064,149.77800696838085,0.15145192554265188
0.16417377473210554,127.729223220777,0.5212517347744351,51.50042280261729,148.69901194053165,0.15201162917341618
0.16479962991693056,126.671350709579,0.5232388249862545,51.07388860610226,147.54674242759535,0.1525490807378186
0.16544442784100255,125.565773069194,0.525286058395183,50.62811970149902,146.33993055103997,0.15310249739680087
0.16608516422750055,124.390832008325,0.5273203964223142,50.154383465756645,145.0503037708231,0.1536521249072624
0.16673343967247256,123.204534361091,0.5293786709601004,49.67606825439189,143.74685015836104,0.15420791219443153
0.16736191399600656,122.003249713322,0.5313740769373207,49.19171028441143,142.4219470990763,0.15474642861599452
0.16797985920470154,120.802859919949,0.5333360529749274,48.707713119723444,141.09530732082732,0.15527564042576755
0.16857021405665254,119.549291069239,0.5352104296298718,48.20227415911717,139.70174065510167,0.15578096224297927
0.16916068596552156,118.266950282108,0.5370851779405309,47.68523435374595,138.2730687188796,0.1562861289594909
0.16976084710053854,116.933725126246,0.5389906895442098,47.147677970902386,136.78449335829904,0.1567993237287077
0.17005297290084256,116.25875183784,0.5399181889601751,46.875528741017085,136.028898213606,0.15704902376836452