File: example/data/02 processed data/test_ID_060.csv
Strain,Stress_MPa,Displacement(mm),Force(kN),True Stress (MPa),True Strain
0.00032895807315452174,15.4781372773018,0.0010444418822656064,6.240784950208085,15.48322893551656,0.0003289039783104913
0.0003551966845812128,17.2185360262766,0.0011277494735453507,6.942513725794725,17.224651993186473,0.00035513361717258386
0.0003887049894862381,19.1553745973423,0.0012341383416188058,7.723447037648415,19.16282038702376,0.00038862946327272827
0.000446311663501891,21.1829350841352,0.0014170395316185037,8.540959425923312,21.192389275130452,0.00044621209607565354
0.000491016176307491,23.3009175962497,0.0015589763597762837,9.39492997480788,23.312358723712265,0.0004908956673110235
0.000532205828387691,25.5048496965676,0.0016897535051309189,10.283555397656057,25.518423526228265,0.0005320642570935773
0.000575180215678391,27.7409411323574,0.001826197184778891,11.185147464566503,27.75689717286103,0.0005750148629401629
0.0006003339956698909,29.9829012819796,0.0019060604362519035,12.089105796894176,30.00090103690799,0.0006001538673046141
0.0006732331743362909,32.2242324782678,0.0021375153285177234,12.992810535237577,32.245926900589694,0.0006730066545440847
0.000729975142006091,34.4088705446414,0.002317671075869339,13.873656603599414,34.433988164803495,0.000729708839740181
0.000773534562303691,36.6450342782329,0.002455972235314219,14.775277820983506,36.67338047878391,0.0007732355386376201
0.000817190178142691,38.8063990534205,0.0025945788156030436,15.646740098339146,38.83811126157604,0.000816856460044068
0.000858573056946591,40.9442896615309,0.002725969455805426,16.50873759152926,40.97944332547011,0.0008582046939288267
0.000916007180450091,43.099975477242,0.002908322797929039,17.377910112423976,43.13945536425638,0.000915587901894743
0.0009723582093089909,45.2031683180635,0.003087237314556046,18.225917465843203,45.24712198986435,0.0009718857752907327
0.000984561559233691,47.321805061151,0.0031259829505669687,19.080151800656083,47.368396291327755,0.0009840771963989749
0.001026678531824191,49.4194152978525,0.0032597043385418066,19.925908248094128,49.470153150594115,0.0010261518578728013
0.001070736260423591,51.4066463908846,0.003399587626844901,20.727159824804673,51.4616893512021,0.0010701634312168214
0.001118586156782091,53.4407527850906,0.003551511047783139,21.54731152294853,53.50053087136402,0.001117961005434102
0.001182269629541391,55.4637995865386,0.003753706073793916,22.363003993292363,55.52937275232873,0.0011815712991585842
0.001152717541415091,57.4599902730267,0.003659878193992914,23.167868078084368,57.52622541174395,0.0011520536726696395
0.001190746916824991,59.4527006540861,0.003780621460919346,23.971328903727517,59.52349377408688,0.0011900385399910395
0.001244980876545591,61.4232778968733,0.003952814283032251,24.765865648019318,61.499748703229656,0.0012442065304848066
0.001287122686479591,63.3421132047215,0.004086614529572701,25.53954004414371,63.42364227563686,0.0012862950541747441
0.001344728376184791,65.2808185982545,0.0042695125943867105,26.321226058816215,65.36860356744414,0.0013438250387201832
0.001391039047432591,67.2593491779886,0.004416548975598476,27.118969588565,67.35290955900008,0.0013900724488971718
0.0014249944436385909,69.1487424652762,0.004524357358552526,27.880772961999366,69.24727903907382,0.0014239801025623606
0.0015411861672940909,70.9637048059256,0.004893266081158738,28.6125657777492,71.07307308615243,0.0015399997587208034
0.001565678015710091,72.7545388893037,0.004971027699879539,29.334630080167255,72.86844907138581,0.0015644536197255974
0.001616026060028291,74.5620642075538,0.005130882740589824,30.063424288485695,74.68255844640271,0.0016147216949843723
0.001677341493741491,76.3506741715398,0.005325559242629233,30.784591825964846,76.47874032540285,0.0016759363275743635
0.0017203646336207909,78.1231715802675,0.005462157711746011,31.499262781163853,78.25757192172048,0.0017188865014259051
0.001771367131770491,79.8475424759738,0.0056240906433713085,32.19452912631264,79.98898178826839,0.0017698001112522721
0.001832077848608691,81.620283307114,0.005816847169332594,32.909298229428366,81.76981802015813,0.0018304016409700394
0.001891701698452891,83.4091736088763,0.006006152892587929,33.63057879909893,83.56695888425877,0.001889914684105491
0.001965414444074191,85.2118944863643,0.006240190859935556,34.357435856902086,85.37937117459472,0.0019634855440840973
0.002013288346534791,86.9537821133051,0.006392190500247962,35.05976494808462,87.12884514952093,0.0020112643976247743
0.002051237737958691,88.6805051120933,0.006512679818018844,35.75597966119602,88.86240991080047,0.002049136822324259
0.002100090965470191,90.4253818667753,0.006667788815367856,36.4595139686838,90.61528339428291,0.0020978888569850966
0.002149331347072191,92.1047725334136,0.0068241270269542055,37.136644285472364,92.30273620823462,0.00214702483882813
0.002189336913475491,93.7406805303175,0.006951144700284684,37.79624238982402,93.94591046249685,0.0021869438076552988
0.002226641780615291,95.4133811632024,0.007069587653453548,38.47067528500321,95.62583258413017,0.002224166487518819
0.002283021623675891,97.0479388242497,0.007248593655170953,39.12972893393748,97.26950136711865,0.0022804194895420004
0.002331906079655591,98.6357338229094,0.0074038018029065015,39.76992787739707,98.86574309028234,0.0023291914060968775
0.002391303049459491,100.26829154719,0.007592387182033884,40.42817515182701,100.5080634185309,0.0023884484342500383
0.002443143842502791,101.860934878354,0.007756981699946362,41.07032894295234,102.10979579419363,0.002440164218698109
0.0024948636454423913,103.567281253224,0.007921192074279592,41.75832780129992,103.82566749807998,0.002491756639768518
0.0025497790035482913,105.197507506357,0.008095548336265825,42.415635026563145,105.46573790222232,0.0025465338322074207
0.002595526655876991,106.758810663359,0.008240797132409446,43.04515245946635,107.03590600218548,0.0025921640937227376
0.0026361628506546913,108.346490379717,0.008369817050828645,43.685304921101896,108.63210937265481,0.0026326942678624936
0.002688638740476691,109.967943524551,0.008536428001013494,44.33907482909896,110.26360759772167,0.002685030816827028
0.0027358906929882913,111.518023722668,0.008686452950237825,44.964067164979745,111.82312484587129,0.0027321549562066556
0.0027739663739287912,113.019042666951,0.008807343237223911,45.56927800331464,113.33255369092274,0.0027701260295584155
0.0028192224198030913,114.553019460441,0.008951031182874814,46.18777744644982,114.87596990116003,0.002815255865593862
0.002858926474403591,116.099131131799,0.0090770915562314,46.81116967234136,116.43105001144696,0.002854847516555006
0.002923547386519691,117.624388797888,0.009282262952200018,47.426153563308446,117.96826927234905,0.002919282132950849
0.002985468652947791,119.087617233848,0.009478862973109237,48.01612726868751,119.44314958205389,0.0029810209914460863
0.003033946658682991,120.606798615393,0.009632780641318495,48.628661201726466,120.97271320906664,0.0030293535303783383
0.003087127193908891,122.115003729664,0.009801628840660728,49.236769503800524,122.49198827846212,0.003082371801240791
0.003149283010021391,123.591613609637,0.009998973556817916,49.83213860740563,123.98083857855896,0.003144334405265363
0.003207219861746091,124.860266261679,0.010182923061043838,50.343659356708976,125.26072058757636,0.0032020877025062
0.0032702140795776912,126.16979718889,0.01038292970265917,50.871662226560446,126.58239943607458,0.0032648785585474584
0.0033234006541708913,127.515175796975,0.010551797076992579,51.41411888134032,127.93895981563539,0.0033178903634441884
0.003375461167840191,128.88767132081,0.010717089207892607,51.9675090765506,129.32272665036675,0.0033697770861323756
0.0034353356909154914,130.123295390055,0.010907190818656685,52.46571270127018,130.570312590928,0.0034294484046112354
0.003498949829235791,131.349331068931,0.011109165707823635,52.96005028699298,131.80891578844486,0.0034928427457218514
0.003563635527803891,132.594276048578,0.011314542800777354,53.46201210278665,133.06679372148815,0.0035573008239726616
0.003622934647185791,133.821879128779,0.011502817504814886,53.95698166472369,134.30670705122617,0.0036163876276413846
0.003689629012522991,135.021006886049,0.011714572114760496,54.44046997645496,135.51918431035585,0.003682839027955518
0.0037593757978334912,136.135535234552,0.011936018158121333,54.88984780657137,136.6473198709379,0.0037523270051559444
0.003847248249099191,137.238204084414,0.01221501319088993,55.33444388683573,137.7661935247873,0.003839866516402034
0.003933249176911491,138.262592919624,0.012488066136693985,55.747477465192404,138.80641414942278,0.003925534175765348
0.004018036775968091,139.24053510986,0.012757266763698687,56.141783756295546,139.80000870063688,0.004009986024473191
0.004114965108169691,140.165565758162,0.013065014218438769,56.51475611369092,140.74234217062371,0.004106521793952585
0.004234231502661391,141.04137086362,0.013443685020949914,56.86788073221158,141.63857267930928,0.0042252923691424235
0.004341143399316891,141.799080231695,0.013783130292831127,57.17338914941943,142.41465037287202,0.004331747818205812
0.004459815568215191,142.50080515099,0.01415991442908323,57.456324636879174,143.1363324602856,0.00444990006072309
0.004583341547085191,143.072582592747,0.01455210941199548,57.68686530139559,143.72833310479314,0.004572870021411375
0.004710908927302791,143.626758742058,0.01495713584418636,57.910309124797784,144.30337132201552,0.004699847322380355
0.004847271566993991,144.095750155094,0.01539008722520592,58.099406462533906,144.79422138774547,0.004835561372587209
0.004977942571909991,144.44814836427,0.01580496766581422,58.24149342047366,145.1672029514461,0.004965593580543305
0.0051332823911406904,144.740793269357,0.01629817159187169,58.359487846204736,145.48378863472632,0.0051201520125452454
0.005306221189786191,145.032435499977,0.016847252277571154,58.47707799359073,145.8020096824333,0.005292192801401683
0.005441664065727491,145.237068671449,0.01727728340868478,58.559586088328246,146.02740000905004,0.005426911705884217
0.005605114169994291,145.412003682917,0.017796237489731873,58.63011988495214,146.22705456524736,0.005589463971098019
0.005770601556533791,145.530513028796,0.018321659941994785,58.677902853210554,146.37031163380314,0.005754015412799379
0.005958502509644891,145.618440529685,0.018918245468122527,58.71335522156899,146.4861083730317,0.005940820836330601
0.006145699315023091,145.67800223365,0.019512595325198313,58.73737050060769,146.5732954321913,0.0061268915236722355
0.006315050455573591,145.695282847335,0.020050285196446152,58.74433804404547,146.61535590965497,0.006295194076623446
0.0064850376404736905,145.662859926779,0.020589994508503965,58.73126512247729,146.60748905622322,0.006464100254946464
0.006695423508115291,145.636309599298,0.02125796963826605,58.72056003043695,146.6114063702243,0.006673108709446873
0.00689041902693719,145.544125788233,0.02187708041052558,58.683391517815544,146.54698580182318,0.0068667885767883215
0.00709269437067379,145.474422792471,0.022519304626889284,58.6552872699243,146.50622841208815,0.007067659520612085
0.007281089256318891,145.382392555577,0.023117458388812476,58.618180678408656,146.44093473207136,0.007254710094567857
0.007478523133952291,145.324036466728,0.02374431095029852,58.59465150338473,146.41084563536373,0.0074506976228577645
0.007683944797005791,145.276778137369,0.024396524730493384,58.57559694498718,146.39307688086342,0.007654573654725355
0.007897212083529791,145.20502633891,0.025073648365207087,58.54666661984851,146.3517412275029,0.007866192310309533
0.00810911709190089,145.120141320977,0.025746446766785325,58.51244098061793,146.29693753934203,0.008076414873686273
0.008307323800994991,145.063016437725,0.026375753068159095,58.48940822769072,146.26810188682222,0.008273007904483608
0.008518106392195891,144.978052442813,0.027044987795221954,58.4551507449422,146.21299091805426,0.008482032035985411
0.008727620502763692,144.882920783517,0.02771019509627472,58.416793659914056,146.14740393344752,0.00868975498071922
0.008944755892294692,144.76837173665,0.028399599958035645,58.37060748421728,146.0632894827593,0.008904988526967224
0.009156686077157692,144.637841387415,0.02907247829497567,58.317977647405726,145.96224469587727,0.009115017796294077
0.009369477315684691,144.504175781908,0.029748090477298893,58.26408367526531,145.8581043789183,0.009325856023882481
0.009586614914794891,144.360915748181,0.03043750235447378,58.20632122966657,145.74484825620596,0.00954095490669925
0.009808348941681092,144.226914556989,0.031141507889837466,58.15229194937796,145.64154246174596,0.009760559324602574
0.010030752655368392,144.095654269001,0.03184763968079464,58.099367801261195,145.54104213568684,0.00998077856326399
0.010244395653206591,143.959365686109,0.03252595619893092,58.04441624463915,145.43414238618215,0.010192277475987197
0.010451578674228992,143.829647349742,0.033183762290677044,57.992113811415976,145.33289422470443,0.010397338528595439
0.010666517620366892,143.707200511038,0.03386619344466488,57.942743246050526,145.24005589746258,0.010610031638752866
0.010882870068537791,143.594888613435,0.034553112467607484,57.897459088936984,145.15761312872115,0.010824077805830916
0.011085789266142591,143.494068218349,0.03519738092000273,57.856808305638324,145.08481321955912,0.0110247922900534
0.011307996892815692,143.388643538855,0.03590289013468982,57.81430107486634,145.01008187445743,0.011244539432363521
0.011521296106539791,143.272629030251,0.036580115138263834,57.767524024997215,144.92331541327096,0.011455431389735305
0.011739293924902791,143.154611174901,0.03727225821156636,57.71993922572008,144.83514523218832,0.011670922978194666
0.011967453090766592,143.016672334463,0.03799666356318392,57.66432228525549,144.72821765182323,0.01189640937059504
0.012167397815047892,142.879199394073,0.03863148806277705,57.608893195690236,144.61766745259624,0.012093970046794213
0.012388224628631792,142.754062082307,0.03933261319590594,57.55843783158618,144.52253147003228,0.012312118476021488
0.012617737881433692,142.624992689882,0.04006131777355197,57.50639705256042,144.4245974629843,0.012538797565400687
0.012837119499180592,142.460857549688,0.040757854409898375,57.44021776403421,144.28964460200908,0.012755422110554495
0.013059088180720591,142.321825748561,0.04146260497378788,57.38416014181979,144.18041902105261,0.012974553457547378
0.013267452986769991,142.200200683399,0.04212416323299472,57.335120915546476,144.08683516067526,0.013180211136653436
0.013487977341765392,142.085726577849,0.04282432806010512,57.288964956188714,144.00217563851928,0.013397824325265756
0.013722009110836292,141.970815588353,0.04356737892690522,57.24263284522392,143.91894041332924,0.01362871483160173
0.013947828525323792,141.847085096078,0.044284355567903035,57.192744710738644,143.8255439158151,0.01385145268687741
0.014169831463310691,141.72471676509,0.04498921489601144,57.14340579968429,143.73293211583677,0.01407037779487616
0.014389456572811592,141.620759252323,0.0456865246186768,57.10149013053664,143.65860501739292,0.014286910889722546
0.01461207449194809,141.507167111129,0.04639333651193519,57.05568977920721,143.57488037810137,0.014506346820766855
0.014865253642925992,141.398486308832,0.04719718031629002,57.01186967972106,143.50041067253858,0.014755848649421387
0.015098217991839092,141.284405789887,0.047936842124089114,56.96587241448244,143.41754854735015,0.014985374306598184
0.015332752258921391,141.175576809944,0.04868148842207541,56.92199256976943,143.3401869541812,0.015216393505538538
0.015561497543712192,141.062417063414,0.04940775470128621,56.87636655996852,143.25755952005642,0.015441659085743114
0.01579288568070299,140.935254990862,0.050142412036231994,56.82509481231557,143.1610293613134,0.015669475699035706
0.01601630512583439,140.823460330692,0.050851768774524186,56.78001920533501,143.07893184022421,0.015889397379715942
0.01624879073373219,140.709432885403,0.0515899105795997,56.734043339394496,142.99579101462004,0.016118191949268404
0.01645864346860179,140.581972940278,0.05225619301281068,56.6826514895201,142.89576151101468,0.016324668033415382
0.01667527625280589,140.456988139019,0.0529440021026587,56.632257617652456,142.7991472178742,0.016537770360736392
0.01690520929822029,140.313998369554,0.05367403952184942,56.57460414260418,142.68603587946146,0.01676390652601519
0.01712472692534679,140.163911621374,0.054371007987976054,56.51408916573801,142.56418033267846,0.016979751557663333
0.01734795064516539,140.038127211434,0.05507974329840011,56.46337289165019,142.46750173073934,0.017199192912836597
0.01756182713673059,139.92661475045,0.055758801159119624,56.41841106738144,142.3839817705253,0.01740940025931247
0.01778350170652129,139.806192969731,0.05646261791820509,56.369857005395545,142.29243664099047,0.01762722528146063
0.01801050661748659,139.685344550642,0.057183358510519915,56.321130922818845,142.2011483730372,0.01785023891739612
0.01823603668630289,139.606129810818,0.05789941647901167,56.28919153972183,142.15199231568084,0.018071754401835057
0.01844808635044619,139.513893082517,0.05857267416266664,56.252001690870856,142.0876574291902,0.018279984693917246
0.01865625890560149,139.438991136505,0.05923362202528473,56.22180122623882,142.0404010566835,0.018484365541039473
0.01887049077343049,139.343214709709,0.0599138082056418,56.183184170954675,141.9726895572287,0.018694651731051254
0.01910843925958869,139.24431527441,0.060669294649194086,56.14330791864212,141.9050568150741,0.01892816590897801
0.01933063947571239,139.152260385561,0.06137478033538683,56.106191387458196,141.84216256330473,0.019146176071088695
0.01955739381710489,139.061444930055,0.062094725369308025,56.06957459579818,141.78112437332774,0.019368605492052236
0.01980680099756959,138.942301672296,0.06288659316728344,56.02153603426975,141.69430419166343,0.019613198568994728
0.02004438973640519,138.848412074217,0.06364093741308648,55.983679748324306,141.6315437601136,0.019846145698657065
0.02029118938856709,138.742041782649,0.0644245263087005,55.940791246764086,141.55728282861725,0.020088066347290295
0.02052640802791769,138.656027952327,0.06517134548863866,55.90611047037825,141.50213815760685,0.020318580471325624
0.02075038437880519,138.532712476339,0.06588247040270646,55.856389670459876,141.40731950926153,0.02053802778255706
0.02099092131653349,138.405340502403,0.06664617517999383,55.80503329056889,141.31059611467697,0.02077364719053019
0.021230515265834488,138.289512776155,0.0674068859690245,55.75833155134569,141.22547038825397,0.021008287711003007
0.02144561828409219,138.171923733427,0.0680898380519927,55.710919649317766,141.13510606739277,0.021218896740520406
0.02167429469771209,138.051784621157,0.06881588566523589,55.66247955925051,141.043959684581,0.021442746954227203
0.02190682610037979,137.91382935651,0.06955417286870583,55.60685599654484,140.93508363306054,0.021670319426202886
0.02214756408204829,137.774655603296,0.07031851596050331,55.55074113924895,140.82602861715213,0.021905868914453105
0.02239390859637789,137.657219368275,0.07110065979349979,55.50339084928848,140.7399025564397,0.02214684667774481
0.02262520897947789,137.534340134908,0.0718350385098423,55.45384594239491,140.6460833223149,0.022373055207629392
0.02284878847818659,137.425790413436,0.07254490341824242,55.4100786946974,140.5658032300402,0.022591664194961374
0.02307492362618599,137.32319657924,0.07326288251314052,55.368712860749575,140.4919188524097,0.022812723413917105
0.02332874584073459,137.220182645073,0.07406876804433232,55.32717764249344,140.4213574102191,0.023060790029157535
0.02356097341363179,137.156734942086,0.07480609058828093,55.30159552864907,140.388281127557,0.02328769778262282
0.02379376206964259,137.071171792046,0.07554519457111522,55.26709646655294,140.33261064027306,0.023515102103896124
0.02402404801586789,136.99648206245,0.07627635245038054,55.236981567579846,140.2876921255233,0.02374001073205815
0.02425464017413299,136.930740601427,0.07700848255287224,55.21047461049537,140.25194644349216,0.02396516774859966
0.02449227279138089,136.84474896725,0.07776296611263432,55.17580278359521,140.19638788902395,0.02419714624902816
0.02473536766849889,136.752111988809,0.07853479234748396,55.13845155388779,140.13472575829593,0.024434401372332756
0.02496104795845979,136.656621624799,0.07925132726810984,55.099949839118956,140.0677141110167,0.02465460987653106
0.02519915080713749,136.521088117521,0.08000730381266152,55.045302728984474,139.96130360534892,0.024886887188217653
0.02544101383105949,136.40972211355,0.08077521891361387,55.000399956183365,139.88012374053181,0.025122777452354986
0.02568029924433269,136.296331677279,0.08153495010075629,54.95468093227889,139.79646226065637,0.0253560990144035
0.02591720753758879,136.196952389175,0.0822871339318444,54.91461120331536,139.72679707023238,0.025587049084800778
0.02615481380533489,136.07061055724,0.08304153383193827,54.86367017667917,139.62951204074287,0.025818626014203493
0.02638831120903639,135.961415911847,0.08378288808869053,54.81964289565672,139.54920806735007,0.026046146110481234
0.02662754007532639,135.839059515784,0.08454243973916128,54.770308796764105,139.45611951683517,0.026279197274916354
0.02686598428939969,135.756687636387,0.08529950011884402,54.737096454991246,139.40392467360712,0.026511430016160256
0.02711474154902909,135.674434762112,0.08608930441816735,54.70393209608356,139.3532119954973,0.02675364968036295
0.02736051387501299,135.572482911121,0.08686963155316624,54.66282510976399,139.2818157108807,0.026992905253295667
0.02760240151394949,135.466299120351,0.08763762480678962,54.62001180532553,139.20549430027972,0.02722832326326776
0.027852287688951288,135.397876336897,0.08843101341242034,54.592423739036875,139.16901694110533,0.027471467690187493
0.02809544876622989,135.293291591427,0.0892030498327799,54.55025516966336,139.09441733374854,0.027708011717159378
0.02833170275000499,135.209395608047,0.08995315623126583,54.51642830916455,139.040108013422,0.02793778303158717
0.02857907124257619,135.121927953713,0.0907385511951794,54.481161350937086,138.98358715913642,0.02817830731381808
0.02880169677962399,135.011540113034,0.09144538727530616,54.4366529735753,138.90010155311964,0.028394723780207822
0.02903780419365109,134.899593255198,0.0921950283148422,54.391516000495834,138.8167812299456,0.02862419494640062
0.02927201150732399,134.755371341609,0.09293863653575365,54.33336572493675,138.69993212219427,0.028851767406967238
0.02950146670625019,134.623540758174,0.09366715679234434,54.28021163369576,138.59513266372875,0.029074672162934186
0.02974333048953379,134.522633471203,0.09443507430426978,54.23952581558905,138.52378461685942,0.029309577488153674
0.02998098246699909,134.432293363577,0.0951896193327221,54.203100684194254,138.46270559390888,0.029540338446816763
0.03020449095482729,134.318913923704,0.09589925878157664,54.157386094037456,138.37594834437476,0.029757317443697112
0.03044088033121449,134.211715038637,0.096649795051606,54.11416350357844,138.2972377951752,0.02998674981543651
0.03067336937024329,134.122693794955,0.09738794775052244,54.078270138125866,138.2366887226597,0.030212345305883993
0.03092484498428399,134.052211978868,0.09818638282510167,54.049851869879575,138.1977558541149,0.030456307115258006
0.03117247021132379,133.964637113557,0.09897259292095302,54.01454168418618,138.14064577335014,0.030696475439425178
0.03142429553940059,133.871057182199,0.09977213833759688,53.97681025586264,138.07786084726442,0.030940658241909478
0.03166983598694349,133.77377107344,0.10055172925854558,53.937584496811006,138.01036446269077,0.03117868950277148
0.03192731154367129,133.699307559942,0.10136921415115634,53.90756080816862,137.96796700558141,0.03142823002803548
0.03219454105688969,133.620930110627,0.10221766785562475,53.8759590206048,137.92279463113337,0.03168715806988027
0.03245193905043899,133.564652919883,0.1030349064851438,53.85326805729683,137.89908489573207,0.03193649663448464
0.03269616603257619,133.50590213384,0.1038103271534294,53.82957974036429,137.8710332763369,0.032173019121830376
0.03294637021017789,133.431845080398,0.1046047254173148,53.79971993641648,137.82794004624392,0.03241527224591692
0.03318700217724049,133.353918639849,0.10536873191273856,53.76829999558712,137.77953542809323,0.03264820199901646
0.03344043414882129,133.263426647399,0.10617337842250758,53.73181362423128,137.71981349064762,0.03289346340259264
0.03368611161083209,133.102739840174,0.10695340436439188,53.667024703558155,137.58645359013764,0.03313116289290345
0.03392552903622239,132.98361707357,0.10771355469000608,53.61899440406342,137.49515663594127,0.03336275128383115
0.034178482386748386,132.861741922459,0.10851668157792613,53.56985434313547,137.4027546286285,0.033607374717072654
0.03443097862218579,132.761129426568,0.10931835712543987,53.52928738479223,137.3322250357114,0.03385149642438433
0.03469577060054369,132.649641789602,0.11015907165672621,53.48433556956752,137.25202333137833,0.034107442059327205
0.03495790544593089,132.538586218815,0.11099134979083056,53.4395579634262,137.1718575837897,0.034360754823508616
0.03521765962597069,132.439036431784,0.11181606931245694,53.399419489295305,137.1032293380301,0.03461170376309204
0.03548733955838459,132.39318182478,0.11267230309787106,53.38093091175129,137.0914636234109,0.03487217537449465
0.03575223416352439,132.321933138934,0.11351334346918993,53.352203441618194,137.0527378774874,0.035127959022069534
0.03600953577076529,132.232082504006,0.11433027607217978,53.31597566561523,136.9936984089768,0.03537634820686656
0.03627315897783089,132.117320442975,0.11516727975461308,53.26970360260753,136.90963301112805,0.03563077605028367
0.03651925247769179,132.025211714006,0.11594862661667144,53.23256536308722,136.84667375401048,0.035868227229337746
0.03677317818151649,131.940582835516,0.11675484072631485,53.19844299928006,136.7924573974996,0.03611317647174988
0.03701598636377119,131.818207199666,0.11752575670497352,53.14910114290534,136.6975881598656,0.036347345101343714
0.03726377320823419,131.695358374547,0.11831247993614354,53.09956849661735,136.60282434159325,0.036586258723769256
0.03751235834599049,131.575223767203,0.1191017377485198,53.05113022293625,136.5109207106122,0.03682588471055902
0.03776556441812479,131.464179521299,0.11990566702754621,53.006357182987756,136.42899846168655,0.037069906073301136
0.03802868386092559,131.370498901721,0.12074107125843873,52.968585157173905,136.36634607310663,0.03732341813927609
0.03829724085643569,131.273119863226,0.1215937397191833,52.929321928852715,136.3005181526037,0.03758210295731038
0.03855463856495619,131.168187284304,0.12241097744373589,52.88701311303137,136.22532933627082,0.037829975915790334
0.03882515110568169,131.082617157886,0.12326985476053935,52.85251123805964,136.17191957636913,0.03809041220538888
0.039095804712466486,131.019557785757,0.12412917996208109,52.82708569921722,136.1418728304627,0.03835091644406811
0.03936553210272369,130.924495155064,0.12498556442614772,52.7887564465218,136.07840757212355,0.03861046170189298
0.03962765791332379,130.805057606771,0.125817813874803,52.74059922705006,135.9885556829447,0.038862627811188315
0.03987341624759449,130.653560941964,0.12659809658611249,52.67951577179989,135.86316476163339,0.03909899059884793
0.04012241608375879,130.521483369716,0.12738867106593416,52.62626209466949,135.75832063334516,0.03933841399910994
0.04038104800728079,130.39477244671,0.1282098274231165,52.57517225051347,135.66025001277904,0.03958703836270099
0.04063362031103739,130.268748180757,0.1290117444875437,52.52435926648123,135.56203903272802,0.03982977793473949
0.04088882354627029,130.142491520074,0.12982201475940816,52.473452580893834,135.4638648917103,0.040074986183408455
0.04114211524284839,130.040181449275,0.13062621589604362,52.43220116034768,135.39030958066198,0.04031829831975448
0.04141280412998539,129.936042879161,0.1314856531127036,52.390212488877715,135.31705877234108,0.0405782567834122
0.04168750946378119,129.874288246157,0.13235784254750527,52.3653130208505,135.2884238665205,0.040842003405306
0.04196685974595669,129.80749787261,0.13324477969341247,52.33838314223636,135.2551109298034,0.041110138358950006
0.04223798041051219,129.723793958617,0.1341055878033762,52.304633724114375,135.2030650266184,0.04137030536447765
0.04251160849087749,129.657255704491,0.13497435695853602,52.277805500050775,135.1691941970019,0.041632809871871
0.04277538173294859,129.565085079719,0.13581183700211177,52.2406423041427,135.10728105326595,0.041885794947512475
0.04303691808821639,129.45435128264,0.13664221493008705,52.19599443716045,135.02566759495417,0.04213657144994358
0.04329846646294299,129.357637174317,0.137472631019844,52.15699930868462,134.95862448923472,0.04238729659992036
0.04356058424268769,129.267331979865,0.1383048549705334,52.120588254281564,134.89829248440137,0.04263850453946415
0.04382565108413109,129.152773469526,0.1391464421921162,52.074398262912894,134.81297785614927,0.042892474636978664
0.04409509280790169,129.0489063994,0.14000191966508788,52.03251906023809,134.73932990383977,0.04315057037749436
0.04437460323550819,128.91403192522,0.1408893652727385,51.97813767224871,134.63454094339127,0.04341824046129275
0.04465202435954969,128.802462542621,0.14177017734157024,51.93315289718478,134.5537532376441,0.043683838919452864
0.04493838258978939,128.704928506524,0.1426793647225813,51.89382717383048,134.48871982494165,0.0439579196494179
0.04521689158114469,128.625655124455,0.14356363077013437,51.86186414618025,134.44170742677116,0.044224415633180705
0.04550027958364609,128.51154946865,0.14446338767807632,51.81585674575968,134.35886089920115,0.04449550730272407
0.04578535474777219,128.408877768063,0.1453685013241767,51.774459516083006,134.2881237894371,0.044768138799074424
0.04606507834797549,128.303001297697,0.14625662375482218,51.73177012323143,134.2132891047558,0.04503558010122959
0.04634178335470189,128.205260770193,0.1471351621511785,51.69236114254182,134.14652118973837,0.045300064999844715
0.04662957317646769,128.096447620059,0.1480488948352849,51.64848768040779,134.06953029800408,0.04557507098373589
0.04691269953483149,127.97533965155,0.14894782102308995,51.59965694750497,133.97900830849116,0.045845546878854254
0.04719433284107159,127.84392638379,0.1498420067704023,51.546671117944136,133.87743519725603,0.04611452387342415
0.04747445423259649,127.723993465726,0.15073139218849385,51.49831416538073,133.78762034791905,0.04638198514932937
0.04774509332424129,127.579864169032,0.15159067130446607,51.440201232953704,133.67117669007646,0.04664032475241841
0.04801549525825799,127.443325500191,0.1524491974449691,51.38514884167701,133.56257989144203,0.04689837134131801
0.04829062662222949,127.331272682746,0.15332273952557862,51.33996914568319,133.48017962920176,0.04716086293324682
0.04855566732440729,127.20863128756,0.15416424375499313,51.29052013514419,133.38533126915195,0.04741366229613237
0.04882999633082579,127.102574088333,0.1550352383503719,51.24775787241587,133.30899231470482,0.047675253678906425
0.04911253622222199,126.959331276561,0.15593230250555482,51.1900023707094,133.1946260326302,0.04794460318559714
0.04939021062806419,126.800158030541,0.15681391874410378,51.12582371791413,133.06284454334124,0.048209243685000326
0.04967485166979409,126.673503747591,0.1577176540515962,51.0747567110287,132.96599125674567,0.048480451136915105
0.04995423769770289,126.542992622501,0.15860470469020665,51.02213462539241,132.8643513549441,0.04874658007461429
0.05023222720152689,126.410344598386,0.15948732136484786,50.96865094206924,132.76021774887545,0.049011308478585695
0.05050304073356239,126.243122770652,0.16034715432906058,50.90122710112689,132.61878434227037,0.04926913585709388
0.05078843228633239,126.093619050591,0.16125327250910532,50.8409472011983,132.49771628348054,0.049540770285909703
0.05106027633864479,125.964360857979,0.16211637737519718,50.78883029793714,132.39613593220818,0.0497994416666924
0.05133506700153789,125.842867514969,0.1629888377298828,50.739844182035505,132.30301955051561,0.050060848889961346
0.05160916312136459,125.706438043652,0.16385909291033257,50.68483581920049,132.19404211005255,0.050321527340157594
0.05189100826096649,125.563664698328,0.1647539512285686,50.62726960636586,132.07928986046616,0.05058950463354975
0.05217325185914099,125.414231414659,0.16565007465277265,50.567018106390506,131.95749969697658,0.05085778883495642
0.05247016288428529,125.297202734641,0.1665927671576058,50.51983214260726,131.87156737107293,0.05113993736903499
0.05274275526825939,125.152233034659,0.16745824797672354,50.46138035957451,131.75310663288218,0.05139890631526093
0.05302331588056789,125.029586524505,0.16834902792080306,50.41192928668042,131.65906978521065,0.05166537524342225
0.05330945676634729,124.894268815684,0.16925752523315263,50.357369186483794,131.55231443947827,0.05193707104691098
0.05356514930898369,124.76794855421,0.17006934905602322,50.30643685705747,131.45116234749185,0.05217979317489571
0.05385650536318409,124.631188017775,0.1709944045281095,50.25129500876688,131.3433882636743,0.052456297931701965
0.05413762489216059,124.489062677868,0.17188695903260987,50.19399007171638,131.22860485629909,0.052723015496621325
0.05441780394908799,124.355272342229,0.17277652753835435,50.14004580838673,131.12241317258386,0.0529887700077373
0.05470339651245669,124.195992839401,0.17368328392705,50.07582431284648,130.98993548095297,0.05325958665407481
0.05499262951742719,123.996874338394,0.17460159871783132,49.995539733240456,130.81578851020427,0.05353378066422046
0.05526973279582819,123.800780785545,0.1754814016267545,49.91647481273175,130.64321685947698,0.053796405146315625
0.05558566034511929,123.597818487912,0.17648447159575373,49.83464041432612,130.46808484577878,0.05409574119053405
0.05586967718846639,123.409824729024,0.17738622507338078,49.75884133074247,130.30469179851977,0.05436476591486645
0.05615942509674139,123.229347438778,0.1783061746821539,49.6860728873153,130.1498367459864,0.054639144624685686
0.05644296855074949,123.052277217633,0.1792064251486296,49.61467817414963,129.99771303072598,0.05490757512212639
0.05672645131901469,122.898955150647,0.18010648293787163,49.552858716740865,129.87057674715794,0.05517587615591969
0.05701523080118189,122.71746942964,0.1810233577937525,49.47968367403085,129.71423427250792,0.05544911624614146
0.05731370395256379,122.552456986437,0.18197101004939004,49.41315065693139,129.57639222481694,0.05573144994404282
0.05759587191158419,122.389515370012,0.1828668933192798,49.34745259718884,129.43864622058408,0.055998286847062005
0.05789812750507999,122.214212205999,0.18382655482862897,49.2767703614588,129.29018624723486,0.0562840409977578
0.05817840880238399,122.017808845651,0.18471644794756914,49.19758052656649,129.11661080984445,0.05654894757758512
0.05846548388799669,121.791948088555,0.18562791134438947,49.106513469305376,128.91257326721416,0.056820202547175784
0.05875996412636869,121.551871396875,0.18656288610122057,49.00971454722,128.69425499964836,0.057098378157191335
0.05905678105903939,121.343165146826,0.18750527986245005,48.925564187200244,128.50930188391297,0.057378682801385784
0.05934645524606209,121.137509278994,0.1884249954062471,48.84264374129039,128.32659105203925,0.0576521663231853
0.05964077515208109,120.926778252518,0.18935946110785745,48.75767699141526,128.138945044142,0.0579299593213587
0.05992050378609239,120.680727372303,0.19024759952084333,48.65846927651257,127.91197735372346,0.058193908883388296
0.06021798376801329,120.42664774456,0.19119209846344218,48.55602437060659,127.67849766367816,0.05847453204609146
0.06054025244380479,120.179994142818,0.1922153015090802,48.456573638384214,127.45572132691919,0.05877845040205434
0.06083922360430869,119.930418439747,0.19316453494368008,48.355944714905995,127.22689198416107,0.059060315260142104
0.06112805127141489,119.693789924615,0.19408156278674227,48.26053609760477,127.01043805199684,0.059332541577964894
0.06142498098118059,119.432064593172,0.19502431461524836,48.155008443966956,126.76817688935073,0.05961232701294886
0.06172554361700559,119.16501806844,0.19597860098399275,48.04733528519501,126.52054358884477,0.05989545591440976
0.06202410091929489,118.873869346182,0.19692652041876127,47.92994412038059,126.24691421517666,0.06017661645988553
0.06232288472888219,118.585738282861,0.19787515901420094,47.81376967564955,125.97634358035313,0.06045791119523343
0.06259490224878689,118.288973889076,0.19873881463989837,47.69411427207545,125.69326064677202,0.060713937591226355
0.06289010211382148,117.972746338925,0.1996760742113832,47.56661132385456,125.39206440282797,0.06099170936221212
0.06319243131913649,117.668916641684,0.20063596943825834,47.44410718992699,125.10470157496083,0.06127610961723388
0.06348955794719378,117.364003275166,0.20157934648234024,47.321166120546934,124.81539196201928,0.06155553703655663
0.0637788803956626,117.024253302049,0.20249794525622872,47.18417893138616,124.48792915679212,0.061827550145046456
0.0640749144889847,116.72468099429,0.2034378535025264,47.06339137689773,124.20380494775316,0.06210579679520976
0.0643673520579509,116.425819229076,0.2043663427839941,46.942890313163446,123.91984092402927,0.062380587025983286
0.064659394650173,116.091834465993,0.20529357801429923,46.80822765668838,123.5982622063922,0.06265493077906709
0.06494797526963919,115.738000264803,0.20620982148110442,46.66556170676858,123.25494904375891,0.06292594845613624
0.06523108175438379,115.40436116092,0.2071086845701685,46.53103842008295,122.9323124786204,0.06319175379815943
0.06551460445992659,115.082315029878,0.2080088691602669,46.40118942004681,122.62188737939313,0.06345787913545385
0.06580905358976699,114.756346140871,0.20894374514751018,46.26975876399919,122.30835267382145,0.06373418548676907
0.06611057301881049,114.419780446377,0.20990106933472327,46.13405547597921,121.98413769637348,0.06401704739890737
0.06640228372426839,114.08027358283,0.21082725082455211,45.99716630859706,121.65546427661924,0.06429063140695211
0.06670200049731739,113.775215323508,0.2117788515789827,45.874166818438425,121.36424979259901,0.06457164605517003
0.06698819510472578,113.43889724351,0.21268751945750436,45.738563368583236,121.03796422452318,0.06483990862647926
0.06728087529775278,113.009668823672,0.21361677907036508,45.56549846970455,120.61305825923782,0.06511417600815149
0.06757931480974329,112.596922034521,0.21456432452093493,45.39907896431887,120.20614487530001,0.06539376294814639
0.0678788027297147,112.215500058986,0.21551519866684413,45.24528962378316,119.83255385070618,0.06567425350843888
0.06816565041793539,111.843722316128,0.21642594007694485,45.095388837862814,119.4676223929698,0.0659428318982962
0.06844592379417229,111.457431078954,0.217315808046497,44.93963621103426,119.0862379128783,0.06620518503840588
0.06875821370623579,111.059115882067,0.21830732851729862,44.77903552364942,118.69534230591177,0.06649742657846876
0.06907175914001688,110.671444338766,0.2193028352695536,44.62272635739045,118.31571568581103,0.06679075714265016
0.06937140751364379,110.332292895092,0.22025421885581903,44.48598049530109,117.98619934743213,0.06707100623251204
0.06967069804921469,109.899706584926,0.22120446630625662,44.311561695042165,117.55649585810167,0.067350842273837
0.06996605183790269,109.470359332029,0.22214221458534103,44.13844888267409,117.12956816776757,0.0676269207161982
0.07025574668518018,109.041315379516,0.22306199572544708,43.96545836102086,116.70209441103812,0.06789763550776477
0.0705645447899376,108.538456841806,0.22404242970805185,43.76270579861618,116.19742364105034,0.06818612128877952
0.07084548795453029,108.05655051049,0.22493442425563365,43.56840116582956,115.71186955808902,0.0684485121078274
0.07112911027327239,107.637825184299,0.2258349251176398,43.39957111430936,115.29400792140821,0.06871333534208438
0.07142924347916679,107.197020857156,0.22678784804635455,43.22183880960531,114.85402296020312,0.06899349873397707
0.07172781886802249,106.815732465183,0.22773582490597138,43.06810332996179,114.47739197570078,0.06927213010078903
0.07202933093317869,106.341045965662,0.22869312571284234,42.87670973335492,114.00072035730305,0.06955342321943585
0.07233184669875099,105.844295356471,0.2296536132685344,42.67641988772911,113.50020870213258,0.06983557323290816
0.0726291715781601,105.434108241113,0.2305976197606583,42.51103244281676,113.0917001787471,0.07011280426767288
0.07293754323805149,105.019405109737,0.23157669978081347,42.34382414024595,112.67926251076288,0.07040025434777074
0.07323902400915559,104.57737004626,0.232533901229069,42.16559560265203,112.23651456189239,0.07068120119779982
0.07352950217242739,104.1117233529,0.23345616939745695,41.97784685588928,111.76700654135222,0.07095182018769268
0.07382239914524628,103.618101805707,0.23438611728615694,41.77881864806106,111.26743867588065,0.07122461848819998
0.07411136661932818,103.103759211122,0.23530358901636697,41.571435713924394,110.7449197098484,0.07149368402497878
0.07440834747789829,102.59740302089,0.23624650324232704,41.36727289802285,110.23150623519835,0.07177013562885544
0.07470088669776169,102.066797863275,0.23717531526539334,41.153332898472485,109.69127816606284,0.0720423779300081
0.07496832293150839,101.510011610029,0.23802442530753912,40.928836681163695,109.12004694119081,0.072291194105007
0.0752477585267673,100.980024221645,0.23891163332248613,40.71514576616726,108.57854470030244,0.07255110807294876
0.07553492185002149,100.452346577526,0.23982337687381822,40.50238614005848,108.0400067259107,0.07281813953789458
0.07581960985772988,99.8928796275328,0.24072726129829236,40.276809065821226,107.46671878845753,0.07308279885385055
0.07611542663626189,99.4413815451446,0.2416664795701315,40.094765039002304,107.01040472675257,0.07335772981168943
0.07640537769405999,98.9937804581765,0.24258707417864045,39.91429228073677,106.55743764344635,0.07362713585781794
0.07671258417920108,98.5219440750238,0.24356245476896343,39.7240478510496,106.0798170033776,0.07391249550152126
0.0770509086219543,98.0349047249232,0.24463663487470488,39.52767358508903,105.58858321064525,0.07422666597257523
0.07737152894416699,97.4785553399816,0.24565460439773018,39.30335351308058,105.02062020590456,0.07452430520895614
0.07766954309932929,96.9167781764592,0.24660079934037046,39.07684496074835,104.44426005608383,0.07480087920184006
0.07796361344344109,96.3522444519884,0.24753447268292544,38.84922496304172,103.86421359285117,0.07507371815409274
0.0782460578915597,95.7471752959713,0.248431233805702,38.60526107933563,103.23901431713318,0.0753357005146106
0.0785050310872507,95.1444978019155,0.24925347370202094,38.362261513732335,102.61381955963573,0.07557585172933261
0.07878370855276338,94.5709593408785,0.25013827465502375,38.13101080624221,102.02161023914552,0.07583421071665059
0.0790413936579317,93.9879072743688,0.2509564248639331,37.895924213025495,101.41684245232736,0.07607304852248505
0.07932789734524419,93.3896497694588,0.2518660740711503,37.65470678704579,100.79805431947874,0.07633853014343799
0.0796224201469932,92.789843023706,0.25280118396670337,37.41286470715826,100.17799489031307,0.07661136903295739
0.07992095358828769,92.1378752910653,0.2537490276428134,37.14999131735753,99.50162214592596,0.07688784733557158
0.08022648032164958,91.4611894530778,0.2547190750212374,36.87715158748097,98.79879876892981,0.07717072315284518
0.0805526793855204,90.739471563734,0.2557547570490272,36.58615493449755,98.04877912421901,0.07747265041355886
0.0808704312078573,90.0233674688643,0.2567636190849469,36.29742176344608,97.30359601485473,0.07776667135103148
0.0811893942738738,89.2881235555472,0.2577763268195493,36.00097141759664,96.53737222287288,0.07806172615439194
0.08149851550448249,88.5479177480556,0.2587577867267319,35.702520436016016,95.76444159553515,0.07834759378357342
0.08181419498440098,87.7208457563881,0.2597600690754731,35.36904500897568,94.8976561352978,0.0786394420037854
0.08214086764818729,86.9457662548711,0.26079725478299465,35.05653295396403,94.0875669333827,0.07894136386150699
0.08245662658168619,86.1481634384558,0.26179978939685367,34.73493949838538,93.25165038179861,0.0792331122688485
0.08279972236876638,85.2999966782633,0.26288911852083324,34.39295866067577,92.36281272128019,0.07955002235676306
0.0831186355148688,84.262887309193,0.2639016677597084,33.97479616306662,91.26670352687628,0.07984450543111
0.08344916587433199,83.2697544154182,0.26495110165100405,33.57436498029662,90.21854596394532,0.08014962430328704
0.08378723340346159,82.2320306714543,0.2660244660559905,33.155954766730375,89.12202501856405,0.08046160460408328
0.08416648634092319,81.1334367772214,0.2672285941324311,32.713001708575675,87.96215307552357,0.08081147640981093
0.08455773580352559,79.8748733131286,0.2684708111761937,32.205548919853456,86.62891174808021,0.08117228712318053
0.0849821428113666,78.5554995610963,0.2698183034260889,31.673577423034025,85.23131424341562,0.08156352861861281
0.08542059190126369,76.9382250008278,0.2712103792865122,31.02149232033377,83.5103337202311,0.08196755418386743
0.08588649097445349,75.2540102156613,0.2726896088438898,30.342416918954637,81.71731308484011,0.08239669576776804
0.0863652198816097,73.2683558310055,0.27420957312411076,29.541801071061414,79.59619349271429,0.08283746320969396
0.08687410511587719,71.0055775434562,0.27582528374291004,28.62944886552154,77.17412355077998,0.08330578277092689
0.08734788977213719,68.4978510970517,0.27732955002653553,27.618333562331244,74.48099384430523,0.08374160272387837
0.08759529369652219,67.3191652642668,0.27811505748645793,27.143087434552378,73.21600731699496,0.08396910652934098
0.08784159736401918,65.9279863981873,0.2788970716307609,26.58216411574912,71.7192060343974,0.08419554717633164
0.08807610088054459,64.6236370905594,0.27964162029572903,26.05625047491355,70.31543507021522,0.0844110916499324