File: example/data/02 processed data/test_ID_069.csv
Strain,Stress_MPa,Displacement(mm),Force(kN),True Stress (MPa),True Strain
0.0004282357690355199,23.0730727529062,0.0013596485666877757,9.303062933971779,23.082953467960554,0.0004281441022676191
0.00046853754805699393,25.4908257727847,0.0014876067150809556,10.277900951586792,25.50276918179023,0.0004684278186136928
0.0005195361771825071,28.0835478668612,0.0016495273625544598,11.323286499918437,28.09813828596167,0.0005194012649887094
0.0005578122292013464,30.6636255151963,0.0017710538277142746,12.363573807727148,30.68073006050033,0.0005576567097909128
0.0006021351658942421,33.2652712594861,0.0019117791517142186,13.412557371824796,33.28530144911445,0.0006019539552537936
0.0006625985362834199,35.9473115148142,0.002103750352699858,14.493956002773087,35.97113015080724,0.0006623791147934449
0.0007176338245093199,38.6342214473874,0.0022784873928170905,15.577318087586598,38.66194667148163,0.0007173764484834941
0.0007653439583939199,41.3222122546458,0.002429967067900696,16.661115981073184,41.353837960142364,0.0007650512320546036
0.0008145745463400199,44.0612160962084,0.002586274184629563,17.765482329991226,44.097107241321154,0.000814242960549503
0.00086619561294452,46.6700725180651,0.002750171071098851,18.81737323928385,46.71049793013605,0.0008658206820179951
0.0009299949741484199,49.3688011193333,0.002952734042921233,19.905500611315187,49.41471385625401,0.0009295627967501753
0.0009915174789823199,52.050224512556,0.0031480679957688654,20.986650523462583,52.10183321994515,0.0009910262502078606
0.0010423287777127199,54.6387047828482,0.0033093938692378855,22.030325768444396,54.695656277220316,0.0010417859302566655
0.0010985492693386199,57.229676828251,0.0034878939301501177,23.075005697150804,57.29254644791517,0.0010979463056399583
0.00115464173770672,59.7787368399918,0.003665987517218836,24.102786693884696,59.847759864574634,0.0011539756516133013
0.00121282412679732,62.2853262386565,0.003850716602581491,25.113443539426303,62.36086738506418,0.0012120892497403718
0.00127374691511152,64.7968814651695,0.004044146455479076,26.126102606756344,64.87941629304461,0.0012729363877079188
0.0013289546716955198,67.2261460451373,0.004219431082633275,27.105582085399362,67.31548654598407,0.0013280723930214975
0.00138495243195042,69.6654407595449,0.004397223971442583,28.089105714248504,69.76192408114773,0.0013839942699016335
0.00143400524800592,72.0611054312594,0.0045529666624187955,29.05503770988379,72.16444143462495,0.0014329780443733163
0.00148653370052462,74.4381001930385,0.0047197444991656685,30.01344199783312,74.54875493757847,0.0014854299030558312
0.0015436563679897199,76.7454272305961,0.004901108968367361,30.94375625937635,76.86389579805471,0.0015424661551941997
0.0016093767740986199,79.054620232865,0.005109771257763118,31.87482287789117,79.18184890255296,0.001608083115101893
0.0016645459460739199,81.3289926529245,0.005284933378784695,32.79184983765916,81.46436849794321,0.0016631621248805364
0.0017186166309906198,83.5623490406764,0.005456607803395218,33.69233913320072,83.70596068346234,0.001717141499310498
0.0017730440608321198,85.7760538827601,0.00562941489314198,34.584904925528875,85.92813860565853,0.0017714740737082516
0.00183616314324662,87.9401761029963,0.005829817979808018,35.457479004728114,88.10164861316724,0.0018344794564030928
0.00189688569293682,90.088376679763,0.006022612075074403,36.323633477280445,90.25926403258676,0.0018950888771481452
0.00195340283102652,92.2091335367461,0.006202053988509201,37.17872264201603,92.38925511924329,0.0019514974206689855
0.00200471515882612,94.3134651592979,0.006364970629272931,38.027189152228914,94.50253679258417,0.002002708398932453
0.00205450547321472,96.3859572959557,0.006523054877456735,38.86281798172934,96.58398277276127,0.002052397863082226
0.00211594966804802,98.4266198294366,0.0067181401960524625,39.68561311522884,98.63488560299179,0.0021137141994198643
0.00217460273705602,100.408391393418,0.006904363690152863,40.48466340982614,100.6267397561655,0.002172241710767194
0.0022343984589192198,102.42575934875,0.0070942151070685225,41.29806616941601,102.65461930759248,0.0022319059029010154
0.00229566335991472,104.389967296971,0.0072887311677292356,42.09003481413871,104.62961152003734,0.0022930323506220704
0.0023561613075707196,106.361229161323,0.0074808121515370345,42.88484759784543,106.61183337409857,0.002353389911900172
0.00241496080264492,108.275550831706,0.0076675005483976206,43.65670209534386,108.53703204284936,0.0024120494710315166
0.00247778646262312,110.184776298394,0.007866972018828406,44.426501803512465,110.45779064549332,0.0024747218110700866
0.0025423691089800195,112.13559523949,0.00807202192101156,45.21307200056237,112.42068531284397,0.00253914275586695
0.0026011837557789203,113.990639184036,0.008258758424598072,45.96102571900332,114.28714978299237,0.002597806532564272
0.0026586486927967197,115.824805429117,0.008441209599629585,46.70056154901998,116.13274289666455,0.002655120738038891
0.00270992984753032,117.637996572953,0.008604027265908766,47.43164021821465,117.95678729106972,0.0027062646078428593
0.0027738134429329203,119.448161055446,0.008806857681312022,48.16149853755583,119.7794879703152,0.0027699735216028276
0.00283192163974212,121.183900932485,0.00899135120618123,48.86134885597795,121.52708424392407,0.0028279193040754184
0.0028984675419662202,122.845231107335,0.00920263444574275,49.53119718247747,123.20129402238496,0.0028942750841020443
0.0029634035560341197,124.46310263495,0.00940880629040833,50.183522982411844,124.83193703589346,0.0029590213311155664
0.00303439323918082,126.062181716438,0.009634198534399103,50.8282716680678,126.44470394835474,0.003029798759973772
0.0031136889459301197,127.615033089342,0.00988596240332813,51.45438134162269,128.01238660720682,0.003108851455529922
0.0032047145878336203,129.101377386207,0.010174968816371744,52.05367536211866,129.51511045362597,0.0031995904347522242
0.0032807621669023197,130.565603354165,0.010416419879914865,52.64405127239933,130.99395804594815,0.0032753922085365867
0.0033833410687034203,131.996126358035,0.01074210789313336,53.22083814755972,132.4427142732519,0.003377630447337926
0.00347229488772372,133.344948732584,0.01102453626852281,53.76468332897787,133.80796171637192,0.00346628039054738
0.0035816663303528196,134.566265793871,0.011371790598870201,54.25711836808879,135.0482372572662,0.003575267438081366
0.0036906750989927203,135.741186126768,0.011717893439301887,54.730846246312865,136.2421627423138,0.00368388126839947
0.00379690623460352,136.848831746732,0.012055177294866175,55.17744896028235,137.36843392918937,0.003789716180353845
0.00391714496692642,137.872726168574,0.012436935269991383,55.590283191169036,138.41279362396165,0.0039094929308275605
0.00405400719834002,138.736085272262,0.012871472854729562,55.938389581776036,139.29852236062524,0.004045811853017127
0.00419053365035772,139.489523726736,0.01330494433988576,56.24217596661995,140.07405926978527,0.0041817778167742336
0.00434144473505672,140.178322004306,0.013784087033805086,56.519899432136185,140.78689844234069,0.004332047851413344
0.00448307621251602,140.789726981018,0.014233766974738363,56.766417918746455,141.42089805701323,0.004473057159311728
0.00464318626527762,141.293033307805,0.014742116392256442,56.96935102970697,141.9490831794392,0.0046324399279217875
0.00481356458416452,141.675938791362,0.01528306755472235,57.123738520677165,142.35790507275635,0.004802016425871446
0.00499338311730372,141.979694020155,0.015853991397439312,57.2462126289265,142.68865302727517,0.004980957526482789
0.00518063618433352,142.247394467396,0.016448519885258927,57.354149449254066,142.98432646630096,0.005167262857039807
0.0053739032915842205,142.47099143594,0.017062142950779898,57.44430374697101,143.23661676577288,0.005359515396377842
0.00556755871296392,142.63313684512,0.017676998913660445,57.50968077595238,143.42725520891943,0.005552117145993495
0.00578560883527132,142.769920176862,0.01836930805198644,57.56483181531076,143.59593108844822,0.005768936476063969
0.00599364321109312,142.862089042745,0.019029817195220657,57.60199430203478,143.71835343285863,0.005975752781930394
0.00620103419293832,142.925226872413,0.019688283562579165,57.627451474956914,143.8115110912823,0.006181886895004491
0.0064154731507189205,142.951588149581,0.02036912725353257,57.63808034191106,143.86869022520727,0.006394981598152874
0.0066294901005952206,142.958823169674,0.021048631069389825,57.64099750201255,143.9065672726701,0.006607611673078772
0.00684613003701202,142.958307320342,0.021736462867513164,57.64078951156189,143.93701848212817,0.0068228017007960435
0.00707030979831672,142.937296251708,0.022448233609655584,57.63231784868867,143.94790721794135,0.007045432350009084
0.00728146129292732,142.879750361203,0.02311863960504424,57.60911534563706,143.92012373300122,0.007255079441856982
0.0075055194679506205,142.849014524589,0.023830024310743218,57.596722656314284,143.92117058408084,0.007477493203794505
0.0077350581286436204,142.787256189211,0.024558809558443494,57.57182169548988,143.8917239158641,0.0077052959428199255
0.00795258340925722,142.747476066715,0.02524945232439167,57.55578235009949,143.8826872765965,0.0079211282741548
0.00817780077956412,142.677383290626,0.02596451747511608,57.52752094278041,143.84417050692625,0.008144543756615476
0.008398997956543319,142.603787281327,0.026666818512025035,57.49784703183104,143.8015161992982,0.008363922634727117
0.00862231700899202,142.534010704677,0.02737585650354966,57.46971311612577,143.7629841295358,0.008585357134902528
0.008852017312315419,142.468393960101,0.028105154966601452,57.44325644471272,143.7295266498936,0.00881306789226706
0.009076549537076019,142.387523178112,0.028818044780216358,57.41064934541476,143.67991058569967,0.0090356052301845
0.00930117953385602,142.323835242193,0.029531245019992863,57.38497036965222,143.6476147857276,0.009258189927262881
0.00952491929400422,142.266378882137,0.030241618758463398,57.36180396527763,143.62145465923956,0.009479843254604
0.009767420612891119,142.221938139877,0.0310115604459293,57.34388545799841,143.61107963006975,0.009720027714536037
0.01000336506515662,142.190912948705,0.03176068408187226,57.33137610091786,143.61330055987878,0.00995366259529756
0.01024088763330982,142.163524835044,0.03251481823575868,57.32033321348974,143.61940551843492,0.010188805023180128
0.010471419212666219,142.106952059596,0.03324675600021524,57.297523070429115,143.5950135276463,0.010416973654187726
0.01072150415470312,142.03750205607,0.034040775691182405,57.269520829007426,143.5603577244878,0.010664436368332196
0.010975799699257719,141.97890213576,0.03484816404514326,57.24589334113843,143.53723412712262,0.01091600275802953
0.01122442445293272,141.917331350282,0.03563754763806138,57.22106800043371,143.51027171458506,0.01116189804768318
0.011459587802587719,141.848528363819,0.036384191273216,57.19332663629183,143.47405402927205,0.011394424086639173
0.011708528956055819,141.74297913819,0.03717457943547722,57.15076918851822,143.40258091374713,0.011640514515469418
0.011953022106242819,141.6585457475,0.03795084518732095,57.116725645392,143.35179347635807,0.011882148944159416
0.01219604323091812,141.585847782617,0.03872243725816503,57.08741382595118,143.31263490306,0.012122270711873733
0.01243419249701902,141.514157949919,0.03947856117803539,57.05850848540734,143.27377223092185,0.012357522821613866
0.01267507254265122,141.45650886104,0.04024335532291762,57.03526437277133,143.24948037248384,0.012595416204382485
0.01292633076575802,141.385165398576,0.04104110018128171,57.00649868870585,143.2127568118894,0.012843498797517698
0.013180429019746519,141.306563207001,0.041847862137695195,56.974806285062805,143.1690443333752,0.013094322949891136
0.01342679758527942,141.238539339756,0.042630082333262154,56.94737906178962,143.1349206187114,0.013337456955841664
0.01368197763466752,141.155843438453,0.04344027899006937,56.91403607438425,143.08713453138054,0.013589224452342601
0.013935806919360619,141.075196965638,0.04424618696896997,56.88151941654525,143.04119367166192,0.01383959637939195
0.01418740666776242,140.997137959244,0.04504501617014568,56.850046025167174,142.9975216944624,0.014087707291004184
0.01444149967129192,140.897964511627,0.04585176145635184,56.81005929108801,142.93274241980737,0.014338214423249106
0.014701328788720719,140.80929479283,0.04667671890418828,56.774307660469056,142.87937853208732,0.014594311840547455
0.014959212004213919,140.720232837855,0.04749549811337919,56.73839788022314,142.82529663415883,0.014848426468779924
0.015217474858144519,140.633539361591,0.04831548267460885,56.703443070593494,142.7736267110379,0.015102850487137663
0.01547247922438322,140.534852384395,0.049125121537416716,56.66365248138807,142.70927496821432,0.015354000956529933
0.01572924069919602,140.410508812116,0.04994033921994736,56.61351715304518,142.61905950191837,0.015606818265280601
0.01598790156894962,140.322719684604,0.05076158748141504,56.57812057683233,142.56618551480878,0.015861441180813417
0.01624189715246532,140.241242097442,0.051568023459077385,56.545268813688615,142.51902592812266,0.01611140856638963
0.016487447258955918,140.131819701889,0.05234764504718504,56.50114970380164,142.44223568852541,0.016353005027187617
0.01673363939918232,140.025377610767,0.053129305092403864,56.458232252661254,142.36851178643994,0.01659517460042788
0.016985210294701118,139.929809818687,0.053928042685676046,56.4196993188946,142.3065470649549,0.016842574477593453
0.01723763783609942,139.855801000054,0.05472950012961565,56.38985896322177,142.2665846469705,0.017090755293108367
0.01749779464461862,139.795201286571,0.055555497996664115,56.36542515874543,142.24130901098655,0.017346470906827914
0.01775196069683862,139.717171484873,0.05636247521246261,56.33396354270079,142.19742522174593,0.017596234900533532
0.01800840714984962,139.634740738141,0.05717669270077254,56.30072746561846,142.14934000161713,0.017848176591135145
0.01825828988721692,139.572374330574,0.057970070391913715,56.27558133008745,142.12072720134879,0.018093608821584443
0.01851472274953862,139.497527793277,0.058784244729785114,56.245403206249286,142.08028584461556,0.018345411906253682
0.01877296240987282,139.434458762525,0.0596041556513462,56.21997377305008,142.05205661551486,0.018598925107750502
0.01901963369158562,139.336547626146,0.06038733697078434,56.180496002862064,141.98667772184547,0.01884102166202137
0.01928114981876292,139.251515444152,0.061217650674572265,56.14621102708209,141.93644477592048,0.019097623759933395
0.01954453248810232,139.138648098081,0.06205389064972486,56.100702913146264,141.85804792618458,0.019355990792574055
0.01979872347968562,139.041643320904,0.06286094704800184,56.061590586988494,141.79449036917566,0.01960527790219225
0.020065850630492318,138.938562779036,0.0637090757518131,56.02002851250732,141.72648322657543,0.01986718465396773
0.02032282759604242,138.84507081687,0.06452497761743467,55.982332553361985,141.66679525364154,0.02011907486454481
0.02058615346928592,138.738294930638,0.06536103726498278,55.93928051603324,141.59438276214718,0.020377122506206304
0.02085083160722702,138.655102486145,0.06620139035294578,55.90573732241367,141.54617667956643,0.02063642822209087
0.02110430432627422,138.547889606429,0.06700616623592065,55.862509089312184,141.47184643244614,0.02088469295219044
0.02135790657643832,138.445042021112,0.06781135338019166,55.821040942912354,141.40193829456996,0.021133022884674422
0.02161917854269562,138.333773283743,0.0686408918730586,55.77617738800518,141.324435826849,0.021388798604906268
0.02187592427839762,138.23202480229,0.06945605958391243,55.73515240028333,141.25597810971448,0.021640079595693695
0.02214298586526762,138.139586537337,0.07030398012222469,55.69788129185429,141.19840944946716,0.021901389886967586
0.02240245222718702,138.042960011659,0.07112778582131878,55.65892147670091,141.1354608286197,0.022155203139026726
0.02266482950393482,137.972475316146,0.07196083367499305,55.63050204747007,141.0995979454223,0.02241179839193726
0.02292341115800462,137.897747213079,0.07278183042666467,55.60037167631344,141.05883397020696,0.022664617263601593
0.023188545322792718,137.847229629165,0.07362363139986687,55.58000298647933,141.04370636104233,0.022923776265563623
0.02344913290082952,137.796335203306,0.07445099696013371,55.55948235397298,141.02753978073557,0.023178425715456655
0.02370441010116122,137.757672714769,0.07526150207118687,55.54389363859487,141.02313708338144,0.023427822935833703
0.02396022370887272,137.698242947127,0.07607371027567088,55.51993155628161,140.99752365245888,0.02367768182856304
0.02421754016663202,137.627995595205,0.07689069002905666,55.491607823986655,140.96100710658493,0.023928945623777932
0.02447807977623192,137.537431150456,0.07771790328953634,55.45509223986386,140.90408336237485,0.024183292446671674
0.02474631925798632,137.465965167638,0.07856956364410655,55.426277155591634,140.8677418287836,0.0244450885519816
0.02500894775355362,137.396518616728,0.07940340911753274,55.398276306264734,140.8326609723339,0.02470134206793151
0.02527866556294262,137.315633232391,0.0802597631623428,55.365663319300054,140.7867892014363,0.02496444448263001
0.02555501253205342,137.204361517537,0.0811371647892696,55.320798563870916,140.71062069557004,0.025233941686362275
0.02582741625733842,137.083210949838,0.08200204661704948,55.27195065497468,140.623716100932,0.025499522324144097
0.02609631443542142,136.97607377427,0.08285579833246301,55.228752945785665,140.5506444656128,0.02576161606145027
0.02636691981198622,136.860840309305,0.08371497040305624,55.18229081271177,140.4694391111415,0.026025304466306947
0.02662851487534922,136.76015589875,0.08454553472923376,55.141694858376006,140.40187574445494,0.02628014679119354
0.02689464957753072,136.615836900086,0.08539051240866004,55.083505438114685,140.2900719602549,0.02653934494223305
0.02715873938057472,136.51718150324,0.08622899753332473,55.04372758210638,140.22481605665712,0.02679648509829615
0.02742084681467672,136.4177564106,0.08706118863659858,55.00363938475392,140.15844681193695,0.02705162969068386
0.027683083838595718,136.348118841336,0.0878937911875414,54.97556151682667,140.12265524645554,0.02730683529992899
0.02794858570450902,136.285713948187,0.08873675961181612,54.950399863909006,140.09470690476812,0.02756515187611659
0.028217592073096518,136.225909856793,0.08959085483208144,54.92628685425894,140.06987701091842,0.027826810075759826
0.02847799259977342,136.163353998804,0.0904176265042806,54.90106433231779,140.04101298634228,0.028080032312447538
0.02874034416386972,136.110044594782,0.09125059272028636,54.87956998061611,140.02189412059568,0.02833508697614572
0.02901265556202512,136.033117365402,0.09211518140942974,54.84855292173009,139.97979934455296,0.02859975567037813
0.02928588372557362,135.973843725688,0.09298268082869623,54.8246537901974,139.9559579027578,0.02886524501503646
0.02955298490318732,135.886099846449,0.09383072706761973,54.78927545808824,139.90193970376413,0.029124712798729555
0.02982247282631792,135.791675915539,0.0946863512235594,54.75120372914533,139.84131948057032,0.02938643090715647
0.030093382529697718,135.69867010704,0.09554648953179025,54.71370378715852,139.78230209534237,0.029649460782126588
0.03037901919537052,135.605211451532,0.0964533859453014,54.6760212572577,139.72476477321038,0.029926714354912645
0.030661607311778718,135.538478482551,0.09735060321489743,54.64911452416456,139.69430608541896,0.03020093322720904
0.03092968595168882,135.469417088372,0.098201752896612,54.6212689700316,139.6594436149737,0.03046100285623497
0.03120304922501082,135.364663785747,0.09906968128940935,54.5790324384132,139.58845405318073,0.030726129606089808
0.03147646560103462,135.225382708087,0.09993777828328491,54.522874307900686,139.48179981528486,0.03099123756460683
0.031755198838933824,135.096473098715,0.10082275631361488,54.470897953401895,139.38648846440336,0.0312614284931378
0.03202760765046512,134.992664815089,0.10168765429022675,54.42904245344389,139.3161569194774,0.03152541830084121
0.032293874370533916,134.869299536791,0.10253305112644517,54.37930157323414,139.22475175247405,0.03178338850932323
0.03256405598534482,134.763214031212,0.1033908777534698,54.33652789738468,139.15165087768938,0.03204508362391771
0.03283983112717922,134.648371234494,0.10426646382879401,54.29022328174798,139.0702010073845,0.03231212596386282
0.03311368978438452,134.580201137876,0.10513596506542083,54.262737098791604,139.03664816947568,0.03257724195610307
0.033389062228387216,134.567502812321,0.1060102725751294,54.25761713392784,139.06058553764026,0.032843752557518424
0.03366226417154622,134.52710253348,0.10687768874465924,54.241327741499134,139.0555893971947,0.03310809233588834
0.03394032998450442,134.438211166242,0.10776054770080153,54.20548674222878,139.00108841575076,0.03337706647571634
0.03422345158573902,134.376133162971,0.10865945878472139,54.18045689130991,138.97494825055276,0.03365085678722453
0.03450642880325062,134.282526219191,0.1095579114503207,54.14271457157781,138.91613664969415,0.03392443259038681
0.03478917438548712,134.190092974784,0.1104556286739216,54.10544548743291,138.85845552008848,0.03419770972252824
0.03507839101491332,134.089750674126,0.11137389147234979,54.06498747180761,138.79340337936523,0.03447716396022233
0.03536226932981842,133.975111455047,0.11227520512217347,54.01876493867495,138.7127754298128,0.03475138415123876
0.03564082821041182,133.858611275967,0.11315962956805752,53.9717920664699,138.62944304493806,0.03502039280951095
0.03591807161573832,133.751758260195,0.11403987737996915,53.92870893051063,138.5558634921156,0.03528805925819841
0.03619667623117732,133.647484681136,0.11492444703398798,53.88666582343404,138.48507941325033,0.035556967741579855
0.03647366713850072,133.543235444604,0.11580389316473978,53.84463253126433,138.4140469628089,0.03582424701236047
0.03674561159391012,133.435039234523,0.11666731681066463,53.801007819359675,138.33819135925296,0.03608658728650213
0.03701436236519372,133.327158764587,0.11752060050949005,53.757510413881484,138.26217853222116,0.03634577906970065
0.03727807795486032,133.21294066963,0.11835789750668152,53.711457677994815,138.17886305650865,0.036600049476284875
0.03755879091974542,133.129696388384,0.1192491611701917,53.677893583796426,138.1298868202445,0.036870637464004805
0.03783508570778092,133.043530861445,0.12012639712220442,53.643151643334626,138.07724425445357,0.037136895153958814
0.03810527747170942,132.972811166319,0.12098425597267741,53.614637462259815,138.0397770320048,0.03739720298384307
0.03838058932041432,132.907343501898,0.12185837109231545,53.58824089996528,138.0084056705116,0.0376623739197218
0.03866441916748472,132.840729759032,0.12275953085676397,53.56138223884171,137.9769394169498,0.037935675507003
0.03894715638611812,132.772677621514,0.12365722152592502,53.53394361699444,137.94379586064275,0.03820785075256443
0.03924191689182562,132.704058415581,0.12459308613154635,53.50627635316226,137.9116200471332,0.038491521291953025
0.03951421635120482,132.631096705682,0.1254576369150753,53.47685819173099,137.8719105558079,0.038753504365948106
0.03979797741951602,132.568826908012,0.12635857830696334,53.45175100931044,137.8447980878288,0.03902644180258985
0.04009820833339342,132.476006622188,0.1273118114585241,53.41432587006621,137.7880571349005,0.039315139784747946
0.04039900060859632,132.384690235694,0.1282668269322933,53.377507103031824,137.73289941709464,0.039604294008080645
0.04069230689681862,132.295793847908,0.1291980743973991,53.34166407947651,137.6792148923253,0.03988617139530192
0.04098192604065352,132.21246443909,0.1301176151790749,53.30806566184109,137.63078587838532,0.040164427369383755
0.04128041154453442,132.145020848892,0.1310653066538968,53.28087240627325,137.60002169309533,0.04045112083786537
0.04159257594260022,132.054818786279,0.13205642861775568,53.24450293462769,137.5473188652336,0.04075086489549947
0.041895952696422316,131.971389156572,0.13301964981114084,53.21086410792983,137.50045623395687,0.0410420848871587
0.04219065694170332,131.885953604505,0.13395533578990804,53.17641649333642,137.4503086284621,0.04132489870677888
0.04247508160868272,131.790095048314,0.13485838410756762,53.1377663234802,137.38789009070717,0.041597771871511695
0.04276992768599292,131.702194090887,0.13579452040302753,53.102324657445635,137.33508740824084,0.0418805646157321
0.04306550216648392,131.599305185043,0.13673296937858645,53.06083985060934,137.26669534759722,0.04216397574034822
0.04335436440746072,131.482227563862,0.13765010699368777,53.013634153749166,137.18255597077038,0.04244087325982677
0.04364658660501882,131.379034716949,0.13857791247093476,52.972026797873845,137.1132811338061,0.04272091357253104
0.04393619432957972,131.283686989542,0.1394974169964156,52.933582594183335,137.05179257341823,0.042998371050206846
0.04423023068333862,131.176909060249,0.14043098241960011,52.89052973309239,136.97889400831113,0.04327999262230012
0.044528539858723216,131.07040461615,0.1413781140514462,52.84758714123168,136.90677835239921,0.0435656255844399
0.04481887642255582,130.962586182438,0.14229993264161472,52.804114748759005,136.832182148527,0.04384354639688024
0.04511820867775362,130.844127990004,0.14325031255186774,52.756352405569615,136.7475806609157,0.04412999737129323
0.04541073093940492,130.743540807015,0.1441790707326106,52.715795653388454,136.68070056066747,0.044409852156383336
0.04570110354149842,130.655758600573,0.1451010037442575,52.68040186775104,136.6268709526708,0.04468757293551321
0.04599843084491892,130.561057573475,0.14604501793261757,52.64221841362512,136.56666135130797,0.04497186549334478
0.04629153054279662,130.46958645277,0.14697560947337926,52.60533725775686,136.50922329895445,0.04525203669829641
0.04659125307891022,130.39884225674,0.14792722852553994,52.57681319791757,136.4742877175207,0.04553845745774669
0.04688940101007242,130.291140689327,0.14887384820697994,52.533387925936644,136.40041423316862,0.04582329212540462
0.047180990584330916,130.218603081035,0.14979964510525065,52.50414076227332,136.36244576690606,0.04610178283642711
0.04748271030823152,130.143275885749,0.15075760522863507,52.473768837134,136.32283135319628,0.046389867005603026
0.04777435816055732,130.037131163055,0.15168358715976948,52.43097128494377,136.24957164141017,0.046668255618244746
0.04806688997628862,129.923324626254,0.15261237567471636,52.38508448930561,136.16833477641777,0.046947410175290444
0.04835616023206262,129.814735403948,0.1535308087367988,52.341301314871835,136.0920775496241,0.04722337571343032
0.04864977391018162,129.704113366889,0.15446303216482662,52.296698509529655,136.01418915740874,0.047503407043105975
0.04893351826765512,129.60413267232,0.155363920499805,52.256386293479416,135.94611886600455,0.04777395111185623
0.04921775708645982,129.460281455605,0.1562663787495099,52.19838548289994,135.8320261406317,0.04804489327306482
0.04950455450839932,129.332298921132,0.15717696056416783,52.14678292500042,135.7348367627698,0.04831819996270199
0.04979719652482982,129.244336070021,0.15810609896633468,52.11131630343247,135.680341673021,0.04859699934748025
0.05009247052271532,129.155032051825,0.15904359390962114,52.07530892329584,135.6247266877414,0.04887822745623766
0.05039468762411412,129.084264764446,0.16000313320656231,52.04677555302463,135.5894259644387,0.04916598651471336
0.05068585321298542,128.995740514813,0.1609275839512287,52.01108257557261,135.53399968364718,0.04944314446756287
0.05100223703584622,128.933364208691,0.16193210258881174,51.985932448944205,135.50925421189174,0.04974422037575178
0.05131540037750582,128.879199347796,0.16292639619858099,51.964093177031344,135.49268706266054,0.05004214238182994
0.05161934314969152,128.79710900049,0.16389141450027056,51.930994348997565,135.4455311666745,0.05033120772276603
0.05191390056307302,128.660488242614,0.16482663428775682,51.87590885942197,135.33975603563752,0.050611267394927
0.05220548184785272,128.545500451863,0.16575240486693238,51.82954578219116,135.2562802423259,0.05088842019251403
0.05250370614806182,128.42547253867,0.16669926702009627,51.78115052759175,135.1682858107663,0.051171807849018515
0.05279917593883722,128.313951681147,0.16763738360580815,51.73618531783846,135.08882259136735,0.05145249885574208
0.05309494768979002,128.195903795693,0.1685764589150833,51.68858841042342,135.00245860177066,0.05173339783312067
0.053391585635178616,128.098925879235,0.1695182843916921,51.649486914507555,134.93833065009056,0.05201504021977405
0.05369514812631662,128.016990867971,0.17048209530105526,51.61645071796591,134.89088215531203,0.052303175006419816
0.05400523697551472,127.957589845733,0.17146662739725924,51.59250022579954,134.86796980816752,0.05259741877429798
0.05432285642972562,127.882499677284,0.17247506916437882,51.56222386988091,134.82944234712753,0.05289871861240882
0.05463070730185842,127.785524579934,0.1734524956834005,51.5231235106294,134.7665381706748,0.053190665177391204
0.05494166710929742,127.689717702118,0.1744397930720193,51.48449417749398,134.70520366538793,0.05348547355985126
0.05524050128642592,127.586154760114,0.1753885915844023,51.44273759927796,134.63407790627022,0.053768704253012965
0.055551463008882716,127.478276159026,0.1763758950532026,51.399240947319285,134.55988090151027,0.05406334411328005
0.05586031827114922,127.365241994589,0.17735651051089876,51.35366557221829,134.47990494908868,0.054355902170602446
0.056178460481507916,127.254960040201,0.17836661202878762,51.309199888209044,134.4039477838953,0.054657167673836035
0.05648933077837022,127.14423417126,0.17935362522132545,51.264555217852035,134.32652687192288,0.05495145937496586
0.05679873994859682,127.041193540366,0.1803359993367949,51.223009235475566,134.2569732550246,0.055244281898050376
0.05711402277640222,126.923516526049,0.18133702231507703,51.17556186330296,134.17262913977882,0.05554257503076871
0.057426165239023316,126.814359443444,0.18232807463389902,51.13154972759662,134.0968218035241,0.05583780939581652
0.05774194166662592,126.678698782045,0.18333066479153728,51.07685134892055,133.9933728175219,0.056136392216650045
0.05805662018602332,126.521320485243,0.184329769090624,51.01339641964998,133.8667207340889,0.056433848248042914
0.05835280271735282,126.358400201346,0.1852701486275952,50.94770696118271,133.73176699997546,0.05671373977570083
0.05865660288785402,126.206351682459,0.1862347141689365,50.88640099836747,133.60918753502185,0.057000748583297456
0.058952645836636716,126.06806286762,0.18717465053132157,50.83064294822439,133.50010872916565,0.0572803496956269
0.05924908365249472,125.94600058758,0.18811584059667072,50.78142743691225,133.4081857120907,0.057560245433286285
0.05955281593698142,125.827105544201,0.189080190599916,50.73348895542185,133.32046400055793,0.057846947353485535
0.059844873520549416,125.734478937463,0.19000747342774438,50.69614190758508,133.25904292664765,0.05812255167906307
0.060137855640155516,125.660850397554,0.19093769165749375,50.66645488029378,133.2178244783813,0.058398952158596494
0.06044031232142402,125.571882375906,0.19189799162052126,50.6305829739653,133.1614861654949,0.05868421085633204
0.06073997054576632,125.477768214333,0.19284940648280804,50.59263614401906,133.0992841598201,0.05896674999622125
0.06105397415531602,125.382920957864,0.19384636794312834,50.55439373021077,133.03804657354345,0.059262729360877474
0.06135791281879102,125.266458329941,0.1948113731996615,50.50743599863221,132.95254675926824,0.05954913810879125
0.06166161174487782,125.148986286981,0.19577561728998705,50.46007127091074,132.86587448967387,0.05983523903687454
0.06196981545071702,125.030492586451,0.19675416405602653,50.412294610857046,132.77860913774563,0.06012550005303417
0.06227892984688322,124.914828257186,0.1977356022638542,50.365658753297396,132.69439008305076,0.06041653414123344
0.06259268911045253,124.818820161545,0.19873178792568677,50.32694828913495,132.63156576705006,0.06071185482136324
0.06289829996015302,124.718774595807,0.19970210237348582,50.28660991702938,132.56337349099678,0.06099942212075722
0.06320653130248333,124.604327947175,0.20068073688538454,50.24046502830096,132.48013530199302,0.06128937145905656
0.06351834306082753,124.50259359294,0.2016707392181274,50.199445736673404,132.41079204473914,0.0615826033334161
0.06382943621793143,124.391035532689,0.20265845999193227,50.15446552678021,132.3308452013052,0.061875073762888616
0.06413126925595383,124.271883031856,0.2036167798876534,50.10642323844434,132.2415966235164,0.0621587566704444
0.06443832128052003,124.141078379778,0.2045916700656511,50.05368280272649,132.14052107252434,0.06244726217955341
0.06474944477270662,124.033300633086,0.2055794871533435,50.010226815260275,132.06438798240453,0.0627395083584592
0.06507474675580503,123.916273771695,0.20661232094968096,49.96304158474743,131.98009390631105,0.06304498144578909
0.06537923567216572,123.792711995203,0.20757907325912614,49.91322147646585,131.88618488723392,0.06333082560946993
0.06569042226927413,123.674443078977,0.20856709070494533,49.865535449443534,131.79866946875234,0.06362287293712135
0.06600952004764363,123.556149804387,0.2095802261512685,49.817839601128846,131.71203195190935,0.0639222563300823
0.06633159778451653,123.437798579697,0.21060282296583996,49.770120387333826,131.62562498649163,0.06422434471231042
0.06664682542108193,123.316532697793,0.21160367071193512,49.72122598375014,131.53518812403595,0.0645199197968316
0.06695227816883943,123.170875509528,0.2125734831860652,49.66249700544169,131.4174462289414,0.06480624607933742
0.06725527853922572,123.037374396062,0.21353550936204166,49.6086693564922,131.31228728180415,0.06509019256942435
0.06756435340238312,122.899020409137,0.2145168220525664,49.55288502896404,131.2026132568666,0.06537974852131122
0.06787066340719163,122.707113862168,0.2154893563178334,49.475508309226136,131.03532708477516,0.0656666315259433
0.06816468746786333,122.511358186887,0.21642288271046606,49.396579620952835,130.86230662895963,0.06594193039907126
0.06845743084839102,122.294057047707,0.21735234294364147,49.308963801635464,130.6659940012196,0.06621595487897326
0.06875893571305802,122.120646386159,0.21830962088895922,49.239044622899314,130.517532060262,0.0664981021349877
0.06905985024854112,121.969218340371,0.21926502453911806,49.17798883483759,130.39239429388863,0.06677961761183393
0.06935835821677473,121.818797175591,0.22021278733825977,49.1173390211983,130.26794894763228,0.06705880338474854
0.06966048523643052,121.676553373333,0.2211720406256669,49.05998632012786,130.1526011232158,0.06734129460504759
0.06995742452368883,121.590360193791,0.22211482286271203,49.02523323013653,130.0965086398563,0.06761885751738848
0.07026162182304563,121.508004850291,0.22308064928816987,48.992027555637335,130.04535433555495,0.06790312496368042
0.07057828969668863,121.442009078168,0.22408606978698636,48.96541806031733,130.01317837623483,0.06819896013963038
0.07088420107634112,121.332380270029,0.22505733841738304,48.921215724875694,129.9329291101608,0.06848466337566778
0.07120123286184543,121.200045174658,0.22606391433635922,48.86785821442211,129.82963781400503,0.068780666310748
0.07151451190435593,121.034173949402,0.22705857529633006,48.80097893639889,129.6898738231404,0.06907307938094447
0.07182281563616973,120.866530217631,0.22803743964483886,48.73338498374882,129.54750473403544,0.06936076506623416
0.07213480348167463,120.695447807067,0.22902800105431692,48.66440455580942,129.4017902157625,0.06965180425929013
0.07244312034455902,120.482861294167,0.23000690709397487,48.57868967380813,129.21101571435716,0.06993933576988072
0.07274283619540033,120.303541686295,0.23095850492039602,48.50638800791415,129.05476251290767,0.07021876688574999
0.07304424084191502,120.115118258673,0.23191546467308016,48.430415681896946,128.8888358855146,0.07049969377893736
0.07333843054818903,119.933471809372,0.23284951699050016,48.35717583353879,128.7292044020668,0.07077381983487105
0.07363665634653703,119.754848077831,0.23379638390025506,48.285154744981455,128.57319467156998,0.07105163004523293
0.07393823271691552,119.599467372764,0.23475388887620677,48.22250524469844,128.44244062419057,0.07133248299606296
0.07424023169553153,119.424296304695,0.23571273563331258,48.15187627005303,128.29038373243137,0.0716136504927198
0.07454859901227052,119.299788115489,0.2366918018639589,48.101674568165166,128.19342018195943,0.07190066549805589
0.07486042279185523,119.148499552218,0.23768184236414033,48.04067501945429,128.0680066037122,0.07219081388638879
0.07517124281600543,119.005405630387,0.23866869594081722,47.98297955017204,127.95118987344604,0.07247994453621816
0.07547781815216573,118.857282419093,0.23964207263312617,47.9232562713783,127.82837076758192,0.07276504482877727
0.07578495544348722,118.704136538489,0.2406172335330719,47.861507852318766,127.70012423701601,0.07305058623002131
0.07609704196973953,118.536597430484,0.24160810825392298,47.793956083971146,127.55688186010165,0.07334064537714509
0.07639890138448673,118.370209706551,0.24256651189574535,47.72686855368136,127.4135636847828,0.07362111923137749
0.07670675919577863,118.18032683599,0.24354396044659712,47.65030778027117,127.2455567082767,0.0739070855162897
0.07700722399009162,117.985874301505,0.24449793616854087,47.57190451836682,127.0716389515078,0.07418610566344765
0.07731367247270952,117.804744952714,0.24547091010085273,47.49887316493429,126.91266241971921,0.07447060226299135
0.07763164908739863,117.602563531515,0.24648048585249063,47.41735361590685,126.73224447537208,0.07476571565989815
0.07793968358338893,117.421073368519,0.24745849537725984,47.344176782186864,126.57283467288327,0.07505151877243572
0.07824696033667833,117.216402199433,0.24843409906895367,47.26165336681139,126.38822937314016,0.07533653747082701
0.07856058584037942,117.007529735206,0.24942986004320464,47.177435989235065,126.19970981893941,0.07562736129186536
0.07886959236112193,116.82444786874,0.2504109557465621,47.10361738067597,126.03834444996066,0.07591381925094809
0.07917967981196483,116.630882529855,0.25139548340298834,47.025571836037535,125.8656784647558,0.07620119679786076
0.07948909516560983,116.402798364228,0.25237787715081117,46.93360830045673,125.6555514809454,0.07648786917608807
0.07978506876466802,116.144905927854,0.25331759332782094,46.829626070110734,125.41153523397372,0.07676201092784515
0.08009161576512502,115.912721923315,0.2542908800542719,46.73600947948061,125.19635910988693,0.07704586695047001
0.08039472984435993,115.688542492124,0.25525326725584274,46.6456203328244,124.98929161186607,0.07732646495733979
0.08070104741546133,115.4341124594,0.25622582554408974,46.543034143630074,124.74976624234772,0.0776099485274582
0.08100466251363503,115.187372336841,0.2571898034807912,46.44354852621429,124.51808655881923,0.07789085179636827
0.08130872956580643,114.948349491971,0.2581552163714354,46.347174515162706,124.29465375484946,0.0781720941503113
0.08160124837936543,114.712861444823,0.2590839636044852,46.25222573455264,124.07357414388973,0.07844258050279493
0.08190675967754993,114.514714832989,0.260053961976221,46.17233302066116,123.8942440603578,0.07872500266076952
0.08220294385853963,114.279164274487,0.2609943467508633,46.07735903547316,123.67324799954349,0.07899872647648458
0.08249358767762062,114.032898395654,0.26191714087644546,45.978064633127694,123.4398812975891,0.07926725725351806
0.08279693754077122,113.833376359816,0.26288027669194863,45.89761734827781,123.2584313123348,0.07954745047618471
0.08309185428282782,113.589453191775,0.26381663734797833,45.79926752692368,123.02781148445206,0.0798197790878775
0.08339764987020493,113.332323688502,0.26478753833790064,45.695592911204,122.78397313845242,0.0801020750222189
0.08370744643666743,113.086435269284,0.2657711424364191,45.5964507005753,122.55261199230124,0.08038798323137843
0.08401384129288303,112.806062422782,0.2667439461049036,45.483404368865706,122.28333304804467,0.08067067165630686
0.08431808316085662,112.513252477549,0.26770991403571975,45.365343398947765,122.00015425664942,0.08095129462416426
0.08462162459617202,112.234862937188,0.26867365809284616,45.2530967362742,121.73235937526154,0.08123119307981197
0.08490264346294113,111.867332601842,0.2695658929948381,45.104908505062696,121.36516485688644,0.08149025343924486
0.08520266948235833,111.505183247657,0.2705184756064877,44.9588898854553,121.00572252147691,0.08176676169858037
0.08548198831039752,111.173244758245,0.2714053128855121,44.82505228652439,120.67655476709825,0.08202411720950464
0.08576163326028763,110.867945734989,0.2722931856014132,44.70195572034756,120.37616183743458,0.08228170686794568
0.08603777364371303,110.612628649204,0.27316993131878886,44.59901187135905,120.1294929550603,0.08253600326754479
0.08632816678698743,110.369914688633,0.27409192954868505,44.50114960245683,119.89794709213889,0.08280335522662277
0.08662562510789573,110.104490655622,0.27503635971756896,44.39413063234679,119.64236098585174,0.08307713769164884
0.08693877575759333,109.913344064269,0.2760306130303588,44.31706032671326,119.46907563663967,0.0833652825027613
0.08722497310113042,109.717693155293,0.27693928959608904,44.23817388021415,119.2878159894815,0.08362855369872377
0.08754239216065843,109.46400454809,0.27794709511009047,44.13588663378989,119.046745361715,0.08392046451810824
0.08785477975899852,109.165064182305,0.2789389257348203,44.015353878305376,118.75573685341836,0.0842076650390244
0.08816737504669382,108.859196047572,0.27993141577325287,43.89202784638103,118.45702561277984,0.08449497396109136
0.08846678900992842,108.525564224247,0.28088205510652275,43.757507495216394,118.12647241665691,0.08477009044145124
0.08876285900487413,108.181431332833,0.2818220773404753,43.61875311339827,117.78392446917472,0.08504205991149828
0.08905698473087642,107.850943480605,0.2827559265205326,43.48550041137994,117.45582330736785,0.08531217015834591
0.08936753953856443,107.522385545673,0.283741938034942,43.35302585201536,117.13139658720671,0.08559728888183808
0.08966296533774633,107.214879366394,0.28467991494734457,43.22903936053006,116.82808337871364,0.08586844231482657
0.08995363436312913,106.900523482132,0.28560278910293496,43.10229106799562,116.51661408467079,0.08613515805478357
0.09025443965534033,106.545168844479,0.28655784590570554,42.95901207809393,116.16134335652107,0.08641109987676353
0.09055885623935553,106.214675971704,0.2875243685599538,42.825757351791054,115.83335554353528,0.08669027699528659
0.09085827016740103,105.911643163207,0.28847500778149826,42.70357452340507,115.53459185160304,0.08696479022460087
0.09115646954462153,105.56570336582,0.28942179080417335,42.564091597098624,115.18870018964293,0.0872381150318535
0.09144499355872132,105.112541407831,0.2903378545489402,42.381376695637464,114.72455707981095,0.08750250046424493
0.09173081983688942,104.676903471385,0.2912453529821239,42.205727479662436,114.27900164480208,0.08776434495523579
0.09202481053898763,104.299758012372,0.29217877346128573,42.053662430588396,113.89792348272277,0.08803359733840994
0.09231842774071562,103.935184098224,0.2931110080767721,41.90666622840392,113.53031688111386,0.08830243531071295
0.09260278073912763,103.570063847195,0.2940138288467302,41.75944974318902,113.16093976077426,0.08856272204225622
0.09290663009930943,103.178986829384,0.2949785505653074,41.60176748960763,112.7649987927631,0.08884078020172471
0.09321048264635763,102.785473626747,0.2959432824021855,41.443102966304394,112.36615723253055,0.08911876398148964
0.09352520037450113,102.484310093038,0.2969425111890411,41.32167382951292,112.06917572973188,0.08940660647910846
0.09383753767770052,102.150926921413,0.29793418212669914,41.18725373471372,111.73651837521312,0.08969218993528491
0.09415958207677412,101.764786653456,0.29895667309375784,41.031561978673466,111.34691643487751,0.08998656363303037
0.09446673078069202,101.343296270195,0.29993187022869716,40.86161705614262,110.91686615537942,0.09026724079032299
0.09478923640332812,100.899040540963,0.30095582558056677,40.68249314611628,110.46318354766932,0.0905618665716871
0.09510382920333092,100.465164594807,0.30195465772057567,40.50755436462619,110.01978644931606,0.0908491799634757
0.09541099374800682,99.9840287662704,0.30292990514992163,40.31356039856023,109.52360430978955,0.091129629603415
0.09572005191626592,99.4797375570241,0.3039111648341443,40.11023018299211,109.00194320059896,0.09141172881507131
0.09601651039711062,99.0225689332413,0.3048524205108262,39.9258997938829,108.53037045276848,0.09168225264329981
0.09631713957771623,98.5729409969279,0.30580691815924904,39.74460980996133,108.067204713515,0.09195650759759781
0.09662171252828333,98.1531986192787,0.30677393727729957,39.57536968329317,107.63692876000214,0.0922342836534445
0.09692089318315733,97.7356302493702,0.3077238358565245,39.40700611654607,107.20825482895798,0.09250706673588856
0.09721044752527333,97.3018406978012,0.3086431708927428,39.232102169353446,106.7605961770673,0.09277100202401346
0.09750349838985473,96.8417470589558,0.3095736073877887,39.04659241417098,106.28415618738943,0.09303805356106555
0.09778165383461362,96.4269910823114,0.3104567509248982,38.87936280438796,105.85578174463535,0.0932914652383281
0.09806288819607352,95.9594219280822,0.3113496700225334,38.690838921402744,105.36947999197555,0.09354761667128647
0.09832916104687453,95.4055249898019,0.31219508632382664,38.46750767588813,104.78667022128576,0.0937900805357841
0.09859350156747662,94.8139415129877,0.31303436747673824,38.22898121803664,104.16198000416708,0.09403072671452858
0.09885639526781792,94.2767940224474,0.31386905497532186,38.01240334985079,103.59665803691311,0.09426999833748949
0.09912085190989382,93.7810846385969,0.3147087048139129,37.81253332628227,103.07674564100847,0.0945106347168621
0.09938894014316063,93.3895836458816,0.31555988495453496,37.654680126019464,102.67147538485682,0.09475451649129374
0.09966909395884002,92.9667290041859,0.31644937331931705,37.48418513448775,102.23263865235012,0.09500931087402535
0.09995489929985443,92.5374148664597,0.3173568052770378,37.31108567415655,101.78698285090553,0.09526917832727984
0.10026380407145792,92.1659485330826,0.3183375779268789,37.161310448538906,101.40685713886366,0.09554997293479746