File: example/data/02 processed data/test_ID_097.csv
Strain,Stress_MPa,Displacement(mm),Force(kN),True Stress (MPa),True Strain
-0.0002945841432509,1.43829297183558,-0.0009353046548216074,0.28995986312205296,1.4378692735327279,-0.0002946275416828277
-0.0003921250062727,3.8960260803746,-0.0012449968949158224,0.7854388578035193,3.8944983511233944,-0.000392201907386888
-0.0004647001416703,10.0184814951963,-0.0014754229498032026,2.019725869431574,10.01382590542616,-0.00046480814824290334
-0.0003891477147282,17.2826138950827,-0.001235543994262035,3.4841749612486725,17.2758884053809,-0.0003892234523495242
-0.0002517639313885,24.4768927668162,-0.0007993504821584875,4.934541581790146,24.470730368065052,-0.00025179562924741977
-0.0001038017284477,32.2798617504489,-0.0003295704878214475,6.5076201288904985,32.27651104500515,-0.00010380711621996315
3.80261777850682e-05,40.3840760837829,0.00012073311446759153,8.141429738490633,40.385611735839746,3.8025454808262756e-05
0.0001778817744756,48.3527648246466,0.00056477463396003,9.747917388648755,48.361365900254405,0.0001778659553886085
0.0003356863989969,56.082994637152,0.0010658043168151575,11.306331718849842,56.10182093566671,0.0003356300689235196
0.0004845744321657,63.8185587825239,0.0015385238221260974,12.865821450556819,63.84948362440758,0.00048445706388985504
0.0006380781839746,71.1291106096397,0.002025898234119355,14.339628698903365,71.17449654336522,0.0006378746986452106
0.000791180706835,77.9958383169015,0.002511998744201125,15.723961004687341,78.05754711939126,0.000790867888366021
0.0009258910155809,84.7053689437882,0.0029397039744693573,17.0766023790677,84.78379688386472,0.0009254626428917951
0.001062819049333,91.3027121123525,0.0033744504816322746,18.406626761850266,91.39975037404126,0.001062254657029636
0.0012010431904555,97.5218549726009,0.0038133121296962127,19.660405962476343,97.63898293243633,0.001200322515066567
0.0013450453977267,103.651807522368,0.004270519137782273,20.89620439650939,103.791223909042,0.0013441416344766087
0.001479828656082,109.91064167683,0.00469845598306035,22.157985362048926,110.07329059399173,0.0014787347886808771
0.0016112071262544,116.003493274687,0.00511558262585772,23.3863042441769,116.19039892972158,0.0016099105245949378
0.0017529946636009,122.226789946521,0.005565758056932857,24.64092085321863,122.4410528570463,0.001751459961743169
0.0018901066294435,128.354156765334,0.006001088548483112,25.876198003891336,128.5967598079528,0.0018883226255261463
0.0020324051782196,134.299844992682,0.006452886440847229,27.074848750524694,134.57279669307923,0.0020303426369556762
0.0021649358410399,140.195164750481,0.006873671295301681,28.263345213696972,140.49867828738982,0.0021625957442728675
0.0023025887701824,146.059327363833,0.00731071934532912,29.445560396548736,146.39564193080136,0.0022999418750221526
0.0024264353487115,151.878296027931,0.007703932232159012,30.618664479230887,152.24681889411525,0.002423496307762642
0.0025544199074178,157.679847023358,0.008110283206051514,31.788257159908976,158.0826275635931,0.0025511629221790792
0.0027007938676737,163.329504132783,0.008575020529863997,32.92722803316905,163.77062345595502,0.0026971532774319284
0.0028347237678483,168.848605955398,0.009000247962918352,34.03987896060824,169.32724511186782,0.0028307135152795923
0.0029610329399727,174.407847038668,0.009401279584413322,35.16062196299547,174.92427441873923,0.0029566577165961723
0.0030850168214639,180.006484400719,0.009794928408147881,36.28930725518495,180.5618074330678,0.0030802679215203065
0.0032202121790211,185.52385989894,0.010224173668391992,37.40161015562631,186.12128609208557,0.0032150383999175534
0.0033548701370235,190.806708666229,0.010651712685049611,38.466632467111765,191.44684039507706,0.003349255115146671
0.0035043539328617,196.275939506241,0.011126323736835898,39.56922940445819,196.9637598667758,0.003498227992089718
0.0036574687901979,201.543158239598,0.01161246340887833,40.63110070110296,202.28029605073723,0.0036507965153644746
0.0038181471826312,206.550436731274,0.012122617304854059,41.64056804502484,207.33907669935078,0.003810876559673016
0.0039896210002344,211.46416899384,0.012667046675744219,42.63117646915815,212.30783088325492,0.003981683566934632
0.004169011279623,216.18126324164,0.013236610812803026,43.582142669514624,217.08252536653757,0.0041603450302098235
0.0043852101527116,220.382884964816,0.013923042234859328,44.4291896089069,221.34931022944755,0.004375623135840681
0.0046549005849307,224.090084212523,0.014779309357154973,45.176560977244634,225.13320127660108,0.004644100039211382
0.005007991186297,226.926329002423,0.015900372016492977,45.74834792688847,228.06277405800586,0.004995492908577895
0.0054129586465689,228.721960787691,0.017186143702856257,46.1103472947985,229.96002330299694,0.005398361238996869
0.0058626367855694,229.716127853797,0.018613871794182845,46.31077137532548,231.06287007519123,0.005845518403847327
0.0063452332155719,230.245852823235,0.020146115459440783,46.41756392916418,231.7068164563167,0.006325186977308753
0.006850948288435,230.642758032246,0.02175176081578112,46.4975800193008,232.22287964062693,0.006827587178686265
0.0073976417294784,231.002883055442,0.02348751249109392,46.57018122397711,232.71175962276274,0.007370413379162959
0.0079460813940378,231.218604751259,0.02522880842607001,46.613670717853815,233.05588660442834,0.00791467753798129
0.0085070297067966,231.456373244939,0.0270098193190792,46.6616048461797,233.4253794879611,0.008471048845740315
0.0090428855842419,231.72075244123,0.028711161729968033,46.714903692151964,233.8161766930505,0.009002243524973932
0.0095963815718682,231.910680071129,0.030468511490681534,46.75319310233961,234.13618344768304,0.009550628776863941
0.0101486542663294,232.094867410952,0.03222197729559584,46.79032527004792,234.4503179772953,0.01009750246480543
0.0107125039306651,232.224647198744,0.03401219997986169,46.8164888752668,234.71235464465786,0.01065553157697902
0.0112649501701556,232.380168077399,0.03576621679024403,46.847841884403636,234.99791909132327,0.011201973133106936
0.0118244648315342,232.594897097074,0.03754267584012109,46.891131254770116,235.34520727779267,0.011755102096656483
0.0123929132661136,232.818534942611,0.03934749961991068,46.93621664443038,235.7038348528984,0.012316749729636093
0.0129635912620143,233.003722501539,0.0411594022568954,46.97355045631026,236.02428752257674,0.012880283122130057
0.0135302860700426,233.104020887053,0.04295865827238525,46.99377061082989,236.257984973732,0.013439569117650797
0.014088028979024,233.266064432211,0.0447294920084012,47.02643858953374,236.55232350775486,0.013989714989690915
0.0146443269203539,233.427761127834,0.04649573797212363,47.059036643371336,236.8461535740763,0.014538134256190252
0.0152039266305703,233.625349096412,0.0482724670520607,47.09887037783667,237.17737176311525,0.015089505249972083
0.0157634890514363,233.836472944148,0.05004907773831026,47.14143294554024,237.52255162522954,0.015640535690641652
0.0163222006581625,233.942486170159,0.05182298708966593,47.16280521190405,237.76094237189773,0.016190425514317996
0.016877588104665,234.067209351919,0.053586342232311374,47.18794940534687,238.01769930016906,0.01673674414309777
0.0174433816169927,234.277726529899,0.05538273663395182,47.23038966842764,238.3643223181215,0.01729299218393057
0.0180250875947112,234.471058777656,0.05722965311320805,47.26936544957545,238.69742015054794,0.017864561827335836
0.0186012588602355,234.607702630268,0.05905899688124771,47.296912850262025,238.97170123749876,0.0184303713406013
0.0191609370397782,234.686411597218,0.060835975101295785,47.312780577999156,239.1832231539238,0.018979678020980204
0.0197268534310268,234.7714631345,0.06263275964351009,47.3299269679152,239.402765377542,0.019534800679938007
0.0202988248754682,234.884361485411,0.06444876897961153,47.352687275458855,239.65223800518956,0.020095549954333214
0.0208550386543553,234.958834238657,0.06621474772757807,47.367700982513256,239.85890980888647,0.020640549331981874
0.0214092704938522,234.968977036251,0.06797443381798073,47.36974577050821,239.99949142328384,0.021183311452066124
0.0219564718945429,235.085728589479,0.06971179826517371,47.39328288363897,240.24738178206204,0.021718899773255907
0.0225122884401131,235.244442043156,0.07147651579735909,47.42527951590025,240.54033277636498,0.0222626268969441
0.0230732478448344,235.408184593235,0.07325756190734921,47.45829001399618,240.83981598105723,0.022811085427602087
0.0236265286493935,235.539082340083,0.07501422846182436,47.48467899976074,241.10405321704283,0.023351741975661453
0.0241890570691319,235.647995534361,0.07680025619449378,47.50663589972718,241.3480983465682,0.02390113562009955
0.0247432797444388,235.713304522265,0.07855991318859318,47.519802191688626,241.5456247555455,0.024442122434418474
0.0253046893167775,235.825200752483,0.08034238858076856,47.542360471700576,241.79268419059125,0.02498982628803112
0.0258654275357358,235.967648408187,0.08212273242596116,47.57107791909049,242.0710525188669,0.025536575900186587
0.0264395968749153,236.048708925608,0.08394572007785607,47.58741971940257,242.2897416324453,0.026096111980184862
0.0270161544711447,236.118786936149,0.08577629044588442,47.60154744632764,242.49780855755532,0.026657660590133924
0.0275892038555419,236.200346002237,0.08759572224134553,47.61798975405099,242.71692549884224,0.02721548002434699
0.0281491356652663,236.201804044346,0.0893735057372205,47.61828369534015,242.85068067077094,0.027760230115160354
0.0287148416880412,236.1741414153,0.0911696223595308,47.61270690932448,242.95584449684938,0.02831029666624724
0.0292859023518018,236.27401216551,0.0929827399669707,47.632840852566815,243.19350981405753,0.028865263111299357
0.029863681430799,236.428942379438,0.09481718854278683,47.66407478369471,243.4895809956783,0.02942644535732066
0.0304439515408924,236.631970900383,0.09665954614233337,47.705005333517214,243.83598315550012,0.029989730292201065
0.0310499485167434,236.703713164337,0.09858358654066028,47.719468573930335,244.05335127181166,0.03057765053129513
0.0316216892849215,236.479958529643,0.10039886347962575,47.67435963957603,243.9578543003785,0.031132019702172838
0.0321619294193075,236.353996400331,0.1021141259063013,47.64896567430673,243.95559695052967,0.03165556310258513
0.0327143480784349,236.389932122891,0.1038680551490308,47.656210315974825,244.12327464459685,0.03219062535142486
0.0332848203213182,236.497094256293,0.10567930452018529,47.67781420206867,244.36885754512758,0.03274287364475187
0.0338626334198553,236.601485491672,0.10751386110804056,47.69885947512108,244.6134348614697,0.033301917570273405
0.0344493395941695,236.686037862272,0.10937665321148816,47.715905233034036,244.83971555778786,0.033869246094892114
0.0350238087369273,236.693334142052,0.11120059273974417,47.71737616303769,244.98323620634883,0.03442443006331111
0.0355931940243149,236.626285597876,0.1130083910271998,47.70385917653181,245.04857089241415,0.034974396861593766
0.0361722860026467,236.605563112991,0.11484700805840327,47.69968152357898,245.1641272117314,0.03553342924146117
0.0367508731416599,236.642594609422,0.11668402222477019,47.70714707325948,245.3394165838261,0.03609166233513468
0.03734966293631,236.682054385374,0.11858517982278424,47.7151021640914,245.52204933974107,0.03666905942931608
0.0379414861750777,236.711571315642,0.12046421860587168,47.721052777233425,245.69276012619537,0.037239411454442435
0.0385360684967434,236.70796615955,0.1223520174771603,47.72032597776528,245.82976055719928,0.03781209507105874
0.0391357208320715,236.700687326834,0.124255913641827,47.71885856508973,245.9641393468164,0.03838932998858348
0.0397198110984903,236.695023718269,0.1261104002377067,47.71771678160303,246.0965053483113,0.038951264449941785
0.0403037257849777,236.640298046519,0.12796432936730417,47.70668408617823,246.1777837286613,0.03951271454074325
0.0408890320892853,236.598936350428,0.12982267688348081,47.69834556824629,246.27323785115146,0.04007518653429077
0.0414697071994371,236.60949783002,0.1316663203582128,47.70047476253203,246.42162442563674,0.040632895553631976
0.0420605085315576,236.541598864283,0.13354211458769538,47.68678633103946,246.49065880138244,0.041200011253221404
0.0426531926173417,236.467588497851,0.13542388656005988,47.67186584116676,246.55368609780814,0.04176861124987872
0.0432220295312611,236.406181852451,0.137229943761754,47.65948626145412,246.62413682585031,0.04231402923268113
0.0438028283352638,236.457308025331,0.13907397996446255,47.66979329790673,246.8148068973832,0.042870609875989694
0.0443983271371492,236.422147627478,0.1409646886604487,47.66270496169957,246.9188954803102,0.04344095609619709
0.0449945312986165,236.432045231228,0.14285763687310737,47.66470031861556,247.07019429038036,0.04401165219601542
0.0455902636134893,236.443832014483,0.1447490869728285,47.66707653411978,247.22336864580686,0.04458157151471284
0.0461831669782291,236.461108727991,0.1466315551558774,47.670559519562985,247.38163159623298,0.04514846214631467
0.0467873560610549,236.456594185282,0.1485498554938493,47.669649387752855,247.51977305041316,0.045725812943144414
0.0473984872684754,236.444421078708,0.15049019707740938,47.66719528946753,247.65152896090916,0.04630945858922218
0.0480086636080906,236.380928011655,0.15242750695568763,47.654395087149645,247.7292604679348,0.046891852666293705
0.0486146034340279,236.305862707941,0.15435136590303858,47.639261921920905,247.79377851262336,0.04746986766053018
0.0492336795734253,236.215664999862,0.15631693264562532,47.621078063972185,247.84543136068882,0.048060068736921376
0.0498496984522927,236.178826641321,0.1582727925860293,47.61365145089031,247.95226993020717,0.04864700959215463
0.0504559230537597,236.14458204794,0.16019755569568703,47.606747740864705,248.0594749093131,0.049224282358646045
0.0510711098994996,236.044508731137,0.16215077393091124,47.586572960197216,248.0995637777183,0.049809748882431504
0.0516663650539786,235.92309429554,0.16404070904638204,47.56209580998087,248.1123830100776,0.05037592053007662
0.0522623576602548,235.870755733944,0.16593298557130898,47.55154435596312,248.19791753170597,0.05094247263403685
0.0528747522843345,235.890838873466,0.167877338502762,47.55559311689075,248.36350854504437,0.051524282377888246
0.0534925159456336,235.846200045102,0.16983873812738667,47.54659392909256,248.46220666173173,0.05211085024601763
0.0541040229674512,235.840203389357,0.17178027292165754,47.54538500329437,248.60010717018312,0.052691138766791684
0.0547215496715945,235.899719888613,0.17374092020731252,47.557383529544374,248.80851812801296,0.05327679813075824
0.0553526008858917,235.843654358408,0.17574450781270615,47.546080718655055,248.89821402957918,0.05387492993853798
0.0559862711362507,235.744530488328,0.17775641085759597,47.526097346446925,248.94298769113564,0.05447518438161391
0.0566199369390826,235.644094412042,0.17976829978158723,47.50584943346767,248.986248177719,0.055075074526225544
0.0572555317583915,235.563971250418,0.181786313332893,47.48969660408427,249.05131168747917,0.055676429570905434
0.0578837914050079,235.525115957395,0.18378103771090007,47.48186337701083,249.15820264011316,0.05627048941198777
0.0585230035265781,235.3959684474,0.18581053619688545,47.455827238995845,249.17204753898946,0.05687454354991373
0.0591553574947331,235.291553458027,0.1878182600457776,47.43477717713825,249.21030941832768,0.05747175793203065
0.0597832006259903,235.183560204175,0.1898116619875192,47.413005737161676,249.24358616779588,0.05806435949400127
0.0604074014495128,235.027954752421,0.19179349960220313,47.38163567808808,249.22538276700845,0.058653175274003135
0.0610372973495217,234.964325262322,0.19379341908473138,47.36880797288411,249.30591264988809,0.05924701202956511
0.0616733026387218,235.005905878658,0.1958127358779417,47.37719062513746,249.49949623379945,0.05984625085961132
0.0623164380199568,235.025987623682,0.19785469071336284,47.381239104934295,249.6719700145123,0.06045184267446725
0.062963342980218,234.981143075259,0.19990861396219212,47.37219844397222,249.7763413805902,0.061060614268704495
0.0636140793134995,234.872355956224,0.20197470182036087,47.35026696077476,249.81354463657175,0.06167261771308495
0.0642572913346456,234.788060410843,0.20401689998749975,47.33327297882595,249.8749052105589,0.06227717685101886
0.0649109714711968,234.616082624685,0.20609233442104982,47.2986022571365,249.84524047061987,0.0628912008044172
0.065565529341386,234.496209219639,0.20817055565890055,47.274435778679226,249.87107730567303,0.06350567168971895
0.0662128989174734,234.499560387046,0.210225954062978,47.27511137402848,250.02645607514543,0.06411302336136172
0.0668669881466438,234.461563391325,0.21230268736559404,47.26745117969113,250.1393019714563,0.06472630489257665
0.0675331469570063,234.390100581482,0.21441774158849497,47.25304427722677,250.21920168931868,0.06535051665215875
0.0681806576356839,234.195936880498,0.21647358799329636,47.2139008751084,250.16356987261545,0.06595688132248569
0.0688173165256638,234.023233622914,0.21849497996898254,47.17908389837947,250.12808456550144,0.06655272550812741
0.0694663543557198,233.955128113097,0.22055567507941035,47.165353827600356,250.2071379459392,0.06715978981753279
0.070119119238924,233.936512317616,0.22262820358358368,47.16160088323139,250.33993451915296,0.06776996866900982
0.0707655513936584,233.91835074797,0.22468062567486538,47.157939510790754,250.4717118197453,0.06837386124038197
0.0714465472843626,233.904545762509,0.22684278762785126,47.15515642572182,250.61621795135747,0.06900964881161646
0.0721303792459202,233.866080073043,0.2290139541057966,47.14740174272547,250.73492912146835,0.06964767768409778
0.072805801653767,233.766342465642,0.2311584202507102,47.12729464107343,250.78588842852207,0.07027746092537594
0.0734855561815728,233.621777867808,0.23331664087649365,47.09815041815009,250.78960415055172,0.07091088336175874
0.0741732465555179,233.493715308483,0.2355000578137693,47.07233300619018,250.812702223223,0.07155129271968076
0.0748555604906001,233.407249877611,0.2376664045576553,47.054901575326376,250.87908038976911,0.0721862902178735
0.0755348259278651,233.31669931415,0.2398230723209717,47.03664658173264,250.94023558290837,0.07281805035235672
0.0762280995254407,233.218412205895,0.2420242159932742,47.01683190070843,250.99620854269122,0.07346242767976888
0.076905606006975,232.979824223141,0.24417529907214564,46.96873256338523,250.8972787924202,0.07409174902860452
0.0775649880121633,232.809793313817,0.24626883693861845,46.934454332065506,250.86768214131746,0.07470385487735136
0.0782444529766106,232.70298950286,0.24842613820073867,46.91292268377658,250.91070762253324,0.07533421206387005
0.0789228760602499,232.671762284918,0.25058013149129343,46.906627276639476,251.0348869424505,0.07596320648342614
0.0796040779517568,232.66908836785,0.2527429474968278,46.906088214958565,251.19049661524855,0.07659437943482765
0.0802911792410067,232.566608925019,0.2549244940901963,46.885428359283836,251.23965620769084,0.07723061520611314
0.080982589025346,232.444811763272,0.2571197201554735,46.86087405147564,251.26879442537097,0.07787043216783046
0.0816801107105785,232.413364801064,0.25933435150608675,46.8545343438945,251.39691416863297,0.07851549041894308
0.0823815535237006,232.350030484863,0.26156143243774943,46.84176614574838,251.49138695748522,0.07916375553012733
0.0831038015089076,232.291658804585,0.26385456979078165,46.82999841500434,251.59597871005613,0.07983080969450619
0.0838340687830614,232.178601845441,0.26617316838621996,46.8072061320409,251.64307872250671,0.08050481822221849
0.0845406710959391,231.980867422943,0.26841663072960664,46.767342872465306,251.59268563629666,0.08115655274475618
0.085231825461901,231.793176788723,0.27061104584153567,46.72950444060656,251.549332376039,0.08179362818970216
0.0859361120905436,231.688354273331,0.2728471558874759,46.708372221503524,251.5987506562375,0.08244239113536268
0.0866552961323964,231.557573775191,0.27513056522035856,46.68200687307851,251.6232639023794,0.083104442973918
0.0873776494847047,231.416197378726,0.27742403711393737,46.653505391551164,251.63680075836757,0.08376897143044132
0.0880920759339576,231.33531965139,0.2796923410903154,46.637200441720225,251.7141281963266,0.08442577346872149
0.0888047228369145,231.207253494896,0.2819549950072035,46.61138230457104,251.73954955939448,0.08508050999901295
0.0895133048689362,231.067828808467,0.28420474295887244,46.58327428778694,251.75147381400248,0.08573108723153985
0.0902404949730839,231.008383016568,0.2865135715395414,46.57129001614011,251.85469384291486,0.08639830949414425
0.0909564893610915,230.907966906949,0.2887868537214655,46.55104612844092,251.91054494231219,0.08705482462676802
0.091665139221397,230.752075282144,0.2910368170279355,46.51961837688024,251.903996388508,0.08770418123162009
0.0923905078583428,230.643232826917,0.29333986245023835,46.49767573790647,251.9524782418859,0.0883684213251233
0.0931353964228394,230.565190112792,0.29570488364251507,46.481942326738874,252.03897049525423,0.0890500774810905
0.093871842549297,230.46443594848,0.29804310009401797,46.461630287213566,252.09855719304826,0.08972355138750462
0.0946205687234242,230.383707210514,0.30042030569687184,46.44535537363962,252.1827446113837,0.09040779063775964
0.0953607033280752,230.279575605197,0.30277023306663875,46.42436244200771,252.23919789699926,0.09108371845712121
0.096100566504764,230.069403882253,0.3051192986526257,46.3819918226622,252.17920393075087,0.09175894207615927
0.0968582023386112,229.874767605117,0.30752479242509057,46.34275314919159,252.14002435835468,0.0924499134475825
0.0976043552728001,229.721142513981,0.3098938279911403,46.311782330818566,252.14292652158915,0.09312994597796702
0.0983464374452688,229.647347454778,0.31224993888872843,46.29690524688324,252.2323459457112,0.09380581012135088
0.0990956389098037,229.55466140871,0.31462865353862673,46.27821973999594,252.30252724572975,0.09448769521095211
0.0998555886111267,229.447394894009,0.31704149384032726,46.256594810632215,252.3589995664399,0.09517888810515304
0.10061930509705,229.32503980653,0.31946629368313373,46.23192802499644,252.39956595321638,0.09587302601035885
0.101388261429462,229.176799503712,0.32190773003854184,46.20204277994834,252.41263676536178,0.0965714399262401
0.102139573362687,229.011914147169,0.3242931454265312,46.16880189206927,252.40309335313316,0.09725335730479673
0.102880060688898,228.660222378683,0.32664419268725114,46.097900831542496,252.1847999341388,0.09792499518285616
0.103624331973469,228.473588060396,0.3290072540157641,46.060275352975836,252.1490109967361,0.09859961093732557
0.104365422424858,228.466855553729,0.33136021619892414,46.058918079631766,252.31089544367296,0.09927089166020187
0.105128327222147,228.52233846926,0.3337824389303167,46.070103435402814,252.54650964542662,0.09996146145948658
0.105903389505211,228.442533237196,0.3362432616790449,46.05401470061871,252.6353718141719,0.1006625480236883
0.10666953693987,228.235120955212,0.3386757797840872,46.01220038457074,252.5808556209197,0.10135508787728853
0.107428140505888,228.028028662842,0.34108434610619437,45.970450578428945,252.5246557653144,0.10204033641300582
0.108207367647174,227.924836600147,0.3435583922797774,45.94964705858963,252.58798319006115,0.10274372573001758
0.109001276078705,227.881645624554,0.34607905154988833,45.940939757910094,252.72103579254562,0.10345985902465085
0.109790728042183,227.76193539155,0.348585561533931,45.91680617493648,252.76808409848493,0.10417146425427634
0.11059608636072,227.576644861665,0.351142574195286,45.879451604111665,252.7457311304686,0.10489688592281655
0.11138962579198,227.389716462893,0.35366206188953647,45.84176683891923,252.71857188863908,0.10561114745983406
0.11216517336403,227.179645333921,0.3561244254307952,45.799416499318475,252.66128963757913,0.10630872199570213
0.112945916991307,226.992936679415,0.3586032864473997,45.76177603457007,252.6308620632212,0.10701047901152178
0.11373152014164,226.835700774965,0.36109757644970697,45.73007727623294,252.63406984649598,0.10771610719980691
0.114520396564209,226.740813403828,0.36360225909136357,45.71094798221173,252.70726127212572,0.10842417476578882
0.115318304301853,226.668451745331,0.36613561615838325,45.69635987185873,252.80747323932897,0.10913983888211248
0.116110476769591,226.453631592083,0.3686507637434514,45.653052128963935,252.7472707224451,0.10984985258072288
0.116896835339115,226.184914843327,0.3711474522016901,45.59887883241472,252.62521558995917,0.11055415712801718
0.117678983784939,226.011127712641,0.3736307735171813,45.563843346868424,252.60788754595268,0.11125419914142452
0.118474759318303,225.952825329376,0.37615736083561196,45.5520895864022,252.7225319275644,0.11196593514742258
0.119278905686989,225.915385831529,0.37871052555619006,45.54454178363624,252.86232583136766,0.11268464374870964
0.120091023598374,225.819835376879,0.3812889999248374,45.52527881197881,252.93877055610474,0.11340995307466556
0.120909516820085,225.669920742236,0.38388771590376985,45.49505602163478,252.95556182000666,0.11414042434706698
0.121733386130958,225.442788856695,0.3865035009657916,45.44926623350971,252.88670292302706,0.11487515509430378
0.122546831528448,225.267634674855,0.38908619010282236,45.41395515045077,252.87346955016642,0.11560006050202476
0.123356355688513,225.10362569654,0.39165642931102873,45.38089094042247,252.8715886147363,0.1163209501643492
0.124169064635766,224.935336847244,0.39423678021855707,45.3469639084044,252.86534722709726,0.1170441535375576
0.12497675458453,224.684368294735,0.39680119580588274,45.296368648218575,252.76469145008625,0.11776237285138023
0.125781067885706,224.422651083052,0.39935489053711654,45.24360645834329,252.65077179401948,0.118477077318812
0.126588277474348,224.244257499601,0.4019177809810549,45.207642311919564,252.63095178998964,0.11919384220008129
0.127387193945679,224.146053712566,0.4044543407775308,45.1878444284533,252.69939052900722,0.11990273767380566
0.128194547676274,223.913926658111,0.40701768887216994,45.14104761427517,252.61847120446592,0.12061860954860934
0.129010574779875,223.80602515585,0.4096085749261031,45.11929467141936,252.67936910040532,0.12134165162487735
0.12985237322446,223.717676678093,0.4122812849876605,45.10148361830355,252.76794792700582,0.12208698102549308
0.130658579623799,223.521999614654,0.4148409903055618,45.06203512231425,252.72706659897605,0.12280027678060167
0.131455562755018,223.217060320577,0.4173714117471821,45.00055936062832,252.56018460153925,0.12350491245681626
0.132259089787348,223.040665590682,0.41992261007482984,44.9649981830815,252.53982100726986,0.1242148314964572
0.1330718295404,222.960774882266,0.42250305879077,44.94889221626483,252.63057311159443,0.1249323776889268
0.133903571821237,222.864323043513,0.42514384053242743,44.92944752557222,252.70665193056138,0.12566616802265348
0.134742684869626,222.703124120075,0.4278080244610626,44.89694982260712,252.71074099286747,0.1264059158649447
0.135564443378194,222.433071442812,0.43041710772576597,44.842507202870905,252.58708696185886,0.12712983425839092
0.136386460038536,222.187911891068,0.43302701062235177,44.79308303723931,252.49133465724492,0.12785345614209903
0.137207471125679,222.013605943963,0.4356337208240308,44.75794295830294,252.4755313710272,0.12857567052838456
0.138027252486509,221.70928793017,0.438236526644666,44.69659244672227,252.3112117939117,0.1292962831208324
0.138840550002224,221.434015950229,0.4408187462570612,44.64109761556617,252.17803651396005,0.13001068344694378
0.139658997563195,221.328409140976,0.4434173172631441,44.61980728282076,252.2389128938614,0.1307290927150486
0.140488787520352,221.199078048569,0.44605190037711756,44.59373413459151,252.27506832423217,0.13145693149744428
0.141312078611357,221.04309874474,0.44866584959105843,44.56228870693959,252.2791584910547,0.1321785467259692
0.142130545514256,220.807909564157,0.45126448200776276,44.514874568134054,252.19145820437316,0.13289541776034744
0.142958599803148,220.57894648168,0.4538935543749949,44.46871561070669,252.11260381675447,0.13362016351202527
0.143783776528519,220.304799037118,0.45651349047804785,44.41344748588299,251.98105503003126,0.13434186856260596
0.144597609372831,220.046584042264,0.4590974097587384,44.36139134292043,251.8647940454331,0.13505314237704658
0.14540913403333,219.84054855707,0.46167400055582275,44.31985458910532,251.8073723481658,0.13576189548164508
0.146219282441991,219.520849442978,0.4642462217533214,44.255403247704365,251.61903052958658,0.13646894592366898
0.147005761439247,219.244937610583,0.4667432925696092,44.19977942229353,251.47520660572698,0.13715486118540024
0.147811887417602,219.04067186936,0.4693027425508864,44.15859944886298,251.41748699958976,0.13785742333617917
0.148611188831474,218.822783599983,0.4718405245399299,44.11467317375657,251.34229761418888,0.1385535506782329
0.149400473792356,218.598385024422,0.4743465042907303,44.06943442092347,251.2570873173145,0.13924047929983743
0.150205990441946,218.336916461133,0.47690401965317847,44.016722358564415,251.1324292482179,0.13994104845813785
0.151018009559675,218.132495899005,0.4794821803519681,43.97551117323941,251.0744312499567,0.14064677649802507
0.151824988608516,217.936738208262,0.4820443388320383,43.93604642278562,251.0249810041085,0.1413476311220833
0.152626698121494,217.489660535819,0.48458976653574337,43.84591556402112,250.6843892989657,0.14204342314058283
0.153434834042865,217.117403908193,0.4871555980860964,43.770868627891716,250.4307767446643,0.1427443029247353
0.154237154889101,216.919848963848,0.48970296677289565,43.73104155111176,250.37694930700545,0.14343965380857995
0.155062543567638,216.772117430729,0.4923235758272506,43.70125887403497,250.38535333408058,0.14415449278269493
0.155879562821356,216.476552978191,0.4949176119578053,43.64167308040331,250.22082341750553,0.1448615804120214
0.156701997680146,216.143797929745,0.49752884263446356,43.57458966263659,250.01396285150986,0.14557285036894732
0.157514505023394,215.85080695877,0.500108553449276,43.51552268288803,249.8504399757808,0.14627503823744087
0.158323272907929,215.526928092271,0.5026763914826745,43.450228703401834,249.6498567476312,0.14697350505158674
0.159120090101328,215.096507120776,0.5052062860717164,43.36345583554845,249.3226827143148,0.14766117426285477
0.159881600912053,214.65499986327,0.5076240828957682,43.27444797243524,248.9743848851861,0.14831793172969748
0.160657326940646,214.308503485001,0.510087013036551,43.204594302576204,248.73873479555138,0.1489865057821966
0.161459467691783,213.951964427711,0.5126338099214109,43.13271602862654,248.4965347158205,0.1496773760992249
0.162245306978049,213.662986138846,0.5151288496553056,43.07445800559136,248.3288029147897,0.15035374370391436
0.163026960942968,213.412249579995,0.5176106009939234,43.023909515327,248.2042000570238,0.15102605550597303
0.163835349811211,213.106048376699,0.5201772356505949,42.96217935274252,248.02035235938035,0.15172088725173685
0.164634161500276,212.694308234972,0.5227134627633763,42.87917254017036,247.71105732711786,0.15240701323837513
0.165404374755693,212.083086745823,0.5251588898493252,42.75595028795792,247.16255710527327,0.15306812958601124
0.166170050601368,211.687714580697,0.5275899106593434,42.676243259468514,246.86387282425935,0.1537249182905638
0.166968680735853,211.399231385948,0.5301255613363333,42.61808504740712,246.69628215903307,0.15440951552856755
0.167814352108409,211.057123348372,0.5328105679441986,42.54911606703179,246.4755377609436,0.15513392666025871
0.168656818734653,210.644897414461,0.5354853994825233,42.466011318755335,246.17159569507132,0.1558550711565122
0.169437119091681,209.947858206789,0.5379628531160872,42.32548821448866,245.52081846081606,0.1565225382529994
0.170202070817333,209.177807267135,0.5403915748450322,42.17024594505441,244.78030323303037,0.1571764439972771
0.170990407480461,208.713467650179,0.5428945437504636,42.076635078276084,244.40146853034312,0.1578498928488604
0.171825027845025,208.472393880733,0.5455444634079544,42.02803460635577,244.29316876420899,0.15856238636182543
0.172667882701781,208.009946755213,0.5482205275781546,41.93480526585095,243.92658384234582,0.1592813946294771
0.173500861531104,207.399391994287,0.5508652353612552,41.811717426048254,243.38336518632292,0.1599914704638519
0.174305358452352,206.70134703706,0.5534195130862176,41.6709915626713,242.73049942493876,0.16067678848191247
0.17510329767792,205.910432007648,0.555952970127396,41.51154309274184,241.96602767847233,0.16135605664938704
0.175923064901432,205.199365867576,0.5585557310620466,41.36819215890332,241.29866722683028,0.16205342633420444
0.176737223302038,204.502100323469,0.5611406839839707,41.22762342521135,240.64523369407368,0.16274554362558596
0.177560357818022,203.831252629321,0.5637541360722199,41.09238053007112,240.02360278067889,0.16344480488816004
0.178407243112743,202.983077730221,0.566442996882959,40.92138847041255,239.19672902660935,0.1641637327128576
0.179234242204688,202.21175039759,0.5690687189998844,40.76588888015415,238.45502024498558,0.16486528053597987
0.180039628368259,201.359453411721,0.5716258200692224,40.594065807802956,237.61213457240302,0.16554802127659626
0.180809691297753,200.19255779692,0.5740707698703658,40.35881965185907,236.38931237228869,0.16620038223024908
0.181565175990866,199.079636394084,0.5764694337709995,40.13445469704733,235.22556561217348,0.1668399798904925
0.182353476281936,198.196610707247,0.5789722871951467,39.956436718580996,234.3384516570111,0.16750692358547345
0.183229799546519,197.320030371538,0.5817546135601978,39.77971812290206,233.47493998302795,0.1682478176504793
0.184120724659465,196.221700910246,0.5845833007938013,39.5582949035056,232.35018267575327,0.1690004946587187
0.184963630569715,194.93242659659,0.5872595270588451,39.29837720187255,230.98783593565975,0.1697120826137504
0.185755528674012,193.431823333156,0.589773803539988,38.99585558396425,229.36285393878447,0.1703801483613631
0.186582978013875,191.967604059809,0.5924009551940531,38.70066897845749,227.7854913074766,0.17107772956327397
0.187454176024087,190.387487759055,0.5951670088764762,38.382117532225486,226.07641740222462,0.17181166757080452
0.188300883982834,188.735701343741,0.5978553066454979,38.04911739089819,224.27480074588757,0.17252445821900658
0.189142243302622,186.995205735395,0.6005266224858248,37.69823347625563,222.36389843502292,0.1732322432719955
0.189944202897112,184.982619090753,0.6030728441983306,37.29249600869581,220.11899522376618,0.17390641770239176
0.190737097340857,182.994932227187,0.6055902840572209,36.8917783370009,217.89885442828754,0.17457252489866615
0.191516494998514,180.867043625209,0.6080648716202819,36.46279599484213,215.50606588105234,0.17522686135383772
0.192312770306364,178.74459468819,0.6105930457227057,36.034910289139106,213.11946286996402,0.17589492542122276
0.193214326491576,176.46716099338,0.6134554866107538,35.57577965626541,210.5631446525964,0.17665078036778356
0.194225578128982,173.954497534943,0.6166662105595179,35.06922670304451,207.74091038680385,0.17749792353224683
0.195209783461744,171.165702531537,0.6197910624910372,34.50700563035786,204.57892225879564,0.17832172099020968
0.196233240461495,168.184420219025,0.6230405384652467,33.905979116155436,201.18779399374205,0.1791776536233491
0.197289385993792,164.960759014275,0.6263938005302896,33.256089017277844,197.50576587327123,0.1800601567500532
0.198505891649086,161.622079730131,0.630256205985848,32.58301127359441,193.70501477714032,0.18107569073260643
0.199015181225588,160.345813887736,0.6318732003912418,32.325716079767574,192.25706509736818,0.18150053753785406