File: example/data/02 processed data/test_ID_094.csv
Strain,Stress_MPa,Displacement(mm),Force(kN),True Stress (MPa),True Strain
0.0001922326436001,10.9429727722271,0.0006103386434303175,2.2061033108809833,10.945076368811948,0.00019221416927304053
0.0002418200896678,14.4419348966489,0.0007677787846952649,2.9114940751644185,14.445427246640586,0.00024179085590278395
0.0003058564363903,17.8841762252346,0.0009710941855392024,3.6054499270072955,17.889646215642625,0.00030580967184565814
0.0003631707989844,21.48702410366,0.00115306728677547,4.331784059297856,21.494827563371526,0.00036310486843200285
0.0004709955854777,28.4546474077748,0.0014954109838916975,5.736456917407399,28.46804942109019,0.00047088470187279656
0.0005978515200501,35.6304139950299,0.0018981785761590674,7.1830914613980275,35.651715692196845,0.0005976728780275848
0.0007358629424648,43.1737405611551,0.00233636484232574,8.703826097128868,43.20551051692164,0.0007355923280782972
0.0008662461998137,50.8500642563026,0.0027503316844084973,10.251372954070606,50.8941129312249,0.000865871225105654
0.0010102278666072,58.5247454037192,0.00320747347647786,11.79858867338979,58.58386873241212,0.0010097179298418496
0.0011497599344323,66.3183206498186,0.003650487791822552,13.36977344300343,66.3945707978206,0.0011490994666833521
0.0012954167869873,74.083343364458,0.004112948298684677,14.935202022274735,74.17931217108845,0.001294578458572886
0.0014431631707031,81.8883536364297,0.0045820430669823425,16.508692093104226,82.0065318925073,0.001442122811552785
0.0015850120239308,89.6123072421891,0.00503241317598029,18.065841140025324,89.75434382666016,0.0015837572181194538
0.0017341164214966,97.3526112597922,0.005505819638251704,19.626286429974108,97.52143202165338,0.0017326145776123375
0.0018846501439342,104.963973189586,0.005983764206991085,21.16073699502054,105.16179355676566,0.0018828764190692857
0.0020248227051025,112.453711345584,0.0064288120887004375,22.67066820726973,112.68141017358958,0.0020227755146083695
0.0021693891919302,119.853438943417,0.006887810684378384,24.162453290992868,120.1134476984765,0.002167039464898378
0.0023172225108585,127.142187354785,0.007357181471975737,25.631864970724656,127.4368040934033,0.0023145418910391806
0.0024621904470262,134.336874332627,0.007817454669308185,27.0823138654576,134.66763730129213,0.0024591642225368594
0.0026011376581027,141.306944146015,0.008258612064476072,28.487479939836625,141.67450295978463,0.0025977605544845257
0.0027350002566441,147.986738643192,0.008683625814845016,29.83412651046751,148.39148241136107,0.002731266948958073
0.0028761024798138,154.518045784037,0.009131625373408815,31.150838030061866,154.96245551869248,0.0028719744103497015
0.0030140599128059,160.84167464706,0.009569640223158732,32.42568160884729,161.32646109092227,0.0030095267407774236
0.0031480099153396,166.984166345738,0.009994931481203229,33.66400793530078,167.5098341570991,0.00314306530652672
0.0032772230472278,172.976816593622,0.010405183174948264,34.872126225274194,173.54370020359872,0.0032718646556816593
0.0034095754655767,178.615118080005,0.010825402103206023,36.00880780492901,179.22411980439168,0.0034037760417923125
0.0035487337717319,184.271752763986,0.011267229725248781,37.14918535721958,184.92568415619579,0.0035424518735100935
0.0036939982816397,189.728522195215,0.011728444544206046,38.24927007455534,190.42937903018216,0.0036871922258767636
0.0038420980682288,194.909581798311,0.01219866136662644,39.2937716905395,195.65844352601755,0.0038347360604578436
0.004015619504203,199.682386391224,0.012749591925844525,40.25596909647076,200.48423487666236,0.0040075784236268215
0.0042308369778714,203.834717813734,0.013432907404741694,41.09307911124877,204.6971092752343,0.004221912151240506
0.0045028832917623,207.206082561225,0.014296654451345302,41.77274624434296,208.13910736834148,0.004492775643807103
0.0048241130420473,209.969324962855,0.015316558908500177,42.32981591251157,210.98224072183817,0.0048125142962092355
0.0051924936057501,211.87344581218,0.016486167198256567,42.71368667573549,212.973597324788,0.005179059096495009
0.005608156123848,213.115758985348,0.0178058956932174,42.964137011446155,214.3109454341902,0.005592488964915067
0.0060786675240654,213.829267972315,0.019299769388907644,43.107980423218706,215.12906499923298,0.006060266954278142
0.0065909028048505,214.111524598504,0.020926116405400336,43.16488335905841,215.5227128465311,0.006569277771946644
0.0071139554728923,214.234535377,0.02258680862643305,43.189682332003194,215.75859032242772,0.007088770663523864
0.0076495010555459,214.317651256346,0.02428716585135823,43.20643849327936,215.95707435585356,0.007620391974731778
0.0081911553507798,214.388649422664,0.026006918238725862,43.22075172360906,216.14474015552892,0.008157789914939184
0.008738911099632,214.46184981905,0.027746042741331602,43.235508923520484,216.33601285888133,0.008700947827481818
0.009298731669304,214.543349059065,0.0295234730500402,43.25193917030751,216.53833009339908,0.009255764617979587
0.0098539529052007,214.602861648489,0.03128630047401222,43.26393690833538,216.7175481404945,0.009805719313463622
0.0104045542147448,214.694011615489,0.033034459631814735,43.28231274168258,216.9278070989234,0.010350799382411503
0.0109581645733694,214.821652050515,0.03479217252044784,43.30804505338383,217.17570306760766,0.01089855893820127
0.0115093497976202,214.932287650252,0.03654218560744413,43.3303491902908,217.40601853162147,0.011443621080342338
0.0120618178528613,214.98609632184,0.03829627168283462,43.341197018482944,217.57921945657174,0.011989653834514445
0.0126153469889006,215.089103860377,0.0400537266897594,43.36196333825201,217.80252753910733,0.012536436461831
0.0131632141848528,215.212773164081,0.04179320503690764,43.386895069878726,218.04566499255594,0.01307733191783993
0.0137128863985858,215.320322011021,0.043538414315509914,43.40857691742183,218.27298512606507,0.01361971556630273
0.0142632868284134,215.449423827245,0.045285935680212545,43.434603843572596,218.5224407563094,0.014162523169871285
0.0148206187510877,215.533463949124,0.047055464534703446,43.4515463321434,218.7278032464153,0.014711866580617117
0.0153736643043526,215.631742667809,0.048811384166319506,43.4713593218303,218.94679269294642,0.015256686917823874
0.0159359307305804,215.725270151149,0.050596580069592764,43.49021446247164,219.16305311311345,0.015810286863358718
0.0164890172764189,215.835829643958,0.052352629852630006,43.51250325622193,219.39475036782744,0.016354549577742253
0.0170406151767566,215.910336804309,0.0541039531862022,43.527523899748694,219.58958176647513,0.01689705252932265
0.0175951758907494,216.025029512162,0.05586468345312934,43.550645949651866,219.8260279032328,0.017442172919084765
0.0181498700431896,216.095288560041,0.057625837387126976,43.564810173704274,220.01738996435134,0.017987127374237005
0.0186957217894241,216.183362733643,0.059358916681421514,43.582565927102436,220.22506673881335,0.01852310492844194
0.0192395960922661,216.248295434162,0.06108571759294486,43.595656359527055,220.40882529395628,0.019056855250134376
0.0197793802848131,216.356170851924,0.06279953240428159,43.617404043747875,220.6355618321702,0.019586310062875492
0.0203192502369855,216.373840573359,0.06451361950242897,43.620966259589174,220.7703947847067,0.02011556875331088
0.0208598245572007,216.445727059741,0.06622994296911222,43.63545857524378,220.96074695236294,0.020645237452670617
0.0214019415404603,216.486144949677,0.06795116439096144,43.64360682185488,221.1193687682096,0.021176136091613035
0.0219418146452005,216.561988099053,0.06966526149851159,43.65889680076908,221.3137511011185,0.021704557328292535
0.0224796454114902,216.615675352051,0.07137287418148137,43.66972015097348,221.48511892453558,0.02223070204864984
0.0230202150449582,216.675310321415,0.07308918276774229,43.68174256079727,221.663222559947,0.0227592473265085
0.0235546377097431,216.700454608392,0.07478597472843435,43.686811649051826,221.8047553082293,0.02328150789881339
0.0240953605354651,216.810156432202,0.07650276970010168,43.70892753673193,222.0342753191865,0.023809647804318775
0.0246364899913072,216.852253721645,0.07822085572240035,43.71741435028363,222.19473210005071,0.024337905778427822
0.0251732690970618,216.90527591225,0.07992512938317121,43.728103623909604,222.36549079136154,0.024861641325733663
0.0257093563205905,216.954265493159,0.08162720631787483,43.73797992342085,222.53202000999462,0.025384428177691317
0.0262545761510791,216.990522833647,0.08335827927967614,43.745289403263236,222.68751703944542,0.025915840874270808
0.0267949657728814,217.02099011928,0.08507401632889845,43.75143160804684,222.83606012152293,0.026442267171588072
0.027340586299128,217.052002634944,0.0868063614997314,43.75768373120471,222.98633164438326,0.026973508197554646
0.0278858272218524,217.06520209179,0.08853750142938137,43.76034474170487,223.11824481319812,0.027504097851257795
0.0284324317962432,217.086240337902,0.09027297095307216,43.76458605212105,223.25853006021228,0.028035732081385253
0.028977807867588,217.104707820167,0.09200453997959189,43.768309096545664,223.39592633052862,0.028565889921182735
0.0295257422941712,217.108456462899,0.09374423178399355,43.769064822920434,223.51874479830786,0.029098251829891657
0.0300667858403733,217.063015932301,0.09546204504318523,43.75990401195189,223.58940314620304,0.02962364076120387
0.0306140213818656,217.0643763877,0.09719951788742327,43.760178279760325,223.70958984767435,0.030154761886259575
0.0311569634193299,217.088546041347,0.09892335885637242,43.76505088193556,223.85236592911275,0.03068143730658234
0.0317017836742131,217.09672936267,0.10065316316562659,43.766700639514276,223.97908291330455,0.031209655991762408
0.0322500885751049,217.111028348321,0.10239403122595804,43.76958331502152,224.1128782431865,0.03174097159186214
0.0327982459191344,217.130757443114,0.1041344307932517,43.77356070053178,224.2522654223412,0.03227186217466144
0.0333493986227443,217.12695142377,0.10588434062721315,43.77279340703203,224.36800467854255,0.03280536975640527
0.0339064854353785,217.172642097812,0.10765309125732672,43.78200464691891,224.53620312406414,0.033344332378706286
0.0344562604579593,217.164741814148,0.10939862695402076,43.78041194973223,224.64742672038173,0.033875936456975037
0.0350074022386996,217.151046540695,0.11114850210787124,43.77765098260411,224.7529405734997,0.03440857861320651
0.0355597638838473,217.135068139515,0.11290225033121518,43.77442973692622,224.85633989345928,0.03494211518935641
0.0361166013905766,217.118759674605,0.11467020941508069,43.77114195040037,224.96035137218914,0.03547968710886352
0.0366693548614062,217.09998279765,0.11642520168496467,43.76735653200625,225.0608991072622,0.03601303063356752
0.0372234070694677,217.084546790518,0.11818431744555995,43.76424463296843,225.16517324419237,0.03654734198409951
0.0377749292703133,217.066612473334,0.11993540043324472,43.76062907462414,225.26628840646072,0.03707893008629163
0.0383358955834774,217.032045667998,0.12171646847754074,43.753660406668395,225.35216350899486,0.03761933122490165
0.0389070768110428,217.012995927677,0.12352996887506089,43.749819979019684,225.45633722922966,0.03816927290197234
0.0394716390309257,216.976101820551,0.1253224539231891,43.742382127023085,225.5405041899492,0.03871254466420243
0.0400252989594134,216.903686943797,0.12708032419613752,43.72778328786948,225.58532185912148,0.03924503877992375
0.0405851637719197,216.847876099215,0.12885789497584504,43.71653182160175,225.6486826642946,0.03978321239391599
0.041142379310583,216.794341396545,0.130627054311101,43.705739225543475,225.71377642266967,0.04031855195246918
0.0417054014098667,216.76190595371,0.13241464947632675,43.699200240267935,225.80204825187727,0.04085917918236912
0.0422596608339415,216.727913475286,0.13417442314776423,43.69234735661766,225.88676159199937,0.041391106945636594
0.0428095968967317,216.703873652047,0.13592047014712313,43.687500928252675,225.98087912905143,0.04191860604285193
0.0433670977734085,216.679195155491,0.13769053543057197,43.682525743346986,226.07594299726262,0.042453077443450296
0.0439316745274953,216.700071141633,0.13948306662479756,43.686734342153215,226.22006813711232,0.04299404146388407
0.0444987604837483,216.67461047415,0.14128356453590082,43.681601471588635,226.31636206854867,0.0435371153060228
0.0450703050448665,216.665968524467,0.1430982185174511,43.67985925453255,226.43116981870614,0.04408416070863723
0.0456399377328908,216.634801055097,0.1449068023019283,43.67357589270756,226.52199988602882,0.04462907859392293
0.0462195700156619,216.604875506589,0.1467471347997265,43.667542902128346,226.6162597157995,0.0451832575867839
0.0468018520001889,216.527443853412,0.14859588010059976,43.65193268084786,226.6613292346186,0.04573966087384482
0.0473825377001291,216.486115067694,0.15043955719790988,43.6436007976471,226.74377657644348,0.04629423067932948
0.0479629980344439,216.423228554007,0.15228251875935936,43.630922876487816,226.80353543975085,0.046848278056493727
0.048542502812128,216.352101999307,0.1541224464285064,43.61658376306029,226.85437451901817,0.04740110731662134
0.0491240834054942,216.255529229429,0.15596896481244407,43.59711469265289,226.87888388419475,0.04795560974526189
0.0497031599636198,216.181859565737,0.15780753288449284,43.58226288845258,226.9267811129656,0.04850741940434533
0.050274731778279,216.100129905988,0.15962227339603582,43.56578618904719,226.9645059742628,0.049051779257866975
0.0508475173628797,216.046214764814,0.16144086762714305,43.554916896586505,227.03162842125232,0.04959699798469153
0.0514226000193215,215.985940801683,0.16326675506134575,43.54276566561929,227.0924994453248,0.05014410433989437
0.0520042103663905,215.934292092779,0.16511336791328984,43.53235328590425,227.1637844440895,0.05069711655692974
0.0525870457676994,215.885237027867,0.16696387031244558,43.52246378481799,227.23800386802205,0.05125098697191883
0.0531686628938348,215.846900926782,0.1688105046879255,43.51473522683926,227.32319203883705,0.051803394013755
0.0537572204695205,215.797022849563,0.17067917499072757,43.504679806471906,227.3976709835531,0.05236208247607066
0.0543516547020744,215.7724665567,0.17256650367908621,43.49972925783072,227.50005715320466,0.052926032711572604
0.0549447605102253,215.729083636984,0.17444961461996533,43.49098326121598,227.58226647250845,0.05348840585126502
0.0555417099850038,215.625972961543,0.17634492920238706,43.47019614904707,227.60220821700727,0.05405410432793681
0.0561392214687419,215.53082946375,0.17824202816325552,43.451015219892,227.63056243235712,0.05462001510620311
0.0567335604933589,215.449013827207,0.18012905456641448,43.43452118756493,227.6722034864074,0.05518260367790224
0.0576004139706497,215.31872507938,0.1828813143568128,43.40825497600301,227.72117277958478,0.056002581539801255
0.0584813135729223,215.221933474045,0.1856781705940283,43.38874178836747,227.80839485331123,0.056835157750532626
0.059365237207465,215.123502829909,0.18848462813370137,43.36889817050966,227.89436060430728,0.057669895928841614
0.0602525366387709,215.05817459768,0.19130180382809758,43.35572799889229,228.0159751420939,0.058507121860878544
0.0611834440210377,215.00707145528,0.1942574347667947,43.34542560538444,228.16194457579138,0.059384741973390526
0.0621117428923285,214.94576774138,0.19720478368314298,43.33306677666221,228.29642400312676,0.06025913658056317
0.0630427484202498,214.879005302133,0.20016072623429312,43.319607468910014,228.4255683741889,0.061135313433857454
0.0637069544421297,214.851495579789,0.2022695803537618,43.31406150888546,228.53903002051402,0.06175993422734423
0.0643602180163868,214.781578051735,0.20434369220202808,43.29996613522978,228.60496724104829,0.062373884391353794
0.0650131127399062,214.733516686943,0.20641663294920218,43.29027696408771,228.6940110163478,0.06298711151742796
0.065664381448382,214.627307642385,0.20848441109861285,43.26886522070482,228.72067704065378,0.06359843700477617
0.0662816608379024,214.541646266693,0.21044427316034012,43.25159588736531,228.76182290014717,0.06417751301751413
0.0668943147089956,214.40131808576,0.212389449201061,43.22330572608922,228.7435473318123,0.0647519184064376
0.0675175492619808,214.359446601566,0.214368218906789,43.21486443487571,228.83247109725818,0.06533590557519159
0.0681311962320838,214.190664107167,0.21631654803686606,43.180837884004866,228.78373027453276,0.0659105759073664
0.0687403052228787,214.078866186404,0.21825046908263987,43.15829942317905,228.79471278982524,0.06648067009120222
0.0693457303198522,213.956424799887,0.2201726937655307,43.13361523965722,228.7933893342597,0.06704699446083952
0.0699467433789629,213.79741890532,0.22208091022820717,43.10155965131251,228.75185210057504,0.06760887469209535
0.0705468962944963,213.698125977701,0.22398639573502574,43.081542197104525,228.7738655093781,0.06816963592972437
0.0711537047878903,213.708516287779,0.2259130127015517,43.08363688361624,228.91466896637766,0.06873629637640362
0.0717596205419411,213.598352983604,0.22783679522066297,43.061427961494566,228.92608974209102,0.06930180293519556
0.0723823285633938,213.59835902409,0.2298138931887753,43.06142917925655,229.05910562757342,0.06988264884348075
0.0730099739412459,213.554435168376,0.23180666726345575,43.052574129944595,229.14603891505664,0.07046775898396727
0.0736557267053054,213.470993038658,0.23385693228934465,43.03575219659346,229.19435416142352,0.07106939228284843
0.0743065948382682,213.454655332665,0.2359234386115015,43.032458515065265,229.31574392281152,0.0716754254021034
0.0749531501357879,213.343106930468,0.23797625168112657,43.00997035718235,229.3338448546628,0.07227707936090047
0.0756010826826578,213.166020513304,0.24003343751743852,42.97426973548209,229.28160245526345,0.07287965199690963
0.0762422732253696,213.021047246163,0.24206921749054847,42.94504312482646,229.2622561330593,0.07347559738478175
0.076882586779704,212.917731402466,0.24410221302556018,42.92421465073714,229.2873973639538,0.07407037345662491
0.0775309160347593,212.818661123662,0.24616065841036075,42.90424208253027,229.31868686987053,0.07467223495979411
0.0781724178645528,212.706496447619,0.24819742671995512,42.881629683839996,229.3342775704273,0.07526740205782843
0.0788187799661345,212.602062328779,0.250249626392477,42.86057576548185,229.3590974998174,0.07586672033189316
0.0794714524530422,212.533862814484,0.25232186153840896,42.84682674339997,229.42423758780666,0.07647152546606763
0.0801244685809667,212.466285454297,0.25439518774456926,42.833203147586275,229.49003366769455,0.07707628318158906
0.080788846409695,212.401172548595,0.2565045873507816,42.82007638579676,229.5608182548626,0.07769118785643489
0.0814527487679559,212.313177510176,0.25861247733826,42.80233658605148,229.6066694180388,0.07830527499693281
0.0821141530104818,212.189826509678,0.26071243580827974,42.777469024351085,229.6136143909613,0.07891667671747647
0.0827796642195329,212.090255335131,0.2628254338970169,42.75739547556241,229.64701545600812,0.07953149784608629
0.0834514011311204,211.999787734835,0.26495819859130726,42.739157207342735,229.6914670608071,0.08015168739452674
0.0841181497742246,211.877973116909,0.2670751255331631,42.71459938036885,229.7007561934163,0.08076689133467692
0.0847892572532765,211.756557683826,0.2692058917791529,42.690122029059324,229.7112389283482,0.08138573518047226
0.0854634512998415,211.637455420679,0.27134645787699674,42.66611101280889,229.7247227852466,0.08200703984752392
0.0861352246600209,211.496809737665,0.2734793382955663,42.637756843113266,229.71413495929644,0.08262573002176682
0.0868044126737087,211.37725153794,0.2756040102390251,42.613653910048704,229.72572971027367,0.08324165880630001
0.0874783940732912,211.270845272292,0.27774390118269954,42.59220240689407,229.7524795312189,0.08386161626452772
0.0881448343781533,211.144987549925,0.2798598491506367,42.566829490064876,229.75632750729037,0.08447425940695362
0.0888234251235316,211.05028646571,0.2820143747672128,42.54773775148714,229.7964957828969,0.08509768674852836
0.0895075324161995,210.962834285991,0.2841864154214334,42.53010739205579,229.84559701445767,0.08572578902361275
0.0901916432009588,210.862236196658,0.28635846716304414,42.50982681724625,229.88024776826327,0.08635350023704516
0.0908844122507212,210.792888525237,0.28855800889603983,42.49584632668778,229.950676305485,0.08698875463024065
0.0915920547341312,210.697392083568,0.29080477378086655,42.47659424404731,229.99559915162484,0.08763723127492651
0.0922922434894046,210.582738807115,0.2930278730788596,42.45348014351438,230.01789221176696,0.08827846376131329
0.0930025399649051,210.465524123961,0.29528306438857366,42.429849663390534,230.03935244253435,0.08892853303882402
0.0937076876697822,210.331206579795,0.29752190835155845,42.40277124648667,230.0408575931829,0.08957347238232533
0.0944115057171898,210.199197575058,0.2997565306520776,42.3761582311317,230.0444203186643,0.09021678109586095
0.0951186076947588,210.07938400855,0.30200157943085915,42.35200381612368,230.06184252081584,0.0908626749320042
0.09582888134533,209.955407505239,0.30425669827142277,42.32701015305618,230.07519933886897,0.0915110461768713
0.0965280676499256,209.811603064264,0.30647661478851373,42.29801917775563,230.06431167859063,0.09214888604014784
0.0972405018900905,209.698467408022,0.30873859350103733,42.27521102945723,230.08965162436087,0.09279839326265306
0.0979550772550288,209.600476485682,0.3110073702847164,42.25545605951349,230.13190735252783,0.09344942900358305
0.0986697938460544,209.499456155114,0.3132765954612227,42.235090360870984,230.1707243047996,0.09410016971552684
0.0993909153263663,209.371558446626,0.31556615616121303,42.2093061828398,230.18118928394398,0.09475631310881391
0.100113673299758,209.240815524698,0.3178609127267316,42.18294840977912,230.18868217111256,0.0954135138285971
0.100836727427643,209.126050363049,0.32015660958276654,42.15981175319068,230.21363690152728,0.09607055194600103
0.101569548026084,209.04098539329,0.3224833149828167,42.14266265528726,230.2731837986137,0.096736024646159
0.102300761991206,208.913610819791,0.324804919322079,42.116983941269865,230.28563239698985,0.0973995972607811
0.103034159377067,208.786309036561,0.32713345602218774,42.091319901770696,230.29843087758357,0.09806470930865296
0.103786787291189,208.6530404862,0.32952304964952506,42.064452962017924,230.30846921680111,0.09874680174976234
0.104533487815116,208.558539170654,0.33189382381299326,42.04540149680384,230.35989068378797,0.09942306285264824
0.105277800370811,208.417819896246,0.3342570161773249,42.01703249108319,230.3595895330026,0.10009670642377247
0.106023031243553,208.295582556409,0.3366231241982808,41.99238944337205,230.37971161368122,0.10077072679250845
0.106773360671253,208.167200952062,0.33900542013122825,41.966507711935705,230.39391257924171,0.10144889985822671
0.107522866580268,208.049223324995,0.34138510139235084,41.942723422319,230.4192722066968,0.10212586974907935
0.108273663800564,207.938332182228,0.34376888256679067,41.92036776793717,230.45257725217655,0.10280354681801165
0.109021327064548,207.824388927334,0.34614271342993985,41.89739680775054,230.4816796045707,0.1034779390801157
0.109778191422048,207.68703356312,0.3485457577650024,41.86970596632499,230.48654048948947,0.1041601678083536
0.110544595987794,207.611642056289,0.3509790922612459,41.854507038547865,230.56198714976398,0.10485052202219154
0.111318485575806,207.466245618606,0.353436191703184,41.825195116710965,230.56107388896743,0.10554713526153021
0.112091438464307,207.323944665987,0.3558903171241747,41.79650724466298,230.5631838516919,0.1062424212825938
0.112862826240764,207.158802422032,0.35833947331442567,41.763214568281654,230.53933034403457,0.10693581783424483
0.113638190602567,207.007599218014,0.3608012551631502,41.732732002351625,230.53156823413048,0.10763230473210031
0.11440860190063,206.881316386381,0.36324731103450025,41.70727338349441,230.55031855350876,0.108323862316402
0.115185655405505,206.765665259978,0.36571445591247836,41.68395811641157,230.58210392830384,0.10902089814145421
0.11595989033849,206.632127803812,0.3681726518247057,41.6570369652485,230.5931666843509,0.10971492275633328
0.116739116143028,206.512966097148,0.37064669375411385,41.633013965185036,230.62110723140415,0.11041293519232569
0.117525295852728,206.408759065359,0.37314281433241137,41.612005827576375,230.66700954110976,0.11111668335921766
0.118328681504816,206.315478536982,0.3756935637777908,41.59320047305557,230.7285170862982,0.11183532213867192
0.119132020035221,206.174281887878,0.37824416361182667,41.56473522859621,230.736240568492,0.11255340274171595
0.119938227686827,206.030385269396,0.38080387290567574,41.53572567031023,230.7413045282415,0.11327352993492633
0.120743293650742,205.866925789674,0.38335995734110584,41.502772239198286,230.72397646327212,0.11399212023068345
0.121559532481603,205.716384171165,0.3859515156290895,41.47242304890687,230.72317165481766,0.1147201564775288
0.122372765456092,205.567295489989,0.3885335303230921,41.44236677078178,230.72313392642857,0.11544498495015326
0.123191281013465,205.393056176921,0.3911323172177514,41.40724012526727,230.69568987862647,0.11617399162881817
0.12399237335852,205.24975977773,0.39367578541330095,41.37835157119037,230.69916462383682,0.11688696618025864
0.124793437349644,205.090026365022,0.39621916358511966,41.346149315188434,230.68391572124222,0.1175994075530143
0.125600318476731,204.930476506202,0.3987810111636209,41.313984063650324,230.6698096209692,0.11831650975752862
0.1264092771886,204.810910519536,0.40134945507380504,41.28987956073846,230.7009096786496,0.11903494252817158
0.12722472157295,204.659645660896,0.4039384909941163,41.25938456523664,230.6974120973221,0.11975861320440864
0.128037877474566,204.524666707469,0.406520260981747,41.23217280822575,230.7115709238864,0.12047973183351819
0.128846913096473,204.425656657285,0.4090889490813018,41.21221238210865,230.7652714752956,0.12119668084211767
0.129670934225247,204.284507530948,0.4117052161651592,41.18375671823912,230.7742704702305,0.12192638166455269
0.130512335569777,204.173655162658,0.414376665434042,41.16140888079185,230.82083575975477,0.12267092428164343
0.131353326309466,204.051498239804,0.41704681103255453,41.13678204514449,230.8543412720324,0.12341455003503533
0.132196418385994,203.894912449412,0.4197236283755309,41.105214349801464,230.8490896023501,0.12415947920435552
0.133030530586259,203.74431281339,0.4223719346113723,41.07485346317942,230.84852685088796,0.124895928360889
0.133870597912272,203.564208283867,0.42503914837146356,41.03854439002759,230.81547056036658,0.12563708760591072
0.134714064014821,203.360639363571,0.42771715324705667,40.99750489569592,230.75617755289005,0.12638069321655485
0.135560880922302,203.207941723915,0.4304057969283088,40.96672105154126,230.75498931441678,0.12712669708594718
0.136397671591279,203.070659935073,0.4330626073023108,40.93904504291071,230.76902511872137,0.12786332206168807
0.137244099331896,202.90735332613,0.43575001537876973,40.90612243054781,230.75519028119348,0.12860787891364622
0.1380927487411,202.759477805409,0.43844447725299246,40.876310725570455,230.759091428868,0.12935383391303487
0.138950705771087,202.600563287224,0.4411684908232012,40.84427355870436,230.75205454560356,0.1301074050132152
0.139812495022267,202.455400441731,0.4439046716956977,40.81500872905297,230.76119510822159,0.13086377082776315
0.140677175199576,202.307991816984,0.4466500312586538,40.785291150303976,230.76810862609625,0.13162209938328065
0.141533165332083,202.115042697193,0.4493677999293635,40.7463926077541,230.72102445135582,0.13237224073304546
0.142393645975746,201.89627120173,0.45209982597299353,40.70228827426877,230.64501736705233,0.13312575059169426
0.143249531840012,201.730885655942,0.45481726359203806,40.668946548237905,230.62874058382667,0.13387467405671952
0.144107373448795,201.507324631333,0.45754091069992414,40.62387664567673,230.54601591464808,0.13462474646301395
0.144960207489488,201.308301153248,0.4602486587791244,40.5837535124948,230.4899942577792,0.13536988311800366
0.145812746286924,201.089621050188,0.4629554694609837,40.5396676037179,230.41105094531275,0.13611420728630746
0.146660579286778,200.892792191479,0.46564733923552015,40.49998690580217,230.3558454688196,0.13685387394157486
0.147522893684679,200.754722030998,0.46838518744885577,40.4721519614492,230.37063954587424,0.13760561367701374
0.148382862873232,200.604818765355,0.47111558962251154,40.441931463095564,230.3711360799242,0.13835474654217117
0.149247464486465,200.414090958442,0.4738606997445264,40.403480737221905,230.32538588134923,0.13910734946854056
0.150114093182249,200.263063841822,0.47661224585364054,40.37303367051132,230.32537206833592,0.1398611489168521
0.150982783061171,200.092500060768,0.4793703362192179,40.33864801225083,230.30302258961026,0.14061617138388294
0.151847140793947,199.877989704078,0.48211467202078173,40.295402724342125,230.22889094828423,0.14136686318653297
0.152709179348195,199.683910853048,0.4848516444305191,40.25627642797448,230.17747700845507,0.14211497993848124
0.153567511852403,199.45063425835,0.48757685013137947,40.20924786648336,230.07977189878844,0.14285932474941632
0.154429298233399,199.246891333583,0.49031302189104176,40.168173292850334,230.01644893741454,0.14360610777552849
0.155297570673897,199.03641645462,0.49306978688962294,40.12574155725139,229.94628840566054,0.14435794773815488
0.156153152328528,198.784977991035,0.49578625864307635,40.075051562992655,229.82587893989216,0.14509824618812067
0.157008280708383,198.551949793328,0.49850129124911596,40.02807307833493,229.72625006167561,0.14583760523725295
0.157871881936971,198.371188933681,0.5012432251498828,39.99163168903009,229.68842185271566,0.14658373566991073
0.158730155808294,198.164017415842,0.5039682446913334,39.94986591103375,229.61862277585612,0.14732471223524923
0.159586164103232,197.941980708853,0.5066860710277616,39.905103310904764,229.5307821251748,0.14806318638261845
0.160446345795694,197.715283502,0.5094171479013284,39.8594011540032,229.43797824785557,0.14880471196745992
0.16129763139702,197.474310830543,0.5121199796855385,39.81082106343747,229.32644942926848,0.14953802765414795
0.162152017304861,197.284273017051,0.5148326549429336,39.772509440237485,229.27431586928876,0.15027347371542013
0.16302297845549,197.059413656317,0.5175979565961807,39.727177793113505,229.18462620326224,0.15102263125663895
0.163889154479064,196.82970359249,0.5203480654710282,39.680868244245985,229.08795729062797,0.15176711666399184
0.164770279046475,196.562061226903,0.5231456359725581,39.62691154334365,228.94964690521016,0.1525238822062407
0.16565387205388,196.283345046935,0.5259510437710689,39.5707223614621,228.79844117364757,0.15328219313374217
0.166534324102029,195.992756025979,0.5287464790239421,39.512139614837366,228.63227717965927,0.15403723690887858
0.167417269141917,195.721390765836,0.5315498295255865,39.45743237839254,228.4885315205103,0.15479384650143804
0.168304778018058,195.402505733822,0.5343676702073341,39.39314515593852,228.28968108552522,0.15555379045104664
0.169176589278031,195.099154606484,0.5371356709577484,39.331989568667176,228.10536415383623,0.15629973119957677
0.170046266428607,194.726821473474,0.5398968959108272,39.25692720905236,227.83939043854815,0.15704329198389758
0.170910404939369,194.414237390107,0.5426405356824965,39.193910257845566,227.6416534284288,0.1577815701080349
0.171773041108915,194.062404883869,0.5453794055208051,39.12298082458799,227.39709433568072,0.1585180214710983
0.172623653078417,193.708855789877,0.548080098523974,39.051705327239205,227.14758610996586,0.15924367682536253
0.173470463793401,193.373880791938,0.5507687225440482,38.9841743676547,226.91853757844532,0.15996556666402556
0.174322044655938,193.079937089754,0.5534724917826032,38.924915317294406,226.73802650527978,0.16069099780567678
0.175181213200994,192.755216226571,0.556200351913156,38.859451591276716,226.52230885596165,0.16142235970566962
0.176052654375053,192.498827095445,0.5589671776407932,38.80776354244171,226.38875656968244,0.16216362260255016
0.176929328763765,192.147097726112,0.5617506188249538,38.73685490158418,226.14355475069857,0.16290878294424396
0.177815236804352,191.833584641525,0.5645633768538175,38.673650663731436,225.94451892158546,0.1636612281099228
0.178715346920138,191.475850035012,0.5674212264714381,38.60153136705842,225.69552300084746,0.16442515637444605
0.179623348285755,191.079849105449,0.570304130807272,38.521697579658515,225.40225139170659,0.1651951911555653
0.18052760415161,190.586787360319,0.5731751431813618,38.42229633184031,224.9929634654297,0.16596146071062665
0.181433994278215,190.098519438369,0.5760529318333326,38.323861518775196,224.58885312644722,0.16672895004804794
0.182338149000266,189.617818243445,0.5789236230758444,38.22695215787851,224.1923802394236,0.16749396013475842
0.183252965676405,189.160946784594,0.5818281660225859,38.13484687177415,223.82525127302748,0.16826739618299782
0.184166147147246,188.681259782582,0.584727517192506,38.03814197216853,223.42996043562874,0.1690388535993752
0.185096917258982,188.164294261355,0.5876827122972679,37.93392172308916,222.99292506734378,0.16982455795918389
0.186023827365557,187.615443622484,0.5906256518856434,37.82327343429278,222.51638651802537,0.17060639090117286
0.186947406806799,187.10723049411,0.5935580166115868,37.72081766761258,222.08644202978587,0.17138480698525954
0.187901061429685,186.5782063669,0.5965858700392498,37.61416640356704,221.63644938288732,0.17218793584750183
0.188868855002193,185.947043473752,0.5996586146319627,37.4869239643084,221.06664866568255,0.17300231305692776
0.189809767845564,185.256448408165,0.6026460129096657,37.34769999908606,220.4199318724125,0.17379343539132602
0.19076339807605,184.555248635278,0.6056737888914587,37.20633812487205,219.76163499771388,0.1745946124315006
0.191712633571514,183.862826682969,0.6086876115895569,37.066745859286556,219.11165340226384,0.17539146036036343
0.192683889348162,183.114328649429,0.6117713486804143,36.91584865572489,218.39750968897854,0.17620613679612418
0.193670193309048,182.311846193376,0.6149028637562274,36.754068192584604,217.62021668817653,0.17703275680546457
0.194632147655732,181.510399063927,0.6179570688069491,36.59249645128769,216.83815785558807,0.17783831176574208
0.195616916466676,180.712667682993,0.6210837097816962,36.43167380489139,216.06312250160724,0.17866230026254223
0.196627028861549,179.869244987118,0.6242908166354181,36.26163978940299,215.2364002125051,0.17950678976945622
0.197650352143745,178.906611972279,0.6275398680563903,36.06757297361145,214.26756682944426,0.18036159744765246
0.198701568242912,177.901898491634,0.6308774791712456,35.86502273591342,213.25128471531303,0.18123894451646494
0.199764884063148,176.886852702402,0.6342535069004949,35.66038950480424,212.2226343247925,0.18212560764979835
0.200856004204192,175.836839160514,0.6377178133483096,35.44870677475962,211.15472406619003,0.1830346393269889
0.20197386807055,174.662851198242,0.6412670311239963,35.21203080156559,209.94018286298186,0.18396509550277207
0.203066433204099,173.398728727659,0.6447359254230143,34.95718371149606,208.61019009250987,0.18487365841386177
0.20418089278883,172.11263598149,0.6482743346045352,34.697907413868386,207.25474765642954,0.18579957878134443
0.205288569793934,170.820839157261,0.6517912090957404,34.437481174103816,205.88840491885472,0.18671901527999096
0.206353488831827,169.406443477275,0.6551723270410507,34.15233900501864,204.3640541194024,0.18760216384119605
0.207379333521208,167.942900090218,0.6584293839298353,33.85728865818795,202.77078678054622,0.18845217071987477
0.208466273375487,166.31603785302,0.6618804179671712,33.52931323116883,200.9873224668155,0.18935201293207468
0.209538293547701,164.745932461507,0.6652840820139506,33.212779984239816,199.266514018416,0.19023871120975114
0.210626665993508,163.078047340373,0.6687396645293878,32.876534343819195,197.4266327484072,0.1911381313214973
0.211705899026479,161.320739190536,0.6721662294090708,32.52226102081206,195.47329131248458,0.19202920063209952
0.212824475358152,159.503073327903,0.6757177092621326,32.155819582905245,193.4492312269268,0.19295191657152788
0.213961165673735,157.591547995498,0.6793267010141085,31.770456075892394,191.3100193049431,0.19388870338902914
0.215097915832754,155.479850386981,0.682935882768994,31.344737838015373,188.92324215920902,0.1948246627081401
0.216192129646539,153.385139492293,0.6864100116277613,30.922444121646272,186.54579945526328,0.19572477241713765
0.217301713701528,151.025155656991,0.6899329410023514,30.446671380449384,183.84318079329515,0.1966366992214049
0.218437936130347,148.535060587263,0.6935404472138518,29.94466821439222,180.98075266494078,0.19756965813703656
0.219687703736027,145.664284415876,0.6975084593618857,29.365919738240606,177.66493657555134,0.1985948454323133
0.220941522127769,142.241691934938,0.7014893327556665,28.6759250940835,173.66878786107242,0.19962230055639035
0.221537197767491,140.720130565003,0.703380602911784,28.369178321904602,171.8948739598492,0.20011006378370505
0.222199444093281,139.154684634027,0.705483234996167,28.053584422219846,170.07477820268366,0.20065205863753477
0.222877989268061,137.356850317327,0.7076376159260936,27.691141023973124,167.97066892824688,0.2012070882516819