File: example/data/02 processed data/test_ID_145.csv
Strain,Stress_MPa,Displacement(mm),Force(kN),True Stress (MPa),True Strain
1.77530457093408e-06,0.161415559719561,5.636592012715704e-06,0.032541376839463496,0.161415846281342,1.7753029950543945e-06
4.9915264991446e-06,0.17727135484344,1.5848096634784103e-05,0.03573790513643751,0.17727223969810527,4.991514041615896e-06
5.43594641539846e-05,0.138039736561759,0.0001725912986889011,0.027828810890850614,0.13804724032787044,5.4357986731866294e-05
9.11731942329135e-05,0.0754282316583619,0.00028947489168950035,0.01520633150232576,0.07543510869117755,9.11690382099552e-05
0.0001456074886909,0.597693110961658,0.00046230377659360746,0.12049493116987027,0.597780139554553,0.00014559688894950917
0.0002236701254427,1.86507731227821,0.0007101526482805724,0.37599958615528717,1.8654944743546078,0.00022364511500959028
0.0002654540120672,4.13615468368464,0.0008428164883133599,0.8338487842308234,4.137252642539955,0.000265418785384878
0.0003583951403194,7.0472414964756,0.0011379045705140949,1.420723885689481,7.049767193580594,0.0003583309321219443
0.0004317925185815,9.94517625932399,0.0013709412464962625,2.0049475338797165,9.949470512028741,0.00043169932301841216
0.000507527397317,13.0038461053247,0.0016113994864814748,2.6215753748334594,13.010445913493646,0.0005073986488478594
0.0005911762456546,15.8628308659533,0.0018769845799533548,3.197946702576185,15.872208594750088,0.0005910015698172235
0.0006418608627177,19.1221945164818,0.0020379082391286975,3.8550344145227315,19.134468304751206,0.0006416549581374747
0.0006974069203032,22.4766297606908,0.00221426697196266,4.531288559755265,22.492305117830995,0.0006971638451052529
0.000763038595788,26.0201642052051,0.0024226475416269,5.2456651037693485,26.04001859476241,0.0007627476298413942
0.000832880026797,29.4570366954077,0.0026443940850804748,5.938538597794193,29.48157087291993,0.0008325333746938038
0.0009395199187246,32.8365077301658,0.002982975741950605,6.619839958401425,32.86735828323964,0.0009390788461284082
0.0010006036168064,36.0543561672148,0.00317691648336032,7.268558203310504,36.09043228639734,0.0010001033466943557
0.0010733807384653,39.1587386153852,0.0034079838446273276,7.894401704861656,39.20077085115755,0.0010728050772593884
0.001138677624973,42.1463634305036,0.003615301459289275,8.496706867589525,42.1943545515159,0.0011380298233178308
0.0011855060354873,44.9705504874574,0.003763981662672177,9.066062978271413,45.023863346479466,0.0011848038780936238
0.0012534224291668,47.7147001685493,0.00397961621260459,9.619283553979539,47.77450684394152,0.0012526375510611585
0.0013146362051362,50.3673371828172,0.004173969951307435,10.154055176055948,50.43355190783404,0.0013137728275623443
0.0013653732471882,52.8931346650444,0.004335060059822535,10.663255948472951,52.965353536075966,0.001364441972731143
0.0014587507468307,55.2843602195534,0.004631533621187472,11.145327020261966,55.365006321311725,0.0014576878035472813
0.0015186867419284,57.5554413577432,0.00482183040562267,11.60317697772103,57.642850043459035,0.0015175347034611575
0.0015959840786719,59.9134837282176,0.005067249449783283,12.07855831960867,60.0091046943456,0.001594711849540623
0.0016718110549822,62.1534818627696,0.005308000099568485,12.530141943534352,62.257390740853424,0.0016704151344741499
0.0017524736704318,64.265972711541,0.0055641039036209644,12.956020098646666,64.37859713662266,0.0017509398801389155
0.0018430955991457,66.1838737567086,0.005851828527287597,13.342668949352456,66.30585696316402,0.0018413991825707331
0.0019510359427775,67.9781070444726,0.006194539118318562,13.704386380165674,68.11073477463833,0.0019491351441019236
0.0020560271436423,69.7176987687668,0.0065278861810643025,14.055088071783388,69.86104024982765,0.00205391641248646
0.0021927074607135,71.4463035647677,0.006961846187765361,14.40357479865717,71.60296440763457,0.0021903069860947015
0.0023114326022645,73.0199085628976,0.007338798512189787,14.720813566280157,73.18868916016424,0.002308765351250257
0.0024630085949139,74.5431850598739,0.007820052288851631,15.02790610807058,74.72678556536864,0.0024599803606035293
0.0026207813865493,75.8227037869225,0.008320980902294026,15.285857083443577,76.0214185176851,0.0026173531275165683
0.0028176547382078,76.9840002697208,0.008946053793809765,15.519974454375713,77.20091460284696,0.002813692589994693
0.0030389277873752,77.8273625150306,0.00964859572491626,15.689996283030169,78.06387424959566,0.003034319579972692
0.0032601878291771,78.5361074563922,0.010351096357637292,15.832879263208667,78.79214991807248,0.003254884939321823
0.0035236130170623,79.1013316417348,0.011187471329172803,15.946828458973737,79.38005412357458,0.0035174196371674004
0.0037736331704303,79.5206845664505,0.011981285316116202,16.031370008596422,79.82076645946579,0.003766530878799164
0.0040448075499645,79.831998260992,0.012842263971137288,16.094130849415986,80.1549033302868,0.004036649307520826
0.0043639895077656,80.1002981026567,0.01385566668715578,16.14822009749559,80.44985496314558,0.004354494918390444
0.004694987639986,80.3426581257643,0.01490658575695555,16.197079878154085,80.71986591262839,0.004684000561559868
0.0050222459244622,80.4995557308143,0.015945630810167484,16.22871043533216,80.90384429650439,0.005009676514279186
0.0053813586640783,80.6173386123668,0.0170858137584486,16.252455464253146,81.05116942598339,0.005366930891077886
0.0056965918228889,80.6379227325081,0.018086679037672256,16.256605222873635,81.09728406376085,0.0056804276019497635
0.0060304935544556,80.6785865575852,0.01914681703539653,16.264803050009178,81.1651182538033,0.006012382902507054
0.00635139947897,80.7078291458361,0.02016569334572975,16.27069835580056,81.22043680982176,0.006331314342255603
0.0067180739268313,80.7247341993933,0.021329884717689377,16.27410641459769,81.26704893146864,0.006695608229536289
0.0070698860533629,80.735335691976,0.022446888219427207,16.276243675502364,81.30612531579828,0.007045011579940878
0.0074199473600635,80.7289441917089,0.023558332868201613,16.274955149048516,81.3279487080449,0.007392554967271927
0.0078008249534984,80.7218921851837,0.02476761922735742,16.273533464533035,81.35158953603549,0.007770555832688498
0.0081804132530287,80.7468751454041,0.02597281207836612,16.278570029313467,81.40741795298423,0.008147135035730951
0.0085569854573888,80.7594992735058,0.027168428827209438,16.28111505353877,81.45055713433518,0.008520581979271863
0.008933324430064,80.7359315748535,0.028363305065453197,16.276363805490465,81.4571718447751,0.00889365834568205
0.0093091059092244,80.7066960592549,0.02955641126178747,16.27046992554579,81.45800324045408,0.009266043226560406
0.0096933271830933,80.6764822607458,0.030776313806321228,16.264378823766354,81.45850579928023,0.009646648293904152
0.0100647819296723,80.5999814494441,0.03195568262670955,16.24895626020793,81.41120268626838,0.010014469320680517
0.0104594185905046,80.5235969792995,0.033208654024852104,16.23355715102678,81.3658269865191,0.010405097322808922
0.0108353134096083,80.438170337737,0.03440212007550635,16.216335140087782,81.30974312344183,0.010777032021381886
0.0112302649353396,80.352176676076,0.035656091169703225,16.19899881789692,81.25455290827954,0.011167673685018817
0.0116325911710916,80.3055937880126,0.03693347696821583,16.189607707663342,81.2397559293003,0.011565452743388912
0.0120527171947598,80.2344422064312,0.038267377093362365,16.175263548816528,81.2014852476246,0.011980661598211567
0.0124375177061308,80.1779523443486,0.03948911871696529,16.16387519262068,81.17516704627275,0.012360807186835708
0.0128430979502434,80.0887058665806,0.040776835992022795,16.145883102702648,81.11729296073332,0.012761324770817836
0.0132684594681469,80.0137434127845,0.0421273588113664,16.130770672017356,81.07540252415174,0.013181204438939097
0.013656913416707,79.948889241354,0.04336070009804472,16.117696071056965,81.04074429948507,0.01356449822815546
0.0140591718385277,79.8859021070916,0.04463787058732544,16.104997864789667,81.00903173229099,0.013961258336755083
0.01444887252845,79.7908725996657,0.045875170277828746,16.085839916092606,80.94376074679207,0.014345482294652297
0.0148475030429798,79.6828185566558,0.047140822161460864,16.06405622102181,80.86590944764896,0.01473835789868524
0.0152565384430554,79.5925899974068,0.04843950955670089,16.045866143477213,80.8068974064846,0.015141327793086632
0.015703334879567,79.518300653494,0.04985808824262522,16.03088941174439,80.76700315770991,0.015581313289194406
0.0161106336386152,79.4276486728287,0.051151261802603265,16.012613972442267,80.70727842137327,0.01598223460464432
0.0165284306273403,79.3345153673283,0.05247776724180545,15.993838298053383,80.64579040093085,0.016393322831721912
0.0169509698874593,79.2316456579313,0.053819329392683274,15.973099764638949,80.57469889761273,0.016808905370786054
0.0173738400757385,79.1253762278761,0.05516194224046973,15.951675847539823,80.50008786039186,0.017224640549650998
0.0177926780275859,79.0133138028755,0.056491752737585235,15.929084062659701,80.41917225526267,0.017636241226091916
0.0182135980777554,78.8853555043879,0.05782817389687339,15.903287669684602,80.32214166376566,0.018049717413377
0.0186297385983313,78.7777754721253,0.059149420049701876,15.88159953518046,80.24538483652904,0.018458330603083776
0.0190491489063462,78.6819361698501,0.060481047777649184,15.86227833184178,80.1807600881892,0.01886998556649287
0.019497943490592,78.6009433660755,0.0619059705826296,15.84595018260082,80.13350011813446,0.01931029385583314
0.0199260076983559,78.5241231887612,0.06326507444227998,15.830463234854259,80.0887954719271,0.01973008319271971
0.0203672091052637,78.4271498462888,0.06466588890921225,15.810913409011821,80.02449200673801,0.02016257143524422
0.0208059959246192,78.3459448629448,0.06605903706066596,15.794542484369673,79.97601027247367,0.020592507341744542
0.021242042383166,78.2225216126943,0.06744348456655205,15.76966035711917,79.88412773210926,0.02101957512565002
0.0216946177483189,78.1141866502919,0.0688804113509125,15.747820028698849,79.8088440703908,0.021462638663926538
0.022143274721237,78.0059994030145,0.07030489723992747,15.726009479647724,79.7333076777001,0.02190167248532471
0.0225762716588291,77.8944682216173,0.07167966251678239,15.703524793478048,79.65303489690857,0.02232519946224555
0.0230249344822657,77.7926644483386,0.0731041669811936,15.683001152785062,79.58383545046247,0.02276386055540887
0.0234757040372893,77.6717893873015,0.07453536031839353,15.658632740479982,79.49518932700445,0.02320438772049149
0.0239279187576886,77.5613837112381,0.0759711420556613,15.6363749561856,79.41726619941451,0.023646132301499628
0.0244004410794837,77.4471765083971,0.07747140042736074,15.613350784092857,79.33692177556263,0.02410750591663106
0.0248570416909623,77.3422412984401,0.0789211073688053,15.592195845765525,79.2647406148679,0.024553131342302147
0.0252795077091856,77.2424547886433,0.08026243697666427,15.572078885390491,79.19510601994924,0.024965265865074984
0.0257136148454252,77.1209189034762,0.08164072713422502,15.547577250940801,79.10397650868545,0.02538857995418442
0.0261514380389913,76.967485038508,0.08303081577379737,15.516644983763213,78.98029545450953,0.02581533628457319
0.0265832466443109,76.8372761743738,0.0844018080956871,15.490394876753758,78.87986043839422,0.02623605174761951
0.0270590493107966,76.6909201907126,0.08591248156177919,15.460889510447663,78.76610358184345,0.026699426188179276
0.0275062927294464,76.6070175706279,0.08733247941599231,15.443974742238586,78.71419262105545,0.027134791680395932
0.0279873333722693,76.4980560030179,0.08885978345695501,15.422008090208408,78.63903259870489,0.027602845334755453
0.0284573232839534,76.4215326545903,0.09035200142655203,15.406580983165405,78.59628491519717,0.02805993511672038
0.0289441777121801,76.3465793555082,0.09189776423617181,15.391470398070453,78.5563683160911,0.02853320631544214
0.0294052140412394,76.2441127396122,0.09336155458093509,15.37081312830582,78.48608719410488,0.028981173350209014
0.0298769852408451,76.1050582920072,0.09485942813968318,15.342779751668653,78.37884799535117,0.029439363303993757
0.0303500802029467,75.9703842161174,0.09636150464435576,15.315629457969267,78.27609147012522,0.029898628186348024
0.0308324992092243,75.861335488001,0.09789318498928715,15.293645234381001,78.2003300544455,0.030366727441508812
0.0313086431210971,75.7637194718905,0.09940494190948329,15.273965845533123,78.13577872636283,0.03082852310676226
0.0317739248278846,75.6548714322703,0.1008822113285336,15.252022080745691,78.05872363002253,0.03127957797185031
0.0322406071425325,75.5455632411225,0.10236392767754067,15.229985549410294,77.98119806694088,0.031731786340902055
0.0327217504326681,75.4325171611744,0.1038915576237212,15.207195459692759,77.9008011622303,0.03219779318802702
0.0332083814958475,75.3310138405234,0.1054366112493158,15.186732390249517,77.83263488660846,0.03266889437839042
0.0337329718986509,75.2504992910876,0.10710218577821659,15.170500657083263,77.78892226903332,0.033176495054341615
0.0342100443736533,75.1244985279304,0.10861689088634921,15.14509890323077,77.69451095611934,0.033637893148691284
0.0346971418359382,74.9840437905292,0.11016342532910378,15.116783228170688,77.5857757933614,0.034108767313111854
0.0351856140223921,74.8471360438902,0.11171432452109491,15.089182626448265,77.48067848341199,0.03458074785803804
0.0356444007270601,74.7233899628223,0.11317097230841582,15.064235416504976,77.3868604183415,0.03502384237463907
0.036141572457154,74.6243610532902,0.11474949255146394,15.044271188343306,77.32140280536652,0.035503787452048303
0.0366180662200316,74.4880215664507,0.11626236024860033,15.016785147796462,77.21562887277013,0.0359635549642864
0.0370887916818677,74.367027955046,0.11775691358992993,14.992392835737274,77.12521116287033,0.03641754919025673
0.0375815216869686,74.2329940574988,0.1193213313561253,14.965371601991759,77.0227829335593,0.036892545155823006
0.0380717824185976,74.1309872434711,0.12087790917904737,14.944807028283774,76.95328606028036,0.03736493689848668
0.0385793983916348,74.0212286912539,0.12248958989344048,14.922679704156785,76.87692316237208,0.037853816290305535
0.0390922015976473,73.9135942710897,0.12411774007253017,14.900980605051684,76.80303939914187,0.038347448889825435
0.0396040462424151,73.8034203237244,0.12574284681966794,14.878769537262839,76.72633439507358,0.03883991589229799
0.0400972926581191,73.7190588236002,0.12730890418952814,14.861762258837798,76.67499349973119,0.03931425941050058
0.040608479479863,73.6254174314725,0.12893192234856501,14.842884154184857,76.61523368443478,0.039805618485746805
0.0411099643721799,73.5127270026274,0.13052413688167117,14.820165763729683,76.53483259060721,0.040287417456687284
0.041639715382685,73.4088001939541,0.13220609634002486,14.799214119101146,76.46552174061473,0.04079612095291494
0.0421562666565949,73.2945890336065,0.1338461466346888,14.776189149175071,76.38441527339275,0.04129190008766964
0.042657375093037,73.1736045769158,0.13543716592039245,14.751798682706227,76.29499847426287,0.04177262261946568
0.0431863378597304,73.0159528364061,0.13711662270464403,14.72001609181947,76.16924444474927,0.042279815727700946
0.0436901685552572,72.8786413764157,0.1387162851629416,14.692334101485406,76.06272150222944,0.04276267199999784
0.0442278199523104,72.7703463069511,0.1404233283485855,14.670501815481341,75.9888200812822,0.04327768399941193
0.044729085400894,72.7239498985048,0.14201484614783844,14.661148299538567,75.97682566420535,0.04375760338589631
0.0452633255913446,72.6146815844012,0.1437110587525191,14.639119807415282,75.90146355966776,0.044268839885394325
0.0457857750453873,72.4921825470315,0.14536983576910467,14.614424001481552,75.81129330967904,0.04476854069562881
0.0462934415675959,72.3671586522543,0.14698167697711698,14.589219184294468,75.71728348273538,0.04525386317112763
0.0468115519243234,72.2421636043624,0.1486266773597268,14.56402018263946,75.62393139705348,0.04574892707754456
0.0473263745379869,72.143640731183,0.1502612391581084,14.544157971406491,75.55793769296092,0.04624060684469773
0.0478365240942563,72.0225566375095,0.15188096399926376,14.519747418121915,75.46786540342966,0.04672758527170611
0.0483660303714297,71.9075711886165,0.15356214642928928,14.496566351625086,75.38545496066087,0.04723279054140463
0.0488986768317862,71.8194147575591,0.15525329894092116,14.478794015123915,75.331289110037,0.047740734502869635
0.0494338339950611,71.7211927820282,0.156952422934319,14.458992464856886,75.26664631994275,0.04825081302676098
0.0499649748386974,71.64571423123,0.15863879511286424,14.44377598901597,75.22549054009392,0.04875680631658639
0.0504969473698881,71.4934326841,0.16032780789939471,14.413076029114562,75.10363279164164,0.04926333541567664
0.0510306234621364,71.3901878062584,0.16202222949228307,14.392261861741693,75.03327359909078,0.04977122892240716
0.0515862858071443,71.2883874977847,0.16378645743768314,14.371738919553396,74.96589062997587,0.05029977252489979
0.0521553346181786,71.2236897034915,0.16559318741271706,14.358695844223888,74.93838507271843,0.05084075989653131
0.052707729572978,71.1472237468562,0.16734704139420514,14.34328030736621,74.89723237597366,0.051365634865244265
0.0532700014262,71.023431622027,0.169132254528185,14.318323815000644,74.806849925826,0.0518996118948259
0.053805027253191,70.9291516568102,0.17083096152888141,14.299316974012939,74.74549659475059,0.05240744937683983
0.0543711670812319,70.8228694165129,0.17262845548291128,14.277890474369002,74.67359148273039,0.05294453905954449
0.0549252193940167,70.6989860147349,0.17438757157600301,14.252915580570557,74.58214333252873,0.053469882324796186
0.0554882971563241,70.5798974420975,0.17617534347132902,14.228907324326858,74.49625576462749,0.05400350075668462
0.0560865157965891,70.4616396120752,0.17807468765417037,14.205066545794361,74.41358747523142,0.05457010976584678
0.0566666322524752,70.358940313865,0.17991655740160875,14.184362367275185,74.34594451030465,0.055119266652443516
0.0572246081082751,70.3809475788003,0.18168813074377343,14.188799031886143,74.4084697222862,0.05564718015916044
0.0577607862321147,70.1667782577684,0.18339049628696416,14.145622496766109,74.21966653731155,0.05615420790201025
0.0582644915123903,69.9773705785671,0.1849897605518392,14.10743790863913,74.05456649270141,0.056630294171004555
0.0588122724232947,69.7088927603618,0.18672896494396066,14.053312780488941,73.80863115171044,0.05714778218321105
0.0593648616894434,69.6511919330545,0.1884834358639828,14.04168029370379,73.78602530866516,0.05766954145422329
0.0599272094073222,69.6385367488571,0.19026888986824797,14.039129008569594,73.81177992342536,0.058200235395607196
0.0604993518451437,69.5720415790478,0.19208544210833123,14.025723582336038,73.78110500112359,0.058739883843859586
0.0610688903383962,69.4710693430642,0.19389372682440792,14.005367579561744,73.71359045846691,0.059276787154919526
0.0616551503886471,69.3553466218219,0.19575510248395453,13.982037878959295,73.63146094804708,0.05982915293955173
0.0622106942341626,69.2587910267502,0.19751895419346624,13.962572270992842,73.56742849834313,0.06035229695977523
0.0627941613729376,69.1570265106653,0.19937146235907685,13.942056544550127,73.49968399344856,0.0609014412611616
0.0634105000766282,69.058875166296,0.2013283377432945,13.922269233525274,73.43793297532028,0.061481196100504135
0.0639873954642065,68.9475564823402,0.20315998059885562,13.899827386839787,73.35933104526642,0.0620235444810569
0.0645979281526292,68.8354339954225,0.2050984218845977,13.877223493477176,73.28206041501386,0.06259719562709405
0.0651741788499565,68.7164647519392,0.20692801784861187,13.853239293990944,73.19500391561881,0.06313833400475855
0.0657625495583383,68.6125155491825,0.20879609484772407,13.832283134715192,73.12464950330788,0.06369055192422066
0.0663524106468597,68.5043938630079,0.21066890380377956,13.810485802782393,73.04982553572043,0.06424386271147178
0.066962924595655,68.392695894165,0.21260728559120462,13.787967492263665,72.97247083221953,0.06481622438288179
0.0675635392081346,68.2805393790482,0.21451423698582733,13.765356738816115,72.89381427853709,0.06537898585575729
0.0681617828491573,68.1645857078941,0.21641366054607442,13.741980478711453,72.81080539691837,0.06593921113425255
0.0687322291194529,68.0218626040134,0.21822482745426294,13.713207500969105,72.6971568496444,0.06647311340610233
0.0692978974857098,67.8492770614545,0.22002082451712862,13.678414255589228,72.5510893077387,0.06700226252558084
0.0698715784937465,67.7118295522421,0.22184226171764515,13.650704837732006,72.44296196575677,0.06753862117152398
0.0704581070684915,67.5825989869118,0.22370448994246048,13.62465195576142,72.34434098229856,0.06808669429631736
0.0710651373958375,67.5020117719336,0.22563181123178405,13.608405573221813,72.2990515130015,0.06865360884667118
0.0716707859756497,67.4075421801669,0.22755474547268778,13.589360503521648,72.23869370890623,0.06921891284828438
0.0722863608272341,67.3235104563637,0.22950919562646824,13.572419708002924,72.19008202536848,0.06979315461372078
0.0728853049766763,67.2233763853068,0.23141084330094722,13.552232679277852,72.12297267471179,0.07035156602158481
0.073468562996897,67.0927450533723,0.23326268751514795,13.525897402759856,72.02195261996073,0.07089505332186696
0.0740556953381952,66.9480488066453,0.23512683269876974,13.496726639419695,71.90593311255685,0.07144185259889335
0.0746446342481816,66.8387312859539,0.23699671373797657,13.474688227248306,71.82788393640642,0.07199003413600698
0.0752462320784318,66.7173283030758,0.23890678684902095,13.450213385900081,71.73755587222196,0.07254968844718633
0.0758619859820892,66.6425611657387,0.24086180549313319,13.435140331012922,71.69819820670449,0.07312218769692726
0.0764916535318185,66.5436041429626,0.24286099996352373,13.41519059522126,71.63363445582458,0.07370728445438644
0.0771175931284415,66.4364574497231,0.24484835818280176,13.393589821864175,71.55987714422587,0.0742885780341937
0.0777515808440951,66.3324510300039,0.24686126918000192,13.372622127648786,71.48990395885022,0.07487700144439786
0.0783501563070409,66.217694131089,0.24876174627485484,13.349487136827543,71.40586081655167,0.07543224006603604
0.0789512999201015,66.0905170984375,0.25067037724632224,13.323848247045001,71.30844933575084,0.07598955079966999
0.0795328878553932,65.9157131429861,0.2525169189408734,13.288607769626,71.15818016429549,0.07652843633115532
0.0801355468625074,65.7877997757077,0.25443036128846097,13.262820434782673,71.05974108761517,0.07708653961503825
0.0807592893196135,65.651825539706,0.25641074358977284,13.235408028804729,70.9538203128279,0.07766383978160374
0.0813764908026312,65.5626164118997,0.25837035829835403,13.217423468638978,70.89787206333908,0.07823475813507312
0.0819889235391142,65.4491869941962,0.26031483223668755,13.194556098029953,70.81529538236055,0.07880094334704288
0.0826069526438253,65.3295610430255,0.2622770746441453,13.170439506273942,70.72623699834861,0.07937197753250463
0.0832261789065302,65.2129161273896,0.26424311802823336,13.146923891281745,70.64033795202428,0.07994379100285642
0.0838556564948926,65.0939098359231,0.266241709371284,13.122932222922097,70.55240237903378,0.08052473593606861
0.0844763357109871,64.9763526911813,0.268212365882384,13.099232702542151,70.46531687439703,0.08109723058659046
0.0851097445590544,64.8445097741717,0.27022343897499773,13.072653170473016,70.36340943710856,0.08168112893644043
0.0857199757642643,64.7165246790733,0.2721609230515391,13.046851375301179,70.26402360611088,0.08224333905874562
0.0863494059267438,64.5888685815094,0.2741593638174115,13.021115906032296,70.16607901300327,0.08282290634642414
0.0869638266640023,64.4733176859843,0.2761101496582073,12.997820845494434,70.08016410968139,0.08338832944735047
0.0875567417904892,64.3347567982555,0.2779926551848032,12.969886970528309,69.96769848739427,0.08393365897863378
0.0881701475788845,64.1618826120141,0.27994021856295825,12.935035534582042,69.81904527085445,0.08449752184914815
0.0887965734175681,64.0312786965409,0.2819291206007787,12.908705785222644,69.71703683633906,0.08507302523184249
0.0894306172820902,63.9209447800846,0.2839422098706364,12.886462467665055,69.63743432902197,0.08565519029261899
0.090060781201601,63.7938965332796,0.2859429803150832,12.860849541109166,69.53922469096086,0.08623345725665414
0.0906747320998213,63.6679607272685,0.2878922744169326,12.835460882617332,69.44103600955552,0.0867965250020973
0.0912882269905539,63.5113579008307,0.28984012069500864,12.80388975280747,69.30919715736005,0.08735885801911136
0.0919128165215179,63.3749808733064,0.29182319245581934,12.77639614405857,69.19995386236931,0.08793103578520428
0.092540293149414,63.2565078598242,0.29381543074938943,12.75251198454056,69.11028364078054,0.08850552890879283
0.0931624378101351,63.1143183517999,0.2957907400471789,12.72384657972286,68.99420211017852,0.08907481462977497
0.0937859177304475,62.9756753418363,0.29777028879417083,12.6958961489142,68.88190684846512,0.0896449972183344
0.0944064942719057,62.8007610530088,0.2997406193133006,12.660633428286573,68.72956074163099,0.09021220196202331
0.0950377601188485,62.6432917074608,0.301744888377344,12.628887608224098,68.59676983780952,0.09078884680070266
0.0956823937791852,62.4997241288941,0.303791600248913,12.59994438438505,68.4798473440854,0.09137735983172154
0.0963011461188404,62.3365144597932,0.30575613892731823,12.56704131509431,68.33959224732494,0.0919419191405184
0.0969065249720066,62.1888332200248,0.3076782167861209,12.537268777157,68.21533693944109,0.09249396797430691
0.0975112333781461,62.024650465221,0.30959816597561385,12.504169533788554,68.0727506319331,0.09304510133908662
0.0981214111766748,61.8437863433963,0.3115354804859425,12.467707326828695,67.91198593191912,0.0936009118165363
0.0987576871831673,61.692653983065,0.31355565680655617,12.437239042985905,67.78527780662391,0.09418016629144897
0.0993976977609415,61.5470916622485,0.3155876903909892,12.407893679109298,67.66473087735763,0.09476248235540245
0.100030449540817,61.4200070032043,0.31759667729209395,12.382273411845986,67.56387791453496,0.09533786082194476
0.100654704921871,61.2884277928175,0.3195786881269404,12.355747043032009,67.45739640742893,0.09590518904382288
0.101269344605405,61.1152309346947,0.32153016912216087,12.320830556434453,67.30433031685921,0.09646346415747158
0.101880893005543,60.9303920140577,0.323471835292599,12.283567030034034,67.13803476362772,0.09701862231727815
0.102507006171674,60.6931294660353,0.32545974459506494,12.235734900352718,66.91460046278839,0.09758668312291174
0.103124700654297,60.5073278541101,0.32742092457739297,12.198277295388596,66.74712792645661,0.09814678977794394
0.103763278415221,60.3343970866502,0.32944840896832667,12.16341445266868,66.59489192956678,0.09872550313793539
0.104381430660468,60.1589168743826,0.3314110423469859,12.128037641875533,66.43839068471482,0.09928538697059736
0.105017790029624,60.055485199052,0.3334314833440562,12.107185816128883,66.36237953381324,0.09986143441443981
0.105655923636259,59.8642054444112,0.3354575575451223,12.068623817593298,66.18921336339123,0.10043875491218159
0.10630005499211,59.6844854393267,0.3375026745999492,12.032392264568264,66.02894952370292,0.10102116376686215
0.106929177362954,59.4457576602555,0.33950013812737895,11.98426474430751,65.80224362458414,0.10158967459130944
0.107535370213913,59.2315355247885,0.3414248004291738,11.94107756179736,65.60102062578517,0.10213715941491076
0.108164651414119,59.054405795172,0.3434227682398278,11.905368208306674,65.44200501247471,0.10270517964416838
0.108798400192821,58.8888758828791,0.34543492061220665,11.871997377988425,65.29589136808994,0.10327690662491852
0.109389457840419,58.7233823828254,0.34731152864333026,11.8386338883776,65.1471013442383,0.10380982601625502
0.109993273368081,58.5289477007644,0.34922864294365713,11.799435856474103,64.9667382451607,0.10435395527712492
0.110595759769325,58.2260782603823,0.35114153726760683,11.738377377293073,64.66563562397747,0.10489659185421045
0.111200616431995,57.9953098535003,0.3530619571715841,11.691854466465662,64.44442405937409,0.105441067202259
0.111813092355803,57.8157421408977,0.3550065682296745,11.655653615604976,64.28029905651718,0.10599209928711237
0.112433091568779,57.6489076182848,0.3569750657308733,11.622019775846216,64.1305525273715,0.10654959083954468
0.113071771682674,57.4645797563783,0.35900287509248996,11.584859278885865,63.96220159843231,0.10712355510444
0.113694067711012,57.2493342478557,0.36097866498246306,11.541465784367709,63.75824393224177,0.10768247875373384
0.114363482878493,57.0042050350169,0.36310405813921526,11.492047735059407,63.52340446154116,0.10828337453171427
0.114972196326557,56.7419825407079,0.36503672333681847,11.439183680206714,63.26573289733624,0.10882946857118048
0.115603902369366,56.4381097373135,0.36704239002273703,11.377922923042401,62.96257546529746,0.10939587476558621
0.116233345163737,56.1910855781439,0.3690408708948649,11.328122852553811,62.72236342327338,0.10995993275122595
0.116844864707166,55.9679666182374,0.37098244544525205,11.283142070236659,62.50753610568053,0.11050762477205377
0.117469061037178,55.7911365783557,0.3729642687930401,11.247493134196509,62.3448690064121,0.11106636124955466
0.118099645032981,55.4942915119581,0.37496637297971463,11.187649168810754,62.048147640877126,0.11163049869772561
0.118731307924977,55.2192284504931,0.37697190266180197,11.13219645561941,61.77547966702824,0.11219528246732732
0.119367753179717,54.9288259663953,0.37899261634560144,11.073651314825293,61.48555650680361,0.11276401982391368
0.119991717684368,54.7014446765462,0.38097370364786837,11.027811246791714,61.265164983101414,0.11332129035498927
0.120606321539263,54.4609036124645,0.38292507088716,10.979318168272844,61.0292328648682,0.11386989734254388
0.121217970843283,54.2226392907898,0.3848670574274235,10.931284081023223,60.79539759938661,0.11441556840273823
0.121814621367363,53.9416212150138,0.3867614228413775,10.87463083694678,60.512499379262415,0.11494757185219709
0.122422484032544,53.6419060822014,0.38869138680332715,10.814208266171802,60.20888147302493,0.11548928170859618
0.123028586837345,53.3649037948339,0.39061576320857033,10.758364605038514,59.93031249542319,0.11602913120911217
0.123626455425357,53.0793864632095,0.39251399597550846,10.700804310983035,59.64140286780877,0.11656136120515366
0.124187374467048,52.6968821047223,0.39429491393287736,10.623691432312016,59.24116953590733,0.1170604408405528
0.1247492990524,52.3409083617176,0.39607902449136995,10.551927125722269,58.870399991607776,0.11756016553592749
0.125366792345716,52.0471025332206,0.39803956569764826,10.492695870697274,58.57208082869906,0.11810902015829819
0.12604893100354,51.7800552662273,0.4002053559362395,10.438859141671424,58.306875879839474,0.11871498437150198
0.126684708008855,51.6028467202449,0.4022239479281146,10.40313389880137,58.14013828942483,0.11927943372422165
0.127297888266588,51.3028967118013,0.40417079524641686,10.342663977099145,57.83364712517249,0.11982351980001726
0.127905630651241,50.9701317422642,0.40610037731769016,10.275578559240461,57.48949858713534,0.12036248880593325
0.128519007514984,50.646643501904,0.40804784886007417,10.210363329983847,57.15569985873392,0.12090616030151663
0.129150514753504,50.310015163589,0.4100528843423752,10.142499056979542,56.807579519223104,0.12146559315806274
0.129763284103084,49.9534718892967,0.41199842702729167,10.070619932882215,56.43559845400293,0.12200812768498508