File: example/data/02 processed data/test_ID_106.csv
Strain,Stress_MPa,Displacement(mm),Force(kN),True Stress (MPa),True Strain
0.0003214436484367998,-1.18525351394823,0.000269914538581,-0.2389471084119631,-1.185354275256992,8.50088397426392e-05
0.00032993965945789976,-1.12556916134526,0.0002968893735729,-0.2269147429272044,-1.125674411588795,9.350409247346646e-05
0.0003316769756474998,-0.813470726901281,0.0003024053524749,-0.1639956985432982,-0.8135482065554217,9.524124471583564e-05
0.00032708032224369976,-0.359284724881582,0.0002878109779179,-0.0724318005361269,-0.3593172937282021,9.064501851943876e-05
0.0003179131378242998,0.372376428644338,0.0002587051673863,0.0750710880146985,0.3724067705990792,8.147862301075999e-05
0.00030777781077709977,1.37894715790739,0.0002265255040116,0.2779957470341298,1.379045541119973,7.134407038801515e-05
0.0003021250390863998,2.73583938193505,0.0002085779538934,0.5515452193981062,2.7360191097399214,6.569168599994213e-05
0.0002931644337015998,4.46400032233964,0.0001801280317968,0.8999424649836714,4.464253579533971,5.673162909189343e-05
0.00028688775198779977,6.46466930953229,0.0001601995673555,1.3032773328017098,6.464995494485514,5.045528375824492e-05
0.0002800049142467998,8.53932395696171,0.0001383465575279,1.721527709723481,8.53969604706346,4.357276959948462e-05
0.0002798470180615998,10.6927724071702,0.0001378452371396,2.1556629172855124,10.693236642681429,4.341488028160656e-05
0.0002935375730976998,12.9470105413659,0.0001813127493794,2.610117325139366,12.947749898240705,5.7104747250127695e-05
0.0003110911042084998,15.2819739995135,0.0002370452106561,3.080845958301921,15.283114950299629,7.465712195584114e-05
0.0003454948844275998,17.6307399496302,0.0003462772128518,3.554357173845448,17.632662823170445,0.0001090577420755
0.00036893629698119977,19.9728413954402,0.0004207036977095,4.026524825320744,19.97548789881936,0.0001324963236151
0.0003861060149172998,22.3985404903691,0.0004752175521566,4.515545762858411,22.40189298787578,0.0001496636194186
0.0004217694258022998,24.8357628050481,0.0005884488817165,5.006889781497697,24.84036582137856,0.0001853210574539
0.0004537184928168998,27.3508644749905,0.0006898871694878,5.513934278158086,27.356807470415923,0.0002172636940108
0.0004983347707629998,29.891938217911,0.0008315438519667,6.026214744730858,29.899767023406586,0.0002618692846682
0.0005491922324078998,32.44380011159,0.0009930162926893,6.540670102496545,32.45394726815931,0.0003127121375299
0.0005842340107362998,34.9947826675434,0.0011042739388819,7.054948185776749,35.00695395147933,0.0003477423460171
0.0006200429320539997,37.5072285924171,0.0012179672640656,7.561457284231287,37.52161680551675,0.000383538176543
0.0006580975975181998,39.9797585477447,0.0013387908269145,8.059919323225332,39.99661666869147,0.0004215775258837
0.0006923893169339997,42.4412735707458,0.0014476670360596,8.556160751862354,42.46062501412115,0.0004558542042759
0.0007370420612668998,44.9040121747578,0.0015894394993166,9.052648854431174,44.92649161117618,0.0005004856021107
0.0007874676273531998,47.3609803029487,0.0017495406716406,9.547973629074455,47.387077928551456,0.0005508846671874
0.0008274116640334997,49.8284169412109,0.0018763629881005,10.045408855348116,49.85786456240904,0.0005908059085068
0.0008666551722608998,52.2592481477532,0.0020009611267225,10.535464426587046,52.29218317895175,0.0006300254691884
0.0009076484178822998,54.7028550538571,0.0021311146815705,11.028095578857592,54.739572552291456,0.0006709920570129
0.0009482655885850998,57.1261454434088,0.0022600741985519,11.516630921391217,57.16680979848891,0.0007115811593095
0.0009943730873011997,59.5708524026324,0.0024064655069755,12.009483844370692,59.61600364720817,0.0007576547990623
0.0010499209549041997,61.9451435723908,0.002582829986615,12.488140944193988,61.99553531234165,0.0008131590561063
0.0010912212940235998,64.2898102855659,0.0027139585633191,12.960825753570086,64.34476457884423,0.0008544249736822
0.0011291090658975998,66.5906135592285,0.0028342522390191,13.424667693540467,66.65005752633965,0.0008922796706254
0.0011675046415756999,68.9083125263278,0.002956158191797,13.891915805307686,68.97247122634596,0.0009306402662149
0.0012280663366135997,71.2418157261492,0.0031484415735424,14.36235005039168,71.31246161415135,0.000991143795943
0.0012890470029581999,73.527300237977,0.0033420551891865,14.823103727976164,73.60469623649895,0.001052062196058
0.0013426286065626998,75.8373342326594,0.0035121767806308,15.288806581304137,75.92122529546157,0.0011055860256998
0.0013866376216010998,78.1617703050611,0.0036519054033777,15.757412893500318,78.25167247555389,0.0011495454456434
0.0014308326796988997,80.4461279406618,0.0037922247128382,16.21793939283742,80.54221291528502,0.001193688754373
0.0014754035731278999,82.762513782304,0.0039337372994753,16.684922778512487,82.86505425079653,0.001238205484885
0.0015306438973807998,85.0495504622293,0.0041091253289782,17.14598937318543,85.15962267074035,0.0012933759306768
0.0015683468251784997,87.3049269452828,0.0042288321247359,17.600673272169015,87.4212097420431,0.0013310294170354
0.0016222877958218997,89.5704147743333,0.0044000947065287,18.057395618505595,89.69454652485616,0.0013848971875264
0.0016810275836468998,91.7909058996577,0.0045865935328731,18.505046629370995,91.92350671079971,0.001443553962746
0.0017329574521248998,93.988172478119,0.0047514708652907,18.94801557158879,94.1288282460597,0.0014954075773156
0.0017842597672783997,96.1932624896812,0.0049143557159031,19.39256171791973,96.34215316979063,0.0015466319199428
0.0018388578564806997,98.3568573956768,0.0050877046491204,19.828742450968445,98.5144670462736,0.0016011441454468
0.0018865608656575999,100.494904249404,0.0052391617032571,20.25977269667985,100.66073387262163,0.0016487697022297
0.0019464661595148998,102.582498495717,0.005429361011254,20.68063169673655,102.75791815485708,0.0017085745190895
0.0019996098099151994,104.623855063305,0.0055980921012749,21.09216918076229,104.808325607127,0.0017616260398712
0.0020479358700541996,106.664406358412,0.0057515273422163,21.503544321855856,106.85762942915584,0.0018098658789462
0.0021049197253593995,108.668766185854,0.0059324510828103,21.907623263068167,108.8718125290436,0.0018667450767361
0.0021610611773551,110.670791373164,0.0061107001928963,22.311231540829866,110.88379169637406,0.0019227802547109
0.0022161701308244,112.634670932097,0.0062856711201613,22.707149659910755,112.85765817562668,0.0019777818349639
0.0022774668849022996,114.593961631815,0.0064802883143587,23.102142664973904,114.8278519973138,0.0020389556060875
0.0023308239059422,116.533016268211,0.0066496968561603,23.493056079671337,116.77708216802756,0.002092202527724
0.0023877000674678997,118.476930263677,0.0068302786690044,23.88494914115729,118.73180599581848,0.0021489582065625
0.0024484846436729994,120.379056126818,0.007023269698456,24.26841771516651,120.64534103303036,0.0022096104601203
0.0025121694793321997,122.238709715537,0.0072254690516736,24.64332387865226,122.5168930270224,0.0022731527136011
0.0025594239335351,124.049750292154,0.0073755019437678,25.00842965889825,124.33791696125752,0.0023202987618155
0.0026174422181439,125.870293022902,0.0075597099974007,25.375451073417043,126.16999157803302,0.0023781809075248
0.0026749453531570997,127.638493283747,0.007742282451068,25.7319202460034,127.9497415567018,0.0024355458067658
0.0027335521037984995,129.391107130948,0.0079283588843544,26.08524719759912,129.71421236993322,0.0024940082827007
0.0027872650791899998,131.108211802156,0.0080988975812224,26.431415499314653,131.44264707127186,0.0025475860290842
0.0028292336368358,132.77929074063,0.0082321477517475,26.768305013311007,133.12356120984234,0.0025894469281157
0.0028796724350806996,134.412346757996,0.0083922909361754,27.097529106412,134.76763101607702,0.0026397540213026
0.0029545086696364997,136.008957107669,0.0086298959808898,27.41940575290608,136.37863999028588,0.0027143901817712
0.0030178076811836997,137.525352673503,0.0088308703425524,27.725111098978203,137.90786245563638,0.0027775156156308
0.0030844530682512996,139.006391280859,0.0090424694464921,28.02368848222117,139.4022845237013,0.0028439739425249
0.0031587087952097996,140.453208591455,0.009278231379585,28.31536685203733,140.8636518567516,0.0029180160469591
0.0032281023597335997,141.964352025546,0.009498555946948,28.620013368350072,142.38906268387257,0.0029872050214853
0.0033198374776334996,143.38586497671,0.0097898149462802,28.90659037930473,143.8279818535712,0.0030786623343199
0.0033996144964215996,144.742573686918,0.0100431069809328,29.18010285528268,145.20042097895998,0.0031581909618021
0.0034813878605412995,146.04321442772,0.0103027374120128,29.44231202862835,146.51711832978458,0.0032397031551949
0.0035802063322202997,147.289146601273,0.0106164860595936,29.69349195481664,147.78164838761057,0.0033381971516903
0.003684776029148,148.429465951815,0.0109484948473388,29.923380335885906,148.94130193391473,0.0034424129256925
0.0037849925494039998,149.502190283627,0.0112666822991516,30.1396415611792,150.03270797841532,0.0035422800655277
0.0038936117953403994,150.374833173994,0.011611548405,30.315566367877192,150.92478109660618,0.0036505093753311
0.0040138310617641,151.204767901067,0.0119932445758949,30.482881208855105,151.7759287711391,0.00377028340706
0.0041472660388877,151.961444699559,0.0124169006282623,30.635427251431093,152.5557408123658,0.0039032074089176
0.0042783638943333,152.636098383028,0.0128331363193021,30.77143743401845,153.25304322012906,0.0040337860338246
0.0044125830950772,153.195839107418,0.013259282281664,30.88428116405547,153.8356082019382,0.0041674559793082
0.0045594692887995,153.714767130547,0.0137256459467323,30.988897053518272,154.3792819243795,0.0043137206078585
0.0047172329493283,154.126919717113,0.0142265455689112,31.07198701496998,154.8175318893182,0.0044707928492829
0.0048741120150704,154.457719299708,0.0147246366026424,31.13867621082113,155.1740449019635,0.0046269599120236
0.0050249639765204,154.733372729929,0.0152035915802461,31.194247942353687,155.47431855758876,0.0047771042275623
0.0051725440811671,154.951402659703,0.0156721584124994,31.238202776196125,155.71626027504846,0.0049239702225932
0.0053356732183981,155.110547389278,0.0161900934232078,31.270286353678443,155.90149361074486,0.0050862849173977
0.0055027632236005,155.254999267065,0.0167206041897255,31.299407852240304,156.0726236422526,0.0052525133961818
0.0056679817273364,155.355701965019,0.0172451729390869,31.319709516147828,156.19952431067568,0.0054168528581575
0.0058355564304467,155.425525023349,0.0177772226214621,31.33378584470716,156.29577200268685,0.0055835084000319
0.0060129501323133,155.479987033626,0.0183404476248886,31.34476538597901,156.37812012304602,0.0057598988250035
0.0061881685457572,155.504643117012,0.018896766087573,31.349736052389616,156.43016590961474,0.0059340957259413
0.0063674222731436,155.542029266887,0.0194658966720248,31.35727310020442,156.49565606054568,0.0061122730198745
0.0065439115878424,155.540202753271,0.0200262502461935,31.35690487505943,156.521269532383,0.0062876714905888
0.0067159413546616,155.521274521585,0.0205724447558444,31.35308894355154,156.52897619983818,0.0064586083736725
0.0068904900624571,155.501982110302,0.0211266369030952,31.34919959343688,156.5367014532173,0.00663201833605
0.0070662412136152,155.478078972616,0.0216846468080221,31.344380720879386,156.5399647140053,0.0068065925199511
0.0072288811145176,155.444813621148,0.0222010284933872,31.33767442602344,156.5317536955897,0.0069681161106787
0.0074069173736651,155.401269693598,0.0227662936161806,31.32889597022936,156.51557235003006,0.0071449004774451
0.0075946411049721,155.34787758257,0.0233623164630803,31.318132120646112,156.4909598748383,0.0073312703536498
0.0077812960686254,155.272308779741,0.0239549459726795,31.302897449995783,156.44381736804712,0.0075165447388282
0.0079672792288229,155.180861695037,0.0245454425063066,31.28446171771946,156.3805413545062,0.0077011181543011
0.0081331035651941,155.086682885233,0.0250719347742851,31.26547526966297,156.31135160890506,0.0078656568253273
0.0083164096839177,155.00627675143,0.0256539317012326,31.249265393088287,156.258724133176,0.0080475102402968
0.0085057005251826,154.906198998085,0.0262549301222486,31.22908971801393,156.18716007846226,0.0082352662473731
0.0086967920896744,154.803616800018,0.0268616458395101,31.208409146883632,156.11331126589434,0.0084247726266119
0.0088772442512414,154.711972460082,0.0274345814524853,31.18993364795253,156.04880969161923,0.0086036948982151
0.0090649265438323,154.644995225624,0.0280304727314614,31.1764310374858,156.01027784664095,0.0087897520464955
0.0092556572773854,154.564249788364,0.0286360428104925,31.160152757334185,155.95829970140693,0.0089787957806639
0.0094707254544507,154.471593491596,0.0293188842726748,31.14147324790575,155.89802964057102,0.0091919188355345
0.0096521950722192,154.351273286944,0.0298950503090898,31.117216694647915,155.80460843030943,0.0093717118784404
0.0098640416165239,154.257446234756,0.0305676630872572,31.098301160926813,155.74257683167087,0.0095815603123859