File: example/data/02 processed data/test_ID_056.csv
Strain,Stress_MPa,Displacement(mm),Force(kN),True Stress (MPa),True Strain
-3.38728165697079e-05,1.30483001761722,-0.00010754619260882257,0.2630537315516316,1.3047858193493787,-3.387339026655298e-05
-3.924090015073e-05,2.67481783685187,-0.00012458985797856773,0.539243275909337,2.674712874592213,-3.9241670094992264e-05
-4.71023365452925e-05,5.23690968194364,-0.00014954991853130368,1.0557609918798379,5.236663011261344,-4.710344589514666e-05
-4.1880499919188e-05,9.82971905826451,-0.0001329705872434219,1.9816713621461253,9.829307384716286,-4.188137693177908e-05
6.83897438147705e-07,15.3622690403382,2.1713743661189633e-06,3.097033438532181,15.362279546554642,6.83897204378412e-07
6.40128675916458e-05,21.4163393299207,0.00020324085460347543,4.317534008912013,21.417710251214526,6.401081885554406e-05
0.0001441064771131,27.5981051488364,0.0004575380648340925,5.563777998005418,27.602082214544392,0.00014409609477210525
0.0002377398774723,33.8677998516884,0.0007548241109745524,6.8277484501003824,33.875851578275395,0.0002377116218257909
0.0003256034177449,40.2910417845559,0.0010337908513400576,8.12267402376647,40.30416068546545,0.00032555042045572083
0.0004214957066019,46.8058646570207,0.0013382488684610325,9.436062314855374,46.825593128017424,0.0004214069022395465
0.000535173377694,53.3827042550823,0.0016991754741784498,10.761953177824592,53.41127325722893,0.0005350302234944359
0.0006307344587152,60.0229229902707,0.00200258190642076,12.100621274838574,60.06078151611348,0.0006305356293379044
0.0007496951136297,66.639238678683,0.0023802819857742974,13.434470517622492,66.6891977902964,0.0007494142326226013
0.0008592908995195,73.3049745800319,0.002728248605974412,14.77828287533443,73.36796487757803,0.0008589219204529687
0.0009762655202318,80.019166260729,0.003099643026735965,16.131863918162964,80.09728621370705,0.0009757892829796948
0.0011032007206559,86.7953132410102,0.003502662288082482,17.497935149387658,86.89106589312725,0.0011025926419217637
0.0012221438932525,93.6024056813352,0.003880306861076687,18.870244985357175,93.71680128983239,0.0012213976833266296
0.0013467902974186,100.365421503785,0.004276059194304055,20.233668975163056,100.50059267966263,0.0013458841888336684
0.0014669662491733,107.071649187354,0.004657617841125227,21.585644476170565,107.22871968295517,0.00146589130532768
0.0015890529371392,113.670544791048,0.00504524307541696,22.915981829875278,113.85117330411443,0.001587791728428825
0.0017060868725461,120.253668225014,0.005416825820333867,24.243139514162824,120.4588314297482,0.0017046331595432786
0.0018201888249846,126.72514323162,0.005779099519326105,25.547788875494593,126.95580692117477,0.0018185342887134409
0.0019386232662939,133.161434480146,0.006155128870483132,26.845345191197435,133.41958433520227,0.0019367465613008017
0.0020548329746375,139.567033219205,0.006524094694474062,28.13671389699173,139.85382016123614,0.002052724692977768
0.0021727175678411,145.81573699442,0.0068983782778954915,29.396452578075074,146.1325534078555,0.0021703606303819377
0.0022839077585398,151.974638230921,0.007251407133363865,30.638087067353673,152.32173428627786,0.002281303605558004
0.0023907886981222,157.979002771829,0.007590754116537984,31.848566958800724,158.3566971861965,0.0023879353098167975
0.0025048776769545,163.897106792229,0.007952986624330536,33.04165672931337,164.30764899635028,0.002501745699922208
0.0026103739232566,169.801737534825,0.008287937206339704,34.23203028702072,170.24498356260958,0.0026069728147379016
0.0027232691659472,175.66680811768,0.008646379601882359,35.41442851652429,176.14519611970724,0.002719567786850265
0.0028214825255716,181.460128566494,0.008958207018689828,36.582361919005194,181.97211514833236,0.002817509614994704
0.0029356485305246,187.195051501983,0.009320684084415604,37.73852238279977,187.74459037984624,0.0029313479290243014
0.0030468006768688,192.874479682518,0.00967359214905844,38.88349510399563,193.46212977776543,0.003042168586006679
0.0031632217586024,198.512982112349,0.01004322908356262,40.02021719384956,199.14092269673182,0.0031582292980579913
0.0032791087302558,204.040861974422,0.010411170218562164,41.134637774043476,204.70993414625124,0.0032737441773258652
0.0033947691681967,209.439896998382,0.010778392109024522,42.22308323487381,210.15089710330244,0.0033890199471886774
0.0035027880610862,214.719445839125,0.011121352093948685,43.287440281167605,215.47156255049336,0.003496667587303316
0.00361217270343,219.877439363189,0.011468648333390249,44.3272917756189,220.6716746477568,0.0036056644754639193
0.0037337562194385,224.921250080068,0.011854675996717237,45.34412401614171,225.76105119643836,0.0037268030539276565
0.0038619138725929,229.808165445762,0.012261576545482458,46.32932615386562,230.6956647879321,0.003854475827123491
0.0040051206498441,234.468670306694,0.012716258063255015,47.268883933829514,235.40774561988084,0.003997121505379985
0.0041638514964587,238.914749529959,0.013220228501256372,48.165213505239734,239.90955506731535,0.004155206655730018
0.0043621379841361,242.940874905092,0.013849788099632117,48.97688038086654,244.00061652341475,0.004352651437983448
0.0046191887012261,246.364693517025,0.014665924126392869,49.667122213032236,247.50269852569986,0.004608552988762823
0.0049260772172382,248.948122788845,0.015640295164731283,50.18794155423116,250.17446046478935,0.004913983798013595
0.005272563287757,250.742853162093,0.016740388438628472,50.549759197477954,252.06491072434292,0.0052587119925000415
0.0056379858466451,251.899704816508,0.017900605063098193,50.78298049100801,253.31991178703757,0.005622151890975578
0.0060156944334926,252.662454952904,0.019099829826339003,50.93675091850545,254.18239507671674,0.005997672384377266
0.0064064739486622,253.214545724818,0.020340554787002484,51.048052418123305,254.8367581154264,0.0063860397222262055
0.0067978890286442,253.643293983274,0.021583297665945335,51.13448806702803,255.36753294863206,0.006774887563123022
0.007192225378675,253.979448418495,0.022835315577293125,51.20225680116859,255.80612585307236,0.007166484674001594
0.0075758679410056,254.26225767028,0.02405338071269278,51.259271146328445,256.188514956772,0.007547315170811061
0.0079604242264554,254.513626067524,0.025274346918995893,51.30994701521284,256.53966250243496,0.007928907198313254
0.0083406753135214,254.762765068484,0.026481644120430445,51.360173437806374,256.8876585738951,0.00830608409085233
0.0087283593203139,254.984985063548,0.027712540841996633,51.40497298881128,257.2105856344675,0.008690487405671651
0.0091115662605743,255.219546054553,0.0289292228773234,51.452260484597886,257.5449958594228,0.009070306379426027
0.0094929280828679,255.410359991315,0.030140046663105578,51.490728574249104,257.834952170332,0.009448153380063848
0.0098658814148687,255.620088911485,0.03132417349220812,51.53300992455537,258.1420063959439,0.0098175313573575
0.0102385659704042,255.810597493501,0.03250744695603333,51.57141645468981,258.42973117186676,0.010186506892504915
0.0106084566187348,256.032881512999,0.03368184976448299,51.6162289130206,258.7489952294993,0.010552581759455858
0.0109799102179653,256.242888738519,0.03486121494203982,51.65856636968543,259.05641265086,0.010920068642052092
0.011350500211093,256.41788231373,0.03603783817022027,51.693845074447964,259.32835354106,0.011286566614257539
0.0117199676478744,256.605362961297,0.037210897282001214,51.73164117299747,259.6127695134744,0.01165182076309589
0.0120893559310466,256.810621855977,0.03838370508107295,51.77302136616496,259.91529687046733,0.012016863341930395
0.0124605753800532,257.006598531285,0.03956232683166891,51.812530263907064,260.2090486254552,0.012383581344213935
0.0128373923561371,257.202225840093,0.04075872073073529,51.851968729362746,260.50403172807404,0.012755691509172079
0.0132077163563832,257.393843947619,0.041934499431516656,51.89059893984,260.7934288303584,0.013121254943843646
0.0135807267310025,257.587222638288,0.04311880737093293,51.92958408387886,261.08544431833644,0.013489335174518636
0.0139540946742038,257.774742697922,0.04430425059059707,51.967388127901074,261.3717558621474,0.013857632619751214
0.0143262418076234,257.969747160519,0.04548581773920429,52.00670102756063,261.665484137392,0.014224590905449589
0.0146958128160292,258.170514225571,0.046659205690892706,52.047175667875116,261.96453977724804,0.014588875770319086
0.0150567572500188,258.384772386167,0.04780520426880969,52.09037011305127,262.2752091810869,0.014944529403296124
0.015424552463518,258.584148198837,0.04897295407166965,52.13056427688554,262.57269295896407,0.015306803328953162
0.0157839576050417,258.776897006579,0.05011406539600739,52.16942243652633,262.86142057809514,0.0156606863926496
0.0161425236587377,258.959182265883,0.05125251261649219,52.20617114480201,263.1394369922574,0.016013618509755464
0.0165007767141196,259.136028482559,0.05238996606732972,52.2418233420839,263.4119742271335,0.01636611819233697
0.0168528175714972,259.348657514262,0.0535076957895036,52.284689354875226,263.7194131267626,0.016712384441241682
0.0172074449623373,259.546184106989,0.05463363775542092,52.32451071596899,264.0123107851947,0.017061073613303345
0.0175521416566946,259.716942967077,0.055728049760005345,52.358935702162725,264.2755315406788,0.017399881893083766
0.0178907233825168,259.886610296927,0.05680304673949084,52.39314063586049,264.53616975256926,0.01773256794854665
0.0182280887558947,260.067258228595,0.057874181799965674,52.42955925888476,264.80778729408803,0.018063948783941984
0.018564917855588,260.244349939511,0.0589436141914919,52.46526094780542,265.0757649185189,0.018394693343325698
0.0189100888397737,260.480267144571,0.060039532066281494,52.51282185634551,265.4059721372828,0.018733515646768558
0.0192584317275734,260.657542746183,0.06114552073504554,52.5485606176305,265.67739823743744,0.019075335165298333
0.0196036902181305,260.866841070974,0.062241716442564335,52.59075515990836,265.9807938115116,0.01941401279351155
0.0199566510939845,261.026860837087,0.06336236722340079,52.623015144756735,266.2360828249708,0.01976012746560862
0.0203005954326421,261.211299073293,0.06445439049863866,52.66019789317586,266.5140439782148,0.02009728528480145
0.0206513805199613,261.394599604845,0.06556813315087713,52.69715128033675,266.79275894714755,0.02044103182553974
0.0209991829847727,261.578261704176,0.06667240597665332,52.73417755956188,267.0711914865407,0.020781738971407802
0.0213448871750686,261.765572857265,0.0677700167808428,52.77193948802463,267.3529294762205,0.021120275654475624
0.0216922988383801,261.9368273378,0.06887304881185681,52.80646439130049,267.61883927318877,0.02146036899104186
0.0220333612481549,262.120798762133,0.06995592196289181,52.84355303044602,267.896201011914,0.021794134348694184
0.0223850180439001,262.303119253435,0.07107243228938281,52.8803088414925,268.1747793108944,0.022138150820836273
0.0227324146334964,262.510343845077,0.07217541646135107,52.92208531916752,268.477837826945,0.022477883481060973
0.0230792676348306,262.681327395903,0.07327667474058715,52.95655560301405,268.7438200535456,0.02281696943668815
0.0234282943181726,262.871638514108,0.074384834460198,52.99492232444417,269.0302726291168,0.023158064376393932
0.0237689856000662,263.029154548845,0.07546652928021018,53.02667755704715,269.2810907357141,0.023490901165872765
0.0241061402861658,263.207080627076,0.07653699540857642,53.06254745441852,269.5519874369844,0.023820173868962822
0.0244356684949313,263.363573206961,0.07758324747140688,53.09409635852334,269.7990381754869,0.024141893650512208
0.0247699980202625,263.555200707535,0.07864474371433344,53.13272846263905,270.0834625072905,0.024468195235326815
0.025104187691745,263.746862229663,0.07970579592129037,53.171367425500065,270.3680129621853,0.02479425395324492
0.0254380014928453,263.89983001193,0.08076565473978382,53.2022057304051,270.61291428173513,0.025119839845415035
0.0257770830887495,264.083220390727,0.08184223880677965,53.23917723077056,270.89051550508333,0.0254504551977901
0.0261090793432741,264.267294283203,0.08289632691489526,53.276286527493724,271.1670700374755,0.025774056246912792
0.0264481139466356,264.484063986576,0.08397276178056802,53.31998729969373,271.47916864796224,0.026104409630051697
0.0267785631393769,264.674573181884,0.08502193796752165,53.35839395346781,271.7621779512227,0.026426292449208796
0.0271099514794044,264.829859804198,0.08607409594710896,53.38969973652632,272.0093844537873,0.02674898605262934
0.0274409903894094,264.992952162084,0.08712514448637483,53.422579155876136,272.264621215625,0.02707123546112411
0.0277758707779071,265.159342431913,0.08818838971985504,53.45612343427366,272.5243740628566,0.02739711872705934
0.0281097427659497,265.343881328665,0.08924843328189029,53.493326475858865,272.8026295773325,0.027721914998581832
0.0284440312762532,265.524419206739,0.09030979930210391,53.52972291207859,273.0770040912645,0.02804701081418076
0.0287780280994044,265.690136162899,0.09137023921560897,53.563131450440444,273.3361743671295,0.02837171744909501
0.029110516832815,265.854571549068,0.09242589094418763,53.596281624292104,273.59373552922796,0.028694853254600642
0.0294492562088094,266.020297107452,0.09350138846296985,53.629691896862326,273.85439699371295,0.029023956527177715
0.0297835634983893,266.185249304913,0.09456281410738603,53.66294625987046,274.1131945799205,0.029348647634776324
0.0301190238423111,266.342330741734,0.09562790069933774,53.69461387753357,274.36430175156096,0.029674352693791053
0.0304547632770443,266.507140494111,0.09669387340461565,53.727839523612786,274.6235523695011,0.0300002225459681
0.0307873253937974,266.654296045706,0.09774975812530673,53.75750608281434,274.86386862571914,0.03032290382777058
0.0311188882002509,266.811038332178,0.0988024700357966,53.78910532776708,275.1139012046299,0.03064451186903394
0.0314476247160025,266.941363430676,0.09984620847330794,53.81537886762429,275.33603524902196,0.030963276395148936
0.0317735320992801,267.123619881406,0.10088096441521431,53.85212176809145,275.6110807921837,0.031279197337420794
0.0321084318045593,267.28869475336,0.10194427097947577,53.88540086227738,275.8709155809779,0.03160373111801077
0.0324427470923978,267.477750705399,0.103005722018363,53.923514542208444,276.1554637243777,0.031927593557632424
0.0327768490351175,267.635800174863,0.10406649568649806,53.955377315252385,276.40805839358734,0.03225114457008724
0.0331079069318556,267.78585083482,0.10511760450864152,53.98562752829971,276.651679861927,0.032571644441743486
0.0334385921893401,267.927952071399,0.10616753020115482,54.01427513759403,276.88708559683954,0.032891681044304906
0.033775299432167,268.077171156133,0.10723657569713022,54.04435770507641,277.1315578828596,0.03321744050941797
0.0341101996824691,268.241775810831,0.1082998839918394,54.07754200346352,277.39155634691855,0.03354134650264006
0.0344464887940197,268.375153310891,0.10936760192101255,54.104430907475624,277.6197350220079,0.033866490228588356
0.0347816490503308,268.524888028751,0.11043173573480028,54.1346174265962,277.86462644544633,0.03419043735951348
0.035116965999977,268.681935056676,0.11149636704992696,54.16627810742589,278.11722943486933,0.03451443096010958
0.0354636793620794,268.83764205822,0.11259718197460208,54.19766863893716,278.37161399663023,0.03484932577922182
0.0358144346051353,268.983323918107,0.11371082987130458,54.227038101890365,278.6168095824439,0.035188010617383664
0.0361615669888704,269.171654329842,0.11481297518966352,54.26500551289615,278.90532313939565,0.03552308436989428
0.0365093229345761,269.2688069929,0.11591710031727911,54.284591489768644,279.09962882361185,0.03585864748380641
0.0368429219748213,269.399683747346,0.11697627727005762,54.31097624346495,279.325155275691,0.03618044426864405
0.037179388409014,269.498645411319,0.11804455819861943,54.33092691492191,279.5184402247695,0.0365049021449744
0.037510598038005,269.672549296166,0.11909614877066588,54.36598593810706,279.78812789469856,0.03682418804693421
0.0378483950420042,269.821311171885,0.12016865425836333,54.39597633225201,280.03361474787,0.03714971920381688
0.0381776524000154,269.960416671833,0.1212140463700489,54.424020001041534,280.2668716212936,0.0374669188470273
0.0384961352222354,270.084410517289,0.12222522933059737,54.44901716028546,280.4816165059803,0.037773642827091176
0.038825937150247,270.22095842916,0.12327235045203422,54.47654521931866,280.7125403778101,0.03809116887196286
0.0391594140087343,270.378517281346,0.1243311394777314,54.50830908391935,280.96638157863396,0.03841213057764965
0.0395020241634817,270.536011899289,0.12541892671905439,54.540059998896666,281.2227319784267,0.03874177556125121
0.039844001939706,270.702630265238,0.12650470615856654,54.573650261471975,281.48850639060964,0.039070703767537844
0.0401737147493141,270.853576928334,0.12755154432907226,54.60408110875213,281.73477126668433,0.03938773261755613
0.0405104210943793,270.950169543031,0.12862058697465428,54.62355417987504,281.9264750068126,0.039711382269325704
0.0408439508453403,271.071359515346,0.12967954393395545,54.647986078293755,282.1429847989703,0.040031875269760875
0.0411795847470234,271.191689297534,0.1307451815717993,54.67224456238286,282.35925044965023,0.04035428651906025
0.0415168629876355,271.33272626308,0.1318160399857427,54.70067761463694,282.59760988340594,0.04067817264651529
0.0418490504139727,271.468811978904,0.1328707350643633,54.72811249494705,282.82952397723045,0.04099706759148449
0.0421861890817611,271.597174172532,0.13394115033459147,54.75399031318245,283.05482391624645,0.041320611708532115
0.0425215019529962,271.705028292817,0.13500576870076292,54.77573370383191,283.25833418400896,0.041642299852696144
0.0428645887941464,271.811085403657,0.1360950694214148,54.79711481737725,283.46215580917533,0.041971339013135274
0.0432116345404976,271.971187205614,0.13719693966607988,54.82939134065178,283.72350675268825,0.04230406487010149
0.0435541177145303,272.082062304329,0.1382843237436337,54.85174376055273,283.93235647394386,0.04263230791965083
0.0438952473592673,272.20207352986,0.13936741036567368,54.875938023619774,284.15045087915865,0.042959146647795744
0.0442310952224443,272.298133694324,0.14043372733126064,54.89530375277572,284.3421783746515,0.04328082054196989
0.0445646186319323,272.384038650859,0.14149266415638503,54.91262219201318,284.52272945476005,0.0436001657130753
0.0448943224499661,272.51683626741,0.14253947377864234,54.939394191509855,284.75129498784366,0.04391575346097272
0.0452229206848621,272.599975762236,0.14358277317443716,54.95615511366678,284.9277428448269,0.04423018389656913
0.0455465252858171,272.718545735965,0.14461021778246927,54.980058820370544,285.1399278752394,0.04453973940893125
0.0458802578622219,272.833718977082,0.14566981871255452,55.003277745779734,285.35140035725954,0.044858882858681934
0.0462136988796563,272.959677099246,0.14672849394290874,55.028670903207995,285.57415342299873,0.045177645808293386
0.0465481588144612,273.08484288072,0.1477904042359143,55.05390432475315,285.7964395169539,0.04549728077910754
0.046887848559871,273.216229667969,0.1488689191775904,55.08039190106255,286.02675086873967,0.04582180920719847
0.0472274301651806,273.332410160124,0.1499470907744484,55.103813888281,286.24119747284175,0.04614612908751837
0.0475671768900107,273.420748626127,0.15102578662578398,55.12162292302721,286.4266017414252,0.046470501440459284
0.0479022381029679,273.510175184708,0.15208960597692306,55.13965131723713,286.6119247199903,0.04679029729471067
0.0482323892881532,273.581570174396,0.15313783598988642,55.154044547158236,286.7770629691116,0.04710530682091292
0.0485753827745927,273.716723493058,0.15422684030933181,55.1812914562005,287.01261810854066,0.04743246460244049
0.0489197174763889,273.816954138401,0.15532010298753476,55.201497954301644,287.2120021750969,0.04776079405107496
0.0492625855765982,273.923138491144,0.15640870920569927,55.222904719814636,287.4173005424744,0.04808761799078922
0.0496121536603832,273.99119234796,0.15751858787171666,55.23662437734873,287.58448548431863,0.04842071846647017
0.0499596503682943,274.075186432589,0.1586218899193344,55.253557584809954,287.7678869213862,0.04875173521037682
0.0503045091400859,274.189640734358,0.1597168165197727,55.27663157204658,287.98261602279644,0.04908013082988
0.0506466423610384,274.27771787351,0.1608030894962969,55.29438792329962,288.16896335825146,0.04940582447937988
0.0509875132961994,274.361307992534,0.16188535471543308,55.31123969129486,288.35030883176603,0.04973021104041154
0.0513289315644407,274.418448515955,0.1629693577170992,55.32275922081652,288.50405427985044,0.050055013019749586
0.0516678049773793,274.527775504847,0.16404528080317926,55.34479954177716,288.7120230705052,0.050377289711846455
0.0520141893565868,274.59822967268,0.16514505120716308,55.359003102012295,288.8812339878583,0.050706602206102555
0.0523573185043262,274.71895221983,0.16623448625123566,55.38334076751773,289.1024999003784,0.051032713018284284
0.0527013268985191,274.786267350568,0.16732671290279813,55.396911497874505,289.26786825343413,0.0513595527460101
0.0530466058457991,274.880251764477,0.16842297356041214,55.41585875571857,289.4617161346212,0.05168749223487797
0.0533904136074344,274.985287986606,0.1695145632036042,55.43703405809977,289.6668662481704,0.05201392759611901
0.0537379661723162,275.059193131096,0.17061804259710392,55.45193333522895,289.84031474695945,0.05234381026617262
0.0540866332436914,275.122957237923,0.1717250605487202,55.46478817916528,290.00343172297033,0.052674641469728896
0.0544298670125002,275.184131800943,0.17281482776468812,55.47712097107012,290.1623674988187,0.053000210439000904
0.0547719982323251,275.254529110174,0.17390109438763218,55.49131306861108,290.330769692036,0.05332462815213034
0.0551129021529762,275.314294005919,0.17498346433569942,55.503361671593275,290.4876637527829,0.053647777460943666
0.0554571987863981,275.415443087968,0.17607660614681395,55.523753326534354,290.6892120641414,0.053974036831644284
0.0557997524456463,275.486480302604,0.177164214014927,55.538074429004965,290.8585577056117,0.05429853893647273
0.0561479677266796,275.572797439627,0.1782697975322077,55.555475963828805,291.045649976618,0.054628296421341
0.0565011373566403,275.657974483387,0.17939111110733294,55.57264765585082,291.2329635631261,0.054962634605945936
0.0568558843151109,275.737304064477,0.1805174327004771,55.588640499398565,291.4145923257274,0.05529835351965968
0.0572094717507078,275.816886580005,0.18164007280849725,55.60468433452901,291.596224961172,0.05563286298776072
0.0575632073254767,275.868279881683,0.1827631832583885,55.6150452241473,291.74814287103493,0.055967400672654835
0.0579140527145126,275.910481214715,0.1838771173685775,55.62355301288654,291.8895753682705,0.056299094516762634
0.0582697928356878,275.953953724056,0.18500659225330876,55.632317070769695,292.0337334397458,0.056635303608684726
0.0586187422020912,276.025965184949,0.18611450649163955,55.64683458128571,292.2062600792089,0.05696498499132555
0.058966131219339,276.078899188531,0.18721746662140132,55.657506076407856,292.3582037849726,0.057293084256412295
0.0593142640534972,276.166111328058,0.18832278836985358,55.67508804373649,292.5467009779979,0.05762177807623839
0.0596647516307111,276.249287233047,0.18943558642750774,55.69185630618228,292.73163234396776,0.05795258605292532
0.0600235880159639,276.312749826272,0.19057489195068536,55.704650364976445,292.89803248540227,0.05829116072163381
0.0603823497671297,276.381108634352,0.1917139605106368,55.71843150068537,293.0696494049385,0.05862955041220814
0.0607349686505941,276.431443071648,0.19283352546563626,55.72857892324424,293.220498100643,0.05896203450787881
0.0610958482592989,276.474620862015,0.193979318223274,55.73728356578223,293.36607234574785,0.05930219321356693
0.0614467331054446,276.526798128108,0.1950933776097866,55.74780250262658,293.51846648918905,0.05963282012529328
0.0618034650706482,276.571525803616,0.196226001599308,55.75681960200898,293.66460443815566,0.05996884455507235
0.062155911120896,276.614603143246,0.1973450178088448,55.76550399367839,293.8078358309595,0.06030072100942775
0.0625067476581036,276.664766488277,0.1984589238144789,55.77561692403664,293.95818123304787,0.06063097253330768
0.0628630199848438,276.740714927277,0.19959008845187903,55.79092812933904,294.1374720203704,0.06096622933003195
0.0632183683862738,276.803795536564,0.2007183196264193,55.80364518017131,294.3028798535133,0.061300504778453
0.0635734804338758,276.855736281844,0.20184580037755565,55.81411643441975,294.4564190153641,0.06163444629802321
0.0639268656015197,276.890237139538,0.20296779828482503,55.82107180733085,294.59096211553015,0.061966653220153566
0.0642737542303553,276.924819823266,0.2040691696813781,55.82804367637043,294.723817632872,0.06229264563710438
0.0646270092611137,276.953897616195,0.20519075440403597,55.83390575942491,294.8525997223383,0.062624511772021
0.0649793293220116,277.018232988168,0.20630937059738683,55.84687577041467,295.0186919777079,0.06295538988571657
0.0653442322086242,277.050184262856,0.20746793726238183,55.85331714739177,295.1538158367702,0.06329796966727728
0.0657033303079649,277.126988695775,0.20860807372778853,55.86880092106824,295.33515477130516,0.06363498523563506
0.0660687582064037,277.144761165033,0.20976830730533175,55.872383850870655,295.4553713786171,0.06397782479525502
0.0664375005254417,277.195324295603,0.21093906416827737,55.882577377993556,295.6114887991421,0.06432365479805398
0.0668032734508614,277.246038715569,0.21210039320648494,55.89280140505871,295.7669816530533,0.06466658179763743
0.0671628447402037,277.27732250286,0.21324203205014675,55.89910821657658,295.90005626409896,0.06500357992490859
0.0675252933895386,277.315734338317,0.21439280651178502,55.906852042604704,296.04156066104713,0.06534315988166545
0.0678848102187164,277.334853418772,0.21553427244442455,55.910706449224435,296.1616773101409,0.06567987912071675
0.0682510851874533,277.367143456467,0.21669719547016422,55.917216120823745,296.2977519927149,0.06602281139680859
0.0686250304316399,277.399883295258,0.21788447162045665,55.92381647232401,296.4364587281284,0.06637280384163995
0.0689935054783643,277.432638934381,0.21905437989380666,55.9304200091712,296.5736892285773,0.06671755670019172
0.0693690248950085,277.45040878908,0.22024665404165197,55.93400241187852,296.69687310349997,0.06706877817472702
0.0697379988141112,277.479138813297,0.22141814623480305,55.93979438476068,296.8299786667993,0.06741375756909333
0.0701043044500795,277.498320530209,0.22258116662900237,55.943661418890144,296.95214727704456,0.06775612451733777
0.0704757795526611,277.511275415074,0.22376060007969897,55.94627312367892,297.0690988846046,0.06810320343214865
0.0708483336927418,277.549355879303,0.22494345947445518,55.953950145267484,297.2132652608454,0.06845116957285115
0.0712280936563441,277.580207069946,0.2261491973588925,55.96016974530112,297.3517160562715,0.0688057413917951
0.0716066293908477,277.63118159018,0.22735104831594147,55.97044620858029,297.5114147176512,0.06915904511080788
0.0719837437196613,277.638862068979,0.22854838630992463,55.97199459310617,297.62434676277076,0.06951089809301451
0.0723616020390652,277.63261483691,0.22974808647403203,55.97073515112106,297.7225556248036,0.06986332110553169
0.072723264237443,277.635712654342,0.23089636395388152,55.97135967111535,297.8262879474545,0.07020052193845949
0.0730960837392832,277.667908438775,0.23208006587222413,55.97785034125704,297.9643451257273,0.07054800646081044
0.0734711908156135,277.687862306166,0.23327103083957285,55.98187304092306,298.08992022484216,0.07089750128875748
0.0738517720950065,277.729249881714,0.23447937640164562,55.99021677615354,298.24004714809547,0.07125197175263405
0.0742438438439872,277.742095310137,0.23572420420465937,55.99280641452362,298.36273606324465,0.07161701300165975
0.074629738411721,277.756448016062,0.23694941945721418,55.9956999200381,298.4853390736695,0.07197617286575646
0.0750202969993843,277.771264725629,0.23818944297304515,55.998686968686805,298.60974750324027,0.07233954233104341
0.0754077912882522,277.788419303428,0.23941973734020072,56.002145331571086,298.7358304485544,0.07269993038137854
0.0757965694582136,277.800110403763,0.24065410802982817,56.00450225739862,298.8564057674812,0.07306138202334085
0.0762021576849661,277.824274761251,0.24194185064976736,56.0093737918682,298.99508395531916,0.07343832298193811
0.0766133005501311,277.818105546352,0.24324722924666622,56.00813007814457,299.1026675648427,0.07382028128550824
0.0770258741579017,277.819015154884,0.24455715045133788,56.008313455224624,299.21826765487634,0.07420342217341828
0.0774373925987479,277.817517286568,0.2458637215010246,56.0080114849721,299.33098144349736,0.07458543699093735
0.0778509233316099,277.824080864216,0.2471766815778614,56.00933470222594,299.45294208325106,0.07496917287896665
0.0782673858230643,277.834142238505,0.24849894998822916,56.01136307528262,299.5794942439062,0.0753554805271744
0.0786906397548941,277.830237070875,0.24984278122178874,56.0105757934884,299.69287616923606,0.07574793502303685
0.0791042793516437,277.817161335252,0.25115608694146874,56.00793972518681,299.79368767419646,0.07613132604704347
0.0795234473702459,277.817807034652,0.25248694540053074,56.008069898185845,299.9108367908893,0.0765196913206679
0.079957966898613,277.814740236872,0.25386654490309624,56.007451631753405,300.0282420406786,0.07692212084042216
0.0803918311112543,277.801703122492,0.2552440637782324,56.00482334949438,300.1346907223342,0.07732378192222848
0.0808275278319561,277.773769263969,0.2566274008664606,55.99919188361615,300.2255363301398,0.07772697720622526
0.0812838919159911,277.765318038807,0.25807635683327174,55.997488116623494,300.34316412828423,0.07814912389731989
0.0817369447011972,277.755318703822,0.2595147994263011,55.99547225069052,300.45818982917973,0.07856803136613563
0.0822037064714188,277.769209391233,0.26099676804675465,55.998272613272576,300.602867946828,0.07899943116188086
0.0826857133351183,277.758795858354,0.2625271398390006,55.99617324504417,300.7254800290055,0.07944472584275858
0.0831715964930375,277.732302832011,0.26406981886539405,55.990832250933416,300.8317418562371,0.07989340098295877
0.0836825144822198,277.660001848984,0.2656919834810479,55.976256372755174,300.8952889748448,0.08036497679977331
0.0842017651343075,277.610954000988,0.26734060430142625,55.96636832659918,300.9862863484902,0.08084401589507896
0.0847372314775656,277.53484649347,0.2690407099412708,55.95102505308356,301.05238102387784,0.08133777469140605
0.0852877397037255,277.455672381844,0.27078857355932845,55.935063552179756,301.1192395472689,0.08184514971729798
0.0858464021658578,277.355974574075,0.2725623268765985,55.91496447413352,301.16598711046447,0.08235977703920172
0.086406470277841,277.20965261511,0.2743405431321452,55.88546596720617,301.16236022452813,0.08287543350949422
0.0869777960037484,277.070739608082,0.27615450231190114,55.85746110498933,301.16974187632144,0.0834011810709641
0.0875570835629537,276.920718967142,0.277993740312378,55.82721694377583,301.16708949806133,0.08393397323571823
0.0881615650073691,276.743493978241,0.2799129688983969,55.79148838601339,301.14163351297015,0.08448963465854582
0.0887789660380447,276.498464855249,0.2818732171707919,55.742090514818194,301.04571267620463,0.08505685368765965
0.0894160396043337,276.216439164398,0.2838959257437595,55.68523413554264,300.91461922808986,0.08564180919697316
0.0900539843648617,275.877356793565,0.2859214003584359,55.6168751295827,300.7212119688721,0.08622722195487409
0.090695820300658,275.491728111175,0.2879592294545891,55.53913238721289,300.4776763782639,0.08681585981966337
0.0913569818564853,275.048858648298,0.2900584173943408,55.44984990349688,300.17649223747753,0.08742185943196154
0.0920179817492194,274.567991354187,0.29215709205377155,55.352907057004096,299.8331837715364,0.08802734399045153
0.0926979517422783,273.974734082271,0.2943159967817336,55.23330639098584,299.37163076083294,0.0886498231005191
0.0933886715702686,273.337039270272,0.2965090322356028,55.10474711688683,298.863622258673,0.08928174668818446
0.094072594870136,272.611461393688,0.29868048871268177,54.958470616967496,298.25672895833213,0.08990705908355845
0.0947710472877352,271.777505161468,0.3008980751385592,54.790345040551955,297.5341439548682,0.09054525217131756
0.0954729165530403,270.937375937763,0.3031265100559029,54.62097498905303,296.8045574217688,0.09118615729505483
0.0961856228657622,269.973955006982,0.30538935259879496,54.42674932940758,295.94156802686183,0.09183653811398798
0.0968984411524407,268.989811673525,0.3076525506589992,54.22834603338265,295.0545051105782,0.0924865982949682
0.0976299384500762,267.960630919937,0.30997505457899194,54.0208631934593,294.121610823694,0.09315325390218313
0.0983702100852737,266.900184971483,0.312325417020744,53.80707729025097,293.1552122389262,0.0938274539141747
0.0991265428153675,265.73171963675,0.3147267734387918,53.5715146787688,292.07278632072354,0.09451581239202951
0.0998694528503743,264.567341746417,0.31708551279993835,53.33677609607768,290.9895374087097,0.0951914935344557
0.100621770384891,263.279657542982,0.3194741209720289,53.07717896066518,289.7713227912847,0.09587526591753526
0.101374808156646,261.993090047027,0.321865015897351,52.81780695348065,288.55258928891124,0.09655922501942409
0.102142609120602,260.649337015261,0.32430278395791134,52.546906342276614,287.2727403635548,0.09725611172339065
0.10290955266821,259.333315762381,0.32673782972156673,52.28159645769602,286.0211912794513,0.0979517357016574
0.103688212927829,257.861308573175,0.32921007604585706,51.984839808352085,284.59848684235897,0.09865749214180224
0.104470740465272,256.398009901169,0.3316946009772386,51.689838796075676,283.1840998493663,0.0993662523232182
0.105240536662787,254.84664170774,0.3341387039043487,51.377082968280384,281.6668390477716,0.10006299151862723
0.106019159051514,253.329329154457,0.33661082998855696,51.07119275753854,280.18709159449674,0.10076722578149157
0.1068062934936,251.723878245819,0.33910998184218,50.747533854357116,278.6095726650892,0.1014786551211895
0.107626347253003,250.050899313502,0.3417136525282845,50.410261301602006,276.96296423394267,0.10221929972857165
0.108454201077548,248.357645568526,0.3443420884212149,50.06890134661485,275.29307560016133,0.1029664330975985
0.109283397588511,246.507849631589,0.3469747873435224,49.695982485728344,273.4470649715668,0.10371421908463431
0.110110443612087,244.712513196957,0.3496006584683762,49.33404266050653,271.6579165825026,0.10445950912419842
0.110949979768144,242.807915185843,0.35226618576385715,48.95007570146595,269.7474484632575,0.1052154869329987
0.111800431156486,240.86863826875,0.354966368921843,48.559117474980006,267.79785587927194,0.10598071133755797
0.112655396755081,238.80715032924,0.3576808846973822,48.14352150637478,265.7100645975308,0.10674940778004674
0.113540251067152,236.672524021346,0.36049029713820757,47.71318084270335,263.5443818194262,0.10754435530367036
0.114477165512132,234.333069817635,0.36346500050101904,47.241546875235215,261.1588554361144,0.10838538508488653
0.114961299539409,233.031961932333,0.36500212603762355,46.97924352555833,259.82161911029203,0.10881969537644758