File: example/data/02 processed data/test_ID_100.csv
Strain,Stress_MPa,Displacement(mm),Force(kN),True Stress (MPa),True Strain
-9.76473067799621e-05,-0.168061371096594,-0.00031003019902637967,-0.03388117241307335,-0.16804496035633268,-9.76520745886078e-05
-0.0001463418801879,0.952535782355566,-0.00046463546959658246,0.19203121372288212,0.9523963864782299,-0.00014635258920566322
-0.0002326700916792,4.30245130598119,-0.0007387275410814599,0.8673741832858081,4.301450254241383,-0.00023269716356422905
-0.0002420835781021,9.17995854242529,-0.0007686153604741675,1.8506796421529383,9.177736225214511,-0.00024211288506138142
-0.0001860146099484,15.0626846913234,-0.00059059638658617,3.0366372337707976,15.059882811905767,-0.00018603191281169566
-6.6233639784687e-05,21.5700206257467,-0.00021029180631638119,4.348516158150535,21.568591964770427,-6.623583332901852e-05
8.79880478710127e-05,29.0540014655843,0.0002793620519904653,5.857286695461795,29.0565578704561,8.79841771497895e-05
0.000246143299381,36.6773464618707,0.000781504975534675,7.394153046713133,36.68637434494136,0.0002461130110891528
0.0003906602165116,44.3466367031673,0.00124034618742433,8.940281959358527,44.363961169863316,0.00039058392867695913
0.0005332285915359,52.0164152132701,0.0016930007781264824,10.486509306995252,52.044151853091016,0.0005330864756883126
0.0006818422069269,59.6631006185761,0.0021648490069929075,12.028081084704944,59.703781438773966,0.000681609858140031
0.0008421997985743,67.3008651605625,0.0026739843604734023,13.567854416369398,67.3575459356446,0.000841845347322556
0.0010086101756986,74.6103781980389,0.003202337307843055,15.041452244724642,74.68563098470216,0.0010081018702146143
0.0011597203636152,81.6516544133212,0.0036821121544782596,16.460973529725553,81.7463474996672,0.0011590484074248957
0.0013034099554593,88.2680648596325,0.004138326608583277,17.794841875701913,88.38311433411967,0.001302561254093687
0.0014405015782009,94.3946778888214,0.004573592510787857,19.029967062386394,94.53065357129401,0.0014394650510956807
0.0015990601940231,100.255711614256,0.005077016116023342,20.21155146143401,100.4160265319218,0.001597783058567328
0.001745956721365,106.158746032068,0.005543412590333875,21.401603200064912,106.34409460823436,0.0017444343107129532
0.0018786970898491,111.977763150444,0.0059648632602708924,22.57471705112951,112.18813544820254,0.001876934545650476
0.0020104342495319,117.68161917868,0.006383128742263783,23.724614426421887,117.91821033641719,0.0020084160311403293
0.0021633979945245,123.261719227501,0.006868788632615287,24.849562596264207,123.52838338367943,0.0021610612187270453
0.0023102511252924,128.726630889299,0.007335047322803369,25.951288787282678,129.0240217331661,0.002307586598190141
0.0024597064937849,134.065183719878,0.007809568117767057,27.02754103792741,134.39494472286424,0.0024566863671699165
0.0025979396432231,139.290912921709,0.008248458367233341,28.081048045016537,139.65278230632907,0.002594570831413352
0.0027424554734153,144.639194314784,0.008707296128093577,29.159261573860455,145.03586086490293,0.002738701803685329
0.0028857658157419,149.881029508349,0.009162306464980532,30.21601554888316,150.31355105973242,0.002881609986816611
0.0030268223713145,154.959105380802,0.009610161028923538,31.23975564476968,155.4281390676075,0.003022250767113632
0.0031707181875935,159.886666167039,0.010067030245609362,32.233151899275065,160.39362172740854,0.003165702061033184
0.00333724424992,164.684241848458,0.010595750493496,33.200343156649126,165.2338333876192,0.0033316880085860812
0.0034914500583642,169.409458651966,0.011085353935306333,34.15294686423635,170.00094331626386,0.003485369096747846
0.0036471352937046,173.998745751173,0.011579654557512104,35.078147143436475,174.63334271786243,0.003640500622581465
0.0038158504558036,178.458319242432,0.01211532519717643,35.97719715927429,179.13928950125518,0.003808588566114117
0.0039901077297222,182.863649046761,0.012668592041867984,36.86531164782701,183.5932947063077,0.003982168362155283
0.0042188970609811,187.001609451845,0.01339499816861499,37.699524465491955,187.79054999236013,0.004210022466686208
0.0044989963579997,190.667238655774,0.014284313436649047,38.43851531300404,191.52504986807622,0.004488906126508978
0.004813749444173,193.761311993011,0.015283654485249272,39.062280497791015,194.69403040091956,0.004802200400290107
0.0051936009590826,196.030951313515,0.016489683045087255,39.519839784804624,197.04905785026673,0.005180160728997699
0.0056278269651575,197.457838499557,0.01786835061437506,39.807500241510695,198.56909704754653,0.005612049912984442
0.0060935855981458,198.194634714512,0.01934713427411291,39.956038358445625,199.40235068623815,0.0060750947843087166
0.0066010162995974,198.612853510277,0.020958226751221744,40.040351267671845,199.92390019360786,0.006579324995612593
0.0071272458491997,198.882508327578,0.022629005571209046,40.094713678839724,200.29999285953417,0.007101967073466182
0.0076522641313152,198.973425005302,0.024295938616925757,40.11304248106888,200.49602220855502,0.007623134071044131
0.0081820281604629,198.993931143827,0.02597793940946971,40.11717651859553,200.62210509220705,0.00814873683846349
0.0087058023396329,199.164289475495,0.027640922428334457,40.15152075825979,200.89817441278208,0.008668125356777568
0.0092325006484733,199.323283544894,0.029313189558902726,40.183573962650634,201.16353588947806,0.009190141634501122
0.0097838049989197,199.429498762931,0.03106358087157005,40.20498695060689,201.3806780898598,0.009736253483727877
0.0103324999146536,199.517908412132,0.032805687229025174,40.22281033588581,201.57942718377222,0.010279484512449123
0.0108861867282403,199.642999869328,0.03456364286216295,40.24802877365653,201.8163508448916,0.010827358753960485
0.0114411325923787,199.736894049669,0.03632559598080237,40.26695784041327,202.02211033808115,0.011376177802950012
0.0120083841098937,199.878299642796,0.0381266195489125,40.295465207987675,202.27851504013913,0.011936855524526755
0.0125662499305983,199.982624016089,0.0398978435296496,40.31649700164354,202.49565565125204,0.012487949888195776
0.0131120010510853,200.007346612183,0.04163060333719583,40.321481077016095,202.62984315118672,0.013026782877518685
0.013669821201297,200.147788507289,0.04340168231411797,40.34979416306946,202.88377299001863,0.013577232026185751
0.0142265218452986,200.302805640888,0.04516920685882306,40.38104561720302,203.1524178810127,0.01412627454494687
0.0147754278848406,200.380558283796,0.04691198353436891,40.39672055001328,203.34126677224234,0.014667334698196994
0.0153120290060649,200.423509382814,0.048615692094256056,40.4053794915753,203.49239997198094,0.015195982990564634
0.0158497435867905,200.566950466475,0.05032293588805984,40.43429721404136,203.74588520335314,0.01572544804897887
0.0164082200374451,200.648220049709,0.05209609861888819,40.45068116202134,203.94050019440635,0.01627505983518831
0.0169678406572506,200.789607440057,0.05387289408677065,40.4791848599155,204.19657350473182,0.016825494793829214
0.0175252762812855,200.919776248671,0.055642752193081464,40.50542689173208,204.44095083780303,0.01737347958015557
0.0180724623945899,201.015737165952,0.05738006810282293,40.52477261265592,204.6485865166044,0.017911096729248954
0.0186070596816496,201.122320972067,0.05907741448923748,40.546259907968704,204.86461600170614,0.01843606621368946
0.0191511743900462,201.180372887525,0.06080497868839668,40.55796317412504,205.0332132925485,0.018970098869997867
0.019711230588947,201.258460146789,0.06258315711990671,40.57370556559266,205.22551206271876,0.01951947994801434
0.0202720480139704,201.355349201816,0.064363752444356,40.59323839908611,205.43723450870502,0.020069305473580136
0.0208356100546264,201.406728406592,0.06615306192343882,40.60359644676895,205.6031604620498,0.020621517457841777
0.0213816025676685,201.482686071758,0.06788658815234748,40.61890951206641,205.79070878961065,0.02115622309314476
0.0219373112693959,201.494943654766,0.06965096328033198,40.62138064080083,205.91520095292998,0.021700150633447036
0.0224733150259953,201.51878996699,0.07135277520753508,40.62618805734518,206.04758521757554,0.022224510820179157
0.0230090220476154,201.504238294466,0.07305364500117889,40.623254440164345,206.14065375607132,0.022748306136480566
0.0235332762286029,201.592342227321,0.07471815202581421,40.641016193027916,206.33647050252762,0.023260637782786125
0.0240879909014612,201.730128775496,0.0764793711121393,40.66879396114,206.58940228199077,0.023802451540372405
0.0246332113331199,201.834972095619,0.07821044598265567,40.689930374476795,206.80681561766474,0.02433470594759514
0.025173901970555,201.893709595687,0.07992713875651213,40.7017718544905,206.97616204952052,0.024862258658741553
0.0257230775485963,201.971081495898,0.08167077121679325,40.71737002957304,207.16639928779088,0.025397805394293208
0.026284818151945,202.010020113415,0.08345429763242537,40.725220054864465,207.31981675696687,0.025945308762635937
0.0268436142491966,202.080884089839,0.0852284752411992,40.739506232511545,207.50546538948325,0.026489645007978072
0.0273783218619085,202.104769605809,0.08692617191155948,40.7443215525311,207.6380590379037,0.02701023883028002
0.0279433924319833,202.132015538601,0.08872027097154697,40.74981433258196,207.78026977186389,0.027560099789157924
0.0285124088747177,202.211009103935,0.0905268981772287,40.7657394353533,207.97653207447567,0.02811349505969509
0.0290655360340315,202.270413942111,0.09228307690805,40.77771545072957,208.1495119471639,0.028651143875387954
0.0296149703789281,202.258457164051,0.09402753095309671,40.775304964272685,208.2483353818521,0.029184917189149093
0.0301598776822367,202.225117730412,0.09575761164110151,40.768583734451056,208.32420254543715,0.02971401124671883
0.03072266068463,202.25853076216,0.09754444767370024,40.775319801651456,208.47245097333766,0.030260168541863433
0.0312786483331942,202.302816464526,0.09930970845789158,40.78424779924844,208.63057511753462,0.030799438482776272
0.0318414984073306,202.38586544602,0.10109675744327466,40.80099047391763,208.83013465828566,0.03134506844910619
0.0323966611501363,202.411927236235,0.10285939915168274,40.806244530824976,208.96939785565334,0.031882954790970766
0.0329482326761769,202.340686437489,0.10461063874686165,40.791882385797784,209.00745445408876,0.03241707530595336
0.0335019408086592,202.295305376642,0.10636866206749296,40.78273356393103,209.0725907232399,0.03295297803696397
0.0340551339005868,202.366272987949,0.10812505013436309,40.79704063437052,209.2578835115163,0.03348809565175193
0.03461793711851,202.410920020598,0.10991195035126924,40.80604147615256,209.41796852197083,0.03403221568666067
0.0351942284445815,202.49388154422,0.11174167531154625,40.822766519314754,209.62049746991727,0.034589069444263626
0.0357519714293096,202.537949862544,0.11351250928805798,40.831650692288875,209.7790808593806,0.0351277053569173
0.0363100912310893,202.504669103359,0.11528453965870854,40.824941291237174,209.85763211322347,0.03566641491136052
0.0368838806854647,202.474041053232,0.11710632117635042,40.81876667633158,209.94206942534333,0.03621994678227927
0.0374374200857859,202.41726000953,0.11886380877237022,40.80731961792125,209.9952400051205,0.03675365331390925
0.0379960923699528,202.429951092691,0.12063759327460014,40.80987814028651,210.1214982128539,0.037292020160457406
0.0385761557810514,202.436725266749,0.12247929460483818,40.8112438137766,210.24595591644498,0.037850694125885195
0.0391516751825206,202.445545220502,0.12430656870450289,40.8130219164532,210.37162744912337,0.03840468335162643
0.0397280008117927,202.474649760609,0.12613640257744183,40.81888939173878,210.51856281066588,0.03895914126536898
0.0403087188258711,202.468188954186,0.12798018227214075,40.8175868931639,210.6294222539236,0.039517514128390004
0.0408696778292937,202.397931207578,0.1297612271080075,40.80342293144773,210.66986944934726,0.04005659239088681
0.0414429446926996,202.385882351724,0.13158134939932123,40.80099388210756,210.77334928060972,0.04060719835820273
0.0420147123044804,202.392904004891,0.13339671156672528,40.802409447386026,210.89638363912482,0.04115606252562604
0.0426022520787817,202.361310537024,0.13526215035013187,40.79604020426404,210.9823580995149,0.041719753409752
0.0431692213010125,202.270448511362,0.13706227763071469,40.77772241989058,211.002306265804,0.04226340763403429
0.0437232141256902,202.262649341531,0.13882120484906638,40.77615010725265,211.10622246832014,0.042794333740513724
0.0442896465622675,202.254366814292,0.1406196278351993,40.77448034976127,211.21214123617222,0.04333689021718753
0.0448553105357747,202.203514499113,0.14241561095108465,40.76422852302118,211.27341593339574,0.04387841701302694
0.0454268045151426,202.197412734875,0.14423010433557776,40.7629984073508,211.38259507664978,0.04442522740717685
0.0460054909341282,202.199157418145,0.14606743371585704,40.76335013549804,211.50142892163382,0.044978615087966266
0.0465943720412675,202.213537381179,0.1479371312310243,40.766249136045694,211.63555017369845,0.04554143756836836
0.0471682965522525,202.203976170582,0.14975934155340168,40.76432159598933,211.7415932826406,0.04608966066353387
0.0477577432647816,202.191762527832,0.15163083486568157,40.761859325610935,211.84798481288988,0.04665239817013892
0.0483532788684745,202.181261345496,0.15352166040740653,40.759742287251996,211.95738825731468,0.047220627250973445
0.048942864434704,202.142422894278,0.15539359458018517,40.75191245548645,212.03585209449528,0.04778286123365947
0.049532293310191,202.037097936466,0.1572650312598564,40.73067894399155,212.04445873099482,0.048344629991142855
0.0501206878152284,201.979526944576,0.15913318381335018,40.719072632026524,212.10287975963263,0.048905098340655186
0.0507193615632744,201.934995963758,0.1610339729633962,40.710095186293614,212.1770100363222,0.049475035842016644
0.0513118551088652,201.89960075274,0.162915139970647,40.70295951175239,212.25944381310234,0.05003877015441168
0.051896297125464,201.805886661873,0.16477074337334818,40.6840667510336,212.27886491774527,0.05059453257956305
0.0524663782477568,201.715130748653,0.16658075093662783,40.66577035892845,212.29839309680753,0.05113634140644473
0.0530385134528789,201.659718571497,0.16839728021289052,40.6545992640138,212.3554502678551,0.051679807461982426
0.0536365216169977,201.622697352339,0.1702959561339677,40.647135786231544,212.4370375173551,0.05224753449175774
0.0542340424702987,201.609049522898,0.17219308484319837,40.64438438381624,212.5431232771194,0.052814477148945646
0.0548223305937992,201.618275796513,0.17406089963531246,40.64624440057702,212.6714595659812,0.05337234572587976
0.0554265425951284,201.632356965794,0.17597927273953265,40.64908316430407,212.8081413877147,0.053944990995844884
0.0560504868558867,201.587870639354,0.17796029576744027,40.64011472089377,212.8869689329313,0.05453599366385086
0.0566509186592212,201.510573634329,0.1798666667430273,40.62453164468073,212.9263327502604,0.055104395632943934
0.0572592602681336,201.411502082008,0.18179815135132416,40.604558819732816,212.94417570071747,0.055679956157483244
0.057876567127869,201.403807406919,0.18375810063098405,40.60300757323487,213.0603683861139,0.05626366039932587
0.058480401246692,201.315064423863,0.1856752739582471,40.58511698785078,213.08805016837414,0.05683429583014554
0.0590959388969039,201.185807415672,0.18762960599766987,40.55905877499948,213.07507159763284,0.05741565637510405
0.0596971859276343,201.086149002226,0.1895385653202389,40.53896763884876,213.09042622668386,0.05798319365830963
0.0602997669734603,201.001511744375,0.19145176014073645,40.521904767666,213.12185606387408,0.05855166717543344
0.0609010428387044,200.913393208489,0.19336081101288646,40.50414007083138,213.14922837514865,0.05911858745810239
0.0614997053042334,200.940047106428,0.19526156434094102,40.509513496655885,213.29780078729212,0.05968272453912241
0.0621014822381388,200.967546143848,0.19717220610609068,40.51505730259976,213.4479286411425,0.06024947591743525
0.0627149612546336,200.942203006384,0.1991200019834617,40.50994812608702,213.5442854823501,0.060826917828166086
0.0633394720435735,200.85498977097,0.20110282373834584,40.49236593782756,213.57703878038063,0.06141440119370999
0.0639563785453103,200.765430679606,0.2030615018813602,40.47431082500857,213.60566056296315,0.061994392471236705
0.0645789440477606,200.650591643136,0.2050381473516399,40.45115927525622,213.60839497400815,0.06257936328529387
0.0652033715048954,200.531000209118,0.2070207045280429,40.42704964215819,213.60629751400137,0.06316574009053515
0.0658306341255796,200.450891027606,0.20901226334871523,40.410899631165364,213.64670029499075,0.06375443331377068
0.0664445183775313,200.481046242669,0.21096134584866189,40.41697892252207,213.80191280408673,0.06433023542654398
0.0670696066236315,200.437411730549,0.21294600103003,40.408182204878685,213.8806700879758,0.06491620601531231
0.0677018051735145,200.313801023601,0.21495323142590853,40.38326228635796,213.875406954067,0.06550849291298273
0.0683307860542397,200.17036065406,0.21695024572221103,40.3543447078585,213.8481587423126,0.06609741735307552
0.0689541026235731,200.042145838825,0.2189292758298446,40.328496601107126,213.83587249203512,0.06668069625080901
0.0695890274009451,199.999407941143,0.22094516199800066,40.31988064093443,213.91717222053202,0.06727448815251395
0.0702151184645868,199.944663116669,0.2229330011250631,40.30884408432047,213.9838013237678,0.06785967356092426
0.0708635641180465,199.896001562174,0.2249918160747976,40.29903391493428,214.06134468581624,0.0684653922377395
0.0714897464651442,199.850583192187,0.2269799450268328,40.2898775715449,214.13785071550768,0.0690499665577982
0.0721184619910212,199.734818918173,0.2289761168214923,40.26653949390368,214.13938686460676,0.06963656213195657
0.0727677388463701,199.63625485761,0.23103757083722504,40.24666897929418,214.16333371535595,0.070241980615163
0.0734132646340546,199.632943875399,0.23308711521312336,40.24600148528044,214.28865001379904,0.07084353827139435
0.0740791676588979,199.593538820753,0.23520135731700081,40.23805742626381,214.3792620466883,0.07146370627401209
0.0747518144530358,199.529048207453,0.23733701088838866,40.225056118622526,214.44420659704735,0.07208976464873544
0.075406020492131,199.428750729232,0.23941411506251592,40.204836147013175,214.46687919344055,0.07269828375244991
0.0760451123139518,199.26831525907,0.24144323159679693,40.17249235622852,214.42169667355793,0.07329238680305934
0.0766813397953732,199.048605999089,0.2434632538503099,40.128198969416346,214.31191979150051,0.0738834767665074
0.0773259432566322,198.902638795118,0.24550986983980722,40.098771981095794,214.28297295618373,0.07448199236631378
0.077976822271433,198.893769698231,0.24757641071179975,40.096983971163375,214.4028738288853,0.07508597157981191
0.0786316447792922,198.888166491961,0.2496554721742527,40.095854364779335,214.5270701503616,0.07569324224390095
0.0792998678002457,198.824456732745,0.2517770802657801,40.083010477321395,214.59120986710735,0.0763125603625867
0.0799673333285297,198.740462707799,0.2538962833180818,40.06607728189228,214.6332075350198,0.07693079376065311
0.0806389128058153,198.689512383256,0.25602854815846354,40.05580569646441,214.71161864775934,0.0775524521494644
0.0813012096320334,198.669022844384,0.258131340581706,40.05167500542782,214.82105471804647,0.07816513965182616
0.0819746984466506,198.568503784844,0.26026966756811565,40.031410363024555,214.84609700360917,0.07878779609048144
0.0826446668961731,198.451797804798,0.2623968173953496,40.00788243744727,214.85278052932222,0.07940681343980635
0.0833404641459841,198.33813756229,0.2646059736634995,39.984968532557666,214.8677300045813,0.08004928994047393
0.0840306101758787,198.25224578458,0.2667971873084149,39.96765275017133,214.91150296659654,0.08068614078839471
0.0847015634856329,198.148066202816,0.26892746406688445,39.94665014648771,214.93151721184924,0.0813048924621229
0.0853664881299041,197.96783300144,0.27103859981244555,39.9103151330903,214.86765166746025,0.081917707036841
0.0860273919374394,197.834644323929,0.27313696940137006,39.88346429570409,214.85384280998758,0.08252644397214415
0.0867185657099887,197.751091304687,0.2753314461292141,39.866620007024906,214.89978231021448,0.0831626654258588
0.0873964145328362,197.670356816146,0.27748361614175493,39.85034393413503,214.94603726130353,0.08378622843974846
0.088083433074723,197.597096849615,0.2796649000122455,39.835574724882385,215.0021275057276,0.08441783030494723
0.088777948136882,197.49880567044,0.28186998533460034,39.815759223160704,215.03234439734646,0.08505591878565451
0.0894519700137709,197.434151013511,0.2840100047937226,39.80272484432382,215.09502476966588,0.08567479000102528
0.0901481752777591,197.409910346583,0.28622045650688516,39.79783792587113,215.20605354607346,0.08631362762376064
0.0908648621437406,197.304189620401,0.28849593730637635,39.77652462747284,215.23220761064118,0.08697083313283434
0.091573414153166,197.260203280169,0.290745589936302,39.76765698128207,215.32399357108162,0.08762015462065423
0.0922698907236039,197.170339201154,0.2929569030474424,39.74954038295265,215.3632248531804,0.08825799946281478
0.0929794447013889,197.070041868672,0.2952097369269097,39.72932044072428,215.3935049289006,0.08890740270593113
0.0936864636966761,196.935356569956,0.29745452223694663,39.70216788450313,215.38553370383917,0.08955406666791074
0.0943765705679105,196.731734967763,0.2996456115531158,39.66111776950102,215.29860143589556,0.09018485918468033
0.0950802651620273,196.573530423908,0.3018798418894367,39.62922373345985,215.26379382044902,0.0908276620998723
0.0957957600123939,196.500675334424,0.30415153803935063,39.61453614741988,215.3246068710338,0.09148082080678412
0.0965279244248725,196.485471320317,0.30647616004897016,39.611471018175905,215.45180604651,0.09214875542327927
0.097249365271406,196.446346375704,0.308766734736714,39.603583429341924,215.55062887062797,0.09280647111386396
0.0979736490022102,196.345102411218,0.31106633558201735,39.58317264610155,215.5817485581577,0.09346634371211601
0.0987181548541361,196.194460707105,0.3134301416618821,39.55280327855237,215.56241586071272,0.09414418652932444
0.0994599562530796,196.105310981545,0.31578536110352773,39.53483069387947,215.60993663276602,0.09481911038863701
0.100173760101802,196.006400441485,0.31805168832322134,39.51489032900337,215.64109857772806,0.09546813105827967
0.10088422524128,195.827550855425,0.320307415141064,39.47883425245368,215.5834616043719,0.09611369802551388
0.10160401576254,195.586372356426,0.32259275004606447,39.430212667055486,215.45873321626632,0.0967673138164951
0.102332616593461,195.429358877743,0.3249060576842387,39.398558749752986,215.42815653088496,0.09742849512884998
0.103074543451722,195.492700471524,0.3272616754592173,39.41132841505924,215.64302132077054,0.09810132044627075
0.103805226681198,195.522415701055,0.3295815947128036,39.417319005332686,215.81866438415844,0.09876350718255303
0.104552175674437,195.366768480193,0.3319531577663375,39.38594052560691,215.7927891792812,0.09943998194241484
0.105309527282537,195.170966567859,0.33435774912205496,39.346466860080376,215.7243287963961,0.1001254109325981
0.106068388709977,195.094208854804,0.3367671341541769,39.33099250512849,215.78753723468077,0.1008117354651348
0.106811173466698,195.048166635176,0.3391254757567661,39.32171039365148,215.88149019600718,0.10148306416942902
0.107559796785322,195.008463063682,0.34150235479339736,39.31370615363829,215.9835337222296,0.10215921406229006
0.108339539989867,194.907618190411,0.34397803946782773,39.293375827186864,216.02381988568075,0.10286298541488532
0.109119920359393,194.676183745946,0.34645574714107275,39.24671864318271,215.91923341217415,0.10356683629982558
0.109881025286169,194.459325837049,0.34887225528358656,39.20300008874908,215.82671593648115,0.10425282515270687
0.110642179863141,194.378732992078,0.35128892106547266,39.18675257120292,215.88521972935695,0.10493838845149925
0.111410740397871,194.320097261435,0.3537291007632404,39.1749316079053,215.96944317151778,0.10563014566247327
0.112199944281125,194.202269442162,0.3562348230925718,39.15117751953986,215.9917532528406,0.10633998567343374
0.11299037408307,194.134465237925,0.35874443771374726,39.137508191965686,216.0697910875749,0.1070504236334296
0.113770558329274,194.045145231115,0.36122152269544494,39.119501278592786,216.121769745144,0.1077511582895593
0.114561608929777,193.852509043098,0.363733108352042,39.08066582308856,216.06056437414944,0.10846115175045883
0.115341215590365,193.630222829103,0.3662083594994089,39.03585292234716,215.96376810524498,0.10916038104760967
0.116118237539844,193.506860738027,0.3686754041890047,39.01098312478624,215.97653635879473,0.10985680596341452
0.116907847877748,193.510057402699,0.37118241701184984,39.01162757238412,216.132901756348,0.11056401702196011
0.11772006190948,193.469484673963,0.373761196562599,39.003448110270945,216.24472438737712,0.11129095152764815
0.118548905813087,193.326232496974,0.3763927759565512,38.97456847138996,216.24484582445675,0.11203222545625288
0.11936579219166,193.205153827332,0.3789863902085205,38.95015901159013,216.267240069443,0.11276226795124343
0.120164087194765,193.063933541129,0.3815209768433788,38.92168900189161,216.2632848853295,0.11347518099988238
0.120962946605952,192.880707942626,0.3840573554738976,38.8847507212334,216.21212671880812,0.11418808966857724
0.121777456329283,192.755437693033,0.3866434238454735,38.859496238915455,216.22870458892817,0.11491444190985795
0.122594550806986,192.68333263387,0.3892376988121805,38.8449598589882,216.3052592461124,0.11564256943168133
0.123410876112397,192.517006560463,0.39182953165686046,38.81142852258934,216.2756990066258,0.11636948249393189
0.124202782328183,192.242004964366,0.394343833891981,38.75598820081619,216.11899686128865,0.11707414652333978
0.125009213248074,192.069260173911,0.39690425206263497,38.721162851060456,216.07968727739126,0.11779122517669281
0.125820796053975,192.01736508282,0.3994810274713706,38.71070080069651,216.17714281372716,0.11851236612267142
0.126639546239694,191.961714258328,0.40208055931102843,38.69948159447892,216.27165864739646,0.11923934915221038
0.127489535059435,191.950826124821,0.4047792738137061,38.69728654676391,216.42254770174887,0.11999351080788416
0.128349023879395,191.881545236451,0.40750815081707914,38.68331951966852,216.50935426801945,0.12075552354868402
0.129206991963058,191.702836113476,0.4102321994827091,38.64729176047676,216.47218291848532,0.12151560933964423
0.130037486697257,191.506746279507,0.41286902026379096,38.60776004994862,216.40980225126336,0.1222508062423709
0.130869122328252,191.341455928252,0.41550946339220013,38.57443751513561,216.38214433059227,0.12298647189541677
0.13171816721881,191.302592337085,0.4182051809197217,38.566602615156334,216.500619183933,0.12373697989511538
0.132576541431142,191.192494155646,0.42093051904387585,38.54440682177823,216.54013377839536,0.12449516234386813
0.133451608388387,191.020637861976,0.4237088566331287,38.50976059297437,216.51264922003233,0.12526749785153868
0.134329398685006,190.825112911716,0.42649584082489406,38.470342763001945,216.4585355831452,0.12604163815672598
0.135196388501755,190.676479546993,0.4292485334930721,38.44037827667379,216.45525095397522,0.12680566548245054
0.136043822371439,190.523777168677,0.4319391360293188,38.409593477205284,216.44336006734812,0.12755189558612
0.136886098154198,190.292183839738,0.43461336163957864,38.36290426209118,216.34053839480103,0.12829303222540372
0.137758756833735,190.083868951667,0.43738405294710864,38.32090798065607,216.26958643259525,0.12906032450880123
0.138622361740543,189.989008493727,0.44012599852622397,38.30178411233536,216.32573355587155,0.1298190770227746
0.139492904500266,190.058367877031,0.4428899717883445,38.31576696400945,216.5701616367781,0.13058334283056508
0.140378922596999,189.970440127849,0.4457030792454718,38.298040729774364,216.63828583827413,0.13136059542065148
0.141305469396272,189.810068826495,0.4486448653331636,38.26570987542139,216.6312696981616,0.1321727558171148
0.142228893764303,189.638800574434,0.451576737701662,38.23118219580589,216.610917394925,0.13298152351797618
0.143125888935264,189.469392940884,0.4544246973694632,38.19702961688221,216.58736823157287,0.1337665177987883
0.144013354073206,189.252454657023,0.45724239918242904,38.15329485885584,216.50733541876824,0.13454256603038994
0.144918022731317,189.046317063369,0.4601147221719314,38.11173751997519,216.44253553683006,0.135333038575251
0.145810431127831,188.833647834221,0.46294811883086334,38.068863403378955,216.36756343636978,0.13611218674548214
0.146700845853913,188.603922498177,0.4657751855861737,38.02255077563249,216.27227746002544,0.1368889897037027
0.147606035033047,188.447272113218,0.4686491612299242,37.99097005802474,216.2632267626438,0.13767806394101767
0.148499940095142,188.302152540864,0.4714873098020758,37.961713952238185,216.26501091296856,0.1384566909877998
0.149411808132725,188.14946781152,0.4743824908214019,37.93093271080243,216.2612199964491,0.1392503403402174
0.150335938234656,188.046034412572,0.4773166038950327,37.910080537574515,216.31611142729244,0.1400540199204081
0.151263997092957,187.918662302981,0.4802631907701384,37.88440232028097,216.3439902912915,0.14086046668324767
0.152182971111812,187.74082974078,0.4831809332800031,37.84855127574125,216.31178700972873,0.14165837875180967
0.153102377917457,187.562306376519,0.486100049887926,37.81256096550623,216.27854149044666,0.14245602998815618
0.154042937653196,187.372559402536,0.48908632704889726,37.77430797555126,216.23597888850063,0.14327137506546653
0.154977857455145,187.201565358086,0.49205469742008534,37.73983557619014,216.21366286953145,0.14408117275548377
0.155901768122117,187.005246685004,0.49498811378772145,37.70025773169681,216.15969529130882,0.14488079096663958
0.156826033928959,186.725737532596,0.4979226577244448,37.64390868657136,216.00919438229278,0.14568007729443688
0.157767363210621,186.48074634546,0.5009113781937216,37.59451846324474,215.90132198593187,0.1464934636410183
0.1586967886314,186.266150886179,0.503862303904695,37.55125601865369,215.82599086254737,0.14729591548981003
0.159633933488812,186.112772614885,0.506837738826978,37.52033495916081,215.82268657990792,0.14810438073552734
0.160573185275393,185.907546224126,0.5098198632493727,37.4789613187838,215.7593130880663,0.14891400831600626
0.1615119124775,185.617342202475,0.5128003221160624,37.42045618801896,215.5967541305873,0.14972252929067073
0.16244061763109,185.335608477974,0.5157489609787107,37.36365866915956,215.44163918816997,0.15052177556700003
0.163357595622924,185.14621996322,0.5186603661027838,37.32547794458515,215.39126129508466,0.15131030316507058
0.164265589064663,184.997310496282,0.5215432452803049,37.29545779605046,215.38600268033213,0.15209049258212898
0.165195639347053,184.785760497636,0.5244961549268933,37.25280931632342,215.3115623452744,0.15288900368887315
0.166172193198675,184.570010262152,0.5275967134057931,37.20931406884984,215.24041366611576,0.1537267555829362
0.167152025738228,184.312872647014,0.5307076817188738,37.15747512563802,215.1211426795944,0.15456661537541222
0.16812915778261,184.050761723408,0.5338100759597867,37.10463356343905,214.99506128121243,0.1554034585858159
0.169084349737504,183.688941931573,0.5368428104165751,37.03169069340512,214.74786723204318,0.15622083535092643
0.170010930021916,183.312103286816,0.5397847028195832,36.95572002262211,214.4771644508811,0.1570130906651029
0.170969229250753,183.05602807861,0.5428273028711408,36.90409526064778,214.35297610891416,0.15783180694389745
0.171938403580317,182.840197599326,0.5459044313675064,36.86058383602412,214.27744928486382,0.1586591331015862
0.172897098211556,182.509062375136,0.5489482868216903,36.79382697482742,214.06434965710892,0.159476840513407
0.173812994336893,182.037983070541,0.5518562570196353,36.698857387021064,213.6785499910804,0.160257419396798
0.174728340398765,181.564678450584,0.5547624807660788,36.60343917563774,213.28917339128995,0.161036921204735
0.175671949032416,181.258322616911,0.5577584381779208,36.54167783956926,213.1003254293702,0.16183985565687056
0.176667517114934,181.128289097654,0.5609193668399154,36.51546308208705,213.12777421181252,0.16268630503740175
0.177670026516837,180.800394609559,0.5641023341909575,36.449359553287096,212.92320551409392,0.16353793267695182
0.17865199483146,180.359611332885,0.5672200835898854,36.36049764470962,212.5812156845317,0.16437140820582494
0.179595512299773,179.855365324314,0.5702157515517793,36.2588416493817,212.156581799597,0.16517159352632596
0.180543455723188,179.429076182473,0.5732254719211218,36.17290175838656,211.82382165367585,0.16597488815196684
0.181514833719504,179.013413981007,0.5763095970594252,36.08910425857101,211.50700405333023,0.16679737255501273
0.182491249957475,178.540665719038,0.5794097186149831,35.99379820895806,211.12277497434494,0.16762344174344465
0.183481141372779,178.073649481892,0.5825526238585732,35.89964773554943,210.74680593724574,0.16846021522118326
0.184467165920063,177.571611562352,0.5856832517962,35.79843689097016,210.32774349511735,0.16929302445205793
0.185471389312301,177.040982992398,0.5888716610665556,35.69146217126744,209.87702007321352,0.1701404923749067
0.186456407410393,176.372082607683,0.5919990935279977,35.556611853708894,209.25778749820063,0.17097105573023139
0.18742379557917,175.715991514896,0.5950705509638647,35.42434388940303,208.64934958857503,0.17178608272368226
0.188416812452313,175.253184477526,0.5982233795360937,35.33104199066924,208.27383086889864,0.17262201163878796
0.18944530795861,174.630773410025,0.6014888527685868,35.20556391946104,207.71375405773745,0.17348707068624591
0.190444426426754,173.911090795935,0.6046610539049438,35.060475904460496,207.03148873181797,0.17432670498728547
0.191404404903808,173.118158635641,0.6077089855695904,34.90062078094523,206.2537367673389,0.17513278345574776
0.192391947100862,172.485774980546,0.6108444320452368,34.77313223607808,205.6706490762544,0.1759613292773891
0.193389554999681,171.81196173983,0.6140118371239871,34.63729148674973,205.03860056431793,0.1767976237629349
0.194404103829724,170.949659921643,0.6172330296593737,34.46345144020323,204.18297535870607,0.17764740312920813
0.195420907802969,170.050095934289,0.6204613822744266,34.282099340352666,203.28144005374972,0.17849834747002954
0.196472844361237,169.116534968838,0.6238012808469274,34.09389344971775,202.3433416226822,0.17937793221340462
0.197517971647877,168.147599633021,0.6271195599820094,33.89855608601703,201.3597724499946,0.18025105782946546
0.198527766031722,167.196093451787,0.6303256571507173,33.706732439880255,200.38916037400128,0.18109394194286074
0.199516887160592,166.186029889105,0.6334661167348795,33.50310362564357,199.3429492621563,0.18191888169837928
0.200510512815795,165.091273425487,0.636620878190149,33.28240072257818,198.193809321444,0.18274689367189442
0.201503962980993,163.995980409788,0.6397750824646528,33.06158965061326,197.04182037531356,0.18357407455015623
0.202533857215047,162.884662914084,0.6430449966577741,32.83754804347934,195.87432197524615,0.18443087828960403
0.203612667696498,161.634953194197,0.6464702199363811,32.58560656395012,194.54587720706604,0.185327590557598
0.204690785016496,160.339438138577,0.6498932424273748,32.32443072873713,193.15944360026626,0.18622292406783633
0.205792278431301,158.930486024896,0.6533904840193806,32.040385982619036,191.63715285615336,0.18713684336324735
0.206880027189547,157.581477370963,0.6568440863268117,31.768425837986143,190.1819376940368,0.1880385396519742
0.207910528570845,156.122414490424,0.6601159282124328,31.47427876126948,188.58190820888458,0.18889203101700808
0.208961205876424,154.589482338448,0.6634518286576462,31.165239639431118,186.89268698370225,0.18976148333985343
0.210032150001834,153.021871529566,0.6668520762558229,30.84920930036051,185.1613842042252,0.19064692950511652
0.211114369138924,151.402039553532,0.6702881220160837,30.522651173992053,183.36518562022235,0.19154090200996826
0.212233675819939,149.567210418278,0.6738419207283063,30.152749620324844,181.3104092674834,0.19246467089487104
0.213320129243472,147.794083839613,0.6772914103480235,29.795287302065983,179.32153690569976,0.1933605104296808
0.214374185705114,145.893636189095,0.6806380396137369,29.41215705572155,177.16946564669038,0.1942288706028591
0.215453855527864,143.913798767658,0.6840659913009681,29.013021831559854,174.92058157581107,0.19511755068678643
0.216579090697546,141.861215400547,0.6876386129647085,28.599221024750275,172.58538843724617,0.1960428960869957
0.217720133794472,139.643701132435,0.6912614247974486,28.152170148298897,170.04694642654403,0.19698036767554425
0.218861766395933,137.300496828599,0.6948861083070872,27.67978016064556,167.35032609154536,0.19791744488596913
0.220029101230689,135.024353460961,0.6985923964074375,27.22090965772974,164.73364059723113,0.1988747119284536
0.221292306240231,132.541904681405,0.7026030723127333,26.720447983771248,161.87240844182597,0.1999095655273359
0.22261981311879,129.619592659843,0.7068179066521583,26.13130988022435,158.47548215431092,0.20099594420568995
0.223979880134452,126.568190617642,0.711136119426885,25.51614722851663,154.9169187810159,0.20210774615638186
0.224892922748389,124.339545278136,0.7140350297261351,25.06685232807222,152.30262902894165,0.20285343017489832
0.225116508639922,123.82585484168,0.7147449149317523,24.963292336082688,151.70109896299277,0.20303594856792112