File: example/data/02 processed data/test_ID_082.csv
Strain,Stress_MPa,Displacement(mm),Force(kN),True Stress (MPa),True Strain
0.0004256594004206,0.334300695536063,-2.9321266612355683e-05,0.0673950202200703,0.3342976082542291,-9.235087245549598e-06
0.0004232776796831,1.03369356667246,-3.688322995391739e-05,0.2083926230411679,1.0336815584968628,-1.1616832814924662e-05
0.0004162471152895,1.75360779945217,-5.9205271903807575e-05,0.3535273323695574,1.7535750993493104,-1.8647503597060008e-05
0.0004037718443251,2.55749977311978,-9.88142572156331e-05,0.5155919542609477,2.5574201770755565,-3.112308501600531e-05
0.0003780349773764,4.02057032385998,-0.0001805288097779,0.8105469772901719,4.02034171637173,-5.686108420736148e-05
0.0003601924659441,5.93256602120983,-0.0002371787835754,1.1960053098759018,5.9321228467870295,-7.470476941068609e-05
0.0003504482265024,7.96927059569958,-0.0002681167438026,1.6066049520930354,7.968597620933406,-8.444978430320798e-05
0.0003427332187817,10.0247852253188,-0.0002926118933159,2.02099670142427,10.02386132881963,-9.216547334798632e-05
0.0003302095866774,12.1151727549914,-0.0003323744252472,2.4424188274062666,12.113904479847712,-0.0001046903381878
0.0003189096795492,14.2878747955965,-0.0003682516303793,2.8804355587922545,14.286217619789213,-0.0001159914922268
0.0003294007889497,16.5419528524746,-0.0003349423580327,3.33485769505888,16.5402077813896,-0.0001054992209203
0.0003512392321851,18.7867545200311,-0.0002656053007602,3.78740971123827,18.7851829100832,-8.365871213040464e-05
0.000372893863399,20.9939644170988,-0.0001968518466559,4.232383226487118,20.992662779094346,-6.200250373948716e-05
0.0003954310258137,23.3271068615505,-0.0001252963559895,4.702744743288581,23.326186294153484,-3.946419791045495e-05
0.0004206924613086,25.7334372257117,-4.509129829301776e-05,5.187860944703479,25.733071759855303,-1.4202084563504749e-05
0.0004561839022386,28.2360272735048,6.759402665952237e-05,5.692383098338568,28.236628403199376,2.128923059830072e-05
0.0005032573396031,30.8603467692688,0.000217052190292,6.221445908684591,30.86245647190169,6.83605579439352e-05
0.0005420502284796,33.464130249525,0.0003402196124747,6.74636865830424,33.467716124619585,0.0001071500426857
0.0005809002404966,36.1500642651325,0.0004635684006286,7.287852955850711,36.15534238402196,0.0001459951376648
0.0006260857482818,38.8273862424899,0.0006070323878466,7.827601066485965,38.83480970106773,0.0001911730285308
0.0006672388149662,41.5347508986047,0.0007376933745696,8.373405781158707,41.544401264132986,0.0002323173821703
0.0007094640101402,44.3318370178612,0.0008717583692471,8.937298342800817,44.34400919107204,0.0002745318777925
0.0007563749164096,47.1294869541843,0.0010207004966524,9.501304569963557,47.14463816386655,0.0003214288076122
0.0008017718061517,49.8993559533365,0.0011648356215836,10.05971016019264,49.91766289737068,0.0003668100780855
0.0008464444628186,52.747025006427,0.001306671306501,10.633800241295685,52.76873304550707,0.0004114653543151
0.0008992051248561,55.6051734226934,0.00147418640847,11.21000296201499,55.63099149856752,0.0004642029209837
0.0009376429926842,58.4541714514472,0.0015962266388243,11.784360964611755,58.48355920124916,0.0005026222119517
0.0009830203511072,61.3205845348409,0.0017402997518173,12.362229842223924,61.35419593580067,0.0005479757399505
0.0010338178488681,64.1936567196207,0.0019015818072081,12.941441194675535,64.23210380300848,0.0005987441208041
0.0010825758931829,67.0701704313755,0.0020563885979076,13.521346358965303,67.11361053648884,0.0006474717930524
0.0011319956229715,69.9833217371137,0.0022132962399864,14.108637662202122,70.03210719313338,0.000696858315782
0.0011779097187365,72.8983479199844,0.0023590734940403,14.696306940668856,72.95251250591744,0.0007427393745214
0.0012170945914788,75.8142135830688,0.0024834854649971,15.284145458346671,75.8735154720369,0.0007818943873539
0.0012717270588504,78.683051031223,0.0026569435489019,15.862503087894556,78.74889557448138,0.0008364826646347
0.0013264001225799,81.5293292930016,0.0028305305262431,16.436312785469124,81.60201315295372,0.0008911085223968
0.001373922887215,84.3531930607855,0.0029814153039596,17.005603721054356,84.4324031082593,0.0009385878307938
0.0014165643821492,87.1721001799882,0.0031168020503756,17.57389539628562,87.25767441009104,0.0009811884142986
0.0014566881470321,89.954594554311,0.0032441950038788,18.1348462621491,90.04650959249338,0.0010212720261575
0.0015008093641627,92.6905455593038,0.0033842798682685,18.68641398475565,92.78934579467864,0.0010653472351982
0.001547338277073,95.3940994356752,0.0035320091667587,19.23145044623212,95.5002200132064,0.0011118255249224
0.0015994112442412,98.1179436604965,0.0036973408375177,19.78057744195609,98.2322036541939,0.0011638392754712
0.0016482249493896,100.820663952542,0.0038523243513639,20.32544585283247,100.94299273958612,0.0012125950137789
0.0016964141241156,103.54971546196,0.004005324981119,20.875622637131137,103.68034546577972,0.0012607246317172
0.0017545502107149,106.267016938006,0.0041899070560717,21.42343061470201,106.4072528196111,0.0013187857853208
0.0018056602728085,108.969931049766,0.0043521815032189,21.968338099632827,109.11930330750516,0.0013698271859823
0.0018623627141631,111.657912199682,0.0045322117545198,22.51023509945589,111.81730032634547,0.0014264504048413
0.0019181298029438,114.374573759161,0.0047092722613985,23.057914069846856,114.54421817100771,0.0014821364508483
0.0019660201457817,117.128524134708,0.0048613240999088,23.61311046555713,117.3078626283026,0.0015299547229266
0.0020134974816412,119.852985680258,0.0050120646412627,24.16236191314001,120.04218596740064,0.0015773583525804
0.0020609962915202,122.52681306765,0.0051628733626286,24.70140551443824,122.72605414462473,0.0016247811743939
0.0021016945710062,125.220508958796,0.0052920903999966,25.244454606093274,125.4292265189042,0.0016654125563067
0.0021556530782823,127.922226706782,0.0054634086605982,25.789120904087248,128.14234998277345,0.001719279824328
0.0022009581835255,130.64348862391,0.0056072523697454,26.337727306580256,130.87421335184015,0.001764506081616
0.002249867665472,133.34570115541,0.0057625399749255,26.88249335293066,133.5877200320691,0.0018133281467626
0.0022944928342854,135.976411489664,0.0059042248859081,27.412844556316266,136.22927300544785,0.0018578714767554
0.0023421698804964,138.709638974372,0.006055599507628,27.9638632172334,138.9741964614512,0.0019054588950752
0.0023926321410252,141.431885048899,0.0062158171848069,28.51266802585804,141.7087715816759,0.0019558238250568
0.0024438950950748,144.129613271449,0.0063785770639144,29.05653003552412,144.41916975820303,0.0020069853070113
0.0024970576075049,146.841655615556,0.00654736804088,29.60327777209609,147.14446706848426,0.002060039822642
0.0025539813427683,149.55921828855,0.0067281009003413,30.151138406971683,149.8761472684623,0.002116844800013
0.0026148544253185,152.250429822758,0.0069213729374382,30.693686652268017,152.5823296667544,0.0021775873151219
0.002668584141872,154.985645513287,0.0070919647874955,31.245106135478665,155.33183535282953,0.0022311987207068
0.0027137175473215,157.65296797372,0.0072352633497977,31.78283834350196,158.01223119928443,0.0022762305228722
0.0027735895609584,160.329229071159,0.0074253569930948,32.32237258074566,160.7041902561294,0.0023359646248748
0.0028332619729039,163.009059201745,0.0076148169010218,32.862626335071795,163.4000148360849,0.0023954960348288
0.0028779453467684,165.769809450597,0.0077566866130416,33.41919358524036,166.17479353305745,0.0024400715044507
0.0029281860641222,168.480229209905,0.0079162008906399,33.96561420871685,168.90029955337795,0.0024901885244265
0.0029691527137503,171.191226963762,0.0080462700032091,34.512151355894424,171.6250697462285,0.0025310524513448
0.0030236860397731,173.909047642631,0.0082194133133315,35.060064004754416,174.35926192341924,0.002585446445808
0.0030881069454564,176.611002305017,0.008423949688876,35.60477806469143,177.07958882404677,0.0026496989455802
0.0031392477137894,179.297578516529,0.0085863216283333,36.146391828932245,179.7824625090721,0.0027007030849088
0.0031929919807169,181.89147928834,0.0087569596758281,36.66932222452935,182.39315372912893,0.0027543009639604
0.0032475037521175,184.446699692992,0.008930034550025,37.18445465810719,184.96547619721144,0.0028086613225636
0.0032981557667023,187.007972895102,0.0090908546963317,37.70080733565256,187.5434255907382,0.0028591699968087
0.0033573058862563,189.578175100215,0.0092786563259157,38.21896010020335,190.132200528136,0.0029181494983322
0.0034118390918114,192.081164396866,0.0094517992535531,38.72356274240818,192.65297939096607,0.0029725223215778
0.003463941342844,194.54914123719,0.0096172239005816,39.221106873417504,195.13843970992824,0.0030244685782328
0.003512605496069,197.000912196529,0.009771732587071,39.71538389882025,197.6072240810624,0.003072984593686
0.0035613020584466,199.505369584443,0.0099263441726199,40.22028250822371,200.1291046908307,0.0031215305635942
0.0036168526080136,201.909705710135,0.0101027171674951,40.704996671163215,202.5521739464064,0.0031769064475098
0.0036729426204872,204.29376490508,0.0102808029570988,41.18562300486413,204.9552779577896,0.0032328169869891
0.0037251405281391,206.680871058383,0.0104465313138936,41.66686360537001,207.36090198483785,0.0032848450673437
0.0037770584258992,209.028496568929,0.0106113706392819,42.14014490829609,209.7271040811384,0.0033365913637867
0.0038291224909789,211.321501997235,0.0107766740459099,42.60241480264258,212.03877536602752,0.0033884806555723
0.0038852530782611,213.571079455494,0.0109548886605309,43.0559296182276,214.30797627330324,0.0034444198026986
0.0039358167018729,215.729900813472,0.0111154281654984,43.49114800399596,216.4851544246979,0.0034948082940425
0.0039900715231418,217.818591011252,0.0112876872230271,43.91222794786841,218.5929746732033,0.0035488723745634
0.0040408738090168,219.866026815776,0.0114489844806803,44.32499100606044,220.6588591713169,0.0035994934078798
0.004094455226218,221.784780477002,0.0116191054802941,44.7118117441636,222.5964153615016,0.0036528808806802
0.0041492800709908,223.631172721701,0.0117931743624477,45.08404442069493,224.4618251351768,0.0037075043302718
0.0042055773729963,225.411597549044,0.0119719182963152,45.44297806588727,226.2615532116893,0.0037635917233012
0.0042598165002154,227.117920822,0.0121441275252358,45.7869728377152,227.98662916648152,0.0038176256403886
0.0043198687844415,228.80561129635,0.0123347935276537,46.12721123734416,229.6945152249513,0.0038774473151751
0.0043780596669969,230.41378238166,0.0125195495797671,46.45141852814266,231.32234199501085,0.0039354113225771
0.004443309235424,231.936514667335,0.0127267169595231,46.75840135693474,232.8662124231616,0.0040004024997544
0.0044994134846757,233.428612558089,0.0129048479508973,47.05920829171074,234.37738759823105,0.00405628119651
0.0045598382158215,234.91400808562,0.0130966964722852,47.35866403006099,235.88301515994607,0.004116459513629
0.0046217607872926,236.34953929383,0.0132933006367059,47.648067121636124,237.33910322491025,0.0041781258058639
0.0046921546440349,237.794003273548,0.0135168011318627,47.93927105994728,238.80635421924816,0.0042482237048704
0.0047612831777843,239.204953324966,0.0137362842265171,48.22371859031315,240.23984693985184,0.0043170568190039
0.0048394602865522,240.583521321785,0.0139844965468552,48.50163789847186,241.6431872818337,0.0043948941307945
0.0049190640714996,241.873894297781,0.0142372385640632,48.76177709043265,242.9584978680287,0.0044741456926989
0.0050110267300951,243.159352671385,0.0145292200051039,49.020925498551215,244.27208203556177,0.0045656936254039
0.0051072214386065,244.321455106954,0.0148346382046276,49.25520534956193,245.46300483676183,0.0046614455550776
0.0052062841241707,245.430961679646,0.0151491622312939,49.47888187461664,246.6020084371476,0.0047600426790701
0.0053116154103613,246.375148515059,0.0154835890649491,49.66922994063589,247.5766513671607,0.0048648682808548
0.0054303611837768,247.16689043912,0.0158606068955433,49.8288451125266,248.4016044192298,0.004983030793158
0.0055558196732445,247.882573799512,0.0162589375996032,49.97312687798161,249.1519619253184,0.0051078578829048
0.0056884135889439,248.513308630695,0.0166799232819488,50.10028301994811,249.8188780551055,0.0052397675540238
0.0058255543521049,248.982376561407,0.017115345204985,50.19484711477965,250.32455587630653,0.0053761823058755
0.0059685641114844,249.364395628851,0.0175694011910149,50.271862158776365,250.74429582083783,0.005518415166175
0.0061205971632448,249.686281381506,0.0180521061303542,50.33675432651161,251.1059233502596,0.0056696001180878
0.0062784229908547,249.909817206341,0.0185532031330156,50.38181914879834,251.3701723570698,0.0058265213554038
0.0064366419137944,250.152494790777,0.0190555482133491,50.43074294982064,251.6538468931944,0.0059838087225313
0.0065955286400025,250.297186427291,0.0195600135690599,50.45991278374186,251.83917583290216,0.0061417350688204
0.0067623775491143,250.447738393956,0.0200897588554898,50.490264060221534,252.03244222710163,0.0063075486287216
0.0069360258183855,250.581280116423,0.0206410921104259,50.51718607147088,252.2103419381652,0.0064800901640048
0.0071123297936461,250.704733868453,0.0212008572318783,50.54207434788013,252.37879852045336,0.0066552400276341
0.0072879620497658,250.801078267483,0.0217584896450583,50.561497378724575,252.51983501219243,0.0068296920722466
0.0074613123351616,250.918141181024,0.02230887680119,50.58509726209444,252.6811968971787,0.0070018476426993
0.0076365730382144,250.978587372951,0.0228653295333826,50.59728321438693,252.78605449298425,0.0071758703403282
0.0078179486323057,251.113831715375,0.0234411970446225,50.62454847381961,252.96781874210583,0.0073559328530934
0.0079893704791663,251.173410102515,0.0239854614084049,50.636559476667024,253.07089360954848,0.007526083882297
0.0081629404167097,251.23192280793,0.0245365459601052,50.64835563807869,253.17345465694493,0.0076983375847702
0.0083417920245062,251.287824242863,0.0251043998148591,50.65962536736118,253.27473133212249,0.0078758018709874
0.0085254496894473,251.347235341784,0.0256875129010471,50.67160264490365,253.38077403485005,0.0080580021661238
0.0087097919980003,251.473481814803,0.0262727997307029,50.69705393386428,253.55439911411105,0.0082408482953419
0.0088932706635308,251.604160156801,0.0268553444937622,50.72339868761108,253.7323228015489,0.0084228045990562
0.0090771216360573,251.67592187948,0.0274390713315339,50.73786585090318,253.85096237487545,0.0086050969177684
0.0092616642638645,251.811879837069,0.0280249941748217,50.76527497515311,254.0345653380406,0.0087880416158981
0.0094452389194223,251.917775665549,0.0286078437062177,50.78662357417468,254.18764160352,0.0089699935234765
0.0096256574589408,252.044404049261,0.029180672569189,50.81215185633102,254.36088443586192,0.0091487849623771
0.0098092970353253,252.146358567903,0.0297637282242098,50.83270588728925,254.51008004479723,0.0093307355677082
0.0099933310408962,252.197426332142,0.0303480361918974,50.84300114855983,254.60803944138016,0.0095130437678709