File: example/data/02 processed data/test_ID_059.csv
Strain,Stress_MPa,Displacement(mm),Force(kN),True Stress (MPa),True Strain
0.00034448476996160044,0.512111917244544,-3.8809337649247e-05,0.1032417625165,0.5121056574888556,-1.2223488139403672e-05
0.0003457335077376004,0.453553356919533,-3.4844595210596854e-05,0.0914363567549778,0.4535483793185477,-1.0974735879109732e-05
0.0003485856150452004,0.424352430115232,-2.578915450895064e-05,0.0855494499112307,0.4243489832836142,-8.12260133749277e-06
0.00034839593821820044,0.408836806304551,-2.639137843448453e-05,0.0824215001509974,0.4088334079527799,-8.312279723068841e-06
0.00034944824404190044,0.365591709802202,-2.3050307444342057e-05,0.0737032886961239,0.365589055628561,-7.259965706064656e-06
0.00034809027973120045,0.315542279884091,-2.736184413083224e-05,0.0636133236246327,0.3155395605711212,-8.617940797589009e-06
0.00034844884139250044,0.251259910129953,-2.622341085623996e-05,0.0506539978821985,0.2512578348884238,-8.259376110545704e-06
0.00034943493693660044,0.191560463967758,-2.309255750353335e-05,0.0386185895359,0.191559070701292,-7.273272907958212e-06
0.00034744926467010045,0.179313533651433,-2.939706694990269e-05,0.0361496083841288,0.1793118734019987,-9.25896158843889e-06
0.0003426171153230004,0.224801545050381,-4.473914112685883e-05,0.0453199914821568,0.2247983773565071,-1.4091167351519084e-05
0.00033870483196550045,0.264756846874399,-5.716064078700197e-05,0.0533749803298788,0.2647520803638414,-1.8003513491262132e-05
0.00033549543873140044,0.314362180991063,-6.735046430523868e-05,0.0633754156877983,0.3143555125063859,-2.1212969656496017e-05
0.00033325815174820044,0.374657734931843,-7.445385047692566e-05,0.0755309993622595,0.3746489491961023,-2.3450306602567727e-05
0.00032394117553340043,0.454624380157598,-0.0001040352499587,0.0916522750397717,0.4546094834769595,-3.276754471116369e-05
0.0003143333511689004,0.53155638678869,-0.0001345400923161,0.1071617675765999,0.5315338621759814,-4.237573006414492e-05
0.00030832265941690046,0.598806520780573,-0.0001536240386288,0.1207193945893635,0.5987775472133038,-4.8386694594793744e-05
0.0003110668770088004,0.599643774248394,-0.0001449111477744,0.1208881848884762,0.5996164057231713,-4.5642347981741866e-05
0.00031414368012720045,0.601100036792451,-0.0001351422978733,0.1211817674173581,0.6010744512679711,-4.256540916140362e-05
0.0003148361396528004,0.602034063087777,-0.0001329437388797,0.1213700671184958,0.6020088546911534,-4.187292040011508e-05
0.00031780988050710045,0.603852621913914,-0.0001235021116671,0.121736688577845,0.6038291330717275,-3.8899059445883296e-05
0.00032543667430540044,0.606721238137012,-9.928704135785536e-05,0.1223150016084216,0.606702265048299,-3.1271998052937726e-05
0.0003340836783215004,0.609573147807302,-7.183280360650226e-05,0.122889946597952,0.609559356516527,-2.2624761010929768e-05
0.00033704586768920045,0.613488178403838,-6.242785236416875e-05,0.1236792167662137,0.6134761158055927,-1.966250901113445e-05
0.00032733286594740043,0.615533695990601,-9.326663289422246e-05,0.1240915931117051,0.6155156144928821,-2.937574891004292e-05
0.0003139868418120004,0.617582262804102,-0.0001356402595241,0.1245045841813069,0.6175558788612975,-4.272225416495689e-05
0.00029763220150510046,0.624257180617709,-0.0001875662424985,0.1258502476125301,0.6242203020118124,-5.907772694391278e-05
0.00028175122161290045,0.637030022303413,-0.0002379883536565,0.128425252496368,0.6369822724683775,-7.495977119506442e-05
0.0002613916121005004,0.701026984434937,-0.0003026301138583,0.1413270400620833,0.7009601649463961,-9.532111420708456e-05
0.00023648400300680042,0.922016017101403,-0.0003817117727306,0.1858784290476428,0.9219051684814428,-0.0001202314078936
0.00021374493070520044,1.39246967148626,-0.0004539083272882,0.28072188577163,1.3922705994927531,-0.0001429734729091
0.00020029141011580043,2.15013950905622,-0.0004966232551595,0.433468125025734,2.1498031911721145,-0.0001564290076578
0.00019492039440990042,3.2257256902537,-0.0005136762300257,0.6503062991551459,3.2252038072264035,-0.0001618008780405
0.00019494359662440043,4.61606546081538,-0.0005136025629947,0.9305987969003808,4.615318744893608,-0.0001617776720719
0.00019170557708160044,6.26586383816407,-0.0005238832750431,1.2631981497738765,6.264829954299972,-0.0001650162207404
0.00019502270587310044,8.16593749823211,-0.0005133513911301,1.6462529996435933,8.164617184728298,-0.0001616985500271
0.00020344939184030044,10.1780417867966,-0.0004865966631842,2.0518932242181944,10.176481912411967,-0.0001532705368828
0.00021948053362830043,12.2246477870196,-0.0004356977880073,2.464488993863152,12.222970227334567,-0.0001372370663415
0.00023673151432080042,14.2701679094559,-0.0003809259243086,2.8768658505463094,14.268455822243002,-0.0001199838668498
0.00025325149121260045,16.2814613604852,-0.0003284749976772,3.282342610273816,16.27977693434896,-0.0001034620441945
0.00027141058242710045,18.2793989255795,-0.0002708198830711,3.685126823396828,18.277839736704024,-8.53012390145603e-05
0.00029598191392390044,20.310679431978,-0.0001928059055688,4.094632973486765,20.309446040185684,-6.072811338506405e-05
0.00032682025691770046,22.3394268494344,-9.489416656367204e-05,4.503628452845975,22.33875917028719,-2.9888373129709133e-05
0.00036271447620380044,24.4152920418353,1.9069979669762607e-05,4.922122875633997,24.415438687228328,6.0062747716307495e-06
0.00040144233378820043,26.5526476998924,0.0001420309275001,5.353013776298308,26.55383551002796,4.473314985147684e-05
0.0004446922239653004,28.7429987421099,0.0002793493288125,5.794588546409356,28.74552766727736,8.79801702022976e-05
0.0004908329438429004,30.9824892286958,0.0004258461144239,6.246069828505074,30.98664474764169,0.000134115766527
0.0005374331735151004,33.2801978952406,0.0005738018436332,6.709287895680505,33.28621245867643,0.0001807086613269
0.0005835787039532004,35.6630464769479,0.0007203139027741,7.189670169752697,35.67113737086684,0.0002268447893339
0.0006342925286238004,38.1182955773349,0.0008813302961033,7.684648388390716,38.12887661945399,0.0002775458258231
0.0006870626671443004,40.635190172485,0.0010488754859059,8.192054338772975,40.64861418975651,0.000330299928722
0.0007354840174875004,43.2062669589873,0.0012026132732455,8.71038341893184,43.22263244879274,0.0003787041166362
0.0007788724118210005,45.8311477524837,0.0013403714252544,9.239559386900714,45.850496023612536,0.0004220751421804
0.0008240238565192004,48.5200968118715,0.0014837272621712,9.781651517273296,48.542771013573216,0.0004672065151617
0.0008782759211768004,51.2335158676807,0.0016559775674591,10.32867679892443,51.26023761665044,0.0005214317686058
0.0009386365560607005,53.9604170313632,0.0018476225832155,10.87842007352282,53.991818129034655,0.0005817591180103
0.0009894948416171005,56.729070406186,0.002009097639857,11.436580593887095,56.76496780507241,0.0006325865331651
0.0010388964437289005,59.5014399859735,0.002165947726562,11.99549030117226,59.54203116980493,0.0006819556756948
0.0010904861238878005,62.2605808486295,0.0023297449610665,12.551733099083709,62.30626628941854,0.000733508857084
0.0011472608198540004,65.0454155870764,0.0025100046207592,13.113155782354603,65.09683741185837,0.0007902403143179
0.0012050349220933004,67.817208959302,0.002693437395369,13.671949326195282,67.8747401110061,0.0008479671129435
0.0012547130355618004,70.5922302108545,0.0028511654056314,14.231393610508269,70.65562237610916,0.0008976018870351
0.0013034045095717004,73.375757344585,0.0030057608356129,14.792552680668337,73.4452219044936,0.00094624849183
0.0013589013030504003,76.1622780486406,0.0031819631549077,15.354315254605943,76.23860735967827,0.0010016912594107
0.0014161730561944004,78.9850805066328,0.0033638009711399,15.923392230137171,79.06876242490485,0.0010589040359812
0.0014715155016214005,81.8021858375346,0.0035395132353707,16.491320664846974,81.89337951295325,0.0011141863819886
0.0015247337318069004,84.616912964164,0.0037084811162096,17.05876965357546,84.71574768033395,0.0011673439372795
0.0015764556663956004,87.4786459591166,0.0038726982585288,17.635695025357908,87.58534781734159,0.001219004195394
0.0016300323687024004,90.3959381601674,0.0040428042883528,18.22382113308975,90.51104149448037,0.0012725141955809
0.0016808621497798005,93.314917129255,0.0042041888432736,18.812287293257807,93.43848044689462,0.0013232780476708
0.0017312945981047005,96.2353705118101,0.0043643118667052,19.40105069518092,96.36765434473024,0.0013736425356677
0.0017793443825952005,99.1622270939794,0.0045168699324625,19.991104982146247,99.30329886783667,0.0014216252110552
0.0018291552754211005,102.105584053084,0.0046750195171847,20.58448574510173,102.25592912340264,0.0014713641047711
0.0018791304998002005,105.018575881521,0.0048336908545884,21.171744897714635,105.1784585050802,0.0015212646064178
0.0019267314477972005,107.888160426691,0.0049848238644788,21.750253142020902,108.05754734851452,0.0015687920663818
0.0019739389956631003,110.713674385486,0.0051347078289531,22.319876756113977,110.89272395104167,0.0016159245027315
0.0020227180820351002,113.513572945958,0.0052895814281842,22.884336305905137,113.70268768211604,0.0016646236436123
0.0020714798424539002,116.300857513409,0.0054444000175139,23.44625287470325,116.50028692779732,0.0017133031167083
0.0021185237965838004,119.022880973516,0.0055937645718763,23.995012804260824,119.2325773435419,0.0017602654365451
0.0021651132092005004,121.727803359022,0.0057416859569343,24.54032515717884,121.9479365303968,0.001806771830127
0.0022078299992317005,124.432569592022,0.0058773117652834,25.08560602975164,124.66290943619448,0.0018494106013009
0.0022523937623400003,127.117876285877,0.0060188017131522,25.62696385923281,127.35885181077832,0.0018938910346084
0.0022940320633301004,129.76293018572,0.0061510033187958,26.16020672544116,130.0143230090992,0.0019354496882482
0.0023399495171659004,132.393500451142,0.0062967912347245,26.690529690950225,132.6560687135594,0.0019812773070081
0.0023822727741187005,134.981888259532,0.0064311675755496,27.212348673121657,135.25530279277962,0.0020235159008047
0.0024274939716363002,137.497563276327,0.006574744877668,27.71950875650753,137.7822912762775,0.0020686446667112
0.0024724830857947005,140.088625192371,0.0067175853151209,28.241866838782,140.3850211896648,0.0021135398027714
0.0025187269040635005,142.63828031047,0.0068644094381243,28.755877310590755,142.94666694278527,0.0021596849214012
0.0025647617234642005,145.166652227157,0.0070105699897216,29.26559708899485,145.48718796750725,0.0022056193723749
0.0026111004120273006,147.673777725734,0.0071576953259094,29.771033589507976,148.00669234261176,0.0022518548991809
0.0026537569499230002,150.184673721561,0.0072931298337283,30.2772302222667,150.5296552410846,0.0022944145831379
0.0026954752265513004,152.654806771693,0.0074255853620231,30.775209045173305,153.01183080275013,0.0023360363842704
0.0027371954521460003,155.164302514456,0.0075580470782863,31.28112338691433,155.5336691611564,0.0023776583974385
0.0027818723329656003,157.572629134847,0.0076998961748885,31.76664203358516,157.95476862597852,0.0024222281848345
0.0028220818696399006,159.995496057129,0.0078275614538294,32.255092005117206,160.38994474302604,0.0024623396382239
0.0028640472196323004,162.387936896306,0.0079608014400553,32.73740807829529,162.79509850950026,0.0025042009061927
0.0029076895971166003,164.785711940398,0.0080993659885679,33.220799527184234,165.2060772288049,0.0025477331835792
0.0029482200958082004,167.162506057739,0.0082280503219138,33.69996122124018,167.59570968349658,0.0025881597356394
0.0029939334988173002,169.5347115382,0.0083731903764677,34.17819784610113,169.9818127713115,0.0026337539386033
0.0030382117918785006,171.891423448248,0.008513773956937,34.6533109671668,172.35235092049194,0.0026779147918679
0.0030787186614267006,174.216832221291,0.0086423832677525,35.12211337581227,174.69105226404696,0.0027183125165842
0.0031233169225166005,176.501931516801,0.0087839827467129,35.58278939378708,176.99024330300733,0.0027627887212058
0.0031658195053475002,178.797548333561,0.008918928447201,36.0455857440459,179.29981055092225,0.0028051731422097
0.0032086679861366004,181.071621079537,0.0090549723737064,36.504038809634665,181.5880300642732,0.0028479006811868
0.0032528115005296004,183.364568089657,0.0091951280319042,36.96629692687485,183.8956108235465,0.0028919176893165
0.0032921049843766003,185.622007416121,0.0093198848431184,37.42139669509,186.16688166288216,0.0029310969362768
0.0033313278044792005,187.892537763056,0.0094444172969442,37.87913561303209,188.45144659254137,0.0029702041941163
0.0033718487316649003,190.249353266571,0.0095730712407588,38.35426961854072,190.8229818058873,0.0030106041283492
0.0034149468463973006,192.591369508602,0.0097099077550342,38.82642009293417,193.1803598809939,0.0030535717637165
0.0034558823959478006,194.930220910057,0.009839878124857,39.29793253546749,195.5343436239488,0.0030943816715468
0.0034965793121158003,197.246950123386,0.0099690908336904,39.76498514487462,197.8662801273068,0.0031349520275749
0.0035394134802439006,199.488360563612,0.0101050893174971,40.21685348962418,200.12327322543769,0.0031776512112835
0.0035835054358040004,201.760508589525,0.0102450812764004,40.67491853164824,202.41154884428644,0.0032216023144965
0.0036302028656961007,204.01314246304,0.0103933456163078,41.12904952054886,204.6809784000124,0.0032681484626214
0.0036733018834098005,206.155194058661,0.0105301849975488,41.560887122226056,206.83892707650145,0.0033111059335767
0.0037162350078041003,208.286922962571,0.0106664976675007,41.99064366925432,208.9866684674376,0.0033538962214181
0.0037634239732633004,210.38002373257,0.0108163226328337,42.41261278448612,211.0967286812928,0.0034009260791721
0.0038145136108889005,212.461144507981,0.010978532232295,42.83216673280897,213.1957938065924,0.0034518409636563
0.0038650748329933002,214.487238038971,0.0111390641124765,43.24062718865655,215.2397379116715,0.0035022266879586
0.003915175674611301,216.438547920101,0.0112981342846136,43.63401126069236,217.20873745672085,0.0035521511257262
0.0039648899673088,218.327583892934,0.0114559771639282,44.0148409128155,219.1153495040625,0.0036016879120471
0.004022879362966301,220.161527672816,0.0116400934951407,44.38456397883971,220.96867752042056,0.0036594671544191
0.0040844155987169,221.951094964688,0.0118354710436489,44.74534074488111,222.7784637072268,0.003720776732401
0.0041512547046622,223.665237001248,0.0120476852050252,45.0909117794516,224.51394514823963,0.0037873653899752
0.004222089862558301,225.309581788432,0.0122725868313453,45.42241168854789,226.1804893180171,0.0038579302868787
0.0043034974739878,226.933457405401,0.012531055997634,45.74978501292884,227.829115944766,0.0039390211505074
0.0043978292819813,228.496647343942,0.0128305594880134,46.064924104538704,229.42002996648,0.0040329777003202
0.004508405727913001,229.977070789121,0.0131816397038465,46.3633774710868,230.9318660292118,0.004143103027945
0.004633335755269601,231.35852567467,0.0135782925407037,46.64187877601347,232.34795992455872,0.0042675087893611
0.0047724128985853,232.674452035691,0.0140198624707311,46.90716953039531,233.7018737106495,0.0044059840962086
0.004922739307800201,233.907656630693,0.0144971488199884,47.15578357674771,234.9756862711056,0.0045556384278669
0.0050856034898762,235.051786556253,0.0150142425980797,47.38644016974061,236.16332184647905,0.0047177492064196
0.0052600692546105,236.067691265677,0.0155681714011111,47.59124655916049,237.225216393201,0.0048913787494555
0.005445193311549201,236.990715308992,0.0161559402818914,47.77732820629279,238.19663903935256,0.0050755825389505
0.0056342666324332,237.810114350623,0.0167562480756981,47.9425190530856,239.065171128881,0.0052636809422692
0.005822606435658,238.537282789189,0.0173542269509369,48.0891162103005,239.8411033062861,0.0054510144413766
0.0060144389651039,239.112368685091,0.0179632952319276,48.20505352691436,240.4652020936881,0.0056417859357375
0.006213028679272701,239.600601963319,0.0185938175744136,48.30348135580512,241.0037798794216,0.0058392389087238
0.0064138031504799,239.98682313637,0.0192312765204964,48.38134354429219,241.44044611495613,0.0060388245075179
0.0066134930788846,240.309723039885,0.0198652920431813,48.446440164840816,241.8132892852404,0.0062372924811859
0.0068089733453023,240.585085273886,0.0204859418890575,48.50195319121542,242.13740403807333,0.0064315384076171
0.0070023282471683,240.801869438931,0.0210998437024821,48.54565687888849,242.40214717386863,0.0066236352786929
0.007200938311390001,240.983797090712,0.021730430656386,48.58233349348754,242.63314565511905,0.0068209147085812
0.0073969334047019,241.153089099963,0.0223527150776513,48.616462762552544,242.8508611600408,0.0070155585407138
0.0075858938279169,241.319090207185,0.0229526644213589,48.64992858576851,243.06363070986004,0.0072031803382251
0.0077728064314453,241.468461232995,0.0235461119375616,48.6800417845718,243.2592150653045,0.0073887341978142
0.0079593238797064,241.616136423332,0.0241383048357906,48.70981310294373,243.4530510545863,0.0075738614599116
0.0081444542981231,241.748534506257,0.0247260939142636,48.736504556461405,243.63121071659944,0.0077575781457163
0.0083308096010021,241.883691529534,0.0253177720009044,48.763752212354056,243.81249661705584,0.0079424762810176
0.0085106176713518,242.020474512848,0.0258886626242647,48.79132766179016,243.9938875562583,0.0081208459776378
0.0086899080604605,242.159048676141,0.0264579096096848,48.81926421311003,244.17700843079948,0.0082986704613635
0.0088691428533928,242.259415883979,0.0270269800772449,48.83949824221017,244.3216333348833,0.0084764082022533
0.0090450287260204,242.37570613779,0.0275854177228375,48.86294235737847,244.48154396446043,0.0086507942891304
0.0092183095355934,242.477302970383,0.0281355842932318,48.88342427882922,244.6260401662629,0.0088225677933381
0.0093902754040895,242.54811174456,0.0286815759257069,48.89769932770329,244.7391864162572,0.0089930086285121
0.0095579384477463,242.66762461377,0.0292139060893172,48.92179312213603,244.90046530554457,0.0091591568331226
0.009728344446519,242.757824014566,0.0297549451354206,48.939977321336514,245.0328620412581,0.0093279949285943
0.0098963436300231,242.853741229049,0.0302883425430461,48.95931423177628,245.17047738722405,0.0094944204533272
0.0100628340889365,242.949160071495,0.0308169497500961,48.97855067041339,245.30725520779464,0.0096593240648414
0.0102351771241437,243.046901558092,0.031364138886879,48.99825535411135,245.44783282627893,0.0098299958317635