File: example/data/02 processed data/test_ID_068.csv
Strain,Stress_MPa,Displacement(mm),Force(kN),True Stress (MPa),True Strain
0.00013819496788810044,0.111361694723748,6.815971684595756e-05,0.0224505176563075,0.1113640853951117,2.146739692689685e-05
0.00014602933393630043,-0.0276199078259896,9.303382904889762e-05,-0.0055681734177195,-0.0276207171443464,2.930156410620921e-05
0.00014899632266320045,-0.144595241076134,0.0001024540182568,-0.0291504006009486,-0.1445999070173841,3.2268461495754904e-05
0.00014957653132490042,-0.203990115152394,0.0001042961807576,-0.0411244072147226,-0.2039968160626058,3.284865126686628e-05
0.00015465803856180044,-0.370359079153221,0.0001204299662348,-0.0746643903572893,-0.3703731271316138,3.79299786759752e-05
0.00015805013912150045,-0.374477904197332,0.000131199885512,-0.0754947454861821,-0.3744933786723422,4.132194482316336e-05
0.00015958544180370043,-0.326718705476777,0.0001360744715279,-0.0658664910241182,-0.3267327080201426,4.285718288640139e-05
0.00016493925393490044,-0.145796782777037,0.0001530728250445,-0.0293926314078506,-0.1458038119189022,4.821075124282116e-05
0.00016094132148510043,0.108191450247598,0.0001403793895164,0.0218113963699157,0.1081962338223182,4.421300354075733e-05
0.00016132985768050045,0.382732304343513,0.0001416129919367,0.0771588325556522,0.3827493751676796,4.460152248275062e-05
0.00016507678836750044,0.632652783424416,0.0001535094968681,0.1275428011383622,0.6326833718371643,4.834827903561718e-05
0.00016849625157720045,0.880285466652931,0.0001643662925587,0.1774655500772309,0.8803310380729459,5.176757107836392e-05
0.00017115229889670043,1.02135778586226,0.0001727992427981,0.2059057296298316,1.021413373217228,5.442347737729808e-05
0.00017473457744810044,1.15469790890017,0.0001841729771991,0.2327870984342742,1.1547648897353349,5.800555455847402e-05
0.00017430486871210043,1.19056646091463,0.0001828086519622,0.2400181985203894,1.19063501078858,5.757587065478122e-05
0.00017596017927430044,1.19009594373512,0.0001880642629972,0.2399233422570002,1.1901664364962394,5.923108454388712e-05
0.00017462736454300042,1.18979984186226,0.0001838325762253,0.2398636481194316,1.1898687313016685,5.789834786627063e-05
0.00017293522500570044,1.19037261175186,0.0001784600331944,0.239979118529175,1.1904395200780984,5.6206304866634864e-05
0.00017224269526910043,1.19133369566186,0.0001762612512807,0.240172873045431,1.1913998329745814,5.551381381386087e-05
0.00017388666892070043,1.19206274153991,0.0001814808676246,0.2403198486944459,1.1921308790456102,5.7157694853628536e-05
0.00017546958265030044,1.19382471818355,0.0001865066187159,0.2406750631858036,1.1938948461241887,5.874051685727627e-05
0.00017411851019780045,1.1965348017837,0.0001822169636791,0.2412214160395939,1.1966034723155166,5.738952285246534e-05
0.00017896017448870043,1.2015033804751,0.0001975892478028,0.2422230815037802,1.201578153435472,6.223089757120564e-05
0.00018769441352640043,1.21130211702077,0.0002253204567474,0.2441985067913872,1.211388079586523,7.096455494766399e-05
0.00019693236255050042,1.27167627221106,0.000254650944899,0.2563699364777497,1.271778267034469,8.020180576463846e-05
0.00020482566699630043,1.51755261477209,0.0002797121865144,0.3059386071380534,1.5176863086177683,8.809444603162528e-05
0.00021389729967390044,2.00337500581081,0.0003085146202658,0.4038804011714593,2.0035696736782644,9.716523844410094e-05
0.00022365526205130043,2.73269264210431,0.0003394961508142,0.5509108366482289,2.7329848432486727,0.0001069222051335
0.00023836800095320044,3.79387150426119,0.0003862090968277,0.764844495259056,3.794332993296511,0.000121633262793
0.00025416827429380044,5.29484752915667,0.0004363749646841,1.0674412618779847,5.295575257945188,0.000137431489619
0.00027214570663220046,7.36869825385877,0.0004934533123586,1.485529567977928,7.369843484901648,0.0001554062899141
0.00029467578820590044,9.6726249014617,0.0005649863213551,1.950001180134679,9.67434613004782,0.0001779326167239
0.00031805321907070044,12.0806467181727,0.0006392096643508,2.435458378383616,12.083078864986517,0.0002013056152005
0.00034444050914390044,14.5743346303252,0.0007229893103332,2.9381858614735603,14.577653398244236,0.0002276872459004
0.0003780634156516004,17.2290347874242,0.0008297420384952,3.473373413144719,17.233537355753594,0.0002613019327928
0.0004170518375278004,19.9590474044678,0.0009535302779521,4.0237439567407085,19.96504159534,0.0003002794086182
0.0004571303413941004,22.735354245323,0.0010807795277276,4.583447415857116,22.7430934281337,0.0003403450769022
0.0004966579649643005,25.2570989939575,0.001206279732563,5.091831157181832,25.26669493934954,0.0003798584690649
0.0005344163436696004,27.9106144593983,0.0013261625849523,5.626779875014697,27.92227241612872,0.0004176017953659
0.0005749959777205004,30.9488250960123,0.0014550029230639,6.23928313935608,30.96300797191154,0.0004581636641828
0.0006184945359734005,34.0950330495443,0.0015931108455169,6.873558662788131,34.112140818655945,0.0005016413523733
0.0006623877325620004,37.2626231387994,0.0017324717446857,7.512144824781959,37.28295587634927,0.0005455115735291
0.0007062026459665004,40.4457019008771,0.001871584094745,8.153853503216823,40.469543643358506,0.0005893016331105
0.0007519251574562004,43.6097544126224,0.0020167530687248,8.791726489584676,43.63745523342177,0.0006349961641763
0.0007991534053124004,46.8713138583788,0.0021667027556682,9.449256873849166,46.90330006464611,0.0006821933179926
0.0008497842426434004,50.1347242407944,0.0023274556641941,10.10716040694415,50.17147584643442,0.0007327883471336
0.0009035556338386004,53.2033200508823,0.0024981798312389,10.725789322257873,53.24518192839602,0.0007865189062011
0.0009564315473629004,56.2122970213059,0.0026660608566785,11.33239907949527,56.25949872359016,0.0008393518524856
0.0010090896562543004,59.2464305106826,0.0028332503524087,11.944080390953612,59.299299792611215,0.0008919643971754
0.0010609774183059004,62.3367401107985,0.0029979939969226,12.56708680633698,62.39560158249611,0.0009438045541014
0.0011143344894295004,65.4009828476236,0.00316740269774,13.184838142080917,65.46622733565711,0.0009971098695814
0.0011672508843443004,68.4872105801749,0.0033354122515945,13.80702165296326,68.55915800733919,0.0010499721300994
0.0012213216547958005,71.6176005588493,0.003507086947778,14.43810827266402,71.69670895322761,0.0011039846988385
0.0012756078178947005,74.7374297443826,0.003679445515617,15.067065836467531,74.8240414926414,0.0011582094937224
0.0013302984791001005,77.9060459128244,0.0038530883649441,15.705858856025396,78.00059044166392,0.0012128353563333
0.0013836480661594003,81.0310670953528,0.0040224733038574,16.335863126423124,81.13372703367536,0.0012661188587582
0.0014351987506649004,84.1827178862861,0.0041861467271624,16.971235925875277,84.2937103930462,0.0013176029899412
0.0014855404279510004,87.2993655396039,0.0043459815525457,17.599552092784144,87.41886205367763,0.0013678771167971
0.0015375732900113003,90.4573363436882,0.0045111858895872,18.236199006887546,90.58586228363254,0.0014198375029885
0.0015897728312309004,93.6057843214653,0.0046769194329594,18.870926119207404,93.74366989996308,0.001471961623447
0.0016426890549215004,96.7458618642931,0.0048449284431771,19.50396575184149,96.89349234552334,0.0015247986178864
0.0016965078794697005,99.8878438934472,0.0050158032111176,20.13738932891896,100.0456447653062,0.0015785339983267
0.0017489647030411004,103.037117975874,0.0051823536259568,20.7722829839362,103.20529900955916,0.0016309067108651
0.0018021394734617005,106.152005357549,0.0053511835220422,21.40024428008188,106.3309152353131,0.0016839934197516
0.0018554168388468005,109.33060047169,0.0055203391571399,22.041049055092703,109.52069243857426,0.0017371797274878
0.0019100630565661004,112.42349488518,0.0056938408983987,22.66457656885229,112.62510795387864,0.0017917296094414
0.0019640615185496004,115.502953368341,0.0058652860151963,23.285395399057546,115.71632592175996,0.0018456299547556
0.0020152066729357005,118.521720313499,0.0060276718803722,23.8939788152014,118.74673134995474,0.0018966794981182
0.0020656615368716004,121.557663835293,0.0061878660733687,24.506025029195072,121.7945717231684,0.001947037488059
0.0021183132454592004,124.631189703675,0.0063550352481343,25.12564784426088,124.88064973629984,0.0019995854008659
0.0021729151860440006,127.679436150935,0.006528396409491,25.7401743280285,127.94196905567,0.0020540767846108
0.0022273194498246005,130.658862388096,0.0067011299469944,26.34082665744016,130.93462995206107,0.0021083679387584
0.0022749029987692002,133.695764341576,0.0068522077148935,26.95306609126172,133.984303285787,0.0021558501424616
0.0023226875419677002,136.698746212084,0.0070039236395488,27.558467236356133,137.00029820581358,0.0022035306435766
0.0023733484990798004,139.730487000675,0.0071647721783797,28.169666179336083,140.0458057741345,0.0022540788130403
0.0024239609257674004,142.742440082245,0.0073254666331128,28.7768759205806,143.07178023404077,0.0023045760088053
0.0024722416444794004,145.680260675201,0.0074787579150234,29.36914055212052,146.0234126130238,0.0023527444289271
0.0025205178727856006,148.543936434072,0.0076320349398956,29.94645758510892,148.90100494209548,0.0024009060493262
0.0025652116849739005,151.432939369886,0.0077739377935935,30.528880576969016,151.80372055116553,0.0024454916906284
0.0026164677098418003,154.294456849847,0.007936675672549,31.10576250092916,154.68015293239483,0.0024966212153185
0.0026670359719247003,157.142626728013,0.0080972299046622,31.679953548367425,157.5433889253167,0.0025470621129098
0.0027139842800024006,159.951201442542,0.0082462907828089,32.246162210816465,160.36663581046477,0.002593889896453
0.0027608057579961006,162.717326726724,0.0083949489754389,32.80381306810756,163.14756409846908,0.0026405889916458
0.0028105123485556004,165.489152761311,0.0085527674004654,33.3626131966803,165.93494496000946,0.002690163271847
0.0028595108121335006,168.270874906955,0.0087083375223252,33.923408381242126,168.7324054814012,0.0027390289047548
0.0029095782561084004,171.016995301697,0.0088673016569455,34.477026252822114,171.49462027360397,0.0027889581537064
0.0029555672970323003,173.713321910329,0.0090133168618789,35.02060569712233,174.2064662295439,0.0028348180602299
0.0030029547928638006,176.367359421874,0.0091637721611439,35.5556596594498,176.87639573633214,0.0028820702949556
0.0030521717345179003,179.013564063243,0.0093200359508957,36.08913451514979,179.53904842631934,0.0029311443899809
0.0030997127485202004,181.678283738754,0.009470978670353,36.62634200173281,182.2202274080945,0.0029785451350012
0.0031470308772804005,184.292195610274,0.0096212137291666,37.15330663503124,184.8506569024264,0.0030257214214492
0.0031935617014051004,186.884813011548,0.0097689490957625,37.67597830312808,187.4598266257467,0.0030721105930483
0.0032409402209292006,189.457669938461,0.0099193758952515,38.19466625959375,190.0495760311722,0.0031193426684158
0.0032918820729458003,191.984263473666,0.0100811162754042,38.70402751629107,192.5938432163828,0.0031701245734994
0.0033395465658990005,194.566402726996,0.0102324510405307,39.22458678976239,195.19345507031449,0.0032176370745893
0.0033890749342609006,197.08337681916,0.0103897036100797,39.73200876674266,197.7283021330576,0.0032670051161286
0.0034385958636144005,199.56259634383,0.010546932560777,40.23181942291613,200.22551705100847,0.0033163633062058
0.0034870907436651004,202.051213598239,0.010700903804938,40.733524661404985,202.7321996141085,0.0033646964579354
0.0035374069550055003,204.535410937023,0.0108606577759438,41.23433884490383,205.2350610476526,0.0034148423976694
0.0035868414297444006,206.946663462604,0.0110176122332398,41.720447354060965,207.6647919952005,0.0034641071358446
0.0036377625055258006,209.333500402757,0.0111792866488457,42.201633681195815,210.0705710188857,0.0035148508332557
0.0036897348697980006,211.610563825219,0.01134429890541,42.66068966716415,212.3666499630381,0.0035666395020259
0.0037403597054400006,213.856065544452,0.0115050327585733,43.113382813761525,214.6310013049901,0.0036170828264581
0.0037921451534706006,216.005974351377,0.0116694515560705,43.54680442923761,216.7998865572086,0.0036686799694324
0.0038472436498673004,218.090800973861,0.01184438928213,43.96710547633038,218.90439226380937,0.003723575190647
0.0039032745665194004,220.09906093437,0.0120222874425004,44.37197068436899,220.9324764229928,0.0037793963018936
0.0039649894930304,222.069820609367,0.0122182323341728,44.76927583484839,222.92440349522948,0.0038408765334996
0.0040258852398493,223.943597101458,0.0124115763303229,45.147029175653934,224.81902798306805,0.0039015369959931
0.004090340538338901,225.744038745537,0.0126162219030273,45.50999821110027,226.6410582372218,0.003965739248674
0.004159486504770901,227.528190176792,0.0128357603464489,45.86968313964127,228.44803185275123,0.0040346091716596
0.004232418322082,229.244781235953,0.0130673188664117,46.21574789716813,230.1882819146525,0.0041072446923656
0.0043097277925415005,230.901259147189,0.0133127764351206,46.5496938440733,231.86942823116203,0.0041842343213281
0.004400195435981401,232.477653799928,0.0136000112030423,46.86749500606548,233.47346441288423,0.0042743201599404
0.004498328124373001,234.034960175021,0.0139115824886856,47.18144797128424,235.06040793996937,0.0043720295192457
0.0046053963885211,235.56367626928,0.0142515242273558,47.48963713588685,236.62104365177976,0.0044786250180765
0.0047240035221846,237.049910348725,0.0146281018767374,47.78926192630296,238.14206475453685,0.0045966951720508
0.00485013348398,238.446070462622,0.0150285645054378,48.0707278052646,239.57473255743008,0.0047222388024272
0.0049898495442887,239.731402957629,0.0154721629969179,48.32985083625801,240.89964338031885,0.0048612869778417
0.0051395665870216,240.988437958395,0.0159475146075949,48.58326909241243,242.198884142522,0.0050102668712107
0.005289126934483201,242.092933543956,0.0164223687107855,48.80593540246153,243.34513493511648,0.0051590686839378
0.005445530956258901,242.991015955086,0.0169189514799233,48.986988816545335,244.2858673594959,0.005314655780172
0.0056092161209677,243.810956362078,0.0174386518778738,49.15228880259493,245.15008530444325,0.0054774600688367
0.005777445888469101,244.487567975512,0.0179727813896907,49.28869370386322,245.87154328629023,0.005644756888672
0.0059513248863798,245.057202415284,0.0185248472080572,49.40353200692125,246.4870125670878,0.0058176422013571
0.006125817184732001,245.595665518165,0.0190788602553254,49.51208616846207,247.0714719376089,0.0059911072671408
0.0062999361727508005,245.973508621094,0.0196316880422851,49.58825933801255,247.49441419209103,0.0061641712318205
0.006477171619730901,246.319195354271,0.0201944105864469,49.65794978342104,247.88589487121817,0.0063403020175197
0.006656026964273901,246.638645023991,0.020762276305371,49.72235083683659,248.25148902259588,0.0065180111613115
0.006839543801854401,246.859326974471,0.021344942264689,49.76684031805336,248.5189169214852,0.0067003191048449
0.007027720804009801,247.062244849108,0.0219424042465324,49.807748561580176,248.7696904083316,0.0068872220082187
0.007216500853826,247.20862662095,0.0225417809046989,49.83725912678352,248.9637518804905,0.0070746887819464
0.0074026803428242,247.319118212521,0.0231329007822682,49.85953423164424,249.12107368438507,0.0072595386714962
0.007594818085251,247.43179473154,0.0237429381144733,49.88224981787847,249.2821121456704,0.007450268443159
0.0077887016560849,247.554778377413,0.0243585184518709,49.90704332088646,249.45401227881607,0.007642694381846
0.0079806898497243,247.675020334015,0.024968080966676,49.93128409933742,249.62272740838435,0.0078332027133644
0.0081692889376972,247.799405522437,0.0255668830709899,49.9563601533233,249.79482549914664,0.0080203127313319
0.0083532218650035,247.912260687691,0.0261508701151874,49.97911175463851,249.95418866539376,0.0082027597145736
0.0085388766336094,247.990772377132,0.0267403240055112,49.99493971122981,250.07938768539705,0.0083868808792534
0.0087284192873601,248.109382931765,0.0273421219311696,50.01885159904383,250.24602450669025,0.0085748228467436
0.0089148997920216,248.237344549622,0.0279341975334699,50.0446486612038,250.4213795158687,0.0087596940605544
0.0090989988334345,248.343714679713,0.0285187119899559,50.066092879430144,250.57440534852137,0.0089421708433742
0.0092833900227964,248.456617600788,0.0291041540161799,50.08885410831886,250.73413560551,0.0091249038287871
0.0094714262783035,248.58374779376,0.0297011691274149,50.11448355522202,250.9091739151928,0.0093112147191511
0.0096579530422222,248.700143362406,0.0302933916028568,50.13794890186106,251.07304756226867,0.0094959956800446
0.0098433769545566,248.843563278806,0.0308821125245185,50.16686235700729,251.2639774275236,0.0096796502759725
0.0100323906599957,248.977888908317,0.0314822310392877,50.19394240391671,251.446669828722,0.0098668257028098