File: example/data/02 processed data/test_ID_151.csv
Strain,Stress_MPa,Displacement(mm),Force(kN),True Stress (MPa),True Strain
0.00047123481510739977,0.264751278298104,-0.0073012427970159,0.0533738577048977,0.2641424551914348,-0.0023022521804812
0.0004687652937455998,0.68882837384756,-0.0073090835273396,0.1388678001676681,0.6872426402663149,-0.0023047273969171
0.00047331979056419976,1.20766253411236,-0.0072946229999405,0.2434647668770518,1.204887906428107,-0.002300162401539
0.0004740728868547998,1.78919971542348,-0.0072922319192179,0.3607026626293736,1.7850903424235849,-0.0022994075712957
0.0004918604553145998,2.76473676539784,-0.007235756389358,0.5573709319042045,2.758435990054495,-0.0022815792138325
0.0005067774898917998,3.93496772478422,-0.0071883948045754,0.7932894933164988,3.926058716422327,-0.0022666282177704
0.0005217213204763998,5.27253648024973,-0.0071409481424693,1.0629433544183455,5.260677926049812,-0.0022516505888261
0.0005252919590353998,6.66153859520362,-0.0071296113650445,1.3429661807930495,6.646579797951008,-0.0022480719077819
0.0005376292962917998,7.9995276167087,-0.0070904403192554,1.612704767528474,7.981662995244602,-0.0022357068805528
0.0005424920473293998,9.31370270012787,-0.007075001084711,1.8776424643457783,9.292948540535404,-0.0022308332575433
0.0005603782630197998,10.6047179126616,-0.007018212349894,2.1379111311925785,10.581276601725603,-0.0022129072568203
0.0005729587380293998,11.8873994819289,-0.0069782693417385,2.3964997355568665,11.861272403076068,-0.002200298991045
0.0005725003179207998,13.156582712736,-0.0069797248255833,2.652367074887578,13.127660090065158,-0.0022007584210309
0.0005744295282732998,14.4866822912655,-0.0069735995827142,2.920515149919125,14.454863607302892,-0.0021988249621463
0.0005773632422203998,15.8266539265782,-0.0069642850409321,3.190653431598165,15.791938547306112,-0.0021958847947008
0.0005860065063630998,17.2158940534932,-0.006936842677279,3.470724241184229,17.17828021141516,-0.0021872225676092
0.0006014804412397997,18.6199529569459,-0.0068877129340455,3.753782516120294,18.579559605508777,-0.0021717148709977
0.0006116659492071998,20.0317165447305,-0.006855373946249,4.038394055417669,19.988464605297622,-0.0021615072710723
0.0006147922183886998,21.4106056637294,-0.0068454480415978,4.316378101807847,21.3644433996002,-0.0021583742420367
0.0006266653168860998,22.8414824024941,-0.0068077509538685,4.604842852342811,22.79250630056864,-0.0021464755600632
0.0006303394426851997,24.1911186696315,-0.0067960856044564,4.876929523797711,24.139337594561773,-0.0021427935461515
0.0006291023033465998,25.5396886494446,-0.0068000135218564,5.148801231728031,25.484989364984685,-0.002144033340035
0.0006357982861974998,26.8123806508604,-0.0067787537763048,5.405375939213457,26.75513513067497,-0.0021373230078867
0.0006447426981521998,28.0651837122273,-0.0067503552683486,5.657941036385023,28.00551443325753,-0.0021283594985625
0.0006488585405287998,29.2853102280728,-0.0067372874688029,5.903918541979476,29.223167376539067,-0.0021242348953711
0.0006479724802972998,30.4329469100087,-0.006740100710038,6.135282097057754,30.36834183061446,-0.0021251228401974
0.0006578419678799998,31.5012589561555,-0.0067087650869629,6.350653805560949,31.43469689433489,-0.0021152324053499
0.0006575265663348997,32.5625699286009,-0.0067097664868686,6.564614097605942,32.49375504972429,-0.0021155484747986
0.0006784041883324997,33.5935636089774,-0.0066434800370262,6.772462423569843,33.523271272218715,-0.0020946268572859
0.0007013275121958998,34.6431118283745,-0.0065706984837599,6.984051344600299,34.57141751581909,-0.0020716557311283
0.0007100161027464997,35.6449112011009,-0.0065431122087617,7.186014098141942,35.57145335742842,-0.002062949160054
0.0007329127922156998,36.606543452991,-0.006470415219697,7.379879160122986,36.53194202436148,-0.0020400054503325
0.0007715788611580998,37.5813966001321,-0.0063476504508049,7.576409554586632,37.506261617747626,-0.0020012611724564
0.0007889316451397997,38.5410145711184,-0.006292555361663,7.76986853753747,38.46462985682441,-0.001983873777411
0.0008083726524269998,39.4791379409633,-0.0062308301635262,7.9589942088982015,39.401661467416034,-0.0019643943530616
0.0008275619665459998,40.3911003603324,-0.0061699040911983,8.142845832643012,40.31260926888005,-0.001945167491351
0.0008402549758066998,41.2503945286906,-0.0061296037867956,8.316079536984025,41.17075718238828,-0.0019324498489023
0.0008631875007820998,42.1086144733836,-0.0060567930199987,8.489096677834134,42.02828591835235,-0.0019094732290902
0.0008738981303838998,42.9692809243187,-0.006022786771013,8.662607034342651,42.88777074582707,-0.0018987421858674
0.0008806642124189998,43.8047237113414,-0.0060013044605516,8.831032300206427,43.721925133765936,-0.0018919632675595
0.0008974406769391998,44.645711903121,-0.0059480391856999,9.000575519669193,44.56207270820029,-0.0018751551737967
0.0009332471110610998,45.479745903529,-0.0058343537573629,9.168716774151449,45.39617269836485,-0.0018392821775074
0.0009512013519428998,46.2785658894964,-0.0057773490425632,9.329758883322476,46.19435567584824,-0.0018212950450919
0.0009620855114436998,47.0716415769234,-0.0057427918361481,9.489642941907755,46.986500588273934,-0.0018103911037105
0.0009692235715703998,47.8938525894902,-0.0057201284952459,9.655400682041224,47.80756629312981,-0.0018032401347669
0.0009883694972353998,48.69858421026,-0.0056593401812595,9.817634576788416,48.61178047659337,-0.0017840598371965
0.0009995006168711997,49.4862137050188,-0.0056239988764158,9.97642068293179,49.39855688288491,-0.0017729089034241
0.0010157296998832997,50.2731754513898,-0.0055724715378524,10.135072171000184,50.184940541367645,-0.0017566511543634
0.0010123178055386998,51.0498568185832,-0.0055833043023965,10.291651134626372,50.96008457127236,-0.0017600690533245
0.0010434914409179997,51.8791800605852,-0.0054843280100672,10.458842700213976,51.78956669354722,-0.0017288409894815
0.0010650970411282999,52.7020066639696,-0.0054157302293995,10.62472454345627,52.61211064801997,-0.001707198238523
0.0010976295988808999,53.4932672616934,-0.005312439358535,10.78424267995739,53.40376183227051,-0.0016746106247917
0.0011163835619825999,54.3177338230598,-0.0052528955256871,10.950455138728856,54.227867561338655,-0.0016558254062367
0.0011521429933447997,55.1712364974773,-0.0051393593311121,11.122521277891424,55.081931045791535,-0.0016200073559246
0.0011878516321334998,55.9886507511307,-0.005025984402958,11.287311991427948,55.900021432888856,-0.001584241461603
0.0012272430579894997,56.8151528665516,-0.0049009166258652,11.453934817896805,56.72745323591074,-0.0015447883590419
0.0012483792262406998,57.6995064306526,-0.0048338092916677,11.632220496419563,57.6116612620513,-0.0015236197387086
0.0012851566197140999,58.5750088926647,-0.0047170410673896,11.808721792761204,58.48798504306804,-0.0014867869460986
0.0013110177283196997,59.4361159592316,-0.0046349320475668,11.982320977381091,59.34934986202141,-0.0014608876943253
0.0013410975300390997,60.2479331201639,-0.0045394286771077,12.145983317025044,60.16179416100102,-0.0014307643709918
0.0013697355035810997,61.0190149057245,-0.0044485031111119,12.30143340499406,60.9335209600095,-0.0014020858051655
0.0013940552576399998,61.7800474991284,-0.0043712878919749,12.454857575824285,61.69498974366428,-0.0013777322253599
0.0014310340034197997,62.5696175309997,-0.004253880374124,12.61403489424954,62.48578645445432,-0.0013407031832422
0.0014617100221417999,63.3073797239254,-0.0041564840146817,12.76276775234336,63.224502208387165,-0.0013099864812648
0.0014935667053571997,64.0191998810268,-0.0040553390454728,12.906270696015,63.937429940574056,-0.0012780885476235
0.0015292770610597997,64.7334046033425,-0.003941958666117,13.05025436803385,64.6530340819997,-0.0012423331609766
0.0015820361426549998,65.4575440748391,-0.0037744485820523,13.196240885487564,65.37972796951064,-0.0011895098894676
0.0016268168082328998,66.2284892363683,-0.0036322699688424,13.351663430051852,66.15272238517616,-0.0011446769301638
0.0016873353811869998,66.9952436028794,-0.0034401234997132,13.506241110340486,66.92265402433222,-0.0010840908787039
0.0017284051397265998,67.7176965471348,-0.0033097270163499,13.65188762390238,67.64710533776565,-0.0010429774178412
0.0017844809514925997,68.3924636814948,-0.0031316863139929,13.787920678189352,68.32500423504075,-0.000986844665232
0.0018325634266109997,69.0866547677219,-0.002979024455492,13.927869601172734,69.02183245776877,-0.0009387158749677
0.0018811804248323998,69.7798470959637,-0.002824665486139,14.067617174546283,69.71776686739047,-0.00089005440176
0.0019231455326575997,70.4564356910146,-0.002691426268794,14.204017435308543,70.3967102416211,-0.0008480528081579
0.0019682813075462997,71.094013804743,-0.0025481201835224,14.33255318303619,71.03695676804898,-0.0008028797598308
0.0020114553018020995,71.7058214297094,-0.0024110427517602,14.455893600229416,71.6513692089166,-0.0007596720215976
0.0020761399606688997,72.31540316932,-0.0022056689598581,14.578785278934914,72.26516573937033,-0.0006949403000788
0.002124525283678,72.9036067387638,-0.0020520455593042,14.697367118534784,72.85648814901087,-0.0006465225126324
0.0021900738714201997,73.4994644003225,-0.0018439287932227,14.817492023105014,73.45677848577314,-0.0005809336835445
0.0022571613770215994,74.0091537799669,-0.0016309259629383,14.920245402041326,73.97113694519687,-0.0005138094461106
0.0023183702891282,74.4875392253911,-0.0014365876669998,15.016687907838843,74.45383595603792,-0.0004525709513207
0.0023887666520064996,74.9477320414652,-0.0012130792148612,15.109462779559385,74.9190965970745,-0.0003821452018344
0.0024644748223012995,75.396031694912,-0.0009727057741753,15.199839989694258,75.3729330632964,-0.0003064109624068
0.0025353792534601,75.8421481501861,-0.0007475842052461,15.28977706707752,75.82429038891082,-0.0002354873171654
0.0026136608586543,76.2799100177674,-0.0004990401087545,15.37802985958191,76.26792049506156,-0.0001571903407636
0.0026778250098655,76.6686538189589,-0.0002953189286591,15.456400609902117,76.66152257338172,-9.301816185326592e-05
0.0027573431100443996,77.0625669957504,-4.284896059106319e-05,15.53581350634328,77.06152697972009,-1.3495826687521515e-05
0.0028500439668256994,77.4391683048495,0.0002514762596896,15.611736330257662,77.44530188355778,7.92019846020068e-05
0.0029403344528562995,77.7836386409942,0.0005381485528368,15.68118155002443,77.79682262605532,0.0001694812444352
0.0030135510584397996,78.1255651215783,0.0007706112755644,15.750113928510189,78.14452715036334,0.0002426827629321
0.0031056350541550995,78.4197492673612,0.0010629779619605,15.809421452300016,78.44600390208676,0.0003347401767466
0.0032076258021999995,78.7133940706831,0.001386798587003,15.868620244649712,78.74777505451789,0.0004366915928818
0.0033174490741817,78.9965619490738,0.0017354874755449,15.92570688893328,79.03974227785292,0.000546460891564
0.0034237885219863,79.2735357716293,0.0020731152223245,15.981544811560466,79.32529740115234,0.000652736597431
0.0035248532813410994,79.539101753678,0.002393995833276,16.035082913541483,79.5990753846011,0.0007537303096073
0.0036308143066939996,79.8106146222842,0.0027304220887715,16.089819907852494,79.87924979238912,0.0008596058939974
0.0037352164235942,80.0368293456087,0.0030618988099296,16.135424796074712,80.11401506923826,0.0009639128646229
0.0038476190351124,80.2582168795527,0.0034187771014999,16.180056522917827,80.34463733752911,0.0010762008774845
0.0039831323879897,80.4282415262115,0.0038490319968853,16.214333491684236,80.52574416403435,0.0012115593078548
0.0041252925189368,80.5962242478281,0.0043003904126424,16.248198808362147,80.70538809981252,0.0013535372283248
0.0042520682101262,80.7399202633714,0.0047029032321687,16.277167925095675,80.85951460414988,0.0014801334263378
0.0043657146002311,80.871750447355,0.0050637305207518,16.303744890186767,81.00073084137291,0.0015936052908729
0.0044823307014026,80.9849383855755,0.0054339866419713,16.32656357853202,81.12354344805995,0.0017100289225139
0.0046293341211366,81.1081011460201,0.0059007224996267,16.35139319103765,81.25884016880256,0.0018567704099008
0.004742711421775,81.1871705353089,0.0062606954291536,16.367333579918274,81.34726129041954,0.0019699309873412
0.0048379009356251,81.2780469145288,0.0065629221356277,16.385654257969005,81.44605368405193,0.0020649286565732
0.0049456412822509,81.3583614640574,0.0069049977361646,16.40184567115397,81.53529982680618,0.0021724409769538
0.0050663326849013,81.4446693128673,0.0072881929395796,16.41924533347405,81.63162504951374,0.0022928632182017
0.0052109642572967,81.5413197949534,0.007747398181935,16.438730070662604,81.74029084148316,0.0024371531397829
0.0053462938269995,81.619514637037,0.0081770695657414,16.45449415082666,81.82972202258318,0.0025721441804828
0.0054660561141674,81.6986316913321,0.0085573148274995,16.47044414897255,81.9188272542797,0.0026915916834733
0.0056138629302508,81.7822702371722,0.0090266014685643,16.487305679813915,82.0147792011487,0.0028389903351702
0.0057582591074225,81.8647754203014,0.0094850593310845,16.503938724732762,82.10933990911634,0.00298296678924
0.0058914321154408,81.9143173165017,0.0099078836315426,16.513926371006743,82.16993858381795,0.003115734324503
0.0060241635735822,81.9652282549976,0.0103293060111415,16.524190016207516,82.23188775890907,0.0032480441169543
0.0061468484860135,81.9961507126316,0.0107188306081109,16.53042398366653,82.27297050790904,0.003370323713373
0.0062854942569985,82.015868418689,0.0111590309309883,16.5343990732077,82.30412593444208,0.003508493443912
0.0064264832590838,82.0283822908391,0.0116066710126091,16.536921869833165,82.3282488883025,0.0036489787852199
0.0065652850466238,82.0503457622384,0.0120473666880486,16.541349705667262,82.3616813850034,0.0037872654488937
0.0066966329316145,82.0696194401939,0.0124643962228941,16.545235279143093,82.39180786682846,0.0039181082650814
0.006823048493394,82.097270513039,0.012865765631544,16.550809735428665,82.42994586466428,0.0040440215586647
0.0069743528604667,82.1085999450017,0.0133461569969998,16.553093748912342,82.45374459560638,0.0041947039300143
0.0071224029315872,82.1269523499577,0.0138162159728074,16.556793593751475,82.48433304629013,0.0043421234088255
0.0072644909737616,82.1461244834481,0.0142673455067111,16.560658695863136,82.51526059054815,0.0044835858184374
0.0074202452163386,82.1449625530404,0.0147618652268931,16.560424450692945,82.52688786525337,0.0046386312665254
0.0075580067577687,82.1477498523379,0.0151992581209336,16.56098637023132,82.54100492448265,0.0047757458621381
0.0077121065907757,82.1357200656792,0.0156885250907309,16.558561165240928,82.54157464996129,0.0049290997487377
0.0078754126059785,82.1300780942805,0.0162070216889998,16.55742374380695,82.54931713585317,0.0050915895907004
0.0080192816074213,82.1343620434704,0.0166638057685806,16.558287387963635,82.56543954142903,0.0052347176886076
0.0081689064946558,82.1195803501511,0.0171388647855502,16.55530739859046,82.56286740018807,0.0053835503021337
0.0083269395570204,82.1126968188251,0.0176406197585578,16.55391967867514,82.5689232320316,0.005540722519359
0.0084703855042611,82.0993256340091,0.018096060641047,16.551224047816238,82.56725457109953,0.0056833656961938
0.0086250824872442,82.078655285273,0.0185872235620184,16.547056905511038,82.55916373108629,0.0058371741442045
0.008772524487582,82.0484622196377,0.0190553519130909,16.54096998347896,82.5408912972828,0.0059837472645318
0.0089193654296057,82.0086111905825,0.0195215719040161,16.53293601602143,82.51284331659997,0.0061297015192311
0.0090716581453809,81.9778284563792,0.0200051012766024,16.526730216806047,82.49435594006607,0.0062810521272626
0.0092244345851645,81.9490326876657,0.0204901664729153,16.520924989833407,82.47789861587505,0.0064328604541358
0.0093648902662145,81.9194624917406,0.0209361132602491,16.514963638334905,82.45964363975503,0.006572405766415
0.0095207811969791,81.9190673652741,0.0214310669654267,16.514883980839258,82.47201634746324,0.00672726348726
0.0096765342519012,81.9116280083174,0.0219255829148043,16.513384206476786,82.47728476157188,0.0068819603006696
0.0098458071870276,81.8953906460538,0.0224630244838306,16.510110754244444,82.47479794217827,0.0070500581762569
0.0100098673485363,81.8910255019911,0.0229839154966208,16.509230741201403,82.48383696972948,0.007212952503684
0.0101496060720616,81.8802548385231,0.0234275859438136,16.507059375446257,82.48443017941472,0.0073516773020509
0.0102922218488511,81.8670404551418,0.0238803910351203,16.50439535575659,82.48279382174238,0.0074932384379825
0.0104596146551391,81.8154597489523,0.0244118631950847,16.493996685388787,82.44452047671116,0.0076593678175322
0.0106166829317647,81.7690131822614,0.0249105549733709,16.4846330575439,82.41056011076377,0.0078152254995519
0.0107748473391207,81.7352306050969,0.0254127269667262,16.47782248998754,82.38944008507478,0.0079721463212869
0.0109238333709459,81.7152261576318,0.0258857576177713,16.473789593378573,82.38144994912717,0.0081199384147332
0.0110819486563151,81.6956838963663,0.0263877736488185,16.469849873507446,82.37466569628528,0.0082767627146086
0.011257630769914,81.6675805616613,0.026945564359495,16.464184241230917,82.36067632484507,0.00845098157302
0.0114442560328886,81.6448106985371,0.0275380995694393,16.45959383682508,82.35295020289752,0.0086360191943889
0.0116077713484839,81.660924006556,0.0280572606964544,16.46284227972169,82.38255608011988,0.0087981153303305
0.0117780452438852,81.6407020219503,0.0285978803143535,16.458765527625182,82.37605667555772,0.0089668834651163
0.0119469814632071,81.6249805844631,0.0291342528107006,16.455596085827764,82.37398304746034,0.0091342976099201
0.0121103474360566,81.591611448398,0.0296529397744977,16.44886886799704,82.35363700442431,0.009296165042663
0.0122705833502786,81.5599279160156,0.0301616888021526,16.442481467868745,82.33472639303255,0.0094549056797027
0.0124428402064212,81.5314493191768,0.0307086043204053,16.436740182746043,82.32002160793643,0.0096255269821385
0.0126061001904019,81.5037847216797,0.0312269547695441,16.431162999890624,82.3053957450027,0.0097872099702132
0.0127632266684096,81.4858796164139,0.0317258313372185,16.427553330669042,82.30011812761869,0.0099427940156037