File: example/data/02 processed data/test_ID_066.csv
Strain,Stress_MPa,Displacement(mm),Force(kN),True Stress (MPa),True Strain
-0.00019930825092969956,0.175511512674531,8.047341064637663e-05,0.0353831209551854,0.1755159611816278,2.5345634905717145e-05
-0.00020336707788279955,0.171613806659553,6.758663507037906e-05,0.0345973434225658,0.1716174598248203,2.1286902588337145e-05
-0.00020268308494449957,0.171187773451037,6.975831264939202e-05,0.034511455127729,0.1711915346385085,2.1970880732776428e-05
-0.00020235918244079957,0.168537724251554,7.078670309876429e-05,0.0339772052091132,0.1685414818042619,2.22947760676844e-05
-0.00020629361152359958,0.166194484381388,5.829489076098352e-05,0.0335048080512878,0.1661975358110926,1.8360426961628105e-05
-0.00020223960235109955,0.161131074321289,7.116636988364054e-05,0.0324840245831718,0.1611346860106228,2.2414353484161527e-05
-0.00020182985682119957,0.215050764325037,7.246731194104637e-05,0.0433542340879274,0.2150556727189965,2.2824089746091496e-05
-0.00020436717412179956,0.281126983226656,6.441132951157755e-05,0.0566751998184938,0.2811326864590186,2.0286827138052e-05
-0.00020133602311699956,0.347904027027898,7.403523395176422e-05,0.0701374518488242,0.3479121395179874,2.331791205713665e-05
-0.00020265493824809958,0.412854597158606,6.984767841043758e-05,0.0832314867871749,0.4128636796578603,2.199902681028643e-05
-0.00020273558841739958,0.480066179611657,6.959161412301136e-05,0.09678134180971,0.4800767019991609,2.1918378412030405e-05
-0.00020090157282519957,0.54696861369893,7.541461362823746e-05,0.1102688725217043,0.5469816056443376,2.3752352124375945e-05
-0.00020515378492209956,0.61658071208971,6.191384022068029e-05,0.1243026715572855,0.6165927356738649,1.9500231986087488e-05
-0.00020318841411799956,0.627049638047711,6.815389252374383e-05,0.1264132070304185,0.6270630981653924,2.14655625341135e-05
-0.00019227718639859957,0.627769765931429,0.0001027970405328,0.1265583848117761,0.6277900912460979,3.237649651587539e-05
-0.00017773529855489957,0.628678366886089,0.0001489675344365,0.1267415587642355,0.6287078637888508,4.69178078264026e-05
-0.00015907573298589957,0.629637044844571,0.0002082116551179,0.1269348282406655,0.629678335481179,6.557632387873646e-05
-0.00013377298486819957,0.630253284700771,0.0002885478803918,0.1270590621956754,0.6303105628895618,9.087709272263272e-05
-9.66559977763803e-05,0.631172407363975,0.0004063943144084,0.1272443573245773,0.6312531963018535,0.0001279900181907
-4.8894798835780304e-05,0.63984922529198,0.0005580361210448,0.1289936038188631,0.6399616848131564,0.0001757439643278
-2.298742024280315e-06,0.764578067676456,0.0007059786014213,0.1541389384435735,0.7647480757882342,0.0002223307477022
3.410687054341969e-05,1.1877034029416,0.0008215664213238,0.2394410060330266,1.1880107343539934,0.0002587276047089
6.697737692941972e-05,1.95042567856266,0.0009259302790993,0.3932058167982322,1.950994484292712,0.0002915890677437
0.00010057454696420043,3.09791398807863,0.0010326012939598,0.6245394599966518,3.098921518784982,0.000325175878596
0.00013733281306120044,4.63773900931823,0.0011493087888178,0.9349681842785552,4.639417810642215,0.0003619215186054
0.00017538373982310044,6.65647256907576,0.0012701204812868,1.341944869925673,6.659135410695637,0.0003999579530155
0.00022700838596990044,9.01886542965852,0.0014340287328029,1.818203270619157,9.022938913804476,0.0004515606241624
0.0002760545645209004,11.6115331757236,0.0015897503497023,2.340885088225878,11.617347172235943,0.0005005834587512
0.00032209108623300044,14.2856126812033,0.0017359163061382,2.879979516530585,14.293423272698254,0.0005465958825213
0.0003685660594851004,17.0343104190664,0.0018834743462136,3.4341169804837866,17.04441551723325,0.0005930443809374
0.0004248906094281004,19.8101546871029,0.0020623047922827,3.993727184919945,19.82302227039332,0.0006493339535376
0.0004830086490500004,22.6138616734892,0.0022468295680822,4.558954513375423,22.62986466342826,0.0007074125807967
0.0005433261658875005,25.3820587004675,0.0024383376840413,5.117023034014248,25.401551623373923,0.0007676856268962
0.0005856060752259004,28.2614287328066,0.0025725763961907,5.697504032533811,28.28432784602885,0.0008099321986124
0.0006271553201630004,31.2460425741434,0.002704495248866,6.29920218294731,31.27265825089541,0.0008514469433535
0.0006798646069755004,34.324055549528,0.0028718472344957,6.919729598784844,34.35510230354582,0.0009041099833834
0.0007438240918236004,37.4057459490703,0.0030749185988884,7.540998383332573,37.441972602274745,0.0009680096263299
0.0008054159421778005,40.5581957246098,0.003270472723763,8.176532258081336,40.59997351133181,0.0010295399909961
0.0008615466936322004,43.7103082675239,0.0034486878596307,8.811998146732819,43.7577864437327,0.0010856114113034
0.0009084280464581005,46.917531288873,0.0035975361548529,9.458574307836797,46.97069271095431,0.0011324408003007
0.0009586012667888005,50.1082725521845,0.0037568361294029,10.101827746520396,50.16756343996593,0.0011825559788028
0.0010208228619670004,53.3302892539676,0.0039543896940937,10.75138631359987,53.39671090631686,0.0012447021058402
0.0010800864554175004,56.5343399722795,0.004142551603299,11.397322938411548,56.60810262446647,0.0013038902280088
0.0011353074200705004,59.801787845166,0.0043178781660723,12.056040429585464,59.88311598186796,0.0013590377168559
0.0011848375041535004,63.0768892246695,0.0044751361830358,12.716300867693372,63.16579557719948,0.0014084993101616
0.0012285005067585004,66.3962774880503,0.0046137662163067,13.385489541590944,66.49276155166066,0.0014520999062284
0.0012780563223807003,69.6989318046531,0.0047711059309072,14.051304651818066,69.80366912336525,0.0015015825897884
0.0013225218218001005,73.0438260502468,0.0049122838915638,14.725635331729755,73.15683770696644,0.0015459803850956
0.0013769251336496005,76.3856376251026,0.0050850144066859,15.399344545220686,76.50797528424829,0.0016002981802339
0.0014246087944676004,79.7328818666109,0.0052364100297831,16.074148984308756,79.86438235867699,0.0016479044608046
0.0014742565142088005,83.0725452724906,0.0053940415399614,16.747425126934107,83.21367811029538,0.0016974692048691
0.0015266842152578005,86.3976329634354,0.005560499490792,17.417762805428577,86.54894445763975,0.0017498066173737
0.0015853088454873005,89.7445471713821,0.0057466326917706,18.09250070975063,89.90698148592799,0.0018083270431805
0.0016409008014520005,93.0559839343734,0.0059231371519586,18.76008636116968,93.22958499127222,0.00186381702195
0.0017004445393511004,96.3197543831021,0.0061121885197882,19.41806248363338,96.50517942151758,0.0019232481185118
0.0017460685011945005,99.5822444585668,0.006257044598641,20.07578048284707,99.77849344905816,0.0019687833817356
0.0017985196139005005,102.851978453477,0.0064235768814825,20.734958856220967,103.0600658837159,0.0020211299610427
0.0018484309236155004,106.113385267625,0.0065820452898277,21.392458469953205,106.33336734878672,0.0020709392548851
0.0018998438034160004,109.344510794449,0.0067452811831943,22.04385337616092,109.57681299008595,0.0021222444557738
0.0019536719663933006,112.521308784531,0.0069161856006472,22.684295850961448,112.7664168965252,0.0021759570608162
0.0020085613883618005,115.698650833966,0.0070904595153972,23.324848008127542,115.95703086537524,0.0022307256757821
0.0020595983383620005,118.896443936209,0.0072525018316478,23.96952309753973,119.1680334409094,0.0022816476066931
0.0021092862951885005,122.094780955407,0.0074102610945719,24.614307840610053,122.3797429097894,0.0023312210935634
0.0021613766325486003,125.253365187648,0.0075756479156903,25.25107842182984,125.55222357974785,0.0023831887879213
0.0022149870909057004,128.385270860503,0.0077458611209741,25.88247060547741,128.69848486934208,0.0024366702044004
0.0022700929135353004,131.518683811617,0.007920822107823,26.514166656421985,131.84678966935775,0.0024916404048837
0.0023206658430540003,134.646098059804,0.0080813911590449,27.144653368856485,134.98881547286237,0.0025420862092917
0.0023698307756058004,137.77644701028,0.0082374898198969,27.775731717272453,138.1339059330103,0.0025911251166419
0.0024228388144769005,140.864387352164,0.0084057903433126,28.398260490196265,141.23732483465895,0.0026439945852298
0.0024750906135619006,143.910190861978,0.0085716898054075,29.01229447777477,144.2987116543893,0.0026961070554401
0.0025268578337320005,146.951599161425,0.0087360507294476,29.62544239094328,147.3559382559282,0.0027477335609504
0.0025799699792103006,149.969061001552,0.0089046817913412,30.233762697912884,150.38966785722604,0.0028006985660494
0.0026291813069181003,152.91903601766,0.0090609277568134,30.82847766116026,153.35544179340727,0.0028497710564125
0.0026798601212231006,155.873721832103,0.0092218329922318,31.424142321351965,156.32645929056386,0.0029003043764606
0.0027289679904646006,158.790280455649,0.0093777504770736,32.01212053985884,159.2592869527506,0.0029492688254982
0.0027791558234948003,161.719839718095,0.0095370968469444,32.60271968716795,162.2056153947765,0.0029993076072134
0.0028313971195180004,164.610840241371,0.0097029629618181,33.185545392660394,165.1138994180563,0.0030513910938944
0.0028834311713960004,167.499673751528,0.0098681710765308,33.76793422830804,168.02027703840776,0.0031032652660397
0.0029314612806461003,170.348580304853,0.0100206666733998,34.34227378945837,170.88622009745828,0.0031511454098796
0.0029797917765364006,173.236897697518,0.0101741159978515,34.92455857581963,173.79202597855186,0.0031993226885083
0.0030280484205244002,176.113165740313,0.0103273308425134,35.5044142132471,176.68600949726502,0.0032474240337383
0.0030799960457897004,178.973453111551,0.0104922645527308,36.08104814728868,179.56489777862572,0.0032992018961576
0.0031324483100247003,181.773692775685,0.0106588004916769,36.645576463578095,182.38392569723817,0.0033514800284083
0.0031824380119033005,184.522891125366,0.0108175177951414,37.199814850873786,185.151577631936,0.003401301230142
0.0032276214512734006,187.300098453055,0.0109609752151415,37.75969984813589,187.946710023744,0.0034463302342676
0.0032740381582196006,190.060954112163,0.0111083482596957,38.316288349012055,190.72591892124896,0.0034925861794241
0.0033223122926348005,192.781330891491,0.0112616186364639,38.864716307724585,193.4651198139256,0.0035406908493018
0.0033727090081455005,195.474827316139,0.0114216282082104,39.407725186933625,196.1780212694206,0.0035909081802383
0.0034217308741916006,198.168138890981,0.0115772726329068,39.950696800421774,198.89073623620828,0.0036397531360115
0.0034661979149314005,200.846590079339,0.0117184554872557,40.49067255999474,201.58788514252385,0.0036840576404296
0.0035152801001562006,203.55592969716,0.0118742914253444,41.036875426947454,204.3172155020674,0.0037329581410759
0.0035703206926065005,206.185990835929,0.0120490453063741,41.567095752523294,206.96846149580983,0.0037877921489046
0.0036224054242852003,208.800234033626,0.012214414329454,42.094127181179005,209.60350098498776,0.0038396786214875
0.0036751664209378004,211.352309597724,0.012381930493826,42.60862561490116,212.17654569446373,0.0038922360401378
0.0037268890084666004,213.800176435792,0.0125461497092299,43.10211556945566,214.64501707246072,0.0039437563752299
0.0037786143314314006,216.201769052837,0.0127103776096432,43.58627664105194,217.06728279284783,0.0039952767806429
0.0038350023039621004,218.524798935987,0.0128894094224281,44.05459946549499,219.41193455880267,0.0040514383399666
0.0038874188634513006,220.694857495924,0.0130558319988063,44.49208327117828,221.60237087622863,0.0041036416039894
0.0039387411173878,222.785450970748,0.0132187801550547,44.9135469157028,223.7129948756699,0.0041547523751513
0.003999623292420101,224.784146798889,0.0134120810607823,45.31648399465602,225.73369741244665,0.0042153802866594
0.004063095470123601,226.739609986704,0.0136136052249909,45.71070537331953,227.71181267622444,0.0042785834707736
0.004129609269479001,228.733797776953,0.0138247865379443,46.11273363183373,229.7297649984584,0.0043448111001313
0.0041989811883966,230.604113555801,0.0140450423805077,46.48978929284948,231.62422207485943,0.0044138798796953
0.0042705253750589,232.469012521759,0.0142721951731605,46.86575292438662,233.51400248031723,0.0044851064381398
0.004351011182716901,234.335186212485,0.0145277376124746,47.24197354043697,235.40742561363945,0.0045652288568215
0.0044363947937116,236.150085212514,0.0147988305773828,47.60785717884283,237.25079233122096,0.0046502199486473
0.004523829164439901,237.933348646841,0.0150764347044451,47.96736308720315,239.0631711964108,0.0047372448874413
0.004619556943627701,239.687593430513,0.0153803704033664,48.321018835591424,240.8486907432856,0.0048325157147299
0.0047193248985907005,241.325753706921,0.0156971336603739,48.65127194731527,242.5188631908984,0.0049317977739326
0.0048401877786647,242.926578816019,0.0160808733046089,48.97399828930943,244.1569635518497,0.0050520588185125
0.0049740521834161,244.440961238451,0.0165058927896946,49.27929778567172,245.7117380257303,0.0051852397688984
0.005118255454357101,245.853390899918,0.0169637381749323,49.56404360542347,247.16696335744413,0.0053286869574936
0.0052783196918533,247.246835680975,0.0174719421289827,49.84496207328456,248.60742856431108,0.0054878878581124
0.0054539448205905006,248.555221403772,0.0180295519127233,50.10873263500044,249.96666684234768,0.0056625365636772
0.0056472244718603,249.780695287958,0.0186432148055049,50.35578817005233,251.24737722702,0.0058547063889007
0.005853165392054901,250.902020237898,0.0192970772271228,50.58184727996024,252.42695745395213,0.0060594241520637
0.0060631809509124005,251.956028783852,0.0199638766264953,50.794335402824565,253.5402867598969,0.0062681492007382
0.006279053899663,252.870839334453,0.0206492732387785,50.97876120982573,254.51543746218096,0.0064826502505866
0.0065056246261747,253.717969572351,0.0213686352954531,51.14954266578596,255.4255622525697,0.0067077316161288
0.006742113863593101,254.407588266955,0.0221194886242566,51.28856979461813,256.17998692981973,0.0069426122689751
0.006983913674857801,255.022951704388,0.022887203025022,51.412627063604624,256.8613019631907,0.0071827103459501
0.0072182997438353,255.531847760964,0.0236313787940255,51.51522050861035,257.4337595368307,0.0074153918469392
0.0074611060515932005,255.942361633969,0.0244022888211569,51.59798010540816,257.90947326551577,0.0076563752711946
0.0077066389618191,256.286653360677,0.0251818558111241,51.66738931751249,258.319337943746,0.0079000057872422
0.007964311813703,256.613016633978,0.0259999671158555,51.733184153409965,258.71441190767376,0.0081556183699862
0.0082173037259293,256.95641214845,0.026803216437174,51.80241268912752,259.12562737041367,0.0084065238882428
0.0084668706382694,257.253770251541,0.0275955913838538,51.86236008271067,259.48969778723153,0.0086539709865576
0.0087164229178236,257.546177155034,0.0283879198714384,51.92130931445486,259.84891738819067,0.0089013423668407
0.0089757092482286,257.808730395589,0.0292111539704743,51.97424004775075,260.1806644171695,0.0091582979266622
0.0092357518676406,258.127631309282,0.0300367892871074,52.03853047195125,260.5696235205629,0.0094159366788245
0.009490654151608,258.401080941959,0.0308461040387039,52.09365791789893,260.9115271235178,0.0096684182073013
0.0097365984476733,258.619452120169,0.0316269771787112,52.13768154742608,261.19562582416125,0.0099119664090564