File: example/data/02 processed data/test_ID_091.csv
Strain,Stress_MPa,Displacement(mm),Force(kN),True Stress (MPa),True Strain
-1.79312522792273e-06,0.180215682193762,-5.693172598654667e-06,0.036331481530262416,0.18021535904447578,-1.793126835617782e-06
-5.36537189435661e-05,0.908100186954411,-0.00017035055764582236,0.18307299769000923,0.9080514640022075,-5.3655158355878724e-05
-0.0001522865175452,2.24465837215758,-0.00048350969320601003,0.4525231278269682,2.2443165409510057,-0.0001522981143142572
-0.0002893443335555,5.11187294754885,-0.0009186682590387123,1.0305535862258481,5.1103938560776205,-0.00028938620170362395
-0.0004136958217869,8.88793022328841,-0.0013134842341734074,1.7918067330149436,8.884253323690704,-0.0004137814175112108
-0.0004890380233519,12.9699793316721,-0.0015526957241422824,2.614747833265095,12.963636518616825,-0.0004891576414461358
-0.000460558263504,17.4173515405234,-0.0014622724866252,3.511338070569517,17.409329835343055,-0.00046066435303589463
-0.0004431031272045,22.071080076262,-0.0014068524288742875,4.449529743374419,22.061300311659426,-0.00044320132640451393
-0.0003474696108999,27.1418791105879,-0.0011032160146071824,5.47180282869452,27.13244813241425,-0.00034752999245275524
-0.0002656678046243,32.5799358286726,-0.0008434952796821524,6.568115063060397,32.5712803886462,-0.00026570310056701235
-0.0001682387380918,38.2062002347744,-0.000534157993441465,7.70236996733052,38.19977247185962,-0.00016825289181578653
-5.43555223670303e-05,43.9704683387317,-0.00017257878351532117,8.864446417088311,43.96807830095643,-5.435699968192855e-05
4.36313393396218e-05,49.8009465870907,0.00013852950240329922,10.039870831957485,49.80311946909068,4.3630387520511124e-05
0.0001578009972664,55.6440974757175,0.00050101816632082,11.21785005110465,55.652878169791165,0.00015778854799876221
0.0002539563260482,61.5180027124613,0.0008063113352030349,12.4020293468322,61.53362559841598,0.00025392408459891597
0.0003633101396352,67.3971968208761,0.00115350969334176,13.587274879088623,67.42168290586412,0.00036324415848701337
0.0004662162394536,73.2665077682814,0.00148023656026518,14.770527966085531,73.30066580401102,0.0004661075944293049
0.0005793026757502,79.1487533871277,0.001839285995506885,15.956388682844945,79.19460447174714,0.0005791349447299537
0.0006900830611315,85.1142798632645,0.0021910137190925124,17.159038820434123,85.17301578605856,0.0006898450633018638
0.0007995878418789,91.1790504811096,0.0025386913979655074,18.381696576991693,91.25195614130836,0.0007992683418214031
0.0009162936569862,97.2795773299732,0.002909232360931185,19.611562789722594,97.36871398963494,0.0009158741162154221
0.0010240646340076,103.297823748451,0.00325140521297413,20.82484126768772,103.40360739652174,0.0010235406375273
0.0011363096573368,109.200939186219,0.00360778316204434,22.014909339941752,109.32502526800657,0.001135664546169349
0.0012340553010063,115.011801675903,0.003918125580695002,23.186379217862047,115.15373259943945,0.0012332944806287137
0.0013440249502612,120.833219876421,0.004267279217079309,24.359977127086474,120.9956227387553,0.0013431225571964404
0.0014502288568719,126.582236089679,0.004604476620568282,25.51897879567929,126.76580930122361,0.001449178290588235
0.0015556775520131,132.424203890732,0.0049392762276415925,26.696719504371572,132.63021325206802,0.0015544687392097857
0.0016617090201728,138.145018318818,0.00527592613904864,27.850035693073707,138.3745751418503,0.0016603299093147738
0.0017682026715743,143.877141667618,0.005614043482248403,29.005631760191786,144.13154561389317,0.0017666412415760255
0.0018701929369861,149.602195222876,0.005937862574930867,30.1598025569318,149.88198019173944,0.0018684463035307406
0.0019776035651028,155.288045174921,0.00627889131920139,31.306069907264074,155.59514336667678,0.0019756506814351564
0.0020817465850274,160.921739993748,0.006609545407461994,32.4418227827396,161.25673827643664,0.002079582753117959
0.002179165970348,166.446619204602,0.0069188519558549,33.555638431647765,166.80933401305217,0.0021767950320055614
0.00228636020224,171.86924891993,0.007259193642111999,34.64884058225788,172.2622039306494,0.0022837504578729754
0.002390548126012,177.276513216589,0.0075899903000881,35.738945064464346,177.70030125304487,0.002387695311463048
0.0024970429337078,182.711044072647,0.007928111314522264,36.83454648504564,183.167281394159,0.0024939305021748973
0.0025953669778481,188.217166619709,0.008240290154667717,37.94458079053333,188.7056592386179,0.0025920048290566868
0.0026884924257006,193.551129118905,0.008535963451599404,39.01990763037125,194.071489863527,0.002684884894373043
0.0027869374149785,198.755547790575,0.008848526292556738,40.06911843457993,199.3094670631471,0.0027830611052525695
0.002881682319038,203.902899982283,0.00914934136294565,41.10682463642826,204.49048336396254,0.002877538231930279
0.0029772400562238,208.950552725205,0.009452737178510563,42.124431429401334,209.57264868054858,0.002972816854162454
0.0030809053248853,213.954804852703,0.009781874406510828,43.13328865830493,214.6139793502585,0.0030761690615672293
0.0031763669556714,218.711299617871,0.010084965084256695,44.092198002962796,219.40600696280916,0.0031713329592160584
0.0032698594532789,223.099548428785,0.010381803764160508,44.976868963243064,223.82905259623712,0.003264525088110014
0.0033653403446638,227.115633634761,0.010684955594307564,45.78651174076782,227.87995503953596,0.0033596902596036322
0.0034457406378645,230.949605146702,0.010940226525219787,46.55944039757513,231.74539758645474,0.003439817675687382
0.0035473583765019,234.689800762484,0.011262862845393531,47.31346383371678,235.5223295930984,0.003541081340992681
0.0036295227945179,238.404782475021,0.011523734872594331,48.06240414696424,239.2700780673362,0.003622951971162519
0.0037319041086184,242.002044316212,0.01184879554486342,48.78761213414834,242.9051727396897,0.0037249578310111515
0.0038407089064756,245.439991251301,0.012194250778060028,49.48070223626228,246.38265481170515,0.003833352214614906
0.0039471265300046,248.806201923751,0.012532126732764604,50.159330307828206,249.78827148419393,0.00393935706408203
0.0040797227273085,252.023505526779,0.012953119659204487,50.80793871419865,253.05169155009258,0.004071423223999917
0.00420326640715,255.213870290227,0.01334537084270125,51.451116250509756,256.28660217785665,0.004194457358796383
0.0043478138370619,258.088002413104,0.013804308932671532,52.030541286481764,259.2101210011753,0.004338389401733259
0.0045028360741239,260.952689697673,0.014296504535343382,52.60806224305088,262.12771688248336,0.004492728637829957
0.0046718540584624,263.592780127866,0.014833136635618121,53.14030447377778,264.82424712748775,0.004660974819276819
0.0048638187715341,266.044356994019,0.015442624599620768,53.63454236999422,267.3383485316272,0.00485202861966572
0.0050880128602051,268.231911740755,0.016154440831151192,54.07555340693621,269.59667915720934,0.005075112661852629
0.0053446271972622,269.79481320138,0.016969191351307485,54.39063434139821,271.2367658976964,0.005330395364030917
0.0056440006157741,271.158586586594,0.017919701955082766,54.665571055857356,272.6890058162612,0.005628132921153826
0.0059720510618915,272.052203800657,0.01896126212150551,54.84572428621245,273.67691345325466,0.005954289046973071
0.0063155954927169,272.359307575213,0.020052015689376156,54.90763640716294,274.07941879053453,0.006295735693282733
0.0066809644198092,272.651766870667,0.02121206203289421,54.96659620112647,274.47334362412806,0.006658745683841564
0.0070630342714007,272.911956811696,0.02242513381169722,55.01905049323791,274.839543315732,0.007038207876080888
0.0074551271925736,273.121743699391,0.023670028836421178,55.06134352979723,275.15790103772747,0.007427475080144322
0.0078552322323604,273.426682359209,0.02494036233774427,55.12281916361653,275.5745124476644,0.00782454051790423
0.0082463416522367,273.606250346955,0.02618213474585152,55.15902006994613,275.8625009655034,0.008212526351404629
0.0086462778721956,273.691332727535,0.027451932244221027,55.17617267787106,276.0577440415088,0.008609112883904403
0.0090506211275295,274.046768955592,0.028735722079906163,55.24782862144735,276.52706243263265,0.009009909714138896
0.0094564405480285,274.228593616442,0.030024198739990484,55.28448447307472,276.82182000854533,0.009412008308364252
0.0098630724756652,274.16838416204,0.03131525511023701,55.272346247067276,276.8725268055662,0.009814749856208003
0.0102593623447111,274.07090677283,0.03257347544445774,55.252694805402534,276.882699513556,0.01020709228783361
0.0106557712441365,273.863976594213,0.033832073700133386,55.210977681393345,276.7822084808105,0.010599398622642824
0.0110671765028666,273.94279933597,0.03513828539660145,55.22686834613155,276.9745726479106,0.011006383432176105
0.0114815661557137,274.063609262844,0.03645397254439099,55.25122362738936,277.21028872346903,0.011416153194363099
0.0118953012155318,274.312934629025,0.03776758135931346,55.301487621211436,277.5759696137537,0.011825108216293219
0.0123062968354614,274.531732294146,0.03907249245258994,55.34559723049984,277.91020128251125,0.012231189928681161
0.0127071613284478,274.730747281923,0.04034523721782176,55.385718652035685,278.2217952095194,0.012627102851241117
0.0131097100532897,274.77630319889,0.04162332941919479,55.39490272489622,278.37854086334227,0.013024521527950748
0.0135134243000323,275.014822523412,0.04290512215260255,55.44298822071986,278.731214508969,0.01342293230816871
0.0139242289066641,274.952989063899,0.044209426778658516,55.430522595282035,278.78149742219625,0.013828177432825463
0.014334421301087,274.983732199183,0.04551178763095123,55.43672041135529,278.92546486747136,0.014232654840056737
0.0147350081693616,275.114223110092,0.046783650937723076,55.463027378994546,279.16803343512674,0.014627502712348221
0.0151299224788047,275.325986994838,0.04803750387020492,55.50571897815934,279.49164783447026,0.015016606744309121
0.0155278116089979,275.457787165215,0.049300801858568326,55.53228989250734,279.7350437905479,0.015408488772093585
0.0159060046203455,275.72491305347,0.05050156466959695,55.58614247157955,280.1105947944428,0.015780829739045554
0.0163110637562923,275.777878482944,0.05178762742622805,55.59682030216152,280.27610904145433,0.016179467411776473
0.0167119211667879,276.025596828389,0.05306034970455158,55.64676032060322,280.6385148426006,0.0165738135836232
0.0171101472434672,276.201371465919,0.05432471749800836,55.682196487529275,280.92721760054843,0.01696541724252111
0.0175030252912177,276.293573256434,0.0555721052996162,55.7007843684971,281.12954665694224,0.017351611589374802
0.0178952649783357,276.299346104179,0.05681746630621585,55.701948174602485,281.24379611605417,0.01773702971009226
0.0182900749509146,276.239054149745,0.05807098796915385,55.68979331658859,281.29148715451356,0.018124823463228964
0.0186983139063055,276.297304535048,0.059367146652519964,55.70153659426568,281.4635982667104,0.018525649469984664
0.0190843937389002,276.311740011971,0.06059295012100813,55.70444678641336,281.58498205304005,0.018904570967125434
0.0194850864699408,276.5067334613,0.061865149542062035,55.74375746579807,281.8944910723143,0.01929768264675245
0.0198727452985003,276.880177326457,0.06309596632273845,55.81904374901373,282.3825465686693,0.01967786000179038
0.0202712673393798,276.936634743564,0.06436127380253087,55.83042556430251,282.550491302519,0.020068540310121313
0.020660667902351,276.839298686375,0.06559762058996442,55.8108026151732,282.558983498854,0.020450131249997703
0.0210516340007731,276.768405493546,0.06683893795245459,55.79651054749888,282.5948326689737,0.02083310989281264
0.0214451278631136,276.801922979413,0.06808828096538568,55.80326767264967,282.73797561046223,0.021218416615991553
0.0218379048130341,277.060368294812,0.06933534778138327,55.8553702482341,283.1107862450983,0.021602873344185564
0.0222309920917059,277.372712394031,0.07058339989116623,55.91833881863665,283.5389829697177,0.02198748590212099
0.0226145209583419,277.766504343252,0.07180110404273553,55.9977272755996,284.0480607772478,0.022362603600436792
0.0230005631144034,278.009420167768,0.07302678788823079,56.04669910582203,284.40379338273544,0.022740037423300257
0.0233778095395331,278.14647129377,0.0742245452880176,56.07432861282403,284.648926523769,0.023108734077295818
0.0237644023713512,278.226611110953,0.07545197752904005,56.090484799968124,284.83850024781117,0.023486424336589366
0.0241496651827006,278.062562942431,0.0766751869550744,56.05741268919409,284.7776807373343,0.02386267334234428
0.0245278679488818,278.26955958028,0.07787598073769972,56.099143211384444,285.0949185918586,0.0242318898387047
0.0249052334452277,278.231854596598,0.07907411618859794,56.09154188667416,285.16128388722495,0.02460015314074078
0.0252926754937065,278.341333601702,0.08030424469251814,56.113612854103124,285.3813306289753,0.024978108899452227
0.0256794573043887,278.476681462173,0.08153227694143413,56.14089898277408,285.6278115140488,0.025355278154053383
0.0260725617590028,278.602147105212,0.08278038358483389,56.16619285641074,285.8660187918034,0.025738467209818
0.0264477833914173,278.714669836242,0.08397171226774992,56.188877438986395,286.08605505208135,0.026104087592077423
0.026824210812823,278.755359430787,0.08516686933071302,56.197080461246664,286.23275195736267,0.026470748635217665
0.0272064260366369,278.983810621868,0.08638040266632216,56.24313622136859,286.57396303097096,0.026842909810780042
0.0275860085206042,279.297126777794,0.08758557705291833,56.30630075840327,287.0018196968665,0.027212370474447287
0.0279816946870043,279.434055002967,0.08884188063123864,56.33390548859815,287.2530934152116,0.02759736014972787
0.0283721811926405,279.445493696892,0.09008167528663358,56.336211529293436,287.37397187752714,0.027977145472584928
0.0287523422733426,279.375520758423,0.09128868671786275,56.32210498489808,287.40822135406256,0.02834674982146447
0.0291202829895063,279.391501640541,0.0924568984916825,56.32532673073306,287.52746123317667,0.028704343110346912
0.0295008104071388,279.430939518054,0.09366507304266569,56.33327740683969,287.6743786866648,0.029074034670573373
0.0298780073306265,279.542515779025,0.09486267327473913,56.355771181051445,287.8946891146924,0.029440355742206013
0.0302583679149208,279.835707525679,0.09607031812987353,56.41487863717689,288.3030793197232,0.029809613421636114
0.0306470917252093,280.007019203982,0.09730451622753952,56.44941507152277,288.5884200052289,0.03018684937205778
0.0310193349332181,280.19427949409,0.09848638841296746,56.48716674600854,288.8857196960889,0.03054795843144839
0.0313930014265216,280.161969565879,0.09967277952920607,56.48065306448121,288.9570946761178,0.030910317103188676
0.0317565920352471,280.202091095964,0.10082717971190953,56.48874156494635,289.10035459032173,0.031262778808963075
0.0321382187916432,280.34816921318,0.10203884466346715,56.51819091337708,289.3580600131898,0.031632591028794656
0.032527609453499,280.597476195347,0.10327516001485933,56.568451200981954,289.7246413146667,0.03200978588633093
0.0329016300329446,280.843435305453,0.10446267535459909,56.61803655757933,290.0836421110542,0.03237195814223149
0.0332786207691643,280.846440659271,0.10565962094209663,56.61864243690904,290.1926228523405,0.03273687377847064
0.0336532076016146,281.028788769143,0.10684893413512636,56.65540381585923,290.4863089396212,0.033099330663995015
0.0340287015681838,280.973401949574,0.10804112747898356,56.644237833034126,290.53456199311336,0.033462533503882314
0.0344137987893984,281.175215632206,0.10926381115633993,56.684923471452734,290.85152292753844,0.03383488828347861
0.0347939788951741,281.471404334847,0.11047088299217775,56.74463511390516,291.2649144368687,0.034202352695852964
0.0351833163432248,281.613940549238,0.11170702938973874,56.77337041472639,291.52205290624397,0.03457852827375675
0.0355669761681291,281.694623772084,0.11292514933380988,56.78963615245214,291.71364974247587,0.034949079789003884
0.0359530079028405,281.693574515099,0.11415080009151858,56.78942462224396,291.8213058258197,0.03532178364139082
0.0363348496393168,281.712352519445,0.11536314760483084,56.79321026792012,291.9483284897772,0.03569030555248341
0.0367227097794397,281.8923246567,0.11659460354972104,56.82949265079072,292.2441746841196,0.036064496942284904
0.0371122587472689,282.059451652191,0.11783142152257875,56.863185453081705,292.5273150040199,0.03644017676090374
0.0374907344474477,282.173410144835,0.11903308187064644,56.88615948519873,292.75229853270577,0.036805042429775406
0.037864207990431,282.272329208739,0.12021886036961842,56.90610156848178,292.9603473918421,0.03716495536744001
0.0382392996087498,282.445425583219,0.1214097762577806,56.94099779757695,293.2459408352165,0.03752629729574659
0.0386269710893532,282.652463376726,0.1226406332086964,56.982736616747964,293.57047190791326,0.03789962078852561
0.0390254251369471,282.648641467596,0.12390572480980704,56.98196611986736,293.6791248652495,0.0382831825943432
0.0394110193143696,282.627606334085,0.12512998632312347,56.97772543695153,293.76624838609166,0.03865422514690781
0.0397890248301475,282.737831833951,0.1263301538357183,56.999946897724534,293.9876944452142,0.03901783183401544
0.0401700737432703,282.794856702193,0.12753998413488318,57.01144311116211,294.1547469501376,0.03938423222876065
0.0405444538735679,282.934994754196,0.12872864104857806,57.03969494244591,294.4064395982257,0.03974408950794894
0.0409350933497346,282.960909011315,0.12996892138540736,57.044919256681105,294.5439402360189,0.040119437400532365
0.0413111788086947,282.973709852167,0.13116299271760565,57.047499906196876,294.6636873780296,0.040480667931308875
0.0416902719631698,282.956534669641,0.1323666134830641,57.04403738939962,294.75306955377437,0.04084465534813961
0.0420662701439205,283.004128884675,0.1335604077069476,57.05363238315049,294.90905702218265,0.04120554029533339
0.0424461029465695,283.11185625023,0.13476637685535817,57.07535022004637,295.12885124602167,0.041569973542894
0.0428305826857227,283.228777022429,0.13598710002716957,57.09892144772169,295.3596305756643,0.0419387301171742
0.0432264851241728,283.381468698259,0.13724409026924864,57.129704089569024,295.6310535394106,0.04231830021553112
0.0436183534822632,283.425269877601,0.13848827230618566,57.13853440732437,295.78781348492805,0.042693860827845716
0.0440082987110134,283.370752186277,0.13972634840746753,57.12754364075345,295.8414168944552,0.04306743838576348
0.0444043942012309,283.5310121628,0.14098395158890809,57.15985205202048,296.1210349951509,0.04344676522696814
0.0447926193771193,283.726303672195,0.14221656652235376,57.19922282031452,296.4351479998606,0.043818415366073095
0.045187007562708,284.009242155713,0.1434687490115979,57.25626321859175,296.8427699288822,0.04419582401177129
0.0455773970299352,284.196674003741,0.14470823557004425,57.29404947915419,297.14961864939653,0.04456926586959747
0.0459644188857158,284.302931780467,0.14593702996214766,57.31547104694215,297.3707508272615,0.04493934870251322
0.0463499080327068,284.264536916608,0.14716095800384407,57.30773064238817,297.44017205965275,0.04530782981110506
0.0467479406980242,284.119825019424,0.14842471171622684,57.278556723915884,297.4018417505651,0.04568815858585086
0.0471373077647636,284.118518889484,0.14966095215312444,57.27829340811997,297.5111009560464,0.04606006728668654
0.0475343218160925,284.294523901198,0.15092147176609366,57.31377601848151,297.8082712908703,0.04643913773427001
0.0479305534077441,284.403010562702,0.15217950706958752,57.33564692944072,298.0346042498008,0.04681731787086791
0.0483176578087675,284.646161133306,0.1534085635428368,57.384666084474496,298.39959694352433,0.04718664856687256
0.0487143048542835,284.775700903453,0.1546679179123501,57.41078130213613,298.6483512123561,0.04756494232424823
0.0491277864965486,284.814746363257,0.1559807221265418,57.41865286683261,298.8070644136597,0.047959139436913864
0.0495337028658854,284.799933911825,0.15726950659918612,57.41566667662392,298.90712921443713,0.048345973022469124
0.0499335229251881,284.773208100349,0.1585389352874722,57.41027875303036,298.9929376155071,0.0487268506653535
0.0503352615013718,284.691443004227,0.15981445526685545,57.393794909652165,299.0214612350476,0.049109409873072156
0.0507308180571224,284.796836024613,0.1610703473313636,57.41504214256199,299.2448124962218,0.04948593925905622
0.0511327889858687,284.83081707385,0.1623466050301331,57.42189272208817,299.39501113995976,0.04986842928581141
0.0515387415528819,284.931816739497,0.1636355044304,57.442254254682595,299.61684400262703,0.05025455956451746
0.0519458125557297,284.964311341341,0.16492795486444178,57.44880516641434,299.7670140433509,0.05064160401144195
0.0523437540782606,284.939589355939,0.16619141919847738,57.44382121415731,299.85439714834683,0.05101982337210831
0.0527430411743517,285.023947698875,0.16745915572856662,57.4608278560932,300.05697750803307,0.051399177897327966
0.0531356392757611,285.221864300788,0.1687056547005415,57.50072784303887,300.3773103958348,0.05177203708394922
0.0535335333078915,285.450350907438,0.1699689682525555,57.5467907429395,300.73151677549066,0.052149784137962174
0.0539369733540254,285.561651250936,0.17124989039903063,57.5692288921887,300.9639824253892,0.052532650754398176
0.0543393079408,285.565478444094,0.17252730271203998,57.57000045432936,301.0829089145296,0.05291432235524905
0.0547417584711318,285.471718132672,0.17380508314584345,57.55109837554667,301.0989419770297,0.053295958264485105
0.0551471749334209,285.531519851975,0.17509228041361136,57.56315440215816,301.2777765262574,0.05368025950504801
0.0555544943126474,285.674155251974,0.1763855194426555,57.59190969879796,301.54463848519015,0.054066215881752075
0.0559771304520449,285.813833970972,0.17772738918524256,57.62006892854795,301.81287224016415,0.05446652828066164
0.0563901208349148,285.953566646816,0.17903863365085448,57.6482390359981,302.0785228232048,0.05485754966946655
0.0568164263381074,286.018081357371,0.18039215362349098,57.66124520164599,302.26860660817886,0.05526101757424464
0.057232643190265,286.046127169361,0.18171364212909136,57.66689923734318,302.4173031016022,0.05565478029577714
0.0576529066748772,286.217891339739,0.1830479786927351,57.70152689409139,302.71918471782914,0.0560522140861502
0.0580751814416095,286.24596618243,0.18438870107711017,57.70718678237789,302.8697526054034,0.056451390875182
0.0584996263281396,286.28705648243,0.1857363135918432,57.71547058685788,303.0347423092351,0.056852458572540655
0.0589309168074373,286.370897289423,0.1871056608636134,57.732372893547684,303.2469968136571,0.05725983012638945
0.059367472154379,286.329009164104,0.18849172409015333,57.723928247483364,303.3276386426449,0.057672005630461196
0.0597928806830901,286.312811621112,0.18984239616881105,57.72066282281619,303.43227940441324,0.05807349344978149
0.0602137164605165,286.42526105198,0.19117854976213988,57.74333262807917,303.67199050809336,0.05847050710390988
0.0606192072557677,286.473592436095,0.19246598303706244,57.75307623511675,303.8393945092829,0.05885289535869187
0.0610394413732132,286.521357454188,0.19380022635995192,57.76270566276429,304.01046105468635,0.0592490327139752
0.0614570036811989,286.618183476866,0.19512598668780648,57.782225788936195,304.23287823390234,0.05964249609465206
0.0618832371140609,286.641979735164,0.19647927783714333,57.78702311460906,304.380313333959,0.06004397055493678
0.0623052175205706,286.682773988061,0.19781906562781162,57.7952472359931,304.5446065807877,0.06044128032388861
0.0627389928605724,286.783783278187,0.19919630233231736,57.815610708882495,304.7763090098051,0.06084953097948209
0.0631648793671102,286.858740140153,0.20054849199057487,57.83072201225484,304.978137856507,0.06125019492087557
0.0635928729442102,286.916537074078,0.2019073715978674,57.842373874134125,305.1623839618226,0.06165267948444417
0.0640137268045307,286.93337552563,0.20324358260438496,57.845768505967015,305.3010502376295,0.062048291968311436
0.0644399113376048,287.01900819998,0.2045967184968952,57.86303205311598,305.51448764059404,0.06244875597761149
0.0648784646864062,287.115833137546,0.2059891253793397,57.882551960529284,305.7434675786684,0.06286067498412598
0.0653270900694977,287.142903653216,0.2074135109706552,57.888009376488355,305.9011139829868,0.06328187883341892
0.0657712166904131,287.308760547661,0.20882361299206156,57.921446126408455,306.20540729469525,0.06369868422051567
0.0662069067037377,287.276500864895,0.2102069287843672,57.91494257436283,306.29618935583335,0.06410740325436394
0.0666474087201921,287.288030802659,0.21160552268660993,57.91726700981606,306.43503361198293,0.06452046664976992
0.0670890833428068,287.267359229145,0.2130078396134116,57.91309962059563,306.5398630341371,0.06493445837795746
0.0675454511865739,287.216063835585,0.21445680751737212,57.90275846925393,306.6162024553914,0.06536204243821506
0.0679998206876571,287.186116339669,0.21589943068331127,57.89672105407727,306.7147207547511,0.06578757264253683
0.0684604626025341,287.176742631297,0.21736196876304578,57.89483131446948,306.83699528052443,0.06621879238073444
0.0689091158359975,287.190700501287,0.21878644277929205,57.897645221059456,306.98075774915145,0.06663861050164248
0.0693690958466986,287.206594354206,0.22024687931326806,57.90084942180793,307.1298561257668,0.06706884452384139
0.0698104343711411,287.304140042624,0.22164812912837295,57.920514632593,307.36096685562677,0.06748146863927454
0.0702500884458134,287.390821659433,0.22304403081545754,57.9379896465417,307.5800522995232,0.06789234868324531
0.0706954737173485,287.491576891607,0.22445812905258145,57.958301901347966,307.81593010970664,0.0683084127680415
0.0711452639441255,287.474785870497,0.22588621302259845,57.95491683149219,307.92725538853443,0.0687284162029189
0.0716051911724871,287.433604169394,0.22734648197264656,57.946614600549836,308.01534234534046,0.06915770299581316
0.0720627914854407,287.421297149264,0.2287993629662742,57.944133505291624,308.1336781542062,0.06958463508007812
0.0725244088886872,287.426417073576,0.23026499822158186,57.94516568203292,308.27184807083034,0.0700151304316266
0.0729847125602318,287.479634076251,0.23172646237873595,57.955894229772206,308.4612525362268,0.07044421616610834
0.0734472978091483,287.520149769661,0.23319517054404584,57.96406219356365,308.6377278359242,0.07087524333477095
0.0739169325345828,287.513924429841,0.23468626079730037,57.96280716505595,308.76607178467464,0.07131264908670248
0.0743830710916966,287.549644301715,0.2361662507161367,57.97000829122574,308.9384699362015,0.07174660948668606
0.0748552195645449,287.488885198319,0.23766532211743005,57.95775925598111,309.0089288222054,0.0721859730346893
0.0753224384114982,287.407818254394,0.2391487419565068,57.94141616008583,309.0560759438436,0.07262055931417512
0.0757948394956291,287.371169069826,0.24064861539862237,57.93402768447692,309.1524207051448,0.0730597739461034
0.0762785969340321,287.330054126755,0.24218454526555191,57.92573891195381,309.24718751252334,0.07350934730950441
0.0767520279825313,287.315236847357,0.2436876888445369,57.92275174842718,309.367263945673,0.0739491283796395
0.077234300165742,287.253530519041,0.2452189030262308,57.91031175263868,309.4393559188178,0.07439692341433139
0.0777115720029867,287.174760963543,0.24673424110948275,57.894431810250275,309.4915630776018,0.07483987824787251
0.0781958026062105,287.034583595856,0.2482716732747183,57.866172052924576,309.4794832358734,0.07528909106384925
0.0786994518695815,286.869329709653,0.24987075968592123,57.83285686946605,309.44578871599697,0.07575610425930226
0.0791790060829112,286.770363687095,0.25139334431324306,57.81290531931836,309.4765560578742,0.07620057250027941
0.0796695775143567,286.601330038175,0.2529509086080825,57.778828135696074,309.4347369173691,0.0766550475789086
0.0801377986088984,286.498022557583,0.2544375105832524,57.75800134760873,309.45734339115023,0.07708862430158576
0.0806141852170838,286.375504395675,0.25595003806424105,57.73330168616809,309.4614323486638,0.0775295695090599
0.0811055670213584,286.31455967507,0.2575101752928129,57.7210152304941,309.53626438398703,0.07798419070797234
0.0815941769715249,286.338632794417,0.2590615118845916,57.725868371354466,309.7021978724291,0.07843604257491514
0.0820989655324549,286.252487113291,0.26066421556554425,57.70850140203947,309.75352018638455,0.0789026416135423
0.0825930416010353,286.105305923782,0.26223290708328706,57.67882967423445,309.7356133582218,0.07935912787166287
0.0830960338687742,285.849420940106,0.2638299075333581,57.627243261525365,309.60237410391454,0.07982363801993905
0.083602944942785,285.559978856081,0.26543935019334236,57.56889173738593,309.4336340462488,0.08029154896485255
0.0841181395135045,285.266115927789,0.2670750929553768,57.50964897104226,309.26217086587826,0.08076688187009934
0.0846153918217539,284.925264922234,0.2686538690340686,57.44093340832238,309.03432785354585,0.08122544656675602
0.0851218168691918,284.5457348476,0.270261768559684,57.364420145276156,308.766784780207,0.08169225430237097
0.0856128542972361,284.237664976596,0.2718208123937246,57.30231325928175,308.57206277402395,0.08214467019911054
0.0861211087278145,283.868290379128,0.27343452021081105,57.2278473404322,308.31534227924766,0.0826127334596303
0.0866294365090286,283.544794244502,0.2750484609161658,57.162630519691604,308.1081199949716,0.08308064524232711
0.0871336903488435,283.094640336656,0.2766494668575781,57.07187949186986,307.76172106716746,0.08354459077772568
0.0876371736962075,282.576563158504,0.27824802648545877,56.9674351327544,307.3407745065032,0.08400761275827834
0.0881447984397842,282.066024353946,0.27985973504631484,56.86451050975551,306.92867721733586,0.08447422637976054
0.0886580686494836,281.558087367021,0.2814893679621104,56.762110413191444,306.52048360562367,0.08494580809896118
0.0891575426085147,281.033697206526,0.28307519778203416,56.65639335683565,306.0899710396453,0.08540450071297917
0.0896567093808889,280.507724809902,0.2846600522843223,56.550357321676245,305.65712437227774,0.0858627011131754
0.0901258986873755,279.965436498624,0.2861497283324172,56.4410319981226,305.1975730644658,0.08629319295396343
0.0906004784285876,279.339850628754,0.2876565190107656,56.314913886756806,304.6481747398893,0.08672844219356035
0.0910863783369858,278.706643900983,0.2891992512199299,56.18725941043817,304.09302271237954,0.08717387726131567
0.0915715429510797,278.041811825424,0.29073964886967807,56.05322926400549,303.50252953919187,0.08761844039450531
0.092072267860074,277.317494679084,0.29232945045573494,55.907206927303335,302.85074533146127,0.0880770544919983
0.0925675345852967,276.60949204776,0.293901922308317,55.764473596828424,302.2145507695124,0.0885304626310911
0.0930578224435201,275.773948329872,0.2954585862581763,55.59602798330219,301.4368714481017,0.08897911030519552
0.0935453205194249,274.951341170578,0.297006392649174,55.430190379988524,300.6717525076255,0.08942500565255282
0.0940323845006166,274.110328137755,0.29855282078945766,55.26064215257141,299.8855759087946,0.08987030548178611
0.094505038781532,273.149523108303,0.3000534981313641,55.066943858633884,298.9635293828102,0.09030224169931278
0.094987585369404,272.135674662787,0.3015855835478577,54.86255201201786,297.9851852918788,0.09074302564200537
0.0954939837809934,271.032432305754,0.30319339850465404,54.64013835284001,296.9143990004829,0.0912053882820227
0.0960070303367486,269.832361126767,0.30482232131917675,54.39820400315624,295.738164807301,0.09167360304607974
0.0965034428468186,268.557312484395,0.306398431038649,54.14115419685404,294.47401774082806,0.09212642872205623
0.0969822508273534,267.29565083255,0.307918646376847,53.88680320784208,293.21858468665306,0.09256300142414463
0.0974357919655322,265.854520252757,0.30935863949056475,53.59627128295581,291.758265981201,0.09297636035192614
0.0978956510056924,264.306814178329,0.3108186919430734,53.284253738351126,290.181301817557,0.09339530305723687
0.0983557501337874,262.667475179887,0.312279506674775,52.95376299626521,288.5023317369528,0.09381428891157696
0.0987824418924523,260.595064340857,0.31363425300853603,52.535964971116776,286.3372811415676,0.09420269576334221
0.0992331475031996,258.743413019598,0.31506524332265873,52.16267206475096,284.41933628925307,0.09461279805673671
0.0994388925469457,257.594288903497,0.3157184838365526,51.93100864294499,283.2091797184787,0.0947999519756467
0.099540486114834,257.028728716297,0.31604104341459793,51.816991709205475,282.61349331819497,0.09489235263110206