File: example/data/02 processed data/test_ID_136.csv
Strain,Stress_MPa,Displacement(mm),Force(kN),True Stress (MPa),True Strain
9.32996804869509e-05,1.3355073416374,0.0002962264855460691,0.26923828007409983,1.3356319440456628,9.329532834250209e-05
0.0001354043132051,3.05638329103372,0.0004299086944261925,0.6161668714723979,3.0567971385141344,0.00013539514686854853
0.0001730979486677,4.69842648327967,0.0005495859870199474,0.9472027790291816,4.6992397712658915,0.0001730829689462978
0.0002028274457275,6.35335190673161,0.0006439771401848124,1.2808357443970926,6.35464054087066,0.00020280687902210468
0.0002851324641149,9.43979651348114,0.0009052955735648075,1.903062977117798,9.442488105921772,0.00028509182157932016
0.0003586129061431,12.9403501325114,0.0011385959770043425,2.608774586714298,12.944990709078928,0.0003585486199035946
0.0004215195681191,16.4823399854679,0.0013383246287781425,3.3228397410703288,16.489287614300167,0.000421430753703179
0.0005006756822277,19.8177707908521,0.0015896452910729474,3.9952625914357838,19.827693066763043,0.0005005503859783944
0.0005701908425639,23.1055438676852,0.0018103559251403823,4.658077643725336,23.11871843721101,0.0005700283455320737
0.0006416657414823,26.3712347951603,0.002037288729206302,5.316440934704317,26.388156313088942,0.0006414599620434207
0.0007331613655024,29.6033590675728,0.00232778733547012,5.968037188022676,29.625063106730238,0.0007328927340005958
0.0008175609259664,32.7157739857946,0.0025957559399433197,6.595500035536191,32.74252112426813,0.0008172269050751308
0.0009003265275105,35.7574814347195,0.0028585367248458375,7.208708257239452,35.78967484381214,0.0008999214766828553
0.0009898536763759,38.7168876628935,0.003142785422493482,7.80532455283933,38.755211716484446,0.0009893640942754151
0.0010683480171663,41.5453889512782,0.0033920049545030024,8.375550412577685,41.589773885186695,0.001067777739557202
0.0011550833587937,44.2754206319457,0.0036673896641699973,8.925924799400253,44.32656243352125,0.001154416763276994
0.0012461334588353,46.9177843319792,0.0039564737318020776,9.458625321327006,46.9762501528497,0.0012453576789534123
0.0013347712001204,49.3974119566863,0.00423789856038227,9.958518250467957,49.46334619952656,0.0013338811849317729
0.0014327517010738,51.7861136852212,0.004548986650909315,10.440080518940595,51.8603103276957,0.0014317262916764314
0.0015358001530133,53.9579202868696,0.004876165485817228,10.877916729832911,54.04078886910245,0.0015346220180572235
0.0016506135291774,55.8743676181919,0.005240697955138244,11.264272511827487,55.966594605316715,0.0016492527638586822
0.0017788489828156,57.6629384882342,0.0056478455204395294,11.624848399228014,57.765512147710155,0.0017772687047369904
0.0019231147969043,59.2321362212051,0.006105889480171152,11.94119866219495,59.34604641882436,0.0019212679790260791
0.0020663028398829,60.5729293999486,0.006560511516628208,12.211502567029639,60.69809141598773,0.002064170972387246
0.0022589927653654,61.7170858403467,0.007172302030035145,12.442164505413894,61.856504290759474,0.0022564450772928975
0.0024847522029086,62.5858483040395,0.007889088244234805,12.617307018094364,62.741358628483866,0.0024816703102576412
0.0027219708955365,63.3134328909628,0.008642257593328387,12.763988070818101,63.48577021258851,0.002718273041539273
0.0029898699186319,63.9004983318654,0.009492836991656282,12.882340463704066,64.09155250961344,0.0029854091467733297
0.0032833941284881,64.2788141843104,0.010424776357949717,12.958608939556978,64.48986686538935,0.0032780155600773864
0.0036097479540018,64.537366164471,0.011460949753955714,13.010733018757353,64.77032978993986,0.0036032484502071423
0.003958973958899,64.7555109195794,0.012569742319504326,13.054711001387206,65.0118763010052,0.003951157843900993
0.0043097689823949,64.8282581909396,0.013683516519103807,13.069376851293423,65.1076530072736,0.004300508525473604
0.0046620832227379,64.875942130733,0.014802114232192833,13.078989933555773,65.1783991721,0.004651249371910108
0.0050418143680904,64.900513332527,0.016007760618687018,13.083943487837445,65.22772967314337,0.005029146981927794
0.0054305003748655,64.8670021466427,0.017241838690197964,13.077187632763168,65.21926242611646,0.005415808373649093
0.0058152002359721,64.8377668590392,0.018463260749211417,13.071293798782303,65.2148114561778,0.005798357224524206
0.0062018327864203,64.8124859386987,0.019690819096884454,13.06619716524166,65.21444213896274,0.0061826805665849815
0.0066107719116134,64.7077073688288,0.020989200819372545,13.045073805555887,65.13547526316755,0.0065890165860087915
0.0069738549642416,64.6627887473187,0.022141989511467078,13.03601821145945,65.11373765762589,0.006949650106663612
0.0073701537584993,64.6128960187148,0.023400238183235274,13.025959837372906,65.08910299715467,0.007343126888836659
0.0077667331502525,64.5310851867687,0.024659377752051688,13.009466773652571,65.03228090531054,0.007736727342929208
0.008157264209758,64.4632330341342,0.025899313865981648,12.995787779681457,64.98907665780884,0.008124173561042974
0.0085626747923517,64.3630902432218,0.027186492465716642,12.975598993033516,64.9142104536053,0.008526223027817522
0.0089687383147216,64.2696585136153,0.02847574414924108,12.956763156344843,64.84607626240043,0.008928758051772968
0.0093779543400489,64.1995504209507,0.029775005029655254,12.942629364863663,64.80161087345004,0.009334254324959042
0.0098148251820312,64.1013447633432,0.031162069952949057,12.92283110428999,64.73048825612852,0.009766972640148754
0.0102241907575463,64.0005630854943,0.0324618056552095,12.902513518035652,64.65491705107077,0.010172277268315655
0.0106283261333337,63.8749986782258,0.0337449354733345,12.877199733530322,64.55388299594425,0.010572242508527093
0.0110444974866802,63.7702391300445,0.03506627952020963,12.856080208616973,64.47454937584126,0.010983952409716516
0.0114528937957997,63.6834294144492,0.036362937801664046,12.838579369952958,64.4127889680852,0.011387805899397632
0.0118726266204898,63.5689771713908,0.03769558952005511,12.815505797752385,64.32370790199316,0.011802699920627411
0.0122967309827146,63.458538440151,0.03904212087011885,12.793241349534442,64.2388710159058,0.012221740320421722
0.0127106768243516,63.3495544812087,0.04035639891731633,12.771270183411673,64.154770195186,0.012630574229677428
0.0131304201931312,63.2362796000755,0.04168908411319156,12.74843396737522,64.06659852267482,0.013044963468205589
0.0135637719569029,63.1485916466686,0.043064975963166705,12.73075607596839,64.00512474316359,0.013472607433490854
0.0139840829899439,63.0482523681608,0.044399463493071875,12.710527677421219,63.929924361648084,0.013887207797212194
0.0144216754388184,62.9553284370401,0.04578881951824842,12.691794212907284,63.863249750903314,0.014318672215852167
0.0148397455586852,62.8351576618199,0.04711619214882551,12.667567784622893,63.76761541366118,0.014730713879341991
0.0152679354626309,62.7213772390115,0.048475695093853105,12.644629651384719,63.679003178824054,0.015152553483514897
0.0157018795174818,62.6189246347779,0.04985346746800471,12.623975206371224,63.60215944490745,0.015579880426784704
0.01614152284576,62.5113249389248,0.051249335035287995,12.60228310768724,63.52035291854518,0.016012633595289844
0.0165794624930024,62.406805692703,0.05263979341528261,12.581212027648926,63.441476986993266,0.016443523675312686
0.0170225308646635,62.288251019492,0.054046535495306615,12.557311405529589,63.34855469497721,0.01687927106356154
0.0174528599632854,62.1678991029878,0.055412830383431144,12.533048459162343,63.25290674024391,0.01730230798696673
0.0178926464498548,62.074750844902,0.056809152478288986,12.514269770332245,63.185432415232654,0.017734457213746998
0.0183245995944963,61.9629778872862,0.05818060371252575,12.491736342076898,63.098424646753344,0.0181587274157209
0.0187731240211804,61.8623671144735,0.059604668767247765,12.471453210277858,63.0237170045573,0.018599083741028564
0.01921081888191,61.7509008251663,0.06099434995006425,12.448981606353525,62.937186196713355,0.019028620851940032
0.0196563015874532,61.6483689262834,0.06240875754016391,12.428311175538735,62.860147858273,0.019465611284675742
0.0201039486889903,61.5360208688682,0.0638300370875442,12.40566180716383,62.77313787494056,0.01990453258306178
0.0205589410477354,61.4237864902226,0.06527463782655989,12.383035356428875,62.686594495603764,0.020350458628537557
0.0210064338383059,61.3071564733783,0.06669542743662123,12.359522745033066,62.59500119965098,0.020788840669339916
0.0214536714003072,61.1997906798149,0.06811540669597536,12.337877801050684,62.51275087882724,0.021226780747584207
0.0218955412153965,61.0792977448937,0.06951834335888389,12.31358642537057,62.4166620260745,0.021659276396638047
0.0223543574639072,60.9503398361354,0.07097508494790536,12.287588510964897,62.312845520378985,0.022108161101498488
0.0228005509579171,60.8239627514008,0.07239174929138678,12.262110890682402,62.21078261357656,0.02254450311085129
0.0232556155572871,60.7245292115526,0.07383657939438654,12.242065089049005,62.136715517793725,0.02298932433748331
0.023705894553994,60.6003821780075,0.07526621520893095,12.217037047086313,62.03696844785109,0.023429273014334825
0.0241708994570211,60.499805789315,0.07674260577604199,12.196760847125905,61.962140512217836,0.023883406693058776
0.0246267005082562,60.3975779795288,0.07818977411371343,12.176151720673007,61.8849710438547,0.024328351629310678
0.0250952474818819,60.2831989538516,0.07967741075497503,12.153092909096484,61.79602075059804,0.02478553264573721
0.0255603037263142,60.2022092785311,0.08115396433104757,12.13676539055187,61.74099603268548,0.025239101020134307
0.0260317597858632,60.0920648837425,0.08265083732011565,12.11456028056249,61.6563670818326,0.025698701226464723
0.0264960534514131,59.9832350488382,0.08412496970823659,12.092620185845783,61.572554050880896,0.026151112804495193
0.026969552738558,59.8862392189871,0.08562832994492164,12.0730658265478,61.50134430591748,0.026612283709047498
0.027439385288405,59.7776712708229,0.08712004829068587,12.051178528197898,61.41793382446662,0.027069673228087527
0.0279127181455969,59.6606162965588,0.08862288011227015,12.027580245386256,61.32590626363725,0.027530258900750476
0.028384776646406,59.55292737609,0.09012166585233904,12.005870159019745,61.24332391829995,0.027989393350213523
0.0288613968512014,59.436647503397,0.09163493500256444,11.982428136684835,61.15207217449751,0.028452750841857468
0.0293412689159828,59.3488103909351,0.09315852880824539,11.964720174812516,61.0901797964592,0.028919052903805007
0.0298312578914796,59.2410444165073,0.09471424380544773,11.942994554367871,61.00827929025673,0.029394961530562536
0.0303371235397039,59.1390007946991,0.09632036723855988,11.92242256021134,60.93310796782253,0.029886053096621273
0.0308302078178234,59.0305116737022,0.09788590982158929,11.900551153418364,60.85043461619488,0.03036450458381899
0.0313294156505323,58.9255015873137,0.09947089469044006,11.879381120002442,60.77160311895875,0.030848664817371724
0.0318254896771983,58.8070094277539,0.10104592972510461,11.855493100635185,60.678571299243785,0.03132955361049614
0.0323229466523563,58.697855982342,0.10262535562123125,11.833487766040149,60.59514364986693,0.03181155090878473
0.0328174086852565,58.5869219295545,0.10419527257568938,11.811123460998187,60.5095928901279,0.03229041622277755
0.0333073025945076,58.4725595236747,0.10575068573756162,11.788067999972819,60.42012275720509,0.03276463146811811
0.0337829508539512,58.3728771865875,0.10726086896129505,11.767972040816042,60.34488522778571,0.033224841918092315
0.0342887336065799,58.2742280173537,0.10886672920089117,11.748084368298505,60.27237749796983,0.03371397657093177
0.0347911760894515,58.176274977443,0.11046198408400851,11.72833703545251,60.20029600441157,0.03419964412818096
0.0353026059316435,58.0791805088523,0.1120857738329681,11.708762790584624,60.129526931189105,0.034693756865525664
0.0357990937516984,57.9618439813565,0.11366212266164243,11.68510774664147,60.0368254680664,0.03517320008131871
0.0363203250627813,57.8529001614012,0.11531703207433062,11.663144672538483,59.95413630108792,0.035676290122697484
0.0368302566709295,57.7482056899631,0.11693606493020114,11.642038267096561,59.875086927810074,0.03616822893594627
0.0373499250474862,57.641313471966,0.11858601202576868,11.620488795948345,59.79421220978259,0.03666931210317579
0.0378392410100252,57.5314280945441,0.12013959020683,11.598335903860091,59.708373667864485,0.037140898963410815
0.0383475790537743,57.4205666304548,0.12175356349573338,11.57598623269969,59.62250634862868,0.03763058327215856
0.0388533804382103,57.3173977468042,0.12335948289131769,11.555187385755726,59.544372407188995,0.03811758612291444
0.039376105590894,57.1855693201524,0.12501913525108846,11.528610774942724,59.437314335978115,0.038620634671903985
0.0398908404000008,57.0620844992925,0.12665341827000254,11.503716235057368,59.33833900494515,0.03911574649062863
0.0404185331908353,56.9506781605447,0.12832884288090207,11.481256717165811,59.252541036017256,0.03962306795814813
0.0409353275155108,56.8429937214567,0.1299696648617468,11.45954753424567,59.16988028640666,0.04011966235764207
0.0414791824250955,56.7297453900872,0.1316964041996782,11.436716670641582,59.08284884805185,0.040641993449125995
0.0420155109986671,56.5982643832941,0.13339924742076803,11.41021009967209,58.97626938299586,0.04115682901564873
0.0425441019475088,56.5023522416117,0.13507752368334044,11.39087421190892,58.906194075652884,0.04166397782241671
0.0430773021175095,56.4343611500499,0.13677043422309265,11.377167207850063,58.86540117511924,0.04217528843763962
0.0436048341542283,56.3364944492615,0.13844534843967485,11.35743728097112,58.793037946552154,0.04268090646042099
0.0441298291797186,56.2313954606588,0.14011220764560653,11.336249324868815,58.712877336874875,0.043183839180537725
0.044698165164879,56.1226022505652,0.14191667439849082,11.314316613713945,58.631179595443776,0.043728006532491814
0.0452404336465708,56.0235456947934,0.1436383768278623,11.294346812070348,58.55807519644433,0.04424693899698545
0.0457759881635939,55.944236698503,0.14533876241941063,11.278358118418206,58.50513941543497,0.044759182251651056
0.0463254380230075,55.8411234613516,0.1470832657230488,11.257570489808485,58.42798796539556,0.04528444347003078
0.0468730923983538,55.7370036061106,0.1488220683647733,11.236579926991897,58.3495693261472,0.0458077138429869
0.0474054357942925,55.6471420540171,0.1505122586468787,11.218463838089846,58.28511907379469,0.046316092647656674
0.0479657166752624,55.5546248485114,0.1522911504439581,11.199812369459899,58.2193422439956,0.046850872267641855
0.0484806937884575,55.4658954092923,0.15392620277835256,11.181924514513328,58.15492050033281,0.04734215801764488
0.0490194612660397,55.3301281228899,0.15563678951967602,11.154553829574605,58.04238119525492,0.047855881449924885
0.0495669410099217,55.1919833833313,0.15737503770650138,11.12670385007959,57.92768116791346,0.048377641960436625
0.0501119056379697,55.0738551183468,0.1591053004005538,11.102889191858715,57.83371094915661,0.04889673528859497
0.0506547672330251,54.9849624472473,0.1608288859648547,11.084968429365055,57.77021292132923,0.049413557660302615
0.0512057188197203,54.8494634472548,0.16257815725261196,11.057651830966568,57.65806964994746,0.04993780901092251
0.0517514048731976,54.7389473396545,0.16431071047240237,11.035371783674348,57.5717647657616,0.05045677923582788
0.0523147181369383,54.6278000182733,0.1660992300847791,11.012964483683898,57.4856379786703,0.05099223130269909
0.052879449330335,54.5532678193574,0.1678922516238136,10.997938792382453,57.438014580815306,0.051528743531043725
0.0534395862622188,54.492388614769,0.16967068638254468,10.985665544737431,57.404439316782295,0.05206060687712071
0.0539999054261221,54.4119156684558,0.17144969972793764,10.969442198760689,57.35015396860655,0.052592360390629755
0.05458189678416,54.3065512789367,0.173297522289708,10.948200737833641,57.27070585554732,0.053144382012183015
0.0551739408370274,54.2431665471953,0.175177262157562,10.935422375914573,57.23597580908327,0.053705626169303806
0.0557703593604598,54.168811346704,0.17707089096945985,10.920432367495525,57.18982542163862,0.05427069890878505
0.0563392427770941,54.0130167046767,0.17887709581727376,10.889024167662823,57.056069165924725,0.0548093863233164
0.0569099573485057,53.9115448135722,0.18068911458150558,10.868567434416155,56.979648529504644,0.055349516266583555
0.0574759189449515,53.8172476454938,0.182486042650221,10.84955712533155,56.91044340900658,0.05588485999575619
0.0580682131905272,53.727009093204,0.18436657687992383,10.831365033189927,56.846840511317566,0.056444805072821104
0.0586473376508251,53.6377301528648,0.1862052970413697,10.813366398817543,56.78344022396371,0.056991996663602225
0.0592317091175059,53.5396364330588,0.18806067644808122,10.793590704904656,56.71088060451876,0.05754384260815929
0.0598083237354841,53.440048430651,0.189891427860162,10.773513763619242,56.636208147631315,0.058088065108225596
0.0604103626112893,53.4016752366753,0.1918029012908435,10.765777727713742,56.627689801773165,0.05865596774568706
0.0610202464452785,53.3232825215737,0.19373928246375924,10.74997375634926,56.57708236231134,0.05923094186757217
0.0616502629742399,53.2374645452387,0.19573958494321167,10.732672852320123,56.51956823453444,0.05982454934896468
0.062257408195257,53.1604907836278,0.19766727101994097,10.717154941979366,56.47012515820431,0.0603962740484859
0.0628688791672896,53.0603655797173,0.19960869135614448,10.696969700871007,56.39621129192076,0.060971741956010815
0.0634757136304278,52.9859790256799,0.20153539077660823,10.681973371577069,56.34930185674182,0.06154251913076281
0.0640870533816926,52.863188593175,0.203476394486874,10.657218820384081,56.25103458247229,0.062117204660674226
0.0646925715505196,52.7504453198786,0.20539891467289975,10.634489776487525,56.16300727805662,0.06268609227878705
0.0652838427281995,52.6233666733555,0.2072762006620334,10.608870721348469,56.05882226708721,0.06324128264512517
0.0658593529638651,52.5214117925608,0.20910344566027167,10.588316617380258,55.98043798996757,0.0637813779806417
0.0664517836449358,52.4021891195576,0.21098441307267116,10.564281326502812,55.88440805345145,0.06433704801035099
0.0670444392581989,52.3160403592816,0.2128660946447815,10.54691373643117,55.82353994937893,0.06489262024164429
0.0676307089198394,52.2018965255001,0.21472750082049008,10.523902339540822,55.73234779447977,0.06544190257800471
0.0682270879298223,52.1331961989941,0.21662100417718577,10.51005235371721,55.69009236012555,0.06600034708340348
0.068832717487327,52.0650516281973,0.21854387802226322,10.496314408244578,55.648830617884094,0.06656713475325013
0.0694564316700389,52.0195284877508,0.2205241705523735,10.487136943130562,55.63261931366791,0.06715051160913221
0.0700963181498208,51.9246351186948,0.22255581012568101,10.468006439928873,55.564360861788195,0.06774866138498058
0.0707255172774856,51.8429386103212,0.22455351735601678,10.451536423840754,55.509557260721095,0.0683364722297406
0.0713590631566348,51.7563752739538,0.2265650255223155,10.434085255229085,55.44966172588636,0.0689279949953765
0.0720065937761175,51.6847046462895,0.22862093523917304,10.419636456691963,55.40634417819347,0.06953221354025074
0.0726448431695115,51.5814425563647,0.23064737706319902,10.398818819363123,55.328568361328976,0.07012741460765168
0.0732844898053954,51.4657799858276,0.23267825513213036,10.375501245142846,55.237423414525715,0.07072356346027127
0.0739444206989631,51.3783515333897,0.23477353571920784,10.357875669131364,55.177493973993876,0.07133824493285928
0.0745740481332488,51.2846056396396,0.23677260282306495,10.338976496951343,55.10910628910477,0.07192434876342313
0.075222452041162,51.1801047703034,0.23883128523068933,10.317909121693164,55.02999774684919,0.0725275723034393
0.0758762624202709,51.0820721133418,0.2409071331843601,10.298145738049707,54.95798882198493,0.07313545737616677
0.0765269902981853,50.9764348109512,0.24297319419673832,10.276849257887761,54.877507943164936,0.07374010977754028
0.0771688391812783,50.8821556973569,0.2450110644005586,10.25784258858715,54.808672587563,0.07433615392946731
0.0778106022915628,50.822758927115,0.24704866227571184,10.245868199706383,54.77730840935271,0.07493176344379099
0.0784402600302282,50.7105952188786,0.24904782559597455,10.223255996125927,54.688347494135094,0.07551579359312628
0.0791087256284832,50.6106572335204,0.25117020387043415,10.203108498277713,54.61440183048418,0.07613544637884515
0.0797376365446159,50.524681618971,0.25316699602915543,10.185775814384554,54.55340031843694,0.07671808249871301
0.080370199624402,50.4158412254176,0.25517538380747634,10.16383359104419,54.467772448936564,0.07730375983136846
0.0809719454330245,50.3235002123326,0.25708592674985276,10.145217642806251,54.39829192552438,0.07786058589941737
0.0816279167912849,50.245406492384,0.2591686358123295,10.129473948864614,54.3468343526886,0.07846723661630355
0.082275649200256,50.1496252940717,0.26122518621081275,10.110164459284855,54.27571827229103,0.07906590694385157
0.0829104328482952,50.0570137700065,0.2632406242933373,10.09149397603331,54.20726244877081,0.0796522617809617
0.0835719382742259,49.9604862444571,0.26534090402066723,10.072034026882552,54.13578091702919,0.08026293413657876
0.0842428456743089,49.8777324203577,0.2674710350159307,10.055350855944113,54.07957453523037,0.08088190530189311
0.0848981092224767,49.8007087832344,0.26955149678136353,10.039822890700055,54.02869479687019,0.08148607403202619
0.0855882584010032,49.7127471109523,0.27174272042318515,10.022089817567984,53.96757455650821,0.08212201371087458
0.0862422874888008,49.6296647274821,0.2738192627769425,10.005340409060393,53.909840540882406,0.08272429744687387
0.0869106473074825,49.5480735637993,0.2759413052012569,9.98889163046194,53.85432871006786,0.083339403571301
0.0875829793772223,49.4795172862845,0.27807595952268077,9.975070684914956,53.813080828364065,0.08395778394539244
0.0882871814201881,49.4190544148757,0.2803118010090972,9.962881370038941,53.78212343761598,0.08460506711535384
0.0889589533313501,49.3435597346357,0.28244467682703656,9.947661642502556,53.73311116227185,0.08522215116640074
0.0896336991709458,49.2710073549834,0.2845869948677529,9.933035082764654,53.68735000608944,0.08584158395517429
0.0903095364629366,49.1817667965431,0.2867327782698237,9.91504418618309,53.62334935836716,0.08646163433318071
0.0909794577992278,49.1018129972486,0.28885977851254824,9.89892550024532,53.56906932069735,0.0870758778920273
0.0916379485259607,49.0090428677645,0.2909504865699252,9.880223042141322,53.5001310153873,0.0876792733793019
0.0923308259401369,48.9271313175891,0.29315037235993463,9.863709673625962,53.444613763023646,0.08831378559900348
0.0929568178994394,48.8515226361779,0.29513789683072006,9.848466963453465,53.392604729979425,0.08888670054517962
0.0936089585233415,48.748802712739,0.2972084433116092,9.827758626888183,53.312127363938345,0.0894831981674058
0.0942793185225984,48.6610385113768,0.2993368363092499,9.810065363893564,53.24876806083132,0.0900959899879638
0.0949669261933227,48.5835678323309,0.30151999066379953,9.794447274997909,53.19739993287216,0.09072415842264285
0.0956513943082691,48.5036151453215,0.3036931769287544,9.778328813296815,53.143053562963175,0.09134906704393465
0.096359013571105,48.4346834796178,0.30593986808825835,9.764432189490948,53.10180180234247,0.09199470201434622
0.0970356907653955,48.3239777354539,0.3080883181801307,9.742113911467507,53.013128295545265,0.09261171564570095
0.0977096090329093,48.2257648882929,0.310228008679487,9.722314201479849,52.937885520841,0.09322583546065712
0.0984225820190889,48.1454335890796,0.31249169791060727,9.706119411558447,52.88403147534539,0.09387513427257117
0.0991173167578565,48.0677542679016,0.31469748070619435,9.690459260408963,52.83210109351201,0.09450741836652506
0.0997971806866635,47.9896060137389,0.3168560486801566,9.674704572369762,52.778833396173795,0.09512578161008056
0.100481144205461,47.8962248044479,0.31902763285233865,9.655878920576695,52.7088922759208,0.09574748799430478
0.101154132422247,47.8080629530731,0.3211643704406342,9.638105491339536,52.64404608387937,0.09635884105981136
0.101836771280248,47.7460511520081,0.3233317488147874,9.625603912244832,52.60835484271017,0.096978579324461
0.102523641383322,47.6793822934864,0.3255125613920473,9.612163470366857,52.56764618512211,0.09760177154054143
0.103200401290568,47.5945194638414,0.32766127409755336,9.595055123910427,52.50629297174159,0.09821541124831022
0.103895287183854,47.5010723879234,0.32986753680873643,9.576216193405358,52.43620994520774,0.0988450947911444
0.104595317984559,47.4157932250988,0.3320901346009748,9.55902391417992,52.375263194968106,0.09947903982356696
0.105299750347904,47.3246849141568,0.3343267073545952,9.540656478694011,52.307962420910734,0.10011656546657025
0.106013904951731,47.2378302719122,0.33659414822174594,9.5231465828175,52.24569712048471,0.10076247531020022
0.106719150793419,47.1582851165215,0.3388333037691053,9.507110279490734,52.1909772570306,0.10139991855147815
0.107428940397731,47.0697393977984,0.3410868857627959,9.489259462596157,52.12639162610122,0.10204105870958206
0.108137709020939,46.9940786001844,0.3433372261414813,9.474006245797176,52.07591059755828,0.10268086672219319
0.108835622142269,46.9000444311313,0.34555310030170405,9.45504895731607,52.004439945293534,0.10331047568913435
0.109537669991889,46.8054561183765,0.34778210222424755,9.435979953464702,51.93241672449107,0.103943415037572
0.110246930141017,46.739139322295,0.3500340031977289,9.422610487374673,51.89198595001132,0.1045824501702798
0.110944425146687,46.6487447115581,0.3522485498407312,9.404386933850114,51.82416287739647,0.10521048703611365
0.111656428618314,46.5702466356457,0.35450916086314693,9.388561721746173,51.77011405485595,0.10585118101837025
0.11235886474543,46.4811125503014,0.3567393955667402,9.370592290140761,51.70367758855782,0.10648286386027275
0.113077353100683,46.3879839587072,0.35902059609466846,9.351817566075372,51.63341440043476,0.10712856951964424
0.113802059497675,46.3279208006807,0.3613215389051181,9.33970883341723,51.60013360004334,0.1077794412448721
0.114526949805715,46.2604312691356,0.3636230656331451,9.326102943857737,51.55849735908663,0.10843005462430039
0.115238241575816,46.1724408063993,0.36588141700321575,9.3083640665701,51.49327169419221,0.1090680516627125
0.115960961953082,46.0932715550399,0.36817605420103533,9.292403545496043,51.43829166412695,0.10971588301851358
0.116672052089949,45.9954806508446,0.3704337653855881,9.272688899210271,51.361867765242174,0.1103528799243543
0.117395198927668,45.903027877279,0.3727297565953459,9.254050420059446,51.29182296631446,0.11100026138759879
0.11812602803595,45.8158900859152,0.37505013901414125,9.236483441320503,51.22793920269602,0.11165409470888667
0.118824403815129,45.7218404093499,0.37726748211303457,9.21752302652494,51.154710837321375,0.11227849459895578
0.119533284483445,45.6130019340854,0.37951817823493783,9.195581189911618,51.065273870416355,0.1129118881765071
0.120243883951135,45.5125077255357,0.38177433154485363,9.175321557467997,50.98510842281015,0.11354641512994404
0.120930117318037,45.4269869711455,0.3839531224847675,9.158080573382934,50.92047783497107,0.1141588025554266
0.121646667699892,45.336190422456,0.3862281699471571,9.13977598916713,50.85118691355553,0.11479784458157
0.122362550840849,45.2578926868369,0.3885010989196956,9.123991165666318,50.79576388167967,0.11543588399720893
0.123059421844613,45.1802753957079,0.3907136643566463,9.108343519774714,50.74013396468411,0.11605658784229013
0.123783897865781,45.0821405697104,0.39301387572385466,9.088559538853616,50.662583653562216,0.11670147130160403
0.124502614824546,45.0023632852382,0.3952958020679335,9.07247643830402,50.6052751875345,0.11734081773649158
0.125230071220648,44.9123116452192,0.39760547612555736,9.054322027676191,50.536683631233934,0.11798752249921095
0.125982693872926,44.8300942327388,0.39999505304654,9.037746997320143,50.47791027075636,0.11865616003715307
0.126727024164542,44.7442610712931,0.4023583017224209,9.02044303197269,50.41456812529944,0.1193169911355794
0.127451215879055,44.6448163279928,0.4046576104159996,9.000394971723349,50.33485245169257,0.11995952394559731
0.128205608440683,44.5612210520931,0.40705280679916844,8.98354216410197,50.27421950993647,0.12062841345185686
0.128957262118068,44.4543038963398,0.4094393072248658,8.961987665502104,50.18700921617634,0.12129442981689081
0.129694129735163,44.36763487676,0.41177886190914254,8.944515191154816,50.121856670508855,0.12194691443306094
0.130419280109004,44.2970066859923,0.4140812143460877,8.930276547896048,50.074190408963155,0.12258860824857085
0.131151994764944,44.1857931594628,0.41640758337869715,8.9078559009477,49.98084807259756,0.1232365778170891
0.131853875703022,44.087562564099,0.41863605535709486,8.888052612922358,49.90067855847492,0.12385688638079508
0.132629742001802,43.9968856102467,0.4210994308557213,8.869772139025734,49.83218119761651,0.1245421342872702
0.133351663867494,43.9073746697867,0.4233915327792934,8.851726733428999,49.76249613805622,0.12517931682393835
0.134065321045763,43.8175813862113,0.4256573943202975,8.8336244074602,49.69199950220257,0.12580880597973396
0.134806591831043,43.7312006258144,0.4280109290635615,8.816210046164183,49.62645473886002,0.1264622327399207
0.135534615233666,43.6238989417897,0.43032240336688954,8.794578026664803,49.53644729985749,0.12710356667273323
0.136249490613724,43.5456360577729,0.43259213269857366,8.778800229247018,49.47870678909507,0.12773291820469765
0.136999676109468,43.4627305115266,0.4349739716475609,8.762086471123764,49.41711051443884,0.12839292990421422
0.13767976603216,43.3888234652432,0.437133257152108,8.747186810593028,49.36258652834858,0.12899089542881248
0.138412761775298,43.2811236798437,0.4394605186365711,8.725474533856492,49.271783541109116,0.12963497800412307
0.139170580871249,43.2121109462822,0.44186659426621555,8.711561566770493,49.225965527349146,0.13030043696646001
0.139898652108128,43.1038859527158,0.44417822044330635,8.689743408067505,49.134061498123216,0.1309393567948805
0.140647941954369,43.0032166801506,0.4465572157051215,8.669448482718362,49.05153060363157,0.1315964710806869
0.141404744384794,42.8994818206632,0.4489600634217209,8.648535535045701,48.96567208175419,0.13225973574823793
0.14213724328278,42.792001236045,0.45128574742282646,8.626867449186673,48.87433832628976,0.13290128201895748
0.142902143787998,42.6865090949306,0.45371430652689365,8.60560023353801,48.786502755422056,0.13357076766381387
0.143644537575768,42.592959704896,0.4560714068030634,8.586740676507034,48.71120570568911,0.13422012577218542
0.144381052991879,42.4976579982176,0.4584098432492158,8.567527852440668,48.633514609689,0.13486392577563502
0.145098546664467,42.4060372462082,0.4606878856596827,8.549057108835573,48.55909162043226,0.1354907002585214
0.14582412215658,42.3113403647476,0.46299158784714145,8.529966217533117,48.48135443070519,0.13612413544710167
0.146568413121277,42.2020636491214,0.46535471166005443,8.507936031662874,48.38755314861625,0.13677349281447795
0.147336913078012,42.1026625589845,0.46779469902268805,8.487896771891275,48.305938892790465,0.13744352917274366
0.148083134510012,41.9993457897649,0.4701639520692881,8.467068111216603,48.21874056168316,0.13809371209597124
0.148816951773152,41.8875338215673,0.4724938218797575,8.444526818427969,48.12110892218775,0.13873267527289718
0.149559082201762,41.7681009105447,0.47485008599059436,8.420449143565813,48.01489974803635,0.13937846207490992
0.150337378217842,41.6745424126676,0.4773211758416483,8.401587750393789,47.9397838574163,0.14005527171324242
0.151115527704474,41.5751446755063,0.47979180046170494,8.38154916658207,47.857794602535286,0.14073149629666307
0.151899134220946,41.4900146878566,0.4822797511515035,8.364386961071892,47.79231199775635,0.14141200134047954
0.152657459426651,41.3933419849109,0.48468743367961686,8.344897744158038,47.712344409505924,0.1420701107877937
0.153425614341569,41.2895375672994,0.4871263255344816,8.32397077356756,47.624410234441605,0.14273630963558556
0.154203395351804,41.1879424059806,0.48959578024197764,8.303489189045688,47.53926297253736,0.14341040502649988
0.154987857137582,41.086224296849,0.49208644641182286,8.282982818244758,47.45409015849168,0.14408983061769692
0.155751786110747,40.9649167500527,0.4945119209016217,8.258527216810625,47.34527570175146,0.14475102929771996
0.156516984404523,40.8578142940361,0.4969414254843605,8.236935361677679,47.252756176698654,0.14541288862088084
0.157263423612949,40.7295523534002,0.4993113699711131,8.211077754445482,47.13482119871877,0.14605810044109904
0.158020499409184,40.6160691364164,0.5017150856241592,8.188199537901546,47.03424066539087,0.14671208142001038
0.158778411936574,40.4805499863301,0.5041214578986224,8.160878877244148,46.907987427478695,0.14736635706794463
0.159539306484767,40.3635504973645,0.5065372980891352,8.137291780268683,46.803123350976904,0.14802277665139385
0.160277999746443,40.2371174598492,0.5088826491949565,8.1118028799056,46.68624216187651,0.1486596313594423
0.161048024561152,40.1058981947154,0.5113274779816576,8.085349076054625,46.56487387222499,0.14932306668467407
0.161801199248365,39.9684243082022,0.5137188076135588,8.057634340533564,46.43536329333682,0.1499715588088188
0.162553971484608,39.8513149770449,0.5161088594636304,8.034025099372252,46.32930449544759,0.15061928448520442
0.163317038883228,39.7259590668278,0.5185315984542488,8.008753347872485,46.213885068418435,0.15127544075749647
0.164068948556182,39.6077110458054,0.5209189116658779,7.98491454683437,46.10610655180777,0.15192158170976827
0.164816696526003,39.4832045829458,0.5232930114700595,7.959814043921875,45.99069593056727,0.1525637326003412
0.165578114717897,39.375823910553,0.5257105142293229,7.938166100367486,45.89559859912626,0.15321719974274578
0.16633245806794,39.2448399662756,0.5281055543657095,7.9117597372011605,45.77253066434915,0.1538641742752677
0.167089345704776,39.1261900073006,0.5305086726126638,7.887839905471801,45.6637594955412,0.15451291053217375
0.167863380657035,38.9925085296558,0.5329662335860861,7.860889719578609,45.537922831742094,0.15517590894912098
0.168648193283658,38.8489129156622,0.5354580136756141,7.8319408437975,45.400711889922796,0.15584769047581332
0.169438178984545,38.7147289430363,0.5379662182759304,7.804889354916118,45.274482115024625,0.15652344457995473
0.170196226748096,38.571961046539,0.5403730199252048,7.776107346982264,45.13676327493448,0.15717144991636095
0.170968913478535,38.427500961278,0.5428263002943485,7.7469841937936454,44.99740904832306,0.15783153727646929
0.171757007679996,38.2966820382094,0.5453284993839872,7.720611098903015,44.87440554916449,0.15850433832764768
0.172561414508109,38.1573127532658,0.547882491063246,7.692514251058385,44.74179261579765,0.15919059907795316
0.17335114443727,38.0186349711838,0.5503898835883323,7.664556810190654,44.609208853381325,0.15986388074481003
0.174090221772898,37.8881044684989,0.5527364541289511,7.638241860849379,44.4840529779746,0.1604935683448389
0.174851136802422,37.7310574739571,0.5551523593476898,7.606581186749752,44.32837576603602,0.16114144748695725
0.175628860571628,37.5815027195607,0.5576216323149188,7.576430948263439,44.18189922076669,0.16180320491391426
0.176396876792137,37.4229536241808,0.5600600838150349,7.5444674506348495,44.02424576382328,0.16245627280820207
0.17714175183433,37.2656181931352,0.5624250620739978,7.512748627736056,43.86691508305645,0.16308925588993575
0.177893945812603,37.1073772007507,0.5648132779550146,7.480847243671341,43.70855494974886,0.1637280521549799
0.178613414153043,36.9492199843965,0.5670975899359114,7.448962748854334,43.548846316101404,0.16433867478660663
0.179374085015433,36.776430817674,0.5695127199239998,7.4141284528430775,43.37316944572765,0.16498386131880427
0.180116066537517,36.6192161098708,0.5718685112566164,7.382433967749953,43.214925275268,0.16561279511287297
0.180881243756039,36.4590616484517,0.5742979489254239,7.350146828327864,43.05382206560174,0.16626097649112023
0.181616560096485,36.2975240523488,0.5766325783063398,7.317580848953518,42.88975551075581,0.16688346711353788
0.182381724147436,36.1369797913937,0.5790619741681092,7.285215125944969,42.72770447122913,0.16753081451879742
0.183102141920689,35.9905120474992,0.5813493005981876,7.255687228775839,42.58045189221867,0.16813992270664935
0.183865041013489,35.8365378294331,0.5837715052178275,7.224646026413713,42.42562432722327,0.1687845443344591
0.18465661114327,35.684918045056,0.5862847403798822,7.194079477883291,42.27437408018136,0.16945295296693325
0.185453733558049,35.5378086899324,0.5888156040468056,7.164422231890371,42.12842799395204,0.170125598817888
0.18624066898073,35.3548494000685,0.5913141240138177,7.12753763905381,41.939360204050224,0.1707892049306464
0.187055313504922,35.1780514930697,0.5939006203781273,7.091895181002853,41.75829294359814,0.1714757139562366
0.187832121724767,35.0096957016417,0.5963669864761352,7.057954653450967,41.58564112621951,0.17212989927552796
0.188648686525843,34.8203217825329,0.5989595797195515,7.0197768713586335,41.38912975121493,0.17281710434815167
0.189452694546876,34.6251339004176,0.6015123051863313,6.980426994324189,41.184958816898096,0.17349328077869897
0.190212962337599,34.4298876475103,0.6039261554218768,6.941065349738076,40.97889856989394,0.17413225105957902
0.19097829463196,34.2285182324361,0.606356085456473,6.900469275659118,40.7654222722457,0.1747750657167172
0.191729620680149,34.0437964058008,0.608741545659473,6.863229355409441,40.57100057719721,0.1754057146252654
0.192475021529267,33.8372287339885,0.6111081933554227,6.821585312772083,40.35005006305367,0.17603099725428795
0.19321765581828,33.6212873352252,0.6134660572230389,6.778051526781399,40.11751365973023,0.17665357058072786
0.193942408561684,33.3680354584372,0.6157671471833466,6.72699594842094,39.83951262421818,0.1772607797716712
0.194648848551093,33.1547722328312,0.6180100941497202,6.68400208213877,39.60831047192554,0.1778522916160717
0.195336223347819,32.940695684956,0.6201925091293253,6.64084425008713,39.3752067745051,0.1784275042596659
0.196064646398318,32.7264614988664,0.6225052523146596,6.597654638171466,39.14296360050981,0.17903670624018064
0.196794589437176,32.5001461224921,0.6248228214630338,6.552029458294406,38.89599903531616,0.17964680736988212
0.19749413177868,32.2862349021072,0.627043868397309,6.5089049562648125,38.66257683250138,0.18023114989733965
0.198208514996725,32.0716962883993,0.6293120351146019,6.465653971741299,38.4285795831489,0.18082753713277616
0.198931153378191,31.8822972542135,0.6316064119757564,6.427471126449442,38.224679419340525,0.181430454361914
0.199681829972712,31.6485836338517,0.6339898101633605,6.380354460584503,37.96823072990363,0.18205637994827573