File: example/data/02 processed data/test_ID_100.csv
Strain,Stress_MPa,Displacement(mm),Force(kN),True Stress (MPa),True Strain
0.0012959178912095044,76.786453171376,0.004114539304590176,30.960297918698803,76.8859621098433,0.0012950789143709928
0.0013854220423149045,82.9934292318019,0.004398714984349822,33.46295066626253,83.10841015802693,0.001384463230667539
0.0014854329577069045,89.1364168568723,0.004716249640719422,35.93980327669092,89.26882302820341,0.0014843307934967514
0.0015803686395505045,95.3088841647658,0.005017670430572852,38.428542095233574,95.45950733637035,0.0015791211711658048
0.0016996595558551044,101.47332418161,0.005396419089839956,40.914044310025155,101.64579428671966,0.001698216769151715
0.0017965016649894045,107.646446000521,0.005703892786341359,43.40304702741007,107.83983301999113,0.0017948898859603925
0.0018956309290599045,113.780391645382,0.006018628199765196,45.876253911418026,113.99607727490553,0.0018938364881242171
0.0020180044331498045,119.819653538523,0.006407164075250629,48.31128430673248,120.0614501305422,0.0020159709973989483
0.0021131206271104044,125.830816706347,0.006709157991075534,50.7349852959991,126.09671240065532,0.002110891127965941
0.0022082914934992044,131.781968664282,0.007011325491859973,53.1344897654385,132.0729816646799,0.0022058568015198682
0.0022897968185523043,137.672564153408,0.007270104898903566,55.5095778666541,137.9878063528084,0.0022871792288878937
0.0023878878908916044,143.515838234279,0.007581544053580844,57.86558597606128,143.8585379665498,0.0023850414170749003
0.0024856808768476046,149.277186471946,0.007892036783991144,60.188561585488635,149.64824191970894,0.0024825966819624406
0.0025849348177329045,154.923301127701,0.008207168046301972,62.46507501468905,155.32376776286412,0.002581599620003072
0.0026851762303530045,160.511187856003,0.00852543453137079,64.71811094354041,160.94218868233966,0.002681577585217155
0.0027876770774691046,166.061810152352,0.008850874720964406,66.95612185342833,166.52473685395674,0.002783798711807065
0.0028835069318170043,171.561594134149,0.009155134508518988,69.17363475488888,172.0562931800684,0.0028793576002079276
0.0029868656894760045,176.979439785403,0.009483298564086313,71.3581101214745,177.50805360184071,0.0029824138686102646
0.0030715733049454046,182.218888908407,0.00975224524320166,73.4706560078697,182.77858758323487,0.0030668656611134884
0.0031827314575899046,187.35248471866,0.010105172377847946,75.54052183856372,187.9487773654317,0.0031776772890256435
0.0032721328029683043,192.389881431368,0.010389021649424365,77.57160019312758,193.01940667335876,0.003266791025925579
0.0033672185731918043,197.379186817884,0.010690918969883978,79.58328812497084,198.0438056816987,0.0033615621867019337
0.0034876684446137046,202.276350264213,0.011073347311648512,81.55782442653069,202.98182310812112,0.003481600633273835
0.0035987568626414043,207.047005612567,0.011426053038886459,83.481352662987,207.7921174449046,0.0035922968312456695
0.0037132581914685043,211.633421117396,0.0117895947579125,85.33059539453407,212.4192706519487,0.0037063810673709317
0.0038434647800736047,216.052396287901,0.012203000676733694,87.11232618328168,216.88278606368405,0.0038360975404326952
0.003955851218735304,220.351356695805,0.01255982761948459,88.84566701974857,221.22303387874007,0.003948047412995626
0.0040889299929663045,224.470618790587,0.012982352727668015,90.50655349636469,225.38846343629953,0.004080593037148097
0.004223634819242804,228.364984690062,0.013410040551095903,92.076761827033,229.32951499089478,0.004214740309677993
0.004397284789769904,231.922051205763,0.013961379207519446,93.51097104616365,232.94187851394236,0.004387644981997724
0.004612602394679905,234.932417265858,0.014645012603108696,94.72475064159394,236.01606709632645,0.004601996944233402
0.004876615645067304,237.252712971867,0.01548325467308869,95.66029387025678,238.40970326378024,0.004864763471703414
0.005174716717470904,238.831986233911,0.01642972557797012,96.29705684951293,240.06787410574242,0.005161373881387663
0.005524167749157904,239.729123690601,0.017539232603576344,96.65878267205034,241.0534275842265,0.005508965495333505
0.005875769330329805,240.233036530405,0.01865556762379713,96.8619603290593,241.64459043858233,0.005858574320780246
0.006230839108401104,240.526691760635,0.019782914169173504,96.98036211788803,242.02537487827152,0.0062115076894874045
0.006613799127760904,240.750195448052,0.02099881223064087,97.07047880465458,242.3424688807146,0.006592023916826309
0.006999928967043104,240.927194008231,0.022224774470361856,97.14184462411873,242.61366725251762,0.006975543197240078
0.007390341983088704,241.079109252697,0.023464335796306635,97.20309685068743,242.86076631505284,0.007363167210882603
0.0077764045744463045,241.211249802772,0.024690084523867017,97.25637592047767,243.08700606914618,0.007746324184607267
0.008164953634524606,241.307463180793,0.02592372778961562,97.29516915449574,243.2777274293289,0.008131800739574722
0.008550501652352504,241.498996987112,0.0271478427462192,97.37239558520356,243.5639345598918,0.008514153164667125
0.008928896380951805,241.612861614225,0.02834924600952198,97.41830580285553,243.77019781988366,0.008889269493889683
0.009311881566901605,241.797525881878,0.029565223974912593,97.49276243557321,244.04911580605986,0.009268793279883421
0.009675635426814905,241.897002186973,0.03072014248013732,97.53287128178752,244.23750939097357,0.009629126229728219
0.010048305481270604,242.035591082463,0.03190336990303416,97.58875032444908,244.46763863899946,0.00999815691866235
0.010421458833821605,242.207338514771,0.033088131797383596,97.65799888915568,244.73149232235218,0.010367529787669565
0.010800007353934105,242.367415810157,0.03429002334874078,97.72254205465532,244.9849856832607,0.01074210380726224
0.011182282947739104,242.604258026955,0.035503748359071656,97.81803683646825,245.3171274845387,0.011120223437877398
0.011560210994716205,242.785874543928,0.03670366990822395,97.89126461611177,245.5925304801925,0.01149390229468354
0.011930828616843605,242.954179283179,0.037880380858478446,97.95912508697779,245.8528239579525,0.011860217360099297
0.012309551346574705,243.056647283242,0.03908282552537468,98.00044018460318,246.04856556310136,0.01223440487053415
0.012682004940341204,243.193703483098,0.040265365685583324,98.0557012443851,246.2778872321305,0.012602261809798928
0.013059797435810405,243.379863420538,0.04146485685869803,98.13076093116092,246.5583551367654,0.012975253569564305
0.013428586911392905,243.529020433191,0.042635763443672474,98.19090103866262,246.79927104952446,0.013339222573780847
0.013783384764562805,243.632845659971,0.0437622466274869,98.23276337010032,246.99093091298772,0.013689257855487719
0.014138118265287004,243.716853916338,0.04488852549228624,98.26663549906749,247.1625516202509,0.014039107200062913
0.014486113190008405,243.879362284953,0.04599340937827668,98.33215887329305,247.41222633171992,0.014382191860828484
0.014851509374585604,244.019854942275,0.04715354226430929,98.38880551272528,247.64391810553522,0.014742305608745987
0.015220121885255705,244.24192156801,0.04832388698568686,98.47834277622164,247.9593133837642,0.015105457833569097
0.015590753478956505,244.417239393781,0.0495006422956869,98.5490309235725,248.22788831917654,0.015470466315956093
0.015952389426656104,244.549138015804,0.05064883642963312,98.60221244797218,248.45028109938517,0.0158264872577531
0.016301244507691305,244.747658819313,0.05175645131191989,98.68225603594699,248.73735024841162,0.01616980570839995
0.016653605875095907,244.862023343835,0.0528751986534295,98.72836781223428,248.93985897438176,0.01651645518845772
0.016985164351202106,244.963653205999,0.053927896815066684,98.7693449726588,249.12440111577376,0.01684252930142021
0.017331864372162505,245.111973211561,0.05502866938161595,98.8291475989014,249.3602206872569,0.017183380820059553
0.017677380238394005,245.256303682015,0.05612568225690096,98.88734164458845,249.591792618065,0.017522952613619403
0.018045429745178407,245.432484006496,0.05729423944094144,98.95837755141918,249.86141865381984,0.017884543601340848
0.018392092047840203,245.613886623272,0.05839489225189264,99.03151908650327,250.13123983427502,0.018225003156127587
0.0187440505875519,245.82257515754,0.05951236061547728,99.11566230352014,250.43028594185517,0.018570545641823463
0.019082271797330602,246.008275260442,0.06058621295652466,99.19053658501022,250.70267203335428,0.018902488760988472
0.019437160931936703,246.184303846795,0.06171298595889903,99.26151131102773,250.96942777958193,0.019250671988965923
0.019782525335078703,246.325033456619,0.06280951793887488,99.3182534897088,251.1979646716387,0.019589394107794048
0.020126035159238304,246.448113739723,0.06390016163058161,99.36787945985633,251.40813714177662,0.01992618354439825
0.0204719920836506,246.577863957924,0.06499857486559066,99.42019474783496,251.62580403687411,0.020265257603187217
0.020822017121576303,246.706359142042,0.06610990436100475,99.47200400607133,251.84328317609936,0.02060820187263366
0.021177751518048203,246.837112676718,0.06723936106980304,99.5247238312527,252.064567714418,0.02095661954195362
0.021533037156766202,246.981527263049,0.06836739297273269,99.58295179246136,252.29978966663907,0.021304476560451063
0.021872822476894302,247.144390365781,0.0694462113641394,99.64861819548291,252.55013574241198,0.021637044191749496
0.022219906060424108,247.277845381918,0.07054820174184653,99.70242725798936,252.77233587712828,0.02197664090575352
0.022542801128101003,247.41740265195,0.07157339358172068,99.75869674926624,252.9948839555642,0.0222924673527303
0.022892173888544802,247.556184430783,0.07268265209612974,99.8146535624917,253.22328365195713,0.022634079545841988
0.023255968640037303,247.669904847711,0.07383770043211843,99.86050563459708,253.4297083879304,0.02298966939563287
0.023599074732419602,247.731951219191,0.07492706227543224,99.88552273157781,253.57819604962077,0.02332492136836707
0.023931104566849708,247.821385894648,0.07598125699974782,99.92158279272208,253.75202539439445,0.02364924365743269
0.024264213536268904,247.916574002387,0.07703887797765377,99.95996263776244,253.93207469316113,0.023974514367127137
0.024575973849966404,248.032268371945,0.07802871697364333,100.00661060756823,254.12790291340178,0.024278842950706307
0.024934327819385205,248.189041401188,0.07916649082654802,100.06982149295901,254.3774683206642,0.024628540117662464
0.025279940193467708,248.336686395818,0.08026381011425997,100.12935195479382,254.61462297574823,0.024965687685844538
0.025623794525020303,248.519161534449,0.08135554761693946,100.20292593068984,254.88716546513808,0.0253010075050575
0.025955456709653803,248.633537270114,0.08240857505315081,100.24904222730997,255.08693428329656,0.025624331293132574
0.026281604468278402,248.752679922146,0.08344409418678392,100.29708054460927,255.29029946628407,0.025942177381715618
0.026625148993508402,248.8624776185,0.08453484805438917,100.3413509757792,255.4884781639862,0.026276868207645843
0.026967226164198707,249.011748535714,0.08562094307133089,100.40153700959989,255.72690467601916,0.02661001823098285
0.027309604404943205,249.168857236899,0.08670799398569468,100.46488323791768,255.97356015807048,0.02694335036891078
0.027654311535812805,249.27447165862,0.08780243912620565,100.5074669727556,256.1679855557926,0.02727883765550369
0.027996195077893506,249.351578956045,0.08888791937231187,100.53855663507736,256.3324744034792,0.027611465740027798
0.028340271036127303,249.413180225786,0.08998036053970418,100.56339426703691,256.48161735336726,0.027946115217012603
0.028675797553727102,249.52243332555,0.09104565723308354,100.60744511686177,256.67768810870683,0.02827234166288125
0.029021645169272102,249.630743186993,0.09214372341243891,100.65111565299559,256.8754380391076,0.028608491780601274
0.0293679837267055,249.74282596941,0.09324334833228996,100.69630743086611,257.0772692183411,0.02894500587476475
0.029709658341072205,249.850870010467,0.09432816523290424,100.73987078822029,257.2738539946976,0.029276877398715238
0.0300501093418533,249.938299975347,0.09540909716038423,100.77512255005992,257.4489732183231,0.02960745090463848
0.030392093570134802,249.983322840937,0.09649489708517799,100.79327576946581,257.58083937969195,0.02993940317288311
0.030728473074094403,250.013224379341,0.09756290201024972,100.80533206975029,257.69574901284915,0.030265807666040794
0.031067324449479405,250.086470633629,0.0986387551270971,100.83486495947922,257.85598815722915,0.030594503047846146
0.031409829819431606,250.154782353662,0.09972620967669535,100.86240824499652,258.0121014959075,0.030926633149158295
0.0317388931395074,250.293959753356,0.100770985717936,100.91852457255314,258.238012995432,0.031245624523075603
0.0320770709217702,250.401722304274,0.10184470017662038,100.96197443308327,258.4338761095616,0.031573345396620815
0.0324205527287275,250.464479743269,0.1029352549137098,100.98727823248606,258.584676615459,0.031906096382809265
0.0327724434443585,250.568764659196,0.10405250793583823,101.02932591058783,258.7805153279123,0.032246878788800955
0.0331052563996925,250.640595999463,0.10510918906902368,101.05828830698348,258.93811719419693,0.0325690788476314
0.0334400621652974,250.717642572559,0.10617219737481924,101.08935348525578,259.1016561261222,0.03289310345577962
0.033778680228230204,250.80770547585,0.1072473097246309,101.12566684786272,259.27965875789494,0.03322071084344221
0.0341152924028809,250.927115062922,0.10831605337914685,101.17381279337016,259.4875669651049,0.03354627122717452
0.0344464579464996,251.039615371545,0.10936750398013623,101.21917291780696,259.68704092534637,0.03386646040827296
0.034788318083243605,251.158868584181,0.11045290991429844,101.26725581314179,259.89626319391505,0.03419688220846155
0.035125308005829706,251.214973098644,0.11152285291850932,101.28987715337327,260.0389764044101,0.03452248992592005
0.035473641436517,251.285110377136,0.11262881156094148,101.31815650406122,260.1991082809901,0.03485894661548531
0.035827770402500105,251.364141968615,0.11375317102793782,101.35002204174556,260.36995873448797,0.0352008852318637
0.0361774337895304,251.432036630919,0.11486335228175902,101.37739716958653,260.52820248870086,0.035538397309190756
0.036529915116647,251.496012578936,0.11598248049535421,101.403192271827,260.6831405706197,0.03587851414305101
0.036877765052940506,251.555521516722,0.1170869040430861,101.42718627554233,260.8323269369856,0.03621404867674071
0.0372194794955788,251.594989648951,0.11817184739846269,101.44309982645706,260.9592242073805,0.03654355535404625
0.0375638673027642,251.611465666616,0.11926527868627634,101.44974295677957,261.0629653747708,0.03687553007408617
0.0379078513745763,251.67226742359,0.12035742811427974,101.4742582251915,261.2126223321861,0.03720700563394672
0.0382388579602169,251.675338565818,0.12140837402368865,101.47549650973782,261.2991160893258,0.03752587191344122
0.0385698480372456,251.760189887171,0.12245926751825477,101.50970856250736,261.4705421529473,0.03784462065411754
0.0389103402760093,251.844036470464,0.12354033037632953,101.54351550489109,261.6433736260135,0.03817241414522081
0.039251253101213,251.927045562033,0.12462272859635128,101.57698477061172,261.81549779042916,0.03850050492444431
0.0396061151594738,251.968520634144,0.1257494156313293,101.59370751968687,261.94801487894216,0.038841905991324026
0.0399537474365026,252.016305447056,0.12685314811089576,101.61297435625298,262.0853012647682,0.03917623854555309
0.0403000956620919,252.080870190056,0.1279528037271418,101.63900686063059,262.2397533732986,0.039509225050963
0.040648038767826,252.166225576649,0.12905752308784754,101.67342215250488,262.416288089825,0.03984363329806916
0.040984232652527805,252.252917237723,0.13012493867177577,101.70837623024993,262.5913094850727,0.04016664317088923
0.0413215414883817,252.275861906862,0.1311958942256119,101.71762752084676,262.7002894011636,0.040490619450447234
0.041657602846336704,252.283820170229,0.13226288903711902,101.72083629263635,262.793359355437,0.0408132932148821
0.0420069134644302,252.295105445111,0.13337195024956588,101.72538651546877,262.89324410704313,0.0411485781118812
0.0423611705720029,252.329676359712,0.1344967165661092,101.7393255082359,263.018656820364,0.041488496107840465
0.042693709614999506,252.429952177574,0.13555252802762344,101.77975671799784,263.20712325397153,0.041807470010135406
0.0430546905840964,252.541129700627,0.13669864260450607,101.82458349529281,263.4142098996457,0.04215361048677843
0.043399968309902504,252.653262480861,0.13779489938394043,101.86979543228315,263.6184060659238,0.04248458123420012
0.0437440789541441,252.72667441451,0.13888745067940753,101.89939512393043,263.7819700139166,0.04281432430853242
0.0441004739541149,252.740844975434,0.14001900480431478,101.90510869409498,263.8868360264141,0.04315572424938139
0.0444462953818845,252.738155642069,0.14111698783748328,101.90402435488222,263.9714303620091,0.04348688411231326
0.044792517706347304,252.749193690259,0.14221624371765268,101.90847489591242,264.0704664238949,0.04381831805415197
0.0451153565396986,252.728130683754,0.14324125701354304,101.89998229168961,264.1300504071631,0.04412726835755782
0.0454702470771298,252.779599164668,0.1443680344698871,101.92073438319414,264.2735499947433,0.04446678140139215
0.0458159233694533,252.836916727972,0.14546555669801423,101.94384482471831,264.4208735297496,0.044797368673814925
0.0461641679485051,252.902875723536,0.14657123323650367,101.97043949172972,264.57792655309726,0.045130301653162036
0.0465320188221609,252.949945931122,0.14773915976036087,101.98941819942839,264.72021757625356,0.0454818585392211
0.046882152473215304,252.982902441216,0.14885083410245858,102.00270626429828,264.8432854465816,0.04581636822117528
0.047217571542420705,252.994609264745,0.14991578964718574,102.0074264555452,264.9404003275499,0.04613671502054431
0.047577004957682,253.042699120888,0.15105699074064036,102.02681628554205,265.08171287146774,0.046479883198293874
0.0479241232679199,253.092055852277,0.15215909137564568,102.0467169196381,265.22127073507284,0.04681118181582962
0.0482835768013367,253.133954718495,0.15330035634424402,102.06361054249719,265.3561674621716,0.04715413784726501
0.0486576179091213,253.182425737325,0.15448793686146012,102.08315405728943,265.50167947015626,0.047510887109185315
0.049002547362494604,253.160992116945,0.15558308787592037,102.07451202155224,265.56652562349177,0.04783975778346583
0.0493527274976,253.12244929167,0.15669490980488,102.05897155440134,265.61473255508685,0.048173524083721664
0.0497118363319477,253.139536542758,0.15783508035393395,102.06586113404002,265.7235677525167,0.04851568491482647
0.050063499818353605,253.166194070871,0.15895161192327267,102.0766094493752,265.84057978175133,0.048850638358310966
0.0504128168357418,253.24475922067,0.1600606934534802,102.10828691777415,266.0115408818732,0.049183245793909244
0.0507245979378442,253.294026069067,0.16105059845265532,102.12815131104783,266.1422637014782,0.0494800194386965
0.0510649286981818,253.25938242743,0.1621311486167272,102.11418299473979,266.1920547332322,0.0498038680058332
0.051413530094929,253.241227129251,0.16323795805139957,102.10686277851401,266.2612525815375,0.05013547796690925
0.0517588774071997,253.237878971648,0.16433443576785903,102.10551280136848,266.3451873042008,0.05046388405871866
0.0521501644886439,253.241291876022,0.16557677225144438,102.10688888441207,266.44786690267324,0.050835846038218516
0.052498293793424,253.291626933054,0.1666820827941212,102.12718397940739,266.58900517919983,0.05116666547420086
0.0528500030220934,253.362093017876,0.16779875959514653,102.1555959048076,266.75228039955465,0.051500775732796156
0.053213264271532106,253.415847214874,0.16895211406211444,102.1772695970372,266.9009316633133,0.05184574281776704
0.053555690716730504,253.466461209652,0.17003931802561933,102.19767715973168,267.0410326132603,0.05217081543420462
0.0539173524278099,253.48567814163,0.1711875939582964,102.2054254267052,267.1529547853946,0.05251403378834305
0.054282402463527106,253.496730454142,0.17234662782169854,102.20988171911006,267.257141999842,0.05286034825737646
0.0546508135629144,253.51888333231,0.17351633306225323,102.21881375958739,267.3738965599823,0.053209729736443945
0.0550128007194247,253.520997472683,0.17466564228417342,102.21966618098578,267.4678975848375,0.053552900237761776
0.0553582650972318,253.493615097365,0.17576249168371097,102.20862560725756,267.52658184238055,0.05388029705104141
0.0557087038844946,253.467239737875,0.17687513483327036,102.19799106231119,267.58757114085245,0.05421229863661951
0.056063212005429006,253.461879164054,0.1780006981172371,102.19582967894658,267.6717662309228,0.0545480433461661
0.0564390610400377,253.472607839639,0.1791940188021197,102.20015548094246,267.7783638254779,0.05490387637259171
0.0568041652743011,253.508048296261,0.18035322474590598,102.21444507305243,267.90836137004726,0.05524941562084272
0.0571820268016266,253.515113626059,0.18155293509516446,102.21729381402699,268.0116216480417,0.05560690284830529
0.0575427948766549,253.522025650754,0.1826983737333793,102.22008074238401,268.11039156948937,0.05594809908795785
0.0578984346454732,253.532674200594,0.1838275299993774,102.2243742376795,268.21181916828914,0.056284331328500005
0.0582549801518325,253.523113083105,0.1849595619820682,102.22051919510794,268.29209700379204,0.05662130643365063
0.058615700469940905,253.521478162529,0.18610484899206237,102.2198599951317,268.38181718920043,0.056962111684440805
0.058968723885056605,253.508176804385,0.1872256983350547,102.21449688752803,268.4572304849669,0.057295532552412924
0.0593322492699578,253.490756579137,0.188379891432116,102.20747305270805,268.53093333612054,0.057638756100980036
0.059699707295028104,253.51893942033,0.1895465706617142,102.21883637427707,268.65394589746967,0.05798557298367509
0.0600582507238104,253.534588026607,0.19068494604809802,102.22514589232794,268.76143188146693,0.0583238601271154
0.060446854803572904,253.566560298554,0.19191876400134397,102.23803711237697,268.8938613519621,0.05869038042749088
0.0607887104198093,253.557598896412,0.19300415558289452,102.23442387503331,268.9710383504681,0.059012697877566286
0.0611426489671805,253.541545881289,0.19412791047079808,102.22795129933573,269.04374761970496,0.059346298254494514
0.0615026333282944,253.502618193972,0.19527086081733472,102.21225565580951,269.0936967685185,0.059685482919561016
0.061883558513029506,253.492018656532,0.19648029827886868,102.2079819223137,269.1790068256495,0.060044273223731875
0.062266686472811604,253.508378814955,0.19769672955117684,102.21457833818987,269.2935055568566,0.06040500850113631
0.0626273345590593,253.523056494298,0.19884178722501328,102.22049637850095,269.4005297718017,0.0607444589265609
0.0629871888622618,253.549086909229,0.1999843246376812,102.23099184180114,269.5194311322346,0.06108304741725399
0.0633571545716213,253.521901617394,0.20115896576489764,102.22003073213328,269.58432792545864,0.0614310302961658
0.0637193225820255,253.495020754924,0.20230884919793096,102.20919236838536,269.64755175534424,0.06177156155378042
0.0641000460387546,253.472290922936,0.20351764617304585,102.20002770012779,269.7198764406448,0.062129414730987785
0.06446091643627841,253.45449082735,0.20466340968518393,102.19285070158753,269.79239958097133,0.06246848925818537
0.0648280460428559,253.469337206923,0.20582904618606748,102.19883676183136,269.9012590698256,0.06281332701077304
0.0651955844281763,253.454042672433,0.20699598055945975,102.19267000552497,269.97812711014615,0.06315842965067826
0.065565983178169,253.387959498119,0.20817199659068658,102.16602526964158,270.0015901881232,0.06350609760128788
0.0659239383957593,253.334481686475,0.20930850440653578,102.14446301598672,270.03528845069576,0.06384197084875891
0.0662864080768697,253.318586467374,0.21045934564406127,102.1380540636452,270.1101656634061,0.06418196515110505
0.0666530667670705,253.328027913188,0.21162348698544883,102.1418608545974,270.21311787165604,0.06452577115041913
0.0670152952529294,253.374562328324,0.21277356242805084,102.16062353078023,270.3545334323384,0.06486530703686391
0.0674013881642755,253.384280159492,0.21399940742157472,102.16454176030717,270.4627323812474,0.0652270854267694
0.0677924859972366,253.41530613994,0.21524114304122619,102.1770514356238,270.5949597329173,0.06559342015830613
0.0681717554942325,253.412174273383,0.21644532369418817,102.17578866702803,270.6877270572099,0.06594854735904719
0.0685432159497265,253.413386175261,0.2176247106403816,102.17627730586524,270.78315462842335,0.06629624039644395
0.0689028296181004,253.388422369681,0.21876648403746876,102.16621189945538,270.8476016634184,0.06663272951860232
0.0692752828141245,253.349334123942,0.21994902293484528,102.15045151877341,270.9001808961482,0.06698111321743974
0.06966170594335551,253.327174218617,0.22117591637015374,102.14151664494636,270.9743773364955,0.06734243581409982
0.070067175303665,253.286951288955,0.2224632815891364,102.12529875970665,271.03405250704907,0.06772142716082266
0.07044239898282291,253.257136580365,0.22365461677046272,102.11327746920317,271.0971768406063,0.06807202001731698
0.0708159608222413,253.209071569665,0.2248406756106161,102.09389765688893,271.14031526177854,0.06842093806496669
0.0711766601243326,253.157805616262,0.225985895894756,102.07322722447685,271.17673270443254,0.0687577266252758
0.07154073552985431,253.107231199724,0.2271418353072874,102.05283561972873,271.21470868767716,0.06909755250223346
0.0719164555258832,253.058009373594,0.22833474629467915,102.03298937943309,271.25704445017857,0.06944812633356043
0.072294981462436,253.046434256757,0.22953656614323428,102.02832229232443,271.34042153048483,0.06980119407114957
0.0726912823478512,253.068969412265,0.23079482145442756,102.03740846702526,271.4648773212917,0.07017070775672475
0.0730691366438341,253.05295931934,0.23199450884417328,102.03095319755789,271.54332058197144,0.07052289460530693
0.0734386162002119,253.04672519721,0.23316760643567278,102.02843959951508,271.63012652968837,0.07086715570526088
0.0738140851287748,252.982863492997,0.23435972028385996,102.0026905603764,271.65656211499027,0.07121687600800614
0.0741892978366208,252.931587120016,0.23555102063127104,101.98201592679045,271.6964039691521,0.07156623552451147
0.0745692773865257,252.938700848348,0.2367574557022191,101.9848841820539,271.8001569936959,0.07191990909049245
0.07495362314380791,252.942316425622,0.2379777534815901,101.9863419828108,271.90125948810993,0.07227751938744112
0.0753321422185611,252.957506182779,0.2391795515439315,101.9924664928965,272.0133370137927,0.07262958336401601
0.0757297222286742,252.95475323345,0.2404418680760406,101.99135650372705,272.110946432242,0.07299924266690413
0.0761187948249241,252.928694629119,0.241677173569134,101.98084967446079,272.18132204092876,0.0733608597578901
0.0765166978592857,252.905680253813,0.2429405157032321,101.97157027833741,272.2571877766911,0.07373054895073838
0.0768972918407359,252.86787413306,0.24414890159433647,101.95632685044981,272.3127288474164,0.07408402857633138
0.0772793851921329,252.853659987609,0.24536204798502195,101.95059570700396,272.39403537503205,0.07443877511079902
0.07766584022780461,252.802216190594,0.2465890427232796,101.92985356804752,272.43631272248757,0.07479744319688846
0.07805527163439341,252.770111097302,0.24782548743919905,101.91690879443217,272.5001507800577,0.07515874356054149
0.0784528606972556,252.717044414728,0.2490878327137865,101.89551230801834,272.5434194960188,0.0755274776834564
0.0788656163649543,252.690056997941,0.2503983319587299,101.88463098156983,272.61861409237906,0.07591013390888057
0.0792649109006669,252.694010007986,0.2516660921096174,101.88622483521996,272.72377819640127,0.07628017134194968
0.079662537648881,252.646569994244,0.2529285570351971,101.86709702167919,272.7730368882711,0.07664852716880007
0.080068088709782,252.589316353837,0.25421618165355786,101.84401235386707,272.8136601427992,0.07702408425051942
0.080459060960681,252.480925106608,0.2554575185501622,101.80030900298435,272.7953032511697,0.07738600727030316
0.0808490065958527,252.360675943897,0.25669559594183233,101.75182454057928,272.763785897819,0.0777468495262095
0.081221360147376,252.287007979418,0.2578778184679188,101.72212161730135,272.7781019150182,0.07809129118817579
0.0815931884547529,252.223409833977,0.25905837334384046,101.69647884505952,272.8031220452611,0.07843512863025386
0.0819784975767304,252.209673615973,0.260281729806119,101.69094040196033,272.885443733328,0.07879130737721984
0.0823689659291929,252.180995529833,0.26152146682518745,101.67937739762867,272.9528833586198,0.07915212592718246
0.08275543415728541,252.156520717452,0.26274850344938117,101.66950915327665,273.0238430650153,0.07950911994764755
0.0831591672680592,252.172516077579,0.264030356076088,101.67595848247986,273.1429725224817,0.07988192607322993
0.0835458772375207,252.198191936092,0.26525816022912824,101.6863109886323,273.2683111191094,0.0802388828030333
0.0839361897744852,252.218920724549,0.2664974025339905,101.69466883613815,273.3892159192006,0.08059903576311907
0.0843448535141791,252.222149840497,0.26779490990751864,101.6959708156884,273.49579012182505,0.08097598297279712
0.08475561248702951,252.18996767464,0.2690990696463187,101.68299496641485,273.5644828479883,0.08135471967420736
0.0851773671108253,252.15035903158,0.2704381405768703,101.66702476153306,273.6278627299393,0.08174344562387695
0.0855811288717374,252.089659822635,0.2717200841677662,101.64255084048644,273.66377748714837,0.08211544625528344
0.0859842341366142,252.03489990216,0.27299994338375005,101.62047164055092,273.7059277459454,0.08248670403676545
0.0863936968802097,251.980337695189,0.2742999875946658,101.5984721587002,273.74985060980003,0.08286367596471435
0.08679614419396671,251.929826862306,0.27557775781584426,101.57810619088177,273.7963644414078,0.08323405071132053
0.08720976448097341,251.884252179116,0.27689100222709057,101.55973047861957,273.85101848812286,0.08361456512514721
0.08762074045219691,251.827486271868,0.2781958509357252,101.53684246481718,273.8927970852245,0.08399250352097447
0.0880275237442435,251.795369660501,0.27948738788797306,101.523893047114,273.9602925419813,0.08436644567282027
0.0884364673414765,251.729573452663,0.2807857838091879,101.49736401611372,273.9916476541933,0.08474223282456786
0.088853456486783,251.643457469214,0.282109724345536,101.4626420515871,274.00284846763844,0.08512526784975308
0.089262483210747,251.583649562245,0.28340838419412173,101.4385275034972,274.04063085739335,0.08550084632224607
0.0896749704395693,251.48476767386,0.28471803114563254,101.39865832610036,274.0366567810154,0.08587945951562515
0.0900681814642422,251.431774186799,0.285966476148969,101.37729135211735,274.07777685013195,0.08624024608682693
0.0904806787514348,251.417859495162,0.28727615503580545,101.37168094844932,274.1663180725171,0.0866185887138959
0.0908874387488144,251.404637584277,0.2885676180274857,101.3663498739805,274.25416118388586,0.08699152897907245
0.09130723568045271,251.426574316789,0.28990047328543733,101.37519476452931,274.3836397942609,0.08737627644613953
0.0917237059501816,251.378740022999,0.2912227663918266,101.3559079772732,274.43612965499574,0.08775782877949342
0.0921303229881234,251.316519975738,0.2925137754872918,101.33082085421756,274.4703921333539,0.0881302135975742
0.09255064568652831,251.23708289307,0.29384830005472734,101.29879182248584,274.4892371352235,0.08851500452093376
0.0929692767736907,251.171210872708,0.295177453756468,101.27223222387587,274.52241669391583,0.08889809971762364
0.0933956684384894,251.127770183629,0.2965312472922038,101.25471693803922,274.58201614339634,0.08928814591840833
0.0938177111082718,251.094139292626,0.297871232768763,101.24115696278682,274.65121671376176,0.0896740640725008
0.0942293878244913,251.025318531802,0.2991783063427599,101.21340843202258,274.67928062550163,0.09005036010495639
0.0946510352527396,251.018284589973,0.30051703692744824,101.21057234667711,274.7774250937808,0.09043562320934373
0.0950831971517776,251.006499094594,0.30188915095689384,101.2058204349403,274.87299953438276,0.09083033951623941
0.0955138913375345,250.984023710307,0.303256604996672,101.19675835999578,274.9564844784304,0.09122356033586847
0.09595435783881891,251.016396061725,0.30465508613825,101.20981089208752,275.10251315284245,0.09162554335102854
0.09638759527960661,250.92661707173,0.306030615012751,101.17361200332154,275.1128302829207,0.09202077133616184
0.0968336146064782,250.832620721353,0.30744672637556825,101.13571267484953,275.1216500470174,0.0924274966869926
0.0972790396969526,250.713900732621,0.3088609510378245,101.0878447753928,275.10310823456746,0.0928335151252162
0.0977080484508596,250.624240477348,0.31022305383147925,101.05169376046672,275.1122459088686,0.09322441378852629
0.0981675159496574,250.518153556053,0.3116818631401622,101.00891951380058,275.1108983909455,0.0936428960677155
0.0985766554512032,250.480587586371,0.31298088105757016,100.99377291482479,275.1721261660876,0.09401539233888179
0.0990016561307625,250.416219587611,0.3143302582151709,100.96781973772477,275.2078400487892,0.09440218236371785
0.0994272662382594,250.37174946042,0.3156815703064736,100.94988938244134,275.26552805255994,0.09478937715403703
0.099828536704908,250.329645352755,0.31695560403808287,100.93291300623082,275.3196875421791,0.09515429193163097
0.1002749912831021,250.297360315781,0.31837309732384916,100.91989567932289,275.39592593962936,0.0955601406370601
0.1007076746175144,250.298351774937,0.3197468669106082,100.92029543565461,275.5053167427875,0.0959533135108766
0.1011557000713524,250.263227136519,0.3211693477265438,100.90613318144446,275.57877907962944,0.09636026470064726
0.1015928972308964,250.232641120716,0.32255744870809605,100.8938008998727,275.6545001139087,0.09675722072715015
0.1020384867426224,250.160951115154,0.3239721954078261,100.86489548963009,275.6869960090395,0.09716163456971913
0.10246044963823141,250.094036377776,0.3253119276013847,100.8379154675193,275.7187837968831,0.09754445435139233
0.1029220007384264,250.011969878352,0.32677735234450384,100.80482625495154,275.74370202678716,0.09796302221190546
0.1033675025873194,249.955047257426,0.32819182071473907,100.78187505419417,275.7922762515215,0.09836686935370277
0.1038308201068584,249.878682577027,0.3296628538392754,100.7510848150573,275.82379111622106,0.09878669345521669
0.10428217131767441,249.810725284177,0.3310958939336162,100.72368443458018,275.8615301352541,0.09919550515901548
0.1047268866592484,249.73419526366,0.33250786514311365,100.69282753030771,275.8880800259759,0.09959814302595946
0.1051789645561324,249.650377354398,0.33394321246572034,100.65903214929327,275.90834554558126,0.10000728073012144
0.1056306375473334,249.592149572335,0.3353772742127835,100.63555470756546,275.95672745847014,0.10041588488767135
0.1060765917080354,249.535870574371,0.3367931786730124,100.6128630155864,276.00578523379767,0.100819151794653
0.10653046209733741,249.515030417592,0.3382342171590463,100.60446026437309,276.0959819082093,0.10122941026769514
0.10700161386450341,249.429618603736,0.3397301240197983,100.57002222102636,276.1189903399433,0.10165511159761721
0.1074576823972174,249.381869863564,0.3411781416111652,100.550769928989,276.179867630987,0.1020670121820461
0.1079185365149414,249.29858596977,0.34264135343493896,100.51718986301127,276.20252452287184,0.10248306262118825
0.1083829870392264,249.255427610858,0.3441159838495438,100.49978841269795,276.2704753910624,0.10290218477234674
0.10883622478737841,249.203111557886,0.3455550136999264,100.47869458013963,276.3254374251142,0.1033110191826275
0.1092963276381884,249.130557147396,0.34701584025124815,100.44944064183007,276.3596121460622,0.10372587523521616
0.1097642926050434,249.049596173233,0.3485016290210128,100.41679717704754,276.38634892075964,0.10414764377053534
0.1102263796281054,248.969233153589,0.3499687553192346,100.38439480752709,276.41221036289477,0.10456394014106957
0.1106883673523024,248.911546753393,0.3514355663435601,100.36113565096807,276.46315947866236,0.10497997387805909
0.1111579902178634,248.839951428675,0.3529266189417163,100.33226841604176,276.50050031539723,0.1054027059638799
0.1116350121495544,248.784387666057,0.3544411635748352,100.30986510695419,276.5574358057767,0.10583191546607469
0.1121086809669134,248.725005168634,0.35594506206995,100.28592208399323,276.60923742157826,0.1062579257351438
0.11259507713559841,248.669738614372,0.35748936990552493,100.26363860931478,276.6687270149463,0.10669519400033509
0.1130831102044194,248.619629783332,0.3590388748990316,100.24343472863946,276.73431077710245,0.10713374174674224
0.1135605207849584,248.553072494006,0.3605546534922429,100.21659882958322,276.7788888491268,0.10756255808826205
0.1140430217710114,248.479065497472,0.3620865941229612,100.18675920858072,276.81636897364075,0.1079957599434225
0.11451599430024441,248.387504985869,0.36358828190327597,100.14984201030238,276.8318470910827,0.10842022484017744
0.11500427948148441,248.269139876641,0.36513858735371296,100.10211719826164,276.82115342564197,0.1088582430047027
0.1154960222291224,248.160673963849,0.3666998705774636,100.05838374222392,276.8222446803717,0.10929916897564079
0.1159740160816354,248.062505404593,0.3682175010591924,100.0188021791319,276.831310395636,0.10972758060709217
0.1164481057896234,247.963167704112,0.3697227358820543,99.97874921829796,276.8380088888506,0.11015231185345488
0.11692320991288241,247.896010230961,0.3712311914734016,99.95167132512348,276.8808074717617,0.11057777100311397
0.1174060287634194,247.817070622544,0.3727641413238566,99.91984287500975,276.9122887441207,0.11100995337775629
0.1179031195274734,247.76914260102,0.374342404499728,99.90051829673126,276.98189743632764,0.11145471581487007
0.1183767263390474,247.718615436055,0.3758461061264755,99.88014574381738,277.04273418461656,0.11187828249819928
0.1188702758330774,247.672697391436,0.37741312577002073,99.861631588227,277.1136192466783,0.11231949395277468
0.1193571247485454,247.621346352893,0.3789588710766316,99.84092684948646,277.17671827993803,0.112754524748144
0.1198557474565874,247.488043042574,0.380541998174665,99.78717895476585,277.15090742800976,0.11319988009820711
0.1203687130465144,247.371057453112,0.38217066392268323,99.74001036509478,277.14679328369846,0.11365783920715906
0.12086372611417841,247.242920524766,0.38374233041251643,99.68834555558566,277.12562115474094,0.11409957212790763
0.1213484544130524,247.149768047094,0.3852813427614414,99.65078647658831,277.14101040815325,0.11453193826224117
0.1218481282234074,247.115527828885,0.3868678071093185,99.63698082060644,277.226092349774,0.11497743984911689
0.1223491319898394,247.022761505606,0.3884584940677401,99.59957743906034,277.24578195755,0.11542392802877655
0.1228595041008444,246.955815057172,0.3900789255201809,99.57258463105177,277.29668402991604,0.11587856027238358
0.1233680327850284,246.838076414951,0.3916935040924652,99.52511241050824,277.290004318704,0.11633134493869295
0.1238843363042944,246.748594326378,0.39333276776613474,99.48903323239561,277.31688016851894,0.11679084253269004
0.1244077721066314,246.647900481524,0.3949946764385547,99.44843347415048,277.33281627520853,0.1172564722520988
0.12492921051662541,246.489540590998,0.39665024339028565,99.3845827662904,277.283284297637,0.1177201096913645
0.1254333751005564,246.339457172892,0.39825096594426657,99.32406913211005,277.2386467065268,0.11816818378892424
0.1259388775644854,246.217949292898,0.39985593626724114,99.27507715489648,277.22636146307497,0.11861724544172317
0.1264367638718114,246.081736674969,0.4014367252930012,99.2201562273475,277.1955151081073,0.11905934426953489
0.1269452070422704,245.996987723947,0.4030510323592085,99.18598545029543,277.22512626233834,0.11951061545715466
0.12746130548643542,245.881537883297,0.40468964491943243,99.13943607454536,277.2219196969145,0.11996847294675361
0.12799205381211443,245.781922505112,0.4063747708534633,99.09927115406116,277.24005555643123,0.12043910855824824
0.1285321128031884,245.685355200694,0.40808945815012315,99.06033521691984,277.263812989441,0.12091777305418012
0.1290760091999494,245.538957534506,0.40981632920983935,99.00130767791283,277.2321462761759,0.12139960725913611
0.1295985278909974,245.359454511731,0.41147532605391673,98.92893205912995,277.1576786205895,0.12186228454334751
0.13012876567757842,245.193674395748,0.41315883102631146,98.8620895163656,277.10042459681677,0.12233157815928214
0.13064039461101243,245.000593160997,0.4147832528899644,98.78423916251398,277.00756733148177,0.12278419309331015
0.13113096047183642,244.842238262176,0.4163407994980806,98.72039046730937,276.94863612956937,0.1232179821829228
0.13164944610690843,244.659507076561,0.41798699138943424,98.6467132532694,276.8687956679795,0.12367625523729311
0.1321802720588184,244.477167973997,0.41967236378674844,98.5731941271156,276.7922265489694,0.12414521803725895
0.1327776721015714,244.332105758416,0.42156910892248917,98.51470504179333,276.7739539806934,0.12467273340075316
0.1333374693120034,244.22025225517,0.4233464650656108,98.46960570928455,276.7839626456135,0.12516679234029127
0.13391086726521942,244.042559589579,0.42516700356707166,98.39796002651826,276.72251039384355,0.12567260192117424
0.13446251484127542,243.841809610329,0.4269184846210494,98.31701763488465,276.62939255398135,0.12615898356476324
0.13503616864966742,243.570888848395,0.428739835462694,98.20778238367286,276.4617684730763,0.12666451707732446
0.1355834061906034,243.245731600333,0.4304773146551658,98.07667898125426,276.2258164320314,0.12714653313813445
0.13615243611984143,242.950803081565,0.4322839846804965,97.95776380248701,276.0291467783919,0.1276474980219388
0.1366996235712704,242.668665458566,0.43402130483878354,97.8440059128938,275.8413806792945,0.12812899655121393
0.1372553084751224,242.410169647142,0.4357856044085136,97.73978040172766,275.68225225956724,0.12861773527429254
0.1378153143436114,242.188721152751,0.4375636230409662,97.6504923687892,275.5660358888946,0.12911003285326192
0.1383957461147974,241.916835537931,0.4394064939144817,97.54086808889379,275.3970964899337,0.12962003106375286
0.1390099082557484,241.596328749283,0.4413564587120012,97.41163975171091,275.18061224364646,0.13015938351039383
0.1396137389171674,241.221803074057,0.4432736210620065,97.26063099945978,274.89968090956677,0.1306893794808146
0.14024284806969242,240.793379137037,0.4452710426212734,97.08789046805332,274.5629284235403,0.13124126434241823
0.1408443899932884,240.349286723849,0.44718093822869065,96.90883240705591,274.20113539779146,0.1317686812053093
0.14146708658434543,239.854385138616,0.4491579999052967,96.70928808788999,273.78588620865554,0.13231435309356707
0.14207315360172343,239.35650403882,0.45108226268547186,96.50854242845222,273.3626374026988,0.13284516662681944
0.14269035802626642,238.890073052821,0.45304188673339585,96.32047745489743,272.977383105649,0.13338544524770543
0.14330711452569742,238.349548708952,0.45500008861908925,96.10253803944944,272.5067347829341,0.13392504034507643
0.1439168069323454,237.840168450232,0.45693586201019665,95.89715591913355,272.06936605384055,0.1344581691003057
0.1445485756772184,237.182107361632,0.4589417277751684,95.63182568821003,271.466443156877,0.1350103022159942
0.1451650888188444,236.550221996646,0.460899156999831,95.37704950904767,270.8890559829065,0.13554880898746008
0.1457665507615744,235.863749902334,0.46280879866799873,95.10026396062106,270.2447951752879,0.13607388965434472
0.14637977915489142,235.14853227733,0.46475579881678025,94.81188821421945,269.5695225006824,0.1366089588163295
0.1469799434199154,234.490740369228,0.4666613203582314,94.54666651687273,268.9561761211912,0.1371323518739621
0.14760529920723442,233.673166128637,0.4686468249829693,94.21702058306644,268.1645637317563,0.1376774227575227
0.1482254145418764,233.050704261945,0.47061569117045754,93.96604395841621,267.59474151044805,0.13821763275297988
0.14885770594058942,232.156536368718,0.4726232163613714,93.6055154638671,266.7148257916784,0.13876814954450903
0.14952633243976843,231.34745679781,0.4747461054962647,93.27929458087699,265.9399935320543,0.13934997269231691
0.15020162272341542,230.422876112239,0.47689015214684394,92.90650364845476,265.03276601689385,0.1399372511150014
0.15087442942531643,229.416690328756,0.4790263134253796,92.50080954055441,264.0298025827516,0.14052202685107104
0.15153092788753342,228.456403043087,0.48111069604291856,92.11362170697268,263.0746137780543,0.14109229869996467
0.15217647303500442,227.472069407762,0.483160301886139,91.71673838520965,262.08796664420896,0.14165273893999622
0.15287196053379043,226.339923999946,0.4853684746947846,91.26025735677823,260.9409519288869,0.1422561861472329
0.1535794707967514,225.37168279644,0.4876148197796857,90.86986250352462,259.9841465728906,0.14286969161762075
0.15430726533213643,224.171427695317,0.48992556742953314,90.38591964675182,258.7627076685821,0.14350039376440912
0.15502331428883842,222.97040206239,0.49219902286706196,89.90166611155566,257.53601277841653,0.1441205293014936
0.1556842291552404,221.758254911572,0.4942974275678883,89.41292838034585,256.28251788629143,0.14469257476549024
0.15635820711650641,220.451975051223,0.49643730759490784,88.88623634065313,254.92145062552504,0.14527558999893336
0.1570729497684774,219.258018770536,0.49870661551491574,88.40483316828013,253.69752253921632,0.14589349701776577
0.1578344424166024,217.907329830411,0.5011243546727127,87.86023538762171,252.3006117326846,0.14655140037766912
0.1586353991215574,216.621941239311,0.5036673922109448,87.3419667076902,250.98584934629568,0.14724293257248702
0.15940214396950142,215.024862114567,0.506101807103167,86.69802440459341,249.3002861423754,0.1479044791278418
0.1601719813273554,213.467580057617,0.5085460407143534,86.07012827923118,247.65910530460138,0.1485682538938421
0.16092163893283543,211.868999318273,0.5109262036117524,85.42558052512769,245.96330592762928,0.14921420597867216
0.16169513445186043,210.211627138103,0.5133820518846568,84.75732806208315,244.20182445154293,0.14988026122849568
0.16247594104365942,208.579260247973,0.5158611128136187,84.0991577319827,242.46837183895275,0.15055216238878966
0.16324893316509842,206.758709179175,0.5183153627991874,83.36511154104338,240.51184787526816,0.1512168946264456
0.1640226378246484,205.017576130874,0.5207718750932586,82.6630866959684,238.64509976827563,0.15188179742309277
0.1647989221336864,203.083233178154,0.5232365777744543,81.8831596174317,236.5511311093379,0.15254847309385916
0.1655978819023684,201.044662835268,0.5257732750400197,81.06120805518007,234.3372331685642,0.15323415872353544
0.1664205275757764,198.84185983714,0.5283851750530901,80.17303788633484,231.93322705538543,0.15393968120499432
0.16728171569051242,196.510159491507,0.5311194473173769,79.23289630697563,229.38271612186253,0.1546777257917126
0.1682178170417794,193.767699106829,0.5340915691076495,78.12713627987345,226.36287846378815,0.15547935421276451
0.1689153250884574,191.524440165513,0.5363061571558523,77.22265427473484,223.87585323845545,0.15607624623813818
0.16940194973346742,190.018482676801,0.5378511904037591,76.61545221528615,222.20798412764617,0.15649246405192663