File: example/data/02 processed data/test_ID_098.csv
Strain,Stress_MPa,Displacement(mm),Force(kN),True Stress (MPa),True Strain
-2.88306579161561e-05,0.192260502938387,-9.153733888379562e-05,0.03875971739237882,0.192254959941596,-2.8831073527551888e-05
-8.29544802977709e-05,0.171677202316533,-0.0002633804749454226,0.034610123987013054,0.17166296092343583,-8.295792121102032e-05
-0.0001541529402731,0.664752206683551,-0.0004894355853670925,0.13401404486740387,0.6646497331763377,-0.00015416482305879078
-0.0002756749341458,2.14224289844559,-0.000875267915912915,0.43187616832663095,2.1416523357756367,-0.00027571293946538104
-0.0003677802623636,4.83910722637638,-0.0011677023330044299,0.9755640168374783,4.8373274982510575,-0.0003678479101111532
-0.0003765079314003,8.75660320634575,-0.0011954126821959524,1.765331206399303,8.753306275786436,-0.00037657882830757685
-0.0003412276938543,13.1922147139909,-0.0010833979279874025,2.6595504863405655,13.187713164987215,-0.00034128592527093597
-0.0002498145412709,18.0057464759937,-0.0007931611685351075,3.6299584895603303,18.001248378697557,-0.00024984575012117167
-0.0001633157692229,22.9944822677869,-0.0005185275672827075,4.635687625185839,22.990726906227454,-0.0001633291066953094
-7.19281587036308e-05,28.2552170094035,-0.00022837190388402776,5.696251749095746,28.25318466367024,-7.193074565766258e-05
2.01902844289476e-05,33.5968168649789,6.410415306190863e-05,6.773118279979745,33.59749519426731,2.0190080607962188e-05
0.0001162329103307,39.0200345751017,0.0003690394902999725,7.866438970340503,39.024569987281566,0.00011622615580947602
0.0002171255407551,44.4737867993441,0.0006893735918974425,8.96591541874777,44.483443194352326,0.00021710197241627628
0.0003143288916249,49.9532970855636,0.0009979942309090574,10.070584692449621,49.96899885006952,0.000314279500648652
0.0004280459986678,55.4923692421868,0.0013590460457702648,11.187261639224857,55.51612252879752,0.0004279544131136588
0.0005382595986587,61.0415292046158,0.0017089742257413725,12.305972287650546,61.07438539362699,0.0005381147889221019
0.00064819957802,66.5559340605353,0.0020580336602135,13.417676306603914,66.59907558890806,0.0006479895874126016
0.0007624476312105,71.9851015199624,0.002420771229093337,14.51219646642442,72.03998639009873,0.0007621571156745125
0.0008720640444603,77.2871342590712,0.002768803341161452,15.581086266628754,77.35453358995791,0.0008716840175340623
0.0009809646203142,82.4674721489824,0.0031145626694975845,16.62544238523485,82.5483698214873,0.0009804837889477993
0.0010910708080713,87.5191168802969,0.0034641498156263773,17.64385396306786,87.61460643387318,0.001090476022913082
0.0011871588177972,92.4890406742001,0.0037692292465061096,18.64579059991874,92.59883985438607,0.001186454701977622
0.0012937551574064,97.3196871178729,0.00410767262476532,19.619648922963176,97.44559496499882,0.0012929189773332017
0.001397428918445,101.949789843532,0.004436836816062875,20.553077632456052,102.09225742808876,0.0013964534233383188
0.0014972913617768,106.423782753718,0.00475390007364134,21.45503460314955,106.58313016432275,0.0014961715387273187
0.0016046768720439,110.784986386445,0.0050948490687393825,22.33425325550731,110.96276049186902,0.0016033907537977138
0.0016915769743556,115.180344265046,0.00537075689357903,23.220357403833273,115.3751806833031,0.0016901478694257791
0.001801866479241,119.589157091021,0.005720926071590175,24.10917406954983,119.80464078446398,0.0018002450652586158
0.0019002555606758,124.149567037693,0.006033311405145665,25.028552714798913,124.38548294281186,0.0018984523590790069
0.0020076854381215,128.610222034434,0.006374401266035762,25.927820762141895,128.8684309044061,0.002005672731183619
0.0021087004862652,133.067893290796,0.006695124043892009,26.826487287424474,133.3484936220846,0.0021064802979883787
0.0022051278071583,137.347075721878,0.007001280787727602,27.689170465530605,137.6499435777842,0.0022027000811442807
0.0023114372883436,141.599969017305,0.007338813390490929,28.546553753888688,141.92726846571992,0.002308770026522971
0.0024180399455928,145.847942980812,0.00767727682725714,29.402945304931702,146.20060913292215,0.0024151211911666117
0.0025175327091449,150.044183803808,0.007993166351535057,30.248907454847696,150.42192494435105,0.0025143690323348577
0.0026160253597098,154.16480296184,0.008305880517078614,31.079624277106948,154.56810199596285,0.002612609521351473
0.0027130519254299,158.251820570242,0.008613939863239932,31.903567026960786,158.68116597674288,0.002709378243148649
0.0028142167341228,162.237141357613,0.00893513813083989,32.707007697694785,162.69371183571783,0.0028102642399231953
0.0029209800245688,166.130552549174,0.009274111578005938,33.491919393913484,166.61581657464075,0.002916722251648257
0.0030144229338424,170.132880253362,0.009570792814949618,34.29878865907778,170.6457327093984,0.003009888670869313
0.0031231348138019,173.995298064165,0.009915953033821033,35.077452089735665,174.53870883698704,0.003118267958865783
0.0032142281891986,177.831450876869,0.010205174500705554,35.85082049677679,178.40304173920356,0.0032090736001693576
0.0033230443786606,181.610250895859,0.010550665902247404,36.61262658060517,182.21374981920565,0.0033175352679951755
0.0034149137024481,185.288720538878,0.010842351005272716,37.35420606063781,185.92146552955532,0.0034090961252378343
0.0035202540272312,188.91431667633,0.011176806536459059,38.08512624194813,189.57934306041147,0.0035140724359563774
0.0036174490144408,192.50004133634,0.01148540062084954,38.80800833340614,193.19640042115194,0.0036109217823048455
0.0037256936967476,195.99658865796,0.01182907748717363,39.512912273444734,196.72681191290698,0.0037187704904889157
0.0038376407165011,199.555987311645,0.012184509274890992,40.23048704202763,200.32181149377374,0.0038302957589081343
0.0039413762493097,203.104988468042,0.012513869591558298,40.94596567515727,203.90550164570627,0.003933629374833354
0.0040594669846709,206.592337498654,0.012888807676330107,41.64901523972864,207.43099227201577,0.004051249579919762
0.0041632783785555,209.866886105291,0.01321840885191371,42.30916423882667,210.74062037458793,0.004154635914146528
0.0043028806406075,213.092661632951,0.01366164603392881,42.959480585202925,214.00957392134697,0.004293649719930649
0.0044490587941495,216.162471996479,0.014125761671424663,43.578354354490166,217.12419154348004,0.0044391909895421305
0.00460234845694,219.122645437831,0.014612456350784498,44.17512532026674,220.13112420694242,0.004591790034578708
0.0047956958492503,221.786613409216,0.015226334321369703,44.71218126329794,222.85023455056185,0.004784233133102603
0.0050065795265788,224.1302449983,0.01589588999688769,45.184657391657275,225.25237089419556,0.004994088282224633
0.0052354664299384,226.027102689995,0.01662260591505442,45.56706390230299,227.2104599983847,0.0052218090234249686
0.0054924070123962,227.487148936154,0.017438392264357935,45.861409225528654,228.73660094820096,0.00547737874745391
0.0057812494868011,228.63126311305,0.01835546712059349,46.09206264359088,229.953037485589,0.0057646021946035466
0.006101101373297,229.486024734614,0.019370996860217975,46.264382586498186,230.88614223527483,0.006082565010922296
0.0064295876483422,230.11787931935,0.020413940783486482,46.39176447078096,231.59744239388442,0.006409006023478456
0.0067658490044767,230.52271481478,0.021481570589213524,46.473379306659645,232.0823966953188,0.0067430633664858994
0.0070964179569687,230.698525209706,0.02253112701337562,46.50882268227673,232.33565836665036,0.0070713568758130375
0.0074341357792361,230.806377597784,0.023603381099074616,46.53056572371325,232.52222354755955,0.007406638785342338
0.0077757454688648,230.932082950895,0.024687991863645738,46.55590792290043,232.7277520485159,0.007745670164733205
0.0081143683594042,231.113010665805,0.025763119541108333,46.592382950226295,232.98834676699826,0.0080816238870136
0.0084717423621637,231.310426640617,0.026897781999869745,46.632182010748394,233.27002898079846,0.008436058547255034
0.0088220690490142,231.546005324756,0.028010069230620088,46.67967467347081,233.5887201717544,0.00878338196478659
0.0091879108241167,231.714543150075,0.029171616866570525,46.71365189905512,233.8435157091888,0.009145958743651992
0.00955789371264,231.906333192123,0.030346312537631998,46.752316771531994,234.12286927606135,0.009512506024477852
0.0099227428878948,232.063660878566,0.03150470866906599,46.78403403311891,234.3663689190876,0.00987383573728808
0.0102968631787334,232.191501883378,0.032692540592478544,46.809806779689005,234.5823460095358,0.010244211605329375
0.010663275943351,232.282545026352,0.03385590112013942,46.828161077312565,234.75943790079185,0.010606824169070031
0.0110321240722787,232.408121260939,0.03502699392948487,46.8534772462053,234.97207649009485,0.01097171408573833
0.0113998098240987,232.561683789227,0.03619439619151337,46.88443545190817,235.21284275679633,0.011335321631395124
0.011767719195278,232.720319395857,0.037362508445007644,46.916416390204766,235.45890676554285,0.011699018033158983
0.0121379602025548,232.829784365629,0.03853802364311149,46.938484528110806,235.65586302222843,0.012064885884784318
0.0125067362733888,232.936965615773,0.03970888766800944,46.960092268139846,235.85024681305293,0.01242917308594515
0.0128758435506138,233.095403851223,0.04088080327319882,46.99203341640656,236.0967038035785,0.012793654626359351
0.0132486403852513,233.236280132617,0.042064433223172874,47.02043407473558,236.32634373288775,0.013161644689951253
0.0136027321306711,233.396985795638,0.04318867451488074,47.05283233640062,236.5718224735221,0.013511045493407977
0.0139697975545297,233.5189650599,0.044354107235631796,47.07742335607584,236.7811777269301,0.013873119276214317
0.0143372695094401,233.615680417741,0.045520830692472314,47.09692117221659,236.9650913895214,0.014235462794016041
0.0147045782373877,233.667559142827,0.046687035903705945,47.107379923193925,237.10354204778216,0.014597514204998828
0.0150669002734283,233.762342974233,0.047837408368134854,47.12648834360538,237.28441688350873,0.01495452192111335
0.0154268463050378,233.855306508098,0.048980237018495014,47.14522979203256,237.46295637921594,0.015309062323896103
0.0157948162013558,233.97441969861,0.05014854143930466,47.16924301123978,237.67000265356842,0.015671376203405647
0.0161579694636789,234.149281595157,0.0513015530471805,47.20449516958365,237.9326585371139,0.01602881882584418
0.016525805888906,234.322611215626,0.052469433697276545,47.23943842107021,238.194981203957,0.016390740767370425
0.0168998473900383,234.518570553803,0.0536570154633716,47.278943823646685,238.4818986062922,0.016758633741227602
0.0172772025172183,234.617487585728,0.054855117992168106,47.298885497282775,238.6710214328276,0.01712964877310578
0.0176469656670639,234.701677339543,0.05602911599292788,47.315858151651874,238.84344978155625,0.017493065906477537
0.0180173729654776,234.759637589802,0.05720515916539138,47.32754293810408,238.9893895374978,0.017856983764124354
0.0183843406058776,234.861002432446,0.05837028142366138,47.34797809038112,239.17876709620197,0.01821739167571345
0.0187546187087629,234.994003100778,0.059545914400322204,47.37479102511685,239.40122602777893,0.0185809192645113
0.0191320240977569,235.098383524496,0.06074417651037815,47.395834118538396,239.59629146343033,0.018951308260033516
0.0195018080266251,235.199931455087,0.06191824048453469,47.41630618134555,239.78675536619951,0.019314084475258484
0.0198659786116722,235.295391138052,0.06307448209205922,47.43555085343129,239.96976434582558,0.01967122514532675
0.0202421121746259,235.378553811982,0.06426870615443724,47.452316448495566,240.14311290174535,0.020039964006678578
0.0206158623770396,235.500490574533,0.06545536304710073,47.47689889982585,240.35553627794286,0.020406231734518963
0.0209948281760134,235.601665764953,0.06665857945884254,47.497295818214525,240.54808225567075,0.02077747372015304
0.0213737092713309,235.671933368916,0.0678615269364756,47.51146176717347,240.70911675615568,0.021148495005211813
0.0217418105143056,235.727463508276,0.06903024838292027,47.52265664326845,240.85260535289083,0.021508828274077876
0.022106308090638,235.747484756581,0.07018752818777564,47.526692926926735,240.95899128620297,0.02186550603000177
0.0224736398900334,235.773502779717,0.07135380665085604,47.53193816039094,241.07219157680015,0.022224828543861264
0.0228418373564149,235.837157215396,0.0725228336066173,47.54477089462384,241.22411120310935,0.022584868326921744
0.0232085609231964,235.931614256566,0.07368718093114857,47.5638134341237,241.4072474997476,0.02294333806062609
0.0235774219409198,236.036387366364,0.07485831466242036,47.58493569305899,241.60151686471116,0.023303767558194098
0.023940402069496,236.088553654204,0.0760107765706498,47.59545241668752,241.7406085526914,0.02365832381955825
0.0243125571232414,236.148074715372,0.07719236886629145,47.607451862618994,241.88943827143297,0.02402171160930409
0.0246819905885914,236.200898822783,0.07836532011877768,47.61810120267305,242.03080718454373,0.02438231136762521
0.025050631903634,236.276560347932,0.07953575629403795,47.63335456614309,242.19543748866482,0.02474200834953612
0.0254262658703087,236.350673763652,0.08072839413823012,47.64829583075224,242.36018883339318,0.025108395282531445
0.0257894141860537,236.419177253952,0.0818813900407205,47.66210613439673,242.51628933768023,0.025462476350719503
0.0261590682398519,236.529408124501,0.08305504166152977,47.6843286778994,242.71679705236158,0.025822772002352896
0.0265217109848923,236.616652512878,0.08420643237703304,47.70191714659621,242.89213098503726,0.0261761077499116
0.0268951197780987,236.703090855581,0.08539200529546337,47.719343116485135,243.06924883598802,0.02653980282801577
0.0272684979146038,236.75246590242,0.08657748087886706,47.72929712592787,243.20835002515744,0.02690333583716972
0.0276488279839961,236.764887648524,0.08778502884918761,47.73180134994244,243.3111592997682,0.027273501652545103
0.02801556708918,236.823937916633,0.0889494255081465,47.743705883993215,243.45869483766023,0.027630310001177927
0.0283899912007738,236.880985115604,0.09013822206245681,47.755206599305765,243.60603419866666,0.02799446396314537
0.0287632681684307,236.915344862871,0.09132337643476747,47.762133524354795,243.72980446037798,0.028357370295042074
0.0291436103899306,236.960524103395,0.09253096298802964,47.77124165924443,243.86640929565806,0.028727010175051537
0.0295223336949583,236.964930915604,0.0937334094814926,47.77213007258576,243.9606886800972,0.029094940980327107
0.0299038655511771,237.004564244265,0.09494477312498728,47.78012015164382,244.09191686844085,0.0294654634692839
0.0302859738951052,237.048254374759,0.096157967116959,47.78892808195142,244.2274916186332,0.029836408263781228
0.0306590127151635,237.09118614944,0.09734236537064411,47.7975831277271,244.3601678402489,0.030198415815225765
0.0310392805730949,237.149178398569,0.0985497158195763,47.809274365151516,244.5101182845611,0.030567303797993505
0.0314161466935266,237.214132434413,0.09974626575194696,47.82236909877766,244.66648641675013,0.030932757634855933
0.0317833616942284,237.241180242232,0.10091217337917517,47.82782193683397,244.78150248263648,0.03128872418398178
0.0321548257585381,237.224440183019,0.10209157178335845,47.82444714089663,244.8523507227707,0.031648680766575794
0.0325193770835578,237.158410254382,0.10324902224029602,47.81113550728342,244.87065402598137,0.03200181282809566
0.0328891224892556,237.118665380477,0.10442296390338653,47.80312294070417,244.91729021066433,0.03235984893545548
0.0332557922308267,237.124125814391,0.10558714033287475,47.80422376418122,245.0098764753908,0.032714780230746705
0.0336271551647625,237.166990111476,0.10676621764812093,47.81286520647356,245.1422412879143,0.03307412611281496
0.0340044540220474,237.243728478469,0.1079641415200005,47.82833566125935,245.3110719355342,0.03343908364180264
0.0343777160115783,237.296468325882,0.10914924833676111,47.838968014497816,245.45417892453966,0.033800005331218234
0.0347654471477919,237.347080541082,0.11038029469423928,47.849171437082134,245.59855792531567,0.03417477992164312
0.0351516603825787,237.411435772571,0.11160652171468737,47.862145451750315,245.75684193378882,0.03454794775320865
0.0355332762449426,237.462423100572,0.11281815207769276,47.872424497075315,245.90024097839805,0.034916536774101156
0.0359098098995323,237.472875500519,0.11401364643101504,47.874531700904626,246.00048131603793,0.03528008396615818
0.0362842061882169,237.447856322971,0.11520235464758866,47.86948783471095,246.0634633007438,0.03564143651312229
0.0366598011516422,237.414455418751,0.11639486865646397,47.86275421242021,246.11802214492783,0.0360038148177996
0.0370468389348854,237.368797682029,0.11762371361826113,47.853549612697044,246.16256129792254,0.03637709595627472
0.0374273308907118,237.354376805355,0.11883177557800995,47.85064236395957,246.23791760440773,0.03674392815464825
0.0378080652226304,237.358919316181,0.12004060708185152,47.85155813414209,246.33300081886023,0.03711085938269449
0.0381777697700693,237.367811363928,0.12121441901997002,47.85335077096789,246.42998501700532,0.03746703190094152
0.0385744617728602,237.456856926449,0.12247391612883111,47.87130235637212,246.61662737666185,0.03784906303743475
0.0389623814840892,237.503976661949,0.12370556121198319,47.88080169504892,246.75769720464007,0.03822250499779871
0.0393546609323522,237.538604516404,0.12495104846021823,47.88778267050705,246.8868557554912,0.038600002217823906
0.0397450130483374,237.543726708187,0.12619041642847123,47.8888153043705,246.9849052257546,0.0389755033305959
0.0401254966498416,237.481991255638,0.12739845186324708,47.87636943713662,247.01107410016382,0.0393413757288769
0.0405104302684253,237.430981023849,0.12862061610225034,47.866085774407956,247.04941222417946,0.039711391086196694
0.040903786848091,237.382873261954,0.1298695232426889,47.856387249609924,247.09273171124838,0.04008936158444145
0.0412837534681039,237.336613399195,0.13107591726122989,47.847061261277716,247.13475963572202,0.0404543302694167
0.0416638591068574,237.320536173711,0.13228275266427225,47.843820092620135,247.20822555601634,0.040819299259206056
0.0420431476082383,237.322007093578,0.1334869936561566,47.84411663006533,247.2997712684967,0.041183350927072634
0.042411746173313,237.279716023898,0.13465729410026878,47.83559075041784,247.34316311197932,0.04153701515844184
0.0427862229170477,237.193014271814,0.13584625776162645,47.818111677197706,247.34160745481432,0.041896191364549536
0.0431664326722079,237.134744013721,0.13705342373426008,47.80636439316615,247.37100497543054,0.042260734402812625
0.0435457547903191,237.129964303167,0.13825777145926313,47.80540080351847,247.4559675821498,0.04262429400108243
0.0439303333350264,237.12220273452,0.1394788083387088,47.80383607127923,247.53906014178318,0.04299275671186137
0.0443065604006999,237.153764818868,0.14067332927222218,47.810198987483794,247.66123242406854,0.043353086587147656
0.0446853966431062,237.093266692855,0.1418761343418622,47.79800256527957,247.68787335643498,0.04371578424644884
0.0450663433383656,237.091989363777,0.14308564009931077,47.797745055737444,247.7768583592211,0.04408036984979178
0.0454527420985556,237.113650194306,0.14431245616291402,47.80211187917209,247.8911157846349,0.04445003762013837
0.0458460439538161,237.173279985197,0.1455611895533661,47.81413324501572,248.0467366040691,0.044826169297276605
0.0462344464360102,237.232534204579,0.14679436743433238,47.82607889564312,248.20084910013958,0.045197476700065964
0.0466257586027427,237.220175538799,0.14803678356370806,47.82358738862188,248.2807461791713,0.04557142635074059
0.0470217954999649,237.196369834947,0.14929420071238855,47.81878815872532,248.34976903065996,0.045949748768159715
0.047422488622747,237.159885903692,0.15056640137722171,47.8114329981843,248.4065978947318,0.0463323735347463
0.0478182183723927,237.164803827851,0.15182284333234683,47.81242445169476,248.50560220753687,0.04671011510212811
0.0482168662992368,237.14393447505,0.15308855050007683,47.80821719017008,248.57827185730847,0.047090497982706904
0.048612447689724,237.106542823015,0.1543445214148737,47.80067903311982,248.63287223289012,0.04746781185612638
0.0489946801966582,237.031121945816,0.1555581096243898,47.78547418427651,248.64438596220634,0.04783225809210947
0.0493753758740942,236.894147770781,0.15676681840024909,47.75786019058945,248.59088535933654,0.048195107038139375
0.0497622108131138,236.820830071887,0.15799501933163632,47.74307934249242,248.60555814286081,0.04856367262988694
0.0501537392020371,236.790838700224,0.15923812196646778,47.73703308196516,248.66678466982663,0.04893657173897504
0.0505457804638015,236.79674310066,0.16048285297256976,47.73822340909305,248.76581929196914,0.04930982004283353
0.0509601661860582,236.815937424146,0.16179852764073477,47.74209298470783,248.88411695078761,0.04970419030696534
0.0513436165949052,236.788036940564,0.163015982688824,47.73646824721771,248.9455911235006,0.050068980986828084
0.0517375571215177,236.692799873561,0.1642667438608187,47.7172684545099,248.93870712727133,0.050443612775789175
0.052117042873216,236.677740174172,0.1654716111224608,47.71423241911308,249.0126841059652,0.05080436561090894
0.0525163078096043,236.637371535844,0.16673927729549365,47.70609410162615,249.06469257867607,0.05118378081028167
0.0529041519905008,236.621092083198,0.16797068256984005,47.702812163972716,249.1393303029258,0.051552205258214065
0.0533005757320243,236.603771567968,0.16922932794917714,47.699320348102354,249.2148888129091,0.051928639458543056
0.0536878512636912,236.565781111578,0.17045892776221955,47.69166147209412,249.2664895819753,0.05229624995992604
0.0540845702348184,236.516805805438,0.1717185104955484,47.6817880503763,249.30871560073714,0.05267268431476023
0.0544907298478652,236.525540041656,0.17300806726697202,47.68354887239785,249.4139893461863,0.0530579298576195
0.0548949586579077,236.535874458622,0.17429149373885694,47.685632290858194,249.52050150814011,0.053441196717912934
0.0553044007026393,236.511979164263,0.17559147223087976,47.68081499951543,249.59213243093768,0.05382925678252582
0.0557112847695947,236.480608630242,0.17688332914346316,47.67449069985679,249.65524716012845,0.054214743327977884
0.0561114550498212,236.440093458287,0.1781538697831823,47.666322841190656,249.7070911343472,0.05459372426938999
0.0565107356000358,236.366819225974,0.17942158553011364,47.65155075595636,249.7240820518745,0.054971719498954394
0.0569158238668469,236.320115554868,0.1807077407772389,47.642135295861394,249.77046962798175,0.05535506688328363
0.0573195035867618,236.265603099778,0.1819894238879687,47.63114558491524,249.80823018408415,0.05573693518297441
0.0577250705044812,236.214783168731,0.1832770988517278,47.620900286816166,249.85029818134674,0.056120441920996224
0.0581254754536326,236.170054949349,0.1845483845652835,47.61188307778876,249.89755168119046,0.056498923241140656
0.0585372114309228,236.118425192236,0.18585564629317988,47.60147451875478,249.94013937045045,0.056887965845835824
0.0589427261303911,236.044318530602,0.18714315546399174,47.58653461576936,249.9574141523861,0.05727098218259778
0.0593550390172877,235.982828123278,0.18845224887988843,47.574138149652846,249.98959809394506,0.057660269183591906
0.0597474172251204,235.909132954771,0.18969804968975726,47.559281203681834,250.0040943486361,0.058030594092763864
0.060148457799167,235.795899694972,0.19097135351235522,47.53645337850636,249.97865941699163,0.05840895284477201
0.0605383014687031,235.695951470603,0.19220910716313233,47.51630381647357,249.96458403568317,0.05877661079540884
0.0609404501971209,235.65051823213,0.19348592937585884,47.50714447559741,250.01116690238084,0.059155731946557655
0.0613355633767194,235.664633972772,0.19474041372108408,47.50999020891084,250.11925706546035,0.05952808048335154
0.0617364878833259,235.702274434604,0.19601334902955972,47.517578526016166,250.2537050443083,0.05990576386073332
0.0621384008079084,235.696643313689,0.19728942256510917,47.5164432920397,250.34245580499365,0.06028423524011636
0.0625483845150325,235.640507441894,0.19859112083522817,47.50512630028583,250.37944050868697,0.06067015914668432
0.0629630379763538,235.581831511526,0.19990764557492333,47.49329723272364,250.41477931552515,0.06106032733133272
0.0633810879808693,235.513793183244,0.20123495433926003,47.479580705741995,250.44091362969945,0.06145353744704139
0.0637936586400462,235.482952773849,0.20254486618214668,47.47336327920796,250.50527187865407,0.06184144226304728
0.0642086791685233,235.420538654219,0.20386255636006145,47.460780592690554,250.53658049034868,0.06223149872714522
0.0646065804658499,235.31456633814,0.2051258929790734,47.43941657376902,250.51743580305163,0.06260532290015383
0.0650189320013256,235.216390705633,0.20643510910420876,47.41962436625561,250.5099092185198,0.06299257553045423
0.065428814105345,235.122227174609,0.20773648478447035,47.40064099840118,250.5059956684512,0.06337736047514536
0.0658458266468149,235.097045013199,0.20906049960363732,47.39556427466092,250.57720428431654,0.06376868737297255
0.0662522194346098,235.081548718258,0.21035079670488607,47.39244022160082,250.65622306896796,0.06414990135463096
0.0666558401187831,235.049760886076,0.21163229237713635,47.38603179463292,250.71720016765647,0.06452837119741987
0.0670611072528086,235.009686580407,0.2129190155276673,47.377952814610055,250.76969637762463,0.06490824083232918
0.0674735632315952,234.902766382832,0.21422856326031475,47.356397702778935,250.75249304364067,0.06529470069135446
0.0678818180826391,234.77603674954,0.21552477241237913,47.33084900870727,250.71306096633526,0.06567707718904715
0.0682916106968625,234.659520260186,0.21682586396253842,47.307359284453504,250.68479686410717,0.06606074699200364
0.0686978932798768,234.600990056752,0.2181158111636088,47.29555959544121,250.7175838350242,0.06644098525443144
0.0691050372348202,234.587825645829,0.2194084932205541,47.29290565019913,250.7990260719195,0.06682188468538866
0.0695151735718569,234.541816332796,0.22071067609064562,47.28363017269167,250.8460314050289,0.0672054369776492
0.0699417071346387,234.521121431569,0.22206492015247783,47.27945808060431,250.9239290236228,0.0676041676763413
0.0703696576898129,234.513086741575,0.22342366316515597,47.277838287101524,251.01569237936104,0.06800406328770944
0.0707968866645353,234.496725702093,0.22478011515989957,47.27453990154195,251.09836381482867,0.06840312517434169
0.0712154395143817,234.486683846221,0.22610902045816186,47.27251546339816,251.18575609659953,0.06879392857921311
0.0716316731031524,234.432266944849,0.22743056210250884,47.26154501608156,251.22504245547339,0.06918241508537076
0.0720485687866785,234.353834899668,0.2287542058977042,47.245733115773064,251.23869329385863,0.0695713683262837
0.0724750875493392,234.266326469208,0.23010840296915197,47.22809141619233,251.24479898992593,0.06996914315802716
0.0728969683923008,234.182837637743,0.23144787464555502,47.21126006776899,251.2540565510409,0.07036243703657036
0.0733237214275321,234.106861090603,0.23280281553241441,47.19594319586557,251.27244735748434,0.07076011565636908
0.0737502908066815,234.04885065131,0.23415717331121375,47.184248291304094,251.31002144981366,0.07115746514905637
0.0741744244176283,234.009826171138,0.23550379752596984,47.17638095610142,251.36737033545143,0.07155238924807458
0.0745989853800456,233.943229136483,0.23685177858164477,47.16295499391497,251.39515666659614,0.07194755512829827
0.0750138993507621,233.87590462184,0.23816913043866964,47.14938237176294,251.41984819171114,0.07233359112465508
0.0754311635585718,233.773951003157,0.23949394429846543,47.128828522236454,251.4077921370097,0.07272166354765565
0.0758456350893538,233.62595338359,0.2408098914086983,47.09899220213175,251.34546219132412,0.07310698963509418
0.0762649144648703,233.471286411863,0.24214110342596318,47.06781134063158,251.27695410006697,0.07349663447086548
0.0766694133529012,233.322909124047,0.2434253873954613,47.03789847940788,251.21163968837993,0.07387239966496717
0.0770888879619445,233.260464729659,0.2447572192791738,47.02530968949925,251.24225456115477,0.07426192769519344
0.0775025922264278,233.274828963747,0.24607073031890825,47.0282055190914,251.354232909614,0.07464594877145926
0.0779337261822715,233.267013109326,0.247439580628712,47.02662984284012,251.44638063634454,0.07504599210181531
0.0783546303460553,233.305384942259,0.24877595134872557,47.03436560435942,251.58594213715386,0.07543638902424495
0.0787835828058866,233.246708078657,0.2501378754086899,47.02253634865725,251.62271941877236,0.07583409415307717
0.0792023129132396,233.192083920147,0.25146734349953576,47.011524118301644,251.66143631968092,0.07622216908298159
0.0796263083250859,233.10819177322,0.2528135289321477,46.994611461481156,251.66973652445768,0.07661497045047018
0.0800568525515868,233.062675065625,0.25418050685128807,46.985435293230005,251.72093927863213,0.07701368100209552
0.0804925017058423,233.022436162705,0.2555636929160493,46.97732313040133,251.77899500303104,0.07741695728856512
0.0809359537203255,232.976227596206,0.25697165306203346,46.968007483395134,251.83238077086858,0.0778272896496407
0.0813777444404366,232.90800070711,0.2583743385983862,46.954252942553374,251.86152846678624,0.07823591743258843
0.0818138913815466,232.818159585938,0.25975910513641043,46.9361409725251,251.86591920595353,0.07863916136141799
0.082236836385279,232.712975742255,0.2611019555232608,46.91493590963861,251.85055465310222,0.07903004407381528
0.0826639402122261,232.634531296128,0.26245801017381787,46.899121509299405,251.86501828249033,0.07942461535126612
0.0830956211907774,232.545531557001,0.2638285972807182,46.8811791618914,251.86904695686954,0.07982325700287075
0.0835317788967263,232.463807361177,0.265213397997106,46.86470356401328,251.881922719162,0.08022587141808855
0.0839559584421774,232.339192642799,0.26656016805391325,46.839581236788284,251.84545224480686,0.08061727344870594
0.0843774081151589,232.170987096401,0.2678982707656295,46.80567099863444,251.76097322713332,0.08100600489082532
0.0848006748247652,232.081848178799,0.2692421425686295,46.78770059284588,251.76254551893985,0.08139626027677732
0.0852349192524526,232.019921792806,0.270620868626537,46.775216233429695,251.7961210917762,0.08179647899638628
0.0856653297555371,231.982236630625,0.2719874219738303,46.767618904734,251.85507142901457,0.08219300620570494
0.0861006794855738,231.979316587452,0.2733696573666968,46.76703022403032,251.95289337223068,0.08259392392337392
0.0865221338944894,231.896388471722,0.2747077751150038,46.750311915899154,251.96055884472088,0.08298189224590695
0.0869502292789118,231.851679866082,0.27606697796054497,46.741298661002126,252.0112365891387,0.08337581985889314
0.0873825404710278,231.722062979362,0.2774395659955132,46.71516789663938,251.97052552568613,0.0837734693850624
0.0878210824224223,231.655377129258,0.2788319366911908,46.701724029258415,251.9996030977239,0.08417668860805447
0.0882501194064956,231.573924631203,0.2801941291156235,46.68530320565053,252.01035113133744,0.08457101117366887
0.0886903628593288,231.515509437053,0.2815919020783689,46.67352670250989,252.04870397658757,0.08497547189496206
0.0891211722124211,231.467700373455,0.28295972177443696,46.663888395288524,252.09637316005075,0.08537110701009842
0.0895629018498177,231.408052866926,0.2843622133731712,46.65186345797229,252.1336295931039,0.085776608338821
0.0899927878687089,231.378527115988,0.2857271014831507,46.645911066583174,252.20092582411144,0.08617107958495039
0.0904297633254116,231.306779781793,0.28711449855818183,46.63144680400948,252.22379713302365,0.08657189681399023
0.0908690642364403,231.265220399564,0.28850927895069794,46.6230684325521,252.2800745677065,0.08697468519989784
0.0913226210844004,231.183435796581,0.28994932194297124,46.60658065659073,252.295713104822,0.08739037448837084
0.0917767904924657,231.100022746918,0.2913913098135786,46.58976458577867,252.30964111736597,0.08780645211837619
0.0922281116205177,231.016530957575,0.29282425439514365,46.57293264104712,252.322749360915,0.0882197489329022
0.0926795570269519,230.940579686852,0.29425759356057224,46.55762086486937,252.34405031177693,0.08863298874100627
0.093120058404304,230.812250473877,0.2956561854336652,46.5317496955336,252.30550071843325,0.08903604616695301
0.093565376278615,230.724170666665,0.2970700696846026,46.51399280639966,252.31196451166292,0.08944334561058054
0.0939987068081752,230.589211313194,0.29844589411595623,46.486785000739914,252.26429898055127,0.08983952192246844
0.0944375735718285,230.464288311093,0.2998392960905555,46.461600523516346,252.22877649415094,0.0902405998733973
0.0948740751653746,230.39499242565,0.30122518865006437,46.44763047301104,252.25350425476705,0.09063935680650165
0.0953139000534105,230.336741939473,0.3026216326695783,46.43588717499776,252.29103513932012,0.09104098890285546
0.095759494932216,230.302427525257,0.3040363964097858,46.42896938909181,252.3560716667389,0.09144772551511904
0.0962011580532504,230.225546563201,0.30543867681907,46.41347018714132,252.37351075602348,0.09185071005447192
0.096640061258768,230.08494060345,0.3068321944965884,46.38512402565552,252.32036335808743,0.09225101556452278
0.0970963025724302,229.952067313714,0.30828076066746585,46.35833677044474,252.27956281876223,0.09266696465281102
0.0975441768791496,229.888280959807,0.30970276159129995,46.34547744149709,252.31254410019406,0.09307511743877332
0.0979941250895534,229.858610873878,0.311131347159332,46.33949595217381,252.38340434076378,0.09348499251706223
0.0984314875466745,229.798222252648,0.3125199729606915,46.327321606133836,252.41760310455746,0.09388324180024815
0.0988662227537875,229.726817716032,0.3139002572432753,46.31292645155205,252.43904044886398,0.09427894167354942
0.0993083070759532,229.568116672267,0.3153038749661514,46.28093232112903,252.36613769760476,0.09468117027016618
0.0997507821712326,229.447595784568,0.31670873339366346,46.2566353101689,252.3351729313875,0.09508359247283851
0.100199204485156,229.347827974984,0.3181324742403703,46.23652211975678,252.32829788847582,0.09549125839511273
0.100664095546796,229.294160492518,0.3196085033610773,46.22570275529162,252.37584977265917,0.09591372086113445
0.101115497338033,229.282344320674,0.3210417040482548,46.22332061504788,252.4663425974891,0.096323754453071
0.101566138972965,229.245777869348,0.3224724912391639,46.215948818460554,252.52938640339164,0.09673292991791393
0.102015431722668,229.15375720282,0.3238989957194709,46.197397452088516,252.53097667473713,0.09714071401077802
0.102466945738889,229.020791522872,0.32533255272097256,46.170591571011,252.4878525409235,0.09755034670020278
0.10290848970178,228.835714758275,0.3267344548031515,46.13328009526824,252.3848525538764,0.09795077191732926
0.103356617290758,228.654695744563,0.32815725989815664,46.0967866621039,252.28767162436853,0.09835700378286565
0.103795152354872,228.582117578618,0.32954960872671857,46.082154903849386,252.30783329828992,0.09875438023510204
0.104239428089746,228.523214793188,0.3309601841849435,46.070280102306704,252.34434400846013,0.09915679761099312
0.104697302173707,228.541450400168,0.33241393440151973,46.07395640067387,252.46912369193166,0.09957136275832895
0.105151170809026,228.527905229585,0.33385496731865755,46.071225694284344,252.55788202701,0.09998213177462106
0.105618583999245,228.487450006081,0.3353390041976028,46.063069921225924,252.61997093732154,0.1004049828618199
0.106075364893692,228.40583403382,0.33678928353747206,46.04661614121812,252.63406622280553,0.10081804263545663
0.106533516576844,228.290719752969,0.33824391513147967,46.023409102198556,252.6113329301116,0.10123217067546994
0.106994458880958,228.155411796884,0.33970740694704166,45.996131018251816,252.56677662285375,0.10164864818638218
0.107452930840029,228.036491263926,0.3411630554170921,45.97215663880748,252.5396805887115,0.1020627216638103
0.107906910053932,227.941435892927,0.3426044394212341,45.95299347601408,252.5378919133892,0.10247256859872148
0.108360059255398,227.819670940422,0.34404318813588863,45.92844566158907,252.50622398307138,0.10288149876287213
0.108812680677046,227.695777549012,0.34548026114962105,45.90346875388082,252.47196548296435,0.10328978578515388
0.109274991035224,227.607341309506,0.3469480965368362,45.88564000799641,252.47913149065346,0.10370664069198962
0.109740147362675,227.538731303937,0.3484249678764931,45.871808230873704,252.50886520794714,0.10412588644314752
0.110204640680242,227.471143712082,0.3498997341597683,45.85818257235574,252.53951936999567,0.10454435930503794
0.110670409620908,227.409115840796,0.3513785505463829,45.84567775350448,252.5765758424254,0.10496380563762794
0.111128277138079,227.254091962249,0.3528322799134008,45.8144249395894,252.5084476745923,0.10537596496275632
0.111580398048655,227.086889832706,0.3542677638044796,45.78071699027353,252.4253353918704,0.10578278473347907
0.11202966112665,226.921071246976,0.35569417407711373,45.74728796339036,252.34296196127113,0.10618686914769948
0.112480569593624,226.810041227196,0.35712580845975617,45.72490431140272,252.32176385398432,0.10659226937191285
0.112937245819145,226.762305889121,0.35857575547578535,45.7152808672468,252.37221617183684,0.10700268779201234
0.113410465098705,226.739009747102,0.36007822668838835,45.710584365015755,252.4535862985406,0.10742779594952585
0.11388240566608,226.70203743369,0.361576637989804,45.703130746631906,252.51941082604037,0.10785157548982142
0.114362995566813,226.629519817262,0.36310251092463125,45.68851119516002,252.5475505874325,0.1082829372311441
0.114826732213793,226.532198410636,0.36457487477879275,45.668891199584216,252.54415049533594,0.10869899571902457
0.115295735181455,226.439545026962,0.3660639592011196,45.65021227743554,252.54705884499978,0.10911960309053277
0.115766279744488,226.308658197953,0.3675579381887494,45.62382549270733,252.50756963149698,0.10954141527402379
0.116231630856889,226.212219124965,0.36903542797062255,45.604383375592946,252.5052342736156,0.10995839695391989
0.116696192295757,226.054217026358,0.3705104105390285,45.57253015251377,252.43388340573267,0.11037449768118389
0.117170009142458,225.919313050071,0.3720147790273041,45.54533351089432,252.39028102560562,0.11079871006552576
0.117642171753458,225.797901540346,0.3735138953172291,45.520856950533755,252.36125705492577,0.11122126245902145
0.118119409587373,225.707627588195,0.3750291254399093,45.50265772178012,252.36807929827927,0.11164817545828418
0.118594558525391,225.634670086168,0.3765377233181164,45.487949489371466,252.39371417305932,0.11207303885337105
0.119068441243166,225.502320151153,0.37804230094705205,45.461267742472444,252.35252990826814,0.112496590321942
0.119542775303424,225.345612464559,0.37954831158837116,45.429675472855095,252.28405238102224,0.11292036561963603
0.120006784081899,225.196077096048,0.3810215394600293,45.39952914256328,252.2211340962041,0.11333474250463958
0.1204827957588,225.058202587022,0.38253287653419,45.371733641543635,252.1738440431568,0.11375966006582454
0.120945663607473,224.931079492591,0.38400248195372677,45.34610562570635,252.1355181677677,0.11417267155706222
0.121420510047269,224.762728029448,0.38551011940007907,45.312165970736714,252.05353310639916,0.11459619422028523
0.121893775156733,224.614534794449,0.38701273612262727,45.28229021456092,251.99364839561778,0.11501812807022037
0.122367074538214,224.529429933067,0.3885154616588294,45.26513307450631,252.0044394217093,0.11543991450254354
0.122844480872572,224.462796802801,0.3900312267704161,45.25169983544468,252.03681255124667,0.11586518074563093
0.123322448642245,224.456949978185,0.39154877443912783,45.2505211156021,252.1375306642647,0.11629076601323221
0.123800643579926,224.33587370526,0.393067043366265,45.22611213898042,252.10879924803618,0.11671637237770277
0.124285914156721,224.144900559715,0.3946077774475891,45.187611952838544,252.00295442934652,0.11714809114997345
0.124766238578162,223.990447251227,0.3961328074856644,45.15647416584737,251.93689283220283,0.11757522613495786
0.125247294552347,223.800575401433,0.39766016020370176,45.11819600092889,251.83099198972104,0.11800282887994719
0.12573211083303,223.710441070648,0.39919945189487016,45.10002491984264,251.83802704184873,0.11843358918545663
0.126219943158958,223.610556717479,0.4007483195296916,45.07988823424376,251.83466847610214,0.11886684204507585
0.126714569993779,223.523132989909,0.40231875973024833,45.06226361076565,251.8467706703876,0.11930593766892172
0.127211554646599,223.387390336376,0.4038966860029518,45.0348978918134,251.80484754951306,0.11974693230085856
0.127703956691303,223.162159403384,0.405460062494887,44.989491335722214,251.6608501429714,0.12018366888815397
0.128203152887632,222.971516955006,0.4070450104182316,44.951057818129215,251.55716843277585,0.12062623693748305
0.128703901900275,222.790007550312,0.4086348885333731,44.9144655221429,251.46395082642886,0.12106998495962479
0.129195152175708,222.624880333142,0.4101946081578729,44.881175875161425,251.38693562588105,0.12150512423859089
0.129691067346861,222.422616553295,0.4117691388262837,44.840399497144276,251.2688430961734,0.12194420361747622
0.130178207738245,222.209345478619,0.4133158095689279,44.7974040484896,251.1361598157141,0.12237532625301974
0.130673594020227,222.006531201163,0.41488866101422067,44.756516690154456,251.01692252918264,0.12281355602953568
0.131169707168076,221.856011396837,0.41646382025864126,44.72617189760234,250.95679944523744,0.12325223642401242
0.131675868783924,221.776232994863,0.4180708833889587,44.71008857176438,250.9788111500875,0.12369960378276541
0.132182046525144,221.634358484765,0.4196779977173322,44.68148667052862,250.93044156956864,0.12414678533619436
0.13268766619787,221.453111050056,0.42128334017823726,44.644947187691294,250.83720752754567,0.12459327431371511
0.133197232708207,221.253283502494,0.42290121384855717,44.604661954102795,250.7236085926306,0.12504304695589408
0.133710590094953,221.024216801878,0.42453112355147576,44.558482107258605,250.57749525573195,0.12549596117707038
0.134232051183174,220.791532552326,0.4261867625065774,44.511572962548925,250.42883285070127,0.12595581504455294
0.134746082551463,220.535904686119,0.427818812100895,44.46003838472159,250.25225390451638,0.12640891009156152
0.135263337489217,220.284762529975,0.429461096528264,44.40940812604296,250.08121470779903,0.1268646394309552
0.135772686032646,220.031322544963,0.431078278153651,44.358314625064544,249.90556621820812,0.12731319995284385
0.136281909964167,219.723671159971,0.4326950641362302,44.296292105850156,249.6680327299904,0.12776144969203992
0.136800051710848,219.414422726101,0.4343401641819424,44.23394762158197,249.4303271011375,0.1282173432888317
0.13730801098604,219.087920289729,0.435952934880677,44.16812473040937,249.17044685577977,0.12866407604702557
0.137822639014513,218.69944520108,0.4375868788710787,44.089808152537735,248.84117988970272,0.1291164703191961
0.13832592949407,218.503575753944,0.4391848261436722,44.05032087199511,248.72828596788625,0.12955870022872176
0.13882893417362,218.247596169067,0.44078186600124347,43.99871538768391,248.5466773311732,0.1300004836978714
0.139329935840323,218.004558205159,0.44237254629302547,43.94971893416005,248.37911931278177,0.13044031401995654
0.139859544450349,217.709254666754,0.44405405362985806,43.89018574081761,248.15797184707122,0.1309050481933438
0.140410381335514,217.327078815805,0.44580296074025694,43.813139089266286,247.8420568268655,0.13138818125548754
0.140955161981106,216.947411688896,0.4475326392900115,43.73659819648144,247.52726924488604,0.13186577298342705
0.141501522962128,216.499196513696,0.4492673354047564,43.64623801716112,247.134162540461,0.1323445211630193
0.14202299140355,216.123276813488,0.4509229977062712,43.57045260559918,246.81775109847706,0.13280124360870027
0.142553773548155,215.68545693694,0.45260823101539205,43.4821881184871,246.4322327227589,0.13326590924156334
0.143091097413806,215.295568962953,0.454314234288834,43.40358670293133,246.1024481941917,0.13373608191132139
0.143639418033903,214.77843551428,0.45605515225764204,43.29933259967885,245.62908499778334,0.13421564924722004
0.144156141222984,214.294295083098,0.4576957483829742,43.20172988875256,245.18613374837688,0.1346673707271196
0.144685442670156,213.738746951794,0.4593762804777453,43.08973138548168,244.6636321702788,0.13512987670423238
0.145218707901978,213.239105970754,0.4610693975887801,42.989003763704005,244.20541341399985,0.13559563003397646
0.145756675414402,212.743046585398,0.46277744444072627,42.88899819161624,243.75176577321685,0.1360652706300558
0.14630337318504,212.204218757208,0.46451320986250194,42.780370501453135,243.25041176548368,0.13654230680660756
0.146848889172814,211.60217514517,0.4662452231236844,42.658998509266276,242.67571951178942,0.13701808506784124
0.147421387752618,210.951289584614,0.46806290611456214,42.52777998025818,242.05002144338218,0.13751715320069782
0.147998180884931,210.17330976499,0.4698942243096559,42.37093924862198,241.2785772807736,0.13801971330111126
0.148570422208583,209.47468353585,0.47171109051225096,42.23009620082737,240.59642571078058,0.13851805794862082
0.149121475874883,208.775579886105,0.47346068590275353,42.08915690503876,239.90850248535554,0.13899771640702846
0.149628092919225,208.069453283244,0.47506919501853934,41.946801781901996,239.2024887727616,0.1394384926093792
0.150136034414728,207.238948070323,0.4766819092667614,41.77937193097712,238.35298190988104,0.1398802261747699
0.150676949019704,206.27877090985,0.4783993131375602,41.58580021542576,237.36022675808067,0.14035042050941252
0.151221180567198,205.339388253611,0.4801272483008536,41.39642067192797,236.39105296226825,0.14082327510765844
0.151771340280472,204.391447220488,0.4818740053904986,41.20531575965038,235.4122111070068,0.14130105323221526
0.15228343503897,203.345123028822,0.4834999062487297,40.99437680261052,234.31121686207297,0.14174556937168878
0.152776725006916,202.400543806758,0.48506610189695826,40.803949631442414,233.32263602917334,0.14217357553311305
0.153274243234306,201.468894943578,0.4866457222689215,40.616129220625325,232.3488873513068,0.1426050648990991
0.153780437822865,200.404239132506,0.4882528900875963,40.401494609113215,231.2224907678609,0.1430438881318887
0.154288689499803,199.519870173167,0.48986658916187453,40.223205826910466,230.30352947135577,0.14348430101132692
0.154808902800712,198.389304298725,0.49151826639226054,39.99528374662296,229.10173482460718,0.1439348781644492
0.1553762788883,197.128055514912,0.49331968547035243,39.741015991806265,227.75707924530525,0.14442607350540523
0.155961962268108,195.817202630561,0.4951792302012428,39.476748050321106,226.35723779867502,0.14493286509645367
0.156557094556152,194.403836534836,0.4970687752157826,39.19181344542294,224.83913635329904,0.14544756987211946
0.157104941972395,192.990858854457,0.4988081907623541,38.906957145058534,223.31067653598916,0.14592114588956065
0.157613408269559,191.476548330303,0.5004225712558498,38.60167214338908,221.65581971633299,0.14636047908557492
0.158102038230644,189.869674629868,0.5019739713822947,38.277726405381394,219.8884571870393,0.14678249118475165
0.158570845645141,188.206678866344,0.5034624349233227,37.94246645945495,218.05077109024367,0.14718721592958672
0.159028145165242,186.53920538061,0.5049143608996433,37.60630380473098,216.20418921288655,0.14758184807073702
0.159501126608245,184.75387251277,0.5064160769811779,37.246380698574434,214.22232332379284,0.1479898493457887
0.159977866930014,182.936783953975,0.5079297275027944,36.88005564512136,212.20262043396875,0.1484009247034968
0.160469633105891,180.929217686411,0.5094910851112039,36.47533028558046,209.96286286668524,0.14882477931191318
0.160960996715419,178.790112084958,0.5110511645714553,36.04408659632753,207.56834672901434,0.149248107591082
0.161420622404047,176.718511428749,0.5125104761328492,35.6264519040358,205.24452353389438,0.14964393030242717
0.161944468576785,174.372187742963,0.5141736877312924,35.15343304898134,202.61079902156854,0.1500948677669249
0.162464567581034,172.606949295336,0.5158250020697829,34.79756097793974,200.64946267408425,0.15054237851467922
0.162825836986532,171.479881397187,0.5169720324322391,34.5703440896729,199.40123661203523,0.15085310908639202