File: example/data/02 processed data/test_ID_134.csv
Strain,Stress_MPa,Displacement(mm),Force(kN),True Stress (MPa),True Strain
0.00025337238849580044,0.0516702948657722,0.0001295871846615,0.0104167314449396,0.051672403781691,4.081402840690082e-05
0.0002570298190704004,0.276829630454757,0.0001411995267361,0.055808853499679,0.276841941702885,4.447130302225645e-05
0.0002654797458660004,0.722957343231554,0.0001680280443121,0.1457482003954812,0.7229956037381695,5.2920818349708e-05
0.0002673823388575004,1.19296616737537,0.0001740687770599,0.2405019793428746,1.193031571520828,5.48233088474562e-05
0.00027839785106300045,2.23002347238746,0.0002090430283123,0.4495727320333119,2.2301702978551377,6.583815649902845e-05
0.00028086577604720045,3.58286305577724,0.0002168786901373,0.7223051920446916,3.583107794878493,6.830591595997574e-05
0.00028718173857990043,5.16212618560651,0.0002369318711787,1.0406846390182725,5.162511405202232,7.462142714697555e-05
0.00029814813176110044,7.00407314827232,0.0002717501695291,1.4120211466916996,7.004672631127575,8.558694190922055e-05
0.00031474622824960045,8.94036923084659,0.0003244491258801,1.8023784369386728,8.941282835565328,0.0001021834801549
0.00033726962863300043,10.9109287980297,0.0003959609220974,2.1996432456827875,10.912289522888852,0.0001247043255404
0.00036940464841370043,13.0062165191687,0.0004979896099011,2.62205325026441,13.00825650678781,0.000156834822005
0.00040248859136330045,14.9073911320599,0.0006030311287661,3.005330052223276,14.910222508721732,0.0001899130295571
0.00044422509760530044,16.8129869050475,0.0007355445360844,3.389498160057576,16.8168819288753,0.0002316407396325
0.00048193471444430043,18.8773732113895,0.0008552725695482,3.8056784394161234,18.88245834508803,0.0002693409117391
0.0005222349574726004,20.96000001455,0.0009832258411631,4.22553600293328,20.966490853493333,0.0003096294901291
0.0005635195474307004,23.0406519720787,0.00111430441428,4.644995437571065,23.0487383658426,0.0003509004474819
0.0006011815431564004,25.1423373939171,0.0012338812507091,5.068695218613688,25.15210831004603,0.0003885485212172
0.0006364224073434004,27.3495990962217,0.0013457709945029,5.513679177798294,27.361191630765,0.0004237750748161
0.0006753540432521004,29.5464961429663,0.001469378938513,5.956573622422006,29.560170158443256,0.0004626894587886
0.0007185927858399004,31.7061557052557,0.0016066619462293,6.391960990179549,31.722200137958964,0.0005059072659908
0.0007611498842032005,33.791532662187,0.0017417807335327,6.8123729846969,33.810070438737405,0.0005484419352419
0.0008092886333598004,35.9178955169909,0.0018946212621049,7.241047736225367,35.93932884251423,0.0005965531329661
0.0008511310125143004,38.064105732829,0.0020274708159205,7.673723715738326,38.08841246149276,0.000638369684038
0.0008928455228683004,40.2143900006054,0.0021599143862944,8.10722102412205,40.24174736737654,0.0006800567046951
0.0009453099569044004,42.2812050439314,0.002326488964359,8.52389093685657,42.3121866996588,0.0007324840977303
0.0009943438725835004,44.3737580072893,0.0024821716466402,8.945749614269522,44.40844880539341,0.0007814809096335
0.0010459200733601004,46.5266414508341,0.0026459260841059,9.379770916488154,46.56541501121855,0.0008330154924095
0.0010977481401029004,48.6905925079124,0.0028104801960143,9.81602344959514,48.733692963337816,0.0008847990627546
0.0011446895966788005,50.8176206546602,0.0029595193206428,10.244832323979496,50.86498938856778,0.0009316979041748
0.0012012101556265005,53.0086988961938,0.0031389720953017,10.686553697472672,53.06110608568778,0.0009881642333072
0.0012469474824870004,55.1549002448207,0.0032841881080838,11.119227889355855,55.21195191961963,0.0010338553426457
0.0012901016127842004,57.3134307992579,0.0034212024717774,11.554387649130392,57.375188547641045,0.0010769639516802
0.0013346351140019004,59.4419976347077,0.0035625963381436,11.983506723157072,59.50869616796922,0.0011214485282857
0.0013771803224518005,61.5368714532628,0.003697677374972,12.40583328497778,61.60853869650667,0.0011639451482236
0.0014221830028400004,63.6308840223544,0.0038405608852046,12.827986218906648,63.70785356070629,0.0012088944681968
0.0014606310200197005,65.7454431752392,0.0039626333397501,13.254281344128223,65.82749832014089,0.001247295296543
0.0015011615328827004,67.792859303003,0.0040913177180901,13.667040435485406,67.88021745305855,0.0012877744681097
0.0015551279702881004,69.8525578051467,0.0042626611568523,14.082275653517575,69.94633978463105,0.0013416700012534
0.0015998148600425005,71.8701720836858,0.0044045420318225,14.48902669207106,71.96987450692262,0.0013862959803965
0.0016456402332846005,73.8728736748252,0.0045500375918662,14.89277133284476,73.97873961253846,0.0014320568230781
0.0016918656242333003,75.8730607759864,0.0046968032081283,15.296009052438858,75.98530040914017,0.001478214998712
0.0017375105475168004,77.8558083955333,0.0048417258395534,15.695730972539511,77.97453484569645,0.0015237914602078
0.0017940326858867004,79.7632719013807,0.0050211836288778,16.08027561531835,79.8894155344695,0.0015802259437578
0.0018405625605806004,81.6866376126164,0.005168915981031,16.468026142703465,81.8196238698109,0.0016266812697358
0.0018858903408511005,83.6655175743737,0.0053128316833898,16.866968342993736,83.80551783030324,0.001671934352157
0.0019317483930537005,85.5997712635695,0.0054584309991331,17.25691388673561,85.74693360844627,0.0017177147488278
0.0019812586404180004,87.5508150249449,0.0056156260345147,17.650244309028892,87.70566624894397,0.0017671388033206
0.0020222315870742002,89.4454146243019,0.0057457151401482,18.032195588259267,89.60728167092354,0.0018080385726229
0.0020654093143469003,91.3226805992824,0.005882804424239,18.41065240881533,91.4918879912392,0.0018511373746641
0.0021032478603261002,93.2257684110701,0.0060029418077229,18.794314911671734,93.40202947020455,0.0018889052278731
0.0021472533980075002,95.0757643060952,0.0061426593898614,19.1672740841088,95.25970699471348,0.0019328267571554
0.0021852493216806003,96.8111299173746,0.0062632964475235,19.51712379134272,97.00210843897844,0.001970748593176
0.0022369065761467005,98.623109567086,0.0064273082304533,19.88241888872454,98.82275716514378,0.0020223028154875
0.0022706041066091003,100.399145089637,0.0065342978896715,20.240467650070823,100.60577120676584,0.002055931702742
0.0023162191212428005,102.153691059341,0.0066791255611335,20.594184117563145,102.36858785591376,0.0021014519962945
0.0023618189603028003,103.961224485353,0.006823905050149,20.95858285624717,104.18466433567907,0.0021469550748172
0.0023958358362672003,105.73767110123,0.0069319086313359,21.31671449400797,105.9685258649982,0.0021808984203382
0.0024294409747923004,107.476609994582,0.0070386049461531,21.667284574907733,107.71487311228394,0.0022144297871475
0.0024755735522697005,109.18883731673,0.0071850758796439,22.012469603052768,109.43593340533812,0.0022604592609254
0.0025094792171860003,110.893738125273,0.0072927263657531,22.35617760605504,111.14845235765824,0.0022942877978343
0.0025621171679179005,112.526700238405,0.0074598518593269,22.68538276806245,112.79108843179,0.0023468037414025
0.0026047077302161006,114.174715596003,0.0075950768946237,23.017622664154207,114.447838665097,0.0023892935664962
0.0026449595049978006,115.716025680978,0.0077228762795556,23.32835077728517,115.99749357070904,0.0024294484765539
0.0026938939597169003,117.279836463367,0.0078782431732887,23.64361503101479,117.57084719438495,0.0024782630003825
0.0027472063670737003,118.880768640369,0.0080475100666466,23.96636295789839,119.1820896426884,0.0025314420351242
0.0027865175409763003,120.519594867806,0.0081723230437873,24.29675032534969,120.82980748587408,0.0025706530521574
0.0028282727642405005,122.096115769425,0.0083048958776512,24.61457693911608,122.41548443982836,0.0026123002078211
0.0028658470830978003,123.723682459214,0.0084241943400231,24.942694383777543,124.05195721370212,0.002649775797153
0.0029013089792722002,125.3126057486,0.0085367858603768,25.263021318917765,125.6495401992714,0.0026851432262029
0.0029415980586310004,126.853563263842,0.008664703687341,25.573678353990548,127.19975177954736,0.0027253234614887
0.0029805683260973005,128.381868728317,0.0087884342865465,25.881784735628703,128.73723112734152,0.0027641869117695
0.0030200895205661003,129.880156909572,0.0089139140789849,26.18383963296972,130.244799605401,0.0028035982364797
0.0030697592332694004,131.371272976556,0.0090716154168179,26.48444863207369,131.7466272018351,0.0028531276636854
0.0031127627115572006,132.840171955635,0.0092081514603817,26.780578666256016,133.2254357110336,0.0028960077030628
0.0031615600142903006,134.279861038535,0.0093630828965593,27.07081998536865,134.67585268270577,0.0029446627091879
0.0032150886300995004,135.779738945961,0.0095330362517535,27.373195371505737,136.18742183529184,0.0029980325089319
0.0032598238104606003,137.281234782,0.0096750704494,27.6758969320512,137.69956726007766,0.0030426327780048
0.0033184535199351005,138.728123538148,0.0098612197769815,27.96758970529064,139.15899866112687,0.0031010826616863
0.0033625420317541003,140.14171216548,0.0100012008020068,28.252569172560765,140.58315638724503,0.0031450336972991
0.0034039954139846004,141.549120691905,0.0101328152905887,28.53630273148805,142.0008659185243,0.003186356058263
0.0034274649448964006,142.946820657925,0.0102073310512336,28.81807904463768,143.40638145199642,0.0032097506522522
0.0034594403388510005,144.352655011109,0.0103088529270395,29.101495250239573,144.82135116548292,0.0032416230697715
0.0035046396178931003,145.641776211882,0.0104523606379982,29.36138208431541,146.12124089500804,0.0032866750521554
0.0035503869025791004,146.945031025312,0.0105976082668762,29.6241182547029,147.4355084664365,0.0033322711876784
0.0035907561051214004,148.300938789316,0.010725780484948,29.89746925992611,148.80192880984072,0.0033725052835699
0.0036363238767327002,149.631694826571,0.0108704581598139,30.16574967703671,150.14399878814402,0.0034179186052783
0.0036902316348446005,150.890521992969,0.0110416152918192,30.419529233782555,151.41527005439522,0.0034716409825093
0.0037676091594895005,152.138146120763,0.0112872889325667,30.671050257945826,152.67900508546538,0.0035487473731433
0.0038233549731841003,153.334459856529,0.0114642818910471,30.912227107076248,153.88811953256263,0.003604294166882
0.0038786583467080005,154.595163167867,0.0116398701019855,31.166384894642,155.161924622251,0.0036593970513775
0.003940248108430501,155.74988547725,0.0118354175954544,31.3991769122136,156.3304728583736,0.0037207599608433
0.0039932598465092,156.79608428059,0.0120037298638543,31.610090590966948,157.38888360009057,0.0037735734268078
0.004060347171445501,157.843323968967,0.012216732120527,31.82121411214375,158.45067187635047,0.003840405836519
0.004120108289007201,158.81814726251,0.0124064736687854,32.01773848812201,159.43873723483682,0.0038999361153101
0.0041894463064517,159.693873868512,0.0126266218741717,32.19428497189202,160.32895864361728,0.0039690018604361
0.004271160326197001,160.525477890935,0.0128860638868631,32.3619363428125,161.1769870448159,0.0040503888878399
0.004348944168634001,161.26638548807,0.0131330275866005,32.511303314394915,161.93344561071763,0.0041278553120516
0.004440903616932,162.001846906886,0.0134249988349467,32.65957233642821,162.68684678278652,0.0042194317541824
0.004538294566310301,162.703024140471,0.0137342150992228,32.80092966671895,163.4068346383731,0.0043164079324916
0.004647990557187001,163.326450716095,0.0140824998702563,32.92661246436475,164.05087425027418,0.004425625486694
0.0047639788762231,163.94598879206,0.0144507627831959,33.051511340479294,164.69217606553735,0.004541094952223
0.0048912702619376,164.528111458661,0.0148549129328395,33.16886727006606,165.29789122896742,0.0046678015785326
0.005025924165850501,165.044372184589,0.0152824390777629,33.272945432413145,165.83879125956182,0.004801819428612
0.005166716871313801,165.49288140638,0.0157294559176089,33.36336489152621,166.31275951118624,0.0049419278778465
0.0053083142101809,165.865329652608,0.0161790274685119,33.43845045796577,166.7105390146626,0.0050828172537493
0.005467925240592501,166.17245109828,0.0166857924900688,33.500366141413245,167.04574843263967,0.0052416064610773
0.0056237797162131,166.415984768292,0.0171806304501642,33.549462529287666,167.31649863767913,0.0053966341287329
0.005780948152148,166.586421167207,0.0176796402342575,33.58382250730893,167.51403943308063,0.005552944451576
0.0059465746590822,166.721001859967,0.0182055043937736,33.61095397496935,167.6769829408791,0.0057176402294657
0.0061160952924319,166.828668306892,0.0187437324046589,33.63265953066943,167.8135476505676,0.0058861801668301
0.00628114562192,166.893991058351,0.0192677672007836,33.64582859736356,167.90680194557052,0.006050248374075
0.006463247130341701,166.930758470756,0.0198459394900225,33.65324090770441,167.9741908271762,0.0062312350703084
0.0066337005777969,166.955090490534,0.0203871291856927,33.658146242891654,168.02713300960156,0.0064006153389615
0.0068135713367062,166.946164897028,0.0209582188452298,33.65634684324085,168.0481788369599,0.0065793225218656
0.007000667865429501,166.922811503477,0.0215522503239262,33.65163879910096,168.0559019659326,0.0067651748511725
0.007179433086784901,166.859746720641,0.0221198299017296,33.63892493888123,168.02223781195008,0.0069427190142676
0.0073782147263827,166.769760237235,0.0227509616074526,33.62078366382658,167.9647751702874,0.0071401058664335
0.007584632371675001,166.657870627976,0.0234063376312557,33.59822671859996,167.88648492366875,0.0073450339178982
0.007776391773043101,166.56550646075,0.0240151737305994,33.5796061024872,167.82538034269652,0.0075353718845619
0.007981598154489,166.451405729994,0.0246667039916902,33.5566033951668,167.7445734635822,0.0077390170339202
0.0081990861790136,166.337288944093,0.0253572284695558,33.53359745112915,167.66574646811247,0.0079548051271623
0.0084099085092335,166.219879676369,0.0260265893680039,33.50992774275599,167.5824423702701,0.008163935190266
0.0086230411204349,166.094280150204,0.0267032854085684,33.48460687828113,167.49121336833997,0.0083753125422139
0.008822057803667,165.977949763125,0.0273351633778303,33.461154672246,167.40693696750054,0.0085726498868804
0.0090289543215146,165.852964303104,0.0279920598219964,33.43595760350576,167.31518984591594,0.0087777592977125
0.0092442556219738,165.705236251286,0.0286756414509544,33.40617562825926,167.20183591783328,0.0089911562345995
0.0094602757927066,165.547221983416,0.029361505493031,33.37431995185666,167.0781560519584,0.0092052199264813
0.0096607669103277,165.390405197101,0.029998064791478,33.34270568773556,166.95304837536602,0.0094038542185849
0.0098757867739146,165.238420821149,0.0306807528583664,33.31206563754364,166.83515756191133,0.0096168388615183
0.0101054068940403,165.097928241003,0.0314097967397655,33.2837423333862,166.7312171758711,0.0098442354894671