File: example/data/02 processed data/test_ID_057.csv
Strain,Stress_MPa,Displacement(mm),Force(kN),True Stress (MPa),True Strain
1.65078241212904e-05,0.115951865856047,5.241234158509701e-05,0.023375896156579076,0.11595377996905508,1.6507687868585534e-05
2.83479347763795e-05,0.116554883395377,9.00046929150049e-05,0.023497464492508006,0.11655818748560938,2.834753298135289e-05
1.31576219404707e-05,0.14162527322999,4.1775449660994473e-05,0.028551655083165987,0.14162713668179236,1.315753537968119e-05
-5.48035773065248e-05,0.182220952605231,-0.00017400135794821622,0.03673574404521457,0.18221096624516803,-5.4805079077383884e-05
-0.0001258903748526,0.297987768355316,-0.00039970194015700495,0.0600743341004317,0.29795025456345625,-0.00012589829971091144
-0.0002116202014949,1.0187655575925,-0.0006718941397463075,0.20538313641064804,1.0185499662199262,-0.0002116425962092452
-0.0002433286436055,2.92680848993344,-0.0007725684434474624,0.5900445915705815,2.926096313593491,-0.00024335825282322223
-0.0002454405631937,6.30928495602898,-0.0007792737881399974,1.2719518471354425,6.3077364015760224,-0.000245470688658227
-0.0002342844950054,10.9790476639074,-0.0007438532716421449,2.2133760090437318,10.976475443269821,-0.00023431194390501712
-0.0001804763370381,16.3222613679512,-0.0005730123700959675,3.290567891778962,16.319315586007335,-0.00018049262485195943
-0.0001346850233487,21.8615083760783,-0.0004276249491321225,4.4072800886173855,21.85856395831223,-0.00013469409419091704
-7.12373817969221e-05,27.5512326211686,-0.00022617868720522767,5.5543284964275905,27.549269943491392,-7.123991929972257e-05
-4.86958175104037e-06,33.4278534780555,-1.5460922059553172e-05,6.73905526117599,33.42769069839023,-4.86959360750638e-06
6.79710457445897e-05,39.4716490260716,0.0002158080702390723,7.9574844436560355,39.47433195533316,6.796873581766099e-05
0.0001622597866351,45.7600453747415,0.0005151748225664424,9.225225147547887,45.76747038994042,0.0001622466239397404
0.0002475820472115,52.1094128420445,0.0007860729998965124,10.505257628956171,52.12231419715492,0.00024755140383410373
0.0003469183395392,58.5849873122392,0.00110146572803696,11.810733442147423,58.60531151875949,0.00034685817728596224
0.0004565749812589,65.1743389112355,0.0014496255654970075,13.139146724505077,65.20409588380245,0.0004564707826172057
0.0005544128525034,71.8581052886516,0.001760260806698295,14.486594026192163,71.89794434578018,0.0005542592224783013
0.0006653693983528,78.6158578218243,0.00211254783977014,15.848956936879782,78.6681664078442,0.000665148138275595
0.0007654524996154,85.3940840897397,0.002430311686278895,17.215447352491527,85.45944920485857,0.0007651596902624496
0.0008514295852429,92.1730051871994,0.0027032889331462073,18.5820778457394,92.25148401077652,0.0008510673246852099
0.0009593180398552,98.928361555633,0.00304583477654026,19.943957689615612,99.02326531752665,0.000958858188376857
0.0010604613200042,105.597018103817,0.0033669646910133347,21.28835884972951,105.7089996570239,0.0010598994281066424
0.0011685333621808,112.292226547974,0.0037100934249240393,22.638112872071556,112.42344376100885,0.00116785115847158
0.0012979623031145,118.865478909064,0.004121030312388537,23.963280548067303,119.0197618198296,0.0012971206782304533
0.0014140648812821,125.462270927928,0.004489655998070667,25.293193819070286,125.6396827191731,0.001413066033051174
0.0015255557687303,131.933989148338,0.004843639565718702,26.597892212304938,132.13526180657485,0.0015243932906618502
0.0016330546097756,138.402507840204,0.005184948386037529,27.90194558058513,138.62852669363696,0.0016317226260339503
0.0017394469286531,144.813353997691,0.005522743998473592,29.194372165934507,145.06524914153024,0.0017379358428928871
0.001844188102062,151.114414855024,0.005855297224046849,30.464666034772836,151.3930982609497,0.0018424896750095906
0.00194331650786,157.303989901935,0.0061700299124555,31.7124843642301,157.60968134226368,0.0019414307110732004
0.0020566360707786,163.416940343,0.006529819524722055,32.9448551731488,163.75302951708568,0.0020545240900361776
0.0021678214943205,169.508267605183,0.0068828332444675865,34.17286674920489,169.87573127116255,0.0021654751596495926
0.0022756395523288,175.55196425924,0.0072251555786439405,35.39127599466279,175.95145725259738,0.002273054206110686
0.0023837206302539,181.527555389651,0.007568313001056132,36.595955166553644,181.9602663683929,0.0023808840750415526
0.0024929955279744,187.397618156833,0.00791526080131872,37.77935982041753,187.86479958085104,0.0024898931696636945
0.0025918821104755,193.165514324598,0.008229225700759712,38.94216768783896,193.66617656553674,0.002588528976740114
0.0027099684251656,198.8325495876,0.008604149749900779,40.084641996860164,199.37137951887757,0.00270630308121728
0.0028222510802823,204.460127584014,0.008960647179896301,41.21916172093723,205.03716539996262,0.002818276007048948
0.0029460591869107,210.029346611332,0.009353737918441471,42.34191627684453,210.64810549743714,0.002941728058965277
0.003070428499822,215.594399718459,0.00974861048693485,43.46383098324133,216.25636690775656,0.0030657243609240347
0.003189667868897,221.009896852014,0.010127195483747974,44.555595205366025,221.71484501871112,0.003184591669735295
0.0033128796363333,226.241631765586,0.010518392845358228,45.610312963942135,226.991143060353,0.00330740414036426
0.0034597411392415,231.295178849979,0.010984678117091761,46.629108056155765,232.09540029555447,0.003453770003292495
0.0036242223405696,236.063752442916,0.01150690593130848,47.59045249249187,236.9192999683183,0.003617670671813815
0.003829686210133,240.622723393516,0.012159253717172275,48.50954103613282,241.5442329191408,0.003822371630979775
0.0040839948653348,244.760266339245,0.012966683697437989,49.343669693991785,245.75986601021245,0.004075677994653135
0.0043806466114275,248.297180588499,0.01390855299128231,50.0567116066414,249.38488279127102,0.004371079508947964
0.004715011054273,251.072088473677,0.014970160097316774,50.616133036293284,252.25589614624982,0.004703930206879399
0.0050720777130858,253.015385080835,0.016103846739047415,51.00790163229634,254.29869877657129,0.005059258056844344
0.0054440865274579,254.266193216353,0.017284974724678832,51.260064552416765,255.65044037323014,0.005429321053834104
0.0058234240874187,255.067910293116,0.018489371477554372,51.42169071509218,256.5532789058445,0.00580653349569648
0.0062106831595887,255.629770794248,0.01971891903169412,51.53496179212039,257.2174063068094,0.006191476350847167
0.0066047308517031,256.058793803477,0.020970020454157343,51.62145283078097,257.74999321876066,0.006583015181884854
0.0069967821814027,256.414394161655,0.022214783425953573,51.69314186298965,258.20846982578047,0.006972418280875649
0.007389827501615,256.717764436772,0.023462702317627624,51.75430131045323,258.61486443255995,0.007362656503579208
0.0077784486145669,256.988530922887,0.024696574351249907,51.80888783405401,258.9875030052037,0.00774835245004223
0.0081657063938745,257.232515892704,0.025926117800551537,51.85807520396912,259.33300109244146,0.008132547402178121
0.0085510897345642,257.464747572574,0.027149709907241335,51.90489311063093,259.666351732554,0.008514736260941607
0.0089329920790165,257.685439941593,0.02836224985087739,51.94938469222515,259.98734193546915,0.008893328937291759
0.0093110253529959,257.896393778864,0.029562505495761983,51.99191298581899,260.2976736397853,0.009267944965022217
0.0096882813537358,258.088935611799,0.030760293298111162,52.03072941933868,260.5893738342923,0.009641650893377048
0.0100564292043492,258.305321321938,0.031929162723808704,52.0743527785027,260.90295049891876,0.010006199791825545
0.0104332230420071,258.526403718771,0.03312548315837254,52.11892298970423,261.2236673510169,0.01037917259236109
0.010807203339149,258.715851710622,0.03431287060179807,52.1571157048614,261.51184652711987,0.010749222880816197
0.0111766116048138,258.942807946065,0.03548574184528381,52.202870081926704,261.83691113833805,0.011114614796463083
0.0115443830272366,259.140518937491,0.036653416111476204,52.242728617798186,262.13213634598225,0.011478255088378282
0.0119156146196068,259.349213175563,0.03783207641725159,52.28480137619351,262.4395184516613,0.011845182625336858
0.0122775549657858,259.521731699025,0.038981237016369914,52.319581110523444,262.7080240247757,0.012202797062016768
0.0126499104517116,259.723365338617,0.04016346568418433,52.360230452265185,263.0088426523677,0.01257056874419504
0.0130323631417354,259.928750139008,0.04137775297500989,52.401636028024015,263.316236001797,0.012948172576300128
0.0134059161589753,260.132355398072,0.042563783804746576,52.442682848251316,263.6196679447753,0.013316851973335495
0.0137790825251509,260.320139144007,0.0437485870173541,52.48054005143181,263.90711182423104,0.013685014100258226
0.014154833096434,260.496314592709,0.04494159508117795,52.51605702189013,264.18359644800495,0.014055588873616147
0.0145202593945516,260.675647660526,0.04610182357770133,52.55221056836204,264.46072568239964,0.014415849916325822
0.0148897787903214,260.870235922316,0.047275047659270444,52.591439561938905,264.7545360281783,0.014780014272370858
0.0152535992650126,261.060905951714,0.048430177666415004,52.629878639865545,265.04302439486264,0.01513843277868789
0.0156175751888981,261.264509803552,0.049585801224751466,52.67092517639609,265.3448279295996,0.015496875926003975
0.0159817307344321,261.452233604932,0.05074199508182192,52.708770294754295,265.6306928023219,0.015855367434021623
0.0163425881182945,261.638441371935,0.051887717275585034,52.746309780582095,265.9142906551891,0.016210485349314265
0.0166969869977301,261.827250871772,0.053012933717793066,52.78437377574923,266.1989770752294,0.016559124782961267
0.0170408162543167,261.981982635585,0.05410459160745552,52.81556769933393,266.4463694636196,0.016897250237789038
0.0173761706963723,262.180796745945,0.05516934196098205,52.85564862398251,266.7364950235134,0.017226931367315557
0.0177120868376658,262.368417059664,0.05623587570958891,52.89347287922827,267.01550924608574,0.017557055766688257
0.018058948578464,262.552632907569,0.0573371617366232,52.93061079416591,267.2940574043871,0.017897822717509556
0.0184057388041576,262.754396691224,0.05843822070320037,52.97128637295076,267.59058548636665,0.018238403363169172
0.0187623422241931,262.959539659166,0.05957043656181309,53.012643195287865,267.89327653336755,0.01858850056624125
0.0191132008682798,263.138381201034,0.06068441275678836,53.04869765012846,268.1677979370833,0.01893283822586189
0.01946366267722,263.326263420379,0.06179712900017349,53.08657470554841,268.45155698564605,0.01927666809920142
0.0198179121976413,263.478290173972,0.06292187122751113,53.117223299072755,268.6998797946245,0.019624093906749785
0.0201699596645435,263.664067993257,0.06403962193492561,53.15467610744061,268.9821616096704,0.019969240537524184
0.0205190175298641,263.851615309193,0.06514788065731851,53.19248564633331,269.2655912290053,0.02031133859619533
0.020868872080525,264.042287538392,0.06625866885566688,53.23092516773983,269.5525522608799,0.020654100063397764
0.0212281104442042,264.230185204863,0.06739925066034833,53.268805337300385,269.8392927590844,0.021005932880799834
0.0215831042412504,264.399797986336,0.06852635596597002,53.30299927404534,270.10636638764066,0.021353487072854005
0.0219329554146415,264.586667893205,0.06963713344148675,53.340672247270135,270.3898354834152,0.02169588827411293
0.0222863508665556,264.767505964047,0.07075916400131403,53.37712920235188,270.6682075000246,0.022041639294415695
0.0226241481475796,264.965933038969,0.07183167036856523,53.417132100656154,270.96056156210426,0.022372017845711023
0.0229644911322358,265.146283821713,0.07291225934484866,53.45349081845734,271.23523330528195,0.022704775841391443
0.0232946439843578,265.334208144587,0.07396049465033601,53.491376361948745,271.51507406018663,0.023027465034877247
0.0236279573967782,265.523638473337,0.07501876473477077,53.52956551622474,271.7974196910225,0.023353137744867834
0.0239596335170394,265.694029126812,0.07607183641660009,53.5639162719653,272.05996069235596,0.023677105446795636
0.0242984610487677,265.892268312915,0.07714761382983744,53.60388129188367,272.35304123768486,0.02400795001732899
0.0246365118089219,266.043552294259,0.07822092499332703,53.634380142522616,272.597937412044,0.02433792707145692
0.0249697318484365,266.213296012369,0.07927889861878588,53.6686004760936,272.8605706282863,0.02466308225039095
0.0253069535184397,266.39932991428,0.08034957742104605,53.70610491071884,273.14108537376416,0.02499203460638364
0.0256513582116086,266.588744601802,0.0814430623218573,53.74429091172328,273.4271079847659,0.025327882189863368
0.0259958660499607,266.778729409607,0.08253687470862522,53.78259184897678,273.7138735243179,0.025663717549389065
0.0263395182579912,266.934772658726,0.08362797046912206,53.814050167999156,273.96570597686326,0.025998606489929636
0.0266834430455695,267.096191621106,0.08471993166968315,53.84659223081498,274.2232376379163,0.026333648812668323
0.0270172129311116,267.251251656576,0.08577965105627933,53.877852333965734,274.47163562868786,0.026658691206270745
0.0273542117666147,267.425204579181,0.08684962235900166,53.91292124316289,274.7404102569702,0.02698677096290526
0.0276863428492323,267.598226226069,0.08790413854631254,53.947802407175516,275.0070424632104,0.02731000651634795
0.0280246777740371,267.765460069179,0.08897835193256778,53.98151674994649,275.2695008066346,0.027639172361610828
0.0283622727847201,267.951477327013,0.09005021609148631,54.019017829125815,275.5511902200305,0.027967510385370552
0.0287041893906573,268.124531663578,0.09113580131533693,54.05390558337733,275.8208290007306,0.028299941656185473
0.0290429719151052,268.280522958592,0.092211435830459,54.085353428452144,276.07218665224815,0.02862921683039498
0.0293722234498198,268.441311645859,0.09325680945317785,54.117768427805174,276.3260298346839,0.028949124629622083
0.0297039007458472,268.605121969002,0.09430988486806485,54.15079258895081,276.5837418517955,0.029271285908652796
0.0300244936136908,268.758764637606,0.09532776722346828,54.18176695094137,276.8281104500913,0.029582582166266608
0.0303561789296951,268.92744433176,0.09638086810178194,54.21577277728282,277.0910539510005,0.029904547250961425
0.0306898793809672,269.053064780568,0.09744036703457085,54.241097859762505,277.31027088576315,0.030228363841903055
0.0310278354537112,269.222992392272,0.09851337756553305,54.275355266282034,277.57639910057514,0.030556203170574815
0.0313678141825373,269.384865354597,0.09959281002955592,54.30798885548677,277.8348797546279,0.030885896197192286
0.0317043237937317,269.534087249685,0.10066122804509814,54.338071989536495,278.07948322529694,0.031212118056316282
0.0320406209718569,269.713805331066,0.10172897158564564,54.374303154742904,278.35560313855586,0.031538027691569215
0.0323771268984371,269.838841231491,0.10279737790253779,54.399510392268596,278.5754476361702,0.03186403334610088
0.0327165009005293,270.022924525257,0.10387489035918052,54.436621584291814,278.8571297786511,0.032192709974200234
0.0330561093142724,270.163367033844,0.10495314707281486,54.46493479402295,279.0939168272267,0.0325215055203542
0.0333921420627331,270.341019405768,0.1060200510491776,54.50074951220283,279.3682851311495,0.0328467328771956
0.0337274302120766,270.500965844526,0.1070845909233432,54.53299471425644,279.6242682923466,0.0331711341907733
0.0340621268270717,270.645926192814,0.10814725267595264,54.5622187204713,279.86470205602393,0.03349485825329083
0.0344033530336728,270.774798900671,0.10923064588191113,54.58819945837528,280.0903598998725,0.03382478999546257
0.0347437939104731,270.920264183984,0.11031154566575209,54.617525259491174,280.3330620089633,0.034153853958240846
0.0350832141165702,271.078363502258,0.11138920482011037,54.649398082055214,280.5886637713772,0.03448182359804481
0.0354277500539282,271.252680216825,0.11248310642122204,54.68454033171192,280.8625523730048,0.03481462641483741
0.0357585799372513,271.405556238877,0.11353349130077288,54.71536013775761,281.11063351705906,0.03513408573276181
0.0360918678021297,271.53583146495,0.1145916802717618,54.741623623333915,281.33606679772436,0.03545581539053422
0.0364323700988369,271.673125396248,0.11567277506380716,54.7693020798836,281.57082124659183,0.035784402428064487
0.0367680357515126,271.802382923569,0.1167385135110525,54.795360397391505,281.7960226562491,0.03610821642565144
0.0371152373839742,271.961833647052,0.11784087869411808,54.82750566324569,282.05576166224324,0.036443048805277704
0.0374448587396894,272.088621817752,0.11888742649851383,54.85306615845881,282.27694182639453,0.03676082350759152
0.0377743490887045,272.262990454073,0.11993355835663679,54.88821887554113,282.5475476994198,0.037078371023093463
0.0381066047155756,272.379004520898,0.12098846997195252,54.911607311413036,282.7584435789978,0.03739848150833041
0.038441792418885,272.506348367603,0.12205269092995986,54.937279830908764,282.9819808443787,0.037721313094324714
0.0387819120619104,272.657273199211,0.12313257079656552,54.96770627696094,283.23144359146306,0.038048788315535945
0.0391141650221862,272.787403853119,0.12418747394544116,54.99394061678879,283.4572553834036,0.03836858579412181
0.0394471546194982,272.953857203877,0.12524471591690678,55.0274976123016,283.7211102129868,0.03868898971679075
0.0397782716722106,273.045397700684,0.12629601255926864,55.045952176457895,283.9066717092686,0.03900749010768117
0.0401176024999835,273.192927480329,0.1273733879374476,55.075694180034326,284.1527727507916,0.03933378608720328
0.0404648191797695,273.316849214292,0.12847580089576816,55.10067680160127,284.37656609653266,0.03966755482367952
0.0408066718370957,273.442310856935,0.12956118308277884,55.125969868758105,284.60058150245106,0.039996058492591496
0.0411502817889234,273.587809428401,0.1306521446798318,55.15530238076565,284.84602488039394,0.040326142123138314
0.0414896077288985,273.677872031487,0.13172950453925272,55.17345900154778,285.0326595861531,0.0406520034923415
0.0418337632432856,273.826985020289,0.13282219829743178,55.203520180090266,285.2821982812505,0.04098239436906582
0.0421772914514628,273.945960179959,0.1339129003583944,55.22750557227973,285.50025878442,0.041312074204990654
0.0425205250673804,274.071896866224,0.13500266708893277,55.25289440823076,285.7255778271888,0.04164136281104106
0.0428547348754384,274.186818424914,0.13606378322951693,55.276062594462665,285.9370218348537,0.041961890072814166
0.0431987481206182,274.299097554466,0.13715602528296278,55.29869806698035,286.1484751794343,0.042291712151780445
0.043537416081918,274.40918985615,0.13823129606008966,55.32089267499984,286.35625693161927,0.04261630322379331
0.0438812135003546,274.526855924415,0.13932285286362583,55.34461415436206,286.5734275008153,0.04294570281491799
0.0442200548346803,274.637984606977,0.14039867410010995,55.36701769676656,286.7824913459836,0.043270247742348694
0.0445519246100095,274.757971060098,0.14145236063678016,55.39120696571575,286.99896747276665,0.04358801318672232
0.0448835821127483,274.87455646033,0.14250537320797585,55.41471058240252,287.2119111859225,0.04390547453401645
0.045217388890437,274.983540402378,0.14356520972713746,55.436681745119415,287.41757808722156,0.04422489142837509
0.0455464253564342,275.083798917731,0.14460990050667857,55.456893861814564,287.61288263190175,0.044539643832708344
0.0458872960915267,275.153454556481,0.14569216509059726,55.47093643858657,287.77950259632064,0.04486561231510879
0.0462311063213672,275.285820579437,0.14678376257034084,55.49762142881449,288.0125886194097,0.04519428418429079
0.0465751526021542,275.423619461935,0.14787610951183958,55.5254016835261,288.2515165686123,0.04552307360989526
0.0469170651824799,275.547013793796,0.14896168195437368,55.55027798082928,288.47487100079724,0.045849716890879175
0.0472575345139667,275.663659559134,0.15004267208184427,55.57379376712141,288.69084446499613,0.04617487538963655
0.0475948995161382,275.738512630277,0.15111380596373877,55.588884146263844,288.8622594316444,0.04649696490735875
0.0479407092414823,275.835358883465,0.1522117518417063,55.60840835090655,289.0591016222171,0.04682700914715884
0.0482892169224646,275.923299617489,0.1533182637288251,55.626137202885786,289.2474196866802,0.047159518171902254
0.0486346321746628,276.027546775014,0.1544149571545544,55.647153429842824,289.4520449824914,0.04748896767048194
0.0489796867950851,276.140566250565,0.1555105055743952,55.66993815611391,289.6658446969351,0.04781796487498621
0.0493261374770655,276.228733774287,0.15661048648968295,55.68771272889626,289.8540302715532,0.04814818431308815
0.049674746912961,276.344791545966,0.15771732144865117,55.71110997566675,290.07214912672686,0.048480351337593396
0.0500216089368764,276.438539348194,0.15881860837458256,55.730009532595915,290.26643985855065,0.048810743897550184
0.0503737833072466,276.532312221675,0.15993676200050794,55.74891414388968,290.4622909949815,0.04914608492426446
0.0507158839087545,276.609148590641,0.16102293141029553,55.764404355873225,290.63762605866333,0.049471726052169526
0.0510580242754019,276.658372840802,0.16210922707440104,55.774327964705684,290.78400275730087,0.04979729900588961
0.0514059180536337,276.765825333697,0.16321378982028698,55.79599038727332,290.9932266708474,0.05012823812394315
0.0517476949386218,276.83541158169,0.16429893143012422,55.8100189748687,291.1610060084271,0.05045325184228053
0.0521034930397805,276.949023887225,0.1654285904013031,55.83292321566456,291.37903542570706,0.05079148689101773
0.0524509519280762,277.047588685809,0.16653177237164193,55.85279387905909,291.5789984417578,0.051121683995001846
0.0527948371082804,277.127943829326,0.16762360781879027,55.86899347599212,291.75886848194796,0.051448377614391694
0.0531337934440793,277.248604877065,0.16869979418495176,55.893318743216305,291.9798749812621,0.05177028438160899
0.053479724300485,277.327261095462,0.16979812465403984,55.909175836845144,292.1586465598559,0.052098708040340225
0.0538244975091332,277.401420517836,0.1708927795914979,55.92412637639575,292.3324125855283,0.052425925352540474
0.0541718858485665,277.507266331646,0.17199573756919861,55.94546489245983,292.5403582855117,0.05275551637586546
0.0545161941563314,277.566031988809,0.1730889164463522,55.9573120489439,292.69787567991347,0.05308207800827533
0.0548620515217185,277.654314435917,0.17418701358145622,55.97510979028087,292.8869997397277,0.05341000152715571
0.0552113299037455,277.692151581992,0.17529597244439193,55.98273775892959,293.0239045746663,0.05374105957309081
0.0555419473038773,277.7576270989,0.1763456826898104,55.995937623138246,293.18482658647713,0.05405432915926724
0.0558960246817259,277.869124555324,0.17746987836447972,56.018415510353314,293.400903999758,0.05438971896078212
0.0562513812548897,277.963989710489,0.1785981354842748,56.03754032563458,293.59984807082395,0.05472620738532852
0.0566071358112845,278.071947542785,0.17972765620082828,56.059304624625454,293.81280404264777,0.055062959285073064
0.0569876311872223,278.141499920324,0.18093572901943078,56.07332638393732,293.9921251356443,0.0554230050100051
0.0573438185096602,278.195198677356,0.18206662376817112,56.08415205335498,294.14797366056916,0.05575993167858243
0.0577046298456463,278.250169015966,0.183212199759927,56.09523407361874,294.30649202352083,0.05610111661906618
0.0580559465471431,278.281959250913,0.18432763028717933,56.10164298498407,294.43788180221827,0.05643321157219606
0.0584135199652199,278.362075360256,0.18546292588957317,56.1177943926276,294.6221840068723,0.05677110770264966
0.0587661604665799,278.386401123108,0.18658255948139116,56.12269846641857,294.7461010432222,0.05710423059049943
0.0591165396588687,278.487151568785,0.1876950134169081,56.143009756267055,294.95034830898646,0.057435107456781605
0.0594728447249424,278.544956463202,0.1888262820016921,56.154663222981526,295.11081740785386,0.05777146812398726
0.0598368484973888,278.617800599145,0.18998199397920942,56.169348600787636,295.2894117222717,0.058114979765716515
0.0602024129101783,278.698502858196,0.19114266098981608,56.18561817621231,295.47682520471363,0.058459845469920474
0.060567805689844,278.755039373687,0.19230278306525467,56.197015937735294,295.63862043353726,0.05880443045143003
0.060926618037231,278.801081354031,0.1934420122682084,56.20629800097265,295.787488346055,0.05914269422134179
0.0612826999410239,278.853234605834,0.19457257231275088,56.216812096536145,295.9421137097673,0.05947827083399533
0.0616451610684519,278.875339670364,0.19572338639233477,56.22126847754538,296.0666549023628,0.059819743700414506
0.0620137635931876,278.934391689756,0.19689369940837062,56.23317336465482,296.23216311401416,0.06016688280468106
0.0623822399195005,279.008578415533,0.1980636117444141,56.24812940857146,296.4137584938495,0.06051378265706139
0.0627346310037336,279.051790676394,0.19918245343685415,56.25684100036103,296.55800179540864,0.06084542661724502
0.0630935113498531,279.126886016711,0.20032189853578355,56.27198022096894,296.73798136765555,0.06118306477564447
0.0634576560387387,279.143435469612,0.20147805792299534,56.275316590673775,296.8572235831145,0.061525539199047984
0.0638196708011062,279.201466361152,0.20262745479351219,56.28701561840824,297.02001203150684,0.06186589422591231
0.0641880168164372,279.243120047383,0.2037969533921881,56.29541300155242,297.16718213285884,0.062212082842760884
0.0645451465432394,279.276858658324,0.20493084027478506,56.30221470551812,297.3028244265611,0.0625476154837698
0.0649091417376318,279.298386776722,0.20608652501698096,56.306554774187155,297.42740535110414,0.06288948259962257
0.0652766590493213,279.32477682563,0.2072533924815951,56.31187500804701,297.5581650465044,0.06323453918125993
0.0656520359153017,279.400009718161,0.2084452140310829,56.32704195918126,297.74318919091337,0.06358685211481818
0.0660244560585504,279.449294737803,0.2096276479858975,56.33697781914108,297.8997824188119,0.063936267374066
0.0664008551833139,279.533734942678,0.21082271520702162,56.354000964443884,298.09501399545763,0.06428929181688085
0.0667745849635455,279.56022286652,0.21200930725925696,56.359340929890436,298.22774072074816,0.06463968942321148
0.067151386799714,279.5935927036,0.21320565308909192,56.366068289045764,298.36869019396113,0.06499284304247532
0.0675377928068016,279.644853176189,0.21443249216159505,56.3764024003197,298.53144932949084,0.06535486859167401
0.0679190081154005,279.667498275498,0.21564285076639655,56.38096765234041,298.6622373604853,0.06571190256443699
0.0683092964140101,279.695659859108,0.21688201611448205,56.38664502759617,298.801473594136,0.06607730199494237
0.0687000959925332,279.729930110002,0.2181228047762929,56.3935539101764,298.94740316054373,0.06644304637048709
0.0690875525287192,279.760434933746,0.21935297927868347,56.39970368264319,299.0883986776885,0.0668055300256774
0.0694721082208128,279.782656700913,0.22057394360108062,56.40418359090406,299.21974770554533,0.06716516993032588
0.0698571568995228,279.80368129151,0.22179647315598486,56.40842214836841,299.34997095655507,0.06752514133738859
0.0702449812816725,279.81245184646,0.22302781556931017,56.41019029224634,299.4678722887935,0.06788757673659318
0.0706315281289069,279.84202256386,0.22425510180927938,56.41615174887417,299.60769225222947,0.06824868757109089
0.0710198158128846,279.892077626805,0.2254879152059086,56.4262428495639,299.7699614273463,0.06861129345400492
0.0714081988018588,279.9313696334,0.22672103119590165,56.43416411809344,299.92076452705845,0.0689738568545761
0.0717969539713786,279.95668582395,0.22795532885912703,56.43926786210833,300.05672311003184,0.06933663609974565
0.0721884144505177,279.963200386725,0.22919821588039369,56.440581197963766,300.17329992713525,0.06970180695329238
0.0725913656389766,279.980589888335,0.2304775859037507,56.444086921488335,300.3047632607354,0.07007755759859462
0.0729978722425994,280.00594480184,0.2317682443702531,56.44919847205094,300.44578298765305,0.07045648064808592
0.0734104062697033,280.04974541221,0.23307803990630796,56.45802867510153,300.60831099864726,0.07084087539377643
0.0738176456015624,280.047913334477,0.2343710247849606,56.45765932823057,300.7203909524585,0.07122019172804954
0.0742248742878013,280.083709421799,0.23566397586376914,56.46487581943468,300.87288754369314,0.0715993543259469
0.0746349007781587,280.10833277233,0.23696580997065383,56.46983988690173,301.0141903959283,0.07198097671014447
0.0750507313916492,280.132919421783,0.23828607216848618,56.47479655543146,301.15709991126573,0.0723678524583508
0.0754696457231634,280.145471239211,0.2396161251710438,56.477327001824946,301.28795070458295,0.07275744591793476
0.0758858185503109,280.135213926637,0.2409374738972371,56.475259127610016,301.39350394022625,0.07314433951989865
0.0763099819256982,280.134739465315,0.24228419261409176,56.47516347620751,301.5118163706734,0.07353850754195819
0.0767349079878743,280.176347263066,0.2436333328615009,56.48355160823411,301.6756534906761,0.07393322858998075
0.0771717409287515,280.19438208254,0.245020277448786,56.48718742784007,301.8174703463054,0.07433884779087435
0.077613627878537,280.209188306993,0.24642326851435495,56.49017236268978,301.95723997639885,0.07474899254345785
0.0780532493719263,280.195462766748,0.24781906675586599,56.48740529377639,302.0656290949633,0.07515686771575229
0.078503248539304,280.195756148928,0.2492478141122902,56.48746443962389,302.19203323354554,0.07557419893275931
0.0789456764913338,280.206441597619,0.2506525228599848,56.489618626079995,302.3275286867725,0.07598433884670928
0.0793991919374248,280.171815804014,0.25209243440132373,56.48263806608922,302.41723158249374,0.07640458258013594
0.0798630700577547,280.161683621253,0.25356524743337117,56.480595418044615,302.53625578779565,0.07683424611441886
0.0803359401504756,280.162116981896,0.25506660997776004,56.480682783550236,302.66920404418414,0.0772720484632202
0.0808114111484075,280.159863982097,0.25657623039619376,56.48022857879076,302.7999779376362,0.07771206566548801
0.0812878624468923,280.154907379302,0.25808896326888303,56.47922932766729,302.9281009541726,0.07815279594278443
0.0817638847029003,280.11469131104,0.25960033393170845,56.471121768305665,303.0179566349844,0.07859293544875788
0.0822460738217546,280.101127197311,0.26113128438407085,56.4683872429779,303.1383451823377,0.07903857954104583
0.0827285039873913,280.05104766159,0.26266300015996735,56.45829120857655,303.219251874735,0.0794842477521802
0.0832319889792195,280.05214759405,0.2642615650090219,56.45851295496048,303.3614448562047,0.07994915466302335
0.0837414138687666,280.009178394938,0.26587898903333396,56.4498503644195,303.4575428899618,0.08041932646878912
0.0842738712433012,279.955916395299,0.2675695411974813,56.439112745292285,303.5488852473968,0.0809105198555668
0.0848091697257686,279.881722261371,0.2692691138793153,56.4241552078924,303.61825874777605,0.08140409108656545
0.0853478807141912,279.765901712266,0.27097952126755703,56.40080578519282,303.6433285195026,0.08190056298879816
0.085871536838022,279.639688271724,0.2726421294607198,56.37536115557957,303.6527780645224,0.08238292431050612
0.0864027493419174,279.520460248253,0.2743287291605877,56.35132478604781,303.67179651102026,0.08287200850936996
0.0869306425806552,279.367874001355,0.27600479019358026,56.320563398673166,303.65350280468436,0.08335779982981935
0.0874569223685488,279.199428747674,0.2776757285201424,56.28660483553108,303.6173515130025,0.08384187158101387
0.0879859095432721,278.963190584604,0.27935526279988887,56.23897922185616,303.5080206372835,0.0843281975624549
0.0885081111821753,278.704081131003,0.28101325300340657,56.18674275601021,303.3716529306718,0.08480805337087974
0.0890442152558279,278.405793575168,0.28271538343725355,56.12660798475387,303.19621898674484,0.08530044483075444
0.0895782734443418,278.068442808135,0.2844110181857852,56.05859807012001,302.9773338142444,0.08579071627702957
0.0901076806742963,277.637846796174,0.2860918861408907,55.97178991410868,302.6551492383828,0.08627648097112627
0.090650343792567,277.126487949781,0.28781484154140025,55.868699970675856,302.2480993564553,0.08677416400003948
0.0911879921051777,276.562300254117,0.28952187493393916,55.754959731229995,301.7814611062792,0.08726700374407302
0.0917325337675343,275.916158370451,0.2912507947119214,55.62469752748292,301.2266466851767,0.08776591487454964
0.0922594138987559,275.246097606099,0.29292363912854996,55.489613277389566,300.6401412491574,0.08824840762550133
0.0927942891533261,274.478210399637,0.29462186806181034,55.33480721656682,299.94822082174846,0.08873798393614922
0.0933308479215637,273.644419540149,0.29632544215096474,55.16671497929404,299.1838852448352,0.08922886048288668
0.0938739256759121,272.751658070053,0.29804971402102093,54.98673426692269,298.3559269477029,0.08972545574645277
0.0944258793063171,271.766479143086,0.2998021667975568,54.78812219524613,297.4282679021537,0.09022991463353344
0.0949763867301289,270.744859587334,0.3015500278681592,54.58216369280654,296.4592280766951,0.09073279840592498
0.0955174790563415,269.612109553594,0.30326799600388427,54.35380128600455,295.3647785812155,0.09122683524909483
0.0960674059391928,268.45871175827,0.3050140138569371,54.12127629046723,294.2488437986645,0.09172868840400404
0.0966089032011066,267.274232419519,0.30673326766351344,53.88248525577504,293.0953028674864,0.09222260286886579
0.0971628855806161,266.009066058568,0.3084921617184561,53.62742771740731,291.8552745074232,0.09272765302414451
0.0977048769081554,264.687172462682,0.3102129841833934,53.360933968476694,290.54840006731604,0.09322152454371262
0.098256861447144,263.304543579687,0.31196553509468217,53.082195985664896,289.1760216365998,0.09372425147285064
0.0988275995031071,261.896075487464,0.313777628422365,52.79824881827274,287.77863594717456,0.09424379278220413
0.0993970867836485,260.452151613778,0.31558575053808396,52.507153765337655,286.3403367307207,0.09476192661705227
0.0999659636537901,258.917634127879,0.3173919346007835,52.19779504018041,284.8005849304319,0.09527923719268917
0.100521727611523,257.343002249777,0.3191564851665855,51.88034925355504,283.21156542466065,0.09578436518932022
0.101079149379129,255.704698658598,0.32092629927873456,51.55006724957336,281.5511120912556,0.09629074378440776
0.101650460402931,254.001778426923,0.32274021177930595,51.20675853086768,279.821176147183,0.09680947384921057
0.102214800437131,252.265307473125,0.3245319913878909,50.856685986582,278.050555533702,0.09732161046351503
0.102774212516013,250.442454521683,0.32630812473834125,50.489198831571294,276.18148056572636,0.09782901624884806
0.103353901433152,248.612002764758,0.3281486370502576,50.12017975737521,274.3070231936053,0.0983545423294189
0.103952999733737,246.729670870933,0.330050774154615,49.74070164758009,272.3779602812841,0.09889737424371182
0.104557966511078,244.826550428308,0.3319715436726726,49.35703256634689,270.4251166890138,0.09944522462953173
0.104879439092839,243.842339073763,0.33299221911976384,49.158615557270615,269.4163868229051,0.09973622412398586