File: example/data/02 processed data/test_ID_060.csv
Strain,Stress_MPa,Displacement(mm),Force(kN),True Stress (MPa),True Strain
1.31237940120475e-06,2.55842585547996,4.166804598825081e-06,0.51577865246476,2.558429213105352,1.312378539983604e-06
9.13456573719564e-06,2.60571108163359,2.9002246215596157e-05,0.5253113540573318,2.605734883672757,9.13452401725401e-06
2.84261568251965e-05,3.64086727613719,9.025304791999888e-05,0.7339988428692575,3.6409707720013618,2.842575280976127e-05
5.16053446877032e-05,5.61304129588602,0.00016384696938345766,1.1315891252506216,5.6133309588168405,5.160401317774124e-05
7.87659470184749e-05,8.42070882345165,0.0002500818817836578,1.6976148988078528,8.421372088556696,7.876284514417527e-05
0.0001154636153212,11.8995995437031,0.00036659697864481,2.3989592680105454,11.90097351448729,0.00011545694991094817
0.0001478705955234,15.3016377138696,0.00046948914078679495,3.0848101631161113,15.303900376150832,0.00014785966374448285
0.0001914006160356,19.0280754070273,0.00060769695591303,3.8360600020567035,19.031717392382173,0.000191382301274533
0.0002489387096421,23.0742900264306,0.0007903804031136675,4.651776869328409,23.080034110415685,0.0002489077295427885
0.0003027217746464,27.4639514371128,0.00096114163450232,5.53673260972194,27.472265373230645,0.0003026759636549647
0.0003699343278904,32.0509895748515,0.0011745414910520199,6.461479498290063,32.062846336138094,0.00036986591905764106
0.0004335921715871,36.7493982101309,0.0013766551447890424,7.408678679162389,36.765332461505345,0.000433498197664631
0.0004978666298313,41.5878975641158,0.0015807265497143773,8.384120148925746,41.608602790517814,0.0004977427353608935
0.0005668065970582,46.4985077878892,0.0017996109456597847,9.374099170038463,46.524863448856735,0.0005666460228723395
0.0006384534366463,51.5689516720166,0.0020270896613520024,10.396300657078548,51.601876046435855,0.0006382497119588589
0.0007076374078643,56.6344726728857,0.002246748769969152,11.417509690853759,56.6745493443237,0.000707387150567767
0.0007796665637419,61.6539093321532,0.0024754413398805322,12.429428121362085,61.70197882378345,0.0007793627816554368
0.0008521717494277,66.7011033457074,0.002705645304432947,13.446942434494611,66.75794414163425,0.0008518088572320666
0.0009233089155419,71.7261973221851,0.0029315058068455323,14.460001380152518,71.79242275965059,0.0009228829280569243
0.0009993749005096,76.8536105977901,0.00317301530911798,15.493687896514485,76.93041616723505,0.0009988758578730616
0.0010692118470534,82.0659435415566,0.0033947476143945444,16.544494217977814,82.15368942063085,0.0010686406471860216
0.0011433593080139,87.24081167627,0.0036301658029441325,17.587747633936033,87.34055927033874,0.0011427061705600772
0.0012167554794506,92.4503684427275,0.003863198647255655,18.637994278053863,92.56285793510742,0.001216015832421194
0.001291040466644,97.5656049049142,0.0040990534815947,19.6692259488307,97.69156604899904,0.0012902077905027213
0.001370438828192,102.66378899645,0.0043511432795096,20.69701986168432,102.80448343914006,0.0013695006339619071
0.0014446428099986,107.793980338562,0.004586740921745555,21.7312664362541,107.94970413721923,0.0014436003174731005
0.0015247843497639,113.114863446546,0.004841190310500383,22.803956470823675,113.28733922005497,0.001523623046448779
0.0016063089295561,118.57114655327,0.005100030851340617,23.903943145139234,118.76160844476622,0.0016050201952532712
0.0016855054163829,124.103071890208,0.0053514796970157074,25.019179293065932,124.31224829006871,0.0016840865462470372
0.0017642043338622,129.553747247169,0.005601348760012484,26.118035445029275,129.78230652953056,0.0017626499532911173
0.0018418310243288,134.874176355119,0.0058478135022439395,27.19063395319199,135.12259179751067,0.0018401369334016557
0.0019165967210926,139.985019662126,0.006085194589469004,28.220979963884602,140.25331449181252,0.0019147623930010952
0.0019954228007515,145.078783461266,0.006335467392386012,29.247882745791227,145.3682769736899,0.001993434589117158
0.0020714063053502,150.118530622263,0.006576715019486885,30.263895773448223,150.42948709314385,0.0020692639013252735
0.0021495147558635,155.169319540557,0.006824709349866613,31.282134819376292,155.50285828256673,0.0021472078542418465
0.0022261274934877,160.157142430886,0.007067954791823447,32.28767991406662,160.51367264892983,0.0022236533428484566
0.0023016750276167,165.087289785734,0.007307818212683023,33.28159762080397,165.46726707801074,0.0022990302311809083
0.002377582802109,169.953000243444,0.007548825396696075,34.26252484907831,170.35707757398964,0.0023747608242242527
0.0024487900347947,174.764961624763,0.007774908360473172,35.232616263552224,175.192924321221,0.0024457966342877374
0.0025228311868799,179.512143107331,0.008009989018343683,36.18964805043793,179.96502194038584,0.0025196541905096502
0.0025951717015253,184.152492715828,0.008239670152342827,37.125142531510924,184.63040005368947,0.002591810058216808
0.0026653303799165,188.646010704944,0.008462423956234888,38.03103575811671,189.14881464832592,0.00266178468579952
0.0027367578509372,193.024129336463,0.00868920617672561,38.91366447423094,193.5523896378449,0.0027330197478054167
0.0028066736397299,197.276650684444,0.008911188806142433,39.770972777983914,197.83034185965423,0.0028027422855706847
0.0028805546669417,201.466478353249,0.009145761067539896,40.615642036015,202.04681355770174,0.0028764138193996484
0.002955943167471,205.600644436296,0.009385119556720424,41.44908991835728,206.20838825644512,0.0029515829577080204
0.0030314743703741,209.666948168972,0.009624931125937767,42.26885675086475,210.3025481486608,0.003026888717134415
0.0031100665016071,213.662329449836,0.009874461142602542,43.074325617086934,214.32683350331325,0.003105240248840401
0.0031942336079093,217.446993219758,0.010141691705112027,43.83731383310322,218.1415697134394,0.003189142881503956
0.0032834764438834,221.045953508561,0.010425037709329794,44.5628642273259,221.77175268992212,0.003278097606080035
0.0033775946287095,224.370150965716,0.010723862946152662,45.233022434688344,225.12798238246054,0.003371903367553142
0.0034867980544368,227.457791606524,0.011070583822836839,45.85549078787524,228.25089099176415,0.0034807332678027238
0.0036128894846307,230.305953977508,0.011470924113702471,46.42968032186562,231.1380239368812,0.0036063786765909785
0.003770420846484,232.885332686249,0.0119710861875867,46.9496830695478,233.7634083994496,0.003763330626291653
0.0039709945390745,235.131062547887,0.012607907661561536,47.40242220965403,236.06476671323145,0.0039631309508959545
0.0042168734032913,236.906418755175,0.013388573055449876,47.760334021043285,237.90542313149268,0.004208007308701447
0.0045085541887082,238.210413625491,0.014314659549148534,48.02321938689898,239.2843981836361,0.0044984211038976004
0.0048356781371957,239.133657925639,0.015353278085596346,48.20934543780883,240.29003132713763,0.00482402380164824
0.0051845590197155,239.668434823776,0.01646097488759671,48.31715646047324,240.9110099692827,0.005171165466765868
0.0055475404854979,240.08557659386,0.017613441041455832,48.401252241322176,241.41746104999854,0.0055322095559458126
0.0059172943164563,240.341177972778,0.018787409454748754,48.452781479312044,241.76334745920673,0.00589985588883293
0.0062927865128842,240.573491376948,0.019979597178407336,48.49961586159272,242.0873689988423,0.0062730696047999706
0.0066653236157303,240.836983474027,0.0211624024799437,48.55273586836385,242.4422399075177,0.006643208561219342
0.0070366177743725,241.039472356423,0.022341261433632686,48.59355762705488,242.7355749919316,0.007011976307049294
0.0074129787786819,241.272973842356,0.023536207622315033,48.640631526618975,243.06152527731885,0.00738563768763912
0.0077889841977235,241.465875186064,0.02473002482777211,48.679520437510504,243.3466490721777,0.007758806660588738
0.008169755886559,241.62952560391,0.025938974939824826,48.71251236174826,243.603579843079,0.008136564087655583
0.0085367040355336,241.863427728022,0.027104035312819175,48.759667029969236,243.92814422755578,0.008500472430606263
0.0088994955327053,242.049138509774,0.028255898316339328,48.797106323570446,244.2032537366369,0.008860128414929417
0.0092536935360614,242.277264393226,0.029380476976994946,48.84309650167437,244.51922394867626,0.009211140428201085
0.0096089307810835,242.454781016302,0.03050835522994011,48.87888385288648,244.78451222463045,0.009563058626506995
0.0099664027988548,242.64749721855,0.03164332888636399,48.91773543925968,245.06581991396408,0.009917065744301233
0.0103234338760929,242.800623343397,0.032776902556594954,48.94860566602883,245.30715952355672,0.010270511150473716
0.0106845322310412,242.992085726176,0.033923389833555806,48.98720448239708,245.58834249800523,0.010627855965384405
0.0110412735785104,243.22971613565,0.03505604361177052,49.035110772947036,245.91528197392714,0.010980763713949113
0.0114022632680813,243.395413676265,0.03620218587615812,49.06851539713502,246.17067226124533,0.011337747418885932
0.0117613633833486,243.5660892071,0.0373423287421318,49.10292358415136,246.4307584901258,0.011692736124997476
0.012122109460089,243.773051119351,0.03848769753578257,49.144647105661164,246.72809472843966,0.012049225108084937
0.012482642708637,243.973763786851,0.039632390599922476,49.18511077942916,247.0192011104837,0.012405376847798955
0.0128371360157316,244.236693110886,0.04075790684994783,49.23811733115462,247.37199276038294,0.012755438417767731
0.013186552330676,244.399275010825,0.0418673036498963,49.270893842182325,247.62205884033452,0.0131003665846185
0.01353621785495,244.613283969981,0.04297749168946625,49.31403804834817,247.92442267201343,0.013445421698112286
0.0138901904771598,244.770489162739,0.044101354764982365,49.34573061520819,248.17039788039702,0.01379460588980638
0.0142418060280869,244.954235834387,0.0452177341391759,49.382773944212424,248.44282654689857,0.014141344223461005
0.0145916261495029,245.232343460095,0.0463284130246717,49.43884044155515,248.8106821356312,0.014486192764829242
0.0149295267367132,245.425734842703,0.047401247389064406,49.47782814428893,249.0898249129146,0.014819178296763038
0.0152682919316783,245.652147863452,0.048476826883078604,49.523473009271925,249.40283657067496,0.015152904591801056
0.0156005202892038,245.806742343878,0.049531651918222064,49.55463925652581,249.64145541503675,0.01548008314561998
0.0159370856357452,245.99021287233,0.050600246893491005,49.59162691506174,249.91057996043153,0.01581142365208078
0.016266006947298,246.228013485787,0.051644572057671145,49.63956751873466,250.23316006376618,0.01613513274948883
0.016599122975521,246.421479011434,0.052702215447279176,49.67857016870509,250.51185944535453,0.016462863326693607
0.0169329679316679,246.658572216085,0.053762173183045575,49.72636815876274,250.83523390949094,0.016791203322545134
0.0172675219552397,246.831026539452,0.05482438220788605,49.76113495035353,251.09318670945632,0.017120132578290963
0.0176043040121623,247.043237013583,0.055893665238615296,49.80391658193833,251.39226126211878,0.017451143166476394
0.0179381541046659,247.305255343651,0.05695363928231423,49.856739477280044,251.74145512489918,0.017779163929851634
0.0182711646301869,247.552926027043,0.0580109477008434,49.90666988705187,252.07600629316758,0.018106252628863118
0.0185941577036249,247.768577212088,0.05903645070900906,49.95014516595694,252.37562521077228,0.018423399837962894
0.0189181692935266,247.966631376936,0.060065187506946956,49.9900728855903,252.65770608847035,0.01874144610285147
0.0192426659968549,248.234471672673,0.061095464540014306,50.04406948921088,253.011164699976,0.01905986720137484
0.0195703834285923,248.490794597366,0.062135967385780554,50.095744190828995,253.35385472611202,0.019381345852546018
0.0199070289956655,248.629629591393,0.06320481706123797,50.12373332562483,253.57910683685046,0.01971147509847921
0.0202385158183837,248.799317583698,0.06425728772336824,50.15794242487352,253.83464650821878,0.020036438997724504
0.0205701020609248,248.948815022373,0.06531007404343624,50.188081108510396,254.0697175553295,0.02036139474570979
0.0208989744819616,249.13667726509,0.06635424398022807,50.225954136642144,254.3433783257738,0.020683586668830894
0.0212286149552563,249.339672884979,0.06740085248293876,50.26687805361176,254.63280879372377,0.021006426904536808
0.0215564278857395,249.536883682764,0.06844165853722291,50.306635750445224,254.91600752070366,0.021327373970843045
0.021885632345734,249.754826401643,0.06948688269770545,50.35057300257123,255.22086870884195,0.02164957979135483
0.0222053850985365,249.975634842641,0.07050209768785339,50.39508798427642,255.52644007957295,0.02196243548386735
0.0225244078250602,250.134637880017,0.07151499484456614,50.42714299661143,255.76877247480024,0.022274479383473496
0.0228422544078329,250.345118952952,0.07252415774486945,50.469575980915124,256.0635658498345,0.022585276064772886
0.0231619691418993,250.553668320343,0.07353925202553027,50.51161953338116,256.3569846543685,0.02289780204393645
0.0234851367507724,250.776914531952,0.07456530918370237,50.55662596964153,256.66644466367165,0.023213604031126555
0.0238022592019349,251.006465255376,0.0755721729661433,50.60290339548381,256.98098620274595,0.02352340172179341
0.0241228652381566,251.115549598496,0.0765900971311472,50.62489479905679,257.1731761606662,0.02383650500375894
0.0244437512363084,251.331105827297,0.07760891017527917,50.66835093478308,257.47458085608577,0.024149783564676303
0.0247651861176303,251.486357236502,0.0786294659234762,50.6996496188788,257.7144636795088,0.024463499631494905
0.0250870890883878,251.704560840896,0.07965150785563126,50.74363946552463,258.0190955826651,0.024777573945334204
0.0254106988835263,251.851716553894,0.080678968955196,50.773306057265025,258.25144468654423,0.025093214176426838
0.0257328455120186,252.049512522933,0.08170178450065904,50.81318172462329,258.5354636900652,0.02540732835144048
0.0260588142863556,252.194748457953,0.08273673535917903,50.84246128912333,258.766644572013,0.025725068971471438
0.0263843475463937,252.411010974849,0.0837703034598,50.88605981252956,259.070710812946,0.026042284345637604
0.0267107318685793,252.558444416048,0.08480657368273928,50.915782394275276,259.30446530599056,0.026360228047522225
0.0270358801075532,252.748640891689,0.08583891934148141,50.95412600376451,259.58192284418374,0.02667686714973129
0.0273575408181505,252.974396343252,0.08686019209762783,50.9996383027996,259.89515371715953,0.026990011370258346
0.0276748401134614,253.171576353505,0.08786761736023994,51.03938979286661,260.17805925036123,0.027298813606930136
0.0279992422408644,253.375052950543,0.08889759411474446,51.080410674829466,260.4693624358971,0.027614429912919944
0.0283236884873635,253.523838193375,0.08992771094737911,51.11040577978441,260.7045684104849,0.027929989540586484
0.0286455133856052,253.658388020735,0.09094950499929651,51.137531024980184,260.924562770154,0.02824290127555521
0.0289654147477946,253.815938584608,0.09196519182424785,51.169293218656975,261.16782251531197,0.02855384574070463
0.0292785481936638,254.023364647333,0.09295939051488256,51.21111031290234,261.46079997147655,0.0288581181728583
0.0295869887575331,254.178356115622,0.09393868930516759,51.242356592909395,261.69872828042315,0.029157740038046814
0.029904327318873,254.371660627116,0.09494623923742176,51.28132678242659,261.97847402715456,0.029465911829182123
0.0302264127551719,254.615830897718,0.09596886049767077,51.33055150897995,262.3119540964335,0.02977859629396664
0.0305530669716279,254.806889456296,0.09700598763491858,51.369068914389274,262.59202141468637,0.03009561635594341
0.0308844212859047,254.996118598224,0.09805803758274742,51.40721750940196,262.87152615128207,0.03041709524532824
0.0312070765828391,255.099136276429,0.09908246815051414,51.42798587332809,263.06003455842364,0.03073003509295486
0.0315281888067328,255.189353401492,0.10010199946137663,51.44617364574079,263.2350115170023,0.03104138113127145
0.031847107675487,255.365343872321,0.10111456686967121,51.48165332465992,263.49799147521054,0.0313505046066155
0.0321714580778099,255.548718163717,0.10214437939704642,51.51862158180535,263.77009303695905,0.031664794807657805
0.0324958635191293,255.74060198187,0.10317436667323553,51.55730535954499,264.05111368017276,0.03197903956815323
0.0328232013601155,255.911206667759,0.10421366431836672,51.59169926422022,264.311031734525,0.032296024821709006
0.0331487263749714,256.051683407371,0.10524720624053419,51.620019374925995,264.53947059849276,0.03261115496765123
0.0334734561452852,256.223645482437,0.1062782232612805,51.654686929259306,264.80033644287846,0.032925416351016666
0.0338018027127366,256.361697467695,0.10732072361293869,51.68251820948732,265.02718498860037,0.033243077551483965
0.034130337298515,256.507625874044,0.10836382092278513,51.711937376207274,265.26231766476644,0.03356081968836154
0.0344565878611833,256.662316767638,0.10939966645925697,51.74312306035582,265.506024435997,0.03387625295481529
0.0347797521662873,256.830889732528,0.11042571312796218,51.77710737007765,265.76340442607244,0.03418860423289807
0.035097848237439,256.992989070311,0.11143566815386882,51.8097865965747,266.0128899987866,0.03449596160861309
0.0354142606104684,257.112225774463,0.11244027743823716,51.833824716131744,266.21766514417743,0.03480159843550289
0.0357326940560287,257.253293865249,0.1134513036278911,51.8622640432342,266.4456471098416,0.03510909322466015
0.0360503692122289,257.357612993141,0.11445992224882676,51.88329477941723,266.63544996112165,0.03541576158615231
0.0363698002577559,257.489854476003,0.11547411581837498,51.90995466236221,266.8547090516939,0.03572403020152515
0.036683771079356,257.644190296325,0.11647097317695529,51.941068763739125,267.09555079308143,0.036026936820381245
0.0369962336393151,257.765364901952,0.11746304180482543,51.96549756423353,267.30171256598794,0.03632829726327779
0.0373137905992307,257.905667306959,0.11847128515255746,51.993782529082935,267.52910537120573,0.036634478073943294
0.0376326197626726,258.080346449833,0.1194835677464855,52.02899784428633,267.79258599599837,0.03694179123090869
0.0379543931540757,258.229136623793,0.12050519826419034,52.058993943356676,268.03006679905,0.037251846547287616
0.0382750465160945,258.40836486078,0.12152327268860003,52.09512635593325,268.2989570459743,0.03756072701920611
0.0385950988466649,258.526422240725,0.12253943883816105,52.11892672373017,268.5042750615805,0.037868933417009594
0.0389154598927218,258.634115397225,0.1235565851593917,52.14063766408056,268.69898094185527,0.038177342004632256
0.0392472653880342,258.818050540447,0.12461006760700857,52.17771898895412,268.9759512572216,0.038496667814970034
0.0395777266923087,259.003390366851,0.1256592822480801,52.21508349795717,269.2541557631716,0.03881459867333188
0.0399090175674353,259.150368383111,0.12671113077660706,52.24471426603518,269.4928049875199,0.03913322621817566
0.0402376460928727,259.255248394849,0.1277545263448708,52.26585807640156,269.6870693274807,0.03944919290832542
0.0405649196375103,259.367786769334,0.12879361984909518,52.288545812697734,269.8890201961909,0.039763757637076215
0.0408986638665882,259.486036751472,0.1298532577764175,52.31238500909675,270.0986689466436,0.04008443990563274
0.0412259654700937,259.649400523459,0.1308924403675475,52.34531914552934,270.35369774376966,0.04039883185085043
0.0415504546578458,259.778411844987,0.1319226935386604,52.37132782794937,270.5723229674393,0.040710424768113755
0.0418744678928514,259.892528148568,0.13295143555980318,52.39433367475131,270.77538947411716,0.04102146380207239
0.0421932810822865,260.028828830735,0.13396366743625965,52.421811892276175,271.00029829508793,0.04132741661198356
0.042519517099801,260.134565049682,0.13499946679186817,52.443128314015894,271.19536113656125,0.0416403959542335
0.0428467151841022,260.308272087817,0.13603832070952449,52.47814765290391,271.46162648202943,0.04195419991050819
0.0431779196166253,260.452614960246,0.13708989478278533,52.5072471759856,271.6984170329394,0.04227174595457775
0.043509671856348,260.588417486364,0.13814320814390488,52.53462496525098,271.9265340207607,0.04258971616140068
0.0438398800308424,260.718993880832,0.13919161909792463,52.560949166375735,272.1488832943296,0.04290610607985059
0.0441656511550583,260.834552331364,0.1402259424173101,52.584245750002985,272.35448017881686,0.0432181465624965
0.0444916668964673,260.934395131309,0.14126104239628368,52.60437405847188,272.54380132132235,0.04353032390364184
0.0448202552352958,261.039986986667,0.14230431037206415,52.62566137651206,272.7398658300277,0.04384486606276809
0.0451504602860216,261.129900815307,0.14335271140811856,52.64378800436589,272.92003603156127,0.04416085618743439
0.0454790940715531,261.225750137644,0.14439612367718108,52.663111227749035,273.10606060206595,0.044475243580986104
0.045806161553994,261.320136195631,0.14543456293393095,52.68213945703921,273.29020857151977,0.044788034468052094
0.0461365833481894,261.432931196929,0.14648365213050135,52.7048789293009,273.4945534170576,0.04510393393303364
0.0464729450427629,261.618094447307,0.1475516005107722,52.742207840577095,273.7762577727491,0.04542540976778144
0.0468170671003066,261.741878660565,0.14864418804347346,52.76716273796991,273.995865756777,0.04575419561078194
0.0471608879437647,261.840429696968,0.1497358192214529,52.787030626908745,274.18905686105387,0.046082585740887826
0.047498189221786,261.911306103568,0.15080675077917055,52.801319310479315,274.3516188802004,0.04640464414610891
0.0478293472283205,261.994172100805,0.1518581774499176,52.81802509552228,274.5251823300107,0.046720736025331486
0.0481619688866979,262.079330576475,0.15291425121526583,52.83519304421736,274.7015871415458,0.04703812442156415
0.0484934824237083,262.199323152179,0.15396680669527385,52.85938354747928,274.91428142096737,0.04735435524486495
0.0488239803655425,262.313322421509,0.15501613766059744,52.88236580017622,275.120502925037,0.04766951778027861
0.0491577725097646,262.39618574505,0.1560759277185026,52.89907104620208,275.2949977513351,0.047987720878642934
0.04949015882181,262.546384556701,0.15713125425924673,52.92935112663093,275.5398468265041,0.04830448321868329
0.049823805563902,262.630633943612,0.15819058266538885,52.946335803032184,275.71589158434284,0.04862234586387258
0.0501597924279352,262.744766609574,0.15925734095869426,52.969344948490125,275.9239895642365,0.04894233585543379
0.0504983003669624,262.826709861387,0.1603321036651056,52.985864708055615,276.09901200042776,0.04926462337391987
0.0508374608575965,262.916433937642,0.1614089382228689,53.003953081828634,276.28243785676574,0.049587428039254915
0.051178426823841,263.017090373788,0.16249150516569516,53.02424541935566,276.4778912869025,0.04991184610976828
0.0515161580659121,263.128400817228,0.1635638018592709,53.046685604753165,276.683765105359,0.05023308272435054
0.0518499514645554,263.229890614089,0.1646235958999634,53.06714594780035,276.87834766644977,0.05055047245496665
0.052184335080223,263.296251131642,0.16568526387970803,53.08052422813903,277.03619092606215,0.050868322425968615
0.0525212608280944,263.351919057422,0.16675500312919972,53.09174688197627,277.1834938878161,0.05118848668210462
0.0528579146044729,263.401138428001,0.16782387886920144,53.101669507085,277.32397330974925,0.05150829014855485
0.053201407403245,263.497632127154,0.16891446850530287,53.12112263683425,277.5160770037411,0.05183448495059895
0.0535381959540621,263.585863400319,0.16998377215414714,53.13891006150431,277.69777500576595,0.052154209849821886
0.0538732982994011,263.632020476066,0.1710477221005985,53.1482153279749,277.83474695644685,0.05247223255120405
0.0542064709277715,263.684379966853,0.1721055451956745,53.15877100131757,277.97777964363365,0.05278832365554265
0.0545399255540727,263.782523832932,0.1731642636341808,53.17855680471909,278.16920304524547,0.053104582291134725
0.0548769785841416,263.896339401716,0.17423440700464957,53.20150202338594,278.3781731674973,0.05342415215167416
0.0552138599592645,264.002869260177,0.17530400537066476,53.22297844285169,278.57948671235243,0.053743457246821225
0.055557212212669,264.080156085783,0.17639414877522408,53.23855946689386,278.7517133585956,0.05406879073367802
0.0558945736246187,264.156625784973,0.17746527125816436,53.25397575825056,278.92154775334205,0.05438834471741888
0.0562356109050747,264.194499621528,0.17854806462361217,53.26161112370004,279.0516387055052,0.05471127678469169
0.0565793988391321,264.284528435119,0.1796395913142444,53.27976093251999,279.23758817646154,0.05503670796111354
0.0569201981406816,264.366058064515,0.18072162909666406,53.29619730580623,279.4138264712181,0.055359205590155086
0.0572681532979279,264.45084894697,0.18182638672092108,53.31329114770915,279.59546070423227,0.05568836752140063
0.0576136054312753,264.519659290784,0.18292319724429906,53.32716331302205,279.75959056997857,0.05601505447209537
0.0579594677030801,264.56275834641,0.1840213099572793,53.33585208263626,279.89667499422654,0.05634202240270319
0.0583104661292142,264.627537444653,0.18513572996025507,53.34891154884205,280.0580925036768,0.05667373663607316
0.0586569407330738,264.66550194673,0.1862357868275093,53.35656519246077,280.18997060850853,0.05700106770959842
0.0590119787582376,264.718579829291,0.18736303255740436,53.36726569358507,280.3401470390879,0.05733637794173383
0.0593659081342284,264.787256968595,0.18848675832617517,53.38111100486876,280.5065929409069,0.05767052925767614
0.0597204760542753,264.847432842383,0.18961251147232408,53.393242461024414,280.6642476134828,0.058005171512943716
0.0600724190842605,264.901037891398,0.19072993059252707,53.404049238905834,280.81428405546563,0.05833722568109015
0.0604161166958593,264.922605654781,0.19182117050935327,53.408397300003855,280.9282007133914,0.058661394011933814
0.0607582850114371,264.913486525269,0.19290755491131278,53.40655888349423,281.0091756429448,0.05898401559200799
0.0611018327541024,264.95572873328,0.1939983189942751,53.41507491262925,281.14500935758224,0.05930783311682104
0.0614412571776355,265.022937837208,0.19507599153899272,53.42862426798114,281.3062803188364,0.0596276611834798
0.061780785408475,265.042173929292,0.1961539936719081,53.43250226414527,281.41668760101334,0.05994748476002874
0.0621210321044582,265.118329060909,0.19723427693165477,53.44785513867925,281.58775329198204,0.060267882526147974
0.0624611805970997,265.182574300453,0.19831424839579154,53.46080697897133,281.7461909650374,0.06058808524037013
0.0628069995428483,265.251619993581,0.19941222354854332,53.474726590705934,281.9112783692576,0.06091352082730665
0.0631536192676397,265.30126446586,0.20051274117475604,53.484734916317386,282.0559995131603,0.061239603751699415
0.0634985912902845,265.336601589031,0.20160802734665326,53.491858880348644,282.18510200768594,0.061564031059519735
0.0638406764673326,265.373198119216,0.202694147783781,53.49923674083395,282.31480260344625,0.061885639544993966
0.0641872594496782,265.442905656242,0.20379454875272826,53.513289780298386,282.48095831067565,0.06221137115740395
0.0645336574627002,265.47897577245,0.20489436244407314,53.52056151572592,282.61130505849775,0.06253682294709369
0.0648880371910347,265.515527490205,0.20601951808153515,53.52793034202533,282.7443089127866,0.0628696642368165
0.0652432395961135,265.538997436402,0.20714728571766036,53.53266188317865,282.8636218682569,0.0632031670704135
0.0655918454123606,265.555363515645,0.2082541091842449,53.53596128475404,282.9736298677864,0.063530368196216
0.0659410380481849,265.589476518189,0.20936279580298703,53.5428384660669,283.10272229447236,0.06385801281446958
0.0662847014067754,265.603335278696,0.2104539269665119,53.54563239218512,283.208773050288,0.06418036457601822
0.0666335302927151,265.597199850154,0.21156145867937043,53.54439548979105,283.29487891202956,0.0645074553044535
0.0669824293174724,265.627730964216,0.21266921308297487,53.55055056238595,283.42012167828716,0.06483450481521078
0.0673294879550771,265.607596894422,0.21377112425736977,53.54649153391548,283.49082039030196,0.06515972310955205
0.0676746287389362,265.619920761136,0.21486694624612243,53.54897602544501,283.5956502843115,0.0654830393824968
0.0680164713637219,265.605668535,0.21595229657981702,53.546102776656,283.6712288829531,0.06580316304428341
0.068359357630524,265.583240898082,0.2170409604769137,53.54158136505333,283.7383406433076,0.06612416112438965
0.068698486108879,265.574557196822,0.21811769339569084,53.53983073087932,283.8191272252796,0.06644153997512625
0.0690376122739476,265.54485083001,0.21919441896978362,53.533841927330016,283.87743328295545,0.06675881596458992
0.0693712944533718,265.524359029258,0.22025385988945545,53.52971078029841,283.94412752401945,0.06707090050659005
0.0697069683739821,265.460409465302,0.22131962458739315,53.51681854820488,283.96484983244414,0.06738474963422512
0.0700437142797249,265.41213251663,0.22238879283812654,53.50708591535261,284.0025840929973,0.06769950210632651
0.0703859567868664,265.292750984594,0.22347541279830083,53.483018598494155,283.9656350912645,0.06801929071202957
0.0707308334415743,265.13820952981,0.2245703961769984,53.4518630412097,283.89165606706024,0.06834143722852466
0.0710817879269344,264.914697021252,0.2256846766680167,53.4068029194844,283.7453073336447,0.06866915449473136
0.0714281268833714,264.631402760952,0.2267843028547042,53.34969079660793,283.5335281746859,0.06899245657801203
0.0717675754243805,264.286655768778,0.22786205197240808,53.28018980298565,283.2538682703211,0.06930922517126928
0.0720990380979752,263.843769665542,0.22891444596107124,53.19090396457327,282.86665166657133,0.06961844466668476
0.0724404684719504,263.321558147344,0.22999848739844253,53.08562612250455,282.3966951783015,0.06993686302718975
0.0727781702843,262.712074444462,0.2310706906526525,52.962754208003545,281.83177853412275,0.07025170442287607
0.0731355948772579,261.977639275773,0.23220551373529383,52.81469207799584,281.13752976874633,0.07058482554085
0.0734846491701055,261.193464518459,0.23331376111508495,52.65660244692133,280.3871746241224,0.07091003843949108
0.0738364146575203,260.212840998824,0.23443061653762695,52.45890874536292,279.4260242260246,0.07123767038655945
0.074191664606711,259.285486218837,0.23555853512630742,52.27195402171754,278.5223080497729,0.07156843883028592
0.074545342641394,258.17432253572,0.23668146288642591,52.04794342320116,277.42001587035503,0.0718976350387415
0.0748870457160457,257.050548035836,0.23776637014844507,51.82139048402454,276.3003041779303,0.0722155823064771
0.0752246451361002,255.849053027203,0.2388382483071181,51.57916909028413,275.0952072495817,0.07252961196760141
0.0755629803602661,254.665257471754,0.23991246264384483,51.34051590630561,273.90852332053424,0.07284422715595913
0.0759052754896964,253.424977648608,0.24099924967978606,51.090475493959374,272.6612703929958,0.07316242393286986
0.0762590796272103,252.274699005522,0.2421225778163927,50.85857931951324,271.5129353649146,0.07349121307934912
0.076607744562293,250.84526056519,0.24322958898528024,50.5704045299423,270.0619502112299,0.07381512065617978
0.0769757911846675,249.507030758971,0.24439813701131932,50.30061740100856,268.71303185778,0.07415691991295209
0.0773305981022607,248.120956246311,0.2455246489746777,50.0211847792563,267.3082981945431,0.07448631309728798
0.0777059730054388,246.665322802905,0.24671646429226818,49.72772907706565,265.8326917180054,0.07483468296906373
0.0780784113774594,245.211368424761,0.24789895612343357,49.434611874431816,264.3570825230592,0.07518020766849463
0.0784562880229775,243.614433638586,0.24909871447295354,49.11266982153894,262.72751781068945,0.07553065568075307
0.0788410944472149,242.039441061356,0.25032047486990733,48.79515131796937,261.1220954940255,0.07588740429728168
0.0792083980263624,240.404524786327,0.2514866637337006,48.46555219692352,259.4465820729409,0.07622780759570033
0.0795955244820705,238.696448495893,0.25271579023057383,48.12120401677203,257.6956175059311,0.07658645661965417
0.0799956865430994,237.079427270142,0.2539863047743406,47.79521253766063,256.0447588198618,0.0769570471865778
0.0804163622987987,235.279414603889,0.2553219502986859,47.432329984144026,254.19972925012462,0.07734648748917355
0.0808311989579962,233.450736006915,0.25663905669163795,47.06366837899406,252.3208388959806,0.07773037378866869
0.0812469374628988,231.476077867149,0.25795902644470364,46.66557729801724,250.28280028977835,0.0781149468556853
0.0816687285979074,229.491017399764,0.259298213298356,46.265389107792416,248.23325701544297,0.07850496773997025
0.082096318666492,227.445674815186,0.2606558117661121,45.853048042741506,246.11812741412885,0.0789001955625947
0.0825306449992412,225.462936669166,0.2620347978725908,45.45332803250387,244.07053825589531,0.07930148996192356
0.0829489956800357,223.288379033807,0.26336306128411335,45.01493721321549,241.80992582168443,0.0796878715082013
0.0833782792817895,221.171309406954,0.26472603671968165,44.588135976441926,239.61219261180608,0.08008419538071522
0.0837960423286543,218.98369463967,0.26605243439347737,44.14711283935747,237.33366158498092,0.0804697324811448
0.0842426982948682,216.707453500555,0.26747056708620653,43.68822262571189,234.96347412405146,0.08088176937344198
0.0846828538329859,214.365344892694,0.26886806091973026,43.216053530367105,232.51841406109963,0.08128764364951223
0.0851401552783702,211.905996703731,0.27031999300882537,42.72024893547217,229.94770616750446,0.08170915402177269
0.0855990616139607,209.364925338578,0.27177702062432524,42.207968948257324,227.28636648243722,0.08213196514422907
0.0860868423156233,206.662173061107,0.27332572435210395,41.66309408911918,224.4530669660226,0.08258118361452689
0.0865902864256815,203.849982343863,0.27492415940153875,41.09615644052278,221.50141070288822,0.0830446156748259
0.0871054553409735,200.749516670382,0.27655982070759083,40.47110256074902,218.235894729436,0.08351861846651278
0.0876350608814487,197.589326737635,0.2782413182985996,39.834008270307216,214.90507941581208,0.08400567018325224
0.0881903919063586,193.962439194755,0.28000449430268853,39.10282774166261,211.06806272245373,0.08451612568533012
0.088474732573868,192.170514527025,0.28090727592203085,38.74157572864824,209.17274940838615,0.08477738835355479
0.0886193194376753,191.310264525578,0.28136633921461907,38.56814932835652,208.26404996927633,0.0849102139096085