File: example/data/02 processed data/test_ID_110.csv
Strain,Stress_MPa,Displacement(mm),Force(kN),True Stress (MPa),True Strain
8.18751164798688e-06,0.218924981318501,2.5995349482358344e-05,0.0441352762338098,0.2189267737693356,8.18747813050404e-06
2.65165219473605e-05,1.19976708294294,8.418995718286958e-05,0.24187304392129672,1.1997988965931266,2.651617039054175e-05
7.35434092840394e-05,2.84480500072767,0.00023350032447682506,0.5735126881466983,2.8450142173861717,7.354070510006272e-05
0.0001209432461042,5.81033658392972,0.000383994806380835,1.1713638553202317,5.811039304897139,0.00012093593305947976
0.0001673676559239,9.4822042485188,0.0005313923075583824,1.9116123765013902,9.483791262816867,0.00016735365152039858
0.0002271585693995,13.3566788612264,0.0007212284578434125,2.692706458423242,13.359712945288445,0.00022713277279830103
0.0002579145163714,17.5279252961779,0.0008188785894791949,3.5336297397094647,17.53244600255366,0.0002578812621403035
0.0003289075674971,21.5302841073622,0.0010442815268032924,4.340505276044219,21.53736558073547,0.0003288534892605629
0.0004059474514179,25.9098642636401,0.0012888831582518324,5.223428635549844,25.92038230700451,0.00040586507704367736
0.0004569964219274,30.522198768685,0.001450963639619495,6.153275271766896,30.536147304311648,0.0004568920308656144
0.0005308667982327,35.2203785136794,0.0016855020843888223,7.100428308357768,35.2390758432535,0.000530725938303634
0.0005840995360258,40.0436555360024,0.0018545160268819147,8.072800956058083,40.067045016621755,0.0005839290162888929
0.0006529075682687,44.9933201521109,0.0020729815292531224,9.070653342665558,45.02269663135974,0.0006526945168524943
0.0007300118361239,50.0409590181677,0.0023177875796933822,10.088257338062608,50.07748951054195,0.0007297455070912198
0.0007969280082122,55.1607605415158,0.002530246426073735,11.120409325169586,55.204719696545624,0.0007966106296945177
0.0008683124421797,60.2700344003812,0.0027568920039205474,12.15043893511685,60.32236762114165,0.0008679356770152987
0.0009416117264241,65.2628384356901,0.0029896172313965174,13.156988228635123,65.32429068966086,0.0009411686881938879
0.0010195689588136,70.164446558763,0.0032371314442331796,14.145152426246623,70.23598405048665,0.0010190495514004149
0.0011058379745147,75.1043699251076,0.003511035569084172,15.141040976901692,75.1874231894228,0.0011052269860965065
0.0011880966654053,80.0047725578307,0.003772206912661827,16.12896214765867,80.09982596132316,0.0011873914370930305
0.0012745942904782,85.0158401065257,0.004046836872268285,17.13919336547558,85.12420081092569,0.0012737826847476514
0.0013575614876694,90.022513242435,0.0043102577233503445,18.148538669674895,90.14472433943612,0.0013566408342078262
0.0014439687883143,94.8521687996645,0.004584600902897903,19.12219723001236,94.98913237091513,0.0014429272678782895
0.0015231968182923,99.656611714222,0.004836149898078052,20.090772921587156,99.80840834810688,0.001522037930678673
0.0015919024473709,104.35660941139,0.005054290270402607,21.038292457336226,104.52273495331133,0.001590636713774872
0.0016718621378321,109.080406239537,0.005308162287616917,21.99060989789066,109.26277364070822,0.0016704661320642404
0.0017484556419828,113.810417968118,0.0055513466632953895,22.944180262372587,114.0094104355308,0.0017469288728166146
0.0018279030745649,118.555312650615,0.005803592261743557,23.90075103036398,118.77202027111505,0.0018262344927676985
0.0019075531559029,123.338358460492,0.006056481269991707,24.86501306563519,123.57363293541721,0.0019057360867853325
0.0019947696196981,128.02250436315,0.006333393542541467,25.809336879611042,128.27787976549126,0.001992782708627984
0.0020832438571253,132.673032520961,0.006614299246372826,26.746883356225737,132.94942280096646,0.0020810769136336868
0.002161897513576,137.185441823737,0.0068640246056038004,27.656585071665376,137.48202268931456,0.0021595639757875235
0.0022365201469272,141.607560700073,0.0071009514664938595,28.548084237134717,141.92426886253594,0.0022340228585407875
0.0023194510010534,145.897165246137,0.007364256928344545,29.41286851362122,146.23556657211802,0.0023167652267930047
0.0023971281613097,149.984671993292,0.007610881912158298,30.236909873847672,150.34420447429193,0.0023942596328379202
0.0024800635222561,154.054244999384,0.007874201683163117,31.05733579187581,154.43630931285568,0.0024769932400012127
0.0025700313326766,158.026381388723,0.008159849481248205,31.858118487966557,158.4325141402815,0.002566734449671454
0.0026456700661515,162.048868122444,0.008400002460031013,32.66905181348471,162.47759596208925,0.002642176441730398
0.0027272432820194,165.909564815395,0.008658997420411594,33.44736826678363,166.36204056146053,0.0027235311018735608
0.0028035865159771,169.734842853573,0.008901387188227292,34.21854431928032,170.21070917028877,0.002799663797377653
0.0028960620552292,173.503143279079,0.00919499702535271,34.97823368506233,174.00561914879253,0.002891876546563289
0.0029938555215851,177.095427558598,0.009505491281032692,35.70243819581336,177.6256256822418,0.002989382860919348
0.0030863972957867,180.538334283165,0.009799311414122772,36.39652819148606,181.0955473098824,0.0030816441492074504
0.003211504396883,183.670786923776,0.010196526460103524,37.02803064383325,184.26064646356068,0.003206358531007853
0.003340916352902,186.473501710852,0.01060740942046385,37.59305794490776,187.09649408210066,0.0033353478909269665
0.0035048298571943,188.749989879544,0.011127834796591901,38.05199795971607,189.4115264796189,0.0034987022543267366
0.0037068404893531,190.453500337747,0.011769218553696092,38.39542566808979,191.15948108413795,0.003699987087237174
0.0039572592176852,191.486153867714,0.01256429801615051,38.60360861973114,192.24391421516611,0.003949449863074547
0.0042508229000209,192.028994351551,0.013496362707566358,38.71304526127268,192.84527559820856,0.004241813674415324
0.0045756588780794,192.145019792861,0.014527716937902094,38.73643599024078,193.02420985855497,0.004565222374804739
0.0049198193424586,192.078924015572,0.015620426412306055,38.723111081539315,193.02391762122247,0.004907756579508721
0.0052801029194495,191.825844972091,0.01676432676925216,38.67209034637355,192.83870517615404,0.005266212051383643
0.0056409367816001,191.605540467292,0.017909974281580317,38.62767695820607,192.68637520807232,0.0056250862775709546
0.0060168792122304,191.375998117,0.01910359149883152,38.5814012203872,192.52748438179,0.005998850077773787
0.0064100015409527,191.145198395388,0.02035175489252482,38.534871996510226,192.37043941164816,0.006389544852806621
0.0068094410710884,190.986506914623,0.02161997540070567,38.502879793987994,192.28701827883114,0.006786361540468684
0.0071969882425049,190.76178378164,0.022850437669953056,38.45757561037862,192.1346940966357,0.007171213515675091
0.0075818162613164,190.628321167382,0.024072266629679567,38.430669547344216,192.0736300726763,0.007553218748836151
0.0079642776368627,190.523980819197,0.025286581497039072,38.40963453315012,192.0413666989214,0.007932730168887153
0.0083620806202036,190.422493266387,0.026549605969146427,38.38917464250362,192.0148215069807,0.008327312114288197
0.0087773302281755,190.294803898362,0.02786802347445721,38.36343246590978,191.96508423288384,0.008739033398007653
0.0091814379446229,190.110314850293,0.029151065474177704,38.32623947381907,191.8558009087237,0.009139544774377532
0.0095911784313097,190.000683220934,0.030451991519408295,38.3041377373403,191.82301367577674,0.009545475079741687
0.009995767892193,189.883069978042,0.03173656305771277,38.280426907573265,191.78109707219951,0.009946140638639562
0.0104015377016832,189.826111301202,0.03302488220284416,38.268944038322324,191.80059475466538,0.010347813927177941
0.0108063896220043,189.717285648238,0.03431028704986365,38.24700478668478,191.76744455498195,0.010748417863331541
0.0112023742664779,189.598454991841,0.03556753829606733,38.22304852635515,191.7224078450056,0.011140092376922121
0.0116176090931332,189.496005964153,0.036885908870697905,38.20239480237325,191.69749648615456,0.011550642832131702
0.0120148233084943,189.395151895151,0.0381470640044694,38.182062622062446,191.67070118065666,0.011943218296037448
0.0124220205659137,189.301560792773,0.039439915296776,38.163194655823034,191.65306867410038,0.012345500307593488
0.0128233419956817,189.205759734411,0.0407141108362894,38.14388116245726,191.63200989903817,0.012741819136353397
0.013231392983355,189.140156256651,0.04200967272215212,38.13065550134085,191.64274399301593,0.013144622660014958
0.0136406356273632,189.060968550227,0.04330901811687816,38.11469125972576,191.63988033357703,0.013548439619144866
0.014052751372099,188.97493616649,0.04461748560641432,38.09734713116439,191.63055395999595,0.013954926865246752
0.0144528135434807,188.85177586427,0.04588768300055122,38.07251801423683,191.5812153681915,0.01434936716995978
0.014862131230474,188.753982900839,0.04718726665675495,38.052802952809145,191.5592693649859,0.014752771967818526
0.0152665081392236,188.616630545805,0.048471163342034926,38.025112718034286,191.49614787122547,0.015151147623681551
0.0156612375146798,188.549453420195,0.04972442910910836,38.011569809511315,191.50237119347173,0.015539865913902684
0.0160641411387975,188.395078217839,0.05100364811568205,37.980447768716346,191.42148334418513,0.015936478205733195
0.0164587665604946,188.302924345087,0.052256583829570345,37.96186954796954,191.40215821954126,0.01632478913217923
0.0168518017011634,188.265188313603,0.0535044704011938,37.954261964022365,191.43779593429602,0.016711385406943165
0.0172605345259933,188.258459786757,0.05480219712002872,37.952905493010206,191.50790143171662,0.01711326373298398
0.0176667588688174,188.264846890929,0.05609195940849525,37.954193133211284,191.59087654442584,0.017512515686150712
0.0180722579422926,188.173465086596,0.057379418966779,37.93577056145775,191.57418448553594,0.017910895906296367
0.0184874227133054,188.046028463782,0.05869756711474464,37.91007933829845,191.5225148815502,0.01831860777519704
0.0188891082629183,187.891401944426,0.059972918734765596,37.87890663199629,191.44050297742578,0.01871292423924816
0.0193003440742732,187.782240308829,0.0612785924358174,37.856899646259926,191.40650215782725,0.019116454751550264
0.0197031766418052,187.713506770184,0.06255758583773151,37.8430429648691,191.41205915212964,0.019511581654157673
0.0201021296503554,187.663915961267,0.0638242616398784,37.83304545779143,191.4363603306138,0.01990274939198697
0.0205276841580105,187.678458487441,0.06517539720168333,37.83597723106811,191.53106260653345,0.02031983093313121
0.0209349446521507,187.626679225942,0.06646844927057846,37.82553853194991,191.55463337080394,0.020718819867629017
0.0213670955249592,187.55110510205,0.06784052829174546,37.81030278857328,191.55852748057717,0.021142019640000356
0.0217792097301046,187.453503294236,0.0691489908930821,37.790626264117975,191.536092457124,0.021545430995980518
0.0221871566044512,187.31328001036,0.07044422221913256,37.76235725008858,191.46922908804325,0.021944602808670267
0.0226288450874948,187.196116718133,0.07184658315279599,37.73873713037561,191.4321486443282,0.02237661086176407
0.0230519373916833,187.072636336168,0.07318990121859446,37.71384348537147,191.38502303668648,0.022790255369592394
0.0234615793008138,186.944659352117,0.07449051428008381,37.688043325386786,191.33067630237028,0.023190586871202408
0.0238701691708376,186.889910631261,0.07578778711740938,37.67700598326222,191.3510044143519,0.023589730659944495
0.024284760943187,186.822821701694,0.07710411599461872,37.663480855061515,191.35976926545132,0.023994574816913607
0.0247044810368547,186.771076332124,0.07843672729201367,37.6530489885562,191.3851588456039,0.02440425983715557
0.0251402661040503,186.694140433081,0.0798203448803597,37.63753871130913,191.3876808036356,0.024829448207512667
0.0255636720888578,186.589425412185,0.0811646588821235,37.616428163096494,191.3593362986705,0.02524238542671674
0.0259920687808789,186.497129729311,0.0825248183792905,37.5978213534291,191.3445759526718,0.02566001648563799
0.0264200953895669,186.411902519604,0.0838838028618749,37.58063954795217,191.33692276592257,0.026077112644358216
0.0268395470567888,186.352786586161,0.08521556190530444,37.56872177577006,191.35441097090398,0.02648568413174907
0.0272609461771637,186.220481881964,0.08655350411249475,37.542049147403944,191.29702841563372,0.026895984531047728
0.0276697092462383,186.081677036308,0.0878513268568066,37.5140660905197,191.2305029359551,0.027293820899284404
0.0280760901931691,185.969716074988,0.08914158636331189,37.491494760717586,191.19101859670744,0.0276891819914341
0.0284992879334092,185.882543609757,0.0904852391885742,37.47392079172701,191.18006374188593,0.02810073777559301
0.0289428006650347,185.878308338194,0.09189339211148516,37.47306696097991,191.2581471643802,0.028531868003707925
0.0293827492131123,185.836085252774,0.09329022875163154,37.46455478695924,191.29646034050282,0.028959349997315063
0.0298303405467658,185.781586725607,0.09471133123598141,37.45356788388238,191.32351472495034,0.029394070758297166
0.0302615609056653,185.688666962652,0.09608045587548732,37.43483525967064,191.3078958674341,0.029812712630432704
0.0307030308827889,185.554420806145,0.09748212305285475,37.40777123451883,191.2515039185941,0.030241123662465636
0.0311487946726673,185.407885038111,0.09889742308571868,37.378229623683175,191.18311717985665,0.030673515351624474
0.0315760548827162,185.252500427548,0.10025397425262392,37.346904086193675,191.10204354820866,0.031087783125875942
0.0320041274751416,185.115566201353,0.10161310473357457,37.319298146192764,191.04002837969415,0.03150266654278942
0.0324291473226311,185.034164414784,0.10296254274935374,37.30288754602045,191.03466459231095,0.031914421050607884
0.0328592126901684,184.962878887683,0.10432800029128467,37.28851638375689,191.04061346483923,0.032330891101066885
0.0333103456573353,184.932966692531,0.10576034746203958,37.28248608521425,191.0931477364957,0.03276757643747933
0.0337502661504714,184.874002582735,0.10715709502774669,37.270598920679376,191.11354937420523,0.0331932248168882
0.0342121524034348,184.781607727454,0.1086235838809055,37.25197211785473,191.10338425237737,0.033639931446080386
0.0346657515721862,184.654970549778,0.11006376124169119,37.22644206283525,191.05617388542598,0.03407842921837313
0.0351030095114253,184.460383728748,0.11145205519877532,37.1872133597156,190.9354983332594,0.03450094786293437
0.0355471535154493,184.306517531177,0.11286221241155152,37.156193934285284,190.8580896037556,0.03492993777032276
0.0359926219936267,184.193213907058,0.11427657482976476,37.13335192366289,190.82281062900597,0.03536002218415888
0.036451357048551,184.12203373058,0.11573305862914941,37.11900200008493,190.8335317225987,0.03580272178622809
0.0368993472772178,184.062630646483,0.11715542760516652,37.107026338330975,190.85442157546586,0.03623486308745991
0.0373516544494729,183.951770274215,0.11859150287707645,37.084676887281745,190.8226732328663,0.03667097923641926
0.0378143774174466,183.845256461639,0.12006064830039295,37.06320370266643,190.79725037588668,0.03711694160139334
0.0382746919276435,183.716658446496,0.12152214687026812,37.0372783428136,190.74835695051175,0.03756038550227109
0.0387354647679511,183.624558348297,0.12298510063824475,37.01871096301667,190.73734095872805,0.03800407408644217
0.0391974107761234,183.492471358023,0.12445177921419177,36.99208222577744,190.6849011321695,0.03844869481622529
0.0396425648248465,183.292468600277,0.12586514331888762,36.951761669815845,190.5586521686696,0.03887696641072191
0.0400783102774177,183.144955117482,0.12724863513080117,36.92202295168437,190.48509545442417,0.03929600866217408
0.0405248034112693,182.997767459371,0.12866625083078004,36.89234991980919,190.41371601036317,0.03972520454078077
0.0409804812687152,182.954417017978,0.13011302802817076,36.883610470824365,190.45197707761193,0.040163039475026745
0.0414392678407637,182.940937706659,0.13156967539442474,36.88089304166246,190.52187622332573,0.04060366781584783
0.0419083849373039,182.881677555996,0.13305912217593988,36.86894619528879,190.54595329699256,0.04105401714073671
0.0423683344740824,182.838231937979,0.1345194619552116,36.860187558696566,190.58478330337715,0.04149536884798468
0.0428435752421904,182.691913113596,0.13602835139395453,36.83068968370095,190.51908783921803,0.041951188972665476
0.0433237320246995,182.533835667292,0.13755284917842092,36.79882127052607,190.4418826491823,0.04241151330937172
0.0438025405120251,182.406374845127,0.13907306612567968,36.773125168777604,190.3962374689323,0.04287033413111656
0.0442927605945534,182.283074802889,0.14062951488770703,36.74826788026242,190.35689539557242,0.04333987217497396
0.0447622759478052,182.27773496254,0.1421202261342815,36.747191368448064,190.43690123407413,0.04378937240636517
0.0452532010608992,182.181884253785,0.14367891336835495,36.727867865563056,190.426197691575,0.04425915373336792
0.0457351924988454,182.051999741447,0.14520923618383413,36.70168314787571,190.37818299442182,0.04472017154481771
0.0462272945341861,181.920139868822,0.14677166014604087,36.675100197554514,190.32981575623836,0.04519064082662169
0.0467158702962975,181.801603359709,0.14832288819074455,36.65120323731733,190.2946234819201,0.04565751998435148
0.0472135350422575,181.718131533695,0.14990297375916756,36.634375317192905,190.29768690467466,0.046132860513083504
0.0477150754034431,181.589752034841,0.15149536440593184,36.60849401022395,190.25432074567595,0.04661167431921198
0.0482010007501154,181.463082393447,0.1530381773816164,36.582957410518915,190.2097845640118,0.04707536211750461
0.048697938659188,181.31433557821,0.15461595524292188,36.55297005256714,190.14396997022908,0.047549336240945775
0.0491885417306904,181.154965279974,0.156173619994942,36.52084100044276,190.06571384936976,0.04801704799277963
0.0496854333733853,181.032781296399,0.15775125096049833,36.49620870935404,190.02747348989988,0.04849053202076038
0.0501875076242408,180.888330074583,0.15934533670696452,36.467087343035935,189.96666451933731,0.04896872691590903
0.0506772914829633,180.800127660581,0.16090040045840848,36.449305736373134,189.96258843019328,0.04943499572845158
0.051186205218411,180.728013851316,0.16251620156845492,36.43476759242531,189.9787950570253,0.04991924577246379
0.0516982203765779,180.645668402389,0.1641418496956348,36.41816674992162,189.9847279775299,0.050406210402619306
0.0522116005431385,180.553955878941,0.16577183172446475,36.399677505194504,189.98096689977572,0.05089423529004103
0.0527284664058829,180.371326136977,0.1674128808386782,36.36285934921456,189.88202954777512,0.05138533323743441
0.0532345105509527,180.196772543279,0.1690195709992748,36.327669344725045,189.7894595324818,0.0518659154322274
0.053736751500846,180.021933243184,0.17061418601518605,36.2924217418259,189.69572713457487,0.05234265753920503
0.0542477900509013,179.913992856399,0.1722367334116116,36.27066095985004,189.6739293680923,0.05282751741364295
0.0547607859939927,179.835219283033,0.1738654955309268,36.25478020745946,189.68313724037392,0.05331399808426281
0.0552822221745716,179.736545209678,0.17552105540426483,36.23488751427109,189.6727808348494,0.053808240324041676
0.0558083533220379,179.642180739049,0.17719152179747033,36.215863636992275,189.66771503327524,0.05430668521737409
0.0563406225829415,179.533432289718,0.17888147670083926,36.193939949607156,189.64845763937308,0.054810692537163544
0.0568720899431978,179.370038095151,0.180568885569653,36.16099967998244,189.57118703481322,0.055313687212816695
0.0573984474627307,179.20179680909,0.18224007069416995,36.127082236712546,189.48770172846352,0.0558115965589432
0.0579194673750412,179.066682573078,0.1838943089157558,36.09984320673253,189.43812945232625,0.05630421274603466
0.0584543364465597,178.919591503756,0.18559251821782705,36.070189647157214,189.3782175023976,0.0568096707912443
0.0589847290342993,178.788274527845,0.18727651468390027,36.04371614481355,189.33405245537986,0.05731064633994291
0.0595179761272082,178.596733390917,0.18896957420388602,36.005101451608866,189.22644950527496,0.0578140651959788
0.0600526314556267,178.424059964833,0.19066710487161476,35.97029048891033,189.13889428071775,0.05831855920796924
0.060575953889967,178.233387854202,0.19232865360064522,35.931850991407124,189.03004533851075,0.05881211328771711
0.0611005735963091,178.140572013659,0.1939943211682814,35.91313931795366,189.02506314446816,0.05930664646488851
0.061642499519005,178.048818104186,0.19571493597284087,35.8946417298039,189.0241922885327,0.059817236692535886
0.0621764955607029,177.97648305059,0.19741037340523168,35.880058982998946,189.0424370588945,0.060320100688185
0.0627252111294406,177.917237085754,0.1991525453359739,35.86811499648801,189.07713334552466,0.0608365627713079
0.0632861073287902,177.813244980351,0.20093339076890887,35.84715018803876,189.06635308665795,0.061364213971932764
0.0638430463718642,177.693480851641,0.20270167223066884,35.82300573969083,189.03797398963027,0.06188786722996995
0.064409945779065,177.580082516269,0.20450157784853137,35.80014463527983,189.01800600258377,0.06242060410166622
0.0649805849840966,177.468795285421,0.2063133573245067,35.777709129540874,189.00082141949053,0.06295656893333765
0.065558485551352,177.350101207722,0.2081481916255426,35.75378040347675,188.97690525527926,0.06349906129071381
0.0661257903220657,177.143178125621,0.20994938427255858,35.7120647101252,188.85691077934018,0.06403132096024151
0.0666937282848441,176.908538506193,0.21175258730438,35.66476136284851,188.7072285045939,0.06456389108279273
0.0672569715944223,176.664045546507,0.2135408848122908,35.61547158217581,188.54593423958414,0.06509177893201971
0.067818878768212,176.466076063807,0.21532494008907307,35.575560934463496,188.4338074830804,0.06561813698779315
0.0683777042937481,176.394051397377,0.21709921113265024,35.561040761711205,188.45547168300305,0.06614133372232094
0.0689318116584256,176.290391952814,0.21885850201550128,35.5401430176873,188.44240804809542,0.06665984297234416
0.0694908419695377,176.133399978991,0.22063342325328217,35.508493435764585,188.37305824248844,0.06718268659532821
0.0700568545945479,175.987392312046,0.22243051333768957,35.479058290108476,188.31651546572468,0.06771178219728502
0.0706237939340252,175.828474644377,0.22423054574052997,35.4470204883064,188.24614860539546,0.06824146358915656
0.0712035242888684,175.743707719806,0.22607118961715716,35.429931476312895,188.257279081049,0.06878280542756555
0.071758787286416,175.591034736388,0.22783414963437082,35.39915260285582,188.19123444743815,0.0693010254699571
0.0723315345744138,175.425396372961,0.2296526222737638,35.36575990878894,188.11418449594206,0.06983528216220683
0.0729109979382779,175.31935857189,0.23149241845403234,35.34438268809303,188.10206796326526,0.07037551327283874
0.0735085411055927,175.218369994293,0.23338961801025682,35.32402339084947,188.09841674747344,0.07093229462138893
0.0741103819024755,175.154749964666,0.2353004625403597,35.31119759287667,188.13553537658,0.07149276725104386
0.0747026436363743,174.93964745378,0.23718089354548838,35.26783292668205,188.00810159539267,0.07204401274505125
0.0752965010620826,174.74797358951,0.23906639087211226,35.229191475645216,187.9058845684893,0.07259643849114993
0.0758975812910602,174.584338877786,0.2409748205991161,35.19620271776166,187.83486792990877,0.07315527253550834
0.0764953290603295,174.443224470461,0.24287266976654617,35.167754053244934,187.78731632867382,0.07371069880713507
0.0770955507694406,174.335720971827,0.24477837369297387,35.14608134792032,187.77622939893752,0.07426811361630252
0.077711402848768,174.167156749599,0.24673370404483838,35.11209880071916,187.7019308307916,0.07483972129100547
0.0783143077728083,173.989399100847,0.24864792717866635,35.07626285873076,187.6152584512367,0.07539899564175674
0.0789252733886682,173.814428020201,0.25058774300902154,35.040988688872524,187.53277927059037,0.07596542844554063
0.0795366218262679,173.617004130164,0.2525287742984006,35.00118803264106,187.42591413027444,0.07653189520161593
0.0801397686301508,173.406127342688,0.25444376540072877,34.9586752722859,187.30285426698148,0.0770904481609659
0.0807474817518234,173.225229747905,0.2563732545620393,34.92220631717765,187.21273082592938,0.0776529144697351
0.0813441590684202,173.073772765828,0.2582677050422341,34.891672589590925,187.15231326826316,0.07820485900388839
0.0819486991959571,172.904466210856,0.26018711994716376,34.85754038810857,187.07376230200694,0.07876376635752227
0.0825535681088072,172.674439520503,0.2621075787454628,34.81116700733341,186.92933062410896,0.07932266522099954
0.0831349854503658,172.412131537789,0.2639535788049114,34.758285718018264,186.74561158464965,0.07985960055694302
0.0837318298569303,172.157223260873,0.26584855979575367,34.706896209392,186.57226258759397,0.08041048298076528
0.084320569113528,172.032250606992,0.2677178069354514,34.68170172236959,186.53810788405463,0.08095358726306828
0.0849192023267423,171.895832077312,0.2696184673874068,34.654199746786105,186.49308902060898,0.08150551631793095
0.0855232774986812,171.777391210197,0.2715364060583128,34.63032206797572,186.4683567066662,0.08206215414008143
0.0861194056112124,171.613680899572,0.27342911281559934,34.59731806935371,186.3929490933954,0.08261116538593796
0.0867295191378689,171.392114722773,0.27536622326273374,34.552650328111035,186.25687041670156,0.08317274473528122
0.0873429336999672,171.218806545144,0.27731381449739584,34.517711399501025,186.173559413404,0.08373704476822187
0.087950839736398,171.057975315398,0.27924391616306365,34.485287823584244,186.1026678879953,0.08429596334710952
0.0885662704646801,170.911471224763,0.2811979087253593,34.45575259891222,186.04846281077175,0.08486148221374241
0.0891933653449861,170.739002771033,0.2831889349703309,34.42098295864025,185.96778902382835,0.08543739048876675
0.0898278994767622,170.54334716673,0.28520358083872,34.38153878881277,185.86289781245358,0.0860197933867613
0.0904593254930678,170.315569732236,0.28720835844049025,34.33561885801878,185.72220129118165,0.08659900701212882
0.0910954913973949,170.098450683653,0.28922818518672877,34.29184765782445,185.59365263461592,0.08718222950778572
0.0917081016097092,169.869843105506,0.2911732226108267,34.24576037007001,185.4482839374511,0.08774353537182329
0.0923350574536733,169.618362679498,0.2931638074154127,34.195061916186795,185.28008394270742,0.08831765943030043
0.0929543199302883,169.361764443792,0.29512996577866535,34.14333171186847,185.10467207985835,0.0888844150276141
0.0935614274129997,169.063768981685,0.29705753203627405,34.0832558267077,184.88161653143305,0.08943973460310833
0.0941554809310387,168.794665009213,0.2989436519560479,34.02900446585734,184.687607871749,0.08998281541066075
0.0947531481016042,168.557364375871,0.3008412452225933,33.981164658175594,184.52870528619397,0.09052890233040772
0.0953460266592888,168.365400825471,0.3027236346432419,33.942464806414954,184.41837282107818,0.09107031943060083
0.0959569034108588,168.146129430764,0.30466316832947665,33.898259693242025,184.28091133146157,0.09162786604728439
0.0965535865318947,167.924258611737,0.30655763723876567,33.85353053612618,184.1379480464096,0.09217215820780435
0.0971690097831688,167.669532889075,0.3085116060615609,33.802177830437515,183.96181537071286,0.09273323486212043
0.0977788921538199,167.425432896039,0.31044798258837814,33.75296727184147,183.7961062429874,0.09328894954291822
0.0983898485296237,167.190393778704,0.3123877690815552,33.705583385786724,183.6402312981988,0.0938453333764979
0.0989942857663633,166.840125808777,0.31430685730820346,33.63496936304944,183.35634490038709,0.09439547592331113
0.0995965505517283,166.474191182213,0.31621904800173734,33.56119694233414,183.05444637985033,0.09494334030123966
0.100186315497874,166.099382229982,0.31809155170574993,33.48563545756437,182.74026734207695,0.09547954318687742
0.100781158818961,165.845782739982,0.31998017925020117,33.434509800380376,182.55991290975507,0.09602007215199067
0.101375466316606,165.608868397607,0.321867105555224,33.38674786895757,182.39754465757986,0.09655982259961074
0.101990633659928,165.423361660916,0.32382026187027135,33.34934971084066,182.29499513886822,0.09711821129344826
0.10260088049412,165.140864487017,0.325757795568831,33.29239828058263,182.08446258894512,0.09767182573481793
0.10320260793265,164.82630373468,0.32766828018616373,33.22898283291149,181.83680813599807,0.09821741146501835
0.103817709829643,164.43133023994,0.32962122870911653,33.1493561763719,181.50221436969227,0.09877481631350887
0.104413774227921,164.064799070488,0.3315137331736492,33.07546349261038,181.19542395938313,0.09931467313292122
0.105004192313506,163.669757454896,0.33338831059538154,32.99582310290703,180.8557681425948,0.09984912891139344
0.105594663752372,163.310602433782,0.3352630574137811,32.923417450650454,180.5553305849745,0.10038334745700465
0.106180213390627,162.896723180014,0.3371221775152407,32.83997939309082,180.1931320079018,0.10091283140945069
0.106757674060242,162.483696712661,0.3389556151412683,32.75671325727245,179.83007824641447,0.10143472647573044
0.107344183092237,162.080930545475,0.34081778131785245,32.67551559796777,179.47937562970864,0.10196452057153398
0.107920037689701,161.657126990222,0.3426461196648007,32.590076801228754,179.10317022781553,0.10248441757075641
0.108513472347682,161.269639937015,0.3445302747038903,32.51195941130222,178.7695685508409,0.10301990367442156
0.109100961065909,160.851077707644,0.34639555138426104,32.42757726586103,178.4000848740352,0.10354974215591678
0.109695088182464,160.374705282757,0.34828190497932315,32.33154058500381,177.9670227209857,0.10408528225745617
0.110269075505538,159.875647057511,0.35010431473008313,32.23093044679422,177.50498685439243,0.10460239631294707
0.110845610365421,159.326064534989,0.35193481291021167,32.12013461025378,176.98665940549031,0.1051215364334449
0.111402204834477,158.802814356542,0.3537020003494645,32.014647374278866,176.4937980097809,0.10562246569694811
0.111948882906581,158.26886015362,0.3554377032283947,31.907002206969796,175.98688224671568,0.1061142261626121
0.112525567515376,157.753225966681,0.3572686768613188,31.80305035488289,175.5044972459631,0.10663271683046832
0.113088596315837,157.20028276731,0.35905629330278244,31.691577005889695,174.97784208591776,0.1071386704873255
0.113660719479114,156.650062492394,0.36087278434618697,31.58065259846663,174.45502130172767,0.10765253450588214
0.114219673318935,156.070619816161,0.3626474627876186,31.46383695493806,173.89695502624662,0.10815431534955385
0.114785466696619,155.479810072493,0.36444385676176533,31.34472971061459,173.3266326335658,0.10866197984944971
0.115343962205409,154.880615574645,0.36621708000217357,31.22393209984843,172.74515944383734,0.10916284362285014
0.115891278663358,154.137188531742,0.3679548097561616,31.074057207999186,172.00034440026064,0.10965343866088227
0.11643821963997,153.480345563218,0.36969134735690473,30.94163766554475,171.3513237503265,0.1101434568127474
0.116980576449079,152.765026917025,0.3714133302258258,30.79742942647224,170.63556782703768,0.11062913090192368
0.117503522416692,152.025789940399,0.3730736836729971,30.64839925198444,169.88935575657598,0.11109719955135028
0.118026072878664,151.304600207495,0.3747327813897582,30.503007401830995,169.16248797846194,0.111564695461571
0.118550521696311,150.58305091845,0.3763979063857874,30.357543065159522,168.4347501634544,0.1120336700797721
0.119079140284765,149.870340313986,0.3780762704041289,30.213860607299576,167.7167715927606,0.11250615094402742
0.119601938327103,149.172330911546,0.379736154188552,30.073141911767674,167.0136308333389,0.11297320992517167
0.120162183379976,148.260529678719,0.3815149322314238,29.88932278322975,166.0758386339856,0.11347348141280533
0.120706744534325,147.411390033583,0.3832439138964819,29.718136230770334,165.20493903181645,0.11395950820204348
0.121266803353257,146.566897530397,0.3850221006465909,29.547886542128037,164.3405966713126,0.1144591205468094
0.121814367191544,145.664096674895,0.3867606158331522,29.365881889658837,163.4080764338752,0.11494734527657309
0.122338648568311,144.757381590414,0.3884252092043874,29.183088128627464,162.4668040244726,0.11541458737871459
0.122864825672167,143.786735318869,0.3900958215091302,28.98740584028399,161.45306748779186,0.11588329956406951
0.123386563513777,142.819963334536,0.39175233915624197,28.792504608242456,160.44202781154803,0.11634784049079243
0.123934531834585,141.913103872363,0.39349213857480736,28.60968174066838,159.50103796197715,0.11683550407638497
0.124462601270566,140.795911819259,0.395168759034047,28.384455822762618,158.31973725254522,0.117305233767742
0.124985950167952,139.773664700263,0.3968303917832476,28.17837080357302,157.2434089912821,0.11777054683880027
0.125522348530505,138.633803375535,0.39853345658435335,27.948574760507853,156.0354439609484,0.1182472377028336
0.126054058310416,137.577164806446,0.40022163513557074,27.735556424979514,154.91932476113945,0.11871953772177087
0.126585169383896,136.44806830947,0.4019079127938698,27.50793057118915,153.72037014852967,0.11919108334416058
0.127090945379992,135.180139782686,0.40351375158147457,27.2523161801895,152.36031154426703,0.11963992867847806
0.127596689483801,133.957066229359,0.4051194891110682,27.00574455183877,151.04954441318748,0.12008854435762649
0.128077888597528,132.590037540912,0.40664729629715135,26.73015156824786,149.57188959821897,0.12051520086712703
0.12860060774433,131.255782283881,0.4083069295882477,26.461165708430407,148.13535565554554,0.1209784650467591
0.129135798146106,129.863425893513,0.41000615911388655,26.180466660132225,146.63344304625952,0.12145255972885231
0.129677112737712,128.363869683901,0.4117248329422356,25.87815612827444,145.0097256843492,0.12193185095245061
0.130236712208695,126.794907151963,0.4135015612626066,25.56185328183574,143.3082589842414,0.12242709061711658
0.130789529429666,125.238968091314,0.4152567559391896,25.248175967208905,141.61891379423392,0.12291608735833628
0.131372522542,123.488280661315,0.41710775907084996,24.895237381321103,139.71124759616643,0.12343151738664285
0.1320035493895,121.690119416288,0.41911126931166254,24.53272807432366,137.7536471048701,0.12398911527916737
0.132647285551589,119.589100661563,0.42115513162629503,24.1091626933711,135.45227024587507,0.12455762338601979
0.13332554299691,117.272296454319,0.4233085990151892,23.642094965190715,132.90768905758569,0.1251562691041253
0.134028473299291,114.648664984687,0.42554040272524885,23.113170860912902,130.01485051838648,0.12577631371987488
0.134799734547057,111.641630022095,0.4279891571869059,22.506952612454352,126.69089211347416,0.12645619003206754
0.13572030346703,108.070052074535,0.43091196350782024,21.786922498226254,122.73735233778862,0.12726707824710454
0.136729741968321,103.554114175807,0.43411693074941915,20.87650941784269,117.71304148682313,0.12815549255545217
0.137823900433592,98.3035608629817,0.43759088387665457,19.81799786997711,111.85214104762883,0.12911757894398215
0.138949026854807,92.7055140647078,0.4411631602640122,18.689431635445093,105.58685502807357,0.13010593092174755
0.139568352781305,89.6957060458488,0.4431295200806433,18.082654338843117,102.21438799022405,0.13064955279383442