File: example/data/02 processed data/test_ID_120.csv
Strain,Stress_MPa,Displacement(mm),Force(kN),True Stress (MPa),True Strain
-0.0002245301317713,0.408270021278028,-0.0007128831683738774,0.08230723628965045,0.40817835235635214,-0.0002245553424350708
-0.0003429452759482,1.38907372398837,-0.001088851251135535,0.2800372627560554,1.3885973477167843,-0.00034300409512761943
-0.0005188240305973,3.21651252189436,-0.0016472662971464274,0.648448924413903,3.214843717903284,-0.0005189586663548855
-0.0007416765896315,6.25911139087083,-0.0023548231720800124,1.2618368563995592,6.254469154480325,-0.0007419517677838803
-0.0008917937530734,9.60075357047406,-0.0028314451660080447,1.9355119198075705,9.592191678415114,-0.0008921916376939667
-0.0009893466336398,13.1113053833301,-0.003141175561806365,2.6432391652793483,13.098333757486479,-0.00098983636005332
-0.0010302401600179,16.6117652009839,-0.003271012508056832,3.3489318645183546,16.59465109334506,-0.0010307712221905552
-0.0010090066052754,20.5148281628913,-0.0032035959717493945,4.1357893576388856,20.49412856576885,-0.0010095159951207485
-0.000973660951222,24.551589790099,-0.00309137352012985,4.949600501683959,24.52768486582996,-0.0009741352669527424
-0.0009030949730696,28.9108709121007,-0.0028673265394959795,5.828431575879502,28.884761649912917,-0.0009035030090167821
-0.00079571293401,33.3691303739368,-0.00252638856548175,6.7272166833856595,33.34257812530159,-0.0007960296815846231
-0.0007022970749725,37.9518073510604,-0.0022297932130376876,7.651084361973777,37.925153907767836,-0.0007025438010866972
-0.0006143220017586,42.5449090882597,-0.001950472355583555,8.577053672193156,42.518772814543965,-0.0006145107748351114
-0.0005349667395628,46.9409715431531,-0.00169851939811189,9.463299863099664,46.91585968465475,-0.000535109885323413
-0.0004497348948179,51.2409603441275,-0.0014279082910468323,10.330177605376106,51.21791549621677,-0.0004498360558873088
-0.0003327540281969,55.4557829975235,-0.0010564940395251575,11.179885852300739,55.437329862344264,-0.00033280940310300995
-0.0002229626557652,59.7583763499728,-0.00070790643205451,12.047288672154517,59.745052463677595,-0.00022298751563337404
-0.0001341924018148,64.0145115033451,-0.00042606087576199,12.905325519074374,64.00592124229547,-0.000134201406420709
-4.59986351994552e-05,68.2427096848307,-0.00014604566675827023,13.75773027246187,68.23957061332288,-4.5999693169159324e-05
5.18850577614308e-05,72.4339881778924,0.00016473505839254278,14.60269201666311,72.4377464195529,5.188371177827297e-05
0.0001464754641573,76.6079028800166,0.00046505959869942747,15.444153220611344,76.61912405814907,0.00014646473767399005
0.0002496805099783,80.7500927803471,0.0007927356191811025,16.279218704517977,80.7702545046933,0.0002496493449871995
0.0003452457467246,84.7652222095655,0.001096155245850605,17.088668797448403,84.79448704200351,0.0003451861631253444
0.0004435631828071,88.7759377602375,0.0014083131054125424,17.897229052463878,88.81531549774711,0.00044346483773888273
0.0005357627424728,92.8492164778121,0.0017010467073511398,18.71840204192692,92.8989616286687,0.000535619272856075
0.0006459635547706,96.7857550803674,0.0020509342863966546,19.512008224202066,96.84827515077026,0.0006457550101169306
0.000759310332311,100.674825407314,0.002410810305087425,20.2960448021145,100.75126884244938,0.000759022202064827
0.0008605994712372,104.400775669865,0.0027324033211781097,21.047196375044784,104.49062292220323,0.0008602293678375363
0.0009612245466038,108.046929855225,0.0030518879354670646,21.78226105881336,108.15078721638702,0.0009607628661179724
0.0010523198945337,111.709551532365,0.0033411156651444976,22.520645588924786,111.82710571585196,0.001051766594085614
0.0011253521977116,115.293734689405,0.0035729932277343297,23.24321691338405,115.42348074712011,0.001124719463581929
0.001227304116126,118.743500578178,0.0038966905687000493,23.938689716560685,118.8892349652008,0.001226551594081867
0.0013173617012618,122.296984303033,0.0041826234015062145,24.655072035491454,122.45809366633364,0.0013164947416519307
0.0014172471923088,125.812874008395,0.00449975983558044,25.363875400092436,125.9911819508397,0.001416243845388652
0.001521817525668,129.326625944448,0.0048317706439959,26.07224779040072,129.52343747034578,0.0015206607348448697
0.0016224385221938,132.716864560593,0.005151242307965315,26.755719895415552,132.9321895142009,0.001621123790670035
0.0017206346031753,135.990709189951,0.005463014865081577,27.41572697269412,136.22469950989355,0.0017191560072956486
0.0018208262170938,139.23590286359,0.005781123239272814,28.069958017299747,139.48942724588477,0.0018191705225540419
0.0019147138051831,142.512453587333,0.0060792163314563425,28.730510643206337,142.7853241496272,0.001912883077212863
0.0020118795566536,145.783445402396,0.006387717592375179,29.38994259312304,146.07674413589962,0.00200985843735665
0.002107584150451,149.060589388295,0.006691579677681925,30.05061482068027,149.37474712394666,0.002105366310618063
0.0021956215752057,152.189118387682,0.0069710985012780965,30.681326266956688,152.52326809952552,0.0021932147205391164
0.0022921186486116,155.278272332697,0.007277476709341829,31.304099702271717,155.63418855643494,0.0022894957518909327
0.002379980412382,158.40583986569,0.007556437809312849,31.93461731692311,158.7828426617773,0.0023771527446409466
0.0024871558489193,161.535997094026,0.007896719820318776,32.56565701415564,161.9377622940094,0.002484067995732457
0.0025836028085846,164.727824170695,0.008202938917256104,33.20912935281211,165.15341543987444,0.0025802710442516382
0.0026877550041421,167.879916509183,0.008533622138151167,33.8445911682513,168.33113659487555,0.0026841494497806097
0.0027810475378109,170.978300653296,0.008829825932549606,34.46922541170448,171.45379943534695,0.002777187579935304
0.0028847100260089,173.955343734262,0.009158954332578257,35.06939729682721,174.45715445841006,0.002880557234524472
0.0029935726659848,176.741253594451,0.00950459321450174,35.63103672464132,177.27034138016325,0.0029891008495803928
0.0031065308100366,179.497567293127,0.009863235321866205,36.186709566294404,180.05518201624972,0.0031017155132010365
0.0032387121590605,182.316067777351,0.010282911105017088,36.75491926391396,182.9065370428536,0.0032334788272949254
0.0033600451866951,185.076234145459,0.01066814346775694,37.311368803724534,185.69809865517112,0.0033544128479488476
0.0035115432779632,187.710962996853,0.011149149907533159,37.842530140165564,188.37011816716458,0.0035053922054987777
0.00364528278767,190.119628303089,0.01157377285085225,38.328117065902745,190.8126681117405,0.003638654846631847
0.0037969616954836,192.366175381925,0.01205535338316043,38.78102095699608,193.09658238135685,0.003789771431449195
0.003940013439824,194.446582247717,0.0125095426714412,39.200430981139746,195.21270439510084,0.003932271914683861
0.0041124022884004,196.445479681109,0.01305687726567127,39.60340870371157,197.2533425212955,0.004103969473621829
0.0042819179921276,198.192539257029,0.01359508962500513,39.95561591421705,199.04118345677915,0.004272776666928375
0.0044933787432538,199.743674540805,0.014266477509830814,40.26832478742629,200.64119852208603,0.0044833136565566945
0.0046955961005958,201.294993544374,0.014908517619391663,40.581070698545794,202.24019353113044,0.004684606178620902
0.0049257276261916,202.565503625679,0.015639185213158328,40.83720553093689,203.56328612300143,0.004913635920577345
0.005170359988574,203.78491830362,0.016415892963722447,41.08303953000979,204.83855969149187,0.005157039571872874
0.0054204331852006,204.73182670206,0.017209875363011905,41.273936263135305,205.84156188958258,0.005405795508451503
0.0056805498978543,205.543852735427,0.0180357459256874,41.43764071146208,206.71145484708782,0.005664476416364362
0.0059411390862812,206.274377357458,0.018863116598942808,41.58491447526353,207.49988212327472,0.005923560111187832
0.00621589027893,207.020968152836,0.01973545163560275,41.73542717961173,208.30778777631187,0.006196651316642198
0.0065071633936758,207.717481486391,0.020660243774920664,41.87584426765642,209.06913307814577,0.006486083204698146
0.0068070564657252,208.273621335098,0.02161240427867751,41.98796206115576,209.69135163584707,0.0067839930603076515
0.0071187108073083,208.663070903747,0.022601906813203853,42.066475094195404,210.14848296167565,0.0070934923965149275
0.0074422612410818,208.883399716654,0.023629179440434713,42.11089338287745,210.43796454627065,0.007414704254626578
0.0077511867568808,209.014530018893,0.02461001795309654,42.137329251808836,210.63464067597107,0.007721300644690989
0.0080541035165934,209.205487400493,0.025571778665184043,42.1758262599394,210.89045005225594,0.00802184233237711
0.0083757003954497,209.40737457263,0.026592848755552796,42.216526713842214,211.16130800264807,0.00834081885311609
0.0086952822770306,209.565491678514,0.027607521229572152,42.248403122388424,211.38772278418338,0.008657696034931064
0.0090227290405272,209.710212360971,0.028647164703673858,42.27757881197175,211.60237078413547,0.00898226742155154
0.0093513648416521,209.769631442881,0.029690583372245415,42.28955769888481,211.73126379920228,0.00930791151798068
0.0096857738379972,209.846865040163,0.030752331935641107,42.30512799209686,211.87939431555475,0.009639167434968579
0.0100081711490955,209.947739815188,0.031775943398378206,42.3254643467419,212.04893272762416,0.009958421067071501
0.0103568917506497,210.101049292605,0.032883131308312795,42.35637153738917,212.27704311682646,0.0103036266058336
0.0106913285521883,210.259304176629,0.03394496815319785,42.38827572200841,212.50725547873586,0.010634580416070767
0.0110369609076129,210.333705698902,0.03504235088167096,42.40327506889865,212.65515058625414,0.010976498131318365
0.0113788881061253,210.298894847783,0.036127969736947825,42.396257201313055,212.69186244109773,0.011314635514821359
0.0117291150109264,210.285847730721,0.03723994015969132,42.393626902513354,212.7523146239248,0.011660862120380922
0.0120859651699053,210.319016433069,0.038372939414449324,42.40031371290671,212.8609247402478,0.012013513077646391
0.0124360660178208,210.355416687449,0.039484509606581036,42.40765200418972,212.97141053658035,0.012359373331091156
0.0127887627111414,210.417076454835,0.040604321607873944,42.42008261329474,213.108050515988,0.01270767707681156
0.0131447870224787,210.419081564504,0.041734698796369867,42.42048684340401,213.184995577135,0.013059143999356147
0.013503801332069,210.439054120315,0.04287456922931907,42.424513310655506,213.28078129966426,0.013413437600534506
0.0138657654634528,210.466086428666,0.04402380534646264,42.42996302401906,213.38435982109667,0.013770515206076374
0.0142286080233695,210.449114218528,0.04517583047419816,42.426541426455245,213.44351217360875,0.014128331458151646
0.014591935403731,210.438932930482,0.04632939490684592,42.42448887878517,213.50964424623365,0.014486497571386779
0.0149654746573839,210.44252093605,0.04751538203719388,42.425212220707685,213.59189314995444,0.014854596799345608
0.0153478161329627,210.441664102393,0.04872931622215657,42.42503948304243,213.67148406975122,0.01523122978680898
0.0157375325979401,210.406841453757,0.04996666599845981,42.41801923707742,213.71812597996512,0.01561498172515414
0.0161046884037447,210.362715433331,0.05113238568188942,42.40912343135953,213.75054141715043,0.015976383615523292
0.0164765410663335,210.269299435317,0.05231301788560885,42.39029076615991,213.73381018245217,0.016342275675673968
0.0168487640317877,210.21001669587,0.053494825800925946,42.3783393658874,213.75179566429685,0.016708398074956343
0.0172260029338249,210.184675614583,0.05469255931489406,42.37323060389993,213.80531745336484,0.017079317485087144
0.0175948275270402,210.146459681824,0.05586357739835263,42.36552627185573,213.8439503953438,0.017441830578852523
0.0179854679930516,210.15685983253,0.05710386087793883,42.36762294223805,213.93662930856817,0.01782564297049993
0.0183805945967032,210.14180031818,0.05835838784453266,42.36458694414509,214.00433155764983,0.01821371328444731
0.0187800338484992,210.099105651744,0.05962660746898495,42.35597969939159,214.04477396742314,0.018605866216658322
0.0191717257365783,209.979671869386,0.06087022921363609,42.33190184886822,214.00534454872258,0.01899026382671943
0.0195338774808131,209.802555143893,0.06202006100158158,42.29619511700883,213.90081255123533,0.019345539985741768
0.0198960329423344,209.684158996816,0.06316990459191171,42.272326453758104,213.85604193170232,0.01970069361321085
0.020264034610667,209.599174243858,0.06433830988886773,42.25519352756177,213.84649916510276,0.020061451259805983
0.0206346605414691,209.615724848829,0.06551504721916439,42.258530129523926,213.94107417523855,0.02042465001705605
0.0210305787397221,209.572131995007,0.06677208749861767,42.24974181019341,213.9795552185794,0.020812488528089416
0.0214188573565564,209.530180712564,0.06800487210706656,42.2412844316529,214.01807776513988,0.0211926973250855
0.0218116397825991,209.462236442409,0.06925195630975214,42.22758686678965,214.03095129174844,0.021577169298689195
0.0221962041709262,209.426923478996,0.07047294824269068,42.22046777336559,214.07540623142475,0.02195345395337119
0.0225837522863137,209.354534822167,0.071703413509046,42.20587422014887,214.08254577660728,0.02233251490690222
0.0229700942099142,209.286461450353,0.07293004911647759,42.19215062839117,214.09379118672717,0.022710253120790943
0.0233745195678399,209.179824228276,0.07421409962789167,42.17065256442044,214.06930212289714,0.02310551925579884
0.0237649704065373,209.076750090293,0.07545378104075592,42.149872818203065,214.04545286888379,0.02348697918595422
0.0241611141186725,208.935987802368,0.07671153732678518,42.121495140957386,213.9841140471586,0.023873852247506277
0.0245540996937914,208.840948038486,0.07795926652778769,42.10233512455878,213.9688494967689,0.024257493250696243
0.0249470873677686,208.781972065682,0.0792070023926653,42.090445568441496,213.9904741636196,0.02464098917768033
0.0253329183947293,208.706337905791,0.08043201590326553,42.07519772180746,213.9934785324212,0.025017358288661057
0.0257320527212161,208.604044276527,0.08169926738986111,42.05457532614784,213.9718545417095,0.025406555449302846
0.0261335940788793,208.483478494361,0.08297416120044177,42.03026926446318,213.9319010934854,0.025797946926045357
0.0265248239889137,208.37920235173,0.08421631616480099,42.00924719410877,213.90642401705986,0.026179140320258566
0.0269436774413555,208.312395215488,0.08554617587630371,41.99577887544238,213.92509719921026,0.026587087613298352
0.0273488632771297,208.251988341245,0.0868326409048868,41.983600849595,213.94744349758014,0.026981564868117106
0.0277608914416867,208.187703579597,0.08814083032735527,41.97064104164676,213.96717981816425,0.0273825441045122
0.0281626879816052,208.066318260156,0.0894165343415965,41.946169761247454,213.92602506079817,0.027773411303133187
0.0285723006315899,207.961726533955,0.09071705450529793,41.92508406924532,213.90367150434764,0.028171724802604853
0.0289880263928729,207.860934403968,0.09203698379737145,41.90476437583995,213.88641265651742,0.02857582062568209
0.0293963706910543,207.775995296163,0.0933334769440974,41.88764065170646,213.88385547459174,0.02897258257560435
0.0298128700798949,207.626465596379,0.09465586250366631,41.857495464230006,213.81640644035164,0.0293771062017361
0.0302178731493003,207.450084046554,0.09594174724902844,41.82193694378529,213.71878437108447,0.029770307202211025
0.0306148938474498,207.312220998336,0.09720228796565311,41.794143753264535,213.65906263747908,0.03015560843520693
0.0310134831546219,207.176101345301,0.09846780901592453,41.76670203121268,213.60135387441372,0.03054228269385097
0.0314077666099551,207.120377507761,0.09971965898660742,41.75546810556462,213.62556598469052,0.03092463276921179
0.0318094153039074,207.037800119215,0.10099489358990599,41.73882050403375,213.6235514868145,0.031313974911713324
0.0322189738520481,206.901573523877,0.10229524198025271,41.71135722241361,213.5677299111904,0.03171082851670024
0.0326343119047718,206.795586678916,0.10361394029765045,41.689990274469466,213.54421835512605,0.03211312156210945
0.0330409443688155,206.690793443017,0.10490499837098921,41.668863958112226,213.52005245071405,0.032506825720651486
0.0334520347632393,206.606263112921,0.10621021037328476,41.65182264356488,213.51766300887738,0.032904688577189346
0.0338700470240312,206.530314758322,0.10753739930129906,41.63651145527771,213.52550623107433,0.03330908832715705
0.0342999699649792,206.440787945863,0.10890240463880896,41.61846284988598,213.52170077195277,0.03372484036263691
0.034738233929721,206.334609781387,0.11029389272686417,41.597057331927616,213.50230972377054,0.034148480651609296
0.0351628257579565,206.247205257899,0.11164197178151188,41.57943657999243,213.499439799448,0.03455873391681102
0.0355952644154182,206.146575499816,0.11301496451895278,41.55914962076291,213.48441736306495,0.034976396091644525
0.0360086708483541,206.042222595301,0.11432752994352427,41.53811207521269,213.4615291695985,0.03537551334701013
0.0364432547790508,205.919741760965,0.11570733392348627,41.51341993901055,213.42412737399619,0.035794904438009784
0.0368753538121536,205.786351266773,0.11707924835358767,41.486528415381436,213.37479577944737,0.03621172319183597
0.0372962859481522,205.622639016979,0.11841570788538323,41.45352402582297,213.29159975916994,0.03661760295000872
0.0377390648180962,205.457478216286,0.11982153079745542,41.42022760840326,213.211251304053,0.03704437050025861
0.0381632939398552,205.317652629333,0.12116845825904025,41.39203877007353,213.15325055766735,0.0374530883051929
0.0385861931296701,205.187445872898,0.12251116318670256,41.36578908797624,213.10484828713336,0.03786035860745453
0.0390246862596858,205.084440912682,0.1239033788745024,41.34502328799669,213.08779687604246,0.03828247146879592
0.0394528218903714,204.926240990104,0.1252627095019292,41.31313018360496,213.0111594765499,0.03869444189913459
0.0398966006924992,204.752441567109,0.12667170719868495,41.27809221992918,212.92136796912624,0.039121285799487336
0.0403054279085227,204.565535118763,0.12796973360955957,41.24041187994262,212.81063654706065,0.039514350718823095
0.0407235259258217,204.426308661513,0.1292971948144839,41.212343826161025,212.75126874221013,0.03991616927320127
0.041146445655167,204.319458288272,0.13063996495515523,41.19080279091563,212.7264777750235,0.04032245760142162
0.041575150925354,204.200792670935,0.13200110418799893,41.16687980246049,212.690471445306,0.040734135549108506
0.0420087404714585,204.09306363239,0.13337775099688073,41.14516162828983,212.6667561745479,0.041150331464380886
0.0424501502481551,203.947795364142,0.13477922703789244,41.11587554541103,212.60540992012983,0.041573856039761124
0.0428913314017546,203.870367076626,0.13617997720057085,41.10026600264781,212.6146385539069,0.04199698209759274
0.0433318540413905,203.743790116433,0.13757863658141484,41.07474808747289,212.57238629159798,0.04241929803124461
0.0437701093322964,203.687251095463,0.13897009713004108,41.063349820845346,212.60266434550633,0.042839263423485235
0.0442173854148656,203.589543938043,0.14039019869219826,41.04365205790947,212.59174126878813,0.04326769136238413
0.0446713708051077,203.467904004474,0.14183160230621694,41.01912944730196,212.55709419119592,0.043702358259831986
0.0451190095531423,203.308792130742,0.14325285533122678,40.987052493557584,212.4818834651268,0.04413076367224884
0.0455597533408362,203.141752372661,0.14465221685715493,40.95337727832846,212.39684050398466,0.044552391137974885
0.0460040837676796,203.005744639983,0.14606296596238272,40.92595811942057,212.34483792172094,0.04497726981071181
0.0464429074623064,202.770388178506,0.1474562311928228,40.87851025678681,212.18763455277633,0.04539670571795296
0.0468877906196902,202.582154228648,0.14886873521751637,40.84056229249544,212.08078385940664,0.045821753862032
0.047317462183846,202.38330251384,0.15023294243371105,40.80047378679014,211.95956677718047,0.04623209718402443
0.0477712188789416,202.251978442071,0.15167361994063958,40.77399885392151,211.91380197292617,0.04666525947094051
0.0482113805229676,202.164581050151,0.15307113316042212,40.756379539710444,211.91121459542617,0.04708526453264481
0.0486663782470326,202.044495517421,0.15451575093432848,40.73217029631208,211.87726935900272,0.04751924093332256
0.0491122044597269,201.881035384927,0.1559312491596329,40.69921673360128,211.7958580712929,0.0479442869539861
0.0495546755775994,201.720173951965,0.15733609495887807,40.66678706871615,211.71635172961152,0.04836595570821981
0.0500120738652221,201.614328536757,0.15878833452208016,40.64544863301021,211.69747922782446,0.048801663022579087
0.0504605240571836,201.501903774497,0.1602121638815579,40.6227838009386,211.6697954374783,0.04922866235522339
0.0509434822858592,201.429885959182,0.16174555625760295,40.608265009371095,211.69142578638622,0.049688315268914554
0.0514009787100134,201.300979332772,0.16319810740429255,40.58227743348684,211.64804668576065,0.05012354026640051
0.0518715116764901,201.165874094509,0.16469204957285608,40.55504021745302,211.60065208151366,0.05057096966651596
0.052329847216315,201.021716025632,0.16614726491180012,40.52597795076741,211.54115171241477,0.05100660815247784
0.05280727808329,200.864733556832,0.16766310791444575,40.49433028505733,211.4718533988936,0.05146019463805434
0.0532519792562242,200.682090084936,0.16907503413851183,40.4575093611231,211.36880858323474,0.05188250106461248
0.0536976013129867,200.427792991432,0.17048988416873276,40.406243067072694,211.19028471152774,0.05230550317867976
0.0541394949248968,200.241274737561,0.17189289638654734,40.3686409870923,211.08223621497007,0.05272478948801803
0.0545875699532103,200.071529025542,0.1733155346014427,40.33442025154927,210.9929476118695,0.0531497615410827
0.055051682433416,199.979902379968,0.1747890917260958,40.31594831980155,210.98913245885552,0.05358975381669853
0.0555183869550649,199.937011915329,0.17627087858233104,40.30730160213033,211.03719230948366,0.054032008291946494
0.0559945643918824,199.837682708612,0.1777827419442266,40.28727683405618,211.02750670096393,0.05448303791465012
0.0564605694300523,199.707757797345,0.17926230794041606,40.26108397194476,210.9833715221821,0.05492423549396726
0.0569037347489349,199.351231633209,0.18066935782786828,40.189208297254936,210.69506123993864,0.0553436287093272
0.0573388153140199,199.053977971521,0.18205073862201318,40.12928195905863,210.46749725195104,0.05575519981427314
0.0577857180108638,198.818149156829,0.18346965468449256,40.08173887001673,210.3069986594474,0.05617777796175625
0.0582467362926488,198.758906054542,0.18493338772915993,40.069795460595664,210.33596364131628,0.0566135163533313
0.0587244008017778,198.712886797988,0.1864499725456445,40.06051797847438,210.38218200679134,0.057064787992198045
0.0591903818196185,198.665142903678,0.1879294622772887,40.05089280938149,210.42420856639578,0.05750482555101146
0.0596523858999244,198.546116510168,0.18939632523225997,40.02689708844987,210.3898660711639,0.057940916510346885
0.0601171842852733,198.455190849311,0.19087206010574273,40.0085664752211,210.3857581299681,0.05837945322616274
0.0606008177996604,198.338878134305,0.19240759651392175,39.98511783187589,210.35837635071107,0.058835556793252676
0.0610926570942958,198.236762341679,0.19396918627438917,39.96453128808248,210.3475728869026,0.05929918578515509
0.0615782251748787,198.118477006991,0.19551086493023986,39.94068496460938,210.3182611954315,0.059756692498144345
0.0620757467750484,197.977861610632,0.19709049601077866,39.912336900703416,210.26748521503916,0.06022524492320358
0.0625665610377191,197.83343113772,0.19864883129475813,39.88321971736435,210.21118858229954,0.06068726553683514
0.0630658971530226,197.662216291569,0.20023422346084677,39.84870280438031,210.12796129525162,0.06115708911575591
0.0635712325025234,197.496692389532,0.2018386631955118,39.81533318572965,210.0518005399063,0.06163233273110064
0.0640423604122711,197.320724236548,0.20333449430896072,39.77985800608808,209.95760917491535,0.06207520254450738
0.0645299934719214,197.149486341545,0.20488272927335044,39.745336446455475,209.87154140815758,0.06253338106711309
0.065015166212887,196.967842256631,0.20642315272591621,39.708716998936815,209.77373925953958,0.0629890396354732
0.0655054151204965,196.70421574629,0.20797969300757638,39.655569894452064,209.58940705470243,0.0634492547777794
0.0659928035604783,196.475789061802,0.2095271513045186,39.609519074859286,209.44177721374746,0.06390657483951297
0.0664647695167913,196.254275285104,0.21102564321581235,39.564861897476966,209.29827045861333,0.06434922464411222
0.066937449621161,196.092937925341,0.21252640254718613,39.53233628574875,209.21889907878398,0.06479234794066085
0.0674135880182252,195.963448539063,0.214038141957865,39.5062312254751,209.17404772550606,0.0652385148518821
0.067897518509516,195.805121403052,0.2155746212677133,39.47431247485528,209.09980325777377,0.06569177948212428
0.0683844287600481,195.650331025196,0.21712056131315272,39.44310673467952,209.02976714906836,0.0661476277933324
0.0688697999483623,195.506603237967,0.2186616148360503,39.414131212774144,208.97110389154963,0.06660182850575934
0.0693691902595067,195.362071237749,0.22024717907393376,39.3849935615302,208.9141799269317,0.06706893281216411
0.0698620741150757,195.226857637112,0.2218120853153653,39.35773449964178,208.86581083460925,0.06752973746895734
0.0703563385750616,195.067406522355,0.22338137497582056,39.325589154906766,208.79163502060098,0.0679916197383951
0.0708381292961283,194.922115954304,0.22491106051520734,39.296298576387684,208.73003400694986,0.06844164026331878
0.071322333778172,194.781403493721,0.22644840974569608,39.267930944334154,208.673667767481,0.06889371143038284
0.0718280911888272,194.643901393333,0.22805418952452636,39.240210520895936,208.62480129196243,0.06936568709214856
0.0723215162160453,194.504540747134,0.2296208139859438,39.21211541462222,208.5714040448723,0.069825939524371
0.0728312561715459,194.335072869752,0.2312392383446582,39.177950690542005,208.48874034504493,0.0703011876947168
0.0733289453651723,194.153056554462,0.23281940153442204,39.14125620137954,208.39009543102534,0.07076498271075644
0.0738423415448122,193.961409018141,0.23444943440477872,39.10262005805723,208.2839736293716,0.07124318972903536
0.0743468555612322,193.783172480486,0.23605126640691224,39.06668757206598,208.19034201509,0.07171290070828751
0.0748610043485444,193.6084239504,0.23768368880662843,39.03145826840064,208.10214501766575,0.07219135493945911
0.0753668056730613,193.453103480161,0.2392896080119696,39.000145661600456,208.03304593700088,0.07266181795876213
0.075878566289979,193.294971362093,0.2409144479706833,38.968266226597954,207.96191666011117,0.07313759876298034
0.0763738640232846,193.123727739989,0.24248701827392857,38.93374351238178,207.87333306207273,0.07359785866100449
0.0768687390102696,192.88505848591,0.24405824635760595,38.88562779075946,207.711889705644,0.07405751424742203
0.0773689291772381,192.60908152059,0.24564635013773095,38.82999083455095,207.5110399076494,0.07452189214160128
0.0778694272965995,192.362191504133,0.2472354316667034,38.780217807233214,207.3413251900786,0.07498634019381308
0.0783788321028629,192.177362604705,0.24885279192658968,38.74295630110853,207.23999984227018,0.07545883199852053
0.0788770054392278,192.136052866845,0.2504344922695483,38.734628257955954,207.2911693538949,0.07592069038040639
0.0793785465740963,192.019680711706,0.25202688537275575,38.71116763147993,207.26192388022326,0.07638545567979711
0.0798845047158791,191.836100710494,0.25363330247291616,38.67415790323559,207.16083260237733,0.07685409533974083
0.0803938175323741,191.644914088791,0.2552503706652877,38.63561468030027,207.0519803430528,0.07732562053229243
0.0808998276191434,191.41021713346,0.2568569526907803,38.58829977410554,206.89527070409974,0.07779386796100247
0.0814041663082775,191.252543604838,0.25845822802878105,38.55651279073534,206.8212974713273,0.0782603506569563
0.0819044909802931,191.021184098295,0.26004675886243056,38.50987071421627,206.66667694831872,0.07872290571515446
0.0824266516316258,190.841232957014,0.2617046189304119,38.47359256413402,206.57163678291175,0.07920542029084315
0.0829324558846463,190.639307084028,0.263310547433752,38.43288430814004,206.44949300865366,0.07967259846970892
0.0834485304062812,190.509056992006,0.2649490840399428,38.40662588958841,206.4067578270754,0.08014903777993458
0.0839521444832537,190.299985584802,0.26654805873433046,38.36447709389608,206.27607746977836,0.08061375488727
0.0844483060386323,190.07585825244,0.26812337167265754,38.319293023691905,206.12744250069775,0.08107138397872153
0.0849620698824261,189.852821628578,0.2697545718767029,38.274328840321324,205.983110327161,0.08154502774764688
0.0854748355682302,189.69189704145,0.27138260292913086,38.241886443556325,205.9057807496936,0.08201752772592895
0.0860060045462939,189.526190059432,0.2730690644344831,38.20847991598149,205.82658042332525,0.08250675054461125
0.0865069588689329,189.37399976997,0.27465959440886195,38.17779835362595,205.7561685789161,0.08296792554329135
0.0870217627924339,189.151281819503,0.2762940968659776,38.132898414811805,205.6115597978846,0.08344162890685594
0.0875159376750715,188.928442226652,0.277863102118352,38.087973952893044,205.46269200160805,0.08389613920671293
0.0880229740685058,188.688317617816,0.2794729426675059,38.03956483175171,205.29722450651903,0.08436226408260251
0.0885380184305097,188.42941532625,0.28110820851686824,37.987370129771996,205.1125823732557,0.08483552844173799
0.0890568687758462,188.175251344938,0.2827555583633117,37.9361306711395,204.93355001082602,0.08531206368546337
0.0895711503724368,187.950341943339,0.28438840243248686,37.890788935777145,204.78527028409673,0.08578417879793139
0.0900990957284579,187.695367397731,0.2860646289378538,37.83938606738257,204.60655027268726,0.0862686056210162
0.0906115455502079,187.4530674111,0.28769165712191,37.79053839007776,204.43847956734706,0.0867385898742981
0.0911201929535966,187.126310298275,0.28930661262766916,37.72466415613224,204.1772957993484,0.08720486847640811
0.0916137672682905,186.796908216558,0.2908737110768223,37.658256696458096,203.91007669234594,0.08765712178084324
0.0921073438192833,186.487393564391,0.29244081662622445,37.595858542581226,203.66425204138835,0.08810917269237395
0.0925802431786549,186.187409198947,0.2939422720922293,37.53538169450771,203.42468481938923,0.08854209442413281
0.0930717534045915,185.798043539355,0.29550281705957804,37.456885577533974,203.09059323070542,0.08899185516828642
0.0935690902507855,185.364008268472,0.29708186154624394,37.369384066923956,202.708349887392,0.0894467418097876
0.0940692200309155,184.917374264184,0.2986697735981567,37.2793426516595,202.31240743138065,0.08990397442131438
0.0945628547396592,184.505943487679,0.3002370637984179,37.19639820711608,201.95335222030818,0.09035506414334186
0.0950553189126058,184.077456295481,0.3018006375475234,37.11001518916897,201.5749976082692,0.09080488154728553
0.0955444848283446,183.695811611145,0.3033537393299941,37.033075620806834,201.2469332966565,0.09125148610101012
0.0960293168996451,183.224541395978,0.30489308115637315,36.93806754542917,200.81946894548452,0.09169393716410233
0.0965229476997219,182.725927751971,0.30646035894661705,36.83754703479735,200.36317291975763,0.09214421679153668
0.0970293125084396,182.099194653685,0.3080680672142957,36.711197642182896,199.76815431927258,0.09260590154543825
0.0975306523112844,181.359626330071,0.30965982108832796,36.562100668142314,199.0477489889736,0.09306279479019158
0.0980570559924806,180.527876331421,0.3113311527761259,36.394419868414474,198.2299084090548,0.09354230530055904
0.0985990042765733,179.778856324379,0.3130518385781202,36.24341743499481,197.5048725479439,0.09403573556931212
0.0991314611247671,178.81023849791,0.31474238907113555,36.048144081178656,196.5359587042759,0.09452028712556008
0.0996661479581281,177.795830967096,0.3164400197670567,35.843639522966555,195.5160565626009,0.09500663188206823
0.100204577255951,176.646822120513,0.3181495327876444,35.611999339495426,194.3476422547062,0.09549614183590621
0.100755675354689,175.223247079367,0.31989926925113754,35.325006611200386,192.87798367669018,0.09599692153840321
0.101320492635859,173.915054715667,0.32169256411885233,35.061275030678466,191.53621373625077,0.09650990769371108
0.101859258176111,172.388427056082,0.3234031447091524,34.75350689450613,189.94778435416117,0.09699898767076952
0.102398057718644,170.867080813854,0.3251138332566947,34.446803492072966,188.36353801724724,0.09748785940945323
0.102957194403312,169.449767866436,0.3268890922305156,34.1610732018735,186.89584055825674,0.0979949311804167
0.103525029700913,167.913747651453,0.32869196930039873,33.85141152653293,185.2970233642613,0.09850962856064778
0.104159206790576,166.165164619766,0.3307054815600788,33.498897187344824,183.47279636278628,0.09908414650721284
0.104796604296501,163.823674825667,0.33272921864139066,33.026852844854474,180.99183965077108,0.09966124951707496
0.105490881458032,161.062743866126,0.33493354862925157,32.470249163411005,178.05339468661288,0.10028947293944837
0.106212844524939,157.88088110307,0.3372257813666813,31.828785630378917,174.6498585811308,0.1009423299058391
0.106576473652991,156.282316615937,0.3383803038482464,31.5065150297729,172.9383348151838,0.10127099122785291
0.10676421764996,155.450424820032,0.338976391038623,31.33880564371845,172.04696780929663,0.10144063885431805