File: example/data/02 processed data/test_ID_143.csv
Strain,Stress_MPa,Displacement(mm),Force(kN),True Stress (MPa),True Strain
-4.42455834401057e-06,-0.631055736098465,-1.4047972742233559e-05,-0.12722083639745055,-0.6310529439555422,-4.424568132427684e-06
1.69988306004911e-05,-0.744001811273127,5.3971287156559235e-05,-0.1499907651526624,-0.7440144584338833,1.6998686121984002e-05
4.14639256777286e-05,-0.749707682417763,0.0001316479640267883,-0.15114106877542102,-0.7497387682413869,4.1463066073026864e-05
8.2711534838597e-05,0.0556364202480868,0.00026260912311254546,0.0112163023220143,0.05564102202179844,8.270811442812585e-05
8.0571253925691e-05,1.83480859860552,0.0002558137312140689,0.36989741347887284,1.8349564314350235,8.056800823665729e-05
8.37614743942071e-05,4.80037771931414,0.0002659426812016075,0.9677561482137307,4.800779806029559,8.37579665978427e-05
9.13128285943833e-05,8.04886173897199,0.00028991823078716695,1.6226505265767532,8.04959670330434,9.13086598318648e-05
9.64076591941018e-05,11.3550398786956,0.00030609431794127316,2.289176039545033,11.35613459151036,9.640301227434099e-05
0.0001303963137421,14.3763828387003,0.0004140082961311675,2.8982787802819803,14.37825746602741,0.0001303878128816699
0.0001890041396061,17.4547072663838,0.0006000881432493675,3.518868984902974,17.458006278312762,0.00018898628057406586
0.0002218968842391,20.7116457027526,0.0007045226074591425,4.175467773674924,20.716241552401506,0.00022187226876683848
0.0002660615787232,23.9179590013578,0.00084474551244616,4.821860534673733,23.924322651289536,0.00026602619061807703
0.0002663050736888,27.1377277580661,0.00084551860896194,5.470965916026126,27.144954672656457,0.00026626962078677097
0.0003262369174416,30.2680212465511,0.0010358022128770798,6.102033083304702,30.277895792499628,0.000326183713749365
0.0003657126718175,33.3637843246383,0.0011611377330205625,6.726138919847082,33.37598588334561,0.0003656458152380468
0.0004252487386146,36.6009393107291,0.001350164745101355,7.378749365042987,36.616503814003096,0.0004251583459949692
0.0004878921451283,39.677883454939,0.0015490575607823526,7.999061304515703,39.697241982611985,0.00048777316445395587
0.0005541324647823,42.8816943563274,0.0017593705756838026,8.644949582235604,42.90545649531511,0.0005539789900821934
0.0006315618106439,45.9615957298837,0.0020052087487943825,9.265857699144554,45.99062331850294,0.000631362459414167
0.0007088794207981,49.0223117998054,0.0022506921610339673,9.88289805884077,49.057062707800235,0.000708628284458079
0.0007717290415703,52.0326708388964,0.0024502397069857025,10.489786441121515,52.07282596209325,0.0007714314118299992
0.0008374560395326,54.8521245833149,0.002658922925516005,11.058188315996283,54.89806082632838,0.000837105568879011
0.0009187386395567,57.6985023567922,0.0029169951805925226,11.632018075129306,57.75151220035193,0.0009183168575312243
0.0010023166220753,60.4860762647829,0.0031823552750890774,12.193992974980233,60.54670246442721,0.0010018146381731538
0.0010815212042135,63.3062258260835,0.0034338298233778626,12.762535126538433,63.37469285167313,0.0010809367814949582
0.0011601102266015,66.0192339007473,0.0036833499694597623,13.309477554390655,66.09582348914795,0.0011594378187271088
0.0012569468953409,68.6709691102161,0.0039908063927073575,13.844067372619568,68.75728487163924,0.0012561575989253155
0.0013692420463824,71.2302510512351,0.00434734349726412,14.360018611928997,71.32778250594883,0.0013683054893097262
0.0014871223039713,73.7099168265806,0.004721613315108877,14.85991923223865,73.81953248791729,0.0014860176326498846
0.0016182630142445,76.1346480003872,0.005137985070226288,15.34874503687806,76.25785388534875,0.0016169550375629287
0.0017250642329488,78.5323736266485,0.00547707893961244,15.83212652313234,78.66784701552041,0.0017235780186094652
0.0018526202201599,80.7778409838303,0.005882069199007682,16.28481274234019,80.9274916453778,0.0018509062359012226
0.001996738401864,82.7898790683822,0.0063396444259182,16.690439620185852,82.95518879920373,0.0019947475694151503
0.0021886076101489,84.5158746031389,0.006948829162222758,17.038400319992803,84.70084668947372,0.0021862160972665355
0.0024044645944463,86.1224586071809,0.0076341750873670025,17.36228765520767,86.32953700968854,0.00240157849487703
0.0026407517929255,87.6617231407782,0.008384386942538463,17.672603385180885,87.89321599333314,0.002637271134266671
0.0028855789268032,89.0211553859637,0.009161713092600159,17.946664925810282,89.27803295598511,0.002881423635626323
0.0031717786105623,90.1662134908819,0.010070397088535302,18.17750863976179,90.45220075822768,0.0031667591317680764
0.0034649370293943,91.010893005913,0.011001175068326902,18.34779602999206,91.32624001916743,0.0034589479655840853
0.0037969159832404,91.5068567809363,0.012055208246788268,18.44778232703676,91.85430062802394,0.0037897258921161556
0.0041234241144081,91.8989268630714,0.013091871563245717,18.526823655595194,92.27786511418681,0.004114946098839699
0.004477786237513,92.1334616570515,0.014216971304103774,18.574105870061583,92.54601560367387,0.004467790779959057
0.004823547085974,92.3299911499047,0.015314761997967448,18.61372621582079,92.77534920966384,0.0048119510571058375
0.0051696154736726,92.4796942816618,0.016413529128910503,18.64390636718302,92.9577787402208,0.005156298886306877
0.0054922340437253,92.5644091589663,0.017437843088827825,18.660984886447608,93.0727945581865,0.00547720672359315
0.0058606951352195,92.5650371324109,0.01860770705432191,18.661111485894036,93.10753259522423,0.0058435880684786145
0.0062348789012718,92.5667322307071,0.019795740511537964,18.66145321771055,93.14387459645202,0.006215522458866602
0.0066766011344863,92.5334910735402,0.021198208601994,18.654751800425707,93.15130028501979,0.006654411346615545
0.0070530565156226,92.4915970443123,0.022393454437101754,18.64630596413336,93.14394550548603,0.007028300050187666
0.0074444867665626,92.4527830767599,0.023636245483836252,18.638481068274796,93.14104659690672,0.0074169133370804614
0.0078268364790906,92.3826252891171,0.024850205821112657,18.62433725828601,93.10568899076412,0.007796365684469431
0.0082220603562745,92.3497996103278,0.026105041631171534,18.617719601442086,93.10910523661379,0.008188443359636356
0.0086092386705302,92.2869554060302,0.027334332778933386,18.60505020985569,93.08147583129728,0.008572390513965689
0.009014011135422,92.2217715527935,0.02861948535496485,18.591909145043168,93.05305962849872,0.008973627435042233
0.0094171773301708,92.1591883595978,0.029899538023292285,18.57929237329492,93.02706777898474,0.009373112146152923
0.0098151176625926,92.0521385109837,0.031162998578731504,18.557711123814315,92.95564108156228,0.009767262277923816
0.0102001663785582,91.959970777557,0.032385528251922285,18.539130108755494,92.89797777965543,0.010148495750433788
0.0105984578925938,91.8207303194292,0.03365010380898531,18.511059232396928,92.79388846338688,0.010542687941985372
0.0110033938921687,91.7053313975649,0.034935775607635625,18.487794809749087,92.71440128094419,0.010943296998247498
0.0114305645769172,91.5678022958471,0.03629204253171211,18.460068942842778,92.61447397315618,0.011365729275269009
0.011858835869597,91.4580013768474,0.037651803885970475,18.437933077572435,92.54258680413682,0.011789070888170654
0.0122820035749141,91.3917940981379,0.03899536135035227,18.4245856901846,92.51426843996903,0.012207191705888243
0.0127011925722941,91.2922293331781,0.040326286417033765,18.404513433568706,92.45174951829284,0.012621208971972699
0.0131284280970642,91.1977784743481,0.041682759208178835,18.385472140428575,92.39506195166058,0.01304299718826196
0.0135616085799145,91.0701070924808,0.043058107241228535,18.35973358984413,92.30516423819991,0.013470473005093665
0.0139888325390719,90.9413363582297,0.04441454331155328,18.33377340981911,92.21349948342439,0.013891891833267736
0.0143841413425284,90.8156432545344,0.045669648762527666,18.308433680114135,92.12194830322024,0.014281671044045614
0.0148059064857588,90.6976934042239,0.04700875309228419,18.28465499029154,92.04055497124087,0.014697369070709537
0.0152313819605516,90.5478422932422,0.04835963772475133,18.254445006317628,91.92701106491437,0.015116549036953898
0.0156991000716574,90.4147623839114,0.04984464272751224,18.227616096596538,91.83419278653153,0.015577143945063652
0.0161277776751139,90.2760801260893,0.05120569411848663,18.199657753419604,91.73203267574362,0.015999106676743365
0.0165689002483954,90.1383251277565,0.05260625828865539,18.171886345755713,91.63181804535573,0.01643313363708349
0.0169924239552001,90.0286277440722,0.05395094605776031,18.149771353204954,91.55843235480437,0.016849667633759696
0.017445698337857,89.8821279317657,0.05539009222269597,18.120236991043964,91.45018442162795,0.01729526918358336
0.0178805532773527,89.7212662031357,0.05677075665559482,18.087807266552158,91.3255320835924,0.01772257654599499
0.0183137929485752,89.5459057013307,0.058146292611726255,18.05245458938827,91.18583087773752,0.018148115177475093
0.0187288995303919,89.4087497461167,0.059464256008994285,18.024803948817127,91.08327723724966,0.018555673241029733
0.0191649978114871,89.2619062038562,0.060848868051471536,17.99520029069741,90.97261044090227,0.018983662439408546
0.019630539301503,89.1547237376558,0.06232696228227202,17.97359230551141,90.9048790459025,0.019440345308909212
0.0200754384942103,89.0040966588102,0.06373951721911769,17.943225886416137,90.7908929270169,0.019876583869374288
0.0205357622675928,88.8737224338968,0.06520104519960714,17.916942442673598,90.69881206963534,0.020327746522033216
0.0209886195896536,88.7401048064447,0.06663886719715018,17.890005128979254,90.60263710857316,0.020771392783143754
0.0214355197818236,88.6244258803549,0.06805777530728992,17.866684257479548,90.52413651446602,0.021209010211069114
0.0218812111603685,88.4775882183655,0.06947284543416998,17.837081784822484,90.4135850091317,0.021645253284758033
0.0223363471066369,88.3359222016019,0.07091790206357215,17.808521915842945,90.30902402188175,0.022090544395724422
0.0227864931784604,88.1555514657329,0.07234711584161177,17.77215917549175,90.16430733785025,0.02253075861682252
0.0232533214598443,87.9621761685154,0.07382929563500565,17.733174715572705,90.00758892726934,0.022987082375670778
0.0237254349968115,87.8523788506119,0.07532825611487651,17.71103957628336,89.93671475434735,0.023448360778144963
0.0242003488157893,87.7278678637357,0.07683610749013102,17.685938161329116,89.85091286690358,0.02391216062015584
0.0247278384705265,87.651170652466,0.07851088714392164,17.670476003537146,89.81859464211274,0.024427053889391953
0.0251955584090222,87.5119250737921,0.07999589794864548,17.64240409487649,89.7168368934748,0.024883383084252635
0.0256584028058134,87.3306031015146,0.08146542890845754,17.605849585265343,89.57136689316788,0.025334750576431347
0.0260931183657557,87.1904350496185,0.08284565081127433,17.57759170600309,89.46550539172993,0.025758501271349016
0.0265621299216727,87.053422864753,0.08433476250131082,17.549970049534206,89.3657471930129,0.026215481628347848
0.0270475793323738,86.9321754739043,0.08587606438028682,17.525526575539107,89.28348038657057,0.026688258337140988
0.0275458541392918,86.7891730401853,0.08745808689225146,17.496697284901355,89.17985494162001,0.027173293292056314
0.0280155866008051,86.6067091861218,0.08894948745755618,17.459912571922157,89.03304694753635,0.02763032898107049
0.0285032154152386,86.4267745931489,0.09049770894338255,17.42363775797882,88.89021556702171,0.02810455642124186
0.0289893901720273,86.301835334127,0.09204131379618667,17.398450003360004,88.80367291119006,0.028577145984399362
0.029468750714689,86.1516107727515,0.09356328351913758,17.368164731786703,88.69039111428262,0.029042893178190136
0.0299647425198117,86.067409180814,0.09513805750040213,17.351189690852102,88.64639693626437,0.029524571092375725
0.0304434882585773,85.9357449581393,0.09665807522098292,17.324646183560883,88.5519288007645,0.029989280697229493
0.030936152051975,85.7697062965979,0.09822228276502061,17.29117278939414,88.4230909720427,0.03046727494258235
0.0314297809171613,85.6452292390377,0.09978955441198713,17.266078214590003,88.33704003062071,0.03094597648310094
0.0319148722261656,85.5024783046643,0.10132971931807576,17.237299626220324,88.23127897477815,0.031416175504095804
0.0324249897644505,85.364072860223,0.10294934250213032,17.209397088620957,88.13200204896754,0.031910394075427465
0.0329403253575049,85.249607837844,0.10458553301007806,17.18632094010935,88.05775765662227,0.032409420179890194
0.0334342078055943,85.1019144672607,0.10615360978276189,17.156545956599757,87.947229560213,0.032887438515450826
0.0339529269296284,84.9826969095188,0.10780054300157017,17.13251169695899,87.86810820797044,0.03338924983680805
0.0344486377322388,84.8657285782532,0.10937442479985819,17.108930881375844,87.78923731792796,0.033868567606210445
0.0349722660710753,84.7142114664406,0.11103694477566407,17.078385031634426,87.67685940984632,0.03437463029171757
0.0354844966499128,84.5771701841096,0.11266327686347313,17.050757509116497,87.57834849616675,0.03486942989199021
0.0360004097796676,84.4197294209323,0.11430130105044461,17.019017451259952,87.45887427357452,0.03536753937743275
0.0365176535617253,84.2527493234342,0.11594355005847783,16.985354263604336,87.32946203485025,0.03586668464612385
0.0370137866843072,84.1246326363879,0.11751877272267536,16.9595259394958,87.23840384368687,0.0363452239365538
0.0375232227369086,83.9887843349428,0.11913623218968479,16.93213892192447,87.14031419694506,0.03683635623308845
0.03802001382231,83.8541432972125,0.12071354388583426,16.90499528871804,87.04227898443048,0.03731506569684501
0.0385435382961576,83.6756718433158,0.12237573409030038,16.869015443612465,86.90082830546535,0.03781928766915631
0.0390179939334405,83.5025017956653,0.12388213073867357,16.834104362006123,86.76060190415566,0.03827603047861897
0.0395579647694495,83.3718203075954,0.12559653814300215,16.807758974011232,86.66983983808814,0.03879558892525148
0.0400908879653826,83.2714619339584,0.12728856929008975,16.787526725886014,86.60988878506635,0.03930810160920522
0.0406360674603145,83.1871052973542,0.12901951418649854,16.770520427946607,86.56750212004577,0.03983212952741544
0.0411851494641562,83.0795010014756,0.1307628495486959,16.748827401897483,86.5011426676289,0.04035963113236594
0.0417427095199073,82.8979865908696,0.13253310272570568,16.712234096719314,86.35837316491744,0.040894992994912574
0.0422830956048918,82.7693436575487,0.13424882854553147,16.686299681361817,86.26908772857499,0.041413591273078726
0.042794624111031,82.6142595459547,0.13587293155252342,16.655034724464468,86.14970572943498,0.04190424781941715
0.043307238356843,82.5078364552253,0.1375004817829765,16.63357982937342,86.08102299489916,0.042395704411592405
0.0438370947307911,82.3170966438402,0.13918277577026175,16.595126683398185,85.92563900737991,0.04290343775511938
0.0443642370480345,82.1075832541569,0.14085645262750954,16.552888784038032,85.75022354108556,0.04340831467519285
0.0449167942380896,81.933167667849,0.14261082170593448,16.517726601838362,85.61334290126068,0.04393725950804565
0.0454558086082249,81.7853383672785,0.14432219233111404,16.487924214843346,85.50295705506042,0.04445297080405812
0.0460237371764159,81.7618269922814,0.14612536553512046,16.48318432164393,85.52481182883774,0.04499605867053484
0.0465828737829759,81.6694253851278,0.1479006242609485,16.464556157641763,85.47382191977137,0.04553045115208205
0.0471344127485957,81.553198666964,0.14965176047679135,16.441124851259943,85.39716079390091,0.04605730258701596
0.0476992823034656,81.4252944749846,0.15144522131350327,16.415339366156896,85.30922258278972,0.046596600355516396
0.0482362053534712,81.257130756412,0.15314995199727105,16.38143756049266,85.17666640201216,0.047108947290727676
0.048796614464336,81.067354990398,0.1549292509242668,16.343178766064238,85.02316745750791,0.047643425453309976
0.0493509377828224,80.9220314146395,0.15668922746046113,16.313881533191324,84.91560955224298,0.0481718185406218
0.0499188832877741,80.7612608681974,0.15849245443868276,16.281470191028596,84.79277282365042,0.04871290717354349
0.0504790501678869,80.6704647117965,0.1602709842830409,16.263165685898176,84.74263314705003,0.04924629837953467
0.0510462857947143,80.5256936080177,0.1620719573982179,16.23397983137637,84.63623117775018,0.04978613069170883
0.0516067741322911,80.4159083545463,0.16385150787002425,16.211847124276535,84.56591397364241,0.050319255591421634
0.0521791354068152,80.2708204758547,0.16566875491663827,16.18259740793231,84.4592824866805,0.05086338062434494
0.052755576152597,80.1442679257186,0.1674989542844955,16.15708441382487,84.37232495546799,0.051411084794955327
0.0533319321255956,79.9796807034892,0.169328884498766,16.12390362982342,84.24515160619448,0.05195840866931577
0.0539079624662239,79.8253062509659,0.17115778083026087,16.092781740194727,84.1285258641978,0.05250512416806328
0.0545074652849714,79.7047038969841,0.1730612022797842,16.068468305631995,84.04920527769788,0.05307380036632368
0.0551266490630111,79.584620997336,0.17502711077506025,16.04425959306294,83.97185446986889,0.05366080622824854
0.0557046277992048,79.4704160895835,0.17686219326247524,16.021235883660033,83.89728603890168,0.054208437634864354
0.0563107981843418,79.3395584364934,0.1787867842352852,15.99485498079707,83.80723229964558,0.05478245844392084
0.0568835284834013,79.176305823074,0.18060520293479912,15.96194325393172,83.68013347057132,0.05532451016709188
0.0574875676707674,79.0185420704337,0.1825230273546865,15.930138081399434,83.56112585495313,0.05589587552948977
0.0580925424559309,78.860914262975,0.1844438222975806,15.89836031541576,83.4421452729104,0.056467798850907
0.0586612602571506,78.7384993876097,0.18624950131645315,15.873681476542117,83.35739899244378,0.05700514789374349
0.0592064481120117,78.6010803092584,0.18798047275563715,15.845977790346495,83.25477109213656,0.0575199939011208
0.059745763852247,78.4495716303927,0.18969280023088422,15.815433640687168,83.13660121133206,0.05802903393405398
0.0603168502889682,78.150214353943,0.19150599966747403,15.755083213754908,82.86398913318055,0.05856777882462931
0.0608959396245114,77.9123949955268,0.19334460830782368,15.707138831098202,82.65694349717549,0.059113777182439646
0.0614751983977693,77.7468522824292,0.1951837549129175,15.673765420137727,82.5263554512936,0.059659637213480915
0.0620403938980283,77.6600427978691,0.19697825062623983,15.65626462805041,82.47810244318663,0.060191957781934445
0.0626088238349075,77.6307452209441,0.1987830156758313,15.650358236542331,82.49111487265478,0.060727039004469616
0.0632120463978455,77.4627510577846,0.20069824731315944,15.616490613249375,82.35933007175404,0.06129455867423613
0.06383716434435,77.2990841511585,0.20268299679331123,15.583495364873553,82.23363848978374,0.0618823381777331
0.064445944491194,77.1382438315775,0.2046158737595409,15.551069956446025,82.10949081169554,0.0624544238752798
0.0650614856008703,76.9847505384338,0.2065702167827632,15.520125708548255,81.9934927770767,0.0630325304534689
0.0656680942959125,76.8460849945604,0.20849619938952219,15.492170734903377,81.8924209502549,0.063601921067045
0.0662810119418191,76.6891359557562,0.21044221291527562,15.460529808680452,81.77216949184746,0.0641769044575955
0.0668749184215009,76.520171122424,0.21232786598826534,15.426466498280679,81.6374513238354,0.06473373810165678
0.0674614486649579,76.3503591957788,0.21419009951124132,15.392232413869007,81.50106503321592,0.06528335180572559
0.0680364238015136,76.1457326152451,0.21601564556980568,15.350979695233411,81.32641595013266,0.06582184463951683
0.0686253502867425,75.9428196702962,0.21788548716040745,15.310072445531715,81.1544222719332,0.06637310315622237
0.0692278635541509,75.7189963446701,0.2197984667844291,15.264949663085492,80.96086069207618,0.06693676513213359
0.069841222951087,75.5588525713072,0.2217458828697012,15.232664678375532,80.83597523966817,0.06751024769762501
0.0704606081738366,75.3773366564459,0.22371243095193122,15.196071069939494,80.68846963978311,0.06808903077488354
0.0710723654504167,75.2334121901452,0.225654760305073,15.167055897533274,80.58042875540504,0.06866035729729074
0.071684844134992,75.068768292435,0.2275993801285996,15.133863687754895,80.45006124688403,0.06923203074542185
0.0722867955616185,74.851563341052,0.22951057590813873,15.090075169556084,80.26234299775416,0.06979356004114393
0.0728505746198746,74.6804671297771,0.23130057441810184,15.055582173363064,80.12098207306202,0.0703191945101282
0.073445785322986,74.4463384847523,0.23319036840048052,15.008381838526063,79.91410827918577,0.0708738343347847
0.0740207102917324,74.2211088018925,0.23501575517625037,14.962975534461528,79.71500799404853,0.0714092792263875
0.074610244139489,73.9635004168173,0.23688752514287756,14.911041684030367,79.48193524032723,0.07195803224638327
0.0752094785193605,73.7543384455043,0.23879009429896955,14.868874630613668,79.3013637785311,0.07251550633509378
0.0758112480750723,73.577272300421,0.24070071263835452,14.833178095764875,79.15525714347537,0.07307502634712447
0.0764199849210949,73.3541875641915,0.24263345212447632,14.788204212941007,78.95991347174619,0.07364070614297782
0.0770146166967758,73.1650105374063,0.24452140801226313,14.75006612434111,78.79978577956021,0.07419296975975767
0.0776071953743755,72.9153639178045,0.24640284531364223,14.699737365829387,78.57412081116725,0.0747430233136767
0.0781789506065645,72.6837958345382,0.24821816817584227,14.653053240242903,78.36613871898417,0.07527346112789196
0.0787768276230902,72.4662212161917,0.2501164277033114,14.609190197184246,78.17488023343635,0.07582783228178601
0.0793498231748566,72.2297664605264,0.2519356885801697,14.561520918442126,77.96118565713037,0.07635884427315237
0.0799743572439247,71.9780636605568,0.2539185842494609,14.510777633968251,77.73446303747212,0.07693729756158953
0.080557157612437,71.7520779146267,0.25576897541948745,14.465218907588742,77.53222136421515,0.07747679479052662
0.0811575863551665,71.5093929889704,0.25767533667765363,14.416293626576435,77.31292272567832,0.07803230634434813
0.0817543741822973,71.2588379358635,0.2595701380287939,14.36578172787008,77.08455963626776,0.07858414373131889
0.0823736251397407,71.0015184437957,0.2615362598186767,14.313906118269216,76.85017090843732,0.07915643055958267
0.082979851643482,70.7116811894586,0.26346102896805534,14.255474927794856,76.57932600402108,0.07971636363848206
0.0835847758485287,70.4511253754886,0.26538166331907864,14.202946875698501,76.3397668982754,0.08027478152557392
0.0841710442435664,70.1632552313669,0.2672430654733233,14.144912254643568,76.06896969171892,0.08081568046252764
0.0847604666380664,69.8719644408769,0.2691144815758608,14.086188031280784,75.794344751804,0.08135919454404918
0.0853386956403804,69.5569538524486,0.2709503586582077,14.022681896653637,75.4928535669347,0.08189210016057508
0.0859360211787475,69.2449617120028,0.2728468672425233,13.959784281139767,75.19559820820703,0.08244230741791478
0.0865266597330868,68.9510236903327,0.27472214465255057,13.900526375971074,74.91712545543412,0.08298605767340264
0.0871064319954232,68.6733741866674,0.27656292158546864,13.844552236032149,74.6552667851546,0.08351951686510514
0.0877018767520715,68.3841142777046,0.278453458687827,13.786237438385246,74.38152943988742,0.08406710054788939
0.0882898165646301,68.0786897314866,0.28032016759270056,13.7246638498677,74.08934475983993,0.08460748848105296
0.0888757433265186,67.7571843456747,0.2821804850616965,13.65984836408802,73.7791544701085,0.08514573581219616
0.0894529054925099,67.432300660563,0.2840129749387189,13.594351813169501,73.46431587869486,0.08567564866975345
0.0900468143565157,67.0577079596093,0.2858986355819373,13.518833924657235,73.09604093942168,0.08622064426970431
0.0906175812486307,66.658597217718,0.28771082046440244,13.438373199091949,72.69903806701431,0.08674412409200012
0.0912052073445349,66.3042360224255,0.28957653331889827,13.366933982120981,72.35152761667179,0.0872827802222639
0.091768786397701,65.9641183023376,0.29136589681270064,13.29836624975126,72.0175653847375,0.08779912083585156
0.0923279328707662,65.6382925734893,0.29314118686468266,13.232679782815442,71.69854044396612,0.08831113706695326
0.0929104278293509,65.2286762335093,0.2949906083581891,13.150101128675477,71.28910044910687,0.08884425508543264
0.0934931737989632,64.8438026459111,0.29684082681170815,13.072510613415677,70.90625555647094,0.08937731859024726
0.0941037473355108,64.4602180228482,0.29877939779024676,12.995179953406195,70.52616609286224,0.08993553253405338
0.0947138414590523,64.222562947354,0.30071644663249103,12.947268690186569,70.3053285924437,0.09049299711444095
0.0952956751853709,63.8717931238192,0.30256376871355256,12.876553493761952,69.95849877485388,0.09102434981915382
0.0958759286160085,63.4671180044893,0.3044060733558269,12.794970989705044,69.5520868797515,0.0915539783002775
0.0964465987225081,63.0156850816423,0.3062179509439632,12.70396211245909,69.0933335739354,0.09207458611438554
0.0970430036261275,62.5606687641496,0.3081115365129548,12.61223082285256,68.63174396988194,0.09261838164245922
0.097660835621097,62.1587371787338,0.31007315309698297,12.531201415232733,68.2292113927611,0.0931814024931468
0.0982872884435348,61.7630671399492,0.312062140808223,12.451434335413758,67.83359153509079,0.09375195589790793
0.0989348941751856,61.405176186592,0.31411828900621425,12.379283519216948,67.48029079442111,0.09434143269777484
0.0995626687413882,61.0035663750792,0.3161114732539075,12.298318981215967,67.0772442461245,0.09491252687941419
0.099863920039889,60.7623394831475,0.31706794612664757,12.249687639802538,66.83030489472912,0.09518646309708223