File: example/data/02 processed data/test_ID_098.csv
Strain,Stress_MPa,Displacement(mm),Force(kN),True Stress (MPa),True Strain
9.850138957700637e-05,5.87788623789952,0.0003127419119069952,2.3699637311210866,5.878465217861728,9.849653863357222e-05
0.00017432752071130638,10.3333042443673,0.0005534898782583978,4.166388271328895,10.335105623676975,0.0001743123274348102
0.00029033396094120637,15.3810340395013,0.0009218103259883302,6.201632924726924,15.38549967603736,0.00029029182219281825
0.00035473260889090635,20.8077881076598,0.0011262760332286276,8.389700165008431,20.81516930862048,0.0003546697061542739
0.0004652178607115064,26.5194835649222,0.0014770667077590328,10.692655773376632,26.531820902333447,0.0004651096804327445
0.0005582931750014063,32.4486143399826,0.0017725808306294651,13.083281301880984,32.46673017990686,0.0005581373873475777
0.0006599901897144063,38.498398592524,0.00209546885234324,15.522554312505678,38.52380715791478,0.0006597724919694681
0.0007799555737082064,44.5524150325165,0.0024763589465235554,17.963533741110652,44.58716393694328,0.0007796515664242809
0.0008777816713963064,50.6037365221525,0.002786956806683273,20.403426565731888,50.648155554575816,0.000877396646360447
0.0009784220987765063,56.6643771108683,0.0031064901636154076,22.8470768511021,56.71981878964698,0.0009779437558635918
0.0010657850544898064,62.7920590217865,0.0033838675480051352,25.31775819758432,62.858981859832554,0.0010652175088172139
0.0011547616916048064,68.9350973441037,0.00366636837084526,27.79463124914261,69.01470095372372,0.0011540954671602315
0.0012482190296184063,75.1383210226398,0.00396309541903844,30.29577103632837,75.23211010479383,0.0012474406519019958
0.0013479010197511064,81.2570840831065,0.004279585737709763,32.76285630230854,81.36661058960412,0.0013469934166527135
0.0014402363029918065,87.3957124014862,0.004572750261998985,35.23795124027924,87.52158287921264,0.001439200157431155
0.0015438545714154064,93.5269106786542,0.004901738264243915,37.71005038563338,93.67130262725581,0.0015426640531138757
0.0016480711979257063,99.6642411046778,0.0052326260534141175,40.18462201340609,99.82849486990554,0.0016467146188769814
0.0017435459855344065,105.764801074623,0.00553575850407174,42.64436779328799,105.9492068689475,0.001742027773691162
0.0018502231169109063,111.840203823929,0.005874458396192128,45.093970181808174,112.04713315444405,0.0018485135624995953
0.0019430622156317062,117.80871872158,0.006169222534630667,47.500475388541055,118.03762839159988,0.001941176912024648
0.0020458650047172062,123.769914309488,0.00649562138997713,49.90402944958556,124.02313084581064,0.0020437750729019625
0.0021475233318829063,129.68649690721,0.006818386578728227,52.28959555298707,129.9650016851484,0.0021452206997006136
0.0022446879390037064,135.533500517905,0.007126884206336767,54.647107408819295,135.83773093184848,0.0022421723907424963
0.002340908209921606,141.33147118399,0.007432383566501099,56.984849181384774,141.6623151852049,0.0023381725527476245
0.0024553850248195063,147.057775974646,0.007795847453801932,59.29369527297727,147.4188594355574,0.0024523754923766366
0.0025564375486235064,152.698803060447,0.008116689216879632,61.568157393972236,153.0891680142206,0.002553175420588494
0.002639834131167206,158.271450047467,0.00838147336645588,63.8150486591387,158.68926042329164,0.002636355889024106
0.0027249171079747063,163.756192158888,0.008651611817819692,66.02649667846364,164.20241420843854,0.0027212112519258373
0.0028025547596586065,169.196286162659,0.008898111361916075,68.2199425807841,169.6704680197607,0.002798634925061052
0.0028910474427422065,174.554908151143,0.009179075630706504,70.38053896654085,175.05955467197145,0.00288687640226752
0.0029836755818146063,179.803601138221,0.009473169972261374,72.49681197893071,180.34007675245945,0.002979233255938508
0.0030995919384470064,184.962353082935,0.009841204404569245,74.5768207630394,185.53566090146708,0.0030947981067482476
0.0031968647819930066,190.029515402891,0.010150045682827796,76.61990061044565,190.63701406822173,0.003191765674324195
0.0032858171800547063,195.020787510515,0.010432469546673692,78.63238152423965,195.66159016458485,0.0032804306789310693
0.0033881638347499064,199.936012717948,0.010757420175330951,80.61420032787663,200.61342868550304,0.003382436939790848
0.0034563026596203064,204.713986890995,0.010973760944294472,82.54067951444918,205.42154038834784,0.0034503433730339347
0.0035580630827407064,209.309725156188,0.011296850287701742,84.393681182975,210.05446236212484,0.003551748151140681
0.0036607657708075062,213.822464410247,0.011622931322313831,86.21321765021159,214.6052183689897,0.0036540814759181846
0.0037327751878968064,218.150542761503,0.01185156122157236,87.95829884143801,218.96484969474938,0.0037258256712152356
0.003825635028673006,222.290201655973,0.012146391216036794,89.62740930768831,223.14060283795885,0.0038183358969399502
0.003948719165119206,226.286927691328,0.012537183349253479,91.23888924514345,227.18047121951872,0.003940943436321499
0.004122548750591407,230.003235156773,0.013089092283127716,92.73730441521087,230.95143470650052,0.004114074329316849
0.004325955587975206,233.363198690204,0.013734908991821278,94.09204171189025,234.37271752360564,0.004316625540004874
0.004559552520652706,236.033132828931,0.014476579253072342,95.16855915662498,237.10933829467874,0.004549189250368289
0.004848252327969106,237.944270584394,0.01539320114130191,95.93912989962766,239.0978844481817,0.004836537402004042
0.005165596446676706,239.087315278414,0.01640076871819854,96.40000552025653,240.32234386466166,0.005152300521285913
0.005513993263438906,239.745431734418,0.017506928611418525,96.66535807531733,241.06738642994182,0.005498846855203858
0.005872410246115806,240.102821662868,0.018644902531417686,96.80945769446839,241.51280393292234,0.005855234852900519
0.006218487954368806,240.316946327802,0.01974369925512096,96.89579275936977,241.8113543637721,0.006199232941630174
0.006595441369544106,240.496696697811,0.020940526348302534,96.96826810855738,242.08287856045044,0.006573786609101003
0.006965466985514906,240.663258667133,0.022115357679009826,97.03542589458803,242.3395906500053,0.006941320184669103
0.007367007612158806,240.826667640651,0.02339024916860421,97.10131239271048,242.60083953437052,0.007340003755555668
0.007742951599319606,240.957338253534,0.02458387132783975,97.15399878382492,242.82305926113202,0.007713128795014711
0.008111876984898906,241.076483828471,0.025755209427054025,97.20203827963951,243.03206660923954,0.00807915256266583
0.008487332358937005,241.20470705781,0.02694728023962499,97.253737885709,243.25189157314966,0.008451517459603843
0.008861916800477206,241.370333729859,0.028136585841515127,97.32051855987915,243.5093375454764,0.008822880470744483
0.009234983940433105,241.464673727244,0.029321074010875105,97.35855644682479,243.69459611129702,0.009192602206176221
0.009612158842436706,241.609870532036,0.03051860432473654,97.41709979851692,243.93226298549052,0.00956625595974574
0.009988494524207706,241.736863325564,0.03171347011435946,97.4683032928674,244.15145066119055,0.009938939228093364
0.010360274171666005,241.851794320242,0.032893870495039564,97.51464346992158,244.35744521830907,0.010306974348974707
0.010727929351668506,242.015587986677,0.034061175691547506,97.58068507622816,244.61191411660056,0.01067079338806159
0.011094612351048905,242.201971163625,0.03522539421458027,97.6558347731736,244.88910814434533,0.01103351859844729
0.011461378829574907,242.403786818272,0.03638987778390033,97.73720684512728,245.18206844871978,0.011396194820164315
0.011832709030898206,242.577169846108,0.037568851173101804,97.80711488195075,245.4475149144358,0.011763249918798097
0.012210330960527207,242.722585674677,0.03876780079967388,97.86574654402978,245.68630877735973,0.012136386187690836
0.012588119436473807,242.842410548008,0.039967279210804334,97.91405993295683,245.89933981622752,0.01250954775372862
0.012951358856893606,242.955719581076,0.0411205643706372,97.95974613508984,246.10232629170537,0.01286820719059104
0.013301518987919606,243.070149287689,0.042232322786644745,98.0058841927962,246.30335149383563,0.013213830521558494
0.013667553158733105,243.24258466091,0.04339448127897761,98.07541013527893,246.56711561723066,0.013574994566755028
0.014040086730488606,243.425236647712,0.04457727536930132,98.14905541635748,246.84294808263562,0.013942437652354181
0.014399331576942306,243.60618682671,0.04571787775679182,98.22201452852947,247.1139530850224,0.014296645766205117
0.014761384687781307,243.792880504067,0.04686739638370564,98.29728941923983,247.39160099732982,0.014653495878449874
0.015113059362841005,243.940016199927,0.04798396347702019,98.35661453181056,247.62669614572889,0.014999994825327191
0.015468442903936307,244.105476863615,0.04911230621999777,98.42332827140957,247.88140849501795,0.015350026128505135
0.015829886468752205,244.308621828957,0.05025988953828825,98.50523632143546,248.17599957584673,0.01570590055955663
0.016178897698628406,244.410581362939,0.051368000193145184,98.54634640553701,248.36487515527227,0.016049414067989685
0.016532224050861907,244.496906243427,0.05248981136148655,98.58115259734976,248.5389838771859,0.016397054568414372
0.016881376348165205,244.592870948498,0.05359836990542452,98.61984556643439,248.7219352550578,0.016740469504427643
0.017231050755592607,244.77116433144,0.054708586149006526,98.69173345843662,248.98882868754055,0.017084279813250863
0.017577713210188407,244.915269441864,0.05580923944234819,98.74983663895956,249.22031980890912,0.01742501203741731
0.017924655315133205,245.065452070388,0.05691078062554793,98.81039027478045,249.45816582839697,0.017765902928697164
0.018269542252846705,245.223947490429,0.05800579665278829,98.87429562814097,249.70407676051525,0.01810465936108824
0.018621288216033306,245.419225513895,0.059122590085905743,98.95303172720246,249.9892476459449,0.018450034735577065
0.018977680791224007,245.614092094435,0.060254136512136215,99.03160193247619,250.2752779320295,0.018799850949901924
0.019331536677682604,245.759929429491,0.06137762895164227,99.09040354597077,250.51084651916187,0.019147056258086367
0.019684923211015806,245.877538575003,0.06249963119497518,99.13782355344121,250.71761904116553,0.01949368076438478
0.020039650505756307,246.000570590292,0.06362589035577627,99.18743006200573,250.93033604913808,0.019841499585501594
0.020395171415238306,246.124701827427,0.06475466924338162,99.23747977681856,251.1444573107218,0.020189975223400304
0.020741504174281507,246.250579068034,0.06585427575334378,99.2882334802313,251.35818648169288,0.020529328061952175
0.021066842980636907,246.385574152669,0.06688722646352217,99.34266349835615,251.57614035603734,0.020848005189080168
0.021405719071062607,246.552256610106,0.06796315805062378,99.40986986519475,251.8298849514385,0.021179834462903845
0.021757868466756706,246.702624905663,0.06908123238195253,99.47049836196331,252.07034816876404,0.02152454440324254
0.022114506703536405,246.836490658537,0.07021355878372808,99.52447303352211,252.29515788588262,0.021873527289582993
0.022457204302911905,246.948821410168,0.07130162366174529,99.56976479257973,252.49460154493943,0.022208754076435116
0.022796129952646207,247.049238602585,0.0723777125996517,99.61025300456228,252.68100515047183,0.022540180650503144
0.023136089480905404,247.093554095839,0.07345708410187465,99.62812101144229,252.81033267355528,0.02287250791741728
0.023466878690331705,247.220787380996,0.07450733984180316,99.67942147201758,253.0222876081941,0.023195764765424554
0.023805386288383804,247.36464560305,0.07558210146561857,99.73742510714976,253.25325654571978,0.023526456102309894
0.024140709373972304,247.500083371261,0.07664675226236206,99.79203361529244,253.47491095396055,0.023853928675240728
0.024474348290190306,247.616685869989,0.07770605582135422,99.83904774277957,253.67694288243376,0.02417965011121246
0.024818171806194705,247.729832755356,0.07879769548466818,99.88466856695953,253.8780343061983,0.024515203494498303
0.025150087058399606,247.87901901065,0.07985152641041875,99.9448204650941,254.11319791871856,0.02483902826951144
0.025491084667440805,248.008777070229,0.08093419381912455,99.99713891471634,254.33078980479465,0.025171604847886914
0.025818861112779506,248.137549983181,0.08197488403307493,100.04906015321858,254.5441789230621,0.025491182539013092
0.026154322943330605,248.234467964246,0.08303997534507467,100.08813748318398,254.7268724050487,0.025818147663261536
0.026496342036829306,248.362724534175,0.08412588596693304,100.13985053217935,254.94342823263133,0.026151393940866536
0.026834410961266607,248.525976206008,0.08519925480202148,100.20567360626242,255.19502438607,0.026480682271057234
0.027180095623556805,248.648783269227,0.08629680360479285,100.25518941415234,255.40708097516566,0.026817276452301565
0.027529842202335106,248.740184965477,0.08740724899241395,100.29204257808033,255.58796300695624,0.027157710472420424
0.027873551607573807,248.841282877784,0.08849852635404683,100.33280525632252,255.7773732181728,0.027492155194539333
0.028213152242805805,248.882656693845,0.08957675837090842,100.34948717895831,255.9044209777424,0.027822492079344896
0.028531512136321206,248.975849413056,0.09058755103281982,100.38706248334418,256.0795068822355,0.02813206856841691
0.028871904073458906,249.078845687583,0.09166829543323202,100.42859058123346,256.27022622700275,0.028462963265647026
0.029210345965412905,249.164588496917,0.09274284844018596,100.46316208195692,256.4427723292417,0.028791853809257164
0.029575244119883305,249.303666124023,0.09390140008062949,100.51923818120608,256.67688290962286,0.029146332838106612
0.029900722785585306,249.379152113995,0.09493479484423334,100.54967413236278,256.83576900985986,0.0294624119510867
0.030237550848309706,249.411170001253,0.09600422394338332,100.56258374450522,256.9527529363023,0.029789407541660998
0.030587259847415105,249.503576551262,0.09711455001554295,100.59984206546883,257.13520728009485,0.030128794956493246
0.030931840501776504,249.545080628238,0.0982085935931404,100.61657650930556,257.2639692602336,0.030463092763883988
0.03127388249387951,249.670946157638,0.09929457691806744,100.66732549075965,257.4791259899077,0.03079481718053691
0.03160469959539721,249.740337975368,0.10034492121538614,100.69530427166838,257.63330633393247,0.031115550651935504
0.03193883998831601,249.79960995446,0.10140581696290332,100.71920273363828,257.7779197259393,0.03143940172600267
0.03227704465215331,249.89810843139,0.10247961677058674,100.75891731953645,257.9640808357186,0.03176708515231477
0.03260731373385951,250.017773095426,0.10352822110500393,100.80716611207578,258.1701810617895,0.03208697627181644
0.03294892332884321,250.183512065822,0.10461283156907718,100.87399206493943,258.42678942301944,0.03241774392845876
0.03328824568555451,250.268841849198,0.10569018005163557,100.90839703359663,258.5998525441133,0.032746188663506925
0.03362631099932161,250.370579984855,0.10676353742284611,100.94941784989355,258.7896189725063,0.033073309410407925
0.03397238040603881,250.421981355252,0.10786230778917322,100.97014288243761,258.9294121678866,0.03340806432332938
0.034304970966626706,250.540128489326,0.10891828281903979,101.01777980689626,259.1349003231273,0.0337296755068914
0.03464574941514131,250.6051309633,0.11000025439307365,101.04398880440256,259.2875335328032,0.03405909703272977
0.03499595710521361,250.680754580131,0.1111121638090532,101.07448024670883,259.4535675145199,0.03439752053116571
0.035346300228654606,250.758039282076,0.11222450322597836,101.10564143853304,259.62140822328905,0.03473596034762031
0.03569495616753401,250.832282026601,0.11333148583192047,101.13557611312554,259.78572933894304,0.03507265662645706
0.036038833203869906,250.904180850027,0.11442329542228695,101.16456571873088,259.9464747738347,0.03540462692231093
0.03638525112112091,250.952954096631,0.11552317230955889,101.18423109176162,260.08394035102407,0.035738938729529914
0.03672018134254911,250.964518419614,0.11658657576259342,101.18889382678837,260.1799810465277,0.036062058064511536
0.037060503966092506,250.956210603341,0.1176671000923437,101.18554411526709,260.25677424172164,0.03639027273929321
0.03740436584817561,251.056690600127,0.11875886156795755,101.22605764997121,260.44730690396636,0.03672179137837543
0.03773624559198611,251.088867404409,0.11981257975455588,101.23903133745772,260.5640185701954,0.03704165379618993
0.038077522998968306,251.190855626807,0.12089613552172436,101.28015298872859,260.75558120906726,0.03737046692501768
0.03841793124856011,251.276071334961,0.12197693171417835,101.31451196225628,260.92957816791585,0.0376983349701367
0.03875527615166931,251.341815281716,0.12304800178155004,101.3410199215879,261.0826367414208,0.0380231465023414
0.03909297560560981,251.435966526771,0.12412019754781113,101.37898170359408,261.26534663257496,0.038348193778174056
0.03943111697972821,251.463513204908,0.12519379641063705,101.3900885242189,261.37900041022414,0.038673560588506135
0.03977884901623931,251.505148479694,0.1262978456265598,101.40687586701263,261.5097338078746,0.03900804536439719
0.04012776250990711,251.565134373888,0.12740564596895507,101.43106217955165,261.65988034181623,0.03934355417523229
0.04047591666463791,251.647274477116,0.12851103541022535,101.46418106917318,261.83292858773507,0.03967822065829706
0.04081741567814331,251.659858563434,0.129595294778105,101.4692549727766,261.93196361992045,0.04000638104901486
0.04115833110976551,251.627589474851,0.13067770127350548,101.45624407625992,261.984161118809,0.04033387327383544
0.04148690715110221,251.645980623107,0.1317209302047495,101.46365938723675,262.0859940561659,0.04064941049354676
0.04182428534152821,251.518130698547,0.13279210595935206,101.41211029765415,262.03769676545085,0.04097329700132457
0.04216226152883921,251.726561536788,0.13386518035406447,101.49614961163292,262.3399226580575,0.04129765244477183
0.04251582031862201,251.831866970324,0.13498772951162485,101.53860876243463,262.5387053769374,0.04163684994125942
0.04286239646428531,252.049118640263,0.13608810877410585,101.62620463575404,262.85254789189565,0.04196923679182205
0.04320904751930641,252.141908590917,0.13718872587379785,101.66361754385775,263.03672030083055,0.042301585004738275
0.04355576185802391,252.125324166715,0.1382895438992259,101.65693070401949,263.1068347444975,0.04263388344139014
0.04390268223463271,252.086573676892,0.13939101609495883,101.64130650652285,263.15385041664587,0.042966268865190456
0.04423859924241541,252.084905387367,0.1404575525946689,101.64063385218638,263.236788491861,0.043288006684044256
0.04458581045464191,252.09118779503,0.14155994819348805,101.64316691895611,263.3308777113448,0.043620453215990576
0.04492236274089041,252.154030771127,0.14262850170232705,101.6685052069184,263.4813856080052,0.043942588628980206
0.04527038753718781,252.219321776904,0.1437334804305713,101.6948305404477,263.63738821811114,0.04427559600302964
0.04562642054227591,252.267778433272,0.14486388522172602,101.71436826429529,263.77785418133413,0.044616151316092686
0.04596624077507431,252.330688688227,0.1459428144608609,101.73973367909313,263.92938187941036,0.044941090528276016
0.04631051499580201,252.334379365679,0.14703588511167137,101.74122176024177,264.0201144252497,0.04527018104929368
0.04665578577064111,252.346220202344,0.14813211982178554,101.74599598558511,264.1196313921356,0.04560011543748205
0.047015324175550606,252.352648895082,0.14927365425737316,101.74858803449706,264.2170904894432,0.04594356805211266
0.04735592294471521,252.391856170389,0.15035505534947077,101.76439640790085,264.34410546306754,0.04626881962595413
0.047707675058697406,252.473532622944,0.15147186831136425,101.79732835357102,264.51845787824084,0.0466046109762717
0.04805057852112281,252.504222976381,0.1525605868045649,101.80970270407681,264.63719696942263,0.04693184668191627
0.04840995389238601,252.62242168822,0.15370160360832558,101.85736042469031,264.85186147432967,0.04727468678715759
0.04876655088130791,252.598530456997,0.1548337990481526,101.84772748026118,264.91688954507174,0.04761476020639234
0.04911956287183701,252.634035182114,0.1559546121180825,101.86204298542836,265.04330855680774,0.04795130087134707
0.04944916869943561,252.619163582325,0.15700111062070804,101.85604675639344,265.1109712190177,0.04826542527942597
0.049794438847274906,252.647764931266,0.1580973433400978,101.86757882028645,265.2282186120366,0.04859437247708458
0.05014173404813711,252.707350302224,0.15920000560283531,101.8916036418567,265.37853505308755,0.04892513986755228
0.05049538135516241,252.673564491348,0.16032283580264065,101.87798120291153,265.43241248870686,0.04926184467751042
0.050830255573939206,252.639301557874,0.16138606144725698,101.8641663881348,265.48102182408223,0.04958057130961971
0.051177798061775207,252.626934879995,0.16248950884613628,101.85918014361398,265.55582513824857,0.04991124795988433
0.051526246634824406,252.628940096871,0.1635958330655675,101.85998864705839,265.6459611713966,0.050242676985398055
0.05188733521110571,252.689344460714,0.1647422892952606,101.8843436865599,265.80072118102163,0.05058601277341904
0.05224216345928831,252.777920331864,0.16586886898324038,101.92005747780757,265.9835857647402,0.05092328122744731
0.05259435453894601,252.823874957779,0.16698707566115356,101.9385863829765,266.1209834732186,0.05125793057425697
0.05293332059835381,252.909359829825,0.16806329289977334,101.97305388338543,266.2966920560215,0.05157990787841567
0.05327942442287271,252.916676248111,0.16916217254262084,101.97600386323836,266.3919311855564,0.05190855827562965
0.05363510137002931,252.906371840871,0.17029144684984304,101.97184912623919,266.47103073168245,0.052246186543109106
0.05398490980145361,252.90644747103,0.1714020886196152,101.97187962031929,266.55957922595957,0.05257813294026047
0.05434373671202791,252.899488640277,0.17254136406068862,101.96907381975969,266.6429918655507,0.05291852286441422
0.05470195364340951,252.924565788575,0.1736787028178252,101.97918492595343,266.7600336616211,0.053258218620143336
0.05505870065285401,252.882636021386,0.17481137457281146,101.96227884382283,266.8060253783921,0.05359640580940406
0.05541559991160641,252.880246612349,0.17594452971935035,101.96131543409912,266.89375718416727,0.05393462292207782
0.05577110923779451,252.90743087309,0.17707327182999757,101.97227612802988,267.0123588273631,0.05427140917410169
0.05613036671162801,252.924925766809,0.1782139143094189,101.9793300691774,267.12169460061125,0.05461163098974034
0.05648318412212821,252.929215621853,0.17933410958775706,101.98105973873113,267.2154630776876,0.05494564135679604
0.05683338817936951,252.894454097929,0.18044600746949818,101.96704389228499,267.26730277608635,0.05527706738641868
0.05718264481898511,252.912648820996,0.1815548973002777,101.97438000462559,267.37486298875575,0.0556074874374889
0.05752976169640581,252.893723383305,0.18265699338608843,101.96674926814858,267.44263902406334,0.055935774990414536
0.05789162453930761,252.930412248624,0.18380590791230164,101.98154221864522,267.57296470909364,0.05627789391649297
0.05824712365472661,252.940957292874,0.18493461760375698,101.9857939804868,267.67404050965695,0.05661388239462731
0.05860611426618001,252.907538680796,0.18607441279512152,101.97231959609695,267.72946679150107,0.056953056229132215
0.05897057177015431,252.944124229051,0.1872315653702399,101.98707088915337,267.8603838607391,0.05729727753641827
0.05932508234935871,252.974673127276,0.1883571364592139,101.9993882049177,267.9824164428538,0.05763199057029033
0.05968749180149951,252.998046400138,0.18950778646976094,102.00881230853565,268.09886522044167,0.05797404560110543
0.060049298979088006,252.981235279299,0.1906565242586044,102.00203406461337,268.1725811126846,0.05831541551332807
0.06040460589277231,252.930236192857,0.19178462370955207,101.98147123295995,268.20838742845234,0.05865053896608818
0.06076016655844731,252.867905262981,0.1929135288230702,101.95633940203393,268.2322013040454,0.05898578936589038
0.06111820141413001,252.870631130921,0.19405028948986278,101.95743847198736,268.32562929609884,0.05932325909505555
0.06148198901525621,252.903882490827,0.19520531512343844,101.97084542030144,268.45291621604366,0.059666034532774276
0.06184049004464271,252.958528963642,0.1963435558917406,101.99287887814046,268.6016083557256,0.06000371384086676
0.06221046386941991,252.96780431935,0.1975182227854082,101.99661870156191,268.7050487700854,0.06035208008682426
0.0625701207901367,252.947749356057,0.198660133508684,101.98853254036217,268.77472058685873,0.06069061567656796
0.0629295680408822,252.912335606818,0.19980137852980098,101.97425371666903,268.8279996387657,0.061028839442076585
0.0632894065899154,252.875744776405,0.20094386592298139,101.9595002938465,268.8801006042866,0.061367316858337316
0.0636450286651741,252.876427127788,0.20207296601192776,101.95977541792412,268.9707545810829,0.06170171558043988
0.0640057516038563,252.872177656213,0.20321826134224374,101.95806203098509,269.0574514468028,0.06204079654756434
0.0643648732809669,252.906989158717,0.2043584726670699,101.9720980287947,269.1853154677887,0.062378258149711874
0.0647123303589595,252.832286284957,0.2054616488896964,101.94197783009467,269.1936527204401,0.06270465033547482
0.06507082109691441,252.777338115328,0.20659985698270322,101.91982272810026,269.22576706118474,0.06304129563299782
0.0654362135023704,252.740109629955,0.207759977870026,101.90481220279786,269.27846540431324,0.06338430544531448
0.0657852869959562,252.712110366216,0.20886828621216094,101.8935228996583,269.3368490740113,0.06371188612768444
0.0661476776632202,252.790095995939,0.21001887658072413,101.92496670556261,269.51157378233285,0.06405185054191458
0.0665136037707887,252.80421874085,0.21118069197225411,101.9306609963107,269.6191383777627,0.06439501437608287
0.0668877952277731,252.847613975634,0.2123687498481796,101.94815795497563,269.7600334030672,0.06474580767826897
0.0672575900103289,252.826405822028,0.21354284828279424,101.9396068274417,269.830900568591,0.06509235837609363
0.0676356430587316,252.814453963132,0.2147431667114728,101.93478783793482,269.91372213147054,0.0654465241456024
0.0679989557393157,252.784848099653,0.21589668447232735,101.9228507537801,269.97395379715095,0.06578676276534876
0.068365849860872,252.756016839552,0.2170615733082686,101.91122598970736,270.03589673823683,0.06613023792858069
0.068726868760386,252.751880134773,0.21820780831422554,101.90955807034047,270.1227254297363,0.0664680977694781
0.0691002848936713,252.704987933957,0.21939340453740638,101.89065113497146,270.1669745942452,0.06681743951719116
0.06946489435291721,252.688481385235,0.22055103957051211,101.88399569452675,270.24146004885944,0.06715842464714378
0.0698322610513049,252.643160246706,0.22171742883789303,101.86572221147186,270.2858033658806,0.06750187081222721
0.07019458739030421,252.612523587129,0.22286781496421584,101.85336951033041,270.34455544995103,0.06784048931388321
0.0705583522108183,252.54626887027,0.22402276826934808,101.82665560849287,270.3655174587466,0.0681803368668503
0.0709186881464743,252.499917888693,0.2251668348650559,101.80796689272101,270.40688082245157,0.06851686715157052
0.0712882219116459,252.460521893363,0.2263401045694757,101.79208242740397,270.457983602027,0.06886187002417074
0.0716466235708213,252.468457228681,0.22747802983735763,101.79528195460418,270.5569697472503,0.069196366113282
0.0720175380151888,252.473840231897,0.22865568319822444,101.79745238150086,270.65638461863836,0.06954242260358101
0.0723892803141562,252.462597781308,0.22983596499744594,101.79291942542339,270.7381835409392,0.06988913135260537
0.0727671142884314,252.424545812408,0.23103558786576966,101.77757687156291,270.7927515867449,0.0702413984219278
0.07314100365760161,252.314075914831,0.2322226866128851,101.73303540885985,270.768580664182,0.07058986569303496
0.0735050627358078,252.333769752999,0.23337857418618976,101.74097596440919,270.8815793290561,0.07092905442786743
0.0738770286971722,252.320505415238,0.23455956611352174,101.73562778342395,270.9611946346845,0.07127549111146328
0.07425314278956001,252.327352916847,0.23575372835685302,101.7383886960727,271.06345188269336,0.07162566923495288
0.07463599388274711,252.344796572022,0.23696928057772207,101.74542197783927,271.17880126531446,0.07198199389656906
0.0750140038110978,252.296616267802,0.23816946210023549,101.72599567917776,271.22239560204196,0.0723336882957993
0.07538697174315201,252.249622332954,0.23935363528450762,101.70704772464705,271.2659574839892,0.07268057051919304
0.0757541447042836,252.227254075385,0.24051940943610042,101.69802884319523,271.3345139789758,0.0730219455799827
0.0761304273925891,252.220224266648,0.2417141069714704,101.69519442431248,271.4218577371226,0.07337166944251691
0.076508210726664,252.186588730734,0.2429135690571582,101.68163257623195,271.4809334037835,0.07372266503579807
0.0768915236674929,252.178005337675,0.24413058764428994,101.67817175215056,271.568356403518,0.07407867227287089
0.0772709666954182,252.125482146842,0.2453353192579528,101.6569944016067,271.6074618808768,0.07443096049026113
0.0776565718237438,252.113041938744,0.24655961554038655,101.65197850970159,271.69127648776265,0.07478884271650658
0.0780312173182958,252.087809863309,0.24774911498558916,101.64180493688619,271.75852853804605,0.07513643061880944
0.07840975869831711,252.041708806939,0.2489509838671568,101.62321699095781,271.80423837640257,0.07548751037301504
0.0787912492865856,251.995376401757,0.25016221648490927,101.60453576518843,271.8504069228948,0.07584120072531275
0.07916717393405161,251.925944378246,0.25135577724061386,101.57654077330879,271.8702094353388,0.0761896084121556
0.0795416731711458,251.811859126462,0.2525448123183879,101.53054159978949,271.84139572571763,0.07653657436947163
0.079906437903317,251.704630486797,0.2537029403430315,101.48730701227655,271.8174509127676,0.07687440581239424
0.080280713728266,251.629681193115,0.25489126608724455,101.45708745706398,271.8306915945143,0.07722092748151116
0.08065504607330021,251.555513755682,0.25607977128272813,101.42718314629099,271.8447353076392,0.07756738141664608
0.081027697470249,251.610462086845,0.2572629394680406,101.44933831341591,271.9978784891674,0.0779121604104678
0.0813997970934438,251.615091906075,0.25844435577168406,101.45120505652946,272.09650933287776,0.07825631033253724
0.0817739949335845,251.66118640417,0.25963243391413077,101.46979035816133,272.24052698616447,0.07860228146555696
0.0821527089608572,251.703572100713,0.2608348509507216,101.4868802710075,272.381702403911,0.07895230628890948
0.0825254502791662,251.707098385143,0.2620183046363527,101.48830206888967,272.4793400178393,0.07929669126863674
0.0829108575548776,251.675649904784,0.2632419727367364,101.47562204160891,272.54229386407076,0.0796526539708291
0.08329826945489001,251.588916182065,0.26447200551927574,101.44065100460861,272.5458375140624,0.08001034049270031
0.0836850161955909,251.529912559195,0.2656999264210011,101.41686074386742,272.5791973653868,0.08036728532690193
0.0840730654010084,251.503040252668,0.2669319826482016,101.40602582987574,272.64767180438304,0.08072530425240555
0.08445865003097071,251.436855722277,0.268156213848332,101.37934022722207,272.67287312461247,0.08108092241679016
0.0848502789106243,251.447959738338,0.26939963554123214,101.38381736649788,272.7833892536434,0.08144198568323713
0.0852392096330753,251.367795517434,0.27063449058501404,101.35149515262938,272.7941877345486,0.08180043240045196
0.0856290013194583,251.358488291093,0.2718720791892801,101.34774247896871,272.88206461662804,0.08215954373535958
0.0860222423919681,251.282812595742,0.2731206195944987,101.31723003860317,272.8987236097884,0.08252170232592208
0.0864086890542942,251.245862417077,0.2743475877473841,101.30233172656544,272.9556880188522,0.08287747581524994
0.08680134749387171,251.198285635711,0.27559427829304267,101.28314876831868,273.0026353170412,0.08323883844219074
0.0871882420119333,251.117975000506,0.2768226683878882,101.25076752020401,273.0125097783967,0.08359476886983724
0.0875554860663552,251.047956108284,0.27798866826067775,101.22253590286012,273.0285819313098,0.08393250434935265
0.0879419085936495,250.966643979224,0.27921555978483714,101.18975085242312,273.0371296440999,0.0842877541715834
0.0883287307672195,250.837282776063,0.2804437201859219,101.13759241530862,272.9934215927708,0.08464324504725629
0.0887166007941547,250.850472759782,0.28167520752144115,101.1429106167441,273.10507401063654,0.08499957206113694
0.0891303636496921,250.836632456847,0.28298890458777237,101.13733020660071,273.19379272438994,0.085379546290062
0.0895164388521081,250.86256736616,0.2842146933554432,101.14778716203571,273.3188910380757,0.0857339637257051
0.08990197941575691,250.833545625316,0.28543878464502814,101.13608559612742,273.38397788090447,0.08608776505585714
0.09028509277605841,250.766660167147,0.28665516956398546,101.10911737939367,273.40715134548014,0.0864392150475862
0.09067381688268761,250.711932765862,0.2878893686025331,101.08705129119556,273.4449406477784,0.08679568587243662
0.0910683187908283,250.630671568432,0.28914191216087987,101.05428677639179,273.4551854655854,0.08715732523025978
0.09145485686085321,250.625608208441,0.29036917053320893,101.05224522964342,273.54653733280827,0.08751153734436574
0.0918449134606323,250.578460493346,0.29160760023750754,101.0332352709171,273.59281751245584,0.08786884659638057
0.092243224974139,250.546550930703,0.2928722392928913,101.02036933525946,273.6577727946984,0.0882335860140928
0.0926411094838199,250.506599178086,0.2941355226111282,101.00426078860428,273.7138084589625,0.08859780164583526
0.0930469221346593,250.485135477894,0.29542397777754326,100.99560662468686,273.7920063745952,0.0889691379478435
0.0934432649840078,250.465393260332,0.29668236632422473,100.98764656256586,273.8696973720809,0.08933167591487814
0.0938384898855134,250.368874364852,0.29793720538650503,100.94873014390832,273.8631114495855,0.08969306045523469
0.09423757216384031,250.353104943648,0.29920429162019296,100.94237191327888,273.9457737372165,0.09005783962326631
0.0946438317590058,250.280410178221,0.3004941658348434,100.91306138385872,273.96790721170345,0.09042904255742468
0.09504925606296011,250.193187476318,0.30178138799989834,100.87789319045142,273.97386381796275,0.09079934496267221
0.0954477231701645,250.11358272798,0.3030465210652723,100.84579655592154,273.98635473329824,0.09116315930743245
0.095840097634049,250.007595443815,0.3042923099881056,100.8030624829462,273.96834780040405,0.09152128156262215
0.0962354408560756,249.946824834224,0.30554752471804003,100.77855977315913,274.0005677127219,0.09188198375501595
0.09663747333349701,249.924532982177,0.306823977833853,100.76957169841377,274.0766083736288,0.09224865569420963
0.0970403778541984,249.892851069219,0.3081031996870799,100.7567975511091,274.14254776003895,0.09261598814005054
0.0974514074558989,249.858760347006,0.30940821867247903,100.74305217191282,274.20784820800793,0.09299058932038624
0.0978526753889369,249.814312686738,0.3106822443598746,100.72513087529276,274.25931153358374,0.09335615866510015
0.0982585520872878,249.757411201067,0.31197090287713874,100.70218819627021,274.2982127987532,0.09372579085667054
0.098669616110896,249.793150344139,0.3132760311520948,100.71659821875684,274.4401445957265,0.09410000794246842
0.09907266240838951,249.753023472651,0.31455570314663667,100.70041906417288,274.4967204526315,0.09446679007698107
0.0994760490694846,249.62717492046,0.3158364557956136,100.64967692792948,274.4591000219245,0.09483374730064023
0.0998720639974361,249.567752650253,0.3170938031918596,100.62571786858202,274.4925992146354,0.09519386758344456
0.10027531725068481,249.494577402323,0.31837413227092426,100.59621360861664,274.51272530366646,0.09556043689711963
0.1006976441822548,249.441537529246,0.31971502027865895,100.57482793179199,274.55971271964063,0.09594420075442608
0.1011092686153668,249.380701869965,0.3210219278537896,100.5502989939699,274.595402242824,0.096318097698354
0.1015223570693408,249.326406232566,0.322333483695157,100.52840699297062,274.6386106729241,0.09669318398513957
0.1019328053148018,249.250058604767,0.32363665687449567,100.49762362944206,274.6568163032297,0.09706573365823042
0.1023467690348068,249.153095620365,0.32495099168551156,100.45852815413116,274.6531099521296,0.0974413336771107
0.1027581801494658,249.118652140483,0.3262572219745539,100.44464054304275,274.7176314757268,0.09781447793002687
0.1031845999361638,249.071699251391,0.32761110479732003,100.42570913816085,274.7720628940663,0.09820108795079348
0.1035939534099658,249.061983457428,0.3289108020766414,100.42179173003497,274.86329896791045,0.09857208437712399
0.1040079694261218,248.992145450837,0.33022530292793667,100.39363304577748,274.8893129022321,0.09894716651193032
0.1044238467963588,248.918532333039,0.33154571357843915,100.36395223668133,274.91156301815874,0.099323793376385
0.1048331254397828,248.84988933788,0.3328451732713104,100.33627538103322,274.93760100251404,0.09969430586384077
0.1052629730169258,248.738145761874,0.33420993932873944,100.29122037118759,274.9210624874863,0.10008329128656816
0.1056779610523758,248.788229694317,0.3355275263412931,100.31141421274863,275.07966254224254,0.10045868624527418
0.1061054868614578,248.723401693078,0.3368849207851285,100.28527556264905,275.1143193235599,0.10084527546114862
0.1065295765804258,248.609445716852,0.3382314056428519,100.23932851303472,275.0937047029626,0.10122861000299709
0.1069540915934478,248.516589941144,0.33957924080919677,100.20188906426925,275.09645606420037,0.10161218185792478
0.1073632104763248,248.459501819237,0.3408781932623312,100.17887113351637,275.1349116078985,0.1019817033236604
0.1077854167692618,248.437180358031,0.3422186982424062,100.1698711203581,275.2150853839016,0.10236290239342644
0.1082102732520378,248.364970081146,0.34356761757522003,100.14075593671807,275.240611359861,0.10274634762294084
0.1086505560664798,248.282893573803,0.34496551551107335,100.10766268895738,275.25896802239134,0.10314356048755385
0.1090790413714898,248.173536030776,0.3463259563544801,100.06356972760888,275.2440674347859,0.10352997848083544
0.10951236060799681,248.104287283597,0.34770174493038986,100.0356486327463,275.2747734609883,0.10392060402966834
0.1099355368783368,248.07739284693,0.34904532958871937,100.02480479588218,275.3499142169353,0.1043019387534501
0.1103719739385308,248.066049469977,0.3504310172548353,100.02023114629473,275.44558901711156,0.10469507084320681
0.1108044700664188,247.997439314655,0.3518041924608797,99.9925675316689,275.4766641557442,0.10508450062895958
0.1112331680534728,247.911347398317,0.3531653085697761,99.9578552710014,275.48731196583685,0.10547036087274532
0.1116690230389068,247.768627489307,0.35454914814852906,99.90031060368858,275.43670806072873,0.10586251037240937
0.1121025065669478,247.69533031561,0.35592545835005923,99.87075718325396,275.462597708918,0.10625237374439746
0.1125353443042738,247.564903198886,0.35729971816606926,99.81816896979082,275.42470481802684,0.10664150471474235
0.1129529750818848,247.502504004796,0.3586256958849842,99.79300961473375,275.45864817235383,0.10701682080054277
0.11338844741467981,247.414786072348,0.36000832054160836,99.7576417443707,275.4687645325267,0.10740802076111337
0.1138273268591958,247.358526909966,0.36140176277794667,99.73495805009829,275.5146868039559,0.10780212667152043
0.1142683797293578,247.322061688292,0.36280210564071097,99.72025527271933,275.5831529487374,0.1081980278660863
0.1147143135130318,247.279135887094,0.3642179454038759,99.7029475896763,275.64559220647766,0.10859815101731161
0.1151635494398138,247.262250573748,0.3656442694714088,99.6961394313352,275.7378489922974,0.10900107526740023
0.1156034545421918,247.186243556272,0.3670409681714589,99.66549340188887,275.7618272266846,0.10939547334420074
0.1160470753546138,247.05253466894,0.3684494642508988,99.61158197851661,275.72225877621486,0.10979304528687045
0.1164732227132358,246.947432881157,0.36980248211452366,99.5692049376825,275.71019622958585,0.11017480877109632
0.1169244159195798,246.806733260133,0.37123502054466584,99.51247485048563,275.6644663915936,0.11057885076046468
0.1173671968356788,246.721054854354,0.3726408499532802,99.47792931727554,275.6780134629513,0.1109752009229662
0.1177951029773728,246.671942418926,0.37399945195315865,99.45812718331095,275.72868927779194,0.11135808689680111
0.11823912679323881,246.610682991684,0.3754092275685332,99.43342738224699,275.76971480650496,0.11175523987039218
0.1186877426097558,246.534027108796,0.3768335827859746,99.40251973026656,275.79459426283137,0.11215633999455613
0.1191564263316678,246.424256555965,0.37832165360304526,99.3582602433651,275.78729032861185,0.1125752107410266
0.1196212567690208,246.334164608657,0.379797490241641,99.32193517021051,275.8009669642914,0.11299046451771116
0.1200685113585078,246.233639624687,0.3812175235632622,99.28140349667379,275.79854618081043,0.11338985429195322
0.1205108914662428,246.063343573762,0.38262208040532086,99.21274012894084,275.7166564650004,0.11378473439566707
0.1209418051663088,245.910088377149,0.3839902314030304,99.15094763366648,275.65089837408794,0.11416922942072122
0.12138314518265281,245.777051228425,0.3853914859549226,99.09730705530096,275.6102427202492,0.11456287443811664
0.1218359258057478,245.720723640295,0.3868290644332492,99.07459577176695,275.6583354946686,0.11496656272260003
0.1222997975732788,245.711947020418,0.38830185729516015,99.07105703863253,275.7624684023514,0.11537997067231105
0.1227736875016048,245.646731951715,0.3898064578175952,99.04476232293149,275.8056870561453,0.11580213051564292
0.1232480915788158,245.560685200248,0.39131269076274017,99.01006827274,275.82557101796493,0.11622456994938726
0.1237187501222278,245.423737591086,0.39280703163807323,98.95485099672588,275.7872556561808,0.11664349784948845
0.12419895072663781,245.247970743285,0.394331668557075,98.88398180369252,275.7075113774382,0.11707073823425262
0.1246681679949078,245.149327774307,0.39582143338383224,98.84420895860059,275.711645353113,0.11748803036429671
0.1251387306540218,244.998128451591,0.3973154698265192,98.78324539168149,275.6568832586341,0.11790634419048204
0.1256085358853528,244.874553472498,0.3988071014359952,98.7334199601112,275.632887609758,0.1183238101984503
0.1260756997282248,244.706132232154,0.4002903466371137,98.6655125160045,275.55762908111035,0.11873875634603737
0.1265510603685708,244.546136097827,0.4017996166702123,98.60100207464386,275.49370893004385,0.11916080642181805
0.1270396587017468,244.445868889611,0.40335091637804604,98.56057433629115,275.50018864439915,0.11959442405850515
0.1275342381591458,244.367503219146,0.40492120615528787,98.52897729795967,275.5327265730524,0.12003315837191217
0.1280431469408388,244.269147635079,0.40653699153716316,98.48932032646385,275.5461379988309,0.12048440317839955
0.1285486796575488,244.099416322725,0.4081420579127174,98.42088466132273,275.4780739961896,0.12093245294903901
0.1290498102194198,243.898678728987,0.40973314744665784,98.33994726352756,275.37375693173,0.12137640307776981
0.1295585819308688,243.708145407642,0.41134849763050846,98.26312422836126,275.2826271316581,0.12182692094693442
0.1300633059653028,243.510181576637,0.41295099643983635,98.18330521170004,275.18192082870553,0.12227365413316474
0.1305576896719308,243.324852278977,0.4145206647083802,98.10858043888354,275.09278283228406,0.12271104166116148
0.1310612242493328,243.144053489524,0.41611938699163165,98.03568236697608,275.01081080880624,0.1231563285153018
0.1315697602205138,242.927632523677,0.41773398870013134,97.94842143354657,274.8895628857543,0.12360583705932374
0.13209826076777081,242.755909611752,0.4194119779376723,97.8791827554584,274.82354306256263,0.12407277881223035
0.1326310892756428,242.557207199423,0.42110370845016587,97.79906594280736,274.7278338019403,0.12454332379606525
0.1331800090642698,242.362908232757,0.4228465287790566,97.72072459944762,274.6408025480384,0.12502784768225159
0.1337290717355938,242.135623548636,0.42458980276051034,97.62908341481003,274.5161957199143,0.1255122629476994
0.13429346978749981,241.865951859549,0.4263817665753119,97.52035178977016,274.34696975822425,0.12600996352449992
0.1348729949635818,241.602774074424,0.42822175900937215,97.41423850680776,274.1884638053512,0.12652074596173765
0.1354410155439058,241.287210402257,0.43002522435190094,97.28700323419002,273.9673952168948,0.12702113541407534
0.1360187075566408,240.976655620859,0.4318593964923345,97.16178754633034,273.75398886972994,0.12752978808294307
0.1365923779297108,240.630978836548,0.43368079992683173,97.02241066689616,273.499336439386,0.1280346438313978
0.1371866849649248,240.29973545909,0.43556772476363625,96.88885333710509,273.26565956467095,0.12855739211283457
0.1377781588160428,239.973189680477,0.43744565424093584,96.75719007916832,273.0362539198661,0.1290773771719988
0.1383736412917858,239.555082335539,0.4393363111014199,96.58860919768934,272.70319136826106,0.1296006133544894
0.1389843557980528,239.17069767404,0.4412753296588176,96.43362530217293,272.41168301603733,0.13013694933828038
0.1395910256405728,238.734489957971,0.4432015064088186,96.25774635105391,272.0596822669832,0.13066944860233576
0.1402037018470298,238.315350508511,0.4451467533643196,96.08874932503164,271.7280448567767,0.1312069322747205
0.1408253139877758,237.853129700734,0.4471203719111882,95.90238189533595,271.34887137381503,0.13175196011243623
0.1414568336521718,237.40393722973,0.4491254468456454,95.72126749102713,270.98634648680655,0.13230537081248192
0.1421003169938488,236.875169813387,0.45116850645546996,95.50806846875764,270.5352065318411,0.1328689506278827
0.14275966341518181,236.343347290767,0.45326193134320225,95.29363762763725,270.0836440004143,0.13344609447502295
0.1434411846714268,235.847448980576,0.4554257613317801,95.09369142896823,269.6776864640837,0.13404229867729428
0.1441352230100638,235.2021615447,0.4576293330569525,94.83351153482305,269.1030775513944,0.13464908790418226
0.1448487958512488,234.593197552219,0.4598949268277149,94.5879772530547,268.57373973255204,0.13527257226092812
0.1455654276179938,233.881221745653,0.46217023268713026,94.30090860784729,267.9262418008778,0.13589833836278606
0.1462759999059218,233.180475709266,0.46442629970130167,94.01836780597606,267.2891829521774,0.13651842691006758
0.1470065202740208,232.443799919839,0.466745701870016,93.72134012767908,266.6145541053252,0.13715552276404977
0.1477397984396478,231.722357759914,0.46907386004588175,93.43045464879731,265.95697218932366,0.13779461579547161
0.1484761313759008,230.916909182862,0.471411717118485,93.10569778252997,265.20255852761363,0.13843596049823348
0.1492310927268948,230.033409603329,0.473808719407891,92.74947075206227,264.36154668212714,0.13909310373236072
0.1499749490168768,229.156516726861,0.4761704631285838,92.39590754427036,263.5242536398571,0.1397401586743103
0.1507368428177888,228.226884511085,0.4785894759464794,92.02107983486947,262.62908452842606,0.14040247007851728
0.1514971531849358,227.249174064344,0.4810034613621712,91.62686698274351,261.6767769987201,0.1410629680088823
0.1522684922881558,226.276476207497,0.4834524630148947,91.23467520686279,260.73125407988937,0.14173260134034432
0.1530330651051408,225.263050508545,0.485879981708822,90.82606196504535,259.73574558280177,0.14239591833032036
0.1537719767248688,224.128874864082,0.48822602610145843,90.36876234519787,258.59361499305265,0.14303655473573898
0.1545057194976488,223.017072129365,0.4905556594050349,89.92048348255997,257.47448531897163,0.1436723038907859
0.1552493537013168,221.86142572568,0.49291669800168075,89.45452685259417,256.3052686808445,0.14431621132321476
0.1560085014167888,220.711161679077,0.4953269919983044,88.99074038900386,255.14397925858842,0.14497312438991639
0.1567831880922108,219.508681582146,0.4977866221927693,88.50590041392128,253.92395249451283,0.14564303920144767
0.1575503209639458,218.208360515758,0.5002222690605279,87.98161095995361,252.58715775203203,0.14630597986823463
0.1583371218812198,216.852980580578,0.5027203619728728,87.43512177008904,251.18885739707073,0.14698546103211987
0.1591153370678338,215.473943783671,0.5051911951903723,86.87909413357615,249.75915297814527,0.1476570737013342
0.1598932677049728,214.069844586508,0.5076611249632886,86.31296133728003,248.29817155454043,0.14832799028587695
0.1606731703268438,212.612844903847,0.510137315787729,85.7254990652311,246.77402474675762,0.1490001560454545
0.1614617664379718,211.133920277175,0.5126411084405604,85.12919665575697,245.2239760001016,0.14967935528487716
0.1622880778054118,209.625511858172,0.5152646470321824,84.52100638121495,243.6452332366103,0.15039054319894224
0.1631143675788038,207.924200884367,0.517888117062702,83.83503779657678,241.8396254159487,0.15110120711847846
0.1639433531013818,206.19228494393,0.5205201460968872,83.13672928939258,239.99613952127345,0.15181368240456916
0.1647649334067438,204.433354417931,0.5231286635664115,82.4275285013098,238.11680244471867,0.15251929275878118
0.1655935634815148,202.612660769771,0.5257595640538094,81.69342482237167,236.1640132731087,0.15323045381902223
0.1664343848944708,200.753477444377,0.5284291720399448,80.94380210557281,234.1657589782579,0.15395156134260632
0.1672840400885118,198.780430120144,0.5311268272810249,80.14826942444206,232.03322356117377,0.15467971708109363
0.1681155240435058,196.781587258022,0.5337667888381309,79.34233598243448,229.8636269220172,0.1553917870864986
0.1689628291769068,194.66310937333,0.5364569826366791,78.48816569932666,227.55393906942146,0.15611688487310657
0.1698008893287048,192.422062817108,0.5391178236186377,77.58457572785795,225.09550020991688,0.15683355426645906
0.1706569964391758,190.073905702481,0.5418359636943831,76.63779877924034,222.51134755112952,0.15756512662574745
0.1715134458046208,187.627985671565,0.544555190429671,75.651603822775,219.80870802347513,0.1582964563259009
0.1723785985009908,185.007873683488,0.5473020502406457,74.59517466918236,216.89927166069597,0.1590346752534848
0.1732860353591578,182.121529934746,0.5501831622653259,73.43140086968958,213.68064781068233,0.15980838935595
0.1737485604029238,180.660119256329,0.551651679279283,72.84216008415186,212.04955489933673,0.16020252504580187
0.1739762092045978,179.884054997435,0.552374464224598,72.52925097496579,211.17960098224012,0.16039645646854309