File: example/data/02 processed data/test_ID_070.csv
Strain,Stress_MPa,Displacement(mm),Force(kN),True Stress (MPa),True Strain
5.46620859865085e-05,0.317439578086867,0.00017355212300716448,0.06399581894231239,0.3174569299963799,5.4660592069096795e-05
8.25084856279516e-05,1.02226640110857,0.00026196444186874635,0.20608890646348774,1.0223507467612338,8.250508199008117e-05
0.0001213041436758,2.32451568109127,0.000385140656170665,0.468622361308,2.3247976544754256,0.00012129678692313166
0.0001501944250675,4.04316341736596,0.00047686729958931246,0.8151017449409775,4.043770677970885,0.00015018314701406596
0.0002235458987153,6.72350607490253,0.0007097582284210775,1.35545882470035,6.7250090871105614,0.00022352091605390046
0.0002960701264325,10.0721921893631,0.0009400226514231874,2.030553945375601,10.075174264578058,0.00029602630632163365
0.0003729088652625,14.0422093518393,0.0011839856472084375,2.8309094053308033,14.047445816194472,0.00037283935203238965
0.000452649880107,18.6677403295815,0.0014371633693397248,3.7634164504436303,18.676190280003553,0.0004525474650542539
0.0005419778240712,23.5394261929933,0.0017207795914260598,4.745548320507449,23.552184039981263,0.000541831007135566
0.0006250530596427,28.4272618844014,0.0019845434643655725,5.730935995895322,28.44503043141951,0.0006248577953418885
0.0007177355241001,33.3115675848134,0.002278810289017817,6.715612025098383,33.33547648023249,0.0007174780751383502
0.0008066529172635,38.3440504691419,0.0025611230123116125,7.730160574579006,38.374980809312525,0.000806327747653246
0.000898748233057,43.5407014253308,0.002853525639955975,8.77780540734669,43.57983355380288,0.0008983446006881816
0.0009882373654621,48.8914017752194,0.003137653635342167,9.856506597884232,48.9397180853035,0.0009877493803871766
0.0010785180971606,54.3832573728733,0.0034242949584849048,10.963664686371258,54.44191070013249,0.0010779369143576012
0.0011687510951691,59.9446874155693,0.0037107847271618923,12.08484898297877,60.014747834635806,0.0011680686373049373
0.0012635754805045,65.5949185821264,0.004011852150601787,13.223935586156681,65.67780271289247,0.0012627778408550294
0.0013569807577228,71.2318566581661,0.004308413905769889,14.360342302286286,71.3285169169881,0.0013560608914008755
0.0014496350810604,76.8881153594145,0.00460259138236677,15.500644056457963,76.99957506875613,0.001448585374464869
0.0015495526525897,82.4847488871763,0.004919829671972297,16.62892537565474,82.61256334861261,0.001548353334655813
0.001643322485901,88.0901443720976,0.005217548892735675,17.758973105414874,88.23490488713053,0.001641973708952747
0.0017351819132584,93.7021431152669,0.005509202574595419,18.89035205203781,93.86473337923408,0.0017336782243203923
0.0018286231292333,99.3283748706639,0.0058058784353157275,20.024600373925843,99.51000903434154,0.0018269532333890757
0.0019228418839707,104.937080517397,0.006105022981606973,21.15531543230724,105.13885793099747,0.0019209955898909009
0.0020169397567363,110.569833945604,0.006403783727637753,22.29087852343377,110.79284663958461,0.002014908464615713
0.0021103823667862,116.132107611408,0.006700464014546184,23.412232894459855,116.37719076352884,0.0021081586379817115
0.0022046018274383,121.726606072883,0.006999610802116603,24.540083784293216,121.99496477107913,0.0022021752585870717
0.0022992313893073,127.332742946529,0.007300059661050677,25.670280978020248,127.62551038599825,0.002296592201444757
0.0023939219030021,132.926967714748,0.007600702042031667,26.7980766912932,133.24518449425997,0.00239106103684694
0.0024859788013462,138.529372622921,0.007892982694274185,27.92752152078087,138.87375370662537,0.0024828938677078738
0.0025738738481878,144.247777516109,0.008172049467996264,29.08035194724758,144.61905309831693,0.0025705671077676496
0.0026633696601633,149.962526219773,0.008456198671018477,30.232445285906238,150.36193186226816,0.0026598291762083134
0.0027486461263409,155.678366097098,0.008726951451132357,31.38475860517496,156.10627083502587,0.002744875506396551
0.0028294595413321,161.377927927207,0.008983534043729417,32.53379027012493,161.83454024514103,0.002825464155431543
0.0029144645337719,167.072886115847,0.009253424894725781,33.68189384095476,167.5598141169866,0.0029102257159383245
0.0030003820835658,172.703856946435,0.009526213115321414,34.817097560401294,173.2220345045798,0.002995889920469479
0.0030834600745779,178.2850100162,0.009789985736784832,35.94225801926592,178.8347447264807,0.0030787159612497756
0.0031676441344287,183.682819057812,0.01005727012681112,37.030456322054896,184.2646608621958,0.003162637719322294
0.003250908633565,189.074389670795,0.010321634911568876,38.11739695763227,189.68905323656182,0.0032456358545512125
0.0033362646286238,194.400310859225,0.010592640195880564,39.19110266921976,195.0488817401381,0.0033307116451749457
0.0034195444400959,199.632718480692,0.010857053597304482,40.24595604570751,200.3153714332339,0.003413711092485383
0.0035030767685086,204.736347671611,0.011122268740014804,41.27484769059677,205.4535548148087,0.0034969552869333694
0.0035871602842697,209.736097824614,0.011389233902556297,42.28279732144219,210.48845482490816,0.003580741769731079
0.0036698621941369,214.53724082636,0.011651812466384658,43.250707750594174,215.3245629357031,0.0036631446797599485
0.0037529839985325,219.191373909532,0.011915724195340687,44.18898098016165,220.0139956284308,0.0037459591247590886
0.0038367271115514,223.659320798155,0.012181608579175694,45.089719072908046,224.51744057801244,0.003829385646228177
0.0039200849211475,227.959935858553,0.012446269624643312,45.95672306908428,228.8535581657379,0.003912421409468578
0.0040053012106368,232.081096375524,0.012716831343771839,46.78754902930564,233.01065107180278,0.003997301345873414
0.0040850472466799,236.073103781454,0.012970025008208682,47.59233772234113,237.03747356407158,0.004076726095010115
0.0041663017703037,239.979806397369,0.013228008120714247,48.37992896970959,240.97963468959952,0.004157646766327542
0.004248002742231,243.818412151881,0.013487408706583423,49.15379188981922,244.85415343530858,0.00423900544993049
0.0043260875596629,247.691648951526,0.013735328001929708,49.93463642862764,248.76318471268758,0.004316756943239447
0.0044074023362657,251.493267218341,0.013993502417643596,50.70104267121755,252.6016992318342,0.0043977181828028
0.0044881653051436,255.306411622629,0.01424992484383093,51.469772583122015,256.4522690014544,0.0044781235261390565
0.0045704794532978,259.029798373784,0.014511272264220514,52.22040735215485,260.2136887450432,0.004560066528066737
0.004659078285076,262.823527259275,0.014792573555116298,52.98522309546985,264.04804264793574,0.0046482583740352044
0.0047497166206953,266.731216904281,0.015080350270707577,53.773013327903044,267.99811459846956,0.004738472307517187
0.0048523963716596,270.758245222601,0.01540635848001923,54.58486223687636,272.07207154931604,0.004840661442759178
0.0049673259195779,274.737171836964,0.01577125979465983,55.387013842331946,276.1018809117013,0.004955029459720037
0.0051022946196224,278.734324303516,0.01619978541730112,56.19283977958883,280.1565089467139,0.0050893220223936775
0.0052636699682912,282.714555511342,0.01671215214932456,56.99525439108655,284.20267162678584,0.0052498652785550794
0.005455073382077,286.768653208663,0.017319857988094472,57.81256048686646,288.33299725559567,0.005440248359228973
0.0056778518726443,290.549892086612,0.018027179695645653,58.57485824466097,292.1995913354926,0.005661793627252745
0.0059316861633427,293.93146076355,0.01883310356861307,59.25658248993168,295.67496994233227,0.005914162973535943
0.0062116148019949,296.880392897216,0.019721876996333806,59.851087208078745,298.7244995401584,0.006192402242402884
0.0065200416235293,299.398436686107,0.020701132154705527,60.358724835919176,301.35052695532005,0.006498878093730652
0.0068447489489748,301.473414288015,0.021732077912994988,60.77704032046383,303.5369241236068,0.006821430002635758
0.0071779166240242,303.110852200745,0.022789885281276834,61.107147803670195,305.2865566256789,0.007152277995345496
0.0075216355032259,304.3370898599,0.02388119272274223,61.35435731575584,306.6262025199387,0.0074934890530176665
0.0078676657393046,305.312479118483,0.024979838722292102,61.55099579028617,307.71457565022564,0.007836877041894617
0.0082180805682131,306.047789727921,0.026092405804076593,61.699234409148865,308.5629151216286,0.00818449601899303
0.008570730862552,306.598240032473,0.0272120704886026,61.81020519054655,309.22601103072344,0.008534210670258748
0.0089240182042981,307.045002017699,0.028333757798646466,61.90027240676812,309.7850772052437,0.008884434476809417
0.0092786429573459,307.414047163823,0.029459691389573234,61.97467190822672,310.2664323475288,0.009235860786487856
0.0096398662599427,307.747920303474,0.03060657537531807,62.04198073318037,310.71456909697497,0.009593699208199327
0.0099982807316643,308.004467892079,0.03174454132303415,62.09370072704313,311.0839830286709,0.00994862860584234
0.0103555336041613,308.162838298746,0.032878819193212123,62.1256282010272,311.35402892630236,0.010302282380429168
0.010714660479857,308.357783940376,0.034019047023545974,62.164929242379806,311.6617329016182,0.01065766526671057
0.0110743713845122,308.571057984313,0.03516112914582623,62.2079252896375,311.9882884789431,0.011013499533077276
0.011437994019806,308.720673158936,0.03631563101288405,62.2380877088415,312.2518183723184,0.01137307472819736
0.011803635617519,308.914848301248,0.03747654308562282,62.2772334175316,312.56116660743714,0.011734516086795033
0.0121665511048723,309.088279856542,0.03862879975796955,62.31219721907886,312.8488182093337,0.01209313351468351
0.0125337737460546,309.253152992031,0.03979473164372335,62.345435643193454,313.12926204188716,0.012455876228458784
0.0129092927720029,309.462947151819,0.04098700455110921,62.38773014580671,313.4578949386887,0.012826678090489322
0.0132858247365307,309.592351254902,0.042182493538484966,62.413818012988244,313.705540973445,0.013198342167268872
0.0136663497745726,309.729505058978,0.043390660534268,62.44146821988997,313.9623768106193,0.013573807407443185
0.0140425755182179,309.967510493953,0.04458517727034183,62.48945011558092,314.3202526682583,0.013944891978083173
0.0144218655137285,310.155243165108,0.04578942300608799,62.527297022085776,314.62826037041293,0.01431885958851664
0.0148046400021834,310.283280364797,0.047004732006932295,62.55310932154308,314.8769126292944,0.014696121064211405
0.0151852044665425,310.423090621047,0.048213024181272435,62.58129506920307,315.1369287232637,0.015071063303311172
0.0155664000641039,310.56924469764,0.04942332020352988,62.61075973104422,315.40368980821,0.015446486472927772
0.0159460597059681,310.76122323728,0.05062873956644871,62.649462604635644,315.71664025732133,0.015820256906339095
0.016322063549403,310.935480103161,0.05182255176935452,62.68459278879727,316.0105887691689,0.016190290607525033
0.0167025615645682,311.064587038233,0.05303063296750403,62.71062074690778,316.26016245379606,0.016564607784904584
0.0170804290123051,311.195689990726,0.05423036211406869,62.737051102130366,316.5110458825479,0.016936198513940653
0.0174551409425742,311.377853129653,0.055420072492673084,62.77377519093804,316.8129974424273,0.017304549837003948
0.0178287636888773,311.582387775562,0.05660632471218542,62.8150093755533,317.13751653682857,0.017671695422589936
0.0181993480395218,311.768829177192,0.05778293002548171,62.8525959621219,317.4428186072619,0.018035722179000756
0.0185677125700551,311.939510476001,0.05895248740992494,62.88700531196179,317.7315136457631,0.018397437116043722
0.0189384810585903,312.123158570936,0.060129677361024196,62.9240287679007,318.03429709747905,0.01876138054236255
0.0193058663363544,312.312426936411,0.06129612561792522,62.96218527038046,318.34188890602775,0.019121872435508044
0.0196717678599928,312.488260510344,0.06245786295547713,62.99763331888535,318.6354570300764,0.019480779292973743
0.020037519606198,312.666515994104,0.06361912474967865,63.03356962441137,318.93157743853743,0.019839410547312666
0.020405409733295,312.84851315213,0.06478717590321162,63.070260251469406,319.23231524745137,0.02020000885250777
0.0207707221935834,313.044952685015,0.06594704296462729,63.10986246129903,319.5471224313389,0.02055795196038041
0.0211356346801871,313.249554013759,0.06710564010959405,63.15111008917382,319.87028215112537,0.02091537529594159
0.021499706202557,313.422924348401,0.06826156719311847,63.186061548637646,320.1614251390379,0.02127184766175094
0.0218661885555544,313.584764472611,0.06942514866388522,63.21868851767839,320.44166806071826,0.021630552246051902
0.0222297567643959,313.761543446224,0.07057947772695698,63.254327158758755,320.736386239055,0.02198627743938998
0.0225910506691601,313.962204867664,0.07172658587458332,63.294780501321064,321.0549409460306,0.022339652079564218
0.0229533365316452,314.162322517738,0.0728768434879735,63.33512421957598,321.3733960320509,0.022693871590556126
0.0233176886717623,314.320755865802,0.07403366153284531,63.367064382545685,321.6499893941538,0.02304998487123103
0.0236801838988975,314.49060795472,0.07518458387899955,63.40130656367156,321.9378033855639,0.023404157423906204
0.0240382616888306,314.643424158001,0.07632148086203715,63.432114310253,322.20690512658075,0.023753890849763055
0.0243935616780517,314.840133926863,0.07744955832781414,63.47177099965558,322.520206152534,0.024100790354770925
0.0247533939878082,315.038787443529,0.07859202591129102,63.51181954861544,322.83706667056,0.024451992412251558
0.0251144855203946,315.166962744885,0.07973849152725286,63.537659689368816,323.0822188672482,0.02480429954378043
0.0254718761414591,315.292580071226,0.08087320674913263,63.562984142359156,323.32367361912134,0.02515287362128829
0.0258247767197279,315.483237583494,0.08199366608513607,63.601420696832385,323.6305217529046,0.025496949239271798
0.0261789577027063,315.674683291921,0.0831181907060925,63.640016151651274,323.9387174736354,0.025842154250894495
0.0265348350760039,315.903664521808,0.08424810136631238,63.6861787675965,324.28611615979946,0.026188892678935604
0.0268909507770331,316.027885992028,0.0853787687170801,63.71122181599285,324.5261763184095,0.026535743007837558
0.0272418337065079,316.16802192699,0.08649282201816258,63.73947322048118,324.7810186036406,0.026877379084665684
0.0275915534660631,316.388234774549,0.08760318225475033,63.78386813054908,325.1178776703643,0.027217766548792967
0.0279433019987001,316.625424307783,0.0887199838458728,63.831685540449065,325.47298415968197,0.0275600118141897
0.0282991893003508,316.807163432917,0.08984992602861377,63.86832414807606,325.7725493226123,0.027906164864435694
0.0286542845650756,316.94693486978,0.09097735349411502,63.89650206974766,326.0288225335672,0.028251428160629814
0.0290107645163637,317.104143631153,0.09210917733945474,63.928195356040455,326.3035772691996,0.02859791794040582
0.0293660921132641,317.353040627393,0.09323734245961351,63.978372990482434,326.6724592508815,0.028943168227577927
0.0297183823987613,317.589981205063,0.09435586411606713,64.02614021094071,327.0282417125305,0.029285349709974866
0.0300711109175493,317.777137836928,0.09547577716321902,64.06387098792469,327.3330493958836,0.029627839584188267
0.030420310439668,317.930160561243,0.09658448564594589,64.09472036914659,327.6016947436495,0.029966787392310578
0.030768435141685,318.087710819558,0.09768978157484987,64.1264825012229,327.87477191927667,0.03030457761756131
0.0311170963294798,318.260720871137,0.09879678084609836,64.16136132762122,328.16407038037386,0.030642774074926438
0.0314694054112518,318.424413433133,0.09991536218072447,64.1943617481196,328.4450403923003,0.03098439279966943
0.0318207743142347,318.552430899502,0.10103095844769516,64.2201700693396,328.6890159104059,0.031324983677125356
0.0321788063760982,318.673433012756,0.10216771024411178,64.2445640953716,328.92796371087996,0.031671914043588704
0.0325325330280016,318.810772846785,0.10329079236390508,64.27225180591186,329.18249484410575,0.03201455434261099
0.0328858912235606,319.014705768515,0.1044127046348049,64.31336468293263,329.50578868113456,0.03235672055441344
0.0332389544103868,319.178992698109,0.10553368025297809,64.34648492793879,329.7881686851547,0.03269848421018564
0.0335904565356834,319.358251360709,0.10664969950079478,64.38262347431893,330.0856408223528,0.033038620775713436
0.0339377368562085,319.50760802884,0.107752314518462,64.41273377861415,330.35097315367943,0.03337455846681828
0.0342822717292152,319.687741951008,0.10884621274025824,64.44904877732321,330.64736398907166,0.033707728898168414
0.034626499520705,319.884702885567,0.10993913597823836,64.4887561017303,330.9611903967149,0.03404049155977018
0.0349723532064625,320.058274247486,0.11103722143051842,64.52374808829317,331.2514652611199,0.03437471448274985
0.035320195032742,320.168473741495,0.11214161922895585,64.5459643062854,331.4768866773799,0.0347107460545665
0.0356686533411418,320.341907633214,0.1132479743581252,64.58092857885595,331.76807208722323,0.03504725999761535
0.0360204947433466,320.53268038807,0.11436507081012545,64.61938836623492,332.0784261170593,0.03538692621241679
0.0363730409787531,320.715757779604,0.11548440510754109,64.65629676836818,332.3811651798534,0.0357271571895264
0.0367262468576161,320.868770637259,0.11660583377293111,64.68714416047142,332.65307631658277,0.036067908724537884
0.0370779951192917,321.008611898501,0.11772263450375113,64.7153361587378,332.9109676437242,0.03640713868455895
0.0374314219929093,321.171484785745,0.11884476482748703,64.7481713328062,333.19339016484946,0.0367478716541195
0.0377841700983204,321.352231703765,0.11996474006216726,64.78460991147902,333.49425908793495,0.03708783450921063
0.0381336735470165,321.490626212706,0.12107441351177739,64.81251024448153,333.7502448011272,0.03742455636269666
0.0384851856832823,321.60789290321,0.12219046454442128,64.83615120928712,333.98503237879913,0.037763099122298846
0.0388337123904477,321.780621589219,0.12329703683967144,64.87097331238655,334.2765577008342,0.03809865348591522
0.0391828387261688,321.933899694268,0.12440551295558594,64.90187417836444,334.5481837664751,0.038434672310037186
0.0395315231477685,322.078680300218,0.12551258599416498,64.93106194852396,334.8109411059088,0.03877015315460652
0.0398769505898641,322.217559727871,0.12660931812281853,64.9590600411388,335.0666134363259,0.039102389412788395
0.0402229791708141,322.296624684246,0.12770795886733474,64.974999536344,335.26035510574417,0.039435093221092156
0.0405706760306283,322.444968164797,0.12881189639724483,65.00490558202307,335.52677850591726,0.03976928961022582
0.0409171170888315,322.576259167936,0.12991184675704,65.0313738482559,335.77514973438764,0.04010216791251254
0.0412664425267897,322.728482724365,0.1310209550225573,65.06206211723199,336.04633910846803,0.040437705516411585
0.0416174804902673,322.921094924589,0.13213550055659867,65.10089273679714,336.36025729250883,0.04077477467607251
0.0419651244032013,323.095336272188,0.1332392699801641,65.13601979247309,336.6540722529445,0.04110847290847612
0.0423165712099422,323.251736962002,0.1343551135915665,65.1675501715396,336.9306421078921,0.04144570833189456
0.0426676895676205,323.441775526848,0.13546991437719508,65.20586194621256,337.24228879822755,0.04178251505758809
0.0430160911870531,323.573427586596,0.13657608951889358,65.23240300145775,337.49229165336834,0.04211660369162554
0.0433571043572133,323.726995976675,0.13765880633415223,65.26336238889769,337.7628611244829,0.042443499353365485
0.0437014415723022,323.833436731043,0.13875207699205946,65.28482084497827,337.9854247455025,0.04277347305619696
0.0440468480505132,323.912906899304,0.13984874256037938,65.30084203089969,338.1802494910977,0.04310436206525924
0.0443939575384208,324.035068779239,0.14095081518448602,65.32546986589459,338.42026786358383,0.04343677224435077
0.0447393459685336,324.189858140864,0.14204742345009416,65.35667540119819,338.69390036371794,0.04376742460883109
0.045086738099528,324.349147488775,0.1431503934660014,65.38878813373704,338.9729925544065,0.04409988493827415
0.0454372745454091,324.507641268158,0.14426334668167387,65.42074047966065,339.2523840565424,0.04443524243433359
0.0457918543249306,324.644099101718,0.14538913748165466,65.44825037890635,339.51015439523223,0.04477435380001277
0.0461399816880222,324.764674706887,0.14649444185947047,65.47255842090841,339.7493108507792,0.04510718239443635
0.0464890210631167,324.91965494497,0.1476026418753955,65.50380243690594,340.0248516275273,0.045440771748184776
0.0468383368111754,325.072392388625,0.1487117193754819,65.5345943055468,340.298242591338,0.04577451386452112
0.0471890609253647,325.141959950685,0.1498252684380329,65.5486191260581,340.48510370819037,0.04610948953661402
0.0475412659601311,325.251685024109,0.15094351942341622,65.57073970086037,340.71456188582096,0.046445766749546806
0.0478949893209736,325.348756619169,0.15206659109409118,65.59030933442448,340.9313318430362,0.046783379848786624
0.048251407662586,325.481345143349,0.15319821932871056,65.61703918089917,341.1862782144276,0.04712344993698283
0.0486057579044454,325.650233977879,0.15432328134661413,65.65108716994041,341.4787104121338,0.047461432181125654
0.0489567270825081,325.748473154015,0.15543760848696322,65.67089218784943,341.69605225175985,0.04779607697368857
0.0493091555677595,325.821240323935,0.1565565689276364,65.6855620493053,341.8872105503483,0.048132000548941484
0.0496586618617541,325.969771381532,0.15766625141106924,65.71550591051685,342.15699403572074,0.04846502737700661
0.0500032995523598,326.049439309232,0.15876047607874236,65.73156696474118,342.3529870918905,0.04879330659531346
0.0503474280472419,326.136690814942,0.15985308404999302,65.74915686829232,342.5568343893129,0.04912099329395792
0.0506890939578687,326.220558103638,0.1609378733162331,65.76606451369342,342.7563826243417,0.049446228871788504
0.0510371563157481,326.304532473222,0.1620429713025002,65.78299374660156,342.958187903595,0.04977744456747293
0.0513880477552605,326.425171493388,0.16315705162295208,65.80731457306703,343.1995237946093,0.050111241405610976
0.0517401277792811,326.534430292141,0.1642749056992175,65.82934114689563,343.42936343979113,0.05044605697358768
0.0520934121600408,326.640331332315,0.16539658360812953,65.8506907965947,343.65614074050154,0.05078190520242668
0.0524470783836103,326.765029417466,0.16651947386796268,65.87582993056115,343.9029005283466,0.05111800348942858
0.0527977927648418,326.942951234465,0.1676329920283727,65.91169896886814,344.204817419668,0.051451185048763705
0.0531499041805693,327.056260952288,0.16875094577330751,65.93454220798127,344.43926988355736,0.05178558216557653
0.0535017992254217,327.152811303541,0.16986821254071388,65.95400675879387,344.6560753299353,0.05211966211581833
0.0538512052466502,327.251011486637,0.17097757665811436,65.97380391570603,344.8738728733778,0.05245126866079575
0.054200136344033,327.368498022112,0.17208543289230477,65.99748920125779,345.11191524965176,0.05278231477308458
0.0545517815964803,327.446900649335,0.17320190656882495,66.01329517090593,345.3097124580019,0.053115825085715475
0.0549044460616283,327.537354730797,0.17432161624566986,66.03153071372869,345.5206117567825,0.053450190372664644
0.0552583342857377,327.582972514943,0.1754452113572172,66.0407272590125,345.68466191648935,0.05378560357464419
0.0556124063196412,327.672755679312,0.1765693900648608,66.0588275449493,345.8954261080264,0.054121078438559955
0.0559647264105771,327.761861201474,0.17768800635358228,66.07679121821715,346.10496409143605,0.05445478170588963
0.0563198220964994,327.849900745478,0.17881543515638557,66.09453999028837,346.3143488298183,0.05479100126448865
0.0566759735012763,327.925898544036,0.17994621586655224,66.10986114647766,346.51141808029996,0.055128106912206196
0.0570318610260091,328.017838386625,0.18107615875757888,66.1283962187436,346.72530615954287,0.05546484931556233
0.0573861126594211,328.125706965093,0.18220090769366198,66.15014252416275,346.955565751444,0.055799931254077284
0.0577405609030249,328.207851913835,0.18332628086710406,66.16670294582914,347.15875737611674,0.056135086827832754
0.0580963295187001,328.301023999643,0.1844558462218728,66.18548643832804,347.3741084712529,0.05647137798585031
0.0584526795288046,328.373471284553,0.18558725750395458,66.20009181096587,347.56778056731,0.056808105377418636
0.0588065745069706,328.444239311293,0.18671087405963163,66.21435864515668,347.7589199417379,0.05714240074610081
0.0591590130313762,328.524471990824,0.1878298663746194,66.23053355335011,347.95965551045515,0.05747520929571305
0.059510336846587,328.610405752787,0.1889453194879137,66.24785779976186,348.166121690429,0.05780685502273623
0.0598618723862097,328.663713880098,0.1900614448262158,66.25860471822776,348.33813917836613,0.05813859056339779
0.060212683648817,328.748198695416,0.19117527058499398,66.27563685699587,348.54300998358156,0.058469532949183785
0.0605611829088257,328.82657110698,0.1922817557355216,66.29143673516717,348.7406972250718,0.05879818587030943
0.0609071821418493,328.927020351806,0.1933803033003715,66.3116873029241,348.96103829174916,0.0591243743176993
0.0612589769065301,329.015409365013,0.19449725167823306,66.32950652798662,349.1705567291969,0.05945591741238437
0.0616121592587445,329.08718072846,0.19561860564651376,66.34397563485753,349.36295251751307,0.059788657680463785
0.0619649506182175,329.135867691115,0.19673871821284056,66.35379092652879,349.53075547927915,0.060120919090777485
0.0623196993033257,329.21928371825,0.19786504528805907,66.3706075975992,349.7361304844276,0.06045491264330721
0.0626760938724469,329.316449259699,0.19899659804501887,66.39019617075533,349.9567179472408,0.06079034349320095
0.0630337144825617,329.372503428458,0.2001320434821334,66.40149669117713,350.13407576797397,0.06112681520922082
0.0633949514557592,329.424016423545,0.20127897087203545,66.41188171098668,350.3078359530769,0.06146657452723506
0.0637526673118157,329.501985186102,0.20241471871501482,66.42760021351816,350.50861562625437,0.061802908363469425
0.0641108050262689,329.55005242779,0.20355180595840375,66.43729056944245,350.67777158538473,0.06213952555953557
0.0644744132521395,329.663975615064,0.2047062620755429,66.4602574839969,350.9188670132129,0.06248116866246142
0.0648360593771793,329.733860394189,0.2058544885225443,66.4743462554685,351.11250454537316,0.06282085245509365
0.0652010463960303,329.78134157206,0.2070133223073962,66.4839184609273,351.283430124445,0.06316355730416305
0.0655651026380317,329.852492109475,0.20816920087575064,66.49826240927017,351.4793046100433,0.06350527124185545
0.0659311998484911,329.935059193398,0.20933155951895926,66.51490793338903,351.68807351810165,0.06384878318098687
0.0662979834671519,330.012047651979,0.21049609750820727,66.53042880663897,351.8911809311709,0.06419282089058087
0.0666626580754474,330.077391904686,0.21165393938954546,66.5436022079847,352.08122821966356,0.06453476307624167
0.067020873789303,330.122758538922,0.21279127428103703,66.55274812144668,352.2478742739357,0.06487053519227612
0.0673818438426786,330.180385974242,0.21393735420050455,66.56436581240719,352.4285491818737,0.06520877506972292
0.067740139622099,330.246256790859,0.21507494330016433,66.57764536903717,352.6171843355473,0.06554439597153405
0.0680963182159011,330.303954508371,0.216205810335486,66.5892772288876,352.7964377025436,0.0658779220669398
0.0684537292900095,330.340042472411,0.21734059049578014,66.59655256243806,352.9530503134677,0.06621249047815922
0.0688075193925274,330.37631379846,0.21846387407127446,66.60386486176954,353.10868841697925,0.06654355913527117
0.069167685501004,330.449896570174,0.21960740146568766,66.61869914854708,353.3063510899791,0.06688048176286682
0.0695342625167808,330.480150386059,0.220771283490779,66.62479831782949,353.4598439195884,0.06722328504100138
0.0698999869196035,330.558528749192,0.2219324584697411,66.64059939583711,353.66456558492393,0.06756517393661154
0.0702686987544268,330.649883617244,0.2231031185453051,66.65901653723638,353.88422068233035,0.06790973727962206
0.0706405896226802,330.704206052988,0.22428387205200964,66.66996794028239,354.0653461592714,0.0682571512256617
0.0710106835173044,330.787451252719,0.22545892016744146,66.68675017254816,354.27689426512154,0.06860276668878555
0.0713844390768358,330.829433496287,0.22664559406895363,66.69521379285146,354.4455070365268,0.0689516804436589
0.071755487712591,330.876981230699,0.22782367348747642,66.70479941610893,354.6192203917776,0.06929794681182681
0.072125073592994,330.944314617846,0.22899710865775594,66.71837382695774,354.8136976648411,0.06964272897062307
0.0724948905833945,330.959491324794,0.23017127760227754,66.72143345107847,354.9523634359208,0.06998760778387991
0.0728630943513696,330.932575060569,0.23134032456559847,66.7160071322107,355.0453465011489,0.07033086403684655
0.073234149750388,330.952529030629,0.2325184254574819,66.72002985257481,355.1895561019277,0.07067665955355538
0.0736034287414261,330.966626782789,0.23369088625402784,66.72287195941026,355.3269053129861,0.07102068091630755
0.073971701060925,331.01124797113,0.23486015086843687,66.73186759097982,355.4967130538542,0.07136364663424528
0.0743374330601616,331.051334253102,0.2360213499660131,66.73994898542537,355.6608406526192,0.07170413022383759
0.0747026559775582,331.054047852971,0.23718093272874724,66.74049604715896,355.78466449970955,0.07204402422839863
0.0750688212357277,331.040333716552,0.2383435074234354,66.73773127725688,355.8911413501355,0.07238467928461449
0.0754324741800754,331.060765564475,0.23949810552173936,66.74185033779816,356.0334982149532,0.07272288224091035
0.0757958778519046,331.098376861883,0.2406519121797971,66.74943277535561,356.19426899147015,0.07306073914479759
0.0761664824889217,331.117752440442,0.2418285819023264,66.75333889199311,356.337826933468,0.07340517327386134
0.0765406190168727,331.10763546724,0.24301646537857083,66.75129931019559,356.4508188471156,0.0737527695924282
0.0769198277322443,331.126918520208,0.24422045304987564,66.75518677367393,356.59714405029126,0.07410495504339722
0.0772984099697209,331.186725950637,0.24542245165386384,66.76724395164842,356.786933269699,0.07445643497681192
0.07768071254482,331.251165501664,0.24663626232980346,66.78023496513546,356.9829920691353,0.07481124359200039
0.0780660803705428,331.294172693871,0.24785980517647338,66.7889052150844,357.15701020568326,0.0751687696531262
0.0784511726640562,331.299571114535,0.24908247320837842,66.78999353669026,357.29041097156914,0.07552591244627076
0.0788316225825458,331.295899264649,0.2502904016995829,66.78925329175324,357.41249255862493,0.07587862459256155
0.0792101896338593,331.306057883049,0.25149235208750326,66.79130126922267,357.5488735548117,0.07622946770695684
0.0795900889689831,331.268283588417,0.25269853247652135,66.78368597142487,357.6339557518214,0.07658142183889836
0.079972694865276,331.235673156316,0.2539133061972513,66.7771117083133,357.72548257414036,0.0769357582843678
0.0803565586696558,331.220271158,0.25513207377615715,66.7740066654528,357.8359923098871,0.07729113356597508
0.0807431765337252,331.215696027231,0.2563595854945775,66.77308431908976,357.9591034422984,0.07764893090581661
0.0811355789546378,331.23994423609,0.257605463180975,66.77797275799576,358.11528888458713,0.07801195073218355
0.0815312795517819,331.217978572459,0.2588618125769075,66.77354448020773,358.22260417602627,0.07837788837070934
0.0819306544757676,331.207440427062,0.2601298279605621,66.77141999009571,358.343482788495,0.0787470882371278
0.0823320717205063,331.204651809004,0.26140432771260746,66.77085780469521,358.47341695590825,0.0791180388102564
0.0827384743471767,331.174665261205,0.262694656052286,66.76481251665894,358.57555180735403,0.0794934562599849
0.0831503621616504,331.132765518701,0.26400239986324003,66.75636552857011,358.66657489516984,0.07987379694275333
0.0835687654550016,331.04372358519,0.26533083031963006,66.7384146747743,358.7086388768311,0.08026000602100344
0.0839911162485581,330.939614393616,0.26667179408917197,66.71742626175299,358.7356020174032,0.08064970764121383
0.0844216619082729,330.895720828035,0.26803877655876646,66.70857731893186,358.8304874986736,0.08104681438187668
0.0848637906791062,330.815380878177,0.26944253540616214,66.69238078504048,358.88962811445134,0.08145444056719756
0.0853145293286152,330.64203794917,0.27087363061835323,66.65743485055268,358.8506077930576,0.08186983376492231
0.0857769976285796,330.461423970581,0.2723419674707402,66.62102307246913,358.80741275084256,0.08229585754256302
0.0862472324561158,330.276812463392,0.2738349630481677,66.58380539261982,358.7622734827871,0.08272884979777802
0.0867244188295299,330.054812629524,0.27535002978375744,66.53905022611204,358.6786244367089,0.08316805146044348
0.0872109111410233,329.765210088158,0.276894642872749,66.48066635377266,358.52433452255724,0.08361561980611364
0.0877044844066783,329.392545393338,0.2784617379912036,66.40553715129695,358.2817487544641,0.0840694979432942
0.0882023429156073,328.938123106953,0.28004243875705315,66.31392561836172,357.9512362392488,0.08452710808667485
0.0887050392826396,328.489164061242,0.28163849972238075,66.22341547474637,357.6278082632159,0.0849889526098535
0.089206179754854,327.990977865083,0.2832296207216614,66.12298113760073,357.2497999944859,0.08544915546539546
0.0897079791644497,327.401593199272,0.28482283384712775,66.00416118897323,356.7721285003999,0.08590975132357825
0.0902148548361709,326.726017985752,0.28643216410484257,65.8679652259276,356.2015582695368,0.0863747913451334
0.0907238706098919,325.977194140879,0.28804828918640674,65.71700233880121,355.5511069238917,0.0868415773002126
0.0912390405405084,325.159561030178,0.28968395371611416,65.55216750368389,354.8268074011443,0.08731378508849037
0.0917577436858313,324.300954332719,0.2913308362025144,65.37907239347615,354.0580781774511,0.08778900626960494
0.0922816398629534,323.407232618615,0.292994206564877,65.1988980959128,353.2517823882004,0.08826875603155215
0.0928112151518526,322.402965524869,0.294675608107132,64.99643784981359,352.3255765237929,0.0887534725487953
0.0933497194921844,321.373616465816,0.29638535938768545,64.7889210795085,351.37375341508874,0.08924612095604617
0.0938936599867188,320.299812815002,0.2981123704578322,64.5724422635044,350.3739345332635,0.0897434963380921
0.0944431563194903,319.305006948341,0.2998570213143817,64.37188940078553,349.4611796331591,0.09024570088012232
0.0949909479097071,318.216175190371,0.30159625961332,64.1523809183788,348.4438313119058,0.09074609648516843
0.0955420298067774,317.187427523978,0.3033459446365182,63.94498538883397,347.49215817880895,0.09124924518395755
0.0961029177743337,316.164073731691,0.3051267639335095,63.73867726430891,346.54836371272614,0.09176108719597736
0.0966691935589986,315.119245761734,0.30692468954982055,63.52803994556558,345.5815691244407,0.09227758026365776
0.0972373980825935,314.035412343205,0.30872873891223435,63.30953912839013,344.5713987452526,0.09279556451919926
0.0978096465023555,312.936084400771,0.31054562764497873,63.08791461519543,343.54425219384166,0.0933169642168848
0.0980936292394979,312.352533588431,0.3114472728354058,62.9702707714277,342.9923272102724,0.09357561198326203
0.0983834010213826,311.856209814591,0.3123672982428897,62.87021189862155,342.5376843657884,0.09383946339584112
0.0986787764212845,311.271506132234,0.3133051151375783,62.752335636258366,341.98739749217316,0.09410834554648208