File: example/data/02 processed data/test_ID_153.csv
Strain,Stress_MPa,Displacement(mm),Force(kN),True Stress (MPa),True Strain
-3.99248481961007e-05,0.0713597934827117,-0.0001267613930226197,0.014386134366114679,0.0713569444537896,-3.9925645214114634e-05
-5.88520509449852e-05,0.0509382442515827,-0.000186855261750328,0.010269150041119073,0.05093524643143695,-5.885378279492327e-05
-0.0001317794477659,0.0772394210560117,-0.00041839974665673244,0.015571467284891958,0.07722924248775918,-0.00013178813144020012
-0.0001439770019714,0.259897188498285,-0.000457126981259195,0.05239527320125426,0.2598597692802642,-0.00014398736765494733
-0.0001592832985861,0.660183060586067,-0.0005057244730108675,0.1330929050141511,0.6600779044505062,-0.00015929598551788784
-0.0001897535868571,1.36106841562557,-0.0006024676382712925,0.2743913925901149,1.360810148011747,-0.00018977159234676927
-0.0002407228603651,2.32605837885021,-0.0007642950816591924,0.4689333691762023,2.325498443423877,-0.00024075183876349213
-0.0002651777368047,3.50588080442323,-0.0008419393143549225,0.7067855701717233,3.5049511228860064,-0.0002652129026376613
-0.0002808067322567,4.88424884491996,-0.0008915613749150226,0.984664567135864,4.88287731496229,-0.0002808461658494807
-0.0002473348687596,6.42768448797583,-0.0007852882083117299,1.2958211927759273,6.426094697476568,-0.00024736546107272773
-0.000237108749693,8.02244011483551,-0.000752820280275275,1.6173239271508388,8.020537924090394,-0.00023713686441680323
-0.0002344144291875,9.63529111468956,-0.0007442658126703125,1.9424746887214153,9.633032463422854,-0.00023444190854424082
-0.0002175904210902,11.2468391880163,-0.0006908495869613849,2.267362780304086,11.244391983541448,-0.00021761409732037047
-0.0001919865669866,12.8297783899617,-0.000609557350182455,2.5864833234162785,12.827315244853413,-0.00019200499876669385
-0.0001730858610291,14.4269129890884,-0.0005495476087673925,2.9084656586002215,14.424415894431691,-0.00017310084211549933
-0.0001460433642473,16.0976714280328,-0.00046368768148517743,3.245290559891413,16.0953204699409,-0.00014605402961782095
-0.0001111834106479,17.8528558061754,-0.0003530073288070825,3.59913573052496,17.850870864777065,-0.00011118959198144414
-0.0001474699680799,19.6513066272937,-0.00046821714865368246,3.96170341606241,19.648408649732644,-0.00014748084284479525
-0.0001240647526821,21.4813417747707,-0.0003939055897656675,4.330638501793774,21.478676697416134,-0.0001240724493501439
-9.31139443481573e-05,23.2236611412615,-0.0002956367733053994,4.681890086078318,23.22149869457043,-9.311827972062931e-05
-5.4144552390111e-05,25.0300361519173,-0.00017190895383860242,5.046055288226528,25.02868091181355,-5.414601825924589e-05
1.39444040280491e-05,26.8846820087013,4.427348278905589e-05,5.419951892954182,26.8850568995694,1.3944306805834194e-05
6.28775096839249e-05,28.6889351859468,0.00019963609324646152,5.783689333486875,28.69073907474678,6.287553297628178e-05
0.0001186938802473,30.5527345073716,0.0003768530697851775,6.1594312766861155,30.556360929982446,0.00011868683668606468
0.0002339116540478,32.3682834518221,0.000742669501601765,6.525445943887336,32.375854770543,0.00023388430098217035
0.0002876905537562,34.1683539162278,0.0009134175081759351,6.888340149511524,34.178183828886894,0.0002876491787640161
0.0003363653879558,35.9734785571368,0.0010679601067596649,7.252253277118779,35.98557879020779,0.00033630882980112474
0.0003717747033044,37.7630073135656,0.00118038468299147,7.613022274414825,37.77704664440548,0.00037170561221296945
0.0003947713236194,39.4873496340949,0.001253398952491595,7.960649686233531,39.502938107376174,0.00039469342192201203
0.0004464560550028,41.2328198741773,0.00141749797463389,8.312536486634144,41.25122851627497,0.00044635642315135447
0.0004720338683923,42.8482065002188,0.0014987075321455524,8.638198430444112,42.868432304886774,0.0004719224954523743
0.0004961154508375,44.4283712326967,0.0015751665564090625,8.956759640511654,44.45041283412079,0.0004959924262552444
0.0005391815417952,46.0076613896995,0.00171190139519976,9.27514453616342,46.03246787150199,0.0005390362356562923
0.0006000737409569,47.5716537393862,0.0019052341275381573,9.590445393860259,47.600200239609094,0.0005998937687036869
0.0006554071907448,49.0353410436131,0.00208091783061474,9.885524754392401,49.067479158733704,0.0006551925052510661
0.0007112928338897,50.5086621573727,0.0022583547475997973,10.182546290926336,50.54458860681459,0.000711039985034553
0.0007241322882745,51.9216774852283,0.0022991200152715375,10.467410181022027,51.95927564835673,0.0007238702309908388
0.0007664534435171,53.3466362437021,0.0024334896831667923,10.754681866730344,53.38752395675113,0.0007661598680748235
0.0008145610276949,54.7960796127392,0.0025862312629313074,11.046889649928223,54.8407143636622,0.0008142294529073009
0.000867250781293,56.1335584937049,0.002753521230605275,11.31652539233091,56.182240366165324,0.0008668749366195502
0.0008896355984511,57.4633265866154,0.0028245930250822425,11.584606639861665,57.514448007552275,0.0008892401072467609
0.000938040845643,58.7860278332196,0.002978279684916525,11.851263211177072,58.84117152848027,0.0009376011602693363
0.0009787179876868,60.1030290851023,0.0031074296109055897,12.116770663556624,60.16185300078235,0.0009782393555088963
0.0010621585041462,61.3904704240005,0.0033723532506641845,12.3763188374785,61.45567683423488,0.0010615948129198268
0.0011277258440419,62.6453931580635,0.003580529554833032,12.629311260665602,62.71603998693801,0.001127090438915855
0.001167500979784,63.8499958006792,0.0037068156108141996,12.872159153416929,63.924540733335704,0.0011668199805084654
0.0011989791562916,65.0840480667906,0.00380675882122583,13.120944090264986,65.16208248382976,0.0011982609547981165
0.0012517312465572,66.2987959975855,0.00397424670781911,13.365837273113236,66.3817842721448,0.001250948484137755
0.0012921909482145,67.4837625607321,0.004102706260581037,13.604726532243593,67.57096446786453,0.0012913567880099488
0.0013310490583877,68.6386480997049,0.0042260807603809476,13.837551456900508,68.73000950762702,0.0013301639978754388
0.0013668720343533,69.8161427180764,0.004339818709071727,14.074934371964204,69.91157245110416,0.0013659387151626862
0.0014105624576038,70.9253018877891,0.004478535802892065,14.298540860578285,71.02534645592623,0.001409568548917407
0.0014789666773003,72.0393857419792,0.004695719200428453,14.523140165583007,72.14592959294477,0.001477874083224835
0.0015126776666555,73.1446435285268,0.004802751591631212,14.745960135351003,73.25528779722788,0.0015115347222529549
0.001554891574914,74.2673654594001,0.00493678075035195,14.972300876615058,74.38284316024398,0.0015536839826303971
0.0016168398321146,75.3521519812235,0.0051334664669638545,15.190993839414658,75.47398434198229,0.001615534153785582
0.0016697615677461,76.3520128600477,0.0053014929775938675,15.392565792585616,76.47950251674146,0.0016683690657815684
0.0017196871597708,77.3313343895831,0.00546000673227229,15.589997012939955,77.46432009238082,0.0017182101908477057
0.001778606582432,78.3402575366354,0.0056470758992216,15.793395919385699,78.47959403435948,0.00177702673475196
0.0018331952023266,79.29841344522,0.005820394767386955,15.986560150556354,79.44378291629988,0.0018315169507304076
0.0019473015951918,80.1653718620345,0.0061826825647339646,16.161338967386158,80.32147801854059,0.0019454080612298485
0.0020344025284618,81.0167206023187,0.006459228027866215,16.33297087342745,81.18154122355973,0.0020323359340198347
0.0021045248925591,81.8527084077288,0.006681866533875142,16.501506014998128,82.02496947009624,0.002102313482149359
0.0022149097975515,82.7132040919228,0.007032338607226012,16.674981944931638,82.89640637805287,0.0022124605008265953
0.0023211839828751,83.5236207015267,0.007369759145628442,16.838361933427784,83.71749439209083,0.0023184941968553492
0.0024230364821806,84.212648536972,0.007693140830923405,16.977269945053553,84.41669885663813,0.0024201056626507278
0.0025380507498223,84.8416917755256,0.008058311130685803,17.104085061945963,85.05702429495267,0.002534835338453609
0.0026382023020881,85.4475589281769,0.008376292309129717,17.226227879920465,85.67298687484903,0.0026347283550367507
0.0027573826711107,85.9389358805826,0.008754689980776472,17.325289473525455,86.17590241315342,0.0027535880653661625
0.0028750598329003,86.386324277676,0.009128314969458453,17.415482974379483,86.63469012871865,0.002870934753055153
0.0029986354043598,86.7514526034635,0.009520667408842364,17.48909284485824,87.0115885806199,0.0029941484647751228
0.0031555577628243,87.0500257965718,0.010018895896967151,17.549285200588876,87.32471718122824,0.0031505894395706256
0.0033039365037598,87.3488504053051,0.010489998399437364,17.60952824170951,87.63744546072063,0.003298490497757731
0.0034454751809337,87.6529649532843,0.010939383699464495,17.670837734582115,87.95497106856608,0.0034395531302762617
0.003599491166018,87.9211509918734,0.011428384452107148,17.72490403996168,88.23762239817479,0.0035930285012511307
0.003754184879883,88.1788418432893,0.011919536993628525,17.776854515607123,88.50988151806298,0.003747155515356541
0.0039216701540007,88.4008238104211,0.012451302738952221,17.821606080180896,88.74750268274751,0.00391400045109295
0.0040649677782701,88.6021719793042,0.012906272696007567,17.86219787102773,88.96233695348481,0.00405672811850418
0.0042029738300213,88.7852254628682,0.013344441910317629,17.89910145331423,89.15838744198118,0.004194166006257354
0.0043548854076905,88.9470472581214,0.013826761169417336,17.931724727237274,89.33440145628295,0.00434543033480047
0.0045234925352544,89.0755701656514,0.01436208879943272,17.957634945395323,89.47850284236925,0.004513292291812034
0.0046863179366139,89.2053854758429,0.014879059448749132,17.98380571192993,89.6234302738409,0.004675371334893837
0.0048599177050148,89.287552943384,0.015430238713421989,18.000370673386215,89.721483102771,0.004848146427851419
0.0050284082803264,89.3755633926148,0.01596519629003632,18.018113579951144,89.82498021563705,0.005015808057134971
0.0052244593405305,89.4410370534303,0.016587658406184338,18.03131306997155,89.90831811489083,0.005210859201180863
0.0053996335769472,89.508263430488,0.01714383660680736,18.04486590758638,89.9915752551215,0.005385107821275662
0.0055756006275062,89.5620627463973,0.017702531992332182,18.055711849673695,90.06142503964688,0.005560114502626196
0.0057562929838445,89.5878358815853,0.018276230223706287,18.060907713727598,90.10352971270828,0.005739788834245112
0.0059315274538837,89.6243090674931,0.018832599666080748,18.068260708006612,90.15591811726229,0.005914005199927821
0.0061062385109029,89.6752817949973,0.019387307272116707,18.07853680987146,90.22286045416999,0.006087670983357798
0.0062920506042425,89.7192483330686,0.019977260668469936,18.087400463946633,90.28376638375488,0.0062723382978478286
0.0064642337195605,89.7711806244746,0.02052394205960459,18.097870013894077,90.35148251731208,0.006443430165332145
0.0066332456456726,89.8012292170025,0.021060554925010504,18.103927810147706,90.39690282968223,0.0066113424778174576
0.0068101982597804,89.8358775833313,0.02162237947480277,18.11091292079959,90.44767772051514,0.006787113607718306
0.0069818943252894,89.8847287901701,0.022167514482793846,18.120761324098293,90.51229446804038,0.006957633758787909
0.0071704838427396,89.9077677843456,0.02276628620069823,18.125405985324072,90.55244998058002,0.00714489815848809
0.0073575782710626,89.9298760653363,0.023360311010623754,18.1298630147718,90.59154216739398,0.007330643328664275
0.0075459853540796,89.9363899942969,0.023958503499202727,18.131176222850257,90.61504867599265,0.007517656828434027
0.0077362285945949,89.944092103681,0.024562525787838806,18.13272896810209,90.63992016092838,0.007706457423967271
0.0079291393264993,89.9649481540927,0.025175017361635275,18.136933547865087,90.67829276250778,0.0078978688909334
0.0081227845470335,89.9830705169719,0.02578984093683136,18.140587016221538,90.71398361166179,0.00808997229743464
0.00831917213147,89.9931674078778,0.026413371517417246,18.142622549428165,90.74183605820014,0.008284758548937598
0.0085002506774685,89.9980012086873,0.026988295900962488,18.14359704367136,90.76300677943226,0.008464326976767347
0.0086883064522748,89.9956931044146,0.02758537298597249,18.143131729849983,90.77760326549061,0.008650780320145993
0.0088732544228492,89.9957500239864,0.02817258279254621,18.14314320483566,90.79430521092436,0.008834118439466899
0.0090757453679227,89.989601646902,0.028815491543154572,18.141903692015443,90.80632435721007,0.00903480829414028
0.0092654279285435,89.9666146152916,0.029417733673125612,18.137269506442788,90.80019379898464,0.00922276716223347
0.0094676295646962,89.9451910736219,0.03005972386791043,18.132950520442176,90.79675882383277,0.009423092446528345
0.0096665323537875,89.9395974747154,0.03069124022327531,18.131822850902626,90.80900150359136,0.009620110350029696
0.0098617485588704,89.932414005836,0.03131105167441352,18.130374663576536,90.81930486005378,0.009813438868908078
0.0100484087118872,89.9011921195417,0.031903697660241856,18.12408033129961,90.80455604164476,0.00999825912230042
0.010214290347589,89.8838391716652,0.032430371853595076,18.120581977007706,90.80193880252058,0.01016247700956009
0.0103868278880824,89.8703230876808,0.03297817854466162,18.117857134476452,90.80379066583889,0.01033325543718294
0.0105814594161214,89.8651429688064,0.03359613364618544,18.11681282251137,90.81604733205477,0.010525867592320071
0.0107631825590541,89.8636591975408,0.034173104624996765,18.116513694224224,90.83087816690856,0.01070567180744379
0.0109384923074084,89.8487747138843,0.03472971307602167,18.113512982319072,90.8315848449222,0.010879099718171834
0.0111276054649218,89.8371554120804,0.03533014735112671,18.111170531075413,90.83682783359691,0.01106614915070332
0.0113226996861332,89.827701993806,0.03594957150347291,18.10926472195129,90.84479408697734,0.011259077719894556
0.011541235042805,89.8191929400312,0.03664342126090587,18.10754929671029,90.85581735710716,0.011475143025889718
0.011737204732936,89.7951475484052,0.03726562502707179,18.102701745758488,90.84909157920502,0.011668858025161462
0.0119459081851627,89.7706221402697,0.03792825848789157,18.09775742347837,90.84301375008229,0.01187511902683148
0.0121487912104537,89.7456827829847,0.0385724120931905,18.092729649049716,90.83598434515478,0.012075586945680285
0.012359599271296,89.7184317561351,0.039241727686364795,18.087235842036836,90.82731561989004,0.012283842996971852
0.0125715279603603,89.6931597321001,0.03991460127414395,18.08214100199138,90.82073979752525,0.012493162402444975
0.0127787625714198,89.680027651941,0.04057257116425786,18.079493574631307,90.82602743270351,0.012697803162862115
0.0129867769689563,89.6564638249119,0.041233016876436254,18.07474310710224,90.82081232443132,0.012903171843696506
0.0131785721141948,89.6321722874124,0.04184196646256849,18.06984593314234,90.813396333654,0.013092490199079727
0.0133608389815747,89.5971706288075,0.04242066376649967,18.062789598767594,90.79426399878368,0.013272370113453351
0.0135587579570523,89.5630016691356,0.04304905651364105,18.055901136497738,90.77736473067448,0.013467660520044169
0.0137558041568067,89.5280905814537,0.04367467819786127,18.048863061221066,90.75962146202502,0.01366205186321048
0.0139498859670031,89.4821196144074,0.044290887945234836,18.03959531426453,90.7303849791141,0.013853481824406925
0.0141505079054709,89.448108841106,0.044927862599870104,18.03273874236697,90.7138450123915,0.014051324041417824
0.0143550772710462,89.4189529632575,0.04557737033557168,18.026860917392714,90.70256894254109,0.014253018695614132
0.0145724168577241,89.3961915927297,0.046267423523274016,18.02227222509431,90.69891016211194,0.014467259557486484
0.0147644530979738,89.3800984594959,0.04687713858606681,18.019027849434373,90.69974673109341,0.01465651964896363
0.0149600293521143,89.3454434317008,0.0474980931929629,18.01204139583088,90.68205388791672,0.014849231769684335
0.0151640765384717,89.3216990883154,0.04814594300964765,18.007254536204385,90.67618016983695,0.015050251191553576
0.0153762450890771,89.2981951362973,0.04881957815781979,18.002516139477535,90.67126607072524,0.0152592286239322
0.0155757084375907,89.2541285667698,0.04945287428935047,17.99363231906079,90.64432485017703,0.015455652127509987
0.0157533799182392,89.213755092304,0.05001698124040946,17.985493026608484,90.6191732702058,0.015630583390120318
0.0159342778654317,89.1602586854676,0.05059133222274564,17.974708150990267,90.58096302191561,0.015808659923663697
0.016158019354663,89.1104296191504,0.05130171145105502,17.96466261122072,90.55027766563897,0.016028867923508626
0.0163631039534381,89.0753594068634,0.051952855052165965,17.95759245642366,90.53290877252778,0.016230671090146632
0.0165577267245657,89.0334368443597,0.0525707823504961,17.949140867822916,90.50762816097749,0.016422142168395423
0.016747389835543,89.0054267856381,0.05317296272784902,17.94349403998464,90.49603536549606,0.016608698637449293
0.0169386563186273,88.9804015173291,0.05378023381164168,17.938448945893548,90.4876099577246,0.016796796976433277
0.0171488905503831,88.9400570343156,0.05444772749746634,17.930315498118027,90.46528033794192,0.017003508071860823
0.0173622717666174,88.9112639249137,0.055125212859010245,17.924510807262603,90.45496545229149,0.017213269729568853
0.0175478309479696,88.8835877839218,0.05571436325980347,17.918931297238636,90.44330195640306,0.017395645532430115
0.0177529761121506,88.8475879374199,0.056365699156078156,17.911673728183853,90.42489704369513,0.01759723260414377
0.0179525107992255,88.797264734161,0.05699922178754096,17.90152857040686,90.39139858824272,0.017793267530607167
0.0181579476928372,88.7490211906626,0.057651483924758114,17.89180267203758,90.36052127523317,0.017995060997608968
0.0183617597764973,88.708262461392,0.05829858729037892,17.88358571221663,90.33710226689855,0.018195218239979834
0.0185639341526722,88.6702833149679,0.058940490934734226,17.87592911629753,90.31635261572576,0.018393727569447602
0.0187686732597417,88.6384365643638,0.059590537599679895,17.86950881137574,90.30206241849469,0.018594714985065194
0.0189797984703067,88.6005704908582,0.060260860143223766,17.861875010957014,90.28219146312888,0.01880192918666995
0.0191768255554829,88.5703294194817,0.060886421138658206,17.85577841096751,90.26882717615075,0.018995267699978995
0.0194013437348101,88.5456551291366,0.06159926635802206,17.85080407403394,90.26355982052094,0.019215537085393992
0.0195946459081264,88.5075027376752,0.06221300075830132,17.84311255191532,90.24177591403247,0.019405142337073973
0.0197976233068459,88.4700597454702,0.06285745399923573,17.83556404468679,90.22155666224518,0.019604199087904853
0.0200087898631662,88.4279712248853,0.06352790781555269,17.827078998936877,90.19730791915013,0.019811244771957233
0.0202141017566168,88.390413768047,0.06417977307725833,17.819507415638274,90.17714658626377,0.020012508952441634
0.0204286354855859,88.3658042940823,0.06486091766673523,17.81454614568699,90.17099709939671,0.020222769892138757
0.0206592339599954,88.3152051872727,0.0655930678229854,17.804345365754177,90.13972967346156,0.02044872633315499
0.0208607245466515,88.2629214487855,0.06623280043561851,17.793804964075157,90.10414994081135,0.02064611905172308
0.0210820025339008,88.2282870465164,0.06693535804513503,17.786822668577706,90.08831601759279,0.020862851857380186
0.021287800939728,88.1852603694182,0.06758876798363639,17.77814849047471,90.06253063798046,0.021064380891126694
0.021510925519138,88.1534088181799,0.06829718852326315,17.771727217745067,90.04967022952589,0.021282830782843692
0.021725192419404,88.1080766795034,0.06897748593160768,17.762588258587886,90.0222415990692,0.021492563666058045
0.0219359354145107,88.0590246278899,0.06964659494107146,17.752699364982604,89.99068170479211,0.021698804312301763
0.0221307187273539,88.0222933492535,0.07026503195934863,17.745294339209508,89.97028996510247,0.02188938842367402
0.0223402626081265,87.9856931420046,0.07093033378080163,17.73791573742813,89.95131663255503,0.0220943743426912
0.0225570767808282,87.9444475627484,0.07161871877912952,17.729600628650076,89.92821721886884,0.022306428189442194
0.0227910475939459,87.8971930437214,0.07236157611077823,17.720074117614235,89.9004621537551,0.022535211555315092
0.0229991971836425,87.8370040367631,0.07302245105806493,17.70794001381144,89.85718461262502,0.022738702202458643
0.0232277657465102,87.7779210052314,0.07374815624516988,17.69602887465465,89.81680599205659,0.02296210710128855
0.023450552127636,87.7206896267911,0.0744555030052443,17.684491028761087,89.77778823155634,0.023179812424162415
0.0236738803037388,87.6770326592589,0.07516456996437068,17.675689784106595,89.7526882358212,0.023397999627100097
0.0239084622427287,87.6346629653719,0.07590936762066362,17.667148053818977,89.72987299603376,0.023627130280497437
0.0241214573257484,87.5839151327251,0.07658562700925116,17.656917290757377,89.6965668040211,0.023835130253302948
0.0243497661218938,87.5409346793231,0.0773105074370128,17.648252431351537,89.6725359648566,0.024058036774495396
0.0245785847233462,87.5022726544101,0.07803700649662418,17.64045816712908,89.65295467633186,0.024281391195170147
0.0248023168288663,87.4569420638209,0.0787473559316505,17.631319520066295,89.6260768497716,0.02449973235980132
0.0250039659986431,87.4085874646086,0.07938759204569183,17.621571232865094,89.59414881356311,0.024696481849854866
0.0252316656159869,87.3573563472681,0.0801105383307584,17.61124303960925,89.56152795171899,0.024918602287885366
0.025436393990282,87.2985461231125,0.08076055091914534,17.59938689841948,89.5191063370788,0.02511827221887796
0.0256583288675292,87.2324497559269,0.0814651941544052,17.586061870794865,89.47068863968468,0.02533467848782307
0.0258861957171882,87.1786279692967,0.08218867140207252,17.575211398610215,89.43535099526584,0.025556820242842584
0.0260842345798698,87.1273766799101,0.0828174447910866,17.564879138669877,89.40002761155755,0.025749843358938724
0.0262957975929833,87.0734408977638,0.08348915735772197,17.554005684989185,89.363106475336,0.02595600694516209
0.0265327553204386,87.0077237494066,0.08424149814239255,17.54075710788037,89.31627839463792,0.026186866680790146
0.0267530104436272,86.9522526869096,0.08494080815851636,17.529574141680975,89.27848721113939,0.026401405862530695
0.0269765699229428,86.917648057955,0.0856506095053434,17.52259784848373,89.26238806832815,0.026619116589722682
0.0271825320319749,86.8802013440857,0.0863045392015203,17.51504859096768,89.24182520006575,0.026819648388380746
0.0273898474453707,86.8303914959426,0.08696276563905198,17.50500692558203,89.20866267263828,0.027021457208717403
0.0276202436481728,86.7688820331054,0.08769427358294864,17.49260661787405,89.16545969593933,0.0272456859896523
0.0278452775573679,86.7219299383965,0.08840875624464307,17.483141075580733,89.13672614784176,0.027464647492798557
0.0280549279808785,86.690165689897,0.08907439633928924,17.476737403083234,89.1222520449775,0.027668597493555092
0.0282759086525172,86.650499597483,0.08977600997174211,17.468740718852573,89.10062120879643,0.027883524652699502
0.0284962675354627,86.6007451208245,0.09047564942509408,17.45871021635822,89.06854312255794,0.028097801067306607
0.0287405258480506,86.5561079638644,0.09125116956756066,17.449711365515064,89.04377602210651,0.0283352635845251
0.0289721897335223,86.5053928443342,0.0919867024039333,17.439487197417776,89.01164349879312,0.02856042998865541
0.029216175382936,86.4687231451686,0.09276135684082179,17.43209458606599,88.99500852571639,0.028797517764188464
0.0294447200297999,86.4248760287373,0.09348698609461467,17.42325500739344,88.96963230701363,0.02901955010405745
0.0296857170445469,86.3786623403743,0.09425215161643641,17.413938327819462,88.94287486929711,0.029253626597229784
0.0299211360351867,86.3242200053137,0.09499960691171777,17.402962753071243,88.90713873522408,0.029482232354016022
0.0301790334972114,86.2636879328375,0.09581843135364619,17.39075948726004,88.8670426605556,0.02973260606611607
0.0304236757569215,86.2100222997357,0.09659517052822575,17.37994049562672,88.83284806517982,0.029970053352544206
0.0306533442670981,86.1606811623741,0.09732436804803646,17.36999332233462,88.80179418433204,0.030192915971355726
0.0308855240429248,86.1043519591464,0.09806153883628624,17.358637354963914,88.76372999178108,0.030418164964112957
0.0311110940091198,86.0528928664112,0.09877772347895536,17.348263201868498,88.73009250613482,0.030636952875906648
0.0313561984193588,85.9940551832534,0.09955592998146419,17.336401524943884,88.69050184046479,0.030874633650087014
0.0315842614177624,85.9205900145607,0.10028003000139563,17.321590946935437,88.63432839074898,0.031095738431124294
0.0318005949346413,85.8663514797141,0.10096688891748613,17.310656458310362,88.59695254163603,0.031305426427045806
0.0320275253775121,85.8075994261099,0.1016873930736009,17.298812044303755,88.55580449431304,0.031525338581117085
0.0322616949413727,85.7494148324894,0.10243088143885833,17.287082030229865,88.5158362952164,0.031752215282850625
0.0325053011904475,85.6851130580881,0.1032043312796708,17.274118792510563,88.4703334655788,0.03198818016475877
0.0327544913085098,85.6274993802822,0.1039955099045186,17.262503875064894,88.43218456450309,0.03222949616788503
0.0329889528980484,85.5693813387763,0.10473992545130367,17.250787277897302,88.39222562927634,0.03245649588675429
0.0332369105567506,85.5196695205221,0.10552719101768314,17.240765375337254,88.36207912721855,0.03269650610468633
0.0334917612885891,85.453471573793,0.10633634209127038,17.22741986927667,88.3154588450237,0.032943128447137
0.0337459319496647,85.3846055377742,0.10714333394018542,17.21353647641528,88.2659886258009,0.03318903211190457
0.0339878298232679,85.3328973593634,0.10791135968887558,17.203112107647662,88.23317735313982,0.03342300602013085
0.0342190017116075,85.2829555328726,0.10864533043435382,17.19304383542712,88.20125313422292,0.03364655415446401
0.0344547811982645,85.2133416299748,0.10939393030448978,17.179009672602923,88.14934867100855,0.03387450646828538
0.0346869590700465,85.1205197099203,0.11013109504739763,17.160296773519935,88.0730916931194,0.03409892596380658
0.0349222958902389,85.0458474397376,0.11087828945150852,17.1452428438511,88.01584368826423,0.03432634746440401
0.0351479031786111,84.9397763321963,0.11159459259209023,17.123858908570778,87.92523136673321,0.03454431812971468
0.035380122553906,84.8713644174094,0.11233188910865154,17.110067066549735,87.87412369181456,0.03476862745891254
0.0356169598357817,84.7377477711463,0.11308384747860688,17.083129950663096,87.75584873008582,0.03499734558210245
0.0358652670804192,84.6418449072598,0.11387222298033095,17.063795933303574,87.67754728103809,0.03523708429923976
0.0361074129329268,84.5671023945726,0.11464103606204257,17.048727842745837,87.62060168127454,0.03547081890003435
0.0363644022160513,84.5198719099911,0.11545697703596287,17.039206177054204,87.59338652737515,0.03571882158220646
0.0365992340328065,84.4739446803191,0.11620256805416064,17.02994724755233,87.56562635134844,0.03594538785057073
0.0368607657400126,84.4557328254868,0.11703293122453999,17.026275737618143,87.56883580856817,0.03619765382977622
0.0371026885132621,84.4005063451388,0.11780103602960716,17.01514207917998,87.53199204242408,0.03643094894773082
0.0373556944645826,84.3938716028234,0.11860432992504975,17.0138045151292,87.54646328510168,0.03667487377615922
0.0375966918058169,84.3546337207264,0.11936949648346866,17.005894158098442,87.52608888711711,0.03690716570142227
0.0378575081972853,84.2968384319571,0.12019758852638081,16.994242627882553,87.48810668390016,0.037158499980772926
0.0380868437695345,84.2332775345864,0.12092572896827203,16.981428750972622,87.44145721624204,0.03737944576187232
0.0383531462594853,84.1598249382387,0.12177123937386582,16.966620707548923,87.38761901326764,0.03763594485906709
0.0385857297507738,84.0885253246933,0.12250969195870681,16.95224670545817,87.33314243801301,0.037859912444196654
0.0388528738110877,84.0145792168936,0.12335787435020344,16.93733917012575,87.27878706149919,0.03811709844365596
0.0390950219555027,83.9403899186597,0.12412669470872106,16.922382607601797,87.22204130548316,0.038350163137919446
0.0393865488094339,83.8648714702387,0.12505229246995264,16.907158088400124,87.16801932379815,0.0386306822052457
0.0396393262804866,83.7958078419921,0.12585486094054496,16.893234860945608,87.11741720997779,0.038873851350302586
0.0399090637211512,83.7271401800633,0.12671127731465506,16.879391460300763,87.06861195269921,0.03913327060063043
0.0401647399718231,83.6440278789052,0.12752304941053832,16.862636020387292,87.00356850885734,0.03937910442778166
0.0404564804011886,83.5708028044721,0.12844932527377378,16.847873845381574,86.95178335024282,0.03965954031723713
0.0407155324520383,83.4756777371516,0.1292718155352216,16.828696631809763,86.87443440301449,0.039908488554660705
0.040999271213263,83.3769760566072,0.13017268610211002,16.808798373012014,86.79537131089377,0.04018108954926589
0.041244116613379,83.2962571608933,0.13095007024747832,16.79252544363609,86.73173770469519,0.04041626417167166
0.0415211533709195,83.2162838021089,0.1318296619526694,16.776402814505154,86.67151988481423,0.04068229199839489
0.0418028928792198,83.1370810936695,0.13272418489152288,16.76043554848377,86.61245158891917,0.04095276313371828
0.0420652350000833,83.058629817401,0.13355712112526447,16.74461977118804,86.5525105994549,0.04120454693782736
0.042314095825288,82.9744839725351,0.1343472542452894,16.727655968863075,86.48547423840276,0.04144333344151852
0.0425853324212324,82.9179847924544,0.13520843043741287,16.716265734158807,86.44907473853976,0.04170352498246289
0.0428553248787976,82.8660580679076,0.13606565649018237,16.705797306490172,86.41730990783309,0.04196245583060615
0.0431202639976756,82.7894980069603,0.13690683819262003,16.690362798203196,86.35940301725546,0.042216475217712546
0.0433875442838668,82.7086500727007,0.13775545310127707,16.674063854656463,86.29717529038885,0.042472673911618485
0.0436588653249049,82.6310774063166,0.13861689740657304,16.658425205113428,86.23865648645076,0.04273267871200763
0.0439522976503788,82.557037928527,0.13954854503995268,16.643498846391044,86.18560943269523,0.0430137965107726
0.0442392151440855,82.4852784705182,0.14045950808247146,16.62903213965647,86.13436245099525,0.043288596493201784
0.0445143904409137,82.3976574512367,0.141333189649901,16.611367742169318,86.06553894643771,0.04355207926846486
0.0447952871188739,82.2952231446752,0.14222503660242464,16.590716985966523,85.98166129395273,0.04382096873245344
0.04508573320145,82.1825237999125,0.14314720291460373,16.56799679806236,85.88778314177718,0.04409892339266808
0.0453347923177099,82.0761190873866,0.14393796560872893,16.546545608017137,85.7970229004569,0.04433720953117262
0.0456084770732827,81.9736106446466,0.14480691470767257,16.525879905960757,85.71230218634717,0.04459899067190681
0.0458776958152128,81.8847235870987,0.14566168421330064,16.5079602751591,85.64140602774039,0.04485643319952829
0.0461434280549231,81.7770181059853,0.14650538407438085,16.486246850166637,85.55049005750499,0.045110476753971895
0.0464094657353986,81.6821721947624,0.14735005370989054,16.4671259144641,85.47299816642816,0.04536474768083672
0.0466730434006681,81.6013301557441,0.1481869127971212,16.450828159398007,85.40991257965538,0.045616603654514094
0.046922951111759,81.4945319788596,0.14898036977983484,16.429297646938096,85.3184959187793,0.04585533902937428
0.04722688830677,81.4001977339302,0.14994537037399475,16.41027986316033,85.24447578045951,0.04614561166548074
0.0475014239270835,81.3055784220245,0.15081702096849012,16.391204609880138,85.1677091702858,0.046407732170829386
0.0477780757736566,81.2063733160148,0.1516953905813597,16.371204860508584,85.0862575736112,0.04667180371662581
0.0480677946266038,81.1103834464972,0.15261524793946707,16.351853302813833,85.00918070008849,0.04694827333577507
0.0483641374736547,81.0127652550212,0.15355613647885366,16.332173475412272,84.93087777093596,0.047230984970231
0.0486687424609814,80.9144285008632,0.15452325731361594,16.31234878577402,84.85243198294918,0.04752149542658429
0.0489827657923636,80.86037157698,0.15552028139075444,16.30145090991917,84.82113621981871,0.0478209001012813
0.0492890221169983,80.7733851952866,0.1564926452214696,16.28391445536978,84.75462636464191,0.048112813025597626
0.0496002302637383,80.6757820468402,0.1574807310873691,16.264237660642983,84.67731941307065,0.04840935859003618
0.0499125258320518,80.5752980331116,0.15847226951676446,16.243980083475297,84.59701467761455,0.04870685196768772
0.0502067484370635,80.4832518924185,0.1594064262876766,16.225423581511567,84.52405427357796,0.04898704805992052
0.0505127464426184,80.3812447015668,0.1603779699553134,16.20485893183587,84.44152213391912,0.0492783749205177
0.0507954481758941,80.2599403216195,0.16127554795846374,16.18040396883849,84.33677996082668,0.04954744704968488
0.0511029918440681,80.1393986795712,0.16225199910491622,16.156102773801553,84.23476171668186,0.04984008123648782
0.0513936968839698,80.0285486892249,0.16317498760660412,16.133755415747743,84.14151166262296,0.050116614410892095
0.0516995364698748,79.9049368148574,0.16414602829185249,16.108835261875253,84.03598500984016,0.05040746180007157
0.0520228718837508,79.7360022623467,0.16517261823090879,16.074778056089094,83.88409809256322,0.05071485541354258
0.0523309257106805,79.5846534493787,0.1661506891314106,16.04426613539475,83.7493920367484,0.0510076330153721
0.0526293179757013,79.4374482874125,0.1670980845728516,16.01458957474236,83.61818701250905,0.051291146462160035
0.0529427801039258,79.3106973142989,0.16809332682996442,15.98903657856266,83.50962612209885,0.0515888917930618
0.0532419300379749,79.1650288087609,0.1690431278705703,15.959669807846197,83.37992773405121,0.05187295988511506
0.0535458715905409,79.0247608134283,0.17000814229996736,15.931391779987147,83.25621050841734,0.05216149540296795
0.0538220288739673,78.8771341026115,0.17088494167484616,15.901630235086479,83.12246149177805,0.052423582801135446
0.054103714991408,78.7651022805631,0.17177929509772039,15.87904461976152,83.0265869256198,0.05269084659819979
0.054421991943197,78.6301737007196,0.17278982441965046,15.851843018065072,82.90938438035234,0.05299274185435858
0.0547251884044906,78.478562010026,0.17375247318425766,15.821278101221242,82.77331610173816,0.0532802480712857
0.0550362182910908,78.3191878970944,0.17473999307421328,15.789148280054231,82.62957981857984,0.05357509647249966
0.0553440526599423,78.1776552864847,0.1757173671953168,15.760615305755314,82.50432355749072,0.05386683002902685
0.0556398827148873,78.0222577718665,0.17665662761976716,15.729287166808287,82.36340704344387,0.05414710696711658
0.0559526889068213,77.8655901845728,0.17764978727915762,15.697702981209876,82.22237932871624,0.054443382108851794
0.0562594980045218,77.6928079315591,0.1786239061643567,15.662870079002314,82.06376630435035,0.05473389184244722
0.0565530660825119,77.5035590809894,0.17955598481197527,15.624717510727464,81.88662297932648,0.05501178500236996
0.0568693615936504,77.3298212828458,0.18056022305984,15.589691970621715,81.72751885135231,0.055311105677080225
0.057177021680212,77.1581274602698,0.1815370438346731,15.55507849599039,81.56979938687022,0.05560216843820778
0.0574708888173702,76.9885350019505,0.18247007199515036,15.52088865639322,81.41313453725981,0.055880103254298034
0.0577805556537567,76.7895144838963,0.1834532642006775,15.480766119953493,81.22645529915803,0.05617289760686366
0.0580770336753676,76.5989811587484,0.18439458191929212,15.442354601603679,81.04762276700387,0.0564531414427876
0.0583486116631937,76.4281057739381,0.18525684203064,15.407906124025923,80.8875796378951,0.05670977978953501
0.0586714079413231,76.2720061470198,0.18628172021370082,15.376436439239193,80.74699213417469,0.05701473324074635
0.0589794376652547,76.1004905421249,0.18725971458718366,15.34185889329238,80.58885468034946,0.057305649684071286
0.0592542037072002,75.904710545988,0.18813209677036064,15.30238964607118,80.40238372701603,0.05756507908611645
0.0595764041734087,75.702949678935,0.1891550832505726,15.261714655273297,80.21305920612645,0.05786920955081107
0.0599014928435825,75.5116551327009,0.19018723977837443,15.223149674752502,80.03491600223946,0.058175972525957804
0.0602377731359927,75.3122744732573,0.1912549297067768,15.182954533808672,79.84891817733299,0.05849319724852783
0.0605927439282986,75.0801298449672,0.19238196197234805,15.136154176745388,79.6294409267667,0.05882794421936254
0.0608959678328382,74.8468071379139,0.19334469786926128,15.089116319003443,79.40467589777495,0.05911380377159449
0.0612037821943351,74.6273564498155,0.19432200846701395,15.044875060282806,79.19483291970901,0.059403907348159944
0.0615626659725486,74.4153037423233,0.1954614644628418,15.002125234452379,78.9965082298577,0.05974203572016484
0.0618533255931615,74.1842511254002,0.19638430875828775,14.95554502688068,78.77279376414442,0.06001580178727821
0.0621625357047116,73.9469789662906,0.1973660508624593,14.907710959604186,78.54371068653819,0.060306957912209844
0.0624818163883828,73.7071738080509,0.19837976703311538,14.85936623970306,78.31253190843216,0.06060750768258456
0.0627998027581865,73.4800356001179,0.19938937375724214,14.813575176983768,78.09456734246982,0.060906749316551226
0.0631066416591323,73.2360937807249,0.20036358726774503,14.764396506194139,77.85777770745972,0.06119541573823919
0.0634243020586921,72.9496471929227,0.2013721590363474,14.706648874093217,77.57642765156166,0.061494174994821876
0.0637351488276138,72.645711785222,0.2023590975276738,14.645375495900758,77.27579703754107,0.06178643965885996
0.064068931207913,72.3485555297943,0.20341885658512376,14.58546879480653,76.98385015702456,0.06210017379084017
0.064387815547855,72.0814959357856,0.20443131436443962,14.531629580654377,76.72266600051242,0.06239981280658612
0.0646815899479579,71.803489081851,0.20536404808476633,14.475583398901161,76.44785291947595,0.06267577788429463
0.0649958875473284,71.4678510207589,0.20636194296276764,14.407918765784993,76.11296742895337,0.06297093769602541
0.0653175691439574,71.1116990365383,0.20738328203206471,14.336118525766121,75.75654235530168,0.06327294170211521
0.0656347119051224,70.8114671070302,0.20839021029876362,14.275591768777288,75.45915735017917,0.06357059525947258
0.0659392829164461,70.5423249134588,0.20935722325971637,14.221332702553294,75.19383523351122,0.06385636625699487
0.0662475240836867,70.2548685036493,0.21033588896570526,14.1633814903357,74.90907959684105,0.06414549774245004
0.0665509471234038,69.9522152562147,0.21129925711680705,14.102366595652883,74.60760143489601,0.06443002818061423
0.0668759016030432,69.6448860972332,0.21233098758966215,14.040409037202211,74.30245064702692,0.06473465965400764
0.0671620903765036,69.3707796725918,0.2132396369453989,13.985149181994506,74.02986624645092,0.06500287303751036
0.0674557384879436,69.0546765649053,0.21417196969922092,13.921422795484908,73.71281076863707,0.06527800248627778
0.0677529178342804,68.7175105260559,0.21511551412384028,13.853450122052871,73.37332237050407,0.0655563634299503
0.0680237532491376,68.3303420194797,0.21597541656601188,13.775396951127108,72.97842834444197,0.06580998116065771
0.0683587286740617,67.9404320692974,0.2170389635401459,13.696791105170357,72.58475363112102,0.0661235724117595
0.06864141525662,67.5356995276744,0.21793649343976848,13.615197024779158,72.1714455235998,0.06638813634733992
0.0689141847176404,67.1274533283759,0.21880253647850825,13.532894591000584,71.75348704667239,0.0666433525976254
0.0692039276826317,66.7267411068034,0.21972247039235562,13.452111007131567,71.34449367285632,0.06691437875383678
0.0694764620905783,66.3525069317859,0.22058776713758607,13.376665397448036,70.96244436424695,0.06716924096768137
0.0697478812436085,65.9616329141754,0.221449522948457,13.29786519549776,70.56231705330781,0.06742299570390842
0.0700499411634839,65.5114686558997,0.22240856319406135,13.207112081029381,70.1005431807789,0.06770532136918261
0.0702867771568514,65.090935632083,0.2231605174730032,13.122332623427933,69.66596771978618,0.06792662859837413
0.070580389269826,64.6842495138058,0.22409273593169754,13.04034470198325,69.24968902411676,0.06820092129566983
0.0708417886682599,64.2767549030506,0.22492267902172516,12.958193788455,68.83023519017405,0.0684450575546713
0.0711140852931999,63.8659664160984,0.22578722080590968,12.875378829485438,68.40773619914548,0.06869930800839633
0.0713856812214956,63.4063121327578,0.22664953787824854,12.782712525963973,67.9326149180975,0.06895283982575784
0.0716569168359608,62.9395266558478,0.22751071095417552,12.688608573818918,67.44957908312063,0.06920597115983336
0.0719067986577686,62.5513262943861,0.2283040857384153,12.610347380948237,67.04919192001292,0.06943911731838558
0.0721580843653423,62.1056763523675,0.22910191785996178,12.520504352637289,66.58710298616828,0.06967351853517137
0.072411292862011,61.6333467527941,0.22990585483688494,12.42528270536329,66.09629707457655,0.06990965778115171
0.0726989095635245,61.1065793216868,0.23081903786419025,12.31908639125206,65.54896100553044,0.07017781808630681
0.072974581815268,60.6093077377712,0.2316942972634759,12.218836439934677,65.03224662404794,0.07043477447260517
0.0732467192898321,60.1956838273706,0.23255833374521692,12.135449859597914,64.6048201831335,0.07068837131826348
0.0734967972327008,59.7572613887133,0.23335233121382504,12.047063895964602,64.14922871218106,0.07092135485083284
0.0737637284015751,59.2655970550192,0.2341998376750009,11.94794436629187,63.63724845974282,0.07116997970753997
0.0740247494136682,58.770063128679,0.23502857938839652,11.848044726741687,63.12050232480492,0.07141303996796523
0.0742927546962982,58.2979850854658,0.23587949616074677,11.752873793229906,62.62910299070875,0.07166254245864237
0.0745585076789548,57.8883455294522,0.2367232618806815,11.670290458737563,62.20441418413185,0.071909886691968
0.0748061059774389,57.4218840406212,0.2375093864783685,11.576251822589233,61.717391583588125,0.07214027877901201
0.0750755950300542,56.9294785171516,0.23836501422042208,11.476982869057762,61.20349299157744,0.07239098006541332
0.0753560749068721,56.41761231719,0.2392555378293189,11.373790643145503,60.669022137031035,0.07265183920577059
0.0756431719993389,55.9483306043127,0.240167071097901,11.279183449829441,60.1804397992906,0.07291878220408606
0.0759323782897831,55.4844951718569,0.24108530107006132,11.185674226646352,59.69756484846398,0.07318761430914243
0.0760653412288886,55.2443550924977,0.24150745840172128,11.137261986647536,59.44653581357842,0.0733111859449937
0.0761981623638676,54.975694513041,0.24192916550527963,11.083100013829066,59.164741409612084,0.07343461054883615
0.0763426094220682,54.7165352695899,0.24238778491506655,11.030853510349322,58.89373835060502,0.07356882130136706