File: example/data/02 processed data/test_ID_096.csv
Strain,Stress_MPa,Displacement(mm),Force(kN),True Stress (MPa),True Strain
0.0006185604438029022,34.9378942094105,0.0019639294090742143,14.086958945234315,34.95950540875821,0.0006183692141456145
0.0007127360159035023,40.2294344714509,0.0022629368504936197,16.220507978889003,40.25810743829814,0.0007124821402131569
0.0008129232681012022,45.6100839614111,0.002581031376221317,18.389985853240955,45.647161459923375,0.0008125930249439862
0.0009092651711299022,51.081150171009,0.0028869169183374393,20.595919748950827,51.12759648176076,0.0009088520399658292
0.0010054285082938023,56.5435643161679,0.003192235513832822,22.7983651322789,56.60041482769193,0.0010049234035873328
0.0011058260426940023,62.1249520388588,0.003510997685553457,25.04878066206787,62.193651428724486,0.0011052150674556562
0.0012042139970921022,67.6891820293041,0.0038233794407674243,27.292278194215413,67.77069428975551,0.0012034895129809091
0.0013050825339784022,73.3927240565276,0.004143637045381427,29.591946339591928,73.48850761881486,0.001304231654000123
0.0014070578825799021,79.1493979989315,0.004467408777191189,31.913037273169184,79.26076578328737,0.001406068904228694
0.001509311619769802,84.8310871481286,0.0047920643927691214,34.20389433812545,84.95912369367898,0.0015081737537726546
0.0016103034543331024,90.6027544060807,0.0051127134675076,36.53103057653174,90.74865233447291,0.001609008305927137
0.0017150479454424022,96.3434458736923,0.005445277226779626,38.84567737627274,96.50867950259482,0.0017135789300961673
0.0018100334081097022,102.235369819713,0.005746856070748305,41.221301111308286,102.42041925457713,0.0018083972716507223
0.0019144298780829024,108.199049241716,0.006078314862913215,43.62585665425989,108.4061887343645,0.0019125996926726487
0.002008506786987402,114.132080814353,0.006377009048685002,46.01805498434713,114.36131587328164,0.0020064924340075963
0.0021111085931385023,119.939669956197,0.006702769783214745,48.359674926338634,120.19287562409971,0.002108883334683589
0.0022100509049201023,125.625196543744,0.007016911623121324,50.65207924643758,125.90283462304626,0.002207612334667598
0.0023048132428387024,131.328307221233,0.00731778204601288,52.951573471601144,131.63099444287607,0.0023021612349367823
0.0024007836540309024,136.949221737297,0.007622488101548115,55.21792620447815,137.27800719027616,0.002397906377180229
0.0024902742751824023,142.50294475303,0.007906620823704127,57.457187324421696,142.85781617048622,0.0024871786803879197
0.0025771483071605024,147.998919891869,0.008182445875234595,59.67316450040158,148.38033505772992,0.0025738331549996834
0.002668618418603402,153.400792073605,0.008472863479065802,61.85119936407754,153.81016025276097,0.002665063978696197
0.0027581642349261025,158.767667260145,0.008757171445890374,64.01512343929046,159.2055745616446,0.0027543674797333557
0.0028451627873899024,164.082288692212,0.00903339184996294,66.15797880069988,164.54912951406885,0.0028411229725531536
0.002935638450549002,169.246265564105,0.009320652080493081,68.24009427544713,169.7431114089068,0.00293133787855338
0.003018317917181502,174.456022079135,0.009583159387051269,70.34066810230723,174.98258581633667,0.0030137719408276312
0.0031058372717632024,179.503397624899,0.009861033337848168,72.37576992235928,180.06090596765054,0.003101024122514276
0.0031924536975871023,184.608820491655,0.010136040489839048,74.4342764222353,185.19817560324077,0.003187368636954285
0.0032808710176962025,189.65826036295,0.010416765481185442,76.47021057834144,190.28050465264147,0.0032755007033786207
0.0033632871783076026,194.732556081993,0.010678436791126638,78.51616661225958,195.38749759106264,0.0033576439775821324
0.0034431287583028027,199.83784421064,0.010931933807611397,80.57461878573005,200.52591163903887,0.0034372147616929167
0.0035240090666147023,204.791509636783,0.01118872878650168,82.5719366855509,205.51319677350872,0.003517814296016455
0.003600996468385702,209.648371287482,0.011433163787124603,84.53022330311275,210.40331433209104,0.0035945284036046003
0.003687490572912202,214.325282041339,0.01170778256899624,86.41595371906787,215.1156044984032,0.0036807084471196017
0.0037726042287844026,218.776551219926,0.011978018426390477,88.21070545187416,219.60190856221718,0.0037655058048788547
0.0038660664455279024,222.920947126901,0.01227476096455109,89.8817258815665,223.78277432059363,0.0038586124163186224
0.003962157977803003,226.798552393368,0.012579851579524532,91.44517632500597,227.69716408708757,0.003954329302035926
0.0040686743021435025,230.451377626007,0.012918040909305619,92.91799545880602,231.3890092240475,0.004060419629662318
0.004177105159756002,234.244482333821,0.013262308882225307,94.44737527699662,235.222946169622,0.004168405274474296
0.004295257510517002,237.873216126653,0.013637442595891482,95.9104807422665,238.89494284477186,0.0042860592219153915
0.004422357522240402,241.595710350724,0.014040985133113276,97.41139041341192,242.66413295773455,0.004412607633640136
0.004554903278196502,245.032015418099,0.014461817908273894,98.79690861657751,246.14811254838997,0.0045445610994504105
0.004709117639333602,248.366274474324,0.014951448504884186,100.14128186804744,249.53586047846662,0.004698064431849372
0.004880399550084102,251.527135005818,0.015495268571517022,101.41574083434581,252.75468792233434,0.0048685290065300325
0.005077763554936603,254.507611569343,0.016121899286923713,102.61746898475909,255.79994104382376,0.0050649151891975506
0.005304938937419702,257.605140808186,0.016843181126307553,103.8663927738606,258.9717203501388,0.005290917316223906
0.005564874947209102,260.884927391122,0.0176684779573889,105.18880272410038,262.3367193876653,0.005549448235970419
0.005853345512804003,264.246958725705,0.01858437200315271,106.54437375820426,265.7936874758342,0.005836281242292505
0.006163906796661802,267.536418800615,0.01957040407940122,107.87068406040798,269.1854883508147,0.006144987627357304
0.006493044804596602,271.03482880912,0.02061541725459421,109.28124297583717,272.7946700961837,0.006472055795240449
0.006843840399154202,274.499740232257,0.02172919326731459,110.67829526164604,276.3783726440159,0.006820527628926618
0.0071957204666199025,278.007461942919,0.02284641248151819,112.09260865538494,280.0079259266947,0.007169954797968799
0.007565572513215803,281.535595225073,0.024020692729460173,113.51515199474943,283.66557318579964,0.007537097101167651
0.007943357721675502,284.856411987599,0.025220160766319718,114.85410531339993,287.1191283673295,0.007911975333872803
0.008332257117145601,287.972710667459,0.026454916346937283,116.11059694111948,290.37217333546164,0.008297735492286412
0.008738155271582903,290.788945623899,0.027743642987275715,117.24610287555608,293.3299045820205,0.008700198547044525
0.009145879414947003,293.179163188117,0.029038167142456734,118.20983859744878,295.86054446161063,0.009104309132097222
0.009555849212859503,295.142458940339,0.03033982125082892,119.00143944474469,297.9627957742855,0.009510480878754857
0.009969397400845702,296.66160532237,0.0316528367476851,119.61395926597959,299.61914275940154,0.009920030791002747
0.010377454994876103,297.877775149647,0.03294841960873163,120.10431894033768,300.96898835523626,0.010323978854767367
0.010792349288052703,298.815836554401,0.03426570898956733,120.4825452987345,302.0407614352978,0.010734527536154656
0.011210516378281103,299.52976205486,0.0355933895010425,120.77040006051955,302.88764535815864,0.011148144255785166
0.011630408378995703,300.085690222333,0.03692654660331136,120.99455029764468,303.57580934831157,0.011563295048520546
0.012055798440662503,300.541260908491,0.03827716004910344,121.17823639830357,304.1645257731063,0.011983706144369886
0.012475728227903903,300.987309913871,0.03961043712359489,121.35808335727279,304.74234579240436,0.012398547590632629
0.012890861631903202,301.335614418297,0.04092848568129266,121.49851973345734,305.2200901285278,0.012808481685419319
0.013296218035003903,301.664635113891,0.04221549226113739,121.63118087792085,305.67563387581515,0.01320859914009694
0.013693745708125402,301.985414125087,0.04347764262329815,121.76051897523509,306.1207255936789,0.013600833621104529
0.014094086668263402,302.215296069812,0.044748725171736295,121.85320737534819,306.4747446450948,0.01399568850577001
0.014484936760563302,302.436545182751,0.04598967421478848,121.9424150176852,306.8173194138064,0.014381032229255403
0.014880034724228402,302.657622187708,0.047244110249425174,122.03155326608386,307.16117811541346,0.014770413118556956
0.015268726215433402,302.914756565819,0.04847820573400105,122.13522984733824,307.53987905043715,0.01515333234441162
0.015643042934030703,303.1441703856,0.04966666131554748,122.22772949947392,307.886267658143,0.01552195172859344
0.0160229433215565,303.371706932649,0.05087284504594189,122.31947223524406,308.23261459819463,0.015895930910726323
0.016396433021409702,303.561728509376,0.0520586748429758,122.3960889349804,308.5390580587433,0.016263463033677813
0.0167691522793164,303.726476112047,0.053242058486829565,122.46251516837737,308.81971164123007,0.01663010239131448
0.0171455520586758,303.884190964476,0.05443712778629567,122.5261057968767,309.094453180466,0.017000225860950364
0.017505177006704904,304.121712340858,0.05557893699628807,122.62187441583394,309.4454167469669,0.017353726288946936
0.017862891783207505,304.285928330488,0.05671468141168382,122.68808630285275,309.72135493940834,0.01770522515116332
0.0182156363693972,304.431994330121,0.05783464547283611,122.74698011390478,309.97741683804884,0.018051719242468272
0.0185709169983429,304.609097119996,0.058962661469738706,122.81838795878241,310.2659673795517,0.018400583125099092
0.018932655335712804,304.753355688498,0.06011118069088815,122.87655301360239,310.5231459341502,0.018755663082829985
0.019287630844123403,304.966899236998,0.0612382279300918,122.96265377235761,310.8489882091582,0.01910398216728477
0.019645700082954305,305.072870070657,0.06237509776337991,123.00538121248893,311.0662401795113,0.019455214095352995
0.019996458458163502,305.176347732894,0.06348875560466911,123.04710340590286,311.27879389274887,0.01979915519031231
0.0203486017862448,305.285394820659,0.06460681067132723,123.09107119168972,311.49752575102116,0.020144335364430114
0.0206945640719104,305.470478535222,0.06570524092831552,123.16569694540152,311.79205692534634,0.020483340726752744
0.021040225880181805,305.671921114936,0.06680271716957722,123.24691859354222,312.1033273804234,0.020821936917869103
0.0213882073100728,305.830305714352,0.06790755820948113,123.31077926402673,312.3714676946735,0.02116268955096337
0.021732152181508806,305.976799167113,0.06899958317629046,123.36984542417996,312.62633353062364,0.02149937541784065
0.0220825445559761,306.043314253973,0.07011207896522412,123.39666430720192,312.8015293770449,0.02184225618727579
0.0224233296158352,306.140964704285,0.07119407153027676,123.43603696876771,313.0056644647589,0.022175622862637603
0.022767166048701604,306.320526957581,0.07228575220462759,123.50843646929667,313.2945772589501,0.022511861894487985
0.023099701572676504,306.479542165773,0.07334155249324789,123.57255140123968,313.5591281279329,0.02283694221341413
0.0234343821616377,306.659234634609,0.07440416336319969,123.64500340467436,313.8456043324317,0.02316401283941013
0.023766878049082202,306.761425133211,0.07545983780583598,123.68620661371068,314.0521865145147,0.023488842544071437
0.024104100561468902,306.840335484429,0.07653051928266376,123.71802326732177,314.2364457872605,0.023818182154776213
0.024447367060699506,306.89773819077,0.07762039041772092,123.74116803851847,314.40057984641817,0.02415331310742138
0.024790307397895,307.019654082401,0.07870922598831662,123.7903245260241,314.63076568429915,0.02448801351301253
0.0251369016278431,307.16438651904,0.07980966266840184,123.84868064447694,314.88554748654593,0.024826166235435775
0.025475243907143903,307.316007656643,0.08088389940518188,123.90981428715847,315.1449579082657,0.0251561577290567
0.025822003822325502,307.427176486214,0.08198486213588346,123.95463755924149,315.3655622125278,0.025494246144929577
0.026163018137276,307.560797254151,0.0830675825858513,124.00851345287369,315.60751597102643,0.025826621200732112
0.026501378760580105,307.679077172986,0.08414187756484183,124.05620391614798,315.83299693385305,0.026156300642612696
0.0268469451276198,307.839964505378,0.08523905078019287,124.12107368856842,316.10452714054236,0.02649288880574312
0.027185679769379502,308.038249643841,0.08631453326777991,124.2010222563967,316.41247885537865,0.026822712821899946
0.027527504176672705,308.228214884077,0.08739982576093583,124.27761624125984,316.7129683566668,0.02715543508515055
0.027865590114778405,308.405551579933,0.08847324861442143,124.34911839702899,316.99945426938154,0.027484409569003557
0.0282092684602967,308.555203099906,0.08956442736144202,124.4094578898821,317.2593196589726,0.027818714856853975
0.0285558994021421,308.715799892494,0.09066498060180116,124.47421051665357,317.5314572180759,0.028155779049250484
0.0288969939631505,308.82630456178,0.09174795583300283,124.5187659993097,317.75045642036383,0.02848734879282339
0.029240716272548005,308.93310404263,0.09283927416533991,124.56182754998844,317.96652928513817,0.028821361731689227
0.029578737120828,308.988073810646,0.09391249035862889,124.58399136045246,318.12755081936206,0.02914972549448543
0.029918869532680005,309.138678309316,0.09499241076625901,124.64471509431623,318.3877580931575,0.02948003169522635
0.030258874943522904,309.234570529033,0.09607192794568521,124.68337883730612,318.59166072688504,0.029810105558844623
0.030600366329636502,309.394181276533,0.09715616309659589,124.74773389069811,318.8617565638529,0.030141512364705143
0.030943005880010303,309.575031319425,0.09824404366903271,124.82065262799217,319.1542133338463,0.030473923080043534
0.031278587770308,309.681772601549,0.0993095161707279,124.86369071294457,319.36818110673113,0.030799379756758685
0.0316202799699745,309.774080865829,0.10039438890466902,124.90090940510225,319.569224030248,0.031130653585189988
0.0319604778099808,309.938441202069,0.10147451704668903,124.96717949267422,319.8442218745678,0.03146036963027887
0.032301264972466104,310.103341836558,0.10255651628757988,125.0336674285002,320.1200720500679,0.03179054788095152
0.0326438820627122,310.246844369348,0.10364432554911124,125.09152764972113,320.3745057672696,0.03212238923168381
0.0329838124900585,310.389230485018,0.10472360465593573,125.14893773155926,320.6270506622694,0.032451519627554694
0.0333316399640267,310.417888373021,0.10582795688578477,125.16049259200207,320.76462566666396,0.0327881840771578
0.0336742278654547,310.59388064546,0.10691567347281868,125.23145267624946,321.05288975593106,0.03311966635294328
0.0340187148212654,310.7292539008,0.10800941955751764,125.28603517280257,321.2998637758759,0.033452875362739845
0.034361256787624,310.931808703693,0.1090969903007062,125.36770526932902,321.61581642600095,0.03378409300571831
0.0347073517688778,311.127952711207,0.110195841866187,125.44679053315866,321.92638001108566,0.03411863482134543
0.035053137941151204,311.247000480769,0.11129371296315506,125.49479059384605,322.15718452239093,0.03445276640537122
0.0353973126652321,311.397350291551,0.1123864677121119,125.55541163755335,322.4199796629458,0.03478523002665737
0.0357410523898516,311.475588892707,0.11347784133777881,125.58695744153945,322.6080542334811,0.03511716316408105
0.0360885056924829,311.581890312026,0.1145810055736332,125.62981817380889,322.8264151342261,0.035452570393438486
0.0364256959831926,311.655869780546,0.11565158474663649,125.65964669551617,323.00815174454965,0.03577796289826397
0.0367563135331154,311.729144902083,0.11670129546764138,125.68919122451987,323.18715908951395,0.03609690986115295
0.0370824682098885,311.876403357448,0.11773683656639598,125.74856583372305,323.4415501703649,0.03641145184226869
0.0374122549682189,312.001729359494,0.118783909524095,125.79909727774799,323.6744176088166,0.03672939602156591
0.0377489584279707,312.171674019135,0.11985294300880696,125.86761896451524,323.9558295640734,0.037053904267511165
0.0380909055945866,312.328954125991,0.12093862526281246,125.93103430359957,324.2258468320601,0.03738335855310932
0.0384370674144062,312.433836773373,0.12203768904073968,125.973322987024,324.4428772199727,0.037716762993141466
0.038777800678589804,312.580236019001,0.12311951715452261,126.03235116286122,324.70141010741236,0.03804483041887914
0.0391207991772726,312.675442999196,0.12420853738784049,126.07073861727582,324.90755621243227,0.038374970207049795
0.0394595728939734,312.780432106898,0.12528414393836554,126.11307022550127,325.12261436742864,0.03870093664477092
0.039800173447948,312.851645265906,0.1263655506972349,126.1417833712133,325.30319501096494,0.03902855377641621
0.0401388783523974,312.931893827879,0.12744093876886173,126.1741395914008,325.4926290468216,0.039354241115331444
0.040481989321934,313.02337887518,0.12853031609714044,126.2110263624726,325.69518795632075,0.039684057064000855
0.0408313104230978,313.072467254346,0.1296394105933355,126.23081879695232,325.8556263497333,0.040019730798932195
0.041176988310204,313.245663859703,0.13073693788489768,126.30065166823225,326.14417689867605,0.04035179277053234
0.0415245875677578,313.429070217834,0.13184056552763102,126.37460111183067,326.4440830903754,0.040685589282531257
0.0418675451928258,313.619347593529,0.13292945598722192,126.4513209497109,326.74981980224567,0.041014819313472554
0.0422125167286524,313.781290687418,0.13402474061347136,126.51661640516694,327.02678866969876,0.041345873331291014
0.0425602597740175,313.905083084978,0.13512882478250554,126.56652949986314,327.2649649654592,0.041679476160826734
0.042901640948882803,314.004116611801,0.13621271001270288,126.60645981787818,327.4754084791516,0.04200686759175728
0.0432475225542666,314.07728059396,0.13731088410979644,126.63595953548467,327.66034487022995,0.04233846574840335
0.043586983349587,314.15929715152,0.13838867213493872,126.66902861149285,327.8525532055812,0.04266380136783479
0.043926718990490804,314.277060386483,0.1394673327948083,126.71651074782996,328.0822205032376,0.042989294458991474
0.0442702447959219,314.380340307635,0.14055802722705202,126.75815321203844,328.2980349320792,0.0433183111317358
0.0446091237129664,314.485699608681,0.14163396778866832,126.80063408222017,328.51463108848344,0.043642771150946474
0.0449587616928512,314.633469661984,0.14274406837480255,126.86021496771195,328.7790008451121,0.043977422143230444
0.0453074343756368,314.797039659847,0.14385110414264682,126.92616639085031,329.05968587588023,0.04431103772451403
0.0456494576077247,314.865561640315,0.14493702790452592,126.953794453375,329.23900374854696,0.04463818290522011
0.0459950347943409,314.938852113546,0.14603423547203237,126.98334517218174,329.4244755745983,0.044968618780930385
0.0463345146480152,315.027670488681,0.14711208400744824,127.01915674103618,329.6243247014689,0.04529311819522545
0.0466805934726767,315.181609841602,0.14821088427574852,127.08122508813393,329.89447444068156,0.04562381702914466
0.0470284850545047,315.308591948703,0.14931544004805242,127.13242427371705,330.1370773527195,0.045956137874096456
0.0473754997696015,315.43324372814,0.15041721176848477,127.18268387118604,330.3770512937071,0.046287511115158504
0.0477154394787059,315.52374985066,0.15149652034489122,127.21917593978611,330.5791042407535,0.046612021813686504
0.0480604263545287,315.650197887823,0.1525918536756286,127.27015978837024,330.8204809772032,0.04694124297188683
0.0484068144538071,315.811667723887,0.15369163589083754,127.33526442627125,331.09910452574456,0.04727169230654632
0.0487618342092984,315.904400640119,0.15481882361452243,127.37265433809598,331.3084786501202,0.04761026284459913
0.0491184663059846,316.090641600108,0.15595113052150109,127.44774669316354,331.61652912917987,0.04795025564593669
0.0494679773281356,316.136556873349,0.15706082801683052,127.4662597313343,331.77519290135467,0.04828334750064006
0.0498134105388403,316.282432283503,0.15815757846081796,127.52507669670841,332.0375389290641,0.04861244412943772
0.0501609785096824,316.35908851781,0.15926110676824162,127.555984490381,332.2279699582946,0.04894346528457973
0.0505046691977322,316.393279196973,0.16035232470279973,127.56977017221952,332.3726170992019,0.04927068603148119
0.0508527762041495,316.446227345649,0.16145756444817463,127.59111886576568,332.5383965255047,0.04960200235309352
0.051208082195364,316.546070912971,0.16258566097028068,127.6313757921099,332.7557881309019,0.049940057260665256
0.0515586072455067,316.65221851802,0.16369857800448376,127.67417450646566,332.978365886009,0.050273451407671414
0.0519165983307902,316.762964526575,0.1648351997002589,127.71882729711504,333.2082201219715,0.05061383201951859
0.0522730241668064,316.873416568189,0.16596685172961032,127.7633615602938,333.43734833027645,0.05095260931944853
0.0526267206347542,316.945797535715,0.16708983801534458,127.79254556640028,333.6256154789864,0.051288678979916
0.0529845686580117,317.020421759728,0.16822600548918715,127.82263405352232,333.8176120624481,0.051628578398695224
0.0533477372760153,317.117758681817,0.16937906585134857,127.86188030050862,334.0352735575334,0.0519734134663427
0.0537096467498548,317.157101880825,0.170528128430789,127.87774347834865,334.1914977870518,0.05231693470135235
0.0540662564640279,317.232536458319,0.17166036427328857,127.90815869999422,334.38411213320853,0.052655310063773005
0.0544206057646055,317.337693495712,0.17278542330262245,127.95055801747108,334.6074030076914,0.0529914272198828
0.0547730589753497,317.491755161415,0.1739044622467353,128.01267568108256,334.8817497910585,0.05332563381258865
0.055132098806129,317.609384910193,0.17504441370945956,128.0601039957898,335.11985690081565,0.05366597122815522
0.0554835261671969,317.740837693455,0.17616019558085014,128.11310575800107,335.3702197760068,0.053998980574013665
0.0558374943030792,317.823348775865,0.17728404441227646,128.14637422642878,335.56980820252295,0.05433428547153221
0.0561927683546048,317.89305591962,0.17841203952587023,128.17448014679078,335.75634677244864,0.054670714414959826
0.056547632488174,317.939847976454,0.17953873314995245,128.19334670410626,335.9185936531724,0.05500664223341275
0.0569107347258675,317.977619512548,0.18069158275462932,128.20857618745936,336.07395946538946,0.05535025178531958
0.0572703115697968,318.019286654418,0.18183323923410483,128.22537637906134,336.23235028632104,0.05569040888589188
0.0576318881639916,318.126760076193,0.1829812449206733,128.26870966272102,336.46100593487716,0.05603234110172984
0.0579971654091591,318.239638045367,0.18414100017408014,128.31422205989196,336.69663497283506,0.05637765423512644
0.0583596501939763,318.298596890789,0.18529188936587473,128.3379942663661,336.8743916625689,0.056720209692400284
0.0587311461285494,318.350446149255,0.18647138895814433,128.3588998873796,337.04753272213577,0.05707115915477701
0.0591011067381729,318.401004848248,0.18764601389369895,128.3792851548136,337.2188566213258,0.057420535846803414
0.0594692538083861,318.46679480622,0.18881488084162587,128.4058116658679,337.4057774560943,0.057768078775539446
0.0598447941749072,318.543329338057,0.19000722150533034,128.4366703891046,337.6064893180827,0.05812247681372454
0.0602247289163058,318.634888718229,0.19121351430927092,128.47358713118993,337.8245885145616,0.058480894064977654
0.0606095803105429,318.727850110231,0.1924354174859737,128.51106916444513,338.0458113386937,0.05884381859593882
0.0609959663052294,318.841187065319,0.19366219301910334,128.5567666247366,338.2892133682745,0.059208057838784495
0.0613840168942639,318.950548463759,0.19489425363928786,128.60086114058763,338.5290143190931,0.05957373278524126
0.0617748634765849,319.026245647547,0.19613519153815706,128.63138224509095,338.73404841787163,0.059941907386162105
0.062167611462849104,319.02941783018,0.1973821663945459,128.6326612691286,338.8627147230656,0.06031173660270139
0.0625554345893818,319.074250175217,0.1986135048212872,128.65073767064752,339.0340785612088,0.060676794186615875
0.0629437173775237,319.124695872598,0.19984630267363773,128.67107737583152,339.21159053779104,0.06104215099431155
0.0633379926039641,319.24515931559,0.201098126517586,128.71964823604588,339.4655068551722,0.06141300987825753
0.0637365486035442,319.349072505851,0.20236354181625285,128.76154603435913,339.7032801871169,0.061787755564431786
0.0641414395695107,319.401243226596,0.20364907063319646,128.78258126896353,339.88809876744136,0.062168314011019014
0.0645527045548938,319.465217209069,0.2049548369617878,128.80837557869663,340.087560991131,0.06255471521537719
0.0649652145790239,319.464348030902,0.2062645562884009,128.80802512605968,340.21841795107747,0.06294213626084792
0.0653850300775495,319.522600823598,0.20759747049621965,128.8315126520747,340.4145956889058,0.06333626441420033
0.0658041240534104,319.562518920851,0.20892809386957803,128.84760762888712,340.59105055873897,0.06372956031705405
0.0662274395578415,319.582879883396,0.21027212059614672,128.85581716898528,340.7480357445945,0.06412666092027097
0.0666661077998284,319.618988162828,0.21166489226445515,128.87037602725223,340.9267420825631,0.06453799719977293
0.0671153819863166,319.645348773908,0.2130913378065552,128.88100462563972,341.0984684570182,0.06495910329266769
0.06757753273780841,319.659696254179,0.21455866644254168,128.886789529685,341.26150984275364,0.06539209368254939
0.0680565902222232,319.661845616515,0.21607967395555863,128.88765615257884,341.4169408533177,0.06584072623369627
0.068555022109276,319.690370644291,0.2176621951969513,128.89915744377817,341.60675107193305,0.06630728917215245
0.0690649287750606,319.711607780117,0.21928114886081737,128.90772025694318,341.7924672000109,0.06678436806098394
0.0695905537507143,319.717805780048,0.22095000815851787,128.91021929051536,341.96714492824486,0.06727591519471506
0.0701139263847103,319.747323675888,0.22261171627145518,128.92212090611807,342.1660639898074,0.06776511606267858
0.0706422263505014,319.716589381307,0.2242890686628419,128.909728838543,342.3020810563916,0.06825867996143527
0.0711751913451699,319.686007664723,0.22598123252091443,128.8973982904163,342.4397204306331,0.06875635544139512
0.0717160565342086,319.647234418868,0.22769847949611227,128.88176491768758,342.57107355345494,0.0692611549276586
0.0722737615304657,319.558623737598,0.2294691928592286,128.84603709099952,342.6543275046129,0.06978140460807875
0.0728323529184876,319.50987977783,0.2312427205161981,128.82638352642107,342.7805361027525,0.07030220998631653
0.0733919499557333,319.433343508951,0.2330194411094532,128.79552410280905,342.8771794699525,0.07082368115703942
0.0739390646516228,319.302632020021,0.23475653026890236,128.7428212304725,342.9115699723826,0.07133325765363595
0.0744904734527158,319.141633391759,0.23650725321237265,128.67790658355725,342.9146447615842,0.07184657103294025
0.0750585194567466,318.848588287512,0.23831079927517046,128.55975079752483,342.7808912552464,0.07237509680195282
0.0756240298775319,318.533694843455,0.24010629486116378,128.43278576088105,342.6224964992971,0.07290098606812416
0.076210854234171,318.180587199325,0.2419694621934929,128.29041275876784,342.4294015505157,0.07344640372588165
0.0767837379243418,317.808066313275,0.2437883679097852,128.14021233751248,342.21055758731535,0.07397857756949264
0.0773843539585716,317.364953112,0.24569532381846482,127.96154909475841,341.9240349776645,0.07453620912299727
0.077990813627096,316.82567838693,0.2476208332660298,127.74411352561017,341.5351708222833,0.07509895076876648
0.0786068903506288,316.264994245915,0.24957687686324642,127.51804567995292,341.1256019703458,0.07567029213591657
0.0792184963804328,315.605133483389,0.2515187260078741,127.25198982050246,340.60689760788887,0.07623716473825312
0.0798237756871379,314.800262467077,0.25344048780666284,126.92746582672545,339.9288080045011,0.07679785716229032
0.0804253978508091,313.927397045888,0.25535063817631887,126.57552648890204,339.17513284957244,0.07735485048194522
0.0810306823299754,312.972046942195,0.2572724163976719,126.19032932709302,338.3323854561301,0.07791492153824693
0.081634416645329,311.960499028869,0.25918927284891957,125.78247320843997,337.42721238347644,0.07847324592358347
0.0822411784620552,310.947262883038,0.2611157416170252,125.37393639444092,336.5199322220895,0.07903405619752027
0.0828551108278862,309.786097282932,0.2630649768785387,124.90575442447819,335.45345870624766,0.07960117405303777
0.0834950872759457,308.599137112643,0.26509690210112763,124.42717208381767,334.36564899914464,0.08019200785935117
0.0841236116031786,307.51382949006,0.2670924668400921,123.98957605039219,333.3830034446879,0.08077192936046472
0.0847705440651946,306.497043065495,0.2691464774069928,123.5796077640076,332.47896416053044,0.08136848450310363
0.0854131950513098,305.434142703312,0.2711868942879086,123.15104633797539,331.52224870935953,0.08196073942909592
0.0860544093813254,304.386385918618,0.27322274978570815,122.72859080238678,330.5801765825608,0.08255132097619701
0.0866804743853122,303.293403466284,0.27521050617336623,122.28790027760571,329.5830195566774,0.08312761311933096
0.0873564392719551,302.284871135793,0.2773566946884574,121.88126004195176,328.69140112399765,0.08374946540176405
0.0876775011467349,301.837953105607,0.27837606614088334,121.70106269218076,328.30235058515206,0.08404469010713125
0.0878522188611179,301.592103090235,0.2789307948840493,121.60193596598276,328.0876385377032,0.08420531095560942