File: example/data/02 processed data/test_ID_070.csv
Strain,Stress_MPa,Displacement(mm),Force(kN),True Stress (MPa),True Strain
0.001482544388101528,55.5182064817886,0.004707078432222352,22.384940853457167,55.600514687245635,0.0014814465041439703
0.001578055524934728,59.2151443680815,0.005010326291667761,23.875546209210462,59.30858915381136,0.0015768117036888984
0.001667787824080128,62.7656436965796,0.005295226341454406,25.307107538460897,62.8703234729073,0.0016663986103616505
0.001757560593753528,66.1674641165738,0.005580254885167451,26.67872153180255,66.28375744409368,0.0017560178914637387
0.001844239243958628,69.5991546648573,0.005855459599568643,28.06237916087046,69.72751215723657,0.0018425407227631212
0.001935359795422028,72.9435059110331,0.006144767350464938,29.41082158332855,73.08467783971044,0.0019334893995235922
0.002032667020524028,76.400140984299,0.006453717790163788,30.804536844869357,76.55543703124117,0.0020306039481355533
0.0021263632595293278,79.6278853066987,0.006751203349005615,32.10596335566092,79.79720311644888,0.0021241057487991744
0.0022243920159543277,82.7839918231523,0.00706244465065499,33.37850550309501,82.96813587361255,0.002221921718628904
0.002314464947766528,85.7701385468421,0.007348426209158726,34.58251986208674,85.96865052607384,0.002311790699277276
0.002401725098492328,88.7894267623323,0.0076254771877131405,35.79989687057238,89.00267455706813,0.0023988455664092603
0.002493698076978228,91.8614060463396,0.007917491394405873,37.038518917884126,92.09048065794588,0.0024905939713259725
0.0025940972944579277,94.9158890665396,0.00823625890990392,38.27008647162877,95.16211011756819,0.002590738431628808
0.002702257664992028,97.9634607018302,0.008579668086349688,39.49886735497794,98.22818321440086,0.0026986131309183663
0.0028007371579855276,100.875077701851,0.00889234047660405,40.67283132938632,101.15760228028525,0.0027968224014373664
0.0029039758271740277,103.765337779546,0.009220123251277537,41.83818419271295,104.06666981215635,0.0028997674347828973
0.0030059493997978276,106.57393658678,0.009543889344358103,42.97061123178969,106.89429244749711,0.0030014405671894445
0.0031086968134081275,109.326786026982,0.009870112382570803,44.08056012607914,109.66664985832425,0.003103874806323457
0.0032112614566326275,112.017118601439,0.010195755124808591,45.1653022201002,112.37683485688684,0.003206116368434246
0.003307268114222328,114.589314255356,0.010500576262655891,46.20241150775954,114.96829184062334,0.003301811131525704
0.0034076704029177276,117.051512752746,0.010819353529263784,47.19516994190719,117.45038572837029,0.0034018774507144447
0.0035167142616066276,119.435182256892,0.011165567780601042,48.15626548597886,119.8552016656724,0.003510545081273282
0.0036269641814195277,121.775750169777,0.011515611276007,49.09998246845408,122.21742645380827,0.003620402607775124
0.003745051089401828,123.97766197334,0.011890537208850803,49.98779330765069,124.44196465137476,0.0037380558451624284
0.003879662557776928,126.098160438059,0.012317928620941745,50.84277828862539,126.58737874971507,0.0038721560758097017
0.004018850343118428,128.098920652261,0.012759849839401007,51.64948480699163,128.61373104347743,0.0040107963354346415
0.004172103627895928,129.935464007004,0.01324642901856957,52.389979087624006,130.47756822777995,0.004163424535229992
0.004345161565567028,131.542553834148,0.013795887970675314,53.03795770592848,132.11412748330469,0.004335748608414067
0.004535494909848328,132.895423569468,0.014400196338768441,53.5834347832095,133.49817008660946,0.00452524054685992
0.004740246900504728,133.975832584019,0.015050283909102511,54.01905569787647,134.61091110916794,0.00472904730877358
0.0049812562874714285,134.842502715383,0.015815488712721783,54.36849709484243,135.5141877798524,0.0049688908768895845
0.005219869310249928,135.568942448486,0.016573085060043524,54.661397595229566,136.2765946105959,0.005206293016268281
0.005482842370585428,136.090388293735,0.017408024526608733,54.87164456003396,136.83655044090133,0.0054678663063497295
0.005748618364679928,136.512096529324,0.01825186330785877,55.04167732062344,137.29685247443345,0.005732158110480892
0.006037626413756228,136.82403919182,0.019169463863676024,55.16745260214182,137.65013162488134,0.0060194729798558316
0.006337974825182528,137.010913240366,0.020123070069954525,55.24280021851557,137.8792849592587,0.006317974326693464
0.006665998191985228,137.145351692452,0.021164544259553098,55.297005802396654,138.05956235887308,0.006643878670751289
0.007005833607888128,137.179721056438,0.022243521705044806,55.3108635299558,138.14077935653594,0.006981406776138307
0.007348008267247428,137.168912340485,0.02332992624851058,55.306505455683556,138.17683064237224,0.00732114317749658
0.007691292662866928,137.135839678975,0.024419854204602496,55.29317055856273,138.190591556514,0.00766186546393741
0.008037704631880827,137.123378877638,0.025519712206221623,55.288146363463646,138.22553609518195,0.008005574338383514
0.008391233522056927,137.017319859251,0.026642166432530742,55.24538336725,138.1670641867563,0.00835622284090095
0.008749833678261527,136.945451388665,0.027780721928480346,55.216405999909725,138.14370131131025,0.008711775722961002
0.009122855245120628,136.852247207206,0.02896506540325799,55.178826073945466,138.1007304484468,0.00908149336982328
0.009497413765674327,136.759084656587,0.030154288706015987,55.14126293353587,138.05794226978549,0.00945259687116268
0.009870656207486526,136.651049884117,0.03133933345876972,55.09770331327597,137.9998854179152,0.009822259491477
0.010244703450875527,136.479548942338,0.032526933456529794,55.02855413355068,137.8777414483615,0.010192582152383663
0.010619698544206427,136.343264048404,0.0337175428778554,54.97360406431649,137.79118841113117,0.010563705615457011
0.010990454125926528,136.176685573362,0.03489469184981672,54.90643962317956,137.67332918917674,0.010930497981816126
0.011363471368025327,136.039831296889,0.03607902159348041,54.851259978905645,137.58571602474217,0.011299392112192256
0.011736310873527427,135.919590260506,0.03726278702344958,54.802778793036026,137.51478482560574,0.011667974535062067
0.012112376945479127,135.791061772007,0.038456796801896224,54.750956106473225,137.4358142980164,0.01203960911282824
0.012486235736648428,135.678616253139,0.03964379846385876,54.705618073265654,137.37273144009797,0.012408925571978957
0.012873756966512728,135.573483600166,0.040874178368677905,54.663228587586936,137.31882367913806,0.012791594565135078
0.013248540927746928,135.391800686189,0.042064117445596495,54.5899740366714,137.18554449886133,0.013161546532889748
0.013633679690499226,135.240304361424,0.04328693301733504,54.528890718526156,137.08412735233327,0.013541577265282313
0.014012049880881127,135.075543417924,0.044488258371797575,54.462459106106955,136.96822866998306,0.013914788610100133
0.014392173755818726,134.879766167345,0.04569515167472445,54.3835217186735,136.82097919816962,0.014289589524984856
0.014777447168580827,134.751670842359,0.04691839476024413,54.33187368363915,136.74295653910997,0.014669324578593842
0.015153065168121427,134.587684029729,0.04811098190878553,54.26575420078673,136.627099976658,0.015039404245404784
0.015541154134131627,134.486503486889,0.049343164375867915,54.224958205913644,136.5765789665392,0.015421627198566625
0.015930641424703927,134.369535192207,0.050579786523434964,54.17779658949786,136.5101280757582,0.015805080511771565
0.01632842208125963,134.278929247285,0.05184274010799932,54.14126427250532,136.47149228065425,0.016196547002219123
0.01672221203583613,134.134171669339,0.053093023213779705,54.08289801707749,136.3771917292449,0.01658393524813183
0.017111927456311928,133.990422150204,0.05433036967379037,54.024938210962254,136.2832565338789,0.01696716750653293
0.01750831150414873,133.838175757448,0.05558888902567221,53.96355246540304,136.1814562297564,0.017356806855696516
0.017898620769767528,133.665648048326,0.0568281209440119,53.89398929308504,136.0580787926882,0.017740326499079927
0.01829191271400843,133.523004328599,0.05807682286697676,53.83647534529112,135.9653954690899,0.018126628215608252
0.01867925845787873,133.313384744241,0.05930664560376496,53.75195672887798,135.80357991377332,0.018506943611349757
0.019075693896329828,133.166510013093,0.0605653281208472,53.69273683727909,135.7067535953453,0.018896034010069725
0.01946413136785623,133.014635668255,0.06179861709294353,53.63150110144042,135.60365001074948,0.01927712784146171
0.01985585220053933,132.891634386731,0.06304233073671237,53.58190698472994,135.53031103780205,0.019661295937353537
0.02024483590282793,132.746551888627,0.06427735399147867,53.52340972149441,135.43398404827852,0.020042633691191542
0.020647516340842928,132.624596225551,0.0655558643821763,53.474237198142156,135.36296474331573,0.020437245825239234
0.02104485535234693,132.486587928864,0.0668174157437015,53.41859225291796,135.27474900795295,0.02082647098180966
0.02145339689893103,132.363635691893,0.06811453515410601,53.36901791097125,135.20328530337667,0.02122651201154569
0.02185439234399933,132.232128570593,0.06938769569219787,53.3159942396631,135.1219813888569,0.021619008386616817
0.02225250353538413,132.020146895415,0.0706516987248446,53.23052322823133,134.95792568094717,0.02200852930376757
0.022649293753224428,131.852300184648,0.07191150766648756,53.16284743445007,134.8386616635684,0.022396606837217913
0.02304189137798213,131.695906200566,0.07315800512509325,53.09978938006821,134.73042896616437,0.02278043566967447
0.02344742676013523,131.590502677826,0.07444557996342935,53.05729067969945,134.6759613516937,0.023176758664245664
0.02383883930005003,131.47022362241,0.07568831477765885,53.00879416455571,134.60432115608626,0.023559130735189046
0.02424092112250953,131.329674878116,0.07696492456396775,52.95212491085638,134.51322716788127,0.023951773478304128
0.02463738895490993,131.177313145119,0.07822370993183902,52.89069266011198,134.40917963113532,0.024338783126850505
0.025031984216515528,130.990440189621,0.0794765498874368,52.81534548445519,134.269390820962,0.02472381621720686
0.02542982352020403,130.864549540818,0.0807396896766478,52.76458637485782,134.19241194069198,0.025111864711628643
0.02581872070577853,130.714329800124,0.08197443824084683,52.70401777541,134.08920657347642,0.025491045665910202
0.02621567800805283,130.615430589342,0.08323477767556772,52.6641416136227,134.03960266055537,0.025877937140511946
0.026621706475818328,130.49154788407,0.08452391806072318,52.614192106857026,133.9654555694149,0.026273514964775063
0.02702383430592143,130.363226155743,0.08580067392130054,52.56245278599558,133.8861403789612,0.026665138375200216
0.027432899695491328,130.234970564693,0.08709945653318496,52.510740131684216,133.80769344903948,0.02706336082321349
0.02785120270622123,130.106669905247,0.0884275685922524,52.45900930579559,133.73029714220945,0.027470412107283466
0.02825941433375713,129.982832933702,0.08972364050967888,52.40907823886865,133.65607166585102,0.027867483772121223
0.02866936657667413,129.846702666342,0.09102523888094036,52.35419051506909,133.56932538385578,0.028266089938897322
0.02907588322554993,129.725545798985,0.09231592924112102,52.30534006615075,133.497430620007,0.02866119876415483
0.02947830315257763,129.585431976583,0.09359361250943396,52.248846172958274,133.40539062454644,0.029052172132567153
0.02988893999180563,129.468486936876,0.09489738447398287,52.2016939329484,133.33816277376215,0.029450971177310024
0.030305055878640328,129.318837513356,0.09621855241468304,52.14135528538514,133.23785211035906,0.029854929147605444
0.03071575511266663,129.113626774444,0.09752252248271655,52.05861431545582,133.07944931615606,0.030253468781239516
0.03111992780373703,128.951623541482,0.09880577077686506,51.99329461192555,132.9645887562676,0.0306455200970608
0.031528783104365625,128.777113187327,0.10010388635636086,51.92293203713024,132.83729885781656,0.031041957264302165
0.03193346999701923,128.687825156333,0.10138876724053605,51.88693110303347,132.79727395994442,0.031434197924129104
0.03235184835383783,128.57016885973,0.1027171185234351,51.83949208424313,132.7296514655073,0.03183954728046846
0.03276573805319763,128.469932915599,0.10403121831890247,51.799076951569525,132.6793450852234,0.03224038615533518
0.03318335796229993,128.313357311429,0.10535716153030228,51.735945667968174,132.57122537843864,0.03264467483369239
0.03359383047848803,128.13454193547,0.10666041176919949,51.6638473083815,132.43907201568888,0.03304188506407483
0.03399201961438353,127.930972779185,0.1079246622756677,51.5817682245674,132.2796049151822,0.0334270580819696
0.03439934482424123,127.796806923562,0.1092179198169659,51.5276725515802,132.1929333523626,0.03382091508807229
0.03480929116653403,127.664158201599,0.11051949945374553,51.474188586884715,132.1080570559689,0.0342171499969413
0.03522620062323703,127.563380201109,0.11184318697877757,51.433554897087156,132.05695342425153,0.034619954165269425
0.03565273065210733,127.460985298682,0.11319741982044075,51.392269272428585,132.0053174761881,0.035031885571263195
0.03607055334689083,127.300015597282,0.11452400687637837,51.32736628882411,131.8917976009438,0.03543524320466479
0.03648756536044473,127.143299671199,0.11584802001941201,51.264178427427446,131.7824491280945,0.035837656063843454
0.03690727924415443,126.991194043912,0.1171806116001903,51.20284943850532,131.67809350403928,0.03624251275627204
0.03732886587484253,126.882494350242,0.11851914915262501,51.15902172201758,131.61887396370764,0.0366490109628387
0.03775230037802573,126.807927700587,0.11986355370023169,51.12895644887668,131.59521867745454,0.037057124646242286
0.03817490854804683,126.686816075879,0.12120533464004868,51.08012424179441,131.5230736938189,0.03746427589320495
0.03860255923191143,126.545269506229,0.12256312556131878,51.02305266491154,131.43024076786142,0.03787611654204103
0.03902196958681643,126.388598838636,0.12389475343814217,50.95988305173803,131.3205308986376,0.03827985682791508
0.03944552009013943,126.220806178261,0.12523952628619267,50.892229051074835,131.19965152415918,0.038687417216797235
0.03987161312159763,126.054669674474,0.12659237166107246,50.82524281274792,131.08067269590543,0.03909725661129535
0.04029570877427763,125.897719487785,0.12793887535833146,50.76196049747491,130.97085732761047,0.03950500809752613
0.04071806670969693,125.742747241272,0.12927986180328774,50.699475687680874,130.86274881170266,0.03991092366252063
0.04113808547215833,125.63594552108,0.1306134213741027,50.65641323409945,130.8043677863016,0.04031442778332173
0.04156319714620233,125.52299300257,0.1319631509391924,50.610870778636226,130.7401299071172,0.04072265884698468
0.04198997930176543,125.358478755068,0.13331818428310524,50.54453863404342,130.62227868329413,0.04113232649200216
0.04240792125678903,125.181765768253,0.13464514999030516,50.47328795775962,130.49046423373886,0.04153334585640703
0.042821210452018726,125.019794756421,0.13595734318515945,50.40798124578895,130.3732936983539,0.041929742774478834
0.04324383156844243,124.903206525336,0.1372991652298047,50.36097287101548,130.30449975067603,0.042334927765064194
0.04365913435306663,124.820861973651,0.13861775157098652,50.32777154777608,130.27043275662422,0.042732936486014075
0.04408583101513513,124.739195523097,0.13997251347305403,50.294843634912716,130.23842661789215,0.043141699697122636
0.044514385381073426,124.61552225517,0.14133317358490813,50.24497857328454,130.16270563730038,0.043552074424261296
0.04494508992877743,124.460007334489,0.14270066052386834,50.18227495726597,130.0538735566739,0.043964338513508866
0.045373631798384426,124.318369012241,0.14406128095987053,50.125166385735575,129.95914491357811,0.04437436390452375
0.04580461095736933,124.163738968705,0.14542963978964762,50.06281955218186,129.8510107271789,0.04478655178624051
0.04624340596794123,124.045567324114,0.1468228139482134,50.015172745082765,129.7818568524066,0.045206040262084836
0.046677599623131026,123.905076416273,0.148201378803441,49.958526811041274,129.68866796450524,0.04562095669730515
0.047123263426454426,123.784821249483,0.14961636137899278,49.91003992779155,129.61796598941896,0.04604665506998093
0.04755389864734423,123.622109611052,0.15098362820531794,49.84443459517616,129.50082288206684,0.04645782604635274
0.04798433243033243,123.450524900671,0.15235025546630546,49.77525163995055,129.37421592620382,0.046868635816041615
0.04840409531774773,123.314758665549,0.15368300263384904,49.72051069394936,129.2836979980813,0.04726909871449037
0.048836146197022826,123.187739896998,0.15505476417554745,49.6692967264696,129.2037543722886,0.04768111721083106
0.04927289888158593,123.125545115826,0.15644145394903533,49.644219790701044,129.19229765005826,0.048097447040680696
0.04970002723922603,122.990812238013,0.15779758648454265,49.58989549436685,129.1034589564168,0.04850443500914886
0.050136177524207126,122.769891543705,0.15918236363935762,49.500820270421855,128.92510462076785,0.04891984864023471
0.05056168193007653,122.560526179945,0.16053334012799297,49.416404155753824,128.7573925218382,0.049324956314119005
0.05098240297120113,122.409517544323,0.16186912943356357,49.35551747387103,128.650248895278,0.04972534862543715
0.05140708125538053,122.291260737099,0.16321748298583316,49.30783632919832,128.57789751463397,0.05012934445317672
0.05183306593717503,122.196735837808,0.16456998435053072,49.26972388980419,128.5305673037967,0.05053441915488197
0.05226914594534413,122.09937262763,0.16595453837646762,49.23046704346042,128.48140255533855,0.05094892374686436
0.052708224996498326,121.982653674438,0.16734861436388218,49.1834059615334,128.4121428299802,0.05136610548343174
0.05316282589237253,121.858471189092,0.16879197220828276,49.1333355834419,128.33681187642838,0.05179785167486534
0.05360688179018813,121.771980281699,0.1702018496838473,49.09846244958104,128.29979643401717,0.05221940311712546
0.05405749422685973,121.659549352635,0.17163254417027962,49.05313029898243,128.2361597394074,0.05264699723378334
0.05449563639355593,121.491396889639,0.17302364554954008,48.98533122590245,128.11214787948197,0.05306258284710241
0.054938001600985026,121.29306900552,0.17442815508312745,48.905365423025664,127.95666782473364,0.053481998946235336
0.05537952653891993,121.146817105335,0.17582999676107075,48.84639665687108,127.85587047832557,0.05390044303200891
0.05582322335789883,121.00221461336,0.17723873416132876,48.78809293210675,127.756948266522,0.05432076914756848
0.05626811068943053,120.941607823819,0.17865125143894192,48.76365627456382,127.74676359980734,0.054742045757097325
0.05671180345201503,120.855444846425,0.1800599759601477,48.72891536207856,127.7093750806613,0.05516201450941384
0.05716092859317593,120.71974726734,0.1814859482833336,48.67420209819149,127.62020012067467,0.05558694562386599
0.057612612928946226,120.607263412614,0.18292004604940426,48.62884860796596,127.5557629960244,0.056014116035988284
0.05806886940045163,120.466126593089,0.18436866034643393,48.57194224233349,127.46145836540136,0.05644542526886587
0.05851512370753683,120.2909330686,0.18578551777142943,48.501304213259516,127.32977189800415,0.05686709935801191
0.05895353360629143,120.123961635172,0.18717746919997527,48.43398133130135,127.20569364435197,0.05728118804216302
0.05938391508036593,119.936193901739,0.18854393038016182,48.35827338118117,127.05847465546216,0.05768752696636327
0.05982263895329353,119.752054467169,0.18993687867670694,48.28402836116255,126.91593838547358,0.05810157238195539
0.06025771439753883,119.610946098555,0.19131824321218577,48.227133466937374,126.81842832738116,0.05851200536357837
0.06069653069806673,119.48691004985,0.19271148496636184,48.17712213209952,126.73935095370786,0.05892579675752642
0.061135245101869726,119.436064615276,0.19410440319843636,48.15662125287929,126.73781769953364,0.059339320972837326
0.061591279435680026,119.33534332651,0.19555231220828406,48.11601042924884,126.6853598038859,0.05976898945396748
0.062035764418141626,119.213877887178,0.19696355202759966,48.06703556411018,126.60940193116006,0.060187598729300046
0.06248516870514903,119.082529938895,0.19839041063884816,48.01407607136246,126.52342191196281,0.06061066285326693
0.06292498936953553,118.929444529452,0.19978684124827528,47.952352034275044,126.41307856219254,0.06102453183661923
0.06336506803354683,118.762264624996,0.20118409100651116,47.88494509679839,126.28764360277698,0.061438472228959325
0.06381118800066583,118.632050435951,0.202600521902114,47.83244273577545,126.20210250922393,0.06185792028587898
0.06425757670162632,118.519365159558,0.20401780602766356,47.78700803233379,126.13513235692635,0.062277444988192814
0.06470715405606862,118.459030000165,0.20544521412801786,47.762680896066534,126.12417670371813,0.0626997886321527
0.06516457816720873,118.378927494204,0.20689753568088773,47.73038356566306,126.0930403682504,0.06312932071265547
0.06562557331297733,118.24487255911,0.208361195268703,47.676332615833154,126.00476011212153,0.06356201949591289
0.06609254999271633,118.118975161928,0.20984384622687433,47.625570785289376,125.92575943290615,0.06400014185562199
0.06655513249688733,118.040301316169,0.21131254567761726,47.59384949067934,125.89648921023914,0.06443395238628179
0.06702095472470802,117.910589881309,0.21279153125094796,47.54154984014379,125.81307018730782,0.06487061104402744
0.06749014268582683,117.769982556021,0.21428120302750017,47.48485696658767,125.7182954828342,0.06531023206004788
0.06794772878861063,117.582365647259,0.21573403890383874,47.40920982897483,125.57182033858219,0.06573879625842606
0.06839750299884333,117.391075181144,0.21716207202132756,47.33208151303727,125.42033159788375,0.0661598651102069
0.06884723000179803,117.249878354913,0.21858995525570873,47.275150952700926,125.32220769769651,0.0665807125710973
0.06929347953882643,117.085062252132,0.2200067975357739,47.208697100059624,125.19829361760233,0.06699813088366839
0.06975443082432684,116.992456696185,0.2214703178672377,47.171358539901796,125.15319892376708,0.06742911823126564
0.07021791986444643,116.87050293406,0.2229418955696174,47.12218678301299,125.07690654360137,0.06786229116195122
0.07068365415716232,116.748086607038,0.22442060194899036,47.072828519957724,125.00026798428031,0.06829737356435038
0.07113874455040593,116.643616039678,0.22586551394753882,47.030705987198175,124.94149644456027,0.06872232980756356
0.07159190761079832,116.495617766907,0.22730430666428467,46.9710330836169,124.83576127113828,0.06914530697148431
0.07204272497011392,116.330179498498,0.22873565178011168,46.9043283737944,124.71092262583227,0.0695659172369745
0.07249124496625453,116.170514958809,0.23015970276785813,46.839951631391784,124.59186021654395,0.06998420858508834
0.07294966941423613,116.053130165623,0.2316152003901997,46.7926220827792,124.51916764569252,0.07041155613112018
0.07341177550395762,115.953170572337,0.23308238722506544,46.75231837476628,124.46549869936551,0.07084215098545425
0.07388302693269892,115.867532986292,0.23457861051131906,46.71778930007294,124.4281770465436,0.07128107668468502
0.07435244540833293,115.752262653293,0.23606901417145704,46.67131230180774,124.35872644311297,0.07171810371375062
0.07482504080552653,115.626618367822,0.23756950455754672,46.62065252590583,124.27838480539931,0.07215789559491671
0.07529874245152993,115.504769712482,0.2390735072836075,46.57152314807275,124.20213361898546,0.07259852292749762
0.07576864623441833,115.378116560295,0.24056545179427818,46.52045659711094,124.12016025714547,0.07303542582773653
0.07624226621309693,115.229439077505,0.24206919522658274,46.46050983605002,124.014792647238,0.07347559086926686
0.07670658459660992,115.091915475961,0.2435434060942365,46.40506031990748,123.92022322680369,0.07390692335590449
0.07717481791783753,114.960509406082,0.24503004688913416,46.352077392532266,123.83256578723822,0.07434170433136301
0.07763795677977253,114.796962030106,0.24650051277577778,46.286135090538735,123.70956360664856,0.07477156893445518
0.07810557519123713,114.686159472054,0.24798520123217788,46.24145949913217,123.64378792409273,0.07520540386135063
0.07857575731956602,114.501728906741,0.2494780294896221,46.16709709519797,123.49878896998781,0.07564142760643547
0.07903539616656213,114.331428796111,0.25093738282883477,46.09843209059195,123.36765856530073,0.07606749034086906
0.07948932834157793,114.216963706225,0.2523786174845099,46.05227976634992,123.2959934364472,0.07648808518192264
0.07994957464710563,114.111531098925,0.2538398995045604,46.00976933908656,123.23469947261403,0.07691434990454096
0.08042588985921983,114.055623509352,0.25535220030302297,45.987227398970724,123.22864852353979,0.07735530586581497
0.08089733649142272,113.927238162511,0.25684904336026715,45.93546242712444,123.14364828368211,0.07779156327880367
0.08137876062301293,113.77898063162,0.258377564978066,45.875684990669185,123.03817306037104,0.07823685714316049
0.08185661088794342,113.651509230643,0.2598947395692204,45.82428852179526,122.95463659856327,0.07867864935772567
0.08233589558520722,113.553851404644,0.2614164684830329,45.784912886352465,122.90340945719491,0.07912157179061056
0.08281420727826183,113.39849879355,0.2629351081084813,45.722274713559365,122.78950557768277,0.07956339954213976
0.08329022122154933,113.248918041908,0.26444645237841913,45.6619637544973,122.68144547871964,0.08000291108616987
0.08376770157547073,113.081133555624,0.26596245250211953,45.5943130496276,122.55368020512748,0.08044358261287458
0.08423819224430343,112.943450480079,0.2674562603756634,45.53879923356785,122.45760257435485,0.08087761342207107
0.08470265998377594,112.786815328599,0.26893094544848856,45.47564394049112,122.34015859803026,0.08130590333702678
0.08516986173705472,112.651488387559,0.27041431101514873,45.42108011786379,122.24600007800082,0.08173652933539466
0.08564522190011013,112.541220519679,0.2719235795328497,45.37662011353457,122.17983832399612,0.0821744848058873
0.08611613186435862,112.450526291394,0.27341871866933865,45.34005220069006,122.13433064172021,0.08260815121293753
0.08659353666536374,112.331244918762,0.27493447891252987,45.29195795124484,122.05840469430078,0.08304760689871386
0.08706850676771963,112.17705795537,0.2764425089875098,45.22978976760519,121.94414688514003,0.08348462985851603
0.08754604187339322,112.041791955671,0.27795868294802345,45.175250516526546,121.8506073657922,0.08392382043934603
0.08802225569082213,111.903489201575,0.2794706618183602,45.11948684607504,121.75348674077118,0.08436160382272008
0.08849368150056923,111.791078549329,0.2809674387643073,45.074162871089456,121.68388264907844,0.0847947968989239
0.08897448052786992,111.661162255247,0.282493975675987,45.02178062131559,121.5961561620458,0.08523640981754087
0.08946658068051402,111.537285379559,0.284056393660632,44.97183346503819,121.51614492085481,0.08568820093530613
0.08996017024181333,111.434131142,0.2856235405177573,44.9302416764544,121.45876455028288,0.08614115451085488
0.09045662277700353,111.313445457188,0.2871997773169862,44.881581208338204,121.38248380291742,0.08659652849747865
0.09093746591939322,111.178101074917,0.28872645429407345,44.82701035340653,121.2883558524001,0.08703738707747485
0.09141399757053233,110.979256274525,0.2902394422864401,44.74683612988848,121.12431373798391,0.08747410102267124
0.09188264066896414,110.796677014328,0.2917273841239611,44.673220172177054,120.97696827575078,0.08790339963232523
0.09236316006759993,110.632674487165,0.29325303321462975,44.60709435322493,120.85105790952969,0.0883433861999776
0.09285644676411803,110.503888942481,0.29481921847607473,44.555168021608345,120.76488742329649,0.08879486183506241
0.09334837073008513,110.406680628179,0.29638107706802025,44.515973629281774,120.71296438253636,0.0892448873499024
0.09383860507908692,110.267832063345,0.297937571126101,44.4599898879407,120.6152116092643,0.08969316576654761
0.09431941073844152,110.117059415027,0.29946412909455183,44.39919835613889,120.5032355713023,0.0901326273261032
0.09480551311912003,109.942968252391,0.3010075041532061,44.32900479936405,120.36616777139805,0.0905767339034579
0.09529113405198893,109.796348201238,0.3025493506150648,44.26988759473917,120.25896673610102,0.09102020377631008
0.09579384324722903,109.657722269523,0.30414545230995216,44.21399361907168,120.16225692745786,0.0914790716059646
0.09627944262010132,109.523447536896,0.30568723031882167,44.159854046876475,120.06830401958025,0.09192212192179698
0.09677183852119253,109.373059958014,0.30725058730478627,44.099217775071246,119.95729205483963,0.09237117289803234
0.09725035889486072,109.203574199223,0.3087698894911828,44.03088111712671,119.823660982699,0.09280737667192251
0.09773334289090953,109.012333553882,0.31030336367863776,43.95377288892522,119.66647332844175,0.09324745648067076
0.09820726767329463,108.860313406053,0.31180807486271045,43.89247836532057,119.55118734371997,0.09367909364559518
0.09868512572709442,108.713638860954,0.3133252741835248,43.83333918873665,119.44205798019719,0.09411412456724766
0.09916972958678853,108.570487492093,0.3148638914380536,43.775620556811894,119.33739337778967,0.09455510352122692
0.09966051843323404,108.45237349386,0.31642214602551805,43.72799699272435,119.2607932615728,0.09500151256534274
0.10015933957348433,108.326183365968,0.31800590314581273,43.6771171331583,119.17606235041953,0.09545502347168743
0.10066109117022892,108.235126024238,0.3195989644654768,43.64040281297276,119.13019191278502,0.09591099125390948
0.10116651685425603,108.098110071829,0.32120369101226287,43.58515798096145,119.0340193463239,0.09637008777087791
0.10165509898937403,107.965789248181,0.32275493929126253,43.53180622486658,118.94106224167074,0.0968136844194816
0.10214064479505103,107.783551414739,0.32429654722428697,43.45832793042277,118.79263285454097,0.09725432944287166
0.10263338954253302,107.575009970942,0.32586101179754234,43.37424402028381,118.61579787433158,0.09770130926757187
0.10312879302679903,107.422533071959,0.3274339178600869,43.31276533461387,118.50088925155153,0.09815049957150457
0.10362193875061003,107.249752251127,0.32899965553318683,43.243100107654406,118.36317950991139,0.09859744242274635
0.10411845944371204,107.144721077289,0.3305761087337857,43.20075153836293,118.30046437338257,0.09904724231940037
0.10460474156570403,106.893618831289,0.33212005447111026,43.099507112775726,118.07519820415887,0.09948757103929322
0.10509862349848303,106.670019917904,0.3336881296076836,43.00935203089889,117.88089217983148,0.09993458302181649
0.10557735071853704,106.446735881316,0.3352080885313551,42.919323907346616,117.6851002483012,0.10036768785773166
0.10605944145125903,106.273839276687,0.3367387266077474,42.8496119963602,117.5451833112533,0.10080364618693309
0.10654742399065603,106.186987806293,0.3382880711703329,42.81459348349734,117.50093781838073,0.10124473904886956
0.10704247759736203,106.035995978251,0.3398598663716244,42.7537135784308,117.3863517022669,0.10169202480365573
0.10753911197033902,105.883617738658,0.3414366805058264,42.69227467222691,117.27024796248013,0.10214053786241321
0.10802509703711703,105.681365387412,0.34297968309284654,42.61072652420452,117.0976051384022,0.10257923882408837
0.10851309686419003,105.482513204991,0.3445290825438033,42.53054932425237,116.92874737788239,0.10301956494732008
0.10900843122701404,105.33949396811,0.34610176914576957,42.472883967941954,116.82238695182119,0.10346631088848683
0.10950888772784503,105.158721705013,0.34769071853590794,42.39999659146124,116.67453635381095,0.10391747392881463
0.11001624736657303,105.079431808353,0.34930158538886935,42.36802690512793,116.6398765713197,0.104374652484302
0.11052213870663202,104.924529516861,0.35090779039355663,42.30557030119836,116.52101292185161,0.10483029995428877
0.11102658775121803,104.730349984449,0.3525094161101172,42.22727711372984,116.3582033772132,0.1052844417403754
0.11152061143292903,104.42012475255,0.35407794129954967,42.102194300228156,116.06512091085709,0.10572899804948646
0.11202047914136602,104.192654170968,0.3556650212738371,42.0104781617343,115.86436521421047,0.10617861215284319
0.11252163721636503,103.986068030183,0.35725619816195897,41.92718262976979,115.68675065263152,0.10662918405237484
0.11303124871536303,103.854964227455,0.3588742146712776,41.87432157650986,115.5938205193736,0.10708714801371329
0.11354352351609803,103.683828902041,0.3605006871636112,41.80531981330293,115.45645616721897,0.1075472940785682
0.11405364596300303,103.460627176659,0.3621203259325346,41.71532487762891,115.26068891977592,0.10800529650630655
0.11454852605581703,103.239324707897,0.36369157022721904,41.62609572222407,115.06523718418448,0.10844941354716885
0.11506116865052103,103.042419353411,0.3653192104654043,41.54670348329532,114.89860054479153,0.10890926318359158
0.11556196760152902,102.805486389031,0.3669092471348546,41.4511721120573,114.68589067637963,0.10935828476082106
0.11607309097444903,102.550471303391,0.36853206384387566,41.34835002952725,114.45382148846213,0.10981635551920352
0.11658280109488903,102.287601137085,0.37015039347627265,41.24236077847268,114.21257619492313,0.11027295085134224
0.11709061992637103,102.034992925517,0.371762718266228,41.14050914756846,113.98233350134868,0.11072764475193847
0.11759603695170703,101.815733108494,0.37336741732166984,41.05210358934478,113.7888598213856,0.11117998291970636
0.11810099808261003,101.58009748024,0.3749706689122868,40.95709530403277,113.57680837798516,0.11163170883030755
0.11860507200553302,101.333892735146,0.37657110361756735,40.857825550810865,113.35260637959894,0.1120824376392448
0.11910943096738302,101.072442611394,0.37817244332144107,40.75240886091406,113.11112373732061,0.11253321808484734
0.11961396129338503,100.827526378842,0.37977432710649744,40.65365863594909,112.88790621642856,0.1129839484754689
0.12012759504106403,100.622657240939,0.38140511425537826,40.57105539954661,112.71021506193432,0.11344260296194793
0.12063915797626804,100.383466516302,0.383029326574651,40.474613699372966,112.49364339156756,0.11389919929746803
0.12115412190022302,100.068501213975,0.38466433703320807,40.34761968947472,112.19221260842554,0.11435862072373003
0.12166749222305503,99.7808455372902,0.3862942878081997,40.23163692063541,111.92093078570831,0.1148164104369777
0.12217494612931003,99.4954598661602,0.3879054539605593,40.116569418035795,111.65131231541925,0.11526871841211256
0.12268571267724503,99.2175545506054,0.38952713775025294,40.0045179948041,111.39013094073985,0.11572377254186005
0.12319428072055903,98.9546405515225,0.3911418412877749,39.89851107037388,111.14528631822878,0.11617666232537636
0.12370337901001703,98.6289136926845,0.3927582283568041,39.7671780008904,110.82964358455692,0.11662981896645902
0.12421594166797803,98.3109078974226,0.39438561479583023,39.63895806424079,110.5226898981348,0.11708585194071125
0.12471822958904603,97.9124708899795,0.39598037894522115,39.47830826283974,110.12394091406676,0.11753254169787672
0.125222984612318,97.5526098782382,0.39758297614410965,39.33321230290564,109.76843884391229,0.11798122455994793
0.125729002963809,97.2133561802272,0.3991895844100936,39.196425211867606,109.4358945275328,0.11843082842782945
0.12623918573331402,96.8873494854671,0.400809414703272,39.06497931254034,109.1183295923715,0.11888392788171526
0.126758250909786,96.6157189578015,0.4024574466385706,38.95545788378557,108.86255850328388,0.11934470531289525
0.12725986485124902,96.1738475658314,0.4040500709027156,38.77729533854322,108.41291840928373,0.11978978953492203
0.12775799281722303,95.7958046487103,0.4056316271946831,38.624868434359996,108.03448437094033,0.12023158468291358
0.128260788623404,95.4183187104185,0.4072280038793077,38.47266610404074,107.65674751733609,0.12067732194240977
0.12876782500928902,95.0757558199589,0.4088378444044926,38.33454474660743,107.31845410800925,0.1211266174376923
0.129273207124449,94.7624074037282,0.4104424326201256,38.208202665183215,107.01264772364179,0.12157424625967282
0.129796944243521,94.416594693876,0.4121052979731792,38.068770980570804,106.67158017102012,0.12203792121738767
0.130323263360503,94.0422891268769,0.41377636116959704,37.91785097595676,106.29818713978344,0.12250366558330698
0.130858339877403,93.6786563736301,0.4154752291107545,37.77123424984766,105.93728982862903,0.12297693719149747
0.131393253350189,93.215352971745,0.41717357938685007,37.58443031820759,105.46322146088879,0.12344984081049028
0.131922656169563,92.7420011395138,0.41885443333836253,37.39357485945197,104.97677226831911,0.12391765250818766
0.13244779458208,92.2404609350639,0.420521747798104,37.191353849017766,104.45750655714762,0.12438147981326265
0.132966290162173,91.7154407146131,0.4221679712648993,36.979665696132,103.91050261702392,0.12483922887789342
0.133484768174693,91.2823637902428,0.4238141389546503,36.80504908022589,103.46716895922134,0.12529675300545576
0.134015353488622,90.8232756535622,0.4254987473263748,36.61994474351628,102.9949890452689,0.12576474444549476
0.134529567665499,90.3598311377008,0.4271313773379593,36.43308391472096,102.51590015498317,0.12621808718593489
0.135034870746453,89.6764408464185,0.4287357146199883,36.15754094927594,101.78588744511657,0.1266633735860487
0.135528170533316,89.1426462609315,0.43030194144327827,35.94231497240758,101.22398602517409,0.12709789117984024
0.13603500060630402,88.6207064534,0.43191112692501527,35.73186884201088,100.67622430951937,0.12754413021720246
0.136569801076069,88.2089653983157,0.43360911841651906,35.56585484860089,100.25564625588953,0.12801478000131017
0.13711300446479802,87.711582210744,0.4353337891757337,35.36530994737198,99.73798077402024,0.1284925981013022
0.137646869331769,87.1359487569616,0.4370288101283666,35.13321453880692,99.1299393096108,0.12896197940428916
0.13818483409206803,86.5085592177242,0.43873684824231596,34.8802510765864,98.46273012076925,0.12943474263147287
0.13871635403318103,85.8532880248146,0.44042442405534976,34.61604573160525,97.76254312137745,0.12990162275217382
0.139240914232432,85.2056605584322,0.4420899026879716,34.35492233715986,97.06977463236657,0.13036217591164756
0.139775995859855,84.5776992763078,0.44378878685503964,34.1017283482073,96.39963142018905,0.13083174823898355
0.140304759661547,83.9641948105791,0.44546761192541173,33.854363347625494,95.74477098365271,0.13129555971573983
0.14084594888137,83.3668820330738,0.4471858876983497,33.61352683573535,95.10876963830331,0.13177004763795372