File: example/data/02 processed data/test_ID_139.csv
Strain,Stress_MPa,Displacement(mm),Force(kN),True Stress (MPa),True Strain
1.57449349855157e-05,-1.6520638317866,4.999016857901235e-05,-0.3330560684881786,-1.6520898434242235,1.5744811035385373e-05
4.93188698271863e-05,-0.878178697751938,0.0001565874117013165,-0.17704082546679073,-0.8782220085328174,4.931765369170009e-05
6.44996623072688e-05,0.605166471887691,0.00020478642782557842,0.12200156073255851,0.6052055049207675,6.449758229359201e-05
0.0001234207267363,3.17640043013402,0.00039186080738775247,0.6403623267150185,3.1767924637835123,0.0001234131110249359
0.0001402930414656,6.41180842176502,0.0004454304066532799,1.292620577827828,6.412707953869804,0.0001402832013171504
0.0001723282098138,9.77194656581438,0.000547142066158815,1.9700244276681789,9.773630547872463,0.0001723133630135407
0.0002390349155821,13.2283651436891,0.0007589358569731674,2.6668384129677225,13.23152718483451,0.00023900635128846614
0.0003336562018318,16.866695443968,0.001059358440815965,3.4003258015039486,16.87232312150729,0.0003336005509798801
0.0004109932728115,20.6771417915233,0.0013049036411765125,4.1685117851710976,20.685639957700587,0.00041090883821033895
0.0004535116923356,24.3871980603993,0.00143989962316553,4.916459128976499,24.398257939862997,0.0004534088869892183
0.0004988025667742,28.0053941999713,0.0015836981495080849,5.6458874707142135,28.01936336248177,0.0004986782061265038
0.0005145387746559,31.5871454663446,0.0016336606095324825,6.367968526015073,31.603398277467733,0.0005144064449711484
0.0005563548996662,35.1009031599509,0.001766426806440185,7.076342077046101,35.120431719406646,0.0005562001916579552
0.0006230201960347,38.5189451813117,0.0019780891224101724,7.765419348552439,38.54294326208961,0.0006228261995239765
0.0006825695663605,41.8330354413862,0.0021671583731945874,8.433539944983458,41.86158939824698,0.0006823367217032237
0.0007524510813861,45.0145238135373,0.0023890321834008675,9.074928000809122,45.04839504065888,0.0007521681319993194
0.0007928131943133,48.13152634567,0.0025171818919447276,9.703315711287072,48.16968565481928,0.0007924990839424083
0.0008483029107753,51.168805162703,0.0026933617417115776,10.315631120800925,51.21221180906342,0.0008479433052163548
0.0009011554323953,54.0935713103036,0.0028611684978550773,10.905263976157208,54.14231802594754,0.000900749635610902
0.0009714729283885,57.0351509504363,0.0030844265476334875,11.498286431607958,57.090559055551196,0.0009710013539530296
0.0010424785910091,59.9409742340374,0.0033098695264538926,12.084100405581939,60.003461416400604,0.001041935587549565
0.0011102282325805,62.7927560309966,0.003524974638443087,12.659019615848916,62.86247032154375,0.0011096123849951177
0.0011905949173589,65.5992041876266,0.003780138862614507,13.224799564225522,65.67730626671518,0.0011898867212910256
0.0012766596615176,68.2392619576809,0.00405339442531838,13.75703521066847,68.326380270754,0.0012758454245007066
0.0013715006346957,70.6684744819443,0.004354514515158847,14.24676445555997,70.76539633954927,0.0013705609867539351
0.0014609126698702,73.0312584113135,0.004638397726837885,14.723101695720802,73.13795070202315,0.0014598465751435334
0.0015677651812764,75.0691545501929,0.00497765445055257,15.13394155731889,75.18684535688456,0.0015665375203997808
0.0016794036950226,76.9695329323008,0.005332106731696754,15.517057839151839,77.09879585031146,0.001677995073512675
0.0018216064351817,78.6204086272544,0.005783600431701897,15.849874379254489,78.76362406954642,0.0018199493222791822
0.0020037483446668,80.0827283195709,0.00636190099431709,16.144678029225496,80.24319395387765,0.0020017435186170415
0.0022067703335259,81.2923503635678,0.007006495808944731,16.38853783329527,81.47174391069272,0.0022043389921578608
0.0024605184525705,82.1716209299744,0.0078121460869113365,16.56579877948284,82.37380571955023,0.0024574963333477817
0.0027406497282623,82.7803462365822,0.0087015628872328,16.68851780129497,83.00721817000095,0.002736900995542615
0.0030187064315067,83.1855256716259,0.009584392920033772,16.77020197539978,83.43663835297909,0.003014159285946829
0.0033482364123111,83.4210337463432,0.010630650609087742,16.817680403262788,83.70034708908534,0.0033426435494490984
0.003696330108772,83.5653067709417,0.011735848095351099,16.84676584502185,83.8741917304079,0.003689515468247015
0.0040712848358611,83.6330088192819,0.012926329353858991,16.86041457796723,83.97350261986527,0.004063019581628576
0.0044263160372871,83.678344827517,0.014053553418386542,16.869554317227426,84.04873162720067,0.004416548712028717
0.004776429695886,83.6992427019058,0.01516516428443805,16.87376732870421,84.09902625027037,0.004765058749541136
0.0051624494789728,83.7258046874387,0.016390777095738638,16.87912222498764,84.15803492422394,0.0051491697211059504
0.0055332006811659,83.7198071975292,0.017567912162701732,16.877913131021888,84.18304569174165,0.005517948761698548
0.0059313952889277,83.7278325429362,0.018832180042345447,16.879531040655937,84.22445541443349,0.0059138738142808425
0.0063063385911064,83.7000590054999,0.02002262502676282,16.87393189550878,84.22789991768417,0.006286536845298542
0.0066845383505259,83.6756908368761,0.021223409262919733,16.869019272714223,84.23502420128195,0.006662295889417046
0.007072824934062,83.6270406722075,0.022456219165646846,16.859211399517033,84.21852009063569,0.0070479298246938354
0.0074461371107875,83.5729337961614,0.02364148532675031,16.848303453306137,84.19522931995837,0.007418551484784638
0.0078278063213954,83.5116738760793,0.024853285070430393,16.835953453417588,84.16538708475679,0.007797327994464721
0.0082114216182415,83.4263103368712,0.02607126363791676,16.818744163913234,84.1113589451015,0.008177891324939056
0.0086151745692402,83.3733813980629,0.027353179257337632,16.808073689849483,84.09165763323506,0.008578275727996588
0.0090299585627066,83.2779005644948,0.02867011843659345,16.788824753802153,84.02989655578138,0.008989432271333505
0.0094400485112789,83.2061750598792,0.029972154023310507,16.774364892071645,83.99164538888242,0.009395769697976137
0.0098456275661427,83.1437597616637,0.03125986752250307,16.7617819679514,83.96236225472589,0.00979747517741639
0.0102504219725599,83.0918544942174,0.03254508976287768,16.751317866034228,83.94358106526568,0.010198242667583594
0.0106820568474341,83.0209960271818,0.033915530490603266,16.73703279907985,83.90783102627476,0.01062540674749354
0.0110949723400191,82.9293236344248,0.03522653717956064,16.71855164470004,83.84942218632524,0.011033874637240997
0.011507604400265,82.8032633748095,0.03653664397084137,16.693137896361595,83.75613057277778,0.011441895541313642
0.0119338210039609,82.7039365019228,0.03788988168757586,16.673113598787637,83.6909104764597,0.011863174462114979
0.0123501184150153,82.5766723061018,0.03921162596767357,16.647457136910123,83.59650398740007,0.012274477845811692
0.0127776108774297,82.4671935482282,0.040568914535839294,16.625386219322806,83.52092725754115,0.012696665999754685
0.0132009095407826,82.3646009329861,0.04191288779198475,16.604703548089997,83.4518885792651,0.013114536836238143
0.0136096356791493,82.2408154310666,0.043210593281299024,16.579748390903028,83.36008296703957,0.013517856371821959
0.0140341084808364,82.161383864369,0.04455829442665557,16.56373498705679,83.3144456384572,0.01393654215832705
0.0144563507863471,82.0281926238419,0.04589891374665204,16.53688363296653,83.21402095078221,0.014352854011981674
0.0148698668620037,81.8982383908109,0.04721182728686175,16.510684859587478,83.1160542919149,0.014760394285973916
0.0153036077779946,81.7603053065272,0.04858895469513285,16.482877549795884,83.0115329507474,0.0151876887295359
0.0157356250604513,81.6285028588673,0.04996060956693287,16.456306176347645,82.9129783741004,0.015613103740715445
0.0161656797085605,81.5196705873293,0.05132603307467959,16.434365590405587,82.83749147199143,0.016036406441020376
0.0166163033755632,81.3791707889399,0.05275676321741316,16.406040831050284,82.7313917792207,0.016479763060799634
0.0170723872780919,81.2623731536137,0.05420482960794178,16.38249442776852,82.64971585922899,0.016928291798035296
0.0174961938195274,81.0948096136103,0.05555041537699949,16.348713618103837,82.5136601203677,0.017344897609707404
0.0179420965328888,80.945477557847,0.05696615649192194,16.318608275661955,82.39780913009066,0.01778303687691867
0.0183873143582697,80.8140601029035,0.058379723087506295,16.292114516745347,82.30001363058369,0.018220311740301805
0.0188522076766175,80.6786390148977,0.05985575937326056,16.264813625403377,82.1996094726734,0.018676707094298323
0.0193038380203936,80.505037170605,0.06128968571474968,16.229815493593968,82.05909336797211,0.019119882534296046
0.0197570319065856,80.4050214290652,0.06272857630340928,16.209652320099543,81.99358600288895,0.01956439490794629
0.0202073443569727,80.2131190792725,0.06415831833338832,16.17096480638134,81.83401319845423,0.020005885419193677
0.0206566550102622,80.1238713742594,0.06558487965758249,16.152972469050695,81.7789625433241,0.020446199580929098
0.0211416237919828,79.9554177735899,0.06712465553954539,16.119012223155725,81.64580513628995,0.020921240426908294
0.0216053296527551,79.8333713066337,0.06859692164749744,16.094407655417353,81.55819761100432,0.02137524268886763
0.0220655526002771,79.7141513514695,0.0700581295058798,16.07037291245625,81.47308815110179,0.02182563121208641
0.0225334300447484,79.5737856277576,0.07154364039207617,16.042075182555934,81.36685595959648,0.022283302820660676
0.0229655435649569,79.473719904202,0.07291560081873814,16.021901932687125,81.29887708093113,0.0227058046475611
0.0234605568898967,79.3441653993025,0.07448726812542202,15.995783744499384,81.20562370553421,0.023189587897280574
0.02394093832809,79.241299834896,0.07601247919168574,15.975046046715034,81.13841090728093,0.0236588475399354
0.02442403817588,79.1050002857636,0.07754632120841899,15.94756805760994,81.03706383264608,0.024130540682796908
0.0248752019829076,78.9854227927932,0.07897876629573163,15.92346123502711,80.95020113846928,0.024570851014714627
0.025359279323486,78.8180893556551,0.08051571185206804,15.88972681410007,80.81685929936864,0.025043067587001904
0.0258557120911964,78.6818870506623,0.08209188588954856,15.862268429413518,80.71626326903626,0.02552710536898062
0.0263689935962604,78.5182766657251,0.08372155466812677,15.82928457581018,80.588724600313,0.02602732497392367
0.0268644171492496,78.3884630351125,0.08529452444886748,15.80311414787868,80.49432340577629,0.026509903876070013
0.027361872949442,78.2260012125793,0.08687394661447835,15.770361844455989,80.3664111191008,0.026994228132179658
0.0278502912059873,78.0951467752849,0.08842467457900967,15.743981589897437,80.2701193547509,0.027469525305151295
0.0283383564322365,77.9460002321571,0.08997428167235087,15.713913646802874,80.15486176920317,0.02794425337640689
0.0288083251969851,77.7624935650695,0.09146643250042769,15.676918702718012,80.00270076782049,0.028401166611735872
0.0292952454999087,77.623632805613,0.09301240446221011,15.64892437361158,79.8976361852482,0.02887434038096811
0.029794266565137,77.4573665101111,0.09459679634430997,15.615405088438397,79.76515193534686,0.029359041091718243
0.0302887570348906,77.3293906305428,0.09616680358577764,15.58960515111743,79.67160175500746,0.029839109587585455
0.0307961467028739,77.1803661145706,0.09777776578162463,15.559561808697433,79.55722399201643,0.030331461627341624
0.0313023951759988,77.0209965852785,0.09938510468379619,15.527432911592145,79.43193825724013,0.030822464819491985
0.0318022950921657,76.9160803342809,0.1009722869176261,15.50628179539103,79.36218821840443,0.031307074183532804
0.0323041792390673,76.7643867242674,0.10256576908403868,15.475700363612306,79.2441972321852,0.031793370954589464
0.0328136998509722,76.6468232633432,0.10418349702683673,15.451999569889988,79.16188911643705,0.03228682522894636
0.0333250210947257,76.520884086921,0.1058069419757541,15.426610231923274,79.07094416330472,0.032781778688758645
0.0338575186688299,76.4049679526007,0.10749762177353492,15.403241539244302,78.99185058144722,0.033296970333075736
0.0343824104800996,76.2633414789385,0.10916415327431622,15.374689642154001,78.88545899025137,0.033804543767996034
0.0349145329100708,76.1350082215574,0.11085364198947478,15.348817657465972,78.79322647171747,0.034318846409190334
0.0354393555349176,75.9838746213125,0.11251995382336338,15.3183491236566,78.67669416893779,0.03482583474487281
0.0359603815642803,75.8078214023353,0.11417421146658996,15.2828567947108,78.5338995855201,0.035328901372737496
0.036501521308884,75.6660310151802,0.11589233015570669,15.254271852660327,78.42795625863947,0.03585112062912175
0.0370352809484884,75.5409247816916,0.11758701701145068,15.229050435989027,78.33860415409018,0.036365950798340624
0.0375654382080141,75.4140036602511,0.11927026631044475,15.203463137906622,78.24696375476921,0.03687704410528
0.0380934586669074,75.2512235303542,0.120946731267431,15.170646663719406,78.11780290354196,0.03738581794194284
0.0386238689336369,75.1093139799297,0.12263078386429715,15.142037698353827,78.01032627878588,0.037896633998816306
0.0391538323949185,74.9543130612109,0.12431341785386624,15.110789513140118,77.8890616720858,0.03840675928549677
0.0396755900870357,74.8162135195352,0.12596999852633833,15.082948645538295,77.78459093900042,0.03890873188356613
0.0402171559570337,74.6428851043879,0.12768947016358198,15.0480056370446,77.64480965571401,0.03942949516164099
0.0407389853558481,74.4715927684115,0.1293462785048177,15.01347310211176,77.5054898956305,0.039931023665190614
0.0412676558713126,74.3416637663789,0.1310248073914175,14.987279415301987,77.40956996359066,0.04043887077418459
0.0418012046610346,74.2423467171022,0.13271882479878483,14.967257098167803,77.34576624673927,0.040951142654868926
0.0423687881471992,74.1572632467759,0.13452090236735745,14.950104270550021,77.29921662285463,0.04149580408090871
0.0429452386261897,74.035545902754,0.1363511326381523,14.925566053995206,77.215020088368,0.04204867092616332
0.0434971854408087,73.8891944326663,0.13810356377456762,14.896061597625526,77.10316642497595,0.04257775030178139
0.0440561947952262,73.7385748120172,0.13987841847484317,14.86569668210267,76.9872158278578,0.043113314444065624
0.0446246527865799,73.5974529743218,0.14168327259739116,14.837246519623275,76.88171375927755,0.043657636958486463
0.0451864456770925,73.4678970454788,0.1434669650247687,14.811128044368525,76.78765018433455,0.0441952864182473
0.045755678378539,73.3364411920597,0.1452742788518613,14.784626544319236,76.6919998086702,0.04473976128339071
0.0463178050767408,73.2009461709889,0.147059031118652,14.757310748071363,76.59145332716976,0.045277148441322926
0.0468585234996408,73.0216576884463,0.14877581211135954,14.721166189990775,76.44334475122308,0.04579379716082707
0.0473953625025702,72.8859374763152,0.15048027594566038,14.693804995225147,76.34039290434484,0.04630647522557952
0.0479716506038664,72.7597510617081,0.1523099906672758,14.668365814040353,76.25015641766466,0.04685653458245763
0.0485593176630874,72.6462586551697,0.15417583358030248,14.645485744882212,76.1739114062409,0.04741714359182322
0.0491516951893948,72.5513967090328,0.15605663222632848,14.626361576541013,76.11742084564005,0.04798192829135952
0.0497512844109827,72.4081073893828,0.15796032800487006,14.597474449699574,76.01050373377296,0.048553264121291
0.0503218919117761,72.268600463578,0.1597720068198891,14.569349853457325,75.9052931647215,0.04909668091387565
0.050886330246652,72.0724846970509,0.1615640985331201,14.52981291492546,75.7399889550418,0.04963393214152669
0.0514407774903815,71.9320215372071,0.16332446853196125,14.501495541900951,75.63226065153592,0.05016139264426546
0.0520101155646499,71.7322077734844,0.16513211691776342,14.461213087134457,75.46300818949081,0.05070272982503987
0.0525771384858562,71.5885474445629,0.16693241469259343,14.432251164823882,75.35246841755698,0.05124157461166939
0.0531447044971116,71.4435351213133,0.16873443677832933,14.403016680456762,75.24038068356451,0.0517806448852586
0.0537106771368201,71.3242903991324,0.1705313999094038,14.378976944465093,75.15516633277299,0.0523179125669956
0.0542998235012091,71.2728319939463,0.17240193961633887,14.368602929979575,75.1429341916489,0.05287687219224404
0.0548956360680459,71.1955970920447,0.17429364451604573,14.353032373756209,75.10392467965681,0.05344183887656119
0.0554760032091174,71.0907513022499,0.17613631018894774,14.33189546253358,75.03458204963209,0.0539918530493267
0.0560744856632961,70.9615125928139,0.1780364919809651,14.305840938711283,74.94064291334546,0.054558718462546806
0.0566577950062329,70.8335225858064,0.17988849914478944,14.280038153298571,74.84679378804239,0.05511090329267877
0.0572661299629223,70.7068396469104,0.18181996263227831,14.254498872817138,74.75594671539787,0.05568645378084624
0.0578887249076428,70.5799175815074,0.18379670158176586,14.228911384431893,74.66569901438739,0.05627515295931796
0.0585229336809888,70.4548987845477,0.18581031443713944,14.203707594964815,74.57812615361655,0.056874477565904524
0.0591429361660025,70.3060222946992,0.18777882232705792,14.17369409461136,74.46412688336015,0.05746003028369351
0.0597499949052896,70.1443356573924,0.18970623382429447,14.14109806853031,74.33545935555652,0.05803302644314499
0.0603750074817141,70.02198958633,0.19169064875444225,14.116433100604127,74.24956773148918,0.05862262620148656
0.060989983274775,69.8920677360134,0.1936431968974106,14.090240855580303,74.15478377827229,0.05920241875295021
0.0616318529002852,69.7601840755776,0.1956811329584055,14.063653109636444,74.05963347882042,0.05980720820167439
0.0622601875300689,69.6340927291964,0.19767609540796874,14.038233094205994,73.96952440100237,0.0603988904869825
0.0628594796138988,69.4228633226559,0.19957884777412868,13.995649245847432,73.78674838442487,0.0609628983487343
0.0634453202655701,69.2188190068792,0.20143889184318503,13.954513911786847,73.61042914717518,0.06151393944738437
0.0640184033223605,69.0496725697142,0.20325843054849457,13.920413990054383,73.4701223575591,0.06205268712547441
0.0646118242071777,68.9031985764906,0.20514254185778918,13.890884833020506,73.35515993022707,0.06261024840832746
0.0652255318030916,68.8642142361047,0.20709106347481582,13.88302558999871,73.35591923185666,0.06318654369319246
0.0658406066482508,68.7164101676828,0.20904392610819628,13.853228289804852,73.24074029981307,0.06376378984350241
0.066463158002829,68.5932097465366,0.21102052665898205,13.82839108490178,73.15213108384185,0.06434771356261576
0.0670917673447636,68.4481756801502,0.21301636131962443,13.79915221711828,73.04048475805634,0.064936973630548
0.0677134284857211,68.3157762801883,0.21499013544216447,13.772460498085962,72.94167171178336,0.06551937914440358
0.0683446914752067,68.2242057713867,0.21699439543378127,13.753999883511561,72.88696806597314,0.06611043329406735
0.0689618729436236,68.1142168257667,0.21895394659600492,13.731826112074568,72.81150079215966,0.06668796531108953
0.0695947742654329,67.9760190799896,0.22096340829274944,13.703965446525904,72.70679478332423,0.06727986110315351
0.070235569552162,67.8439381473851,0.22299793332811432,13.677337930512838,72.60899578382833,0.06787878270246189
0.0708819899288911,67.7041092503621,0.22505031802422923,13.649148424873,72.5031112403908,0.06848259858684133
0.0715315127283136,67.5557180372489,0.22711255291239565,13.619232756309378,72.38808074190072,0.06908894541812954
0.0721580807223439,67.4021473497522,0.2291019062934419,13.588272905710044,72.26575693907493,0.06967351513735308
0.0727975261117496,67.2663958908616,0.23113214540480495,13.560905411597698,72.16322310216988,0.07026974697199939
0.073446539733092,67.1319632596156,0.23319276365256708,13.533803793138507,72.06257366652342,0.0708745371274652
0.0740778891913297,66.9894338777974,0.23519729818247176,13.505069869763954,71.95186973758678,0.07146251598155728
0.0747369112938026,66.8440819520295,0.23728969335782324,13.475766921529148,71.839802175394,0.07207589794726837
0.0753877948076271,66.6761164439835,0.23935624851421602,13.441905075107075,71.70268182903199,0.07268133588476067
0.0760248260265848,66.5280606735538,0.24137882263440671,13.412057031788445,71.5858449121468,0.07327353398883965
0.0766706138408987,66.3734058370961,0.24342919894485335,13.380878616758574,71.46229560533736,0.07387351466583328
0.0772949413104063,66.2069232621801,0.24541143866054,13.34731572965551,71.32438351007288,0.07445321519586104
0.0778740464223826,66.0447700993937,0.24725009739106477,13.31462565203777,71.18794359206947,0.07499062560702621
0.0785095813413675,65.8423599427435,0.2492679207588418,13.27381976445709,71.01161605637591,0.07558007075881032
0.0791187339875792,65.7379257686083,0.2512019804105639,13.252765834951436,70.93902723039005,0.07614472098894373
0.0797663758583206,65.5787190488528,0.2532582433501679,13.220669760248725,70.80969580081081,0.07674469908617149
0.0803776640959273,65.4687297832455,0.25519908350456916,13.198495924302293,70.73095335455022,0.07731066898689806
0.0810094116802052,65.2807287185782,0.2572048820846515,13.160594909665365,70.5690821461253,0.0778952450763443
0.08164791351055,65.1434156256819,0.2592321253959962,13.13291259013747,70.46223959046938,0.07848572405926905
0.0823094895972718,65.0394719600742,0.26133262947133795,13.111957547150958,70.39283770078397,0.07909717427209098
0.0829984084300777,64.9426605393282,0.2635199467654967,13.092440364728565,70.33279800330725,0.07973349842412428
0.0836436800326063,64.7556777542368,0.265568684103525,13.05474463525414,70.17208094460675,0.08032914052398259
0.0843034246383785,64.5645758046695,0.26766337322685174,13.016218482221372,70.00759065532733,0.08093777587741607
0.0849404832074017,64.4008505282933,0.2696860341835004,12.983211466503931,69.87108989113419,0.08152513130115037
0.0855769997547286,64.2439698281987,0.2717069742212633,12.95158431736486,69.74177601842925,0.08211164264747217
0.0862473167189177,64.0970167819927,0.27383523058256365,12.92195858324973,69.62521248912702,0.08272892737017228
0.0868885003767895,63.9302043001735,0.2758709886963066,12.888329186914978,69.48500388059735,0.08331902732750912
0.0875286062256622,63.7564483819973,0.2779033247664775,12.853299993810657,69.3369614467719,0.08390778821006437
0.0881690409582393,63.5350858257262,0.27993670504240975,12.808673302466403,69.1369134101799,0.08449650489310456
0.0888196683270863,63.3510826343499,0.282002446938499,12.77157825908494,68.9779047820947,0.08509423641595866
0.0894662291352946,63.1602363386335,0.28405527750456033,12.733103645868514,68.81094451514504,0.08568787825879422
0.0900991648554638,62.9696853271949,0.2860648484160976,12.694688561962492,68.64320138638652,0.0862686690345205
0.0907366547645816,62.7831755793247,0.2880888788775466,12.657088196791861,68.47991090689,0.08685329803000917
0.0913825966738878,62.5845322811365,0.2901397444395938,12.617041707877117,68.3036693526075,0.08744532976956444
0.0920323995802679,62.4115742192867,0.29220286866735057,12.582173362608199,68.15546115626964,0.08804054682786944
0.0926900917567161,62.2460788051821,0.2942910413275736,12.54880948712471,68.01567356113021,0.08864262988319954
0.09333423586399,62.0445680848259,0.29633619886816825,12.5081849259009,67.83545043653442,0.0892319592129586
0.0939902076061956,61.8632328995341,0.298418909149671,12.471627752546073,67.67777100295173,0.0898317529599078
0.0946687582209521,61.6605847203331,0.3005733073515229,12.430773879619153,67.49791570698484,0.0904518135971213
0.0953340632979328,61.4622643373257,0.30268565097093664,12.390792490404861,67.32171173609458,0.09105939737821084
0.0959943422870796,61.2420392079006,0.30478203676147775,12.346395104312762,67.12092848198257,0.09166202636567478
0.0966570301445862,61.0305497156852,0.30688607070906115,12.303758822682138,66.92958139929485,0.09226648896836295
0.0972860730261912,60.7987004397196,0.30888328185815705,12.257018008647472,66.71356725059569,0.09283992489560583
0.0979298086631129,60.5460696207471,0.31092714250538345,12.206087635542616,66.47533463401037,0.09342641450762368
0.0985625977374838,60.3522257640289,0.312936247816511,12.167008714028228,66.30069791457069,0.09400259595949972
0.0992096829350298,60.1363343505625,0.31499074331871957,12.123485005073402,66.10244101435674,0.09459145152195689
0.0998983152138519,60.0170759809234,0.31717715080397973,12.099442517754158,66.0126807554794,0.09521773481673862
0.10059175951798,59.8187345107531,0.3193788364695865,12.059456877367825,65.83600626732867,0.09584799835216253
0.101254080067141,59.5696340956294,0.3214817042131726,12.009238233678886,65.60130259591855,0.09644960320317426
0.101926336696771,59.3198632431209,0.3236161190122479,11.958884429813175,65.36611959684565,0.09705986339374074
0.102590696835885,59.0612102952169,0.32572546245393486,11.906739995515727,65.12034101537395,0.09766258965905936
0.103268734805567,58.8292674069676,0.3278782330076752,11.859980309244667,64.90449142162352,0.09827735049223879
0.103957684769909,58.6138971088138,0.33006564914446107,11.816561657136862,64.70726214758776,0.09890161810756468
0.104642260832663,58.3639620228251,0.332239178143705,11.766174743801539,64.4712989600452,0.09952153669992031
0.105310862682018,58.0939621493754,0.33436198901540715,11.71174276931408,64.21188741994263,0.10012661909975973
0.105991853345325,57.8431306509728,0.3365241343714069,11.661175139236118,63.97403127196519,0.10074253720079519
0.106684944114958,57.5796049845078,0.33872469756499163,11.608048364876772,63.722481924441375,0.10136900989043202
0.107373751680066,57.3612550606401,0.34091166158420955,11.564029020225044,63.52034821757819,0.10199122247100965
0.10805517864739,57.0939152255913,0.34307519220546323,11.510133309479206,63.26320843497151,0.10260638730837829
0.108739054751264,56.7958780651758,0.34524649883526315,11.450049017939442,62.971808159751056,0.10322338289169902
0.109423594193585,56.4945677227001,0.3474199115646323,11.38930485289634,62.67640637533084,0.1038405959390634
0.110079724069989,56.2162372039634,0.34950312392221505,11.333193420319022,62.40450508362875,0.10443183623153635
0.110766254214912,55.9228661943093,0.3516828571323456,11.274049824772757,62.11723260761467,0.10505009627613573
0.111446938053253,55.6536757927249,0.35384402831907824,11.21978103981334,61.85610755123253,0.10566271423916272
0.112134359292661,55.340502321196,0.3560265907541986,11.156645267953113,61.546074091917326,0.1062810152314658
0.112845652796362,55.0570941960318,0.3582849476284493,11.09951018992001,61.2700479316538,0.10692038594407215
0.11352075846729,54.7291047526726,0.36042840813364574,11.033387518138795,60.94199423443175,0.10752685008061716
0.114186154754956,54.4161837351216,0.3625410413469853,10.970302641000515,60.62975851227432,0.10812423235160161
0.114844031583184,54.1100114416575,0.3646298002766092,10.908578306638152,60.32422330462966,0.10871451313950856
0.115514493417265,53.7793779912609,0.36675851659981634,10.841922603038197,59.991675596217014,0.10931572756020456
0.116183518950035,53.4388440058993,0.3688826726663611,10.773270951589298,59.64755695112667,0.10991529394338402
0.116887909788892,53.1288845187805,0.3711191135797321,10.710783118986148,59.33900877959618,0.11054616571322876
0.117636825426422,52.8185178478262,0.3734969207288898,10.648213198121763,59.031920611173284,0.11121647887089421
0.118367291888453,52.5755326939367,0.37581615174583827,10.599227391097639,58.798756118510816,0.11186984661951357
0.119050838549083,52.2087604541906,0.37798641239333847,10.525286107564826,58.424257165870195,0.11248086042385988
0.119743492138729,51.8520255279796,0.38018558754046455,10.453368346440687,58.0609681391664,0.11309963420066645
0.120413739065513,51.474481747846,0.38231362153300374,10.377255520365754,57.67271656156363,0.11369802697189473
0.121111425525281,51.1440406258143,0.38452877604276714,10.310638590164162,57.33816829312955,0.11432053747797333
0.121814944401303,50.7862402698992,0.386762448474137,10.23850603841168,56.97276330472819,0.11494785980876976
0.122489941064293,50.4316456747207,0.38890556287913025,10.167019768023692,56.609014981192544,0.11554937940418118
0.123187299757271,50.0456653815026,0.3911196767293354,10.089206140910925,56.21065576440584,0.11617044702932089
0.123872273257274,49.5973564426292,0.39329446759184494,9.998827058834047,55.74109373272898,0.1167801091223471
0.124621052116938,49.1884934578164,0.3956718404712781,9.916400281095786,55.3184152645766,0.11744613634946269
0.124992082005055,49.0123621779381,0.39684986036604963,9.88089221507232,55.138519370544394,0.11777599741388615