File: example/data/02 processed data/test_ID_091.csv
Strain,Stress_MPa,Displacement(mm),Force(kN),True Stress (MPa),True Strain
0.0008612739599962995,0.180215682193762,-5.693172598654667e-06,0.0363314815302624,0.1802153590444757,-1.793126835617782e-06
0.0008369070929936996,0.444403794001793,-8.305797533171589e-05,0.0895918048707614,0.4443921684019947,-2.616033440899888e-05
0.0008094133662805995,0.908100186954411,-0.0001703505576458,0.1830729976900092,0.9080514640022076,-5.365515835587872e-05
0.0007708128116470995,1.43178179756545,-0.0002929073186071,0.2886472103891947,1.4316497095757947,-9.225852926429924e-05
0.0007107805676789996,2.24465837215758,-0.000483509693206,0.4525231278269682,2.2443165409510057,-0.0001522981143142
0.0006349548118739995,3.53086790382797,-0.0007242564678868,0.7118229694117187,3.5300624695235285,-0.0002281382949121
0.0005737227516686995,5.11187294754885,-0.0009186682590387,1.030553586225848,5.1103938560776205,-0.0002893862017036
0.0005092728268179995,6.94267643521713,-0.0011232967704396,1.3996435693397735,6.9402201561563786,-0.0003538568583602
0.00044937126343729954,8.88793022328841,-0.0013134842341734,1.7918067330149436,8.884253323690704,-0.0004137814175112
0.00039630741442859955,10.8677179963825,-0.001481961954776,2.190931948070712,10.86264538390821,-0.0004668686369993
0.00037402906187229955,12.9699793316721,-0.0015526957241422,2.614747833265095,12.963636518616823,-0.0004891576414461
0.0003819879673077996,15.2738660746441,-0.0015274261993845,3.079211400648251,15.266518136625738,-0.0004811948736018
0.0004025088217201996,17.4173515405234,-0.0014622724866252,3.511338070569517,17.409329835343055,-0.0004606643530358
0.00040543824830589954,19.6910271837788,-0.0014529715572156,3.969711080249806,19.682016001910963,-0.0004577335809515
0.00041996395801969957,22.071080076262,-0.0014068524288742,4.449529743374419,22.061300311659423,-0.0004432013264045
0.0004620347093290996,24.5480531918034,-0.0012732777934669,4.948887523467566,24.538208627708293,-0.0004011128108837
0.0005155974743242996,27.1418791105879,-0.0011032160146071,5.47180282869452,27.13244813241425,-0.0003475299924527
0.0005631736735361996,29.8479206262761,-0.0009521615821093,6.017340798257262,29.83896943152769,-0.0002999383887096
0.0005973992805998995,32.5799358286726,-0.0008434952796821,6.568115063060397,32.5712803886462,-0.000265703100567
0.0006355093837075996,35.3882940539812,-0.0007224957023152,7.13428008128261,35.38024117512568,-0.0002275835966988
0.0006948283471323995,38.2062002347744,-0.0005341579934414,7.70236996733052,38.19977247185962,-0.0001682528918157
0.0007556202449799995,41.0839204642689,-0.0003411437177753,8.28251836559661,41.07950612683017,-0.0001074526130694
0.0008087115628571996,43.9704683387317,-0.0001725787835153,8.864446417088311,43.96807830095643,-5.435699968192855e-05
0.0008565639171509995,46.8849759238353,-2.0647558632405305e-05,9.452011146245196,46.88467102295676,-6.503189218846709e-06
0.0009066984245637995,49.8009465870907,0.0001385295024032,10.039870831957485,49.80311946909068,4.363038752051112e-05
0.0009623042152207996,52.7000466700169,0.0003150778877392,10.624329408675408,52.70527647139912,9.92322063183523e-05
0.0010208680824905995,55.6440974757175,0.0005010181663208,11.21785005110465,55.652878169791165,0.0001577885479987
0.0010700380033116996,58.5710231398959,0.0006571326649278,11.807918265003014,58.58314563832848,0.0002069495025618
0.0011170234112723996,61.5180027124613,0.000806311335203,12.4020293468322,61.53362559841598,0.0002539240845989
0.0011678431240859995,64.4721097939928,0.0009676639233862,12.99757733446895,64.49175934823288,0.0003047296040793
0.0012263772248593996,67.3971968208761,0.0011535096933417,13.587274879088625,67.42168290586412,0.000363244158487
0.0012755471392042995,70.3190669755596,0.0013096241713868,14.176323902272811,70.34807218810151,0.0004123950074685
0.0013292833246777995,73.2665077682814,0.0014802365602651,14.770527966085533,73.30066580401102,0.0004661075944293
0.0013853894619706997,76.1928675539515,0.0016583735461701,15.360482098876624,76.23266479362341,0.0005221860138954
0.0014423697609743996,79.1487533871277,0.0018392859955068,15.956388682844944,79.19460447174714,0.0005791349447299
0.0014994392965590995,82.1265091516043,0.0020204817709883,16.556704244963427,82.17877217984233,0.000636169812402
0.0015531501463556996,85.1142798632645,0.0021910137190925,17.159038820434123,85.17301578605856,0.0006898450633018
0.0016028265361091995,88.1382906404811,0.0023487362565598,17.76867939312099,88.20349177396724,0.0007394859637304
0.0016626549271030995,91.1790504811096,0.0025386913979655,18.381696576991693,91.25195614130836,0.0007992683418214
0.0017235620318006995,94.2599370100408,0.0027320714553803,19.002803301224223,94.34104720950256,0.0008601249330478
0.0017793607422103995,97.2795773299732,0.0029092323609311,19.6115627897226,97.36871398963494,0.0009158741162154
0.0018313345171560996,100.310701729856,0.0030742490963837,20.222637468738974,100.40782931541526,0.0009677989633994
0.0018871317192317996,103.297823748451,0.0032514052129741,20.82484126768772,103.40360739652174,0.0010235406375273
0.0019413381533912996,106.290459996219,0.0034235106414305,21.42815673523775,106.4050699240551,0.0010776901514718
0.0019993767425609994,109.200939186219,0.0036077831620443,22.014909339941752,109.32502526800656,0.0011356645461693
0.0020513411603197995,112.115574374307,0.0037727701884285,22.602499793860293,112.24879840475046,0.001187568636238
0.0020971223862304997,115.011801675903,0.003918125580695,23.186379217862047,115.15373259943944,0.0012332944806287
0.0021477605809520997,117.935894959549,0.004078901848936,23.77587642384508,118.08740643671638,0.0012838689831272
0.0022070920354853997,120.833219876421,0.0042672792170793,24.35997712708648,120.9956227387553,0.0013431225571964
0.0022586233468368994,123.700600709978,0.0044308911306203,24.938041103131567,123.87323185786408,0.0013945833780104
0.0023132959420960994,126.582236089679,0.0046044766205682,25.51897879567929,126.7658093012236,0.0014491782905882
0.0023643928173797996,129.508100183201,0.004766709199594,26.108832996933327,129.70253402652864,0.0015001998693956
0.0024187446372372994,132.424203890732,0.0049392762276415,26.69671950437157,132.63021325206802,0.0015544687392097
0.0024738035448233996,135.271166469592,0.0051140882592274,27.27066716026975,135.48905266935708,0.0016094406149509
0.0025247761053969996,138.145018318818,0.0052759261390486,27.850035693073707,138.3745751418503,0.0016603299093147
0.0025756026934694995,141.008490701561,0.0054373005561788,28.4273117254347,141.24997276295232,0.0017110708911555
0.0026312697567984996,143.877141667618,0.0056140434822484,29.005631760191783,144.13154561389317,0.001766641241576
0.0026823143024364998,146.725920127855,0.005776109914649,29.57994549777557,146.9928508497405,0.0018175943912893
0.0027332600222102995,149.602195222876,0.0059378625749308,30.1598025569318,149.88198019173944,0.0018684463035307
0.0027844560076769995,152.432478452895,0.0061004098287876,30.73038765610363,152.72536052841642,0.0019195454157749
0.0028406706503269997,155.288045174921,0.0062788913192013,31.306069907264074,155.59514336667678,0.0019756506814351
0.0028926254698748996,158.14904252525,0.0064438478712659,31.8828469730904,158.4700152405316,0.0020275016134537
0.0029448136702515996,160.921739993748,0.0066095454074619,32.4418227827396,161.25673827643664,0.0020795827531179
0.0029915241461275993,163.711347672785,0.0067578511683682,33.004207690833454,164.05980024668915,0.002126195105255
0.0030422330555721997,166.446619204602,0.0069188519558549,33.555638431647765,166.80933401305217,0.0021767950320055
0.0030935766977993997,169.125749779119,0.0070818680199262,34.09575115547039,169.5029863897353,0.0022280257188894
0.0031494272874641994,171.86924891993,0.0072591936421119,34.64884058225788,172.2622039306494,0.0022837504578729
0.0032011930067417996,174.581165598501,0.0074235498008183,35.195562984657805,174.9893583471956,0.002335396758362
0.0032536152112361996,177.276513216589,0.0075899903000881,35.738945064464346,177.70030125304487,0.002387695311463
0.0033015846063749995,180.015881458443,0.0077422931296537,36.29120170202211,180.4548533394648,0.0024355491619182
0.0033601100189319996,182.711044072647,0.0079281113145222,36.83454648504564,183.167281394159,0.0024939305021748
0.0034076535651741996,185.446684008153,0.0080790620738412,37.38605149604365,185.91856913303167,0.0025413545013114
0.0034584340630722994,188.217166619709,0.0082402901546677,37.94458079053333,188.7056592386179,0.0025920048290566
0.0035071365945561995,190.876689377321,0.008394920692129,38.48074057846792,191.38138061174573,0.0026405801070083
0.0035515595109247996,193.551129118905,0.0085359634515994,39.01990763037125,194.071489863527,0.002684884894373
0.0036009283446363995,196.147096578743,0.0086927094986337,39.54325467027459,196.68412011561213,0.002734120144155
0.0036500045002026997,198.755547790575,0.0088485262925567,40.06911843457993,199.3094670631471,0.0027830611052525
0.0036930600331294998,201.350011189592,0.0089852276095993,40.59216225582175,201.9198303013192,0.0028259960568692
0.0037447494042621996,203.902899982283,0.0091493413629456,41.10682463642826,204.4904833639625,0.0028775382319302
0.0037940858956455998,206.407664065548,0.0093059847230879,41.61178507561448,207.0126488115393,0.0029267317497154
0.0038403071414479994,208.950552725205,0.0094527371785105,42.12443142940133,209.57264868054853,0.0029728168541624
0.0038937033931145996,211.46755722783,0.009622270277552,42.63185953713053,212.1084384847056,0.0030260531871882
0.003943972410109499,213.954804852703,0.0097818744065108,43.13328865830493,214.6139793502585,0.0030761690615672
0.003995110427544699,216.374752329415,0.0099442376118675,43.62115006961007,217.0524474318946,0.0031271487120378
0.004039434040895599,218.711299617871,0.0100849650842566,44.0921980029628,219.4060069628092,0.003171332959216
0.0040848178785379,220.941194510213,0.0102290587687709,44.54174481325894,221.653011978902,0.0032165720742734
0.0041329265385031,223.099548428785,0.0103818037641605,44.97686896324306,223.82905259623712,0.00326452508811
0.0041851016739226,225.147570773774,0.0105474598191174,45.38975026799284,225.89551879144588,0.0033165288219894
0.004228407429888,227.115633634761,0.0106849555943075,45.78651174076782,227.879955039536,0.0033596902596036
0.004268778130240899,229.033084581772,0.010813132567928,46.173069851685234,229.8131050876064,0.0033999247450775
0.0043088077230887,230.949605146702,0.0109402265252197,46.55944039757513,231.7453975864548,0.0034398176756873
0.004360054508072499,232.844322837163,0.0111029350675433,46.94141548397206,233.6585765056062,0.0034908871798425
0.004410425461726099,234.689800762484,0.0112628628453935,47.31346383371678,235.5223295930984,0.0035410813409926
0.004453922947652199,236.510482631654,0.0114009673632089,47.68051329854145,237.3597576847376,0.003584424131862
0.0044925898797421,238.404782475021,0.0115237348725943,48.06240414696424,239.2700780673362,0.0036229519711625
0.0045386724053903,240.211658861794,0.0116700468915273,48.42667042653768,241.0945821130724,0.0036688667900017
0.0045949711938426,242.002044316212,0.0118487955448634,48.78761213414834,242.9051727396897,0.0037249578310111
0.004648139342501299,243.710627088714,0.0120176044168547,49.13206242108475,244.6330894221111,0.0037779268960773
0.004703775991699799,245.439991251301,0.01219425077806,49.48070223626228,246.38265481170515,0.0038333522146149
0.004753561721149499,247.123524350035,0.0123523204690628,49.82010250896706,248.08495709592967,0.0038829462333481
0.004810193615228799,248.806201923751,0.0125321267327646,50.159330307828206,249.788271484194,0.003939357064082
0.004875075982460099,250.458441451894,0.0127381282487239,50.49242179670183,251.4632829473869,0.0040039822510284
0.0049427898125327,252.023505526779,0.0129531196592044,50.80793871419865,253.05169155009256,0.0040714232239999
0.005001576342906199,253.643894805693,0.0131397668931403,51.13460919282771,254.6936024125009,0.0041299691822567
0.0050663334923742,255.213870290227,0.0133453708427012,51.45111625050976,256.28660217785665,0.0041944573587963
0.0051346850282476,256.61554690453,0.0135623869690992,51.73369425595325,257.7117104791461,0.0042625204811507
0.005210880922286099,258.088002413104,0.0138043089326715,52.03054128648176,259.2101210011753,0.0043383894017332
0.005286575963963199,259.505370278741,0.0140446406899963,52.31628264819418,260.6532945882495,0.0044137539201898
0.005365903159348099,260.952689697673,0.0142965045353433,52.60806224305088,262.12771688248336,0.0044927286378299
0.005445251586125599,262.401448463809,0.0145484357903619,52.9001320103039,263.6038203139739,0.0045717182535067
0.005534921143686599,263.592780127866,0.0148331366356181,53.14030447377778,264.8242471274877,0.0046609748192768
0.0056302548226657995,264.822712229633,0.015135821066377,53.38825878549401,266.0851718159701,0.0047558606825129
0.005726885856758299,266.044356994019,0.0154426245996207,53.63454236999422,267.3383485316272,0.0048520286196657
0.005835938555063199,267.20055446409,0.0157888669167388,53.86763177996054,268.5293084781096,0.0049605475843569
0.005951079945429299,268.231911740755,0.0161544408311511,54.07555340693621,269.59667915720934,0.0050751126618526
0.0060725634155121,269.05528599623,0.016540150848664,54.241545656839975,270.45692852127195,0.0051959738474984
0.0062076942824864,269.79481320138,0.0169691913513074,54.39063434139821,271.2367658976964,0.0053303953640309
0.006353318369224099,270.547934999597,0.0174315478266996,54.54246369591875,272.033311147112,0.0054752347922213
0.006507067700998299,271.158586586594,0.0179197019550827,54.66557105585736,272.6890058162612,0.0056281329211538
0.0066669501428538,271.750586183877,0.0184273287079739,54.7849181746696,273.3277948069305,0.0057871054140432
0.006835118147115699,272.052203800657,0.0189612621215055,54.84572428621245,273.67691345325466,0.005954289046973
0.0070057141634922,272.293884766706,0.0195029044735009,54.894447168967936,273.9664900023985,0.0061238579258674
0.0071786625779411,272.359307575213,0.0200520156893761,54.90763640716294,274.07941879053453,0.0062957356932827
0.0073594963573502,272.484826577498,0.020626162939,54.93294103802359,274.2550049810862,0.0064754184233842
0.0075440315050334,272.651766870667,0.0212120620328942,54.96659620112647,274.47334362412806,0.0066587456838415
0.007734014857076999,272.851117991819,0.0218152591756326,55.00678538715072,274.7258637730324,0.0068474503817011
0.0079261013566249,272.911956811696,0.0224251338116972,55.01905049323791,274.839543315732,0.0070382078760808
0.0081179498738982,272.996587187716,0.0230342528540399,55.03611197704355,274.9771454294709,0.0072286927208302
0.0083181942777978,273.121743699391,0.0236700288364211,55.06134352979723,275.15790103772747,0.0074274750801443
0.0085199526043296,273.299026313584,0.0243106115231596,55.097083704818544,275.39164567055013,0.0076277203527975
0.0087182993175846,273.426682359209,0.0249403623377442,55.12281916361653,275.5745124476644,0.0078245405179042
0.0089152928532545,273.535378510406,0.0255658168134962,55.14473230769785,275.7379471337154,0.0080199795848267
0.0091094087374609,273.606250346955,0.0261821347458515,55.15902006994613,275.8625009655034,0.0082125263514046
0.0093068650467753,273.528702864463,0.0268090585279247,55.14338649747574,275.8383239681357,0.0084083485117521
0.0095093449574198,273.691332727535,0.027451932244221,55.17617267787106,276.0577440415088,0.0086091128839044
0.0097100455249797,273.865875007075,0.0280891565462237,55.21136040142632,276.2887604986474,0.0088080732200483
0.0099136882127537,274.046768955592,0.0287357220799061,55.24782862144735,276.52706243263265,0.0090099097141388
0.0101177383559496,274.177753372697,0.0293835812845531,55.274235079935714,276.7151783499073,0.0092121091976953
0.0103195076332527,274.228593616442,0.0300241987399904,55.28448447307472,276.82182000854533,0.0094120083083642
0.0105230005955619,274.082101693785,0.0306702888953221,55.25495170146706,276.7297165725206,0.0096135746624514
0.0107261395608894,274.16838416204,0.031315255110237,55.27234624706728,276.8725268055662,0.009814749856208