File: example/data/02 processed data/test_ID_080.csv
Strain,Stress_MPa,Displacement(mm),Force(kN),True Stress (MPa),True Strain
-2.45558760376272e-05,0.0924937358465878,-7.796490641946635e-05,0.018646737146672098,0.09249146458187608,-2.455617753812825e-05
-3.8289793751061e-05,0.0952036383879744,-0.00012157009515961866,0.01919305349901564,0.09519999306029617,-3.8290526823955155e-05
-2.7760535634167e-05,0.171776549862032,-8.813970063848022e-05,0.03463015245218565,0.17177178125299844,-2.7760920964936632e-05
-1.0096778706174e-05,0.842209385935084,-3.2057272392102446e-05,0.16978941220451294,0.8422008823332899,-1.0096829679038835e-05
6.01328365101964e-05,2.57205730032622,0.00019092175591987355,0.518526751745766,2.572211965427355,6.013102860364759e-05
0.0001317638678294,6.00726200859584,0.00041835028035834494,1.2110640209329215,6.008053548673157,0.00013175518773335634
0.0001979585654746,10.4581292015429,0.000628518445381855,2.1083588470310484,10.460199477797184,0.00019793897426318785
0.0002731441617188,15.3432720715308,0.0008672327134571899,3.0932036496206092,15.3474629967188,0.00027310686464370956
0.0003481448568642,20.4358952534492,0.001105359920543835,4.119876483095359,20.443009905277105,0.0003480842685055583
0.0004483364533699,25.563595519309,0.0014234682394494325,5.1536208566926955,25.57505661105951,0.0004482359806114036
0.0005468092611566,31.376095775022,0.001736119404172205,6.3254209082444355,31.393252514770722,0.0005466598154490284
0.0006446610908783,37.3887489320215,0.0020467989635386025,7.537571784695534,37.412852003694596,0.0006444533861786033
0.000734137535107,43.5400613887528,0.0023308866739647246,8.777676375972563,43.572025782099146,0.000733868187964037
0.0008190396728809,49.5548240567538,0.0026004509613968573,9.990252529841566,49.595411423638915,0.0008187044429199442
0.0009274387340556,55.7095908213914,0.0029446179806265297,11.231053509592508,55.76125805377755,0.000927008928477971
0.0010139762087862,61.8740331450987,0.0032193744628961846,12.473805082051896,61.93677194264948,0.0010134624821519192
0.0011235776931125,68.1116629889097,0.0035673591756321876,13.731311258564197,68.18819173408482,0.0011229469521096833
0.0012231093712109,74.4244695864252,0.003883372253594607,15.00397306862332,74.51549885262376,0.0012223619823074844
0.0013188048536301,80.7333553598052,0.004187205410275567,16.27584444053673,80.83982690070356,0.001317935994329153
0.001425792857542,87.0079849455474,0.0045268923226958495,17.540809765022356,87.1320403090319,0.0014247773800315539
0.0015281599712111,93.2057821068164,0.0048519079085952415,18.79028567273419,93.34821545211746,0.001526993522957479
0.0016296676508405,99.3623047632452,0.005174194791418587,20.031440640270233,99.52423229703082,0.0016283411834528462
0.0017294512007056,105.60813075714,0.0054910075622402795,21.290599160639427,105.79077486568221,0.001727957422007999
0.0018386262925249,111.806584452844,0.005837638478766558,22.540207425693353,112.01215497869642,0.0018369380882043292
0.0019549809344403,118.063240297554,0.006207064466847953,23.801549243986887,118.29405168139397,0.0019530724461806399
0.0020618873807145,124.270064000795,0.006546492433768537,25.052844902560274,124.52629487755883,0.00205976460837336
0.0021615539930831,130.355132705158,0.006862933928038843,26.279594753359856,130.63690236277571,0.002159221196289851
0.002268397901253,136.452492073802,0.007202163336478274,27.508822402078486,136.76202062044297,0.002265828970904442
0.0023846020435075,142.566121532619,0.007571111488136313,28.741330100975993,142.9060849973606,0.0023817633918618818
0.0024922877034457,148.705903519632,0.007913013458440097,29.979110149557812,149.07652141440374,0.0024891871051008403
0.0026231498493307,154.796611338017,0.008328500771624971,31.206996845744225,155.2026660457252,0.002619715396509943
0.0027303656917705,160.761914231451,0.008668911071371337,32.40960190906052,161.2008530466119,0.0027266450143663802
0.0028337325528503,166.610629108623,0.008997100855299702,33.588702828298395,167.08275907197896,0.0028297251016711944
0.0029418881675448,172.387904520581,0.009340494931954739,34.75340155134913,172.89505045711792,0.002937569282926563
0.0030471777968161,178.137364003195,0.009674789504891116,35.91249258304411,178.6801802235689,0.0030425445603641287
0.003159405388731,183.759604858611,0.010031112109220926,37.04593633949598,184.34017594443236,0.0031544249549081685
0.0032610522928898,189.321844775711,0.010353841029925115,38.16728390678334,189.93923321171096,0.0032557465935075126
0.0033748831429059,194.744360913734,0.010715253978726233,39.26046316020877,195.40160037455774,0.003369201005569091
0.0034933556631606,200.071219616253,0.011091404230534905,40.3343578746366,200.77013954433488,0.0034872680695661475
0.0036006158790406,205.358919533584,0.011431955415953904,41.40035817797053,206.09833812015924,0.0035941491797711928
0.0037234288118209,210.38107809984,0.011821886477531357,42.412825344927754,211.1644170674989,0.0037165140099621385
0.0038256772960386,215.23495978686,0.012146525414922555,43.391367893030974,216.05837928583037,0.0038183780032214026
0.0039340068779171,219.598826047615,0.01249047183738679,44.271123331199185,220.4627293396688,0.003926288907935225
0.0040611572386631,223.663195554463,0.01289417423275534,45.090500223779735,224.5715269601115,0.004052932998706179
0.0041775710107732,227.449249121153,0.013263787959204909,45.85376862282445,228.39943451070366,0.00416886918756955
0.0043098158437864,230.93518366882,0.01368366530402182,46.55653302763412,231.9304717822836,0.004300555185768851
0.0044499054779678,234.191873888455,0.014128449892547766,47.213081775912535,235.2340055909668,0.004440033922744295
0.0046068838287141,237.240695907629,0.014626856156167267,47.827724294978005,238.33363623311874,0.004596304618427189
0.0047981105192927,239.943495138218,0.015234000898754324,48.37260861986475,241.09477054627652,0.00478663627550353
0.005013126352845,242.412788714727,0.015916676170282876,48.87041820488896,243.62803465409942,0.005000602473351309
0.0052688020548548,244.411929755538,0.016728446524163988,49.27344503871647,245.69968783326502,0.005254970479923296
0.0055403052421414,245.894286861511,0.017590469143798946,49.572288231280616,247.25661626802247,0.005525014203070659
0.0058471397470261,246.958704621445,0.018564668696807868,49.786874851683315,248.40270667911113,0.005830111570590963
0.0061787856479795,247.657339738449,0.01961764443233491,49.92771969127132,249.18756135484173,0.006159775219325425
0.0065350800766342,248.176333268356,0.020748879243313586,50.03234878690057,249.79818547939016,0.006513819019036639
0.0068940691140195,248.531280445295,0.02188866943701191,50.103906137771475,250.24467226968065,0.006870413678782962
0.0072620109870447,248.783759265869,0.02305688488386692,50.154805867999194,250.59042965905604,0.007235769552394865
0.0076292412804292,248.980974196861,0.02422284106536271,50.19456439808718,250.88051012324522,0.007600285798160036
0.0079855528523712,249.212332281517,0.025354130306278557,50.24120618795383,251.20243053241373,0.007953837058738731
0.0083435731305264,249.461108387265,0.026490844689421318,50.291359450872626,251.5425053883163,0.00830895793390164
0.0087120153740571,249.654363111795,0.027660648812631288,50.33031960333788,251.8293557614254,0.008674284749611062
0.0091002441491812,249.88774302547,0.028893275173650312,50.37736899393475,252.16178249688963,0.009059086435776091
0.0094761432528074,249.964685349158,0.03008675482766349,50.392880566390254,252.33338651566956,0.009431526250605352
0.0098487971716773,250.160184379377,0.03126993102007543,50.4322931708824,252.62396129575885,0.009800613875524045
0.0102221647005231,250.277041954581,0.03245537292416084,50.45585165804353,252.83541509820046,0.010170271714426467
0.0105882415114426,250.384955343746,0.033617666798830256,50.47760699729919,253.03609172175734,0.010532578652077457
0.010956489492881,250.522966706807,0.03478685413989717,50.5054300880923,253.26781895925555,0.010896902013182254
0.011325533091348,250.648648281953,0.0359585675650299,50.530767493641726,253.4873778423719,0.011261879398573786
0.0117019916872525,250.866165472109,0.03715382360702669,50.57461895917718,253.80179925507653,0.011634052881770548
0.0120781583953906,251.174538314716,0.038348152905365154,50.63678692424674,254.20826417337022,0.012005799499064725
0.0124591334413368,251.467349705562,0.039557748676244335,50.6958177006413,254.6004149716829,0.012382157150740833
0.0128312906663184,251.683878183223,0.04073934786556092,50.73946984173776,254.9133071802182,0.012749667138187922
0.0131988550691937,251.827766841211,0.04190636484468999,50.76847779518814,255.15160503814684,0.01311250913013125
0.0135649408029154,251.933427174749,0.04306868704925639,50.789778918429406,255.3508892006501,0.013473760637039586
0.0139420491139669,252.090897257354,0.044266005936844904,50.82152488708256,255.60556092809998,0.013845752760642966
0.0143123578332809,252.37237664228,0.045441736120666855,50.87827113108365,255.98442040401983,0.014210902933284308
0.0146844605076961,252.626337139215,0.04662316211193512,50.92946956726574,256.3360186101397,0.014577687814584517
0.0150568706749325,252.934137355483,0.047805564392910685,50.991522090865374,256.7425339509201,0.014944641145724847
0.0154346969660681,253.166425748703,0.049005162867266215,51.038351430938526,257.07397281211684,0.015316793684073191
0.0157999849755578,253.346111876785,0.050164952297396016,51.07457615435986,257.3489766380542,0.015676464594259195
0.0161702760841455,253.477441498498,0.051340626567161964,51.101052206097194,257.5762417086316,0.016040929684898377
0.0165201615847748,253.580808176699,0.052451513031659985,51.121890928422516,257.77000410257585,0.016385188208085974
0.0168874653342377,253.659209076913,0.0536177024362047,51.13769654990566,257.9428701769095,0.01674645738854474
0.0172405428406035,253.691390144607,0.054738723518916114,51.14418425315277,258.06516742468733,0.01709361106667395
0.0175996181356517,253.844470802079,0.055878787580694145,51.17504531369913,258.31203655404215,0.017446538343873993
0.0179563887727178,254.012549947947,0.05701153435337901,51.20893006950612,258.5736980479618,0.01779707710528229
0.0183132485837755,254.21958775652,0.05814456425348721,51.25066889171443,258.87517426197013,0.018147580602623063
0.0186793462049688,254.515278531124,0.059306924200775935,51.31028015187461,259.26945753326095,0.018507029749440358
0.0190473060400085,254.734348781912,0.060475196677026985,51.354444714433455,259.58635188206335,0.018868177147334606
0.0194023967020524,254.973880662463,0.06160260952901637,51.402734341552545,259.92098504373786,0.01921657001192969
0.019764302879231,255.160581333862,0.06275166164155843,51.440373196906584,260.2036523461851,0.019571524985500587
0.0201057519751973,255.299885085507,0.06383576252125142,51.46845683323821,260.43288125433253,0.019906300329001266
0.020463661174616,255.515339709977,0.06497212422940579,51.51189248553136,260.7441190467189,0.020257093789672203
0.0208183425205822,255.723108161151,0.06609823750284848,51.553778605288045,261.04683941727774,0.020604602217114704
0.0211839819983223,255.953043886413,0.0672591428446733,51.60013364750086,261.3751485605186,0.020962720792453884
0.0215614566797058,256.169437417213,0.0684576249580659,51.64375858331014,261.6928236447488,0.02133229663732681
0.0219344524116395,256.290327024453,0.06964188640695541,51.66812992812973,261.91191500613445,0.02169735314115118
0.0222968453399372,256.487773471181,0.0707924839543006,51.707935131790094,262.2066416878528,0.022051904930366538
0.0226650701477933,256.653983676066,0.07196159771924372,51.74144310909491,262.47106421979464,0.022412033702493703
0.0230126893150483,256.849884016459,0.07306528857527834,51.78093661771813,262.760690597936,0.02275189091509039
0.0233625827684612,257.001875268678,0.07417620028986431,51.811578054165494,263.0061028512922,0.02309385503242083
0.0237134630030039,257.059287032031,0.07529024503453738,51.823152265657455,263.15505292464366,0.023436666173906
0.0240548581617644,257.147180396971,0.07637417466360197,51.84087156802935,263.33281934811777,0.023770097605962992
0.0244102261778528,257.280469974233,0.07750246811468263,51.86774274680537,263.56074443744825,0.024117057895762527
0.0247569588043597,257.516361926466,0.07860334420384205,51.91529856437555,263.8916838901281,0.02445547111295356
0.02509488367904,257.697613030313,0.07967625568095199,51.951838786911104,264.16450465367495,0.024785177749050757
0.0254477709052035,257.85544987986,0.08079667262402111,51.983658695779766,264.4172962950608,0.02512936686295034
0.0257922969613146,258.040723367986,0.08189054285217386,52.021009830985975,264.69618633320556,0.025465286646059227
0.0261423821060938,258.173534635625,0.0830020631868478,52.047784582542,264.9228058277503,0.025806511102906958
0.0265022491769135,258.330670120622,0.08414464113670035,52.0794630963174,265.1770139101978,0.026157148586884796
0.026850163022436,258.437030479589,0.0852492675962343,52.100905344685145,265.37610687900025,0.026496022563689606
0.0272056242224886,258.542355165528,0.0863778569064013,52.12213880137045,265.57616132575856,0.026842129233048996
0.0275538304614315,258.779010675344,0.087483411715045,52.169848552149354,265.90936366246945,0.027181055759443642
0.0279020885465524,259.014497239172,0.08858913113530387,52.21732264341708,266.2415426759801,0.027519917892396988
0.02825816173382,259.167677798103,0.0897196635048785,52.24820384409756,266.49127995350034,0.027866265596354887
0.0286142798722675,259.337281472199,0.09085033859444931,52.28239594479532,266.7580310255575,0.028212537085828247
0.0289755133553487,259.380306588434,0.09199725490323211,52.29106980822829,266.8959841261016,0.028563660023919607
0.0293273768116585,259.516591779056,0.09311442137701573,52.318544902657685,267.1275326550377,0.028905556701438014
0.0296789302322221,259.696874820261,0.09423060348730515,52.354889963764606,267.4044002495776,0.029247035426177296
0.030022928911334,259.819276431906,0.09532279929348544,52.37956612867225,267.6198120980154,0.029581063072735378
0.030373167278756,259.919837514953,0.0964348061100503,52.399839243014526,267.8144262188617,0.02992103495624157
0.0307280971352773,260.051465364968,0.09756170840450543,52.42637541757756,268.0423520528739,0.030265442934789482
0.0310790731899221,260.156096081956,0.09867605737800267,52.44746897012233,268.2415064328915,0.030605897719394506
0.0314212707155073,260.300258224944,0.09976253452173567,52.47653205814871,268.4792231059464,0.030937725570707286
0.0317592459828061,260.441339461704,0.10083560599540936,52.50497403547953,268.71276002575974,0.03126535106696074
0.0321071554843544,260.578497333043,0.10194021866282522,52.53262506234147,268.94493166279443,0.03160249450279217
0.0324657456762349,260.771020654107,0.1030787425220458,52.57143776386798,269.23714629039546,0.03194986920221293
0.0328161754064894,260.930933369244,0.10419135691560384,52.603676167239584,269.4936886476681,0.03228922213029512
0.03315552476154,261.051509196119,0.1052687911178895,52.6279842539376,269.70680897330834,0.03261773520535327
0.0334974544701124,261.184422952155,0.10635441794260687,52.65477966715444,269.9334362682974,0.03294863711789342
0.0338371683499189,261.297833310707,0.10743300951099251,52.677643195438534,270.13941208591046,0.0332772862674936
0.03419180779708,261.37882849889,0.10855898975572899,52.69397182537623,270.31584316515,0.033620259653967206
0.0345377441083724,261.492591289703,0.10965733754408236,52.71690640400412,270.52395549390195,0.03395470290122315
0.0348974867527112,261.621275736854,0.11079952043985805,52.74284918854976,270.7512007411083,0.03430237519615447
0.035260813294211,261.772289263456,0.11195308220911991,52.773293515512734,271.0025930807729,0.034653388493274755
0.0356103622893326,262.01138647755,0.113062900268631,52.82149551387408,271.3417068739459,0.03499097491831438
0.0359748489242496,262.194499431127,0.11422014533449247,52.858411085315204,271.626906936931,0.03534286644245249
0.036326062789581,262.350271432396,0.11533524935691966,52.889814720771035,271.8804238653129,0.035681826741807546
0.0366857951278624,262.428683045577,0.11647739953096312,52.90562250198832,272.0560879474617,0.0360288892446276
0.0370403054979103,262.523512021789,0.1176029699558652,52.92474002359266,272.24746310746036,0.036370795896035917
0.0373947596659896,262.596415663488,0.11872836193951698,52.939437397759185,272.41614551637446,0.03671253151117396
0.037750294579391,262.659994793607,0.1198571852895664,52.95225495039117,272.575486971287,0.037055191814513125
0.038107914281776,262.783812571212,0.12099262784463878,52.97721661435635,272.79795557531406,0.03739974300244712
0.038467245588726,262.873858785974,0.12213350474420505,52.995369931252355,272.98589207075014,0.03774582371985201
0.0388155301987284,262.982742961675,0.12323930838096267,53.01732098107368,273.1905575628483,0.03808115082825088
0.0391782686484655,263.01961321975,0.12439100295887795,53.0247540251016,273.32426628628883,0.038430274539421515
0.0395283882633496,263.130921295509,0.12550263273613496,53.04719373317461,273.53206251657076,0.038767137479683904
0.0398819642062729,263.247094990821,0.12662523635491646,53.07061435014951,273.7459062106502,0.03910721075662112
0.0402278405550307,263.406964230182,0.12772339376222247,53.10284398880469,274.00325758831843,0.03943976661607985
0.0405822812864923,263.515279857775,0.12884874308461305,53.12468041932744,274.2093310682519,0.039780442328072124
0.0409371332865954,263.62406668852,0.1299753981849404,53.146611844405626,274.4160802441022,0.040121397114327155
0.0412935444418733,263.720551502891,0.13110700360294772,53.166063182982825,274.610507816611,0.040463733016464234
0.041655469993579,263.904302425819,0.1322561172296133,53.20310736904512,274.8973601766941,0.04081124565632208
0.0420153507307475,264.023549783933,0.1333987385701233,53.2271476364409,275.1165918292819,0.04115667520994216
0.0423696456702515,264.160605775565,0.13452362500304849,53.254778124353905,275.3529970423147,0.04149662674819246
0.0427220135242624,264.25149568212,0.13564239293953312,53.27310152951539,275.54085165445804,0.04183461463070239
0.043069750104155,264.277271369534,0.13674645658069212,53.27829790809806,275.65962740562776,0.0421680482832637
0.0434284977478676,264.351768656358,0.13788548034947962,53.29331656112178,275.83216884609544,0.04251192362331448
0.0437974312968191,264.448599389994,0.13905684436740065,53.312837637022795,276.03076875331726,0.042865439309048126
0.0441676184182092,264.663068588903,0.1402321884778142,53.35607462752285,276.35260601172996,0.04322003061345665
0.0445382303230776,264.806872121413,0.14140888127577136,53.385065419676856,276.60090158309026,0.04357490289859079
0.0449059116342631,264.971041171329,0.14257626943878535,53.41816190013992,276.8698073318074,0.043926844649602344
0.0452588765360244,265.071706234068,0.14369693300187747,53.43845597678811,277.068553859709,0.04426458347968323
0.0456178854020222,265.108373813157,0.14483678615142045,53.44584816073246,277.20205722888204,0.04460798857754563
0.0459656132540453,265.156469358349,0.1459408220815938,53.455544222643155,277.344549080683,0.04494049058423127
0.0463115480745274,265.199537022105,0.1470391651366245,53.464226663656376,277.4813381302466,0.04527116840266576
0.046664895494257,265.266555349369,0.14816104319426598,53.47773755843279,277.64519143286884,0.04560881904768137
0.0470261891780015,265.364474894785,0.14930815064015474,53.49747813878866,277.8435548923082,0.0459539451171151
0.0473810180789405,265.431777876535,0.15043473240063607,53.51104641990946,278.00820574282847,0.04629277980322991
0.0477401727380243,265.529689722005,0.15157504844322714,53.530785447956205,278.20612297640747,0.0466356283832319
0.0481027510013095,265.637499603215,0.15272623442915764,53.552519920008145,278.4153941032389,0.04698162594134611
0.0484610209166339,265.732676918241,0.15386374141031262,53.57170766671739,278.610353732609,0.047323394623616136
0.0488297960687822,265.818726709408,0.15503460251838347,53.58905530461665,278.7986009258918,0.04767506274037164
0.0491945354996087,265.925973155517,0.1561926502112576,53.61067618815223,279.00807788218407,0.04802276074273778
0.0495521103144778,266.065121310448,0.15732795024846702,53.63872845618631,279.24920955245824,0.04836351156089132
0.0499119018978585,266.175567433675,0.15847028852570072,53.66099439462888,279.46089624303136,0.04870625769496169
0.0502700292244315,266.319052955416,0.15960734278757002,53.68992107581187,279.7069195305077,0.04904730179665334
0.0506421904839903,266.360024697204,0.1607889547866692,53.69818097895632,279.84907980524014,0.04940158719702389
0.0510022189095102,266.439177970298,0.16193204503769487,53.71413827881207,280.0281672512091,0.04974420312903669
0.0513598603645626,266.484924012726,0.16306755665748626,53.72336068096557,280.1715524992807,0.05008443135330693
0.0517299268386927,266.575973289881,0.1642425177128493,53.74171621524001,280.36592888511984,0.05043635781902531
0.0520977138270971,266.683487179729,0.1654102414010333,53.76339101543337,280.57708717723085,0.05078599386814076
0.0524572371445343,266.715618745604,0.1665517279338964,53.76986873911376,280.7067832082933,0.05112765595757067
0.0528243070616591,266.739680190928,0.16771717492076765,53.77471952649109,280.83001896286237,0.051476369336885514
0.0531617459743792,266.844824217289,0.16878854346865393,53.795916562205456,281.0307609769064,0.051796826269751926
0.0535248544764132,266.863604672118,0.1699414129626119,53.799702701898994,281.1474402772442,0.05214154627276704
0.0538983560315666,267.007782519342,0.17112728040022393,53.82876895589935,281.39906304476864,0.05249600906619356
0.0542788588685206,267.1081597624,0.1723353769075529,53.84900500809985,281.6064858687736,0.052856987107694424
0.0546602867632867,267.257070717081,0.17354641047343528,53.879025456563525,281.8654188419926,0.053218712005935385
0.0550259263433906,267.460394017435,0.17470731614026516,53.920015433914905,282.1776499584126,0.05356534135914762
0.0553980277481631,267.547637482675,0.17588873810041783,53.937603716507276,282.36924892789574,0.0539179732631848
0.0557679910947521,267.562280693176,0.17706337172583791,53.94055578774428,282.4836915801646,0.054268455742605255
0.0561384152844758,267.635062672702,0.17823946852821065,53.955228634816734,282.65967096570887,0.054619251774477955
0.0565122059660198,267.687351309648,0.17942625394211287,53.96577002402504,282.81495404135717,0.05497311121690989
0.0568869795118506,267.703756301029,0.18061615995012564,53.96907727028744,282.93261440097103,0.05532777544914231
0.057265073382651,267.743393700185,0.18181660798991692,53.97706816995729,283.07573878814605,0.05568545442905649
0.0576305410322179,267.787266129925,0.18297696777729183,53.98591285179288,283.2199911585311,0.05603106737629975
0.0580023315562066,267.77464852233,0.18415740269095593,53.98336914210173,283.30620246826885,0.056382537173005114
0.0583699993695408,267.877408624434,0.18532474799829202,54.00408557868589,283.51341279695646,0.05672998815000043
0.0587473605837093,267.910813572507,0.186522869853277,54.0108200162174,283.64986674172593,0.057086474025845386
0.0591223669900117,267.975592128831,0.18771351519328713,54.023879373172335,283.81894343103744,0.05744060950957148
0.0594971702921157,268.011516221933,0.18890351567746735,54.03112167034169,283.95744304283744,0.057794427927100954
0.0598645761370452,268.038825035339,0.19007002923511848,54.03662712712435,284.08485568435117,0.05814114160090297
0.0602396920777619,268.141702873558,0.19126102234689402,54.0573672993093,284.2944764878679,0.05849500716332366
0.0606129181323061,268.167655751009,0.19244601507007186,54.06259939940342,284.4220799147774,0.058846965669633974
0.0609849688593324,268.222750743973,0.19362727612838035,54.073706549984955,284.58030684545867,0.05919769257516249
0.0613583314269835,268.340344820432,0.1948127022806726,54.09741351579909,284.80526063315506,0.05954953251684599
0.0617310727698556,268.383586372075,0.19599615604429152,54.10613101261032,284.9511930726444,0.05990066360531087
0.0621107722127342,268.459142873064,0.1972017017754311,54.12136320320971,285.1333475444788,0.06025822266538964
0.0624901614549721,268.489981304708,0.1984062626195364,54.127580231029135,285.26796358548165,0.060615361966477384
0.0628748874335311,268.469925808997,0.19962776760146125,54.12353704309379,285.3499421735262,0.060977394816281234
0.0632523738422321,268.49268684623,0.2008262869490869,54.12812566819997,285.47548664853315,0.06133248777759429
0.0636321906743087,268.534024883224,0.20203220539093011,54.13645941645796,285.62143315713286,0.06168964569998525
0.0640168579646874,268.613007448843,0.20325352403788247,54.15238230168675,285.8087681941631,0.062051234745712405
0.0643932307400288,268.698723525006,0.20444850759959143,54.169662662641215,286.0011024285029,0.062404900405598
0.0647853387627624,268.783972780593,0.20569345057177063,54.18684891256755,286.19723351118483,0.062773218998301
0.0651641601333431,268.810789862734,0.20689620842336434,54.19225523632718,286.3276192189196,0.06312892825316485
0.0655397273461966,268.826442176889,0.2080886343241742,54.19541074286082,286.4452539006104,0.0634814570291717
0.0659155708044868,268.818259463665,0.2092819373042456,54.19376110787487,286.5375684788811,0.06383412073505525
0.0662866203275251,268.837564093006,0.21046001953989216,54.19765292115001,286.6578976338158,0.06418216420703671
0.0666704926244441,268.91238919053,0.21167881408261002,54.21273766081085,286.8409106506789,0.06454210796655487
0.0670550709878683,268.992382990222,0.21289985038648182,54.228864410828756,287.0296863268272,0.06490258390980369
0.0674350959225104,268.973643272058,0.21410642955397052,54.22508648364689,287.11190670673636,0.06525866419965355
0.067806809588642,269.00686500405,0.21528662044393837,54.231783984816474,287.2473622774171,0.06560683427717687
0.068184561734185,269.060203511749,0.21648598350603734,54.2425370279686,287.40595556830823,0.06596053622050195
0.0685722394430659,269.12058839732,0.2177168602317342,54.25471062089971,287.5747898239598,0.0663234017678784
0.0689565424200614,269.17424429188,0.21893702218369493,54.265527649243005,287.73556948678095,0.0666829786628395
0.0693326201810264,269.215542337856,0.2201310690747588,54.27385333531177,287.8809612815956,0.06703473442293083
0.0697174881162798,269.271553167749,0.22135302476918836,54.2851451186182,288.0444894757738,0.06739458381394191
0.0701059976169075,269.368041147315,0.2225865424336813,54.3045970952987,288.25235639805976,0.0677577067607523
0.0705017342765016,269.398444897284,0.22384300632789256,54.310726491292456,288.391502473935,0.06812744910841007
0.0708990072794346,269.40102532231,0.22510434811220484,54.31124670497769,288.5012905777236,0.06849848942775003
0.0712906773534132,269.44789443062,0.2263479005970869,54.320695517213,288.65701733602987,0.06886416206743513
0.071690209603346,269.478749753448,0.22761641549062356,54.326915950295124,288.79773780692034,0.06923703730584131
0.0720801661826414,269.54850953502,0.22885452762988645,54.340979522260035,288.9776108965875,0.06960084173937664
0.0724728968462253,269.579917549547,0.23010144748676528,54.34731137798868,289.11715510592927,0.06996710049486728
0.0728573158335983,269.580813314881,0.23132197777167457,54.34749196428002,289.22174777324165,0.0703254779504359
0.0732562741676136,269.555871823676,0.23258867048217316,54.342463759653086,289.30253067348133,0.0706972740571004
0.0736381628631191,269.551567341414,0.23380116709040313,54.34159597602907,289.40084955731004,0.07105303323458595
0.0740272588131309,269.517629316719,0.23503654673169058,54.334754070250554,289.4692806168493,0.07141537640996318
0.0744189032728851,269.55129129991,0.23628001789141018,54.34154032606186,289.6110027742393,0.0717799603320587
0.0748122332700331,269.635214034549,0.23752884063235508,54.35845914936508,289.807226564717,0.07214597959806657
0.0752053916552042,269.648312645227,0.23877711850527333,54.36109982927776,289.92731960687627,0.07251170533444698
0.0756000483572914,269.710496594019,0.24003015353440016,54.37363611335423,290.1006231789959,0.07287869037100533
0.0759949766228182,269.679371864422,0.2412840507774478,54.36736136786748,290.1736494249151,0.07324579316254087
0.0763927417359484,269.713124846963,0.24254695501163615,54.37416596914775,290.3172499361927,0.07361539675604362
0.0767826282503022,269.748812128714,0.24378484469470948,54.38136052514875,290.46083489135367,0.07397754702401496
0.0771859087609106,269.81570882424,0.24506526031589113,54.39484689896679,290.6416795078082,0.07435200051151131
0.0775823101588472,269.845297719167,0.24632383475433986,54.40081202018407,290.7805193017218,0.07471993001680821
0.0779812621129854,269.881071495952,0.2475905072087286,54.408024013583926,290.9267380716112,0.0750900902513061
0.0783790851794764,269.907291649752,0.24885359544483754,54.413309996589994,291.06237825252964,0.07545906668096812
0.0787817859223361,269.910547311253,0.2501321703034171,54.413966337948615,291.17458226770873,0.07583242849457461
0.0791939138200736,269.922258273159,0.25144067637873363,54.41632726786886,291.2984583329632,0.0762143863662942
0.0796004091714173,269.901388378924,0.2527312991192499,54.41211989719109,291.38564932982,0.07659098116443555
0.0800209819036906,269.880831808536,0.25406661754421767,54.40797569260086,291.47696096683984,0.0769804686360156
0.0804258840811697,269.906572937501,0.25535218195771375,54.413165104200196,291.6140476853182,0.07735530051787755
0.0808295809067817,269.944287952578,0.2566339193790319,54.42076845123973,291.76377161596446,0.0777288767441466
0.0812164868544932,269.993449361887,0.2578623457630159,54.43067939135642,291.9213687927859,0.07808678396694901
0.081612450063953,270.004304564695,0.25911952895305074,54.43286780024252,292.04001738803356,0.07845293702429425
0.0820247001057129,269.980697416121,0.26042842283563844,54.42810859909,292.12578315600956,0.07883400835755015
0.0824236973088269,269.971143351835,0.2616952389555254,54.42618249972994,292.22316315358455,0.0792026909356242
0.082835077097415,269.976804226571,0.2630013697842926,54.427323732076715,292.3403536191927,0.0795826730406737
0.0832433626104292,270.054495742727,0.2642976762881127,54.44298634173377,292.53474005641544,0.07995965432663733
0.0836430435643653,270.079505620399,0.26556666331685985,54.44802833307244,292.6697774748483,0.08032855318292238
0.0840536159840003,270.061225357646,0.2668702307492009,54.444343032101436,292.7608478860261,0.08070736303414025
0.0844472332201717,270.036718228552,0.2681199654740451,54.43940239487608,292.84057195080834,0.08107039470243682
0.084853391612177,269.978111421571,0.26940951836866195,54.427587262588716,292.8866698367415,0.08144485492441049
0.0852638899914808,269.940056817618,0.27071285072295154,54.41991545443179,292.95619612640945,0.08182317400207487
0.0856756241462676,269.980908860262,0.27202010666439963,54.42815122622882,293.1116917344415,0.08220248826398038
0.0860926515071373,270.003630210821,0.2733441685351609,54.432731850501504,293.24895865222317,0.08258653233596597
0.0865193632661334,270.09456780834,0.27469897836997353,54.451064870161346,293.4629778367591,0.08297934224549536
0.0869341861756516,270.149673209925,0.27601604110769384,54.46217411912088,293.6349151960481,0.08336106000952274
0.0873643264289832,270.182550833508,0.27738173641202163,54.46880224803522,293.7868673999419,0.08375671889117986
0.0877748104178312,270.183936199688,0.278685023076614,54.4690815378571,293.899279977559,0.08413415129241553
0.0882040064427241,270.194377127198,0.28004772045564896,54.47118642884311,294.02660370811316,0.08452863677833412
0.088640774146128,270.201135548432,0.2814344579139564,54.47254892656389,294.1519733786078,0.08492992189811813
0.0890648265339896,270.202696598139,0.28278082424541695,54.47286363418483,294.2682528996685,0.0853193706767674
0.0894859992572375,270.205330740171,0.28411804764172904,54.47339467721848,294.3849247660875,0.08570602470706032
0.0899113784830472,270.195978624441,0.28546862668367484,54.47150929068731,294.48967152314043,0.08609638879169786
0.090318747350554,270.194413039984,0.2867620228380089,54.47119366886078,294.5980339668736,0.08647008225407188
0.0907519570807781,270.192397860917,0.2881374637314705,54.47078740876087,294.71288675514353,0.08686732727234743
0.0911727493950941,270.162407062342,0.28947347932942374,54.464741263768154,294.7938564974123,0.0872530347335478
0.0916024436856779,270.084598860064,0.2908377587020273,54.4490551301889,294.8250081175119,0.08764674847694805
0.0920173242311052,269.990040036268,0.292155004433759,54.42999207131163,294.83380108945437,0.08802674187736996
0.092444449575593,269.901981533378,0.2935111274025078,54.412239477129,294.852921655593,0.08841779962445659
0.0928652722058277,269.845653149234,0.2948472392535029,54.400883674885584,294.904943182497,0.08880293737517633
0.0932852920764574,269.822746315218,0.29618080234275224,54.39626565714795,294.99324001410497,0.08918719258857297
0.0937143443166502,269.840648671978,0.29754304320536434,54.39987477227076,295.12858813225193,0.08957955867639261
0.0941371328549963,269.886815670092,0.29888539681461324,54.409182039090545,295.2931866926393,0.08996604610300295
0.0945640273812104,269.905848488334,0.300240786935343,54.41301905524814,295.4292325351337,0.09035613547599122
0.0949809059926634,269.924687651438,0.30156437652670626,54.4168170305299,295.56237903435823,0.09073692566680759
0.0954008499474333,269.903923547751,0.30289769858310067,54.412630987226606,295.6529872583535,0.09112036929144182
0.095829055013534,269.893154976933,0.30425724966797046,54.41046004334969,295.75676097299373,0.09151120465799277
0.0962615796495625,269.873592399436,0.3056305153873609,54.4065162277263,295.85205070950786,0.09190582761272116
0.0967009499079398,269.850550040302,0.3070255159577088,54.401870888124876,295.94535456237924,0.09230653693477701
0.0971426516879476,269.844829863817,0.3084279191092336,54.4007177005455,296.05827218107123,0.0927092108406606
0.0975985130020189,269.804933040429,0.30987527878140997,54.39267450095048,296.1374933057841,0.09312462321635295
0.098039146911983,269.775670921426,0.31127429144554597,54.38677525775948,296.2242475561705,0.09352599537709175
0.098480725667288,269.758864756827,0.3126763039936394,54.38338713497632,296.3249135132631,0.09392806664151901
0.0989107649178351,269.778242733469,0.3140416786141264,54.38729373506736,296.46221508042584,0.09431947550778605
0.0993530274087827,269.767052141756,0.31544586202288505,54.385037711778004,296.5692254671824,0.09472184987109795
0.0997988837698577,269.712588316017,0.31686145596929816,54.37405780450903,296.62960356863465,0.0951273301518531
0.100242084331861,269.616890585148,0.31826861775365867,54.354765141965835,296.64384966847854,0.09553023225633618
0.10068157056524,269.493218010853,0.319663986544637,54.329832750987975,296.6262184568663,0.09592959753031317
0.101128957937586,269.457197470615,0.3210844414518355,54.32257101007598,296.70712305960063,0.09633597889029993
0.101575747807049,269.511524706026,0.3225029992873806,54.33352338073485,296.88735937065854,0.09674165276426504
0.102022855315942,269.554790559669,0.32392256562811583,54.34224577682928,297.0555399566571,0.09714745036678196
0.10245807280124,269.521406733184,0.325304381143937,54.335515597409895,297.1360506457452,0.09754229841051104
0.102909229956178,269.401420286876,0.3267368051108651,54.3113263298342,297.12531299769904,0.09795144310098274
0.10335872777377,269.303723978995,0.32816396068171977,54.29163075416539,297.13861427420244,0.09835891656515235
0.103807450930668,269.23936697183,0.32958865670487086,54.27865638152093,297.18841934736236,0.09876552225475523
0.10426958045441,269.194738532279,0.33105591794275174,54.26965928810745,297.2635609795744,0.09918410324076343
0.104718952561302,269.169394802646,0.3324826743821338,54.264549992213446,297.3565318879387,0.09959096104593025
0.105185670351583,269.124267997093,0.333964503366276,54.25545242821395,297.4322845342463,0.10001334832217826
0.105647274227856,269.091466916441,0.3354300956734428,54.248839730354504,297.5202469141383,0.10043093200629381
0.106092370410643,269.017632509659,0.3368432760537915,54.23395471394725,297.55835082486794,0.10083341716305666
0.10655145034491,268.961503045832,0.3383008548450892,54.222639014039736,297.61974128231236,0.10124837770622978
0.106998723497052,268.894449247082,0.3397209471031401,54.20912096821173,297.6658120719626,0.10165250060664074
0.107464453626629,268.801791061868,0.3411996402645471,54.19044107807259,297.6884286721909,0.10207312637387389
0.107920470488703,268.731182749407,0.342647493801632,54.17620644228045,297.73277842670865,0.10248480821168962
0.10837789401204,268.653457405232,0.344099813488227,54.16053701289478,297.76955333786435,0.10289758975514847
0.108833762107712,268.562946485097,0.3455471946919856,54.14229001139555,297.7916623138022,0.1033087982212753
0.109293279763111,268.52371736563,0.3470061632478774,54.134381420911005,297.8715551307023,0.10372312765624322
0.109757360849885,268.436756150546,0.34847962069838484,54.116850039950066,297.89966606073403,0.104141397600197
0.110233610688754,268.359220078931,0.3499917139367939,54.101218767912485,297.9414258698495,0.10457045326058557
0.1106994054277,268.302092528762,0.3514706122329475,54.08970185379842,298.0029746467037,0.1049899118776581
0.111175162812946,268.235401555679,0.3529811419311035,54.07625695362489,298.05651599582757,0.10541816052798028
0.111641881476312,268.224113482054,0.3544629736872906,54.073981277982085,298.1691581685063,0.10583809492737109
0.112108315043225,268.190841806941,0.3559439002622393,54.06727370827931,298.25726519194126,0.10625759669918272
0.112580723130474,268.114362529942,0.3574437959392549,54.05185548603631,298.298871345229,0.10668229254318032
0.113058358191014,268.007507883206,0.3589602872564694,54.03031358925434,298.30799670734655,0.1071115041542462
0.113537957610777,267.916350532911,0.36048301541421696,54.01193626743486,298.3350257829507,0.10754229569358024
0.114024701829001,267.841429596942,0.36202842830707815,53.99683220674351,298.38196874418674,0.10797931525297019
0.114500768481317,267.782127634063,0.36353993992818145,53.9848769310271,298.44338703372534,0.10840656337366728
0.114981660071082,267.659833486867,0.36506677072568533,53.96022243095239,298.43580547553637,0.10883795641006362
0.115459392060949,267.537751240329,0.3665835697935131,53.93561065005032,298.4274973518908,0.1092663308759262
0.115945704326382,267.444114294723,0.3681276112362628,53.91673344181616,298.4531104945701,0.10970221073827839
0.116423848816215,267.394759838968,0.3696457199914826,53.906783583535955,298.52588693270815,0.11013058470214263
0.116893448375586,267.359382868041,0.37113669859248555,53.89965158619707,298.61194308705484,0.110551124646809
0.117385263089261,267.297304709797,0.37269821030840367,53.88713662949508,298.67406914620693,0.11099136938359584
0.117865877267248,267.211180521336,0.37422416032351236,53.86977399310135,298.7062607291003,0.11142140087018472
0.118355883266852,267.092922940926,0.3757799293722551,53.845933264890675,298.7049417499245,0.11185964542722675
0.118852545301613,266.983786569202,0.37735683133262127,53.82393137235112,298.7154891572142,0.1123036470111452
0.119336061840269,266.867784174838,0.37889199634285403,53.800545289647346,298.714734570302,0.11273570760213827
0.119815005350273,266.751010096863,0.3804126419871167,53.777003635527585,298.71178379880934,0.11316349786991049
0.12029264855362,266.634897970676,0.3819291591577435,53.75359543088828,298.70911604439283,0.1135899445272872
0.120780970297493,266.531500340522,0.38347958069454025,53.73275046864923,298.7234335664968,0.11402573721833817
0.121276701675101,266.476314317774,0.38505352781844565,53.72162496646323,298.7936827927711,0.11446794831030388
0.121778024637917,266.42495387419,0.38664522822538644,53.71127070103671,298.869658471237,0.1149149485241483
0.122292952425206,266.383960402123,0.38828012395002903,53.703006417068,298.9608413984178,0.11537387143843192
0.122801279361807,266.293868002909,0.3898940619737372,53.68484378938645,298.99509567987036,0.11582670494367203
0.123311419669084,266.179348030553,0.3915137574493417,53.66175656295948,299.0023013227917,0.11628094779290124
0.123825810767635,266.060035633773,0.39314694918724113,53.637703183768636,299.00513525899083,0.11673876683534189
0.124327269650377,265.954737060691,0.394739081139947,53.61647499143531,299.0201633700306,0.11718487426052221
0.124834775502573,265.847230855571,0.39635041222066925,53.59480174048312,299.0342102374069,0.11763615865054894
0.125348030543476,265.757978967737,0.3979799969755363,53.57680855989578,299.07021823255735,0.11809234829738569
0.125852019862341,265.6283508969,0.3995801630629327,53.550675540815035,299.0582153899775,0.11854009999958928
0.126363461652802,265.518788776046,0.4012039907476463,53.52858781725087,299.07066205964634,0.11899426773216179
0.126881805686361,265.444594860966,0.4028497330541962,53.513630323970744,299.12468436660987,0.11945435439047279
0.127409502281204,265.351149455294,0.4045251697428227,53.494791730187266,299.15940733713836,0.11992252512121779
0.127927226430604,265.248834123922,0.4061689439171677,53.474164959382676,299.18138178734665,0.12038163541894216
0.128431486004938,265.084112534479,0.40776996806567817,53.44095708695097,299.12925902358234,0.12082860298659888
0.1289334645841,264.882077407522,0.4093637500545174,53.40022680535643,299.0342413539076,0.12127335037873439
0.12941823586262,264.728440132291,0.4109028988638185,53.369253530669866,298.9891278368753,0.12170266463113333
0.129934512291327,264.595847247873,0.41254207652496316,53.34252280517119,298.9759796143358,0.12215967732037776
0.130451886594229,264.547996487887,0.41418473993667704,53.33287609195803,299.05878172445534,0.12261745242660932
0.130982395206153,264.481383107727,0.4158691047795358,53.31944683451777,299.1237881546133,0.12308663132420115
0.131529541895349,264.430973987775,0.41760629551773304,53.309284355935446,299.21145885932805,0.12357029436340093
0.132049718787402,264.319671025023,0.4192578571500013,53.28684567864464,299.2230092538559,0.12402990000676832
0.132571745814236,264.188614142665,0.4209152929601993,53.26042461116127,299.21255994380164,0.12449092808076666
0.133113416387631,264.051665600264,0.4226350970307284,53.23281578501323,299.2004849111595,0.12496907976110769
0.133646645470954,263.891735674381,0.42432809937027893,53.20057391195521,299.1599809147697,0.12543955663436038
0.134175958526621,263.687368392363,0.42600866832202167,53.15937346790038,299.0678737977706,0.125906359517748
0.134700061001044,263.502182449263,0.4276726936783147,53.12203998177142,298.99594249908694,0.12636835257442808
0.135230772570282,263.298889187824,0.4293577029106453,53.08105606026532,298.9050013895905,0.126835954116342
0.13576343707333,263.163222062347,0.4310489127078227,53.05370556776916,298.89116560082323,0.12730505660066735
0.136307108623409,263.067565996398,0.43277506987932357,53.03442130487384,298.9255452899648,0.12778362586119046
0.136855438431515,262.975085762085,0.43451601702006004,53.01577728963633,298.9646564206204,0.12826606370484725
0.137404331754791,262.845001005383,0.4362587533214614,52.98955220268521,298.96104272361504,0.1287487643542007
0.137946949571214,262.651559732188,0.43798156488860446,52.9505544420091,298.8835411973648,0.12922571736902763
0.138496705812664,262.450224904571,0.43972704095520815,52.90996534076151,298.79871649364685,0.12970871307229254
0.139045667140914,262.221923424144,0.4414699931724019,52.86393976230743,298.6827457056277,0.1301907777270712
0.139599331319817,262.067711118243,0.44322787694041893,52.832850561437795,298.65218835086466,0.13067673687399664
0.140141062025529,261.869781690187,0.44494787193105456,52.7929479887417,298.5684910086432,0.13115199337029776
0.140683928790698,261.593409712215,0.4466714739104661,52.737231397982555,298.3953983362842,0.13162802005152588
0.14122487907757,261.352600660362,0.4483889910712847,52.68868429312898,298.26209008523006,0.1321021409236135
0.141780498129415,261.170918648726,0.4501530815608926,52.65205719958316,298.1998615916593,0.13258888446645564
0.142345806071774,261.037866034987,0.45194793427788243,52.62523379265338,298.195511490993,0.13308387281527106
0.142923984135234,260.925457993181,0.4537836496293679,52.60257233142529,298.21796401187703,0.13358987703260594
0.143507096633665,260.696760635151,0.45563503181188636,52.55646694404644,298.1085958557031,0.13409994052498747
0.144092160929982,260.424709878451,0.45749261095269284,52.50162151149573,297.9498690844006,0.13461144996628388
0.14467246050092,260.151165545476,0.45933506209042096,52.44647497396796,297.78787476712216,0.13511853538515053
0.14526190486102,259.874349390245,0.4612065479337385,52.3906688370734,297.62419240719026,0.13563334871957144
0.145855097530623,259.558495198964,0.46308993465972803,52.32699263211114,297.41642483111065,0.136151168352736
0.146456817074313,259.218924751194,0.4650003942109437,52.25853522984071,297.18330339567973,0.1366761576036983
0.147046055389051,258.900075661765,0.4668712258602369,52.19425525341183,296.9703105277544,0.13718999025224382
0.147619855405776,258.576198873506,0.46869304091333874,52.128961692898805,296.74717996258806,0.13769010665349024
0.148211403403884,258.262061313428,0.4705712058073317,52.06563156078708,296.53944386667104,0.1382054302504915
0.148791264684267,257.948488847134,0.4724122653725477,52.002415351582215,296.3289707260946,0.13871031542172504
0.149376714667805,257.55565142811,0.4742710690702808,51.923219327906985,296.02846848256746,0.13921980820159355
0.149948842113948,257.165026312831,0.47608757371178484,51.84446930466673,295.726624240643,0.13971745626736048
0.150521359493925,256.665847723833,0.4779053163932119,51.74383490112473,295.29954005888504,0.14021519572201332
0.151114447564634,256.275898149375,0.4797883710177129,51.665221066914,295.0028889223482,0.1407305579544022
0.151707227212936,255.918777442327,0.48167044640107176,51.593225532373125,294.74350555982693,0.14124538692955704
0.152333224668324,255.589827196871,0.4836579883219287,51.5269091628892,294.52464976619007,0.14178877797139416
0.152981203754778,255.1988793839,0.48571532192142014,51.44809408379424,294.2395111489194,0.142350939120025
0.153637673887281,254.711131469682,0.4877996145921171,51.349764104287885,293.8443572218813,0.14292014468457706
0.15428135799372,254.154288312617,0.489843311630061,51.23750452382359,293.36555705341505,0.1434779494552276
0.154911805932432,253.516431082721,0.4918449838354716,51.10891250627656,292.78911925529025,0.14402398255823926
0.155525062699768,252.887918131656,0.4937920740717634,50.98220429534185,292.21832745509556,0.14455484041465919
0.156155780690475,252.302844282994,0.4957946036922581,50.86425340745159,291.70139190243225,0.14510051955385433
0.156794095907133,251.643500919793,0.49782125450514725,50.73132978543027,291.0997161374178,0.14565246859461964
0.157439681022103,251.033213616654,0.49987098724517703,50.60829586511744,290.55580269441344,0.14621039419241572
0.158118720311525,250.273038409298,0.5020269369890918,50.45504454331448,289.8458909710534,0.14679689575376337
0.158808959666372,249.552426021196,0.5042184469407311,50.309769085873114,289.18358717984137,0.14739271873195264
0.159522892944865,248.798520349441,0.5064851850999463,50.1577817024473,288.4875800759857,0.14800862132610226
0.16024086285873,247.872061894244,0.5087647395764677,49.9710076778796,287.5912949707502,0.14862762395944687
0.160918703101465,246.952655416878,0.5109168823471514,49.78565533204261,286.691956454025,0.14921167709559843
0.161578101434327,245.882280060417,0.5130104720539882,49.56986766018007,285.6114720489226,0.14977951283969254
0.1622635863687,244.696257754877,0.5151868867206225,49.3307655633832,284.4015501091832,0.15036947123303143
0.162956702168604,243.499029929469,0.5173875293853176,49.089404433780956,283.1788288280295,0.15096564340979235
0.163685364323141,242.251862802488,0.5197010317259727,48.83797554098158,281.9049472232728,0.1515920072058006
0.164418921440571,241.01717745364,0.5220300755738129,48.58906297465383,280.64496181921817,0.15222218270626373
0.165151511865984,239.478038260246,0.5243560501744992,48.278772513265594,279.0281983376256,0.15285113166534114
0.165902156931376,237.91109039615,0.5267393482571188,47.96287582386384,277.38105345076684,0.15349517096944307
0.16665552400471,236.043029946224,0.5291312887149543,47.58627483715876,275.38090478957145,0.15414112892854295
0.167451134610944,233.972402936184,0.5316573523897471,47.1688364319347,273.15134727549696,0.15482285496202178
0.168326569436522,231.508663515609,0.5344368579609573,46.672146564746775,270.47772264002555,0.1555724424463546
0.169028932831186,229.353460602051,0.5366668617390156,46.23765765737348,268.12083128875514,0.15617343225310257
0.169505298333757,227.725516092267,0.5381793222096785,45.90946404420102,266.3261976356955,0.15658083745830464