File: example/data/02 processed data/test_ID_149.csv
Strain,Stress_MPa,Displacement(mm),Force(kN),True Stress (MPa),True Strain
0.0009387008148291,0.0285484792820402,0.0001575289289469,0.0057553734232593,0.0285498957265644,4.961417988814976e-05
0.0009188411935085,0.549637009142646,9.4474631254028e-05,0.1108068210431574,0.5496533640257207,2.975534667664749e-05
0.0008901527241228,1.18193769293886,3.3887409544477035e-06,0.2382786388964742,1.1819389544445815,1.0673194161402746e-06
0.0008678180962182,1.94865798735596,-6.752370264279896e-05,0.3928494502509615,1.948616544646514,-2.126753407135909e-05
0.0008363704739722,3.19392025365453,-0.0001673699032737,0.6438943231367533,3.1937518863714063,-5.271631964577212e-05
0.0007971811778796,4.65166307862105,-0.0002917959183678,0.9377752766500038,4.651235571124999,-9.190844970977247e-05
0.0007417937196353,6.27599443587093,-0.0004676510982935,1.2652404782715796,6.275070034078547,-0.0001473025329873
0.0006837333778258,7.8845327354469,-0.0006519926835386,1.589521799466095,7.882913630673157,-0.0002053731139257
0.0006266636387037,9.4786646478656,-0.0008331891052513,1.910898793009705,9.476177239954756,-0.00026245620405
0.0005929800336019,11.0504908615377,-0.0009401345514495,2.227778957686,11.047218751846549,-0.0002961492183864
0.0005573618801588,12.5288300561609,-0.0010532221886314,2.525812139322037,12.524673948503343,-0.0003317785563972
0.0005290264099674,13.9730239412675,-0.0011431873064891,2.8169616265595283,13.967992828321698,-0.0003601238309732
0.0004967245645317,15.441736798157,-0.0012457456657474,3.113054138508452,15.435678065341907,-0.0003924378332598
0.0004699589805242,16.976194399602,-0.0013307263949712,3.422400790959764,16.969079227956737,-0.0004192142816423
0.000455976759214,18.5451435443648,-0.0013751199476311,3.738700938543944,18.5371114823744,-0.0004332024635624
0.0004581433134794,20.1554888663989,-0.0013682411378385,4.063346555466018,20.146803017888587,-0.000431034972886
0.0004464226593682,21.7868253337227,-0.0014054542146415,4.392223987278497,21.77718111782067,-0.0004427607488447
0.0004375944930256,23.3976348907649,-0.0014334836427793,4.716963193978203,23.38707107127021,-0.0004515928638213
0.0004232123145397,25.0125044366063,-0.001479147059472,5.04252089441983,25.00085178388585,-0.000465981642181
0.0004249657401903,26.6291157196594,-0.0014735799330314,5.368429729083336,26.61675662342039,-0.0004642274008146
0.0004434949993936,28.2176313655689,-0.0014147495350609,5.688674483298691,28.20505785978781,-0.0004456897096486
0.0004534248413114,29.7919843652882,-0.0013832222869719,6.006064048042101,29.77900517261192,-0.0004357554904606
0.0004558713863295,31.3718516076855,-0.0013754545065394,6.324565284109397,31.358260881804465,-0.0004333078821101
0.0004594203600666,32.9378644640673,-0.0013641865149241,6.640273475955968,32.923712215080755,-0.0004297573765446
0.0004747368327045,34.5140046317754,-0.0013155567142988,6.9580233337659205,34.4997038032618,-0.0004144344375218
0.0004946585616784,36.1042944073848,-0.0012523052248066,7.278625752528776,36.09005390454249,-0.0003945046491859
0.0005091589642385,37.6904904103306,-0.0012062664466783,7.598402866722648,37.676170796490965,-0.0003799986302338
0.0005306118178556,39.2605122279626,-0.001138153636444,7.914919265157261,39.246438371344986,-0.0003585378532967
0.0005568510130187,40.849067567177,-0.0010548441918012,8.235172021542883,40.83549610208606,-0.0003322895931908
0.0005766049141001,42.4256360129808,-0.0009921255558677,8.55300822021693,42.41237882944933,-0.0003125293222384
0.0005946499202187,43.965975039715,-0.0009348326614412,8.863540568006544,43.95302989657823,-0.0002944788385558
0.0006141215337497,45.5076956248309,-0.0008730102884803,9.17435143796591,45.49518265270948,-0.0002750016798834
0.0006320174952088,47.0246747274087,-0.0008161906108476,9.480174425045597,47.01258619260849,-0.0002571009565471
0.0006664637275993,48.5134387846266,-0.0007068238230078,9.780309258980722,48.50263864154975,-0.0002226464604216
0.0006788901158429,49.9578398284499,-0.0006673700403344,10.0715005094155,49.9473389259046,-0.0002102173824199
0.0006966677421867,51.3787243323125,-0.0006109260766928,10.3579508253942,51.36883815830248,-0.0001924361766039
0.0007228621330371,52.7406913556773,-0.0005277588857428,10.632523377304544,52.73192462544008,-0.000166237087719
0.000754147374033,54.0681392270688,-0.0004284282455808,10.90013686817707,54.060843378870096,-0.0001349471350592
0.000788052438305,55.3400735650752,-0.0003207796665172,11.15655883071916,55.33448239331355,-0.000101038070006
0.0008223583995415,56.590045483416,-0.0002118582395912,11.408553169456663,56.58626939919096,-6.67292309412558e-05
0.0008514532349169,57.8056215350933,-0.0001194821372743,11.65361330147481,57.80344618416181,-3.763287732810384e-05
0.0008800578042811,59.0062272545232,-2.8662629543077625e-05,11.895655414511875,59.00569456991453,-9.027640605128844e-06
0.0009044882492439,60.1350843161042,4.89040332137452e-05,12.123232998126609,60.1360105674934,1.5402726484103922e-05
0.0009339283556423,61.2424062981088,0.0001423763710287,12.346469109698733,61.24515258836448,4.4841946090104574e-05
0.0009670789623592,62.3558297304406,0.0002476295473549,12.570935273656824,62.36069308347716,7.799051688259608e-05
0.0009946842676163,63.4585465543175,0.0003352763915461,12.793242985350409,63.46524770471167,0.0001055932883115
0.001024309737513,64.5283783740971,0.0004293372584681,13.008921080217975,64.53710418104656,0.0001352151913898
0.0010453395901411,65.5831685418748,0.0004961070405623,13.22156677804196,65.59341618649086,0.00015624197959
0.0010771748206738,66.6422661601775,0.0005971838975037,13.435080857891784,66.65480086513625,0.0001880717299401
0.0011097827629058,67.6711038635021,0.0007007141140903,13.642494538882024,67.68603869738973,0.0002206730086891
0.0011561727191975,68.714682572139,0.0008480022253164,13.852880006543222,68.73303539221241,0.000267051653593
0.0011944862018351,69.7119687569191,0.0009696475326908,14.053932901394893,69.73325884778656,0.000305354172367
0.0012392977453379,70.6910209880989,0.0011119241833122,14.251309831200738,70.71577785606101,0.0003501510311726
0.0012713549783439,71.6248239148895,0.0012137058981062,14.439564501241724,71.65220390583008,0.0003821965278079
0.0013115501801687,72.5149614080231,0.0013413256639,14.619016219857455,72.54559642495327,0.0004223755629134
0.0013544806057732,73.4237485635665,0.0014776297651943,14.802227710415009,73.45791962383412,0.0004652869388778
0.0014124848633213,74.2862298442952,0.0016617932829095,14.976103936609912,74.32511121682053,0.0005232625334628
0.0014578271391781,75.1183524379702,0.0018057550087548,15.143859851494792,75.16107538006918,0.0005685800627572
0.001502705388134,75.918173186136,0.0019482434491898,15.30510371432502,75.96475809435154,0.0006134317962343
0.0015526589145715,76.7043101091194,0.0021068458956289,15.463588917998472,76.75520905744396,0.000663353442881
0.0016238445824123,77.432574162449,0.0023328603910234,15.610406951149718,77.48946845701234,0.0007344893749023
0.0017044377467,78.156850656708,0.0025887436876368,15.756421092392332,78.22057602797827,0.0008150201234129
0.001793036163194,78.7882291843133,0.0028700436600053,15.88370700355756,78.85944986388918,0.0009035424416166
0.0018697196116792,79.4067917302712,0.0031135136089458,16.008409212822674,79.48466074655306,0.0009801536999266
0.0019608225661235,79.948294172689,0.0034027654893065,16.117576105214102,80.03397773059129,0.0010711632617244
0.0020665751571863,80.4561916910858,0.0037385299659308,16.2199682449229,80.55092803237142,0.0011767970556993
0.0021805473834993,80.9189628621012,0.0041003917844746,16.3132629129996,81.02346662604701,0.0012906287596438
0.0022993657107085,81.3316782900566,0.0044776399733638,16.39646634327541,81.44637875424945,0.0014092867952762
0.0024179607368974,81.6842196684874,0.0048541791815136,16.46753868516706,81.80910465701432,0.0015277077927326
0.0025363824618131,81.9731469214005,0.0052301681581209,16.52578641935434,82.10818104513257,0.0016459417520676
0.0026774655746208,82.2475787859809,0.0056781070412854,16.58111188325375,82.39466872495204,0.0017867829227072
0.0028136206741119,82.4905158814049,0.0061103994821696,16.630088001691227,82.64927178865706,0.0019226857246019
0.0029702334145736,82.6913229033387,0.0066076449331355,16.67057069731308,82.86341578547933,0.0020789854218405
0.0031151040812225,82.8323791667759,0.0070676092997458,16.69900764002202,83.01676558986854,0.0022235447681413
0.0032656509038453,82.958776000192,0.0075455954615732,16.724489241638707,83.15593296513207,0.0023737459342918
0.0034194381437541,83.0819416203768,0.0080338699482836,16.749319430667963,83.29216823896861,0.0025271567872461
0.003574323299193,83.1949174423745,0.0085256303168021,16.7720953563827,83.41831558736679,0.0026816390847807
0.003727764214316,83.2567983509056,0.0090128052223176,16.784570547542568,83.49313766018764,0.0028346573700721
0.0038941817836877,83.3246702907754,0.0095411810050728,16.798253530620322,83.57506895579345,0.0030005901030316
0.0040562207423878,83.3721072918926,0.0100556546989456,16.80781683004555,83.63615803912117,0.0031621305296116
0.0042255552946764,83.4188176976074,0.0105932919024619,16.817233647837654,83.69714207115983,0.0033309162245382
0.0043935096205159,83.4839350878391,0.0111265468870023,16.830361313708362,83.7764982116395,0.003498298030166
0.0045584611950827,83.5114365604524,0.0116502681362519,16.835905610587204,83.81787140403439,0.0036626600549568
0.0047442757765191,83.5421909455121,0.0122402294323125,16.842105694615242,83.86426199573292,0.0038477781701708
0.0049113260246561,83.5865054170746,0.0127706139701475,16.85103949208224,83.92271045449039,0.0040141730366541
0.0050813955590298,83.6023358386707,0.013310584741784,16.85423090507601,83.9528227601799,0.0041835469063084
0.0052541347910087,83.6155166735465,0.013859031803317,16.856888161386973,83.9805025333353,0.0043555501917352
0.0054192716005864,83.6123127563019,0.0143833411737262,16.856242251670466,83.99109210140371,0.0045199557884281
0.0056070842791845,83.5913737172685,0.0149796464282751,16.852020941401328,83.98575772443021,0.0047069040017353
0.0057889353488272,83.576086307586,0.0155570235743907,16.848938999609338,83.98559658945763,0.0048878847491405
0.0059638239061707,83.5582548994386,0.0161122947439563,16.84534418772682,83.98229119273951,0.0050619054146655
0.0061522077521866,83.5440196984521,0.0167104134550568,16.842474371207945,83.98372209557292,0.005249320525564
0.0063521580897712,83.5385970990008,0.0173452557768879,16.84138117515856,83.99497452700852,0.0054482042311003
0.0065320747497614,83.535431171016,0.0179164911723568,16.840742924076828,84.00682071909617,0.0056271273260747
0.0067267917045115,83.5232141689984,0.0185347175036884,16.838279976470076,84.01079816258027,0.0058207329179949
0.0068970078333375,83.5082388809504,0.0190751537127109,16.8352609583996,84.00994990234628,0.0059899468246698
0.0070902036646147,83.4712352782863,0.019688550477016,16.827801032102517,83.9888502795951,0.0061819704444471
0.0072698044608925,83.4150717377224,0.020258783005198,16.816478462324834,83.9473198755799,0.0063604484505827
0.0074605042759126,83.3669324981027,0.0208642549178868,16.806773591617507,83.91477153160275,0.0065499212274037
0.0076350129716909,83.3277333038231,0.0214183200269829,16.798871034050734,83.88985615705911,0.0067232756134114
0.0078239691161357,83.2786920928681,0.0220182557855952,16.788984325922208,83.85622013821947,0.0069109480031377
0.0080085634698902,83.2383090563257,0.0226043428587657,16.780843105755263,83.8309223718826,0.0070942542313853
0.0082065548195649,83.2067775173178,0.0232329653939829,16.77448634749127,83.81564056695707,0.007290826629007
0.0083913306890472,83.1931580393754,0.0238196287795892,16.771740660738082,83.81729351701308,0.007474243406848
0.0085957581529859,83.1732978640536,0.0244686859775946,16.767736849393206,83.81428725213436,0.0076771280435826
0.0087912760977403,83.148082688276,0.0250894554521898,16.762653469956444,83.80513469348625,0.0078711318991063
0.0089840394426444,83.1126133670713,0.0257014790722603,16.755502854801577,83.78540615229797,0.0080623656476214
0.0091676337235569,83.0869421794751,0.0262843909141575,16.75032754338218,83.77478144502071,0.0082444690934415
0.0093610983073149,83.0575071629718,0.0268986409675891,16.744393444055117,83.76117143536227,0.008436326815533
0.0095488673514287,83.0042665910979,0.0274948076826505,16.733660144765338,83.72306544047167,0.0086225011102772
0.0097456863824919,82.9690304582879,0.0281197081062761,16.726556540390842,83.7038540546179,0.00881761132931
0.0099281749455017,82.9366639685032,0.0286991092938322,16.720031456050243,83.68633590037656,0.0089984814945666