File: example/data/02 processed data/test_ID_131.csv
Strain,Stress_MPa,Displacement(mm),Force(kN),True Stress (MPa),True Strain
-0.0001757053656828,0.025880228309496,-0.00055786453604289,0.005217454027194394,0.025875681014516927,-0.00017572080367893835
-0.0002803368553993,0.926576767246164,-0.0008900695158927775,0.18679787627682667,0.9263170136289481,-0.0002803761571208657
-0.0004242953489111,2.59971981004022,-0.0013471377327927423,0.5241035137041083,2.598616761016348,-0.00042438538765221957
-0.0005394317464564,5.56207673861297,-0.0017126957949990698,1.1213146705043748,5.559076377843936,-0.0005395772921046229
-0.0006214573894341,8.85841195084581,-0.0019731272114532675,1.7858558492905152,8.852906825280305,-0.0006216505741190422
-0.0006079986469456,12.0225591275764,-0.0019303957040522797,2.4237479201194025,12.01524942789401,-0.0006081835530752002
-0.000617623984104,14.8016040987999,-0.0019609561495301997,2.98400338631806,14.792462273105269,-0.00061781479236612
-0.0005720397762517,17.3886861968846,-0.0018162262895991472,3.5055591372919355,17.378739176723222,-0.0005722034534274405
-0.0005342872583559,20.010965093598,-0.0016963620452799823,4.034210562869356,20.000273489921085,-0.0005344300406532416
-0.0004407632457226,22.6166987818425,-0.0013994233051692548,4.559526474419449,22.606730172279885,-0.00044086041039413583
-0.0003694273596367,25.2541059357424,-0.0011729318668465224,5.091227756645668,25.24477637806657,-0.00036949561473448463
-0.0002784687033237,28.0237456282638,-0.0008841381330527474,5.6495871186579825,28.015941892156423,-0.0002785074829325128
-0.0002199838361855,31.0647314037417,-0.0006984486798889625,6.262649850994327,31.057897664957434,-0.00022000803617871698
-0.0001251972916422,34.2402219875369,-0.0003975014009639849,6.902828752687439,34.235935204478835,-0.0001252051294772841
-3.43100786839892e-05,37.5933352779546,-0.00010893449982166569,7.578816392035648,37.59204544766322,-3.431066728825419e-05
5.90706845761526e-05,40.9895978816744,0.0001875494235292845,8.263502932945558,40.992019165281775,5.906893997203826e-05
0.0001574239687721,44.5400136486164,0.0004998211008514174,8.979266751561067,44.54702531433413,0.00015741157891936995
0.0002527000211378,48.2518485364751,0.000802322567112515,9.727572664953382,48.26404177962021,0.0002526680978654168
0.0003578062881537,52.0960515047389,0.0011360349648879976,10.502563983355362,52.11469179955528,0.0003577422907491454
0.0004554753149833,55.9304182148807,0.0014461341250719775,11.27557231211995,55.95589313973427,0.00045537161758850593
0.0005503115995426,59.7600743925002,0.0017472393285477548,12.04763099752804,59.79296105462792,0.0005501602336440949
0.0006508953607142,63.7869983026733,0.002066592770267585,12.859458857818936,63.8285169639424,0.000650683620204605
0.0007380548814902,67.6685867820272,0.002343324248731385,13.641987095256685,67.71852991282522,0.0007377826529242805
0.0008429706088065,71.4688508044784,0.002676431682960637,14.408120322182844,71.52909694515174,0.0008426155086281225
0.0009271633376838,75.0449719059755,0.0029437435971460648,15.129066336244662,75.11455085260422,0.0009267337872447923
0.0010222417193782,78.5634738728974,0.0032456174590257845,15.838396332776117,78.64378473350955,0.0010217195861123715
0.0011220390153702,81.9654090474348,0.0035624738738003845,16.524226463962858,82.0573774342968,0.0011214100000699434
0.0012075014242369,85.4449914246803,0.0038338170219521578,17.225710271215547,85.5481663735195,0.001206772980730957
0.0013077761076485,88.899515427086,0.004152189141783987,17.922142310100536,89.01577608934308,0.0013069217132978927
0.0013966828500887,92.3113595189718,0.004434468049031622,18.609970079024716,92.44028921168031,0.00139570839582696
0.0014900849068045,95.7075520740811,0.0047310195791042875,19.29464249813475,95.85016445289388,0.0014889758318968787
0.0015776076346791,99.0193695360283,0.005008904240106142,19.962304898463305,99.17558324938945,0.0015763645190154478
0.001670520722005,102.211937455944,0.005303903292365875,20.60592659111831,102.38268461550042,0.0016691269542596272
0.001754363259143,105.392933093106,0.005570103347779024,21.247215311570166,105.57783058269786,0.001752826161409785
0.0018429480899567,108.533356883448,0.005851360185612522,21.880324747703117,108.73337822621293,0.0018412519447441782
0.0019440356801083,111.688325554655,0.006172313284343852,22.516366431818447,111.9054516445848,0.0019421484881953874
0.0020305991951635,114.752241106763,0.006447152444644113,23.13405180712342,114.9852569151976,0.002028540315319807
0.0021093657363089,117.688970055612,0.006697236212780757,23.726096363211383,117.9372191365888,0.0021071441479505464
0.0022002593223222,120.643125795192,0.006985823348372985,24.32165416031071,120.90857195739697,0.0021978422965192633
0.0022915892489628,123.35633915938,0.00727579586545689,24.86863797453101,123.63902121998905,0.0022889675627744592
0.0023940336122984,125.940257821567,0.00760105671904742,25.38955597682791,126.24176303193337,0.00239117247935254
0.0025185857401427,128.515789187622,0.007996509724953072,25.908783100224596,128.83946722165314,0.002515419418398274
0.0026461645153045,130.915238215649,0.008401572336091788,26.39251202427484,131.26166147352788,0.002642669586064233
0.0027764172839706,133.148041301492,0.008815124876606654,26.842645126380784,133.51771582468828,0.002772570156678611
0.0029218746318309,135.306699667713,0.009276951956063107,27.277830653010938,135.70204888098885,0.0029176142529931987
0.0030859933967014,137.220396921751,0.009798029034526945,27.663632019425,137.64385816054426,0.0030812414927984975
0.0032629139248268,138.812215536844,0.01035975171132509,27.984542652227752,139.26514784785525,0.0032576021725769814
0.0034666651246443,140.185674849347,0.011006661770745652,28.261432049628358,140.67165163932196,0.0034606700922855177
0.0036928508890634,141.262877440393,0.011724801572776293,28.478596091983228,141.78454018294042,0.0036860490555140025
0.0039523166659385,142.219638559212,0.012548605414354735,28.67147913353714,142.78173560691332,0.003944526781073105
0.0042372390582647,143.077198861288,0.013453234009990421,28.84436329043566,143.68345115665016,0.0042282872392688225
0.0045411307972962,143.688624167526,0.014418090281415436,28.967626632173243,144.34113300395427,0.004530850972441246
0.0048712659237977,144.051360349301,0.015466269308057697,29.040754246419084,144.75307283224726,0.004859439698190721
0.0052125404580754,144.262869745798,0.016549815954389396,29.08339454075288,145.01484579094605,0.005199002194513823
0.0055459086935967,144.354258285255,0.01760826010216952,29.101818470307414,145.1548338212369,0.005530586765217889
0.0059065402622392,144.414772365256,0.01875326533260946,29.11401810883561,145.2677640326935,0.005889165038041327
0.0062579556595324,144.3958533534,0.01986900921901537,29.110204036045445,145.29947620110593,0.006238455964879873
0.0066239096448368,144.395725433214,0.021030913122356838,29.110178247335945,145.35218967158428,0.006602067953883662
0.006998314633637,144.330175334688,0.022219648961797473,29.096963347473103,145.34024331280813,0.00697394008421732
0.0073920444022563,144.263062808739,0.023469740977163752,29.083433462241782,145.32946177462668,0.007364857139461632
0.0077934196007411,144.198673698476,0.024744107232352992,29.070452617612766,145.3224744684786,0.00776320777364609
0.0081973667462874,144.11104639095,0.02602663941946249,29.052786952415524,145.29237749040786,0.00816395082633046
0.0086108095458649,143.979473339497,0.027339320308121057,29.026261825242596,145.21925316293732,0.008573947979484723
0.0090143368417419,143.780807227828,0.02862051947253053,28.98621073713013,145.0768958555572,0.008973950231617654
0.0094219658675953,143.599406101259,0.029914741629615077,28.949640270013816,144.95239480415202,0.009377855998520484
0.0098284831503261,143.403643082242,0.031205434002285364,28.91017444537999,144.8130833719712,0.009780497769302858
0.0102351990981884,143.239977570018,0.03249675713674817,28.87717947811563,144.70606725926717,0.010183174137312418
0.0106479690441314,143.072408363318,0.03380730171511719,28.84339752604491,144.59583893863996,0.010591678654733512
0.0110606064731717,142.903682496021,0.03511742555232015,28.809382391197833,144.48428389167657,0.01099988529714202
0.0114799880925666,142.768035779715,0.036448962193898954,28.782036013190545,144.40701113046526,0.011414593042966516
0.0118997201652322,142.620719294296,0.037781611524612235,28.752337009730077,144.31786594366227,0.011829475209643536
0.0123227020997686,142.413826272935,0.0391245791667653,28.710627376623698,144.16874942898457,0.012247395627913963
0.0127421489745828,142.204656268752,0.04045632299430039,28.668458703780402,144.01664918380774,0.012661650885556732
0.0131674130000465,142.061262785855,0.04180653627514764,28.63955057762837,143.9318421042645,0.013081476172619908
0.0135868103388014,141.84401269723,0.043138122825694444,28.59575295976157,143.77122039544182,0.013495337251493378
0.0140116064244442,141.608267778056,0.04448685039761033,28.548226784056087,143.59242709260943,0.013914351281437297
0.0144237019585689,141.352740539075,0.045795253718456254,28.49671249267752,143.39157033963752,0.014320669923290131
0.014855628350604,141.156283656857,0.047166620013167695,28.457106785222372,143.2532489462157,0.01474636429873326
0.0152880243881651,141.025385037911,0.04853947743242419,28.43071762364286,143.18138456372094,0.015172340109377019
0.0157224616167127,140.918664070067,0.049918815633062816,28.409202676525506,143.13425235698705,0.01560014413911195
0.0161564629395484,140.75304564183,0.05129676983306617,28.37581400139293,143.02711700737078,0.01602733625591648
0.0165867458075595,140.575489146738,0.05266291793900141,28.340018611982376,142.90717905198827,0.016450688180139998
0.017021983252648,140.338698807242,0.0540447968271574,28.29228167953999,142.72754178803726,0.016878732617119772
0.0174418838703621,140.082018043907,0.055377981288399665,28.240534837651655,142.52531233495478,0.017291520114073734
0.0178714418778236,139.907476249682,0.05674182796208993,28.20534721193589,142.40782457975118,0.01771362516139527
0.018303962740837,139.737465293495,0.05811508170215747,28.171073003168594,142.29521465172616,0.01813846171382353
0.0187379046135329,139.61763638743,0.05949284714796696,28.14691549570589,142.23377834042458,0.018564512730461325
0.0191763720933478,139.475109173517,0.06088498139637926,28.11818200938103,142.1497357647887,0.018994822770085882
0.0196167531343552,139.321555873796,0.06228319120157776,28.087225664157273,142.05459244166653,0.019426824469921992
0.020068503287016,139.160422098469,0.06371749793627579,28.054741095051355,141.95316348677468,0.019869785126351992
0.0205139728272461,138.979966680704,0.06513186372650637,28.018361282829925,141.83099794072353,0.020306395312434677
0.020962917391291,138.785201319998,0.06655726271734892,27.979096586111602,141.69454403040282,0.020746218631947328
0.0214042711892472,138.616664853771,0.06795856102585986,27.945119634520236,141.5836535396501,0.021178416923512286
0.0218364784830703,138.458283543806,0.0693308191837482,27.913189962431293,141.48172487321315,0.02160147749563398
0.0222700442801184,138.269305621023,0.07070739058937592,27.875092013198238,141.34856917978442,0.022025688072452636
0.0227083082469174,138.067048072593,0.07209887868396274,27.834316891434746,141.20231715896742,0.022454312632675718
0.0231630936913979,137.903235191969,0.07354282247018833,27.801292214700954,141.09750074906745,0.022898901135687644
0.0236083771673832,137.763701285887,0.07495659750644165,27.773162179234824,141.01607870581893,0.023334009294414915
0.0240571213409834,137.595555308251,0.07638136025762228,27.7392639501434,140.9057082782816,0.023772307621081103
0.0244984795452894,137.437588105065,0.07778267255629384,27.707417761981105,140.80460004601085,0.024203204601318258
0.0249358041311662,137.2526367334,0.07917117811645268,27.670131565453445,140.67514159947018,0.024629980513088533
0.0253698725677926,137.037609242684,0.0805493454027415,27.626782023325095,140.51423592616587,0.02505339878485605
0.0258126798009415,136.833776932107,0.08195525836798925,27.585689429512772,140.36582340200894,0.025485156786615854
0.0262486178325009,136.62430348323,0.08333936161819035,27.543459582219167,140.21050261199292,0.025910034969953033
0.0267027498960232,136.482369036848,0.08478123091987366,27.514845597828558,140.12682360245572,0.02635245370238721
0.0271484246821288,136.342796374507,0.08619624836575893,27.48670774910061,140.04428851283112,0.026786443076707012
0.027600965990585,136.242124904884,0.08763306702010737,27.466412380824618,140.00253916086874,0.02722692629848333
0.0280452165439268,136.131271524565,0.08904356252696759,27.444064339352305,139.94910251287152,0.027659151030572586
0.0285042488145398,136.018504352432,0.09050098998616386,27.421330477450287,139.89560964387528,0.028105561181136017
0.0289552356876424,135.888905574985,0.09193287330826462,27.395203363916977,139.82360086324445,0.02854395317254341
0.0294063595124913,135.706017816463,0.09336519145215987,27.358333191798945,139.69663776438247,0.028982286100172915
0.0298689313415348,135.528542846179,0.09483385700937298,27.32255423778969,139.57663558726978,0.029431543019709606
0.0303270923741802,135.382399876476,0.09628851828802214,27.293091815097565,139.48815442336812,0.029876317240147256
0.030787984549628,135.26723806859,0.0977518509450689,27.269875194627744,139.43184370431658,0.030323543295877716
0.0312537311303113,135.134929787062,0.09923059633873839,27.2432018450717,139.35840054894032,0.030775276725964994
0.031720111887046,134.943512742928,0.10071135524137105,27.204612168974286,139.2239360655647,0.031227420863670467
0.0321866909643092,134.71231937151,0.1021927438116817,27.15800358529642,139.0482631642061,0.0316795527957585
0.0326527064084371,134.492115940257,0.1036723428467878,27.11361057355581,138.8836475163037,0.03213093458616155
0.0331173618084707,134.350378709272,0.10514762374189446,27.085036347789238,138.79970881009203,0.03258079627698459
0.0335816010190759,134.230462040954,0.10662158323556599,27.060861147456325,138.73813586181953,0.03303005301612588
0.0340397783721944,134.067972304644,0.10807629633171721,27.028103216616234,138.6316163687036,0.03347324572556959
0.0345005006734715,133.867804773372,0.109539089638272,26.9877494423118,138.48631106211187,0.03391870217963311
0.0349568725038078,133.682828924991,0.11098807019958976,26.950458311278187,138.35596253167026,0.03435975677070571
0.0354154741801885,133.524063381402,0.11244413052209848,26.918451177690642,138.25288140051987,0.034802770496826584
0.0358719846132719,133.443046854546,0.11389355114713828,26.902118245876473,138.22991377806042,0.03524356922665745
0.0363349397817388,133.23158909218,0.11536343380702069,26.859488360983487,138.07255085886973,0.035690392534425665
0.036814651062652,133.113117548773,0.11688651712392009,26.835604497832637,138.01363052319286,0.036153177556397416
0.0372850030408513,132.985583207951,0.11837988465470287,26.809893574722924,137.94395108224884,0.036606725663723624
0.0377576793418281,132.867504728707,0.11988063191030422,26.78608895330733,137.88427336720235,0.03706230791575671
0.0382232397004588,132.724647333187,0.12135878604895668,26.757288902370497,137.79781334236225,0.037510828768877166
0.0386946615744878,132.578086261935,0.12285555049899877,26.727742190406097,137.70815044203383,0.03796479171255995
0.039183981730504,132.443461347759,0.12440914199435019,26.700601807708217,137.6331235175343,0.03843577221629429
0.0396718457889773,132.346883867247,0.1259581103800029,26.681131787636993,137.5973290346801,0.03890513046708912
0.0401728385024519,132.23108899373,0.12754876224528477,26.657787541135967,137.54318717687846,0.039386890212851196
0.040662092786258,132.089106066982,0.12910214459636915,26.62916378310357,137.4601255539315,0.03985713827094087
0.0411527878250364,131.92202516813,0.13066010134449055,26.59548027389501,137.35098427932317,0.04032854910812493
0.0416425531097666,131.777680089401,0.13221510612350895,26.566380306023245,137.26523913120573,0.0407988452376885
0.0421311983440299,131.649640778344,0.13376655474229493,26.540567580914153,137.19619790589672,0.04126784552419216
0.042617871961051,131.478368719396,0.1353117434763369,26.506039133830235,137.0816970031271,0.04173473492857547
0.0431160629787086,131.295768391452,0.1368934999573998,26.46922690771672,136.95672501025578,0.042212447851385344
0.0436127469812441,131.125548393251,0.13847047166545,26.434910556079398,136.84429375810274,0.042688488637849346
0.0441144457201377,130.973935657299,0.1400633651614372,26.40434542851148,136.75177823260572,0.04316910578965426
0.0445964556285008,130.816978254418,0.14159374662049004,26.37270281609067,136.65095182059568,0.04363064397247148
0.04507031789482,130.632385045258,0.1430982593160535,26.335488825124013,136.5200281666063,0.04408417300441619
0.0455491605955427,130.463700176898,0.14461858489084806,26.301481955662634,136.40621220814424,0.04454225991504041
0.0460341141602873,130.262765054424,0.14615831245891217,26.26097343497188,136.25929605177404,0.04500597903087762
0.0465355346034106,130.188548393933,0.14775032236582866,26.24601135621689,136.24694209268665,0.0454852179924255
0.0470475123565166,130.081065231329,0.1493758517319402,26.22434275063593,136.20105575514881,0.04597431037789863
0.047554164593639,129.96685572011,0.15098447258480382,26.201318113174175,136.14732096874187,0.04645807991993514
0.0480616886064113,129.830480536801,0.15259586132535588,26.17382487621908,136.07035266398148,0.04694244734053841
0.0485746402388002,129.678234016861,0.15422448275819062,26.143131977799182,135.97730758103296,0.047431756464458484
0.049083558202383,129.548687013712,0.15584029729256602,26.11701530196434,135.90739753279183,0.0479169813442279
0.0495987255427405,129.415085828965,0.15747595359820107,26.090081303119348,135.83390915208605,0.048407924975567534
0.0501010126763559,129.304687063778,0.15907071524742997,26.067824912057645,135.7829828294726,0.04888636209117395
0.0506146760847433,129.150049587477,0.16070159656905997,26.03664999683537,135.6869375136757,0.04937539868129665
0.0511313209615687,128.966955888142,0.1623419440529806,25.99973830704943,135.56120670309505,0.0498670326731851
0.0516436005099314,128.764007735402,0.16396843161903218,25.958823959457046,135.41384471094682,0.05035427413042964
0.0521613772651775,128.557713719017,0.16561237281693855,25.917235085753823,135.2634611246633,0.05084650299305729
0.0526718953335658,128.365159655229,0.16723326768407143,25.87841618649417,135.1263959090657,0.05133159422099012
0.0531879447095154,128.282791319846,0.16887172445271137,25.861810730080958,135.10588933174827,0.051821702229573254
0.0537083632807333,128.174976065855,0.17052405341632823,25.840075174876365,135.05904424389922,0.05231571665242677
0.0542129678521468,128.008495380922,0.17212617293056606,25.806512668793875,134.9482158258096,0.052794486494165654
0.0547246433670691,127.802323537864,0.17375074269044438,25.764948425233385,134.7962601149564,0.05327973131339631
0.0552414254618895,127.622878989179,0.17539152584149917,25.728772404218486,134.6729487460915,0.05376958004868029
0.0557580921707578,127.447552590945,0.177031942642156,25.69342660233451,134.55378497524842,0.05425907965762785
0.05628113097133,127.326332769675,0.17869259083397274,25.668988686366482,134.49240278038423,0.054754372363874516
0.0568195375356109,127.210739491784,0.1804020316755646,25.645685081543654,134.43879487927023,0.05526396150362187
0.057347033438463,127.079701126035,0.18207683116712,25.619267747008656,134.3673449958596,0.05576297224481912
0.0578932089201263,126.972092496172,0.183810938321401,25.597573847228272,134.3229143740785,0.05627939159318836
0.0584227636852181,126.894785391907,0.18549227470056745,25.581988735008455,134.30832945174487,0.056779841226417924
0.0589639508877658,126.770821112334,0.1872105440686564,25.556997536246538,134.2457295824034,0.0572910253295462
0.0595047812245918,126.640860370344,0.18892768038807897,25.530797450661353,134.1765970607754,0.05780161143391258
0.0600395452492166,126.449728496591,0.1906255561662627,25.49226526491275,134.04171269241323,0.058306214266976575
0.0605876307028375,126.265446020825,0.19236572748150904,25.45511391779832,133.9155702348638,0.05882312310605959
0.0611433787103231,126.101340348222,0.19413022740527583,25.422030214201556,133.81160235701267,0.05934698594986928
0.0616869179149543,125.95383306006,0.1958559643799799,25.392292744908097,133.7235368211098,0.05985907513323298
0.0622291519154068,125.811063251584,0.19757755733141658,25.363510351519334,133.64017901930566,0.06036967347554527
0.0627712602441145,125.647529111167,0.19929875127506352,25.33054186881127,133.534582860034,0.060879892991142444
0.0633181150139533,125.504579783416,0.20103501516930172,25.301723284336667,133.45129320092022,0.06139431612712377
0.0638729721459944,125.373794787591,0.2027966865635322,25.275357029178345,133.3817916898964,0.061915996711415414
0.0644357668778684,125.26272279884,0.20458355983723214,25.252964916246146,133.3341224035931,0.06244486241090027
0.0649901235137063,125.116804534847,0.20634364215601747,25.223547794225155,133.24816111520695,0.06296552542233698
0.0655348678939633,124.906595347789,0.20807320556333347,25.18116962211426,133.09233257299107,0.06347689646405198
0.0660715945569209,124.662183200854,0.20977731271822384,25.131896133292166,132.8988124258814,0.06398048536167922
0.0666007749730439,124.436680148939,0.21145746053941436,25.086434718026105,132.72425948193114,0.06447674576674095
0.0671419501154083,124.266061339714,0.21317569161642133,25.052037966086342,132.60952703122334,0.06498400013026397
0.0676909215380066,124.201286278779,0.21491867588317093,25.038979313801846,132.60858580319533,0.06549829934495949
0.068255750804476,124.132750353851,0.2167120088042113,25.025162471336362,132.60552442867768,0.06602717891573634
0.068829155889857,124.043715959316,0.21853256995029596,25.007213137398107,132.58154022223692,0.06656380251674052
0.0693910070030885,123.860956436357,0.220316447234806,24.97036881756957,132.4557929318415,0.06708933411158104
0.0699491124189751,123.663742738299,0.22208843193024594,24.930610536041083,132.3139117812515,0.0676110888559349
0.0705036471173667,123.513728032266,0.22384907959763928,24.900367571304827,132.2218963276033,0.06812923597067756
0.0710741031817715,123.40028400974,0.2256602776021245,24.877497256363586,132.17084852810817,0.06866197971796108
0.0716462821933093,123.32363709348,0.22747694596375703,24.86204523804557,132.15931719778473,0.06919604755905069
0.0722334455682497,123.204115942254,0.2293411896791928,24.837949773958407,132.10357374495314,0.06974380532924462
0.0728204261122781,123.051918270619,0.23120485290648293,24.80726672335679,132.0126113930187,0.07029109280433236
0.0734061161011468,122.878184330654,0.2330644186211411,24.772241961059844,131.8981945959281,0.07083687862133528
0.0739815364201429,122.704581236868,0.23489137813395367,24.737243577352586,131.7824546825617,0.07137280452376184
0.0745580182061275,122.575702060842,0.23672170780445478,24.71126153546575,131.71470348672312,0.07190943118123
0.0751265744185072,122.416502068692,0.23852687377876036,24.67916681704831,131.61323452140894,0.0724383982935102
0.0756982579271435,122.234866880245,0.24034196891868062,24.642549163057392,131.48783336103583,0.07296999297616559
0.0762653891166876,122.00445185787,0.24214261044548313,24.596097494546594,131.3091688527786,0.0734970754884125
0.0768410734339336,121.781243852837,0.24397040815273915,24.55109876073194,131.1390453546086,0.07403182315739894
0.0774098453244344,121.607459540247,0.2457762589050792,24.516063843313795,131.02107417355492,0.07455986926267305
0.0779804497026029,121.427486368094,0.2475879278057642,24.47978125180775,130.89645636133466,0.07508933661048023
0.0785583795636677,121.277951980372,0.2494228551146449,24.449635119242995,130.80535136475032,0.07562531571464208
0.0791313335972426,121.114282981486,0.25124198417124527,24.41663944906758,130.6982177114848,0.07615639675335376
0.0797108919237045,120.958410456022,0.25308208185776176,24.385215547934035,130.60011323914503,0.07669331263681517
0.080293168550694,120.858323028515,0.2549308101484534,24.365037922548627,130.56242073019777,0.07723245666135578
0.0808708125651409,120.670613164296,0.25676482989432237,24.327195613922072,130.42934370362642,0.0777670241752049
0.0814327698508132,120.473499230317,0.2585490442763319,24.287457444831908,130.28398996626154,0.07828680067920193
0.0820042868982281,120.273362973874,0.2603636109018742,24.247109975533,130.13629433739828,0.07881514242959077
0.0825715157682224,120.1103473824,0.2621645625641061,24.21424603229184,130.02804082521249,0.0793392440870883
0.0831620568195526,120.022271889917,0.2640395304020795,24.196490013007264,130.00357088443806,0.07988459377685696
0.0837499883311146,119.930000068669,0.26590621295128886,24.17788801384367,129.9741361749706,0.08042723834547685
0.0843371708657983,119.769906352264,0.26777051749890957,24.14561312061642,129.87096140887556,0.08096889788766756
0.0849390564581731,119.631774977753,0.26968150425469956,24.117765835515005,129.7931850667798,0.08152381625190229
0.0855356793616606,119.482665647383,0.27157578197327237,24.087705394512415,129.70269662547406,0.08207357885329836
0.0861306934440718,119.343228877243,0.27346495168492796,24.05959494165219,129.6223439382945,0.08262155814215358
0.0867299710006314,119.193289598741,0.2753676579270047,24.02936718310619,129.53092014910968,0.08317316053577309
0.0873267869001455,119.000060436652,0.27726254840796194,23.990412184029047,129.39195335550795,0.08372219488120777
0.0879326116379193,118.807092266084,0.27918604195039376,23.951509800842533,129.254110170148,0.08427920868272937
0.088517157033307,118.588411822678,0.28104197358074967,23.907423823451886,129.08552089431646,0.08481636365672145
0.0891067321725381,118.388095170915,0.2829138746478085,23.86703998645646,128.93727145972667,0.08535784848939534
0.0897004188273452,118.181026274628,0.28479882977682097,23.825294896965005,128.78191382890762,0.08590281335168498
0.0902901817809954,117.999653672106,0.28667132715466037,23.78873018029657,128.65386385225494,0.08644388262773937
0.0908858527831668,117.818105212178,0.2885625825865546,23.752130010775087,128.52610417768366,0.08699007514731676
0.0914719197012951,117.644348512547,0.29042334505161194,23.71710066012948,128.4055029129979,0.08752717033822101
0.092066048803984,117.478160129007,0.2923097049526492,23.68359708200781,128.2939101528464,0.0880713597463472
0.0926540287389334,117.251928592568,0.29417654124611353,23.63798880426171,128.11579215407917,0.08860962545387627
0.0932428233357833,117.056914031915,0.296045964091112,23.598673868834062,127.97163118722483,0.0891483467668523
0.0938412839450409,116.892368163893,0.29794607652550487,23.56550142184083,127.86169807576914,0.08969561481402243
0.0944302537901264,116.769195987279,0.2998160557836513,23.540669911035447,127.79574079922678,0.0902339116836303
0.095026905346272,116.577244415129,0.3017104244744136,23.501972474090007,127.65521918569468,0.09077893405908564
0.0956329514053468,116.382763523967,0.3036346207119761,23.462765126431744,127.51279069247451,0.09133223408206122
0.0962296850324101,116.168661540442,0.30552924997790204,23.41960216655311,127.34753525111537,0.09187673320521451
0.0968121014948979,115.989116877259,0.3073784222463008,23.383405962455413,127.21826703268377,0.09240788266142506
0.0973754971163696,115.661052690204,0.30916720334447345,23.317268222345128,126.92360519291523,0.0929214172691402
0.0979489562004715,115.421932542334,0.310987935936497,23.26906160053454,126.72739035749684,0.09344385402902661
0.0985251527703065,115.219860242517,0.31281736004572314,23.228323824891426,126.57191457508436,0.09396850995890904
0.0991223692216733,115.10802173134,0.3147135222788127,23.205777181038144,126.51780156177028,0.09451201519356728
0.0997156331209735,114.979795419577,0.3165971351590908,23.179926756586724,126.44507851596012,0.09505163103890356
0.100296453288499,114.728555600589,0.31844123919098427,23.129276809078743,126.23542281824042,0.09557964648446214
0.100852971864859,114.486992494288,0.3202081856709273,23.08057768684846,126.03334592720675,0.09608530828266515
0.101425357257453,114.202099188778,0.32202550929241325,23.023143196457646,125.78508789855091,0.09660512033177214
0.101990505821718,113.967609117398,0.32381985598395463,22.975869998067438,125.59122321857328,0.09711809528682053
0.102577070952097,113.773238047319,0.32568220027290795,22.93668479033951,125.44376355894866,0.09765023152106445
0.103167543706568,113.616334871664,0.3275569512683534,22.90505311012746,125.33785306531645,0.0981856269287211
0.103758008331466,113.468371251321,0.32943167645240456,22.875223644266317,125.24162346097344,0.09872072847615831
0.104346315776073,113.270444031599,0.33129955258903176,22.83532151677036,125.08979755261622,0.09925359049006259
0.104930215219397,113.043768672911,0.3331534333215854,22.789623764458856,124.90547564897128,0.099782179327836
0.105511889095371,112.775676030783,0.3350002478778029,22.735576287805852,124.67485065279847,0.10030847575357367
0.106081187771131,112.523587306035,0.33680777117334093,22.684755200896657,124.46022309972774,0.10082330707068106
0.106669204559896,112.24279455998,0.3386747244776698,22.628147383291967,124.21564417327289,0.10135478753467242
0.107232861168755,112.012312800447,0.3404643342107971,22.581682260570116,124.02371358816849,0.10186398496464297
0.107800659448852,111.68550969863,0.3422670937501051,22.51579875524381,123.72528129502348,0.1023766618945843
0.108346457774864,111.370522017277,0.34400000343519316,22.45229723868304,123.43712357838646,0.10286922697097768
0.108913841924348,111.110116009967,0.3458014481098049,22.399799387609345,123.21154562127252,0.10338101547135845
0.109492022845161,110.863207220523,0.34763717253338616,22.350022575657437,123.00184403820032,0.10390227350000551
0.110072607304507,110.744606390298,0.34948052819180975,22.32611264828408,122.93455396058948,0.10442542517101451
0.110651062589758,110.503194279226,0.35131712372248164,22.277443966691962,122.73049014578483,0.1049463862488611
0.111207329496826,110.214839507087,0.35308327115242255,22.219311644628743,122.47153747959143,0.10544710845570525
0.111768031953718,109.892166890445,0.3548635014530546,22.154260845113715,122.17459811091956,0.1059515697093079
0.112309523561129,109.587274023328,0.3565827373065846,22.092794443102925,121.89496855725085,0.10643850562282178
0.112850908127829,109.203311605779,0.35830163330585707,22.015387619725047,121.52700449105747,0.10692510835912135
0.113397600001409,108.906125872948,0.36003738000447355,21.955474975986316,121.25581917239165,0.10741624120666525
0.113952366439189,108.618494364101,0.3617987634444251,21.897488463802762,120.99582883595203,0.10791438155965023
0.114503073636389,108.37947569736,0.363547258795535,21.849302300587773,120.78925878380804,0.10840863170125682
0.11505482955136,108.103183600809,0.36529908382556797,21.793601813923097,120.54097696395947,0.1089035781885814
0.115593307739823,107.761079520645,0.367008752073938,21.724633631362032,120.21753914805045,0.10938637795419269
0.11614938121344,107.402923375632,0.368774285352672,21.65242935252741,119.87770646622617,0.10988470913536075
0.116687971739888,107.049486646244,0.37048431027414436,21.58117650788279,119.54087411879046,0.11036713615690937
0.117214812338847,106.74451209663,0.3721570291758392,21.51969363868061,119.25655005023827,0.11083881344965582
0.117745524488911,106.374351515544,0.3738420402522924,21.44506926553367,118.89945532690952,0.11131373208807095
0.118276303770381,106.058739441411,0.37552726447095963,21.38144187138846,118.60297512508701,0.11178848531698064
0.118809681932519,105.734684109351,0.3772207401357478,21.31611231644516,118.29698829761837,0.1122653361628166
0.119341910083137,105.334150569903,0.37891056451396,21.235364754892444,117.90492929589998,0.11274093233114471
0.119857245598118,105.00331517011,0.3805467547740246,21.16866833829418,117.58872330507046,0.11320121789598321
0.120367206266305,104.559848139967,0.38216587989551837,21.079265385017347,117.14542494820394,0.113656494309533
0.120881975687352,104.198633544367,0.3838002728073426,21.00644452254439,116.79437023113248,0.11411585370093286
0.121410326589333,103.822056454494,0.38547778692113227,20.93052658122599,116.42712623581028,0.11458711332326015
0.121930103880616,103.444995384438,0.38712807982095576,20.854511069502703,116.05805441759237,0.11505050915344664
0.122459026136267,103.030535452357,0.3888074079826477,20.770955947195173,115.64755448615077,0.11552183763955347
0.122955513380582,102.575088988484,0.3903837549833478,20.679137940078377,115.18726171512193,0.11596406088489945
0.123464637417721,102.095388937871,0.39200022380126415,20.582430409874792,114.70055911510644,0.11641733677425184
0.123967065715314,101.679777724113,0.39359543364612193,20.49864318918118,114.28472141115664,0.11686445007719455
0.124461994866306,101.239343791795,0.3951668337005215,20.409851708425872,113.83979447907757,0.11730469448397839
0.124966097384386,100.853242210927,0.3967673591954255,20.332013629722884,113.45647829858876,0.11775289954397185
0.125483932620073,100.435683284867,0.3984114860687318,20.247833750229187,113.03874779883624,0.11821310549204637
0.126001130175732,100.002641092879,0.40005358830794907,20.16053244432441,112.60308689113985,0.11867253342546029
0.126511831744401,99.5179799256451,0.4016750657884732,20.06282475301005,112.10818185754097,0.11912598393700306
0.126999799430428,98.9948158510897,0.40322436319160887,19.957354875579682,111.56713760883024,0.11955905708994634
0.127487227686593,98.417876923018,0.4047719479049328,19.84104398768043,110.96489920673389,0.11999146433638164
0.12797118085869,97.8692593244701,0.4063084992263407,19.73044267981317,110.3937040099879,0.12042060386534885
0.128449514397347,97.3429226155376,0.4078272082115767,19.62433319929238,109.84657375552193,0.1208445793649778
0.128940619463328,96.8653165768513,0.40938646679606633,19.52804782189322,109.35519050078189,0.12127968809196522
0.129417502877182,96.2591229626953,0.41090057163505284,19.405839189279373,108.71673828567494,0.12170201563711812
0.129895809735364,95.6963501133477,0.41241919590978066,19.292384182850896,108.1269050000399,0.12212542469920573
0.130371189977732,95.1191731111091,0.4139285281792991,19.176025299199598,107.51997289930229,0.12254606549026077
0.130822616761423,94.5666930272736,0.41536180821751806,19.06464531429836,106.93815526757575,0.12294534731063642
0.131260092159756,93.9541617834815,0.4167507926072253,18.94115901554987,106.2865937179739,0.12333213723839788
0.13167883279618,93.2916250828495,0.4180802941278715,18.807591616702464,105.57615738341795,0.12370222291467083
0.132115967290771,92.6407645639844,0.41946819614819786,18.676378136099256,104.88008878491179,0.1240884191370558
0.132558139823982,91.9731890414818,0.4208720939411429,18.541794910762732,104.16498389450008,0.1244789146502431
0.133025225219776,91.3457531774376,0.42235509007278876,18.415303840571422,103.49704256673631,0.12489124589315252
0.133479195609408,90.7023061073133,0.4237964460598703,18.285584911234363,102.80917696643577,0.12529183668091418
0.133918321918746,90.034346526396,0.42519067209201855,18.150924259721435,102.09159512826184,0.12567917618484656
0.134356775098221,89.3437599127047,0.42658276093685166,18.011701998401268,101.34769936972542,0.1260657723129021
0.134770654937206,88.6276337648587,0.427896829425629,17.867330966995514,100.57203801288355,0.12643056438063383
0.135184360827238,87.8905554258405,0.42921034562648064,17.718735973849444,99.77198398383369,0.12679507018955025
0.135595496127771,87.1152628365436,0.43051570020567287,17.56243698784719,98.9277001211659,0.12715717953605177
0.136002898780152,86.3956934963807,0.4318092036269826,17.41737180887035,98.14575825401,0.1275158720387955
0.13638925592052,85.5857737483811,0.433035887547651,17.25409198767363,97.25875374730477,0.12785591646580305
0.136773336799903,84.8036034473025,0.434255344339692,17.096406454976186,96.40247526344582,0.12819384291617478
0.137132781020902,83.9906118627388,0.43539657974136386,16.932507351528145,95.50847804712333,0.12850998985045314
0.137482651585728,83.0975808751209,0.4365074187846864,16.752472304424373,94.522056634192,0.12881762037345915
0.137828981394009,82.2338508112769,0.43760701592597856,16.578344323553424,93.5680587047021,0.12912204444085792
0.138208047761214,81.3687600908444,0.43881055164185445,16.403942034314234,92.61457757175059,0.12945513776566248
0.138575904636898,80.4627250815413,0.43997849722215115,16.221285376438725,91.6129199992659,0.12977827503874226
0.138970562779523,79.5775510495369,0.4412315368249855,16.042834291586637,90.63648810350726,0.1301248393369652
0.139336650710309,78.7355047801115,0.44239386600523106,15.873077763670478,89.70624630815776,0.13044620770359214
0.13965325148691,77.6742558739877,0.4433990734709392,15.659129984195923,88.52171826361631,0.13072405077637836
0.139939169371878,76.7007481262835,0.44430686275571263,15.462870822258754,87.43418710927723,0.13097490078259086
0.140200745180798,75.6798071319464,0.44513736594903364,15.257049117800396,86.29017248698436,0.13120433916783922
0.140454839981959,74.6746665671051,0.44594411694271985,15.05441277992839,85.16308491049399,0.13142716527438972
0.140706684761922,73.7795700916074,0.4467437241191023,14.87396133046805,84.16084880235734,0.13164796926240596
0.14096087553135,72.6157095025088,0.4475507798120362,14.639327035705776,82.85168349131263,0.13187078066131713
0.141234029075802,71.365657322064,0.4484180423156713,14.3873165161281,81.44491664330211,0.13211015859105044
0.141526668708043,69.8036439176653,0.4493471731480365,14.072414613801325,79.68272110501492,0.13236654957774308
0.141737218875364,68.5231231351147,0.45001566992928066,13.814261624039124,78.23540003693998,0.13255097869175209
0.141887722210766,67.5616653661771,0.4504935180191821,13.620431737821303,77.14783617374995,0.1326827895972226