File: example/data/02 processed data/test_ID_142.csv
Strain,Stress_MPa,Displacement(mm),Force(kN),True Stress (MPa),True Strain
0.0004321148357360998,-0.345641443185096,0.0001168175400996,-0.0696813149461153,-0.345654160345143,3.6792249172560334e-05
0.0004321987156132998,-0.163959554378287,0.0001170838587097,-0.0330542461626626,-0.1639656006829481,3.687612596023631e-05
0.0004109659912343998,0.182918931311366,4.966995880677156e-05,0.0368764565523713,0.1829217929100378,1.5643959146632105e-05
0.0003786673172602998,0.593274030758819,-5.287833106106832e-05,0.1196040446009779,0.5932641500216196,-1.665473114940622e-05
0.0003522675578365998,1.32881517200939,-0.0001366975672312,0.267889138677093,1.3287579607333857,-4.305527874910961e-05
0.0003061935444667998,2.25726046013391,-0.0002829825596804,0.4550637087629963,2.257059274199147,-8.913233742242461e-05
0.0002675954453895998,3.43702443762852,-0.0004055315242502,0.6929041266259097,3.436585438649284,-0.0001277346220502
0.00023799811325939978,4.83482986813248,-0.0004995030537636,0.974701701415508,4.834069234342381,-0.0001573361731476
0.0002157118550301998,6.3042413607234,-0.0005702619236413,1.2709350583218375,6.30310905558782,-0.0001796261865077
0.00020922739175219978,7.79617180003939,-0.000590850094549,1.571708234887941,7.794720975206263,-0.0001861118357015
0.00023206178086289977,9.37621225235857,-0.0005183509091225,1.890244390075488,9.374681490738055,-0.0001632734572429
0.00025185006934839977,10.9325655818103,-0.0004555230931811,2.2040052212929564,10.93099706650629,-0.000143482133441
0.0002945617797919998,12.5854795537151,-0.0003199134125226,2.537232678028964,12.584211439160056,-0.0001007652065713
0.0003290138995390998,14.2572567703295,-0.0002105279323256,2.874262964898428,14.256311400002415,-6.631020865455154e-05
0.0003727701720586998,16.0352663769323,-7.160176707614038e-05,3.232709701589552,16.03490475381163,-2.255199195600576e-05
0.0004066913175687998,17.8351258840623,3.6097869918516965e-05,3.59556137822696,17.835328658882503,1.1369343217066456e-05
0.0004630669478606998,19.6933460637402,0.0002150904960952,3.970178566450024,19.6946801902204,6.774274354886673e-05
0.0004987789963975998,21.5288840590355,0.0003284762502001,4.340223026301557,21.53111137465966,0.0001034517353618
0.0005434155357103998,23.3722454282488,0.0004701972625182,4.711844678334958,23.3757067088218,0.0001480826612116
0.0005790206119963998,25.1880225390634,0.0005832433797263,5.077905343875182,25.192649546116726,0.0001836818317355
0.0006109095882316998,26.9826427715548,0.0006844908792733,5.439700782745448,26.98845989687002,0.0002155644428271
0.0006478112800939997,28.756190315583,0.0008016537509361,5.797247967621534,28.763450947970128,0.000252457500297
0.0006853069412008998,30.4876057790233,0.0009207024749505,6.146301325051097,30.4964467283449,0.0002899429939479
0.0007161042313960998,32.1989015698267,0.0010184838713203,6.491298556477063,32.20923040822768,0.0003207308820271
0.0007569866443735998,33.900288393636,0.0011482855325239,6.834298140157018,33.912548932442554,0.0003615993497274
0.0008017323736209998,35.5812502919103,0.0012903532228844,7.173180058849117,35.5957108843476,0.0004063279015366
0.0008391263498042998,37.2352675708641,0.0014090790972663,7.506629942286203,37.25179274793976,0.0004437059880212
0.0008896347664770998,38.8722909577312,0.0015694433202025,7.83665385707861,38.8915060309232,0.0004941907244026
0.0009189921826794998,40.4537044928105,0.0016626531166451,8.155466825750597,40.47488889528447,0.0005235332055318
0.0009617935029892998,42.0380826702043,0.0017985473086287,8.474877466313187,42.06189604987246,0.0005663112088019
0.0010050514205232999,43.573839819106,0.0019358911967992,8.78448610753177,43.60040807514271,0.0006095437012899
0.0010433864294911999,45.0788476942109,0.0020576048502722,9.087895695152918,45.10806169599367,0.0006478546166422
0.0010697643992457998,46.5470685407601,0.0021413549042431,9.383889017817236,46.57846186154684,0.0006742151553995
0.0011055867536053999,47.9793497036788,0.0022550908793348,9.672636900261644,48.013427749005785,0.0007100127251844
0.0011381714123319998,49.3934021189039,0.0023585471707918,9.957709867171028,49.43009398310022,0.0007425737264848
0.0012019241660286997,50.7579660640718,0.0025609621637788,10.232805958516876,50.7989075540247,0.0008062771275296
0.0012385428342965997,52.1079432260402,0.0026772264355294,10.504961354369703,52.15188173410502,0.0008428656135354
0.0012506330000755998,53.3991634876145,0.0027156127118777,10.765271359103084,53.44483638436115,0.0008549455202605
0.0012847584552164997,54.6859218539595,0.0028239610319501,11.024681845758234,54.73456151138056,0.0008890412311991
0.0013317520477998997,55.9234168447842,0.0029731656884024,11.274160835908496,55.97578521774204,0.0009359919609045
0.0013733895880945997,57.1398201610695,0.003105364878838,11.519387744471612,57.19570677231715,0.0009775896818323
0.0014125664467307998,58.3058876167328,0.003229751405008,11.754466943533332,58.36519896238647,0.0010167274943959
0.0014352806539501997,59.4698415783074,0.0033018690129296,11.989120062186773,59.531687760074725,0.0010394183617528
0.0014718257059899997,60.6093509669,0.0034178995531559,12.218845154927042,60.674597163305314,0.0010759247815617
0.0015287658678390997,61.7681774556576,0.0035986845670268,12.452464575060572,61.83818822319872,0.0011328020954801
0.0015719176820309998,62.8997545133794,0.0037356915770861,12.680590509897288,62.97376209861922,0.0011759041259772
0.0016122338835541999,64.0606602360946,0.0038636955169223,12.914629103596672,64.13861642058761,0.0012161721366082
0.0016825263927044997,65.2071993258566,0.0040868742334745,13.145771384092694,65.29113432515169,0.001286376745529
0.0017235784359170999,66.3601577783367,0.0042172144706745,13.37820780811268,66.44830109098523,0.001327375173852
0.0017558012090085997,67.5063160360129,0.00431952177524,13.609273312860203,67.59815698155111,0.001359554685843
0.0018104833750513998,68.6468611089715,0.0044931376524259,13.839207199568657,68.74400750152886,0.0014141610680491
0.0018529643587426997,69.7696329631443,0.0046280147756458,14.065558005369892,69.87133214180409,0.0014565811195017
0.0019008073639974997,70.8767224401619,0.0047799163173297,14.28874724393664,70.9834263148424,0.0015043533471553
0.0019483742344276998,71.9673859795632,0.0049309411309456,14.50862501347994,72.07915509566187,0.0015518475861324
0.0019665601036199,73.0374845711181,0.0049886812656309,14.72435688953741,73.15224385646259,0.0015700050906654
0.0020311940016043,74.144747128735,0.0051938938917313,14.947581021152978,74.26603845132269,0.0016345355105855
0.0021056332747575995,75.1836789353774,0.0054302385839931,15.157029673372085,75.31226643592588,0.0017088504480659
0.0021661642460911994,76.1860168450634,0.0056224244179772,15.359100995964782,76.32093026913209,0.0017692762436768
0.0022359839560884,77.1761738785943,0.0058441019972184,15.55871665392461,77.31822913273652,0.0018389701038616
0.0023169983956171994,78.1356540683832,0.0061013228427223,15.752147860186051,78.28580551751658,0.001919832427716
0.0024046865921801995,79.0554823098411,0.0063797328668098,15.937585233663963,79.21433360394931,0.0020073486094783
0.0025124387904966,79.9350100793797,0.0067218460964644,16.114898032002944,80.10424183858376,0.002114878946921
0.0026020388134275997,80.7011046244512,0.0070063261692703,16.269342692289364,80.87918911617382,0.0022042856799853
0.0026950399841585,81.4488875859442,0.0073016048863409,16.420095737326353,81.63619706486848,0.0022970777700229
0.0028039774604867998,82.1454145619314,0.0076474813736833,16.560515575685372,82.34327457068599,0.0024057593896226
0.0029373120695487,82.7432082676608,0.0080708187574548,16.68103078676042,82.95354068886982,0.0025387647676291
0.0030685314085265,83.2810844426019,0.0084874401587093,16.78946662362854,83.50371222860473,0.0026696428291832
0.0031898664654693995,83.757347255914,0.008872678964503,16.885481206792264,83.99141089469198,0.0027906470755448
0.0033117228413743994,84.160634545121,0.0092595729580014,16.966783924296394,84.40608069811698,0.0029121564847936
0.0034584023869589997,84.4867545101821,0.0097252805152325,17.03252970925271,84.74554423850749,0.0030583988040252
0.0036335038491452,84.7392653669141,0.0102812276576737,17.08343589796988,85.01366652558535,0.0032329503192046
0.0037856138199358997,84.9391001009464,0.0107641768149342,17.123722580350798,85.22706844487963,0.0033845578270861
0.0039320329457616,85.1213998549361,0.0112290575394308,17.16047421075512,85.42244964920633,0.003530471580671
0.0040951023626967,85.2774472511495,0.0117468029381997,17.19193336583174,85.59295508356902,0.0036929530998994
0.0042688401076362,85.3940521239706,0.0122984202783826,17.215440908192473,85.72482753886656,0.0038660354431342
0.0044471192958611,85.4890697826235,0.0128644567009967,17.2345964681769,85.83545417211234,0.0040436109608189
0.0046230705613016,85.5782663377271,0.0134231019687703,17.252578493685782,85.94006973784109,0.0042188368313784
0.0047813899087335,85.6641570944614,0.0139257658968665,17.26989407024342,86.03988591255585,0.0043764772363655
0.0049722402432936,85.7420044791634,0.0145317157090949,17.28558810299934,86.13443863142139,0.0045664760929224
0.0051607520800457,85.812648945178,0.0151302407907828,17.299830027347884,86.22158313145688,0.004754111452766
0.0053406009336642,85.8610065114378,0.0157012609010215,17.30957891270586,86.2856131459135,0.0049330912962587
0.0055282676842362,85.904730760108,0.0162971028340876,17.318393721237772,86.345675084874,0.0051198171149875
0.005712788383302,85.9339047524766,0.0168829560536215,17.324275198099283,86.39085540994184,0.0053033786676225
0.0059115298840464,85.9664581903256,0.017513960318485,17.33083797116964,86.44066705251964,0.0055010494187315
0.0061097209448011,85.9900517672139,0.0181432169363812,17.335594436270323,86.481433236059,0.0056981337915582
0.0062876976011149,85.9817392127854,0.0187082928201775,17.333918625297535,86.48837592282663,0.0058750835403999
0.0064670563778941,85.977795296658,0.0192777569364514,17.33312353180625,86.4998296398583,0.006053375763754
0.0066512269009438,85.9787151172776,0.0198624983471342,17.333308967643166,86.51658979031876,0.0062364180476768
0.0068275104759712,85.9704639785456,0.0204221986978462,17.331645538074792,86.52344221398367,0.006411590322052
0.007008039497774,85.9849833064074,0.0209953783420701,17.33457263457173,86.55357771782619,0.0065909494826301
0.0071844762269282,85.9974754598888,0.0215555649571347,17.337091052713586,86.58132559167629,0.0067662117907343
0.0073715057694168,85.9913930239555,0.022149383754536,17.33586483362943,86.59128479204203,0.0069519628705455
0.0075596429086651,86.0086013156982,0.0227467191716494,17.339334025244757,86.62479454419412,0.0071387791719322
0.0077584658150297,86.0178561758589,0.023377981899357,17.341199805053154,86.65121802930794,0.0073361682971478
0.0079368204892519,86.001713142947,0.0239442579900125,17.337945369618115,86.6502949404518,0.0075132036475335
0.0081316797108247,85.9572222249618,0.0245629360185061,17.3289760005523,86.62221805168313,0.0077065856385707
0.0083235247724015,85.9329585673779,0.0251720440890124,17.324084447183385,86.61425249549043,0.0078969397936221
0.008512416864523,85.9103881696037,0.0257717764814982,17.319534254992107,86.60773094798033,0.008084328532237
0.0087005735538311,85.9034248436346,0.0263691739700514,17.318130448476733,86.61687440405193,0.008270952817741
0.0089248515699228,85.8910567233891,0.0270812566711426,17.315637035435245,86.62366703925737,0.0084933587570824
0.0091129741088185,85.8795456388786,0.0276785457321364,17.313316400797927,86.62821364877492,0.0086798728750675
0.0093145290939539,85.8844316781799,0.0283184828099413,17.314301426321066,86.65045271821772,0.0088796659992547
0.0095140359903047,85.9047606388367,0.0289519172058551,17.31839974478948,86.6881015892633,0.0090773896345726
0.0097165310147982,85.9027482516886,0.029594838908622,17.317994047540424,86.70346573084346,0.0092780347197661
0.0099196706579483,85.8948308601822,0.0302398072756235,17.31639790141273,86.71292318496462,0.0094792780917967