File: example/data/02 processed data/test_ID_071.csv
Strain,Stress_MPa,Displacement(mm),Force(kN),True Stress (MPa),True Strain
0.0009939696897874406,38.8097050938778,0.003155853765075124,15.648073093851531,38.8482807644107,0.0009934760290107537
0.0010814473492045406,42.3001849541954,0.0034335953337244164,17.055434573531585,42.345930377084976,0.0010808630062727035
0.0011587048963872407,45.7667478283025,0.0036788880460294888,18.45315272437157,45.819777983102874,0.0011580341159764926
0.0012477267303098406,49.1446917610426,0.0039615323687337434,19.815139718052375,49.2060109066057,0.0012469489662039824
0.0013358769292390407,52.4475938875644,0.004241409250333954,21.146869855465965,52.5176574182329,0.0013349854395127685
0.0014128801269129407,55.6188661141992,0.004485894402948587,22.425526817245117,55.69744890481338,0.001411882950935937
0.0015015063195253408,58.7359383034685,0.004767282564492957,23.6823303239585,58.82413068601441,0.001500380186035036
0.0015712117270438408,61.7996303757112,0.004988597233364194,24.91761096748676,61.896730679684495,0.0015699786653299963
0.0016413702967894407,64.6610177544291,0.005211350692306474,26.071322358585814,64.76715042833139,0.0016400247207550035
0.0017158111274707406,67.4338141073557,0.005447700329719601,27.189313848085817,67.5495177959689,0.0017143408051813838
0.0017981779912798407,70.2101465114052,0.005709215122313494,28.308731073398576,70.33639685162655,0.0017965632047283711
0.0018760263510818407,72.8998429183043,0.005956383664684844,29.393216664660294,73.03660494460875,0.0018742688114306038
0.0019497717916647406,75.5950375050632,0.006190525438535551,30.479919122041483,75.74243057678042,0.0019478734537948987
0.0020232302987452408,78.2376190353891,0.006423756198516139,31.545407995068885,78.3959117567232,0.0020211863248134104
0.0020835287411649405,80.8169243692667,0.006615203753198686,32.58538390568834,80.98530875396261,0.0020813612053838413
0.002164426600011541,83.3636119558791,0.006872054455036642,33.61220834061045,83.54404637506944,0.002162087603208053
0.0022410568516773406,85.8993480822777,0.007115355504075556,34.63461714677437,86.0918534048521,0.0022385494292564267
0.0023140157232801406,88.424096168893,0.007346999921414446,35.65259557529766,88.62871091774466,0.002311342512004065
0.0023854932558833404,90.9293897891169,0.007573941087429605,36.66272996297194,91.14630123522042,0.0023826524837113534
0.0024793554392353407,93.4344735655337,0.007871953519572206,37.67277974162319,93.66613083578048,0.0024762869084773054
0.0025745614095270407,95.8477487059067,0.008174232475248355,38.64581227822158,96.09451462091496,0.002571252903718819
0.0026575720653420403,98.3123910860856,0.008437791307460977,39.63955608590971,98.57366335031297,0.0026540469647921812
0.002734487376527841,100.645529053537,0.008681997420475894,40.58027731438612,100.92074298223787,0.0027307554676121444
0.0028200304470106406,102.988484107932,0.008953596669258783,41.52495679231818,103.27891476880785,0.0028160616208725677
0.0029061790323365406,105.234917032146,0.009227118427668516,42.430718547361266,105.54074854149451,0.002901964258003874
0.0029881858828220403,107.463783959118,0.009487490177959978,43.32939769231638,107.78490572125928,0.0029837301295926157
0.0030779618055206404,109.69977234495,0.009772528732528032,44.23094820948384,110.03742405430206,0.0030732345787474235
0.0031555686842154405,111.918347823498,0.010018930572384023,45.12547784243439,112.27151385707897,0.0031506003266070187
0.0032611102241443405,114.173546379246,0.01035402496165828,46.034773900111986,114.5458788986702,0.003255804336457742
0.003362815586063041,116.342217315962,0.010676939485750154,46.90918202179588,116.73345473766925,0.003357173966010609
0.003476780308409441,118.424008741001,0.011038777479199974,47.7485603243716,118.83574300263463,0.003470750280432684
0.0036053182270596408,120.396991695037,0.011446885370914359,48.54406705143892,120.83106116367827,0.003598834646208968
0.003733427414391641,122.207395336817,0.011853632040693458,49.274021799804615,122.66364777680887,0.0037264754719381244
0.0038847637036045404,123.963093458185,0.012334124758944414,49.98191928234019,124.4446607842379,0.0038772374944871465
0.004056464166708241,125.510940569393,0.012879273729298665,50.60601123757926,126.02007120234259,0.004048258898041144
0.00424365942409244,126.810122550441,0.013473618671493498,51.12984141233781,127.34826152207249,0.004234680494820843
0.004457182522420741,127.895181305893,0.01415155450868585,51.56733710253606,128.46523347271145,0.0044472787022528165
0.0047012577560949405,128.742175343259,0.014926493375601434,51.908845098402026,129.34742549362804,0.004690241357643142
0.00497010985888524,129.429212521675,0.015780098801960636,52.18585848873936,130.07248992685672,0.004957799634808824
0.005264237255552141,129.947719897453,0.016713953286378046,52.39492066265305,130.63179552581124,0.005250429595278966
0.0055691575440564405,130.299817975261,0.0176820752023792,52.53688660762523,131.0254781895271,0.005553707123521611
0.00588198316512564,130.522304316377,0.018675296549273905,52.62659310036321,131.2900343130393,0.005864751838712644
0.006219257711500141,130.664513249855,0.019746143234012945,52.68393174234153,131.47714953150356,0.006199997941325719
0.00656468914946134,130.647911598915,0.020842888049539755,52.67723795668252,131.50557452658816,0.006543235417847948
0.0069211240683799405,130.606299265477,0.02197456891710631,52.66045986384032,131.5102416668053,0.0068972830305026375
0.00729387035100364,130.559957611254,0.023158038364436556,52.641774908857606,131.51224501510302,0.007267398721142959
0.00766690825092844,130.542832445525,0.024342433696697797,52.634870042035686,131.54369236470114,0.007637666875390063
0.008045439295459141,130.481870520682,0.025544269763082772,52.610290193938994,131.53165448911412,0.008013247299294497
0.00844370042986354,130.391286010003,0.02680874886481674,52.57376651923322,131.49227096773615,0.008408251796702336
0.008845230744312241,130.275903632038,0.028083607613191362,52.527244344437726,131.42822406008716,0.008806340849337613
0.00924778201214964,130.169879712347,0.029361707888575107,52.48449550001832,131.37366238447456,0.00920528308899837
0.009655956912936041,130.022599590025,0.030657663198571928,52.425112154698084,131.27809220937422,0.009609636103436804
0.010067912039816041,129.828361731582,0.03196562072641593,52.34679545017386,131.13546225776898,0.01001756823606671
0.01046081332685914,129.652420273208,0.03321308231277777,52.27585585415747,131.00869003906152,0.010406477621083324
0.01086535333157904,129.463708697867,0.03449749682776345,52.19976734697997,130.87037763648593,0.010806749498817799
0.01126971303422594,129.31751437415,0.03578133888366736,52.140821795657274,130.77488565144606,0.011206682930330104
0.01168244142421994,129.157930254601,0.03709175152189831,52.07647747865513,130.66681020927388,0.011614728562858981
0.01209694677793794,128.981250292407,0.03840780601995296,52.0052401178985,130.54152961254613,0.012024363488415091
0.012514958307348641,128.851597722344,0.03973499262583193,51.9529642016491,130.4641700956744,0.012437293526315682
0.01293705051176864,128.710698694025,0.04107513537486543,51.896153713430884,130.37583550443466,0.012854081688851639
0.013359894180811441,128.566253996611,0.042417664024076325,51.837913611433564,130.28388554522908,0.013271437769151817
0.01378107700322344,128.360634105611,0.04375491948523442,51.755007671382366,130.129581888403,0.013686981467848384
0.01420474780096324,128.128615150561,0.04510007426805829,51.661457628706195,129.9486498148614,0.014104805693956444
0.01462122079620274,127.910794886202,0.0464223760279437,51.57363249811665,129.78100686045096,0.014515361362639333
0.015031639441898441,127.712904169109,0.04772545522802755,51.49384296098475,129.63263849665677,0.014919783871857448
0.01543685866681284,127.555432672183,0.04901202626713077,51.43035045342419,129.52448785852764,0.015318922524509834
0.01585773198029764,127.443225882536,0.05034829903744501,51.385108675838524,129.4641864012858,0.015733311773066354
0.01628183583637054,127.314267432873,0.05169482878047646,51.333112628934394,129.3871774348428,0.01615070816546647
0.01670302210707994,127.174336160152,0.053032095189978805,51.276692339773284,129.29853190848823,0.016565060761443432
0.01713555400912784,127.041835153551,0.05440538397898089,51.223267933911764,129.2187673812434,0.016990396295588624
0.01757026835928854,126.853771313401,0.05578560204074111,51.14744059356328,129.08262611776524,0.017417695762662413
0.01802492413426274,126.690478816831,0.0572291341262842,51.08160105894626,128.9740650860378,0.017864401261094762
0.01845440727687294,126.474136279504,0.05859274310407158,50.99437174789601,128.8081415003967,0.018286191104333563
0.01889002035063654,126.305661072539,0.05997581461327101,50.92644254444773,128.69157758059987,0.01871381941744037
0.01932039958248214,126.115897838483,0.06134226867438079,50.84993000847634,128.552507378426,0.01913613031726998
0.01975368802447694,125.936921464397,0.06271795947771427,50.77776673444487,128.42464012176774,0.019561115805683097
0.02018580551422264,125.785188580979,0.06408993250765688,50.71658803585073,128.32426393424444,0.019984772975493885
0.02061627751573824,125.646867184654,0.06545668111246891,50.66081684885249,128.23723786751592,0.020406638487568178
0.02106054275018914,125.504887815734,0.06686722323185051,50.60357076730395,128.14808887093494,0.020841834927134876
0.021493349525402442,125.286966554855,0.06824138474315275,50.515704914917535,127.9798031179959,0.021265624755474433
0.02193310680201284,125.097920086439,0.06963761409639076,50.43948137885221,127.84170612840452,0.021696036412363378
0.02236290696295404,124.93687994676,0.07100222960737908,50.37454999453364,127.73083176925115,0.022116523625937176
0.02279891506386184,124.81466447705,0.07238655532776134,50.32527271714656,127.66030341118669,0.022542903683316937
0.02323555285466704,124.711571552062,0.07377288031356785,50.2837056497914,127.60931386444852,0.022969717409361236
0.02367339086218764,124.549362649001,0.07516301598744575,50.2183030200772,127.49786839262714,0.023397521504450187
0.02412154588020144,124.386349980664,0.07658590816963957,50.15257631220372,127.38674102859339,0.023835216722001208
0.024566177696124642,124.225968742406,0.07799761418519574,50.0879105969381,127.27772596500516,0.024269281726430506
0.02499104589844544,124.096511159121,0.07934657072756426,50.03571329935759,127.19781276533554,0.024683876843381292
0.02543936714387354,123.947567174651,0.08076999068179848,49.975659084819284,127.10071484259687,0.025121171617903382
0.02588269102010644,123.781357977404,0.08217754398883795,49.90864353648929,126.98515261998233,0.025553403973978858
0.026318230326137542,123.574816106094,0.08356038128548669,49.825365853977104,126.82708657888428,0.025977864666925594
0.02675256927937704,123.415918052872,0.0849394074620221,49.76129815891799,126.71761095075938,0.02640097619313571
0.02718095013712344,123.19767012502,0.08629951668536692,49.67330059440807,126.54629985369795,0.026818108354335863
0.02760879471474434,123.072479793274,0.08765792321931327,49.62282385264808,126.47036262292102,0.027234544717108143
0.02803838900831754,122.933539672062,0.08902188510140818,49.5668031957754,126.38039807955671,0.027652509729031237
0.02847356755660204,122.867481739318,0.09040357699221148,49.54016863729302,126.36595728113204,0.028075729787043497
0.02891003034726494,122.776874114229,0.09178934635256618,49.503635642857134,126.32635727081369,0.02850001896447758
0.02936485256888514,122.65807031885,0.09323340690621032,49.45573395256032,126.25990647014697,0.028941964044600917
0.029820806251352642,122.52444211727,0.09468105984804463,49.401855061683264,126.17821976670419,0.02938481259297355
0.03027794299184324,122.367526226315,0.09613246899910229,49.33858657445021,126.07256320944823,0.029828613404135108
0.03075018374655834,122.22278635883,0.09763183339532272,49.280227459880265,125.98115949738036,0.030286870869768646
0.03121413606439674,122.092258209305,0.09910488200445965,49.22759850999178,125.9032625694597,0.030736880912338685
0.03168520130840624,121.984778879405,0.10060051415418982,49.18426284417609,125.84989115476039,0.031193583034117768
0.03215044816690814,121.855117786098,0.10207767292993333,49.13198349135472,125.77281443435244,0.031644439541515565
0.03262660127137444,121.709845896221,0.10358945903661385,49.07340986535631,125.68082450907744,0.03210565457975563
0.03308206371261654,121.533589234245,0.1050355522875575,49.00234317924758,125.55417117651527,0.03254662910471489
0.03353277402471394,121.345342824666,0.10646655752846676,48.92644222690534,125.41438878455698,0.03298281132020379
0.03400703331061534,121.193575504218,0.10797233076120369,48.86524964330071,125.31500946342251,0.03344157810431761
0.03446570352565574,121.043452215694,0.10942860869395697,48.80471993336783,125.21529995348199,0.03388506494790984
0.03493184444657864,120.937678504013,0.11090860611788717,48.76207197281804,125.16225467724551,0.034335573772822384
0.03539536747804564,120.795361161139,0.1123802917427949,48.70468962017125,125.07095735908075,0.03478335133816761
0.03585264708286234,120.628241149813,0.11383215448808794,48.637306831604604,124.95308290798366,0.035224901175783974
0.03631030080267994,120.427866634593,0.11528520504850881,48.5565158270679,124.80063869712009,0.03566661713999009
0.03677059352138394,120.256256938543,0.116746634430394,48.487322797620536,124.67815088083329,0.03611068348349676
0.03722714924382484,120.090711146743,0.11819619884914387,48.42057473436678,124.56134597339985,0.03655094985447817
0.03769280980807544,119.994992328306,0.11967467114063952,48.38198090677298,124.51794075205832,0.03699979663532591
0.03815068161767494,119.90228837641,0.12112841413611793,48.34460267336851,124.47664240548906,0.03744093954317613
0.03862517366762994,119.762482590848,0.12263492639472506,48.288232980629914,124.388329279786,0.03789789021216994
0.039095604142705444,119.619198289964,0.12412854315308977,48.23046075051349,124.29578311417623,0.03835072342069195
0.03957233796801684,119.489041472332,0.12564217304845346,48.17798152164426,124.21750220494951,0.038809415089536274
0.04005173434885604,119.359570564638,0.12716425655761793,48.12577885166205,124.14012837688642,0.03927045648226909
0.04052049720302224,119.2789519145,0.12865257861959561,48.093273411926404,124.11219435193091,0.03972106603572676
0.04100718126183904,119.161547197733,0.13019780050633895,48.04593583012595,124.04802636311163,0.040188688035396214
0.04147720388909834,119.037791476357,0.1316901223478872,47.99603752326714,123.97514622392983,0.0406400937108403
0.04195697086962144,118.906356391219,0.13321338251104806,47.94304289693951,123.89530692253821,0.04110064772768036
0.04243142790412254,118.755039363864,0.13471978359558906,47.882031871509966,123.79398525488303,0.04155589593667483
0.042928929934636643,118.595222896019,0.13629935254247133,47.817593871674866,123.68638891030481,0.042033033653504075
0.04342037214107914,118.462120836577,0.13785968154792627,47.763927121307844,123.60579020792265,0.04250413618177445
0.04390365467818124,118.309220284504,0.13939410360322543,47.70227761871202,123.50342743711974,0.042967200410929524
0.04439779529989364,118.182748275954,0.1409630000771623,47.65128410486465,123.42980174188867,0.043440446867699524
0.04488473937567664,118.067825042745,0.14250904751777332,47.60494705723479,123.3672685984416,0.043906582085429184
0.04537286910273524,117.926222901613,0.14405885940118437,47.54785307393036,123.27687397710787,0.044373634312821694
0.045855135206082843,117.749784608547,0.145590054279313,47.476713154166156,123.14921690225904,0.04483486198469983
0.04633617355939974,117.582540814709,0.14711735105109416,47.40928045649067,123.03086583345456,0.04529470364428232
0.04682411106106904,117.41338869022,0.1486665526188942,47.34107831989671,122.91116624230733,0.045760924520048686
0.04731022732232304,117.330642091261,0.15020997174837564,47.30771489119644,122.88158144047269,0.04622518916733102
0.04780633060977994,117.252406883928,0.1517850996860513,47.27617045559977,122.85781421221351,0.04669876978493506
0.04830031797021554,117.167650817047,0.15335350955543434,47.24199680943335,122.82688560733355,0.04717010779620989
0.04880586055047574,117.052796598647,0.15495860724776048,47.19568758857447,122.76565906648378,0.04765224131451345
0.04930846685342314,116.924655598364,0.15655438225961846,47.14402113726036,122.69003110328384,0.04813134419846669
0.04981676297044574,116.78674092494,0.1581682224311652,47.08841394093581,122.6046783156886,0.04861563748381768
0.05032944364372214,116.653663058996,0.15979598356881777,47.03475694538719,122.52477701975748,0.04910387080952203
0.05083274057137784,116.511744807202,0.16139395131412465,46.97753550626385,122.43435610450507,0.049582936101161504
0.05135110159498094,116.375772729432,0.16303974756406447,46.92271156450698,122.35179685805548,0.05007610042267488
0.05185674683166554,116.209453699643,0.16464517119053806,46.855651731696064,122.23569791959154,0.05055693282999483
0.05237032616064814,116.06703135667,0.16627578556005784,46.79822704300935,122.14549964531697,0.05104507343589459
0.05287580293348784,115.913013868788,0.1678806743138239,46.73612719189532,122.04200754754069,0.05152528026355979
0.05338349304320034,115.781084920364,0.16949259041216108,46.68293343989077,121.96188366174445,0.05200735777463785
0.05390013310045364,115.681764883182,0.1711329225939403,46.64288760089899,121.91702740768089,0.05249769525099358
0.054417065650180244,115.570966492978,0.17277418343932227,46.59821368996874,121.85999936388117,0.05298806981170184
0.05493641984142954,115.472032988777,0.17442313299653878,46.55832370107489,121.81565307299185,0.05348049955884101
0.05544889865485364,115.301815239964,0.1760502532291603,46.489691904753485,121.69517390792542,0.05396617278543719
0.05595128170554844,115.129320330842,0.17764531941511627,46.4201419573955,121.57095336524128,0.0544420494712959
0.05645620242740484,114.96926203748,0.17924844270701035,46.35560645351194,121.45998996799732,0.054920101869107375
0.05696460841623824,114.848260308853,0.1808626317215564,46.306818556529535,121.39054648463302,0.055401223277614285
0.05747972807181474,114.764308648445,0.1824981366280118,46.27296924705303,121.36092990190743,0.05588846208251261
0.05800818992974164,114.654543775742,0.18417600302692969,46.22871205037917,121.30544632739311,0.0563880743605337
0.05854708748334244,114.551415631775,0.18588700275961223,46.187130782731685,121.25806738410925,0.056897295708066425
0.05908647157723904,114.4320373229,0.18759954725773395,46.13899744859328,121.19342264370509,0.0574067172774908
0.05962961489663474,114.317030780854,0.1893240272968153,46.09262681084033,121.13371130244305,0.05791942715377975
0.060160648993274043,114.18792344812,0.19101006055364508,46.040570734281985,121.0575430299532,0.05842045229460995
0.06070293805831434,114.056121973006,0.19273182833514801,45.987428379516025,120.97966368030494,0.058931837449383
0.06124028079004814,113.914521536523,0.19443789150840282,45.93033508352607,120.89067882148365,0.05943830033533261
0.06179272694813654,113.764632785752,0.19619190806033351,45.86989993921521,120.794459675837,0.05995873140592274
0.062328899932864744,113.608283041441,0.19789425728684554,45.80685972230901,120.68936234667557,0.060463573491545825
0.06287422974413955,113.460112435711,0.19962567943764303,45.74711733407867,120.5938296117898,0.06097677603263805
0.06341656032493793,113.326768863531,0.20134757903167794,45.6933532057757,120.51356273759541,0.0614868949637756
0.06396513716930734,113.2241353648,0.20308931051255077,45.651971379087364,120.46653271428565,0.062002624564321276
0.06451269777695175,113.082691896739,0.2048278154418218,45.59494137276516,120.37796142287746,0.06251713367569982
0.06505946405138505,112.949328009526,0.2065637983631475,45.54116905344088,120.29775075478986,0.0630306323927175
0.06561150584326585,112.803574048152,0.20831653105236905,45.48240105621488,120.2047864059536,0.06354881827128206
0.06614457920400424,112.610727980556,0.21000903897271345,45.40464552176019,120.05931719668648,0.06404894431814916
0.06668835116897263,112.44448356433,0.2117355149614881,45.33761577313786,119.94322077128182,0.06455885015184722
0.06722301965562603,112.276656389697,0.21343308740661265,45.26994785632583,119.82423226904957,0.06505996608866843
0.06776105235265593,112.141950474864,0.2151413412196826,45.21563443146517,119.74080705192021,0.0655639817536786
0.06831363630361593,112.09636125879,0.2168957952639806,45.19725285954412,119.75407131278172,0.06608136437725536
0.06886847911608994,112.004689416887,0.21865742119358555,45.16029077288884,119.71828203089801,0.06660059277705918
0.06943644652252023,111.917302983377,0.22046071770900172,45.125056562897605,119.68844280692696,0.06713182423331923
0.07000103296990073,111.771636490806,0.2222532796794348,45.06632383309299,119.59576650189868,0.06765961386577946
0.07056000417108833,111.622594184082,0.22402801324320545,45.00622997502186,119.49868489529852,0.06818187994854402
0.07111554816484825,111.48828335675,0.22579186542339316,44.9520758494416,119.41683374162321,0.06870067375521022
0.07168867666903134,111.39422918241,0.22761154842417447,44.91415320634771,119.37993406106378,0.06923560691541952
0.07226536952670704,111.302050747092,0.22944254824729482,44.8769868612275,119.3453345734109,0.06977357821439155
0.07284485490900504,111.178728882244,0.23128241433609098,44.827263485320785,119.27752725663868,0.07031386317485024
0.07341602546521735,111.043761139641,0.23309588085206506,44.77284449150326,119.19615273522241,0.07084611027949535
0.07398594332121824,110.884701926751,0.23490537004486792,44.70871181686601,119.08861119869378,0.07137690784573199
0.07456696411484434,110.722010780163,0.23675011106463076,44.64311474656172,118.97821498473083,0.07191775634499717
0.07515154577137564,110.575032959286,0.23860615782411765,44.58385328918412,118.88491760989716,0.0724616244544752
0.07573688132873733,110.443774219264,0.24046459821874103,44.53092976520725,118.80844124080626,0.07300589775516013
0.07633279874349073,110.332113902427,0.24235663601058308,44.48590832545857,118.75407294788485,0.0735597064310616
0.07691275762021524,110.181773623083,0.24419800544418338,44.42529112482706,118.65615767192062,0.07409838989801215
0.07749828607620483,109.994388248717,0.24605705829195032,44.349737341882694,118.51876481599321,0.07464195234596688
0.07806582912543324,109.832960481328,0.24785900747325051,44.28464966607145,118.40716160660382,0.0751685366014205
0.07863522300500785,109.664707066349,0.2496668330408999,44.21680988915192,118.2882157622902,0.0756965596134568
0.07919362362154174,109.559540584906,0.251439754998395,44.17440676383411,118.23595760613608,0.07621411746321091
0.07977496539439674,109.451562903332,0.25328551512720965,44.13087016262347,118.18305754630795,0.07675265404948886
0.08036321817096294,109.295231472263,0.2551532176928073,44.067837329616445,118.07854800411438,0.07729729771680917
0.08094844501093484,109.200637972127,0.2570113129097181,44.029697230361606,118.04025981017271,0.07783884557799346
0.08162483937430325,109.032647636036,0.2591588650134128,43.961963526849715,117.93241998588245,0.07846439144070148
0.08238058715175545,108.911300958472,0.26155836420682355,43.913036546455906,117.88347787889245,0.07916286270968559
0.08313599372153745,108.736968750935,0.26395678006588136,43.842745800376996,117.77692470231176,0.07986053143879608
0.08390276892608885,108.585184993921,0.26639129134033207,43.78154658954895,117.69578267926258,0.08056820243182865
0.08450707939471754,108.469638672549,0.2683099770782282,43.73495831277176,117.63609103976643,0.08112557905944509
0.08512960737471714,108.348413900818,0.27028650341472693,43.68608048480982,117.57207183586799,0.0816994336599683
0.08573166313208884,108.201713437216,0.27219803044438207,43.62693085788549,117.4780262839302,0.08225410362528275
0.08632962382708843,108.043177879865,0.27409655565100577,43.56300932116157,117.37050478331696,0.08280469647797613
0.08693444384015164,107.881687134313,0.2760168591924814,43.497896252555,117.26032160587174,0.08336129706570582
0.08753607467902824,107.736685908228,0.27792703710591465,43.43943175819753,117.16753249156166,0.0839146555491663
0.08813039547415213,107.606892978337,0.279814005630433,43.38709924886548,117.09033101226261,0.08446099003384928
0.08873231756877774,107.486971136781,0.28172510828086933,43.338746762350105,117.0245391941959,0.0850140080136783
0.08933167827284703,107.346772609564,0.2836280785162893,43.2822187161762,116.93623996395004,0.08556436899512083
0.08994934535021504,107.200140707242,0.28558917148693275,43.22309673315998,116.84272318530934,0.08613122300542213
0.09057580766374344,107.03324297271,0.28757818933238544,43.15580356659667,116.7278654018329,0.08670582067048356
0.09119102100301354,106.871985685821,0.289531491684568,43.090784628523025,116.61775117713047,0.0872697795202491
0.09180525815361554,106.721518027002,0.2914816946377293,43.0301160684872,116.51911454001666,0.08783252639497045
0.09241575043700224,106.602461255514,0.2934200076374821,42.98211237822325,116.45420771087379,0.0883915287091896
0.09303168369867575,106.483103074004,0.29537559574329547,42.93398715943841,116.38940543843823,0.0889551966047069
0.09364678705039114,106.385228516281,0.2973285488849919,42.8945241377645,116.34786335645238,0.08951778811156758
0.09427014663180894,106.16098308728,0.29930771555599334,42.8041083807913,116.16879452949489,0.09008760828041239
0.09487404384443884,105.969217375924,0.3012250892060933,42.72678844597256,116.02294555140828,0.09063932819961708
0.09548850924842414,105.767714602275,0.3031760168637466,42.64554252763728,115.86731599625902,0.09120039095083754
0.09610405758909445,105.686957453348,0.30513038284537486,42.612981245189914,115.84390289886072,0.09176212707476016
0.09672780234607244,105.612076337629,0.30711077244878,42.58278917933201,115.8277003829735,0.09233102137550148
0.09735356690121054,105.463817778287,0.30909757491134343,42.52301132820532,115.73109661802252,0.09290143282958505
0.09797791794688344,105.315663468372,0.3110798894813549,42.463275510447595,115.63427290219772,0.0934702317256199
0.09860081114537764,105.116111970009,0.31305757538657397,42.38281634630763,115.48064587470022,0.09403738027071039
0.09922351248875394,104.939547579863,0.3150346521517937,42.31162558420077,115.35201808971773,0.0946040328037108
0.09984594138330574,104.791274132214,0.31701086389199573,42.25184173010868,115.25425754670096,0.09517011670804343
0.10047244098717224,104.621964882912,0.3190000001342719,42.18357624079012,115.13358907557237,0.09573957940563911
0.10110240531540224,104.502947349621,0.3210001368764021,42.135588371367184,115.06844668921651,0.09631186460092214
0.10172287328285924,104.36088872236,0.32297012267307806,42.07831033285555,114.9767781815512,0.09687520295543812
0.10233030172923324,104.0939053132,0.3248987079903155,41.97066262228224,114.74586605207398,0.09742639515773092
0.10294846267175524,103.853761799601,0.32686136898282286,41.87383675759913,114.54534691954858,0.09798701449410788
0.10354763762050324,103.63180408722,0.3287637494450978,41.78434340796711,114.36263258280246,0.09853011535288253
0.10416604771981423,103.471120860297,0.3307272015104102,41.719555930871756,114.24929857345337,0.09909034208843391
0.10480431802918325,103.454785071984,0.3327537097426568,41.71296934102396,114.29729326830902,0.09966823153143282
0.10544384193235525,103.339499030123,0.33478419813522786,41.6664860089456,114.23601283122407,0.10024692123026756
0.10609163171243824,103.217086431095,0.3368409306869914,41.61712924901751,114.16755555117363,0.10083274931788293
0.10675447469031324,103.057090662367,0.3389454571417445,41.55261895506637,114.05889623913998,0.10143183571235191
0.10741507604509624,102.857836210753,0.34104286644318055,41.472279560175615,113.9063185091651,0.10202853922511085
0.10805572971152023,102.652283473524,0.3430769418340767,41.38940069652487,113.74445087080947,0.10260688463378584
0.10868255237441324,102.432017398116,0.345067103788762,41.30058941492037,113.56459049380355,0.10317242065999596
0.10928397765680424,102.206188131617,0.3469766290603534,41.209535054667974,113.37568691177975,0.10371474200613731
0.10991258916402824,102.004185895927,0.3489724705957896,41.12808775323777,113.21573007331718,0.10428126372254132
0.11053040204840923,101.825668948098,0.3509340265036993,41.05610971987311,113.0805010757795,0.10483774087846837
0.11115911763970024,101.616847727021,0.35293019850604823,40.971913003534866,112.91248685768443,0.10540372060020953
0.11179021540646623,101.455589329765,0.3549339339155303,40.906893617761256,112.79733151512941,0.1059715228207457
0.11241089909011524,101.251270351512,0.3569046046111159,40.82451220572965,112.6330166857418,0.10652964114531194
0.11302420937125623,101.039025210784,0.35885186475373854,40.73893496498811,112.45888115087529,0.10708082351350247
0.11363412414398225,100.836605883551,0.3607883441571436,40.657319492247765,112.29508527478025,0.10762865321759278
0.11425298273212024,100.641356542926,0.36275322017448175,40.578594958107765,112.13993171416207,0.10818420973762029
0.11489045390455624,100.45328790161,0.36477719114696605,40.50276568192915,111.99441174483104,0.1087561524662366
0.11550531989431125,100.219543341727,0.36672939066443816,40.40851987538433,111.79543375507497,0.10930750394614339
0.11612989621003424,99.9708294961508,0.3687124204668587,40.308238452848,111.58043154956982,0.10986725163924616
0.11674816144682525,99.752388301809,0.37067541259367015,40.22016296328939,111.39829623597501,0.11042103490606761
0.11737077904590525,99.539221352801,0.3726522234707491,40.13421404944936,111.22221730860205,0.11097840685606898
0.11799813829516824,99.3868429080092,0.3746440890871591,40.072775060509315,111.11430534218863,0.11153970952147467
0.11861376148017024,99.1876808827543,0.3765986926995405,39.992472931926535,110.95270480475256,0.1120902057435602
0.11923972281738024,98.9689870094449,0.37858611994518226,39.90429556220818,110.77002158796802,0.11264963589207289
0.11985715125031224,98.7399335956003,0.38054645521974134,39.81194122574605,110.57462075101395,0.11320113364612892
0.12048040106847424,98.4945391387453,0.3825252733924057,39.712998180742105,110.36120071723585,0.11375752286845404
0.12112449080990624,98.2794227442114,0.3845702583214523,39.62626325046604,110.18346778119553,0.11433219127812011
0.12175119485900024,98.0482572081917,0.3865600436773257,39.5330573063429,109.98574967713162,0.11489103104744695
0.12239094315182324,97.784334456501,0.38859124450703875,39.4266436528612,109.75225137610549,0.11546118059307282
0.12302024681067524,97.521406124866,0.39058928362389383,39.32063094954598,109.51851357567111,0.11602170481076762
0.12363722861194024,97.2487264369117,0.39254820084291026,39.210686499362794,109.27228945961218,0.11657094903114834
0.12423032429559724,96.949867475105,0.3944312796385212,39.090186565962334,108.99398095195247,0.11709864533305266
0.12482030637055624,96.6333500740583,0.39630447272651603,38.96256674986031,108.69515443591547,0.11762329522794382
0.12542559328793224,96.3312038459909,0.3982262586891848,38.84074139070353,108.41360224051505,0.11816126926186271
0.12603867204705324,96.0931769742321,0.400172783749394,38.74476895601038,108.20463339284677,0.11870587375211672
0.12665617959268624,95.8424546147099,0.4021333702067788,38.64367770065103,107.98149375899446,0.11925411272966867
0.12727354444654623,95.6050199597704,0.4040935036177843,38.547944047779424,107.77300971693319,0.11980192472461666
0.12787837526079823,95.3149365289721,0.4060138414530344,38.43098240848155,107.50365575038315,0.12033832391215558
0.12848866796318625,95.0110761907199,0.4079515207831163,38.308465920098264,107.2189228122143,0.1208792755442079
0.12910721096855424,94.7362852876513,0.40991539482515965,38.197670227981,106.96742285866124,0.12142724165861986
0.12971709831133024,94.4475159688972,0.4118517871384735,38.081238438659355,106.69897368309559,0.12196724590338641
0.13031419486388424,94.1656241096684,0.4137475686928324,37.967579641018304,106.436741599375,0.12249564262802434
0.13091036988454424,93.8337887519138,0.41564042438342796,37.83378362477165,106.11760474509502,0.1230229454388711
0.13150445753589723,93.4718791389996,0.4175266526764737,37.68786166884464,105.76384790003469,0.1235481255763132
0.13208818567982425,93.0813568741715,0.41937998953344197,37.53040309166595,105.37630442429705,0.12406387929075988
0.13268826360782723,92.7115134982402,0.4212852369548514,37.38128224249045,105.01324324077532,0.12459380174048736
0.13328625993544324,92.3470651943867,0.42318387529503226,37.23433668637672,104.65566013016104,0.1251216067403099
0.13388360189321125,92.0798145463705,0.4250804360109457,37.12658122509659,104.40779177949749,0.12564855620417453
0.13449198884146024,91.7656857020742,0.42701206457163626,36.99992447507631,104.1074352795465,0.12618496381261618
0.13509433076373423,91.4062355373977,0.42892450017485617,36.85499416867876,103.75469975495471,0.12671575828490658
0.13570455439572723,91.0029211202831,0.43086196020643397,36.69237779569815,103.35243197962063,0.12725321111762536
0.13634202249875224,90.5632652214054,0.4328859214335383,36.515108537270656,102.91084396578272,0.1278143511279005
0.13698513342496724,90.157370544948,0.43492779862427094,36.35145180372303,102.5075899782919,0.1283801394190359
0.13761442214127123,89.8045684159895,0.4369257902985361,36.20920198532696,102.16297220420213,0.12893345767746897
0.13819451856466924,89.4172953990666,0.4387675964428248,36.05305350490366,101.77427548809544,0.12944325129466222
0.13875939980228624,88.8941709903667,0.4405610943722588,35.84212974331586,101.22907280291179,0.12993942404954248
0.13932381573907923,88.3749170723344,0.44235311497157653,35.63276656356523,100.68764773447673,0.13043494233833133
0.13992400646375824,87.9157316243318,0.4442587205224324,35.44762299093058,100.21725302440082,0.1309615991877577
0.14051854564835825,87.4904250038642,0.44614638243353744,35.27613936155805,99.78445228356395,0.13148302359068323