File: example/data/02 processed data/test_ID_070.csv
Strain,Stress_MPa,Displacement(mm),Force(kN),True Stress (MPa),True Strain
-0.00011214169229950044,0.317439578086867,0.0001735521230071,0.0639958189423123,0.3174569299963799,5.46605920690968e-05
-8.429529265811689e-05,1.02226640110857,0.0002619644418687,0.2060889064634877,1.0223507467612338,8.250508199008117e-05
-4.54996346102685e-05,2.32451568109127,0.0003851406561706,0.468622361308,2.3247976544754256,0.0001212967869231
-1.6609353218568492e-05,4.04316341736596,0.0004768672995893,0.8151017449409775,4.043770677970885,0.000150183147014
5.674212042923151e-05,6.72350607490253,0.000709758228421,1.35545882470035,6.7250090871105614,0.0002235209160539
0.00012926634814619956,10.0721921893631,0.0009400226514231,2.030553945375601,10.075174264578058,0.0002960263063216
0.00020610508697619956,14.0422093518393,0.0011839856472084,2.830909405330804,14.047445816194472,0.0003728393520323
0.0002858461018206996,18.6677403295815,0.0014371633693397,3.7634164504436303,18.67619028000356,0.0004525474650542
0.00037517404578489956,23.5394261929933,0.001720779591426,4.745548320507449,23.552184039981263,0.0005418310071355
0.0004582492813563996,28.4272618844014,0.0019845434643655,5.730935995895322,28.44503043141951,0.0006248577953418
0.0005509317458137996,33.3115675848134,0.0022788102890178,6.715612025098383,33.33547648023249,0.0007174780751383
0.0006398491389771996,38.3440504691419,0.0025611230123116,7.730160574579006,38.374980809312525,0.0008063277476532
0.0007319444547706996,43.5407014253308,0.0028535256399559,8.77780540734669,43.57983355380288,0.0008983446006881
0.0008214335871757995,48.8914017752194,0.0031376536353421,9.856506597884232,48.9397180853035,0.0009877493803871
0.0009117143188742996,54.3832573728733,0.0034242949584849,10.963664686371258,54.44191070013249,0.0010779369143576
0.0010019473168827995,59.9446874155693,0.0037107847271618,12.08484898297877,60.014747834635806,0.0011680686373049
0.0010967717022181995,65.5949185821264,0.0040118521506017,13.22393558615668,65.67780271289247,0.001262777840855
0.0011901769794364996,71.2318566581661,0.0043084139057698,14.360342302286286,71.3285169169881,0.0013560608914008
0.0012828313027740995,76.8881153594145,0.0046025913823667,15.500644056457965,76.99957506875613,0.0014485853744648
0.0013827488743033995,82.4847488871763,0.0049198296719722,16.62892537565474,82.61256334861261,0.0015483533346558
0.0014765187076146995,88.0901443720976,0.0052175488927356,17.758973105414874,88.23490488713053,0.0016419737089527
0.0015683781349720995,93.7021431152669,0.0055092025745954,18.89035205203781,93.86473337923408,0.0017336782243203
0.0016618193509469995,99.3283748706639,0.0058058784353157,20.024600373925843,99.51000903434154,0.001826953233389
0.0017560381056843995,104.937080517397,0.0061050229816069,21.15531543230724,105.13885793099747,0.0019209955898909
0.0018501359784499996,110.569833945604,0.0064037837276377,22.29087852343377,110.7928466395846,0.0020149084646157
0.0019435785884998995,116.132107611408,0.0067004640145461,23.41223289445985,116.37719076352884,0.0021081586379817
0.0020377980491519997,121.726606072883,0.0069996108021166,24.540083784293216,121.99496477107913,0.002202175258587
0.0021324276110209995,127.332742946529,0.0073000596610506,25.670280978020248,127.62551038599824,0.0022965922014447
0.0022271181247157995,132.926967714748,0.0076007020420316,26.7980766912932,133.24518449425997,0.0023910610368469
0.0023191750230598996,138.529372622921,0.0078929826942741,27.92752152078087,138.87375370662537,0.0024828938677078
0.0024070700699014994,144.247777516109,0.0081720494679962,29.08035194724758,144.61905309831693,0.0025705671077676
0.0024965658818769994,149.962526219773,0.0084561986710184,30.23244528590624,150.36193186226816,0.0026598291762083
0.0025818423480545995,155.678366097098,0.0087269514511323,31.38475860517496,156.10627083502587,0.0027448755063965
0.0026626557630457996,161.377927927207,0.0089835340437294,32.53379027012493,161.83454024514103,0.0028254641554315
0.0027476607554855997,167.072886115847,0.0092534248947257,33.68189384095476,167.5598141169866,0.0029102257159383
0.0028335783052794994,172.703856946435,0.0095262131153214,34.817097560401294,173.2220345045798,0.0029958899204694
0.0029166562962915994,178.2850100162,0.0097899857367848,35.94225801926592,178.8347447264807,0.0030787159612497
0.0030008403561423997,183.682819057812,0.0100572701268111,37.030456322054896,184.2646608621958,0.0031626377193222
0.0030841048552786997,189.074389670795,0.0103216349115688,38.11739695763227,189.68905323656185,0.0032456358545512
0.0031694608503374994,194.400310859225,0.0105926401958805,39.19110266921976,195.0488817401381,0.0033307116451749
0.0032527406618095994,199.632718480692,0.0108570535973044,40.24595604570751,200.3153714332339,0.0034137110924853
0.0033362729902222995,204.736347671611,0.0111222687400148,41.27484769059677,205.4535548148087,0.0034969552869333
0.0034203565059833995,209.736097824614,0.0113892339025562,42.28279732144219,210.48845482490816,0.003580741769731
0.0035030584158505995,214.53724082636,0.0116518124663846,43.250707750594174,215.3245629357031,0.0036631446797599
0.0035861802202461998,219.191373909532,0.0119157241953406,44.18898098016165,220.0139956284308,0.003745959124759
0.0036699233332650994,223.659320798155,0.0121816085791756,45.089719072908046,224.51744057801244,0.0038293856462281
0.0037532811428611997,227.959935858553,0.0124462696246433,45.95672306908428,228.8535581657379,0.0039124214094685
0.0038384974323504998,232.081096375524,0.0127168313437718,46.78754902930564,233.0106510718028,0.0039973013458734
0.003918243468393699,236.073103781454,0.0129700250082086,47.59233772234113,237.0374735640716,0.0040767260950101
0.003999497992017499,239.979806397369,0.0132280081207142,48.37992896970959,240.97963468959952,0.0041576467663275
0.0040811989639446995,243.818412151881,0.0134874087065834,49.15379188981922,244.8541534353085,0.0042390054499304
0.004159283781376699,247.691648951526,0.0137353280019297,49.93463642862764,248.7631847126876,0.0043167569432394
0.004240598557979399,251.493267218341,0.0139935024176435,50.70104267121755,252.6016992318342,0.0043977181828028
0.004321361526857399,255.306411622629,0.0142499248438309,51.469772583122015,256.4522690014544,0.004478123526139
0.004403675675011499,259.029798373784,0.0145112722642205,52.22040735215485,260.2136887450432,0.0045600665280667
0.0044922745067898,262.823527259275,0.0147925735551162,52.98522309546985,264.04804264793574,0.0046482583740352
0.004582912842409099,266.731216904281,0.0150803502707075,53.77301332790304,267.9981145984696,0.0047384723075171
0.004685592593373299,270.758245222601,0.0154063584800192,54.58486223687636,272.07207154931604,0.0048406614427591
0.0048005221412917,274.737171836964,0.0157712597946598,55.387013842331946,276.1018809117013,0.00495502945972
0.004935490841336099,278.734324303516,0.0161997854173011,56.19283977958883,280.1565089467139,0.0050893220223936
0.005096866190004899,282.714555511342,0.0167121521493245,56.99525439108655,284.20267162678584,0.005249865278555
0.0052882696037908,286.768653208663,0.0173198579880944,57.81256048686646,288.33299725559567,0.0054402483592289
0.005511048094358099,290.549892086612,0.0180271796956456,58.57485824466097,292.1995913354926,0.0056617936272527
0.005764882385056399,293.93146076355,0.018833103568613,59.25658248993168,295.67496994233227,0.0059141629735359
0.006044811023708699,296.880392897216,0.0197218769963338,59.851087208078745,298.7244995401584,0.0061924022424028
0.006353237845243099,299.398436686107,0.0207011321547055,60.358724835919176,301.35052695532005,0.0064988780937306
0.006677945170688499,301.473414288015,0.0217320779129949,60.77704032046383,303.5369241236068,0.0068214300026357
0.007011112845738,303.110852200745,0.0227898852812768,61.1071478036702,305.2865566256789,0.0071522779953454
0.007354831724939599,304.3370898599,0.0238811927227422,61.35435731575584,306.6262025199387,0.0074934890530176
0.0077008619610182995,305.312479118483,0.0249798387222921,61.55099579028617,307.71457565022564,0.0078368770418946
0.0080512767899269,306.047789727921,0.0260924058040765,61.69923440914887,308.5629151216286,0.008184496018993
0.0084039270842658,306.598240032473,0.0272120704886026,61.81020519054655,309.22601103072344,0.0085342106702587
0.0087572144260119,307.045002017699,0.0283337577986464,61.90027240676812,309.7850772052437,0.0088844344768094
0.0091118391790597,307.414047163823,0.0294596913895732,61.97467190822672,310.2664323475288,0.0092358607864878
0.0094730624816565,307.747920303474,0.030606575375318,62.04198073318037,310.71456909697497,0.0095936992081993
0.0098314769533781,308.004467892079,0.0317445413230341,62.09370072704313,311.0839830286709,0.0099486286058423