File: example/data/02 processed data/test_ID_079.csv
Strain,Stress_MPa,Displacement(mm),Force(kN),True Stress (MPa),True Strain
9.90440144920579e-06,0.10279082704252,3.144647460122838e-05,0.020722630731772034,0.10279184512413633,9.904352400952058e-06
1.18155797457085e-05,0.109258493657584,3.7514465692624485e-05,0.022026512321368936,0.1092597846100287,1.1815509942309485e-05
1.64864946011427e-05,0.119770556677971,5.234462035862807e-05,0.024145744226278954,0.11977253127460703,1.6486358700306116e-05
3.69107006303527e-05,0.139489156006562,0.00011719147450136982,0.028121013850922902,0.13949430464904056,3.691001944723955e-05
5.8013017846677e-05,0.685852357413888,0.00018419133166319945,0.13826783525463981,0.6858921457789388,5.801133515665046e-05
0.0001085605177526,2.51464738683258,0.000344679643864505,0.5069529131854481,2.51492037825486,0.00010855462548608764
0.00018259166184,5.96145007431289,0.000579728526342,1.2018283349814787,5.962538585388936,0.0001825749940115125
0.0002515686168547,10.6982949607779,0.0007987303585136724,2.1567762640928247,10.700986316043887,0.0002515369787762079
0.0003478139746607,16.0025489633756,0.0011043093695477224,3.226113871016521,16.008114873535252,0.00034775350140206545
0.0004343465873767,21.6013045782479,0.0013790504149210224,4.3548230029747765,21.610687031174344,0.0004342522862029127
0.0005284512874981,27.2706875412811,0.0016778328378064672,5.49777060832227,27.285098771223247,0.0005283117062889074
0.0006269205182658,33.1841755139918,0.001990472645493915,6.689929783620747,33.20497935450326,0.0006267240856918583
0.000712377280589,39.1266603167241,0.0022617978658700747,7.887934719851578,39.15453326059906,0.0007121236603358117
0.0008108080532844,45.0628480454248,0.0025743155691779697,9.08467016595764,45.099385365523965,0.0008104795260045646
0.0009022092934567,51.0216711733904,0.002864514506725022,10.285968908555505,51.06770339929073,0.0009018025472805483
0.0009983930352752,57.0702426300868,0.00316989788699876,11.5053609142255,57.12722116285015,0.0009978949724295768
0.0010969198025131,63.1087402647023,0.0034827203729790924,12.722722037363983,63.1779654916103,0.0010963186255748866
0.0011972540659499,69.3417039598409,0.0038012816593909326,13.979287518303925,69.42472359684672,0.0011965379288424482
0.0013011125759964,75.6434827453221,0.0041310324287885695,15.249726121456936,75.7419034320142,0.0013002668625280605
0.0014016922099439,81.9422714984571,0.004450372766571882,16.51956193408895,82.0571293420816,0.0014007107564415237
0.0015114487970117,88.1762133773643,0.004798849930512147,17.776324616876643,88.30948720899856,0.0015103077079323725
0.0016157432202365,94.3984536752632,0.005129984724250887,19.03072826093306,94.55097733678983,0.0016144393114919326
0.0017176287852943,100.655877251578,0.005453471393309402,20.292224853918125,100.82876668375435,0.0017161553479432016
0.0018188389795971,106.840164128197,0.005774813760220792,21.538977088244515,107.03448918329991,0.0018171868949274778
0.0019130411380069,112.952987499864,0.0060739056131719074,22.771322279972583,113.169071211612,0.0019112136052014124
0.0020133661769552,119.016200536045,0.00639243761183276,23.993666028066674,119.255823728714,0.0020113420716620705
0.0020995658143317,125.056873194056,0.0066661214605031474,25.21146563592169,125.31943832986144,0.0020973648062631053
0.0022094053354105,131.150637586778,0.007014861939928337,26.439968537494448,131.44040250520473,0.0022069681885457694
0.0023132538177105,137.231597746861,0.0073445808712308365,27.66589010576718,137.54904926425945,0.0023105823651365424
0.0024196761628747,143.264709458966,0.007682471817127171,28.882165426927546,143.61136366142503,0.0024167534602213482
0.0025236880658028,149.172857585826,0.008012709608923889,30.07324808930252,149.54932334625704,0.0025205089127464664
0.0026191879210247,154.956123033953,0.008315921649253422,31.239154403644925,155.36198223969234,0.002615763825937674
0.0027247038325942,160.72585903871,0.008650934668486585,32.40233318220394,161.16378940282976,0.00272099855610118
0.0028256896671934,166.358003794035,0.008971564693339045,33.537773564877455,166.82807988641073,0.0028217049108374467
0.0029243883068223,171.923868091834,0.009284932874160802,34.659851807313736,172.42664024134544,0.0029201206015982088
0.0030195446228914,177.463311190402,0.009587054177680195,35.776603535985046,177.99916957746748,0.003014994954343784
0.0031116939806048,182.874154765051,0.00987962838842024,36.86742960063428,183.4432031716416,0.0031068626806471412
0.0032121227170466,188.205298551766,0.010198489626622955,37.94218818803603,188.80983706671265,0.0032069748716002967
0.0033106647943199,193.423467832733,0.01051136072196568,38.99417111507897,194.0638280980821,0.0033051966091913135
0.0034051760680757,198.539618471231,0.010811434016140346,40.02558708380017,199.21568082861413,0.0033993915837872975
0.0035074258714892,203.547786135279,0.01113607714197821,41.035233684872246,204.26171490645422,0.003501289198464677
0.0036142142616879,208.382052363916,0.01147513028085908,42.009821756565465,209.13518974944947,0.0036076986837338607
0.0037254472853075,213.057063943483,0.011828295130851312,42.95230409100617,213.85079680396683,0.0037185249936644987
0.0038451315082462,217.4891852806,0.012208292538681683,43.84581975256896,218.3254597996252,0.0038377578857428903
0.0039651449646139,221.578020300893,0.012589335262649133,44.67012889266003,222.4566092723582,0.003957304496213929
0.0040976317430521,225.230121613854,0.013009980784190417,45.40639251735297,226.15303170967042,0.004089259313729849
0.0042412814505596,228.385992861154,0.013466068605526727,46.04261616080865,229.35464213624365,0.0042323125671512255
0.0044328339940254,230.998440569081,0.014074247931030645,46.569285618726724,232.02241830900246,0.0044230379243144664
0.0046682559072763,233.009295005794,0.01482171250560225,46.974673873168065,234.0970420236551,0.004657393393545784
0.0049576729677213,234.419259961827,0.015740611672515125,47.25892280830433,235.58143399005297,0.004945424174087837
0.0052785768555952,235.270157295215,0.016759481516514758,47.43046371071535,236.51204890232577,0.0052646940018288135
0.0056050898295821,235.77939466085,0.017796160208923165,47.533125963627356,237.10095934788853,0.005589439766355937
0.0059466988341249,236.131717498159,0.018880768798346555,47.60415424762885,237.5359217073052,0.005929087007607093
0.0063041216593296,236.424662068605,0.02001558626837148,47.66321187303077,237.91511190155137,0.006284333804202803
0.0066769846834282,236.662999148864,0.021199426369884533,47.71126062841098,238.24319436931515,0.006654792351665668
0.0070661579400761,236.855263318621,0.022435051459741617,47.750021085034,238.52892001816872,0.0070413096321028735
0.0074488143470561,237.026838635721,0.023649985551903115,47.78461066896135,238.7924075519881,0.007421208929796093
0.0078300253924071,237.185111736593,0.024860330620892542,47.816518526097155,239.04227718419142,0.007799529827510685
0.0082071830751378,237.336068581692,0.026057806263562515,47.84695142606911,239.2839291468754,0.008173687293996526
0.0085876275208885,237.566562664728,0.027265717378820983,47.89341903320917,239.6066958163105,0.008550963602190598
0.0089629321079519,237.761299337509,0.028457309442747283,47.93267794644182,239.8923377213695,0.008923003439904847
0.0093361669945763,237.943180622307,0.02964233020777975,47.96934521345709,240.1646578918175,0.009292854361450692
0.0097139201177189,238.067827983247,0.030841696373757506,47.9944741214226,240.38039984687515,0.009667043322845431
0.0100853336843018,238.221406039142,0.03202093444765821,48.02543545749103,240.62394840979033,0.010034816080529236
0.0104529737996595,238.411361537557,0.03318819181391891,48.06373048597149,240.90346925325025,0.0103987192226305
0.0108164975316719,238.553486371406,0.03434237966305828,48.09238285247545,241.133799567914,0.010758417660753507
0.0111748318310217,238.78494894545,0.035480091063493896,48.13904570740272,241.4533305936945,0.011112854693096383
0.0115392117405792,238.946818925576,0.036636997276338956,48.171678695396125,241.70407686389606,0.011473142806640918
0.0118940205931824,239.099495074119,0.03776351538335412,48.202458206942396,241.9433493923501,0.011823842647455892
0.0122482202547738,239.254168123562,0.03888809930890681,48.2336402937101,242.18460587161206,0.012173817721399648
0.0125937531934019,239.345554881267,0.03998516638905103,48.25206386406343,242.3598137273795,0.012515111458405455
0.0129514453358196,239.485937998164,0.04112083894122723,48.28036510042986,242.58762703284467,0.0128682925638139
0.0133007019441325,239.696230878529,0.04222972867262068,48.32276014511145,242.88435900257628,0.01321302420270753
0.0136467494980165,239.819805819639,0.043328429656202386,48.34767285323922,243.0925666343226,0.013554471196806897
0.0140036812535736,240.036868812786,0.04446168798009618,48.39143275265766,243.3982686127461,0.013906535589988753
0.0143426542034931,240.190358864825,0.04553792709609059,48.42237634714872,243.63532612503607,0.014240771363386634
0.0146904594120668,240.41173649815,0.04664220863331209,48.46700607802703,243.94349535536054,0.014583599885648094
0.0150340007253554,240.602917914474,0.04773295230300339,48.50554825155796,244.22014235692282,0.014922110184278354
0.0153701632928905,240.752855754062,0.04880026845492733,48.535775720018904,244.45326646023165,0.015253238908858395
0.0157068709175773,240.897808534874,0.04986931516330793,48.5649982006306,244.68155931785853,0.015584794652043042
0.0160493599948753,241.047469225599,0.050956717983729076,48.59516979588076,244.91612683505426,0.015921930648311638
0.0163871663247245,241.226058881001,0.05202925308100028,48.631173470409806,245.17907042974176,0.01625434578510482
0.0167299932021395,241.460744418042,0.053117728416792916,48.67848607467727,245.50038103073936,0.01659158840691597
0.017071858748441,241.633984374623,0.05420315152630017,48.71341124992399,245.75912562468957,0.01692777214004964
0.0174130270063879,241.796718147923,0.055286360745281586,48.74621837862128,246.00713093108874,0.017263157537634674
0.0177578235865266,241.98578968261,0.05638108988722195,48.784335200014176,246.28293064624012,0.017601995511200445
0.0180911331122909,242.152658691905,0.057439347631523606,48.81797599228805,246.53347467379538,0.017929435842808133
0.018420068700404,242.33742434995,0.058483718123782696,48.85522474894992,246.80129635515502,0.018252474174913328
0.0187539213321686,242.498021358223,0.05954370022963531,48.88760110581776,247.04581017398166,0.018580234725938286
0.0190810946967699,242.636564580918,0.06058247566224442,48.915531419513066,247.2663358465854,0.018901333700918066
0.0194079768472719,242.735190997558,0.06162032649008828,48.935414505107694,247.44618996445672,0.019222043934656256
0.0197422612163841,242.85728068735,0.06268167936201952,48.96002778656976,247.65183256098035,0.01954991028394894
0.0200648274292213,242.975981675953,0.06370582708777763,48.983957905872124,247.85125281772662,0.01986618157972151
0.0203900442727925,243.1758632179,0.06473839056611619,49.02425402472864,248.1342298349875,0.020184950547205538
0.0207131362430335,243.383277941202,0.06576420757163136,49.06606883294633,248.4245089364742,0.02050153618189935
0.0210396223420103,243.542331589657,0.0668008009358827,49.09813404847486,248.66637027059608,0.020821345816427143
0.0213694828958307,243.735414725574,0.06784810819426247,49.13705960867572,248.94391450166034,0.02114435706411726
0.0217070558332292,243.84329107966,0.06891990227050271,49.15880748165945,249.13641101368455,0.021474812564996927
0.0220345185335713,243.96606056039,0.06995959634408888,49.18355780897462,249.3417352433703,0.021795266684295985
0.0223712749139987,244.144537235054,0.07102879785194587,49.21953870658689,249.60636179629037,0.022124708505046397
0.0227019267146091,244.273285498789,0.07207861731888389,49.24549435655587,249.81875972451928,0.02244807277702299
0.0230291325938012,244.444604494445,0.0731174959853188,49.28003226608012,250.07395170318688,0.02276796417280889
0.0233658619689848,244.624249891721,0.07418661175152674,49.31624877817096,250.3401063489574,0.023097059366177952
0.0236898840879854,244.823656184007,0.07521538197935365,49.35644908669581,250.6235002210029,0.02341363317940297
0.0240234599018271,245.001131316151,0.07627448518830103,49.39222807333605,250.88690617022687,0.023739436415262737
0.0243548112118478,245.117864626326,0.07732652559761675,49.41576150866732,251.08766394395147,0.024062961925744485
0.0246765816628052,245.182488230621,0.0783481467794065,49.42878962729319,251.2327539237337,0.0243770327152123
0.0250075695917176,245.309777613755,0.07939903345370337,49.454451166933005,251.44437894895972,0.0246999975306321
0.0253296469768905,245.483751688795,0.08042162915162733,49.489524340461074,251.7017684576348,0.025014167692710174
0.0256595273197093,245.677136902395,0.08146899924007701,49.52851079952284,251.98109610856997,0.025335846958303203
0.0259826302180609,245.816262027158,0.08249485094234335,49.55655842467505,252.2032150649956,0.02565081699324378
0.0263111908935284,245.920303941243,0.08353803108695267,49.57753327455459,252.39076000283552,0.025971005725378207
0.0266359766169092,246.011086399394,0.08456922575868671,49.59583501811783,252.56383194422872,0.026287414964963784
0.026961625983782,246.099013883002,0.08560316249850784,49.61356119881321,252.73424345029304,0.026604565091346694
0.0272932988231701,246.203532008014,0.08665622376356506,49.634632052815626,252.92323857842862,0.026927478122504473
0.0276166754818568,246.357344148078,0.08768294465489535,49.66564058025252,253.16091497398756,0.02724221372201954
0.0279409131158069,246.534549469019,0.0887123991426869,49.70136517295423,253.42294989577744,0.027557687867271176
0.0282704366787952,246.69191096978,0.08975863645517476,49.73308925150764,253.66599901802212,0.027878203135161546
0.0285962130197256,246.77576791056,0.09079297633762877,49.7499948107689,253.83262033783677,0.028194972667792573
0.0289315666664047,246.891753756706,0.09185772416583492,49.773377557351935,254.03471898990372,0.02852094994300562
0.0292588562282738,247.055250726748,0.0928968685247693,49.8063385465124,254.28380478820208,0.02883898617618127
0.0295853239517302,247.237993417578,0.09393340354674337,49.84317947298372,254.5526095460128,0.029156123072052762
0.0299233724199581,247.343880961415,0.09500670743336696,49.864526401821266,254.74524402722122,0.029484403765267883
0.0302556819290373,247.416055674666,0.09606179012469343,49.87907682401267,254.9017971592957,0.02980700631892435
0.0305876422533797,247.516179262316,0.09711576415448055,49.89926173928291,255.08711560551512,0.03012916601279156
0.0309176210482593,247.632923066306,0.09816344682822327,49.922797290167296,255.2891439407428,0.030449299852439687
0.0312385385079084,247.755650587797,0.09918235976260917,49.94753915849988,255.49517501923577,0.030760544430841332
0.0315655411696361,247.887660777824,0.10022059321359461,49.97415241280932,255.7123689395512,0.031077591180640244
0.0319019747120367,247.982457704981,0.10128876971071651,49.99326347332417,255.89358779971397,0.03140367680378893
0.0322349967210068,248.094773888054,0.10234611458919658,50.01590641583169,256.0921081108343,0.031726351138359275
0.0325675392912998,248.182055433291,0.10340193724987687,50.03350237535147,256.26473427501026,0.03204845707088155
0.0329047092690891,248.239605581455,0.10447245192935789,50.04510448522133,256.4078576321861,0.032374939289191815
0.0332381873746374,248.330519284389,0.10553124491447374,50.06343268773282,256.5845756152045,0.032697741849446335
0.0335649951149467,248.38786303283,0.10656885948995576,50.074993187418535,256.725000442139,0.03301398651734854
0.0338895845445983,248.464591212672,0.10759943092909958,50.090461588474675,256.8849529829129,0.033327985611221855
0.0342030386078597,248.544827931468,0.10859464757995453,50.106637310983956,257.0458162769919,0.03363111909968613
0.0345322344195097,248.659286422868,0.10963984428194329,50.129712142850195,257.2460471922105,0.03394937713755165
0.0348561820485871,248.811618710723,0.11066837800426403,50.16042233208175,257.4842417883076,0.03426246251982761
0.0351844428618847,248.94148611179,0.11171060608648391,50.18660360013687,257.7003536058429,0.03457961650424592
0.0355163132028138,249.065247282069,0.11276429441893382,50.211553852065116,257.91112661247524,0.034900155667424104
0.0358468015589325,249.154965571253,0.11381359494961069,50.22964105916461,258.08637417950837,0.03521925795959869
0.0361799457738965,249.276179243778,0.11487132783212138,50.25407773554564,258.294977891542,0.0355408215863843
0.0365098202021179,249.399589231729,0.11591867914172432,50.278957189116575,258.5051233930615,0.035859127235808176
0.0368416183463986,249.512490505067,0.11697213824981553,50.30171808582151,258.70493445291413,0.036179186962243585
0.0371742258601926,249.61904987736,0.11802816710611151,50.323200455275774,258.89844481650766,0.03649992464375588
0.0375112872485123,249.674331711313,0.11909833701402654,50.3343452730007,259.0399372867164,0.036824852339212004
0.0378469986152588,249.747983569209,0.12016422060344668,50.34919348755254,259.20019515751653,0.03714837370124495
0.0381926679297521,249.854573477702,0.12126172067696292,50.37068201310473,259.3971862332657,0.03748138209531201
0.0385304095771464,249.946712794143,0.12233405040743982,50.389257299299224,259.5772620105627,0.037806646117299295
0.0388660970862264,250.027388843313,0.12339985824876883,50.405521590811894,259.7449776123129,0.0381298270901421
0.0392023572103349,250.03866873317,0.1244674841428133,50.407795616607075,259.8407739412443,0.038453454664919985
0.039533021788803,250.125467546895,0.1255173441794495,50.425294257454034,260.01368310536094,0.03877159480396584
0.0398686796287304,250.166814107207,0.126583057821219,50.433629724012924,260.1406346725874,0.03909443559284654
0.0402030329962595,250.286246186282,0.1276446297631239,50.45770723115446,260.348512400219,0.039415918134414085
0.040538689088298,250.335058863659,0.12871033785534614,50.467547866913655,260.48331398283364,0.03973854933019147
0.0408694029091398,250.432248524825,0.12976035423651885,50.487141302604726,260.6672649912279,0.04005632826541951
0.0412144599196097,250.523375965142,0.1308559102447608,50.50551259457263,260.84856160278264,0.040387781786374186
0.0415538615314767,250.608054723837,0.13193351036243853,50.52258383232554,261.02178712850406,0.04071369572637015
0.0418913940463266,250.637344851983,0.13300517609708695,50.52848872215977,261.13689262790245,0.041037709536571446
0.0422267472581007,250.68154656307,0.13406992254446973,50.53739978711491,261.2670128720585,0.041359527391348544
0.0425496490861044,250.667001750978,0.13509513584838148,50.53446755299717,261.332794712948,0.04166929857942615
0.0428818983454711,250.697192568872,0.13615002724687073,50.54055402188459,261.44756409610534,0.04198793695677977
0.0432100524408166,250.783769089952,0.1371919164995927,50.558007848534324,261.62014890363446,0.04230254830258217
0.043548091624797,250.844058668548,0.1382651909087305,50.570162227579274,261.76783871898186,0.04262653332010677
0.0438871381212289,250.963041372025,0.13934166353490177,50.59414914060024,261.9770910320427,0.04295137836878847
0.044226111939437,251.062104443517,0.14041790540771246,50.614120255813035,262.1656051783866,0.0432760483273511
0.0445703150969787,251.160444226807,0.14151075043290737,50.63394555612429,262.35474436589294,0.04360561913300944
0.0449157166297586,251.221479394964,0.14260740029948354,50.64625024602475,262.50527217477696,0.04393622822125553
0.0452606439848535,251.265168014572,0.14370254465190985,50.65505787173772,262.63759132987394,0.04426627439795662
0.0456023166087786,251.308617311114,0.14478735523287206,50.663817249920584,262.76887244424984,0.04459309890382422
0.0459333079424813,251.326781560156,0.14583825271737813,50.66747916252746,262.8710520117514,0.04490960447282379
0.0462725367072439,251.353010169845,0.14691530404549938,50.67276685024075,262.9837515594054,0.04523388305048165
0.0466124557460991,251.354837519532,0.14799454699386463,50.67313524393765,263.0711037599791,0.04555871603754969
0.04695626950021,251.411134257595,0.14908615566316674,50.68448466633116,263.2164632331481,0.04588716358556235
0.0472985939606132,251.485535806452,0.1501730358249469,50.699484018580726,263.3804480515286,0.04621408125869255
0.0476395396065227,251.563323701397,0.15125553825070956,50.71516605820163,263.5476846244182,0.04653957597708714
0.0479889744857984,251.62795637363,0.1523649939924099,50.72819600492381,263.7033239519577,0.046873065314690966
0.0483307190679145,251.661176619735,0.15345003304062854,50.73489320653857,263.8241422472442,0.04719910774628609
0.048678429030812,251.697313793945,0.1545540121728281,50.742178460859314,263.94954362070956,0.047530732399806874
0.0490273667388099,251.727549711212,0.15566188939572143,50.74827402178033,264.0690886091656,0.04786341748073669
0.0493738937171866,251.756995099756,0.15676211255206743,50.75421021211081,264.18721821836965,0.0481936946189151
0.0497134482372014,251.771621411141,0.15784019815311442,50.75715887648603,264.28805687976006,0.04851722048293224
0.0500536629496257,251.784197118928,0.1589203798650616,50.75969413917589,264.38691845756097,0.048841270434556744
0.0503935154338341,251.816393088583,0.15999941150242325,50.766184846658334,264.506306380185,0.04916487056187409
0.0507440268753452,251.842961425519,0.16111228532922098,50.771541023384636,264.6224874284621,0.04949851025723379
0.05109200702398,251.872682841451,0.1622171223011365,50.777532860836516,264.7413637223351,0.04982963042664931
0.0514388266321233,251.885383449668,0.16331827455699147,50.78009330345307,264.8420720201014,0.050159537228240264
0.051776442695738,251.887758864877,0.16439020555896813,50.78057218715921,264.9296109775022,0.05048058478950355
0.0521154231227395,251.884464527917,0.1654664684146979,50.77990804882807,265.01152997483405,0.050802826094241645
0.0524550472320616,251.935480682148,0.16654477496179557,50.79019290552104,265.1507682207622,0.0511255751939313
0.0527944885919097,251.939681059901,0.1676225012793133,50.79103970167605,265.2407076774673,0.05144804657512718
0.0531376453805998,252.00351349463,0.16871202408340435,50.803908320517415,265.3943868293729,0.051773941969562406
0.0534784828832982,252.015817821146,0.16979418315447178,50.80638887274303,265.4932414208145,0.05209752964279765
0.0538332105332682,252.062043124271,0.1709204434431265,50.815707893853045,265.6313521592256,0.05243419332138748
0.0541831161593897,252.11971528907,0.17203139380606228,50.827334602276515,265.78034710864995,0.05276616952565541
0.0545314002200701,252.156042505468,0.17313719569872257,50.83465816910235,265.9064645772427,0.053096497847618385
0.0548904597870902,252.190710962126,0.17427720982401138,50.8416473299646,266.0335750408703,0.05343693195166883
0.0552440232963499,252.21714424126,0.17539977396591092,50.84697627903802,266.150634033463,0.05377204188461642
0.0555981634688525,252.230703547945,0.17652416901360668,50.84970983526571,266.2542674356673,0.05410758584715974
0.0559639208950144,252.241919385477,0.17768544884167073,50.85197094811216,266.35836620837244,0.054454018881289735
0.0563144834041369,252.242629039729,0.17879848480813465,50.852114014409366,266.44754238660266,0.05478594720250687
0.0566759682972919,252.224008590103,0.17994619934390177,50.848360131764764,266.5190485047716,0.055128101987343234
0.0570331454271798,252.216951491507,0.18108023673129586,50.84693742068781,266.60167756512203,0.05546606441648575
0.057389487907305,252.180514306336,0.18221162410569336,50.83959168415734,266.65302488257737,0.05580312331651923
0.0577504026810216,252.136365833336,0.18335752851224357,50.830691352000535,266.69734249074054,0.05614439131380436
0.0581060847189855,252.13035606554,0.18448681898277894,50.82947978281287,266.7806638953123,0.05648059752006877
0.0584596088518653,252.129068498471,0.1856092581046723,50.829220209291755,266.8684352230768,0.05681465200960454
0.0588156824881583,252.16697566686,0.18673979189990259,50.83686229443898,266.9983484416812,0.05715100282908106
0.059167572572225,252.155513216665,0.18785704291681435,50.83455146447967,267.07494284439866,0.05748329071328765
0.0595257154983999,252.124355029239,0.18899414670741965,50.828269973894585,267.1322376569271,0.05782136978457442
0.0598797178919567,252.082404313563,0.19011810430696252,50.8198127096143,267.17702756938536,0.058155427998516675
0.0602389733563837,252.075636571902,0.19125874040651825,50.81844833289544,267.2604141271503,0.05849432927734452
0.0605964243089459,252.066189142461,0.1923936471809032,50.816543731120134,267.34049889367657,0.05883141433009332
0.0609516701696183,252.094338713074,0.19352155278853808,50.82221868455572,267.4599096979413,0.05916630738758948
0.0613120354997203,252.089014103281,0.19466571271161195,50.821145243221444,267.54510468507084,0.05950591205839723
0.0616636352990952,252.075276193468,0.19578204207462727,50.81837568060315,267.6191540925807,0.059837145060664454
0.0620256743365907,252.075321148651,0.19693151601867548,50.81838474356804,267.71046292650874,0.06017809798570883
0.0623950539791339,252.075283018453,0.19810429638375013,50.818377056520134,267.8035339091948,0.060525844212566834
0.0627616669749695,252.114515723897,0.19926829264552814,50.826286369937634,267.9376429993159,0.06087086629574567
0.0631327769054884,252.126311236565,0.20044656667492564,50.8286643452915,268.0437453958668,0.06121999927867127
0.0634901424677507,252.109015875404,0.20158120233510846,50.825177600481446,268.1154532107378,0.06155608666150788
0.0638517101005494,252.073696401688,0.20272917956924433,50.818057194580305,268.1690329883025,0.061896011000272366
0.0642222957932989,252.049098274513,0.20390578914372398,50.813098212141824,268.2362700183331,0.062244293715506216
0.0645923353824073,252.033551295078,0.20508066483914317,50.80996394108773,268.31298696794886,0.06259194220252451
0.064969792039262,252.022500859295,0.20627908972465683,50.80773617323387,268.39635032933813,0.06294643447673148
0.0653434856312027,252.009058682811,0.20746556687906853,50.8050262304547,268.47620898778416,0.0632972688818781
0.0657133267464556,251.947443374907,0.2086398124199965,50.79260458438125,268.50374804433636,0.06364436532418578
0.066085891511104,251.89733135496,0.2098227055477552,50.78250200115994,268.5441910668205,0.06399389614796197
0.0664471789315649,251.867804915713,0.21096979310771855,50.77654947100775,268.60371001604784,0.06433273021241322
0.0668172422302652,251.818474388593,0.212144744081092,50.766604436740344,268.6442903898714,0.06467967576566142
0.0671842842653882,251.761272074348,0.21331010254260752,50.75507245018856,268.67567294440676,0.06502366993266213
0.0675448145855401,251.706874524546,0.2144547863090898,50.744105904148476,268.7083686942123,0.06536144611585448
0.0679097645882911,251.674689673528,0.21561350256782422,50.73761743818324,268.76585860208854,0.06570324688264499
0.0682776546855458,251.707657090786,0.2167815536266079,50.74426366950246,268.8936655833384,0.06604768304734887
0.0686553301347881,251.753604315825,0.2179806731779522,50.75352663007032,269.03783113275074,0.06640115735455228
0.0690314565174138,251.79309255768,0.2191748744427888,50.76148745962829,269.1747364779606,0.06675305772541634
0.0694039982582405,251.764682724433,0.2203576944699136,50.75576003724569,269.238158325726,0.06710148231196496
0.0697828117888854,251.735355090912,0.22156042742971113,50.74984758632786,269.30215599582937,0.06745564823410467
0.0701598652388699,251.670744191342,0.2227575721334119,50.73682202897455,269.3279296883727,0.06780804407903467
0.0705445799826055,251.645000043442,0.22397904144477243,50.731632008757906,269.39719087622933,0.06816747225580701
0.0709313716510259,251.616295438131,0.22520710499200725,50.72584516032721,269.4637844033074,0.06852871065526832
0.0713124834253107,251.592136673372,0.22641713487536147,50.720974753351804,269.53379674983034,0.06888451681375253
0.0716897122013317,251.513655033118,0.22761483623922815,50.70515285467659,269.5445965771473,0.06923657317719181
0.072071966439983,251.463291498054,0.228828493446946,50.69499956600768,269.5867454037894,0.06959319326841816
0.0724455605287654,251.416756795607,0.23001465467883012,50.68561816999437,269.6307846679891,0.06994161111799388
0.0728313270367589,251.430317047537,0.2312394633417095,50.68835191678346,269.74232069538215,0.07030125374910352
0.0732172511822959,251.443775132964,0.23246477250378947,50.69106506680554,269.853797175099,0.07066091396706323
0.0736066894804104,251.428862316398,0.233701239100303,50.688058642985844,269.935708511334,0.07102371810298685
0.0739940603572154,251.389937392145,0.23493114163415887,50.68021137825643,269.99129959273597,0.07138446567772602
0.0743700868035351,251.297499362451,0.23612502560122392,50.66157587147012,269.98651620354775,0.0717345240704399
0.0747516839313084,251.243637141404,0.23733659648190417,50.65071724770706,270.0245220947506,0.07208964320513016
0.0751341542769828,251.158464035906,0.23855093982942038,50.63354634963866,270.0290428207498,0.07244544846968133
0.0755139283156297,251.13361961649,0.23975672240212428,50.628537714684384,270.09770576585424,0.07279862019095755
0.075905310376674,251.096868594155,0.24099936044593995,50.62112870858166,270.1564543394053,0.07316245635856547
0.0762955800370521,251.094918875371,0.2422384666176404,50.6207356452748,270.252351355324,0.07352512665239737
0.0766865014028821,251.088682825677,0.24347964195415067,50.61947845765649,270.34379545343614,0.07388827075238405
0.0770807084977987,251.101348796294,0.24473124948051087,50.62203191733287,270.4564186662652,0.07425433361888742
0.0774608718499086,251.076619888948,0.24593826812345979,50.617046569611915,270.525233766674,0.07460722850801166
0.0778617546231363,251.023613338382,0.24721107092845773,50.606360449017814,270.5687523247482,0.07497922179841443
0.0782614714816072,250.981353239406,0.24848017195410285,50.59784081306425,270.62352325836696,0.07534999547054091
0.0786612118945621,250.954015825989,0.24974934776523466,50.592329590519384,270.6943628406684,0.07572065355727947
0.0790712051633149,250.890483722643,0.25105107639352475,50.57952151848484,270.72869663459943,0.07610067590893499
0.079470457717318,250.867201615994,0.2523187032524847,50.5748278457844,270.80373295467973,0.07647060396306697
0.0798778961917443,250.821463017611,0.25361232040878817,50.56560694435038,270.85655380319315,0.07684797566275038
0.0802880109655739,250.774010354679,0.25491443481569714,50.55604048750329,270.9081568479164,0.07722768240416146
0.0806881656228616,250.745933407674,0.25618492585258557,50.550380174987076,270.9781628117314,0.0775980286080636
0.081095362096209,250.690706221664,0.25747777465546356,50.53924637428746,271.0205598168642,0.07797475132145465
0.0815052197633112,250.627128826693,0.25877907274851303,50.5264291714613,271.0545480403603,0.07835379281015804
0.0819039797015736,250.556221349745,0.2600451355524962,50.512134224108586,271.07777301727754,0.07872243314216448
0.0823123495313511,250.39852250888,0.2613417097620397,50.48034213779022,271.0094132157648,0.07909981670508102
0.0827172682530895,250.288544860463,0.26262732670355915,50.458170643869344,270.9917295663613,0.0794738704576333
0.0831169281183301,250.168015721119,0.26389624677569806,50.43387196937759,270.9612127013165,0.07984292905911494
0.0835215778214451,250.148791452571,0.2651810095830882,50.42999635683832,271.04161320481734,0.0802164567211688
0.0839195340695254,250.184775128703,0.26644452067074315,50.43725066594652,271.1801648887927,0.08058366969906136
0.0843303584530166,250.197995332962,0.2677488880883277,50.43991585912514,271.29728196361685,0.0809626153084436
0.0847335453561017,250.183859379128,0.2690290065056229,50.4370660508322,271.3828247751939,0.08133437651568208
0.0851471653445951,250.123515921601,0.2703422499690894,50.424900809794764,271.420824288349,0.08171561405695627
0.085561469178003,250.085602248649,0.2716576646401595,50.41725741332763,271.48329379730905,0.08209733625757742
0.085985803326934,250.058611083064,0.2730049255630154,50.4118159943457,271.56010163585864,0.0824881489833281
0.086419344517145,250.061768920323,0.27438141884193534,50.41245261433712,271.6719430792151,0.08288728373625097
0.0868484099932256,250.031926272792,0.2757437017284913,50.40643633659487,271.7468015171274,0.08328214118606571
0.0872756985064928,249.951063818221,0.2771003427581146,50.390134465753356,271.7657175053972,0.08367520846046661
0.0877056645958238,249.855010933609,0.2784654850917405,50.37077020421558,271.768710720138,0.08407058297008427
0.088137181312335,249.767985501543,0.2798355506666636,50.35322587711107,271.78183172570914,0.08446722625062275
0.0885718352822503,249.696955174865,0.2812155770211447,50.33890616325279,271.81307275909256,0.08486659426203683
0.0890036055434383,249.646401918034,0.28258644760041657,50.328714626675655,271.86583179968534,0.08526315482085968
0.0894451509660341,249.599178388754,0.28398835431715824,50.31919436317281,271.9246145807342,0.08566853082736255
0.0898849704385085,249.532860746276,0.28538478114226445,50.30582472644924,271.9621145578915,0.0860721589643995
0.0903234933594145,249.474251379661,0.28677709141614105,50.29400907813966,272.00763726749676,0.08647443510826501
0.0907562407624963,249.379598578244,0.28815106442092575,50.274927073373995,272.0123534680658,0.08687125453855918
0.0911866036083759,249.297182718632,0.28951746645659343,50.25831203607621,272.02974609988075,0.08726573127984577
0.0916240096183017,249.191809692151,0.2909062305381079,50.23706883393764,272.0237624601866,0.08766650449684399
0.0920741556255491,249.129896295816,0.2923354441111184,50.22458709323651,272.0683211383339,0.08807878309906855
0.0925165616241805,249.081625147356,0.2937400831567731,50.214855629706975,272.1258006697524,0.08848380725410686
0.0929572419674317,249.030334407637,0.29513924324659563,50.204515416579625,272.17950746039816,0.08888708854578775
0.093408091389228,248.985460884115,0.29657069016079884,50.195468914237594,272.24271756896746,0.0892995076610273
0.0938477668245713,248.886146714055,0.29796665966801383,50.17544717755349,272.24355577674163,0.0897015415059607
0.0942942743913579,248.816628650256,0.2993843211925613,50.16143233589162,272.27861210533587,0.09010965721743994
0.094739564077115,248.71702674139,0.30079811594484007,50.141352591064226,272.2803694334254,0.09051649395433606
0.0951984019457411,248.665687233468,0.302254926177728,50.13100254626715,272.33826327683363,0.09093553584726564
0.0956661248461013,248.632071506717,0.30373994638637164,50.12422561575415,272.4177383002234,0.09136251150162154
0.0961286625529578,248.602749112093,0.305208503605641,50.118314220997945,272.500598891227,0.09178457447611352
0.096600794795342,248.537233116975,0.30670752347521085,50.10510619638216,272.54612737230997,0.09221520876900197
0.097072622616887,248.434236915559,0.3082055768086162,50.0843421621767,272.55039984077735,0.09264538021118268
0.0975440839455829,248.335573922767,0.30970246652722566,50.06445170282983,272.5592399921639,0.09307503276466861
0.0980238597669039,248.227716153148,0.31122575475991987,50.04270757647464,272.559954991603,0.09351207305789334
0.098506777537583,248.149494951759,0.312759018681826,50.02693818227462,272.5939020470355,0.09395178263467623
0.098993743281695,248.035914400158,0.3143051349193816,50.00404034307185,272.5899180349277,0.09439498230400008
0.099484790324336,247.910203206694,0.3158642092797668,49.97869696646951,272.5734977919755,0.094841697651274
0.0999732981171833,247.737312670121,0.317415221522057,49.9438422342964,272.50442888444087,0.09528590507077159
0.100463061885763,247.60035209096,0.3189702214872975,49.91623098153754,272.47504158601083,0.09573105657396402
0.100954406255993,247.45702199039,0.3205302398627778,49.88733563326262,272.43889871930605,0.09617744567144292
0.101457573315949,247.372394066618,0.32212779527813806,49.87027464383019,272.47019687397375,0.0966343693291212
0.101962401918569,247.293608137772,0.3237306260914566,49.85439140057483,272.5082584026086,0.09709259210746317
0.102479642807303,247.185691122156,0.325372865913187,49.83263533022665,272.51719245543086,0.09756186359451677
0.103000072373698,247.026073082686,0.3270252297864911,49.800456333469505,272.46977648839305,0.09803380588668321
0.103523424457819,246.838456118927,0.32868687265357527,49.762632753575694,272.3920183842394,0.09850817390921865
0.104050552078389,246.650029705536,0.330360502848885,49.724645988636055,272.3141014665481,0.09898573673265387
0.104580986481652,246.452901580433,0.33204463207924506,49.6849049586153,272.2271891489802,0.09946606530190646
0.105124040906307,246.287166031326,0.3337688298775247,49.65149267191532,272.1778681479015,0.09995758288353583
0.105663295496167,246.045191714683,0.3354809632003302,49.60271064968009,272.0431375122426,0.10044542229863948
0.106212526496946,245.792207335409,0.3372247716278035,49.55170899881845,271.89841866976394,0.10094204241321021
0.106760608558045,245.520550053455,0.33896493217179285,49.49694289077653,271.7324733906678,0.10143737790881417
0.107313425580052,245.227886749294,0.3407201262166651,49.43794196865767,271.5441313241178,0.10193674425788035
0.10787545562897,244.97177917036,0.3425045716219797,49.386310680744586,271.39822146460205,0.1024441773402195
0.108441886852666,244.659672637393,0.3443029907572145,49.32339000369842,271.19102917494746,0.10295532366856465
0.10902953698941,244.354156348412,0.34616877994137674,49.261797919839864,270.99597687651726,0.10348534190842344
0.109623974317346,244.002870812699,0.3480561184575735,49.19097875584011,270.75143525602897,0.10402119605521143
0.110223122500813,243.527266044025,0.34995841394008126,49.09509683447544,270.36960172148366,0.10456100638617966
0.110813258944896,243.091103744946,0.3518320971500448,49.00716651498111,270.02882117143525,0.10509241277186561
0.111401064957697,242.620305720299,0.353698381240688,48.91225363321228,269.64846615790236,0.10562144007601679
0.111993896565037,242.112996637227,0.35558062159399245,48.809980122064964,269.22817453966775,0.10615470711282127
0.112591235551511,241.654394059758,0.3574771728760474,48.717525842447216,268.8625608633979,0.10669174118016862
0.11320251237621,241.129712986645,0.35941797679446674,48.61175013810763,268.42620230528763,0.10724100756267704
0.113842609626286,240.570081085133,0.36145028556345804,48.49892834676282,267.95720691387174,0.10781584752562005
0.114481496179867,239.951397458647,0.3634787503710777,48.374201727663234,267.42139245016284,0.10838927090637754
0.115118847707886,239.230311740885,0.365502341472538,48.22883084696242,266.770229565294,0.10896098910432869
0.115740792702595,238.460437681785,0.36747701683073913,48.07362423664786,266.06003776728255,0.10951857237810939
0.116368875178676,237.730630706579,0.3694711786922963,47.92649515044633,265.3950767974208,0.11008134265924328
0.117010840991967,236.991652954141,0.37150942014949523,47.777517235554825,264.7222455743814,0.11065622549383088
0.117662328376014,236.174579829968,0.3735778925938444,47.61279529372155,263.96343079598887,0.11123929724806746
0.118320334288935,235.381509601355,0.3756670613673686,47.452912335633165,263.23192850282146,0.11182785810133568
0.118957907839267,234.500819189692,0.37769135738967274,47.27536514864192,262.39654602709203,0.11239781275032487
0.11956823249527,233.287361044809,0.37962913817248223,47.03073198663349,261.1811184684227,0.11294310427954037
0.120192381248122,232.536705054094,0.38161081046278733,46.87939973890535,260.48584536213775,0.11350043952794002
0.12083614472357,231.574560448842,0.38365475949733474,46.68543138648654,259.55713754953535,0.11407496456025885
0.121548811416646,230.787478551804,0.38591747624785105,46.526755676043685,258.8394222596205,0.1147105973628421
0.122290988093511,229.740031967394,0.38827388719689737,46.315590444626636,257.83516748132143,0.1153721211526354
0.123004679890879,228.422011815729,0.3905398586535408,46.04987758205097,256.51898825915333,0.11600784305918038
0.12371681834644,227.245738464235,0.39280089824994696,45.812740874389775,255.35985820981733,0.11664177875612257
0.124413714338364,226.008076262966,0.3950135430243057,45.56322817461394,254.1265805013098,0.1172617570039284
0.125147830604857,224.840490652793,0.397344362170421,45.32784291560307,252.97879029012168,0.11791443200560017
0.125851707473538,223.563243121854,0.39957917122848313,45.070349813365766,251.699058997061,0.11853982253075601
0.126573187186004,222.323060754813,0.4018698693155627,44.82032904817031,250.4631991394973,0.11918044743136993
0.127278672333598,220.9087133253,0.4041097846591736,44.53519660638048,249.02568106426756,0.11980647364303469
0.128020500014207,219.496200855492,0.40646508754510724,44.25043409246719,247.59621424023086,0.12046432668218623
0.128765857696219,217.987895811769,0.40883159818549536,43.94635979565263,246.05729418336546,0.12112487455067797
0.129517385917466,216.482884608351,0.41121770028795457,43.64294953704356,244.52118191869707,0.12179044938600095
0.130232227501497,214.903393496918,0.41348732231725294,43.324524128978666,242.89074112965238,0.1224231226730152
0.130935182466393,213.254372578225,0.41571920433079773,42.99208151177016,241.17687276351103,0.12304488555925104
0.131645792446328,211.633791852747,0.4179753910170914,42.665372437513795,239.4944900896231,0.12367302661690079
0.13232809510632,209.829085191411,0.42014170196256595,42.30154357458846,237.59536833269215,0.12427577445281915
0.133029904114554,208.078323724357,0.42236994556370894,41.94859006283037,235.75896317772535,0.12489537544385698
0.133752256841511,206.205700259263,0.4246634154717974,41.57106917226743,233.7861780425236,0.12553271304413527
0.134470069829364,204.085066306973,0.42694247170823063,41.14354936748576,231.52839942440204,0.1261656430734146
0.135221723916476,201.855528728203,0.42932897343481125,40.69407459160573,229.15078130490235,0.1268279833230133
0.136012005353079,199.210232928109,0.4318381169960258,40.160782958306775,226.30521619551507,0.12752388833561673
0.136844445823381,195.982965560568,0.4344811154892347,39.51016585701051,222.8021458735267,0.1282563943476817
0.137523126978407,193.058645676202,0.43663592815644214,38.92062296832233,219.6086743198096,0.12885320304587666
0.137982412732744,190.883340702086,0.4380941604264622,38.48208148554054,217.22188460264624,0.12925688104406982