File: example/data/02 processed data/test_ID_093.csv
Strain,Stress_MPa,Displacement(mm),Force(kN),True Stress (MPa),True Strain
0.00042357440158864924,31.172043570381,0.0013448487250439613,12.56856796757762,31.185247250082618,0.0004234847192755983
0.0005080148784362493,37.3463020020234,0.0016129472390350914,15.058028967215835,37.365274479095,0.00050788588256389
0.0005881648399445492,43.6263174089997,0.0018674233668239436,17.590131179308678,43.65197687499593,0.0005879919387980707
0.0006723771290375492,50.0041385204703,0.0021347973846942187,20.161668651453624,50.03776015956869,0.0006721511848098818
0.0007660653984972492,56.3769290357358,0.002432257640228766,22.731177787208676,56.42011745034362,0.0007657721201706356
0.0008555155375232493,62.7641650384606,0.0027162618316363164,25.306511343507314,62.81786075685067,0.0008551497926910871
0.0009525561708157493,69.0498795115219,0.0030243658423400035,27.84091141904563,69.11565340034467,0.0009521027770855622
0.0010500077473585491,75.2761684224299,0.003333774597863393,30.351351107923737,75.35520898246492,0.0010494568748036824
0.0011434796486963494,81.3908771126717,0.0036305478846109093,32.81680165182923,81.48394592423959,0.0011428263737998815
0.0012426444837223493,87.453839858748,0.003945396235818459,35.26138823104719,87.5625138904288,0.0012418730400865418
0.0013364243628452492,93.3765160756462,0.004243147352033666,37.649411281700544,93.5013067266473,0.0013355321426412542
0.001432419459112049,99.2593285654305,0.004547931782680755,40.021361277581576,99.401509559166,0.0014313945249988694
0.0015273426382768495,104.99678315689,0.004849312876528997,42.334702968858046,105.15714922068744,0.0015261774367999487
0.001619674467862449,110.720020655026,0.005142466435463276,44.642312328106485,110.89935104556216,0.0016183642097751497
0.0017224178211482492,116.339933296315,0.005468676582145691,46.90826110507421,116.54031927073578,0.001720936160687984
0.0018165155711672492,121.934183451144,0.005767436938456016,49.16386276750126,122.15567879404057,0.001814867702042032
0.0019147558972389491,127.458308961235,0.0060793499737336635,51.39119017316995,127.70236050997065,0.0019129250888276009
0.0020169805292906493,132.971311603416,0.006403913180497811,53.61403283849734,133.23951214987434,0.002014949155099073
0.002114407887047349,138.42244773186,0.006713245041375333,55.81193092548595,138.71512924708864,0.0021121756726783297
0.0022176638558775493,143.818188612775,0.007041082742411219,57.98749364867088,144.13712901147932,0.0022152084688672885
0.0023247137233030494,149.153376500287,0.007380966071487181,60.138641404915724,149.50011540151422,0.002322015756879477
0.002418738475707649,154.476619698095,0.007679494660371786,62.2849730622719,154.85025824175605,0.0024158180360393518
0.002520881685836649,159.712247706586,0.00800379935253136,64.39597827529548,160.11486338683335,0.0025177095934609695
0.002622484337596649,164.91776614824,0.00832638777186936,66.49484331097037,165.35026040695516,0.0026190516257251373
0.002721961607338149,170.040960174426,0.008642228103298623,68.56051514232857,170.50380513969571,0.0027182637785543727
0.0028257293117692492,175.122593346696,0.008971690564867366,70.60942963738782,175.6174423918688,0.0028217444437048924
0.0029277092913000493,180.216168722895,0.009295476999877657,72.66315922907127,180.74378927450752,0.002923431897063731
0.003027432828587949,185.238562703502,0.009612099230766738,74.68818848205201,185.79936000935103,0.003022859382032013
0.003135975458766249,190.213848896584,0.00995672208158284,76.69422387510268,190.81035485864118,0.0031310685436943897
0.0032453954033256492,195.201031549106,0.010304130405558935,78.70505592059955,195.83453607961988,0.0032401404741427137
0.0033532207239166494,200.041912287756,0.010646475798435362,80.65689903442322,200.7126969736912,0.003347611215753156
0.003465773291061749,204.764342908986,0.011003830199121052,82.56098306090317,205.47400969960177,0.003459781339315594
0.0035804421528383493,209.281029326027,0.011367903835261758,84.3821110242541,210.03034794521528,0.003574047628770204
0.003695147064857749,213.58257881635,0.011732091930923352,86.11649577875232,214.37179785556802,0.0036883367804548045
0.003818057849646649,217.679685850568,0.01212233367262811,87.76844933494903,218.5107994838384,0.0038107875664736093
0.003940948322068349,221.520106876401,0.012512510922567008,89.31690709256489,222.39310616989994,0.003933203127501841
0.00407111550634155,225.069171416961,0.012925791732634419,90.74788991531868,225.98545401071604,0.004062850938688227
0.004218076033080449,228.366898427329,0.013392391405030426,92.07753344589906,229.33016736833426,0.0042092048877314745
0.004376209371240249,231.479249975698,0.013894464753687791,93.33243359020143,232.4922516386893,0.0043666616122034424
0.004554723816595849,234.274030085225,0.014461248117691821,94.45928893036273,235.3410835896641,0.004544382451557783
0.004763099957739049,236.742417902029,0.01512284236582148,95.4545428980981,237.8700457027332,0.004751792289289376
0.004997345085894649,238.88762779725,0.01586657064771551,96.31949152785121,240.0814317101036,0.004984899801972317
0.005264262860124349,240.648228220645,0.016714034580894807,97.02936561856406,241.91506375082164,0.005250455065767962
0.005555800513230249,242.094392344255,0.01763966662950604,97.61245899320362,243.4394204934914,0.005540423979903171
0.0058707940396208495,243.201169738525,0.018639771075796195,98.05871163857329,244.62895371625473,0.005853628080732343
0.006208333666017249,243.993822508382,0.019711459389604766,98.37830923537962,245.50861757096104,0.006189141356443087
0.006560671151054549,244.599977043862,0.02083013090459819,98.62271074408517,246.20471705680228,0.006539243616357689
0.006923071486656349,245.092230115075,0.021980751970133907,98.82118718239825,246.78902114498572,0.0068992170612292595
0.007292803174169849,245.522777012771,0.02315465007798927,98.99478369154927,247.31332630030076,0.007266339271234136
0.007665581754491649,245.881877365683,0.024338222070510986,99.1395729538434,247.76670499857755,0.007636350470833225
0.00804121842771435,246.23941860695,0.02553086850799306,99.28373358232224,248.21948355748188,0.008009060110486205
0.00842144842491755,246.550775736669,0.02673809874911322,99.40927277702495,248.6270903786588,0.00838618586437213
0.00880590642792765,246.806524874152,0.027958752908670288,99.51239082925808,248.97988003799574,0.008767360556198481
0.00919255672785995,247.078594929349,0.02918636761095534,99.62208947551352,249.34987892947697,0.009150562339275284
0.00957669311125085,247.314826741212,0.030406000628221446,99.71733814205668,249.68328493877476,0.00953112726818707
0.00996215003946065,247.484534059046,0.03162982637528756,99.78576413260735,249.95001211978825,0.009912854942500122
0.01034651097122405,247.734532194972,0.03285017233363636,99.8865633810127,250.2977202502783,0.010293352184152574
0.01073106058389745,247.864212959699,0.0340711173538744,99.93885066535064,250.5240588455496,0.010673891380397474
0.01111501538850055,248.06333395281,0.035290173858489246,100.019136249773,250.82056172701823,0.011053697552372104
0.01149268356027005,248.336604933735,0.0364892703038574,100.12931910928195,251.1906589506702,0.011427144342231594
0.01187156739420995,248.539065290191,0.03769222647661659,100.21095112500501,251.48961355387746,0.011801653122041966
0.01224967831401335,248.786410198843,0.038892728646992385,100.31068059217348,251.83396369267697,0.012175258137060833
0.01262761814597005,249.000636144227,0.04009268761345491,100.39705649335232,252.14492109555994,0.012548554669158208
0.01300583047356555,249.167180416676,0.04129351175357062,100.46420714400377,252.4078065247516,0.012921980900096781
0.01338075702891145,249.426599337797,0.04248390356679385,100.56880485299975,252.76411606008372,0.013292025354532586
0.01375116536575705,249.611857249278,0.043659950036278636,100.64350084290889,253.04431117556658,0.013657476006141436
0.01412348332940605,249.74639710746,0.04484205957086421,100.69774731372789,253.27368618358642,0.014024676185966988
0.01449339853658765,249.935422810851,0.046016540353665786,100.77396247733513,253.5578365020592,0.014389373152248182
0.01486373043608375,250.102522974209,0.047192344134565904,100.84133726320108,253.81997945708207,0.014754347752647322
0.01522829817270305,250.302511220926,0.04834984669833218,100.92197252427735,254.1141924951746,0.015113511510152642
0.01558658846854065,250.521104248548,0.049487418387616555,101.01010923301456,254.42587360315449,0.015466365235927402
0.015947836811319147,250.673120080612,0.050634381875938286,101.07140201650276,254.6708140926418,0.015822006117116212
0.01630678561937695,250.888933684954,0.051774044341521816,101.15841806177345,254.98012574082864,0.016175257927030985
0.01666261506640985,251.087722710026,0.05290380283585126,101.23856979668248,255.2715007814446,0.016525316762689146
0.017015833513856847,251.292247978352,0.05402527140649548,101.32103438487152,255.56819503327446,0.01687268578874675
0.017366673050130548,251.529565354157,0.05513918693416449,101.4167207507961,255.89779707810408,0.017217595891561504
0.01771992822272285,251.729807884578,0.05626077210714504,101.49745853906185,256.1904420118126,0.017564760651940202
0.018077844581824848,251.873579515353,0.05739715654729389,101.55542726059033,256.42691094009945,0.017916383359824876
0.01843088382285195,252.111510158102,0.05851805613755493,101.65136089574673,256.7581481122297,0.018263093628864784
0.018785610959848747,252.29452760581,0.05964431479751977,101.7251535306626,257.03403444871157,0.01861134050541447
0.019140842727815948,252.468414243984,0.06077217566081563,101.79526462317436,257.30087245476915,0.01895996130173629
0.019498571129291948,252.669383230036,0.06190796333550193,101.87629531835051,257.5960751711412,0.0193109094907255
0.019854461201260748,252.834145859378,0.06303791431400287,101.94272761050121,257.8540315986969,0.019659932018889714
0.02021231174191665,253.036591332459,0.06417408978058536,102.02435362524749,258.15104579858263,0.02001075440281573
0.020565282703902548,253.272730263936,0.06529477258489058,102.11956484241901,258.4813555630031,0.020356672514094655
0.02092243437781825,253.414799030306,0.06642872914957294,102.1768469690194,258.7168535333856,0.020706566049648285
0.021276840434234147,253.610971114146,0.06755396837869342,102.25594355322366,259.00701127891284,0.02105364878965782
0.02163254431708435,253.802018314353,0.0686833282067428,102.33297378434715,259.2924017233037,0.021401881451468416
0.02198242080888115,253.994026273903,0.06979418606819764,102.4103913936377,259.577429842398,0.021744290859488875
0.022331918684779347,254.145422960716,0.07090384182417442,102.47143453776069,259.8209778803835,0.022086212718129813
0.022676091668044247,254.345522066685,0.07199659104604048,102.55211449728739,260.1130844404257,0.022422810897473947
0.02302283665765335,254.533201387503,0.07309750638804938,102.6277867994412,260.393277706997,0.022761809943842453
0.02336696387930825,254.715884225059,0.07419011031680368,102.70144451954378,260.667821091232,0.023098136116703975
0.02370768180031185,254.894607631627,0.07527188971599012,102.77350579707202,260.93756788197294,0.023431018871975382
0.02404925277639565,255.068501711488,0.07635637756505619,102.84361989007198,261.20270858444405,0.023764623875073203
0.02439203916376205,255.258794252694,0.07744472434494451,102.92034584268622,261.4850767590004,0.02409930409453059
0.024733427390062547,255.45804394322,0.07852863196344859,103.0006833179063,261.77639692429705,0.024432507927122912
0.025078988002569948,255.622524992248,0.07962578690815958,103.0670020768744,262.0332792297152,0.024769671087211134
0.025422496280526747,255.767113629606,0.08071642569067242,103.12530021545714,262.2693521245357,0.025104719155991592
0.02576462746426805,255.949780051677,0.08180269219905105,103.19895131683617,262.5442307842698,0.025438312500990243
0.026109507661184347,256.151181343475,0.0828976868242603,103.28015631768913,262.8391625751839,0.025774473666297808
0.02645570312911045,256.354418386952,0.08399685743492567,103.36210149361904,263.13645477563296,0.02611180323749868
0.02679947075509975,256.517808275139,0.0850883196474417,103.42798029653605,263.3923497761709,0.026446654583375185
0.027144947864374748,256.692344294327,0.08618520946938982,103.49835321947263,263.66024459738065,0.026783058148536196
0.027488737457602348,256.866350171468,0.08727674142788745,103.5685123891359,263.92728183302404,0.02711770621635659
0.027832822041239547,257.035479742344,0.08836920998093556,103.6367054321131,264.1895025082973,0.02745252933467754
0.02817728717554375,257.238514265618,0.0894628867823514,103.71856895189718,264.4867977546905,0.0277876105057116
0.02852186342615425,257.384640783925,0.09055691637803974,103.77748716407858,264.7257303563539,0.028122687469917706
0.02886246581333795,257.595756854466,0.09163832895734798,103.8626091637207,265.03060558033894,0.028453789817159996
0.029207775808893048,257.756007882752,0.09273468819323542,103.92722237832561,265.2844875743867,0.028789356594048413
0.029546484380968848,257.902269617766,0.09381008790957608,103.98619510988327,265.52237499884376,0.029118398851962535
0.02988497695408995,258.129684906311,0.09488480182923559,104.0778889542246,265.8438845909026,0.029447123145559383
0.03022246375902385,258.318875749496,0.09595632243490071,104.1541707021968,266.12590861010693,0.029774763152370067
0.030560906482053847,258.46988446801,0.09703087808052095,104.21505741750163,266.36895843566407,0.03010322341749065
0.030900134943506248,258.67100185006,0.09810792844563233,104.2961479459442,266.6639707131988,0.030432338018928792
0.03123579491063135,258.826223220169,0.09917364884125453,104.35873320237215,266.91086604616754,0.030757883939767607
0.03157045959765115,259.006642205792,0.10023620922254241,104.43147813737532,267.18360093907324,0.031082359095128933
0.031910161012615755,259.211369525307,0.10131476121505502,104.5140241926038,267.4828460631602,0.03141160998766505
0.03225018401779025,259.341430972984,0.10239433425648403,104.56646496830716,267.7052398452998,0.031741064052673684
0.032593492824623455,259.532702705779,0.10348433971817947,104.6435857309701,267.9917799891749,0.03207359170486053
0.032934987559752354,259.706608260847,0.10456858550221372,104.71370445077352,268.2600421731035,0.03240425259042426
0.033275215145333555,259.86124567738,0.10564880808643402,104.77605425711961,268.5081845352292,0.03273357783352932
0.03362563511122385,260.017430276972,0.10676139147813572,104.83902788767512,268.7606815100235,0.0330726555103364
0.033975639109873855,260.198843181222,0.10787265417384949,104.91217357066871,269.0392651739538,0.03341121595364527
0.03432659315959455,260.341063142039,0.10898693328171269,104.96951665887013,269.2776848992521,0.033750580334356683
0.03467195166082935,260.489510122257,0.11008344652313318,105.02937048129402,269.521189825369,0.03408442155943326
0.03501683988704885,260.664844559443,0.1111784666413801,105.10006532636743,269.79250368556353,0.03441769700724003
0.03536099349377395,260.806433743465,0.1122711543427323,105.1571540853651,270.02880835020204,0.034750151889963415
0.03570661531724955,260.927010823295,0.11336850363226732,105.20577076395256,270.24383122464224,0.0350839138832597
0.03603860406292835,261.079958101333,0.11442256789979752,105.26743910645746,270.48891534011284,0.03540440575206175
0.03637295506433165,261.233587169246,0.11548413232925298,105.32938234663997,270.73542469664716,0.03572707429039499
0.03670809920336835,261.408021162277,0.11654821497069451,105.3997141326301,271.0038127356581,0.03605040380157494
0.03704940666692865,261.542728646027,0.11763186616749846,105.45402819007808,271.2327315604118,0.036379571957134045
0.03738593589615305,261.652957684545,0.11870034647028592,105.49847253840855,271.43509838757825,0.036704025773815305
0.03772489247772645,261.845466785449,0.11977653361678148,105.57609220789304,271.7235588657102,0.03703071346678413
0.03806088634785315,262.017189268411,0.12084331415443375,105.64533071302333,271.98979573033995,0.03735444039129465
0.03840412348282915,262.180699802608,0.12193309205798254,105.71125816041155,272.2495197726419,0.03768503795636534
0.03874594087521675,262.295474727097,0.12301836227881319,105.7575354099655,272.45835968270995,0.038014159478530006
0.039084517539792654,262.495656473316,0.12409334318884167,105.838248690041,272.75517256286673,0.03834005389036851
0.03942032806588315,262.651819826577,0.125159541609179,105.90121375407585,273.0056407312419,0.03866318090132763
0.03976320717509025,262.812359736159,0.12624818278091154,105.9659434456193,273.26262204452223,0.038993001820456404
0.04010754318930595,262.942639666145,0.12734144962604638,106.01847231338967,273.488622942865,0.03932411471994914
0.04045080270581635,263.137757031523,0.1284312985909669,106.09714363511009,273.7818905256562,0.03965408337504811
0.04079522893614875,263.265403260847,0.12952485187227228,106.14861059477352,274.0053756578408,0.03998506417043733
0.04113736533669745,263.424166952249,0.13061113494401438,106.2126241151468,274.26074314667886,0.04031373610205493
0.04148005982660115,263.501293317915,0.13169918994945864,106.24372146578332,274.4313427291289,0.0406428359058461
0.04182583191985535,263.688472263435,0.13279701634554072,106.319192016617,274.7174619835289,0.040974781490792714
0.04216828108772925,263.857659351049,0.13388429245354036,106.38740825034296,274.98408329771434,0.04130342845655782
0.042507579847855255,264.023522896721,0.13496156601694043,106.4542844319579,275.2465238779654,0.04162894550165838
0.04285076169116555,264.112253885744,0.1360511683694506,106.49006076673199,275.4296651367186,0.0419580801540318
0.04319175119813705,264.264242280494,0.13713381005408512,106.55134248749519,275.6782776836373,0.0422850049486145
0.04353600840367825,264.392299428531,0.13822682668167843,106.60297512958368,275.9028847983193,0.042614954274376164
0.04387976222370745,264.547260136347,0.13931824506027116,106.66545528697512,276.1555310080632,0.042944312544035496
0.044223223339995954,264.653808385034,0.14040873410448715,106.7084155408457,276.3576528610258,0.043273282064945615
0.04456264107049925,264.780154460922,0.14148638539883512,106.75935827864376,276.57945744675544,0.04359827251923192
0.04490212104961015,264.862684179408,0.14256423433251222,106.79263426113731,276.75558048595644,0.0439232169626629
0.045243721098232055,264.983544090254,0.14364881448688677,106.84136497719041,276.97238565469456,0.04425008415515743
0.04558317685855695,265.128024963851,0.1447265865259183,106.89961966542471,277.2134026159381,0.04457479373646135
0.045919390277432054,265.265124856245,0.14579406413084675,106.95489834203798,277.44593765151063,0.04489629792876228
0.04626142933790705,265.389577351041,0.14688003814785489,107.00507758793972,277.6668785306832,0.045223266860238545
0.046601637087094555,265.539442816902,0.1479601977515252,107.06550334377489,277.91401556336456,0.045548379150327514
0.04694511190761255,265.65822695039,0.14905073030666985,107.11339710639724,278.12958214375396,0.04587650635719756
0.04728907293383875,265.827238517369,0.15014280656493803,107.18154257020319,278.39796218741776,0.046204990183704296
0.047633580018715954,265.975300796751,0.15123661655942314,107.24124128125001,278.6446565702551,0.046533887374726905
0.04798027995956545,266.13071722974,0.1523373888716203,107.30390518703118,278.8997435482629,0.046864768889335884
0.04832777537465215,266.237527688466,0.15344068681452058,107.3469711639895,279.1041951228969,0.04719629976084613
0.04867533733579375,266.363204200108,0.15454419604114517,107.39764393348355,279.32852301839114,0.04752778421331797
0.04902677799519285,266.481407319175,0.1556600201347373,107.44530343109136,279.5461321156588,0.047862856252497234
0.04937598259671965,266.634966910495,0.15676874474458488,107.50721865831157,279.8003303963445,0.048195685212988934
0.049730064904887954,266.753315955421,0.15789295607301923,107.55493699322575,280.01897567147813,0.048533050075472185
0.05007800043106335,266.932050368181,0.15899765136862612,107.62700270845059,280.2994737015834,0.04886444753517662
0.05042730426409035,267.020204548274,0.16010669103848685,107.6625464738641,280.4853136476895,0.04919703782710897
0.050778626220867054,267.17821356504,0.1612221382512529,107.72625570942411,280.7451562060182,0.049531438139761366
0.05112858738614765,267.275951809702,0.1623332649510188,107.76566376967185,280.9413936680201,0.04986443206665659
0.051477932819871154,267.386886682874,0.16344243670309092,107.8103927105348,281.15141087244945,0.050196729558917706
0.05183004845801145,267.471185928274,0.16456040385418635,107.84438216628008,281.3342304560582,0.05053155036934021
0.05218180582699415,267.59864205063,0.16567723350070643,107.89577247481402,281.5624224296833,0.05086591861117641
0.05253503816895325,267.670624006051,0.16679874618642657,107.92479559923977,281.73271045491646,0.05120157644209403
0.05288843218701515,267.772556595131,0.1679207721937731,107.96589481915682,281.93462729615624,0.05153727519947589
0.05324084093636215,267.858971484072,0.16903966997294984,108.00073730237784,282.120008378233,0.05187192583762329
0.05359160771841005,267.997843701831,0.1701533545059519,108.05673058057826,282.3602790108793,0.05220490607581248
0.05394114828209795,268.10568871142,0.171263145795661,108.10021368844455,282.5676174214767,0.0525366120157536
0.05428944738417755,268.225795354673,0.1723689954447637,108.14864068700416,282.78762555865967,0.05286703043010009
0.054636054802196854,268.336539667497,0.17346947399697502,108.1932927939348,282.99738955420224,0.053195735660114984
0.05498498827800955,268.458211941688,0.1745773377826803,108.24235105488859,283.2193835784371,0.05352653770642485
0.05533746876192745,268.603781490353,0.17569646331911964,108.30104469691034,283.46763485791104,0.053860591382458925
0.05568954990245485,268.770197518767,0.17681432094029415,108.36814363956687,283.737888845781,0.05419415522667215
0.05604497234524315,268.878698428664,0.177942787196147,108.41189120643732,283.9479976463235,0.05453077182539707
0.056403760850300355,268.992340481342,0.17908194069970362,108.4577116820771,284.1645201244142,0.05487046149726369
0.05676511035681305,269.155046562895,0.18022922538288144,108.52331477415926,284.4336624841309,0.05521245925708143
0.05712468386910655,269.265056353047,0.1813708712844133,108.56767072154855,284.64673757421195,0.05555266007241609
0.05748483850821955,269.352403594723,0.18251436226359707,108.60288912939232,284.83608301716646,0.05589329472745211
0.05784104737004505,269.421954526022,0.18364532539989303,108.63093206489206,285.0056025602917,0.056230083368455745
0.05819998050262265,269.458993710718,0.1847849380958269,108.64586626416151,285.1415018909381,0.056569333062854214
0.05856126265917285,269.588691391212,0.1859320089428738,108.6981603689367,285.3761455577155,0.05691068678068651
0.05891901157234485,269.677269200295,0.1870678617421949,108.73387494155894,285.5663873451055,0.05724858737029705
0.059278103950557354,269.725126253162,0.18820798004301958,108.75317090527491,285.71392032527416,0.05758764210606372
0.05963693856237655,269.795571421999,0.18934727993554554,108.78157439735,285.885353339294,0.05792633866354706
0.06000037584688785,269.899416055685,0.19050119331386892,108.8234445536522,286.09348245988167,0.05826926269644866
0.060368256778866154,270.038009475947,0.19166921527290004,108.87932542070183,286.33973337204486,0.05861625984591505
0.060736947105668855,270.197981081384,0.1928398070604986,108.94382597201404,286.60898156638257,0.05896389967994183
0.06110058140324305,270.285647752794,0.1939943459552967,108.97917317392654,286.80025797544187,0.05930665382228153
0.06146470736136035,270.376225656025,0.1951504458723191,109.01569418450927,286.99482124344166,0.05964975371524288
0.061829846843501055,270.48287794763,0.19630976372811584,109.05869638848442,287.20679286492134,0.05999369043849873
0.06220194108748035,270.618705108267,0.1974911629527501,109.11346189965327,287.45171386058166,0.060344056426333774
0.06256720513998705,270.727608400823,0.19865087631945888,109.15737170721182,287.6662782126954,0.06068787171257638
0.06293197049614585,270.771098668493,0.19980900632526305,109.17490698313637,287.81125746110763,0.06103109966008259
0.06329802068020854,270.851041525172,0.2009712156596621,109.20713994294934,287.99537635288834,0.06137541818554602
0.06366436767010734,270.949608705003,0.2021343673525908,109.24688222985722,288.19944421367006,0.06171989723748241
0.06403551963067604,271.068198244623,0.2033127748273964,109.294697532232,288.42619117456854,0.06206877347378667
0.06440267309220135,271.133930839948,0.20447848706773927,109.32120091466703,288.5956807520367,0.062413771478823626
0.06476722562931395,271.199059173396,0.20563594137307176,109.34746065871326,288.763869829337,0.06275620778782255
0.06513316141177865,271.274199530964,0.2067977874823972,109.37775725088468,288.9431457558653,0.06309982553472927
0.06550114696254625,271.354534233124,0.20796614160608431,109.41014820279561,289.12856745888115,0.06344524901071483
0.06587139693473705,271.451071849099,0.20914168526779012,109.44907216955671,289.3319331512308,0.06379267769180144
0.06624127486764934,271.549589876273,0.21031604770478665,109.48879463811328,289.5373808994646,0.06413963678220452
0.06661228290466474,271.660086549757,0.21149399822231055,109.53334689686203,289.7559850889151,0.06448753506092642
0.06698890712112905,271.739081060327,0.21268978010958473,109.56519748352385,289.9425851226582,0.06484057594048431
0.06736854110667985,271.800387649633,0.2138951180137085,109.58991630033205,290.1111832378188,0.06519631203320801
0.06775649583074765,271.874809149595,0.21512687426262378,109.61992304911672,290.2960935222249,0.06555971438353958
0.06814330863398764,271.95933089519,0.21635500491291074,109.65400221694063,290.4915395162737,0.06592191565034065
0.06852994992393005,271.994992992536,0.2175825910084779,109.66838117459052,290.6347962418742,0.06628382526156831
0.06891664345002084,272.013974735548,0.21881034295381616,109.67603461337296,290.76026484582076,0.06664565280992281
0.06930464148049714,272.037368851909,0.2200422367005784,109.6854671210897,290.89082116948833,0.06700856944298547
0.06969228064689384,272.135872933736,0.22127299105388792,109.72518396688234,291.10164256432137,0.06737101893193073
0.07008154183095945,272.231096419661,0.22250889531329623,109.76357807640733,291.30947139108343,0.06773485288883835
0.07046757233519364,272.336810745997,0.2237345421642398,109.806202092786,291.5277246567765,0.06809553651517
0.07085733647860215,272.433344641129,0.2249720433195618,109.8451245593032,291.73724581035646,0.06845957669058521
0.07124665307944275,272.535799633526,0.22620812352723071,109.88643441223769,291.9530632017443,0.06882306661173276
0.07164323098400975,272.617806651653,0.22746725837423096,109.91949964194647,292.1490271439515,0.06919320033819631
0.07203566464772665,272.659126854537,0.2287132352565321,109.93615994774933,292.3003082797724,0.06955933135613974
0.07243262921404374,272.695398795024,0.22997359775458887,109.95078479415368,292.4474435043198,0.06992955326334863
0.07282397136221104,272.73253425264,0.23121610907502005,109.96575781066446,292.5940005165975,0.07029439740591231
0.07321972079893314,272.754167049829,0.23247261353661272,109.97448015449105,292.72515100796306,0.07066321509835143
0.07361716202625214,272.823805280249,0.23373448943335054,110.00255828899641,292.9083195581838,0.07103347260141477
0.07401780816012135,272.89658237057,0.23500654090838527,110.03190201181383,293.0957892520276,0.07140657710388242
0.07441601048805614,272.941341008168,0.23627083329957824,110.04994869449334,293.252546703256,0.07177726791040243
0.07481827369625385,273.022464482273,0.23754801898560596,110.08265767925248,293.44953395513346,0.07215159956503411
0.07521863242602954,273.0994793477,0.23881915795264377,110.11371007299266,293.6416487004947,0.07252401990187853
0.07562670688994655,273.152210377397,0.24011479437558028,110.13497122416648,293.8098125279494,0.07290347486440335
0.07603593906666065,273.202415329488,0.24141410653664755,110.15521386084957,293.97561753434553,0.07328386180137757
0.07644552445662464,273.22156779356,0.24271454014978322,110.16293613436339,294.10813383639993,0.07366443222843899
0.07685252787219594,273.249666713436,0.2440067759942221,110.17426561885739,294.24959434059855,0.07404246017489809
0.07726748286979905,273.341577991922,0.24532425811161196,110.21132424634295,294.4619936870167,0.07442772654879232
0.07768368609812934,273.422165586377,0.24664570336156064,110.2438171644272,294.6626072700599,0.07481400280367823
0.07810730449488724,273.483585208034,0.24799069177126698,110.26858155587932,294.84465087223134,0.07520700788075554
0.07852742717555894,273.557954303508,0.24932458128239962,110.29856717517441,295.0397566383716,0.07559661737727022
0.07894573177066455,273.60012254606,0.25065269837185994,110.31556941057138,295.1996844330022,0.07598439008128992
0.07936666001972205,273.667595229861,0.2519891455626175,110.34277439667994,295.3876782188843,0.07637444321353833
0.07979627347176454,273.714105431141,0.2533531682728524,110.36152730983603,295.5554710412037,0.07677238766788969
0.08022264833108014,273.754980774339,0.25470690845117944,110.37800824821349,295.7163303258804,0.07716717575103996
0.08064789882068014,273.762761652428,0.2560570787556594,110.38114549825897,295.84115315504306,0.07756076757971325
0.08107090294142325,273.817061564892,0.2574001168390188,110.40303922296445,296.01565798672505,0.07795212664620897
0.08149891838922355,273.851802769076,0.25875906588578473,110.41704687649145,296.1704284936947,0.07834796630804786
0.08193624679650255,273.902397690592,0.26014758357889556,110.43744674884671,296.34493214592214,0.0787522570584926
0.08237386284198064,273.93330070388,0.26153701452328854,110.4499068438044,296.4982448439124,0.07915665017156163
0.08280831651810165,273.965576458323,0.2629164049449727,110.46292042799585,296.65220462874805,0.079557959295656
0.08324961252000214,273.993213759083,0.26431751975100676,110.47406378766227,296.8030426376368,0.07996542393645813
0.08369912211180955,274.079187806224,0.2657447127049953,110.50872852346953,297.01937521472274,0.080380301862337
0.08415256990713074,274.13505460033,0.2671844094551401,110.53125401485306,297.2042239465794,0.08079864026030374
0.08461075397581375,274.206498643707,0.26863914387320864,110.56006025314265,297.407317239019,0.0812211705294706
0.08506525395793124,274.281031940949,0.2700821813164317,110.59011207859064,297.6128175788493,0.08164012708068238
0.08552384493080764,274.336962771086,0.2715382076553142,110.61266338930189,297.7993146339091,0.08206267686676066
0.08598499988429614,274.363314489109,0.2730023746326402,110.62328840200875,297.9544440537101,0.08248740915511604
0.08644914089957954,274.399234762973,0.27447602235616503,110.63777145643071,298.120812871734,0.08291470958612301
0.08691783800799714,274.417168463155,0.2759641356753909,110.64500232434409,298.2689154582488,0.08334601927310377
0.08738647153340344,274.422363261127,0.2774520471185559,110.6470968668864,298.4031652963747,0.08377708453899729
0.08785979215080944,274.440368751704,0.27895484007881993,110.65435668068706,298.55264250802026,0.08421227262117296
0.08833635169640494,274.48500879132,0.28046791663608567,110.67235554466022,298.7320130633008,0.08465024743751531
0.08881511104026424,274.490393227246,0.28198797755283894,110.67452654922558,298.8692879812096,0.08509005087771751
0.08929567067452604,274.559095993806,0.2835137543916202,110.70222750470259,299.0760346103645,0.08553131368775797
0.08977585084342385,274.570242281144,0.2850383264278707,110.70672168775725,299.2200193982187,0.08597203366590318
0.09025854664812755,274.592602300021,0.28657088560780497,110.71573724736847,299.3769315039482,0.08641486687362435
0.09074228584900475,274.610658491,0.28810675757059007,110.7230175035712,299.5294573609737,0.0868584606601115
0.09122850111652915,274.588641618328,0.28965049104498003,110.71414030050984,299.63895181679186,0.08730412682436683
0.09171772980362815,274.56124822043,0.29120379212651937,110.70309528247738,299.7433825992583,0.08775235471780754
0.09220988638596525,274.59182762976,0.29276638927543963,110.71542490031925,299.9119088580147,0.08820306250410956
0.09271025657294145,274.562966734266,0.29435506461908906,110.70378818725605,300.0177698256278,0.0886610839996192
0.09321167423021384,274.591867621012,0.29594706568092893,110.71544102479204,300.18703533196776,0.08911985396665331
0.09371640719642324,274.548666219004,0.2975495928486438,110.69802221950242,300.27838081761905,0.08958144479760727
0.09422884563913575,274.535402599675,0.29917658490425597,110.69267432818897,300.4045566737178,0.09004986460968287
0.09473952407861184,274.53737278637,0.3007979889495926,110.69346870746438,300.5469128259431,0.090516457417332
0.09525305396193645,274.528081464645,0.3024284463291482,110.68972244654488,300.67771962246377,0.09098543607770392
0.09576893788489564,274.47538329719,0.30406637778454365,110.668474545427,300.76159923111146,0.0914563432017876
0.09628473017131704,274.445166888986,0.30570401829393157,110.65629128963916,300.8700457297141,0.09192694508846311
0.09680157059261114,274.394217799439,0.30734498663154036,110.6357486167338,300.9560090439557,0.09239828124215882
0.09731496683504964,274.372513524532,0.3089750197012826,110.6269974530913,301.073065578621,0.09286625661452445
0.09782437358910365,274.314718270333,0.3105923861454041,110.60369440659827,301.14938375139974,0.09333037909988767
0.09833557267089285,274.263771822898,0.31221544323008477,110.58315279899247,301.23365688798174,0.09379591813486762
0.09883867727222044,274.184006831924,0.31381280033929987,110.55099155463176,301.28399139638884,0.09425387417557174
0.09933488108337865,274.109396319361,0.3153882474397272,110.52090859596636,301.33802060658144,0.09470534336707417
0.09982201239939124,274.024936749375,0.3169348893680672,110.48685449734799,301.3786573833135,0.09514835980253016
0.10030784046933774,273.925381998239,0.3184773934901473,110.44671402168997,301.4022455162208,0.09558999562435189
0.10078672708095675,273.814243072753,0.31999785848203766,110.40190280693402,301.41108446020536,0.09602513060331655
0.10126565928434775,273.679293061914,0.32151846822780406,110.34749096256371,301.3936071063029,0.09646011772161407
0.10173338225690774,273.516169714327,0.32300348866568207,110.28171962881666,301.3418947613199,0.09688474158278522
0.10220099347156375,273.323335133409,0.3244881542722149,110.20396872579052,301.2572515230045,0.09730908381985222
0.10267233181223774,273.144665382032,0.3259846535038548,110.1319290820353,301.18906509887864,0.09773662615749933
0.10314240983591574,272.918004752489,0.3274771512290325,110.04053951620358,301.06742545027066,0.0981628433025012
0.10361239821696674,272.658200817856,0.3289693643388694,109.93578656975956,300.90897089811745,0.09858879763729372
0.10407437079930575,272.388097697525,0.3304361272877957,109.82688099164208,300.73671757861473,0.09900731044043723
0.10453294874578975,272.120170832964,0.33189211226788246,109.71885287985107,300.56569470334176,0.09942257480093791
0.10499227858044174,271.803179470515,0.3333504844929025,109.59104196251165,300.3404146085331,0.09983834723529456
0.10545032183987775,271.472149802842,0.33480477184161184,109.45757080050589,300.09897537011517,0.10025278302829348
0.10590082290568574,271.106099992785,0.33623511272555223,109.30997951709092,299.81645907677205,0.10066022720386984
0.10634959050926575,270.701361491774,0.3376599498669187,109.14678895348327,299.49034043672486,0.10106593860707663
0.10679223598659575,270.272644608152,0.3390653492574415,108.97393030600689,299.1356646518671,0.10146595407642714
0.10724213941107474,269.767792651012,0.3404937926301623,108.77037399688803,298.6982678791097,0.10187236459621922
0.10768070440358274,269.209916311615,0.34188623648137517,108.54543825684317,298.1986297324793,0.10226837387434302
0.10811967334695774,268.629326410662,0.3432799628765908,108.31134440877892,297.67344143359605,0.10266459092848343
0.10855585218541575,267.994172370447,0.34466483068869497,108.05525029976423,297.0865081328461,0.1030581341774284
0.10898901798131974,267.288403222024,0.3460401320906902,107.77068417912007,296.4199038069874,0.10344880568738594
0.10942269124689474,266.524917582471,0.3474170447088908,107.46284676925232,295.6887913487018,0.10383978205060593
0.10984879231304374,265.744441632931,0.34876991559391385,107.1481588663978,294.93614761021263,0.10422378290362594
0.11027462120183175,264.916191896125,0.3501219223158158,106.8142085725176,294.1297246077019,0.10460739121244125
0.11070800069741675,264.043244602966,0.35149790221429816,106.4622362239159,293.2749443106194,0.1049976504578872
0.11114389146467074,263.108851016892,0.35288185540032957,106.08548873001087,292.3517925977077,0.10539001754084514
0.11157699337505375,262.132880599163,0.35425695396579565,105.69197745758252,291.38087928115954,0.10577972181619359
0.11201303936367274,261.101126340253,0.35564139997966093,105.27597414039003,290.34785708290303,0.10617192180610933
0.11244263510893175,260.075075931369,0.3570053664708583,104.86227061552798,289.31860279524767,0.10655816978176463
0.11288570972571074,258.927517465695,0.3584121283791316,104.39957504216824,288.1567340423264,0.1069563803412646
0.11333474735186774,257.820419719297,0.3598378228421801,103.95319323082055,287.040431850336,0.10735978839622075
0.11378407851999374,256.63348564491,0.3612644493009801,103.47462141202772,285.83429032639015,0.10776329733252253
0.11423561220357975,255.399215982946,0.3626980687463657,102.97696388432384,284.5749017770721,0.1081686202223046
0.11470406537950074,254.170992707494,0.36418540757991485,102.4817442596616,283.32543887258703,0.1085889574683322
0.11517179489173074,252.885011073605,0.36567044878124505,101.96323646487754,282.0102317001673,0.10900846917965475
0.11563432063223975,251.515859032607,0.3671389680073612,101.41119436194715,280.5997245200767,0.1094231405793052
0.11610091646412074,250.145928115856,0.36862040977358335,100.85883821631315,279.18809961987495,0.10984128681002622
0.11657589071490175,248.686318489326,0.37012845301981306,100.27032361489624,277.6771475758289,0.11026676196739708
0.11705304929070375,247.160538364824,0.37164343149798434,99.65512906869705,276.0914330447586,0.11069401160990876
0.11754390108469374,245.605459473451,0.37320188594390263,99.02812125969544,274.47488330765907,0.11113333182092226
0.11802548410875374,243.921015197932,0.37473091204529313,98.3489533278062,272.7099111009666,0.11156416884588691
0.11852571903047475,242.127817573601,0.3763191579217573,97.62593604567591,270.82619124879164,0.11201149589957587
0.11904513461513475,240.272722121039,0.3779683024030528,96.87796155920293,268.87602067028297,0.11247576329306953
0.11956549219492074,238.307687449283,0.3796204377188733,96.0856595795509,266.8010633929899,0.1129406566362227
0.12011565080794574,236.100893871343,0.3813671913152277,95.1958804089255,264.4603063950371,0.11343193962604405
0.12038503853447674,235.070586210248,0.3822224973469636,94.78046035997198,263.3695677894907,0.1136724106324673
0.12064784431139275,233.965809523493,0.38305690568867196,94.33501439987238,262.19328008507233,0.11390695050034025
0.12092649984038374,232.805461081558,0.38394163699321837,93.86716190808419,260.9578106338775,0.11415557533953284