File: example/data/02 processed data/test_ID_135.csv
Strain,Stress_MPa,Displacement(mm),Force(kN),True Stress (MPa),True Strain
0.0003702147257139,0.114113566798732,0.0001156623384995,0.0230052950666243,0.1141177238513274,3.642841946902162e-05
0.0003739091726908,0.108197583312047,0.0001273922076512,0.0218126327957086,0.1082019245810236,4.0122725041662985e-05
0.0003737515571176,0.101111278247578,0.0001268917782063,0.0203840336947117,0.1011153192522688,3.996511577982242e-05
0.0003639523886612,0.261049357946444,9.57794183572794e-05,0.0526275505620031,0.2610572329561028,3.0166290932123365e-05
0.0003605306332696,0.636895549318911,8.491534498883447e-05,0.1283981427426924,0.6369125830843573,2.6744632906672885e-05
0.000339556599817,1.2295757058557,1.832278877675416e-05,0.2478824623005091,1.2295828016843435,5.770940443177073e-06
0.0003320018231042,2.23497239971553,-5.663627286186991e-06,0.4505704357826509,2.2349684129279184,-1.7838212086925852e-06
0.0003197188062745,3.75770421023803,-4.466220572076869e-05,0.7575531687839869,3.757651351227487,-1.4066935386317766e-05
0.0002962885843758,5.47088519882324,-0.0001190531602489,1.102930456082765,5.470680056721735,-3.749776137836996e-05
0.0002710783209386,7.4027185783723,-0.0001990957466621,1.4923880653998558,7.402254373716334,-6.270928796967214e-05
0.0002734732963698,9.39864350552429,-0.0001914916996679,1.894766530713697,9.398076651281944,-6.031416521487084e-05
0.0002815917208878,11.4251567847816,-0.0001657157018233,2.3033116078119704,11.424560461041432,-5.219528398422294e-05
0.0002971986442314,13.5078369623125,-0.0001161637202074,2.7231799316022,13.507342751101948,-3.658766781107255e-05
0.0003289580731545,15.4781372773018,-1.532753337671493e-05,3.1203924751040426,15.47806255551732,-4.827581220185265e-06
0.0003551966845812,17.2185360262766,6.798005790302921e-05,3.4712568628973623,17.21890469307221,2.141081264618005e-05
0.0003887049894862,19.1553745973423,0.0001743689259764,3.861723518824208,19.15642659800221,5.49178387521585e-05
0.0004463116635018,21.1829350841352,0.0003572701159761,4.270479712961656,21.185318715528656,0.0001125196902021
0.0004910161763074,23.3009175962497,0.0004992069441339,4.69746498740394,23.3045812119564,0.0001572181741606
0.0005322058283876,25.5048496965676,0.0006299840894885,5.141777698828029,25.50991037357977,0.0001984005029842
0.0005751802156783,27.7409411323574,0.0007664277691365,5.592573732283252,27.747637644995454,0.0002413654419744
0.0006003339956698,29.9829012819796,0.0008462910206095,6.044552898447088,29.99089317493291,0.0002665128352469
0.0006732331743362,32.2242324782678,0.0010777459128754,6.496405267618789,32.235170914440715,0.0003393899323351
0.000729975142006,34.4088705446414,0.001257901660227,6.936828301799707,34.42250297783342,0.0003961110369477
0.0007735345623036,36.6450342782329,0.0013962028196718,7.387638910491753,36.66114889246479,0.0004396522583623
0.0008171901781426,38.8063990534205,0.0015348093999607,7.823370049169573,38.82515824272627,0.0004832877330886
0.0008585730569465,40.9442896615309,0.0016662000401631,8.25436879576463,40.96577670942964,0.0005246497614664
0.00091600718045,43.099975477242,0.0018485533822867,8.688955056211988,43.1250692112404,0.0005820521125273
0.0009723582093089,45.2031683180635,0.0020274678989137,9.112958732921602,45.23203382127422,0.0006383687658819
0.0009845615592336,47.321805061151,0.0020662135349246,9.54007590032804,47.35260095221066,0.00065056425369
0.0010266785318241,49.4194152978525,0.0021999349228994,9.962954124047064,49.45365765929597,0.0006926529496527
0.0010707362604235,51.4066463908846,0.0023398182112025,10.363579912402336,51.44453055069633,0.000736679202933
0.001118586156782,53.4407527850906,0.0024917416321408,10.773655761474265,53.4826931153481,0.0007844927191644
0.0011822696295413,55.4637995865386,0.0026939366581515,11.18150199664618,55.510859732335945,0.000848124227767
0.001152717541415,57.4599902730267,0.0026001087783505,11.583934039042184,57.50704609195987,0.0008185967569254
0.0011907469168249,59.4527006540861,0.002720852045277,11.98566445186376,59.50364931618749,0.0008565942924347
0.0012449808765455,61.4232778968733,0.0028930448673899,12.38293282400966,61.47924649493876,0.0009107803474557
0.0012871226864795,63.3421132047215,0.0030268451139303,12.769770022071857,63.402499587669446,0.0009528829066056
0.0013447283761847,65.2808185982545,0.0032097431787443,13.160613029408108,65.34681376745091,0.0010104320749929
0.0013910390474325,67.2593491779886,0.0033567795599561,13.5594847942825,67.33045935390565,0.0010566949059448
0.0014249944436385,69.1487424652762,0.0034645879429102,13.940386480999685,69.22419818162662,0.0010906138653528
0.001541186167294,70.9637048059256,0.0038334966655164,14.3062828888746,71.04938642033386,0.0012066722027505
0.00156567801571,72.7545388893037,0.0039112582842372,14.667315040083627,72.8441646508617,0.00123113421616
0.0016160260600282,74.5620642075538,0.0040711133249475,15.031712144242848,74.65767069987851,0.001281419049115
0.0016773414937414,76.3506741715398,0.0042657898269869,15.392295912982425,76.45325556655226,0.0013426540874798
0.0017203646336207,78.1231715802675,0.0044023882961036,15.749631390581929,78.23149552868308,0.0013856185779396
0.0017713671317704,79.8475424759738,0.0045643212277289,16.09726456315632,79.96232982498327,0.0014365491580346
0.0018320778486086,81.620283307114,0.0047570777536902,16.454649114714183,81.7425743414353,0.0014971708860229
0.0018917016984528,83.4091736088763,0.0049463834769456,16.815289399549464,83.53911809963681,0.0015567037634489
0.0019654144440741,85.2118944863643,0.0051804214442932,17.178717928451043,85.35092866762604,0.0016302991412242
0.0020132883465347,86.9537821133051,0.0053324210846056,17.52988247404231,87.09982122547115,0.0016780939163011
0.0020512377379586,88.6805051120933,0.0054529104023765,17.87798983059801,88.83280963140471,0.0017159789608377
0.0021000909654701,90.4253818667753,0.0056080193997255,18.2297569843419,90.58510070007812,0.0017647472399317
0.0021493313470721,92.1047725334136,0.0057643576113118,18.568322142736186,92.2719929575368,0.00181389959334
0.0021893369134754,93.7406805303175,0.0058913752846423,18.89812119491201,93.91462116919682,0.0018538318621329
0.0022266417806152,95.4133811632024,0.0060098182378112,19.235337642501605,95.59398496737433,0.0018910669431502
0.0022830216236758,97.0479388242497,0.0061888242395286,19.56486446696874,97.23710815848334,0.0019473386856166
0.0023319060796555,98.6357338229094,0.0063440323872641,19.884963938698537,98.8328198984729,0.0019961268494703
0.0023913030494594,100.26829154719,0.0065326177663915,20.214087575913503,100.47459530239216,0.0020554036167411
0.0024431438425027,101.860934878354,0.006697212284304,20.53516447147617,102.075796076577,0.0021071366272862
0.0024948636454423,103.567281253224,0.0068614226586372,20.87916390064996,103.79109822654188,0.002158746232474
0.0025497790035482,105.197507506357,0.0070357789206235,21.20781751328157,105.43062448456656,0.0022135416688261
0.0025955266558769,106.758810663359,0.0071810277167671,21.522576229733176,107.00027144395196,0.0022591871270439
0.0026361628506546,108.346490379717,0.0073100476351863,21.842652460550948,108.59594486972676,0.0022997307987719
0.0026886387404766,109.967943524551,0.0074766585853711,22.16953741454948,110.2269018770135,0.0023520847763403
0.0027358906929882,111.518023722668,0.0076266835345955,22.48203358248988,111.78590173064794,0.0023992246077581
0.0027739663739287,113.019042666951,0.0077475738215815,22.78463900165732,113.29482955712632,0.0024372083246971
0.002819222419803,114.553019460441,0.0078912617672324,23.09388872322491,114.83773374793368,0.0024823531874158
0.0028589264744035,116.099131131799,0.008017322140589,23.40558483617068,116.39229778834266,0.0025219580204766
0.0029235473865196,117.624388797888,0.0082224935365576,23.713076781654223,117.92900794013435,0.0025864140893589
0.0029854686529477,119.087617233848,0.0084190935574669,24.00806363434376,119.40339984519528,0.0026481735015332
0.0030339466586829,120.606798615393,0.0085730112256761,24.31433060086324,120.93245639127414,0.0026965221301181
0.0030871271939088,122.115003729664,0.0087418594250184,24.618384751900265,122.45122804345624,0.0027495580495951
0.0031492830100213,123.591613609637,0.0089392041411755,24.916069303702816,123.9395854723752,0.0028115412784189
0.003207219861746,124.860266261679,0.0091231536454015,25.171829678354488,125.21904402335178,0.0028693137982036
0.0032702140795776,126.16979718889,0.0093231602870168,25.435831113280223,126.54028576922776,0.0029321255522237
0.0033234006541708,127.515175796975,0.0094920276613502,25.70705944067016,127.8963970807252,0.0029851549994255
0.0033754611678401,128.88767132081,0.0096573197922502,25.9837545382753,129.27970579615598,0.0030370589890855
0.0034353356909154,130.123295390055,0.0098474214030143,26.23285635063509,130.52687930314312,0.0030967501640024
0.0034989498292357,131.349331068931,0.0100493962921813,26.48002514349649,131.76507326755294,0.0031601655991391
0.0035636355278038,132.594276048578,0.010254773385135,26.73100605139333,133.022535655836,0.0032246451239951
0.0036229346471857,133.821879128779,0.0104430480891725,26.97849083236185,134.26203922929088,0.0032837515859145
0.0036896290125229,135.021006886049,0.0106548026991181,27.22023498822748,135.47411623679142,0.0033502250933016
0.0037593757978334,136.135535234552,0.010876248742479,27.444923903285684,136.6018797838123,0.0034197361862121
0.0038472482490991,137.238204084414,0.0111552437752476,27.667221943417864,137.72038538263098,0.0035073048158634
0.0039332491769114,138.262592919624,0.0114282967210516,27.8737387325962,138.7602640809807,0.0035930009685261
0.004018036775968,139.24053510986,0.0116974973480563,28.070891878147773,139.75353220913226,0.0036774809037612
0.0041149651081696,140.165565758162,0.0120052448027964,28.25737805684546,140.6955569171696,0.0037740487756653
0.0042342315026613,141.04137086362,0.0123839156053075,28.43394036610579,141.59149509468517,0.003892858843086
0.0043411433993168,141.799080231695,0.0127233608771888,28.58669457470972,142.3673198757395,0.0039993496855081
0.0044598155682151,142.50080515099,0.0131001450134409,28.728162318439587,143.08876773744987,0.0041175412058169
0.0045833415470851,143.072582592747,0.0134923399963531,28.8434326506978,143.6805775308565,0.0042405520409388
0.0047109089273027,143.626758742058,0.013897366428544,28.95515456239889,144.25543077203673,0.0043675715430801
0.0048472715669939,144.095750155094,0.0143303178095636,29.04970323126696,144.74612429516642,0.0045033306922099
0.0049779425719099,144.44814836427,0.0147451982501719,29.12074671023683,145.11898823340428,0.004633406105222
0.0051332823911406,144.740793269357,0.0152384021762293,29.179743923102368,145.4354762360168,0.0047880158841584
0.0053062211897861,145.032435499977,0.0157874828619288,29.238538996795366,145.75359993773438,0.0049601138185492
0.0054416640657274,145.237068671449,0.0162175139930424,29.279793044164123,145.97892196073647,0.0050948774647627
0.0056051141699942,145.412003682917,0.0167364680740895,29.31505994247607,146.17851812613858,0.0052574837074675
0.0057706015565337,145.530513028796,0.0172618905263524,29.33895142660528,146.32173563797616,0.005422089781572
0.0059585025096448,145.618440529685,0.0178584760524802,29.35667761078449,146.43750302826734,0.0056089572151091
0.006145699315023,145.67800223365,0.0184528259095559,29.368685250303844,146.52467020658528,0.0057950896570428
0.0063150504555735,145.695282847335,0.0189905157808038,29.37216902202273,146.56672491602822,0.0059634480576594
0.0064850376404736,145.662859926779,0.0195302250928616,29.365632561238645,146.55886888490184,0.0061324102744958
0.0066954235081152,145.636309599298,0.0201982002226237,29.360280015218475,146.562795061021,0.0063414880592569
0.0068904190269371,145.544125788233,0.0208173109948832,29.34169575890777,146.49840526225256,0.0065352321592704
0.0070926943706737,145.474422792471,0.0214595352112469,29.32764363496215,146.45767113837678,0.0067361697074949
0.0072810892563188,145.382392555577,0.0220576889731701,29.309090339204328,146.39240817673175,0.0069232822912871
0.0074785231339522,145.324036466728,0.0226845415346562,29.29732575169237,146.36233855844876,0.0071193347796902
0.0076839447970057,145.276778137369,0.023336755314851,29.28779847249359,146.34458557810024,0.0073232783728037
0.0078972120835297,145.20502633891,0.0240138789495647,29.27333330992425,146.30327387445988,0.0075349671408434
0.0081091170919008,145.120141320977,0.024686677351143,29.25622049030897,146.2484985196993,0.0077452593394352
0.0083073238009949,145.063016437725,0.0253159836525167,29.24470411384536,146.2196819346454,0.0079419174774815
0.0085181063921958,144.978052442813,0.0259852183795796,29.2275753724711,146.16459932563902,0.0081510108190941
0.0087276205027636,144.882920783517,0.0266504256806323,29.208396829957028,146.09904409461433,0.0083588025287671
0.0089447558922946,144.76837173665,0.0273398305423933,29.18530374210864,146.0149678787534,0.0085741073112047
0.0091566860771576,144.637841387415,0.0280127088793333,29.158988823702863,145.91396666102787,0.0087842060794689
0.0093694773156846,144.504175781908,0.0286883210616565,29.132041837632656,145.80987095972895,0.0089951140589955
0.0095866149147948,144.360915748181,0.0293777329388314,29.10316061483329,145.696662655159,0.0092102840881508
0.009808348941681,144.226914556989,0.0300817384741951,29.07614597468898,145.59340158837273,0.0094299611268573
0.0100307526553683,144.095654269001,0.0307878702651523,29.0496839006306,145.49294507511317,0.0096502531736181
0.0102443956532065,143.959365686109,0.0314661867832886,29.022208122319576,145.38609081678078,0.0098618219962605