File: example/data/02 processed data/test_ID_133.csv
Strain,Stress_MPa,Displacement(mm),Force(kN),True Stress (MPa),True Strain
0.0004410356669103,0.47052067339809,-0.0005669519218701,0.0948569677570549,0.4704366536815348,-0.0001785834795277
0.0003988919192046,0.987044571248113,-0.0007007583208357,0.1989881855636195,0.9868267193752508,-0.0002207356424724
0.0003650264421234,1.76743414201564,-0.0008082812105685,0.356314723030353,1.766984194359606,-0.0002546091693981
0.0003415957136224,2.66794088572952,-0.0008826737735592,0.5378568825630713,2.6671991781864524,-0.0002780461389805
0.000295964644143,4.08295210984307,-0.0010275524191563,0.823123145344363,4.081630709113064,-0.0003236909394747
0.000285750380237,5.81244102164662,-0.0010599827070579,1.1717881099639589,5.810500521813946,-0.0003339085623803
0.0002974187683358,7.91147186887018,-0.0010229355748442,1.5949527287642284,7.90892291579174,-0.0003222363455768
0.0003308044502305,10.1400812792897,-0.0009169360348285,2.0442403859048035,10.137152836479911,-0.0002888404615172
0.0003564904747817,12.64659236909,-0.0008353829068784,2.549553021608544,12.643264889689874,-0.0002631473468021
0.0004260721289689,15.2256943507384,-0.0006144611548341,3.0694999811088617,15.22274770578284,-0.0001935498019432
0.0004989743340388,17.9108107931343,-0.0003829966537371,3.6108194558958746,17.908650232315562,-0.0001206361435657
0.0005708470364692,20.7167517738593,-0.0001548008235206,4.176497157610035,20.715741704493865,-4.875735350886191e-05
0.0006437963289193,23.6809511594337,7.681318000830066e-05,4.774079753741835,23.681524075705884,2.419283491275408e-05
0.0007184272372574,26.6925209429257,0.000313766313982,5.381212222093821,26.695158805573623,9.881915312654336e-05
0.0007993396885938,29.783279082907,0.0005706633469749,6.004309063114051,29.78863222486774,0.000179720336569
0.0009046987718584,32.9053145773098,0.00090517843634,6.633711418785656,32.91469573674173,0.000285054938481
0.000979284382017,36.004889608886,0.0011419877485935,7.258585745151419,36.01783989009004,0.0003596165108901
0.0010696478873894,39.0148781551407,0.0014288918781509,7.865399436076365,39.0324365937306,0.0004499434462959
0.0011574024194807,42.0503911832179,0.0017075125175408,8.477358862536729,42.073005850718,0.0005376546559514
0.001226758404058,45.0435032519048,0.0019277177685737,9.080770255584008,45.070851649252056,0.0006069709585531
0.0013050364674493,47.9981038652284,0.0021762506198411,9.676417739230049,48.03100336232696,0.0006851984639985
0.0013725779579172,50.8992757133307,0.0023906948520767,10.261293983807471,50.937601583070006,0.0007526914132921
0.0014543784656227,53.6755994593138,0.0026504114640416,10.82100085099766,53.72040652203703,0.000834427033177
0.0015193985164588,56.3582063743996,0.0028568501254463,11.36181440507896,56.40891722446278,0.000899390741967
0.0015884398361822,59.054245673871,0.0030760563155681,11.905335927852391,59.11145959052178,0.000968367615523
0.0016620749972183,61.6359647102551,0.0033098479518577,12.425810485587428,61.700218465076205,0.0010419287994775
0.0017393148571721,64.1499710456879,0.003555084507211,12.932634162810682,64.22180051598794,0.0011190852462736
0.0018072309390942,66.5795924922827,0.0037707180673137,13.422445846444193,66.65866426309373,0.0011869230657849
0.0018782384966006,68.92049335846,0.0039961670623965,13.894371461065536,69.00723912396653,0.0012578438778408
0.0019464183867553,71.2052846059032,0.0042126382136376,14.354985376550085,71.29976085879889,0.0013259357439479
0.0020253589023466,73.4271114932852,0.00446327435064,14.802905677046295,73.53033207387404,0.0014047685514626
0.0020885815263538,75.5593326485269,0.0046640061818629,15.232761461943024,75.67032767043877,0.0014679004318085
0.0021461001619152,77.7287083506365,0.0048466278497703,15.67010760348832,77.8473609876818,0.0015253330483939
0.0022189482534957,79.8219851135971,0.0050779205405384,16.092112198901177,79.94964801054037,0.0015980674618639
0.0022776384576394,81.9019231786645,0.0052642619386947,16.511427712818765,82.03771945485201,0.0016566622332971
0.0023488799479829,83.972606180209,0.0054904536705353,16.928877405930134,84.11781805542995,0.0017277832691014
0.0024070204780591,86.0234628612337,0.0056750498535272,17.342330112824715,86.17722268495355,0.001785821747409
0.002464865025883,88.0938959648162,0.0058587062928681,17.759729426506947,88.25645226801379,0.0018435614203975
0.0025203854833676,90.1835813241967,0.0060349837453817,18.181009994958053,90.35500067770596,0.0018989780812683
0.0025708632882145,92.2178556358224,0.0061952507757706,18.5911196961818,92.39779665682012,0.0019493588516948
0.0026202841471761,94.242807108404,0.0063521620029737,18.99934991305425,94.43135689686622,0.0019986822490872
0.002684760776522,96.345397762735,0.0065568753011469,19.423232188967376,96.54436619075696,0.0020630280685997
0.0027143919572674,98.419735795761,0.0066509543000136,19.841418736425418,98.62590435166555,0.0020925977452133
0.0027660554867596,100.442198867484,0.0068149860061513,20.24914729168477,100.6577932547939,0.002144151947817
0.0028207914677918,102.476622011855,0.0069887727459285,20.65928699758997,102.7021923498113,0.0021987692007708
0.0028779675520541,104.432343500367,0.0071703068134613,21.053560449673988,104.66818978198792,0.0022558180788121
0.0029319745875257,106.407451599589,0.0073417791510837,21.45174224247714,106.65350514594296,0.0023097019697837
0.0029951210838842,108.318602488726,0.0075422692770219,21.837030261727165,108.57591526594828,0.0023727008003921
0.003042892665557,110.133479143388,0.007693944048833,22.20290939530702,110.4003644430518,0.0024203580331345
0.0031158781985456,111.923309224525,0.0079256731160719,22.56373913966424,112.20270058294471,0.0024931644781557
0.0031781811886931,113.728481412541,0.0081234851097902,22.927661852768264,114.01946460161624,0.0025553103990764
0.0032372731507851,115.52800087666,0.0083111020894323,23.29044497673466,115.83041505287228,0.002614249818661
0.003294112196879,117.354983500759,0.0084915660607804,23.658764673753016,117.66885045980104,0.0026709388604932
0.0033569958184947,119.090300315133,0.0086912215594102,24.00860454353081,119.41629722398828,0.0027336527813448
0.0034130181924239,120.956237956876,0.0088690925966355,24.3847775721062,121.2941189252477,0.0027895206580498
0.0034822386650635,122.727921550017,0.0090888675972662,24.74194898448343,123.07924685063298,0.0028585459255191
0.0035654967160696,124.476521450007,0.0093532119092106,25.09446672432141,124.84321602728048,0.0029415628733994
0.0036452525720303,126.175802720416,0.0096064367518858,25.437041828435863,126.55756645851116,0.0030210813055382
0.0037405245966565,127.896259064407,0.009908925430074,25.78388582738445,128.2954132356998,0.0031160614292104
0.0038454962025732,129.486714564716,0.0102422102788595,26.10452165624675,129.90442485098075,0.0032207009713467
0.0039708480296581,131.027946659817,0.010640202329854,26.41523404661911,131.46705338842352,0.003345641921669
0.0041022192730195,132.387664864691,0.0110573060275265,26.689353236721708,132.84872027403856,0.0034765658074064
0.0042627535636448,133.740784501998,0.0115670024002618,26.9621421556028,134.22802228950903,0.0036365301640523
0.0044183824343468,135.028209620321,0.0120611240647407,27.22168705945672,135.5411519788944,0.0037915820922994
0.0046049065413604,136.143092864089,0.0126533381045088,27.44644752140034,136.68566438679858,0.0039773830548323
0.0048116138276891,137.009037768471,0.0133096337386025,27.62102201412376,137.5833811106999,0.0041832486281771
0.0050373169267745,137.778569159138,0.0140262410781986,27.77615954248222,138.3872354351806,0.0044079842722387
0.0052772217308334,138.394043652498,0.0147879388310856,27.9002392003436,139.03863031458295,0.004646805386955
0.0055400418255153,138.892612548781,0.0156223926317006,28.00075068983425,139.57602512417617,0.0049083728291798
0.0058003140269223,139.231127959791,0.0164487568711679,28.068995396693865,139.95244417166785,0.0051673371135719
0.0060824808420656,139.375296264105,0.0173446365092479,28.09805972684357,140.13668645373323,0.0054480102459105
0.006359736942508,139.442366021888,0.0182249246281525,28.111580990012623,140.2427838520361,0.0057237219474442
0.0066405486617775,139.448240759938,0.0191165018368331,28.112765337203506,140.28785101210508,0.0060028919979997
0.0069484489045644,139.400914277078,0.0200940851076815,28.103224318258924,140.2831611544236,0.006308902659309
0.007247536226276,139.344246158846,0.0210436873541159,28.09180002562336,140.26781048979458,0.0066060648508403
0.0075480144827513,139.227242898533,0.0219977058184249,28.068212168344253,140.19186649890852,0.0069045201282954
0.0078632040890199,139.100370913411,0.0229984328183278,28.04263477614366,140.10795848363355,0.0072174920164333
0.0081802558928027,138.999691316668,0.0240050722953381,28.02233776944027,140.0506197069314,0.0075322142092583
0.0085026323482379,138.903829063535,0.0250286175413449,28.00301193920865,139.99881199665612,0.0078521204027079
0.0088378816012156,138.792540912288,0.0260930339195491,27.980576247917263,139.93317665332884,0.0081846922380742
0.0091412506714458,138.672970663822,0.02705623071753,27.95647088582652,139.85469283344898,0.0084855431991991
0.0094631402423737,138.520106432383,0.0280782301052261,27.92565345676841,139.74511412454325,0.0088046619944782
0.0097845880433735,138.361040981546,0.0290988268734004,27.89358586187968,139.62911782486742,0.0091232412276507
0.0101038089369538,138.21112427847,0.0301123532105179,27.86336265453956,139.52194701607507,0.0094395130174507
0.0104278770521269,138.072078688197,0.0311412694761925,27.835331063540515,139.4263274471158,0.0097604849630518