File: example/data/02 processed data/test_ID_087.csv
Strain,Stress_MPa,Displacement(mm),Force(kN),True Stress (MPa),True Strain
3.28156830120808e-05,1.20383198431283,0.00010418979356335654,0.24269252803746655,1.203871488881627,3.2815144589308506e-05
5.41272491053704e-05,2.16534636611762,0.000171854015909551,0.43653382740931224,2.165463570359779,5.412578427878332e-05
7.73530502321578e-05,4.06640501987609,0.000245595934487101,0.8197872520070197,4.066719568707857,7.735005863934647e-05
0.0001236984541427,7.3149477513591,0.00039274259190307247,1.4746934666739946,7.315852599088077,0.0001236908041196967
0.0001544284017029,11.0909317107159,0.0004903101754067075,2.2359318328803255,11.092644465573382,0.0001544164788648296
0.0001902683588374,15.1113312592869,0.000604102039308745,3.046444381872239,15.114206467485454,0.00019025026010902852
0.000250051933486,19.0928367283826,0.0007939148888180499,3.8491158844419324,19.097610929122265,0.00025002067571192223
0.0002991232914212,23.5284848546947,0.0009497164502623099,4.743342546706451,23.535522772526587,0.00029907856296871205
0.0003671843530543,28.2911370526556,0.0011658103209474023,5.703493229815369,28.301525115511453,0.000367116957377074
0.0004400571443851,33.4577345303713,0.0013971814334226924,6.7450792813228535,33.472457845486325,0.000439960347636195
0.0005022868781173,38.8306867535057,0.0015947608380224275,7.82826644950675,38.85019089793027,0.0005021607742883982
0.0005814067947547,44.360833762824,0.0018459665733461725,8.943144086585319,44.38662545299469,0.0005812378433073939
0.0006636005515223,50.0055705020458,0.0021069317510833026,10.081123013212434,50.038754226210145,0.0006633804660368966
0.0007383785700002,55.6285264873974,0.0023443519597506346,11.214710939859318,55.669601399236385,0.0007381061026582724
0.0008277755897805,61.3328612145801,0.0026281874975530874,12.364704820859346,61.383631059944925,0.0008274331725170868
0.0009098286572506,67.1136666724185,0.002888705986770655,13.53011520115957,67.17472860965023,0.0009094150140351543
0.0010009548068134,72.8689294642969,0.003178031511632545,14.690376180002254,72.94186796951153,0.0010004541855891584
0.0010948942307717,78.6742256191822,0.0034762891827001476,15.86072388482713,78.76036557492307,0.00109429527124187
0.0011872225321755,84.3939464440062,0.0037694315396572123,17.013819603111653,84.49414083880373,0.001186518340804418
0.001287372460274,90.1247060060147,0.00408740756136995,18.169140730812565,90.24073007051715,0.0012865445068616923
0.0013834075759471,95.8137242360768,0.004392319053632042,19.316046805993082,95.94627366806469,0.001382451549301296
0.0014747262620021,101.485801904318,0.004682255881856667,20.459537663910506,101.63546568160663,0.0014736399211339355
0.0015574608868752,107.10776864793,0.004944938315828759,21.592926159422685,107.27458480827963,0.0015562493025017769
0.0016441082330707,112.634953323508,0.0052200436399994716,22.707206590019215,112.82013737759871,0.0016427581666972769
0.0017265634334524,118.22476571427,0.00548183890121137,23.834112767996835,118.42888827168075,0.001725074636229814
0.0018200738773507,123.729826756855,0.005778734560588472,24.94393307418197,123.95502418238428,0.00181841954991904
0.0019084361827505,129.177132924705,0.006059284880232837,26.04210999762053,129.4236592391625,0.0019066174320309444
0.0019963087880299,134.578085271825,0.006338280401994932,27.130941990799922,134.84674468612937,0.001994318811606169
0.0020906580101603,139.849128711946,0.006637839182258952,28.193584348328315,140.14150541310158,0.0020884756259192767
0.0021804624530978,145.109564008003,0.006922968288585515,29.254088104013405,145.42596996390785,0.0021780886948108177
0.0022841616841653,150.343016750723,0.007252213347224827,30.309152176945755,150.68642450906682,0.00228155695253036
0.0023690940951039,155.562774081521,0.007521873751954882,31.361455254834638,155.93131693101554,0.002366292216092393
0.0024610603254508,160.659178228032,0.00781386653330629,32.388890330771254,161.05457015748857,0.00245803687606634
0.0025503267016966,165.678783315451,0.008097287277886705,33.400842716394926,166.101318340445,0.0025470801372490808
0.0026409127841869,170.659695100797,0.008384898089793407,34.40499453232068,171.11039247133414,0.002637431701496978
0.0027354271930918,175.482311166331,0.008684981338066463,35.37723393113233,175.96233025220195,0.002731692720828538
0.0028176560262786,180.25595050408,0.008946057883434555,36.33959962162253,180.76384976929043,0.0028136938744465338
0.0029061869158816,184.893756756051,0.009227143457924079,37.27458136201988,185.43109257276362,0.0029019721187041685
0.0029938785958215,189.453198055447,0.009505564541733262,38.19376472797811,190.02039793001512,0.002989405866280654
0.0030880329326019,193.897410293315,0.009804504561011031,39.089717915132304,194.496171881847,0.003083274752001183
0.0031843891890714,198.266914120396,0.010110435675301696,39.97060988667183,198.89827313827155,0.0031793297597669974
0.0032823593282751,202.558248097063,0.010421490867273443,40.835742816367905,203.22311705222347,0.003276984145870233
0.0033776748368118,206.740778440847,0.010724117606877465,41.67894093367476,207.4390815659295,0.0033719833056535973
0.0034777123348586,210.820167134408,0.011041736663176054,42.50134569429665,211.55333903008827,0.003471679077226579
0.0035795057989481,214.700189416246,0.011364930911660217,43.2835581863152,215.46870998929668,0.003573114615044858
0.0036843169477428,218.299553501827,0.01169770630908339,44.00918998596833,219.10383824647846,0.0036775464766688236
0.0037989712720843,221.618437467592,0.012061733788867652,44.678276993466554,222.4603595448956,0.0037917734046228617
0.0039298421142934,224.635578583026,0.012477248712881544,45.286532642338045,225.51836094011026,0.003922140455712608
0.0040816686409068,227.324631908079,0.012959297934879089,45.82864579266873,228.2524957294439,0.004073361229188764
0.0042600331991643,229.681321889853,0.013525605407346653,46.303754492994365,230.6597719463317,0.004250984945872935
0.0044784191206209,231.51615727183,0.014218980707971358,46.673657306000926,232.55298365728882,0.004468420841586316
0.004735842892036,233.026139230368,0.0150363011822143,46.97806966884219,234.12971441550073,0.004724664068295178
0.0050352945652519,234.074255490798,0.01598706024467478,47.189369906944876,235.25288831733621,0.00502265986478234
0.0053617661677728,234.837328391107,0.017023607582678638,47.34320540364717,236.09647123340457,0.005347443074793224
0.0056930445026765,235.362827204809,0.018075416295997886,47.449145964489496,236.70275825436178,0.005676900368689556
0.0060359733093127,235.762064289153,0.01916421525706782,47.52963216069325,237.1851178165508,0.006017829794990444
0.0063936871028356,236.042421193189,0.020299956551503028,47.586152112546905,237.55160257729398,0.0063733341928107964
0.006752139158033,236.24686010348,0.021438041826754774,47.62736699686157,237.84203177854704,0.00672944556269723
0.0071223170992134,236.420515751769,0.022613356790002544,47.66237597555663,238.10437763371266,0.0070970731913206535
0.0074825679895944,236.598705428638,0.02375715336696222,47.69829901441342,238.3690713282578,0.00745471244543675
0.0078450485482985,236.797374337521,0.024908029140847738,47.73835066644424,238.6550612353085,0.00781443615451351
0.0082177381551036,236.95477658528,0.02609131864245393,47.77008295959245,238.90200889385892,0.008184156396867454
0.0085912525733193,237.088774676579,0.027277226920288777,47.79709697479832,239.1256642221243,0.00855455778262415
0.0089551665191677,237.224527079352,0.028432653698357447,47.82446465919737,239.34891222177836,0.008915306805646441
0.0093187817930133,237.35680573038,0.02958713219281723,47.85113203524461,239.56868201006807,0.009275629821344026
0.0096818351476769,237.517474441719,0.030739826593874156,47.88352284745055,239.81707947395628,0.009635266520342816
0.0100507122509345,237.640998072401,0.03191101139671704,47.90842521139604,240.02945936305161,0.010000539742120888
0.0104251275820802,237.805626667142,0.03309978007310463,47.941614336095824,240.28478066488347,0.010371160689968817
0.0107708974070395,237.926238615607,0.034197599267350415,47.965929704906365,240.48891772217848,0.010713304474201017
0.0111328704202866,238.105548584981,0.03534686358440996,48.00207859473217,240.75634680372886,0.011071356150916782
0.0115044146591387,238.243639912072,0.03652651654276537,48.029917806273716,240.98449353552303,0.01143874208389837
0.0118731913300108,238.427006842992,0.037697382472784285,48.066884579547185,241.25789631348061,0.011803258004074368
0.0122516417223356,238.567248376887,0.03889896246841553,48.09515727278042,241.49008883068404,0.0121771977834347
0.0126174262814747,238.716945098177,0.040060328443682174,48.12533613179249,241.7289385550921,0.012538489848090164
0.0129708268180369,238.803057668589,0.04118237514726716,48.142696425987545,241.90053077322594,0.012887426054258574
0.0133352225354131,238.997175034468,0.04233933154993659,48.18183048694875,242.1842555488877,0.013247091092440398
0.0136869326324143,239.153195581832,0.0434560111079154,48.21328422929734,242.42646925858713,0.013594112559012968
0.0140465908590048,239.325449508737,0.04459792597734024,48.24801062096138,242.68715618013366,0.013948851706140056
0.0144110581080121,239.531304880272,0.045755109492938414,48.28951106386284,242.98320443358955,0.01430820577312295
0.0147709144861934,239.691788310769,0.04689765349366404,48.32186452345103,243.23225521895014,0.014662887006066938
0.0151339210139971,239.812339912508,0.048050199219440794,48.34616772636162,243.44164092292573,0.01502054567589708
0.0154917088038737,239.922027259183,0.049186175452298996,48.3682806954513,243.63882944111734,0.015372937360829375
0.0158464240630423,240.118520611856,0.0503123964001593,48.40789375535017,243.92354051486183,0.015722180312590737
0.0162141197442015,240.2594212146,0.05147983018783976,48.43629931686336,244.15501623984605,0.016084074731822204
0.0165627547249488,240.433521234232,0.05258674625171244,48.47139788082117,244.41576267409033,0.01642708826030569
0.0169087476154002,240.53117837918,0.05368527367889563,48.49108556124269,244.59825936802835,0.016767386015540665
0.0172523237743918,240.673663162295,0.05477612798369397,48.51981049351867,244.8258431231398,0.017105192266079202
0.0175970736392787,240.837319068081,0.05587070880470987,48.55280352412513,245.07535110680848,0.017444037852021563
0.0179465305714673,241.055625838787,0.05698023456440867,48.59681416909946,245.38173799732695,0.017787392752303507
0.0182976582766232,241.279045150035,0.05809506502827866,48.641855502247054,245.69388666750027,0.018132270552873104
0.0186466553314023,241.419084377364,0.0592031306772023,48.67008741047658,245.9207428341714,0.018474937807802384
0.0189958952185307,241.592014840249,0.060311967318834966,48.7049501917942,246.18127143978808,0.018817725987656634
0.0193421776626159,241.694672392444,0.06141141407880549,48.72564595431672,246.3695736859664,0.019157495383149557
0.0196845692568798,241.793315673514,0.062498507390593365,48.745532439780426,246.55291294173992,0.01949333364324042
0.0200384185793657,241.885639968231,0.0636219789894861,48.764145017595375,246.73264567025214,0.01984029186074895
0.0203882313255053,241.992063846592,0.06473263445847932,48.78560007147295,246.92585402323277,0.020183173825737203
0.0207307416624365,242.148523752169,0.06582010477823588,48.81714238843727,247.1684422420156,0.020518784189149483
0.0210727439462734,242.286405253002,0.06690596202941805,48.844939299005205,247.39204463256155,0.02085378438818523
0.0214189107734848,242.452225285696,0.06800504170581424,48.878368617596315,247.64528786592314,0.021192749621875062
0.0217638448668488,242.629325789296,0.06910020745224493,48.91407207912207,247.90987279592238,0.021530393521510448
0.0221143819552529,242.774212996366,0.07021316270792795,48.94328134006739,248.14301467145359,0.02187340524035047
0.022467844528236,243.006844515888,0.0713354063771493,48.990179854403024,248.4666845177682,0.022219160546178673
0.0228224374674133,243.128188838394,0.07246123895903722,49.014642869820236,248.6769667247237,0.022565901491316293
0.0231724164360894,243.268253084077,0.07357242218458383,49.04287982174992,248.90536635022121,0.022908012783944238
0.0235202050196169,243.40053829316,0.07467665093728365,49.069548519901055,249.1253688557002,0.023247867028034483
0.0238613670098313,243.509618657083,0.07575984025621438,49.091539121267935,249.32009103828372,0.02358113367264335
0.0242071923944766,243.651407970984,0.0768578358524632,49.12012384695038,249.54952448092274,0.023918842472814207
0.0245526589803898,243.691387172237,0.0779546922627376,49.12818365392298,249.67465869793506,0.024256087063931602
0.0248900724375471,243.777751628747,0.07902597998921203,49.1455947283554,249.8453975254489,0.024585360436671855
0.0252274286258532,243.870239480746,0.0800970858870839,49.16424027931839,250.02245854121622,0.02491446956449112
0.0255657246725996,244.014191975681,0.08117117583550372,49.19326110229729,250.25259162393812,0.025244386844808533
0.0259085986899429,244.20396404626,0.0822598008405687,49.23151915172602,250.53094654922782,0.025578657682743366
0.0262459910424386,244.321679809067,0.08333102155974255,49.25525064950791,250.73414442880934,0.02590747536268196
0.026589301598755,244.418693697017,0.08442103257604712,49.27480864931863,250.91761606010073,0.02624194989237043
0.0269280012759744,244.540560583071,0.08549640405121871,49.29937701354711,251.12554911047945,0.02657182262323725
0.0272727099987144,244.68047410382,0.08659085424591821,49.32758357933011,251.35357371640143,0.026907436104513488
0.0276201534726464,244.830411786371,0.08769398727565231,49.357811016132395,251.59266533468178,0.027245598237848175
0.0279683038673975,244.975210475451,0.08879936477898706,49.387002431850924,251.82675160200807,0.027584333743816688
0.0283158179696414,245.059741340529,0.08990272205361144,49.40404385425065,251.99880836801483,0.027922335775600132
0.0286622825999373,245.182766354025,0.09100274725480091,49.42884569697144,252.21026409189844,0.028259203371299092
0.0290062934405424,245.30129548917,0.09209498167372211,49.452741170616676,252.41657684747406,0.028593572907594674
0.0293457606440069,245.41945437792,0.0931727900447219,49.47656200258867,252.6214749434772,0.028923416586054407
0.0297002203377167,245.531764127185,0.09429819957225052,49.49920364804049,252.8241116216707,0.029267711662983573
0.0300405713708013,245.621732282687,0.09537881410229412,49.5173412281897,253.00034946154491,0.02959819114618103
0.0303822854405332,245.755764772251,0.0964637562736929,49.544362178085805,253.22238656621806,0.02992988429522083
0.0307241016895147,245.851955135488,0.09754902286420916,49.563754155314385,253.40553560563677,0.03026156659386366
0.0310631549953492,245.940872126069,0.0986255171102337,49.58167982061551,253.58057155661245,0.03059045921631197
0.0314054281763596,246.025675670695,0.09971223445994172,49.59877621521211,253.75221735751134,0.030922365541523562
0.0317439110921901,246.100188175328,0.10078691771770357,49.61379793614612,253.91237066853688,0.03125048809903798
0.0320679216717211,246.142384961101,0.10181565130771449,49.62230480815796,254.03565968212416,0.03156448046699424
0.0324003046663744,246.222721444986,0.1028709673157387,49.63850064330918,254.20041263558738,0.03188648396725141
0.0327290517637876,246.323738521576,0.10391473935002561,49.65886568594972,254.38568091029836,0.032204863151748225
0.0330659410880842,246.502618827939,0.10498436295466733,49.6949279557125,254.65345990016212,0.032531022648163675
0.0334136672816454,246.664222219886,0.10608839361922415,49.72750719952902,254.90617847142713,0.03286756233182154
0.0337576212390878,246.847397453788,0.10718044743410376,49.76443532668366,255.18037840088755,0.03320033974850348
0.0341057030701872,246.914187217056,0.10828560724784435,49.77790014295849,255.33536917009752,0.03353699820198549
0.0344515317331619,246.983984968223,0.10938361325278903,49.79197136959376,255.49296156393854,0.03387136522879837
0.0347977010451662,247.112034950146,0.11048270081840267,49.817786245949435,255.71096566700382,0.03420594968556653
0.0351441211545381,247.162155727623,0.11158258466565846,49.827890594688796,255.84845247333138,0.03454066451560751
0.0354850043866236,247.253101128036,0.11266488892752993,49.84622518741206,256.02687850617065,0.034869920229207076
0.0358305318689851,247.337700490115,0.11376193868402767,49.86328041880718,256.19994184992754,0.03520355117970077
0.0361822125725262,247.411803652251,0.11487852491777067,49.8782196162938,256.36371012494885,0.035543009233577685
0.0365307218514366,247.572549136985,0.11598504187831118,49.91062590601618,256.6165530675593,0.03587929244617948
0.0368767830263419,247.68264379253,0.11708378610863551,49.93282098857405,256.81638290705786,0.036213101576612956
0.0372241076578469,247.771412391332,0.1181865418136639,49.95071673809253,256.9944821207238,0.03654801742985008
0.0375693912972223,247.776883134147,0.11928281736868081,49.95181963984403,257.0857098110199,0.036880854064181935
0.0379155231824414,247.80221269482,0.12038178610425145,49.95692607927572,257.1977632349107,0.03721439721452053
0.0382587427015814,247.838811155216,0.12147150807752094,49.96430432889155,257.32081246266927,0.03754502410640198
0.0386085933559912,247.928904087189,0.12258228390527205,49.9824670639773,257.50109032628785,0.03788192637420204
0.038957753473614,248.036909197947,0.12369086727872444,50.00424089430612,257.69986995883784,0.03821805053355129
0.0393059677179569,248.161216941948,0.12479644750451314,50.02930133549672,257.9154337239171,0.03855315165094131
0.0396562102775786,248.26272653484,0.12590846763131205,50.04976566942374,258.1078854223906,0.03889009146316341
0.0400041485438398,248.316688204839,0.12701317162669137,50.06064434209555,258.25038588569976,0.03922470212978669
0.0403536073306385,248.384877041045,0.12812270327477723,50.074391211474676,258.40810283602826,0.03956066241267442
0.0407026383610757,248.417209801391,0.12923087679641534,50.080909495960434,258.5284456546045,0.039896098837742235
0.0410448335088183,248.504518034657,0.1303173463904981,50.09851083578685,258.70434460357865,0.040224856437257595
0.0413909238930855,248.557295155816,0.13141618336054645,50.10915070341251,258.84531124268153,0.04055724641493005
0.0417324940419007,248.568396919701,0.13250066858303472,50.11138881901172,258.9417760631572,0.0408851868038053
0.0420664499370282,248.620066880231,0.13356097855006452,50.12180548305457,259.07863047698885,0.041205712830514094
0.0424139040313642,248.725479446471,0.13466414529958132,50.143056656408554,259.27489806186867,0.04153908521936146
0.0427713579615398,248.852596749887,0.13579906152788887,50.16868350477722,259.4963602451351,0.04188193622660045
0.043130467601259,248.965446387948,0.13693923463399732,50.19143399181032,259.7034425072164,0.04222625697925149
0.043486845672381,249.05763372019,0.13807073500980968,50.21001895799031,259.8883646013083,0.04256784148765189
0.0438423124009075,249.119278262989,0.13919934187288133,50.22244649781858,260.0412434856836,0.04290843629090854
0.0441938897924654,249.21650402659,0.14031560009107763,50.24204721176055,260.2303507400046,0.043245190408975155
0.0445496043269747,249.236703374652,0.14144499373814465,50.246119400329846,260.34009989375227,0.04358579186525692
0.0449037927941157,249.290722884813,0.14256954212131734,50.2570097335783,260.48482185072794,0.04392481686674435
0.0452600984750023,249.29257195704,0.14370081265813228,50.257382506539265,260.5755783129022,0.04426575250899354
0.045614044280444,249.351647901684,0.1448245905904097,50.269292216979494,260.7255850104731,0.0446043150284537
0.0459695494481738,249.41242654464,0.14595331949795182,50.28154519139943,260.87780341967283,0.04494425379276527
0.0463206048321848,249.455469540324,0.14706792034218674,50.290222659329324,261.0103977681284,0.04527982425519566
0.0466798979642292,249.52868443271,0.1482086760364277,50.30498278163434,261.1766579611772,0.04562315253924878
0.0470328465303257,249.590090536579,0.1493292877337841,50.31736225217433,261.32902296027606,0.04596030344055374
0.0473934473561697,249.68329135645,0.1504741953558388,50.33615153746032,261.5166432810671,0.0463046467392027
0.0477568043275246,249.779472655067,0.1516278537398906,50.35554168726151,261.7081420556873,0.04665150203008766
0.0481124917668925,249.788826350243,0.15275716135988368,50.35742739220899,261.8067892014808,0.046990919610607126
0.0484762254319396,249.809772307742,0.15391201574640823,50.36165009724079,261.9196071452336,0.047337896264361384
0.0488403330402234,249.769229444741,0.1550680574027093,50.35347665605978,261.9680417940221,0.047685109097322646
0.0492032888600784,249.800914723187,0.15622044213074893,50.3598644081945,262.0919412878238,0.0480311036416564
0.0495613085332315,249.882207611238,0.15735715459301,50.37625305442558,262.26669679962356,0.048372275469188264
0.0499206640270532,249.932720689726,0.15849810828589392,50.38643649104876,262.40952806864516,0.04871460324530424
0.0502674206772225,249.965175877624,0.15959906065018142,50.392979456929,262.53028052812044,0.04904481810162639
0.0506233965211559,249.976867582775,0.16072928395466995,50.39533650468744,262.6315456715343,0.04938369896533062
0.0509765215020514,249.972663459086,0.1618504557690132,50.39448895335174,262.71540031283314,0.049719752446481184
0.0513246397269806,249.971857433033,0.1629557311331634,50.39432645849946,262.8015729576676,0.05005093071392547
0.0516739577895849,249.980627776528,0.16406481598193204,50.39609455974804,262.89811618446623,0.05038314022298491
0.0520312676754942,250.040849646847,0.16519927486969407,50.408235288804356,263.0507920246301,0.05072283599881895
0.0523866155012959,250.105865708236,0.16632750421661446,50.421342526780386,263.20806552971214,0.05106055203138064
0.0527458026159627,250.153484634695,0.16746792330568155,50.43094250235451,263.3480309589319,0.05140180098566118
0.0531003232578719,250.210034450901,0.16859352634374328,50.44234294530165,263.4962681626071,0.051738502362749204
0.0534726835860667,250.275468588352,0.16977577038576178,50.455534467411766,263.6583695295315,0.052092024724293744
0.0538452149134405,250.351059971998,0.17095855735017357,50.470773690354804,263.8312665999979,0.05244558441409645
0.0542199264385112,250.401463281872,0.17214826644227305,50.48093499762539,263.9782122011107,0.052801087213006005
0.0545938166628857,250.41577409482,0.17333536790466209,50.483820057515715,264.0869269552472,0.0531556848909804
0.0549631177379208,250.443658822246,0.17450789881789852,50.4894416185648,264.2088231288088,0.05350580682681018
0.0553368899367348,250.441286414007,0.17569462554913298,50.48896334106382,264.2999283159132,0.05386004290828025
0.0557109462276314,250.430016111239,0.1768822542727297,50.486691248025785,264.3817092725971,0.054214422651271556
0.0560739150657845,250.434445841508,0.17803468033386577,50.48758428164802,264.4772856871715,0.05455817816195856
0.0564438830562666,250.377154886167,0.17920932870364645,50.47603442505127,264.50941373652256,0.05490844076764489
0.0568052873584565,250.363560477764,0.18035678736309937,50.47329379231722,264.5855344747897,0.05525047739141173
0.0571774622442227,250.376185460476,0.18153844262540708,50.47583898883197,264.6920603514949,0.055602585174392705
0.0575536237117939,250.425045688181,0.18273275528494562,50.48568921073729,264.8379145357274,0.05595833865438514
0.0579257760227813,250.461974069234,0.18391433887233063,50.493133972357576,264.9701782813921,0.056310175987212066
0.0583001805420327,250.465765098461,0.1851030732209538,50.493898243849735,265.0679644232996,0.056664017713797324
0.058673044015995,250.415516738421,0.1862869147507841,50.483768174465666,265.1081573743025,0.05701627864321542
0.0590445236526955,250.392221373172,0.1874663625973082,50.47907182883148,265.1765108104912,0.05736710884473245
0.0594078911019845,250.365234910225,0.1886200542488008,50.47363135790136,265.2389055214944,0.057710158752600674
0.0597731123039126,250.363458086964,0.1897796315649225,50.47327315033194,265.32846118399203,0.058054840216767406
0.0601431932787275,250.419470520938,0.1909546386599598,50.4845652570211,265.4804971372354,0.058403986999213266
0.0605191836068913,250.425253827632,0.19214840795187987,50.48573117165061,265.5807857438288,0.05875858406869644
0.0608968515143938,250.438438720128,0.1933475035582003,50.48838924597781,265.6893511363642,0.05911463672903258
0.0612715192268501,250.406919647411,0.19453707354524905,50.48203500091806,265.7497320391236,0.05946773568339897
0.0616454823550288,250.354151448991,0.19572440647721642,50.47139693211659,265.787353874648,0.05982004633121815
0.0620274634852942,250.375832113687,0.19693719656580908,50.47576775411931,265.9060098977189,0.060179782641023284
0.0623977507259446,250.426411009202,0.1981128585548741,50.485964459455126,266.05245577854714,0.06052838257471187
0.0627808921397817,250.402490689605,0.19932933254380691,50.48114212302437,266.12298244912176,0.060888955949825005
0.0631706576246631,250.399038976711,0.20056683795830535,50.48044625770495,266.2169109374535,0.061255629865128135
0.0635569097870607,250.368344201169,0.20179318857391773,50.47425819095567,266.28098246709845,0.06161886601494168
0.0639405666945144,250.369947945355,0.20301129925508318,50.474581505783576,266.37874430025704,0.061979530989498426
0.0643207662050687,250.385278993162,0.2042184327010931,50.47767224502146,266.490251984472,0.06233681748314612
0.0647065876189502,250.326380226379,0.2054434156901669,50.465798253638006,266.5241460818318,0.06269925661988336
0.0650877339807565,250.268572650728,0.20665355538890187,50.45414424638677,266.55798693116225,0.06305717509305221
0.0654659384422915,250.231832845311,0.20785435455427548,50.4467375016147,266.6134946106639,0.06341220437056155
0.0658481721763027,250.188344374764,0.20906794665976108,50.43797022595243,266.66278955165757,0.06377088799791125
0.0662234531799925,250.186454976799,0.21025946384647615,50.43758932332268,266.75466596422336,0.06412292214451533
0.0665988182087398,250.129696422089,0.21145124781274882,50.426146798693146,266.78803860271097,0.06447491118519462
0.0669843349314942,250.103367751063,0.21267526340749404,50.420838938614295,266.85637550399485,0.06483629079806097
0.0673712849089501,250.154705457782,0.21390382958591656,50.43118862028885,267.00794939049274,0.06519888265304359
0.0677674341120281,250.224585909817,0.2151616033056892,50.4452765194191,267.18166404867003,0.06556995850314604
0.0681611843411109,250.223434655721,0.2164117602830271,50.44504442659336,267.27896031175555,0.06593865081818083
0.0685552091047068,250.154382410472,0.2176627889074441,50.431123493951155,267.3037684050807,0.0663074641705479
0.068942955198327,250.075323218319,0.21889388275468818,50.41518516081311,267.3162550231667,0.06667026784855687
0.0693364063735293,250.052277232603,0.2201430902359555,50.41053909009276,267.39000354142917,0.06703827512273602
0.0697275872299996,250.026039554603,0.2213850894552487,50.405249574207964,267.4597520374179,0.0674040246860972
0.0701229359968539,250.004575747158,0.22264032179001111,50.40092247062705,267.53563061119655,0.06777353532907088
0.0705201649770008,250.000452952821,0.2239015238019775,50.40009131528872,267.6305261393789,0.06814466584076224
0.0709109219207362,249.960260803927,0.22514217709833742,50.39198857807169,267.68517334108117,0.06850961519679168
0.0713066038156294,249.942524210782,0.2263984671146233,50.38841288089366,267.7650767613586,0.06887902856834636
0.0716998010611812,249.869836390606,0.22764686836925033,50.37375901634617,267.7854539510023,0.06924598710759221
0.0720910332660721,249.83237141555,0.2288890306197789,50.36620607737488,267.84304521421006,0.0696109781346734
0.0724865750181589,249.774476772249,0.23014487568265452,50.354534517285394,267.879773120422,0.06997985427610477
0.0728958709304263,249.811410324076,0.23144439020410346,50.361980321333725,268.02163064800766,0.07036141414018038
0.0732967340404073,249.774389215897,0.23271713057829319,50.354516865924836,268.0820361923598,0.07073497158671532
0.0737012613943817,249.730029532853,0.23400150492716187,50.34557395382317,268.1354477174805,0.07111180226808665
0.0740905322768704,249.648811684094,0.23523743997906352,50.32920043551335,268.1454250240567,0.07147428701907418
0.0744867815643784,249.594799977389,0.2364955314669014,50.31831167544162,268.1863133229095,0.07184313508374267
0.0748774776164786,249.573483001032,0.23773599143231955,50.314014173008054,268.2609158881084,0.07220668077380847
0.0752732588949932,249.553080857704,0.23899259699160338,50.30990110091313,268.3377545211491,0.07257482359864743
0.0756787069993233,249.565294448527,0.24027989472285147,50.31236336082305,268.4520732442969,0.07295181770689431
0.0760812182124686,249.547638869442,0.2415578678245878,50.30880399607952,268.53352723667433,0.07332594050110022
0.0764880750260008,249.514290430193,0.24284963820755254,50.30208095072692,268.59915819667697,0.07370396021889067
0.0769039875817923,249.520891633653,0.24417016057219054,50.30341175334445,268.7100431852452,0.07409024617971056
0.0773089901052055,249.481970186906,0.24545604358402748,50.295565189680254,268.7691693515127,0.07446625591726197
0.077720890817278,249.461587102928,0.24676382834485763,50.29145595995029,268.84996387725954,0.0748485250641863
0.0781328122335219,249.42352061542,0.24807167884143203,50.28378175606868,268.91168171828855,0.07523066734097793
0.0785529569839797,249.393836694827,0.24940563842413552,50.277797477677126,268.98446002078543,0.07562028808385077
0.0789710758561522,249.352125709653,0.25073316584328326,50.26938854306604,269.0437313439628,0.07600787948125119
0.0793938244418235,249.293430211073,0.2520753926027896,50.25755553055232,269.08578904375094,0.07639960989812279
0.0798048259086738,249.248696214378,0.2533803222600393,50.2485371568186,269.1399450237304,0.07678030805366076
0.0802286834375621,249.200988801459,0.25472606991425967,50.23891934237414,269.1940560443387,0.07717276264521634
0.0806471708333717,249.13944024905,0.2560547673959551,50.22651115420848,269.2318312481458,0.07756009392129552
0.0810626306600945,249.090599096459,0.2573738523458,50.216664777846134,269.28253833191695,0.07794447468466258
0.0814835024001935,249.025918741318,0.25871012012061434,50.20362521824971,269.3174227887866,0.07833371192587414
0.0819039329068264,248.990663704973,0.26004498697917383,50.19651780292256,269.3839783194913,0.07872238988994518
0.0823151281324095,248.902109472622,0.26135053182040013,50.1786652696806,269.3905185062879,0.07910238398382716
0.0827219012666871,248.774827193114,0.2626420365217315,50.153005162131784,269.3539538858199,0.0794781495098116
0.0831176595738596,248.679448468113,0.2638985691470042,50.133776811171586,269.3491022089008,0.07984360438350838
0.0835247365147082,248.632359278076,0.2651910384341985,50.12428363046013,269.3993115758076,0.08021937192721887
0.0839404156750447,248.673609969703,0.2665108197682669,50.132599769892124,269.5473761579738,0.08060293441726651
0.0843640915034122,248.694698990561,0.26785599052333375,50.13685131649709,269.67560133261424,0.08099372439381897
0.0847804756176285,248.699514920956,0.2691780100859705,50.137822208064726,269.78437808182815,0.08137763990193385
0.0852026933256957,248.679104012534,0.27051855130908387,50.133707368926856,269.86723344822275,0.08176678366990235
0.0856375140894121,248.649689334815,0.2718991072338834,50.1277773698987,269.9434306085532,0.08216738502973175
0.0860839069778377,248.611087640586,0.2733164046546347,50.11999526834214,270.0125013826972,0.08257848093768927
0.08652254581857,248.575073004808,0.27470908297395974,50.11273471776929,270.0824211482208,0.08298227136750003
0.0869467637062955,248.535991453216,0.2760559747674882,50.10485587696835,270.14539157460865,0.08337263150854592
0.0873802676503764,248.449768341728,0.2774323497899451,50.08747329769237,270.1593755971022,0.08377137920709635
0.0878072236379163,248.398379510549,0.27878793505038424,50.07711330932668,270.2095515715278,0.08416394857845697
0.0882570132047777,248.312744133289,0.2802160169251692,50.05984921727106,270.22808527117525,0.08457734590896926
0.0887016646436739,248.263342282686,0.2816277852436646,50.0498898041895,270.28471401316244,0.08498585292346074
0.089153111722979,248.235841548349,0.2830611297204583,50.04434565614715,270.36683926355664,0.085400432527822
0.0895956127574773,248.173777652559,0.2844660705049904,50.0318335747559,270.40905933167795,0.08580662993426057
0.0900442395999394,248.09245834311,0.28589046072980756,50.015439601970975,270.43175510509496,0.08621828220636618
0.0904914716766843,248.039923570491,0.2873104225734726,50.00484859181099,270.485421288957,0.08662848606654894
0.0909353845464057,247.939349304553,0.2887198459348381,49.98457281979789,270.4858093777481,0.08703547920004116
0.0913776991291688,247.868473478366,0.2901241947351109,49.97028425323859,270.5181242714785,0.08744084229127531
0.0918075726591894,247.793035499628,0.29148904319292634,49.955075956725004,270.5423126107012,0.08783464628137266
0.092241450558336,247.717781698214,0.2928666055227168,49.93990479035995,270.56762921115046,0.08823196145172087
0.0926808704614423,247.630354805125,0.2942617637150793,49.9222795287132,270.5809516411398,0.08863419077109154
0.0931235060452196,247.559541706112,0.2956671316935722,49.90800360795218,270.6131541847329,0.08903920010732061
0.0935625420542684,247.525340183606,0.2970610710223021,49.90110858101497,270.68444023403174,0.08944075387891016
0.0940028243611497,247.508943893128,0.2984589673466503,49.89780308885461,270.77548367372736,0.08984328567940912
0.0944485711666263,247.487924283617,0.2998742134540385,49.89356553557718,270.8628051131988,0.09025064844976959
0.0948978958522694,247.437595697744,0.3013008193309553,49.883419292665195,270.9189028842045,0.09066111312379038
0.0953537614254969,247.376656634653,0.30274819252595264,49.871133977546044,270.9649513336308,0.09107738088762958
0.0958085108212016,247.352543845575,0.3041920218573151,49.86627283926792,271.05102271925557,0.09149245685712179
0.0962669594519256,247.327517468869,0.30564759625986376,49.86122752172399,271.13698556439005,0.09191073500823937
0.0967205333949278,247.280806029156,0.30708769352889576,49.85181049547785,271.19793748662363,0.09232439350009054
0.0971841266388072,247.224627704744,0.3085596020782128,49.840484945276394,271.2509372318338,0.0927470128228212
0.0976609211047797,247.148385449818,0.3100734245076755,49.82511450668331,271.28512442240634,0.09318148037119116
0.0981355519580671,247.087283633436,0.311580377466863,49.81279638050069,271.3353305946227,0.0936137889813033
0.0986134486294129,247.023876487007,0.31309769939838594,49.80001349978061,271.3837528411969,0.09404888345842127
0.099081787354479,246.954319366045,0.3145846748504708,49.785990784194674,271.42299472374157,0.09447509244726304
0.0995546353010842,246.917738877244,0.31608596708094233,49.778616157652394,271.49954432053636,0.09490522082048831
0.100032039846584,246.797310633167,0.3176017265129042,49.754337823646466,271.48494904445374,0.09533930651339627
0.100515625498179,246.723236067938,0.3191371109567183,49.739404391296304,271.5227764662416,0.09577882042804158
0.10099848343262,246.646653408924,0.32067018489856847,49.723965327239085,271.55759134695643,0.09621748029419921
0.101477412732319,246.582463063521,0.3221907854251128,49.71102455360584,271.60501344036976,0.09665238113291581
0.101945937494772,246.557288452681,0.3236783515459011,49.705949352060486,271.6928023701585,0.0970776509926238
0.102437084799309,246.480085363748,0.32523774423780605,49.6903852093316,271.7287867694952,0.09752326076887138
0.10292532781536,246.35005372967,0.326787915813768,49.66417083190147,271.7057137671278,0.09796603880955522
0.103416364365615,246.242724713484,0.3283469568608276,49.64253330223837,271.7082520548355,0.09841115260140579
0.103893800345644,246.136565868862,0.3298628160974197,49.62113167916258,271.708629101004,0.09884374788874462
0.10437248522095,246.078220138516,0.33138264057651623,49.609369179924826,271.7620155331209,0.09927728698313044
0.104851855552056,246.017762950649,0.3329046413777778,49.59718101085084,271.8131818947904,0.0997112586081774
0.105343925930734,245.935859627407,0.3344669648300804,49.580669300885255,271.843708607708,0.10015653172916597
0.10583702322714,245.85334370923,0.3360325487461695,49.56403409178077,271.87372975785377,0.10060253530455637
0.106335681263388,245.789550835611,0.33761578801125686,49.551173448459174,271.92575017113785,0.10105336633025501
0.106824869530578,245.721134516843,0.33916896075958514,49.53738071859555,271.97026265251037,0.10149543843838225
0.107313436448307,245.627192415955,0.3407201607233747,49.51844199105653,271.98629051926065,0.10193675407285654
0.107793251158073,245.530759704177,0.34224357242688175,49.499001156362084,271.99731855200184,0.10236997448608078
0.108286765033128,245.474521348331,0.34381047898018136,49.48766350382353,272.0561631631973,0.10281536804552603
0.108792087700819,245.472709937631,0.34541487845010027,49.487298323426415,272.17819852532347,0.10327121351608126
0.109294212941529,245.44217183026,0.3470091260893545,49.48114184098042,272.26758082310783,0.10372396889276977
0.109797880085832,245.328852629094,0.3486082692725166,49.45829669002536,272.265440571658,0.10417790873107957
0.110308819597808,245.24266516127,0.35023050222304036,49.44092129651204,272.29509407023016,0.10463819248326994
0.110818021290318,245.107395910651,0.35184721759675963,49.41365101558725,272.2697125290919,0.10509670002282791
0.111325055331828,245.050124960533,0.3534570506785539,49.40210519204346,272.33034368083565,0.10555304692113822
0.11183360176027,244.97330134026,0.35507168558885727,49.38661755019642,272.3695479642452,0.10601054592660938
0.112354207546579,244.910612490123,0.3567246089603883,49.3739794780088,272.42735027619807,0.1064786770742024
0.112882773551479,244.841423140519,0.35840280602594576,49.36003090512863,272.47980206491206,0.10695374199477546
0.113401723141482,244.775350585788,0.36005047097420534,49.34671067809486,272.5332971247767,0.10741994440526971
0.113924631895988,244.663329312159,0.3617107062697619,49.32412718933126,272.53650904249355,0.10788948382676523
0.114435671313459,244.52979294898,0.3633332564202323,49.29720625851437,272.5127239612376,0.10834815240535568
0.114946050007533,244.42812230537,0.36495370877391725,49.276709456762596,272.52416947513046,0.10880601809799091
0.115457862848018,244.321040493208,0.3665787145424571,49.255121763430736,272.52982567735785,0.10926495994840517
0.115976170081649,244.262038515868,0.36822434000923554,49.243226964798986,272.5906142392746,0.10972951075770848
0.116502827615713,244.198023440813,0.36989647767988876,49.2303215256679,272.64778366983586,0.11020132486604003
0.117036329436177,244.116743054055,0.37159034595986196,49.2139353996975,272.68727061501596,0.11067904367291716
0.117578259764668,244.020184478051,0.3733109747528209,49.19446919077508,272.71165311643347,0.11116407616284575
0.118121084939441,243.950397699017,0.3750344446827252,49.18040017612183,272.76608334663297,0.11164967382312647
0.118663998065524,243.854851995824,0.37675819385803866,49.16113816235812,272.79164368132507,0.11213511441450884
0.119199796259103,243.774491139933,0.378459353122652,49.144937413810496,272.8323608169795,0.11261396232757288
0.119719221878853,243.641418822265,0.3801085294653583,49.11811003456863,272.80997990112627,0.11307795912679709
0.12024887509285,243.517723058381,0.38179017841979873,49.093172968569604,272.8004553213235,0.11355087052636959
0.120778565380409,243.366688698633,0.3834719450827986,49.06272444164441,272.76016822103446,0.11402359146486106
0.12131168747539,243.196643937974,0.38516460773436323,49.02844341789556,272.69923920244116,0.11449914957796488
0.12184276921817,243.09627681832,0.3868507922676897,49.008209406573314,272.71580037249095,0.1149726628941063
0.122383329682741,243.017119586385,0.38856707174270266,48.99225130861522,272.75836385127565,0.11545439731051792
0.122927455434576,242.987780594306,0.39029467100477877,48.98633656781209,272.8576501644591,0.11593907476906264
0.123488771082621,242.913986874666,0.3920768481873217,48.97145975393267,272.9111365925984,0.1164388180072934
0.124044755503865,242.783550122993,0.39384209872477133,48.94516370479539,272.89957623836005,0.11693356874271817
0.124597078809699,242.633044411911,0.39559572522079434,48.91482175344126,272.8644129683391,0.11742481933542107
0.125160464461348,242.490429382024,0.39738447466477983,48.886070563416034,272.84064415090984,0.11792566056172185
0.125705231014456,242.369425763132,0.39911410847089773,48.86167623384741,272.83653041952755,0.11840971126704802
0.126258375599562,242.198904424139,0.4008703425286093,48.82729913190642,272.77854466872435,0.11890096662713096
0.126814169274866,242.061804861116,0.4026349874476995,48.799659860000986,272.7586715577532,0.11939433173234443
0.127359549881029,241.880539345694,0.404366570872267,48.763116732091916,272.6863359617421,0.1198782169024799
0.127919941902075,241.730838872438,0.40614581553908813,48.7329371166835,272.6530337369401,0.1203751770660614
0.128473594051455,241.587092593679,0.4079036611133696,48.70395786688569,272.6246546556306,0.12086591784480352
0.129024967412103,241.410220218988,0.40965427153342704,48.66830039614798,272.55816601569154,0.12135439954842372
0.129582146629773,241.252918170756,0.4114233155495292,48.63658830322441,272.51498918801957,0.12184778259455746
0.130138214695623,241.07651878008,0.41318883165860304,48.60102618606413,272.4497865391554,0.12233993913444706
0.130700474548304,240.890528784459,0.41497400669086515,48.56353060294694,272.3750352107797,0.12283732965323807
0.131250371060318,240.686372406566,0.41671992811650965,48.5223726771637,272.2765480940897,0.12332354404106602
0.131795618256534,240.416114073042,0.4184510879644954,48.46788859712527,272.101904466132,0.12380541423666998
0.132331749033438,240.187465264,0.4201533031811656,48.421792997222404,271.97189263829324,0.12427900136314517
0.13288212510724,240.039043942694,0.42190074721548704,48.39187125884712,271.9359422105094,0.12476493877586846
0.133438859676639,239.899278198906,0.42366837947332875,48.363694484899455,271.9111643190168,0.12525625009878857
0.134022831447249,239.792929060312,0.42552248984501556,48.342254498558894,271.9306563740043,0.125771338654249
0.134603078302663,239.555068846989,0.427364773610955,48.29430187955299,271.7999185368001,0.1262828790237505
0.135181973997649,239.241583498103,0.42920276744253555,48.23110323321757,271.5827330176999,0.1267929675953103
0.135753184033742,238.947892994501,0.43101635930713084,48.1718952276914,271.3858302866584,0.12729602911700924
0.136324452829399,238.625937821877,0.43283013773334184,48.106989064890406,271.15648822634654,0.12779888940525505
0.136905335038079,238.366487605828,0.4346744387459008,48.05468390133493,271.000131453354,0.1283099527605072
0.13749799007012,238.102244444108,0.436556118472631,48.00141247993218,270.8408244863573,0.12883110487008434
0.138089242757863,237.821600451718,0.438433345756215,47.94483465106635,270.66220516955883,0.12935075333050663
0.138680121331274,237.496743307843,0.4403093852267949,47.87934345086115,270.4328204855571,0.12986980334584558
0.139260676419919,237.066635562791,0.44215264763324275,47.792633729458665,270.0806955878597,0.13037952256399882
0.139847905052861,236.684529223888,0.4440170985428336,47.71560109153582,269.78436479427137,0.1308948368853177
0.14044275683847,236.326998616054,0.4459057529621422,47.64352292099648,269.5174138170539,0.13141657019681516
0.14104261094968,236.006116820611,0.4478102897652339,47.57883315103518,269.2930357370852,0.13194241544965044
0.141631541475054,235.588523217668,0.44968014418329644,47.49464628068187,268.95528891481786,0.13245841598158403
0.142214165517217,235.129176396301,0.45152997551716395,47.40204196149429,268.5678760062514,0.13296862913041285
0.142805693981844,234.623695433313,0.4534080783923547,47.3001369993559,268.1292950842521,0.13348637384530615
0.143392988947305,234.153219969491,0.4552727399076934,47.205289145849385,267.7291500525521,0.13400014807041163
0.1439961838905,233.664471775693,0.4571878838523375,47.10675750997971,267.31126402218223,0.13452755719199
0.144603265270225,233.202310539428,0.4591153672329643,47.01358580474868,266.9241261119903,0.13505808374978204
0.145216883336706,232.65060627048,0.4610636045940415,46.90236222412877,266.4354022194742,0.13559403683023918
0.145845185108383,232.08236843329,0.46305846271911605,46.78780547615126,265.93046441783514,0.13614251763840388
0.146475900510147,231.45817975425,0.4650609841197167,46.6619690384568,265.36122506419326,0.13669280304269274
0.147093351603802,230.790543576749,0.4670213913420713,46.5273735850726,264.7382981499163,0.1372312224586334
0.147708618431473,230.154391774175,0.4689748635199268,46.39912538167368,264.1501790090744,0.13776744898314208
0.148337491575139,229.45112421305,0.4709715357510663,46.25734664135088,263.4873284179095,0.1383152369013818
0.148958762001566,228.724663693241,0.472944069354972,46.110892200557394,262.7952064362107,0.13885610788448235
0.14958972233908,227.952467575585,0.474947368426579,45.955217463237936,262.05181390672493,0.13940511553662524
0.150212140383405,227.209643918162,0.4769235457173108,45.80546421390146,261.33929084686037,0.13994639526129207
0.150848654108066,226.363992419797,0.47894447679310953,45.634980871831075,260.5106960148518,0.1404996303104656
0.151501306010863,225.594352399001,0.48101664658449,45.479821443638606,259.7721914161245,0.14106657446021148
0.152131274491197,224.569996668614,0.4830167965095505,45.27331132839259,258.7341164742941,0.14161350933287314
0.152768200818372,223.714723635242,0.48503903759833106,45.10088828486479,257.89121946157724,0.14216618102221135
0.153401167052638,222.867279501764,0.48704870539212564,44.93004354755563,257.05538027518105,0.14271511403552653
0.154052141305516,221.991271897843,0.4891155486450133,44.75344041460515,256.18950268484076,0.14327935017221494
0.15472907918124,221.041237116952,0.49126482640043695,44.56191340277753,255.2427441971401,0.1438657529799953
0.155384989536742,219.943777319016,0.49334734177915585,44.34066550751362,254.11973885640282,0.14443361270779811
0.156013699935097,218.811902120824,0.49534349729393296,44.11247946755812,252.94955656053003,0.1449776213348895
0.156646465375561,217.800735492069,0.49735252756740617,43.90862827520111,251.91845086309914,0.1455248400449667
0.157302434645996,216.717725834239,0.4994352300010373,43.690293528182586,250.80795173890823,0.14609180959904874
0.15795472049682,215.632296080384,0.5015062375774034,43.47147088980542,249.69243513784858,0.14665527691552652
0.158617851683403,214.438789597387,0.5036116790948045,43.230859982833216,248.45260972091378,0.14722778753976454
0.159277054862905,213.230559364626,0.5057046491897234,42.98728076790861,247.19329486699345,0.14779658226416112
0.159941797097765,211.927512523686,0.5078152057854038,42.7245865247751,245.82357973118346,0.14836982894375028
0.160612754771513,210.622289842774,0.5099454963995537,42.46145363230324,244.450916030706,0.1489481025222834
0.161272262007848,209.239043370071,0.5120394318749174,42.182591143406306,242.98349719472054,0.14951618169011896
0.161922908416478,207.843861424867,0.5141052342223176,41.90132246325318,241.49854396329286,0.1500763123532028
0.162589824016531,206.4038934284,0.5162226912524859,41.611024915165444,239.96306613725042,0.15065012346556794
0.163282424152048,204.893222527176,0.5184216966827524,41.30647366147868,238.3486845937383,0.1512456851147807
0.163993771431407,203.408399667152,0.5206802242947172,41.00713337289784,236.7661102693952,0.15185699829098356
0.164698689439176,201.751555706971,0.5229183389693838,40.67311363052536,234.97977252422405,0.15246241789116272
0.165428888708952,200.105801324672,0.5252367216509226,40.341329547053874,233.20908166202685,0.15308916408353987
0.166137913104725,198.424558291052,0.5274878741075019,40.00239095147608,231.3904003142542,0.15369735975443127
0.166836508570228,196.679956255961,0.5297059147104739,39.65067918120174,229.4933534634507,0.1542962480061779
0.167490860122598,194.869782616478,0.5317834808892486,39.28574817548197,227.5086901188156,0.15485688194149055
0.168187037409858,192.998366745701,0.5339938437762991,38.90847073593332,225.4581902736017,0.15545300635454587
0.168884945699028,191.078783152695,0.5362097025944139,38.521482683583315,223.34911306967425,0.15605025651625243
0.169595201884168,189.022142198385,0.5384647659822334,38.10686386719442,221.07939056509804,0.1566577076487448
0.170290467676321,186.966051474422,0.5406722348723192,37.69235597724347,218.80458781959643,0.15725198096872747
0.170968454780124,184.68142029122,0.5428248439268937,37.23177433070995,216.25611734500853,0.15783114555086872
0.171683087483145,182.370055477042,0.5450938027589853,36.765803184171666,213.679909665813,0.15844125141791354
0.172444432188435,179.681184768621,0.5475110721982811,36.223726849353994,210.66620465099112,0.1590908276254123
0.172832832058585,178.415476660162,0.5487442417860073,35.96856009468866,209.25152877442017,0.1594220463513359
0.173023741031351,177.67675118072,0.5493503777745394,35.81963303803315,208.4190473643047,0.15958480904994032