File: example/data/02 processed data/test_ID_116.csv
Strain,Stress_MPa,Displacement(mm),Force(kN),True Stress (MPa),True Strain
2.6958723329159876e-05,0.019143782825867,0.0001384991333593,0.0038593866176947,0.0191446179116404,4.362082288436729e-05
3.7282093317920475e-05,0.3693771135472,0.0001712758330736,0.0744664260911155,0.3693970396488822,5.3943689288177725e-05
5.166965257050787e-05,0.832264048692022,0.0002169563337006,0.1677844322163116,0.832320919544518,6.833036895496133e-05
7.510539442730628e-05,1.38132159757048,0.0002913648140959,0.2784744340702088,1.3814483593060651,9.176423491830498e-05
0.00010654315199569957,2.31476803301562,0.000391179694376,0.466657235455949,2.3150532267956847,0.0001231986136921
0.00013232792172199957,3.52081855002999,0.000473046338257,0.709797019686046,3.521343120210387,0.0001489798746268
0.00015837161177589956,5.05390495307824,0.0005557350541782,1.018867238540573,5.054789561627188,0.000175019345954
0.00019219909194349957,6.84685861716993,0.0006631373037103,1.3803266972214578,6.848288666732851,0.00020884033424
0.00023682036291669957,8.66657932507802,0.0008048098390502,1.7471823919357288,8.668776159191951,0.0002534512923816
0.00027749888376839955,10.5529263145465,0.0009339641427544,2.1274699450125745,10.556030583768209,0.0002941186775868
0.00031080155246589956,12.5384058080956,0.0010397001158689,2.5277426109120733,12.542511692181108,0.0003274109985921
0.00034053326732569957,14.5586202380581,0.0011340983105488,2.935017839992513,14.563820523606417,0.0003571325388656
0.0003836441267262996,16.6365314854843,0.0012709752891457,3.353924747473635,16.6431912084497,0.0004002270761415
0.00043031114301539955,18.6837461392788,0.0014191430658636,3.766643221678606,18.692097291649794,0.0004468743307641
0.00048471360453669957,20.7673320748966,0.0015918708811937,4.186694146299155,20.777744330395844,0.0005012510082146
0.0005244660106862995,22.9517754967056,0.0017180847707187,4.627077940135849,22.96419536944319,0.0005409827041095
0.0005623098792468996,25.1521002754332,0.0018382390533986,5.070663415527333,25.16666266063046,0.0005788053900417
0.0005935393887509995,27.3539128981248,0.0019373927460741,5.514548840261959,27.370604322510804,0.0006100163419006
0.0006471135461051995,29.6055850004222,0.0021074906956737,5.968485936085116,29.625236494887822,0.0006635563948151
0.0006902348725936995,31.8422108955499,0.0022444009072747,6.41938971654286,31.86472008831324,0.0007066481888983
0.0007315406003048996,34.1348318184529,0.0023755465927578,6.881582094600105,34.160371624254694,0.000747923886449
0.0007612229550089996,36.4147405439022,0.0024697880689433,7.341211693650684,36.4430670609822,0.0007775836094571
0.0007934168294492995,38.6787296028114,0.0025720036202912,7.797631887926778,38.71006246346233,0.0008097519427922
0.0008366143700372996,40.994575423776,0.0027091558116581,8.264506405433242,41.029555169368365,0.000852913586769
0.0008868976369790996,43.343809415153,0.0028688051841983,8.738111978094844,43.38297317740594,0.000903152722707
0.0009290428643344995,45.6451673002787,0.0030026162810517,9.202065727736189,45.688334204999066,0.0009452590171867
0.0009670693220614995,47.9605126958514,0.003123350284335,9.66883935948364,48.00769300481689,0.0009832488254229
0.0010032142540964996,50.2747076582592,0.0032381104435461,10.135381063905056,50.32598169161808,0.0010193575835332
0.0010454734525374995,52.6295309121406,0.0033722833985963,10.610113431887546,52.6854306580842,0.0010615728356116
0.0010902069507685995,54.9516935763921,0.00351431225548,11.07826142500065,55.01251795755585,0.0011062578727821
0.0011318066925971996,57.2773533050347,0.0036463914357858,11.547114426294996,57.34313461229642,0.0011478107566814
0.0011712818105803996,59.5358305472802,0.0037717249353825,12.00242343833169,59.60655583125622,0.0011872398133576
0.0012064728039637995,61.8332029123926,0.0038834563393748,12.465573707138349,61.90883331989937,0.0012223884336645
0.0012515117335062996,64.1541911562515,0.0040264549406722,12.933484937100303,64.23554988379351,0.0012673713300303
0.0012989641392080996,66.4772616313638,0.0041771163287754,13.401815944882944,66.56472092429377,0.0013147625110276
0.0013384907868155996,68.7429613181978,0.0043026134349292,13.858581001748677,68.83611860604803,0.0013542364455225
0.0013822499967049995,71.0197779962047,0.0044415489263281,14.317587244034868,71.11912849028568,0.0013979354803864
0.0014283326528810995,73.3045184074191,0.0045878613596872,14.77819091093569,73.41044312158976,0.0014439527021808
0.0014743439554580995,75.6354036638113,0.0047339472453692,15.24809737862436,75.74817658060712,0.0014898965591217
0.0015191391767345995,77.9101519878675,0.0048761720729221,15.706686640754087,78.02980657285028,0.0015346240895544
0.0015659551078701995,80.1935521186931,0.0050248126542776,16.16702010712853,80.32046789049704,0.0015813671384604
0.0016073727724211996,82.4837485353344,0.005156313739227,16.628723704723416,82.61770509780233,0.0016227185032579
0.0016516356235171995,84.7813059788381,0.0052968482914568,17.09191128533376,84.92274651922284,0.0016669086100547
0.0016975915203947995,87.0888829461834,0.0054427582640432,17.557118801950573,87.23817546188786,0.0017127869140372
0.0017331848529419996,89.3784391152623,0.0055557670948805,18.01869332563688,89.53483778960194,0.0017483187037078
0.0017779806755676996,91.6691644908102,0.0056979938317171,18.480503561347337,91.83367798177945,0.0017930352775801
0.0018232382056722995,93.9459800719856,0.0058416864897992,18.939509582512297,94.11883139877536,0.0018382107116189
0.0018620462133061995,96.1868133173208,0.0059649019140369,19.39126156477188,96.36752037460003,0.0018769466972358
0.0019067672489348996,98.4344294480521,0.006106891202158,19.844380976727304,98.6237612122051,0.0019215828763805
0.0019578964289282998,100.664670559925,0.006269226348637,20.29399758488088,100.86343893946868,0.001972612599715
0.0019954469241721994,102.855810789703,0.0063884491710364,20.735731455204128,103.062767992593,0.0020100883931628
0.0020400718958601995,105.044584836041,0.0065301334561458,21.176988302945865,105.26063370464723,0.0020546227631357
0.0020804168437996997,107.207275927592,0.0066582286658537,21.612986827002548,107.43209815051142,0.0020948840920278
0.0021224596176352994,109.416975372727,0.0067917144727818,22.05846223514176,109.65103170507564,0.0021368380032365
0.0021687661365655995,111.604424271772,0.0069387376703855,22.499451933189235,111.84832783803223,0.0021830446107399
0.0022122546116718996,113.763665414997,0.007076813578848,22.9347549476634,114.01723525820594,0.002226437310639
0.0022522768705995995,115.941859297643,0.0072038842509434,23.37387883440483,116.20492441078297,0.0022663697643271
0.0022988471076982996,118.14936064479,0.0073517447537318,23.818911105989663,118.42293668960168,0.0023128334961047
0.0023476877515664994,120.321861081836,0.0075068137980133,24.25688719409814,120.60634417064604,0.0023615601230631
0.0023922936378403996,122.47986995873,0.007648437486933,24.69194178367997,122.77491866071016,0.002406059804014
0.0024453432152550998,124.610911389568,0.0078168698952246,25.12155973613691,124.91770423424757,0.0024589804940806
0.0024839418251239994,126.742083375145,0.0079394204815584,25.55120400842923,127.0590152468376,0.0024974835660674
0.0025310657379946995,128.877612309207,0.0080890389049229,25.98172664153613,129.2059575123386,0.0025444888298191
0.0025783689126999995,130.998160464482,0.0082392264846122,26.40922914963957,131.33810487806764,0.0025916706820442
0.0026265559262954995,133.080382482197,0.0083922202527779,26.829005108410914,133.43214307467403,0.002639731817505
0.0026666330601051997,135.16225828267,0.0085194651526237,27.24871126978628,135.52493864468232,0.0026797024991006
0.0027168568512060997,137.262989379416,0.0086789256893691,27.67221865889027,137.6382004927151,0.0027297906311142
0.0027566658823788997,139.334216424488,0.0088053193633427,28.089778031176785,139.72063603830176,0.0027694903521111
0.0028034099933829998,141.397477961379,0.0089537319157807,28.50573155701401,141.79622917751558,0.0028161040984133
0.0028445768356826994,143.42160428058,0.0090844366400823,28.913795422964927,143.8319678953535,0.0028571543311099
0.0028896395260648994,145.411196033816,0.0092275106820458,29.314897120417303,145.83380496757698,0.0029020874446795
0.0029283219671831996,147.348353694231,0.0093503274325964,29.70542810475697,147.7822923883082,0.0029406570448909
0.0029783113324382995,149.254258206463,0.0095090436672813,30.08965845442294,149.70127088640407,0.0029904983823956
0.0030181190874976997,151.124703666852,0.0096354332895949,30.46674025923737,151.5833342182195,0.0030301864826695
0.0030594830222083996,153.028985075133,0.0097667637823014,30.85064339114681,153.49972458665243,0.00307142441636
0.0031054975401108996,154.895803393274,0.0099128598766418,31.22699396408404,155.37941296635034,0.0031172967688165
0.0031514202269945996,156.719895721775,0.0100586644074975,31.59473097750984,157.21639740273352,0.0031630754760918
0.0031927669240049998,158.528716706522,0.0101899401705056,31.959389288034835,159.03750352181223,0.0032042907476378
0.0032411087441081995,160.384376401582,0.0103434254493332,32.33349028255893,160.90687209939227,0.0032524767534395
0.0032797553715041994,162.218684856994,0.0104661284913155,32.70328686716999,162.75342551822408,0.0032909971458506
0.0033230339759560998,164.012336630483,0.0106035380604503,33.064887064705374,164.56008814350494,0.0033341326243018
0.0033675519904945994,165.743403930545,0.0107448827566101,33.41387023239788,166.3043152511482,0.0033785014727299
0.0034123345264645997,167.460835135431,0.0108870673083148,33.760104363302894,168.03505793342347,0.0034231319701731
0.0034668062249645997,169.181745601066,0.0110600149510523,34.10703991317491,169.7710850139142,0.0034774160502345
0.0035178912267785994,170.892181230624,0.0112222098318118,34.4518637360938,171.49620892082436,0.003528322421005
0.0035676239477370995,172.564492841643,0.011380111220855,34.78900175687523,173.18301350977157,0.0035778787501528
0.0036239735687193997,174.22072115158,0.0115590212674738,35.12289738415853,174.85499548891093,0.0036340255430051
0.0036832462191789994,175.835062086978,0.011747211932683,35.44834851673477,176.48563586320864,0.0036930814422128
0.0037529021121969998,177.410149537638,0.0119683693930152,35.76588614678782,178.0789086569251,0.0037624781567662
0.0038204259586201994,178.938457697638,0.0121827576054088,36.07399307184382,179.62506048706038,0.0038297461609923
0.0038805738559358994,180.431620865209,0.0123737271793862,36.37501476642613,181.13480563721544,0.003889662352649
0.003951879821251499,181.861063607544,0.0126001236192632,36.66319042328088,182.58278703525605,0.0039606889780976
0.0040253376638483,183.205613945409,0.012833352269508,36.93425177139446,183.94613116793275,0.0040338537758264
0.0041038911347725995,184.493786270556,0.0130827595396927,37.19394731214409,185.2540029138144,0.0041120879514143
0.0041843778327338,185.751857025206,0.0133383048057195,37.44757437628153,186.53220817079043,0.0041922411481949
0.004265416479425799,186.921110864637,0.0135956025089666,37.68329595031082,187.72152192726696,0.0042729375164266
0.0043570516206465,187.994611982891,0.0138865440823423,37.899713775750826,188.81684677550305,0.0043641777792418
0.0044585424908578,188.989145430653,0.0142087775952632,38.10021171881965,189.8349107016272,0.0044652215852507
0.0045609843280382,189.852812527831,0.014534030428311,38.27432700561073,190.72189175749395,0.0045672018165028
0.004677694584033099,190.622373677088,0.0149045854910948,38.42947053330094,191.51722327235905,0.0046833735004111
0.004800582932597899,191.28202919571,0.015294755997788,38.56245708585514,192.20348178257936,0.0048056801827879
0.0049241471379007,191.839851302456,0.0156870723496244,38.67491402257513,192.78769559440025,0.0049286444421712
0.0050615512770971,192.307477299921,0.016123330491573,38.76918742366408,193.2840558865375,0.0050653636848594
0.0051968765909045,192.751418826931,0.0165529883629115,38.858686035509294,193.7563359900104,0.0051999961965281
0.005332423545347499,193.080321901662,0.016983349943268,38.924992895375055,194.1131252635564,0.0053348310461162
0.005471079594580099,193.365366055204,0.0174235828995815,38.98245779672913,194.4265054206751,0.0054727398484975
0.0056149836709827,193.608095721666,0.0178804783421598,39.03139209748787,194.698428119278,0.005615848285927
0.0057500820497351,193.865347850314,0.0183094156946986,39.08325412662331,194.98331989522384,0.0057501810759945
0.0058986635262944995,194.05437187834,0.0187811618827747,39.12136137067335,195.20226686174385,0.0058978997229133
0.0060403956400565,194.24888076323,0.0192311613439691,39.16057436186717,195.42545763467663,0.0060387884498503
0.006187645824190799,194.371787757428,0.0196986806785955,39.18535241189748,195.57773036528985,0.0061851413906468
0.006344604462531699,194.489338224046,0.0201970243553278,39.20905058596768,195.72653693301064,0.0063411200484363
0.0065007259831569,194.609717911848,0.0206927101833129,39.23331913102856,195.8780651532988,0.0064962426838027
0.006646214867009899,194.733264374699,0.0211546373895461,39.25822609793932,196.0307483417949,0.0066407790539377
0.0068101880461988,194.793230743158,0.0216752522334709,39.27031531782065,196.12305512417555,0.006803653666297
0.0069700051584553994,194.808304879791,0.0221826715648856,39.27335426376587,196.16936587042423,0.0069623745320176
0.007122916213768,194.789389814148,0.0226681641655031,39.26954098653224,196.1801041026536,0.0071142131327984
0.0072880087329114,194.841148338253,0.0231923329137834,39.2799755049918,196.264398976856,0.0072781218827448
0.007445547912420199,194.868468789191,0.0236925198087238,39.28548330790091,196.3226184134063,0.0074345064066109
0.007610031723662199,194.913985833459,0.0242147559094172,39.294659544025336,196.40053531071533,0.0075977585699661
0.007788828364945299,194.929446229632,0.024782435245491,39.29777635989381,196.45096634888404,0.0077751861638859
0.0079544314866056,194.963780377462,0.0253082251567625,39.30469812409634,196.51785510225145,0.007939493184006
0.0081235379903675,195.028910437809,0.0258451383062065,39.317828344262296,196.61648497764327,0.008107248311939
0.0082986268553869,195.124459943136,0.0264010454526431,39.33709112453622,196.7469763953821,0.0082809083468323
0.0084644839662786,195.172205844363,0.0269276417797243,39.34671669822358,196.82749001580729,0.0084453841543347
0.0086370065499848,195.182038207422,0.0274754009829914,39.34869890261628,196.8710790781076,0.0086164412227128
0.0088165365403749,195.186792320178,0.02804540870248,39.349657331747885,196.91091621433404,0.0087944151105287
0.00899197970243,195.216468383644,0.0286024407420049,39.35564002614263,196.9751038068902,0.0089683069972123
0.0091685775090005,195.288093625719,0.0291631387778663,39.37007967494496,197.0818617441668,0.0091433127867764
0.0093438583824372,195.350210960205,0.0297196555510278,39.38260252957733,197.17879079691613,0.0093169832352521
0.0095218060275052,195.368274185185,0.0302846393241187,39.386244075733295,197.23178842741297,0.0094932651060789
0.0096991729960319,195.35878031386,0.030847779449191,39.384330111274174,197.25685419372925,0.0096689408181799
0.0098784173447187,195.395961661372,0.0314168802562716,39.3918258709326,197.3294204110017,0.0098464446608241