File: example/data/02 processed data/test_ID_128.csv
Strain,Stress_MPa,Displacement(mm),Force(kN),True Stress (MPa),True Strain
-3.46377537126706e-05,-0.896785355652872,-0.00010997486803772914,-0.180791927699619,-0.8967542930225897,-3.4638353613551366e-05
-3.32282126316874e-05,-0.583058502383033,-0.00010549957510560748,-0.11754459408041946,-0.5830391283911391,-3.3228764701028703e-05
-4.35617273832518e-05,-0.154122450916748,-0.00013830848444182446,-0.031071086104816396,-0.1541157370765575,-4.356267622289181e-05
-4.96289490869068e-05,0.327277109437734,-0.00015757191335092908,0.06597906526264719,0.3272608670187324,-4.9630180643929574e-05
-7.27313255537406e-05,1.16035968529818,-0.0002309219586331264,0.23392851255611308,1.160275290800149,-7.27339706048544e-05
-9.01697212074247e-05,2.2604938066518,-0.0002862888648335734,0.4557155514210029,2.260289978555463,-9.01737867411611e-05
-0.0001127533107856,3.99125168556339,-0.00035799176174427995,0.8046363398095795,3.990801658721664,-0.00011275966791804998
-0.0001429033560709,5.80747417869862,-0.0004537181555251075,1.170786794425642,5.806644271148189,-0.0001429135677283757
-0.000168286317267,7.73779805886954,-0.000534309057322725,1.5599400886680994,7.736495893330457,-0.0001683004789980814
-0.0001887293365871,9.73741815861726,-0.0005992156436640425,1.9630635007772395,9.735580422148113,-0.00018874714820942012
-0.0002035409294221,11.8617641682668,-0.0006462424509151675,2.391331656322587,11.859349813763405,-0.00020356164668832734
-0.0002000154910243,14.1223302264507,-0.0006350491840021524,2.8470617736524613,14.119505541636048,-0.00020003549679034152
-0.0001870418709053,16.4716918180238,-0.0005938579401243275,3.3206930705135984,16.46861092196918,-0.0001870593654175875
-0.0001689328877512,18.5073381122959,-0.0005363619186100599,3.731079363438854,18.504211614224005,-0.0001689471585187223
-0.0001451129082908,20.7267431441397,-0.00046073348382329,4.178511417858564,20.72373542616266,-0.00014512343818754998
-0.0001090942928267,23.0730727529062,-0.0003463743797247725,4.651531466985889,23.070555612350883,-0.00010910024404188027
-6.8792513805226e-05,25.4908257727847,-0.00021841623133159253,5.138950475793396,25.48907219480082,-6.879488011870634e-05
-1.77938846797128e-05,28.0835478668612,-5.649558385808813e-05,5.661643249959218,28.08304815144906,-1.7794042992750554e-05
2.04821673391264e-05,30.6636255151963,6.503088130172632e-05,6.181786903863574,30.664253572705327,2.0481957582350097e-05
6.48051040320222e-05,33.2652712594861,0.00020575620530167047,6.706278685912398,33.26742701885072,6.480300427191283e-05
0.0001252684744212,35.9473115148142,0.00039772740628730996,7.246978001386544,35.95181457968721,0.00012526062898113386
0.0001803037626471,38.6342214473874,0.0005724644464045424,7.788659043793299,38.6411873428813,0.0001802875098772869
0.0002280138965317,41.3222122546458,0.0007239441214881475,8.330557990536592,41.331634293275286,0.00022798790531392314
0.0002772444844778,44.0612160962084,0.000880251238217015,8.882741164995613,44.07343182535046,0.0002772060593277131
0.0003288655510823,46.6700725180651,0.0010441481246863025,9.408686619641925,46.6854206971828,0.00032881148665986186
0.0003926649122862,49.3688011193333,0.001246711096508685,9.952750305657593,49.3881865152945,0.0003925878395947864
0.0004541874171201,52.050224512556,0.0014420450493563175,10.493325261731291,52.073865069587875,0.0004540843052352972
0.0005049987158505,54.6387047828482,0.0016033709228253372,11.015162884222198,54.66629725859927,0.000504871246911647
0.0005612192074764,57.229676828251,0.0017818709837375698,11.537502848575402,57.26179522212468,0.0005610617828740596
0.0006173116758445,59.7787368399918,0.0019599645708062875,12.051393346942348,59.815638952210364,0.0006171212173694521
0.0006754940649351,62.2853262386565,0.002144693656168942,12.556721769713151,62.32739960686327,0.0006752660215081613
0.0007364168532493,64.7968814651695,0.0023381235090665273,13.063051303378172,64.84459898071846,0.0007361458314069866
0.0007916246098333,67.2261460451373,0.0025134081362207274,13.552791042699681,67.27936391677088,0.0007913114403361722
0.0008476223700882,69.6654407595449,0.0026912010250300347,14.044552857124252,69.72449074555473,0.000847263341113374
0.0008966751861437,72.0611054312594,0.0028469437160062476,14.527518854941896,72.1257208363857,0.0008962734131042853
0.0009492036386624,74.4381001930385,0.0030137215527531198,15.00672099891656,74.50875710859685,0.000948753429759403
0.0010063263061275,76.7454272305961,0.0031950860219548123,15.471878129688175,76.82265817289326,0.0010058202992538777
0.0010720467122364,79.054620232865,0.0034037483113505697,15.937411438945585,79.13937047857276,0.0010714724805253788
0.0011272158842117,81.3289926529245,0.003578910432372147,16.39592491882958,81.42066798528981,0.0011265810534030376
0.0011812865691284,83.5623490406764,0.0037505848569826697,16.84616956660036,83.66106012128296,0.0011805893991334562
0.0012357139989699,85.7760538827601,0.003923391946729432,17.292452462764437,85.88204855331941,0.0012349511328177802
0.0012988330813844,87.9401761029963,0.00412379503339547,17.728739502364057,88.05439571290164,0.001297990327349978
0.0013595556310746,90.088376679763,0.004316589128661855,18.161816738640223,90.21085683957234,0.0013586322721280877
0.0014160727691643,92.2091335367461,0.004496031042096652,18.589361321008013,92.33970837981572,0.0014150710836487636
0.0014673850969639,94.3134651592979,0.004658947682860383,19.013594576114457,94.4518593325157,0.0014663095394953567
0.0015171754113525,96.3859572959557,0.004817031931044187,19.43140899086467,96.5321917003648,0.0015160256635040055
0.0015786196061858,98.4266198294366,0.005012117249639915,19.84280655761442,98.58199802126994,0.0015773748960323083
0.0016372726751938,100.408391393418,0.005198340743740314,20.24233170491307,100.57278730900661,0.0016359338054847089
0.001697068397057,102.42575934875,0.005388192160655975,20.649033084708005,102.59958286798533,0.00169563000362291
0.0017583332980525,104.389967296971,0.005582708221316687,21.045017407069356,104.57351965245186,0.001756789239773324
0.0018188312457085,106.361229161323,0.005774789205124487,21.442423798922714,106.55468228825359,0.0018171791750801886
0.0018776307407827,108.275550831706,0.005961477601985073,21.82835104767193,108.47885233442278,0.0018758701956079382
0.0019404564007609,110.184776298394,0.006160949072415858,22.213250901756233,110.39858505282861,0.0019385761472129354
0.0020050390471178,112.13559523949,0.006365998974599014,22.606536000281185,112.36043148651697,0.0020030316391672492
0.0020638536939167,113.990639184036,0.006552735478185523,22.98051285950166,114.22589918578788,0.002061726873676121
0.0021213186309345,115.824805429117,0.0067351866532170375,23.35028077450999,116.07050674679816,0.0021190718114864914
0.0021725997856681,117.637996572953,0.006898004319496217,23.715820109107327,117.89357685909383,0.002170243103554493
0.0022364833810707,119.448161055446,0.007100834734899473,24.080749268777915,119.71530488254595,0.002233986174727619
0.0022945915778799,121.183900932485,0.007285328259768682,24.430674427988976,121.4619684909393,0.002291963022830757
0.002361137480104,122.845231107335,0.0074966114993302,24.765598591238735,123.13528558675456,0.002358354375005654
0.0024260734941719,124.46310263495,0.007702783343995782,25.091761491205922,124.76505926925505,0.002423135329049176
0.0024970631773186,126.062181716438,0.007928175587986554,25.4141358340339,126.37696694845458,0.002493950695362225
0.0025763588840679,127.615033089342,0.008179939456915582,25.727190670811346,127.94381521358235,0.002573045760827774
0.0026673845259714,129.101377386207,0.008468945869959195,26.02683768105933,129.44574040252857,0.0026638333693319457
0.0027434321050401,130.565603354165,0.008710396933502318,26.322025636199665,130.92380122222076,0.002739675763792407
0.0028460110068412,131.996126358035,0.009036084946720811,26.61041907377986,132.37178878651036,0.0028419687851709728
0.0029349648258615,133.344948732584,0.00931851332211026,26.882341664488933,133.7363114668204,0.002930666225370482
0.0030443362684906,134.566265793871,0.009665767652457654,27.128559184044395,134.97593075734264,0.0030397116603637004
0.0031533450371305,135.741186126768,0.010011870492889338,27.365423123156432,136.1692249223751,0.0031483836718638712
0.0032595761727413,136.848831746732,0.010349154348453628,27.588724480141174,137.29490093796113,0.0032542752703348353
0.0033798149050642,137.872726168574,0.010730912323578834,27.795141595584518,138.33871046348037,0.003374116167509928
0.0035166771364778,138.736085272262,0.011165449908317015,27.969194790888018,139.2239752913434,0.0035105080862447902
0.0036532035884955,139.489523726736,0.011598921393473212,28.121087983309977,139.99910735537205,0.0036465468476264743
0.0038041146731945,140.178322004306,0.012078064087392537,28.259949716068093,140.71157641590636,0.0037968973269221938
0.0039457461506538,140.789726981018,0.012527744028325814,28.383208959373228,141.34524750430495,0.003937982110896424
0.0041058562034154,141.293033307805,0.013036093445843893,28.484675514853485,141.8731621851112,0.004097450177267935
0.0042762345223023,141.675938791362,0.013577044608309802,28.561869260338582,142.2817783318012,0.00426711741347999
0.0044560530554415,141.979694020155,0.014147968451026761,28.62310631446325,142.61236306950417,0.00444615424654308
0.0046433061224713,142.247394467396,0.014742496938846378,28.677074724627033,142.90789266503205,0.004632559231161201
0.004836573229722,142.47099143594,0.015356120004367351,28.722151873485505,143.160062819131,0.0048249145862283745
0.0050302286511017,142.63313684512,0.015970975967247895,28.75484038797619,143.35061413667484,0.005017619318499972
0.0052482787734091,142.769920176862,0.016663285105573893,28.78241590765538,143.51921651840755,0.005234554556435695
0.0054563131492309,142.862089042745,0.017323794248808106,28.80099715101739,143.64158933771552,0.0054414813992944185
0.0056637041310761,142.925226872413,0.017982260616166618,28.813725737478457,143.73471307028527,0.005647725661992171
0.0058781430888567,142.951588149581,0.018663104307120024,28.81904017095553,143.79187803950353,0.0058609342103395
0.006092160038733,142.958823169674,0.019342608122977275,28.820498751006276,143.82975119937257,0.00607367785804726
0.0063087999751498,142.958307320342,0.020030439921100613,28.820394755780946,143.86020268601203,0.006288982801305042
0.0065329797364545,142.937296251708,0.020742210663243037,28.816158924344336,143.871102711704,0.006511732313453546
0.0067441312310651,142.879750361203,0.02141261665863169,28.80455767281853,143.8433501479008,0.006721491312087913
0.0069681894060884,142.849014524589,0.02212400136433067,28.798361328157142,143.8444135142694,0.006944023769829422
0.0071977280667814,142.787256189211,0.022852786612030943,28.78591084774494,143.8150000306628,0.007171948053221798
0.007415253347395,142.747476066715,0.023543429377979125,28.777891175049746,143.8059847664509,0.007387895516546706
0.0076404707177019,142.677383290626,0.02425849452870353,28.763760471390206,143.76750565973634,0.007611430149911822
0.0078616678946811,142.603787281327,0.02496079556561249,28.74892351591552,143.7248908974565,0.007830926000230871
0.0080849869471298,142.534010704677,0.025669833557137114,28.734856558062884,143.68639632074638,0.00805247854263162
0.0083146872504532,142.468393960101,0.026399132020188905,28.72162822235636,143.6529740989536,0.008280310660694594
0.0085392194752138,142.387523178112,0.02711202183380381,28.70532467270738,143.60340148906198,0.008502966575373952
0.0087638494719938,142.323835242193,0.027825222073580316,28.69248518482611,143.57113991053242,0.008725669848041353
0.008987589232142,142.266378882137,0.02853559581205085,28.680901982638815,143.54501065707393,0.008947441228572777
0.0092300905510289,142.221938139877,0.029305537499516754,28.671942728999205,143.53465950725092,0.009187753581876524
0.0094660350032944,142.190912948705,0.03005466113545972,28.66568805045893,143.53689710782785,0.009421512839006026
0.0097035575714476,142.163524835044,0.03080879528934613,28.66016660674487,143.5430167828408,0.009656780416452009
0.009934089150804,142.106952059596,0.0315407330538027,28.648761535214557,143.51865519030505,0.009885070457224032
0.0101841740928409,142.03750205607,0.03233475274476986,28.634760414503713,143.48403670472126,0.01013266481629197
0.0104384696373955,141.97890213576,0.03314214109873071,28.622946670569213,143.46094459485488,0.01038436500057543
0.0106870943910705,141.917331350282,0.03393152469164883,28.610534000216855,143.43401526615128,0.010630391036121034
0.0109222577407255,141.848528363819,0.03467816832680346,28.596663318145914,143.39783455075127,0.01086304068276799
0.0111711988941936,141.74297913819,0.035468556489064676,28.57538459425911,143.32641814999826,0.011109261898616263
0.0114156920443806,141.6585457475,0.0362448222409084,28.558362822696,143.27567608120827,0.011351024714812957
0.0116587131690559,141.585847782617,0.03701641431175248,28.54370691297559,143.23655657071217,0.011591274035567548
0.0118968624351568,141.514157949919,0.03777253823162284,28.52925424270367,143.1977324196762,0.011826651081863067
0.012137742480789,141.45650886104,0.03853733237650508,28.517632186385665,143.17347153782674,0.012064670774001078
0.0123890007038958,141.385165398576,0.03933507723486916,28.503249344352923,143.13678631221939,0.012312885054442406
0.0126430989578843,141.306563207001,0.04014183919128265,28.487403142531402,143.09311606902565,0.012563842316171244
0.0128894675234172,141.238539339756,0.04092405938684961,28.47368953089481,143.05902890563067,0.012807105318529069
0.0131446475728053,141.155843438453,0.041734256043656826,28.457018037192125,143.01128725329352,0.01305900635892709
0.0133984768574984,141.075196965638,0.04254016402255742,28.440759708272626,142.96538972734913,0.01330951105627166
0.0136500766059002,140.997137959244,0.043338993223733135,28.425023012583587,142.92175969360034,0.013557753506373811
0.0139041696094297,140.897964511627,0.044145738509939296,28.405029645544005,142.85703370782008,0.013808393414365423
0.0141639987268585,140.80929479283,0.04497069595777573,28.387153830234528,142.8037174650055,0.01406462653601978
0.0144218819423517,140.720232837855,0.045789475166966645,28.36919894011157,142.74968342274278,0.014318875783576658
0.0146801447962823,140.633539361591,0.0466094597281963,28.351721535296747,142.69806008263282,0.014573434550875747
0.014935149162521,140.534852384395,0.047419098591004176,28.331826240694035,142.6337613672888,0.014824718001822777
0.0151919106373338,140.410508812116,0.04823431627353481,28.30675857652259,142.54361271453223,0.015077669140957059
0.0154505715070874,140.322719684604,0.04905556453500249,28.289060288416167,142.49078589915996,0.015332426808470724
0.0157045670906031,140.241242097442,0.049862000512664845,28.272634406844308,142.44367009283079,0.01558252644883103
0.0159501171970937,140.131819701889,0.05064162210077249,28.25057485190082,142.36693864917612,0.015824250704025863
0.0161963093373201,140.025377610767,0.05142328214599132,28.229116126330627,142.29327194162605,0.016066548343818165
0.0164478802328389,139.929809818687,0.0522220197392635,28.2098496594473,142.2313585715887,0.016314079021439186
0.0167003077742372,139.855801000054,0.053023477183203105,28.194929481610885,142.19143592076736,0.01656239101776511
0.0169604645827564,139.795201286571,0.05384947505025157,28.182712579372716,142.1661928468312,0.016818241760892576
0.0172146306349764,139.717171484873,0.054656452266050065,28.166981771350397,142.12235098534873,0.017068137705583044
0.0174710770879874,139.634740738141,0.05547066975435999,28.15036373280923,142.0743100577382,0.017320212464250268
0.0177209598253547,139.572374330574,0.05626404744550117,28.137790665043724,142.04573076881547,0.01756577429241271
0.0179773926876764,139.497527793277,0.05707822178337257,28.122701603124643,142.0053296293768,0.017817710305782854
0.0182356323480106,139.434458762525,0.05789813270493366,28.10998688652504,141.97713428916225,0.01807135730493621
0.0184823036297234,139.336547626146,0.058681314024371795,28.090248001431032,141.91180800608984,0.01831358159977997
0.0187438197569007,139.251515444152,0.05951162772815972,28.073105513541044,141.8616207505125,0.018570319058240414
0.0190072024262401,139.138648098081,0.06034786770331231,28.050351456573132,141.7832845477946,0.018828822347345623
0.0192613934178234,139.041643320904,0.06115492410158929,28.030795293494247,141.7197791143686,0.01907824089151537
0.0195285205686301,138.938562779036,0.06200305280540056,28.01001425625366,141.65182736004232,0.019340285696134846
0.0197854975341802,138.84507081687,0.06281895467102212,27.991166276680993,141.59218962315026,0.019592308645645377
0.0200488234074237,138.738294930638,0.06365501431857024,27.96964025801662,141.51983450554943,0.019850492236344643
0.0203135015453648,138.655102486145,0.06449536740653324,27.952868661206836,141.47167312477004,0.020109934528714877
0.020566974264412,138.547889606429,0.0653001432895081,27.931254544656092,141.397400486353,0.020358329986807328
0.0208205765145761,138.445042021112,0.06610533043377911,27.910520471456177,141.32754761157625,0.020606790649136827
0.0210818484808334,138.333773283743,0.06693486892664605,27.88808869400259,141.25010493189285,0.020862700984993196
0.0213385942165354,138.23202480229,0.06775003663749989,27.867576200141666,141.18170188727612,0.02111411419227112
0.0216056558034054,138.139586537337,0.06859795717581214,27.848940645927144,141.12418289688745,0.02137556194189885
0.0218651221653248,138.042960011659,0.06942176287490623,27.829460738350456,141.06128619637698,0.021629508674204583
0.0221274994420726,137.972475316146,0.0702548107285805,27.815251023735033,141.02546118672538,0.021886238835962808
0.0223860810961424,137.897747213079,0.07107580748025212,27.80018583815672,140.98473736516632,0.022139190597115294
0.0226512152609305,137.847229629165,0.07191760845345432,27.790001493239664,140.96963690061813,0.022398485786250186
0.0229118028389673,137.796335203306,0.07274497401372118,27.77974117698649,140.95349766741637,0.022653269019170124
0.023167080039299,137.757672714769,0.07355547912477432,27.771946819297433,140.9491157445796,0.022902797230220467
0.0234228936470105,137.698242947127,0.07436768732925833,27.759965778140806,140.92353424705777,0.02315278732333426
0.0236802101047698,137.627995595205,0.07518466708264411,27.745803911993328,140.88705544719778,0.023404183023573187
0.0239407497143697,137.537431150456,0.0760118803431238,27.72754611993193,140.83018036598642,0.02365866333620791
0.0242089891961241,137.465965167638,0.07686354069769401,27.713138577795817,140.7938772332161,0.0239205968054187
0.0244716176916914,137.396518616728,0.0776973861711202,27.699138153132367,140.75883369248595,0.024176984742243043
0.0247413355010804,137.315633232391,0.07855374021593026,27.682831659650027,140.71300538373688,0.02444022513463484
0.0250176824701912,137.204361517537,0.07943114184285706,27.660399281935458,140.63689666750804,0.024709863632001762
0.0252900861954762,137.083210949838,0.08029602367063693,27.63597532748734,140.55005717071202,0.024975583472750463
0.0255589843735592,136.97607377427,0.08114977538605046,27.614376472892832,140.47704310341805,0.02523781454912067
0.025829589750124,136.860840309305,0.0820089474566437,27.591145406355885,140.39589966735156,0.025501641092319446
0.026091184813487,136.76015589875,0.08283951178282122,27.570847429188003,140.3283904014256,0.025756616886729422
0.0263573195156685,136.615836900086,0.08368448946224749,27.541752719057342,140.21666416416204,0.02601595075368074
0.0266214093187125,136.51718150324,0.08452297458691219,27.52186379105319,140.15146127107474,0.026273225513317976
0.0268835167528145,136.4177564106,0.08535516569018604,27.50181969237696,140.08514545044574,0.026528503630450975
0.0271457537767335,136.348118841336,0.08618776824112885,27.487780758413336,140.0493913033237,0.026783842762279502
0.0274112556426468,136.285713948187,0.08703073666540358,27.475199931954503,140.02147649366142,0.027042294453981534
0.0276802620112343,136.225909856793,0.0878848318856689,27.46314342712947,139.99667873434782,0.027304089481417382
0.0279406625379112,136.163353998804,0.08871160355786806,27.450532166158894,139.96784832291476,0.027557444100413674
0.0282030141020075,136.110044594782,0.08954456977387382,27.439784990308056,139.9487581019135,0.027812632070496297
0.0284753255001629,136.033117365402,0.0904091584630172,27.424276460865045,139.90670466118368,0.028077439060002738
0.0287485536637114,135.973843725688,0.09127665788228369,27.4123268950987,139.88289506889703,0.028343067091956223
0.0290156548413251,135.886099846449,0.0921247041212072,27.39463772904412,139.82892401732744,0.028602670381788924
0.0292851427644557,135.791675915539,0.09298032827714685,27.375601864572666,139.76835453095026,0.02886452513594705
0.0295560524678355,135.69867010704,0.0938404665853777,27.35685189357926,139.70938712053916,0.02912769230548964
0.0298416891335083,135.605211451532,0.09474736299888885,27.33801062862885,139.65190001655228,0.02940509055812854
0.0301242772499165,135.538478482551,0.09564458026848488,27.32455726208228,139.6214771863912,0.029679452487201476
0.0303923558898266,135.469417088372,0.09649572995019945,27.3106344850158,139.58665182470918,0.029939657755250558
0.0306657191631486,135.364663785747,0.0973636583429968,27.2895162192066,139.51571855001475,0.03020492274533848
0.0309391355391724,135.225382708087,0.09823175533687237,27.261437153950343,139.40913915202898,0.030470168897629248
0.0312178687770716,135.096473098715,0.09911673336720232,27.235448976700948,139.31389706815588,0.030740500631840896
0.0314902775886029,134.992664815089,0.0999816313438142,27.214521226721946,139.24362130254138,0.031004627976850888
0.0317565443086717,134.869299536791,0.10082702818003263,27.18965078661707,139.1522824234106,0.0312627325513699
0.0320267259234826,134.763214031212,0.10168485480705726,27.16826394869234,139.07923855155724,0.03152456393672085
0.032302501065317,134.648371234494,0.10256044088238146,27.14511164087399,138.99785038973945,0.03179174529507165
0.0325763597225223,134.580201137876,0.10342994211900829,27.131368549395802,138.96433418167285,0.03205699926615113
0.032851732166525,134.567502812321,0.10430424962871686,27.12880856696392,138.98827837302946,0.03232364853534193
0.033124934109684,134.52710253348,0.10517166579824669,27.120663870749567,138.9833039408682,0.03258812581546918
0.0334029999226422,134.438211166242,0.10605452475438898,27.10274337111439,138.92885072342816,0.032857239830389656
0.0336861215238768,134.376133162971,0.10695343583830884,27.090228445654954,138.9027439146075,0.03313117248289859
0.0339690987413884,134.282526219191,0.10785188850390816,27.071357285788906,138.84398261157375,0.033404890476599614
0.0342518443236249,134.190092974784,0.10874960572750905,27.052722743716455,138.78635114912905,0.033678309605195175
0.0345410609530511,134.089750674126,0.10966786852593724,27.032493735903806,138.72135292534043,0.033957909008859845
0.0348249392679562,133.975111455047,0.11056918217576092,27.009382469337474,138.64078657488668,0.03423227160750647
0.0351034981485496,133.858611275967,0.11145360662164497,26.98589603323495,138.55751678906034,0.03450141992900363
0.0353807415538761,133.751758260195,0.1123338544335566,26.964354465255315,138.48399465157547,0.0347692253067671
0.0356593461693151,133.647484681136,0.11321842408757543,26.94333291171702,138.41326660203887,0.03503827332642754
0.0359363370766385,133.543235444604,0.11409787021832724,26.922316265632166,138.3422901678462,0.035305691250894486
0.0362082815320479,133.435039234523,0.11496129386425208,26.900503909679838,138.26649270136647,0.03556816758051786
0.0364770323033315,133.327158764587,0.1158145775630775,26.878755206940742,138.19053784175426,0.035827493751254644
0.0367407478929981,133.21294066963,0.11665187456026897,26.855728838997408,138.1072837388578,0.03608189595984857
0.0370214608578832,133.129696388384,0.11754313822377915,26.838946791898213,138.0583522322484,0.03635262417103398
0.0372977556459187,133.043530861445,0.11842037417579188,26.821575821667313,138.0057559657854,0.03661901980336596
0.0375679474098472,132.972811166319,0.11927823302626486,26.807318731129907,137.9683267431548,0.03687946245761375
0.0378432592585521,132.907343501898,0.1201523481459029,26.79412044998264,137.93699055940576,0.03714477070056357
0.0381270891056225,132.840729759032,0.12105350791035142,26.780691119420855,137.90556009941054,0.03741821376689889
0.0384098263242559,132.772677621514,0.12195119857951248,26.76697180849722,137.87245310956274,0.03769052987000275
0.0387045868299634,132.704058415581,0.1228870631851338,26.75313817658113,137.84031416721538,0.03797434717522145
0.0389768862893426,132.631096705682,0.12375161396866274,26.738429095865495,137.8006438804102,0.03823646575736348
0.0392606473576538,132.568826908012,0.1246525553605508,26.72587550465522,137.7735648718653,0.038509544330414265
0.0395608782715312,132.476006622188,0.12560578851211154,26.707162935033104,137.71687379406694,0.03879839155684836
0.0398616705467341,132.384690235694,0.12656080398588077,26.688753551515912,137.66176514330067,0.03908769521710909
0.0401549768349564,132.295793847908,0.12749205145098655,26.670832039738254,137.6081283852329,0.0393697182389303
0.0404445959787913,132.21246443909,0.12841159223266235,26.654032830920546,137.55974414668933,0.039648117936296176
0.0407430814826722,132.145020848892,0.12935928370748423,26.640436203136623,137.5290162008678,0.03993495944430609
0.041055245880738,132.054818786279,0.13035040567134315,26.622251467313845,137.47636184128598,0.04023485823498379
0.0413586226345601,131.971389156572,0.1313136268647283,26.605432053964915,137.42954403925734,0.04052622851497975
0.0416533268798411,131.885953604505,0.13224931284349548,26.58820824666821,137.37944234085302,0.0408091882429026
0.0419377515468205,131.790095048314,0.1331523611611551,26.5688831617401,137.31707531078203,0.041082202148261374
0.0422325976241307,131.702194090887,0.13408849745661497,26.551162328722818,137.2643198601426,0.04136514070882048
0.0425281721046217,131.599305185043,0.1350269464321739,26.53041992530467,137.19598308480116,0.04164869792724419
0.0428170343455985,131.482227563862,0.13594408404727523,26.506817076874583,137.1119066172997,0.04192573814286964
0.0431092565431566,131.379034716949,0.1368718895245222,26.486013398936922,137.04268722895424,0.04220592273112302
0.0433988642677175,131.283686989542,0.13779139405000307,26.466791297091667,136.98124990176663,0.04248352311382189
0.0436929006214764,131.176909060249,0.13872495947318755,26.445264866546196,136.90840871165088,0.042765289695100954
0.043991209796861,131.07040461615,0.13967209110503365,26.42379357061584,136.8363502837785,0.04305106969019323
0.0442815463606936,130.962586182438,0.14059390969520216,26.402057374379503,136.76181201399197,0.043329133525338646
0.0445808786158914,130.844127990004,0.14154428960545518,26.378176202784807,136.67727417752855,0.04361573187060794
0.0448734008775427,130.743540807015,0.14247304778619807,26.357897826694227,136.61044812579755,0.04389573059221984
0.0451637734796362,130.655758600573,0.14339498079784493,26.34020093387552,136.5566656858193,0.044173594170460836
0.0454611007830567,130.561057573475,0.144338994986205,26.32110920681256,136.49650697016523,0.04445803286540371
0.0457542004809344,130.46958645277,0.1452695865269667,26.30266862887843,136.43911806799463,0.04473834804827338
0.046053923017048,130.39884225674,0.14622120557912738,26.288406598958787,136.4042204995441,0.04502491595552826
0.0463520709482102,130.291140689327,0.14716782526056738,26.266693962968322,136.33040488648192,0.045309896914328636
0.0466436605224687,130.218603081035,0.14809362215883812,26.25207038113666,136.2924753968569,0.04558853061793412
0.0469453802463693,130.143275885749,0.1490515822822225,26.236884418567,136.25290145871364,0.04587676266358777
0.0472370280986951,130.037131163055,0.14997756421335695,26.215485642471887,136.17969878167793,0.04615529413539189
0.0475295599144264,129.923324626254,0.15090635272830383,26.192542244652806,136.098523068359,0.04643459190470593
0.0478188301702004,129.814735403948,0.15182478579038627,26.170650657435917,136.0223241898189,0.046710698979768726
0.0481124438483194,129.704113366889,0.1527570092184141,26.148349254764828,135.9444952381495,0.04699087389168422
0.0483961882057929,129.60413267232,0.15365789755339246,26.128193146739708,135.87647866937814,0.04726155664000942
0.0486804270245976,129.460281455605,0.15456035580309738,26.09919274144997,135.76246323958844,0.04753263764723724
0.0489672244465371,129.332298921132,0.1554709376177553,26.07339146250021,135.66534263058972,0.04780608435648369
0.0492598664629676,129.244336070021,0.15640007601992212,26.055658151716234,135.61089480592514,0.048085026535426845
0.0495551404608531,129.155032051825,0.1573375709632086,26.03765446164792,135.55532780637918,0.048366398641934226
0.0498573575622519,129.084264764446,0.15829711026014978,26.023387776512315,135.52006510846738,0.048654305000280486
0.0501485231511232,128.995740514813,0.15922156100481613,26.005541287786304,135.4646863944164,0.04893160478635364
0.050464906973984,128.933364208691,0.16022607964239918,25.992966224472102,135.43997443932537,0.049232834723014894
0.0507780703156436,128.879199347796,0.16122037325216843,25.982046588515672,135.42343639450223,0.04953090909838499
0.0510820130878293,128.79710900049,0.16218539155385803,25.965497174498783,135.37632460812762,0.04982012223555276
0.0513765705012108,128.660488242614,0.16312061134134428,25.937954429710985,135.27062288753086,0.05010032505867412
0.0516681517859905,128.545500451863,0.16404638192051982,25.91477289109558,135.18720888061597,0.05037761948190534
0.0519663760861996,128.42547253867,0.1649932440736837,25.890575263795874,135.09927894366243,0.050661151909478425
0.052261845876975,128.313951681147,0.16593136065939562,25.86809265891923,135.01987564777272,0.050941986269205417
0.0525576176279278,128.195903795693,0.16687043596867077,25.84429420521171,134.93357508885367,0.05122302866550399
0.0528542555733164,128.098925879235,0.16781226144527955,25.824743457253778,134.86949924632341,0.05150481481017923
0.0531578180644544,128.016990867971,0.16877607235464273,25.808225358982956,134.8220947776895,0.0517930966268317
0.0534679069136525,127.957589845733,0.1697606044508467,25.79625011289977,134.7992143485,0.0520874904982832
0.0537855263678634,127.882499677284,0.1707690462179663,25.781111934940455,134.76072723566486,0.0523889439937193
0.0540933772399962,127.785524579934,0.17174647273698793,25.7615617553147,134.69787516684718,0.05268103940185181
0.0544043370474352,127.689717702118,0.17273377012560676,25.74224708874699,134.6365921414759,0.05297599804239125
0.0547031712245637,127.586154760114,0.17368256863798975,25.72136879963898,134.56552202984022,0.053259373050973134
0.0550141329470205,127.478276159026,0.17466987210679008,25.699620473659643,134.49138299149564,0.053554162996615265
0.055322988209287,127.365241994589,0.17565048756448623,25.676832786109145,134.41146777572862,0.05384687003510253
0.0556411304196457,127.254960040201,0.17666058908237509,25.654599944104522,134.33556986834463,0.05414828890808099
0.055952000716508,127.14423417126,0.17764760227491289,25.632277608926017,134.2582084527102,0.0544427303840682
0.0562614098867346,127.041193540366,0.17862997639038236,25.611504617737783,134.18871020264052,0.05473570189053302
0.05657669271454,126.923516526049,0.1796309993686645,25.58778093165148,134.1044293187921,0.05503414674511723
0.0568888351771611,126.814359443444,0.18062205168748646,25.56577486379831,134.02868063591936,0.055329531231659665
0.0572046116047637,126.678698782045,0.18162464184512472,25.538425674460274,133.92530454446876,0.05562826583152495
0.0575192901241611,126.521320485243,0.18262374614421148,25.50669820982499,133.79873702512563,0.05592587302408808
0.0578154726554906,126.358400201346,0.18356412568118263,25.473853480591355,133.66387083297846,0.0562059067459147
0.0581192728259918,126.206351682459,0.18452869122252397,25.443200499183735,133.5413730682649,0.05649306132214863
0.0584153157747745,126.06806286762,0.185468627584909,25.415321474112194,133.43236856914615,0.056772804400582244
0.0587117535906325,125.94600058758,0.18640981765025819,25.390713718456126,133.34051113980365,0.05705284221416912
0.0590154858751192,125.827105544201,0.18737416765350345,25.366744477710924,133.25285331415193,0.05733968962389127
0.0593075434586872,125.734478937463,0.18830145048133184,25.34807095379254,133.19148201130196,0.05761543376807901
0.0596005255782933,125.660850397554,0.1892316687110812,25.33322744014689,133.1503031258635,0.057891974431408824
0.0599029822595618,125.571882375906,0.1901919686741087,25.31529148698265,133.09401261816967,0.05817737776497556
0.0602026404839041,125.477768214333,0.1911433835363955,25.29631807200953,133.0318611828631,0.058460060121102594
0.0605166440934538,125.382920957864,0.1921403449967158,25.277196865105385,132.9706745608687,0.058756189471297966
0.0608205827569288,125.266458329941,0.19310535025324893,25.253717999316105,132.88523732546454,0.05904274331262772
0.0611242816830156,125.148986286981,0.19406959434357451,25.23003563545537,132.79862817713027,0.05932898913668268
0.0614324853888548,125.030492586451,0.19504814110961397,25.206147305428523,132.71142649542946,0.05961939711331412
0.061741599785021,124.914828257186,0.19602957931744167,25.182829376648698,132.62726959065583,0.05991057851055217
0.0620553590485903,124.818820161545,0.1970257649792742,25.163474144567473,132.5644968626911,0.0602060486255714
0.0623609698982908,124.718774595807,0.19799607942707328,25.14330495851469,132.49635834412783,0.06049376139415103
0.0626692012406211,124.604327947175,0.19897471393897198,25.12023251415048,132.41318165074887,0.060783857364249
0.0629810129989653,124.50259359294,0.19996471627171483,25.099722868336702,132.34389305842183,0.061077237487179636
0.0632921061560692,124.391035532689,0.2009524370455197,25.077232763390104,132.26400615848732,0.06136985573694371
0.0635939391940916,124.271883031856,0.20191075694124083,25.05321161922217,132.17482160491912,0.061653681982086046
0.0639009912186578,124.141078379778,0.2028856471192385,25.026841401363246,132.0738163391989,0.061942333223796546
0.0642121147108444,124.033300633086,0.20387346420693095,25.005113407630137,131.99774116130234,0.06223472698194423
0.0645374166939428,123.916273771695,0.2049062980032684,24.981520792373715,131.91350996725959,0.06254035428175711
0.0648419056103035,123.792711995203,0.20587305031271358,24.956610738232925,131.81966734163944,0.06282634270593947
0.0651530922074119,123.674443078977,0.20686106775853277,24.932767724721767,131.73221547260192,0.06311853738211592
0.0654721899857814,123.556149804387,0.20787420320485595,24.908919800564423,131.64564151829148,0.06341807178023093
0.0657942677226543,123.437798579697,0.2088968000194274,24.885060193666913,131.55929814654468,0.06372031248613609
0.0661094953592197,123.316532697793,0.20989764776552253,24.86061299187507,131.4689264438928,0.06401603656554464
0.0664149481069772,123.170875509528,0.2108674602396526,24.831248502720847,131.35126281478423,0.06430250713874937
0.0667179484773635,123.037374396062,0.2118294864156291,24.8043346782461,131.24617560180855,0.06458659667945203
0.0670270233405209,122.899020409137,0.21281079910615383,24.77644251448202,131.13657591862736,0.064876298466124
0.0673333333453294,122.707113862168,0.21378333337142083,24.737754154613068,130.96939286369266,0.06516332591765256
0.0676273574060011,122.511358186887,0.2147168597640535,24.698289810476417,130.79647759328623,0.06543876336603677
0.0679201007865288,122.294057047707,0.2156463199972289,24.654481900817732,130.60028172798079,0.0657129257418139
0.0682216056511958,122.120646386159,0.21660359794254663,24.619522311449657,130.45191296578466,0.06599521494178631
0.0685225201866789,121.969218340371,0.2175590015927055,24.588994417418796,130.3268565662525,0.0662768720048232
0.0688210281549125,121.818797175591,0.21850676439184719,24.55866951059915,130.20249204580992,0.066556198152841
0.0691231551745683,121.676553373333,0.21946601767925433,24.52999316006393,130.08722065326452,0.06683883137032437
0.0694200944618266,121.590360193791,0.22040879991629947,24.512616615068264,130.0311744840915,0.06711653376349977
0.0697242917611834,121.508004850291,0.22137462634175728,24.496013777818668,129.98006443179196,0.06740094401964367
0.0700409596348264,121.442009078168,0.2223800468405738,24.482709030158667,129.94792393398419,0.06769692777370107
0.0703468710144789,121.332380270029,0.22335131547097048,24.460607862437847,129.86773357476446,0.06798277445751705
0.0706639027999832,121.200045174658,0.22435789138994666,24.433929107211053,129.7645133862336,0.06827892596847505
0.0709771818424937,121.034173949402,0.2253525523499175,24.400489468199446,129.62483852296472,0.06857148576945352
0.0712854855743075,120.866530217631,0.2263314166984263,24.36669249187441,129.48255951387654,0.06885931577147089
0.0715974734198124,120.695447807067,0.22732197810790436,24.33220227790471,129.33693692332582,0.06915050092127092
0.0719057902826968,120.482861294167,0.2283008841475623,24.289344836904064,129.14627665104462,0.0694381765877666
0.0722055061335381,120.303541686295,0.22925248197398346,24.253194003957073,128.99011980341112,0.06971774775862366
0.0725069107800528,120.115118258673,0.2302094417266676,24.215207840948473,128.8242944215901,0.06999881541703991
0.0728011004863268,119.933471809372,0.2311434940440876,24.178587916769395,128.66476054224012,0.07027307879234353
0.0730993262846748,119.754848077831,0.2320903609538425,24.142577372490727,128.50884679164403,0.07055102812917913
0.0734009026550533,119.599467372764,0.2330478659297942,24.11125262234922,128.37817623498847,0.07083202169097501
0.0737029016336693,119.424296304695,0.23400671268690001,24.075938135026515,128.2262134679101,0.07111332991650585
0.0740112689504083,119.299788115489,0.23498577891754632,24.050837284082583,128.12931681943115,0.07140048853666259
0.074323092729993,119.148499552218,0.23597581941772777,24.020337509727145,128.00398453307702,0.07169078206576725
0.0746339127541432,119.005405630387,0.23696267299440466,23.99148977508602,127.88724469147672,0.07198005730535968
0.0749404880903035,118.857282419093,0.2379360496867136,23.96162813568915,127.76450517666687,0.07226530013121268
0.075247625381625,118.704136538489,0.23891121058665934,23.930753926159383,127.63634093598648,0.0725509842455337
0.0755597119078773,118.536597430484,0.23990208530751042,23.896978041985573,127.49318858287138,0.07284118832195818
0.0758615713226245,118.370209706551,0.24086048894933276,23.86343427684068,127.34995981267853,0.0731218022761669
0.0761694291339164,118.18032683599,0.24183793750018456,23.825153890135585,127.18205486594701,0.07340791136411831
0.0764698939282294,117.985874301505,0.2427919132221283,23.78595225918341,127.00824159437049,0.07368707080624619
0.0767763424108473,117.804744952714,0.24376488715444017,23.749436582467144,126.84936238882612,0.0739717093947321
0.0770943190255364,117.602563531515,0.24477446290607807,23.708676807953424,126.66905308263453,0.07426697003660095
0.0774023535215267,117.421073368519,0.24575247243084727,23.672088391093432,126.50974080026623,0.07455291570735938
0.0777096302748161,117.216402199433,0.2467280761225411,23.630826683405694,126.32524547649508,0.07483807653211651
0.0780232557785172,117.007529735206,0.24772383709679208,23.588717994617532,126.13683815574844,0.07512904533251176
0.0783322622992597,116.82444786874,0.24870493280014955,23.551808690337985,125.97557116216034,0.07541564605328077
0.0786423497501026,116.630882529855,0.24968946045657575,23.512785918018768,125.80300918543098,0.07570316677906659
0.0789517651037476,116.402798364228,0.25067185420439864,23.466804150228366,125.59300475809944,0.07598998194382452
0.0792477387028058,116.144905927854,0.2516115703814084,23.414813035055367,125.34912708448654,0.07626426020252271
0.0795542857032628,115.912721923315,0.2525848571078594,23.368004739740304,125.13407571984526,0.07654825752979179
0.0798573997824977,115.688542492124,0.2535472443094302,23.3228101664122,124.927128680172,0.07682899518001665
0.0801637173535991,115.4341124594,0.25451980259767715,23.271517071815037,124.68774002355892,0.0771126197897252
0.0804673324517728,115.187372336841,0.25548378053437865,23.221774263107147,124.45619292091573,0.07739366277501364
0.0807713995039442,114.948349491971,0.2564491934250228,23.173587257581353,124.232888551106,0.07767504497465849
0.0810639183175032,114.712861444823,0.2573779406580727,23.12611286727632,124.0119354749532,0.07794566578738439
0.0813694296156877,114.514714832989,0.25834793902980846,23.08616651033058,123.83271186155245,0.07822822830012882
0.0816656137966774,114.279164274487,0.2592883238044507,23.03867951773658,123.61184236913431,0.07850208810997593
0.0819562576157584,114.032898395654,0.2602111179300329,22.989032316563847,123.37860799323983,0.07877075226490016
0.082259607478909,113.833376359816,0.26117425374553604,22.948808674138906,123.19726521717338,0.079051084619939
0.0825545242209656,113.589453191775,0.26211061440156574,22.89963376346184,122.96677645654161,0.07932354842139192
0.0828603198083427,113.332323688502,0.26308151539148805,22.847796455602,122.72307627395388,0.07960598445461024
0.0831701163748052,113.086435269284,0.2640651194900065,22.79822535028765,122.49184725104223,0.07989203451503414
0.0834765112310208,112.806062422782,0.26503792315849106,22.741702184432853,122.2227189595446,0.08017486315386614
0.0837807530989944,112.513252477549,0.26600389108930717,22.682671699473882,121.93969750373536,0.08045562527194015
0.0840842945343098,112.234862937188,0.26696763514643357,22.6265483681371,121.6720522094164,0.08073566247963485
0.0843653134010789,111.867332601842,0.2678598700484255,22.552454252531348,121.30505517613912,0.08099485122657536
0.0846653394204961,111.505183247657,0.2688124526600751,22.47944494272765,120.9458074344645,0.0812714964837002
0.0849446582485353,111.173244758245,0.26969928993909953,22.412526143262195,120.6168180406149,0.08152897946901322
0.0852243031984254,110.867945734989,0.27058716265500066,22.35097786017378,120.31658915729427,0.08178669668495886
0.0855004435818508,110.612628649204,0.2714639083723763,22.299505935679527,120.07005746446546,0.0820411189790101
0.0857908367251252,110.369914688633,0.2723859066022725,22.250574801228414,119.83864201905152,0.0823086032614182
0.0860882950460335,110.104490655622,0.27333033677115637,22.197065316173394,119.58319853307643,0.08258252119581598
0.0864014456957311,109.913344064269,0.2743245900839462,22.15853016335663,119.41001589267415,0.08287080854281124
0.0866876430392682,109.717693155293,0.2752332666496765,22.119086940107074,119.22886137463101,0.0831342099345677
0.0870050620987962,109.46400454809,0.27624107216367794,22.067943316894944,118.98792706137947,0.0834262650728435
0.0873174496971363,109.165064182305,0.27723290278840773,22.007676939152688,118.69707918272807,0.08371360754278051
0.0876300449848316,108.859196047572,0.2782253928268403,21.946013923190517,118.39853229423332,0.08400105842664046
0.0879294589480662,108.525564224247,0.27917603216011017,21.878753747608197,118.06815836851865,0.08427631080616284
0.0882255289430119,108.181431332833,0.2801160543940628,21.809376556699135,117.72579533398431,0.08454841458408296
0.0885196546690142,107.850943480605,0.2810499035741201,21.74275020568997,117.3978717532355,0.08481865818448849
0.0888302094767022,107.522385545673,0.2820359150885295,21.67651292600768,117.07362157712987,0.08510391763213888
0.0891256352758841,107.214879366394,0.282973892000932,21.61451968026503,116.77047360095114,0.08537520485929317
0.0894163043012669,106.900523482132,0.2838967661565224,21.55114553399781,116.45917321977504,0.08564205216833697
0.0897171095934781,106.545168844479,0.28485182295929296,21.479506039046964,116.10409343435475,0.0859181300736216
0.0900215261774933,106.214675971704,0.2858183456135412,21.412878675895527,115.77628320512471,0.08619744483273868
0.0903209401055388,105.911643163207,0.28676898483508567,21.351787261702533,115.47768234183022,0.08647209336576293
0.0906191394827593,105.56570336582,0.28771576785776076,21.282045798549312,115.13197656372284,0.08674555285405407
0.0909076634968591,105.112541407831,0.2886318316025276,21.190688347818732,114.66807695143378,0.08701006852756123
0.0911934897750272,104.676903471385,0.28953933003571136,21.102863739831218,114.22275559778427,0.08727204197400235
0.0914874804771254,104.299758012372,0.29047275051487315,21.026831215294198,113.8418800872978,0.08754142692570432
0.0917810976788534,103.935184098224,0.2914049851303595,20.95333311420196,113.4744693822127,0.08781039722687173
0.0920654506772654,103.570063847195,0.29230780590031763,20.87972487159451,113.10528845196015,0.08807081204423425
0.0923693000374472,103.178986829384,0.29327252761889483,20.800883744803816,112.70955762138719,0.08834900699791015
0.0926731525844954,102.785473626747,0.2942372594557729,20.721551483152197,112.31092750762816,0.08862712749725535
0.0929878703126389,102.484310093038,0.2952364882426285,20.66083691475646,112.0141078290497,0.08891511152316019
0.0933002076158383,102.150926921413,0.29622815918028655,20.59362686735686,111.68162961133116,0.08920083535660858
0.0936222520149119,101.764786653456,0.29725065014734525,20.515780989336733,111.2922351557696,0.08949535371045633
0.0939294007188298,101.343296270195,0.2982258472822846,20.43080852807131,110.86241135572523,0.08977616875365997
0.0942519063414659,100.899040540963,0.2992498026341542,20.34124657305814,110.40896745997362,0.09007093923171017
0.0945664991414687,100.465164594807,0.3002486347741631,20.253777182313094,109.96580349620935,0.0903583936878505
0.0948736636861446,99.9840287662704,0.3012238822035091,20.156780199280114,109.46987988542735,0.09063898098309266
0.0951827218544037,99.4797375570241,0.30220514188773173,20.055115091496056,108.94848974706339,0.0909212186207636
0.0954791803352484,99.0225689332413,0.30314639756441364,19.96294989694145,108.47716264967781,0.09119187515827688
0.095779809515854,98.5729409969279,0.30410089521283645,19.872304904980666,108.01423850903116,0.09146626461555614
0.0960843824664211,98.1531986192787,0.305067914330887,19.787684841646584,107.58418809571606,0.09174417686362471
0.0963835631212951,97.7356302493702,0.30601781291011193,19.703503058273036,107.15573853670993,0.09201709365343054
0.0966731174634111,97.3018406978012,0.30693714794633026,19.616051084676723,106.70831297298584,0.092281158277352
0.0969661683279925,96.8417470589558,0.3078675844413762,19.52329620708549,106.2321202054514,0.09254834064249563
0.0972443237727514,96.4269910823114,0.3087507279784857,19.43968140219398,105.80396862355191,0.09280187643338735
0.0975255581342113,95.9594219280822,0.30964364707612085,19.345419460701372,105.31791810985469,0.09305815328985202
0.0977918309850123,95.4055249898019,0.31048906337741405,19.233753837944064,104.73540596464098,0.09330073584618438
0.0980561715056144,94.8139415129877,0.3113283445303257,19.11449060901832,104.1110336231085,0.09354149979849719
0.0983190652059557,94.2767940224474,0.3121630320289093,19.006201674925396,103.54600028134887,0.09378088849420163
0.0985835218480316,93.7810846385969,0.3130026818675003,18.906266663141135,103.0263542449981,0.09402164258581364
0.0988516100812984,93.3895836458816,0.31385386200812243,18.827340063009732,102.62129435409909,0.09426564363112463
0.0991317638969778,92.9667290041859,0.31474335037290446,18.742092567243876,102.18268483410316,0.0945205625904882
0.0994175692379922,92.5374148664597,0.3156507823306252,18.655542837078276,101.73725971605076,0.09478055706804386
0.0997264740095957,92.1659485330826,0.3166315549804663,18.580655224269453,101.3573336040368,0.09506148889202667