File: example/data/02 processed data/test_ID_088.csv
Strain,Stress_MPa,Displacement(mm),Force(kN),True Stress (MPa),True Strain
0.0005319670038823367,28.8565435888071,0.001688995237326419,11.634958375007022,28.871894317842436,0.0005318255595959902
0.0005935824061681365,32.1294682522486,0.0018846241395838333,12.954601599306637,32.14853973932268,0.0005934063058150591
0.0006496430599712366,35.4375758700927,0.002062616715408676,14.288430590821378,35.460597645318906,0.0006494321332649247
0.0007093419165788365,38.7992161728685,0.002252160585137806,15.643843960900579,38.82673808323032,0.0007090904525105666
0.0007736354871030367,42.1792062061733,0.0024562926715521413,17.006655942329072,42.211837536912235,0.0007733363854234634
0.0008401665413928366,45.572086546048,0.0026675287689222563,18.374665295366555,45.61037468838545,0.0008398137990452645
0.0009064159681539366,48.9834682671172,0.0028778706988887488,19.750134405301655,49.027867664930085,0.0009060054212657731
0.0009705518673546365,52.4066787400977,0.0030815021788509708,21.130372868007395,52.45754214001076,0.0009700811864132316
0.0010349824702506367,55.8552148742215,0.003286069343045771,22.52082263728611,55.91302404248841,0.0010344472451610492
0.0010984621818458365,59.3537957279697,0.003487617427360531,23.931450437517384,59.418993627925865,0.0010978593137080989
0.0011612962505553365,62.8698164082538,0.003687115595513193,25.349109975807934,62.94282689032181,0.0011606224676551978
0.0012282762842680366,66.3670324060123,0.003899777202551016,26.75918746610416,66.44854945797385,0.0012275225700692756
0.0012973213498936366,69.876077155682,0.004118995285912296,28.174034309170985,69.96672888242288,0.0012964805556595544
0.0013651792883670366,73.4263708863756,0.004334444240565341,29.605512741386637,73.52661104712963,0.0013642482783564717
0.0014322863345745365,76.9921329849531,0.0045475091122741534,31.04322801953309,77.1024077648972,0.0014312615908700602
0.0014948512851397366,80.5506158515852,0.004746152830318664,32.478008311359154,80.67102704320975,0.0014937351071657415
0.0015580528097086364,84.1171362034903,0.00494681767082492,33.91602931724729,84.2481951438968,0.0015568403046974744
0.0016248007751909366,87.6991249232794,0.005158742461231223,35.360287169066254,87.8416185294383,0.0016234822144837824
0.0016923701562420366,91.3158416454745,0.005373275246068466,36.81854735145532,91.47038185066744,0.0016909397115364758
0.0017582050279642365,94.9360463329769,0.005582300963786451,38.27821388145629,95.10296336697459,0.0017566611948227054
0.0018200981679087364,98.5574642258034,0.005778811683110238,39.73836957584393,98.73684848587453,0.0018184437963466873
0.0018835795405125364,102.192075726531,0.005980365041127303,41.2038449329373,102.384562629572,0.0018818078289940133
0.0019483045360659365,105.824715768607,0.006185866902009348,42.66852539790235,106.03089454236688,0.0019464090523703648
0.0020120761689239367,109.430665293549,0.006388341836333499,44.12244424635895,109.65084812733564,0.0020100546548418776
0.0020758470859388364,113.028425682553,0.006590814497855805,45.57306123520537,113.26305541063438,0.002073695492448212
0.0021384662736193367,116.595704287786,0.006789630418741394,47.011387968835315,116.84504026905432,0.002136183009160812
0.0022035455814320365,120.131591205254,0.006996257221046715,48.43705757395841,120.39630664224472,0.0022011213355050087
0.0022695708812474364,123.625622539037,0.00720588754796061,49.845851007739725,123.90619965212768,0.002266999295450782
0.0023329077027965366,127.121170379474,0.007406981956379004,51.25525589700392,127.41773233704077,0.002330190698481307
0.0023924612316782367,130.618234726567,0.007596064410578402,52.66527224175182,130.93073378930055,0.0023896038528435143
0.0024570741091304365,134.084968940555,0.007801210296489136,54.063059476831775,134.4144256461624,0.0024540604380742805
0.0025229529466731368,137.506207954883,0.008010375605687209,55.44250304740883,137.8531296474286,0.00251977564388902
0.0025894058641393364,140.922897449246,0.008221363618642393,56.82011225153599,141.28780402629258,0.002586059128900365
0.0026487543474744365,144.359301530127,0.008409795053231335,58.20567037694721,144.7416738576533,0.002645252579862993
0.0027075189963924368,147.768408491214,0.008596372813545985,59.580222303657486,148.16849426427063,0.002703860269395295
0.0027678163854269367,151.141119292573,0.008787817023730523,60.94009929876544,151.55945015906275,0.0027639930349185843
0.0028310068644249366,154.49866502738,0.008988446794549174,62.29386173903962,154.936051808617,0.002827007111598534
0.0028917572997868364,157.841045695633,0.009181329426823205,63.64150962447923,158.29748369172933,0.002887584212747321
0.0029495155676005367,161.153096230781,0.009364711927131703,64.9769284002509,161.6284197968807,0.0029451742809255676
0.0030080179294825365,164.440882659444,0.009550456926107053,66.30256388828782,164.9355237828235,0.003003502895486596
0.0030701314653402366,167.681657381794,0.009747667402455251,67.60924425633934,168.19646211428224,0.00306542823562992
0.0031339721754840366,170.905750530935,0.009950361657161816,68.90919861407299,171.44136439772916,0.003129071521025797
0.0031964052305223367,174.099513546971,0.010148586606908419,70.19692386213872,174.65600614270394,0.003191307587190906
0.0032582732013444367,177.265979443211,0.010345017414268586,71.47364291150268,177.8435604335409,0.003252976531430336
0.0033191000706981368,180.421829792864,0.010538142724466584,72.74608177248277,181.020667900885,0.003313604016004498
0.0033839814391161366,183.56403158262,0.010744141069193733,74.0130175341124,184.18520885838493,0.0033782686582610505
0.0034467018697564365,186.695617825789,0.010943278436476685,75.27567310735812,187.33910196082445,0.003440775606338274
0.003511207859259136,189.827204068957,0.011148084953147756,76.53832868060347,190.49372683978513,0.0035050579604547364
0.0035708165704219368,192.937559218952,0.011337342611089648,77.79242387708145,193.6265038524678,0.0035644563412431884
0.003631220043624837,196.035782315704,0.011529123638508857,79.04162742969186,196.74763137771646,0.003624643080912829
0.0036939168088164363,199.124906372525,0.011728185867992185,80.28716224940209,199.86045721122846,0.003687111052902906
0.0037576041721325364,202.179150776274,0.011930393246520803,81.51863359299368,202.93885999674916,0.0037505620131596555
0.0038182492391688363,205.196999020296,0.012122941334361054,82.73543000498336,205.98049230568495,0.0038109782280205565
0.003878666511330837,208.163286038038,0.012314766173475405,83.93143693053693,208.9706820044823,0.0038711638782612536
0.003940932530183337,211.035549643153,0.012512460783332093,85.08953361611928,211.8672265057668,0.003933187397607507
0.004007843480436637,213.841086955435,0.012724903050386323,86.2207262604314,214.69812856163884,0.00399983347053279
0.004074853025996237,216.520754215328,0.012937658357538052,87.30116809962024,217.40304446583332,0.004066573297235093
0.004140204285897737,219.151893262251,0.013145148607725313,88.3620433633396,220.05922686999799,0.004131657223069347
0.004203194409484537,221.796680869073,0.013345142250113405,89.42842172641024,222.72893543814408,0.004194385662486883
0.004271372242898937,224.477864635621,0.013561606871204125,90.50947502108238,225.4366931557708,0.004262275826069305
0.004342545357060237,226.860296591078,0.013787581508666252,91.47007158552266,227.8454477187409,0.004333143715181826
0.004408269267323137,229.203299373497,0.013996254923750959,92.414770307394,230.21368923409423,0.004398581309340134
0.004474279040513637,231.496257436292,0.014205835953630796,93.33929099831293,232.53203628889656,0.004464299211334912
0.004541226080369637,233.784665979121,0.014418392805173597,94.26197732278159,234.84633500145588,0.004530945824773312
0.004610094863116637,235.951753989526,0.014637051190395321,95.13574720857689,237.03951395853647,0.004599500922695619
0.004687172553619337,237.985389414267,0.014881772857741393,95.95570901183247,239.10086799969193,0.004676221965211625
0.004762645651668237,239.835527533718,0.015121399944046652,96.7016847015951,240.977779166042,0.004751340136763581
0.004840247203834037,241.890394051632,0.015367784872173067,97.53020688161801,243.06120335507472,0.004828570869740927
0.004923184033230437,243.85730318354,0.015631109305506638,98.32326464360332,245.05785756495985,0.004911104792046845
0.005015183970989637,245.769618075858,0.015923209107892095,99.09431000818596,247.00219792498828,0.005002649825753231
0.005115173400198737,247.644020301793,0.016240675545630988,99.85006898568294,248.91076240715904,0.005102135343122895
0.005225249675346937,249.433498155032,0.016590167719226525,100.5715864561089,250.7368504602872,0.005211645428076205
0.005343237834585037,251.206294435063,0.016964780124807493,101.2863779162174,252.54854941177433,0.005329013386548195
0.005473917141793837,252.977574208439,0.017379686925195433,102.00055792084261,254.362352488388,0.005458989706940588
0.005619376455830437,254.707908302122,0.017841520247261638,102.69822862741559,256.13920792514875,0.005603646660203919
0.005779373864442237,256.407912262699,0.0183495120196041,103.38367022432026,257.88978944946626,0.005762737351618466
0.005947826768052237,258.066970543584,0.018884349988565852,104.05260252317306,259.60190817893323,0.005930208273074061
0.006128046383545437,259.627455891875,0.01945654726775676,104.681790215604,261.21846498402226,0.006109346265214339
0.006318698351775337,261.125764467299,0.020061867266886694,105.28590823321497,262.7757394048446,0.006298819074171003
0.006515260554114937,262.475455390505,0.020685952259314924,105.83010361345161,264.1855513714341,0.006494127983874944
0.006717336966064137,263.679561674803,0.021327544867253634,106.31559926728056,265.45078614163674,0.006694876186419245
0.006923238494801637,264.710786200399,0.021981282220995196,106.73138899600087,266.54344210541086,0.006899382921100974
0.007132922156825337,265.635855260124,0.022647027847920446,107.104376840882,267.5306151377562,0.007107603195071193
0.007347428485318637,266.416856187597,0.023328085440886673,107.4192764148391,268.37433498571875,0.007320567624568496
0.007555431844465238,267.075020075992,0.023988496106177128,107.68464809463997,269.0928871875353,0.007527032525662113
0.007770255877311237,267.67404020483,0.024670562410463177,107.92617301058746,269.7539359889352,0.007740222914658138
0.007987509673270237,268.180553427696,0.025360343212633,108.13039914204703,270.3226481923827,0.007955778375252798
0.008205028107938236,268.64915398418,0.026050964242703898,108.31933888642138,270.853427843794,0.008171549866750623
0.008420691906801735,269.06770982104,0.02673569680409551,108.48810059984334,271.3334461075117,0.008385435663748293
0.008632952896974536,269.419539365066,0.02740962544789415,108.62995827199461,271.7454255579292,0.00859590204524811
0.008841181652048936,269.757720349195,0.02807075174525537,108.76631284479541,272.1426973568448,0.008802327250159258
0.009059668937560435,270.083769280082,0.028764448876754382,108.89777577372907,272.53063881516795,0.009018876330161392
0.009272597002535736,270.402235677693,0.02944049548305096,109.02618142524581,272.909566637717,0.009229870396260983
0.009481397697336936,270.711603035371,0.03010343768904477,109.15091834386159,273.27832740503294,0.009436731357124846
0.009691705497843036,270.986090739978,0.030771164955651638,109.26159178635913,273.6124081254416,0.009645042175978086
0.009899581218524736,271.256028924619,0.031431170368816035,109.37043086240638,273.94135001397274,0.009850901374107142
0.010113116528053436,271.536582655848,0.03210914497656966,109.48355012683793,274.28266375787604,0.010062321144450487
0.010328836173873037,271.785289747315,0.03279405485204689,109.58382882611741,274.59251547958365,0.010275858233552105
0.010536844667469536,272.05067841199,0.03345448181921577,109.69083353571438,274.9172341520969,0.010481719015199377
0.010740014363348536,272.266022357041,0.0340995456036316,109.77766021435893,275.19016334780736,0.010682750057191822
0.010946946465444536,272.482882808747,0.0347565550277864,109.8650983484868,275.46573833960434,0.010887462366098371
0.011149236938807936,272.673962647313,0.035398827280715195,109.94214173939659,275.71406926391154,0.011087542338256448
0.011353688999134436,272.892339605675,0.03604796257225183,110.03019132900816,275.99067435980396,0.011289719609202038
0.011553392360346935,273.101617524104,0.03668202074410152,110.11457218571871,276.2568676656054,0.011487161561629449
0.011752810925021836,273.29269736267,0.03731517468694433,110.19161557662856,276.5046547619627,0.011684283050207581
0.011950094468668036,273.448897548165,0.03794154993802101,110.25459549142013,276.7166377062187,0.011879255883171845
0.012150063094180536,273.600548213694,0.0385764503240232,110.31574103976143,276.9248121370928,0.012076843562235769
0.012347544180177037,273.764330932465,0.03920345277206209,110.38177823196988,277.1446481036102,0.012271935011999276
0.012544949204391836,273.947828237755,0.03983021372394408,110.45576434546281,277.3844898276511,0.012466913289103031
0.012741695255134236,274.084313836731,0.040454882435051194,110.51079533896993,277.5766126378512,0.012661202874628628
0.012939185053257337,274.222315942362,0.04108191254409204,110.56643778796037,277.770529234073,0.012856188966138575
0.013135586763883936,274.325438394921,0.041705487975331496,110.60801676083214,277.928863992498,0.013050063065923805
0.013333307551068535,274.458890980587,0.0423332514746426,110.66182484337268,278.11833578415633,0.013245201306995738
0.013530326916188936,274.612058152771,0.04295878795889987,110.72358184719728,278.32764907470545,0.01343960941851401
0.013726585339345836,274.731862178538,0.043581908452423025,110.77188683038652,278.5029925301691,0.01363322910488294
0.013924278358959437,274.853182710961,0.04420958378969621,110.82080326905947,278.6803149348744,0.013828226205990907
0.014122663102641935,274.974503243384,0.044839455350888145,110.86971970773243,278.8578755145066,0.014023867382000559
0.014321552402333437,275.08520822922,0.04547092887740866,110.9143559580215,279.02485545398156,0.014219967722161438
0.014519444955348536,275.238375401404,0.0460992377332316,110.9761129618461,279.23468384264424,0.01441504713341187
0.014718315916593736,275.3232997741,0.04673065303518511,111.01035446891713,279.37559507937425,0.014611052713158724
0.014913820629058137,275.424905720005,0.04735138049725958,111.05132198630601,279.5325433606884,0.014803703104871424
0.015107943963408737,275.553808785704,0.04796772208382274,111.10329570239587,279.7168602877423,0.014994955571547534
0.015300806317178938,275.667546784851,0.04858006005704312,111.14915486365193,279.8854825261379,0.015184929491157092
0.015492524764385835,275.790383823929,0.04918876612692502,111.19868275780819,280.06307317510067,0.01537374087323342
0.01568433890324204,275.893506276489,0.04979777601779347,111.24026173068037,280.2207135301332,0.015562610826271391
0.01587437144748874,276.022409342188,0.05040112934577674,111.29223544677019,280.40409159591667,0.015749691360870566
0.016065357929233238,276.160411447819,0.051007511425315524,111.34787789576063,280.5970273036125,0.015937675757795013
0.016256066339381738,276.263533900379,0.051613010627537016,111.3894568686328,280.7544922346156,0.01612535119971195
0.01644980450888374,276.368172859594,0.05222812931570587,111.4316472969883,280.9143752756117,0.016315972157585852
0.016642995932615638,276.466745792187,0.05284151208605465,111.47139190340981,281.06798071790985,0.016506018990933926
0.01684048368508534,276.566835231436,0.053468535700145946,111.51174796531501,281.2243545079867,0.016700254897023287
0.01703686653668634,276.671474190651,0.054092051253979125,111.55393839367049,281.3850891709453,0.016893366691291344
0.01723114780612474,276.770047123245,0.054708894284446044,111.59368300009237,281.5391127135337,0.017084375219822805
0.01742583586170974,276.900466695599,0.05532702886092842,111.64626817166551,281.7256887782673,0.01727574709011044
0.017620657268183036,277.021787228022,0.05594558682648114,111.69518461033847,281.9030931965865,0.01746721338606601
0.01781277901681594,277.132492213858,0.0565555733783906,111.73982086062753,282.0689920560429,0.01765599062218544
0.01800487858440604,277.320539039114,0.05716548950548917,111.81564134057076,282.3136616734753,0.017844710439447097
0.018192018144079936,277.417595465053,0.057759657607453795,111.85477449150937,282.4643813952403,0.018028523272578863
0.01837975214294264,277.517684904301,0.05835571305384288,111.89513055341416,282.61839116812536,0.01821288603566286
0.018562494321508638,277.602609276998,0.058935919470789924,111.9293720604856,282.75560613533827,0.018392313979065086
0.018740263667409537,277.684500636383,0.05950033714402528,111.96239065658963,282.88838139466174,0.01856682839098048
0.01891933519743894,277.787623088943,0.06006888925186863,112.00396962946184,283.0431802438626,0.018742590358867914
0.019099234998547637,277.887712528192,0.060640071120388744,112.04432569136704,283.19515525297686,0.018919134188454922
0.019276828945907237,277.936240741161,0.061203931903255474,112.06389226683612,283.29397011179685,0.019093384613536258
0.019451755609486338,278.084858393379,0.061759324060119115,112.12381490421043,283.49409709754565,0.019264988293725513
0.019624432798563338,278.169782766075,0.062307574135438595,112.15805641128145,283.6287069745588,0.019434356354096485
0.019805557347674137,278.259256658737,0.06288264457886539,112.19413228480276,283.77033632401276,0.019611979072662083
0.01998708598148754,278.357829591331,0.06345899799122293,112.23387689122465,283.9213914649932,0.019789966413567804
0.020168381040225537,278.480666630409,0.06403460980271608,112.28340478538092,284.09717082734716,0.01996769312326799
0.020349783346379338,278.56710750976,0.0646105621247544,112.31825774793522,284.23588779501114,0.020145493360283893
0.02053015847750964,278.658097909078,0.0651832531660931,112.35494507694024,284.37899282019276,0.020322255479312712
0.020711370978422038,278.761220361637,0.06575860285648996,112.39652404981206,284.53474741094453,0.02049980673796926
0.02089185440512944,278.914387533821,0.06633163773628596,112.45828105363664,284.7414263096735,0.020676612323828048
0.021073154376376038,279.04025758621,0.06690726514499391,112.50903185875987,284.92051601154793,0.020854186347813
0.021256384045353238,279.150962572046,0.06748901934399652,112.55366810904896,285.08470263910743,0.021033618379737107
0.021437696638756637,279.246502491329,0.06806468682805232,112.59218980450385,285.23290429917193,0.021211141382906345
0.02162041494039754,279.35569097051,0.06864481743576219,112.63621459930964,285.3954769252539,0.02139000883762292
0.02179942358509654,279.434549316585,0.0692131698826815,112.66801028444706,285.52606142144776,0.02156521379725175
0.021981818113929137,279.492176569486,0.06979227251172501,112.69124559281676,285.6359227591026,0.021743701128082923
0.022167403941645538,279.571034915561,0.07038150751472458,112.72304127795418,285.7683989769181,0.021925278701993817
0.02235022543928764,279.665058328189,0.07096196576973825,112.7609515179258,285.9156354293155,0.022104119417771528
0.022531004337477137,279.762114754127,0.07153593877148991,112.80008466886402,286.06543617511403,0.02228093056555664
0.022713620506802937,279.847039126823,0.07211574510909932,112.83432617593505,286.2033785735021,0.022459506925169476
0.022891345658336736,279.944095552761,0.07268002246521914,112.87345932687323,286.35239260906974,0.022633269850974413
0.023074816763893637,280.06996560515,0.0732625432253623,112.92421013199647,286.53252874255884,0.022812618961842814
0.02325630009547054,280.165505524433,0.07383875280311895,112.96273182745139,286.68111859730845,0.022989993317886735
0.023437793431406638,280.27924352358,0.07441499414471607,113.00859098870748,286.84837053639666,0.023167345993096798
0.023618566000115238,280.364167896276,0.07498894705036588,113.0428324957785,286.9859674998016,0.02334396308362822
0.023802809835383038,280.452125282283,0.07557392122734115,113.07829691381653,287.1276738883062,0.023523939553484193
0.023984739482091438,280.556764241498,0.07615154785564031,113.120487342172,287.28584514176885,0.023701623656747304
0.024169250038491838,280.658370187402,0.07673736887221158,113.1614548595605,287.4416725118569,0.02388179620026077
0.024352466313315137,280.735712026821,0.07731908054477556,113.19263908921423,287.5723189968987,0.024060672776329724
0.024535026101894737,280.829735439449,0.07789870787351579,113.23054932918583,287.7199003286441,0.024238876596440452
0.024714568477457437,280.91011029218,0.07846875491592736,113.26295646980698,287.8526824490062,0.024414104032373037
0.024894244933306338,281.01929877136,0.07903922766324761,113.30698126461235,288.0150620259602,0.02458943159257228
0.02506984383131614,281.120904717265,0.07959675416442874,113.34794878200124,288.16856189624514,0.024760750592160412
0.02524900747690204,281.186114503442,0.08016559873916397,113.37424136778782,288.28578481094047,0.024935517210462346
0.02542542138777174,281.25739031624,0.08072571290617526,113.40297977550797,288.4084779834554,0.025107571739276673
0.02560369177205714,281.352930235524,0.0812917213762814,113.44150147096329,288.5566039404395,0.025281406799530594
0.025781866359302536,281.449986661462,0.08185742569078555,113.48063462190149,288.7062926043953,0.02545511825712288
0.02595973136085874,281.525811994226,0.0824221470707265,113.51120739607191,288.83414644474374,0.025628497792050137
0.026138215247157738,281.59557130037,0.08298883340972582,113.53933434830918,288.9559769556654,0.025802450392162533
0.026319332982581437,281.686561699687,0.08356388221969606,113.5760216773138,289.10036411377956,0.02597893904699506
0.026499974629541137,281.794233672212,0.0841374194487931,113.61943501663588,289.2617737152766,0.02615493276135273
0.026678782133708837,281.903422151393,0.08470513327452556,113.66345981144167,289.424262133717,0.02632910902733134
0.02685494848116294,281.979247484157,0.08526446142769233,113.69403258561209,289.5517856481011,0.02650068288098642
0.027032257134223837,282.067204870164,0.08582741640116068,113.72949700365012,289.69211808134605,0.026673339541991643
0.027206897707448937,282.150612736205,0.08638190022115037,113.76312705523786,289.82705559501295,0.02684336898888847
0.027386132486013837,282.227954575624,0.08695097064309393,113.79431128489159,289.9570867308887,0.027017841282316577
0.02756373852255114,282.325011001563,0.08751486980909987,113.83344443583019,290.1069437831864,0.027190698089662766
0.02773926714322584,282.422067427501,0.08807217317974203,113.87257758676843,290.2562486030146,0.02736150367951273
0.02791573879060674,282.488793720334,0.08863247066017639,113.89948162803867,290.37467709710444,0.027533197516567093
0.028098894390008837,282.585850146272,0.08921398968827805,113.93861477897687,290.52620010564294,0.02771136317446733
0.02827753172269704,282.669258012313,0.0897811632195631,113.97224483056459,290.6624469227874,0.027885103089853574
0.028458451761986237,282.776929984838,0.0903555843443063,114.01565816988666,290.824323606214,0.028061032369263716
0.028636978875823737,282.911899077159,0.09092240793074036,114.0700777079105,291.01364115475076,0.0282346043986669
0.028812793271143937,282.977108863336,0.091480618635882,114.09637029369708,291.1304698014813,0.028405509563038993
0.028991793311041836,283.045351662824,0.09204894376255783,114.12388579045063,291.2513439958837,0.028579481417817063
0.029168371106509636,283.140891582107,0.0926095782631681,114.16240748590553,291.39965018320186,0.02875106942049428
0.029342626566054037,283.234914994735,0.09316283934722157,114.20031772587716,291.54577133589356,0.02892037185332828
0.029516818764163438,283.318322860776,0.09371589957621891,114.23394777746488,291.68097844922426,0.02908958418000755
0.029691718591782237,283.398697713506,0.0942712065289086,114.26635491808563,291.813292095293,0.029259455103584728
0.02986575880191884,283.457841473063,0.0948237841960923,114.29020168193902,291.9235249970101,0.029428462487414753
0.030042220479814436,283.550348379035,0.09538405002341083,114.3275004664269,292.06883046216615,0.02959979215854776
0.030215367563085738,283.618591178523,0.09593379201279721,114.35501596318046,292.1882311587066,0.029767875105732478
0.030395083364367238,283.691383497977,0.09650438968186598,114.38436582638431,292.3142067491506,0.029942304776955454
0.030574261721517837,283.762659310775,0.09707328096581913,114.41310423410448,292.43849312333657,0.030116182528247017
0.030753018764165137,283.861232243369,0.0976408345762243,114.45284884052639,292.5908220449684,0.030289621307025737
0.030933309619148336,283.956772162652,0.09821325804079596,114.49137053598128,292.74049491441326,0.030464517801182756
0.031113506019680638,284.056861601901,0.09878538161248603,114.53172659788649,292.8948664752833,0.030639292107589564
0.03129658288141444,284.129653921355,0.09936665064849083,114.56107646109032,293.0219411843723,0.030816828925509545
0.03147939840050184,284.249457947123,0.09994708992159333,114.60938144427999,293.19745987896715,0.030994080862922845
0.03166078595670184,284.355613412993,0.10052299541252833,114.6521833281188,293.3585356248484,0.03116991724868339
0.03183996381493604,284.451153332276,0.10109188511242193,114.6907050235737,293.5080677614925,0.031343581211446134
0.03202539886943894,284.533044691661,0.10168064141046863,114.72372361967773,293.6453289394474,0.03152327806411366
0.03220981782082274,284.6301011176,0.10226617158111219,114.76285677061632,293.7979848209203,0.031701958236201914
0.03239166904828214,284.687728370501,0.10284354922829579,114.78609207898603,293.90923904998556,0.03187811932984275
0.03257156462832294,284.778718769818,0.10341471769492533,114.82277940799062,294.0544072130001,0.032052355439776324
0.032751719970558035,284.854544102582,0.10398671090652176,114.85335218216107,294.18402036337073,0.032226812721147705
0.032928698140200136,284.94856751521,0.10454861659513542,114.89126242213268,294.3315528804008,0.03239816368959714
0.03310342206808234,285.019843328009,0.10510336506616141,114.92000082985324,294.4549754994748,0.03256730329453332
0.03327601138862524,285.10325119405,0.10565133615888513,114.95363088144097,294.5903502277173,0.032734348434597924
0.03344867499451104,285.173010500193,0.10619954310757254,114.98175783367782,294.7116698456203,0.032901437556264866
0.03362263796687494,285.257934872889,0.10675187554482793,115.01599934074885,294.8490591442985,0.033069755864088814
0.033796063311123635,285.333760205653,0.10730250101281753,115.04657211491929,294.97691803036423,0.033237525793371414
0.03397125482257424,285.376222392001,0.10785873406167319,115.06369286845481,295.0708107631833,0.03340697572164289
0.03414693659991914,285.415651565039,0.10841652370474325,115.07959071102374,295.16172172365503,0.03357687101920959
0.034326163285775035,285.492993404458,0.10898556843233573,115.11077494067746,295.2928725130041,0.033750164726837915
0.03450269315116924,285.571851750533,0.10954605075496232,115.14257062581491,295.42484972409284,0.03392082153614658
0.03467940206788784,285.662842149851,0.11010710156554389,115.17925795481992,295.5694587086212,0.03409162227674501
0.03485151694857574,285.738667482615,0.11065356631172796,115.20983072899038,295.6970934952488,0.03425795454025768
0.035026737490406135,285.822075348656,0.11120989153203947,115.24346078057812,295.83349015085645,0.034427259707721675
0.03519996828153974,285.925197801215,0.11175989929388867,115.2850397534499,295.98975569471077,0.034594614124564105
0.03537734839568754,286.023770733809,0.11232308115630793,115.3247843598718,296.14253332050725,0.03476594809326264
0.035556463024993636,286.114761133126,0.11289177010435479,115.3614716888764,296.2879900582609,0.03493892767258557
0.03573957945487754,286.173904892683,0.11347316476923618,115.38531845272979,296.40163990450765,0.035115741055709526
0.035915391277359536,286.219400092341,0.11403136730561653,115.40366211723189,296.49908183782856,0.03528547185102809
0.03609548733519124,286.307357478348,0.11460317228923217,115.43912653526992,296.64176107417984,0.035459308832430314
0.03626573226192404,286.401380890976,0.11514369993160882,115.47703677524153,296.7879366898134,0.035623609269541126
0.03644977878999354,286.499953823569,0.11572804765822947,115.51678138166302,296.9428137637815,0.0358011990328945
0.036632300841516835,286.563647103091,0.11630755517181594,115.54246251196629,297.0611328340137,0.0359772866598999
0.03681404856387214,286.601559769474,0.11688460419029403,115.55774889905193,297.15252350930893,0.036152596450648
0.03698976103217344,286.645538462477,0.11744249127715067,115.57548110807075,297.24848843114273,0.03632205555561125
0.03717244123106524,286.703165715378,0.11802250090863212,115.59871641644042,297.36062229369327,0.036498203977528114
0.03735586595478504,286.775958034832,0.11860487440644249,115.62806627964426,297.4887222822362,0.03667503909090056
0.03754780998112784,286.84723384763,0.11921429669008089,115.6568046873644,297.61771927775294,0.036860053970498644
0.03772742826387674,286.954905820156,0.11978458473780865,115.70021802668691,297.7809764444534,0.037033157065343186
0.03790866576348234,287.039830192852,0.12036001379905642,115.73445953375793,297.92112717643954,0.03720779027834989
0.03808854705649164,287.13688661879,0.12093113690436094,115.77359268469614,298.07351343642426,0.03738108655480779
0.03827157997449994,287.202096404967,0.1215122664190373,115.7998852704827,298.19377440637373,0.03755738826287822
0.03845368903277534,287.34919755053,0.12209046267906169,115.8591964523737,298.3988342369556,0.03773276924510055
0.03863495801321914,287.444737469813,0.12266599169197076,115.8977181478286,298.55015283308,0.037907310645788166
0.038816629619569935,287.519046295923,0.12324279904213453,115.92767946651615,298.6795666245638,0.038082209168473914
0.03899831805752184,287.526628829199,0.12381965983263184,115.93073674393305,298.7396837502871,0.03825709330685008
0.039175863607675235,287.593355122032,0.12438336695436886,115.9576407852033,298.86007317676643,0.03842796016887921
0.03935565123645974,287.652498881588,0.12495419267575966,115.98148754905628,298.97325030486786,0.038600955024091894
0.039535838722273335,287.7707864007,0.12552628794321782,116.02918107676224,299.14804580081983,0.0387743046069202
0.03971665285090654,287.769269894045,0.12610037280162825,116.02856962127895,299.1985020875856,0.03894822685043977
0.03989772493934094,287.799600027151,0.12667527668240747,116.04079873094729,299.28214930668656,0.03912236691296838
0.04008204181614774,287.845095226809,0.12726048276626906,116.0591423954494,299.38251437026304,0.0392995964035965
0.04026235042194324,287.913338026297,0.12783296258966978,116.08665789220296,299.5054057330632,0.03947294136217132
0.04044547675353464,287.98309733244,0.12841438869247246,116.11478484443982,299.6307110010101,0.039648964472838305
0.04062559379042854,288.068021705137,0.1289862602846106,116.14902635151125,299.77095613894227,0.0398220647959296
0.040804828392734936,288.14081402459,0.1295553301469334,116.17837621471469,299.89835049380633,0.03999428732216847
0.04098298438471914,288.228771410597,0.13012097542148326,116.2138406327527,300.0412466485443,0.04016544404748473
0.04116288419938264,288.300047223396,0.13069215733303988,116.24257904047327,300.1673086819292,0.0403382463643883
0.04134019114961174,288.345542423054,0.13125510690001727,116.26092270497537,300.26580226396146,0.04050852889866749
0.041516476287813735,288.425917275784,0.1318148122138086,116.2933298455961,300.40034503115504,0.04067780136122242
0.04169625409544714,288.491127061962,0.13238560675304464,116.3196224313831,300.5201264002195,0.040850398048500304
0.041876163724656336,288.541171781586,0.13295681982578386,116.33980046233548,300.6241691324159,0.0410230914745772
0.042059098426173835,288.55936986145,0.1335376375031019,116.34713792813666,300.69591680024746,0.0411986580627626
0.04224211801120064,288.594249514521,0.13411872468556202,116.36120140425487,300.78508185986726,0.04137427527591183
0.042427968957158335,288.66855834063,0.1347088014389777,116.39116272294201,300.9161789728139,0.04155257777817513
0.04261407204861844,288.758032233292,0.13529967875436352,116.42723859646334,301.06318782349877,0.04173109033407975
0.04279970268158624,288.814142979538,0.1358890560140363,116.44986244934974,301.1753024292994,0.04190911796169743
0.04298220116837754,288.893001325613,0.13646848870959868,116.48165813448718,301.3102584247269,0.042084110837913455
0.04316762618673764,288.968826658377,0.137057213142892,116.5122309086576,301.442924947186,0.04226187852882119
0.043351707888288835,289.082564657524,0.13764167254531703,116.55809006991369,301.61478755615434,0.04243832712339937
0.04353742668533884,289.162939510254,0.1382313297259508,116.59049721053441,301.7523497892987,0.04261631338482884
0.04372198165109804,289.234215323053,0.13881729174223625,116.61923561825498,301.88010837827727,0.04279315289553187
0.04390542536827874,289.279710522711,0.13939972554428498,116.63757928275709,301.9806592636232,0.042968896629337956
0.04409366280210554,289.331271748991,0.13999737939668508,116.65836876919319,302.0889472835954,0.04314920076395499
0.044279439032736935,289.397998041824,0.14058721892893977,116.68527281046343,302.2123790523131,0.04332711555414095
0.04446403667289544,289.517802067592,0.141173316436443,116.7335777936531,302.3909322361815,0.04350387028040208
0.04465136713324544,289.596660413666,0.14176809064805426,116.76537347879012,302.52754721835834,0.043683209785065825
0.04483930983781954,289.689167319639,0.142364808735077,116.80267226327845,302.6786296497442,0.04386310310275548
0.04502554532882904,289.755893612472,0.1429561064190322,116.82957630454871,302.80231073461573,0.0440413304087386
0.04521348019055964,289.846884011789,0.14355279960502684,116.86626363355332,302.95187036035145,0.0442211518166662
0.04540365336227594,289.922709344553,0.1441565994252261,116.89683640772378,303.086259541485,0.04440308199334811
0.04559468357935974,289.960622010935,0.14476312036446715,116.91212279480901,303.1812848219979,0.04458579875044955
0.045783641355880735,289.963655024246,0.14536306130492133,116.913345705776,303.23924701211644,0.04476650041956634
0.045969796248711337,289.989435637386,0.14595410308965848,116.92374044899404,303.32019090791545,0.044944489746583015
0.04615790132408884,290.019765770492,0.14655133670398207,116.93596955866236,303.40646950096175,0.04512431153863013
0.04634466691908054,290.066777476805,0.1471443174680807,116.95492467864777,303.5098256632586,0.04530282084927283
0.04652771854890054,290.107723156498,0.1477255063927592,116.97143397670001,303.60577364838593,0.045477749460838296
0.04671187941265344,290.165350409399,0.14831021713517464,116.99466928506969,303.7195192674532,0.04565370721016373
0.04689690336583044,290.219944648989,0.14889766818651162,117.01668168247235,303.83036134802927,0.045830458430525946
0.04708907344316854,290.276055395235,0.1495078081820601,117.03930553535876,303.9448858865345,0.0460140031915759
0.04728259411118604,290.336715661447,0.15012223630301566,117.06376375469543,304.06458874364205,0.04619880388532688
0.04747093647023224,290.398892434313,0.15072022329298734,117.088833429515,304.184399808088,0.046378626816095565
0.04765837593505284,290.456519687214,0.15131534359379276,117.11206873788467,304.29920569525433,0.04655755559553743
0.047851656077941035,290.526278993358,0.1519290080474628,117.14019569012194,304.4284425773521,0.046742026335818775
0.04804109363680914,290.571774193016,0.152530472296869,117.15853935462405,304.5311600052364,0.046922796615605174
0.04822977002323224,290.630917952572,0.15312951982376236,117.18238611847704,304.6479802870654,0.04710280807328771
0.04841579484300144,290.667314112299,0.15372014862652955,117.19706105007896,304.74020315992635,0.047280258018452266
0.048599720341685235,290.69612773875,0.15430411208485062,117.208678704264,304.8238782512641,0.04745567445941185
0.04878613137605494,290.735556911787,0.15489596711897444,117.22457654683252,304.9194199869759,0.04763343005427089
0.04897626173859284,290.793184164688,0.15549963102003225,117.2478118552022,305.03514726413664,0.04781469973827579
0.049163872009020636,290.834129844381,0.1560952936286405,117.2643211532544,305.132661779905,0.04799353457195546
0.04935246620754944,290.888724083971,0.15669408020896947,117.2863335506571,305.2448000094824,0.048173275082526765
0.049544747214131137,290.947867843528,0.15730457240486634,117.31018031451049,305.362806408326,0.04835649606723232
0.04973103068364284,291.034308722879,0.157896022420566,117.34503327706481,305.5077448599693,0.04853397010086061
0.04992084355442464,291.126815628851,0.1584986782852982,117.38233206155272,305.6601118463567,0.04871477423665836
0.05011056673878954,291.213256508203,0.15910104939565678,117.41718502410745,305.80611783367755,0.048895460281591856
0.05030234195250774,291.263301227827,0.15970993569921207,117.43736305505985,305.9145274044054,0.0490780674379824
0.05049463674449354,291.310312934141,0.16032047166376698,117.45631817504565,306.0199213656752,0.04926113585865599
0.050688220156800835,291.346709093868,0.16093509899784264,117.47099310664758,306.11455522637743,0.04944539722574181
0.05088069460167894,291.374006213663,0.16154620536033062,117.48199930534894,306.1993180386881,0.049628569373049956
0.051076317787247937,291.389171280216,0.1621673089745122,117.48811386018308,306.2722571922871,0.04981470370879601
0.051273868508343735,291.413435386701,0.16279453251399134,117.49789714791785,306.35532955428346,0.05000263693035447
0.051475056500633234,291.428600453254,0.1634333043895105,117.50401170275201,306.4299041274857,0.050193994053889766
0.05167323726403874,291.458930586359,0.164062528313323,117.51624081241995,306.5195570592709,0.05038245510019795
0.05186999248435184,291.492293732776,0.16468722613781708,117.52969283305526,306.61199681794153,0.05056952539008247
0.052065634699031735,291.527173385847,0.16530839016942575,117.54375630917352,306.7057207001958,0.05075550276763737
0.052262623115604735,291.577218105472,0.165933828392045,117.56393434012632,306.81580836441475,0.05094272490507412
0.05246115591750174,291.613614265199,0.166564170038068,117.57860927172823,306.91200155083175,0.05113137940165323
0.052660217011292136,291.630295838407,0.16719618901085254,117.5853352820457,306.98761050432483,0.05132050017819725
0.05285561252673344,291.662142478168,0.16781656977237866,117.59817584719735,307.078123669711,0.051506103642451444
0.05305246069465234,291.70005514455,0.16844156270552116,117.61346223428257,307.1754608547341,0.05169305213369406
0.05325431174361254,291.737967810932,0.1690824397859698,117.62874862136778,307.27427249618336,0.05188471561996255
0.05345864933382054,291.78042999728,0.1697312116348802,117.64586937490331,307.378617686976,0.052078702740774835
0.053661680804691636,291.798628077144,0.17037583655489594,117.65320684070444,307.4570329162666,0.05227141263834977
0.05386750258436974,291.825925196939,0.1710293207053739,117.66421303940581,307.54585897667124,0.05246673309412772
0.05407438145572354,291.879002929874,0.17168616112192223,117.68561398132519,307.66217947322025,0.05266301827028405
0.05428479266687824,291.919948609567,0.1723542167173384,117.70212327937742,307.76676249516305,0.05286261539247801
0.05449637990844654,291.947245729362,0.17302600620931774,117.71312947807877,307.85731374585396,0.05306328793738706
0.05470445086707874,291.973026342502,0.17368663150297498,117.72352422129681,307.94525041656766,0.05326058632289027
0.05491054218553994,292.007905995573,0.1743409714390893,117.73758769741504,308.04221843625413,0.05345596919587488
0.055118405412238836,292.065533248474,0.17500093718385829,117.76082300578473,308.16371971700516,0.05365299324865663
0.05532311845917954,292.107995434822,0.17565090110789502,117.77794375932022,308.26832066913613,0.05384699345692321
0.055525862766701135,292.132259541307,0.1762946142842761,117.78772704705499,308.353155294324,0.05403909086412604
0.055731303015361736,292.145908101205,0.1769468870737735,117.79323014640586,308.42758023029126,0.0542337050045903
0.055936339118147535,292.174721727655,0.17759787670011842,117.80484780059051,308.51790604396354,0.054427898540863905
0.056150486713723635,292.192919807519,0.17827779531607252,117.81218526639167,308.5996944690152,0.0546306814886962
0.05635891377117454,292.195952820829,0.17893955122347915,117.81340817735826,308.66379933014434,0.05482800800291612
0.05657048270608034,292.192919807519,0.17961128259180506,117.81218526639167,308.72241432432935,0.05502826924776926
0.056786941482407836,292.205051860761,0.18029853920664488,117.81707691025883,308.798483041642,0.055233117490292784
0.057002357657027436,292.229315967245,0.1809824855610621,117.82686019799317,308.8870759538783,0.0554369374031412
0.05721610472816024,292.267228633628,0.18166113251190874,117.84214658507881,308.98962099573885,0.05563913701085826
0.05743231703722994,292.277844180215,0.18234760659320504,117.8464267734627,309.0640379901312,0.05584362708835547
0.05764443830521014,292.306657806665,0.18302109161904218,117.85804442764733,309.15651090880345,0.05604420729723497
0.05786563468232924,292.358219032945,0.18372339011639532,117.87883391408343,309.27571293188174,0.05625332601593032
0.05808443722061474,292.374900606153,0.18441808817545177,117.8855599244009,309.3573321652946,0.05646013858865681
0.05830357086984144,292.394615192672,0.18511383751174657,117.89350884568536,309.44226536151797,0.05666722126836577
0.05852543263865944,292.400681219293,0.1858182486277437,117.89595466761894,309.5135575914909,0.05687683836002765
0.058748582475003835,292.408263752569,0.18652674935813718,117.89901194503582,309.58683475200945,0.05708762811664645
0.05897152520581714,292.414329779191,0.1872345925284694,117.90145776696981,309.6584487983067,0.0572981778779944
0.059192666201957636,292.424945325778,0.1879367151912155,117.90573795535371,309.73435750357254,0.057506982273650864
0.059416516801485235,292.432527859054,0.1886474408447156,117.90879523277057,309.8078500638923,0.05771830071988098
0.05964085346556744,292.423428819122,0.18935970975317662,117.90512649987001,309.8638116872221,0.05793003322704948
0.059866557236221835,292.441626898986,0.19007631922500431,117.91246396567117,309.94910029398795,0.05814301079944944
0.060094632819606635,292.43707737902,0.19080045920225105,117.91062959922088,310.01097616695114,0.05835818038400087
0.060320085940324335,292.424945325778,0.19151627286052975,117.90573795535371,310.0640431589236,0.058570830409085756
0.060546282117413835,292.421912312467,0.19223444572278892,117.9045150443867,310.12697191265124,0.05878413585949404
0.06077608353445864,292.421912312467,0.19296406522190618,117.9045150443867,310.1941708824756,0.05900079450757563
0.06100837502817614,292.402197725948,0.19370159071445922,117.89656612310222,310.2411806638756,0.05921975312394993
0.061242293843514636,292.400681219293,0.19444428295315896,117.89595466761894,310.3079696585688,0.05944019722107447
0.06147633846665644,292.361252046256,0.1951873746316342,117.88005682505043,310.3345513315871,0.05966071125484953
0.06171192841951174,292.350636499668,0.19593537273194975,117.87577663666613,310.3921580527342,0.05988263218150181
0.06195167491113444,292.332438419805,0.19669656784285183,117.86843917086537,310.44292261076794,0.06010841793425956
0.062191936956719644,292.309690819976,0.19745939983758487,117.85926733861434,310.48899668329017,0.060334638087423884
0.062435783822510645,292.264195620317,0.1982336136364713,117.84092367411182,310.5119397571271,0.06056418123465562
0.06267669869803423,292.230832473901,0.19899851836625868,117.82747165347688,310.5468963111434,0.0607909126463218
0.06292033710909962,292.206568367416,0.1997720703213913,117.81768836574214,310.592304154587,0.06102015497967855
0.06316473823934333,292.183820767587,0.20054804390991507,117.80851653349107,310.63953532414286,0.06125006217779977
0.06340798240041214,292.141358581239,0.20132034412130853,117.79139577995556,310.6654527045907,0.061478828548936465
0.06365685954600443,292.09586338158,0.20211052905856405,117.77305211545305,310.68976873083017,0.06171283847831914
0.06390870401495923,292.048851675266,0.20291013524749552,117.75409699546726,310.71331529488936,0.06194958274081747
0.06414989544632144,292.004872982263,0.20367591804207055,117.73636478644845,310.73695505389156,0.06217626017578667
0.06439171808632403,291.93511367612,0.2044437049240788,117.7082378342116,310.7333172154517,0.06240347926279485
0.06463412191274623,291.877486423219,0.20521333707296927,117.68500252584191,310.7427314642833,0.06263119263565811
0.06487940156677133,291.80317759711,0.20599209997449897,117.65504120715475,310.73519313489277,0.06286155478401301
0.06512519210628644,291.724319251035,0.20677248493745942,117.62324552201731,310.72292158433436,0.06309234352628737
0.06536918559782984,291.628779331752,0.20754716427310974,117.58472382656242,310.6923151335579,0.0633213922345716
0.06561230521390413,291.468029626291,0.2083190690541456,117.51990954532053,310.5919189462265,0.0635495684230345
0.06586335744987043,291.351258613834,0.2091161599033386,117.47282747309787,310.54063070338657,0.06378513502276138
0.06612048130453733,291.257235201206,0.20993252814190602,117.43491723312627,310.5153037761386,0.06402634121883065
0.06637608278720464,291.155629255302,0.21074406284937472,117.39394971573779,310.4813994067126,0.0642660616368565
0.06663218431543813,291.047957282777,0.21155718520151606,117.35053637641569,310.44111841707473,0.06450619341075901
0.06688882773196714,290.902372643869,0.21237202804899566,117.291836650008,310.3604913344652,0.06474677544985556
0.06714268113910343,290.791667658033,0.2131780126166534,117.24720039971892,310.31619987750446,0.0649846851595093
0.06739936398274184,290.734040405132,0.2139929806452053,117.22396509134924,310.3293298165707,0.06522518906100182
0.06765996450419803,290.605137339433,0.21482038730082875,117.17199137525938,310.2674706165566,0.06546930454694934
0.06791646131124034,290.456519687214,0.21563476466318807,117.11206873788467,310.1832986691482,0.06570951773264964
0.06817588863074933,290.265439848648,0.21645844640262912,117.03502534697488,310.05454414912487,0.06595241670730442
0.06843353278180213,290.074360010082,0.21727646658222174,116.95798195606505,309.9251732349922,0.06619358774186006
0.06869286444565594,289.916643317932,0.21809984461495757,116.89439058579019,309.8318479979103,0.06643627967197989
0.06895061994976223,289.730112999332,0.21891821834049507,116.81918156133067,309.7071839087506,0.06667743822553396
0.06920858260122294,289.536000147455,0.2197372497588828,116.74091525945387,309.5743763296879,0.0669187323746362
0.06946383349288693,289.338854282268,0.22054767133991598,116.66142604661047,309.43744027915415,0.06715743269260462
0.06971821477548813,289.128059857183,0.2213553319121748,116.57643373441618,309.28555203192633,0.06739526311382213
0.06996796292649153,288.965793645067,0.2221482822916106,116.51100799769101,309.18414158184925,0.0676287068353736
0.07021623498116573,288.785329353088,0.2229365460652012,116.43824479516509,309.06274789805775,0.06786071682407509
0.07046035772672463,288.577567941313,0.22371163578235068,116.3544753939374,308.91084661036615,0.06808879681284952
0.07070816205405082,288.357674476296,0.22449841452161134,116.26581434884254,308.7469156526952,0.06832026325385429
0.07095181642307613,288.127165464693,0.2252720171432667,116.17287311536423,308.5703112152452,0.06854780111936541
0.07119356130564623,287.842062213499,0.22603955714542678,116.0579194844828,308.3345637160394,0.06877350464640854
0.07143350783638873,287.538760882441,0.2268013873805342,115.93562838780022,308.0786632112024,0.06899747879030069
0.07167037475122423,287.209678938244,0.22755343983513693,115.80294254789999,307.7941042599267,0.06921852912549385
0.07189071545730613,286.860882407528,0.22825302157694696,115.66230778671529,307.4835164805193,0.06942411291581777
0.07200818478433993,286.692297417682,0.22862598669027925,115.5943343188094,307.3364893463814,0.06953369767948189
0.07212209049135074,286.500863727562,0.22898763731003857,115.51714825495299,307.1639049471713,0.0696399465473155
0.07223278661173434,286.282714245199,0.2293390974922565,115.42919038366423,306.96171245390053,0.06974319076464532