File: example/data/02 processed data/test_ID_065.csv
Strain,Stress_MPa,Displacement(mm),Force(kN),True Stress (MPa),True Strain
0.0007743519844788439,28.9731903230109,0.002458567550720329,11.681990338237995,28.99562577043421,0.0007740523286637546
0.0008456411668879438,32.1663266397618,0.0026849107048692216,12.969462901151958,32.19352780975595,0.0008452838138438832
0.0009259045286878438,35.3874871288498,0.002939746878583904,14.26823481035224,35.42025256344128,0.0009254761434984691
0.0010244021141700439,38.5033476645643,0.003252476712489889,15.524549778352327,38.542790575314505,0.0010238777723850093
0.0011176513874038437,41.596611125241,0.0035485431550072036,16.77175360569717,41.64310163537642,0.001117027280071611
0.001190991539813344,44.6282073044674,0.003781398138907367,17.994093185161258,44.681359121804064,0.0011902828720118648
0.0012715893423618438,47.6272209964122,0.004037296161998854,19.2032955057534,47.687783263037545,0.0012707815573420528
0.001341449110255244,50.5791184576805,0.004259100925060399,20.39350056213678,50.64696777113305,0.0013405501712283761
0.0014181470195887438,53.526792966525,0.004502616787194261,21.58200292410288,53.60270182843862,0.0014171423987918916
0.001497266433855444,56.4486583430753,0.004753820927491034,22.760099043927962,56.53317702444856,0.0014961466480742857
0.001582965578405544,59.307087880437,0.005025915711437601,23.9126178333922,59.40096895910721,0.0015817140090145325
0.0016576082299370439,62.1688830299686,0.005262906130050114,25.06649363768334,62.27193468212507,0.0016562359137142714
0.0017288428274320439,65.0762122913722,0.005489075977096739,26.238728795881272,65.18871883422858,0.0017273500988854266
0.0017954050877424439,68.0174257632952,0.005700411153582259,27.424626067760624,68.13954459556575,0.0017937952745843827
0.0018740196010201438,70.9939288529962,0.005950012233238956,28.62475211352807,71.12697286722015,0.001872265817029448
0.0019588178292626436,73.936788833584,0.006219246607908893,29.811313257701073,74.08161753378965,0.001956901847250365
0.0020452431711899437,76.6843394960975,0.006493647068528071,30.919125684826508,76.8411776177891,0.0020431545087721183
0.002116210096442044,79.385820110925,0.006718967056203489,32.008362668724956,79.55381718495806,0.0021139740778902227
0.002173281376435844,81.8818276653282,0.006900168370183804,33.01475291466033,82.05977991646179,0.0021709232164773495
0.002238810507120544,84.4718627969715,0.007108223360107726,34.059055079738904,84.6609792909574,0.0022363081051170407
0.0023129541351905435,87.0657322823019,0.0073436293792299755,35.10490325622413,87.26711132781763,0.002310283374213724
0.0023941234250838437,89.5786348354455,0.007601341874641203,36.118105565651625,89.79309714349208,0.002391262077632653
0.0024711640189083437,92.0796983720691,0.00784594576003399,37.126534383618264,92.3072424095581,0.002468115713979009
0.002535155911552844,94.4135171308147,0.008049120019180279,38.067530107144485,94.65287011689936,0.0025319478246611698
0.002602802457438944,96.7544207933968,0.008263897802368646,39.0113824638976,97.00625343760593,0.00259942103330452
0.0026713884508312437,99.1122494702018,0.008481658331389199,39.96205898638537,99.3770167887724,0.0026678266346232015
0.0027485422274907438,101.442706126329,0.00872662157228311,40.90169911013586,101.72152568778814,0.002744771892339355
0.002834374465850444,103.726637839157,0.008999138929075159,41.8225803767481,104.02063797287683,0.0028303652005968977
0.002886329444638844,106.035512129448,0.00916409598672833,42.753518490593436,106.34156555028459,0.002882171993734765
0.0029717254007039437,108.285480306269,0.009435228147235021,43.66070565948766,108.60727501862257,0.002967318553243769
0.0030842718993676437,110.560953085638,0.009792563280492269,44.57817628412924,110.90195312640734,0.0030795252901774386
0.0032094776887390437,112.79736453664,0.010190091661746463,45.47989738117325,113.15938516146892,0.0032043383087692772
0.003368079542479544,114.923949481569,0.010693652547372551,46.33733643096862,115.31102248475882,0.003362420266278697
0.003568798422624044,117.147531212825,0.011330934991831338,47.23388458501104,117.56560713743163,0.003562445372217502
0.003800696943721644,119.268755341306,0.012067212796316219,48.08916215361458,119.7220597352132,0.0037934925438164826
0.004105049915861844,121.500349539741,0.013033533482861355,48.988940934423574,121.9991145393963,0.004096647186356041
0.004422191485731344,123.683106961713,0.014040457967197016,49.86902872696268,124.2300573442479,0.004412442328157372
0.004767709788073644,125.831744744734,0.015137478577133818,50.73535948107675,126.43167398580384,0.004756380256104534
0.0051394947198231435,128.007989015343,0.01631789573543848,51.612821170986294,128.6658853989825,0.00512633259535283
0.005521676555159644,129.966746692935,0.017531323062631866,52.40259226659139,130.68438103109975,0.005506487984434906
0.005912488446784644,131.721652210257,0.018772150818541243,53.110170171175625,132.50045495714153,0.00589507827820927
0.006318707170815144,133.006970776921,0.020061895267338082,53.62841061725455,133.84740287693754,0.006298827837835732
0.006719893958378244,133.892050881525,0.021335663317850924,53.985274915430885,134.79179126531864,0.006697416113937059
0.007158604795866144,134.390673524676,0.022728570226875005,54.18631956514936,135.35272324468943,0.007133103614150091
0.007591584510663844,134.647228256835,0.024103280821357702,54.28976243315588,135.66941406927342,0.0075629134474102105
0.008016029055991844,134.677271479172,0.025450892252774103,54.301875860402156,135.75684840053074,0.0079840713640057
0.008444468066988444,134.655055230576,0.02681118611268831,54.29291826896825,135.79214554452918,0.008409013006110716
0.008867971625740744,134.546790667391,0.02815580991172686,54.24926599709205,135.7399477893639,0.008828882091970755
0.009305357128591443,134.423594066738,0.02954450888327783,54.19959312770876,135.6744536160378,0.009262329014954919
0.009745035581081144,134.222778838688,0.03094048796993263,54.118624427758995,135.53078459426257,0.009697858966091611
0.010191953880479145,134.052719688664,0.03235945357052128,54.05005657846933,135.41897882528366,0.010140366142327682
0.010628500185199345,133.856541924768,0.03374548808800792,53.97095770406646,135.27923620540554,0.010572414729952219
0.011075277007277545,133.667104295306,0.0351640044981062,53.89457645186738,135.14750450213717,0.011014395236089112
0.011522896990262044,133.472586212913,0.036585197944081986,53.816146761046525,135.01057707486828,0.011457014038031092
0.011973028005605143,133.225662604537,0.03801436391779633,53.716587162149324,134.82077719396642,0.011901918341724122
0.012418190350156644,133.0156452193,0.03942775436174734,53.631908152421765,134.66745882118218,0.012341717079922895
0.012854767022299143,132.777723980061,0.040813885295799775,53.535978308760605,134.48455068757585,0.01277284580982138
0.013305960681470844,132.610977189965,0.04224642516366993,53.468746002993896,134.37549363838613,0.013218213899786366
0.013757467178798343,132.392822243659,0.043679958292684735,53.38078592864331,134.2142121503846,0.013663692318062423
0.014209819314556444,132.236327447522,0.04511617632371671,53.317687226840874,134.1153817673718,0.014109806164447347
0.014664808474009243,132.037463097629,0.046560766904979345,53.237505120964016,133.9737672053498,0.014558319996547667
0.015111307135262144,131.837577996977,0.047978400154457305,53.15691144838112,133.8298161300584,0.014998268683519689
0.015589392114143844,131.63463450616,0.0494963199624067,53.075084632883716,133.68673843927857,0.015469125849119008
0.016046622473725243,131.373882398037,0.05094802635407764,52.96994938288853,133.4819894917859,0.01591923636499667
0.01651137069721404,131.113894955564,0.05242360196365458,52.865122446083404,133.27876507873088,0.016376540149832818
0.016991148279297444,130.910383574383,0.05394689578676938,52.78306665719122,133.13470131299505,0.01684841327170869
0.017450104962784645,130.693797718271,0.05540408325684124,52.69573924000686,132.97441820643976,0.01729960024065319
0.017902042350186442,130.54882244123,0.05683898446184195,52.63728520830393,132.88591298933983,0.01774368790914405
0.018351467896496144,130.384852700238,0.05826591057137526,52.57117260873597,132.77760613875583,0.018185111878552634
0.018802173505771243,130.173517518336,0.05969690088082369,52.485962263393084,132.62106258057233,0.018627597518780143
0.019270056425412845,129.994290216919,0.06118242915068578,52.413697815461745,132.49928752438055,0.019086740154639542
0.019738670286683246,129.776140671156,0.0626702781602193,52.32573991861011,132.3377491229422,0.019546388868626797
0.020207229313394144,129.52930606758,0.0641579530700264,52.22621620644826,132.1467344580924,0.02000577265428781
0.020662171742590343,129.311578357132,0.06560239528272434,52.138428393595625,131.9834363974525,0.020451604647747455
0.021112387695484847,128.987941153059,0.06703183093316438,52.00793787291339,131.71118457472477,0.020892609222038075
0.021565693094997847,128.771548097945,0.06847107557661816,51.92068819309142,131.54859578359302,0.021336443628660752
0.02202657451684204,128.554829039115,0.06993437409097347,51.833307068571166,131.38645156044495,0.021787493906117904
0.022500068295554343,128.412029700261,0.07143771683838504,51.775730375145244,131.30130913848762,0.022250675727535658
0.022969487365258043,128.282918671384,0.07292812238469429,51.723672808302034,131.22951155098477,0.02270965990224063
0.02344545136772804,128.132222408132,0.07443930809253653,51.662912074958825,131.13634019724077,0.02317482852669102
0.02391854553437514,127.915545784431,0.07594138207164107,51.575548060282586,130.97509959083035,0.023636978076827988
0.024374054009240143,127.715730778665,0.07738762147933745,51.49498264995773,130.82868089849376,0.024081747034618003
0.024834439434644945,127.391959426379,0.0788493452049977,51.36443804071602,130.55566732721417,0.02453107704142175
0.025293990008570744,127.162347251515,0.0803084182772121,51.27185841181085,130.37879039236122,0.024979390986073
0.025775000144873446,126.988535925805,0.08183562545997318,51.20177768528458,130.2616654576899,0.0254484245948207
0.026253602296881146,126.861336176441,0.08335518729259764,51.15049074634101,130.19190324326823,0.025914891933644723
0.026736778909661543,126.711265831349,0.0848892730381754,51.08998238319992,130.09911693124513,0.026385597131413488
0.027211704530088643,126.52757845039,0.08639716188303144,51.01591963119725,129.9706095300896,0.026848048485690605
0.027669492974436743,126.323779702615,0.08785064019383665,50.93374797609437,129.8190946376008,0.027293610450516294
0.028133152435735546,126.146785373609,0.08932275898346036,50.862383862639156,129.69569211580276,0.02774468436093819
0.028602351075408546,125.929547205584,0.09081246466442212,50.77479343329147,129.53142832552535,0.028200940060333073
0.029083149011137545,125.693450148076,0.0923389981103617,50.67959909970425,129.34901148845648,0.02866825923467616
0.029564337643605644,125.523900251657,0.09386677201844791,50.611236581468106,129.23493122103926,0.02913573960161662
0.030041137368098846,125.346825523466,0.09538061114371382,50.539840051061496,129.11238672767155,0.029598740636325106
0.030528517691406944,125.176023630473,0.09692804367021704,50.47097272780671,128.99746208241586,0.03007179461069594
0.031017846570756742,125.027494715819,0.09848166286215265,50.41108586941822,128.90557836404037,0.030546514846943856
0.03150122772435084,124.809993187175,0.10001639802481392,50.32338925306897,128.7416612048389,0.03101524376050276
0.031995574950708046,124.654505119614,0.10158595046849804,50.26069646422837,128.64289768111203,0.03149437921171709
0.032484628016870444,124.501652324876,0.10313869395356365,50.19906621739001,128.54604218813535,0.031968157622967834
0.03297403960659524,124.344068910619,0.10469257575093989,50.13552858476158,128.44419516372295,0.03244205875355522
0.03344406887193355,124.196204374968,0.106184918668389,50.0759096039871,128.34983078771717,0.03289698050585308
0.03392102008568004,124.011214277199,0.10769923877203413,50.00132159656664,128.21780116754545,0.0333583902730548
0.034396902824825146,123.830099686219,0.10921016646881983,49.928296193483504,128.0894715919143,0.033818554295491784
0.03487825376357265,123.660540094462,0.11073845569934315,49.85992976608708,127.97360379241708,0.034283790584534284
0.03536737115396925,123.484511661438,0.11229140341385235,49.78895510189181,127.85183421713472,0.034756311713051935
0.03584381651873574,123.276004072596,0.11380411744698597,49.704884842070705,127.69468654373705,0.035216376216378194
0.03634443518026335,123.114111072868,0.11539358169733611,49.63960958458038,127.5886239025316,0.0356995549728031
0.03683294385231345,122.904018833216,0.1169445967310952,49.55490039355269,127.43093565812352,0.03617082065998629
0.037328812300281344,122.662765538892,0.11851897905339326,49.45762706528126,127.24162088992672,0.03664895931618702
0.037821444872012944,122.490912863633,0.12008308746864109,49.38833606661683,127.12369617182743,0.03712375151909699
0.038300306854405344,122.364117321699,0.12160347426273696,49.33721210410904,127.05070056308854,0.03758505586262717
0.03879396671153325,122.280470454036,0.12317084430911805,49.303485687067315,127.02421495430052,0.03806039284921026
0.039273606361885045,122.146820821396,0.12469370019898501,49.24959815518687,126.94396698069121,0.03852201369839148
0.039771832424799945,121.939151486614,0.12627556794873981,49.165865879402766,126.78889498556191,0.039001297184127225
0.040274545648263146,121.738788926655,0.1278716824332355,49.0850796952273,126.64176333844584,0.039484664515308444
0.04078912589635795,121.540454454993,0.1295054747209365,49.00511123625318,126.49798335325826,0.03997920032948684
0.041292274134756744,121.372215031653,0.13110297037785265,48.937277100762486,126.38394980708266,0.04046251308391185
0.041807460438571045,121.27916177973,0.13273868689246307,48.89975802958714,126.34953553785911,0.0409571474077203
0.04231459505454854,121.091061497861,0.1343488392981916,48.82391599593756,126.21498072986842,0.04144381240380354
0.042829152222063946,120.933112208815,0.13598255830505301,48.76023084259421,126.11257488029428,0.041937358403816634
0.04333642881002315,120.790062377699,0.1375931614718235,48.70255315068824,126.0246723168884,0.04242368279011614
0.04384413476290244,120.665405258604,0.13920512787221526,48.652291400269135,125.95587554798246,0.042910182110542844
0.044357701208665744,120.574044107469,0.14083570133751372,48.615454584131506,125.9224315295086,0.043402056456471494
0.04488130126697325,120.432982814085,0.14249813152264004,48.55857867063907,125.83817179824416,0.04390329166091617
0.04539703430947734,120.249060661733,0.14413558393259054,48.48442125881075,125.70801139427611,0.04439675039719207
0.04589310386251295,120.094812956341,0.1457106047634786,48.42222858399669,125.60633668069543,0.04487116526032857
0.04640468572813865,119.931025199235,0.14733487718684019,48.35618936033155,125.49638673265896,0.045360179661974004
0.046911611881073546,119.751169127146,0.1489443677224085,48.28367139206527,125.36888949554347,0.04584450796288407
0.047409998109647244,119.621734017595,0.15052674399812999,48.2314831558943,125.2930002012419,0.04632044846371644
0.047919281336873246,119.474385257866,0.15214371824457254,48.172072135971575,125.19951193758766,0.046806561307411725
0.048417026022051446,119.290614272651,0.15372405762001334,48.09797567473288,125.06631104807643,0.04728143234101873
0.048934757832482544,119.090277609658,0.15536785611813206,48.01719993221411,124.91793150468973,0.047775132849376706
0.04946457136497404,118.903357001954,0.15705001408379257,47.94183354318786,124.78486058991214,0.048280102076518304
0.04998991667072115,118.716610269308,0.15871798542953963,47.86653726058499,124.65124372410119,0.048780560952579516
0.050519363278623046,118.575017767589,0.16039897840962816,47.80944716389188,124.565352165959,0.04928467357342629
0.051044578558656746,118.35603456704,0.16206653692373515,47.72115313743053,124.39746847138838,0.04978450636986208
0.051586664408613044,118.147907484133,0.16378765949734642,47.637236297602435,124.24276393809684,0.05030013255374934
0.05211758735971075,117.990616516506,0.16547333986708163,47.57381657945522,124.14000278043113,0.05080488312591127
0.05265268386662625,117.856713827548,0.16717227127653833,47.51982701526736,124.06218612226931,0.05131334385985335
0.053181026428116944,117.812196171641,0.16884975890927129,47.50187749640565,124.07756968979955,0.05181513331264251
0.053715592090515046,117.722352140486,0.17054700488738525,47.46565238304395,124.04587798800031,0.05232257698042415
0.05425438515305365,117.554106691615,0.17225767286094532,47.39781581805917,123.93193247238506,0.052833773136051
0.05480515270581675,117.385835970764,0.17400635984096816,47.329969063412044,123.81918463664168,0.05335606049247352
0.05534063129869504,117.197389669516,0.17570650437335675,47.25398751474885,123.68316720038618,0.05386358808457801
0.05588875588959705,117.044805956447,0.1774467999494706,47.192465761639426,123.58629454469212,0.05438283493339849
0.05641943583545234,116.855563515761,0.17913170877756118,47.116163209554834,123.44848848355412,0.0548852994497975
0.056938402955993145,116.680458399361,0.18077942938527822,47.045560826622356,123.32405735679382,0.05537642984091876
0.057468316083264845,116.514466114842,0.18246190356436587,46.9786327375043,123.21035628180258,0.055877670338874676
0.058004304968662344,116.353134499185,0.18416366827550293,46.913583830071396,123.1021171967355,0.05638440239631927
0.05854907219265275,116.225756740223,0.18589330421167247,46.86222511765792,123.03066696225201,0.0568991706435068
0.05909633723993905,116.099525114366,0.18763087073680645,46.811328526112376,122.96058180392136,0.05741603249113442
0.05964987812083355,115.935250683375,0.1893883630336465,46.7450930755368,122.8507742565466,0.05793854990211584
0.060192370630120146,115.743828810975,0.19111077675063146,46.66791177658512,122.71072425291439,0.058450373384687844
0.060746494451546645,115.520060488689,0.1928701198836606,46.5776883890394,122.53749920220747,0.058972900311943674
0.06130653808466614,115.344038577983,0.194648258418815,46.50671635464275,122.41538227190333,0.059500732215798574
0.06187327222973994,115.160523469548,0.1964476393294243,46.43272306292175,122.28588188829869,0.06003458634890632
0.06243214236395075,115.052941105556,0.1982220520055436,46.389345853760176,122.23594270404931,0.06056075376651499
0.06299331512151825,114.953343388733,0.20000377551082044,46.34918805433715,122.19463557309156,0.06108881064908522
0.06353777843905925,114.76190515445,0.20173244654401312,46.27200015827424,122.05362165739777,0.06160087777200357
0.06409631200332384,114.623798422982,0.20350579061055318,46.216315524146346,121.97076116970756,0.06212590562298959
0.06465303009488374,114.455762778006,0.20527337055125586,46.14856355209202,121.85567465342531,0.06264895274107202
0.06522375583010495,114.32171227121,0.2070854247605832,46.09451438775187,121.77820371846693,0.06318487646459708
0.06579601779904294,114.143067827836,0.20890235651196132,46.022484948183475,121.65322715027366,0.06372195452438364
0.06637087275983634,113.903854384417,0.21072752101248038,45.926034087796936,121.46375261062008,0.06426117589328091
0.06693938845859104,113.732680238546,0.21253255835602655,45.85701667218174,121.34587630147075,0.06479416513778823
0.06750864023749145,113.564670009777,0.21433993275403534,45.78927494794208,121.23126646115647,0.06532755998717647
0.06806942379176925,113.477289267378,0.21612042053886735,45.75404303260681,121.20162296126033,0.06585274197570953
0.06862365190560694,113.357382158477,0.21788009480030204,45.705696486297924,121.13637969265118,0.06637151384104781
0.06917787651840195,113.17741959793,0.21963975794592616,45.63313558188537,121.00679315554696,0.06689001344715494
0.06974137611249125,112.994156103531,0.2214288691571597,45.55924374094371,120.8745240428609,0.0674169146907928
0.07031028510586125,112.81868525657,0.22323515521110945,45.48849389544903,120.75099918222787,0.06794859251622232
0.07090573928023465,112.643685987614,0.225125722214745,45.41793419020597,120.63076981781637,0.06850477571580757
0.07149003405027045,112.443184503886,0.22698085810960866,45.33709199196684,120.48175159278965,0.06905023495522199
0.07207220946716615,112.210680362128,0.22882926505825252,45.24334632201001,120.29795202164053,0.06959341995763617
0.07265292142799634,111.998026422039,0.23067302553388838,45.157604253366124,120.13501023577005,0.07013494573793873
0.07323679756100135,111.794677489842,0.23252683225617926,45.075613963904296,119.982161653563,0.0706791266827907
0.07380317693303505,111.649726859791,0.23432508676238628,45.01716986986773,119.88983140574918,0.07120671759111075
0.07437552355165865,111.496536314755,0.2361422872765162,44.95540344210922,119.78914957736141,0.07173958446297524
0.07494518704537964,111.356209158726,0.23795096886908035,44.898823532798325,119.70182108279114,0.07226967148465767
0.07553265175109504,111.208377058385,0.23981616930972674,44.83921762994083,119.60824067454045,0.07281602886600844
0.07612317337965045,110.974783513264,0.24169107548039018,44.745032712548046,119.42253619941336,0.07336492858917491
0.07672027404643984,110.778741644344,0.24358687009744648,44.6659886309995,119.27771706181782,0.07391963746298008
0.07730806250715505,110.531952825196,0.24545309846021726,44.56648337911903,119.07696394324415,0.07446539488439355
0.07791147567827404,110.397859418535,0.24736893527852008,44.51241691755332,118.9991195575557,0.07502535007800107
0.07850841765215065,110.228695108087,0.2492642260455783,44.444209867580675,118.88257554088426,0.07557899177920299
0.07909944844537364,110.070537745883,0.2511407488140613,44.380440819140034,118.77705657166801,0.07612684926275483
0.07968010389291225,109.895547082541,0.25298432985999636,44.309884583680535,118.6520356914463,0.07666479716105938
0.08025652117636835,109.683275250922,0.2548144547349695,44.22429658117175,118.48607335379106,0.07719853254056061
0.08082412613359885,109.484980057396,0.25661660047417634,44.14434395914207,118.33400789528953,0.07772382989213238
0.08142481052178635,109.327988683707,0.25852377340667165,44.08104503727067,118.22999944700584,0.07827944066705944
0.08201903305538724,109.162882809429,0.2604104299508545,44.01447434876177,118.1163169029969,0.07882877089377911
0.08262405771591065,108.975514934178,0.2623313832480163,43.93892762146057,117.97951416972062,0.07938777729890732
0.08319771089921145,108.74124747497,0.26415273210499635,43.8444709819079,117.78827034521215,0.0799175098974325
0.08378199043928775,108.42373624978,0.2660078196447386,43.7164504559113,117.50769268365093,0.08045676696003848
0.08437050339944495,108.212390427045,0.2678763482932377,43.631235820184536,117.34232428143204,0.08099963742351625
0.08496630785834784,107.981079148314,0.2697680274502544,43.53797111260021,117.15583276210626,0.08154893384516165
0.08557082334031954,107.847138960034,0.27168736410551453,43.48396642868571,117.07570743574198,0.08210595310911523
0.08617884666595364,107.693990994356,0.2736178381644028,43.422217168924334,116.9749349311032,0.08266589180731564
0.08679981234656255,107.4440357261,0.27558940420033606,43.321435204763524,116.77015786488283,0.08323742590401434
0.08741062132307574,107.189869732764,0.27752872270076545,43.21895547625044,116.55940284564444,0.08379929331401595
0.08802395811331525,106.945348228353,0.2794760670097759,43.12036440567193,116.35910108121946,0.08436316851604543
0.08864676065813984,106.74684178865,0.28145346508959396,43.04032660918369,116.20960352370078,0.08493542095317283
0.08926089607754635,106.547044426795,0.2834033450462096,42.959768312883746,116.05752908674485,0.08549938924979439
0.08987518728267464,106.360376859383,0.28535371962249195,42.88450394970322,115.9195356490759,0.0860631826045011
0.09049207643601044,106.127324378189,0.28731234268433314,42.79053718928581,115.73100632776935,0.0866290406414119
0.09110121242312394,105.900971166784,0.2892463494434185,42.699271574447316,115.5486780368643,0.08718747287170331
0.09170847141239555,105.69286982059,0.29117439673435586,42.61536511166189,115.38580135102562,0.08774387410946119
0.09231708036803554,105.456113944877,0.29310673016851285,42.51990514257441,115.19151449122693,0.08830120181187519
0.09292820616626485,105.226875593377,0.2950470545778909,42.42747623924961,115.00542038275024,0.08886052191925821
0.09354447741542854,104.944457675414,0.2970037157939856,42.31360533472693,114.76143212630616,0.08942423467003789
0.09418998488823514,104.679983919898,0.29905320202014657,42.20696951650288,114.53979002341389,0.0900143496978545
0.09483855572007195,104.456358159135,0.30111241441122844,42.11680360976323,114.36284830272591,0.09060691469989378
0.09547572440638935,104.22298951379,0.3031354249902862,42.022709371960126,114.17375493741861,0.09118872043441506
0.09610860173208655,103.976310516373,0.30514481049937475,41.923248400201594,113.96932833336285,0.09176627278842785
0.09673277993308775,103.728278594721,0.3071265762875536,41.82324192939151,113.76220334086216,0.09233555994533534
0.09736456282153244,103.397407098489,0.3091324869583655,41.689834542110766,113.4646504375134,0.0929114531781421
0.09801217240888904,103.158411247287,0.3111886473982227,41.593471414906126,113.26919123588318,0.0935014290084847
0.09864885856451744,102.912295236476,0.3132101259423429,41.494237439347124,113.06447569380899,0.09408111441691144
0.09928808530158445,102.672328249002,0.3152396708325306,41.39748274999761,112.8664671343012,0.09466277510274076
0.09990649007035654,102.394969470255,0.31720310597338197,41.28565169040682,112.62489147088951,0.09522516716390417
0.10054267654489264,102.10789357569,0.3192229980300341,41.169902689718214,112.37409449215093,0.095803400464554
0.10117368592865765,101.786936948107,0.321226452823488,41.040492977476745,112.08509653853486,0.09637659818592881
0.10180720872020264,101.496822855319,0.32323788768664335,40.92351897526462,111.82993108418789,0.09695174871088154
0.10246843353764465,101.217606033273,0.32533727648202176,40.81093875261568,111.58921556993293,0.0975516962170818
0.10311822513463265,100.909106215517,0.32740036480245865,40.68655162609645,111.31467414838323,0.09814091959965232
0.10378907482654864,100.63872981041,0.32953031257429194,40.57753585955731,111.08393046915145,0.09874887419075867
0.10442267237876264,100.301649051546,0.33154198480257135,40.441624897583345,110.77541528950522,0.0993227300000156
0.10506616074252265,99.9639121827617,0.3335850603575094,40.30544939208952,110.46673664860717,0.09990520715247493
0.10571670977212465,99.6586217460284,0.33565055352649575,40.18235628799865,110.19420333744323,0.10049373084429039
0.10638389169881464,99.2877072885521,0.3377688561437365,40.03280357874421,109.85031998776104,0.10109694206034157
0.10707386518559664,99.0070604603335,0.3399595219642693,39.919646777606474,109.60812910448547,0.10172037705202709
0.10778286833608765,98.696951360803,0.3422106069670783,39.79461078867577,109.33479187449768,0.10236060191531328
0.10848492258123865,98.3538412719491,0.3444396291954327,39.65626880084988,109.02375012790394,0.1029941483409851
0.10917215086255065,98.0525755860983,0.3466215789885983,39.53479847631484,108.75718616044549,0.10361392703584278
0.10986571713643364,97.6685146517886,0.3488236519081768,39.37994510760116,108.39893605565763,0.10423903245334791
0.11054739603410664,97.2265352463919,0.35098798240828855,39.20173901134522,107.97467554329882,0.10485304334622733
0.11123884136993664,96.8602169557392,0.35318332134954883,39.05403947655405,107.63483526473632,0.10547546628369285
0.11195540246693765,96.5093385299039,0.355458402832527,38.91256529525725,107.31408036683722,0.10612008932893571
0.11267756010158264,96.1859421227553,0.3577512533225249,38.782171863894945,107.02393939721941,0.10676932690849363
0.11340323472166965,95.8416814457491,0.36005527024130113,38.64336595892604,106.71043814286087,0.10742130202770749
0.11410120805300064,95.4205698357872,0.362271335568277,38.4735737577894,106.30817212715624,0.10804798841339647
0.11481031390056265,94.9744425407108,0.3645227466342864,38.29369523241459,105.87848810134076,0.10868426837740706
0.11552972992193565,94.524403313223,0.36680689250214565,38.112239415891516,105.44478209903177,0.10932938619100306
0.11626861735655064,94.0619129809332,0.3691528601070483,37.92576331391227,104.99836154913848,0.10999153155239946
0.11701433160132564,93.670961225813,0.3715205028342089,37.7681315662478,104.63180614410521,0.11065935044461611
0.11773705147909465,93.2259544553304,0.37381513844612546,37.58870483638922,104.20210345422537,0.11130615161313695
0.11846025541566864,92.7744319854539,0.3761113109447479,37.40665097653501,103.76451489449435,0.11195296749075026
0.11921251423371965,92.2790529053992,0.37849973269205983,37.206914131456955,103.27987081335827,0.1126253257163081
0.11996533146739465,91.686872836756,0.380889927408978,36.968147127780014,102.6861189278263,0.11329773078094779
0.12072934138175265,91.1742527385817,0.38331565888706465,36.761458704196144,102.18166022268413,0.11397967103208839
0.12149446061983664,90.6845022746153,0.3857449124679813,36.56399131712489,101.70216696504804,0.11466213570586242
0.12225262144912165,90.1252853754671,0.3881520731009612,36.338515063388336,101.14333777146815,0.11533793456411924
0.12302198696236465,89.5700506318185,0.3905948086055077,36.11464441474922,100.5891362328644,0.11602325433789873
0.12381577161104465,88.9277560373996,0.39311507486506675,35.85567123427952,99.93841476880897,0.11672983377709163
0.12459367242708065,88.2902132159629,0.39558490995598106,35.59861396867624,99.29061511990967,0.11742179035033694
0.12537650531906763,87.7475120595979,0.3980704043880397,35.37979686242987,98.74898847207302,0.11811765106113083
0.12620187380046463,87.0922124601446,0.4006909493164752,35.1155800639303,98.08341286604302,0.11885079766266259
0.12700984572659263,86.3596785692885,0.40325626018193156,34.82022239913712,97.32820802137196,0.11956797124538165
0.12782917755467563,85.6289543892721,0.4058576387360951,34.52559440975451,96.57483320371958,0.12029470326987068
0.12864975143599663,84.8641197848813,0.4084629608092893,34.21721309726414,95.78186770104091,0.12102200801617269
0.12946364708307964,84.2346855827295,0.41104707948877783,33.96342522695653,95.14001518916616,0.12174287144390095
0.13027156379909663,83.5564711736038,0.41361221506213175,33.68996917719705,94.4415033389233,0.12245792579765918
0.13105764454490662,82.744820124778,0.4161080214300785,33.362711474310494,93.58916134862339,0.12315316360255066
0.13187556309333864,81.9710871237282,0.4187049128213502,33.050742328287214,92.78107039554297,0.12387604714262948
0.13270893455810362,81.1192626352499,0.42135086722197895,32.70728669453276,91.8845135517129,0.12461205103495428
0.13352775475335563,80.286309744357,0.4239506213419041,32.37144008892474,91.00676042195344,0.1253346765530613
0.13433801429771663,79.5248711201763,0.4265231953952503,32.064428035655084,90.20808439374261,0.12604923346369898
0.13512096030643264,78.6638495545466,0.42900904897292363,31.71726414039319,89.29298444775769,0.12673921821208128
0.13591532116381663,77.8679449675539,0.4315311446951178,31.39635541091773,88.45139171618538,0.1274387762915895
0.13672462460677964,76.9814891987425,0.43410068312652533,31.038936444932975,87.50675441111143,0.12815099071752972
0.13756012526743663,76.0248474564886,0.4367533977241113,30.653218494456205,86.48283499604092,0.12888572782403265
0.13842128604766862,75.0639582910999,0.43948758320134784,30.265787982971478,85.4544079335825,0.12964246583344363
0.13928296441737464,73.9519260596474,0.44222341202516446,29.817416587249838,84.25216954560959,0.13039908593514243
0.14013316492493563,72.8616016084288,0.4449227986366706,29.377797768518494,83.0719284433177,0.1311450669221538