File: example/data/02 processed data/test_ID_130.csv
Strain,Stress_MPa,Displacement(mm),Force(kN),True Stress (MPa),True Strain
-8.65551899589802e-06,-1.24752732028509,-2.7481272811976213e-05,-0.25150150776947416,-1.2475165222886715,-8.655556455091057e-06
-6.85167967753434e-05,-0.701891520227192,-0.00021754082976171526,-0.14150133047780192,-0.7018434288685423,-6.851914415827508e-05
-0.0001204071117912,0.61918772254517,-0.00038229257993705997,0.12482824486510627,0.6191131679398417,-0.00012041436130939629
-0.0001910923396982,3.56428881462152,-0.000606718178541785,0.7185606250276985,3.563607706332574,-0.00019111060016563532
-0.0002224425871478,7.36887162108791,-0.0007062552141942649,1.4855645188113227,7.367232470220156,-0.00022246733116953687
-0.0001870026217915,11.3185712100479,-0.0005937333241880125,2.2818239559456566,11.316454607556686,-0.00018702010896190908
-0.0001443229207849,14.9988699791831,-0.00045822527349205744,3.023772187803313,14.996705298459231,-0.00014433333633980235
-8.21419397484112e-05,18.3534943972285,-0.0002608006587012055,3.7000644704812653,18.351986805597548,-8.214531358231535e-05
-2.23885480673676e-05,21.8448137109688,-7.108364011389212e-05,4.40391444413131,21.84432463730701,-2.2388798694636652e-05
5.97345050206075e-05,25.6113656819896,0.00018965705344042882,5.163251321489104,25.612895564241516,5.973272098611462e-05
0.0001347113621981,29.4769439119903,0.00042770857497896744,5.942551892657244,29.480914791258122,0.00013470228943735527
0.0002185410944712,33.3542812303072,0.00069386797494606,6.724223096029932,33.361570511432575,0.00021851721784491368
0.0002979940217513,37.0404364995664,0.0009461310190603773,7.467351998312586,37.051474328206325,0.0002979496303515424
0.0003783373637886,40.5581672947047,0.001201221130028805,8.176526526612468,40.57351196479908,0.0003782658122547632
0.0004657000596289,44.0590243676026,0.0014785976893217573,8.882299312508685,44.07954265787779,0.0004655916550108205
0.0005420548491101,47.4630720379314,0.0017210241459245674,9.56855532284697,47.488799626283225,0.0005419079904483664
0.0006372551815783,50.7783109097,0.0020232852015111026,10.23690747939552,50.810669651439,0.0006370522207157505
0.000715808366182,54.0503964144151,0.00227269156262785,10.896559917146083,54.08908614036399,0.0007155522975635521
0.0008029615774848,57.198755364448,0.00254940300851424,11.531269081472717,57.24468376728559,0.0008026393763025029
0.0008790315493429,60.2805335081453,0.0027909251691637074,12.152555555242094,60.333521998910186,0.00087864542736965
0.0009533191476253,63.2292581357875,0.003026788293710327,12.74701844017476,63.28953579825848,0.000952865027517929
0.0010251810441033,66.0615988653128,0.0032549498150279774,13.31801833124706,66.12932396421267,0.0010246559048945865
0.001096974853205,68.8267046726084,0.003482895158925875,13.875463661997854,68.90220583686322,0.0010963736159453517
0.0011804552753974,71.5418558307867,0.0037479454993867446,14.4228381354866,71.62630779191387,0.0011797590858952526
0.0012582951501193,74.271667107702,0.003995087101628777,14.973168088912724,74.3651227862149,0.0012575041602397646
0.0013282412380843,76.9262838168619,0.004217165930917652,15.508338817479359,77.02846047932003,0.0013273599060191945
0.0013912275638778,79.5134176008786,0.004417147515312015,16.029904988337126,79.62403885914307,0.001390260703455329
0.001469370741703,82.0953660315126,0.004665252104907025,16.55042579195294,82.21599456038871,0.0014682922728325824
0.0015465532897789,84.6513858498337,0.0049103066950480076,17.065719387326475,84.7823037291041,0.0015453586078407696
0.0016138222188501,87.1678351909631,0.005123885544849067,17.573035574498164,87.30850858016335,0.001612521407104388
0.0017013300410335,89.6550018125269,0.005401722880281362,18.074448365405424,89.80753456043948,0.0016998844185010778
0.0017804936693738,92.179444939071,0.0056530674002618145,18.583376099716716,92.3435698572314,0.001778910469493385
0.0018710411590924,94.656618722856,0.00594055568011837,19.08277433452777,94.83372515246697,0.0018692929419006814
0.0019624914748616,97.1097537397087,0.006230910432685579,19.577326353925272,97.30033080354877,0.0019605683041933413
0.0020446854827747,99.4879954268004,0.006491876407809672,20.05677987804296,99.69141708675993,0.0020425979584823813
0.0021211390687471,101.777502897618,0.0067346165432720425,20.51834458415979,101.99338713533365,0.002118892629385171
0.0022094614900607,104.150808328969,0.007015040230942723,20.99680295912015,104.38092552913056,0.002207024219399592
0.0022888500641886,106.365661621277,0.007267098953798804,21.44331738284944,106.60911667270634,0.0022862346370006704
0.0023781831081721,108.591918668682,0.007550731368446417,21.892130803606292,108.85017013534386,0.002375359706216053
0.0024586201992053,110.799446866998,0.0078061191324768275,22.337168488386798,111.07186062512598,0.0024556027374130953
0.0025484078195223,113.049175267935,0.008091194826983302,22.790713734015693,113.33727067017836,0.002545166134570578
0.0026612929692223,115.285306359442,0.008449605177280802,23.24151776206351,115.59211433471101,0.0026577579994261293
0.0027592010257495,117.421666495114,0.008760463256754662,23.672207965414984,117.74565647775253,0.0027554014182485497
0.002884965119378,119.440497083696,0.009159764254025149,24.079204212073115,119.78507875162364,0.002880811594107485
0.0030078592995035,121.308742908791,0.009549953275923612,24.455842570412266,121.6736225392603,0.003003344741225973
0.0031540760130054,123.106344186032,0.010014191341292144,24.818238987904053,123.49463095327795,0.00314911234969963
0.003311708161904,124.784427842382,0.0105146734140452,25.156540653024212,125.19767745054615,0.003306236533392469
0.0034898546102074,126.185146232214,0.011080288387408495,25.43892548041434,126.62551404653217,0.0034837791983733965
0.0036889877949009,127.385819401148,0.011712536248810357,25.680981191271435,127.85574413416228,0.0036822001672874387
0.0039185109342868,128.354847120744,0.012441272216360589,25.87633717954199,128.85780699265536,0.0039108535674477135
0.0041743592516602,129.109308296634,0.013253590624021136,26.028436552601416,129.64825693219748,0.004165670784874568
0.0044557350187974,129.71187094105,0.014146958684681745,26.14991318171568,130.28983266675576,0.004445837620749933
0.0047568335649874,130.142866396158,0.015102946568834994,26.236801865465456,130.76193435127493,0.004745555583052159
0.0050667201519863,130.435907939647,0.016086836482556502,26.295879040632837,131.09679018294744,0.00505392751837095
0.0053870426147629,130.604579697288,0.017103860301872206,26.32988326697326,131.30815213380046,0.005372584402124673
0.0057305409965521,130.657785017458,0.018194467664052916,26.340609459519534,131.4065248110192,0.005714183906727068
0.00608847017324,130.632455581309,0.019330892800036997,26.335503045191892,131.4278073907729,0.006070010328962117
0.006451295986819,130.58803311119,0.020482864758150324,26.326547475215904,131.43049516512679,0.00643057544534951
0.006821314067924,130.533459880892,0.021657672165658698,26.315545511987825,131.42386960711232,0.006798154166108245
0.0071976274633965,130.516276866584,0.022852467196283886,26.312081416303336,131.4556844053792,0.007171848168772918
0.0075877458529348,130.438162955164,0.024091093083067987,26.29633365176106,131.42789458519147,0.007559103704355404
0.0079864451787311,130.335367499177,0.02535696344247124,26.275610087834085,131.37628376655894,0.007954722315439504
0.0083886329558328,130.22106873036,0.026633909634769137,26.25256745604058,131.31344547905525,0.008353643911720459
0.008795378033091,130.095873753837,0.027925325255063922,26.22732814877354,131.24011614404728,0.008756924009673855
0.0092039236543453,129.928964368267,0.029222457602546326,26.19367921664263,131.12482063680068,0.0091618256630038
0.0096043358967629,129.738823765672,0.030493766472222208,26.155346871159477,130.98487900796843,0.009558507463540068
0.0100052930922631,129.568827542983,0.03176680556793534,26.121075632665374,130.86520163817144,0.009955571524844817
0.0104131280178676,129.381470866141,0.03306168145672963,26.083304526614025,130.72873668541013,0.010359284861530413
0.0108132190134082,129.238464985982,0.03433197036757103,26.054474541173974,130.6359488128321,0.01075517421984372
0.0112319421808865,129.060660628187,0.03566141642431463,26.018629182642503,130.5102625061898,0.01116933230246145
0.011649767942491,128.926509693767,0.036988013217408924,25.991584354263427,130.4284736133347,0.011582431857868404
0.012068038598818,128.774401897129,0.03831602255124715,25.960919422461206,130.32845634976326,0.011995800422330428
0.0124873270873071,128.633360788694,0.03964726350220004,25.932485535000712,130.23964763920202,0.012410003463245063
0.0129147398134929,128.462089238626,0.04100429890783995,25.897957190507,130.12114369704057,0.012832055696246266
0.0133397380384676,128.255678124812,0.042353668272134624,25.8563447099621,129.966575272943,0.01325154716274514
0.0137535467972686,128.021860046093,0.043667511081327805,25.80920698529235,129.78261468931032,0.013659825131642609
0.0141646943746259,127.805278185486,0.04497290463943723,25.76554408219398,129.61560089044744,0.014065312468008769
0.0145796929469998,127.634497574216,0.046290525106724364,25.731114710961947,129.49536935829266,0.01447443111376423
0.0149881823590628,127.494876047093,0.047587478990024384,25.702967011093953,129.40579249913293,0.014876969429973151
0.0154128022827446,127.388682741632,0.048935647247714105,25.68155844071301,129.35209932178805,0.015295231569406853
0.0158272591552476,127.247578357892,0.05025154781791113,25.653111796951027,129.26155875744,0.015703314184675004
0.0162632165690437,127.118553849186,0.05163571260671375,25.627100455995897,129.18591042037895,0.01613238702930734
0.0166959775632143,126.943123769754,0.053009728763205394,25.591733751982407,129.06256331601813,0.01655813192566969
0.0171407322259077,126.76490668369,0.05442182481725695,25.555805187431908,128.9377500047973,0.0169954872626464
0.0175800600586386,126.592448838945,0.05581669068617755,25.521037685931315,128.8179516925038,0.017427318343573094
0.0180172698975497,126.389657397869,0.0572048319247203,25.48015493141039,128.66685396746524,0.01785688252033822
0.018451152773067,126.207644278311,0.05858241005448773,25.443461086507497,128.53632080401903,0.01828299556707389
0.018879105746715,126.007257204992,0.05994116074582012,25.403063052526388,128.38616153861855,0.01870310711074981
0.0193127361080638,125.861552850456,0.06131793714310257,25.373689054651926,128.29228380680797,0.01912861206959289
0.0197451526353831,125.7138114252,0.06269085961734133,25.343904383320325,128.19604982016637,0.019552745720911664
0.0201801140831683,125.579336623184,0.06407186221405935,25.3167942632339,128.11354196272845,0.019979194141815503
0.0206164446046557,125.396184204078,0.06545721161978185,25.279870735542126,127.98140768935657,0.020406802201304274
0.0210560187789583,125.188136205352,0.0668528596231926,25.237928258998963,127.82409995219469,0.020837404258175058
0.021495250249994,125.011780595563,0.06824741954373095,25.202374968065502,127.69894010366198,0.02126748548498798
0.0219184251601035,124.867082906402,0.06959099988332862,25.173203913930642,127.6039727180464,0.02168166977009022
0.0223613752888702,124.783605732586,0.07099736654216289,25.15637491568934,127.57393877027077,0.022115025454181616
0.0227994098743642,124.627022873668,0.07238812635110632,25.124807811331472,127.46844544958653,0.022543387464024338
0.0232424572462067,124.459033303887,0.07379480175670626,25.090941114063618,127.3517670643568,0.02297646499375311
0.0236850170990956,124.307260572352,0.07519992928962853,25.060343731386165,127.2514801645499,0.023408878809417413
0.0241213671332006,124.164972224143,0.0765853406479119,25.03165840038723,127.16000110424521,0.023835042185084865
0.0245590441810663,124.017031339362,0.0779749652748855,25.001833518015385,127.06277109123009,0.024262319228500095
0.0250014024984013,123.868277212085,0.07937945293242411,24.97184468595634,126.9651578674479,0.024693980880558637
0.0254347527913498,123.67349475751,0.08075534011253561,24.932576543114013,126.81909952350958,0.025116671729315594
0.0258828729295024,123.503550018336,0.08217812155117012,24.898315683696538,126.70017670980303,0.025553581293843455
0.026309681270109,123.301519710681,0.08353323803259607,24.85758637367329,126.54554339438907,0.02596953480257911
0.0267325037391911,123.125243656372,0.08487569937193173,24.822049121124596,126.41668969280478,0.026381433280016582
0.0271657472910705,123.012247817729,0.08625124764914884,24.79926916005417,126.35396745565197,0.026803307691845687
0.0276025338540083,122.885359796726,0.08763804498647634,24.77368853501996,126.2773071006771,0.027228452048535266
0.0280379956243051,122.829672570746,0.08902063610716869,24.762461990262395,126.27357039281941,0.027652127073974825
0.0284801038297086,122.72457652726,0.0904243296593248,24.741274627895613,126.21978520921338,0.028082085081474757
0.028935640049553,122.597756598367,0.09187065715733077,24.71570773023079,126.14520115418007,0.02852490878265771
0.0293941762341348,122.441385444294,0.09332650954337798,24.68418330556967,126.0404491063952,0.02897045078330251
0.0298635556380796,122.298955344389,0.09481678915090272,24.655469397428824,125.95123700179516,0.029426323212293583
0.0303244862056555,122.15732699233,0.09628024370295621,24.62691712165373,125.86168516962866,0.02987378777951271
0.0307939468297498,122.045659684869,0.0977707811844556,24.60440499246959,125.80392724000659,0.030329327475522586
0.03126719517415,121.922973450643,0.09927334467792624,24.57967144764963,125.73516285773695,0.030788332636008848
0.0317250682562073,121.781900876585,0.10072709171345817,24.551231216719536,125.64543999426533,0.031232224838313477
0.0321984902108918,121.640056925575,0.10223020641958146,24.52263547619592,125.55668310774544,0.03169098404094511
0.0326531455869637,121.436565921734,0.10367373723860974,24.481611689821577,125.40185178835729,0.03213135987767565
0.0331170194615145,121.261430871622,0.10514653679030853,24.446304463718995,125.2772480377286,0.032580464904165087
0.0335694642115317,121.117446851584,0.10658304887161314,24.41727728527934,125.18329464906034,0.033018310470795176
0.0340385424020632,120.983421889132,0.10807237212655066,24.390257852849015,125.10152122505194,0.03347205044189129
0.0345126377694533,120.874962745981,0.10957762491801422,24.36839248958977,125.0466765506292,0.03393043443570865
0.0349655526524173,120.71827129,0.11101562967142492,24.336803492064,124.93925236089929,0.03436814370202643
0.0354178683281808,120.515639288304,0.11245173194197404,24.295952880522087,124.78404633210367,0.034805082752422584
0.0358853756212242,120.330682631584,0.11393606759738684,24.258665618527335,124.64879437657672,0.035256496423837484
0.0363419165104742,120.164187710208,0.11538558492075558,24.225100242377934,124.53118458752132,0.03569712462941119
0.0367996471317583,120.044123491397,0.11683887964333259,24.200895295865635,124.46170487612162,0.03613870627221787
0.0372656312280519,119.949392102391,0.11831837914906476,24.18179744784203,124.41938191450771,0.03658804999249151
0.0377280167734833,119.823475684175,0.11978645325580947,24.156412697929678,124.34417778464461,0.03703372417904154
0.0382033313084986,119.680882094393,0.12129557690448306,24.12766583022963,124.25309048433846,0.03749165314067181
0.0386724026592128,119.563228452013,0.12278487844300062,24.103946855925823,124.18702576594471,0.037943361782665476
0.0391505481380633,119.417139753953,0.12430299033835096,24.074495374396925,124.09238623239997,0.03840359876975528
0.0396228114860019,119.323088206961,0.12580242646805603,24.055534582523336,124.051004436913,0.03885796610506583
0.0401114700552802,119.216340061838,0.12735391742551463,24.034014156466544,123.99828271632852,0.039327890155083034
0.0405751018322337,119.098926978217,0.12882594831734198,24.010343678808546,123.93137806846792,0.03977354284577761
0.0410533129080949,118.972429212271,0.1303442684832013,23.984841729193832,123.85664157615854,0.04023300148968115
0.0415409820973535,118.834505999965,0.13189261815909734,23.957036409592945,123.77100808625741,0.04070133005405066
0.0420183554491095,118.66514354686,0.13340827855092266,23.922892939046974,123.65125772783158,0.0411595587701775
0.0425152759032498,118.521502489609,0.1349860009928181,23.893934901905176,123.56047686842246,0.04163632772806739
0.0430044208652582,118.383405246756,0.13653903624719477,23.86609449774601,123.47441502944991,0.04210541461488575
0.0434946078977056,118.237900226633,0.13809538007521527,23.836760685689214,123.38061133563845,0.042575280198054885
0.0439853279314936,118.127657911571,0.1396534161824922,23.814535834972716,123.32354168259076,0.043045435656226906
0.0444714006328457,118.000070812611,0.14119669700928508,23.78881427582238,123.24769923642279,0.043510920723243716
0.0449640448623825,117.832411788269,0.14276084243806442,23.75501421651503,123.13063363815945,0.043982477994589764
0.0454385415636466,117.666312861456,0.14426736946457794,23.721528672869532,123.01289850905233,0.0444364543841088
0.0459266491198949,117.498699893904,0.1458171109556663,23.68773789861105,122.89502145597515,0.044903238059466166
0.0464106667858885,117.359357897874,0.14735386704519599,23.6596465522114,122.80608395147807,0.045365895462694594
0.0469028479098143,117.295141439151,0.1489165421136604,23.646700514132842,122.79661761863166,0.045836136665973574
0.0473997412330699,117.199880029542,0.15049417841499693,23.627495813955665,122.75512401548914,0.04631065580676566
0.0478962584047795,117.122763634696,0.1520706204351749,23.611949148754714,122.73250578682531,0.04678459092723463
0.0484018762906587,116.992927275363,0.15367595722284136,23.585774138713184,122.65560446822714,0.04726698213611427
0.0489040973572981,116.860484742901,0.15527050910942147,23.55907372416884,122.57544126598887,0.04774590231519068
0.049413575281349,116.708879536099,0.15688810151828306,23.52851011447756,122.47588254105791,0.048231508418314244
0.0499195266732851,116.587168642375,0.1584944971876802,23.503973198302802,122.40714491718083,0.04871351996880223
0.0504360021531989,116.449614588146,0.1601343068364065,23.476242300970235,122.32286760025292,0.049205318127004724
0.0509448513617096,116.299342854442,0.16174990307342796,23.44594751945551,122.22419558962606,0.04968961797927128
0.0514436821066765,116.127799858634,0.16333369068869788,23.411364451500617,122.10184147830934,0.05016415515105159
0.0519649318359299,115.997459548873,0.16498865857907744,23.385087845052794,122.02525962747121,0.050659779003182116
0.0524711559122656,115.841172641975,0.16659592002144327,23.35358040462216,121.91949287273177,0.051140880889855876
0.0529811585461304,115.739174320337,0.168215178383964,23.33301754297994,121.871169865001,0.05162533987317007
0.0534990442704297,115.63442228745,0.16985946555861428,23.31189953314992,121.82075336459185,0.052117047067039006
0.054016223711515,115.5357591499,0.17150151028406013,23.292009044619842,121.77656456282071,0.05260784251637585
0.0545320390197792,115.407015220098,0.17313922388779893,23.266054268371757,121.70039507723664,0.053097103613853044
0.0550435237365198,115.207866691281,0.17476318786345035,23.225905924962248,121.54931363613635,0.053582020803636124
0.0555448320308104,115.067846073079,0.176354841697823,23.197677768332724,121.4592702553553,0.05405706208996543
0.0560496402467291,114.902733183829,0.1779576077833649,23.16439100985993,121.34299004214853,0.05453519198863994
0.0565638373046622,114.811818284101,0.17959018344230246,23.14606256607476,121.30601529417532,0.055021979632049973
0.0570830478462441,114.701730012971,0.18123867691182502,23.123868770614955,121.2492543553484,0.05551327319264703
0.0576218833682554,114.599783644018,0.18294947969421088,23.10331638263403,121.20323901118091,0.056022881437011555
0.058158226685218,114.489712904183,0.18465236972556714,23.081126121483294,121.14823158039,0.0565298748867588
0.0587041534098568,114.383329616417,0.18638568707629535,23.05967925066967,121.09810614574937,0.057045663482064086
0.0592318523527392,114.242164271941,0.18806113121994694,23.031220317223305,121.00893927855397,0.057543977833740545
0.059772545515831,114.119901181543,0.1897778320127634,23.00657207819907,120.9411381691789,0.058054305396411245
0.0603110318527421,113.990575591232,0.19148752613245615,22.98050003919237,120.86546482662719,0.05856229135907708
0.0608589832621275,113.849166888619,0.1932272718572548,22.95199204474559,120.77791143070063,0.05907894152636177
0.061400636429263,113.679853291681,0.19494702066291003,22.91785842360289,120.65986863297546,0.05958939102450111
0.0619426480101244,113.522445085699,0.19666790743214496,22.88612492927692,120.55432594289114,0.060099917604546686
0.0624898875864923,113.392398241361,0.19840539308711305,22.859907485458375,120.47827646062642,0.06061510420548824
0.0630312764949403,113.277164918495,0.20012430287143543,22.836676447568593,120.41716922103562,0.06112452178203804
0.0635852682772272,113.151224166029,0.20188322678019635,22.811286791871446,120.34597511052262,0.06164552947962258
0.0641297451159855,113.009507563217,0.20361194074325395,22.782716724744546,120.25677847892914,0.0621573243837482
0.0646765173166963,112.874369371393,0.20534794248051072,22.75547286527283,120.17469047665308,0.06267101341443472
0.065223187671468,112.711875838932,0.20708362085691087,22.72271416912869,120.06330366957786,0.0631843430942273
0.0657627967201249,112.521735064308,0.20879687958639656,22.684381788964494,119.92147905393783,0.06369078383493852
0.066298015093811,112.370839163353,0.21049619792284993,22.653961175331965,119.82080275430918,0.06419285055082509
0.0668320055373456,112.195113898211,0.21219161758107227,22.61853496187934,119.69333837151937,0.06469351431676937
0.0673785884854065,112.119144544207,0.2139270184411656,22.603219540112132,119.67357424578694,0.06520572521249053
0.0679331567524539,112.052702236661,0.21568777268904113,22.58982477091086,119.66479602224014,0.06572515126889926
0.0684978464066655,111.98083711349,0.21748066234116292,22.575336762079584,119.65128329457966,0.06625378024547438
0.0690599503653824,111.857933575664,0.2192653424100891,22.550559408853864,119.5828369163736,0.06677971126125548
0.0696188492133581,111.699484267277,0.22103984625241196,22.518616028283045,119.47587381969042,0.0673023693254853
0.0701799302680858,111.547689672451,0.22282127860117243,22.488014237966123,119.37609875522969,0.06782679346570554
0.0707441314919231,111.442333365093,0.22461261748685582,22.466774406402752,119.32622445043987,0.06835385675298009
0.0713217315976149,111.356556041669,0.2264464978224273,22.44948169800047,119.29869844330767,0.06889314933930393
0.071894461906675,111.246338076495,0.22826491655369313,22.42726175622139,119.24433369159266,0.06942760808819652
0.0724712291989206,111.107014675211,0.23009615270657288,22.399174158522538,119.15907660134607,0.06996554553846124
0.0730491036245421,110.956994228606,0.23193090400792116,22.368930036486972,119.06230319787917,0.07050422553207829
0.0736192188796873,110.803520382878,0.23374101994300714,22.337989709188204,118.960789002585,0.07103538841604366
0.0742034893432507,110.646568944526,0.23559607866482096,22.30634829921644,118.85693044406837,0.07157944680199735
0.0747867032819716,110.50341352446,0.2374477829202598,22.277488166531136,118.7675995233588,0.07212222634100202
0.0753809947258114,110.380927234568,0.2393346582544512,22.252794930488907,118.70155132826716,0.07267501248835585
0.0759703697170142,110.2747171954,0.24120592385152007,22.23138298659264,118.65232823117373,0.07322292392271133
0.0765547336651247,110.091367193446,0.2430612793867709,22.194419626198716,118.5193824877697,0.07376588062184414
0.0771287062767063,109.918299147058,0.2448836424285425,22.15952910804689,118.39615535640657,0.07429889546936155
0.0776865539944409,109.755207658272,0.24665480893234984,22.126649863907637,118.28171152418741,0.07481666396718341
0.078261573432184,109.616553871109,0.2484804956471842,22.098697260415573,118.19531785127576,0.07535009002142189
0.078826819677921,109.514193194349,0.2502751524773992,22.07806134798076,118.14684875345294,0.0758741726324822
0.0794073092884642,109.382321171805,0.25211820699087384,22.05147594823589,118.06807697978465,0.07641210280117915
0.0799895000113273,109.253075168253,0.25396666253596417,22.025419953919805,117.99217402566153,0.07695131887713336
0.0805955411942284,109.123638994728,0.25589084329167516,21.999325621337167,117.9185177365917,0.07751231618780358
0.0813436938548223,108.960824081268,0.2582662279890608,21.966502134783628,117.82409999750381,0.07820442878590991
0.0820937856150082,108.826160360398,0.26064776932765105,21.93935392865624,117.76011183832901,0.07889785468553506
0.082860048237948,108.648525544763,0.2630806531554849,21.903542749824222,117.651147612384,0.07960573366471269
0.0835522403300432,108.53462075308,0.26527836304788716,21.880579543820932,117.60293147037144,0.08024475525751157
0.0841601957288493,108.394560427512,0.2672086214390965,21.85234338218642,117.517067849034,0.08080567413644876
0.0847703446139009,108.2818594618,0.26914584414913534,21.82962286749888,117.46095000381078,0.0813683006381258
0.0853716891203643,108.129111546152,0.2710551129571566,21.798828887704243,117.36027644193128,0.08192249894635326
0.0859753197862473,107.963724114644,0.27297164032133514,21.765486781512234,117.2459398207147,0.0824784954581566
0.0865782579968454,107.814106793976,0.27488596913998414,21.73532392966556,117.1484643476843,0.08303354572917712
0.0871749163245208,107.672907794419,0.27678035933035355,21.70685821135487,117.05928452181533,0.08358251177528385
0.0877680439889338,107.55069140201,0.2786635396648648,21.682219386645215,116.99020521602188,0.08412793084138326
0.0883680335864109,107.416372958496,0.2805685066368546,21.655140788432796,116.90854661182283,0.08467935739863137
0.0889834339107439,107.286007063368,0.2825224026666119,21.628859023974993,116.8326843824388,0.08524463163194296
0.0896018725636458,107.114766525394,0.2844859453895754,21.594336931519432,116.71245018528703,0.08581237499060422
0.090223145487011,106.956963560328,0.2864584869212599,21.562523853762126,116.60695724448041,0.086382395918929
0.0908405184434677,106.788996166618,0.28841864605800993,21.52866162719019,116.48976394245108,0.08694851692048912
0.0914499598821107,106.662065498121,0.29035362262570147,21.503072404421193,116.41630710886723,0.08750705068172708
0.0920740479798733,106.54304810558,0.2923351023360977,21.479078498084927,116.35289782877513,0.08807868452913128
0.0926867271522426,106.456065877096,0.29428035870837027,21.461542880822552,116.32313020874757,0.08863955068473421
0.0933032116390628,106.265013678472,0.29623769695402435,21.423026757579954,116.17988073954238,0.08920358301829992
0.0939186582172281,106.059208277915,0.2981917398396992,21.381536388827666,116.02014681095831,0.08976634860042032
0.0945298798651385,105.881075720527,0.30013236857181474,21.34562486525824,115.89000108838006,0.09032493762197351
0.0951436948121383,105.706106021329,0.30208123102853907,21.310350973899926,115.76337551240186,0.09088558279774417
0.0957572876937483,105.666572483404,0.30402938842765087,21.302381012654248,115.78491686430962,0.0914457111673529
0.0963852936975865,105.538958532319,0.30602330748983714,21.27665404011551,115.71136204699395,0.09201867209275032
0.0970158391421573,105.396185156846,0.3080252892763494,21.247870927620156,115.62128450221961,0.09259361978699564
0.0976321635678446,105.21864309599,0.3099821193279066,21.212078448151583,115.49136686912436,0.09315528110227574
0.0982535653894302,105.02764410117,0.31195507011144086,21.173573050795873,115.34698459856209,0.09372125029637215
0.0988802016379474,104.865516020346,0.313944640200483,21.140888029701756,115.23463938930522,0.09429166278095727
0.0995099205487392,104.697778816753,0.3159439977422469,21.107072209457407,115.11624646843757,0.09486455375391038
0.100128634493783,104.556300770912,0.317908414517761,21.07855023541586,115.0253803948247,0.09542711341621728
0.10075775756878,104.444705136887,0.31990588028087646,21.05605255559642,114.96831941641216,0.09599881315901274
0.101372953236533,104.256443213442,0.32185912652599225,21.018098951829906,114.82522675592551,0.09655754083193303
0.10198144333252,103.959666909976,0.323791082580751,20.958268849051162,114.56162378982336,0.09710987150774592
0.102590660818138,103.740248201314,0.32572534809758813,20.914034037384905,114.38302881772445,0.09766255699258783
0.103197255304285,103.533217111494,0.32765128559110485,20.872296569677193,114.21756095022282,0.09821255955358182
0.103825520216516,103.476458537326,0.3296460266874383,20.86085404112492,114.21995567512661,0.09878189208260667
0.104464804459952,103.399826403434,0.3316757541603476,20.845405002932292,114.20146904986173,0.09936087778403474
0.105107055528201,103.275867187676,0.3337149013020382,20.82041482503548,114.13088949489418,0.0999422131078289
0.105767807211679,103.133514954242,0.3358127878970808,20.791716614775186,114.04172068098508,0.10053994182987146
0.106433469574153,102.963318177299,0.3379262658979358,20.757404944543477,113.92206136977637,0.10114175179133354
0.10707191870782,102.759605053054,0.33995334189732845,20.716336378695686,113.76227313174229,0.10171861883195785
0.107718491648649,102.536174258417,0.34200621098446055,20.67129273049687,113.58121628895672,0.10230248713495746
0.108330316038234,102.327158363342,0.3439487534213929,20.629155126049746,113.41229176813725,0.10285466306448397
0.108934593467945,102.105091459616,0.34586733426072536,20.58438643825859,113.22786808877663,0.1033997286920335
0.10956079431724,101.921503651363,0.34785552195723696,20.54737513611478,113.08810454941381,0.10396425622666186
0.110177522315947,101.716970153248,0.3498136333531317,20.506141182894797,112.92389390221798,0.10451993255116798
0.110816194542209,101.544721073221,0.35184141767151356,20.471415768361354,112.79752063840542,0.10509505551438814
0.111442644108917,101.359486136526,0.35383039504581143,20.434072405123644,112.65525527710156,0.1056588508494824
0.112048231998323,101.132659822623,0.3557531365946755,20.388344220240796,112.46439555303573,0.10620356898697285
0.11266932882154,100.937401317557,0.3577251190083895,20.348980105619493,112.30995057699657,0.10676192915843165
0.113282997252869,100.738862396103,0.35967351627785904,20.308954659054365,112.1508626681779,0.10731330525008269
0.11391283989785,100.531368157949,0.36167326667567373,20.26712382064252,111.98318180363727,0.10787889777792878
0.114540331822143,100.343962922081,0.363665553535304,20.22934292509153,111.83739373152497,0.10844206145472522
0.115165660285967,100.07969938142,0.3656509714079452,20.17606739529427,111.60544404190232,0.10900296812352568
0.115786908622647,99.8661311518755,0.3676234348769042,20.1330120402181,111.42932175405501,0.10955990363295437
0.116398550758127,99.6334844638876,0.3695653986570532,20.086110467919738,111.23067766246646,0.11010792454064115
0.117033724579341,99.4557533277871,0.37158207553940764,20.050279870881877,111.0954305705822,0.11067671173455083
0.117653051901852,99.2864665673356,0.3735484397883801,20.016151659974856,110.96782237153381,0.11123099732382047
0.118266107311863,99.0829083940843,0.375494890715165,19.975114332247394,110.80105827099055,0.11177936726183668
0.118896501255355,98.8553117823193,0.3774963914857521,19.929230855315573,110.60886248374433,0.11234293287639023
0.119512754796357,98.6155417744326,0.3794529964784335,19.88089322172561,110.40135683763027,0.11289355028909587
0.120142951856565,98.3706079949529,0.38145387214459386,19.831514571782506,110.18914321539157,0.1134563127484936
0.120777163968252,98.1691477124067,0.38346749559920007,19.790900178821193,110.0257389622916,0.1140223410724317
0.121417301690607,97.9170037541445,0.3854999328676772,19.74006795683553,109.80582213960177,0.11459333324064139
0.1220546140369,97.6527776062804,0.3875233995671575,19.68679996542613,109.57174968664619,0.11516148152809583
0.122660475928256,97.3901314330866,0.3894470110722128,19.63385049691026,109.33605130538439,0.11570129338108016
0.12327648816612,97.0884907037054,0.39140284992743096,19.57303972586701,109.05721887900718,0.1162498504093133
0.123865219150559,96.8140750109971,0.3932720708030248,19.517717522217016,108.80597162909291,0.11677383249374716
0.124459523130966,96.4742652601606,0.39515898594081705,19.449211876448377,108.48140630885051,0.11730249633226862
0.125067553366692,96.2072861986365,0.3970894819392471,19.39538889764512,108.23969609954908,0.11784308129066788
0.125685463481512,95.9718675174353,0.39905134655380053,19.347928491514956,108.03413616755043,0.11839215098042812
0.126307853347563,95.7369718818536,0.4010274343785125,19.300573531381687,107.82930328624653,0.11894489674325633
0.12692044562436,95.4612273451839,0.402972414857343,19.244983432789073,107.57720885968298,0.11948864305797265
0.127530413438626,95.1681760429728,0.40490906266763754,19.18590429026332,107.30501287993306,0.12002976625584388
0.128143068392564,94.8712280548059,0.4068542421463907,19.12603957584887,107.02831831991942,0.12057297871450687
0.128753089735256,94.596425985507,0.4087910599094378,19.07063947867821,106.77600810905348,0.12111356305229377
0.129368003173044,94.302859723028,0.41074341007441467,19.011456520162447,106.50263237890381,0.12165818703629402
0.129961229154883,94.0094634406009,0.41262690256675355,18.95230782962514,106.22704886153242,0.12218332165322676
0.130547340466861,93.6697281469387,0.4144878059822837,18.883817194422843,105.89806203877541,0.12270188754852014
0.131145167609305,93.2707905011268,0.4163859071595434,18.803391365027164,105.50280395444943,0.12323054222127737
0.131732385749148,92.90263721391,0.4182503247535449,18.72917166232426,105.14092325648593,0.12374954348332326
0.132329983232237,92.5237651588332,0.4201476967623524,18.652791056020774,104.76743345088502,0.12427744192389127
0.132931643453119,92.2136020465806,0.4220579679636528,18.59026217259065,104.47170771536446,0.12480864788080359
0.133537166579599,91.9408371887521,0.4239805038902268,18.535272777252423,104.21835607989428,0.12534297964677066
0.134138450986352,91.6159193263065,0.42588958188166753,18.46976933618339,103.90513683042784,0.12587328866997194
0.134738173189144,91.2071287333742,0.4277936998755322,18.38735715264824,103.49621064073612,0.12640193990677254
0.135366552788391,90.7772841975744,0.4297888051031414,18.300700494231002,103.06549223089212,0.12695555279353096
0.136007053143543,90.3658830995158,0.431822393730749,18.217762032862385,102.65628056459485,0.1275195290328043
0.136649599375121,90.0001315370689,0.43386247801600913,18.14402651787309,102.29861345531755,0.12808498730208268
0.137246906141946,89.6040891978118,0.4357589270006786,18.06418438227886,101.90197321787845,0.12861034699115753
0.137819767888466,89.1677796336147,0.43757776304587953,17.976224374136724,101.45686232584937,0.12911394696487802
0.13838182549232,88.6381619838012,0.439362295938116,17.869453455934323,100.90407264740357,0.12960780270850975
0.138962564142522,88.1428867790256,0.44120614115250734,17.76960597465156,100.391448336763,0.13011781662246455
0.139570397718712,87.6806375926751,0.44313601275691056,17.6764165386833,99.918259053715,0.13065134727642702
0.140164695210922,87.3139400284484,0.44502290729467736,17.6024903097352,99.5522718202006,0.13117272145495829
0.140763504263631,86.9412177981671,0.44692412603702836,17.527349508110486,99.17936828038468,0.13169777881240055
0.141337730231962,86.4607449642725,0.44874729348647935,17.430486184797335,98.68091041168731,0.13220102202682937
0.141933725168548,85.9347790940191,0.4506395774101398,17.324451465354255,98.1318224123695,0.13272307554675777
0.142511883132069,85.3921941822822,0.4524752289443191,17.215066347148092,97.56159657997854,0.13322924472300288
0.143107454167095,84.867172624799,0.4543661669805266,17.109222001159477,97.01229764149335,0.1337503910388273
0.143713896909681,84.3518405089211,0.45629162268823714,17.005331046598496,96.47437221996204,0.13428077156594342
0.144325386341701,83.8299602278388,0.45823310163490066,16.9001199819323,95.92875162473106,0.13481528113582264
0.144926028102171,83.2942274873999,0.4601401392243929,16.792116261459817,95.36572904098743,0.13534003064167677
0.145520795590893,82.7257566108431,0.4620285260010853,16.677512532745972,94.76407452871157,0.13585937690716354
0.146092550292483,82.1522147174718,0.4638438471786335,16.561886487042315,94.15404127772291,0.1363583744492061
0.14665603085017,81.5578156977715,0.46563289794928975,16.442055644670738,93.51876123281637,0.136849907252817
0.147207629978011,80.8989324956834,0.46738422518018496,16.309224791129772,92.80787261612404,0.13733084179822386
0.147754764930632,80.2559912611648,0.46912137865475656,16.179607838250824,92.11419638423307,0.137807655679097
0.148301184260632,79.6356777355097,0.4708562600275065,16.054552631478757,91.44574305308385,0.13828361911588347
0.148881490508066,78.8745895896053,0.47269873236310955,15.901117261264432,90.61755605091773,0.13878885212686845
0.149504169350684,78.3143426885805,0.4746757376884217,15.788171486017827,90.02266344048154,0.1393306923138549
0.149814191368604,77.9907406271888,0.47566005759531765,15.722933310441263,89.67486036848962,0.13960035659792705