File: example/data/02 processed data/test_ID_068.csv
Strain,Stress_MPa,Displacement(mm),Force(kN),True Stress (MPa),True Strain
2.14676273530575e-05,0.111361694723748,6.815971684595756e-05,0.022450517656307598,0.11136408539511175,2.146739692689685e-05
3.22689821281306e-05,-0.144595241076134,0.00010245401825681466,-0.029150400600948614,-0.1445999070173841,3.2268461495754904e-05
3.79306980267177e-05,-0.370359079153221,0.0001204299662348287,-0.07466439035728936,-0.37037312713161386,3.7929978675975203e-05
4.28581012686534e-05,-0.326718705476777,0.00013607447152797454,-0.06586649102411825,-0.32673270802014265,4.285718288640139e-05
4.4213980950058e-05,0.108191450247598,0.00014037938951643413,0.021811396369915758,0.1081962338223182,4.421300354075733e-05
4.83494478324846e-05,0.632652783424416,0.0001535094968681386,0.12754280113836228,0.6326833718371643,4.834827903561718e-05
5.44249583616297e-05,1.02135778586226,0.0001727992427981743,0.20590572962983164,1.021413373217228,5.442347737729808e-05
5.75775281770876e-05,1.19056646091463,0.0001828086519622531,0.24001819852038941,1.19063501078858,5.757587065478122e-05
5.79000240079827e-05,1.18979984186226,0.00018383257622534507,0.23986364811943162,1.1898687313016685,5.789834786627063e-05
5.55153547340809e-05,1.19133369566186,0.00017626125128070687,0.240172873045431,1.1913998329745814,5.5513813813860866e-05
5.87422421152538e-05,1.19382471818355,0.0001865066187159308,0.24067506318580367,1.1938948461241887,5.874051685727627e-05
6.2232833953661e-05,1.2015033804751,0.00019758924780287365,0.2422230815037802,1.201578153435472,6.223089757120564e-05
8.02050220154402e-05,1.27167627221106,0.0002546509448990226,0.2563699364777497,1.271778267034469,8.020180576463846e-05
9.71699591388426e-05,2.00337500581081,0.0003085146202658252,0.40388040117145935,2.0035696736782644,9.716523844410094e-05
0.0001216406604182,3.79387150426119,0.000386209096827785,0.764844495259056,3.7943329932965106,0.00012163326279307133
0.0001554183660972,7.36869825385877,0.0004934533123586099,1.4855295679779281,7.369843484901648,0.00015540628991419041
0.0002013258785357,12.0806467181727,0.0006392096643508475,2.435458378383616,12.083078864986515,0.00020130561520056704
0.0002613360751166,17.2290347874242,0.0008297420384952049,3.473373413144719,17.233537355753594,0.00026130193279289726
0.0003404030008591,22.735354245323,0.0010807795277276424,4.583447415857116,22.7430934281337,0.0003403450769022579
0.0004176890031346,27.9106144593983,0.0013261625849523549,5.626779875014697,27.92227241612872,0.0004176017953659605
0.0005017671954384,34.0950330495443,0.00159311084551692,6.873558662788131,34.112140818655945,0.0005016413523733531
0.0005894753054315,40.4457019008771,0.0018715840947450123,8.153853503216823,40.469543643358506,0.000589301633110563
0.0006824260647774,46.8713138583788,0.002166702755668245,9.449256873849166,46.90330006464611,0.00068219331799266
0.0007868282933036,53.2033200508823,0.00249817983123893,10.725789322257873,53.24518192839602,0.0007865189062011519
0.0008923623157193,59.2464305106826,0.0028332503524087773,11.944080390953612,59.299299792611215,0.000891964397175475
0.0009976071488945,65.4009828476236,0.0031674026977400373,13.184838142080917,65.46622733565711,0.0009971098695814309
0.0011045943142608,71.6176005588493,0.00350708694777804,14.438108272664019,71.69670895322761,0.0011039846988385486
0.0012135711385651,77.9060459128244,0.0038530883649441922,15.705858856025397,78.00059044166392,0.001212835356333396
0.0013184714101299,84.1827178862861,0.004186146727162432,16.971235925875277,84.2937103930462,0.0013176029899412925
0.0014208459494763,90.4573363436882,0.004511185889587253,18.236199006887542,90.58586228363254,0.0014198375029885397
0.0015259617143865,96.7458618642931,0.004844928443177137,19.50396575184149,96.89349234552334,0.0015247986178864952
0.0016322373625061,103.037117975874,0.005182353625956867,20.772282983936197,103.20529900955917,0.0016309067108651622
0.0017386894983118,109.33060047169,0.005520339157139965,22.041049055092703,109.52069243857426,0.0017371797274878178
0.0018473341780146,115.502953368341,0.0058652860151963545,23.285395399057542,115.71632592175995,0.0018456299547556895
0.0019489341963366,121.557663835293,0.0061878660733687045,24.506025029195072,121.79457172316839,0.0019470374880590018
0.002056187845509,127.679436150935,0.006528396409491075,25.7401743280285,127.94196905567,0.002054076784610836
0.0021581756582342,133.695764341576,0.006852207714893584,26.95306609126172,133.984303285787,0.0021558501424616787
0.0022566211585448,139.730487000675,0.00716477217837974,28.169666179336083,140.0458057741345,0.0022540788130403157
0.0023555143039444,145.680260675201,0.007478757915023469,29.36914055212052,146.0234126130238,0.002352744428927132
0.0024484843444389,151.432939369886,0.007773937793593508,30.528880576969016,151.80372055116553,0.002445491690628427
0.0025503086313897,157.142626728013,0.008097229904662297,31.679953548367422,157.5433889253167,0.002547062112909843
0.0026440784174611,162.717326726724,0.008394948975438993,32.80381306810756,163.14756409846908,0.002640588991645834
0.0027427834715985,168.270874906955,0.008708337522325237,33.923408381242126,168.7324054814012,0.0027390289047548463
0.0028388399564973,173.713321910329,0.009013316861878926,35.02060569712233,174.20646622954393,0.0028348180602299697
0.0029354443939829,179.013564063243,0.009320035950895707,36.08913451514979,179.53904842631934,0.0029311443899809496
0.0030303035367454,184.292195610274,0.009621213729166645,37.15330663503124,184.85065690242638,0.003025721421449296
0.0031242128803942,189.457669938461,0.009919375895251586,38.194666259593745,190.0495760311722,0.0031193426684158875
0.003222819225364,194.566402726996,0.0102324510405307,39.22458678976239,195.19345507031449,0.003217637074589323
0.0033218685230794,199.56259634383,0.010546932560777095,40.23181942291613,200.22551705100855,0.0033163633062058342
0.0034206796144705,204.535410937023,0.010860657775943836,41.23433884490383,205.2350610476526,0.003414842397669417
0.0035210351649908,209.333500402757,0.01117928664884579,42.201633681195815,210.07057101888574,0.0035148508332557187
0.003623632364905,213.856065544452,0.011505032758573374,43.113382813761525,214.63100130499015,0.0036170828264581343
0.0037305163093323,218.090800973861,0.011844389282130052,43.96710547633038,218.90439226380937,0.0037235751906470587
0.0038482621524954,222.069820609367,0.012218232334172893,44.769275834848386,222.92440349522948,0.003840876533499624
0.0039736131978039,225.744038745537,0.012616221903027382,45.50999821110027,226.6410582372218,0.0039657392486740165
0.004115690981547,229.244781235953,0.013067318866411723,46.21574789716813,230.18828191465252,0.004107244692365655
0.0042834680954464,232.477653799928,0.01360001120304232,46.86749500606548,233.47346441288423,0.0042743201599404045
0.0044886690479861,235.56367626928,0.014251524227355867,47.48963713588685,236.62104365177976,0.004478625018076581
0.004733406143445,238.446070462622,0.015028564505437873,48.070727805264596,239.57473255743008,0.004722238802427289
0.0050228392464866,240.988437958395,0.015947514607594953,48.58326909241243,242.19888414252193,0.005010266871210757
0.0053288036157239,242.991015955086,0.01691895147992338,48.986988816545335,244.2858673594959,0.0053146557801720855
0.0056607185479341,244.487567975512,0.017972781389690766,49.28869370386322,245.87154328629026,0.00564475688867208
0.006009089844197,245.595665518165,0.019078860255325476,49.51208616846207,247.07147193760898,0.005991107267140817
0.0063604442791959,246.319195354271,0.02019441058644698,49.65794978342104,247.88589487121817,0.00634030201751971
0.0067228164613194,246.859326974471,0.021344942264689092,49.766840318053355,248.5189169214852,0.0067003191048449805
0.007099773513291,247.20862662095,0.022541780904698924,49.83725912678352,248.96375188049046,0.007074688781946462
0.007478090744716,247.43179473154,0.0237429381144733,49.88224981787847,249.28211214567042,0.00745026844315909
0.0078639625091893,247.675020334015,0.024968080966676028,49.93128409933742,249.62272740838435,0.007833202713364415
0.0082364945244685,247.912260687691,0.026150870115187488,49.97911175463851,249.95418866539376,0.008202759714573689
0.0086116919468251,248.109382931765,0.027342121931169694,50.01885159904383,250.24602450669022,0.008574822846743687
0.0089822714928995,248.343714679713,0.028518711989955915,50.066092879430144,250.57440534852137,0.008942170843374252
0.0093546989377685,248.58374779376,0.029701169127414984,50.11448355522202,250.90917391519278,0.009311214719151101
0.0097266496140216,248.843563278806,0.030882112524518578,50.16686235700729,251.26397742752354,0.009679650275972514
0.0101066203689012,249.119151161501,0.032088519671261306,50.22242087415861,251.63690384891325,0.010055890003289419
0.0104880802389693,249.326698587973,0.03329965475872752,50.26426243533536,251.94165700848097,0.010433461887928127
0.0108670426955584,249.445622768102,0.034502860558397914,50.28823755004936,252.15635900094313,0.010808420703159871
0.0112471868544402,249.565739454478,0.03570981826284764,50.31245307402277,252.37265195858905,0.011184407536944881
0.011621867186145,249.693180604936,0.03689942831601037,50.3381452099551,252.5950815872127,0.01155485201553453
0.0119985068982162,249.954106882468,0.03809525940183643,50.39074794750555,252.9531829581348,0.01192709546716588
0.0123749174729062,250.247858142812,0.03929036297647718,50.4499682015909,253.34465473510082,0.012298974068708798
0.0127499684143036,250.472862634403,0.04048114971541393,50.49532910709564,253.6663837216318,0.01266937191261356
0.0131254938381556,250.584110993909,0.04167344293614403,50.51775677637205,253.87315119869925,0.013040100948183682
0.0134973436065917,250.745319724455,0.042854065950928645,50.55025645645013,254.12971546252066,0.013407065896706519
0.0138702903148612,250.881870822553,0.04403817174968431,50.57778515782668,254.36167520559735,0.01377497816504538
0.014239673107904,251.111264050349,0.0452109621175952,50.62403083255036,254.68700636413854,0.014139241251158959
0.0146060470916896,251.387722051984,0.04637419951611448,50.67976476567998,255.05950295854785,0.01450040620729178
0.0149687796794587,251.660391604129,0.04752587548228137,50.73473494739241,255.42744056009747,0.01485785308419092
0.0153284096597824,251.974331704596,0.04866770066980912,50.79802527164656,255.83669748471394,0.015212116475750784
0.0156828418579825,252.227111154927,0.04979302289909444,50.84898560883328,256.18274905146546,0.015561136897506848
0.0160369891475933,252.398042686318,0.05091744054360872,50.88344540556171,256.4457473577523,0.015909755134916482
0.0163902659923302,252.594347587554,0.05203909452564839,50.92302047365089,256.7344361326732,0.01625739547225347
0.0167410106985735,252.629612537574,0.053152708967970856,50.930129887574914,256.858887583842,0.016602424554973197
0.0170951479752281,252.70965291845,0.054277094821349216,50.94626602835952,257.02976182985947,0.016950670187959285
0.0174504246459884,252.793314342958,0.05540509825101317,50.96313217154034,257.20466502590943,0.017299914440978007
0.0178119210435344,252.901596126694,0.056552849313221715,50.98496177914151,257.40625938868646,0.01765514766397069
0.0181791053926326,253.129834121463,0.057718659621608506,51.030974558886946,257.73150805397665,0.01801584115260735
0.0185436947120049,253.327550416367,0.058876230710615554,51.070834163939594,258.02517917342817,0.01837385680721483
0.0189036609319285,253.506970264595,0.06001912345887298,51.10700520534235,258.29918007435737,0.018727207015426687
0.0192609621860843,253.680192401933,0.06115355494081765,51.141926788229696,258.5663169951452,0.019077817808846674
0.0196139071420182,253.89805309642,0.06227415517590778,51.185847504238275,258.8779859333924,0.019424033228703085
0.0199680039903607,254.17798404339,0.06339841266939522,51.242281583147424,259.25341104303027,0.019771258167272453
0.0203231501796928,254.496749139347,0.06452600182052463,51.30654462649236,259.66892479234957,0.02011939102291228
0.0206783474693345,254.739310217609,0.06565375321513704,51.355444939869976,260.00689818838725,0.020467452789291858
0.0210352802864303,254.904519717654,0.0667870149094162,51.38875117507905,260.26650773619275,0.02081709322454169
0.0213909576534756,255.034733721015,0.06791629054978503,51.415002318156624,260.49017091020664,0.021165382297639052
0.0217395733318902,255.116488638455,0.06902314532875138,51.43148410951253,260.662612251385,0.021506638694634452
0.022083025019326,255.209205971538,0.07011360443636004,51.45017592386206,260.84499725216983,0.02184272626989253
0.0224263292572626,255.418244374187,0.07120359539180875,51.4923180658361,261.1463380208345,0.02217855671297174
0.022769643976572,255.68082819704,0.07229361962561609,51.54525496452327,261.5025896267217,0.0225142846598553
0.0231171939919396,255.898253295298,0.07339709092440823,51.58908786433208,261.81390285892394,0.022854039539999028
0.0234645619717838,256.169041883818,0.07449998426041357,51.643678843777714,262.17993624235334,0.023193501163916587
0.0238061814160205,256.266167087008,0.07558462599586507,51.66325928474082,262.3668859514695,0.02352723274144318
0.0241484793836937,256.434069131243,0.0766714220432275,51.69710833685859,262.6265619629355,0.023861515504057764
0.0244925054358761,256.543838418006,0.07776370475890662,51.71923782507,262.8272397749995,0.024197373331725378
0.0248398160176091,256.730206935424,0.07886641585590888,51.756809718181486,263.10733804186265,0.024536323321848883
0.0251903111332825,256.948336167599,0.07997923784817193,51.80078457138796,263.4209447008401,0.024878264754266407
0.0255373932143495,257.131343085732,0.08108122345555965,51.83767876608357,263.6978073018461,0.025216761263232617
0.0258787435089046,257.294565738421,0.08216501064077211,51.87058445286568,263.95302581140055,0.025549556049814296
0.0262197884463142,257.392896929997,0.08324782831704759,51.890408021087396,264.1416842350855,0.025881942565606674
0.026556600168063,257.536597145434,0.08431720553360002,51.919377984519485,264.37589358446877,0.026210094941714824
0.026891320421193,257.713217365926,0.08537994233728777,51.95498462097069,264.6434660708897,0.026536102972148194
0.0272302098006278,257.926459748956,0.08645591611699326,51.99797428538953,264.9498513610533,0.026866063373734584
0.0275674048298082,258.077198651332,0.08752651033464104,52.02836324810853,265.1917172638961,0.027194266044213
0.0279120767180964,258.287875481187,0.08862084357995606,52.0708356970073,265.497226476972,0.027529634890862038
0.0282585742298831,258.501878847294,0.08972097317987884,52.11397877561447,265.8067733792645,0.027866666756292825
0.0286040801812515,258.726900388897,0.09081795457547351,52.15934311840163,266.1275453926676,0.028202621083507684
0.02894722647333,258.957435241284,0.09190744405282274,52.20581894464285,266.4535347661661,0.028536169310616286
0.0292828634979355,259.159888692543,0.0929730916059452,52.24663356041667,266.7488323372669,0.028862310716493082
0.0296143805406837,259.348273484374,0.09402565821667073,52.2846119344498,267.0287119479095,0.029184344316346745
0.0299415412000271,259.455144505925,0.09506439331008604,52.306157132394475,267.2236314047081,0.02950204451437645
0.0302703565276224,259.566662634507,0.09610838197520111,52.328639187116615,267.4238380551386,0.029821249864806634
0.0306031414638927,259.692262115303,0.09716497414785931,52.35396004244508,267.6396611498959,0.0301442050966413
0.0309437382653402,259.914239756176,0.09824636899245513,52.39871073484508,267.956957962626,0.030474633483107152
0.0312836576788634,260.168275129326,0.0993256131303913,52.449924266072124,268.3072903873722,0.030804295883354735
0.0316251591295677,260.361979240695,0.10040988023637744,52.488975014924115,268.5959682654712,0.031135383182067593
0.0319657730780075,260.597132862363,0.1014913295226738,52.53638198505239,268.9273216762207,0.03146550088729374
0.0323047693952455,260.743594974493,0.10256764282990445,52.565908746857794,269.1668566814313,0.03179394264268424
0.0326452441460209,260.944714514915,0.10364865016361635,52.60645444620686,269.46331842886815,0.03212370825601946
0.0329890815654436,261.131224736876,0.10474033397028341,52.644054906954196,269.745704009005,0.032456620445092316
0.0333300340178884,261.249061157822,0.10582285800679567,52.667810729416914,269.95650125335357,0.03278662993197912
0.0336727483202365,261.410444950943,0.10691097591675087,52.700345702110106,270.21285307205716,0.03311823500616389
0.0340080326793335,261.481952227127,0.10797550375688386,52.714761568988806,270.3744390035231,0.033442544604740804
0.0343470132821543,261.737425626695,0.1090517671708399,52.76626500634172,270.727324461132,0.03377032257160169
0.0346862745609298,261.91036059763,0.11012892173095211,52.80112869648221,270.9950552756715,0.03409826440202971
0.0350258232122853,262.069736720279,0.11120698869900582,52.833258922808255,271.24894498793367,0.03442637636964792
0.0353673366989434,262.196626397575,0.1122912940191453,52.85883988175113,271.4698227647051,0.034756278434983225
0.0357083687406968,262.321240513981,0.11337407075171234,52.88396208761858,271.68830409877125,0.03508560685493423
0.0360493413675574,262.51548466869,0.11445665884199474,52.92312170920791,271.97899498978137,0.03541476950583267
0.0363873346480723,262.712647138162,0.11552978750762954,52.96286966305346,272.27206014585926,0.03574094910632254
0.0367217912113572,262.920335811352,0.1165916870960591,53.00473969956857,272.5752414882364,0.036063610911255595
0.0370531274391686,263.075764572087,0.1176436796193603,53.03607413773274,272.82354440293324,0.03638315979541946
0.0373845512956627,263.132988042954,0.11869595036372906,53.047610389459535,272.97009673202683,0.03670269107149637
0.0377210122021142,263.254802058011,0.11976421374171257,53.07216809489503,273.1850396587064,0.037026974245633025
0.0380595857359542,263.429175197447,0.12083918471165458,53.10732171980533,273.45518047622596,0.03735318746602723
0.0384049121394591,263.608885653655,0.12193559604278265,53.14355134777686,273.73276174636436,0.037685797445193125
0.0387488284649665,263.761387653555,0.12302753037626864,53.17429575095669,273.9818324194241,0.03801693935532428
0.0390900242636688,263.885630205998,0.12411082703714844,53.1993430495292,274.20092589358393,0.038345353468209775
0.0394306994105763,264.04347530073,0.12519247062857974,53.23116462062717,274.454894206637,0.038673158859878834
0.0397676705380112,264.277448635327,0.12626235395818555,53.278333644881926,274.7871471432829,0.03899729448373818
0.040107710496276,264.438904606832,0.12734198082567627,53.31088316873734,275.04494363675514,0.039324275575389235
0.0404493333980048,264.567995488022,0.12842663353866524,53.33690789038524,275.2695945439588,0.03965267119020931
0.0407903144485428,264.648883286062,0.1295092483741234,53.353214870470104,275.4439944537562,0.03998034230097432
0.0411334464622102,264.771604977447,0.13059869251751738,53.37795556345332,275.66257361550026,0.04030997206284816
0.0414744441799835,264.873517302998,0.1316813602714476,53.39850108828439,275.8589992111371,0.04063744390462195
0.0418184851947678,265.045170349845,0.13277369049338777,53.43310634252875,276.12895788206475,0.04096772968734689
0.0421625221814555,265.200847140891,0.1338660079261212,53.46449078360364,276.3823837410096,0.04129790255225814
0.0425066167274533,265.3222620278,0.13495850810966423,53.48896802480448,276.6002137290766,0.04162802165144798
0.0428472131966855,265.517811408279,0.13603990189947646,53.528390779909046,276.89450968120684,0.041954677461482105
0.0431828143693365,265.658946196837,0.13710543562264338,53.55684355328234,277.13084715600854,0.04227643809878026
0.0435220195868989,265.821413344556,0.138182412188404,53.58959693026249,277.39049810275486,0.04260154897697477
0.043858741486332,265.959295685479,0.1392515042191041,53.61739401019257,277.62393568083536,0.0429241752161673
0.0441986339917839,266.031886647788,0.14033066292391388,53.63202834819406,277.79013263587734,0.043249733807081095
0.0445368658998128,266.168125067612,0.14140454923190565,53.65949401363058,278.02241916055283,0.04357359665233159
0.0448728231844169,266.34891137957,0.14247121361052364,53.69594053412131,278.30073898526734,0.04389517770869827
0.045202370839588,266.564968593264,0.1435175274156919,53.73949766840202,278.61433715645984,0.04421052297363841
0.0455378822345864,266.710452839851,0.14458277609481182,53.76882729251396,278.8558820320053,0.044531472835664596
0.0458774441844835,266.840190232232,0.14566088528573512,53.79498235081797,279.0821361657882,0.044856192606617266
0.0462245163778375,266.970377160806,0.14676283949963403,53.82122803561849,279.3109537322731,0.04518798541889927
0.0465748614824124,267.172068697552,0.14787518520665935,53.86188904942648,279.61557078911005,0.04552279544565485
0.0469204114901243,267.381195255077,0.14897230648114462,53.90404896342352,279.92683096116644,0.0458529132303101
0.0472638644235277,267.505997426799,0.15006276954470044,53.92920908124268,280.1493646216598,0.046180919643530716
0.0476065203902138,267.536529925005,0.1511507022389288,53.935364432881016,280.27301319200683,0.04650805775405636
0.0479486131512335,267.631997582874,0.15223684675516636,53.9546107127074,280.4645807018671,0.04683455144404135
0.0482906644787527,267.757665484736,0.1533228597200398,53.97994536172278,280.68786107027347,0.04716089904586827
0.0486345157086614,267.878651342828,0.1544145873749999,54.00433611071412,280.9067998195758,0.04748885660605168
0.0489797476958005,268.015346339869,0.15551069893416658,54.03189382211759,281.14267038219833,0.04781802293208146
0.049331834875896,268.125024203837,0.15662857573096978,54.05400487949353,281.3521236239563,0.04815361387703384
0.0496869259408478,268.281745071304,0.15775598986219178,54.08559980637489,281.6118402699433,0.04849195393855966
0.0500368098542781,268.490956468426,0.15886687128733296,54.12777682403469,281.9253874048299,0.048825220559023934
0.0503857858825646,268.690082609867,0.1599748701771426,54.167920654149185,282.22824358101633,0.04915751181527498
0.0507236265681949,268.792913236428,0.16104751435401882,54.188651308463875,282.4270645916098,0.04947909496229225
0.0510635782531411,268.892646744119,0.16212686095372297,54.2087575836144,282.62326745283156,0.049802583169976385
0.0514046275275453,268.971227170367,0.1632096923999563,54.224599397545994,282.79759291868646,0.050127010694214734
0.0517430822621218,269.061303314528,0.1642842861822367,54.24275874820884,282.98336446548535,0.05044886610733947
0.0520893212656282,269.144114511778,0.16538359501836952,54.259453485574454,283.16364875933505,0.050778016857229685
0.0524386392541384,269.220603817218,0.1664926796318894,54.274873729551146,283.33816594057043,0.051109984878820666
0.052784645343106,269.428517818945,0.16759124896436153,54.31678919229931,283.65020657733675,0.051438696892044715
0.0531286125540183,269.599501494956,0.1686833448590081,54.35125950138313,283.92294895463795,0.051765364871061564
0.0534709727654491,269.687777631474,0.16977033853030088,54.36905597050515,284.108245444381,0.052090400741030156
0.0538127729788142,269.725657137667,0.17085555420773507,54.376692478953665,284.24034269177776,0.052414799595292653
0.054161025737112,269.831066325931,0.17196125671533058,54.397942971307685,284.4453936538821,0.05274521429179231
0.0545035776622415,270.03596165463,0.17304885907761677,54.43924986957341,284.7538876622712,0.053070113687922686
0.0548509732147789,270.195114501059,0.174151839956923,54.471335083413486,285.01557948932066,0.053399499333909715
0.0551979084526882,270.289427557383,0.17525335933728503,54.49034859556842,285.2088386354249,0.053728340285462924
0.0555503860548229,270.373796715255,0.1763724757240627,54.50735741779541,285.3931655018957,0.05406232383653672
0.0559060252345432,270.431857404853,0.17750163011967465,54.519062452818375,285.5506276491531,0.05439919006894556
0.0562610911308222,270.526482665839,0.17862896434036046,54.538138905433144,285.74659776040255,0.05473540011300175
0.0566141431727084,270.582305067767,0.17974990457334916,54.54939270166183,285.901090426875,0.05506959120904004
0.0569691498662401,270.664087375735,0.1808770508253123,54.56588001494818,286.08359033285234,0.05540551995908224
0.0573212129441093,270.812759437783,0.181994851097547,54.59585230265705,286.336075289498,0.055738551871175206
0.0576703854399817,270.990928051945,0.1831034737719419,54.63177109527211,286.619079323439,0.05606873994313853
0.0580228351099915,271.124204916281,0.184222501474223,54.65863971112224,286.85559995246587,0.05640191648295704
0.0583756656465063,271.237559110124,0.1853427384276575,54.681491916601,287.07123217151104,0.05673534191267402
0.058727119063949,271.258807387467,0.18645860302803807,54.68577556931336,287.1890556660556,0.057067355476880105
0.0590879373570253,271.297430968807,0.1876042011085553,54.6935620833115,287.32783657501375,0.05740810128041334
0.0594485087659013,271.382992001444,0.1887490153317366,54.71081118749111,287.51630618035836,0.05774849798495682
0.0598198050012811,271.577305382358,0.18992788087906748,54.74998476508338,287.82300683310405,0.05809889839132977
0.0601901827576058,271.75820130379,0.1911038302553984,54.78645338284406,288.11537710614334,0.05844830972640054
0.0605532169483085,271.850308783207,0.1922564638108795,54.80502225069454,288.3117195084212,0.05879067476150946
0.0609116988090308,271.885240231838,0.1933946437186728,54.81206443073854,288.4462320954607,0.059128631671823306
0.0612627314645019,271.896777769641,0.19450917239979354,54.81439039835963,288.5539170522059,0.0594594552400137
0.0616152427764786,272.005651125641,0.19562839581531954,54.83633926692923,288.7653453563215,0.059791562237678245
0.0619714108748422,272.121066823789,0.19675922952762398,54.85960707167587,288.98479326362644,0.06012700237720893
0.062328043999024,272.189866984338,0.1978915396969012,54.87347718404254,289.15492898982626,0.06046276777668126
0.062687023095963,272.265328821331,0.1990312983296825,54.88869029038034,289.3328317773838,0.060800628063803534
0.0630491745060689,272.36086535809,0.20018112905676874,54.907950456190946,289.53299308667613,0.0611413584084418
0.063409474861632,272.434952743108,0.20132508268568158,54.92288647301058,289.70991003050204,0.06148023201796936
0.0637715453334558,272.565232988922,0.20247465643372217,54.94915097056667,289.94713910079895,0.061820654832843006
0.0641271147368907,272.608750302559,0.20360358928962796,54.95792406099589,290.0903629114916,0.06215485252131056
0.0644810440680924,272.656087197745,0.20472731491619334,54.9674671790654,290.2372363717764,0.06248739783548613
0.064837897873742,272.68393373496,0.20586032574913085,54.97308104096795,290.3641867822776,0.06282257900723232
0.0652015288073593,272.715526601822,0.20701485396336577,54.979450162927314,290.49699586576486,0.06316401018695124
0.0655730992815369,272.884563055967,0.20819459021887965,55.01352791208296,290.77844960163475,0.06351277581710824
0.0659503675693545,272.971713528599,0.20939241703270053,55.03109744736557,290.97429837184666,0.06386676515630564
0.0663204605791421,273.130290495091,0.21056746233877613,55.063066563810345,291.2444171588403,0.06421390024685643
0.0666943901499257,273.269392101308,0.2117546887260141,55.09110944762369,291.49492755414565,0.06456451156537245
0.0670601933286262,273.326509577934,0.21291611381838818,55.102624330911496,291.65583815206884,0.06490738434475998
0.0674281509281197,273.357364463448,0.21408437919678003,55.108844675831115,291.7893460918024,0.06525215793336114
0.0678027598085674,273.419197152431,0.21527376239220147,55.121310145930096,291.95777330400864,0.06560304165503032
0.068178797237813,273.496594449939,0.21646768123005627,55.1369134411077,292.14326330817374,0.06595513967000616
0.068557015562005,273.545015204907,0.21766852440936585,55.146675065309246,292.2984450692187,0.06630915472968406
0.0689317955169636,273.636030520555,0.21885845076635943,55.16502375294389,292.49825342247146,0.0666598278717904
0.0693069362052679,273.719121527444,0.22004952245172557,55.181774899932705,292.6897552213085,0.06701071543788664
0.0696822987436236,273.908062970589,0.2212412985110049,55.219865494870746,292.9946064427929,0.06736168732318264
0.0700616081551004,274.038979718606,0.22244560589244378,55.24625831127098,293.2385913348745,0.06771622453132893
0.0704369393430831,274.122574442837,0.22363728241428882,55.26311100767594,293.4309295914369,0.0680669196460423
0.0708117759573788,274.155191005041,0.22482738866467766,55.26968650661627,293.56860696804233,0.06841702994891946
0.0711831911920236,274.166898443054,0.22600663203467491,55.27204672611968,293.68297319345,0.06876382370339915
0.0715518824446227,274.186549307942,0.22717722676167704,55.27600834048111,293.8051130519206,0.06910795514622088
0.0719235525611107,274.214594225203,0.22835727938152647,55.28166219580092,293.937082005983,0.06945474719631207
0.0722967262601172,274.225121218274,0.2295421058758721,55.28378443760405,294.05069974063906,0.069802821231858
0.0726768809068021,274.293652856923,0.23074909687909667,55.297600415955685,294.2284599990973,0.07015728214400624
0.0730591896020174,274.4477702823,0.23196292698640525,55.328670488911676,294.4987019672055,0.07051362485037654
0.0734411840508025,274.579604731419,0.23317575936129792,55.35524831385408,294.7450560190957,0.07086954787513486
0.0738228445232111,274.679570450799,0.23438753136119522,55.37540140288108,294.9571976738908,0.07122503324754281
0.0742041794104533,274.714536315194,0.23559826962818922,55.38245052114311,295.09950305458614,0.07158008920074946
0.0745902414959559,274.716406969877,0.23682401674965997,55.38282764512721,295.20757010866146,0.07193941821417235
0.0749807242005262,274.762080983719,0.23806379933667068,55.39203552631775,295.3639407987219,0.0723027304426096
0.0753739725116395,274.816941054561,0.2393123627244554,55.403095316599504,295.5309856153404,0.07266848248909613
0.0757645935283209,274.911592774639,0.24055258445241887,55.42217710336723,295.7401578574328,0.07303165855514926
0.076154041370227,274.958751970812,0.2417890813504707,55.43168439731569,295.89797214350324,0.07339361261776314
0.0765511371728409,275.019227431489,0.24304986052376984,55.44387625018819,296.0722620357657,0.07376253987364176
0.0769465107294586,275.033620056929,0.24430517156603104,55.44677780347689,296.19649745360135,0.0741297318800461
0.0773457426424088,275.110776080981,0.24557273288964793,55.46233245792577,296.38942336589395,0.0745003704662413
0.0777401153028957,275.167752484546,0.24682486608669382,55.473818900884474,296.5593252903332,0.07486636299821857
0.0781305307438507,275.220927430093,0.248064435111726,55.48453896990675,296.724084562021,0.07522855118974008
0.0785249446656058,275.284856102296,0.24931669931329842,55.49742699022287,296.901584195008,0.0755943156158614
0.0789165052976728,275.320451743611,0.2505599043201111,55.50460307151197,297.04777963219334,0.07595730172273626
0.0793093449229372,275.359740306989,0.2518071701303256,55.51252364588899,297.1983409288864,0.07632134112997684
0.0796995022877871,275.38745172286,0.25304591976372404,55.51811026732859,297.335694561474,0.07668276379816187
0.0800869417833472,275.402876347629,0.25427604016212735,55.52121987168201,297.4590504726479,0.07704153954729168
0.0804827499815237,275.459869359168,0.25553273119133774,55.53270966280827,297.6296371547451,0.0774079319891676
0.08088593815518,275.572596917713,0.25681285364269646,55.555435538610936,297.86254494926146,0.0777810179698669
0.0812921080785883,275.649382009285,0.25810244314951786,55.57091541307185,298.0575013633798,0.07815672239337017
0.0817004480880163,275.725346300656,0.25939892267945175,55.586229814212246,298.25223064264304,0.07853429189828132
0.0821062842488731,275.79051334048,0.2606874524901721,55.599367489440766,298.4346476219561,0.07890940503528245
0.082510742226547,275.799829956366,0.2619716065692867,55.60124571920339,298.5562786320212,0.07928310438018629
0.08292102628491,275.80825924543,0.26327425845458924,55.602945063878686,298.6785631599156,0.0796620441087326
0.0833339964006453,275.845560519415,0.2645854385720488,55.610465000714065,298.83287346687393,0.08004331973548315
0.0837471989022352,275.886213210038,0.2658973565145967,55.618660583143665,298.99091078212354,0.0804246644746586
0.0841621333840026,275.959985864466,0.26721477349420825,55.63353315027634,299.1853670034386,0.08080746137548347
0.0845745193029202,275.932608281513,0.26852409878677164,55.62801382955302,299.26947598692294,0.08118776197433847
0.0849910077787311,275.965202299812,0.26984644969747124,55.634584783642104,299.4197629551344,0.08157169919654096
0.0854100340813379,275.963052940584,0.27117685820824783,55.63415147282174,299.5330666974294,0.08195782719752463
0.0858315191847819,275.976411956414,0.2725150734116825,55.63684465041306,299.66388665379816,0.08234607060425582
0.0862549733199141,276.042278315105,0.27385954029072723,55.65012330832518,299.8522976663427,0.08273597601728438
0.0866765939666962,276.068432543919,0.2751981858442604,55.65539600085407,299.99710397855057,0.08312404222095214
0.0870959308642527,276.106056678823,0.2765295804940023,55.662981026450716,300.1537707025232,0.08350985711001531
0.0875169149109549,276.145624278275,0.2778662048422818,55.67095785450025,300.31303738126934,0.0838970378008488
0.0879370811490565,276.140221982013,0.2792002326482544,55.669868751573816,300.4231870909637,0.08428331693530719
0.0883598413382429,276.190514623053,0.2805424962489212,55.68000774800748,300.59466467427364,0.08467183027660342
0.0887849185400892,276.272977731681,0.2818921163647832,55.69663231070689,300.8018515544162,0.08506232080813017
0.0892138753710024,276.307780926333,0.2832540543029326,55.70364863474873,300.9582688579331,0.08545622078425373
0.0896424585093113,276.35304034072,0.28461480576706333,55.71277293268915,301.12600629338505,0.08584962271458961
0.0900774161981202,276.33228935539,0.2859957964290316,55.708589534046624,301.22358799263486,0.0862487177539376
0.0905164679370045,276.302142976805,0.2873897856999893,55.70251202412389,301.3120370424906,0.08665140781742141
0.0909571036598254,276.267124162651,0.2887888041199456,55.69545223119044,301.39558161291507,0.08705538770931706
0.0913994383767297,276.252843656827,0.29019321684611676,55.69257328121632,301.50219841703546,0.0874607611800963
0.0918461201868202,276.216962096285,0.2916114315931541,55.68533955861106,301.5864183946187,0.08786995181334512
0.0922951747819968,276.252769899738,0.2930371799328398,55.692558411787175,301.74956758164507,0.08828114737339281
0.0927476011429435,276.271766423059,0.2944736336288456,55.69638811088869,301.8953100223213,0.08869525951105625
0.0932083896318157,276.294060339741,0.2959366370810148,55.700882564491785,302.04698476884397,0.08911684942196178
0.093667988112589,276.294031528379,0.29739586225747006,55.700876756121204,302.17393758915847,0.0895371735813127
0.0941302424709414,276.296398385768,0.2988635198452389,55.70135391457083,302.30424535966813,0.08995974853248428
0.0945881210525471,276.293794170111,0.300317284341837,55.70082890469438,302.427905019141,0.0903781473506384
0.0950451630044688,276.289560888969,0.3017683925391884,55.69997547521615,302.54954724009417,0.0907956071708623
0.0955050241019727,276.291787762603,0.3032284515237633,55.70042441294077,302.6790416120475,0.09121546616972559
0.095957730125151,276.254025522603,0.3046657931473544,55.69281154535676,302.7627347496875,0.0916286203780231
0.0964115300497414,276.268755580407,0.30610660790792893,55.69578112501006,302.9042490108521,0.09204260167151672
0.0968616652110649,276.263560441789,0.30753578704513107,55.69473378506466,303.0229089433184,0.09245307052566243
0.0973089241517826,276.214379493097,0.30895583418190975,55.684818905808356,303.0925035968225,0.09286074980919719
0.0977660574675811,276.22375185305,0.31040723245956997,55.686708373574874,303.2290590506261,0.09327725797063585
0.0982262679335479,276.171460934831,0.31186840068901456,55.67616652446193,303.29875285221505,0.09369639465648016
0.0986996527444429,276.185034322987,0.31337139746360615,55.67890291951419,303.44440130387784,0.09412734666425218
0.0991720902993755,276.160446200911,0.3148713867005172,55.67394595410366,303.54785490866357,0.09455725124235528
0.0996484026025463,276.175841556492,0.3163836782630845,55.677049657788785,303.69632300501036,0.09499049471280567
0.100127503906973,276.11843473485,0.3179048249046393,55.66547644254576,303.765484387551,0.0954260857296764
0.100608942120056,276.064945058713,0.31943339123117775,55.65469292383655,303.83954713750154,0.0958636103788747
0.101101880997664,275.956673110308,0.32099847216758315,55.63286529903809,303.8564118356176,0.09631138842553608
0.101602884135834,275.878114438612,0.32258915713127295,55.61702787082418,303.90812653553064,0.09676628656235392
0.102099259489361,275.788312578624,0.3241651488787211,55.598923815850604,303.94609506872195,0.09721677880637841
0.102598837151474,275.657446585966,0.32575130795592994,55.572541231730746,303.93958005783065,0.09766997253065701
0.103098947027223,275.523173558899,0.327339156811433,55.545471789474036,303.92932263442026,0.09812344343488189
0.103605080394542,275.322904877218,0.32894613025267083,55.505097623247146,303.847756571481,0.09858216682497402
0.104111396827156,275.17781675924,0.3305536849262203,55.47584785866278,303.82696363789165,0.09904084568769467
0.104616236984487,274.979508276377,0.3321565524257462,55.4358688685176,303.74682968009614,0.09949797780158146
0.105119219689443,274.78588041645,0.3337535225139815,55.39683349195632,303.67115774750386,0.09995322027155559
0.105620031054625,274.547585661622,0.3353435985984344,55.348793269382995,303.5453101851748,0.10040629168066027
0.106126453585395,274.302488615113,0.33695149013362913,55.299381704806784,303.41323894148314,0.1008642307285006
0.106633103185491,274.01796254786,0.33856010261393393,55.24202124964858,303.23734822290396,0.10132216535352537
0.107147140879409,273.736987713913,0.34019217229212356,55.185376723124854,303.0671233004006,0.10178656348385866
0.107650109670235,273.403352750055,0.34178909820299613,55.118115914411085,302.8352536578083,0.10224075295817515
0.108156651283775,273.031501005511,0.34339736782598557,55.04315060271102,302.56167384924976,0.10269796035666322
0.10867162532915,272.547899220648,0.3450324104200512,54.94565648288263,302.16612240900116,0.10316256472865828
0.109188324840669,272.091228608382,0.346672931369124,54.85359168744981,301.8004140639708,0.10362850895640602
0.109718391252188,271.611088165374,0.3483558922256969,54.756795374139394,301.411819805135,0.10410628156194869
0.110237561467968,270.98197659048,0.35000425766079835,54.62996648064076,300.8543688915845,0.1045740117658826
0.110767316140958,270.421366437825,0.35168622874754163,54.51694747386552,300.3752154253134,0.10505105230584436
0.111309049332908,269.725326604242,0.35340623163198287,54.376625843415184,299.74819628956834,0.10553864419161427
0.111823100223901,268.949597620028,0.3550383432108857,54.22023888019764,299.0243754298702,0.10600110064095926
0.112358128248639,268.250238007049,0.35673705718942883,54.07924798222108,298.39033265177295,0.1064822017564697
0.11288942537165,267.3247244633,0.35842392555498875,53.89266445180129,297.5028589955966,0.10695971908459097
0.113428181022692,266.489836674001,0.3601344747470471,53.72435107347861,296.7172941089672,0.10744370722717353
0.113984709667329,265.636227166526,0.36190145319376954,53.55226339677164,295.9146953972271,0.10794341579808459
0.114524770769079,264.599010091101,0.36361614719182583,53.343160434365956,294.9021510675096,0.10842809949996128
0.115082946463637,263.684352053105,0.3653883550220474,53.158765373905965,294.02992422373126,0.1089287935923836
0.11562796153848,262.527142140696,0.36711877788467395,52.92547185556432,292.8826204349475,0.10941744058266169
0.116171100666783,261.458769089178,0.368843244617036,52.71008784837829,291.83272207325007,0.10990416821708304
0.116719312564014,260.344052637193,0.3705838173907444,52.48536101165811,290.73123149113565,0.1103952016372615
0.117260886653233,259.109982960475,0.37230331512401477,52.23657256483176,289.4934493031244,0.11088005293542269
0.117820610356995,257.982892493948,0.37408043788345907,52.00935112677991,288.378594349248,0.11138090600607041
0.118385845991776,256.68848010984,0.3758750610238888,51.74839759014374,287.07676298398655,0.11188643683057357
0.118944591945732,255.394440552658,0.37764907942769904,51.48751921541586,285.7722280694024,0.11238591241638576
0.119505527830495,254.100607379554,0.37943005086182163,51.22668244771808,284.467034586497,0.11288709481178416
0.120054273413259,252.681479431469,0.3811723180870973,50.940586253384154,283.01697084960136,0.11337714253762816
0.120618497550346,251.248112165969,0.3829637297223485,50.65161941265935,281.55328196778896,0.11388076283981961
0.121189843082711,249.665565521632,0.38477775178760737,50.33257800916102,279.92249623035485,0.11439048129735192
0.121781828262649,248.206001591732,0.3866573047339105,50.03832992089317,278.4329822513351,0.11491833922908283
0.122348405234207,246.673778925725,0.3884561866186072,49.72943383142616,276.85392239038276,0.11542328049776598
0.122925495357972,244.987200513065,0.3902884477615611,49.38941962343391,275.1023734924963,0.11593732926154537
0.123493760168082,243.328545836285,0.3920926885336603,49.055034840595056,273.3781029178394,0.1164432587053334
0.124062346789063,241.506578931105,0.393897951055275,48.68772631251077,271.4684518782959,0.11694921860671287
0.124650713703121,239.673889636561,0.3957660160074092,48.3182561507307,269.54941103576135,0.1174725107401748
0.125245392733838,237.756015719965,0.39765412192993566,47.93161276914495,267.53386128364457,0.11800113874469825
0.125865040156692,235.80256415929,0.3996215024974971,47.53779693451286,265.48186336625,0.11855166476905563
0.12650957757802,233.564352141059,0.40166790881021347,47.086573391637494,263.1124796677083,0.11912398292061542
0.126999695021814,231.899695218093,0.4032240316942594,46.75097855596755,261.3508857864424,0.11955896444696729
0.127333067658531,230.694549014437,0.4042824898158359,46.5080210813105,260.06959363254657,0.11985472614166114