File: example/data/02 processed data/test_ID_124.csv
Strain,Stress_MPa,Displacement(mm),Force(kN),True Stress (MPa),True Strain
-0.0001300970119299,0.0861108094512489,-0.00041305801287743247,0.01735993918537178,0.08609960669224442,-0.00013010547528019944
-0.0002126896141505,0.100170916919527,-0.0006752895249278374,0.020194456850976643,0.10014961160585828,-0.00021271223579418492
-0.0002996835389788,0.107161185716599,-0.0009514952362576899,0.02160369504046636,0.10712907127322228,-0.000299728453064134
-0.0003627339823658,0.11080557489272,-0.0011516803940114148,0.022338403898372352,0.11076538194527083,-0.00036279978625008085
-0.0003822783820728,0.0820027467751462,-0.00121373386308114,0.016531753749869475,0.08197139889778347,-0.0003823514690805138
-0.0003430886136072,-0.0039672198723542,-0.00108930634820286,-0.0007997915262666068,-0.003965858764388319,-0.0003431474819707006
-0.0002891485682542,-0.10294060504467,-0.0009180467042070851,-0.02075282597700547,-0.1029108399161061,-0.00028919037976151926
-0.0002348159417725,-0.0826253316621467,-0.0007455406151276874,-0.016657266863088774,-0.08260592991707817,-0.00023484351535236532
-0.0001485760178653,0.684955969816816,-0.00047172885672232745,0.1380871235150701,0.6848542017864074,-0.0001485870563752595
-9.90725797960112e-05,2.17293699071686,-0.00031455544085233554,0.438064097328519,2.1727217122434554,-9.907748780822503e-05
-3.77144077328411e-05,4.94553468393154,-0.00011974324455177049,0.9970197922805986,4.945348166020014,-3.771511893897117e-05
2.15440469892368e-05,8.14349761205379,6.840234919082683e-05,1.6417291185900442,8.143673055949002,2.1543814919638606e-05
6.38980757824777e-05,11.4460082154967,0.00020287639060936668,2.307515256244135,11.446739593397062,6.389603438746957e-05
0.0001272748136898,14.7110755542383,0.000404097533465115,2.965752831734441,14.712947903638643,0.0001272667149378637
0.0001889416876574,17.6454511531106,0.000599889858312245,3.557322952467097,17.648785114430947,0.00018892384042483923
0.0002628396732192,20.7763794610172,0.00083451596247096,4.188518099341068,20.78184031780541,0.0002628051369237927
0.0003217213826686,23.9844686481934,0.001021465389972805,4.835268879475789,23.992184964609464,0.0003216696414416805
0.000361780090971,27.3271085254216,0.001148651788832925,5.509145078724995,27.336994929229903,0.0003617146643334362
0.0004132267639792,30.5787865231352,0.0013119949756339598,6.164683363064056,30.591422496136563,0.00041314140931299095
0.0004989471901217,33.7743777153323,0.0015841573286363973,6.808914547410993,33.79122934619148,0.0004988227573610442
0.0005695370559611,36.9466065258285,0.0018082801526764923,7.448435875607025,36.96764898733697,0.0005693749312864407
0.0006904834823472,40.0508926876698,0.00219228505645236,8.074259965834232,40.078547167523894,0.000690245208303981
0.0007676149322709,43.1383588654387,0.0024371774099601075,8.696693147272441,43.171472513857466,0.0007673204666099112
0.0008406903207401,46.1407656690557,0.0026691917683498174,9.30197835888163,46.17955576414521,0.0008403371385630826
0.0009170780884504,49.086348484984,0.0029117229308300197,9.895807854572775,49.13136449962162,0.0009166578292609741
0.0009938170755474,52.067401957081,0.003155369214862995,10.49678823454753,52.11914743022535,0.0009933235663025185
0.0010680449983783,55.0380139835202,0.003391042869851102,11.095663619077673,55.09679705907597,0.0010674750441073627
0.0011465948669172,57.8578191397347,0.00364043870246211,11.664136338570515,57.92415861817134,0.0011459380290593957
0.0012312288894349,60.7433953172371,0.003909151723955807,12.245868495955,60.818184340394055,0.001230471548721957
0.0012995526357989,63.6229788788283,0.004126079618661507,12.826392541971787,63.70566028872766,0.0012987089481374795
0.001373451443315,66.537351522384,0.004360708332525125,13.413930066912615,66.62873734386677,0.0013725091216048432
0.0014440552565004,69.4973871697098,0.00458487543938877,14.010673253413495,69.59774523696527,0.0014430136113833968
0.0015274663008392,72.4905895886154,0.00484970550516446,14.614102861064866,72.60131652133998,0.0015263009107674493
0.0016091033370692,75.3118864165532,0.0051089030951947095,15.182876301577124,75.43307102430704,0.0016078101173912808
0.001691124657304,78.0635832700592,0.0053693207869402,15.737618387243934,78.19559852056469,0.001689696316109258
0.0017546108381886,80.6437723619364,0.005570889411248805,16.257784508166377,80.78527079895505,0.0017530733068418123
0.0018162946590083,83.1454854861635,0.005766735542351352,16.76212987401056,83.29650218737267,0.0018146471904214574
0.0018795383133575,85.7627903005926,0.005967534144910062,17.289778524599466,85.923984750823,0.001877774191365757
0.0019574290602445,88.3301655858983,0.0062148372662762874,17.807361382117097,88.50306561891234,0.001955515792298832
0.0020476475592643,90.8410064936589,0.006501281000664152,18.313546909121634,91.02701685888675,0.002045553986446571
0.0021156817324045,93.2129311813957,0.0067172895003842865,18.791726926169375,93.41014007712005,0.0021134468294817053
0.0021698327103087,95.5772887464584,0.006889218855230122,19.26838141128601,95.78467547394308,0.002167482023097952
0.0022487448181177,97.9286551363645,0.007139764797523697,19.742416875491084,98.14887169214762,0.0022462201756318725
0.0023207036221988,100.273698451596,0.00736823400048119,20.215177607841753,100.5064039868039,0.0023180149484875313
0.0023955914909111,102.59862326873,0.007606002983642742,20.68388245097597,102.84440765761175,0.002392726636051128
0.0024664280936201,104.854136473408,0.007830909197243817,21.138593913039053,105.11275166133831,0.0024633914519303574
0.0025369271418824,107.158863162476,0.008054743675476619,21.60322681355516,107.43071739092615,0.0025337145744401025
0.0026296691672438,109.428831586329,0.008349199605999063,22.060852447803928,109.71659321075909,0.0026262176368771076
0.0027554638619309,111.690054976132,0.008748597761630608,22.51671508318821,111.99781288635582,0.0027516745306978745
0.0028954518153359,113.848427070171,0.009193059513691483,22.951842897346474,114.17806970500446,0.0028912680686740727
0.003070113268786,116.023155006042,0.00974760962839555,23.390268049218065,116.37935923371248,0.003065410094770315
0.0032890314944809,118.20656441942,0.010442674994976857,23.83044338695507,118.59534953264986,0.003283634461165564
0.0035630163000626,120.344157899103,0.011312576752698755,24.261382232459166,120.77294609531481,0.0035566837949070154
0.0038677122466712,122.612383982692,0.01227998638318106,24.718656610910706,123.08661340181541,0.003860251877845679
0.0042027299440958,124.722036750067,0.013343667572504166,25.14396260881351,125.24620978860514,0.004193923141058359
0.004563298354423,126.932906387654,0.014488472275293025,25.589673927751047,127.51213911049491,0.0045529180753813014
0.0049406583142103,129.010753272282,0.0156865901476177,26.00856785969205,129.6481513230592,0.004928493314206423
0.0053273380252553,130.901412198275,0.016914298230185577,26.389724699172245,131.5987682690385,0.005313197957087958
0.0057220506872272,132.415405184337,0.018167510931946358,26.694945685162338,133.17309284457153,0.0057057419386092436
0.0061298442233222,133.532924111369,0.019462255409047984,26.92023750085199,134.35146013485638,0.006111133153252121
0.0065489448611097,134.195096406961,0.020792899934023296,27.05373143564334,135.0739326939615,0.006527593689446906
0.006982551139652,134.54812279072,0.0221695998683951,27.124901554609153,135.48761193885036,0.006958286018924807
0.0074095169902351,134.69393694681,0.023525216443996442,27.154297688476895,135.69195396109905,0.007382201366619215
0.0078433952623829,134.678316043602,0.024902779958065707,27.15114851439016,135.7346513096041,0.007812795736401474
0.0082624974891542,134.591712049967,0.026233429528064584,27.133689149273348,135.70377573284082,0.008228549923039289
0.0086974031136893,134.476718970727,0.027614254885963526,27.110506544498566,135.64631720502172,0.008659798587075817
0.0091374748179368,134.331391472497,0.029011482546949338,27.081208520855395,135.55884117933533,0.009095980671187342
0.0095796607108742,134.117428181104,0.030415422757025582,27.038073521310565,135.40222763849403,0.009534066713285272
0.0100232026981668,133.941728940841,0.03182366856667959,27.002652554473542,135.28425403975794,0.009973303557775474
0.0104648735655933,133.748120809929,0.033225973570758724,26.963621155281686,135.1477779838406,0.01041049581805163
0.0109144302953916,133.584337187363,0.03465331618786833,26.93060237697238,135.04233412415056,0.010855297777141386
0.0113605482709357,133.337032271786,0.03606974076022085,26.88074570599206,134.85181406321294,0.011296501854241974
0.0118041815350777,133.128859580729,0.037478276373871695,26.838778091474964,134.7003368067778,0.011735055635569343
0.0122425171749836,132.883267919403,0.038869992030572925,26.789266812551645,134.51009360917425,0.01216818363309806
0.0126928412303265,132.683331473527,0.040299770906286635,26.748959625063044,134.36745993383127,0.012612962337660147
0.0131457002827464,132.522230975482,0.04173759839771982,26.71648176465717,134.26432850468657,0.013060045410356548
0.0135834037789043,132.308490196088,0.04312730699802115,26.673391623531344,134.10568984179866,0.013491976349805344
0.0140468752008015,132.14077561902,0.044598828762544764,26.63958036479443,133.9969406030775,0.013949132109190047
0.0145016283722357,131.929384348389,0.04604267008184834,26.59696388463522,133.84257525158716,0.01439748538075439
0.0149603071007412,131.745851275535,0.04749897504485331,26.559963617147854,133.71680966986557,0.014849505424390657
0.0154276513187508,131.519043793505,0.04898279293703379,26.514239228770613,133.5480737429267,0.015309855107144697
0.0158869341237772,131.225441366409,0.050441015842992605,26.455048979468057,133.31021130876073,0.01576205765237763
0.0163621506802925,130.99828469198,0.05194982840992868,26.409254193903166,133.14169836497,0.01622973316393788
0.0168279647157575,130.796060755449,0.053428787972530055,26.368485848298516,132.99709225080176,0.016687943185802256
0.0172894836459565,130.617734495419,0.05489411057591189,26.33253527427647,132.87604767984945,0.017141721249099674
0.0177366566207905,130.471000836738,0.056313884771009834,26.30295376868638,132.7851201775501,0.01758119765009835
0.0181789339624552,130.279075287556,0.05771811533079526,26.26426157797129,132.6474099938982,0.018015672783220364
0.0186431254090669,130.089144926627,0.0591919231737874,26.225971617208003,132.5144131698524,0.018471472495828905
0.0191129270167776,129.908860176398,0.06068354327826887,26.18962621156184,132.39179873978227,0.018932569510336762
0.0195851260261256,129.648190246276,0.06218277513294877,26.13707515364924,132.1873663913084,0.019395805365285585
0.0200466980767442,129.436080206601,0.06364826639366283,26.094313769650764,132.03084622673995,0.019848408676376918
0.0204887389503628,129.134110559131,0.06505174616740188,26.03343668872081,131.7799056399643,0.020281668371368865
0.0209502846453464,128.872390023021,0.06651715374897482,25.980673828641038,131.5723032769294,0.02073384519126218
0.0214092331694051,128.650813680298,0.06797431531286119,25.936004037948077,131.40512894781318,0.021183274909958225
0.021871342494348,128.458058915353,0.06944151241955489,25.89714467733517,131.26760911804982,0.021635595886651763
0.0223467986574559,128.355979464596,0.07095108573742248,25.876565460062558,131.22432469417188,0.02210076754530216
0.0228188785918587,128.19682583837,0.07244993952915138,25.84448008901539,131.1221336430374,0.022562422019595848
0.0232924801971514,128.031830763369,0.07395362462595569,25.81121708189519,131.01400964602982,0.023025350502658477
0.0237571170508415,127.825234934802,0.07542884663642176,25.769567362856083,130.8619940031994,0.0234793081031914
0.0242177170119127,127.555488261889,0.07689125151282282,25.715186433596823,130.64459097993176,0.023929118287551437
0.0246712012460528,127.265206479828,0.07833106395621764,25.656665626333325,130.4049920005123,0.024371781857551886
0.0251349236438687,127.077126069394,0.07980338256928313,25.61874861558983,130.2711999300305,0.024824236750818168
0.0256265549085743,126.897166505588,0.0813643118347234,25.582468767526542,130.14910371078597,0.025303698920617495
0.0261086805331061,126.793816468851,0.08289506069261186,25.561633400120364,130.10423571660954,0.025773667584290533
0.0265873497545221,126.62054729679,0.08441483547060767,25.526702335032866,129.98705207387877,0.026240048600310033
0.027047871351012,126.424511325199,0.08587699153946309,25.48718148316012,129.84402524313757,0.026688542665347897
0.0275116399983939,126.220921099291,0.08734945699490063,25.446137693617064,129.69346564084037,0.027139995789676206
0.0279802885627444,126.040848380482,0.08883741618671347,25.409835033505175,129.567507688861,0.027595992299279882
0.0284503148648258,125.821525025833,0.0903297496958219,25.36561944520793,129.40118702959052,0.02805312059671226
0.0289325519072726,125.5970001307,0.0918608523055905,25.320355226349122,129.2308418563792,0.02852190748034629
0.0294139605640296,125.441085628549,0.09338932479079398,25.28892286271548,129.1308047743362,0.028989669990320197
0.0298955766120229,125.246688986266,0.0949184557431727,25.24973249963122,128.9910109722571,0.029457415171974206
0.030382332957376,125.127407619246,0.09646390713966879,25.22568537603999,128.92907017962725,0.029929930410961057
0.0308664115586754,124.909070849307,0.0980008566987944,25.18166868322029,128.76456563755346,0.030399624921618046
0.0313635612961873,124.721259200035,0.09957930711539467,25.143805854727056,128.63296205789297,0.030881772648774362
0.0318555377968236,124.582249856697,0.10114133250491493,25.115781571110116,128.55088442582036,0.03135867450585493
0.0323401476169151,124.418820843098,0.10267996868370545,25.08283428196856,128.4425438754863,0.03182821315707799
0.0328196471922696,124.268561511042,0.10420237983545598,25.05254200062607,128.34701185692526,0.0322925835996717
0.0332939372294997,124.108965248596,0.10570825070366154,25.020367394116953,128.24104134720093,0.03275169683443022
0.0337782070696092,123.925298348035,0.1072458074460092,24.983340146963855,128.111272736798,0.03322025314515678
0.0342425263044859,123.742423308144,0.10872002101674272,24.94647253892183,127.97967649325395,0.03366930013504982
0.0347323283367875,123.5833978046,0.11027514246930031,24.914412997407357,127.87573695412519,0.0341427733049659
0.0352126446089145,123.377884055809,0.11180014663330354,24.872981425651098,127.72234563966606,0.034606859343025306
0.0357023242178122,123.215500568162,0.11335487939155373,24.840244914541458,127.61458031810655,0.035079770713501726
0.0362024841866548,123.002276494161,0.114942887292629,24.797258941222857,127.4552644638634,0.03556257279642487
0.0366830781417907,122.763367292032,0.11646877310018545,24.749094846073653,127.26670548735495,0.036026268402666754
0.0371803973520769,122.566128121061,0.11804776159284415,24.7093314292059,127.12318546650759,0.036505874920352906
0.0376758215692071,122.434970077946,0.11962073348223255,24.682889967713916,127.0478081644339,0.03698342533760842
0.0381603622073584,122.29522305565,0.1211591500083629,24.654716968019038,126.96205306368327,0.03745026434035648
0.0386389536476672,122.222747972992,0.12267867783134336,24.640105991355185,126.94530706661095,0.037911157643938743
0.0391315057985314,122.047009166137,0.12424253091033718,24.60467704789322,126.8228924130151,0.03838527369256322
0.0396348263838372,121.834275435826,0.1258405737686831,24.561789927862524,126.66315579032558,0.03886952301616392
0.0401460315591134,121.637889935304,0.12746365020018505,24.52219861095729,126.52116850343067,0.039361118256709335
0.0406494672714086,121.449179456145,0.1290620585867223,24.484154578358837,126.386023901587,0.03984500600291159
0.0411573119350854,121.320790978294,0.13067446539389613,24.458271461224072,126.31402861679895,0.04033289438796539
0.0416727047799213,121.177483331331,0.13231083767625013,24.42938063959633,126.22727682017138,0.04082779109217937
0.0421860245315854,121.005460611073,0.13394062788778366,24.394700859192316,126.11019994086753,0.041320453819096985
0.0426897293922916,120.87179030573,0.1355398908205258,24.36775292563517,126.03177432504344,0.04180365275271078
0.0431954297941383,120.718784933624,0.1371454895963891,24.336907042618595,125.93328473305804,0.042288531231784644
0.0437124242890239,120.615917292003,0.13878694711765088,24.316168926067807,125.88833144468086,0.04278399585371339
0.0442282243281924,120.518393287653,0.14042461224201086,24.296508086790848,125.84870782165264,0.04327807124805259
0.0447441367013077,120.355707497784,0.14206263402665195,24.263710631553256,125.74091972684745,0.04377201017537304
0.0452579819084926,120.17060487,0.143694092559464,24.226393941792004,125.60928393113907,0.04426372758844444
0.045758250841845,120.007434441466,0.14528244642285787,24.193498783399548,125.49876472952488,0.04474222118888807
0.0462717542356759,119.832427063682,0.14691281969827097,24.15821729603829,125.37728367823725,0.04523313518428702
0.0467710858498745,119.685040788607,0.14849819757335153,24.12850422298317,125.28284010627667,0.04571026982683567
0.0472741766729807,119.543405707529,0.15009551093671372,24.099950590637846,125.19472178903655,0.0461907664443534
0.0477817769061286,119.377781076614,0.1517071416769583,24.066560665045383,125.08186357956544,0.04667533607335361
0.0482856734895446,119.192476273002,0.1533070133293041,24.029203216637203,124.94776526473045,0.04715613796074319
0.0488126841801585,118.99343691025,0.15498027227200323,23.9890768811064,124.80182596566166,0.04765874738750753
0.0493319842292067,118.80661373668,0.15662904992773125,23.951413329314693,124.66757973186334,0.048153756208844434
0.0498615023456339,118.652100763652,0.15831026994738762,23.920263513952246,124.56827276419322,0.04865825294156082
0.050393142621669,118.504061391421,0.15999822782379908,23.890418776510472,124.4758534583659,0.04916451563562424
0.0509260521031441,118.251393431873,0.1616902154274825,23.839480915865597,124.27347005505395,0.04967172986013405
0.0514612404180079,118.06760065218,0.16338943832717506,23.80242829147949,124.1435058349192,0.05018085425251229
0.0519923310179101,117.916868620344,0.16507565098186455,23.77204071386135,124.04764148624834,0.05068582438201697
0.0525284586439567,117.855235184435,0.1667778561945625,23.759615413182097,124.04598903179439,0.05119532530049512
0.0530610996133804,117.78026200596,0.16846899127248277,23.744500820401537,124.02981222074828,0.051701255792690436
0.0535955912732969,117.633638986302,0.17016600229271764,23.714941619638484,123.9382834214024,0.05220868699749685
0.0541393389567004,117.472281008943,0.17189240118752377,23.682411851402907,123.83215264850293,0.05272464153017313
0.054684164145341,117.299807511586,0.17362222116145765,23.647641194335737,123.71424943976648,0.05324135162939298
0.0552265993425625,117.112012079969,0.17534445291263592,23.609781635321752,123.57971024931079,0.05375552997149067
0.0557688081558986,116.965704871904,0.17706596589497806,23.580286102175847,123.48874282772468,0.05426922964448261
0.0562872128994982,116.765397294924,0.17871190095590678,23.539904094656677,123.33779607175788,0.0547601302160982
0.0568184949693242,116.589663247598,0.18039872152760433,23.504476110715753,123.21411244230686,0.05526297499006505
0.0573430904833842,116.424057831079,0.18206431228474482,23.471090058745528,123.10017311372933,0.055759243135732106
0.057883972067413,116.293898087205,0.18378161131403625,23.44484985438053,123.02545083569534,0.056270660189147864
0.0584364047230128,116.152479941305,0.18553558499556563,23.41633995616709,122.94001326873673,0.05679272922387985
0.0589853430451386,116.001969491998,0.18727846416831503,23.385997049586795,122.8443854563952,0.05731122615062804
0.0595263953089122,115.849017997122,0.1889963051057962,23.355162028219798,122.74509243856798,0.05782201140212489
0.0600761473335781,115.644518621001,0.19074176778411045,23.313934953993805,122.59199575999696,0.05834074265096344
0.0606378205283053,115.408133395631,0.1925250801773693,23.26627969255921,122.40623107598199,0.058870444644133844
0.0612015224519434,115.256292585784,0.1943148337849203,23.235668585294054,122.3101531642006,0.05940177793170313
0.0617614590698961,115.103825072535,0.1960926325469201,23.204931134623056,122.21280525354085,0.05992928277828825
0.0623280155027763,115.01264130601,0.19789144922131474,23.186548487291617,122.18115099634625,0.0604627409523419
0.062875070552075,114.848031672752,0.19962834900283813,23.153363185226805,122.06910976694324,0.06097756710234263
0.0634266300978813,114.687549144293,0.2013795505607731,23.12100990748947,121.96179390070064,0.06149636418368677
0.0639873862520997,114.528472455778,0.20315995135041653,23.088940047084844,121.85685005966883,0.062023535822959136
0.0645469138677255,114.377910180485,0.20493645153002846,23.058586692385774,121.76065129727522,0.06254927565104856
0.0651213084640386,114.256170284239,0.20676015437332254,23.034043929302584,121.69668159323865,0.06308869733581413
0.0656934087540288,114.020347260234,0.20857657279404146,22.986502007663177,121.51073253907687,0.06362567532748496
0.066265222551633,113.811939317024,0.21039208160143477,22.944486966312038,121.35371280489953,0.06416209644083966
0.0668353860643114,113.657875534586,0.2122023507541887,22.913427707772538,121.25424352518951,0.06469668306460608
0.0674024750724133,113.525510301779,0.21400285835491223,22.886742876838643,121.17741067997765,0.06522810370124103
0.0679587286637852,113.431859111958,0.215768963507518,22.867862796970737,121.14054404717628,0.06574909621808622
0.0685089562543101,113.279261120301,0.21751593610743455,22.83709904185268,121.03990506491229,0.06626417782364867
0.0690696309345764,113.083174909235,0.21929607821728003,22.797568061701778,120.89378806512602,0.06678876643665622
0.0696340985311837,112.906567304,0.22108826283650823,22.761963968486402,120.76871433646446,0.06731662600124862
0.070217738059836,112.735045712493,0.2229413183399793,22.72738521563859,120.65104562249647,0.06786212128568346
0.0708041965477789,112.546724008349,0.224803324039198,22.689419560083163,120.51550437584476,0.06840995173349962
0.0713902151140775,112.331092125358,0.22666393298719606,22.64594817247217,120.35043295618657,0.06895707161928284
0.0719780932063736,112.111706800676,0.2285304459302362,22.601720091016283,120.18129368230069,0.0695056269979881
0.0725543895721951,111.883653219402,0.23036018689171942,22.555744489031444,120.00130338184289,0.07004308342200763
0.073123956892847,111.712196963251,0.2321685631347892,22.521178907791406,119.881034838397,0.07057398064149813
0.0737030298099019,111.580328596453,0.23400711964643853,22.494594245044922,119.80413688119603,0.07111344929424515
0.074274754051897,111.42163783044,0.23582234411477296,22.462602186616706,119.69745257635549,0.07164578650908232
0.0748471262344927,111.290655889908,0.2376396257945143,22.436196227405453,119.62044166001944,0.07217844331312762
0.0754364074345342,111.072973002366,0.23951059360464605,22.392311357276984,119.4519190487375,0.07272653960421355
0.0760337933962736,110.885573653326,0.24140729403316866,22.354531648510523,119.31662445111027,0.0732818677485318
0.0766224472874329,110.650513548206,0.24327627013759942,22.307143531318328,119.1288266898808,0.07382877709216669
0.077218455247945,110.45265368334,0.24516859541222538,22.267254982561344,118.98163697880375,0.07438221441896574
0.0778184344306512,110.319907800371,0.24707352931731755,22.240493412554795,118.90483031192966,0.07493903012925031
0.0784130439232226,110.148980172474,0.24896141445623174,22.206034402770758,118.78609699283639,0.07549055672888783
0.0789993124344534,109.987950089822,0.2508228169793896,22.173570738108115,118.67692252299291,0.07603404905100632
0.0795768212680481,109.788349823759,0.25265640752605273,22.133331324469815,118.52495771499822,0.07656913219063423
0.0801448459778699,109.581259052226,0.2544598859797369,22.091581824928763,118.36363218102773,0.07709514878947088
0.0807375863266269,109.411553373369,0.2563418365870404,22.05736916007119,118.24517810898172,0.07764375833412927
0.0813307733096627,109.233947917603,0.25822520525817905,22.021563900188767,118.11802937340907,0.0781924801127685
0.0819267676198484,109.065530468639,0.2601174871930187,21.987610942477623,118.00091683867866,0.07874349571214935
0.0825258130230542,108.879701796302,0.26201945634819707,21.950147882134484,117.86508770874951,0.07929702635898235
0.0831032099634923,108.570465934174,0.26385269163408803,21.88780593232948,117.59302016053584,0.07983026353671778
0.0836897173398438,108.301937236014,0.26571485255400407,21.83367054678042,117.36569575065352,0.08037162342698242
0.0842688819182908,108.090857626409,0.2675537000905733,21.79111689748406,117.19955334417565,0.08090591830920302
0.0848854708316817,107.90536894792,0.2695113698905894,21.753722379900672,117.06496699633051,0.08147442458374818
0.0854893666524673,107.794629637854,0.27142873912158366,21.731397334991367,117.0099242541314,0.0820309144821199
0.0860965805438027,107.581791646609,0.27335664322657355,21.688489195956375,116.84421603615789,0.08259014991827175
0.0867145852306819,107.321179728257,0.27531880810741505,21.63594983321661,116.62749131486026,0.0831590025763204
0.0873292797961371,107.075640838412,0.27727046335273525,21.58644919302386,116.42647943654038,0.08372448756190318
0.0879452621720657,106.846020698949,0.2792262073963086,21.54015777290812,116.24262200136005,0.08429083666451903
0.0885592515076644,106.666009966197,0.28117562353683445,21.503867609185313,116.11227197011246,0.08485503430162618
0.0891757285620627,106.456267399705,0.28313293818454904,21.461583507780528,115.94958260507146,0.0854211978398964
0.0897942105627519,106.256385488098,0.2850966185367373,21.421287314400555,115.7975937402532,0.08598888076768117
0.0904033553466062,105.99715844853,0.28703065322547466,21.369027143223647,115.57965722948298,0.08654767856585316
0.091020353280996,105.819225418563,0.2889896216671623,21.3331558443823,115.45092870008193,0.08711336229653112
0.091623434009491,105.581092308158,0.29090440298013387,21.285148209324653,115.2547945519045,0.08766597720085442
0.0922287123509547,105.339104828403,0.29282616171428116,21.236363533406042,115.05439482692883,0.08822029893730637
0.0928467457153015,105.100197661493,0.29478841764608227,21.188199848556987,114.85840898839757,0.08878598501331468
0.0934816938061572,104.813229681642,0.2968043778345491,21.130347103819027,114.61134792557567,0.08936682007654571
0.0941262600908923,104.565363237765,0.29885087578858305,21.080377228733422,114.40770981438149,0.08995610875803883
0.0947677445664371,104.342527735137,0.3008875889984378,21.03545359140362,114.23083375095683,0.09054223535214952
0.0953970471598744,104.102022872781,0.3028856247326012,20.98696781115265,114.03304845821403,0.09111689769092232
0.0960341232069387,103.860358992939,0.30490834118203036,20.938248372976506,113.83449750478377,0.09169832235406132
0.0966541503204216,103.561388441836,0.30687692726733856,20.87797590987414,113.5710264476848,0.09226386296235876
0.0973021750306488,103.268858575458,0.3089344057223099,20.81900188881233,113.31714312778253,0.0928545991785581
0.0979344930404236,103.040222456649,0.31094201540334493,20.772908847260442,113.13141440571339,0.09343068105297177
0.098579269772469,102.778627158657,0.3129891815275891,20.720171235185255,112.91046917217426,0.09401777207100358
0.0992103951459754,102.53543982882,0.3149930045884719,20.671144669490115,112.70802133070362,0.09459209945176125
0.099836214210899,102.251670573133,0.3169799801196043,20.61393678754361,112.46009025989459,0.09516127254627943
0.100469140001237,101.947689359502,0.31898951950392745,20.552654174875602,112.19028603456441,0.09573657979314255
0.101096048100689,101.628347894997,0.3209799527196876,20.4882749356314,111.90257224218318,0.09630609108427722
0.101749629735745,101.350949709911,0.32305507441099035,20.43235146151806,111.66337131626057,0.09689948867069022
0.102401559809361,101.069804749682,0.32512495239472117,20.375672637535892,111.41951040567702,0.09749103619766486
0.103061539866941,100.770196838318,0.32722038907753764,20.31527168260491,111.1557284971698,0.09808953188537513
0.103732179177007,100.49947503882,0.3293496688869972,20.260694167826113,110.924504590742,0.09869732709969344
0.104357595755086,100.116172119639,0.33133536652239803,20.183420299319224,110.5640551382469,0.0992638046060917
0.105000512260892,99.8115212706904,0.3333766264283321,20.122002688171186,110.29178213365181,0.09984579855412624
0.105654429720582,99.4926590122571,0.33545281436284785,20.057720056871034,110.00449916158145,0.10043740375342189
0.106347567613295,99.1420286909062,0.3376535271722116,19.987032984086692,109.68554229043158,0.10106411016348389
0.10704145889046,98.8460559701667,0.3398566319772105,19.927364883585607,109.4266820067814,0.10169110459743848
0.107741064028848,98.5226821267124,0.3420778782915924,19.86217271674522,109.13762073002036,0.10232286428889098
0.108436861703426,98.2067759045276,0.3442870359083775,19.798486022352765,108.8560104816262,0.10295079013307622
0.109131563697015,97.8655556372431,0.3464927147380226,19.72969601646821,108.54577675601266,0.1035773340614237
0.109815419346759,97.4400042518581,0.34866395642595976,19.643904857174594,108.14041917992589,0.10419371261992096
0.110499481278817,97.0328981897215,0.35083585306024395,19.561832275047852,107.75498310666597,0.10480989724626294
0.111207036297501,96.6885836354852,0.3530823402445657,19.492418460913818,107.44103446539057,0.10544684459912697
0.111921115083388,96.3307717934564,0.3553495403897569,19.42028359356081,107.11221918942344,0.10608925363884086
0.112651037408808,96.0288862470283,0.3576670437729654,19.359423467400905,106.84663990396847,0.10674548980613903
0.113363417049661,95.6492809692646,0.35992884913267364,19.28289504340374,106.49241029828353,0.10738553925752119
0.114062243451962,95.1813869206627,0.3621476229599793,19.188567603205602,106.03798944770273,0.10801301377900308
0.114773738189794,94.7632476928074,0.36440661875259595,19.10427073486997,105.63957987351627,0.10865145892961993
0.115508303830277,94.295246658962,0.3667388646611295,19.00992172644674,105.18713065979631,0.10931017890602185
0.116253380988141,93.8592218893947,0.3691044846373477,18.922019132901973,104.77067377095297,0.10997788208473809
0.11698979251466,93.4550365596584,0.3714425912340455,18.840535370427133,104.38832189622279,0.11063738174151314
0.117709400066507,93.0060965911236,0.3737273452111597,18.750029072770516,103.95378842339237,0.1112814125615082
0.118442852618881,92.5339001203821,0.37605605706494716,18.65483426426903,103.49387921459078,0.11193740776737604
0.119198556846695,91.9656636889465,0.3784554179882566,18.540277799691616,102.92783808011743,0.11261285491753005
0.119962908727361,91.4182192049595,0.38088223520937114,18.429912991719835,102.38501469146193,0.11329556755090299
0.12071399017312,90.9348484011821,0.38326691879965596,18.332465437678312,101.91195679747655,0.11396597342178806
0.121482461458617,90.4126449828464,0.385706815131109,18.227189228541835,101.39619564234665,0.11465143638827092
0.122264890673473,89.8477895959936,0.38819102788827675,18.11331438255231,100.83301976820096,0.11534886718040314
0.123029325866843,89.2567001967153,0.3906181096272265,17.994150759657806,100.23789185101609,0.11602978927718213
0.123810253175306,88.5998772754703,0.39309755383159656,17.861735258734814,99.56945051224733,0.11672492331985564
0.124600630985998,88.0391639290442,0.3956070033805436,17.748695448095308,99.00889930608281,0.11742797795174316
0.12541742900188,87.4317007235166,0.39820033708096897,17.626230865860947,98.39715984152186,0.11815401483676818
0.126214845530923,86.7035226512697,0.40073213456068046,17.47943016649597,97.64679436968659,0.11886231571822242
0.127023995905162,85.9792882736798,0.40330118699888934,17.33342451597385,96.90072103528445,0.1195805266722862
0.127853831107059,85.2532740404794,0.4059359137649123,17.187060046560646,96.15323174097466,0.12031656232745072
0.128664872719538,84.5308754309499,0.40851097088453314,17.0414244868795,95.40702975914421,0.12103540560229555
0.129473888874964,83.88453081367,0.4110795971780107,16.91112141203587,94.7453872345676,0.12175193923946537
0.130274835880819,83.1644260728851,0.41362260392160033,16.76594829629364,93.99865803065272,0.12246082074529037
0.131067333785101,82.3747318702987,0.4161387847676956,16.606745945052218,93.17136834780133,0.12316173009669867
0.131907142786362,81.5857875579877,0.41880517834669934,16.447694771690323,92.34753568673699,0.12390394707573127
0.132729316580661,80.6796100146687,0.42141558014359864,16.26500937895721,91.38815951390994,0.1246300449242583
0.133548274397336,79.9196099862487,0.42401577121154177,16.111793373227737,90.59273599042031,0.1253527788519848
0.134345304716848,79.1097036494389,0.4265463424759924,15.948516255726881,89.7377208922823,0.12605566046835864
0.135128747381403,78.2618223588317,0.42903377293595457,15.777583387540469,88.83724438196649,0.12674607831645116
0.135932899041833,77.4344059222334,0.43158695445781975,15.610776233922252,87.96028920482466,0.12745425080952627
0.136750053884312,76.4987091855557,0.43418142108269053,15.422139771808029,86.95991178876075,0.12817336112505967
0.137599569915395,75.527129204022,0.43687863448137904,15.226269247530837,85.9196296994399,0.1289204020036481
0.138469874766155,74.5258467632154,0.43964185238254205,15.024410707464224,84.8454314313595,0.12968514571145454
0.13931899909945,73.4172481875732,0.44233782214075373,14.800917234614756,83.6456657217018,0.13043071469931938
0.139743272654791,72.8616016084288,0.4436848906789614,14.688898884259247,83.04352026806022,0.1308030376195838