File: example/data/02 processed data/test_ID_096.csv
Strain,Stress_MPa,Displacement(mm),Force(kN),True Stress (MPa),True Strain
-6.78161620895802e-05,0.179190588825325,-0.00021531631463441714,0.03612482270718552,0.17917843680730827,-6.781846170950629e-05
-0.0001429477616784,0.98379615726379,-0.00045385914332891995,0.19833330530438006,0.9836555258051612,-0.0001429579796835036
-0.0002660430367949,2.44103465550175,-0.0008446866418238075,0.4921125865491528,2.4403852352290785,-0.0002660784325216045
-0.0003995029349621,5.30604266344876,-0.0012684218185046675,1.0696982009512699,5.303922883831678,-0.0003995827575198419
-0.0004707913839945,8.85029026519703,-0.0014947626441825376,1.784218517463721,8.846123624794325,-0.00047090224105321465
-0.0004714039267367,12.7340943985082,-0.0014967074673890223,2.567193430739253,12.728091496405307,-0.0004715150724988673
-0.0004140696101648,16.8103986097775,-0.00131467101227324,3.388976359731144,16.803437934578437,-0.0004141553606577324
-0.0003521253354968,20.8319438356479,-0.00111799794020234,4.199719877266616,20.82460838043572,-0.00035218734618017633
-0.0002843295895131,25.1288301045725,-0.0009027464467040925,5.065972149081817,25.121685234623925,-0.0002843700188344966
-0.0002106965986387,29.6174663748137,-0.0006689617006778724,5.9708812211624425,29.611226075388227,-0.00021071879828535813
-0.0001264220420109,34.252121887699,-0.00040138998338460746,6.905227772560117,34.24779166450675,-0.00012643003395078594
-4.21856297364577e-05,38.9445078954931,-0.0001339393744132532,7.85121279173141,38.942864996902756,-4.2186519575161384e-05
4.26180075737827e-05,43.69035133474,0.00013531217404676006,8.807974829083586,43.69221333046409,4.261709945239691e-05
0.0001240121652949,48.2948675052972,0.0003937386248113075,9.736245289067915,48.300856656389165,0.00012400447642210529
0.0002062291338281,52.9526204616499,0.0006547774999042175,10.67524828506862,52.96354083470163,0.0002062078715234631
0.0002945422804802,57.4890050025695,0.0009351717405246349,11.589783408518011,57.50593794520549,0.000294498911418403
0.0003771872150688,61.9837245368378,0.00119756940784344,12.4959188666265,62.007104005275444,0.00037711609785368787
0.0004643400334334,66.4575241959316,0.001474279606151045,13.397836877899811,66.48838308493863,0.0004642322609608641
0.0005573917097572,70.935003051424,0.00176971867847911,14.30049661516708,70.97454163405646,0.0005572364246985527
0.0006572981156123,75.5115056923081,0.0020869215170690523,15.223119547569315,75.5611392627067,0.0006570821898191626
0.0007526609378355,80.1843351997972,0.002389698477627712,16.165161976279116,80.24468681672839,0.0007523778306386772
0.0008493474631275,84.8479167319597,0.002696678195429812,17.105340013163076,84.91998209478764,0.0008489869716781449
0.000944881754395,89.42669992026,0.002999999570204125,18.02842270392442,89.51119757737042,0.0009444356346283849
0.0010387636533442,93.8967562509691,0.0032980745993678347,18.929586060195373,93.99429278852953,0.0010382245117086441
0.001141360585307,98.3404607363977,0.003623819858349725,19.825436884457776,98.45270266222316,0.0011407097285086145
0.0012376083692083,102.919430923109,0.003929406572236353,20.748557274098776,103.0468048721736,0.0012368431632556324
0.0013349532662524,107.55761863665,0.00423847662035137,21.68361591714864,107.70120303095932,0.0013340630083545013
0.001433366288515,112.179411961241,0.004550937966035125,22.615369451386186,112.34020614861168,0.0014323399996380999
0.0015287465547449,116.802602292743,0.004853770311315057,23.54740462221699,116.98116386858327,0.0015275792112939759
0.0016217084855251,121.160599989065,0.005148924441542193,24.425976957795505,121.35708716217857,0.0016203949362565727
0.0017180676051836,125.498101555697,0.00545486464645793,25.30041727362852,125.71371577849189,0.0017165934152992993
0.0018133235090826,129.669829479443,0.005757302141337255,26.141437623055708,129.90496282965682,0.0018116814227978342
0.0019126299496166,133.844474800386,0.006072600090032705,26.98304611975782,134.10046975147992,0.0019108032018453134
0.001999361861444,137.902432519851,0.0063479739100847,27.801130396001962,138.17814938403154,0.0019973657976439145
0.0020978318135759,141.91699646664,0.006660616008103482,28.610466487674625,142.21471445671483,0.002095634437031089
0.0021926675857444,145.923339994295,0.00696171958473847,29.418145342849872,146.24330137190404,0.00219026719836765
0.002289411464569,149.914969807637,0.007268881400006574,30.22285791321962,150.25818685822512,0.0022867947551972806
0.0023786409506825,153.877736775813,0.007552185018416938,31.021751734003903,154.24375666190627,0.0023758164623720658
0.0024651875372111,157.725738277572,0.007826970430645242,31.797508836758517,158.11456180187128,0.0024621539469706043
0.0025535658664234,161.422998214833,0.008107571625894294,32.542876440110334,161.8352024731301,0.002550311056842498
0.0026416664104446,165.106142197153,0.008387290853161604,33.285398266946046,165.54229754715328,0.002638183342453161
0.0027286501806119,168.748325697204,0.008663464323442782,34.019662460556326,169.20878084659563,0.002724934172962884
0.002818265622432,172.41083750123,0.0089479933512216,34.75802484024797,172.89673703749443,0.00281430175760893
0.0029083384571204,175.993136322383,0.00923397460135727,35.480216282592416,176.50498392893863,0.0029041174229800454
0.00300217402738,179.524166136289,0.0095319025369315,36.19207189307586,180.06312892515044,0.002997676502254995
0.0030892472523591,183.009986396948,0.009808360026240142,36.89481325762471,183.57534949457906,0.003084485332710262
0.0031784643260123,186.492601989252,0.010091624235089051,37.5969085610332,187.08536207174004,0.00317342368644739
0.0032671099475344,190.032538987982,0.01037307408342172,38.310559859977175,190.65339618646485,0.003261784539805579
0.0033509281284147,193.53648587021,0.010639196807716671,39.016955551434336,194.185012724587,0.0033453262795275574
0.003438551033795,196.898034960037,0.010917399532299124,39.69464384794346,197.57507890170106,0.003432652734390775
0.0035254316872391,200.252340510795,0.011193245606984143,40.37087184697627,200.95831645747555,0.003519231919913034
0.0036187658877068,203.598668440827,0.01148958169346909,41.04549155767072,204.33544435696317,0.003612233908158506
0.0037216745566546,206.87884521541,0.011816316717378355,41.70677519542665,207.64878094995828,0.0037147662608821774
0.0038230813175656,210.106372837466,0.012138283183270778,42.357444764033154,210.90962658616243,0.0038157919149310916
0.0039303668991931,213.258870931509,0.012478914904938094,42.992988379792216,214.09705653877748,0.003922663186226595
0.0040472776734681,216.322655604866,0.012850106613261216,43.61064736994098,217.1981734591609,0.004039109477073724
0.0041631342698874,219.260943103904,0.013217951306892496,44.203006129747045,220.1737558501877,0.004154492402945159
0.0043072331439785,221.880791664039,0.013675465232131737,44.73116759947026,222.83648396390652,0.0042979835658482485
0.0044635212589434,224.160988984658,0.014171679997145295,45.19085537930705,225.1615363244168,0.004453589291327708
0.00464479550617,226.118518152289,0.01474722573208975,45.58549325950146,227.16879242926456,0.004634041730059579
0.004857488586741,227.636232865147,0.015422526262902672,45.89146454561364,228.74197326821817,0.00484572905487524
0.0050983863826042,228.849173693571,0.016187376764768335,46.13599341662392,230.01593520440053,0.005085433617564075
0.0053624651612716,229.832010339216,0.017025826887037326,46.33413328438594,231.06447648760505,0.005348138340198563
0.0056553313819136,230.484538413421,0.01795567713757568,46.46568294414568,231.7880048565563,0.005639400031881137
0.0059687160671064,231.035880688001,0.01895067351306282,46.576833546701,232.41486826114155,0.005950973845214164
0.0062860921151145,231.500408566331,0.019958342465488534,46.67048236697233,232.9556414592656,0.006266417047883277
0.0066098441522906,231.674674649536,0.020986255183522654,46.70561440934647,233.20600814300207,0.006588094919187682
0.0069448269062517,231.880178209897,0.022049825427349144,46.747043927115236,233.49054591055554,0.006920822668641322
0.0072819425114344,232.061815563992,0.02312016747380422,46.78366201770079,233.75167636402807,0.007255557181605588
0.0076267115669757,232.284217188104,0.02421480922514785,46.828498185121774,234.05578191415842,0.007597775235221338
0.0079764005352239,232.460565508272,0.025325071699335882,46.864050006467636,234.31476408741062,0.007944757207671157
0.008322435849528,232.643556871351,0.026423733822251397,46.90094106526436,234.57971794921883,0.00828799533433875
0.0086740489604475,232.816668578806,0.02754010544942081,46.93584038548729,234.83613176086686,0.008636645534901156
0.0090225843987832,233.000155482353,0.028646705466136655,46.97283134524237,235.10241905012214,0.008982124073190677
0.0093766207989148,233.223738013822,0.029770771036554487,47.01790558358652,235.41058856648303,0.009332933172649983
0.0097350754480748,233.409432331819,0.03090886454763749,47.05534155809472,235.68169076586156,0.00968799490954355
0.0100845493189803,233.515228701261,0.03201844408776245,47.07667010617423,235.87012454183184,0.010034039546507834
0.0104315267177993,233.628690530734,0.03312009732901277,47.09954401099597,236.0657944580498,0.010377493782130993
0.0107851092340526,233.743103149591,0.034242721818117,47.12260959495755,236.26404804976576,0.010727364759413542
0.0111365592636513,233.953752138708,0.03535857566209288,47.165076431163534,236.55919196435428,0.011075004372375708
0.0114946127191238,234.133202117699,0.03649539538321806,47.20125354692812,236.82447260073027,0.011429051579965932
0.0118543800024214,234.269448469727,0.03763765650768794,47.22872081149696,237.0465675348448,0.011784667233403032
0.0122022725147767,234.427609852634,0.038742215234416025,47.26060614629101,237.2881594330436,0.012128424919581087
0.0125583073808103,234.51632372945,0.039872625934072696,47.27849086385712,237.46145180866202,0.012480105877061299
0.0129038946009641,234.66106842109,0.04096986535806102,47.30767139369174,237.68911011494535,0.012821348703680608
0.0132545639866778,234.7780550619,0.04208324065770201,47.33125590047904,237.88993581538574,0.013167490820777932
0.0136083934660123,234.953827775446,0.04320664925458905,47.366691679529914,238.15117191015995,0.013516630837006107
0.0139576606327267,235.162428478935,0.04431557250890727,47.408745581353294,238.44474584921184,0.013861149497163244
0.0143080623512336,235.320319938857,0.045428097965166676,47.44057649967357,238.68729774905438,0.014206668053259779
0.0146639176159909,235.410779032814,0.0465579384307711,47.458813053015305,238.8628233024674,0.014557442013590039
0.0150235183522403,235.467752791572,0.04769967076836295,47.470298962780916,239.00530689699696,0.014911783015696522
0.0153829323088251,235.558986228328,0.04884081008051969,47.48869162363092,239.18257416821382,0.015265814554772647
0.0157411831068249,235.70753064132,0.04997825636416905,47.518638177290114,239.41784604080254,0.015618575667691186
0.0160982894512405,235.895652532884,0.05111206900768859,47.556563550629406,239.6931690276476,0.015970086062991322
0.0164612707538737,236.062585812229,0.05226453464354899,47.59021729974536,239.94847595214364,0.016327252773968518
0.0168224121403936,236.242343573059,0.05341115854574968,47.6264564643287,240.2165096416575,0.016682482487712823
0.0171851671758845,236.384701256361,0.05456290578343328,47.65515577328238,240.44701186527308,0.01703917244602532
0.0175527924381452,236.480462779286,0.055730115991111,47.67446129630406,240.63135525812731,0.01740052144875444
0.0179174588430933,236.617271935866,0.056887931826821225,47.70204202227059,240.85685216734188,0.017758833154484496
0.018279917896936,236.733765909832,0.0580387393227718,47.72552720742213,241.06123971409616,0.018114848796004848
0.0186281588840957,236.83469715808,0.05914440445700385,47.74587494706893,241.24649152600742,0.018456779779069205
0.0189794875639953,236.917480665903,0.06025987301568508,47.76256410224605,241.4140530438946,0.018801624071338653
0.0193238821233829,236.958276606599,0.06135332574174071,47.770788563890356,241.5372304119049,0.019139546843568386
0.0196731407383855,237.031542064068,0.06246222184437396,47.785558880116106,241.69469695053093,0.019482125684539938
0.0200216148649275,237.128216684771,0.06356862719614481,47.805048483649834,241.87590651284054,0.019823818115699263
0.0203689664997308,237.215438861929,0.06467146863664529,47.822632474564884,242.04727218932658,0.02016429374946403
0.0207250015410224,237.327789435213,0.06580187989274612,47.845282350138945,242.2464082369852,0.02051316063210367
0.0210792499574376,237.416775804551,0.06692661861486437,47.86322200219748,242.4213433658241,0.020860156108981426
0.0214333602842106,237.50760962514,0.06805091890236865,47.881534100428226,242.59819579247724,0.021206896029748668
0.0217836282032316,237.608037046544,0.06916301954526033,47.90178026858327,242.7840021836656,0.0215497552800641
0.0221431558059707,237.754829172368,0.07030451968395697,47.93137356114939,243.01947139835366,0.02190155614618111
0.0224956255126276,237.882774430934,0.07142361100259262,47.957167325276295,243.23409624043717,0.022246330698409072
0.0228562401484771,237.972613582358,0.07256856247141479,47.97527889820338,243.41177278715713,0.022598949380446428
0.0232142167771675,238.103746313149,0.07370513826750681,48.00171525673084,243.63113829551813,0.02294886561244245
0.0235743812466972,238.205281508943,0.0748486604582636,48.02218475220291,243.82082363021166,0.02330079689991885
0.0239341819307758,238.295267990607,0.07599102763021316,48.04032602690637,243.9986702879372,0.023652249093333598
0.0242957172359522,238.404750048708,0.07713890222414824,48.062397609819534,244.19696444359926,0.024005271289795047
0.0246591202283209,238.480924586589,0.07829270672491885,48.077754396656346,244.36165437813082,0.02435999164725194
0.0250279370259023,238.605775149928,0.07946370005723981,48.102924270225486,244.57758546439703,0.0247198678539701
0.0253938836491127,238.649033649422,0.08062558058593282,48.111645183723475,244.70925944288862,0.025076815505820048
0.0257626239842854,238.651973944383,0.08179633115010615,48.112237947187616,244.80027501221963,0.025436359341478306
0.0261224169462191,238.723173448758,0.08293867380424563,48.12659176726961,244.95919972031103,0.025787054393534434
0.026478340975125,238.757937257686,0.08406873259602188,48.133600151149494,245.0798513309125,0.026133857376140462
0.0268351410054524,238.859201922322,0.08520157269231136,48.15401510754012,245.26902228635734,0.026481393236640838
0.0271952612380906,238.921991150732,0.08634495443093765,48.166673415987574,245.41953711560092,0.0268320406622434
0.0275625305607967,238.9730736157,0.08751103453052951,48.176971640925125,245.55977626044026,0.02718952253001704
0.0279361277098653,239.085074351888,0.08869720547882232,48.19955098934062,245.764185522505,0.027553032524712754
0.0283007203568174,239.185282511231,0.08985478713289524,48.219752954264166,245.9543983050477,0.02790765378453076
0.0286606134159406,239.243106056816,0.0909974475956114,48.23141018105411,246.0999602319393,0.028257580695539432
0.0290130075777833,239.297173304699,0.09211629905946198,48.24231013822731,246.23990400713032,0.02860009776111529
0.0293662028261916,239.289004930086,0.09323769397315831,48.24066339390534,246.3160143829405,0.02894327578204508
0.0297251060945207,239.320566032022,0.09437721185010323,48.247026112055636,246.43439524792458,0.029291879333921415
0.0300868257261095,239.394806408193,0.09552567168039766,48.261992971891715,246.59743622833204,0.029643095510232583
0.030443943854954,239.453854892959,0.09665952173947895,48.27389714642053,246.74377460717253,0.029989722833339914
0.0308105343903833,239.566224304444,0.09782344668946696,48.296550819775916,246.94738769715036,0.03034541936975832
0.0311672583746372,239.632944741503,0.09895604533947311,48.31000165988701,247.1016466453366,0.030691421144427664
0.0315372720991735,239.676794705766,0.10013083891487586,48.31884181268243,247.23554699625953,0.031050186758250383
0.0318951685614785,239.788466526056,0.10126716018269423,48.34135485165289,247.436560085003,0.03139708104840643
0.0322646645526563,239.837021904927,0.10244030995468376,48.35114361603329,247.57528296399758,0.03175509207952594
0.0326330803142433,239.893732232961,0.10361002999772247,48.36257641816495,247.72220366380282,0.03211192889278916
0.032999768762482,239.914359561065,0.10477426582088034,48.3667348875107,247.8314779493791,0.03246696628702329
0.0333719969545832,239.944602217012,0.10595609033080165,48.37283180694962,247.9520327514668,0.032827238530675665
0.0337339235648739,239.972905709015,0.10710520731847462,48.37853779093743,248.06813336784361,0.03317741566518673
0.0340997305160512,240.028957201766,0.10826664438846255,48.38983777187603,248.21387995839498,0.033531222611186656
0.0344657067197038,240.035008658274,0.10942861883505957,48.39105774550804,248.30798486915162,0.03388506803554061
0.0348341107841778,240.067596115259,0.11059830173976451,48.39762737683622,248.4301373540292,0.034241134435634056
0.0352104816024387,240.111015978615,0.11179327908774286,48.406380821288785,248.5654404892729,0.03460476990879486
0.0355798656901269,240.159599850454,0.1129660735661529,48.41617532985152,248.70444615732777,0.03496152653757565
0.0359576024046135,240.192993929091,0.11416538763464786,48.42290757610475,248.829758105167,0.03532621867999739
0.0363194847359552,240.241174702965,0.11531436403665775,48.43262082011775,248.96661038053728,0.0356754792468066
0.0366885426596295,240.320621918298,0.11648612294432366,48.44863737872888,249.1376353075362,0.03603153954439946
0.037055401307629,240.350575037637,0.11765089915172207,48.454675927587616,249.256862050176,0.03638535241786799
0.0374289300464441,240.361289838291,0.11883685289746,48.45683603139946,249.35775574152146,0.036745469616350813
0.0377969937278493,240.357558749416,0.12000545508592153,48.45608384388227,249.44235188990885,0.03710019117321644
0.0381667491525121,240.361081584187,0.12117942855922591,48.4567940473721,249.53488269103715,0.03745641649732534
0.0385390429039785,240.420582915581,0.12236146122013172,48.468789515781125,249.68616207556408,0.03781495910541034
0.0389071299422356,240.408817341678,0.12353013756659803,48.466417576082286,249.76243443724988,0.038169324043400295
0.0392764380223909,240.390512327364,0.1247026907210911,48.46272728519659,249.83219538596052,0.03852473834821504
0.0396460668627554,240.366441911353,0.1258762622892484,48.45787468932877,249.89602593893312,0.03888033490690434
0.0400195813488212,240.400192182508,0.1270621707825073,48.46467874399361,250.0209072298281,0.039239541196052885
0.0403975848759515,240.421004106734,0.128262331981146,48.46887442791757,250.13343202609724,0.039602933247826835
0.0407648422038254,240.478103058183,0.12942837399714563,48.48038557652969,250.2811549828251,0.039955868056669654
0.0411243893221827,240.461038521906,0.13056993609793008,48.47694536601625,250.34985188689723,0.040301272717481865
0.0414917076210792,240.509033954644,0.13173617169692645,48.48662124525623,250.4881644717183,0.04065401972951591
0.041869819835041,240.621456900677,0.13293667797625516,48.50928571117648,250.6962339495534,0.0410170025465932
0.0422654737897612,240.779213224256,0.1341928792824918,48.54108938601001,250.95586074990513,0.04139668419267792
0.0426617840218011,240.849767014709,0.13545116426921847,48.55531303016534,251.1248477567916,0.04177685116044926
0.0430529486222562,240.838871419022,0.1366931118756634,48.553116478074834,251.20769497646734,0.042151940427374406
0.043439248579512,240.709806161761,0.13791961423995058,48.52709692221102,251.16605926714792,0.042522226941925347
0.0438229339707835,240.600802600041,0.1391378153572376,48.50512180416827,251.14463568570008,0.04288987159988985
0.0442017809442029,240.583369510102,0.1403406544978442,48.50160729323656,251.2175829080057,0.04325274755137685
0.0445833616911053,240.528029657373,0.14155217336925932,48.4904507789264,251.25157780043656,0.04361810896970429
0.0449633069578982,240.506751613114,0.14275849959132678,48.48616112520378,251.32073051134145,0.04398177184135096
0.0453487380127083,240.53845656349,0.14398224319034883,48.49255284319958,251.4465720121689,0.044350550330768776
0.0457357513419887,240.469123652654,0.14521101051081411,48.478575328375044,251.4671596974577,0.044720705946832674
0.0461191352131582,240.459093793167,0.14642825430177728,48.47655330870247,251.54885925304757,0.045087255154357735
0.0464952331428237,240.432685372467,0.14762236522846525,48.47122937108935,251.61165913401504,0.04544670784607409
0.0468766023168172,240.444244653628,0.1488332123558946,48.4735597221714,251.71545388962363,0.04581106660141098
0.0472487547505459,240.422297663187,0.15001479633298323,48.46913520889851,251.78195184203764,0.046166491778218424
0.047632939389643,240.394556778079,0.1512345825621165,48.46354264646073,251.84525613068934,0.04653327587345299
0.0480135496341938,240.380063238087,0.1524430200885653,48.46062074879834,251.92156333543952,0.046896514855532354
0.0484014126913999,240.327868011699,0.15367448529519467,48.450098191158524,251.9600763325775,0.04726653993988042
0.0487781054843452,240.286821594393,0.154870484912796,48.44182323342962,252.00755752462234,0.0476257774717481
0.0491626961601076,240.262369670606,0.15609156030834162,48.436893725594174,252.07431554942949,0.04799241382275394
0.0495445808440878,240.263293168166,0.15730404417997876,48.437079902702266,252.16703732040295,0.04835633755083088
0.0499225976063044,240.220215022778,0.15850424740001648,48.42839534859205,252.2126321542601,0.04871644488680814
0.0503059072913898,240.20337110175,0.1597212556501626,48.42499961411281,252.28701961947397,0.04908146201560859
0.0506988555504705,240.222930475679,0.16096886637274382,48.428942783896886,252.4019581277762,0.04945551948621708
0.051092569684846,240.223329635715,0.16221890874938602,48.42902325456014,252.49695684505352,0.0498301657372708
0.0514899660580041,240.253161044161,0.163480642234163,48.43503726650286,252.62378815165306,0.05020817361200058
0.0518802226789848,240.185676800924,0.16471970700577673,48.42143244306628,252.6465631976586,0.050579251064318244
0.0522730367461053,240.156744289385,0.16596689166888431,48.41559964874002,252.71046660844902,0.05095262127385444
0.052664885775454,240.083111190517,0.16721101233706645,48.40075521600823,252.72706081798117,0.051324935373650474
0.053061882017374,240.035258420279,0.16847147540516244,48.39110809752825,252.77198098258575,0.05170199877303908
0.0534536826375277,239.984517658075,0.16971544237415043,48.38087875986792,252.81257390288988,0.05207398807256814
0.053851574910086,239.971983610256,0.17097875033952303,48.37835189582761,252.89485286196563,0.05245161943457594
0.0542475682355377,239.879214563652,0.1722360291478322,48.359649656032246,252.8920786239809,0.05282730701207601
0.0546404199040032,239.819494867254,0.17348333319521014,48.347610165238414,252.92333276796668,0.05319987461663262
0.0550394927255058,239.725008807595,0.1747503894034809,48.32856177561115,252.91935168598243,0.05357820009043891
0.0554329699409023,239.629270364887,0.17599967956236479,48.30926090556122,252.91263250598413,0.0539510807860331
0.0558199957103876,239.56702159062,0.1772284863804806,48.296711552668995,252.93965170815872,0.05431771214676255
0.0562019168773094,239.463942954733,0.17844108608545733,48.27593089967418,252.92227557178765,0.054679376170046146
0.0565885670622201,239.3944663475,0.17966870042254882,48.261924415656004,252.94145616072993,0.05504538519192155
0.0569810664150584,239.343318442971,0.1809148858678104,48.25161299810296,252.98135596717037,0.055416794159133406
0.0573747539772997,239.371669919931,0.18216484387792653,48.25732865585809,253.10556059072246,0.0557891889689323
0.0577755317823432,239.36639688099,0.18343731340893965,48.25626561120758,253.19591775161263,0.05616814814978863
0.0581777978036037,239.384873491699,0.18471450802644174,48.25999049592652,253.31175825894036,0.056548370171212475
0.0585718333066024,239.349476025905,0.18596557074846262,48.25285436682245,253.36861363771692,0.05692067259352899
0.0589756182072438,239.317944937374,0.18724758780799905,48.24649769937459,253.43186868814277,0.0573020429427477
0.0593744315324349,239.258755462586,0.1885138201154808,48.23456510125734,253.4646080573349,0.05767857497998296
0.0597722035021674,239.178928396753,0.1897767461193815,48.21847196478541,253.4751799783141,0.0580539826727098
0.0601782406507752,239.09534685774,0.19106591406621123,48.20162192652038,253.48368417942564,0.05843704554542233
0.0605729628135905,238.979692240411,0.19231915693314983,48.17830595566686,253.4554002516927,0.05880929304595754
0.0609747834810652,238.893185914883,0.193594937552382,48.160866280440416,253.45964620114484,0.05918809260206583
0.0613763112788662,238.80775452233,0.19486978831040017,48.14364331170173,253.46489359969956,0.05956647278956909
0.0617783886271506,238.789781419173,0.19614638389120315,48.140019934105275,253.54182933587902,0.05994522743529408
0.0621839714870664,238.779323283303,0.1974341094714358,48.13791157391389,253.62756991405294,0.06032713897239289
0.0625890975918387,238.74254238809,0.19872038485408786,48.130496545438945,253.68522267294182,0.06070847485769489
0.0629874707842305,238.696822378899,0.19998521973993183,48.12127939158604,253.7317315047785,0.06108331263393226
0.0633904324464138,238.593283932788,0.2012646230173638,48.10040604085007,253.71781538009745,0.061462324912412984
0.0637960047263943,238.475031635523,0.2025523150063019,48.07656637772144,253.6887858808699,0.06184364765667978
0.0641978070167451,238.380132534248,0.20382803727816567,48.057434718904396,253.68361427930776,0.06222128249086812
0.0646002055757296,238.25847759267,0.20510565270294145,48.03290908268227,253.65002422531683,0.06259933485788169
0.065000371654549,238.235375618303,0.20637618000319305,48.02825172464989,253.72076357475382,0.06297514813273514
0.0654053351855854,238.197798197133,0.20766193921423365,48.02067611654202,253.77720502868493,0.06335532317133336
0.0658103031443635,238.213803977873,0.2089477124833541,48.02390288193919,253.89072663082882,0.06373535788614
0.0662133899373699,238.196310268155,0.21022751305114942,48.020376150060045,253.96809544158307,0.06411348388832001
0.0666185438697319,238.182295072501,0.21151387678639877,48.017550686616204,254.04965274578186,0.06449340499772717
0.0670342799206204,238.093237516354,0.21283383874796977,47.99959668329697,254.05364624723205,0.06488309918931658
0.0674581960121066,238.041249342927,0.21417977233843846,47.98911586753408,254.0990826000689,0.06528030470944785
0.0678771403073909,237.962309725118,0.21550992047596612,47.97320164058379,254.11451081020067,0.06567269675535667
0.0682951562917184,237.897569883881,0.21683712122620588,47.96015008859041,254.14482160052066,0.06606406592565119
0.0687073512707923,237.821951491044,0.21814584028476555,47.944905420594466,254.1620678520445,0.06644983522889439
0.0691319919331399,237.748526783119,0.21949407438771917,47.93010299947679,254.18455601880547,0.06684709676239749
0.0695559637981677,237.686132047007,0.22084018505918243,47.91752422067662,254.21862004299513,0.06724357523832057
0.0699736369284386,237.574015970551,0.22216629724779252,47.89492161966308,254.19793390770536,0.0676340097856479
0.070392878010036,237.495100314813,0.2234973876818643,47.8790122234663,254.21306393925488,0.06802575679162381
0.0708082551385627,237.380797334588,0.22481621006493657,47.85596874265294,254.18931739725096,0.06841374195313596
0.0712214224042744,237.30485968062,0.2261280161335712,47.840659711613,254.20604933052053,0.06879951370519649
0.0716342327144248,237.14386054095,0.22743868886829874,47.80820228505552,254.1314790337375,0.0691848036002681
0.0720476567375902,236.996356805513,0.22875131014184888,47.778465531991415,254.07138896869606,0.06957051757240672
0.0724598784932143,236.841530057822,0.23006011421595537,47.74725245965692,254.00303854795874,0.06995496178995214
0.0728764684082809,236.750467776535,0.23138278719629182,47.728894303749456,254.0040057620974,0.0703433297220059
0.073274433047184,236.755370148409,0.23264632492480922,47.72988262191926,254.10348566690988,0.0707141933394658
0.0736881348236412,236.738336659432,0.2339598280650608,47.726448670541494,254.1831431291168,0.07109957665985381
0.0740973035560831,236.767337620995,0.23525893879056384,47.73229526439259,254.31115890886346,0.071480591197042
0.0745158494301954,236.68595201714,0.23658782194087039,47.71588792665543,254.32280677989166,0.07187018750834145
0.074946890868438,236.592661810724,0.23795637850729065,47.69708062104196,254.3245462157256,0.07227125651590265
0.0753630889827916,236.4899070885,0.23927780752036334,47.6763652690416,254.31251699994274,0.07265836174580038
0.0757917062443093,236.459039214107,0.240638667325682,47.67014230556398,254.3806732530342,0.07305686144293111
0.0762131440201814,236.45235063414,0.24197673226407593,47.668793887842625,254.47312768693016,0.07344853136059695
0.0766488208307911,236.455235144308,0.2433600061377617,47.669375405092495,254.57925009738668,0.0738532733493268
0.0770779022225939,236.376562895152,0.24472233955673564,47.65351507966265,254.59597249769732,0.07425172816988203
0.0775119715159764,236.276134865574,0.24610050956322505,47.63326878889971,254.5903639011794,0.07465465338970774
0.0779428496613732,236.158552578796,0.2474685476748599,47.60956419988527,254.56542313869258,0.07505445592502674
0.0783744301995557,236.032579781721,0.24883881588358933,47.58416808399495,254.53149873064456,0.07545475002643393
0.0788023991206164,235.970222889258,0.2501976172079571,47.571596934474414,254.5652425739581,0.07585153615991977
0.0792376050469448,235.884079856683,0.2515793960240497,47.5542304991073,254.57496941322884,0.07625487060357033
0.079669650568808,235.814794155382,0.25295114055596535,47.54026250172501,254.60207640469665,0.07665511524261814
0.0800943841551037,235.68588889359,0.2542996696924542,47.51427520094774,254.56300501857027,0.07704843005381268
0.0805167565116193,235.608410080184,0.25564070192439126,47.49865547216509,254.57883506669995,0.07743940495341058
0.0809427584113918,235.448883041754,0.25699325795616895,47.4664948212176,254.50676510003473,0.07783358481414554
0.0813712226803525,235.352674252201,0.2583536320101192,47.447099129243725,254.50360911719332,0.07822988644130524
0.081801955790838,235.257081467251,0.25972120963591067,47.4278276237978,254.50157084491664,0.07862812835782412
0.0822319805886288,235.170105859184,0.2610865383688964,47.41029334121149,254.50860943922217,0.07902555724858384
0.0826616726974494,235.119455274033,0.2624508108144018,47.40008218324505,254.55482273069768,0.07942252096438675
0.0830800073953995,234.94170979491,0.2637790234803934,47.36424869465385,254.4606687821589,0.07980884100153442
0.0835004249428157,234.870002693011,0.26511384919343983,47.34979254291102,254.4817477241977,0.08019693418876898
0.0839227291886977,234.75790274838,0.2664546651741152,47.32719319407341,254.45942664563893,0.08058661744044136
0.0843481813746934,234.699158578858,0.26780547586465153,47.31535036949777,254.49560577515544,0.08097905197376751
0.0847704000610401,234.726733569205,0.2691460201938023,47.320909487551724,254.62461267888767,0.08136835175229754
0.085201178994522,234.674089114827,0.2705137433076073,47.31029636554913,254.66859818687578,0.08176538823268156
0.0856331375075741,234.635231410609,0.27188521158654777,47.30246265237878,254.72778244611516,0.08216335367432719
0.086075149558865,234.56590424702,0.27328859984939635,47.28848629619924,254.75619953649266,0.08257041760646465
0.0865275480181548,234.475700768746,0.2747249649576415,47.2703012749792,254.7643082261042,0.0829868752186484
0.0869748777444964,234.395309408334,0.27614523683877606,47.25409437672013,254.78181278800722,0.08339849632139501
0.0874230582924144,234.317530780172,0.2775682100784157,47.23841420528268,254.8022859325016,0.08381073048225143
0.087863314768079,234.221169247629,0.2789660243886508,47.21898772032201,254.80061756658094,0.08421551073291451
0.0883041046580614,234.120070599389,0.28036553228934497,47.19860623283683,254.7938338161502,0.08462061733645605
0.088745789038751,233.987860715787,0.2817678801980344,47.17195272030266,254.75329804049892,0.08502638147445626
0.0891874367587136,233.858903424679,0.28317011170891565,47.145954930415286,254.71617958432967,0.0854319473759126
0.0896206681657297,233.736088056015,0.2845456214261918,47.12119535209263,254.6836724420389,0.0858296248140922
0.090055934423365,233.641155626785,0.28592759179418387,47.10205697435986,254.68192821650996,0.08622901090917068
0.0904994659300708,233.585792830678,0.2873358043279748,47.09089583466469,254.72518233070653,0.08663581691166965
0.0909449448215004,233.542552728459,0.2887501998082637,47.082178630057335,254.78206729982105,0.08704424253592724
0.0913931750491587,233.505776516189,0.2901733307810789,47.074764545663704,254.84661082432282,0.08745502235953012
0.0918426026755165,233.396456414919,0.29160026349476487,47.05272561324767,254.8321944273079,0.0878667301899821
0.0922891888939605,233.243540915969,0.2930181747383246,47.02189784865935,254.76939812185907,0.0882756672572335
0.0927339111054441,233.110920240995,0.294430167759785,46.99516152058459,254.7282075963317,0.08868273134513688
0.0931819318084066,233.019069416039,0.29585263349169094,46.976644394273464,254.7322364524227,0.0890926471346109
0.0936331847636831,232.9529925947,0.2972853616246938,46.96332330709152,254.76512319157243,0.08950535048411837
0.094089997890413,232.868754455444,0.29873574330206126,46.946340898217514,254.77937507089985,0.08992296559830742
0.0945391966151673,232.764247734935,0.30016194925315615,46.9252723433629,254.76959271652956,0.09033344968779086
0.0949797258515026,232.589376503038,0.30156062957852076,46.89001830301247,254.6806517192685,0.09073584789294843
0.0954231446633555,232.487470488132,0.3029684843061537,46.86947405040742,254.67215601693863,0.09114072210479233
0.0958611218485244,232.387352216959,0.3043590618690649,46.84929020693893,254.66426450388485,0.09154046685511469
0.0963076743944576,232.32798631079,0.30577686620240285,46.837322040255266,254.70295436912957,0.09194787394244763
0.0967622473984586,232.295500646989,0.307220135490106,46.830772930432985,254.77293535014178,0.09236242799382006
0.0972096203213808,232.246518664214,0.308640544520384,46.82089816270555,254.82311456452473,0.09277024810829367
0.0976663056758014,232.136853819309,0.31009052052066943,46.7987897299727,254.80880274304445,0.09318638585494415
0.0981216776596216,232.01423495178,0.3115363265692986,46.77406976627884,254.77986092616229,0.09360115448816786
0.0985727116016708,231.834271506383,0.31296835933530476,46.73778913568682,254.68680429096514,0.0940118023694501
0.0990354689804461,231.710837259491,0.31443761401291637,46.71290479151338,254.6584286953365,0.09443294876825205
0.0994931044351774,231.651044278082,0.31589060658168827,46.70085052646133,254.69872581895913,0.09484925944701664
0.09995320471434,231.58189474702,0.3173514249680295,46.686909980999225,254.72924728080358,0.09526763773064174
0.10041637625054,231.518285015377,0.31882199459546445,46.67408625910001,254.7665122323608,0.09568863204636739
0.100874751080769,231.43839009249,0.32027733468144154,46.65797944264598,254.78468008360386,0.09610509203311149
0.101335686507938,231.348730854245,0.32174080466270316,46.6399041402158,254.79261331810008,0.09652370364808929
0.101802831102592,231.241364513104,0.3232239887507296,46.618259085841764,254.78239008856445,0.09694777557812981
0.10226577050337,231.097745673838,0.32469382134819974,46.589305527845745,254.7311346967649,0.09736785270934832
0.102726765177383,230.922449480107,0.326157479438191,46.55396581518957,254.644365722036,0.09778598988965144
0.103193232543738,230.776170242924,0.3276385133263681,46.52447592097348,254.5907092443553,0.09820891309066487
0.103652135947566,230.690491825151,0.32909553163352206,46.50720315195044,254.60205404562242,0.09862480395188665
0.104104141934311,230.589088587988,0.3305306506414374,46.48676025933838,254.5943677948553,0.09903427486820914
0.104556835253394,230.48933915936,0.33196795192952594,46.46665077452697,254.58857502150886,0.09944420045669737
0.105010382521848,230.384826706808,0.3334079645068674,46.445581064092494,254.5776254865196,0.09985473087294827
0.105465580796919,230.303396614998,0.3348532190302178,46.42916475758359,254.59247809850194,0.10026658631861608
0.105934298228073,230.221062624048,0.3363413968741318,46.41256622500808,254.60936933044778,0.10069049647852789
0.106405494836822,230.141642411657,0.33783744610690986,46.39655511019005,254.6299777550283,0.10111646776680012
0.106869238776492,229.965149467626,0.33930983311536206,46.3609741326734,254.54134993635338,0.10153552459640512
0.107326419025637,229.750019130539,0.3407613804063975,46.31760385671666,254.4082659548913,0.1019484783966087
0.107777912864439,229.540698819944,0.3421948733445938,46.27540488210071,254.28011625620235,0.10235612858134667
0.108228766050857,229.434357176576,0.343626332211471,46.253966406797716,254.26575454346838,0.10276303456852487
0.108688357157793,229.410985887399,0.34508553397599273,46.24925475489964,254.34528905745003,0.10317765639512247
0.109151878680357,229.429225173269,0.34655721481013346,46.25293179493103,254.47185612510995,0.10359565001055307
0.109622998352893,229.392038184832,0.3480530197704353,46.24543489806213,254.53868120893458,0.10402031650961326
0.110096539545336,229.32260982103,0.3495565130564418,46.231438139919646,254.57023560183066,0.10444698410571436
0.110581108310081,229.206979180975,0.35109501888450717,46.20812700288456,254.55294097121285,0.10488339933500604
0.111059678164375,229.096625624221,0.35261447817189057,46.18587972584295,254.54002313459125,0.10531422493436471
0.111535317106441,228.980408217545,0.3541246318129502,46.16245029665707,254.5198106592512,0.1057422281921234
0.112011913343638,228.847974829865,0.3556378248660506,46.135751725700786,254.48167435537485,0.10617090920952546
0.112485587688284,228.693367511483,0.35714174091030165,46.10458289031497,254.41807535642488,0.10659678008740721
0.112955925811733,228.52770399377,0.35863506445225224,46.071185125144034,254.34126237201593,0.10701947205895415
0.113432372456781,228.375789367363,0.3601477825502797,46.04055913646039,254.2809969669931,0.10744747166054353
0.113896965088865,228.228422410339,0.36162286415714634,46.010849957924336,254.22294706989612,0.10786464628397302
0.114364741382632,228.021987506968,0.36310805388985656,45.96923268140475,254.09966313775615,0.10828450387904826
0.114826902470782,227.793696079093,0.36457541534473287,45.92320912954515,253.95054060222597,0.10869914843959633
0.115284021428612,227.643284616432,0.36602676803584305,45.89288617867269,253.88691791823234,0.10910910021314546
0.115751342845075,227.544928119947,0.3675105135331131,45.87305750898132,253.88355910741691,0.10952802806232344
0.116215629309179,227.51889533814,0.3689846230566433,45.86780930016902,253.96014693959117,0.10994406152213096
0.116679686109475,227.438221526351,0.3704580033975831,45.85154545971236,253.97564182334287,0.11035971630341232
0.117147400910708,227.335198082286,0.3719429978914979,45.83077593338886,253.96692567314682,0.11077847280501044
0.117615457780283,227.265699459141,0.3734290784523985,45.816765010962825,253.99565873878407,0.11119736009284835
0.118094655471969,227.204279489687,0.3749505311235016,45.804382745120904,254.03589059777855,0.11162603615078968
0.118577659641857,227.087495234099,0.37648406936289597,45.78083903919436,254.01499895288984,0.1120579314929301
0.119064757850894,227.000050632375,0.37803060617658846,45.7632102074868,254.02775669305944,0.1124932988357397
0.119551208188367,226.833266051661,0.37957508599806516,45.72958643601486,253.95145706545037,0.11292789802783794
0.12003119749502,226.531301871949,0.3810990520466885,45.668710457384925,253.7221253057449,0.11335653982533024
0.120496865748821,226.252328659578,0.38257754875250666,45.612469457770935,253.51502513142933,0.11377221706512528
0.120964751509159,226.041455710253,0.3840630860415798,45.569957471187,253.3845042310123,0.11418969980364842
0.121442490261287,225.93130634804,0.38557990657958624,45.547751359764874,253.3689668189317,0.11461579435994215
0.12192035120175,225.948291852059,0.3870971150655562,45.55117563737509,253.4959869480975,0.1150418163469862
0.122413661872552,225.927315568713,0.3886633764453526,45.54694681865254,253.58390558451478,0.11548142174963372
0.122908897055513,225.826324308861,0.3902357481512538,45.52658698066638,253.58238875576367,0.11592254784888618
0.123399696211218,225.638443695269,0.39179403547061714,45.48871024896623,253.4821591008372,0.11635953069708987
0.123889398342225,225.456710295239,0.3933488397365643,45.45207279552018,253.38840648593344,0.11679534657849533
0.124378207947568,225.298628370312,0.39490081023352835,45.420203479454905,253.3208680200565,0.11723017881259193
0.124872018433581,225.121782867606,0.39646865852661967,45.38455142610937,253.2331942876503,0.117669267792693
0.125356490424061,224.898620462984,0.39800685709639366,45.33956188533758,253.09112222543658,0.11809986583734366
0.125830340017872,224.589320012817,0.39951132955674357,45.277206914583914,252.84947051441245,0.11852084342516658
0.126293791635873,224.345056618697,0.4009827884438968,45.22796341432932,252.67844445383685,0.11893241188005697
0.126759264621863,224.19450582329,0.402460665174415,45.19761237397526,252.6132365137122,0.11934560498380524
0.127240943556571,224.143256414461,0.4039899957921129,45.18728049315534,252.6634558524795,0.1197730041830536
0.127729305132097,224.096790540236,0.4055405437944079,45.17791297291157,252.7205178782734,0.12020614655683437
0.128225834600354,224.018481264742,0.40711702485612394,45.162125822971994,252.7434379908173,0.12064634101596153
0.128729129250599,223.877638680608,0.4087149853706518,45.133731958010564,252.69721216664288,0.12109233543467941
0.129219217697851,223.714654703099,0.4102710161906769,45.10087438814476,252.62288737137834,0.12152643611338676
0.129723930336641,223.479236171136,0.4118734788188352,45.05341401210102,252.4698410358862,0.1219732934392364
0.130217247734048,223.283488305261,0.41343976155560236,45.01395124234062,252.35884961682956,0.12240986887759667
0.130709641376775,223.008648671557,0.41500311137126056,44.95854357218589,252.15802916333544,0.12284543683238833
0.131207834007551,222.745109251941,0.41658487297397445,44.905414025191305,251.97101257266348,0.12328594153183357
0.131695643598444,222.539518084064,0.41813366842505967,44.863966845747306,251.8470031442324,0.12371707755091386
0.132188817457934,222.305308374661,0.41969949542894047,44.81675016833166,251.69158420332877,0.12415276574593882
0.132690226073051,222.139012978993,0.42129146778193693,44.78322501656499,251.61468883081997,0.12459553431209303
0.133185484033318,221.879914904678,0.42286391180578464,44.730990844783086,251.43109876852895,0.12503267917925842
0.133689353215359,221.636814476772,0.42446369645876475,44.681981798517235,251.26729685288416,0.1254772288139004
0.134184155089107,221.393401736127,0.4260346924079147,44.632909790003204,251.10088829039245,0.12591358637951186
0.13468312045064,221.143824008026,0.42761890743078196,44.582594920018046,250.9281642938141,0.12635342292258012
0.135180345062566,220.94391195711,0.429197595573647,44.542292650553385,250.8111862149453,0.12679153263925122
0.135680204764663,220.627348369455,0.430784650127805,44.478473431282126,250.5621121729073,0.12723177077735112
0.13617221077321,220.326096240283,0.43234676920494175,44.41774100204105,250.32838785635334,0.12766490280025347
0.136660787534797,219.955509573408,0.43389800042298043,44.34303072999906,250.0148027343275,0.12809483035716268
0.137158812531122,219.651560114932,0.4354792297863123,44.28175451917029,249.77870727090445,0.12853288182287656
0.137652947556146,219.37074398221,0.4370481084907635,44.22514198681353,249.5677734989459,0.12896732219413343
0.138156189004847,219.131935471164,0.4386459000903892,44.17699819098667,249.40636856511608,0.12940957497255728
0.138643414596349,218.732020736148,0.440192841343408,44.09637538040744,249.05777497256696,0.12983756661325202
0.1391245355173,218.160302811219,0.4417204002674275,43.98111704674175,248.51175360814338,0.13026001608013685
0.139600350806082,217.73736438908,0.4432311138093103,43.89585266083853,248.13357684138725,0.1306776314742135
0.140094496231276,217.416966094843,0.4448000255343013,43.83126036472035,247.87588643203244,0.13111115040204313
0.14059773608301,217.247205625764,0.44639781206355666,43.79703665415403,247.79167090710655,0.13155245489089162
0.141118775326229,216.962913700558,0.448052111660777,43.739723402032496,247.5804543731911,0.1320091630311627
0.141646849410683,216.555132199797,0.4497287468789185,43.65751465147907,247.2294843996122,0.13247182471500038
0.142164963745763,216.071972519867,0.45137375989279754,43.56010966000518,246.78983665962937,0.13292555241794313
0.142693857106671,215.518531253122,0.45305299631368046,43.448535900629395,246.2717017555946,0.13338850738525007
0.143216012934807,214.900444853092,0.45471084106801224,43.32392968238335,245.67762974286822,0.13384535465124325
0.143739198086093,214.312029136229,0.4563719539233453,43.20530507386376,245.11706834447395,0.13430289326668418
0.144254862812719,213.717037473291,0.45800918943038277,43.085354754615466,244.5467593947413,0.13475365032429173
0.144778268029832,213.146190864562,0.45967100099471664,42.97027207829569,244.00512721508926,0.13521096587746798
0.145301945886408,212.418005489565,0.46133367818934534,42.8234699066963,243.2827550285085,0.13566831043904415
0.145810946126419,211.611050739966,0.4629497539513803,42.660787829177146,242.4662582591661,0.13611263620767788
0.146336787375024,210.845697686069,0.4646192999157012,42.506492653511515,241.70017971729388,0.136571455899048
0.14684299414344,210.070592525914,0.46622650640542196,42.35023145322427,240.91798731390577,0.13701294485749574
0.147368498829632,209.335881576883,0.46789498378408156,42.202113725899615,240.18539619604587,0.1374710584158945
0.147874639828129,208.505595191076,0.4695019814543096,42.03472799052093,239.33828498210602,0.13791209317877123
0.148390643963651,207.630209316377,0.47114029458459195,41.85825019818161,238.44058978314186,0.13836152221282041
0.148914710021384,206.640405546908,0.4728042043178942,41.65870575825666,237.41220161762698,0.1388177663650525
0.149432813530249,205.700017023628,0.47444918295854055,41.46912343196341,236.43834931068884,0.13926861508338767
0.149972789329681,204.638551856563,0.47616360612173714,41.2551320542831,235.32876628287832,0.13973828064277077
0.150524564899903,203.600470218184,0.47791549355719204,41.045854795985896,234.2473424111918,0.14021798176460726
0.151075338538351,202.46267986845,0.4796641998592644,40.81647626147952,233.04979777095787,0.14069658245288374
0.15162532827068,201.115633127245,0.48141041725940903,40.54491163845259,231.60985702052918,0.14117427349689574
0.152180658787184,199.84300684264,0.4831735916493092,40.288350179476225,230.25524727796466,0.14165637184231133
0.152739591505095,198.384698464341,0.4849482030286766,39.99435521041114,228.6858962686459,0.14214136279051975
0.153308492474352,196.947865817378,0.48675446360606756,39.7046897487834,227.14164622188116,0.14263476185253446
0.15387215403473,195.365580761477,0.48854408906026775,39.385701081513766,225.42690349749148,0.143123376883564
0.154435157084148,193.712580277583,0.49033162374216993,39.05245618396073,223.62861304192714,0.14361118286838245
0.155007291633438,192.159815989869,0.4921481509361656,38.73941890355759,221.9459886272384,0.14410665705637302
0.155595051621435,190.429467890982,0.4940142888980561,38.39058072682197,220.05935077772176,0.14461540751478938
0.156187423627817,188.608131677671,0.495895070018319,38.023399346218476,218.06634983966248,0.14512788827428028
0.156769170700846,186.515452741995,0.49774211697518606,37.601515272786195,215.7553255912504,0.14563092156658053
0.157374505949717,184.256497583347,0.49966405639035144,37.14610991280276,213.25377285855143,0.146154082914586
0.157840302250424,182.380706347648,0.5011429596450961,36.76795039968584,211.16773216220656,0.1465564613939755
0.158162357837557,181.175303432421,0.5021654861342435,36.524941171976074,209.83041660522755,0.1468345747094383