File: example/data/02 processed data/test_ID_059.csv
Strain,Stress_MPa,Displacement(mm),Force(kN),True Stress (MPa),True Strain
-1.22234134328337e-05,0.512111917244544,-3.8809337649246996e-05,0.10324176251650008,0.5121056574888556,-1.2223488139403672e-05
-8.12256834927579e-06,0.424352430115232,-2.5789154508950634e-05,0.08554944991123078,0.4243489832836142,-8.12260133749277e-06
-7.25993935254868e-06,0.365591709802202,-2.3050307444342057e-05,0.07370328869612393,0.36558905562856103,-7.259965706064656e-06
-8.25934200196534e-06,0.251259910129953,-2.6223410856239956e-05,0.050653997882198536,0.25125783488842385,-8.259376110545704e-06
-9.2589187243788e-06,0.179313533651433,-2.939706694990269e-05,0.03614960838412889,0.17931187340199872,-9.25896158843889e-06
-1.8003351428977e-05,0.264756846874399,-5.716064078700197e-05,0.053374980329878835,0.26475208036384146,-1.8003513491262132e-05
-2.34500316462758e-05,0.374657734931843,-7.445385047692566e-05,0.07553099936225956,0.3746489491961023,-2.3450306602567727e-05
-4.23748322255435e-05,0.53155638678869,-0.00013454009231610061,0.10716176757659991,0.5315338621759814,-4.237573006414492e-05
-4.56413063856491e-05,0.599643774248394,-0.0001449111477744359,0.12088818488847623,0.5996164057231713,-4.5642347981741866e-05
-4.18720437416395e-05,0.602034063087777,-0.00013294373887970542,0.12137006711849584,0.6020088546911534,-4.187292040011508e-05
-3.12715090890883e-05,0.606721238137012,-9.928704135785535e-05,0.12231500160842161,0.606702265048299,-3.1271998052937726e-05
-1.966231570525e-05,0.613488178403838,-6.242785236416875e-05,0.12367921676621374,0.6134761158055927,-1.966250901113445e-05
-4.27213415823998e-05,0.617582262804102,-0.00013564025952411937,0.12450458418130696,0.6175558788612975,-4.272225416495689e-05
-7.4956961781587e-05,0.637030022303413,-0.0002379883536565387,0.12842525249636805,0.6369822724683775,-7.495977119506442e-05
-0.0001202241803876,0.922016017101403,-0.00038171177273063,0.18587842904764285,0.9219051684814428,-0.00012023140789365725
-0.0001564167732786,2.15013950905622,-0.0004966232551595549,0.433468125025734,2.1498031911721145,-0.0001564290076578732
-0.00016176458677,4.61606546081538,-0.0005136025629947499,0.9305987969003807,4.615318744893608,-0.00016177767207191905
-0.0001616854775213,8.16593749823211,-0.0005133513911301274,1.6462529996435933,8.164617184728298,-0.00016169855002719647
-0.0001372276497661,12.2246477870196,-0.00043569778800736745,2.4644889938631516,12.222970227334569,-0.00013723706634150817
-0.0001034566921818,16.2814613604852,-0.00032847499767721497,3.282342610273816,16.27977693434896,-0.00010346204419452977
-6.07262694704973e-05,20.310679431978,-0.00019280590556882893,4.094632973486765,20.309446040185684,-6.072811338506405e-05
6.00629280937405e-06,24.4152920418353,1.9069979669762607e-05,4.922122875633997,24.415438687228328,6.0062747716307495e-06
8.79840405708903e-05,28.7429987421099,0.0002793493288125767,5.794588546409356,28.745527667277358,8.79801702022976e-05
0.0001807249901207,33.2801978952406,0.0005738018436332225,6.709287895680505,33.28621245867643,0.0001807086613269638
0.0002775843452294,38.1182955773349,0.000881330296103345,7.684648388390716,38.12887661945399,0.00027754582582313104
0.0003787758340931,43.2062669589873,0.0012026132732455925,8.71038341893184,43.222632448792744,0.0003787041166362563
0.0004673156731248,48.5200968118715,0.0014837272621712398,9.781651517273295,48.542771013573216,0.0004672065151617329
0.0005819283726663,53.9604170313632,0.0018476225832155023,10.87842007352282,53.991818129034655,0.0005817591180103247
0.0006821882603345,59.5014399859735,0.002165947726562037,11.995490301172259,59.54203116980493,0.0006819556756948976
0.0007905526364596,65.0454155870764,0.0025100046207592298,13.113155782354605,65.09683741185837,0.0007902403143179339
0.0008980048521674,70.5922302108545,0.0028511654056314947,14.231393610508267,70.65562237610916,0.0008976018870351934
0.001002193119656,76.1622780486406,0.0031819631549077996,15.354315254605945,76.23860735967827,0.001001691259410717
0.001114807318227,81.8021858375346,0.003539513235370725,16.491320664846974,81.89337951295325,0.0011141863819886047
0.0012197474830012,87.4786459591166,0.00387269825852881,17.635695025357908,87.58534781734159,0.0012190041953940509
0.0013241539663854,93.314917129255,0.004204188843273645,18.812287293257807,93.43848044689462,0.0013232780476708495
0.0014226361992008,99.1622270939794,0.00451686993246254,19.991104982146247,99.30329886783667,0.0014216252110552396
0.0015224223164058,105.018575881521,0.004833690854588415,21.171744897714635,105.17845850508019,0.0015212646064178535
0.0016172308122687,110.713674385486,0.005134707828953123,22.319876756113977,110.89272395104169,0.0016159245027315785
0.0017147716590595,116.300857513409,0.0054444000175139125,23.446252874703255,116.50028692779732,0.0017133031167083665
0.0018084050258061,121.727803359022,0.0057416859569343675,24.540325157178838,121.94793653039679,0.0018067718301270981
0.0018956855789456,127.117876285877,0.00601880171315228,25.626963859232806,127.35885181077833,0.001893891034608452
0.0019832413337715,132.393500451142,0.006296791234724513,26.690529690950225,132.6560687135594,0.001981277307008148
0.0020707857882419,137.497563276327,0.006574744877668032,27.719508756507526,137.7822912762775,0.0020686446667112714
0.0021620187206691,142.63828031047,0.006864409438124392,28.755877310590755,142.94666694278527,0.0021596849214012013
0.0022543922286329,147.673777725734,0.007157695325909457,29.771033589507976,148.00669234261176,0.002251854899180937
0.0023387670431569,152.654806771693,0.007425585362023158,30.775209045173305,153.01183080275013,0.0023360363842704454
0.0024251641495712,157.572629134847,0.00769989617488856,31.76664203358516,157.95476862597852,0.002422228184834527
0.0025073390362379,162.387936896306,0.007960801440055332,32.73740807829529,162.79509850950026,0.0025042009061927587
0.0025915119124138,167.162506057739,0.008228050321913814,33.69996122124018,167.59570968349658,0.00258815973563941
0.0026815036084841,171.891423448248,0.008513773956937016,34.653310967166796,172.35235092049194,0.0026779147918679176
0.0027666087391222,176.501931516801,0.008783982746712984,35.58278939378708,176.99024330300733,0.0027627887212058836
0.0028519598027422,181.071621079537,0.009054972373706484,36.504038809634665,181.5880300642732,0.002847900681186808
0.0029353968009822,185.622007416121,0.009319884843118485,37.421396695089996,186.16688166288216,0.0029310969362768783
0.0030151405482705,190.249353266571,0.009573071240758837,38.35426961854072,190.8229818058873,0.0030106041283492688
0.0030991742125534,194.930220910057,0.009839878124857045,39.29793253546749,195.53434362394879,0.0030943816715468097
0.0031827052968495,199.488360563612,0.010105089317497162,40.21685348962418,200.12327322543766,0.003177651211283512
0.0032734946823017,204.01314246304,0.010393345616307897,41.12904952054886,204.6809784000124,0.0032681484626214123
0.0033595268244097,208.286922962571,0.010666497667500796,41.99064366925432,208.98666846743754,0.0033538962214181177
0.0034578054274945,212.461144507981,0.010978532232295037,42.83216673280897,213.1957938065924,0.003451840963656358
0.0035584674912169,216.438547920101,0.011298134284613657,43.63401126069236,217.20873745672085,0.003552151125726242
0.0036661711795719,220.161527672816,0.011640093495140781,44.38456397883971,220.96867752042056,0.0036594671544191615
0.0037945465212678,223.665237001248,0.012047685205025265,45.0909117794516,224.51394514823963,0.0037873653899752726
0.0039467892905934,226.933457405401,0.012531055997634044,45.74978501292884,227.82911594476593,0.003939021150507484
0.0041516975445186,229.977070789121,0.013181639703846552,46.3633774710868,230.9318660292118,0.004143103027945093
0.0044157047151909,232.674452035691,0.014019862470731106,46.90716953039531,233.70187371064947,0.004405984096208659
0.0047288953064818,235.051786556253,0.015014242598079715,47.38644016974061,236.16332184647905,0.00471774920641962
0.0050884851281548,236.990715308992,0.01615594028189149,47.777328206292786,238.19663903935256,0.005075582538950594
0.0054658982522636,238.537282789189,0.01735422695093693,48.0891162103005,239.8411033062861,0.005451014441376647
0.0058563204958783,239.600601963319,0.018593817574413602,48.30348135580512,241.0037798794216,0.005839238908723802
0.0062567848954902,240.309723039885,0.019865292043181382,48.446440164840816,241.8132892852404,0.006237292481185999
0.0066456200637739,240.801869438931,0.02109984370248213,48.54565687888849,242.40214717386863,0.006623635278692917
0.0070402252213075,241.153089099963,0.02235271507765131,48.616462762552544,242.8508611600408,0.007015558540713813
0.0074160982480509,241.468461232995,0.023546111937561606,48.6800417845718,243.25921506530455,0.007388734197814211
0.0077877461147287,241.748534506257,0.02472609391426362,48.736504556461405,243.63121071659944,0.007757578145716372
0.0081539094879574,242.020474512848,0.02588866262426474,48.791327661790156,243.9938875562583,0.008120845977637854
0.0085124346699984,242.259415883979,0.027026980077244918,48.83949824221017,244.3216333348833,0.008476408202253372
0.008861601352199,242.477302970383,0.028135584293231822,48.88342427882922,244.6260401662629,0.008822567793338162
0.0092012302643519,242.66762461377,0.029213906089317277,48.92179312213603,244.90046530554457,0.00915915683312269
0.0095396354466287,242.853741229049,0.03028834254304612,48.95931423177628,245.17047738722403,0.009494420453327242
0.0098784689407493,243.046901558092,0.03136413888687902,48.99825535411135,245.44783282627898,0.009829995831763564
0.0102196124754327,243.291923665085,0.03244726960949882,49.047651810881135,245.77827284334475,0.010167745311419746
0.0105659586564737,243.495913980876,0.033546918734303995,49.088776258544605,246.0686817410182,0.010510529018290958
0.0109106936343269,243.716575911757,0.034641452288987906,49.13326170381021,246.37569280513733,0.010851601452448841
0.0112539519764718,243.869573543411,0.03573129752529796,49.164106026351654,246.6140700125912,0.011191097394272346
0.0115999799893695,244.074194310903,0.03682993646624816,49.20535757307805,246.90545008083097,0.011533216032503962
0.0119534595157846,244.207041560976,0.03795223396261611,49.23213957869276,247.12616054574465,0.01188258118699859
0.0123008042566805,244.416879250493,0.03905505351496059,49.274442856899384,247.42340343918204,0.012225764106774324
0.0126416276357458,244.611828047308,0.040137167743492914,49.313744534337296,247.70411969278112,0.012562389362797084
0.0129782362063639,244.803491526994,0.041205899955205384,49.352383891841995,247.98060906417396,0.012894740540552794
0.0133073077356508,245.060527860158,0.042250702060691286,49.40420241660785,248.32162371825413,0.013219543264594886
0.0136487999930392,245.250063653621,0.04333493997789945,49.44241283256999,248.5974327207094,0.013556494083921882
0.0139922492995265,245.457086056285,0.04442539152599664,49.484148548947054,248.8915827967199,0.013895261450948482
0.0143439620661896,245.663158656918,0.04554207956015198,49.52569278523467,249.18694168575314,0.014242060732268056
0.014693572296354,245.89566943354,0.04665209204092395,49.57256695780166,249.50875522972208,0.014586667697593581
0.0150370445278716,246.107110631155,0.04774261637599233,49.615193503240846,249.8078342123415,0.014925108899543394
0.0153832079517635,246.272072979167,0.04884168524684911,49.64844991260007,250.06052749051742,0.015266086021716092
0.0157177003163228,246.437700668454,0.049903698504324884,49.68184045476033,250.3111345942044,0.015595456528342815
0.0160590796996371,246.581047160465,0.050987578046347785,49.71073910754974,250.5409118492349,0.015931496776351015
0.0163951573846598,246.77235055857,0.05205462469629486,49.749305872607714,250.81822208416023,0.016262207974619317
0.0167323146798987,246.980183140779,0.053125099108678374,49.79120492118104,251.11273328478953,0.016593871682834452
0.0170615696685093,247.164785526109,0.05417048369751702,49.82842076206358,251.38180473396486,0.016917655714265387
0.0173943834571131,247.414926626803,0.05522716747633409,49.87884920796348,251.7185567335631,0.017244832904866496
0.0177294420940464,247.607591616987,0.05629097864859732,49.917690469984585,251.99753607460667,0.017574108829755117
0.0180679326586796,247.842303437808,0.057365686191307726,49.96500837306209,252.32030148629437,0.01790664739371084
0.0184103037848486,248.076991554903,0.0584527145168943,50.01232149746845,252.6441643314601,0.018242885830506005
0.0187383693886637,248.279283002041,0.059494322809007245,50.05310345321147,252.93163191848586,0.01856496895676124
0.0190588763042449,248.463539187797,0.06051193226597755,50.09024950025988,253.19897504729215,0.018879531083981126
0.0193796998969286,248.588965791536,0.06153054717274831,50.11553550357365,253.40654534626384,0.01919430494970201
0.0197061627337178,248.726228370069,0.06256706667955401,50.14320763940591,253.62766790247346,0.019514510043132826
0.020029853686461,248.855865121407,0.06359478545451366,50.16934240847565,253.84041168880643,0.019831895187930527
0.0203570300378737,249.042870875155,0.06463357037024899,50.20704276843125,254.11264407827883,0.020152595499059477
0.0206773845705035,249.25604388912,0.06565069601134861,50.250018448046596,254.41000696513765,0.020466509397784168
0.0209978632471898,249.42649070473,0.06666821580982761,50.284380526073576,254.6639140467744,0.020780446376410952
0.0213223081747336,249.693684991118,0.06769832845477917,50.33824689420939,255.01773069178347,0.02109816828388946
0.0216402939547771,249.973700329072,0.06870793330641728,50.394697986340915,255.38320468515647,0.021409466965793825
0.0219620435213958,250.201798184517,0.06972948818043166,50.44068251399863,255.69674096537688,0.02172435168027763
0.0222802256857477,250.441255260132,0.07073971655224894,50.488957060442615,256.0211429483497,0.022035647627645677
0.0225994855596721,250.600724073108,0.07175336665195892,50.521105973138575,256.26417151804156,0.02234790059271024
0.0229246422772902,250.768428799357,0.07278573923039638,50.55491524595037,256.5172053240204,0.02266582079314384
0.0232516725268356,250.942414836393,0.07382406027270302,50.589990831016834,256.77724568926214,0.022985470913188717
0.0235766582779167,251.112293565013,0.07485589003238552,50.62423838270663,257.0326822997792,0.023303021485379712
0.0239008578814565,251.335247760118,0.07588522377362437,50.66918594843979,257.34237579743325,0.02361970345496487
0.0242241919898077,251.554816495067,0.07691180956763945,50.7134510054055,257.64852866580435,0.023935440144047863
0.0245490857947568,251.777338036995,0.07794334739835283,50.7583113482582,257.9582415096407,0.02425259950101088
0.024872174157233,251.973822536735,0.07896915294921478,50.797922623405775,258.24095933393244,0.02456789667438015
0.0252004370240426,252.176736668071,0.08001138755133526,50.83883011228311,258.5317006394033,0.02488814178943084
0.0255216019550634,252.360688524949,0.0810310862073263,50.875914806629716,258.80133756658853,0.025201363111035657
0.0258385559738846,252.586687372951,0.0820374152170836,50.92147617438692,259.11316263289507,0.025510381515354535
0.0261505762766517,252.794171364349,0.08302807967836914,50.963304947052755,259.4048846249054,0.025814496483867737
0.0264629128669398,252.912683172421,0.08401974835253385,50.98719692756007,259.6054894701567,0.026118827128044822
0.0267774072788557,253.07873441535,0.08501826811036683,51.02067285813456,259.8555267604072,0.02642516673309711
0.0270946856050486,253.274916158972,0.08602562679602929,51.06022309764875,260.1373203839444,0.02673412300142166
0.0274129849702332,253.458904157212,0.0870362272804904,51.09731507809394,260.4069692874454,0.027043977641820243
0.0277327840083902,253.669362797681,0.08805158922663889,51.13974354001249,260.7043204456951,0.027355195508275826
0.0280566340346888,253.839854806042,0.08907981306013693,51.17411472889807,260.9617467157537,0.02767025698892659
0.0283806828642552,254.056797338294,0.09010866809401025,51.21785034340007,261.2671027330605,0.027985412553927877
0.0287033404364183,254.252919878772,0.0911331058856281,51.25738864756044,261.55082799500576,0.028299116390187756
0.0290224475180851,254.435231620782,0.09214627086992018,51.29414269474965,261.819564777248,0.028609271500351495
0.0293427136088281,254.635795745169,0.09316311570802921,51.33457642222607,262.1075009742755,0.028920456414841568
0.0296631287851635,254.810023232817,0.09418043389289411,51.369700683735914,262.3684857677225,0.029231689314063756
0.0299854382354269,254.991353332449,0.0952037663974804,51.40625683182172,262.6373808083671,0.029544664506099313
0.0303055613452071,255.129894692482,0.09622015727103254,51.434186770004374,262.8617493670812,0.029855419746423462
0.0306167193163199,255.33713944797,0.09720808382931569,51.47596731271076,263.1547249774805,0.030157379676108154
0.0309332356613278,255.482505362607,0.09821302322471577,51.50527308110157,263.385405908335,0.030464446062475222
0.0312468181085558,255.729776900213,0.09920864749466465,51.55512302308294,263.72051872395554,0.030768573191502363
0.031570665438711,255.878987472503,0.10023686276790743,51.58520387445661,263.9572573787935,0.03108255863655366
0.0318936949673321,256.072127114949,0.1012624815212794,51.624140826373726,264.2392134267891,0.031395653001019874
0.0322136808621266,256.232061512752,0.10227843673725195,51.656383600970806,264.4862393689686,0.031705700725382265
0.0325254229822044,256.403794283569,0.10326821796849896,51.69100492756752,264.7434361468843,0.03200766829297122
0.0328389930450658,256.592147265931,0.10426380291808392,51.72897688881169,265.0183750054154,0.03231131452879997
0.0331499248741117,256.779491403604,0.10525101147530463,51.766745466966576,265.2917122528461,0.032612315012100206
0.0334684521153035,256.988554541384,0.1062623354660886,51.80889259554302,265.5895636732334,0.032920574386216664
0.0337951285460279,257.167158022468,0.10729953313363856,51.84489905732955,265.85815518565397,0.03323662158648617
0.0341300395151665,257.279644205439,0.10836287546065364,51.86757627181651,266.06060862861864,0.03356053173298417
0.0344636423793443,257.415760579642,0.10942206455441815,51.89501733285582,266.2872452950657,0.03388307247164139
0.0347931929808547,257.581995514409,0.11046838771421366,51.92853029570486,266.5440955927355,0.03420159320687847
0.0351109116801237,257.746255898329,0.11147714458439274,51.96164518910313,266.79596192505784,0.034508582019595814
0.0354307509615894,257.915514783348,0.11249263430304635,51.99576778032296,267.0536551567669,0.03481752464053442
0.0357511285943834,258.056964560038,0.11350983328716728,52.02428405530366,267.2827922847002,0.035126891614542445
0.0360725244479272,258.210625462702,0.11453026512216885,52.055262093280724,267.5249345624199,0.035437145680471134
0.0363940792912448,258.355329695137,0.11555120174970224,52.084434466539626,267.7579340493775,0.03574745692535939
0.0367140210744021,258.472369015569,0.11656701691122667,52.1080295935387,267.9619290187572,0.03605611597274922
0.0370365571003628,258.608743562985,0.11759106879365189,52.13552270229778,268.1867210606086,0.03636718137468903
0.0373553093246848,258.764357832395,0.11860310710587424,52.166894539010826,268.4305804614275,0.03667450250527181
0.0376744428264635,258.951354647093,0.1196163559740216,52.204593096853955,268.7072026525802,0.036982096653224696
0.0379955236698432,259.10836008608,0.12063578765175215,52.23624539335373,268.9533179147849,0.03729147227759983
0.0383154518901535,259.235849908969,0.12165155975123736,52.261947341648145,269.1685886443591,0.03759964212942636
0.0386435317715397,259.367564676231,0.12269321337463855,52.288501038728164,269.3904434023038,0.03791556544490427
0.0389597029510996,259.526283154751,0.12369705686974122,52.320498683997805,269.63735005446307,0.03821992690980427
0.039276589732964,259.701270220827,0.1247031724021607,52.35577607651872,269.90145046442007,0.0385248843253166
0.0395955386001674,259.867220389914,0.1257158350555315,52.389231630606666,270.15680294578107,0.03883173231789766
0.0399131531962276,259.961469934149,0.12672426139802265,52.408232338724446,270.3373519087472,0.039137203124327016
0.0402366702474007,260.04246054181,0.12775142803549722,52.424560045228894,270.5057032769535,0.0394482548092926
0.0405617106153564,260.191440945627,0.12878343120375657,52.45459449463841,270.7452508778561,0.03976067370925812
0.0408824172191144,260.361898898939,0.1298016746706882,52.488958818026106,271.00612267768634,0.040068831494525795
0.0412108465672109,260.59168766295,0.13084443785089458,52.53528423285072,271.3308917199184,0.04038431145551778
0.0415380214928824,260.749213749378,0.13188321823990162,52.567041491874605,271.58022019435185,0.04069848752674753
0.0418651708616399,260.883489770808,0.13292191748570667,52.5941115377949,271.8054216450438,0.041012540392411714
0.0421929494358268,260.95894481225,0.13396261445875007,52.6093232741496,271.96957237554,0.04132709839220761
0.0425303748960868,261.039858194232,0.13503394029507557,52.62563541195718,272.14198122605404,0.04165081085732779
0.0428678826467199,261.135297241817,0.13610552740333567,52.6448759239503,272.32961451889554,0.04197449747436526
0.0432081780699644,261.249214844158,0.13718596537213698,52.66784171258226,272.5373174397828,0.04230075156708142
0.043547323775263,261.441639314546,0.13826275298646,52.706634485812486,272.8267230301121,0.0426257975132737
0.0438791305490533,261.578009897968,0.1393162394932442,52.73412679543035,273.0558255430425,0.04294370742180962
0.0442198562519008,261.699137429027,0.14039804359978503,52.75854610569185,273.271435667385,0.04327005756902506
0.0445557386879765,261.84501333486,0.14146447033432538,52.787954688307785,273.51171132575774,0.04359166458107985
0.0448868783708693,261.977947038534,0.14251583882751,52.81475412296846,273.73731928310275,0.043908629194476495
0.0452159063664454,262.149192575016,0.14356050271346416,52.84927722312323,274.0025059205272,0.04422347303918761
0.0455407553958973,262.231880606959,0.14459189838197392,52.86594713036294,274.1741185386867,0.044534220854088355
0.0458692032731508,262.278964952749,0.14563472039225378,52.875439334474194,274.3094921104382,0.0448483131520543
0.046201846847444,262.360875399777,0.1466908637406347,52.891952480595045,274.48243238375886,0.04516631724381543
0.0465385751864852,262.466755882381,0.1477599762170905,52.913297985888015,274.68158473496607,0.045488123367883
0.0468733935196376,262.581317818429,0.14882302442484938,52.936393672195294,274.88939525943726,0.04580800148171101
0.0472167897254967,262.740681256549,0.14991330737845202,52.96852134132028,275.1464527557732,0.04613596845437012
0.0475596705270046,262.868714018332,0.1510019539232396,52.994332746095736,275.37066344890127,0.046463335895312874
0.0478984767786397,263.011818080769,0.15207766377218102,53.02318252508303,275.6096835416185,0.04678670790350423
0.048234459393297,263.135914018008,0.15314440857371797,53.04820026603042,275.82813257762774,0.04710728167221598
0.0485660011431428,263.25121962836,0.1541970536294784,53.07144587707738,276.03627866176464,0.04742351753618932
0.04890443894816,263.295547746006,0.155271593660408,53.080382425594806,276.1718687860729,0.04774622797966971
0.0492426350841278,263.356826033627,0.15634536639210575,53.0927361283792,276.32521011491497,0.04806860398760764
0.0495870110054745,263.465473737641,0.15743875994238155,53.11463950550842,276.52993908343194,0.0483967639457814
0.0499289347907068,263.616277787678,0.15852436796049407,53.145041601995885,276.7783577311078,0.04872248072725171
0.0502692873812766,263.804057435171,0.1596049874355532,53.18289797893047,277.0652994107264,0.04904659546076233
0.0506157789333928,263.917070476377,0.16070509811352213,53.2056814080376,277.2754385723579,0.049376448398282126
0.0509610607538521,263.954359791119,0.1618013678934804,53.21319893388959,277.4057539566783,0.049705041497564294
0.0513165682189616,264.010279672594,0.16293010409520306,53.22447238199495,277.5583811999198,0.050043253219554475
0.0516655182814574,264.11845479461,0.16403802054362723,53.24628048659338,277.76427164927117,0.05037511535755209
0.0520167393492879,264.193160592897,0.16515314743398907,53.261341175528045,277.93562736532226,0.05070902611790557
0.0523597913126016,264.347849261506,0.16624233741751007,53.29252641111961,278.18904748277356,0.05103506279561441
0.0527024636288379,264.432308717649,0.16733032202156034,53.30955343747804,278.36854285013055,0.0513606325676805
0.0530521102963216,264.531295412154,0.16844045019082107,53.32950915509025,278.56523887318843,0.051692719388268575
0.0534012393213086,264.584503792827,0.1695489348451548,53.34023596463392,278.7136442005774,0.05202420456286062
0.0537555317831164,264.626559225493,0.17067381341139456,53.34871433985939,278.8517006405957,0.05236047993639232
0.0541137830435016,264.74475988405,0.17181126116311757,53.37254359262448,279.0711003823194,0.052700397844314614
0.0544667162866801,264.846622208,0.1729318242102093,53.39307903713279,279.27194803928865,0.05303515693611732
0.0548337757881736,264.962749617055,0.17409723812745115,53.41649032279829,279.4916576217746,0.0533831960197641
0.0551946698568764,265.029383919586,0.17524307679558254,53.42992379818854,279.6575932673989,0.05372527109744071
0.0555649688081703,265.136048968229,0.1764187759659407,53.45142747199497,279.86832525907016,0.054076139048778865
0.0559264419785968,265.264128864638,0.17756645328204484,53.477248379111025,280.0994077765892,0.054418525640655184
0.0562809144871754,265.343922153299,0.17869190349678188,53.49333470610508,280.27772074570055,0.054754167414481365
0.0566399266164964,265.443170519604,0.17983176700737608,53.51334317675217,280.47785221868446,0.05509399285970561
0.0569999433454634,265.437603113039,0.1809748201218463,53.51222078758867,280.5675314522378,0.055434653288726696
0.0573593656008323,265.526322034011,0.18211598578264254,53.53010652205662,280.75674341620413,0.055774635483153326
0.0577217185205915,265.601654191616,0.183266456302878,53.54529348502978,280.93263811346793,0.0561172728657338
0.0580854466205794,265.692519415144,0.18442129302033958,53.56361191409303,281.12538806911954,0.056461092576304224
0.0584535475934321,265.763609119395,0.1855900136091469,53.577943598470036,281.2984348936578,0.05680892550314399
0.058822083901083,265.789467107778,0.1867601163859385,53.583156568928054,281.42375744201587,0.057157048634483905
0.0591934273353761,265.850708949115,0.1879391317898191,53.59550292414159,281.58732357135267,0.05750770087109692
0.0595672048071791,265.961708922926,0.18912587526279362,53.61788051886189,281.8043045092053,0.05786052739619869
0.0599577428967067,266.04641207648,0.19036583369704377,53.63495667461837,281.9979544503529,0.0582290421375517
0.0603518005111449,266.139350501363,0.19161696662288505,53.65369306107478,282.201339490987,0.05860074033624197
0.0607461233611769,266.15927755116,0.19286894167173665,53.657710354313856,282.32742185900446,0.058972550472998535
0.0611325600470349,266.313442731732,0.1940958781493358,53.68879005471717,282.5938652608622,0.05933679060901785
0.0615146805737255,266.325234428545,0.19530911082157845,53.69116726079467,282.70814615313947,0.059696832092600974
0.0619003969108482,266.374216757494,0.19653376019194302,53.7010420983108,282.86288650159923,0.06006013020181677
0.0622955584622125,266.376794397243,0.19778839811752466,53.70156175048419,282.97088556559316,0.06043218773720852
0.0626942160116408,266.432831914677,0.19905413583695952,53.71285891399889,283.13662943132897,0.06080739665246464
0.0630951462213558,266.529058721965,0.20032708925280465,53.732258238348145,283.3457486542677,0.06118460261801494
0.0634972750311581,266.600423803487,0.20160384822392693,53.746645438782984,283.52882423716034,0.06156279338985878
0.0638989352280749,266.668801525478,0.20287911934913777,53.76043038753636,283.7086540015029,0.06194040072012706
0.0643012628912753,266.715408506798,0.20415650967979906,53.769826354970476,283.8655461063475,0.06231849265748215
0.0647122471290418,266.780669598092,0.20546138463470773,53.782982990975356,284.04464621837496,0.06270457216419933
0.0651219738229633,266.833150866576,0.20676226688790844,53.79356321470172,284.209852332408,0.06308932201462934
0.0655375928666338,266.864058133708,0.2080818573515623,53.79979411975553,284.35368612641264,0.0634794538361926
0.0659499083159582,266.928314408501,0.20939095890316728,53.81274818475381,284.53221227067496,0.06386633431683215
0.0663623144429159,266.951011536352,0.21070034835625798,53.81732392572856,284.6664985047819,0.0642531502133957
0.0667787547505199,266.974599872935,0.21202254633290069,53.8220793343837,284.8028312024679,0.06464359819539614
0.0671964702524182,266.980004274258,0.2133487930514278,53.82316886169042,284.92011818946366,0.06503508868913681
0.0676194241568161,266.959266098052,0.2146916716978911,53.81898804536729,285.0108979449285,0.06543133260978538
0.0680493248076045,267.016046310828,0.2160566062641443,53.830434936262925,285.186307975076,0.06583392374832557
0.0684866186862915,267.066674163009,0.21744501432897548,53.84064151126261,285.3571676402271,0.06624327224173604
0.0689332476280389,267.149353416389,0.2188630612190235,53.85730964874402,285.56482594911137,0.06666118634021201
0.0693856030607101,267.223201435098,0.22029928971775453,53.87219740931576,285.7646444184859,0.06708428080928378
0.0698434112133395,267.269517776964,0.22175283060235293,53.881534783835946,285.9365326118514,0.06751229310395973
0.0703116044112423,267.298889180686,0.2232393440056943,53.887456058826295,286.0931029363229,0.06794982515369802
0.0707904235427726,267.279097291877,0.22475959474830298,53.883466014042405,286.1998977932989,0.06839708935060301
0.0712776792536767,267.333943540618,0.22630663163042353,53.894523017788586,286.3888866219267,0.06885202887252762
0.0717771929949399,267.345944237851,0.22789258775893417,53.896942358350756,286.5352856738257,0.06931819869092819
0.0722837109468274,267.384007285853,0.22950078225617696,53.90461586882796,286.71151558030795,0.06979068336743999
0.0727982744594063,267.384213574066,0.23113452140861498,53.90465745653171,286.84932293994336,0.07027044453829454
0.073320811767008,267.397305717937,0.2327935773602504,53.9072968327361,287.003093237487,0.07075740476457579
0.0738587619571337,267.398252021382,0.23450156921389947,53.90748760751061,287.14795586518295,0.0712584808813239
0.0744015246525829,267.395966946914,0.2362248407719507,53.90702693649786,287.29063457371603,0.07176378529939735
0.0749420643821358,267.38727880122,0.23794105441328114,53.905275406325956,287.4258334641051,0.07226676652930067
0.0754976023333176,267.386319289808,0.23970488740828338,53.9050819688253,287.5733452929194,0.07278344037245844
0.0760548975185013,267.361608131649,0.2414742996212416,53.90010019934044,287.6957678384833,0.07330148043672402
0.0766314932016634,267.338860723655,0.2433049909152813,53.895514321888854,287.8254368117402,0.07383717917987268
0.0772144879571907,267.307739834117,0.24515599926408047,53.889240350557984,287.9477700924023,0.0743785315094868
0.077807232424639,267.263215795629,0.2470379629482288,53.88026430439881,288.05822694559595,0.07492863685347478
0.0784197841306816,267.236125502381,0.24898281461491406,53.87480290128001,288.19272477619745,0.07549680682613337
0.0790436620690755,267.11307057115,0.2509636270693147,53.84999502714384,288.2266658556091,0.07607515076691493
0.0796898853422097,266.985295982581,0.25301538596151574,53.82423567008834,288.2613236074888,0.076673856700968
0.0803541108386212,266.813017560664,0.2551243019126223,53.78950434022986,288.25254034692057,0.07728886780122547
0.0810169476694828,266.566289122437,0.25722880885060784,53.7397638870833,288.1626762187177,0.07790221630428068
0.0816971078397087,266.265748893663,0.2593883173910751,53.67917497696246,288.01889049504933,0.07853120393296623
0.0823864055695525,265.8574416578,0.2615768376833292,53.59686023821248,287.76048066990313,0.07916823827002692
0.0830880960628443,265.379470889177,0.2638047049995306,53.500501331258086,287.4293458595238,0.07981630918226523
0.0837918090543888,264.868610679508,0.2660389937476844,53.39751191298881,287.0624307300665,0.08046582650403493
0.0844970465929571,264.234692826401,0.2682781229326388,53.26971407380245,286.5617439776291,0.081116327991971
0.0851998537366892,263.518705019611,0.2705095356139882,53.125370931953576,285.97046014416355,0.08176416702257999
0.085932292103653,262.690795634301,0.27283502742909826,52.95846439987508,285.26441781768875,0.08243887343890997
0.0866894837918457,261.777712904675,0.2752391110391101,52.77438692158248,284.4710877045913,0.08313590384452446
0.0874279176505159,260.837072692119,0.277583638540388,52.5847538547312,283.6415148036472,0.08381519916369694
0.0881673896762079,259.842008035171,0.27993146222196,52.38414881989047,282.75159961185625,0.08449498740526758
0.0889068981346811,258.737902965902,0.28227940157761244,52.161561237925845,281.7414873484724,0.08517434730681586
0.0896458896215292,257.502475035249,0.2846256995483552,51.9124989671062,280.5865134895295,0.08585277155188858
0.0904073342774292,256.356640527749,0.2870432863308377,51.681498730394196,279.53316102217997,0.08655132760411399
0.0911567327791208,255.110199720937,0.28942262657370854,51.4302162637409,278.3652120261266,0.08723835627540992
0.0919241294975971,253.849287877828,0.2918591111548708,51.17601643617013,277.1841626895823,0.08794139642691792
0.0926821248384807,252.587279003181,0.29426574636217623,50.92159544704129,275.997604728366,0.08863533875157914
0.0934672796965871,251.175485884355,0.296758613036664,50.63697795428597,274.6521752764342,0.0893536381415808
0.0942604176436429,249.845800288895,0.2992768260185662,50.36891333824123,273.39636977063645,0.09007871739414847
0.0950734540860075,248.431483485584,0.3018582167230738,50.08378707069374,272.0507227242694,0.09082144237569494
0.0958886403755949,247.018576018823,0.3044464331925138,49.79894492539472,270.7048514207835,0.09156557786691571
0.0967114101340683,245.54592691423,0.30705872717566685,49.502058865908765,269.29301975878207,0.09231607479124124
0.0975351798032557,244.020997083982,0.30967419587533684,49.19463301213077,267.82162891033795,0.09306691994389323
0.0983595438645384,242.39145236071,0.3122915517699094,48.86611679591913,266.2329650515724,0.09381774291470722
0.0991718577394335,240.731654236859,0.31487064832270134,48.531501494150774,264.6054596042153,0.09455703966496115
0.100025183531395,239.014190757857,0.3175799577121791,48.18526085678397,262.9216290550195,0.09533307366170851
0.100898592413569,237.265444988931,0.32035303091308154,47.832713709768484,261.20519441669325,0.09612674851548408
0.101802969965789,235.500039528997,0.32322442964138004,47.476807969045794,259.4746429801096,0.0969479016108321
0.102689962538534,233.68945486409,0.32604063105984543,47.11179410060055,257.68701622973384,0.09775261511889743
0.10356355142227,231.795632391659,0.3288142757657072,46.72999949015846,255.80121128631018,0.09854453583323336
0.104428345411357,229.805052771167,0.33155999668105846,46.32869863866727,253.80321419922956,0.09932786663670923
0.105262089977035,227.757707253218,0.3342071356770861,45.91595378224876,251.73195952706942,0.10008249234526162
0.106106970818157,225.679924514462,0.33688963234764846,45.49707278211554,249.62613767916187,0.1008466170652917
0.106959922511898,223.511417570891,0.33959775397527614,45.059901782291625,247.418181474798,0.10161744937817459
0.107814182999048,221.267630675686,0.3423100310219774,44.6075543442183,245.1234195011202,0.10238886938655176
0.108668833988938,219.021421474762,0.3450235479148781,44.15471856931202,242.8222239650241,0.10316004699151932
0.109519946727562,216.643953735089,0.34772583086000936,43.67542107299395,240.3707880070044,0.10392744135199135
0.110432268930585,214.26779295819,0.35062245385460733,43.19638706037111,237.92987149331174,0.10474937098448464
0.111433825121294,211.75698928974,0.35380239476010844,42.69020904081159,235.35388060246464,0.10565091609670152
0.112510144792291,209.012044118208,0.3572197097155239,42.13682809423073,232.52801946528027,0.1066188539311
0.113062144688373,207.655271554762,0.3589723093855843,41.86330274544002,231.1332219125899,0.10711490603420201
0.113350280963773,206.939472893111,0.3598871420599793,41.71899773525118,230.3961202880402,0.10737374062719003