File: example/data/02 processed data/test_ID_148.csv
Strain,Stress_MPa,Displacement(mm),Force(kN),True Stress (MPa),True Strain
6.74544331049899e-05,0.109391525355271,0.0002141678251083429,0.022053331511622632,0.10939890429860033,6.745215815699335e-05
7.65746730364794e-05,0.0620485212346953,0.0002431245868908221,0.012508981880914575,0.06205327257992124,7.657174134584171e-05
0.000107959366241,-0.0273938310112417,0.000342770987815175,-0.005522596331866326,-0.027396788431876585,0.00010795353904798949
0.0001612496804834,-0.188790134270027,0.000511967735534795,-0.03806009106883745,-0.18882057661885648,0.000161236681151156
0.0002257635149399,-0.355117728658692,0.0007167991599341824,-0.07159173409759231,-0.35519790128533146,0.00022573803419252938
0.0002745698567538,0.167036475952585,0.000871759295193315,0.03367455355204114,0.16708233913385998,0.0002745321693491658
0.0003645132369193,1.92410285038341,0.0011573295272187774,0.3878991346372954,1.9248042113415686,0.00036444681810913934
0.0004269920549395,4.89840562014773,0.0013556997744329125,0.9875185730217824,4.900497200429404,0.0004269009197738153
0.0005405968340232,8.62110797911497,0.0017163949480236598,1.738015368589578,8.625768522794253,0.0005404507641957078
0.0006360982313037,12.6035963537987,0.0020196118843892473,2.540885024925818,12.611613479147417,0.0006358960065756666
0.0006888364417975,16.5820777375315,0.0021870557027070625,3.34294687188635,16.593500076957827,0.0006885993028693364
0.000795454295377,20.8286761842198,0.002525567387821975,4.199061118738711,20.84524444415755,0.0007951380892828435
0.000833275165048,25.0588485205942,0.0026456486490274,5.051863861751791,25.07972943673111,0.0008329281840379926
0.0009346271902006,29.2771755416195,0.002967441328886905,5.902278589190492,29.304538785932973,0.0009341906981587047
0.0009998959399012,33.4112094947742,0.00317466960918631,6.735699834146478,33.44461722749521,0.0009993963769354022
0.0010755236234286,37.4130411540919,0.003414787504385805,7.542469096664927,37.45327976367743,0.001074945662266412
0.0011492622189111,41.1862469428927,0.0036489075450427426,8.30314738368717,41.23358074044291,0.0011486023226347012
0.0012265911199833,44.914095334485,0.003894426805946977,9.054681619432175,44.96918656498436,0.0012258394716761854
0.0013000902697388,48.4521955616082,0.004127786606420689,9.767962625220212,48.515187789605335,0.0012992458841565575
0.0013824469144464,51.8912580567675,0.00438926895336732,10.461277624244328,51.96299496635481,0.00138149221449075
0.0014736475544124,55.1508054330462,0.004678830985259369,11.118402375302114,55.23207828259648,0.0014725628014200195
0.0015561811208017,58.2182569283852,0.004940875058545398,11.736800596762457,58.30885508070315,0.0015549715256982061
0.0016597244740838,61.1313882755369,0.005269625205216065,12.32408787634824,61.23284953679252,0.0016583486535304169
0.0017669240334242,63.9279075267561,0.005609983806121835,12.887866157394031,64.04086328297164,0.0017653648595119373
0.0019068491357446,66.5454125388689,0.006054246005989104,13.415555167835972,66.67230460125641,0.0019050334067790525
0.0020481879725991,69.008809309834,0.006502996813002143,13.912175956862537,69.1501523230658,0.002046093295321094
0.0022263428756233,71.31706080688,0.007068638630103977,14.377519458667008,71.47583703711778,0.0022238682465579394
0.002422431504582,73.4107451592808,0.0076912200270478496,14.799606224111008,73.58857766112948,0.002419502147209419
0.0026326683048483,75.2271906199072,0.008358721867893352,15.165801628973293,75.42523886031502,0.002629208903953185
0.0028773397874256,76.8845446934681,0.00913555382507628,15.499924210203169,77.10576765295271,0.0028732081687824454
0.0031527956740922,78.1729067883082,0.010010126265242733,15.759658008522933,78.4193699906616,0.003147836035561269
0.0034226085365294,79.2196713319229,0.010866782103480844,15.970685740515655,79.49080925528459,0.0034167647421497844
0.0037485057656307,80.0067385782771,0.011901505805877472,16.129358497380665,80.30664429912709,0.0037414976258018443
0.0040604697172102,80.6275167945839,0.012891991352142383,16.254507385788113,80.95490238490216,0.004052248257858163
0.0043779740204549,81.0665376015356,0.013900067514944306,16.34301398046958,81.42144479708335,0.0043684185710480055
0.0047213433108211,81.3721047340581,0.014990265011856992,16.40461631438611,81.75629037643168,0.0047102327270207
0.0050568110727325,81.61209377905,0.016055375155925686,16.45299810585648,82.02479071854079,0.0050440683439471334
0.0053868699840831,81.7928268004543,0.01710331219946384,16.48943388297159,82.23343412405899,0.005372412696416071
0.0057468417790014,81.9049163337345,0.01824622264832944,16.512031132880878,82.37561092882683,0.005730391677780672
0.0061036132460454,81.9519961035511,0.019378972056194144,16.5215224144759,82.4521993925086,0.006085061648297429
0.0064608892128329,81.9554669257575,0.020513323250744456,16.522222132232713,82.4849721179508,0.006440107133899465
0.0068496352446536,81.9448949895246,0.02174759190177518,16.520090829888158,82.5061876303643,0.0068262830684406835
0.007226229550407,81.9623050338111,0.022943278822542223,16.52360069481632,82.5545834644659,0.007200245456576024
0.0075930656409514,81.9783041491569,0.024107983410020694,16.52682611647003,82.60077079369532,0.0075643834172091735
0.0079608310372284,81.9574623036674,0.025275638543200172,16.522624400419346,82.60991181330691,0.00792931079619366
0.0083257564792748,81.9405852944774,0.02643427682169749,16.519221995366646,82.62280265340846,0.008291288551033029
0.0086994925573296,81.8915382708478,0.02762088886952148,16.50933411540292,82.60395309854331,0.008661870012529889
0.0090676163387266,81.8577987711784,0.02878968187545695,16.502532232269566,82.60005388476813,0.009026752345935321
0.009454395663311,81.7915931352087,0.030017706231012426,16.489185176058076,82.56488321864153,0.009409982577776595
0.0098322900345939,81.7461198402658,0.03121752085983563,16.480017759797587,82.54987139973798,0.009784267594729355
0.0102150202914149,81.6458741893599,0.0324326894252423,16.459808236574958,82.47988845091452,0.010163199572652978
0.0105918945713839,81.57257287207,0.03362926526414388,16.445030691009315,82.43658096384749,0.010536193431261161
0.0109842994708013,81.4816894118061,0.03487515081979413,16.426708585420112,82.37670868969221,0.010924410215275845
0.0113876992607459,81.4150545920386,0.036155945152868234,16.413275005754983,82.34218474902995,0.011323347498374874
0.0117935581274618,81.35476122074,0.03744454705469121,16.401119862101183,82.31422332614257,0.01172455611048299
0.0122002236857226,81.2887617284173,0.03873571020216925,16.38781436444893,82.2805028046394,0.012126400787465031
0.012605136337837,81.2262247911391,0.04002130787263247,16.375206917893642,82.25009242883921,0.012526352966085529
0.0129873968591021,81.1487677842154,0.04123498502764916,16.359591585297824,82.20267903605613,0.012903783786488167
0.0133802401417662,81.0581735643844,0.04248226245010768,16.341327790579896,82.14275139212883,0.013291515292274599
0.0137733537672692,80.9249612123437,0.043730398211079706,16.31447218040849,82.03956933172385,0.013679363190541562
0.0141886050485767,80.8173744005276,0.04504882102923102,16.292782679146363,81.96406020695963,0.01408888890704304
0.0146053388811427,80.6804628793991,0.04637195094762807,16.26518131648686,81.85882838084018,0.014499708191745671
0.0150295115466851,80.5772015253521,0.04771869916072519,16.244363827510984,81.78823750607695,0.014917687486522347
0.0154514989406547,80.4824316172293,0.049058509136578665,16.225258214033428,81.72600582410422,0.015333340130270698
0.0158639640732969,80.3744574928214,0.05036808593271766,16.203490630552796,81.64951499889825,0.015739446563093295
0.0162678621229458,80.3038839137448,0.05165046224035291,16.18926299701095,81.61025642519064,0.016136958230161993
0.0166820661743763,80.1890773029533,0.052965560103644754,16.166117984275385,81.52679679698333,0.01654444889325862
0.0171023182743878,80.0704638925014,0.054299860521181256,16.14220552072828,81.43985445036884,0.01695771994520139
0.0175149006623017,79.9484023197397,0.05560980960280789,16.117597907659523,81.34869064447967,0.017363282612939488
0.017927132820598,79.8263269841221,0.05691864670539865,16.092987519999017,81.25738415054695,0.017768336804757735
0.0183336067438911,79.6969580906992,0.05820920141185424,16.06690675108496,81.15809077901845,0.01816757244368564
0.0187617782549823,79.5635109985053,0.059568645959568796,16.04000381729867,81.05626394904709,0.018587946983385253
0.019183904248965,79.449820911214,0.06090889599046387,16.017083895700743,80.97397866817215,0.019002213176683453
0.0195949238590271,79.3429647275341,0.06221388325241104,15.995541689070874,80.8976840801196,0.019405414946256423
0.0200205737696514,79.2222928410442,0.0635653217186432,15.971214236754511,80.80836859906925,0.019822797455164114
0.0204394116146003,79.0906746339959,0.06489513187635594,15.944680006213574,80.70724148771657,0.02023333023094152
0.0208351657897703,78.969260891777,0.0661516513825207,15.920202995782242,80.6145985347528,0.02062108226049138
0.021276368563291,78.8195930613143,0.06755247018844893,15.890029961160963,80.49658777329543,0.02105318674936344
0.0217105952701697,78.7200378995057,0.06893113998278878,15.86995964054035,80.42909678199429,0.021478276797517886
0.0221595331340487,78.568959281825,0.07035651770060462,15.83950219121592,80.31001073833833,0.021917578556333077
0.0225796074414467,78.4579105605902,0.07169025362659327,15.817114769014983,80.22945938172445,0.02232846159267928
0.0230025170051828,78.3303007617206,0.07303299149145538,15.791388633562873,80.13209483701316,0.022741947382086125
0.0234392991746586,78.2270601936802,0.07441977487954105,15.770575335045928,80.0606476611139,0.02316881725217464
0.0238648224310873,78.0564199595601,0.07577081121870217,15.736174263847317,79.91922256150139,0.023584508558674343
0.0242965361366302,77.9265082049284,0.07714150223380088,15.709984054113566,79.81985242753086,0.024006070766290976
0.0247420397020867,77.8358841603271,0.07855597605412527,15.691714246721943,79.76170269646894,0.024440912333189284
0.0252081026637172,77.7532522408266,0.0800357259573021,15.675055651750643,79.71326420575126,0.024895618972173926
0.0256758479948496,77.6662667552072,0.08152081738364747,15.657519377849772,79.66041401474135,0.025351759202919055
0.0261276796778382,77.5293424317882,0.08295538297713628,15.6299154342485,79.55500425647939,0.025792183136495957
0.0265809618847657,77.4247280661736,0.0843945539841311,15.608825178140599,79.48275181183891,0.026233826149164363
0.0270037580062118,77.3005066383504,0.08573693166972246,15.58378213829144,79.38791081336998,0.026645590147332827
0.0274532419941454,77.1703656235128,0.08716404333141164,15.55754570970018,79.28894234575176,0.027083159777755987
0.0279047280254751,77.0300876038858,0.08859751148088345,15.529265660943379,79.17959124825076,0.02752248572017291
0.028362130685604,76.8829916323329,0.09004976492679269,15.499611113078313,79.06355708850931,0.027967372205344086
0.0288233995378374,76.7746749797295,0.09151429353263374,15.477774475913465,78.98758211105785,0.02841581873890839
0.0292816267199705,76.6670801999443,0.09296916483590634,15.456083368308771,78.9120170240691,0.028861109123858208
0.0297181379046283,76.5863207532155,0.09435508784719485,15.439802263848247,78.86232359496766,0.02928511227208297
0.0301673435145291,76.4586514622751,0.09578131565862988,15.41406413479466,78.7652058655952,0.02972125847639731
0.030622522430564,76.330540468692,0.0972265087170407,15.388236958488308,78.66797415633161,0.03016301038032408
0.0310773097175945,76.1801640243639,0.09867045835336252,15.357921067311764,78.54763857608621,0.030604187400679266
0.0315369233240713,76.0678492778503,0.10012973155392636,15.33527841441462,78.46679520795287,0.031049848646220162
0.0319819830602249,75.9281346062463,0.10154279621621405,15.307111936619256,78.35646692101774,0.03148120863199758
0.0324478143929579,75.8226798560814,0.10302181069764133,15.285852258986008,78.28296009882818,0.03193250161489664
0.032920555722029,75.7097420962574,0.10452276441744209,15.263084006605494,78.20214887963768,0.03239028081222253
0.0333832410119886,75.5739393038766,0.10599179021306379,15.235706163661524,78.0968423338833,0.03283811941022921
0.0338610457846344,75.4261889195456,0.1075088203662142,15.205919686180392,77.98019855591082,0.03330038193450465
0.0343548242737678,75.3064000919078,0.10907656706921276,15.181770258528614,77.89353823375535,0.03377787415924157
0.0348291247478636,75.1834423430641,0.11058247107446692,15.156981976361724,77.80201583540449,0.03423631622537774
0.0353177553920139,75.1258057698574,0.11213387336964413,15.14536244320325,77.77908060166516,0.034708389639986535
0.035792070041343,75.0192368109976,0.11363982238126402,15.123878141097116,77.70433058938492,0.035166419100130804
0.0362667111898586,74.8951042433531,0.11514680802780106,15.098853015459985,77.61130335848115,0.035624553937922854
0.036744055030464,74.7691557660702,0.11666237472172318,15.073461802439752,77.51647774012002,0.03608508589156278
0.0372226809841108,74.6506338927827,0.11818201212455179,15.049567792784993,77.42933062343539,0.036546641955922214
0.037708151770594,74.5483980289746,0.11972338187163595,15.02895704264128,77.35948033610582,0.0370145812121886
0.0381845680435661,74.4170200262797,0.12123600353832235,15.00247123729799,77.2586017910726,0.037473580154464545
0.0386389061246132,74.2666923188386,0.1226785269456469,14.972165171477862,77.13627607153174,0.03791111188881387
0.0391140143784104,74.1305756105154,0.12418699565145302,14.944724043079903,77.03012001082493,0.038368440820843716
0.0395932982203531,74.0149715099329,0.1257087218496211,14.921418256402474,76.94546834969661,0.038829577266105676
0.0400872203284395,73.9064146529761,0.1272769245427954,14.899533194039982,76.86911738085496,0.039304575337172624
0.0405824915821002,73.7662620422564,0.12884941077316814,14.87127842771889,76.75988075062928,0.03978064442221746
0.0410938668281861,73.6415166338471,0.13047302717949086,14.846129753383577,76.66773131142408,0.04027195543154556
0.0415831441937452,73.5047213411395,0.132026482815141,14.818551822373724,76.56127876758916,0.04074180973153617
0.0420866094997898,73.3973325790254,0.1336249851618326,14.796902247931522,76.48637745360504,0.04122505839889346
0.0425822294210993,73.3221895900464,0.13519857841199026,14.781753421353356,76.4444118888271,0.041700548722722566
0.0430739644587413,73.2216731384151,0.1367598371565036,14.761489304704485,76.37562088478876,0.04217208861332991
0.0435586759115787,73.1181062773102,0.13829879601926237,14.740610225505737,76.30303417191193,0.04263667586474934
0.0440680922048536,73.008163292898,0.13991619275041017,14.718445719848237,76.22549376459644,0.0431247097519996
0.0445673142791165,72.8707796302245,0.14150122283619487,14.69074917345326,76.11843456776896,0.043602746351609115
0.0450587470960674,72.7493120018578,0.143061522030014,14.666261299574533,76.02730485276243,0.04407310115345119
0.045559520050342,72.6429885540819,0.14465147615983584,14.64482649250291,75.95256824762836,0.044552168012974576
0.0460712865140287,72.5233976029292,0.1462763346820411,14.620716956750526,75.86464383286457,0.04504151486356872
0.0465921604813746,72.4344843726565,0.14793010952836436,14.602792049527551,75.80936349293293,0.04553932446486934
0.0471005099849079,72.3035024536184,0.14954411920208258,14.576386094649472,75.70903429287888,0.04602492535624525
0.0476002104178376,72.1973593874386,0.1511306680766344,14.55498765250762,75.63396888589293,0.04650203450844207
0.0481017393493248,72.0874589198582,0.15272302243410624,14.532831718243413,75.55499107917638,0.04698066071873612
0.0486117394637143,71.9873013575293,0.15434227279729287,14.512639953677908,75.4867292958174,0.047467136462418666
0.049136424394705,71.8796253705951,0.15600814745318836,14.490932474711972,75.41153314813705,0.047967372812016504
0.0496363431252328,71.7549969307146,0.15759538942261414,14.465807381232064,75.31665257931758,0.04844376429919337
0.0501444562600614,71.6300733137917,0.15920864862569495,14.440622780060409,75.22192439198012,0.04892773209706546
0.0506543365041474,71.5265328761105,0.16082751840066797,14.419749027823876,75.14966194139195,0.04941314769788737
0.0511564354619583,71.3969922146866,0.16242168259171758,14.39363363048082,75.04940783909515,0.049890925216262524
0.0516799497448052,71.2878064078099,0.1640838404397565,14.371621771814475,74.97195666038292,0.05038883774749469
0.0522074821614708,71.1854148379151,0.16575875586266978,14.350979631323685,74.90182611322246,0.05089032125818155
0.0527604862423795,71.0906350879331,0.1675145438195549,14.331872033727311,74.841411562452,0.0514157488199609
0.0533173253086386,70.9963029772033,0.16928250785492754,14.312854680204184,74.7816359587495,0.05194454132342914
0.0538478472120083,70.8985281211231,0.17096691489812632,14.293143269218419,74.71626123094562,0.052448082214763055
0.0543807270119891,70.8081608309457,0.17265880826306537,14.274925223518654,74.65876009531438,0.05295360596853847
0.0549133449762342,70.7044263905351,0.17434987029954357,14.254012360331876,74.58704294826532,0.05345862609127857
0.0554394891012946,70.6009657427751,0.17602037789661035,14.233154693743462,74.51504721361256,0.05395725753097501
0.0559881044530498,70.4963819892795,0.1777622316384331,14.212070609038747,74.44334078765739,0.05447692049813166
0.0565223744048685,70.3791920266133,0.17945853873545747,14.188445112565242,74.35719106865366,0.05498273570573088
0.0570567767902794,70.2820633161495,0.1811552663091371,14.16886396453574,74.29213131513933,0.05548842047887678
0.0575998015590347,70.177163473629,0.18287936994993517,14.147716156283606,74.21935416368596,0.05600200248197923
0.0581655991412162,70.0667960137645,0.1846757772733614,14.125466076374924,74.14227318381049,0.05653684211541086
0.0587044867119318,69.9814911870169,0.18638674531038346,14.108268623302607,74.0897187064863,0.05704597830280158
0.0592492753568615,69.8142774316222,0.18811644925803525,14.074558330215037,73.9507227790087,0.057560426414655266
0.0597843188973115,69.7755518256037,0.189815212498964,14.066751248041706,73.94703566718148,0.05806541468220434
0.0603232553036985,69.6725033549087,0.19152633558924273,14.045976676349595,73.87537556243466,0.058573819467464934
0.0608735468333996,69.5838026773017,0.19327351119604372,14.028094619744024,73.81961554842447,0.059092669525594194
0.0614409598564174,69.4084963468541,0.19507504754412522,13.992752863525787,73.67302098459545,0.059627381072585556
0.06199999064235,69.2446348704396,0.19684997028946122,13.959718389880623,73.5378015844398,0.0601539140084006
0.0625505451544039,69.1223215035511,0.1985979808652324,13.935060015115903,73.44596039593621,0.06067219259495466
0.0631199319047434,69.0888840623521,0.20040578379756027,13.928319026970183,73.44976971974246,0.061207916988836215
0.0636775867810589,69.0147257946943,0.202176338029862,13.913368720210372,73.40941698565693,0.06173232505701931
0.0642326635501495,68.9115017767245,0.20393870677172465,13.892558758187661,73.33787108508439,0.06225403576506678
0.0648017241042034,68.7916734399269,0.20574547403084578,13.868401365489262,73.2494924828475,0.06278860727871181
0.0653729884660712,68.6850157468642,0.20755923837977605,13.846899174567824,73.17516048907586,0.06332496175911353
0.0659501090365359,68.5992783192253,0.20939159619100148,13.829614509155823,73.12340820420589,0.06386652261888767
0.0665294875533595,68.5180439122431,0.21123112298191637,13.81323765270821,73.07651426188322,0.06440990744845977
0.0670994186705346,68.4329052633204,0.21304065427894733,13.79607370108539,73.02471342442495,0.0649441438651747
0.0676851939900161,68.3183591547328,0.2149004909183011,13.772981205594133,72.94250054720048,0.06549293490545965
0.0682564524806295,68.217496442873,0.21671423662599867,13.752647282883197,72.87378074717347,0.06602783575837204
0.0688326571152572,68.106417881121,0.2185436863409416,13.730253844833994,72.79436359048061,0.06656707826913386
0.0694209296092427,67.98707198439,0.22041145150934557,13.706193712053024,72.70679772295685,0.06711731469804022
0.0699976347559997,67.899790833572,0.22224249035029903,13.688597832048115,72.65261559234914,0.06765643796296006
0.0705730093090688,67.7854892912497,0.22406930455629345,13.665554641115941,72.56931525802085,0.06819402785145225
0.0711392781546673,67.6677425470491,0.22586720814106864,13.641816897485098,72.48157690620205,0.06872282797283977
0.0717088758242201,67.5425076596756,0.2276756807418988,13.616569544190602,72.38590495429972,0.06925445470701637
0.0722820200142564,67.3777231585871,0.22949541354526407,13.583348988771162,72.24792109245112,0.06978910642107138
0.0728497702195696,67.2495048808648,0.2312980204471335,13.557500183982345,72.14861585881563,0.07031844473133736
0.0734478552881172,67.1225193393165,0.2331969405397721,13.531899898806206,72.05252442632447,0.07087576266983786
0.0740420934887649,67.0337803965608,0.23508364682682856,13.514010127946658,71.9971018315883,0.07142918851115837
0.0746465686612154,66.9715228736032,0.23700285549935887,13.501459011318406,71.97071725413379,0.07199183418341902
0.0752210044658678,66.8825627803336,0.23882668917913025,13.483524656515254,71.91353633392177,0.07252622599945749
0.0757995430260508,66.8151100312018,0.24066354910771126,13.469926182290283,71.8796648388022,0.07306414608098143
0.0763794529901232,66.7040202261099,0.24250476324364117,13.447530477583758,71.79883680322229,0.07360305105048498
0.0769932345322871,66.5953671551372,0.24445351964001152,13.42562601847566,71.72275987727645,0.07417311638319986
0.0775872506467747,66.4475647585484,0.24633952080350965,13.395829055323357,71.60304862033769,0.07472451479567435
0.0782092636735637,66.3271052672545,0.24831441216356476,13.371544421878507,71.51449933180541,0.07530157579370256
0.0788189950390182,66.2519889851447,0.25025030924888275,13.356400979405173,71.4739041762899,0.07586691969147633
0.0794234883361262,66.1878518245419,0.25216957546720065,13.343470927827646,71.44472190192165,0.07642709151421785
0.0800470557736475,66.107400372893,0.2541494020813308,13.327251915175227,71.3991031375928,0.07700461034776113
0.0806670753127258,65.9966543085137,0.2561179641179044,13.304925508596362,71.3204113920065,0.0775785127878626
0.0812945954487437,65.8955974522017,0.25811034054976123,13.284552446363861,71.2525533889317,0.07815902275908623
0.0819131938225765,65.8004449083386,0.2600743903866804,13.265369693521064,71.19036950572712,0.07873094968516603
0.0825134648244067,65.7150876126711,0.26198025081749127,13.248161662714494,71.13746718283204,0.07928561945401406
0.0831298068798593,65.6129126739084,0.26393713684355324,13.227563195059934,71.06730143331548,0.07985481945121231
0.0837293176492924,65.5108411140352,0.26584058353650336,13.206985568589497,70.99601913914458,0.08040816486988167
0.084350682804329,65.3912107954456,0.2678134179037446,13.182868096361833,70.90700407544325,0.08098135882205978
0.0849720931385423,65.2798011220548,0.2697863957148718,13.160407906206249,70.82676246306356,0.08155426605200385
0.0855840103844958,65.1632093239728,0.27172923297077417,13.136902999712916,70.74013810744276,0.08211810060221109
0.0861919921704809,65.0245737295629,0.27365957514127687,13.10895406387988,70.62917127935025,0.08267799425712971
0.0868198419852838,64.9173595699052,0.27565299830327605,13.08733968929289,70.55347446986622,0.08325585565889976
0.0874497998889077,64.7980981556939,0.27765311464728193,13.06329658818789,70.46467887259114,0.08383532189355525
0.0880922093352529,64.7277024701914,0.27969276463942794,13.049104817990587,70.42970878598547,0.08442589606982309
0.0887320138545003,64.6433339585646,0.28172414398803847,13.032096126046623,70.37926716297704,0.08501372905225227
0.0893656023472092,64.5443224768075,0.2837357874523892,13.012135411324392,70.3123647330399,0.08559551060865897
0.0899955459066042,64.4379571735726,0.2857358582534683,12.990692166192236,70.23708630651464,0.08617360990848695
0.0906103507961311,64.3577289037973,0.2876878637777162,12.974518147005536,70.18920529621268,0.0867374943836662
0.0912336355707866,64.2685953103595,0.28966679293724745,12.956548814568476,70.1320529135512,0.08730883201871685
0.0918552674251289,64.1628970489764,0.2916404740747842,12.935240045073643,70.05659711618115,0.08787832955066832
0.0924904674935217,64.0422131317979,0.2936572342919314,12.910910167370455,69.96550736367763,0.08845992254315406
0.0931332796889244,63.8674498672696,0.295698163012335,12.875677893241553,69.81563493877637,0.08904814109153494
0.093778501057677,63.7226817552523,0.29774674085812447,12.846492641858866,69.69849933363525,0.08963821646005664
0.0944281919606705,63.6229210639289,0.2998095094751288,12.826380886488067,69.63071846725217,0.09023202775234178
0.0950705933520029,63.5850650845929,0.30184913389260914,12.81874912105393,69.63013495051086,0.0908188300050539
0.0957075262497605,63.5148480642663,0.3038713958429896,12.804593369756088,69.59369705262661,0.09140029730199692
0.0963222168227441,63.4201799918295,0.3058230384122125,12.785508286352826,69.52895231993995,0.09196113876962611
0.0969554093229635,63.2903399331739,0.3078334246004091,12.759332530527859,69.42668074758427,0.09253853263008643
0.0975990423697818,63.1545944597813,0.3098769595240572,12.731966243091911,69.3184224003079,0.09312510551259245
0.0982492438571448,63.0172600064041,0.31194134924643474,12.704279617291068,69.20865815198239,0.09371731537558156
0.098918120650163,62.9046700500122,0.31406503306426753,12.681581482082459,69.127081791478,0.0943261691429241
0.0995808292346168,62.8214065351001,0.3161691328199083,12.664795557476182,69.07721429155035,0.09492904284869559
0.100237048972576,62.7439826598113,0.3182526304879288,12.64918690421796,69.03325432241726,0.09552565565371461
0.100886543631209,62.668072352245,0.32031477602908853,12.633883386212592,68.99043756789352,0.09611580395766785
0.101523060909037,62.5655900325345,0.32233571838619246,12.613222950558956,68.91744024021733,0.0966938229548951
0.102161266032166,62.4505530277549,0.3243620196521271,12.590031490395388,68.83058058947925,0.09727303943628436
0.102822298478215,62.3290465043605,0.32646079766833264,12.565535775279077,68.73786232789439,0.09787261983814464
0.103481265451208,62.1767249937069,0.3285530178075854,12.53482775873131,68.61085117766744,0.09846996918150895
0.104142517219151,62.049593745401,0.33065249217080445,12.509198099072842,68.51159463047274,0.09906903120730276
0.104805093232961,61.9233711762751,0.33275617101465116,12.48375162913706,68.41325586570386,0.09966893319732333
0.105470310921134,61.8275312769625,0.33486823717460046,12.46443030543564,68.34850022422987,0.1002708651620079
0.106130835943633,61.7082527142957,0.33696540412103476,12.440383747202013,68.25740115948487,0.1008681926168929
0.106789392378724,61.589597920794,0.3390563208024487,12.416462940832071,68.1667136596055,0.10146338483946257
0.107435248408614,61.4943919474454,0.3411069136973494,12.397269416604994,68.10105722205587,0.10204675477972025
0.108083309377117,61.371045610505,0.3431645072723465,12.372402795077807,68.00423132002237,0.10263177446706037
0.108727231787821,61.2325213472069,0.34520896092633163,12.344476303596911,67.89016388867736,0.1032127194029102
0.109381714223316,61.0848713813341,0.34728694265902826,12.314710070476956,67.7664393261352,0.10380284592096568
0.110038624607049,60.9337588761636,0.34937263312738054,12.284245789434584,67.63882589503422,0.10439481166213062
0.110696377022843,60.8490539619144,0.35146099704752654,12.267169278721942,67.5848237807658,0.10498718529927814
0.111355267532832,60.7220785771649,0.35355297441674155,12.241571041156444,67.48380188227475,0.10558023229790621
0.112012981088952,60.6221596759858,0.35564121495742257,12.221427390678738,67.41262850134343,0.10617186940139817
0.112677521884482,60.4991060123187,0.35775113198323033,12.19661977208345,67.31599535401334,0.106769292561525
0.113339629929497,60.3890866708258,0.35985332502615297,12.174439872838482,67.23356340587752,0.10736417392980316
0.114012091779366,60.298968796982,0.361988391399487,12.156272109471573,67.17378036166465,0.10796799582622531
0.114698035002302,60.1702905501261,0.3641662611323088,12.130330574905422,67.07170464174314,0.10858354760781587
0.115365490912821,60.0878904103475,0.36628543364820665,12.113718706726056,67.01995938545302,0.10918214573983583
0.116046525532815,59.972708486159,0.3684477185666876,12.090498030809654,66.93233293277012,0.10979255263566733
0.116714624755188,59.8587453935658,0.37056893359772186,12.067523071342864,66.84513640049217,0.11039100378860552
0.117382707478687,59.7188017766954,0.3726900962448312,12.039310438181792,66.72875641662694,0.11098908224631115
0.118059001495489,59.5306054608445,0.3748373297481775,12.001370060906252,66.5587292999737,0.11159414748663458
0.118722486438558,59.3845994791394,0.3769438944424216,11.971935254994504,66.43488678546073,0.11218739717696632
0.119389460920134,59.2561567755324,0.3790615384214254,11.946041205947333,66.33071738916216,0.11278341249434792
0.120049302025719,59.1622633440261,0.3811565339316578,11.927112290155662,66.26465176473822,0.11337270400398661
0.120704971771922,59.0318685194489,0.38323828537585236,11.9008246935209,66.15730854273279,0.11395792637538468
0.121361322392174,58.8933000543926,0.38532219859515243,11.872889290965547,66.04066882903277,0.11454341364729083
0.122018135562313,58.7329567355907,0.38740758041034373,11.840564077895085,65.89944261252947,0.11512897057264956
0.122671959270238,58.6058108111043,0.3894834706830056,11.814931459518627,65.79510044792335,0.11571152201520317
0.123346568445019,58.4310539555948,0.3916253548129353,11.779700477447912,65.63832395164317,0.11631223762528671
0.12402457474296,58.2923129351887,0.39377802480889795,11.751730287734043,65.52199225775902,0.11691561488281352
0.124707941888454,58.1407367288517,0.3959477154958414,11.721172524536502,65.39134834618524,0.11752339474233527
0.125380168314023,58.0251696336599,0.39808203439702294,11.697874198145835,65.30037516877792,0.11812090596202551
0.126044412005445,57.9205318365469,0.40019100811728786,11.676779218247855,65.2210912149271,0.1187109712180427
0.126709927567937,57.7987538668011,0.4023040200282,11.652228779547102,65.12242978278049,0.1193018173393105
0.127373988896633,57.6740959170899,0.4044124147468098,11.627097736885323,65.02027557005665,0.11989102463816656
0.128047528771505,57.5269315406785,0.40655090384952836,11.597429398600784,64.89311296226992,0.12048828762392605
0.128709653551565,57.3782150322035,0.4086531500262188,11.567448150492226,64.76334521040562,0.12107508074836607
0.129376874373279,57.2175510735011,0.4107715761351608,11.535058296417821,64.62017899068412,0.12166604201834473
0.130047903187719,57.0607329354626,0.4129020926210078,11.503443759789262,64.48136160807394,0.12226002402724653
0.130723298519069,56.9120982482686,0.415046472798044,11.473479006850951,64.3518354569236,0.12285751514083885
0.131379947999472,56.7308485686216,0.4171313348983236,11.436939071434114,64.18414450353303,0.12343808059456657
0.132053623515498,56.6070699142354,0.4192702546617061,11.411985294709858,64.08223861300532,0.12403334925576948
0.132731431893819,56.4587299316744,0.4214222962628753,11.382079954225558,63.95257799841196,0.12463191237056863
0.133394176650122,56.3677263534869,0.4235265108641373,11.363733632862958,63.886852800049674,0.12521682679252247
0.134059060841759,56.1778198374394,0.42563751817258483,11.325448479227783,63.70896560498406,0.12580328582038636
0.134725219421734,56.0183934649793,0.4277525716640054,11.293308122539827,63.56548381620167,0.12639052419726854
0.135404215851317,55.8356838045651,0.42990838532793146,11.256473855000324,63.39607078664432,0.12698872484546134
0.136089026756607,55.6274837129698,0.4320826599522272,11.214500716534713,63.19777383238687,0.12759168585207326
0.136760471623926,55.4314176890001,0.434214497405965,11.174973806102422,63.01224451493058,0.12818252557756343
0.137433450653831,55.2712672548924,0.4363512058259134,11.142687478586309,62.86738823574236,0.1287743652117799
0.138103200255697,55.13607374446,0.438477660811838,11.115432466883135,62.75054197810404,0.1293630172301404
0.138786146291056,55.0022324582464,0.4406460144741028,11.088450063582474,62.63578033853125,0.12996291116602793
0.139464322213749,54.8267905778398,0.44279922302865304,11.053080980492505,62.47317176493339,0.13055825917723154
0.14014842099184,54.6554678225915,0.44497123664909194,11.018542313034445,62.31534533649801,0.13115844778441124
0.140841856165159,54.4818871401227,0.4471728933243798,10.983548447448737,62.15521725231829,0.13176646019167643
0.141525803392086,54.3055888919863,0.44934442576987305,10.948006720624438,61.991230988605004,0.132365791543517
0.142225881038345,54.0993669826045,0.4515671722967453,10.906432383693069,61.793697115322175,0.13297888592935656
0.142918601055401,53.9268691251098,0.45376655835089813,10.871656815622137,61.634021819768186,0.13358516710212526
0.143611578481898,53.7268557754767,0.45596676168002614,10.831334124336104,61.442654340262195,0.13419130600544327
0.144299168368663,53.5505488035163,0.45814985957050497,10.795790638788885,61.277848461549205,0.13479236958138238
0.144988720938684,53.3698798093115,0.4603391889803217,10.759367769557198,61.107910419514866,0.13539478624911147
0.145660506455888,53.1877675418797,0.4624721079974443,10.72265393644295,60.93512469928794,0.13598133221907477
0.146343800516202,52.9696736260267,0.4646415666389413,10.678686203006983,60.72145697656228,0.13657757375184884
0.14701455773689,52.756632504961,0.46677122081462574,10.635737113000136,60.51262550036547,0.13716253007792875
0.147682905883234,52.508717708367,0.4688932261792679,10.585757490006788,60.26335772374107,0.137745045355728
0.14836838759648,52.2673489606853,0.47106963061882395,10.537097550474156,60.02217124992473,0.13834214154043303
0.149043750351229,52.0820830781072,0.473213907365152,10.499747948546412,59.84459206617258,0.1389300750357321
0.149735675786583,51.8648402075064,0.475410770622401,10.45595178583329,59.630857105540514,0.1395320688141544
0.15041988511277,51.6791196625253,0.4775831352330447,10.418510523965102,59.45268690489145,0.14012699322535369
0.151097127608165,51.433724381897,0.4797333801559238,10.369038835390436,59.20521239819168,0.1407155115905874
0.151756758182998,51.182134288629,0.4818277072310186,10.318318272587607,58.9493690651582,0.14128839256835457
0.152398933537139,50.9895743915832,0.48386661398041625,10.279498197343173,58.76033115037309,0.1418457988001259
0.153098548509828,50.7843270624709,0.48608789151870385,10.238120335794134,58.55933382278357,0.14245270902198615
0.153795300401473,50.6017873434085,0.48830007877467674,10.201320328431155,58.38410442873946,0.14305676968404066
0.154511270823068,50.3660234951971,0.4905732848632409,10.153790336631735,58.14814179174451,0.14367711227932733
0.155197380244806,50.1008752881328,0.492751682277259,10.100336458087572,57.87639988082275,0.14427122136022977
0.155884955928444,49.8581302548548,0.4949347350728097,10.051399059378728,57.63026269230747,0.14486624620479077
0.156556360586928,49.6048104666354,0.4970664448634964,10.000329790073698,57.37075906089619,0.14544693525627522
0.157235823908011,49.3721738416406,0.49922374090793487,9.953430246474746,57.13524827376051,0.1460342510447607
0.157910883082467,49.1128690062327,0.5013670537868328,9.901154391656512,56.86832552172042,0.14661741857496438
0.158587955371763,48.8696552957442,0.5035167583053476,9.852122507622031,56.61979400881913,0.14720198377943347
0.159286901263007,48.6086096637677,0.5057359115100473,9.79949570821557,56.35132447181231,0.14780507579747595
0.159995476543502,48.3571542071341,0.5079856380256188,9.748802288158235,56.09408013879213,0.14841610557920618
0.16069944555585,48.0907707443796,0.5102207396398237,9.695099382066926,55.818930939354885,0.1490227937114866
0.16136693361914,47.833264323721,0.5123400142407695,9.643186087662153,55.551971512633656,0.1495977024114799
0.162058277636735,47.5426511325869,0.5145350314966336,9.584598468329519,55.2473312894181,0.150192810043651
0.162761600824615,47.2305918058059,0.5167680826181525,9.52168730805047,54.91791853601282,0.15079786613066487
0.163447833570208,46.9101033596268,0.5189468715854104,9.457076837300765,54.577458126312344,0.15138786697526038
0.164140436167914,46.5977321482632,0.5211458848331268,9.394102801089861,54.24630422751475,0.15198299166045703
0.164803192743345,46.3477782286634,0.5232501369601203,9.343712090898542,53.986040057307626,0.15255213947931728
0.165488391079669,46.0735210265646,0.525425641677949,9.288421838955424,53.698153892626074,0.1531402189804645
0.166199829889737,45.7793809067528,0.527684459899915,9.229123190801364,53.38790622591259,0.15375045393876413
0.166940295738751,45.4176648334786,0.5300354389705344,9.156201230429286,52.99970323254298,0.1543851915318825
0.16767722088981,45.1185957845832,0.5323751763251467,9.095908910171973,52.68395653619281,0.15501649423588865
0.168422673291095,44.8426602384178,0.5347419876992267,9.040280304065028,52.395180953256414,0.15565469676176846
0.169122620982431,44.5939254810998,0.5369643216192184,8.990135376989722,52.135767038358615,0.1562535709003535
0.169790251013215,44.2686934792242,0.5390840469669576,8.924568605411599,51.78508605708875,0.15682446010012677
0.170479984554451,43.9260086170377,0.5412739509603819,8.855483337194801,51.41451388760897,0.1574139078918594
0.171188413101048,43.5308664876272,0.5435232115958273,8.775822683905645,50.98284644255769,0.15801897099039153
0.171879948801011,43.1731474059748,0.5457188374432099,8.703706517044521,50.59374577169225,0.15860925314458454
0.172578106546259,42.8242527400286,0.5479354882843722,8.633369352389765,50.214781192161176,0.15920483451085646
0.173242019277995,42.4670656069315,0.5500434112076341,8.56136042635739,49.824145805487404,0.1597708734344327
0.173923693797965,42.1504473419864,0.5522077278085388,8.497530184144459,49.481408838941285,0.16035172252858726
0.17462946447339,41.7775676871426,0.5544485497030133,8.422357645727947,49.07316195934911,0.16095274847870034
0.175305704023779,41.4330369173308,0.5565956102754983,8.35290024253389,48.69648462396671,0.1615282873940896
0.176006806957178,41.0448334719018,0.5588216120890401,8.274638427935404,48.269003553380344,0.16212463768857638
0.176681297265687,40.6664213851657,0.5609631188185562,8.198350551249405,47.85141747064985,0.16269801613663948
0.177350128286415,40.2048560595819,0.5630866573093676,8.10529898161171,47.335192439485596,0.16326625922079302
0.178029006402406,39.7913791290435,0.565242095327639,8.021942032415168,46.875398818768545,0.16384270835782724
0.178725142512674,39.376976181906,0.5674523274777399,7.93839839827225,46.414631861735316,0.16443346673695994
0.179418076900648,38.9544606768045,0.5696523941595574,7.853219272443789,45.94359509813868,0.16502116166762706
0.179769368683265,38.7689099157055,0.5707677455693664,7.815812239006228,45.738372375790256,0.16531896910626112