File: example/data/02 processed data/test_ID_106.csv
Strain,Stress_MPa,Displacement(mm),Force(kN),True Stress (MPa),True Strain
8.50124530963979e-05,-1.18525351394823,0.0002699145385810633,-0.23894710841196318,-1.185354275256992,8.50088397426392e-05
9.5245780307086e-05,-0.813470726901281,0.00030240535247499803,-0.16399569854329826,-0.8135482065554217,9.524124471583563e-05
8.1481942483876e-05,0.372376428644338,0.0002587051673863063,0.07507108801469854,0.3724067705990792,8.147862301075999e-05
6.56938437459828e-05,2.73583938193505,0.00020857795389349538,0.5515452193981062,2.7360191097399214,6.569168599994213e-05
5.04565566474053e-05,6.46466930953229,0.00016019956735551183,1.3032773328017098,6.464995494485514,5.045528375824492e-05
4.34158227211434e-05,10.6927724071702,0.00013784523713963027,2.1556629172855124,10.693236642681427,4.3414880281606554e-05
7.46599088680707e-05,15.2819739995135,0.00023704521065612448,3.0808459583019214,15.283114950299629,7.465712195584114e-05
0.0001325051016408,19.9728413954402,0.00042070369770953996,4.026524825320744,19.975487898819356,0.00013249632361518948
0.0001853382304619,24.8357628050481,0.0005884488817165325,5.006889781497697,24.84036582137856,0.00018532105745397063
0.0002619035754226,29.891938217911,0.000831543851966755,6.026214744730858,29.899767023406582,0.00026186928466825796
0.0003478028153959,34.9947826675434,0.0011042739388819826,7.054948185776749,35.00695395147933,0.00034774234601715645
0.0004216664021778,39.9797585477447,0.001338790826914515,8.059919323225332,39.99661666869147,0.0004215775258837469
0.0005006108659265,44.9040121747578,0.0015894394993166373,9.052648854431174,44.92649161117618,0.0005004856021107869
0.0005909804686931,49.8284169412109,0.0018763629881005924,10.045408855348116,49.85786456240904,0.0005908059085068582
0.0006712172225419,54.7028550538571,0.0021311146815705326,11.028095578857592,54.739572552291456,0.0006709920570129219
0.0007579418919608,59.5708524026324,0.0024064655069755397,12.009483844370692,59.61600364720817,0.0007576547990623035
0.0008547900986832,64.2898102855659,0.00271395856331916,12.960825753570086,64.34476457884423,0.000854424973682217
0.0009310734462353,68.9083125263278,0.0029561581917970773,13.891915805307686,68.97247122634596,0.0009306402662149463
0.0010526158076178,73.527300237977,0.0033420551891865146,14.823103727976163,73.60469623649895,0.0010520621960580776
0.0011502064262607,78.1617703050611,0.0036519054033777227,15.757412893500318,78.25167247555389,0.0011495454456434478
0.0012389723777875,82.762513782304,0.003933737299475312,16.684922778512487,82.86505425079653,0.0012382054848850698
0.0013319156298381,87.3049269452828,0.004228832124735967,17.600673272169015,87.4212097420431,0.0013310294170354824
0.0014445963883065,91.7909058996577,0.004586593532873137,18.505046629370995,91.92350671079973,0.0014435539627460018
0.001547828571938,96.1932624896812,0.00491435571590315,19.39256171791973,96.34215316979065,0.0015466319199428189
0.0016501296703172,100.494904249404,0.00523916170325711,20.259772696679846,100.66073387262163,0.0016487697022297856
0.0017631786145748,104.623855063305,0.005598092101274989,21.09216918076229,104.808325607127,0.0017616260398712021
0.001868488530019,108.668766185854,0.005932451082810325,21.907623263068167,108.8718125290436,0.0018667450767361664
0.0019797389354839,112.634670932097,0.006285671120161382,22.707149659910755,112.85765817562668,0.0019777818349639023
0.0020943927106017,116.533016268211,0.006649696856160397,23.493056079671337,116.77708216802756,0.0020922025277240876
0.0022120534483326,120.379056126818,0.007023269698456005,24.26841771516651,120.64534103303035,0.0022096104601203943
0.0023229927381946,124.049750292154,0.007375501943767854,25.00842965889825,124.33791696125753,0.002320298761815581
0.0024385141578167,127.638493283747,0.007742282451068022,25.731920246003398,127.94974155670181,0.002435545806765816
0.0025508338838496,131.108211802156,0.008098897581222479,26.431415499314653,131.44264707127186,0.002547586029084278
0.0026432412397403,134.412346757996,0.008392290936175452,27.097529106411994,134.76763101607702,0.0026397540213026855
0.0027813764858433,137.525352673503,0.008830870342552477,27.725111098978203,137.90786245563638,0.002777515615630856
0.0029222775998693,140.453208591455,0.009278231379585028,28.31536685203733,140.8636518567516,0.0029180160469591404
0.003083406282293,143.38586497671,0.009789814946280275,28.906590379304735,143.8279818535712,0.0030786623343199817
0.0032449566652009,146.04321442772,0.010302737412012855,29.44231202862835,146.51711832978458,0.003239703155194963
0.0034483448338075,148.429465951815,0.010948494847338812,29.923380335885906,148.94130193391473,0.0034424129256925952
0.0036571806,150.374833173994,0.011611548405,30.315566367877192,150.92478109660618,0.0036505093753311036
0.0039108348435472,151.961444699559,0.01241690062826236,30.635427251431093,152.5557408123658,0.0039032074089176945
0.0041761518997367,153.195839107418,0.013259282281664023,30.88428116405547,153.83560820193821,0.004167455979308204
0.0044808017539878,154.126919717113,0.014226545568911264,31.07198701496998,154.8175318893182,0.004470792849282931
0.0047885327811799,154.733372729929,0.015203591580246182,31.194247942353687,155.47431855758876,0.004777104227562393
0.0050992420230576,155.110547389278,0.016190093423207878,31.270286353678443,155.90149361074486,0.0050862849173977705
0.0054315505319959,155.355701965019,0.01724517293908698,31.319709516147828,156.19952431067568,0.005416852858157508
0.0057765189369728,155.479987033626,0.01834044762488864,31.344765385979006,156.37812012304602,0.00575989882500356
0.0061309910778031,155.542029266887,0.01946589667202484,31.35727310020442,156.49565606054568,0.006112273019874598
0.0064795101593211,155.521274521585,0.02057244475584449,31.35308894355154,156.52897619983818,0.0064586083736725254
0.0068298100182747,155.478078972616,0.021684646808022172,31.344380720879386,156.53996471400527,0.006806592519951173
0.0071704861783246,155.401269693598,0.022766293616180603,31.32889597022936,156.51557235003006,0.007144900477445103
0.0075448648732849,155.272308779741,0.023954945972679557,31.302897449995786,156.44381736804712,0.0075165447388282755
0.0078966723698536,155.086682885233,0.025071934774285178,31.26547526966297,156.31135160890506,0.007865656825327305
0.0082692693298421,154.906198998085,0.02625493012224867,31.229089718013935,156.18716007846226,0.00823526624737319
0.0086408130559009,154.711972460082,0.027434581452485354,31.189933647952532,156.04880969161923,0.008603694898215197
0.0090192260820449,154.564249788364,0.028636042810492555,31.160152757334185,155.95829970140693,0.008978795780663913
0.0094157638768787,154.351273286944,0.02989505030908987,31.117216694647915,155.80460843030943,0.009371711878440487
0.0098173045012656,154.187291065488,0.03116994179151828,31.084157878802387,155.70099465210316,0.009769427858797659
0.0102055727616828,154.014146572622,0.032402693518342886,31.049251949040595,155.58594915179737,0.010153847530048938
0.0105842288468666,153.896609792316,0.03360492658880145,31.02555653413091,155.5254867291148,0.010528608021530066
0.0109702216079992,153.790872475974,0.03483045360539746,31.00423989115636,155.47799242832298,0.010910485210874775
0.0113641261549475,153.622017926388,0.03608110054195831,30.97019881395982,155.36779791828107,0.011300039541854105
0.011743016885227,153.505758357217,0.03728407861059572,30.946760884814946,155.30837906958538,0.011674602733934919
0.0121433657526421,153.381945516895,0.03855518626463866,30.921800216206034,155.2445185811585,0.012070226595107559
0.0125413636842336,153.277619945581,0.03981882969744168,30.90076818102913,155.19993032197226,0.012463372185560415
0.012949417258735,153.161166789845,0.041114399796483625,30.877291224832753,155.1445146464414,0.012866290415414698
0.0133375756819138,153.003094662747,0.04234680279007631,30.845423884009797,155.0437850173784,0.013249413269461609
0.0137165790448486,152.869046497999,0.043550138467394306,30.8183997739966,154.96588685779943,0.013623358254076295
0.014096837720629,152.70373057115,0.044757459762997075,30.78507208314384,154.85637028034614,0.013998401319768325
0.0144998569644123,152.537276585074,0.04603704586200905,30.751514959550924,154.7490452772986,0.01439573929250742
0.01489826645605,152.412273696648,0.04730199599795875,30.726314377244236,154.68295236135307,0.014788377377817656
0.0153347575550713,152.287435013266,0.04868785523735138,30.701146898674423,154.6227259078781,0.015218368517341414
0.0157389486494626,152.186909634234,0.04997116196204376,30.68088098226158,154.58217159008763,0.015616375835827393
0.0161310423750525,152.083656198769,0.05121605954079169,30.660065089671832,154.53692410146425,0.016002319554853577
0.0165315867636722,151.936185200849,0.05248778797465923,30.63033493649116,154.4479314290382,0.016396427645455736
0.0169251343648137,151.781294838136,0.0537373016082835,30.59910903936822,154.3502136473369,0.016783500162875078
0.017333280184699,151.624331549652,0.05503316458641932,30.56746524040984,154.25247857121983,0.017184772511012074
0.0177324229644925,151.510161801431,0.05630044291226369,30.544448619168488,154.19680407391266,0.017577037767405296
0.0181232306243286,151.379108830024,0.0575412572322433,30.518028340132837,154.12258733105585,0.017960962496005456
0.0185204056690779,151.23611416943,0.058802287999322335,30.489200616557092,154.03706835566285,0.018350991505211137
0.0189063420606693,151.12041186761,0.060027636042625024,30.465875032510176,153.97754606672825,0.018729838397878305
0.0193074490121556,151.031398380513,0.06130115061359403,30.44792991351142,153.94742940397933,0.019123425133893153
0.0197121114992772,150.966710458837,0.06258595401020511,30.434888828501546,153.94258308808068,0.01952034382979095
0.0201388727579472,150.872126631377,0.06394092100648235,30.415820728885606,153.9105211923272,0.019938767791335313
0.0205248144172297,150.768987632588,0.06516628577470429,30.395027906729737,153.86349312362046,0.020317018912585152
0.0209023902025558,150.654620629135,0.06636508889311465,30.371971518833618,153.8036622953432,0.02068693246010445
0.0212967499116956,150.595207816646,0.06761718096963353,30.35999389583583,153.80239629541694,0.021073143291649117
0.0217161421139766,150.505584526238,0.0689487512118757,30.341925840489584,153.7739851887569,0.021483705760255302
0.0221318582727174,150.414274212026,0.07026865001587775,30.32351768114444,153.7432216110802,0.021890503295487893
0.0225764319952948,150.31664777209,0.07168017158506099,30.303836190853346,153.71026134827727,0.022325356258816657
0.0230205877654903,150.231023827892,0.0730903661554317,30.286574403703025,153.68943029702143,0.0227596116599389
0.0234268160294531,150.147966550945,0.07438014089351358,30.269830056670514,153.66545534053046,0.02315661992757881
0.02384337503938,150.029214798124,0.0757027157500315,30.2458897033018,153.60641763341937,0.023563560855544997
0.0242437588869469,149.878847371249,0.0769739344660564,30.2155756300438,153.5124740091711,0.023954544076947026
0.0246456084979276,149.716009548734,0.07824980698092013,30.182747525024777,153.4058517059441,0.02434680499891799
0.0250603865802752,149.606151321351,0.07956672739237375,30.160600106384365,153.35533930825122,0.024751524591879324
0.0254667956797819,149.465544142572,0.08085707628330753,30.13225369914252,153.2719526164183,0.02514791934181893
0.0258685933731164,149.393596941943,0.08213278395964457,30.117749143495708,153.25819915378136,0.025539661911675827
0.0262615489214984,149.301727719135,0.08338041782575742,30.09922830817761,153.22262234569527,0.025922635237865938
0.0267017927189314,149.212400480528,0.08477819188260718,30.081219936874447,153.19663906925325,0.026351521419369472
0.0271082728804576,149.114242598728,0.08606876639545287,30.061431307903565,153.1564721774571,0.026747351757960135
0.0275440626908812,148.996782908708,0.0874523990435478,30.03775143439554,153.1007596378851,0.027171549866237273
0.0279450791004167,148.885983233704,0.08872562614382302,30.015414219914724,153.04661381211318,0.02756174060621266
0.0283119618712839,148.809388587816,0.08989047894132637,29.999972739303704,153.02247432360332,0.02791858585216205
0.0287312489269243,148.753099130666,0.09122171534298465,29.988624784742264,153.02696145044058,0.028326245797510766
0.0291463143845613,148.645442747312,0.09253954817098212,29.9669212578581,152.97790955345747,0.028729637593665723
0.0295721567926501,148.474875332345,0.09389159781666406,29.93253486700075,152.8655976254423,0.029143334191937004
0.0300645518173054,148.298676448649,0.09545495201994464,29.897013172047636,152.75720969117722,0.0296214719450444
0.0304605413379913,148.172238194126,0.09671221874812237,29.871523219935803,152.68564478078088,0.03000582982243804
0.0308762876675134,148.104338836915,0.09803221334435504,29.857834709522063,152.67725100765045,0.030409205272106835
0.0312794081505964,148.07596478445,0.09931212087814356,29.852114500545124,152.70769332423617,0.030800175254669736
0.0317207381712057,148.022018093208,0.1007133436935781,29.841238847590734,152.7173857727161,0.03122802789261402
0.0321600931824982,147.939617539897,0.10210829585443178,29.824626896043238,152.69736942536323,0.03165378408091199
0.0325739952041014,147.829979995726,0.10342243477302193,29.802523967138363,152.64539305512918,0.03205470934240256
0.0329849030282712,147.710567850602,0.10472706711476105,29.77845047868136,152.58278660740496,0.03245257534364993
0.0334324490013217,147.58082544624,0.1061480255791964,29.752294409961983,152.5148138665444,0.032885736611492335
0.0338578760637483,147.414004255527,0.10749875650240084,29.718663257914244,152.40512934167148,0.033297316023705344
0.0342918789726955,147.309717012132,0.1088767157383082,29.697638949645818,152.36124399941409,0.03371701765726571
0.0347138295644964,147.239593927613,0.11021640886727607,29.68350213580678,152.3508440963618,0.03412489531164777
0.0351302746620826,147.180696273253,0.11153862205211225,29.671628368687806,152.35119455828894,0.03452728803519149
0.0355424815470464,147.138580808912,0.11284737891187233,29.66313789107666,152.36825110217134,0.03492542616606988
0.0359654177575004,147.005102848394,0.11419020138006378,29.63622873423623,152.2922027848208,0.03533376273719531
0.0363716754314237,146.881990932712,0.11548006949477024,29.611409372034743,152.2243350336379,0.03572583956722721
0.0367929816294938,146.746046034768,0.11681771667364281,29.58400288060923,152.14527061072607,0.036132277331285184
0.03723822104708,146.666619950045,0.118231351824479,29.56799058192907,152.12822396397286,0.0365616242223553
0.0376628854919431,146.600436982067,0.11957966143691932,29.554648095584707,152.12183245319144,0.0369709588643335
0.0381032948809014,146.522758405887,0.12097796124686194,29.53898809462682,152.1057582761896,0.03739529316530713
0.0385443179439507,146.463035832367,0.12237820947204346,29.52694802380519,152.108353652526,0.037820038381544956
0.0389818940343806,146.336536127666,0.1237675135591584,29.501445683337465,152.04101147235298,0.03824128562682904
0.0394205384198244,146.233502747879,0.12516020948294246,29.480674153972405,151.99810616121727,0.038663383277512134
0.0398482431451466,146.123143843947,0.12651817198584045,29.458425798939714,151.94589440897383,0.03907478245317093
0.0402898182483125,146.037743302282,0.1279201729383922,29.441209049740053,151.92157743732466,0.03949934572422906
0.0407219724644419,145.970767499891,0.12929226257460302,29.427706727978027,151.914985074635,0.03991467659767269
0.0411616499077438,145.83183123818,0.13068823845708655,29.399697177617092,151.83451002101114,0.04033706087037074
0.0415957460360284,145.652059941391,0.13206649366439016,29.363455284184425,151.71056603633747,0.04075390839703485
0.0420270926149604,145.516488008535,0.13343601905249924,29.336123982520654,151.63212292707345,0.04116794358333882
0.042432936404158,145.370088181025,0.13472457308320165,29.306609777294643,151.5385678878773,0.04155734303324512
0.0428677484217857,145.306068793519,0.13610510123916958,29.29370346877343,151.53501279471823,0.04197436876684137
0.0433145512474669,145.253126882682,0.1375237002107074,29.283030379548695,151.54470089089673,0.04240271372268118
0.0437561442242978,145.188279840606,0.1389257579121455,29.269957215866167,151.54115915298925,0.04282588384756365
0.0441993229938892,145.141425986674,0.1403328505055982,29.26051147891348,151.55657875365267,0.04325039364502344
0.044649647904757,145.050329034431,0.14176263209760345,29.24214633334129,151.5267751542875,0.0436815640399328
0.0451136100010715,144.957607136099,0.14323571175340202,29.22345359863756,151.49716809112553,0.04412559721180775
0.0455710327563326,144.862146014425,0.144688029001356,29.204208636508085,151.463663615601,0.04456317900028496
0.0460197417218318,144.780655789423,0.14611267996681596,29.187780207147682,151.4434241751697,0.04499223900366427
0.0464592221859107,144.667042552293,0.14750803044026645,29.164875778542267,151.38816082520856,0.04541229624497598
0.0468852206016308,144.543176242753,0.14886057541017778,29.139904330539004,151.32011494735488,0.04581929894638861
0.0473311919010236,144.420669029647,0.1502765342857499,29.11520687637684,151.25627142996342,0.046245206511119484
0.0477744733621774,144.307223183509,0.15168395292491324,29.092336193795415,151.20142477345934,0.04666836556712142
0.048222709432588,144.264869641966,0.1531071024484669,29.083797719820346,151.2217125320407,0.04709607232257229
0.0486801934882621,144.161878403581,0.15455961432523216,29.06303468616193,151.17970653789865,0.04753241495178554
0.0491212871342118,144.083192327679,0.15596008665112246,29.04717157326009,151.16074418922076,0.04795294440276021
0.04954951269784,143.942120579762,0.15731970281564198,29.01873150888002,151.07438251118293,0.04836103658149126
0.049994447263901,143.801291237432,0.15873237006288568,28.99034031346629,150.99055730868264,0.04878487583535441
0.0504506352053904,143.694935203561,0.1601807667771145,28.968898937037892,150.94443596037806,0.049219248485674764
0.0509078824294102,143.632000229067,0.16163252671337738,28.956211246179905,150.94400120982937,0.04965444050778729
0.0513727998117834,143.551285283582,0.1631086394024123,28.93993911317013,150.92591672517966,0.050096738621335846
0.0518352221729575,143.475952530534,0.16457683039914006,28.924752030155652,150.9130604064309,0.05053646913186224
0.0522872500694482,143.372981888176,0.16601201897049803,28.903993148656287,150.86956084536556,0.05096612844058396
0.052750266038288,143.292157445843,0.16748209467156439,28.88769894108195,150.85085687231145,0.05140604076781205
0.0532031689480431,143.185999632644,0.16892006141003682,28.866297525941032,150.803948562094,0.05183615751133852
0.0536656080806656,143.087520501092,0.1703883056561133,28.84644413302015,150.76639929753782,0.05227513989608966
0.0541086593927306,142.954679006085,0.17179499357191966,28.819663287626735,150.6897650410224,0.05269553720848429
0.054526184336447,142.840830829429,0.17312063526821922,28.796711495212886,150.6293963020057,0.053091551672927645
0.0549815041684783,142.748473577321,0.1745662757349186,28.778092273187912,150.59699937235638,0.053523235180490146
0.0554452597331968,142.693882616605,0.17603869965289984,28.76708673550757,150.60558200062096,0.05396272503165718
0.0559553076137244,142.631116336446,0.17765810167357496,28.754433053427515,150.61208432634078,0.054445862052966226
0.0564417919952812,142.533303679461,0.1792026895850178,28.734714021779336,150.57813875813738,0.054906461426301276
0.0569162687718273,142.408053574346,0.18070915335055168,28.709463600588155,150.51338862685625,0.05535548782966055
0.0573929774638361,142.279203267591,0.1822227034476796,28.683487378746346,150.44503037430042,0.05580642347300192
0.0578512345195949,142.178663020802,0.1836776695997138,28.663218464993683,150.40387419890087,0.05623971345468067
0.0583252904318035,142.091797441888,0.1851827971209761,28.64570636428462,150.3793427956631,0.0566877440556715
0.05878216470317,142.00860342663,0.18663337293256474,28.62893445080861,150.35617654252133,0.05711934640759818
0.0592298248850915,141.845369983396,0.1880546940101655,28.596026588652634,150.24684640827357,0.057542063739500056
0.0597036086257699,141.70121270925,0.1895589573868194,28.5669644821848,150.16128645464002,0.05798925452056096
0.0601906786716766,141.584230187344,0.1911054047825732,28.54338080576855,150.1062810915271,0.05844877748582973
0.060675651206498,141.501858050114,0.19264519258063115,28.526774582902988,150.08757543423414,0.058906111865127654
0.0611605213782545,141.460665995778,0.19418465537595803,28.518470264748846,150.11247408259487,0.05936314072198373
0.0616424682707614,141.402088143012,0.19571483675966742,28.50666096963122,150.11846187478704,0.059817207258669
0.0621343748073258,141.3312673198,0.19727664001325942,28.49238349167168,150.11279725544279,0.06028044476590899
0.0626236554899547,141.226509746817,0.19883010618060618,28.471264364958305,150.07063003925037,0.06074099668222182
0.0630857129818332,141.136340034154,0.2002971387173204,28.453086150885444,150.04002667285505,0.06117572920587612
0.0635636814588029,141.013709116159,0.20181468863169919,28.428363757817653,149.97705960374282,0.061625232999277336
0.0640497652071465,140.91303690998,0.20335800453269012,28.40806824105197,149.93848383869022,0.06208216163691355
0.064514495027755,140.826504552259,0.2048335217131221,28.390623317735415,149.91185537997183,0.06251882200622877
0.0650165730804178,140.706947510866,0.2064276195303265,28.366520618190584,149.85523104662872,0.06299036061816538
0.0654806085119691,140.599372851904,0.2079009320255019,28.344833566943848,149.8059053426479,0.06342597296527237
0.0659669690767588,140.496589729937,0.20944512681870917,28.3241124895553,149.76472392004183,0.06388233940688216
0.0664613638713756,140.345396917274,0.21101483029161755,28.29363201852244,149.67294340946557,0.06434603124199446
0.0669417660764,140.255219529373,0.21254010729256997,28.275452257121596,149.6441516261024,0.06479639358223913
0.0674189002819646,140.138085240491,0.21405500839523758,28.251837984482986,149.5860408350251,0.06524349160183177
0.0678944339883659,140.034303404295,0.2155648279130617,28.23091556630587,149.5418531728847,0.06568889107237381
0.0683833992609491,140.000314150745,0.21711729265351337,28.224063332790195,149.5740115299737,0.0661466641892519
0.0688755060544973,139.891876260794,0.2186797317230289,28.20220225417607,149.52700003116928,0.06660716693978039
0.0693786183068736,139.832903109122,0.22027711312432366,28.190313266798995,149.5343167206718,0.0670777492301909
0.0698664881525643,139.736679306908,0.22182609988439164,28.170914548272656,149.49959035618278,0.06753386326095402
0.0703606063058182,139.586935746569,0.22339492502097277,28.14072624650831,149.40835717806888,0.06799560693601764
0.0708729066528311,139.519979075957,0.22502147862273872,28.127227781712932,149.40816552921225,0.06847411649948901
0.071380727796794,139.420440117901,0.22663381075482092,28.107160727768843,149.3723726032661,0.06894821643360374
0.0718826609500018,139.364919713187,0.2282274485162557,28.095967814178497,149.38284098525423,0.0694165985886105
0.0723887382235927,139.295895233628,0.22983424385990678,28.082052479099403,149.37934932931606,0.06988862585454557
0.0728820620107584,139.210498376721,0.23140054688415793,28.064836472746958,149.35644655196177,0.07034854335848749
0.073388118253854,139.117902403785,0.23300727545598643,28.046169124603058,149.3275034766221,0.0708201114370331
0.073856609407316,139.026598477561,0.2344947348682283,28.0277622530763,149.294631658546,0.07125647637938065
0.0743776720507375,138.926276870472,0.23614910876109155,28.007537417087157,149.25928993077392,0.07174158422645042
0.0748972165104077,138.802320083229,0.23779866242054445,27.982547728778968,149.19822750264953,0.07222504445999718
0.0753992981821682,138.701973101191,0.23939277172838402,27.962317777200106,149.16000452950277,0.07269203278226274
0.0759134759014443,138.582381271821,0.24102528598708564,27.938208064399113,149.10265153286414,0.07317004577531604
0.0764507405210591,138.488608316387,0.24273110115436264,27.91930343658362,149.0761649759057,0.07366927785385925
0.0769824636651336,138.428088097352,0.24441932213679918,27.907102560426164,149.0846233595403,0.07416311546521122
0.0774996209362558,138.344240077778,0.24606129647261216,27.890198799680046,149.06586624252017,0.07464319119640529
0.077989639036947,138.262992564085,0.2476171039423067,27.87381930091954,149.0460734463261,0.07509786115763621
0.0784952751846471,138.135663949744,0.24922249871125454,27.848149852268392,148.9786609042931,0.07556680592384502
0.078988861702294,137.942103532312,0.2507896359047834,27.8091280721141,148.83799327114932,0.07602436342595538
0.0794909754190054,137.803689605158,0.25238384695534216,27.781223824399856,148.75783930820987,0.07648961097391314
0.0799919988805894,137.654735049657,0.25397459644587134,27.751194586010854,148.666012461657,0.07695363266478705
0.0804833454883686,137.559924263631,0.25553462192557025,27.73208073154801,148.63120717349463,0.0774084831378841
0.0809894676839672,137.516732383329,0.2571415598965958,27.72337324847913,148.65413933669342,0.07787679548654222
0.0815094003478831,137.413118259938,0.2587923461045288,27.7024846412035,148.61357912923827,0.07835765832686144
0.0820429780908346,137.371994526487,0.2604864554383999,27.69419409653978,148.64240206371778,0.07885090060662928
0.0825805069875549,137.284737800054,0.26219310968548676,27.676603140490883,148.621781049236,0.07934754948018603
0.083092802447292,137.20624291321,0.2638196477701521,27.660778571303137,148.6070941501325,0.07982065451136562
0.0836192631061988,137.12885989002,0.2654911603621812,27.645178153828034,148.59547410461664,0.08030660802372831
0.0841210676158449,137.032191149256,0.2670843896803075,27.625689735690006,148.55948536646991,0.08076958277351512
0.0846570924944922,136.946705729431,0.2687862686700127,27.608455875053288,148.54021566318343,0.08126389325618308
0.0851876882823166,136.866170468192,0.27047091029635517,27.592219966387507,148.52548313443074,0.08175295662431042
0.0857148768755334,136.745185591126,0.27214473407981854,27.567829415171,148.4662823373913,0.08223864272744669
0.0862465919913825,136.64772848915,0.27383292957263944,27.548182063412643,148.43312937470293,0.08272826018530018
0.0867970338190203,136.549996076217,0.27558058237538946,27.52847920896535,148.4021307036315,0.08323486928681352
0.0873348525915779,136.497495290446,0.2772881569782598,27.517895050553918,148.4184839207567,0.08372961276294705
0.0878782142378218,136.41783904512,0.2790133302050842,27.50183635149619,148.40599513058774,0.08422920672533316
0.0884070952439484,136.333945215476,0.28069252739953615,27.484923355439964,148.38683329512384,0.08471524687294983
0.0889357050299121,136.198523762344,0.2823708634699709,27.457622390488552,148.3114354971813,0.08520080183129877
0.0894658493215071,136.036002893379,0.284054071595785,27.424858183305204,148.20657943053814,0.08568752963499701
0.0900037119876812,135.925017789768,0.28576178556088777,27.40248358641723,148.1587739428387,0.08618110172853906
0.0905307182520342,135.786564279624,0.2874350304502086,27.3745713587722,148.0794194728344,0.08666447522386746
0.0910960142351731,135.659209340986,0.2892298451966746,27.348896603142776,148.0172226062448,0.08718270869375709
0.0916460509040074,135.569128657869,0.29097621162022347,27.330736337426387,147.99350392385998,0.08768669557270309
0.0921905586620308,135.475345323967,0.2927050237519478,27.311829617311748,147.96489309431504,0.08818536636787341
0.0927163384625906,135.460013158624,0.2943743746187251,27.3087386527786,148.01936958678598,0.0886666498599991
0.0932412258932798,135.369599576127,0.2960408922111633,27.290511274547203,147.99162698928748,0.08914688556936112
0.0937854518081197,135.260547892385,0.29776880949078005,27.268526455104816,147.94601948828617,0.08964457124610409
0.0943343724601581,135.111555507774,0.299511632561002,27.23848959036724,147.85721930871568,0.09014629940327847
0.0948759307840938,134.969685953437,0.3012310802394978,27.2098886882129,147.77506053590616,0.09064105162893717
0.0954176953259309,134.899843103612,0.3029511826598306,27.19580836968818,147.77167523238833,0.09113574745092869
0.0959692948075962,134.811397423238,0.3047025110141179,27.17797772052478,147.74915216597276,0.0916391724468774
0.0965394000670682,134.752252085562,0.3065125952129415,27.166054020449298,147.7611536595885,0.09215922080395207
0.0970544806260403,134.655150216783,0.30814797598767796,27.146478283703456,147.7240358846943,0.09262884334709645
0.0976171193627418,134.563131785412,0.3099343539767052,27.127927367939062,147.6987970827329,0.09314157495489649
0.0981727871282593,134.478393872649,0.31169859913222325,27.110844204726043,147.6805126076588,0.09364769603299836
0.0987624779661649,134.39250374089,0.3135708675425735,27.093528754163422,147.66544043041736,0.09418452646349529
0.0993304545619446,134.304526636226,0.3153741932341741,27.07579256986316,147.64505631672913,0.09470131681390821
0.0998924206558022,134.205610563176,0.317158435582172,27.055851089536283,147.61173386792157,0.09521237561783523
0.100441141567846,134.073060614588,0.31890062447791107,27.029129019900942,147.53951187621223,0.09571113719911493
0.100977618475281,133.968027569741,0.32060393865901715,27.007954358059788,147.49579994556424,0.096198529173593
0.101536934787266,133.84022785346,0.3223797679495695,26.982189935257534,147.42995434092958,0.09670641805285561
0.102110199884697,133.761714462373,0.3241998846339129,26.966361635614394,147.42014986304565,0.09722670562643579
0.102682041728922,133.66907747438,0.3260154824893273,26.94768601883501,147.3944912654708,0.0977454319229589
0.103245343065155,133.558212680531,0.3278039642318671,26.925335676395047,147.34747616790136,0.09825614805292743
0.103794412976637,133.460593738836,0.32954726120082245,26.90565569774934,147.31305772147192,0.09875371038392457
0.104352673075575,133.373867971547,0.3313197370149506,26.88817178306388,147.29178761280676,0.09925934709115153
0.104922290717835,133.295637373567,0.3331282730291261,26.87240049451111,147.2813209894955,0.0997750073545567
0.10549656426852,133.22779515424,0.334951591552551,26.858723503094783,147.2828698080825,0.1002946134575449
0.106090764065636,133.109448917885,0.33683817590839427,26.834864901845616,147.2311320579392,0.10083196489178513
0.106648008034857,132.988772514597,0.3386074255106709,26.810536538942756,147.17176019427953,0.10133563390868605
0.107236509089912,132.875421635453,0.3404759163604706,26.787685001707324,147.12451799548913,0.10186727958791113
0.107843491939269,132.769180183075,0.342403086907179,26.766266724907922,147.0874721959318,0.1024153255855885
0.108407680389575,132.68467878672,0.3441943852369006,26.749231243402757,147.0687170372242,0.10292446324068617
0.10897614577623,132.58803702997,0.3459992628395302,26.729748265241952,147.03697028153218,0.10343719846712811
0.109517086967361,132.47907551821,0.3477167511213711,26.707781624471142,146.9877979530934,0.10392486387342054
0.110118082559099,132.367670223463,0.3496249121251393,26.68532231705014,146.9437442612859,0.1044663903500921
0.110708828620545,132.267048123557,0.35150053087023037,26.66503690170909,146.91017808641325,0.10499839585885594
0.111285162304373,132.135986060935,0.3533303903163843,26.6386147898845,146.8407607159745,0.10551714946404679
0.111857104120773,132.002528535537,0.3551463055834543,26.611709752764263,146.76794911414189,0.10603168408259646
0.112413108484797,131.921241277947,0.3569116194392305,26.59532224163411,146.75091808517394,0.10653162727515803
0.112997135148282,131.815955127235,0.35876590409579534,26.574096553650577,146.71078042344703,0.10705649829933307
0.113568323731725,131.739667201246,0.36057942784822683,26.558716907771192,146.70112037426682,0.10756956526863777
0.114158796632192,131.664264212527,0.3624541793072096,26.543515665245447,146.69489817449207,0.1080996776947937
0.1147594206507,131.578988984814,0.36436116056597245,26.526324179338502,146.6789175305161,0.10863861539864349
0.115348048282323,131.523982772791,0.36623005329637554,26.515234926994662,146.6950174879503,0.10916650712896818
0.115946386689551,131.395806422753,0.36812977773932437,26.489394574827006,146.6306754036309,0.10970282220437176
0.116544948707123,131.278106547657,0.3700302121451155,26.46566628000765,146.57790674162192,0.11023905007000721
0.117136311155241,131.156429676259,0.37190778791789014,26.441136222733814,146.51961003282776,0.11076854590503149
0.117744107701672,131.072121544656,0.37383754195280855,26.42413970340265,146.50509154049664,0.11131246454719895
0.118324777928042,131.007808020137,0.37568116992153333,26.411174096859618,146.50927781095928,0.11183183158741342
0.118950311046062,130.905027118679,0.3776672375712468,26.390453467125685,146.47622081193902,0.11239102355929274
0.119542052699132,130.813193327474,0.3795460173197441,26.371939774818763,146.45087097796866,0.11291972017352972
0.120148807731284,130.689756976093,0.3814724645468267,26.34705500638035,146.39197545946183,0.11346154052714687
0.120685990040128,130.574997714866,0.3831780183774064,26.323919539316986,146.33357058857203,0.11394098891813802
0.121294605727958,130.467271111932,0.3851103731862666,26.302201856165492,146.2922473218564,0.11448391574268674
0.121922872137089,130.369063284766,0.3871051190352575,26.282403158208826,146.26403391826662,0.11504406332691146
0.122528828631931,130.277613963462,0.3890290309063809,26.263966975033938,146.2403773993679,0.1155840228273604
0.123172769566831,130.148205086014,0.3910735433746884,26.237878145340424,146.17891996061027,0.11615751037625392
0.123757423413101,129.982543950441,0.39292981933659565,26.204480860408907,146.0688486784277,0.11667791271121845
0.124319607008365,129.79869732741,0.39471475225155883,26.167417381205855,145.93522036935133,0.11717805892451584
0.124953441734258,129.603300677614,0.3967271775062691,26.12802541660698,145.79767915740175,0.11774164967489148
0.125514852810459,129.513949962753,0.3985096576732073,26.11001231249101,145.7698743292291,0.11824057791059067
0.126108562131469,129.411212811762,0.4003946847674141,26.08930050285122,145.73107478314284,0.11876793904107971
0.126708109453878,129.382424923967,0.40229824751606263,26.083496864671748,145.77622738264117,0.11930020368926492
0.127305076222678,129.309421855133,0.4041936170070026,26.06877944599481,145.77116766071111,0.11982989605002947
0.127934386855975,129.219590947116,0.40619167826772057,26.050669534938585,145.7512200847152,0.12038798370318879
0.128539928466863,129.136997627863,0.40811427288228996,26.03401872177718,145.73625806537396,0.12092469854307157
0.129152114501637,129.036280721869,0.4100579635426974,26.01371419352879,145.70158922452518,0.12146700992843917
0.129753115236706,128.948102210585,0.4119661408765415,25.995937405653937,145.6795201762696,0.12199912676214947
0.130353522452348,128.83286990045,0.41387243378620486,25.97270657193072,145.62668829961873,0.12253043552409353
0.130951069067855,128.68272766217,0.4157696442904396,25.942437896693473,145.53386842009883,0.12305893277444731
0.131579974869213,128.586880348896,0.41776642020975124,25.923115078337432,145.50633883371424,0.1236148639907201
0.132211885064974,128.479505809301,0.4197727350812924,25.901468371155083,145.46602346456498,0.1241731398846813
0.132844267263459,128.386840566133,0.4217805485614823,25.88278705813241,145.44229632741147,0.1247315209334386
0.133483012420088,128.275662358677,0.4238085644337794,25.860373531509286,145.39828419049533,0.12529520401599076
0.134088977492396,128.165800269538,0.4257325035383573,25.838225334338862,145.35142137717503,0.1258296656246437
0.134719439349435,128.051829385614,0.4277342199344561,25.815248804139788,145.30290004811346,0.1263854303763845
0.135337480205561,127.909689170517,0.42969649965265616,25.786593336776228,145.2206641967313,0.12692994612493022
0.1359658547598,127.75529272628,0.43169158886236497,25.75546701361805,145.1256503018971,0.12748326241747243
0.136581703223025,127.624393758449,0.4336469077331044,25.729077781703317,145.05555083078397,0.12802525193592043
0.137200472992217,127.467042508393,0.43561150175028895,25.69735576969203,144.95558103146354,0.1285695167216498
0.137804053966264,127.373964411425,0.4375278713428882,25.67859122534328,144.926613077074,0.1291001363147596
0.138416766610127,127.265843957743,0.4394732339871532,25.656794141880994,144.88157057828275,0.12963849590898083
0.139026045700644,127.185101078896,0.4414076950995447,25.640516377505435,144.86714275393163,0.13017355136834
0.139686228543268,127.101105427643,0.4435037756248759,25.62358285421283,144.85537948851075,0.1307529864015007
0.140292710588081,127.004193653758,0.4454293561171571,25.604045440597613,144.82195623749723,0.1312849931220087
0.140932637107899,126.875820515117,0.44746112281757927,25.57816541584759,144.7567644855409,0.13184603066900055
0.141549667607117,126.756405505859,0.44942019465259647,25.554091349981174,144.69873257228627,0.1323866968664772
0.142184424102618,126.601376763589,0.45143554652581214,25.522837555539546,144.60212060931846,0.13294259040430287
0.142827567089716,126.419025508674,0.45347752550984827,25.48607554254868,144.47514735593066,0.1335055134931624
0.143463161340059,126.249364093634,0.4554955372546873,25.451871801276617,144.36149698367888,0.13406151825564808
0.144085713579884,126.095339198509,0.4574721406161317,25.420820382419414,144.2638761260237,0.1346058146088498
0.144722618886851,125.990246956175,0.45949431496575194,25.39963378636488,144.22388544987373,0.13516235341061109
0.145346231861883,125.901502858677,0.4614742861614785,25.381742976309283,144.2008118849338,0.13570697720237404
0.145960671817471,125.804555315286,0.4634251330204704,25.362198351561656,144.16707272680335,0.1362432999178773
0.146564383762823,125.621033932488,0.465341918446963,25.325200440789583,144.03260335845178,0.13676997853178183
0.147176607491414,125.472602194263,0.46728572878523944,25.295276602363426,143.93923411833438,0.1373037996959533
0.14777830929622,125.295222804217,0.4691961320154984,25.25951691733015,143.81113899311737,0.13782816888002014
0.148422077627581,125.174998676813,0.47124009646756965,25.235279733245502,143.75373204745532,0.138388893764394
0.14905468690327,125.055054478381,0.4732486309178822,25.21109898284161,143.69509646932747,0.13893959295007718
0.149679468942581,124.918683934572,0.47523231389269466,25.183606681209717,143.61644620690487,0.1394831808661542
0.15030778048171,124.756871810301,0.4772272030294292,25.150985356956685,143.5088003119486,0.14002954176873406
0.150933774039973,124.636257806539,0.4792147325769142,25.126669573798264,143.448078579499,0.1405735903258909
0.151574350154752,124.496604658266,0.4812485617413376,25.098515499106426,143.36709660581573,0.14113000628340663
0.152200065563525,124.39065782562,0.48323520816419185,25.07715661764499,143.32292410216937,0.14167321521904716
0.15282003088461,124.217086110006,0.4852035980586367,25.042164559777206,143.19994504573336,0.14221114140631988
0.153423604777357,124.024666149307,0.48711994516810847,25.003372695700293,143.05297751124192,0.14273456737675436
0.154046777634734,123.762855775574,0.48909851899028045,24.950591724355718,142.8281248986735,0.14327470247645288
0.154671093916175,123.588511177949,0.4910807231838556,24.915443853474518,142.70408139731381,0.14381553624774376
0.155311879553756,123.454038010962,0.4931152175831753,24.88833406300994,142.62791669294535,0.14437033311107697
0.155930732983098,123.348805313377,0.4950800772213361,24.867119151176805,142.58267493848132,0.14490584889014269
0.156563450937211,123.249421308244,0.4970889567256449,24.847083335741992,142.54577603427688,0.14545306580796355
0.15716934379177,123.102090910391,0.4990126665388697,24.817381527534828,142.44996575817197,0.14597680205770608
0.15780878436636,122.908244835717,0.5010428903631929,24.778302158880546,142.30424554184444,0.14652923975296947
0.158460306843289,122.738570161984,0.5031114742274425,24.744095744655976,142.18776165135856,0.14709180175976233
0.159097514576576,122.55727540281,0.5051346087806288,24.7075467212065,142.05583331267403,0.14764169764020557
0.159738230400426,122.354017474713,0.5071688815213525,24.66656992290214,141.89863170850646,0.1481943162045376
0.160344054041347,122.109146013892,0.5090923715812766,24.617203836400627,141.68862152128622,0.14871655945319548
0.16095294405753,121.854620294062,0.5110255973826577,24.5658914512829,141.4674801774037,0.14924117136683374
0.161554973939599,121.671747509122,0.5129370422582268,24.529024297838998,141.32842350714367,0.14975960223278506
0.162157382627107,121.488472860293,0.5148496898410647,24.492076128635066,141.18872563868243,0.1502780904176941
0.162786433495346,121.359681911932,0.5168469263477236,24.466111873445495,141.11539170050506,0.15081922253385696
0.163396935356927,121.187281595363,0.5187852697582432,24.431355969625184,140.98891201228227,0.15134411827833932
0.164026436204669,121.014603747328,0.520783934949824,24.396544115461325,140.8641979287224,0.1518850605673822
0.164623362806189,120.82587414416,0.52267917690965,24.358496227462656,140.71663585976899,0.15239774101838716
0.165253012970134,120.633363673576,0.5246783161801755,24.31968611659292,140.56839048535633,0.15293824195296057
0.165883861613697,120.423338164492,0.526681260623488,24.277344973961586,140.39962652763003,0.15347947886259133
0.166548844343321,120.201934798556,0.5287925807900442,24.23271005538889,140.2214281270867,0.1540496841645003
0.167155981364669,119.967556241226,0.530720240832824,24.185459338231162,140.02085083664926,0.15457000449666702
0.167762801662372,119.702929714772,0.5326468952780311,24.132110630498037,139.78462857091614,0.1550897830138267
0.168377966473944,119.463035718364,0.5346000435547722,24.083748000822183,139.57797874142625,0.15561643349155563
0.168981898660797,119.239986037959,0.5365175282480305,24.03878118525253,139.38938527494022,0.15613319790537253
0.169618583689017,119.039458708616,0.5385390032126289,23.998354875656986,139.23076309787865,0.15667769881414742
0.170246406961882,118.82982259317,0.5405323421039754,23.956092234783075,139.06017292957506,0.1572143308766297
0.170844753262904,118.585783726748,0.5424320916097202,23.9068939993124,138.84554268803237,0.15772549962068935
0.171463082516099,118.288557647586,0.5443952869886144,23.846973221753338,138.57067836822438,0.1582534654654114
0.172042989426082,117.961884752575,0.5462364914278104,23.78111596611912,138.25640004374296,0.1587483708797924
0.172647854477673,117.624966283397,0.5481569379666118,23.713193202732835,137.93266434523412,0.1592643152880555
0.173241949847087,117.324248389188,0.5500431907645011,23.6525684752603,137.64972994447487,0.15977081425575596
0.17381830350944,116.99494718366,0.5518731136424719,23.586181352225857,137.33081042230032,0.16026194240051822
0.174418376634233,116.627866460229,0.5537783458136898,23.512177878382168,136.96990959853628,0.16077302643470362
0.174987271769528,116.325679683108,0.5555845878682514,23.451257024114575,136.68119300759108,0.16125731500087803
0.175601457127412,116.025501984075,0.557534626379533,23.39074119998952,136.399749196418,0.1617798950373692
0.17618914457713,115.795267363502,0.5594005340323878,23.344325900482005,136.19713646635748,0.16227967376896602
0.176778974055999,115.496703443651,0.5612732426277968,23.28413541424004,135.9140921852696,0.1627810230958462
0.177355826413294,115.206556492567,0.5631047488622084,23.22564178890151,135.63911052753605,0.16327109899865797
0.177922688445674,114.850998683164,0.5649045358150149,23.15396133452586,135.28559713954309,0.16375245357286142
0.178551195638263,114.52850433589,0.5669000461514849,23.088946474115424,134.97770571972515,0.16428588380668455
0.179140692215152,114.185365367697,0.5687716977831075,23.019769658127718,134.6406107605063,0.164785946255226
0.179729775762305,113.807271610636,0.5706420380453183,22.943545956704217,134.26182701733535,0.16528540866098024
0.180283542721741,113.446845334858,0.5724002481415276,22.870884019507372,133.89944452243162,0.16575470005460247
0.180859263639597,112.990427283984,0.5742281620557205,22.778870140451176,133.42579276088878,0.166242363001303
0.18147814218759,112.570607005682,0.5761931014455982,22.69423437234549,132.99971163000248,0.16676631742087467
0.182141438386582,112.136202407002,0.5782990668773978,22.606658405251604,132.56085160862224,0.16732757205072746
0.182797800874056,111.722971135695,0.5803830177751278,22.52335098095611,132.1456845664157,0.1678826497401923
0.183411725756615,111.253077924869,0.5823322292772526,22.428620509653594,131.6581969428044,0.1684015597432375
0.183974124562053,110.755970217906,0.5841178454845183,22.32840359592985,131.13220287876607,0.16887668196798342
0.184532246322946,110.19788364413,0.5858898820753534,22.21589334265661,130.53294665301593,0.1693479678197625
0.185086261448742,109.596928515497,0.5876488800997558,22.094740788724195,129.88181428069538,0.16981556640921783
0.185648146659669,109.011831571523,0.5894328656444491,21.976785244819038,129.24967606675224,0.17028958426590057
0.186239502266534,108.496865853935,0.5913104196962454,21.8729681561533,128.70326814805077,0.17078822139096478
0.186817277425747,107.97934350966,0.5931448558267467,21.768635651547456,128.1517504823542,0.17127516732127215
0.187424571926925,107.502319632415,0.5950730158679868,21.672467637894865,127.65089587067183,0.1717867365319553
0.188033193129088,106.95597445146,0.5970053881848544,21.562324449414337,127.06724785180117,0.17229916089447916
0.188659914922996,106.309230911035,0.5989952298805122,21.431940951664657,126.36552137023999,0.17282655065827413
0.189287256041356,105.669752570921,0.6009870379313053,21.303022118297676,125.67169008163965,0.17335418318146398
0.18990871090167,105.037198373782,0.6029601571128022,21.175499192154454,124.98467731366993,0.17387659065279637
0.190521298349736,104.280968895254,0.6049051222604117,21.023043329283208,124.14871448234624,0.1743912770407248
0.191138597005249,103.557554407097,0.6068650454916655,20.877202968470755,123.35140006576427,0.17490965388415244
0.191745618134532,102.79960662455,0.6087923375771391,20.72440069550928,122.51098074076107,0.17541913826325645
0.192304768097058,102.00692476853,0.6105676387081591,20.564596033335647,121.6233427804362,0.17588821389689885
0.192880185236044,101.195929279146,0.6123945881244397,20.401099342675835,120.71461886364129,0.1763707065852289
0.193444079532027,100.380835823982,0.6141849525141857,20.236776502114772,119.79891421260771,0.17684331151558483
0.194026384340579,99.4328983153985,0.6160337702813383,20.04567230038434,118.72550406003973,0.17733111216393638
0.194634890225356,98.5038001537717,0.6179657764655052,19.858366111000375,117.67607648348148,0.17784060750713943
0.195242683045425,97.4349487600524,0.6198955186692243,19.642885670026562,116.45840957835853,0.17834924681148742
0.1959073283204,96.3050696644076,0.62200576741727,19.41510204434457,115.17193856607169,0.1789051678444072
0.196567464939519,95.0297462038257,0.6241017011829727,19.15799683469126,113.7095025089576,0.17945701201658526
0.19727015550311,93.6445671869073,0.6263327437223742,18.878744744880514,112.11784551788993,0.18004409493129345
0.197924484475314,92.1693930569282,0.6284102382091219,18.581349640276727,110.4119726621233,0.18059046304481544
0.198616063793454,90.4432573174388,0.6306060025442164,18.233360675195662,108.406741082487,0.18116761108250382
0.199340383506687,88.6054330073763,0.6329057176337313,17.862855294287062,106.26807400384276,0.18177172525319868
0.199722489083498,87.5572066200786,0.6341189028401061,17.651532854607847,105.04434986343884,0.18209027095236135