File: example/data/02 processed data/test_ID_140.csv
Strain,Stress_MPa,Displacement(mm),Force(kN),True Stress (MPa),True Strain
3.77533141911029e-05,0.0597770764517563,0.00011986677255675169,0.012051058612674071,0.059779333234505,3.7752601552661335e-05
8.04271918396404e-05,-0.0086401557197827,0.00025535633409085826,-0.0017418553931081923,-0.008640850623244298,8.042395774634954e-05
0.0001262187601505,-0.126421033391402,0.00040074456347783744,-0.025486480331706644,-0.12643699009749362,0.00012621079523301003
0.0002116969561455,-0.311235681943324,0.0006721378357619625,-0.06274511347977413,-0.31130156958983524,0.00021167455150674353
0.0002988262878016,-0.517851974495161,0.00094877346377008,-0.10439895805822445,-0.5180067222783301,0.00029878164811929063
0.0003661927442041,-0.72022797532323,0.0011626619628480174,-0.14519795982516318,-0.7204917175819662,0.00036612571200503595
0.0004517698419623,-0.910710964946015,0.0014343692482303024,-0.18359933053311664,-0.9111223966947221,0.00045166782469172046
0.000523583223541,-1.07691983469588,0.001662376734742675,-0.2171070386746894,-1.0774836918544253,0.0005234462016712305
0.0006094238624871,-1.24278493937192,0.0019349207633965423,-0.25054544377737903,-1.243542322169913,0.0006092382391767939
0.0007350106245893,-0.905239993298271,0.0023336587330710272,-0.18249638264893142,-0.9059053543111484,0.0007347406365681736
0.0008248635154626,0.287170015530013,0.002618941661593755,0.05789347513085062,0.28740689159855853,0.0008245235025163913
0.000944197971633,2.2874430464653,0.002997828559934775,0.46114851816740454,2.2896028455499984,0.0009437524971168068
0.0010531549406675,5.50775231942723,0.0033437669366193122,1.1103628675965298,5.513552835994409,0.0010526007620595712
0.0011418189846767,8.80165158151303,0.003625275276348522,1.7744129588330269,8.81170147438531,0.00114116760517109
0.0012151627034686,12.329010017466,0.003858141583512805,2.485528419521146,12.343991770609916,0.001214424990837485
0.0012980309068754,15.9010750748804,0.0041212481293293945,3.205656735095889,15.921715161780138,0.0012971891930593322
0.001381675044256,19.5103532733326,0.0043868182655128,3.9332872199038524,19.53731024155498,0.0013807214095996824
0.0014637193825919,23.4737915165033,0.004647309039729282,4.732316369727066,23.50815056012893,0.001462649189557355
0.0015541482146732,27.4979014882092,0.0049344205815874094,5.543576940022976,27.540637302714362,0.0015529417761644185
0.001628924772714,31.6220731510834,0.005171836153366949,6.375009947258413,31.67358312940377,0.001627599513725953
0.0017132637737773,35.6830760103459,0.005439612481742928,7.193708123685733,35.74421053181137,0.0017117978115458907
0.0017936986386892,39.7346572306707,0.00569499317783821,8.010506897703213,39.80592923125414,0.0017920918823569043
0.0018810486867251,43.5230227177085,0.005972329580352192,8.774241379890034,43.604891642433955,0.0018792817301181482
0.0019700786415343,46.9967505712989,0.0062549996868714024,9.474544915173858,47.08933786582092,0.001968140581610143
0.0020634668175028,50.3850441431391,0.00655150714557139,10.157624899256843,50.48901200982688,0.002061340793999611
0.0021691701994671,53.4392754435439,0.0068871153833080425,10.77335792941845,53.555194327317146,0.002166820946462931
0.0022832079506534,56.4859715984242,0.0072491852433245445,11.387571874242319,56.61494081787811,0.0022806053920825637
0.0024185433977639,59.4019879547952,0.007678875287900382,11.975440771686714,59.54565424057733,0.0024156234287806356
0.0025829693095077,62.17532414784,0.008200927557686947,12.534545348204546,62.33592110192256,0.0025796391774673194
0.0027776818082774,64.855431838252,0.008819139741280745,13.074855058591604,65.03557959143708,0.0027738311790637894
0.0029842917223611,67.4635195381281,0.009475126218496492,13.600645538886624,67.66485036104707,0.0029798475634014426
0.0032251126129094,69.9038479146773,0.010239732545987344,14.092615739598944,70.12929569627784,0.0032199230920922314
0.0034831016849457,72.282138043342,0.011058847849702597,14.572079029537747,72.53390408015224,0.0034770497352378943
0.0037802612217004,74.3824553156855,0.012002329378898769,14.995502991642198,74.66364042709026,0.003773133990465148
0.0040980043172916,76.4514544430129,0.013011163707400828,15.412613215711401,76.7647528333836,0.004089630367458649
0.0044308815136151,78.2368645462918,0.014068048805727942,15.772551892532427,78.58352282309318,0.004421094058839505
0.0047821731677664,79.988374115985,0.01518339980765832,16.125656221782577,80.37089237241572,0.004770774902204856
0.0051364511106421,81.3983854012698,0.016308232276288664,16.409914496895993,81.81648422836864,0.0051233045442166435
0.0055004840022267,82.4081754807416,0.01746403670706977,16.613488176917507,82.86146033162612,0.005485411585229371
0.0058769232534923,83.1774061892894,0.01865923132983805,16.768565087760745,83.6662334218884,0.005859721502704577
0.0062513984371083,83.6888832913606,0.01984819003781885,16.871678871538297,84.21205584557154,0.006231939500833801
0.0066535220167368,84.039798448411,0.021124932403139337,16.94242336719966,84.59895909766962,0.006631485034149254
0.0070543715026271,84.2635338033964,0.022397629520841043,16.987528414764714,84.85796007496972,0.00702960582661856
0.0074348397274621,84.3662773835542,0.023605616134692167,17.00824152052453,84.99352713430355,0.007407337538695248
0.007815096646087,84.4378170338541,0.024812931851326225,17.02266391402499,85.09770673455829,0.0077847169557833384
0.008176742553554,84.4507236985893,0.02596115760753395,17.025265897635602,85.14125552473398,0.008143494113819616
0.0085779878926926,84.4805957207211,0.027235111559299006,17.031288097297374,85.20526924798091,0.008541406005013347
0.0089684582241368,84.4917791296715,0.028474854861634338,17.033542672541774,85.24954012107895,0.008928480450878918
0.009355256165374,84.5311571925599,0.02970293832506245,17.041481290020077,85.3219678220518,0.009311766782219106
0.0097531746317257,84.5161259275556,0.030966329455729094,17.038450986995212,85.34042646292397,0.009705919434383632
0.0101469135406988,84.4650400192489,0.03221645049171869,17.02815206788058,85.32209947753589,0.010095779226227604
0.0105393251805562,84.3861893832677,0.033462357448265936,17.01225577966677,85.27556287392595,0.010484173661019754
0.0109548908449936,84.2788008240974,0.034781778432854675,16.990606246138036,85.20206588767235,0.01089532068978406
0.0113604843774479,84.1961375354739,0.03606953789839708,16.97394132715154,85.1526464405871,0.011296438678463602
0.0117685069704162,84.1158764598487,0.037365009631071436,16.9577606943055,85.10579473828909,0.01169979664549893
0.0122001219019774,84.0376697056233,0.03873538703877824,16.941994212653658,85.06293952039002,0.012126300230531782
0.0126062543714021,83.9403125993286,0.04002485762920167,16.922367020024648,84.99848553197074,0.01252745708150794
0.0130367776777587,83.8939790556346,0.041391769126883866,16.913026177615937,84.98768620908545,0.012952530311121951
0.0134615638465954,83.8084122932578,0.04274046521294039,16.895775918320773,84.93660458622529,0.013371762013762951
0.0138754807777919,83.7466267710016,0.04405465146948928,16.883319957033923,84.90865148096755,0.013780097606549909
0.0143013602974429,83.6492081027207,0.0454068189443812,16.863680353508492,84.8455055663935,0.014200060518348616
0.0147149442457464,83.5493413818333,0.046719947980244814,16.84354722257759,84.7787652820358,0.014607729942300874
0.0151320722468205,83.4276543036377,0.048044329383655084,16.81901510761336,84.6900875959431,0.015018724469037664
0.0155563051294523,83.2852788793405,0.04939126878601105,16.790312222075045,84.58089009037904,0.015436546222025343
0.0160035511127831,83.1601580050282,0.05081127478308634,16.765087853813686,84.49101584420879,0.015876844339929207
0.0164456690852968,83.0055716831979,0.05221499934581734,16.733923251332698,84.37065384733565,0.016311903651712704
0.0168900315347765,82.9250439669201,0.05362585012291539,16.71768886373109,84.3256505745441,0.016748980968968544
0.017331265522379,82.8227934264573,0.055026768033553324,16.697075154773792,84.25821725063636,0.017182792172460114
0.0177635686963066,82.7230259980642,0.05639933061077345,16.67696204120974,84.19248215314718,0.017607640364457135
0.0182024625184689,82.5995476084195,0.05779281849613875,16.65206879785737,84.10306277780424,0.0180387809849113
0.0186504343045939,82.4660669714556,0.05921512891708563,16.62515910144545,84.00409493586498,0.018478647598790584
0.0190938819766602,82.3419860772592,0.06062307527589613,16.600144393175455,83.91421424114218,0.018913881475311145
0.0195305459995061,82.223051614762,0.06200948354843186,16.57616720553602,83.82891270654387,0.019342272328998128
0.0200000515970573,82.0848833260448,0.06350016382065693,16.548312478530633,83.72658522790412,0.01980267788152874
0.0204310201967405,81.9241367430483,0.06486848912465108,16.515905967398538,83.59793043544605,0.020225106859453616
0.0208963938681519,81.7720999895238,0.06634605053138228,16.485255357887997,83.48084199833079,0.020681058879954733
0.0213388122179646,81.6314416312249,0.0677507287920376,16.45689863285494,83.37335963527534,0.02111432763902335
0.0217809994225242,81.5280516422149,0.06915467316651433,16.436055211070524,83.30381408795351,0.021547182539596976
0.022249838232895,81.3889490156054,0.07064323638944162,16.40801212154605,83.19983996514797,0.02200592201647353
0.0227142818463118,81.2517722123452,0.07211784486203997,16.380357278008795,83.09734786688873,0.02246015357666763
0.023194866589338,81.0697159054442,0.07364370142114815,16.34365472653755,82.95011715030651,0.022929954254017344
0.0236716085688071,80.9028967739165,0.07515735720596253,16.310023989621566,82.81799847843125,0.023395780426731547
0.0241431244489478,80.7339501951377,0.07665442012540927,16.27596435933976,82.68312000195407,0.023856286820079526
0.0246238978254639,80.5799055995928,0.07818087559584788,16.244908968877912,82.5640969618627,0.024325616304705117
0.0251034017050032,80.4507490323947,0.07970330041338515,16.21887100493077,82.47033650282329,0.024793487214553697
0.0256015258383978,80.3175260313034,0.08128484453691301,16.192013247910765,82.37377724926999,0.025279294935109674
0.0260761963883765,80.1897818070688,0.08279192353309539,16.16626001230507,82.28082630581098,0.025742009476780146
0.0265611158800246,80.0441903807744,0.0843315429190781,16.136908780764116,82.17025339700089,0.026214493824376236
0.0270636593772743,79.9223949573217,0.08592711852284589,16.112354823396053,82.08538743106264,0.02670391478709151
0.0275152999998013,79.7750220560609,0.08736107749936912,16.08264444650188,81.9700557204242,0.027143557788145686
0.0280134530859924,79.6474905397645,0.08894271354802587,16.056934092816526,81.87869177941721,0.02762825360686941
0.0284899430580164,79.4865653166475,0.09045556920920207,16.024491567836137,81.75113303639608,0.028091651801537235
0.0290083268558282,79.3382491846744,0.09210143776725453,15.994591035630359,81.63971904919256,0.028595549001705623
0.0295130114224845,79.1973446104193,0.09370381126638828,15.96618467346053,81.53469674653704,0.029085885990089922
0.0299909015477472,79.0456211688582,0.09522111241409735,15.935597227641816,81.41627061111396,0.02954996875374024
0.0304931110451003,78.9033439334499,0.09681562756819344,15.9069141369835,81.30935236184233,0.030037436265478744
0.0309733786298223,78.6974511741714,0.0983404771496858,15.865406156712957,81.13497712659097,0.030503383779849284
0.031474348940606,78.5293708936151,0.09993105788642405,15.831521172152803,81.001031715207,0.030989185493938167
0.0319773639383157,78.3962349973762,0.10152813050415234,15.804680975471042,80.90313993528102,0.031476732650514795
0.0324880631635899,78.2834980787134,0.10314960054439794,15.78195321266862,80.82677730896141,0.03197148468558149
0.0330052803700808,78.1531033622623,0.10479176517500653,15.755665637832081,80.73256845052568,0.0324723018089295
0.0335150406575794,78.0076432969948,0.10641025408781458,15.726340888674152,80.62207263369554,0.03296565316158841
0.0340362476347945,77.8385498107483,0.10806508624047254,15.692251641846859,80.4878819676402,0.033469831211445734
0.0345637495758039,77.6987699862965,0.10973990490317738,15.664072029237376,80.38433081445085,0.033979839867691396
0.0350959882476358,77.5313080766183,0.11142976268624366,15.63031170824625,80.25234595369913,0.034494164685281284
0.0356197570544861,77.3940175380285,0.11309272864799336,15.602633935666548,80.15077364020371,0.03500004659515579
0.0361568584850048,77.2718767500739,0.11479802568989024,15.5780103528149,80.06578506259704,0.0355185401803452
0.0366784698005337,77.1336951381209,0.1164541416166945,15.550152939845173,79.96284104584805,0.03602182311789585
0.0372228164852839,76.9840291688331,0.11818244234077638,15.519980280436753,79.84959155888232,0.03654677259437315
0.0377435031774508,76.8245862316688,0.11983562258840628,15.48783658430443,79.72421524621015,0.03704864744232804
0.0382732431798219,76.6719806095647,0.12151754709593453,15.457071290888244,79.60646596851315,0.03755899015974399
0.0387889713309136,76.5616416174329,0.12315498397565068,15.434826950074473,79.53138893917918,0.03805558401050798
0.0393148220108107,76.4285975443591,0.12482455988432396,15.408005264942798,79.43337425335146,0.03856167104312444
0.0398497068724,76.2852255804122,0.12652281931987,15.3791014770111,79.32516945848654,0.0390761900876338
0.0403679181255842,76.1412070156819,0.1281681400487298,15.350067334361473,79.2148690264741,0.03957441802078524
0.0409044801401634,76.0032087941508,0.1298717244450188,15.3222468929008,79.11208053885983,0.040090027632399286
0.0414613047216065,75.8503287421794,0.13163964249110063,15.291426274423369,78.99518233539294,0.040624827616880965
0.042006826929096,75.7055953610586,0.1333716754998798,15.262248024789415,78.88574720295476,0.041148495065083036
0.0425590687940928,75.5421040635382,0.13512504342124462,15.229288179209302,78.75710566722886,0.041678333799420014
0.0430712682315108,75.3819480853487,0.13675127663504677,15.197000734006297,78.62874419114658,0.042169503724044044
0.0436155526223076,75.213101758721,0.13847937957582662,15.162961314558155,78.49356275636548,0.04269117702710127
0.0441721824703709,75.047399251902,0.1402466793434276,15.129555689183443,78.36240666558379,0.043224401599595806
0.044750722607441,74.8881788911471,0.14208354427862516,15.097456864455257,78.23947901128125,0.043778314001490654
0.0453339628710422,74.7306498775873,0.14393533211555898,15.0656990153216,78.1184863844667,0.04433641605619911
0.0459028817395963,74.6090959037952,0.14574164952321825,15.04119373420511,78.0338684097653,0.0448805140468744
0.0464912264527244,74.4784811860138,0.14760964398739998,15.014861807100381,77.94107712068774,0.04544287916378052
0.0470531681467427,74.3780495631285,0.14939380886590806,14.994614791926706,77.87777243564915,0.04597971201906978
0.0476102762025628,74.2580514649743,0.15116262694313687,14.97042317533882,77.79349780548584,0.04651164288410592
0.0481527916491933,74.1161081581572,0.15288511348618872,14.941807404684491,77.68500567214602,0.04702936883039299
0.048698560110106,73.968424967852,0.15461792834958654,14.912034473518963,77.5705807573988,0.047549928833637164
0.0492571839443764,73.8380439105165,0.15639155902339505,14.885749652360127,77.47509802150977,0.048082469950441735
0.0498370808626448,73.7274310963001,0.15823273173889724,14.8634501090141,77.40179104164147,0.04863499104751031
0.0504154870147978,73.6145934616521,0.160069171271983,14.840702041869065,77.32590904241763,0.04918578781892954
0.0509828753421391,73.475329676671,0.16187062921129164,14.812626462816873,77.22131325029929,0.04972579808189848
0.0515704285372676,73.3293478459804,0.16373611060582463,14.783196525749647,77.11097373875596,0.0502846930305674
0.0521384914387566,73.1266498323002,0.1655397103180522,14.742332606191722,76.93936303852654,0.050824751505294426
0.0526970477664141,72.9562993075552,0.16731312665836476,14.70798994040313,76.80088089702625,0.05135548783159164
0.0532884933740655,72.7881554177448,0.16919096646265797,14.674092132217352,76.66692655543376,0.051917168443017414
0.0538693162183752,72.6670164315582,0.17103507899334125,14.649670512602134,76.58153891835568,0.052468454024358895
0.0544636120734541,72.6003573400305,0.17292196833321674,14.636232039750148,76.55443503859206,0.053032213061505365
0.0550713054256478,72.4802298001631,0.17485139472643177,14.612014327712883,76.47181067280901,0.053608352725241074
0.0556726826099578,72.3526887672698,0.176760767286616,14.586302055481593,76.38075704498706,0.05417817758698762
0.0562721393349398,72.1908188739552,0.17866404238843384,14.553669084989368,76.2531506923338,0.054745859786685044
0.0568751801887837,72.0437572213957,0.18057869709938823,14.524021455833372,76.14125889483957,0.055316611162741586
0.0574861677254365,71.9037613142124,0.1825185825282609,14.495798280945221,76.03723299721098,0.05589455168767808
0.0581047321588855,71.7593826382534,0.18448252460446146,14.466691539871887,75.92894234633609,0.056479319235231217
0.058713328987925,71.6424528349147,0.18641481953666186,14.443118491518806,75.84881973771294,0.057054330245368295
0.0593147835942667,71.5221852171375,0.18832443791179676,14.41887253977492,75.76450815548108,0.057622268526201864
0.0599114274695896,71.4119695089208,0.19021878221594696,14.396653052998433,75.69036254061506,0.058185345641775556
0.0605212762396665,71.2908538264011,0.19215505206094113,14.372236131402463,75.60546728419041,0.05876055728214041
0.0611328953765529,71.1559589751429,0.19409694282055545,14.345041329388808,75.5059287705886,0.05933710661992692
0.0617195997325397,71.0363485623572,0.19595972915081356,14.320927870171213,75.42068356208706,0.05988985757391617
0.0623348094563397,70.8973047787063,0.19791302002387853,14.29289664338719,75.31667476305499,0.0604691362763279
0.0629402054480951,70.7672552668142,0.19983515229770193,14.266678661789742,75.22136085230528,0.06103884702329893
0.0635233228406653,70.6065383532083,0.2016865500191123,14.234278132006791,75.09170028368096,0.06158728568629866
0.0641238854604068,70.4638007704145,0.20359333633679158,14.205502235315562,74.98221346012147,0.06215181784496487
0.0647235108926408,70.3205929877584,0.20549714708413455,14.176631546332095,74.87198865397853,0.06271515127047819
0.0653328633474371,70.1961837309805,0.20743184112811278,14.151550640165667,74.78230141018823,0.06328729807258941
0.0659550582649707,70.0630671718268,0.20940730999128196,14.124714341840283,74.68408084936719,0.06387116562882128
0.0665646821978715,69.9387367668524,0.21134286597824198,14.099649332197444,74.59418655305853,0.06444290612710636
0.0671355313161182,69.7642925379658,0.21315531192867526,14.064481375653907,74.44795538439523,0.06497798516796786
0.0677422596845623,69.63184938601,0.21508167449848528,14.037780836219618,74.34886820943342,0.06554638152989226
0.0683332977358062,69.4236488119777,0.21695822031118467,13.995807600494704,74.16759567615262,0.0660997683839049
0.0689779529010853,69.2817865641749,0.21900500046094581,13.96720817133766,74.06070237470159,0.06670300779008494
0.0696167393240863,69.1297721706547,0.22103314735397397,13.936562069603989,73.94236149939265,0.06730039676174988
0.0702541801952905,69.0207655500832,0.22305702212004735,13.914586334896773,73.86976285025564,0.06789617184728844
0.0708918341149598,68.9205828301932,0.22508157331499737,13.894389498566948,73.8064893552976,0.0684917911411235
0.0715271136644485,68.7950628186075,0.22709858588462398,13.869084664231274,73.7157750963869,0.06908484001120226
0.0721582739018715,68.6378559938369,0.229102519638442,13.837391768357518,73.5906452066774,0.06967369531555047
0.0728131511188961,68.4893663079246,0.2311817548024951,13.8074562476776,73.47629288694094,0.07028431159671224
0.0734748976473354,68.2847508678924,0.2332828000302899,13.766205774967107,73.30196594878458,0.0709009544092077
0.0741032712467752,68.1329485905221,0.23527788620851123,13.735602435849257,73.18182296076816,0.07148614718726218
0.0747155178731796,68.0122908882343,0.2372217692473452,13.711277843068036,73.09386442369006,0.07205599202115116
0.0753334056539565,67.9490908317981,0.2391835629513119,13.698536711690497,73.06792725524748,0.07263075828904948
0.0759536291262794,67.8724582186793,0.24115277247593708,13.683087576885747,73.02761773810977,0.07320736520340332
0.0765945948591486,67.7386577760739,0.2431878386777968,13.656113407656497,72.9270728247348,0.07380290656658516
0.0772207929681065,67.5974635453964,0.24517601767373812,13.627648650751912,72.81739328300458,0.07438438456153404
0.0778467546071947,67.4657015738589,0.24716344587784317,13.601085437289953,72.7176874886813,0.0749653052453389
0.078451789638394,67.3118525883662,0.24908443210190093,13.570069481814626,72.59258788779928,0.07552648453908033
0.0790913354294779,67.1288217819343,0.25111498998859233,13.533170471237957,72.43812994247492,0.07611933091363
0.0797101688867888,66.9123560034376,0.2530797862155544,13.48953097029302,72.24595120108454,0.07669264297870282
0.0803189950986802,66.7369033351565,0.2550128094383096,13.45415971236755,72.09714434703403,0.0772563633563397
0.0809278583485509,66.5419065676053,0.2569459502566491,13.414848364029229,71.92700055655096,0.0778198003973302
0.0815517671379005,66.4652066985363,0.25892686066283405,13.39938567042492,71.88556175798776,0.07839683131989521
0.0821891815012355,66.3331155647032,0.2609506512664227,13.372756097844167,71.78498003939302,0.07898600941182411
0.0828196356769565,66.1935118052927,0.26295234327433686,13.344611979947008,71.67563433718537,0.079568412761445
0.0834604129775335,66.024263174524,0.26498681120366885,13.310491455984039,71.53467544560714,0.08016000508088064
0.084099553576146,65.8785614996531,0.2670160826042635,13.281117998330064,71.4189191120126,0.08074973789288878
0.084735190260234,65.7289654893488,0.26903422907624297,13.250959442652718,71.29852188569713,0.0813358929276084
0.0853730797498102,65.5301394351035,0.2710595282056474,13.210876110116866,71.12464925511277,0.0819237801927402
0.0860022993639024,65.3488260145554,0.2730573004803901,13.174323324534368,70.96897531253877,0.08250333878749717
0.0866342114466309,65.1870500396568,0.2750636213430531,13.14170928799481,70.83447871637453,0.08308503949758181
0.0872565454536245,65.0559684488235,0.2770395318152578,13.11528323928282,70.73252751680783,0.08365759266937217
0.0878922239963511,64.9479464841511,0.2790578111884147,13.093506011204864,70.65636594463913,0.08424208470021809
0.0885321225468271,64.7909382763576,0.28108948908617604,13.061853156513692,70.527017563764,0.08483011209472036
0.089182112398942,64.6176958737126,0.2831532068666408,13.026927488140462,70.3804384900827,0.08542705898608582
0.0898075941201982,64.449399062585,0.2851391113316293,12.992998851017138,70.23744453488831,0.08600116150393099
0.090449092380613,64.2686716404911,0.2871758683084462,12.956564202723007,70.08171465888117,0.08658962274603935
0.0910828921456446,64.0439851056359,0.2891881825624216,12.911267397296196,69.8772964935898,0.08717068210007102
0.0917209346971554,63.8667823751556,0.2912139676634684,12.87554332683137,69.72470335070469,0.08775529035651299
0.0923405513318265,63.6859759413153,0.29318125047854915,12.839092749769163,69.56677407184179,0.08832268889841113
0.0929453742936312,63.5450759894073,0.29510156338227905,12.810687319464511,69.45129686176,0.08887623017203206
0.09356187329028,63.3565354891742,0.297058947696639,12.77267755461752,69.28429163472344,0.08944014233254936
0.0942037030330508,63.1568148908068,0.2990967571299363,12.732413881986652,69.10642072529372,0.09002688687970761
0.0948320792698662,62.9340000866438,0.3010918516818252,12.68749441746739,68.90216217163017,0.09060099924384098
0.0954703588525307,62.7469967487403,0.303118389356785,12.649794544546044,68.73747504526112,0.09118382250114362
0.0960776117936207,62.5513145143035,0.3050464174447457,12.610345006083586,68.56109542738942,0.09173799969896428
0.0966935363994892,62.3574903834318,0.3070019780683782,12.571270061299852,68.38705664960297,0.09229977708514943
0.0972967350669909,62.1325056192198,0.3089171338376961,12.525913132834713,68.17779555750136,0.0928496415859584
0.0979270558149949,61.8800756450778,0.3109184022126088,12.475023250047684,67.93980926660944,0.09342390719654851
0.0985315756352631,61.6673622207853,0.31283775264196034,12.432140223710316,67.74354458566978,0.09397435674918399
0.0991729156124948,61.468155918512,0.314874007069671,12.391980233172019,67.56413215827426,0.09455800209185067
0.0998230569657655,61.2975769954395,0.31693820586630544,12.357591522280602,67.41648851571865,0.09514930956155158
0.100468046838257,61.0807578073178,0.31898604871146596,12.313880773955269,67.21742224361964,0.09573558643178136
0.101105122607798,60.8621760174808,0.3210087642797586,12.26981468512413,67.01565378590557,0.09631433239050266
0.101747068530669,60.6144704659432,0.3230469425848741,12.21987724593415,66.78181514639174,0.09689716399729448
0.10238257902889,60.2813561755216,0.32506468841672576,12.152721404985154,66.45311688813061,0.0974738183846942
0.103023835853918,60.0452185994181,0.32710067883618965,12.105116069642689,66.23130734421717,0.0980553500595567
0.103670770396693,59.8053194883933,0.32915469600950026,12.056752408860092,66.0053830335754,0.09864168815951568
0.104334444616776,59.6675393968615,0.33126186165826377,12.028975942407278,65.89291898148265,0.09924284094263147
0.104985313886754,59.4827098256458,0.33332837159044393,11.991714300850193,65.72752078752593,0.09983204428117273
0.105641872646,59.2279095151069,0.33541294565105,11.940346558245551,65.48485678919063,0.1004260465467295
0.106276760231058,58.9641019294589,0.33742871373360916,11.887162948978915,65.23061565245567,0.10100010708680232
0.106938801291325,58.6796873926036,0.3395306940999569,11.829824978348887,64.95482282251831,0.1015983688119802
0.107605692335318,58.3896375108784,0.34164807316463464,11.771350922193085,64.67269488044472,0.10220065164357053
0.108263258858497,58.1586633364059,0.34373584687572795,11.724786528619429,64.4551097600594,0.10279415835083969
0.108928760529922,57.8875799684883,0.34584881468250234,11.670136121647243,64.19320230453248,0.10339446873044701
0.109563291406846,57.6733184417783,0.34786345021673604,11.626940997862505,63.992197036614684,0.10396650674489295
0.11021140331801,57.3901117290199,0.34992120553468176,11.569846524570412,63.71515647925256,0.10455045062993744
0.110863332097484,57.097313662012,0.3519910794095117,11.510818434261619,63.42731210839784,0.10513748967711657
0.111484407484559,56.7503986425614,0.3539629937634748,11.440880366340378,63.07718320973987,0.10569642596974284
0.112107622054428,56.4398861420173,0.35594170002280884,11.378281046230688,62.76722756642152,0.10625697356832078
0.112725567664244,56.1317533185299,0.3579036773339747,11.31616146901563,62.4592370753505,0.10681247195675019
0.113340579247117,55.8459102684934,0.35985633910959647,11.25853551012827,62.175518086906955,0.10736502660511409
0.113966659394134,55.5289291370522,0.36184414357637545,11.194632114029723,61.85737569053563,0.10792721232663897
0.114559438860034,55.1856316240258,0.3637262183806079,11.125423335403603,61.507666616010745,0.10845920473215297
0.115154185556991,54.8773691988824,0.3656145391434464,11.063277630494692,61.19672795449001,0.10899267836262222
0.115781550620267,54.5797403792922,0.3676064232193477,11.003275660465306,60.89906735285825,0.10955510162712048
0.116436721878916,54.2852682229181,0.3696865919655583,10.94391007374029,60.60606690111237,0.11014211525883749
0.117095676509325,53.9368563147366,0.3717787729171068,10.873670233050898,60.25262899369694,0.11073217130638201
0.117789707752656,53.5757468030622,0.3739823221146828,10.80087055549734,59.88641836162519,0.1113532602181702
0.11844159564159,53.1439683857203,0.3760520661620482,10.713824026561213,59.43842480005123,0.11193628390307281
0.119119382564501,52.7491680414737,0.37820403964229066,10.634232277161098,59.03261636936516,0.11254211047069977
0.119788821406125,52.3780737642287,0.38032950796444687,10.559419670868506,58.65238148796873,0.11314011521282055
0.120434612251755,52.0281952924724,0.3823798938993221,10.488884170962436,58.294190818679894,0.11371665668972498
0.121089989947688,51.7978169689309,0.3844607180839094,10.44243990093647,58.070014105010934,0.1143014173601769
0.121673022817273,51.4606049917917,0.38631184744484176,10.374457966345206,57.721972357148644,0.11482134111440369
0.122306820544025,51.1255424860279,0.38832415522727937,10.306909365183227,57.37854503608244,0.11538622831290553
0.122972601266844,50.736557230377,0.3904380090222297,10.228489937644003,56.97576365232056,0.11597927765533023
0.123669645369821,50.342323531505,0.3926511240491817,10.149012423951408,56.568140829739015,0.11659979845821879
0.124353571879841,49.8883968581074,0.3948225907184952,10.057500806594453,56.09219720277209,0.1172082677354693
0.125004879717364,49.450911249587,0.39689049310263064,9.969303707916739,55.632516462255666,0.11778737317352216
0.125642016215499,49.0354834654595,0.3989134014842093,9.885553466636635,55.19640047416159,0.11835355396030524
0.126262724511984,48.5702997614378,0.4008841503255492,9.79177243190586,54.70291813968071,0.11890482800043552
0.126900353911433,48.1434128589503,0.40290862366879976,9.70571203236438,54.25282898925533,0.1194708140336495
0.127572354928869,47.6704992310544,0.4050422268991591,9.610372644980568,53.75193707859485,0.12006696322161964
0.128275320690481,47.2471709920326,0.40727414319227717,9.525029671993773,53.30781700275357,0.12069020191983822
0.128990096998207,46.8204337000462,0.40954355796930714,9.438999433929315,52.85980598451328,0.12132351364828202
0.129665234922822,46.3499463565408,0.41168712087995984,9.344149185478626,52.35992303952186,0.12192133655218497
0.130307021078732,45.840496929398,0.413724791924974,9.241444180966637,51.813835529036616,0.122489295890144
0.130941995348493,45.3499935433835,0.4157408352314652,9.142558698346113,51.2882121869954,0.12305090965478273
0.131591200489474,44.8809477164095,0.41780206155407995,9.047999059628156,50.78688550551714,0.1236247842480857
0.132253984425098,44.3985662740878,0.41990640054968614,8.9507509608561,50.27045356659769,0.12421032248098011
0.132921565194606,43.8579140206923,0.422025969492874,8.841755466571568,49.68757659849318,0.12479975210726058
0.133601885836895,43.3126190114892,0.4241859875321416,8.731823992716222,49.09926659195911,0.12540007297524966
0.13430283601627,42.7896396384888,0.4264115043516572,8.626391351119343,48.536409594052046,0.12601822081447805
0.13497585629408,42.2738835225403,0.42854834373370393,8.522414918144126,47.97983714987138,0.12661137871951927
0.135681580635623,41.6704417539042,0.430789018518103,8.400761057587086,47.324353156858585,0.12723298227167923
0.136341304626851,41.0747486544391,0.43288364219025194,8.280669328734922,46.67493347320532,0.1278137193884122
0.136978228788696,40.5001073231204,0.43490587640410977,8.164821636341074,46.047740289993534,0.12837406664197543
0.137594533955198,39.8963157755609,0.4368626453077536,8.043097260353077,45.38583075122862,0.1289159751635923
0.138213857030413,39.3392123329086,0.43882899607156123,7.930785206314375,44.77643660197829,0.12946024162552852
0.138848119080103,38.6749930335708,0.440842778079327,7.796878595567874,44.044943071718194,0.13001732972655317
0.139457262856098,38.0095110017707,0.4427768095681111,7.662717417956973,43.31021336857638,0.13055206382790724
0.139787574544495,37.6689384983143,0.4438255491787716,7.594058001260163,42.93458804665941,0.13084190692443579