File: example/data/02 processed data/test_ID_097.csv
Strain,Stress_MPa,Displacement(mm),Force(kN),True Stress (MPa),True Strain
0.0012134980419398372,83.8960775718557,0.003852856283158983,33.82689847697222,83.99788529771558,0.0012127623483059655
0.001363541138241237,94.3532179099845,0.004329243113915927,38.04321746130575,94.4818724041302,0.0013626123602123283
0.001513824143981937,104.880306530128,0.0048063916571426495,42.28773959294761,105.03907687038154,0.0015126794672931166
0.001658862681670137,115.3357191048,0.005266889014302685,46.50336194305536,115.52704522508654,0.001657488288714577
0.001810870313901237,125.652662112322,0.005749513246636427,50.66315336368824,125.88020278800387,0.0018092326650028304
0.001957258590073637,135.973638322941,0.006214296023483797,54.82457097180982,136.23977389457215,0.0019553456551448718
0.002106975736049137,146.226960692295,0.00668964796195601,58.95871055113334,146.5350573504299,0.0021047591756197196
0.002253986452250637,156.291443177833,0.007156406985895772,63.01670988930227,156.64372197335854,0.002251450035438197
0.002393617951721437,166.198811724328,0.007599736996715563,67.01136088724905,166.59662818362614,0.0023907578114182627
0.002532425205190337,175.898586947976,0.00804045002647932,70.92231025742393,176.34403696312043,0.0025292240198497183
0.002673255962913337,185.507409536694,0.008487587682249845,74.79658752519502,186.00331832540257,0.002669689169412212
0.002809889591921737,194.840480105904,0.008921399454351515,78.55968157870049,195.3879603430386,0.002805949231754558
0.002946729411013637,203.724300085789,0.009355865879968298,82.14163779459014,204.32462047258997,0.002942396314125189
0.003082909508806237,212.194310796857,0.009788237690459802,85.55674611329275,212.84848665532724,0.003078167087756543
0.003218721496620237,220.275886073748,0.010219440751769253,88.8152372649352,220.98489280344063,0.003213552501317968
0.003361294335115037,227.845348952955,0.010672109513990242,91.86724469783145,228.61120423367288,0.003355657812454316
0.0034995248317570373,235.029276090265,0.011110991340828593,94.76380411959484,235.85176687813276,0.0034934157431890985
0.0036453572834487372,241.75424941256,0.01157400937494974,97.4753133631442,242.63553002646074,0.003638729071835881
0.003830347058271137,248.009425996458,0.01216135191001086,99.99740056177187,248.95938817174707,0.003823029957715638
0.0040769992860137366,253.659718355995,0.012944472733093612,102.27559844113719,254.69388884662283,0.004068710844766688
0.004403884479883036,258.385550604931,0.01398233322362864,104.18105400390817,259.52345072106607,0.0043942157568599245
0.004818503717019837,262.411327153928,0.01529874930153798,105.80424710846378,263.6757571092073,0.0048069318857044095
0.0053203781681776365,265.643525705032,0.016892200683963996,107.10746956426891,267.0568497197108,0.005306274957080027
0.005921116867014337,267.943155743568,0.018799546052770517,108.03468039580663,269.5296784824423,0.005903655946070968
0.006609432738449537,269.457682211806,0.020984948944577277,108.64533746780019,271.23864463824344,0.006587686206787877
0.007354180986450237,270.114391012589,0.0233495246319795,108.9101224562759,272.10086113114033,0.007327270851587186
0.008127881172336336,270.528880525382,0.025806022722167865,109.07724462783403,272.72770711997754,0.008095027844732967
0.008914427148008136,270.958206199932,0.02830330619492583,109.2503487398126,273.3736433892563,0.008874928209038575
0.009706097328550937,271.047656220601,0.030816859018149224,109.28641498814633,273.6784711525538,0.009659295762555392
0.010497710245385837,271.142314638486,0.03333023002910003,109.32458126223757,273.9886880928241,0.010442991896958307
0.011283895209975837,271.321407441655,0.03582636729167328,109.39679148047531,274.38296977144984,0.011220706959846477
0.012063937306458238,271.324311633481,0.0383030009480049,109.39796245061954,274.59755111874523,0.011991748026134157
0.012837794911580536,271.719396569708,0.0407599988442682,109.55726069690627,275.20767445636835,0.01275608896227409
0.013609560580620137,272.068386289877,0.04321035484346893,109.69797335207842,275.7711174751607,0.013517782281630517
0.014372672665041837,272.248439668159,0.04563323571150783,109.77057087420171,276.16137737507785,0.01427036493046187
0.015128573346430736,272.535655673488,0.048033220374917585,109.88637636755037,276.658731329862,0.015015277719087365
0.015886878533551738,272.832129105662,0.05044083934402677,110.00591445540292,277.16658000081395,0.01576200293149759
0.01663783418667534,272.971425995723,0.0528251235426942,110.0620789614755,277.51307931914016,0.016500941732678423
0.01738758927217594,273.214525132583,0.05520559593915861,110.16009653345748,277.965067078781,0.017238154857755622
0.01813493408420024,273.235619038977,0.057578415717335754,110.16860159651553,278.19072897970455,0.01797245756089913
0.018879954806788238,273.308837054122,0.05994385651155265,110.198123100222,278.46889554599966,0.01870394043799597
0.01962409146278564,273.443676143231,0.0623064903943444,110.25249022095075,278.80975985378615,0.019434021587859233
0.020368036507731738,273.720534707523,0.06466851591204827,110.36411959407327,279.29568455136166,0.02016338232187898
0.02110393925510734,273.930841788254,0.06700500713496581,110.44891540902401,279.71186163345374,0.020884335426293657
0.021841352963015037,274.218814764206,0.06934629565757273,110.56502611292787,280.20812468657067,0.021606247797361384
0.022570142911285538,274.462766299576,0.07166020374333158,110.66338737198905,280.65743015878417,0.02231920600622691
0.023296131110806837,274.875845720037,0.0739652162768117,110.82994099431892,281.2793894611249,0.023028918306793836
0.02401608847066784,275.132052458402,0.07625108089437038,110.93324355122768,281.7396481713594,0.023732237891029996
0.02473333316695774,275.477280307516,0.07852833280509082,111.07243941999046,282.2907516612892,0.024432415978225094
0.02544491908599144,275.824863809962,0.08078761809802282,111.21258508817668,282.84320515151103,0.025126585811337025
0.02615406095140074,276.188321197756,0.08303914352069734,111.35913110693522,283.4117673844272,0.025817892348873342
0.02685879089700274,276.529003692238,0.0852766610979837,111.49649428871037,283.9562383793643,0.026504424800579476
0.02756018130716374,276.922181273724,0.08750357565024486,111.65502348956552,284.5542067976031,0.02718723628830564
0.02826115807144214,277.374007853562,0.08972917687682878,111.83719996655618,285.21291853442096,0.027869179585631218
0.02896011005999294,277.666917597843,0.09194834944047757,111.9553011754503,285.70818209149553,0.02854869036677321
0.029652904708452537,278.105847617417,0.0941479724493368,112.13227775934254,286.3524938156797,0.029221759729148568
0.03034624986352744,278.192457892891,0.09634934331669961,112.16719902241367,286.6345557302575,0.029894910666824828
0.03103533716850504,278.458220949868,0.09853719551000349,112.2743546869868,287.10026572438926,0.030563479101684426
0.031721432511589036,278.670761274388,0.10071554822429518,112.36005094583325,287.51059702110666,0.0312287008849501
0.03241017946124084,279.00700535659,0.10290231978943967,112.4956245597771,288.04967247114047,0.03189604881103969
0.03308729733712344,279.160501691296,0.10505216904536692,112.55751428193057,288.3971682155365,0.03255169512166932
0.03376481936535704,279.585814754424,0.10720330148500859,112.72900050898376,289.0259792867233,0.033207302793864364
0.03444543890381104,279.824721079264,0.10936426851960006,112.82532753915925,289.4634064129758,0.03386547529862078
0.03512665304172174,280.220751107789,0.11152712340746651,112.98500684666053,290.063968207043,0.03452378931934395
0.03580881308039684,280.491902168891,0.11369298153025995,113.09433495449684,290.5359842642218,0.035182583448380156
0.03648950051001944,280.726721811645,0.11585416411931171,113.18901423445527,290.9702996703671,0.03583952308842992
0.03716474481402264,280.866934343846,0.11799806478452188,113.24554792743871,291.30528228543193,0.036490783373882396
0.03785092147762204,280.896728436343,0.12017667569144998,113.25756090553348,291.5289284477079,0.03715215350207765
0.03853567478435524,281.032170167872,0.12235076744032788,113.31217101168599,291.86193448140267,0.037811715967747045
0.039220128648975436,281.152187515647,0.124523908460497,113.36056200630887,292.17901247995155,0.03847055555635281
0.03990231425481864,281.345485950338,0.12668984775904918,113.43849993517628,292.5718219449031,0.03912678014057814
0.04058329441094214,281.491746107717,0.12885195975474129,113.49747203063151,292.91560851425663,0.0397814159406109
0.04126602483573544,281.705362605081,0.13101962885346,113.58360220236865,293.33022309470215,0.04043730437879598
0.041952643228668936,281.891563723457,0.13319964225102388,113.65867849329787,293.71765992551883,0.04109649434125399
0.04263975819048084,282.193724051522,0.13538123225477666,113.78050953757368,294.2263962079502,0.04175572631986854
0.043325310806107235,282.288484115418,0.13755786180939047,113.81871679533653,294.5187204267033,0.04241302653116916
0.04401210091099174,282.42812036192,0.13973842039239875,113.87501812992615,294.85837529539054,0.0430710803041845
0.04469900283415084,282.634528429161,0.1419193339984289,113.95824186263772,295.2680100164449,0.04372880836115757
0.04539259675426214,282.82454986583,0.14412149469478228,114.03485850590266,295.66269061009535,0.044392505536638566
0.04608769268154484,283.018639814539,0.14632842426390485,114.11311557322212,296.06231590946027,0.04505719834429802
0.04678055727518724,283.293979500582,0.1485282693487195,114.22413253463466,296.54662973432465,0.04571931801568153
0.04747234885789184,283.501232388972,0.15072470762380658,114.30769689923352,296.95970179458357,0.04637997519403936
0.048171119154740635,283.739983901281,0.15294330331630152,114.40396150899649,297.40805647475383,0.04704685420605792
0.04886950144361464,284.053284982104,0.15516066708347648,114.53028450478435,297.93482740260043,0.04771291885719856
0.04957095011777494,284.234368053537,0.15738776662393542,114.60329719918613,298.3241357340762,0.04838146172651317
0.05026843597871914,284.477680856373,0.15960228423243325,114.7014009212896,298.7779289438761,0.04904578480875822
0.050965792477877137,284.842995088372,0.1618163911172599,114.84869561963158,299.36024406482295,0.04970954377034108
0.05167027148222654,285.071352585203,0.16405311195606925,114.94076936235385,299.801066765086,0.050379635036047886
0.05237684511534984,285.401292427451,0.16629648324123572,115.07380110674823,300.34971171664426,0.0510512679611001
0.05308412283880674,285.685243824134,0.16854209001321138,115.18829030989082,300.8505944005288,0.05172311869671228
0.05379363939192714,285.761111275517,0.17079480506936867,115.21888006628846,301.13324144770854,0.05239664289698758
0.05450448526757454,285.901863362742,0.17305174072454915,115.27563130785758,301.48479726236866,0.053070974381960644
0.055215787688468236,286.069757934569,0.17531012591088663,115.34332639921823,301.86532495277567,0.053745284106300736
0.05592701077377174,286.005587211188,0.17756825920672525,115.31745276355102,302.001024768507,0.05441906430982678
0.05663825740867154,286.138259706045,0.17982646727253213,115.37094631347735,302.34463211374526,0.055092413126533256
0.05734964942816924,286.198876037471,0.1820851369344373,115.39538681830831,302.612281244956,0.05576544634876756
0.05806110530756564,286.335515257748,0.1843440093515209,115.450479751924,302.96047176242416,0.05643808725751612
0.05877764582709214,286.604892372545,0.18661902550101753,115.55909260461014,303.4508532287303,0.05711507840434695
0.05949877674918394,286.808004506171,0.188908616178659,115.64098741688815,303.8727299361626,0.05779594417074503
0.06022474846393524,286.927914005435,0.19121357637299438,115.68933492699139,304.208075453694,0.05848091250222855
0.06096163347466084,287.13332787595,0.19355318628204815,115.77215779958304,304.63744456828323,0.059175698256693804
0.06170183012242364,287.299383117433,0.19590331063869504,115.839111272949,305.026280848822,0.059873120801962575
0.06244589997086684,287.406137129391,0.1982657324075022,115.88215449057047,305.3534720195862,0.06057370284560775
0.06319375313469074,287.513831874711,0.20064016620264308,115.92557701188348,305.68290998901045,0.061277352867931976
0.06394487043811403,287.603447394333,0.20302496364101205,115.96170998939506,305.99421257551853,0.06198357607907386
0.06469317276798023,287.746713493938,0.20540082353833722,116.01947488075581,306.3619613434198,0.06268665696507023
0.06544030220830663,288.005283947324,0.20777295951137353,116.12373048756105,306.852436766426,0.0633881430266158
0.06618612519102673,288.206882936499,0.21014094748150988,116.20501519999641,307.28217977144976,0.06408791199510665
0.06693842093312834,288.291408593839,0.21252948646268247,116.23909594503588,307.58918025369786,0.06479325831410919
0.06769913139341013,288.447051993515,0.21494474217407716,116.30185136378525,307.9746668664658,0.06550598867121843
0.06846474650915983,288.595250986839,0.21737557016658246,116.3616051978935,308.3538516894003,0.06622280179258247
0.06923623180661753,288.740652996288,0.21982503598601066,116.42023128810334,308.73196777913313,0.06694459154594594
0.07001720797523762,288.872944920106,0.22230463532137945,116.47357139178676,309.0990219829965,0.0676747305643456
0.07080951626031823,288.852487574589,0.22482021412651035,116.4653229900743,309.30599249033526,0.06841491968127429
0.07161176388621124,288.917797401975,0.22736735033872066,116.49165591247633,309.6077104920495,0.06916383649873145
0.07241290868417473,289.014377891868,0.22991098507225474,116.53059716600117,309.9427496465654,0.06991116449873021
0.07321808263116643,289.189132225815,0.2324674123539534,116.60105811344862,310.36300600516,0.07066168869235527
0.07403130081186143,289.286204541165,0.23504938007766005,116.64019767099772,310.7024385702736,0.07141913980711292
0.07485176242354233,289.363843314118,0.2376543456947469,116.67150162425239,311.0232369678295,0.07218275665121793
0.07568191767529914,289.492331371112,0.24029008861907475,116.72330800883238,311.401666161571,0.07295480249330263
0.07651718359050613,289.60064717887,0.24294205789985696,116.76698094252039,311.760073066985,0.07373100015703342
0.07735910394410374,289.715429632098,0.24561515502252934,116.81326122766191,312.12755566721813,0.0745127724448382
0.07821923631443323,289.835840268381,0.24834607529832547,116.86181079621122,312.5065783507258,0.07531082501376218
0.07909315907065984,289.841155748561,0.25112078004934496,116.86395399781979,312.7656083854058,0.07612102089072556
0.07998074430907383,289.848357976183,0.25393886318130937,116.866857935997,313.03064538388105,0.07694321163373358
0.08087696096626804,289.870472904726,0.256784351067901,116.87577467518554,313.3143158271152,0.0777727125364489
0.08178154082245984,289.881300173436,0.25965639211131,116.88014022992938,313.58823955723756,0.07860925691753926
0.08270478139068153,289.835625977467,0.26258768091541385,116.86172439411469,313.80641806316476,0.07946233749812544
0.08364369666251173,289.682945029374,0.2655687369034747,116.80016343584361,313.9130974117141,0.08032915587026812
0.08459983738409033,289.524661489397,0.26860448369448675,116.73634351252485,314.01840077008376,0.08121110549312323
0.08557062373302353,289.255725377052,0.2716867303523497,116.62790847202736,314.0075182159145,0.0821057692359767
0.08655641117759763,288.941487593712,0.2748166054888725,116.50120779778469,313.95122580014004,0.08301343945637359
0.08756747912420024,288.459621461728,0.27802674621933576,116.30691937336873,313.71930334225254,0.08394353182507434
0.08859565585063803,287.788956660526,0.2812912073257757,116.0365073255241,313.2858080224362,0.08488847642634964
0.08963740906256863,287.025939349784,0.2845987737736554,115.7288587458329,312.7542008868486,0.08584498866384847
0.09069599758611503,286.090772067749,0.28795979233591523,115.35179929771641,312.03806004061533,0.08681602236309599
0.09176763401982344,284.886997015295,0.29136223801293937,114.86643719656693,311.0304026944011,0.08779806532070943
0.09284513645860233,283.526428944594,0.29478330825606236,114.3178561504603,309.850478929575,0.0887845124757513
0.09393422085862004,281.941000118574,0.2982411512261186,113.67861124780903,308.42490829281235,0.08978057500617284
0.09502629354697813,280.169148415266,0.3017084820116555,112.96420064103526,306.792584155382,0.09077837535184127
0.09613371130164393,278.192989870554,0.30522453338271943,112.16741351580738,304.936714444911,0.09178918044732046
0.09725625803210514,276.030545122286,0.3087886192519338,111.29551579330574,302.8762430434417,0.09281275294848416
0.09838947975593763,273.66576502152,0.31238659822510195,110.34203645667685,300.59159726899804,0.09384499763618818
0.09952625039396504,271.080902574716,0.315995845000839,109.2998199181255,298.06056836138924,0.094879405574396
0.10068915598919433,268.158525548691,0.31968807026569196,108.12151750123222,295.1591811574955,0.09593648907644198
0.10185695154734734,264.979062560368,0.3233958211628278,106.83955802434036,291.9690220966409,0.09699689427167067
0.10303752246413034,261.44947356009,0.3271441338236138,105.41642773942829,288.3885795652728,0.0980677582459028
0.10423559582831733,257.508161002769,0.33094801675490754,103.82729051631647,284.3496775955469,0.09915332710633526
0.10482976065386333,255.606803850161,0.33283449007601607,103.06066331238492,282.4020039192723,0.09969126034414579
0.10542665126474933,253.561374809325,0.3347296177655791,102.23594632311985,280.2935014455581,0.10023137019038592
0.10603408411689934,251.336314751307,0.3366582170711554,101.33880210772698,277.9865306912786,0.10078072009084572