File: example/data/02 processed data/test_ID_063.csv
Strain,Stress_MPa,Displacement(mm),Force(kN),True Stress (MPa),True Strain
0.0010093411103384682,44.0232438640259,0.003204658025324636,17.750171925975245,44.067678333868315,0.0010088320681026562
0.001055547325387468,46.4849900134823,0.003351362758105211,18.742747973436064,46.5340571203617,0.0010549906270226255
0.001102980220100168,48.8358226702248,0.003501962198818033,19.69060370063464,48.88968761666238,0.00110237238433
0.0011552545904579682,51.2379547783357,0.0036679333247040488,20.659143366624953,51.297147660799055,0.0011545877973681215
0.0012108353356248681,53.5782765383146,0.003844402190608956,21.602761100248443,53.64315100876907,0.0012101028657271623
0.001254903429355868,55.9046360622943,0.003984318388204881,22.54074926031706,55.97479098180577,0.001254116696161359
0.0013005247441788682,58.1684008428612,0.004129166062767906,23.45349921984164,58.24405028748666,0.0012996797943798178
0.001356686170133768,60.4290280423046,0.004307478590174713,24.364984106657218,60.51101126892422,0.001355766702976585
0.001414395234639868,62.6924790647591,0.004490704869981581,25.27760755891087,62.78115100839606,0.0014133959198730948
0.0014616846487718682,65.0296632436146,0.004640848759850681,26.219960219825413,65.1247161040926,0.0014606174275995653
0.0015102559788693682,67.2810345787439,0.004795062732910244,27.127713142149542,67.38264616348096,0.0015091166892435431
0.001550865413842668,69.5537414655126,0.004923997688950471,28.044068558894683,69.66160995755483,0.001549664064004373
0.001599851922968168,71.8032302519677,0.005079529855423933,28.95106243759338,71.91810478796164,0.0015985735231989551
0.001655359994905068,74.0740545900624,0.005255767983823591,29.86665881071316,74.1966738166912,0.00165399139668892
0.0017006071661903681,76.3456633234378,0.005399427752654419,30.782571452010124,76.47549730559321,0.0016991627711574566
0.001750836354776068,78.6001722396905,0.0055589054264140155,31.691589447043206,78.7377882787394,0.0017493054274803847
0.0017995017372253682,80.8247172562143,0.005713418015690544,32.58852599770561,80.97016147532761,0.0017978845737426383
0.0018535056949331682,83.0625969925128,0.005884880581412809,33.490839107381156,83.21655398907436,0.0018517900728689596
0.001912677661019068,85.2937309293958,0.00607275157373554,34.39043231073239,85.45687034316943,0.0019108508221665093
0.001969157427659768,87.540552771896,0.006252074832819763,35.29635087762847,87.71293390160821,0.00196722117860836
0.002027449014608668,89.7727848621723,0.006437150621382521,36.19638685642787,89.95479460637978,0.0020253965136143894
0.002085591528020068,92.0177241559985,0.006621753101463716,37.1015463796986,92.20963554192592,0.002083419701180673
0.002136913700654168,94.2314445176464,0.006784700999576984,37.99411842951503,94.43280898246859,0.0021346337480357266
0.0021960740809574683,96.4172404072956,0.006972535207039962,38.87543133222158,96.6289798099115,0.0021936662348341902
0.002245460014770268,98.5506386921832,0.0071293355468956,39.735617520688265,98.77193021079657,0.002242942737024758
0.002297906331289068,100.680271879723,0.00729585260184279,40.59428562190431,100.91162571391132,0.002295270182178876
0.0023485783820923678,102.788098878454,0.0074567363631432675,41.44416146779265,103.02950478541631,0.0023458247824044336
0.002390948261941068,104.909731234129,0.007591260731662891,42.29960363360081,105.16056497368395,0.0023880944930494484
0.0024376793043181678,106.96923948356,0.007739631791210182,43.129997359771394,107.22999618484774,0.0024347129837702843
0.002483742926060468,109.053534623865,0.007885883790241986,43.97038516034237,109.32439556904892,0.002480663534489794
0.0025339677277404684,111.100492548802,0.008045347535575986,44.795718595676966,111.38201761145673,0.0025307626447606665
0.002584132003839768,113.187454633063,0.008204619112191263,45.637181708051,113.47994595701346,0.0025807988756604374
0.0026243085831628684,115.2573169002,0.008332179751542107,46.47175017416065,115.5597876662135,0.0026208710980939283
0.002674628250246168,117.311020624553,0.008491944694531583,47.29980351581977,117.62478399438064,0.0026710577971138516
0.002724565962119168,119.297109475694,0.008650496929728359,48.10059454059982,119.62214231955068,0.002720861060252132
0.002770764119636668,121.306730185262,0.00879717607984642,48.910873610697635,121.64284252072976,0.0027669326285402365
0.002818837321550068,123.278699921348,0.008949808495921465,49.705971808287515,123.62620252163846,0.002814871849892531
0.0028553712546378683,125.228706589571,0.009065803733475231,50.49221449691503,125.58628103862236,0.0028513024256417853
0.002893724263362468,127.150475027682,0.009187574536175835,51.267071531161385,127.51841344236767,0.002889545502819119
0.002937386059257868,129.062830722423,0.00932620073814373,52.038133347280954,129.44193808215542,0.0029330803704135365
0.002974512639618268,130.976755207725,0.009444077630788,52.80982769975473,131.36634722158658,0.0029700975299296662
0.003023112464236268,132.889110902466,0.00959838207395015,53.5808895158743,133.29084962999653,0.003018552048538596
0.0030684639309295682,134.752834089793,0.009742372980701379,54.33234270500454,135.16631830078805,0.0030637658037175847
0.003103775639959068,136.604006952627,0.00985448765687004,55.07873560329921,137.02799514172736,0.003098968871865596
0.003147773926755968,138.453611024899,0.009994182217450197,55.82449596523928,138.8894316917484,0.0031428300584785867
0.0031975890455110683,140.348710023461,0.01015234521949764,56.58859988145948,140.79748752118363,0.003192487629587445
0.003239385078363768,142.17791981843,0.010285047623804963,57.32613727079098,142.63848885036265,0.003234149574017072
0.003291102552376468,143.993010498344,0.010449250603795285,58.0579818329323,144.46690626271948,0.0032856987274866396
0.003321661608811868,145.770450204777,0.010546275607977681,58.77464552256609,146.25465031292143,0.0033161570769833634
0.003356680944517068,147.554165073456,0.010657461998841692,59.49383935761746,148.04945732764222,0.0033510598663006215
0.003404131113455968,149.406906726852,0.010808116285222697,60.24086479226672,149.9155074266061,0.0033983501748044084
0.003444313359876368,151.195327967216,0.010935694917607467,60.961956236381496,151.71609205528435,0.0034383952978292638
0.003479185136892068,152.856677172081,0.011046412809632316,61.63181223578306,153.3884938513728,0.0034731467739522012
0.003517492591261568,154.582346789977,0.011168038977255478,62.32760222571873,155.1260890495506,0.0035113206830565415
0.003544048559806768,156.312722779558,0.011252354177386488,63.02528982471779,156.86670265960436,0.0035377832184620107
0.003585495045570368,158.054080303071,0.011383946769685918,63.72740517819823,158.62078242492984,0.0035790824817819766
0.003628683874045268,159.825244847257,0.011521071300093727,64.44153872241402,160.4052001358996,0.00362211608421
0.003660455004003468,161.508557119986,0.011621944637711011,65.12025023077835,162.09975192608522,0.0036537718425611997
0.003701493582327468,163.229520366196,0.01175224212388971,65.81414261165023,163.83371338827786,0.003694659912954949
0.003743836676273168,164.972446680271,0.011886681447167308,66.51689050148526,165.5900765767271,0.0037368459623719173
0.003774131077325468,166.687134764235,0.011982866170508361,67.20825273693956,167.31623385973901,0.003767026913716902
0.003812795965321368,168.398685267075,0.012105627189895342,67.89834989968463,169.04075509482672,0.003805545682174628
0.003851363190318068,170.15102432452,0.012228078129259867,68.60489300764647,170.80633771639836,0.003843965678692071
0.003887849338004868,171.851593293428,0.012343921648165456,69.29056241591017,172.51972639664893,0.003880311183589361
0.003928438346516668,173.517648869979,0.01247279175019042,69.96231602437554,174.19930225559725,0.003920742181949395
0.003959545375139968,175.216649048325,0.012571556566069397,70.64735289628464,175.91042732071182,0.003951727006678753
0.003997433886898968,176.940749875659,0.012691852590904223,71.34251034986572,177.64805882518527,0.003989465376728216
0.0040531916089956675,178.619355776703,0.012868883358561244,72.01932424916664,179.34333425074135,0.004044999556397935
0.004097541227409568,180.296392887185,0.013009693397025379,72.695505612113,181.03516479019348,0.00408916916746941
0.004132678998926268,181.924797490254,0.0131212558215909,73.35207834807042,182.6766342802259,0.004124162935779771
0.004181236307928068,183.534376606582,0.013275425277671615,74.00106064777385,184.30177720580238,0.0041725192297249105
0.004222662130420269,185.178469115269,0.013406952264084351,74.66395874727645,185.96041522417124,0.0042137717113897785
0.004272992691345068,186.77236032598,0.01356675179502059,75.30661568343514,187.57043725659815,0.004263889381113829
0.004318579631240168,188.358407583882,0.013711490329187533,75.94610993782123,189.1718483662466,0.004309281326924213
0.004359235771357469,189.985243396389,0.013840573574059963,76.60205013742404,190.81343386543261,0.004349761825898403
0.004396347662098768,191.565015492045,0.013958403827163589,77.23901424639254,192.40720190004336,0.004386711956667394
0.004445873490390268,193.124393310398,0.0141156483319891,77.86775538275248,193.9829999309644,0.004436019789587356
0.004482181817673868,194.708871777738,0.01423092727111453,78.50661710078397,195.58159234256,0.004472166755818075
0.004526201026252468,196.197654020814,0.014370688258351584,79.10689410119221,197.08568404379136,0.004515988582507909
0.004572694874158868,197.70526175063,0.014518306225454405,79.71476153785402,198.60930758763135,0.004562271867028654
0.0046223706089369675,199.267777150106,0.01467602668337487,80.34476774692274,200.18886666651287,0.004611720261205629
0.004671739667284968,200.750284230935,0.014832773443629772,80.94251460191299,201.6881372969954,0.004660860960026687
0.004731224100538768,202.268873494683,0.015021636519210589,81.55480979305618,203.22585286374988,0.004720067036999523
0.0047889806109383684,203.793737920678,0.015205013439729319,82.16963512961739,204.76970218021083,0.0047775499229940205
0.004849423659529768,205.263694677013,0.015396920119007012,82.76232169377165,206.2591052944222,0.004837703081374258
0.0049158241116942685,206.758752082336,0.015607741554629302,83.36512883959787,207.77514174112616,0.00490378090042525
0.004983879856153068,208.17380116901,0.01582381854328599,83.93567663134483,209.21131438323505,0.004971501438271432
0.005052532794902968,209.463347010747,0.016041791623816925,84.4556215147332,210.52166744084892,0.005039811582649427
0.005124821588091168,210.768580758101,0.016271308542189455,84.98189176166632,211.84873213086146,0.005111734383950384
0.005201035659992268,212.025181998041,0.01651328822047545,85.48855338161013,213.12793253042918,0.005187556989189021
0.005284155468713068,213.222169196636,0.01677719361316399,85.97117862008363,214.34886828804727,0.005270243307033989
0.005375305902843668,214.346992029392,0.017066596241528644,86.42470718625086,215.49917268090437,0.005360910509456038
0.0054744786767313685,215.398081705746,0.017381469798622096,86.8485065437568,216.57727391105294,0.005459548184660459
0.005578418820261768,216.419364361428,0.017711479754331114,87.26028771052778,217.62664221665085,0.005562917065461397
0.005693025328605668,217.457903713289,0.018075355418322996,87.67902677719813,218.69589706703422,0.005676881303159288
0.005818206803121668,218.369371029651,0.018472806599911296,88.04653039915529,219.63988918976912,0.005801346404499989
0.005955662142825568,219.116115337031,0.018909227303471176,88.3476177038909,220.42109689002677,0.0059379972896115565
0.006090008892885968,219.784420116325,0.019335778234912948,88.61707819090225,221.1229091893512,0.0060715397356841646
0.006223145776212468,220.455862476743,0.019758487839474585,88.88780375062277,221.82779144615643,0.006203861967153913
0.006356136977930968,221.045727727951,0.020180734904930824,89.12563741990985,222.4507246517763,0.0063360219302934315
0.006494991405076968,221.541465545455,0.020621597711119374,89.32551890792746,222.98037546004088,0.006473989836024942
0.006637026186557868,221.90071858409,0.02107255814232123,89.47036973310509,223.3734794641486,0.006615098099641444
0.006779958377024368,222.21918306812,0.021526367847052367,89.59877461306598,223.72581987989818,0.00675707782048655
0.006921611437548468,222.565885782261,0.021976116314216386,89.73856514740764,224.10640036289962,0.006897767049597063
0.007072056727349768,222.871799941797,0.022453780109335512,89.86190973653257,224.4479619539119,0.007047167012922709
0.007228224022387268,223.083586667629,0.022949611271079577,89.94730214438802,224.69608480778027,0.007202225617484305
0.007384952688512868,223.271841535036,0.023447224786028356,90.02320650692651,224.92069352144938,0.007357817438538057
0.007548280256685068,223.45695882132,0.023965789814975092,90.09784579675623,225.14367457180987,0.007519934540841501
0.007704874009217368,223.632663364233,0.02446297497926514,90.16868986845876,225.35572485980015,0.007675343058640852
0.007864683313113168,223.79424879209,0.024970369519134308,90.2338411129707,225.55431968613584,0.007833917892885603
0.008033326130191969,223.924458408713,0.0255058104633595,90.2863416303931,225.7233166116368,0.008001230739748155
0.00819505025696107,224.032704957472,0.026019284565851394,90.32998663885272,225.86866423380138,0.008161653169081974
0.008367848128468568,224.134676343984,0.0265679178078877,90.37110150189436,226.01020127595393,0.008333031777771912
0.008538630482624368,224.246060473866,0.027110151782332365,90.41601158306277,226.16081472143657,0.008502382569566144
0.008709317944268768,224.333912745323,0.02765208447305334,90.45143361891424,226.28770811710388,0.008671610613332362
0.008879497650346367,224.401370739477,0.028192405039849714,90.47863268215713,226.39394218369267,0.008840306737305481
0.009054091781640069,224.478241477002,0.028746741406707216,90.50962696352721,226.51068807831592,0.009013349232503182
0.00921531774695197,224.581781654075,0.029258633846572502,90.55137436292304,226.65137413219392,0.009173115777934495
0.009393674718469368,224.6586523916,0.029824917231140242,90.58236864429311,226.76902269485635,0.009349828526809696
0.009557077135950168,224.708853689575,0.030343719906641784,90.60260980763664,226.85641353741718,0.009511697178323363
0.009734731313723467,224.738660710248,0.030907771921072007,90.614627998372,226.92643118806834,0.009687654093008351
0.00990670539669487,224.75905498755,0.03145378963450621,90.62285097098017,226.98567673055118,0.009857955692352706
0.010081139383886467,224.802981123278,0.03200761754383953,90.64056198890569,227.06925130989495,0.010030663650052491
0.01024757552396427,224.812393866649,0.03253605228858655,90.64435720703288,227.11617585152067,0.010195425096272713
0.01042352415438087,224.781018055414,0.03309468919015926,90.63170647994293,227.12402842656093,0.010369573804480977
0.01058784144127517,224.777880474291,0.03361639657604866,90.63044140723414,227.15779303225872,0.010532182773488932
0.010761767489575767,224.79513717047,0.03416861177940306,90.6373993071335,227.2143301694859,0.01070427180545178
0.010936342987985067,224.810825076087,0.034722888986852586,90.6437246706783,227.269433366531,0.010876973652417386
0.011108754981953569,224.837494515636,0.03527029706770258,90.65447778870443,227.33515915296653,0.011047505946241577
0.011275726386909567,224.846907259007,0.03580043127843787,90.65827300683162,227.38221946420242,0.011212629251798695
0.011458016441280867,224.872007907994,0.03637920220106675,90.66839358850319,227.44859507178765,0.011392870527261812
0.01163535026279217,224.868870326871,0.036942237084365136,90.66712851579437,227.48529839632252,0.01156818010504395
0.011817851754301868,224.763761359235,0.03752167931990843,90.62474858004354,227.41998617071772,0.011748566280343405
0.01237295453227047,224.611588674748,0.03928413063995874,90.5633925536584,227.39069764884167,0.012297035120494104
0.012921413520522167,224.451572037452,0.041025487927657873,90.49887384550064,227.3518036150792,0.012838644291299491
0.013472094451635368,224.257042007799,0.04277389988394229,90.42043933754456,227.2782540591724,0.01338215268935014
0.014033621864076369,224.101731742188,0.04455674941844247,90.3578182384502,227.24669070454257,0.013936062276168563
0.014593766846867667,223.897788969164,0.04633520973880484,90.27558851236692,227.16530109890914,0.014488302672945173
0.015159015132374467,223.675020709399,0.04812987304528893,90.18576835002969,227.06571373306693,0.015045265378095486
0.015725985317117268,223.489903423116,0.049930003381847325,90.11112906020037,227.00450236287188,0.01560361328981562
0.01591427259397357,223.303217346271,0.05052781548586608,90.03585723401648,226.8569256182309,0.015788968228183545
0.016114665781609968,223.107118526055,0.051164063856611645,89.95679018970537,226.70241517460042,0.0159862028093468
0.016308110547943268,222.942395517074,0.05177825098971987,89.89037387248423,226.57816474898974,0.016176561596081815
0.01651074081890457,222.71962725731,0.052421602100022,89.8005537101474,226.39689329823847,0.016375920502554077
0.016702190653441567,222.495290206983,0.05302945532467697,89.71010101145554,226.2114489635128,0.016564242967102034
0.016889452990323267,222.327429616879,0.05362401324427637,89.6424196215256,226.08241828785265,0.016748412033685604
0.017088368439266366,222.206632743626,0.05425556979467071,89.59371432223001,226.00378155359783,0.0169440045789746
0.01729087299230367,222.114074100484,0.054898521750564144,89.55639467731515,225.95462034555857,0.01714308698168679
0.01748619279366277,222.018377876219,0.05551866211987929,89.51780995969152,225.90063403549883,0.01733506850658527
0.017690877064650567,221.917975280269,0.056168534680265544,89.47732763300446,225.84389889938842,0.017536214907760417
0.017887863249490467,221.831691799374,0.05679396581713223,89.44253813350761,225.79978676668432,0.01772975808204645
0.018090216292601966,221.775215339152,0.05743643672901124,89.41976682474609,225.78717695297564,0.017928535314287817
0.01830179597347197,221.695207020504,0.0581082022157735,89.3875074706672,225.75262746768988,0.018136333891729525
0.01848831168352317,221.605785958486,0.05870038959518606,89.35145289846156,225.70290280015863,0.01831948060858712
0.01868961706917417,221.511658524783,0.05933953419462798,89.31350071719251,225.65162659896887,0.01851711222776469
0.018887991378593667,221.437925368382,0.05996937262703489,89.28377150853163,225.62044299363367,0.018711828060156952
0.019090296054621966,221.356348259172,0.06061168997342474,89.25087961809815,225.5821064810096,0.01891036273340661
0.01929332491944837,221.251239291536,0.061256306619248566,89.20849968234732,225.51991134001824,0.019109568479968544
0.019490765126822067,221.146130323901,0.06188317927766006,89.16611974659689,225.45643760874975,0.019303252753801004
0.019691355697227766,221.030039822333,0.06252005433869816,89.11931205636468,225.382420956247,0.019499989052147518
0.019903364053987266,220.904536577396,0.06319318087140957,89.06870914800605,225.30127999007323,0.019707881684414008
0.02010671854661677,220.788446075828,0.06383883138550824,89.02190145777386,225.22777721941958,0.019907247849353715
0.020303745254318568,220.672355574261,0.06446439118246144,88.97509376754203,225.1528308665112,0.02010037243071582
0.020505100392095067,220.581365721681,0.06510369374490184,88.93840665898179,225.10440877042953,0.020297701189711876
0.020701972749631366,220.498219821909,0.06572876348007958,88.9048822321937,225.06296796000439,0.020490599167322484
0.020903889530384967,220.429193037193,0.06636984925897227,88.87705063259622,225.0370205377144,0.0206884010889789
0.02109593222006397,220.363303833601,0.0669795847987031,88.85048410570793,225.012073155064,0.02087649384804725
0.02129185778197727,220.316240116749,0.06760164845777783,88.8315080150732,225.00718216837473,0.021068353164356703
0.02148907101732077,220.278589143268,0.06822780047999344,88.81632714256567,225.0121713889629,0.021261436263161838
0.02169735393735297,220.223681473608,0.06888909875109567,88.79418837015874,225.00195263592778,0.02146531674925931
0.021900698513058068,220.159361060577,0.06953471777895937,88.76825437962465,224.9810048519922,0.021664323179249108
0.022107979962628966,220.09817822867,0.07019283638134696,88.74358546179974,224.96410434276058,0.021867141741091962
0.022315377098896368,220.041701768448,0.07085132228899596,88.72081415303825,224.95201532089382,0.02207003233736948
0.02252028336463757,219.994638051596,0.07150189968272427,88.70183806240351,224.94897963921883,0.022270445769498895
0.022737270671742766,219.936592800812,0.07219083438278327,88.6784342172874,224.93735064194496,0.022482631572202386
0.022947856294741567,219.87070359722,0.07285944373580447,88.6518676903991,224.91626490679272,0.02268851430651637
0.023149042991832666,219.811089555874,0.07349821149906871,88.6278313089284,224.8995059180845,0.022885168431557603
0.02335476877923647,219.716962122171,0.07415139087407578,88.58987912765936,224.84840096941053,0.023086219401424777
0.023558153454785166,219.627541060153,0.0747971372189429,88.55382455545369,224.8015603753452,0.023284942731576063
0.023763641789965168,219.534982417011,0.0754495626831394,88.51650491053884,224.75193309953517,0.023485681410124196
0.023972972232293468,219.42516707769,0.07611418683753175,88.4722273657246,224.6854405151098,0.023690131964579326
0.024168772335196268,219.337314806234,0.07673585216424815,88.43680532987355,224.6384284323991,0.02388132977012046
0.024369101857988566,219.251031325339,0.0773718983991137,88.40201583037668,224.59398204017523,0.02407691270364065
0.02457587125696547,219.175729378376,0.07802839124086536,88.37165408536121,224.56216388623045,0.024278742818545553
0.024774272784348766,219.080033154111,0.07865831609030732,88.33306936773755,224.5075816570751,0.024472366664211924
0.024977434400743667,218.998456044902,0.07930335422236114,88.3001774773045,224.4684756146277,0.024670597129246307
0.02517991962566817,218.923154097939,0.07994624481149643,88.269815732289,224.43562152232286,0.024868128528663255
0.02538214977851967,218.855696103785,0.08058832554679994,88.24261666904611,224.41072416217344,0.02506537215910443
0.025578453739962866,218.783531737946,0.0812115906243821,88.21351999673983,224.37967618357072,0.02525679851971408
0.025782331457959568,218.689404304242,0.08185890237902163,88.17556781547039,224.32772701235768,0.025455571665948612
0.025989860030177368,218.617239938403,0.08251780559581313,88.14647114316409,224.2990714045858,0.025657863688217448
0.026203786879390567,218.576451383798,0.08319702334206505,88.13002519794736,224.30398213271252,0.025866349715167408
0.026413535604501267,218.527818876385,0.08386297554429152,88.11041657095842,224.29991120085037,0.02607072168800738
0.026621737131413768,218.474479997286,0.08452401539223871,88.08891033490572,224.29065017369606,0.02627354482542845
0.026831239009722667,218.44153539549,0.08518918385586946,88.07562707146157,224.3025924413372,0.02647759320780693
0.027037647964891366,218.389765306953,0.08584453228853008,88.05475337176345,224.29451090045762,0.026678588468188408
0.027252724074630866,218.35054554291,0.08652739893695299,88.03893996290131,224.30119271213607,0.026887980590600005
0.027460115921619167,218.279949967632,0.08718586805114086,88.01047582694922,224.27394269710842,0.02708985001357293
0.02766615520150697,218.22347350741,0.08784004276478462,87.98770451818771,224.26087799407796,0.027290362540197812
0.02787138469301117,218.156015513256,0.08849164640031046,87.96050545494482,224.23632574472046,0.027490047039461913
0.028081443434795166,218.080713566294,0.08915858290547465,87.93014370992975,224.20473478852566,0.027694389025952074
0.028291002699503767,217.97717338922,0.08982393357092446,87.88839631053352,224.14396619000465,0.027898203530302243
0.028516104461930068,217.873633212146,0.09053863166662796,87.84664891113728,224.08654049632375,0.0281170881914269
0.028730869849673366,217.771661825634,0.09122051177271293,87.80553404809564,224.02843109849337,0.02832587730737191
0.028940010651883768,217.66812164856,0.09188453381973095,87.7637866486994,223.96743940764486,0.028529156466262143
0.02915512008412687,217.580269377104,0.0925675062671028,87.72836461284832,223.92384825873015,0.02873819387159286
0.02936890124597037,217.506536220703,0.09324626145595591,87.69863540418744,223.8944642033219,0.02894589721670503
0.029581159559451266,217.43123427374,0.09392018160125776,87.66827365917197,223.86310230799992,0.029152078336173108
0.029788542411025968,217.377895394641,0.09457862215500744,87.64676742311926,223.85326605082383,0.029353482534824102
0.029990001043406867,217.322987724981,0.0952182533128168,87.62462865071235,223.84050435360948,0.029549094469576445
0.030185984477594067,217.252392149704,0.09584050071636116,87.59616451476066,223.81036948685514,0.02973935339517864
0.030389692789593966,217.178658993303,0.09648727460696084,87.56643530609978,223.77865172056545,0.029937073202231483
0.030589618926367967,217.073550025667,0.09712204009121829,87.52405537034895,223.71374719994603,0.0301310840166677
0.030785857279371966,216.9574595241,0.09774509686200598,87.4772476801171,223.63668090870405,0.0303214795616444
0.030986256793900768,216.838231441409,0.09838136532063493,87.42917491717611,223.5572365635878,0.030515874969160067
0.031191218694704967,216.720572149279,0.09903211935568826,87.3817346905893,223.48035091082875,0.030714656988569487
0.031390900491944866,216.620169553329,0.09966610906192494,87.34125236390226,223.42007174032577,0.03090828011368648
0.03158895971416277,216.54800518749,0.1002949470924668,87.31215569159596,223.38853139953991,0.031100292868291527
0.03179888748201687,216.507216632885,0.10096146775540356,87.29570974637923,223.39190525363878,0.03130377159757046
0.03200239372787467,216.471134449965,0.10160760008600206,87.28116141022589,223.39872892535246,0.031500986560435415
0.032210082608381374,216.425639523675,0.10226701228161085,87.26281785594576,223.39672725130433,0.03170221476110607
0.032420192811311574,216.378575806824,0.10293411217591424,87.24384176531143,223.3936109547182,0.03190574776762733
0.03264169695870477,216.344062414466,0.10363738784388765,87.2299259655127,223.4058997386141,0.03212027320082619
0.03285778040666167,216.290723535367,0.10432345279115081,87.20841972945996,223.39755663329004,0.032329504383030026
0.03308204395741397,216.213852797843,0.10503548956478936,87.1774254480903,223.36664898030307,0.032546609982126794
0.03329576962880467,216.119725364139,0.10571406857145482,87.13947326682084,223.3155979521039,0.03275347019011749
0.03350926538307477,216.03814825493,0.10639191759126239,87.10658137638778,223.27742789767254,0.032960065153273495
0.03373745585749517,215.962846307967,0.10711642234754716,87.0762196313723,223.24888330214105,0.03318083268237637
0.03395444646325197,215.900094685498,0.10780536752082501,87.0509181771928,223.23086289190778,0.03339071947093494
0.03415541404774197,215.826361529097,0.10844343960158076,87.02118896853192,223.19800026954096,0.03358506851298533
0.03437070106645617,215.744784419887,0.10912697588599833,86.98829707809844,223.16008391183,0.033793223505971394
0.03457779436004047,215.685170378542,0.10978449709312849,86.96426069662813,223.14308784640153,0.033993415337458435
0.03479526144954187,215.613006012703,0.11047495510229544,86.93516402432186,223.11531692883668,0.03420359212476264
0.03500395433450897,215.52829132237,0.11113755501206599,86.90100706117958,223.07263378961295,0.03440524732308592
0.03521956041952637,215.443576632036,0.11182210433199621,86.86685009803692,223.03140469622687,0.03461353989078262
0.03543201812958287,215.371412266197,0.1124966575614256,86.83775342573064,223.00245605020677,0.034818748447357675
0.03565591735038197,215.302385481481,0.11320753758746274,86.80992182613315,222.97918954354873,0.035034962561529874
0.03587836191514057,215.230221115642,0.11391379908057131,86.78082515382685,222.95232888390473,0.03524972566522574
0.036098708760332374,215.139231263062,0.11461340031405529,86.7441380452666,222.90547971534906,0.03546241802475134
0.03630943299433737,215.060791734976,0.11528244975702115,86.71251122754232,222.86952714218626,0.0356657797376163
0.03653594299220037,214.988627369137,0.11600161900023617,86.68341455523603,222.8434396026672,0.03588432956423487
0.03672241350250317,214.899206307118,0.11659366287044758,86.64735998302999,222.79082382248774,0.03606421116000572
0.03693359689827017,214.786253386674,0.1172641701520078,86.60181736550696,222.71908228854713,0.03626789334783038
0.03715222692740547,214.667025303983,0.11795832049451235,86.55374460256596,222.64238334190765,0.03647871396810888
0.03736235528671637,214.57289787028,0.11862547803532447,86.51579242129691,222.58984671540972,0.036681294718161124
0.03757685259279877,214.467788902644,0.11930650698213609,86.47341248554606,222.52681339214217,0.03688804516755453
0.03778726602089997,214.373661468941,0.1199745696163574,86.43546030427703,222.47425604274224,0.03709081770942794
0.038003337076105974,214.287377988046,0.12066059521663645,86.40067080478015,222.43101344488062,0.037298999648072366
0.03823835350235217,214.158737161985,0.12140677236996814,86.34880282371235,222.34781465920233,0.0375253860348948
0.03845306520727367,214.050490613226,0.1220884820330939,86.30515781525274,222.2813880864253,0.03773216851952592
0.03866951506077087,213.965775922893,0.1227757103179475,86.27100085211045,222.2397287174328,0.03794058169295804
0.03888382580882227,213.885767604245,0.1234561469430107,86.23874149803157,222.20246453475468,0.0381468923994951
0.039097473220512574,213.827722353461,0.12413447747512742,86.21533765291548,222.18784600197864,0.03835252217349055
0.03931937151012137,213.758695568746,0.12483900454463534,86.1875060533184,222.16355313333247,0.038566048436053914
0.03953360571109517,213.68966878403,0.12551919813272716,86.1596744537209,222.13759189427236,0.03877215651977076
0.03975138602372187,213.66299934448,0.12621065062531694,86.14892133569434,222.15639971040866,0.038981632675554025
0.039982018807815774,213.593972559765,0.12694290971481506,86.12108973609726,222.1338907878856,0.03920342339594479
0.04019409180121687,213.495138754376,0.12761624146886355,86.08123994576441,222.07638196058292,0.0394073224726185
0.04041062170906657,213.410424064043,0.12830372392628636,86.04708298262214,222.0344719796665,0.039615463795403455
0.04063438153323737,213.255113798432,0.12901416136802862,85.98446188352779,221.92060345643142,0.039830509433229126
0.04085477332687787,213.10764748563,0.12971390531283722,85.92500346620602,221.8141121178796,0.04004227301023315
0.04107584260993427,212.975869078446,0.13041580028654132,85.87187041242943,221.72403235642622,0.040254642512074425
0.041296455882707174,212.877035273057,0.13111624742759528,85.83202062209659,221.66810236865228,0.04046652899727016
0.04151193485967147,212.806439697779,0.1318003931794569,85.8035564861445,221.64044676023184,0.04067344095200484
0.04172184638114587,212.738981703625,0.13246686226013812,85.7763574229016,221.61484481754508,0.040874965643160545
0.04194960239327157,212.660542175539,0.13318998759863723,85.74473060517732,221.5815673645404,0.041093575936224314
0.04217127761764357,212.647991851045,0.1338938064360183,85.73967031434135,221.6156293502298,0.04130630373654921
0.04239799454898797,212.619753620934,0.13461363269303678,85.7282846599606,221.63440477596154,0.04152382294808671
0.04262086259872157,212.569552322959,0.13532123875094096,85.70804349661707,221.6294500051876,0.041737603317332166
0.04284765515347297,212.486406423188,0.13604130511227666,85.6745190698294,221.59095069040944,0.041955101259607226
0.04306428798978017,212.400122942293,0.13672911436755203,85.63972957033253,221.54698300574464,0.042162811693212364
0.04330099241107657,212.316977042522,0.13748065090516812,85.60620514354488,221.51051285418296,0.04238971771444985
0.04352071342642217,212.221280818257,0.1381782651288904,85.56762042592122,221.4573023637366,0.04260029729155788
0.04375094524748087,212.125584593991,0.13890925116075176,85.52903570829716,221.40627943115257,0.04282090280884712
0.04397816941524447,212.003218930177,0.1396306878934012,85.47969787264738,221.32673240886552,0.043038578720022584
0.04420288704850877,211.869871732431,0.14034416637901534,85.42593228251617,221.23513174160166,0.04325380683296425
0.04442441063823587,211.763193974233,0.14104750377639888,85.38291981041075,221.1706490614087,0.043465930451958554
0.04466370992283437,211.651809844351,0.14180727900499912,85.33800972924232,221.104964883882,0.04369502493896458
0.04489113302980697,211.546700876716,0.14252934736963713,85.29562979349188,221.04327196778942,0.043912701070928824
0.04512037339641787,211.440023118518,0.14325718553362674,85.25261732138647,220.98027591257278,0.044132068635964056
0.04534426502819207,211.331776569759,0.1439680414645098,85.20897231292683,220.91446065541683,0.044346271381626445
0.04557344156112457,211.261180994482,0.1446956769565705,85.18050817697515,220.8890800806682,0.044565482815082706
0.04580891813902227,211.199998162575,0.1454433150913957,85.15583925915026,220.87484158936604,0.044790670311573216
0.046044222735332374,211.129402587297,0.1461904071846803,85.12737512319815,220.85069182600415,0.045015642698692376
0.04627106337771357,211.043119106402,0.1469106262242406,85.0925856237013,220.80830864600466,0.04523247487955482
0.04650182656046557,210.942716510452,0.14764329932947817,85.05210329701424,220.75193812781447,0.04545300830178788
0.04673849848251627,210.790543825965,0.14839473268198916,84.99074727062909,220.64257733870363,0.045679138020605
0.04696845079118717,210.647783884848,0.14912483126201925,84.9331864623707,220.54158395651612,0.04589879847468643
0.04719510798510297,210.511299105978,0.14984446785270192,84.87815579953032,220.44640259936892,0.046115264083450326
0.04742721098244547,210.396777394972,0.15058139486926436,84.8319806456527,220.3753097465099,0.0463368820774826
0.04766589601436707,210.280686893405,0.15133921984561544,84.78517295542089,220.30390424869572,0.046564733557836496
0.04790299279811667,210.186559459701,0.1520920021340204,84.74722077415144,220.25512470375998,0.046791017490593084
0.04814755311527747,210.090863235436,0.15286848114100596,84.7086360565278,220.20622423209866,0.04702437094549653
0.04838934266522007,210.035955565776,0.15363616296207372,84.68649728412089,220.19945739166525,0.047255027082768505
0.04865207994868117,209.948103294319,0.1544703538370627,84.65107524826942,220.16251520086817,0.047505606095660326
0.04889763724169537,209.852407070054,0.1552499982423828,84.61249053064577,220.1136939452621,0.047739743377006816
0.04913786506908587,209.737885359048,0.15601272159434765,84.56631537676815,220.0439572696963,0.04796874601130521
0.04938102780167647,209.620226066919,0.15678476327032279,84.51887515018174,219.97148827812322,0.04820049301582815
0.04962056647275647,209.491585240858,0.15754529855100177,84.46700716911396,219.88667637178511,0.04842873359722965
0.04985530180347017,209.308036745136,0.15829058322601777,84.39300041563884,219.7431520869566,0.048652346866844956
0.05009982102037057,209.1291946211,0.15906693173967654,84.32089127122752,219.60652984175132,0.04888522728923851
0.05032795693998497,208.964471612119,0.15979126328445228,84.25447495400638,219.48122654140047,0.04910245534430948
0.05057043033950927,208.795042231453,0.16056111632794193,84.18616102772185,219.35389736985363,0.04933328364335437
0.05080634766861087,208.627181641348,0.1613101538478395,84.11847963779152,219.22676676494075,0.049557819607167916
0.05104616125875227,208.465596213491,0.16207156199653844,84.05332839327957,219.10696465470681,0.049786012204092206
0.05129266222874837,208.313423529004,0.16285420257627606,83.99197236689443,218.99837359979142,0.05002051386326513
0.05153473422416027,208.224002466985,0.16362278116170886,83.95591779468836,218.954771093212,0.05025074863849164
0.051777875192970974,208.143994148337,0.16439475373768284,83.92365844060947,218.92124789951606,0.05048194676739083
0.05201636071337157,208.057710667443,0.16515194526495472,83.88886894111302,218.88011559471903,0.050708666203495324
0.05226704290473847,207.947895328122,0.16594786122254462,83.84459139629878,218.81671689518703,0.05094692516815918
0.05253155090323937,207.823960873746,0.16678767411778497,83.79462102429437,218.741275853298,0.05119826323031053
0.05278723747835507,207.690613675999,0.16759947899377733,83.74085543416281,218.65402742213928,0.05144115905946846
0.053040200206866374,207.532165829265,0.16840263565680072,83.67696926235965,218.53971345421382,0.0516814092577526
0.05329528567513567,207.37214919197,0.16921253201855574,83.61245055420231,218.4241071242229,0.051923617083833515
0.05354921434481577,207.212132554674,0.17001875554479007,83.54793184604456,218.30817945569063,0.05216466825861861
0.05381566034540147,207.041134383446,0.17086472159664967,83.47898538340543,218.18318974895215,0.052417539515234424
0.05407388453085997,206.884255327274,0.1716845833854804,83.41573174795687,218.07129066109394,0.05266254683772713
0.05432736573990917,206.73522022391,0.17248938622421162,83.35564079428052,217.96660014433505,0.0529029955760667
0.05459361949186707,206.583047539423,0.17333474188667794,83.29428476789535,217.86116383026055,0.05315549792701955
0.05486367896956137,206.437150017182,0.17419218072835732,83.23545888692779,217.76305154311586,0.053411544332288535
0.05513643648479217,206.267720636516,0.17505818583921512,83.16714496064326,217.6405877142541,0.05367008224871077
0.05540312968641607,206.081034559671,0.17590493675437102,83.09187313445935,217.49856884329125,0.05392280738811885
0.05566639880231257,205.883366948894,0.1767408161973424,83.01217355379407,217.344152560234,0.05417222514884002
0.05592724527615577,205.619810134524,0.17756900375179457,82.90590744624008,217.11955968955408,0.05441928639180358
0.05620177613047167,205.343702995661,0.17844063921424755,82.79458104785051,216.88438382122519,0.054679242912527036
0.05647180205681697,205.080146181292,0.17929797153039387,82.68831494029693,216.661391602225,0.0549348677573716
0.05674602617865417,204.811882995237,0.180168633117227,82.58015122367955,216.43414346938417,0.055194400040047276
0.05703208781656257,204.540482228059,0.18107687881758616,82.47072243435339,216.20585297253174,0.05546506386967153
0.05732349079117447,204.251824764702,0.18200208326197895,82.35433574512784,215.96025236068198,0.055740706225578994
0.05761951073685377,203.950616976851,0.1829419465895107,82.23288876506633,215.70215174153662,0.056020638069981976
0.05792312948926377,203.690197743605,0.18390593612841247,82.12788773022154,215.48857144320158,0.056307674359131935
0.05821758976985327,203.404677861371,0.18484084751928412,82.01276611370479,215.24640795437347,0.05658597369887836
0.05851775663828917,203.083075796218,0.1857938773265681,81.8830961610351,214.9670418030163,0.056869586736244676
0.05881582675823157,202.692446946349,0.18674024995738522,81.72559460876792,214.6139707911475,0.05715113908515072
0.05912014731018327,202.295542934233,0.18770646770983188,81.56556291108275,214.25528523269836,0.05743851373459444
0.05942159954357557,201.89236375987,0.18866357855085242,81.40300106797959,213.8891309501149,0.057723098388991353
0.05971431322179097,201.506441281686,0.18959294447918631,81.24739712477579,213.53926003258903,0.05799935596955872
0.06000868824006717,201.031097741484,0.19052758516221327,81.05573860936634,213.09471021241117,0.05827710454327864
0.060300280620078174,200.525947180609,0.1914533909687482,80.85206190322155,212.61771806720668,0.05855215161059911
0.06058849883204067,199.964320159512,0.1923684837917291,80.62561388831524,212.0798581379464,0.05882394164176825
0.06087809673971927,199.426224996841,0.19328795714860866,80.4086539187263,211.56691401463573,0.05909695834642154
0.06114305230536657,198.883423462484,0.19412919106953885,80.18979634007354,211.04376302592104,0.05934667835241059
0.06141781321374377,198.302970954647,0.19500155695363644,79.95575788891368,210.48230578446996,0.059605574023555055
0.06170417419926187,197.642510128161,0.19591075308265643,79.68946008367452,209.83787800228845,0.059875328648067765
0.06199745102725587,196.933416794262,0.1968419070115374,79.40355365144644,209.14278665759443,0.060151522654207416
0.06231049410052817,196.243148947104,0.19783581876917694,79.12523765547233,208.47115652184158,0.06044624741504659
0.06261344637076546,195.526211660396,0.19879769222718033,78.83616854147168,207.76878162827316,0.060731389171436057
0.06291923436078807,194.76534823796,0.1997685690955021,78.52938840954549,207.01983482910472,0.06101911750881164
0.06324460844046406,193.889963104519,0.20080163179847338,78.17643312374206,206.15245790160034,0.061325184309183295
0.06356130957372357,192.948688767485,0.2018071578965723,77.79691131104995,205.21276010607914,0.06162300286697251
0.06389610944790167,191.830141096976,0.2028701474970878,77.34591289030072,204.0873407879148,0.06193774465587832
0.06423873664855877,190.769638677251,0.20395798885917407,76.9183183146676,203.02443925677966,0.06225974230019685
0.06455978763534627,189.564807525847,0.20497732574222438,76.4325303944215,201.80307124285096,0.0625613687674827
0.06488791128659337,188.212510061642,0.20601911833493392,75.88728405685406,200.4252267175489,0.0628695460042471
0.06521570803305127,186.720590237443,0.20705987300493775,75.28574198373701,198.89770573412707,0.06317732140641288
0.06553446572509757,185.165918790775,0.20807192867718477,74.65889845644048,197.30066834922525,0.0634765190301887
0.06586165419829926,183.495156842539,0.20911075207960014,73.98524723891173,195.58045140956497,0.06378353701967768
0.06617464725702857,181.99382427497,0.2101045050410657,73.3799099476679,194.03720139932378,0.06407714652413517
0.06648801941668116,180.410914598191,0.21109946164796267,72.74168076599061,192.40607899097674,0.06437102531406755
0.06681171214722516,178.804473062986,0.21212718606743985,72.09396353899596,190.7507060479065,0.0646744920311338
0.06713449896177447,177.243526454072,0.2131520342036339,71.46458986628183,189.14268179678413,0.06497701776053662
0.06746256325080527,175.684148635719,0.21419363832130672,70.8358487299219,187.53625162522005,0.06528439595141057
0.06779881520707827,174.121633236242,0.21526123828247348,70.20584252085278,185.92687367158064,0.06559934751888138
0.06813184331575846,172.64540131766,0.2163186025275331,69.61062581128051,184.40805074942105,0.06591118171635402
0.06848145218192186,171.07974833706,0.2174286106776019,68.9793545295026,182.79553794209963,0.06623843688229375
0.06881640349709596,169.448206152868,0.21849208110327967,68.32151672083639,181.10902227934287,0.06655187126583201
0.06916512631366227,167.849608570472,0.2195992760458777,67.6769621756143,179.45894794894747,0.06687808813421606
0.06959598635715317,166.150608392125,0.2209672566839613,66.9919253037048,177.71402386701604,0.06728099432768181
0.07007515383424916,164.482984025013,0.22248861342374107,66.31953915888523,176.00915443368214,0.06772888323556649
0.07060327959562997,162.57690349252,0.22416541271612514,65.55100748818406,174.05536606559411,0.06822230229734443
0.07115562456049336,160.093508033311,0.2259191079795664,64.549702439031,171.4850615855016,0.06873808862234758
0.07170975712562827,157.065742249185,0.22767847887386974,63.3289072748714,168.32888847863057,0.06925527703952251
0.07228869003297016,153.835602482597,0.22951659085468024,62.02651492098312,164.9561766664967,0.06979532679765543
0.07262411804864287,152.286421802895,0.2305815748044411,61.401885270927266,163.34608887711389,0.07010809290837397
0.07292167991524197,150.583185890032,0.23152633373089324,60.71514055086091,161.5639647721223,0.07038546929324463
0.07319894906642237,148.431903392741,0.232406663285891,59.84774344795317,159.2969627290184,0.07064386031654397