File: example/data/02 processed data/test_ID_122.csv
Strain,Stress_MPa,Displacement(mm),Force(kN),True Stress (MPa),True Strain
-3.05961003484292e-06,0.0139376530512361,-9.71426186062627e-06,0.002809830855129198,0.013937610407452962,-3.05961471549975e-06
-4.17123165759775e-05,0.0064561755770675,-0.00013243660512872856,0.001301564996336808,0.00645590627502796,-4.171318655888453e-05
-8.30916988775232e-05,0.0303960806114643,-0.00026381614393613617,0.006127849851271202,0.030393554949487072,-8.30951511839977e-05
-0.0001125037203759,0.224756795929141,-0.0003571993121934825,0.04531097005931483,0.2247315099534192,-0.00011251004939410182
-0.0001541140256659,0.662874034255029,-0.0004893120314892324,0.13363540530581386,0.6627718760691006,-0.00015412590245261892
-0.0001965750644623,1.32835404926376,-0.0006241258296678025,0.267796176331574,1.3280929279808973,-0.0001965943878726049
-0.0002550368242139,2.35220559949051,-0.0008097419168791324,0.4742046488572868,2.3516057004445177,-0.0002550693516353359
-0.0003020018824423,3.81699419495042,-0.0009588559767543024,0.7695060297020047,3.8158414555182736,-0.0003020474941942914
-0.000319973553373,5.50538495648604,-0.001015916031959275,1.1098856072275856,5.503623378898827,-0.0003200247558329966
-0.0003206348890121,7.49591662249867,-0.0010180157726134176,1.5111767910957319,7.493513170104371,-0.0003206863033686053
-0.0003100641387515,9.61635669734649,-0.0009844536405360124,1.9386575101850523,9.6133750099892,-0.00031011221857533305
-0.0003012009639993,11.834846182302,-0.0009563130606977774,2.3859049903520835,11.831281515223107,-0.0003012463341202615
-0.0002923184781478,14.2063711865537,-0.000928111168119265,2.864004431209226,14.202218401748443,-0.0002923612115221856
-0.0002679640719271,16.5436965565597,-0.0008507859283685425,3.3352092258024353,16.539263440265678,-0.00026799998071399314
-0.000240958938496,18.8305068704783,-0.0007650446297248,3.796230185088425,18.82596949153145,-0.00024098797376528029
-0.0002022036746181,21.2732706541378,-0.0006419966669124675,4.288691363874181,21.26896912064039,-0.0002022241205373165
-0.0001633098658772,23.7367424732121,-0.00051850882416011,4.785327282599559,23.73286602898244,-0.0001633232023853587
-0.0001308325780287,26.2642209472047,-0.00041539343524112245,5.294866942956467,26.26078473146826,-0.0001308411373570099
-9.46236613969545e-05,28.8130349728367,-0.00030043012493533055,5.808707850523879,28.81030857797161,-9.46281384980854e-05
-4.60612764261455e-05,31.3896165914112,-0.00014624455265301197,6.328146704828498,31.388170745604473,-4.6062337279315175e-05
4.48203765832343e-06,33.9661982099857,1.4230469565176888e-05,6.847585559133117,33.96635044776519,4.482027614047986e-06
5.38838335467867e-05,36.5239543418195,0.00017108117151104775,7.363229195310811,36.52592239249572,5.388238186526401e-05
9.77055031401686e-05,39.0200570045777,0.0003102149724700353,7.8664434921228645,39.02386947887989,9.770073026836024e-05
0.0001401624641489,41.5432997440536,0.0004450158236727575,8.375129228401205,41.5491225553146,0.00014015264230840977
0.0001815677408716,44.0232438640259,0.00057647757726733,8.875085962987622,44.03123706496013,0.0001815512594443396
0.0002277739559206,46.4849900134823,0.0007231823100479049,9.371373986718032,46.49557808354861,0.00022774801937153693
0.0002752068506333,48.8358226702248,0.0008737817507607276,9.84530185031732,48.84926262317996,0.00027516898817450886
0.0003274812209911,51.2379547783357,0.0010397528766467425,10.329571683312476,51.254734246327594,0.0003274276107198894
0.000383061966158,53.5782765383146,0.00121622174255165,10.801380550124222,53.598800338268724,0.00038298861665405205
0.000427130059889,55.9046360622943,0.001356137940147575,11.27037463015853,55.928514612843664,0.00042703886581190256
0.000472751374712,58.1684008428612,0.0015009856147106,11.72674960992082,58.19590003432447,0.00047263966298741417
0.0005289128006669,60.4290280423046,0.0016792981421174073,12.182492053328609,60.460989728768034,0.0005287729755929013
0.000586621865173,62.6924790647591,0.001862524421924275,12.638803779455435,62.72925584376039,0.000586449869827626
0.000633911279305,65.0296632436146,0.002012668311793375,13.109980109912707,65.07088628063414,0.0006337104424206909
0.0006824826094025,67.2810345787439,0.0021668822848529374,13.563856571074771,67.3269527147865,0.0006822498240550569
0.0007230920443758,69.5537414655126,0.0022958172408931647,14.022034279447341,69.60403522262288,0.000722830739280889
0.0007720785535013,71.8032302519677,0.002451349407366627,14.47553121879669,71.85866798611737,0.0007717806541794561
0.0008275866254382,74.0740545900624,0.002627587535766285,14.93332940535658,74.13535728693311,0.0008272443644475631
0.0008728337967235,76.3456633234378,0.0027712473045971124,15.391285726005062,76.41230039861976,0.0008724530988129718
0.0009230629853092,78.6001722396905,0.00293072497835671,15.845794723521603,78.67272514932388,0.0009226372246542306
0.0009717283677585,80.8247172562143,0.0030852375676332375,16.294262998852805,80.90325692678823,0.0009712565453789751
0.0010257323254663,83.0625969925128,0.0032567001333555024,16.745419553690578,83.14779698328519,0.001025206621521544
0.0010849042915522,85.2937309293958,0.0034445711256782348,17.195216155366197,85.38626646412361,0.001084316208195594
0.0011413840581929,87.540552771896,0.0036238943847624575,17.648175438814235,87.64047016327524,0.0011407331746337136
0.0011996756451418,89.7727848621723,0.003808970173325215,18.098193428213936,89.880483085768,0.0011989566093307234
0.0012578181585532,92.0177241559985,0.00399357265340641,18.5507731898493,92.13346572035064,0.0012570277680021662
0.0013091403311873,94.2314445176464,0.004156520551519677,18.997059214757513,94.35480670213049,0.0013082841541397772
0.0013683007114906,96.4172404072956,0.004344354758982654,19.43771566611079,96.54916818594486,0.0013673654411289577
0.0014176866453034,98.5506386921832,0.004501155098838295,19.867808760344133,98.69035261654324,0.001416682676354935
0.0014701329618222,100.680271879723,0.004667672153785485,20.297142810952156,100.82828526601861,0.0014690533743215036
0.0015208050126255,102.788098878454,0.004828555915085962,20.722080733896323,102.94441953446659,0.001519649759810063
0.0015631748924742,104.909731234129,0.004963080283605585,21.149801816800405,105.07372349197041,0.0015619544063253563
0.0016099059348513,106.96923948356,0.005111451343152877,21.564998679885697,107.14144989705112,0.0016086114254644569
0.0016559695565936,109.053534623865,0.00525770334218468,21.985192580171184,109.23412395724105,0.0016545999508159681
0.0017061943582736,111.100492548802,0.00541716708751868,22.397859297838483,111.29005158239019,0.0017047404621975137
0.0017563586343729,113.187454633063,0.005576438664133957,22.8185908540255,113.38625239631048,0.0017548180401735281
0.001796535213696,115.2573169002,0.0057039993034848,23.235875087080323,115.46438072864731,0.0017949233745040859
0.0018468548807793,117.311020624553,0.005863764246474277,23.649901757909884,117.52767705556265,0.0018451515411955252
0.0018967925926523,119.297109475694,0.006022316481671053,24.05029727029991,119.52339134927233,0.0018949959531254761
0.0019429907501698,121.306730185262,0.006168995631789115,24.455436805348818,121.5424280399453,0.0019411055851526566
0.0019910639520832,123.278699921348,0.00632162804786416,24.852985904143758,123.52415569682108,0.00198908441141182
0.002027597885171,125.228706589571,0.006437623285417925,25.246107248457516,125.4826200502147,0.0020255450829489013
0.0020659508938956,127.150475027682,0.0065593940881185295,25.633535765580692,127.41316166522469,0.002063819752065746
0.002109612689791,129.062830722423,0.006698020290086424,26.019066673640477,129.33510330789537,0.002107390581583564
0.0021467392701514,130.976755207725,0.006815897182730694,26.404913849877364,131.25792815160642,0.0021444383178456433
0.0021953390947694,132.889110902466,0.006970201625892844,26.79044475793715,133.18084756289932,0.0021929328589243733
0.0022406905614627,134.752834089793,0.007114192532644073,27.16617135250227,135.05477349326836,0.002238183958016714
0.0022760022704922,136.604006952627,0.007226307208812734,27.539367801649604,136.91491798260952,0.00227341610066677
0.0023200005572891,138.453611024899,0.007366001769392892,27.91224798261964,138.77482347963547,0.0023173135111594773
0.0023698156760442,140.348710023461,0.007524164771440335,28.29429994072974,140.68131059658717,0.002367012091320627
0.0024116117088969,142.17791981843,0.007656867175747657,28.66306863539549,142.52079775461073,0.0024087084401473204
0.0024633291829096,143.993010498344,0.00782107015573798,29.02899091646615,144.3477126832396,0.0024603001608771505
0.002493888239345,145.770450204777,0.007918095159920376,29.387322761283045,146.13398541618673,0.002490783660646784
0.0025289075750502,147.554165073456,0.008029281550784384,29.74691967880873,147.9273159192405,0.0025257152691870286
0.0025763577439891,149.406906726852,0.008179935837165392,30.12043239613336,149.79183236800316,0.002573044623678558
0.0026165399904095,151.195327967216,0.008307514469550161,30.480978118190748,151.59093658920528,0.002613122809145122
0.0026514117674252,152.856677172081,0.008418232361575009,30.81590611789153,153.26196316466456,0.002647902976043738
0.0026897192217947,154.582346789977,0.008539858529198172,31.163801112859364,154.99812989948816,0.0026861084003300933
0.0027162751903399,156.312722779558,0.008624173729329181,31.512644912358894,156.73731115037856,0.0027125927816679463
0.0027577216761035,158.054080303071,0.00875576632162861,31.863702589099116,158.4899494663194,0.002753926138105689
0.0028009105045784,159.825244847257,0.00889289085203642,32.22076936120701,160.2729010544465,0.0027969952638729947
0.0028326816345366,161.508557119986,0.008993764189653704,32.56012511538918,161.96605944356028,0.0028286771524147565
0.0028737202128606,163.229520366196,0.009124061675832405,32.90707130582511,163.69859633820786,0.002869598972569467
0.0029160633068063,164.972446680271,0.009258500999110002,33.25844525074263,165.4535167786694,0.002911819841675485
0.0029463577078586,166.687134764235,0.009354685722451055,33.60412636846978,167.17825468854846,0.002942025702991892
0.0029850225958545,168.398685267075,0.009477446741838036,33.949174949842316,168.9013591477094,0.0029805762619795188
0.0030235898208512,170.15102432452,0.00959989768120256,34.302446503823234,170.66549122967504,0.0030190279662870305
0.003060075968538,171.851593293428,0.009715741200108149,34.64528120795509,172.37747222422018,0.0030554034657868127
0.0031006649770498,173.517648869979,0.009844611302133115,34.98115801218777,174.05566896673017,0.0030958678290742623
0.0031317720056731,175.216649048325,0.009943376118012092,35.32367644814232,175.7653876447424,0.0031268782225386286
0.0031696605174321,176.940749875659,0.010063672142846918,35.67125517493286,177.5015919844647,0.0031646477332903152
0.0032254182395288,178.619355776703,0.010240702910503939,36.00966212458332,179.19547790475806,0.0032202277361536185
0.0032697678579427,180.296392887185,0.010381512948968073,36.3477528060565,180.88592023755052,0.003264433791297374
0.0033049056294594,181.924797490254,0.010493075373533594,36.67603917403521,182.52604177761782,0.003299456431605267
0.0033534629384612,183.534376606582,0.01064724482961431,37.00053032388693,184.14985233646576,0.0033478526207842106
0.0033948887609534,185.178469115269,0.010778771816027044,37.33197937363823,185.80712941883897,0.003389139135321937
0.0034452193218782,186.77236032598,0.010938571346963286,37.65330784171757,187.41583207056786,0.0034392981497173313
0.0034908062617733,188.358407583882,0.011083309881130227,37.97305496891062,189.01593029253348,0.0034847275399140483
0.0035314624018906,189.985243396389,0.011212393126002656,38.30102506871202,190.65616914035735,0.0035252414303252383
0.0035685742926319,191.565015492045,0.011330223379106283,38.61950712319627,192.24862948169755,0.003562222039230764
0.0036181001209234,193.124393310398,0.011487467883931795,38.93387769137624,193.82313670118762,0.0036115705417222544
0.003654408448207,194.708871777738,0.011602746823057225,39.253308550391985,195.42041752370343,0.0036477473210410442
0.0036984276567856,196.197654020814,0.011742507810294279,39.553447050596105,196.92327685064103,0.0036916052893999182
0.003744921504692,197.70526175063,0.0118901257773971,39.85738076892701,198.44565243695072,0.003737926743934905
0.0037945972394701,199.267777150106,0.012047846235317567,40.17238387346137,200.02391810719516,0.0037874159164512323
0.0038439662978181,200.750284230935,0.012204592995572467,40.471257300956495,201.5219615577961,0.0038365971378667195
0.0039034507310719,202.268873494683,0.012393456071153282,40.77740489652809,203.05842007679888,0.0038958520349385794
0.0039612072414715,203.793737920678,0.012576832991672013,41.084817564808695,204.60100715109593,0.003953382317356998
0.0040216502900629,205.263694677013,0.012768739670949707,41.38116084688583,206.0891934742502,0.004013585070964268
0.0040880507422274,206.758752082336,0.012979561106571995,41.682564419798936,207.6039923522482,0.004079717366579897
0.0041561064866862,208.17380116901,0.013195638095228683,41.96783831567242,209.03899365440665,0.004147493731560082
0.0042247594254361,209.463347010747,0.013413611175759618,42.2278107573666,210.34827926031403,0.0042158601852959115
0.0042970482186243,210.768580758101,0.013643128094132151,42.49094588083316,211.67426351258953,0.004287842269776346
0.0043732622905254,212.025181998041,0.013885107772418144,42.744276690805066,212.95242373111483,0.004363727368031756
0.0044563820992462,213.222169196636,0.014149013165106684,42.98558931004182,214.17236865460634,0.004446481830562065
0.0045475325333768,214.346992029392,0.01443841579347134,43.21235359312543,215.3217419490771,0.00453722374851374
0.0046467053072645,215.398081705746,0.014753289350564788,43.4242532718784,216.39897311518268,0.004635942699723591
0.0047506454507949,216.419364361428,0.015083299306273806,43.63014385526389,217.44749603019554,0.004739396746364805
0.0048652519591388,217.457903713289,0.015447174970265688,43.839513388599066,218.5158912053603,0.004853454869228874
0.0049904334336548,218.369371029651,0.01584462615185399,44.023265199577644,219.45912883972355,0.004978022494245611
0.0051278887733587,219.116115337031,0.016281046855413872,44.17380885194545,220.23971840492976,0.005114785925929897
0.0052622355234191,219.784420116325,0.01670759778685564,44.308539095451124,220.9409774993552,0.005248438343574237
0.0053953724067456,220.455862476743,0.017130307391417278,44.44390187531138,221.64530395405535,0.005380869527278605
0.0055283636084641,221.045727727951,0.017552554456873516,44.562818709954925,222.2677488849287,0.005513138294642129
0.0056672180356101,221.541465545455,0.017993417263062066,44.66275945396373,222.7969893346297,0.00565121977078878
0.005809252817091,221.90071858409,0.018444377694263922,44.735184866552544,223.18979595863914,0.005792444173634266
0.0059521850075575,222.21918306812,0.018898187398995063,44.79938730653299,223.54187275796974,0.005934540734408903
0.0060938380680816,222.565885782261,0.01934793586615908,44.86928257370382,223.92216624969723,0.0060753457250835715
0.0062442833578829,222.871799941797,0.01982559966127821,44.930954868266284,224.26347461311497,0.0062248685994751125
0.0064004506529204,223.083586667629,0.02032143082302227,44.97365107219401,224.51142215557167,0.006380054751021935
0.006557179319046,223.271841535036,0.02081904433797105,45.01160325346326,224.73587503687486,0.006535774537776086
0.0067205068872182,223.45695882132,0.021337609366917785,45.048922898378116,224.95870285207553,0.006698024951268074
0.0068771006397505,223.632663364233,0.021834794531207836,45.08434493422938,225.17060769652429,0.006853561243387836
0.0070369099436463,223.79424879209,0.022342189071077,45.11692055648535,225.3690687667459,0.007012266434762749
0.0072055527607251,223.924458408713,0.02287763001530219,45.14317081519655,225.5379579081938,0.007179716799448715
0.0073672768874942,224.032704957472,0.023391104117794086,45.16499331942636,225.68321592674798,0.0073402710616093094
0.0075400747590017,224.134676343984,0.023939737359830397,45.18555075094718,225.8246685597023,0.0075117904833733075
0.0077108571131575,224.246060473866,0.02448197133427506,45.208005791531384,225.97518980436845,0.0076812803983645535
0.0078815445748019,224.333912745323,0.02502390402499603,45.22571680945712,226.102010478265,0.00785064744093683
0.0080517242808795,224.401370739477,0.02556422459179241,45.23931634107856,226.2081887049227,0.008019482103384191
0.0082263184121732,224.478241477002,0.02611856095864991,45.254813481763605,226.3248709679965,0.008192666682130879
0.0083875443774851,224.581781654075,0.026630453398515195,45.27568718146152,226.4654713140732,0.008352564388509186
0.0085659013490025,224.6586523916,0.027196736783082934,45.291184322146556,226.58305624518627,0.00852942218595639
0.0087293037664833,224.708853689575,0.027715539458584473,45.30130490381832,226.67040553244954,0.008691423679266655
0.0089069579442566,224.738660710248,0.028279591473014704,45.307313999186,226.74039850964277,0.008867524973245045
0.009078932027228,224.75905498755,0.0288256091864489,45.31142548549008,226.79962717028596,0.00903796628727234
0.0092533660144196,224.802981123278,0.029379437095782227,45.320280994452844,226.88316538874435,0.009210815909502715
0.0094198021544974,224.812393866649,0.029907871840529246,45.32217860351644,226.93008213875174,0.009375712479268704
0.009595750784914,224.781018055414,0.03046650874210195,45.31585323997147,226.937960685853,0.009550003985449477
0.0097600680718083,224.777880474291,0.030988216127991353,45.31522070361707,226.9717278887569,0.009712746267639308
0.0099339941201089,224.79513717047,0.03154043133134576,45.31869965356675,227.02825074135052,0.009884976361281949
0.0101085696185182,224.810825076087,0.032094708538795286,45.32186233533915,227.08334095236515,0.01005781974782999
0.0102809816124867,224.837494515636,0.03264211661964527,45.32723889435221,227.14904466254882,0.010228491779153874
0.0104479530174427,224.846907259007,0.03317225083038057,45.32913650341581,227.19609718216637,0.010393750367254906
0.010630243071814,224.872007907994,0.033751021753009446,45.334196794251596,227.26245201210284,0.010574139285623679
0.0108075768933253,224.868870326871,0.03431405663630783,45.33356425789719,227.29915793384384,0.010749592441011256
0.010990078384835,224.763761359235,0.03489349887185112,45.31237429002177,227.23393271464332,0.01093012632532831
0.0115451811628036,224.611588674748,0.03665595019190143,45.2816962768292,227.20477015726308,0.011479044114807066
0.0120936401510553,224.451572037452,0.03839730747960057,45.24943692275032,227.16600858101162,0.012021096378189522
0.0126443210821685,224.257042007799,0.040145719435884984,45.21021966877228,227.09262005188296,0.012565049181203955
0.0132058484946095,224.101731742188,0.04192856897038516,45.1789091192251,227.061185258955,0.013119411428969786
0.0137659934774008,223.897788969164,0.04370702929074754,45.13779425618346,226.97996447171798,0.013672102872877682
0.0143312417629076,223.675020709399,0.04550169259723163,45.092884175014845,226.88056150750876,0.01422952022971921
0.0148982119476504,223.489903423116,0.04730182293379002,45.055564530100185,226.8195033724735,0.01478832366957631
0.0150864992245067,223.303217346271,0.047899635037808766,45.01792861700824,226.67208116159537,0.014973829773499243
0.0152868924121431,223.107118526055,0.048535883408554345,44.97839509485269,226.51773304334608,0.015171225177824934
0.0154803371784764,222.942395517074,0.049150070541662566,44.945186936242116,226.39361897105556,0.015361739151164263
0.0156829674494377,222.71962725731,0.0497934216519647,44.9002768550737,226.21253192193728,0.015561260549735964
0.0158744172839747,222.495290206983,0.05040127487661967,44.85505050572777,226.02727328744768,0.015749736481100188
0.0160616796208564,222.327429616879,0.05099583279621907,44.8212098107628,225.8983815623138,0.015934055601861046
0.0162605950697995,222.206632743626,0.05162738934661341,44.79685716111501,225.81984482049376,0.016129807478475887
0.0164630996228368,222.114074100484,0.052270341302506844,44.77819733865758,225.77076023003443,0.01632905202335508
0.0166584194241959,222.018377876219,0.05289048167182198,44.75890497984576,225.71685313476067,0.01652118987653323
0.0168631036951837,221.917975280269,0.053540354232208244,44.73866381650223,225.66020110924535,0.016722500036619476
0.0170600898800236,221.831691799374,0.054165785369074924,44.721269066753806,225.616160399709,0.016916200748699487
0.0172624429231351,221.775215339152,0.05480825628095393,44.709883412373046,225.60359733571013,0.017115139747325446
0.0174740226040051,221.695207020504,0.055480021767716194,44.6937537353336,225.56911407917988,0.017323107398387026
0.0176605383140563,221.605785958486,0.05607220914712875,44.67572644923078,225.51946343202238,0.017506403101929295
0.0178618436997073,221.511658524783,0.05671135374657068,44.656750358596256,225.46826514701561,0.017704195460378568
0.0180602180091268,221.437925368382,0.05734119217897758,44.641885754265815,225.43714257602372,0.017899069629462097
0.0182625226851551,221.356348259172,0.05798350952536744,44.62543980904908,225.39887359075823,0.018097765712996528
0.0184655515499815,221.251239291536,0.058628126171191265,44.60424984117366,225.33676545617112,0.018297133383199625
0.0186629917573552,221.146130323901,0.05925499882960276,44.583059873298446,225.273378731307,0.018490975061615823
0.0188635823277609,221.030039822333,0.05989187389064085,44.55965602818234,225.19945817542987,0.018687871213651314
0.0190755906845204,220.904536577396,0.060565000423352264,44.534354574003025,225.11842109750006,0.018895932730238024
0.0192789451771499,220.788446075828,0.061210650937450935,44.51095072888693,225.04501442347203,0.019095460819907015
0.0194759718848517,220.672355574261,0.061836210734404144,44.48754688377102,224.97016416718927,0.019288742225794596
0.0196773270226282,220.581365721681,0.06247551329684453,44.469203329490895,224.9218173900845,0.01948623119196399
0.0198741993801645,220.498219821909,0.06310058303202228,44.45244111609685,224.88044540562097,0.019679285748908648
0.0200761161609181,220.429193037193,0.06374166881091496,44.43852531629811,224.85455512186513,0.019877248199145586
0.0202681588505971,220.363303833601,0.06435140435064579,44.42524205285397,224.82966228054283,0.02006549357772994
0.0204640844125104,220.316240116749,0.06497346800972052,44.4157540075366,224.82481025194502,0.020257508540165163
0.0206612976478539,220.278589143268,0.06559962003193613,44.408163571282834,224.8298306390064,0.02045074824772122
0.0208695805678861,220.223681473608,0.06626091830303837,44.39709418507937,224.81965733707793,0.020654794067431516
0.0210729251435912,220.159361060577,0.06690653733090206,44.384127189812325,224.79876279586742,0.020853961845964622
0.0212802065931621,220.09817822867,0.06756465593328966,44.37179273089987,224.7819129321547,0.021056944814053267
0.0214876037294295,220.041701768448,0.06822314184093865,44.360407076519124,224.76987065999774,0.021259999841582163
0.0216925099951707,219.994638051596,0.06887371923466698,44.350919031201755,224.76687393641424,0.02146057566458647
0.0219094973022759,219.936592800812,0.06956265393472598,44.3392171086437,224.75529298745317,0.021672933361580087
0.0221200829252747,219.87070359722,0.07023126328774716,44.32593384519955,224.73426179362903,0.02187898284910308
0.0223212696223658,219.811089555874,0.0708700310510114,44.3139156544642,224.71755215183666,0.022075796220628493
0.0225269954097696,219.716962122171,0.07152321042601847,44.29493956382968,224.66652511934566,0.022277009965057215
0.0227303800853183,219.627541060153,0.0721689567708856,44.276912277726844,224.61975854565412,0.022475894153087463
0.0229358684204983,219.534982417011,0.0728213822350821,44.25825245526942,224.57020788742398,0.02267679528837414
0.0231451988628266,219.42516707769,0.07348600638947446,44.2361136828623,224.50380620521207,0.022881411270023955
0.0233409989657294,219.337314806234,0.07410767171619084,44.218402664936775,224.45686684427216,0.023072763748929477
0.0235413284885217,219.251031325339,0.07474371795105639,44.20100791518834,224.41249187521598,0.02326850487263261
0.0237480978874986,219.175729378376,0.07540021079280805,44.18582704268061,224.38073605421758,0.02347049819806677
0.0239464994148819,219.080033154111,0.07603013564225003,44.166534683868775,224.32623303984823,0.02366427858725711
0.0241496610312768,218.998456044902,0.07667517377430383,44.15008873865225,224.28719452475937,0.02386266928881185
0.0243521462562013,218.923154097939,0.07731806436343913,44.1349078661445,224.2544027654009,0.02406036032805196
0.0245543764090528,218.855696103785,0.07796014509874263,44.12130833452306,224.2295612451826,0.02425776333426146
0.024750680370496,218.783531737946,0.0785834101763248,44.10675999836992,224.19857300232016,0.02444934434011924
0.0249545580884927,218.689404304242,0.07923072193096432,44.087783907735194,224.14670174729008,0.024648278035407374
0.0251620866607105,218.617239938403,0.07988962514775584,44.073235571582046,224.11810587525844,0.024850733416137263
0.0253760135099237,218.576451383798,0.08056884289400774,44.06501259897368,224.12305036706445,0.02505938776883767
0.0255857622350344,218.527818876385,0.08123479509623421,44.05520828547921,224.11901969189685,0.025263924711770955
0.0257939637619469,218.474479997286,0.0818958349441814,44.04445516745286,224.1098028172462,0.025466911535701055
0.0260034656402558,218.44153539549,0.08256100340781215,44.037813535730784,224.12177235555137,0.025671124559886536
0.0262098745954245,218.389765306953,0.08321635184047278,44.02737668588173,224.11373366857242,0.025872281965715366
0.026424950705164,218.35054554291,0.0838992184888957,44.019469981450655,224.12044794532704,0.026081842972744546
0.0266323425521523,218.279949967632,0.08455768760308355,44.00523791347461,224.09325636743662,0.026283875179419738
0.0268383818320401,218.22347350741,0.08521186231672732,43.993852259093856,224.08023841411597,0.026484549363018008
0.0270436113235443,218.156015513256,0.08586346595225315,43.98025272747241,224.05574200468962,0.026684394819447548
0.0272536700653283,218.080713566294,0.08653040245741735,43.965071854964876,224.02421338144114,0.026888901484007816
0.0274632293300369,217.97717338922,0.08719575312286715,43.94419815526676,223.96353049072138,0.027092880207789116
0.0276883310924632,217.873633212146,0.08791045121857066,43.92332445556864,223.90619050484176,0.0273119411935201
0.0279030964802065,217.771661825634,0.08859233132465563,43.90276702404782,223.84816551620958,0.027520898465518837
0.0281122372824169,217.66812164856,0.08925635337167366,43.8818933243497,223.7872595331623,0.02772434130905937
0.02832734671466,217.580269377104,0.0899393258190455,43.86418230642416,223.74374110601838,0.027933547000976246
0.0285411278765035,217.506536220703,0.09061808100789862,43.84931770209372,223.71441808495342,0.0281414175238163
0.0287533861899844,217.43123427374,0.09129200115320046,43.83413682958599,223.68311852257781,0.028347764561425924
0.0289607690415591,217.377895394641,0.09195044170695015,43.82338371155963,223.6733264179054,0.028549330801080377
0.02916222767394,217.322987724981,0.0925900728647595,43.812314325356176,223.66061017179777,0.028745100085370748
0.0293582111081272,217.252392149704,0.09321232026830385,43.79808225738033,223.63053374218066,0.02893551202502119
0.0295619194201271,217.178658993303,0.09385909415890353,43.78321765304989,223.59887701023428,0.02913339081560092
0.0297618455569011,217.073550025667,0.09449385964316098,43.76202768517447,223.53405949601915,0.02932755760064197
0.0299580839099051,216.9574595241,0.09511691641394869,43.73862384005855,223.45708930140285,0.029518106180369166
0.0301584834244339,216.838231441409,0.09575318487257763,43.714587458588056,223.3777436501183,0.029712657807532843
0.0303634453252381,216.720572149279,0.09640393890763096,43.69086734529465,223.30095539258798,0.029911599540324376
0.030563127122478,216.620169553329,0.09703792861386765,43.67062618195113,223.2407593326801,0.030105378203314315
0.0307611863446959,216.54800518749,0.09766676664440947,43.65607784579798,223.20927872763454,0.030297545172416132
0.03097111411255,216.507216632885,0.09833328730734625,43.647854873189615,223.21268634541264,0.030501187292717512
0.0311746203584078,216.471134449965,0.09897941963794477,43.640580705112946,223.21953988499652,0.030698560585125205
0.0313823092389145,216.425639523675,0.09963883183355354,43.63140892797288,223.2175758704368,0.030899950305067828
0.0315924194418447,216.378575806824,0.10030593172785693,43.621920882655715,223.21449853194216,0.031103646647767103
0.0318139235892379,216.344062414466,0.10100920739583033,43.61496298275635,223.22681588510514,0.031318344202606124
0.0320300070371948,216.290723535367,0.10169527234309349,43.60420986472998,223.21851693228476,0.03152774322308435
0.0322542705879471,216.213852797843,0.10240730911673204,43.58871272404515,223.1876729108472,0.03174502293989993
0.0324679962593378,216.119725364139,0.10308588812339751,43.56973663341042,223.13669979883093,0.03195204901365876
0.0326814920136079,216.03814825493,0.10376373714320507,43.55329068819389,223.09859727175814,0.03215880959563408
0.0329096824880283,215.962846307967,0.10448824189948985,43.53810981568615,223.07011500917307,0.03237975406728532
0.0331266730937851,215.900094685498,0.10517718707276769,43.5254590885964,223.05214654306175,0.032589809041360066
0.0333276406782751,215.826361529097,0.10581525915352344,43.51059448426596,223.01934495503826,0.03278431378679216
0.0335429276969893,215.744784419887,0.10649879543794102,43.49414853904922,222.98149612468578,0.03299263551025819
0.0337500209905736,215.685170378542,0.10715631664507118,43.482130348314065,222.96454940617326,0.033192987661034595
0.033967488080075,215.613006012703,0.10784677465423811,43.46758201216093,222.93683822434866,0.03340333272930361
0.0341761809650421,215.52829132237,0.10850937456400866,43.45050353058979,222.8942252096896,0.03360514935239309
0.0343917870500595,215.443576632036,0.1091939238839389,43.43342504901846,222.85306624086815,0.03381360862386195
0.034604244760116,215.371412266197,0.10986847711336828,43.41887671286532,222.82417733058836,0.034018981381988986
0.0348281439809151,215.302385481481,0.11057935713940543,43.404960913066574,222.80096796246448,0.03423536846754038
0.0350505885456737,215.230221115642,0.11128561863251399,43.39041257691343,222.77416703856076,0.03445030334475761
0.0352709353908655,215.139231263062,0.11198521986599796,43.3720690226333,222.72739318898192,0.034663165785181665
0.0354816596248705,215.060791734976,0.11265426930896384,43.35625561377116,222.6915055459716,0.0348666900837769
0.0357081696227335,214.988627369137,0.11337343855217887,43.34170727761801,222.6654777421928,0.03508541460199086
0.0358946401330363,214.899206307118,0.11396548242239025,43.32367999151499,222.6129359823871,0.03526543995234104
0.0361058235288033,214.786253386674,0.11463598970395047,43.30090868275348,222.54128794786604,0.03546928488404055
0.0363244535579386,214.667025303983,0.11533014004645505,43.27687230128298,222.46468769505836,0.035680273916929746
0.0365345819172495,214.57289787028,0.11599729758726716,43.257896210648454,222.41222898474336,0.03588301646375479
0.0367490792233319,214.467788902644,0.11667832653407877,43.23670624277303,222.34928266788006,0.03608993200634826
0.0369594926514331,214.373661468941,0.11734638916830008,43.217730152138515,222.29680323466314,0.03629286643182854
0.0371755637066391,214.287377988046,0.11803241476857915,43.200335402390074,222.25363205996925,0.036501214538500956
0.0374105801328853,214.158737161985,0.11877859192191081,43.174401411856174,222.17053975974093,0.03672778158460733
0.0376252918378068,214.050490613226,0.1194603015850366,43.15257890762637,222.10420279057436,0.036934729048589215
0.037841741691304,213.965775922893,0.12014752986989019,43.13550042605522,222.06261354614654,0.037143308467857364
0.0380560524393554,213.885767604245,0.12082796649495339,43.119370749015786,222.0254155922239,0.037349783708997615
0.0382696998510457,213.827722353461,0.1215062970270701,43.10766882645774,222.0108451077607,0.037555577440745745
0.0384915981406545,213.758695568746,0.12221082409657802,43.0937530266592,221.98660937764865,0.037769273921576495
0.0387058323416283,213.68966878403,0.12289101768466984,43.07983722686045,221.96070527712274,0.037975546275460306
0.038923612654255,213.66299934448,0.12358247017725962,43.07446066784717,221.97953516951085,0.038185189351080756
0.0391542454383489,213.593972559765,0.12431472926675775,43.06054486804863,221.957083385522,0.03840715676596153
0.03936631843175,213.495138754376,0.12498806102080624,43.040619972882205,221.89965637021143,0.038611218248752195
0.0395828483395997,213.410424064043,0.12567554347822904,43.02354149131107,221.8578165138597,0.03881952532243485
0.0398066081637705,213.255113798432,0.12638598091997133,42.99223094176389,221.74407655232648,0.03903474217306823
0.040026999957411,213.10764748563,0.12708572486477993,42.96250173310301,221.63770728246126,0.039246674313798025
0.0402480692404674,212.975869078446,0.127787619838484,42.935935206214715,221.54773660366402,0.03945921282580726
0.0404686825132403,212.877035273057,0.12848806697953796,42.916010311048296,221.4918884278822,0.03967126790097658
0.0406841614902046,212.806439697779,0.12917221273139962,42.90177824307225,221.46429125659895,0.039878344453143574
0.040894073011679,212.738981703625,0.12983868181208083,42.8881787114508,221.43874515384326,0.04008002942342861
0.0411218290238047,212.660542175539,0.1305618071505799,42.87236530258866,221.40553263099113,0.04029881354780691
0.0413435042481767,212.647991851045,0.13126562598796102,42.86983515717068,221.43960500550492,0.040511710465385826
0.0415702211795211,212.619753620934,0.13198545224497948,42.8641423299803,221.4584038060915,0.04072940256609263
0.0417930892292547,212.569552322959,0.13269305830288367,42.85402174830853,221.45349059061513,0.04094335281612368
0.0420198817840061,212.486406423188,0.13341312466421934,42.8372595349147,221.41506010179862,0.04116102355606213
0.0422365146203133,212.400122942293,0.1341009339194947,42.81986478516627,221.37116384030148,0.04136889897624648
0.0424732190416097,212.316977042522,0.1348524704571108,42.80310257177244,221.33476251470148,0.04159598519212743
0.0426929400569553,212.221280818257,0.13555008468083307,42.78381021296061,221.2816312390411,0.04180673196182738
0.042923171878014,212.125584593991,0.13628107071269444,42.76451785414858,221.23068752124308,0.042027512594156075
0.0431503960457776,212.003218930177,0.13700250744534387,42.73984893632369,221.15124178999383,0.042245361256979815
0.0433751136790419,211.869871732431,0.13771598593095802,42.712966141258086,221.05975150398922,0.042460760141954726
0.043596637268769,211.763193974233,0.13841932332834156,42.69145990520538,220.99535712880362,0.04267305203374341
0.0438359365533675,211.651809844351,0.1391790985569418,42.66900486462116,220.92976515209338,0.04290232821602378
0.0440633596603401,211.546700876716,0.1399011669215798,42.64781489674594,220.8681592424051,0.04312017694875182
0.044292600026951,211.440023118518,0.14062900508556941,42.62630866069323,220.8052514921958,0.04333971841769369
0.0445164916587252,211.331776569759,0.1413398610164525,42.604486156463416,220.73952583865028,0.04355409093600844
0.0447456681916577,211.261180994482,0.1420674965085132,42.590254088487576,220.71420370103883,0.043773476074221926
0.0449811447695554,211.199998162575,0.1428151346433384,42.57791962957513,220.70001585525563,0.04399884197127023
0.0452164493658655,211.129402587297,0.14356222673662297,42.563687561599075,220.67592452903097,0.044223992548387325
0.0454432900082467,211.043119106402,0.14428244577618327,42.54629281185065,220.63361277219917,0.04444099643381077
0.0456740531909987,210.942716510452,0.14501511888142088,42.52605164850712,220.57732536460412,0.04466170445331938
0.0459107251130494,210.790543825965,0.14576655223393184,42.49537363531454,220.46809053998908,0.04488801316001479
0.0461406774217203,210.647783884848,0.14649665081396196,42.46659323118535,220.36721533067902,0.04510784744259342
0.0463673346156361,210.511299105978,0.14721628740464462,42.43907789976516,220.27214695199714,0.04532448431423106
0.0465994376129786,210.396777394972,0.14795321442120704,42.41599032282635,220.20114889716072,0.04554627760915927
0.0468381226449002,210.280686893405,0.14871103939755811,42.392586477710445,220.12983949597216,0.045774309280594894
0.0470752194286498,210.186559459701,0.1494638216859631,42.37361038707572,220.08113786721938,0.0460007721241128
0.0473197797458106,210.090863235436,0.15024030069294864,42.3543180282639,220.03231661034405,0.046234310036845326
0.0475615692957532,210.035955565776,0.1510079825140164,42.343248642060445,220.02559522101737,0.0464651484574812
0.0478243065792143,209.948103294319,0.15184217338900538,42.32553762413471,219.98872575199107,0.04671592545074349
0.0480698638722285,209.852407070054,0.1526218177943255,42.306245265322886,219.93998371117098,0.046950247677122796
0.048310091699619,209.737885359048,0.15338454114629033,42.28315768838407,219.8703418336278,0.047179431158679695
0.0485532544322096,209.620226066919,0.15415658282226546,42.25943757509087,219.7979702372834,0.04741136113554641
0.0487927931032896,209.491585240858,0.15491711810294448,42.23350358455698,219.71326481639537,0.0476397818793746
0.0490275284340033,209.308036745136,0.15566240277796048,42.19650020781942,219.56989246812358,0.04786357161892805
0.0492720476509037,209.1291946211,0.15643875129161924,42.16044563561376,219.43341826366594,0.04809663578268616
0.0495001835705181,208.964471612119,0.15716308283639496,42.12723747700319,219.3082513166352,0.04831403519089169
0.0497426569700424,208.795042231453,0.1579329358798846,42.093080513860926,219.1810623942177,0.04854504553035313
0.049978574299144,208.627181641348,0.15868197339978218,42.05923981889576,219.05407073983113,0.04876975853185182
0.0502183878892854,208.465596213491,0.15944338154848114,42.026664196639786,218.93440238571125,0.04899813100881583
0.0504648888592815,208.313423529004,0.16022602212821876,41.995986183447215,218.82593729529165,0.04923281747855252
0.0507069608546934,208.224002466985,0.16099460071365154,41.97795889734418,218.78240880908604,0.04946323365942405
0.0509501018235041,208.143994148337,0.16176657328962551,41.961829220304736,218.7489518441456,0.04969461391095331
0.0511885873439047,208.057710667443,0.1625237648168974,41.94443447055651,218.70789096251625,0.04992151190075067
0.0514392695352716,207.947895328122,0.16331968077448733,41.92229569814939,218.64458316519773,0.050159958463450414
0.0517037775337725,207.823960873746,0.16415949366972768,41.897310512147186,218.5692447129496,0.0504114943732537
0.0519594641088882,207.690613675999,0.16497129854572004,41.870427717081405,218.48210666305005,0.05065458135724757
0.0522124268373995,207.532165829265,0.16577445520874343,41.838484631179824,218.3679238540326,0.05089502058259639
0.0524675123056688,207.37214919197,0.16658435157049842,41.806225277101156,218.25244998155267,0.05113741892998797
0.0527214409753489,207.212132554674,0.16739057509673275,41.77396592302228,218.13665477053144,0.051378659670412566
0.0529878869759346,207.041134383446,0.16823654114859235,41.739492691702715,218.01180661152532,0.05163172973898365
0.0532461111613931,206.884255327274,0.16905640293742308,41.707865873978434,217.90003738397206,0.051876929642679676
0.0534995923704423,206.73522022391,0.1698612057761543,41.67782039714026,217.7954702345028,0.05211756733316823
0.0537658461224002,206.583047539423,0.17070656143862062,41.647142383947674,217.6901598849241,0.05237026805943771
0.0540359056000945,206.437150017182,0.17156400028030003,41.617729443463894,217.592168367863,0.052626515573181695
0.0543086631153253,206.267720636516,0.1724300053911578,41.58357248032163,217.4698447881306,0.052885256502724055
0.0545753563169492,206.081034559671,0.1732767563063137,41.545936567229674,217.32798045093054,0.05313818004009076
0.0548386254328457,205.883366948894,0.1741126357492851,41.506086776897035,217.17372779185752,0.053387793553171914
0.0550994719066889,205.619810134524,0.17494082330373725,41.45295372312004,216.94935308648988,0.05363504865084609
0.0553740027610048,205.343702995661,0.17581245876619023,41.39729052392526,216.71440577229768,0.053895209092718124
0.0556440286873501,205.080146181292,0.17666979108233655,41.34415747014847,216.49163171860977,0.05415103440903028
0.0559182528091873,204.811882995237,0.17754045266916968,41.290075611839775,216.26460564689035,0.05441077017508546
0.0562043144470957,204.540482228059,0.17844869836952884,41.235361217176695,216.0365398083654,0.05468164615936042
0.0564957174217076,204.251824764702,0.17937390281392163,41.17716787256392,215.79117813947676,0.05495750451318655
0.0567917373673869,203.950616976851,0.1803137661414534,41.11644438253317,215.53332685211686,0.055237655655847866
0.0570953561197969,203.690197743605,0.18127775568035515,41.06394386511077,215.31996212188798,0.055524916745083155
0.0573898164003864,203.404677861371,0.18221266707122682,41.00638305685239,215.0780349788148,0.055803433980691826
0.0576899832688223,203.083075796218,0.18316569687851078,40.94154808051755,214.79893504108279,0.056087269011878875
0.0579880533887647,202.692446946349,0.1841120695093279,40.86279730438396,214.44618738137325,0.05636904167931693
0.0582923739407164,202.295542934233,0.18507828726177455,40.782781455541375,214.08783036949555,0.056656641139312285
0.0585938261741087,201.89236375987,0.18603539810279512,40.701500533989794,213.72200982789576,0.05694144835796555
0.0588865398523241,201.506441281686,0.18696476403112902,40.623698562387894,213.37245836672002,0.05721792192983549
0.0591809148706003,201.031097741484,0.18789940471415595,40.52786930468317,212.9283020232661,0.057495887600395444
0.0594725072506113,200.525947180609,0.18882521052069087,40.42603095161078,212.45172802824345,0.05777114959351564
0.0597607254625738,199.964320159512,0.1897403033436718,40.31280694415762,211.9143329988748,0.05804315194728259
0.0600503233702524,199.426224996841,0.19065977670055137,40.20432695936315,211.40183429641,0.05831638187467594
0.0603152789358997,198.883423462484,0.19150101062148153,40.09489817003677,210.87913262435035,0.05856629685795824
0.0605900398442769,198.302970954647,0.19237337650557915,39.97787894445684,210.31815586602755,0.05882539461916564
0.060876400829795,197.642510128161,0.1932825726345991,39.84473004183726,209.67427479572976,0.059095359754382536
0.061169677657789,196.933416794262,0.19421372656348007,39.70177682572322,208.97977041961403,0.05937176923750765
0.0614827207310613,196.243148947104,0.19520763832111962,39.562618827736166,208.30871166920286,0.05966672386670592
0.0617856730012986,195.526211660396,0.19616951177912303,39.41808427073584,207.60693023722794,0.05995208795274185
0.0620914609913212,194.76534823796,0.1971403886474448,39.264694204772745,206.8586132605384,0.060240040572261455
0.0624168350709972,193.889963104519,0.19817345135041609,39.08821656187103,205.9919609535355,0.06054634587859804
0.0627335362042567,192.948688767485,0.199178977448515,38.89845565552498,205.05304231984388,0.06084439644469881
0.0630683360784348,191.830141096976,0.2002419670490305,38.67295644515036,203.92854890565366,0.0611593833504039
0.0634109632790919,190.769638677251,0.20132980841111678,38.4591591573338,202.86652523017978,0.06148163168240086
0.0637320142658794,189.564807525847,0.2023491452941671,38.21626519721075,201.64615454339295,0.06178349290434475
0.0640601379171265,188.212510061642,0.20339093788687662,37.94364202842703,200.26942941391937,0.06209190992102699
0.0643879346635844,186.720590237443,0.20443169255688046,37.642870991868506,198.7431434019974,0.062399924716663537
0.0647066923556307,185.165918790775,0.20544374822912748,37.32944922822024,197.1473929327174,0.06269935499128138
0.0650338808288324,183.495156842539,0.20648257163154285,36.99262361945586,195.42855900530458,0.06300661164018535
0.0653468738875617,181.99382427497,0.2074763245930084,36.68995497383395,193.88655175818153,0.06330044931243095
0.0656602460472143,180.410914598191,0.20847128119990538,36.370840382995304,192.25673964031117,0.06359455641228981
0.0659839387777583,178.804473062986,0.20949900561938256,36.04698176949798,190.6026964667634,0.06389825881753779
0.0663067255923076,177.243526454072,0.21052385375557664,35.73229493314091,188.99596432567506,0.06420101943306601
0.0666347898813384,175.684148635719,0.21156545787324943,35.41792436496095,187.39082496554195,0.06450863620477579
0.0669710418376114,174.121633236242,0.2126330578344162,35.10292126042639,185.7827404205396,0.06482383215527242
0.0673040699462916,172.64540131766,0.2136904220794758,34.80531290564026,184.2651394838494,0.06513590824100692
0.067653678812455,171.07974833706,0.21480043022954462,34.4896772647513,182.65392268237113,0.06546341717601198
0.0679886301276291,169.448206152868,0.21586390065522237,34.16075836041819,180.9687575667856,0.06577709453342179
0.0683373529441954,167.849608570472,0.2169710955978204,33.83848108780715,179.32000651289735,0.06610356420371251
0.0687682129876863,166.150608392125,0.218339076235904,33.4959626518524,177.57648881806833,0.06650678251561724
0.0692473804647823,164.482984025013,0.21986043297568378,33.15976957944262,175.87299979977576,0.06695501824091875
0.0697755062261631,162.57690349252,0.22153723226806785,32.77550374409203,173.92078923439263,0.06744881919592344
0.0703278511910265,160.093508033311,0.22329092753150911,32.2748512195155,171.3525404429271,0.06796500452427531
0.0708819837561614,157.065742249185,0.22505029842581245,31.6644536374357,168.19887363994118,0.06848259282268641
0.0714609166635033,153.835602482597,0.22688841040662294,31.01325746049156,164.82883565148572,0.06902305991721272
0.071796344679176,152.286421802895,0.22795339435638381,30.700942635463633,163.22003023261405,0.06933606762231773
0.0720939065457751,150.583185890032,0.22889815328283594,30.357570275430454,161.43931602095304,0.06961365820172331
0.0723711756969555,148.431903392741,0.2297784828378337,29.923871723976585,159.17409475221058,0.06987224870526802