File: example/data/02 processed data/test_ID_141.csv
Strain,Stress_MPa,Displacement(mm),Force(kN),True Stress (MPa),True Strain
7.49886555662227e-05,0.69732964231722,0.00023808898142275704,0.14058165589115157,0.6973819341295839,7.498584405753196e-05
7.87552672186777e-05,2.09035190359843,0.0002500479734193017,0.42141494376544353,2.090516529821179,7.875216618554527e-05
9.23382265050135e-05,4.28260164556759,0.00029317386915341784,0.8633724917464263,4.282997093408369,9.233396359338729e-05
0.0001083257356317,7.57172672982864,0.0003439342106306475,1.5264601087334537,7.572546942696651,0.00010831986882297827
0.0001110584917922,11.105325788101,0.00035261071144023496,2.2388336788811616,11.106559128833888,0.00011105232525453123
0.0001428441149306,14.3658540381223,0.00045353006490465495,2.896156174085456,14.3679061158276,0.00014283391368156913
0.0001697203549829,17.7305924684487,0.0005388621270707075,3.5744874416392585,17.733601710896504,0.00016970595411280382
0.0002050944376711,21.2390909721733,0.0006511748396057425,4.281800739990138,21.243446991592883,0.00020507340868208216
0.0002442005746436,24.7838060102016,0.0007753368244934299,4.996415291656643,24.78985822987115,0.00024417076253668927
0.0002998408976296,28.3303694157097,0.0009519948499739799,5.711402474207076,28.338864019105486,0.00029979595433129996
0.0003624215580917,31.8710584851208,0.0011506884469411475,6.425205390600353,31.88260924379501,0.0003623558992624941
0.0004194061859897,35.2878509838225,0.0013316146405172972,7.114030758338616,35.302650926815396,0.00041931825979892246
0.0004675131479339,38.6691094144902,0.0014843542446901325,7.795692457961224,38.68718773156037,0.0004674038977114563
0.0005189254398673,41.9004874943767,0.0016475882715786773,8.447138278866342,41.922230723280364,0.0005187908446223823
0.0005849663786755,45.0137024177898,0.0018572682522947125,9.074762407426425,45.04003392028391,0.0005847953525364647
0.0006466031481865,48.0541955651723,0.0020529649954921375,9.687725825938736,48.085267559308306,0.0006463941904411141
0.0007151865241534,50.9526125977987,0.0022707172141870446,10.272046699716219,50.98905321969906,0.0007149309001432823
0.0007836532730926,53.8248531867462,0.0024880991420690047,10.851090402448035,53.86703320911973,0.0007833463771893493
0.0008459995518413,56.5546671482067,0.0026860485770961273,11.40142089707847,56.60251237126861,0.000845641895924039
0.0009298405727416,59.2682500567386,0.00295224381845458,11.948479211438503,59.32336008031675,0.0009294085387906224
0.0010046639758979,61.8617551402055,0.0031898081234758326,12.47132983626543,61.92390541708068,0.0010041596388101939
0.0010917264340154,64.368588495342,0.0034662314279988943,12.976707440660945,64.43886138492262,0.0010911309340879084
0.0011576613555548,66.8017577954963,0.0036755748038864895,13.467234371572054,66.87909160897928,0.001156991782357289
0.001250885437806,69.0163577691585,0.00397156126503405,13.913697726262356,69.10268932606235,0.0012501037324313526
0.0013697831477036,71.1539003796608,0.00434906149395893,14.344626316539616,71.25136579329423,0.0013688458505992165
0.0014693683452941,73.0639381489276,0.004665244496308767,14.729689930823806,73.17129598682617,0.0014682898799397773
0.0015859715416112,74.8997252007691,0.00503545964461556,15.09978460047505,75.018514033412,0.0015847152169004577
0.0017113704703866,76.5877388980425,0.005433601243477454,15.44008816184537,76.7188088927863,0.0017099077445492385
0.0018931684102435,77.9560066523678,0.006010809702523112,15.71593094111735,78.1035905015508,0.0018913786254819783
0.0021155609442442,79.0482714381755,0.006716905997975335,15.936131521936181,79.21550287394012,0.002113326296324085
0.0023744236832835,79.8220156516544,0.007538795194425112,16.09211835537353,80.0115469360651,0.0023716091936829896
0.0026606068313841,80.2958120357226,0.008447426689644516,16.18763570640168,80.50944762175638,0.002657073682521028
0.0029649977238851,80.6100263956423,0.009413867773335192,16.250981321361486,80.84903494042769,0.0029606107874987765
0.0032758543964931,80.7632310496074,0.010400837708865593,16.28186737960085,81.02779963511624,0.0032705004747385974
0.0036002688841123,80.9035976548347,0.011430853707056552,16.310165287214677,81.19487236008415,0.0035938034296960704
0.0039390293754406,80.9415340502164,0.012506418267023903,16.31781326452363,81.26036513053344,0.003931291711830672
0.0043025139778277,81.0086948684982,0.013660481879602946,16.33135288548924,81.35723591049549,0.004293284628030669
0.0046669734890014,81.0315681280733,0.014817640827579444,16.33596413461958,81.40974030829923,0.004656116933295503
0.005030367270005,81.063616203967,0.015971416082265873,16.34242502671975,81.47139596570769,0.005017757243598873
0.0054083831401522,81.0843557964908,0.017171616469983234,16.346606128572546,81.52289105931064,0.005393810355910656
0.0057854597586452,81.0673264263391,0.01836883473369851,16.34317300754996,81.53633818111965,0.005768788256964719
0.0061671749149291,81.0599395161341,0.01958078035489989,16.341683806452632,81.55985034172366,0.006148235719380355
0.0065423332412211,81.0440131379329,0.02077190804087699,16.33847304860727,81.57423007908716,0.006521025065400268
0.0069344291289252,81.0539815516801,0.022016812484337508,16.340482680818706,81.61604464236744,0.006910496550731911
0.0073053898457812,80.9470554896866,0.02319461276035531,16.318926386720822,81.53840528690684,0.007278834737233227
0.0076800857272454,80.8988947397072,0.024384272184004144,16.30921717952497,81.52020518654756,0.007650744004397205
0.0080601283422238,80.8412641782601,0.025590907486560562,16.29759885833724,81.4928551428845,0.008027819003277205
0.0084467820602429,80.8350458091501,0.026818533041271207,16.29634523512466,81.51784182392974,0.008411307619917405
0.0088891247007564,80.8052513630818,0.028222970924901572,16.29033867479729,81.5235393189242,0.008849849011185053
0.009343481101999,80.7750800534307,0.029665552498846823,16.28425613877163,81.52980048742239,0.009300100788519528
0.0097957740322892,80.7131718383305,0.031101582552518207,16.271775442607428,81.50381983108811,0.009748106478770948
0.0102432952854826,80.6475959270056,0.032522462531407254,16.258555338884328,81.47369306615019,0.010191188265962325
0.0106398451732202,80.567291089315,0.033781508424974134,16.242365883605906,81.42451459253108,0.010583640342866973
0.0110869327559692,80.4780639043076,0.0352010115002022,16.22437768310841,81.37031878714527,0.011025923241741308
0.0115372997234147,80.3682445443544,0.03663092662184167,16.202238100141848,81.29547706990729,0.011471252599173467
0.0119760742763958,80.2753911013172,0.03802403582755666,16.183518846025546,81.2367751477133,0.011904928566425225
0.0123972305941309,80.2162025757394,0.0393612071363656,16.171586439269063,81.21066133645635,0.012321014199245854
0.012815331499263,80.1440902931576,0.040688677510160025,16.157048603100574,81.17116337797128,0.012733910029439405
0.0132588975671904,80.1025309836006,0.042096999775829515,16.148670246293882,81.16460223678486,0.013171767703803542
0.0136776709075661,80.0063205668027,0.04342660513152236,16.129274226267423,81.10062069004067,0.01358497584543707
0.014108501649062,79.9097234308515,0.044794492735771844,16.109800243659663,81.03712989565176,0.01400990304319526
0.0145242780384252,79.8040454264891,0.04611458277200001,16.088495557980202,80.96314157085453,0.014419811035758456
0.0149446773624901,79.7113936706657,0.047449350625906064,16.069816964006204,80.90265473118824,0.014834105946709766
0.0153538784940584,79.5929663177015,0.048748564218635417,16.045942009648623,80.81502705152516,0.015237200492512953
0.0157772196186938,79.4688513885044,0.05009267228935281,16.020920439922488,80.72264890970618,0.01565405308381938
0.016199563537872,79.3502042691138,0.0514336142327436,15.997001180653342,80.63564294491444,0.01606975067324163
0.0166306982426916,79.2743875079098,0.052802466920545826,15.981716521594615,80.59277592492803,0.016493922547686442
0.017066883062607,79.2199833339119,0.054187353723777226,15.970748640116641,80.57202152569346,0.016922879960640482
0.0175051433942119,79.1327704771545,0.05557883027662278,15.953166528194346,80.51800097153834,0.0173536932547233
0.0179618725579386,79.018322918819,0.057028945371455045,15.93009390043391,80.43763996482886,0.01780246414397139
0.0183864064762329,78.8601822398814,0.058376840562039456,15.89821273956009,80.31013760533367,0.018219420249973157
0.0188161836256158,78.6885573323554,0.05974138301133016,15.86361315820285,80.16917567635579,0.0186413489848441
0.0192278615169347,78.5572938345705,0.061048460316267664,15.837150437049413,80.06778260156678,0.019045342115315823
0.0196484420965691,78.431015559615,0.06238380365660688,15.811692736818387,79.97206282741321,0.019457903274474237
0.0200818319103492,78.3446232751112,0.06375981631535871,15.79427605226242,79.91792683080162,0.019882851441224474
0.0205197256397745,78.2462915587232,0.06515012890628404,15.774452378238598,79.851883993838,0.020312032468286327
0.0209765358513914,78.1325642890099,0.0666005013281677,15.751524960664398,79.77151482497946,0.02075955738210357
0.0214301869916557,78.0500129731824,0.06804084369850684,15.734882615393575,79.72263934589887,0.02120378931950465
0.0218948556715559,77.958670200336,0.06951616675718998,15.716467912387738,79.66556403271879,0.02165860554130804
0.022342777054303,77.8456127254445,0.07093831714741203,15.69367552544961,79.58489989522471,0.022096833839960566
0.022796380297004,77.707743019445,0.0723785074429877,15.665880992720114,79.47919828133813,0.022540425415143645
0.023244404794062,77.5360682900894,0.07380098522114685,15.631271367282025,79.33834804756428,0.02297836830219017
0.0237160053392174,77.4334432087328,0.07529831695201523,15.610582150880532,79.26985516130509,0.023439149615951612
0.0241818800421228,77.34504483562,0.0767774691337399,15.592761038860992,79.21539343168757,0.023894128073879143
0.0246474847687397,77.2175884839849,0.07825576414074854,15.567065838371354,79.12080782002272,0.024348636138463834
0.0251047245000122,77.0937309515748,0.07970750028753873,15.54209615983748,79.02914782779214,0.024794777615261974
0.0255521600814015,76.9299441185999,0.08112810825844977,15.50907673430974,78.89567036577164,0.025231160309855002
0.0260364257828362,76.7586762515202,0.08266565186050494,15.474549132306473,78.75719782893167,0.025703248830687468
0.0264947622267581,76.6503049084873,0.08412087006995696,15.45270146955104,78.68113651164619,0.026149854908312595
0.0269562165384371,76.5483750128464,0.08558598750953779,15.432152402589837,78.61182958535818,0.026599297650524288
0.0274277611794114,76.438085465376,0.08708314174463119,15.409918029819803,78.53461101853178,0.02705835949521318
0.0278805637122131,76.3500842589614,0.08852078978627659,15.39217698660662,78.4787676475762,0.027498977123861457
0.0283428795346986,76.210444902053,0.08998864252266804,15.364025692253886,78.37046836119767,0.027948651824141826
0.0288046241897674,76.0721120002316,0.0914546818025115,15.33613777924669,78.26334059772017,0.028397569232336904
0.0292942811852071,75.9368304534845,0.09300934276303255,15.308865019422477,78.16134531710227,0.028873403511631947
0.0297745401646995,75.8225872862451,0.0945341650229209,15.285833596907011,78.08016995679084,0.029339885236984484
0.0302653870125284,75.7219470464231,0.09609260376477767,15.265544524558896,78.01370107912528,0.029816426347321467
0.0307270748879546,75.6062838130459,0.09755846276925585,15.242226816710055,77.92944375776932,0.030264451162243137
0.0311828618103517,75.459449073589,0.09900558624786665,15.212624933235544,77.812490646336,0.03070655284836308
0.0316702339161957,75.3026083380221,0.10055299268392134,15.181005840945254,77.68745955858692,0.03117907521645777
0.0321543130682773,75.1788234904457,0.10208994399178041,15.156050815673852,77.59614691706224,0.03164818404808432
0.032654832850315,75.0897392752101,0.10367909429975013,15.138091437882359,77.54178216001581,0.03213299378735776
0.0331800985901892,74.9950925342941,0.10534681302385071,15.11901065491369,77.48343709836233,0.03264152013977778
0.0336322592465784,74.8655916797234,0.10678242310788642,15.092903282632237,77.38349066774433,0.03307906413054055
0.034136115650953,74.7071563256226,0.10838216719177578,15.060962715245516,77.25736845390789,0.03356640731700546
0.0346470684504826,74.5786117333944,0.11000444233028224,15.035048125452311,77.16254199906328,0.03406037189854867
0.0351688294654584,74.4479096511526,0.11166103355283041,15.008698585672365,77.06615548973384,0.03456453367115151
0.0356954976267913,74.3564278763616,0.11333320496506237,14.990255859874496,77.01061757115895,0.03507317942432594
0.0362161130890912,74.2299529859712,0.11498615905786455,14.964758521971794,76.91827335790906,0.0355757254504828
0.0367127441935338,74.1049916296469,0.1165629628144698,14.939566312536815,76.8255892308101,0.036054884310372945
0.0372040564466936,73.9784001203368,0.11812287921825217,14.9140454642599,76.73069669424989,0.03652868563374257
0.0376901505086946,73.8556908099069,0.11966622786510535,14.889307267277232,76.63932291245591,0.03699723392817087
0.0381863063447179,73.7333255484892,0.12124152264447934,14.864638430575424,76.54892890569863,0.03747525451926433
0.0386910852688579,73.5841770378269,0.12284419572862383,14.834570090825906,76.43122870603621,0.037961348629699396
0.0392009708067145,73.4372799490862,0.12446308231131854,14.80495563773578,76.31609261649486,0.03845212056041614
0.0397166073873618,73.3110227772113,0.12610022845487373,14.779502191885799,76.22268788601974,0.03894818312357863
0.0402420243625623,73.2345324133513,0.1277684273511353,14.764081734531624,76.18163825091024,0.03945340181240833
0.0407652130923197,73.1345762397295,0.12942955156811506,14.743930569929466,76.11592282455858,0.03995622441808122
0.0412838070447823,73.0699164324965,0.1310760873671838,14.730895152791295,76.08652076327405,0.04045438172194044
0.0417977427797862,72.9460090622575,0.13270783332582117,14.705915426951112,75.99498758585369,0.04094781967253339
0.0423136676142434,72.8376883250201,0.1343458946752228,14.68407796632405,75.91971805859485,0.041442922614173795
0.0428291721256689,72.7227409164594,0.13598262149899873,14.660904568758214,75.83739570462086,0.04193737748997735
0.0433846507746551,72.6130226561021,0.13774626620952993,14.638785367470184,75.76331328572921,0.0424699007203536
0.0439334086598857,72.4967148588039,0.1394885724951371,14.615337715534865,75.68174265919494,0.04299570261757098
0.0444800710929267,72.4016587117228,0.14122422572004226,14.596174396283319,75.62208963846605,0.043519221978872126
0.045014491821099,72.2625490597389,0.1429210115319893,14.568129890443362,75.51541098336028,0.04403075309200434
0.0455217563988631,72.1344279690618,0.14453157656639032,14.54230067856286,75.41811382704077,0.04451604923374928
0.0460517040513175,72.0195200787796,0.14621416036293305,14.519135247881968,75.33614170336548,0.04502279468048193
0.0465833951584859,71.9088073177456,0.14790227962819272,14.496815555257513,75.25856370440357,0.0455309493213081
0.0471190281486175,71.8069797856455,0.14960291437186055,14.476287124786131,75.19045488743254,0.046042610382454635
0.0476347340727453,71.6482868747646,0.15124028068096632,14.444294633952543,75.06123396681177,0.0465349889558671
0.0482263094883437,71.51289806869,0.15311853262549124,14.417000250647904,74.96170122335903,0.04709950675453151
0.0487785367399145,71.3853179464467,0.15487185414922852,14.391280098003657,74.86738930058793,0.04762618866976829
0.0493259814262029,71.3325099589143,0.1566099910281942,14.380634007717124,74.85105602023214,0.04814803559776628
0.0498312030307321,71.2446563620694,0.15821406962257442,14.362922722593192,74.79486329810243,0.04862939222796569
0.0503659976658001,71.1360798119759,0.1599120425889153,14.341033690094344,74.71891944174006,0.04913867263882389
0.0509157957994091,71.0371484417107,0.16165765166312387,14.321089125848879,74.65406138594115,0.0496619705114511
0.0514876197115093,70.9215363101073,0.16347319258404203,14.297781720117632,74.5731174009981,0.0502059421602621
0.0520669382588595,70.822258682926,0.16531252897187892,14.277767350477882,74.50975685312288,0.050756741814876494
0.0526479971698945,70.7226809888164,0.16715739101441504,14.257692487345388,74.44608849736296,0.05130889157731355
0.0532123872262963,70.6149054758274,0.16894932944349075,14.235964943926804,74.37249316995545,0.05184491008461537
0.0537573899154331,70.5096631964835,0.1706797129815001,14.214748100411075,74.30007865374273,0.05236224327771996
0.0543200288310416,70.4002819774437,0.17246609153855708,14.19269684665265,74.2244273241719,0.05289603669912362
0.0548829899065952,70.2904143795919,0.17425349295343975,14.170547538925726,74.14816248251744,0.05342985073591444
0.0554560041497916,70.1476741817651,0.17607281317558832,14.141771115043843,74.0377838922873,0.05397290496454064
0.0560337640982876,70.030127046456,0.17790720101206312,14.118073612565532,73.95417866515022,0.054520158350849585
0.0565928397585063,69.9191061388457,0.17968226623325748,14.095691797591295,73.8760269086194,0.05504942904378616
0.0571661010016321,69.7839343953152,0.1815023706801819,14.068441174095545,73.77320983724906,0.055591838347066894
0.0577519870173903,69.6752729689192,0.1833625587802142,14.046535030534113,73.69915842885335,0.056145889148433596
0.0583355316152555,69.5645491043689,0.1852153128784362,14.02421309944077,73.62263405794779,0.056697420791164826
0.0589315951389973,69.4555412610637,0.18710781456631642,14.002237118230441,73.54866709882063,0.05726047070768895
0.0594945760250311,69.3805328326464,0.18889527887947374,13.987115419061514,73.50829821791545,0.05779197934079665
0.0600659203706412,69.2076933540307,0.1907092971767858,13.952270980172589,73.36471715206966,0.058331095219225165
0.0606127127335171,69.0719698585361,0.19244536292891679,13.924909123480877,73.2586093255097,0.05884677200915215
0.0612086031209206,68.9240232315162,0.1943373149089229,13.895083083473667,73.1427664149912,0.05940845022269164
0.0617979209348916,68.836516819547,0.19620839896828082,13.877441790820676,73.0904704433947,0.05996362310834204
0.0623859021223001,68.7679970204663,0.1980752392383028,13.863628199326007,73.05815055173173,0.060517229812284794
0.0629866843124243,68.6907578252275,0.19998272269194714,13.848056777565862,73.01736090354629,0.061082572764348954
0.0635841790185856,68.5900796350588,0.20187976838400926,13.827760054427854,72.95132353747341,0.06164450534057914
0.0641792400604665,68.4801745988379,0.20376908719198114,13.805603199125722,72.87518016379939,0.062203835435324636
0.0647837259782952,68.3836548995133,0.20568832998108724,13.786144827741882,72.81380285991769,0.0627717043402476
0.065397091065825,68.2947376210055,0.20763576413399437,13.76821910439471,72.76101479652301,0.0633475851289331
0.0660040798401593,68.1952730579676,0.20956295349250575,13.748167048486268,72.69643930560716,0.06391715297850466
0.0666342236325607,68.0990058276448,0.21156366003338023,13.728759574853193,72.63673021111914,0.06450810533054092
0.0672546825523351,67.9817655909663,0.21353361710366395,13.705123943138808,72.553857655134,0.065089634139713
0.0678745146811056,67.8775551066744,0.21550158411251027,13.684115109505559,72.48471121727991,0.06567023801790996
0.0685013988636178,67.7741591468995,0.2174919413919865,13.66327048401494,72.41678385526758,0.06625710496068916
0.0691424169996702,67.6823212756211,0.21952717397395288,13.644755969165216,72.36204055676575,0.0668568476778897
0.0697678649730193,67.5827364298231,0.22151297128933628,13.624679664252337,72.29783965956615,0.06744167631371158
0.070394731825254,67.4713894244186,0.22350327354518146,13.602232107962791,72.22101978882783,0.06802748869179875
0.071004639756864,67.3661001871203,0.22543973122804317,13.581005797723451,72.14940586273158,0.06859712362883666
0.0716179026624678,67.2429751508006,0.22738684095333525,13.556183790401402,72.05877599988537,0.0691695650273649
0.0722574013389487,67.1281496089311,0.2294172492511621,13.533034961160508,71.97865525636463,0.06976614701536997
0.072879318903583,67.0101951473664,0.23139183751887601,13.509255341709068,71.89385252930265,0.07034598659034001
0.0735054897901718,66.8910041956667,0.23337993008379543,13.485226445846406,71.80786022162562,0.07092945224087639
0.0741244708738367,66.7879513089465,0.2353451950244315,13.464450983883614,71.73857286046973,0.07150588403978149
0.0747455144628647,66.6842915846619,0.2373170084195954,13.443553183467841,71.66864326574915,0.07208390282226453
0.0753776711524458,66.5854420828303,0.2393241059090154,13.423625123898589,71.60449763969011,0.07267192188277713
0.0760090953400016,66.48497052366,0.24132887770450506,13.403370057569855,71.53843298687006,0.07325891462208411
0.076636358784845,66.3723121513824,0.24332043914188284,13.380658129718693,71.45884447879548,0.07384169843480624
0.0772628808347545,66.237281649699,0.2453096466503455,13.353435980579318,71.35496484861775,0.07442345458760566
0.0778996289658934,66.132481975074,0.24733132196671154,13.332308366174919,71.28417778352589,0.07501435958597212
0.07854288525297,66.0164767725939,0.24937366067817973,13.30892171735493,71.2016013325491,0.07561094985157316
0.0791569971566966,65.9560701880783,0.2513234659725117,13.296743749916587,71.17695464842289,0.07618017815372506
0.0798260281275534,65.8738209870898,0.25344763930498204,13.280162310997305,71.13226647407464,0.07679994309345521
0.0804531100061333,65.7935596355049,0.2554386242694732,13.26398162251779,71.08685612655526,0.07738049945316207
0.0810964746253309,65.6990400090514,0.2574813069354256,13.244926465824763,71.02700054005403,0.07797578039676892
0.081767256175695,65.6062094130189,0.2596110383578316,13.226211817664613,70.97064914480951,0.07859605208778472
0.0824267370349702,65.50511848883,0.2617048900860304,13.205831887348129,70.90449166495337,0.07920549919073064
0.0831185323897024,65.4211813773717,0.2639013403373051,13.188910165678136,70.85889396065936,0.07984441021977494
0.0837637588029298,65.3158567656144,0.2659499341993021,13.167676723947864,70.78695843773603,0.08043994458259639
0.0844230765593716,65.2082658205851,0.2680432680760048,13.145986389429957,70.71334823826021,0.08104811890227283
0.0850854269876054,65.0714937467696,0.27014623068564714,13.118413139348752,70.60812957693479,0.08165871844380916
0.0857632757977423,64.9675547546508,0.2722984006578318,13.097459038537602,70.53938507097884,0.08228321966427407
0.0864395600100347,64.841967233604,0.27444560303186016,13.072140594294565,70.44687835146182,0.08290589101245112
0.0871098926654212,64.7609042049424,0.2765739092127123,13.055798287716389,70.40221961915057,0.08352270023739324
0.087779335961727,64.6742584914787,0.27869939167848323,13.038330511882105,70.35132195567778,0.08413831165211366
0.0883840048503254,64.5728416294886,0.28061921539978313,13.0178848725049,70.28004797726861,0.08469403179758245
0.0890405021925808,64.4432776416682,0.28270359446144405,12.991764772560309,70.18133944581825,0.08529703535524841
0.0896970706137281,64.3285259045835,0.2847881991985867,12.968630822364034,70.09860623512397,0.08589974074686348
0.0903965986030312,64.1654276016142,0.28700920056462403,12.935750204485423,69.96576400470919,0.08654148199237777
0.0910841506903788,64.0618086915516,0.28919217844195266,12.914860632216802,69.8968241279111,0.08717183558164186
0.0917422630114012,63.9652772487387,0.2912816850611988,12.895399893345724,69.83359653768967,0.08777482658159677
0.0924065855105787,63.8424654467736,0.2933909089960874,12.870641034069559,69.74192968928705,0.08838313907835069
0.0930802548308663,63.8035421983821,0.2955298090880005,12.862794107193832,69.74239216531943,0.08899963269358453
0.0937629171891926,63.7082119992395,0.2976972620756865,12.843575539046682,69.68167980519571,0.08962396862149703
0.0944470209604432,63.6166116856124,0.29986929154940717,12.82510891581946,69.6250111429158,0.09024923202206167
0.0951014379650113,63.4862347412067,0.3019470655389109,12.798824923827272,69.52386695607971,0.09084699638885334
0.095758448230983,63.3704169545622,0.304033073133371,12.77547605803974,69.43866974588146,0.09144677028567519
0.0964202380268168,63.2704807800691,0.30613425573514336,12.755328925261932,69.3710355969545,0.09205054389234937
0.097108267603157,63.198263462063,0.3083187496400234,12.7407699139519,69.33533734239182,0.09267787068307766
0.0978055559847523,63.100240564222,0.3105326402515885,12.721008497747155,69.27179467537735,0.09331323813810884
0.0984692912234599,62.9697241378926,0.3126399996344852,12.694696386199148,69.17030824228767,0.09391765726147831
0.0991117870777933,62.751608487637,0.31467992397199374,12.65072427110762,68.97103254685273,0.09450238733490644
0.0997494123762542,62.5563092834315,0.31670438429460707,12.611351951539792,68.796264374881,0.09508234692170653
0.100399967465071,62.4723572446235,0.31876989670160044,12.594427220516097,68.74457987945,0.09567372050182531
0.101087634225678,62.3739127171499,0.32095323866652764,12.574580803777419,68.67914399112551,0.09629844969170973
0.101804431450028,62.4359821572268,0.32322906985383887,12.587094002896924,68.79224182276737,0.0969492280578553
0.102509151868842,62.3435584394695,0.32546655718357337,12.568461381397052,68.7343437395851,0.09758862931923337
0.103223906456771,62.2316834730645,0.3277359030002479,12.545907388169804,68.65548094653549,0.09823671736438348
0.103920170463378,62.1075145942176,0.32994654122122513,12.520874942194268,68.56173809790543,0.09886763587757338
0.104582349262376,61.9797388164976,0.3320489589080438,12.495115345405916,68.4617255085954,0.0994672990547051
0.105269069149293,61.8680768008158,0.33422929454900524,12.472604283044467,68.38087165569465,0.10008880682061233
0.105956063194499,61.7549649122947,0.3364105006425343,12.449800926318613,68.29827787711586,0.10071017644712499
0.106656030592511,61.6597162935982,0.3386328971312224,12.430598804789398,68.23609688093376,0.10134288330372081
0.107335055955622,61.539800653468,0.34078880265909983,12.406423811739149,68.14517860010582,0.10195627817105081
0.108016106700309,61.4309307241549,0.3429511387734811,12.384475633989627,68.0664606919545,0.10257112495256558
0.108708401575733,61.3107511595221,0.3451491750029523,12.360247433759655,67.97574491748126,0.10319573562957747
0.109410423707089,61.2070884433678,0.34737809527000757,12.339349030182948,67.90378192383395,0.103828724400778
0.110119442454696,61.084466569129,0.3496292297936598,12.314628460336406,67.811053970364,0.10446761535019385
0.11081583126929,60.9877431186804,0.3518402642799957,12.295129012725967,67.74615056961488,0.10509472848190493
0.111503770689273,60.8391098655719,0.3540244719384418,12.265164548899294,67.6229000209621,0.10571384684935406
0.112156732304263,60.7214384956749,0.356097625066035,12.241442000728062,67.53175661816408,0.10630113221317497
0.112818035502582,60.5802729332524,0.35819726272069785,12.212983023343684,67.41482031579218,0.10689556881296067
0.113502633073626,60.4212759716169,0.3603708600087625,12.180929235877969,67.27924988806363,0.10751057239468605
0.114196934159678,60.3217795059688,0.36257526595697764,12.160870748403312,67.21034178860653,0.10813390699396956
0.114881423353184,60.207201681308,0.3647485191463592,12.137771858951695,67.12389070656889,0.10874805248841878
0.115574454086066,60.1137628397724,0.3669488917232595,12.118934588498117,67.06137816303833,0.1093694776976722
0.116247873645346,59.9973254001219,0.36908699882397356,12.095460800664576,66.97188690229399,0.10997294829777292
0.116938698208514,59.8801161060955,0.37128036681203197,12.071831406988855,66.88241893211699,0.11059163783666848
0.117642871681039,59.7626310000842,0.3735161175872988,12.048146409616976,66.79327853014838,0.11122188871255727
0.118335285972111,59.6443667760136,0.3757145329614524,12.02430434204434,66.70239997507863,0.11184122777974373
0.119035309299369,59.5331051268908,0.37793710702549654,12.001873993581187,66.6196467092221,0.11246698316562377
0.119750709878658,59.398127614899,0.38020850386473914,11.97466252716364,66.51109556224628,0.11310608006681122
0.120443869296212,59.3059449266418,0.38240928501547305,11.956078497210989,66.44898240587459,0.11372491866781372
0.121133096125124,59.1651779708548,0.3845975801972687,11.927699878924328,66.33203916125842,0.11433986685943416
0.121812788998354,59.0364273876001,0.3867556050697739,11.901743761340182,66.22781926018247,0.11494593845353161
0.122501541277122,58.8878187254204,0.3889423935548623,11.871784255044755,66.10166728173216,0.1155597137087167
0.123174028271515,58.7196217325647,0.3910775397620601,11.837875741285043,65.95235407994429,0.1161586310444297
0.123847305148599,58.5593440427214,0.3932151938468018,11.805563759012635,65.81176099368211,0.11675789273119608
0.124509570413872,58.3899475501193,0.3953178860640436,11.771413426104052,65.66005483607317,0.11734700319815472
0.125179355821885,58.2404172320896,0.39744445473448486,11.741268113989262,65.53091514400039,0.11794245034641763
0.125842112514362,58.0868999677427,0.3995487072330993,11.710319033496928,65.39667816909387,0.11853130009392136
0.126506051424928,57.9284319110666,0.40165671327414637,11.678371873271029,65.25672909737342,0.11912085275760474
0.12718149407749,57.7858454825411,0.4038012436960307,11.649626449280285,65.13513564754166,0.11972026386420079
0.127855956054732,57.6682161428131,0.40594266047377403,11.62591237439112,65.04144105172341,0.12031844638867638
0.128530273214957,57.530969273681,0.40808361745748845,11.59824340557409,64.92544047274852,0.12091614298117646
0.129231978397047,57.40020450617,0.4103115314106242,11.571881228443871,64.81814649489745,0.1215377365118352
0.129892698763542,57.2365536512715,0.41240931857424584,11.538889216096335,64.67116407295941,0.12212267136913946
0.130579894374187,57.0521863708399,0.4145911646380437,11.501720772361322,64.5020548409606,0.12273068195409509
0.131207957577361,56.8843675055119,0.4165852653081212,11.4678884891112,64.34804918399011,0.12328605076888045
0.13187350681053,56.7048267828216,0.41869838412343274,11.431693079416835,64.18269114375595,0.12387423043702742
0.132548345465425,56.5646123789639,0.4208409968527243,11.403425855599123,64.06215816168867,0.12447026661658928
0.133209397933899,56.3933494556689,0.4229398384401293,11.368899250262851,63.905473584134526,0.12505378221013114
0.133878420519656,56.2360277330552,0.4250639851499078,11.337183190983929,63.7648183022562,0.12564398661221196
0.134544612108859,56.0337235540065,0.42717914344562735,11.296398668487711,63.57275915459534,0.12623134761037963
0.135205951650906,55.8035286539577,0.4292788964916265,11.249991376637873,63.348497851094656,0.12681408967139884
0.135868062221864,55.6254871779559,0.4313810975544182,11.214098215075907,63.18321433097191,0.1273971711435766
0.136560967893072,55.4418401861466,0.4335810730605036,11.177074981527156,63.01303154373979,0.12800700818006902
0.137233501434487,55.303808967183,0.43571636705449623,11.149247887784092,62.893344314413504,0.12859855994088035
0.137897524055612,55.1098105063134,0.4378246388765681,11.110137798072781,62.70931692630797,0.12918228248919944
0.138556762496943,54.8907714402844,0.43991772092779396,11.065979522361335,62.496259022009866,0.12976146254447554
0.139232054395734,54.6647378949551,0.4420617727064554,11.02041115962295,62.27582165507403,0.13035439891642306
0.139897665911205,54.4555499677823,0.44417508926807586,10.97823887350491,62.07375430418603,0.13093849163257174
0.140575783889133,54.2599426010012,0.44632811384799725,10.938804428361841,61.887576565916305,0.1315332084866305
0.141240642588554,54.0741416070263,0.44843904021865894,10.901346947976501,61.711608115027154,0.132115953628195
0.141904820133238,53.8480866546295,0.4505478039230306,10.855774269573308,61.48938970587371,0.13269776286835416
0.142582498944879,53.6404662271719,0.4526994341499908,10.813917991397854,61.28865794641045,0.1332910503213941
0.143254522906498,53.4258787752179,0.45483311022813117,10.77065716108393,61.079377550022144,0.13387903973144968
0.143933896032584,53.2006527787094,0.4569901199034542,10.725251600187814,60.85803000462575,0.1344731080997927
0.144603399764747,52.9520841350737,0.45911579425307175,10.675140161630857,60.60913552563428,0.13505820125295398
0.145266802091995,52.685186465903,0.4612220966420841,10.621333591526046,60.338595021425185,0.13563762478994776
0.145903450134248,52.4233207055279,0.46324345417623736,10.568541454234426,60.07206406395858,0.13619336529680887
0.146529068611904,52.0271353405007,0.4652297928427952,10.48867048464494,59.65062302448975,0.1367391772132528
0.147162640048449,51.7742671561654,0.46724138215382555,10.437692258682945,59.3935049974404,0.13729162412690415
0.147828622855493,51.5362995867164,0.46935587756619024,10.389717996682027,59.15483978168881,0.13787200352660223
0.148523195173191,51.4017739910379,0.4715611446748814,10.362597636593241,59.03612970175707,0.13847693900158142
0.149208257598023,51.1843706777509,0.473736217873723,10.318769128634582,58.821501442829444,0.13907323361582333
0.149869365353689,50.8680821521878,0.47583523499796254,10.25500536188106,58.491649341095496,0.13964834057810052