File: example/data/02 processed data/test_ID_085.csv
Strain,Stress_MPa,Displacement(mm),Force(kN),True Stress (MPa),True Strain
7.33781983876708e-08,0.763519162794752,0.0001433449514886,0.153925463219422,0.7635536341702958,4.514699707590208e-05
1.4468807700582469e-05,1.32897023660684,0.0001890504401581,0.2679203996999389,1.329049368073986,5.95416730785252e-05
1.7544440374850064e-05,1.88758838927651,0.0001988155738989,0.3805378192781444,1.8877065883218327,6.261711790079736e-05
2.2380104885843567e-05,2.51227430331005,0.0002141688087213,0.5064744995473062,2.5124437681272846,6.74524679353947e-05
4.254760559953716e-05,3.62086269641244,0.0002782006234873,0.729965919596748,3.6211799645257328,8.761840501357654e-05
6.123320947328407e-05,5.01050632316743,0.0003375274157864,1.010118074750554,5.0110389793094905,0.0001063021972131
8.044496661798408e-05,6.69490467831517,0.0003985247447208,1.3496927831483383,6.695745020103472,0.0001255117277101
0.0001048888399539,8.42623746783158,0.000476134042563,1.6987294735148468,8.42750109570848,0.0001499522345743
0.0001277662197683,10.2339301050654,0.0005487697234737,2.063160309181185,10.235698946323293,0.0001728259225268
0.0001585534547044,12.1750418988163,0.0006465191943958,2.454488446801366,12.17752107937698,0.000203607363337
0.000187504216597,14.2635247926042,0.0007384378634048,2.875526598189007,14.266842186863247,0.0002325518123468
0.0002064932563161,16.4482487416043,0.0007987280645129,3.3159669463074266,16.45238659290572,0.0002515362564381
0.000229288402091,18.7047277485564,0.0008711026523482,3.77087311410897,18.70985963452592,0.0002743254094535
0.0002514225069603,20.9594169460177,0.0009413784353083,4.225418456317168,20.96563135330262,0.000296453198387
0.0002765549859689,23.2744018079902,0.0010211740561606,4.692119404490824,23.28188754509224,0.0003215779122678
0.0003012792919441,25.6904695880567,0.0010996737276318,5.179198668952231,25.69936758316112,0.0003462939632865
0.0003150405970894,28.1657826312096,0.0011433658714682,5.678221778451855,28.17592555864384,0.0003600504091794
0.0003364787760515,30.6543141576043,0.0012114320896728,6.179909734173028,30.66601041582712,0.0003814806410767
0.0003661077410477,33.1833472065012,0.0013055040535358,6.689762796830642,33.19699161415096,0.0004110978667578
0.0004041132268213,35.7564280354887,0.0014261714708669,7.208495891954523,35.77248938905227,0.0004490870101717
0.0004411110177146,38.2756558086233,0.0015436394569532,7.716372211018458,38.29426488344123,0.0004860675057809
0.0004686729719653,40.8870545469766,0.0016311486616991,8.242830196670482,40.90806017352939,0.000513615686862
0.0004963508557777,43.5074827386462,0.0017190259428035,8.771108520111074,43.53103879897181,0.0005412789758969
0.0005420269248841,46.1272742639521,0.0018640474622163,9.299258491612743,46.15435565876492,0.0005869292862062
0.0005867035387598,48.7577813612479,0.0020058957112717,9.829568722427576,48.78858546346007,0.000631578688963
0.0006261903953547,51.4594153288929,0.0021312664809605,10.37421813030481,51.49395823504102,0.0006710398357733
0.0006581911901743,54.155546944505,0.0022328690045127,10.917758264012209,54.19363269007817,0.0007030186526603
0.0006930940495022,56.923096286768,0.0023436855828788,11.475696211412428,56.96511513404364,0.0007378963750154
0.0007349037201825,59.6583169360725,0.0024764312872888,12.027116694312218,59.70484913216935,0.0007796743331599
0.0007802646650062,62.3935182708862,0.002620452287104,12.578533283410655,62.44501409376916,0.0008249988978292
0.0008221521999053,65.1724377581397,0.0027534452104086,13.138763452040962,65.22895704525648,0.0008668510139971
0.0008607684065708,67.942405603691,0.0028760516665716,13.697188969704104,68.00395075923977,0.0009054330163741
0.0009037528850716,70.7079145859132,0.0030125273858117,14.2547155805201,70.77500420137262,0.0009483776707882
0.00094881235827,73.4610932509223,0.0031555912132166,14.809756399385938,73.53410527623754,0.0009933934176218
0.0009903988511557,76.1736823788285,0.0032876283281287,15.356614367571826,76.25255820750458,0.0010349377562939
0.0010279947581958,78.9245029517211,0.003406995332981,15.911179795066973,79.00919442045003,0.0010724940687906
0.0010671647097305,81.6873504097509,0.0035313599291037,16.468169842605782,81.77820629509,0.0011116212678252
0.0011063814840215,84.4504044901232,0.0036558731874776,17.025201545208837,84.54764542538213,0.0011507937048871
0.0011508305314823,87.2031575086774,0.0037969989131656,17.580156553749365,87.30744421553884,0.0011951906445264
0.0011871661659536,89.927808638977,0.003912364552612,18.12944622161777,90.03862135419375,0.0012314822183821
0.0012269999816719,92.6920191685606,0.0040388369175176,18.68671106438181,92.8099303335928,0.0012712662182635
0.0012684147980535,95.4278981240516,0.0041703289595292,19.2382642618088,95.55324166014412,0.0013126275634474
0.0013173537136639,98.1289144076335,0.0043257100165922,19.78278914457892,98.2626080227423,0.0013615010883003
0.0013619028349286,100.846318079727,0.0044671534766076,20.330617724872965,100.98820657749484,0.0014059886075747
0.0014062024407866,103.574598135535,0.0046078047252068,20.88063898412386,103.72491357575558,0.0014502249940136
0.0014448996466139,106.304483508689,0.0047306683537085,21.430983875351703,106.4628744554581,0.00148886537431
0.0014931835181011,109.027271557817,0.0048839696456803,21.979897946055907,109.19498364753032,0.0015370762489394
0.001538415029709,111.684379249028,0.0050275796950354,22.515570856604047,111.86123030961542,0.0015822372698956
0.0015824815018997,114.385822444552,0.0051674907442409,23.06018180482169,114.57199179219126,0.0016262331057711
0.0016247653174944,117.11117865659,0.005301741858754,23.609613617168545,117.306735581948,0.0016684473228747
0.0016704703110371,119.810763295057,0.0054468552132521,24.15384988028349,120.01630404487037,0.0017140750826608
0.0017141644229151,122.481715284325,0.0055855840184648,24.69231380131992,122.69718990210336,0.0017576934124083
0.0017577352445814,125.159332370633,0.0057239213772553,25.23212140591961,125.38497085193042,0.0018011867713449
0.001800180104109,127.834388823677,0.0058586838062554,25.771412786853286,128.07027583586088,0.0018435543510445
0.001846691343215,130.49464830445,0.0060063569904169,26.30772109817712,130.74151364084543,0.0018899788455098
0.0018947208668619,133.144156131044,0.0061588507279959,26.84186187601848,133.40242856660814,0.001937916531071
0.0019366117593334,135.758225805647,0.0062918543115929,27.36885832241844,136.02725603505468,0.0019797254470949
0.0019765641955001,138.351597954734,0.0064187032964221,27.891682147674373,138.63129491783866,0.0020195980717248
0.0020197936811258,140.918363878491,0.0065559569132837,28.409142157903783,141.20934174364936,0.0020627394086662
0.0020664551619734,143.478861640933,0.0067041071149749,28.925338506812093,143.78182153295677,0.0021093036541087
0.002108416449196,146.028209864354,0.0068373342019066,29.43928710865377,146.3426803127788,0.0021511756488714
0.0021465449954687,148.559142566988,0.0069583923363224,29.94952314150478,148.88472770057186,0.0021892215383476
0.0021867062710689,151.067595306076,0.0070859043863531,30.45522721370492,151.40474508126186,0.0022292941852691
0.0022331628838654,153.519327159148,0.007233404131982,30.94949635528424,153.86908065061638,0.0022756462736873
0.0022772002198588,155.960731754827,0.007373222673761,31.441683521773125,156.32291544099743,0.0023195825450077
0.0023180500744895,158.404379267513,0.0075029209622135,31.93432286033062,158.77870857072958,0.0023603369243683
0.0023590859880696,160.803026515718,0.0076332099878303,32.41789014556875,161.1896228206229,0.002401275255601
0.0023993567026488,163.168573298076,0.0077610695066193,32.894784376892126,163.56742767245782,0.0024414485781611
0.0024450703956482,165.549834878578,0.0079062104818924,33.37484671152132,165.96207797772527,0.0024870497599114
0.0024899169372242,167.882837376497,0.0080485982513962,33.8451800151018,168.3084189548743,0.0025317839039024
0.0025351933649134,170.25409738843,0.0081923509093094,34.32322603350749,170.69339858828943,0.002576944826678
0.0025758465349018,172.613297897305,0.0083214247240225,34.79884085609669,173.06570374449166,0.002617492548486
0.0026250170851352,174.922913599721,0.0084775412210136,35.26445938170376,175.38997382351357,0.0026665333609438
0.0026713917870683,177.183079586383,0.0086247808996512,35.72010884461481,177.6643914731729,0.0027127834983578
0.0027184677269497,179.421371840908,0.0087742470087746,36.171348563127054,179.91721040317108,0.0027597308024284
0.0027597760517932,181.655514121591,0.0089054009401527,36.62175164691275,182.1650307156831,0.002800924436106
0.0028018628013984,183.885732855641,0.0090390263701492,37.07136374369723,184.4092440330824,0.0028428925881655
0.0028419197348255,186.064787345088,0.0091662071337803,37.51066112876975,186.60195533913773,0.002882835008042
0.0028874938741627,188.187823198732,0.0093109050261759,37.93866515686437,188.7396968834205,0.002928276921351
0.0029273364671503,190.32125252636,0.0094374052589115,38.36876450931418,190.88696553091904,0.0029680022257872
0.0029669055572601,192.474851276081,0.0095630371200101,38.802930017257935,193.0545817162138,0.0030074532706573
0.0030062990846906,194.595603558957,0.009688111569602,39.23047367748573,195.1893874702116,0.0030467277306176
0.0030503961498984,196.708044188397,0.0098281197516367,39.65634170838084,197.3169481929305,0.0030906896821922
0.0030973997203321,198.7994953129,0.0099773560877637,40.07797825508064,199.42421762937389,0.0031375471056159
0.003139328769553,200.90674877559,0.0101104808190401,40.50280055315894,201.5465169109951,0.0031793439331335
0.0031837319303655,203.017668954385,0.0102514608546198,40.92836206120402,203.6731737374029,0.0032236051656642
0.0032288014890455,205.163432680421,0.0103945567034288,41.36094802837288,205.83511234481995,0.0032685286627283
0.003276268935282,207.257160162418,0.0105452658452297,41.78304348874347,207.945532399344,0.0033158400943308
0.0033274169670787,209.379525782663,0.0107076608461842,42.21091239778486,210.0856564756443,0.0033668175089331
0.0033770347665655,211.466771410094,0.0108651973595548,42.63170111627496,212.1904338372935,0.0034162673125869
0.0034181783679426,213.554826933202,0.0109958282939271,43.05265310973353,214.294421329516,0.0034572697556299
0.0034675386005273,215.602817858912,0.0111525470323835,43.46552808035666,216.36014717119104,0.0035064584214477
0.0035125933450835,217.626930901182,0.0112955958463494,43.87358926967829,218.40117526550992,0.0035513544522299
0.0035564526917829,219.630188738293,0.01143484927212,44.27744604963987,220.42119286548345,0.0035950573601096
0.0036002829218041,221.602551710525,0.0115740102524373,44.675074424841846,222.410372247679,0.003638729347206
0.0036453562774981,223.509075854266,0.0117171181567658,45.05942969222003,224.3339206576972,0.003683637982782
0.0036892134939122,225.342621641508,0.0118563648188806,45.42907252292802,226.1841159191221,0.0037273329876357
0.0037383356650603,227.104831737275,0.0120123277122758,45.78433407823464,227.9640624975488,0.0037762712074044
0.0037875756100066,228.812344998107,0.0121686645374803,46.12856875161837,229.68930268891523,0.0038253243564838
0.0038386116397109,230.469606050608,0.0123307039317914,46.46267257980258,231.3646776970605,0.0038761642373842
0.0038912208862055,232.018754343067,0.0124977382894118,46.77498087556231,232.9320487273237,0.0039285685833748
0.0039466410991199,233.54924782702,0.012673697465415,47.08352836192723,234.481510034968,0.0039837699776654
0.0040008522794802,235.049959758027,0.012845817963059,47.38607188721824,236.000954717169,0.0040377641650471
0.0040575291141473,236.542890306167,0.013025766913127,47.68704668572328,237.5133320554853,0.0040942110202639
0.0041150796145796,238.014982749037,0.0132084897519996,47.98382052220586,239.00516179170248,0.0041515247360299
0.0041735499690628,239.433834346887,0.0133941331274837,48.26986100433243,240.44391581223064,0.0042097511573756
0.0042314873425855,240.809583293395,0.0135780842884183,48.54721199194844,241.83942040187267,0.0042674434774028
0.0042961048515324,242.105356801745,0.0137832448793247,48.80843993123179,243.1563796110032,0.0043317837524438
0.0043670290008927,243.351420948105,0.0140084290535436,49.05964646313797,244.42511263800435,0.0044023988448848
0.004440518559594,244.539146489333,0.0142417584024203,49.29909193224953,245.6360496213756,0.0044755629077934
0.0045212152460097,245.657884702773,0.0144979703817901,49.52462955607904,246.7796298166231,0.0045558960113222
0.0046061149503407,246.70591933535,0.014767526943041,49.73591333800656,247.8533953387492,0.0046404062301003
0.0046978326889344,247.683436144693,0.015058730763076,49.93298072677011,248.8581757287486,0.0047316951801358
0.0047986841829065,248.56424403257,0.0153789342564375,50.11055159696612,249.76822928216936,0.0048320655655046
0.0049058892249691,249.377517086667,0.0157193102649862,50.27450744467208,250.6121761620048,0.0049387481445306
0.0050176640730242,250.124689150883,0.0160741954075612,50.42513733281801,251.3910050972348,0.0050499661407334
0.0051379764297163,250.771200510827,0.0164561871400586,50.55547402298272,252.07096044939183,0.005169665291402
0.0052622846880358,251.314749704913,0.016850865860223,50.66505354051046,252.6485673855344,0.0052933249297023
0.0053950678672288,251.7681667436,0.0172724524541608,50.75646241550976,253.1378214489701,0.0054253983792679
0.0055337444049096,252.187990678282,0.0177127504612973,50.84109892074165,253.5949018430758,0.0055633150678244
0.0056815851368745,252.550844125514,0.0181821447852859,50.91425017570363,253.9971168856829,0.0057103247923922
0.0058310824486873,252.87200710966,0.0186567987502915,50.97899663330745,254.357922746267,0.0058589598120242
0.0059886284698926,253.139145089947,0.0191570073676183,51.03285165013332,254.66651153641024,0.0060155732117041
0.0061456026574557,253.355031902512,0.0196554004131312,51.07637443154642,254.92347114620503,0.006171593772244
0.0063092754934629,253.565953087595,0.020175061667454,51.11889614245916,255.17719993493645,0.0063342463679749
0.0064796459448502,253.758762959077,0.0207159878506087,51.15776661254992,255.41446798283943,0.006503526732874
0.0066512186247036,253.897887815523,0.0212607311091433,51.18581418360944,255.5980625311216,0.0066739726790358
0.006823821143969,254.053063187918,0.0218087441078109,51.21709753868428,255.79812720205047,0.0068454123926614
0.0069995196210802,254.189360061213,0.022366586772639,51.24457498834054,255.98002096782423,0.0070198970251203
0.0071727596251216,254.291993058159,0.0229166237854704,51.26526580052486,256.12743051849645,0.0071919103656022
0.0073529219816397,254.401929700921,0.0234886392674154,51.28742902770568,256.28399431688297,0.0073707656632094
0.0075339600682236,254.481364317516,0.0240634351923193,51.30344304641123,256.4100874097704,0.0075504581204994
0.0077110028680175,254.606459244823,0.0246255460816649,51.32866218375632,256.58120667626326,0.0077261537645404
0.0078912494089274,254.699008938577,0.0251978288490538,51.34732020201713,256.7203828079496,0.0079049970654841
0.0080701599460701,254.776090493365,0.0257658698044819,51.36285984346239,256.84365823413566,0.0080824831390384
0.0082517637159014,254.900291749776,0.0263424617736963,51.38789881675484,257.015158266791,0.0082626087916862
0.0084319644693384,255.033132911057,0.0269145991658587,51.41467959486909,257.1950587524159,0.008441310782951
0.0086171810733438,255.138874259734,0.0275026618835759,51.43599705076237,257.3489524304809,0.0086249536330027
0.008800257902757,255.247697748749,0.0280839308169628,51.4579358661478,257.50544851560414,0.0088064417532773
0.0089854216970135,255.328516791986,0.0286718258637272,51.47422898526438,257.63426002710526,0.008989965230913
0.0091718799202208,255.454558414082,0.0292638307224104,51.49963897627893,257.8090714706797,0.0091747376419027
0.0093584437370666,255.564157583176,0.0298561708408958,51.52173416876828,257.9673598350226,0.0093595805282983
0.0095440867044355,255.626899828962,0.030445587262292,51.53438300551874,258.0781474148933,0.0095434771513588
0.0097253810186895,255.688412037485,0.0310211967100485,51.54678386675698,258.1866043292314,0.0097230333960365
0.0099105428064818,255.768516112368,0.031609085386289,51.56293284825339,258.3148496131303,0.0099063867633838