File: example/data/02 processed data/test_ID_055.csv
Strain,Stress_MPa,Displacement(mm),Force(kN),True Stress (MPa),True Strain
0.0019280833223116658,46.8159610839017,0.0061216645483395385,18.876195509029166,46.90622615768556,0.0019262269554331062
0.002037070714850666,49.4286561679305,0.0064676995196508635,19.929634166909576,49.52934583588461,0.0020349986997191304
0.002129668980257966,51.9329051812938,0.006761699012319041,20.93934736909766,52.04350507851307,0.002127404449838676
0.0022251850855352657,54.3941172923572,0.007064962646574468,21.931708092278424,54.51515427089701,0.0022227130277144066
0.002310841850196166,56.7744836787222,0.007336922874372827,22.891471819260794,56.905680531630274,0.00230817596134306
0.002403088937102166,59.0693467454663,0.007629807375299377,23.81676060777201,59.211295639152176,0.002400206136376248
0.002507929023777866,61.3273136662633,0.007962674650494724,24.727172870237364,61.481118216157256,0.0025047894179605567
0.002598605947706866,63.5171926007337,0.0082505738839693,25.610132056615832,63.6822487552076,0.0025952354091427045
0.002678289087248366,65.6375141173998,0.008503567852013562,26.4650456921356,65.81331035517454,0.0026747088621912854
0.0027722026721368658,67.7292720145169,0.008801743484034548,27.308442476253212,67.91703128337743,0.002768367205135256
0.002852960305980366,69.724952615843,0.009058148971487661,28.113100894707895,69.92387513799235,0.0028488983386470127
0.0029528449014902657,71.698287307015,0.009375282562231593,28.908749442188448,71.91000122913509,0.0029484938182622847
0.0030583557322863657,73.5986009471271,0.009710279450009211,29.674955901881646,73.82369165022199,0.0030536884760589034
0.003164775118399966,75.4072243923072,0.01004816100091989,30.404192874978264,75.64587129981159,0.003159777758529158
0.003294076400037666,77.2108930505072,0.010458692570119589,31.1314320779645,77.4652316311307,0.0032886628156224753
0.003427426649913366,78.8936979609005,0.010882079613474937,31.80993901783508,79.1641003238019,0.0034215664097378695
0.0035648628487724657,80.4058649504773,0.011318439544852578,32.41964474803245,80.69250083126268,0.003558523785999882
0.0037337230195054662,81.7807241248293,0.011854570586929855,32.97398796713117,82.086070697046,0.003726769977493203
0.003924819337880366,83.0307196880505,0.01246130139777016,33.47798617822196,83.35660026232028,0.003917137328235853
0.004124369146827366,84.1053944369671,0.013094872041176887,33.91129503698514,84.45227613086467,0.004115887250048609
0.0043487336821420655,85.0389979330783,0.013807229440801058,34.28772396661717,85.4088098876855,0.0043393052643920195
0.0045941670798647655,85.7582142656478,0.01458648047857063,34.57771199190919,86.15220183045503,0.004583646105389179
0.0048740575615311655,86.3424031057906,0.01547513275786145,34.81325693225477,86.76324094852914,0.004862217799177749
0.005174994352671066,86.8046915167227,0.016430607069730634,34.99965161954259,87.2539053051071,0.005161650087262327
0.005498200030364066,87.1683735838969,0.01745678509640591,35.14628822902723,87.64764273818267,0.005483140105013213
0.005829614668603966,87.400401544283,0.01850902657281759,35.23984190265491,87.90991220716742,0.0058126882162829645
0.006183362473444966,87.5514744534728,0.019632175853187765,35.300754499640234,88.09283695510318,0.006164323928880081
0.006543186543488366,87.6450314866007,0.02077461727557556,35.338476695397404,88.21850927722744,0.006521872821006181
0.006909606953313466,87.7000087519313,0.02193800207677025,35.36064352877871,88.30598134220931,0.006885845013504247
0.007277652320397766,87.7212251518954,0.023106546117262906,35.36919798124423,88.35962972967022,0.007251297996573126
0.007656165811124866,87.7169040574342,0.02430832645032145,35.36745571595747,88.38847921933646,0.007627006113409177
0.008037787981645466,87.7017560633473,0.025519976841724353,35.36134804474164,88.40668418420249,0.008005657023545802
0.008426104157404366,87.7009649195241,0.02675288069975886,35.361029055552116,88.43994238464087,0.008390802705620933
0.008819020893563166,87.6986525342543,0.02800039133706305,35.36009670181133,88.47206878329122,0.008780360460648782
0.009221590943807966,87.6726503516774,0.02927855124659029,35.34961262179633,88.48113167018008,0.009179331673837892
0.009627176338968365,87.6202072344548,0.030566284876224557,35.328467556932175,88.46374242035785,0.009581130369401178
0.010039752962689665,87.5638756173525,0.03187621565653968,35.305754648916526,88.44299529700639,0.00998968944760811
0.010460305525721565,87.5063612806624,0.03321147004416597,35.28256486836308,88.4217045551023,0.010405975076839664
0.010872957900515965,87.4455403110937,0.03452164133413819,35.25804185343298,88.3963319894841,0.010814272301244593
0.011286501056949866,87.3614587335221,0.03583464085581582,35.22414016135611,88.34746392985467,0.01122328372748709
0.011706256391189464,87.2818902676106,0.03716736404202655,35.1920581559006,88.30363445339091,0.011638268248531992
0.012125085044339665,87.2035304262712,0.03849714501577843,35.160463467872546,88.2608806488564,0.012052165049668016
0.012549784464557066,87.1253750881465,0.039845565674968685,35.12895123554067,88.21877976689642,0.01247168863129791
0.012977151718270866,87.0290242039992,0.041202456705509996,35.09010255905248,88.15841305498756,0.012893669946304203
0.013397231409123765,86.9503206007171,0.04253620972396795,35.05836926620914,88.11521416690242,0.01330828207362721
0.013824989281353665,86.8561385048819,0.04389434096829788,35.02039504516838,88.05692368873164,0.013730295875777234
0.014259726447892666,86.7757505178381,0.045274631472059214,34.98798260879232,88.01314898253307,0.014159012851775477
0.014689651930180165,86.692802773137,0.04663964487832202,34.95453807812884,87.96628987072614,0.014582804093985454
0.015125342787063265,86.6072625863383,0.04802296334892586,34.920048274811606,87.91722712080586,0.015012095300039281
0.015565380324043265,86.5129956851097,0.04942008252883736,34.88203986023623,87.85960336592075,0.015445482362736143
0.015997658734667766,86.4154889193118,0.050792566482570155,34.84272513226652,87.79793442043241,0.01587104475862296
0.016443899848611665,86.3186392942421,0.052209382019342034,34.803675363438416,87.73805435386505,0.016310163039027988
0.016893794884360765,86.2151034465199,0.053637798757845426,34.761929709636824,87.67160372007936,0.016752681804362676
0.017338673554384766,86.0927812294291,0.05505028853517163,34.71260939170581,87.58551585855523,0.017190073974646884
0.017786078092451765,85.9688014509644,0.05647079794353435,34.662620745028846,87.49784926708574,0.01762975664757648
0.018227853732235167,85.8624462981655,0.05787343559984665,34.61973834742033,87.42753441038035,0.018063717967596055
0.018673502997727166,85.7530641028394,0.05928837201778375,34.57563544626485,87.35437420242806,0.018501293671623578
0.01912462632073217,85.6488930232263,0.06072068856832463,34.533633666964846,87.28689609707985,0.01894404933410458
0.019575345407469368,85.5399833528539,0.06215172166871524,34.48972128787069,87.21445807313519,0.019386212575710486
0.020027108177044867,85.4314023305917,0.06358606846211745,34.44594141969457,87.1423462667831,0.019829203587188624
0.020480162602688767,85.3326030366824,0.06502451626353684,34.40610554439034,87.08022862218435,0.020273264178960484
0.020944912635080366,85.2425241442235,0.06650009761638016,34.369785734950916,87.02792136521799,0.02072858340282845
0.021418454068358767,85.1332759675415,0.06800359166703908,34.325736870112735,86.9566991285412,0.02119230249364665
0.021876442605757166,85.0312399033556,0.069457705273279,34.284595929032974,86.89142094279772,0.021640586826773035
0.022349054268483867,84.9094881401453,0.07095824730243627,34.235505618106586,86.80713489849859,0.022102973849995086
0.022812927645286966,84.7961117880551,0.07243104527378612,34.18979227294382,86.73055935087766,0.022556603820491187
0.023288179100435867,84.6903485159486,0.07393996864388387,34.14714852163048,86.66263252026634,0.023021147299920153
0.023772118308509466,84.5796202876783,0.07547647562951755,34.10250289999189,86.5902570276458,0.023493961137110796
0.02424723021243297,84.4578151751273,0.07698495592447467,34.05339107861133,86.50568326291773,0.023957933230723778
0.024716977567043767,84.3277065199063,0.07847640377536395,34.00093126882622,86.41203255023908,0.02441645501559169
0.025207494706768568,84.2039913734528,0.0800337956939902,33.95104932177617,86.3265630402879,0.02489502596366449
0.025683903111854468,84.0875394031023,0.08154639238013793,33.90409588733085,86.24723561804582,0.02535961264452106
0.026176865356853266,83.9802851483126,0.08311154750800911,33.86085097179964,86.17862576527013,0.0258401152810146
0.026662545061808967,83.8738465584509,0.08465358057124346,33.8179349323674,86.11013677182284,0.026313293759129025
0.027146297082775068,83.7629516115471,0.08618949323781083,33.77322208977579,86.03680558052427,0.026784371709506344
0.027627766463700968,83.6475586668159,0.08771815852225057,33.726695654460165,85.95855388292142,0.027253006581124777
0.028118813881627267,83.5396378640256,0.08927723407416657,33.683181986775125,85.88867339286267,0.027730738060248034
0.028609534937531367,83.4330234592423,0.09083527342666209,33.6401950587665,85.82000345884336,0.028207924136374633
0.029100332647385867,83.321932965469,0.09239355615545013,33.5954033716771,85.74662893158732,0.02868495710092732
0.029591829075564367,83.2025683792303,0.09395405731491686,33.54727557050566,85.66468456135644,0.029162441249995348
0.03007393549195147,83.0798687828039,0.09548474518694591,33.49780309322654,85.57840739725773,0.029630581696358547
0.030564682267211967,82.9501338217557,0.09704286619839798,33.4454939569319,85.48547830604036,0.03010688722641011
0.031081791523990966,82.8453626670163,0.09868468808867131,33.403250227340976,85.42034495816192,0.030608534113203783
0.031581697899090565,82.7505146606981,0.10027189082961253,33.365007511193475,85.36391641570654,0.031093253397227523
0.032088135024237664,82.6443909889939,0.10187982870195458,33.32221844676234,85.29629536604463,0.031584065568083616
0.03260090907609736,82.5546942494781,0.10350788631660912,33.28605272138957,85.24605233051037,0.03208077383886908
0.033113852096088164,82.4382669557243,0.10513648040507992,33.23910923654804,85.16811553475398,0.032577399065327826
0.03364434893819476,82.3356377669092,0.10682080787876837,33.197729147617785,85.1057666939879,0.03309076038015586
0.03415849128833567,82.249690268545,0.10845320984046573,33.16307511627734,85.0592155970514,0.0335880441160461
0.03467549723387106,82.1406515241774,0.11009470371754061,33.119110694548326,84.98891945889237,0.03408784831412688
0.03519296061450716,82.0235846758523,0.11173764995106024,33.07190934130365,84.91023746081027,0.03458784471675279
0.03571209126056246,81.9176456043734,0.1133858897522858,33.02919470768335,84.8430960400472,0.03508920102612022
0.03624557608458706,81.8010707330642,0.11507970406856391,32.98219171957148,84.76599766612016,0.035604158299834536
0.03678484574384306,81.6888621422214,0.11679188523670171,32.93694921574367,84.69377433511308,0.036124430135444856
0.037316940525982466,81.5639641362372,0.11848128616999432,32.886590339730844,84.60768173497254,0.03663751468831965
0.03785386763865956,81.4421513112778,0.1201860297527441,32.83747540870721,84.52505172722259,0.0371549922111781
0.03837317633355836,81.311630430941,0.1218348348590478,32.78484938975541,84.43181596343663,0.03765523490596047
0.038912761888618766,81.1765747011482,0.12354801899636457,32.730394919502956,84.33537942342764,0.03817474505838354
0.03944223228840226,81.0271681541852,0.12522908751567718,32.670154199767474,84.223060542194,0.03868425417758713
0.039968439534911464,80.9089884488745,0.12689979552334388,32.6225041425862,84.14279446152418,0.03919036609176711
0.040488884975536266,80.8097752349854,0.12855220979732765,32.582501374746116,84.08167292937365,0.039690684406735476
0.04102057212079396,80.7106143130907,0.13024031648352083,32.54251969103817,84.02140988843442,0.040201551321136016
0.041558932923280265,80.5971054972774,0.13194961203141484,32.49675293650225,83.94663519844929,0.040718564777932696
0.04210871805756066,80.4997689797837,0.13369517983275508,32.457506852648784,83.88951105545216,0.0412462738363136
0.04266036878236786,80.4023834356296,0.13544667088401796,32.41824100124585,83.83237876397492,0.041775493826349784
0.043224197888611066,80.3151451195673,0.13723682829634012,32.38306651220954,83.78670284566799,0.04231610775003892
0.04377644678186096,80.2027514620228,0.13899021853240853,32.3377493894876,83.71374294315886,0.04284533509603876
0.044327177420009765,80.0831125255164,0.140738788308531,32.28951097028821,83.63297086278158,0.043372828697923076
0.04488268379100236,79.9473702047909,0.1425025210364325,32.23477966657169,83.53562274161473,0.04390461479983418
0.04544799152145036,79.8423314636904,0.1442973730806049,32.192428046159975,83.47100506710503,0.044445493571701376
0.046010971105395766,79.7334225707785,0.14608483325963154,32.148515980537894,83.4020347728169,0.04498385421621131
0.046558160876082964,79.6207607204537,0.1478221607815634,32.10309072248693,83.32775690715269,0.045506837925371746
0.04711479029118036,79.5065845791793,0.14958945917449765,32.05705490232509,83.25252063839534,0.046038563215037236
0.047681439514357764,79.3886625709319,0.1513885704580859,32.00950874859974,83.17402828343354,0.04657956976157933
0.048255527815643164,79.2715337279051,0.15321130081466702,31.962282399091333,83.09682342870072,0.04712738043011638
0.04882127124829826,79.1584961931087,0.15500753621334698,31.916705665061432,83.02311460735984,0.047666934772267855
0.04938909126469036,79.0031907111123,0.1568103647653919,31.854086494720477,82.90508650734516,0.04820817700459924
0.049960940328190366,78.8526160919178,0.1586259855420044,31.793374808261255,82.7921669392078,0.048752963790068785
0.050546161930443964,78.7166083617206,0.16048406412915958,31.73853649144575,82.69543079458747,0.04931018315558914
0.051109178002832566,78.5889857453508,0.1622716401589934,31.68707905252544,82.605604206872,0.04984596661652043
0.05166685278251226,78.4556998577798,0.16404225758447644,31.633338182656818,82.50925895228067,0.05037638429732893
0.05223878265800616,78.3272180853406,0.16585813493916954,31.581534332009333,82.41893660710696,0.05092006827245404
0.05281739080542176,78.2139455242295,0.16769521580721408,31.535862835369336,82.3450020514167,0.051469800074655826
0.053387358597035764,78.1195022016602,0.16950486354558855,31.49778328770939,82.29009607912215,0.05201102742274623
0.053953774196103865,78.0094422162544,0.17130323307262976,31.453407101593776,82.21834604675419,0.05254859165844961
0.05453631271763067,77.8970462418776,0.17315279287847735,31.408089044725052,82.14526391550437,0.053101156301712
0.05513337230506316,77.7727890344016,0.17504845706857552,31.357988538670725,82.06066516743839,0.05366717818429559
0.055748291212767864,77.6629691599022,0.17700082460053795,31.313709165272567,81.99254698107664,0.05424979627769845
0.05635385474795216,77.5306969564532,0.1789234888247481,31.260377012841932,81.89985059124466,0.05482321887748653
0.056964499509261864,77.3923666718026,0.1808622859419064,31.20460224207081,81.80098410509913,0.05540112024012271
0.05757115353050806,77.2557503766102,0.1827884124593631,31.149518551849233,81.70345304265663,0.05597491433720365
0.058187063592964064,77.130427643945,0.1847439269076609,31.098988426038623,81.61842074221573,0.05655712649629545
0.058775415938407266,76.975776052892,0.18661194560444305,31.036632904526055,81.50005930758242,0.05711297230488236
0.05938093740661556,76.8358350877369,0.1885344762660044,30.980208707375517,81.39841900166684,0.05768471620258574
0.05998172777043476,76.6964627261063,0.19044198567113035,30.92401377116606,81.29684907429892,0.05825167002298063
0.06056702323614746,76.5555967384268,0.19230029877476817,30.867216604933688,81.19234134494023,0.05880369268249066
0.061143338826392266,76.3975118972751,0.19413010077379544,30.803476796981318,81.06871085270352,0.059346948364061014
0.06172835670376276,76.2568226574698,0.19598753253444676,30.746750895491825,80.96403100756567,0.05989810545321696
0.062317630632974165,76.0964826521424,0.19785847725969297,30.682101805343816,80.83863515052714,0.06045296532710193
0.06291788680932386,75.9668075244556,0.19976429061960327,30.6298167938605,80.746478521545,0.0610178497245108
0.06349666384172657,75.8181342782534,0.20160190769748185,30.569871740991772,80.63233286362653,0.06156221869199946
0.06408554643417856,75.6698643319203,0.20347160992851693,30.510089298630266,80.51920893623156,0.06211578847148521
0.06468166680136127,75.5066669259508,0.20536429209432203,30.44428810454336,80.39056399733651,0.06267585006869357
0.06529133519328656,75.3713099924041,0.2072999892386848,30.389712188937327,80.29240345707527,0.06324831592436818
0.06590099436103997,75.2076543978528,0.20923565709630187,30.323726253214254,80.16391360623275,0.0638204455965043
0.06650546545325277,75.0578669263345,0.21115485281407753,30.26333194469807,80.04962530219869,0.06438738357929034
0.06711052083946917,74.9024437679141,0.2130759036653146,30.200665327222964,79.92918578132786,0.06495454787344887
0.06772786039252256,74.7268126535677,0.2150359567462591,30.1298508619185,79.78789978854674,0.06553289570126421
0.06833877464586596,74.5528812078567,0.21697560950062442,30.059721703007824,79.64773375592043,0.06610489496381439
0.06895477215772436,74.3950938697469,0.21893140160077482,29.996101848281953,79.52499061718781,0.06668132259570063
0.06955664353538686,74.2246188113596,0.22084234322485327,29.927366304740193,79.38743416357131,0.06724421077028542
0.07016754710209316,74.0568908786146,0.22278196204914577,29.859738402257403,79.25328125757434,0.06781522229221722
0.07077803240907976,73.8824187246625,0.22472025289882822,29.78939122978392,79.11167095161785,0.06838551733322613
0.07138451727998546,73.6964249323656,0.22664584236395383,29.71439853272981,78.9572086514232,0.06895175343626904
0.07199002047764626,73.4943892996241,0.22856831501652686,29.63293776560844,78.78525189029615,0.06951675334935184
0.07259265323838957,73.2862360322056,0.23048167403188685,29.549010368185296,78.60627835163827,0.07007875805450121
0.07318629227244067,73.0681107140992,0.2323664779649991,29.4610622399248,78.41569482061632,0.07063206672633646
0.07378587357789787,72.8498865496626,0.23427014860982573,29.373074256823962,78.2251790687802,0.07119060337677031
0.07438429464053556,72.6153921424304,0.2361701354837004,29.278526111827937,78.01683686699097,0.07174774832456905
0.07498387188567346,72.3853232426069,0.23807379323701322,29.185762331419106,77.8130550470336,0.07230565857003358
0.07559897618156866,72.1439908524291,0.2400267493764805,29.088457111699412,77.59800269852519,0.07287769355415072
0.07618898466302436,71.9181518975956,0.24190002630510232,28.99739884511055,77.39752286951457,0.07342608262126882
0.07678303544768196,71.6593318391969,0.2437861375463902,28.89304259756419,77.16155285596315,0.07397792518511465
0.07738322952783616,71.4192791801303,0.2456917537508798,28.796253365428537,76.94593365363893,0.07453516545523073
0.07798024718518136,71.1681098463536,0.2475872848129508,28.69498189004977,76.7178166438744,0.0750891487430281
0.07857388697557846,70.9120722258539,0.2494720911474616,28.591747521464296,76.48390937413221,0.07563969351812833
0.07916724418352676,70.6441852363026,0.25135600028269744,28.483735487277208,76.23689069905127,0.07618967350816161
0.07974409901976537,70.3626785845509,0.25318751438775505,28.370232005290926,75.97368699289325,0.07672406770807416
0.08032991752450666,70.0960292188492,0.25504748814030864,28.26271898104,75.72683746479477,0.07726647367621882
0.08094196064342736,69.814715968176,0.25699072504288184,28.149293478368563,75.46565596040416,0.07783284678407638
0.08153572924235636,69.5215326680014,0.2588759403444814,28.031081971738164,75.1900215321332,0.07838200261271513
0.08213984941668476,69.2231573931917,0.26079402189797407,27.910777060934894,74.90913711761593,0.07894042291933194
0.08273065351002436,68.9176572991529,0.26266982489432733,27.787599423018452,74.61926012589173,0.07948623303333921
0.08333424115794097,68.5975044067295,0.26458621567646257,27.658513776793335,74.31402538179282,0.08004354566513082
0.08392716674271497,68.2864420336108,0.26646875440812,27.533093427951872,74.0175296404324,0.08059071140840998
0.08453637559930867,67.9038396095222,0.26840299252780503,27.378828130559352,73.64418409938799,0.08115259207711928
0.08511814218109626,67.5406077230864,0.2702501014249806,27.232373033948434,73.28953877425771,0.08168886786753894
0.08571785540052876,67.1816593175719,0.2721541908966788,27.08764503684499,72.9403270765231,0.08224138610047504
0.08630833163231777,66.7868282947402,0.2740289529326089,26.92844916843925,72.55108801987332,0.08278509616240783
0.08691718926160306,66.392917489727,0.2759620759055897,26.769624331857926,72.16360326481158,0.08334542240500106
0.08751625599940677,65.9874227406831,0.27786411279811646,26.606128849043426,71.7623949219978,0.08389643191441265
0.08812920817506546,65.5625206023578,0.2798102359558328,26.434808306870664,71.34049362900501,0.08445989889648257
0.08873120943469996,65.1763057079718,0.2817215899551724,26.27908646145423,70.95947813992588,0.0850129901926548
0.08932581988472627,64.7108809124652,0.2836094781340059,26.091427183905967,70.49123340543403,0.08555899101521733
0.08993036891788586,64.2670876808394,0.2855289213142876,25.912489752914443,70.0466505852554,0.0861138124738177
0.09052786086251606,63.8320999670415,0.2874259582384885,25.737102706711134,69.61068343142004,0.08666185503792134
0.09111908923701627,63.3854567517469,0.28930310832752665,25.55701616230435,69.16108184183835,0.08720385693144202
0.09168845621079376,62.9012812256617,0.29111084846927016,25.361796590186795,68.66860259492361,0.08772554010765969
0.09226517232704257,62.4260742197767,0.2929419221383601,25.170193125413967,68.18582671536515,0.08825367964516474
0.09283058731786706,61.9311163736518,0.29473711473422787,24.970626121856405,67.68021827986907,0.08877119930163564
0.09339387052834856,61.4821111244587,0.29652553892750666,24.789587205381746,67.22416345062594,0.0892865015807995
0.09393642644777267,60.964764654499,0.2982481539716782,24.580993108694,66.69157678537212,0.08978259120320475
0.09447041354312627,60.4284699012431,0.2999435629994259,24.364759064181218,66.13717244259189,0.09027060567674165
0.09500233004595857,59.9079086942379,0.30163239789591845,24.154868785516726,65.59929960837104,0.09075649116205277
0.09553673599696047,59.4033936659069,0.30332913679034945,23.95144832609366,65.07860000389016,0.09124441303469885
0.09607507913205826,58.8622421945405,0.305038376244285,23.73325605283873,64.51743677127135,0.09173568903732747
0.09661296121523136,58.3113301106488,0.3067461518583595,23.511128300613596,63.94496038503746,0.09222630337376278
0.09712953172384386,57.7489875067851,0.3083862632232042,23.284391762735755,63.358119620845244,0.09269725246630472
0.09764626503579707,57.1698746752667,0.3100268914886557,23.050893469067532,62.752299409871085,0.0931681281906167
0.09819065837874026,56.6010605211487,0.3117553403525003,22.821547602127158,62.15875591865522,0.09366396952408906
0.09872251756129706,55.9845949100226,0.31344399325711814,22.572988667721113,61.51153506418941,0.0941481572460003
0.09924386604808616,55.3608052165365,0.3150992747026735,22.321476663307518,60.85502555376063,0.0946225489386614
0.09974432079902837,54.7573718339925,0.31668821853691503,22.07817232346578,60.219108696313924,0.0950777171497285
0.10024435655221337,54.1540695468411,0.3182758320532774,21.83492084128633,59.582709403247996,0.095532297454567
0.10074754534269306,53.5152541538075,0.31987345646305043,21.577350474815184,58.90678464819396,0.09598953566504227
0.10125785749813807,52.8894683770888,0.32149369755658835,21.325033649642204,58.24494262916833,0.09645303331488668