File: example/data/02 processed data/test_ID_074.csv
Strain,Stress_MPa,Displacement(mm),Force(kN),True Stress (MPa),True Strain
0.0003564904747817478,12.64659236909,0.0011318572574320492,5.099106043217088,12.651100758808028,0.00035642694714994465
0.0004260721289689478,15.2256943507384,0.0013527790094764092,6.138999962217723,15.232181594745452,0.00042598138601396285
0.0004989743340388478,17.9108107931343,0.0015842435105733418,7.221638911791749,17.9197478280219,0.000498849887741163
0.0005708470364692573,20.7167517738593,0.0018124393407898919,8.35299431522007,20.728577870214675,0.0005706841652796999
0.0006437963289193173,23.6809511594337,0.0020440533443188322,9.54815950748367,23.696196868855463,0.0006435891809654831
0.0007184272372574961,26.6925209429257,0.00228100647829255,10.762424444187642,26.711697577002166,0.0007181692919458498
0.0007993396885938478,29.783279082907,0.0025379035112854664,12.008618126228102,29.807086039934436,0.0007990203867674524
0.0009046987718584478,32.9053145773098,0.0028724186006505717,13.267422837571312,32.93508397499551,0.0009042897785830452
0.0009792843820170477,36.004889608886,0.0031092279129041264,14.517171490302838,36.04014863495624,0.0009788051958808277
0.001069647887389448,39.0148781551407,0.003396132042461497,15.73079887215273,39.05661033713611,0.0010690762217056811
0.001157402419480748,42.0503911832179,0.0036747526818513747,16.954717725073458,42.099060407713466,0.0011567331456633716
0.001226758404058048,45.0435032519048,0.003894957932884302,18.161540511168017,45.098760748067285,0.0012260065507990346
0.0013050364674493478,47.9981038652284,0.004143490784151679,19.352835478460094,48.06074314114095,0.0013041856475122912
0.001372577957917248,50.8992757133307,0.004357935016387262,20.522587967614943,50.96913893724877,0.001371636833870935
0.001454378465622748,53.6755994593138,0.004617651628352225,21.642001701995323,53.75366409529681,0.0014533218815866995
0.0015193985164588478,56.3582063743996,0.004824090289756841,22.72362881015792,56.44383694955514,0.0015182453984156517
0.0015884398361822479,59.054245673871,0.005043296479878637,23.810671855704786,59.148049790195074,0.00158717959998878
0.0016620749972183478,61.6359647102551,0.005277088116168254,24.851620971174857,61.73840830612944,0.0016606952791551137
0.0017393148571721478,64.1499710456879,0.005522324671521569,25.865268325621365,64.26154804341483,0.0017378040007355318
0.0018072309390942478,66.5795924922827,0.005737958231624237,26.844891692888385,66.69991719174703,0.0018055998621200832
0.001878238496600648,68.92049335846,0.005963407226707057,27.788742922131075,69.04994248229058,0.0018764768122396813
0.001946418386755348,71.2052846059032,0.006179878377948229,28.70997075310017,71.34387988109427,0.0019445265689353205
0.0020253589023466476,73.4271114932852,0.006430514514950606,29.605811354092594,73.57582774722172,0.002023310628198919
0.0020885815263538476,75.5593326485269,0.006631246346173466,30.46552292388605,75.71714447484024,0.0020864034721263473
0.002146100161915248,77.7287083506365,0.006813868014080912,31.340215206976637,77.89552194421326,0.0021438005784659105
0.002218948253495748,79.8219851135971,0.0070451607048489994,32.18422439780235,79.99910596805547,0.0022164900236049164
0.002277638457639448,81.9019231786645,0.007231502103005247,33.02285542563753,82.08846614865087,0.0022750485709724594
0.002348879947982948,83.972606180209,0.00745769383484586,33.85775481186027,84.16984775104557,0.002346125641658012
0.002407020478059148,86.0234628612337,0.007642290017837794,34.68466022564943,86.23052309793424,0.002404128244448784
0.0024648650258830476,88.0938959648162,0.007825946457178675,35.519458853013894,88.31103552797364,0.0024618322286865417
0.002520385483367648,90.1835813241967,0.008002223909692283,36.36201998991611,90.41087871340432,0.002517214638591944
0.0025708632882145478,92.2178556358224,0.008162490940081188,37.1822393923636,92.45493513539442,0.002567564272194398
0.0026202841471761476,94.242807108404,0.008319402167284268,37.99869982610849,94.48975004185552,0.0026168571877696937
0.0026847607765220476,96.345397762735,0.008524115465457501,38.84646437793475,96.60406210764681,0.002681163243879703
0.0027143919572674476,98.419735795761,0.008618194464324146,39.682837472850835,98.6868855350414,0.002710714648354014
0.0027660554867596477,100.442198867484,0.008782226170461881,40.49829458336955,100.7200275627636,0.002762236995100936
0.002820791467791848,102.476622011855,0.008956012910239116,41.31857399517994,102.76568719287417,0.002816820501298957
0.002877967552054148,104.432343500367,0.009137546977771919,42.107120899347976,104.73289639634602,0.002873834132105295
0.0029319745875257476,106.407451599589,0.009309019315394249,42.90348448495428,106.71943554360237,0.002927684733151974
0.002995121083884248,108.318602488726,0.009509509441332487,43.67406052345433,108.64302981881687,0.0029906446448213927
0.003042892665557048,110.133479143388,0.009661184213143627,44.40581879061404,110.46860349930569,0.0030382724378684705
0.0031158781985456477,111.923309224525,0.00989291328038243,45.12747827932848,112.27204862364678,0.0031110339102711623
0.003178181188693148,113.728481412541,0.010090725274100744,45.85532370553653,114.08993113278497,0.003173141446178913
0.003237273150785148,115.52800087666,0.010278342253742844,46.58088995346932,115.9019965720619,0.003232044463479219
0.003294112196879048,117.354983500759,0.010458806225090976,47.31752934750603,117.7415639832734,0.0032886984949327316
0.003356995818494748,119.090300315133,0.010658461723720824,48.01720908706163,119.49008595531419,0.0033513736868333705
0.0034130181924239477,120.956237956876,0.010836332760946034,48.769555144212404,121.36906379750997,0.0034072070644029224
0.003482238665063548,122.727921550017,0.011056107761576764,49.48389796896686,123.15528946372135,0.0034761897105380414
0.0035654967160696476,124.476521450007,0.01132045207352113,50.18893344864282,124.92034207846477,0.0035591554014742575
0.003645252572030348,126.175802720416,0.011573676916196355,50.87408365687173,126.63574538981058,0.003638624740736128
0.003740524596656548,127.896259064407,0.01187616559438454,51.567771654768904,128.3746581672578,0.0037335462309463917
0.003845496202573248,129.486714564716,0.012209450443170062,52.2090433124935,129.98465523385832,0.0038381211830777963
0.003970848029658148,131.027946659817,0.01260744249416462,52.83046809323822,131.54823872364128,0.003962985020955883
0.004102219273019548,132.387664864691,0.013024546191837063,53.378706473443415,132.930748095009,0.004093828111964891
0.004262753563644848,133.740784501998,0.013534242564572392,53.9242843112056,134.31088850773855,0.004253693767001078
0.004418382434346848,135.028209620321,0.014028364229051241,54.44337411891343,135.62481588984875,0.00440865003977572
0.004604906541360448,136.143092864089,0.014620578268819424,54.89289504280068,136.7700190829799,0.0045943363964974695
0.004811613827689147,137.009037768471,0.015276873902913043,55.242044028247506,137.66827234911617,0.004800075012620656
0.005037316926774548,137.778569159138,0.015993481242509187,55.55231908496444,138.4726034777101,0.005024672092112964
0.005277221730833448,138.394043652498,0.016755178995396195,55.8004784006872,139.12437970707887,0.005263345991728631
0.005540041825515348,138.892612548781,0.01758963279601123,56.0015013796685,139.66208343155634,0.005524752237777774
0.005800314026922347,139.231127959791,0.01841599703547845,56.13799079338773,140.03871222428037,0.005783556971747665
0.006082480842065648,139.375296264105,0.01931187667355843,56.19611945368713,140.22304383348865,0.006064057225254557
0.0063597369425080486,139.442366021888,0.020192164792463052,56.223161980025246,140.32918278842814,0.006339599151125995
0.006640548661777547,139.448240759938,0.021083742001143713,56.225530674407004,140.37425358850362,0.0066185973441209335
0.006948448904564447,139.400914277078,0.02206132527199212,56.20644863651785,140.36953440718182,0.006924419679819736
0.007247536226276047,139.344246158846,0.023010927518426448,56.183600051246714,140.35414863080535,0.007221399046393611
0.007548014482751348,139.227242898533,0.02396494598273553,56.136424336688506,140.27813214432467,0.007519670757979666
0.007863204089019948,139.100370913411,0.024965672982638333,56.08526955228732,140.19414551876153,0.00783245021056354
0.008180255892802748,138.999691316668,0.025972312459648723,56.04467553888054,140.13674436065892,0.008146978952319518
0.008502632348237947,138.903829063535,0.02699585770565548,56.00602387841731,140.08487725382474,0.008466688570585119
0.008837881601215647,138.792540912288,0.02806027408385968,55.961152495834526,140.01917295600265,0.008799056114631939
0.009141250671445847,138.672970663822,0.02902347088184056,55.91294177165304,139.94061505001406,0.009099722328334602
0.009463140242373748,138.520106432383,0.030045470269536648,55.85130691353682,139.83094162594116,0.009418645218926786
0.009784588043373548,138.361040981546,0.031066067037711014,55.78717172375936,139.71484676880277,0.00973702894095591
0.010103808936953847,138.21112427847,0.03207959337482846,55.726725309079114,139.60758307114125,0.010053106697246952
0.010427877052126947,138.072078688197,0.033108509640503055,55.67066212708103,139.5118773490891,0.01037388178847568
0.010741640736028247,137.952504897944,0.03410470933688968,55.62244997485102,139.43434114419293,0.010684359146916442
0.011060222296432047,137.815978046736,0.03511620579117175,55.567402348443956,139.3402533999331,0.010999505323072927
0.011405213249790148,137.676563302788,0.03621155206808372,55.511190323684126,139.24679386675453,0.011340664139081164
0.011739396930886147,137.565554176045,0.03727258525556351,55.46643144378134,139.1804908205349,0.011671024788985917
0.012059224866578948,137.476464892443,0.03828803895138816,55.430510644633024,139.13432449644333,0.011987091748327272
0.012392927935210048,137.35658450456,0.0393475461942919,55.38217487223859,139.05883475775158,0.012316764219164894
0.012721073235048147,137.216840498649,0.04038940752127786,55.32583008905527,138.96238597571423,0.01264084010083931
0.013068439057588047,137.07290714844,0.041492294007842045,55.26779616225102,138.86423608195582,0.01298378375202968
0.013411525846556248,136.937221533896,0.042581594562816086,55.213087722466874,138.77375861985342,0.01332238743742284
0.013753797092787947,136.809768850969,0.04366830576960173,55.1616988007107,138.69142265205645,0.013660072031383766
0.014101088276567647,136.668393075213,0.04477095527810228,55.10469608792589,138.59556615058324,0.014002592780457937
0.014461385281564548,136.511808180485,0.045914898268967434,55.04156105837154,138.48595803406602,0.014357816751601811
0.014812221644213048,136.368263712328,0.047028803720376426,54.98368392881065,138.3881806596715,0.014703592072333998
0.015176980363357247,136.230938312314,0.04818691265365926,54.928314327525015,138.29851258796174,0.015062962183967202
0.015526886402729747,136.105664512194,0.049297864328666945,54.877803931316635,138.2189617038429,0.015407577712170927
0.01587965469916905,135.967971962412,0.05041790366986173,54.822286295244524,138.1270964073214,0.01575489204128009
0.016232913614936048,135.845344483376,0.05153950072742195,54.7728428956972,138.05051022536585,0.016102568567505617
0.016593911083268548,135.710040045944,0.05268566768937764,54.71828814652462,137.96200038357318,0.016457736521550026
0.01695034541898035,135.58017122705,0.05381734670526261,54.66592503874656,137.87830196131299,0.016808291311023932
0.01732069682237095,135.446238471095,0.05499321241102776,54.6119233515455,137.7922617033834,0.017172403466967745
0.017669194651422648,135.309077018561,0.0560996930182669,54.556619853883795,137.6998794385063,0.017514909180552637
0.01803477072718035,135.162218944129,0.0572603970587976,54.49740667827281,137.59983857376332,0.01787407346564026
0.01839348459405105,135.023324640998,0.05839931358611208,54.44140449525039,137.50687408261973,0.018226370552113454
0.01874601062152665,134.895788617325,0.05951858372334711,54.389981970505445,137.4245465035446,0.018572469610938423
0.01909148129457305,134.732791735774,0.06061545311026943,54.324261627864075,137.30504030896313,0.018911525769956385
0.01945727838505025,134.57522186684,0.06177685887253454,54.26072945670989,137.19368942243298,0.019270405676719744
0.01981827938394075,134.437873367537,0.06292303704401188,54.20535054179092,137.10220070171772,0.01962445395752833
0.02018859801299185,134.30320061101,0.06409879869124911,54.15105048635924,137.0145939400039,0.019987510217016332
0.02056229048503955,134.156071512164,0.06528527229000057,54.091728033704534,136.91462762492887,0.02035374058675977
0.02092749182720555,133.988446042529,0.06644478655137762,54.0241414443477,136.792488152024,0.020711519841131572
0.021297593359957748,133.820498876065,0.06761985891786584,53.95642514682941,136.6705534443541,0.021073969151433662
0.02166902036640965,133.711352154776,0.06879913966335063,53.912417188805684,136.608746167838,0.021437584501825296
0.02202954611197185,133.59211362267,0.06994380890551062,53.864340212660544,136.53508724991642,0.02179040145361621
0.02238646876234865,133.415164071259,0.07107703832045696,53.79299415353163,136.40185847416387,0.022139569774942455
0.02275935975465645,133.270418455585,0.07226096722103421,53.734632721291874,136.30356785386928,0.02250422934223629
0.02312176539184705,133.126942089166,0.07341160511911438,53.67678305035173,136.2050720114857,0.02285850763976453
0.023487531093363948,133.024889723555,0.07457291122143053,53.63563553653738,136.1493159571283,0.02321594342981921
0.02385845656817195,132.906971734486,0.07575059960394594,53.588091003344765,136.07792694722048,0.023578291055576364
0.02423533790000955,132.790097889223,0.07694719783253032,53.54096746893472,136.00831078134368,0.023946322380225225
0.02461467192965365,132.662682659144,0.07815158337665033,53.48959364816686,135.92813107010656,0.024316612086312552
0.02498935849147035,132.580276511052,0.07934121321041836,53.45636748925617,135.89337256968497,0.02468223057693755
0.02534434323445815,132.45836500125,0.08046828976940462,53.407212768504,135.81543526811683,0.02502850079259654
0.025727411022291948,132.337304266085,0.08168452999577692,53.35840108008547,135.74200048652068,0.025402030184235556
0.026107942862850148,132.214260953237,0.08289271858954922,53.30879001634516,135.66610332385807,0.02577294868332503
0.02648926413957315,132.132162940656,0.08410341364314475,53.2756880976725,135.63224670612414,0.026144498717407566
0.026874205240634948,131.987151861796,0.08532560163901595,53.217219630676155,135.53420167005677,0.026519435849884764
0.02724962987630495,131.851217110464,0.08651757485726821,53.16241073893909,135.4441139754645,0.026884968475943575
0.027632988878219848,131.685214152318,0.08773473968834801,53.09547834621461,135.324070210415,0.02725808857814659
0.02803177369215495,131.530546358807,0.08900088147259197,53.033116291870975,135.21758086794256,0.02764607481617401
0.02841277325699895,131.393168111596,0.09021055509097166,52.97772538259551,135.12641240466954,0.02801661684685371
0.02881452766440365,131.246989951623,0.09148612533448158,52.91878634849439,135.02880997445374,0.02840719538169238
0.02920612784032415,131.049971731329,0.09272945589302917,52.83934860207186,134.87743395918508,0.028787755391718774
0.029595289659216848,130.904501835648,0.09396504466801349,52.780695140133275,134.7786584851695,0.029165802366254327
0.02999217299483165,130.757607706441,0.09522514925859048,52.721467427237016,134.6793124971629,0.02955120317852751
0.03039092992758365,130.644421250306,0.09649120252007808,52.67583064812339,134.6148267019538,0.029938273852098036
0.03078927186978835,130.511323424149,0.097755938186578,52.622165604616875,134.529672043141,0.030324792165068976
0.03117765393662475,130.363933025271,0.09898905124878357,52.56273779578926,134.42837461495023,0.030701502447439306
0.03155657454503335,130.18801051456,0.10019212418048087,52.4918058394706,134.2962981732323,0.03106889889380509
0.03194451552672275,130.049373053159,0.10142383679734472,52.435907215033716,134.2037372698962,0.03144490158954065
0.03233327537337905,129.896785842318,0.10265814931047848,52.37438405162262,134.0967743890745,0.031821556178342744
0.032730035102342146,129.776694065645,0.10391786144993631,52.32596304726806,134.02428981787946,0.03220581532607171
0.03312720742183815,129.624585850493,0.1051788835643361,52.26463301491877,133.91868639293213,0.03259032623632623
0.03351957212558705,129.486851389559,0.10642464149873888,52.2090984802702,133.82719524402648,0.032970037672597055
0.03391306844391985,129.361781583971,0.10767399230944552,52.15867033465711,133.74883653685563,0.03335069948025445
0.03431903807843935,129.22266834245,0.10896294589904493,52.102579875675836,133.65746601789206,0.033743275959899025
0.03472132599286665,129.088622187159,0.1102402100273516,52.04853246586251,133.57075032008933,0.034132140214538476
0.03513156449368615,128.975730149876,0.11154271726745353,52.00301439643001,133.50684933175665,0.034528534091684784
0.03553448952980585,128.852423362214,0.11282200425713355,51.953297099644686,133.4311284510687,0.03491770842563598
0.03593537103661775,128.74121563129,0.11409480304126135,51.908458142536126,133.36757898270562,0.03530475872209255
0.03634754090315915,128.623827186053,0.11540344236753029,51.86112712141658,133.29898700581893,0.03570255177399845
0.03677078474799305,128.49586793431,0.11674724157487792,51.8095339511138,133.22076183512905,0.036110867927955884
0.03718433806767875,128.404240478415,0.11806027336488002,51.77258976089693,133.17886716568793,0.036509674363656944
0.037602491678027046,128.283068813844,0.11938791107773586,51.723733345741906,133.10683184134837,0.03691275540313038
0.03802086897541255,128.149324642539,0.12071625899693483,51.669807695871725,133.02167332406057,0.03731588952754086
0.03845496301055905,128.005541212465,0.12209450755852497,51.611834216865894,132.92798956493695,0.037733996047042424
0.03887327519238845,127.871978697576,0.12342264873583332,51.55798181086264,132.8427813148821,0.038136736624858246
0.03930448002388995,127.732164446214,0.12479172407585058,51.50160870471348,132.75261075209843,0.038551720219603666
0.039728648803321547,127.602838266445,0.1261384599505459,51.44946438903063,132.67232661423964,0.038959764496951134
0.04015868095917645,127.45698550043,0.12750381204538522,51.39065655377337,132.57548991716016,0.039373279359827755
0.04058917491136205,127.322215065132,0.1288706303435745,51.33631711426122,132.4901187225127,0.0397870670824616
0.04100724496181865,127.173372548919,0.13019800275377422,51.27630381172415,132.38840218965314,0.04018874922611489
0.041416132828611646,127.01968788105,0.13149622173084197,51.21433815363937,132.28035214618035,0.0405814531079562
0.04183772184629285,126.86021246831,0.13283476686197979,51.15003766722259,132.16775475092075,0.040986194011221985
0.04225772838035835,126.705389053628,0.13416828760763774,51.08761286642281,132.05967096858384,0.04138925284396977
0.04268361414407495,126.550696918095,0.13552047490743796,51.0252409973759,131.95233803501074,0.04179778785735699
0.04311510275409855,126.429943106776,0.13689045124426288,50.97655306065208,131.88098309501947,0.04221152731618693
0.04354110705860065,126.299397930745,0.13824301491105706,50.923917245676385,131.79861353748439,0.042619840203012654
0.04398471691958405,126.182466313957,0.13965147621967935,50.876770417787455,131.73256637499134,0.043044850387380505
0.04442691167173675,126.065308053839,0.14105544455776417,50.829532207307885,131.66600035961721,0.043468325101567416
0.04488196515069525,125.947970296551,0.1425002393534574,50.78222162356937,131.60076271020162,0.04390392702831177
0.04532269909972945,125.82648679934,0.143899569641641,50.73323947749389,131.52928279932257,0.044325640713200165
0.04577624701783295,125.706208597265,0.1453395842816196,50.68474330641725,131.46056705368864,0.0447594297752219
0.04620190956205575,125.55639342543,0.146691062859527,50.624337829133374,131.3573385594096,0.045166377188853794
0.04666367107440985,125.403259256969,0.14815715566125126,50.5625941324099,131.25503569859515,0.04560764921713816
0.04711217997778455,125.234158089151,0.14958117142946595,50.49441254154568,131.1342122844134,0.04603607034923717
0.04756615466456645,125.073298489939,0.15102254105999846,50.42955395114341,131.02255435031893,0.04646952563101662
0.04802141137437965,124.928448562409,0.1524679811136554,50.37115046036331,130.9276889831875,0.04690401639089055
0.04847395906648285,124.795449020855,0.15390482003608305,50.31752504520874,130.84477850837527,0.04733573468181795
0.04889913524121605,124.645963095449,0.15525475439086095,50.25725232008504,130.741042902125,0.04774117154158434
0.049376627270001146,124.524364194996,0.15677079158225363,50.20822364342239,130.6729573118862,0.04819629955245743
0.04982742692801675,124.40530916787,0.15820208049645318,50.16022065648518,130.60410561988937,0.04862579535496783
0.05029763932451965,124.305680487825,0.15969500485534988,50.12005037269104,130.5579627709906,0.049073590023881626
0.05076026331510825,124.197528915615,0.1611638360254687,50.07644365877597,130.5018281864574,0.04951396246434013
0.051224834134217447,124.068789600712,0.16263884837614037,50.024535967007075,130.42419276924159,0.049955993026057494
0.05169662674300575,123.927751257885,0.16413678990904323,49.96766930717923,130.33439795776394,0.0504046951059793
0.05218368995162905,123.767270831877,0.16568321559642224,49.90296359941281,130.22590371912696,0.050867709293107626
0.05264753496157365,123.60165737715,0.16715592350299632,49.83618825446688,130.10897995522194,0.051308452486160894
0.05311401621115465,123.435647024746,0.168637001470416,49.76925288037759,129.99180998185273,0.05175150479372348
0.05357197616293725,123.282031856689,0.17009102431732576,49.70731524461701,129.886493928634,0.05218627291830773
0.05404643122938385,123.134287247995,0.1715974191532937,49.64774461839159,129.78925603572296,0.05263650154868699
0.05451947142295315,122.994853381502,0.17309932176787624,49.591524883421606,129.7004677756051,0.05308518584250983
0.05501220016237145,122.871887708364,0.17466373551552933,49.541945124012365,129.63134058930495,0.05355233099611492
0.05550423890458745,122.777402092103,0.17622595852206516,49.503848523535936,129.5920683499077,0.05401860431388933
0.05599393504031025,122.672944060547,0.17778074375298503,49.461731045212545,129.54188492147688,0.05448244193453719
0.05648791977700125,122.562438271514,0.17934914529197896,49.41717511107445,129.48573545226893,0.05495012381740724
0.05698588865489295,122.442216303083,0.1809301964792851,49.36870161340306,129.4196948079888,0.055421356425183026
0.05747710093576365,122.302399271107,0.18248979547104957,49.31232738611035,129.3319866186985,0.05588597774239285
0.05796328459663775,122.156064573447,0.18403342859432484,49.253325236013836,129.23663130952298,0.05634563018427604
0.05844441161149875,122.008221819957,0.1855610068665085,49.19371503780666,129.1389205559896,0.05680029402244977
0.05893895715225555,121.803502806083,0.18713118895841135,49.11117233141266,128.98247423896538,0.057267422986477114
0.05943478588482225,121.669732599533,0.18870544518431062,49.05723618413171,128.90114710524983,0.057735545047799895
0.05994081447175995,121.543212680515,0.19031208594783783,49.00622335278365,128.8286118420994,0.0582130711611215
0.06045067705126695,121.407699774714,0.19193089963777255,48.95158454916469,128.74687742533243,0.058693984795581966
0.060969567234680146,121.282733970298,0.19357837597010946,48.90119833682416,128.67728977350592,0.05918317612404104
0.06148517294548185,121.157396231593,0.19521542410190487,48.850662160578295,128.60677969251677,0.05966903404240659
0.06199734308548005,121.010659106097,0.19684156429639915,48.79149775157831,128.51299845569775,0.060151421013868146
0.06252423483569465,120.90789199845,0.1985144456033305,48.75006205377504,128.4675654312499,0.06064743081343211
0.06304871437176915,120.726327715422,0.20017966813036703,48.67685533485815,128.33796746870422,0.06114092556449592
0.06356326804248175,120.553663183174,0.20181337603487953,48.60723699545575,128.21644798958914,0.06162484429062855
0.06407995622416715,120.389835566048,0.20345386101173069,48.54118170023055,128.10441095895504,0.06211053492329606
0.06457771356158445,120.232531610789,0.20503424055803063,48.477756745470124,127.99687359793467,0.06257820744157341
0.06511172151840465,120.082639405077,0.20672971582093475,48.41732020812705,127.90142678121539,0.06307969649365373
0.06564970021551415,119.925306183469,0.20843779818425742,48.3538834531747,127.79836658266748,0.0635846603089861
0.06617713572119585,119.794433143549,0.21011240591479682,48.301115443478956,127.72208560433336,0.06407948053317349
0.06670627297760745,119.673830464031,0.21179241670390364,48.2524884430973,127.65682566724058,0.06457565136474284
0.06722548134565755,119.548087672218,0.2134409032724627,48.201788949438296,127.58476540993574,0.06506227271731789
0.06775606004301606,119.398216888106,0.21512549063657596,48.14136104928434,127.48816964060556,0.06555930624945441
0.06831709671082085,119.237331719674,0.2169067820568562,48.07649214937256,127.3832800423072,0.06608460350243645
0.06885834675301525,119.086213884615,0.2186252509408234,48.01556143827678,127.28629369378557,0.06659111320936884
0.06939717084278045,118.961798564072,0.22033601742582792,47.965397181033836,127.21741082278734,0.06709509797333776
0.06993593768647155,118.800448240884,0.22204660215454716,47.90034073072443,127.10886898618335,0.0675987753604012
0.07049648249070375,118.643494503164,0.2238263319079844,47.83705698367573,127.00744353604222,0.06812254318578324
0.07106456449484555,118.479226850011,0.22562999227113462,47.77082426592444,126.89890150779304,0.06865307395749853
0.07162651833110614,118.345431835414,0.22741419570126198,47.71687811603893,126.82210307817597,0.069177604865056
0.07218689140564324,118.220439358853,0.2291933802129173,47.66648114948953,126.75440537677794,0.06970038645113469
0.07274197597894975,118.075134932998,0.23095577373316545,47.60789440498479,126.6641535620054,0.07021796500037132
0.07330114085421804,117.926306910152,0.2327311222121423,47.547886946173286,126.5704397433908,0.07073907744544396
0.07386086907450715,117.750561115995,0.23450825931156016,47.47702624196918,126.44771989403324,0.07126044307167949
0.07441512723993675,117.582792203968,0.23626802898679916,47.4093818166399,126.33273064705331,0.07177644583731904
0.07498190306934426,117.430542565863,0.238067542245168,47.34799476255596,126.23570812591704,0.07230382708382833
0.07555265716248255,117.277253397597,0.2398796864908821,47.28618856991111,126.13786151650322,0.07283462916168723
0.07610990053973765,117.104602442201,0.24164893421366704,47.216575704695444,126.01742208682244,0.07335259457194071
0.07667576743330685,116.911968302382,0.24344556160074926,47.13890561952042,125.87628319410558,0.0738783012551651
0.07723183234346985,116.724276136703,0.24521106769051676,47.06322813831865,125.73910586170571,0.07439463252450483
0.07779428231781704,116.568317237379,0.2469968463590691,47.000345510111224,125.63666581785652,0.07491662154662554
0.07836487352121226,116.405135017818,0.2488084734298489,46.934550439184214,125.52720870070895,0.07544588787204473
0.07892896204346794,116.234780181502,0.2505994544880107,46.86586336918161,125.4090707345786,0.07596884726293714
0.07947945259219365,116.070836089277,0.25234726198021484,46.79976111119649,125.29608260357095,0.0764789366018491
0.08004785825901804,115.905953687448,0.2541519499723823,46.73328052677903,125.18397703959715,0.07700535335712186
0.08061073628711404,115.701754213411,0.2559390877115871,46.65094729884731,125.02855781026474,0.07752637786534385
0.08118179966509075,115.514196262836,0.2577522139366631,46.575323933175476,124.89184660231952,0.07805470182036059
0.08175218753512525,115.366313912784,0.2595631954240227,46.51569776963451,124.79776244301804,0.07858212233955544
0.08230960905626256,115.214548194696,0.2613330087536336,46.454505832101425,124.69781261419533,0.07909728464623558
0.08288328647413586,115.043423299216,0.26315443455538134,46.3855082742439,124.57860030949018,0.07962719348944465
0.08345878678510554,114.844386586273,0.26498164804271007,46.305256671585276,124.429159759843,0.08015850415511633
0.08402449504506895,114.639560806148,0.2667777717680939,46.222670917038876,124.27209201507307,0.08068049966719348
0.08460371900229324,114.516527807979,0.26861680783228103,46.173064012177136,124.20505194776356,0.08121468433494418
0.08519015363567985,114.351285200149,0.2704787377932835,46.10643819270007,124.09288875478713,0.08175522844382095
0.08577360653433025,114.136337410809,0.2723312007464985,46.019771244038196,123.92622270715329,0.08229273434180231
0.08632531187447685,113.927184249878,0.274082865201464,45.93544068955081,123.7619839612297,0.08280072718442584
0.08690232616889695,113.718460002518,0.2759148855862478,45.85128307301526,123.60085870508149,0.08333174777138898
0.08748111563429276,113.514112456908,0.2777525421388795,45.7688901426253,123.44445365487488,0.0838641188959462
0.08806191361334975,113.323918033904,0.27959657572238544,45.69220375127009,123.30343911413198,0.08439805270929487
0.08863411008693625,113.112807382952,0.28141329952602256,45.60708393680625,123.13846040477499,0.08492380043018602
0.08920497415322826,112.88295337514,0.2832257929364997,45.51440680085645,122.95267431330946,0.08544804860214471
0.08976970446548635,112.665704076368,0.28501881167791915,45.42681188359158,122.7796710346995,0.08596639361133075
0.09036072904122985,112.411620374141,0.2868953147059048,45.324365334853645,122.56921634385434,0.08650858556566399
0.09091265136174975,112.143520529494,0.28864766807355546,45.21626747749198,122.33878531387111,0.08701464073257435
0.09146336897549025,111.862487350745,0.2903961964971815,45.10295489982039,122.0938073058223,0.08751933618404396
0.09200650318677675,111.562990911497,0.29212064761801615,44.982197935515586,121.82751159032199,0.08801683260422666
0.09255023555346475,111.251094052892,0.2938469978822506,44.85644112212605,121.54740901306783,0.08851462913042706
0.09308648507001815,110.962512299754,0.29554959009730764,44.74008495926081,121.29162254427675,0.08900533238614523
0.09362520148719995,110.655775281822,0.2972600147218598,44.61640859363063,121.0159445383049,0.08949805068219882
0.09415980461042554,110.346469442707,0.2989573796381011,44.49169647929946,120.73667144488259,0.08998676701618608
0.09469862655269945,110.008976303412,0.3006681393048207,44.35561924553572,120.42667526781358,0.09047909849408015
0.09523355360524875,109.66492388243,0.30236653269666475,44.21689730939578,120.10870428960291,0.09096763148887785
0.09576697432162824,109.266970162746,0.30406014347116966,44.05644236961919,119.73113728852383,0.09145455125007339
0.09630238540168515,108.874323128109,0.30576007365035035,43.89812708525355,119.35918015433975,0.09194304956179791
0.09680539015943905,108.454262068025,0.307357113756219,43.72875846582768,118.95321922197421,0.09240176369539341
0.09731166050525285,108.018200268397,0.3089645221041778,43.552938348217666,118.52963070130366,0.09286324350080784
0.09781561621781965,107.461890309752,0.31056458149157734,43.32863417289201,117.97334133033213,0.09332240204415485
0.09831298323286135,106.940652311397,0.31214372176433475,43.11847101195527,117.45430686899863,0.09377535095039785
0.09880701195097034,106.434177399804,0.3137122629443308,42.91426032760097,116.95062043813813,0.09422505668109782
0.09931327874489305,105.968904024375,0.3153196600150354,42.726662102628,116.49302332803857,0.09468569280280384
0.09980772661321935,105.448523884232,0.3168895319969714,42.516844830122345,115.97310132783696,0.09513537053809294
0.10032850253776594,104.895634748604,0.31854299555740684,42.29391993063713,115.4196567056799,0.09560877389136949