File: example/data/02 processed data/test_ID_075.csv
Strain,Stress_MPa,Displacement(mm),Force(kN),True Stress (MPa),True Strain
0.0006753540432521833,29.5464961429663,0.002144249087325682,11.913147244844012,29.566450488600392,0.0006751260943354246
0.0007185927858399832,31.7061557052557,0.0022815320950419467,12.783921980359098,31.728939520012215,0.0007183347216653383
0.0007611498842032833,33.791532662187,0.0024166508823454244,13.6247459693938,33.81725308335988,0.0007608603565368229
0.0008092886333598833,35.9178955169909,0.0025694914109176295,14.482095472450734,35.946963461567016,0.0008089613358874087
0.0008511310125143833,38.064105732829,0.0027023409647331667,15.347447431476652,38.09650327368183,0.0008507690059095654
0.0008928455228683833,40.2143900006054,0.002834784535107117,16.2144420482441,40.250295238672315,0.0008924471733964882
0.0009453099569044832,42.2812050439314,0.003001359113171734,17.04778187371314,42.32117388804935,0.0009448634328275302
0.0009943438725835833,44.3737580072893,0.0031570417954528765,17.891499228539043,44.41788078166736,0.0009938498401801483
0.0010459200733601833,46.5266414508341,0.0033207962329185815,18.759541832976307,46.575304599073554,0.001045373480055606
0.0010977481401029834,48.6905925079124,0.003485350344826972,19.63204689919028,48.744042515278466,0.0010971460551981054
0.0011446895966788833,50.8176206546602,0.0036343894694554546,20.489664647958993,50.87579105635157,0.0011440349390813998
0.0012012101556265833,53.0086988961938,0.003813842244114402,21.373107394945343,53.07237348364446,0.0012004892799320835
0.0012469474824870833,55.1549002448207,0.003959058256896489,22.23845577871171,55.2236755088278,0.0012461706891548896
0.0012901016127842833,57.3134307992579,0.004096072620590099,23.108775298260785,57.38737094876622,0.0012892701467388417
0.0013346351140019832,59.4419976347077,0.004237466486956296,23.967013446314144,59.521331011997404,0.0013337452802058656
0.0013771803224518833,61.5368714532628,0.004372547523784729,24.81166656995556,61.62161882173348,0.0013762328793984096
0.0014221830028400832,63.6308840223544,0.004515431034017264,25.655972437813293,63.72137878406668,0.0014211726584095845
0.0014606310200197834,65.7454431752392,0.004637503488562812,26.508562688256447,65.8414730089659,0.0014595653361192508
0.0015011615328827832,67.792859303003,0.004766187866902837,27.334080870970812,67.8946273355928,0.0015000359162563647
0.0015551279702881832,69.8525578051467,0.004937531305664981,28.16455130703515,69.96118747158566,0.0015539200109781744
0.0015998148600425833,71.8701720836858,0.005079412180635201,28.978053384142118,71.9851510529791,0.0015985365194733554
0.0016456402332846833,73.8728736748252,0.005224907740678869,29.785542665689523,73.99444184789286,0.001644287651101812
0.0016918656242333834,75.8730607759864,0.005371673356940992,30.592018104877717,76.00142779931866,0.0016904360318131084
0.0017375105475168832,77.8558083955333,0.005516595988366104,31.391461945079026,77.99108368380598,0.0017360028222718118
0.0017940326858867832,79.7632719013807,0.0056960537776905365,32.1605512306367,79.90636981830505,0.0017924253313915896
0.0018405625605806832,81.6866376126164,0.005843786129843669,32.93605228540693,81.8369869795059,0.0018388708008525829
0.0018858903408511833,83.6655175743737,0.005987701832202506,33.73393668598747,83.82330156582952,0.001884114282279552
0.0019317483930537834,85.5997712635695,0.006133301147945762,34.51382777347122,85.76512848415368,0.0019298849665217342
0.001981258640418083,87.5508150249449,0.006290496183327414,35.300488618057784,87.72427583368871,0.0019792985360733103
0.0020222315870742835,89.4454146243019,0.0064205852889608495,36.064391176518534,89.62629396707413,0.0020201896291895706
0.0020654093143469836,91.3226805992824,0.006557674573051672,36.82130481763067,91.5112993144033,0.0020632792889411287
0.0021032478603261835,93.2257684110701,0.0066778119565356325,37.58862982334347,93.42184530900796,0.0021010391310065176
0.0021472533980075835,95.0757643060952,0.006817529538674077,38.33454816821759,95.27991606406962,0.0021449513442361517
0.002185249321680683,96.8111299173746,0.006938166596336169,39.03424758268544,97.02268637335769,0.0021828651371084877
0.0022369065761467834,98.623109567086,0.007102178379266037,39.76483777744908,98.84372024943666,0.002234408425357848
0.002270604106609183,100.399145089637,0.007209168038484156,40.480935300141645,100.62711180077758,0.0022680301806129806
0.0023162191212428834,102.153691059341,0.007353995709946154,41.18836823512629,102.39030139187818,0.0023135408206242324
0.002361818960302883,103.961224485353,0.007498775198961654,41.91716571249434,104.20676207647882,0.0023590342496953207
0.002395835836267283,105.73767110123,0.0076067787801486235,42.63342898801594,105.99100120289778,0.002392970397424845
0.0024294409747923833,107.476609994582,0.0077134750949658165,43.334569149815465,107.73771807473463,0.0024264946540441946
0.0024755735522697833,109.18883731673,0.007859946028456561,44.024939206105536,109.45914231459437,0.0024725143678471784
0.002509479217186083,110.893738125273,0.007967596514565814,44.712355212110076,111.17202365641445,0.002506335732123928
0.0025621171679179834,112.526700238405,0.008134722008139597,45.3707655361249,112.81500682893498,0.0025588405412678527
0.0026047077302161835,114.174715596003,0.008269947043436383,46.03524532830841,114.47210736031114,0.0026013213581014753
0.0026449595049978835,115.716025680978,0.00839774642836828,46.65670155457034,116.02208988298351,0.002641467755275683
0.002693893959716983,117.279836463367,0.008553113322101421,47.28723006202958,117.59577590641226,0.0026902719308334964
0.002747206367073783,118.880768640369,0.008722380215459262,47.93272591579678,119.20735864490044,0.002743439692639717
0.002786517540976383,120.519594867806,0.008847193192600016,48.59350065069938,120.85542483293652,0.00278264239807336
0.0028282727642405833,122.096115769425,0.008979766026463852,49.229153878232154,122.44143688827523,0.002824280726103225
0.002865847083097883,123.723682459214,0.009099064488835778,49.885388767555085,124.07825561369985,0.002861748372330815
0.0029013089792722835,125.3126057486,0.0092116560091895,50.52604263783553,125.67617633687442,0.002897108305382804
0.002941598058631083,126.853563263842,0.009339573836153688,51.147356707981096,127.22671545926937,0.0029372800249357067
0.0029805683260973833,128.381868728317,0.009463304435359192,51.763569471257405,128.76451965989378,0.0029761352388857783
0.003020089520566183,129.880156909572,0.009588784227797631,52.36767926593944,130.27240661038408,0.003015538211481365
0.003069759233269483,131.371272976556,0.00974648556563061,52.96889726414738,131.77455115476218,0.0030650571427939238
0.0031127627115572834,132.840171955635,0.009883021609194374,53.56115733251203,133.25367188949534,0.003107928095784354
0.0031615600142903834,134.279861038535,0.010037953045371967,54.14163997073731,134.7043948779189,0.003156572792264883
0.0032150886300995832,135.779738945961,0.010207906400566177,54.746390743011474,136.21628284084406,0.0032099312839100813
0.003259823810460683,137.281234782,0.010349940598212669,55.351793864102405,137.7287474198718,0.0032545221034523657
0.0033184535199351833,138.728123538148,0.010536089925794207,55.93517941058128,139.18848636801715,0.003312959603901282
0.003362542031754183,140.14171216548,0.01067607095081953,56.50513834512153,140.6129445630384,0.0033569013284942472
0.0034039954139846833,141.549120691905,0.010807685439401369,57.07260546297609,142.03095324959378,0.0033982149356954535
0.0034274649448964834,142.946820657925,0.010882201200046335,57.63615808927536,143.43676587471444,0.0034216045739151827
0.0034594403388510833,144.352655011109,0.010983723075852188,58.202990500479146,144.85203440887466,0.003453470239960568
0.003504639617893183,145.641776211882,0.011127230786810856,58.72276416863082,146.15219815081448,0.0034985126794354646
0.0035503869025791833,146.945031025312,0.011272478415688906,59.2482365094058,147.4667427388634,0.0035440991572244806
0.003590756105121483,148.300938789316,0.011400650633760709,59.79493851985222,148.833451290669,0.003584324731482885
0.0036363238767327835,149.631694826571,0.011545328308626587,60.33149935407342,150.17580413118483,0.0036297284350036594
0.0036902316348446833,150.890521992969,0.011716485440631868,60.83905846756511,151.4473429706257,0.00368343943481763
0.0037676091594895833,152.138146120763,0.011962159081379426,61.342100515891644,152.71134319359535,0.0037605294967964025
0.003823354973184183,153.334459856529,0.01213915203985978,61.824454214152496,153.92071192618195,0.0038160645282891426
0.0038786583467080834,154.595163167867,0.012314740250798165,62.33276978928399,155.19478498784875,0.0038711557451839595
0.0039402481084305834,155.74988547725,0.012510287744267101,62.798353824427195,156.36357866889,0.003932505662294255
0.0039932598465092835,156.79608428059,0.012678600012666975,63.220181181933896,157.42221178803757,0.003985307946713644
0.004060347171445583,157.843323968967,0.012891602269339726,63.6424282242875,158.48422266297598,0.004052126207667143
0.004120108289007283,158.81814726251,0.013081343817598123,64.03547697624403,159.47249522749104,0.0041116438843946685
0.0041894463064517835,159.693873868512,0.013301492022984413,64.38856994378403,160.3629027785534,0.004180695009818502
0.004271160326197084,160.525477890935,0.01356093403567574,64.723872685625,161.2111079434466,0.0042620648106705215
0.004348944168634084,161.26638548807,0.013807897735413214,65.02260662878983,161.96772399483504,0.004339514839475752
0.004440903616932083,162.001846906886,0.014099868983759364,65.31914467285642,162.72128149476447,0.004431071901518451
0.004538294566310383,162.703024140471,0.014409085248035466,65.6018593334379,163.44141839084998,0.004528027558941467
0.004647990557187083,163.326450716095,0.014757370019068988,65.8532249287295,164.08559051676227,0.00463722200427273
0.004763978876223183,163.94598879206,0.015125632932008604,66.10302268095859,164.72702401950693,0.004752667040860004
0.004891270261937683,164.528111458661,0.015529783081652142,66.33773454013212,165.3328629174915,0.004879346864117502
0.0050259241658505835,165.044372184589,0.0159573092265756,66.54589086482629,165.87387268318918,0.005013336368249949
0.005166716871313883,165.49288140638,0.016404326066421577,66.72672978305242,166.3479362688247,0.0051534151873833004
0.0053083142101809835,165.865329652608,0.01685389761732462,66.87690091593154,166.74579493897932,0.005294274772219985
0.005467925240592583,166.17245109828,0.01736066263888145,67.00073228282649,167.0810696379314,0.0054530304085907665
0.005623779716213183,166.415984768292,0.017855500598976854,67.09892505857533,167.35187160788553,0.005608025305689176
0.005780948152148083,166.586421167207,0.018354510383070163,67.16764501461786,167.5494486308265,0.005764302591982895
0.005946574659082283,166.721001859967,0.01888037454258625,67.2219079499387,167.7124207447643,0.005928963566623312
0.006116095292431983,166.828668306892,0.019418602553471546,67.26531906133886,167.8490083397665,0.006097467894328795
0.006281145621920083,166.893991058351,0.019942637349596264,67.29165719472712,167.9422765196119,0.006261501442479751
0.0064632471303417835,166.930758470756,0.020520809638835163,67.30648181540882,168.0096732164079,0.006442449912215299
0.006633700577796983,166.955090490534,0.02106199933450542,67.31629248578331,168.0626205707872,0.006611794412048305
0.0068135713367062836,166.946164897028,0.02163308899404245,67.3126936864817,168.08366450094346,0.006790463863090662
0.007000667865429583,166.922811503477,0.022227120472738927,67.30327759820192,168.09138266597654,0.006976276959074746
0.0071794330867849835,166.859746720641,0.02279470005054232,67.27784987776246,168.0577051070997,0.0071537836495045425
0.007378214726382783,166.769760237235,0.023425831756265336,67.24156732765316,168.00022333813268,0.0073511288487930985
0.007584632371675083,166.657870627976,0.02408120778006839,67.19645343719992,167.9219093085354,0.007556013664720737
0.007776391773043183,166.56550646075,0.024690043879412104,67.1592122049744,167.86078509486413,0.007746311481984648
0.007981598154489084,166.451405729994,0.02534157414050284,67.11320679033359,167.77995396278064,0.007949913683419756
0.008199086179013684,166.337288944093,0.026032098618368443,67.0671949022583,167.70110271092912,0.008165656277382933
0.008409908509233585,166.219879676369,0.02670145951681663,67.01985548551198,167.61777365686308,0.008374742254429638
0.008623041120434985,166.094280150204,0.027378155557381073,66.96921375656225,167.52651795780827,0.008586075055942612
0.008822057803667084,165.977949763125,0.02801003352664299,66.92230934449199,167.44221683006944,0.0087833708177791
0.009028954321514683,165.852964303104,0.028666929970809118,66.87191520701153,167.35044314188454,0.008988437016749659
0.009244255621973884,165.705236251286,0.02935051159976708,66.81235125651853,167.23705781309246,0.009201789005187165
0.009460275792706684,165.547221983416,0.03003637564184372,66.74863990371333,167.11334436009554,0.009415807617812976
0.009660766910327785,165.390405197101,0.030672934940290716,66.68541137547112,166.98820335091483,0.009614400088536298
0.009875786773914683,165.238420821149,0.03135562300717912,66.62413127508728,166.87028023203706,0.009827339897927013
0.010105406894040384,165.097928241003,0.032084666888578216,66.5674846667724,166.76630998324143,0.010054688669128013
0.010321304569278385,164.908261968528,0.03277014200745887,66.4910112257105,166.61033036629553,0.010268403598588011
0.010542250232312584,164.736698288121,0.033471644487592454,66.42183674977039,166.47339378391933,0.010487068202033782
0.010764789406122684,164.569624414149,0.03417820636443952,66.35447256378488,166.341181763612,0.010707261542625097
0.010986853160488984,164.40488572416,0.03488325878455252,66.28804992398132,166.21117806247835,0.010926936156048433
0.011212665192999485,164.203699359275,0.03560021198777336,66.20693158165967,166.0448604636425,0.011150269245983028
0.011438127078164584,164.008342393173,0.03631605347317255,66.12816365292736,165.8842906553452,0.011373206281837413
0.011656602775660585,163.81207480372,0.037009713812722354,66.04902856085991,165.72156708956376,0.011589187960916956
0.011884703834908184,163.657581697555,0.03773393467583348,65.98673694045418,165.60260358636774,0.011814635357981199
0.012116592235834485,163.493240698062,0.03847018034877449,65.9204746494586,165.47422162891556,0.012043773948347736
0.012348392988267584,163.327874225217,0.03920614773774957,65.8537988876075,165.3447110020883,0.01227277346687529
0.012578937528390684,163.166687488912,0.03993812665264042,65.78880839552933,165.21915105754948,0.012500479950604257
0.012815694528908085,163.039058171794,0.040689830129283164,65.73734825486734,165.12851693760462,0.0127342684655421
0.013051785159886684,162.875387439301,0.04143941788264022,65.67135621552616,165.00120200399203,0.012967344552121526
0.013280291773949484,162.69515140666,0.04216492638228961,65.5986850471653,164.8557904875473,0.013192881735915414
0.013509484557660083,162.519126232116,0.042892613470570766,65.52771169678917,164.71467585827318,0.01341904508779727
0.013746256441267484,162.33931841515,0.04364436420102426,65.45521318498848,164.57087631658524,0.013652633657700666
0.013983011844430284,162.1392384585,0.04439606260606615,65.37454094646719,164.40643335031208,0.013886151423549771
0.014222338325331783,161.900964645513,0.04515592418292841,65.27846894507084,164.20357493989906,0.014122149698568887
0.014455956564633684,161.674633239598,0.04589766209271195,65.1872121222059,164.0117947153127,0.014352465407987241
0.014699260554534884,161.475319268745,0.04667015226064825,65.10684872915799,163.848887059803,0.014592273569545882
0.014947905499642684,161.276848514744,0.04745959996136552,65.02682532114478,163.68759960562255,0.014837286545702771
0.015198308082465485,161.07875708905,0.04825462816182791,64.94695485830495,163.52688166483,0.015083970831216306
0.015429177018973984,160.89216072355,0.0489876370352424,64.87171920373537,163.3745943523189,0.01531135762588652
0.015675725459735182,160.715665163072,0.0497704283346592,64.80055619375064,163.23499980724705,0.015554130356798914
0.015917263339617384,160.565066457577,0.05053731110328519,64.73983479569505,163.1208229035254,0.015791912119535675
0.016153280649461883,160.401867225304,0.05128666606204148,64.67403286524257,162.99288360329206,0.016024204558008348
0.016390683543955783,160.219508021345,0.052040420252059606,64.60050563420631,162.84561527489114,0.016257806290374915
0.016631499005406183,160.06408935097,0.05280500934216463,64.53784082631111,162.7261950938119,0.016494710210699766
0.01686983319442958,159.858365846007,0.05356172039231392,64.45489310911002,162.5551498125632,0.01672911791561805
0.017124219013338684,159.67165739268,0.05436939536735032,64.37961226072858,162.40590982409503,0.016979252196944458
0.01736174525079288,159.455780915244,0.055123541171267394,64.29257086502638,162.22421156226068,0.017212752199112544
0.01761088901409628,159.273170777056,0.05591457261975569,64.21894245730898,162.07811291053395,0.017457614228560188
0.017866738688729584,159.098683663447,0.056726895336716425,64.14858925310183,161.94125827018266,0.017709004538626717
0.01811591822957478,158.943633602255,0.057518040378899925,64.08607306842923,161.82304347170495,0.017953780240661747
0.01835985765327978,158.788543850485,0.058292548049163305,64.02354088051555,161.7038789125515,0.01819335041160179
0.01862148449722338,158.65703257818,0.05912321327868423,63.97051553552218,161.61146205071006,0.018450227428556832
0.01887684565819158,158.456628379791,0.05993398496475827,63.88971256273173,161.44778969723373,0.018700888897600305
0.019129999075722083,158.299820947207,0.06073774706541761,63.82648780591386,161.32809637561405,0.018949321251482406
0.019392978421454883,158.149108929739,0.06157270648811925,63.76572072047077,161.21609118658571,0.019207330947811116
0.019643009911995482,157.957642629093,0.06236655647058565,63.68852150805029,161.0604061689317,0.01945257575292928
0.01989325145412218,157.758457083707,0.06316107336683792,63.608209896150655,160.8967857394875,0.019697966382282165
0.020152162750609683,157.555754127525,0.06398311673318574,63.526480064218084,160.73084332699793,0.019951795337338565
0.02040496300857018,157.369919541782,0.06478575755221032,63.451551559246504,160.5810469286937,0.020199571061000086
0.020657187572664982,157.209115884693,0.06558657054321132,63.38671552470823,160.4566140796559,0.02044672136488168
0.02091417915813988,157.050286131585,0.06640251882709412,63.32267536825508,160.33486395257813,0.020698479976919835
0.021169235351032982,156.869409258531,0.06721232223952972,63.2497458130397,160.19021470250235,0.02094827995316664
0.021436254542432982,156.718899287925,0.06806010817222471,63.18906019289137,160.07836550467087,0.021209729551968017
0.021704986719633484,156.589021967989,0.0689133328348363,63.13669365749316,159.9877846102446,0.021472787409470086
0.021968682295573083,156.440130993198,0.06975056628844453,63.07666081645744,159.87691452926543,0.0217308477655837
0.022228851958687082,156.282879305488,0.07057660496883147,63.01325693597276,159.75686829324704,0.021985392309502843
0.022495930881779484,156.097863940196,0.07142458054964985,62.938658740687025,159.60943069818808,0.022246629349179547
0.022758403266893983,155.925075847022,0.0722579303723884,62.86899058151926,159.47368160256954,0.022503294138661097
0.02301450127649128,155.753880917046,0.07307104155285982,62.79996478575295,159.3384788082298,0.022753662114858623
0.02327011551324998,155.575292992923,0.07388261675456868,62.72795813474656,159.19554803187603,0.023003494651340512
0.023527083287793384,155.38826684233,0.07469848943874399,62.65254919082746,159.0440995382754,0.02325458721297197
0.023789888214360583,155.207906904146,0.07553289508059485,62.57982806375167,158.90028565938053,0.023511318272860376
0.02406743376023318,155.043751927758,0.07641410218874034,62.51364077727202,158.77525715721734,0.023782377730561553
0.024335263853685483,154.915464349688,0.0772644627354514,62.4619152257942,158.68537304965386,0.02404387913874723
0.024604106813690282,154.77204739469,0.07811803913346664,62.40408950953901,158.58007538056248,0.02430630072661479
0.024881799354530384,154.610674494032,0.07899971295063396,62.3390239559937,158.45766627486108,0.024577288237876693
0.025152929312690083,154.461555011995,0.07986055056779101,62.27889898083639,158.34671558673986,0.02484180079071214
0.025436356709259884,154.294150351811,0.08076043255190013,62.2114014218502,158.21883139831183,0.025118235862627156
0.025698430956402483,154.148598721661,0.08159251828657788,62.152715004573714,158.1099758429358,0.025373776600510153
0.025963231328584382,153.994640598671,0.0824332594682554,62.09063908938415,157.9928390758965,0.025631909194709285
0.02623936624507388,153.848899367144,0.08330998782810957,62.031876224832466,157.88579698404004,0.025901019972058893
0.02651844766405258,153.655257115656,0.08419607133336694,61.953799669032506,157.72995600978408,0.026172928736752962
0.02679317892443678,153.486028305347,0.08506834308508678,61.88556661271591,157.59840692413334,0.026440526950746657
0.027071178536396984,153.30759760551,0.08595099185306042,61.81362335454163,157.45781495127488,0.026711235785678283
0.02733212733442718,153.136489997946,0.0867795042868063,61.74463276717183,157.32203604211708,0.026965274317146504
0.027617288380889983,152.957765879738,0.08768489060932569,61.67257120271036,157.1820446101354,0.027242810149525194
0.027890338636148784,152.776229961023,0.08855182516977238,61.59937592028447,157.0372107501901,0.02750848686439212
0.028156894118150984,152.545127775786,0.08939813882512937,61.50619551919692,156.84032478680862,0.02776777612511437
0.028419184859102782,152.360403349186,0.09023091192765133,61.43171463039179,156.690361817174,0.028022851291119928
0.028679621507226482,152.116118320352,0.09105779828544408,61.33321890676592,156.47875101892816,0.028276059011341295
0.02896005946983688,151.91116671789,0.0919481888167321,61.25058242065325,156.31052314017242,0.028548641200477246
0.02923878555482678,151.721874798669,0.09283314413657502,61.174259918823346,156.15803815988357,0.028819485863875588
0.029493855471026283,151.543226326403,0.09364299112050845,61.10222885480568,156.01282034128693,0.02906727900847491
0.02976794066427658,151.372188134193,0.09451321160907813,61.03326625570662,155.87822644879338,0.029333476531668148
0.030040394356975683,151.247189287037,0.09537825208339779,60.98286672053332,155.79071449860373,0.029598019294852108
0.030329025493970083,151.108126101329,0.09629465594335501,60.92679644405585,155.69108831020225,0.02987819345789464
0.03061622485577638,151.024598196343,0.09720651391709001,60.8931179927655,155.64840125347553,0.030156899904479433
0.030893207925094483,150.911277309344,0.09808593516217498,60.8474270111275,155.57341077750317,0.03042561860795024
0.03117405844685168,150.789763197703,0.09897763556875408,60.798432521313856,155.4904920888151,0.03069801566121205
0.03146501172711498,150.606352515136,0.09990141223359006,60.72448133410283,155.34518316320276,0.03098013315467009
0.03174345181196088,150.416893578461,0.10078545950297578,60.648091490835476,155.19164499147374,0.0312500429494939
0.032032292786253386,150.240079708644,0.1017025295963545,60.57680013852526,155.05261393010133,0.031529958029351254
0.032316437700717786,150.070833305161,0.10260468969977897,60.50855998864091,154.92058804036202,0.031805245738314857
0.032602738341465785,149.906409189296,0.10351369423415387,60.44226418512415,154.79376862380332,0.03208254534975188
0.032884995199437383,149.731528732478,0.10440985975821368,60.371752384935135,154.65544933604997,0.032355853058284985
0.033169688640523685,149.539919850215,0.1053137614336627,60.29449568360669,154.5001124309755,0.03263144445004722
0.03346877958187948,149.391211618445,0.10626337517246734,60.23453652455703,154.39115315157267,0.03292089124787173
0.03376500311427768,149.240530738229,0.10720388488783163,60.17378199365394,154.27963772338177,0.033207480541163334
0.03405043173183668,149.067003260892,0.10811012074858145,60.10381571479166,154.14279907889647,0.033483548331897185
0.03433103466851938,148.905721888687,0.10900103507254903,60.0387870655186,154.01780938918841,0.033754874432002334
0.034623503832883686,148.730897161898,0.1099296246694057,59.96829773567728,153.88048194985123,0.03403759612633632
0.03490967966344848,148.564588959839,0.11083823293144893,59.901242268607085,153.75093116975887,0.03431415688377761
0.035192608670066385,148.388560520906,0.11173653252746077,59.8302676020293,153.6107410624327,0.03458750473714134
0.03548080367335308,148.208193269234,0.11265155166289602,59.75754352615514,153.46673907740205,0.034865863461824444
0.035772866206525485,148.025547960392,0.11357885020571841,59.683900937630064,153.32084608272675,0.03514787868705276
0.036073297729401585,147.817118496465,0.11453272029085003,59.599862177774696,153.14936942149023,0.03543789203863389
0.036371824312155784,147.613913389331,0.1154805421910946,59.517929878578265,152.98290071315753,0.035725983222949405
0.03665577995165828,147.413174214384,0.11638210134651503,59.436991843239625,152.81671909036191,0.03599993581354136
0.036957114901300284,147.221579660907,0.11733883981162839,59.359740919277705,152.6624644963861,0.03629057342725533
0.03726586648636318,147.029956308611,0.11831912609420309,59.282478383631954,152.5091550299035,0.036588276798699595
0.03756093323747308,146.843213139761,0.11925596302897702,59.207183537951636,152.35878126487958,0.03687270222942795
0.03786064591811858,146.659128768865,0.12020755079002649,59.13296071960637,152.21173811384276,0.037161523243663355
0.03815251213568148,146.502797011153,0.12113422603078869,59.06992775489689,152.09224675203228,0.03744270279048222
0.038450499295796185,146.320804846959,0.12208033526415288,58.99654851429386,151.9469128506873,0.03772969761859304
0.03874411189433828,146.146452232465,0.12301255526452404,58.926249540129895,151.8087667307202,0.03801239871835128
0.039035748372405685,145.958273579833,0.12393850108238805,58.85037590738866,151.65586402016612,0.038293118043395774
0.039321782739099885,145.740555829923,0.12484666019664213,58.76259211062496,151.4713343025429,0.03856836844109524
0.03961615868293978,145.48457807271,0.1257813038183338,58.659381878916676,151.24811820355902,0.03885156683768224
0.03989910748328878,145.230363917479,0.12667966625944188,58.55688273152753,151.02492581725966,0.03912369641201025
0.040182508597145686,144.985327686765,0.12757946479593754,58.45808412330365,150.81120186299842,0.0393961867925987
0.04047227298795858,144.753212960178,0.1284994667367685,58.36449546554377,150.6117045109864,0.03967471871942361
0.04076567351196058,144.527284863277,0.12943101340047483,58.273401256873285,150.41903697158347,0.03995666680367715
0.04105910641382758,144.292413422752,0.13036266286390255,58.17870109205361,150.21693098018474,0.04023856651650558
0.041346274371717985,144.101974933892,0.1312744211302046,58.101916293345255,150.0600547270151,0.040514370605719406
0.04163792053016088,143.917438068426,0.1322003976832608,58.02751102918936,149.9098609176235,0.04079439784842496
0.041935597101684985,143.718497367927,0.13314552079784983,57.94729813874817,149.74541836960796,0.04108013441690255
0.04220794219800448,143.517920392321,0.1340102164786642,57.86642550218383,149.5755164806179,0.04134148407227326
0.04250030667132238,143.313171464488,0.13493847368144854,57.78387073448156,149.40402520176852,0.04162196885991031
0.04279789803213138,143.075644490398,0.13588332625201713,57.68809985852847,149.1989813341795,0.04190738737910147
0.04309346012095348,142.808261035646,0.1368217358840273,57.58029084957248,148.9623631375283,0.042190779023297036
0.04339843060536018,142.546499471242,0.13779001717201855,57.47474858680477,148.7327938365817,0.042483107489018825
0.04369678253631118,142.308511292312,0.138737284552788,57.378791753060206,148.52693536331836,0.04276900909149947
0.04399689801652888,142.04787250517,0.13969015120247918,57.27370219408454,148.29753826524487,0.043056518207497216
0.044321377046735284,141.789760983069,0.1407203721233845,57.169631628373416,148.07407844096605,0.0433672745100132
0.044620918093064385,141.531829237788,0.1416714149454794,57.065633548676125,147.84710939776892,0.04365406179856499
0.04492083583720848,141.289577578179,0.14262365378313693,56.96795767952178,147.6364234980769,0.0439411273675009
0.04521750360535588,141.048283514599,0.14356557394700492,56.87066791308632,147.42613478294965,0.04422500118057958
0.045510889901110685,140.786805261514,0.1444970754360264,56.76523988144244,147.19413805529987,0.04450565580658629
0.04579816477949798,140.466420335554,0.1454091731749061,56.63606067929538,146.89952460006793,0.04478038792191019
0.04611196420462518,140.185353895108,0.14640548634968495,56.52273469050754,146.64957591593193,0.04508040026291194
0.04640775716771798,139.894591653624,0.14734462900750459,56.405499354741195,146.38678589216244,0.045363114888768714
0.04669568380888888,139.577602414407,0.14825879609322218,56.27768929348891,146.09527400355296,0.04563823425205503
0.04697402343492618,139.256521545771,0.14914252440589063,56.148229487254866,145.79796065232833,0.04590412110776495
0.04725848583682328,138.983584831317,0.1500456925319139,56.03818140398701,145.5517386066187,0.046175783783601786
0.04754873603501738,138.699418931757,0.15096723691118016,55.923605713284424,145.29440099075342,0.046452897779601966
0.04785308119491078,138.449901290994,0.15193353279384172,55.82300020052879,145.07515565889932,0.04674338637184334
0.048109499042612885,138.149645154086,0.1527476594602959,55.70193692612747,144.7959553753638,0.04698806426008354
0.04840654837249148,137.854198545429,0.15369079108266046,55.58281285351697,144.52724447566936,0.047271438510648085
0.04872143547054558,137.546020489153,0.1546905576189822,55.45855546122649,144.2474600506456,0.04757174168989749
0.04902468796610878,137.217856853209,0.15565338429239536,55.32623988321387,143.94491946881575,0.04786086389995664
0.04932867456550078,136.836512738249,0.15661854174546497,55.172481936062006,143.58647654379212,0.04815060213656325
0.049626388074401284,136.445022823056,0.15756378213622407,55.014633202256185,143.2162964764935,0.04843427996863884
0.04990246263273088,136.03158914978,0.15844031885892054,54.84793674519129,142.81990044419788,0.048697267123902606