File: example/data/02 processed data/test_ID_095.csv
Strain,Stress_MPa,Displacement(mm),Force(kN),True Stress (MPa),True Strain
-0.0001577395519864,0.0442470036957104,-0.00050082307755682,0.008920195945055217,0.0442400241931707,-0.0001577519941779559
-0.0002506905849967,0.746207295210298,-0.0007959426073645224,0.1504353907143961,0.7460202280669329,-0.00025072201313402044
-0.0004159900089616,2.13918827368082,-0.00132076827845308,0.4312603559740533,2.1382983927316808,-0.0004160765568082785
-0.0005616889492529,4.83628809442724,-0.0017833624138779574,0.9749956798365317,4.833571604849197,-0.0005618467555855751
-0.0005993951052545,8.49363466239884,-0.0019030794591830373,1.7123167479396062,8.488543619356378,-0.0005995748143153738
-0.0005896031233497,12.7145445626255,-0.0018719899166352973,2.5632521838253006,12.707048027439408,-0.0005897770076230228
-0.0004754101405829,17.4276339135125,-0.0015094271963507074,3.51341099696412,17.41934863962365,-0.00047552318381317995
-0.0004040128946626,22.2865332229986,-0.001282740940553755,4.492965097756517,22.27752917619918,-0.00040409452986068
-0.0002875544815611,27.4899103022751,-0.0009129854789564925,5.54196591693866,27.482005455369965,-0.0002875958332785182
-0.0001818183205122,32.892314612981,-0.0005772731676262349,6.631090625976969,32.8863341875803,-0.00018183485146684903
-6.8797375358823e-05,38.3848882365146,-0.00021843166676426302,7.738393468481343,38.38224745695049,-6.879974200678379e-05
5.65753399682899e-05,44.019747897957,0.00017962670439932043,8.87438117622813,44.022238330159645,5.657373964420263e-05
0.0001767373032921,49.6598558671705,0.0005611409379524175,10.011426942821574,49.66863261617834,0.00017672168709491335
0.0002901867483542,55.3547020548929,0.0009213429260245849,11.159507934266408,55.37076525588832,0.0002901446523233873
0.0004114976578324,60.9300273918565,0.00130650506361787,12.28349352219827,60.95509995541991,0.00041141301589041514
0.0005301217478262,66.5307199500497,0.0016831365493481848,13.412593141930019,66.56598933159376,0.0005299812829325628
0.0006318315418021,72.054310223597,0.0020060651452216676,14.526148941077157,72.09983640951907,0.0006316320202917544
0.0007482613460773,77.5158165572043,0.0023757297737954275,15.627188617932388,77.57381864644367,0.0007479815381271269
0.0008544728229205,82.920819466199,0.002712951212772587,16.71683720438572,82.99167305288717,0.0008541079688417535
0.0009732202802935,88.309094085892,0.0030899743899318625,17.803113367715827,88.39503828719073,0.0009727470084767276
0.0011024159525272,93.7819560284314,0.0035001706492738594,18.90644233533177,93.88534275281634,0.0011018087382885222
0.0012164877878016,99.2988515261428,0.00386234872627008,20.01864846767039,99.41964736636707,0.0012157484660558287
0.0013290807913239,104.854449508215,0.004219831512453382,21.138657020856144,104.99380954294122,0.0013281983452572612
0.001437980619359,110.188744474311,0.004565588466464825,22.214050886021095,110.34719375333655,0.0014369477153069053
0.0015434442754229,115.345351284364,0.004900435574467707,23.253622818927784,115.52338040650051,0.001542254389498365
0.0016606150215957,120.371238920987,0.005272452693566348,24.26684176647098,120.57112920850727,0.0016592377250327609
0.0017644385799888,125.365472568342,0.00560209249146444,25.273679269777748,125.58667224474011,0.001762883786860252
0.0018697909993037,130.401215376547,0.005936586422789247,26.288885019911874,130.64503839535632,0.001868045116065608
0.0019854026380714,135.443129564937,0.006303653375876694,27.3053349202913,135.7120387116839,0.001983434331077838
0.0020964859874476,140.386043408322,0.00665634301014613,28.301826351117715,140.68036078116074,0.0020942914274073563
0.002212126618242,145.271715436053,0.0070235020129183505,29.286777831908285,145.59307486464678,0.002209683468528687
0.0023237109757149,150.037858768476,0.007377782347894807,30.247632327724766,150.38650338766908,0.0023210153344852633
0.0024206551052392,154.838943154106,0.00768557995913446,31.215530939867772,155.21375483234183,0.002417730039103204
0.0025329626417999,159.567779799915,0.008042156387714681,32.168864407662866,159.97195902498314,0.00252976009873542
0.0026488272763478,164.228592311773,0.008410026602404265,33.10848421005344,164.66360548664466,0.002645325316073372
0.0027584600128952,168.833064690313,0.00875811054094226,34.0367458415671,169.29878394811576,0.002754662444098577
0.0028716280512886,173.356473195416,0.009117419062841303,34.948664996195866,173.85428850671641,0.002867512803880308
0.0029719135545561,177.93142016371,0.009435825535715616,35.870974305003934,178.46021696307594,0.002967506149593338
0.0030881116151684,182.381766570481,0.009804754378159669,36.76816414060897,182.94498182222225,0.0030833531923382153
0.0032075119361603,186.805729309143,0.010183850397308953,37.66003502872323,187.40491091564522,0.0032023788431259142
0.0033160263888066,191.136358280133,0.010528383784460953,38.533089829274815,191.77017148805032,0.003310540497529069
0.0034351428037173,195.378448494832,0.010906578401802427,39.388295216558134,196.0496013661805,0.0034292561777582516
0.0035410482633333,199.562098927768,0.011242828236083226,40.231719143838035,200.26875795160333,0.003534793513164274
0.0036522367891981,203.632728905138,0.011595851805703968,41.052358147275825,204.37644384913014,0.003645583566923836
0.0037658190695141,207.643668944057,0.011956475545707267,41.86096365912189,208.42561743223038,0.003758746124275265
0.0038958875029947,211.429080612825,0.012369442822008171,42.62410265154552,212.25278452575415,0.0038883181863779512
0.0040283427767891,215.04584294708,0.012789988316305392,43.353241938131326,215.91212131519438,0.004020250728442185
0.0041720902729296,218.274643272483,0.013246386616551479,44.00416808373257,219.1853047885073,0.004163411235750466
0.0043284234114602,221.200925837714,0.013742744331386133,44.59410664888315,222.15837710374666,0.004319082730759961
0.0044963409345609,223.846789058405,0.014275882467230857,45.12751267417445,224.85328053911832,0.004486262592808702
0.004681945167944,226.115119340565,0.014865175908222198,45.584808059057906,227.17377793096065,0.004671018953351714
0.0048981639004461,227.918302505376,0.015551670383916368,45.94832978508381,229.03468370695882,0.004886206924570926
0.0051507937388758,229.307963716548,0.016353770120930665,46.22848548525608,230.48908174033352,0.005137573776905167
0.0054310104637485,230.276984516548,0.017243458222401486,46.42384007853608,231.52762122901783,0.0054163157073268825
0.0057361533680716,230.931298129587,0.01821228694362733,46.55574970292474,232.25595547314614,0.005719764284006258
0.0060628096411065,231.428214715271,0.019249420610513136,46.655928086598635,232.83131992667077,0.006044504759482911
0.0064036078186318,231.763370332385,0.020331454824155965,46.72349545900882,233.24749206271792,0.006383191833042436
0.0067477219237009,232.067471004097,0.021424017107750357,46.784802154425954,233.63339776596916,0.006725057944483318
0.0071019159656034,232.324589588542,0.022548583190790793,46.83663726105007,233.97453930054314,0.007076816128302728
0.0074547217937075,232.520955206841,0.02366874169502131,46.87622456969915,234.25433423911514,0.007427072681132538
0.007810182311512,232.680956852719,0.024797328839050597,46.90848090150815,234.4982375461558,0.007779840717499992
0.008171137851885,232.807459839155,0.025943362679734874,46.93398390357365,234.7097616864479,0.008137934853214367
0.008522025041594,232.992665126119,0.02705742950706095,46.97132128942559,234.97823445283152,0.008485917580290672
0.0088765919799005,233.085862906394,0.02818317953618409,46.99010996192903,235.1548710076971,0.008837426636523487
0.0092322382401646,233.19121785351,0.029312356412522604,47.01134951926762,235.34409473224775,0.00918988162668074
0.0095886393954582,233.264959083086,0.030443930080579783,47.02621575115014,235.50165265933006,0.009542960161725043
0.0099533663888497,233.456138253057,0.0316019382845978,47.06475747181629,235.77981273281563,0.009904157894985539
0.0103201893349899,233.711523283244,0.032766601138592935,47.116243093901986,236.12347045329594,0.01026729975677138
0.0106850115056422,233.877065446369,0.03392491153041398,47.14961639398799,236.3760445815693,0.01062833017318337
0.0110602281968507,234.068154130371,0.035116224525000975,47.1881398726828,236.6570013286685,0.010999511158945461
0.0114303752540391,234.293531280103,0.03629144143157414,47.233575906068765,236.9715942622285,0.011365542091983658
0.0118139025926689,234.493750153355,0.037509140731723754,47.273940030916364,237.26403647625636,0.011744663236595879
0.0121795333440764,234.706269447693,0.03867001836744257,47.316783920654906,237.56488228249495,0.012105959621152166
0.0125518840725982,234.821347014785,0.039852231930499284,47.339983558180656,237.76879734028594,0.012473762214144467
0.0129154993764287,234.915492617333,0.04100671052016112,47.358963311654335,237.9495435157456,0.012832805574415686
0.0132806702923582,235.020008608107,0.04216612817823728,47.38003373539437,238.14123185453846,0.01319325529330246
0.0136485809411851,235.104338094592,0.043334244488262695,47.39703455986975,238.31317868269977,0.013556277981581624
0.0140131241500878,235.231342432885,0.04449166917652876,47.422638634469614,238.52766843838882,0.013915848034036737
0.0143927960034013,235.331193653085,0.04569712731079913,47.442768640461935,238.7182675165708,0.014290202943944327
0.0147628220853984,235.456956317747,0.046871960121139915,47.468122393657794,238.93296547263532,0.014654912365735276
0.0151332821423774,235.596199840992,0.04804817080204824,47.496193887943996,239.16154360485763,0.015019916328568968
0.0155086740547429,235.715921533505,0.049240040123808705,47.52032978115461,239.3715629300815,0.015389643660850615
0.0158641744451055,235.934031088048,0.05036875386320996,47.56430066735047,239.67692971476575,0.0157396536496662
0.0162164975643738,236.054322133719,0.05148737976688682,47.58855134215775,239.88229647366035,0.0160864146101453
0.0165754278721472,236.124586160243,0.05262698349406735,47.60271656990499,240.03845220698275,0.016439554847483277
0.0169366436728444,236.242478856478,0.05377384366128096,47.62648373746596,240.24363354125964,0.016794817852361185
0.0172996250217171,236.348480811711,0.054926309443951785,47.647853731640936,240.43722090420607,0.017151690216020195
0.0176674104678223,236.455319458097,0.0560940282353358,47.66939240275236,240.63287264426324,0.01751315597315104
0.0180344975245418,236.583845806251,0.057259529640420206,47.6953033145402,240.85051658779042,0.0178738051028269
0.0184056803184826,236.747151406175,0.05843803501118225,47.728225723484876,241.10464379126847,0.018238345934509435
0.018779313327108,236.915878562878,0.059624319813567896,47.76224111827621,241.36499607857732,0.01860515897699709
0.0191428182630549,237.034314068503,0.0607784479851993,47.7861177162102,241.57181886482422,0.018961899731874118
0.0195105963222721,237.150828145947,0.06194614332321391,47.80960695422292,241.7777822213951,0.019322704624531045
0.0198882515110712,237.237154465587,0.06314519854765105,47.82701034026234,241.95538666136943,0.019693063952248693
0.0202604968305317,237.378980593969,0.06432707743693813,47.85560248774416,242.18839667792798,0.02005798373948875
0.0206329888971156,237.49793464561,0.06550973974834202,47.87958362455498,242.39822689424074,0.020423012167796968
0.0209972083663347,237.581903465243,0.06666613656311267,47.89651173859299,242.57046019637312,0.020779804963643407
0.0213585052211554,237.669141850605,0.06781325407716839,47.914098997081965,242.74539945772867,0.021133609010789308
0.0217198783925644,237.732184133027,0.06896061389639196,47.92680832121824,242.89569826239511,0.02148736261914431
0.0220898753822499,237.789076136495,0.07013535433864343,47.93827774911739,243.0418071956105,0.02184942860209005
0.0224612852181575,237.906295736924,0.07131458056765005,47.961909220563875,243.24997690066638,0.022212745350675772
0.0228396160394033,238.002362007523,0.07251578092510548,47.98127618071664,243.4382445722459,0.022582696613424536
0.0232150951892225,238.078811446247,0.07370792722578143,47.99668838756339,243.60583371650856,0.022949724095117575
0.023578294434836,238.170109203623,0.0748610848306043,48.01509401545041,243.78575416400307,0.02330461995443269
0.0239420278270151,238.190892060913,0.07601593835077294,48.01928383948006,243.89366502677692,0.023659911564533564
0.0242873351158659,238.247205513641,0.07711228899287423,48.030636631550024,244.0335952343694,0.023997087955390645
0.0246437985122545,238.294493112671,0.07824406027640804,48.04016981151448,244.1669745875195,0.02434503854693036
0.0250072923289074,238.373809384633,0.079398153144281,48.056159971942016,244.33489291946975,0.02469972703229044
0.025367018355992,238.469477589945,0.0805402832802746,48.07544668213291,244.51873720531296,0.025050615188566036
0.0257285068569714,238.598027456546,0.08168800927088418,48.10136233523968,244.7367984420216,0.02540309853249485
0.0260876384944178,238.728474472752,0.08282825221977652,48.1276604537068,244.95633661312098,0.02575316073658401
0.0264532893309668,238.832268080839,0.08398919362581958,48.14858524509714,245.15016716995245,0.026109451649432718
0.026821149769826,238.964435075367,0.08515715051919755,48.17523011119399,245.3737359781853,0.02646776755284034
0.0271915255676484,239.049263040415,0.08633309367728367,48.19233142894767,245.54937718830598,0.026828403888033116
0.0275680296730539,239.096726594519,0.08752849421194614,48.20190008145504,245.68815224800673,0.027194874124084622
0.0279353093530597,239.130823096821,0.08869460719596454,48.20877393631911,245.81101661588247,0.02755223640799952
0.0283027242949487,239.167015340495,0.08986114963646212,48.21607029264379,245.9360934361228,0.027909602568713384
0.0286711848876247,239.236532538527,0.09103101201820842,48.23008495976705,246.09572739481334,0.02826785757133832
0.0290387077800336,239.295625379049,0.09219789720160668,48.24199807641628,246.2444611174716,0.02862507303463237
0.0294128089052575,239.387221107691,0.09338566827419256,48.26046377531051,246.42827169649212,0.028988551237845047
0.0298006417143365,239.49808174286,0.09461703744301837,48.282813279360575,246.63527826814988,0.02936523177433651
0.0301759257928335,239.552430652789,0.09580856439224636,48.29377001960226,246.78114702366048,0.029729589397202952
0.03055669111441,239.618888309227,0.09701749428825174,48.30716788314017,246.94084866447034,0.030099133046665855
0.0309213711432505,239.637189400329,0.09817535337982033,48.310857383106324,247.047099873502,0.030452937474005105
0.0312918143469357,239.656491401237,0.09935151055152083,48.31474866648938,247.15577783720246,0.030812205090249678
0.031665676884502,239.671579024263,0.10053852410829385,48.31779033129142,247.2609418040437,0.031174658066860646
0.0320356510086674,239.739142975038,0.10171319195251899,48.33141122376767,247.41934249250335,0.03153321201372154
0.0324127410298778,239.807272371899,0.102910452769862,48.34514611017484,247.58008338837072,0.031898529961952506
0.0327936419918168,239.8978053769,0.10411981332401833,48.36339756398304,247.76492812105263,0.032267404442865966
0.0331719285419633,239.962584816601,0.10532087312073346,48.376457099026766,247.92260653288213,0.03263361243758716
0.0335481178433883,240.002321671726,0.10651527415275784,48.384468049019965,248.05394784185586,0.03299765720140267
0.0339217007133192,240.047308491707,0.10770139976478846,48.393537391928135,248.19012144740051,0.033359048570354
0.0342884697216129,240.058030060352,0.10886589136612096,48.39569886016696,248.28925255550638,0.033713721434244996
0.0346607832275627,240.043604222387,0.11004798674751157,48.39279061123322,248.363703553502,0.034073627323128526
0.0350277721788411,240.066348277901,0.11121317666782049,48.39737581282484,248.4753376331856,0.034428259380368066
0.0353933219162265,240.08420441885,0.11237379708401914,48.40097561084016,248.5815819528475,0.034781375702672285
0.0357706798733153,240.140613313599,0.11357190859777608,48.41234764402156,248.73060631702134,0.03514576786180423
0.036146193411847,240.201913604312,0.11476416408261422,48.4247057826293,248.88429843134924,0.0355082472136403
0.0365279723912784,240.274464256249,0.1159763123423089,48.43933199405979,249.05120325293046,0.03587663988244277
0.0369144078130798,240.385510804205,0.11720324480652836,48.46171897812773,249.25919958238694,0.0362493875700228
0.0373003876022211,240.451746350429,0.11842873063705198,48.47507206424649,249.42068968893096,0.03662155712010947
0.0376927849016235,240.500551580967,0.1196745920626546,48.48491119872295,249.5656871404302,0.036999772633567324
0.0380775349418279,240.480701191308,0.12089617344030357,48.480909360167686,249.63761349375528,0.037370478429803455
0.0384597273034123,240.467932909726,0.12210963418833405,48.47833527460076,249.71626403464933,0.03773858390313066
0.0388383624330092,240.445902039315,0.1233118007248042,48.47389385112591,249.78442712824972,0.03810312969043065
0.0392187531140823,240.424980777412,0.1245195411372113,48.469676124726256,249.85414874097933,0.03846923193321895
0.0395880562029671,240.447661666059,0.12569207844442054,48.4742485918775,249.96651720996695,0.038824534880192774
0.039974294529014,240.489792781116,0.12691838512961945,48.48274222467298,250.10320258896988,0.039195996048791204
0.0403653378025844,240.552844869226,0.12815994752320548,48.49545352563596,250.26284171174495,0.039571937815316725
0.0407569870661837,240.569223802421,0.12940343393513323,48.49875551856807,250.3741005454581,0.03994832056182117
0.0411421495023027,240.592435155934,0.13062632466981108,48.503434927436295,250.49092509224252,0.040318331225400426
0.0415317221339767,240.618763486522,0.13186321777537602,48.508742718882836,250.61207511186527,0.040692439376967496
0.041924973092591,240.642936679119,0.13311178956897643,48.51361603451039,250.73188532431314,0.04106993794863009
0.04231272274225,240.640123526316,0.13434289470664373,48.513048902905304,250.82226235374577,0.04144201609970395
0.0426968161610104,240.620313986085,0.135562391311208,48.50905529959474,250.89403529695346,0.04181044935234731
0.0430777482753407,240.603522043432,0.13677185077420673,48.505670043955895,250.96818000017933,0.042175716169826676
0.0434700746458162,240.603167092763,0.13801748700046643,48.50559848590102,251.06220472630517,0.042551769256929814
0.043858136477986,240.647544272655,0.13924958331760554,48.514544925367254,251.2018971124573,0.04292359562766804
0.0442507846544302,240.645338935627,0.14049624127781588,48.5141003294224,251.2940840069598,0.04329967579963454
0.0446336700583873,240.62213452971,0.14171190243537968,48.50942232118953,251.36198349105396,0.04366626898996761
0.0450312341938884,240.583187800126,0.14297416856559567,48.50157066050541,251.4169456730657,0.04404677415085604
0.0454155191411479,240.565770573893,0.14419427327314457,48.498059347696824,251.4911899320966,0.044414432356907126
0.045808608919922,240.56659473809,0.14544233332075235,48.498225499198945,251.58661579564455,0.044790374636961484
0.0461989956231513,240.557930311376,0.14668181110350537,48.496478750773406,251.67146508094558,0.045163591930161354
0.0465950452341167,240.574218484956,0.14793926861832052,48.49976244656713,251.78378507742477,0.04554208079047093
0.0469893416639285,240.581695967456,0.14919115978297298,48.50126990703913,251.88647147735813,0.04591875195494972
0.0473833774155073,240.632665974445,0.15044222329423568,48.51154546044812,252.03465440481182,0.04629503240650297
0.0477756456548362,240.644052794347,0.15168767495410493,48.513841043340356,252.14097778959342,0.046669484407132054
0.0481698081044581,240.674565948934,0.15293914073165446,48.5199924953051,252.2678136063179,0.047045603407329994
0.0485721524023077,240.66162712441,0.15421658387732695,48.51738402828106,252.3510803544842,0.047429383872801
0.0489707436365637,240.661061982377,0.15548211104608975,48.5172700956472,252.44641315201912,0.047809439260279744
0.0493775958084094,240.630547155502,0.15677386669169982,48.51111830654921,252.5123050521028,0.048197222517517097
0.049785509506939,240.612105531421,0.15806899268453134,48.507400475134475,252.59110179884019,0.048585866642055185
0.0501916215807879,240.574474223356,0.15935839851900158,48.49981400342857,252.64929719557168,0.04897264426253449
0.0506022122377312,240.540319190983,0.16066202385479655,48.49292834890218,252.71219147441676,0.04936353522533316
0.0510106230755604,240.504826738908,0.16195872826490426,48.48577307056386,252.7731278035394,0.04975219943227745
0.0514184490740624,240.427594882369,0.1632535758101481,48.4702031282856,252.79000892582738,0.05014015639978652
0.0518281760468604,240.356440940335,0.16455445894878176,48.45585849357154,252.8136768753875,0.05052977022166299
0.0522310222016286,240.31753837435,0.1658334954901708,48.448015736268964,252.86956905662143,0.0509126930596003
0.0526374449619584,240.311601600928,0.1671238877542179,48.44681888274709,252.96099030391693,0.051298867085883534
0.0530430716860056,240.293162682913,0.16841175260306776,48.44310159687526,253.03905013675973,0.0516841361006818
0.0534469037664838,240.231178608955,0.16969391945858606,48.43060560756533,253.07079129377678,0.05206755315002116
0.0538529090304498,240.124503253863,0.1709829861716781,48.40909985597879,253.05590628357524,0.05245288538089233
0.0542533326713452,240.061933073465,0.172254331231521,48.396485707610545,253.08609299022592,0.052832774817003304
0.0546577879843124,240.013458819071,0.17353847685019186,48.386713297924715,253.13206356458528,0.05321634272933922
0.0550676513947826,239.980047301021,0.17483979317843473,48.37997753588583,253.19518488749705,0.05360488941695665
0.0554765968106722,239.987452084614,0.1761381948738842,48.38147034025818,253.30113920353267,0.05399241545092188
0.0558887579338011,239.939626495422,0.1774468064398185,48.37182870147708,253.34955419935127,0.054382836869401596
0.0563043344663771,239.901104055638,0.1787662619307473,48.36406257761662,253.4085760572398,0.054776339281121356
0.0567108330566783,239.890767432422,0.1800568949549536,48.36197871437628,253.49517269612053,0.05516109619301087
0.057127366751513,239.841170312839,0.18137938943605375,48.35197993506835,253.5426648114127,0.05555519797456042
0.0575531992391782,239.817181223917,0.18273140758439077,48.34714373474167,253.6194272358752,0.05595793728211295
0.0579738182393248,239.77066760525,0.18406687290985624,48.337766589218404,253.67108870811833,0.05635558666424226
0.0583953613842975,239.70967113881,0.18540527239514457,48.3254697015841,253.70760401227193,0.056753951141107734
0.0588162580915089,239.641149544872,0.18674161944054074,48.311655748246196,253.73594524584905,0.057151546458348745
0.0592366635806863,239.596811724551,0.188076406868679,48.302717243669484,253.78972745568325,0.05754852000928951
0.0596642261829887,239.512349838486,0.18943391813098912,48.28568972743878,253.80266885286855,0.05795209019057649
0.0600939676894919,239.459416352881,0.19079834741413676,48.27501833674081,253.8494827821356,0.058357552958577856
0.060527562869036,239.40341773112,0.1921750121091893,48.26372901459379,253.89392314890245,0.05876648513184724
0.0609637432053506,239.315405821473,0.19355988467698815,48.24598581360896,253.90496876705757,0.05917768676271113
0.0613862080130923,239.268714560243,0.19490121044156805,48.236572855344996,253.9565136432633,0.0595757971809094
0.0618037990448687,239.161732811636,0.1962270619674581,48.21500533482582,253.94283648554895,0.0599691590898982
0.0622153465701685,239.082685093879,0.197533725360285,48.199069314926014,253.95729720592115,0.0603566768119484
0.0626295907695815,238.953940740216,0.19884895069342123,48.17311445322755,253.91952826155458,0.06074658216210508
0.0630573277548715,238.858914860617,0.20020701562171697,48.15395723590039,253.92071974215585,0.06114902806073242
0.0634831160744983,238.82381670358,0.20155889353653209,48.14688144744173,253.98509678072807,0.06154947972065954
0.0639157767756296,238.822153704661,0.20293259126262395,48.14654618685966,254.0866571699232,0.061956230620597144
0.0643510435611456,238.835032661285,0.20431456330663728,48.14914258451506,254.204316251999,0.06236526466409727
0.0647846923271775,238.794221650152,0.20569139813878853,48.140915084670645,254.26443182926494,0.06277261189397909
0.0652254077334794,238.707047936717,0.2070906695537971,48.12334086404215,254.27681246724455,0.06318642722056213
0.0656589870169414,238.619380715974,0.20846728377878893,48.10566715234036,254.28688753639474,0.06359337495598502
0.0661014353348541,238.54602805005,0.20987205718816176,48.090879254890076,254.3142628975867,0.06400847631505582
0.0665433296274875,238.521209658446,0.21127507156727282,48.08587586714271,254.39320513589504,0.06442288597785335
0.0669807258948113,238.47005116943,0.21266380471602586,48.07556231575709,254.44294830093125,0.06483290832779555
0.0674184343717492,238.386632106782,0.2140535291303037,48.05874503272726,254.45828561857542,0.06524305511872579
0.0678633738051566,238.274249933033,0.21546621183137218,48.03608878649945,254.4443444243817,0.06565980520589772
0.0683047718983965,238.194734780453,0.21686765077740885,48.02005853173932,254.46457180703086,0.0660730667746648
0.0687581584744079,238.122467763715,0.21830715315624508,48.00548950116495,254.49533013852962,0.0664973748999614
0.0692049968892039,238.073671289883,0.21972586512322237,47.99565213204041,254.5495589709007,0.06691537875581009
0.0696498727905165,238.03325969707,0.2211383461098899,47.987505154929316,254.61224595488292,0.06733137323400941
0.0700953288966822,237.960370847745,0.22255266924696596,47.9728107629054,254.64028130669413,0.06774773693212599
0.07053589853758,237.851024362686,0.22395147785681646,47.95076651151749,254.62806008419184,0.06815936285019365
0.070985748699433,237.691737270146,0.22537975212069977,47.918654233661435,254.56446319993623,0.06857948484060182
0.0714339232891397,237.583085742254,0.22680270644301853,47.89675008563841,254.55457766396327,0.06899786654433981
0.0718766789889971,237.449834755625,0.2282084557900658,47.869886686734,254.51694030434547,0.06941101777466993
0.072330568603215,237.39281489816,0.22964955531520762,47.85839148346906,254.56357218206168,0.06983438134785722
0.0727812247420081,237.358976825121,0.2310803885558757,47.8515697279444,254.63425386196323,0.0702545516595596
0.0732379789283001,237.336133846187,0.2325305830973528,47.8469645833913,254.7181526157383,0.07068022743394958
0.0736880470455697,237.301096469207,0.23395954936968377,47.83990104819213,254.7873508297952,0.0710994949060631
0.0741490196695988,237.286633688886,0.23542313745097618,47.836985351679424,254.88120495761612,0.0715287384816124
0.0746113578462278,237.206351199486,0.23689106116177325,47.82080040181638,254.9046391522288,0.07195906862786929
0.0750757436070625,237.128440059677,0.2383654859524234,47.80509351603089,254.93103402754002,0.07239111826685599
0.0755441602545309,237.029465483104,0.23985270880813558,47.78514024139377,254.93565740860538,0.07282672909146916
0.0760074209473299,236.918548005355,0.24132356150777243,47.762779277879574,254.9261158138282,0.07325735850700864
0.0764748881375836,236.826385188745,0.24280776983682792,47.74419925405099,254.93765650408258,0.07369171022793122
0.0769373437202014,236.741252320038,0.24427606631163945,47.727036467719664,254.9554954225357,0.0741212198061584
0.0774075806693088,236.666222364736,0.24576906862505546,47.71191042873078,254.9859820641349,0.07455776731649598
0.0778813241505086,236.61953368795,0.24727320417786477,47.702497991490716,255.0477762914434,0.07499737751239108
0.0783575741111179,236.545828959854,0.24878529780279934,47.68763911830656,255.0809862832516,0.07543911888783686
0.078824752900018,236.478774342309,0.2502685904575571,47.674120907409495,255.1191552959406,0.0758722568663508
0.0792943912051336,236.389781575106,0.25175969207629917,47.65617996554137,255.13416539221856,0.07630748613885129
0.0797582706085434,236.259567964658,0.2532325091821253,47.62992890167506,255.10322252024073,0.07673719257330011
0.080223692199745,236.080450382683,0.25471022273419036,47.5938187971489,255.01969576856055,0.07716814209641522
0.0806929202333657,235.939673690858,0.2562000217409361,47.56543821607698,254.97833495988075,0.07760242821212725
0.0811674552282828,235.785770908688,0.2577066703497979,47.5344114151915,254.92390191238508,0.07804143436435118
0.0816373300460332,235.766574307514,0.2591985228961554,47.53054138039482,255.0139279480791,0.07847593943696983
0.0821064885250828,235.739097160871,0.26068810106713786,47.5250019876316,255.09480663682345,0.07890959381173945
0.0825908535624047,235.722404901769,0.2622259600606349,47.521636828196634,255.19091952638888,0.07935710676053656
0.0830739766604691,235.642977802739,0.2637598758969894,47.50562432503219,255.2187770409272,0.07980327285174013
0.083559344538124,235.550675061255,0.2653009189085437,47.487016092349,255.2331350748861,0.0802513116417147
0.0840506061296041,235.466819926781,0.26686067446149303,47.470110897239046,255.25794886503726,0.08070458654916737
0.0845405616272519,235.417826989548,0.26841628316652477,47.46023392109288,255.3201823003116,0.08115645180922128
0.0850350634321935,235.365488914383,0.2699863263972143,47.44968256513961,255.3798081939668,0.0816123029976224
0.085532761005863,235.295670598144,0.271566516193615,47.435607192585834,255.4211589571293,0.08207089044813948
0.0860402153385851,235.206677678915,0.27317768370000767,47.41766622006927,255.44391087548203,0.08253825152463727
0.086541675789598,235.10913192017,0.27476982063197364,47.39800099510628,255.45587018997918,0.0829998778154259
0.0870441194481436,235.001664508805,0.2763650792478559,47.376335564975086,255.45717746482197,0.08346219558415216
0.0875488353627521,234.893539994785,0.2779675522767379,47.35453766294865,255.45819585556242,0.08392638905314578
0.0880469018041484,234.809576283231,0.27954891322817116,47.33761057869937,255.48383198891432,0.08438425578048747
0.0885526598894461,234.717029889427,0.2811546951489914,47.31895322570848,255.5018472074864,0.08484897892322908
0.0890532122309209,234.618803950457,0.28274394883317383,47.299150876412135,255.51236209202185,0.08530870614632227
0.0895599321395246,234.473911956193,0.28435278454299057,47.26994065036851,255.47337959947853,0.08577388273726547
0.0900667714227923,234.333957330604,0.28596199926736554,47.24172579784977,255.43966030209788,0.08623895255089425
0.0905690521072259,234.207753790089,0.2875567404404422,47.21628316408194,255.4197280470199,0.08669962616534808
0.0910744975942428,234.078961472174,0.2891615298617209,47.19031863279028,255.39758528563436,0.08716298829077816
0.0915809495132979,234.000454146591,0.2907695147047208,47.17449155595275,255.43043792387877,0.08762705780648251
0.092089696114216,233.874337169769,0.2923847851626358,47.149066373425434,255.4117538086467,0.08809301324819833
0.0925937491357753,233.800459177462,0.29398515350608656,47.13417257017633,255.44892024236898,0.08855445587193343
0.0930895367712464,233.689337984664,0.2955592792487073,47.11177053770826,255.4433702060356,0.08900812420272146
0.093594476785855,233.596891700084,0.2971624637950896,47.093133366736936,255.4602705575554,0.08946995592642085
0.0940993702484798,233.460280388111,0.2987655005389233,47.06559252624317,255.42874575066574,0.08993153191181143
0.0946126809688686,233.35989931115,0.3003952620761578,47.04535570112784,255.43870501560312,0.09040058468603486
0.0951425941332832,233.324765123914,0.30207773637317414,47.038272648981064,255.5238885533422,0.0908845777429616
0.0956676990237212,233.277404400303,0.3037449444003148,47.02872472710109,255.5945169135061,0.09136394823171068
0.096194183247411,233.232478983686,0.3054165318105299,47.0196677631111,255.6680868062906,0.09184434732808933
0.0967155446257684,233.119760102406,0.30707185418681465,46.99694363664505,255.66606466373867,0.0923198446835471
0.0972409259781215,233.014399727957,0.3087399399805358,46.97570298515613,255.67293572373967,0.09279877976674968
0.0977781092393026,232.907214720379,0.31044549683478573,46.95409448762841,255.6804418039299,0.09328823636214749
0.098319916187514,232.795659584121,0.3121657338953569,46.931604972158794,255.6841093232488,0.09378166329749459
0.0988483124305827,232.668187218104,0.31384339196710004,46.90590654316977,255.66704488089647,0.09426264262932105
0.0993801053845572,232.523378442959,0.3155318345959691,46.87671309410053,255.63157629699353,0.09474648039616898
0.0999104782541668,232.393668905636,0.3172157684569796,46.85056365137621,255.6122315092386,0.095228793087213
0.100451480162746,232.28264949435,0.31893344951671854,46.82818213806097,255.6157854521818,0.09572053210988721
0.100986716040739,232.180851062333,0.3206328234293463,46.80765957416634,255.62803273866194,0.0962067923096623
0.101526775622642,232.026035895188,0.3223475126018883,46.7764488364699,255.5828911801298,0.09669719529222796
0.102062592086338,231.914596861305,0.32404872987412314,46.75398272723909,255.5844017596279,0.0971835077441829
0.102611065600785,231.793658503464,0.3257901332824924,46.72960155429834,255.5782528020089,0.09768106303890842
0.103161426887325,231.694495444863,0.32753753036725686,46.709610281684384,255.59643019689392,0.0981800821352434
0.103709615676998,231.596760307135,0.32927802977446863,46.68990687791842,255.61557131062582,0.09867688397855454
0.104256506199253,231.44583261603,0.33101440718262826,46.659479855391645,255.57556649895443,0.09917226343933558
0.104808608589045,231.312150544034,0.3327673322702179,46.63252954967726,255.55565519229393,0.09967211507122384
0.105360892679045,231.219562525468,0.33452083425596785,46.61386380513435,255.58106203800958,0.10017188135718368
0.105913683574599,231.139196968976,0.3362759453493518,46.59766210894556,255.62000073843504,0.1006718562703
0.106467117494302,231.0196649747,0.33803309804440884,46.57356445889952,255.61566278905565,0.10117216248429306
0.107022600955704,230.872673316789,0.33979675803436016,46.54393094066466,255.5812673047483,0.10167406991890461
0.107577603948201,230.702621252136,0.34155889253553817,46.50964844443062,255.52105647101013,0.1021752917673332
0.108137477743144,230.525756652187,0.34333649183448217,46.4739925410809,255.45423053138433,0.10268065801363904
0.108689341655983,230.375640795958,0.345088659757746,46.44372918446513,255.41501752764592,0.10317854437933068
0.109240915353049,230.226992934698,0.3468399062459306,46.413761775635116,255.37720038186433,0.10367592134300536
0.109795550608655,230.17190307969,0.34860087318247956,46.402655660865506,255.44375391296654,0.10417580971858051
0.110355656070732,230.089857938226,0.35037920802457406,46.386115360346366,255.48157516622044,0.10468037487817396
0.110914989241827,229.937645124416,0.35215509084280067,46.35542925708227,255.44117655968165,0.10518399039580335
0.111474010399813,229.760916694294,0.35392998301940626,46.31980080556967,255.3732875113443,0.10568707169243181
0.112039445667835,229.532290791214,0.3557252399953761,46.273709823508746,255.24896141432993,0.10619566792212175
0.112599098144655,229.380849844604,0.3575021366092796,46.24317932867217,255.20892666876094,0.1066988080750988
0.113175951740099,229.313202355455,0.35933364677481433,46.22954159485973,255.26594227860352,0.1072171476156462
0.113732890542419,229.239294657238,0.3611019274721803,46.21464180289918,255.31134226451098,0.1077173376578762
0.114320789808544,229.20014644739,0.3629685076421272,46.206749523793825,255.40248821348962,0.10824506217811866
0.114911025270703,229.105229889799,0.36484250523448203,46.18761434578348,255.43194675131593,0.1087746037645602
0.115509347225956,228.963821407673,0.3667421774424103,46.15910639578688,255.4112829568337,0.10931111426005499
0.116098850101551,228.793935355583,0.3686138490724244,46.12485736768553,255.35664816057476,0.10983943539636633
0.116691567658007,228.593264721406,0.37049572731417224,46.08440216783545,255.26817113780865,0.11037035631546764
0.117286326760368,228.390496111073,0.3723840874641684,46.04352401599232,255.17757846691887,0.11090282274487984
0.11787516144269,228.191306181251,0.37425363758054075,46.00336732614021,255.08939323718428,0.11142970610346647
0.118464961860827,228.0429152746,0.3761262539081257,45.97345171935937,255.0580105352373,0.11195717545007043
0.11905403160154,227.868477392167,0.3779965503348895,45.938285042260866,254.99713830060887,0.11248371377760545
0.119643404148101,227.730421573267,0.37986780817022064,45.91045298917063,254.97686443837478,0.11301024545693422
0.120236479567249,227.570668702991,0.38175082262601556,45.87824681052299,254.93296476060337,0.11353980549032693
0.120834942622245,227.412131920342,0.3836509428256279,45.84628579514095,254.89146383253896,0.11407389205561559
0.121434140148826,227.244569876897,0.38555339497252256,45.81250528718244,254.8398188233878,0.11460834846448108
0.122036631674755,227.02658758345,0.38746630556734707,45.768560056823524,254.732147632748,0.11514545511902724
0.122635596748783,226.778176707566,0.389368019677386,45.71848042424531,254.58925373769932,0.11567913222400464
0.123231951894381,226.515452325843,0.39126144726465967,45.66551518888995,254.42939365019524,0.11621020108420897
0.123822384550232,226.227384971063,0.3931360709469866,45.6074408101663,254.23939922874334,0.11673571812210441
0.124411226432441,226.028294390335,0.39500564392300014,45.567304149091534,254.1487517038694,0.1172595443764555
0.12500582217839,225.846463308702,0.39689348541638825,45.53064700303432,254.0785861406879,0.11778821091267186
0.125596814614198,225.763861629886,0.3987698864000786,45.513994504585014,254.11908350560023,0.11831339686929551
0.126203644833407,225.655213431366,0.40069657234606726,45.492091027763394,254.13372384206477,0.1188523702329015
0.126811077148907,225.460277071771,0.4026251699477797,45.452791857669034,254.05113766153332,0.11939158759734331
0.127419423856052,225.16251304788,0.4045566707429651,45.39276263045261,253.85259073442165,0.11993132541177018
0.128031904682926,224.909541600149,0.40650129736829,45.34176358659004,253.70513859257983,0.1204744369692481
0.128649194390471,224.659455973725,0.4084611921897454,45.29134632430296,253.56171399694622,0.12102151446566045
0.129268898157817,224.447859326127,0.41042875165106896,45.248688440147205,253.46198679509615,0.12157043055340629
0.129885385575279,224.20286865869,0.4123860992015108,45.199298321591904,253.3235447015076,0.12211619888556802
0.130483178108736,223.843451202527,0.4142840904952368,45.12683976242945,253.05125611426053,0.1226451325798323
0.13108763378077,223.515688632586,0.41620323725394476,45.060762828329345,252.81583136831105,0.12317967758125274
0.131673918573776,223.249389629451,0.4180646914717388,45.00707694929733,252.64551158116456,0.12369788048735725
0.132283791311509,223.03265747749,0.42000103741404105,44.96338374746198,252.53626299489355,0.12423664739967386
0.132883453224601,222.779492561274,0.4219049639881081,44.91234570035284,252.3832008404404,0.12476611111017671
0.13350816676542,222.51948122313,0.42388842948020844,44.859927414583005,252.22764923082238,0.12531739584943413
0.134112445353155,222.181469627445,0.4258070139962671,44.79178427689291,251.9787698313394,0.12585035854946366
0.13471641236667,221.671560247951,0.42772460926417727,44.68898654598692,251.53435756827707,0.12638276276825375
0.135300770851883,221.281070211351,0.4295799474547285,44.61026375460836,251.22056958587643,0.12689761217330756
0.135884017868976,220.930415953296,0.43143175673399875,44.53957185618447,250.95132854249397,0.12741121814038764
0.136495596975855,220.68396676212,0.4333735203983396,44.48988769924339,250.80635654831534,0.12794949010661208
0.137119708126341,220.505652395138,0.43535507330113266,44.45393952285982,250.7413230917677,0.12849849341843986
0.137756388935356,220.222625421956,0.43737653486975525,44.39688128506633,250.55969906194815,0.1290582433111581
0.138398648997256,219.881008176319,0.4394157105662878,44.32801124834591,250.31224264807614,0.1296225810370529
0.139045271455105,219.516423381515,0.44146873686995836,44.25451095371343,250.0391440594515,0.13019043034338926
0.139692942990634,219.044899967925,0.44352509399526296,44.15945183353369,249.64392669153347,0.1307588778718184
0.140335264377163,218.532930892461,0.44556446439749253,44.056238867920136,249.2008075243708,0.1313223107288732
0.140982570895425,218.078352283824,0.44761966259297437,43.96459582041892,248.82359904543569,0.13188979547442276
0.141619919597879,217.631017463081,0.44964324472326583,43.87441312055713,248.45190465820716,0.13244823587013063
0.14226506470172,217.166859336689,0.45169158042796104,43.7808388422765,248.06211663129238,0.1330131899947344
0.142917802154965,216.67495417162,0.4537640218420138,43.681670760998585,247.6416624038557,0.13358446810158903
0.143571367661747,216.055569540912,0.4558390923260467,43.55680281944786,247.07496315083839,0.13415614413068103
0.14421775103589,215.397653880941,0.4578913595389507,43.424167022397704,246.46181910205735,0.13472121665949047
0.144882152623704,214.790091229805,0.46000083458026014,43.301682391928686,245.90934200942093,0.13530170823647136
0.145532551760237,214.201076818692,0.46206585183875243,43.18293708664831,245.3743061179068,0.13586963958337553
0.146193360301743,213.725944288954,0.46416391895803394,43.08715036865313,244.9712582682193,0.13644633032666356
0.146828057437229,213.058086604859,0.466179082363202,42.95251025953958,244.34099158234332,0.13699992057818514
0.147465741294241,212.13133987011,0.46820372860921516,42.765678117814176,243.41344515579635,0.13755580742561996
0.148101924670562,211.349385613303,0.4702236108290343,42.60803613964189,242.65063640057397,0.13811007851249785
0.148748207696803,210.56533681613,0.4722755594373495,42.449971902131814,241.886553270603,0.1386728344661317
0.149415938877792,209.928177013604,0.4743956059369896,42.321520485942564,241.29479267899495,0.13925393412411227
0.150086653096388,209.234154746293,0.4765251235810319,42.18160559685267,240.63740874561586,0.13983729005504925
0.150761909646422,208.382035675231,0.4786690631273898,42.009818392126576,239.79810930963765,0.14042425312628748
0.151465770322527,207.509175082792,0.4809038207740232,41.83384969669087,238.93971213569924,0.14103571367309564
0.152168678018338,206.49281163509,0.4831355527082231,41.62895082563415,237.91454980189133,0.14164597344597912
0.152850192822686,205.403207275891,0.485299362212028,41.409286586819626,236.79912711440906,0.14223730467786463
0.153516618041721,204.275217224435,0.4874152622824642,41.1818837924461,235.6348577224682,0.1428152051527093
0.154167761004277,203.047346094843,0.4894826411885795,40.934344972720346,234.35070082014548,0.14337953100744824
0.154821879909586,201.895516973876,0.49155946871293554,40.7021362219334,233.1533604570892,0.1439461155526683
0.155480661757128,200.684084037274,0.4936511010788813,40.45791134191444,231.88657822751247,0.1445164147697761
0.156134229454951,199.388357036281,0.49572617851946943,40.196692778514254,230.51970452442941,0.14508187895476857
0.156761153743098,198.011093193276,0.4977166631343361,39.91903638776444,229.05154061618603,0.14562399106935434
0.157404978289599,196.528041812729,0.4997608060694768,39.620053229446164,227.46253396755898,0.14618041141809257
0.15807709841594,195.095384290443,0.5018947874706094,39.33122947295331,225.93549655341903,0.1467609558774775
0.158773132506855,193.562645441169,0.5041046957092646,39.02222932093967,224.29519299417714,0.14736180102712507
0.159498285797263,191.934599509513,0.50640705740631,38.69401526111782,222.5478391164645,0.14798739931413557
0.160193269928555,190.323892997104,0.5086136320231621,38.369296828216164,220.8124997618425,0.14858660324740935
0.160875399983711,188.470055112349,0.5107793949482824,37.99556311064956,218.79025061350018,0.1491743756676195
0.161558184784715,186.665800801647,0.5129472366914701,37.63182544161204,216.8231887405463,0.14976236649341004
0.16222399721079,184.570948843228,0.5150611911442582,37.209503286794764,214.51278593356466,0.15033540853620858
0.162947572284221,182.352475675784,0.5173585420024016,36.76225909623806,212.06636888717048,0.15095779279918614
0.163735460911404,179.826175067437,0.5198600883937077,36.2529568935953,209.27009672603864,0.1516350562218854
0.164137913406899,178.609475230265,0.5211378750669043,36.00767020642142,207.92606180926188,0.15198082459910423
0.164358040563051,177.918529535278,0.5218367787876869,35.868375554312045,207.1608704295556,0.15216989699704625