File: example/data/02 processed data/test_ID_130.csv
Strain,Stress_MPa,Displacement(mm),Force(kN),True Stress (MPa),True Strain
0.0006480253801972997,-1.24752732028509,-2.7481272811976213e-05,-0.2515015077694741,-1.2475165222886715,-8.655556455091057e-06
0.0006287711925744998,-1.05363200394045,-8.861331851421851e-05,-0.2124122119943947,-1.053602597380336,-2.791009610180932e-05
0.0005881641024177998,-0.701891520227192,-0.0002175408297617,-0.1415013304778019,-0.7018434288685423,-6.851914415827508e-05
0.0005627924144637998,-0.18873967858405,-0.0002980959390158,-0.0380499192025444,-0.1887219581016194,-9.389289252903314e-05
0.0005362737874019998,0.61918772254517,-0.000382292579937,0.1248282448651062,0.6191131679398417,-0.0001204143613093
0.0005010199651632998,1.92815981330029,-0.0004942234655449,0.3887170183613384,1.927859674142793,-0.0001556730504504
0.00046558855949499977,3.56428881462152,-0.0006067181785417,0.7185606250276985,3.563607706332574,-0.0001911106001656
0.0004407926001953998,5.4034548046129,-0.000685445349318,1.0893364886099606,5.4022882619464205,-0.0002159116062311
0.00043423831204539976,7.36887162108791,-0.0007062552141942,1.485564518811323,7.367232470220156,-0.0002224673311695
0.0004556004127976998,9.3612738225369,-0.0006384305443057,1.887232802623439,9.359391453043385,-0.000201100705787
0.00046967827740169977,11.3185712100479,-0.000593733324188,2.281823955945657,11.316454607556686,-0.0001870201089619
0.00048151321430769977,13.2922214479976,-0.0005561573995114,2.679711843916316,13.289893080339567,-0.0001751830285362
0.0005123579784082998,14.9988699791831,-0.000458225273492,3.023772187803313,14.996705298459233,-0.0001443333363398
0.0005487711756722998,16.6742418211067,-0.0003426133721788,3.361527151135111,16.672442508281865,-0.000107915546194
0.0005745389594447997,18.3534943972285,-0.0002608006587012,3.700064470481265,18.351986805597548,-8.214531358231535e-05
0.0006048546518941998,20.0410731496036,-0.0001645483351744,4.040280346960087,20.04003449599041,-5.18275903254046e-05
0.0006342923511257998,21.8448137109688,-7.108364011389212e-05,4.40391444413131,21.84432463730701,-2.238879869463665e-05
0.0006740763828465998,23.6584427355735,5.5230660599638025e-05,4.769542055491618,23.658854285627378,1.7395332353866117e-05
0.0007164154042137998,25.6113656819896,0.0001896570534404,5.163251321489104,25.61289556424152,5.973272098611462e-05
0.0007534271191822998,27.5611473363657,0.0003071692484652,5.556327303011325,27.56381377318905,9.674154037528768e-05
0.0007913922613912998,29.4769439119903,0.0004277085749789,5.942551892657244,29.48091479125812,0.0001347022894373
0.0008330221067315998,31.408432419204,0.0005598833339344,6.331939975711527,31.41397102010369,0.0001763256612552
0.0008752219936643998,33.3542812303072,0.000693867974946,6.724223096029932,33.361570511432575,0.0002185172178449
0.0009173521095418998,35.2009382751262,0.0008276310928571,7.096509156265442,35.21011414631179,0.0002606372415118
0.0009546749209444998,37.0404364995664,0.0009461310190603,7.467351998312586,37.051474328206325,0.0002979496303515
0.0009939696897873999,38.8097050938778,0.0010708919101365,7.824036546925766,38.82279517237223,0.0003372319215171
0.0010350182629817997,40.5581672947047,0.0012012211300288,8.176526526612468,40.57351196479908,0.0003782658122547
0.0010814473492044999,42.3001849541954,0.0013486334787858,8.527717286765792,42.318152653593216,0.0004246762622809
0.0011223809588220997,44.0590243676026,0.0014785976893217,8.882299312508685,44.07954265787779,0.0004655916550108
0.0011587048963871997,45.7667478283025,0.0015939261910909,9.226576362185783,45.78972383398583,0.0005018980253059
0.0011987357483032998,47.4630720379314,0.0017210241459245,9.56855532284697,47.488799626283225,0.0005419079904483
0.0012477267303097998,49.1446917610426,0.0018765705137952,9.907569859026188,49.17373852622948,0.0005908712323233
0.0012939360807714998,50.7783109097,0.0020232852015111,10.23690747939552,50.810669651439,0.0006370522207157
0.0013358769292389997,52.4475938875644,0.0021564473953954,10.573434927732984,52.48321608511829,0.0006789654808084
0.0013724892653751999,54.0503964144151,0.0022726915626278,10.896559917146083,54.08908614036399,0.0007155522975635
0.0014128801269128997,55.6188661141992,0.00240093254801,11.21276340862256,55.6609250578014,0.0007559134531428
0.0014596424766779997,57.198755364448,0.0025494030085142,11.531269081472717,57.24468376728559,0.0008026393763025
0.0015015063195252998,58.7359383034685,0.0026823207095544,11.84116516197925,58.78555991723433,0.0008444687562018
0.0015357124485360998,60.2805335081453,0.0027909251691637,12.152555555242094,60.333521998910186,0.0008786454273696
0.0015712117270437998,61.7996303757112,0.0029036353784256,12.45880548374338,61.85614804283957,0.0009141128993193
0.0016100000468184997,63.2292581357875,0.0030267882937103,12.74701844017476,63.28953579825848,0.0009528650275179
0.0016413702967893998,64.6610177544291,0.0031263888373679,13.035661179292909,64.72468877304966,0.0009842049090124
0.0016818619432964997,66.0615988653128,0.0032549498150279,13.31801833124706,66.12932396421267,0.0010246559048945
0.0017158111274706998,67.4338141073557,0.003362738474781,13.594656924042908,67.50523529828484,0.0010585697455717
0.0017536557523981997,68.8267046726084,0.0034828951589258,13.875463661997854,68.90220583686322,0.0010963736159453
0.0017981779912797998,70.2101465114052,0.0036242532673749,14.154365536699288,70.29029118948294,0.0011408460796531
0.0018371361745905999,71.5418558307867,0.0037479454993867,14.4228381354866,71.62630779191387,0.0011797590858952
0.0018760263510817997,72.8998429183043,0.0038714218097463,14.696608332330149,72.98873301021013,0.0012186026539798
0.0019149760493124997,74.271667107702,0.0039950871016287,14.973168088912724,74.3651227862149,0.0012575041602397
0.0019497717916646998,75.5950375050632,0.004105563583597,15.239959561020742,75.69278875957704,0.001292255570464
0.0019849221372775,76.9262838168619,0.0042171659309176,15.50833881747936,77.02846047932003,0.0013273599060191
0.0020232302987451996,78.2376190353891,0.0043387943435776,15.772703997534444,78.3445346067043,0.0013656165207079
0.002047908463071,79.5134176008786,0.004417147515312,16.029904988337126,79.62403885914307,0.0013902607034553
0.0020835287411648997,80.8169243692667,0.0045302418982601,16.29269195284417,80.93223782339777,0.0014258308618585
0.0021260516408962,82.0953660315126,0.004665252104907,16.55042579195294,82.21599456038871,0.0014682922728325
0.0021644266000114994,83.3636119558791,0.0047870926000981,16.806104170305225,83.48930308341026,0.0015066101934967
0.0022032341889721,84.6513858498337,0.004910306695048,17.065719387326475,84.7823037291041,0.0015453586078407
0.0022410568516773,85.8993480822777,0.005030393649137,17.317308573387184,86.03544494371332,0.0015831221530563
0.0022705031180433,87.1678351909631,0.005123885544849,17.573035574498164,87.30850858016335,0.0016125214071043
0.0023140157232801,88.424096168893,0.0052620380664759,17.82629778764883,88.57064450276212,0.0016559629602766
0.0023580109402267,89.6550018125269,0.0054017228802813,18.074448365405424,89.80753456043948,0.001699884418501
0.0023854932558832996,90.9293897891169,0.005488979232491,18.33136498148597,91.08658964177062,0.0017273196807312
0.002437174568567,92.179444939071,0.0056530674002618,18.58337609971672,92.3435698572314,0.0017789104694933
0.0024793554392353,93.4344735655337,0.0057869916646336,18.8363898708116,93.60477420166382,0.0018210154844422
0.0025277220582856,94.656618722856,0.0059405556801183,19.08277433452777,94.83372515246695,0.0018692929419006
0.0025745614095269995,95.8477487059067,0.0060892706203098,19.32290613911079,96.03157323510912,0.0019160437256218
0.0026191723740547996,97.1097537397087,0.0062309104326855,19.577326353925272,97.30033080354876,0.0019605683041933
0.0026575720653419996,98.3123910860856,0.0063528294525224,19.81977804295485,98.50910348093272,0.0019988920496516
0.0027013663819679,99.4879954268004,0.0064918764078096,20.05677987804296,99.69141708675993,0.0020425979584823
0.0027344873765278,100.645529053537,0.0065970355655373,20.29013865719306,100.8546509857192,0.0020756508229612
0.0027778199679403,101.777502897618,0.006734616543272,20.51834458415979,101.99338713533363,0.0021188926293851
0.0028200304470106,102.988484107932,0.0068686348143202,20.76247839615909,103.21128419845728,0.002161012876602
0.0028661423892538994,104.150808328969,0.0070150402309427,20.99680295912015,104.38092552913056,0.0022070242193995
0.0029061790323365,105.234917032146,0.0071421565727299,21.21535927368064,105.47164278155132,0.0022469718001626
0.0029455309633817997,106.365661621277,0.0072670989537988,21.44331738284944,106.60911667270634,0.0022862346370006
0.0029881858828219995,107.463783959118,0.0074025283230214,21.66469884615819,107.7143363069783,0.0023287912431322
0.0030348640073653,108.591918668682,0.0075507313684464,21.89213080360629,108.85017013534386,0.002375359706216
0.0030779618055205996,109.69977234495,0.0076875668775894,22.11547410474192,109.96538630915728,0.0024183543288058
0.0031153010983984994,110.799446866998,0.0078061191324768,22.3371684883868,111.07186062512598,0.002455602737413
0.0031555686842153997,111.918347823498,0.0079339687174454,22.5627389212172,112.198019215794,0.0024957707565974
0.0032050887187154995,113.049175267935,0.0080911948269833,22.790713734015693,113.33727067017836,0.0025451661345705
0.0032611102241442997,114.173546379246,0.0082690631067197,23.017386950056,114.47090331156978,0.0026010436760782
0.0033179738684155,115.285306359442,0.0084496051772808,23.24151776206351,115.592114334711,0.0026577579994261
0.003362815586063,116.342217315962,0.0085919776308116,23.45459101089794,116.65705502578808,0.0027024796968433
0.0034158819249426996,117.421666495114,0.0087604632567546,23.672207965414984,117.74565647775252,0.0027554014182485
0.0034767803084094,118.424008741001,0.0089538156242614,23.8742801621858,118.75797621808852,0.002816130389147
0.0035416460185712,119.440497083696,0.0091597642540251,24.079204212073115,119.78507875162364,0.0028808115941074
0.0036053182270596,120.396991695037,0.0093619235159758,24.27203352571946,120.7519987589118,0.0029442986235719
0.0036645401986966997,121.308742908791,0.0095499532759236,24.455842570412266,121.6736225392603,0.0030033447412259
0.0037334274143916,122.207395336817,0.0097686701857549,24.637010899902307,122.58339651455104,0.0030720230168303
0.0038107569121986,123.106344186032,0.0100141913412921,24.818238987904053,123.49463095327796,0.0031491123496996
0.0038847637036044996,123.963093458185,0.0102491629040058,24.990959641170097,124.363256588559,0.003222883730804
0.0039683890610972,124.784427842382,0.0105146734140452,25.15654065302421,125.19767745054617,0.0033062365333924
0.0040564641667082,125.510940569393,0.0107943118743601,25.30300561878963,125.93765056503088,0.0033940170699007
0.0041465355094006,126.185146232214,0.0110802883874084,25.43892548041434,126.62551404653216,0.0034837791983733
0.0042436594240924,126.810122550441,0.0113886568165549,25.564920706168905,127.26498773676926,0.0035805606600137
0.0043456686940941,127.385819401148,0.0117125362488103,25.680981191271435,127.85574413416228,0.0036822001672874
0.0044571825224207,127.895181305893,0.0120665926537473,25.78366855126803,128.381247150049,0.0037932979628465
0.00457519183348,128.354847120744,0.0124412722163605,25.87633717954199,128.85780699265536,0.0039108535674477
0.0047012577560949,128.742175343259,0.0128415315206628,25.954422549201013,129.2628829661595,0.0040364195437817
0.0048310401508534,129.109308296634,0.0132535906240211,26.028436552601416,129.64825693219748,0.0041656707848745
0.0049701098588852,129.429212521675,0.013695136947022,26.09292924436968,129.98749623519612,0.0043041527901627
0.0051124159179906,129.71187094105,0.0141469586846817,26.14991318171568,130.28983266675576,0.0044458376207499
0.0052642372555521,129.947719897453,0.0146289914314395,26.197460331326525,130.54646134026086,0.0045969740617991
0.0054135144641806,130.142866396158,0.0151029465688349,26.236801865465456,130.76193435127493,0.0047455555830521
0.0055691575440564,130.299817975261,0.0155971133474406,26.268443303812614,130.93991278789437,0.0049004498031073
0.0057234010511795,130.435907939647,0.0160868364825565,26.29587904063284,131.09679018294744,0.0050539275183709
0.0058819831651256,130.522304316377,0.0165903346943353,26.313296550181605,131.20432280887607,0.0052116977452897
0.0060437235139561,130.604579697288,0.0171038603018722,26.32988326697326,131.30815213380046,0.0053725844021246
0.0062192577115001,130.664513249855,0.0176611813790744,26.341965871170764,131.39134464145,0.0055471628165156
0.0063872218957453,130.657785017458,0.0181944676640529,26.34060945951953,131.4065248110192,0.005714183906727
0.0065646891494613,130.647911598915,0.0187579261946012,26.33861897834126,131.41978053852168,0.0058906244051882
0.0067451510724332,130.632455581309,0.0193308928000369,26.33550304519189,131.4278073907729,0.0060700103289621
0.0069211240683799,130.606299265477,0.0198896070621677,26.33022993192016,131.42447500476337,0.0062449031076874
0.0071079768860122,130.58803311119,0.0204828647581503,26.326547475215904,131.4304951651268,0.0064305754453495
0.0072938703510036,130.559957611254,0.021073076509498,26.320887454428803,131.42650878474024,0.0066152602884296
0.0074779949671172,130.533459880892,0.0216576721656586,26.315545511987825,131.42386960711232,0.0067981541661082
0.0076669082509284,130.542832445525,0.0222574718417592,26.317435021017843,131.4579673801076,0.0069857699427804
0.0078543083625897,130.516276866584,0.0228524671962838,26.312081416303336,131.4556844053792,0.0071718481687729
0.0080454392954591,130.481870520682,0.0234593079081442,26.305145096969497,131.44596953705218,0.0073615952402159
0.008244426752128,130.438162955164,0.0240910930830679,26.29633365176106,131.42789458519147,0.0075591037043554
0.0084437004298635,130.391286010003,0.0247237870098782,26.28688325961661,131.40664550079214,0.0077568571761243
0.0086431260779243,130.335367499177,0.0253569634424712,26.275610087834085,131.37628376655894,0.0079547223154395
0.0088452307443122,130.275903632038,0.0259986457582528,26.263622172218863,131.34267436254686,0.0081552055746444
0.009045313855026,130.22106873036,0.0266339096347691,26.25256745604058,131.31344547905525,0.0083536439117204
0.0092477820121496,130.169879712347,0.0272767460336365,26.24224775000916,131.28818231081718,0.0085544076124001
0.0094520589322842,130.095873753837,0.0279253252550639,26.22732814877354,131.24011614404728,0.0087569240096738
0.009655956912936,130.022599590025,0.0285727013436333,26.21255607734904,131.19270885176,0.0089590238427137
0.0098606045535385,129.928964368267,0.0292224576025463,26.19367921664263,131.12482063680068,0.0091618256630038
0.010067912039816,129.828361731582,0.0298806588714773,26.17339772508693,131.05020645244628,0.0093672214131682
0.0102610167959561,129.738823765672,0.0304937664722222,26.15534687115948,130.98487900796843,0.00955850746354
0.0104608133268591,129.652420273208,0.0311281204578392,26.13792792707873,130.9235497711339,0.0097563837572061