File: example/data/02 processed data/test_ID_147.csv
Strain,Stress_MPa,Displacement(mm),Force(kN),True Stress (MPa),True Strain
-0.0003164238488926,0.803703121883699,2.8660803527059323e-05,0.1620265493717537,0.803710376931658,9.026983989479115e-06
-0.0003072050395112,0.781820551281261,5.793052331294568e-05,0.1576150231383022,0.7818348162493468,1.824566766104341e-05
-0.0002945927732768,0.756766803201139,9.797446860720663e-05,0.1525641875253496,0.7567901555870927,3.08576242473676e-05
-0.0002884473430196,0.729013206482367,0.0001174862096737,0.1469690624268451,0.7290401825448651,3.700284599212252e-05
-0.0002713526310876,0.669628851190107,0.0001717619200579,0.1349971763999255,0.669665076934109,5.40967792807311e-05
-0.0002476280121583,0.590898477954961,0.0002470875851585,0.1191251331557201,0.5909444633653521,7.781983342550765e-05
-0.0002189746444894,0.507802273702006,0.0003380620275071,0.1023729383783244,0.5078563425732565,0.0001064705609447
-0.0001989223234993,0.420249782986394,0.0004017281466506,0.084722356250057,0.4203029565821261,0.0001265205460643
-0.0001777571245405,0.327406874109411,0.0004689276533448,0.0660052258204572,0.3274552300581244,0.0001476828434369
-0.0001599237703993,0.233081245384256,0.0005255485527431,0.046989179069466,0.2331198266476208,0.0001655134051267
-0.0001341584144637,0.119648915900832,0.0006073535578387,0.0241212214456077,0.1196718038361907,0.0001912741650923
-0.0001081035637852,0.005295588399172,0.0006900777087429,0.001067590621273,0.0052967393810645,0.0002173236933357
-7.519933640057414e-05,-0.0292746453685922,0.0007945486306893,-0.0059017685063081,-0.0292819713935974,0.000250220229532
-5.637482662897413e-05,0.14996203594475,0.0008543164492142,0.0302323464464616,0.1500023871365815,0.0002690398525295
-3.079295416617416e-05,0.501372616567108,0.0009355388942835,0.1010767194999289,0.5015203499791795,0.0002946145163404
2.9877664499258555e-06,1.01502720418279,0.0010427926822397,0.2046294843632504,1.0153605783373714,0.0003283847159121
3.835712248292586e-05,1.73948282232606,0.0011550903876444,0.3506797369809337,1.7401156600859158,0.0003637418340259
6.859279033842586e-05,2.84994510604846,0.0012510886330857,0.5745489333793696,2.851068108860144,0.0003939660491478
9.659989137182584e-05,4.29056864087198,0.0013400111788667,0.8649786379997911,4.292379478649134,0.0004219617266249
0.0001204906274226,5.87170260584904,0.0014158642658283,1.1837352453391663,5.874321041722801,0.0004458420986877
0.0001518887457926,7.4449605436189,0.0015155532916531,1.5009040455935705,7.448514318251375,0.0004772257291035
0.0001937389665677,9.0492432127255,0.001648427742614,1.8243274316854607,9.053941487862987,0.0005190551077808
0.0002338201137857,10.7198627681556,0.0017756853850311,2.1611243340601693,10.72585807639086,0.0005591146536785
0.0002626047911241,12.4104397735349,0.0018670767355806,2.501944658344636,12.417737802945762,0.0005878828277724
0.0003053769399463,13.9837033558763,0.002002878308091,2.8191145965446616,13.992524664889928,0.0006306289253452
0.0003473371542064,15.4516643570607,0.0021361019883669,3.1150555343834374,15.46206005185021,0.0006725618074268
0.0003856306995805,16.9872625830926,0.0022576839949296,3.4246321367514687,16.999341912494653,0.00071082887449
0.0004354895474812,18.5809935874017,0.0024159858370144,3.745928307220183,18.59513261648668,0.00076065105273
0.0004686220510281,20.2924214503355,0.0025211815357758,4.0909521643876365,20.30853511278488,0.000793757815551
0.0004973160908193,22.0738777019501,0.0026122851121128,4.45009374471314,22.09203935930046,0.0008224286772476
0.0005393880019057,23.88231639693,0.0027458634298121,4.814674985621088,23.90297075258781,0.000864465117869
0.0005750793596659,25.7555683233831,0.0028591834907008,5.192322573994033,25.778761991333912,0.0009001249992065
0.0006129153265393,27.7151462716029,0.0029793126855238,5.587373488355145,27.741153228096803,0.0009379262098286
0.0006530499586202,29.7009787031921,0.0031067401423807,5.987717306563527,29.73004113557169,0.0009780224123705
0.0006945798622419,31.6982820741845,0.0032385975863796,6.390373666155596,31.73061529617437,0.0010195108580141
0.0007389456364044,33.6297980428727,0.0033794589193455,6.779767285443137,33.66559348254255,0.0010638304417099
0.0007955112088915,35.5705780341677,0.0035590546119921,7.171028531688209,35.61045130339723,0.0011203342736448
0.0008404658055646,37.4976914900287,0.0037017854564292,7.559534604389786,37.54141067396805,0.001165237526178
0.0008763564964262,39.3818540412451,0.0038157383999147,7.939381774715011,39.42918344367818,0.00120108577766
0.0009126878512468,41.2789677219329,0.0039310904514701,8.321839892741673,41.33007681039219,0.0012373728632183
0.0009501033114772,43.0868710364167,0.0040498845377017,8.686313200941608,43.14183067509019,0.001274741356994
0.0009890369439544,44.8862885992885,0.0041734988208168,9.049075781616562,44.94529107882865,0.0013136246348148
0.0010301920382931,46.6497841562797,0.0043041662453421,9.404596485905987,46.7130246055137,0.0013547248576753
0.001062450580513,48.3553639743036,0.0044065871168903,9.748441377219606,48.42247645427894,0.0013869392091467
0.0011019494214137,50.0936657688534,0.00453199593675,10.098883019000846,50.16516948215146,0.0014263825276308
0.0011508029186072,51.8166624104305,0.0046871057903394,10.44623914194279,51.89315695481475,0.0014751652008297
0.0012026860839608,53.4454292545098,0.0048518348403371,10.774598537709176,53.52710119016769,0.0015269705444474
0.0012518186991286,55.1351581985894,0.0050078308934949,11.115247892835624,55.22212120600503,0.0015760269895226
0.0012932277982648,56.7413341392101,0.0051393047832523,11.439052962464755,56.833180126595856,0.0016173700235662
0.0013363926994219,58.391074630039,0.0052763533444261,11.771640645415864,58.48811146213627,0.0016604642389637
0.0013917807297808,59.9712269139009,0.0054522103408156,12.090199345842422,60.074211400052505,0.001715758847018
0.0014418822964825,61.4782332663654,0.0056112828150935,12.394011826499266,61.5868857872567,0.0017657732744742
0.0014905046939871,62.9529198931295,0.0057656589271706,12.691308650454909,63.0672395985069,0.0018143087137418
0.0015356706883494,64.4902376264142,0.0059090609592709,13.001231905485104,64.61026179819761,0.0018593918210803
0.0015935228773766,65.9496915625905,0.0060927416594323,13.295457819018246,66.07624728958581,0.0019171348730037
0.0016555947522976,67.3768430071924,0.0062898198623064,13.58317155024999,67.51031960732033,0.0019790859427582
0.0017173494266641,68.7203120659013,0.0064858909534201,13.854014912485702,68.86069394002553,0.0020407166209675
0.0017844366644042,70.0690030173569,0.0066988929332449,14.125911008299152,70.2168407336254,0.002107664851182
0.0018611925540078,71.3946732399268,0.0069425928827363,14.393166125169245,71.55078793293492,0.0021842562022673
0.0019283934762628,72.6686253049748,0.0071559558108959,14.64999486148292,72.83240907553258,0.0022513082526425
0.0020230334694714,73.862384357068,0.0074564377893332,14.890656686384908,74.03584901027439,0.0023457309637452
0.0021166771523143,75.011587311696,0.0077537564823595,15.122336002037914,75.19477521134013,0.0024391508773592
0.0022218707984591,76.1865506204218,0.0080877463088692,15.359208605077036,76.38062227193859,0.0025440827474568
0.0023370338874515,77.3292078326368,0.0084533891164201,15.58956829905958,77.53509567007737,0.0026589466272858
0.0024381945505081,78.4714933727416,0.0087745742216248,15.81985306394471,78.68836075632612,0.002759833577565
0.002563756499015,79.5666354671118,0.0091732334081342,16.04063371016974,79.7965199769196,0.0028850416348776
0.0027107668848137,80.6254472016818,0.009639991383045,16.25409015585905,80.87024361625765,0.0030316177580175
0.0028384741144189,81.5845130484086,0.0100454618370416,16.447437830559174,81.8426403278799,0.0031589303097981
0.0029724851094899,82.5197897455856,0.010470946746392,16.635989612710055,82.79193472950669,0.003292509719282
0.0031067125313266,83.3859102905914,0.0108971188107235,16.810599514583224,83.67210436037941,0.0034262869742082
0.0032484908581033,84.2428952309457,0.0113472649982395,16.983367678558654,84.54397442981326,0.0035675703780301
0.0034018065985044,84.9954473126837,0.011834042474013,17.135082178237035,85.31224722877694,0.0037203284601355
0.0035513938120474,85.7202461903459,0.012308981877012,17.281201631973733,86.05257027124354,0.0038693490899092
0.0037014887645962,86.368942661822,0.0127855333513545,17.411978840623316,86.71674518053821,0.0040188532185435
0.0038634975192906,86.9609374673579,0.0132999111475092,17.53132499341935,87.32521234660828,0.0041801991734394
0.0040305081901201,87.4795112753585,0.0138301700273929,17.635869473112276,87.86056844539046,0.004346499334909
0.0041940336343587,87.9353357254364,0.0143493633128504,17.72776368224798,88.33275811295191,0.0045093023052205
0.0043648292377221,88.2951931464926,0.0148916393535292,17.800310938332906,88.70932233483519,0.0046793150204505
0.0045407600386887,88.6191133513663,0.0154502196465982,17.865613251635445,89.05035264779633,0.0048544091789894
0.0047107493839003,88.8672121453635,0.015989935817645,17.915629968505282,89.31476522205558,0.005023561019071
0.0048937694833541,89.0796809175214,0.0165710246334108,17.958463672972314,89.5446074015594,0.0052056474326509
0.0050697916972327,89.2601492380214,0.0171298951624754,17.994846086385113,89.74172939507154,0.0053807403881366
0.005247160945834,89.4227249307903,0.0176930425267845,18.02762134604733,89.92104306466791,0.0055571422621636
0.0054184755969484,89.5600756499574,0.0182369665440727,18.05531125103141,90.0745021391898,0.0057274930232371
0.0055922488531995,89.6667577517511,0.01878869663267,18.076818362753023,90.19737869960392,0.0059002589142997
0.0057666327264406,89.7560554744195,0.0193423654302105,18.09482078364297,90.30285686798184,0.0060736018822344
0.0059608566109448,89.833931825561,0.0199590262635113,18.1105206560331,90.39865554356442,0.0062666310719413
0.0061362257402483,89.9107289567586,0.0205158232490499,18.126002957682537,90.49170301139486,0.0064408894799813
0.0063374244964575,89.9769040004089,0.0211546293000141,18.13934384648244,90.57640889794956,0.0066407765229174
0.0065206685435394,90.0114089974759,0.0217364291494991,18.146300053891142,90.62763785237992,0.0068227911531596
0.0067005374604617,90.0549376248085,0.0223075129607274,18.1550754251614,90.68766256598737,0.0070014210837378
0.0068858389073214,90.0891718089303,0.022895845054507,18.161977036680348,90.73883093297005,0.0071854127607818
0.0070751954525239,90.1014749668861,0.0234970520855249,18.16445735332424,90.76828411658045,0.0073733959076761
0.0072592050021879,90.1074544338652,0.0240812824057081,18.165662813867225,90.79088846759164,0.0075560369919307
0.0074522258046579,90.0967959807309,0.0246941234535504,18.16351406971535,90.79753972961832,0.0077475864715872
0.0076214001139479,90.0761318999933,0.0252312518855461,18.15934819103865,90.79195349773956,0.0079154410641819
0.007811600921551,90.0502519031142,0.025835139449686,18.15413078366782,90.78299546701857,0.0081041244894152
0.0080222738815587,90.003893021202,0.0265040260977104,18.14478483307433,90.75522074703808,0.0083130751973245
0.0082257035868963,89.9693176013854,0.0271499154121573,18.13781442843929,90.7386591329026,0.0085148004381124
0.0084208430405439,89.9406318097368,0.0277694831774884,18.13203137284294,90.72727901037086,0.0087082666564072
0.0086059157226639,89.9102128658348,0.0283570889432194,18.12589891375229,90.71323393769,0.008891717845129
0.0087936728326905,89.8800203530507,0.0289532177675539,18.119812103175025,90.69964737737638,0.009077795558715
0.0089946086183021,89.8580720927587,0.0295911888868707,18.11538733390016,90.69555467049317,0.0092768957227904
0.009187693431489,89.8429052713167,0.0302042331687391,18.112329702697448,90.69759379395347,0.0094681792953137
0.0093794480243755,89.8157321457867,0.0308130540011538,18.1068516005906,90.68738474571153,0.009658108851568
0.0095731642866272,89.7938466082267,0.0314281031338029,18.102439476218503,90.68268133956032,0.0098499447852028