File: example/data/02 processed data/test_ID_111.csv
Strain,Stress_MPa,Displacement(mm),Force(kN),True Stress (MPa),True Strain
0.001189647322324,-0.22511482092346,0.0001986297020935,-0.0453831478981695,-0.2251289042273393,6.25585792637125e-05
0.0011760636710787,0.170816466371247,0.0001555016093897,0.0344365996204433,0.1708248324296504,4.897568551859762e-05
0.0011571907717815,0.749159059003007,9.558015412090106e-05,0.1510304662950062,0.7491816116764939,3.0103532434043706e-05
0.0011377320748169,1.42658513899221,3.379879125859452e-05,0.2875995640208295,1.426600325402706,1.06452319246157e-05
0.0011065885443554,2.70946548259445,-6.508191795694612e-05,0.5462282412910411,2.7094099433156327,-2.04984519680522e-05
0.0010708905813445,4.29329444252325,-0.0001784229505165,0.8655281596126874,4.293053175669118,-5.619778395294059e-05
0.0010259916071388,6.21444820882568,-0.0003209771936196,1.2528327588992572,6.213819958071046,-0.0001011002895548
0.0009914594913739,8.3842976053051,-0.0004306166611731,1.6902743972295082,8.38316046570161,-0.0001356364930709
0.0009641316077074,10.6834217321432,-0.0005173826918143,2.153777821200069,10.68168081324759,-0.0001629684571618
0.00094227758635,13.0533874034115,-0.000586769209624,2.6315629005277583,13.050975017329732,-0.0001848262792061
0.0009262808718871,15.5231260341548,-0.0006375587780437,3.129462208485608,15.520008898638029,-0.0002008260785515
0.0009211758477094,17.8869010963043,-0.0006537672298079,3.605999261014947,17.883217987712307,-0.00020593214109
0.0009255460216283,20.3668108069113,-0.0006398919276154,4.105949058673319,20.362706064288744,-0.0002015610766724
0.000933853540956,22.9148932895838,-0.00061351555375,4.619642487180094,22.91046537038831,-0.0001932519172245
0.0009335542905935,25.4955842827772,-0.0006144656736509,5.139909791407884,25.490650058723205,-0.0001935512254681
0.0009522724847656,28.1307528520007,-0.0005550354071545,5.671159774963342,28.125835194091163,-0.000174829583267
0.0009728237691554,30.8016987931062,-0.0004897850792169,6.20962247669021,30.796947230119304,-0.0001542749168392
0.0009973405077604,33.4928745946386,-0.000411944434146,6.752163518279142,33.48852901880464,-0.0001297546962476
0.0010219598209893,36.2181810105007,-0.0003337781146443,7.301585291716941,36.21437350304447,-0.000105132491469
0.001046881960202,38.9460122763084,-0.0002546503226437,7.851516074903774,38.94288861816924,-8.020804260860118e-05
0.0010801861136531,41.6868273167635,-0.0001489096354364,8.404064387059522,41.684872176524685,-4.6901772449332326e-05
0.0011160631373125,44.4291346158547,-3.500008531810948e-05,8.956913538556307,44.42864484467292,-1.1023709680003824e-05
0.0011507437643386,47.1805774098654,7.511090548983072e-05,9.511604405828866,47.18169355975227,2.3656698285240423e-05
0.0011955042456603,49.972167933263,0.0002172254336861,10.07438905534582,49.97558690203514,6.841511906113015e-05
0.0012396133099117,52.7773752711273,0.0003572717126843,10.639918854659264,52.78331412569552,0.0001125201930457
0.0012931908643528,55.6247763586946,0.0005273804480348,11.213954913912833,55.63401586089235,0.0001660902843661
0.0013493370606009,58.465138286,0.0007056446211225,11.7865718784576,58.47813217902511,0.0002222255804359
0.0014009812339461,61.2823412862352,0.0008696148714935,12.354520003305018,61.29912617925645,0.0002738569454778
0.0014482529893324,64.1172888068544,0.001019702694845,12.926045423461847,64.13788111305362,0.0003211146402757
0.0015007003820437,66.9527680699807,0.0011862231667034,13.49767804290811,66.9777825344089,0.0003735438196316
0.0015577729687059,69.7920168057751,0.0013674286293559,14.070070588044262,69.82207526306037,0.0004305934638012
0.0016154523519829,72.6162038043692,0.0015505606712603,14.639426686960832,72.65166705782283,0.0004882463540993
0.001674036653173,75.4085926861372,0.0017365658275389,15.20237228552526,75.44983740587313,0.0005468003443814
0.0017354442158025,78.1787144553213,0.0019315348388876,15.760828834192774,78.2262750570945,0.0006081724552064
0.0018003252693582,80.9839659531001,0.0021375321839269,16.326367536144982,81.03848747549593,0.0006730119597627
0.0018681930936988,83.7858457365591,0.0023530125262083,16.891226500490312,83.84793995531093,0.0007408318237936
0.0019325806263975,86.5807451383348,0.0025574429425267,17.454678219888297,86.6504853952207,0.0008051696041042
0.0019933346852928,89.3804839561422,0.0027503370795193,18.01910556555827,89.45790961258628,0.0008658729228823
0.0020596252691176,92.2257225299647,0.002960809683163,18.59270566204088,92.31172656533586,0.0009321039390065
0.0021204201998266,95.0469426387816,0.0031538335881641,19.16146363597837,95.14135594276476,0.0009928403844275
0.0021786822479387,97.9040780090412,0.00333881559092,19.737462126622702,98.00703349315812,0.0010510429225308
0.0022405414015249,100.740987728198,0.0035352184035562,20.309383126004715,100.85315824593316,0.0011128351844659
0.0023097732847504,103.586057199637,0.0037550296327971,20.88294913144681,103.7085670309218,0.0011819876757797
0.0023655085137117,106.417564441059,0.0039319889847493,21.45378099131749,106.54935426504832,0.0012376555158227
0.0024265817603409,109.194486472358,0.004125896542797,22.01360847282737,109.33638415872926,0.0012986513612833
0.0024885945591021,111.921609811884,0.0043227871788638,22.56339653807581,112.07399195359508,0.0013605817615818
0.0025430894099678,114.64458628319,0.0044958083303624,23.112348594691102,114.80692331816414,0.0014150010374087
0.0026065086893545,117.323964610103,0.0046971645424152,23.652511265396765,117.4975362531084,0.0014783286366745
0.002663309421228,119.944007557653,0.0048775068661135,24.180711923622844,120.12826825699524,0.0015350438520985
0.0027100917872257,122.505142227889,0.0050260408781562,24.69703667314242,122.69906848068324,0.0015817533692963
0.0027748054941801,125.017949980624,0.0052315068977364,25.2036187160938,125.22394439563644,0.0016463627088105
0.0028294724327193,127.551874727868,0.0054050744275984,25.71445794513819,127.76901720858731,0.0017009382305169
0.0028841293396722,130.069670043574,0.0055786101071739,26.22204548078452,130.29820798875255,0.0017555007599069
0.0029333853060756,132.582111098822,0.0057349978005046,26.72855359752252,132.8215939698576,0.0018046691244937
0.0029786914251711,135.069830731914,0.0058788447286329,27.230077875553867,135.319926657078,0.001849892532174
0.0030452086275137,137.553657758206,0.0060900368460706,27.730817404054328,137.81750243350024,0.0019162845945832
0.0031108635383501,140.039219254034,0.0062984911879762,28.23190660161325,140.31702580157497,0.0019818116654503
0.0031696781567663,142.51608007662,0.0064852276014476,28.7312417434466,142.80718219194694,0.0020405081171224
0.0032325860213878,144.949110193445,0.0066849600716209,29.22174061499852,145.25430043409386,0.0021032857780518
0.0032914318833656,147.330870315306,0.0068717956834004,29.701903455565688,147.64974516212942,0.0021620062763531
0.0033631690713865,149.664118279006,0.0070995612553668,30.17228624504761,149.998779562613,0.0022335859737743
0.0034326027248403,151.968738810775,0.0073200131050826,30.63689774425224,152.3191051602735,0.0023028623146027
0.0034923592998273,154.26275509738,0.0075097402306663,31.09937142763181,154.62762855188336,0.002362479659604
0.003555410106581,156.54360748977,0.0077099265421093,31.55919126993763,156.92374598248907,0.0024253797076745
0.0036090633098436,158.803863324246,0.0078802754624681,32.014858846168,159.19801078487566,0.0024789015069085
0.0036599218523967,161.023278866328,0.0080417513350741,32.46229301945173,161.43112427350954,0.0025296328454204
0.0037162999692533,163.193208452714,0.0082207518560938,32.89975082406714,163.61575045941936,0.0025858669454051
0.0037732297028769,165.319453535176,0.0084015037603488,33.32840183269148,165.75691243613178,0.0026426480444076
0.0038317728595638,167.386578141755,0.0085873782828297,33.745134153377805,167.83930628851772,0.0027010349918257
0.0038751040522006,169.472860416372,0.0087249548194515,34.16572865994059,169.93857476290935,0.0027442483696046
0.0039325318973698,171.545299515171,0.0089072882278637,34.583532382258475,172.02656043703456,0.0028015171946567
0.0039844169519371,173.62128319931,0.0090720232761149,35.002050692980895,174.11737652920388,0.002853255757309
0.0040504027435673,175.62086476089,0.0092815281645408,35.40516633579542,176.13426003728657,0.002919051378362
0.0041173561438088,177.620244350885,0.0094941052103076,35.80824126113842,178.15137672485284,0.0029858073949288
0.0041783277904316,179.628521145497,0.009687690188335,36.21310986293219,180.17661105474,0.0030465954158414
0.0042514896901989,181.64381237629,0.0099199792200961,36.61939257506006,182.21134083116613,0.0031195321001459
0.0043236579715941,183.544811776472,0.0101491135135259,37.00263405413676,184.13152583301945,0.0031914730132485
0.0043911028645677,185.399412555154,0.0103632510487171,37.37652157111904,186.0045592186481,0.0032587007409469
0.0044794774675883,187.179749882314,0.0106438404133075,37.73543757627451,187.8072495315581,0.0033467839468649
0.0045593220780233,188.951259633463,0.0108973470514386,38.09257394210614,189.59978481520545,0.0034263586151615
0.0046397622420821,190.665089485371,0.0111527445723253,38.43808204025079,191.33483406549385,0.00350652042097
0.004734977255766,192.298206365206,0.0114550522407717,38.76731840322553,192.9919972312596,0.0036013976449613
0.004826182705842,193.812674915784,0.011744629544763,39.07263526302205,194.5296065907337,0.0036922710895884
0.0049241645446028,195.269394683126,0.0120557218828285,39.3663099681182,196.01084775856788,0.0037898870553106
0.0050349835462953,196.589504858617,0.0124075722132022,39.63244417949719,197.3577563477165,0.0039002807667488
0.0051566910806366,197.772017345177,0.0127939936347358,39.870838696787686,198.56896031558423,0.0040215071838325
0.0052908178062879,198.808138773253,0.0132198459886787,40.07972077668781,199.6359223877029,0.0041550866788863
0.0054197122484409,199.708321472431,0.0136290858425145,40.26119760884209,200.56559449819864,0.004283438427147
0.0055590720261833,200.463908762226,0.0140715531368466,40.41352400646476,201.3523618470032,0.0044221929156652
0.0057110708424029,201.101264005178,0.0145541493783438,40.542014823443886,202.0231089930536,0.0045735095988898
0.005871861207152,201.609100057845,0.0150646587864222,40.64439457166156,202.56568975882425,0.004733553458725
0.0060326369139272,202.012911368829,0.0155751216554335,40.725802931955926,203.0038958319905,0.0048935571222025
0.0061791495392602,202.332121477422,0.0160402992408658,40.79015568984828,203.35431605207933,0.0050393439036287
0.0063443374197501,202.601316623112,0.0165647707614212,40.844425431219385,203.6583384706156,0.0052036879343132
0.0065222098325792,202.833695651184,0.0171295156721536,40.89127304327869,203.9280083971676,0.005380621505022
0.0067003022148813,202.999875274874,0.0176949589859627,40.9247748554146,204.1312373117699,0.0055577425261343
0.0068706521031161,203.17988465621,0.0182358198811082,40.96106474669194,204.34686159481,0.0057271339320758
0.0070545964543199,203.323090882215,0.0188198431961803,40.98993512185455,204.5282904691649,0.0059100110972384
0.007237379349491,203.438253556672,0.0194001788883485,41.01315191702508,204.68132080446185,0.006091700422828
0.0074313520343898,203.546025599889,0.0200160421629022,41.034878760937616,204.82923373547908,0.0062844764934905
0.0076058064004841,203.638175229993,0.0205699347752516,41.05345612636659,204.95748987006613,0.0064578229176635
0.0077882466791417,203.709293176586,0.0211491826599895,41.06779350439973,205.06623335010693,0.0066390723986501
0.0079679692896299,203.763698571063,0.0217198019482896,41.0787616319263,205.15762209144552,0.0068175898346212
0.0081511393807231,203.79021897027,0.0223013669875105,41.08410814440643,205.2216521865601,0.0069994988478882
0.0083371643056521,203.834155471393,0.02289199612416,41.09296574303283,205.30381553344736,0.0071842091779107
0.008517711452479,203.886418714921,0.0234652333153354,41.10350201292808,205.3932667101884,0.0073634478202027
0.0087050237490625,203.925355450591,0.0240599498569881,41.11135165883915,205.47068893931845,0.0075493686337479
0.0088895119273013,203.931261345272,0.0246456998228962,41.11254228720684,205.5142624953885,0.0077324525259016
0.0090906757854241,203.954775967841,0.0252843950724361,41.11728283511674,205.57898797807124,0.0079320469721501
0.0092729516861928,204.00295353791,0.0258631210573768,41.126995433242655,205.6647340366229,0.0081128664221189
0.0094565900367318,204.047888849375,0.0264461728203381,41.136054392034005,205.7475064028036,0.008295004378225
0.0096477790825245,204.05268305696,0.0270531980407299,41.13702090428313,205.7913531815213,0.0084845960958324
0.0098357512111729,204.031528376082,0.0276500095491886,41.13275612061813,205.8083704888172,0.0086709627363596
0.0100174124109106,204.030389837448,0.0282267838583558,41.13252659122952,205.8442864404332,0.0088510393532936
0.0102202537861612,204.075355146048,0.0288708052247764,41.14159159744327,205.9310464309609,0.0090520730849124
0.0103918049944124,204.089078652448,0.029415480310974,41.14435825633352,205.9799064555302,0.0092220639571175
0.0105844683095403,204.11335922007,0.0300271863365051,41.14925321876612,206.0437371322184,0.0094129404682911
0.0107818040937494,204.127509403029,0.030653727451369,41.15210589565065,206.0983028010029,0.0096084083523691
0.0109652072320847,204.150784367644,0.0312360324155835,41.15679812851703,206.15924437336827,0.0097900412211872