File: example/data/02 processed data/test_ID_113.csv
Strain,Stress_MPa,Displacement(mm),Force(kN),True Stress (MPa),True Strain
1.79927888271149e-05,0.308467808712367,5.71271045260898e-05,0.06218711023641319,0.30847335890850913,1.799262695879819e-05
9.09519390281766e-06,0.256760170235535,2.887724064144607e-05,0.051762850319483855,0.2567625055190698,9.095152541882975e-06
2.03687854255043e-05,0.240841928723698,6.467089372597615e-05,0.04855373283069752,0.2408468343812656,2.036857798454676e-05
3.9838024776363e-05,0.885924108714981,0.00012648572866495253,0.17860230031694016,0.8859594021815739,3.983723126332744e-05
4.25491506886717e-05,2.70752802820411,0.00013509355343653263,0.5458376504859487,2.7076432312221757,4.254824549914001e-05
8.32071668450176e-05,5.8409893111866,0.00026418275473293084,1.1775434451352185,5.841475323358756,8.320370532077457e-05
0.0001333406728873,9.84328812034232,0.0004233566364171774,1.9844068850610117,9.844600631003711,0.00013333178381004615
0.000193469556762,14.1282024338384,0.0006142658427193499,2.8482456106618215,14.130935810901118,0.00019345084394086542
0.0002864100187129,18.5194114012153,0.0009093518094134575,3.7335133384850048,18.524715546181277,0.0002863690111933702
0.0003574308075749,23.1938593082775,0.0011348428140503075,4.675882036548744,23.202149508140835,0.00035736694440110996
0.0004439274742088,28.1310299859375,0.00140946973061294,5.671215645165001,28.143518123026045,0.00044382896755968684
0.0005297681166817,33.238485267102,0.0016820137704643974,6.700878629847763,33.2560939568433,0.0005296278390937444
0.0005862409672722,38.190229405775,0.0018613150710892349,7.699150248204241,38.21261808280219,0.000586069195166209
0.0006621305026072,42.9433415032889,0.00210226434577786,8.657377647063042,42.9717755995821,0.0006619113909208833
0.0007367757637252,47.6707555998353,0.00233926304982751,9.610424328926797,47.70587825719972,0.0007365044777052312
0.0008106568131008,52.2166199023309,0.00257383538159504,10.526870572309909,52.25894966101182,0.0008103284083368491
0.0008929164740232,56.796731924155,0.00283500980502366,11.450221155909649,56.847446661760756,0.0008925180612570158
0.0009711755511209,61.3847159219853,0.0030834823748088574,12.375158729872238,61.44433125730122,0.000970704265254784
0.0010503561644136,65.9084703500188,0.00333488082201318,13.287147622563792,65.977697718138,0.001049804926341223
0.0011350553966087,70.565712898872,0.003603800884232622,14.226047720412595,70.64580889211341,0.001134411708267296
0.0012194309865535,75.1296122094384,0.0038716933823073623,15.146129821422782,75.22122758657434,0.0012186880844718122
0.0013119340896323,79.7056549476927,0.004165390734582552,16.068660037454848,79.81022351355504,0.0013110742560524316
0.0013995917389906,84.1946325205354,0.004443703771295155,16.973637916139936,84.31247063267848,0.0013986132233812
0.0014859769681122,88.5550657206821,0.0047179768737562345,17.85270124928951,88.68665650875269,0.0014848739968619839
0.0015650934226216,92.960356875996,0.00496917161682358,18.740807946200793,93.10584851910718,0.0015638699403206207
0.0016477969523578,97.3404973902376,0.005231755323736015,19.6238442738719,97.50089476517823,0.0016464408245042473
0.0017234575381886,101.626259805809,0.005471977683748805,20.487853976851092,101.80140834934923,0.0017219740894416666
0.0018055085148545,105.945450665464,0.005732489534663037,21.358602854157542,106.13673607875059,0.0018038805436053182
0.001887732927273,110.15705974947,0.005993552044091775,22.20766324549315,110.36500685833066,0.0018859533986353013
0.0019770578086991,114.21692709225,0.006277158542619642,23.0261325017976,114.44274055984334,0.001975106002042587
0.0020596548580825,118.261845434199,0.0065394041744119375,23.841588039534518,118.50542401867335,0.0020575366769978983
0.0021375007918398,122.191230845786,0.006786565014091365,24.63375213851046,122.45241469847474,0.002135219587161768
0.0022212684210517,126.078148632086,0.007052527236839147,25.41735476422854,126.3582020422271,0.0022188050515479386
0.0022940575480393,129.875212032783,0.007283632715024777,26.182842745809054,130.17315324325,0.0022914302154233086
0.0023767118468803,133.565148102539,0.007546060113844952,26.926733857471863,133.88259397236465,0.00237389193447437
0.0024549239227888,137.248075358292,0.00779438345485444,27.669211992231666,137.5850089418458,0.0024519155196501756
0.0025325009413709,140.881766220866,0.008040690488852607,28.40176407012659,141.23854942644235,0.0025292995647155734
0.0026092608808954,144.523626880912,0.008284403296842895,29.135963179191858,144.9007267268975,0.0026058626696526966
0.0027003239392325,148.008331892855,0.008573528507063187,29.838479709599568,148.40800233467115,0.0026966846146421267
0.0027877678096319,151.644056286734,0.008851162795581282,30.57144174740558,152.0668047053722,0.002783889191737028
0.0028749715148098,155.186380975206,0.009128034559521114,31.28557440460153,155.63253739999612,0.0028708466881525096
0.002956812916026,158.786939252809,0.009387881008382549,32.011446953366296,159.25644252568793,0.002952450142536789
0.0030404315832202,162.377841744073,0.009653370276724135,32.73537289560512,162.8715404625268,0.003035818818612415
0.0031307714023248,165.802990433713,0.009940199202381239,33.42588287143654,166.3220816945828,0.0031258807425710265
0.0032256681892686,169.23811717692,0.010241496500927804,34.11840442286707,169.78402318790933,0.003220476882261874
0.0033377843985373,172.521053149681,0.010597465465355926,34.78024431497569,173.09689122930322,0.0033322263604464255
0.0034273885308357,175.803636689724,0.010881958585403346,35.44201315664836,176.40618405779358,0.0034215284208635537
0.0035439115482433,179.043139589388,0.011251919165672477,36.095096941220625,179.6776526394126,0.0035376466907500706
0.0036645313757746,182.093084190869,0.011634887118084355,36.709965772879194,182.760370011198,0.0036578333391289295
0.0038098414290046,185.071352271155,0.012096246537089605,37.310384617864855,185.77644477635957,0.0038026023637823337
0.0039793763002312,187.962906127967,0.012634519753234059,37.89332187539815,188.71088126193519,0.0039714795249229514
0.0041730342841773,190.567211986019,0.013249383852262925,38.41834993638143,191.36245549507674,0.004164351324419563
0.0043947633280491,192.934708051098,0.013953373566555892,38.89563714310136,193.7826104307488,0.004385134556169091
0.004637701511371,194.874233603141,0.014724702298602925,39.28664549439323,195.77800213084956,0.004626980508146301
0.0048980591247799,196.487144461398,0.015551337721176181,39.61180832341784,197.44955011222908,0.004886102659605986
0.0051746860314626,197.726199612178,0.016429628149893755,39.86160184181508,198.7493706153653,0.005161343353352726
0.0054622040684487,198.64785893508,0.01734249791732462,40.04740836131213,199.7329140783438,0.005447340333077508
0.005774584160278,199.34011607805,0.01833430470888265,40.186967401334876,200.4912223548623,0.005757975158543725
0.0060864475658513,199.951904379731,0.019324471021577878,40.31030392295377,201.16890116143034,0.0060679999596141496
0.0064173091091946,200.411309539412,0.020374956421692854,40.40292000314546,201.6974108617049,0.006396805851505536
0.006744979411396,200.72699668926,0.021415309631182298,40.46656253255482,202.08089614924043,0.006722333810144025
0.0070902186277553,200.914341953978,0.022511444143123074,40.50433133792197,202.3388685638833,0.0070652012106914965
0.0074351939723478,201.049622510361,0.023606740862204264,40.531603898088775,202.54446545179283,0.007407689169202152
0.0077820921674426,201.199271028207,0.024708142631630254,40.561773039286535,202.76502229937074,0.007751967873942345
0.0081403478137932,201.366265494005,0.02584560430879341,40.59543912359141,203.0054569330908,0.008107393899286271
0.0084978539840875,201.501789093272,0.026980686399477812,40.62276068120364,203.214121874519,0.008461950481345211
0.0088640317984868,201.62210694277,0.02814330096019559,40.64701675966243,203.4092917099886,0.008824976888259544
0.0092296209911913,201.7199061853,0.029304046647032376,40.666733086956484,203.58170446576898,0.009187288316372343
0.0095990770729811,201.793664034053,0.03047706970671499,40.68160266926508,203.7306969679551,0.009553298653226055
0.0099695372387524,201.860038472131,0.03165328073303887,40.69498375598161,203.87248964269492,0.00992016924856145
0.0103360752869476,201.89671544897,0.03281703903605863,40.702377834512355,203.983535100038,0.010283023313752701
0.0107078066767744,201.917074842696,0.03399728619875872,40.70648228828751,204.07916384485134,0.010650884098306624
0.0110758890657321,201.904485123956,0.035165947783699414,40.703944200989525,204.1407568030627,0.011015000589897328
0.0114428961898761,201.909793109347,0.03633119540285661,40.70501429084435,204.2202259116166,0.011377921449617126
0.0118053038916149,201.923943340773,0.0374818398558773,40.70786697749984,204.30771685490404,0.011736164897554054
0.012169591096438,201.931136387884,0.03863845173119065,40.70931709579742,204.3885557473636,0.012096136960111586
0.0125334117049464,201.889250380024,0.03979358216320482,40.70087287661284,204.41961147383986,0.012455518668857003
0.012904950280187,201.841023367048,0.040973217139593725,40.69115031079688,204.44577173810183,0.012822390933529288
0.0132855060284912,201.852000532686,0.04218148164045956,40.6933633073895,204.533706502626,0.013198027637960501
0.0136763447505171,201.85941640587,0.043422394582891786,40.69485834742339,204.62011537577487,0.01358366758152379
0.0140690442677836,202.019006148915,0.04466921555021293,40.727031639621266,204.86122048935772,0.013970993844774302
0.014456489392405,202.028518287889,0.04589935382088587,40.72894928683842,204.94914141948118,0.01435299064284646
0.0148370825832564,202.025896674037,0.04710773720183906,40.72842076948586,205.02337158694613,0.014728089840488205
0.0152148753798351,201.968823627226,0.04830722933097644,40.71691484324876,205.04175410932612,0.015100289970103748
0.0156000586000828,201.905976254494,0.04953018605526289,40.70424481290599,205.05572131577102,0.015479628548348069
0.0160035612420623,201.864893214564,0.0508113069435478,40.6959624720561,205.09545039574567,0.0158768543096573
0.01639071615548,201.868796686816,0.052040523793649,40.69674941206211,205.1775708339579,0.01625783837599332
0.0167893325310641,201.832101896669,0.05330613078612851,40.68935174236847,205.2207281708558,0.016649949621575406
0.0172085017575442,201.801215096703,0.054636993080202825,40.683124963495324,205.2739116613692,0.017062112530844865
0.0176005930562755,201.774747776855,0.05588188295367471,40.677789151813975,205.32610300150807,0.017447496402563673
0.0180015604107653,201.741812233536,0.05715495430417982,40.671149346280856,205.37347965383526,0.01784145094716142
0.0183989742012776,201.679265237896,0.05841674308905638,40.65853987195983,205.38995683594067,0.018231760995506822
0.0187902020849841,201.55479030089,0.05965889161982451,40.63344572465943,205.34204554184032,0.0186158469636341
0.0191974613692189,201.456141313384,0.06095193984727001,40.61355808877821,205.3235878038396,0.019015515025378543
0.0195988578496126,201.390536361519,0.06222637367252,40.60033213048223,205.33756085592566,0.019409273324622233
0.0200056476287751,201.334304753906,0.06351793122136094,40.588995838387454,205.36212791039705,0.019808164171807172
0.0204168490908039,201.299469362757,0.06482349586330238,40.581973023531816,205.40937025079532,0.020211219390279457
0.0208304040512412,201.223996948911,0.0661365328626908,40.56675778490046,205.41557411016257,0.020616417697793765
0.0212463682290716,201.190802344423,0.06745721912730232,40.56006575263567,205.46537621533494,0.021023810984108767
0.021664630158553,201.134597129713,0.06878520075340577,40.54873478135014,205.49210378861778,0.021433287398554407
0.0220852169554863,201.038894320305,0.07012056383366899,40.529441094973485,205.47888191786004,0.021844870844996814
0.0224894201999149,200.925377518666,0.0714039091347298,40.50655610776307,205.44407276250982,0.022240261888540943
0.0229023878154723,200.809531493941,0.07271508131412455,40.48320154917851,205.40854926125854,0.022644064836759126
0.023308004520955,200.69528808885,0.07400291435403213,40.46017007871216,205.37309477095928,0.0230405213422237
0.0237262420125689,200.587021040883,0.07533081838990625,40.438343441842015,205.34619724667925,0.023449149090530173
0.0241455272525859,200.48231618288,0.07666204902696022,40.41723494246861,205.32306741193526,0.023858632977332372
0.0245695212943359,200.384864566061,0.07800823010951648,40.3975886965179,205.30822476307947,0.024272545149358588
0.0249989526579558,200.325227984996,0.07937167468900966,40.38556596177519,205.33314887558709,0.024691590792733083
0.0254254090060328,200.292620291726,0.08072567359415413,40.37899225081196,205.38514208353317,0.02510755966454283
0.0258556688523889,200.228790083814,0.08209174860633475,40.3661240808969,205.4058393749356,0.025527063219965097
0.0262874987828976,200.158319512902,0.08346280863569988,40.351917213801045,205.41998109348424,0.025947920734872364
0.0267229489119934,200.070037231565,0.08484536279557904,40.33411950588351,205.4164986153247,0.026372127183616582
0.0271585053306722,199.918617133873,0.08622825442488423,40.303593214188794,205.3481079630039,0.02679625723679796
0.0275983610740603,199.78808089567,0.08762479641014145,40.27727710856708,205.30190449052225,0.02722439134579976
0.028034818916937,199.614475943333,0.08901055006127498,40.24227835017593,205.21063162960363,0.02764903700114707
0.0284869146127006,199.485183685531,0.09044595389532441,40.21621303100306,205.16790107967964,0.028088707242093756
0.0289272227177345,199.414892981869,0.09184393212880702,40.20204242514479,205.18341200438869,0.028516728128862936
0.0293730856934795,199.354788082707,0.0932595470767974,40.18992527747373,205.2104533564658,0.028949962269572957
0.0298107811160107,199.291905843962,0.09464923004333396,40.17724821814274,205.23295322726898,0.029375077710867774
0.0302524499112494,199.197913355486,0.09605152846821684,40.15829933246598,205.22413825169824,0.02980386921139429
0.0306896855710233,199.002388785766,0.09743975168799897,40.118881579210424,205.10970952548368,0.03022817580283721
0.0311375828142959,198.856765208371,0.09886182543538947,40.089523866007596,205.04868420322964,0.030662642120346802
0.0315860557264984,198.712352114449,0.1002857269316324,40.06041018627292,204.98889154187955,0.031097477801569018
0.0320408196077044,198.570736120559,0.10172960225446145,40.031860401904694,204.9331052559669,0.031538220160571305
0.0324957196833462,198.423649205037,0.10317390999462417,40.00220767973546,204.8715684881505,0.031978900259320944
0.0329493696400838,198.286982998454,0.10461424860726605,39.974655772488326,204.82041409608706,0.032418176003205276
0.0333968855682928,198.199221851442,0.10603511167932965,39.9569631252507,204.8184585833393,0.03285132309467449
0.0338496851099558,198.036188192102,0.10747275022410965,39.92409553952777,204.73965080278063,0.033289393284584794
0.0343014990551912,197.886413110021,0.10890725950023204,39.89390088298024,204.67421372234955,0.033726318743305866
0.034750355716754,197.725799809144,0.11033237940069394,39.861521241523434,204.59684168689148,0.03416019541736718
0.0352070636920548,197.556623235971,0.11178242722227398,39.82741524437175,204.51201185302708,0.03460146824590872
0.0356674670255487,197.451166568154,0.11324420780611713,39.80615518013985,204.49374954087978,0.03504611453833288
0.0361265911209346,197.314759422741,0.11470192680896736,39.778655499624584,204.4430690585319,0.03548932857410659
0.0366018706896055,197.190461310576,0.11621093943949745,39.753597000212125,204.40800107668935,0.03594793141162989
0.037071336708113,197.086095316145,0.11770149404825878,39.73255681573483,204.39234031609706,0.03640071830674286
0.0375517438513918,196.9806400022,0.11922678672816897,39.71129702444352,204.37760653924582,0.036863845470772934
0.0380347056272612,196.853414726996,0.12076019036655432,39.68564840896239,204.34067640785844,0.03732921927845718
0.0385230151019926,196.734417207166,0.12231057294882651,39.66165850896466,204.31322013231937,0.03779952595845705
0.0390053641904145,196.615227026754,0.12384203130456602,39.63762976859361,204.28427556231358,0.03826387494343035
0.0395022839978031,196.474927285703,0.12541975169302486,39.609345340797724,204.23613566179057,0.03874202552160059
0.0399999040888282,196.334610324615,0.12699969548202952,39.58105744144239,204.18797590691705,0.03922062093099641
0.0404991051369106,196.196888751808,0.12858465880969117,39.55329277236449,204.1426871769022,0.03970050681938077
0.0409931638223855,196.070566478959,0.13015329513607396,39.52782620215814,204.10811933137887,0.04017522267792216
0.0414775093409634,195.923582609847,0.13169109215755878,39.498194254145155,204.05000483766193,0.04064038699793213
0.0419720659747255,195.752177137043,0.13326130946975345,39.46363891082787,203.96830043053512,0.041115134886156
0.0424696678891719,195.540716106849,0.13484119554812077,39.42100836714076,203.84526537871773,0.04159257871758067
0.0429683066657761,195.350683284053,0.1364243736638391,39.382697750065084,203.74457135077105,0.042070788851078574
0.0434769045066073,195.183976995284,0.13803917180847816,39.34908976224926,203.6699721243278,0.0425583145701164
0.0439798433902316,195.0584943514,0.13963600276398533,39.32379246124224,203.63713638490893,0.0430401821765833
0.0444717674946686,194.92836155191,0.1411978617955728,39.29755768886506,203.59717032496326,0.043511271964798315
0.0449597533183601,194.765771932238,0.1427472167857933,39.26477962153918,203.52239299317142,0.043978371104160446
0.0454378258366898,194.506295108348,0.14426509703149012,39.21246909384296,203.34423826962094,0.04443576976500078
0.0459272508788015,194.216389701789,0.14581902154019474,39.15402416388067,203.13621455639816,0.044903813394968045
0.0464371806344973,194.040579854431,0.14743804851452894,39.11858089865329,203.0512773115538,0.0453912330414801
0.0469485469659674,193.861162546055,0.14906163661694646,39.08241036928469,202.9626624407255,0.0458797873818478
0.047467494949546,193.876434696412,0.15070929646480855,39.08548923479666,203.0792633811999,0.04637534125826284
0.0479760864809383,193.831772124784,0.15232407457697908,39.076485260356456,203.13106198699614,0.04686076739513077
0.0484921614240822,193.736353704606,0.15396261252146098,39.05724890684857,203.13104824216285,0.04735309534150816
0.0490149608655273,193.563436002153,0.15562250074804918,39.02238869803405,203.05094024279552,0.047851591338699824
0.0495564978843563,193.36220454152,0.15734188078283126,38.981820435570434,202.9445582217963,0.0483676919733401
0.0500981792010218,193.183864641624,0.15906171896324423,38.9458671117514,202.86202451118604,0.04888366379917851
0.0506471887294666,193.043711377379,0.16080482421605644,38.91761221367961,202.8208326605458,0.049406344509867944
0.0511890222461338,192.929290980115,0.1625251456314748,38.89454506159119,202.80515274802693,0.04992192562493336
0.0517303057258134,192.776655880972,0.16424372067945753,38.86377382560396,202.7490512264946,0.05043671807030548
0.0522736330345099,192.61799357083,0.16596878488456893,38.83178750387933,202.68683588259518,0.05095318794069364
0.0528188127535051,192.446817282734,0.16769973049237868,38.79727836419917,202.61162968979875,0.05147115068601129
0.0533491501650879,192.285653427432,0.16938355177415407,38.76478773097029,202.5439296267241,0.05197475479748608
0.0538823652123868,192.078523906083,0.17107650954932807,38.72303041946633,202.42816908064674,0.05248083593265168
0.0544122211334474,191.73143577385,0.17275880209869549,38.65305745200816,202.1639690554101,0.05298347530349461
0.0549425664907301,191.468350302402,0.17444264860806805,38.600019420964244,201.98811286976215,0.0534863261008754
0.055484601523649,191.252063660846,0.17616360983758556,38.556416034026554,201.8636082036436,0.05399999940176194
0.056026833927648,191.169742509373,0.17788519772028238,38.5398200898896,201.88037792493688,0.054513595877551155
0.0565827107794119,191.029210556417,0.17965010672463277,38.51148884817367,201.83816112775014,0.05503984254342006
0.057149256733213,190.908761153132,0.18144889012795126,38.48720624847141,201.819054956892,0.05557590480304026
0.0577076328720913,190.711649982064,0.18322173436888986,38.4474686363841,201.7171678636597,0.056103955806961606
0.0582657456711763,190.576931145748,0.18499374250598474,38.4203093189828,201.68103814667944,0.05663147927931449
0.058835806236359,190.447306793736,0.18680368480043982,38.39417704961718,201.65242763448867,0.05717000855151316
0.0594083685116236,190.302450572868,0.1886215700244049,38.36497403549019,201.60800868516597,0.057710609390674635
0.0599932686706933,190.146316337698,0.19047862802945123,38.33349737367992,201.55381538048815,0.05826255779314569
0.0605813036002,189.994140368575,0.19234563893063497,38.30281869830472,201.50423306850266,0.05881715743068591
0.0611692831155894,189.833809205543,0.19421247389199633,38.27049593583747,201.44580722574764,0.05937139743808553
0.0617509334311427,189.636280387709,0.19605921364387804,38.230674126162135,201.34649771405995,0.059919369354857796
0.0623233338606257,189.423611886028,0.1978765850074866,38.18780015622325,201.2291228906865,0.0604583339778498
0.0628994625844136,189.198751840953,0.19970579370551317,38.14246837113613,201.0992516533908,0.06100051594471463
0.0634838424747294,188.991867948536,0.2015611998572658,38.100760578424854,200.98979792238575,0.06155016275922615
0.0640815282236687,188.762754538903,0.20345885211014808,38.05457131504285,200.85896032146516,0.06211201225432845
0.0646795075700949,188.570615182186,0.20535743653505129,38.0158360207287,200.76726971435968,0.06267382201324462
0.0652688155009916,188.359285401538,0.20722848921564832,37.973231936950064,200.65327284830957,0.06322717623273483
0.0658570061790824,188.20186857779,0.2090959946185866,37.94149670528247,200.5962801996324,0.06377917620105442
0.0664374221650737,188.04765728234,0.210938815374109,37.91040770811974,200.5410588763599,0.06432358131941991
0.0670211426716201,187.780553518106,0.2127921279823938,37.85655958925017,200.36582078639876,0.06487078718573737
0.0675996636142922,187.531309001945,0.21462893197537775,37.80631189479211,200.20836240762438,0.06541282346228143
0.0681787940701284,187.274521850608,0.21646767117265767,37.754543605082574,200.04267291044238,0.06595513670450584
0.0687783787458469,187.06749552779,0.2183713525180639,37.712807098402465,199.93369458623735,0.06651629412879095
0.0693792301823861,186.902012713581,0.22027905582907586,37.67944576305793,199.8691304751878,0.06707832140858211
0.0699981377267307,186.75384988036,0.22224408728236997,37.64957613588058,199.82627158528263,0.06765690802999247
0.070619721404602,186.618664992544,0.22421761545961133,37.62232286249687,199.79762312321623,0.0682376596972647
0.0712531063989676,186.459098463083,0.22622861281672213,37.59015425015753,199.74488844492862,0.06882909071464942
0.0718774037028506,186.343680338044,0.22821075675655064,37.566885956149676,199.73758027717656,0.0694116938912632
0.0725119602584715,186.166204801902,0.23022547382064698,37.53110688806345,199.66548124596798,0.0700035235140051
0.0731384476827742,185.960502124978,0.23221457139280804,37.489637228395566,199.5613645807081,0.07058748392040422
0.0737615992735417,185.697778761111,0.23419307769349487,37.43667219823998,199.39514390407487,0.07116799684102287
0.0743586222576684,185.434720123715,0.23608862566809716,37.38363957694094,199.2233904308508,0.07172385306686611
0.0749806931220815,185.148978452329,0.23806370066260873,37.326034055989524,199.03157718752996,0.07230270153190967
0.0756198783518061,184.862633729742,0.24009311376698436,37.26830695991599,198.84192360417956,0.07289712641677548
0.0762628893502527,184.648193191853,0.24213467368705233,37.22507574747757,198.72999791796735,0.07349475285557187
0.0769297016333564,184.443675639918,0.24425180268590654,37.18384500900748,198.63287257505647,0.0741141236514894
0.0775678477327593,184.290213598658,0.2462779165515108,37.15290706148946,198.5852088257164,0.07470650874680056
0.0782048102392861,184.092896167437,0.24830027250973336,37.1131278673553,198.489846178612,0.07529744538634577
0.0788313373501174,183.826527023404,0.2502894960866227,37.05942784791824,198.31781798908645,0.07587836020240085
0.0794703315169601,183.594244457479,0.2523183025663483,37.012599682627766,198.18453992912066,0.07647048705355415
0.0800892362164436,183.336292078511,0.2542833249872084,36.96059648302782,198.01955568183376,0.07704366384911462
0.0807170875525404,183.068282299937,0.25627675297931574,36.906565711667305,197.8450208704342,0.07762479076165622
0.0813576067469984,182.789517147378,0.2583104014217199,36.850366656911405,197.6608348009281,0.07821729500296211
0.0819895715030935,182.479582144284,0.26031688952232185,36.787883760287656,197.44100489235737,0.07880154221064585
0.0826267811364637,182.215646030349,0.2623400301082722,36.73467423971836,197.27153833453798,0.07939029286939366
0.0832700065536831,181.988398941195,0.26438227080794385,36.68886122654491,197.1425741137226,0.07998425047603985
0.0839304360670967,181.775300455778,0.266479134513032,36.645900571884845,197.03178068925897,0.08059372758841869
0.0845979201224308,181.59997114179,0.26859839638871774,36.61055418218486,196.9629509946789,0.08120933777816684
0.0852704176520508,181.398736669171,0.27073357604526127,36.569985312504876,196.8666827065056,0.08182918879810652
0.0859376318964847,181.190384296955,0.2728519812713389,36.52798147426613,196.7614568458493,0.08244379066970053
0.0866080631560734,180.934134724167,0.274980600520533,36.476321560392066,196.60448969144716,0.08306097564527752
0.0872637836747914,180.642561681683,0.27706251316746267,36.41754043502729,196.40611510673352,0.08366424997311861
0.0879188893208103,180.287808122625,0.2791424735935727,36.3460221175212,196.13851197084955,0.08426659539813418
0.0885825781768191,179.960343851194,0.28124968571140063,36.28000532040072,195.90169507911963,0.0848764630104384
0.0892403735546165,179.590508383646,0.2833381860359074,36.20544649014304,195.61723243866606,0.08548054829411866
0.0899242515829927,179.279570343773,0.28550949877600185,36.14276138130464,195.4011515310573,0.0861081998656781
0.0906002062406431,179.020725702156,0.2876556548140418,36.09057830155465,195.24004037212092,0.08672819261730949
0.0912654603564264,178.705004294776,0.2897678366316538,36.02692886582684,195.01459877973588,0.08733799563734243
0.0919354448132895,178.412111531106,0.2918950372821941,35.96788168467097,194.81450836479644,0.08795175910391914
0.0925995221790285,178.092116253329,0.2940034829184155,35.90337063667113,194.5833611222393,0.08855973965468072
0.0932649193196736,177.66770385343,0.29611611883996364,35.81780909685149,194.2378679190318,0.08916855797713967
0.0939198877805966,177.353493169705,0.2981956437033942,35.754464223012526,194.0105133457005,0.08976747259868877
0.0945724114691426,176.994201689529,0.3002674064145277,35.68203106060905,193.73297015936356,0.09036379519768183
0.095233947593374,176.564022767489,0.30236778360896244,35.59530698992579,193.37891165860333,0.0909679912185931
0.0959137420306236,176.135996258907,0.3045261309472299,35.50901684579565,193.02985876639067,0.09158848290181407
0.0965972949908063,175.711167429205,0.30669641159580996,35.42337135372773,192.68439090254287,0.09221201726108298
0.0972717824829433,175.394105490559,0.30883790938334493,35.359451666896696,192.45500276862705,0.09282690127609868
0.0979507031311525,175.113239234779,0.3109934824414092,35.30282902973145,192.2657041453993,0.09344544511327636
0.0986356385805307,174.697962688645,0.31316815249318497,35.219109278030835,191.9294077971572,0.09406908139705973
0.0993412399526098,174.178727983075,0.31540843684953607,35.11443156138792,191.48185879428198,0.09471112763804536
0.100045266341859,173.685232320576,0.3176437206354023,35.01494283582812,191.0616176477357,0.09535133017750841
0.100748389705833,173.222265259959,0.31987613731601977,34.921608676407736,190.6741295460965,0.09599030274630407
0.10144878691945,172.874589151664,0.32209989846925374,34.85151717297546,190.4125065102986,0.09662639223426353
0.102153408076803,172.383174360363,0.3243370706438495,34.752447951049184,189.99270311637184,0.09726590982320743
0.102863623557583,171.79519329341,0.32659200479532596,34.63391096795146,189.46666938534554,0.09791009124688878
0.103585763987697,171.194836130503,0.32888480066093795,34.51287896390941,188.92818402182974,0.0985646636653403
0.104299921677654,170.617238518184,0.33115225132655146,34.396435285265895,188.4126031324882,0.09921157914606456
0.105020116685859,170.059232349795,0.33343887047760234,34.28394124171867,187.91887277467808,0.09986353994957832
0.105724811493151,169.439382590843,0.3356762764907544,34.15897953031395,187.35332937477577,0.10050105793926319
0.106428854934355,168.77072613342,0.3379116144165771,34.024178388497475,186.73280126223952,0.1011375810485388
0.107144968094223,168.040134645817,0.340185273699158,33.876891144596705,186.044789510992,0.10178460097387437
0.107870475593355,167.311212893402,0.3424887600089021,33.72994051930984,185.35915300031436,0.10243968220786265
0.10859099421669,166.582940071724,0.3447764066379907,33.58312071845956,184.67234715365183,0.10308983440633682
0.109324696662627,165.860674229022,0.3471059119038407,33.437511924570835,183.9933421273686,0.10375144880017323
0.110059697748956,165.082873688241,0.3494395403529353,33.28070733554939,183.2518448698979,0.10441379563387228
0.110802963779241,164.251777434603,0.35179940999909015,33.11315833081597,182.45136118036527,0.10508314459534632
0.111537055775221,163.411901821533,0.35413015208632664,32.943839407221056,181.63838422933628,0.10574379239561157
0.112286772904466,162.560301005599,0.3565105039716795,32.77215668272876,180.81367260789634,0.1064180518832379
0.113030284389298,161.659736000864,0.3588711529360211,32.59060277777419,179.9321819353405,0.10708628161711943
0.113783811090103,160.702013461606,0.361263600211077,32.397525913859766,178.98730100312056,0.10776305722321594
0.114544899957173,159.751644654317,0.36368005736402426,32.205931562310305,178.05038080923958,0.10844616011812751
0.115336540092703,158.652141055241,0.366193514794332,31.984271636736587,176.950530082852,0.10915618905022231
0.116109665505562,157.655628205437,0.3686481879801593,31.783374646216103,175.96097046143956,0.10984912571331971
0.116868667753422,156.527392760264,0.3710580201171148,31.555922380469223,174.82054061907272,0.1105289373046691
0.117630111294946,155.390146991143,0.3734756033614535,31.32665363341443,173.6687072758492,0.11121047141705
0.118419624378087,154.051349456515,0.3759823074004262,31.056752050433424,172.29405239409294,0.11191663917651841
0.119266628408485,152.72503120116,0.37867154519693985,30.789366290153854,170.940030746103,0.11267367477057881
0.120147170766354,151.408850771508,0.3814672671831739,30.524024315536018,169.60019582068978,0.11346007914441372
0.12104524186092,150.123745740786,0.384318642908421,30.26494714134246,168.29551085304672,0.11426150175995874
0.122005260680243,148.699456392401,0.3873667026597715,29.97781040870804,166.84157233256633,0.11511749575283109
0.12302010887458,146.974929325727,0.3905888456767915,29.630145752066564,165.05580113321162,0.11602158198475084
0.123838448463862,145.587944139295,0.3931870738727618,29.35052953848187,163.6173292565487,0.11675001201680087
0.124388000541869,144.611810831574,0.3949319017204341,29.153741063645317,162.59978483565246,0.11723888811662193