File: example/data/02 processed data/test_ID_071.csv
Strain,Stress_MPa,Displacement(mm),Force(kN),True Stress (MPa),True Strain
6.85458920617066e-05,0.184332328689961,0.00021763320729591842,0.037161397463896136,0.18434496391386687,6.854354289942363e-05
5.77799848862528e-05,0.698258662247748,0.00018345145201385262,0.140768946309146,0.6982990076226994,5.777831568717866e-05
4.87939857705057e-05,1.63657699922864,0.0001549209048213556,0.32993392304449387,1.6366568543434528,4.879279538271086e-05
4.561832926175e-05,2.91237435286149,0.00014483819540605624,0.5871346695368764,2.912507210513652,4.5617288777304004e-05
5.33587363304109e-05,5.0237734678182,0.0001694139878490546,1.0127927311121492,5.024041530022053,5.33573128037667e-05
5.28369708572427e-05,7.70826062659655,0.00016775738247174559,1.5539853423218646,7.708667907738637,5.2835575033650984e-05
5.98192654244248e-05,11.0231783774845,0.00018992616772254872,2.222272760900875,11.023837775917684,5.981747632351133e-05
9.68144450692949e-05,14.8374596720181,0.0003073858630950113,2.9912318698788494,14.838896152442485,9.680975885333263e-05
0.0001331375619212,19.1087232092717,0.00042271175909980996,3.852318598989175,19.11126729809121,0.00013312869990249863
0.0001859087106869,23.4583589967875,0.0005902601564309074,4.72920517375236,23.46272011006342,0.00018589143180394168
0.0002513273630683,27.8857373516246,0.0007979643777418525,5.62176465008752,27.892745800460396,0.0002512957856372341
0.0003137097673046,32.3434303107433,0.000996028511192105,6.52043555064585,32.35357676073991,0.0003136605706841466
0.0003850029615781,36.8411899930128,0.0012223844030104674,7.427183902591381,36.855373960268174,0.0003849288669551178
0.0004607913051825,41.4766493641687,0.0014630123939544373,8.361692511816411,41.49576144356381,0.00046068517347072445
0.0005322317356616,45.9680198248956,0.0016898357607255797,9.267152796698953,45.99248546387193,0.0005320901505864558
0.0006156790669916,50.5007355257731,0.00195478103769833,10.180948281995859,50.531827771504,0.000615489614392138
0.0006963879987835,55.1080376881418,0.0022110318961376125,11.109780397929388,55.14641426422433,0.0006961456331749582
0.0007747994751489,59.6884951224318,0.0024599883335977572,12.033200616682253,59.734741737125084,0.0007744994729864673
0.0008636214510142,64.381644243964,0.002741998106970085,12.979339479583144,64.43724561298465,0.000863248744578349
0.0009488906861054,69.1438856247543,0.003012727928384645,13.939407341950469,69.20949561382477,0.000948440773927553
0.0010358660194908,73.726718696629,0.0032888746118832895,14.863306489240408,73.80308969925541,0.0010353298804992367
0.0011219008159882,78.5656891759014,0.003562035090762535,15.838842937861724,78.65383208669651,0.0011212719555697814
0.0012109414808743,83.2352277374893,0.0038447392017759018,16.78022191187784,83.33602072742664,0.0012102088826020363
0.001299910449228,87.9621507700463,0.0041272156762989,17.733169595241336,88.07649368896885,0.0012990662971088581
0.0013889227389013,92.6600868556074,0.004409829696011627,18.680273510090455,92.78878455722972,0.0013879590779111537
0.0014753274561585,97.1930043566598,0.004684164673303237,19.594109678302615,97.33639586453371,0.0014742402298189591
0.0015645060046537,101.717628777423,0.0049673065647754975,20.50627396152848,101.87676661842441,0.00156328344010794
0.0016511250559129,106.125631652254,0.005242322052523458,21.39492734109441,106.30085834174962,0.001649763447522118
0.0017395072664488,110.52747980109,0.00552293557097494,22.282339927899745,110.71974315534626,0.0017379960759145742
0.001828224049041,114.799444458998,0.005804611355705175,23.143568002934,115.0093235641745,0.0018265548815527442
0.001917830021098,118.914529965841,0.00608911031698615,23.973169241113546,119.14258782135425,0.0019159933330318635
0.0020047480053802,123.291492070694,0.006365074917082134,24.855564801451912,123.53866044350308,0.002002741179769816
0.0020927894079132,127.477050095447,0.006644606370124409,25.699373299242115,127.74383271563877,0.002090602574683078
0.0021805930304471,131.61398589783,0.006923382871669542,26.533379557002526,131.90098243818815,0.0021782189880519462
0.0022666630655893,136.006598864537,0.007196655233246027,27.41893033109066,136.31487999885965,0.002264098060133587
0.0023539462775293,140.380333763192,0.007473779431155527,28.30067528665951,140.71078152729217,0.002351180086117376
0.0024369059804242,144.930987130065,0.007737176487846834,29.218087005421108,145.28417031935103,0.0024339415401102085
0.0025195172192074,149.197139502792,0.007999467170983494,30.078143323762866,149.57304426482577,0.0025163485569152876
0.0026026671818823,153.343287125017,0.008263468302476302,30.914006684403432,153.74238866597926,0.0025992861089203785
0.0026842845766452,157.747456400216,0.00852260353084851,31.80188721028355,158.17089546443614,0.0026806883189495834
0.0027640746946751,161.884096458845,0.008775937155593442,32.635833846103154,162.33155619333724,0.0027602616649328483
0.0028429167312646,165.764210783502,0.009026260621765104,33.418064893954,166.2354646317833,0.002838883286184922
0.0029199079388062,169.676052045332,0.009270707705709685,34.20669209233893,170.17149049672446,0.0029156532877348744
0.0030001631765364,173.507613077898,0.009525518085503068,34.97913479650423,174.02816422950303,0.0029956716682562287
0.0030769253604996,177.555993596253,0.00976923801958623,35.795288309004604,178.102320135858,0.003072201313541881
0.0031544471560919,181.361630702894,0.010015369720591782,36.56250474970343,181.9337263830889,0.003149482325784763
0.0032306602355602,185.132885702446,0.010257346247903634,37.322789757613116,185.73098715457942,0.0032254528652633117
0.003308242473201,189.237395558318,0.010503669852413175,38.15025894455692,189.86343874782196,0.0033027822781888
0.0033880363076353,193.387891285278,0.010757015276742077,38.986998883112044,194.04309648240954,0.003382309843291859
0.0034663583369136,197.344621579808,0.01100568771970068,39.784675710489296,198.02868875406625,0.00346036436436439
0.0035442016570405,201.340924922803,0.011252840261103587,40.59033046443709,202.05451776254444,0.0035379357750160542
0.0036260621232614,205.318314725626,0.011512747241354945,41.3921722486862,206.06281168986445,0.003619503809122091
0.0037054320951173,209.320917354202,0.011764746901997428,42.19909693860713,210.09654179954566,0.0036985838934289915
0.0037862590209421,213.153568273934,0.012021372391491168,42.971759364025104,213.9606228946572,0.0037791091839954735
0.0038650704570759,216.803186234405,0.012271598701215983,43.707522344856045,217.64114582451953,0.0038576202631028567
0.0039463264845124,220.410439333674,0.012529586588326869,44.43474456966867,221.28025088787948,0.0039385601637374435
0.0040285127085174,224.192829419324,0.012790527849542745,45.19727441093572,225.0959930817982,0.004020419978359368
0.0041106618582026,227.601528876447,0.013051351399793253,45.884468221491716,228.53712180006798,0.0041022361699574765
0.0041904626551201,231.400262846119,0.013304718930006319,46.65029298977759,232.36993700596065,0.0041817071178004645
0.0042699853442507,235.137875237733,0.01355720346799597,47.40379564792698,236.14191051887636,0.004260894825232146
0.0043484856722272,238.84011139364,0.01380644200932136,48.15016645695783,239.87870419598838,0.0043390583283056255
0.0044297912855048,242.298732302475,0.01406458733147774,48.84742443217896,243.37206511531733,0.004420008639501849
0.0045085837814369,245.741032033204,0.014314753506062155,49.54139205789393,246.84897606466248,0.004498450563804291
0.0045866104525674,248.817521362675,0.014562488186901494,50.16161230671528,249.95875040693895,0.004576124007445587
0.0046654753261653,252.148330956721,0.014812884160574828,50.83310352087496,253.32472277333332,0.004654625728754296
0.0047484133614422,254.9613521171,0.015076212422578984,51.40020858680736,256.17201400814423,0.004737175208272617
0.0048318850588973,257.71730797603,0.015341235061998929,51.955809287967654,258.9625683858586,0.004820248970061354
0.004916118681804,260.639305097977,0.015608676814727699,52.544883907752165,261.9206388549816,0.00490407402952086
0.0050032518239898,263.714538595541,0.015885324541167613,53.16485098086107,265.03396884178176,0.00499077715156533
0.0050948258763196,266.650363804785,0.01617607215731473,53.75671334304466,268.0089009782277,0.005081891165761171
0.0052003868191882,269.649994933261,0.016511228150922534,54.361438978545415,271.0522792127061,0.00518691150535983
0.0053188673717796,272.365690967974,0.01688740390540023,54.90892329914355,273.81436795485575,0.005304772155022087
0.0054548751368703,274.872795086284,0.017319228559563204,55.41435548939485,276.37219186200224,0.005440051189577651
0.0056201318031758,277.069705709249,0.017843918475083164,55.8572526709846,278.62687397400214,0.005604397786404909
0.0058182400212375,278.78582820378,0.018472912067429063,56.20322296588205,280.407871066789,0.005801379430463369
0.0060435295374689,280.156752189107,0.019188206281463754,56.47960124132397,281.84988779608324,0.006025340659392806
0.0063013115922529,281.256216806023,0.020006664305402957,56.70125330809424,283.02849986537603,0.0062815413372540796
0.0065812215651095,282.020204485666,0.02089537846922266,56.85527322431027,283.87624193722365,0.006559659876264631
0.0068826508914023,282.6011206756,0.0218524165802023,56.97238592820096,284.54616553072924,0.006859073570911142
0.0071999595376949,283.076454712473,0.022859871532181306,57.06821327003456,285.11459373247686,0.007174163574940389
0.0075299968744939,283.46832536367,0.02390774007651813,57.14721439331587,285.60284096767646,0.007501787968175697
0.0078648252097178,283.802716535422,0.024970820040854012,57.21462765354107,286.0347752950162,0.007834058682216798
0.008211068112017,284.090263227093,0.026070141255653975,57.27259706658195,286.4229477284115,0.008177540697800058
0.0085584126873802,284.323079525129,0.027172960282432133,57.319532832266006,286.75643377625187,0.008521997099093579
0.0089102256635874,284.5274229532,0.028289966481889993,57.36072846736513,287.062626499192,0.008870763838844197
0.0092651961872873,284.738910045629,0.029416997894637177,57.40336426519881,287.3770719093561,0.00922253754842091
0.0096240745656017,284.934770386728,0.030556436745785398,57.44284970996437,287.6770038632625,0.009578058167895585
0.0099831613372915,285.103030261502,0.03169653724590051,57.476770900718805,287.9492598103533,0.00993365877091405
0.0103452679854753,285.276289155767,0.032846225853884074,57.511699893802636,288.22754881698535,0.010292121926513366
0.0107049791990471,285.426336576409,0.03398830895697454,57.541949453804065,288.4818195723197,0.01064808657199528
0.0110661330446642,285.570225083178,0.03513497241680883,57.57095737676868,288.73038318754317,0.011005351395170846
0.0114246295516218,285.700164951236,0.03627319882639921,57.59715325416918,288.9641834986411,0.01135986130675333
0.011781051853895,285.820375756147,0.03740483963611663,57.62138775243923,289.1876404238299,0.011712195534791617
0.0121352830322983,285.927076929453,0.0385295236275471,57.642898708977725,289.39688293458966,0.012062240816717997
0.0124859477481797,286.037751798277,0.039642884100470545,57.665210762532645,289.6092042212371,0.012408641135016338
0.0128327574569001,286.144018677534,0.040744004925657815,57.68663416539086,289.8160354669655,0.012751115345340555
0.0131804088588917,286.249105382839,0.041847798126981146,57.707819645180344,290.02198562727676,0.013094303051307815
0.0135286309596276,286.34695138463,0.04295340329681763,57.72754539914141,290.2208336163271,0.013437936101065992
0.0138786284039679,286.451451309354,0.04406464518259808,57.74861258396577,290.4270045578538,0.013783202150795856
0.0142313121135359,286.552172188994,0.04518441596047648,57.768917913301195,290.6301855882273,0.014130997609096614
0.0145839816166797,286.652395044042,0.04630414163295805,57.789122840878875,290.83292830374154,0.014478658145554319
0.0149376019399073,286.747023770422,0.04742688615920567,57.80819999211708,291.03033666895766,0.014827134682755093
0.0152921788710478,286.835676390292,0.04855266791557676,57.82607236028287,291.22201886025033,0.015176432026432214
0.0156478712861583,286.931266065183,0.0496819913335526,57.845343238740895,291.42112958454544,0.01552670570262432
0.016000222678581,287.032822037761,0.05080070700449467,57.86581692281261,291.62541110642667,0.015873568328097748
0.0163498796739187,287.124513899269,0.05191086796469187,57.88430200209264,291.8189651529545,0.01621765963242865
0.0166954721116188,287.200737914257,0.05300812395438969,57.899668763514214,291.9956898245408,0.016557634774375433
0.0170369407282164,287.278907532069,0.05409228681208707,57.915427758465114,292.17326125215965,0.016893439640001454
0.0173788487491357,287.369421540223,0.05517784477850585,57.933675382508966,292.36357125229716,0.0172295636770904
0.0177188852283896,287.474615662593,0.05625746060013698,57.95488251757875,292.5683453835939,0.0175637358170727
0.0180521566581399,287.595077570039,0.05731559738959418,57.97916763811986,292.78678896444325,0.017891151254143443
0.0183857215680291,287.725392907022,0.05837466597849239,58.00543921005564,293.0154318690623,0.018218747707184225
0.0187162276272509,287.868576579621,0.0594240227165216,58.03430503845159,293.2563903856179,0.018543234228099215
0.0190443264231001,288.025846237288,0.060465736393342816,58.06601060143726,293.5111044713206,0.0188652532190275
0.019374910681467,288.19522683861,0.06151534141365772,58.10015773066378,293.77898361743314,0.019189606772258855
0.0196999539148288,288.370492726362,0.06254735367958143,58.13549133363458,294.0513781434678,0.019508421193208968
0.0200206126529699,288.53517100114,0.06356544517317943,58.16869047382982,294.31182189651224,0.01982283557529483
0.0203405808145777,288.684765121982,0.0645813440862842,58.19884864859158,294.5567809168831,0.02013647432244929
0.0206575027724185,288.82846993104,0.06558757130242873,58.22781953809766,294.79494484939386,0.020447030185226846
0.0209724651905359,288.961385901338,0.06658757697995148,58.25461539770975,295.0216185085628,0.020755570347311385
0.0212865831252294,289.09066926292,0.06758490142260334,58.28067892340468,295.24442182491333,0.021063188460135607
0.0215970882534219,289.215383792432,0.06857075520461452,58.30582137255429,295.4615939604445,0.02136717554949757
0.0219057793208507,289.320506853856,0.06955084934370097,58.32701418173737,295.65829802999326,0.021669295086176526
0.0222167364653927,289.426631511965,0.07053813827762181,58.34840891281215,295.85674671033263,0.021973540203129235
0.0225256754692786,289.529489474014,0.07151901961495956,58.36914507796122,296.05133679269153,0.02227571910295894
0.0228323727607342,289.633143139291,0.07249278351533109,58.39004165688107,296.2461550273104,0.022575615049313803
0.0231390553953212,289.748088119788,0.07346650088014481,58.41321456494927,296.45258518148023,0.02287540675966073
0.0234479167698551,289.853457656303,0.07444713574428993,58.43445706351069,296.64991740688276,0.023177237447610393
0.0237560805710389,289.953866453917,0.0754255558130485,58.45469947710966,296.84203386728046,0.023478295675233567
0.0240653294675918,290.053875664907,0.07640742105960395,58.47486133404526,297.03411774613494,0.023780322890485726
0.0243719929100106,290.147607748037,0.07738107748928365,58.49375772200426,297.2190831869287,0.024079734975356086
0.0246805404504508,290.241471436086,0.07836071593018128,58.51268064151493,297.40478781226267,0.024380896158633637
0.0249890127422605,290.322053807564,0.07934011545667709,58.5289260476049,297.5769153095204,0.024681893257076246
0.0252985644711865,290.390107599477,0.08032294219601713,58.54264569205457,297.73656045837714,0.024983852586799905
0.025605772685639,290.46841012489,0.08129832827690382,58.55843148117782,297.90607820690684,0.025283435762069748
0.0259146275729563,290.540033723327,0.08227894254413624,58.572870798622716,298.06927049230114,0.025584534293297444
0.026219867455651,290.611568956347,0.08324807917169193,58.587292301599554,298.23136577546126,0.025882019556261796
0.0265278081646339,290.685781962259,0.08422579092271262,58.60225364359141,298.3970386223404,0.02618204738233126
0.0268336323476116,290.753922437611,0.08519678270366682,58.61599076342238,298.5559062959278,0.026479924004736987
0.0271412141242028,290.820263602204,0.0861733548443439,58.629365142204335,298.71347864828857,0.02677942307544753
0.0274473362054925,290.883833161846,0.08714529245243868,58.64218076542815,298.8678195273816,0.02707741177348225
0.0277522408485516,290.940330437428,0.08811336469415133,58.65357061618548,299.01457656028464,0.02737412713747919
0.0280563712690524,291.000800097002,0.08907897877924136,58.665761299555605,299.1652265841148,0.027670001394379324
0.0283592688437179,291.066529632541,0.09004067857880434,58.67901237392027,299.32096359779825,0.02796458928891547
0.0286585893769409,291.131177981449,0.09099102127178735,58.69204548106012,299.47458686604443,0.02825561304851899
0.0289577243986185,291.212201020056,0.09194077496561373,58.70837972564329,299.6450436787099,0.028546371847214747
0.0292543130826185,291.30054602698,0.09288244403731373,58.72619007903917,299.82234340159096,0.02883457216929203
0.0295512193171578,291.388255602439,0.09382512133197601,58.743872329451705,299.99913385019073,0.02912299789180473
0.0298472162148998,291.486045494186,0.09476491148230685,58.7635867716279,300.186092517677,0.029410457467060388
0.0301388857938898,291.600001132509,0.0956909623956001,58.78656022831382,300.38850026413985,0.029693633727963027
0.0304361361331187,291.717327049068,0.09663473222265187,58.81021313309211,300.59607532752295,0.029982145757981537
0.0307347067921541,291.846206734517,0.09758269406508926,58.83619527767863,300.8160143269048,0.030271855523815453
0.0310321923139044,291.964637682351,0.09852721059664646,58.860070956761966,301.0249404677691,0.030560428906134793
0.0313302142937884,292.090258800246,0.09947343038277816,58.885396174129596,301.24150920158576,0.03084943919938258
0.0316285798205203,292.232131609599,0.10042074093015195,58.913997732495154,301.475018910334,0.031138699003954082
0.0319263941537798,292.385533038106,0.10136630143825086,58.94492346048218,301.7203488107436,0.03142734102133014
0.0322248107186561,292.544028569086,0.10231377403173311,58.97687615952774,301.9712045165979,0.03171648317937642
0.0325205525341499,292.694735680323,0.10325275429592592,59.007258713153114,302.213330208484,0.0320029512570191
0.0328123467786133,292.841725026688,0.10417920102209721,59.0368917653803,302.450549259511,0.03228551514442137
0.0331038601359708,292.984717582861,0.10510475593170729,59.06571906470477,302.6836426957009,0.03256772732545431
0.0334000712798349,293.116232960938,0.10604522631347581,59.092232564925105,302.90633603511003,0.032854405846980024
0.0336940186799259,293.232557560554,0.10697850930876472,59.11568360420769,303.11274083256177,0.03313881225450668
0.0339881214901974,293.332203624933,0.10791228573137673,59.135772250786495,303.3020141987246,0.03342328809974528
0.0342810910722698,293.411262998886,0.10884246415445661,59.15171062057542,303.4697212273805,0.03370658737457114
0.034573333297775,293.495773216751,0.10977033322043561,59.168747880497,303.64290040566186,0.033989103364102824
0.0348671026845847,293.574436368659,0.11070305102355642,59.18460637192165,303.8105263870941,0.034273015269635436
0.0351594109765953,293.652552858061,0.11163112985069007,59.20035465618509,303.97720364832395,0.03455543512467069
0.0354431367387222,293.730988344613,0.11253195914544298,59.21616725027398,304.14173592891115,0.03482948652503788
0.0357294031922252,293.810088492305,0.113440855135315,59.23211384004869,304.30774760598996,0.03510591589034365
0.0360145992298522,293.879780141159,0.11434635255478073,59.246163676457655,304.46374264469995,0.03538123565870786
0.0363009857645482,293.953363741122,0.11525562980244054,59.260998130210204,304.62416061372954,0.03565762844230986
0.036585969011262,294.018305845308,0.11616045161075685,59.27409045841409,304.7752504717082,0.03593259109558209
0.0368708386982135,294.080541260951,0.11706491286682785,59.28663711820773,304.92353746206686,0.03620736864357314
0.0371572090470849,294.145349540747,0.11797413872449455,59.2997024674146,305.0749697838604,0.03648351760983473
0.0374465300220797,294.205049030304,0.11889273282010303,59.311737884509284,305.2220072314647,0.03676243446650659
0.0377288494164957,294.26179645066,0.11978909689737384,59.32317816445305,305.36395545797444,0.03703452654986032
0.0380135929576774,294.319430843003,0.12069315764062574,59.334797257949404,305.5075698866042,0.037308879992903145
0.038297417928034,294.36936408533,0.12159430192150793,59.34486379960253,305.6429506469155,0.03758227349766839
0.0385839880942637,294.416357628495,0.12250416219928724,59.3543376979046,305.77611486598937,0.03785823549262629
0.0388706398737895,294.468504755023,0.12341428159928165,59.36485055861264,305.9146839575288,0.038134199913206934
0.0391582582908136,294.520671404776,0.12432747007333317,59.37536735520285,306.0535879276281,0.03841101841088506
0.0394434850860152,294.579743754892,0.12523306514809826,59.387276340986226,306.1989954843303,0.03868545943634908
0.0397346704630495,294.637670933369,0.12615757872018216,59.3989544601672,306.34500169390685,0.038965556048715655
0.040025827439567,294.696479212702,0.12708200212062523,59.410810209280726,306.49194963671755,0.03924554692142752
0.0403166865985845,294.758107237514,0.12800547995050576,59.42323441908283,306.64177746940084,0.03952517314542657
0.040604354873891,294.821450849226,0.12891882672460392,59.43600449120396,306.79248566394335,0.039801654829648016
0.0408924992513025,294.878969969464,0.12983368512288543,59.44760034584394,306.93730802816515,0.04007851749094002
0.0411776025795468,294.930690915881,0.13073888819006108,59.45802728864161,307.07522969492624,0.040352382746269816
0.0414608676455708,294.977971781897,0.13163825477468727,59.46755911123044,307.20801442830515,0.040624407941060516
0.0417392207986525,295.024010389222,0.13252202603572166,59.476840494467154,307.3380826997616,0.040891644061375874
0.0420147396090071,295.072946992215,0.13339679825859752,59.48670611363055,307.47036002575527,0.041156088729216035
0.042290770385737,295.120131752741,0.134273195974715,59.49621856135258,307.60098948090456,0.04142095467810871
0.0425693810167648,295.168625656444,0.13515778472822823,59.50599493233912,307.733771346208,0.04168822501036486
0.0428466200888206,295.219960221509,0.1360380187820054,59.51634398065621,307.8691376997567,0.04195410872233607
0.043128239970783,295.273716802097,0.13693216190723603,59.527181307302754,308.0083525174029,0.042224121452657616
0.0434103647906579,295.337170418149,0.13782790821033883,59.53997355629885,308.1578647222415,0.042494545226222376
0.043699358469706,295.404914247006,0.13874546314131653,59.55363071219641,308.3139194883987,0.042771477174432276
0.0439871424875413,295.4710723443,0.13965917739794362,59.566968184610886,308.46800050445535,0.04304717375964862
0.0442748185306181,295.54725174258,0.14057254883471246,59.58232595130413,308.6325526807056,0.043322690960331915
0.0445598364183197,295.653612455479,0.14147748062816504,59.60376827102456,308.82788906298043,0.043595587514202463
0.0448467982817633,295.754478912986,0.14238858454459846,59.624102948857974,309.01812036972467,0.043870270154222936
0.0451290207329832,295.871933324315,0.14328464082722164,59.64778175818191,309.2243439376159,0.044140342611873155
0.0454127790769868,296.011078264957,0.14418557356943307,59.67583337821533,309.4537639665441,0.04441181132469376
0.0456920058815558,296.157421939049,0.14507211867393965,59.70533626291228,309.68944860415445,0.04467887283996275
0.0459736977783753,296.326591757708,0.14596649044634158,59.739440898353934,309.9498209308729,0.04494821979921126
0.0462541432757248,296.511420826191,0.14685690490042624,59.77670243856011,310.22630256797436,0.045216302933873895
0.0465373873053823,296.683971583542,0.1477562046945888,59.81148867124207,310.49086847642434,0.04548698831007877
0.04682045822311,296.860372977444,0.14865495485837424,59.847051192252714,310.7595116685313,0.04575743506628696
0.047103895285903,297.020527405953,0.14955486753274203,59.879338325040116,311.0113512266467,0.04602815837493871
0.0473866068576454,297.15445301573,0.15045247677302412,59.90633772797117,311.235594256785,0.046298115744685585
0.0476724703810266,297.282445907348,0.15136009345975945,59.93214109492136,311.4546345046652,0.04657100878933607
0.0479599387234508,297.391642920618,0.1522728054469563,59.954155212796586,311.6545278919572,0.04684535875928167
0.0482468115975214,297.478190879759,0.15318362682213044,59.971603281359414,311.8305651095062,0.04711906542091473
0.0485318347716212,297.545494791486,0.15408857539989732,59.985171749963584,311.9859235817467,0.0473909331036088
0.0488173983442424,297.608431761823,0.1549952397429696,59.99785984318351,312.13690112574517,0.047663242140059986
0.0491039280001009,297.664643045338,0.15590497140032034,60.00919203794014,312.281146245612,0.04793639791005198
0.0493913827738566,297.713145599066,0.1568176403069947,60.01897015277171,312.4176095301584,0.0482103606623896
0.049676602877738,297.757919857038,0.15772321413681814,60.02799664317887,312.54952179547746,0.04848211946923764
0.0499601563354445,297.798464061134,0.15862349636503628,60.03617035472461,312.67652188208353,0.04875221710225553
0.0502482550377379,297.837667673353,0.15953820974481783,60.04407380294797,312.8034907584487,0.049026569592741945
0.0505362799847254,297.877017386883,0.16045268895150314,60.05200670519561,312.9306137385614,0.0493007766272954
0.0508233109394591,297.923651119896,0.16136401223278263,60.06140806577104,313.0651174769814,0.04957396257581998
0.0511096712775628,297.978187785111,0.16227320630626188,60.07240265747838,313.20775501069187,0.049846435906128736
0.0513968963988699,298.040897379374,0.16318514606641193,60.08504491168179,313.35927450460787,0.05011965752408666
0.0516843240644124,298.106309059306,0.16409772890450938,60.09823190635609,313.5137321423731,0.050392997102734934
0.0519728664066172,298.171105930539,0.16501385084100959,60.11129495559666,313.6679129853802,0.05066732159374163
0.0522589526217811,298.244780582987,0.165922174574155,60.12614776553018,313.8307404411668,0.050939236707218734
0.0525474060912168,298.316847007231,0.16683801433961334,60.14067635665777,313.99262351077135,0.051213326976898316
0.0528323920651864,298.388358787636,0.1677428448069668,60.155093131587414,314.1529295467918,0.05148404865472541
0.0531190726035294,298.45557648488,0.16865305551620585,60.16864421935181,314.30925992110855,0.05175630615440995
0.0534067546618403,298.521514386594,0.16956644605134294,60.18193730033735,314.4645796667198,0.052029440294400826
0.0536959881203448,298.592525135907,0.17048476228209472,60.19625306739886,314.6257458184284,0.05230397219495655
0.0539850677229289,298.668725199616,0.17140259002029926,60.211615000242595,314.79237655623814,0.05257828277301629
0.0542750119769178,298.740249002928,0.17232316302671402,60.22603419899029,314.9543795955493,0.0528533382641377
0.054567210012339,298.815885114935,0.17325089178917633,60.241282439170895,315.12143427302465,0.053130455285263764
0.0548625247372677,298.893488369067,0.17418851604082494,60.2569272552039,315.29153976852314,0.05341045013125741
0.0551577118946908,298.978248430301,0.1751257352656433,60.27401488354868,315.46920451999887,0.05369024570309533
0.0554527284932027,299.065669733879,0.17606241296591857,60.29163901835002,315.64967711926965,0.053969801413412906
0.0557462191431799,299.152651472839,0.17699424577959616,60.309174536924345,315.8292807391072,0.05424783362084309
0.0560384420006358,299.241811667551,0.17792205335201866,60.32714923217829,316.0108565748483,0.054524588031174784
0.05633106031419,299.330841275668,0.17885111649755325,60.345097601174665,316.19246494946486,0.054801640237339626
0.0566213608855827,299.42233121921,0.17977282081172508,60.363541973792735,316.37603109237534,0.055076422168354
0.0569117123121742,299.512062561359,0.18069468659115306,60.38163181236998,316.55780689987705,0.055351176731791005
0.0572042184528126,299.602401065095,0.18162339358768,60.399844054723154,316.7409222646099,0.05562789395268522
0.057496931130516,299.689156807994,0.1825527563393883,60.41733401249159,316.9203636175456,0.055904729929844986
0.0577903243098066,299.769924097403,0.18348427968363595,60.43361669803645,317.09372522931807,0.05618213261396499
0.0580849372764034,299.842990638235,0.1844196758525808,60.44834691266818,317.2593519422261,0.056460611193349594
0.0583821459102045,299.915033404808,0.18536331326489927,60.4628707344093,317.4247166457114,0.056741464732831294
0.0586796649825631,299.984583932185,0.18630793631963782,60.4768921207285,317.5875788172592,0.05702253264760496
0.0589783200313327,300.04959922757,0.1872561660994813,60.48999920427812,317.7460205160868,0.05730459429576829
0.0592754935045971,300.114544977851,0.1881996918770958,60.50309226753476,317.9039827393207,0.05758517773984385
0.059573667890481,300.183202035366,0.18914639555227716,60.51693353032978,318.066216419722,0.05786662711650059
0.0598718598521185,300.25371967006,0.19009315503047622,60.53114988548409,318.23046829422304,0.05814801388459793
0.0601703240357245,300.325537875506,0.19104077881342527,60.545628435702,318.3962228056784,0.058429578268407126
0.0604662002626253,300.396172817084,0.19198018583383533,60.55986843992413,318.559987960768,0.05870862300373114
0.0607618511903346,300.463575799972,0.19291887752931236,60.57345688127435,318.7202988808457,0.058987377501081066
0.0610553130782516,300.528819234508,0.19385061902344883,60.586609957676814,318.87770038190814,0.05926399124021959
0.0613511967368977,300.58370003655,0.1947900496396502,60.597673927368476,319.024869753397,0.05954281026870869
0.0616447944322745,300.637710147612,0.19572222232247152,60.60856236575858,319.17045998825125,0.05981939835316086
0.0619386720198057,300.686516597404,0.1966552836628831,60.61840174603665,319.3106401297085,0.060096173524987
0.0622314417855997,300.739586434236,0.19758482766927904,60.62910062514198,319.4550445000435,0.06037182919469563
0.0625277952903215,300.793307392616,0.19852575004677075,60.639930770351384,319.60124974196026,0.06065078174750472
0.0628213808673371,300.85439389461,0.1994578842537953,60.65224580915338,319.7544823590751,0.06092705219019359
0.0631186698326025,300.920953919957,0.20040177671851295,60.66566431026334,319.91468425614255,0.061206729848183455
0.0634155353290034,300.988124783276,0.2013443246695858,60.679205956308444,320.0754478440803,0.061485931092733155
0.0637160659448006,301.05141995227,0.2022985093747419,60.69196626237764,320.2332320787247,0.06176849999220036
0.0640189982275378,301.113909005803,0.2032603193724325,60.70456405556989,320.39091981273253,0.062053246237054785
0.0643238893381203,301.166615229322,0.20422834864853195,60.715189630231315,320.5388232596692,0.062339751869628715
0.0646251983175225,301.216180075279,0.20518500465813394,60.72518190317624,320.6823354490905,0.06262281075831803
0.0649313313177807,301.264716680741,0.2061569769339537,60.73496688283739,320.8262358138955,0.06291031944672956
0.0652388717260868,301.307172021205,0.2071334177303256,60.74352587947493,320.96411196684636,0.06319906671209219
0.0655481297727729,301.34961074759,0.20811531202855393,60.75208152671415,321.10251413984764,0.06348934260418286
0.0658554414098458,301.390759529304,0.2090910264762604,60.76037712110769,321.238981034955,0.06377770811445728
0.0661635265093736,301.432980379826,0.21006919666726118,60.76888884457292,321.3768493679861,0.06406671595754691
0.0664715434998969,301.481099247779,0.21104715061217263,60.77858960835225,321.52101325082447,0.06435557643536284
0.0667825339747102,301.531304072757,0.2120345453697049,60.78871090106781,321.6683286314345,0.0646471408395285
0.0670937279388267,301.580620905389,0.21302258620577477,60.79865317452643,321.8147890360376,0.0649388109535618
0.067403497158836,301.630670724717,0.21400610347930432,60.80874321810295,321.96163278192824,0.0652290612462694
0.0677128586194752,301.68289750526,0.21498832611683372,60.81927213706041,322.1107088919473,0.06551884541842184
0.0680230534040156,301.732322449204,0.21597319455774952,60.82923620575953,322.25707633288386,0.06580932588932199
0.0683328371292562,301.782300737958,0.2169567578853884,60.83931182877234,322.4039415427771,0.06609933723882098
0.0686442647491603,301.831051979406,0.21794554057858395,60.849140079048254,322.55002262099794,0.06639080280654752
0.0689561717591478,301.877904844643,0.21893584533529425,60.85858561668003,322.6942495014019,0.06668263191256193
0.0692660329293526,301.918851781441,0.21991965455069448,60.866840519138506,322.83157291092664,0.0669724625687907
0.0695768226977867,301.961886023787,0.22090641206547276,60.875516222395454,322.97143462915324,0.0672630774401018
0.0698857414449646,302.004191744052,0.22188722908776257,60.884045055600886,323.1099786035723,0.06755185907573515
0.07019656405773,302.045361591684,0.22287409088329274,60.8923448968835,323.2479081649949,0.06784233632901818
0.0705042868634781,302.087888397034,0.22385111079154293,60.90091830084206,323.38637953856085,0.06812983358276582
0.0708123023218023,302.133310845695,0.2248290598717223,60.91007546649212,323.52806619478747,0.0684175215052378
0.0711204378764893,302.177354888112,0.22580739025785354,60.91895474544338,323.66834068411384,0.06870523880936207
0.0714310639647616,302.227121828106,0.2267936280881181,60.92898776054618,323.8155266992952,0.0689951978513562
0.0717408468638783,302.27272331854,0.22777718879281358,60.93818102101766,323.9580244732628,0.06928428609454283
0.0720546286373696,302.316282605917,0.22877344592364846,60.94696257335288,324.09957008011645,0.06957702090000153
0.0723682978847297,302.36482104024,0.2297693457840168,60.95674792171238,324.24644847914306,0.06986956510452183
0.0726858900260761,302.419577734882,0.23077770083279162,60.96778687135222,324.401213903852,0.07016568083479742
0.0730061371128863,302.467706084901,0.23179448533341399,60.97748954671604,324.5497049075555,0.07046418321550968
0.0733264549668946,302.513272564073,0.23281149451989036,60.98667574891712,324.6954984216304,0.07076266245173655
0.0736488641723757,302.551890413549,0.23383514374729286,60.99446110737148,324.834493495712,0.071063000518067
0.0739732076642385,302.591923368513,0.23486493433395722,61.00253175109222,324.97561855337335,0.07136504946660595
0.0742970420549042,302.635309702492,0.23589310852432083,61.01127843602239,325.12021803475704,0.07166653331684399
0.0746228989684089,302.674672630152,0.23692770422469825,61.01921400223864,325.26113414612803,0.07196980838054591
0.0749502457501608,302.706294955544,0.2379670302567605,61.02558906303768,325.3942061525827,0.07227437748542767
0.075280559986136,302.736403218856,0.2390157779559818,61.03165888892138,325.5265691813602,0.07258161356231048
0.0756128889041193,302.769938784218,0.24007092227057875,61.038419658898356,325.6632485290161,0.07289062833084703
0.0759456019051647,302.806170902842,0.24112728604889788,61.04572405401294,325.8029678126565,0.07319990461138397
0.0762785009390677,302.844460471947,0.24218424048153991,61.05344323114452,325.94498193444787,0.07350925811794289
0.0766113467307413,302.883227934599,0.2432410258701036,61.06125875161516,326.0875199288227,0.07381846650097816
0.0769440747742246,302.928293814339,0.2442974374081631,61.070344032970745,326.2368311048178,0.07412746996827549
0.0772781933873857,302.970899938902,0.2453582640049496,61.07893342768264,326.38394373513074,0.07443766880038134
0.0776087959331516,303.015874693942,0.24640792708775633,61.088000338298706,326.5325718775696,0.0747445086021883
0.0779376766382341,303.057624583439,0.24745212332639327,61.09641711602131,326.6772317309744,0.07504965693632948
0.0782655694682536,303.097240575271,0.24849318306170515,61.104403699974625,326.81931871315084,0.07535379601332907
0.0785951158540876,303.135011472186,0.2495394928367281,61.112018312792706,326.9599428182727,0.07565937568348666
0.078926300544116,303.167997107877,0.25059100422756825,61.118668216948,327.095925562971,0.0759663804623153
0.0792592037892077,303.193165279396,0.2516479720307344,61.123742120326234,327.22401415377055,0.07627488336631821
0.0795917270584731,303.216735371152,0.2527037334106521,61.128493850824256,327.3502790123741,0.07658293916317174
0.0799270766266078,303.23977480767,0.25376846828947974,61.13313860122628,327.4768435249579,0.07689351721440983
0.080267164475708,303.264362194931,0.2548482472103729,61.13809541849809,327.6065326348522,0.0772083850586426
0.0806076860003762,303.289301868598,0.25592940305119444,61.14312325670936,327.7367506808952,0.07752355511803945
0.0809498325860008,303.312086677614,0.25701571846055254,61.147716674206976,327.86514931547737,0.07784012924159626
0.0812917776029714,303.335821597811,0.2581013938894342,61.1525016341187,327.99452974615485,0.07815641676303688
0.08163286960929,303.35754121178,0.25918436100949577,61.15688030829485,328.1214878185161,0.07847181564629052
0.0819752894360621,303.381653906492,0.26027154395949714,61.16174142754879,328.2514527950679,0.07878834230403992
0.0823175135821782,303.408334129687,0.26135810562341577,61.16712016054489,328.3841537953536,0.07910458800655402
0.0826600502474844,303.433517874741,0.262445659535763,61.172197203547796,328.51534770903805,0.07942102238803402
0.0830041122582998,303.459041954362,0.26353805642010186,61.177342857999385,328.647390338538,0.07973876511072109
0.0833520131784921,303.490632274446,0.2646426418417124,61.183711466528315,328.78718745533456,0.08005995045887151
0.0837017547159436,303.520629449986,0.2657530712231209,61.18975889711718,328.92583872743757,0.08038273113526216
0.0840566076227289,303.552672653355,0.26687972920216424,61.19621880691637,329.06828055140875,0.08071012270816066
0.084411490096701,303.587477604192,0.2680064810570257,61.20323548500511,329.21374896346066,0.081037434396549
0.0847686352115744,303.620872354818,0.2691404167967487,61.20996786673131,329.35839932608354,0.08136672481732472
0.0851265033561419,303.65655366128,0.27027664815575053,61.21716121811404,329.5057742956414,0.08169657315096207
0.0854853122626443,303.69261300484,0.27141586643389565,61.224430781775744,329.6538708594171,0.08202717939496079
0.0858390207086472,303.722454352349,0.27253889074995485,61.23044679743356,329.7936924011815,0.08235297913271596
0.0861922175409495,303.757867556631,0.27366029069251463,61.237586099416816,329.9394317568471,0.08267820174387881
0.0865434174264268,303.794079185166,0.27477535032890504,61.24488636372948,330.08545699176483,0.08300148073179045
0.0868965903094409,303.832835522005,0.2758966742324748,61.252699641236205,330.2348729529164,0.08332647050364116
0.0872502117994991,303.871817472213,0.2770194224634096,61.260558402398146,330.38469790656234,0.08365176729853413
0.0876063562134063,303.914345000108,0.278150180977565,61.26913195202178,330.53917336655155,0.08397927801563501
0.0879626073759086,303.959528111663,0.27928127841850975,61.27824086731127,330.6966007411157,0.08430677962247778
0.0883264429955329,304.009364737074,0.28043645651081694,61.28828793099412,330.8614305616313,0.08464114294884921
0.0886949584538949,304.059489156778,0.2816064930911163,61.29839301400644,331.02803291505097,0.08497969309965307
0.0890691008609586,304.112348845287,0.2827943952335435,61.30904952720986,331.19936231765087,0.08532329543723807
0.0894445020935329,304.161666665197,0.2839862941469669,61.31899199970371,331.36725549600465,0.0856679352281312
0.0898231880597068,304.21181155018,0.2851886220895691,61.3291012085163,331.53708630903594,0.08601547029387517
0.0902015532802492,304.255784902061,0.2863899316647912,61.3379662362555,331.7001292947283,0.08636259041335496
0.0905859157177066,304.296619059697,0.28761028240371844,61.346198402434915,331.8616069470218,0.08671508917529445
0.0909712909681101,304.336678625208,0.2888338488237496,61.354274410841924,332.02257916869,0.087068392085006
0.0913580013647818,304.38494607443,0.2900616543331822,61.364005128605086,332.19294639331684,0.08742279359725981
0.0917428458223313,304.467620526287,0.29128353548590186,61.38067229809946,332.40034649412223,0.08777536041709473
0.0921306744842568,304.521240397452,0.2925148914875153,61.39148206412632,332.5769876700517,0.08813053544201835
0.0925200729648325,304.566442471555,0.29375123166334316,61.40059480226549,332.7449519516627,0.08848702124200658
0.0929098276639376,304.609663760364,0.2949887028330019,61.409308214089386,332.9108951251094,0.08884370594109028
0.0932980145431336,304.658203499654,0.2962211961744492,61.41909382553025,333.0822090004497,0.08919882943464054
0.0936861731890247,304.707011941395,0.2974535998751534,61.42893360738523,333.25384583404673,0.08955380104544973
0.0940729286219592,304.743333329536,0.29868154837472044,61.436255999234454,333.4114311738633,0.08990736413806209
0.0944617277567315,304.724666455311,0.2999159856276225,61.432492757390705,333.5094849387734,0.09026266958203048
0.094851815090607,304.713962158924,0.3011545129126772,61.430334771239075,333.6166345531485,0.09061902542633438
0.0952410879887199,304.667953064046,0.30239045436418566,61.421059337711675,333.684860389162,0.09097451071343339
0.0956353459509377,304.608165679464,0.3036422233942272,61.40900620097994,333.7394729837001,0.09133441961597673
0.0960339360208177,304.539676503294,0.3049077468660962,61.395198783064075,333.7858203124119,0.09169815156910778
0.0964335131128776,304.399230815032,0.30617640413338637,61.36688493231046,333.75351803138324,0.09206265148142494
0.0968369062649922,304.215823720855,0.3074571773913502,61.32991006212436,333.67514292683876,0.09243049773795504
0.0972436661421827,304.051771136399,0.30874864000143004,61.29683706109804,333.61888005872635,0.09280127708577489
0.0976513513626548,303.898358144859,0.310043040576429,61.265909002003575,333.57444349459655,0.09317276202870765
0.098062435695384,303.706527100779,0.31134823333284417,61.227235863517045,333.48872888486756,0.09354720458124367
0.098473597099784,303.463445666586,0.31265367079181416,61.17823064638374,333.3465827496696,0.0939215771415508
0.09888811487174,303.216037056632,0.3139697647177745,61.12835307061702,333.200499360042,0.09429886393472153
0.099308094026138,302.999599676681,0.3153031985329881,61.08471929481889,333.089912411255,0.09468097646663116
0.0997306342175619,302.9392978346,0.316644763640759,61.072562443455354,333.1516261370675,0.09506527183278107
0.100153269225962,302.916536637991,0.31798662979242936,61.067973786218985,333.25461808489166,0.09544950575797877
0.100580710511891,302.615047847328,0.31934375587525393,61.00719364602133,333.05228437140215,0.09583795915147338
0.101009941625658,302.318839416168,0.32070656466146413,60.94747802629947,332.85604773793176,0.09622788733252627
0.101445036860038,302.04456250035,0.32208799203062066,60.89218380007056,332.6854842765721,0.09662298756775474
0.101879932691193,301.726895206896,0.32346878629453774,60.82814207371024,332.4668109816972,0.09701775079407214
0.102312856310218,301.408721769615,0.3248433187849421,60.76399830875438,332.2467090106761,0.09741056908723791
0.102751773066769,300.853743142017,0.32623687948699154,60.65211461743063,331.7669986836335,0.09780866786085235
0.103193901350948,300.18200660654,0.32764063678925986,60.51669253187847,331.1589589836249,0.09820951933713884
0.103635121937724,299.686089816098,0.3290415121522737,60.41671570692535,330.744094277229,0.09860938773473463
0.104073006361063,299.176682660744,0.330431795196375,60.314019224405996,330.3128994583774,0.09900607461871924
0.104511691844011,298.689946922873,0.3318246216047349,60.2158932996512,329.9065386125803,0.09940332946620012
0.104954024700687,298.190038658457,0.3332290284246812,60.11511179354494,329.4862833413155,0.09980372749842423
0.105405943200344,297.663071362914,0.3346638696610922,60.008875186763476,329.03852815583326,0.10021263691817192
0.1058504145133,297.062826576574,0.3360750660797275,59.887865837837325,328.5070499061969,0.10061464486934532
0.106290292795027,296.39100676513,0.3374716796242107,59.752426963850205,327.8944936560084,0.10101233954226678
0.106741670200559,295.68590601132,0.33890480288677477,59.61027865188212,327.24791347373383,0.10142026624132847
0.10719101943531,294.919979820317,0.3403314867071092,59.45586793177591,326.5327531090978,0.1018261947892241
0.1076471306684,293.991291516639,0.34177963987216997,59.26864436975443,325.6386104899023,0.10223806347544502
0.108107793671248,292.998745960435,0.34324224490621236,59.06854718562369,324.6741939346601,0.10265387029994984
0.108554431220059,291.832040935419,0.34466031912368733,58.83333945258047,323.5117021509524,0.10305685235994973
0.109030471389362,290.756997160962,0.34617174666122436,58.61661062764993,322.45836962117704,0.10348618444645066
0.109488105989243,289.569533309231,0.34762473651584647,58.377217915140974,321.2739530634477,0.10389874317914581
0.109955498021327,288.292509092602,0.34910870621771317,58.11976983306857,319.99185550569706,0.10431992264786387
0.110456285512045,286.996163318533,0.35069870650074286,57.85842652501625,318.69669347490634,0.1047709988877965
0.110953427064147,285.52556145031,0.3522771309286667,57.5619531883825,317.20560100763663,0.10521858994458103
0.111470723935185,283.816052969582,0.35391954849421237,57.21731627866773,315.45323385852817,0.1056841148356308
0.112007221309215,281.836720644191,0.3556229276567576,56.81828288186891,313.40446858644833,0.10616668979041176
0.112540437855162,279.5696292215,0.3573158901901393,56.3612372510544,311.0325177050929,0.10664608303151611
0.113127041673533,276.756975489745,0.35917835731346726,55.79420625873259,308.06567338941437,0.1071732092418323
0.11341582275334,275.536173845693,0.3600952372418545,55.5480926472917,306.78633570070957,0.10743260786922007
0.113695150634497,274.058313634503,0.36098210326452795,55.250156028715814,305.21741488581404,0.10768345112396528
0.113993289844631,272.465466272036,0.3619286952567034,54.92903800044246,303.5247011414367,0.10795111800816379