File: example/data/02 processed data/test_ID_072.csv
Strain,Stress_MPa,Displacement(mm),Force(kN),True Stress (MPa),True Strain
6.87742607133979e-07,0.239495508755862,2.183582777650383e-06,0.04828229456518179,0.23949567346712758,6.87742370591312e-07
-1.05178112278173e-06,0.243317342419119,-3.3394050648319925e-06,0.0490527762316944,0.24331708650253142,-1.05178167587388e-06
-5.66488580019749e-06,0.246915940127446,-1.798601241562703e-05,0.04977825352969312,0.24691454137684293,-5.664901845753444e-06
-1.56167398246818e-05,0.252122167427331,-4.958314894336471e-05,0.05082782895334994,0.2521182301010383,-1.5616861767193007e-05
-4.26548953335587e-05,0.319691294390609,-0.00013542929268404885,0.06444976494914678,0.3196776579919077,-4.2655805079422986e-05
-6.13422757991484e-05,0.583591779000141,-0.00019476172566229615,0.11765210264642843,0.5835559801522795,-6.134415731347029e-05
-5.99783613664792e-05,0.967657514422921,-0.00019043129733857146,0.19507975490766088,0.9675994759108419,-5.998016014034983e-05
-3.32770470434986e-05,1.34245348707771,-0.00010565462436310805,0.27063862299486635,1.342408814189867,-3.3277600736691966e-05
4.05799382466087e-06,1.41436819189316,1.2884130393298261e-05,0.2851366274856611,1.4143739313905488,4.057985591111809e-06
5.86156409504669e-05,1.14681391024651,0.0001861046600177324,0.23119768430569643,1.1468811314789102,5.861392312099993e-05
0.0001162543449219,0.806200244526422,0.00036910754512703246,0.1625299692965267,0.8062939688077252,0.00011624758790912203
0.0001908353541943,0.522529688920757,0.0006059022495669025,0.10534198528642462,0.5226294060590193,0.00019081714744448197
0.0002719767117486,0.452355985123665,0.000863526059801805,0.09119496660093086,0.45247901541703867,0.000271939732787426
0.000354709678567,0.909010820109776,0.001126203229450225,0.18325658133413084,0.909333255045591,0.0003546467839613984
0.0004491594898373,2.2773156833326,0.0014260813802334273,0.45910684175985217,2.278338561283124,0.00044905864790854605
0.0005307531984975,5.1459148920141,0.0016851414052295626,1.0374164422300427,5.148646102802233,0.0005306123988363442
0.0006288424397021,9.09108991140566,0.0019965747460541673,1.8327637261393812,9.0968067745651,0.0006286448011464195
0.0007230512104106,13.6326705699347,0.002295687593053655,2.7483463868988354,13.64252768889142,0.0007227899348203386
0.0008206529003981,18.1998255386149,0.0026055729587639675,3.6690848285847637,18.2147612782299,0.0008203163489219221
0.0009201427457578,22.6874819248626,0.002921453217781015,4.5737963560523,22.70835764677527,0.000919719673925833
0.0010173568520677,27.4167224718075,0.003230108005314947,5.527211250316392,27.44461506227543,0.001016839695311087
0.0011212250905373,32.3807896329676,0.0035598896624559275,6.527967190006268,32.41709578675549,0.0011205969871384415
0.0012226121805325,37.5603668773998,0.0038817936731906874,7.572169962483801,37.60628863944938,0.0012218653988814723
0.0013152494555241,42.9039625268679,0.004175917021289018,8.649438845416569,42.96039194022119,0.001314385272620133
0.0014182260436073,48.3527984195967,0.004502867688453177,9.747924161390696,48.42137361759667,0.001417221310898467
0.0015103660888392,53.8142777389277,0.00479541233206446,10.848958392167825,53.89555699911995,0.0015092266331638358
0.0016084277979688,59.3348546479394,0.00510675825855094,11.961906697024583,59.43029047754359,0.0016071356633295378
0.0017074620009761,64.8912415503117,0.005421191853099117,13.08207429654284,65.00204087945502,0.001706005944938274
0.0018087226457033,70.5171346160062,0.005742694400107978,14.21625433858685,70.64468055429629,0.0018070888766255387
0.0019084370763515,76.2933875704556,0.006059287717416012,15.380746934203849,76.43898869997551,0.0019066183239297829
0.0020127115051101,81.9799802948021,0.006390359028724567,16.527164027432104,82.14498234433015,0.0020106887150491298
0.0021114343686791,87.7195768940035,0.006703804120556142,17.684266701831106,87.90479102346347,0.0021092084238725998
0.0022169026306262,93.4497481947738,0.007038665852238184,18.8394692360664,93.65691718737816,0.002214448927733838
0.0023174011392021,99.2698819083265,0.007357748616966668,20.012808192718623,99.49993004574932,0.0023147201064022847
0.0024161582547733,105.263364523551,0.007671302458905227,21.22109428794788,105.51769747066979,0.002413244037613171
0.0025161658546971,111.162105779681,0.007988826588663291,22.41028052518369,111.44180807458005,0.0025130056094170004
0.0026120605676719,117.052894357613,0.008293292302358283,23.59786350249478,117.35864360729637,0.0026086550664285208
0.002716200501615,122.821269138875,0.008623936592627625,24.760767858397198,123.15487633171901,0.00271251829526597
0.0028117527985458,128.492718301381,0.008927315135382915,25.904132009558406,128.85400806165765,0.002807807215917391
0.0029093723816182,134.156951713942,0.009237257311637785,27.046041465530706,134.54726424406064,0.002905148348664078
0.0030008550143188,139.731961222526,0.009527714670462189,28.169963382461244,140.15127657902121,0.0029963614363830867
0.0030883204647088,145.264125984432,0.00980541747545044,29.285247798461498,145.71274815749777,0.003083561398891726
0.0031785481265062,150.706546715705,0.010091890301657185,30.38243981788613,151.18557472742043,0.003173507221425043
0.003270093568713,156.077152066526,0.010382547080663773,31.465153856611643,156.5875389577218,0.0032647584404873714
0.0033556353728897,161.449482597201,0.010654142308924797,32.54821569159572,161.99124819193892,0.0033500177920391555
0.0034462657170369,166.673802157828,0.010941893651592156,33.601438515018124,167.2482043681327,0.0034403409516491194
0.0035303384710336,171.851228177691,0.01120882464553168,34.645207600622506,172.4579211798211,0.0035241214539933293
0.0036163515844016,176.977802157581,0.011481916280475079,35.678724914968335,177.6178161128175,0.0036098283072560117
0.0037047438287308,182.034008730037,0.01176256165622029,36.69805615997546,182.70839810049873,0.0036978981677165236
0.0037890565904699,187.178210757981,0.012030254674741931,37.73512728880897,187.88743959104588,0.0037818961972707014
0.003878355099887,192.176802767591,0.012313777442141224,38.74284343794635,192.9221326506847,0.0038708536699637447
0.0039576353749347,197.271917636992,0.01256549231541767,39.770018595617586,198.05264795671334,0.003949824537569329
0.0040393945707408,202.331035162901,0.01282507776210204,40.78993668884085,203.1483300478304,0.004031258120022
0.0041170451922495,207.254728855819,0.01307161848539216,41.78255333733311,208.1080059408258,0.004108593351490737
0.004198609195056,211.988320880299,0.013330584194302799,42.73684548946828,212.87837699359153,0.004189819629514652
0.0042843423579251,216.569661001911,0.013602786986412192,43.660443657985255,217.49751957398294,0.004275190693137327
0.0043731311004055,220.88152564233,0.01388469124378746,44.52971556949373,221.8474695116215,0.004363596749134009
0.0044673971816311,224.855668353479,0.01418398605167874,45.33090274006137,225.8601879325551,0.004457447983184274
0.0045688745567678,228.640597337537,0.014506176717737764,46.09394442324746,229.68522754535667,0.004558468932034693
0.004678018157927,232.349014903368,0.014852707651418225,46.84156140451899,233.43594781406236,0.004667110236059793
0.0047886966776939,236.049565172084,0.015204111951678133,47.58759233869213,237.17993494059465,0.004777267342979642
0.0049123150050645,239.730150398597,0.015596600141079785,48.32959832035716,240.9077804135664,0.004900288953465781
0.0050416012953358,243.400216897979,0.016007084112691163,49.06948372663256,244.62734374677686,0.00502893497803493
0.0051858235325434,246.7262223296,0.016464989715825294,49.74000642164736,248.0057009794524,0.005172423456675566
0.0053479706326326,250.028756241904,0.016979806758608502,50.40579725836785,251.3659026875994,0.005333721019453505
0.00552981318405,253.006050059705,0.017557156859358748,51.006019692036524,254.40512625096954,0.005514579899467406
0.005742395984277,256.069538724836,0.018232107250079475,51.62361900692694,257.5399914157052,0.005725971276576525
0.0059866965320167,259.190552706421,0.01900776148915302,52.25281542561447,260.74224788944,0.005968847466864215
0.006258655101721,262.581986916508,0.019871229947964173,52.93652856236801,264.22539700854304,0.006239151056969918
0.0065620415852074,265.908746380766,0.020834482033033494,53.607203270362426,267.653650632387,0.006540605117218173
0.0068814037716172,269.244782133436,0.02184845697488461,54.279748078100695,271.09756419269723,0.006857834975175627
0.0072200521283454,272.754909756554,0.02292366550749664,54.98738980692129,274.7242144232585,0.007194112334915881
0.0075747570021503,276.232433574276,0.0240498534818272,55.688458608574045,278.32482713471376,0.007546212584392357
0.0079364522948236,279.845310788726,0.025198236036064928,56.416814655007165,282.0662897477308,0.007905124303550852
0.0083090624579676,283.263185247782,0.026381273304047128,57.10585814595285,285.6168367460487,0.008274732235382101
0.0086902907960351,286.393018597536,0.02759167327741144,57.73683254926326,288.8818572111029,0.008652747569885955
0.0090895905125494,289.480024727521,0.028859449877344345,58.359172985068234,292.1112796138569,0.009048528819788834
0.009497571978262,292.080630261222,0.03015479103098185,58.88345506066236,294.8546870705841,0.00945275359526434
0.0099075264849918,294.180130873642,0.031456396589848966,59.306714384126224,297.09472831163094,0.009858768725832667
0.0103167652218793,295.955508778915,0.03275572957946678,59.664630569829264,299.0088122791089,0.01026391061444904
0.0107263092021275,297.339566561377,0.03405603171675481,59.9436566187736,300.5289226903409,0.010669190433604278
0.0111401553121224,298.357172979222,0.03536999311598862,60.14880607261116,301.6809182246963,0.011078560807996319
0.0115573591613863,299.19259018883,0.0366946153374015,60.31722618206813,302.6504664120678,0.011491083048415304
0.0119719734616194,299.817793383521,0.03801101574064159,60.44326714611783,303.40720404922985,0.011900876273896266
0.0124005706086975,300.321363824397,0.03937181168261456,60.54478694699844,304.0455201018018,0.012324313308485026
0.0128195957319184,300.720695747423,0.04070221644884092,60.62529226268048,304.57581349512617,0.01273812029714175
0.0132364726169629,301.150273512002,0.042025800558857206,60.71189514001961,305.1364408609345,0.013149635948105236
0.0136517431327587,301.487500963369,0.043344284446508875,60.77988019421519,305.60333088425824,0.013559397589994993
0.0140496300977247,301.829285379624,0.04460757556027592,60.84878393253221,306.06987519186833,0.013951848840781305
0.0144464001645651,302.06600355413,0.04586732052249419,60.896506316512614,306.4297699175839,0.01434304514186454
0.0148479380577572,302.321548272947,0.04714220333337911,60.948024131826116,306.810399895229,0.01473878654898294
0.0152361117149105,302.553281387829,0.048374654694840834,60.99474152778632,307.1630169827667,0.015121207820582372
0.0156311730264844,302.811484093603,0.04962897435908797,61.04679519327036,307.54478279587664,0.015510264574340144
0.0160117398543668,303.038787657963,0.05083727403761459,61.09261959184534,307.890965891725,0.015884904064302492
0.0163882186407578,303.271572027422,0.05203259418440601,61.139548920728274,308.2416528573337,0.016255381134156154
0.0167647072456823,303.485012057619,0.053227945505041306,61.18257843081599,308.5728494382173,0.016625730658222114
0.0171379320527642,303.667377113954,0.05441293426752634,61.21934322617312,308.8716079895741,0.016992734273891686
0.017515316506863,303.825712653675,0.05561112990929002,61.25126367098088,309.1473161737273,0.017363691299314483
0.0178813370068517,304.002989914534,0.056773244996754145,61.28700276677006,309.43896982828636,0.017723346507848403
0.018239152684532,304.205151739101,0.057909309773389095,61.32775859060276,309.7535959490917,0.01807481458960016
0.0185960399185035,304.347464899016,0.05904242674124861,61.35644892364163,310.00712250537345,0.018425247691816523
0.0189464665502584,304.54735226294,0.060155031297070415,61.39674621620871,310.31744848555957,0.018769217581129184
0.0193077314916907,304.679496670527,0.06130204748611797,61.42338652877824,310.562166583265,0.019123702262738067
0.0196632654099807,304.848811316057,0.06243086767668872,61.45752036131709,310.84313440288173,0.019472440839631466
0.0200205831643182,305.0228727648,0.06356535154671028,61.492611149383684,311.12960855600693,0.01982280666543575
0.0203762488180165,305.130690590325,0.06469458999720239,61.514347223009516,311.3481094638067,0.02017143067006646
0.0207235725505979,305.239921757577,0.06579734284814832,61.536368226327525,311.565583421459,0.020511760655202396
0.0210770783517189,305.373292015916,0.0669197237667075,61.563255670408665,311.80966881825776,0.020858029331820734
0.0214202159745408,305.568119517874,0.06800918571916705,61.6025328948034,312.1134546328812,0.02119402745236013
0.02176861194992,305.751171081302,0.069115342940996,61.63943608999049,312.4069496778045,0.021535059053545705
0.0221143938569498,305.905406748519,0.07021320049581561,61.67053000050143,312.6703193963262,0.021873416884543237
0.0224623945990695,306.0235598633,0.07131810285204565,61.69434966844128,312.8975818215614,0.022213830360275643
0.0228073220058813,306.069081047136,0.07241324736867312,61.70352673910263,313.04969713462225,0.02255112319484083
0.0231499818248438,306.215438056045,0.07350119229387907,61.73303231209868,313.304319881529,0.022886086022779337
0.0234899674752572,306.368647616669,0.0745806467339416,61.76391935952048,313.5652371846231,0.023218323897503716
0.0238219816168688,306.59148624806,0.07563479163355843,61.808843627608894,313.89510299734974,0.023542665427058577
0.0241561424866162,306.719442444394,0.07669575239500644,61.83463959678984,314.12860099949626,0.02386899789006681
0.0244875771375991,306.788862444182,0.07774805741187714,61.84863466874709,314.3013783782402,0.024192562842527625
0.0248319015649585,306.86120228607,0.07884128746874323,61.863218380871714,314.4811494553425,0.024528600667940232
0.0251739650179457,306.977775522198,0.07992733893197759,61.88671954527512,314.7056233044806,0.024862320157955083
0.0255196536797345,307.094637764527,0.08102490043315703,61.91027897332865,314.9315865671812,0.02519946331957733
0.025860899943279,307.237893527835,0.08210835731991081,61.93915933521154,315.18334195114215,0.025532162453426075
0.0262038632815055,307.37781864648,0.08319726591877996,61.96736823913037,315.4323049820598,0.025866424166376037
0.0265477581329728,307.508245808269,0.08428913207218863,61.99366235494704,315.67190034188167,0.026201481609367996
0.0268863237770383,307.615863404515,0.0853640779920966,62.015358062350224,315.88652310696193,0.026531237163847303
0.0272303339957358,307.753654512519,0.08645631043646115,62.043136749723836,316.1338893133032,0.026866184276624006
0.0275696369662974,307.962232249696,0.08753359736799425,62.08518602153871,316.4526391921507,0.02719643829496203
0.0279098157469078,308.1271350594,0.08861366499643226,62.11843042797505,316.72690662553043,0.027527435312000654
0.0282544477974104,308.306060804239,0.08970787175677801,62.15450185813458,317.01707830485765,0.027862653718273213
0.0285906141670158,308.499470316711,0.09077519998027517,62.19349321584894,317.3196596432648,0.028189529455114055
0.0289373520021552,308.641939779091,0.09187609260684275,62.222215059464745,317.57322023310655,0.02852657259049108
0.0292813309764903,308.753687059236,0.09296822585035669,62.244743311141974,317.7944059602292,0.028860821793826312
0.0296274604672561,308.885342246992,0.09406718698353811,62.27128499699359,318.0368305133297,0.029197047949608475
0.0299658983786488,308.949258656701,0.09514172735220994,62.28417054519092,318.20720074576656,0.029525693323206356
0.0303032206253699,309.067227989328,0.09621272548554943,62.30795316264852,318.4329603871601,0.02985314787428786
0.0306468923158628,309.189095290736,0.09730388310286438,62.33252161061239,318.6647801993502,0.03018665589228426
0.0309861399392629,309.30478180614,0.0983809943071597,62.35584401211782,318.8889430590682,0.030515761626577837
0.0313277631509733,309.487421424625,0.09946564800434021,62.3926641592044,319.18297006122106,0.030847062515664804
0.0316647575826347,309.621757086987,0.10053560532486516,62.41974622873658,319.42585496745585,0.031173766981407787
0.0320041860670803,309.737511440917,0.10161329076297994,62.44308230648887,319.6504083890265,0.031502723317695075
0.0323472766263059,309.855799434648,0.10270260328852122,62.46692916602504,319.87879069322577,0.03183511881195547
0.0326841383987828,309.995177588558,0.10377213941613539,62.4950278018533,320.1271028758177,0.03216137222680798
0.0330271219089181,310.18499148707,0.10486111206081496,62.533294283793325,320.4295090152302,0.03249344527097207
0.0333661117827217,310.328474787207,0.10593740491014138,62.56222051710094,320.68292936631855,0.03282154339994136
0.0337122205183075,310.402339094548,0.10703630014562632,62.577111561460875,320.8666911995019,0.03315642063551763
0.0340599399022469,310.501415155422,0.1081403091896339,62.59708529533308,321.07707469517834,0.03349274336378796
0.0344009172774385,310.670090960789,0.10922291235586723,62.63109033769507,321.3574270605054,0.033822435247583105
0.0347432917406642,310.804340177936,0.11030995127660882,62.658154979871895,321.6027060430027,0.03415336864976772
0.0350887942888681,311.054842577345,0.11140692186715621,62.70865626359276,321.9693819610977,0.03448721462089233
0.035434151429688,311.177758488643,0.11250343078925938,62.73343611131043,322.2040783044805,0.034820808744770025
0.0357803074195034,311.337772934051,0.1136024760569233,62.765695023504676,322.47753416093485,0.03515506287433076
0.0361238210713851,311.440203566947,0.11469313190164769,62.78634503909652,322.6906137550351,0.03548665510420814
0.0364682238500186,311.508772259757,0.11578661072380904,62.80016848756701,322.8689438977703,0.0358189952602437
0.0368110504557746,311.636806685568,0.11687508519708434,62.825980227810504,323.1084849003469,0.036149704791881926
0.0371466141900187,311.701010693065,0.11794050005330936,62.8389237557219,323.27964787991914,0.036473302272093444
0.037472383200335,311.793879411539,0.1189748166610636,62.85764608936627,323.47753914036724,0.036787354166348256
0.037798944936986,311.936745420222,0.12001165017493054,62.88644787671676,323.7276252841836,0.037102071316745686
0.0381351500289795,312.078093019623,0.1210791013420099,62.91494355275599,323.97923791768415,0.03742597860816522
0.0384731319729296,312.263257295369,0.12215219401405147,62.95227267074639,324.2770028035906,0.03775149204260911
0.0388180225466206,312.367977740603,0.12324722158552039,62.97338431250557,324.49348494338,0.038083550046235204
0.0391633065571383,312.524395977387,0.1243434983189141,63.004918229041216,324.7638847036339,0.03841587643325286
0.0395035974132997,312.605343315289,0.12542392178722656,63.021237212362266,324.95437894686256,0.03874328902499741
0.0398465570352266,312.709082206705,0.12651281858684443,63.042150972871724,325.16946248628784,0.039073160955709126
0.040185374829332,312.830658796169,0.1275885650831291,63.06666081330767,325.40187607799993,0.039398942297727474
0.0405239790016359,312.895530688419,0.12866363333019398,63.07973898678527,325.5753026037422,0.03972441223870653
0.0408652358311899,312.955724680115,0.12974712376402792,63.09187409551119,325.7447341738888,0.040052324798433375
0.0412129938461851,313.041460259849,0.13085125546163767,63.10915838838556,325.94283603513895,0.040386373743638494
0.0415574963575738,313.14687231376,0.13194505093529682,63.130409458454025,326.1604723193247,0.04071718553125575
0.0419075946732125,313.369606644397,0.13305661308744968,63.175312699510435,326.5021731025544,0.0410532586629258
0.0422543295428114,313.503547450552,0.1341574962984262,63.20231516603128,326.75042965736804,0.041385991804980767
0.0425939580948059,313.712930611766,0.13523581695100872,63.24452681133203,327.0752060320423,0.04171179829844361
0.0429431194312291,313.853769289213,0.1363444041941524,63.272919888705346,327.3316291877411,0.04204663899099053
0.0432888124882526,313.967868790009,0.137441979650202,63.295922348065815,327.55916498939604,0.04237804323698867
0.0436294906489604,314.021254939255,0.13852363281044927,63.30668499575381,327.7218423452021,0.042704532456257015
0.0439742394702583,314.129162449345,0.1396182103180701,63.328439149787954,327.94275346348417,0.04303481431910079
0.0443116129237556,314.224012271834,0.14068937103292403,63.347560874001736,328.1477850749729,0.043357924736236134
0.0446549575358599,314.309175895341,0.1417794901763552,63.36472986050075,328.34463879807856,0.043686646717766564
0.0449933276833206,314.440491624439,0.1428538153945429,63.3912031114869,328.5882157010018,0.044010500404352414
0.0453389415389591,314.592306637816,0.14395113938619514,63.421809018183716,328.85558883707427,0.04434117879828691
0.0456868951957452,314.69775235278,0.145055892246491,63.44306687432045,329.0753155828581,0.04467398545603826
0.0460331108065271,314.840426707849,0.1461551268107235,63.47183002430236,329.33351095686567,0.04500501983248445
0.0463791337561283,314.929669562797,0.14725374967570734,63.48982138385988,329.53583483122327,0.04533576053967992
0.0467190798105501,314.969143290325,0.14833307839849658,63.49777928732952,329.6842118335663,0.0456605862503966
0.0470604541957406,315.09907455015,0.1494169420714764,63.523973429310246,329.92778011513764,0.04598667061856525
0.0474118978792639,315.240916956084,0.15053277576666288,63.55256885834653,330.18708711817135,0.046322262240458385
0.0477566030585477,315.362386787896,0.15162721471088894,63.577057176439844,330.42302311332173,0.0466513099349418
0.0480997425418636,315.500441754116,0.1527166825704169,63.60488905762979,330.67593177433326,0.04697875555124301
0.0484415753938983,315.556226852003,0.1538020018756271,63.61613533336381,330.8422676060684,0.047304847722324336
0.0487873253671153,315.734840148401,0.15489975804059108,63.65214377391764,331.1386985244552,0.0476345685040893
0.0491377767297003,315.846618460563,0.15601244111679846,63.6746782816495,331.366619079309,0.04796866180941693
0.0494936204037482,316.000275332928,0.1571422447819005,63.705655507118294,331.64027300773586,0.0483077815595018
0.0498468908540615,316.119138068414,0.15826387846164525,63.72961823459225,331.8766942405902,0.048644335302692486
0.0501962640088274,316.205305295215,0.15937313822802698,63.74698954751534,332.07763028080547,0.04897706480606495
0.0505426476414312,316.33307666091,0.16047290626154406,63.77274825483946,332.32138789191225,0.04930683794809798
0.0508879363852481,316.373511442033,0.16156919802316272,63.780899906713856,332.47310656627275,0.04963546050603435
0.0512339446799004,316.427913150429,0.16266777435868376,63.791867291126486,332.6397633479544,0.049964659589012105
0.0515838300772087,316.481327092344,0.16377866049513762,63.80263554181654,332.80664609168497,0.050297437259752116
0.05193786615113,316.596790875171,0.16490272502983774,63.82591304043447,333.04015262352294,0.05063404997727159
0.0522943321700207,316.723626460447,0.1660345046398157,63.85148309442612,333.2864769886632,0.05097285861501124
0.0526475791588134,316.808004252497,0.16715606382923254,63.8684936573034,333.4871787345261,0.051308494472901436
0.0530017272863653,316.907235520404,0.16828048413420982,63.88849868091346,333.7038663925324,0.05164487349841825
0.0533601278813972,316.968099712908,0.1694184060234361,63.90076890212226,333.88155804791216,0.05198517646925998
0.0537200529475117,317.082542850652,0.17056116810834962,63.92384063869144,334.11623384132065,0.05232681042594566
0.0540813667944412,317.145239309291,0.1717083395723508,63.936480244753064,334.29688732348757,0.05266964523674351
0.0544405534916208,317.1697280935,0.17284875733589602,63.941417183649605,334.436623641697,0.05301034522871268
0.0547967075113983,317.275676862033,0.1739795463486896,63.96277645538585,334.6613393275227,0.053348054058105256
0.055153550509284,317.422135088838,0.17511252286697668,63.992302433909735,334.92909284922496,0.053686301843740486
0.0555045488403753,317.549910163352,0.17622694256819157,64.01806188893177,335.1753746612706,0.05401889795149967
0.0558607162661221,317.671879120828,0.17735777414493767,64.04265083075893,335.4172578261224,0.05435627910956953
0.0562147856837258,317.782835139303,0.1784819445458294,64.06501956408349,335.6469291106257,0.05469156013583381
0.0565706582944975,317.857286300745,0.17961184008502956,64.0800289182302,335.83868223048074,0.055028435434886586
0.0569226141697726,317.932605075451,0.180729299989028,64.09521318321093,336.03016008615157,0.055361491501933334
0.0572839111412788,317.94846991652,0.18187641787356018,64.09841153517044,336.1618018147235,0.05570327171185886
0.0576450423440169,317.995303552814,0.18302300944225364,64.1078531962473,336.3261562913145,0.056044778414155165
0.0580045502566821,318.075062754115,0.18416444706496565,64.12393265122958,336.5248637170334,0.05638463423657768
0.0583688052139452,318.185349495074,0.185320956554276,64.14616645820692,336.75744818168306,0.05672885985245806
0.0587312521586229,318.266743988227,0.18647172560362768,64.16257558802657,336.95894838310346,0.05707125930302398
0.0591011657142972,318.333124837747,0.1876462011428936,64.1759579672898,337.1469836011328,0.05742059153187674
0.0594708774003735,318.382468217782,0.18882003574618583,64.18590559270486,337.31695295159005,0.05776961123222721
0.0598369944929561,318.421000452998,0.1899824575151356,64.19367369132439,337.47435610354563,0.058115117518576835
0.0602118700229127,318.500269792858,0.1911726873227478,64.20965439024016,337.67776663988815,0.05846876553125985
0.0605895053248107,318.581566041429,0.19237167940627398,64.2260437139521,337.88426553348273,0.058824890635929085
0.0609707727592904,318.688412860581,0.193582203510747,64.24758403269314,338.1190916621224,0.059184312371453295
0.0613568362769214,318.792066073584,0.19480795517922544,64.26848052043454,338.3521386780424,0.05954812380211617
0.0617441520412997,318.891614766321,0.19603768273112654,64.28854953689033,338.58130711314834,0.0599129823470522
0.0621344283866113,319.001425964697,0.19727681012749085,64.31068747448292,338.8223972215273,0.060280495210829496
0.0625255176447083,319.03740402859,0.19851851852194885,64.31794065216374,338.98538286350157,0.06064863813482511
0.0629176428718882,319.048858692629,0.199763516118245,64.32024991243401,339.12266084253537,0.06101762022657252
0.0633016346586835,319.111513227529,0.20098269004132013,64.33288106666984,339.31179365323766,0.061378817018481836
0.0636954728126476,319.162004729608,0.20223312618015613,64.34306015348896,339.4911795246928,0.06174914019107251
0.0640912089118456,319.310957645791,0.20348958829510977,64.37308906139147,339.77598294010886,0.06212110990698418
0.064491975073827,319.376850981224,0.20476202085940068,64.38637315781475,339.97409489386246,0.06249766664174775
0.0649024620805568,319.436422736373,0.20606531710576784,64.3983828236528,340.16863305016915,0.06288321006634962
0.065312366532046,319.475902191445,0.20736676373924604,64.40634188179531,340.3416294135288,0.06326805806481699
0.0657283974554419,319.508501975041,0.20868766192102803,64.41291399816826,340.5092837832493,0.06365850665286059
0.0661483826909539,319.555881652778,0.2100211150437786,64.42246574120006,340.6939864034911,0.0640525118269461
0.0665707164039991,319.578312198927,0.21136202458269712,64.42698773930368,340.8528693891904,0.06444856372027312
0.0670000225585129,319.634805196125,0.21272507162327842,64.4383767275388,341.0503443547513,0.06485099346161516
0.0674441147026852,319.640506057818,0.21413506418102551,64.43952602125611,341.19837701200584,0.06526711318368023
0.0678984365973021,319.649735320908,0.21557753619643416,64.44138664069506,341.35345260793906,0.06569263919700839
0.0683732025103907,319.668394717979,0.21708491797049045,64.44514837514457,341.5251466062029,0.06613712005067292
0.0688599541735155,319.67041649381,0.21863035450091167,64.4455559651521,341.6829067242024,0.06659261707496195
0.0693659470448492,319.68954586241,0.2202368818673962,64.44941244586185,341.86511397149377,0.06706589997784916
0.0698822084331481,319.728666015859,0.2218760117752452,64.45729906879717,342.07201129643164,0.06754855683745586
0.0704104001375813,319.724050507969,0.22355302043682063,64.45636858240655,342.2359488378434,0.06804212646717935
0.0709338695559455,319.736982173969,0.22521503584012692,64.45897560627215,342.417163559709,0.06853104311285878
0.0714637450068,319.689674653889,0.22689739039659,64.44943841022403,342.53589604466146,0.06902569962111577
0.0719988445488812,319.685849672163,0.22859633144269778,64.44866729390806,342.7028614671861,0.06952498480183654
0.0725479416512519,319.601303950423,0.23033971474272477,64.43162287640529,342.7877207010824,0.0700370716613104
0.0731105118149749,319.522081009923,0.23212587501254528,64.41565153160047,342.88250388874434,0.07056145164891288
0.0736655494437875,319.476781463233,0.2338881194840253,64.40651914298778,343.01121410425486,0.0710785411126871
0.0742234859345666,319.381131991198,0.23565956784224892,64.38723620942552,343.08671294931264,0.07159806190183234
0.0747674882362374,319.246027726954,0.2373867751500537,64.35999918975394,343.1152513494946,0.07210434817276562
0.0753321450406202,319.007292440026,0.23917956050396913,64.31187015590923,343.03879606313353,0.07262958598837635
0.075890661032694,318.687268525601,0.24095284877880344,64.24735333476116,342.87265599671247,0.07314884043570384
0.0764742475583771,318.381661307087,0.2428057359978473,64.18574291950873,342.7296592919325,0.07369111515655127
0.0770511140634718,318.003260737931,0.24463728715152294,64.10945736476688,342.50576625360526,0.07422685671703877
0.0776363174321895,317.591956042934,0.24649530784720167,64.02653833825549,342.24862595619317,0.07477004769179697
0.0782433988764774,317.067506860211,0.24842279143281573,63.920809383018536,341.87594627024475,0.0753332344556426
0.0788482142474601,316.553877695305,0.2503430802356858,63.81726174337349,341.51358566468866,0.0758940037647921
0.0794717628133217,315.931196794873,0.2523228469322964,63.691729273846406,341.03880593188404,0.0764718129773623
0.0800742816763782,315.214548129266,0.2542358443225008,63.54725290286003,340.4551266446611,0.07702981810091847
0.0806823975639538,314.360422807171,0.2561666122655533,63.37506123792568,339.7237754184718,0.07759269119947122
0.0812847708593755,313.455239957751,0.2580791474785172,63.1925763754826,338.9343773123874,0.07814993676712573
0.0818836846820501,312.476990729143,0.25998069886550906,62.99536133099523,338.06375810840404,0.07870367435186516
0.0824956082715359,311.511236073607,0.2619235562621265,62.800665192439176,337.20954497691724,0.07926912386229291
0.0831043680214784,310.340870223704,0.2638563684681939,62.564719437098724,336.13155211488055,0.07983133273987074
0.0837280185983705,309.225321579469,0.2658364590498263,62.33982483042095,335.1161450557618,0.08040696618338371
0.0843666850527169,308.041977492066,0.2678642250423761,62.10126266240051,334.03045799015524,0.08099611616077565
0.0849973085718167,307.019874952745,0.269866454715518,61.895206790473395,333.11573800178405,0.0815775064103755
0.0856484751073726,305.951699617093,0.271933908465908,61.67986264280596,332.15599614580594,0.08217748136712354
0.0862911902270878,304.884413944182,0.2739745289710037,61.464697851147086,331.1932529051135,0.08276931653523033
0.0869176409661651,303.836059288474,0.2759635100675742,61.253349552556365,330.2447728022841,0.08334583798815018
0.0875471321455694,302.795458787429,0.2779621445621828,61.043564491545695,329.3043328309704,0.08392482294552749
0.0880703784287563,302.014659005422,0.27962345151130125,60.88615525549308,328.6132043150613,0.08440583239754029
0.0884071587897478,301.592103090235,0.28069272915744925,60.80096798299138,328.25500403786737,0.08471530525716812