File: example/data/02 processed data/test_ID_063.csv
Strain,Stress_MPa,Displacement(mm),Force(kN),True Stress (MPa),True Strain
-0.00043484483494170045,,-1.0003676111632112e-05,,,-3.150769093267974e-06
-0.00043450807947760045,,-8.934477513314449e-06,,,-2.8140126249712225e-06
-0.00043453944577150045,,-9.034065496445646e-06,,,-2.8453790076239707e-06
-0.00043451086739110045,,-8.943329138703428e-06,,,-2.816800546275992e-06
-0.00043392368268860043,0.361330458222076,-7.079017708194585e-06,0.0728442203775705,0.3613296525953949,-2.229614362157925e-06
-0.00043239462483170044,0.355902880902802,-2.2242590125388447e-06,0.0717500207900048,0.3559026315736081,-7.005542650716898e-07
-0.0004308492815636004,0.345903036017836,2.682205863730944e-06,0.0697340520611957,0.3459033282330018,8.447888914989637e-07
-0.00042562427161260046,0.344990099011353,1.9271612458059788e-05,0.0695500039606887,0.3449921930319798,6.069780778325187e-06
-0.0003978138434234004,0.353487085800929,0.0001075697219587,0.0712629964974672,0.3534990620237748,3.387965346654215e-05
-0.0003677991538718004,0.366210576638791,0.0002028663612852,0.0738280522503802,0.3662339756331679,6.389287574699679e-05
-0.00034003840392650046,0.380314088532964,0.0002910067423614,0.0766713202482455,0.3803489464743744,9.165146676152045e-05
-0.00030371377157010045,0.395410912286352,0.000406337450093,0.0797148399169285,0.3954615170932299,0.0001279721104621
-0.00025754588239770046,0.433561670213419,0.0005529204982154,0.0874060327150252,0.4336371741928526,0.0001741330263788
-0.00019436991897760043,0.692967716133622,0.0007535041820742,0.1397022915725382,0.6931321741091019,0.0002372959949125
-0.00012065399242320043,1.31140216317317,0.0009875522488844,0.2643786760957111,1.3118100618048028,0.0003109917154518
-6.66568954717277e-05,2.3274752707757,0.0011589930317057,0.469219014588381,2.3283248857742183,0.0003649705654801
-1.9252342287627696e-05,3.75437913033553,0.0013095024880652,0.7568828326756429,3.755927592953582,0.0004123566978141
3.357738293027231e-05,5.57291931711671,0.0014772368656321,1.123500534330729,5.575512237388974,0.0004651632485413
9.451427518307226e-05,7.82241126615755,0.0016707114985347,1.576998111257362,7.826527484251608,0.0005260699469324
0.00016270895568819957,10.480880796023,0.001887229609139,2.112945568478237,10.487110663288547,0.0005942264389942
0.00022745492369829958,13.3562380747143,0.0020927980575711,2.6926175958624032,13.365041825611693,0.0006589318512268
0.0002809734073443996,16.3111664576085,0.0022627192431475,3.2883311578538734,16.32279089547364,0.0007124136512785
0.00033174488332879956,19.3420869889992,0.0024239186793979,3.899364736982239,19.35685349166099,0.0007631476828585
0.00039323231595139957,22.4412654849444,0.0026191412779747,4.524159121764791,22.4597778769953,0.0008245863219979
0.0004646044909314996,25.6257778103826,0.0028457479335365,5.166156806573132,25.64874615817761,0.0008958971260408
0.0005319670038822996,28.8565435888071,0.0030596239121553,5.817479187503511,28.88435151661386,0.0009631970514446
0.0005935824061680995,32.1294682522486,0.0032552528144127,6.477300799653318,32.16240984026552,0.0010247512400314
0.0006496430599711995,35.4375758700927,0.0034332453902376,7.144215295410689,35.47589583670599,0.0010807529069122
0.0007093419165787996,38.7992161728685,0.0036227892599667,7.8219219804502895,38.84348747480431,0.001140385500601
0.0007736354871029996,42.1792062061733,0.003826921346381,8.503327971164536,42.230046050143,0.0012046037314252
0.0008401665413927996,45.572086546048,0.0040381574437511,9.187332647683276,45.63004788794192,0.0012710524826428
0.0009064159681538995,48.9834682671172,0.0042484993737176,9.875067202650827,49.04901353774881,0.0013372155675732
0.0009705518673545995,52.4066787400977,0.0044521308536799,10.565186434003698,52.48016579249382,0.0014012637094415
0.0010349824702505996,55.8552148742215,0.0046566980178747,11.260411318643056,55.937136407573554,0.0014656020215449
0.0010984621818457996,59.3537957279697,0.0048582461021894,11.965725218758692,59.44461630962184,0.0015289867564353
0.0011612962505552996,62.8698164082538,0.0050577442703421,12.674554987903967,62.96996741729831,0.0015917228581448
0.0012282762842679995,66.3670324060123,0.0052704058773799,13.37959373305208,66.47719971236094,0.0016585941270784
0.0012973213498935995,69.876077155682,0.0054896239607412,14.087017154585492,69.99689397062261,0.0017275223942728
0.0013651792883669996,73.4263708863756,0.0057050729153942,14.802756370693318,73.55830877608254,0.0017952609135296
0.0014322863345744995,76.9921329849531,0.005918137787103,15.521614009766544,77.135644812206,0.0018622453496496
0.0014948512851396996,80.5506158515852,0.0061167815051476,16.239004155679577,80.70580026647316,0.0019246919475162
0.0015580528097085995,84.1171362034903,0.0063174463456538,16.958014658623647,84.28450801284956,0.0019877699561484
0.0016248007751908996,87.6991249232794,0.0065293711360601,17.680143584533127,87.8794777216831,0.0020543831551026
0.0016923701562419995,91.3158416454745,0.0067439039208974,18.40927367572766,91.50980235807702,0.0021218115918978
0.0017582050279641996,94.9360463329769,0.0069529296386153,19.139106940728144,95.14394669528288,0.0021875047646746
0.0018200981679086996,98.5574642258034,0.0071494403579391,19.869184787921967,98.77939515881508,0.0022492607541172
0.0018835795405124996,102.192075726531,0.0073509937159562,20.60192246646865,102.42867834274716,0.0023125974952084
0.0019483045360658997,105.824715768607,0.0075564955768382,21.33426269895117,106.07657844470955,0.0023771708959371
0.0020120761689238994,109.430665293549,0.0077589705111624,22.06122212317948,109.6980886967079,0.0024407890890875
0.0020758470859387995,113.028425682553,0.0079614431726847,22.786530617602686,113.31184911183476,0.0025044025211682
0.0021384662736192994,116.595704287786,0.0081602590935703,23.505693984417658,116.89537394327756,0.0025668631307039
0.0022035455814319997,120.131591205254,0.0083668858958756,24.218528786979206,120.44816673788527,0.0026317734963307
0.0022695708812473995,123.625622539037,0.0085765162227895,24.922925503869862,123.95956810037826,0.0026976230928326
0.0023329077027964998,127.121170379474,0.0087776106312079,25.62762794850196,127.4726097925683,0.0027607872908586
0.0023924612316781994,130.618234726567,0.0089666930854073,26.33263612087591,130.987120906772,0.0028201748683859
0.0024570741091303997,134.084968940555,0.009171838971318,27.031529738415887,134.4723093322391,0.0028846037073469
0.0025229529466730995,137.506207954883,0.0093810042805161,27.721251523704414,137.91249026210264,0.0029502906269412
0.0025894058641392995,140.922897449246,0.0095919922934713,28.410056125768,141.3486396055631,0.0030165455830057
0.0026487543474743996,144.359301530127,0.0097804237280602,29.102835188473605,144.80399291219044,0.0030757135582272
0.0027075189963923995,147.768408491214,0.0099670014883749,29.790111151828743,148.23228501006966,0.0031342960256041
0.0027678163854268994,151.141119292573,0.0101584456985594,30.47004964938272,151.62469688411727,0.0031944029141824
0.0028310068644248998,154.49866502738,0.0103590754693781,31.14693086951981,155.00274796625777,0.0032573898756713
0.0028917572997867996,157.841045695633,0.0105519581016521,31.820754812239613,158.36562273528693,0.0033179409118783
0.0029495155676004994,161.153096230781,0.0107353406019606,32.48846420012545,161.69798863301656,0.0033755062018304
0.0030080179294824996,164.440882659444,0.0109210856009359,33.15128194414391,165.00651193686673,0.0034338097218583
0.0030701314653401998,167.681657381794,0.0111182960772841,33.80462212816967,168.26884929155793,0.0034957084216619
0.0031339721754839994,170.905750530935,0.0113209903319907,34.454599307036496,171.5151433969011,0.0035593243293748
0.0031964052305222994,174.099513546971,0.0115192152817373,35.09846193106936,174.73116387043348,0.0036215336248898
0.0032582732013443994,177.265979443211,0.0117156460890975,35.73682145575134,177.92008510582323,0.0036831760440677
0.0033191000706980995,180.421829792864,0.0119087713992955,36.37304088624138,181.09855493505168,0.003743777453127
0.0033839814391160997,183.56403158262,0.0121147697440226,37.0065087670562,184.2644523624336,0.0038084142852532
0.0034467018697563996,186.695617825789,0.0123139071113056,37.63783655367906,187.41969735208647,0.0038708943528616
0.0035112078592590998,189.827204068957,0.0125187136279766,38.269164340301735,190.57567411826057,0.0039351490647659
0.0035708165704218995,192.937559218952,0.0127079712859185,38.89621193854072,193.7097938528196,0.0039945219050903
0.0036312200436247996,196.035782315704,0.0128997523133377,39.52081371484593,196.8322588626092,0.0040546827668594
0.0036939168088163995,199.124906372525,0.0130988145428211,40.14358112470104,199.9464182526605,0.0041171238817564
0.0037576041721324996,202.179150776274,0.0133010219213497,40.75931679649684,203.0261395373812,0.0041805475640168
0.0038182492391687995,205.196999020296,0.0134935700091899,41.36771500249168,206.06907463351047,0.004240937807147
0.0038786665113307995,208.163286038038,0.0136853948483043,41.96571846526847,209.06054486082573,0.0043010975863312
0.0039409325301832995,211.035549643153,0.013883089458161,42.54476680805964,211.95832930127835,0.0043630944462337
0.004007843480436599,213.841086955435,0.0140955317252152,43.1103631302157,214.7904424909736,0.0044297118746544
0.0040748530259963,216.520754215328,0.0143082870323669,43.65058404981012,217.49651519163584,0.004496423018469
0.004140204285897699,219.151893262251,0.0145157772825542,44.1810216816698,220.15383344292653,0.0045614789749176
0.004203194409484499,221.796680869073,0.0147157709249423,44.71421086320512,222.8246837502011,0.0046241804589261
0.004271372242899,224.477864635621,0.014932235546033,45.25473751054119,225.53359891896253,0.0046920414509289
0.004342545357060199,226.860296591078,0.0151582101834951,45.73503579276133,227.943381963682,0.0047628788910809
0.004408269267323099,229.203299373497,0.0153668835985798,46.207385153697,230.3126349394444,0.004828288371364
0.004474279040513599,231.496257436292,0.0155764646284597,46.66964549915647,232.63197185064703,0.004893978040906
0.004541226080369599,233.784665979121,0.0157890214800025,47.1309886613908,234.9472584556059,0.0049605960248106
0.004610094863116599,235.951753989526,0.0160076798652242,47.56787360428845,237.1413729317315,0.005029121675357
0.0046871725536194,237.985389414267,0.0162524015325703,47.97785450591624,239.20360488124203,0.0051058097652639
0.0047626456516683,239.835527533718,0.0164920286188755,48.35084235079755,241.0813147412485,0.0051808956751074
0.004840247203833999,241.890394051632,0.016738413547002,48.76510344080901,243.16562600397324,0.0052580932416
0.004923184033230499,243.85730318354,0.0170017379803355,49.16163232180166,245.16312931686844,0.0053405917228141
0.005015183970989599,245.769618075858,0.017293837782721,49.54715500409298,247.10829521189743,0.0054320974493655
0.0051151734001986995,247.644020301793,0.0176113042204599,49.92503449284147,249.01766886239545,0.0055315402542122
0.0052252496753468995,249.433498155032,0.0179607963940554,50.28579322805445,250.8445294225027,0.005641003327665
0.005343237834584999,251.206294435063,0.0183354087996364,50.6431889581087,252.65699367963265,0.0057583209070489
0.005473917141793799,252.977574208439,0.0187503156000243,51.000278960421305,254.47156140722225,0.0058882414432292
0.005619376455830499,254.707908302122,0.0192121489220905,51.349114313707794,256.2491638189518,0.0060328363200576
0.005779373864442199,256.407912262699,0.019720140694433,51.69183511216013,258.00047922489944,0.0061918587514702
0.0059478267680523,258.066970543584,0.0202549786633947,52.02630126158653,259.7133141599893,0.0063592578290003
0.006128046383545499,259.627455891875,0.0208271759425856,52.340895107802,261.33054461735094,0.00653831898543
0.006318698351775299,261.125764467299,0.0214324959417156,52.64295411660749,262.88846584910146,0.0067277105408455
0.006515260554114999,262.475455390505,0.0220565809341438,52.915051806725806,264.2988604692599,0.0069229357103598
0.006717336966064099,263.679561674803,0.0226981735420825,53.15779963364028,265.5646150450061,0.0071235978576118
0.006923238494801599,264.710786200399,0.0233519108958241,53.36569449800044,266.6577161822936,0.007328016943575
0.007132922156825299,265.635855260124,0.0240176565227493,53.552188420441,267.6452885614672,0.0075361479956623
0.007347428485318599,266.416856187597,0.0246987141157156,53.70963820741955,268.4893455628994,0.0077490211896245
0.007555431844465199,267.075020075992,0.025359124781006,53.842324047319984,269.2081818901642,0.0079553976581684
0.0077702558773113,267.67404020483,0.0260411910852921,53.96308650529373,269.86948928500203,0.0081684967531199
0.0079875096732703,268.180553427696,0.0267309718874619,54.06519957102351,270.43842014720457,0.0083839599266583
0.0082050281079383,268.64915398418,0.0274215929175328,54.15966944321069,270.9694020906977,0.0085996390585214
0.0084206919068018,269.06770982104,0.0281063254789244,54.24405029992167,271.4496010424885,0.0088134333227016
0.0086329528969746,269.419539365066,0.028780254122723,54.314979135997305,271.86173237563406,0.0090238096538295
0.008841181652049,269.757720349195,0.0294413804200843,54.3831564223977,272.25915016527546,0.0092301465558315
0.0090596689375605,270.083769280082,0.0301350775515833,54.44888788686453,272.6472323769888,0.0094466030217948
0.0092725970025358,270.402235677693,0.0308111241578799,54.513090712622905,273.02629767959337,0.0096575068689126
0.009481397697337,270.711603035371,0.0314740663638737,54.5754591719308,273.3951919989634,0.0098642793965399