File: example/data/02 processed data/test_ID_056.csv
Strain,Stress_MPa,Displacement(mm),Force(kN),True Stress (MPa),True Strain
0.0004557084238626,1.30483001761722,-0.0001075461926088,0.2630537315516316,1.3047858193493789,-3.387339026655298e-05
0.000451783962066,1.92342568114305,-0.000120006358813,0.3877626173184389,1.9233529808871628,-3.779799270140651e-05
0.0004503403402816,2.67481783685187,-0.0001245898579785,0.539243275909337,2.674712874592213,-3.924167009499226e-05
0.0004487715606851,3.6272234448923,-0.0001295707331973,0.7312482464902876,3.627075419065143,-4.081051248481442e-05
0.000442478903887,5.23690968194364,-0.0001495499185313,1.055760991879838,5.236663011261344,-4.710344589514666e-05
0.0004385414740502,7.36948226936679,-0.0001620512582632,1.485687625504345,7.369106132713404,-5.104106895529777e-05
0.0004477007405131,9.82971905826451,-0.0001329705872434,1.9816713621461253,9.829307384716286,-4.188137693177908e-05
0.0004669196744348,12.5204123668506,-7.195047204203678e-05,2.524115133157081,12.520128634699432,-2.266182277467207e-05
0.0004902651378704,15.3622690403382,2.171374366118964e-06,3.097033438532181,15.362279546554642,6.83897204378412e-07
0.0005194869832583,18.3677575102428,9.495073347255508e-05,3.702939914064949,18.36830681167519,2.990529565809688e-05
0.0005535941080239,21.4163393299207,0.0002032408546034,4.317534008912013,21.41771025121453,6.401081885554406e-05
0.0005911496807053,24.5426970366831,0.0003224797978667,4.947807722595313,24.54518980014121,0.0001015632825481
0.0006336877175454,27.5981051488364,0.000457538064834,5.563777998005418,27.602082214544392,0.0001440960947721
0.000679300015233,30.7051544939357,0.0006023571099922,6.190159145977438,30.71097983822636,0.0001897007804699
0.0007273211179046,33.8677998516884,0.0007548241109745,6.8277484501003824,33.875851578275395,0.0002377116218257
0.0007727452994568,37.0730063026533,0.0008990458874027,7.473918070614904,37.0835040455982,0.0002831239756488
0.0008151846581772,40.2910417845559,0.00103379085134,8.12267402376647,40.30416068546545,0.0003255504204557
0.0008604453824752,43.5322459770351,0.0011774936509862,8.776100788970277,43.54839052609057,0.000370795388935
0.0009110769470342,46.8058646570207,0.001338248868461,9.436062314855374,46.825593128017424,0.0004214069022395
0.0009709186011772,50.0714465034105,0.001528246120365,10.094403615087558,50.095547761319125,0.0004812215550769
0.0010247546181263,53.3827042550823,0.0016991754741784,10.761953177824592,53.41127325722893,0.0005350302234944
0.0010716302244447,56.694078064152,0.0018480055242393,11.429526137733044,56.72707679468876,0.0005818796592029
0.0011203156991475,60.0229229902707,0.0020025819064207,12.100621274838574,60.06078151611348,0.0006305356293379
0.0011787887163837,63.3252300874686,0.0021882337361456,12.766366385633669,63.368874309461226,0.0006889700815487
0.001239276354062,66.639238678683,0.0023802819857742,13.434470517622492,66.6891977902964,0.0007494142326226
0.0012986082734062,69.9526818148845,0.0025686608296921,14.102460653880714,70.00927542550177,0.0008086999470062
0.0013488721399518,73.3049745800319,0.0027282486059744,14.77828287533443,73.36796487757803,0.0008589219204529
0.0014044775167459,76.6549735048416,0.0029047956772956,15.453642658576069,76.7251048546621,0.0009144780138072
0.0014658467606641,80.019166260729,0.0030996430267359,16.131863918162964,80.09728621370705,0.0009757892829796
0.0015326718100519,83.3748887794096,0.0033118125585422,16.808377577928976,83.4618563396385,0.0010425469286631
0.0015927819610882,86.7953132410102,0.0035026622880824,17.497935149387658,86.89106589312725,0.0011025926419217
0.0016504471790103,90.2011502996086,0.0036857493549851,18.184551900401093,90.30586174261197,0.0011601926547254
0.0017117251336848,93.6024056813352,0.0038803068610766,18.87024498535717,93.7168012898324,0.0012213976833266
0.0017736198654413,96.9930838458363,0.0040768226344035,19.5538057033206,97.11762671185308,0.0012832149524233
0.0018363715378509,100.365421503785,0.004276059194304,20.233668975163056,100.50059267966265,0.0013458841888336
0.0018980381223909,103.719418848853,0.0044718506002185,20.909834839928763,103.8655031781234,0.0014074659369241
0.0019565474896056,107.071649187354,0.0046576178411252,21.585644476170565,107.22871968295516,0.0014658913053276
0.0020173523949816,110.390173042397,0.004850673415694,22.25465888534724,110.55882396451688,0.0015266052994878
0.0020786341775715,113.670544791048,0.0050452430754169,22.91598182987528,113.85117330411444,0.0015877917284288
0.0021372166200534,116.947652649312,0.0052312423302969,23.576646774101302,117.14033973938064,0.0016462795175555
0.0021956681129784,120.253668225014,0.0054168258203338,24.243139514162824,120.4588314297482,0.0017046331595432
0.0022506115904484,123.506880654231,0.0055912713613011,24.89898713989297,123.72438001949892,0.0017594815541204
0.0023097700654169,126.72514323162,0.0057790995193261,25.5477888754946,126.95580692117476,0.0018185342887134
0.002369747770102,129.939871408534,0.0059695287317012,26.19587807596045,130.1841800056259,0.0018784012289399
0.0024282045067262,133.161434480146,0.0061551288704831,26.845345191197435,133.41958433520227,0.0019367465613008
0.0024883594641398,136.371846696917,0.0063461208602713,27.49256429409847,136.64442377442157,0.0019967833243123
0.0025444142150698,139.567033219205,0.006524094694474,28.13671389699173,139.85382016123614,0.0020527246929777
0.0026011901318227,142.683921232984,0.0067043582301645,28.765078520569578,142.98521386971802,0.0021093825788519
0.0026622988082734,145.81573699442,0.0068983782778954,29.39645257807508,146.1325534078555,0.0021703606303819
0.0027195660763261,148.91474067775,0.0070802018539628,30.0212117206344,149.24681829130242,0.0022275021099852
0.0027734889989721,151.974638230921,0.0072514071333638,30.63808706735368,152.32173428627786,0.002281303605558
0.0028273216214336,154.976005234871,0.0074223257096791,31.243162655349995,155.33829890039482,0.0023350121171111
0.0028803699385545,157.979002771829,0.0075907541165379,31.848566958800724,158.3566971861965,0.0023879353098167
0.0029371683060181,160.948206979988,0.0077710889332349,32.44715852716558,161.34214172962143,0.0024445966029817
0.0029944589173868,163.897106792229,0.0079529866243305,33.04165672931337,164.30764899635028,0.0025017456999222
0.0030474403737547,166.843459458492,0.0081212027482986,33.63564142683199,167.270221525103,0.0025545933793564
0.0030999551636889,169.801737534825,0.0082879372063397,34.23203028702072,170.24498356260958,0.0026069728147379
0.0031568868360271,172.751575973983,0.0084686952660134,34.82671771635498,173.21235721922622,0.0026637546489297
0.0032128504063795,175.66680811768,0.0086463796018823,35.41442851652429,176.14519611970724,0.0027195677868502
0.0032676431104501,178.57375210727,0.0088203464373065,36.000468424825634,179.0698410389852,0.0027742101879659
0.0033110637660039,181.460128566494,0.0089582070186898,36.5823619190052,181.9721151483324,0.0028175096149947
0.0033680274198415,184.332980279823,0.0091390666196242,37.16152882441232,184.86357284264847,0.0028743113858254
0.0034252297709569,187.195051501983,0.0093206840844156,37.73852238279977,187.74459037984624,0.0029313479290243
0.0034804799791496,190.042702394731,0.0094961034954274,38.312608802777774,190.61110087362584,0.0029864348994639
0.0035363819173011,192.874479682518,0.0096735921490584,38.88349510399563,193.46212977776543,0.0030421685860066
0.0035942091130051,195.708097216822,0.0098571934954186,39.45475239891132,196.3156980303296,0.0030998184671641
0.0036528029990347,198.512982112349,0.0100432290835626,40.02021719384956,199.14092269673185,0.0031582292980579
0.0037185880018773,201.286574021208,0.0102520964675878,40.579373322675536,201.9365297297106,0.0032238047144009
0.0037686899706881,204.040861974422,0.0104111702185621,41.13463777404348,204.70993414625124,0.0032737441773258
0.0038280242464044,206.74967831307,0.0105995565439614,41.68073514791491,207.43990033062127,0.0033328827766891
0.003884350408629,209.439896998382,0.0107783921090245,42.22308323487381,210.15089710330244,0.0033890199471886
0.0039382529285221,212.076660252993,0.0109495326096851,42.75465470700339,212.8080430269121,0.0034427386566888
0.0039923693015185,214.719445839125,0.0111213520939486,43.287440281167605,215.47156255049336,0.0034966675873033
0.0040432513136007,217.324191180056,0.0112829024823096,43.812556941899295,218.0964896544281,0.003547370707175
0.0041017539438623,219.877439363189,0.0114686483333902,44.3272917756189,220.6716746477568,0.0036056644754639
0.0041649931026186,222.418051201976,0.0116694326624415,44.839479122318366,223.2355291457281,0.0036686740404743
0.0042233374598708,224.921250080068,0.0118546759967172,45.34412401614171,225.7610511964384,0.0037268030539276
0.0042878672802824,227.379395721559,0.012059558176524,45.83968617746629,228.24304770607773,0.0037910907654811
0.0043514951130252,229.808165445762,0.0122615765454824,46.32932615386562,230.6956647879321,0.0038544758271234
0.0044192339943562,232.149404861122,0.0124766474937083,46.801320020002194,233.0616714092563,0.0039219518365685
0.0044947018902764,234.468670306694,0.012716258063255,47.26888393382952,235.40774561988084,0.0039971215053799
0.0045704294345767,236.736838783488,0.0129566930164084,47.72614669875118,237.70292588452503,0.0040725441172711
0.004653432736891,238.914749529959,0.0132202285012563,48.16521350523973,239.90955506731527,0.00415520665573
0.0047456654999981,240.992340574665,0.0135130675241214,48.58405585985247,242.0180242820608,0.0042470527497963
0.0048517192245684,242.940874905092,0.0138497880996321,48.97688038086654,244.00061652341475,0.0043526514379834
0.0049749039908725,244.739488432025,0.0142408997326476,49.33948086789625,245.83722402742023,0.0044752936682834
0.0051087699416584,246.364693517025,0.0146659241263928,49.66712221303224,247.50269852569983,0.0046085529887628
0.0052560189414788,247.750096242013,0.0151334397008226,49.94641940238982,248.93098164117885,0.0047551142044391
0.0054156584576705,248.948122788845,0.0156402951647312,50.18794155423116,250.1744604647893,0.0049139837980135
0.0055848220406783,249.934862912635,0.016177389540781,50.38686836318721,251.2083412235513,0.0050823039863528
0.0057621445281893,250.742853162093,0.0167403884386284,50.549759197477954,252.06491072434287,0.0052587119925
0.0059419366735551,251.381278695098,0.0173112285001648,50.67846578493176,252.7518987757765,0.0054375451527905
0.0061275670870774,251.899704816508,0.0179006050630981,50.78298049100801,253.3199117870376,0.0056221518909755
0.0063150513901901,252.315694879226,0.018495867725481,50.86684408765196,253.7855524280603,0.0058085677098627
0.0065052756739249,252.662454952904,0.019099829826339,50.93675091850545,254.1823950767168,0.0059976723843772
0.0066999097840567,252.958267297516,0.0197177931260074,50.99638668717922,254.52922124525952,0.006191123923634
0.0068960551890945,253.214545724818,0.0203405547870024,51.048052418123305,254.8367581154264,0.0063860397222262
0.0070899603916673,253.442938905039,0.0209562038051711,51.09409648325586,255.11575839501555,0.006578692025296
0.0072874702690765,253.643293983274,0.0215832976659453,51.13448806702803,255.3675329486321,0.006774887563123
0.0074851758698006,253.81732890275,0.0222110129482443,51.16957350679441,255.59293204566268,0.006971238979456
0.0076818066191073,253.979448418495,0.0228353155772931,51.20225680116859,255.8061258530724,0.0071664846740015
0.0078736148094576,254.131716063648,0.0234443065816553,51.232953958431445,256.008233186016,0.0073569050565293
0.0080654491814379,254.26225767028,0.0240533807126927,51.259271146328445,256.188514956772,0.007547315170811
0.0082573498417656,254.394847800542,0.0246626653092332,51.28600131658927,256.370928111628,0.0077377548133892
0.0084500054668877,254.513626067524,0.0252743469189958,51.30994701521284,256.53966250243496,0.0079289071983132
0.0086412743367695,254.641519270479,0.0258816255808706,51.335730284928566,256.71727878515696,0.0081186475096899
0.0088302565539537,254.762765068484,0.0264816441204304,51.36017343780637,256.8876585738951,0.0083060840908523
0.0090217776615684,254.876236731582,0.0270897236371071,51.38304932508693,257.05089084645584,0.0084960029606773
0.0092179405607462,254.984985063548,0.0277125408419966,51.40497298881128,257.2105856344675,0.0086904874056716
0.0094101721332067,255.114790542523,0.0283228760845587,51.43114177337264,257.39056521964864,0.0088810374743759
0.0096011475010066,255.219546054553,0.0289292228773234,51.452260484597886,257.5449958594228,0.009070306379426
0.0097931913120119,255.326453736522,0.0295389619772652,51.473813073282834,257.7019115030458,0.0092605980635519
0.0099825093233002,255.410359991315,0.0301400466631055,51.490728574249104,257.834952170332,0.0094481533800638