File: example/data/02 processed data/test_ID_067.csv
Strain,Stress_MPa,Displacement(mm),Force(kN),True Stress (MPa),True Strain
0.00031381412272609956,0.0345559955879448,1.3684924415099987e-05,0.0069664887105296,0.0345561445316259,4.310203125376892e-06
0.00031217833348919956,0.0333648124952518,8.491293588082916e-06,0.0067263461990427,0.0333649017268796,2.674419601099039e-06
0.00030776401632389956,0.0375716223060733,-5.524163411855169e-06,0.0075744390569043,0.0375715569354335,-1.739895501612645e-06
0.0003069386268183996,0.095082783281952,-8.144775091607198e-06,0.0191686891096415,0.0950825393676575,-2.565286783750674e-06
0.00030400772547879956,0.174234399890878,-1.7450386845050114e-05,0.035125655018001,0.1742334422664119,-5.496199937110695e-06
0.00030082276923439955,0.263487882051596,-2.7562622920935565e-05,0.0531191570216017,0.2634855946761197,-8.681178758761175e-06
0.00029806620743679955,0.351984526261713,-3.631470662842726e-05,0.0709600804943613,0.3519805003672849,-1.14377682861723e-05
0.00029319648060649955,0.441539433948759,-5.177608931452879e-05,0.0890143498840698,0.4415322335754777,-1.6307562672952947e-05
0.0002901076451046996,0.530340312340583,-6.158314203261234e-05,0.1069166069678615,0.5303300257192348,-1.939645331706779e-05
0.00028959510883519955,0.617340053686954,-6.321044468831708e-05,0.1244557548232899,0.6173277631863816,-1.990899965943873e-05
0.00028743999857469956,0.649001694405181,-7.005291976558776e-05,0.1308387415920845,0.6489873748890783,-2.206415514888333e-05
0.00028623312172959954,0.651776740592443,-7.388475374873773e-05,0.1313981909034365,0.6517615732337098,-2.327105935133153e-05
0.00028660358623669956,0.654740518953732,-7.270852893857332e-05,0.1319956886210723,0.6547255251836628,-2.290058629157258e-05
0.0002865872699451996,0.657261728966465,-7.276033316417503e-05,0.1325039645596393,0.6572466667357955,-2.2916902956902705e-05
0.00028733200777989956,0.658981651690397,-7.039579053892823e-05,0.132850700980784,0.6589670408134454,-2.2172148332217525e-05
0.00028674939892489956,0.660516124264565,-7.224557365341416e-05,0.1331600506517363,0.6605010945428942,-2.275477027471248e-05
0.00028328165413199957,0.660652580734841,-8.325566337106884e-05,0.1331875602761439,0.6606352569336231,-2.622259998924518e-05
0.00028475947427119956,0.66121879303588,-7.85635844291625e-05,0.1333017086760334,0.6612024315497469,-2.474474218933233e-05
0.00029803261840889955,0.684596793864476,-3.64213517919615e-05,0.1380147136430783,0.6845889406548178,-1.1471357698703528e-05
0.0003089985450474996,0.819670711420175,-1.6045347143355258e-06,0.1652456154223072,0.8196702971870693,-5.0536539199985e-07
0.00031929189315269956,1.23560890446108,3.107684551971891e-05,0.2490987551393537,1.235620998579835,9.787934938911629e-06
0.00033161510702659955,1.9777028502123,7.02030495693722e-05,0.3987048946027997,1.9777465795890643,2.2110952265784703e-05
0.0003520961683442996,3.13819563935793,0.0001352304192531,0.6326602408945587,3.138329302196358,4.25913510080248e-05
0.00037834162744429956,4.62997953933023,0.0002185597518956,0.9334038751289744,4.630298256552088,6.883534792558487e-05
0.00040023877542609955,6.58945606227781,0.0002880831967376,1.3284343421552067,6.590053955684796,9.073074895534976e-05
0.0004182513291671996,8.88036078368084,0.0003452730548658,1.7902807339900575,8.881326499994572,0.0001087415062835
0.00044023654119589956,11.4445303480643,0.000415076103057,2.3072173181697626,11.446026521625935,0.0001307240861184
0.00047127845491229956,14.1108675446997,0.0005136341791065,2.8447508970114592,14.11315032387066,0.0001617614605099
0.0005016455733594995,16.8456890690394,0.0006100497801764,3.3960909163183426,16.848925827752307,0.0001921232062025
0.0005289028022131996,19.5470579772674,0.0006965914817869,3.940686888217108,19.551346580127547,0.0002193748274843
0.0005551913300888996,22.3464172424731,0.0007800575577922,4.505037716082576,22.351907476066664,0.0002456572435655
0.0005859610784819995,25.0841540248635,0.0008777515089403,5.0569654514124815,25.09108871905116,0.0002764189609288
0.0006174561848365995,27.8772143438993,0.0009777484716162,5.620046411730099,27.88579919546392,0.0003079048669557
0.0006534995062810996,30.7112322113434,0.0010921860172025,6.19138441380683,30.72179673997089,0.0003439364430493
0.0006862276719778995,33.578227258971,0.0011960979432898,6.769370615408554,33.59087697505407,0.0003766528190863
0.0007194822302902995,36.4502002380031,0.0013016811659317,7.348360367981424,36.46514402985955,0.00040989430183
0.0007538712176637996,39.3458904971219,0.0014108662008426,7.932131524219775,39.36337452453747,0.0004442686054389
0.0007928365251099995,42.2290861687703,0.0015345810519842,8.513383771624094,42.24949686340879,0.0004832158472134
0.0008337709740112995,45.166455595603,0.0016645479272459,9.105557448073563,45.19013488065582,0.0005241296837362
0.0008714949179117995,48.1020914666878,0.00178432144913,9.69738163968426,48.12912440953883,0.000561833149794
0.0009097506144758996,50.9994902245615,0.001905783285721,10.281497229271595,51.03010250048284,0.0006000666281676
0.0009503525262235995,53.9112116258616,0.0020346943555199,10.8685002637737,53.94576055121416,0.0006406433601247
0.0009970115943394996,56.8574185499571,0.0021828368967879,11.462455579671351,56.89650846210419,0.0006872714588848
0.0010440008769305995,59.8500094551039,0.0023320278690146,12.065761906148946,59.89396910550078,0.0007342273557326
0.0010929616782864996,62.8521211497185,0.0024874784133196,12.67098762378325,62.90136313226693,0.0007831510251404
0.0011425690598803996,65.8763527411209,0.0026449818498803,13.280672712609974,65.9312320347702,0.0008327183433915
0.0011923066930244995,68.9279641781177,0.0028028988351128,13.89587757830853,68.98881397670088,0.0008824133415192
0.0012453871968175995,72.0291603114325,0.0029714294346559,14.521078718784793,72.09657119870903,0.0009354456207909
0.0012979977382715996,75.1631293978154,0.0031384679037723,15.152886886599584,75.23742768731529,0.0009880055896564
0.0013488137167020995,78.3417864949912,0.0032998086352892,15.793704157390223,78.42320788194557,0.0010387700978707
0.0014029216907977995,81.4951298597403,0.003471601453043,16.429418179723648,81.58423808375196,0.0010928204346573
0.0014559528207041996,84.6698054670123,0.0036399752904958,17.06943278214968,84.7668750732331,0.0011457922396854
0.0015073556478448996,87.8347776591011,0.0038031792666675,17.707491176074786,87.9399907001359,0.0011971348855383
0.0015624614900202995,91.0082940648711,0.0039781403155744,18.34727208347801,91.122323596736,0.0012521732834184
0.0016131418573853997,94.1827452479552,0.0041390504819586,18.987241441987766,94.30552544862,0.0013027889489025
0.0016666599228084996,97.3407162984715,0.004308970339677,19.62388840577185,97.47282283685672,0.0013562359086645
0.0017213647389583996,100.48244773515,0.0044826581309529,20.25726146340624,100.6243149670738,0.001410865090266
0.0017741769543790995,103.654664901123,0.0046503369149136,20.8967804440664,103.8064850946955,0.0014636014567267
0.0018276112032678995,106.835795792529,0.0048199906551356,21.538096431773848,106.9979839932704,0.0015169561329886
0.0018832392449243996,109.987948508303,0.004996609687395,22.173570419273887,110.16104042925208,0.0015724983108228
0.0019369886708250996,113.149356122243,0.0051672641146297,22.81091019424419,113.33350497499386,0.0016261618423487
0.0019925000853992995,116.324582920243,0.0053435128559028,23.45103591672099,116.52035674836642,0.0016815815240372
0.0020489369814665997,119.509108103231,0.0055227000009164,24.09303619361137,119.71698619816998,0.001737922009457
0.0020989046591443996,122.680565938177,0.0056813473775435,24.73240209313649,122.90009063473398,0.0017878016786134
0.0021530453313361995,125.844052635593,0.0058532440117524,25.37016101133555,126.07605135921632,0.0018418441841697
0.0022079386359411994,129.012980803002,0.0060275302538733,26.009016929885203,129.25790352581538,0.0018966349758706
0.0022647459483565997,132.159754344127,0.0062078934707922,26.643406475776004,132.41815865155834,0.0019533330402946
0.0023209867168415997,135.325343919693,0.0063864579107321,27.28158933421011,135.59754852227522,0.0020094624837653
0.0023746629169802995,138.487665025126,0.0065568798461724,27.9191132690654,138.77366407386512,0.0020630294971535
0.0024261342093980995,141.649759828675,0.006720301199599,28.55659158146088,141.94958000218668,0.0021143933930873
0.0024817562249939995,144.791759050131,0.0068969010991159,29.190018624506408,145.10628328387452,0.0021698963857872
0.0025404881699338995,147.898108245559,0.0070833750243001,29.81625862230469,148.22806659708274,0.0022284993094756
0.0025970651748485995,150.965889474483,0.0072630070149043,30.434723318055774,151.31123319551116,0.0022849487796548
0.0026481455802559997,154.031379077303,0.0074251873020728,31.052726021984288,154.39160327889215,0.0023359113035844
0.0026997770481532995,157.051887243739,0.0075891172126467,31.661660468337782,157.42728415106504,0.0023874209790596
0.0027532531165701995,160.062503562617,0.0077589037298704,32.26860071822359,160.45365617864985,0.0024407681068851
0.0028042118397871994,163.051852127593,0.0079206976760843,32.87125338892275,163.45861887601137,0.0024916013113127
0.0028607204754699995,166.005014954975,0.0081001125943772,33.46661101492296,166.42852969902748,0.0025479677366472
0.0029098217533078995,168.979534434934,0.0082560091515126,34.0662741420827,169.41893493342633,0.002596942865963
0.0029601114534911995,171.947199738581,0.0084156789495945,34.66455546729793,172.40296428323666,0.002647100878167
0.0030118235604045997,174.876553278744,0.0085798648890446,35.255113140994794,175.34912562500966,0.0026986749489689
0.0030681158754589997,177.764195099193,0.0087585929893423,35.83726173199731,178.2545775347684,0.002754813978338
0.0031218630104664995,180.656817975281,0.0089292401429911,36.42041450381665,181.1648898213188,0.0028084118173532
0.0031796444941703996,183.524251378274,0.009112696353751,36.99848907786004,184.05099178027703,0.0028660295945727
0.0032312784884407997,186.376346935153,0.0092766342855595,37.573471542126846,186.92089660759268,0.0029175144907789
0.0032834423039807994,189.167066665963,0.009442254399899,38.13608063985814,189.72963786833867,0.0029695249868526
0.0033375993605944997,191.93280380166,0.0096142030546475,38.693653246414655,192.51399465161177,0.0030235200035205
0.0033937348616248997,194.722755112761,0.009792433270419,39.25610743073262,195.3233250610048,0.0030794844680287
0.0034439501997197996,197.525626995991,0.0099518669688703,39.82116640239178,198.1447604645916,0.0031295441536204
0.0034970656751437995,200.269440493639,0.0101205086033416,40.37431920351762,200.90781170482083,0.0031824922598797
0.0035495986796762998,202.978882234814,0.0102873008927322,40.9205426585385,203.63655304943447,0.0032348569732282
0.0036043069511744997,205.695217299908,0.010460999654739,41.468155807661454,206.37294252735865,0.0032893870704335
0.0036594748179559996,208.387168392179,0.0106361576317703,42.010853147863294,209.0852593438192,0.0033443722551673
0.0037117947133026995,211.017707666568,0.0108022732994961,42.54116986558011,211.7356512726301,0.0033965161060621
0.0037651391107189998,213.579703757721,0.0109716417612928,43.05766827755656,214.3177573001188,0.0034496782125945
0.0038209273697185995,216.006603398959,0.0111487694836165,43.54693124523013,216.76509405352084,0.0035052728062109
0.0038774664674867997,218.346672622901,0.0113282811190306,44.01868920077685,219.12572537530323,0.0035616124788488
0.003930676038344599,220.629861636622,0.0114972215065041,44.478980105943,221.42880034219223,0.0036146314693872
0.0039872829370842,222.823187737303,0.0116769484100023,44.92115464784029,223.6426821838418,0.0036710325338345
0.0040447927189855,224.934371681892,0.0118595419675389,45.346769331069424,225.77456652312145,0.0037283299409687
0.004105126918051399,226.93727874275,0.0120511030495732,45.75055539453841,227.7986470992598,0.0037884378065352
0.0041663916554758994,228.868458346785,0.012245618590896,46.13988120271186,229.7511782990373,0.0038494690229588
0.0042340098994852,230.764191836328,0.0124603065156255,46.52206107420372,231.66982728927644,0.0039168252045092
0.0042994675330879,232.638748490353,0.0126681345023141,46.89997169565517,233.56696863407765,0.0039820248279158
0.0043777767462239,234.379718110044,0.0129167662540209,47.25095117098487,235.3332387505198,0.0040600197901673
0.0044592257938189,236.072852999286,0.013175366980135,47.59228716465606,237.0524896834791,0.0041411355334322
0.004548316183643399,237.669561731691,0.0134582289678278,47.914183645108906,238.67699838695663,0.0042298538151469
0.004643205348891,239.227633653978,0.0137595020674889,48.22829094464197,240.2643747940921,0.0043243379969927
0.0047478145337443,240.68947348489,0.0140916362293981,48.52299785455382,241.75772813200635,0.0044284903690088
0.0048629874005695,242.040323507661,0.0144573100815681,48.79532921914445,243.1424501247297,0.0045431477481866
0.004996977576322399,243.245961282141,0.0148827288895836,49.03838579447963,244.3861703200145,0.0046765216727766
0.0051360841253410994,244.34171461216,0.015324392182718,49.25928966581146,245.5210494976133,0.0048149696213962
0.005286065039449299,245.260288556672,0.0158005815850115,49.44447417302507,246.48084137522417,0.0049642189795062
0.0054496687110634,246.062019471013,0.0163200232423863,49.60610312535622,247.32681880229973,0.005126999249791
0.0056249968910196,246.760644535973,0.0168766902137472,49.74694593845216,248.07229900991888,0.0053014156112979
0.0058079235857184,247.305060535194,0.0174574824694159,49.85670020389511,248.66484754586835,0.0054833585489831
0.0059945331325061,247.814930609749,0.0180499677804669,49.9594900109254,249.22376573196152,0.0056689304294852
0.0061845396905093,248.174628350616,0.018653238602127,50.032005075484186,249.6326631719131,0.0058578450553758
0.006381239336130799,248.498957909288,0.0192777599769753,50.09738991451246,250.0077778353049,0.0060533767156198
0.006584573199388299,248.756140580922,0.0199233449928178,50.149237941113874,250.31710259915053,0.0062554630195044
0.006788568599182599,249.01442094766,0.0205710303871647,50.20130726304826,250.6278014894416,0.0064581657709723
0.006994780456016999,249.209270025962,0.021225753032614,50.24058883723394,250.8753029138389,0.0066630291825994
0.007201564513000899,249.410680943732,0.0218822924135378,50.28119327825637,251.12963447175417,0.0068684189174716
0.0074100122171285,249.552820791282,0.022544113874143,50.30984867152245,251.32477266830003,0.0070754183951159
0.0076172870401277,249.722134837203,0.0232022114371654,50.34398238318012,251.5470500413079,0.0072812106613727
0.0078256241367788,249.873453370528,0.0238636817190327,50.37448819949845,251.75153228746345,0.0074880149354799
0.0080325683834048,250.086857451889,0.0245207297020702,50.417510462300825,252.01829437586315,0.0076933942759816
0.0082411087107727,250.223156448117,0.0251828452414633,50.4449883399404,252.2078276369874,0.0079003149666048
0.008448230114678,250.381985373259,0.0258404556988626,50.47700825124902,252.4197757987176,0.0081057853824416
0.0086569940658798,250.519221639877,0.0265032812439284,50.504675082599206,252.61042837629645,0.0083128425398415
0.0088675450885919,250.626210392201,0.0271717807410393,50.526244015067725,252.77107982109376,0.0085216287424732
0.0090806036885832,250.782979326413,0.0278482417960116,50.55784863220486,252.9826218607772,0.00873285713992
0.0092866896681171,250.912888773666,0.0285025647810318,50.58403837677107,253.16538038521475,0.0089371303703598
0.0094928173113748,251.028165710221,0.029157020048375,50.60727820718056,253.33343602843195,0.0091414031663643
0.0096934412631082,251.125199862053,0.0297940010951285,50.62684029218988,253.481743005267,0.0093401817330125
0.0098966958709415,251.227552944455,0.0304393344749992,50.647474673602126,253.6361197203328,0.0095415264729831
0.0100980538920111,251.355953433717,0.0310786461918952,50.67336021223735,253.81636374710047,0.0097409524812833
0.0102936598527065,251.492476538553,0.0316996951171031,50.70088327017229,254.0034166426529,0.0099346435443751