File: example/data/02 processed data/test_ID_105.csv
Strain,Stress_MPa,Displacement(mm),Force(kN),True Stress (MPa),True Strain
6.9898604961711e-05,-0.95019901399983,0.00022192807075343242,-0.1915601212223657,-0.9502654315853445,6.989616216799246e-05
4.39735742765101e-05,0.160189718536313,0.00013961609832791958,0.032294247256920705,0.1601967626507994,4.397260746727096e-05
3.00877677829986e-05,1.85475254437518,9.552866271102055e-05,0.3739181129460363,1.8548083497390302,3.008731515520974e-05
2.34840793195009e-05,3.7196679698099,7.456195183941534e-05,0.7498850627136758,3.7197553227875453,2.3483803572728797e-05
1.73516771604466e-05,6.72291449481892,5.509157498441795e-05,1.3553395621554944,6.723031148660811,1.7351526621828875e-05
1.57463658487315e-05,10.5144867931648,4.9994711569722506e-05,2.1197205375020234,10.514652358120557,1.5746241876061553e-05
1.40586536656481e-05,15.0915572968642,4.4636225388432714e-05,3.042457951047823,15.091769463841512,1.405855484371537e-05
4.05350400928216e-05,20.0481277510216,0.00012869875229470858,4.041702554605955,20.048940402683773,4.05342185701777e-05
8.10135519728258e-05,25.3177392564207,0.0002572180275137219,5.104056234094413,25.319790336405788,8.10102705522985e-05
0.0001339743319084,30.5775626956137,0.00042536850380916997,6.164436639435722,30.581659304147234,0.0001339653581491145
0.0001859990443186,36.0190590773675,0.0005905469657115551,7.261442309997289,36.02575858793315,0.00018598174864108366
0.000249459631417,41.6099035002773,0.000792034329748975,8.388556545655904,41.62028349146778,0.00024942852153690464
0.0003255500067161,47.2132491426416,0.0010336212713236174,9.518191027156547,47.22861941621708,0.0003254970268107373
0.0004064323989221,52.8276096922881,0.0012904228665776675,10.650046113965281,52.84908054442466,0.00040634982764701957
0.0004866780804578,58.4942477553271,0.0015452029054535148,11.792440347473944,58.52271562354249,0.00048655969109088646
0.0005872596311434,64.1732978839,0.001864549328880295,12.93733685339424,64.21098427114455,0.0005870872616866287
0.0006781044353781,69.7822780089376,0.0021529815823254674,14.06810724660182,69.82959768116625,0.0006778746264492074
0.000781979201094,75.3837626477879,0.00248278396347345,15.197366549794042,75.44271118227867,0.0007816736146562177
0.0008916797178029,80.9882951778992,0.002831083104024207,16.32724030786448,81.06051079808877,0.0008912824076080896
0.0009980982540996,86.6119467292296,0.00316896195676623,17.460968460612687,86.69839396204421,0.0009976004852244552
0.0011050957404531,92.2367758888242,0.0035086789759385924,18.594934019186958,92.33870635697205,0.0011044855716438435
0.0012018437612116,97.7677210886328,0.00381585394184683,19.709972571468374,97.88522261427104,0.0012011221251363976
0.0012944026301255,103.209843497167,0.0041097283506484625,20.807104449028866,103.34343859004458,0.0012935656132545214
0.0013762893472033,108.644197190295,0.004369718677370477,21.902670153563474,108.79372304152346,0.0013753431291001707
0.0014740305683967,113.964374112275,0.004680047054659522,22.97521782103464,114.13236108342468,0.001472945251734114
0.0015816662702598,119.213174170213,0.005021790408074865,24.03337591271494,119.40172962676864,0.0015804167535367914
0.0016778805163535,124.354069662471,0.005327270639422362,25.069780443954155,124.56272093308694,0.0016764744474306711
0.0017753361455472,129.369846197801,0.005636692262112359,26.080960993476683,129.59952116189984,0.0017737620990315069
0.0018900313668732,134.337541640328,0.00600084958982241,27.08244839469012,134.59144380777687,0.001888247504939063
0.0019996901641733,139.210519854505,0.006349016271250228,28.06484080266821,139.4888977618075,0.0019976934452332613
0.0021320770427223,143.995903068986,0.0067693446106433025,29.029574058707578,144.30291342816543,0.0021298073919385294
0.0022459730388955,148.699228621858,0.0071309643984932124,29.977764490166575,149.03320308024726,0.0022434546116246908
0.0023528988090557,153.246245264816,0.007470453718751847,30.894443045386907,153.60681817279186,0.0023501350769918957
0.0024710585388457,157.666971238921,0.007845610860835097,31.785661401766475,158.05657555449488,0.002468010493926783
0.0025910786712929,161.953463661249,0.008226674781354956,32.6498182741078,162.37309782668368,0.002587727614272495
0.0027168075951235,166.045117536364,0.008625864114517112,33.47469569533098,166.49623017281996,0.002713123744070417
0.0028549297628595,169.937912367205,0.009064401997078912,34.25948313322853,170.42307317106034,0.002850862190800049
0.0030042284758643,173.578874308629,0.009538425410869153,34.99350106061961,174.10034490563544,0.0029997247992909967
0.0031779108027029,176.846277907375,0.010089866798581707,35.652209626126805,177.40827960435462,0.0031728719167655214
0.0033810103893925,179.696612876479,0.010734707986321186,36.226837155898174,180.30416899155304,0.003375307624223007
0.0036114038557646,182.061400498728,0.011466207242052604,36.703578340543565,182.718897742475,0.00360489839472006
0.0038742600646925,183.921940102922,0.012300775705398687,37.07866312474908,184.63450153048353,0.0038667744470917914
0.0041606183435959,185.29958447191,0.01320996324091698,37.35639622953706,186.07054532212453,0.004151986904229375
0.0044778063101796,186.218547675202,0.01421703503482023,37.54165921132072,187.0523982630545,0.004467810763145061
0.0048209477667918,186.73815658835,0.015306509159563964,37.64641236821136,187.63841148732942,0.004809364212329064
0.0051818278540981,186.989090366761,0.01645230343676147,37.69700061793902,187.95803564363592,0.005168448384312365
0.0055413171882388,187.063802254395,0.017593682072658188,37.71206253448603,188.10038211712458,0.005526020573061887
0.0059116971115793,187.036836061032,0.018769638329264277,37.706626149904054,188.14254118453294,0.00589429159395421
0.0062884622416159,186.960754805264,0.01996586761713048,37.691288168741224,188.13645045252093,0.006268772365847897
0.0066672499154901,186.869993826443,0.021168518481681064,37.67299075541091,188.11590277698997,0.006645122104749137
0.0070506150715844,186.771653797759,0.02238570285228047,37.653165405628215,188.0885088349702,0.007025875702252936
0.0074364004562317,186.686592660747,0.023610571448535646,37.636017080406596,188.07486892358173,0.00740888674813199
0.0078213222723642,186.597888746736,0.02483269821475633,37.61813437134198,188.05733096996698,0.007790894286395898
0.0082112283542763,186.487954745261,0.026070650024827252,37.595971676644616,188.01924992699628,0.00817769963500237
0.0085926386423667,186.416162124945,0.027281627689514268,37.581498284388914,188.0179688431815,0.008555932044091686
0.0089849421968942,186.321740647891,0.02852719147513908,37.56246291461483,187.995830717637,0.008944817768434784
0.0093706072096731,186.251349487252,0.029751677890712088,37.54827205663001,187.9966377255686,0.009326975428997616
0.00975369449204,186.140595314817,0.030967980012226996,37.52594401546711,187.9561538140842,0.009706434273250785
0.0101417464150562,186.073511065449,0.03220004486780343,37.51241983079452,187.96062142923392,0.010090663991216765
0.0105302429002818,186.014227010844,0.03343352120839471,37.50046816538615,187.97300200417635,0.010475186063148016
0.0109192867905758,186.002867457768,0.034668735560078164,37.49817807948603,188.03388611140883,0.010860101827190797
0.0113137744659258,185.919199000369,0.035921233929314414,37.48131051847439,188.02264688674472,0.011250252386898061
0.0117029934388893,185.88758898968,0.03715700416847353,37.47493794031949,188.06303022399717,0.011635043046017564
0.0121128493812724,185.849726138001,0.038458296785539865,37.467304789421,188.1008958782613,0.01204007589467347
0.0125148900653221,185.864551755145,0.03973477595739766,37.47029363383723,188.190626187401,0.012437226127776592
0.012909279486901,185.831459105414,0.04098696237091067,37.463622155651464,188.2304093484644,0.012826664974702855
0.0133087319875302,185.79820922,0.04225522406040839,37.456918978752,188.27094779027203,0.013220948811429243
0.0136891840502235,185.729462879923,0.04346315935945961,37.44305971659248,188.27194768083544,0.013596333575420106
0.0140936492385303,185.719151666759,0.0447473363323337,37.440980976018615,188.33661224722772,0.013995257155431618
0.014496916109678,185.695323630182,0.046027708648227646,37.43617724384469,188.38733315880825,0.01439284046607908
0.0148886151537582,185.635830255575,0.047271353113182285,37.42418337952392,188.39969069099863,0.014778867707241579
0.0152955912097886,185.564255413122,0.048563502091078806,37.4097538912854,188.4025704070699,0.015179792963389447
0.0157004334663221,185.51124544888,0.04984887625557266,37.399067082494206,188.42385241530468,0.015578456729321665
0.0160977865577562,185.40251175496,0.05111047232087594,37.37714636979994,188.38708181646322,0.01596959113684701
0.0165187912771772,185.334772061564,0.052447162305037605,37.36349004761131,188.39627847765217,0.016383840169381957
0.0169195324818415,185.220880988938,0.053719515629846754,37.3405296073699,188.35473170114562,0.016777991499343677
0.017311279926468,185.128278822166,0.05496331376653589,37.321861010548666,188.33308627916176,0.017163146858391338
0.0177049851407398,185.037028270072,0.05621332782184887,37.303464899246514,188.31310610608028,0.017550077642131987
0.0180938572407023,184.991677584556,0.0574479967392298,37.29432220104649,188.33889058948898,0.0179321115608047
0.0184907336693045,184.908807098244,0.05870807940004178,37.27761551100599,188.32790660340646,0.018321858625962202
0.0188925327105246,184.867742792749,0.059983791355915604,37.2693369470182,188.36036267058188,0.018716285195630844
0.0192965638657718,184.793431791664,0.061266590273825465,37.25435584919946,188.359310050207,0.019112746114019603
0.0196915488362692,184.757286143733,0.0625206675551547,37.24706888657658,188.3954432666889,0.01950017846144481
0.0200968336633745,184.697378929966,0.06380744688121404,37.23499159228115,188.40921143238276,0.01989755775423379
0.0205004033939485,184.67182394296,0.06508878077578648,37.22983970690074,188.4576708292869,0.02029309855817762
0.020905387514436,184.598854181576,0.0663746053583343,37.21512900300572,188.45796476296272,0.020689868399435235
0.0213070355653567,184.528118197931,0.06764983792000752,37.20086862870289,188.45986537518266,0.02108321441139758
0.0216975501543512,184.479619125644,0.06888972174006507,37.191091215729834,188.4823749140783,0.021465508799261793
0.0220939725651512,184.427407776897,0.07014836289435505,37.180565407822435,188.50214186458174,0.021853437226760003
0.0225015469113269,184.370283844137,0.0714424114434629,37.16904922297802,188.5189004351105,0.022252121805388814
0.022915355198865,184.329825765971,0.07275625275639637,37.16089287441976,188.55380919714312,0.02265674180511281
0.0233272533940746,184.279209376675,0.07406402952618685,37.15068861033768,188.57793718906444,0.02305933160462467
0.0237360175489989,184.23160988259,0.0753618557180715,37.14109255233014,188.60453460784348,0.02345869802007387
0.0241438119013306,184.160985752157,0.07665660278672466,37.12685472763485,188.6073339517207,0.023856958066251727
0.024565751291115,184.093178943611,0.07799626034929012,37.11318487503198,188.6155661919305,0.024268865545311574
0.024977944416074,184.02439601724,0.07930497352103495,37.099318237075586,188.62094715216023,0.024671094716009107
0.0253851983899159,183.968295179688,0.08059800488798298,37.088008308225106,188.63836685027897,0.02506834530122993
0.0257977177810718,183.880636415767,0.08190775395490296,37.07033630141863,188.6243371794248,0.025470571151947962
0.0262051129640847,183.789057038109,0.08320123366096892,37.051873898882775,188.60527003935528,0.025867641937876416
0.0266165905910658,183.715134792582,0.0845076751266339,37.036971174184536,188.60500532073863,0.026268531729502456
0.0270276369059487,183.640679363433,0.08581274717638711,37.02196095966809,188.60405296642963,0.026668840911461454
0.0274340793484853,183.574893838914,0.08710320193144082,37.00869859792506,188.61110204288053,0.027064508978306725
0.0278486538672248,183.494062841169,0.08841947602843873,36.99240306877967,188.60412548392355,0.027467932329909198
0.0282584924376979,183.398310531611,0.08972071348969082,36.97309940317278,188.5808703028551,0.02786658721191503
0.0286665577821259,183.333954128007,0.09101632095824973,36.96012515220622,188.58950751744314,0.028263359422684556
0.0290797880595241,183.253119763227,0.09232832708898901,36.94382894426656,188.58208164718823,0.028664993262334584
0.0294923812030467,183.161029546814,0.09363831031967326,36.92526355663771,188.56288445175116,0.02906584697561018
0.0299121053898785,183.090695432442,0.09497093461286422,36.91108419918031,188.56732361012337,0.02947346402740913
0.0303373411214585,183.021059889139,0.09632105806063074,36.897045673650425,188.57343221540668,0.029886264271902323
0.0307586923343995,182.962601756842,0.0976588481617184,36.88526051417934,188.59029213298194,0.03029512558837787
0.0311908232870517,182.918523262653,0.09903086393638914,36.87637428975084,188.62390259766687,0.030714273541036258
0.0316178724827056,182.833226272117,0.10038674513259029,36.85917841645879,188.61402390599048,0.031128319887292814
0.0320492205716993,182.767008687787,0.10175627531514528,36.84582895145786,188.62454886245158,0.03154636027445337
0.0324831400168974,182.684200676881,0.10313396955364924,36.82913485645921,188.61835714634313,0.03196671643827135
0.0328974990205395,182.584524209339,0.1044495593902129,36.80904008060275,188.59109841568142,0.03236795870942416
0.0333210350803962,182.464425194887,0.10579428638025794,36.78482811928922,188.5443287077302,0.032777921217066686
0.0337462180494849,182.364710207825,0.10714424230711454,36.76472557789752,188.5188294830294,0.03318930887215276
0.0341729538699222,182.2895188158,0.10849912853700298,36.74956699326528,188.51889013326266,0.033602028897470416
0.0345879390988091,182.21867291217,0.10981670663871888,36.73528445909347,188.52124127352195,0.034003220969365665
0.0350025221494182,182.141313230423,0.11113300782440279,36.71968874725328,188.516718581095,0.034403863573704445
0.0354100793155794,182.040345062086,0.11242700182696459,36.699333564516536,188.4864081193699,0.03479756014523521
0.035845072034293,181.98713009538,0.11380810370888027,36.68860542722861,188.51047188296317,0.03521758828597439
0.036278842218795,181.95259827196,0.11518532404467412,36.68164381162714,188.55362787596823,0.03563626034304042
0.0367171157078929,181.894941461674,0.11657684237255994,36.67002019867348,188.5735990740027,0.03605910100893962
0.037141616582349,181.804516026376,0.11792463264895806,36.6517904309174,188.55702965356718,0.03646848364795474
0.0375765598192421,181.712453938396,0.11930557742609366,36.63323071398064,188.54058283371342,0.03688776299703645
0.0380150941162759,181.625368488637,0.12069792381917598,36.61567428730922,188.52987396563583,0.03731032617580771
0.0384628022480449,181.575766092279,0.12211939713754255,36.605674444203444,188.55967887652358,0.03774154496170529
0.0388991041050644,181.495713395051,0.12350465553357946,36.589535820442286,188.55573404502803,0.03816159874443851
0.0393335951278477,181.402257644735,0.12488416453091643,36.570695141178575,188.5374606022105,0.038579733854403976
0.0397557224305229,181.298260289095,0.1262244187169102,36.54972927428155,188.50590360228495,0.03898580328577541
0.0401903117678363,181.198071710091,0.12760423986288025,36.529531256754346,188.48047870385034,0.039403688496730156
0.0406233647226129,181.122864481727,0.12897918299429595,36.51436947951616,188.48068466517256,0.039819922747707494
0.0410580138793611,181.007970934967,0.1303591940669715,36.49120694048935,188.43979871788986,0.04023751707076998
0.0414881914587492,180.903034998298,0.1317250078815287,36.470051855656884,188.40837474977621,0.040650643640930975
0.0419264666770905,180.805809941368,0.1331165316997623,36.45045128417979,188.38635870689913,0.04107137143325467
0.042363328847164,180.73252955896,0.13450356908974567,36.43567795908634,188.38896114204604,0.04149056666935769
0.0428062285442041,180.677029036287,0.135909775627848,36.42448905371546,188.4111312339021,0.04191537596328839
0.0432490555510944,180.609371794962,0.1373157513747247,36.410849353864336,188.42055654877058,0.042339935194214105
0.0436980927860982,180.531360342314,0.13874144459586177,36.395122245010505,188.42023647735297,0.042770264483857075
0.0441490771975526,180.47748627456,0.1401733201022295,36.384261232951296,188.44540074851577,0.043202273516847696
0.044603229908788,180.415371156055,0.1416152549604019,36.37173882506068,188.46247943480782,0.04363712902063044
0.0450589627973731,180.349070008048,0.14306220688165958,36.35837251362248,188.47541204408148,0.04407330755455931
0.0455097937570972,180.241688895419,0.1444935951787836,36.33672448131647,188.4444509834804,0.04450460737696326
0.0459647562190449,180.162523162096,0.14593810099546756,36.32076466947856,188.44364961904975,0.04493967121183434
0.0464397295021201,180.067141226343,0.14744614116923133,36.30153567123075,188.42941055711444,0.04539366879640733
0.046898278341974,179.980862221644,0.14890203373576744,36.28414182388343,188.42165479434314,0.04583177181223168
0.0473558557569495,179.857273187235,0.15035484202831464,36.25922627454658,188.37456827312798,0.046268755476063676
0.0478139526414422,179.743762573408,0.15180929963657896,36.23634253479905,188.33802232468756,0.04670604403373216
0.0482675261843107,179.662117784346,0.15324939563518644,36.21988294532416,188.33396375883063,0.04713882639885471
0.0487288090491167,179.577896311653,0.1547139687309455,36.20290389642925,188.32851333046563,0.04757877268249467
0.0491890979408361,179.448661146887,0.1561753859621546,36.17685008721242,188.2755789153931,0.04801757812628392
0.0496346472695632,179.338240439757,0.15759000508086315,36.15458927265501,188.23963074592845,0.04844214863768285
0.0500873639368465,179.216370059018,0.15902738049948761,36.13002020389803,188.19284560960457,0.04887336445756959
0.0505457755378417,179.121823631149,0.1604828373326474,36.11095964403964,188.17567512233794,0.04930981535388066
0.0510091050619549,179.030204300162,0.1619539085717068,36.092489186912665,188.16237480057225,0.04975075509416285
0.051465997134044,178.903068392855,0.16340454090058967,36.06685858799957,188.11049319803337,0.05018537815229469
0.0519196482263018,178.765277560982,0.1648448831185082,36.039079956293975,188.0467078870254,0.050616731385395276
0.0523750306542853,178.638711439701,0.16629072232735584,36.01356422624372,187.9949194273974,0.05104954380436182
0.0528349918450156,178.527755148528,0.16775109910792452,35.99119543794325,187.9602676359094,0.05148651797143617
0.0532992162550337,178.46010220863,0.169225011609732,35.97755660525981,187.97188578914316,0.051927348774858446
0.0537639966578659,178.379834456164,0.17070068938872424,35.96137462636266,187.97024727969585,0.05236851295780463
0.0542328997496007,178.310875912357,0.17218945670498223,35.94747258393117,187.98119176997534,0.052813393213812315
0.0547076834743999,178.242045847501,0.17369689503121968,35.9335964428562,187.99325527355555,0.05326365125957906
0.0551882017756158,178.184887406664,0.17522254063758017,35.92207330118346,188.01859092622834,0.053719141327011326
0.0556709980085775,178.130978814722,0.17675541867723354,35.91120532904796,188.04770818158235,0.05417658182463414
0.056149823166635,178.060759421178,0.17827568855406611,35.89704909930949,188.0588395755939,0.05463005321904581
0.0566353522011612,177.974000251571,0.1798172432386868,35.879558450716715,188.05362043846827,0.055089663641093106
0.0571204490938536,177.894580782387,0.18135742587298517,35.86354748572922,188.05599912803976,0.0555486541270438
0.057604622000409,177.75812622827,0.18289467485129857,35.83603824761923,187.99781589715045,0.05600656037843652
0.0580879090060476,177.650265272937,0.18442911109420113,35.8142934790241,187.96959771701157,0.0564634197821181
0.0585764909293383,177.536171920473,0.1859803587006491,35.791292259167356,187.93561788460204,0.05692507249568287
0.0590487500952511,177.42341452356,0.18747978155242223,35.768560367949696,187.90004538880783,0.05737109964401204
0.0595408641019465,177.282564926032,0.18904224352368013,35.74016508908805,187.8381220319374,0.057835667215049485
0.0600351361855908,177.163334832046,0.19061155738925079,35.716128302140476,187.7993597657813,0.05830205491951172
0.0605140520135433,177.036690737332,0.19213211514299997,35.69059685264613,187.74989824891648,0.05875374530119213
0.0610029520720492,176.953269475046,0.1936843728287562,35.67377912616927,187.74794129182465,0.059214641976749346
0.0614966415338178,176.848223280076,0.1952518368698715,35.652601813263324,187.72379507302344,0.059679838269044605
0.0619875742628228,176.780106172712,0.19681054828446237,35.63886940441874,187.7382761322827,0.06014222243380525
0.0624902163551695,176.694577517309,0.19840643692766316,35.62162682748949,187.7362598951509,0.06061541363772863
0.0629829084226348,176.640030123188,0.1999707342418655,35.6106300728347,187.7653329642082,0.061079020606498335
0.0634799424084354,176.534101442952,0.20154881714678236,35.58927485089912,187.74047603567547,0.06154649549763772
0.0639881801748338,176.449873896709,0.20316247205509733,35.572294577576535,187.74058021943833,0.06202428199950998
0.0644921884104533,176.360662994285,0.20476269820318924,35.554309659647856,187.7345481003049,0.06249786705340867
0.0649999608466672,176.234886676212,0.20637487568816837,35.52895315392434,187.69014740998261,0.06297476239769494
0.0655034479834861,176.100056804889,0.20797344734756837,35.50177145186562,187.635217715697,0.06344740857521831
0.0660171162139706,175.953132690322,0.20960434397935665,35.47215155036892,187.56905109935119,0.06392938210065
0.0665167938362797,175.838024700511,0.21119082043018805,35.44894577962302,187.53420633809353,0.0643980054872217
0.0670203267223707,175.709748560635,0.21278953734352696,35.42308530982402,187.4858733174744,0.06487002248714928
0.0675325031986341,175.587996573853,0.21441569765566326,35.39854010928877,187.44589351411847,0.06534991361836247
0.0680355797395287,175.486431457671,0.21601296567300363,35.37806458186647,187.42575255831468,0.0658210543459466
0.0685422579179246,175.40730137625,0.21762166888941062,35.362111957452,187.43011386786807,0.06629534381854513
0.0690620025774532,175.292042240418,0.21927185818341388,35.33887571566827,187.39806171343275,0.06678163090112252
0.0695856453386252,175.210671486085,0.220934423950135,35.32247137159474,187.40281913165808,0.06727132612711877
0.0701016201069319,175.104541798718,0.22257264383950875,35.301075626621554,187.37965386689012,0.06775361602680725
0.0706079232083791,175.00139113145,0.2241801561866036,35.28028045210032,187.35787591781894,0.0682266396674676
0.0711156575565093,174.903041356087,0.225792212741917,35.26045313738714,187.34138615075844,0.06870077588392608
0.0716354179413549,174.79622682355,0.2274424519638018,35.238919327627684,187.3178275866269,0.06918590959916077
0.0721477001778608,174.700694998373,0.22906894806470804,35.219660111672,187.3049483619795,0.06966383317447666
0.0726613348344195,174.619741933541,0.2306997380992819,35.20333997380187,187.30784547087393,0.0701427892568065
0.0731730950014834,174.537220249457,0.2323245766297098,35.186703602290535,187.30864884806536,0.07061976937200187
0.0737106105153884,174.438317781005,0.23403118838635814,35.16676486465061,187.29627268192021,0.07112050960656145
0.0742503532294162,174.358338272475,0.23574487150339643,35.15064099573097,187.3045064777003,0.07162307248782247
0.0747935211647072,174.272681943632,0.23746942969794532,35.133372679836214,187.30714946901332,0.07212856979602472
0.0753325639626644,174.146774923398,0.23918089058145944,35.10798982455704,187.26569798420658,0.07262997556285758
0.0758815754399921,174.034655555374,0.24092400202197492,35.0853865599634,187.24067940007217,0.07314039568253919
0.07642533648913,173.924898589033,0.24265044335298772,35.06325955554905,187.21716748753767,0.07364567776632851
0.076968154833689,173.810761771213,0.24437389159696257,35.040249573076544,187.18865539498114,0.07414982933755172
0.0775100687103755,173.698987371188,0.2460944681554422,35.0177158540315,187.16240781725145,0.07465288746289553
0.0780611050353914,173.557422576849,0.2478440084873677,34.98917639149276,187.10550677029224,0.07516415458664487
0.078606760478675,173.441773074438,0.24957646451979312,34.9658614518067,187.07546898749706,0.07567017172878528
0.0791499653669222,173.332459364507,0.251301140039978,34.94382380788461,187.05171752017117,0.07617366212991883
0.0796947416362031,173.180186143585,0.2530308046949448,34.913125526546736,186.98173633480755,0.07667835455089499
0.0802389152461285,173.029683338448,0.25475855590645796,34.88278416103112,186.91339743490616,0.07718223449156361
0.0807777881851141,172.874721902888,0.25646947748773724,34.851543935622225,186.83915957132,0.07768095618057162
0.0813148143606826,172.711488581629,0.25817453559516723,34.8186360980564,186.75549121360132,0.07817772138478148
0.0818513758985719,172.612514052193,0.25987811847796577,34.79868283292211,186.7410858246766,0.07867381045210298
0.0823830054831931,172.491657358297,0.2615660424091381,34.77431812343268,186.70203851225065,0.07916509697807961
0.0829303739539659,172.358498196648,0.2633039373038417,34.747473236444236,186.65225290623997,0.07967067597429359
0.0834820162375808,172.266266242578,0.265055401554319,34.72887927450373,186.64740147822835,0.08017994401396604
0.0840353878515643,172.18814374223,0.26681235642871665,34.713129778433576,186.6580411850492,0.08069054810412207
0.084597664591772,172.121759819946,0.26859758507887604,34.699746779701115,186.68285872613933,0.08120910217870275
0.0851627891582955,172.067711101369,0.2703918555775882,34.688850558035995,186.72147730284541,0.0817300118287293
0.0857328688393766,171.969883345248,0.2722018585650207,34.669128482402,186.71335479840906,0.08225521412676232
0.0863135735862589,171.850921035228,0.27404559613637197,34.645145680701965,186.6839881538685,0.08278992162599018
0.0868869879834692,171.756348089948,0.2758661868475147,34.62607977493352,186.67973984252387,0.08331763583760757
0.0874570697910362,171.648745349114,0.2776761965865399,34.604387062381385,186.66064165065526,0.08384200714728257
0.0880349479197881,171.527071029671,0.2795109596453272,34.57985751958167,186.6274477946019,0.08437326916767988
0.0886151849082834,171.402405381926,0.2813532120837998,34.55472492499628,186.59126122856995,0.08490641594537131
0.0891933000745831,171.239059095851,0.28318872773680137,34.52179431372356,186.51243587827648,0.08543733056331447
0.0897717959667574,171.103899432352,0.28502545219445474,34.49454612556216,186.4642037813097,0.08596831282348676
0.0903478153114628,170.995727533791,0.28685431361389435,34.47273867081227,186.44481794406317,0.08649674195657585
0.0909194550344763,170.860140128017,0.2886692697344622,34.44540424980823,186.39465095557057,0.08702087739277073
0.0914951824518454,170.73628010371,0.2904972042846091,34.42043406890794,186.3578272029483,0.08754848330306415
0.0920737611677366,170.574325691737,0.2923341917075637,34.38778405945418,186.2797454168257,0.08807842189842882
0.0926485115809889,170.44338833794,0.29415902426963975,34.36138708892871,186.23471457627065,0.08860457612286354
0.0932341242522703,170.339599963987,0.2960183445009582,34.34046335273978,186.2210633921114,0.08914038959765119
0.0938170306396963,170.212675905986,0.29786907228103576,34.31487546264678,186.1815237367226,0.08967344196812249
0.094406965083796,170.073557431432,0.2997421141410523,34.28682917817669,186.12968582953818,0.09021263216030115
0.0950016104612766,169.959687785391,0.3016301132145532,34.26387305753482,186.1061318384989,0.09075583400827442
0.0955852213190651,169.807140062544,0.3034830776880317,34.23311943660887,186.03819312697973,0.09128866919483689
0.0961658645739567,169.697242824576,0.30532662002231253,34.210964153434524,186.01632489661802,0.09181851336574913
0.0967566087290863,169.566641336506,0.307202232714849,34.184634893439615,185.97333450580763,0.09235728678488396
0.0973417245219716,169.464265957145,0.3090599753572598,34.16399601696043,185.96020985026354,0.09289064100870205
0.0979338171138785,169.336977453897,0.3109398693365642,34.13833465470563,185.92079403448392,0.09343006541810711
0.0985220184221505,169.213181032712,0.3128074084903278,34.113377296194734,185.88440517168752,0.09396565672189418
0.0991170800582006,169.096777668978,0.31469672918478686,34.089910378065966,185.85715651877786,0.09450720301218776
0.0997298359578523,168.989906895687,0.316642229166181,34.0683652301705,185.84324258892659,0.09506454596412328
0.100344445537318,168.879283425412,0.3185936145809846,34.04606353856306,185.82538148347456,0.09562326309528878
0.100956735210593,168.754369309847,0.32053763429363274,34.020880852865155,185.7912594878918,0.0961795610652533
0.101573612472844,168.612914451604,0.32249621960127967,33.99236355344337,185.739537282028,0.09673971432627848
0.102186386146986,168.493140911792,0.3244417760166805,33.96821720781727,185.71084607212293,0.09729583086375841
0.102808362135205,168.319364519179,0.32641654977927587,33.93318388706649,185.62400270103433,0.09785998277858694
0.103417938466473,168.1596863998,0.32835195463105177,33.90099277819968,185.55041450043592,0.09841257917054701
0.104023563515162,168.012672809107,0.3302748141606393,33.87135483831597,185.48994975041728,0.09896129139086243
0.104644451145216,167.871979319547,0.3322461323860608,33.84299103082068,185.43885045810205,0.09952351952319194
0.105251201987784,167.738101771265,0.33417256631121417,33.81600131708703,185.3927386018399,0.1000726412493279
0.105864259582181,167.585948861417,0.33611902417342465,33.785327290461666,185.32731125400815,0.10062716462973167
0.106481618055858,167.444843949228,0.3380791373273491,33.75688054016436,185.27464186805244,0.10118526767857382
0.107100704884738,167.325795836212,0.3400447380090431,33.73288044058034,185.24650651567006,0.10174462057781365
0.10772606363979,167.152089442476,0.3420302520563332,33.69786123160316,185.15872606728007,0.1023093227753466
0.108355729703845,167.006846090356,0.34402944180970785,33.66858017181577,185.10299476401423,0.10287759248713338
0.108970653602572,166.866657221008,0.3459818251881661,33.64031809575521,185.0502259228576,0.10343224598255146
0.109596084328134,166.713728878261,0.3479675677418254,33.60948774185742,184.9849007670606,0.10399606110826941
0.110224160991276,166.561136723445,0.34996171114730124,33.578725163446514,184.92019827253992,0.10456194177471212
0.110847734649036,166.406509542591,0.3519415575106893,33.54755232378635,184.85229415624042,0.10512344874381824
0.111461286411815,166.259843320319,0.3538895843575126,33.51798441337631,184.79137933542856,0.1056756237766814
0.112052189006216,166.136485499692,0.3557657000947358,33.493115476737906,184.75244237373195,0.10620712728663932
0.112664751811036,165.993465888649,0.35771058700003927,33.46428272315164,184.6950785252473,0.10675781560933018
0.113299324261423,165.836042812491,0.359725354530018,33.432546230998184,184.62515440133467,0.10732797078335003
0.11394220888545,165.708225733144,0.3617665132113037,33.40677830780183,184.58938700366718,0.10790526303685155
0.114572827317406,165.562154718813,0.36376872673276406,33.3773303913127,184.53107888170922,0.10847121699143017
0.115206228405323,165.355505065354,0.3657797751869005,33.33566982117537,184.40548914999073,0.10903934602047302
0.115820429675766,165.192264236736,0.36772986422055703,33.30276047012598,184.32490325974743,0.10958994570401774
0.116464413394922,165.024665450419,0.36977451252887733,33.26897255480447,184.2441663077953,0.11016691843132909
0.11710388248733,164.890458738259,0.37180482689727273,33.24191648163302,184.19977164162603,0.11073951709424783
0.117736645732313,164.747408437259,0.3738138502000938,33.21307754095141,184.14421569975323,0.11130578860570615
0.118371119203647,164.570612120716,0.3758283034715792,33.17743540353634,184.0510196654744,0.11187326884821489
0.119017217473335,164.425161059615,0.37787966547783863,33.14811246961838,183.99458621153533,0.11245081569339697
0.119667840371628,164.331649551851,0.3799453931799189,33.12926054965316,183.99686315842823,0.11303207022433792
0.12035136751555,164.193624477476,0.3821155918618713,33.10143469465916,183.9545517206749,0.11364235710288817
0.12102520661206,164.050043844364,0.38425503099329045,33.072488839023784,183.90423429534567,0.11424362966421425
0.121692587714146,163.846329262342,0.3863739659924135,33.031419979288145,183.7852130577404,0.11483878356496233
0.122373319354851,163.621286481656,0.3885352889516519,32.98605135470185,183.64416642552726,0.11544547845698044
0.123029498052425,163.408509083012,0.3906186563164493,32.94315543113522,183.5125759329901,0.11602994259959754
0.123680398310569,163.18494894137,0.3926852646360565,32.8980857065802,183.3677284247285,0.11660936789826072
0.124323733236855,162.985775602944,0.3947278530270146,32.85793236155351,183.2487756904063,0.11718172889601924
0.12496490106466,162.78347224339,0.39676356088029546,32.81714800426742,183.1256927472471,0.11775183611604736
0.125625059999972,162.592319922421,0.3988595654999111,32.77861169636007,183.01798986820978,0.11833849025177731
0.126280607901816,162.433529894662,0.40094093008826576,32.74659962676386,182.94573479339772,0.11892070639848888
0.126918045646798,162.278044200539,0.40296479492858367,32.71525371082866,182.8740564218561,0.11948651337781027
0.127576922698587,162.120723214804,0.4050567295680137,32.68353780010449,182.80358618821808,0.12007101419045203
0.128230593131982,161.897918545506,0.40713213319404284,32.638620378774014,182.65818466742954,0.12065055871905526
0.12889264233524,161.658500911444,0.40923413941438697,32.59035378374711,182.49509224987384,0.12123718971185285
0.129547300943868,161.42576466616,0.4113126804967808,32.543434156697856,182.33803678146103,0.12181693382142023
0.130202757103471,161.215946955359,0.41339375380352045,32.50113490620037,182.20670773799364,0.12239704769343956
0.13085414189017,160.989292911686,0.4154619005012897,32.4554414509959,182.0554086891499,0.12297322497142812
0.13149955511914,160.792308774041,0.41751108750326943,32.41572944884667,181.93642584440678,0.12354379291341927
0.132153004065359,160.576080036063,0.4195857879075148,32.3721377352703,181.79669139386823,0.12412113324925689
0.132815706209164,160.407113315421,0.4216898672140957,32.338074044388875,181.711697351382,0.12470630880573112
0.133480316058344,160.219309615065,0.4238000034852422,32.30021281839711,181.60543370113353,0.12529282518461732
0.134149279130617,160.023910222995,0.42592396123970894,32.26082030095579,181.49100242307233,0.12588283608683737
0.134812261113824,159.810755265391,0.42802892903639117,32.21784826150283,181.35520453302632,0.12646722854154938
0.135478743291698,159.50405379253,0.4301450099511412,32.156017244574045,181.11346255027334,0.1270543622576472
0.136141781530228,159.190447723886,0.43225015635847386,32.09279426113542,180.86291887961045,0.12763812019618825
0.136805396370879,158.925073732964,0.4343571334775408,32.03929486456554,180.66688143827332,0.12822204477301885
0.137440813411808,158.692960324637,0.4363745825824904,31.99250080144682,180.50384987438287,0.12878083832380477
0.138094367354991,158.459679699134,0.4384496163520964,31.945471427345414,180.34206891846043,0.12935525612817658
0.138751828149941,158.207652037238,0.44053705437606266,31.894662650707183,180.1592529847145,0.1299327749913491
0.139421264539244,157.959277994513,0.4426625149120997,31.844590443693825,179.982160278214,0.13052047081720122
0.140081874834178,157.761657132906,0.44475995259851514,31.804750077993855,179.86120584103023,0.1311000798574498
0.140742880993186,157.534353895967,0.4468586471533655,31.758925745426946,179.70619271868551,0.13167970016876496
0.141402773298346,157.265046177593,0.44895380522224854,31.70463330940275,179.50275984999712,0.13225800885148245
0.142090813811228,156.993910368872,0.4511383338506489,31.649972330364598,179.30130285659203,0.13286062979825272
0.142761010994578,156.707962040609,0.4532662099077851,31.592325147386777,179.07974913242631,0.13344727370688148
0.143438742948163,156.442921031686,0.4554180088604175,31.538892879987902,178.88289696760978,0.13404016325843443
0.144106163933582,156.152152817577,0.45753707048912284,31.48027400802352,178.65464055008852,0.13462368929313615
0.144782002204584,155.85547112412,0.4596828569995542,31.42046297862259,178.4205382880088,0.1352142277918195
0.145463910132729,155.578388439579,0.46184791467141456,31.36460310941912,178.20942915414872,0.13580971663834243
0.146128330542016,155.269190818043,0.46395744947090073,31.30226886891747,177.95841845689336,0.1363895932988685
0.146793361990646,154.922166125611,0.466068924320301,31.23230869092318,177.66371173806283,0.13696966672173647
0.147466322180159,154.564660208933,0.4682055729220048,31.160235498120894,177.35774218897032,0.13755631365927043
0.1481490942308,154.211717751837,0.47037337418278996,31.08908229877034,177.05804405654743,0.13815116248794856
0.148815132248235,153.860782804534,0.4724880448881461,31.018333813394058,176.7575955454077,0.13873109144672272
0.149482445037943,153.451263501412,0.474606762995469,30.93577472188466,176.38953356376473,0.13931179328016274
0.150139730325902,153.02671583411,0.47669364378473883,30.850185912156576,176.00210568210173,0.13988343962528801
0.150801629857862,152.669714038229,0.4787951747987118,30.778214350106964,175.69255574512763,0.14045876897671902
0.151472134985086,152.311211704857,0.480924028577648,30.70594027969917,175.3821161239571,0.1410412411018156
0.152139168622684,151.965764895049,0.4830418603770217,30.636298202841882,175.08571002529203,0.1416203610733106
0.15278416377118,151.581380811214,0.4850897199734965,30.55880637154074,174.7406153217361,0.142180028422126
0.153454789622619,151.162620544731,0.4872189570518153,30.474384301817768,174.35924867922648,0.142761603778274
0.154120265237424,150.832802413983,0.4893318421288212,30.40789296665897,174.07919392853003,0.14333837863277074
0.154815063054707,150.470925748097,0.49153782519869466,30.334938630816357,173.76609160568876,0.14394021258605721
0.155528509264271,150.053072099979,0.4938030169140604,30.250699335355765,173.39060271421292,0.14455782309281512
0.156209023113683,149.583558185182,0.49596364838594353,30.15604533013269,172.94985968315805,0.14514656974725795
0.156889773278648,149.084563691586,0.4981250301597074,30.055448040223737,172.4744070885051,0.14573517425103522
0.15757270940187,148.621653353236,0.5002933523509372,29.96212531601238,172.04036994789092,0.14632532090336
0.158252391749134,148.154692955584,0.5024513438035004,29.86798609984574,171.60052746466377,0.14691231028044383
0.158929787714626,147.615914370706,0.5046020759939375,29.759368337134333,171.07648030494272,0.14749698246616347
0.15959658455497,147.087792450297,0.5067191559620298,29.652898957979875,170.5625017550947,0.148072172696219
0.160256459024823,146.550914016752,0.508814257403813,29.5446642657772,170.03664456392795,0.14864106604873195
0.160960553596293,146.05272709593,0.5110497576682302,29.44422978253949,169.56145490353921,0.14924772590796614
0.16165398179961,145.536116535137,0.5132513922137617,29.340081093483622,169.06260926869396,0.14984483594353354
0.162349738049042,144.941905654341,0.5154604183057083,29.220288179915148,168.47318606965223,0.15044359253266984
0.163031363772228,144.344433566949,0.5176245799768239,29.099837807096918,167.87710342429847,0.15102984116277562
0.163738893930918,143.741451786596,0.5198709882306647,28.978276680177757,167.27751811415763,0.1516380062174519
0.164395208805351,143.13763385395,0.5219547879569894,28.85654698495632,166.668775059274,0.15220181814825742
0.165058922088666,142.490606025378,0.5240620776315145,28.726106174716207,166.0099518636877,0.1527716626388381
0.16567320570508,141.760126405665,0.526012428113629,28.578841483382067,165.2459809884489,0.1532987790957763
0.166290637012367,141.022375489493,0.5279727725142651,28.43011089868179,164.47307614263798,0.15382831674160463
0.166883643799924,140.34551206135,0.5298555690647586,28.293655231568163,163.76688250511427,0.1543366429349825
0.167495823924583,139.648149868877,0.531799240960551,28.1530670135656,163.0386317907082,0.15486113361625936
0.168086612871659,138.949046355665,0.5336749958675173,28.012127745302063,162.30452091933583,0.15536703651257228
0.168692544754257,138.193710352237,0.5355988295947659,27.85985200701098,161.50595902058853,0.15588564084383824
0.169308553718616,137.44062858652,0.5375546580566057,27.708030723042434,160.71050263468118,0.15641259438463515
0.169944246608627,136.725502837847,0.5395729829823908,27.563861372109955,159.9612154098106,0.15695609520299064
0.170558833241615,135.971950815004,0.5415242955421276,27.411945284304807,159.16316809959733,0.15748127002750154
0.171187995402847,135.173524598424,0.5435218854040391,27.250982559042278,158.31360930596563,0.1580186143455761
0.17178484265999,134.324814990659,0.5454168754454682,27.07988270211686,157.39978219916162,0.1585280929535711
0.172351148475947,133.322761912169,0.5472148964111317,26.877868801493268,156.30109304571658,0.15901126101985696
0.172931618089646,132.487253689839,0.549057887434626,26.709430343871546,155.3984888466763,0.15950627137325846
0.17349424611025,131.624894945479,0.5508442314000437,26.53557882100857,154.46105686338575,0.15998583311008624
0.174039086732262,130.722946399009,0.5525741003749318,26.353745994040214,153.47384860524298,0.1604500144907486
0.174617010779112,129.803291809802,0.5544090092236805,26.168343628856082,152.46915461491844,0.16094214619034183
0.17519890778801,128.837467959029,0.5562565322269317,25.973633540540245,151.40965162762362,0.16143741649317253
0.175802123042022,127.81698084948,0.5581717406584198,25.767903339255167,150.28747744364006,0.16195057259930654
0.176435115367323,126.989350634244,0.5601814912912505,25.601053087863594,149.39473136381827,0.1624887771054206
0.177048033586504,125.90576589261,0.5621275066371502,25.382602403950177,148.1971341610993,0.1630096376293723
0.177617309226988,124.831368451217,0.563934956795687,25.16600387976535,147.00358022264487,0.16349316761660632
0.178216521921843,123.739496648064,0.5658374571018515,24.945882524249704,145.79191936504154,0.16400187302685584
0.178771597625843,122.578373433535,0.5675998224620514,24.71180008420066,144.49190508662525,0.16447287727983298
0.179280087111086,121.392215962427,0.5692142765776981,24.472670738025286,143.15542301477868,0.1649041566249092
0.17984664085982,120.238057918083,0.5710130847299284,24.239992476285533,141.86246873815873,0.1653844646583086