File: example/data/02 processed data/test_ID_113.csv
Strain,Stress_MPa,Displacement(mm),Force(kN),True Stress (MPa),True Strain
0.00022437398679619956,0.308467808712367,5.71271045260898e-05,0.0621871102364131,0.3084733589085091,1.799262695879819e-05
0.00022339664650799956,0.283354511695511,5.40240491110021e-05,0.057124269557815,0.283359333099623,1.7015303777723932e-05
0.00021547639187189958,0.256760170235535,2.887724064144607e-05,0.0517628503194838,0.2567625055190698,9.095152541882976e-06
0.00022015007961469956,0.232299466509413,4.371619922469173e-05,0.0468315724482976,0.2323026650132736,1.3768786855323156e-05
0.00022674998339459958,0.240841928723698,6.467089372597615e-05,0.0485537328306975,0.2408468343812656,2.036857798454676e-05
0.00023829883058379956,0.452840978615954,0.0001013384835514,0.0912927412889763,0.4528554322279423,3.19171232578777e-05
0.00024621922274549956,0.885924108714981,0.0001264857286649,0.1786023003169401,0.8859594021815739,3.983723126332744e-05
0.00024471556679809956,1.61579682707078,0.0001217116210319,0.3257446403374693,1.6158587676223015,3.833363408591207e-05
0.0002489303486577996,2.70752802820411,0.0001350935534365,0.5458376504859487,2.707643231222176,4.254824549914001e-05
0.00026898799747319957,4.11766562395879,0.0001987765884255,0.8301213897900921,4.117923417824935,6.260483978032785e-05
0.0002895883648140996,5.8409893111866,0.0002641827547329,1.1775434451352185,5.841475323358756,8.320370532077457e-05
0.0003183482101980996,7.78801280541072,0.000355495263827,1.5700633815708012,7.7888848059357425,0.0001119607443908
0.00033972187085639955,9.84328812034232,0.0004233566364171,1.984406885061012,9.844600631003711,0.00013333178381
0.0003676752893537996,11.9738495015366,0.0005121087401464,2.4139280595097787,11.975780812712328,0.0001612810848912
0.00039985075473109955,14.1282024338384,0.0006142658427193,2.848245610661821,14.130935810901118,0.0001934508439408
0.0004440108003845996,16.2868226040848,0.0007544739876692,3.283423436983496,16.29069283526482,0.0002376013729736
0.0004927912166819996,18.5194114012153,0.0009093518094134,3.7335133384850048,18.52471554618128,0.0002863690111933
0.0005297590415730995,20.7968622151297,0.0010267246534426,4.192647422570148,20.80358745958656,0.0003233255682586
0.0005638120055439995,23.1938593082775,0.0011348428140503,4.675882036548744,23.202149508140835,0.0003573669444011
0.0006003285873326995,25.6408913510415,0.0012507829612294,5.169203696369967,25.650992513250195,0.0003938698124641
0.0006503086721778995,28.1310299859375,0.0014094697306129,5.671215645165001,28.143518123026045,0.0004438289675596
0.0006930246847981996,30.6965734323395,0.0015450930706823,6.188429203959643,30.71151171986832,0.0004865251142894
0.0007361493146507995,33.238485267102,0.0016820137704643,6.700878629847763,33.2560939568433,0.0005296278390937
0.0007619789907653996,35.7355085400574,0.0017640229921282,7.2042785216755725,35.75536310972671,0.0005554435054877
0.0007926221652412996,38.190229405775,0.0018613150710892,7.699150248204241,38.21261808280219,0.0005860691951662
0.0008285761427113996,40.5783490674212,0.0019754689495568,8.180595171992115,40.60359671107694,0.0006220014617195
0.0008685117005762995,42.9433415032889,0.0021022643457778,8.657377647063042,42.9717755995821,0.0006619113909208
0.0009025834648423996,45.3413429566647,0.0022104421973227,9.140814740063602,45.372909702414205,0.0006959600304989
0.0009431569616942996,47.6707555998353,0.0023392630498275,9.610424328926795,47.70587825719972,0.0007365044777052
0.0009746357339858996,49.9647730941422,0.0024392081518533,10.07289825577907,50.003158757712825,0.0007679595795588
0.0010170380110698996,52.2166199023309,0.002573835381595,10.526870572309909,52.25894966101182,0.0008103284083368
0.0010630018635606996,54.4950809939598,0.0027197706132533,10.986208328382297,54.54176260651232,0.0008562539755037
0.0010992976719922996,56.796731924155,0.0028350098050236,11.450221155909649,56.84744666176076,0.000892518061257
0.0011426166162471995,59.1124256735083,0.0029725474530329,11.917065015779274,59.16776882008416,0.0009357974232551
0.0011775567490899996,61.3847159219853,0.0030834823748088,12.375158729872238,61.44433125730122,0.0009707042652547
0.0012161783739209995,63.6189773293808,0.0032061060336472,12.82558582960317,63.68321959302496,0.0010092876737507
0.0012567373623826995,65.9084703500188,0.0033348808220131,13.287147622563792,65.977697718138,0.0010498049263412
0.0012972118605342996,68.2286626212878,0.0034633873536445,13.75489838445162,68.30308853854092,0.0010902361391083
0.0013414365945777996,70.565712898872,0.0036038008842326,14.226047720412597,70.64580889211341,0.0011344117082672
0.0013828545600589996,72.8607623936972,0.0037353029246354,14.688729698569356,72.94648113979494,0.0011757818596069
0.0014258121845225995,75.1296122094384,0.0038716933823073,15.146129821422782,75.22122758657434,0.0012186880844718
0.0014724809209476996,77.4223124012749,0.004019866620457,15.60833818009702,77.52033676955851,0.0012652988946053
0.0015183152876013996,79.7056549476927,0.0041653907345825,16.068660037454848,79.81022351355504,0.0013110742560524
0.0015595453685892996,81.9582004604378,0.0042962962417191,16.52277321282426,82.06910336078936,0.0013522494690517
0.0016059729369596995,84.1946325205354,0.0044437037712951,16.973637916139936,84.31247063267848,0.0013986132233812
0.0016440413395332996,86.4046899021539,0.0045645709494663,17.41918548427423,86.52891048087045,0.00143662769764
0.0016923581660812995,88.5550657206821,0.0047179768737562,17.85270124928951,88.68665650875269,0.0014848739968619
0.0017311699830551996,90.7869838642718,0.0048412043926483,18.3026559470372,90.92541483909984,0.0015236274750182
0.0017714746205906996,92.960356875996,0.0049691716168235,18.7408079462008,93.10584851910718,0.0015638699403206
0.0018096197552575997,95.1418142847585,0.0050902824193909,19.18058975980731,95.2943493098302,0.0016019547423438
0.0018541781503268995,97.3404973902376,0.005231755323736,19.6238442738719,97.50089476517824,0.0016464408245042
0.0018929967699361995,99.5175101429448,0.0053550044409955,20.06273004481768,99.68535792523528,0.0016851948331923
0.0019298387361576996,101.626259805809,0.0054719776837488,20.48785397685109,101.80140834934924,0.0017219740894416
0.0019712147148547997,103.839591352484,0.005603346416112,20.93406161666077,104.02285094368256,0.0017632780280647
0.0020118897128235994,105.945450665464,0.005732489534663,21.358602854157542,106.1367360787506,0.0018038805436053
0.0020547376999350995,108.069686709951,0.005868531893742,21.78684884072612,108.26943801804676,0.0018466503930949
0.0020941141252420995,110.15705974947,0.0059935520440917,22.20766324549315,110.36500685833066,0.0018859533986353
0.0021346880556736996,112.190840471627,0.0061223742732121,22.617673439080004,112.40717883868008,0.0019264500606356
0.0021834390066681995,114.21692709225,0.0062771585426196,23.0261325017976,114.44274055984334,0.0019751060020425
0.0022310413999466995,116.267333304575,0.0064282961412788,23.43949439420232,116.50273514710685,0.0020226133398453
0.0022660360560515995,118.261845434199,0.0065394041744119,23.84158803953452,118.50542401867337,0.0020575366769978
0.0023047983969621995,120.255828595293,0.006662474606803,24.24357504481107,120.50817549429652,0.0020962185968083
0.0023438819898088997,122.191230845786,0.0067865650140913,24.63375213851046,122.45241469847474,0.0021352195871617
0.0023863602916854997,124.139946269575,0.0069214336225495,25.026613167946323,124.41056875713775,0.0021776063869669
0.0024276496190207995,126.078148632086,0.0070525272368391,25.41735476422854,126.3582020422271,0.0022188050515479
0.0024610377329473995,127.988002537735,0.0071585344985561,25.802381311607377,128.27657152405553,0.0022521186109817
0.0025004387460083994,129.875212032783,0.0072836327150247,26.18284274580905,130.17315324325,0.0022914302154233
0.0025410810736906995,131.723335799321,0.007412672105416,26.55542449714312,132.03087025504132,0.0023319786985651
0.0025830930448493996,133.565148102539,0.0075460601138449,26.926733857471863,133.88259397236465,0.0023738919344743
0.0026208778780008996,135.386152150145,0.0076660269591009,27.29384827346923,135.71304156503382,0.0024115864664489
0.0026613051207578994,137.248075358292,0.0077943834548544,27.669211992231663,137.5850089418458,0.0024519155196501
0.0027017521150749994,139.055061169409,0.0079228026618112,28.03350033175285,139.4020551249275,0.0024922626488797
0.0027388821393399994,140.881766220866,0.0080406904888526,28.40176407012659,141.23854942644235,0.0025292995647155
0.0027785541988966994,142.703751704144,0.0081666492779451,28.76907634355543,143.07081044140847,0.0025688706255958
0.0028156420788644997,144.523626880912,0.0082844032968428,29.13596317919185,144.9007267268975,0.0026058626696526
0.0028569227895874996,146.25180365246,0.0084154695533884,29.48436361633594,146.6394501408901,0.0026470351009536
0.0029067051372015994,148.008331892855,0.0085735285070631,29.838479709599568,148.40800233467115,0.0026966846146421
0.0029510388369415994,149.829696983198,0.0087142880037376,30.20566691181272,150.24092820556788,0.0027408979440073
0.0029941490076009995,151.644056286734,0.0088511627955812,30.57144174740558,152.0668047053722,0.002783889191737
0.0030403210722714995,153.419495368838,0.0089977591009101,30.929370266357743,153.85427699425912,0.0028299318372686
0.0030813527127788996,155.186380975206,0.0091280345595211,31.28557440460153,155.63253739999612,0.0028708466881525
0.0031268627923651997,156.961848123537,0.0092725290622076,31.64350858170506,157.4202523120042,0.0029162252730163
0.0031631941139950996,158.786939252809,0.0093878810083825,32.011446953366296,159.25644252568793,0.0029524501425367
0.0031991775425123997,160.676517491842,0.0095021283939249,32.392385926355345,161.15738958604553,0.0029883268448777
0.0032468127811892994,162.377841744073,0.0096533702767241,32.73537289560512,162.8715404625268,0.0030358188186124
0.0032942830581386994,164.100427631782,0.0098040884060384,33.08264621056725,164.6071536475208,0.0030831440830701
0.0033371526002938996,165.802990433713,0.0099401992023812,33.42588287143654,166.3220816945828,0.003125880742571
0.0033828904174697996,167.496385832092,0.0100854167719147,33.767271383749744,168.02843964592066,0.0031714747725838
0.0034320493872376998,169.23811717692,0.0102414965009278,34.11840442286707,169.78402318790933,0.0032204768822618
0.0034918263676316998,170.932353406015,0.0104312884136787,34.459962446652625,171.49394228085188,0.0032800598868251
0.0035441655965063996,172.521053149681,0.0105974654653559,34.78024431497569,173.09689122930322,0.0033322263604464
0.0035882291601366995,174.186716422517,0.0107373672798821,35.11604203077943,174.77578941448718,0.0033761423743497
0.0036337697288047997,175.803636689724,0.0108819585854033,35.44201315664836,176.40618405779358,0.0034215284208635
0.0036913124741999996,177.440357657786,0.0110646568020331,35.771976103809656,178.0587251098532,0.0034788729743279
0.0037502927462123997,179.043139589388,0.0112519191656724,36.09509694122063,179.6776526394126,0.00353764669075
0.0038139044727285997,180.575552353587,0.0114538863973614,36.404031354483145,181.22698286155511,0.0036010317701553
0.0038709125737436995,182.093084190869,0.0116348871180843,36.7099657728792,182.760370011198,0.0036578333391289
0.003939068801235899,183.602784942127,0.011851283140372,37.0143214443328,184.28811678140573,0.0037257384122993
0.0040162226269737,185.071352271155,0.0120962465370896,37.310384617864855,185.7764447763596,0.0038026023637823
0.0040994275397104995,186.532856768198,0.0123604221350289,37.60502392446872,187.259037823854,0.0038854880470089
0.004185757498200299,187.962906127967,0.012634519753234,37.89332187539815,188.7108812619352,0.0039714795249229
0.004280243667948599,189.318272761703,0.0129345133421849,38.166563788759326,190.08952936798823,0.004065586760721
0.0043794154821464,190.567211986019,0.0132493838522629,38.41834993638143,191.3624554950768,0.0041643513244195
0.004488712656288099,191.802126630423,0.0135964023801628,38.66730872869328,192.62348691106493,0.004273188370155
0.004601144526018199,192.934708051098,0.0139533735665558,38.89563714310136,193.7826104307488,0.004385134556169
0.004718798588275199,193.941223993499,0.0143269252142218,39.0985507570894,194.8163677453445,0.0045022669588215
0.0048440827093401,194.874233603141,0.0147247022986029,39.28664549439323,195.7780021308496,0.0046269805081463
0.004967425268429899,195.725669642176,0.015116314923713,39.45829499986268,196.65752818106287,0.0047497461458933
0.005104440322748999,196.487144461398,0.0155513377211761,39.61180832341784,197.44955011222908,0.0048861026596059
0.0052393093279771,197.167534716493,0.0159795468127754,39.74897499884499,198.159864748292,0.0050203052827666
0.005381067229431699,197.726199612178,0.0164296281498937,39.86160184181508,198.7493706153653,0.0051613433533527
0.005520268230131799,198.222173119467,0.0168715913271165,39.96159010088455,199.27550335469363,0.0052998181527498
0.0056685852664178,198.64785893508,0.0173424979173246,40.04740836131213,199.7329140783438,0.0054473403330775
0.0058244936024701,199.031568991752,0.0178375068842906,40.124764308737205,200.14975071839183,0.0056023896715724
0.0059809653582471,199.34011607805,0.0183343047088826,40.18696740133488,200.4912223548623,0.0057579751585437
0.0061334401013059,199.657692959718,0.0188184120180943,40.25099090067915,200.8410758663946,0.0059095629885547
0.0062928287638204,199.951904379731,0.0193244710215778,40.31030392295377,201.1689011614304,0.0060679999596141
0.006457236649640999,200.195487884513,0.0198464660590582,40.359410357517824,201.446880941356,0.006231399888582
0.006623690307163699,200.411309539412,0.0203749564216928,40.40292000314546,201.6974108617049,0.0063968058515055
0.0067888503930933,200.598216499403,0.0208993396945193,40.440600446279646,201.9186480801072,0.0065608993482661
0.0069513606093651,200.72699668926,0.0214153096311822,40.46656253255482,202.08089614924043,0.006722333810144
0.0071229815401458,200.842014996054,0.021960206086411,40.48975022320448,202.2311589456992,0.0068927903882719
0.007296599825724399,200.914341953978,0.022511444143123,40.50433133792197,202.3388685638833,0.0070652012106914
0.0074710603473964,200.978591892706,0.0230653562994316,40.517284125569525,202.43863687871016,0.0072384184747404
0.007641575170316899,201.049622510361,0.0236067408622042,40.531603898088775,202.54446545179283,0.0074076891692021
0.007813820682784,201.103386997677,0.0241536203642873,40.542442818731686,202.6332688444532,0.0075786488402549
0.0079884733654117,201.199271028207,0.0247081426316302,40.561773039286535,202.7650222993708,0.0077519678739423
0.0081704796979154,201.296058502241,0.0252860127373295,40.58128539405179,202.8992001398038,0.0079325524473782
0.0083467290117623,201.366265494005,0.0258456043087934,40.59543912359141,203.0054569330908,0.0081073938992862
0.0085230600369384,201.443014624578,0.0264054553137275,40.61091174831493,203.1183514815644,0.0082822858243755
0.0087042351820566,201.501789093272,0.0269806863994778,40.62276068120364,203.214121874519,0.0084619504813452
0.008883128272544,201.558397594576,0.0275486719617753,40.634172955066525,203.3072688312608,0.008639320443135
0.0090704129964559,201.62210694277,0.0281433009601955,40.64701675966243,203.4092917099886,0.0088249768882595
0.0092543186512696,201.667254869988,0.028727201414229,40.65611858178959,203.49192757843048,0.0090072501074339
0.0094360021891604,201.7199061853,0.0293040466470323,40.66673308695648,203.5817044657689,0.0091872883163723
0.0096169697583374,201.752837058519,0.0298786186791693,40.67337195099743,203.65144999896376,0.009366584823799
0.0098054582709502,201.793664034053,0.0304770697067149,40.68160266926508,203.7306969679551,0.009553298653226
0.0099871741384495,201.834933543261,0.0310540175860252,40.68992260232142,203.8090392364033,0.0097332706047031