File: example/data/02 processed data/test_ID_058.csv
Strain,Stress_MPa,Displacement(mm),Force(kN),True Stress (MPa),True Strain
8.87698863003756e-06,0.692567965330976,2.818443890036925e-05,0.13962170181072478,0.6925741132489297,8.876949229716283e-06
1.4487063924687e-05,0.640853625956701,4.599642796088122e-05,0.12919609099287094,0.6408629100441466,1.4486958988209235e-05
1.5482629362479e-05,0.585522871435372,4.9157348225870825e-05,0.11804141088137099,0.5855319368689738,1.5482509507904283e-05
1.18915103446756e-05,0.620802622309918,3.775554534434503e-05,0.12515380865767947,0.6208100045907232,1.1891439641192907e-05
1.1595920534892e-05,0.790455036141389,3.68170476982821e-05,0.15935573528610403,0.7904642021951745,1.1595853302734658e-05
3.54053644945188e-05,0.962042977902852,0.00011241203227009718,0.19394786434521497,0.9620770393851439,3.540473773929912e-05
0.000105732160239,1.12749514117911,0.000335699608758825,0.22730302046170858,1.127614353676046,0.0001057265709880206
0.0001825087367732,1.20386976560035,0.00057946523925491,0.24270014474503057,1.2040894823505093,0.00018249208407992374
0.0002845042386575,2.17506010897609,0.0009033009577375624,0.4384921179695798,2.1756789227964286,0.0002844637750010781
0.0003888036605347,4.49330403189412,0.0012344516221976724,0.9058500928298547,4.495051044949616,0.0003887280959772807
0.0004815501596972,8.27277803000261,0.00152892175703861,1.6677920508485264,8.2767617875841,0.00048143425162802927
0.0005994828722434,13.2239387947805,0.001903358119372795,2.665946061027749,13.231866319591564,0.0005993032541679826
0.0006915941417031,18.4603432051076,0.0021958113999073423,3.721605190149692,18.47311027032208,0.0006913551006813118
0.000809062488605,23.9411610927847,0.002568773401320875,4.826538076305396,23.96053098815852,0.0008087353739753433
0.0009139756128834,29.4999386069027,0.0029018725709047946,5.947187623151584,29.526900831370963,0.000913558191495455
0.0010250119481079,35.2190159803605,0.0032544129352425825,7.100153621640677,35.25511589254098,0.001024486982061363
0.0011356500440375,41.0018533628833,0.0036056888898190623,8.265973637957273,41.04841711946048,0.0011350056813272198
0.0012298165827689,46.8848965424742,0.0039046676502912576,9.451995142962799,46.94255636572354,0.001229060977795493
0.0013435127188744,52.8715443780074,0.00426565288242622,10.658903346606293,52.94257797034578,0.0013426110132064497
0.0014361295627591,58.8662190665992,0.004559711361760142,11.867429763826399,58.9507585840486,0.0014350993149602556
0.001536087119181,64.8280624088509,0.004877076603399674,13.069337381624342,64.92764396047859,0.001534908544137032
0.0016269782128812,70.7136816444676,0.005165655825897809,14.255878219524668,70.82873126385577,0.0016256561176478438
0.001720754529846,76.501786333999,0.00546339563226105,15.422760124934198,76.63342712937454,0.0017192757279637617
0.0018131503793666,82.0918415816241,0.005756752454488955,16.54971526285542,82.24068643533072,0.001811508606438722
0.0019026751974382,87.484271661052,0.006040993751866285,17.636829166868086,87.65072581490745,0.001900867403717746
0.0019828918760208,92.769363402342,0.0062956817063660395,18.702303661912147,92.95331501937612,0.0019809285408838653
0.0020645310130363,97.9645922354927,0.006554885966390252,19.74966179467533,98.16684317434233,0.00206240279755889
0.0021419634414161,103.096699412978,0.0068007339264961175,20.784294601656367,103.31752877405127,0.0021396727082518795
0.0022238859021551,108.224120199279,0.007060837739342442,21.817982632174648,108.46479829446331,0.0022214167279989237
0.0023078509333798,113.16935421229,0.007327426713480864,22.814941809197666,113.43053221203883,0.002305191935675529
0.00238806929429,118.050317850127,0.007582120009370749,23.798944078585606,118.33223018936606,0.0023852223883177493
0.0024831182129336,122.914595232969,0.007883900326064178,24.77958239896655,123.21980670302736,0.0024800403689513575
0.0025664827874677,127.751071326677,0.008148582850209947,25.754615979458087,128.07894225231746,0.0025631949946926793
0.0026564401025139,132.67763347478,0.008434197325481632,26.74781090851565,133.03008366104908,0.0026529180016260437
0.0027354448357547,137.588013577686,0.008685037353521172,27.7377435372615,137.96437799888884,0.0027317103153627017
0.0028115485069832,142.515899860162,0.008926666509671659,28.73120541180866,142.91659022563522,0.0028076034971408663
0.0028971150245043,147.428246720281,0.009198340202801152,29.72153453880865,147.85536330889067,0.0028929264746287925
0.0029765580037312,152.280144882681,0.00945057166184656,30.699677208348486,152.73341556674086,0.0029721368260447914
0.0030634255546141,157.189958796936,0.009726376135899767,31.689495693462295,157.67149853364324,0.0030587428275693973
0.0031360089211852,162.096980288846,0.00995682832476301,32.678751226231356,162.605317865129,0.003131101901503397
0.0032167878359666,167.067241605596,0.010213301379193953,33.68075590768815,167.60466147618138,0.0032116250427531618
0.003294041943322,171.942834686308,0.01045858317004735,34.66367547275969,172.50922159561838,0.0032886284720365765
0.0033773529089804,176.711440578419,0.01072309548601277,35.625026420609274,177.30825747630664,0.00337166246147797
0.0034592970836147,181.407437557107,0.01098326824047667,36.571739411512766,182.0349797767943,0.003453327478588452
0.0035428765014628,186.038852523403,0.01124863289214439,37.50543266871804,186.69796520236727,0.0035366152985983517
0.0036270830462564,190.656121951911,0.01151598867186407,38.436274185505255,191.34764753950776,0.0036205210430444675
0.0037120377676858,195.243446336155,0.011785719912402414,39.361078781368846,195.96819738284793,0.0037051651578323234
0.0037982173567189,199.839408839093,0.012059340107582507,40.28762482196115,200.5984423503021,0.0037910223422386938
0.0038876166497362,204.434577705702,0.012343182862912435,41.214010865469525,205.22934097377245,0.0038800793964472277
0.0039748062514146,209.001211451002,0.012620009848241355,42.134644228522,209.83195077283068,0.0039669275796084535
0.0040652047599487,213.391331550791,0.01290702511283712,43.01969244063947,214.25881100754307,0.004056964140732188
0.0041586881367042,217.574410142121,0.013203834834035835,43.8630010846516,218.47923426042945,0.0041500646930696
0.0042631579751682,221.520217647267,0.013535526571159034,44.65847587768903,222.46459332979094,0.004254096461854112
0.0043781185494002,225.206097613507,0.013900526394345634,45.40154927888301,226.19207660690677,0.004368562469997224
0.0045133256510548,228.693275680895,0.014329808942098989,46.10456437726844,229.72544290824933,0.004503171139120665
0.0046772604253297,231.901485605474,0.014850301850421797,46.75133949806355,232.98614924667166,0.004666356031360217
0.0048868810021557,234.844670854146,0.015515847181844348,47.344685644195835,235.9923288146006,0.004874978959352168
0.0051420235971907,237.614419573018,0.01632592492108047,47.90306698592043,238.83623852549522,0.005128848538860715
0.0054494896908246,239.991033791357,0.017302129768368105,48.382192412337574,241.29886245589336,0.005434694946744835
0.0057689470396208,241.964572155572,0.018316406850796038,48.780057746563315,243.36045295780198,0.005752370387312126
0.0061143891244984,243.414944274543,0.01941318547028242,49.07245276574787,244.90327796255562,0.006095772096608986
0.0064579755401453,244.38613508164,0.020504072339961328,49.26824483245862,245.96437476434787,0.006437212161092973
0.0068142972450824,245.099655173192,0.02163539375313662,49.41209048291551,246.76983707820932,0.006791184858650371
0.0071751336685826,245.655448023489,0.022781049397749754,49.52413832153538,247.41805869947305,0.007149514869545631
0.0075428216238678,246.03188870556,0.023948458655780266,49.60002876304089,247.88766335584933,0.007514516787954565
0.0079149143920603,246.344262474511,0.02512985319479145,49.66300331486142,248.294056222972,0.007883755761087836
0.0082848040660722,246.580185664565,0.02630425290977923,49.710565429976306,248.6230541893716,0.008250673457559431
0.0086587467730844,246.829148335329,0.02749152100454297,49.76075630440233,248.96637942698067,0.008621474822963208
0.0090216246431872,247.10710732298,0.028643658242119358,49.81679283631277,249.3364148919117,0.008981172899185857
0.0093873672488384,247.346431146844,0.02980489101506192,49.86504051920375,249.66836293370898,0.009343579736574683
0.0097536434958069,247.537311221752,0.030967818099186906,49.903521942305204,249.95170190731957,0.00970638376961353
0.0101157438365763,247.791431761118,0.03211748668112975,49.95475264304139,250.29802640971192,0.010064922145331414
0.010481145320701,247.990464149889,0.033277636393225674,49.994877572617625,250.58968824279208,0.010426598925166865
0.0108512481572192,248.238860296203,0.034452712899170956,50.04495423571452,250.93256177154237,0.010792795837508704
0.0112049695440101,248.473337712789,0.03557577830223206,50.092224882898265,251.25747389435935,0.011142658899972145
0.0115572369805733,248.735060879475,0.03669422741332023,50.14498827330216,251.6097509234364,0.011490962263548983
0.0119072432761374,248.970562354286,0.03780549740173625,50.19246537062406,251.9351154088352,0.01183690982276728
0.012255973342599,249.195718765471,0.03891271536275182,50.23785690311895,252.24985485175046,0.012181476967401567
0.0126141528641103,249.383369831705,0.040049935343550204,50.27568735807173,252.5291297805291,0.012535257212970318
0.0129637482949346,249.588868680766,0.04115990083641735,50.317115926042426,252.82447595156094,0.012880438145380058
0.0133089703470861,249.792901000799,0.042255980851998366,50.35824884176108,253.11738731313125,0.013221184040358306
0.0136425940287966,249.924029432205,0.0433152360414292,50.38468433353253,253.33364150378958,0.013550371664361436
0.0139819795191749,250.103838846379,0.044392784973380305,50.42093391143001,253.6007855987961,0.013885133333730988
0.01431621194506,250.266815629289,0.045453972925565495,50.45379003086467,253.84968840465314,0.014214702654767559
0.0146571397591156,250.483016879802,0.04653641873519203,50.497376202968084,254.15438146549414,0.014550762087956096
0.0150123127542276,250.80503013527,0.04766409299467263,50.56229407527043,254.57019368799416,0.014900743212515704
0.0153580993353881,251.067054161634,0.04876196538985721,50.615118118985414,254.92296691929164,0.015241357498898763
0.0157189095570381,251.272567290136,0.049907537843595966,50.65654956569142,255.2222980495344,0.01559664705598169
0.0160717000854713,251.424413144433,0.05102764777137138,50.687161689917694,255.46523090665596,0.01594391761654483
0.0164192401790787,251.601053657906,0.052131087568574874,50.72277241743385,255.73215178722444,0.016285902016189357
0.0167695659133437,251.870033707138,0.053243371774866245,50.77699879535902,256.093784838986,0.0166305092033646
0.0171123498851342,252.144457917379,0.05433171088530109,50.83232271614361,256.4592421028587,0.01696758282831143
0.0174587282500146,252.332227440615,0.05543146219379635,50.870177052027984,256.7376272282215,0.017308075595508544
0.0178047273276641,252.460844321333,0.05653000926533351,50.89610621518074,256.9558408153862,0.01764807981465229
0.0181476130390616,252.59933669112,0.057618671399020584,50.924026276929794,257.18341170731406,0.01798491060174007
0.0184960289412908,252.804571474449,0.058724891888598287,50.96540160924892,257.480452144931,0.01832705774859121
0.0188381630100192,253.053683223862,0.05981116755681095,51.01562253793059,257.8207497587189,0.01866292220646586
0.0191862901430847,253.330318412941,0.060916471204293915,51.071392192048904,258.1907874040517,0.01900455415883299
0.0195278220559252,253.575975305043,0.062000835027562505,51.12091662149666,258.5277618284575,0.019339600562830378
0.0198614391232025,253.751541630337,0.06306006921616793,51.15631079267594,258.79141242684676,0.019666774071688084
0.020193277965514,253.878619353558,0.06411365754050695,51.181929661677295,259.00526088366536,0.019992097547042426
0.0205112562395413,254.03495522074,0.06512323856054363,51.21344697250118,259.245531281073,0.02030373332897058
0.020838965838481,254.210954038817,0.06616371653717718,51.2489283342255,259.5084474257996,0.020624804743577148
0.0211648245470412,254.456687205204,0.06719831793685581,51.29846814056912,259.8422183447235,0.02094396057752852
0.0214879555967265,254.613191835236,0.06822425901960663,51.330019473983576,260.08430879573234,0.021260344307080292
0.0218190926272204,254.820235742257,0.06927561909142477,51.37175952563902,260.3801820692074,0.021584463027935936
0.0221534736093769,254.984863999346,0.07033727870977165,51.404948582268155,260.63366445474605,0.021911650379334898
0.0224964455584761,255.179066355026,0.07142621464816161,51.44409977717324,260.91968832894463,0.022247132702348512
0.0228295909195869,255.416852748358,0.07248395116968841,51.49203751406897,261.2479150105714,0.02257289530265299
0.0231636342245654,255.713111376013,0.07354453866299514,51.55176325340422,261.6363563543525,0.02289942943174143
0.0234811327501405,255.8296541814,0.07455259648169608,51.575258282970246,261.836824252656,0.023209691899606262
0.0238091829414607,255.999807447043,0.07559415583913771,51.60956118132387,262.0949536955283,0.02353016446923976
0.0241444760388708,256.140502720506,0.0766587114234148,51.63792534845401,262.32488095102553,0.023857606546784454
0.02447978605434,256.314429324576,0.0777233207225295,51.672988951834526,262.58895171708184,0.024184957954915248
0.0248068023113894,256.636293181587,0.07876159733866134,51.73787670540794,263.00261897247043,0.024504109274873866
0.0251348350182569,256.793066306696,0.07980310118296566,51.76948216742991,263.2475176621471,0.02482415029818298
0.0254622260979906,256.979042121002,0.08084256786112015,51.80697489159401,263.522300593932,0.025143463232667744
0.0257943679514293,257.166698416101,0.08189711824578802,51.84480640068596,263.8001508599001,0.025467305561613644
0.0261229049902934,257.286840392304,0.08294022334418155,51.869027023088485,264.0079200791249,0.025787530013158512
0.0264476545301867,257.507615557415,0.08397130313334276,51.91353529637487,264.31808801256966,0.026103962051118625
0.0267670511647668,257.713203217246,0.0849853874481346,51.9549817685968,264.611425713598,0.026415080646042647
0.0270887912005256,257.915311282592,0.08600691206166877,51.99572675457054,264.90192529734463,0.02672838407440787
0.0274181377834527,258.18386266075,0.08705258746246232,52.049866712407194,265.2627833806464,0.027048992957348996
0.0277443966960862,258.363221992683,0.08808845951007369,52.086025553724895,265.531353715327,0.02736649477036935
0.0280654482881823,258.527348134718,0.0891077983149788,52.119113383959146,265.78303405487384,0.027678830656384726
0.0283903077344666,258.691560401134,0.09013922705693145,52.15221857686861,266.0358934092315,0.027994771758482338
0.0287084775259145,258.803752422188,0.09114941614477853,52.1748364883131,266.2336141322227,0.02830411012984784
0.0290366257118052,258.929909001503,0.09219128663498151,52.20026965470301,266.4483598547714,0.028623049718775453
0.0293673850726268,259.015480929467,0.09324144760559008,52.21752095538055,266.6220882976943,0.028944424300184717
0.0296981491537581,259.123199247861,0.09429162356318196,52.23923696836878,266.81867866832295,0.02926570021732112
0.030027381996084,259.361386249086,0.0953369378375667,52.28725546781574,267.1493296690212,0.02958538635040123
0.0303542400188621,259.547985657637,0.09637471205988717,52.32487390857962,267.4263675107011,0.02990266546221986
0.030681499036494,259.752877398571,0.09741375944086844,52.36618008355192,267.72248505620183,0.030220232997979612
0.0310109750287467,259.888556414558,0.09845984571627077,52.3935329731749,267.9479539477869,0.030539850010896836
0.031337180450572,260.047175761123,0.0994955479305661,52.4255106334424,268.19632103361096,0.030856193712302513
0.0316599985752509,260.262848400462,0.1005204954764216,52.46899023753315,268.5027698100114,0.03116915403100359
0.0319826491681061,260.451025359499,0.10154491110873687,52.506926712475,268.78093912904535,0.03148185409643132
0.0323184607373702,260.571357973442,0.10261111284115038,52.531185767445905,268.9926231753899,0.03180720544233221
0.0326522616777452,260.721722075836,0.103670930826841,52.561499170488545,269.23487597012854,0.03213050391785937
0.0329886839249491,260.857206040727,0.10473907146171339,52.58881273781057,269.4625419603499,0.032456235503394326
0.0333135100537285,261.065287645798,0.10577039442058797,52.63076198939288,269.7622887304658,0.03277063882000666
0.0336343625147224,261.232521477221,0.1067891009842436,52.66447632980775,270.01891080522086,0.03308109896061225
0.0339541762042931,261.366880180544,0.10780450944863058,52.691563044397675,270.2413772841606,0.0333904580870848
0.0342718532368909,261.50946686438,0.1088131340271286,52.72030851985901,270.4718809328136,0.03369765568596791
0.0345943929826272,261.63667748395,0.10983719771984136,52.74595418076432,270.6878395234986,0.0340094590700086
0.0349272525401519,261.894447643893,0.11089402681498228,52.79792064500883,271.0417011556148,0.0343311368462378
0.0352595810793795,262.031398937333,0.11194916992702991,52.825530025766334,271.2705162935071,0.03465219824676972
0.0355904219018243,262.240840031586,0.11299958953829214,52.86775335036774,271.574102168199,0.03497172001298495
0.0359183641162866,262.396106491723,0.11404080606920995,52.89905506873136,271.82094538738863,0.0352883416169244
0.0362370683870973,262.505603807865,0.11505269212903393,52.92112972766559,272.01803732504686,0.035595948149064534
0.0365669704462879,262.694840355831,0.11610013116696408,52.95927981573553,272.300794819515,0.035914262910899664
0.0369105436203699,262.875539188926,0.11719097599467442,52.99570870048748,272.5784182448871,0.03624566093657925
0.0372571228783237,263.055720508196,0.11829136513867775,53.03203325445231,272.85641981101577,0.03657984728687015
0.0376075774796601,263.162127404599,0.11940405849792081,53.05348488476716,273.0590175006796,0.03691765688439104
0.0379518907531652,263.371380227693,0.1204972531412995,53.09567025390291,273.36682207760475,0.037249435647595384
0.0382858675426882,263.517636520127,0.12155762944803503,53.1251555224576,273.60663784709885,0.03757114908438176
0.0386101193407027,263.651840436224,0.12258712890673107,53.15221103194276,273.8314694598625,0.037883395631822483
0.0389403914832015,263.751048319397,0.12363574295916475,53.17221134119043,274.02161739505914,0.03820133942530471
0.0392587248636109,263.876806193678,0.1246464514419646,53.19756412864549,274.236273125924,0.03850769446163888
0.0395890079559535,264.04673917535,0.12569510026015235,53.23182261775056,274.5000876333065,0.038825450389509256
0.039914058049314,264.187964802942,0.12672713430657195,53.26029370427311,274.7327785660168,0.03913807324765415
0.0402334850084806,264.342178677952,0.1277413149019259,53.29138322147513,274.9775857609005,0.03944519277169316
0.0405573471198277,264.499507693885,0.12876957710545292,53.32310075108722,275.2269060404494,0.03975648029657232
0.0408774258289924,264.628749591996,0.12978582700705085,53.349155917746394,275.44609167566176,0.04006403613819419
0.041199692186487,264.775993452525,0.13080902269209624,53.37884028002904,275.6846828811403,0.04037359850481331
0.041524023153031,264.900980396867,0.13183877351087342,53.40403764800839,275.9007348401271,0.04068504737033195
0.0418415597143456,265.045434265594,0.13284695209304725,53.43315954794375,276.1353486304325,0.04098987775284831
0.0421647321244186,265.197504385477,0.13387302449502902,53.463816884112155,276.3794861179549,0.04130002308583415
0.0424970517258764,265.34597213646,0.13492813922965757,53.49374798271033,276.6223936395961,0.04161884660612641
0.0428309064712407,265.479017978655,0.1359881280461892,53.52057002449685,276.8497249677756,0.041939040604297484
0.0431835078431214,265.683102459425,0.13710763740191045,53.56171345582008,277.1562307982664,0.042277102865822806
0.0435255704185395,265.778445523001,0.1381936860788629,53.580934617436995,277.3466039693423,0.04260495170881253
0.0438608123328867,265.915244091977,0.13925807915691527,53.60851320894257,277.57850270954896,0.04292615905211968
0.0441960305262816,266.005181883235,0.14032239692094406,53.62664466766019,277.76155502189556,0.04324724053744531
0.0445334890574693,266.130429391407,0.14139382775746503,53.65189456530766,277.98214595656884,0.04357036378625265
0.044871706249549,266.300755865236,0.14246766734231806,53.686232382431584,278.2501251564537,0.043894108740839086
0.0452167510760822,266.408859888457,0.14356318466656098,53.70802615351294,278.4550029904962,0.04422428120646693
0.0455561363719441,266.548940122547,0.1446407329809225,53.73626632870547,278.6918799885669,0.04454893177074424
0.0458892779467375,266.647717255893,0.14569845748089155,53.756179798788025,278.8839884669117,0.04486750721653893
0.0462287653595639,266.683841380688,0.14677633001661536,53.763462422346706,279.012306109063,0.04519204666295528
0.0465630269986473,266.830179512071,0.14783761072070517,53.79296418963352,279.2546003647455,0.0455114875582668
0.046895598433322,266.894136363157,0.14889352502579734,53.80585789081245,279.41029660625185,0.04582921195313396
0.0472302328947097,267.036402071371,0.1499559894407033,53.8345386575884,279.6485935325672,0.04614880541712728
0.0475597202978991,267.143809727963,0.15100211194582963,53.856192041157335,279.84909459794005,0.04646338340658573
0.0479042665439905,267.244593114849,0.15209604627716983,53.87650997195357,280.04674933586307,0.046792233008735994
0.0482443110049713,267.419037216754,0.15317568744078386,53.91167790289761,280.3204844168891,0.047116679918278274
0.0485933807487546,267.57237309,0.15428398387729583,53.942590414944,280.5746192934102,0.04744962867094599
0.0489354736728329,267.713638181939,0.15537012891124444,53.971069457478904,280.8143318750496,0.04777581529421012
0.0492762426912802,267.832939430037,0.1564520705448146,53.99512058909546,281.0307403541105,0.0481006338230419
0.0496101442352826,267.929697309635,0.15751220794702225,54.01462697762242,281.2217282380816,0.048418804019293445
0.049945286089601,268.042831709869,0.15857628333448318,54.03743487270959,281.4303076238852,0.04873805432564342
0.050275620875444,268.150176540116,0.1596250962795347,54.05907559048738,281.6315931535302,0.049052625795217415
0.0506159231274117,268.240411369342,0.16070555592953215,54.077266932059345,281.8176474108779,0.04937658564542037
0.0509521085226504,268.289154075116,0.16177294455941502,54.08709346154339,281.9590521690014,0.04969652332342389
0.0512912517719004,268.374441645511,0.16284972437578377,54.104287435735024,282.1397027010941,0.050019172221831845
0.0516340645688354,268.561468941605,0.16393815500605238,54.14199213862758,282.4283891696371,0.05034520643456191
0.051980814281884,268.684264383437,0.1650390853449817,54.1667476997009,282.6506912308171,0.050674876774580255
0.0523246858364675,268.800696615096,0.16613087753078432,54.19022043760336,282.8656086181045,0.05100170342368129
0.0526722214950503,268.849196490412,0.16723430324678468,54.19999801246706,283.0100809167213,0.05133190406248528
0.0530165085912287,268.930308867233,0.16832741477715113,54.21635026763418,283.18805489773445,0.05165891070342613
0.0533593088988526,269.05118894505,0.16941580575385698,54.240719691322084,283.4075744455725,0.05198439897366171
0.0537046830274709,269.160857854347,0.17051236861222008,54.262828943436354,283.61605640881686,0.05231222397853561
0.0540502748187948,269.245058732057,0.17160962254967346,54.279803840382684,283.7978281501272,0.0526401480506714
0.05439927800761,269.323766949826,0.17271770767416172,54.295671417084925,283.9747854221863,0.05297120002346793
0.0547444909504226,269.394660331462,0.17381375876759175,54.309963522822734,284.1425338760699,0.05329854892303202
0.0550797637230524,269.527610870777,0.17487824982069136,54.33676635154864,284.3731279943782,0.053616369494778014
0.0554253716765796,269.608245374015,0.17597555507314022,54.35302226740142,284.55138258094024,0.053943881568375464
0.0557665703114498,269.665160685489,0.1770588607388531,54.36449639419459,284.7034618294048,0.05426711000730136
0.0561217466536728,269.777360158078,0.1781865456254111,54.38711580786853,284.9177368177663,0.05460346903037885
0.056473942912404,269.844032645532,0.1793047687468827,54.400556981339264,285.08318914040865,0.054936894175316435
0.0568256119621451,270.016307471605,0.18042131797981067,54.435287586275564,285.36014938343766,0.055269709324192104
0.0571781014888879,270.098815475949,0.18154047222721906,54.451921199951315,285.54255295926123,0.055603189845315766
0.0575351080324938,270.203816095213,0.18267396800316782,54.47308932479495,285.7500218450432,0.05594083047231901
0.0578933592147042,270.26834641059,0.1838114155066858,54.486098636374955,285.9150888737024,0.05627953366288495
0.0582527074861076,270.378672062264,0.1849523462683916,54.508340287752425,286.1289617563893,0.05661915887166634
0.0586030742971011,270.493562434046,0.186064760893296,54.531502186703676,286.345316770256,0.05695018455344203
0.0589498455340859,270.577350487186,0.18716575957072273,54.5483938582167,286.52784350342785,0.05727770528441142
0.0593013168713028,270.596706534025,0.18828168106638637,54.55229603725944,286.64344757253014,0.057609555771908065
0.0596460035189008,270.642315198205,0.18937606117251002,54.56149074395813,286.7850476828806,0.05793489340283586
0.060002699809355,270.710203788781,0.1905085718947021,54.57517708381825,286.9535468820485,0.05827145511068977
0.0603529597362707,270.871818875831,0.19162064716265947,54.607758685367536,287.21973485413446,0.05860183358141914
0.0607093633376087,270.973497694035,0.1927522285969076,54.62825713511746,287.4241262204049,0.05893789499820572
0.0610631290785469,271.070428941724,0.1938754348243864,54.647798474651566,287.62283753356957,0.059271357464592334
0.0614203467601724,271.105093653226,0.19500960096354736,54.65478688049036,287.75646251385615,0.05960796096616465
0.0617890915553816,271.167959830014,0.19618036568833658,54.667460701730825,287.9231817268368,0.059955307574805536
0.0621583930685399,271.225697640519,0.19735289799261418,54.67910064432863,288.08465116474736,0.06030305771416015
0.0625402063974856,271.297985226531,0.19856515531201677,54.69367382166865,288.26501721782023,0.060662462415750885
0.062919990559386,271.41790261734,0.19977097002605054,54.71784916765575,288.4955144876714,0.06101982894417242
0.0632962920456556,271.558332705744,0.2009657272449565,54.74615987347799,288.7469682401181,0.06137379245510699
0.0636716915392809,271.657112701374,0.20215762063721684,54.766073920597,288.95398058574756,0.06172678272145839
0.0640479291685272,271.70210666198,0.20335217511007384,54.77514470305517,289.1040639444061,0.06208043611592434
0.0644270708638174,271.730519840375,0.20455594999262022,54.7808727998196,289.2373212979928,0.06243669277789553
0.0647989648162876,271.73449061247,0.20573671329171309,54.78167330747395,289.3426043090393,0.06278601591223634
0.0651693378276859,271.805164157866,0.20691264760290273,54.79592109422579,289.5185267241796,0.06313378917691016
0.0655455303160983,271.857799762408,0.2081070587536121,54.80653243210145,289.67686341840266,0.06348690305239472
0.0659244508452848,271.922340071795,0.20931013143377922,54.81954375847388,289.8486710135929,0.06384245160482774
0.0663067702516849,271.999901472915,0.21052399554909954,54.83518013693966,290.03533644836045,0.06420106131536432
0.0666924223474793,272.093084758966,0.21174844095324674,54.85396588740754,290.23963168553945,0.06456266679682433
0.0670715124381031,272.164279464003,0.2129520519909773,54.86831873994301,290.41874931928027,0.0649179920401019
0.0674589496388729,272.20479669976,0.21418216510342145,54.87648701467161,290.5674463717887,0.06528101071039769
0.0678446709911798,272.243310560252,0.21540683039699585,54.8842514089468,290.71356839476186,0.06564229081386935
0.0682318416343964,272.2782529933,0.21663609718920857,54.891295803449275,290.85629963202894,0.06600479716152874
0.0686360869078638,272.327336342907,0.21791957593246755,54.90119100673006,291.01881906752584,0.06638315023884364
0.0690246591032779,272.37734160396,0.21915329265290734,54.91127206735834,291.17809475563047,0.06674669922613642
0.0694196410348536,272.432012308753,0.22040736028566016,54.9222936814446,291.3441448096294,0.06711610977009291
0.0698131890252268,272.487026679567,0.22165687515509508,54.93338457860071,291.51021498006963,0.06748404353520986
0.0702055770955071,272.531299008687,0.222902707278235,54.9423098801513,291.66451613218004,0.06785075814621203
0.0706150240453302,272.623040982598,0.22420270134392337,54.96080506209176,291.8743235768952,0.06823327217340093
0.0710436343035955,272.654025004143,0.2255635389139157,54.967051440835235,292.02435784794073,0.06863353228237441
0.0714835915753729,272.711566772147,0.22696040325180894,54.978651861264844,292.2059690291672,0.06904422230549029
0.0719263852760857,272.761363182377,0.2283662732515721,54.9886908175672,292.38010207906297,0.0694573898392742
0.0723644367608146,272.862106753127,0.22975708671558634,55.00900072143041,292.6076194216863,0.06986596454035558
0.0727854639623667,272.844712538452,0.23109384808051425,55.00549404775192,292.70384153024173,0.07025850326859683
0.0732176906603071,272.858291104059,0.23246616784647503,55.008231486578296,292.836345056216,0.07066132346282993
0.0736515231222533,272.83707297327,0.2338435859131542,55.00395391141123,292.9319389619687,0.07106547706945508
0.0740753351237848,272.880126656792,0.23518918901801672,55.012633534009275,293.09381348751475,0.07146013806222092
0.0744793300615753,272.945066630638,0.23647187294550157,55.02572543273662,293.27383233689994,0.07183620011835375
0.0748838859492725,272.98227682449,0.23775633788894018,55.03322700781719,293.4242505083878,0.07221264267535007
0.0752899051703824,272.814279354759,0.23904544891596413,54.999358717919414,293.354440576505,0.07259030445098202
0.0757307547894433,272.79576545917,0.24044514645648246,54.99562631656868,293.4547946807569,0.07300020253651841
0.0761893151312609,272.888087901174,0.24190107554175333,55.01423852087668,293.67924442584376,0.07342638969390246
0.0766627127483515,272.93383517028,0.243404112976016,55.02346117032846,293.8576833752451,0.0738661761897601
0.0771617333638593,273.174614569736,0.24498850343025327,55.07200229725878,294.253241340941,0.07432955715410727
0.0776663241279743,273.179964179416,0.2465905791063184,55.073080778570265,294.39684782264294,0.07479789222296222
0.0781817775400539,273.190044249866,0.2482271436896711,55.07511292077298,294.5485275155665,0.07527608307648584
0.0787129532404002,273.144409889088,0.24991362653827062,55.06591303364014,294.6444130525645,0.07576862052256919
0.0792599544421354,273.099761353449,0.2516503553537799,55.056911888855325,294.7456359964815,0.07627557889216051
0.0798285672748373,272.970882293869,0.2534557010976084,55.030929870444,294.7617567351368,0.0768022945317726
0.0804109245669465,272.955358414197,0.25530468550005514,55.027800256302115,294.9039511497848,0.07734145447993175
0.0809978052728415,272.84905588724,0.2571680317412718,55.006369666867585,294.9492305848733,0.07788450838011798
0.0815901800448573,272.755652317217,0.2590488216424219,54.98753950715095,295.00983509803126,0.07843234716480857
0.0821823608074674,272.588091769613,0.26092899556370897,54.95375930075398,294.9900246792424,0.07897970671043048
0.0827976182115735,272.364945401697,0.26288243782174586,54.90877299298212,294.9161141652828,0.07954807909874968
0.0834284000692305,272.122087264145,0.2648851702198068,54.85981279245164,294.82479762809214,0.0801304577334462
0.0840940746823753,271.890580195263,0.26699868711654157,54.81314096736503,294.7549669516378,0.08074468401421367
0.0847679132333835,271.550775603137,0.26913812451599256,54.74463636159243,294.56956818792173,0.08136605925749212
0.0854504870822621,271.195136741373,0.2713052964861822,54.6729395670608,294.368893270264,0.08199509629015814
0.0861249420666296,270.658216515657,0.27344669106154895,54.56469644955645,293.9686397329253,0.08261626283772618
0.0868078175155004,270.103908119643,0.2756148206117138,54.45294787692003,293.55103888591646,0.0832447916942591
0.0874864387787141,269.46606956392,0.27776944312241725,54.32435962408626,293.0406963617646,0.08386901381441124
0.0881669881388663,268.754756485582,0.27993018734090047,54.180958907493334,292.45005391291016,0.08449461840191433
0.0888595099180971,268.018245789584,0.2821289439899583,54.03247835118014,291.8342157595545,0.0851308272888597
0.0895636860872929,267.11851245803,0.2843647033271549,53.85109211153885,291.04263105592565,0.08577732811111832
0.0902920281444858,266.27552919299,0.28667718935874237,53.681146685306786,290.31808676907133,0.08644557608692852
0.0910335671491414,265.289579231878,0.28903157569852395,53.48237917314661,289.43983595685063,0.08712547370039873
0.0917671688381432,264.241549742495,0.29136076106110465,53.27109642808699,288.49024865176716,0.0877976392394034
0.0925223333229654,263.098311860819,0.29375840830041516,53.040619671141116,287.4407815675152,0.08848909017954884
0.0932789953810832,261.885482984914,0.29616081033493913,52.79611336975867,286.3138977426365,0.08918143314631888
0.0940326385190647,260.583879012883,0.29855362729803037,52.53371000899722,285.0872687119971,0.0898705376672517
0.0947856557451033,259.303448446448,0.30094445699070294,52.275575206803914,283.8816958444111,0.09055859592930107
0.0955457745290575,257.914958406091,0.3033578341297576,51.99565561466794,282.5576428696306,0.09125266332381725
0.0963341455053596,256.626961062847,0.3058609119795167,51.73599535026995,281.3489000704736,0.09197201934610015
0.0971285274874271,255.17607365272,0.30838307477258103,51.44349644838835,279.96094993663195,0.09269633713511796
0.097949456014787,253.735468863643,0.3109895228469487,51.15307052291043,278.5887200104938,0.09344430925438033
0.0987573947286533,252.262486456282,0.3135547282634742,50.856117269586456,277.1752724064766,0.09417990012306966
0.0995818345704388,250.712025925888,0.31617232476114315,50.543544426659025,275.67838941645937,0.09492995713833745
0.100381912680268,249.107771876954,0.3187125727598509,50.22012681039392,274.11368648148255,0.09565731289236044
0.101183549347014,247.46095768869,0.3212577691767694,49.8881290700399,272.4999357124429,0.09638555533257002
0.101980704441969,245.702372730891,0.3237887366032515,49.533598342547634,270.7592737850505,0.0971092009966378
0.102810044435012,243.990470769365,0.3264218910811631,49.188478907103985,269.0751419108829,0.09786150824627618
0.103666184185119,242.250741022585,0.3291401347877528,48.83774939015314,267.36395096041383,0.0986375327345231
0.104532857323121,240.470358889051,0.33189182200090916,48.47882435203268,265.60741260523986,0.09942249203050299
0.105387178186086,238.659638394991,0.33460429074082304,48.11378310043018,263.8113042323508,0.1001956610970723
0.106213103746119,236.678767161774,0.3372266043939278,47.71443945981364,261.817153612831,0.1009425642379125
0.107034997467414,234.553311418131,0.3398361169590394,47.28594758189521,259.6587245117442,0.10168526792181022
0.107892405582324,232.326047749665,0.3425583877238787,46.83693122633246,257.39226392081025,0.1024594767347554
0.108761099692194,230.000432916545,0.34531649152271593,46.368087275975476,255.0155329302291,0.10324326558788428
0.109488217895831,228.230696306554,0.34762509181926343,46.011308375401285,253.21926851428321,0.10389884404240135
0.109961796941975,227.023464112245,0.3491287052907706,45.76793036502859,251.98737217401944,0.10432559756256655