File: example/data/02 processed data/test_ID_097.csv
Strain,Stress_MPa,Displacement(mm),Force(kN),True Stress (MPa),True Strain
0.0007360071803601,1.43829297183558,-0.0009353046548216,0.2899598631220529,1.437869273532728,-0.0002946275416828
0.0007009024793064,2.1332092275688,-0.0010467620806671,0.4300549802778701,2.132505932283903,-0.0003297432036197
0.0006636969444654,2.84211669094955,-0.0011648896537872,0.5729707248954293,2.8410739343107645,-0.0003669617013555
0.0006384663173383,3.8960260803746,-0.0012449968949158,0.7854388578035193,3.8944983511233935,-0.0003922019073868
0.0005789578453952,5.74587365843518,-0.0014339362933351,1.1583681295405324,5.743278629529432,-0.0004517354953324
0.0005581361204682,7.79354085010826,-0.0015000452699783,1.571177835381825,7.789858751182721,-0.0004725668452675
0.0005658911819407,10.0184814951963,-0.0014754229498032,2.019725869431574,10.01382590542616,-0.0004648081482429
0.000582871198863,12.3142683604262,-0.0014215113960749,2.482556501461922,12.308755014659688,-0.0004478203813287
0.0005991385581874,14.7201836451834,-0.0013698625302199,2.9675890228689736,14.713832581242144,-0.0004315458679484
0.0006414436088828,17.2826138950827,-0.001235543994262,3.4841749612486725,17.2758884053809,-0.0003892234523495
0.0006924437025963,19.6654131510958,-0.0010736186967216,3.9645472912609137,19.65876333842249,-0.0003382048058131
0.0007430205321921,21.999662251241,-0.000913037262755,4.435131909850186,21.99333579095646,-0.0002876121478277
0.0007788273922225,24.4768927668162,-0.0007993504821584,4.934541581790146,24.47073036806505,-0.0002517956292474
0.0008202256394002,26.983097166849,-0.0006679110473692,5.439792388836759,26.97742084915137,-0.000210387814175
0.0008685402726114,29.5901107821474,-0.0005145120869237,5.965366333680915,29.58531567359596,-0.0001620641826898
0.0009267895951633,32.2798617504489,-0.0003295704878214,6.5076201288904985,32.27651104500515,-0.0001038071162199
0.0009746740478063,34.9601812891412,-0.0001775373506799,7.047972547890866,34.95822641104187,-5.5918839233822094e-05
0.0010190038243704,37.6668825159396,-3.6790310089139945e-05,7.593643515213423,37.666446050967046,-1.1587566376271869e-05
0.0010686175013961,40.3840760837829,0.0001207331144675,8.141429738490633,40.38561173583975,3.802545480826276e-05
0.0011203754475249,43.0173851026609,0.0002850645934263,8.672304836696439,43.02124738089541,8.978009356059117e-05
0.0011658320226547,45.6715623155562,0.0004293892194637,9.20738696281613,45.67773896957018,0.0001352315548449
0.0012084730980866,48.3527648246466,0.00056477463396,9.747917388648755,48.361365900254405,0.0001778659553886
0.0012587578892388,50.9306079155076,0.0007244288458682,10.267610555766332,50.94222857740102,0.0002281405395957
0.0013145420523213,53.5430512599717,0.0009015435636552,10.794279134010294,53.558254848394334,0.0002839104223319
0.0013662777226079,56.082994637152,0.0010658043168151,11.306331718849842,56.10182093566671,0.0003356300689235
0.001407191930693,58.677798207542,0.0011957069274853,11.829444118640469,58.69989630196919,0.0003765297108725
0.0014585672403448,61.3047097952926,0.0013588235356298,12.35902949473099,61.33094673466734,0.0004278843611626
0.0015151657557767,63.8185587825239,0.001538523822126,12.86582145055682,63.84948362440758,0.0004844570638898
0.0015781999334221,66.2607263249046,0.0017386573361502,13.358162427100767,66.29701126913245,0.0005474587269319
0.001624032563603,68.7658737751422,0.0018841759369746,13.863200153068668,68.80668228054445,0.0005932652233728
0.0016686695075856,71.1291106096397,0.0020258982341193,14.339628698903365,71.17449654336522,0.0006378746986452
0.0017204304016538,73.5023682549026,0.0021902390727858,14.818077440188365,73.55307306085354,0.0006896012484357
0.0017775502771226,75.7778588760539,0.0023715946773993,15.276816349412464,75.83446182621931,0.000746680118516
0.001821772030446,77.9958383169015,0.0025119987442011,15.72396100468734,78.05754711939126,0.000790867888366
0.0018642622049612,80.2643790482572,0.0026469050482868,16.181298816128653,80.33129312387938,0.0008333235707959
0.001907400603101,82.5242086712962,0.0027838694623807,16.636880468133313,82.59656666324175,0.0008764251067813
0.0019564823391919,84.7053689437882,0.0029397039744693,17.0766023790677,84.78379688386472,0.0009254626428917
0.0020049508727734,86.9249809132322,0.0030935915685906,17.52407615210761,87.00967709844578,0.0009738851690164
0.0020489993184195,89.1497552803521,0.0032334453835169,17.972590664518982,89.24054610386483,0.0010178897692001
0.002093410372944,91.3027121123525,0.0033744504816322,18.406626761850266,91.39975037404126,0.0010622546570296
0.0021391974081914,93.4020387453884,0.0035198243185427,18.8298510110703,93.50558481385374,0.0011079920346394
0.0021868867602854,95.4528202617627,0.0036712380114412,19.24328856477136,95.56319192224908,0.0011556274419891
0.0022316345140665,97.5218549726009,0.0038133121296962,19.660405962476343,97.63898293243632,0.0012003225150665
0.0022844550268093,99.5575587235532,0.0039810172576546,20.07080383866833,99.68239033281569,0.0012530782725852
0.0023310148925673,101.649775464064,0.0041288448314362,20.492594733555304,101.78196322785658,0.001299578750562
0.0023756367213377,103.651807522368,0.0042705191377822,20.89620439650939,103.791223909042,0.0013441416344766
0.0024175749655707,105.719085863733,0.004403673063222,21.31296771012857,105.86571650646894,0.0013860226686151
0.002464301567048,107.817616127828,0.0045520300229124,21.736031411370128,107.97219534849344,0.0014326834621932
0.002510419979693,109.91064167683,0.0046984559830603,22.15798536204893,110.07329059399171,0.0014787347886808
0.0025598426190449,111.970529118597,0.0048553728630026,22.573258670309155,112.14176019530204,0.0015280831814132
0.0025977559703695,114.003451449408,0.0049757477534582,22.983095812200656,114.18211362812796,0.0015659379257255
0.0026417984498654,116.003493274687,0.0051155826258577,23.3863042441769,116.19039892972158,0.0016099105245949
0.0026892810121649,118.107710711184,0.0052663397611586,23.81051447937469,118.30361475307936,0.0016573155820801
0.002737156822544,120.150649288951,0.0054183454591122,24.222370896652524,120.35569424170193,0.0017051109706286
0.0027835859872119,122.226789946521,0.0055657580569328,24.64092085321863,122.4410528570463,0.0017514599617431
0.0028352999699061,124.284933902069,0.0057299499519869,25.05584267465711,124.50923199688629,0.0018030821162939
0.0028758819519308,126.318565540814,0.0058587977449153,25.465822813028105,126.55166000598926,0.0018435901711386
0.0029206979530545,128.354156765334,0.0060010885484831,25.876198003891336,128.5967598079528,0.0018883226255261
0.0029615021372768,130.364106874946,0.0061306418333889,26.28140394598912,130.6158283386247,0.0019290490016573
0.0030093789882731,132.336550820228,0.0062826508353021,26.67904864535797,132.59841675457503,0.0019768324432384
0.0030629965018306,134.299844992682,0.0064528864408472,27.07484875052469,134.57279669307923,0.0020303426369556
0.0031073770399913,136.264487358883,0.0065937946495074,27.470920651550813,136.5474794998798,0.0020746321780341
0.0031494209354085,138.250461240861,0.006727284017457,27.871292986157577,138.5433904119828,0.0021165880580907
0.0031955271646509,140.195164750481,0.0068736712953016,28.26334521369697,140.49867828738982,0.0021625957442728
0.003242691596336,142.143172283989,0.0070234183659018,28.656063532452187,142.4576072341644,0.0022096571811622
0.0032933045962628,144.108232555705,0.0071841146406694,29.052219683230128,144.4343081662072,0.0022601571920335
0.0033331800937934,146.059327363833,0.0073107193453291,29.445560396548736,146.39564193080136,0.0022999418750221
0.0033687056349843,148.01365420492,0.0074235129386102,29.83955268771188,148.35972704809515,0.0023353851753002
0.0034099730841685,149.93857540614,0.00755453708977,30.227616801877826,150.29533651766533,0.0023765555140347
0.0034570266723225,151.878296027931,0.007703932232159,30.618664479230887,152.24681889411525,0.0024234963077626
0.0034992255551092,153.831667923538,0.0078379136850067,31.01246425338526,154.2114220448625,0.0024655921594938
0.0035427609817683,155.768176463191,0.0079761386646494,31.402864374979305,156.15949254980833,0.002509019434789
0.0035850112310288,157.679847023358,0.0081102832060515,31.788257159908976,158.0826275635931,0.002551162922179
0.0036298040416123,159.564515058838,0.0082525003796541,32.16820623586174,159.97925717572062,0.0025958406065838
0.003678495270377,161.47400975936,0.008407095030982,32.553160367486974,161.90157742710193,0.0026444044253468
0.0037313851912847,163.329504132783,0.0085750205298639,32.92722803316905,163.77062345595502,0.0026971532774319
0.0037719968206467,165.158457908784,0.0087039624530883,33.295945114410856,165.61122421317705,0.0027376546983956
0.0038197762923094,166.975869303045,0.0088556622756174,33.66233525149387,167.4415958878404,0.0027853024100775
0.0038653150914593,168.848605955398,0.0090002479629183,34.03987896060824,169.32724511186782,0.0028307135152795
0.0039065315918307,170.671442229777,0.0091311103515975,34.407362753523046,171.16228310312076,0.0028718126639416
0.0039490261290482,172.492589720267,0.0092660305072631,34.77450608760583,172.99599809778664,0.0029141844421777
0.0039916242635837,174.407847038668,0.0094012795844133,35.16062196299547,174.92427441873923,0.0029566577165961
0.0040329637866265,176.312353495223,0.0095325325700742,35.544570464636955,176.8417088502465,0.0029978743439157
0.0040722445752303,178.168646915656,0.0096572490738912,35.918799218196256,178.71057415988363,0.0030370367831297
0.0041156081450749,180.006484400719,0.0097949284081478,36.28930725518495,180.5618074330678,0.0030802679215203
0.0041555865114985,181.834008880272,0.0099218597215428,36.65773619026284,182.4022392830172,0.0031201225391221
0.0042040632380847,183.706653131326,0.0100757733284539,37.03526127127533,184.2896410355402,0.0031684470804507
0.0042508035026321,185.52385989894,0.0102241736683919,37.40161015562631,186.1212860920856,0.0032150383999175
0.004293704412657,187.259836083837,0.010360384057721,37.75158295450154,187.87088610601475,0.0032578006890342
0.0043377134159822,189.008298756905,0.0105001126432785,38.10407302939205,189.63337227736545,0.0033016655910055
0.0043854614606345,190.806708666229,0.0106517126850496,38.466632467111765,191.44684039507703,0.0033492551151466
0.0044318774248278,192.678017131394,0.0107990833713633,38.84388825368903,193.333370193073,0.0033955148104836
0.0044862968918821,194.496150415757,0.0109718651792607,39.21042392381661,195.16827184575604,0.0034497483381277
0.0045349452564727,196.275939506241,0.0111263237368358,39.56922940445819,196.9637598667758,0.0034982279920897
0.0045852090112185,198.072959244277,0.0112859111581538,39.93150858364625,198.77703288864348,0.0035483149655839
0.0046335482003247,199.815173332968,0.0114393880835659,40.28273894392635,200.53509878579976,0.0035964817759311
0.0046880601138089,201.543158239598,0.0116124634088783,40.63110070110296,202.28029605073723,0.0036507965153644
0.0047439659771975,203.23938419692,0.0117899645251371,40.97305985409908,203.9940881748074,0.0037064970986281
0.004797896616482,204.886266608587,0.0119611943048654,41.30507134829114,205.6581357252181,0.0037602267706855
0.0048487385062422,206.550436731274,0.012122617304854,41.64056804502484,207.3390766993508,0.003810876559673
0.0049014301149558,208.205271755599,0.0122899131625197,41.97418278592876,209.01120079807308,0.0038633663716845
0.0049582237447317,209.852820261626,0.0124702329370582,42.3063285647438,210.6770450021492,0.0039199394098705
0.0050202123238454,211.46416899384,0.0126670466757442,42.63117646915815,212.3078308832549,0.0039816835669346
0.0050758658172205,213.107909270091,0.0128437465172101,42.962554508850346,213.9699892598477,0.0040371143699692
0.0051376464167057,214.677460161306,0.0130398999205756,43.27897596851929,215.5591523174341,0.0040986441638941
0.005199602603234,216.18126324164,0.013236610812803,43.582142669514624,217.0825253665376,0.0041603450302098
0.0052641843491733,217.623690513983,0.0134416578561603,43.872936007618975,218.54502065234016,0.0042246565839023
0.0053375837200675,219.017834027,0.0136747008587493,44.1539953398432,219.96114217284264,0.004297743850806
0.0054158014763226,220.382884964816,0.0139230422348593,44.4291896089069,221.34931022944755,0.0043756231358406
0.0054987797258197,221.732124504805,0.0141864981770126,44.70119630016869,222.72286541191448,0.0044582356844756
0.0055913460516485,222.933759014774,0.014480396261519,44.943445817378446,223.9505052102398,0.004550386000389
0.0056854919085417,224.090084212523,0.0147793093571549,45.17656097724464,225.13320127660108,0.0046441000392113
0.0057948896577607,225.14788246431,0.0151266472109252,45.3898131048049,226.220554145672,0.0047529849840608
0.0059141413878028,226.069349928152,0.0155052714538089,45.57558094551545,227.1733709165054,0.0048716642146306
0.006038582509908,226.926329002423,0.0159003720164929,45.74834792688847,228.06277405800583,0.0049954929085778
0.0061677049850335,227.628618318488,0.0163103358750164,45.889929453007184,228.79797240338263,0.0051239637090107
0.0063030342621882,228.220854977435,0.0167400063299826,46.009324363450894,229.4241364126968,0.0052585922745334
0.0064435499701799,228.721960787691,0.0171861437028562,46.1103472947985,229.9600233029969,0.0053983612389968
0.0065935589175309,229.103657005905,0.0176624221106956,46.18729725239046,230.3781532254774,0.0055475514363252
0.006738852281138,229.420960230848,0.0181237285401482,46.25126558253896,230.7305549409721,0.0056920305715082
0.0068932281091804,229.716127853797,0.0186138717941828,46.31077137532548,231.06287007519123,0.0058455184038473
0.0070513379446184,229.926204798457,0.0191158705216984,46.35312288736894,231.3105322190784,0.0060026943486038
0.0072088015803668,230.12250111382,0.0196158175651996,46.39269622454611,231.54424631051168,0.0061592033613251
0.0073758245391829,230.245852823235,0.0201461154594407,46.41756392916418,231.7068164563167,0.0063251869773087
0.007542037532341,230.373001432134,0.0206738417127177,46.443197088718215,231.873062838903,0.0064903383218974
0.0077140163058927,230.511159946619,0.0212198743187443,46.47104984523838,232.05176399170097,0.0066611899134957
0.007881539612046,230.642758032246,0.0217517608157811,46.4975800193008,232.22287964062693,0.0068275871786862
0.0080567277045025,230.782947949122,0.0223079830093305,46.52584230654299,232.4044604157967,0.0070015680976133
0.0082335271021627,230.898447005988,0.0228693210969016,46.54912691640719,232.56159369113945,0.0071771185358012
0.0084282330530894,231.002883055442,0.0234875124910939,46.57018122397711,232.7117596227628,0.0073704133791629
0.0086080921134114,231.072261012442,0.0240585650076162,46.58416782010831,232.8232112527648,0.0075489357410566
0.0087969204306621,231.142766658288,0.0246580949148872,46.59838175831087,232.93789745487047,0.0077363264135583
0.0089766727176488,231.218604751259,0.02522880842607,46.613670717853815,233.0558866044284,0.0079146775379812
0.0091721228310866,231.3151004216,0.025849362536235,46.63312424499456,233.1983595998373,0.0081085680344055
0.0093520525668169,231.385085523752,0.0264206394471787,46.6472332415884,233.31054754519377,0.0082870287717011
0.0095376210304076,231.456373244939,0.0270098193190792,46.6616048461797,233.4253794879611,0.0084710488457403
0.0097109256248137,231.508409882002,0.0275600614063185,46.67209543221161,233.51798027331765,0.0086428768057253
0.0098926603736101,231.619694434952,0.0281370692337471,46.69453039808633,233.67232416037427,0.0088230313828842
0.0100734769078529,231.72075244123,0.028711161729968,46.71490369215197,233.8161766930505,0.0090022435249739
0.010257358057155,231.811343096491,0.0292949843790022,46.73316676825259,233.95021228543183,0.0091844601575231
0.0104369784920117,231.872441193495,0.0298652792596722,46.74548414460859,234.0535231490433,0.0093624225921374
0.0106269728954792,231.910680071129,0.0304685114906815,46.75319310233961,234.13618344768304,0.0095506287768639
0.0108099516557452,231.991906866518,0.031049469054526,46.76956842429003,234.2606393179045,0.0097318518716745
0.0109947932190202,232.036957341006,0.0316363410179242,46.778650599946815,234.34902043114823,0.0099148865571147