File: example/data/02 processed data/test_ID_085.csv
Strain,Stress_MPa,Displacement(mm),Force(kN),True Stress (MPa),True Strain
0.0002542523812495404,14.3557569931856,0.0008072513104672907,5.788241219652434,14.359406978585756,0.00025422006459035475
0.000330144783041487,19.099509732496,0.001048209686156721,7.700922324142387,19.105815335992833,0.000330090297244417
0.0004162445494326969,23.8712279569274,0.0013215764444488125,9.624879112233128,23.881164225452736,0.00041615794370215197
0.0005063804997177969,29.3110143589707,0.0016077580866040051,11.818200989536987,29.32585688506903,0.0005062523323784062
0.000606835877236597,34.9092993282925,0.0019267039102261953,14.075429489167536,34.9304835435741,0.0006066518268008679
0.0007042901366771969,40.5483578488059,0.0022361211839501,16.34909788463854,40.57691565729727,0.0007040422407657903
0.0008051124819191969,46.2811338416177,0.00255623213009345,18.66055316494026,46.318395360150966,0.0008047885527196423
0.0009151488210762969,51.9118597083381,0.0029055975069172423,20.93086183440192,51.95936678555007,0.0009147303276970114
0.0010139347257235969,57.6555192355923,0.00321924275417242,23.246705355790816,57.7139781686749,0.0010134210411087508
0.0011139518269270969,63.4035841237732,0.0035367970504935325,25.564325118705355,63.47421266214161,0.001113331842969631
0.001219342414984297,69.1697586385156,0.0038714121675751424,27.889246683049493,69.25410025905776,0.0012185996207740785
0.0013244706488197968,74.9457148953438,0.004205194310002855,30.21811224580262,75.0449782949775,0.001323594311273566
0.001437772482681397,80.7421946615389,0.004564927632513435,32.55525288753249,80.85828356721456,0.0014367398774743803
0.0015437985995106968,86.5700136928203,0.004901560553446462,34.90502952094515,86.70366035871889,0.001542608167486704
0.001632337985916297,92.3428676366728,0.005182673105284243,37.23264423110648,92.49360240724458,0.0016310071702965191
0.001724464131740497,98.0689088090733,0.005475173618276078,39.54138403181836,98.23802512475348,0.0017229789506521395
0.0018084209364675969,103.659231786993,0.00574173647328462,41.79540225651558,103.84669131201474,0.001806787712067446
0.0019097073745953969,109.091528103992,0.006063320914340384,43.98570413152957,109.29986099971809,0.0019078862017034672
0.002011621744544597,114.54535670502,0.006386899038929095,46.18468782346407,114.77577863530442,0.002009601142860026
0.002102115754747197,119.865849737739,0.0066742175213223495,48.32991061425637,120.11782162892885,0.0020999094008904194
0.002197187558344897,125.16969034643,0.0069760704977450474,50.46841914768058,125.44471163274106,0.0021947772716838093
0.002281754148441497,130.376556695175,0.007244569421301752,52.56782765949456,130.67404394427373,0.0022791549005899596
0.0023756917051858967,135.481080869154,0.0075428211639652215,54.6259718064429,135.80294214918445,0.002372874211096017
0.002464176247986197,140.46436748875,0.007823759587356175,56.635232971464006,140.8104964468042,0.0024611451441239078
0.002546689508373997,145.384787014086,0.00808573918908744,58.61914612407947,145.75503692585193,0.0025434521897798592
0.002638351658899597,150.259633646471,0.00837676651700622,60.58468428625711,150.65607140016783,0.002634877318840561
0.0027236477198351967,155.089957580008,0.008647581510476749,62.53227089625923,155.5123679893401,0.0027199453125626902
0.002816342790323197,159.83458779371,0.008941888359276149,64.44530579842387,160.28473678268708,0.0028123843274840163
0.002913928760891397,164.528068453978,0.009251723815830185,66.33771720064394,165.00749152461995,0.002909691499868499
0.002998884654807897,169.108995814781,0.009521458779015073,68.1847471125197,169.61613418731991,0.0029943969700155994
0.003094156448591197,173.649553447944,0.00982394672427705,70.01549995021102,174.18685233353992,0.0030893793979516813
0.0031901163099474967,178.22204435028,0.010128619284083302,71.85912828203288,178.790593400754,0.003185038684855814
0.003284720622620997,182.771452876393,0.010428987976821664,73.69344979976165,183.37180603688248,0.0032793377121869798
0.0033697172904378968,187.313924542285,0.010698852397140322,75.52497437544932,187.94511951255492,0.003364052515355727
0.0034555713604917967,191.827499889923,0.010971439069561453,77.34484795561696,192.49037350469735,0.0034496145925248813
0.003554694334478097,196.242902070433,0.011286154511967957,79.12513811479859,196.94048560260433,0.0035483913409663443
0.003648611474528197,200.579256142876,0.011584341431627026,80.87355607680762,201.31109191839124,0.00364197143805642
0.003752929494434797,204.891640874083,0.011915551144830479,82.61230960043028,205.66058475628247,0.003745904824448127
0.003868275845600797,209.116213572297,0.01228177580978253,84.31565731235015,209.92513277018222,0.0038608133051776274
0.003980767726681296,213.212047860109,0.012638937532213115,85.96709769719595,214.06079549917015,0.003972865435349708
0.0040995821002489975,217.124232745035,0.013016173168290566,87.5444906427981,218.01435136312682,0.004091201709808692
0.004232032318408498,220.918355576771,0.013436702610946979,89.07428096855406,221.85328919730154,0.004223102455084575
0.004392525710502497,224.308308105435,0.013946269130845425,90.44110982811141,225.29358811586744,0.004382906726912309
0.004598839986182896,227.489961061906,0.014601316956130695,91.7239523001605,228.5361509912927,0.004588297630953612
0.0048580739033899974,230.284981119797,0.01542438464326324,92.85090438750215,231.40372257691777,0.0048463115419297
0.0051590417477145965,232.645504017195,0.016379957548993844,93.80266721973304,233.84573188483782,0.00514577948598867
0.0055008311071089964,234.323476720503,0.017465138765071064,94.47922581370682,235.61245059037307,0.005485756791251428
0.005860697300313297,235.480543465951,0.018607713928494717,94.94575512547145,236.8606236513182,0.005843590220957251
0.0062309014402315965,236.113218426622,0.019783112072735316,95.200849669614,237.58441661937414,0.0062115696353411895
0.006617908510389396,236.535386293299,0.021011859520486332,95.37106775345816,238.1007558392577,0.00659610629106375
0.006997712134895896,236.747126415902,0.02221773602829447,95.45644137089168,238.40381465532428,0.006973341772469817
0.007383103851483396,236.936115517815,0.023441354728459783,95.53264177678302,238.68543946485008,0.007355982153306617
0.007769538062228297,237.090854150458,0.02466828334757484,95.59503239346466,238.9329405659862,0.007739510633923133
0.008143617458546097,237.254564349386,0.025855985430883858,95.66104034567243,239.1866747617414,0.008110637137648787
0.008526539929578197,237.460960835875,0.027071764276410774,95.7442594090248,239.4856812001581,0.008490394307388429
0.008894831946477397,237.600573274093,0.028241091430065732,95.8005511441143,239.71399044375275,0.00885550595548015
0.009264245701103197,237.708059733904,0.02941398010100265,95.8438896847101,239.91024560441141,0.009221595787389856
0.009626491814752697,237.868894738595,0.03056411151183981,95.90873835860151,240.15873770678033,0.009580452372152442
0.009980388100027198,238.032054113364,0.031687732217586355,95.97452421850838,240.40770639366204,0.009930912941896223
0.010336760732117598,238.244689363235,0.03281921532447337,96.06025875125636,240.70736771288045,0.01028370174635964
0.010701047756337498,238.416765057027,0.03397582662637155,96.1296396709933,240.9680742458137,0.010644196761974747
0.011059434322771297,238.575654612312,0.03511370397479887,96.1937039396842,241.21416639550904,0.010998725968935119
0.011416321494427298,238.758063176432,0.03624682074480667,96.26725107273738,241.48380198504094,0.011351647060161002
0.011767181529875097,238.92014647795,0.03736080135735343,96.33260305990943,241.73156321270037,0.011698486621120677
0.012113106667421998,239.100200999795,0.03845911366906484,96.40520104311734,241.99644723870756,0.012040330101620032
0.012460046184895898,239.262748781619,0.03956064663704447,96.47074030874877,242.2439736817631,0.012383058661841265
0.012813879935550998,239.435355934221,0.040684068795374416,96.5403355126779,242.50345183748806,0.012732476831592827
0.013155360251821598,239.644721560899,0.04176826879953357,96.62475173335449,242.7973342054801,0.013069579994593124
0.013506870456756297,239.888575098437,0.04288431370020124,96.72307347968979,243.12871900634744,0.013416465827992803
0.013851013824722697,240.077251634008,0.04397696889349456,96.79914785883203,243.4025649653921,0.013755965206903864
0.014192386160111497,240.243302207435,0.045060826058354,96.86609945003778,243.65292792474327,0.01409261711348074
0.014539236796966197,240.409477887422,0.046162076830367674,96.93310148420856,243.90484821466222,0.014434555530873432
0.014885625555282698,240.528750450999,0.04726186113802256,96.9811921818428,244.1091713654926,0.01477592196242377
0.015217877474056597,240.690419942206,0.04831676098012969,97.04637732069747,244.35321726206573,0.015103247068010311
0.015561427746827597,240.878737898724,0.04940753309617762,97.12230712076553,244.62715497428204,0.015441590358357267
0.015901873467662395,241.069773886065,0.0504884482598281,97.19933283086141,244.9032349272792,0.015776763259406797
0.016249390241148794,241.281914679348,0.05159181401564742,97.28486799871312,245.20259866910428,0.016118781870993512
0.016602736224345195,241.460433609005,0.05271368751229599,97.35684683115082,245.46933749683134,0.016466417571746078
0.016948849386888197,241.626334509087,0.05381259680337002,97.42373807406388,245.72162286058736,0.016806820213443454
0.017279815272301095,241.819880901896,0.05486341348955597,97.50177597964446,245.9984837730506,0.017132217150457596
0.017606283579473594,241.960546687088,0.05589995036482866,97.55849242423389,246.22057268710535,0.017453088485868375
0.017922939565190796,242.103587160258,0.056905333119480775,97.61616634301603,246.4427951214472,0.017764217390008847
0.018244689688330696,242.185510734637,0.057926889760449955,97.64919792820565,246.6041102250003,0.018080252397338556
0.018578958070829595,242.306678285682,0.05898819187488396,97.69805268478699,246.80848390183368,0.018408477558969648
0.018913168719191294,242.477737586708,0.060049310683432354,97.76702379496066,247.0637599483332,0.018736538361722937
0.019247130449314497,242.710617132817,0.06110963917657352,97.86092082795182,247.38210004220593,0.01906424735816276
0.019575035829370795,242.939694364583,0.06215073875825227,97.95328476779987,247.69524758614608,0.019385908941312983
0.019904473110258496,243.094225211827,0.06319670212507073,98.01559160540864,247.93288768081493,0.019708969096915382
0.020234755043203597,243.279659283707,0.06424534726217142,98.09035862319067,248.20236359630684,0.020032752818411236
0.020566783798243296,243.452068477625,0.06529953855942246,98.15987401017841,248.45909453523944,0.020358143358990447
0.020909182032536295,243.578822851961,0.06638665295330273,98.21098137391067,248.67185679824357,0.020693585209136542
0.021247328880933995,243.766142196625,0.06746026919696543,98.28650853367921,248.94552158991323,0.02102475164979
0.021566992029207296,243.913962502165,0.06847519969273316,98.34610968087293,249.17445298726153,0.02133771514099939
0.021904604658153994,244.080543894224,0.06954711978963893,98.41327529815113,249.42703171297416,0.021668145603126535
0.022234235612937494,244.222197504291,0.07059369807107654,98.47039003373013,249.65229138551075,0.021990658879765854
0.022581342257976197,244.335630358721,0.07169576166907442,98.5161261606363,249.85305685366964,0.022330158101239936
0.022909208873221596,244.459845631661,0.07273673817247857,98.56620975868573,250.06022729635225,0.022650733151437136
0.023232813921547895,244.636541961847,0.07376418420091456,98.6374537190167,250.32013721965754,0.02296704066813849
0.023556106536469997,244.832296516634,0.07479063825329224,98.71638195550682,250.59959217694842,0.023282942923011318
0.023887038580795397,244.926211755563,0.07584134749402538,98.75424857984301,250.7767736252162,0.02360620664634986
0.024220509053276294,245.013948695813,0.07690011624415223,98.78962411415182,250.94831125837894,0.023931844307138593
0.024549935269076697,245.114148566794,0.07794604447931851,98.83002470213134,251.13168504764366,0.024253428620844782
0.024868966875338197,245.256589658392,0.07895896982919877,98.88745695026365,251.35586766256495,0.024564767223708792
0.025195493666980796,245.466622125276,0.07999569239266402,98.97214204091128,251.65127484848853,0.024883319933331798
0.025510937873183197,245.58520609864,0.08099722774735664,99.01995509897165,251.8503150339953,0.02519096436633197
0.025835835557520895,245.747048613642,0.08202877789512884,99.08521000102046,252.09612895037017,0.025507729616617833
0.026162119323436095,245.85355662717,0.0830647288519096,99.12815403207495,252.28560671174117,0.025825745302636222
0.026490894909354294,245.967790310819,0.08410859133719988,99.17421305332222,252.483697195029,0.026146087402786747
0.026826518015610396,246.179744428536,0.085174194699563,99.25967295358572,252.7838897775265,0.026472995563339475
0.027155343684476797,246.3442251123,0.08621821619821382,99.32599156527937,253.0337872099106,0.026793179181127905
0.027485953098753894,246.478021655949,0.08726790108854361,99.37993833167864,253.25270499905807,0.027114996344686473
0.027812706899904196,246.57882014029,0.08830534440719581,99.42058028056492,253.43684459257605,0.027432958702432893
0.028141131798923195,246.655735803295,0.08934809346158114,99.45159267588853,253.59690737349592,0.027752445352017024
0.028479643939511395,246.787642256829,0.09042286950794867,99.50477735795346,253.816066436975,0.02808163792620324
0.028813191533233397,246.948190910419,0.09148188311801603,99.56951057508093,254.0635564339064,0.028405896671378866
0.029148792421703196,247.122669363944,0.09254741593890764,99.63986028754222,254.32599675593076,0.028732045447751868
0.029492724402207696,247.254839650359,0.09363939997700943,99.69315134702477,254.54705849327908,0.029066180342918115
0.029831438913308094,247.350382730959,0.0947148185497532,99.73167431712267,254.729200563581,0.029395137308692323
0.030162095288651995,247.441378363383,0.09576465254147008,99.76836375611603,254.90472879593477,0.029716163926197556
0.030492867286855296,247.509861841101,0.09681485363576556,99.79597629433192,255.05714721040962,0.030037199720206253
0.030808016319441196,247.635169991935,0.0978154518142258,99.84650054074818,255.26431835031414,0.03034297656001438
0.031138513578357997,247.738511082639,0.09886478061128663,99.88816766852005,255.45272007386794,0.030663544777429115
0.031464025847506995,247.851570121808,0.0998982820658347,99.93375307311298,255.64997833046576,0.03097917734902676
0.0317917429026682,247.969465184868,0.10093878371597154,99.98128836253878,255.85284666973746,0.03129684718219114
0.0321203298267128,248.085202243806,0.10198204719981313,100.02795354470258,256.0537807650038,0.03161525893156981
0.0324424712848173,248.187664755814,0.10300484632929492,100.0692664295442,256.2394859429004,0.03192732641679758
0.0327680432663161,248.261383327662,0.1040385373705536,100.09898975771331,256.3964230778983,0.032242618230297344
0.0330930679342551,248.32630143649,0.10507049069125994,100.12516473919277,256.5441805997901,0.03255728088487635
0.0334266923577856,248.382521334545,0.10612974823596928,100.14783260208856,256.68512746224593,0.032880166184924675
0.0337549887126287,248.514634309129,0.10717208916259612,100.20110055344081,256.90324298515674,0.03319779318463115
0.034087470300470796,248.639232759917,0.10822771820399477,100.25133864879854,257.11471522215254,0.03351936660939376
0.0344194626908246,248.819660008724,0.10928179404336809,100.32408691551751,257.3838990131379,0.03384036373820139
0.034745367076251,248.951943142312,0.11031654046709691,100.37742347498019,257.6018697911376,0.03415537430036926
0.0350793247680794,249.097874510056,0.11137685613865209,100.43626300245458,257.83605974903253,0.03447806606846172
0.0354073665672724,249.178993302124,0.11241838885108986,100.46897009941641,258.00176525883626,0.03479494016701137
0.0357433007561384,249.277302346788,0.11348497990073941,100.50860830622493,258.18729593624806,0.035119333942038686
0.0360861237958538,249.364598637313,0.1145734430518358,100.54380617056461,258.36320041404247,0.03545027145917382
0.0364300320606888,249.455984105424,0.11566535179268694,100.58065279130695,258.54367360411527,0.035782146573410785
0.0367724482859184,249.553399623262,0.11675252330779091,100.61993072809925,258.73008910548356,0.036112472464479566
0.0371050093089342,249.667508360396,0.11780840455586608,100.66593937091167,258.9314235822469,0.036433186713673474
0.0374330095984801,249.76050310505,0.11884980547517432,100.70343485195616,259.1097904151025,0.03674940197633874
0.0377629267188067,249.823812769566,0.11989729233221126,100.72896130868901,259.257891103796,0.03706736435987312
0.0380872042096563,249.859410731064,0.12092687336565874,100.74331440676501,259.37585713128243,0.03737979297758104
0.0384258586829865,249.948430265615,0.12200210131848213,100.77920708309597,259.55291332503583,0.037705969087314606
0.0387636341695043,250.040337349816,0.12307453848817614,100.81626401944582,259.7328095144637,0.03803119265565771
0.039102229420056596,250.129528467765,0.12414957840867968,100.85222587820284,259.9101506746421,0.0383570994040023
0.0394359053534645,250.20538692673,0.12520899949724978,100.88281200885754,260.0724628844995,0.03867816730330316
0.0397658589112314,250.287497208685,0.12625660204315967,100.9159188745418,260.24039450993075,0.0389955521441661
0.040096600422501696,250.386147371578,0.12730670634144287,100.95569462022026,260.4257806740658,0.03931359386137096
0.0404412444078502,250.445089109508,0.12840095099492438,100.97945992895362,260.5734001689314,0.039644896643829114
0.0407754602750041,250.48327890697,0.12946208637313802,100.99485805529032,260.69684989559397,0.039966070185512605
0.0411063643036998,250.546467754111,0.13051270666424686,101.02033579845757,260.8455221326167,0.04028395953694029
0.0414405330780127,250.644400102717,0.13157369252269033,101.0598221214155,261.0312376559923,0.04060488270808348
0.041765041473149,250.697301019944,0.1326040066772481,101.08115177124142,261.16768419424847,0.040916429875319626
0.0420990181460271,250.735427647956,0.13366438261363603,101.09652442765586,261.29114296635913,0.04123696582793697
0.0424358236381397,250.732051979469,0.13473374005109354,101.09516335812191,261.3720731176986,0.04156011273658282
0.0427803055455179,250.855169109061,0.13582747010701932,101.1448041847734,261.58682989121917,0.04189051677066903
0.0431291773188258,251.020901418572,0.1369351379872719,101.21162745196824,261.8472263865851,0.04222502004554934
0.043470969050398996,251.160314793801,0.1380203267350168,101.26783892486057,262.07849706489077,0.0425526264010121
0.0438186136663319,251.242580942812,0.13912409839060377,101.3010086361418,262.2516825336772,0.04288573266669376
0.0441597864176833,251.262527444788,0.14020732187614446,101.30905106573852,262.3582269915171,0.04321252987338323
0.0444980162071549,251.295786936313,0.1412812014577168,101.3224612927214,262.4779509361948,0.043536402737576765
0.0448397867350349,251.316793635155,0.1423663228837358,101.33093119369448,262.58578506468814,0.04386355953380872
0.0451777626671592,251.358394502883,0.14343939646823045,101.34770466356242,262.7142043941324,0.04418697876554384
0.0455258305894884,251.354004842293,0.14454451212162567,101.34593475241255,262.79710468473263,0.04451994602753884
0.0458761248347623,251.484815233053,0.1456566963503703,101.39867750196697,263.02196401073166,0.044854931129413834
0.0462216424019199,251.55458524216,0.14675371462609568,101.42680876963891,263.1818513257864,0.04518523841783029
0.0465710638422716,251.616678842753,0.14786312769921234,101.451844909398,263.3347352569192,0.04551916680219062
0.0469214353895111,251.632931908462,0.14897555736169774,101.45839814549188,263.43991026487816,0.045853891240553196
0.0472663813744222,251.614745604719,0.15007076086379048,101.45106542782271,263.50766412989987,0.0461833229995096
0.047611883855097396,251.643928130033,0.15116773123993424,101.46283182202932,263.62516960900064,0.04651317747319657
0.047958399639501596,251.695258181328,0.15226791885541757,101.48352809871145,263.7661599605557,0.046843890110507526
0.0483005924741374,251.713339400042,0.15335438110538624,101.49081844609692,263.87124282670766,0.04717036965236043
0.0486501084135265,251.738614493975,0.15446409421294663,101.50100936397072,263.98572538097784,0.0475037260278612
0.0489847694422285,251.769839007363,0.15552664297907548,101.51359908776877,264.1027265236457,0.04782281018790682
0.0493321256172382,251.828416132573,0.1566294988347313,101.53721738465343,264.2516471912152,0.04815389094982642
0.0496712145884705,251.885005108581,0.15770610631839382,101.56003405977987,264.39643924894733,0.048476986170960315
0.0500194866351053,251.894794148683,0.1588118700664593,101.563981000749,264.49444243805567,0.0488087226973218
0.050365111406105396,251.935263231769,0.15990922871438462,101.58029813504928,264.62401083156357,0.049137828875725494
0.0507020158507391,251.968146027237,0.16097890032609663,101.59355647818197,264.74343896099134,0.049458527289546375
0.0510506413159475,252.004724339545,0.1620857861781333,101.60830485370454,264.8697271317273,0.04979027466925531
0.0513881752704351,251.990829605296,0.16315745648363142,101.60270249685534,264.9401785235953,0.0501113626882974
0.0517320530050544,251.987125206001,0.16424926829104772,101.60120888305961,265.02293652374914,0.05043837940665773
0.0520767056215227,252.020816768881,0.16534354034833457,101.61479332121282,265.14523065424976,0.05076602574631513
0.0524266239498782,252.068059563121,0.16645453104086327,101.6338416158504,265.28313693161226,0.051098568182017905
0.052767466710472,252.149217085888,0.1675367068057486,101.66656432903005,265.4544925045392,0.051422379430666305
0.053125462674821496,252.188038161732,0.16867334399255823,101.68221698681035,265.58564437012956,0.051762373893635
0.053476336901231,252.243814241188,0.16978736966140842,101.70470590204701,265.7328894328013,0.052095492596680656
0.0538345092795449,252.296469906667,0.17092456696255504,101.72593666636814,265.8787265570539,0.05243542572274234
0.054191466121501296,252.330372263776,0.17205790493576661,101.73960609675449,266.0045250837342,0.052774090283363016
0.0545532661903882,252.361702806453,0.17320662015448252,101.75223857156185,266.1288579559131,0.053117232880846015
0.0549071057080557,252.379504331905,0.17433006062307685,101.7594161466241,266.2369324548036,0.05345271158971371
0.0552622448261529,252.393867163461,0.17545762732303544,101.76520724030749,266.3417188432677,0.05378930933373865
0.0556202743009794,252.376359143086,0.1765943709056096,101.75814800649229,266.41360146570696,0.05412853188640631
0.0559682706207984,252.348282987393,0.1776992592210349,101.74682770051686,266.4717799803252,0.05445813807204925
0.056330142685655796,252.318318550086,0.17884820302695714,101.73474603939466,266.53144543621704,0.05480077154288642
0.0566900407756764,252.290136701197,0.17999087946277256,101.72338311792264,266.59247483808883,0.05514141958431806
0.0570332648094248,252.290121304944,0.18108061576992374,101.72337691015342,266.67905060213076,0.05546617735735118
0.0573900725199531,252.314765904712,0.1822134802508511,101.73331361277988,266.79512861783843,0.05580367619934374
0.0577414458756188,252.318438871324,0.18332909065508968,101.73479455291783,266.88767035283314,0.056135923490674644
0.058099226316817,252.342115667747,0.18446504355589396,101.74434103723559,267.00299735519184,0.05647411572727401
0.0584631800269005,252.322323928523,0.18562059658540908,101.73636100798046,267.0738893771621,0.0568180259399659
0.0588116831748242,252.307116463648,0.18672709408006682,101.73022935814286,267.1457226598615,0.05714722566469519
0.0591718011950403,252.287982826216,0.18787046879425295,101.72251467553029,267.2163171899066,0.057487283107393934
0.0595290948408696,252.271556256578,0.18900487611976097,101.71589148265227,267.2890536546296,0.057824559265519555
0.0598913115401905,252.30060019961,0.19015491414010482,101.72760200048275,267.4112140479419,0.05816636658393256
0.0602564505274699,252.324707002818,0.1913142304247169,101.73732186353622,267.52889822719163,0.058510813322431035
0.0606189018283674,252.355458457529,0.1924650133050665,101.7497208500757,267.6529692196186,0.05885260738781396
0.0609835179785735,252.334768742249,0.19362266958197086,101.74137875687481,267.72303064846113,0.05919632508948316
0.0613424696030231,252.318577117512,0.19476234098959833,101.73485029378084,267.796421764621,0.05953458757128146
0.0617042863278537,252.292830101216,0.19591110909093548,101.7244690968103,267.86037912824594,0.05987543425995905
0.0620786799482747,252.319546841387,0.19709980883577216,101.73524128644723,267.98321123444714,0.060228006655768225
0.0624459839328494,252.333330296897,0.19826599898679684,101.74079877570888,268.0905333863394,0.06057378187267104
0.0628257579642714,252.33498225723,0.19947178153656167,101.74146484611515,268.1881187784415,0.06093117055664728
0.0631972446798713,252.328845714086,0.20065125185859137,101.73899059191946,268.27533351646855,0.06128063687843063
0.0635675202441991,252.309482221159,0.20182687677533212,101.73118323157131,268.34817034005596,0.06162884235387959
0.06393611477136919,252.276590991362,0.20299716439909718,101.71792148771716,268.4061760671155,0.06197534660871753
0.06430850536556619,252.228160076918,0.20417950453567266,101.69839414301335,268.4485760625713,0.0623252975443137
0.0646682368686775,252.175436968808,0.20532165205805103,101.67713618582339,268.48317785916913,0.06266323595331427
0.0650438149833042,252.144269943301,0.20651411257199082,101.66456964113897,268.54469518659334,0.06301593914452128
0.0654068955886164,252.120502673885,0.20766689349385706,101.65498667811043,268.6109220680253,0.06335678778000087
0.0657692827080553,252.086015691281,0.20881747259807554,101.6410815267245,268.6655321240282,0.06369686958705376
0.0661404410310177,252.045528523199,0.20999590027348117,101.62475710055384,268.71593093961934,0.06404506287364503
0.06650799292030159,252.019590702195,0.21116287752195753,101.61429897112502,268.78090785639387,0.06438975343498801
0.06688215216245179,251.990477379998,0.21235083311578443,101.60256047961519,268.8441428316159,0.06474051838705164
0.0672586637815249,252.00632167679,0.21354625750634154,101.60894890008174,268.955930137268,0.06509336447871202
0.06763674778061549,251.994959258062,0.21474667420345417,101.6043675728506,269.03907875938603,0.06544755888186227
0.0680199465341058,252.051057106402,0.2159633302457859,101.62698622530128,269.1955565346443,0.0658064168936605
0.06840244609839469,252.053076064114,0.21717776636240313,101.62780026905077,269.29412301352414,0.06616449174786061
0.0687772000474063,252.065057549852,0.21836761015051498,101.63263120410033,269.40138643791914,0.06651519128173301
0.06916705378797999,252.062498891054,0.21960539577683647,101.63159955287298,269.4969193097842,0.0668798909170911
0.0695497419787627,252.02075707239,0.22082043078257155,101.61476925158766,269.5487357000672,0.06723775802284755
0.0699341221743651,252.010820727597,0.22204083790360915,101.61076291736713,269.63497625362277,0.06759707851708281
0.07031892869904319,251.968821429808,0.2232625986194621,101.5938288004986,269.6869990183126,0.06795666826621785
0.07068672723754839,251.911328332048,0.22443035897921612,101.57064758348176,269.71811568590397,0.0683002437641186
0.07107408057612309,251.809943957862,0.2256602058291908,101.52976940380996,269.70710420459216,0.06866195861237333
0.07145916325808929,251.743818171427,0.22688284334443348,101.50310748671937,269.7332207733537,0.06902142345355677
0.07184420695622729,251.71425816584,0.22810535708602162,101.4911888924667,269.79846942333984,0.06938072275540211
0.07224052764759349,251.745557595922,0.22936367528110932,101.50380882267575,269.93178950958907,0.06975041028638782
0.07262119911570339,251.739003273371,0.23057230719235824,101.5011661198232,270.02059155527513,0.07010537160380687
0.07300337780931149,251.687114619769,0.23178572454456395,101.48024461469086,270.0611241380915,0.07046161164855665
0.07338643676966729,251.625220082165,0.23300193674369363,101.45528873712892,270.0910983853784,0.07081854491559017
0.07377051598941119,251.549803041135,0.2342213882663805,101.42488058618562,270.10676180851425,0.07117630099238445
0.07415972975561629,251.52782010462,0.23545714197408169,101.41601706618277,270.1810552695979,0.07153870919557084
0.0745407101861207,251.522262777477,0.2366667548409332,101.41377635187874,270.2709108725302,0.07189332394541204
0.0749344722114622,251.53473049353,0.23791694927139245,101.4188033349913,270.38335276591505,0.0722597036393679
0.0753300540141524,251.516580071699,0.23917292149493385,101.41148508490903,270.46333763395495,0.07262764144639418
0.0757408700887776,251.516083710585,0.24047726253186885,101.41128495210788,270.5661307321465,0.07300960568106142
0.0761445679474353,251.493009960746,0.24175900323310703,101.4019816161728,270.64283654600706,0.07338480954299384
0.07653220733676169,251.47883982242,0.24298975829421837,101.39626821639975,270.72507053251775,0.07374495594115921
0.07694054800044739,251.455044145157,0.24428623990142045,101.3866737993273,270.8021330391621,0.07412419516540077
0.07734773128385589,251.402292117058,0.24557904682624243,101.3654041815978,270.84768905187366,0.07450221633570825
0.0777538822757672,251.349982179082,0.24686857622556083,101.34431281460586,270.8934191034505,0.074879136842996
0.0781711931279963,251.277456176666,0.24819353818138823,101.31507033043174,270.92011473216377,0.07526626611961304
0.07857304829765979,251.23220932578,0.24946942834506983,101.29682680015449,270.9722898430623,0.07563891593742211
0.07898491218628959,251.190309415446,0.25077709619146943,101.27993275630783,271.0305539466719,0.07602070303299578
0.07939466014301,251.152826309199,0.25207804595405675,101.26481956786904,271.09301959797426,0.07640038412977396
0.0798092951671298,251.101305773285,0.2533945121556371,101.24404648778851,271.14152400259684,0.07678444699534705
0.08022576839112859,251.054280447117,0.25471681464183327,101.22508587627757,271.19530300386884,0.07717006409590779
0.0806261821395886,251.016003185495,0.2559881282931938,101.2096524843916,271.25446517828027,0.07754067139544521
0.0810255666811674,250.982763219364,0.25725617421270647,101.19625013004756,271.3187838364182,0.07791018933129326
0.0814199013994254,250.882031569485,0.2585081869431756,101.15563512881636,271.30882184276004,0.0782749011619033
0.08181518087757439,250.733913949816,0.25976319928629865,101.09591410456582,271.2477544717624,0.07864035333655298
0.08222048767119619,250.626060956754,0.2610500483560479,101.05242777776323,271.2326579117293,0.07901493754905146
0.08262792825250559,250.573435459608,0.26234367220170524,101.03120917731394,271.2777993067483,0.07939135243623072
0.08303520527366169,250.602232566454,0.26363677674387587,101.04282017079426,271.4110403896474,0.07976747466840291
0.08345767996535629,250.637822429716,0.2649781338900062,101.05717000366151,271.55547360126906,0.08015748259312613
0.08388131385755969,250.663868168531,0.266323171497752,101.0676716455517,271.6898827671255,0.08054840796179775
0.0843151415790068,250.673923570211,0.26770057451334656,101.07172598350908,271.8095309261985,0.08094858178013317
0.08474793106061229,250.643326414124,0.26907468111744404,101.0593892101748,271.8848297618707,0.08134763839845648
0.08516905985239749,250.624460594673,0.270411765031362,101.05178251177215,271.96991027953555,0.0817357903866073
0.08560068144872489,250.580527434679,0.27178216359970153,101.03406866166257,272.03039134086845,0.08213345725454207
0.08603899115340219,250.519892156929,0.27317379691205196,101.00962051767378,272.0743709419703,0.08253712432340159
0.08647139427199399,250.440224981853,0.2745466768135809,100.97749871268311,272.09614041782567,0.08293519204008755
0.08690928467889009,250.372894238564,0.275936978855476,100.95035095698901,272.132623379821,0.08333814989929961
0.0873498560124119,250.307594200232,0.27733579283940774,100.92402198153354,272.1719265124355,0.08374341101220592
0.0877949029478298,250.2561952339,0.2787488168593596,100.9032979183085,272.2274136065534,0.0841526223438149
0.0882423512177368,250.199818828612,0.2801694651163143,100.88056695169637,272.2780391163005,0.08456387290982136
0.0886972109907304,250.140415011038,0.281613644895569,100.85661533245052,272.3271721785809,0.08498176212228217
0.08913802049870409,250.084326701333,0.28301321508338545,100.83400052597746,272.376348541241,0.0853865765064189
0.08958303657872989,250.039145868684,0.2844261411374674,100.81578361425338,272.43841181915263,0.08579508780690771
0.0900306315483386,249.955355874729,0.28584725516597503,100.78199948869074,272.45899442302056,0.08620579818411432
0.0904667311137357,249.87389436399,0.28723187128611083,100.74915420756076,272.47916877775907,0.08660579827462522
0.0909108275254624,249.755299123514,0.28864187739334307,100.70133660660083,272.46076004570205,0.08701296888670325
0.09135792573679279,249.66884063242,0.2900614142143171,100.66647654299175,272.47806803370776,0.08742272430011651
0.0918080493078743,249.607485795902,0.2914905565525009,100.64173827290767,272.5234621594667,0.08783508284967724
0.09225242169975859,249.589319977818,0.2929014388967335,100.63441381505622,272.6145391761677,0.08824200601312898
0.0926981577498251,249.551888933953,0.29431665085569464,100.61932161816985,272.6848893011194,0.08865001163160131
0.09315056730757029,249.541640983082,0.29575305120153567,100.61518964437866,272.78658640751814,0.08906395570652197
0.0936103186635119,249.414844052991,0.29721276175665023,100.56406512216596,272.7626470842016,0.08948444188373975
0.09407549074811579,249.340875652131,0.2986896831252676,100.53424106293922,272.79774089267016,0.08990970595924194
0.0945552639874962,249.258663966164,0.3002129631603004,100.50109331115733,272.8273827386553,0.09034812915696708
0.095029819812525,249.249632239261,0.30171967790476684,100.49745171887004,272.9357798792961,0.09078159560316304
0.09551552515224539,249.249891943001,0.3032617923583791,100.497556431418,273.05712626607715,0.09122505170307584
0.09599154139942699,249.219758595034,0.30477314394318067,100.48540666551771,273.1427473697644,0.09165947079478945
0.0964668439698949,249.18060400306,0.30628222960441626,100.4696195340338,273.21827044974737,0.09209305036107507
0.09695469862741989,249.11203019639,0.30783116814205813,100.44197057518446,273.2646120085457,0.09253788474981008
0.09743970450611569,249.018487812458,0.3093710618069173,100.40425428598306,273.2827756814637,0.09297992551139857
0.0979285091073366,248.930121626386,0.3109230164157937,100.36862503975885,273.30747730916596,0.09342523086497624
0.09842035491532729,248.855628760649,0.3124846268561641,100.3385895162937,273.348088065949,0.0938731067231964
0.09890590145435599,248.764284087807,0.31402623711758026,100.30175934420379,273.3685398551591,0.09431504978515552
0.09939985611903979,248.662694472927,0.3155945431779513,100.26079841148417,273.3797305257087,0.09476444557215648
0.09989662696518099,248.567495215303,0.3171717906144496,100.22241407081017,273.39854956049555,0.09521619990215319
0.10039183513597319,248.450105555855,0.3187440765567149,100.17508256012074,273.3924675923335,0.09566633013524149
0.10090134841809219,248.407301475754,0.3203617812274427,100.15782395502401,273.47193315155715,0.09612925192596398
0.1014077882496942,248.376126031922,0.32196972769277904,100.14525401607096,273.56339962684655,0.09658916904849402
0.1019158325756832,248.329255004377,0.3235827684277941,100.1263556177648,273.63793778104724,0.09705033084078903
0.10241946487260119,248.239395141696,0.32518180097050875,100.09012412113184,273.66394115240666,0.09750727793614615
0.1029311131146532,248.128881413639,0.32680628413902385,100.04556498597924,273.66906337343863,0.0979712842091976
0.10345482003758419,248.031625123786,0.32846905361932976,100.00635124991051,273.69169226459684,0.09844600345472693
0.10397049118646019,247.945644572717,0.3301063095170111,99.9716838917195,273.7246750264859,0.09891321849990606
0.1044941212122012,247.832179021255,0.33176883484873876,99.92593458137003,273.729184776186,0.09938742128550973
0.1050177165741892,247.71644324267,0.3334312501230507,99.87926991544455,273.73105846989495,0.09986136794000117
0.1055411233986842,247.605094579973,0.3350930667908223,99.83437413464512,273.7376144211808,0.10033491953682966
0.10606543936776819,247.499090529658,0.336757769992664,99.79163330155811,273.7501903098092,0.10080906895176997
0.1065914358750482,247.390272902128,0.338427808903278,99.747758034138,273.75995731228585,0.10128451231858707
0.1071120895897362,247.23741991037,0.3400808844474124,99.68612770786117,273.71953658174476,0.10175490387581156
0.1076507229543412,247.093393996984,0.3417910453800333,99.62805645958395,273.6931764980012,0.10224130663837727
0.10818801740193719,246.96275550971,0.34349695525115054,99.57538302151508,273.68116640042484,0.10272626472520967
0.1087286645008022,246.858076257355,0.34521350979004695,99.53317634696555,273.6986252100544,0.10321401161619259
0.10926369007893719,246.720409444592,0.34691221600062555,99.4776690880595,273.6779917982944,0.10369645294418693
0.10979485288846119,246.55009111625,0.34859865792086425,99.408996738072,273.62002209999537,0.10417518102583365
0.1103324305380352,246.345090231279,0.3503054669582617,99.32634038125168,273.5249427876076,0.1046594574581745
0.1108698753148162,246.104741693953,0.3520118541245414,99.22943185100185,273.39034371994666,0.1051433798688917
0.1114187570828282,245.911335787952,0.3537545537379795,99.15145058970225,273.31047117402363,0.105637358707798
0.11196397148921919,245.680333928532,0.3554856094782709,99.0583106399841,273.187679831968,0.10612779556359685
0.1125228881262272,245.470319386599,0.35726016980077135,98.97363277667671,273.09134867324656,0.10663030844323344
0.11307767745430719,245.20204662355,0.3590216259174253,98.86546519861535,272.9289245627838,0.10712886092219233
0.11362006324626019,244.896400928689,0.36074370080687607,98.7422288544474,272.72154549098815,0.10761602700025151
0.11416212632085819,244.496857759806,0.3624647510687247,98.58113304875378,272.40913892043386,0.10810266621285843
0.1147033423943802,244.086323298714,0.3641831121021571,98.41560555404149,272.08384041383175,0.10858830887882978
0.11524173355412619,243.677686657871,0.36589250403435064,98.25084326045359,271.7595256967832,0.10907118280789131
0.11578222280540619,243.284329389767,0.36760855740716464,98.09224160995406,271.45232982023686,0.10955570406129432
0.11630784525276519,242.799546498459,0.36927740867752945,97.89677714817867,271.0390385800433,0.11002667292101613
0.1168399637145052,242.277784960256,0.370966884793554,97.68640289597522,270.58551256384305,0.11050323651405204
0.11737817753892119,241.73347015199,0.3726757136860747,97.46693516528237,270.10770432858976,0.11098502817520553
0.11791255507992919,241.199596323915,0.37437236237877514,97.25167723780253,269.6400570107153,0.11146315618190303
0.11844569231592719,240.62277538423,0.3760650731030688,97.01910303492154,269.12350660159495,0.11193994673790508
0.1189603241254522,239.890789134037,0.3776990290983107,96.72396617884371,268.4282751641325,0.11239997215557089
0.11946920169114919,239.160385336978,0.37931471536939865,96.42946736786953,267.73268564933437,0.11285464590660438
0.1199784204570302,238.346319949434,0.3809314849510708,96.10123620361179,266.94273493871304,0.11330941767230333
0.12046257239632119,237.583593207558,0.38246866735831975,95.7937047812874,266.2035240045016,0.11374161110955226
0.12095375761803419,236.78218440424,0.3840281804372585,95.47057675178958,265.42187934493916,0.11417989222939437
0.12145414024714919,235.868631838587,0.38561689528469867,95.10223235731829,264.51585372981395,0.11462618269947049
0.12197945244583519,235.026212842708,0.3872847615155267,94.76256901817986,263.6945815956798,0.1150944936046808
0.12252397208537719,234.115722610987,0.38901361137107254,94.39545935674997,262.8005108729235,0.11557969638430102
0.12304761905200519,233.081846967565,0.3906761904901164,93.97860069732222,261.7620132811677,0.11604607828740861
0.12354183720437119,232.121746711686,0.3922453331238785,93.5914882741518,260.79849375553545,0.11648605022706338
0.12401572436129019,230.881712535506,0.3937499248470963,93.09150649431602,259.51467535737197,0.1169077410189212
0.12448740984581019,229.715648680718,0.39524752626044735,92.6213495480655,258.3123547860307,0.11732729613028674
0.1249676498708342,228.568448132685,0.3967722883398985,92.1587982870986,257.1321099304503,0.11775427957256174
0.1254669121710942,227.385813444408,0.3983574461432241,91.68195998078531,255.91520932879038,0.11819798259496635
0.12593261813480422,226.098235990984,0.39983606257800336,91.16280875156475,254.57137880498942,0.11861168612833144
0.1264135986295912,224.881944005292,0.401363175648952,90.67239982293376,253.3100798138192,0.11903877899577625
0.1268599012001152,223.418157876389,0.4027801863103657,90.08220125576005,251.76096331089946,0.11943491606159998
0.1273057003237782,222.07366890986,0.40419559852799575,89.54010330445556,250.3449128539006,0.11983044967206201
0.1277310444833582,220.419222049277,0.4055460662346623,88.87303033026849,248.5735995058404,0.12020768890384263
0.1281574064127782,219.0183865097,0.40689976536057076,88.30821344071104,247.08721488149456,0.12058568803259151
0.1285797046344042,217.432410579368,0.4082405622142333,87.66874794560117,245.38980570960962,0.12095994361113269
0.1290331211646882,215.926826904408,0.409680159697885,87.0616966078573,243.78853932307112,0.12136162146412767
0.1294700336254612,214.196080919131,0.4110673567608393,86.36385982659361,241.92805471817292,0.1217485259192281
0.1299121215706282,212.517437726609,0.41247098598674453,85.68703089136874,240.12602893242664,0.12213986117855302
0.1303464963484032,210.683537950367,0.41385012590618014,84.94760250158798,238.14539896048316,0.12252421965831173
0.1308033634421542,208.906130771509,0.4153006789288396,84.23095192707244,236.23175532010887,0.12292832122459224
0.1312584617030982,206.944295446646,0.4167456159073368,83.43993992408767,234.10748532520427,0.123330695962564
0.13171775184897822,204.911201317415,0.4182038621205058,82.62019637118172,231.9016440836183,0.12373661286918976
0.13216242353840021,202.690758635452,0.4196156947344207,81.72491388181425,229.47886052555026,0.12412945317935722
0.1325994975243612,200.409935594158,0.4210034046398468,80.8052860315645,226.98419235283293,0.12451543104954507
0.1328242601888292,199.185823368222,0.4217170260995327,80.31172398206712,225.6425329972089,0.1247138598551407
0.1329344050144742,198.600946231111,0.42206673592095556,80.07590152038397,225.00184485365534,0.12481108541355822