File: example/data/02 processed data/test_ID_057.csv
Strain,Stress_MPa,Displacement(mm),Force(kN),True Stress (MPa),True Strain
2.9962259101333917e-05,1.50460191896753,9.513017264673518e-05,0.6066554937277081,1.5046470002400705,2.9961810241826625e-05
7.310051474953392e-05,3.81603209768376,0.00023209413432977017,1.5386241417860922,3.816311051594402,7.309784303719766e-05
0.0001343796188339339,6.64055063614316,0.00042665528979774007,2.677470016492922,6.6414429908064925,0.00013437059070181177
0.0001970301542789339,10.1026372685968,0.0006255707398356151,4.07338334669823,10.104627792776455,0.00019701074638725822
0.0002608274245697339,13.9595691438377,0.0008281270730089051,5.628498278795361,13.96321018230559,0.00026079341501059435
0.0003318718922148339,17.8306604356369,0.0010536932577820976,7.189322287648799,17.836577930655114,0.0003318168349192848
0.00037219507361123383,21.6207887302455,0.0011817193587156673,8.717502016034986,21.62883588129849,0.00037212582620672213
0.0004661910678660339,25.4993210060943,0.0014801566404746575,10.281326229657221,25.511208561783988,0.00046608243457144154
0.0005476874591697339,29.4014515754883,0.0017389076828639048,11.854665275236883,29.41755438179758,0.0005475375331324423
0.0006154767228501339,33.3422793595803,0.001954138595049175,13.44360703778278,33.36280075641289,0.000615287394732648
0.0006686236056692339,37.1555220445516,0.0021228799479998174,14.981106488363208,37.180365103671555,0.0006684001764939872
0.0007379279703443338,40.8025131643138,0.00234292130584326,16.451573307851326,40.83262248003809,0.0007376558353687345
0.0008113349923339339,44.3104220107334,0.00257598860066024,17.865962154727708,44.34637260663579,0.0008110060380151719
0.0008959643249492339,47.6795631004887,0.0028446867317138175,19.224399842117045,47.72228228805591,0.0008955631884982776
0.0009665505003357338,50.8962174154075,0.003068797838565955,20.521354861892306,50.94541117981556,0.000966083691173138
0.001043450736021334,53.9702896616759,0.003312956086867735,21.760820791587722,54.02660500014666,0.0010429067197053109
0.0011337066093704338,56.9308587258361,0.003599518484751127,22.95452223825712,56.99540161665072,0.001133064449333894
0.0012403373446559338,59.7741963430718,0.00393807106928259,24.100955965526552,59.84833651104291,0.0012395687617606864
0.0013506491564379338,62.5035457331586,0.0042883110716904396,25.20142963960955,62.58796609447747,0.0013497378503435863
0.001472230155386834,65.1564495779934,0.0046743307433531976,26.27108046984694,65.25237486788006,0.0014711474870660404
0.001607056487184534,67.6500495263124,0.005102404346810895,27.276499969009162,67.75876697726203,0.0016057665537204944
0.0017745550578955338,69.9832569305311,0.005634212308818319,28.21724919439014,70.10744607308519,0.0017729823953115263
0.001970627194773934,72.1417465273474,0.00625674134340724,29.08755219982647,72.28391101493267,0.001968688056131843
0.002210317103222034,73.997373592949,0.007017756802729958,29.83574103267704,74.160931253395,0.0022078779459197033
0.002452579653455334,75.555143397399,0.007786940399720685,30.463833817831272,75.74044840480936,0.0024495769884916438
0.002728483843000334,76.8797569199977,0.00866293620152606,30.997917990143073,77.08952209460772,0.0027247682879797145
0.003026307574956134,77.9047862351403,0.009608526550485726,31.41120981000857,78.14055007984905,0.003021737524118473
0.003353917984946234,78.6602879372757,0.010648689602204293,31.71582809630956,78.92410809168958,0.0033483061462850016
0.003699607569559234,79.1736469663433,0.011746254033350568,31.92281445682962,79.46655838996959,0.0036927808537404253
0.004048319515145333,79.539262222127,0.012853414460586432,32.070230527961606,79.86126256960108,0.004040147118587017
0.004394492766090534,79.7673245930961,0.013952514532337444,32.16218527593635,80.11786152399087,0.004384865178027435
0.004770631806916534,79.9218534507813,0.015146755986959992,32.22449131135502,80.30313118692132,0.004759288405486317
0.005135761481810833,80.0120212277207,0.016306042704749394,32.26084695901699,80.42294388442386,0.005122618439293087
0.005518334659743433,80.0617703735135,0.0175207125446854,32.280905814600644,80.50357801588608,0.005503164435030078
0.005895845944660334,80.096784312607,0.018719310874296558,32.295023434843145,80.56902261357682,0.005878533459460596
0.006278053134630234,80.11669544823,0.01993281870245099,32.30305160472634,80.61967231922499,0.006258428253585019
0.006668548530828834,80.1138523355588,0.021172641585381548,32.301905261697314,80.64809544785014,0.006646412118406889
0.007046580345811334,80.1378546348388,0.022372892597950982,32.31158298876701,80.70255246626414,0.007021869216585587
0.007440856435661033,80.145734222926,0.02362471918322378,32.314760038683765,80.74208712520942,0.007413309825928898
0.007842962619921035,80.1066695908916,0.024901406318249285,32.299009179047495,80.73494320609933,0.0078123664608247805
0.008232713509319235,80.0736807698969,0.02613886539208857,32.28570808642243,80.73290444331214,0.00819900958029528
0.008634138770592834,80.0390695152451,0.027413390596632246,32.27175282854683,80.73013794850885,0.008597077768208238
0.009034629845913035,80.0175531064622,0.028684949760773883,32.26307741252556,80.74048207995477,0.008994061739818617
0.009438224783061135,79.9766371308312,0.0299663636862191,32.24658009115114,80.7314746094653,0.009393963023208371
0.009855936014520334,79.9116691850896,0.031292596846102055,32.22038501542812,80.69927348339135,0.009807683070070973
0.010262739411133034,79.8420014489711,0.03258419763034738,32.19229498422515,80.6613991039052,0.010210435053962134
0.010669341577512434,79.8011307724851,0.033875159508601975,32.17581592746599,80.65255629496849,0.010612825788109919
0.011084238739790834,79.7516914454399,0.0351924579988359,32.15588199080137,80.6356782333233,0.011023258762871925
0.011489682153104435,79.6763434868906,0.036479740836106576,32.12550169391429,80.59179934867656,0.01142417703295956
0.011908419122464134,79.5996004223348,0.037809230713823624,32.09455889028539,80.54750582614463,0.011838071832083243
0.012313979893134935,79.5002441779063,0.03909688616070341,32.054498452531824,80.47920858621235,0.012238779556980106
0.012723365148227235,79.415172562941,0.04039668434562147,32.02019757737781,80.42560080176877,0.012643103222093676
0.013134068410040934,79.3388161641879,0.04170066720187996,31.989410677400567,80.38085760326001,0.013048564396840722
0.013556877904725135,79.2481042755157,0.043043087347502305,31.95283564388793,80.32246114935978,0.013465805616166074
0.013980697349020835,79.1537998726517,0.04438871408314115,31.91481210865317,80.26042519269622,0.013883868842851867
0.014410933593662235,79.0699675489887,0.04575471415987759,31.881010915752245,80.2094396005902,0.014308083027657403
0.014826430594522235,78.9803187792147,0.04707391713760809,31.84486453177937,80.15131499392797,0.014717593530469213
0.015253363055126734,78.9076437149072,0.04842942770002737,31.815561945850583,80.11125065231526,0.015138200117692131
0.015686860668680434,78.7935870415169,0.049805782623060374,31.769574295139616,80.02961106302271,0.015565093647174828
0.016126061558777632,78.6813920863205,0.051200245449118977,31.724337289204428,79.95021305863483,0.0159974177968377
0.01655713358230993,78.5651972182476,0.05256889912383403,31.677487518397434,79.86601168351066,0.01642155868709062
0.016990202822927233,78.4747246304244,0.05394389396279396,31.64100897098712,79.80802611836867,0.016847483610903498
0.017432895790414932,78.3748828678997,0.055349444134567403,31.60075277233716,79.74118403352176,0.01728268607668028
0.017865285463826534,78.2293337460292,0.05672228134764924,31.542067366398975,79.62692312504697,0.01770757682133796
0.018309073228509734,78.1074694868659,0.058131307500518405,31.49293169710433,79.53754486539452,0.018143480328143065
0.018747519254850332,78.0176692903855,0.0595233736341498,31.456724257883433,79.48030704762554,0.01857395048270707
0.019177299116830634,77.8922464954672,0.06088792469593726,31.40615378697238,79.38600940539268,0.018995732350691016
0.019611122240685334,77.7475655446798,0.062265313114175935,31.3478184276149,79.27228255649221,0.019421301895679265
0.020054190671661632,77.6032542623206,0.06367205538252568,31.28963211856767,79.15952472003862,0.019855753994403834
0.02050806484022613,77.479437539863,0.06511310586771796,31.23970921607276,79.06839086871476,0.020300606068701852
0.020956466436795634,77.3842169426235,0.06653678093682613,31.201316271265796,79.00591668771929,0.020739900111689785
0.021403803881463134,77.2685391568692,0.06795707732364545,31.15467498804966,78.92237981518998,0.021177959408398922
0.021854538140081033,77.1407335323104,0.06938815859475728,31.10314376022756,78.8266086354461,0.021619151064548568
0.022319255497807933,77.0433324916358,0.07086363620554019,31.06387166062755,78.76288231391919,0.02207382607034236
0.022795104861937834,76.9590293635348,0.07237445793665262,31.02988063937723,78.71331850794954,0.02253917840656421
0.023262802960505632,76.8583344861426,0.07385939939960538,30.989280464812698,78.64627477716635,0.022996348367321853
0.023719354809247934,76.7378392823072,0.07530895151936219,30.94069679862627,78.5580113195393,0.023442421484842678
0.024199061873243034,76.6163107294475,0.07683202144754663,30.891696486113233,78.47035357328902,0.023910904085380845
0.024676044182819632,76.4908374643979,0.07834644028045233,30.841105665645234,78.37832874925024,0.024376508178850082
0.025153434603379033,76.3610235723046,0.07986215486572842,30.788764704353216,78.28176558497765,0.024842293683577283
0.025637377651823633,76.2226020433513,0.08139867404454003,30.732953143879246,78.17674967754137,0.025314251188492613
0.026111303020910633,76.0845796590795,0.08290338709139125,30.677302518540852,78.07124717377633,0.025776223341300492
0.026591343214620634,75.9513741872087,0.0844275147064205,30.62359407228255,77.97102324584284,0.026243938627137278
0.02706292746961733,75.8209772133941,0.08592479471603502,30.571018012440504,77.87291482039569,0.026703202165326293
0.027535584821321433,75.7012427480997,0.08742548180769555,30.5227410760338,77.78572073886944,0.027163299218073814
0.028016930976077034,75.5608252347435,0.08895375584904458,30.46612473464858,77.67780765984072,0.027631636718433866
0.028499155192889033,75.4357763331287,0.09048481773742267,30.415705017517496,77.5856322299426,0.028100608713249212
0.028974066493937033,75.2900905145223,0.09199266111825008,30.356964495455397,77.47155060342462,0.028562253904522186
0.02946368507672713,75.1824265830644,0.09354720011860863,30.31355439829157,77.39757792321197,0.029037972533030813
0.029947021012445132,75.0545148472565,0.0950817917145133,30.26198038641382,77.30217398046616,0.029507365008425098
0.030436291925630934,74.9322011364031,0.09663522686387821,30.212663498197728,77.21285948482075,0.02998229694881713
0.030942659823334433,74.7962211612252,0.09824294493908682,30.157836372206003,77.11061518868789,0.030473587409951333
0.03144073594063383,74.6870359484323,0.09982433661151241,30.113812894407904,77.03525132387558,0.03095659762813469
0.03194848142595033,74.5491768009428,0.10143642852739229,30.05822808614014,76.9309097912876,0.0314487447143861
0.03245195992179743,74.4511114598061,0.10303497275170684,30.018688140593817,76.867195945033,0.03193651684981614
0.03295784220773483,74.3280006340726,0.10464114900955808,29.969049855658074,76.77769115058678,0.03242637827637851
0.033471253490509334,74.1932772575046,0.10627122983236713,29.914729390225858,76.67661924788217,0.03292328503636114
0.033981470568847136,74.0678669251528,0.10789116905608966,29.86416394422161,76.58480196516716,0.0334168557794869
0.03449006319255123,73.9403334380217,0.10950595063635016,29.812742442210347,76.49054021077738,0.03390861273688494
0.035008551733290934,73.8103219881517,0.1111521517531987,29.760321825622764,76.39431446392477,0.03440968922744026
0.03551993532575913,73.6935996957875,0.11277579465928524,29.71325939734152,76.31119159090426,0.034903653552068016
0.036038780246976536,73.5594201047072,0.1144231272841505,29.659158186217944,76.21041188095577,0.03540457580753321
0.036547882878236536,73.426659712841,0.11603952813840099,29.605629196217492,76.11024867216605,0.03589584852539548
0.03705874813553423,73.3028049828184,0.11766152533032118,29.55569096907238,76.01931517030485,0.03638857965384838
0.037573313287342834,73.1601653155791,0.1192952696873135,29.498178655241496,75.90903512713516,0.03688463403566225
0.03809851708494563,73.0312169846072,0.12096279174470237,29.44618668819362,75.81359805262963,0.03739069072644187
0.038620850971506936,72.9001793304826,0.12262120183453451,29.393352306050584,75.7156462922013,0.03789372826305868
0.03913849046097393,72.7763621186573,0.12426470721359223,29.34342920624263,75.62471907322276,0.03839199530472645
0.039657942879946534,72.6467300756345,0.12591396864383023,29.29116156649583,75.52774994738891,0.038891757976485024
0.04018877125223373,72.510560649873,0.12759934872584208,29.236258054028795,75.42467098520197,0.039402207501641126
0.040722455973232735,72.3873972334144,0.12929379771501393,29.18659856451269,75.33518983026903,0.039915141187343385
0.04126428740838013,72.2759102465991,0.1310141125216069,29.141647011428756,75.25832417971705,0.04043563580538305
0.04178667406987353,72.1467777991525,0.13267269017184846,29.08958080861829,75.16155168823728,0.04093719499150466
0.042315941592284335,72.0194046452215,0.13435311455550275,29.03822395295331,75.06697356569978,0.041445104275636066
0.042854764001021235,71.8909025361124,0.1360638757032424,28.986411902560523,74.97177019811792,0.04196191800151934
0.04340393533849463,71.7750205698041,0.13780749469972045,28.93968829374501,74.890338921535,0.04248838324797377
0.04394185591847023,71.6616900040277,0.13951539254114298,28.893993409623974,74.81063766105878,0.04300379434481923
0.04447982185141753,71.5437122222873,0.14122343437825066,28.846424768026242,74.72596379652371,0.043518983351495844
0.04503950349492173,71.41585694321,0.1430004235963765,28.79487351950227,74.63239168159654,0.044054687089767064
0.045600984336413235,71.298317944942,0.14478312526811202,28.747481795400613,74.5495914247619,0.04459182473563126
0.04614954179030623,71.1555501285908,0.1465247951842223,28.689917811847813,74.43934616286244,0.04511632080685664
0.04670289311520463,71.0271785828079,0.1482816856407747,28.63815840458815,74.34435331243535,0.04564512190966159
0.04726213075146393,70.9035158970182,0.15005726513589798,28.58829760967774,74.25456713608158,0.0461792642121179
0.04781495655669003,70.7817644045059,0.15181248706749084,28.539207407896782,74.16619139451323,0.04670700213775851
0.048373871210161234,70.6498634403516,0.1535870410922619,28.486024939149765,74.06747083543064,0.047240269617589065
0.048904813152320134,70.5177272371008,0.15527278175861642,28.43274762199904,73.9663835115575,0.04774658473675783
0.049444029588730336,70.3834049463731,0.1569847939442188,28.378588874377638,73.86344410309717,0.04826052830733667
0.05000065199199903,70.2566321977831,0.1587520700745969,28.327474102146148,73.76950961443434,0.048790785114000264
0.05055756189648733,70.1330846928587,0.16052025902134726,28.277659748160627,73.67884246320949,0.04932103456279405
0.051102688467736336,69.9645664576099,0.16225103588506284,28.209713195708314,73.53994390107339,0.049839792609799496
0.051671521518591335,69.8155479627958,0.16405708082152748,28.149628938599268,73.42302355168765,0.050380823655385744
0.052236218133772834,69.6980785363151,0.16584999257472874,28.10226526584225,73.33884257024287,0.05091763106200254
0.05281516054463693,69.5787740948096,0.16768813472922225,28.05416171502723,73.253588219126,0.05146768169860461
0.05339432561909893,69.4361219650039,0.1695269838406391,27.996644376289574,73.1436168709308,0.05201764132310001
0.05396972064172733,69.3360229418322,0.17135386303748426,27.95628445014674,73.07806873041127,0.05256372166261047
0.05456167120682613,69.2160310690806,0.17323330608167295,27.9079037270533,72.99257339851324,0.053125203064252294
0.055155440508778734,69.1378425915094,0.17511852361537247,27.87637813289659,72.9511707554707,0.053688093050149335
0.055744466498819936,69.0155028299773,0.1769886811337533,27.827050741046847,72.86273521538219,0.054246173519406894
0.05635703155094463,68.8953988267528,0.1789335751742492,27.778624806946727,72.77813899214702,0.054826226201406966
0.05694134727605423,68.7687503286445,0.18078877760147216,27.727560132509463,72.68453562284812,0.05537921554342694
0.057526761510255535,68.6780327796182,0.1826474677950613,27.690982816742064,72.6288575923248,0.05593293801077121
0.05812427212366223,68.5528926435352,0.18454456399262759,27.640526313873394,72.53747963041225,0.05649778601244474
0.058729454921274335,68.3958864756014,0.186466019375046,27.577221426962485,72.41273960717082,0.05706956176281205
0.05932183684267783,68.2237791191109,0.18834683197550212,27.507827740825515,72.27093901280568,0.05762892681610688
0.059914758785365035,68.1232984543124,0.19022935914353398,27.467313936778762,72.20488944886596,0.05818848865019488
0.06050079863714803,67.9915795023513,0.192090035672945,27.414204855348043,72.10512436284469,0.05874124809836364
0.06110586854525643,67.8953608231929,0.19401113263118916,27.37540948391138,72.04416581648768,0.05931163650623619
0.06170702467191883,67.732606312832,0.19591980333334227,27.309786865333862,71.9121839216713,0.059878013453213884
0.06230671347577693,67.6015461641014,0.19782381528559176,27.25694341336569,71.81357633146757,0.06044268853889913
0.06288365141350304,67.4869661118602,0.19965559323787213,27.210744736302033,71.7307929637933,0.06098564032470717
0.06348420679848603,67.3975174771998,0.20156235658519314,27.17467904680696,71.67619541442693,0.06155050533490013
0.06408364531949083,67.2569329915538,0.20346557388938338,27.11799538219449,71.56700243066129,0.06211400185161021
0.06466978489072274,67.1286724343855,0.2053265670280447,27.06628072554424,71.469869240717,0.06266468994702443
0.06525962340997053,66.9767418912909,0.20719930432665642,27.00502233056849,71.34761884434334,0.06321854730213414
0.06586084090749293,66.8798547031075,0.20910816988129005,26.965957416292945,71.2846181736251,0.06378277398339305
0.06646928538962153,66.7676213814764,0.21103998111204836,26.920704941011287,71.20561746186796,0.0643534590674128
0.06708433837983313,66.6630042538759,0.21299277435597017,26.878523315162763,71.13504778865916,0.06493001172622301
0.06769245697600243,66.5468490245939,0.2149235508988077,26.83168952671626,71.05156873907976,0.06549973743613441
0.06828758878260194,66.4206045159081,0.21681309438476115,26.780787740814144,70.95630744378226,0.0660569821755517
0.06891359198627993,66.287683301474,0.21880065455643877,26.72719390715432,70.85580566222752,0.06664279808021581
0.06952125449921503,66.1648043055746,0.22072998303500774,26.67764909600768,70.76466450459321,0.0672111226474006
0.07014194454618393,66.0530189838426,0.22270067393413395,26.632577254285337,70.68610617851533,0.06779129812983767
0.07075979353307714,65.9008580627049,0.2246623444675199,26.571225970882615,70.56398917287451,0.06836848389512189
0.07137277509322343,65.7918726587804,0.22660856092098436,26.52728305602026,70.48762118901753,0.0689407935512611
0.07198642871217713,65.6653522934717,0.22855691116116236,26.47627004472779,70.3923664952057,0.06951340278505772
0.07262070854822833,65.5539903727511,0.23057074964062493,26.43136891829325,70.31456760178402,0.07010491424981491
0.07323409726882403,65.4266321119132,0.2325182588285163,26.3800180675234,70.21809245196862,0.07067661065316859
0.07387292536119233,65.2813132212753,0.23454653802178563,26.3214254908182,70.10383480035118,0.07127167005587703
0.07451351855286834,65.1323904957376,0.23658042140535696,26.2613798478814,69.9856340833344,0.07186801827104589
0.07513617745072593,65.0254821318343,0.2385573634060548,26.218274395555586,69.91124829611081,0.07244733025516045
0.07575709156079194,64.8874726831844,0.2405287657055144,26.162628985859953,69.80315889239279,0.07302468491636979
0.07638925498037553,64.7493139121096,0.24253588456269232,26.10692336936259,69.69546576234612,0.07361215745398865
0.07702146037112233,64.6095822150858,0.24454313667831337,26.050583549122592,69.5859065912598,0.07419932403991059
0.07765060386832684,64.475165117505,0.24654066728193771,25.996386575378015,69.48170062338934,0.07478330480016288
0.07826801356566673,64.3654031195231,0.24850094307099185,25.952130537791714,69.40315536404154,0.07535606270412615
0.07887126475137843,64.2182946761281,0.2504162655856265,25.89281641341485,69.28327279741103,0.07591536938172584
0.07948458479921883,64.086594320143,0.25236355673751976,25.83971482988166,69.18049066087555,0.07648369092562314
0.08010834237788673,63.9458362394298,0.2543439870497904,25.782961171738098,69.06843118253832,0.07706135312127474
0.08073731339893434,63.8044808363927,0.2563409700416165,25.72596667323354,68.95588320193684,0.07764350579574218
0.08135926795853493,63.6748607665684,0.2583156757683484,25.67370386108038,68.85540082589804,0.07821883122950751
0.08198935338434434,63.5521838469416,0.26031619699529324,25.624240527086855,68.76278630671531,0.0788013406201899
0.08262450822028913,63.4226364156096,0.26233281359941796,25.572007002773795,68.66290055948355,0.07938819342145839
0.08326224714352393,63.3126519673429,0.26435763468068846,25.527661273232656,68.58420564275971,0.07997708749921725
0.08390230351027363,63.1779779516726,0.26638981364511877,25.473360710114395,68.47875583293921,0.08056777304283871
0.08453579508671073,63.0503977136054,0.26840114940030657,25.4219203581257,68.38041321485836,0.08115205681360353
0.08515890297773583,62.9340365257331,0.2703795169543112,25.375003527175586,68.29343003622529,0.08172643062639061
0.08579582993182813,62.7919935283272,0.2724017600335543,25.317731790621526,68.17928472616401,0.08231320193277648
0.08641736686483953,62.6537944496588,0.2743751397958655,25.26200992210243,68.06817039008921,0.08288546339485567
0.08705336729718934,62.5036321065734,0.27639444116857614,25.201464465370396,67.94478374975533,0.08347070288348195
0.08768526923752823,62.3541270986152,0.2784007298291521,25.141184046161648,67.82166552132833,0.0840518319879238
0.08832277049162074,62.2104687960098,0.28042479631089584,25.083261018551152,67.7050697536559,0.0846377684924698
0.08895579782965184,62.073942131762,0.2824346581091446,25.028213467526438,67.59577917852452,0.08521925343893302
0.08959097367955163,61.9169366163186,0.2844513414325764,24.96490884369966,67.46413525502967,0.08580237231083863
0.09021966710981794,61.7755058343297,0.2864474430736719,24.907883952401736,67.34887140624353,0.08637920539526742
0.09084603420781243,61.6376057593807,0.2884361586098044,24.8522826421823,67.23713780068505,0.08695357334285915
0.09146334075477164,61.4931791330334,0.29039610689639994,24.794049826439068,67.11755073017224,0.08751931032818858
0.09208708635901994,61.3582590306141,0.2923764991898883,24.739650041143605,67.00856232880538,0.08809062355591986
0.09271517755442633,61.1944231316242,0.2943706887353036,24.673591406670877,66.86807493761343,0.08866558745364525
0.09334339541712963,61.0266096675536,0.2963652804493866,24.60592901795761,66.72304062471888,0.08924033681101765
0.09396924269221384,60.8772970300734,0.2983523455477789,24.545726162525593,66.59789052913835,0.08981258906363036
0.09455779814877463,60.73210594599,0.30022100912235944,24.48718511742317,66.47480016118092,0.09035044439716386
0.09519438814377994,60.5694928302958,0.3022421823565013,24.421619509175265,66.33536864045487,0.09093187093202379
0.09583363974398074,60.4077645405017,0.30427180618713884,24.356410662730287,66.19686048521535,0.09151538845001315
0.09647139834571704,60.2547291517487,0.30629668974765156,24.294706793985075,66.06758712996033,0.0920972040355693
0.09710003147424014,60.1245667645402,0.3082925999307124,24.24222531946261,65.9626640897521,0.0926703635298868
0.09773771717497934,59.9737150164253,0.3103172520305594,24.18140189462268,65.83540901263349,0.09325144130574947
0.09836639400422634,59.8150760728618,0.3123133009634186,24.11743867257788,65.69886941323769,0.09382397959591526
0.09903622858262293,59.6417341229997,0.31444002574982777,24.04754719839348,65.54842653666913,0.0944336399214822
0.09966631484434134,59.489341192593,0.3164405496307837,23.986102368853498,65.41842460177642,0.09500678364285577