File: example/data/02 processed data/test_ID_099.csv
Strain,Stress_MPa,Displacement(mm),Force(kN),True Stress (MPa),True Strain
0.0005836069052571996,0.0051106696707534,-4.674765042591964e-05,0.0010303110056238,0.0051105944229426,-1.4723777819738429e-05
0.0005863210015285996,-0.0290332102384835,-3.813039476446276e-05,-0.0058530951840782,-0.0290328615620212,-1.200964526967134e-05
0.0005928142350170995,-0.0539340783959661,-1.751437843841081e-05,-0.0108731102046267,-0.0539337808772701,-5.516354880669765e-06
0.0005951384130813995,-0.0690866716917611,-1.013511308422237e-05,-0.013927873013059,-0.0690864511559405,-3.192166696342823e-06
0.0005986499229401996,-0.113679623654719,1.0139307176185355e-06,-0.0229178121287913,-0.1136796599581087,3.193482066241707e-07
0.0006134191147259996,-0.146873808073338,4.7906114637331134e-05,-0.0296097597075849,-0.1468760241846724,1.508842621229799e-05
0.0006143906446601996,-0.178090983937625,5.099072217841264e-05,-0.0359031423618252,-0.1780938440912894,1.6059941015909597e-05
0.0006178105975261995,-0.185127347788426,6.184907252798391e-05,-0.0373216733141466,-0.1851309540733898,1.947983311028452e-05
0.0006215596317579996,-0.192993412925386,7.375225621398097e-05,-0.0389074720457578,-0.1929978959803899,2.322878728482308e-05
0.0006208684435935996,-0.19977285411136,7.15577337919732e-05,-0.0402742073888501,-0.1997773565657579,2.253761493698084e-05
0.0006204156236170996,-0.15618082214713,7.012003036676223e-05,-0.0314860537448614,-0.1561842714082297,2.2084805063203453e-05
0.0006196772080256995,0.0819340819787995,6.777556086387419e-05,0.0165179109269259,0.0819358309956058,2.134640550683164e-05
0.0006064520597048996,0.505679868261667,2.578571494556996e-05,0.101945061441552,0.5056839751331431,8.121452043191244e-06
0.0005998883282823996,1.13568788705422,4.94586767913224e-06,0.2289546780301307,1.135689656176114,1.557752386371154e-06
0.0005817571268460996,2.00871821260327,-5.262069688133104e-05,0.4049575916608192,2.008684921216755,-1.6573585177780434e-05
0.0005507985812939996,3.23940057475833,-0.0001509140790091,0.6530631558712794,3.2392465995916275,-4.75331230696894e-05
0.0005231909594024996,4.7971315363331,-0.0002385682785147,0.967101717724753,4.796771081715011,-7.514243840258502e-05
0.0004988583430519996,6.57376339892242,-0.0003158243354276,1.32527070122276,6.573109492006917,-9.94771793213002e-05
0.00047179647445289957,8.44030892379605,-0.0004017457682296,1.7015662790372836,8.439240936900715,-0.0001265421063444
0.00044882591749559954,10.4080699649232,-0.000474677286569,2.098266904928517,10.406513909991116,-0.0001495158341223
0.00042836168518969956,12.4885133043533,-0.0005396512241402,2.5176842821576253,12.48639064561554,-0.0001699833358417
0.00042827999467139955,14.6541035045862,-0.0005399105915358,2.9542672665245777,14.6516115657857,-0.0001700650402505
0.00043997994397509954,16.8164757705146,-0.0005027632524966,3.390201515335743,16.81381287097006,-0.0001583631694923
0.0004524455557546996,18.9806389431849,-0.0004631849350964,3.826496810946076,18.97786995231341,-0.0001458956611823
0.00047078345140409955,21.2425352547593,-0.0004049621164095,4.282495107359475,21.23982583049641,-0.0001275552581046
0.0005034935456594996,23.5730819771603,-0.0003011075671488,4.752333326595517,23.570846376100665,-9.484152633862313e-05
0.0005348176866625995,25.992783024198,-0.0002016534194638,5.240145057678317,25.991132147480453,-6.351490504896736e-05
0.0005768106013199995,28.4827957607881,-6.832591542670934e-05,5.74213162537488,28.48218281178203,-2.152020492069799e-05
0.0006139662361089996,30.9929238424599,4.9643225028563456e-05,6.248173446639916,30.99340843732371,1.5635539190580976e-05
0.0006553224552344996,33.5400427652566,0.0001809492207518,6.761672621475731,33.54195427536758,5.699025657622644e-05
0.0007036438388312996,36.1434736937618,0.0003343696136718,7.286524296662378,36.14728008095416,0.0001053077190961
0.0007516400605409995,38.7659785287413,0.0004867576176001,7.815221271394246,38.771921720978334,0.00015329773516
0.0007965482447449996,41.4357805938505,0.0006293411024478,8.353453367720261,41.44399389773703,0.0001981980275355
0.0008433766631464996,44.1399051999199,0.0007780213308725,8.898604888303852,44.15072151103431,0.0002450160695749
0.0008846657864567996,46.8374431829298,0.0009091142973827,9.442428545678649,46.850854392142544,0.000286294225671
0.0009323887016250995,49.5722272112359,0.0010606345530421,9.993761005785156,49.58878721660645,0.0003340023419496
0.0009857248402830995,52.274201114777,0.0012299767932812,10.538478944739042,52.2944518405277,0.0003873192478154
0.0010341540413972997,54.9732891947115,0.0013837395068188,11.082615101653838,54.99724784418504,0.0004357285232522
0.0010808674099176995,57.7446994124295,0.0015320544518711,11.641331401545788,57.77256335693557,0.0004824204517743
0.0011318046726324995,60.4845622039727,0.0016937802609906,12.193687740320897,60.51682915123436,0.000533331851231
0.0011848586744890996,63.2039235727331,0.0018622267168853,12.741910992262994,63.24099444992652,0.0005863561594289
0.0012407980796947996,65.9063887919961,0.0020398343284134,13.286727980466411,65.94873150516764,0.0006422612111179
0.0012923131897597995,68.7090430981329,0.0022033948028697,13.851743088583593,68.75672597954159,0.0006937419204942
0.0013383150455776995,71.450140745518,0.0023494506950916,14.40434837429643,71.50301274011295,0.0007397108173777
0.0013880782199005995,74.1419450931303,0.0025074487735668,14.947016130775069,74.20049851967947,0.000789435958638
0.0014392501286958996,76.7308318433665,0.0026699195839919,15.468935699622689,76.79535630025929,0.0008405661792575
0.0014861908359324995,79.349000998015,0.0028189563294681,15.996758601199824,79.41945182277101,0.0008874663464717
0.0015364589752823996,81.9497251415601,0.002978557671904,16.521064588538515,82.02660450613672,0.0009376886331689
0.0015866426357251996,84.5072627230166,0.0031378907938099,17.036664164960147,84.59078227001145,0.0009878240022206
0.0016426679313127997,86.9688497951632,0.0033157711073005,17.5329201187049,87.05967461386743,0.0010437924157412
0.0017005084691236996,89.5451788983461,0.0034994148148501,18.052308065906573,89.6438736150816,0.0011015709423239
0.0017569492278765996,92.1460748912436,0.0036786142238906,18.57664869807471,92.2528370524312,0.0011579479725942
0.0018118598444458996,94.7933278775893,0.0038529554314981,19.110334900122005,94.90836235554704,0.0012127935382799
0.0018617205173271996,97.3939497628867,0.0040112630678962,19.63462027219796,97.51699629949157,0.0012625925371229
0.0019185171162748997,99.9702970127306,0.0041915922695552,20.15401187776649,100.10227645340578,0.0013193158615623
0.0019747950948271996,102.592860812534,0.0043702748514587,20.682720739806854,102.73407624546256,0.0013755180612686
0.0020289543347407997,105.181255774068,0.0045422304381844,21.20454116405212,105.33173057769112,0.0014296013928523
0.0020840527987524998,107.778438433546,0.0047171680614216,21.728133188202875,107.93856725480228,0.0014846196307694
0.0021431503347182994,110.378193867022,0.004904802738113,22.252243883591635,110.54870828198484,0.0015436277534557
0.0021984244718156994,112.963042961543,0.0050802981233972,22.77334946104707,113.14379443718734,0.0015988151108302
0.0022572483606747994,115.553282150416,0.0052670639705249,23.295541681523865,115.74497554540508,0.0016575433017759
0.0023106827755996996,118.110652722681,0.0054367182379114,23.811107588892487,118.31289975882244,0.0017108877973651
0.0023700531797775995,120.693098401529,0.0056252192711763,24.33172863774825,120.90693309224592,0.0017701549559532
0.0024326044255333994,123.307645082191,0.0058238194764509,24.858821248569708,123.53382507117526,0.00183259362492
0.0024920503578204994,125.851670858539,0.0060125603114625,25.37169684508146,126.08999865738475,0.0018919289563556
0.0025374245412081997,128.380819541854,0.0061566233437184,25.88157321963777,128.62976201444522,0.0019372163506773
0.0025945345584257994,130.865464382613,0.0063379476483843,26.38247761953478,131.12669854394795,0.0019942142161187
0.0026593150698887994,133.360771356302,0.0065436257722793,26.88553150543048,133.63562583833607,0.0020588635802767
0.0027136829789220994,135.867667739955,0.00671624388346,27.39092181637493,136.15507573756713,0.0021131181965453
0.0027647432927813994,138.337492418692,0.0068783603799633,27.888838471608302,138.63718852165772,0.0021640694298088
0.0028142921805749998,140.762524611025,0.007035678098708,28.37772496158264,141.0744489611115,0.0022135099841047
0.0028615263305644995,143.155043300035,0.0071856465249247,28.86005672928706,143.47903118646474,0.0022606385858911
0.0029202522654279994,145.550580719994,0.0073721013681163,29.34299707315079,145.88853777046833,0.0023192301960644
0.0029820818650986994,147.987017481758,0.0075684103470708,29.83418272432241,148.33978172564494,0.0023809146622915
0.0030341227757481994,150.365505680168,0.0077336402383829,30.313685945121872,150.73176480621305,0.0024328304677119
0.0030912100137662993,152.746086262689,0.0079148922190904,30.793610990558104,153.12686384053373,0.0024897773694554
0.0031488094484975995,155.106142593265,0.0080977704243623,31.269398346802223,155.50173753314803,0.0025472319222544
0.0032038797942459995,157.468930713671,0.0082726187721134,31.745736431876075,157.87922376319747,0.0026021606609568
0.0032618341098427997,159.81312763509,0.0084566237241333,32.21832653123415,160.23879046551107,0.0026599626955847
0.0033247587533258996,162.161012553974,0.0086564094671921,32.691660130881154,162.60313290807846,0.0027227182151061
0.0033725823395439995,164.404209764089,0.0088082493534346,33.14388868844034,164.86030843317764,0.0027704106309754
0.0034256853782001994,166.624280245126,0.008976851501168,33.5914548974174,167.0953862042597,0.0028233653538824
0.0034794468738573994,168.803946294727,0.0091475442498796,34.030875573016964,169.29029009576175,0.0028769738383102
0.0035330026905853996,170.950118889781,0.009317583967991,34.463543968179856,171.4518014368971,0.0029303743719485
0.0035839472877696997,173.045860116668,0.0094793330640512,34.88604539952027,173.56250872876285,0.0029811686108612
0.0036389418024522996,175.199101742715,0.0096539406481684,35.32013891133134,175.73181409856903,0.0030359979186045
0.0036889755366092997,177.26932173264,0.0098127977541169,35.73749526130023,177.81719826875712,0.0030858787367343
0.0037446797174180996,179.362967753302,0.0099896585281848,36.15957429906569,179.9273062731311,0.0031414097442742
0.0038001771912661996,181.429120069055,0.0101658630076526,36.576110605921485,182.01002828329783,0.0031967316210845
0.0038564716952300994,183.500542547232,0.0103445980577379,36.99370937752197,184.0984132105479,0.0032528448795823
0.0039066986343939,185.576080234058,0.010504068589583,37.412137775186096,186.1900342105508,0.0033029074505905
0.0039667853289108,187.62237177826,0.0106948438446742,37.82467015049722,188.254369248476,0.0033627942184564
0.0040279026930937,189.599026228332,0.0108888914759549,38.22316368763173,190.24926976236256,0.0034237045476309
0.0040828855483095,191.573101345752,0.011063462041265,38.62113723130361,192.24064834885948,0.0034784979784882
0.004139389146923,193.509826425368,0.0112428609668629,39.01158100735419,194.19505605504432,0.0035348037856957
0.0041914726588949,195.442462420592,0.0114082261173737,39.40120042399135,196.14471495735748,0.0035867021709321
0.004249378990945999,197.345814907783,0.0115920787216359,39.784916285409054,198.06633403275825,0.0036443995177136
0.004313109432382899,199.181435495288,0.0117944228731981,40.15497739585007,199.92135048071228,0.0037078961067183
0.0043771509536185,200.964299340631,0.0119977547031211,40.51440274707121,201.7237073304179,0.0037716985729196
0.0044429493357392,202.697857226106,0.0122066645663543,40.86388801678297,203.47715321082347,0.0038372471024512
0.004514812673802899,204.33636717399,0.0124348306647066,41.19421162227638,205.1366468982262,0.0039088326492212
0.0045880048178583,205.880206969069,0.0126672157220825,41.50544972496431,206.70160192799315,0.0039817365982993
0.004672551365370399,207.377392833938,0.0129356510104334,41.8072823953219,208.22229411934063,0.0040659436275389
0.0047642270264388,208.736163757306,0.0132267212343256,42.0812106134729,209.60573700125576,0.0041572431293714
0.004862646333288,210.018585213902,0.0135392025335718,42.33974677912264,210.91417077642964,0.0042552493297658
0.004961366842281899,211.163369497094,0.0138526401496274,42.57053529061415,212.08468293659828,0.0043535458196287
0.005064108580389899,212.200929890396,0.0141788451681203,42.77970746590383,213.1485721358912,0.0044558360072917
0.005175296859604899,213.150299970863,0.0145318679546279,42.97110047412598,214.12588170745067,0.0045665238258009
0.0053009829499555995,213.966315726406,0.0149309212914914,43.13560925044345,214.9725249292852,0.0046916294500728
0.005428791385196899,214.601009872081,0.0153367130733825,43.263563590211525,215.63763164016487,0.0048188315693861
0.005559477065311399,215.178532292305,0.0157516401077461,43.37999211012869,216.2460645126456,0.0049488805553843
0.005702820221735499,215.618331236065,0.0162067546293926,43.4686555771907,216.7189527755743,0.0050915059046168
0.005856274583348399,215.974566571835,0.0166939722275135,43.540472620881935,217.1101487501656,0.005244169284455
0.0060118818065825995,216.250130193131,0.0171880251612821,43.59602624693522,217.42081135183653,0.0053989506337834
0.006181655238085299,216.470781971025,0.0177270558063032,43.64050964535864,217.67940862690983,0.0055677956816708
0.006339730158827,216.672059121843,0.0182289436796581,43.68108711896355,217.91605999198083,0.0057249805650082
0.0065089972544619,216.860297005974,0.0187663667082989,43.71903587640436,218.14208593765423,0.00589326721743
0.0066763299501872,216.959595093371,0.0192976480172267,43.7390543708236,218.2782753768582,0.0060596028424105
0.0068434998823631,217.05967675075,0.0198284125518852,43.7592308329512,218.4152511819288,0.0062257490510932
0.007011267187265399,217.189207979394,0.02036107374495,43.78534432864584,218.5820286031029,0.0063924612261987
0.007188152769517699,217.287246347974,0.0209226854686011,43.80510886375156,218.71913066661247,0.0065682042369161
0.007356744977598799,217.355494095272,0.0214579657292586,43.81886760960684,218.8244725971184,0.0067356787010058
0.007532590150424999,217.420417093645,0.0220162741529818,43.83195608607883,218.9280667028385,0.0069103281651921
0.0077100258504313995,217.423459915036,0.0225796325005021,43.83256951887126,218.9697093077507,0.0070865264292268
0.0078913902364323,217.440532612153,0.0231554644260549,43.836011374610045,219.02633938937603,0.0072665939018104
0.0080643484916678,217.466563453391,0.0237046068864276,43.84125919220362,219.0901727124792,0.0074382851552067
0.008238177410894,217.51779902923,0.0242565137049708,43.85158828429277,219.1796016979631,0.0076108109988338
0.0084091743819865,217.504592753351,0.0247994290881895,43.84892589907557,219.2034871547187,0.0077804970867116
0.008583192345378,217.529656603014,0.0253519361219575,43.853978771167625,219.26660084201583,0.0079531514517765
0.0087614539359814,217.506489371093,0.0259179166721233,43.84930825721235,219.28202167571223,0.0081299852877673
0.0089322887963639,217.595502653133,0.0264603173538378,43.86725333487161,219.40893448147,0.0082994225384844
0.0091049042943644,217.689590946103,0.0270083715599893,43.88622153473437,219.5413834994933,0.0084705967048978
0.0092889936835324,217.774616471803,0.0275928553705977,43.90336268071548,219.6672222972184,0.008653116675001
0.0094789567855413,217.827738512084,0.028195988219476,43.914072084036135,219.7621852361665,0.0088414253643402
0.0096641897422977,217.910172202698,0.0287841028571776,43.93069071606392,219.8857151350784,0.0090250109634816
0.0098410717773107,217.940027401498,0.0293457033183438,43.936709524142,219.9543906724637,0.0092002884561637
0.0100165069241014,218.018283812739,0.0299027099094043,43.95248601664818,220.071618457085,0.0093741018447394
0.010198256933956,218.043865559592,0.0304797661906927,43.95764329681375,220.13707061205537,0.0095541398643109
0.0103782425250147,218.107534625269,0.031051220442304,43.97047898045424,220.2406071096081,0.0097323981474935
0.010555503315303,218.130059487463,0.0316140234514694,43.97501999267254,220.30201816970143,0.0099079267270171