File: example/data/02 processed data/test_ID_112.csv
Strain,Stress_MPa,Displacement(mm),Force(kN),True Stress (MPa),True Strain
0.0010738409108660145,-0.453991782090731,-0.0002187428040717,-0.0915247432694913,-0.4539605041583089,-6.889774475634156e-05
0.0010779024012981145,-0.483628726469833,-0.0002058475719497,-0.0974995512563183,-0.4835973709425672,-6.483598273594248e-05
0.0010630191641525146,-0.391741740979957,-0.0002531018498872,-0.0789751349815593,-0.3917105124573365,-7.972029565308113e-05
0.0010362921026702146,-0.131462203153015,-0.0003379602700934,-0.0265027801556478,-0.1314482097666576,-0.0001064498451406
0.0009943861348218146,0.336416069352207,-0.0004710117180121,0.0678214795814049,0.336366161978729,-0.0001483611523769
0.0009548471779969145,1.01076108275625,-0.0005965479059312,0.20376943428366,1.0105711717618202,-0.0001879067575993
0.0009031669940070145,1.91345193363492,-0.0007606324900991,0.3857519098207999,1.912993529317136,-0.0002395979895262
0.0008629762131724145,3.13223061267994,-0.0008882382192489,0.631457691516276,3.131354339627441,-0.000279799209203
0.0007967219939966146,4.70861045514739,-0.0010985953651321,0.949255867757714,4.706981208652198,-0.0003460741649869
0.0007541128645482146,6.43409710753596,-0.0012338793511308,1.2971139768792497,6.431596666728351,-0.0003886989513294
0.0007354684022423145,8.24405980640723,-0.001293075518952,1.6620024569716978,8.240702265647407,-0.0004073508360722
0.0007193081326086145,10.1058481526925,-0.001344384375039,2.037338987582808,10.10156905210888,-0.0004235178206312
0.0007151227397536146,12.0627583095372,-0.0013576729973536,2.4318520752027,12.057600110724456,-0.0004277049952162
0.0007195880705319145,14.1575078538927,-0.0013434955721325,2.854153583344768,14.151517129762263,-0.0004232377641633
0.0007300898527088145,16.2946769962423,-0.0013101524137209,3.285006882442447,16.287953055959644,-0.0004127315914849
0.0007630802005193147,18.4466607659775,-0.0012054080594225,3.718846810421064,18.439657379030496,-0.0003797281693243
0.0007895147240152146,20.7305248608229,-0.0011214784473231,4.179273811941896,20.723202392529007,-0.0003532839556404
0.0008201810113881145,23.0836399127793,-0.0010241129849141,4.653661806416308,23.07619416305528,-0.0003226073029796
0.0008542658307750146,25.5343058068623,-0.0009158936833607,5.14771605066344,25.52693991413868,-0.0002885120670563
0.0008835442405650145,28.0574186442351,-0.0008229347322774,5.656375598677796,28.05014638461293,-0.0002592256377248
0.0009189266570172145,30.6001494732463,-0.0007105955600417,6.168990133806455,30.593300865261323,-0.0002238346743216
0.0009713739258161145,33.1648578081849,-0.0005440754816052,6.686035334130075,33.159174600000846,-0.0001713770406172
0.0010107915298174146,35.7262595129169,-0.0004189245889011,7.202413917804047,35.72154562045093,-0.0001319534578844
0.0010586325403034147,38.2977566036793,-0.000267029380608,7.720827731301746,38.29453561904164,-8.410727884181842e-05
0.0010996652032757145,40.8696890361355,-0.0001367506756709,8.239329309684916,40.8679287345323,-4.3072006537073485e-05
0.0011391052717078147,43.4332027499379,-1.1528458399103288e-05,8.756133674387481,43.43304504352182,-3.631017111501749e-06
0.0011840084585371144,46.0067964994317,0.0001310391597841,9.274970174285432,46.00869530004828,4.1271324637057056e-05
0.0012345608733591146,48.592773580189,0.0002915430768439,9.796303153766102,48.59723559175496,9.18203755121786e-05
0.0012760090581155144,51.1680731019099,0.0004231410634453,10.315483537345036,51.17489241304904,0.0001332638958608
0.0013008980530827144,53.7617537731014,0.0005021636224662,10.838369560657243,53.770256827282445,0.0001581492646012
0.0013410092048567147,56.3116289538591,0.0006295165293486,11.352424397097996,56.32279402510981,0.0001982532691513
0.0013865063158402147,58.877946308294,0.0007739698567212,11.86979397575207,58.89229898724464,0.0002437403265261
0.0014485745212816144,61.4642729664254,0.0009710364089977,12.391197430031362,61.483071091434205,0.0003057914800737
0.0015012526990288147,64.0618618795262,0.001138289623345,12.914871354912483,64.08482910870089,0.0003584521651474
0.0015502386021124144,66.6267536586153,0.0012938198656355,13.431953537576844,66.65390421529762,0.0004074193133644
0.0015977248427498144,69.1513255229144,0.0014445886796592,13.940907225419544,69.1827885849723,0.0004548850846131
0.0016796305380179146,71.6656238156636,0.0017046392621354,14.44778976123778,71.70410067742787,0.0005367501796364
0.0017407868522341147,74.2094484095242,0.0018988105597719,14.960624799360078,74.25382941244541,0.0005978718090333
0.0017891729925880147,76.7410387527898,0.0020524365553955,15.470993412562423,76.79064697743084,0.0006462278601514
0.0018468476584323147,79.2384234948672,0.0022355536194511,15.97446617656523,79.29421617028251,0.0007038636060884
0.0018987905374447146,81.7266459387496,0.0024004722603155,16.47609182125192,81.78843571717624,0.0007557685901754
0.0019530698123301146,84.2167931935581,0.0025728089580767,16.978105507821315,84.28503688488058,0.000810005387146
0.0020137787644166146,86.7146366524001,0.0027655598809513,17.48167074912386,86.79016878475196,0.0008706633448336
0.0020699364966709146,89.2098790798863,0.0029438606808587,17.984711622505078,89.29259449889966,0.0009267706298448
0.0021277939663051147,91.6956351042472,0.0031275581469473,18.48584003701624,91.78596059420305,0.0009845728331354
0.0021915271454321147,94.1784441522853,0.0033299109906755,18.98637434110072,94.27721764402304,0.0010482412663087
0.0022349944045098147,96.6660138875939,0.0034679195382472,19.48786839973893,96.7715981264113,0.0010916620423889
0.0022893426142057147,99.1424553566348,0.0036404751040317,19.98711899989757,99.2561327237146,0.0011459494809899
0.0023471484517746145,101.613120447508,0.0038240086383129,20.48520508221761,101.73550452636066,0.0012036874470616
0.0024007198680469147,104.093685275981,0.0039940978849775,20.98528695163777,104.22463342344568,0.001257192987439
0.0024446773313598147,106.532597172304,0.004133662830996,21.476971589936483,106.67129633363332,0.0013010942587859
0.0024922548993826146,108.955876967295,0.0042847216094683,21.96550479660667,109.10291495171089,0.0013486088353261
0.0025492791191890143,111.371744098773,0.0044657735073537,22.45254361031264,111.52839322767508,0.001405554582159
0.0025793863286745146,113.777153165864,0.0045613638974701,22.937474078238186,113.94061111824438,0.0014356190521032
0.0026329602061889146,116.14640695633,0.0047314609585783,23.415115642396128,116.31949111065852,0.0014891146422054
0.0026840973373902146,118.494436486565,0.0048938213501425,23.888478395691504,118.67707919621886,0.0015401743774544
0.0027411712140833146,120.835654037889,0.0050750309086431,24.360467854038426,121.02880196831684,0.0015971587944411
0.0027987472073247146,123.168589762146,0.0052578346871845,24.830787696048635,123.37255829242098,0.0016546412509273
0.0028450984375097146,125.466030927887,0.0054049998430219,25.29395183506202,125.67961955071216,0.0017009147792346
0.0028939059718752144,127.749481551472,0.0055599637646324,25.754295480776754,127.97319257143316,0.0017496381797021
0.0029700366805631147,130.022609467224,0.0058016787647164,26.21255806859236,130.26019983329613,0.0018256329159815
0.0030294422668325147,132.252119394653,0.0059902915011218,26.66202726996205,132.50164025979163,0.001884928390383
0.0030848811700307146,134.482356791367,0.0061663100187761,27.11164312913959,134.7435410131091,0.0019402613627455
0.003124931787917914,136.689371420097,0.0062934707305679,27.556577278291552,136.9603164778016,0.0019802335484067
0.0031704893354581147,138.883124784559,0.0064381159440081,27.99883795656709,139.1647454648831,0.002025699937015
0.0032276703109255147,141.046322296113,0.0066196655411171,28.434938574896385,141.34039457309092,0.0020827635700648
0.0032747980830828147,143.195749200914,0.0067692962177165,28.868263038904267,143.50105138783016,0.0021297921824994
0.003327838479372015,145.30835486755,0.0069376994759347,29.294164341298085,145.6258684730346,0.0021827183333645
0.0033673116012610145,147.422162845691,0.0070630266379323,29.720308029691303,147.75011455063608,0.0022221046148586
0.0034151353021728142,149.477209908447,0.0072148668883272,30.13460551754292,149.81688177374716,0.0022698210260411
0.003468599712430515,151.476601140634,0.0073846163908954,30.537682789951816,151.82891502775848,0.0023231627965812
0.0035202636157872147,153.470290177826,0.0075486492840529,30.939610499849724,153.83516998761317,0.0023747054872418
0.003566859542292514,155.435889158498,0.0076965913507073,31.3358752543532,155.812684912856,0.0024211898130103
0.0036233182680416144,157.383558304864,0.0078758478049607,31.728525354260587,157.77396112445842,0.0024775104207842
0.003679236313318514,159.315233127494,0.0080533875987148,32.11795099850279,159.7193362212752,0.0025332885443652
0.003737260744541715,161.213776538304,0.0082376151678485,32.50069735012209,161.63204962519472,0.0025911644941466
0.003786088222512715,163.103870788153,0.0083926424104064,32.88174035089164,163.53501172146895,0.0026398644300049
0.003838137819436715,165.033992992384,0.0085578998806401,33.27085298726461,165.4788258707875,0.0026917754568531
0.0038947109382249144,166.936258936397,0.0087375195327926,33.65434980157764,167.39566329015702,0.0027481949066722
0.003955951328335915,168.847518203289,0.0089319577713951,34.03965966978306,169.32252258199662,0.0028092653624664
0.004011007781341415,170.703483147695,0.0091067620096875,34.41382220257532,171.19310708320705,0.0028641658572745
0.004065784158861614,172.54576100031,0.0092806770083142,34.785225417662495,173.05012052062423,0.0029187840790254
0.004126562468144115,174.399552412702,0.0094736481402861,35.158949766400724,174.91993036400322,0.0029793834120124
0.004193573966126415,176.24337610525,0.0096864096463799,35.530664622818406,176.7810660386095,0.0030461933223435
0.004256451468688314,178.03513658489,0.0098860457170139,35.89188353551383,178.5894872933981,0.0031088776146092
0.004318956131300315,179.780429627731,0.010084498020807,36.24373461295057,180.35145179678943,0.0031711863183918
0.004390531252595715,181.506719877966,0.0103117490309199,36.59175472739794,182.0962164898737,0.0032425322759732
0.004459770131628815,183.231585768724,0.01053158247185,36.93948769097476,183.8393711409984,0.0033115446278954
0.004524559824737614,184.90300554821,0.0107372897474705,37.27644591851914,185.52831488545388,0.0033761180369974
0.004603823204624615,186.528557253244,0.0109889509786117,37.60415714225399,187.1741488034069,0.003455111145541
0.0046596690488571145,188.078548601474,0.0111662615340499,37.91663539805716,188.7400082117508,0.003510762820546
0.0047465687345591145,189.570219634645,0.0114421680361537,38.21735627834444,190.25339894416004,0.0035973542078329
0.004837838256539414,190.999349191906,0.0117319487684412,38.50546879708825,191.7051112641973,0.0036882918559108
0.004929244653059415,192.349270467887,0.0120221640773922,38.77761292632602,193.0776025906372,0.0037793575933125
0.005024397591307215,193.574964976206,0.012324274656329,39.02471293920313,194.32635742816063,0.0038741471006186
0.005136971646683115,194.714815601249,0.0126816972821474,39.2545068252118,195.49255240370704,0.0039862795841854
0.005246312267942014,195.740256425986,0.0130288537546444,39.46123569547878,196.54349144169333,0.0040951792809521
0.005393277916713914,196.66318495105,0.0134954696894952,39.64729808613168,197.4991100066552,0.004241533599391
0.0055214780418360145,197.462526285647,0.0139025050867579,39.80844529918643,198.32716369545184,0.0043691829634186
0.0056527073949373145,198.174063057923,0.0143191582828545,39.95189111247728,199.06782235760264,0.0044998316672986
0.005787403286363415,198.769503696362,0.0147468177381324,40.07193194518658,199.69272185160904,0.0046339138221238
0.005932179872929214,199.262537086162,0.0152064834004788,40.17132747657026,200.2168937672764,0.0047780106960179
0.006083688381090914,199.682321287479,0.0156875229138922,40.25595597155577,200.6689420719504,0.0049287856544636
0.006231762303568814,200.011568611724,0.0161576576177595,40.32233223212356,201.0294326889584,0.0050761206936
0.0063849379111129145,200.278910860798,0.016643990171712,40.37622842953688,201.328813293544,0.0052285091216697
0.006543342625385714,200.507406219693,0.0171469251395282,40.42229309389011,201.5902677895733,0.0053860753626473
0.006709488477155315,200.675669583983,0.0176744382188967,40.456214988130974,201.7927813081083,0.0055513150931106
0.006875280391098714,200.848579678273,0.018200827545667,40.49107366313984,201.99995302048293,0.0057161756035515
0.007033451624365714,201.002439789064,0.0187030212112897,40.5220918614753,202.18648794493672,0.0058734329158736
0.007197269058040715,201.132138147074,0.0192231415632078,40.548239050450114,202.3498992697549,0.006036277739002
0.007371023280222614,201.225432963323,0.0197748112186353,40.56704728540591,202.47872271111447,0.0062089713791866
0.007534320087846315,201.333483923686,0.0202932785828406,40.5888303590151,202.62032375906148,0.0063712442557996
0.007708135484122815,201.445324214025,0.0208451424660185,40.61137736154744,202.7678931848453,0.0065439408391602
0.007865665627635614,201.540254266933,0.0213453006716716,40.63051526021369,202.8951951566252,0.0067004312350965
0.008036093065791415,201.575690646145,0.0218864077878163,40.637659234262834,202.96522380066227,0.0068697062253088
0.008206411765823814,201.574036867492,0.0224271696604192,40.63732583248639,202.9978904498425,0.0070388445909339
0.008378947159486113,201.600702123782,0.022974969535297,40.642701548154456,203.0595273173532,0.0072101551244374
0.008554017365961314,201.66989655821,0.0235308174408557,40.65665114613514,203.16452884773048,0.0073839524836423
0.008740183769175316,201.714312566582,0.0241218957710602,40.66560541342293,203.24682646367245,0.0075687322328354
0.008900696442277915,201.75052511061,0.0246315235081609,40.672905862298975,203.3156976466874,0.0077280219271821
0.009085277976006514,201.809776856884,0.0252175698777492,40.68485101434782,203.4126594237821,0.0079111657365673
0.009273613487123515,201.846785323589,0.0258155351255457,40.69231192123554,203.4879767492581,0.0080979997178096
0.009465223260570015,201.942549735815,0.0264238961562383,40.711618026740304,203.62321397636464,0.008288046041148
0.009654866365243715,201.994123044934,0.0270260130135773,40.722015205858696,203.71352329629727,0.0084761061861181
0.009833674264663514,201.999665474816,0.0275937280942352,40.723132559722906,203.7552320399305,0.0086533891802984