File: example/data/02 processed data/test_ID_149.csv
Strain,Stress_MPa,Displacement(mm),Force(kN),True Stress (MPa),True Strain
4.96154106919372e-05,0.0285484792820402,0.00015752892894690062,0.005755373423259305,0.028549895726564408,4.9614179888149755e-05
1.06731998565282e-06,1.18193769293886,3.3887409544477035e-06,0.2382786388964742,1.1819389544445817,1.0673194161402746e-06
-5.27149301649726e-05,3.19392025365453,-0.000167369903273788,0.6438943231367533,3.1937518863714063,-5.271631964577212e-05
-0.0001472916845019,6.27599443587093,-0.0004676510982935325,1.2652404782715796,6.275070034078547,-0.00014730253298732935
-0.0002624217654335,9.4786646478656,-0.0008331891052513624,1.910898793009705,9.476177239954755,-0.0002624562040500316
-0.0003317235239784,12.5288300561609,-0.00105322218863142,2.525812139322037,12.524673948503343,-0.00033177855639724877
-0.0003923608396055,15.441736798157,-0.0012457456657474625,3.1130541385084514,15.435678065341909,-0.00039243783325989325
-0.0004331086449232,18.5451435443648,-0.00137511994763116,3.738700938543944,18.537111482374396,-0.00043320246356242645
-0.000442662744769,21.7868253337227,-0.001405454214641575,4.392223987278497,21.77718111782067,-0.0004427607488447126
-0.0004658730895975,25.0125044366063,-0.0014791470594720624,5.04252089441983,25.00085178388585,-0.0004659816421810459
-0.0004455904047436,28.2176313655689,-0.00141474953506093,5.688674483298691,28.20505785978781,-0.000445689709648605
-0.0004332140178077,31.3718516076855,-0.0013754545065394475,6.324565284109397,31.358260881804465,-0.00043330788211019404
-0.0004143485714327,34.5140046317754,-0.0013155567142988224,6.9580233337659205,34.4997038032618,-0.0004144344375218809
-0.0003799264398987,37.6904904103306,-0.0012062664466783724,7.598402866722648,37.676170796490965,-0.0003799986302338275
-0.0003322343911185,40.849067567177,-0.0010548441918012373,8.235172021542883,40.83549610208606,-0.00033228959319085737
-0.0002944354839185,43.965975039715,-0.0009348326614412374,8.863540568006544,43.95302989657823,-0.00029447883855589793
-0.0002570679089284,47.0246747274087,-0.0008161906108476699,9.480174425045595,47.01258619260849,-0.0002571009565471088
-0.0002101952882943,49.9578398284499,-0.0006673700403344024,10.071500509415499,49.9473389259046,-0.00021021738241996482
-0.0001662232711001,52.7406913556773,-0.0005277588857428175,10.632523377304544,52.73192462544008,-0.00016623708771909676
-0.0001010329658322,55.3400735650752,-0.000320779666517235,11.156558830719161,55.33448239331355,-0.00010103807000608143
-3.76321692202642e-05,57.8056215350933,-0.00011948213727433883,11.65361330147481,57.803446184161814,-3.763287732810384e-05
1.54028451066914e-05,60.1350843161042,4.8904033213745195e-05,12.123232998126607,60.1360105674934,1.5402726484103922e-05
7.79935582220292e-05,62.3558297304406,0.0002476295473549427,12.570935273656824,62.36069308347716,7.799051688259608e-05
0.0001352243333758,64.5283783740971,0.000429337258468165,13.008921080217977,64.53710418104656,0.00013521519138984004
0.0001880894165366,66.6422661601775,0.000597183897503705,13.435080857891785,66.65480086513625,0.00018807172994012952
0.0002670873150603,68.714682572139,0.0008480022253164525,13.852880006543222,68.73303539221241,0.000267051653593053
0.0003502123412007,70.6910209880989,0.0011119241833122224,14.251309831200738,70.71577785606101,0.0003501510311726652
0.0004224647760315,72.5149614080231,0.0013413256639000124,14.619016219857457,72.54559642495327,0.0004223755629134722
0.0005233994591841,74.2862298442952,0.0016617932829095176,14.976103936609913,74.32511121682053,0.0005232625334628826
0.0006136199839968,75.918173186136,0.0019482434491898397,15.30510371432502,75.96475809435154,0.0006134317962343151
0.0007347591782751,77.432574162449,0.0023328603910234423,15.610406951149718,77.48946845701234,0.0007344893749023637
0.0009039507590568,78.7882291843133,0.00287004366000534,15.88370700355756,78.85944986388918,0.000903542441616673
0.0010717371619863,79.948294172689,0.0034027654893065023,16.117576105214102,80.03397773059129,0.0010711632617244188
0.0012914619793621,80.9189628621012,0.004100391784474667,16.3132629129996,81.02346662604701,0.0012906287596438657
0.0015288753327602,81.6842196684874,0.004854179181513635,16.46753868516706,81.80910465701432,0.0015277077927326277
0.0017883801704836,82.2475787859809,0.005678107041285429,16.58111188325375,82.39466872495204,0.0017867829227072045
0.0020811480104364,82.6913229033387,0.00660764493313557,16.67057069731308,82.86341578547933,0.002078985421840528
0.0023765654997081,82.958776000192,0.007545595461573218,16.724489241638707,83.15593296513207,0.0023737459342918917
0.0026852378950558,83.1949174423745,0.008525630316802164,16.7720953563827,83.41831558736679,0.0026816390847807705
0.0030050963795505,83.3246702907754,0.009541181005072837,16.798253530620322,83.57506895579345,0.003000590103031611
0.0033364698905392,83.4188176976074,0.010593291902461959,16.817233647837654,83.69714207115983,0.0033309162245382983
0.0036693757909455,83.5114365604524,0.011650268136251961,16.835905610587204,83.81787140403439,0.0036626600549568285
0.0040222406205189,83.5865054170746,0.012770613970147508,16.85103949208224,83.92271045449039,0.004014173036654186
0.0043650493868715,83.6155166735465,0.013859031803317013,16.856888161386973,83.9805025333353,0.004355550191735222
0.0047179988750473,83.5913737172685,0.014979646428275178,16.852020941401328,83.98575772443021,0.004706904001735324
0.0050747385020335,83.5582548994386,0.01611229474395636,16.84534418772682,83.98229119273951,0.005061905414665551
0.005463072685634,83.5385970990008,0.01734525577688795,16.84138117515856,83.99497452700852,0.005448204231100304
0.0058377063003743,83.5232141689984,0.018534717503688403,16.838279976470076,84.01079816258027,0.005820732917994923
0.0062011182604775,83.4712352782863,0.01968855047701606,16.827801032102517,83.9888502795951,0.00618197044444718
0.0065714188717754,83.3669324981027,0.020864254917886894,16.806773591617507,83.91477153160275,0.006549921227403786
0.0069348837119985,83.2786920928681,0.02201825578559524,16.788984325922208,83.85622013821947,0.00691094800313777
0.0073174694154277,83.2067775173178,0.023232965393982948,16.77448634749127,83.81564056695707,0.00729082662900708
0.0077066727488487,83.1732978640536,0.024468685977594624,16.767736849393206,83.81428725213436,0.007677128043582648
0.0080949540385072,83.1126133670713,0.02570147907226036,16.755502854801577,83.78540615229797,0.008062365647621424
0.0084720129031777,83.0575071629718,0.026898640967589198,16.744393444055117,83.76117143536227,0.008436326815533047
0.0088566009783547,82.9690304582879,0.028119708106276172,16.726556540390842,83.7038540546179,0.008817611329310077
0.0092257241228814,82.8795896393439,0.029291674090148444,16.70852527129173,83.64421386877412,0.00918342707830309
0.0096100158165827,82.7369046528346,0.03051180021765007,16.679759978011454,83.53200761516342,0.009564133334627016
0.0099925804324336,82.6600363559729,0.03172644287297668,16.664263329364136,83.48602341780786,0.009942984719683997
0.0103736463164236,82.5145515297491,0.03293632705464493,16.63493358839742,83.37052830327703,0.010320209287649543
0.0107825356761058,82.4241242250919,0.03423455077163591,16.616703443778526,83.31286528512072,0.010724818658170546
0.0111737707825381,82.344586956044,0.035476722234558465,16.60066873033847,83.2646864958736,0.011111805370064587
0.0115794290373682,82.233865788799,0.03676468719364403,16.57834734302188,83.18608700216886,0.011512900531159614
0.0119782454794374,82.1389961482944,0.03803092939721374,16.55922162349615,83.12287720759323,0.011907074072398742
0.0123864315419532,82.0125310905451,0.039326920145701404,16.533726267853893,83.02837369248044,0.012310347329120765
0.0127835552942987,81.8821840619806,0.04058778805939837,16.507448306895288,82.92892948955487,0.012702535402237567
0.0131756948898428,81.7701522027386,0.041832831275250885,16.4848626840721,82.84753077925788,0.013089650395202431
0.013584808738288,81.6246304659624,0.0431317677440644,16.45552550193802,82.73348545917592,0.013493362479851233
0.0139840150363944,81.4975996027436,0.04439924774055222,16.429916079913113,82.63726326101842,0.013887140780823207
0.0144030089253859,81.3759425157422,0.04572955333810023,16.405390011173626,82.54800094210812,0.014300270908359307
0.0148124657361533,81.2649134166246,0.047029578712286725,16.38300654479152,82.46864716215981,0.014703832601473924
0.0152242755799888,81.1517737092727,0.04833707496646444,16.360197579789375,82.38725067602755,0.015109549247978915
0.0156263645825837,81.0165863018387,0.04961370754970325,16.332943798450682,82.28258101662757,0.015505530124068027
0.0160451746929979,80.8864383651358,0.05094342965026833,16.30670597441138,82.18427539899882,0.01591781144833757
0.0164452266059472,80.7480014533454,0.05221359447388235,16.27879709299443,82.07592063522301,0.016311468331400587
0.0168568716929363,80.6131669395582,0.053520567625072756,16.251614455014934,81.97205275141958,0.016716371363721727
0.0172590380443539,80.4402777087516,0.05479744579082363,16.21675998608432,81.82859952202533,0.017111792642059444
0.0176673001628391,80.306005420376,0.05609367801701414,16.189690692747803,81.72479572301637,0.017513047583132855
0.0180847250998503,80.1747973644564,0.057419002192024705,16.16323914867441,81.6247365347288,0.01792314167876073
0.0184926231291891,80.0604001500713,0.05871407843517539,16.140176670254377,81.54092695761865,0.018323713780917933
0.0189171666537234,79.9660685344129,0.06006200412557179,16.12115941653764,81.47879997952145,0.018740462078494353
0.0193333552913858,79.8405190803586,0.061383403050149915,16.095848646600295,81.38410420238783,0.01914884038034241
0.019759603966951,79.7286308298986,0.06273674259506942,16.07329197530756,81.30403699992463,0.01956691713337963
0.0201851272689978,79.5923090444067,0.06408777907906801,16.04580950335239,81.19888993210147,0.01998410815008028
0.0206395923368111,79.4634500848524,0.06553070566937524,16.019831537106242,81.10354330028028,0.02042948209225118
0.0210660569871905,79.3458855354728,0.06688473093432983,15.996130523951317,81.01739048186217,0.020847235412102046
0.0214976109817342,79.216690097384,0.06825491486700609,15.970084723632615,80.91965968435817,0.021269796537351296
0.0219239613815931,79.078545452759,0.06960857738655808,15.942234763276215,80.81226042937784,0.021687087234299945
0.0223623164602174,78.918187205984,0.07100035476119024,15.909906540726375,80.6829806827509,0.02211594603954078
0.0228085666383789,78.7816424251004,0.07241719907685301,15.882379112900242,80.57853876623423,0.022552340072852405
0.0232368073923453,78.633950673017,0.07377686347069633,15.852604455680227,80.46115263930507,0.022970943458344408
0.0236869520919205,78.5127553509402,0.07520607289184758,15.828171478749544,80.3724832255426,0.023410769030494948
0.0241154437460944,78.3813939466052,0.07656653389384971,15.801689019635608,80.27159604306502,0.02382925829615689
0.0245658456567253,78.2520594334319,0.07799655996010282,15.77561518177987,80.17438744779447,0.02426895764833742
0.0249891194775237,78.0937687091299,0.07934045434113773,15.743703771760588,80.04526322585247,0.024681997390151245
0.0254139473775539,77.972625477676,0.08068928292373363,15.719281296299483,79.95421767845538,0.025096382164517362
0.0258636096238862,77.8243231459503,0.08211696055583868,15.689383546223581,79.83714105904033,0.025534803822279052
0.026315270837353,77.7201644122851,0.08355098490859578,15.668385145516677,79.765391588318,0.025974981065169305
0.0267447970508606,77.5670700715539,0.0849147306364824,15.637521326425267,79.6415856184475,0.02639340644540286
0.0271764684553158,77.4310906271366,0.08628528734562767,15.610107870430738,79.53539421902568,0.026813745255911885
0.0276196238589652,77.323688282922,0.08769230575221451,15.588455557837076,79.45933946868419,0.02724508285887685
0.0280688093234847,77.2176097940612,0.08911846960206392,15.56707013448274,79.38501615978595,0.027682099932493383
0.0285102498133697,77.0959874289306,0.09052004315744878,15.542551065672408,79.29401329013783,0.02811139584961706
0.0289648531426096,76.9265427609144,0.09196340872778548,15.508391020600344,79.15470877475298,0.028553299944577535
0.0294136616525077,76.7826120393523,0.09338837574671195,15.479374587133425,79.04106981067358,0.02898937961970487
0.029871229817304,76.6469836594692,0.0948411546699402,15.45203190574899,78.93652332316435,0.029433774831093017
0.030342972252852,76.5273903585485,0.0963389369028051,15.42792189628338,78.84945884078112,0.02989172958484494
0.0308012969171238,76.4354829110354,0.09779411771186806,15.409393354864735,78.78979491518194,0.03033645796090413
0.0312658462504631,76.3037188205465,0.09926906184522034,15.382829714222174,78.68941916152826,0.030787024609752144
0.0317319707383589,76.1978719880033,0.10074900709428951,15.361490992781464,78.61578063225184,0.031238915049954633
0.0322085063083819,76.0734662295373,0.10226200752911253,15.336410791874721,78.52367894649183,0.03170068764833168
0.0326693474412591,75.9444746827762,0.10372517812599763,15.310406096047682,78.42553111243173,0.032147049296011566
0.0331279119347849,75.799271899448,0.10518112039294204,15.281133214928719,78.31034350365373,0.03259100815884419
0.033600572426948,75.6919708130259,0.1066818174555599,15.259501315906023,78.23526436046741,0.03304840786468855
0.0340590379904872,75.575072076233,0.10813744561979685,15.235934530568572,78.14908632721124,0.03349187115888161
0.0345182951888759,75.462075790062,0.10959558722468098,15.2131544792765,78.06689799774868,0.03393590310157767
0.0349877260401717,75.3041055669185,0.11108603017754515,15.18130768229077,77.938824982194,0.034389567748630216
0.0354418671219075,75.1451932257652,0.11252792811205631,15.149270954314263,77.80847917892282,0.034828260366354585
0.0359265224881633,75.0051169132631,0.11406670889991846,15.121031569713839,77.69978993277476,0.035296217082823926
0.0364030712741858,74.877411873567,0.1155797512955399,15.095286233711107,77.60317963482703,0.03575613310762714
0.0368686146552238,74.7942086253144,0.11705785153033556,15.078512458863385,77.55176748156353,0.03620522368463322
0.0373547601317373,74.6689979479103,0.11860136341826592,15.053269986298718,77.45824045553167,0.036673973088698714
0.0378347335450502,74.5689128354043,0.12012527900553438,15.033092827617509,77.3902077832759,0.03713655582953689
0.0383031060675782,74.4501185439813,0.12161236176456079,15.009143898466633,77.30178933131519,0.03758775181617843
0.0387948906122948,74.3349979859493,0.12317377769403598,14.98593559396738,77.21881610147936,0.03806128224631902
0.0392674063966719,74.2081287099688,0.12467401530943328,14.96035874792971,77.12208945795967,0.038516048008828276
0.0397500662401298,74.0886546609304,0.12620646031241212,14.936272779643568,77.03368359134448,0.03898036334862881
0.0402529460579511,73.9856799414959,0.12780310373399473,14.915513076205576,76.96382152524177,0.03946390094414777
0.0407343728157752,73.8738991240374,0.12933163369008627,14.892978063405938,76.8831060723109,0.039926591669887955
0.0412138297489313,73.7515542125653,0.13085390945285688,14.868313329253166,76.79113821160104,0.040387176559599815
0.0416910528126703,73.5847351183052,0.1323690926802282,14.83468259985033,76.65256019632882,0.04084540494639253
0.0421411671624744,73.4485088218663,0.1337982057408562,14.807219378488247,76.54371470996306,0.04127741127827455
0.0426301490947344,73.3350513804748,0.13535072337578172,14.78434635830372,76.46133555469446,0.04174651015488872
0.043150769910861,73.2378123201327,0.13700369446698368,14.764742963738755,76.39808030833358,0.04224571965689796
0.0436420802331121,73.1151600708588,0.1385636047401309,14.740016270285135,76.30605775292806,0.042716595653329595
0.0441877632932166,72.9636386261845,0.1402961484559627,14.709469547038795,76.18773861881014,0.04323932318711006
0.0446574740957989,72.8328709173764,0.1417874802541615,14.683106776943083,76.0854029636918,0.043689055701603544
0.0451449020424113,72.6841285199411,0.14333506398465587,14.653120309620126,75.96544638201188,0.044155538045596215
0.0456339397654075,72.5702922959258,0.1448877587551688,14.630170926858641,75.88196064331609,0.044623342408387494
0.0461372274479889,72.4372117759673,0.14648569714736476,14.603341894035006,75.77926389137325,0.04510454962663567
0.0466372236174704,72.3548151506978,0.1480731849854685,14.586730734380678,75.72924284468162,0.04558238055460803
0.0471318301174919,72.2658543565366,0.14964356062303677,14.568796238277779,75.67187632736429,0.046054836204231384
0.0476518415400139,72.1928537884259,0.15129459688954414,14.55407932374666,75.63297621747337,0.04655131843315034
0.048118110505411,72.086790495269,0.15277500085467993,14.53269696384623,75.55547064630076,0.046996280412526896
0.0486364720151021,71.9525259767132,0.15442079864794916,14.505629236905381,75.45204299279551,0.047490722179410645
0.0491549955758907,71.8522582030913,0.15606711095345296,14.485415253743206,75.384155637182,0.047985074053140106
0.0496656765900125,71.736727204719,0.15768852317328969,14.462124204471351,75.29958029769453,0.0484717102207483
0.0502264455934659,71.6428787561649,0.15946896475925423,14.443204357242845,75.2412459081707,0.04900580338759212
0.050756805395404,71.5255591984274,0.1611528571304077,14.419552734402965,75.15596808745943,0.04951067158485517
0.0512791521265983,71.4248879882465,0.1628113080019496,14.399257418430494,75.08749568502103,0.05000766283762304
0.0518076832652661,71.3187735268396,0.16448939436721985,14.377864743010864,75.01363395658535,0.05051028701927864
0.0523302414978653,71.1937036598319,0.16614851675572231,14.35265065782211,74.91928736547835,0.05100698282727917
0.0528626791539574,71.0858180234454,0.16783900631381474,14.330900913526593,74.8436048140154,0.05151281548729032
0.0533940985014413,70.967680555381,0.1695262627420761,14.307084399964808,74.75693588137383,0.052017425717531866
0.0539340696033768,70.854285131847,0.17124067099072132,14.284223882580356,74.67574507784555,0.052529895604211646
0.0544621785666197,70.7691252334798,0.17291741694901755,14.267055647069528,74.62336596894905,0.05303085359514509
0.0549886147988473,70.6098729900686,0.17458885198634017,14.23495039479783,74.492612096915,0.05352997520993896
0.0554944934767102,70.4330917205114,0.17619501678855487,14.199311290855098,74.34174046953984,0.05400937131177717
0.0560069751741608,70.2711150218346,0.17782214617796052,14.166656788401855,74.20678761632308,0.054494790540816296
0.0565164917809272,70.1658774244579,0.17943986140444385,14.145440888770713,74.13140665921881,0.05497716777791332
0.0570384093611637,70.1084208889514,0.18109694972169474,14.133857651212603,74.10729369928018,0.05547104431792014
0.0575685614355796,70.0380371711371,0.18278018255796522,14.11966829370124,74.07002621685112,0.05597246334551725
0.0581057228821463,69.9527355400005,0.1844856701508145,14.102471484864102,74.01738980613584,0.056480255553505616
0.0586462272062552,69.8289465832861,0.18620177137986027,14.077515631190478,73.92415085018294,0.05699094773530196
0.0591958150215357,69.7359507825632,0.18794671269337584,14.05876767776474,73.86402722543872,0.057509955117967075
0.0597459415080985,69.6405230907755,0.1896933642882127,14.039529455100341,73.80126170995037,0.05802920157410762
0.060302986020084,69.5606668682797,0.19146198061376668,14.023430440645186,73.75538278998529,0.058554703148690726
0.0608627306763455,69.4634105798863,0.19323916989739695,14.003823572905079,73.69114342987032,0.05908247395400599
0.0614253522665619,69.3479673476476,0.19502549344633402,13.980550217285757,73.6076906709469,0.05961267681187298
0.061970616185633,69.2469593462633,0.19675670638938478,13.96018700420668,73.53823608593271,0.06012625406186041
0.0625225095543344,69.1535075337218,0.1985089678350117,13.941347118798316,73.47715836921465,0.06064580705492913
0.0630862206244372,69.0454834319551,0.20029875048258808,13.919569459882151,73.40130203286435,0.06117620672380017
0.0636661461702649,68.9459866058056,0.20214001409059107,13.89951089973041,73.33551186690396,0.06172156928622709
0.0642633553585792,68.8286617795988,0.20403615326348895,13.87585821476712,73.25182253039662,0.0622828747275634
0.064816870877278,68.712530566555,0.20579356503535765,13.85244616221749,73.16626178793842,0.06280283214800121
0.0653681038709732,68.5949979562938,0.2075437297903399,13.82875158798883,73.07892290773,0.06332037688006321
0.065911548518766,68.4667913176673,0.20926916654708205,13.80290512964173,72.97954355552595,0.06383034717791804
0.0664611761076894,68.3713457881243,0.2110142341419138,13.783663310885858,72.91538584126856,0.06434585517963624
0.0670066071978386,68.2391720389671,0.21274597785313756,13.757017083055766,72.8116474352879,0.06485716461331992
0.067562548401654,68.1331177350383,0.21451109117525144,13.73563653538372,72.73636479976741,0.06537805775461479
0.0681194791352786,68.0302064248375,0.21627934625450956,13.714889615247241,72.66438865196292,0.06589960613032621
0.0687013717862165,67.9464494713982,0.2181268554212374,13.698004213433876,72.6144637580861,0.06644424015060056
0.0692759115730062,67.8727089725605,0.21995101924429467,13.683138128868197,72.57465275756398,0.06698170124066151
0.0698542287472256,67.7656348836909,0.2217871762724413,13.661551992552084,72.4993510440572,0.06752240437733245
0.0704033704624694,67.5773033314424,0.22353070121834034,13.623584351618788,72.3349732527406,0.06803555917467723
0.0709604088296819,67.4319616293641,0.22529929803424,13.594283464479801,72.21696119477119,0.06855582423675025
0.0715292421974075,67.3094404039529,0.2271053439767688,13.569583185436906,72.12403366877922,0.06908682645729192
0.0721077301103736,67.2731057249301,0.22894204310043614,13.562258114145909,72.12401667623,0.06962655210532122
0.0726807929949359,67.2273434873665,0.23076151775892148,13.553032447053086,72.11348012297124,0.07016092917049649
0.0732672277084949,67.1137586021701,0.23262344797447132,13.530133734197491,72.03099763604826,0.07070747990005691
0.0738523648876457,67.0374824687581,0.2344812585182751,13.514756465701632,71.98835908518997,0.07125252377712289
0.0744468889961805,66.9290815541811,0.2363688725628731,13.492902841322909,71.91174345926153,0.07180600730381255
0.0750619030075848,66.8291781804179,0.2383215420490817,13.47276232117225,71.84550347107303,0.07237824411482222
0.0756530659245756,66.7258437198899,0.2401984843105275,13.451930093929803,71.77385837370365,0.07292798030991854
0.0762502705879942,66.613901033791,0.24209460911688158,13.429362448412265,71.69322901253942,0.07348302817718808
0.0768427752891237,66.5153353353428,0.24397581154296774,13.409491603605108,71.62655830179725,0.07403340357059757
0.0774239898534144,66.3865128173377,0.24582116778459068,13.383520983975282,71.52642151211082,0.07457299744801094
0.0780144052277104,66.282970916691,0.2476957365979805,13.362646936804907,71.45399746948227,0.07512083531747629
0.0786074216329649,66.1523469417325,0.24957856368466355,13.336313143453275,71.35241236979144,0.07567078469924991
0.079197681570897,66.0664726889466,0.25145263898759795,13.319000894091635,71.29878415547816,0.07621787762416546
0.0797949907986876,65.9675864737063,0.2533490957858331,13.29906543309919,71.23146942938733,0.07677119978285042
0.0803857694644729,65.8752336763809,0.25522481804970143,13.28044710915839,71.17066502410874,0.07731817130614303
0.0809966407169812,65.7529222517378,0.25716433427641533,13.255789125950342,71.0786880714534,0.07788343108238249
0.0815975949561032,65.6704587778779,0.25907236398562766,13.239164489620185,71.02901027381665,0.07843920270581302
0.0821971229961313,65.5659654260577,0.26097586551271684,13.218098629893232,70.95529915054347,0.07899334774590934
0.0827766847763598,65.4662518422591,0.26281597416494235,13.197996371399434,70.88533113449556,0.07952874618074685
0.0833680320880517,65.3243266096791,0.26469350187956414,13.169384244511306,70.7702871666052,0.0800747367803391
0.0839527520178039,65.1921601457051,0.2665499876565274,13.14273948537415,70.66522139992244,0.08061431536808372
0.0845840968557155,65.0947095961832,0.2685545075168967,13.123093454590533,70.60068681746142,0.08119659263588991
0.0852051225706453,65.0088476156478,0.2705262641617988,13.105783679314596,70.54793444491547,0.0817690221846477
0.0858333992617891,64.9392187272291,0.2725210426561804,13.091746495409389,70.513172615992,0.08234780206567163
0.0864622108008228,64.842805644069,0.27451751929261237,13.072309617844311,70.44925797458328,0.08292673943836085
0.0870565515454712,64.7119570009408,0.27640455115687107,13.045930531389665,70.34555682120151,0.08347363212662105
0.0876824493766776,64.6061709668466,0.2783917767709514,13.024604066916277,70.27099828206812,0.08404923945073897
0.0882935989591356,64.4720645961724,0.2803321766952555,12.997568222588356,70.16453521169433,0.08461096401475261
0.0888858344788521,64.3945300177207,0.2822125244703554,12.981937251572493,70.1182915542193,0.0851550032659307
0.0894927931761934,64.2805728377782,0.28413961833441403,12.958963484096085,70.0332208479967,0.08571226058138776
0.0901073647916957,64.1881234570589,0.28609088321363385,12.940325688943075,69.9719461126985,0.0862761911991598
0.0907265539176553,64.0631681831682,0.28805680868855554,12.91513470572671,69.87539866547424,0.08684403741366131
0.0913658626894126,63.9751960477683,0.29008661403888497,12.89739952323009,69.82034502539695,0.08742999682141482
0.0919972780580812,63.8759752300065,0.29209135783440776,12.877396606369311,69.7523910844725,0.08800838469880187
0.0926234315391912,63.7785375624394,0.29407939513693204,12.857753172587785,69.68592457002374,0.08858162241966165
0.0932421537962751,63.6661797928685,0.29604383830317343,12.83510184624229,69.60255152073644,0.08914773433226868
0.0938545882572988,63.5537908345843,0.29798831771692363,12.812444232252194,69.51860570555469,0.08970777766757725
0.0944774462873652,63.4318827057993,0.2999658919623845,12.78786755348914,69.42476499704291,0.09027703136130732
0.0950957191105541,63.3505398056695,0.30192890817600926,12.771468824822971,69.37490494453142,0.0908417741608556
0.0957570684518582,63.2621516331578,0.3040286923346498,12.753649769244612,69.31994981750593,0.09144551108480324
0.0963928424513902,63.1546637114913,0.30604727478316385,12.731980204236647,69.24232126070362,0.09202555719770407
0.0970319284958357,63.046120001071,0.3080763729742783,12.710097792215914,69.1636066089548,0.09260828615289328
0.0976458764912123,62.906021676685,0.310025657859599,12.681853970019697,69.0485352998801,0.09316777421077285
0.0982650916410692,62.7893638981068,0.3119916659603947,12.658335761858332,68.9593664956387,0.09373174531457049
0.098894357218334,62.6824628401538,0.31398958416821043,12.636784508575007,68.88140471159292,0.09430454452110655
0.0995327620707127,62.6040768489127,0.31601651957451277,12.620981892740799,68.83523353457214,0.09488532781359986
0.100168744857174,62.478795946095,0.31803576492152746,12.595725262732751,68.73721851620283,0.09546357245468341
0.100808627908194,62.3477806192268,0.32006739360851594,12.569312572836125,68.63297483657216,0.09604502601887363
0.101440683477305,62.2036489923241,0.32207417004044336,12.540255636852539,68.51362966088783,0.09661903513146376
0.102089002630477,62.0658530828508,0.3241325833517645,12.512475981502721,68.40209412148876,0.0972074721068915
0.102705423426959,61.9773055117823,0.32608971938059483,12.494624791175312,68.3427109172319,0.09776663608631554
0.103316485878504,61.8349131207407,0.32802984266425017,12.465918485141326,68.22347904897823,0.09832063100775837
0.103926664927131,61.7484366365695,0.3299671611436409,12.448484825932413,68.16574572067245,0.09887351895211363
0.104555649462913,61.6497369595383,0.3319641870447488,12.428586971042922,68.09556524656058,0.09944312691201429
0.10520764868135,61.5592887217046,0.33403428456328627,12.410352606295646,68.03579674261148,0.10003323467414875
0.105845867083208,61.45491072904,0.3360606279891854,12.389310002974465,67.95965904167639,0.10061053270428029
0.106487562431473,61.3160626108707,0.3380980107199268,12.361318222351533,67.8454606561979,0.10119063998621125
0.107119424340439,61.1993469885635,0.3401041722808938,12.337788352894401,67.7549858079892,0.10176152897409661
0.107768153037067,61.064680112156,0.3421638858926877,12.310639510610649,67.64550790364237,0.1023473182681493
0.108408429503193,60.9502244443378,0.34419676367263774,12.2875652479785,67.5577425542156,0.10292513908710815
0.109048444845618,60.8149784115028,0.34622881238483716,12.260299647758965,67.44675723059702,0.1035023907735789
0.109681657893976,60.7000701243225,0.3482392638133738,12.237134137063418,67.35775444983881,0.10407317950066924
0.11032162678284,60.5830839340649,0.350271165035517,12.213549721107483,67.26670830919228,0.10464972721211514
0.110964391187198,60.4833287965822,0.3523119420193536,12.193439085390972,67.19482455347007,0.10522845900720885
0.111601695550889,60.3393873973805,0.35433538337407255,12.164420499311909,67.0733653394301,0.1058019442097055
0.112247064043643,60.1942168658395,0.3563844283385665,12.135154120153244,66.95084098143633,0.1063823510454554
0.11289627517379,60.0746964323838,0.3584456736767832,12.111058800768575,66.85690589179612,0.10696587403664992
0.113548725222524,59.9490854138418,0.3605172025815137,12.085735619430507,66.75622764083974,0.10755196537714506
0.114172591356423,59.8205712967125,0.36249797755664304,12.059827173417242,66.65044093807983,0.10811205890910111
0.114786953808763,59.6239256620714,0.3644485783428225,12.020183413473594,66.4679744629407,0.10866331383809273
0.115386710516742,59.4763403111824,0.36635280589065583,11.990430206734374,66.33911957326404,0.1092011703575483
0.115994766835857,59.3514347985319,0.3682833847038459,11.96524925538403,66.23589063936117,0.10974617473294286
0.116636616116204,59.2719676141966,0.3703212561689477,11.949228671022034,66.18524934726572,0.11032114586604669
0.117280935739636,59.1866216466236,0.37236697097334426,11.93202292395932,66.12808401660742,0.1108979976310222
0.117928362735686,59.0942727420247,0.374422551685803,11.91340538479218,66.06316357354775,0.11147729641489645
0.118577984776274,58.9537543470993,0.3764851016646699,11.88507687637522,65.94437173257384,0.11205822216060694
0.119216563966708,58.8055284472629,0.37851259059429787,11.8551945349682,65.81612149099209,0.11262894408691249
0.119854408141665,58.6508696056323,0.38053774584978634,11.824015312495472,65.68043486920934,0.11319868412655966
0.120485103600538,58.5048868856035,0.3825402039317081,11.794585196137666,65.5538542431532,0.11376171974882028
0.121121863173166,58.3620978741828,0.38456191557480207,11.765798931435253,65.4310239073985,0.11432984752428992
0.121765781894256,58.2310617548391,0.3866063575142628,11.73938204977556,65.32161251994978,0.11490403476919905
0.122411826974449,58.0845900051658,0.3886575506438755,11.709853345041427,65.19483078675997,0.11547978696945847
0.123059355022786,57.9558533772814,0.39071345219734555,11.68390004085993,65.0878633136848,0.11605652834247414
0.123692695846295,57.7998246085486,0.3927243093119866,11.652444641083399,64.94924073382299,0.11662031181830503
0.124339549317924,57.6517641574104,0.39477806908440866,11.622595654133937,64.82015853012605,0.11719579599196198
0.124994122939428,57.518476650703,0.3968563403326839,11.595724892781725,64.70794819246959,0.11777781158889628
0.125636607736717,57.3820301885251,0.39889622956407644,11.56821728600666,64.59131380645728,0.11834874915407255
0.126291252166072,57.2105544552186,0.4009747256272786,11.53364777817207,64.4357470144834,0.11893015716402919
0.12691778449027,57.0221210354735,0.4029639657566072,11.495659600751457,64.25924230423182,0.11948628163375469
0.127555307747043,56.8261326619274,0.4049881020968615,11.456148344644564,64.07460750169385,0.12005184462580053
0.128182792352043,56.6413229016641,0.4069803657177365,11.418890696975481,63.901765833713114,0.12060818990467594
0.128801680572602,56.5037494873124,0.4089453358180113,11.391155896642179,63.78152737993153,0.12115661036879087
0.129426324484251,56.372226355038,0.41092858023749695,11.364640833175661,63.6682764151648,0.12170982636485612
0.130066717590621,56.239324931771,0.41296182835022166,11.337847906245033,63.55418932515883,0.12227667309692584
0.130707858140654,56.0874725740669,0.4149974495965764,11.307234470931887,63.41854598274586,0.12284385973649925
0.131354189303535,55.9033441191297,0.41704955103872365,11.270114174416547,63.246482565254524,0.12341531283275721
0.131991289609942,55.7354636706111,0.41907234451156583,11.236269475995199,63.09205939750313,0.12397828506052294
0.132634052708563,55.5391462913149,0.4211131173496875,11.196691892329083,62.90552834790575,0.12454594020759717
0.133268016366723,55.3499749419231,0.4231259519643455,11.158554948291696,62.72635630838102,0.12510550867558556
0.133915542256107,55.179514037757,0.4251818466631397,11.124190030011812,62.568908581551696,0.12567672480365583
0.134548724455089,55.0099904521344,0.42719220014490755,11.090014075150295,62.411514499755704,0.126234972270647
0.135184287096376,54.8140438042403,0.4292101115309938,11.050511230934845,62.22404123878605,0.12679500523898626
0.135824132207314,54.6219685902226,0.43124161975822195,11.011788867788876,62.04095007344474,0.1273584951163725
0.136454660718414,54.4282713442453,0.4332435477809644,10.972739502999852,61.855262644014076,0.12791346973414086
0.137072233666819,54.2428073870413,0.4352043418921503,10.935349969227527,61.67799015594209,0.12845674280042363
0.137696031573517,54.0404701014423,0.4371849002459165,10.894558772450768,61.481628378778204,0.12900519244416644
0.138320082469049,53.8228026330682,0.4391662618392306,10.850677010826548,61.26757713198953,0.1295535637033328
0.138960819065308,53.6349872501164,0.4412006005323529,10.812813429623468,61.08814900894993,0.1301162844574875
0.139593565239605,53.4225913621608,0.44320956963574587,10.769994418611619,60.880041354743355,0.13067167711778144
0.140224233300238,53.2353321857462,0.44521194072825565,10.732242968646435,60.700215825975945,0.13122493894170797
0.140854790223158,52.9837938528991,0.4472139589585266,10.681532840744458,60.44681502127625,0.13177779742006715
0.141473058532164,52.7715567381627,0.44917696083962066,10.638745838413602,60.2373102734142,0.13231958489767834
0.142103126789419,52.560318803493,0.4511774275564053,10.596160270784189,60.02930445051805,0.1328714108251807
0.142711035022796,52.3819012130118,0.45310753619737726,10.56019128454318,59.85737655158257,0.133403540096683
0.143328651391517,52.2123414828753,0.4550684681680664,10.52600804294766,59.69586597360918,0.13394387750851214
0.14397347588315,51.9992224232407,0.4571157859290012,10.483043240525326,59.485731218735694,0.1345077072719932
0.144597449533006,51.7995779977246,0.459096902267294,10.442794924341278,59.28966486308159,0.13505300272985984
0.145228475752282,51.5616042538111,0.4611004105134954,10.394819417568318,59.04981744693446,0.13560415924204874
0.145862407195089,51.3070451338385,0.4631131428444075,10.343500298981843,58.79081424312726,0.13615754755475445
0.146490558233372,51.0565296969869,0.4651075223909561,10.29299638691256,58.53582923375725,0.13670558798611768
0.147155819342428,50.8111010220232,0.4672197264122089,10.243517966039878,58.28825022460991,0.1372856783908247
0.147796406454156,50.5497612881786,0.4692535904919453,10.190831875696807,58.0208343536868,0.13784393587537183
0.148452146017658,50.3162520483308,0.4713355636060641,10.143756412943489,57.78580764447089,0.1384150757727679
0.149105473466576,50.0650100160768,0.47340987825637876,10.093106019241082,57.5299770386328,0.13898379053403148
0.14973739929672,49.7879395550845,0.475416242767086,10.037248614305035,57.243056140405145,0.13953356786204976
0.150365030801387,49.5139955007401,0.4774089727944037,9.982021492949205,56.95916895930863,0.1400793100968579
0.150962189340611,49.2268608406198,0.47930495115643995,9.924135145468952,56.65825552748536,0.14059827893136354
0.151600330799962,48.9444389748631,0.48133105028987927,9.8671988973324,56.3644321142709,0.1411525670083278
0.152223216486535,48.6420425126354,0.4833087123447486,9.806235770547298,56.046490680383535,0.14169330781504816
0.152844230435265,48.3684084068774,0.4852804316319663,9.751071134826484,55.761240567205185,0.14223213279787847
0.153435041810424,48.077117956236,0.4871562577480962,9.692346979977179,55.45383255997576,0.14274448305414886
0.154028793597515,47.8003650573155,0.4890414196721101,9.636553595554807,55.162997620614625,0.14325911889899687
0.154629970839068,47.510603291362,0.49095015741404086,9.57813762353858,54.85716649285183,0.14377992107591617
0.1552282602688,47.183800699523,0.49284972635343993,9.512254221023836,54.50805999497974,0.14429795238628335
0.155818214333132,46.8923691414499,0.4947228305076941,9.453501618916299,54.19905436692068,0.14480850384739014
0.156447961907127,46.6221969828678,0.4967222790551282,9.39903491174615,53.916144680470076,0.14535320548774333
0.157066078685619,46.3704715021075,0.49868479982684033,9.348287054824873,53.653699627746775,0.14588755866853612
0.157689912949973,46.08746364811,0.5006654736161643,9.291232671458976,53.35499177886551,0.1464265651830124
0.158328967983657,45.788331401306,0.502694473348111,9.23092761050329,53.03795065776846,0.14697842169434183
0.158937627925005,45.4608264146301,0.5046269686618908,9.164902605189429,52.68626232848182,0.1475037474867389
0.159531455281914,45.1128170141931,0.5065123705200769,9.094743910061329,52.309730364334015,0.14801600566106235
0.160120758681685,44.7629404338199,0.5083834088143498,9.024208791458092,51.93041641690622,0.14852410201180113
0.160733254867827,44.4354287872985,0.5103280842053507,8.958182443519378,51.57767988772853,0.14905192168230685
0.161384750316617,44.0937572929725,0.512396582255259,8.889301470263256,51.20981730422037,0.1496130434379019
0.162058980560987,43.74877876323,0.5145372632811337,8.819753798667168,50.83866125038722,0.15019341493933744
0.162692247293302,43.3727160453723,0.5165478851562338,8.743939554747056,50.42912069000818,0.15073821882234292
0.163297256638887,42.9660719733716,0.5184687898284662,8.661960109831714,49.98231365517215,0.1512584355801627
0.163916757823291,42.5975638810127,0.5204357060889488,8.58766887841216,49.58001844355882,0.15179083285448902
0.164546703852455,42.1965283526016,0.5224357847315446,8.506820115884482,49.13982800703886,0.15233191589478712
0.165186166832812,41.8368914715454,0.5244660796941781,8.434317320663553,48.74776720593035,0.1528808741075179
0.165831420895835,41.4180814094426,0.5265147613442761,8.349885212143628,48.28650070034983,0.1534344984841855
0.166499314807366,41.046881848377,0.528635324513387,8.275051380632803,47.88115955111067,0.1540072250872899
0.167135747611642,40.6347975111375,0.5306559986669633,8.19197517824532,47.426324772209156,0.15455266840043158
0.167787128030931,40.2799833275299,0.5327241314982059,8.120444638830028,47.038446047189915,0.15511061439769092
0.168403068347781,39.8700162740036,0.5346797420042047,8.037795280839127,46.58424934962178,0.15563791763873416
0.169016540725781,39.4717256962984,0.5366275168043547,7.957499900373757,46.14310022996368,0.15616283185585178
0.169631943783083,39.0256213359325,0.5385814215112885,7.867565261323992,45.64561334048929,0.1566891213564612
0.170234412628738,38.5758128351343,0.5404942600962431,7.776883867563075,45.142743674799526,0.15720408141588324
0.170834950684499,38.1281571215922,0.5424009684232843,7.686636475712988,44.64177896315024,0.15771712735834406
0.171444004211264,37.6478240160391,0.5443347133707631,7.589801321633484,44.102317715189834,0.15823717945480217
0.172065155411179,37.1533310783149,0.5463068684304934,7.490111545388284,43.546124764348136,0.15876728296381587
0.172665808883992,36.6938441491602,0.5482139432066746,7.397478980470696,43.029616430238086,0.15927962616659586
0.173253976842724,36.2037301224163,0.5500813764756487,7.298671992679127,42.47617034266565,0.15978106528197789
0.173812532164135,35.725341738663,0.5518547896211285,7.202228894514461,41.93485384868907,0.16025702566044367
0.174419693057947,35.2079820961889,0.5537825254589817,7.097929190591682,41.34894752659586,0.1607741473495345
0.174719004568102,34.9478524218865,0.5547328395037238,7.045487048252319,41.053906408831445,0.1610289739479616