File: example/data/02 processed data/test_ID_154.csv
Strain,Stress_MPa,Displacement(mm),Force(kN),True Stress (MPa),True Strain
0.0005691890295373995,0.105050250349074,-0.0001417631239725,0.0211781304703733,0.1050455598761091,-4.465079965815414e-05
0.0005632465137099996,0.0943530903717496,-0.0001606306117244,0.0190215830189447,0.0943483168301355,-5.059359848786198e-05
0.0005705038345018995,0.203930370186091,-0.0001375886182101,0.0411123626295159,0.2039215328639351,-4.33359368496134e-05
0.0005590310445695996,0.456910059191259,-0.0001740147262452,0.0921130679329578,0.456885016961694,-5.480928979544732e-05
0.0005522904467995996,0.92014001479876,-0.000195416124165,0.18550022698343,0.9200833816663564,-6.155027974343109e-05
0.0005325759014889995,1.54048868274531,-0.0002580098055261,0.3105625184414545,1.5403634981199712,-8.126623288525969e-05
0.0005196348536560995,2.32851168207712,-0.0002990976323956,0.4694279551067473,2.328292327012202,-9.420841618078623e-05
0.0005318918009724995,3.4740067917687,-0.0002601818246659,0.7003597692205699,3.473722107225083,-8.195038923228258e-05
0.0005372177086002995,4.90798604536981,-0.0002432720679478,0.9894499867465538,4.907609989963601,-7.662405931130862e-05
0.0005428506564705996,6.42661377199353,-0.0002253874584595,1.2956053364338955,6.426157558404689,-7.09906956726031e-05
0.0005636010662571995,7.99816061578608,-0.000159504907387,1.612429180142474,7.997758806063785,-5.023902806496868e-05
0.0005667441311142995,9.63302963370179,-0.0001495256764658,1.9420187741542807,9.632575969049068,-4.709581023934549e-05
0.0005999995060410996,11.3533568796939,-4.393986107326313e-05,2.28883674694629,11.353199756883187,-1.3839422086622551e-05
0.0006281202604845995,13.1741255975397,4.534353428493541e-05,2.655903720464003,13.17431374286748,1.4281326142586368e-05
0.0006446660240517995,14.9461395318224,9.787633361066204e-05,3.013141729615396,14.94660027933075,3.08267165403452e-05
0.0006819806053901996,16.7599270992847,0.0002163501293601,3.378801303215796,16.761069150433045,6.813945148167735e-05
0.0007137581614709995,18.6208524175723,0.0003172438699166,3.753963847382576,18.62271300065328,9.99143375039161e-05
0.0007476064936613996,20.5366805992509,0.0004247123246211,4.140194808808982,20.539427742985485,0.0001337587152022
0.0007948121952836996,22.4431517072383,0.0005745904272719,4.524539384179241,22.44721331987729,0.0001809569892167
0.0008358740427989996,24.3584377682256,0.000704961793133,4.910661054074281,24.36384619908135,0.0002220105642664
0.0008871655510019995,26.2840948371522,0.0008678123316775,5.298873519169884,26.291278982546423,0.0002732893716961
0.0009377669282430996,28.1396537172194,0.001028471704418,5.672954189391431,28.14876894166673,0.0003238756425012
0.0009784126853301996,29.9439792363547,0.0011575219831695,6.036706214049108,29.954896028238053,0.0003645074120675
0.0010092786581023996,31.7933603708716,0.0012555214467213,6.409541450767716,31.80593273175632,0.000395361660017
0.0010536229807918997,33.5956276815675,0.0013963146712604,6.772878540604008,33.61040250607836,0.0004396874717234
0.0011041960864363995,35.3468361291239,0.0015568842816817,7.125922163631379,35.36416870662835,0.0004902370682425
0.0011638135789615997,37.085285650572,0.0017461698204492,7.476393587155314,37.1056816211502,0.0005498235659151
0.0011860415701571995,38.7684747990446,0.0018167436924953,7.81572451948739,38.79065822646471,0.0005720390922299
0.0012174031337882996,40.4457665838092,0.001916316657024,8.153866543295935,40.47017820466295,0.0006033822297494
0.0012598629939178996,42.0464866236374,0.0020511267129355,8.4765717033253,42.073649669904746,0.0006458155777744
0.0013041821185493995,43.6277940858857,0.0021918399336405,8.795363287714556,43.65791224062399,0.0006901051088693
0.0013521543478846995,45.168247144677,0.0023441517617801,9.105918624366884,45.201595562352814,0.0007380430947012
0.0013936572537652995,46.705578434982,0.002475923487951,9.415844612492371,46.74200030542783,0.0007795145209978
0.0014172165030327997,48.2270281055986,0.0025507241043753,9.722568866088675,48.26577262310138,0.0008030551355618
0.0014705555092296995,49.7387546162216,0.0027200754490505,10.027332930630276,49.78136663678787,0.000856349904599
0.0015232283967507995,51.2179620700907,0.0028873118669299,10.325541153330285,51.26453915030643,0.0009089763202118
0.0015563581080431995,52.7224967127605,0.0029924987002833,10.62885533729252,52.772188682174246,0.0009420753832834
0.0016144022257345997,54.1759984733173,0.0031767887739535,10.921881292220768,54.23020499418904,0.0010000631634657
0.0016445980623176995,55.6366278626812,0.0032726605551049,11.21634417711653,55.69397583037419,0.0010302283624256
0.0016890016162555996,57.1158189941313,0.0034136418388577,11.51454910921687,57.17722779708532,0.0010745852103396
0.0017301257816170995,58.5593503280769,0.0035442110638804,11.805565026140306,58.624719366604914,0.0011156643642565
0.0017803728532862996,59.9921464336482,0.0037037455164302,12.094416721023478,60.06212931345124,0.0011658541487897
0.0018160943615253995,61.4647834631356,0.0038171613050893,12.39130034616814,61.5386798389029,0.0012015333987155
0.0018688004910033995,62.8847820865673,0.0039845032661819,12.677572068651967,62.96370007699787,0.0012541748524631
0.0019083110871971995,64.3098526077368,0.0041099494090973,12.964866285719738,64.39309992764997,0.0012936351479544
0.0019568580173225996,65.7130679271822,0.0042640859122454,13.247754494119931,65.80132183811094,0.0013421181413493
0.0019976646536761997,67.1014099635853,0.0043936469826681,13.527644248658795,67.1942666273394,0.0013828692167752
0.0020492624040955995,68.4888414567406,0.0045574698402497,13.807350437678906,68.58715195416823,0.0014343943361253
0.0021033944361346997,69.8810427182453,0.0047293390419738,14.088018211998252,69.98513441702364,0.001488447316257
0.0021528086145719996,71.2012219248976,0.0048862290585123,14.354166340059356,71.31079845389634,0.0015377867817923
0.0021962918704298996,72.5366815342958,0.0050242883958611,14.623394997314032,72.65146742636101,0.0015812022785959
0.0022397748350421994,73.8159091242362,0.0051623468085051,14.88128727944602,73.93592906845177,0.0016246155998031
0.0022785511873779996,75.077192056745,0.0052854617271713,15.135561918639794,75.20217398594167,0.0016633282572723
0.0023321012755284994,76.3219812553304,0.0054554832570491,15.386511421074609,76.45312244930939,0.0017167879190912
0.0023826585713081997,77.5250453489661,0.0056160026711497,15.629049142351567,77.66217317944194,0.0017672572195823
0.0024215716356029995,78.699637138454,0.0057395516502857,15.865846847112325,78.84190505411223,0.0018061008207917
0.0024724492833715995,79.8464324911088,0.005901088181951,16.097040790207533,79.9948359050125,0.0018568853717732
0.0025271220724603994,80.9512322978106,0.0060746742873079,16.319768431238618,81.10611493383121,0.0019114552449954
0.0025799490816913995,82.0201508646212,0.0062424000416164,16.535262414307635,82.18141152388756,0.0019641799842336
0.0026663889961472996,83.0477907705151,0.0065168467700138,16.742434619335846,83.218250527063,0.0020504465607051
0.0027279536658059997,84.0576799437412,0.0067123145961802,16.94602827665823,84.23538753177505,0.0021118832373583
0.0027994091929402997,85.0189297035866,0.0069391858948316,17.13981622824306,85.20474455643472,0.002183185475933
0.0028743248724383995,85.9098071018348,0.0071770431772381,17.319417111729898,86.10400502149403,0.0022579349851989
0.0029677335210216995,86.7574199605244,0.0074736156364901,17.49029586404172,86.96163779057117,0.0023511286183973
0.0030435384057557998,87.5671429653228,0.0077142961455208,17.653536021809078,87.77990481522883,0.0024267526258833
0.0031367254562673997,88.3262373853913,0.0080101650308952,17.806569456894888,88.54907446823067,0.0025197094880259
0.0032296749199262997,89.0302479686193,0.0083052795780122,17.94849799047365,89.2631365041403,0.0026124207430356
0.0033351278707877997,89.6338708765545,0.0086400926969974,18.070188368713385,89.87779054684242,0.0027175930351529
0.0034287960385443995,90.1946580024237,0.0089374891296246,18.183243053288617,90.44855210492663,0.002811002633708
0.0035484148683702994,90.7211962871053,0.0093172789143219,18.28939317148043,90.98742453568732,0.0029302785731861
0.0036660225820390998,91.1856050318257,0.0096906834052203,18.383017974416063,91.4639202537082,0.003047535293082
0.0038170199746336998,91.5661570114069,0.0101701001267082,18.459737253499632,91.859459998816,0.0031980618865776
0.003963992232940899,91.9018120370463,0.0106367370468332,18.52740530666853,92.20969720516143,0.0033445541387791
0.004105094766375399,92.1873745306585,0.0110847375904881,18.584974705380755,92.50922424902964,0.003485175647794
0.004261120804264499,92.4273183403094,0.0115801202607856,18.633347377406373,92.76442683220316,0.0036406467677557
0.004426746468244199,92.6303151548843,0.0121059817439215,18.67427153522468,92.9835059908524,0.003805656928568
0.0045838154626727,92.7809903374983,0.0126046758012317,18.704647652039657,93.1493287008751,0.0039621170677391
0.004742194274626599,92.8865806937156,0.0131075285291853,18.725934667853064,93.27004951463572,0.0041198571641803
0.004910697604323999,92.9953396218976,0.0136425266009745,18.747860467774554,93.3949274627034,0.0042876536336732
0.005081732588334699,93.0888369471228,0.0141855626752085,18.76670952853996,93.50474798046947,0.0044579423488737
0.005265213262998199,93.174336083164,0.0147681138172651,18.78394615436586,93.60772480761258,0.0046405902166024
0.0054457607697906,93.2454807256732,0.015341352151331,18.79828891429572,93.69603560955753,0.0048202856712545
0.0056366745831461,93.3010527455283,0.0159475035087347,18.809492233498503,93.7696886088442,0.0050102633929774
0.005820881425873699,93.3405991289617,0.0165323602343948,18.81746478439868,93.82662760432996,0.0051935328242276
0.005978833024950399,93.3765744618759,0.0170338565614637,18.824717411514182,93.87753924158754,0.0053506538788447
0.0061705230444303,93.3944490003275,0.017642472373312,18.828320918466027,93.91341246058232,0.0055413027958254
0.00635884358769,93.3946774514764,0.0182403900981616,18.828366974217644,93.93123031755732,0.0057285651491987
0.006498069594899899,93.3929406896398,0.018682432671053,18.828016843031385,93.94248630424951,0.005866986290604
0.006680948366881299,93.3836305762225,0.0192630727720943,18.82613992416646,93.9501992916594,0.0060487787314273
0.006869487772358499,93.3671505305526,0.0198616853844841,18.822817546959406,93.9512226467994,0.0062361635882896
0.007067406435557599,93.3398167504148,0.0204900771401415,18.817307056883624,93.94219156788336,0.0064328324982448
0.007289231740676999,93.3141040483404,0.0211943724838953,18.812123376145426,93.93701235675032,0.0066532111330647
0.007473952917704599,93.2793711008232,0.0217808622209583,18.80512121392596,93.91927822838372,0.0068366905670299
0.007682645432743799,93.2430583124783,0.0224434609562074,18.797800555795625,93.9021754585172,0.0070439397044176
0.0079129123352777,93.1930057633221,0.0231745583717525,18.78770996188574,93.8732283623461,0.007272564183403
0.0081267069107586,93.1444431954513,0.0238533561489044,18.777919748202983,93.8442251094143,0.0074847870433843
0.0083239285994471,93.1134546986769,0.0244795350104904,18.771672467253264,93.83136779292698,0.0076805189236215
0.008520844916817,93.0702800500198,0.0251047443181398,18.762968458084,93.8061873206571,0.0078759095247447
0.0087193424473547,93.0391500295618,0.025734973977597,18.75669264595966,93.79327919646212,0.008072830456757
0.0089177579057447,92.9955792839299,0.0263649430579853,18.74790878364027,93.76780704848584,0.0082696312223135
0.0090998120396738,92.9626843411504,0.0269429649332102,18.741277163175923,93.75156318974906,0.0084501697455584
0.0093088413548174,92.9311411330001,0.0276066330087911,18.73491805241282,93.73917763956604,0.0086574186918916
0.0094911970872713,92.8973061223667,0.0281856124593322,18.728096914269127,93.7219887897308,0.0088381861691782
0.0096952083526229,92.8475596224882,0.0288333482268235,18.71806801989362,93.69074262047434,0.0090403818466603
0.0098955184876484,92.8018975218329,0.0294693329055295,18.708862540401512,93.66325500603313,0.0092388695625