File: example/data/02 processed data/test_ID_132.csv
Strain,Stress_MPa,Displacement(mm),Force(kN),True Stress (MPa),True Strain
0.00017741361062959977,0.201398439609492,9.452571053015916e-05,0.0406019254252735,0.2014044356191309,2.977143415878577e-05
0.00019450590378769977,0.686641318240118,0.0001487937413071,0.1384268897572078,0.6866734971159218,4.6863072399559806e-05
0.0002033309466326998,1.36580777627074,0.0001768132523398,0.2753468476961812,1.3658838370313675,5.568766274875639e-05
0.00021290823521939977,2.02637311460199,0.0002072211436026,0.4085168199037612,2.026505368886769,6.526437215659889e-05
0.0002348244683491998,3.12919193822608,0.0002768051837897,0.6308450947463777,3.129464749737757,8.717893485815421e-05
0.0002548936498242998,4.45535913971644,0.0003405248349732,0.8982004025668343,4.455836985522991,0.0001072461654514
0.0002825817235707998,6.00833375045604,0.0004284344691183,1.2112800840919378,6.009144514953886,0.0001349308866919
0.0003044120172669998,7.60155976596912,0.0004977456516037,1.532474448819375,7.602751464652244,0.0001567579967929
0.0003364936736476998,9.30576465886258,0.0005996049106125,1.876042155226696,9.30752207057485,0.0001888341100674
0.0003636187727345998,10.9697713401312,0.0006857271002134,2.21150590217045,10.972140558868544,0.000215953719754
0.00039676300820399977,12.751419628215,0.0007909600478287,2.5706861970481443,12.754596278129652,0.0002490902493545
0.00042382013784609976,14.6075880355299,0.0008768664344424,2.944889747962828,14.61162233588786,0.0002761402743136
0.00046388631184599976,16.5412245226406,0.0010040765368921,3.334710863764345,16.546455595218443,0.0003161945837721
0.0005023385587096998,18.5192852786869,0.0011261624206843,3.733487912183279,18.52585401038416,0.0003546339353642
0.0005525006216620998,20.5639334730815,0.0012854269705582,4.145688988173231,20.57225896432782,0.0004047769551185
0.0005786617426050998,22.6531445463784,0.0013684885295522,4.566873940549885,22.66290850495163,0.0004309271468663
0.0006190723529174998,24.802229420476,0.0014967922172941,5.000129451167962,24.81392195085966,0.000471319531118
0.0006605561618666998,26.9630626123397,0.0016285033107078,5.435753422647685,26.97689235619199,0.0005127829329259
0.0007072684921835998,29.1683414934074,0.001776814959464,5.880337645070933,29.184664877819444,0.0005594702262288
0.0007445449683555998,31.4036527256437,0.0018951677713101,6.33097638948977,31.422397667548285,0.0005967251591815
0.0007923419828834998,33.6515059447814,0.0020469232924361,6.78414359846793,33.67320107906295,0.0006444925196578
0.0008311687471324998,35.9240131779057,0.0021701982689267,7.24228105666579,35.94856821135817,0.0006832935156413
0.0008843811669335998,38.1542986524448,0.0023391477017952,7.691906608332872,38.1824084288248,0.0007364681743632
0.0009349361425659997,40.3877158541772,0.0024996597494281,8.142163516202125,40.41951287707232,0.0007869846555927
0.0009866560179533999,42.6215995918444,0.0026638703537831,8.59251447771583,42.65735972273686,0.0008386625089207
0.0010390095660726998,44.8245663430166,0.0028300928690618,9.036632574752147,44.86452151957287,0.0008909708003857
0.0010858719608119998,47.0363340576239,0.0029788809723591,9.482524946016978,47.08046496802824,0.0009377903646417
0.0011323884056847998,49.2466087732997,0.0031265706848303,9.92811632869722,49.29510420741558,0.0009842621274597
0.0011806203094582998,51.4134073855821,0.0032797069793111,10.36494292893335,51.466516333938834,0.0010324454209185
0.0012303014165087997,53.6138106995433,0.0034374444941965,10.80854423702793,53.67185621085103,0.0010820740298873
0.0012858647928146998,55.7810268205277,0.0036138582139677,11.245455007018384,55.84451807153838,0.0011375757747738
0.0013338777909670998,57.9376099077981,0.0037662994831016,11.680222157412098,58.006337589765934,0.0011855330355893
0.0013903358524716997,60.0918208946391,0.0039455538283787,12.114511092359242,60.16649664707534,0.0012419226139346
0.0014553959024035997,62.22806899666,0.0041521194869125,12.545178709726656,62.30944801332581,0.0013068998034085
0.0015082652780300998,64.3564951099115,0.0043199797545266,12.97426941415816,64.44406007241453,0.0013596987353008
0.0015700230908120998,66.4948647822696,0.0045160608101094,13.405364740105552,66.58944583830636,0.0014213707313686
0.0016204556666492998,68.5997279784036,0.0046761842383926,13.829705160446167,68.70076261359435,0.0014717304066691
0.0016705453377617997,70.690620915844,0.0048352189441747,14.25122917663415,70.79827591723857,0.0015217451627512
0.0017225766995480998,72.7882535433501,0.0050004185178462,14.67411191433938,72.90289030898785,0.0015736960568074
0.0017716631288283997,74.8430306179262,0.0051562679308112,15.088354972573924,74.96457730095611,0.0016227040988038
0.0018212372986366999,76.8476631393119,0.0053136659199525,15.49248888888528,76.97627504754854,0.0016721966648594
0.0018736578435002997,78.8467061053675,0.0054801011498945,15.89549595084209,78.98279679034181,0.0017245282561906
0.0019219195106587998,80.8379810530253,0.0056333319431227,16.296936980289903,80.98141008637445,0.001772705605917
0.0019801565723991995,82.7519767860992,0.0058182346141485,16.6827985200776,82.90362101152475,0.0018308378322315
0.0020280991165542994,84.6400206825184,0.0059704521918409,17.06342816959571,84.79918263432985,0.0018786915366581
0.0020889471573579,86.5023059288554,0.0061636447213924,17.43886487525725,86.67023332454885,0.0019394235258517
0.0021372025112582,88.3483641248876,0.0063168554700258,17.81103020757734,88.52413856494749,0.0019875842231328
0.0021932142681005996,90.2056652571407,0.0064946927980004,18.185462115839563,90.39018748847435,0.0020434832000776
0.0022483213708730998,92.0254615822257,0.0066696578493031,18.552333054976703,92.21877759551,0.0020984762952439
0.0023054693662008996,93.7692780698411,0.0068511027344689,18.903886458879967,93.97161600917762,0.0021555028665528
0.0023650590732684,95.5276875117491,0.0070403000544082,19.258381802368618,95.739512262485,0.0022149624984104
0.0024310098102392,97.2750940705612,0.0072496936442905,19.61065896462513,97.49720891504344,0.0022807651535894
0.0024769550662954998,98.9668112267253,0.0073955698322692,19.95170914330782,99.19733593964004,0.0023266046880696
0.0025369986702575,100.642624020069,0.0075862082748486,20.28955300244591,100.88309517192522,0.0023865069625087
0.0025904669793794,102.297601374213,0.0077559701563106,20.623196437041344,102.5474965374636,0.0024398463987068
0.0026377205298402998,103.896598566549,0.007906000179024,20.94555427101628,104.1553092836725,0.0024869836873155
0.0026884044286507,105.508541388828,0.008066921557747,21.270521943987724,105.77661355482986,0.0025375404146958
0.0027331064391688,107.039574525271,0.008208850441142,21.57917822429464,107.31632156733755,0.0025821281418071
0.0027792904306625996,108.547732353867,0.0083554846141348,21.883222842539592,108.833391852318,0.002628191973193
0.0028420369190351,110.055966956561,0.0085547047147175,22.187282938442696,110.35250122409047,0.0026907718101073
0.0028938294007197,111.523980683805,0.0087191458440661,22.483234505855084,111.83024646418072,0.0027424237833833
0.0029481033565582,112.952608537458,0.0088914656538533,22.771245881151536,113.26892798291436,0.00279654763622
0.0030051444033834997,114.389358527895,0.0090725709775236,23.06089467922364,114.7162264253179,0.0028534277701772
0.0030561586613174997,115.774734273851,0.0092345412464641,23.34018642960836,116.11146704832356,0.0029042953763154
0.0031110065574831997,117.184652564457,0.0094086833167902,23.62442595699453,117.53191344180094,0.0029589827137053
0.0031654304322319,118.541818625123,0.0095814791191173,23.8980306348248,118.89955278572106,0.0030132443149837
0.0032020901125223,119.862830583549,0.0096978736040393,24.16434664564348,120.22894541215425,0.0030497930290498
0.0032580660828976996,121.214102743865,0.0098755973099812,24.436763113163185,121.59113004055448,0.0031055969872895
0.003302444563614,122.53007677328,0.0100164989862555,24.702063477493247,122.91663500628329,0.0031498368815193
0.0033609775464723997,123.786950183428,0.0102023412068309,24.95544915697909,124.18471922365616,0.0032081840828605
0.0034261885342703998,125.036288524485,0.0104093860930895,25.207315766536176,125.4462258482325,0.0032731840844911
0.0034859937073393995,126.260354477316,0.0105992675175836,25.45408746262691,126.68185598092862,0.0033327920476487
0.0035548250413258995,127.482450853558,0.0108178070029908,25.70046209207729,127.91680693217285,0.0034013920099293
0.0036330602618022,128.699530736603,0.011066203828003,25.945825396499167,129.14810246564227,0.0034793585343405
0.0036956819562611997,129.865010980468,0.0112650277079103,26.18078621366235,130.32577726298237,0.0035417607770199
0.003768945831663,130.967621819192,0.011497640512311,26.40307255874911,131.44189540483904,0.0036147629635484
0.0038350272274748,132.070654938768,0.0117074489440135,26.62544403565563,132.55765035599572,0.0036806037544325
0.0039085958049964,133.182567210422,0.0119410291776446,26.84960554962108,133.6834607288514,0.0037538993666828
0.0039788687328591,134.250030699524,0.0121641457236087,27.06480618902404,134.764373041832,0.0038239065410022
0.004046445248949,135.26069721198,0.0123787011621941,27.268556557935167,135.78805209379956,0.0038912228784464
0.0041159226221654,136.21519917422,0.0125992918221562,27.460984153522755,136.75573934587644,0.0039604280303051
0.0041925299815861,137.115160329647,0.0128425201883169,27.64241632245684,137.66977583032664,0.0040367296807478
0.0042690694016804,137.994504663185,0.0130855328471163,27.819692140098105,138.5632390327887,0.0041129578492264
0.0043450404116727,138.81211060663,0.0133267408038418,27.98452149829661,139.39476037623277,0.0041886141733437
0.0044137040918583,139.549604093055,0.0135447479884311,28.13320018515989,140.1449314062285,0.0042569885117814
0.0044953337740947,140.282802769014,0.0138039222295317,28.281013038233223,140.8927091940736,0.0043382681327165
0.0045770505926504,141.006439004983,0.014063373128446,28.42689810340457,141.6310141751375,0.0044196278998744
0.0046671935508811,141.718293626949,0.0143495770208285,28.57040799519292,142.35879679849555,0.0045093693119817
0.0047559129974707,142.3699653154,0.0146312612637505,28.70178500758464,143.02604473544432,0.0045976856904897
0.0048491795953491,142.999564318751,0.0149273827120144,28.828712166660203,143.67188218465253,0.0046905201528727
0.0049487058736291,143.616291854787,0.0152433786455534,28.95304443792505,144.30580288357842,0.0047895757880952
0.0050471259517358,144.184706581477,0.0155558623935422,29.067636846825764,144.89113727591314,0.0048875208060888
0.005151061088466,144.705194545534,0.0158858564526606,29.17256722037965,145.42921531671658,0.0049909438487025
0.0052572662508677,145.174615377042,0.016223057843286,29.267202460011664,145.91640315110138,0.0050966146843047
0.0053553425501122,145.5562756742,0.0165344500933873,29.34414517591872,146.3142892099211,0.0051941876376753
0.0054643187872531,145.916276629045,0.0168804496463096,29.41672136841548,146.6920663487973,0.0053025934231978
0.0055776027008603,146.251404346357,0.0172401260720125,29.48428311622557,147.04554376340897,0.0054152718796327
0.0056961396794477,146.553653381627,0.0176164809790275,29.545216521736,147.3668060264158,0.0055331617338967
0.0058159233979239,146.839788841165,0.0179967942851894,29.60290143037886,147.67211812389098,0.0056522774053968
0.0059346310304116,147.092749123594,0.0183736910183379,29.65389822331656,147.94397328845534,0.0057703089960956
0.006058088755383,147.31382900487,0.018765669295122,29.698467927381795,148.18451958682388,0.0058930488504071
0.006191051628503,147.532842032314,0.019187826417278,29.7426209537145,148.4244434697199,0.0060252217358404
0.006324313008292,147.704569956966,0.0196109312981081,29.777241303324345,148.61689253140463,0.0061576738281644
0.0064556020598846,147.846250592222,0.0200277740369146,29.805804119391954,148.7788588753924,0.0062881484163597
0.0065816719421005,147.9711637895,0.0204280459129501,29.8309866199632,148.9232147273534,0.0064134201928455
0.0067140056400447,148.082559693704,0.0208482054039229,29.853444034250728,149.05492366889553,0.0065448992511921
0.0068463346711719,148.173319205543,0.0212683500777518,29.871741151837472,149.1658867724866,0.0066763563893049
0.0069831943432876,148.264917247834,0.0217028795367192,29.890207317163338,149.27838988989745,0.0068122961406443
0.0071220631960014,148.339194251681,0.0221437881440855,29.90518156113889,149.37377431183015,0.0069502126816504
0.0072594411593961,148.421136276321,0.0225799631778636,29.92170107330632,149.47667762811184,0.0070866298441164
0.0074041670666427,148.481672721988,0.0230394679333716,29.93390522075278,149.5591337416326,0.0072303234335328
0.0075532263328215,148.530176106436,0.0235127311034893,29.943683503057496,149.63012889117442,0.0073782978911015
0.0076933675423998,148.561928716569,0.0239576794439004,29.950084829260312,149.68293629633567,0.007517399227278
0.0078453075667029,148.580738463673,0.0244400890210627,29.953876874276474,149.72446333764697,0.0076681899706901
0.0079945029231919,148.577581772074,0.0249137842779153,29.95324048525012,149.74344943216968,0.007816234684921
0.0081517913731924,148.561091398585,0.0254131751066669,29.94991602595473,149.7501966048054,0.0079722863469483
0.0083097040503917,148.551978069188,0.0259145478567747,29.948078778748304,149.76446857151635,0.008128932834312
0.0084615116819326,148.549864053459,0.026396537086917,29.94765259317733,149.78488830408693,0.0082795000981198
0.0086187143104608,148.542861195653,0.0268956554324941,29.946240817043645,149.8011785536609,0.0084353943886133
0.0087889941489095,148.49122022375,0.0274362939195687,29.935829997108,149.7743851883277,0.0086042296372027
0.0089467196217152,148.447339124946,0.0279370722957268,29.92698356758912,149.7535388242348,0.0087605916003694
0.009117368313782,148.400323050157,0.0284788818930389,29.917505126911653,149.7314333723725,0.008929737532347
0.0092713968316453,148.360268205104,0.0289679224372549,29.90943007014897,149.71387095853262,0.009082385087637
0.0094249489940853,148.278402488227,0.0294554505530019,29.892925941626565,149.65402678824904,0.0092345373685683
0.0095864599665653,148.194641528378,0.0299682478906259,29.876039732121008,149.5934238129087,0.0093945509244963
0.0097457750886518,148.098269812929,0.0304740734032505,29.85661119428649,149.51973675629077,0.0095523639078513
0.0099064814605747,148.036977144735,0.0309843161341057,29.84425459237858,149.48164627840112,0.0097115297952148