File: example/data/02 processed data/test_ID_135.csv
Strain,Stress_MPa,Displacement(mm),Force(kN),True Stress (MPa),True Strain
3.64290829919852e-05,0.114113566798732,0.00011566233849955299,0.02300529506662437,0.11411772385132742,3.642841946902162e-05
4.01235299689034e-05,0.108197583312047,0.0001273922076512683,0.021812632795708678,0.1082019245810236,4.0122725041662985e-05
3.99659143956928e-05,0.101111278247578,0.00012689177820632462,0.020384033694711725,0.10111531925226888,3.9965115779822423e-05
3.01667459393006e-05,0.261049357946444,9.57794183572794e-05,0.05262755056200311,0.2610572329561028,3.0166290932123365e-05
2.67449905476644e-05,0.636895549318911,8.491534498883447e-05,0.12839814274269246,0.6369125830843573,2.6744632906672885e-05
5.77095709504068e-06,1.2295757058557,1.8322788776754157e-05,0.24788246230050914,1.2295828016843435,5.770940443177073e-06
-1.78381961769669e-06,2.23497239971553,-5.6636272861869905e-06,0.4505704357826509,2.2349684129279184,-1.7838212086925852e-06
-1.40668364474862e-05,3.75770421023803,-4.466220572076869e-05,0.7575531687839869,3.7576513512274867,-1.4066935386317766e-05
-3.74970583461187e-05,5.47088519882324,-0.00011905316024892685,1.102930456082765,5.470680056721735,-3.749776137836996e-05
-6.27073217833561e-05,7.4027185783723,-0.0001990957466621556,1.4923880653998558,7.402254373716334,-6.270928796967214e-05
-6.03123463521231e-05,9.39864350552429,-0.00019149169966799085,1.894766530713697,9.398076651281945,-6.031416521487084e-05
-5.21939218341164e-05,11.4251567847816,-0.00016571570182331955,2.3033116078119704,11.424560461041432,-5.219528398422294e-05
-3.65869984905296e-05,13.5078369623125,-0.00011616372020743149,2.7231799316022,13.507342751101948,-3.658766781107255e-05
-4.82756956746927e-06,15.4781372773018,-1.532753337671493e-05,3.1203924751040426,15.478062555517319,-4.827581220185265e-06
2.14110418592218e-05,17.2185360262766,6.798005790302921e-05,3.4712568628973623,17.21890469307221,2.141081264618005e-05
5.49193467642471e-05,19.1553745973423,0.00017436892597648453,3.8617235188242076,19.15642659800221,5.49178387521585e-05
0.0001125260207799,21.1829350841352,0.0003572701159761825,4.270479712961656,21.185318715528656,0.00011251969020215743
0.0001572305335855,23.3009175962497,0.0004992069441339624,4.69746498740394,23.304581211956393,0.00015721817416067385
0.0001984201856657,25.5048496965676,0.0006299840894885975,5.141777698828029,25.50991037357977,0.00019840050298428218
0.0002413945729564,27.7409411323574,0.0007664277691365699,5.592573732283252,27.747637644995454,0.00024136544197448585
0.0002665483529479,29.9829012819796,0.0008462910206095824,6.044552898447088,29.99089317493291,0.00026651283524690186
0.0003394475316143,32.2242324782678,0.0010777459128754024,6.496405267618789,32.235170914440715,0.0003393899323351948
0.0003961894992841,34.4088705446414,0.0012579016602270174,6.936828301799707,34.42250297783342,0.0003961110369477189
0.0004397489195817,36.6450342782329,0.0013962028196718974,7.387638910491753,36.66114889246479,0.00043965225836236466
0.0004834045354207,38.8063990534205,0.0015348093999607224,7.823370049169573,38.82515824272627,0.00048328773308863114
0.0005247874142246,40.9442896615309,0.0016662000401631049,8.25436879576463,40.96577670942964,0.000524649761466468
0.0005822215377281,43.099975477242,0.0018485533822867172,8.688955056211988,43.1250692112404,0.0005820521125273364
0.000638572566587,45.2031683180635,0.002027467898913725,9.112958732921602,45.23203382127422,0.00063836876588196
0.0006507759165117,47.321805061151,0.0020662135349246474,9.540075900328041,47.35260095221066,0.0006505642536900581
0.0006928928891022,49.4194152978525,0.002199934922899485,9.962954124047064,49.45365765929597,0.0006926529496527364
0.0007369506177016,51.4066463908846,0.00233981821120258,10.363579912402336,51.44453055069633,0.0007366792029330513
0.0007848005140601,53.4407527850906,0.0024917416321408176,10.773655761474265,53.4826931153481,0.0007844927191644796
0.0008484839868194,55.4637995865386,0.002693936658151595,11.181501996646181,55.510859732335945,0.000848124227767007
0.0008189318986931,57.4599902730267,0.0026001087783505926,11.583934039042184,57.50704609195987,0.0008185967569254467
0.000856961274103,59.4527006540861,0.002720852045277025,11.985664451863759,59.503649316187484,0.0008565942924347156
0.0009111952338236,61.4232778968733,0.00289304486738993,12.382932824009659,61.47924649493876,0.0009107803474557797
0.0009533370437576,63.3421132047215,0.00302684511393038,12.769770022071855,63.402499587669446,0.0009528829066056462
0.0010109427334628,65.2808185982545,0.0032097431787443897,13.160613029408108,65.34681376745091,0.0010104320749929688
0.0010572534047106,67.2593491779886,0.003356779559956155,13.5594847942825,67.33045935390565,0.0010566949059448996
0.0010912088009166,69.1487424652762,0.0034645879429102047,13.940386480999683,69.22419818162662,0.00109061386535286
0.0012074005245721,70.9637048059256,0.003833496665516417,14.3062828888746,71.04938642033386,0.0012066722027505822
0.0012318923729881,72.7545388893037,0.003911258284237218,14.667315040083627,72.8441646508617,0.001231134216160038
0.0012822404173063,74.5620642075538,0.004071113324947502,15.031712144242848,74.65767069987851,0.0012814190491150918
0.0013435558510195,76.3506741715398,0.004265789826986913,15.392295912982423,76.45325556655226,0.0013426540874798753
0.0013865789908988,78.1231715802675,0.0044023882961036894,15.749631390581927,78.23149552868308,0.00138561857793967
0.0014375814890485,79.8475424759738,0.004564321227728987,16.09726456315632,79.96232982498327,0.0014365491580346425
0.0014982922058867,81.620283307114,0.004757077753690273,16.454649114714183,81.7425743414353,0.001497170886022961
0.0015579160557309,83.4091736088763,0.0049463834769456075,16.815289399549464,83.53911809963681,0.0015567037634489165
0.0016316288013522,85.2118944863643,0.005180421444293235,17.178717928451043,85.35092866762604,0.0016302991412242445
0.0016795027038128,86.9537821133051,0.00533242108460564,17.52988247404231,87.09982122547115,0.001678093916301115
0.0017174520952367,88.6805051120933,0.005452910402376522,17.87798983059801,88.83280963140471,0.0017159789608377145
0.0017663053227482,90.4253818667753,0.0056080193997255345,18.2297569843419,90.58510070007812,0.0017647472399317274
0.0018155457043502,92.1047725334136,0.005764357611311884,18.568322142736182,92.2719929575368,0.0018138995933400157
0.0018555512707535,93.7406805303175,0.005891375284642362,18.89812119491201,93.91462116919682,0.0018538318621329007
0.0018928561378933,95.4133811632024,0.0060098182378112265,19.235337642501605,95.59398496737431,0.0018910669431502576
0.0019492359809539,97.0479388242497,0.006188824239528632,19.56486446696874,97.23710815848334,0.0019473386856166295
0.0019981204369336,98.6357338229094,0.006344032387264179,19.884963938698537,98.8328198984729,0.00199612684947031
0.0020575174067375,100.26829154719,0.006532617766391562,20.214087575913506,100.47459530239217,0.0020554036167411316
0.0021093581997808,101.860934878354,0.00669721228430404,20.53516447147617,102.075796076577,0.0021071366272862814
0.0021610780027204,103.567281253224,0.00686142265863727,20.87916390064996,103.79109822654189,0.002158746232474064
0.0022159933608263,105.197507506357,0.007035778920623502,21.207817513281572,105.43062448456656,0.0022135416688261276
0.002261741013155,106.758810663359,0.007181027716767124,21.522576229733176,107.00027144395196,0.0022591871270439966
0.0023023772079327,108.346490379717,0.007310047635186323,21.842652460550948,108.59594486972675,0.002299730798771909
0.0023548530977547,109.967943524551,0.007476658585371171,22.16953741454948,110.2269018770135,0.002352084776340352
0.0024021050502663,111.518023722668,0.007626683534595502,22.482033582489873,111.78590173064794,0.002399224607758174
0.0024401807312068,113.019042666951,0.00774757382158159,22.78463900165732,113.29482955712633,0.002437208324697129
0.0024854367770811,114.553019460441,0.007891261767232493,23.09388872322491,114.83773374793367,0.0024823531874158386
0.0025251408316816,116.099131131799,0.008017322140589079,23.40558483617068,116.39229778834266,0.0025219580204766815
0.0025897617437977,117.624388797888,0.008222493536557697,23.713076781654223,117.92900794013437,0.00258641408935892
0.0026516830102258,119.087617233848,0.008419093557466914,24.008063634343756,119.40339984519527,0.0026481735015332474
0.002700161015961,120.606798615393,0.008573011225676174,24.314330600863233,120.93245639127414,0.0026965221301181994
0.0027533415511869,122.115003729664,0.008741859425018407,24.618384751900262,122.45122804345623,0.0027495580495951167
0.0028154973672994,123.591613609637,0.008939204141175595,24.916069303702816,123.9395854723752,0.002811541278418996
0.0028734342190241,124.860266261679,0.009123153645401517,25.171829678354488,125.21904402335178,0.0028693137982036365
0.0029364284368557,126.16979718889,0.009323160287016847,25.435831113280223,126.54028576922776,0.002932125552223734
0.0029896150114489,127.515175796975,0.009492027661350258,25.70705944067016,127.8963970807252,0.0029851549994255305
0.0030416755251182,128.88767132081,0.009657319792250284,25.9837545382753,129.27970579615598,0.0030370589890855227
0.0031015500481935,130.123295390055,0.009847421403014362,26.23285635063509,130.52687930314312,0.0030967501640024957
0.0031651641865138,131.349331068931,0.010049396292181314,26.48002514349649,131.76507326755294,0.0031601655991391237
0.0032298498850819,132.594276048578,0.010254773385135032,26.731006051393326,133.022535655836,0.0032246451239951335
0.0032891490044638,133.821879128779,0.010443048089172563,26.978490832361846,134.26203922929088,0.0032837515859145496
0.003355843369801,135.021006886049,0.010654802699118174,27.22023498822748,135.47411623679142,0.003350225093301619
0.0034255901551115,136.135535234552,0.010876248742479012,27.444923903285684,136.6018797838123,0.003419736186212148
0.0035134626063772,137.238204084414,0.01115524377524761,27.667221943417864,137.72038538263098,0.003507304815863447
0.0035994635341895,138.262592919624,0.011428296721051662,27.873738732596202,138.7602640809807,0.0035930009685261697
0.0036842511332461,139.24053510986,0.011697497348056366,28.070891878147773,139.75353220913226,0.0036774809037612988
0.0037811794654477,140.165565758162,0.012005244802796446,28.25737805684546,140.6955569171696,0.0037740487756653925
0.0039004458599394,141.04137086362,0.012383915605307595,28.43394036610579,141.59149509468517,0.0038928588430860622
0.0040073577565949,141.799080231695,0.012723360877188807,28.586694574709714,142.3673198757395,0.00399934968550814
0.0041260299254932,142.50080515099,0.01310014501344091,28.728162318439587,143.08876773744987,0.004117541205816965
0.0042495559043632,143.072582592747,0.01349233999635316,28.843432650697796,143.6805775308565,0.004240552040938832
0.0043771232845808,143.626758742058,0.01389736642854404,28.955154562398892,144.25543077203673,0.004367571543080175
0.004513485924272,144.095750155094,0.0143303178095636,29.049703231266953,144.74612429516642,0.004503330692209971
0.004644156929188,144.44814836427,0.0147451982501719,29.12074671023683,145.11898823340428,0.004633406105222061
0.0047994967484187,144.740793269357,0.015238402176229371,29.179743923102368,145.4354762360168,0.004788015884158437
0.0049724355470642,145.032435499977,0.015787482861928836,29.238538996795366,145.75359993773438,0.004960113818549294
0.0051078784230055,145.237068671449,0.016217513993042464,29.279793044164123,145.97892196073647,0.005094877464762736
0.0052713285272723,145.412003682917,0.01673646807408955,29.31505994247607,146.17851812613858,0.005257483707467545
0.0054368159138118,145.530513028796,0.017261890526352464,29.338951426605277,146.32173563797616,0.005422089781572051
0.0056247168669229,145.618440529685,0.017858476052480206,29.356677610784494,146.43750302826734,0.005608957215109137
0.0058119136723011,145.67800223365,0.018452825909555992,29.368685250303844,146.52467020658528,0.005795089657042867
0.0059812648128516,145.695282847335,0.01899051578080383,29.372169022022735,146.56672491602822,0.00596344805765941
0.0061512519977517,145.662859926779,0.019530225092861647,29.365632561238645,146.55886888490184,0.006132410274495883
0.0063616378653933,145.636309599298,0.020198200222623728,29.360280015218475,146.562795061021,0.006341488059256941
0.0065566333842152,145.544125788233,0.020817310994883258,29.341695758907772,146.49840526225256,0.006535232159270478
0.0067589087279518,145.474422792471,0.021459535211246963,29.32764363496215,146.45767113837678,0.00673616970749493
0.0069473036135969,145.382392555577,0.022057688973170158,29.309090339204328,146.39240817673175,0.006923282291287122
0.0071447374912303,145.324036466728,0.022684541534656204,29.297325751692366,146.36233855844876,0.007119334779690252
0.0073501591542838,145.276778137369,0.023336755314851066,29.28779847249359,146.34458557810024,0.007323278372803786
0.0075634264408078,145.20502633891,0.024013878949564763,29.273333309924254,146.30327387445988,0.007534967140843404
0.0077753314491789,145.120141320977,0.024686677351143004,29.256220490308966,146.2484985196993,0.007745259339435241
0.007973538158273,145.063016437725,0.02531598365251677,29.24470411384536,146.2196819346454,0.007941917477481573
0.0081843207494739,144.978052442813,0.02598521837957963,29.2275753724711,146.16459932563902,0.008151010819094138
0.0083938348600417,144.882920783517,0.026650425680632396,29.208396829957028,146.09904409461433,0.00835880252876713
0.0086109702495727,144.76837173665,0.02733983054239332,29.18530374210864,146.0149678787534,0.008574107311204721
0.0088229004344357,144.637841387415,0.02801270887933335,29.158988823702863,145.91396666102787,0.008784206079468998
0.0090356916729627,144.504175781908,0.02868832106165657,29.132041837632656,145.80987095972895,0.008995114058995526
0.0092528292720729,144.360915748181,0.029377732938831454,29.103160614833286,145.696662655159,0.009210284088150823
0.0094745632989591,144.226914556989,0.03008173847419514,29.07614597468898,145.59340158837273,0.009429961126857365
0.0096969670126464,144.095654269001,0.03078787026515232,29.049683900630598,145.49294507511317,0.00965025317361815
0.0099106100104846,143.959365686109,0.0314661867832886,29.022208122319576,145.38609081678078,0.009861821996260562
0.010117793031507,143.829647349742,0.03212399287503472,28.996056905707988,145.28488595342134,0.010066950816664167
0.0103327319776449,143.707200511038,0.032806424029022556,28.971371623025263,145.19208849717623,0.010279714202144977
0.0105490844258158,143.594888613435,0.03349334305196516,28.948729544468492,145.10968321653374,0.010493831076512701
0.0107520036234206,143.494068218349,0.0341376115043604,28.928404152819162,145.03691695977207,0.010694611850328304
0.0109742112500937,143.388643538855,0.03484312071904749,28.90715053743317,144.9622208039148,0.010914431552850986
0.0111875104638178,143.272629030251,0.03552034572262151,28.883762012498607,144.87549306670562,0.011125393131467284
0.0114055082821808,143.154611174901,0.036212488795924036,28.85996961286004,144.78736227828873,0.011340955844466743
0.0116336674480446,143.016672334463,0.0369368941475416,28.832161142627744,144.68048073992813,0.011566516643850387
0.0118336121723259,142.879199394073,0.03757171864713473,28.804446597845118,144.5699764271949,0.011764142498190442
0.0120544389859098,142.754062082307,0.03827284378026361,28.77921891579309,144.47488221366896,0.011982362882795085
0.0122839522387117,142.624992689882,0.03900154835790964,28.75319852628021,144.3769912881311,0.012209116724722096
0.0125033338564586,142.460857549688,0.039698084994256054,28.720108882017104,144.24209321310914,0.012425812690873157
0.0127253025379986,142.321825748561,0.04040283555814555,28.692080070909896,144.13291403897173,0.012645016269609703
0.012933667344048,142.200200683399,0.0410643938173524,28.667560457773238,144.03937077529497,0.01285074172476526
0.0131541916990434,142.085726577849,0.041764558644462796,28.644482478094357,143.9547494629519,0.013068426614274731
0.0133882234681143,141.970815588353,0.0425076095112629,28.62131642261196,143.87155259340028,0.013299393179158448
0.0136140428826018,141.847085096078,0.04322458615226071,28.596372355369322,143.77819739534806,0.013522204390739673
0.0138360458205887,141.72471676509,0.04392944548036912,28.571702899842144,143.6856264401617,0.013741201583431282
0.0140556709300896,141.620759252323,0.044626755203034475,28.55074506526832,143.6113340412431,0.013957805959834197
0.0142782888492261,141.507167111129,0.04533356709629286,28.527844889603607,143.52764731737741,0.014177314112283188
0.014531468000204,141.398486308832,0.0461374109006477,28.50593483986053,143.45321388790606,0.014426898038461965
0.0147644323491171,141.284405789887,0.04687707270844679,28.48293620724122,143.370389841157,0.01465649920199509
0.0149989666161994,141.175576809944,0.04762171900643309,28.460996284884715,143.29306457353906,0.014887594381113534
0.0152277119009902,141.062417063414,0.04834798528564389,28.43818327998426,143.210474910513,0.015112934032275925
0.015459100037981,140.935254990862,0.04908264262058967,28.412547406157785,143.11398719664408,0.01534082553837294
0.0156825194831124,140.823460330692,0.049791999358881865,28.390009602667504,143.0319269910074,0.01556081950027635
0.0159150050910102,140.709432885403,0.050530141163957376,28.367021669697248,142.94882422612736,0.015789689250411767
0.0161248578258798,140.581972940278,0.05119642359716837,28.34132574476005,142.84883726682165,0.015996233166646077
0.0163414906100839,140.456988139019,0.051884232687016384,28.316128808826228,142.75226469181342,0.01620940548823576
0.0165714236554983,140.313998369554,0.052614270106207096,28.28730207130209,142.6392010813328,0.016435615912481192
0.0167909412826248,140.163911621374,0.05331123857233373,28.257044582869003,142.51739563135152,0.016651531808009202
0.0170141650024434,140.038127211434,0.054019973882757796,28.231686445825094,142.42075901444247,0.016871045192084266
0.0172280414940086,139.92661475045,0.0546990317434773,28.20920553369072,142.33727627548691,0.017081321521687877
0.0174497160637993,139.806192969731,0.055402848502562774,28.184928502697773,142.24577134101352,0.017299218011531697
0.0176767209747646,139.685344550642,0.0561235890948776,28.160565461409423,142.15452341052753,0.017522304801399335
0.0179022510435809,139.606129810818,0.05683964706336936,28.144595769860913,142.105393793914,0.01774389293218604
0.0181143007077242,139.513893082517,0.05751290474702433,28.126000845435428,142.041089694719,0.017952191499039684
0.0183224732628795,139.438991136505,0.05817385260964242,28.11090061311941,141.9938583234065,0.018156639344945047
0.0185367051307085,139.343214709709,0.05885403878999949,28.091592085477338,141.9261787927479,0.018366994455294914
0.0187746536168667,139.24431527441,0.059609525233551765,28.07165395932106,141.85857906180485,0.018600585149440303
0.0189968538329904,139.152260385561,0.06031501091974452,28.053095693729098,141.7957155366357,0.01881866673139582
0.0192236081743829,139.061444930055,0.061034955953665704,28.03478729789909,141.7347076595539,0.019041169003897487
0.0194730153548476,138.942301672296,0.06182682375164112,28.010768017134875,141.6479272461985,0.01928584217285317
0.0197106040936832,138.848412074217,0.06258116799744416,27.991839874162153,141.5851981536485,0.019518865562845725
0.0199574037458451,138.742041782649,0.06336475689305819,27.970395623382043,141.51097272702827,0.01976086539067838
0.0201926223851957,138.656027952327,0.06411157607299633,27.953055235189126,141.45585676619947,0.019991454942799414
0.0204165987360832,138.532712476339,0.06482270098706415,27.928194835229938,141.3610792787896,0.02021097404471145
0.0206571356738115,138.405340502403,0.06558640576435151,27.902516645284447,141.26439839914121,0.020446670516413273
0.0208967296231125,138.289512776155,0.06634711655338218,27.879165775672845,141.17931133435025,0.020681387762402848
0.0211118326413702,138.171923733427,0.06703006863635039,27.855459824658883,141.0889862630233,0.020892065644002773
0.0213405090549901,138.051784621157,0.06775611624959356,27.831239779625253,140.99787998092233,0.021115989022685373
0.0215730404576578,137.91382935651,0.06849440345306351,27.80342799827242,140.88904997688851,0.021343635859456644
0.0218137784393263,137.774655603296,0.069258746544861,27.775370569624474,140.78004141518076,0.02157926230135786
0.0220601229536559,137.657219368275,0.07004089037785748,27.75169542464424,140.69395455299752,0.021820318772948103
0.0222914233367559,137.534340134908,0.07077526909419997,27.726922971197457,140.60017633419662,0.02204660116993281
0.0225150028354646,137.425790413436,0.07148513400260009,27.7050393473487,140.5199324742605,0.022265281526897628
0.022741137983464,137.32319657924,0.07220311309749819,27.684356430374788,140.44608234097888,0.02248641289954854
0.0229949601980126,137.220182645073,0.07300899862869001,27.66358882124672,140.37555528336048,0.022734560464697934
0.0232271877709098,137.156734942086,0.07374632117263862,27.650797764324533,140.34250017863073,0.02296154224585474
0.0234599764269206,137.071171792046,0.0744854251554729,27.63354823327647,140.28685825109775,0.023189020739966273
0.0236902623731459,136.99648206245,0.07521658303473823,27.618490783789923,140.24196466670742,0.023414002710348342
0.023920854531411,136.930740601427,0.07594871313722992,27.605237305247684,140.2062409282321,0.02363923313358265
0.0241584871486589,136.84474896725,0.07670319669699201,27.587901391797605,140.15071107653677,0.02387128724738411
0.0244015820257769,136.752111988809,0.07747502293184165,27.569225776943895,140.08907986670212,0.024108619685828996
0.0246272623157378,136.656621624799,0.07819155785246751,27.549974919559478,140.02210009273543,0.024328899933710072
0.0248653651644155,136.521088117521,0.07894753439701921,27.522651364492237,139.91573482620652,0.024561252903958837
0.0251072281883375,136.40972211355,0.07971544949797156,27.500199978091683,139.8345921337626,0.024797219985497936
0.0253465136016107,136.296331677279,0.08047518068511397,27.477340466139445,139.7509685019868,0.025030617510623743
0.0255834218948668,136.196952389175,0.08122736451620209,27.45730560165768,139.68133648294236,0.025261642754547953
0.0258210281626129,136.07061055724,0.08198176441629595,27.431835088339586,139.58409362454245,0.025493295044082726
0.0260545255663144,135.961415911847,0.08272311867304821,27.40982144782836,139.50382609875456,0.0257208891633119
0.0262937544326044,135.839059515784,0.08348267032351896,27.385154398382053,139.41077838904792,0.025954016132749457
0.0265321986466777,135.756687636387,0.08423973070320169,27.368548227495623,139.3586110403706,0.02618632439520898
0.0267809559063071,135.674434762112,0.08502953500252504,27.35196604804178,139.30792581708926,0.026428622809646814
0.027026728232291,135.572482911121,0.08580986213752391,27.331412554881997,139.23656356253676,0.026667956150402256
0.0272686158712275,135.466299120351,0.0865778553911473,27.310005902662766,139.16027759456065,0.026903450662667677
0.0275185020462293,135.397876336897,0.08737124399677802,27.296211869518437,139.123823073929,0.027146674083775083
0.0277616631235079,135.293291591427,0.08814328041713758,27.27512758483168,139.0492583754587,0.027383294942122223
0.027997917107283,135.209395608047,0.08889338681562352,27.258214154582276,138.99497705840693,0.02761314087069021
0.0282452855998542,135.121927953713,0.08967878177953707,27.240580675468543,138.93848539956855,0.027853743240525544
0.028467911136902,135.011540113034,0.09038561785966384,27.21832648678765,138.8550366394281,0.02807022995172121
0.0287040185509291,134.899593255198,0.09113525889919988,27.195758000247917,138.77175368250798,0.028299775583427056
0.028938225864602,134.755371341609,0.09187886712011134,27.166682862468374,138.6549527139608,0.028527421876479258
0.0291676810635282,134.623540758174,0.09260738737670203,27.14010581684788,138.55019725865128,0.028750398934272465
0.0294095448468118,134.522633471203,0.09337530488862746,27.119762907794524,138.47888289318558,0.028985380436401607
0.0296471968242771,134.432293363577,0.09412984991707979,27.101550342097127,138.41783402446592,0.029216216210580005
0.0298707053121053,134.318913923704,0.09483948936593432,27.078693047018728,138.331114619361,0.029433265538943466
0.0301070946884925,134.211715038637,0.09559002563596368,27.05708175178922,138.25243985161023,0.029662772262195346
0.0303395837275213,134.122693794955,0.09632817833488012,27.039135069062933,138.19192049310774,0.02988844084411101
0.030591059341562,134.052211978868,0.09712661340945934,27.024925934939787,138.1530111503812,0.030132481676959394
0.0308386845686018,133.964637113557,0.0979128235053107,27.00727084209309,138.09593030084918,0.03037272777699009
0.0310905098966786,133.871057182199,0.09871236892195455,26.98840512793132,138.03317661040097,0.030616989636228324
0.0313360503442215,133.77377107344,0.09949195984290327,26.968792248405503,137.96571269853368,0.030855097943633364
0.0315935259009493,133.699307559942,0.10030944473551402,26.95378040408431,137.923340096276,0.031104719221091925
0.0318607554141677,133.620930110627,0.10115789843998244,26.9379795103024,137.8781938830953,0.03136373103165853
0.032118153407717,133.564652919883,0.10197513706950148,26.926634028648415,137.85450293221228,0.03161315024208129
0.0323623803898542,133.50590213384,0.10275055773778709,26.914789870182144,137.826470922986,0.03184974921143778
0.0326125845674559,133.431845080398,0.10354495600167249,26.89985996820824,137.78340241207417,0.032092080651839695
0.0328532165345185,133.353918639849,0.10430896249709624,26.88414999779356,137.73502380465055,0.032325085689272906
0.0331066485060993,133.263426647399,0.10511360900686526,26.86590681211564,137.6753320721328,0.03257042634389111
0.0333523259681101,133.102739840174,0.10589363494874957,26.833512351779078,137.54202580657204,0.03280820262322012
0.0335917433935004,132.98361707357,0.10665378527436375,26.80949720203171,137.4507686138449,0.03303986581141181
0.0338446967440264,132.861741922459,0.1074569121622838,26.784927171567734,137.35840728670775,0.03328456823309438
0.0340971929794638,132.761129426568,0.10825858770979756,26.764643692396113,137.28791127679727,0.033528768747573885
0.0343619849578217,132.649641789602,0.1090993022410839,26.74216778478376,137.2077467854367,0.03378479698601205
0.0346241198032089,132.538586218815,0.10993158037518824,26.7197789817131,137.1276181066032,0.034038191483139586
0.0348838739832487,132.439036431784,0.11075629989681461,26.699709744647652,137.05902308913323,0.03428922137254684
0.0351535539156626,132.39318182478,0.11161253368222875,26.690465455875646,137.0472726801235,0.03454977698405907
0.0354184485208024,132.321933138934,0.11245357405354761,26.676101720809097,137.0085707159884,0.03480564309861412
0.0356757501280433,132.232082504006,0.11327050665653746,26.657987832807613,136.94956123832972,0.0350541123461573
0.0359393733351089,132.117320442975,0.11410751033897076,26.634851801303764,136.86553414640932,0.035308622178126435
0.0361854668349698,132.025211714006,0.11488885720102911,26.61628268154361,136.802605633863,0.03554614985623443
0.0364393925387945,131.940582835516,0.11569507131067254,26.59922149964003,136.7484175252567,0.03579117799429501
0.0366822007210492,131.818207199666,0.11646598728933119,26.57455057145267,136.653589134853,0.036025422029140254
0.0369299875655122,131.695358374547,0.11725271052050122,26.549784248308676,136.5588663217547,0.03626441256656294
0.0371785727032685,131.575223767203,0.11804196833287747,26.525565111468126,136.46700278998077,0.036504115679223854
0.0374317787754028,131.464179521299,0.1188458976119039,26.503178591493878,136.38511760603012,0.03674821556353331
0.0376948982182036,131.370498901721,0.11968130184279642,26.484292578586953,136.32249648669597,0.03700180918471113
0.0379634552137137,131.273119863226,0.12053397030354099,26.464660964426358,136.25670106991805,0.0372605772007142
0.0382208529222342,131.168187284304,0.12135120802809357,26.443506556515686,136.18154727857345,0.03750852985966685
0.0384913654629597,131.082617157886,0.12221008534489704,26.42625561902982,136.12816608075144,0.03776904986803466
0.0387620190697445,131.019557785757,0.12306941054643877,26.41354284960861,136.09814038315798,0.03802963782550924
0.0390317464600017,130.924495155064,0.1239257950105054,26.3943782232609,136.03470685536016,0.03828926647224702
0.0392938722706018,130.805057606771,0.12475804445916071,26.37029961352503,135.94489483272017,0.03854151357888677
0.0395396306048725,130.653560941964,0.12553832717047017,26.339757885899946,135.81955447882046,0.038777952269215474
0.0397886304410368,130.521483369716,0.12632890165029184,26.313131047334746,135.71475443612957,0.03901745253670024
0.0400472623645588,130.39477244671,0.12715005800747417,26.287586125256734,135.61672610985033,0.03926615670201424
0.0402998346683154,130.268748180757,0.1279519750719014,26.262179633240613,135.51855719488992,0.03950897416777054
0.0405550379035483,130.142491520074,0.12876224534376585,26.236726290446917,135.42042519653282,0.03975426108313997
0.0408083296001264,130.040181449275,0.1295664464804013,26.21610058017384,135.34690403511726,0.03999765125881359
0.0410790184872634,129.936042879161,0.1304258836970613,26.195106244438858,135.2736879867559,0.04025769307991494
0.0413537238210592,129.874288246157,0.13129807313186295,26.18265651042525,135.2450736937452,0.040521524251801784
0.0416330741032347,129.80749787261,0.13218501027777016,26.16919157111818,135.21178305069586,0.04078974513935474
0.0419041947677902,129.723793958617,0.13304581838773388,26.152316862057187,135.15976508667558,0.04104999550313417
0.0421778228481555,129.657255704491,0.1339145875428937,26.138902750025387,135.12591646657302,0.0413125840957372
0.0424415960902266,129.565085079719,0.13475206758646946,26.12032115207135,135.0640340880683,0.04156565018644187
0.0427031324454944,129.45435128264,0.13558244551444473,26.097997218580225,134.98245759110816,0.04181650697643841
0.042964680820221,129.357637174317,0.13641286160420166,26.07849965434231,134.9154467671695,0.04206731237740788
0.0432267985999657,129.267331979865,0.1372450855548911,26.060294127140782,134.85514490491352,0.04231860070229046
0.0434918654414091,129.152773469526,0.13808667277647388,26.037199131456447,134.76986851464744,0.04257265204848944
0.0437613071651797,129.0489063994,0.13894215024944553,26.016259530119044,134.69625523167468,0.042830830336397556
0.0440408175927862,128.91403192522,0.13982959585709617,25.989068836124353,134.59151129038924,0.04309858600726494
0.0443182387168277,128.802462542621,0.14071040792592793,25.96657644859239,134.51076082490013,0.043364269367446896
0.0446045969470674,128.704928506524,0.141619595306939,25.94691358691524,134.44575996765863,0.04363843768725699
0.0448831059384227,128.625655124455,0.14250386135449206,25.930932073090126,134.39877402980494,0.043905018813932245
0.0451664939409241,128.51154946865,0.143403618262434,25.90792837287984,134.31596558906458,0.04417619707138077
0.0454515691050502,128.408877768063,0.14430873190853438,25.887229758041503,134.24526274964006,0.04444891562378574
0.0457312927052535,128.303001297697,0.14519685433917986,25.865885061615714,134.1704634050045,0.0447164423016102
0.0460079977119799,128.205260770193,0.14607539273553619,25.84618057127091,134.10372811437182,0.044981011609657305
0.0462957875337457,128.096447620059,0.1469891254196426,25.824243840203895,134.02677354290483,0.045256105337069384
0.0465789138921095,127.97533965155,0.14788805160744764,25.799828473752484,133.93629197749303,0.04552666750679515
0.0468605471983496,127.84392638379,0.14878223735475998,25.773335558972068,133.83476273011993,0.045795730274717235
0.0471406685898745,127.723993465726,0.14967162277285154,25.749157082690363,133.74498791266907,0.04606327681775054
0.0474113076815193,127.579864169032,0.15053090188882376,25.720100616476852,133.6285923631164,0.04632169875830571
0.047681709615536,127.443325500191,0.15138942802932678,25.692574420838504,133.52004113912932,0.0465798275700441
0.0479568409795075,127.331272682746,0.1522629701099363,25.669984572841596,133.43767827851076,0.04684240277937506
0.0482218816816853,127.20863128756,0.15310447433935082,25.645260067572096,133.34287085439783,0.047095282651425034
0.0484962106881038,127.102574088333,0.15397546893472955,25.623878936207934,133.2665673003211,0.047356957321932354
0.0487787505795,126.959331276561,0.1548725330899125,25.5950011853547,133.1522488306405,0.047626392563685165
0.0490564249853422,126.800158030541,0.15575414932846146,25.562911858957065,133.02052047109578,0.047891117276758946
0.0493410660270721,126.673503747591,0.1566578846359539,25.53737835551435,132.92370945988145,0.04816241100894726
0.0496204520549809,126.542992622501,0.15754493527456434,25.511067312696206,132.82211312081964,0.048428624588521776
0.0498984415588049,126.410344598386,0.15842755194920555,25.48432547103462,132.71802379075694,0.04869343716657853
0.0501692550908404,126.243122770652,0.15928738491341826,25.450613550563446,132.5766462003971,0.04895134650347152
0.0504546466436104,126.093619050591,0.160193503093463,25.42047360059915,132.4556280438026,0.04922306725680615
0.0507264906959228,125.964360857979,0.16105660795955487,25.39441514896857,132.35409083705915,0.049481820820692926
0.0510012813588159,125.842867514969,0.16192906831424048,25.369922091017752,132.26101500810012,0.049743311074675896
0.0512753774786426,125.706438043652,0.16279932349469026,25.342417909600243,132.15208310583586,0.05000407230248818
0.0515572226182445,125.563664698328,0.16369418181292628,25.31363480318293,132.0373785119423,0.050272134668723885
0.051839466216419,125.414231414659,0.1645903052371303,25.283509053195253,131.91563822713738,0.050540504017564845
0.0521363772415633,125.297202734641,0.16553299774196348,25.25991607130363,131.82974496372688,0.05082274207465893
0.0524089696255374,125.152233034659,0.16639847856108123,25.230690179787256,131.71133261434062,0.0510817931670047
0.0526895302378459,125.029586524505,0.16728925850516072,25.20596464334021,131.6173367043133,0.05134834659810333
0.0529756711236253,124.894268815684,0.1681977558175103,25.178684593241897,131.51062652568933,0.05162012853889412
0.0532313636662617,124.76794855421,0.1690095796403809,25.153218428528735,131.40951659759259,0.05186292759869129
0.0535227197204621,124.631188017775,0.16993463511246718,25.12564750438344,131.3017881624786,0.05213951997210156
0.0538038392494386,124.489062677868,0.17082718961696755,25.09699503585819,131.18705219450132,0.05240632202937879
0.054084018306366,124.355272342229,0.17171675812271203,25.070022904193365,131.08090516807925,0.052672160705352994
0.0543696108697347,124.195992839401,0.17262351451140767,25.03791215642324,130.9484806416596,0.052943063096720144
0.0546588438747052,123.996874338394,0.173541829302189,24.997769866620228,130.7744001338077,0.05321734389756284
0.0549359471531062,123.800780785545,0.17442163221111218,24.958237406365875,130.60189393629298,0.05348005148593313
0.0552518747023973,123.597818487912,0.1754247021801114,24.91732020716306,130.42682966849577,0.053779482227007055
0.0555358915457444,123.409824729024,0.17632645565773844,24.879420665371235,130.2634993708544,0.05404859203482633
0.0558256394540194,123.229347438778,0.1772464052665116,24.84303644365765,130.1087045590493,0.054323057497836426
0.0561091829080275,123.052277217633,0.1781466557329873,24.807339087074816,129.95663994728648,0.05459157284472084
0.0563926656762927,122.898955150647,0.1790467135222293,24.776429358370432,129.82955484042313,0.054859958664271034
0.0566814451584599,122.71746942964,0.1799635883781102,24.739841837015426,129.67327294310113,0.055133285077655414
0.0569799183098418,122.552456986437,0.18091124063374772,24.706575328465696,129.5354859741946,0.055415707946828874
0.0572620862688622,122.389515370012,0.18180712390363749,24.67372629859442,129.39779435753388,0.055682629103521994
0.057564341862358,122.214212205999,0.18276678541298666,24.6383851807294,129.24939289786388,0.05596847345607328
0.057844623159662,122.017808845651,0.18365667853192683,24.598790263283245,129.07588301709538,0.05623346363393363
0.0581316982452747,121.791948088555,0.18456814192874715,24.553256734652688,128.87192086354304,0.05650480418200109
0.0584261784836467,121.551871396875,0.18550311668557826,24.50485727361,128.65368273013007,0.05678306752977897
0.0587229954163174,121.343165146826,0.18644551044680774,24.462782093600122,128.4687992775445,0.057063460558550376
0.0590126696033401,121.137509278994,0.1873652259906048,24.421321870645194,128.28615709064684,0.057337030290235264
0.0593069895093591,120.926778252518,0.18829969169221514,24.37883849570763,128.0985814217407,0.05761491083262346
0.0595867181433704,120.680727372303,0.18918783010520102,24.329234638256285,127.87169585957335,0.05787894355368545
0.0598841981252913,120.42664774456,0.19013232904779986,24.278012185303297,127.6383009776599,0.05815965510447003
0.0602064668010828,120.179994142818,0.19115553209343786,24.228286819192107,127.41560697033191,0.05846366915783587
0.0605054379615867,119.930418439747,0.19210476552803776,24.177972357452997,127.18686093236026,0.05874562274315138
0.0607942656286929,119.693789924615,0.19302179337109995,24.130268048802385,126.97048598339701,0.05901793473037505
0.0610911953384586,119.432064593172,0.19396454519960604,24.077504221983478,126.72831218090887,0.05929780818930204
0.0613917579742836,119.16501806844,0.19491883156835044,24.023667642597506,126.4807680166988,0.059581026141526314
0.0616903152765729,118.873869346182,0.19586675100311896,23.964972060190295,126.2072358242941,0.05986227509371609
0.0619890990861602,118.585738282861,0.19681538959855863,23.906884837824776,125.93676136348273,0.060143658253093195
0.0622611166060649,118.288973889076,0.19767904522425603,23.847057136037726,125.65377748559554,0.060399765108474036
0.0625563164710995,117.972746338925,0.19861630479574088,23.78330566192728,125.35268679386753,0.06067762414929168
0.0628586456764145,117.668916641684,0.19957620002261603,23.722053594963494,125.06542537999117,0.0609621137315506
0.0631557723044718,117.364003275166,0.20051957706669793,23.660583060273467,124.77621754275366,0.061241628891446895
0.0634450947529406,117.024253302049,0.2014381758405864,23.59208946569308,124.44886814118962,0.06151372738885247
0.0637411288462627,116.72468099429,0.20237808408688407,23.531695688448863,124.16484392508596,0.06179206136069673
0.0640335664152289,116.425819229076,0.20330657336835176,23.471445156581723,123.88097965712848,0.0620669378045784
0.064325609007451,116.091834465993,0.20423380859865692,23.40411382834419,123.5595124188102,0.06234136760705477
0.0646141896269172,115.738000264803,0.2051500520654621,23.33278085338429,123.21631736095318,0.0626124702670912
0.0648972961116618,115.40436116092,0.2060489151545262,23.265519210041475,122.8937921597574,0.06287835893527494
0.0651808188172046,115.082315029878,0.20694909974462458,23.200594710023406,122.58347455490494,0.06314456767685107
0.065475267947045,114.756346140871,0.20788397573186787,23.134879381999596,122.27004865306837,0.0634209605997109
0.0657767873760885,114.419780446377,0.20884129991908096,23.067027737989605,121.94594601641705,0.0637039111125815
0.0660684980815464,114.08027358283,0.2097674814089098,22.99858315429853,121.6173859191795,0.06397758079139791
0.0663682148545954,113.775215323508,0.2107190821633404,22.937083409219213,121.32627325922643,0.06425868341283035
0.0666544094620038,113.43889724351,0.21162775004186204,22.869281684291618,121.0000999492971,0.06452702994217625
0.0669470896550308,113.009668823672,0.21255700965472277,22.782749234852275,120.57533725429572,0.06480138313791962
0.0672455291670213,112.596922034521,0.21350455510529262,22.699539482159434,120.16856163931021,0.06508105753216477
0.0675450170869927,112.215500058986,0.2144554292512018,22.62264481189158,119.79509792789563,0.06536163580478418
0.0678318647752134,111.843722316128,0.21536617066130254,22.547694418931407,119.43029056423211,0.06563029815884691
0.0681121381514503,111.457431078954,0.21625603863085469,22.46981810551713,119.04903502260946,0.06589273329521882
0.0684244280635138,111.059115882067,0.2172475591016563,22.38951776182471,118.65827236753694,0.06618506614757977
0.0687379734972949,110.671444338766,0.21824306585391126,22.311363178695224,118.27877514663143,0.06647848833749069
0.0690376218709218,110.332292895092,0.21919444944017671,22.242990247650546,117.94937201213516,0.06675882494179912
0.0693369124064927,109.899706584926,0.2201446968906143,22.155780847521083,117.51981291390425,0.06703874834411011
0.0696322661951807,109.470359332029,0.22108244516969872,22.069224441337045,117.09302853351893,0.06731491295042602
0.0699219610424582,109.041315379516,0.22200222630980476,21.98272918051043,116.66569798550093,0.06758571220885083
0.0702307591472156,108.538456841806,0.22298266029240954,21.88135289930809,116.16119506247333,0.06787428797635302
0.0705117023118083,108.05655051049,0.22387465483999133,21.78420058291478,115.67580183292654,0.06813676061961915
0.0707953246305504,107.637825184299,0.2247751557019975,21.69978555715468,115.25807996074788,0.06840166641484809
0.0710954578364448,107.197020857156,0.22572807863071223,21.610919404802654,114.81824213369845,0.06868191712633692
0.0713940332253005,106.815732465183,0.22667605549032907,21.534051664980893,114.44173841778708,0.06896063531098529
0.0716955452904567,106.341045965662,0.2276333562972,21.43835486667746,113.96522524292766,0.06924201605229273
0.071998061056029,105.844295356471,0.22859384385289208,21.338209943864555,113.46487939597854,0.06952425393058356
0.0722953859354381,105.434108241113,0.22953785034501598,21.25551622140838,113.05650778716301,0.06980157127418855
0.0726037575953295,105.019405109737,0.23051693036517115,21.171912070122975,112.64420854113006,0.07008911081929606
0.0729052383664336,104.57737004626,0.2314741318134267,21.082797801326016,112.20160813721733,0.07037014508543601
0.0731957165297054,104.1117233529,0.23239639998181463,20.98892342794464,111.73225554285798,0.07064084825471884
0.0734886135025243,103.618101805707,0.23332634787051462,20.88940932403053,111.23285244117181,0.07091373138945715
0.0737775809766062,103.103759211122,0.23424381960072466,20.785717856962197,110.71050515531304,0.07118288057698612
0.0740745618351763,102.59740302089,0.23518673382668473,20.683636449011424,110.19726069508943,0.0714594181044474
0.0743671010550397,102.066797863275,0.23611554584975103,20.576666449236242,109.65720973433748,0.07173174499767827
0.0746345372887864,101.510011610029,0.2369646558918968,20.464418340581847,109.08616435672285,0.07198063846556171
0.0749139728840453,100.980024221645,0.23785186390684382,20.35757288308363,108.54483901801555,0.07224063315329315
0.0752011362072995,100.452346577526,0.2387636074581759,20.25119307002924,108.00647717484539,0.07250774752660963
0.0754858242150079,99.8928796275328,0.23966749188265005,20.138404532910613,107.43337597942768,0.07277248899257842
0.0757816409935399,99.4413815451446,0.24060671015448917,20.047382519501152,106.97721262130037,0.07304750526571104
0.076071592051338,98.9937804581765,0.24152730476299814,19.957146140368383,106.52439494081062,0.07331699488991053
0.0763787985364791,98.5219440750238,0.24250268535332112,19.8620239255248,106.0469317929523,0.0736024430364233
0.0767171229792323,98.0349047249232,0.24357686545906254,19.763836792544517,105.55586056696245,0.07391671091660175
0.077037743301445,97.4785553399816,0.24459483498208787,19.65167675654029,104.98808326365881,0.0742144424083336
0.0773357574566073,96.9167781764592,0.24554102992472815,19.538422480374177,104.41191062698967,0.0744911021026329
0.0776298278007191,96.3522444519884,0.24647470326728313,19.42461248152086,103.83205259700904,0.0747640255757026
0.0779122722488377,95.7471752959713,0.2473714643900597,19.302630539667813,103.20705528468821,0.07502608907214611
0.0781712454445287,95.1444978019155,0.24819370428637863,19.181130756866168,102.58206169228546,0.0752663146430122
0.0784499229100414,94.5709593408785,0.2490785052393814,19.065505403121104,101.99004381069909,0.0755247536040621
0.0787076080152097,93.9879072743688,0.24989665544829082,18.947962106512747,101.3854706382897,0.07576366532256186
0.0789941117025222,93.3896497694588,0.25080630465550796,18.827353393522895,100.76688219520685,0.07602922908086815
0.0792886345042712,92.789843023706,0.2517414145510611,18.70643235357913,100.14702297292132,0.07630215236128156
0.0795871679455657,92.1378752910653,0.2526892582271711,18.574995658678766,99.4708678460029,0.0765787161569929
0.0798926946789276,91.4611894530778,0.2536593056055951,18.438575793740483,98.76827033702409,0.07686167942114584
0.0802188937427984,90.739471563734,0.25469498763338494,18.293077467248775,98.01849159138285,0.07716369999091527
0.0805366455651353,90.0233674688643,0.2557038496693046,18.14871088172304,97.27354750728415,0.07745781176695563
0.0808556086311518,89.2881235555472,0.256716557403907,18.00048570879832,96.50756912916445,0.07775295770144551
0.0811647298617605,88.5479177480556,0.2576980173110896,17.851260218008008,95.73488557189792,0.07803891359854005
0.081480409341679,87.7208457563881,0.25870029965983077,17.68452250448784,94.86837617641689,0.07833085190726946
0.0818070820054653,86.9457662548711,0.2597374853673523,17.528266476982015,94.05854568491135,0.07863286693539308
0.0821228409389642,86.1481634384558,0.2607400199812113,17.36746974919269,93.222895361696,0.07892470534697199
0.0824659367260444,85.2999966782633,0.26182934910519096,17.196479330337883,92.33434080706475,0.07924171317173156
0.0827848498721468,84.262887309193,0.26284189834406607,16.98739808153331,91.23857778487817,0.07953628703853957
0.08311538023161,83.2697544154182,0.2638913322353617,16.78718249014831,90.19075171544847,0.07984149995410698
0.0834534477607396,82.2320306714543,0.2649646966403482,16.577977383365187,89.09457714735404,0.08015357638344119
0.0838327006982012,81.1334367772214,0.2661688247167888,16.356500854287837,87.93507189918263,0.08050355595729886
0.0842239501608036,79.8748733131286,0.2674110417605514,16.102774459926728,86.60225066215405,0.08086447776872341
0.0846483571686446,78.5554995610963,0.2687585340104466,15.836788711517013,85.20509354550528,0.08125583968691816
0.0850868062585417,76.9382250008278,0.2701506098708699,15.510746160166885,83.48465284534933,0.08165998956037329
0.0855527053317315,75.2540102156613,0.2716298394282475,15.171208459477318,81.69219437667289,0.08208926312501323
0.0860314342388877,73.2683558310055,0.2731498037084685,14.770900535530707,79.57173756747207,0.08253016606419758
0.0865403194731552,71.0055775434562,0.27476551432726776,14.31472443276077,77.15042290844279,0.0829986295271
0.0870141041294152,68.4978510970517,0.27626978061089325,13.809166781165622,74.45813024505173,0.083434583334945
0.0872615080538002,67.3191652642668,0.27705528807081564,13.571543717276189,73.19353714614972,0.08366215699126196
0.0875078117212972,65.9279863981873,0.2778373022151186,13.29108205787456,71.69720021908412,0.08388866714690062
0.0877423152378226,64.6236370905594,0.27858185088008675,13.028125237456775,70.2938646279739,0.08410427776981458