File: example/data/02 processed data/test_ID_092.csv
Strain,Stress_MPa,Displacement(mm),Force(kN),True Stress (MPa),True Strain
0.0007991534053124824,46.8713138583788,0.0025373120618671315,18.89851374769833,46.90877122846019,0.0007988342522533531
0.0009035556338386824,53.2033200508823,0.0028687891374378164,21.451578644515745,53.25139221045319,0.0009031476731718169
0.0010090896562543823,59.2464305106826,0.003203859658607664,23.888160781907224,59.30621547088093,0.0010085808675341348
0.0011143344894295824,65.4009828476236,0.003538012003938924,26.369676284161834,65.4738614184533,0.00111371407960565
0.0012213216547958825,71.6176005588493,0.0038776962539769266,28.876216545328038,71.70506868527634,0.0012205764481998446
0.0013302984791001824,77.9060459128244,0.004223697671143079,31.411717712050795,78.00968420721493,0.0013294144160367176
0.0014351987506649824,84.1827178862861,0.004556756033361318,33.942471851750554,84.30353681782407,0.0014341698372837494
0.0015375732900113825,90.4573363436882,0.0048817951957861394,36.472398013775084,90.59642112793583,0.0015363924344799335
0.0016426890549215824,96.7458618642931,0.005215537749376024,39.00793150368298,96.90478523268652,0.001641341316996933
0.0017489647030411823,103.037117975874,0.0055529629321557535,41.544565967872394,103.21732625831689,0.0017474370452285446
0.0018554168388468825,109.33060047169,0.005890948463338852,44.082098110185406,109.53345430880643,0.0018536976792006964
0.0019640615185496824,115.502953368341,0.006235895321395241,46.570790798115084,115.7298082743306,0.0019621352714914446
0.0020656615368716824,121.557663835293,0.006558475379567591,49.012050058390145,121.80876082598955,0.002063530991565086
0.0021729151860440826,127.679436150935,0.006899005715689962,51.480348656057,127.95687273669292,0.0021705578201277414
0.002274902998769282,133.695764341576,0.007222817021092471,53.90613218252344,133.9999092367994,0.002272319324605766
0.0023733484990798824,139.730487000675,0.007535381484578626,56.339332358672166,140.06211614227374,0.0023705365557994728
0.0024722416444794824,145.680260675201,0.007849367221222356,58.73828110424104,146.04041748242088,0.0024691906825473767
0.0025652116849739824,151.432939369886,0.008144547099792393,61.05776115393803,151.82139691544756,0.002561927145306817
0.0026670359719247823,157.142626728013,0.008467839210861184,63.359907096734844,157.56173176621937,0.002663485742479114
0.0027608057579961826,162.717326726724,0.00876555828163788,65.60762613621512,163.1665576592769,0.002757001733619339
0.0028595108121335826,168.270874906955,0.009078946828524124,67.84681676248425,168.7520472931186,0.0028554301882990733
0.0029555672970323823,173.713321910329,0.009383926168077813,70.04121139424466,174.226743323626,0.0029512081949761523
0.0030521717345179823,179.013564063243,0.009690645257094593,72.17826903029957,179.55994420357214,0.0030475233144851457
0.0031470308772804825,184.292195610274,0.009991823035365532,74.30661327006248,184.87216884030136,0.003142089340341127
0.0032409402209292826,189.457669938461,0.010289985201450472,76.38933251918749,190.0716909211281,0.00323569969394178
0.0033395465658990825,194.566402726996,0.010603060346729587,78.44917357952478,195.2161662890623,0.003333982664097856
0.0034385958636144825,199.56259634383,0.010917541866975982,80.46363884583226,200.24881146215006,0.0034326974105878022
0.0035374069550055823,204.535410937023,0.011231267082142723,82.46867768980766,205.25893592221655,0.0035311650468048375
0.0036377625055258826,209.333500402757,0.011549895955044676,84.40326736239163,210.09500596167265,0.003631161850403145
0.0037403597054400826,213.856065544452,0.011875642064772261,86.22676562752305,214.65596415477845,0.0037333819541976085
0.0038472436498673823,218.090800973861,0.012214998588328939,87.93421095266076,218.92984942300217,0.0038398619347967122
0.003964989493030482,222.069820609367,0.01258884164037178,89.53855166969677,222.95032511480233,0.003957149638651192
0.004090340538338982,225.744038745537,0.012986831209226269,91.01999642220053,226.66740873850625,0.004081997837400171
0.004232418322082082,229.244781235953,0.01343792817261061,92.43149579433626,230.21504104829776,0.0042234868319886015
0.004400195435981483,232.477653799928,0.013970620509241206,93.73499001213096,233.50060091114614,0.00439054288110429
0.0046053963885211826,235.56367626928,0.014622133533554753,94.9792742717737,236.6485403732373,0.004594823998178486
0.004850133483980082,238.446070462622,0.01539917381163676,96.14145561052919,239.60256573309624,0.004838409479947922
0.005139566587021682,240.988437958395,0.01631812391379384,97.16653818482486,242.22701408198452,0.005126404095076446
0.005445530956258982,242.991015955086,0.017289560786122267,97.97397763309067,244.3142310545622,0.005430757660586114
0.005777445888469183,244.487567975512,0.018343390695889653,98.57738740772643,245.90008166989395,0.005760820452275468
0.0061258171847320825,245.595665518165,0.019449469561524362,99.02417233692414,247.10013966649186,0.006107130641377128
0.006477171619730982,246.319195354271,0.020565019892645867,99.31589956684208,247.91464705581464,0.006456284886424771
0.006839543801854482,246.859326974471,0.02171555157088798,99.53368063610671,248.5477321542092,0.006816260227870979
0.007216500853826083,247.20862662095,0.02291239021089781,99.67451825356704,248.99260788603328,0.007190586510770079
0.007594818085251083,247.43179473154,0.024113547420672187,99.76449963575693,249.31099420103322,0.007566122653846935
0.007980689849724384,247.675020334015,0.025338690272874918,99.86256819867484,249.65163785482494,0.007949012570566464
0.008353221865003584,247.912260687691,0.026521479421386378,99.95822350927702,249.9831268042699,0.008318526783816206
0.008728419287360182,248.109382931765,0.027712731237368577,100.03770319808766,250.27498565512167,0.008690546853831409
0.009098998833434582,248.343714679713,0.028889321296154798,100.13218575886029,250.60339384987455,0.009057852349745337
0.009471426278303583,248.58374779376,0.030071778433613874,100.22896711044405,250.93819043497302,0.009426853544315127
0.009843376954556681,248.843563278806,0.031252721830717464,100.33372471401458,251.29302427487437,0.009795246505991286
0.010223347709436281,249.119151161501,0.03245912897746019,100.44484174831722,251.66598286490463,0.010171442752106807
0.010604807579504383,249.326698587973,0.03367026406492642,100.52852487067072,251.97076025093156,0.010548971018031412
0.010983770036093483,249.445622768102,0.03487346986459681,100.57647510009872,252.18547612509695,0.010923886532715437
0.011363914194975282,249.565739454478,0.036080427569046516,100.62490614804554,252.40178310364425,0.011299829963534121
0.011738594526680083,249.693180604936,0.03727003762220926,100.6762904199102,252.62422760813445,0.011670231694907943
0.012115234238751282,249.954106882468,0.03846586870803532,100.7814958950111,252.982359436287,0.012042432207678267
0.012491644813441283,250.247858142812,0.03966097228267607,100.8999364031818,253.37386550205645,0.012414267928401597
0.012866695754838682,250.472862634403,0.04085175902161281,100.99065821419128,253.69562075276335,0.012784623078077508
0.013242221178690682,250.584110993909,0.042044052242342915,101.0355135527441,253.90240121555593,0.013155309397073994
0.013614070947126782,250.745319724455,0.04322467525712753,101.10051291290026,254.15898429684373,0.013522232078324467
0.013987017655396283,250.881870822553,0.044408781055883195,101.15557031565336,254.3909599791669,0.013890101985843869
0.014356400448439083,251.111264050349,0.045581571423794084,101.24806166510072,254.71631791416954,0.01425432314664871
0.014722774432224684,251.387722051984,0.04674480882231337,101.35952953135995,255.08884677878618,0.014615446549128759
0.015085507019993782,251.660391604129,0.047896484788480256,101.46946989478482,255.45681620832747,0.014972852314929286
0.015445137000317483,251.974331704596,0.049038309976008006,101.59605054329312,255.86610977833692,0.015327074976028341
0.015799569198517584,252.227111154927,0.050163632205293324,101.69797121766656,256.21219085136147,0.015676055284226123
0.016153716488128383,252.398042686318,0.051288049849807615,101.76689081112342,256.47520911003136,0.016024633468273486
0.016506993332865285,252.594347587554,0.052409703831847274,101.84604094730177,256.7639207991012,0.016372233878501254
0.01685773803910858,252.629612537574,0.05352331827416974,101.86025977514983,256.8883763666539,0.016717223347739753
0.017211875315763184,252.70965291845,0.05464770412754811,101.89253205671903,257.05925995557214,0.01706542901180133
0.017567151986523484,252.793314342958,0.05577570755721206,101.92626434308067,257.2341729171978,0.01741463319525659
0.017928648384069483,252.901596126694,0.05692345861942061,101.96992355828301,257.4357799194194,0.017769825675909984
0.018295832733167684,253.129834121463,0.05808926892780739,102.06194911777389,257.7610552263238,0.01813047781076372
0.018660422052539982,253.327550416367,0.05924684001681444,102.14166832787919,258.0547494246725,0.01848845243334977
0.019020388272463582,253.506970264595,0.06038973276507187,102.2140104106847,258.32877126880345,0.018841762158645452
0.019377689526619384,253.680192401933,0.06152416424701654,102.28385357645939,258.59592840935073,0.01919233279713519
0.019730634482553282,253.89805309642,0.06264476448210667,102.37169500847655,258.90762277789736,0.01953850857926783
0.020084731330895784,254.17798404339,0.06376902197559411,102.48456316629485,259.2830805631302,0.019885693778314773
0.020439877520227884,254.496749139347,0.06489661112672353,102.61308925298472,259.6986315210514,0.020233786804370546
0.020795074809869585,254.739310217609,0.06602436252133592,102.71088987973995,260.03663323059874,0.020581808763157072
0.021152007626965383,254.904519717654,0.06715762421561508,102.7775023501581,260.29626206286974,0.02093140922420842
0.021507684994010682,255.034733721015,0.0682868998559839,102.83000463631325,260.519940436418,0.021279658491499452
0.021856300672425284,255.116488638455,0.06939375463495027,102.86296821902506,260.69239132063046,0.021620875899893005
0.02219975235986108,255.209205971538,0.07048421374255893,102.90035184772412,260.87478714406296,0.021956925090088668
0.02254305659779768,255.418244374187,0.07157420469800764,102.9846361316722,261.1761523132244,0.022292717190355225
0.022886371317107083,255.68082819704,0.07266422893181498,103.09050992904653,261.5324345698229,0.022628406818995382
0.023233921332474684,255.898253295298,0.07376770023060712,103.17817572866416,261.8437731814786,0.022968122934375865
0.023581289312318884,256.169041883818,0.07487059356661245,103.28735768755543,262.20983817333985,0.02330754584013958
0.023922908756555582,256.266167087008,0.07595523530206397,103.32651856948164,262.3967992196227,0.023641239365875838
0.024265206724228782,256.434069131243,0.07704203134942637,103.39421667371718,262.6564948298478,0.023975484026581426
0.024609232776411184,256.543838418006,0.0781343140651055,103.43847565014,262.85718545498867,0.024311303585635793
0.024956543358144182,256.730206935424,0.07923702516210777,103.51361943636297,263.13730547615324,0.02465021496784328
0.025307038473817583,256.948336167599,0.08034984715437082,103.60156914277592,263.4509375967759,0.0249921174648623
0.02565412055488458,257.131343085732,0.08145183276175855,103.67535753216714,263.72782155969276,0.02533057544379799
0.025995470849439685,257.294565738421,0.08253561994697099,103.74116890573136,263.98305912179336,0.025663332362069927
0.026336515786849285,257.392896929997,0.08361843762324647,103.78081604217479,264.17172902341673,0.025995681068584877
0.026673327508598084,257.536597145434,0.08468781483979891,103.83875596903897,264.40595514654404,0.026323796129377693
0.027008047761728084,257.713217365926,0.08575055164348666,103.90996924194138,264.67354824937354,0.02664976710045851
0.02734693714116288,257.926459748956,0.08682652542319215,103.99594857077906,264.9799584307534,0.026979690005700652
0.027684132170343285,258.077198651332,0.08789711964083992,104.05672649621707,265.22184192894747,0.027307855391851703
0.028028804058631483,258.287875481187,0.08899145288615495,104.1416713940146,265.52737573376936,0.027643186152721513
0.028375301570418184,258.501878847294,0.09009158248607772,104.22795755122894,265.8369476161057,0.027980179756379002
0.028720807521786584,258.726900388897,0.0911885638816724,104.31868623680326,266.15774589567496,0.02831609595697866
0.029063953813865083,258.957435241284,0.09227805335902163,104.4116378892857,266.4837621788936,0.0286496063432023
0.029399590838470584,259.159888692543,0.0933437009121441,104.49326712083334,266.77908338184733,0.028975710760695484
0.02973110788121878,259.348273484374,0.09439626752286963,104.5692238688996,267.0589849821457,0.029297707849873695
0.030058268540562184,259.455144505925,0.09543500261628493,104.61231426478895,267.2539169137144,0.02961537204004721
0.030387083868157482,259.566662634507,0.0964789912814,104.65727837423323,267.4541365813595,0.02993454122354656
0.030719868804427782,259.692262115303,0.0975355834540582,104.70792008489016,267.66997433701016,0.030257459875322967
0.031060465605875283,259.914239756176,0.09861697829865401,104.79742146969016,267.98729706059993,0.030587850847495334
0.031400385019398486,260.168275129326,0.09969622243659018,104.89984853214425,268.33765913821964,0.030917475932497936
0.03174188647010278,260.361979240695,0.10078048954257632,104.97795002984823,268.6263596268844,0.03124852576705592
0.03208250041854258,260.597132862363,0.10186193882887269,105.07276397010477,268.95774048649076,0.03157860613018793
0.03242149673578058,260.743594974493,0.10293825213610334,105.13181749371559,269.1972925878342,0.03190701074529352
0.032761971486555984,260.944714514915,0.10401925946981525,105.21290889241372,269.4937778114201,0.03223673908091027
0.03310580890597868,261.131224736876,0.10511094327648231,105.28810981390839,269.77618516239914,0.032569613649032214
0.033446761358423484,261.249061157822,0.10619346731299456,105.33562145883383,269.98699616147985,0.032899585855347704
0.03378947566077158,261.410444950943,0.10728158522294977,105.40069140422021,270.2433668180843,0.033231153481099
0.03412476001986858,261.481952227127,0.10834611306308274,105.42952313797761,270.40496109640446,0.03355542646713489
0.034463740622689386,261.737425626695,0.1094223764770388,105.53253001268344,270.7578763747439,0.03388316744195869
0.03480300190146488,261.91036059763,0.11049953103715099,105.60225739296442,271.0256273755227,0.034211072273987814
0.03514255055282038,262.069736720279,0.1115775980052047,105.66651784561651,271.27953569133575,0.034539147236151445
0.035484064039478486,262.196626397575,0.11266190332534419,105.71767976350226,271.50042827960175,0.03486901210637765
0.03582509608123188,262.321240513981,0.11374468005791122,105.76792417523716,271.7189241595423,0.035198303408131085
0.03616606870809248,262.51548466869,0.11482726814819363,105.84624341841582,272.00963772415605,0.03552742897172704
0.03650406198860738,262.712647138162,0.11590039681382842,105.92573932610692,272.30272589448464,0.035853571833058644
0.03683851855189228,262.920335811352,0.11696229640225798,106.00947939913713,272.60593147980825,0.03617619730684663
0.037169854779703686,263.075764572087,0.1180142889255592,106.07214827546548,272.85425253729096,0.03649571022192519
0.03750127863619778,263.132988042954,0.11906655966992795,106.09522077891907,273.0008115459281,0.03681520554238838
0.03783773954264928,263.254802058011,0.12013482304791147,106.14433618979005,273.21576869163374,0.0371394522379424
0.038176313076489284,263.429175197447,0.12120979401785346,106.21464343961065,273.4859298632661,0.037465628774574954
0.03852163947999419,263.608885653655,0.12230620534898154,106.28710269555371,273.7635321105281,0.03779820136295979
0.038865555805501585,263.761387653555,0.12339813968246753,106.34859150191338,274.0126205847408,0.038129306059696076
0.039206751604203886,263.885630205998,0.12448143634334734,106.3986860990584,274.2317285614033,0.038457683277901306
0.039547426751111385,264.04347530073,0.12556307993477864,106.46232924125434,274.4857152992945,0.038785451855354744
0.039884397878546286,264.277448635327,0.12663296326438445,106.55666728976385,274.8179955470255,0.039109551088994846
0.04022443783681108,264.438904606832,0.12771259013187516,106.62176633747468,275.07581088682394,0.0394364954829181
0.04056606073853988,264.567995488022,0.12879724284486413,106.67381578077048,275.30047686246286,0.03976485425332978
0.040907041789077885,264.648883286062,0.12987985768032229,106.70642974094021,275.47488621407774,0.04009248861302826
0.04125017380274528,264.771604977447,0.13096930182371627,106.75591112690664,275.6934797007985,0.04042208141630393
0.04159117152051858,264.873517302998,0.1320519695776465,106.79700217656878,275.88991719239004,0.040749516553488616
0.041935212535302885,265.045170349845,0.13314429979958664,106.8662126850575,276.15989589992137,0.0410797653283964
0.04227924952199058,265.200847140891,0.13423661723232008,106.92898156720727,276.413339930604,0.04140990121035619
0.042623344067988386,265.3222620278,0.13532911741586312,106.97793604960896,276.63118409110785,0.04173998334482132
0.04296394053722059,265.517811408279,0.13641051120567535,107.05678155981809,276.92550286919726,0.042066602589936844
0.04329954170987158,265.658946196837,0.13747604492884227,107.11368710656468,277.1618568182875,0.04238832722194185
0.04363874692743398,265.821413344556,0.13855302149460288,107.17919386052498,277.42152672939187,0.04271340173171179
0.043975468826867085,265.959295685479,0.139622113525303,107.23478802038514,277.6549804021113,0.04303599189210827
0.04431536133231898,266.031886647788,0.14070127223011275,107.26405669638812,277.8211858305033,0.043361514088101974
0.044653593240347886,266.168125067612,0.14177515853810452,107.31898802726116,278.05348825792714,0.04368534073975617
0.04498955052495198,266.34891137957,0.14284182291672254,107.39188106824263,278.3318291853471,0.04400688586912544
0.045319098180123085,266.564968593264,0.1438881367218908,107.47899533680403,278.6454525763235,0.04432219591494617
0.045654609575121484,266.710452839851,0.14495338540101071,107.53765458502792,278.88701443385827,0.044643109943308716
0.045994171525018585,266.840190232232,0.14603149459193399,107.58996470163594,279.11328371154184,0.04496779347139259
0.04634124371837258,266.970377160806,0.14713344880583293,107.64245607123698,279.3421164744007,0.045299549263517314
0.04669158882294748,267.172068697552,0.14824579451285824,107.72377809885296,279.6467570741544,0.04563432194591391
0.04703713883065938,267.381195255077,0.14934291578734352,107.80809792684704,279.9580416569977,0.04596440292181618
0.047380591764062785,267.505997426799,0.15043337885089933,107.85841816248536,280.18058988531664,0.04629237277373728
0.04772324773074888,267.536529925005,0.15152131154512768,107.87072886576203,280.304242019641,0.046619474431690414
0.04806534049176858,267.631997582874,0.15260745606136525,107.9092214254148,280.49582067318704,0.046945931752796384
0.048407391819287784,267.757665484736,0.1536934690262387,107.95989072344555,280.7191157104734,0.04727224301388036
0.04875124304919648,267.878651342828,0.1547851966811988,108.00867222142824,280.93806858213316,0.04760016406598674
0.04909647503633558,268.015346339869,0.15588130824036547,108.06378764423518,281.1739551007992,0.047929293761416324
0.04944856221643108,268.125024203837,0.15699918503716867,108.10800975898707,281.3834211449625,0.04826484737322735
0.049803653281382886,268.281745071304,0.15812659916839064,108.17119961274977,281.64315608455956,0.04860314980846295
0.050153537194813184,268.490956468426,0.15923748059353185,108.25555364806938,281.9567276401362,0.04893637937928929
0.05050251322309968,268.690082609867,0.1603454794833415,108.33584130829837,282.2596070597875,0.049268633706624196
0.050840353908729985,268.792913236428,0.16141812366021768,108.37730261692775,282.4584400735265,0.04959018112644363
0.05118030559367618,268.892646744119,0.16249747025992187,108.4175151672288,282.65465457637544,0.049913633406870404
0.051521354868080384,268.971227170367,0.1635803017061552,108.44919879509199,282.82898921471457,0.0502380249111983
0.05185980960265688,269.061303314528,0.1646548954884356,108.48551749641769,283.01477127586213,0.050559844601527834
0.052206048606163284,269.144114511778,0.16575420432456842,108.51890697114891,283.1950652360427,0.05088895883080061
0.05255536659467348,269.220603817218,0.1668632889380883,108.54974745910229,283.3695913456712,0.05122089003135814
0.05290137268364108,269.428517818945,0.16796185827056043,108.63357838459862,283.6816562516861,0.05154956559673801
0.053245339894553385,269.599501494956,0.169053954165207,108.70251900276627,283.95441858745704,0.05187619736642065
0.05358770010598418,269.687777631474,0.17014094783649977,108.7381119410103,284.1397253814387,0.05220119721970199
0.05392950031934928,269.725657137667,0.17122616351393397,108.75338495790733,284.27182705040946,0.052525560139532815
0.05427775307764708,269.831066325931,0.17233186602152947,108.79588594261537,284.47689031664805,0.05285593824719216
0.054620305002776585,270.03596165463,0.17341946838381564,108.87849973914682,284.78540824192396,0.05318080167700998
0.054967700555313984,270.195114501059,0.17452244926312188,108.94267016682697,285.04711864646197,0.053510150871983034
0.05531463579322329,270.289427557383,0.17562396864348392,108.98069719113684,285.24038880147845,0.0538389554447733
0.05566711339535799,270.373796715255,0.1767430850302616,109.01471483559082,285.42472551613656,0.05417290206041394
0.056022752575078286,270.431857404853,0.17787223942587355,109.03812490563675,285.58219444066395,0.054509731051085177
0.05637781847135728,270.526482665839,0.17899957364655936,109.07627781086629,285.77817559726844,0.05484590393845283
0.056730870513243485,270.582305067767,0.18012051387954806,109.09878540332366,285.9326747797414,0.05518005811330595
0.05708587720677518,270.664087375735,0.1812476601315112,109.13176002989636,286.1151842319501,0.05551594976261992
0.057437940284644384,270.812759437783,0.1823654604037459,109.1917046053141,286.3676865426901,0.0558489449062168
0.057787112780516785,270.990928051945,0.18347408307814078,109.26354219054421,286.65071137377964,0.0561790965357449
0.05813956245052658,271.124204916281,0.18459311078042187,109.31727942224448,286.88724755986044,0.05651223631548793
0.05849239298704138,271.237559110124,0.1857133477338564,109.362983833202,287.10289301043923,0.05684562496992681
0.05884384640448408,271.258807387467,0.18682921233423697,109.37155113862671,287.22071898523865,0.057177601926757686
0.05920466469756038,271.297430968807,0.1879748104147542,109.387124166623,287.3595044026248,0.0575183101727449
0.05956523610643638,271.382992001444,0.1891196246379355,109.42162237498222,287.54798399528113,0.05785866937099473
0.05993653234181618,271.577305382358,0.19029849018526637,109.49996953016677,287.854707329711,0.05820903118215745
0.06030691009814088,271.75820130379,0.1914744395615973,109.57290676568812,288.1470987182501,0.058558404044422564
0.060669944288843584,271.850308783207,0.19262707311707836,109.61004450138908,288.34345187198915,0.05890073139561191
0.061028426149565884,271.885240231838,0.19376525302487166,109.62412886147708,288.47796853648373,0.05923865111985571
0.061379458805036986,271.896777769641,0.19487978170599243,109.62878079671925,288.58565483997495,0.05956943829904048
0.06173197011701368,272.005651125641,0.19599900512151844,109.67267853385846,288.7970958525879,0.059901508778633684
0.062088138215377286,272.121066823789,0.19712983883382287,109.71921414335173,289.01655723206034,0.060236912045892786
0.062444771339559085,272.189866984338,0.19826214900310007,109.74695436808508,289.18670098911997,0.060572640549723084
0.06280375043649808,272.265328821331,0.1994019076358814,109.77738058076068,289.36461258513697,0.06091046372350698
0.06316590184660398,272.36086535809,0.2005517383629676,109.81590091238189,289.56478504615524,0.06125115665223249
0.06352620220216708,272.434952743108,0.20169569199188048,109.84577294602116,289.74171063800446,0.06158999306237785
0.06388827267399089,272.565232988922,0.20284526573992107,109.89830194113334,289.97895491556807,0.061930378520496765
0.06424384207742578,272.608750302559,0.20397419859582686,109.91584812199179,290.122183805921,0.062264539547698936
0.06459777140862748,272.656087197745,0.20509792422239223,109.9349343581308,290.2690627917157,0.06259704839403153
0.06495462521427708,272.68393373496,0.20623093505532972,109.9461620819359,290.3960164526691,0.06293219282114743
0.06531825614789438,272.715526601822,0.20738546326956464,109.95890032585463,290.5288292239077,0.06327358658373122
0.06568982662207198,272.884563055967,0.20856519952507854,110.02705582416591,290.8103026909534,0.0636223140061633
0.06606709490988959,272.971713528599,0.20976302633889943,110.06219489473114,291.00616163400815,0.06397626457899426
0.06643718791967718,273.130290495091,0.21093807164497502,110.12613312762069,291.2762989312694,0.06432336166712971
0.06681111749046079,273.269392101308,0.21212529803221297,110.18221889524737,291.5268255635353,0.0646739346160593
0.06717692066916128,273.326509577934,0.21328672312458707,110.20524866182299,291.6877428286296,0.06501676988574412
0.06754487826865478,273.357364463448,0.21445498850297892,110.21768935166223,291.8212543699719,0.06536150576966179
0.06791948714910248,273.419197152431,0.21564437169840037,110.24262029186019,291.9896887997435,0.0657123511317824
0.06829552457834809,273.496594449939,0.21683829053625517,110.2738268822154,292.1751878382893,0.06606441066798573
0.06867374290254008,273.545015204907,0.21803913371556474,110.29335013061849,292.3303752513602,0.06641838705304352
0.06904852285749868,273.636030520555,0.21922906007255832,110.33004750588778,292.5301942285887,0.06676902189911416
0.06942366354580298,273.719121527444,0.22042013175792446,110.36354979986541,292.721705726418,0.06711987115919593
0.06979902608415868,273.908062970589,0.2216119078172038,110.43973098974149,293.02657900253456,0.06747080474271455
0.07017833549563549,274.038979718606,0.22281621519864264,110.49251662254196,293.27057917618004,0.06782530327364206
0.07055366668361818,274.122574442837,0.2240078917204877,110.52622201535188,293.46292719053224,0.06817596014376538
0.07092850329791388,274.155191005041,0.22519799797087656,110.53937301323253,293.60060837438226,0.06852603227920323
0.07129991853255868,274.166898443054,0.2263772413408738,110.54409345223937,293.714975966368,0.0688727882409685
0.07166860978515778,274.186549307942,0.22754783606787593,110.55201668096223,293.83711811863185,0.06921688219415995
0.07204027990164578,274.214594225203,0.22872788868772537,110.56332439160184,293.9690903463028,0.06956363647782238
0.07241345360065228,274.225121218274,0.229912715182071,110.5675688752081,294.08270930974675,0.06991167262049434
0.07279360824733719,274.293652856923,0.23111970618529556,110.59520083191137,294.260477567721,0.0702660949580164
0.07317591694255249,274.4477702823,0.23233353629260414,110.65734097782335,294.53073752554633,0.07062239889875016
0.07355791139133758,274.579604731419,0.23354636866749678,110.71049662770815,294.7771069661212,0.07097828321731357
0.07393957186374618,274.679570450799,0.23475814066739412,110.75080280576216,294.98926028964877,0.07133372994486767
0.07432090675098839,274.714536315194,0.23596887893438812,110.76490104228623,295.1315697518165,0.07168874731361193
0.07470696883649099,274.716406969877,0.23719462605585886,110.76565529025441,295.2396370242484,0.07204803729215631
0.07509745154106129,274.762080983719,0.23843440864286958,110.7840710526355,295.396013045715,0.072411310067264
0.07549069985217459,274.816941054561,0.2396829720306543,110.80619063319901,295.5630642660036,0.07277702240994688
0.07588132086885599,274.911592774639,0.24092319375861776,110.84435420673447,295.7722475565397,0.07314015906619395
0.07627076871076208,274.958751970812,0.2421596906566696,110.86336879463138,295.9300673473776,0.07350207386584265
0.07666786451337598,275.019227431489,0.24342046982996873,110.88775250037638,296.1043642987798,0.07387096111695986
0.07706323806999368,275.033620056929,0.24467578087222994,110.89355560695378,296.2286013966283,0.07423811332141537
0.07746246998294389,275.110776080981,0.24594334219584682,110.92466491585154,296.4215363151384,0.07460871174688537
0.07785684264343078,275.167752484546,0.2471954753928927,110.94763780176895,296.59144489028176,0.07497466463616524
0.07824725808438579,275.220927430093,0.24843504441792488,110.9690779398135,296.75621036893955,0.0753368136113379
0.07864167200614089,275.284856102296,0.2496873086194973,110.99485398044574,296.93371746415045,0.07570253844829997
0.07903323263820788,275.320451743611,0.25093051362631,111.00920614302395,297.0799170563203,0.07606548528104345
0.07942607226347229,275.359740306989,0.2521777794365245,111.02504729177798,297.2304829390629,0.07642948531450226
0.07981622962832219,275.38745172286,0.25341652906992296,111.03622053465718,297.3678398063303,0.0767908689061022
0.08020366912388228,275.402876347629,0.2546466494683262,111.04243974336401,297.4911975179797,0.07714960587879299
0.08059947732205879,275.459869359168,0.2559033404975366,111.06541932561655,297.66179085271955,0.07751595873537272
0.08100266549571508,275.572596917713,0.2571834629488954,111.11087107722187,297.894711805624,0.07788900442250023
0.08140883541912339,275.649382009285,0.2584730524557167,111.1418308261437,298.08967718266194,0.07826466828482542
0.08181717542855138,275.725346300656,0.2597695319856506,111.17245962842449,298.2844153290348,0.07864219704255138
0.08222301158940819,275.79051334048,0.261058061796371,111.19873497888153,298.46683991512316,0.07901726971268877
0.08262746956708208,275.799829956366,0.2623422158754856,111.20249143840678,298.5884720126921,0.07939092875833675
0.08303775362544508,275.80825924543,0.2636448677607881,111.20589012775737,298.7107575245149,0.0797698276378845
0.08345072374118039,275.845560519415,0.2649560478782477,111.22093000142813,298.86507218555175,0.08015106217944908
0.08386392624277028,275.886213210038,0.26626796582079565,111.23732116628733,299.02311424608183,0.08053236584165556
0.08427886072453768,275.959985864466,0.2675853828004071,111.26706630055268,299.2175790786827,0.08091512152483965
0.08469124664345529,275.932608281513,0.2688947080929705,111.25602765910604,299.30168486645454,0.08129538119046238
0.08510773511926618,275.965202299812,0.2702170590036701,111.26916956728421,299.4519756392791,0.08167927710379494
0.08552676142187299,275.963052940584,0.2715474675144467,111.26830294564348,299.56527913068504,0.0820653635761877
0.08594824652531698,275.976411956414,0.2728856827178814,111.27368930082612,299.6961006464163,0.08245356524297612
0.08637170066044918,276.042278315105,0.2742301495969261,111.30024661665036,299.88451934736565,0.08284342875368442
0.08679332130723129,276.068432543919,0.27556879515045934,111.31079200170814,300.0293287124871,0.08323145326890553
0.08721265820478778,276.106056678823,0.2769001898002012,111.32596205290143,300.18599982822496,0.08361722672740457
0.08763364225148998,276.145624278275,0.27823681414848067,111.3419157090005,300.34527112559175,0.0840043658570726
0.08805380848959159,276.140221982013,0.27957084195445325,111.33973750314763,300.4554202046905,0.08439060354317207
0.08847656867877798,276.190514623053,0.28091310555512006,111.36001549601497,300.6269036585266,0.08477907521252041
0.08890164588062428,276.272977731681,0.2822627256709821,111.39326462141378,300.8341001643685,0.08516952387633459
0.08933060271153748,276.307780926333,0.28362466360913147,111.40729726949746,300.9905215303698,0.08556338163574993
0.08975918584984638,276.35304034072,0.28498541507326225,111.4255458653783,301.1582642488327,0.08595674141934846
0.09019414353865528,276.33228935539,0.2863664057352305,111.41717906809325,301.25584352587526,0.08635579371897083
0.09063319527753959,276.302142976805,0.28776039500618816,111.40502404824778,301.34428905682444,0.086758440675015
0.09107383100036048,276.267124162651,0.28915941342614454,111.39090446238087,301.42782953959585,0.08716237733883363
0.09151616571726479,276.252843656827,0.2905638261523157,111.38514656243264,301.5344446767908,0.08756770744996352
0.09196284752735528,276.216962096285,0.29198204089935303,111.37067911722212,301.61866046601494,0.08797685433309115
0.09241190212253188,276.252769899738,0.2934077892390387,111.38511682357435,301.7818138327909,0.08838800594668161
0.09286432848347859,276.271766423059,0.2948442429350445,111.39277622177738,301.9275584908808,0.08880207384443708
0.09332511697235078,276.294060339741,0.29630724638721373,111.40176512898357,302.0792358397131,0.08922361873539189
0.09378471545312408,276.294031528379,0.297766471563669,111.40175351224241,302.2061886566645,0.08964389802884536
0.09424696981147648,276.296398385768,0.2992341291514378,111.40270782914166,302.33649670345113,0.09006642789287124
0.09470484839308219,276.293794170111,0.30068789364803594,111.40165780938877,302.4601560589408,0.09048478208822247
0.09516189034500389,276.289560888969,0.30213900184538733,111.3999509504323,302.58179778575436,0.09090219740439036
0.09562175144250779,276.291787762603,0.3035990608299622,111.40084882588154,302.71129241764476,0.09132201166216207
0.09607445746568609,276.254025522603,0.3050364024535533,111.38562309071352,302.79498114739886,0.09173512186217653
0.09652825739027648,276.268755580407,0.3064772172141278,111.39156225002012,302.9364971279639,0.09214905907751912
0.09697839255159998,276.263560441789,0.30790639635132994,111.38946757012933,303.0551564540155,0.0925594842455068
0.09742565149231769,276.214379493097,0.30932644348810867,111.36963781161671,303.12474536675825,0.09296712015752137
0.09788278480811619,276.22375185305,0.3107778417657689,111.37341674714975,303.2613019145725,0.09338358402642162
0.09834299527408298,276.171460934831,0.3122390099952134,111.35233304892385,303.3309896123817,0.09380267615882129
0.09881638008497798,276.185034322987,0.31374200676980507,111.35780583902837,303.47663964842997,0.09423358237666664
0.09928881763991058,276.160446200911,0.3152419960067161,111.34789190820732,303.58009038310956,0.09466344129579046
0.09976512994308138,276.175841556492,0.31675428756928337,111.35409931557757,303.7285602765153,0.09509663877249908
0.10024423124750809,276.11843473485,0.31827543421083815,111.33095288509152,303.79771495811025,0.09553218356649143
0.10072566946059108,276.064945058713,0.3198040005373767,111.3093858476731,303.87177146435323,0.0959696618078855
0.10121860833819908,275.956673110308,0.32136908147378207,111.26573059807617,303.8886235241727,0.09641739238019179
0.10171961147636908,275.878114438612,0.3229597664374718,111.23405574164836,303.9403290541409,0.0968722423095281
0.10221598682989608,275.788312578624,0.32453575818492003,111.19784763170121,303.97828710499994,0.09732268683458732
0.10271556449200908,275.657446585966,0.3261219172621288,111.14508246346149,303.9717568184693,0.09777583257542628
0.10321567436775808,275.523173558899,0.32770976611763186,111.09094357894807,303.9614837217256,0.09822925548862266
0.10372180773507708,275.322904877218,0.3293167395588697,111.01019524649429,303.87989428195567,0.09868793035394786
0.10422812416769109,275.17781675924,0.3309242942324192,110.95169571732556,303.8590844126162,0.09914656071886074
0.10473296432502208,274.979508276377,0.3325271617319451,110.8717377370352,303.7789273067989,0.09960364452060855
0.10523594702997809,274.78588041645,0.3341241318201804,110.79366698391264,303.70323277254147,0.10005883890009201
0.10573675839516009,274.547585661622,0.33571420790463324,110.69758653876599,303.57735739469945,0.10051186246977983
0.10624318092593009,274.302488615113,0.337322099439828,110.59876340961357,303.44525754148134,0.10096975318625141
0.10674983052602609,274.01796254786,0.3389307119201328,110.48404249929716,303.269333610931,0.10142763950249933
0.10726386821994409,273.736987713913,0.3405627815983225,110.37075344624971,303.0990758909826,0.10189198866478812
0.10776683701077008,273.403352750055,0.342159707509195,110.23623182882217,302.86716730406823,0.10234613026949167
0.10827337862431008,273.031501005511,0.3437679771321845,110.08630120542205,302.59354409024445,0.10280328950224234
0.10878835266968509,272.547899220648,0.34540301972625015,109.89131296576527,302.19793620044567,0.10326784495179747
0.10930505218120408,272.091228608382,0.34704354067532295,109.70718337489961,301.8321745494691,0.10373374013883968
0.10983511859272309,271.611088165374,0.34872650153189577,109.51359074827879,301.4435242451164,0.10421146248245816
0.11035428880850308,270.98197659048,0.35037486696699727,109.25993296128152,300.8859998970448,0.10467914350418751
0.11088404348149308,270.421366437825,0.3520568380537405,109.03389494773104,300.4067809922415,0.10515613390664277
0.11142577667344308,269.725326604242,0.3537768409381818,108.75325168683037,299.77968060961774,0.10564367457065588
0.11193982756443609,268.949597620028,0.35540895251708454,108.44047776039528,299.0557692011384,0.1061060824618033
0.11247485558917408,268.250238007049,0.3571076664956277,108.15849596444215,298.42164478865345,0.10658713308523927
0.11300615271218509,267.3247244633,0.3587945348611876,107.78532890360258,297.53406309974247,0.10706460032142116
0.11354490836322709,266.489836674001,0.360505084053246,107.44870214695722,296.74840075888187,0.10754853771767059
0.11410143700786408,265.636227166526,0.36227206249996846,107.10452679354329,295.94570240757406,0.10804819391971701
0.11464149810961409,264.599010091101,0.3639867564980247,106.68632086873191,294.9330370062657,0.1085328268523093
0.11519967380417208,263.684352053105,0.36575896432824634,106.31753074781193,294.06070339688716,0.1090334685242339
0.11574468887901508,262.527142140696,0.3674893871908729,105.85094371112864,292.9132645300678,0.10952206438059124
0.11628782800731809,261.458769089178,0.3692138539232349,105.42017569675659,291.86324146002545,0.11000874110677185
0.11683603990454908,260.344052637193,0.3709544266969433,104.97072202331621,290.76162076002413,0.11049972319345433
0.11737761399376809,259.109982960475,0.37267392443021363,104.47314512966352,289.5236945223415,0.11098452382913325
0.11793733769753008,257.982892493948,0.374451047189658,104.01870225355982,288.40870800619234,0.11148532459104538
0.11850257333231108,256.68848010984,0.37624567033008766,103.49679518028748,287.1067255476158,0.1119908026448294
0.11906131928626708,255.394440552658,0.37801968873389796,102.97503843083172,285.80203958323557,0.11249022611819964
0.11962225517103009,254.100607379554,0.3798006601680205,102.45336489543617,284.49669507462477,0.11299135624923048
0.12017100075379408,252.681479431469,0.3815429273932962,101.88117250676831,283.0464656866979,0.11348135289717264
0.12073522489088108,251.248112165969,0.3833343390285474,101.3032388253187,281.58260949173655,0.11398492073285715
0.12130657042324608,249.665565521632,0.3851483610938063,100.66515601832204,279.9516390278414,0.11449458611548011
0.12189855560318408,248.206001591732,0.38702791404010944,100.07665984178634,278.46195467780575,0.1150223891120161
0.12246513257474208,246.673778925725,0.38882679592480607,99.45886766285231,276.88271596457656,0.11552727785761288
0.12304222269850708,244.987200513065,0.39065905706775994,98.77883924686782,275.13097019687734,0.1160412731781937
0.12361048750861708,243.328545836285,0.3924632978398592,98.11006968119011,273.40650601187104,0.11654715004972527
0.12417907412959808,241.506578931105,0.3942685603614739,97.37545262502154,271.4966422989763,0.11705305740227454
0.12476744104365609,239.673889636561,0.39613662531360805,96.6365123014614,269.57738753149437,0.11757629521474533
0.12536212007437308,237.756015719965,0.3980247312361345,95.8632255382899,267.5616139110558,0.11810486837323234
0.1259817674972271,235.80256415929,0.399992111803696,95.07559386902572,265.5093879724556,0.11865533731040499
0.1266263049185551,233.564352141059,0.4020385181164124,94.17314678327499,263.13974301337754,0.11922759614833627
0.12711642236234907,231.899695218093,0.4035946410004583,93.5019571119351,261.37795482113614,0.11966253261698236
0.12744979499906608,230.694549014437,0.4046530991220348,93.016042162621,260.09652199372897,0.11995826368629356