File: example/data/02 processed data/test_ID_081.csv
Strain,Stress_MPa,Displacement(mm),Force(kN),True Stress (MPa),True Strain
-0.00024496173183109955,-0.302812223282182,-8.874735908772148e-06,-0.0610469442136878,-0.3028113768637531,-2.795196318754757e-06
-0.00024010772117729956,-0.260548348227188,6.53674791698548e-06,-0.0525265470026011,-0.2605488846488801,2.058816122304725e-06
-0.00023706348078009957,-0.142323573629056,1.6202211178307316e-05,-0.0286924324436176,-0.1423242999145979,5.103045618207372e-06
-0.00023516730030049958,-0.0557456652921783,2.2222584201056588e-05,-0.0112383261229031,-0.0557460554694195,6.99921462395048e-06
-0.00022851516170069956,0.0395325081401714,4.3343124255282456e-05,0.0079697536410585,0.0395330478133721,1.3651284539040193e-05
-0.00022902215190349958,0.144935731987818,4.173343036154136e-05,0.0292190435687441,0.1449376370792441,1.3144301128835566e-05
-0.00023561508164869957,0.260373084986028,2.080087842030461e-05,0.0524912139331832,0.2603747908092987,6.55143630935966e-06
-0.00023530705116329956,0.38574384078467,2.17788752116503e-05,0.0777659583021894,0.3857464867900155,6.859464729446341e-06
-0.00023492346318709957,0.466844027952845,2.2996767036003287e-05,0.0941157560352935,0.4668474093397279,7.2430500009498035e-06
-0.00023311162381469956,0.470212158395643,2.874935704344422e-05,0.0947947711325616,0.4702164161270533,9.054874608711074e-06
-0.00023542440358269957,0.471865995070824,2.1406281280039457e-05,0.0951281846062781,0.4718691764554593,6.742113108195026e-06
-0.00023233113358769956,0.473252358137412,3.1227413513942906e-05,0.0954076754005022,0.4732570127664148,9.835357463817749e-06
-0.00022609541859269956,0.473956925731111,5.102580862330279e-05,0.0955497162273919,0.4739645427501308,1.6070991687054568e-05
-0.00021920697307959957,0.474842864602113,7.289662312724543e-05,0.0957283215037859,0.4748537667883635,2.2959302772433347e-05
-0.00021717834090399956,0.475831779672297,7.933753028490402e-05,0.095927686781935,0.4758436698512672,2.498788631520965e-05
-0.00021978450845179957,0.475893133664016,7.106294832050154e-05,0.0959400557466656,0.4759037851188706,2.2381780493132013e-05
-0.00022053010265649957,0.476698868456647,6.869568672072128e-05,0.09610249188086,0.4767091825215691,2.16362026981294e-05
-0.00021473687421729956,0.477977421188926,8.708918701515207e-05,0.0963602481116874,0.4779905319495631,2.742928901525181e-05
-0.00022013217669119957,0.479627183813121,6.995910166053989e-05,0.0966928402567252,0.4796377520924632,2.203411997473637e-05
-0.00022415092646389958,0.482519912030197,5.7199571132085946e-05,0.0972760142652877,0.4825286049221752,1.8015450675796388e-05
-0.00022603258585139957,0.485412199398472,5.122530257691346e-05,0.0978590993987319,0.4854200310163583,1.6133823416758547e-05
-0.00022282534150369957,0.488450149291189,6.140830338088859e-05,0.0984715500971037,0.4884595965021981,1.93410108766891e-05
-0.00021326271686299958,0.493192891899781,9.176963661511964e-05,0.0994276870069958,0.4932071470596144,2.8903404848617545e-05
-0.00019547970739099957,0.555121613639341,0.0001482306916884,0.1119125173096911,0.555147530508872,4.668574223168591e-05
-0.00016685013073339957,0.843196466735084,0.0002391295975764,0.1699884076937929,0.8432599732647748,7.531357254721744e-05
-0.00012261459138239957,1.47055367985707,0.0003795774350158,0.2964636218591853,1.4707294874141892,0.0001195448022719
-7.937983402689429e-05,2.51099541630226,0.0005168477896202,0.5062166759265356,2.511404172973335,0.0001627734570741
-2.787244238299427e-05,3.98022080352097,0.0006803837580896,0.8024125139898276,3.981073741344064,0.0002142711393357
2.862467970970571e-05,5.94577456652893,0.0008597621207339,1.1986681526122325,5.947384630072466,0.0002707545618042
0.00010011293973990043,8.30248327011546,0.0010867373463301,1.6737806272552769,8.305325039764881,0.0003422209149012
0.00016451226685130043,11.0387173229167,0.0012912052099088,2.2254054123000064,11.04320653530034,0.0004065961348577
0.00021570812303560043,13.9737512607197,0.0014537520532939,2.817108254161092,13.98014948736143,0.0004577698698382
0.00026550469744520045,17.0574201536044,0.0016118561770444,3.438775902966648,17.066079715191496,0.0005075424154194
0.0003297384020437004,20.1818547303384,0.0018157981891447,4.068661913636221,20.19339683278657,0.0005717414661571
0.0003993781755485004,23.3868577089734,0.0020369044700224,4.714790514129038,23.401861423936296,0.0006413390131302
0.0004634823846513004,26.570114923612,0.0022404353339238,5.356535168600179,26.58886409662028,0.0007054000709301
0.0005078929100525004,29.8961584587044,0.0023814387520726,6.027065545274807,29.91858235485925,0.000749778295462
0.0005628945113827004,33.2684146838149,0.002556068836296,6.706912400257084,33.29519778869877,0.0008047371629754
0.0006189882115333004,36.6876808816003,0.0027341663342741,7.39623646573062,36.71927465229292,0.0008607841699364
0.0006819115824748005,40.0820092964416,0.0029339480370134,8.080533074162627,40.11904820431399,0.0009236514245538
0.0007397638141755004,43.5833370206128,0.0031176288726631,8.786400743355541,43.62613282214429,0.000981448575341
0.0007931192945858004,47.0174509604025,0.0032870325229658,9.478718113617145,47.06612746133283,0.0010347502952179
0.0008489193697424004,50.499781658455,0.003464197761588,10.180755982344529,50.55488125863828,0.0010904911075447
0.0009170410381091005,53.8867075378559,0.0036804840586523,10.86356023963175,53.94917341756184,0.0011585362152066
0.0009794148718974005,57.3238630151355,0.0038785209809302,11.556490783851318,57.39388878061965,0.0012208358878276
0.0010454425629148004,60.7711375077623,0.0040881588999104,12.25146132156488,60.84938697757648,0.0012867808446389
0.0011069916732234005,64.2653741941751,0.0042835773251402,12.9558994375457,64.35207835155772,0.0013482489164656
0.0011703751004906004,67.7200355341056,0.0044848197067136,13.65235916367569,67.81569290415369,0.0014115449414425
0.0012307027489073005,71.2123813592052,0.0046763599904366,14.356416082015768,71.31726788865777,0.0014717856802345
0.0012915587544932005,74.7082747554112,0.0048695778081718,15.0611881906909,74.82285672606814,0.001532550338493
0.0013459275192887004,78.2776156596548,0.0050421986363975,15.780767316986408,78.40192787601372,0.0015868343708304
0.0014068389928485003,81.8555681347757,0.0052355925649499,16.502082535970782,81.99054841947687,0.0016476474154681
0.0014687019309696004,85.4393487678577,0.0054320073934844,17.22457271160011,85.58552425579518,0.0017094066020661
0.0015269931345053005,89.0179020742889,0.0056170819647102,17.946009058176642,89.17538895689609,0.0017675965542824
0.0015817689674342003,92.6132803599992,0.0057909952342595,18.67083732057584,92.78220101045396,0.0018222741563109
0.0016458810457816004,96.2178835740837,0.0059945510830125,19.39752532853528,96.39954751681888,0.0018862674636427
0.0017062640182057005,99.7877690634114,0.006186267020459,20.11721424318374,99.98219860193176,0.0019465348288704
0.0017597482391013004,103.401949565675,0.0063560794218025,20.84583303244008,103.60895145663834,0.0019999136174543
0.0018150258961205003,106.95458672406,0.0065315859828385,21.56204468357049,107.174612890815,0.0020550793127518
0.0018748679569771005,110.50516010199,0.0067215845260582,22.277840276561182,110.73910333795573,0.0021147967365867
0.0019379039122076004,114.107388341972,0.006921723683915,23.00404948974156,114.35615048760864,0.002177697546148
0.0020036981839526005,117.684625714733,0.0071306204967054,23.72522054409017,117.94892946410894,0.0022433465388237
0.0020613808354215005,121.32386115931,0.0073137629151192,24.458890409716897,121.60333642118908,0.0023008982770215
0.0021187332830889002,124.931497185119,0.0074958569364632,25.18618983251999,125.22644793464904,0.0023581172772021
0.0021874404630898006,128.524097910561,0.007714002232966,25.9104581387691,128.83636095883566,0.0024266602793699
0.0022498621016530003,132.16417513312,0.0079121909354042,26.644297706837,132.49353204287542,0.0024889286867467
0.0023147202242189005,135.825151203526,0.0081181154745509,27.38235048263084,136.17244073480742,0.0025536234900408
0.0023761061943040006,139.476142155005,0.0083130159295711,28.118390258449008,139.84132873501434,0.0026148510290051
0.0024345494990025006,143.13026240329,0.0084985734219888,28.855060900503265,143.5133814722484,0.0026731400139599
0.0024954865666026002,146.781295873876,0.0086920486116192,29.5911092481734,147.183132144431,0.002733912559082
0.0025603841749081003,150.474640917838,0.0088980985179891,30.335687609036142,150.89635373023043,0.0027986308910352
0.0026259056675167003,154.162385494643,0.0091061292570214,31.079136915720028,154.6045343478351,0.0028639671350656
0.0026908613716060004,157.841326685738,0.009312363617505,31.82081145984478,158.3042797024205,0.0029287349768104
0.0027528025663457003,161.546990246125,0.0095090269108035,32.567873233618805,162.03081849104146,0.002990493120524
0.0028132248657069003,165.204067920989,0.0097008677112753,33.30514009287138,165.70883101020664,0.0030507331828563
0.0028696230333515003,168.902415793149,0.0098799318935469,34.05072702389884,169.42800456942993,0.0031069579762777
0.0029309549046244005,172.560822247105,0.0100746605848384,34.78826176501637,173.10837869257907,0.0031680977186493
0.0029956773688267005,176.241668619498,0.0102801544086807,35.53032039369079,176.81231163261674,0.0032326133790424
0.0030596377716267005,179.900184069519,0.0104832286875707,36.26787710841504,180.49417927283773,0.0032963653242168
0.0031170690548157002,183.53982027606,0.0106655730116958,37.001627767653694,184.1563737732908,0.0033536059663207
0.0031723599471946006,187.194371294429,0.0108411215949988,37.73838525295689,187.83355143335888,0.0034087102271375
0.0032335321505489005,190.826454499273,0.0110353433406487,38.47061322705344,191.48970975718737,0.0034696724089306
0.0033014694700433003,194.406346237865,0.0112510443300434,39.19231940155358,195.09525156686152,0.0035373721249681
0.0033646154604678002,197.947736887292,0.0114515328496412,39.90626375647807,198.66169122161543,0.0036002931595641
0.0034259865242304006,201.459633687831,0.0116463859770874,40.614262151466725,202.1986184603448,0.0036614417971618
0.0034849412743878003,204.836508549012,0.0118335673088372,41.29504012348082,205.599956300578,0.0037201793575451
0.0035460368096133003,208.130359510875,0.0120275456331781,41.9590804773924,208.91879963580945,0.0037810461762483
0.0036080676457416003,211.28186215837,0.0122244935378855,42.594423411127394,212.09534680675657,0.0038428410044288
0.0036627365112340006,214.345712769425,0.0123980671858239,43.21209569431608,215.1827119971128,0.0038972987064585
0.0037241096731283002,217.221272555603,0.0125929269748383,43.79180854720957,218.0828321217996,0.0039584312756662
0.0037878676668037002,219.980966514152,0.0127953586047577,44.34816284925304,220.867497333922,0.0040219353701371
0.0038465575048234005,222.573124079681,0.0129816988404702,44.87074181446369,223.4831641637078,0.004080387927084
0.0039004373746180003,225.06319907695,0.0131527674270681,45.37274093391312,225.9955467663519,0.0041340469543656
0.0039625335566306,227.412785396908,0.0133499228049581,45.84641753601665,228.3689879575093,0.0041958850457242
0.0040255711272756,229.591274071227,0.0135500670917559,46.285600852759366,230.57110939952523,0.0042586567019147
0.0040951690937814,231.601354429607,0.0137710406354119,46.69083305300877,232.6058872368721,0.0043279565035121
0.004155041625041701,233.504539366957,0.0139611359221633,47.07451513637853,234.53130743390008,0.0043875686921539
0.0042157013994298005,235.242338250125,0.0141537307058455,47.4248553912252,236.29101752767008,0.0044479610769785
0.004283561173127601,236.838345474145,0.014369185487336,47.74661044758764,237.91021133765108,0.0045155174013512
0.004360278042687701,238.355481548945,0.0146127615481894,48.05246508026731,239.4524994436154,0.0045918857193663
0.004441389728313601,239.774337558812,0.0148702911500516,48.3385064518565,240.89733416032703,0.0046726225439254
0.004525032536312701,241.07260278441,0.0151358570654487,48.60023672133706,242.2218438735881,0.0047558719670078
0.0046185796627828,242.301909163653,0.0154328691919913,48.84806488739245,243.4796772484065,0.0048489709177439
0.0047187628722386,243.401139607847,0.0157509508820135,49.06966974494196,244.60863548015857,0.0049486645480339
0.0048257533430214,244.411962780798,0.0160906456267489,49.27345169660888,245.6506230264812,0.0050551212000581
0.0049457477561587,245.329661585137,0.0164716278884598,49.45845977556362,246.60241084360385,0.005174503431155
0.0050733991953809,246.102768869192,0.0168769212079903,49.614318204029104,247.4109443146325,0.0053014879807085
0.0052058056667373,246.784812707174,0.0172973117545468,49.75181824176628,248.1292895077042,0.0054331856856344
0.0053494382965828,247.375154111547,0.0177533453543063,49.870831068887874,248.75837821958388,0.0055760298461666
0.005495281252090501,247.843757810291,0.0182163967380432,49.96530157455467,249.2657484311792,0.0057210513239529
0.0056499272441286,248.241715503915,0.0187073977627642,50.04552984558927,249.70437897265288,0.0058748032838905
0.0058152739831679005,248.571216584381,0.019232373659214,50.11195726341121,250.076921944468,0.0060391679824996
0.0059846312544424,248.771152688759,0.0197700829955105,50.15226438205382,250.3202003534978,0.0062074913917374
0.0061609378761724,248.960312715455,0.0203298565195033,50.190399043435725,250.5544315931104,0.0063826916329615
0.006343052604226901,249.10658792852,0.0209080707810763,50.219888126389634,250.7470094001553,0.006563631309978
0.0065230839158242,249.259492048186,0.0214796701953977,50.250713596914295,250.9457949402387,0.0067424688395541
0.0067043174144354005,249.421553251116,0.0220550865534883,50.283385135424986,251.1541560685204,0.0069224682863506
0.006880806928690201,249.576864466042,0.0226154407612473,50.31469587635407,251.35459384988752,0.0070977249181971
0.0070645009942159,249.728811472558,0.0231986694192914,50.3453283928677,251.5534968715578,0.0072801031579689
0.007245227350368401,249.864301851772,0.0237724756000756,50.37264325331724,251.73513429873304,0.0074595024922211
0.0074259264791986,249.947134726744,0.0243461953341115,50.38934236091159,251.86375260556565,0.0076388426279955
0.0076059351986528,249.988830388739,0.0249177230183786,50.39774820636978,251.95076816301145,0.0078174655737215
0.007792259441561601,250.035148472024,0.025509302489614,50.40708593196004,252.044037365066,0.0080023218248942
0.0079806240240415,250.102824676394,0.0261073600389877,50.42072945476103,252.1593678230379,0.0081891676117136
0.0081778447058744,250.158421973262,0.0267335357038071,50.431937869809616,252.2647586993818,0.0083847606857919
0.008369065305457,250.169947098662,0.0273406611074819,50.43426133509026,252.32421851374897,0.0085743666731165
0.0085586977070303,250.285915765675,0.0279427439824771,50.45764061836008,252.488648133127,0.0087623623756298
0.0087502011372979,250.435497739989,0.0285507673735767,50.48779634438178,252.68750581496863,0.0089521770977857
0.0089368668981525,250.633744435754,0.0291434311642901,50.52776287824801,252.9343199565136,0.0091371621404671
0.0091252169592719,250.744793062933,0.0297414426083442,50.5501502814873,253.09361569985347,0.0093237816406042
0.0093100894434979,250.811450040077,0.0303284127457617,50.563588328079526,253.20726521430643,0.0095069216538344
0.0094951139015326,250.843090168953,0.0309158654000219,50.56996697806093,253.2856196846031,0.0096901786412205
0.0096749984307817,250.942937831415,0.0314869987803878,50.59009626681326,253.43158034399605,0.0098683126087747