File: example/data/02 processed data/test_ID_081.csv
Strain,Stress_MPa,Displacement(mm),Force(kN),True Stress (MPa),True Strain
0.0013488721399518432,73.3049745800319,0.004282669044347102,29.55656575066886,73.40385361796278,0.0013479632291714494
0.001465846760664143,80.019166260729,0.004654063465108654,32.26372783632593,80.13646209638333,0.00146477345603992
0.001592781961088243,86.7953132410102,0.005057082726455171,34.995870298775316,86.93355925024748,0.0015915148292317588
0.001711725133684843,93.6024056813352,0.005434727299449376,37.74048997071435,93.76262727171331,0.0017102618018615093
0.001836371537850943,100.365421503785,0.005830479632676744,40.46733795032611,100.54972970721896,0.00183468746904052
0.001956547489605643,107.071649187354,0.006212038279497916,43.17128895234113,107.28113995377946,0.001954635943513877
0.002078634177571543,113.670544791048,0.006599663513789649,45.831963659750556,113.90682427043386,0.0020764768066222185
0.002195668112978443,120.253668225014,0.0069712462587065566,48.48627902832565,120.51770536980435,0.0021932611563553026
0.002309770065416943,126.72514323162,0.0073335199576987945,51.095577750989186,127.01784917399206,0.0023071066470069694
0.002428204506726243,133.161434480146,0.0077095493088558216,53.69069038239487,133.48477767547283,0.0024252611818633206
0.002544414215069843,139.567033219205,0.00807851513284675,56.27342779398346,139.92214956248307,0.0025411826736468877
0.002662298808273443,145.81573699442,0.008452798716268181,58.79290515615015,146.20394205724776,0.0026587611682466475
0.002773488998972143,151.974638230921,0.008805827571736554,61.27617413470735,152.3961382181772,0.002769649975047318
0.002880369938554543,157.979002771829,0.009145174554910674,63.69713391760145,158.43404074233578,0.0028762296215872497
0.002994458917386843,163.897106792229,0.009507407062703225,66.08331345862673,164.38788994519692,0.0029899844554525015
0.003099955163688943,169.801737534825,0.009842357644712394,68.46406057404144,170.32811530789945,0.003095160209553433
0.003212850406379543,175.66680811768,0.010200800040255049,70.82885703304858,176.23119929352828,0.003207700230726864
0.003311063766003943,181.460128566494,0.010512627457062518,73.16472383801039,182.06095462316492,0.0033055942642931536
0.003425229770956943,187.195051501983,0.010875104522788294,75.47704476559954,187.8362375653634,0.0034193770323069947
0.003536381917301143,192.874479682518,0.011228012587431129,77.76699020799126,193.55655750477612,0.003530143621772856
0.003652802999034743,198.512982112349,0.011597649521935309,80.04043438769912,199.23811092875633,0.003646147716194197
0.003768689970688143,204.040861974422,0.011965590656934854,82.26927554808695,204.80982872455556,0.0037616062506254694
0.003884350408629043,209.439896998382,0.012332812547397211,84.44616646974762,210.2534349478709,0.0038768257987670846
0.003992369301518544,214.719445839125,0.012675772532321375,86.57488056233521,215.57668516313217,0.003984420943362689
0.004101753943862343,219.877439363189,0.013023068771762939,88.6545835512378,220.77932251726332,0.004093364683783877
0.004223337459870843,224.921250080068,0.013409096435089926,90.68824803228343,225.87116842105212,0.004214444200917225
0.004351495113025243,229.808165445762,0.013815996983855145,92.65865230773124,230.80817455463253,0.004342054734764438
0.004494701890276443,234.468670306694,0.014270678501627707,94.53776786765903,235.5225370823321,0.004484630883906492
0.004653432736891044,238.914749529959,0.014774648939629063,96.33042701047947,240.02652324674784,0.0046426389911328565
0.004851719224568443,242.940874905092,0.015404208538004805,97.95376076173308,244.1195558183025,0.004839987565360201
0.005108769941658443,246.364693517025,0.016220344564765555,99.33424442606447,247.6233140579507,0.005095764452395486
0.005415658457670542,248.948122788845,0.017194715603103972,100.37588310846232,250.29634079554762,0.005401046511206153
0.005762144528189343,250.742853162093,0.018294808877001165,101.09951839495591,252.18766972142353,0.00574560687124218
0.006127567087077443,251.899704816508,0.01945502550147088,101.56596098201602,253.44323715698619,0.006108869887894639
0.006505275673924943,252.662454952904,0.020654250264711693,101.8735018370109,254.3060938748233,0.0064842076874742065
0.006896055189094544,253.214545724818,0.021894975225375174,102.09610483624661,254.9607272068179,0.00687238615352211
0.007287470269076543,253.643293983274,0.023137718104318025,102.26897613405606,255.49171194712775,0.0072610449623762416
0.007681806619107343,253.979448418495,0.02438973601566581,102.40451360233718,255.93046942647342,0.007652451778934807
0.008065449181437943,254.26225767028,0.02560780115106547,102.51854229265689,256.31299698827735,0.008033097284822432
0.008450005466887744,254.513626067524,0.026828767357368586,102.61989403042568,256.664267599192,0.008414504022097875
0.008830256553953744,254.762765068484,0.028036064558803135,102.72034687561275,257.0123856444333,0.008791497837710516
0.009217940560746244,254.984985063548,0.029266961280369323,102.80994597762256,257.33542149974653,0.009175714638990078
0.009601147501006643,255.219546054553,0.030483643315696092,102.90452096919577,257.66994656136274,0.0095553493939109
0.009982509323300243,255.410359991315,0.03169446710147827,102.98145714849821,257.95999629119575,0.009933013201535387
0.010355462655301044,255.620088911485,0.03287859393058081,103.06601984911075,258.2671531961526,0.01030221215874952
0.010728147210836543,255.810597493501,0.034061867394406024,103.14283290937962,258.5549712415033,0.010671008934835587
0.011098037859167144,256.032881512999,0.03523627020285568,103.2324578260412,258.8743441252219,0.011036906513162456
0.011469491458397643,256.242888738519,0.036415635380412516,103.31713273937086,259.1818643621806,0.011404215488534075
0.011840081451525344,256.41788231373,0.037592258608592964,103.38769014889593,259.4538909259522,0.011770536097336248
0.012209548888306743,256.605362961297,0.03876531772037391,103.46328234599494,259.73839868537465,0.012135613549338167
0.012578937171478944,256.810621855977,0.039938125519445644,103.54604273232992,260.04102653327175,0.012500479598126224
0.012950156620485544,257.006598531285,0.0411167472700416,103.62506052781413,260.3348742347634,0.012867020324991681
0.013326973596569444,257.202225840093,0.04231314116910798,103.70393745872549,260.6299531128428,0.01323895067430921
0.013697297596815544,257.393843947619,0.04348891986988935,103.78119787968,260.91944402775783,0.013604337522043413
0.014070307971434843,257.587222638288,0.044673227809305625,103.85916816775772,261.21155419031527,0.013972240015211143
0.014443675914636144,257.774742697922,0.045858671028969754,103.93477625580215,261.4979575404296,0.014340359683484242
0.014815823048055744,257.969747160519,0.047040238177576986,104.01340205512126,261.7917812862009,0.014707140903709405
0.015185394056461543,258.170514225571,0.0482136261292654,104.09435133575023,262.09093521784564,0.015071250057314616
0.015546338490451143,258.384772386167,0.04935962470718238,104.18074022610254,262.4017095184605,0.01542673220397697
0.015914133703950343,258.584148198837,0.050527374510042335,104.26112855377109,262.6992909069954,0.01578883151385981
0.016273538845474042,258.776897006579,0.05166848583438008,104.33884487305266,262.9881128923268,0.016142544067208737
0.016632104899170042,258.959182265883,0.052806933054864884,104.41234228960403,263.26621854993243,0.01649530619221703
0.016990357954551942,259.136028482559,0.053944386505702414,104.4836466841678,263.53884236539864,0.016847636150832002
0.017342398811929543,259.348657514262,0.055062116227876295,104.56937870975045,263.84638536421284,0.017193735735298477
0.017697026202769642,259.546184106989,0.05618805819379361,104.64902143193798,264.13937972795924,0.017542257135002765
0.018041722897126942,259.716942967077,0.05728247019837804,104.71787140432545,264.40268408377796,0.017880902452634035
0.018380304622949144,259.886610296927,0.058357467177863526,104.78628127172098,264.6634053616102,0.018213428544344306
0.018717669996327044,260.067258228595,0.05942860223833836,104.85911851776952,264.93511134496737,0.01854465009643991
0.019054499096020344,260.244349939511,0.06049803462986459,104.93052189561084,265.2031756701778,0.0188752357309577
0.019399670080206044,260.480267144571,0.06159395250465419,105.02564371269102,265.53349838957956,0.019213895282596267
0.019748012968005744,260.657542746183,0.06269994117341823,105.097121235261,265.8050112805431,0.019555550665464334
0.020093271458562843,260.866841070974,0.06379613688093702,105.18151031981672,266.1085093231508,0.019894065721993627
0.020446232334416843,261.026860837087,0.06491678766177347,105.24603028951347,266.36387667928557,0.02024001430933342
0.020790176673074444,261.211299073293,0.06600881093701136,105.32039578635172,266.64192813003007,0.020577010396993816
0.021140961760393644,261.394599604845,0.06712255358924982,105.3943025606735,266.92073283946445,0.02092059210175115
0.021488764225205043,261.578261704176,0.068226826415026,105.46835511912376,267.199255296376,0.021261135924988392
0.021834468415500942,261.765572857265,0.06932443721921548,105.54387897604926,267.4810849900825,0.021599510380945257
0.022181880078812444,261.9368273378,0.07042746925022951,105.61292878260097,267.7470786300317,0.021939440799713984
0.022522942488587244,262.120798762133,0.0715103424012645,105.68710606089203,268.0245304377151,0.02227304632474984
0.022874599284332442,262.303119253435,0.0726268527277555,105.760617682985,268.30319799738777,0.022616898111043785
0.023221995873928744,262.510343845077,0.07372983689972376,105.84417063833504,268.606357966711,0.02295646819171012
0.023568848875262942,262.681327395903,0.07483109517895983,105.9131112060281,268.87242390365054,0.02329539193230065
0.023917875558604945,262.871638514108,0.0759392548985707,105.98984464888834,269.158969651975,0.023636323751352283
0.024258566840498545,263.029154548845,0.07702094971858288,106.0533551140943,269.409864875468,0.0239690014230443
0.024595721526598145,263.207080627076,0.0780914158469491,106.12509490883704,269.6808486860084,0.024298116764293404
0.024925249735363645,263.363573206961,0.07913766790977957,106.18819271704668,269.92797604034223,0.024619682843612007
0.025259579260694845,263.555200707535,0.08019916415270613,106.2654569252781,270.2124941893753,0.024945828587709235
0.025593768932177345,263.746862229663,0.08126021635966306,106.34273485100013,270.49713847815576,0.025271731631663852
0.025927582733277645,263.89983001193,0.08232007517815652,106.4044114608102,270.7421146878622,0.025597162126233627
0.026266664329181844,264.083220390727,0.08339665924515235,106.47835446154112,271.0198056956995,0.025927619732257223
0.026598660583706444,264.267294283203,0.08445074735326795,106.55257305498745,271.2964503472164,0.026251066432233235
0.026937695187067942,264.484063986576,0.0855271822189407,106.63997459938746,271.60865508408335,0.02658126229702913
0.027268144379809244,264.674573181884,0.08657635840589435,106.71678790693562,271.891757657072,0.02690299168677856
0.027599532719836742,264.829859804198,0.08762851638548165,106.77939947305264,272.1390401850538,0.027225531523862572
0.027930571629841743,264.992952162084,0.08867956492474753,106.84515831175227,272.3943567938503,0.02754762742716882
0.028265452018339444,265.159342431913,0.08974281015822773,106.91224686854731,272.6541911026367,0.027873355507183704
0.028599324006382043,265.343881328665,0.09080285372026298,106.98665295171773,272.9325369638945,0.028197997160700802
0.028933612516685542,265.524419206739,0.0918642197404766,107.05944582415718,273.2069998657848,0.028522938265954506
0.029267609339836742,265.690136162899,0.09292465965398165,107.12626290088089,273.46625127356276,0.028847490425904905
0.029600098073247344,265.854571549068,0.09398031138256031,107.19256324858421,273.7238929401416,0.029170472553512083
0.029938837449241744,266.020297107452,0.09505580890134253,107.25938379372465,273.984635540751,0.029499419361175044
0.030273144738821645,266.185249304913,0.09611723454575871,107.32589251974092,274.2435138844599,0.029823956151956158
0.030608605082743445,266.342330741734,0.09718232113771043,107.38922775506714,274.49469796022515,0.030149506462558547
0.030944344517476643,266.507140494111,0.09824829384298833,107.45567904722557,274.75402926592835,0.030475221538435234
0.03127690663422974,266.654296045706,0.09930417856367942,107.51501216562868,274.99441756674383,0.030797749608059474
0.03160846944068324,266.811038332178,0.10035689047416928,107.57821065553416,275.2445268837376,0.031119204995890593
0.031937205956434844,266.941363430676,0.10140062891168063,107.63075773524858,275.46672473285304,0.031437818266681704
0.03226311333971244,267.123619881406,0.102435384853587,107.7042435361829,275.74185950535406,0.031753589350465586
0.032598013044991644,267.28869475336,0.10349869141784847,107.77080172455476,276.0017751117088,0.03207796923629565
0.03293232833283014,267.477750705399,0.1045601424567357,107.84702908441689,276.2864158133561,0.03240167814926653
0.033266430275549846,267.635800174863,0.10562091612487076,107.91075463050477,276.53908786062107,0.03272507583232055
0.03359748817228794,267.78585083482,0.10667202494701421,107.97125505659942,276.78278279094894,0.03304542386937753
0.033928173429772446,267.927952071399,0.10772195063952751,108.02855027518807,277.0182580959612,0.03336530890533695
0.03426488067259934,268.077171156133,0.1087909961355029,108.08871541015282,277.26280343684584,0.033690914143333237
0.034599780922901446,268.241775810831,0.10985430443021209,108.15508400692704,277.5228824882558,0.03401466683672508
0.034936070034452045,268.375153310891,0.11092202235938524,108.20886181495125,277.7511264624671,0.034339656726950836
0.03527123029076314,268.524888028751,0.11198615617317298,108.2692348531924,277.99609119321445,0.03466345063801152
0.03560654724040934,268.681935056676,0.11305078748829965,108.33255621485178,278.24877106991613,0.034987291046378134
0.03595326060251174,268.83764205822,0.11415160241297477,108.39533727787432,278.50323186290393,0.035322027571027044
0.036304015845567646,268.983323918107,0.11526525030967727,108.45407620378073,278.7484987718234,0.035660552377181264
0.036651148229302745,269.171654329842,0.1163673956280362,108.5300110257923,279.0371045318117,0.03599546785726101
0.036998904175008444,269.2688069929,0.1174715207556518,108.56918297953729,279.2314577801492,0.03633087252070707
0.037332503215253644,269.399683747346,0.11853069770843032,108.6219524869299,279.4570483070321,0.03665251740535051
0.03766896964944634,269.498645411319,0.11959897863699212,108.66185382984382,279.65038170588485,0.03697682217480896
0.038000179278437345,269.672549296166,0.12065056920903856,108.73197187621412,279.9201545158935,0.03729595745893944
0.03833797628243654,269.821311171885,0.12172307469673602,108.79195266450402,280.16571420008864,0.03762133510137674
0.038667233640447746,269.960416671833,0.12276846680842159,108.84804000208307,280.3990391769554,0.03793838520716966
0.03898571646266774,270.084410517289,0.12377964976897007,108.89803432057091,280.61384476670275,0.03824496463343886
0.039315518390679344,270.22095842916,0.1248267708904069,108.95309043863732,280.84483548982865,0.03856234108036495
0.039648995249166645,270.378517281346,0.1258855599161041,109.0166181678387,281.0987538285108,0.03888315161768723
0.03999160540391404,270.536011899289,0.12697334715742709,109.08011999779333,281.35518133471396,0.03921264139369896
0.04033358318013834,270.702630265238,0.12805912659693922,109.14730052294395,281.6210373201232,0.0395414147808419
0.04066329598974645,270.853576928334,0.12910596476744496,109.20816221750427,281.8673760968524,0.03985829446064085
0.041000002334811644,270.950169543031,0.13017500741302696,109.24710835975009,282.05912712691287,0.04018179187568639
0.041333532085772645,271.071359515346,0.13123396437232815,109.29597215658751,282.27569625140757,0.04050213417272963
0.04166916598745574,271.191689297534,0.132299602010172,109.34448912476572,282.4920208132915,0.04082439386533421
0.042006444228067846,271.33272626308,0.1333704604241154,109.40135522927388,282.7304492960997,0.041148127791962946
0.042338631654405046,271.468811978904,0.134425155502736,109.4562249898941,282.96243001493775,0.04146687292969783
0.04267577032219344,271.597174172532,0.13549557077296417,109.5079806263649,283.18779279767574,0.04179026510426221
0.04301108319342854,271.705028292817,0.13656018913913562,109.55146740766382,283.39135586879223,0.0421118022262504
0.04335417003457874,271.811085403657,0.1376494898597875,109.5942296347545,283.59522941753056,0.04244068696367778
0.04370121578092994,271.971187205614,0.13875136010445255,109.65878268130356,283.85665874388224,0.04277325671904565
0.04404369895496264,272.082062304329,0.1398387441820064,109.70348752110546,284.06556274750625,0.043101345821011536
0.044384828599699645,272.20207352986,0.14092183080404636,109.75187604723955,284.2837159079657,0.043428031310383204
0.04472067646287664,272.298133694324,0.14198814776963334,109.79060750555143,284.475490432713,0.043749554436196
0.04505419987236464,272.384038650859,0.14304708459475773,109.82524438402636,284.6560835702767,0.04406874997835368
0.04538390369039844,272.51683626741,0.14409389421701504,109.87878838301971,284.8847141185822,0.04438418990475554
0.04571250192529444,272.599975762236,0.14513719361280983,109.91231022733356,285.06120267910245,0.044698473107307304
0.04603610652624944,272.718545735965,0.14616463822084197,109.96011764074109,285.2734457591497,0.045007883714518054
0.04636983910265424,272.833718977082,0.14722423915092722,110.00655549155947,285.48497462782814,0.045326877817868
0.04670328012008864,272.959677099246,0.1482829143812814,110.05734180641599,285.70778936030104,0.045645491646685264
0.04703774005489354,273.08484288072,0.149344824674287,110.1078086495063,285.93013673307473,0.04596497713646365
0.04737742980030334,273.216229667969,0.1504233396159631,110.1607838021251,286.1605124093668,0.04628935384388768
0.04771701140561294,273.332410160124,0.15150151121282107,110.207627776562,286.3750158932583,0.046613522150198344
0.04805675813044304,273.420748626127,0.15258020706415665,110.24324584605442,286.5604634106975,0.04693774295374569
0.04839181934340024,273.510175184708,0.15364402641529576,110.27930263447426,286.7458301708281,0.047257389444873996
0.04872197052858555,273.581570174396,0.1546922564282591,110.30808909431647,286.91100337359705,0.047572251890113944
0.049064964015025046,273.716723493058,0.15578126074770451,110.362582912401,287.14662468155547,0.04789925696755826
0.049409298716821246,273.816954138401,0.15687452342590744,110.40299590860329,287.3460578191554,0.048227433215417795
0.04975216681703054,273.923138491144,0.15796312964407197,110.44580943962927,287.5514081724,0.04855410470676133
0.05010173490081554,273.99119234796,0.15907300831008933,110.47324875469747,287.71862643213586,0.048887049857591174
0.05044923160872664,274.075186432589,0.16017631035770707,110.50711516961991,287.9020689911316,0.04921791229951382
0.05079409038051824,274.189640734358,0.1612712369581454,110.55326314409317,288.1168541272208,0.04954615488929771
0.05113622360147074,274.27771787351,0.1623575099346696,110.58877584659923,288.3032445835909,0.04987169681777957
0.05147709453663174,274.361307992534,0.16343977515380576,110.62247938258972,288.4846309812596,0.050195932315773094
0.05181851280487304,274.418448515955,0.1645237781554719,110.64551844163304,288.6384044042724,0.05052058308768414
0.052157386217811644,274.527775504847,0.16559970124155196,110.68959908355431,288.84642671937,0.05084270979647988
0.05250377059701914,274.59822967268,0.16669947164553575,110.71800620402459,289.015672129762,0.05117186908296471
0.05284689974475854,274.71895221983,0.16778890668960836,110.76668153503546,289.23699714577646,0.051497828226599436
0.05319090813895144,274.786267350568,0.16888113334117083,110.79382299574901,289.4023984550574,0.05182451599636744
0.053536187086231445,274.880251764477,0.16997739399878484,110.83171751143713,289.59629234925046,0.05215230306584984
0.05387999484786674,274.985287986606,0.1710689836419769,110.87406811619954,289.8014938865635,0.0524785867564021
0.054227547412748545,275.059193131096,0.17217246303547662,110.9038666704579,289.97497856792484,0.05280831620432002
0.054576214484123746,275.122957237923,0.1732794809870929,110.92957635833056,290.1381267616463,0.053138993795902846
0.054919448252932546,275.184131800943,0.17436924820306082,110.95424194214024,290.29709248741307,0.05346441164615084
0.05526157947275744,275.254529110174,0.17545551482600488,110.98262613722216,290.4655291458323,0.05378867882354224
0.05560248339340854,275.314294005919,0.17653788477407212,111.00672334318655,290.62245246635115,0.05411167823370054
0.05594678002683044,275.415443087968,0.17763102658518665,111.04750665306871,290.8240502984026,0.05443778631219784
0.05628933368607864,275.486480302604,0.1787186344532997,111.07614885800993,290.99343071836057,0.05476213798862959
0.05663754896711194,275.572797439627,0.1798242179705804,111.11095192765761,291.1805652486179,0.05509174265885717
0.056990718597072644,275.657974483387,0.18094553154570564,111.14529531170164,291.36792053620877,0.05542592595746943
0.05734546555554324,275.737304064477,0.18207185313884977,111.17728099879713,291.54958813708475,0.05576148939762458
0.05769905299114014,275.816886580005,0.18319449324686995,111.20936866905802,291.731259734636,0.05609584400414974
0.05805278856590904,275.868279881683,0.1843176036967612,111.2300904482946,291.88320280569536,0.05643022686618197
0.058403633954944946,275.910481214715,0.18543153780695018,111.24710602577308,292.0246559639119,0.056761767254650534
0.05875937407612014,275.953953724056,0.18656101269168143,111.26463414153939,292.1688353187122,0.05709782085389968
0.05910832344252354,276.025965184949,0.18766892693001225,111.29366916257142,292.3413972136357,0.057427349813588734
0.05945571245977135,276.078899188531,0.18877188705977402,111.31501215281571,292.4933668348945,0.05775529743704903
0.05980384529392954,276.166111328058,0.18987720880822628,111.35017608747297,292.6819067253473,0.058083839390313675
0.06015433287114345,276.249287233047,0.19099000686588044,111.38371261236456,292.86687881267983,0.0584144945740027
0.06051316925639624,276.312749826272,0.19212931238905806,111.40930072995289,293.03331002420947,0.05875291291475401
0.060871931007562045,276.381108634352,0.19326838094900947,111.43686300137074,293.2049604109358,0.05909114641563171
0.06122454989102644,276.431443071648,0.19438794590400896,111.45715784648849,293.35583374943656,0.059423477098881745
0.061585429499731247,276.474620862015,0.1955337386616467,111.47456713156446,293.5014291335776,0.05976347890373946
0.061936314345876944,276.526798128108,0.1966477980481593,111.49560500525315,293.6538488220293,0.060093953362365476
0.06229304631108054,276.571525803616,0.1977804220376807,111.51363920401796,293.8000086688268,0.0604298229018457
0.06264549236132834,276.614603143246,0.19889943824721745,111.53100798735677,293.94326115148806,0.06076154642896486
0.06299632889853594,276.664766488277,0.2000133442528516,111.55123384807328,294.09363111260916,0.061091645824718564
0.06335260122527614,276.740714927277,0.20114450889025173,111.58185625867809,294.2729590828626,0.061426748239027634
0.06370794962670615,276.803795536564,0.202272740064792,111.60729036034262,294.4383977990885,0.06176086980843339
0.06406306167430814,276.855736281844,0.20340022081592835,111.6282328688395,294.5919623901537,0.06209465765403609
0.06441644684195204,276.890237139538,0.2045222187231977,111.6421436146617,294.72652238129257,0.0624267117513174
0.06476333547078765,276.924819823266,0.2056235901197508,111.65608735274085,294.8593948296676,0.06275255425159512
0.06511659050154604,276.953897616195,0.20674517484240867,111.66781151884982,294.98819115507587,0.06308426781881533
0.06546891056244394,277.018232988168,0.2078637910357595,111.69375154082934,295.15431490783664,0.06341499386940881
0.06583381344905655,277.050184262856,0.20902235770075453,111.70663429478354,295.2894544096436,0.0637574162630623
0.06619291154839724,277.126988695775,0.21016249416616123,111.73760184213648,295.47083094618813,0.06409427705240049
0.06655833944683605,277.144761165033,0.21132272774370445,111.74476770174131,295.5910562545676,0.06443695921174221
0.06692708176587404,277.195324295603,0.21249348460665007,111.76515475598711,295.74719842985274,0.06478263049596411
0.06729285469129374,277.246038715569,0.2136548136448576,111.78560281011742,295.90271611259254,0.065125400163469
0.06765242598063605,277.27732250286,0.21479645248851945,111.79821643315316,296.0358060395937,0.065462243731309
0.06801487462997094,277.315734338317,0.21594722695015772,111.81370408520941,296.17732924225595,0.06580166799716812
0.06837439145914874,277.334853418772,0.21708869288279722,111.82141289844887,296.2974552516928,0.06613823290907647
0.06874066642788565,277.367143456467,0.21825161590853692,111.83443224164749,296.43354574286343,0.0664810080638079
0.06911461167207224,277.399883295258,0.21943889205882935,111.84763294464803,296.5722685070879,0.06683084020804238
0.06948308671879665,277.432638934381,0.22060880033217933,111.8608400183424,296.70951504408316,0.06717543522060394
0.06985860613544084,277.45040878908,0.22180107448002467,111.86800482375703,296.8327076187934,0.06752649594340046
0.07022758005454355,277.479138813297,0.22297256667317575,111.87958876952136,296.96582724777363,0.06787131749791504
0.07059388569051184,277.498320530209,0.22413558706737507,111.88732283778029,297.08800524902756,0.0682135278553915
0.07096536079309344,277.511275415074,0.22531502051807167,111.89254624735784,297.20496319905624,0.06856044807897838
0.07133791493317414,277.549355879303,0.22649787991282788,111.90790029053497,297.349148218778,0.06890825517805504
0.07171767489677644,277.580207069946,0.2277036177972652,111.92033949060225,297.4876141183683,0.06926266499306834
0.07209621063128005,277.63118159018,0.22890546875431414,111.94089241716058,297.64733773591684,0.06961580734464362
0.07247332496009365,277.638862068979,0.23010280674829733,111.94398918621233,297.7602735412548,0.0699674996786454
0.07285118327949755,277.63261483691,0.2313025069124047,111.94147030224212,297.8584793447599,0.07031976183932079
0.07321284547787535,277.635712654342,0.23245078439225422,111.9427193422307,297.9622131840441,0.07065680882110252
0.07358566497971554,277.667908438775,0.23363448631059683,111.95570068251408,298.100286124769,0.0710041348545165
0.07396077205604584,277.687862306166,0.23482545127794555,111.96374608184612,298.225870992923,0.07135347033213504
0.07434135333543884,277.729249881714,0.23603379684001832,111.98043355230708,298.3760181787569,0.07170777923391962
0.07473342508441955,277.742095310137,0.23727862464303204,111.98561282904724,298.4987133827869,0.07207265416267274
0.07511931965215335,277.756448016062,0.23850383989558688,111.9913998400762,298.6213234200273,0.07243165044539301
0.07550987823981664,277.771264725629,0.23974386341141782,111.99737393737361,298.7457391035812,0.07279485447176783
0.07589737252868455,277.788419303428,0.24097415777857342,112.00429066314217,298.87183044745467,0.07315507849994239
0.07628615069864594,277.800110403763,0.24220852846820085,112.00900451479724,298.9924114901249,0.07351636569501142
0.07669173892539845,277.824274761251,0.24349627108814006,112.0187475837364,299.131101508379,0.07389313522293389
0.07710288179056345,277.818105546352,0.24480164968503892,112.01626015628914,299.2386820975707,0.07427491987984078
0.07751545539833404,277.819015154884,0.24611157088971058,112.01662691044925,299.3542826329316,0.07465788665004977
0.07792697383918025,277.817517286568,0.2474181419393973,112.0160229699442,299.4669956882244,0.07503972792798343
0.07834050457204224,277.824080864216,0.24873110201623408,112.01866940445188,299.58895954138256,0.07542328956128919
0.07875696706349665,277.834142238505,0.25005337042660186,112.02272615056523,299.7155166278978,0.07580942185443322
0.07918022099532644,277.830237070875,0.25139720166016144,112.0211515869768,299.82889664133086,0.07620169827433972
0.07959386059207604,277.817161335252,0.2527105073798414,112.01587945037362,299.92970174465637,0.07658491540237518
0.08001302861067824,277.817807034652,0.2540413658389034,112.01613979637169,300.04685117747147,0.07697310459177026
0.08044754813904534,277.814740236872,0.2554209653414689,112.01490326350681,300.1642549258142,0.07737535172268513
0.08088141235168664,277.801703122492,0.25679848421660506,112.00964669898876,300.27069722474306,0.0777768308370633
0.08131710907238844,277.773769263969,0.2581818213048333,111.9983837672323,300.36152915665565,0.07817984353204206
0.08177347315642344,277.765318038807,0.2596307772716444,111.99497623324699,300.4791528172388,0.07860179913071687
0.08222652594162955,277.755318703822,0.2610692198646738,111.99094450138104,300.5941736226474,0.07902051705309592
0.08269328771185114,277.769209391233,0.2625511884851274,111.99654522654515,300.73885854091566,0.07945172173283538
0.08317529457555065,277.758795858354,0.2640815602773733,111.99234649008834,300.86146552482285,0.07989681510147169
0.08366117773346984,277.732302832011,0.2656242393037667,111.98166450186683,300.96771438156577,0.08034528749177187
0.08417209572265215,277.660001848984,0.26724640391942056,111.95251274551035,301.03122610296845,0.08081665030818207
0.08469134637473984,277.610954000988,0.268895024739799,111.93273665319836,301.12219946370766,0.08129547313485697
0.08522681271799794,277.53484649347,0.27059513037964344,111.90205010616712,301.1882568782873,0.08178900912549639
0.08577732094415784,277.455672381844,0.2723429939977011,111.87012710435951,301.25507663951856,0.08229615531598324
0.08633598340629015,277.355974574075,0.2741167473149712,111.82992894826704,301.30177539253776,0.08281055065008668
0.08689605151827334,277.20965261511,0.27589496357051785,111.77093193441235,301.2980768701152,0.08332597478831182
0.08746737724418074,277.070739608082,0.27770892275027387,111.71492220997867,301.3053905127063,0.08385148559436949
0.08804666480338605,276.920718967142,0.2795481607507507,111.65443388755166,301.3026646871546,0.08438403795827065
0.08865114624780145,276.743493978241,0.28146738933676957,111.58297677202678,301.2771219360336,0.08493944942318399
0.08926854727847704,276.498464855249,0.28342763760916456,111.48418102963639,301.1810811376061,0.08550641343847745
0.08990562084476604,276.216439164398,0.28545034618213216,111.37046827108529,301.0498496150038,0.08609110611128658
0.09054356560529404,275.877356793565,0.28747582079680856,111.2337502591654,300.85627634741826,0.08667625598104288
0.09118540154109034,275.491728111175,0.2895136498929618,111.07826477442578,300.61255196024143,0.08726462966446338
0.09184656309691765,275.048858648298,0.2916128378327135,110.89969980699377,300.3111509988741,0.08787035746575297
0.09250756298965174,274.567991354187,0.2937115124921442,110.70581411400819,299.96760710932654,0.08847557060863687
0.09318753298271064,273.974734082271,0.29587041722010626,110.46661278197168,299.505763650992,0.08909777085628205
0.09387825281070095,273.337039270272,0.2980634526739755,110.20949423377365,298.99744294541506,0.08972941152794528
0.09456217611056834,272.611461393688,0.3002349091510545,109.91694123393499,298.3901944157573,0.09035444414303914
0.09526062852816754,271.777505161468,0.30245249557693193,109.58069008110391,297.6672011229668,0.09099235186763183
0.09596249779347264,270.937375937763,0.30468093049427564,109.24194997810606,296.93720327835985,0.09163297059867508
0.09667520410619454,269.973955006982,0.30694377303716763,108.85349865881516,296.07374221063856,0.09228306097813413
0.09738802239287304,268.989811673525,0.3092069710973719,108.4566920667653,295.18619747624103,0.09293283105143824
0.09811951969050854,267.960630919937,0.3115294750173646,108.0417263869186,294.2527993217668,0.09359918934051852
0.09885979132570605,266.900184971483,0.3138798374591167,107.61415458050195,293.28588156255614,0.09427308887111613
0.09961612405579984,265.73171963675,0.31628119387716447,107.1430293575376,292.20288358564545,0.0949611407661952
0.10035903409080664,264.567341746417,0.3186399332383111,106.67355219215536,291.1190646160598,0.09563652117719218
0.10111135162532334,263.279657542982,0.3210285414104016,106.15435792133036,289.9002195726052,0.09631998943430214
0.10186438939707834,261.993090047027,0.32341943633572373,105.6356139069613,288.6808561909212,0.09700364453504821
0.10263219036103434,260.649337015261,0.325857204396284,105.09381268455323,287.40034938928864,0.09770022170559321
0.10339913390864235,259.333315762381,0.32829225015993946,104.56319291539204,286.1481560058677,0.09839553692625182
0.10417779416826134,257.861308573175,0.33076449648422973,103.96967961670417,284.7247309016697,0.09910098033074415
0.10496032170570434,256.398009901169,0.33324902141561125,103.37967759215135,283.30962750509804,0.09980942636637126
0.10573011790321934,254.84664170774,0.3356931243427214,102.75416593656077,281.7916071827388,0.10050585696093685
0.10650874029194635,253.329329154457,0.33816525042692963,102.14238551507708,280.31111688170205,0.10120977952155333
0.10729587473403235,251.723878245819,0.34066440228055267,101.49506770871423,278.73281195364723,0.1019208941970886
0.10811592849343535,250.050899313502,0.34326807296665723,100.82052260320401,277.0853844633998,0.10266121145608503
0.10894378231798034,248.357645568526,0.34589650885958756,100.1378026932297,275.41466684434965,0.10340801485428268
0.10977297882894334,246.507849631589,0.34852920778189506,99.39196497145669,273.5677505903658,0.10415547082891528
0.11018439906916634,245.644653342348,0.3498354670446031,99.0439242276347,272.71086185542833,0.10452612681450255