File: example/data/02 processed data/test_ID_121.csv
Strain,Stress_MPa,Displacement(mm),Force(kN),True Stress (MPa),True Strain
-1.88743049756805e-05,0.173951776225056,-5.992591829778558e-05,0.03506867808697129,0.17394849300618045,-1.8874483097648855e-05
-0.0001231017905683,0.849840540855233,-0.0003908481850543525,0.17132785303641498,0.8497359239629562,-0.0001231093682156001
-0.0002179831562619,2.20586765418738,-0.0006920965211315325,0.4447029190841758,2.205386812193824,-0.00021800691804325123
-0.0003661961374162,4.68078952835658,-0.0011626727362964349,0.9436471689166865,4.679075441311237,-0.000366263203595121
-0.0003996165828963,8.06854171075674,-0.0012687826506957525,1.626618008888559,8.065317387689332,-0.0003996964508814196
-0.0003752544522582,11.9988702653131,-0.0011914328859197849,2.418972245487121,11.994367635823973,-0.0003753248778290271
-0.0003090895214107,16.3226169591013,-0.0009813592304789725,3.290639578954822,16.31757180923724,-0.00030913729942223095
-0.0002093548673169,20.7507166136721,-0.0006647017037311574,4.183344469316295,20.746372350148715,-0.00020937678510623184
-0.0001450563624478,25.3605047578359,-0.00046055395077176497,5.112677759179718,25.35682605526589,-0.00014506688413941856
-3.84776075245827e-05,29.8741739131405,-0.00012216640389055007,6.022633460889125,29.873024426401546,-3.847834780675292e-05
4.23164253358469e-05,34.4095070687533,0.0001343546504413139,6.936956625060665,34.41096315609002,4.23155300211398e-05
0.0001436776329216,38.8192156141539,0.00045617648452607993,7.825953867813426,38.82479306716521,0.00014366731227900806
0.0002363536658001,43.2901267983725,0.0007504228889153175,8.727289562551896,43.300358578534244,0.00023632573867280157
0.000354507190146,47.7757665089022,0.00112556032871355,9.631594528194684,47.79270336164435,0.0003544443673191275
0.000471315277982,52.3063428539577,0.0014964260075928499,10.544958719357874,52.33099563248014,0.000471204243823118
0.0005613245062318,56.8693093962885,0.0017822053072859647,11.464852774291762,56.90123153330511,0.0005611670225612557
0.0006675975418257,61.480250097554,0.0021196221952965973,12.394418419666886,61.52129416138996,0.0006673747977169446
0.0007578860813136,66.1138597886264,0.00240628830817068,13.328554133387083,66.16396656274212,0.0007575990306827236
0.0008607251951977,70.8638527508895,0.0027328024947526975,14.286152714579325,70.92484705438098,0.0008603549836852833
0.000981303644756,75.6136536594075,0.0031156390721003,15.243712577736554,75.68785361333678,0.0009808224810870124
0.0010892356427533,80.3299416430397,0.0034583231657417273,16.194516235236804,80.41743987865759,0.0010886428560277206
0.0012146613336863,85.1337616795456,0.0038565497344540023,17.162966354596392,85.23717036804901,0.0012139242294361724
0.0013181375804965,89.7782485295246,0.004185086818076387,18.09929490355216,89.89658861282253,0.0013172695998174993
0.0014321351602912,94.3899702253686,0.00454702913392456,19.02901799743431,94.52514942050719,0.0014311106327905302
0.0015458064326551,99.0750692783371,0.004907935423679942,19.97353396651276,99.2282201577433,0.0015446129037095563
0.0016525462902309,103.564371728147,0.0052468344714831075,20.878577340394436,103.73551664644643,0.0016511823380661124
0.0017655991954279,108.111216392526,0.0056057774454835825,21.79522122473324,108.30209746920538,0.0017640423574004545
0.0018706731636535,112.544857872253,0.005939387294599863,22.689043347046205,112.75539251758183,0.0018689256336431774
0.001971522182204,116.907549320813,0.006259582928497699,23.568561943075903,117.1380351475661,0.0019695812829452464
0.0020694636653597,121.271652250211,0.006570547137517048,24.448365093642536,121.52261952818097,0.0020673252751343355
0.0021695102075378,125.615946536107,0.006888194908932514,25.324174821679172,125.88847161434661,0.0021671602185371897
0.0022694348259735,129.838400740487,0.0072054555724658615,26.175421589282184,130.13306052887617,0.002266863548255493
0.0023802834981315,134.115276950869,0.007557400106567512,27.037639833295195,134.43450933144248,0.0023774551107191687
0.002475907768064,138.239465318989,0.007861007163603198,27.869076208308183,138.58173348502532,0.002472847758253367
0.002581075950601,142.28461873762,0.008194916143158175,28.684579137504194,142.65186614518413,0.0025777506946661017
0.0026871617388148,146.113084616817,0.00853173852073699,29.456397858750307,146.50571410733951,0.0026835577745558366
0.0027848023417179,149.96307704916,0.008841747434954332,30.232556333110658,150.38069457729773,0.0027809319635037997
0.002875136368218,153.736628524583,0.00912855796909215,30.99330431055594,154.17864229638127,0.002871011068957087
0.0029581342020551,157.518729394944,0.009392076091524941,31.75577584602071,157.98469093583142,0.002953767532420075
0.0030405006971745,161.336232365224,0.009653589713529037,32.52538444482916,161.82677529220996,0.003035887723065097
0.0031558202835545,165.156659126179,0.010019729400285537,33.295582479837684,165.67786386101346,0.0031508511344729385
0.00327213476933,168.921566087034,0.01038902789262275,34.05458772314606,169.47430021671707,0.0032667929858741056
0.0033791848160224,172.653326414138,0.01072891179087112,34.80691060509022,173.23675391319244,0.0033734882006821263
0.0034853642158255,176.27359244074,0.011066031385245962,35.536756236053186,176.88797011202797,0.003479304410304495
0.00357302518282,179.905022017518,0.0113443549554535,36.26885243873163,180.5478271917024,0.0035666570927310854
0.0036841638582537,183.432319202814,0.011697220249955497,36.979955551287304,184.10811392365665,0.003677393949127867
0.0037827984630251,186.812865208976,0.012010385120104692,37.66147362612956,187.51954062836185,0.0037756616732819636
0.0038882732316284,190.099274925448,0.01234526751042017,38.324013824970315,190.83843284749256,0.0038807334354717003
0.0040095314170625,193.249224777996,0.012730262249173438,38.959043715244,194.02406361606634,0.0040015146677643545
0.0041533629108632,196.201768282887,0.01318692724199066,39.55427648583002,197.0166654303189,0.004144761507403615
0.0043341236537791,198.768076533692,0.01376084260074864,40.07164422919231,199.62956195581285,0.004324758390245097
0.0045106927498907,200.86229678247,0.014321449480902972,40.49383903134595,201.7683248882931,0.004500550064270524
0.0047350411037941,202.436077363763,0.015033755504546265,40.81111319653462,203.39462051097124,0.004723866058979982
0.0049843545723334,203.599138231721,0.015825325767158546,41.045586267514956,204.61394852728944,0.0049719738001448525
0.0052651649275029,204.234477532535,0.016716898644821707,41.17367067055906,205.3098057406262,0.0052513524088917225
0.0055668590118854,204.53177342935,0.017674777362736146,41.233605523356964,205.67037297548208,0.005551421318730567
0.0058794715977894,204.650602061843,0.018667322322981343,41.25756137566755,205.85383946413612,0.0058622549548697205
0.0062005615695438,204.657485228647,0.019686782983301565,41.25894902209524,205.92647656647523,0.006181417184191661
0.0065481177957837,204.602515717743,0.02079027400161325,41.247867168696985,205.94227709197648,0.0065267720049475885
0.0068919047725748,204.454826387819,0.02188179765292499,41.21809299978431,205.86390958157716,0.0068682641539845974
0.0072413205350806,204.309755389575,0.022991192698880905,41.18884668653832,205.7892278167948,0.007215228060463678
0.0075937622917293,204.134542355362,0.024110195276240524,41.15352373884098,205.68469154553955,0.007565074817895499
0.0079666211380335,203.980422087484,0.02529402211325636,41.12245309283677,205.60545682983116,0.007935055150534415
0.0083263029756119,203.7777925756,0.02643601194756778,41.081602983240955,205.47450821628584,0.00829183053479739
0.0086901329323345,203.568295726721,0.027591172060162032,41.03936841850696,205.337331277395,0.00865259106623528
0.0090350284582024,203.38962567817,0.02868621535479262,41.00334853671908,205.2272567342754,0.008994456782960718
0.0093985857429157,203.203039208037,0.029840509733757348,40.96573270434026,205.1128603952548,0.009354693836175732
0.0097563484203537,203.062864954608,0.030976406234622993,40.93747357484897,205.0440170163404,0.009709062562546096
0.0101267693897567,202.897201064726,0.03215249281247752,40.904075734648764,204.9518942297356,0.010075837224197809
0.0105086990437297,202.726226367912,0.0333651194638418,40.86960723577106,204.85661526908342,0.010453866477358978
0.010911776058838,202.552110830596,0.034644888986810646,40.83450554344815,204.7623141042244,0.010852672193849097
0.0113015458900501,202.384103049736,0.035882408200909065,40.80063517482678,204.67135627776923,0.011238160541500904
0.0116916441266761,202.245791395407,0.037120970102196615,40.77275154531405,204.61037721452007,0.011623824955386552
0.0120805647255662,202.082949215833,0.03835579300367268,40.73992256191193,204.52422536376818,0.012008177109227483
0.0124754135621823,201.867964679117,0.0396094380599288,40.696581679309986,204.38635102344497,0.012398236802174372
0.0128361588671367,201.650964391468,0.04075480440315902,40.65283442131995,204.23938820610817,0.012754473653511424
0.0131998424676413,201.428261399629,0.041909499834761124,40.60793749816521,204.087082718635,0.013113483665348698
0.0135583465734286,201.215620268986,0.0430477503706358,40.56506904622758,203.9437713845803,0.013467254639572152
0.0139457704721657,201.092897878988,0.0442778212491261,40.54032821240398,203.89729327639103,0.013849422942161873
0.014325481098507,200.926792287392,0.04548340248775972,40.50684132513823,203.80516525248868,0.01422384094023104
0.0147020938500527,200.879481666481,0.04667914797391732,40.49730350396257,203.83283065849153,0.014595065817133192
0.0150782581355101,200.76833458939,0.04787346958024456,40.474896253221026,203.79557136376528,0.014965711132914096
0.0154608899684151,200.656916919552,0.04908832564971794,40.452434450981684,203.7592514334466,0.015342588217792023
0.0158458658009335,200.528556536747,0.05031062391796386,40.4265569978082,203.7061051328832,0.01572163075879113
0.0162340815839178,200.388447714236,0.05154320902893901,40.39831105918998,203.64157012290354,0.016103717879139716
0.0166226298902665,200.216762459235,0.05277684990159613,40.36369931178178,203.5448915994223,0.016485986151061914
0.0170144673706498,200.05290099328,0.05402093390181312,40.33066484024525,203.456694549634,0.016871342501769745
0.0174035758277622,199.909383271543,0.055256353253144985,40.301731667543066,203.38852138199047,0.017253868072812515
0.0178178240406616,199.765475842442,0.05657159132910057,40.272719929836306,203.32486194040166,0.01766094734059813
0.0181931710301303,199.630493703664,0.057763318020663694,40.245507530658664,203.26240541844413,0.01802965555939428
0.0185826778630829,199.471706473471,0.0590000022152882,40.213496025051754,203.17842493766693,0.018412129495259555
0.0189557033579241,199.321771610115,0.06018435816140902,40.18326915659919,203.10005598553226,0.018778282596910906
0.0193533891498604,199.187988563696,0.06144701055080677,40.15629849444111,203.04295122034716,0.019168494070179842
0.0197477907938962,199.058554287927,0.06269923577062043,40.13020454444608,202.98952097374038,0.01955533279386181
0.0201582245245758,198.889692917487,0.06400236286552816,40.09616209216538,202.89895600294162,0.01995773734891086
0.020551259192947,198.704809434431,0.06525024793760673,40.0588895819813,202.78844347600315,0.02034293149473811
0.0209363738081569,198.469534696418,0.06647298684089815,40.01145819479787,202.6247670643532,0.02072021971686857
0.0213241149760622,198.258366019532,0.06770406504899748,39.968886589537654,202.4860502114987,0.021099937362774653
0.0216996240768103,198.128597284309,0.06889630644387269,39.94272521251669,202.42791336424426,0.021467538676258058
0.0220967535668583,198.006569012648,0.0701571925747751,39.918124312949836,202.3818713727396,0.02185615810957352
0.0224996673245006,197.991416632262,0.0714364437552894,39.91506959306402,202.4461576395945,0.022250283579755187
0.022909823997755,197.921397306245,0.07273869119287212,39.900953696939,202.45574168392082,0.02265133449937987
0.0233168983284438,197.809781982789,0.07403115219280906,39.87845204773026,202.42209255765331,0.023049212536664233
0.0236974672183372,197.63185397998,0.0752394584182206,39.84258176236397,202.3152283609698,0.023421040796087787
0.0240774765446598,197.375593201703,0.07644598802929486,39.79091958946332,202.12789941750532,0.023792184443334936
0.0244668817192347,197.129668584545,0.07768234945857017,39.74134118664427,201.95281686915496,0.024172361887571474
0.024882619300535,196.948837407353,0.07900231627919863,39.70488562132237,201.84944035024313,0.024578088277136995
0.0252903948850709,196.867184783152,0.0802970037601001,39.68842445228344,201.84603362623014,0.02497588454807779
0.0256925299611328,196.784898700692,0.08157378262659663,39.67183557805951,201.840800606458,0.02536802343557748
0.0261129704758905,196.677840844829,0.08290868126095233,39.65025271431753,201.81368349607192,0.025777848363479017
0.0265102934997363,196.542716910384,0.08417018186166275,39.62301172913342,201.75312202091388,0.026164985190564097
0.0269156202519099,196.4326775132,0.08545709429981393,39.60082778666112,201.71978486621114,0.026559766180443825
0.0273224665577081,196.29734397457,0.08674883132072321,39.573544545273315,201.6606715906821,0.026955870520763564
0.0277131264349891,196.142545731007,0.08798917643109039,39.542337219371014,201.578268900131,0.027336068200374413
0.0281277520376349,195.934825871995,0.0893056127194908,39.5004608957942,201.44603206965965,0.027739431721947712
0.0285381358240559,195.741701112153,0.09060858124137748,39.46152694421004,201.3278043649234,0.028138508494008473
0.028937440586357,195.505501863264,0.09187637386168347,39.413909175634025,201.1629307077381,0.028526658683388537
0.0293332004978528,195.318047381531,0.09313291158068264,39.37611835211665,201.04735082622256,0.028911214444398266
0.0297318659790334,195.187674188508,0.09439867448343103,39.34983511640321,200.99096795823993,0.029298444059093424
0.0301387141066031,195.08476852898,0.09569041728846484,39.32908933544237,200.96437259422777,0.02969346706373621
0.0305403569092224,195.022647323285,0.09696563318678111,39.31656570037426,200.97870857791955,0.030083283035912074
0.0309629156831149,194.919334421597,0.0983072572938898,39.295737819393956,200.95460533830177,0.03049323511838343
0.0313789084361681,194.789703743578,0.0996280342848337,39.26960427470532,200.90199202165607,0.030896652974560384
0.0317909965216917,194.642009595886,0.10093641395637114,39.239829134530616,200.82987304592388,0.03129612379857068
0.0322065527155864,194.476310636408,0.10225580487198682,39.20642422429985,200.73972218685222,0.03169879501265554
0.0326344283295586,194.303740742251,0.10361430994634856,39.1716341336378,200.6447322436691,0.03211323430752067
0.0330520409113115,194.114093190701,0.10494022989341402,39.133401187245326,200.5299601403022,0.03251756729189261
0.0334499803707002,193.935320748943,0.10620368767697312,39.097360662986915,200.42245342118062,0.03290270068175557
0.0338556178849705,193.808124701743,0.10749158678478132,39.07171793987139,200.36961851464793,0.0332951317957798
0.0342640532128295,193.695647435824,0.10878836895073365,39.04904252306212,200.33244540665854,0.033690114096733684
0.0346880165564311,193.520803789881,0.11013445256666873,39.01379404404001,200.23365663575825,0.03409994799837947
0.0351037588311609,193.242536793358,0.11145443428893587,38.957695417540975,200.02607620087377,0.034501671771045433
0.0355018692126941,193.030317498958,0.11271843475030376,38.91491200778993,199.8832545848908,0.03488620698243175
0.0358976416639878,192.858900944008,0.11397501228316127,38.88035443031202,199.78208066180653,0.03526833747346605
0.0363095173090506,192.773329112601,0.11528271745623564,38.86310314910036,199.7728356427383,0.03566586109817049
0.0367177641438537,192.714024486605,0.11657890115673548,38.85114733649957,199.79005258491702,0.036059726479232425
0.0371380187955987,192.574226425761,0.11791320967602587,38.822964047433416,199.7260516663088,0.03646501469739578
0.0375622850638688,192.437860258036,0.11926025507778343,38.795472628020065,199.66626602212932,0.03687400511726014
0.0379756042606365,192.305058644109,0.12057254352752089,38.76869982265237,199.6079594484962,0.03727228182842704
0.0383933283502482,192.178826651023,0.12189881751203804,38.74325145284624,199.55721144460117,0.03767464201469898
0.038816265182927,192.079786045741,0.12324164195579322,38.72328486682139,199.53560595717235,0.038081858349381666
0.0392441325039437,191.94773514328,0.12460012070002124,38.69666340488525,199.48055749507475,0.03849365323998187
0.0396892590054888,191.791217472789,0.12601339734242695,38.66510944251426,199.40326877804452,0.038921879089030394
0.0401221721303735,191.611771419491,0.12738789651393587,38.628933118169385,199.2996518945896,0.039338179456127206
0.0405483952670225,191.407014753613,0.12874115497279645,38.587654174328385,199.1682620447233,0.03974787731920026
0.0409714185719052,191.237865740535,0.130084253965799,38.55355373329186,199.07315238458827,0.040154333513269753
0.0413933458415015,191.070682220312,0.13142387304676725,38.5198495356149,198.979737049629,0.04055957209834454
0.0418293979750672,190.923325816915,0.13280833857083835,38.49014248469006,198.90953359523417,0.04097820437492501
0.0422619514630724,190.756950148762,0.13418169589525486,38.45660114999042,198.81871111719272,0.04139330469606291
0.0426872704636455,190.570085045842,0.13553208372207445,38.41892914524175,198.70500180847378,0.04180129449456712
0.0431200518244479,190.423196403904,0.13690616454262208,38.389316395027045,198.63425450141736,0.04221627181523198
0.0435714273062464,190.282960849072,0.1383392816973323,38.36104490717292,198.57386104532466,0.04264889493499151
0.0440165108681209,190.200875360945,0.13975242200628385,38.34449647276651,198.57285425839615,0.04307530434316977
0.0444392079928711,189.968959733344,0.14109448537736574,38.297742282242154,198.41102984712342,0.0434800983033237
0.0448560098585258,189.700986398346,0.14241783130081942,38.24371885790656,198.21021571440227,0.04387908631384779
0.0452507287912846,189.449911712511,0.1436710639123286,38.19310220124222,198.02265828694667,0.04425678849541809
0.0456672727271313,189.273178609977,0.14499359090864186,38.15747280777136,197.91676847748985,0.04465522013267456
0.0461125123930559,189.245945019779,0.1464072268479525,38.15198251598744,197.97255100483912,0.0450809242874005
0.0465513447445595,189.168346703632,0.1478005195639764,38.13633869545222,197.97438762579117,0.04550032500141325
0.0469981520557475,189.064044923812,0.1492191327769983,38.1153114566405,197.94970565541598,0.04592716689710717
0.0474292833915547,188.956160304575,0.15058797476818617,38.09356191740232,197.9182155802407,0.04633886064652996
0.0478733653457244,188.832068026092,0.15199793497267497,38.06854491406015,197.87209460769378,0.046762744003988305
0.0483362191598496,188.732849006979,0.15346749583252248,38.048542359806966,197.85548135924313,0.04720435425619641
0.0487772940234653,188.629445490586,0.1548679085245023,38.027696210902135,197.8302794147635,0.04762500375117773
0.0492267645372597,188.479931556232,0.15629497740579953,37.99755420173637,197.75818876694947,0.048053478156493606
0.049674526258182,188.224618392218,0.15771662086972785,37.94608306787114,197.5745871409785,0.04848014112504617
0.0501106339178201,187.968792480056,0.15910126268907882,37.894508563979294,197.3880278279988,0.04889552425488242
0.0505727572926074,187.74464187412,0.16056850440402848,37.84931980182259,197.23940608060735,0.049335498583403845
0.0510185411718631,187.598350823099,0.16198386822066532,37.81982752593676,197.16934500834088,0.04975973319673451
0.0514537436216815,187.498263620323,0.16336563599883877,37.79964994585712,197.14575120615356,0.0501737243434258
0.0518933118508553,187.417037165229,0.16476126512646558,37.78327469251017,197.14272792100758,0.05059169458226913
0.0523338811970998,187.274352698337,0.16616007280079187,37.75450950398474,197.07514642371552,0.05101044152569589
0.0527898031272213,187.113637516336,0.1676076249289276,37.72210932329334,196.99132960324167,0.051443596062548155
0.0532480277502631,186.940349946835,0.16906248810708532,37.687174549281934,196.89455488844797,0.05187874933810123
0.0536951424237538,186.741353704509,0.1704820771954183,37.647056906829015,196.7684572880772,0.05230316959445328
0.0541404859239646,186.546778827833,0.1718960428085876,37.607830611691135,196.64651208112227,0.052725729589975
0.0545846795750618,186.32424075069,0.1733063576508212,37.562966935339105,196.49468972913306,0.053147020770954276
0.0550304015959373,186.184912781978,0.17472152506710092,37.534878416846766,196.4307433034748,0.05356958319145087
0.0554865854575883,186.062339023247,0.17616990882784284,37.5101675470866,196.38630289789918,0.05400187904270786
0.0559443483069329,185.990182156879,0.17762330587451194,37.49562072282681,196.39528168913333,0.05443548342843168
0.0564134862916805,185.88959012086,0.17911281897608558,37.47534136836538,196.37626996490923,0.054879667633188085
0.0568835620458185,185.728333815935,0.18060530949547374,37.4428320972925,196.29322301622025,0.05532454192311405
0.0573536627110798,185.551603669759,0.18209787910767836,37.407203299823415,196.1936677621343,0.05576924194778839
0.0578151748030962,185.348377646264,0.1835631799998304,37.36623293348682,196.06432649935303,0.05620562517276309
0.0582640754271425,185.177359182844,0.18498843948117744,37.33175561126135,195.96654680567224,0.05662990099393687
0.0587239575220498,184.956713972271,0.1864485651325081,37.28727353680983,195.81810418699652,0.05706436929983533
0.0591717169870526,184.751363735497,0.187870201433892,37.245874929076194,195.68341914342585,0.05748720360377521
0.0596358220465782,184.537461319491,0.18934373499788576,37.202752202009385,195.54250452366747,0.05792528498530515
0.0601040708458482,184.346533837192,0.190830424935568,37.16426122157791,195.42651096712913,0.05836708334788382
0.0605666193158738,184.260431738481,0.1922990163278993,37.146903038477774,195.42046316256415,0.05880331182928503
0.0610379429385653,184.157319415484,0.1937954688299448,37.12611559416158,195.39790336968545,0.05924762048022822
0.0615165784934711,184.075256420702,0.19531513671677073,37.109571694413525,195.39893638101194,0.0596986200264691
0.0620048004059345,183.95827582451,0.19686524128884203,37.08598840622122,195.3645720000286,0.06015844296577848
0.0624725471522524,183.744237979174,0.19835033720840137,37.04283837660147,195.22320855028264,0.06059878350827803
0.0629427585211426,183.521181272452,0.19984325830462776,36.997870144526324,195.07251066879877,0.06104124891756187
0.0633897215103877,183.301941364086,0.20126236579548093,36.953671378999736,194.92140037946885,0.06146165635621574
0.0638484388519857,183.066205230951,0.20271879335505458,36.90614697455972,194.75469664150444,0.061892936085261245
0.0643242290265875,182.953395476482,0.20422942715941533,36.883404528058776,194.72173158830307,0.06234007102850162
0.0648019905095389,182.712664240987,0.205746319867786,36.83487311098298,194.55280857510402,0.06278885747111497
0.0652758733586214,182.555429645973,0.20725089791362292,36.803174616628155,194.47189475247225,0.06323380163483676
0.0657474028523153,182.400200102694,0.20874800405610106,36.77188034070311,194.39253953918873,0.06367633974003066
0.0662226422747471,182.338838446253,0.21025688922232202,36.75950983076461,194.4137981174721,0.0641221616045447
0.0667052491411649,182.256120766877,0.21178916602319853,36.7428339466024,194.41356071013374,0.06457469155325582
0.0671982751629887,182.123014460418,0.21335452364248908,36.71599971522027,194.36136689964215,0.06503677995133134
0.0676926909744003,181.960674016952,0.21492429384372094,36.683271881817525,194.2780816926751,0.06549995659884422
0.0681773591683791,181.714289709661,0.2164631153596036,36.63360080546766,194.10309010522346,0.0659537933875247
0.068653522101477,181.432691195397,0.21797493267218948,36.57683054499204,193.88868447031066,0.06639946547617992
0.0691310243487308,181.218353913276,0.21949100230722027,36.53362014891644,193.7461643500916,0.06684619174332203
0.0696307101448317,181.052197125075,0.22107750470984064,36.500122940415125,193.65899018417602,0.067313458196741
0.0701434870567719,180.989112475307,0.22270557140525077,36.48740507502189,193.68431994363533,0.06779273953626426
0.0706531067915663,180.877208899171,0.22432361406322301,36.464845314072875,193.65674565568457,0.06826884244663449
0.071157051345164,180.715458303781,0.22592363802089566,36.43223639404225,193.574637449168,0.06873942062648188
0.0716514197359074,180.510618953745,0.22749325766150597,36.390940781074995,193.44446107918824,0.06920084161317916
0.07214178141201,180.255962351377,0.22905015598313172,36.33960201003761,193.25994858554157,0.06965831268304899
0.0726170086576956,180.019951605475,0.23055900248818353,36.29202224366376,193.0924619897677,0.07010146485070828
0.0731058031615984,179.76118577563,0.2321109250380749,36.239855052367005,192.90277163903872,0.07055706378423801
0.0735921768093146,179.534321249119,0.23365516136957384,36.194119163822386,192.74664276182443,0.07101020033216104
0.0740786858414847,179.379320862654,0.23519982754671392,36.16287108591105,192.66750521929745,0.07146325768741284
0.0746002989711051,179.239907253426,0.23685594923325867,36.13476530229068,192.61125792208472,0.07194877752872343
0.075110382002856,179.119709968174,0.2384754628590678,36.110533529583876,192.5734598081243,0.0724233372411893
0.0756154873309007,178.886262024486,0.24007917227560974,36.063470424136376,192.4128339042707,0.07289304409182362
0.0761231837142353,178.63560125999,0.24169110829269708,36.01293721401399,192.23391195260712,0.07336493819270838
0.0766172778256921,178.396528337724,0.24325985709657238,35.96474011288516,192.06478471251435,0.07382397552578243
0.0771322753236743,178.204454211039,0.24489497415266587,35.926017968945466,191.94976923714998,0.07430220894623223
0.0776573710228239,178.091015190395,0.24656215299746587,35.903148662383636,191.9210952328669,0.07478958432455182
0.0781745788214708,177.89514782236,0.24820428775816977,35.86366180098778,191.80202607775627,0.075269406333505
0.0786923590102941,177.659370425356,0.24984823985768376,35.816129077751775,191.63980538441095,0.07574952885723416
0.0792057143272892,177.375607372472,0.2514781429891432,35.758922446290356,191.42476905864544,0.07622532086337419
0.0797185558589188,177.094176259998,0.25310641485206714,35.702185934015596,191.21186824246988,0.07670041074805224
0.0802446162414752,176.826076177036,0.25477665656668375,35.648136957290454,191.0154168013481,0.07718751200954846
0.0807616101242805,176.565610285187,0.2564181121445906,35.595627033493706,190.82533326439494,0.07766598716279974
0.0812888118946452,176.307644674065,0.25809197776549847,35.5436211662915,190.639483637563,0.07815367401361921
0.0818058861659568,176.080284167741,0.2597336885769128,35.49778528821659,190.48468785043656,0.07863176152557522
0.0823050379210577,175.730027690999,0.2613184953993582,35.427173582505404,190.1934942839752,0.07909306113678904
0.0828244994251653,175.428676375541,0.2629677856748998,35.36642115730906,189.95846868116448,0.0795729044949942
0.0833476063208684,175.108013178498,0.2646286500687572,35.3017754567852,189.7028469245289,0.08005588265216305
0.0838643769534012,174.769881021205,0.26626939682704875,35.233608013874935,189.4268482032684,0.08053278167848359
0.0844006822164999,174.49550155663,0.26797216603738716,35.17829311381661,189.2230409317199,0.08102746776104308
0.0848863140788377,174.120891075781,0.2695140472003097,35.10277164087745,188.90137172332683,0.08147520185181087
0.0853826666496249,173.685835378042,0.2710899666125591,35.01506441221326,188.51559516188698,0.08193261296891102
0.0858576318768112,173.224123533993,0.2725979812088755,34.92198330445299,188.09673656455783,0.08237011888208401
0.0863581566353233,172.790565254809,0.27418714731715144,34.8345779553695,187.71243995418985,0.08283096146505158
0.0868526784759553,172.476819981324,0.2757572541611581,34.771326908234926,187.45689377171718,0.08328606857309456
0.0873525085783472,172.116403567398,0.2773442147362523,34.69866695918744,187.1512031864934,0.08374585048712287
0.0878500019061853,171.653673844757,0.2789237560521383,34.60538064710301,186.73344941922264,0.08420327303432465
0.0883623284003023,171.131195932995,0.28055039267095977,34.5000491000918,186.2527468675628,0.0846741154208391
0.0888903791380294,170.623588828115,0.2822269537632433,34.39771550774798,185.79038432893736,0.0851591769355197
0.0894082175564756,170.060144967196,0.28387109074181,34.28412522538672,185.26491940610885,0.08563462913384286
0.0899288179835295,169.419949872595,0.28552399709770615,34.15506189431515,184.6556857074663,0.08611238950634752
0.0904398043085181,168.735450944759,0.28714637867954496,34.01706691046342,183.9958521081126,0.0865811050520762
0.0909482409073005,168.044785931064,0.2887606648806791,33.8778288437025,183.32816360513817,0.08704726384404778
0.0914431145772273,167.320544814028,0.29033188878269667,33.73182183450805,182.62085656458126,0.0875007789087633
0.0919463514282677,166.543275183409,0.29192966578474994,33.57512427697526,181.85632169143742,0.08796174738716518
0.092433601546535,165.608022420562,0.29347668491024864,33.3865773199853,180.91576837789387,0.08840786952419086
0.0929324348170463,164.729469904787,0.295060480544122,33.20946113280506,180.03818062916022,0.08886439101384024
0.0934388781544427,163.848194177028,0.29666843814035554,33.03179594608885,179.1579856285608,0.08932766396610538
0.0939624798506014,162.883326235536,0.2983308735256594,32.83727856908406,178.1882474949415,0.08980640711421867
0.0944575073821765,161.851886518891,0.29990258593841035,32.62934032220843,177.14001228456834,0.09025881345569453
0.0949563694355369,160.677107337918,0.30148647295782965,32.39250483932427,175.93442210213075,0.09071451721027061
0.0954604238056146,159.620806766091,0.30308684558282634,32.17955464404395,174.85827662817616,0.09117475325350262
0.0959401810050905,158.375370765178,0.3046100746911623,31.928474746259887,173.5699325031375,0.09161260766139818
0.096424525696491,157.160899355882,0.30614786908635894,31.683637310145816,172.3150645343069,0.09205445449263
0.096918147603205,155.829157251946,0.30771511864017587,31.41515810199231,170.93183051537315,0.09250456374464697
0.097412522139513,154.562950258405,0.3092847577929538,31.15989077209445,169.61931707240035,0.09295515631165555
0.0979499739198796,153.268058650591,0.3109911671956177,30.898840623959146,168.28066099816698,0.09344478095639502
0.0984679694888414,151.773498393352,0.31263580312707145,30.597537276099764,166.71832660236333,0.09391645400944007
0.0990237269658007,150.174468672945,0.3144003331164172,30.275172884465714,165.04530425604892,0.0944222647842474
0.0995916277196722,148.486744409827,0.3162034180099592,29.934927673021125,163.2747809803966,0.09493886334733034
0.100225774313336,146.624156494516,0.3182168334448418,29.559429949294426,161.31967611221862,0.0955154081193134
0.100922783604348,144.453594287691,0.3204298379438049,29.121844608398504,159.03225312485793,0.09614872231503337
0.101677638466889,141.790904072985,0.3228265021323726,28.585046261113774,156.2078683552113,0.09683414385997596
0.102575091650493,138.611045079744,0.32567591599031526,27.943986688076393,152.82908573256935,0.09764843636004335
0.103020102130895,137.028925395951,0.3270888242655916,27.625031359823726,151.14565928512866,0.09805196506530642
0.103262731415661,136.13124415589,0.32785917224472366,27.444058821827422,150.18852825843942,0.09827190901995707