File: example/data/02 processed data/test_ID_089.csv
Strain,Stress_MPa,Displacement(mm),Force(kN),True Stress (MPa),True Strain
-1.31100985971402e-05,0.127291487468957,-4.1624563045920136e-05,0.025661963873741728,0.1272898186650057,-1.3110184535262549e-05
-0.000115154027225,0.161171327559162,-0.00036561403643937495,0.03249213963592706,0.16115276803172038,-0.00011516065795898581
-0.0002434087612382,0.839821481952778,-0.0007728228169312849,0.16930801076168003,0.8396170620461946,-0.00024343838995873217
-0.0004421129150387,2.74456984422362,-0.0014037085052478724,0.5533052805954819,2.743356434449263,-0.00044221067576877737
-0.0005991358468383,6.1364753814926,-0.0019022563137116024,1.237113436908908,6.132798799118307,-0.0005993154004414154
-0.0006680140098367,10.5032031910232,-0.0021209444812315226,2.1174457633102772,10.496186904143434,-0.0006682372306106783
-0.0006866768119463,15.4978736715547,-0.0021801988779295025,3.124371332185428,15.48723164106997,-0.0006869126824524255
-0.0006359337394119,20.4071711854303,-0.002019089622632782,4.1140857109827484,20.39419357674753,-0.0006361360310396754
-0.0005962049767541,25.8351296319943,-0.0018929508011942676,5.208362133810051,25.81972659913262,-0.0005963827776152266
-0.0005232060181023,31.5359428636464,-0.0016611791074748023,6.357646081311115,31.51944306855361,-0.0005233429381313233
-0.0004397573142712,37.5053249636836,-0.0013962294728110598,7.561073512678613,37.4888317227067,-0.0004398540358759387
-0.0003550913627651,43.6210264950252,-0.0011274150767791925,8.79399894139708,43.605537045281864,-0.0003551544226315316
-0.0002427072108961,49.8333644171669,-0.0007705953945951174,10.046406266500847,49.821269500279634,-0.00024273666905782164
-0.000130443006614,56.2694583592334,-0.00041415654599945,11.343922805221453,56.26211840190447,-0.00013045151504292808
-8.62068565625014e-06,62.6445530450227,-2.7370676958594196e-05,12.629141893876577,62.644013006022824,-8.620722814537357e-06
0.00010315359524,68.8948659853827,0.00032751266488699997,13.889204982653151,68.90197273850266,0.00010314827527378689
0.0002164769839995,75.2350383046357,0.0006873144241984125,15.167383722214556,75.25132495881896,0.00021645355623808865
0.0003300724780532,81.4719557368874,0.00104798011781891,16.424746276556498,81.49884738720931,0.0003300180161168221
0.0004451288261801,87.7035308565828,0.0014132840231218175,17.681031820687092,87.74257022632486,0.00044502978573366357
0.000556129272777,93.7962679355247,0.001765710441066975,18.90932761580178,93.84843078580087,0.0005559746902021834
0.0006601527592148,99.7515667029125,0.0020959850105069897,20.10991584730716,99.81741797490741,0.0006599349542330683
0.000759870950311,105.600603353697,0.002412590267237425,21.289081636105315,105.68084618452077,0.0007595823945478824
0.0008675037906856,111.371819041483,0.00275432453542678,22.452558718762972,111.46843451667702,0.0008671277267476828
0.0009687004501887,117.091919132998,0.0030756239293491224,23.605730897212396,117.20534612777558,0.0009682315626907552
0.0010740899755271,122.716994777749,0.003410235672298542,24.739746147194197,122.84880387166658,0.0010735135536050332
0.0011662848460991,128.30181010881,0.003702954386364642,25.8656449179361,128.451446565667,0.0011656052642673711
0.0012623254575215,133.69080747277,0.004007883327630762,26.952066786510432,133.85956878247947,0.001261529394597692
0.0013631361340268,138.962880782584,0.004327957225535089,28.014916765768934,139.15230610666717,0.0013622079074038587
0.0014631282682139,144.025333226662,0.004645432251579132,29.035507178495063,144.23606076304486,0.0014620589389660208
0.0015598087689761,149.001763886518,0.004952392841499118,30.03875559952203,149.2341781444211,0.0015585935308068586
0.0016549344253692,154.084260204265,0.00525441680054721,31.063386857179825,154.33925955088458,0.00165356653036939
0.0017628952363906,159.116993057984,0.0055971923755401545,32.07798580048957,159.3974996470747,0.0017613431604138793
0.0018537541158451,164.217135439226,0.005885669317808193,33.106174504547965,164.52155362993878,0.0018520380341525723
0.0019581504336711,169.223170061067,0.006217127626905742,34.115391084311106,169.5545344849093,0.0019562357561876834
0.0020513477634825,174.057056798578,0.006513029149056938,35.089902650593324,174.4141083527601,0.0020492466226155206
0.0021418819280021,178.916823810654,0.006800475121406667,36.06963168022784,179.30004252218959,0.0021395913690601207
0.0022453623333673,183.670627415369,0.0071290254084411765,37.027998486938394,184.08303452391343,0.002242845274465312
0.0023316538094414,188.479316383013,0.007403000844976445,37.99743018281543,188.91878489905835,0.002328939722752778
0.0024343506311989,193.156631442255,0.007729063254056507,38.94037689875861,193.62684240992667,0.0024313923996435527
0.0025232565340883,197.90339628309,0.008011339495730352,39.89732469067094,198.40275732087954,0.0025200784672491715
0.0026191335202296,202.56706038783,0.00831574892672898,40.83751937418653,203.09761056578614,0.002615709567254905
0.0027217880832316,207.234817079883,0.00864167716426033,41.77853912330441,207.7988663354417,0.0027180907254765532
0.0028133931726177,212.003827865593,0.008932523323061197,42.73997169770355,212.60027798747888,0.0028094429892573944
0.0029093136314001,216.45034814103,0.009237070779695317,43.63639018523165,217.08007008939796,0.002905089768874533
0.0029929325070104,220.683083098585,0.00950256070975802,44.48970955267474,221.34357267173803,0.002988462601044976
0.0030787521095175,224.6511409666,0.00977503794771806,45.289670018866566,225.34278614075643,0.003074022457372687
0.0031675936599738,228.43460098187,0.010057109870416813,46.052415557945,229.15818897565882,0.003162587404246441
0.0032645532567334,232.195359266803,0.010364956590128545,46.81058442818749,232.95337338309582,0.003259236171546325
0.0033581192263978,235.747961348589,0.010662028543813014,47.52678900787554,236.5396311101778,0.003352493335451876
0.0034539213823801,239.252203309911,0.010966200389056817,48.23324418727806,240.07856161070467,0.003447970295043942
0.003555706467984,242.719428231752,0.0112893680358492,48.93223673152121,243.58246727262105,0.003549399888882284
0.003656599973649,246.040139250697,0.011609704916335574,49.601692072940516,246.9398096173977,0.003649930864530632
0.0037647877319806,249.179242075365,0.011953201049038405,50.234535202393594,250.11734902899457,0.003757718655473663
0.003873817857292,252.276669930287,0.012299371696902098,50.85897665794586,253.25394379924109,0.003866333946208678
0.0039947137323614,255.405432527158,0.012683216100247445,51.489735197475056,256.42570411579396,0.003986756048864936
0.0041241095573949,258.445396756737,0.013094047844728807,52.10259198615819,259.5112538875662,0.0041156287268278545
0.0042638589254046,261.382652150011,0.013537752088159605,52.694742673442214,262.49715090432676,0.004254794436270809
0.0044243177211493,264.09302173394,0.014047208764649025,53.24115318156231,265.26145317002937,0.0044145592001117095
0.0046161662867233,266.7667589657,0.014656327960346478,53.78017860748511,267.9981986848559,0.0046055444666448
0.0048370097037025,269.267078904464,0.015357505809255436,54.284243107139936,270.5695263780125,0.004825348959237226
0.0050924092646646,271.293513817376,0.016168399415310106,54.692772385583005,272.67505142058303,0.0050794868010206485
0.0053860721332113,272.827624952887,0.017100779022945878,55.00204919050202,274.29709422081595,0.005371619120120008
0.0057094851495013,273.981965503047,0.018127615349666625,55.234764245414276,275.5462614663178,0.005693247814397313
0.0060641744736965,274.854844182923,0.019253753953986385,55.41073658727728,276.5216119129889,0.006045861366298317
0.0064430079164118,275.377753183189,0.020456550134607464,55.5161550417309,277.15201422695196,0.006422340467098253
0.0068295868528019,275.622862681566,0.02168393825764603,55.56556911660371,277.50525296086767,0.006806370868292392
0.0072280114021819,275.632509060881,0.02294893620192753,55.567513826673604,277.624783979185,0.0072020145230939645
0.0076272428281459,275.845613110148,0.02421649597936323,55.610475603005845,277.9495545844179,0.007598302475144633
0.0080361355561819,276.074705528215,0.025514730390877535,55.656660634488155,278.2932792854728,0.008004017772678777
0.0084498662967888,276.3042981055,0.02682832549230444,55.7029464980688,278.63903248171954,0.00841436601812383
0.0088550910201891,276.606899940731,0.02811491398910039,55.76395102805137,279.0562792165185,0.008816114625720956
0.0092689344312165,276.67420332172,0.029428866819112384,55.77751938965875,279.23867837111806,0.009226241467886403
0.0096896828715789,276.819826588846,0.030764743117263002,55.806877040311356,279.5021229210574,0.009643038962245722
0.0101077907854592,276.660338665954,0.03209223574383296,55.77472427505632,279.45676348782376,0.01005704870857479
0.0105314706592867,276.66158649796,0.03343741934323527,55.77497583798874,279.57523987871497,0.01047640102753695
0.0109498426687846,276.481101072415,0.0347657504733911,55.73858997619887,279.5085256300503,0.010890327204062017
0.011360119126663,276.348215326923,0.03606837822715502,55.71180020990768,279.4875639734776,0.0112960775304293
0.0117651849242961,276.422228955777,0.037354462134640116,55.72672135748464,279.6743875966278,0.01169651323476722
0.0121717032704504,276.566656212436,0.03864515788368002,55.7558378924271,279.9329434863544,0.012098223736702529
0.0125786265547372,276.851463450997,0.03993713931129061,55.813255031721,280.33387462087956,0.012500172840027766
0.0129874740902351,276.862050425679,0.04123523023649644,55.81538936581689,280.4577891321519,0.012903860027446682
0.0133949622286496,276.894816784599,0.04252900507596248,55.82199506377517,280.60381239673757,0.01330604288948064
0.0137979437061676,276.952675846466,0.04380847126708213,55.83365945064754,280.774053277068,0.013703618750807233
0.0141984954495633,277.148349504974,0.04508022305236348,55.87310726020276,281.0834390842744,0.014098640892730874
0.014597895025791,277.259137791825,0.04634831670688642,55.89544217883193,281.3065375802514,0.014492371464475259
0.0150004104745421,277.421054239167,0.047626303256671165,55.928084534616076,281.5824839270347,0.014889016902084681
0.0153947195962623,277.470848261006,0.048878234718132796,55.9381230094188,281.7424341661212,0.01527742319880741
0.0157860603086577,277.615451807909,0.0501207414799882,55.96727508447445,281.9979060727639,0.01566275642085178
0.0161671065596211,277.810426188565,0.05133056332679699,56.0065819196147,282.3018169521293,0.016037810592023874
0.0165511127037061,277.753673763783,0.05254978283426687,55.995140630778664,282.3508061221158,0.0164156358557658
0.0169303093656616,277.935257893588,0.05375373223597558,56.031747991347345,282.6407877933514,0.01678858902094885
0.0173155936130062,277.961504251655,0.05497700972129468,56.03703925713365,282.7745726993366,0.017167387131233794
0.0176998087917041,278.095724276618,0.056196892913660514,56.06409801416619,283.0179654221046,0.017544991332960395
0.0180789371862967,278.243340138268,0.05740062556649202,56.09385737187484,283.2736840071331,0.017917456562518863
0.018470442743048,278.381915613425,0.0586436557091774,56.12179418766648,283.5237528464628,0.018301935883700656
0.0188561608148789,278.600383645789,0.05986831058724051,56.16583734299106,283.85371728290096,0.01868058707862045
0.0192432389656088,278.540020048288,0.061097283715807936,56.15366804173487,283.90003221556265,0.019060429352677807
0.019626256367357,278.735997094372,0.062313363966358476,56.1931770142254,284.20654123215706,0.01943614482356072
0.0200041614462599,278.630357133529,0.06351321259187517,56.17187999811945,284.20412378145716,0.01980670713713149
0.0203805987828814,278.696175073243,0.06470840113564844,56.18514889476579,284.37616999973443,0.020175693759880303
0.0207554691802097,278.856780022564,0.06589861464716579,56.21752685254891,284.64458332601487,0.02054300920486895
0.0211359523193223,279.074145454665,0.0671066486138483,56.26134772366046,284.97264328655035,0.02091568636048072
0.0215138450306842,279.270094399455,0.06830645797242232,56.300851030930126,285.2782679320694,0.021285688811379013
0.0218941176561163,279.37792964088,0.06951382355816925,56.322590615601406,285.4946629029596,0.021657883338136105
0.0222757633938838,279.302868206157,0.07072554877558107,56.30745823036125,285.52455281355043,0.022031282580282967
0.0226525336853311,279.553502190455,0.07192179445092624,56.35798604159572,285.8860973156766,0.022399775007375847
0.0230280330278986,279.863229252679,0.07311400486357805,56.42042701734009,286.3079289392041,0.022766889358359885
0.0234021283807617,280.050586023483,0.0743017576089184,56.45819814233417,286.6043657907121,0.02313249710211265
0.0237657592830214,280.297757931514,0.07545628572359293,56.50802799899323,286.959246974085,0.023487749749709574
0.0241333930591279,280.447655505565,0.07662352296273107,56.53824734992191,287.2158090083917,0.023846784792656117
0.0245005141498724,280.523162023476,0.07778913242584487,56.553469463932764,287.39612372399915,0.02420519055113014
0.0248693878423343,280.596364657752,0.0789603063994114,56.56822711500281,287.57462447757473,0.02456517797564226
0.0252407902280852,280.697188908012,0.0801395089741705,56.58855328385522,287.78220777085227,0.024927502297317022
0.0256097234503966,280.843369006342,0.0813108719550092,56.61802319167855,288.03569001947216,0.025287287882693087
0.0259834893930656,280.867641232873,0.08249757882298327,56.622916472547196,288.16556260970265,0.025651654409608978
0.0263594940143139,281.048516790745,0.08369139349544663,56.659380985014195,288.45681348682245,0.02601806940797444
0.026738685059118,281.342636760521,0.08489532506269964,56.718675570921036,288.8653689185624,0.026387453641987822
0.0271272589867805,281.412941128118,0.08612904728302807,56.73284893142859,289.0469028643321,0.026765836596751892
0.0275056482982671,281.50480785628,0.08733043334699804,56.75136926382606,289.24778009544616,0.027134164500410802
0.0278850821224024,281.458508627748,0.08853513573862762,56.742035339354,289.3070022548817,0.027503372965574736
0.0282547622530663,281.37033934766,0.0897088701534855,56.724260412488256,289.32039139099265,0.027862959533247637
0.0286277158966507,281.408161357776,0.09089299797186597,56.731885329727646,289.46423425212527,0.028225599257814944
0.0290027481004308,281.740132831509,0.09208372521886779,56.79881077883222,289.9113709338032,0.028590127499882725
0.0293745781098976,282.190032714648,0.09326428549892488,56.889510595273045,290.479245872459,0.02895141209894665
0.0297515641891137,282.523321413059,0.094461216300436,56.9567015968727,290.92883214500125,0.02931757333179595
0.0301208280462,282.57890775932,0.095633629046685,56.967907804278916,291.09041844942146,0.029676104144125637
0.0304849959899988,282.55197238757,0.09678986226824618,56.96247763333411,291.16556813277134,0.03002956131030693
0.0308408615570543,282.65151790379,0.09791973544364739,56.98254600940407,291.36873423635205,0.03037483963618441
0.031197043658167,282.860869209899,0.09905061361468022,57.024751232715644,291.6852920958273,0.030720305744013226
0.0315530928575852,283.029024457397,0.10018106982283301,57.05865133061123,291.959465547493,0.031065523709729186
0.0319250531994586,283.238379487397,0.10136204390828105,57.10085730465924,292.2807798206606,0.03142604155346111
0.0322987218053335,283.416173509963,0.10254844173193385,57.136700579608544,292.5701536532934,0.031788084287859446
0.0326737475146993,283.692203725605,0.10373914835917027,57.19234827108197,292.961491162024,0.032151310160417876
0.0330471021734754,283.942847316916,0.1049245494007844,57.24287801909027,293.3263356036257,0.03251278655535094
0.0334204393770009,283.985180742535,0.10610989502197785,57.251412437695066,293.4760902595076,0.032874115441559576
0.0337954965682053,284.080093472574,0.1073007016040518,57.270546844070914,293.6807212966218,0.03323697757782501
0.034165608477548,284.271679847967,0.1084758069162149,57.30917065735015,293.98399476290746,0.03359492619919065
0.0345393653743468,284.346661688435,0.10966248506355109,57.3242869963885,294.1678149294677,0.03395627004047297
0.0349105548591804,284.35759348289,0.11084101167789775,57.32649084615063,294.284674849799,0.03431500255695955
0.0352783732618396,284.254992342134,0.11200883510634073,57.30580645617422,294.28304606352117,0.03467035022743857
0.0356546082665104,284.239130742089,0.11320338124617052,57.30260875760514,294.3735656027116,0.03503369854644828
0.0360336225142994,284.494152439871,0.1144067514829006,57.354021131878,294.7455073364149,0.035399597475048
0.0364177153223029,284.794348281756,0.11562624614831171,57.414540613602014,295.1659077828818,0.035770262692019536
0.0367990485669095,285.050828899825,0.11683697919993766,57.46624710620472,295.5404281965474,0.03613812895236322
0.0371792818711443,285.188537068292,0.11804421994088314,57.49400907296768,295.7916420743733,0.03650479942612335
0.0375539849391743,285.260860567047,0.11923390218187839,57.50858949031668,295.9735426285178,0.0368660054453242
0.0379369575154831,285.210611542077,0.12044984011165884,57.49845928688273,296.03063439511374,0.03723504832845263
0.0383178351375036,285.418187365885,0.12165912656157392,57.54030657296242,296.35479441461604,0.0376019374286157
0.0386883651580198,285.463365671984,0.12283555937671287,57.54941451947197,296.50747660233907,0.03795872983914809
0.0390582944359229,285.672021455425,0.1240100848340552,57.59147952541368,296.8298833815363,0.038314816833781296
0.0394275619289423,285.842434491673,0.1251825091243918,57.62583479352127,297.1125047795131,0.03867014039374078
0.0398052847077037,285.863351132697,0.12638177894695923,57.63005158835172,297.2422232120323,0.0390334693816678
0.0401869626987956,285.871413684916,0.12759360656867602,57.631676998879065,297.3597175233237,0.03940046882202801
0.0405673401520485,285.882407080035,0.12880130498275397,57.63389326733506,297.4798959315372,0.03976608378864756
0.0409430940944515,286.129539902859,0.1299943237498835,57.68371524441637,297.8445685783039,0.04012712348395959
0.0413154840241431,286.167222251422,0.13117666177665432,57.69131200588668,297.99035955058406,0.04048480234053874
0.0416892170163638,286.444992103004,0.13236326402695506,57.74731040796561,298.38665954203674,0.04084364262164259
0.0420638453242675,286.373910412313,0.1335527089045493,57.73298033912231,298.4198982848022,0.041203213358416084
0.0424474315078738,286.382213171136,0.1347705950374993,57.734654175301024,298.5384025497911,0.04157124800730414
0.0428297598610744,286.546019320961,0.1359844875589112,57.767677495105744,298.8187165176245,0.04193794108683054
0.0432106135010905,286.578991151034,0.13719369786596233,57.77432461604846,298.9622451751938,0.04230308612343793
0.0435919198488947,286.689571181637,0.13840434552024067,57.79661755021802,299.18691999010093,0.04266853167562031
0.0439761445158623,286.776594238741,0.13962425883786278,57.81416139853019,299.3879231907507,0.04303663911878834
0.0443728458418693,286.847226355671,0.14088378554793501,57.82840083330328,299.575454110919,0.04341655773642373
0.0447622798593232,286.923741891529,0.14212023855335115,57.843826365332255,299.76710272436185,0.04378937615029629
0.0451535927867405,287.09073509733,0.14336265709790108,57.877492195621734,300.05391324276087,0.044163853359749525
0.0455413708723615,287.313015752391,0.14459385251974777,57.92230397568203,300.3976443592273,0.0445348095219905
0.0459187872431172,287.526211193449,0.14579214949689712,57.96528417659932,300.7290661120606,0.04489572136952248
0.0463062314125654,287.637081875296,0.14702228473489515,57.987635706059685,300.9564711514485,0.04526608705239346
0.046692100588056,287.484463592184,0.1482474193670778,57.956867860184296,300.9077170837336,0.045634810881708246
0.0470769867870712,287.507405716885,0.14946943304895105,57.96149299252402,301.0423880570039,0.046002460022839683
0.0474697707789393,287.559844733887,0.15071652222313228,57.97206469835162,301.210244648632,0.046377513952816155
0.047859925452942,287.59789875179,0.15195526331309084,57.97973638836087,301.36231274647344,0.04674991804675257
0.0482491502502128,287.586991162626,0.15319105204442562,57.97753741838541,301.4628191092382,0.04712129643183375
0.0486400540861055,287.671086631322,0.15443217172338494,57.99449106487452,301.6634238440783,0.047494138105693154
0.0490354706251486,287.904259338473,0.15568761923484678,58.04149868263617,302.0217801901199,0.04787114259382136
0.0494245507166832,288.232666344587,0.15692294852546915,58.107705535068746,302.4784363805399,0.048241967000325396
0.0498230112596842,288.506844722519,0.15818806074949732,58.16297989605983,302.88112449562504,0.04862158925641711
0.0502218012051879,288.492453981117,0.15945421882647157,58.16007872259319,302.9810646541535,0.0490013811046006
0.050614548458245,288.523630770639,0.16070119135492786,58.16636396336082,303.12712406162825,0.0493752772033572
0.0510094272647724,288.512237761353,0.16195493156565235,58.164067132688764,303.2290817684374,0.04975106165931664
0.0513994886050127,288.553886976796,0.16319337632091532,58.172463614522066,303.3854092023919,0.050122123008772994
0.0517882669539858,288.705587805864,0.1644277475789049,58.203046501662186,303.65714985826145,0.05049182690456045
0.0521739334256134,288.739079478579,0.16565223862632253,58.20979842288153,303.8037329886673,0.05085843660494168
0.0525657218267304,288.683554451344,0.16689616679986902,58.198604577390945,303.8584138705851,0.051230728165719136
0.0529550300087316,288.692777324134,0.16813222027772282,58.200463908545416,303.9805120106376,0.05160052569547357
0.0533501064311146,288.504236027468,0.16938658791878883,58.162453983137546,303.89596772536083,0.051975662630935796
0.0537419977687631,288.37989842643,0.17063084291582284,58.137387522768286,303.87801028421933,0.05234763625409744
0.0541376028468051,288.353006646108,0.1718868890386062,58.131966139855365,303.9637471995971,0.05272299458345472
0.0545260727651677,288.500258145382,0.17312028102940744,58.16165204210902,304.2310442137868,0.053091445870637584
0.0549178450640136,288.622990827707,0.17436415807824318,58.186394950865726,304.4735435198952,0.05346289191861163
0.0553142491840708,288.840706524598,0.17562274115942478,58.23028643535895,304.81771333980265,0.05383858909978938
0.0557230079142258,288.905353723105,0.1769205501276669,58.243319310577974,305.0040290350798,0.054225847765062944
0.0561315086621842,289.094516048976,0.17821754000243484,58.28145443547356,305.3218273807691,0.05461271224824304
0.0565421401397456,289.127217380626,0.1795212949436923,58.288047023934205,305.47508902397607,0.055001443828215354
0.056953841472687,289.304015575328,0.1808284466757812,58.32368953998612,305.78099061581696,0.055391036561516456
0.0573609804988014,289.372698407523,0.18212111308369444,58.33753599895664,305.9714001177624,0.055776162775376247
0.0577654899099285,289.458436988283,0.18340543046402297,58.35482089683785,306.17914540947334,0.05615865471779008
0.0581669539997462,289.481763205724,0.1846800789491942,58.35952346227396,306.3200356098768,0.0565381224988062
0.0585759443302129,289.523219514235,0.18597862324842593,58.36788105406978,306.48231550280485,0.056924556142569895
0.0589847669082033,289.744652405208,0.18727663493354546,58.41252192488994,306.8351731902276,0.057310682104295595
0.0593950641419893,289.865300616173,0.188579328650816,58.43684460422048,307.0818687388076,0.05769805101038382
0.0598033101019018,289.944535953589,0.1898755095735382,58.452818448243555,307.2841789495735,0.058083334398597225
0.0602111218150162,290.018751783456,0.19117031176267643,58.46778035954473,307.4811061757286,0.058468059815561226
0.0606196727858698,289.970802010725,0.1924674610951366,58.45811368536216,307.5487371460714,0.05885333428153703
0.0610300011103652,289.927419511861,0.1937702535254095,58.44936777359118,307.6216902465952,0.059240135490671426
0.0614433636673531,289.96066353019,0.19508267964384607,58.4560697676863,307.77682202870244,0.05962964573760663
0.0618460015783371,290.030806659573,0.19636105501122028,58.470210622569915,307.96805238600734,0.06000890437507798
0.0622495379593002,290.175374344469,0.19764228302077813,58.49935546784496,308.23865732457915,0.060388865048509696
0.0626542200707231,290.174161404381,0.19892714872454584,58.499110939123206,308.35479717184865,0.060769759585296415
0.0630654470387149,290.280829487671,0.2002327943479198,58.520615224714476,308.58751976607994,0.061156665704183474
0.0634800043887248,290.362337227761,0.20154901393420122,58.53704718511662,308.7945396692996,0.06154655377827384
0.0638917914901968,290.499329501686,0.20285643798137484,58.5646648275399,309.05985209024976,0.06193368602042614
0.0643147752994504,290.644681222067,0.204199411575755,58.59396773436871,309.3374285868446,0.062331188613852666
0.0647387700822224,290.773893865596,0.2055455950110561,58.620017003304156,309.59823812647335,0.0627294827660095
0.0651612187069333,290.840240988972,0.2068868693945132,58.63339258337676,309.7917455408316,0.06312616677227653
0.0655843010802262,290.841224706368,0.20823015592971816,58.633590900803796,309.91584315405214,0.06352328822570602
0.0659998071059484,290.852401370114,0.20954938756138614,58.63584411621498,310.0486037568434,0.06391314479236855
0.0664264729431484,290.797783063355,0.21090405159449618,58.62483306557237,310.11445413194053,0.06431331416458615
0.0668569434801045,290.888589092848,0.2122707955493318,58.64313956111816,310.3365110528359,0.06471688974154385
0.0672931779199178,290.948051055018,0.21365583989573902,58.655127092691636,310.5268700201167,0.06512570301247031
0.067729514072217,291.079244339069,0.21504120717928896,58.68157565875632,310.7939001146623,0.065534444483941
0.0681620496601793,291.062279372076,0.21641450767106926,58.67815552141052,310.9016809128404,0.06593946091943763
0.0685983241930754,291.099815847387,0.2177996793130144,58.68572287483322,311.0687753874306,0.06634781231372315
0.0690229766097617,291.134425344507,0.21914795073599339,58.69270014945261,311.2293899753573,0.06674512536642611
0.0694555288403373,291.096497344322,0.2205213040680709,58.68505386461532,311.3147585109418,0.06714966741384196
0.0698782259026001,291.162261584905,0.22186336724075528,58.69831193551685,311.508163874247,0.06754483442957869
0.0702994345863852,291.117688051193,0.22320070481177298,58.68932591112051,311.5830969192875,0.067938454732229
0.0707204087115107,291.179696935636,0.22453729765904645,58.70182690222422,311.77204411141804,0.06833170109271311
0.0711457851551244,291.24359428648,0.22588786786751996,58.71470860815437,311.96434847339214,0.06872890279506448
0.071573439547784,291.243448710512,0.22724567056421419,58.71467926003922,312.08874408048194,0.06912807259146866
0.0720005780711883,291.341208182975,0.22860183537602285,58.73438756968776,312.3179435881076,0.06952660189397634
0.0724328846289837,291.419425662114,0.22997440869702324,58.750156213482185,312.5277752997426,0.069929791427409
0.0728748022377115,291.553073522204,0.23137749710473401,58.77709962207632,312.79994609693154,0.07034177672693857
0.0733242344066876,291.667389976561,0.23280444424123312,58.800145819274704,313.05367804798914,0.07076059359142498
0.0737588986268795,291.697477809655,0.2341845031403424,58.80621152642645,313.2127625051338,0.07116548171097897
0.0741979905224494,291.749143039695,0.23557861990877682,58.81662723680252,313.39634318988703,0.07157432781390068
0.074633711277125,291.797888457687,0.23696203330487184,58.826454313069696,313.57584781611274,0.07197986982101298
0.0750740631327358,291.830864465403,0.23836015044643616,58.83310227622525,313.7397932083595,0.07238955514383867
0.0755103776796377,291.891007539722,0.23974544913284968,58.84522712000796,313.9318077603364,0.07279531884658687
0.0759585544271572,292.027873811576,0.24116841030622407,58.87281936041372,314.2098889587396,0.07321194280737384
0.0764034732909968,292.099931458949,0.24258102769891482,58.88734618212412,314.41738077047484,0.07362536663147685
0.0768503727193424,292.126545762464,0.24399993338391213,58.89271162571275,314.57657968552337,0.07404045882842367
0.0772982170139499,292.215105018414,0.2454218390192909,58.91056517171227,314.8028116208815,0.07445625586600416
0.0777458304159823,292.297253502425,0.24684301157074381,58.92712630608889,315.02214620428197,0.07487166585171028
0.0782064550440894,292.30903788012,0.24830549476498384,58.92950203663219,315.1694915100726,0.07529897088830333
0.0786540222420672,292.301048428817,0.24972652061856335,58.92789136324951,315.29170159331676,0.07571398818693287
0.0790928525436036,292.322702979148,0.2511198068259414,58.93225692059624,315.4433394210254,0.07612073683082106
0.0795378196824735,292.392432240312,0.25253257749185337,58.946314339646904,315.6486887923618,0.07653300480319569
0.079985126858907,292.411861562469,0.25395277777702974,58.95023129099376,315.8004614045922,0.07694726961436331
0.0804386604887665,292.410855486081,0.2553927470518336,58.95002846599393,315.9319930137557,0.07736712579182083
0.0808871058191157,292.385032008676,0.25681656097569233,58.944822452949076,316.03521103268724,0.07778209825342283
0.0813420273796028,292.493766882668,0.2582609369302389,58.96674340354587,316.28580287680114,0.07820288766950727
0.0818003142874502,292.54156413234,0.25971599786265437,58.97637932907975,316.47155602050765,0.07862661097784114
0.0822635965886963,292.620677019464,0.26118691916911074,58.99232848712394,316.69270634730435,0.07905477052155434
0.0827327102421546,292.643576006489,0.26267635501884085,58.99694492290819,316.8547721844618,0.07948813261027486
0.0832015986036347,292.674022162371,0.2641650755665402,59.00308286793399,317.0249686760359,0.07992109899054772
0.0836737932415192,292.727298554118,0.26566429354182347,59.01382338851019,317.2209020094838,0.08035692898532816
0.0841499672344575,292.835715426609,0.26717614596940253,59.035680230004374,317.47783128483707,0.08079623960575597
0.0846186422138722,292.855119010109,0.26866418902904426,59.03959199243798,317.63612154612633,0.08122844337767393
0.0850937339617201,292.925737936955,0.27017260532846127,59.05382876809013,317.8518827515028,0.08166637400908627
0.0855842889201053,292.911994010355,0.27173011732133434,59.05105799248757,317.98065873390135,0.082118357178921
0.0860612042008685,292.885874452336,0.2732443233377575,59.045792289590935,318.0919855011285,0.0825575773830851
0.0865310571616811,292.927727730738,0.27473610648833746,59.05422991051679,318.27507368324785,0.08299010490009173
0.0869974822037255,292.91329463399,0.2762170059968284,59.05132019821239,318.3960137711452,0.08341929185646857
0.0874710755989126,292.956434407146,0.27772066502654746,59.060017176480635,318.5816488283613,0.08385488647656637
0.0879454434381131,292.963137363695,0.27922678291600905,59.06136849252091,318.727910390166,0.08429100327771041
0.0884121898410942,292.99122967635,0.28070870274547405,59.06703190275215,318.89522589627103,0.08471992764473518
0.0888794909820117,293.053769152649,0.28219238386788714,59.07963986117404,319.1002389852964,0.08514917757225625
0.0893585156037478,293.11637318682,0.28371328704189924,59.09226083446291,319.3088171939484,0.08558900520175312
0.089847895433311,293.148333339023,0.2852670680007624,59.098704001147034,319.4870941393169,0.08603814102965024
0.0903322891903945,293.159627633909,0.28680501817950255,59.10098093099606,319.6414078962837,0.08648250225123222
0.0908137889408162,293.175924052972,0.2883337798870914,59.10426628907915,319.8003405424474,0.0869240130359256
0.0913029345342711,293.176164744621,0.2898868171463107,59.1043148125156,319.94400892130784,0.08737233515947243
0.0917996012704274,293.217107250077,0.291463734033607,59.112568821615525,320.1343207813022,0.0878273451615951
0.0922982317373081,293.229466436921,0.29304688576595317,59.11506043368327,320.2940276823231,0.08828394602260779
0.0927942517496363,293.272840549207,0.29462174930509527,59.12380465472013,320.48687434646104,0.08873794970858148
0.0933001835247495,293.293303423181,0.29622808269107964,59.12792997011329,320.65762245914385,0.08920081332140839
0.0938037254727787,293.281562949846,0.29782682837607233,59.12556309068895,320.7924661670208,0.08966127791557292
0.0943162038200425,293.252871951331,0.2994539471286349,59.11977898538832,320.9113695931055,0.09012969680776774
0.0948236572060066,293.263669967354,0.30106511162907096,59.12195586541857,321.07200367931387,0.090593306652061
0.0953281086379032,293.304282235669,0.3026667449253426,59.13014329871088,321.26442471659306,0.09105396097628105
0.0958300579602833,293.318253350902,0.30426043402389946,59.13295987554185,321.426958570328,0.09151211989772462
0.0963485827851714,293.323704563795,0.3059067503429192,59.13405884006107,321.58502779581295,0.09198518794511869
0.0968552633279016,293.360794876303,0.30751546106608757,59.141536247062675,321.77433191412985,0.09244723396299556
0.0973572693399588,293.316318007287,0.30910933015436914,59.13256971026907,321.8727937813274,0.09290480679456223
0.0978647715525014,293.298612345892,0.3107206496791919,59.12900024893184,322.0022140397884,0.0933671766251583
0.0983685718521103,293.288076285248,0.3123202156304502,59.12687617910599,322.1384054906806,0.09382596240032078
0.0988957192461217,293.300227372309,0.3139939086064364,59.12932583825749,322.30636431334455,0.09430578397322917
0.0994113908034506,293.3348565685,0.3156311658009556,59.136307084209605,322.4956826311053,0.09477493731802798
0.0999244018027275,293.342706514716,0.3172599757236598,59.13788963336674,322.654800986392,0.09524145180872613
0.100440088087669,293.348302223961,0.318897279678349,59.13901772835054,322.8122315397038,0.09571017987332862
0.10095489636726,293.323470396778,0.32053179596605047,59.134011631990454,322.9359109527698,0.09617789084079327
0.101484036482425,293.340705705727,0.3222118158316994,59.13748627027456,323.11010458534724,0.09665839462907422
0.102012738416894,293.375410944393,0.3238904444736384,59.144482846389636,323.3034399990122,0.09713827002588667
0.102549574124558,293.378474486109,0.32559489784547163,59.14510045639957,323.4643121019719,0.09762529252030282
0.103085194065148,293.315615787874,0.32729549115684486,59.1324281428354,323.5521129637054,0.098110975788307
0.10362386809637,293.24237963858,0.32900578120597473,59.11766373513773,323.62928930651384,0.09859919061567878
0.104163502478294,293.231798406201,0.3307191203685835,59.115530558690125,323.77584956619995,0.09908803696008929
0.10471876472662,293.180307275881,0.3324820780070185,59.10514994681761,323.8817868959821,0.09959079101653268
0.10527171290939,293.149649609258,0.3342376884873132,59.098969361226416,324.0100153624121,0.10009119877837988
0.105840272121048,293.139547288015,0.33604286398432737,59.09693273326383,324.16551674241936,0.10060547325026388
0.106400903277512,293.024783747706,0.3378228679061006,59.073796403537536,324.2028854211595,0.10111231777942299
0.106964510201104,292.908597602869,0.33961231988850515,59.05037327673839,324.23942227915217,0.10162159377365466
0.107528515925371,292.795118382437,0.3414030380630529,59.027495865899304,324.2789429322938,0.10213097061955818
0.108091537146048,292.625334151754,0.34319063043870235,58.9932673649936,324.255656328093,0.10263919966543225
0.108665576508278,292.498767004079,0.34501320541378266,58.96775142802233,324.2833141485377,0.1031571087963202
0.109231202455613,292.314863140635,0.3468090677965713,58.93067640915202,324.2447671371345,0.10366716495850271
0.109811240746543,292.138303306239,0.348650689370274,58.89508194653778,324.218372861887,0.1041899474820343
0.110394243730505,292.046609598182,0.35050172384435335,58.87659649499349,324.28687419883136,0.10471512679668615
0.110985569399916,291.902100556744,0.35237918284473324,58.847463472239596,324.29902139606577,0.10524752173417774
0.111585494580523,291.750258970861,0.3542839452931605,58.81685220852558,324.3053559121202,0.1057873696651614
0.112181853016205,291.57425440301,0.3561773833264508,58.78136968764682,324.28359455375806,0.10632371934276848
0.112767452223422,291.30940768868,0.3580366608093648,58.72797659003789,324.1596274024466,0.10685011265821161
0.113343424840971,291.010775990468,0.3598653738700829,58.667772439678345,323.9949340068563,0.1073675825078366
0.11393894459518,290.674845254103,0.3617561490896965,58.60004880322717,323.79403034272275,0.1079023326379252
0.114530604304104,290.370473663226,0.3636346686655302,58.53868749050636,323.6267794839442,0.1084333335870908
0.115138590203387,290.061948040839,0.3655650238957537,58.47648872503314,323.4592718099093,0.10897869333449155
0.115754064483137,289.681243556867,0.36751915473395996,58.39973870106439,323.21302490310387,0.10953046734663177
0.116371836925911,289.280546739127,0.36948058223976743,58.318958222607996,322.94465535009107,0.11008399567418493
0.117008566316954,288.730601962878,0.37150219805632895,58.208089355716204,322.51455575038545,0.11065418909700676
0.117644552768165,288.239874576794,0.37352145503892387,58.10915871468167,322.14972571133296,0.1112233928476477
0.118252583767336,287.694843318026,0.3754519534612918,57.999280412914054,321.7155018769215,0.11176727387349972
0.118855034805428,286.742874548122,0.3773647355072339,57.8073635089014,320.82370888274755,0.11230587205952706
0.119445875754449,286.182177694269,0.37924065552037556,57.69432702316463,320.3654585342763,0.11283380908529211
0.120081480818268,285.534722680251,0.3812587015980009,57.563800092338596,319.822155004729,0.11340143339139352
0.120739285690625,285.095511114821,0.38334723206773436,57.47525504074792,319.5177394804282,0.11398854406180857
0.121428678326865,284.425096436263,0.38553605368779637,57.34009944155062,318.96245997950956,0.11460347806231831
0.122130571059576,283.583561213493,0.3877645631141538,57.17044594064019,318.2177834876051,0.11522917382301806
0.122826916411555,282.712388498074,0.3899754596066871,56.994817521211715,317.437079408638,0.11584953779712245
0.123533471151672,281.756381794433,0.3922187709065586,56.802086569757705,316.5627256566351,0.11647860405677421
0.124235731041651,280.683557496114,0.39444844605724194,56.585805191216586,315.55448445301505,0.1171034546082836
0.124935341502881,279.552067506751,0.3966697092716472,56.357696809360995,314.47800052854336,0.11772555978501596
0.125668942479342,278.288032398381,0.3989988923719108,56.10286733151361,313.2601951345424,0.11837747447980553
0.126381573857872,277.055697505246,0.4012614969987435,55.85442861705759,312.07043260224947,0.11901034785200214
0.127114342644864,275.488500491594,0.40358803789744313,55.538481699105354,310.5070401378022,0.11966068744876143
0.12787820623418,274.024330284453,0.4060133047935215,55.24330498534573,309.06607010575135,0.1203381740496929
0.128633181320843,272.411561734348,0.40841035069367654,54.91817084564457,307.4527275488164,0.12100732654677124
0.129441403431699,270.596603107953,0.4109764558956443,54.55227518656333,305.6230071780969,0.1217231772550051
0.130274722903385,268.734609534243,0.4136222452182473,54.17689728210339,303.7439363258659,0.1224607207895662
0.130700718220977,267.642338915301,0.41497478035160196,53.95669552532468,302.623384837873,0.12283754515915865
0.130922758921118,267.06327010758,0.4156797595745496,53.83995525368813,302.0279302365601,0.12303390030235425