File: example/data/02 processed data/test_ID_062.csv
Strain,Stress_MPa,Displacement(mm),Force(kN),True Stress (MPa),True Strain
1.14248241532508e-05,0.464741622721054,3.6273816686571285e-05,0.0936919111405645,0.46474693231237024,1.1424758890365865e-05
1.19208375690259e-05,0.507515449057921,3.784865928165723e-05,0.10231511453007688,0.507521499067153,1.192076651644875e-05
1.03900213592386e-05,0.536670838304791,3.298831781558256e-05,0.10819284100224588,0.5366764143262639,1.0389967383376421e-05
9.93321261133157e-06,0.558732492714701,3.153795004097773e-05,0.11264047053128373,0.558738042723344,9.933163277305257e-06
4.80811539194176e-06,0.606716686220694,1.526576636941509e-05,0.1223140839420919,0.6067196033845316,4.808103833102298e-06
2.54570348331946e-06,0.743202284287908,8.082608559539285e-06,0.14982958051244227,0.743204176260552,2.545700243049981e-06
-2.85978119301345e-06,1.46905418826863,-9.079805287817704e-06,0.29616132435495585,1.469049987095091,-2.8597852821474035e-06
-4.43304876887232e-07,2.8779979497038,-1.4074929841169615e-06,0.5802043866602861,2.877996673873273,-4.433049751777629e-07
5.18279025295493e-06,5.04018117901485,1.6455359053131903e-05,1.0161005256893936,5.040207301216737,5.182776822355643e-06
2.90497548906066e-05,7.98810291238228,9.223297177767595e-05,1.6104015471362678,7.988334964813927,2.904933295475051e-05
5.76950900461865e-05,11.7723875854755,0.00018318191089664214,2.3733133372318607,11.773066794437302,5.769342574846798e-05
0.0001010422857943,16.3971219399133,0.0003208092573969025,3.3056597830865218,16.39877874259456,0.00010103718136640815
0.0001683371841576,21.8621948236321,0.0005344705597003799,4.4074184764442315,21.86587504394822,0.00016832301704374598
0.0002395992375866,27.6455128138016,0.000760727579337455,5.573335383262402,27.652136657594475,0.0002395705382733456
0.0003235207173081,33.6375073832691,0.0010271782774532174,6.781321488467052,33.64838981378619,0.0003234683957651798
0.0004169311174191,39.7918296442285,0.0013237562978056425,8.022032856276466,39.80842009622622,0.0004168442257918463
0.0005046593948404,46.1443984620984,0.00160229357861827,9.302710729959038,46.16768566630156,0.0005045320971141402
0.0006057283511832,52.6072057647634,0.0019231875150066597,10.605612682176302,52.63907144077164,0.0006055449718137153
0.0007070508336428,59.1878647072509,0.00224488639681589,11.932273524981781,59.229713536333705,0.0007068009909629
0.000801031626132,65.7499475514718,0.0025432754129690997,13.255189426376717,65.80261533887706,0.0008007109715238512
0.0009103161061955,72.3962318902945,0.002890253637170712,14.595080349083371,72.4621353462121,0.0009099020197694495
0.0010115621965657,79.1367670883551,0.0032117099740960973,15.953972245012388,79.2168188503001,0.0010110509122950352
0.001119534223553,85.9277013726963,0.003554521159780775,17.323024596735575,86.02390037513429,0.001118908012447121
0.0012311744993506,92.6787427246945,0.003908979035438155,18.684034533298412,92.792846429369,0.0012304172255203387
0.0013406618778211,99.4731790603482,0.004256601462081992,20.053792898566197,99.60653895938009,0.0013397639931027412
0.0014535709800009,106.238228617597,0.004615087861502857,21.41762688930756,106.39265342368225,0.0014525155683241008
0.0015696577083476,113.090829457659,0.00498366322400363,22.799111218664052,113.26834334986063,0.0015684270832919034
0.0016726752745832,119.889072370826,0.005310743996801659,24.169636989958523,120.0896078578734,0.0016712779113024893
0.0017823568039038,126.624430623468,0.0056589828523945646,25.527485213691147,126.85012053893017,0.001780770290890602
0.001892357462126,133.323093468879,0.006008234942250049,26.877935643326005,133.57538841967855,0.0018905692093971968
0.0020046923510829,139.948060973625,0.006364898214688207,28.213529092282798,140.22861378100768,0.0020026856368204945
0.0021174887106326,146.510600607148,0.006723026656258504,29.536537082401036,146.82083514992163,0.0021152499911644943
0.0022306410620245,153.024416048495,0.007082285371927787,30.849722275376596,153.3657585944251,0.0022281568757834013
0.0023422770913782,159.456009415549,0.007436729765125784,32.14633149817468,159.82949957348563,0.0023395382363296173
0.0024679995761239,165.817561756351,0.007835898654193383,33.428820450080366,166.22679942847958,0.0024649590667929627
0.0025921892800519,172.128867273973,0.008230200964164783,34.701179642432955,172.57505787850806,0.0025888353521804773
0.0027083538826665,178.345769669256,0.008599023577466136,35.954507165322006,178.82879312699686,0.002704692900955844
0.0028255336665219,184.565717326551,0.008971069391207032,37.20844861303269,185.08721397454295,0.0028215493497212598
0.0029426759318445,190.701920278545,0.009342996083606288,38.445507128154674,191.2630942295052,0.002938354736201284
0.0030545953552516,196.726971167141,0.00969834025292383,39.66015738729562,197.32789245952085,0.0030499395575021384
0.003172427317464,202.546466870001,0.0100724567329482,40.83336772099221,203.18903081455522,0.0031674057874115447
0.0032896511675648,208.21826736533,0.01044464245701824,41.976802700850534,208.9032328316767,0.0032842521026159705
0.0034012519564258,213.634265851743,0.010798974961651915,43.068667995711394,214.3608898164308,0.0033954807814345917
0.0035242072625285,218.843186521414,0.011189358058527986,44.11878640271706,219.61443526870767,0.003518011795919338
0.0036473308055048,223.811531492222,0.011580275307477739,45.12040474883195,224.6278461856608,0.0036406954238957564
0.0037740011003946,228.487531309983,0.011982453493752855,46.06308631209257,229.34984350457333,0.0037668974254832796
0.0039084870748731,232.980815407088,0.012409446462722093,46.968932386068936,233.8914179128,0.0039008687834761425
0.0040457757856202,237.276157473484,0.012845338119344133,47.834873346654376,238.23612360589524,0.004037613642161812
0.0041885639486702,241.379648033193,0.013298690537027884,48.66213704349171,242.39068212488758,0.004179816332819449
0.0043468224892985,245.323262337328,0.013801161403522737,49.45716968720532,246.38963901120394,0.004337402345019404
0.0045149406667076,249.117658802929,0.014334936616796629,50.22212001467048,250.2424102514533,0.004504778897139647
0.0047055890775696,252.79785794312,0.014940245321283479,50.964048161333,253.98742078229012,0.004694552402448653
0.0049230197625364,256.3075224107,0.01563058774605307,51.67159651799712,257.56932940881467,0.0049109413261123605
0.0051659007271576,259.488298581101,0.01640173480872538,52.31284099394996,260.82878937143,0.005152603238008245
0.0054364452733398,262.324960144269,0.017260713742853866,52.884711965084634,263.75107543392437,0.005421721145239522
0.0057363201297887,264.736807656913,0.01821281641207912,53.37094042363367,266.25542273577133,0.00571993009459457
0.0060600603164553,266.746680584118,0.019240691504745576,53.776130805758186,268.363181557672,0.006041771999280138
0.0064041709930907,268.322603674766,0.02033324290306297,54.093836900832834,270.0409875100105,0.006383751423943042
0.0067628759205313,269.429556415734,0.021472131047686877,54.31699857341198,271.2516750750974,0.0067401102584338955
0.0071264963771857,270.207620859523,0.022626625997564594,54.473856365279836,272.1332544906664,0.007101222905044603
0.0074979251773478,270.746632235455,0.023805912438079266,54.58252105866774,272.77667022597535,0.007469955459258101
0.0078725643660104,271.177536809999,0.02499539186208302,54.669391420895806,273.31239942315193,0.007841737416890043
0.0082548113170795,271.521651417233,0.026209025931727414,54.73876492571417,273.7630114181841,0.008220926708459106
0.0086383309905095,271.835313404357,0.02742670089486766,54.801999182318376,274.18351681645277,0.008601234093126775
0.0090189592057847,272.133749081427,0.02863519547836642,54.86216381481569,274.5881122629097,0.00897853128987068
0.0094015639473363,272.397164245371,0.02984996553279275,54.9152683118668,274.95812360409695,0.00935764430595957
0.0097840207357035,272.660579409315,0.031064265835858612,54.968372808917906,275.32829617206465,0.009736467130213054
0.0101683338003399,272.928562466276,0.03228445981607918,55.02239819320124,275.70379119308,0.010116984094794656
0.010548418563105,273.182841844187,0.03349122893785837,55.0736609157881,276.064488804218,0.010493172164501022
0.0109233381152467,273.42646280506,0.034681598515908275,55.1227749015001,276.4131925079356,0.010864109384080686
0.0113017823205692,273.685310075988,0.035883158867807206,55.17495851131918,276.77844187480434,0.011238394329822978
0.0116840701423909,273.919795250829,0.037096922702091105,55.22223072256713,277.12029335192904,0.011616338472048904
0.0120629102180879,274.1908235698,0.03829973994242908,55.27687003167168,277.49836285714605,0.011990733180279402
0.0124419932786346,274.394856124531,0.039503328659664855,55.31800299470545,277.8088750801243,0.012365227768385813
0.0128173289227936,274.649135502443,0.04069501932986968,55.369265717292514,278.1694038105387,0.012735882177272131
0.0131929485474245,274.862303843207,0.04188761163807278,55.41224045479053,278.48854807543694,0.013106679535125275
0.0135719535063277,275.113537959107,0.04309095238259045,55.46288925255598,278.8473661052493,0.013480679462731036
0.0139414441720575,275.325183668866,0.04426408524628256,55.505557027643384,279.16361434614697,0.0138451561367134
0.0143075338193014,275.545965164657,0.045426419876281945,55.55006657719485,279.4883483800224,0.014206146976784772
0.0146592601965817,275.791108756536,0.04654315112414689,55.59948752531766,279.8340023797018,0.014552851892647078
0.0150221526726362,276.051478658469,0.04769533473561993,55.65197809754736,280.1983661163835,0.014910437548820023
0.0153821212498412,276.264646999233,0.04883823496824581,55.69495283504537,280.5141832964198,0.015265015782918334
0.0157386586512017,276.459543767932,0.049970241217565395,55.73424402361509,280.81064615816246,0.015616090331069754
0.0160831134652684,276.659008429647,0.051063885252227166,55.77445609941683,281.10854665340963,0.015955150402276564
0.0164334037861638,276.866086246389,0.05217605702107006,55.81620298727202,281.41593843637077,0.01629983672722434
0.0167869252194987,277.092958266202,0.05329848757190837,55.86194038646632,281.74449703546645,0.016647582056989373
0.0171473135947217,277.26806083183,0.05444272066324139,55.89724106369693,282.02246322071375,0.017001957702098374
0.0174969671356999,277.478183910583,0.055552870655847186,55.93960187637354,282.3332105753402,0.017345657628155885
0.0178466902346166,277.660899631238,0.0566632414949077,55.97643736565759,282.6162276972217,0.01768930780348819
0.0182010741891846,277.895384806079,0.0577884105506611,56.023709576905524,282.9533793217665,0.018037417473937983
0.018560723125088,278.113121039859,0.058930295922154395,56.06760520163557,283.2751016769339,0.018390575059783747
0.0189179032065826,278.323244118612,0.06006434268089976,56.109966014312185,283.58853631099004,0.018741184956287814
0.0192711650447897,278.521186149322,0.061185949017207295,56.14987112770331,283.88861389607615,0.019087827814153187
0.0196285714563652,278.722173442042,0.06232071437395951,56.19039016591567,284.1930915399225,0.019438415348044927
0.0199832280408535,278.929251258784,0.06344674902970986,56.232137053770856,284.5031580939528,0.019786184063787956
0.0203401510820765,279.154600647592,0.06457997968559288,56.277567490554546,284.83264740002073,0.02013605315661512
0.0206894364155101,279.349497416291,0.06568896061924456,56.31685867912427,285.12908108079006,0.020478317020875592
0.0210428682832196,279.56418838806,0.06681110679922223,56.3601403790329,285.44702078101517,0.0208245248664646
0.0213902005336904,279.734723060671,0.06791388669446702,56.394520169031274,285.7183048831751,0.021164641033914078
0.0217372556004427,279.952459294452,0.06901578653140557,56.43841579376152,286.037857458108,0.02150437027503251
0.0220833490577967,280.156491849183,0.07011463325850452,56.479548756795296,286.3432854494963,0.021843043307169758
0.0224297514345685,280.360524403915,0.07121446080475498,56.52068171982926,286.6489412783601,0.02218190382119935
0.0227699323191136,280.538672231553,0.07229453511318568,56.55659632188109,286.92651881115944,0.022514566583064943
0.0231146981235076,280.742704786284,0.07338916654213662,56.59772928491485,287.2319876577959,0.022851600062399478
0.0234509040295652,280.936078923978,0.0744566202938695,56.63671351107397,287.5242839492666,0.023180156262824596
0.0237933291700238,281.155337788763,0.07554382011482556,56.680916098214624,287.8449592886803,0.023514679265111225
0.0241390591311419,281.342621402435,0.07664151274137553,56.718672474730894,288.1339675765788,0.023852317330095636
0.0244831338563286,281.54208606415,0.0777339499938433,56.75888455053264,288.43511864344856,0.024188225756353713
0.0248254503884016,281.749163880892,0.07882080498317508,56.800631438387825,288.7437137707907,0.024522305784992284
0.0251680410792471,281.976035900705,0.07990853042660954,56.84636883758213,289.07282035561724,0.024856541669604482
0.0255034929512355,282.178545824431,0.0809735901201727,56.887194838205296,289.37508437885424,0.025183704620290244
0.0258490722203294,282.364306807097,0.08207080429954584,56.92464425231076,289.66316216619697,0.025520632828761672
0.0261933699219295,282.57442988585,0.08316394950212616,56.96700506498736,289.9760064583284,0.025856198699876203
0.0265328281423177,282.781507702592,0.0842417293518587,57.00875195284255,290.28450084829035,0.026186937620442108
0.0268729680652441,282.985540257324,0.08532167360715001,57.04988491587651,290.5902016435849,0.026518231051741274
0.0272128732916073,283.162165453957,0.08640087270085317,57.08549255551773,290.86782158343266,0.02684918628508348
0.0275543871508516,283.340313281595,0.08748517920395384,57.12140715756956,291.1475819691997,0.027181597521104023
0.0279037663674233,283.555004253365,0.08859445821656897,57.16468885747838,291.4672568443646,0.027521550168000147
0.0282476174138458,283.742287867036,0.08968618528896041,57.20244523399446,291.75733145883333,0.02785601099840405
0.0285859385603201,283.925003587691,0.09076035492901631,57.2392807232785,292.0412662959874,0.02818498380083912
0.02892047116983,284.078789319242,0.09182249596421024,57.270283926759184,292.29448175570934,0.028510166372203896
0.0292531639431344,284.229529788782,0.09287879551945172,57.30067320541844,292.5441428211732,0.028833455690972825
0.0295845584552938,284.361998686257,0.09393097309555781,57.32737893514941,292.7747228588547,0.029155379572021026
0.0299181740399842,284.512739155798,0.09499020257694983,57.357768213808875,293.02484080245375,0.0294793564061805
0.030250016346521,284.663479625338,0.09604380190020417,57.388157492468146,293.274554537262,0.029801507103347103
0.0305819571738182,284.817265356889,0.09709771402687278,57.419160695948825,293.52753476839735,0.030123649650078705
0.0309195380637781,284.989322660506,0.09816953335249547,57.45384744835801,293.80106087027787,0.030451159374187367
0.0312594210836916,285.165947857139,0.09924866194072082,57.489455087999225,294.0800702999353,0.03078079422133141
0.0315969002087781,285.348663577794,0.10032015816287047,57.52629057728327,294.3647968255698,0.031107990182207515
0.0319401335300494,285.549650870514,0.10140992395790685,57.566809615495615,294.67014484877717,0.03144065523141639
0.0322833493872334,285.733889222175,0.10249963430446604,57.60395206719048,294.9583361997075,0.031773192733471955
0.032628446321221,285.896810739759,0.10359531706987667,57.63679704513542,295.22517948238954,0.032107441332291216
0.0329669262931472,286.074958567397,0.10466999098074235,57.672711647187235,295.5059706408035,0.0324351724837484
0.0333075766452033,286.216563250905,0.10575155584852047,57.701259151382445,295.7497433685112,0.0327648966851147
0.0336493725801255,286.381007399494,0.10683675794189845,57.734411091738,296.0175486173513,0.03309562049449606
0.0339933348843548,286.527179976018,0.10792883825782648,57.763879483165226,296.26719435841255,0.03342833011222699
0.0343351527908548,286.673352552542,0.10901411011096399,57.79334787459246,296.5163259135001,0.033758855859610665
0.0346746497426619,286.81800249806,0.11009201293295152,57.8225093036089,296.76331627457023,0.03408702922489713
0.035013703100143,286.993105063688,0.11116850734295401,57.857809980839505,297.0417964361761,0.034414666339971256
0.0353587915566155,287.13318711619,0.1122641631922542,57.88605052262391,297.2858696284181,0.034748025153961484
0.0356991205712356,287.291540740758,0.11334470781367303,57.91797461333682,297.5475960927584,0.03507667749698906
0.0360372308900596,287.420964376222,0.11441820807593922,57.94406641824636,297.7788200320915,0.035403080344134516
0.0363777017223311,287.567136952746,0.11549920296840124,57.973534809673595,298.02816848595774,0.035731654347319626
0.036716624298231,287.722445315302,0.11657528214688341,58.00484497556489,298.2866422421123,0.036058627003281885
0.0370533395159113,287.88079893987,0.11764435296301837,58.036769066277785,298.5477439231008,0.036383364294799034
0.0373904822599846,287.976724693214,0.11871478117545109,58.05610769815195,298.7443133091441,0.03670840828346005
0.0377255329013803,288.127465162754,0.11977856696188245,58.086496976811205,298.9972273295428,0.0370313306086306
0.0380647175112676,288.288864049333,0.12085547809827463,58.119034992345526,299.26249822101505,0.03735813107687494
0.0384034609780266,288.4472176739,0.12193098860523444,58.15095908305824,299.52458914206,0.03768439995329993
0.0387398298045149,288.608616560479,0.12299895962933481,58.18349709859256,299.7892652461485,0.03800827633767969
0.0390809717868348,288.736517564937,0.12408208542320047,58.209281941091305,300.02062126172126,0.03833664150287952
0.0394235293335228,288.873554355428,0.12516970563393487,58.23690855805428,300.2619693992382,0.03866626075518798
0.039763350745325,289.02734008698,0.12624863861640687,58.267911761535174,300.5200355858469,0.03899313990018832
0.0401065664199904,289.173512663504,0.12733834838346952,58.29738015296242,300.7712693560448,0.03932317561535321
0.0404479211680089,289.302936298967,0.12842214970842827,58.323471957871746,301.0046386600611,0.039651313862265565
0.0407903547669346,289.432359934431,0.12950937638501736,58.349563762781294,301.23840857718756,0.039980381039220046
0.0411394039796078,289.557215676879,0.13061760763525476,58.374734680458815,301.4694269478206,0.04031569419229568
0.0414798728950794,289.707956146419,0.1316985964418771,58.40512395911807,301.7250053440657,0.0406426564194154
0.0418237379905462,289.84499293691,0.13279036811998418,58.432750576081055,301.967393979375,0.040972771623740675
0.0421686014476515,289.977461834385,0.1338853095962935,58.45945630581202,302.2054058512807,0.041303735854008615
0.0425143670748614,290.106885469849,0.13498311546268493,58.48554811072156,302.44059608965887,0.04163545596263076
0.0428529511757254,290.219560164253,0.13605811998292813,58.508263329113404,302.65632480621224,0.041960179670416965
0.0431949554500349,290.347461168711,0.1371439835538608,58.53404817161214,302.8890068189242,0.04228807652866973
0.0435310003001088,290.464703756132,0.13821092595284543,58.55768427723621,303.1089228625112,0.04261015509586534
0.0438697256359318,290.574333188525,0.13928637889408346,58.579785570806635,303.3217494623494,0.04293469780066307
0.0442062442953394,290.683962620917,0.14035482563770257,58.601886864376866,303.53400888527455,0.04325702195664895
0.0445419681677186,290.79359205331,0.14142074893250653,58.623988157947295,303.7461109739251,0.04357848135828192
0.0448729831198014,290.919970426763,0.14247172140536946,58.64946603803542,303.97441734893624,0.04389533077552966
0.0452126978961314,291.053961955244,0.14355031582021718,58.676478730177195,304.21329680859856,0.0442204033621773
0.0455518927301532,291.172727173669,0.1446272594182364,58.700421798211664,304.4361960078301,0.044544873021285285
0.0458922168344644,291.326512905221,0.14570778844942447,58.731425001692564,304.69613240509585,0.04487031715412972
0.0462334250898116,291.45745917169,0.14679112466015182,58.7578237690127,304.93253577717115,0.045196500487993486
0.0465723993133799,291.580792283132,0.14786736781998117,58.78268772427941,305.1604093734537,0.04552044284574126
0.0469176141965233,291.716306442618,0.14896342507396146,58.8100073788318,305.4029395631275,0.04585024130099498
0.0472630258664335,291.819845350989,0.15006010712592635,58.83088082275938,305.6121342501514,0.04618011893087518
0.0476069813308837,291.935565307404,0.15115216572555573,58.85420996597264,305.83373631481453,0.04650849774804215
0.0479513159832799,292.054330525829,0.15224542824691367,58.87815303400713,306.0587200131583,0.04683713060539235
0.0482984366996539,292.173095744255,0.15334753652140112,58.90209610204182,306.28459951440084,0.0471683132033653
0.0486469449454354,292.279679914637,0.1544540502017574,58.92358347079082,306.4981934121138,0.04750070931824825
0.0490012582002477,292.399967764068,0.15557899478578643,58.94783350123611,306.7279340822192,0.04783852884170363
0.0493462923730502,292.498938779423,0.15667447828443437,58.967786057931676,306.93267693123926,0.04816739159450907
0.0496949221097681,292.605522949805,0.15778137769851372,58.98927342668068,307.1465316216835,0.04849957157984543
0.0500460811648763,292.684699762089,0.15889630769848223,59.00523547203714,307.3324220020999,0.04883405003012514
0.0503874418812308,292.80498761152,0.15998012797290778,59.02948550248243,307.55868190733,0.049159088376366206
0.0507313072463223,292.858279696711,0.1610719005070733,59.04022918685694,307.71536306363424,0.049486404829378834
0.0510727876973005,292.95572808106,0.16215610093892907,59.0598747811417,307.9177937860521,0.04981134515545813
0.0514133252962837,293.050131203399,0.16323730781570076,59.078906450605245,308.11681292707794,0.050135283182783444
0.0517582698227325,293.149102218753,0.1643325066871757,59.09885900730061,308.32199254968305,0.050463306374369396
0.0521040864247235,293.245027972097,0.1654304743984971,59.11819763917475,308.5242922531756,0.05079205088950225
0.0524490921553498,293.342476356447,0.1665258675932356,59.137843233459705,308.7280229319448,0.05111991690612585
0.0528035266838269,293.441447371801,0.1676511972211504,59.15779579015509,308.93619066823874,0.05145663139697049
0.0531543188153454,293.546508911178,0.16876496223872164,59.17897619649349,309.1497736329744,0.051789773995729066
0.053503040075202,293.633298878489,0.16987215223876634,59.196473053903375,309.3435730357985,0.05212083994869002
0.0538511077265439,293.697249380718,0.17097726703177688,59.20936547515276,309.5131715961087,0.05245117612390796
0.0541981675921552,293.774903561997,0.17207918210509274,59.2250205580986,309.69696501961937,0.05278044723992059
0.0545424973125771,293.851035112269,0.1731724289674323,59.24036867863343,309.8784044051779,0.053107021037460136
0.0548870818056732,293.948483496619,0.1742664847330124,59.2600142729184,310.08245795695154,0.05343372973593714
0.0552297600466495,294.007866105832,0.17535448814811216,59.27198580693574,310.2458500026846,0.05375852525170394
0.0555773665284603,294.094656073143,0.17645813872786145,59.289482664345634,310.43966256778157,0.054087884083760696
0.055929963221271,294.190581826486,0.17757763322753542,59.30882129621958,310.64465024808567,0.05442186037749209
0.0562780933487734,294.298688627874,0.17868294638235555,59.3306156273794,310.8612576988951,0.0547514965888225
0.0566330444609612,294.393091750212,0.1798099161635518,59.34964729684274,311.06546880430164,0.055087479592721894
0.0569851683123485,294.472268562496,0.18092790939170647,59.3656093421992,311.25282034984895,0.055420674918648764
0.0573349502674492,294.545354850758,0.1820384670991512,59.38034353791281,311.43309812263436,0.05575154436005253
0.0576873175341642,294.591033780922,0.18315723317097132,59.389552410233875,311.5852002893597,0.05608474867221454
0.0580364406570415,294.658029545162,0.18426569908610674,59.40305875630465,311.75893279098057,0.056414775808029914
0.0583881493933442,294.750910036495,0.1853823743238678,59.421783463357386,311.96087020553,0.056747137037618516
0.0587430522512412,294.840745265817,0.1865091908976908,59.43989424558871,312.16059057076177,0.0570824047441693
0.0591000484640016,294.918399447095,0.18764265387320508,59.45554932853435,312.3480911473441,0.057419536627094196
0.0594570911878274,295.006712045412,0.188776264521352,59.47335314835505,312.54695302451717,0.057756598791265754
0.0598151423115132,295.085888857696,0.1899130768390544,59.48931519371151,312.7364932938384,0.058094498869823714
0.0601740228216293,295.189427766067,0.19105252245867302,59.51018863763911,312.95216312916597,0.05843306712238516
0.0605271739630563,295.277740364383,0.19217377733270374,59.52799245745962,313.15006752283625,0.05876611842185821
0.0608829791983041,295.309715615498,0.1933034589546155,59.534438668084405,313.2890508883735,0.05910156061633793
0.0612412393188647,295.334077711585,0.1944409348373954,59.53935006665554,313.4207026437363,0.05943920355056201
0.0615950968855857,295.414777154874,0.1955644326117346,59.5556190744226,313.61087897516217,0.059772585417042695
0.0619511253747478,295.484818181125,0.19669482306482425,59.569739345314794,313.7904351985984,0.06010790045635375
0.0623043317740479,295.554859207377,0.19781625338260206,59.5838596162072,313.9692072128654,0.06044044652689955
0.0626585142607838,295.602060768546,0.19894078277798855,59.59337545093888,314.124046708729,0.06077380058123201
0.0630161131551181,295.658398115748,0.20007615926749994,59.604733060134805,314.28964118667096,0.0611102574341253
0.0633667613079589,295.742142821048,0.2011894671527695,59.62161599272327,314.48236459389364,0.061440064601244966
0.0637189751027304,295.801525430261,0.20230774595116902,59.63358752674062,314.6496954645015,0.06177123488927008
0.0640677572350151,295.836545943386,0.2034151292211729,59.64064766218662,314.7901299501322,0.06209907050372109
0.0644208555009322,295.89897381461,0.20453621621545973,59.65323312102537,314.96103884959507,0.062430853598113546
0.0647783297215927,295.943130113768,0.2056711968660568,59.66213503093564,315.1138317751179,0.06276663639053638
0.0651339518929628,296.013171140019,0.20680029726015686,59.67625530182782,315.2936787887363,0.06310056767751421
0.0654915919119695,296.061895332194,0.20793580432050315,59.68607809897031,315.45146016197424,0.0634362813118555
0.0658577333647242,296.103006369341,0.20909830343299932,59.69436608405915,315.60367921130626,0.06377985845523057
0.066218114919216,296.189796336652,0.2102425148685108,59.71186294146904,315.80292630837164,0.06411791543215668
0.066583255075554,296.256792100893,0.21140183486488395,59.725369287540026,315.9825336572122,0.06446031971325143
0.0669432337900925,296.28115419698,0.21254476728354366,59.73028068611117,316.11517276998694,0.06479776920809777
0.0673087223015133,296.345104699209,0.21370519330730472,59.74317310736053,316.291715056821,0.06514026720975163
0.0676766750835212,296.399919415406,0.21487344339017977,59.75422375414584,316.4592804564643,0.06548495601755469
0.0680426859106692,296.44864360758,0.2160355277663747,59.76404655128813,316.6198055532145,0.06582770782045166
0.0684009223568078,296.473005703668,0.21717292848286474,59.76895794985947,316.75203274769405,0.06616306555993016
0.0687706124786081,296.506503585788,0.21834669461958073,59.775711122894855,316.8974374412732,0.06650902761254195
0.0691424683424988,296.564363563995,0.2195273369874337,59.7873756945014,317.06955568323184,0.06685689570032957
0.0695188781655219,296.643540376279,0.220722438175532,59.80333773985785,317.2658665182866,0.06720890077820155
0.0698853957543152,296.698355092475,0.22188613151995074,59.81438838664297,317.43323705776703,0.06755153596580699
0.070251096014538,296.759260332694,0.22304722984615813,59.82666688307111,317.6069236235293,0.06789329011577687
0.0706189994228526,296.827778727939,0.224215323167557,59.84048019155251,317.78945946261393,0.06823698533831304
0.0709946839737601,296.920659219272,0.22540812161668833,59.85920489860524,318.00044758582476,0.06858782784335839
0.0713612292069999,296.983087090496,0.22657190273222466,59.87179035744399,318.1761652389633,0.06893001677150172
0.0717238884013271,297.04551496172,0.2277233456742135,59.884375816282756,318.3507743269492,0.06926846268278106
0.0720889879879743,297.092716522889,0.22888253686181842,59.89389165101443,318.5098297956222,0.06960907038618447
0.0724601136743704,297.164280180145,0.23006086091612601,59.90831888431723,318.69683770196076,0.06995518108126088
0.072830895407685,297.234321206396,0.23123809291939987,59.92243915520943,318.88216296575325,0.07030085142196248
0.0732036036558926,297.283045398571,0.23242144160745898,59.93226195235192,319.0452356275447,0.07064819742419806
0.0735733460671165,297.342428007784,0.2335953737630949,59.94423348636926,319.21890536403737,0.0709926602384905
0.0739499710850111,297.4307406061,0.23479115819491023,59.96203730618977,319.42573527371457,0.07134341314417297
0.074329765508122,297.488600584308,0.2359970054882873,59.97370187779649,319.600858507079,0.07169699319298921
0.0747068927005245,297.566254765586,0.23719438432416526,59.989356960742136,319.79650503165556,0.07204796644868798
0.0750841639953283,297.62868263681,0.23839222068516736,60.0019424195809,319.9758834536258,0.07239895060363805
0.0754611907842587,297.685019984012,0.23958928074002134,60.013300028776825,320.14868607064136,0.07274958426217036
0.0758406204192653,297.765719427301,0.24079396983116733,60.02956903654388,320.34845632825636,0.07310232848147508
0.0762257663938477,297.835760453552,0.24201680830046646,60.04368930743608,320.5385195536184,0.07346025979907235
0.0766047813420135,297.875348859694,0.24322018076089283,60.05167033011431,320.6940248262668,0.07381236828478685
0.0769832396985539,297.937776730918,0.24442178604290862,60.06425578895307,320.8739920122485,0.0741638360276781
0.0773635911022412,298.006295126163,0.24562940174961578,60.078069097434465,321.0611322881973,0.07451693739668822
0.0777471662071189,298.065677735376,0.2468472527076025,60.090040631451814,321.23943952290585,0.07487290528151931
0.0781317669155955,298.126582975595,0.24806835995701568,60.10231912787996,321.41973966798713,0.07522969777728286
0.0785134537908229,298.181397691791,0.2492802157858627,60.113369774665074,321.59264908074846,0.07558366130874185
0.0788854102758744,298.217940835922,0.2504611776259012,60.120736872521874,321.74298545039017,0.07592848070670505
0.0792661782151105,298.319957113288,0.2516701158329758,60.14130335403887,321.966639998954,0.07628134557979134
0.0796499002786398,298.380862353506,0.25288843338468137,60.15358185046682,322.1468682850173,0.0766368221741735
0.0800333451233316,298.444812855735,0.2541058707665778,60.16647427171618,322.3303495632861,0.07699191577369763
0.0804160883329323,298.52703493003,0.25532108045706003,60.18305024189405,322.5334113407317,0.077346233914801
0.0808029669445764,298.581849646226,0.25654942004903003,60.19410088867916,322.7081489734405,0.07770425279755312
0.0811926675286211,298.668639613537,0.257786719403372,60.211597746089055,322.91834317090445,0.07806475360713055
0.0815877641084738,298.753906949843,0.25904115104440434,60.228787641088346,323.12857023655175,0.07843011347304046
0.0819757578048537,298.782836938947,0.26027303103041044,60.23461992689172,323.2757864161012,0.07878877518702229
0.0823657432374195,298.868104275252,0.2615112347788069,60.2518098218908,323.4845978138417,0.07914914847986775
0.0827598079299911,298.922918991449,0.26276239017772174,60.26286046867613,323.6617223530537,0.07951315942298422
0.0831512842359279,298.970120552618,0.26400532744907107,60.27237630340779,323.8298700247384,0.07987464823165755
0.0835447467398606,299.049297364902,0.2652545708990574,60.288338348764235,324.033295175986,0.08023783947088335
0.0839360580373044,299.05995578194,0.2664969842684415,60.29048708563911,324.1618695870866,0.0805989142271927
0.0843293541717599,299.151313642268,0.26774569949533766,60.308904830281236,324.37855072135403,0.08096168913155105
0.084729897517268,299.206128358464,0.2690174246173259,60.319955477066344,324.55783295081517,0.08133101362072677
0.085130174751861,299.260943074661,0.27028830483715865,60.33100612385166,324.7370794550136,0.08169995652561636
0.0855265282991242,299.306622004824,0.27154672734971935,60.34021499617253,324.90527828183485,0.082065148820751
0.0859256958555412,299.35839145901,0.2728140843413433,60.350651718136426,325.08096955532096,0.08243279914846528
0.0863211379989177,299.40863828219,0.2740696131465637,60.36078147768951,325.25393266541494,0.08279688498031626
0.0867233905479827,299.52588086961,0.27534676498984506,60.38441758331337,325.5017808154937,0.08316710523892135
0.0871227787933812,299.551765596703,0.2766148226689853,60.38963594429532,325.6495478079513,0.08353455373231063
0.0875198693201886,299.644646088036,0.27787558509159876,60.40836065134806,325.86950635615506,0.08389975445304992
0.0879179090869588,299.675098708145,0.2791393613510942,60.41449989956203,326.0219067919931,0.08426569438032609
0.088321071186768,299.745139734396,0.2804194010179884,60.42862017045423,326.2189515587653,0.08463620709338347
0.0887275668444632,299.82431654668,0.2817100247311706,60.44458221581069,326.426998634671,0.0850096444666402
0.0891368730551388,299.909583882985,0.28300957195006565,60.46177211080977,326.6425863895821,0.08538552297220366
0.0895485488192178,299.967443861193,0.2843166425010165,60.473436682416505,326.829093151973,0.08576343505152023
0.0899617269146892,300.022258577389,0.28562848295413823,60.48448732920162,327.01277907185636,0.08614258270227584
0.090379354099793,300.052711197499,0.28695444926684277,60.490626577415796,327.17128143142065,0.08652566697642691
0.0908016389678363,300.1090485447,0.28829520372288026,60.501984186611516,327.3594420216367,0.08691287452560464
0.0912209647735667,300.142546426821,0.28962656315607427,60.50873735964712,327.52183908147066,0.08729722050824783
0.091641484146497,300.147114319837,0.29096171216512795,60.509658246879134,327.65304133839516,0.08768251219562878
0.0920620418285628,300.131888009782,0.2922969828056869,60.50658862277205,327.76264243782407,0.08806769057013135
0.0924795898423563,300.151682212853,0.29362269774948124,60.51057913411117,327.90958667439094,0.08844996574660306
0.0929032827871878,300.165385891902,0.2949679228493213,60.51334179580745,328.05173562034275,0.08883771743574333
0.0933281760581579,300.177566939946,0.2963169589846513,60.515797495093125,328.1925917560268,0.08922641669683998
0.0937478539470816,300.209542191061,0.29764943628198404,60.522243705717905,328.3535425059088,0.08961019658223673
0.0941659454002977,300.249130597203,0.2989768766459452,60.530224728396135,328.5223738355061,0.08999237933407078
0.0945826121540582,300.268924800274,0.3002997935891347,60.53421523973524,328.66914405657445,0.09037311448736723
0.0949996015662749,300.29024163435,0.30162373497292283,60.53851271348497,328.81769494385367,0.09075399940198228
0.0954196290882758,300.281105848317,0.3029573223552756,60.53667093902071,328.9338175905807,0.09113751276898618
0.095837618428798,300.319171623454,0.3042844385114336,60.54434499928833,329.1010458003552,0.09151901918140348
0.0962549464656475,300.361805291606,0.3056094550284308,60.552939946787774,329.2731147802748,0.0918997768634237
0.096672905934168,300.358760029596,0.30693647634098337,60.55232602196656,329.39531418444045,0.09228096539465976
0.0970999787076003,300.366373184623,0.30829243239663096,60.55386083402,329.531941625329,0.09267031543341475
0.0975314196591129,300.402916328754,0.30966225741768344,60.5612279318768,329.70163922803505,0.09306349394839598
0.0979656303526655,300.450117889923,0.31104087636971295,60.57074376660847,329.88390307854195,0.09345904055066685
0.0984021287018604,300.482093141038,0.31242675862840674,60.57718997723326,330.0501707429068,0.09385651347216836
0.0988369576479199,300.503409975114,0.31380734053214565,60.581487450982976,330.2042527798799,0.09425230922733899
0.0992777784577942,300.504932606119,0.3152069466034966,60.581794413393595,330.3383947308637,0.09465339913274123
0.0997250677259614,300.526249440196,0.31662709002992745,60.586091887143525,330.4962500190487,0.09506021013356554
0.100172291595528,300.546043643267,0.31804702581580135,60.59008239848263,330.6524295649827,0.09546679626253443
0.10061998816438,300.556702060305,0.3194684624219065,60.59223113535749,330.79871386433797,0.09587364663105387
0.101070224198396,300.574973632371,0.32089796182990726,60.595914684285994,330.9541536058217,0.09628263790309012
0.101514425361914,300.553656798294,0.32230830052407694,60.59161721053607,331.06418855859476,0.09668598328155609
0.101967718842409,300.553656798294,0.3237475073246486,60.59161721053607,331.2004275717604,0.09709741705521448
0.102417034813904,300.530817333212,0.3251740855341452,60.58701277437554,331.31029251467857,0.09750507363782515
0.102866788345616,300.533862595223,0.32660205299733075,60.58762669919696,331.44881582949625,0.09791296085236358
0.103314074017784,300.533862595223,0.3280221850064642,60.58762669919696,331.5832403202364,0.09831844499550614
0.103759229276577,300.538430488239,0.329435552953132,60.58854758642898,331.72206640369075,0.09872183464655664
0.104208257588526,300.526249440196,0.33086121784357003,60.586091887143525,331.84356625397356,0.0991285691848236
0.104664142380408,300.570405739354,0.33230865205779536,60.59499379705377,332.0293494809947,0.09954134522237239
0.105116491810978,300.58867731142,0.3337448614998551,60.59867734598227,332.18550454849856,0.09995075186653352
0.105572520096394,300.652627813649,0.335192751306051,60.61156976723164,332.39328340553914,0.10036331852736022
0.106024544332366,300.670899385714,0.336627928255262,60.615253316159944,332.549394487087,0.10077209483615238
0.106481780603095,300.667854123703,0.3380796534148266,60.614639391338535,332.6835026009066,0.10118541458316076
0.106945115744937,300.673944647725,0.3395507424901749,60.61586724098136,332.82955445956276,0.10160407322454078
0.107404871950677,300.681557802753,0.34101046844339944,60.617402053035,332.9762220164878,0.10201932484682379
0.107867227275827,300.678512540742,0.3424784466007507,60.61678812821359,333.11186998993185,0.10243675016629124
0.10833486984894,300.661763599682,0.34396321177038447,60.61341154169589,333.23391662780625,0.10285877176861742
0.108799760041594,300.632833610578,0.34543923813206096,60.60757925589253,333.34161376803337,0.10327813304077448
0.109271863317169,300.635878872589,0.34693816603201155,60.60819318071395,333.48692153699153,0.10370382108234391
0.109747009153488,300.649582551638,0.3484467540623244,60.61095584241022,333.64497503992493,0.10413206966506253
0.11022611629809,300.6389241346,0.3499679192464357,60.60880710553536,333.7771851499931,0.10456370295516638
0.110702263539292,300.635878872589,0.35147968673725205,60.60819318071395,333.916951164909,0.10499248512826108
0.111181193748424,300.643492027616,0.3530002901512462,60.60972799276738,334.0693943639411,0.10542358804230319
0.111657289947841,300.676989909736,0.35451189558439516,60.61648116580278,334.24976775273143,0.10585195583437561
0.112138721596044,300.681557802753,0.3560404410674397,60.617402053035,334.39960330226074,0.10628493768453208
0.112620871688504,300.687648326774,0.35757126761100017,60.61862990267764,334.5513533873017,0.10671837786518237
0.113104451704129,300.652627813649,0.35910663416060956,60.61156976723164,334.6577784359174,0.10715291488388082
0.113582829689215,300.646537289627,0.36062548426325763,60.61034191758881,334.79482173124694,0.10758259173742306
0.114067462969008,300.645014658622,0.36216419492660035,60.6100349551782,334.9388287350112,0.10801769888959684
0.114552557390288,300.608471514491,0.36370436971416437,60.602667857321386,335.04394069966145,0.10845303055179986
0.115040327101651,300.544521012261,0.36525303854774194,60.58977543607182,335.1192610181205,0.10889057206221404
0.115530292281654,300.536907857234,0.36680867799425143,60.588240624018376,335.25802466340474,0.10932989030986383
0.116019099941786,300.511023130141,0.3683606423151705,60.58302226303642,335.3760415562852,0.10976797845584282
0.116509537967694,300.504932606119,0.36991778304742845,60.581794413393595,335.51662346107094,0.11020733500022864
0.116999456116402,300.450117889923,0.37147327316957635,60.57074376660847,335.60261827315287,0.1106460331723543
0.117490745955523,300.369418446634,0.3730331184087855,60.55447475884141,335.6600454821556,0.11108576644715848
0.117981111866806,300.316126361443,0.374590030177109,60.54373107446691,335.74775686109825,0.11152448001667366
0.118463391810307,300.268924800274,0.3761212689977247,60.53421523973524,335.8398000873485,0.11195577169432006
0.118935409866145,300.162340629891,0.37761992632501035,60.512727870986026,335.86227163908853,0.11237770636460505
0.119414659846794,300.039007518449,0.37914154501357095,60.487863915719316,335.8680635420343,0.11280592355409388
0.119883841038146,299.9415591341,0.38063119529611356,60.468218321434556,335.89970533006607,0.11322496656960265
0.120349140108927,299.885221786898,0.3821085198458432,60.456860712238644,335.976150360326,0.11364036896871713
0.120814522073501,299.796909188582,0.38358610758336564,60.43905689241813,336.01672949131336,0.11405567283885924
0.121270275629712,299.649213981052,0.3850331251243356,60.40928153858009,335.98775675276073,0.1144622172862012
0.121726439743782,299.436045640288,0.3864814461865078,60.36630680108207,335.88532940703686,0.11486896252771907
0.122183401511234,299.268556229688,0.3879322997981679,60.3325409359051,335.83420639518727,0.11527625319989089
0.122623470733279,299.09345366406,0.3893295195781608,60.2972402586745,335.7693310259502,0.1156683307840462
0.123064252656394,298.831561131121,0.39072900218405093,60.244442724034,335.607043871866,0.11606088930782019
0.123508427023681,298.540738609079,0.39213925580018716,60.18581290359033,335.4130356371743,0.11645631330375143
0.123942622031456,298.187488215813,0.3935178249498728,60.1145976243079,335.1456273622548,0.11684270215378632
0.12438218808379,297.849464132601,0.3949134471660332,60.04645196913236,334.8966322009982,0.11723371866168318
0.124815725894844,297.46423848822,0.3962899297161297,59.968790479225156,334.59245334288414,0.11761922303524545
0.125244855603283,296.949589208376,0.3976524165404235,59.86503718440861,334.14099763023324,0.118000661399324
0.12568779484672,296.380125212335,0.39905874863833596,59.750233242806736,333.6314895866681,0.11839422204101248
0.125906910207264,296.133458989451,0.39975443990806314,59.70050533227332,333.41870781980236,0.11858885330457322
0.126121546016215,295.815838161712,0.4004359086014826,59.63647297340114,333.1245890067496,0.11877946884409513
0.126340035460994,295.525929218273,0.401129612588656,59.57802733040384,332.86268559535284,0.1189734694408298