File: example/data/02 processed data/test_ID_116.csv
Strain,Stress_MPa,Displacement(mm),Force(kN),True Stress (MPa),True Strain
4.36217742864023e-05,0.019143782825867,0.00013849913335932731,0.003859386617694788,0.01914461791164042,4.362082288436729e-05
6.83327035277503e-05,0.832264048692022,0.00021695633370060716,0.16778443221631165,0.832320919544518,6.833036895496133e-05
0.0001232062029531,2.31476803301562,0.00039117969437609245,0.466657235455949,2.3150532267956847,0.0001231986136921633
0.0001750346627333,5.05390495307824,0.0005557350541782275,1.018867238540573,5.054789561627188,0.0001750193459540929
0.0002534834138741,8.66657932507802,0.0008048098390502675,1.7471823919357288,8.668776159191951,0.0002534512923816082
0.0003274646034233,12.5384058080956,0.0010397001158689776,2.5277426109120733,12.542511692181108,0.000327410998592145
0.0004003071776837,16.6365314854843,0.0012709752891457474,3.353924747473635,16.6431912084497,0.00040022707614153905
0.0005013766554941,20.7673320748966,0.0015918708811937673,4.186694146299155,20.777744330395844,0.0005012510082146406
0.0005789729302043,25.1521002754332,0.0018382390533986522,5.070663415527333,25.16666266063046,0.0005788053900417743
0.0006637765970626,29.6055850004222,0.0021074906956737548,5.9684859360851155,29.625236494887822,0.0006635563948151223
0.0007482036512623,34.1348318184529,0.002375546592757802,6.881582094600105,34.160371624254694,0.0007479238864490606
0.0008100798804067,38.6787296028114,0.0025720036202912726,7.797631887926778,38.71006246346233,0.0008097519427922164
0.0009035606879365,43.343809415153,0.0028688051841983873,8.738111978094844,43.38297317740594,0.000903152722707075
0.0009837323730189,47.9605126958514,0.0031233502843350074,9.668839359483641,48.00769300481689,0.0009832488254229565
0.0010621365034949,52.6295309121406,0.0033722833985963077,10.610113431887546,52.6854306580842,0.001061572835611669
0.0011484697435546,57.2773533050347,0.003646391435785855,11.547114426294995,57.343134612296424,0.0011478107566814486
0.0012231358549212,61.8332029123926,0.00388345633937481,12.465573707138349,61.90883331989937,0.0012223884336645672
0.0013156271901655,66.4772616313638,0.004177116328775462,13.401815944882943,66.56472092429377,0.0013147625110276186
0.0013989130476624,71.0197779962047,0.004441548926328119,14.317587244034867,71.11912849028568,0.0013979354803864588
0.0014910070064155,75.6354036638113,0.004733947245369212,15.24809737862436,75.74817658060712,0.0014898965591217481
0.0015826181588276,80.1935521186931,0.0050248126542776295,16.16702010712853,80.32046789049704,0.00158136713846043
0.0016682986744746,84.7813059788381,0.005296848291456855,17.09191128533376,84.92274651922284,0.001666908610054758
0.0017498479038994,89.3784391152623,0.005555767094880594,18.01869332563688,89.53483778960194,0.0017483187037078693
0.0018399012566297,93.9459800719856,0.005841686489799297,18.939509582512297,94.11883139877536,0.0018382107116189203
0.0019234302998923,98.4344294480521,0.006106891202158052,19.844380976727304,98.6237612122051,0.0019215828763805992
0.0020121099751296,102.855810789703,0.00638844917103648,20.735731455204128,103.062767992593,0.0020100883931628484
0.0020970798947571,107.207275927592,0.006658228665853792,21.612986827002548,107.43209815051142,0.002094884092027844
0.002185429187523,111.604424271772,0.006938737670385525,22.499451933189235,111.84832783803223,0.002183044610739936
0.002268939921557,115.941859297643,0.007203884250943475,23.37387883440483,116.20492441078297,0.002266369764327189
0.0023643508025239,120.321861081836,0.007506813798013382,24.25688719409814,120.60634417064603,0.0023615601230631417
0.0024620062662125,124.610911389568,0.007816869895224687,25.12155973613691,124.91770423424755,0.0024589804940806778
0.0025477287889521,128.877612309207,0.008089038904922916,25.98172664153613,129.20595751233859,0.0025444888298191306
0.0026432189772529,133.080382482197,0.008392220252777957,26.829005108410914,133.43214307467403,0.002639731817505023
0.0027335199021635,137.262989379416,0.008678925689369113,27.67221865889027,137.6382004927151,0.0027297906311142418
0.0028200730443404,141.397477961379,0.00895373191578077,28.505731557014006,141.79622917751558,0.002816104098413368
0.0029063025770223,145.411196033816,0.009227510682045803,29.314897120417303,145.83380496757698,0.0029020874446795456
0.0029949743833957,149.254258206463,0.009509043667281347,30.08965845442294,149.70127088640407,0.0029904983823956935
0.0030761460731658,153.028985075133,0.009766763782301414,30.850643391146814,153.49972458665243,0.003071424416360035
0.003168083277952,156.719895721775,0.010058664407497598,31.59473097750984,157.21639740273352,0.0031630754760918344
0.0032577717950656,160.384376401582,0.01034342544933328,32.33349028255893,160.90687209939227,0.003252476753439555
0.0033396970269135,164.012336630483,0.010603538060450363,33.064887064705374,164.56008814350494,0.0033341326243018048
0.003428997577422,167.460835135431,0.01088706730831485,33.760104363302894,168.03505793342347,0.0034231319701731417
0.003534554277736,170.892181230624,0.0112222098318118,34.4518637360938,171.49620892082436,0.0035283224210050476
0.0036406366196768,174.22072115158,0.01155902126747384,35.12289738415853,174.85499548891093,0.0036340255430051794
0.0037695651631544,177.410149537638,0.011968369393015219,35.76588614678782,178.0789086569251,0.003762478156766275
0.0038972369068933,180.431620865209,0.012373727179386227,36.37501476642613,181.13480563721546,0.003889662352649083
0.0040420007148057,183.205613945409,0.012833352269508097,36.93425177139446,183.94613116793275,0.004033853775826488
0.0042010408836912,185.751857025206,0.013338304805719558,37.44757437628153,186.53220817079045,0.004192241148194985
0.0043737146716039,187.994611982891,0.013886544082342382,37.899713775750826,188.81684677550305,0.004364177779241892
0.0045776473789956,189.852812527831,0.01453403042831103,38.27432700561073,190.72189175749395,0.00456720181650285
0.0048172459835553,191.28202919571,0.015294755997788076,38.562457085855144,192.20348178257936,0.0048056801827879225
0.0050782143280545,192.307477299921,0.016123330491573037,38.76918742366408,193.2840558865375,0.005065363684859482
0.0053490865963049,193.080321901662,0.016983349943268056,38.924992895375055,194.11312526355638,0.005334831046116275
0.0056316467219401,193.608095721666,0.017880478342159816,39.03139209748787,194.698428119278,0.005615848285927
0.0059153265772519,194.05437187834,0.01878116188277478,39.12136137067335,195.20226686174385,0.005897899722913328
0.0062043088751482,194.371787757428,0.019698680678595534,39.18535241189748,195.57773036528982,0.006185141390646857
0.0065173890341143,194.609717911848,0.020692710183312903,39.23331913102856,195.87806515329876,0.006496242683802737
0.0068268510971562,194.793230743158,0.021675252233470933,39.27031531782065,196.12305512417555,0.0068036536662970356
0.0071395792647254,194.789389814148,0.022668164165503144,39.26954098653224,196.1801041026536,0.007114213132798456
0.0074622109633776,194.868468789191,0.023692519808723878,39.28548330790091,196.3226184134063,0.007434506406610996
0.0078054914159027,194.929446229632,0.02478243524549107,39.29777635989381,196.45096634888404,0.007775186163885993
0.0081402010413249,195.028910437809,0.025845138306206557,39.317828344262296,196.61648497764332,0.008107248311939052
0.008481147017236,195.172205844363,0.0269276417797243,39.34671669822358,196.82749001580726,0.008445384154334759
0.0088331995913323,195.186792320178,0.028045408702480054,39.349657331747885,196.91091621433404,0.00879441511052874
0.0091852405599579,195.288093625719,0.029163138777866332,39.370079674944954,197.08186174416682,0.009143312786776428
0.0095384690784626,195.368274185185,0.030284639324118755,39.386244075733295,197.23178842741297,0.009493265106078974
0.0098950803956761,195.395961661372,0.031416880256271616,39.3918258709326,197.32942041100173,0.009846444660824167
0.0102412569330995,195.427940959688,0.03251599076259091,39.3982728974731,197.42936871496272,0.010189170579283289
0.0105951094616283,195.305510244693,0.03363947254066985,39.373590865330115,197.3747935041947,0.010539374621559783
0.0109518483040837,195.272408697013,0.034772118365465746,39.36691759331782,197.41100249503575,0.01089231111387141
0.0113060078378604,195.26595990013,0.03589657488520677,39.36561751586621,197.47363837322823,0.01124257261620331
0.0116604597157967,195.261548857188,0.037021959597654516,39.3647282496091,197.5383882816813,0.011593000452995104
0.0120167403653094,195.27097399374,0.038153150659857346,39.366628357137984,197.61749458910384,0.011945112591412557
0.0123775939861209,195.285694330685,0.039298860905933854,39.3695959770661,197.70286136640792,0.012301617861665686
0.0127391376651027,195.270921488894,0.04044676208670107,39.36661777216103,197.75850463973248,0.012658677459438349
0.0130997863071341,195.26340564983,0.041591821525150764,39.36510257900573,197.821314537446,0.01301472614778535
0.0134553715420297,195.184737366647,0.04272080464594429,39.349243053116034,197.81102052724873,0.013365651941408766
0.0138210629068357,195.164790738939,0.043881874729203345,39.3452218129701,197.86217558894128,0.013726423035629686
0.0141746152976193,195.116340878547,0.04500440356994128,39.33545432111508,197.88203994877952,0.0140750947790315
0.0145201486162194,195.083767796995,0.046101471856496594,39.32888758787419,197.9164130980194,0.014415740723495706
0.0148738125906309,194.984628982159,0.047224354975253104,39.308901202803256,197.88479381169333,0.014764282194252298
0.0152078949639237,194.93938059802,0.04828506651045775,39.29977912856083,197.90399822248702,0.015093414145015988
0.0155532273282173,194.92694570818,0.04938149676708992,39.29727225476909,197.95868880717438,0.015433515561998592
0.0159192578917898,194.998536105985,0.050543643806432614,39.31170487896658,198.10276809077766,0.01579387541938925
0.0162868530996357,195.062968056935,0.051710758591343345,39.3246943602781,198.23992996285722,0.016155645035046715
0.0166617299618602,195.051968061121,0.05290099262890613,39.322476761122,198.30187128148475,0.01652444616420168
0.0170353074143768,194.973563096975,0.05408710104064634,39.30667032035016,198.29499768200836,0.016891833685403503
0.0173942400558165,194.915651682046,0.055226712177217384,39.29499537910048,198.3060613180394,0.017244691955290745
0.0177558048987045,194.872051311061,0.056374680553386784,39.286205544309894,198.33216143435055,0.017600012043446887
0.0181250669708044,194.860454543542,0.05754708763230397,39.28386763597807,198.3923133321051,0.017962766152738223
0.0184960546441731,194.854154566026,0.05872497349524959,39.282597560510844,198.45818765652336,0.01832708298470526
0.0188567570995652,194.787973995452,0.059870203791119514,39.26925555748313,198.46104350700068,0.01868117232758369
0.019229579248431,194.788285861205,0.061053914113768426,39.26931842961893,198.53398264083907,0.019047027440171574
0.0195973326542922,194.746624100133,0.06222153117737773,39.260919418586816,198.56313847592372,0.019407777445679748
0.0199710813410435,194.710364456679,0.06340818325781311,39.25360947446649,198.59894098318756,0.019774275267836733
0.0203424643300285,194.591310838145,0.06458732424784049,39.22960826497003,198.54977763780346,0.020138320288147098
0.0206959104200197,194.490092939485,0.06570951558356254,39.209202736600176,198.5152424805419,0.020484659776808127
0.0210624627845702,194.414649150121,0.06687331934101039,39.19399326866439,198.50950046262068,0.02084371535684047
0.0214321804530358,194.333007563425,0.06804717293838866,39.177534324786485,198.4979876495055,0.02120574095502522
0.0218107797093025,194.332638185552,0.06924922557703543,39.177459858207285,198.5711845473447,0.0215763275842038
0.0221837181634464,194.269691090098,0.07043330516894232,39.164769723763754,198.5793151649405,0.021941238995335562
0.0225593414336889,194.219872574763,0.07162590905196226,39.154726311072224,198.60134499338463,0.022308642882787184
0.0229410817474736,194.168999940786,0.07283793454822868,39.14447038806246,198.62344684125276,0.02268189171118179
0.0233110069185669,194.071247441469,0.0740124469664499,39.12476348420015,198.59524363327202,0.02304345534957444
0.0236863308206727,194.00216780221,0.07520410035563581,39.11083702892554,198.5973673287008,0.023410162134573264
0.0240473021431135,193.941134852558,0.07635018430438535,39.0985327862757,198.6048959203358,0.02376271904956356
0.0244244217272042,193.858578508403,0.07754753898387333,39.08188942729405,198.59346218532858,0.024130915089525137
0.0247946216977747,193.756176111218,0.07872292389043466,39.06124510402155,198.56028719950308,0.024492223438464807
0.025172276837888,193.619773638819,0.07992197896029439,39.03374636558591,198.49362418214454,0.024860673431150327
0.0255569264267796,193.56202856077,0.08114324140502523,39.022104957851234,198.5088790837158,0.025235807888484067
0.0259260789654007,193.523934347434,0.08231530071514721,39.01442516444269,198.5412511510206,0.025595696361003915
0.0263047408981357,193.53181977102,0.08351755235158084,39.01601486583763,198.62262414564137,0.02596472106657497
0.0266866304830304,193.513137265445,0.08473005178362152,39.012248472713715,198.6773508532599,0.026336753403995484
0.0270671095740173,193.442970236988,0.08593807289750492,38.99810279977678,198.67891230871595,0.026707274063720945
0.0274485347034776,193.383527788368,0.08714909768354137,38.986119202134994,198.69162226194797,0.02707857825398576
0.0278292505519584,193.253152881874,0.0883578705024679,38.9598356209858,198.63124329337958,0.027449054552193757
0.0282038271136917,193.132718797589,0.08954715108597114,38.935556109593946,198.57980060855346,0.02781342278142752
0.0285810362431828,193.029246671782,0.09074479007210538,38.914696129031256,198.5462225669025,0.028180217715054738
0.0289524813108575,192.919004743076,0.09192412816197257,38.89247135620412,198.50448862240913,0.028541276301503833
0.029332978889617,192.875558564344,0.09313220797453398,38.883712606571756,198.533173252035,0.028910999151372147
0.0297164241352536,192.810059412253,0.09434964662943018,38.87050797751021,198.53968491529096,0.029283447961493816
0.0301136028026122,192.782213308799,0.09561068889829373,38.86489420305388,198.5875803077886,0.029669090142728793
0.0305067416375423,192.709535060808,0.0968589046991968,38.850242268258896,198.588475057999,0.03005066343036625
0.0309001057811909,192.632337612752,0.0981078358552811,38.8346792627308,198.5846972218641,0.030432309730722324
0.0312921676040366,192.532061908236,0.0993526321428162,38.81446368070038,198.55680745861923,0.030812547628642294
0.0316798959793396,192.401780152938,0.10058366973440323,38.7881988788323,198.49704853442285,0.031188440629534388
0.0320614420824869,192.258586608648,0.1017950786118959,38.75933106030344,198.42267414806196,0.03155820218875465
0.0324407658048408,192.149858704797,0.10299943143036953,38.73741151488708,198.3833472704726,0.031925674526806204
0.0328147426931477,192.070589771258,0.10418680805074394,38.72143089788561,198.37333675352298,0.032287834938295845
0.033203943247969,192.052288343092,0.10542251981230157,38.717741329967346,198.42918162587858,0.03266459877114359
0.0335807883131381,191.971729710581,0.10661900289421346,38.70150070965313,198.41829172809898,0.03302926671511531
0.0339732818643144,191.874817686209,0.10786516991919821,38.68196324553974,198.39343495012653,0.03340893616275149
0.0343685402649791,191.779129741673,0.10912011534130862,38.662672555921276,198.37029848418234,0.03379113450274285
0.034743857111688,191.672393556634,0.1103117463296094,38.64115454101742,198.33183181062094,0.034153915037334406
0.0351258368385357,191.526905091158,0.11152453196235083,38.61182406637745,198.2544479095797,0.03452300081341036
0.0355120757587791,191.348489744443,0.11275084053412364,38.57585553247971,198.1436718085756,0.034896063551587
0.0359074181955078,191.259036062911,0.11400605277073726,38.55782167028286,198.12665425449168,0.035277775167880075
0.0363055625777923,191.192988717622,0.11527016118449054,38.5445065254726,198.13435773394477,0.03566204492285011
0.0366923678058982,191.167240789218,0.11649826778372678,38.53931574310635,198.18161950069467,0.03603522931143582
0.0370835360625287,191.118778323212,0.11774022699852861,38.52954570995954,198.2061384313873,0.03641248151167616
0.0374685607762935,191.022553392235,0.11896268046473185,38.51014676387458,198.17989354365474,0.03678366979735201
0.0378635756347215,190.976294699128,0.12021685264024076,38.50082101134421,198.20734007790728,0.03716434608166125
0.0382649363105366,190.911750823678,0.12149117278595371,38.487808966053485,198.21697680987907,0.037550989469588215
0.0386702323780206,190.849617879214,0.1227779878002154,38.47528296444954,198.22981695185965,0.03794127230435245
0.0390673200667322,190.740636941107,0.12403874121187472,38.453312407327175,198.1923624542176,0.03832350315259306
0.03949269937719,190.623920352549,0.12538932052257826,38.429782343073875,198.15217353313363,0.03873280508510133
0.0399014438607458,190.524569022639,0.12668708425786793,38.409753114964026,198.12677441758865,0.03912594314423229
0.0403093483692037,190.417450997177,0.12798218107222173,38.38815812103089,198.09305436499798,0.039518119278698464
0.0406849340897258,190.311793378996,0.1291746657348794,38.36685754520559,198.05461614911795,0.03987908684863956
0.0410959957645236,190.185030322693,0.13047978655236242,38.34130211305491,198.0008735233102,0.04027400033280619
0.0414904835733632,190.076920109826,0.13173228534542814,38.319507094140924,197.9633034413182,0.04065284444561647
0.0418825794860707,189.96155151127,0.13297718986827448,38.29624878467203,197.91763129173805,0.041029249348117296
0.0422905172820512,189.900149628835,0.13427239237051256,38.28387016517314,197.93112518857734,0.04142071184403236
0.0426852939350495,189.778635403976,0.13552580824378216,38.259372897441565,197.87939223878732,0.04179939888259864
0.0430872689382442,189.668708631518,0.13680207887892534,38.237211660114035,197.8410152894937,0.04218484360013551
0.0434841310581132,189.491641926545,0.1380621161095094,38.20151501239147,197.7315213184959,0.04256524000033071
0.0438768244080683,189.4028386025,0.13930891749561686,38.183612262264,197.71323369425158,0.0429414982162944
0.0442788919934378,189.261550063749,0.140585482079165,38.1551284928518,197.64184179753238,0.04332659171021371
0.0446841157252669,189.165911174604,0.1418720674277224,38.13584769280017,197.61862264080554,0.04371455811786625
0.045080156421415,189.08924425917,0.14312949663799263,38.12039164264867,197.6134169679805,0.04409358718460651
0.0454864142489245,189.02065762182,0.14441936524033527,38.10656457655892,197.6185295560102,0.044482245300854054
0.0458936024433873,188.907545809684,0.14571218775775466,38.083761235232295,197.57719361562962,0.044871641963687335
0.0462983862925953,188.768205323135,0.14699737647899005,38.05567019314402,197.50786861294543,0.04525858910471239
0.046702108678814,188.633357871656,0.14827919505523443,38.02848494692585,197.44293345142768,0.04564437247379986
0.0471086149629515,188.574812186102,0.149569852507371,38.01668213671817,197.458310405088,0.046032665727488105
0.0475274248268228,188.551595967315,0.1508995738251624,38.01200174701071,197.51296777062902,0.04643255369035744
0.0479500751379619,188.518414160184,0.15224148856302902,38.0053122946931,197.5578862840542,0.04683594653697834
0.048363014890755,188.401418038558,0.15355257227814711,37.9817258765733,197.51307862459615,0.04722991417482638
0.0487821564719408,188.255727613024,0.15488334679841204,37.95235468678564,197.4392479741816,0.04762964004263016
0.0491851548572981,188.135002486887,0.15616286667192147,37.92801650135642,197.3884517182827,0.048013819899139595
0.0496013984949835,187.966071871235,0.1574844402215726,37.89396008924097,197.28945190565682,0.04841047161436798
0.050006401716857,187.76249888221,0.158770325451021,37.852919774653536,197.15182582867473,0.04879626102404339
0.0504165350340246,187.587898935355,0.1600724987330281,37.81772042536757,197.04543081398842,0.04918678553718207
0.0508278064922978,187.462828194659,0.1613782856130455,37.79250616404326,196.991152550636,0.04957824069106125
0.0512436848726811,187.42017965086,0.1626986994707625,37.78390821761338,197.02428027566998,0.049973925031501415
0.051661006721448,187.35792610262,0.16402369634059738,37.771357902288194,197.03702518232402,0.05037082542923546
0.0520709676436922,187.276732897457,0.16532532226872274,37.75498935212733,197.02841359657685,0.05076057177756229
0.0524809593252063,187.133363240181,0.16662704585753,37.72608602922049,196.954301664778,0.05115019550834021
0.0528943560301959,187.023984040972,0.16793958039587198,37.70403518265996,196.91649723902088,0.05154290146179889
0.0533090992512849,186.919524353528,0.16925639012282956,37.682976109671245,196.88403582929317,0.051936731626125554
0.053722628759447,186.814639127259,0.1705693463112442,37.661831248055414,196.8508126319228,0.05232925491656708
0.0541268536179633,186.735119798218,0.17185276023703347,37.64580015132075,196.842504292869,0.05271279735339771
0.0545423134317826,186.668340882224,0.17317184514590975,37.63233752185636,196.8496640384131,0.053106846667237154
0.054961798091412,186.573564531823,0.1745037089402331,37.61323060961552,196.8279831148161,0.0535045559325259
0.055389516630815,186.472858726299,0.17586171530283762,37.592928319221876,196.80150023591494,0.053909908863363096
0.0558107776547445,186.339267528379,0.17719921905381378,37.56599633372121,196.73900695675331,0.05430898140106652
0.0562336877077418,186.200135805422,0.1785419584720802,37.537947378373076,196.67085609344323,0.0547094559796895
0.0566700879581447,186.098401585262,0.17992752926710942,37.51743775958882,196.64461437196894,0.0551225370311168
0.0571100856199443,185.948558682888,0.18132452184332315,37.48722943047022,196.56809679017297,0.05553885058505613
0.0575324502740775,185.811783653394,0.18266552962019605,37.45965558452423,196.50199085677053,0.05593831730586643
0.0579501965571468,185.691432181185,0.1839918740689411,37.4353927277269,196.45228717506276,0.05633325913072606
0.0583679833974445,185.551248056365,0.1853183472868863,37.40713160816318,196.38150022229402,0.05672808335865376
0.0587868603279903,185.481885418686,0.1866482815413692,37.393148100407096,196.38578311016659,0.05712378132779637
0.059216558344478,185.384584941111,0.18801257274371763,37.37353232412798,196.36242203144312,0.05752953895650926
0.05964811768469,185.272451709311,0.18938277364889075,37.3509262645971,196.32360471259904,0.05793688856317529
0.0600739514746313,185.160504207643,0.19073479593195436,37.32835764826083,196.28382735243122,0.05833867123257857
0.0605047369596084,185.042200281378,0.19210253984675668,37.304507576725804,196.23812993582993,0.058744961735498744
0.0609247066928979,184.903263110894,0.19343594374995082,37.27649784315623,196.16844018248494,0.059140892639571424
0.0613558642053236,184.785504214501,0.19480486885190243,37.25275764964341,196.1231785181982,0.05954720792537255
0.0617748072691631,184.68438517374,0.19613501307959283,37.23237205102598,196.09322747347167,0.05994185444892913
0.0622101009628956,184.562665046588,0.19751707055719353,37.20783327339214,196.04432707311733,0.06035173843458254
0.0626419963484679,184.508843509625,0.19888833840638556,37.196982851540405,196.06684581101496,0.060758256509008984
0.0630628952325387,184.420389057473,0.20022469236331036,37.17915043398656,196.05047273134844,0.06115426527884187
0.0635145185657175,184.365892110756,0.20165859644615308,37.16816384952841,196.07580298810967,0.061579007248767914
0.0639511168847094,184.276055301216,0.20304479610895235,37.150052748725145,196.0607148528372,0.06198944708652209
0.0644008686637082,184.152417086027,0.20447275800727352,37.12512728454304,196.0119927128886,0.06241207622751659
0.0648572415157082,184.025132478404,0.2059217418123735,37.09946670764625,195.96049494051607,0.06284074465132754
0.0652915231692564,183.853465347672,0.20730058606238908,37.064858614090674,195.8575381401676,0.06324849237934053
0.0657323943220232,183.706877205306,0.20870035197242365,37.03530644458969,195.78237009743268,0.06366225700716847
0.0661668493230091,183.548973720126,0.2100797466005539,37.003473101977406,195.69383100765856,0.06406983256055857
0.0666010766036988,183.436582240147,0.21145841821674366,36.98081497961364,195.65365610584374,0.06447702856290922
0.0670431495992137,183.328006938938,0.2128619999775035,36.9589261988899,195.61889393387088,0.06489141161366492
0.067484382689875,183.244559506628,0.2142629150403531,36.9421031965362,195.61070548621086,0.06530483621491408
0.0679308078476602,183.182959161279,0.21568031491632114,36.92968456691385,195.62672556102962,0.06572295177976258
0.0683681457550377,183.085304423029,0.2170688627722447,36.90999737168264,195.6025072014281,0.06613238690376488
0.0688063559412375,182.895171720916,0.21846018011342908,36.87166661893667,195.47952200627913,0.06654247058386964
0.069229336402412,182.655369990472,0.21980314307765808,36.82332259007916,195.3004800452494,0.06693814261891325
0.0696634531211744,182.437636509547,0.2211814636597287,36.779427520324674,195.14687224806767,0.06734406920564992
0.0700980136446315,182.314933367044,0.22256119332170501,36.75469056679607,195.09484805382712,0.0677502458156889
0.0705406370747368,182.28985784403,0.22396652271228934,36.749635341356445,195.1487005486111,0.06816378916291818
0.0709847460075682,182.21681350866,0.22537656857402902,36.73490960334586,195.15142773388064,0.0685785486074769
0.0714397726159344,182.203375288243,0.2268212780555917,36.73220045810979,195.21994298869083,0.0690033258738429
0.0718968906627256,182.122338310034,0.22827262785415378,36.715863403302855,195.21636815475043,0.06942987393934626
0.072347032377837,182.042335914152,0.22970182779963247,36.69973492029305,195.21255868467026,0.06984973449428337
0.0728000937981493,181.98033114001,0.23114029780912404,36.68723475782602,195.22851631642098,0.07027214041835289
0.0732447670659536,181.842507205797,0.23255213543440267,36.659449452688676,195.16151928877457,0.07068655232770055
0.0737149547213376,181.732977756571,0.23404498124024686,36.637368315724714,195.12941598327046,0.07112455557306155
0.0741810420964742,181.609905713079,0.2355248086563056,36.612556991756726,195.0819177739176,0.07155854994070572
0.0746486604493349,181.494887448857,0.23700949692663828,36.58936930968957,195.043237675317,0.07199378067089181
0.0751085752092008,181.367622234486,0.23846972628921254,36.56371264247238,194.9898859295988,0.07242165667405535
0.0755663314122871,181.236658440757,0.2399231022340115,36.537310341656614,194.93204783654673,0.07284734277713807
0.0760264315116053,181.102846652539,0.24138392004934683,36.510333885151866,194.871449820125,0.0732750260397514
0.0764948139042246,180.986601463079,0.2428710341459131,36.48689885495673,194.8311378611553,0.07371022025770319
0.0769703017652469,180.875725263747,0.2443807081046589,36.464546213171396,194.79778441930551,0.07415182283142478
0.0774341104976487,180.701271322649,0.24585330083003462,36.42937629864604,194.69371353331258,0.07458239077579679
0.0778876298224444,180.552339537526,0.24729322468626097,36.39935165076525,194.61513332300112,0.07500322755668672
0.0783351841818321,180.355535731451,0.24871420977731687,36.35967600346052,194.4837198411872,0.07541835568065249
0.0787947890755988,180.235089502538,0.25017345531502616,36.33539404371166,194.43667536391214,0.07584448197477424
0.0792468130973267,180.114741972563,0.25160863158401225,36.3111319816687,194.38826126573593,0.07626340256266591
0.079713050953247,180.032885168455,0.2530889367765592,36.294629649960534,194.38385571714815,0.07669531227153241
0.0801820071247607,179.951223250637,0.2545778726211152,36.27816660732842,194.38007351542902,0.07712955205288548
0.0806388447687018,179.899885973408,0.2560283321406282,36.26781701223905,194.40680495232482,0.0775523891893814
0.0810984710033531,179.78025060499,0.25748764543564606,36.24369852196598,194.36015404565433,0.07797762701844034
0.0815541213182801,179.621018523061,0.2589343351855393,36.2115973342491,194.26985285900372,0.07839900798668908
0.0820134140324429,179.474804352543,0.2603925895530062,36.18212055747267,194.19414579029979,0.07882357778962594
0.0824957110870914,179.34543182286,0.2619238827015152,36.15603905548858,194.14066075130833,0.0792692188424016
0.0829730705952253,179.318280856231,0.26343949913984027,36.150565420616175,194.19686923272948,0.07971010214665802
0.0834606832004118,179.2677613702,0.26498766916130745,36.14038069223232,194.2295712099653,0.08016025448809605
0.0839386640177875,179.180532746455,0.2665052582564753,36.12279540168532,194.22070728318783,0.08060131840715447
0.0844053104978143,179.083832490041,0.2679868608305604,36.10330062999227,194.1994589765015,0.08103173580652984
0.0848803650930282,178.957758545938,0.2694951591703645,36.0778841228611,194.1477584275472,0.08146971832598605
0.0853893676946475,178.840772216315,0.27111124243050577,36.05429967880911,194.11187267388863,0.08193878685075273
0.0858841935877256,178.722031894183,0.27268231464102877,36.03036162986729,194.0714294797747,0.08239458008700663
0.0863602621228418,178.527581173154,0.2741938322400227,35.99116036450785,193.9452698794245,0.0828328995786151
0.0868308902347466,178.358824317864,0.27568807649532046,35.95713898248138,193.8458798146069,0.08326602127502122
0.0872687248809332,178.144050930784,0.2770782014969629,35.913840667646056,193.69045510063754,0.08366879458776325
0.0877382568699166,177.991476854423,0.2785689655619852,35.88308173385168,193.6081387713322,0.08410054676163368
0.0882147850719274,177.852776170345,0.2800819426033695,35.85511967594156,193.54202059465763,0.08453854170035144
0.0886919820575632,177.775653608857,0.2815970430327632,35.83957176754557,193.5429286890053,0.08497695918380516
0.0891812556737423,177.770893185346,0.2831504867641318,35.83861206616576,193.6247246618579,0.08542627240914258
0.0896510524632827,177.730552613436,0.2846420915709226,35.8304794068687,193.6642837101114,0.08585750963200402
0.0901390205622077,177.628287844759,0.28619139028500945,35.809862829503416,193.6395277352275,0.08630522990847897
0.090633920120925,177.530930125297,0.28776269638393687,35.79023551325988,193.62125426526669,0.08675910528264622
0.0911326534717227,177.415368897697,0.28934617477271957,35.766938369775716,193.58370223200868,0.08721628834294351
0.0916421708495824,177.330062494978,0.2909638924474241,35.749740598987565,193.5809743789099,0.0876831412509363
0.0921334650103061,177.190416628289,0.29252375140772185,35.72158799226306,193.515583678873,0.08813309055977989
0.0926260760786591,177.069646404892,0.2940877915497426,35.69724071522623,193.47091294401278,0.08858404277437047
0.0931231789182142,176.951158481171,0.2956660930653301,35.67335354980408,193.42941287219838,0.08903890084831428
0.0936211727984998,176.803591408755,0.2972472236352368,35.643604028005015,193.3561509914294,0.08949436688256146
0.0941052024636473,176.636286456328,0.29878401782208014,35.609875349595725,193.25867995572756,0.08993686250588862
0.0946063897332499,176.449636496212,0.3003752874030684,35.57224671763634,193.14289957486292,0.09039483721589549
0.0950945399348479,176.270417251497,0.3019251642931421,35.5361161179018,193.0327714841518,0.09084069738161114
0.095581345049425,176.196749200518,0.3034707705319244,35.521264638824434,193.03787148243973,0.09128513110722669
0.0960540334591604,176.10673926646,0.30497155623283423,35.50311863611834,193.0225018923442,0.09171648791201281
0.0965476953089697,176.014187369795,0.30653893260597875,35.48446017375067,193.00795150202987,0.09216678570360326
0.0970539361226203,175.906217328813,0.30814624718931943,35.4626934134887,192.9786081090154,0.09262834701481337
0.0975841281054459,175.77403859551,0.3098296067347907,35.43604618085482,192.92679489542584,0.09311151733959915
0.0980968125797072,175.632853174815,0.3114573799405704,35.40758320004271,192.86187625554408,0.09357851094880602
0.0986005038645607,175.529345759648,0.31305659976998024,35.38671610514504,192.836627694566,0.09403710056869612
0.0991038406039988,175.413981898131,0.3146546939176961,35.363458750663206,192.7981811998761,0.09449515740378002
0.0996118336252615,175.342866380671,0.31626757176020526,35.349121862343274,192.80909081395887,0.09495723900555852
0.100129233941899,175.257086957451,0.3179103177655293,35.33182873062213,192.80544481738937,0.095427658305182
0.100657685865254,175.141617291437,0.31958815262218143,35.3085500459537,192.770967186691,0.09590789737672056
0.10117351728495,174.978398751624,0.32122591737971623,35.2756451883274,192.68157880221432,0.09637644503686366
0.101678459778547,174.778472933942,0.3228291097968867,35.23534014348271,192.5496788643117,0.09683488936966336
0.102193966731163,174.63935761577,0.3244658443714425,35.207294495339234,192.48644631790768,0.09730270860984899
0.102704693295955,174.544929549106,0.32608740121465707,35.188257797099766,192.47151300481102,0.09776597395912336
0.103225107079478,174.439859069588,0.32773971497734267,35.16707558842894,192.4464322009753,0.09823780564940586
0.103748246504921,174.325792282838,0.32940068265312417,35.14407972422014,192.41178755276354,0.09871188426425762
0.1042548268043,174.199877744911,0.33100907510365246,35.11869535337406,192.3610558285369,0.09917074260045375
0.104785144976261,174.084144473729,0.3326928352996287,35.09536352590377,192.32557679047704,0.09965087712850511
0.105313033821495,173.993488776159,0.3343688823832466,35.07708733727366,192.31727094436255,0.10012858337733793
0.105855160294916,173.879955987382,0.3360901339363583,35.054199127056215,192.28604660049928,0.10061893638234796
0.106384260336157,173.756471471666,0.33777002656729843,35.02930464868787,192.24142516779975,0.10109727525145504
0.106916808453339,173.5926445083,0.3394608668393513,34.99627713287328,192.15261603010248,0.10157850045390841
0.10743559005706,173.448800431665,0.34110799843116546,34.967278167023665,192.08337465073018,0.10204706328389128
0.107951742282447,173.280207385773,0.3427467817467692,34.933289808971836,191.98610767613093,0.10251303347988505
0.108478044294648,173.095365496727,0.34441779063550737,34.89602568414016,191.87241222227925,0.10298794319755823
0.109004680417829,172.979244551251,0.34608986032660705,34.872615701532204,191.83479182247763,0.10346292875412041
0.1095316634179,172.850699111989,0.34776303135183245,34.84670094097699,191.7833237086721,0.10393800144017
0.1100763567036,172.738695163239,0.34949243253393,34.824120944908984,191.7531413885421,0.1044288027813945
0.110603766391015,172.619337579318,0.3511669582914726,34.80005845599051,191.71168646751266,0.10490380113153636
0.111146829096388,172.492487650782,0.3528911823810319,34.77448551039765,191.66448069611428,0.10539266132789787
0.111678455023942,172.398723342025,0.35457909470101584,34.75558262575224,191.65194641296236,0.10587099486269111
0.112226350130324,172.316563208374,0.3563186616637787,34.739019142808196,191.65502216425108,0.1063637273899083
0.112765118040022,172.226102206341,0.35802924977706985,34.72078220479835,191.64719895121195,0.10684801501791524
0.113314735376906,172.107294405229,0.35977428482167656,34.69683055209417,191.60958692719277,0.10734181342969136
0.113856940131089,171.98232600368,0.3614957849162076,34.67163692234189,191.5637073990864,0.1078287132684935
0.114408177968767,171.827372057329,0.3632459650508352,34.64039820675753,191.48582861956942,0.10832348190661058
0.114955219908736,171.686493908411,0.3649828232102368,34.61199717193566,191.42275257101224,0.1088142425887581
0.115504995176564,171.461969037672,0.3667283596855907,34.566732957994674,191.26668294433247,0.1093072128513466
0.116057664980698,171.262107996632,0.3684830863137161,34.526440972121016,191.13838835039323,0.10980253375386999
0.116603264187607,171.087795944198,0.3702153637956522,34.49129966235032,191.0371914139547,0.11029127721745795
0.117135146643001,170.97834325728,0.3719040905915281,34.46923400066765,191.00591656749884,0.11076750349611926
0.117675936202858,170.859156270395,0.3736210974440741,34.44520590411164,190.96516744334417,0.11125147243162674
0.118203706466708,170.703107527259,0.37529676803179784,34.413746477495415,190.880847542366,0.11172356427734155
0.118733286964857,170.447589489192,0.37697818611342093,34.36223404102111,190.68539204448038,0.11219705146951355
0.119266416814281,170.17805745776,0.37867087338534217,34.30789638348441,190.47458459116186,0.11267348572337722
0.119801627291914,170.019037127892,0.38037016665182694,34.275837884983034,190.3875944464178,0.11315155113030868
0.1203559875087,169.919637076409,0.3821302603401225,34.25579883460406,190.3704827938601,0.11364648079457819
0.120922167944465,169.966048372158,0.3839278832236764,34.265155351827055,190.51871141827317,0.11415171076474587
0.121489629285048,169.938167917213,0.38572957298002736,34.25953465211014,190.58389293885546,0.11465782775306825
0.122069189646767,169.846564827473,0.38756967712848517,34.24106746921856,190.5795973602497,0.11517447155105545
0.122644541673611,169.700858935025,0.38939641981371487,34.21169316130104,190.51374300072925,0.1156870999823925
0.123223949604756,169.495399713764,0.39123603999510026,34.17027258229482,190.3812923063308,0.11620307671589207
0.12380207765468,169.2904539686,0.39307159655360896,34.12895552006976,190.24896389701664,0.11671764847043972
0.12436788048623,169.085562143036,0.39486802054378023,34.08764932803606,190.11437512758812,0.11722099372816547
0.124940239225288,168.908161667473,0.3966852595402894,34.05188539216256,190.0115877933107,0.11772991355679688
0.12551758186356,168.758735465686,0.39851832241680296,34.021761069882295,189.94092385969108,0.11824300262296603
0.126095346594989,168.603645623504,0.40035272543909006,33.99049495769841,189.86378075557843,0.11875620339278518
0.126680286806658,168.450115507488,0.4022099106111391,33.95954328630958,189.78942445259122,0.11927550963539679
0.127268255902307,168.27978140852,0.40407671248982474,33.92520393195763,189.6964556920038,0.11979723326647791
0.12785288117565,168.072114122411,0.4059328977326887,33.883338207078054,189.5606181582439,0.12031572008018188
0.128437668431174,167.858619354715,0.4077895972689774,33.84029766191054,189.4179890507105,0.12083408175015387
0.129022150593375,167.625455918664,0.4096453281339656,33.79329191320266,189.25285273548502,0.121351904632613
0.129595259497461,167.441557908748,0.4114649489044387,33.7562180744036,189.14119005659134,0.12185939112751507
0.130176126880673,167.261184749621,0.41330920284613676,33.7198548455236,189.03459795779935,0.12237348507481138
0.130749692667188,167.077810023702,0.4151302742183219,33.682886500778324,188.92318233580787,0.12288085758023405
0.131338804491127,166.909820028478,0.4170007042593282,33.64901971774117,188.83155624884748,0.12340171415856635
0.131935665954476,166.740739178705,0.4188957394054613,33.61493301842693,188.73978964398904,0.12392914597028812
0.132545701109384,166.576857357868,0.42083260102229414,33.58189444334619,188.65590370496446,0.12446793174131554
0.133149700087981,166.383452743844,0.42275029777933965,33.54290407315895,188.53735957628956,0.12500110049170082
0.133755673309929,166.151306849491,0.42467426275902453,33.496103460857384,188.37498676846928,0.12553572645667732
0.134362847081084,165.909334266989,0.4266020394824417,33.44732178822498,188.20138477642888,0.12607112509673984
0.134964727038177,165.637208054234,0.4285130083462119,33.39246114373358,187.99238862663944,0.12660157295104704
0.135571763132646,165.389716851534,0.430440347946151,33.34256691726925,187.81189236910555,0.127136280154882
0.136188615733796,165.1323854172,0.4323988549548023,33.29068890010752,187.62153639998814,0.1276793414936114
0.136795749457912,164.903941567558,0.4343265045288706,33.244634620019696,187.46209984285582,0.12821355875251794
0.137409103446289,164.641491983687,0.4362739034419676,33.1917247839113,187.2647317872248,0.12875295959186206
0.138018421191478,164.365768290823,0.43820848728294265,33.13613888742992,187.0512721282467,0.12928852291185838
0.138615454042044,164.002474144298,0.4401040665834897,33.062898787490475,186.73575156182847,0.12981301028837283
0.139228111197064,163.629655542334,0.44204925305067816,32.98773855733454,186.41150341931936,0.13035093763258795
0.139844899678292,163.298795895087,0.4440075564785771,32.921037252449544,186.13529962462133,0.13089220023658787
0.140457047948201,163.041524214225,0.44595112723553815,32.86917128158776,185.94185539833018,0.13142910131256266
0.14106315744418,162.737838090185,0.44787552488527144,32.8079481589813,185.69415136682625,0.13196042205984804
0.141664790893709,162.398432742693,0.4497857110875261,32.73952404092691,185.40457275865265,0.1324875400319195
0.142263520288279,162.001270013564,0.45168667691528575,32.659456034734504,185.04814097686562,0.1330118379315987
0.142879806615652,161.650099224945,0.45364338600469506,32.58866000374891,184.7466341416061,0.13355122321659066
0.143493573080977,161.369838496583,0.4555920945321019,32.53215944091113,184.52537320995788,0.13408811407223006
0.144124584167445,161.097237260417,0.4575955547316379,32.477203031700064,184.3153095910988,0.13463978927245734
0.144751533774126,160.756870500387,0.45958611973285,32.40858509287802,184.0266740700466,0.13518761238743168
0.145381040739098,160.353162484995,0.4615848043466361,32.327197556974994,183.6654721328693,0.13573736831670188
0.146012605421563,159.920405602995,0.46359002221346246,32.2399537695638,183.27080068516142,0.1362886177273094
0.146638157329418,159.508727851058,0.46557614952090215,32.15695953477329,182.89879378109677,0.1368343196140007
0.147232666442378,158.918225141482,0.46746371595455016,32.03791418852278,182.31617917535254,0.1373526653901535
0.14786070518935,158.456283624212,0.4694577389761862,31.94478677864114,181.88574146257164,0.13789995359237728
0.148504697131905,158.009697175499,0.4715024133937984,31.854754950580602,181.47487939845053,0.13846083293569672
0.149160936312733,157.627504209154,0.47358597279292725,31.77770484856545,181.1393703256307,0.1390320554748859
0.149838442099291,157.215029140206,0.47573705366524893,31.694549874665533,180.77188418116913,0.13962144737514715
0.15049488082185,156.657510045081,0.47782124660937375,31.582154025088332,180.23366334916327,0.14019218095869945
0.151124971671772,156.062848229987,0.47982178505787604,31.46227020316538,179.64784174775983,0.14073970045022616
0.151767734273711,155.45223759489,0.48186255631903246,31.33917109912982,179.04487148244505,0.14129792239167444
0.152395870340157,154.84800323863,0.48385688832999846,31.217357452907812,178.4461994626165,0.14184314069192755
0.153026503755649,154.117247987383,0.4858591494241855,31.07003719425641,177.70127161533455,0.14239022780126348
0.153645547581042,153.357710622125,0.4878246135698084,30.9169144614204,176.9204400464364,0.14292696976238978
0.154287404484831,152.686070661688,0.4898625092393384,30.781511845396302,176.24360820506735,0.14348318775803168
0.154930250877513,152.026429974135,0.49190354653610374,30.648528282785616,175.5799229100404,0.1440399532996387
0.155595327879115,151.511084256334,0.4940151660161901,30.54463458607693,175.08550108851847,0.1446156465757359
0.156232514336097,150.797839140868,0.4960382330171079,30.400844370798993,174.35736470629612,0.1451668869937996
0.156858892298465,149.994106556348,0.4980269830476264,30.23881188175975,173.52201596207468,0.14570848078977536
0.157501141011726,149.198830733346,0.5000661227122299,30.078484275842552,172.69781681146335,0.14626349273303704
0.158161547526424,148.381888848268,0.5021629133963962,29.91378879181083,171.8501980134039,0.1468338750567419
0.158844566527806,147.530003914923,0.5043314987257841,29.742048789248475,170.96434343663444,0.1474234453794298
0.159526191740045,146.680356025033,0.5064956587746429,29.570759774646653,170.07971462478048,0.14801146628113293
0.16021398088907,145.791756565194,0.5086793893227972,29.391618123543108,169.14963426531392,0.14860445439014136
0.160906556656559,144.850169303387,0.5108783173845748,29.20179413156282,168.1575112771146,0.1492012142540431
0.161546855060931,143.853635902629,0.512911264818456,29.00089299797001,167.09273837177895,0.14975261254463046
0.162197101932545,142.823669091134,0.5149757986358303,28.793251688772617,165.98925430508874,0.1503122670509966
0.162811865103102,141.752971172135,0.5169276717023488,28.577398988302416,164.83203679257656,0.15084109355756084
0.163445379269856,140.728261712399,0.5189390791817927,28.37081756121964,163.7296458219696,0.1513857574668923
0.164070970964747,139.593905506051,0.5209253328130716,28.14213135001988,162.4972131231899,0.1519233190697509
0.16472526430515,138.497073256043,0.5230027141688512,27.921009968418268,161.3110402536344,0.1524852345758907
0.165416783526155,137.382096567837,0.5251982876955421,27.69623066807594,160.10740109616825,0.15307877713862852
0.166099777133313,136.204767330426,0.5273667923982688,27.45888109381388,158.82834882850452,0.15366465642271263
0.166778474287163,134.94628334054,0.5295216558617425,27.205170721452866,157.45241858679844,0.15424651033865072
0.167382238573405,133.628562820224,0.5314386074705608,26.93951826455716,155.99561080241998,0.15476383915528344
0.167960078386384,132.336128112541,0.5332732488767692,26.678963427488267,154.5633145636739,0.15525870435819175
0.168563533114727,131.109681950442,0.5351892176392582,26.431711881209107,153.20999316555665,0.1557752450332273
0.16920878715311,129.796398638062,0.5372378992111242,26.166953965433294,151.75908982845004,0.1563272697528072
0.169854576398951,128.538344908145,0.5392882800666694,25.913330333482037,150.37117103354024,0.15687944740845539
0.170500126492001,127.055909944724,0.5413379016121032,25.61447144485636,148.7189586618557,0.1574311160154616
0.17111630810151,125.587531878264,0.5432942782222941,25.318446426658024,147.07760667685324,0.1579574034249863
0.171702696262183,124.048884301135,0.545156060632431,25.00825507510882,145.34841220395546,0.15845798684336038
0.172294891158145,122.491980218243,0.5470362794271103,24.69438321199779,143.59672261769083,0.15896327312158848
0.172911608662104,120.88912741636,0.5489943575021802,24.371248087138174,141.79226090768088,0.1594892118977451
0.173538998906359,119.217841851457,0.5509863215276898,24.034316917253733,139.90678677813546,0.16002396874042668
0.174168811796355,117.413458567427,0.552985977453427,23.670553247193283,137.86322113501632,0.16056050305890826
0.174823516974017,115.60174797218,0.555064666392504,23.30531239119149,135.81165212102042,0.16111793799523938
0.175506592388876,113.501949595496,0.5572334308346812,22.88199303845199,133.42228999849547,0.16169919713953596
0.176273650034831,111.104612437854,0.5596688388605884,22.39868986747137,130.6894280079798,0.1623515180148609
0.176669903064544,109.911852440975,0.5609269422299271,22.15822945210056,129.32996875736652,0.16268833275309558
0.176877922180698,109.207993657276,0.5615874029237161,22.016331521306842,128.52447666089782,0.16286510342625918