File: example/data/02 processed data/test_ID_080.csv
Strain,Stress_MPa,Displacement(mm),Force(kN),True Stress (MPa),True Strain
0.001167465321559093,74.3707347253824,0.0037067023959501204,29.986280241274187,74.45755997911317,0.0011667843638654787
0.001269495900022793,81.1088767541977,0.004030649482572368,32.70309910729251,81.2118441406926,0.001268690771435623
0.001372807646219593,87.773270119212,0.0043586642767472076,35.39018251206628,87.89376593556536,0.0013718662073140386
0.001474218955818193,94.4234888839346,0.004680645184722763,38.07155071800243,94.56268978112178,0.001473133361857763
0.001575398866204293,101.030436287347,0.00500189140019863,40.73547191105831,101.18959952212623,0.0015741592271903899
0.001675647142316193,107.604228612178,0.005320179676853913,43.38602497643017,107.78453533035315,0.0016742448119655068
0.001782681423147493,114.178792120351,0.005660013518493289,46.03688898292553,114.38233653198137,0.0017810943325239049
0.001882009231626693,120.686113252501,0.00597537931041475,48.66064086340841,120.91324563177136,0.0018802404711208056
0.001983565419760293,127.215949067175,0.00629782020773893,51.29347066388497,127.46829022458662,0.0019816007514760104
0.002083865013789193,133.652052369257,0.006616271418780688,53.88850751528443,133.9305652052104,0.002081696778774805
0.002189118491756093,140.010326410038,0.006950451211325596,56.45216360852733,140.31682560461903,0.0021867258630662526
0.002286183272272293,146.22007265748,0.0072586318894645304,58.95593329549593,146.55435854165995,0.0022835739314924623
0.002383057840336193,152.326227074935,0.007566208643067412,61.41793475661379,152.68922928465474,0.002380222861054015
0.002486644345176593,158.406047302999,0.007895095795935683,63.8693182725692,158.7999468047668,0.002483557760892834
0.002584850542631093,164.373999574955,0.00820690047285372,66.27559662862186,164.79888179695078,0.002581515562181733
0.002691073778572093,170.339609923968,0.008544159246966394,68.6809307213439,170.7980063816866,0.002687459322590982
0.002796220153886793,176.134369351097,0.008877998988590567,71.01737772236231,176.62687982446866,0.0027923180028020388
0.002898489496143793,181.895747966131,0.009202704150256542,73.34036557994403,182.42297088100403,0.0028942969748296057
0.002999123828613793,187.581700578084,0.009522218155848791,75.63294167308347,188.14428132609962,0.0029946354286829163
0.003097412775923793,193.205397558862,0.009834285563558042,77.90041629573317,193.80383442563826,0.0030926256755082456
0.003205361590095893,198.805249884603,0.01017702304855446,80.15827675347192,199.44249259649254,0.0032002353699727105
0.0033088320090725928,204.28575033164,0.010505541628805482,82.36801453371726,204.96169756133474,0.0033033698699911147
0.003415344494759693,209.620971667458,0.010843718770862026,84.51917577631906,210.33689949902865,0.0034095254513453526
0.003524944476956993,214.830950114422,0.011191698714338451,86.61983908613495,215.58821728550723,0.0035187464211055256
0.003641135080028793,219.897277181989,0.011560603879091417,88.66258215977798,220.69795287193915,0.0036345221951034658
0.003768495203357393,224.826368023743,0.011964972270659723,90.64999158717318,225.67362511322872,0.0037614122145377235
0.003905835540493993,229.641449478052,0.012401027841068427,92.59143242955057,230.53839121299393,0.003898227568748956
0.004061368440629593,234.237564495558,0.012894844798998956,94.444586004609,235.18888954761022,0.004053143346395507
0.004259584949267393,238.631413764283,0.013524182213923973,96.2161860297589,239.64788454277576,0.0042505385973357285
0.004500707332081393,242.665327698739,0.014289745779358423,97.84266012813156,243.75749331835462,0.004490609435950371
0.004791426876153993,246.084361911837,0.015212780331788927,99.22121472285268,247.26345713730257,0.00477998452596526
0.005116292062084293,248.709011357487,0.01624422729711763,100.27947337933877,249.9814792980641,0.005103248311360202
0.005459849513533493,250.503407490878,0.01733502220546884,101.00297390032202,251.87111839840554,0.005444998566611652
0.005816888226162393,251.648000749841,0.018468620118065597,101.46447390233588,253.11180904254007,0.005800035454057303
0.006178314695371493,252.404009929976,0.019616149157804488,101.76929680376634,253.9634413336971,0.006159307158653746
0.006548865009192793,252.948466941618,0.02079264640418712,101.98882187086038,254.6049923059009,0.006527514357070022
0.006919428928142293,253.368399454222,0.021969186846851778,102.15813865994231,255.12156408688261,0.006895599540481332
0.007290008020088593,253.717792242965,0.02314577546378128,102.29901383236349,255.5673969832554,0.007263564350227391
0.007668579936402993,253.994436996012,0.0243477412980795,102.41055699679204,255.94221363951758,0.0076393258403458135
0.008050550557494093,254.270630548158,0.025560498020043742,102.5219182370173,256.3176491146719,0.008018317754333034
0.008432050009073594,254.500712676356,0.02677175877880866,102.61468735110674,256.64667541298786,0.008396698858165897
0.008815538381985894,254.72406451755,0.02798933436280521,102.70474281347617,256.9695942851199,0.008776908386970397
0.009189835505296994,254.925488403437,0.029177727729317954,102.78595692426579,257.2682117079721,0.009147865900212682
0.009561153232376093,255.143423981642,0.030356661512794095,102.87382854939806,257.5828893545636,0.009515734679807566
0.009936208921640193,255.339528253698,0.031547463326207614,102.95289779189103,257.8766351523798,0.009887169374999318
0.010310831447955894,255.560802652774,0.03273688984725996,103.04211562959847,258.19584701363107,0.010258037415514861
0.010690111691909594,255.764822307561,0.03394110462181296,103.1243763544086,258.49897682489024,0.010633376427298993
0.011068591730675193,255.959897975673,0.035142778744893736,103.20303086379135,258.793013585791,0.011007783167872126
0.011445237778840694,256.162766908389,0.0363386299478192,103.28482761746245,259.0946106857413,0.011380236544481155
0.011822774899816995,256.355016116438,0.03753731030691895,103.3623424981478,259.3858437664216,0.011753431912561101
0.012195416998980194,256.535849583117,0.03872044897176211,103.43525455191276,259.6644112439708,0.012121652025270708
0.012566494808049694,256.736978709873,0.03989862101555778,103.51634981582077,259.96326261986496,0.012488191726615567
0.012926287580219693,256.917746813736,0.041040963067197525,103.58923551529837,260.2387394935124,0.012843456163085076
0.013296783333805493,257.123382404644,0.04221728708483244,103.67214778555247,260.5422963105338,0.013209157021034442
0.013663892234781193,257.314263207849,0.043382857845430285,103.74911092540474,260.8301775707932,0.013571382997506884
0.014031100107483693,257.508184315138,0.04454874284126072,103.82729991586365,261.1213074277601,0.013933575416094192
0.014393577883921494,257.678060752967,0.04569960978145074,103.89579409559629,261.38696998939264,0.014290973730391014
0.014752275744190094,257.877603681858,0.046838475487803545,103.97624980452514,261.6818851996237,0.01464451939923829
0.015111996813627494,258.095045673668,0.04798058988326729,104.06392241562293,261.9953771815015,0.014998948094857313
0.015470391445658394,258.296413654857,0.049118492839965396,104.14511398563835,262.29236028310737,0.015351944986610796
0.015828248587625594,258.502153898415,0.05025468926571126,104.22806845184093,262.5937902507557,0.015704288200569193
0.016182901957739294,258.672744405704,0.05138071371582226,104.29685054437985,262.8588200675609,0.016053354566292338
0.016530897300426093,258.844080462251,0.05248559892885284,104.3659332423796,263.12300537319567,0.016395749394539735
0.016879199643157792,259.036474503739,0.05359145886702599,104.44350651990757,263.40880287174735,0.01673832893288442
0.017223491754930792,259.220904899054,0.05468458632190526,104.51786885529859,263.68559401728857,0.017076848828184412
0.017573087679908693,259.415442317065,0.055794553383710095,104.59630634224062,263.97417263042513,0.017420466398560795
0.017927440636636593,259.608022650308,0.05691962402132118,104.67395473260419,264.262130065166,0.017768639199675768
0.018281628098639393,259.796814002516,0.05804416921318007,104.75007540581444,264.54632273732136,0.01811652829516531
0.018637304606477192,260.001756132707,0.05917344212556508,104.83270807270746,264.8474880599712,0.01846575820877842
0.018987699210876192,260.197122715152,0.0602859449945319,104.91147987874928,265.13766741680274,0.018809682735810046
0.019338376162475693,260.339961072516,0.061399344315860326,104.96907230443847,265.3745131698606,0.01915376601011649
0.019691334818228493,260.528513806015,0.06251998804787547,105.04509676658525,265.6586680010647,0.01949996857634443
0.02004309231205549,260.710611102134,0.06363681809077618,105.11851839638044,265.9360579471865,0.019844873768545313
0.02039443623901579,260.904067295429,0.06475233505887514,105.19651993351698,266.2250586603855,0.020189254741269456
0.020746591100798094,261.105668993919,0.06587042674503395,105.27780573834815,266.52272154263613,0.020534311609520486
0.02109063059436399,261.28576876939,0.06696275213710567,105.35042196781806,266.7964503980696,0.020871301740923883
0.021443728243721594,261.473279953695,0.06808383717381605,105.42602647732984,267.08024191201656,0.02121704638051569
0.021787146505214593,261.641869848158,0.06917419015405633,105.49400192277731,267.34229959843816,0.021553198568671113
0.02213654953375349,261.828355395481,0.07028354476966733,105.56919289545795,267.6243317540343,0.021895092967781585
0.022475118684991892,262.010854256199,0.07135850182484925,105.64277643609945,267.8995793023632,0.022226274834338994
0.022818059350917894,262.191279747323,0.0724473384391643,105.71552399412063,268.17397592989056,0.022561621055431146
0.023160278831434393,262.371531949436,0.07353388528980419,105.78820168201261,268.44812978681557,0.022896149996741434
0.02349550515631259,262.54834915378,0.07459822887129247,105.8594943788041,268.717055245104,0.023223734469419874
0.02383485317133329,262.710969614969,0.0756756588189832,105.9250629487555,268.97264700224036,0.023555237411041433
0.024174862162682793,262.864557096166,0.07675518736651786,105.98698942117413,269.2192715314204,0.02388727586957757
0.024520242458495593,263.076653678197,0.0778517698057235,106.07250676304902,269.52735701155603,0.024224446879852198
0.02486240180898079,263.255443015275,0.07893812574351401,106.14459462375888,269.800605617922,0.02455836144150947
0.025199278693111393,263.430977584428,0.08000770985062867,106.21537016204137,270.06924820497676,0.02488701193077714
0.025543957924436592,263.611637547807,0.08110206641008617,106.2882122592758,270.34532212572,0.02522316248187123
0.025884509300550092,263.795849238508,0.08218331702924654,106.36248641296645,270.6240753515687,0.025555176378219926
0.026227778612246292,263.956808556641,0.08327319709388198,106.42738521003767,270.87980929465965,0.025889728553478215
0.026565544768514693,264.126391172029,0.08434560464003414,106.4957609205621,271.14305264125574,0.026218808111044527
0.02689828397113669,264.297235640554,0.08540205160835898,106.56464541027137,271.40637773760005,0.0265428841438212
0.027226780174853093,264.458212203958,0.08644502705515857,106.62955116063587,271.6585578130698,0.026862724656213168
0.027561243144378293,264.656199677518,0.08750694698340107,106.70937970997525,271.9504535464972,0.027188269645461054
0.027901526244840893,264.838512260253,0.08858734582736984,106.78288814333402,272.2279109607271,0.027519370854044326
0.028236652272994593,265.02016622259,0.08965137096675783,106.85613102094828,272.5034485015485,0.027845347030764897
0.028577851676189193,265.166654324856,0.09073467907190068,106.91519502378193,272.74454764162306,0.028177121632382306
0.02891773263934779,265.327195069552,0.09181380112992923,106.97992505204337,272.9998559585213,0.028507504811662046
0.029254779053168492,265.490042056638,0.09288392349380996,107.04558495723644,273.25689457782136,0.028835024895541263
0.02959050017193979,265.65323668531,0.09394983804590883,107.11138503151699,273.51404883112303,0.02916115053998332
0.02992158626016119,265.826408624705,0.09500103637601177,107.18120795748106,273.7803564405979,0.029482669499016987
0.030252290520724392,265.980160093634,0.09605102240329993,107.24320054975324,274.0266691695354,0.029803714501218794
0.030586746633725993,266.155433187571,0.09711292056208003,107.31387066122863,274.29626198766886,0.030128296974578583
0.030919957044390094,266.291013512183,0.09817086361593855,107.36853664811218,274.52472021128676,0.03045156578856926
0.03125507545604729,266.464898397315,0.09923486457295014,107.43864703379741,274.793278903111,0.03077658030899121
0.031597286030075195,266.610736309439,0.10032138314548873,107.49744887996582,275.03491200329734,0.031108364186069788
0.031935997915995495,266.769929710916,0.1013967933832857,107.56163565944135,275.28949363021405,0.03143664761294465
0.0322784839123417,266.950489244896,0.10248418642168489,107.63443726354208,275.56724631737916,0.03176847940901426
0.032611264156425894,267.116141102839,0.1035407636966522,107.70122809266468,275.82713614078875,0.03209080194199826
0.032950579641837695,267.259243571758,0.10461809036283468,107.75892700813283,276.0655905620865,0.032419347407226386
0.033287791742968295,267.403404633787,0.10568873878392433,107.8170527483429,276.3046734785972,0.032745749344964596
0.0336249169776926,267.557702960072,0.10675911140417399,107.87926583350104,276.55430850884653,0.033071960738693375
0.0339580528206849,267.694086853252,0.10781681770567454,107.93425581923121,276.7844567943997,0.03339420739166095
0.03429587394851429,267.836044636503,0.10888939978653288,107.99149319743802,277.0217158622251,0.03372088017246523
0.03462909026271099,267.974607096303,0.1099473615841074,108.04736158122937,277.25432395355534,0.034042995592639395
0.034967576410742995,268.145832580466,0.11102205510410901,108.11639969644389,277.52224247044575,0.034370099087248675
0.035314064970098695,268.302054051227,0.11212215628006335,108.17938819345473,277.776890219603,0.03470482510294148
0.0356487765039724,268.454031543823,0.11318486540011236,108.24066551846946,278.0240893159191,0.035028067538860605
0.035982136173719995,268.575973769213,0.11424328235156098,108.2898326237467,278.23991103036633,0.03534990061306797
0.03631594963219519,268.690607763622,0.11530314008221973,108.33605305029238,278.44836234180957,0.03567206803063097
0.036634032335480494,268.843444891774,0.11631305266515056,108.39767698036329,278.69226434512126,0.03597895696528813
0.036965645332814795,268.987052182065,0.11736592393168696,108.45557943980862,278.93033215214655,0.03629879980065564
0.037294355606954196,269.153212528587,0.11840957905207956,108.52257529152628,279.1911081493823,0.03661574201305148
0.0376259988370267,269.248944713782,0.11946254630755976,108.5611745085969,279.37970519445344,0.0369354104111047
0.03796460996294539,269.416961525149,0.12053763663235162,108.62891888694008,279.64527138685315,0.03726168971443849
0.0382980807457465,269.557196292436,0.12159640636774512,108.6854615451102,279.8807195616408,0.037582911867262196
0.038634518124941994,269.704704882847,0.12266459504669082,108.74493700876393,280.1246161920255,0.037906887120307056
0.03897179452823649,269.811834095145,0.12373544762715086,108.78813150716248,280.3268854547876,0.0382315650000413
0.039306965416030494,269.936933770639,0.12479961519589682,108.83857169632164,280.5473354908708,0.03855411161617371
0.039648667883705496,270.099739349408,0.12588452053076493,108.90421490568131,280.80883421034815,0.038882836736882274
0.039987118567728894,270.247657197651,0.12695910145253922,108.96385538209289,281.0540823086644,0.03920832708400595
0.040329093441872896,270.398980257555,0.12804487167794643,109.02486883984619,281.3039259989491,0.039537099099769865
0.0406707433896591,270.52169538652,0.12912961026216763,109.07434757984485,281.52401384092065,0.03986545083224856
0.041009499431641394,270.637286880592,0.13020516069546142,109.1209540702547,281.7359865431026,0.040190914885760896
0.04135193979533879,270.749396290421,0.13129240885020066,109.16615658429774,281.9454090254468,0.04051981107096049
0.0416915916739114,270.859650579133,0.13237080356466868,109.21061111350645,282.15222053201654,0.04084592224093983
0.04203072389554179,271.007973689073,0.1334475483683452,109.27041499143425,282.3986350046887,0.041171428400844916
0.0423640664169885,271.124133959067,0.13450591087393848,109.31725081229582,282.6100547773574,0.04149127426290301
0.042702239537904293,271.246597631113,0.13557961053284612,109.36662816486476,282.8294348169983,0.0418156506368487
0.0430378720696717,271.354605762805,0.13664524382120763,109.41017704356298,283.0331305711409,0.042137486068594736
0.04337306734333039,271.450074935202,0.137709488815074,109.44867021387346,283.2236973157186,0.042458798874437965
0.043706547813139096,271.582194457057,0.1387682893067166,109.5019408050854,283.45211462429165,0.042778365478629767
0.04404287047451239,271.694160681104,0.13983611375657684,109.54708558662112,283.6603514086632,0.04310055229026202
0.044375054902613696,271.781221749124,0.14089079931579848,109.58218860924678,283.84152838574073,0.04341867293734725
0.044708881118421896,271.909919011089,0.14195069755098952,109.63407934527109,284.0667072550755,0.04373826394361916
0.045039314080417996,271.991616357692,0.14299982220532712,109.66701971542142,284.24193219406664,0.04405450583870393
0.045376403152880496,272.127871940293,0.14407008001039556,109.72195796632614,284.47605596659116,0.04437701496701308
0.045714275118100396,272.249980184942,0.14514282349996874,109.77119201056861,284.6956906800138,0.04470016878494267
0.046055145868460295,272.372833771183,0.14622508813236143,109.820726576541,284.91700436112075,0.04502608496858837
0.0463981564134068,272.484292720553,0.1473141466125666,109.86566682492698,285.12706155439776,0.0453539398819046
0.046739688185797296,272.596920712125,0.14839850998990642,109.91107843112879,285.3380157866182,0.045680274601142185
0.047078613644502894,272.693199894025,0.14947459832129667,109.94989819727087,285.531217695319,0.04600401373492423
0.047422232665048594,272.797233611493,0.15056558871152928,109.991844592154,285.7338874941989,0.046332129165609276
0.0477621637841607,272.920959223737,0.15164487001471022,110.04173075901076,285.95625477831135,0.046656617189356396
0.0481049887762553,273.007578198428,0.15273333936461056,110.07665552960619,286.140604683496,0.046983761011170855
0.0484519134282488,273.100194341065,0.15383482513468993,110.1139983583174,286.3324213145162,0.047314708055627645
0.0487937518441006,273.197707922866,0.15492016210501938,110.15331583449958,286.5280490876314,0.04764069601644634
0.0491356573631149,273.315097661002,0.1560057121278898,110.20064737691602,286.74461465183936,0.04796664170417144
0.0494759660593955,273.392338197416,0.1570861922385807,110.23179076119814,286.9186882429701,0.04829095964415161
0.049817732112328095,273.485850772336,0.15817129945664168,110.26949503140588,287.1102956226244,0.04861656063676127
0.0501591798582332,273.529883417014,0.1592553960498904,110.28724899374005,287.24991803592957,0.048941752544317776
0.050500787999317294,273.62442645774,0.1603400018978324,110.32536874776076,287.4426756097171,0.04926699142097783
0.050840861206797,273.72294825071,0.16141973433158047,110.36509273468626,287.63925867183957,0.049590663880976965
0.051180630430618795,273.792159409148,0.16249850161721466,110.39299867376847,287.80501473466865,0.04991394242796865
0.051522868879796194,273.9272803719,0.1635851086933529,110.44747944595008,288.04079972110054,0.050239464739898695
0.0518698256193721,274.005505641761,0.1646866963415064,110.47901987475804,288.218123438147,0.05056936675356461
0.0522147987359956,274.117020890267,0.165781985986786,110.52398282295565,288.429985966163,0.05089727478133242
0.052563072619675896,274.168450415379,0.16688775556747096,110.54471920748084,288.57958658458665,0.0512282112583818
0.052907052977763,274.25263369591,0.16797989320439752,110.57866190619092,288.76253231615055,0.0515549604788676
0.053251382224126995,274.332065768147,0.1690731385616032,110.61068891771687,288.94062745870093,0.051881934218047474
0.053593371011330694,274.425374507612,0.17015895296097494,110.64831100146915,289.1327554185218,0.052206579676316076
0.05392877489984459,274.496398844202,0.17122386030700656,110.67694801398225,289.2996533482889,0.052524871839457594
0.0542656093727959,274.543925847373,0.17229330975862697,110.69611090166077,289.4422192830803,0.05284441967463857
0.05461056693082209,274.632135704435,0.17338855000536013,110.7316771160282,289.6299523326766,0.053171567911200826
0.054955704206921294,274.700361178578,0.1744843608569751,110.75918562720267,289.7967129730424,0.05349877951284676
0.055310428978054396,274.811271875947,0.17561061200532269,110.80390482038183,290.01120121141037,0.05383496912314839
0.0556642441412479,274.874759391283,0.17673397514846206,110.82950298656532,290.1754551063062,0.054170184103235076
0.0560183803613524,274.959260682013,0.17785835764729385,110.86357390698764,290.36203313077425,0.054505590777813244
0.05637104119020869,275.028227703201,0.1789780557789126,110.89138140993066,290.5318552555283,0.05483948833338218
0.0567176840184351,275.095550694619,0.1800786467585314,110.91852604007039,290.69833321379383,0.055167579461029126
0.0570647700101345,275.142563107801,0.18118064478217702,110.93748144506536,290.84351019154656,0.05549598221993869
0.0574058070528206,275.204610685084,0.1822634373927054,110.96249902822586,291.0029534661185,0.05581855662635758
0.05775575828880639,275.252835029295,0.1833745325669603,110.98194308381176,291.15027123755567,0.056149454506607695
0.058104667436554895,275.304774915402,0.18448231911106178,111.00288524589008,291.301267305557,0.056479258067058905
0.0584600239492964,275.413905652381,0.18561057603901607,111.04688675904004,291.5146091727885,0.05681504418078068
0.058809431470242195,275.467286802513,0.18671994491801897,111.06841003877324,291.6673613280189,0.05714509902875777
0.059161316724907397,275.555372456978,0.18783718060158097,111.10392617465352,291.8575911221551,0.057477384314758954
0.059513126739774595,275.603473410548,0.18895417739878434,111.12332047913297,292.0054978535521,0.05780948821036773
0.05986419557682839,275.652675521237,0.19006882095643013,111.14315877016276,292.1544011999163,0.05814078253589262
0.0602180383835474,275.712183532963,0.19119227186776297,111.16715240049069,292.31503038376263,0.0584745835595854
0.060578895967160595,275.750013490933,0.19233799469573487,111.18240543954418,292.45464487114333,0.058814887321110884
0.0609312785534136,275.797874219544,0.19345680940708818,111.20170288532015,292.60259131805435,0.05914708708496383
0.061283022455345795,275.855039006072,0.19457359629572288,111.22475172724822,292.7602695559014,0.05947857472500658
0.061631107189467994,275.926095325187,0.19567876532656087,111.25340163511541,292.93172608254497,0.05980650578201999
0.06198006081705999,275.983664549361,0.19678669309416547,111.27661354630234,293.08914886264546,0.060135147518313295
0.062334345746149995,276.036824291638,0.19791154774402622,111.29804755438845,293.24339913570225,0.06046869977524871
0.06269044205918749,276.072505746243,0.19904215353792026,111.31243431688517,293.3796131718625,0.06080384534005716
0.0630474571167667,276.100525946148,0.20017567634573424,111.32373206148688,293.5079620156545,0.06113974287575476
0.06339680300013419,276.192985188301,0.20128484952542602,111.36101162792296,293.7027374603027,0.0614683156891246
0.06374480482182289,276.226520711532,0.20238975530928766,111.37453315088969,293.8345263608998,0.06179551705974696
0.06409583214650338,276.256357775263,0.20350426706514824,111.38656345498605,293.9632389126306,0.06212545467045524
0.06444617491563659,276.292704055548,0.20461660535714615,111.40121827519695,294.09871198902607,0.06245464034885358
0.06480541172500119,276.343553454342,0.20575718222687878,111.4217207527907,294.2521112135005,0.06279207047221431
0.065160418899611,276.394890505114,0.20688433000626488,111.44241985166197,294.40489735213936,0.06312541589287125
0.06551722140027298,276.489633791396,0.20801717794586672,111.48062034469088,294.6044663433873,0.06346033516667278
0.06587718182699459,276.510160756163,0.2091600523007078,111.48889681688492,294.72587089330824,0.0637981050600334
0.06623817315096858,276.566040344931,0.21030619975432524,111.51142746707619,294.8852696129763,0.06413672775845405
0.06660000430822219,276.587112093627,0.21145501367860545,111.51992359615042,295.0078149506613,0.06447602322357555
0.06696409018464258,276.609992601471,0.21261098633624018,111.52914901691311,295.13292909200925,0.0648173168185459
0.06733120442846849,276.651425930974,0.21377657406038744,111.54585493536874,295.27869964575973,0.06516133130273921
0.06769719482929179,276.676333882902,0.2149385935830014,111.55589782158609,295.40654556242697,0.06550417489632838
0.06806198482123979,276.703770627486,0.21609680180743632,111.56696031700235,295.5367784639138,0.06584577707598531
0.06842500131961039,276.717768585126,0.21724937918976298,111.5726042935228,295.6521822657229,0.06618560269085577
0.06878167024459339,276.742135993756,0.218381803026584,111.58242923268243,295.77692233446294,0.06651937380718222
0.0691450706621319,276.773227342054,0.21953559935226874,111.59496526431616,295.9107317040066,0.0668593297224951
0.06950058763121508,276.789952743313,0.2206643657291079,111.60170894610381,296.02701710938953,0.06719179898497377
0.06986564927355068,276.843324806802,0.2218234364435234,111.62322856210258,296.18516344147775,0.0675330791637309
0.07023325925605599,276.825318350496,0.22299059813797775,111.61596835891999,296.2676627028466,0.06787662402014437
0.07059791199706508,276.895812343574,0.22414837059068163,111.64439153692904,296.44407853576143,0.06821728866426217
0.0709637488998116,276.908235714628,0.2253099027569018,111.64940064013801,296.5586822221707,0.06855894299342308
0.071322400657324,276.94052094969,0.22644862208700367,111.66241804691501,296.6925837431118,0.06889377385711268
0.07168665761550219,276.959887256845,0.22760513792921944,111.67022654195989,296.8142158678545,0.06923372292105143
0.07205501600837479,276.935821763582,0.22877467582658995,111.66052333507628,296.89043683404935,0.06957738223507247
0.07242791145749979,276.960079074528,0.2299586188775618,111.67030388284968,297.01971915900003,0.06992515413673443
0.072800316005708,276.99329407362,0.23114100331812287,111.68369617048359,297.15849341364157,0.07027234754691028
0.07316874146378079,277.016906427777,0.232310754147504,111.69321667167968,297.28588483528733,0.07061571266712027
0.0735334398520164,277.028090198484,0.23346867153015205,111.69772596802875,297.3989186064132,0.0709554881561644
0.07389711473466089,277.018797476684,0.2346233392825483,111.69397914259899,297.4896873374763,0.07129419516146857
0.07426749622552829,277.009689160622,0.23579930051605233,111.69030666956279,297.5825052047932,0.07163903046193651
0.0746413104192895,277.039025409186,0.23698616058124414,111.7021350449838,297.71758130301055,0.07198694117492345
0.07501964872064878,277.068559234551,0.2381873846880599,111.71404308337097,297.85414521986326,0.07233893929226093
0.0753961544342246,277.080919182671,0.23938279032866308,111.71902661445294,297.97175495614454,0.07268910944714047
0.07576777202490238,277.067947779271,0.24056267617906504,111.71379654460206,298.06076888201835,0.0730346131903036
0.07614079078049639,277.051404214476,0.24174701072807603,111.70712617927673,298.14631721821314,0.07338129963021792
0.07651400518045769,277.035136579167,0.24293196644795315,111.70056706872015,298.23220445455416,0.07372804765911785
0.07689440437951259,276.997698611778,0.24413973390495244,111.68547208026888,298.2972716610264,0.07408134729454513
0.0772749197347573,276.980285233986,0.2453478701578544,111.67845100634317,298.38391454355246,0.07443462997751976
0.07765607649762689,276.977885365826,0.24655804287996536,111.67748337950104,298.48690121994554,0.07478838308377775
0.07803200849778119,276.954204523479,0.24775162698045528,111.66793526386674,298.56549736435136,0.07513716453001947
0.07841643494631499,276.906900426329,0.2489721809545501,111.64886225189586,298.62095236979593,0.07549370118061714
0.07879342119058048,276.818071939859,0.25016911228009303,111.61304660615114,298.6295148753807,0.07584321399878896
0.07917262675584048,276.763268078443,0.2513730899497935,111.59094968922822,298.6753430017442,0.07619466120485048
0.07955233616097789,276.661974322247,0.2525786673111048,111.55010804672999,298.67108070649016,0.07654645165113327
0.07993588878696839,276.615414463801,0.25379644689862463,111.53133511180457,298.72691347114056,0.07690167713983258
0.08032405767144629,276.487079251232,0.25502888310684196,111.47959035409674,298.6956433504177,0.07726104952859719
0.08071198866092999,276.327263381982,0.2562605639984527,111.41515259561515,298.63018633077434,0.07762007268724276
0.0811028120059813,276.16385468861,0.25750142811899057,111.34926621044755,298.5615198782675,0.0779816423732201
0.0814944403585457,275.925582506587,0.25874484813838255,111.25319486665587,298.41198343356706,0.07834382572143003
0.08189100793203419,275.672581079452,0.2600039501842085,111.15118469123504,298.2476866032738,0.07871044330984331
0.0822891414634136,275.358394982098,0.26126802414633815,111.02450485678192,298.0174008999184,0.07907837343431283
0.08269891405633889,275.001226794169,0.26256905212887593,110.88049464340894,297.7435296142077,0.07945691833831225
0.08311049133358579,274.567649584296,0.2638758099841349,110.70567631238815,297.3871018455547,0.07983698620686726
0.0835295142570523,274.080915912032,0.265206207766141,110.5094252957313,296.97476168529204,0.08022378136213937
0.08394617876581319,273.498807280653,0.26652911758145686,110.2747190955593,296.45798704887136,0.08060825119978011
0.08437180320208759,272.850648894008,0.2678804751666281,110.013381634064,295.8715501460551,0.0810008360930296
0.08480138043274178,272.109516282367,0.26924438287395513,109.71455696505038,295.1847788919974,0.0813969107259922
0.08523676701859559,271.332279291851,0.27062673528404096,109.40117501047433,294.459765566475,0.08179818163655862
0.08567566148837198,270.469060714539,0.272020225225581,109.05312528010212,293.6416764033958,0.08220252265924823
0.08611710560469289,269.534108982169,0.2734218102948999,108.67615274161055,292.7456063094533,0.08260904774680651
0.08657087022126349,268.522259596055,0.2748625129525116,108.26817506912937,291.7684652830655,0.083026746586416
0.0870201445272862,267.469749645852,0.2762889588741336,107.84380305720754,290.74500591671114,0.08344014019116724
0.08748196010333789,266.381154226034,0.27775522332809777,107.40488138393692,289.68469973231703,0.08386489543238909
0.08794390731355718,265.206706899602,0.27922190572054406,106.93134422191953,288.53002095011436,0.08428959132672564
0.0884207868855622,264.040521777034,0.28073599836165997,106.4611383805001,287.38719248223373,0.08472782631639264
0.08890144491894929,262.768849315848,0.28226208761766397,105.94840004414992,286.1293796997166,0.08516933932183955
0.08939239903891569,261.479518139211,0.2838208669485573,105.42854171372989,284.85379956521473,0.085620108743643
0.08989148841765869,260.096713059669,0.28540547572606634,104.87099470565855,283.4771937291433,0.08607813937502715
0.09039711633234068,258.684367290523,0.28701084435518165,104.30153689153889,282.0686881338424,0.08654195680052296
0.0909104798948989,257.192957254978,0.288640773666304,103.70020036520714,280.5744924246163,0.08701265022580992
0.0914262888531809,255.652846604457,0.2902784671088493,103.07922775091707,279.02623760425405,0.08748536275604234
0.0919433722413193,254.065090014435,0.29192020686618875,102.43904429382019,277.42469115915645,0.08795901905622779
0.09247191550307068,252.412666842987,0.2935983317222494,101.77278727109235,275.7537496431964,0.08844294102384206
0.0930008925161482,250.715813999798,0.2952778337387705,101.08861620471855,274.03260846969187,0.08892702576876921
0.093548192966586,248.963643732153,0.2970155126689105,100.3821411528041,272.2537427176728,0.08942763237806163
0.09409750121103189,247.157685298782,0.2987595663450262,99.65397871246891,270.4146058905,0.08992982362178296
0.09465848765791698,245.269057750506,0.3005406983138864,98.89248408500401,268.4858558264512,0.09044243120528897
0.0952282249198226,243.2742274863,0.3023496141204367,98.08816852247615,266.4408003385615,0.09096276613539095
0.0958026774780674,241.184525014162,0.30417350099286394,97.24560048571013,264.2906482767946,0.0914871335195102
0.09636578779652379,239.034545602622,0.305961376253963,96.37872878697719,262.06929790020274,0.09200088083388128
0.09693525553573229,236.825716829982,0.30776943632595,95.48812902584876,259.7824782083293,0.09252015998503674
0.09751346423271538,234.502090788004,0.3096052489388713,94.55124300572322,257.369202030557,0.0930471339855272
0.09816577358880078,232.121664250439,0.3116763311444425,93.59145502577701,254.90806698830326,0.09364130945892093
0.0987014263309088,229.451386102462,0.31337702860063543,92.51479887651269,252.09856518437905,0.09412896092255287
0.0990381012054432,227.240907047303,0.31444597132728214,91.62353372147258,249.74641499747048,0.09443534379727454
0.0992361111040145,225.674567645008,0.315074652755246,90.99198567446723,248.06963411317847,0.09461549411519046