File: example/data/02 processed data/test_ID_095.csv
Strain,Stress_MPa,Displacement(mm),Force(kN),True Stress (MPa),True Strain
0.0007180726874763,0.0442470036957104,-0.0005008230775568,0.0089201959450552,0.0442400241931707,-0.0001577519941779
0.0006678320607421,0.339408640046737,-0.0006603370674379,0.0684247818334221,0.3393380497771207,-0.0002080018095972
0.000625121654466,0.746207295210298,-0.0007959426073645,0.1504353907143961,0.7460202280669329,-0.000250722013134
0.0005719589123934,1.25532323752683,-0.000964734313445,0.2530731646854089,1.25494180338456,-0.0003038994998448
0.0004598222305011,2.13918827368082,-0.001320768278453,0.4312603559740533,2.1382983927316808,-0.0004160765568082
0.0003677687447569,3.28576923890284,-0.0016130380956909,0.6624110785628124,3.284099925215911,-0.0005081725925287
0.0003141232902098,4.83628809442724,-0.0017833624138779,0.9749956798365316,4.833571604849197,-0.0005618467555855
0.0002955169510543,6.59664185764146,-0.0018424375406966,1.3298829985005185,6.592813857452153,-0.0005804637248843
0.0002764171342082,8.49363466239884,-0.001903079459183,1.7123167479396062,8.488543619356378,-0.0005995748143153
0.0002582887363662,10.5469156461329,-0.0019606371223313,2.1262581942603926,10.540402677836235,-0.0006177142492658
0.000286209116113,12.7145445626255,-0.0018719899166352,2.5632521838253006,12.707048027439408,-0.000589777007623
0.0003477516399441,14.9921509791438,-0.0016765924034715,3.02241763739539,14.98423421490968,-0.0005282000726193
0.0004004020988798,17.4276339135125,-0.0015094271963507,3.51341099696412,17.41934863962365,-0.0004755231838131
0.0004426444483291,19.8122576527581,-0.0013753077368491,3.994151142796033,19.803675620873285,-0.0004332616354023
0.0004717993448001,22.2865332229986,-0.0012827409405537,4.492965097756517,22.27752917619918,-0.0004040945298606
0.0005182261129961,24.8583618036318,-0.0011353359515314,5.011445739612172,24.849472798324136,-0.0003576500756309
0.0005882577579016,27.4899103022751,-0.0009129854789564,5.54196591693866,27.482005455369965,-0.0002875958332785
0.0006435272781246,30.170285740792,-0.0007375047522484,6.082329605343667,30.163277637135145,-0.0002323119436681
0.0006939939189505,32.892314612981,-0.0005772731676262,6.631090625976969,32.8863341875803,-0.0001818348514668
0.0007472045681841,35.6057318267344,-0.0004083293563095,7.178115536269655,35.60115265647999,-0.0001286159419543
0.0008070148641039,38.3848882365146,-0.0002184316667642,7.738393468481343,38.38224745695049,-6.879974200678379e-05
0.0008721438563893,41.2009151090569,-1.164711625789428e-05,8.306104485985871,41.20076396831731,-3.6683898018411656e-06
0.000932387579431,44.019747897957,0.0001796267043993,8.87438117622813,44.022238330159645,5.657373964420263e-05
0.0009905935868867,46.8453021432834,0.0003644307780712,9.444012912085933,46.85067911018389,0.0001147747605492
0.0010525495427548,49.6598558671705,0.0005611409379524,10.011426942821574,49.66863261617834,0.0001767216870949
0.0011116797169019,52.5337922238378,0.0007488792408694,10.590812512325702,52.54618323688995,0.000235839665079
0.0011659989878169,55.3547020548929,0.0009213429260245,11.159507934266408,55.37076525588832,0.0002901446523233
0.0012216897855091,58.1645142654028,0.0010981612086973,11.725966075905204,58.18463206486389,0.0003458177441968
0.0012873098972951,60.9300273918565,0.0013065050636178,12.28349352219827,60.95509995541991,0.0004114130158904
0.0013507375066608,63.7312280807542,0.0015078877233539,12.848215581080046,63.76149565127931,0.0004748125258877
0.0014059339872889,66.5307199500497,0.0016831365493481,13.41259314193002,66.56598933159376,0.0005299812829325
0.0014541083206665,69.3380858620739,0.001836090057822,13.9785581097941,69.3781838054061,0.0005781289324628
0.0015076437812648,72.054310223597,0.0020060651452216,14.526148941077157,72.09983640951907,0.0006316320202917
0.0015628739451957,74.8083793835166,0.0021814209157022,15.081369283716946,74.85977735625896,0.0006868257868936
0.00162407358554,77.5158165572043,0.0023757297737954,15.627188617932388,77.57381864644367,0.0007479815381271
0.0016777094082982,80.2516657319759,0.0025460235110527,16.17873581156634,80.3160193155207,0.0008015758210812
0.0017302850623832,82.920819466199,0.0027129512127725,16.71683720438572,82.99167305288717,0.0008541079688417
0.0017878466296739,85.6065630699086,0.0028957091889205,17.258283114893576,85.68463919945614,0.0009116187395526
0.0018490325197562,88.309094085892,0.0030899743899318,17.803113367715827,88.39503828719073,0.0009727470084767
0.0019122269487811,91.0448820397306,0.0032906167020859,18.35464821920969,91.13924229468472,0.0010358780023955
0.0019782281919899,93.7819560284314,0.0035001706492738,18.90644233533177,93.88534275281634,0.0011018087382885
0.0020411517949919,96.5504213356077,0.0036999530888052,19.464564941258512,96.66293536069308,0.0011646610744453
0.0020923000272643,99.2988515261428,0.00386234872627,20.01864846767039,99.41964736636707,0.0012157484660558
0.0021500583230278,102.107036935161,0.0040457313153191,20.584778646128456,102.23714642708006,0.0012734349210316
0.0022048930307866,104.854449508215,0.0042198315124533,21.138657020856144,104.99380954294122,0.0013281983452572
0.0022623508468214,107.559535673412,0.0044022600783638,21.68400239175985,107.70867112221276,0.001385578250316
0.0023137928588217,110.188744474311,0.0045655884664648,22.21405088602109,110.34719375333655,0.0014369477153069
0.0023637881400748,112.790992561419,0.0047243234844434,22.73866410038207,112.95882284015651,0.0014868699614097
0.0024192565148856,115.345351284364,0.0049004355744677,23.253622818927784,115.52338040650052,0.0015422543894983
0.0024784309853575,117.888412457165,0.0050883145182159,23.766303951364467,118.07734263689264,0.0016013359228737
0.0025364272610584,120.371238920987,0.0052724526935663,24.26684176647098,120.57112920850729,0.0016592377250327
0.0025986295889521,122.854486968542,0.0054699450846288,24.767464572858067,123.06614281015403,0.001721335001978
0.0026402508194515,125.365472568342,0.0056020924914644,25.273679269777748,125.58667224474011,0.0017628837868602
0.0026938394360119,127.873304552762,0.0057722363490437,25.779258197836818,128.10578169815153,0.0018163765853732
0.0027456032387664,130.401215376547,0.0059365864227892,26.28888501991188,130.64503839535632,0.0018680451160656
0.0027970640964185,132.949757198694,0.0060999746458346,26.80267105125671,133.2051871665938,0.0019194086131196
0.0028612148775341,135.443129564937,0.0063036533758766,27.3053349202913,135.7120387116839,0.0019834343310778
0.0029196192406497,137.914967289347,0.0064890872287687,27.80365740553236,138.19683886506144,0.0020417212690637
0.0029722982269103,140.386043408322,0.0066563430101461,28.301826351117715,140.68036078116074,0.0020942914274073
0.0030373647750198,142.818268087708,0.0068629293003937,28.792162846481933,143.12697727721687,0.0021592197419076
0.0030879388577047,145.271715436053,0.0070235020129183,29.286777831908285,145.59307486464678,0.0022096834685286
0.0031479834342015,147.66314371402,0.0072141435432956,29.76888977274644,147.9986596556916,0.0022695937173446
0.0031995232151776,150.037858768476,0.0073777823478948,30.24763232772477,150.38650338766908,0.0023210153344852
0.0032456366485868,152.432424987925,0.007524192498969,30.73037687756568,152.79366306940338,0.0023670208037537
0.0032964673447019,154.838943154106,0.0076855799591344,31.21553093986777,155.21375483234183,0.0024177300391032
0.0033499396419344,157.224037946397,0.0078553545028476,31.696366049993635,157.61303024700746,0.0024710717882181
0.0034087748812626,159.567779799915,0.0080421563877146,32.168864407662866,159.97195902498314,0.0025297600987354
0.003472835686771,161.898228653573,0.0082455494452038,32.63868289656032,162.318682149464,0.0025936570091349
0.0035246395158105,164.228592311773,0.0084100266024042,33.10848421005344,164.66360548664466,0.0026453253160733
0.0035781815640421,166.518155813508,0.0085800226055395,33.57006021200321,166.96814936976395,0.0026987244895797
0.0036342722523579,168.833064690313,0.0087581105409422,34.0367458415671,169.29878394811576,0.0027546624440985
0.0036899598225186,171.101677057006,0.0089349185762024,34.49409809469241,171.58318242795278,0.0028101952829139
0.0037474402907513,173.356473195416,0.0091174190628413,34.948664996195866,173.8542885067164,0.0028675128038803
0.0038004709766705,175.655649691066,0.0092857914906347,35.4121789777189,176.1693825216749,0.0029203902434098
0.0038477257940188,177.93142016371,0.0094358255357156,35.870974305003934,178.46021696307594,0.0029675061495933
0.0039045820751569,180.160422951576,0.009616344228329,36.320341267037726,180.70608740619764,0.0030241923527676
0.0039639238546311,182.381766570481,0.0098047543781596,36.76816414060897,182.94498182222225,0.0030833531923382
0.0040250570323289,184.572570947111,0.0099988522173501,37.209830302937576,185.15383515507213,0.0031442963080882
0.004083324175623,186.805729309143,0.0101838503973089,37.66003502872323,187.4049109156452,0.0032023788431259
0.0041355462674464,188.974233379406,0.0103496555388482,38.097205449288246,189.59023911836496,0.0032544326126954
0.0041918386282693,191.136358280133,0.0105283837844609,38.533089829274815,191.77017148805032,0.003310540497529
0.0042535766434548,193.251712622786,0.0107244019826749,38.95954526475366,193.90447137869373,0.0033720725713195
0.00431095504318,195.378448494832,0.0109065784018024,39.38829521655813,196.0496013661805,0.0034292561777582
0.0043649935716877,197.505538420592,0.0110781507298143,39.81711654559135,198.19467105826016,0.0034831082616369
0.004416860502796,199.562098927768,0.0112428282360832,40.23171914383804,200.26875795160333,0.0035347935131642
0.0044702364698369,201.572928082066,0.011412296931438,40.637102301344505,202.29746669895167,0.0035879797258389
0.0045280490286608,203.632728905138,0.0115958518057039,41.05235814727583,204.3764438491301,0.0036455835669238
0.0045869383887677,205.643102984341,0.0117828255240433,41.45764956164315,206.4062704812504,0.003704256910486
0.0046416313089768,207.643668944057,0.0119564755457072,41.86096365912189,208.4256174322304,0.0037587461242752
0.004703798714554,209.576880247406,0.0121538570584148,42.25069905787705,210.37913771048488,0.0038206783791221
0.0047716997424574,211.429080612825,0.0123694428220081,42.62410265154552,212.25278452575407,0.0038883181863779
0.0048381306283356,213.255655920654,0.0125803608846714,42.99234023360385,214.10064272763955,0.0039544890800272
0.0049041550162518,215.04584294708,0.0127899883163053,43.353241938131326,215.9121213151944,0.0040202507284421
0.0049777600869153,216.711596488729,0.013023684415662,43.68905785212776,217.600536155464,0.0040935577952596
0.0050479025123923,218.274643272483,0.0132463866165514,44.00416808373257,219.1853047885073,0.0041634112357504
0.0051284049576105,219.772044523525,0.0135019818801192,44.306044175942645,220.70664551971825,0.0042435759996503
0.0052042356509229,221.200925837714,0.0137427443313861,44.59410664888315,222.15837710374663,0.0043190827307599
0.0052857632400742,222.571808717274,0.0140015944269415,44.87047663740243,223.55333948783465,0.004400255660231
0.0053721531740236,223.846789058405,0.0142758824672308,45.12751267417445,224.85328053911832,0.0044862625928087
0.0054675461822263,225.011259807964,0.0145787552682744,45.36226997728554,226.04445164712823,0.0045812240924735
0.0055577574074067,226.115119340565,0.0148651759082221,45.58480805905791,227.17377793096065,0.0046710189533517
0.0056667264070043,227.082979588092,0.0152111524819445,45.77992868495935,228.17091465220813,0.0047794742621139
0.0057739761399088,227.918302505376,0.0155516703839163,45.94832978508381,229.0346837069588,0.0048862069245709
0.0059000931237459,228.665932418281,0.0159520918075991,46.09905197552545,229.81481429141687,0.0050117013030529
0.0060266059783385,229.307963716548,0.0163537701209306,46.22848548525608,230.48908174033352,0.0051375737769051
0.0061633588016467,229.866369515849,0.0167879603349342,46.341060094395154,231.08179864774425,0.0052736165699397
0.0063068227032112,230.276984516548,0.0172434582224014,46.42384007853608,231.52762122901785,0.0054163157073268
0.0064611408873613,230.612673593444,0.017733418457078,46.49151499643831,231.900721165834,0.0055697885374096
0.0066119656075343,230.931298129587,0.0182122869436273,46.55574970292474,232.2559554731461,0.0057197642840062
0.0067774608234723,231.202536006456,0.0187377342542304,46.61043125890153,232.56701212569791,0.0058843020712269
0.0069386218805692,231.428214715271,0.0192494206105131,46.65592808659864,232.8313199266708,0.0060445047594829
0.0071086949757576,231.608446284107,0.0197894026877363,46.69226277087597,233.0520345705313,0.0062135386606513
0.0072794200580945,231.763370332385,0.0203314548241559,46.72349545900882,233.24749206271792,0.0063831918330424
0.0074525284476877,231.922313328923,0.0208810739611143,46.75553836711088,233.4476005660424,0.0065551839662528
0.0076235341631636,232.067471004097,0.0214240171077503,46.784802154425954,233.6333977659692,0.0067250579444833
0.007802238129457,232.205467259149,0.0219914022007319,46.81262219944444,233.81382121937105,0.0069025483959117
0.0079777282050661,232.324589588542,0.0225485831907907,46.83663726105007,233.9745393005432,0.0070768161283027
0.0081570201372463,232.411846825147,0.0231178350754629,46.854228319949634,234.10408579978872,0.0072548278784307
0.0083305340331702,232.520955206841,0.0236687416950213,46.87622456969915,234.2543342391152,0.0074270726811325
0.0085089261657119,232.596374942004,0.0242351367158412,46.891429188308,234.37180957076885,0.0076041291149468
0.0086859945509747,232.680956852719,0.0247973288390505,46.90848090150815,234.4982375461558,0.0077798407174999
0.00886975754658,232.752182429478,0.0253807763500974,46.92283997778277,234.61279064593143,0.0079621629913724
0.0090469500913477,232.807459839155,0.0259433626797348,46.93398390357365,234.7097616864479,0.0081379348532143
0.009226513288866,232.915481066604,0.0265134758318554,46.95576098302737,234.86048861876915,0.0083160268475869
0.0093978372810567,232.992665126119,0.0270574295070609,46.97132128942559,234.97823445283152,0.0084859175802906
0.0095789305704081,233.038917290202,0.0276324007007516,46.980645725704726,235.067082563094,0.008665464509331
0.0097524042193632,233.085862906394,0.028183179536184,46.99010996192903,235.1548710076971,0.0088374266365234
0.0099324787257347,233.126595517639,0.0287549160939135,46.99832165635602,235.23794534232223,0.0090159008314393