File: example/data/02 processed data/test_ID_073.csv
Strain,Stress_MPa,Displacement(mm),Force(kN),True Stress (MPa),True Strain
0.0002303539511328,5.32409582771451,0.0007313737948466399,1.0733377188672453,5.325322254224634,0.00023032742373511457
0.0003431039052989,8.71881669180962,0.0010893548993240075,1.7577134450688194,8.721808151866163,0.00034304505861384283
0.0004395399400201,12.6333655888678,0.0013955393095638174,2.546886502715749,12.638918457620983,0.000439443370637034
0.0005301295584656,16.8421534213129,0.00168316134812828,3.3953781297366805,16.85108194466975,0.0005299890894336049
0.0007018823198577,24.3259230420467,0.0022284763655481977,4.904106085276615,24.342996977344132,0.0007016361156597317
0.0008755240158097,33.2367843136021,0.0027797887501957975,6.700535717622183,33.265883916476945,0.0008751409682204002
0.0010512376622178,42.8276404777591,0.0033376795775415147,8.634052320316234,42.87266250641324,0.0010506854988426625
0.0012092293355076,52.8770597931584,0.00383930314023663,10.660015254300733,52.941000285035685,0.0012084988065734902
0.0013524432399636,63.1548959744086,0.00429400728688443,12.732027028440775,63.2403093865398,0.0013515295123553476
0.001495599894607,73.48126482931,0.004748529665377225,14.813822989588898,73.5911634012443,0.0014944825989639593
0.0016394255162135,83.8960775718557,0.005205176013977862,16.91344923848611,84.03361894213722,0.0016380831251684254
0.0017894686125149,94.3532179099845,0.005681562844734807,19.021608730652876,94.52206003192418,0.001787869421074945
0.0019397516182556,104.880306530128,0.006158711387961529,21.143869796473805,105.08374827444295,0.0019378727294113872
0.0020847901559438,115.3357191048,0.006619208745121565,23.25168097152768,115.5761698766184,0.002082619996641002
0.0022367977881749,125.652662112322,0.0071018329774553066,25.33157668184412,125.93372170901314,0.0022342998801856114
0.0023831860643473,135.973638322941,0.007566615754302676,27.41228548590491,136.29768880291084,0.002380350780218233
0.0025329032103228,146.226960692295,0.00804196769277489,29.47935527556667,146.59733943046825,0.002529700817413958
0.0026799139265243,156.291443177833,0.008508726716714652,31.508354944651135,156.71029079300186,0.002676329359989209
0.0028195454259951,166.198811724328,0.008952056727534442,33.50568044362453,166.66741682373117,0.0028155779636677464
0.002958352679464,175.898586947976,0.009392769757298199,35.461155128711965,176.41895700398752,0.0029539853654260667
0.003099183437187,185.507409536694,0.009839907413068723,37.39829376259751,186.0823310278056,0.0030943908676798505
0.0032358170661954,194.840480105904,0.010273719185170395,39.279840789350246,195.4709482566164,0.0032305930763692793
0.0033726568852873,203.724300085789,0.010708185610787176,41.07081889729507,204.41139224917364,0.0033669822335768073
0.0035088369830799,212.194310796857,0.011140557421278683,42.77837305664637,212.93886604218014,0.003502695376996266
0.0036446489708939,220.275886073748,0.011571760482588131,44.4076186324676,221.07871435523944,0.0036380233317060296
0.0037872218093887,227.845348952955,0.012024429244809122,45.933622348915726,228.70824982767738,0.003780068340365805
0.0039254523060307,235.029276090265,0.012463311071647472,47.38190205979742,235.95187230407828,0.003917767821614047
0.0040712847577224,241.75424941256,0.01292632910576862,48.7376566815721,242.73849980330797,0.004063019503806804
0.0042562745325448,248.009425996458,0.01351367164082974,49.998700280885934,249.06502220015776,0.004247242216371524
0.0045029267602874,253.659718355995,0.014296792463912494,51.137799220568596,254.8019294897872,0.0044928189174748894
0.0048298119541567,258.385550604931,0.01533465295444752,52.09052700195409,259.63350422602406,0.004818185832028099
0.0052444311912935,262.411327153928,0.01665106903235686,52.90212355423189,263.78752530300284,0.005230727054752637
0.0057463056424513,265.643525705032,0.018244520414782875,53.553734782134455,267.1699945956715,0.005729858604575097
0.006347044341288,267.943155743568,0.0201518657835894,54.017340197903316,269.6438028340171,0.006326986681850041
0.0070353602127232,269.457682211806,0.02233726867539616,54.322668733900095,271.35341406825154,0.00701072753176894
0.0077801084607239,270.114391012589,0.024701844362798382,54.45506122813795,272.21591027146934,0.00774999948346742
0.00855380864661,270.528880525382,0.027158342452986747,54.53862231391702,272.84293280277774,0.00851743211681694
0.0093403546222818,270.958206199932,0.02965562592574471,54.6251743699063,273.48905193365675,0.00929700324579214
0.0101320248028246,271.047656220601,0.0321691787489681,54.64320749407317,273.7939177961756,0.010081039936922493
0.0109236377196595,271.142314638486,0.03468254975991891,54.662290631118786,274.1041750540668,0.010864405751131621
0.0117098226842495,271.321407441655,0.03717868702249216,54.69839574023766,274.4985330132378,0.01164179327049567
0.0124898647807319,271.324311633481,0.03965532067882378,54.69898122530977,274.7131155975083,0.012412509855351526
0.0132637223858542,271.719396569708,0.042112318575087085,54.778630348453135,275.32340721266047,0.013176529376450502
0.0140354880548938,272.068386289877,0.044562674574287815,54.84898667603921,275.88699887576286,0.013937902638322208
0.0147986001393155,272.248439668159,0.04698555544232671,54.885285437100855,276.27733546536064,0.014690169297138286
0.0155545008207044,272.535655673488,0.04938554010573647,54.943188183775185,276.7748117533325,0.015434769550124745
0.0163128060078254,272.832129105662,0.05179315907484564,55.00295722770146,277.2827867004646,0.01618118169995264
0.017063761660949,272.971425995723,0.05417744327351307,55.03103948073775,277.6293453491634,0.016919810932929668
0.0178135167464496,273.214525132583,0.056557915669977483,55.08004826672874,278.08143665140557,0.01765671544052303
0.0185608615584739,273.235619038977,0.05893073544815463,55.084300798257765,278.30710753680336,0.018390710970557955
0.0193058822810619,273.308837054122,0.061296176242371526,55.099061550111,278.5853052886628,0.01912188807821938
0.0200500189370593,273.443676143231,0.06365881012516328,55.126245110475374,278.92622702812196,0.01985166426743541
0.0207939639820054,273.720534707523,0.06602083564286713,55.182059797036636,279.4122696473665,0.020580720563874035
0.021529866729381,273.930841788254,0.06835732686578468,55.224457704512005,279.8285363050223,0.021301372958130217
0.0222672804372887,274.218814764206,0.07069861538839162,55.282513056463934,280.3249220137415,0.02202298443599044
0.0229960703855592,274.462766299576,0.07301252347415045,55.33169368599452,280.77433139161633,0.0227356456967737
0.0237220585850805,274.875845720037,0.07531753600763058,55.41497049715946,281.39646663583125,0.023445062611289445
0.0244420159449415,275.132052458402,0.07760340062518926,55.46662177561384,281.8568344715547,0.024148089676813114
0.0251592606412314,275.477280307516,0.07988065253590969,55.53621970999523,282.4080850035104,0.024847976756082177
0.0258708465602651,275.824863809962,0.08213993782884169,55.60629254408834,282.9606865390955,0.025541858279406332
0.0265799884256744,276.188321197756,0.08439146325151622,55.67956555346761,283.5294035784988,0.026232877895116195
0.0272847183712764,276.529003692238,0.08662898082880258,55.74824714435518,284.0740196794703,0.026919125602598282
0.0279861087814374,276.922181273724,0.08885589538106374,55.82751174478276,284.6721555628434,0.027601654083150018
0.0286870855457158,277.374007853562,0.09108149660764767,55.91859998327809,285.3310597450151,0.028283314925869052
0.0293860375342666,277.666917597843,0.09330066917129645,55.97765058772515,285.8264480603973,0.028962544451374625
0.0300788321827262,278.105847617417,0.09550029218015567,56.06613887967127,286.47094673693607,0.029635335412540646
0.0307721773378011,278.192457892891,0.09770166304751848,56.083599511206835,286.7530455412098,0.030308208102542734
0.0314612646427787,278.458220949868,0.09988951524082237,56.1371773434934,287.2188687311292,0.03097650036916624
0.0321473599858627,278.670761274388,0.10206786795511406,56.180025472916626,287.6292905546101,0.031641447549727024
0.0328361069355145,279.00700535659,0.10425463952025854,56.24781227988855,288.1685092202367,0.03230852017885464
0.0335132248113971,279.160501691296,0.1064044887761858,56.27875714096528,288.51607034293886,0.03296389619850025
0.0341907468396307,279.585814754424,0.10855562121582746,56.36450025449188,289.1450625666444,0.03361923377270859
0.0348713663780847,279.824721079264,0.11071658825041893,56.41266376957962,289.5825914496644,0.03427713530080244
0.0355525805159954,280.220751107789,0.11287944313828539,56.49250342333026,290.1833219238014,0.034935178464874456
0.0362347405546705,280.491902168891,0.11504530126107883,56.54716747724842,290.6554534716668,0.035593701718095706
0.0369154279842931,280.726721811645,0.11720648385013058,56.594507117227636,291.0898688939495,0.036250371422406134
0.0375906722882963,280.866934343846,0.11935038451534075,56.622773963719354,291.424911229384,0.036901364280669036
0.0382768489518957,280.896728436343,0.12152899542226885,56.62878045276674,291.6485700817825,0.037562463008376415
0.0389616022586289,281.032170167872,0.12370308717114675,56.656085505842995,291.9816338038319,0.03822175499398119
0.0396460561232491,281.152187515647,0.1258762281913159,56.680281003154434,292.29876292106655,0.03888032457694033
0.0403282417290923,281.345485950338,0.12804216748986805,56.71924996758814,292.69165471713217,0.0395362804039026
0.0410092218852158,281.491746107717,0.13020427948556015,56.74873601531576,293.0355035827052,0.04019064827295595
0.0416919523100091,281.705362605081,0.1323719485842789,56.791801101184326,293.4502091482858,0.04084626844324971
0.0423785707029426,281.891563723457,0.13455196198184274,56.829339246648935,293.83772528727457,0.04150518896459908
0.0430656856647545,282.193724051522,0.13673355198559553,56.89025476878684,294.3465902680913,0.042164151662429865
0.0437512382803809,282.288484115418,0.13891018154020934,56.909358397668264,294.6389548477591,0.04282118355863724
0.0444380283852654,282.42812036192,0.14109074012321765,56.93750906496307,294.97866919136015,0.04347896888548616
0.0451249303084245,282.634528429161,0.14327165372924777,56.97912093131886,295.3883918272813,0.04413642880555617
0.0458185242285358,282.82454986583,0.14547381442560117,57.01742925295133,295.7831533562823,0.04479985558933263
0.0465136201558185,283.018639814539,0.14768074399472375,57.05655778661106,296.18286132388886,0.04546427777939408
0.0472064847494609,283.293979500582,0.14988058907953836,57.11206626731733,296.6672924234903,0.046126128059487674
0.0478982763321655,283.501232388972,0.15207702735462544,57.15384844961676,297.08045275844853,0.04678651661923605
0.0485970466290143,283.739983901281,0.15429562304712038,57.201980754498244,297.5289091294473,0.047453124662737406
0.0492954289178883,284.053284982104,0.15651298681429535,57.265142252392174,298.055813500832,0.04811891885649416
0.0499968775920486,284.234368053537,0.15874008635475428,57.301648599593065,298.445198960563,0.048787190443151926
0.0506943634529928,284.477680856373,0.16095460396325215,57.3507004606448,298.8990958039705,0.04945124413457212
0.0513917199521508,284.842995088372,0.16316871084807877,57.42434780981579,299.48156652228545,0.05011473411269019
0.0520961989565002,285.071352585203,0.16540543168688812,57.470384681176924,299.9224864862804,0.050784554009782136
0.0528027725896235,285.401292427451,0.16764880297205462,57.53690055337412,300.4712719682823,0.051455915124223976
0.0535100503130804,285.685243824134,0.16989440974403025,57.59414515494541,300.972275594868,0.052127494143588395
0.0542195668662008,285.761111275517,0.17214712480018754,57.60944003314423,301.25495495607976,0.05280074613391741
0.0549304127418482,285.901863362742,0.17440406045536802,57.63781565392879,301.6065707209209,0.053474805266207404
0.0556417151627419,286.069757934569,0.17666244564170552,57.671663199609114,301.9871699222388,0.05414884283016432
0.0563529382480454,286.005587211188,0.17892057893754415,57.65872638177551,302.12284240589605,0.05482235127019746
0.0570641848829452,286.138259706045,0.181178787003351,57.685473156738674,302.46650625999496,0.055495428680204975
0.0577755769024429,286.198876037471,0.1834374566652562,57.697693409154155,302.7341812093666,0.056168190805434684
0.0584870327818393,286.335515257748,0.18569632908233977,57.725239875962,303.0824299252327,0.056840560957365414
0.0592035733013658,286.604892372545,0.18797134523183642,57.77954630230507,303.57292612665304,0.057517279780042535
0.0599247042234576,286.808004506171,0.19026093590947787,57.820493708444076,303.9948893451234,0.05819787184950431
0.0606506759382089,286.927914005435,0.19256589610381325,57.844667463495696,304.3302859354049,0.058882565022785834
0.0613875609489345,287.13332787595,0.19490550601286702,57.88607889979152,304.7597425414053,0.05957707186770083
0.0621277575966973,287.299383117433,0.19725563036951393,57.9195556364745,305.1486495494335,0.06027421463966644
0.0628718274451405,287.406137129391,0.19961805213832107,57.941077245285236,305.4758861896645,0.06097451583886661
0.0636196806089644,287.513831874711,0.20199248593346197,57.96278850594174,305.8053700292396,0.06167788398477575
0.0643707979123877,287.603447394333,0.20437728337183095,57.98085499469753,306.11671078545965,0.06238382448798579
0.0651191002422539,287.746713493938,0.20675314326915611,58.009737440377904,306.4845205743289,0.06308662412212847
0.0658662296825803,288.005283947324,0.20912527924219243,58.061865243780524,306.9751061295952,0.06378782976671693
0.0666120526653004,288.206882936499,0.21149326721232878,58.102507599998205,307.4049350011672,0.06448731920049354
0.067364348407402,288.291408593839,0.21388180619350136,58.11954797251794,307.71197148521503,0.06519238395461947
0.0681250588676838,288.447051993515,0.21629706190489606,58.15092568189262,308.09752439078306,0.06590483000082041
0.0688906739834335,288.595250986839,0.21872788989740136,58.18080259894675,308.47677233574046,0.06662135738687237
0.0696621592808912,288.740652996288,0.22117735571682956,58.21011564405167,308.85495035618396,0.06734285962794409
0.0704431354495113,288.872944920106,0.22365695505219835,58.23678569589338,309.22206090681226,0.06807270801924557
0.0712354437345919,288.852487574589,0.22617253385732927,58.23266149503715,309.42902270080555,0.06881260272513363
0.0720376913604849,288.917797401975,0.22871967006953955,58.245827956238166,309.73076851976964,0.06956122188171585
0.0728388361584484,289.014377891868,0.23126330480307364,58.265298583000586,310.06584881056966,0.07030825307436647
0.0736440101054401,289.189132225815,0.2338197320847723,58.30052905672431,310.4861796018364,0.07105847941431456
0.0744572282861351,289.286204541165,0.23640169980847894,58.32009883549886,310.8256535127161,0.07181563015284669
0.075277689897816,289.363843314118,0.23900666542556578,58.33575081212619,311.1464849787584,0.07257894440576003
0.0761078451495728,289.492331371112,0.24164240834989364,58.36165400441619,311.52496889909344,0.07335068455129447
0.0769431110647798,289.60064717887,0.24429437763067585,58.383490471260195,311.88342193918595,0.07412657511226702
0.0777850314183774,289.715429632098,0.24696747475334827,58.406630613830956,312.25095342841945,0.07490803833246988
0.0786451637887069,289.835840268381,0.24969839502914437,58.43090539810561,312.6300273981253,0.07570577564653252
0.0795190865449335,289.841155748561,0.25247309978016386,58.431976998909896,312.8890596968144,0.07651565172881743
0.0804066717833475,289.848357976183,0.25529118291212827,58.4334289679985,313.1540997629162,0.07733751820728567
0.0813028884405417,289.870472904726,0.2581366707987199,58.43788733759277,313.43777962550604,0.07816669223235621
0.0822074682967335,289.881300173436,0.26100871184212887,58.44007011496469,313.7117079672596,0.07900290723459633
0.0831307088649552,289.835625977467,0.26394000064623274,58.430862197057344,313.9298670192918,0.07985565220894313
0.0840696241367854,289.682945029374,0.2669210566342936,58.40008171792181,314.03648133683055,0.08072212986333999
0.085025764858364,289.524661489397,0.26995680342530565,58.36817175626243,314.1417172778919,0.08160373312372007
0.0859965512072972,289.255725377052,0.2730390500831686,58.31395423601368,314.1307201764435,0.08249804582281271
0.0869823386518713,288.941487593712,0.2761689252196914,58.250603898892344,314.07429391816373,0.08340536021670886
0.0879934065984739,288.459621461728,0.27937906595015466,58.153459686684364,313.8421662202517,0.08433508830369163
0.0890215833249117,287.788956660526,0.2826435270565946,58.01825366276205,313.4083852458705,0.08527966315287144
0.0900633365368423,287.025939349784,0.2859510935044743,57.86442937291645,312.8764531202469,0.08623580146744528
0.0911219250603887,286.090772067749,0.28931211206673413,57.675899648858206,312.1599139605752,0.08720645593251843
0.0921935614940971,284.886997015295,0.29271455774375826,57.43321859828347,311.15174389349323,0.08818811573053233
0.093271063932876,283.526428944594,0.29613562798688126,57.15892807523015,309.9712406253452,0.08917417838608749
0.0943601483328937,281.941000118574,0.2995934709569375,56.839305623904515,308.544994710887,0.09016985305363201
0.0954522210212518,280.169148415266,0.30306080174247446,56.48210032051763,306.9119158931359,0.09116726524672857
0.0965596387759176,278.192989870554,0.30657685311353833,56.08370675790369,305.0552044824472,0.0921776775252322
0.0976821855063788,276.030545122286,0.3101409389827527,55.64775789665287,302.993812036348,0.09320085265203029
0.0988154072302113,273.66576502152,0.31373891795592085,55.171018228338426,300.70815903708876,0.09423269701018044
0.0999521778682387,271.080902574716,0.3173481647316579,54.64990995906275,298.17602916554665,0.0952667041940366
0.101115083463468,268.158525548691,0.32104038999651086,54.06075875061611,295.2733972409874,0.09632337858455961
0.102282879021621,264.979062560368,0.3247481408936467,53.41977901217018,292.08188395949264,0.09738337381681403
0.103463449938404,261.44947356009,0.3284964535544327,52.70821386971414,288.4999380791964,0.09845382422538
0.104661523302591,257.508161002769,0.33230033648572643,51.91364525815823,284.4593573961676,0.09953897429276455
0.105255688128137,255.606803850161,0.33418680980683496,51.53033165619246,282.51087387964344,0.10007670017388773
0.105852578739023,253.561374809325,0.336081937496398,51.117973161559924,280.401500201504,0.10061660193657332
0.106460011591173,251.336314751307,0.3380105368019743,50.66940105386349,278.0935817330138,0.10116574030885343