File: example/data/02 processed data/test_ID_125.csv
Strain,Stress_MPa,Displacement(mm),Force(kN),True Stress (MPa),True Strain
-9.53927074015677e-05,0.186586857639528,-0.00030287184599997745,0.03761591050012885,0.1865690586140122,-9.539725757523762e-05
-0.0001464557645957,0.184009741589485,-0.00046499705259134744,0.037096363904440176,0.18398279230208744,-0.00014646649028844064
-0.0002237028887835,0.180348227077576,-0.0007102566718876124,0.03635820257883932,0.18030788265819175,-0.00022372791400692134
-0.0002840855655284,0.859568507754168,-0.0009019716705526699,0.1732890111632403,0.8593243167485323,-0.00028412592547662896
-0.0002969324098788,2.3691502489673,-0.0009427604013651898,0.4776206901918077,2.368446771474509,-0.0002969765030355175
-0.0002870868341552,5.0741608253326,-0.0009115006984427599,1.022950822387052,5.07270410056526,-0.00028712805146923035
-0.0002040285677456,8.64059852792744,-0.0006477907025922799,1.7419446632301716,8.638835598985322,-0.00020404938440533402
-0.0001349971686957,12.7864093642647,-0.00042861601060884745,2.5777401278357632,12.78468323520274,-0.0001350062816336285
-5.23040140036275e-05,17.2164559749972,-0.00016606524446151732,3.470837524559436,17.215555485242792,-5.230538190621761e-05
3.93165528242478e-05,21.9068394281588,0.00012483005521698675,4.4164188287168145,21.90770072956839,3.9315779948892606e-05
0.0001285642709828,26.6913693983741,0.00040819156037039003,5.380980070712219,26.694800954822334,0.00012855600730511546
0.0002122108084561,31.5095629714517,0.0006737693168481175,6.352327895044663,31.51624964128397,0.0002121882949275328
0.0003104355555784,36.1934915063097,0.0009856328889614198,7.296607887672035,36.20472725295378,0.0003103873804311476
0.0003832330968589,40.8226276595023,0.0012167650825270074,8.229841736155665,40.838272241522176,0.00038315968181180243
0.0004738382897917,45.2309048543456,0.0015044365700886474,9.118550418636074,45.25233698894752,0.0004737260638792041
0.000557166377886,49.4395531637403,0.0017690032497880502,9.967013917810045,49.46709922050085,0.0005570112183301803
0.0006381932559871,53.6157475654198,0.0020262635877590423,10.808934709188632,53.64996477393076,0.0006379896972730637
0.0007346465512168,57.5875150270592,0.00233250280011334,11.609643029455135,57.62982149636697,0.0007343768305306897
0.0008460770527827,61.6908494175794,0.002686294642585072,12.436875242584009,61.74304462963829,0.0008457193313521431
0.0009316649532133,65.7340728932772,0.0029580362264522275,13.251989095284685,65.79531502522384,0.0009312312227942549
0.0010322909075943,69.7880495388403,0.003277523631611902,14.069270787030206,69.86009110783799,0.001031758461729941
0.0011271805773158,73.825329022382,0.0035787983329776648,14.88318633091221,73.90854349936997,0.001126545786260247
0.0012147129933979,77.8229727665322,0.003856713754038332,15.689111309732892,77.91750534273656,0.001213975826473533
0.0013003842465605,81.7919605867005,0.004128719982829587,16.48925925427882,81.89832156374274,0.0012995394792348505
0.0013905175703418,85.5995527222173,0.0044148932858352145,17.256869828799008,85.71858040429093,0.0013895516960580824
0.0014737463984874,89.3818601039053,0.004679144815197494,18.01938299694731,89.51358629832352,0.0014726615000430821
0.0015826978710878,92.9879039910945,0.005025065740703765,18.746361444604652,93.13507574877812,0.0015814467247626568
0.0016839130394391,96.5715748970247,0.005346423900219142,19.46882949924018,96.73419303123296,0.001682496847483354
0.0017930150960202,100.097560384922,0.005692822929864135,20.179668173600277,100.27703682176696,0.001791409563329285
0.0019000203094002,103.586502028213,0.006032564482345635,20.88303880888774,103.78331848584634,0.0018982175539655392
0.0019902728942275,107.020758562211,0.006319116439172313,21.575384926141737,107.23375907709705,0.001988294925161504
0.0021116664220664,110.394109856151,0.0067045408900608195,22.25545254700004,110.62722539112815,0.002109439988300036
0.002236178086401,113.654655715274,0.007099865424323175,22.91277859219924,113.90880776580195,0.002233681561274501
0.0023829787934182,116.827287304935,0.007565957669102785,23.552381120674895,117.10568425307524,0.0023801440020585454
0.0025621026376478,119.835809842381,0.008134675874531766,24.15889926422401,120.14284148686284,0.0025588260481307643
0.002777828533046,122.739166299047,0.00881960559242105,24.744215925887875,123.08011465731477,0.002773977497395843
0.0030192973677857,125.402839234902,0.009586269142719598,25.28121238975624,125.78146769731678,0.0030147484435579033
0.0033046459417479,127.765844378051,0.010492250865049582,25.757594226615083,128.18806525716892,0.0032991975992765227
0.003628109813045,129.699050489926,0.011519248656417874,26.147328578769084,130.16961288775113,0.0036215440986004884
0.0039816704578795,131.232754779443,0.01264180370376741,26.456523363535712,131.75528036225447,0.00397376458682891
0.0043657037920296,132.200573917504,0.01386110953969398,26.651635701768807,132.7777224643641,0.004356201752584806
0.0047653957304795,132.863357724214,0.015130131444272412,26.785252917201547,133.49650420185014,0.004754077176261901
0.0051574021182841,133.138035599098,0.016374751725552014,26.840627976778162,133.82468198592096,0.005144148270728552
0.0055444389262516,133.305024448927,0.01760359359084883,26.87429292890369,134.04412601554657,0.005529125103043533
0.0059370637975234,133.289526195513,0.018850177557136794,26.87116848101542,134.0808746160774,0.005919508883084707
0.0063509621139168,133.22160855098,0.02016430471168584,26.857476283877567,134.06769393964234,0.006330879737456196
0.0067632283981442,133.021365089236,0.021473250164107834,26.81710720198998,133.92101896316746,0.006740460368235918
0.0071966263340609,132.831703575073,0.022849288610643354,26.778871440734715,133.7876437110195,0.0071708541932055565
0.0076253927902619,132.702275057558,0.024210622109081533,26.752778651603695,133.71418202903325,0.007596466439452332
0.0080650735731429,132.585088076017,0.025606608594728707,26.72915375612503,133.6543965660517,0.00803272468166912
0.00851667622864,132.457818917872,0.027040447025932,26.703496293842996,133.58591927554733,0.008480613950815686
0.0089617803534593,132.26149694814,0.028453652622233278,26.663917784745028,133.446795433009,0.008921861916154895
0.009400651418895,132.068166071308,0.029847068254991622,26.624942279975695,133.3096928640771,0.009356740276397357
0.0098397075444006,131.920623059752,0.031241071453471905,26.595197608846004,133.21868340973506,0.00979161285654961
0.0102855100563028,131.739731659102,0.03265649442876139,26.558729902474965,133.09474199389635,0.01023297412985585
0.0107388059775381,131.567584727891,0.03409570897868346,26.524025081142824,132.98046349321712,0.010681554510844123
0.011192938705085,131.383510336519,0.03553758038864487,26.48691568384223,132.8540779145746,0.011130761301704107
0.0116431333941885,131.234799061024,0.036966948526548485,26.456935490702442,132.76278333245102,0.011575873688956568
0.0120896044704062,131.022648189581,0.03838449419353968,26.41416587501953,132.6066601828582,0.01201710891246976
0.0125385323673631,130.849855380276,0.03980984026637784,26.379330844663645,132.49052052722638,0.012460575933544844
0.0129896167018231,130.630297249707,0.04124203302828834,26.335067925540933,132.32713474062592,0.012905975166455575
0.0134490199228825,130.483349228782,0.04270063825515193,26.305443204522454,132.23822239216432,0.01335938463134316
0.0139179737496856,130.310173168769,0.044189566655251776,26.270530910823833,132.1238267382489,0.013822008158933804
0.0143646925893575,130.100912609011,0.045607898971210065,26.228343981976618,131.9697722242343,0.01426249789373135
0.0148099602891379,129.885750786537,0.04702162391801283,26.18496735856586,131.80935359781046,0.014701363721564751
0.0152577014175315,129.633210496327,0.04844320200066251,26.13405523605952,131.61111531587596,0.0151424732905702
0.0157217625307435,129.437719923547,0.049916596035110616,26.094644336587077,131.4727090187059,0.015599455874122141
0.0161839836322296,129.288978003382,0.05138414803232898,26.06465796548181,131.38138870721642,0.016054419014348315
0.0166567738282143,129.147340854447,0.052885256904580395,26.036103916256515,131.29851890157485,0.016519571243094656
0.0171186171665257,128.999271498242,0.05435160950371909,26.006253134045586,131.2075606417811,0.016973744647193298
0.0175673753100643,128.794723438029,0.05577641660945415,25.965016245106646,131.05730868262077,0.017414852663343618
0.0180157839562842,128.618597604132,0.05720011406120234,25.92950927699301,130.9357624713283,0.017855422876780318
0.0184602577728356,128.43241821883,0.05861131842875302,25.89197551291613,130.80331376553823,0.018291935572732954
0.0189156318116673,128.243876324999,0.06005713100204368,25.853965467119803,130.66969027166368,0.0187389557311068
0.0193725349790363,128.021498788614,0.06150779855844025,25.809134155784584,130.50159975196507,0.01918727622127706
0.019835721574164,127.807912650326,0.0629784159979707,25.766075190305724,130.34307482063295,0.019641557044831857
0.0202964571568974,127.673120001282,0.06444125147314925,25.73890099225845,130.26443201147544,0.020093229338783592
0.0207590816477525,127.56196207009,0.06591008423161418,25.716491553330144,130.2100312558505,0.02054654821226071
0.0212230199347683,127.434914188261,0.06738308829288935,25.69087870035342,130.13946791246394,0.02100094817457086
0.0216877588762993,127.305689284704,0.06885863443225027,25.66482695979633,130.06666437749175,0.021455925410354477
0.0221300182854107,127.173913645105,0.07026280805617897,25.63826099085317,129.98827467949843,0.021888703147152848
0.0225901589606253,127.016133614811,0.07172375469998532,25.6064525367459,129.8854482637336,0.022338780070247304
0.0230462481268548,126.856876662076,0.07317183780276398,25.574346335074523,129.78045171822802,0.02278469428276982
0.0235185211007664,126.650943853845,0.07467130449493331,25.532830280935155,129.62958674930366,0.023246221803809974
0.0239769187602234,126.457732189909,0.0761267170637093,25.493878809485654,129.48979896122853,0.023693986090060983
0.0244507496331962,126.269932002876,0.07763113008539793,25.456018291779802,129.35732649647903,0.02415661495290526
0.0249087937620772,126.104786833849,0.07908542019459511,25.422725025703958,129.24590496150404,0.02460362693573104
0.0253850834823183,125.972855887318,0.0805976400563606,25.39612774688331,129.17068735052362,0.025068233238364136
0.0258592907868747,125.85154900876,0.08210324824832717,25.371672280166017,129.10598081055613,0.025530593860972173
0.0263175462043163,125.748653278114,0.08355820919870426,25.350928500867784,129.05804927089133,0.025977198088052697
0.0267833956476772,125.620478803969,0.08503728118137512,25.32508852688015,128.98502178922635,0.026430998913778557
0.0272560385156265,125.471641664147,0.08653792228711413,25.295082959492035,128.89150156196388,0.026891207095208595
0.0277243127483809,125.290711605053,0.08802469297610935,25.258607459578684,128.7643104780587,0.027346952806423394
0.0282029320918012,125.115617464366,0.0895443093914688,25.223308480816186,128.64424472733728,0.027812552309779248
0.0286817343652602,124.936278187408,0.09106450660970113,25.187153682581457,128.51966733096347,0.02827811296071447
0.0291578879405823,124.785422650493,0.0925762942113488,25.15674120633939,128.42390202075427,0.028740883313329444
0.0296336738754477,124.657640354398,0.09408691455454644,25.13098029544664,128.35170421474308,0.029203082549191704
0.0301221823730714,124.565343913138,0.09563792903450169,25.11237333288862,128.31752391985387,0.02967741886949004
0.0305934679735757,124.449232492202,0.09713426081610284,25.088965270427927,128.25656610078826,0.030134818810759807
0.031064611615935,124.286755060312,0.09863014188059362,25.0562098201589,128.14767483526543,0.030591871951845907
0.0315345843489895,124.103451978618,0.10012230530804166,25.01925591888939,128.0170027530385,0.03104758117747473
0.0319865465363276,123.911478025982,0.10155728525284012,24.980553970037974,127.87497828424522,0.03148563067238953
0.0324661330201579,123.760212680715,0.10307997233900132,24.950058876432145,127.77822820821012,0.031950244366088246
0.0329417143982339,123.586840780104,0.10458994321439263,24.91510710126897,127.6580031924622,0.03241076492339672
0.0334314866912954,123.455059883469,0.10614497024486289,24.888540072507354,127.58234607493628,0.03288480543260851
0.0339137814682241,123.317753858595,0.10767625616161151,24.860859177892753,127.49992521410762,0.03335138911662713
0.034411610349038,123.205249805775,0.10925686285819565,24.83817836084424,127.44494085504721,0.03383277264786159
0.0349041490255499,123.084939952841,0.11082067315612092,24.813923894492746,127.38111503975583,0.03430881279164536
0.0353927442019478,122.973008339894,0.11237196284118427,24.79135848132263,127.32536056781184,0.03478081773650831
0.0358848760924577,122.841441747592,0.11393448159355318,24.764834656314548,127.24959166372321,0.035256014199743224
0.0363836472784116,122.709237867961,0.11551808010895681,24.738182354180935,127.1738474963516,0.035737391193081884
0.0368840740449927,122.536399604532,0.11710693509285182,24.703338160273653,127.05604124075236,0.03622013326363318
0.0373880901256818,122.365415167341,0.1187071861490397,24.668867697735948,126.94042433788401,0.036706102365773506
0.0378894115596131,122.237626203788,0.12029888170177158,24.64310544268366,126.86913793109346,0.0371892391446147
0.0383846692859523,122.122825275243,0.12187132498289854,24.619961575488986,126.81046953569933,0.03766630307398799
0.0388865985278058,122.013446001094,0.1234649503257834,24.597910713820553,126.75813389073264,0.038149561336304524
0.0393984116659198,121.895937426821,0.12508995703929535,24.574220985247116,126.6984437499661,0.03864209546511789
0.0399219951023045,121.742606499362,0.1267523344498168,24.543309470271378,126.6028142397713,0.03914570563096476
0.0404346917704428,121.585857505147,0.12838014637115588,24.511708873037637,126.5021441770126,0.03963859868315454
0.040932151826083,121.47661686928,0.12995958204781352,24.489685960846845,126.44891619429228,0.04011661154921225
0.0414505054032794,121.340264964287,0.1316053546554121,24.462197416800258,126.36988027282455,0.040614458173225454
0.0419445731428896,121.178137734302,0.1331740197286745,24.429512567235285,126.26090299581757,0.04108874915524764
0.0424672120487914,120.995536178345,0.1348333982549127,24.392700093554353,126.133879270188,0.04159022292407533
0.0429919148886619,120.796156216731,0.13649932977150153,24.352505093292972,125.98941428367822,0.042093424203989906
0.0435084259248363,120.661645588407,0.13813925231135524,24.32538775062285,125.91144385745906,0.04258852217893081
0.0440277921015251,120.539327692176,0.13978823992234218,24.300728462742683,125.84640815186474,0.04308610989302153
0.0445445186926178,120.468690156867,0.1414288468490615,24.286487935624386,125.83490997743475,0.04358092311922894
0.0450668812645907,120.348466307752,0.14308734801507547,24.262250807642804,125.77219634921906,0.044080884578918886
0.045595692507907,120.167693158345,0.14476632371260473,24.225806940722354,125.64682234497742,0.04458676368272824
0.0461257496587388,120.04149638735,0.14644925516649568,24.20036567168976,125.57850039837331,0.04509357797596283
0.0466617037897846,119.910261228695,0.1481509095325661,24.173908663704914,125.50547831950405,0.04560576963869417
0.0471977693489406,119.82285514467,0.1498529176828864,24.156287597165473,125.47822662451966,0.04611780550141116
0.0477556576533249,119.712907581782,0.15162421304930654,24.134122168487252,125.4298762129417,0.046650407620753044
0.0483085754495888,119.573848335582,0.15337972705244443,24.10608782445333,125.35029060969916,0.047177984782136397
0.0488750227071488,119.420731375877,0.15517819709519745,24.075219445376803,125.25742233357731,0.04771818285714764
0.0494268573724072,119.280983986942,0.15693027215739286,24.04704637176751,125.17666816970498,0.04824416501750289
0.0499584811879023,119.145816838232,0.1586181777715898,24.01979667458757,125.09816088736207,0.04875062166183008
0.0505000054230497,119.025670402169,0.1603375172181828,23.995575153077272,125.03646740296067,0.049266246465269094
0.0510318421336715,118.909734162324,0.162026098774407,23.97220240712452,124.97791694425257,0.0497723884231879
0.051584435199741,118.762694736298,0.16378058175917767,23.94255925883768,124.88900126706919,0.0502980126987622
0.0521318909843425,118.586773029241,0.16551875387528742,23.907093442694986,124.76892575298636,0.050818478115268795
0.052674469308633,118.407119147561,0.16724144005490976,23.8708752201483,124.64415131102285,0.05133403940066252
0.0532151703776427,118.247378755922,0.16895816594901555,23.838671557193877,124.53993316312804,0.05184755261683655
0.0537773793851928,118.068878953799,0.17074317954798712,23.802685997085877,124.41831385088186,0.05238121280557919
0.054340041013187,117.916908781119,0.1725296302168687,23.772048810273592,124.32451844043324,0.052915017645775
0.0549231825399603,117.773998628226,0.17438110456437395,23.74323812345036,124.24252145334509,0.05346795151872079
0.055492783855578,117.671339592396,0.17618958874146015,23.722542061827035,124.20124980639315,0.0540077515756941
0.0560595406269652,117.599404434816,0.1779890414906145,23.708039934058906,124.19197302543648,0.05454456686407327
0.0566290916214698,117.477393193644,0.1797973658981666,23.68344246783863,124.1300312562583,0.055083738609126895
0.0571922267018859,117.317545193054,0.18158531977848774,23.65121711091969,124.02719683384389,0.05561655099857242
0.0577657374758721,117.171419176939,0.18340621648589392,23.621758106070903,123.93991261678943,0.05615888876391574
0.0583236575290915,116.998021343757,0.18517761265486551,23.586801102901415,123.82177387219163,0.05668620114255545
0.0588963834310399,116.841572817968,0.18699601739355168,23.55526108010235,123.7231188913408,0.05722721804664477
0.0594707876981199,116.681508621794,0.18881975094153067,23.52299213815367,123.62064984933706,0.05776952656519262
0.0600482854159757,116.515471343466,0.19065330619572282,23.489519022842746,123.51202562207538,0.05831445936572449
0.0606497232605666,116.34592760646,0.19256287135229894,23.455339005462335,123.4022759182857,0.05888166682124616
0.0612369509865022,116.207543969454,0.19442731938214447,23.427440864241927,123.32373964377325,0.0594351626776033
0.061806579082187,116.111089629862,0.1962358885859437,23.40799566938018,123.28751887338895,0.059971777307766004
0.0623796851332201,116.018789518293,0.1980555002979738,23.38938796688787,123.25600507798146,0.06051137788290746
0.0629566572984692,115.91203871379,0.19988738692263971,23.367867004700067,123.20947321186097,0.0610543245854165
0.0635515314247242,115.6647075527,0.20177611227349931,23.318005042624318,123.01537684946693,0.061613809044424886
0.0641374301832414,115.504900246052,0.20363634083179144,23.285787889604084,122.91308772140542,0.062164546284593294
0.064721560309147,115.312289791437,0.2054909539815417,23.246957621953698,122.77548110955934,0.06271331925938761
0.0653186948597831,115.201897432061,0.20738685617981134,23.224702522303495,122.72673501769381,0.06327399839662913
0.0659130607668765,115.096407867298,0.20927396793483288,23.203435826047276,122.68276439310442,0.06383176591387213
0.0665206768889712,114.909605202743,0.21120314912248356,23.16577640887299,122.55346992187391,0.06440164635405589
0.0671211672094155,114.776575952517,0.21310970588989417,23.138957712027427,122.48051369875007,0.06496452464401788
0.0677293470035434,114.624950564431,0.21504067673625027,23.10839003378929,122.38842361647336,0.065534288012958
0.0683496894460389,114.471849167474,0.2170102639911735,23.07752479216276,122.29596450838466,0.06611511152121761
0.0689650557232849,114.342984643315,0.21896405192142954,23.051545704092305,122.22865495080792,0.06669094275584546
0.0695982963814074,114.23188599802,0.22097459101096847,23.02914821720083,122.18223065591735,0.06728315404199384
0.0702153335102617,114.084094030574,0.2229336838950809,22.999353356563716,122.09454674114681,0.06785987449777306
0.0708475040901306,113.956125606575,0.22494082548616465,22.973554922285523,122.02963268158226,0.06845039485722962
0.0714715670394291,113.782788998623,0.22692222535018738,22.9386102621224,121.91502323047129,0.0690329999185956
0.0720865372775638,113.629842924625,0.22887475585626504,22.9077763336044,121.8210248324547,0.06960678446287129
0.0727032162287608,113.486739623761,0.23083271152631554,22.878926708150217,121.73759059372438,0.07018183287233193
0.0733116576342959,113.319589905442,0.23276451298888945,22.845229324937108,121.62723688384857,0.07074887593363445
0.0739438370683512,113.116431818226,0.23477168269201504,22.80427265455436,121.48069482234617,0.07133770148688649
0.0745824532521747,112.938881039224,0.23679928907565467,22.76847841750756,121.36213985468483,0.07193217054738384
0.0752040350964707,112.747846877842,0.23877281143129445,22.72996593057295,121.22693991149472,0.07251044365960804
0.0758115214778021,112.620250260881,0.24070158069202163,22.704242452593608,121.15816278236922,0.07307528048342908
0.0764250519041979,112.492905116135,0.24264953979582835,22.678569671412816,121.09018122848963,0.07364541338666347
0.0770271549939948,112.28006483578,0.24456121710593348,22.63566107089325,120.9286787926214,0.0742046114069939
0.0776431482196773,112.064539476482,0.24651699559747542,22.592211158458774,120.76558312522437,0.07477638634773162
0.0782600080107918,111.8675365123,0.24847552543426396,22.55249536087968,120.62229081590014,0.07534863821921804
0.0788917214794004,111.6450747191,0.25048121569709625,22.50764706337056,120.45294685838608,0.07593433043366077
0.0795234884196813,111.537658018097,0.25248707573248813,22.485991856448354,120.40752167385753,0.07651972934618252
0.0801531379413396,111.385726936604,0.25448621296375323,22.45536255041937,120.31364247245001,0.07710282547438324
0.080783777565266,111.262007479459,0.25648849376971955,22.430420707858936,120.25017274314457,0.0776864978965669
0.0814144159471919,111.101696571253,0.2584907706323343,22.398102028764608,120.1469763083437,0.07826982869547389
0.0820608655805367,110.906751880701,0.260543248218204,22.358801179149324,120.00785593875712,0.07886743168923405
0.0827064030718072,110.718906544068,0.2625928297529878,22.32093155928411,119.87606905637145,0.07946383530245678
0.0833553745440559,110.562459909529,0.2646533141773775,22.289391917761044,119.77843516579995,0.08006305319953942
0.0840014945346938,110.406451387992,0.2667047451476528,22.25794059981919,119.68075831085537,0.08065928173854633
0.0846442392437944,110.226760626925,0.2687454595990472,22.22171494238808,119.55682092449891,0.08125204312682588
0.0852776951130204,110.040381586468,0.27075668198383973,22.18414092783195,119.42437169751923,0.08183589444165032
0.0859066055528162,109.841373431892,0.27275347263019145,22.144020883869427,119.27747297268512,0.08241521924350377
0.0865315643323354,109.648537886405,0.2747377167551649,22.105145237899247,119.13659739646897,0.08299057167969519
0.0871695387079054,109.412527238294,0.27676328539759965,22.05756549124007,118.94996676652224,0.0835775653496125
0.0878066094937798,109.188808837316,0.2787859851427509,22.012463861602907,118.77630793598517,0.08416338400755076
0.0884548025112875,109.002964075143,0.2808439979733378,21.97499755754883,118.64479973555473,0.08475907810303006
0.0890974361064446,108.817805564456,0.2828843596379616,21.93766960179433,118.51319304297861,0.08534931295702515
0.0897217736053874,108.620451436716,0.284866631197105,21.897883009641948,118.36607098943601,0.08592241008527535
0.0903456924554841,108.389180006071,0.286847573546162,21.851258689223915,118.18167552840161,0.0864947950016544
0.0909608736405934,108.116373010735,0.288800773808884,21.796260798964177,117.95073275464372,0.0870588433669607
0.0915892333217782,107.847629623671,0.29079581579664576,21.742082132132072,117.72531133647412,0.08763464659506662
0.0922444516534358,107.661962110142,0.2928761339996586,21.704651561404628,117.59318076892502,0.08823470909600342
0.0928787153529012,107.456493315428,0.29488992124546126,21.663229052390285,117.43691437089257,0.0888152381269114
0.0935153355861785,107.314794460436,0.2969111904861167,21.6346625632239,117.35037347776544,0.08939758534926609
0.0941125628286677,107.067075416678,0.29880738698101994,21.58472240400228,117.1434322787118,0.08994358977511852
0.0947353834818392,106.801142524114,0.30078484255483945,21.53111033286138,116.9189897174345,0.09051267514354729
0.0953651711096288,106.563158484262,0.30278441827307145,21.48313275042722,116.72557232709615,0.09108779727100272
0.0960232033457021,106.257132971048,0.3048736706226041,21.421438006963278,116.46028325725824,0.0916883592375822
0.0966675860986266,106.063886335004,0.30691958586313944,21.382479485136805,116.31682619924794,0.09227611449662478
0.097313954151448,105.817877446552,0.3089718044308474,21.332884093224884,116.11543352078931,0.09286533373996286
0.0979574056939044,105.616008086318,0.31101476307814646,21.292187230201712,115.96187823820014,0.09345154970638297
0.0985890495613414,105.397542681857,0.31302023235725895,21.24814460466237,115.78858624096219,0.09402667424639569
0.0992243427615088,105.106823075463,0.3150372882677904,21.18953553201334,115.53597851487599,0.0946047881300223
0.099853488323236,104.822366040779,0.31703482542627426,21.132188993821046,115.28924494424591,0.09517697850000321
0.100485242384327,104.520362015443,0.31904064457023823,21.071304982313308,115.02311592666238,0.09575121197563499
0.101134932853055,104.189594921972,0.3211034118084496,21.004622336269556,114.72680260839265,0.09634140504789536
0.101767409923145,103.875628961221,0.32311152650598535,20.941326798582153,114.44678267474208,0.09691562667832104
0.10240324452569,103.561031114424,0.32513030136906573,20.87790387266788,114.16601670696694,0.09749256442032256
0.103034900198007,103.278375784396,0.3271358081286722,20.820920558134237,113.91965292595351,0.09806538092945916
0.103684425726951,102.974088218255,0.32919805168306937,20.759576184800206,113.65089741992115,0.09865406073125406
0.104333618588007,102.587164318031,0.33125923901692217,20.681572326515052,113.29045439201366,0.09924209295448179
0.104973971159516,102.278145980941,0.33329235843146326,20.619274229757707,113.01468912739307,0.0998217791805304
0.105601650856374,101.956434932425,0.33528524146898747,20.554417282376882,112.72320277671955,0.10038966720704758
0.106229793034916,101.682057670214,0.3372795928858583,20.499102826315145,112.48372161188523,0.10095765099004676
0.106873158376567,101.334211414163,0.3393222778456002,20.42897702109526,112.16411863959335,0.10153906574923302
0.107518154562258,100.924382145648,0.34137014073516914,20.346355440562636,111.77558546428416,0.10212161518407127
0.108155567265365,100.531784189217,0.3433939260675339,20.267207692546148,111.40485633640101,0.10269698213852133
0.10877307540878,100.132529896297,0.3453545144228765,20.186718027093477,111.02425312157882,0.10325406651868439
0.109385661588471,99.8002170260433,0.3472994755433954,20.11972375245033,110.71692979211002,0.10380640408140918
0.110013032570021,99.3695816773585,0.34929137840981667,20.032907666155474,110.3015307028991,0.10437175630939015
0.110662822865544,98.9186447796608,0.3513544625981022,19.941998787579617,109.86526124501206,0.1049569748251654
0.111337416495923,98.4340542802901,0.3534962973745555,19.844305342906484,109.39344757907706,0.10556416976525153
0.111993080576843,98.0046294441574,0.3555780308314765,19.75773329594213,108.98046980640056,0.10615397330619174
0.112650286691774,97.6010423923673,0.35766466024638244,19.67637014630125,108.59582779928347,0.10674481509568434
0.113281860636908,97.233776230616,0.35966990752218286,19.60232928809219,108.24859931877293,0.10731228429086194
0.11391408521609,96.8170521998208,0.36167722056108575,19.51831772348387,107.84587813448182,0.10788001574470263
0.114540701980276,96.2972156177218,0.36366672878737627,19.413518668532717,107.32716629332165,0.10844239357197662
0.115191084003631,95.7636204602573,0.3657316917115284,19.305945884787874,106.79473570918664,0.10902576601693911
0.115853060831867,95.2117753759779,0.3678334681411777,19.194693915797142,106.24235098052112,0.1096191893691348
0.116543170876672,94.7294968502806,0.3700245675334336,19.097466565016568,105.76957278876401,0.1102374578082102
0.117210568558955,94.2002806751328,0.37214355517468206,18.990776584106772,105.24154913147827,0.11083501490715068
0.117878495446366,93.7068455501815,0.374264223042212,18.89130006291659,104.7528675166619,0.11143268854624658
0.11854906531799,93.1509908864916,0.3763932823846182,18.779239762716706,104.19395378952977,0.11203236805608974
0.119200963455932,92.5808583549092,0.37846305897258403,18.664301044349696,103.61658586839154,0.11261500521216261
0.119882685965159,91.9732012484711,0.3806275279393798,18.541797371691775,102.99919565095192,0.11322393514693148
0.120551136312621,91.338799294688,0.38274985779257165,18.4139019378091,102.34979533909306,0.11382065026580702
0.121208536368119,90.7248257479535,0.3848371029687778,18.290124870787427,101.72144908911558,0.1144071538793336
0.121829227913597,90.0642161100676,0.38680779862567044,18.15694596778963,101.0366700214005,0.11496059223084495
0.122449540021739,89.4204948748957,0.3887772895690213,18.027171766778974,100.36999334084294,0.11551338641381433
0.123098031997315,88.7222934265938,0.3908362515914751,17.88641435480131,99.64383314169581,0.11609096669016623
0.123754092355884,88.0608077069543,0.39291924322993166,17.753058833721987,98.95869303685446,0.11667494849306555
0.124398961781954,87.3523393805945,0.3949667036577039,17.610231619127852,98.21887970876536,0.11724863669687331
0.12504233677851,86.6756870174915,0.39700941927176925,17.473818502726285,97.51381746404141,0.11782066764030041
0.125682270956436,85.9028116243563,0.39904121028668427,17.31800682347023,96.69927207084834,0.11838931490436
0.126326284348473,85.109845155957,0.4010859528064018,17.15814478344093,95.86145565598292,0.11896126069743948
0.126953846377743,84.2845804233527,0.403078462249334,16.991771413347905,94.98483209843154,0.11951828158173954
0.127610891878225,83.4692414384932,0.40516458171336434,16.82739907400023,94.12082578285822,0.12010113955688143
0.128289694304369,82.5823682091178,0.4073197794163716,16.64860543095815,93.17683498159637,0.12070294129476665
0.128950241152961,81.6610133308745,0.40941701566065114,16.4628602875043,92.19122069268593,0.12128821081536245
0.129621308208263,80.6536786119422,0.411547653561235,16.259781608167547,91.10811394543096,0.12188245107774352
0.129969774578531,80.1781982184428,0.41265403428683595,16.16392476083807,90.5989405670066,0.12219088420591882