File: example/data/02 processed data/test_ID_069.csv
Strain,Stress_MPa,Displacement(mm),Force(kN),True Stress (MPa),True Strain
6.91044254193064e-05,0.607245919103103,0.0002194065507062978,0.12242077729118556,0.6072878824834308,6.910203781848636e-05
7.04702657080463e-05,1.07017978303623,0.000223743093623047,0.21574824426010397,1.0702551988898958,7.04677827954173e-05
7.67072653888076e-05,2.12535483008499,0.00024354556760946414,0.42847153374513397,2.125517860241987,7.670432353704498e-05
8.17520517753272e-05,3.70990091382808,0.00025956276438666385,0.747916024227741,3.7102042058396685,8.174871025842803e-05
0.0001082650525537,6.37942659295655,0.0003437415418579975,1.2860924011400405,6.380117261911899,0.00010825919231584651
0.000131670821571,9.88514258621339,0.00041805485848792496,1.9928447453806197,9.886444171059065,0.00013166215372929454
0.0001609836479992,14.1516404633185,0.00051112308239746,2.85297071740501,14.153918646025458,0.00016097069152225368
0.0002101503547129,19.2945575558895,0.0006672273762134575,3.889782803267323,19.2986123140039,0.00021012827622030064
0.0002648576741538,25.0887843415239,0.000840923115438315,5.057898923251218,25.09542929859194,0.0002648226055519499
0.0003282574831909,31.172043570381,0.0010422175091311073,6.28428398378881,31.182276026949328,0.0003282036184905775
0.0004126979600385,37.3463020020234,0.0013103160231222374,7.529014483607917,37.361714744674615,0.00041261282365833546
0.0004928479215468,43.6263174089997,0.0015647921509110898,8.795065589654339,43.647818548859455,0.0004927265118991614
0.0005770602106398,50.0041385204703,0.0018321661687813648,10.080834325726812,50.032993919177784,0.0005768937754221882
0.0006707484800995,56.3769290357358,0.002129626424315912,11.365588893604338,56.41474377519919,0.000670523628877751
0.0007601986191255,62.7641650384606,0.0024136306157234626,12.653255671753657,62.8118782700534,0.0007599098145118466
0.000857239252418,69.0498795115219,0.0027217346264271497,13.920455709522814,69.10907177861391,0.0008568720326984954
0.0009546908289608,75.2761684224299,0.00303114338195054,15.175675553961868,75.34803389006211,0.0009542354015099319
0.0010481627302986,81.3908771126717,0.003327916668698055,16.408400825914615,81.47618799664751,0.001047613791295364
0.0011473275653246,87.453839858748,0.0036427650199056046,17.630694115523596,87.55417805991142,0.0011466698880530162
0.0012411074444475,93.3765160756462,0.003940516136120812,18.824705640850272,93.49240636488426,0.001240337907256359
0.0013371025407143,99.2593285654305,0.004245300566767902,20.010680638790788,99.39204846584492,0.0013362094151570816
0.0014320257198791,104.99678315689,0.004546681660616143,21.167351484429023,105.14714125087522,0.0014310013488815906
0.0015243575494647,110.720020655026,0.004839835219550422,22.321156164053242,110.88879755438839,0.001523196895846505
0.0016271009027505,116.339933296315,0.005166045366232838,23.454130552537105,116.52923010680735,0.0016257786082199905
0.0017211986527695,121.934183451144,0.005464805722543162,24.58193138375063,122.14405640342665,0.0017197190878750594
0.0018194389788412,127.458308961235,0.00577671875782081,25.695595086584976,127.69021157673627,0.0018177858046717055
0.0019216636108929,132.971311603416,0.006101281964584957,26.80701641924867,133.226837734217,0.0019198195774063568
0.0020190909686496,138.42244773186,0.0064106138254624795,27.905965462742977,138.70193524593375,0.0020170553440932164
0.0021223469374798,143.818188612775,0.006738451526498365,28.99374682433544,144.12342070493122,0.0021200979407570123
0.0022293968049053,149.153376500287,0.007078334855574328,30.069320702457862,149.48589856129757,0.002226915387207095
0.0023234215573099,154.476619698095,0.007376863444458932,31.14248653113595,154.8355340064019,0.0023207265870041505
0.0024255647674389,159.712247706586,0.007701168136618507,32.19798913764774,160.09964010755158,0.0024226278334088473
0.0025271674191989,164.91776614824,0.008023756555956506,33.247421655485184,165.3345409536969,0.00252397950142161
0.0026266446889404,170.040960174426,0.00833959688738577,34.280257571164285,170.4875973593705,0.00262320108654141
0.0027304123933715,175.122593346696,0.008669059348954513,35.30471481869391,175.6007502459292,0.002726691588801085
0.0028323923729023,180.216168722895,0.008992845783964802,36.331579614535634,180.7266116246594,0.0028283887078105704
0.0029321159101902,185.238562703502,0.009309468014853885,37.344094241026006,185.7817036403857,0.0029278256426633702
0.0030406585403685,190.213848896584,0.009654090865669986,38.34711193755134,190.79222426072775,0.003036045087779004
0.0031500784849279,195.201031549106,0.010001499189646082,39.352527960299774,195.81593011882458,0.0031451273825464773
0.0032579038055189,200.041912287756,0.010343844582522507,40.32844951721161,200.69362959506157,0.00325260833522069
0.003370456372664,204.764342908986,0.0107011989832082,41.280491530451584,205.45449219343794,0.0033647891151764578
0.0034851252344406,209.281029326027,0.011065272619348905,42.19105551212705,210.01039992242085,0.0034790662589353947
0.00359983014646,213.58257881635,0.0114294607150105,43.05824788937616,214.35143982233177,0.0035933662658551133
0.0037227409312489,217.679685850568,0.011819702456715257,43.88422466747451,218.4900509269853,0.003715828680928238
0.0038456314036706,221.520106876401,0.012209879706654153,44.658453546282445,222.37199155594934,0.0038382558662423006
0.0039757985879438,225.069171416961,0.012623160516721566,45.37394495765934,225.96400111087024,0.003967915986919649
0.0041227591146827,228.366898427329,0.013089760189117573,46.03876672294953,229.30840013931208,0.004114283829710484
0.0042808924528425,231.479249975698,0.013591833537774937,46.666216795100716,232.47018774990863,0.004271755499674142
0.0044594068981981,234.274030085225,0.014158616901778966,47.229644465181366,235.3187533110557,0.004449493205123731
0.0046677830393413,236.742417902029,0.014820211149908627,47.72727144904905,237.84748014500474,0.004656922722711373
0.0049020281674969,238.88762779725,0.015563939431802657,48.159745763925606,240.05866167757864,0.004890052348674323
0.0051689459417266,240.648228220645,0.016411403364981952,48.51468280928203,241.89212590328978,0.005155632797560476
0.0054604835948325,242.094392344255,0.017337035413593185,48.80622949660181,243.41634480205173,0.005445629204522645
0.0057754771212231,243.201169738525,0.018337139859883344,49.02935581928664,244.60577253020455,0.005758862992221995
0.0061130167476195,243.993822508382,0.01940882817369191,49.18915461768981,245.48536083169145,0.0060944080590506055
0.0064653542326568,244.599977043862,0.02052749968868534,49.311355372042584,246.18140254075027,0.0064445434810715685
0.0068277545682586,245.092230115075,0.021678120754221052,49.410593591199124,246.7656597088879,0.0068045510109556815
0.0071974862557721,245.522777012771,0.022852018862076415,49.49739184577464,247.2899238257994,0.007171707970235382
0.0075702648360939,245.881877365683,0.02403559085459813,49.5697864769217,247.74326829573718,0.00754175417965444
0.0079459015093166,246.23941860695,0.0252282372920802,49.64186679116112,248.19601277491222,0.00791449907135446
0.0083261315065198,246.550775736669,0.026435467533200366,49.704636388512476,248.60358991848696,0.008291660481604955
0.0087105895095299,246.806524874152,0.027656121692757434,49.75619541462904,248.9563552006043,0.00867287119895104
0.0090972398094622,247.078594929349,0.028883736395042485,49.81104473775676,249.32632815920627,0.009056109185291056
0.0094813761928531,247.314826741212,0.030103369412308588,49.85866907102834,249.6597116516157,0.009436710054618403
0.0098668331210629,247.484534059046,0.0313271951593747,49.89288206630368,249.92642265665063,0.009818473765417187
0.0102511940528263,247.734532194972,0.032547541117723504,49.94328169050635,250.2741069580888,0.010199006913709667
0.0106357436654997,247.864212959699,0.033768486137961545,49.96942533267532,250.5004331925892,0.010579582006890426
0.0110196984701028,248.06333395281,0.03498754264257639,50.0095681248865,250.7969170944584,0.010959423993033998
0.0113973666418723,248.336604933735,0.03618663908794455,50.064659554640976,251.16698827076257,0.011332905984137224
0.0117762504758122,248.539065290191,0.037389595260703734,50.105475562502505,251.4659235760725,0.011707450052094016
0.0121543613956156,248.786410198843,0.03859009743107953,50.15534029608674,251.8102501387176,0.012081090256935666
0.0125323012275723,249.000636144227,0.03979005639754205,50.19852824667616,252.12118712224355,0.01245442193666981
0.0129105135551678,249.167180416676,0.040990880537657766,50.23210357200188,252.3840566769484,0.012827883314331014
0.0132854401105137,249.426599337797,0.042181272350881,50.284402426499874,252.74034148526843,0.013197962584252489
0.0136558484473593,249.611857249278,0.043357318820365774,50.321750421454446,253.020518942538,0.01356344760649722
0.0140281664110083,249.74639710746,0.04453942835495135,50.348873656863944,253.2498811266332,0.013930682308852247
0.0143980816181899,249.935422810851,0.04571390913775293,50.386981238667566,253.53401342775845,0.01429541354977545
0.014768413517686,250.102522974209,0.04688971291865304,50.42066863160054,253.79614045530866,0.014660422438395946
0.0151329812543053,250.302511220926,0.048047215482419324,50.460986262138675,254.09033443113782,0.015019619925996125
0.0154912715501429,250.521104248548,0.0491847871717037,50.50505461650728,254.40199470350393,0.01537250677747638
0.0158525198929214,250.673120080612,0.05033175066002544,50.53570100825138,254.64692070331057,0.015728181034200844
0.0162114687009792,250.888933684954,0.05147141312560896,50.57920903088672,254.95621178080967,0.016081465983696464
0.0165672981480121,251.087722710026,0.052601171619938415,50.61928489834124,255.24756787346837,0.016431557647846262
0.0169205165954591,251.292247978352,0.053722640190582635,50.66051719243576,255.54424263057993,0.016778959238786268
0.0172713561317328,251.529565354157,0.054836555718251634,50.70836037539805,255.8738220550486,0.017123901664774874
0.0176246113043251,251.729807884578,0.055958140891232196,50.748729269530926,256.1664479022561,0.017471098948364693
0.0179825276634271,251.873579515353,0.05709452533138104,50.77771363029517,256.40290312667423,0.017822754585583543
0.0183355669044542,252.111510158102,0.058215424921642084,50.82568044787337,256.73411761998887,0.018169497312573096
0.018690294041451,252.29452760581,0.059341683581606915,50.8625767653313,257.0099865118116,0.01851777677959738
0.0190455258094182,252.468414243984,0.06046954444490278,50.89763231158718,257.2768079435307,0.018866430190019948
0.0194032542108942,252.669383230036,0.06160533211958908,50.93814765917526,257.57199150415823,0.01921741119935854
0.019759144282863,252.834145859378,0.06273528309809003,50.971363805250604,257.8299322270479,0.019566466356363436
0.0201169948235189,253.036591332459,0.06387145856467251,51.01217681262374,258.126927130455,0.019917321525916565
0.0204699657855048,253.272730263936,0.06499214136897774,51.059782421209505,258.4572143868402,0.02026327195323953
0.0208271174594205,253.414799030306,0.06612609793366009,51.0884234845097,258.69269881566566,0.020613198164854407
0.0211815235158364,253.610971114146,0.06725133716278056,51.12797177661183,258.9828378626744,0.020960313307134146
0.0215372273986866,253.802018314353,0.06838069699082995,51.16648689217357,259.26821009703485,0.02130857846726578
0.0218871038904834,253.994026273903,0.0694915548522848,51.20519569681885,259.55321991452206,0.021651019819126312
0.0222366017663816,254.145422960716,0.07060121060826158,51.23571726888034,259.79675352184205,0.021992973565209937
0.0225807747496465,254.345522066685,0.07169395983012763,51.276057248643696,260.088841009054,0.02232960312486428
0.0229275197392556,254.533201387503,0.07279487517213654,51.3138933997206,260.3690163866109,0.02266863376469554
0.0232716469609105,254.715884225059,0.07388747910089083,51.35072225977189,260.6435423580807,0.023004991271334832
0.0236123648819141,254.894607631627,0.07496925850007727,51.38675289853601,260.9132721134573,0.023337905029202206
0.0239539358579979,255.068501711488,0.07605374634914333,51.42180994503599,261.1783962408806,0.023671541091808513
0.0242967222453643,255.258794252694,0.07714209312903166,51.46017292134311,261.4607462773383,0.02400625246046889
0.0246381104716648,255.45804394322,0.07822600074753573,51.50034165895315,261.7520474507685,0.02433948729449923
0.0249836710841722,255.622524992248,0.07932315569224672,51.5335010384372,262.0089140783599,0.024676681813889267
0.025327179362129,255.767113629606,0.08041379447475956,51.56265010772857,262.24497319143705,0.02501176103477529
0.0256693105458703,255.949780051677,0.0815000609831382,51.599475658418086,262.5198344399707,0.025345385386253368
0.0260141907427866,256.151181343475,0.08259505560834744,51.64007815884457,262.8147470339343,0.02568157778624888
0.0263603862107127,256.354418386952,0.08369422621901282,51.68105074680952,263.11201986245464,0.026018938690147184
0.026704153836702,256.517808275139,0.08478568843152885,51.713990148268024,263.36789928917193,0.02635382112807987
0.027049630945977,256.692344294327,0.08588257825347696,51.74917660973632,263.63577747414615,0.026690255918942606
0.0273934205392046,256.866350171468,0.0869741102119746,51.78425619456795,263.9027981240856,0.027024935039094547
0.0277375051228418,257.035479742344,0.0880665787650227,51.81835271605655,264.1650026784494,0.027359789215590957
0.028081970257146,257.238514265618,0.08916025556643854,51.85928447594859,264.4622785722175,0.027694901458327193
0.0284265465077565,257.384640783925,0.09025428516212688,51.88874358203929,264.70119724555144,0.028030009483434818
0.0287671488949402,257.595756854466,0.09133569774143513,51.93130458186035,265.0060523466032,0.02836114251291773
0.0291124588904953,257.756007882752,0.09243205697732257,51.963611189162805,265.25991906601683,0.02869674037538722
0.0294511674625711,257.902269617766,0.09350745669366324,51.993097554941635,265.497792549256,0.029025813104348448
0.0297896600356922,258.129684906311,0.09458217061332273,52.0389444771123,265.8192804647904,0.029354567829536212
0.0301271468406261,258.318875749496,0.09565369121898787,52.0770853510984,266.1012864509065,0.029682238157606716
0.0304655895636561,258.46988446801,0.09672824686460811,52.10752870875081,266.344321882778,0.03001072880992638
0.0308048180251085,258.67100185006,0.09780529722971948,52.1480739729721,266.63931499042366,0.030339873849088806
0.0311404779922336,258.826223220169,0.09887101762534167,52.179366601186075,266.8861955281696,0.030665449867752582
0.0314751426792534,259.006642205792,0.09993357800662954,52.21573906868766,267.1589132240936,0.03098995501219414
0.031814844094218,259.211369525307,0.10101212999914215,52.2570120963019,267.4581388342034,0.031319236325254005
0.0321548670993925,259.341430972984,0.10209170304057118,52.28323248415358,267.6805202192866,0.0316487208195336
0.0324981759062257,259.532702705779,0.1031817085022666,52.32179286548505,267.9670421317296,0.03198127917471123
0.0328396706413546,259.706608260847,0.10426595428630085,52.35685222538676,268.23528773951654,0.032311970580779927
0.0331798982269358,259.86124567738,0.10534617687052117,52.388027128559806,268.4834153620802,0.032641326211078396
0.0335303181928261,260.017430276972,0.10645876026222285,52.41951394383756,268.73589744983985,0.03298043516449079
0.0338803221914761,260.198843181222,0.10757002295793662,52.45608678533436,269.01446382205114,0.03331902682611511
0.0342312762411968,260.341063142039,0.10868430206579982,52.48475832943507,269.252869991381,0.033658422488665865
0.0345766347424316,260.489510122257,0.10978081530722031,52.51468524064701,269.49636076798924,0.03399229447611284
0.0349215229686511,260.664844559443,0.11087583542546724,52.550032663183714,269.76765791584546,0.03432560062391218
0.0352656765753762,260.806433743465,0.11196852312681943,52.57857704268255,270.0039490846393,0.03465808612084836
0.0356112983988518,260.927010823295,0.11306587241635445,52.60288538197628,270.21896046604377,0.03499187883848553
0.0359432871445306,261.079958101333,0.11411993668388465,52.63371955322873,270.4640300030512,0.03531240020040185
0.0362776381459339,261.233587169246,0.11518150111334012,52.66469117331999,270.7105247161362,0.035635098422607966
0.0366127822849706,261.408021162277,0.11624558375478164,52.69985706631505,270.97889612863645,0.03595845766886013
0.0369540897485309,261.542728646027,0.11732923495158559,52.72701409503904,271.20780211348796,0.036287656086568205
0.0372906189777553,261.652957684545,0.11839771525437306,52.749236269204275,271.4101584339621,0.03661213972223696
0.0376295755593287,261.845466785449,0.11947390240086861,52.78804610394652,271.6986005627198,0.03693885742972375
0.0379655694294554,262.017189268411,0.12054068293852088,52.82266535651166,271.96482105929164,0.037262614087059054
0.0383088065644314,262.180699802608,0.12163046084206969,52.85562908020577,272.2245295162734,0.03759324200605798
0.038650623956819,262.295474727097,0.12271573106290032,52.87876770498275,272.43335848634933,0.0379223937366604
0.0389892006213949,262.495656473316,0.1237907119729288,52.9191243450205,272.7301522857989,0.03824831805094036
0.0393250111474854,262.651819826577,0.12485691039326613,52.95060687703793,272.9806055691645,0.03857147470079748
0.0396678902566925,262.812359736159,0.12594555156499868,52.98297172280965,273.23757158027536,0.03890132586294843
0.0400122262709082,262.942639666145,0.1270388184101335,53.00923615669483,273.46356006073665,0.03923246911389911
0.0403554857874186,263.137757031523,0.12812866737505405,53.04857181755504,273.75680904554184,0.039562468005571894
0.040699912017751,263.265403260847,0.1292222206563594,53.07430529738676,273.9802820108812,0.03989347912025954
0.0410420484182997,263.424166952249,0.13030850372810154,53.1063120575734,274.23563436685345,0.04022218114974406
0.0413847429082034,263.501293317915,0.13139655873354578,53.12186073289166,274.406226597856,0.040551311080673495
0.0417305150014576,263.688472263435,0.13249438512962788,53.1595960083085,274.6923280109357,0.04088328704322929
0.0420729641693315,263.857659351049,0.1335816612376275,53.19370412517148,274.95893319872937,0.04121196407480158
0.0424122629294575,264.023522896721,0.13465893480102756,53.22714221597895,275.22135796937835,0.04153751088963285
0.0427554447727678,264.112253885744,0.13574853715353774,53.24503038336599,275.4044907705672,0.04186667563272893
0.0430964342797393,264.264242280494,0.13683117883817225,53.275671243747595,275.6530888304204,0.04219363030619693
0.0434406914852805,264.392299428531,0.1379241954657656,53.30148756479184,275.8776837390897,0.04252360977736377
0.0437844453053097,264.547260136347,0.1390156138443583,53.33272764348756,276.13031517845644,0.042852998128508145
0.0441279064215982,264.653808385034,0.14010610288857428,53.35420777042285,276.33242687556833,0.043181997685508164
0.0444673241521015,264.780154460922,0.14118375418292226,53.37967913932188,276.5542194183793,0.04350701780287948
0.0448068041312124,264.862684179408,0.14226160311659936,53.396317130568654,276.7303345911019,0.04383199189555882
0.0451484041798343,264.983544090254,0.1433461832709739,53.420682488595205,276.9471282398457,0.044158888903021366
0.0454878599401592,265.128024963851,0.14442395531000546,53.449809832712354,277.18813142961767,0.044483628092840136
0.0458240733590343,265.265124856245,0.1454914329149339,53.47744917101899,277.42065339725093,0.044805161591901954
0.0461661124195093,265.389577351041,0.14657740693194202,53.50253879396986,277.6415824139952,0.04513216031861484
0.0465063201686968,265.539442816902,0.14765756653561235,53.532751671887446,277.8887051619622,0.045457302225094705
0.0468497949892148,265.65822695039,0.14874809909075698,53.55669855319862,278.1042604202141,0.04578545931323964
0.047193756015441,265.827238517369,0.14984017534902516,53.590771285101596,278.3726243542161,0.04611397304367711
0.0475382631003182,265.975300796751,0.1509339853435103,53.620620640625006,278.61930462421327,0.04644290016642082
0.0478849630411677,266.13071722974,0.15203475765570743,53.65195259351559,278.8743767884056,0.046773811783403875
0.0482324584562544,266.237527688466,0.15313805559860771,53.67348558199475,279.0788181821958,0.047105372806375376
0.048580020417396,266.363204200108,0.1542415648252323,53.698821966741775,279.3031340985923,0.04743688739609354
0.0489314610767951,266.481407319175,0.15535738891882445,53.72265171554568,279.52073192910274,0.04777198988853598
0.0492806656783219,266.634966910495,0.156466113528672,53.753609329155786,279.7749155729615,0.048104849088326226
0.0496347479864902,266.753315955421,0.1575903248571064,53.777468496612876,279.99354956742894,0.04844224459194889
0.0499826835126656,266.932050368181,0.15869502015271325,53.813501354225295,280.2740305611207,0.04877367214073977
0.0503319873456926,267.020204548274,0.159804059822574,53.83127323693205,280.459862104642,0.04910629262003665
0.0506833093024693,267.17821356504,0.16091950703534003,53.863127854712054,280.7196896020381,0.04944072327421749
0.0510332704677499,267.275951809702,0.16203063373510593,53.88283188483592,280.9159177479318,0.04977374740495282
0.0513826159014734,267.386886682874,0.16313980548717805,53.9051963552674,281.1259243783909,0.050106075027859104
0.0517347315396137,267.471185928274,0.16425777263827349,53.92219108314004,281.3087359268554,0.0504409261875995
0.0520864889085964,267.59864205063,0.16537460228479356,53.94788623740701,281.5369157517556,0.050775324727590984
0.0524397212505555,267.670624006051,0.1664961149705137,53.962397799619886,281.70719691589056,0.05111101296332874
0.0527931152686174,267.772556595131,0.16761814097786024,53.98294740957841,281.90910404123014,0.05144674211903171
0.0531455240179644,267.858971484072,0.16873703875703697,54.00036865118892,282.094476886506,0.05178142305043417
0.0534962908000123,267.997843701831,0.16985072329003906,54.02836529028913,282.3347342822804,0.052114433420609306
0.0538458313637002,268.10568871142,0.17096051457974812,54.05010684422228,282.5420624134238,0.05244616936724773
0.0541941304657798,268.225795354673,0.17206636422885085,54.07432034350208,282.7620591024117,0.052776617661924936
0.0545407378837991,268.336539667497,0.17316684278106215,54.0966463969674,282.97181254214763,0.053105352607548575
0.0548896713596118,268.458211941688,0.17427470656676747,54.121175527444294,283.19379496895624,0.05343618454916297
0.0552421518435297,268.603781490353,0.1753938321032068,54.15052234845517,283.44203237318936,0.0537702684043235
0.0555942329840571,268.770197518767,0.17651168972438128,54.18407181978343,283.7122704987964,0.05410386237335221
0.0559496554268454,268.878698428664,0.17764015598023414,54.20594560321866,283.9223689573665,0.054440509362406846
0.0563084439319026,268.992340481342,0.17877930948379075,54.22885584103855,284.1388806034469,0.05478022969167595
0.0566697934384153,269.155046562895,0.17992659416696857,54.26165738707963,284.4080074545213,0.055122258306684366
0.0570293669507088,269.265056353047,0.18106824006850045,54.283835360774276,284.6210720588082,0.05546248980461981
0.0573895215898218,269.352403594723,0.1822117310476842,54.30144456469616,284.8104091760927,0.0558031551709273
0.0577457304516473,269.421954526022,0.18334269418398016,54.31546603244603,284.9799220898376,0.05613997416616593
0.0581046635842249,269.458993710718,0.18448230687991404,54.322933132080756,285.11581789002304,0.056479254426275396
0.0584659457407751,269.588691391212,0.18562937772696092,54.34908018446835,285.3504491944172,0.056820638888921936
0.0588236946539471,269.677269200295,0.18676523052628202,54.36693747077947,285.54068253884344,0.05715856990199759
0.0591827870321596,269.725126253162,0.18790534882710672,54.37658545263746,285.6882109574252,0.0574976551548125
0.0595416216439788,269.795571421999,0.18904464871963267,54.390787198675,285.8596372568287,0.057836382186776454
0.0599050589284901,269.899416055685,0.19019856209795605,54.4117222768261,286.0677564792659,0.058179337064013986
0.0602729398604684,270.038009475947,0.19136658405698717,54.439662710350916,286.31399418113136,0.05852636541340762
0.0606416301872711,270.197981081384,0.19253717584458574,54.47191298600702,286.5832271274686,0.05887403649429255
0.0610052644848453,270.285647752794,0.19369171473938382,54.48958658696327,286.7744951804109,0.059216821433716656
0.0613693904429626,270.376225656025,0.19484781465640624,54.507847092254636,286.9690498148042,0.0595599521442578
0.0617345299251033,270.48287794763,0.19600713251220298,54.52934819424221,287.181011270516,0.05990391974964704
0.0621066241690826,270.618705108267,0.19718853173683726,54.55673094982664,287.42591931954996,0.06025431718597991
0.0624718882215893,270.727608400823,0.198348245103546,54.57868585360591,287.6404732913374,0.06059816332202546
0.0628366535777481,270.771098668493,0.19950637510935024,54.58745349156818,287.7854483943913,0.06094142205605517
0.0632027037618108,270.851041525172,0.20066858444374927,54.60356997147467,287.96955966626535,0.06128577145524777
0.0635690507517096,270.949608705003,0.20183173613667796,54.62344111492861,288.17361813192724,0.06163028138466997
0.0639402027122783,271.068198244623,0.20301014361148356,54.647348766116,288.4003537892362,0.06197918888176254
0.0643073561738036,271.133930839948,0.20417585585182643,54.660600457333516,288.569837101276,0.06232421778935821
0.0646719087109162,271.199059173396,0.20533331015715892,54.67373032935663,288.73801997074423,0.06266668476091444
0.0650378444933809,271.274199530964,0.20649515626648435,54.68887862544234,288.91728873512517,0.06301033326561349
0.0654058300441485,271.354534233124,0.20766351039017147,54.705074101397805,289.1027027808848,0.0633557876503741
0.0657760800163393,271.451071849099,0.20883905405187728,54.72453608477836,289.3060592715664,0.0637032474088941
0.0661459579492516,271.549589876273,0.2100134164888738,54.74439731905664,289.51149762936546,0.06405023752395135
0.066516965986267,271.660086549757,0.2111913670063977,54.766673448431014,289.7300912866136,0.06439816690050135
0.0668935902027313,271.739081060327,0.21238714889367188,54.78259874176192,289.9166837908433,0.06475123932651344
0.0672732241882821,271.800387649633,0.21359248679779566,54.794958150166025,290.08527606244877,0.06510700719526216
0.0676611789123499,271.874809149595,0.21482424304671094,54.80996152455836,290.2701792532268,0.06547044199473398
0.0680479917155899,271.95933089519,0.2160523736969979,54.82700110847031,290.46561719092324,0.06583267559169481
0.0684346330055323,271.994992992536,0.21727995979256506,54.83419058729526,290.60887051732254,0.0661946174953542
0.0688213265316231,272.013974735548,0.21850771173790332,54.83801730668648,290.7343373119878,0.06655647731713621
0.0692093245620994,272.037368851909,0.21973960548466556,54.84273356054485,290.86489140580034,0.06691942630903885
0.0695969637284961,272.135872933736,0.22097035983797508,54.86259198344117,291.07570341152785,0.06728190810345218
0.0699862249125617,272.231096419661,0.2222062640973834,54.881789038203664,291.2835231618807,0.06764577447745161
0.0703722554167959,272.336810745997,0.22343191094832696,54.903101046393,291.5017663512099,0.06800649022854426
0.0707620195602044,272.433344641129,0.22466941210364896,54.9225622796516,291.71127830347643,0.06837056281592828
0.071151336161045,272.535799633526,0.22590549231131787,54.943217206118845,291.9270859291702,0.06873408508828167
0.071547914065612,272.617806651653,0.22716462715831812,54.95974982097324,292.12304205472105,0.06910425174517797
0.0719403477293289,272.659126854537,0.22841060404061925,54.968079973874666,292.2743192520276,0.06947041532544701
0.072337312295646,272.695398795024,0.22967096653867602,54.97539239707684,292.42145101924535,0.06984067014668803
0.0727286544438133,272.73253425264,0.2309134778591072,54.98287890533223,292.5680044918857,0.07020554671326189
0.0731244038805354,272.754167049829,0.23216998232069988,54.987240077245524,292.69915292127973,0.0705743971708212
0.0735218451078544,272.823805280249,0.2334318582174377,55.001279144498206,292.8823148337989,0.07094468755476074
0.0739224912417236,272.89658237057,0.23470390969247243,55.01595100590691,293.06977759075477,0.07131782517862005
0.0743206935696584,272.941341008168,0.2359682020836654,55.02497434724667,293.22653077572767,0.07168854888002477
0.0747229567778561,273.022464482273,0.23724538776969312,55.04132883962624,293.4235102951656,0.07206291374025522
0.0751233155076318,273.0994793477,0.23851652673673093,55.05685503649633,293.6156176997073,0.07243536710081894
0.0755313899715488,273.152210377397,0.23981216315966744,55.06748561208324,293.78377650100276,0.0728148556981978
0.0759406221482629,273.202415329488,0.2411114753207347,55.077606930424786,293.9495767220174,0.07319527633982734
0.0763502075382269,273.22156779356,0.24241190893387038,55.081468067181696,294.082091198518,0.07357588047497406
0.0767572109537982,273.249666713436,0.24370414477830926,55.087132809428695,294.22354902441424,0.07395394189162555
0.0771721659514013,273.341577991922,0.24502162689569915,55.10566212317148,294.4359396101325,0.0743392423635778
0.0775883691797316,273.422165586377,0.2463430721456478,55.1219085822136,294.6365455118145,0.07472555279271424
0.0780119875764895,273.483585208034,0.24768806055535414,55.13429077793966,294.818583259657,0.0751185926258016
0.0784321102571612,273.557954303508,0.24902195006648678,55.149283587587206,295.0136819371642,0.0755082365645516
0.0788504148522668,273.60012254606,0.2503500671559471,55.15778470528569,295.17360571244785,0.0758960435351077
0.0792713431013243,273.667595229861,0.25168651434670464,55.17138719833997,295.3615930670416,0.07628613112200483
0.0797009565533668,273.714105431141,0.2530505370569396,55.18076365491802,295.529381456152,0.07668411071422256
0.0801273314126824,273.754980774339,0.2544042772352666,55.189004124106745,295.690236844717,0.07707893364272114
0.0805525819022824,273.762761652428,0.25575444753974663,55.19057274912949,295.8150589322302,0.07747256019746444
0.0809755860230255,273.817061564892,0.25709748562310597,55.201519611482226,295.989558588212,0.07786395377948666
0.0814036014708258,273.851802769076,0.2584564346698719,55.20852343824573,296.14432578375704,0.07825982833827398
0.0818409298781048,273.902397690592,0.2598449523629827,55.218723374423355,296.3188246134325,0.07866415471645216
0.0822785459235829,273.93330070388,0.2612343833073757,55.2249534219022,296.4721343658428,0.07906858345186721
0.0827129995997039,273.965576458323,0.26261377372905986,55.23146021399793,296.62609107425294,0.07946992791240426
0.0831542956016044,273.993213759083,0.2640148885350939,55.23703189383114,296.7769264488394,0.07987742841715365
0.0836038051934118,274.079187806224,0.26544208148908244,55.254364261734764,296.9932508311441,0.08029234284446433
0.084057252988733,274.13505460033,0.26688177823922726,55.26562700742653,297.17809423795006,0.08071071803298718
0.084515437057416,274.206498643707,0.2683365126572958,55.280030126571326,297.38118072056363,0.08113328544574122
0.0849699370395335,274.281031940949,0.26977955010051885,55.29505603929532,297.58667395610973,0.08155227881088986
0.0854285280124099,274.336962771086,0.2712355764394014,55.30633169465094,297.77316568001515,0.08197486571102378
0.0858896829658984,274.363314489109,0.2726997434167274,55.31164420100438,297.9282925880516,0.08239963528932945
0.0863538239811818,274.399234762973,0.2741733911402522,55.318885728215356,298.09465798226574,0.08282697321978012
0.0868225210895994,274.417168463155,0.27566150445947807,55.322501162172045,298.24275885939545,0.08325832074180506
0.0872911546150057,274.422363261127,0.2771494159026431,55.3235484334432,298.37700820236927,0.08368942380499916
0.0877644752324117,274.440368751704,0.2786522088629071,55.32717834034353,298.52648369778683,0.0841246500294526
0.0882410347780072,274.48500879132,0.2801652854201728,55.33617777233011,298.7058499981165,0.0845626632155612
0.0887197941218665,274.490393227246,0.2816853463369261,55.33726327461279,298.8431244027974,0.08500250516882199
0.0892003537561283,274.559095993806,0.28321112317570735,55.351113752351296,299.0498644834163,0.08544380660269599
0.0896805339250261,274.570242281144,0.28473569521195785,55.353360843878626,299.1938482088408,0.08588456514015097
0.0901632297297298,274.592602300021,0.28626825439189213,55.35786862368423,299.35075818328215,0.08632743707495781
0.090646968930607,274.610658491,0.2878041263546772,55.3615087517856,299.5032823192472,0.086771069637854
0.0911331841981314,274.588641618328,0.2893478598290672,55.35707015025492,299.6127788736457,0.08721677474235409
0.0916224128852304,274.56124822043,0.2909011609106065,55.35154764123869,299.7172122671665,0.08766504178236992
0.0921145694675675,274.59182762976,0.2924637580595268,55.357712450159624,299.8857356111879,0.08811578891414194
0.0926149396545437,274.562966734266,0.29405243340317627,55.351894093628026,299.99159932973254,0.08857385037542204
0.0931163573118161,274.591867621012,0.2956444344650161,55.35772051239602,300.16086208132907,0.08903266035518882
0.0936210902780255,274.548666219004,0.29724696163273095,55.34901110975121,300.2522116848049,0.0894942914263803
0.094133528720738,274.535402599675,0.29887395368834313,55.346337164094486,300.3783888051509,0.08996275205503947
0.0946442071602141,274.53737278637,0.30049535773367975,55.34673435373219,300.5207447695841,0.09042938550106815
0.0951577370435387,274.528081464645,0.3021258151132354,55.34486122327244,300.6515524517249,0.09089840498851345
0.0956736209664979,274.47538329719,0.3037637465686308,55.3342372727135,300.7354370833996,0.09136935308829106
0.0961894132529193,274.445166888986,0.3054013870780187,55.32814564481958,300.8438864621371,0.09183999590482632
0.0967062536742134,274.394217799439,0.3070423554156275,55.3178743083669,300.9298546326889,0.0923113730329396
0.0972196499166519,274.372513524532,0.30867238848536976,55.31349872654565,301.04691323613883,0.09277938906845791
0.0977290566707059,274.314718270333,0.31028975492949123,55.30184720329913,301.1232369177831,0.09324355186339787
0.0982402557524951,274.263771822898,0.3119128120141719,55.291576399496236,301.2075149104234,0.09370913131219194
0.0987433603538227,274.184006831924,0.31351016912338703,55.27549577731588,301.25785702178365,0.09416712709006983
0.0992395641649809,274.109396319361,0.31508561622381437,55.26045429798318,301.3118933436204,0.09461863543806714
0.0997266954809935,274.024936749375,0.31663225815215434,55.243427248673996,301.3525381707784,0.09506169027971771
0.10021252355094,273.925381998239,0.31817476227423447,55.223357010844985,301.37613579293776,0.09550336437111194
0.100691410162559,273.814243072753,0.3196952272661248,55.20095140346701,301.3849853303422,0.0959385370397967
0.10117034236595,273.679293061914,0.3212158370118912,55.173745481281856,301.367520839459,0.09637356181861777
0.10163806533851,273.516169714327,0.32270085744976923,55.14085981440833,301.31582404289077,0.09679822242727816
0.102105676553166,273.323335133409,0.32418552305630205,55.10198436289526,301.23119918497343,0.09722260137187592
0.10257701489384,273.144665382032,0.32568202228794196,55.06596454101765,301.16302979109764,0.09765018067812582
0.103047092917518,272.918004752489,0.32717452001311964,55.02026975810179,301.0414117470824,0.0980764346614139
0.103517081298569,272.658200817856,0.3286667331229566,54.96789328487978,300.8829819586396,0.0985024257960931
0.103979053880908,272.388097697525,0.33013349607188286,54.91344049582104,300.71075438453397,0.09892097474095504
0.104437631827392,272.120170832964,0.3315894810519696,54.859426439925535,300.5397570472241,0.09933627494769846
0.104896961662044,271.803179470515,0.33304785327698966,54.79552098125583,300.3145071670553,0.09975208325724437
0.10535500492148,271.472149802842,0.334502140625699,54.728785400252946,300.0730994813652,0.10016655479525734
0.105805505987288,271.106099992785,0.3359324815096394,54.65498975854546,299.7906180787619,0.10057403409838243
0.106254273590868,270.701361491774,0.3373573186510059,54.57339447674163,299.4645380171414,0.1009797804655284
0.106696919068198,270.272644608152,0.33876271804152863,54.486965153003446,299.10990309625583,0.1013798303940597
0.107146822492677,269.767792651012,0.34019116141424943,54.38518699844401,298.6725544444313,0.10178627590981733
0.107585387485185,269.209916311615,0.34158360526546233,54.272719128421585,298.1729694728544,0.10218231927457685
0.10802435642856,268.629326410662,0.34297733166067795,54.15567220438946,297.64783651401126,0.10257857041972945
0.108460535267018,267.994172370447,0.3443621994727821,54.02762514988211,297.0609637541872,0.10297214751625991
0.108893701062922,267.288403222024,0.34573750087477734,53.885342089560034,296.39442670006883,0.1033628526136387
0.109327374328497,266.524917582471,0.34711441349297795,53.73142338462616,295.6633870148816,0.10375386257735367
0.109753475394646,265.744441632931,0.348467284378001,53.5740794331989,294.91081766895485,0.1041378964186074
0.110179304283434,264.916191896125,0.34981929109990295,53.4071042862588,294.10447361265676,0.10452153766928754
0.110612683779019,264.043244602966,0.3511952709983853,53.23111811195795,293.24977652222003,0.10491183041477271
0.111048574546273,263.108851016892,0.35257922418441673,53.04274436500543,292.32671387282556,0.10530423116552971
0.111481676456656,262.132880599163,0.3539543227498828,52.84598872879126,291.35589358277014,0.10569396886711525
0.111917722445275,261.101126340253,0.3553387687637481,52.63798707019502,290.32296972815016,0.10608620248418356
0.112347318190534,260.075075931369,0.35670273525494545,52.43113530776399,289.29381324045784,0.10647248356377838
0.112790392807313,258.927517465695,0.35810949716321877,52.19978752108412,288.1320538692732,0.10687072823910337
0.11323943043347,257.820419719297,0.35953519162626724,51.97659661541027,287.0158572024284,0.10727417084131788
0.113688761601596,256.63348564491,0.3609618180850673,51.73731070601386,285.8098288133808,0.10767771431957708
0.114140295285182,255.399215982946,0.36239543753045284,51.48848194216192,284.55055791084345,0.10808307189256768
0.114608748461103,254.170992707494,0.363882776364002,51.2408721298308,283.301212076816,0.10850344509172517
0.115076477973333,252.885011073605,0.3653678175653322,50.98161823243877,281.9861274802028,0.10892299267050064
0.115539003713842,251.515859032607,0.36683633679144834,50.70559718097358,280.57575080346555,0.10933769950898081
0.116005599545723,250.145928115856,0.3683177785576705,50.42941910815657,279.1642564808572,0.10975588146062021
0.116480573796504,248.686318489326,0.3698258218039002,50.13516180744812,277.6534435623028,0.11018139294966699
0.116957732372306,247.160538364824,0.3713408002820715,49.827564534348525,276.06787446389217,0.11060867905982627
0.117448584166296,245.605459473451,0.3728992547279898,49.51406062984772,274.4514729521204,0.11104803675251868
0.117930167190356,243.921015197932,0.3744282808293803,49.1744766639031,272.6866613014655,0.11147891051940798
0.118430402112077,242.127817573601,0.37601652670584446,48.81296802283796,270.8031123713622,0.1119262757045488
0.118949817696737,240.272722121039,0.37766567118713995,48.438980779601465,268.85311861483535,0.11239058265550207
0.119470175276523,238.307687449283,0.3793178065029605,48.04282978977545,266.7783486385917,0.11285551559104862
0.120020333889548,236.100893871343,0.3810645600993149,47.59794020446275,264.43780198540236,0.11334684040072349
0.120289721616079,235.070586210248,0.3819198661310508,47.39023017998599,263.34716158560724,0.11358733186945326
0.120552527392995,233.965809523493,0.3827542744727591,47.16750719993619,262.17097918509813,0.11382189169019674
0.120831182921986,232.805461081558,0.38363900577730553,46.93358095404209,260.93562033474103,0.11407053767539252