File: example/data/02 processed data/test_ID_099.csv
Strain,Stress_MPa,Displacement(mm),Force(kN),True Stress (MPa),True Strain
0.0008695210452605134,50.5803295346691,0.0027607293187021298,20.39398886837858,50.624310195675704,0.0008691432308322951
0.0009639134873806134,56.4983715149838,0.0030604253224334474,22.78014339484147,56.552831057302136,0.0009634492210928358
0.0010604507886851134,62.3626143631202,0.003366931254075235,25.144606111210067,62.42874684670604,0.0010598889079436627
0.0011648693826123134,68.259625617547,0.0036984602897940947,27.52228104899495,68.33913916549746,0.0011641914486915854
0.0012593822601059134,74.1916230042351,0.003998538675836275,29.914062395307592,74.28505861809509,0.0012585899034508838
0.0013608559181618133,80.0146757958728,0.0043207175401637566,32.261917280895915,80.12356424096942,0.001359930792959668
0.0014397120381173135,85.7808375859124,0.00457108572102247,34.58683371463988,85.90433729042462,0.0014386766463991172
0.0015372320368017133,91.4460034724481,0.004880711716845439,36.87102860009107,91.58657719862342,0.0015360517051084864
0.0016344499481436134,97.098879039025,0.005189378585355973,39.15026802853488,97.25758229683512,0.0016331156884829595
0.0017329949693918134,102.741356779209,0.005502259027819007,41.42531505337707,102.91940703365586,0.0017314950662429126
0.0018415492888322134,108.314507351908,0.005846918992042277,43.67240936428931,108.51397385589212,0.0018398557158205966
0.0019385447071346134,113.82491847713,0.006154879445152397,45.89420712997882,114.04557317038386,0.0019366681541402675
0.0020271103695208136,119.204163583996,0.006436075423228583,48.06311875706719,119.44580358008719,0.0020250585536659795
0.002118608522148913,124.545226660454,0.006726582057822799,50.21663538949506,124.80908923904981,0.002116367435878667
0.0022048088824856136,129.807587127016,0.007000268201891823,52.33841912961286,130.09378804812766,0.0022023818581432537
0.0022914978381527134,135.010452691701,0.007275505636134865,54.43621452529385,135.31982885217207,0.002288876360957362
0.0023885266715039134,140.136458255125,0.007583572182024925,56.503019968466404,140.47117792331747,0.0023856786757814226
0.0024756910839670134,145.175461249396,0.007860319191595267,58.53474597575647,145.5348708444219,0.0024726316092977176
0.0025940079233786133,150.104854639391,0.008235975156727096,60.52227739060245,150.49422782166317,0.0025906492917828323
0.0027019121907404134,154.97019836315,0.008578571205600813,62.483983980022074,155.38891423130883,0.0026982685876518826
0.0028058874380154134,159.800081919218,0.008908692615698937,64.4313930298287,160.248462961669,0.00280195828398468
0.0029067298455045134,164.541578984955,0.009228867259476829,66.34316464673385,165.01985690341704,0.0029025134748979597
0.0030077849007612133,169.182325120137,0.009549717059916852,68.21431348843925,169.69118916310902,0.00300327056559081
0.0031118088422976134,173.616522401844,0.009879993074294921,70.0021818324235,174.15678383142304,0.0031069771860276854
0.0032226691250314132,177.92204456903,0.010231974471974737,71.7381683702329,178.49542844872508,0.0032174874564377424
0.0033395225816952134,182.101757755364,0.010602984196882301,73.42342872696277,182.70989068755443,0.0033339587597233846
0.0034639301267329133,186.171413112301,0.010997978152376998,75.06431376687976,186.81629787891714,0.0034579445392268014
0.0036060991100610135,190.062256811589,0.011449364674443716,76.63310194643269,190.7476401467335,0.0035996127236896233
0.0037557148900078134,193.67987462697,0.011924394775774807,78.0917254495943,194.40728101600135,0.003748679801861921
0.003936031673358714,196.913539734172,0.012496900562913915,79.39553922081815,197.68859766347887,0.003928305766997696
0.004151463435798413,199.726480123555,0.013180896408659961,80.52971678581739,200.55563730294867,0.004142869887127774
0.0044030122280424135,202.0054358641,0.013979563824034662,81.44859174040513,202.8948682683407,0.004393347329096197
0.004691847226049614,203.701660199836,0.014896614942707522,82.13250939257388,204.65739726918628,0.004680874818042528
0.004997801511026513,204.880844917701,0.015868019797509177,82.60795667081706,205.9047987140111,0.0049853539574290446
0.005329352263059014,205.618552014291,0.016920693435212367,82.90540017216213,206.7143657097953,0.0053152015192212765
0.005674003154319813,206.10063881545,0.018014960014965407,83.09977757038943,207.2700544901962,0.005657966630683378
0.0060441778121058136,206.395592464324,0.019190264553435955,83.21870288161544,207.64308412481333,0.0060259850394906445
0.006408219748751313,206.605995700272,0.020346097702285418,83.30353746634967,207.92997232212892,0.0063877744075846
0.006790957518043214,206.7247846786,0.0215612901197872,83.35143318241153,208.128643909279,0.006768002830310795
0.007159697789257413,206.823063813951,0.022732040480892286,83.39105932978504,208.3038544467072,0.007134188838257866
0.0075348989799017135,206.880599591162,0.02392330426118794,83.41425775515653,208.4394240099829,0.0075066534247849774
0.007912235551628613,206.928318997157,0.025121347876420844,83.4334982196537,208.56558459936502,0.007881097953416401
0.008294631469104214,206.989372803183,0.02633545491440588,83.45811511424337,208.7062733686064,0.008260420063975146
0.008669977406400414,207.028414802262,0.027527178265321313,83.47385684827205,208.82334648108053,0.00863260898586062
0.009045512331622313,207.085959161481,0.028719501652900842,83.49705873390913,208.95915775878197,0.009004846728463918
0.009419282856787713,207.086665312919,0.029906223070300986,83.49734345416893,209.0372731893703,0.009375198027459664
0.009781285044824213,207.158272819681,0.031055580017316873,83.52621560089538,209.18454693552377,0.009733757942378093
0.010174342247163914,207.211050885713,0.032303536634745424,83.54749571711949,209.31928703481873,0.010122932043026516
0.010540879693124413,207.305697195833,0.03346729302567001,83.58565710935987,209.49088160967355,0.01048571195976166
0.010920309612637014,207.34999659112,0.03467198302012252,83.60351862553958,209.61432275207423,0.010861113600887254
0.011283605975964213,207.389421453844,0.03582544897368637,83.61941473018989,209.72952196911234,0.011220420953064048
0.011686829531697314,207.451132619215,0.03710568376313897,83.64429667206748,209.87557864229333,0.011619065989091926
0.012065098599687614,207.520268507555,0.03830668805400817,83.67217226224616,210.02402100853226,0.011992895475934795
0.012437803818924214,207.670576711742,0.03949002712508438,83.73277653017438,210.2535426038455,0.012361089784771682
0.012819285492617613,207.729262687006,0.04070123143906092,83.75643871540082,210.3922034105617,0.01273781398459654
0.013172811138481214,207.81572172896,0.041823675364677855,83.79129900111668,210.55323898290277,0.01308680414111247
0.013556710976744714,207.874550351989,0.04304255735116447,83.81501870192197,210.6926455505317,0.013465640920925273
0.013935820458835714,207.966434798233,0.04424622995680339,83.85206651064755,210.86461769504535,0.013839609732776762
0.014307538629957713,208.039041241132,0.04542643515011573,83.88134142842442,211.01556786022888,0.014206151719583329
0.014677686629793013,208.083848790959,0.046601655049592815,83.89940783251467,211.13803831623395,0.014571011945605072
0.015043453156951013,208.137531117824,0.04776296377331946,83.92105254670665,211.26863831739843,0.01493142256945623
0.015416752499010313,208.182572985409,0.04894818918435774,83.93921342771692,211.3920721877322,0.015299121818351035
0.015775844961733315,208.247941532768,0.05008830775350327,83.96557002601206,211.53322877198906,0.01565269977734223
0.016142619010571416,208.348208061984,0.05125281535856424,84.00599749059195,211.71149380626386,0.016013712346817536
0.016515315011663513,208.459928567119,0.05243612516203165,84.05104319826238,211.90270995471383,0.016380420388569704
0.016879569279374014,208.601509913379,0.05359263246201249,84.10812879707443,212.1226135517439,0.016738692433434954
0.01725616851349021,208.658926763882,0.05478833503033142,84.13127927119722,212.25958036596356,0.017108971792301877
0.01762991437542221,208.748164399806,0.05597497814196552,84.16725988600177,212.42837666420112,0.017476310160063516
0.01799240620087751,208.753380525233,0.0571258896877861,84.16936302777394,212.50935614344937,0.017832458572883448
0.018359607495154716,208.813032603218,0.05829175379711622,84.1934147456175,212.646757921686,0.01819310476350996
0.018721458337787912,208.87951788844,0.059440630222476615,84.22022161261901,212.79004708020565,0.018548368824924406
0.01907727201533621,208.977065254898,0.06057033864869247,84.25955271077488,212.9637775737324,0.018897582587662044
0.019438244741356414,209.066804697246,0.06171642705380661,84.29573565392958,213.13069641424443,0.01925173513330201
0.019799847144457317,209.156001062388,0.06286451468365198,84.33169962835484,213.29725791276923,0.019606379751142194
0.020164016439156413,209.229665599425,0.0640207521943216,84.36140116968816,213.448576016131,0.019963414799721663
0.020537189419617415,209.352030639587,0.06520557640728529,84.41073875388149,213.65153294821374,0.020329144955169454
0.020903888675683616,209.438389268828,0.06636984654529547,84.44555855319145,213.81646604251804,0.02068840025177823
0.021277406198757516,209.510144389349,0.0675557646810551,84.47449021778552,213.9679768342815,0.021054202767134194
0.02164220700231021,209.575126714188,0.06871400723233492,84.5006910911606,214.11079498907182,0.021411339489570795
0.022017230650971116,209.615231403762,0.06990470731683329,84.51686130199685,214.23037830153532,0.02177835137615132
0.022371209787758112,209.693617298976,0.071028591076132,84.54846649494712,214.38471720272526,0.02212464480388022
0.022744716503764216,209.739970992438,0.07221447489945138,84.56715630415101,214.51044717216874,0.022489911843618222
0.023107980382027916,209.793902117191,0.07336783771293863,84.5889013336514,214.64181549158417,0.022845034069802362
0.02347371411175711,209.897496697841,0.07452904230482882,84.6306706685695,214.82457052809963,0.023202443436461325
0.023849208673015314,209.970076044736,0.07572123753682362,84.65993466123756,214.9776962034158,0.023569258618658155
0.02422956524191861,210.077429384358,0.07692886964309159,84.70321952777314,215.16751416548087,0.023940686298218612
0.024598106558425314,210.117220702055,0.07809898832300037,84.71926338706857,215.2857064866443,0.024300444540021067
0.024953225662424514,210.137780896029,0.07922649147819782,84.72755325727888,215.38139636292874,0.02464697804905803
0.02530835208108871,210.126499219197,0.08035401785745666,84.72300448518023,215.44445464300304,0.0249933986483324
0.025645418410373516,210.152845229673,0.08142420345293591,84.73362719660416,215.54230287571846,0.02532209092523233
0.02600275372424271,210.171096236608,0.0825587430744706,84.74098600260035,215.63612349200264,0.025670430686733
0.026347033366711917,210.230185646623,0.08365183093931033,84.7648108527184,215.76912736254462,0.026005928707454513
0.026715591562724315,210.296795724532,0.08482200321164969,84.79166803613131,215.91499902605827,0.026364961301488684
0.027073272106430214,210.38767453296,0.08595763893791593,84.82831037168948,216.0835572934299,0.026713274172056083
0.027449095029493213,210.500371008519,0.08715087671864094,84.87374959063487,216.27841569607543,0.027079123610608373
0.02781248769815961,210.549418857988,0.08830464844165675,84.89352568354076,216.40532197983043,0.027432745432285098
0.02817436671248491,210.613235652872,0.08945361431213959,84.919256615238,216.54713018865903,0.027784770074160702
0.028541129529980516,210.64849419158,0.09061808625768814,84.93347285804506,216.6606401495972,0.028141419131410654
0.02892099796999191,210.742783464436,0.0918241685547243,84.9714902928606,216.83767507720137,0.028510678365153416
0.02928359262907431,210.794174780764,0.09297540659731093,84.99221127160405,216.96698552362577,0.02886301910376582
0.029639045316731616,210.838728261357,0.09410396888062288,85.01017523497914,217.08778688281743,0.029208299382527024
0.030004786874199114,210.856639909323,0.09526519832558218,85.01739721143905,217.183348450812,0.02956344968142373
0.030364768438193315,210.889613319545,0.09640813979126377,85.03069209044054,217.2932275940131,0.029912883662069654
0.030742687476180912,210.904536725039,0.09760803273687439,85.03670920753574,217.3883089848856,0.030279598207823506
0.031109581103181412,210.945863032975,0.09877292000260098,85.05337197489553,217.50830046737994,0.030635485616891583
0.031487472351929315,210.99942995272,0.09997272471737557,85.07497015693671,217.64326866962912,0.031001908377307263
0.031848286385093315,211.057500819762,0.10111830927267126,85.09838433052805,217.77932054959183,0.03135164693567216
0.03220101844364071,211.102203183737,0.10223823355855925,85.11640832368276,217.89990912194972,0.03169343340478029
0.03254733359809931,211.126593042715,0.1033377841739653,85.12624231482269,217.99820069790638,0.03202888848080794
0.03290577336587791,211.09265542617,0.10447583043666236,85.11255866783175,218.03882250482494,0.0323759694870709
0.03327018996842391,211.119364034537,0.10563285314974591,85.12332757872531,218.14334538197892,0.03272871447374342
0.03363369477580741,211.125251228021,0.10678698091318851,85.12570129513806,218.2261734872899,0.03308045294964846
0.03396978141456391,211.171996254639,0.1078540559912404,85.14454888987044,218.3454628082862,0.03340555072162145
0.034327920114585714,211.207216383234,0.10899114636380963,85.15874964571995,218.45752083486167,0.03375186325036077
0.03468606172434181,211.202609805401,0.11012824597478525,85.1568922735377,218.52839656545325,0.03409805870044167
0.03504899569091611,211.248024813569,0.11128056131865864,85.17520360483103,218.65205592497432,0.03444876442868828
0.03543197727958111,211.285626819135,0.11249652786267002,85.19036473347523,218.77189434809262,0.03481870899522377
0.03578935684077651,211.298712228424,0.11363120796946542,85.19564077050056,218.8609572403636,0.0351637996514997
0.036142174228208014,211.319769102117,0.11475140317456044,85.20413090197357,218.95732501487038,0.03550436823260486
0.03650127053470561,211.38248844455,0.1158915339476903,85.22941934084257,219.0982178415638,0.03585087868619789
0.03686840169027581,211.420619947179,0.11705717536662569,85.24479396270257,219.21536028899874,0.036205018292198
0.03723954954541681,211.477122331651,0.11823556980669837,85.26757572412168,219.35243510644267,0.03656290502502815
0.03761032170981801,211.49100694449,0.11941277142867218,85.27317400001837,219.44525175440563,0.0369203016477762
0.03798563318991011,211.508032813476,0.1206043853779646,85.28003883039354,219.5422993646482,0.03728194379040674
0.03836197047699131,211.555851394703,0.1217992562644474,85.29931928234426,219.67155072014137,0.03764444310462323
0.03872574419872681,211.586290412486,0.12295423783095762,85.31159229431437,219.78012697095744,0.037994715962995584
0.03909844796966311,211.62078002574,0.12413757230368036,85.32549850637837,219.89482408287594,0.03835346024592231
0.03944521946575571,211.590148314548,0.12523857180377437,85.31314780042577,219.93636815160716,0.03868712800065144
0.03981545263939091,211.570099312565,0.12641406213006612,85.3050640428262,219.99385858165567,0.03904324802207542
0.04018503667125411,211.552853959518,0.1275874914312318,85.29811071647767,220.0541131537897,0.039398617203623185
0.04056319655227631,211.574336108692,0.12878814905347727,85.30677231902462,220.15646748968624,0.0397621017224589
0.04093496451469581,211.576839756969,0.12996851233415918,85.30778179000991,220.23773018455205,0.040119313631963666
0.041305814258355715,211.602434825638,0.1311459602702794,85.31810172169725,220.34284569516163,0.04047551619159225
0.04167044645427921,211.631217033662,0.1323036674923365,85.32970670797253,220.44998433111715,0.04082562310977982
0.04204019483646081,211.625381332227,0.13347761860576307,85.32735375315393,220.52215359577414,0.04118051728628928
0.042408578247341414,211.640260268775,0.13464723593530897,85.33335294037008,220.615622806671,0.0415339761186412
0.042777524570499714,211.64627241566,0.13581864051133657,85.33577703799412,220.6999760341756,0.041887849882244366
0.043153277788258414,211.676902391165,0.13701165697772047,85.34812704411772,220.811454561409,0.04224812379104138
0.043533193140789614,211.688430005215,0.138217888222007,85.35277497810269,220.90390331430254,0.04261225645976944
0.04388906597198671,211.692164528853,0.1393477844610578,85.35428073803352,220.98313590361246,0.04295322516707453
0.044234826825917214,211.668308329372,0.14044557517228715,85.34466191840278,221.0314192928566,0.043284394077389834
0.04458388792080891,211.644131574198,0.14155384414856828,85.33491385071665,221.08004981539898,0.043618612739523284
0.044958528715984714,211.629619558688,0.14274332867325146,85.329062606063,221.14417588677017,0.043977199190037265
0.04532839594666281,211.61477695907,0.1439176571306544,85.32307806989704,221.2069353572355,0.044331090543587276
0.04573091169617681,211.642990617073,0.14519564463536136,85.33445381680383,221.32161753209715,0.04471607795452716
0.046126766257224915,211.660581709346,0.1464524828666891,85.34154654520832,221.42379988772123,0.045094549750142404
0.04649948073111561,211.708439954238,0.14763585132129206,85.36084298954877,221.55277247850464,0.045450766708013714
0.04688409558147731,211.730033990944,0.14885700347119046,85.36954970514863,221.65680514204487,0.045818224310186055
0.04725954654900831,211.697700245701,0.1500490602931014,85.35651273906664,221.70243756478067,0.046176796629677656
0.04762195262574641,211.641667300304,0.15119969958674484,85.33392025548257,221.72045675411306,0.046522788591987975
0.04799765955126301,211.62050046762,0.15239256907526005,85.32538578854438,221.7777892031327,0.04688135264374507
0.04837440687825011,211.567874306351,0.1535887418384441,85.30416692032074,221.8023447404129,0.047240780568850685
0.04875389717016361,211.594049078438,0.15479362351526946,85.3147205884262,221.9100835890267,0.0476026948068332
0.04914167071695401,211.61290625802,0.15602480452632897,85.32232380323367,222.0119180168093,0.04797237340966017
0.04951902498875491,211.614632366693,0.15722290433929684,85.32301977025061,222.09358263484546,0.04833198778337928
0.049902252062147615,211.625363814644,0.15843965029731866,85.32734669006446,222.1859460624661,0.04869706656183918
0.05028621023947151,211.622093442664,0.15965871751032204,85.32602807608212,222.26376652483887,0.04906270820638062
0.05065580173818661,211.605968009572,0.16083217051874246,85.31952630145943,222.32503797168192,0.04941454228882618
0.05102435128283951,211.596753568212,0.16200231532301543,85.31581103870307,222.39334065258484,0.0497652612580288
0.05137094007331711,211.582767883741,0.16310273473278183,85.31017201072439,222.45197357324324,0.050094969752946354
0.05174947511511241,211.552900501646,0.16430458349048188,85.29812948226366,222.5006520616858,0.05045494442976389
0.05213525475524421,211.548894680473,0.16552943384790036,85.29651433516672,222.5780501978298,0.0508216752101896
0.05255492600597801,211.538846112895,0.16686189006898017,85.29246275271926,222.65625451774818,0.05122047144170338
0.052937024923248914,211.509465494603,0.1680750541313153,85.28061648742394,222.70614734099385,0.05158342597239798
0.053324432781638814,211.496630184968,0.16930507408170323,85.27544129057911,222.77456802480947,0.05195128900416138
0.05370990279626721,211.492790154054,0.1705289413781484,85.27389299011459,222.8520473553396,0.05231717769654765
0.05409689872879751,211.517799283688,0.1717576534639321,85.283976671183,222.96025625087577,0.05268438017127037
0.05447493182768021,211.515602787741,0.17295790855288468,85.28309104401717,223.0379008300939,0.053042948086723656
0.054857950940146914,211.459376313233,0.17417399423496643,85.26042052949555,223.05960440485842,0.05340611420413025
0.05523984817939481,211.361358559501,0.17538651796957852,85.22089977119082,223.03692791731848,0.053768085335114686
0.055616600442544115,211.307914214622,0.17658270640507756,85.19935101133558,223.060142049844,0.054125051596269826
0.055997618361583915,211.241675059473,0.17779243829802893,85.17264338397952,223.07070576151511,0.054485929942117366
0.05637997987843771,211.26481286128,0.1790064361140397,85.1819725456681,223.17591875942088,0.05484794999132469
0.05677123452618551,211.307896214904,0.18024866962063898,85.1993437538493,223.30410634815516,0.0552182544442684
0.05717239672285721,211.346962127894,0.18152235959507163,85.21509512996685,223.43017449284062,0.055597793610362746
0.05756717098250571,211.336685606744,0.18277576786945562,85.21095163663918,223.50274072194347,0.055971148580651144
0.05795987011056461,211.324077125698,0.18402258760104262,85.20586789708145,223.5723931871384,0.05634240276454142
0.05835760827380961,211.283395721945,0.1852854062693455,85.18946515508821,223.61338936424656,0.056718280365128486
0.05873788324034531,211.279641125408,0.18649277928809635,85.18795130176451,223.6897600168943,0.057077522517548857
0.05913122842604891,211.251194756765,0.18774165025270528,85.17648172592764,223.74273740920302,0.05744897624720537
0.059523931868709114,211.210696966207,0.18898848368315144,85.16015301677466,223.78278810236606,0.05781968636041015
0.05992629260399881,211.161622036805,0.1902659790176962,85.14036600523978,223.81575518571756,0.05819937042703969
0.060324847405614314,211.107852845229,0.19153139051282544,85.11868626719634,223.84290185424433,0.058575320991375315
0.060719100566490714,211.091007262705,0.19278314429860802,85.11189412832266,223.908263361371,0.05894707487775161
0.061116074439251114,211.079446333105,0.19404353634462226,85.10723276150794,223.97979348779498,0.059321254627496905
0.06150886505334941,211.052589468132,0.19529064654438438,85.09640407355083,224.0341947128873,0.05969135356610236
0.06190186585208881,211.012996758038,0.19653842408038197,85.08044029284092,224.07509497640135,0.060061513514440924
0.06229993933018471,210.990490312412,0.19780230737333646,85.07136569396451,224.13518505812118,0.06043631169207591
0.06270258939024982,210.952135806134,0.19908072131404317,85.05590115703325,224.17938095858224,0.06081527600806327
0.06309256722440591,210.919999061376,0.20031890093748878,85.0429436215468,224.22748328112746,0.061182176682681305
0.06349126672780941,210.891022874248,0.20158477186079488,85.03126042289679,224.2807610580574,0.061557143802913765
0.06389499808416611,210.839848518807,0.2028666189172274,85.01062692278298,224.31146023598205,0.06193670003854577
0.06429620235430022,210.881055594682,0.2041404424749032,85.02724161577578,224.4399066178861,0.06231373784868633
0.06470477312637862,210.873917452938,0.2054376546762521,85.0243635170246,224.51846644000105,0.06269755240001773
0.06511284838108912,210.880305472505,0.20673329360995793,85.02693916651403,224.611322829294,0.06308075446913709
0.06550925350623332,210.803604399111,0.2079918798822908,84.99601329372156,224.61319115972012,0.06345285717976502
0.06590591596878431,210.715245969055,0.20925128320089018,84.96038717472297,224.60262726323325,0.06382506290750033
0.06630756043424282,210.627476194064,0.21052650437872095,84.92499840144662,224.59367030091397,0.06420180236126904
0.06670684349983162,210.583639230818,0.21179422811196538,84.90732333786582,224.63100909661318,0.06457618620932566
0.06711529231660622,210.568937077214,0.21309105310522475,84.9013954295327,224.7013328419483,0.06495901926265968
0.06752118182043072,210.560506395004,0.21437975227986752,84.89799617846562,224.77780063150303,0.06533930837851964
0.06792425159077502,210.536705962507,0.21565949880071067,84.88839984408281,224.83725414739735,0.06571681254587007
0.06832479617462602,210.50159725538,0.21693122785443758,84.87424401336922,224.88407598228707,0.06609181057240064
0.06872246284468352,210.454841862854,0.21819381953187014,84.85539223910273,224.91781691325772,0.0664639751775295
0.06911126783442292,210.356446661464,0.21942827537429277,84.81571929390228,224.89444738738194,0.06682771253319636
0.06952933105884822,210.34399948682,0.22075562611184307,84.81070059308583,224.96907706338132,0.06721867418422528
0.06995219385107553,210.358435148169,0.22209821547716477,84.81652105174174,225.0734691818626,0.06761396883183973
0.07037426179682901,210.380509921987,0.22343828120493212,84.82542160054516,225.1858830041873,0.06800836469618168
0.07076973559408152,210.264767845926,0.22469391051120882,84.77875439547738,225.14514987113313,0.06837776890461562
0.07117396875670552,210.166712951705,0.22597735080254003,84.73921866212746,225.12511201302914,0.06875521408826069
0.07157592452126782,210.114734282079,0.2272535603550253,84.71826086253427,225.1538906438593,0.06913039158381265
0.07200471150996922,210.099258076316,0.22861495904415224,84.71202085637061,225.2273945425597,0.06953045770422167
0.07242294504815092,210.115248350811,0.22994285052787913,84.71846813504699,225.33241343590035,0.0699205231300294
0.07284180296505162,210.072965502504,0.23127272441403887,84.70141969060963,225.3750590639215,0.07031101845011642
0.07326361350079291,210.064796217984,0.23261197286501747,84.69812583509115,225.4549022582212,0.07070411241273027
0.07368661530248072,210.015242930005,0.23395500358537627,84.67814594937802,225.4905553434453,0.07109816142372853
0.07410803230378182,209.983958954031,0.23529300256450728,84.6655322502653,225.54545696747232,0.07149057976519206
0.07453830926972761,209.927757823768,0.23665913193138516,84.64287195454327,225.57541796073647,0.07189108957769332
0.07495783273638922,209.871848080012,0.23799111893803573,84.62032914586084,225.60338696447042,0.07228143544879302
0.07537879129868041,209.828388853705,0.2393276623733103,84.60280638581386,225.6449991856468,0.07267296351278425
0.07579278656654331,209.794478349235,0.240642097348775,84.58913367041156,225.69538646959785,0.0730578656537699
0.07622279125077303,209.768544885868,0.24200736222120434,84.57867729798198,225.75768889368192,0.0734574953724251
0.07665189424877732,209.725970008207,0.24336976423986798,84.56151110730907,225.80186288249834,0.07385612796035683
0.07707504698862593,209.673398697865,0.2447132741888873,84.54031435497916,225.83398575476784,0.07424907725879516
0.07749934689508611,209.580878733005,0.2460604263918984,84.50301030514763,225.82325995651115,0.0746429368657317
0.07791530366319722,209.482826394101,0.24738108913065118,84.46347560210154,225.80474442482222,0.07502890136974673
0.07834179853185852,209.429473076367,0.2487352103386508,84.44196354439119,225.83655466274902,0.07542448951532443
0.07875758361440872,209.425569114313,0.2500553279757477,84.44038946689099,225.91942088482864,0.07580999339255973
0.07917917549491542,209.392735973322,0.25139388219635644,84.42715114444343,225.97228016231415,0.07620072948256867
0.07959918802272872,209.359145687051,0.2527274219721637,84.41360754101898,226.02396368887244,0.07658985005206391
0.08004158630047882,209.269249229305,0.2541320365040202,84.37736128925577,226.01949190152882,0.07699954622857447
0.08046597671685102,209.216231268817,0.25547947607600197,84.35598444758702,226.05101966288095,0.07739240800707042
0.08090856191105042,209.187378267259,0.2568846840675851,84.34435091735882,226.1124282128058,0.07780194850315338
0.08134206035530582,209.168517744873,0.258261041628096,84.33674635473278,226.18271593970633,0.07820291816467136
0.08178244933938011,209.14531922616,0.25965927665253186,84.32739271198773,226.24973570034194,0.07861009675118827
0.08221798093006362,209.119446801122,0.261042089452952,84.3169609502124,226.3128254903221,0.07901262125208203
0.08265844364583241,209.051863742027,0.2624405585755179,84.2897114607853,226.33176544020358,0.07941953844776706
0.08309201368233252,209.027259798903,0.2638171434414057,84.2797911509177,226.39575573009392,0.07981992625867594
0.08352854354633972,208.960049591109,0.2652031257596286,84.25269199513515,226.41417819282526,0.08022288548331509
0.08396431315588532,208.913443242677,0.26658669426993586,84.23390031544737,226.45471701357943,0.0806249810326217
0.08441042464993202,208.84173993563,0.26800309826353413,84.20498954204601,226.4701598882272,0.08103645188455777
0.08485701830712052,208.785608313207,0.2694210331251076,84.18235727188507,226.50253250010408,0.08144819794652708
0.08530871488430841,208.738103119927,0.2708551697576792,84.16320317795457,226.5452824444762,0.0818644763687713
0.08576066301452592,208.680939229747,0.2722901050711198,84.140154697434,226.5775549365841,0.08228081325910439
0.08621873471816671,208.67641344172,0.2737444827301793,84.13832989970152,226.66822977419014,0.082702614415147
0.08667342337710601,208.59128584855,0.27518811922231157,84.10400645413536,226.67060667967633,0.08312112452286863
0.08711992154331141,208.487760132893,0.2766057509000137,84.06226488558245,226.65119743841134,0.08353192546080308
0.08755406234289041,208.401134031056,0.27798414793867704,84.02733724132179,226.6474999123401,0.08393119524428626
0.08799542925671971,208.260670049434,0.2793854878900851,83.97070216393179,226.586657107726,0.08433694737411741
0.08843849158035992,208.204251347579,0.2807922107676427,83.94795414334385,226.61752127737702,0.08474409259044473
0.08887886528333253,208.120405157549,0.28219039727458073,83.91414735952377,226.61791061025937,0.08514860294589581
0.08932433659621061,208.112513888318,0.2836047686929687,83.91096559976982,226.70202612876167,0.08555762935693441
0.08977028824750682,208.066772924542,0.28502066518583413,83.89252284317534,226.7449871047067,0.08596692930420398
0.09021371359312692,208.016708123147,0.28642854065817797,83.87233671525289,226.78266785235365,0.08637374453895906
0.09065578319822762,208.001447576506,0.28783211165437267,83.86618366284722,226.8579817129192,0.0867791512923716
0.09109842028180201,207.984431735935,0.28923748439472136,83.859322875929,226.93148491028694,0.08718491385622179
0.09156040236960092,207.965888555005,0.2907042775234829,83.85184626537801,227.00732899025283,0.0876082343403061
0.09204581194535702,207.939649530354,0.2922454529265085,83.84126669063873,227.07962340700843,0.08805282877365198
0.09249816478444382,207.878047552558,0.2936816731906091,83.81642877319139,227.10638545014297,0.08846696815502456
0.09297706002607012,207.828917306165,0.2952021655827726,83.79661945784574,227.1522390256935,0.08890522089187068
0.09344708270897661,207.774078706343,0.29669448760100076,83.7745085343975,227.18996022399605,0.08933516737934306
0.09391292704451852,207.694739934985,0.29817354336634627,83.74251914178595,227.1999608940295,0.0897611094652436
0.09439238201292932,207.650634840225,0.2996958128910506,83.72473596757872,227.25127288929082,0.09019930698192313
0.09486018270396532,207.585642486972,0.30118108008508987,83.69853105074712,227.2772544600062,0.09062666808743929
0.09533628821581962,207.538999785538,0.30269271508522727,83.67972471352893,227.32499768511497,0.09106142864492815
0.09582560044864091,207.477405939758,0.3042462814244349,83.65489007491043,227.3590529434617,0.09150805218606073
0.09628353900617481,207.405677899169,0.305700236344605,83.62596932894495,227.3754305772758,0.09192585854063805
0.09675203492130552,207.313561208349,0.307187710875145,83.5888278792063,227.3715701220394,0.09235311647281888
0.09722215996384682,207.216212288782,0.30868035788521364,83.54957679483691,227.3622200270244,0.09278167670915402
0.09770321361936832,207.143813051566,0.3102077032414944,83.52038542239141,227.38242926807365,0.0932200093003332
0.09816816683520282,207.035283703582,0.31168392970176895,83.47662638928426,227.35955797496877,0.09364348876905033
0.09863047867827132,206.961600363268,0.31315176980351145,83.44691726646967,227.3743220751182,0.09406438474041087
0.09910814524945372,206.927319402102,0.3146683611670155,83.43309518292752,227.43550222948565,0.09449907390089922
0.09957518563073432,206.905126987271,0.3161512143775815,83.42414720126766,227.50774341497916,0.09492391033072568
0.10005922367346172,206.894053817887,0.31768803516324096,83.41968249937204,227.59571222556016,0.09536401805816702
0.10053689097024592,206.818089013315,0.31920462883053075,83.3890534901686,227.61093667912127,0.09579814343093096
0.10100748092853892,206.718162019851,0.32069875194811104,83.34876292640392,227.5982428276537,0.09622565238461533
0.10149795873402492,206.629197079655,0.32225601898052914,83.3128922625169,227.60163879809053,0.09667103408925178
0.10198540675022992,206.587635650402,0.32380366643198,83.29613469424208,227.65655970177656,0.09711346812963692
0.10248004907069391,206.553787148533,0.32537415579945317,83.2824869782885,227.72142939125231,0.09756223209412465
0.10297250887552992,206.50284725549,0.32693771567980745,83.26194801341357,227.76696352732816,0.09800881600385002
0.10345468463491092,206.461657231134,0.3284686237158422,83.24534019559324,227.82108286918205,0.09844588074677446
0.10395090384191692,206.40962833908,0.3300441196980862,83.22436214631705,227.8660957666015,0.09889547570834831
0.10446693656461492,206.368818317699,0.3316825235926524,83.20790754569623,227.9275365698086,0.09936280822364338
0.10496830568272691,206.287441335414,0.33327437054265796,83.17509634643893,227.9410845360173,0.09981665191829517
0.10547824784690492,206.239934068953,0.3348934369139231,83.15594141660186,227.99376095060737,0.10027804481866667
0.10597368515760892,206.145745369521,0.3364664503754083,83.11796453299087,227.99176968589123,0.10072611001203459
0.10646591104820492,206.045852173742,0.33802926757805063,83.07768759645278,227.98271154312317,0.10117107212495415
0.10696681741079092,205.938663177974,0.33961964527926114,83.03446899335911,227.96726655995474,0.10162367803856215
0.10746087325001692,205.869335206929,0.3411882725688037,83.00651595543377,227.99223374366605,0.1020698934191836
0.10796676751524692,205.781784289223,0.34279448686090896,82.97121542541473,227.99937835245024,0.10252659465800036
0.10846888021755992,205.739436400863,0.34438869469075273,82.95414075682797,228.05576268385653,0.1029796759025799
0.10894905007092291,205.651479027025,0.3459132339751802,82.91867634369648,228.0570123126997,0.10341276508645406
0.10945763123696392,205.576285060377,0.34752797917736045,82.888358136344,228.07817826158072,0.10387127540310273
0.10995753640415092,205.536461230689,0.34911517808317916,82.87230116821382,228.13674414884287,0.10432175910072689
0.11046971511125292,205.484598096753,0.350741345478228,82.8513899526108,228.18442310825162,0.10478309258133191
0.11103124973507292,205.471210485056,0.3525242179088565,82.84599206757457,228.28493576978997,0.10528863783624323
0.11155377960372492,205.372276529606,0.3541832502418266,82.80610189673715,228.28233020230493,0.10575883796031633
0.11208410691455192,205.308786156394,0.35586703945370235,82.78050257825805,228.32063809444415,0.10623582868267933
0.11259752315253292,205.207529465905,0.357497136009292,82.73967588065291,228.31338901601632,0.10669739247693819
0.11309656762945292,205.15265915765,0.359081602223513,82.71755217236449,228.35472074843526,0.10714583189846505
0.11362775108653292,205.045396861245,0.360768109699742,82.674304014454,228.3442441772339,0.10762293044424473
0.11414897473932892,204.990418956462,0.3624229947973693,82.6521369232455,228.38986511172766,0.10809086213260855
0.11469412668528092,204.888331482558,0.3641538522257669,82.61097525376738,228.38781972995434,0.10858004143506791
0.11522060680116092,204.826674187772,0.3658254265936859,82.58611503250968,228.4269278767508,0.10905223897496155
0.11573705691750992,204.75830481421,0.36746515571309396,82.55854850108946,228.45642839282507,0.10951522411714798
0.11625334989705592,204.681432261359,0.36910438592315253,82.52755348777995,228.47633442346932,0.10997785423166638
0.11677038903413092,204.594833271597,0.37074598518336566,82.49263677510791,228.48545154709453,0.11044093855746247
0.11730005638092891,204.482230201718,0.3724276790094493,82.4472352173327,228.46800733327763,0.11091511103291798
0.11783860418080593,204.426698243115,0.3741375682740588,82.42484473162396,228.51605502137448,0.11139700311397875
0.11837791273979492,204.313790865503,0.37584987294884886,82.3793204769708,228.50003097211624,0.1118793433215251
0.11891314273202692,204.292241137031,0.37754922817418546,82.3706316264509,228.58527356640442,0.11235780588108663
0.11944045048046292,204.197164585437,0.3792234302754698,82.33229676084821,228.58656591035484,0.1128289626811469
0.11996915921946992,204.122103398852,0.38090208052181695,82.30203209041713,228.61046052172196,0.11330114851668159
0.12049877350691592,204.052072812028,0.382583605884458,82.2737957578097,228.64009731742127,0.11377391966379295
0.12104474410788292,203.93818179804,0.38431706254252823,82.22787490096972,228.62382682761069,0.11426105775187688
0.12159328706559391,203.864149070343,0.38605868643326063,82.1980249051623,228.6526610706362,0.11475025213904522
0.12214456550243293,203.735692957747,0.3878089954702245,82.1462314005636,228.6209006514081,0.11524164505939116
0.12270320381840191,203.739252948405,0.38958267212342607,82.14766678879691,228.7387120287421,0.11573935215127994
0.12325435567214592,203.639617164664,0.3913325792590633,82.10749364079253,228.73908696761714,0.11623014670122898
0.12381933991124391,203.589255576848,0.3931264042181994,82.08718784858512,228.79754281539485,0.11673300893677928
0.12437003163461592,203.484400469517,0.3948748504399055,82.04491026930926,228.79176179306168,0.11722290693323421
0.12495769916230191,203.381863806222,0.39674069484030855,82.00356748666871,228.79599355878813,0.11774543420483713
0.1255295364755969,203.295947359339,0.3985562783100201,81.9689259752855,228.81559339872416,0.11825362400173653
0.12611354391001592,203.200687033838,0.4004105019143005,81.93051701204348,228.8270458006253,0.11877236291964254
0.12667483206231792,203.120977998638,0.4021925917978594,81.89837832905084,228.85129377494926,0.11927066819314534
0.1272307358120929,203.001088707191,0.40395758620339495,81.85003896673942,228.82906659406288,0.11976394862953157
0.12777767043898391,202.850933195254,0.4056941036437739,81.78949626432642,228.7707528853175,0.12024903297431679
0.1283450068116789,202.717171392563,0.4074953966270805,81.7355635054814,228.73490813578576,0.12075196341367112
0.1288916955929379,202.571365207132,0.4092311335075778,81.67677445151563,228.6811319472555,0.12123635106461235
0.1294533219715119,202.472111001343,0.4110142972595503,81.6367551557415,228.68279837705154,0.12173372979619167
0.13002189469211692,202.384246551049,0.4128195156474712,81.60132820938296,228.69862974345293,0.12223700837027202
0.13056730693491492,202.294177954928,0.41455119951835484,81.56501255142696,228.70718397911537,0.1227195482788838
0.1311375492949789,202.164340203263,0.41636171901155794,81.51266196995564,228.6756763323553,0.12322380715295973
0.13172457460132891,202.068401497318,0.4182255243592193,81.47397948371862,228.68577572492276,0.12374264152056817
0.1323128796582489,201.964810275544,0.4200933929149402,81.43221150309934,228.68735591273312,0.12426233704862058
0.1329128791529929,201.900478447658,0.42199839131075245,81.40627291009571,228.73565234050304,0.12479208513791532
0.13348673022710592,201.727005972435,0.42382036847106125,81.3363288080858,228.65488439819921,0.12529848399538163
0.13404736996294792,201.5852460754,0.4256003996323596,81.27917121760127,228.607218135141,0.1257929768872143
0.1346142690820579,201.395650738474,0.4274003043355338,81.20272637775271,228.5063790589391,0.12629274214189376
0.1351641931043269,201.234314958831,0.42914631310623785,81.13767579140067,228.43398876514334,0.12677730399864812
0.1357543311542859,201.174516070645,0.4310200014148577,81.11356487968408,228.48482794510258,0.1272970391251525
0.1363443974210629,201.037207825299,0.4328934618118747,81.05820219516056,228.4475047854524,0.1278164410971017
0.1369290200113229,200.947896213748,0.43474963853595017,81.0221917533832,228.46349471563354,0.12833078538905116
0.13754030617192892,200.794559605218,0.4366904720958743,80.9603664328239,228.41190481097732,0.1288683052124993
0.1381238575605369,200.67023748143,0.43854324775470466,80.91023975251258,228.38758477995418,0.12938116770837996
0.1387212361532339,200.488138898488,0.4404399247865176,80.83681760387036,228.3001013605475,0.12990591013205544
0.1393101139115419,200.281342822101,0.44230961166914556,80.75343742587113,228.1825595050045,0.1304229159857355
0.1398849777474499,200.08680439297,0.4441348043481534,80.67499953124552,228.07594257303901,0.1309273606032252
0.1404724080496049,199.916576929411,0.44599989555749553,80.60636381793852,227.99933989971947,0.13144256959529604
0.14105759140047092,199.759371120782,0.44785785269649514,80.5429784358993,227.93694687075228,0.13195554410261276
0.1416602140553349,199.605630450725,0.4497711796256883,80.48099019773232,227.88180678702477,0.13248353110777236
0.1422675043288669,199.416535457746,0.4516993262441524,80.40474709656318,227.78702827922848,0.13301532577268727
0.1428692870339519,199.243980486006,0.4536099863327973,80.33517293195762,227.70982592384829,0.13354201872277333
0.14344694541708192,198.990528481607,0.4554440516992351,80.23298108378394,227.53511195922434,0.13404733674240937
0.1440365421256029,198.725667130947,0.45731602124878923,80.12618898719784,227.34942505609217,0.13456283486494305
0.1446348041627249,198.466998358273,0.4592155032166515,80.02189373805568,227.17223379858564,0.1350856378018686
0.1452484947094249,198.257957797406,0.4611639707024241,79.9376085839141,227.05462773164393,0.13562163940657498
0.1458627496247749,198.041030901158,0.4631142300586603,79.85014365934691,226.9278402069259,0.1361578463948531
0.1464722392731489,197.825228231941,0.4650493596922477,79.76313202311862,226.80113239579518,0.13668960956706674
0.1470741372594169,197.522116773368,0.4669603857986486,79.64091748302198,226.5725116874649,0.13721447185565533
0.1476779894379179,197.243655157199,0.46887761646538934,79.52864175938264,226.37220158020014,0.13774076154543374
0.1482860518238469,196.930785713995,0.4708082145407139,79.40249279988278,226.13287441009135,0.1382704409212583
0.14890176680107692,196.671968540076,0.47276310959341916,79.29813771535865,225.9567721359391,0.13880650069572006
0.1495191610574579,196.333878920544,0.47472333635742886,79.16181998076335,225.6895557839003,0.13934373411867343
0.1501569422591009,195.968432252805,0.4767482916726453,79.01447188433097,225.39445281919598,0.13989840459341962
0.15077524626902092,195.63002464897,0.4787114069041414,78.8780259384647,225.12618979303306,0.140435842443944
0.1514029220199549,195.203144477582,0.48070427741335675,78.70590785336105,224.75747093897132,0.14098113105377674
0.1520126093408749,194.835897741615,0.4826400346572778,78.55783396941918,224.45341095058978,0.14151050782219513
0.1526493195657319,194.450013936903,0.4846615896211988,78.40224561935928,224.13267625391833,0.14206304894162788
0.1532821943620379,194.039845635848,0.48667096709947033,78.23686576037392,223.78269896858188,0.14261195926994774
0.1539003408325599,193.583654546862,0.48863358214337765,78.05292951329476,223.37624496123658,0.1431478045928758
0.1545277264267789,193.115138681314,0.49062553140502296,77.86402391630581,222.95678200032953,0.1436913654848649
0.1551457980156729,192.635948613345,0.49258790869976143,77.6708144809007,222.52260658746857,0.144226568055364
0.15579102732708192,192.136881054994,0.49463651176348505,77.46959044137358,222.07008314197287,0.14478498170051404
0.1564542249505839,191.626382148941,0.49674216421810385,77.26375728245301,221.60713924813794,0.14535862123207732
0.1571295684736749,191.058611932963,0.49888637990391776,77.03483233137068,221.0795691791688,0.14594242852204195
0.1578043578010009,190.492099350854,0.5010288360181778,76.80641445826434,220.55258275507998,0.1465254165190462
0.1584482894439749,189.878349530195,0.5030733189846203,76.55895053057463,219.9642492156996,0.14708142810986224
0.1590934194303629,189.178100971777,0.5051216066914022,76.27661031182049,219.27509193671946,0.14763816458677742
0.1597239709020339,188.48227187448,0.5071236076139577,75.99605201979034,218.5874087829087,0.14818202068328767
0.1603507657938889,187.844713023244,0.5091136813955972,75.73898829097199,217.96575660685448,0.1487223437144302
0.1609975648948929,186.991343081495,0.5111672685412849,75.39490953045878,217.09649397404115,0.14927960529313533
0.1616628552736519,186.448599818085,0.5132795654938448,75.17607544665188,216.59041282645111,0.14985247456939846
0.1623323748244199,185.644098532184,0.5154052900675331,74.8517005281766,215.78014591905202,0.15042865438303962
0.1630071514243919,184.836906465223,0.5175477057724442,74.52624068677791,214.96664406621574,0.15100902263575733
0.1636566594383829,184.077696503713,0.5196098937168656,74.22012723029708,214.20323739062317,0.1515673396799564
0.1643511255306459,183.157352086191,0.5218148235598007,73.84904436115221,213.25946905076927,0.15216395805670468
0.1650324970608099,182.377262821421,0.5239781781680715,73.53451236959695,212.4754379119557,0.15274898110141852
0.16572494669696392,181.486484210362,0.5261767057628604,73.17535043361796,211.56332213234361,0.15334316532970985
0.1664241703292759,180.606267271343,0.528396740795451,72.8204469638055,210.66351545824372,0.15394280421914336
0.1670980245524049,179.654062645803,0.5305362279538856,72.43651805878777,209.6739016167307,0.15452034682262722
0.1677986785324499,178.554972398172,0.5327608043405284,71.99336487094295,208.51626081198333,0.15512050527944457
0.1685053668097639,177.525574358737,0.5350045396210004,71.57831158144276,207.43958638417,0.1557254678914606
0.1691986034649079,176.408306758373,0.5372055660010825,71.12782928497599,206.25634590149878,0.15631855981779505
0.1698899009057399,175.286981394793,0.5394004353757241,70.67571089838054,205.06646929402066,0.1569096425918477
0.1706146806337469,174.199526373812,0.5417016110121464,70.237249033921,203.92052293262992,0.15752897891521236
0.1713092211899359,173.043172466135,0.5439067772780465,69.77100713834564,202.68706357354432,0.15812211567427642
0.1720066368964899,171.806415168065,0.5461210721463554,69.2723465957638,201.35825883836594,0.15871735401975087
0.1726657046880539,170.5388256548,0.5482136123845711,68.76125450401535,199.98503216315922,0.15927953731268546
0.1733080615369729,169.188870428312,0.5502530953798889,68.2169525566954,198.5106655958728,0.1598271622471328
0.1740065508235159,167.816488147811,0.552470798864663,67.66360802119739,197.01765642172703,0.16042230130815305
0.1747085387966969,166.42935365199,0.5546996106795127,67.10431539248236,195.50598284140787,0.1610200647381971
0.1754718912689929,164.929810210035,0.5571232547790524,66.49969947668612,193.8703559342259,0.16166967656320838
0.1761991325025939,163.41711728301,0.5594322456957356,65.88978168850963,192.21107158435098,0.16228816550101652
0.17691249808101492,161.87640787525,0.5616971814072224,65.2685676553008,190.51436757284176,0.16289448233784087
0.1776436354744419,160.226253560634,0.564018542631353,64.60322543564763,188.68942774159478,0.16351552288684873
0.1783311074001149,158.580921772254,0.5662012659953648,63.9398276585728,186.86083316443103,0.16409912162640578
0.17903285550507492,156.80612889238,0.5684293162286128,63.224231169407624,184.8795779086796,0.16469448843164342
0.1797266368815999,154.972642564145,0.5706320720990796,62.48496948186327,182.82535442085305,0.1652827479797417
0.1804513404428269,153.029721325327,0.5729330059059754,61.701583638371844,180.6441396660745,0.16589685724689465
0.1812043181543359,150.909400715661,0.5753237101400165,60.84667036855451,178.2548357754218,0.16653452661607868
0.1820133591982109,148.510755094831,0.5778924154543196,59.87953645423587,175.54169650670403,0.1672192211181851
0.1824128706831409,147.304134618563,0.5791608644189724,59.393027078204604,174.17430467783092,0.16755715637172192
0.18261267418741892,146.658811940117,0.579795240545055,59.13283297425518,173.44056978165153,0.16772612156973998