File: example/data/02 processed data/test_ID_104.csv
Strain,Stress_MPa,Displacement(mm),Force(kN),True Stress (MPa),True Strain
-1.76310755853645e-05,0.112738211085168,-5.597866498353228e-05,0.02272802335476987,0.11273622338924699,-1.763123101462931e-05
-2.86400842023628e-05,0.114941611274922,-9.093226734250189e-05,0.023172228833024278,0.11493831933749674,-2.8640494337378435e-05
-4.67754572337619e-05,0.779750404581771,-0.00014851207671719402,0.15719768156368505,0.7797139314000685,-4.677655123956469e-05
-0.0001749789227766,2.87367145890736,-0.000555558079815705,0.5793321661157238,2.8731686269710663,-0.00017499423337438054
-0.0002437707422865,4.56634953700156,-0.0007739721067596375,0.9205760666595145,4.565236394585385,-0.00024380045920344756
-0.0003767886310899,6.15756434629703,-0.0011963039037104323,1.2413649722134812,6.1552442460561405,-0.00037685963376207185
-0.0004314389688572,7.75042799911904,-0.00136981872612161,1.5624862846223986,7.747084162454898,-0.0004315320654271022
-0.0004825745005002,10.153994234644,-0.001532174039088135,2.0470452377042303,10.149094175948134,-0.0004826909770483366
-0.0005392960086459,12.48696137524,-0.0017122648274507323,2.517371413248384,12.480227206810218,-0.0005394414810424947
-0.0005097146802075,14.9728728321948,-0.0016183441096588125,3.0185311629704716,14.96524093910735,-0.0005098446288948729
-0.0004480723040174,17.7203506696587,-0.0014226295652552449,3.5724226950031936,17.71241067130615,-0.00044817271840864967
-0.000403129655286,20.9613110490776,-0.00127993665553305,4.225800307494045,20.952860922980044,-0.0004032109338900908
-0.0003289743079688,24.1473182188823,-0.00104449342780094,4.868099352926672,24.13937437158194,-0.00032902843188708413
-0.0002982596376444,27.6062561005803,-0.00094697434952097,5.565421229876988,27.59802226863902,-0.00029830412589638175
-0.0002065233042464,31.1487788525017,-0.00065571149098232,6.2795938166643435,31.14234590376984,-0.0002065446331206752
-0.0001300226816569,34.5619110063396,-0.00041282201426065746,6.967681258878064,34.55741717398737,-0.0001300311353385103
-8.10398391240964e-05,38.2829098699663,-0.00025730148921900605,7.717834629785207,38.27980742910924,-8.104312302929043e-05
6.49551426319712e-06,42.0535780264845,2.0623257785650857e-05,8.478001330139275,42.05385118610039,6.495493167365914e-06
9.25278994534876e-05,46.0376817645766,0.00029377608076482315,9.281196643738642,46.04194153456598,9.25236190114146e-05
0.000168705842532,50.2976164741647,0.0005356410500391,10.139999481191603,50.30610197592932,0.00016869161330161915
0.000245412902053,54.4638421786178,0.0007791859640182749,10.979910583209348,54.47720830818382,0.00024538279323275795
0.0003141177035691,58.7683011089204,0.0009973237088318925,11.847689503558351,58.78676127270739,0.00031406837893208203
0.0004257691315769,63.0300893532894,0.0013518169927566573,12.706866013623143,63.05692561969657,0.00042567851761979476
0.0004979359263816,67.1163397232085,0.0015809465662615801,13.530654088198833,67.14975936000393,0.0004978119974257207
0.0005840986959767,71.1250249703392,0.0018545133597260223,14.338805034020382,71.16656900467568,0.0005839281767301371
0.0006584098402503,75.2451916373972,0.0020904512427947024,15.169430634099276,75.29473381200278,0.0006581931835853974
0.0007421793174628,79.3164530868837,0.0023564193329443897,15.990196942315754,79.37532011789929,0.0007419040385890345
0.0008311873372636,83.2533168813122,0.00263901979581193,16.78386868327254,83.32251598408914,0.0008308420923642395
0.0009192419059879,87.1439264454162,0.0029185930515115825,17.568215571395907,87.22403279445714,0.0009188196618901049
0.0010127693442429,90.9918303503466,0.003215542667971207,18.343952998629874,91.08398408670199,0.0010122568393742975
0.001091343661753,94.8778782616398,0.003465016126065775,19.127380257546584,94.9814226327212,0.001090748579179361
0.0011856063623489,98.7226960245877,0.0037643002004577575,19.902495518556883,98.8397422811027,0.0011849040861530448
0.0012567715132591,102.302200920198,0.0039902495545976425,20.62412370551192,102.43077141205823,0.0012559824369974507
0.0013324441190171,105.770498126032,0.004230510077879292,21.32333242220805,105.91143140422552,0.0013315572031083619
0.0014252227803516,109.361630286071,0.00452508232761633,22.047304665671913,109.5174949728511,0.0014242081143336924
0.0015238450609789,112.835849345564,0.0048382080686080065,22.747707228065703,113.0077936972906,0.001522685187256364
0.0015982066767662,116.267110077915,0.005074306198732685,23.43944939170767,116.45292894952983,0.0015969309035938895
0.0016634803189873,119.71389022859,0.005281550012784677,24.134320270083744,119.91303192889465,0.0016620982680654538
0.0017709304585986,123.077686313316,0.005622704206050555,24.812461560764504,123.2956483367821,0.0017693642101261823
0.0018147919033758,126.368221925606,0.005761964293218165,25.47583354020217,126.59755395160057,0.0018131471581623482
0.0019085686591599,129.522081740062,0.006059705492832682,26.1116516787965,129.76928352594024,0.0019067496560904048
0.0020029559952933,133.113992512395,0.006359385285056226,26.83578089049883,133.3806139817551,0.002000952753424538
0.0020560531849295,136.337261517922,0.006527968862151162,27.48559192201308,136.61757817869048,0.002053942400341513
0.0021636934254162,139.706452823467,0.006869726625696434,28.164820889210947,140.00873475692936,0.0021613560118202415
0.0022406395445558,142.894022366049,0.007114030553964665,28.80743490899548,143.21419636324302,0.0022381330551660317
0.0023173832134847,146.255736126847,0.007357691702813922,29.48515640317236,146.5946667146232,0.0023147022221295813
0.0024075683193078,149.381722315892,0.007644029413802264,30.115355218883828,149.7413690180234,0.0024046747700495765
0.0024754795882325,152.787666678668,0.007859647692638187,30.801993602419465,153.1658894288647,0.00247242063584602
0.0025695536673436,156.0374107712,0.00815833289381593,31.45714201147392,156.43835727228992,0.002566258008692842
0.0026384455726433,159.104170302355,0.008377064693142477,32.07540073295477,159.52395799607834,0.0026349709854543673
0.00270781051594,161.960600892776,0.0085972983881095,32.65125713998364,162.3991595110414,0.0027041510017369705
0.0027792862110536,164.996328002958,0.00882423372009518,33.26325972539633,165.45490002225108,0.002775431136384149
0.0028475831444127,167.785052419148,0.009041076483510322,33.82546656770024,168.2628343063012,0.0028435364598908466
0.0029231136238058,170.560416431704,0.009280885755583414,34.384979952631525,171.0589839086575,0.0029188496345725823
0.0029961547327895,173.467327709834,0.009512791276606663,34.971013266302535,173.98706266473616,0.002991675206536787
0.0030719853967061,176.13007098853,0.009753553634541867,35.507822311287654,176.67113999452758,0.003067276490895762
0.0031636884288931,179.160245834743,0.010044710761735591,36.11870556028419,179.727053031408,0.003158694496713568
0.003272071594888,182.084073285731,0.0103888273137694,36.708149174403374,182.67986540981073,0.0032667300174710956
0.0033448856073947,184.955413946402,0.010620011803478173,37.287011451594644,185.57406864852106,0.003339303920803683
0.0034096704435434,187.852914778438,0.010825703658250294,37.8711476193331,188.4934313096915,0.0034038706970202772
0.0034970028142864,190.630404131224,0.01110298393535932,38.43108947285476,191.29703919095945,0.0034909025176444583
0.0035799126336167,193.693146934899,0.011366222611733022,39.04853842207564,194.38655147865623,0.003573519998558379
0.0036500193368134,196.404935887455,0.011588811394382545,39.59523507491093,197.1218177012898,0.0036433741812891274
0.0037280902599531,199.310774574649,0.011836686575351092,40.18105215424924,200.05382313204444,0.0037211581551261754
0.0037936954739533,202.225933466024,0.012044983129801727,40.76874818675044,202.99311707453003,0.0037865175594323174
0.0038691607296046,204.784026294918,0.012284585316494604,41.28445970105547,205.5763686075086,0.0038616947790075505
0.0039288669612142,207.38207166136,0.012474152601855084,41.808225646930175,208.19684823105848,0.003921169119358344
0.0040262707570241,210.06703105317,0.012783409653551516,42.34951346031908,210.91281779731423,0.004018187019864606
0.004112801655554,212.838826261734,0.013058145256383949,42.90830737436558,213.71419013874944,0.004104367205064284
0.0041897205070107,215.709512883695,0.013302362609758972,43.48703779735291,216.6132754533811,0.00418096806638417
0.0042713626208865,218.299629073329,0.013561576321314637,44.00920522118312,219.23206594910621,0.0042622662449813544
0.0043596466832052,220.867155272611,0.013841878219176509,44.52681850295838,221.8300580335242,0.004350170954175384
0.0044354953692151,223.559415120955,0.01408269779725794,45.06957808838453,224.55101187146846,0.004425687550624846
0.0045250346459698,225.835776312062,0.014366985000954114,45.528492504511696,226.85769102417356,0.004514827457035256
0.0046228958924557,228.314529646529,0.014677694458546846,46.02820917674025,229.3700039478199,0.004612243127704249
0.0047188388203661,230.857261852823,0.014982313254662366,46.540823989529116,231.9466400620175,0.004707740002452636
0.0048418070466603,232.80829581493,0.01537273737314645,46.934152436289885,233.9355086621277,0.004830123197705381
0.004937061435775,234.821949277359,0.015675170058585625,47.34010497431557,235.9812796674098,0.004924914112944818
0.0050895391984254,236.358705196796,0.016159286955000643,47.64991496767408,237.56166209178414,0.0050766312722049295
0.0052397358913013,237.92077189948,0.016636161454881625,47.96482761493517,239.1674139072878,0.005226056239563691
0.0054593806504334,239.148871903149,0.01733353356512604,48.21241257567483,240.45447662699004,0.005444532249424101
0.0056869999461558,240.130686829287,0.018056224829044665,48.41034646478426,241.4963100323555,0.005670890011236157
0.0059688724221511,240.636644365104,0.01895116994032974,48.512347504004964,242.07297379541384,0.005951129272545095
0.0062703502725202,241.327060064071,0.019908362115251634,48.65153530891671,242.8402652609102,0.006250773419448204
0.0065643384798854,241.291001824192,0.020841774673636144,48.644265967757114,242.87491763231665,0.006542887035234605
0.006930395095392,241.465042343231,0.022004004427869598,48.67935253639537,243.13849048839518,0.006906490290247395
0.0072788554149788,241.311990587826,0.02311036594255769,48.648497302505724,243.0684656772155,0.00725249239799741
0.0076465655270276,241.209385986506,0.024277845548312627,48.627812214879604,243.05380936218592,0.007617478726830444
0.0080241288232824,241.197211183534,0.02547660901392162,48.62535777460045,243.1326086778871,0.007992106687368505
0.0083871770102734,241.181821690407,0.02662928700761804,48.622255252786054,243.20465632058466,0.00835220007691043
0.0087888392467316,241.227665145552,0.027904564608372828,48.63149729334328,243.34777631638067,0.008750442211984046
0.0091681247859745,240.962836927517,0.029108796195469036,48.57810792458743,243.1720142852509,0.009126352650580533
0.0095452977632429,240.919983864352,0.030306320398296206,48.569468747053364,243.2196368474529,0.009500029248203708
0.0099182023776045,240.469511272231,0.03149029254889429,48.47865347248177,242.85453655067263,0.009869339828537596
0.0103026437501598,240.500266802161,0.03271089390675737,48.484853787315664,242.97805537284208,0.010249933245274956
0.0106961324037113,240.458994795463,0.033960220381783375,48.476533350765344,243.03097604145862,0.010639333440036548
0.0110865875009256,240.53077899032,0.03519991531543878,48.491005044448514,243.19744451826196,0.011025581772485374
0.01148501194882,240.543683239627,0.0364649129375035,48.493606541108804,243.30633031584728,0.011419559867655164
0.0118656374477918,240.385161810304,0.037673398896738965,48.461648620957284,243.23748498817386,0.011795792730283633
0.0122564551914054,240.289491987823,0.03891424523271214,48.442361584745115,243.23458937933734,0.012181952982070204
0.0126434698808639,240.147192007894,0.04014301687174288,48.41367390879144,243.18348579701987,0.012564208608018898
0.0130374110715438,240.153802936094,0.04139378015215156,48.41500667191656,243.2847867853664,0.012953155553562447
0.0134425427467786,240.297773306821,0.042680073221022054,48.44403109865512,243.52798639645366,0.013352993390466509
0.0138447154298689,240.315078566754,0.043956971489833754,48.44751983905761,243.6421724430173,0.013749752840064956
0.01423122926598,240.181338971937,0.0451841529194865,48.4205579367425,243.59941467225673,0.01413091592402308
0.0146107333267283,240.214419259982,0.04638907831236235,48.42722692281237,243.7241280810245,0.014505024969647696
0.0150023389129424,240.232887431005,0.047632426048592115,48.430950106090606,243.83694262627967,0.01489091683882209
0.0153829437491986,240.254465043855,0.048840846403705555,48.435300152841165,243.9502859651184,0.015265825821825804
0.0158060397558011,240.216927287264,0.05018417622466849,48.42773254111243,244.0138055899829,0.015682425179303235
0.0162089393590452,240.362038521074,0.0514633824649685,48.45698696584852,244.25805222767858,0.016078976988876427
0.0166080538290805,240.359537472791,0.05273057090733058,48.45648275451467,244.351441609472,0.016471648317875537
0.0170237112075126,240.452728263702,0.054050283083852506,48.47527001796232,244.54612606872178,0.016880431649613937
0.0173952779052789,240.365478542172,0.05523000734926051,48.457680474101885,244.54670284024843,0.017245712060272818
0.0177932221620985,240.309717489832,0.05649348036466273,48.44643904595013,244.5856016808397,0.017636775848101735
0.0181846052294529,240.369037753951,0.057736121603512956,48.45839801119652,244.74005381489008,0.018021242777859006
0.0185657853726337,240.364871854257,0.05894636855811199,48.45755816581821,244.82743447622374,0.018395545048171518
0.018967318360606,240.403980402239,0.06022123579492405,48.46544244909138,244.96379923368517,0.018789681459928025
0.0193732895824248,240.361732806446,0.06151019442419874,48.456925333779516,245.0183302606387,0.019188016483627914
0.0197820025786977,240.387634582683,0.0628078581873652,48.462147131868896,245.14298338988468,0.01958888149211171
0.0201574339829285,240.409574117712,0.06399985289579799,48.46657014213074,245.25561423685372,0.01995696242798727
0.0205486156965397,240.349100127869,0.06524185483651354,48.45437858577839,245.28794141940574,0.020340341228147187
0.0209387584088726,240.257375662422,0.06648055794817051,48.435886933544275,245.28806680736716,0.020722555413775722
0.0213467458744414,240.169423831582,0.06777591815135145,48.418155844446936,245.2962594889258,0.021122095507597638
0.0217211217298344,240.195666749476,0.06896456149222421,48.42344641669436,245.41298606592008,0.02148857952461869
0.0221221079374869,240.224664150372,0.0702376927015209,48.429292292715,245.5389400999531,0.021880964035306153
0.0225022885714687,240.30281654193,0.07144476621441312,48.44504781485309,245.71017986429322,0.02225284714402034
0.0228859624031184,240.305382920538,0.07266293062990091,48.445565196780464,245.80500287932438,0.022628007054092972
0.0233158636690217,240.219031017632,0.07402786714914389,48.42815665315461,245.8199451955436,0.023048201452075586
0.0237081332819512,240.289606045965,0.07527332317019506,48.442384578866545,245.98642405237027,0.023431459897814744
0.0240981946655841,240.268234720463,0.07651176806322951,48.43807611964534,246.05826541271296,0.023812415247963774
0.0245071372921432,240.235320363621,0.07781016090255466,48.431440585306,246.1228003421943,0.0242116552827442
0.0249093400707653,240.245953730815,0.07908715472467982,48.4335842721323,246.23032189292124,0.024604159967105164
0.0252972895663788,240.092610969887,0.08031889437325268,48.40267037152922,246.16630327234017,0.024982609138652658
0.0256794008919057,240.168518220263,0.0815320978318006,48.417973273205014,246.3359018812561,0.025355223153941724
0.0260773168318278,240.092818947217,0.08279548094105327,48.40271229975895,246.35379545595026,0.025743101445235853
0.0264603430158706,240.085500323377,0.08401158907538915,48.40123686519281,246.43824501507046,0.02611632352635205
0.0268636252772824,240.132266931228,0.08529201025537161,48.41066501333557,246.5830901670529,0.026509132720443997
0.0272661222688118,240.12020275949,0.08656993820347746,48.408232876313185,246.66734956714214,0.02690102324942479
0.0276715875486154,240.161348596508,0.0878572904668539,48.41652787705601,246.8069943799898,0.027295648627243648
0.0280442895144735,240.084304066438,0.08904061920845335,48.4009956997939,246.81729779755807,0.027658249290205064
0.0284791690967053,240.068027770866,0.09042136188203932,48.39771439860659,246.90496572846502,0.028081176232169137
0.0288557313964192,240.06457997272,0.09161694718363095,48.397019322500356,246.99181901020702,0.028447244298023585
0.0292675360822724,240.006988513316,0.09292442706121487,48.38540888428451,247.03140170962703,0.028847419251444368
0.0296447527025398,239.989620082479,0.09412208983056386,48.38190740862777,247.1040530210006,0.029213842460963993
0.030058937199712,239.961523614155,0.0954371256090856,48.37624316061365,247.1745119828201,0.029616021186753973
0.0304627189179299,239.843428934478,0.09671913256442742,48.35243527319077,247.14971189442147,0.030007943030610888
0.0308565375833316,239.804679226023,0.09796950682707783,48.34462333196624,247.20422132321957,0.03039004654897784
0.0312570619289301,239.783889270002,0.09924117162435307,48.34043207683241,247.27882914647415,0.030778506574390425
0.0316484178026895,239.628539764899,0.10048372652353917,48.30911361660364,247.2124039088269,0.031157928590861382
0.0320363595658527,239.596522006138,0.10171544162158232,48.30265883643742,247.27232233585434,0.03153389857618789
0.0324275443711208,239.659105656933,0.10295745337830854,48.315275700437695,247.43066193956633,0.031912868447449866
0.0328279760015603,239.641428679184,0.10422882380495395,48.3117120217235,247.5083717488439,0.032300647713993255
0.0332103018129842,239.572155922869,0.10544270825622483,48.29774663405039,247.52841952705478,0.03267075297282934
0.0336076006594951,239.643340580938,0.10670413209389694,48.312097461117105,247.69717827188956,0.03305520759839589
0.0340101479834851,239.514778934709,0.1079822198475652,48.28617943323733,247.66071201051017,0.03344459033545188
0.034413961338692,239.564288195687,0.10926432725034708,48.2961605002505,247.80864434778465,0.03383504542492529
0.0348032776371824,239.588099010309,0.11050040649805411,48.30096076047829,247.92655013872957,0.03421133873599107
0.0352065458354461,239.536345515732,0.11178078302754137,48.290527255971575,247.96959284338683,0.0346009680013138
0.0356292326825231,239.463104305962,0.11312281376701083,48.27576182808194,247.99499096815842,0.03500919627062612
0.0360577136294354,239.443380227892,0.11448324077345738,48.27178545394303,248.07716106261333,0.03542285042217129
0.0364392596299795,239.457251694624,0.1156946493251849,48.2745819416362,248.18289665940574,0.03579104975831272
0.0368601112752222,239.422780097543,0.11703085329883048,48.26763246766467,248.2479304137615,0.036197022631240666
0.0372738263154852,239.344390717295,0.11834439855166551,48.251829168606676,248.2656719664771,0.0365959506254764
0.037687306341274,239.372697025059,0.11965719763354495,48.2575357202519,248.39400918757937,0.03699449306056502
0.0380977507243756,239.349343757435,0.12096035854989252,48.2528277014989,248.46801539194865,0.03738995249125476
0.0384993129410418,239.256175327491,0.12223531858780771,48.23404494602219,248.46737369450085,0.037776702745984235
0.0389416627837822,239.190276323071,0.12363977933850848,48.220759706731116,248.50474340480372,0.03820256307568272
0.0393248241185042,239.13327660776,0.12485631657625083,48.209268564124415,248.53715065124177,0.03857129474842838
0.0397120499260724,238.985398294324,0.12608575851527987,48.179456296135726,248.47599836299048,0.038943799745218
0.0401160311169657,238.994267836619,0.12736839879636608,48.18124439586239,248.58176932192924,0.039332275311690076
0.0405508853355778,239.03032466818,0.12874906094045951,48.18851345310509,248.7232159555253,0.03975027035117001
0.0409444882715118,238.874997837004,0.12999875026204996,48.157199563940004,248.65561238429862,0.04012846282338603
0.0413540158383212,238.744128848863,0.1312990002866698,48.130816375930785,248.61715733458507,0.04052180467257938
0.041738461034307,238.71567898651,0.1325196137839247,48.12508088368041,248.6793040521666,0.04089091473813708
0.0421705382784265,238.569017272391,0.13389145903400412,48.09551388211403,248.62960114732297,0.041305594314312105
0.0425503260784776,238.522912777607,0.13509728529916637,48.08621921596557,248.67214049348246,0.04166994794145324
0.0429773853184029,238.573229239744,0.1364531983859292,48.09636301473239,248.82648283943615,0.04207949344263333
0.0434192126070284,238.624950436887,0.13785600002731516,48.106790008076416,248.98585789324778,0.042503024899374735
0.043807489720368,238.609466586427,0.1390887798621684,48.10366846382369,249.06234834109438,0.04287507563769227
0.0442164065833207,238.654601547884,0.1403870909020432,48.112767672053415,249.20705044290563,0.04326675397902184
0.0446540024939504,238.598166615193,0.14177645791829252,48.101390389622914,249.25252974227982,0.043685732499785565
0.0450745520927601,238.600031213097,0.1431117028945133,48.10176629256035,249.3548207493459,0.044088224587634985
0.0454955019259504,238.46707880567,0.14444821861489252,48.074963087223075,249.31625824874914,0.0444909375587409
0.0459131176127566,238.414699892542,0.14577414842050218,48.06440349833647,249.36106204931832,0.044890300637247
0.0463488758741584,238.32442964102,0.14715768090045292,48.04620501562963,249.37049904823124,0.04530684337334694
0.0467703037317737,238.193659016095,0.1484957143483815,48.019841657644754,249.33404879526032,0.04570952265450402
0.0471804998863654,238.11129514227,0.14979808713921014,48.00323710068164,249.34550507567218,0.04610131424686621
0.0475853272842596,238.15603234767,0.1510834141275242,48.01225612129028,249.4887650916546,0.04648782752456362
0.0480255626710625,238.10014775451,0.15248116148062343,48.000989787309216,249.53504132248344,0.046907977463074554
0.0484522977755065,238.108739623362,0.15383604543723312,48.00272190806978,249.64565517854365,0.04731507464104964
0.048871395524398,237.927208024071,0.15516668078996365,47.96612513765272,249.5550427134311,0.04771472468630364
0.0492996970533883,237.831539015285,0.15652653814450784,47.94683826548146,249.55656183847964,0.04812298646862868
0.0497199408909349,237.754645472594,0.1578608123287183,47.93133652727495,249.5757923920366,0.048523405631522507
0.0501465942669255,237.693902979026,0.15921543679748845,47.91909084057164,249.61344269143717,0.04892976801191017
0.050558614227845,237.559676387709,0.16052360017340786,47.892030759762136,249.57036442228687,0.04932203625072503
0.0509948431241268,237.605382484867,0.16190862691910257,47.90124510894919,249.7220316901309,0.04973718524540895
0.0514101971640136,237.61603090542,0.16322737599574316,47.90339183053268,249.83191790359797,0.050132308009416114
0.0518063013872537,237.558129334306,0.1644850069045305,47.891718873796094,249.86513737959123,0.05050897320598158
0.0522558767538633,237.516022163506,0.16591240869351595,47.88323006816281,249.92763014475,0.050936313593658314
0.0527132484209639,237.53029251295,0.16736456373656036,47.886106970610726,250.05128582968933,0.05137087737782813
0.0531164792854716,237.429544576007,0.16864482173137232,47.86579618652301,250.04096606223746,0.05175384363965911
0.0535537884191908,237.314665040277,0.17003327823093078,47.84263647211984,250.0237644006151,0.05216900983505702
0.0539693262441238,237.115421896845,0.17135261082509307,47.80246905440396,249.9123814587089,0.052563347460515726
0.0544370336278442,237.029288987449,0.17283758176840533,47.785104659869724,249.93246036284276,0.05300700708922258
0.0548451700916805,237.057799204069,0.1741334150410856,47.790852319540306,250.0592745229756,0.05339399795105256
0.055283193544848,236.954424064812,0.1755241395048924,47.770011891466105,250.05402135169496,0.05380916080749979
0.0557410951966478,237.053613791341,0.17697797724935677,47.79000854033435,250.2672418443935,0.054242980220590674
0.0561684752221708,236.963722549593,0.17833490883039227,47.77188646599795,250.27361352817314,0.05464771348885491
0.056591791925222,236.895683182879,0.17967893936257984,47.75816972966841,250.30203439354779,0.055048437333673705
0.0570482826187151,236.834139387442,0.18112829731442043,47.745762500508306,250.34512030497697,0.055480384765110725
0.0575114999967294,236.788378944842,0.18259901248961583,47.73653719528016,250.40643379975387,0.055918506580565845
0.0579408648913525,236.672428398622,0.18396224603004419,47.7131615651622,250.38543359597483,0.05632443857662062
0.0583464989083468,236.467773885652,0.18525013403400106,47.67190321534745,250.2648405965304,0.05670778351256881
0.058777797974516,236.304136708471,0.1866195085690883,47.63891396042776,250.19357351646394,0.057115222105353164
0.0592155923795221,236.274116852774,0.18800950580498266,47.63286195751924,250.26522864615944,0.0575286269943721
0.0596542690831868,236.34443641215,0.1894023043391181,47.64703838068944,250.44339101819452,0.05794269367955248
0.0600902810255914,236.197502329253,0.1907866422562527,47.617416469577414,250.3906766217606,0.05835407527601077
0.0605271646139759,236.127520969715,0.19217374764937348,47.603308227494544,250.419650301339,0.05876610960635525
0.0609642150769868,236.18796236481,0.19356138286943309,47.6154932127457,250.58697610101356,0.0591781315201633
0.0614161065173658,236.185663206794,0.19499613819263642,47.61502970248967,250.69126705617714,0.05960396608205559
0.0618834150429573,236.1496535539,0.1964798427613894,47.60777015646624,250.76340057702657,0.0600441381146789
0.0623306626135157,236.074906570104,0.19789985379791233,47.59270116453296,250.78961192304237,0.060465232750922575
0.0627857547534093,235.996563789547,0.19934477134207454,47.57690725997268,250.81378616628484,0.06089353130730426
0.0632315580205764,235.94109358625,0.20076019671533005,47.565724466987994,250.8600165347872,0.06131291008754504
0.0636887968001109,235.909680653295,0.2022119298403521,47.55939161970428,250.93448436760178,0.061742863927181736
0.0641437809203665,235.726835906639,0.20365650442216363,47.52253011877843,250.8472464260856,0.06217051423383981
0.0645910464459948,235.695076089215,0.20507657246603347,47.51612733958574,250.9188676959858,0.06259073146941106
0.0650663280328863,235.578455825007,0.206585591504414,47.49261669432141,250.90668090919772,0.06303707706516522
0.0655386533189446,235.406314798873,0.20808522428764908,47.4579130634528,250.83452765356668,0.06348044906319376
0.0659847513222133,235.237612698479,0.20950158544802724,47.423902720013366,250.7597080740193,0.06389902106555655
0.0664573177701938,235.150110277686,0.2110019839203653,47.4062622319815,250.77755588010626,0.06434223728471264
0.0669030500398632,235.136697891455,0.21241718387656566,47.40355829491733,250.8680601566952,0.06476010599820439
0.06735953755335,235.01091590583,0.21386653173188624,47.378200646615326,250.84114252123592,0.06518787671686038
0.0678068451953709,234.992132506207,0.2152867334953026,47.37441391325134,250.92620765718547,0.065606867622842
0.0682694664997659,234.943364458847,0.2167555561367567,47.364582274903555,250.9828226081125,0.06604001817003471
0.0687292568867195,234.817140558558,0.21821539061533443,47.3391355366053,250.95594813341205,0.06647033231951627
0.0691559949790204,234.73045917174,0.21957028405838977,47.32166056902278,250.96347762764398,0.06686954747626614
0.0696456667572317,234.718468279502,0.22112499195421065,47.31924320514761,251.065592503064,0.0673274410673618
0.0701165894097309,234.70700211105,0.22262017137589557,47.31693162558768,251.16385660965932,0.0677676046030492
0.0705759055626283,234.57319158393,0.22407850016134484,47.289955423320286,251.12840700068176,0.06819673317805454
0.0710549670829775,234.539760264702,0.22559952048845353,47.283215669363926,251.20497520995983,0.06864411328865937
0.0715409102701562,234.505821903908,0.22714239010774592,47.27637369582785,251.28258186656473,0.06909771557609706
0.072024454400963,234.465402868717,0.22867764272305752,47.26822521833335,251.3526455862383,0.06954887432961865
0.0725124365077878,234.309196636592,0.23022698591222623,47.23673404193694,251.29952738089364,0.07000396756426126
0.07295947199201,234.214685734964,0.23164632357463175,47.217680644168745,251.30286553896153,0.07042069219152894
0.0734421857558319,234.115384250547,0.23317893977476628,47.19766146491028,251.30932978897363,0.07087048104648777
0.0739145751579767,234.047189984458,0.234678776126576,47.18391350086673,251.34668859907742,0.07131045396422876
0.0743995839292099,233.925898202957,0.2362186789752414,47.15946107771613,251.32988769952374,0.071761978968076
0.0748857332108806,233.846222261265,0.2377622029445459,47.143398407871025,251.35796807389437,0.07221436124239249
0.0753468527824159,233.772886334259,0.2392262575841705,47.12861388498662,251.38693758540686,0.07264326328918312
0.0758395876599236,233.670757744555,0.24079069082025742,47.10802476130229,251.39225166008396,0.07310136852530899
0.076340000097942,233.551414058592,0.24237950031096586,47.083965074212145,251.3807290306994,0.07356639704791253
0.0768099665546767,233.485905815581,0.24387164381109852,47.07075861242113,251.41995043226416,0.07400293558120254
0.0772678559986582,233.293390287352,0.24532544279573976,47.03194748193017,251.31947037351387,0.07442807291476033
0.0777572933971724,233.213698948046,0.24687940653602236,47.01588170792608,251.34776496138903,0.07488230186616417
0.0782550181870624,233.153728259901,0.2484596827439231,47.003791617196036,251.39917750526095,0.07534401054570897
0.0787477370253586,233.017491497502,0.25002406505551356,46.976326285896405,251.36709164025604,0.07580086563843
0.079196016060111,232.882287095076,0.2514473509908524,46.94906907836732,251.32563644397305,0.07621633433687011
0.0796846863886815,232.862218338904,0.2529988792840637,46.945023217123044,251.41777117901225,0.07666904146085525
0.0801780862892675,232.854284405109,0.2545654239684243,46.94342373606998,251.5240953129675,0.07712592225477438
0.0806918774581799,232.828025635809,0.2561967109297212,46.938129968179105,251.6153561492437,0.07760146329816388
0.0811632773037737,232.653447937191,0.2576934054394815,46.902935104137704,251.53636424779634,0.07803757008545419
0.0816769295098487,232.554382064441,0.2593242511937696,46.8829634241913,251.54870993552478,0.07851254943354809
0.08216132224769,232.486693603726,0.26086219813641576,46.86931743051117,251.5881077552017,0.0789602656577522
0.082659941130606,232.417901506479,0.26244531308967406,46.85544894370617,251.62955156270354,0.0794209216021189
0.0831593026915385,232.343636261461,0.26403078604563474,46.840477070310534,251.66517103778054,0.07988205109961104
0.0836677476592969,232.201279182046,0.26564509881826764,46.811777883100476,251.62903721481536,0.08035135018557896
0.0841761822574068,232.092829777731,0.2672593786672666,46.78991448319057,251.62951811773857,0.08082041956867965
0.0846922372114249,232.040836493475,0.268897853146274,46.77943263708457,251.69289406051786,0.0812962944157884
0.0851669507610276,231.918351694167,0.27040506866626257,46.75473970154407,251.6701305334828,0.08173384682454163
0.0856907475974329,231.762065907701,0.27206812362184946,46.72323248699252,251.6219306000574,0.08221641815749116
0.0861851000971435,231.500927280432,0.2736376928084306,46.670586939735095,251.45285787067755,0.08267164906654385
0.0867112049866935,231.459654772999,0.27530807583275185,46.662266402236604,251.52980034416984,0.08315589205466976
0.0871812235809203,231.381183459917,0.27680038486942193,46.64644658551927,251.55327814755398,0.08358831326868583
0.0876941270592881,231.309671180046,0.2784288534132397,46.63202970989727,251.5941708745511,0.08405997569083373
0.0882292394680349,231.272492685477,0.2801278353110108,46.624534525392164,251.6774888249933,0.08455182428050935
0.0887344089073205,231.221383465269,0.28173174828074254,46.61423090659823,251.73867625379256,0.08501592890506769
0.0892502985832357,231.166670952916,0.28336969800177336,46.60320086410787,251.79836535795636,0.08548966013356438
0.0897874325436727,230.996218641367,0.28507509832616085,46.56883767809959,251.7367760404722,0.08598266120797753
0.0903021409495325,230.942547517874,0.28670929751476565,46.5580175796034,251.7971539950772,0.08645485136170464
0.0908312256314982,230.734536497086,0.28838914138000676,46.51608255781253,251.692437242632,0.08693999793774593
0.0913644560874461,230.604437733923,0.2900821480776414,46.48985464715887,251.67348675883417,0.08742870797509757
0.0918999820256889,230.497738040027,0.29178244293156225,46.46834398886945,251.68047602286745,0.0879192815763841
0.092398795046323,230.22097775052,0.2933661742720755,46.412549114504834,251.4931186890544,0.08837600758341292
0.0929029483131629,229.999265340918,0.2949668608942922,46.36785189272907,251.36687520095074,0.08883741139395411
0.0933991034979356,230.075299559021,0.29654215360594555,46.383180391098634,251.56412627485253,0.08929128755702052
0.0939472719558429,230.082295646654,0.2982825884598012,46.384590802365445,251.69789964799486,0.08979250535730562
0.094461243600651,230.033468637698,0.29991444843206694,46.37474727735992,251.76271615498635,0.09026222721280446
0.0950036408607325,229.992828715591,0.30163655973282566,46.366554269063144,251.84298481543095,0.09075768824990664
0.0955612204287341,229.855713538066,0.30340687486123075,46.33891184927411,251.8210060462811,0.09126676204169128
0.0960970905988878,229.653355522955,0.30510826265146873,46.298116473427726,251.722374834983,0.09175577091514195
0.0966091505086127,229.390687853111,0.3067340528648453,46.245162671187174,251.55192734118637,0.09222282838908308
0.0971277450183802,229.28132398072,0.30838059043335714,46.223114914513154,251.55090195379603,0.0926956239376153
0.0976400129607321,229.136051025015,0.3100070411503244,46.19382788664303,251.50889801686847,0.09316243228195326
0.0982212047147975,229.340293041527,0.31185232496948206,46.23500307717184,251.86637291371045,0.09369178428558485
0.0987731305806734,229.064943323722,0.313604689593638,46.17949257406235,251.69040488209052,0.09419422151868999
0.0992896729160585,228.890787948495,0.3152447115084857,46.14438285041659,251.6172794174,0.09466421932227603
0.0998389946631056,228.664294751741,0.3169888080553603,46.09872182195099,251.49390805510288,0.09516380060332645
0.100373553962156,228.621516219914,0.3186860338298453,46.090097669934664,251.56907031512347,0.09564971666621097
0.100908429168998,228.525076485415,0.32038426261156866,46.07065541945966,251.5851829792834,0.09613568368131173
0.101465739129857,228.404188985181,0.32215372173729595,46.046284499412494,251.57938884091794,0.09664178294525741
0.10203727860886,228.3404815589,0.32396835958313047,46.03344108227424,251.6397228934067,0.09716053829727551
0.102592094831424,228.21020758528,0.3257299010897712,46.00717784919245,251.62277084336802,0.0976638575771153
0.103128448046283,228.01876245727,0.3274328225469485,45.968582511385634,251.53398355492232,0.09815018684231823
0.103705172367807,227.839081482235,0.3292639222677872,45.93235882681858,251.46717269947302,0.09867285817496284
0.104252962507945,227.732883556535,0.33100315596272534,45.91094932499745,251.47471132778062,0.0991690543144861
0.104791849995266,227.491536778746,0.33271412373496956,45.8622938145952,251.3307957760569,0.09965694618065438
0.105343131892658,227.283854146512,0.3344644437591891,45.82042499593682,251.22664717093969,0.10015581336600086
0.105906860545281,227.245346074196,0.3362542822312672,45.81266176855791,251.31218725044002,0.10066568666550439
0.106451840069578,227.182858955803,0.33798459222091015,45.80006436548989,251.36689232391564,0.1011583549974242
0.107046172066676,226.932865087433,0.3398715963116963,45.749665601626496,251.2251596111661,0.10169536204068515
0.107562985374003,226.658073032415,0.3415124785624595,45.694267523334865,251.03809202690036,0.10216209298955023
0.108131062036409,226.515788309269,0.3433161219655986,45.665582923148634,251.00918106716466,0.1026748683662025
0.108656047789131,226.234044716424,0.3449829517304909,45.60878341483108,250.81574189066015,0.10314851399523885
0.109195046900518,226.096369873169,0.34669427390914465,45.58102816643087,250.78497358550658,0.1036345692793733
0.109762966187781,226.060461087168,0.3484974176462047,45.57378895517307,250.873527833873,0.10414644854550964
0.110367531770516,226.027906477435,0.3504169133713883,45.5672259458509,250.97404862660653,0.10469107022268977
0.110940783317446,225.853013425033,0.352236987032891,45.53196750648665,250.9093236490118,0.10520720889264613
0.111525098605326,225.712212068002,0.35409218807191,45.50358195290921,250.8847887753122,0.10573303500866973
0.112067901950618,225.513058149364,0.3558155886932121,45.46343252291179,250.78583343863093,0.10622125686935924
0.112672325251359,225.295627731837,0.3577346326730648,45.419598550738336,250.68020997734763,0.10676462216497622
0.113242165535781,225.106596571087,0.3595438755761046,45.381489868731144,250.5981550431863,0.10727662772424545
0.113846262262929,224.916662959912,0.36146188268479956,45.34319925271826,250.52258435854895,0.10781912683153143
0.114389045765339,224.647309736641,0.3631852203049513,45.28889764290683,250.3445011311659,0.10830631371990906
0.114966795546922,224.265762719055,0.3650195758614773,45.211977764161496,250.04887880975113,0.1088246246901104
0.115530284013365,223.975264909543,0.3668086517424339,45.15341340576387,249.85119087651117,0.10932988289788315
0.116115786919239,223.854872808775,0.36866762346858384,45.12914235824905,249.8479575206721,0.10985461029703004
0.116691194184964,223.715923171359,0.3704945415372607,45.101130111345974,249.82160140441655,0.11037002186939837
0.117263699425308,223.527520887364,0.37231224567535287,45.063148210892585,249.73918490998412,0.11088257049293139
0.117833886123467,223.112694195145,0.3741225884420077,44.979519149741236,249.40292999563562,0.11139278240870147
0.118433100425587,222.904838511876,0.37602509385123867,44.937615443994204,249.30414963670225,0.11192868829119694
0.118987877643611,222.57596499633,0.37778651151846493,44.87131454326013,249.05980668572195,0.11242459606611402
0.119529932421027,222.265250369439,0.3795075354367607,44.808674474478906,248.8326007256407,0.11290889401145401
0.1201191938291,222.025977700387,0.3813784404073925,44.760437104398015,248.6955591508752,0.11343510270616729
0.120706749231475,221.925769384108,0.3832439288099331,44.74023510783618,248.7137075771577,0.11395951239328264
0.121256047045486,221.748668604849,0.384987949369418,44.70453159073756,248.63703559747245,0.11444952750496451
0.121895009806472,221.443763432161,0.3870166561355486,44.643062707923654,248.43665314730632,0.11501922857464143
0.12245217976563,220.791270539681,0.3887856707558752,44.51152014079968,247.82764289048785,0.1155157381817049
0.123031246608839,220.434416476063,0.3906242079830638,44.439578361574306,247.55473753060505,0.1160314995979274
0.123614259995149,220.173452574162,0.39247527548459804,44.38696803895106,247.3900309846941,0.11655050751233441
0.124222211443831,220.02907294611,0.3944055213341634,44.35786110593578,247.3615709694118,0.11709142894610433
0.124839709011257,219.710749002814,0.396366076110741,44.2936869989673,247.13937497497062,0.11764054462613607
0.125409661902876,219.325190233806,0.3981756765416313,44.2159583511353,246.83068818781157,0.1181471132857469
0.126008279508188,218.744704895479,0.4000762874384969,44.09893250692857,246.30834881088464,0.11867888271727527
0.126551940573043,218.093384365469,0.4018024113194115,43.967626288078556,245.69352538306168,0.11916158774825704
0.127137113916489,217.73053836088,0.4036603366848525,43.89447653355341,245.41217061956567,0.1196808904048775
0.127773711410731,217.527684148256,0.40568153372907084,43.853581124288404,245.32200368645988,0.12024552249941928
0.12838671974986,217.076960765926,0.4076278352058054,43.76271529041068,244.9467596919323,0.12078893097848611
0.128962109292264,216.46053839699,0.4094546970029382,43.63844454083318,244.3757460072049,0.12129872330429999
0.129608095429082,215.905223526455,0.4115057029873353,43.526493062933326,243.88828834090904,0.12187075436455443
0.130183475995971,215.409428494402,0.4133325362872079,43.42654078447145,243.4521766581088,0.12237998768199722
0.130813823330988,214.808851741626,0.4153338890758869,43.30546451111181,242.9088189232875,0.12293757114442413
0.131388673808049,214.102225859811,0.41715903934055554,43.163008733337904,242.23283337488294,0.12344579310082371
0.131921050128,213.27838670221,0.4188493341564,42.996922759165535,241.4142954455712,0.12391623364560576
0.132547133759258,213.133658812668,0.4208371496856441,42.96774561663386,241.38391439591078,0.12446919672246952
0.133226284650982,212.668401396746,0.4229934537668678,42.873949721584,241.00142237749816,0.12506868377315625
0.133862194848313,211.841843433543,0.4250124686433937,42.707315636202274,240.19945755626975,0.1256296766234652
0.134487725747926,211.09900785503,0.426998529249665,42.557559983574045,239.48923332909655,0.1261812060941079
0.135056131285054,210.304225122514,0.42880321683004646,42.39733178469883,238.7071001604618,0.12668210458721346
0.135684372330683,209.632686398102,0.43079788214991854,42.261949577857365,238.0765658720234,0.12723544043572485
0.136340426543255,208.628347265729,0.43288085427483464,42.059474808770965,237.0728251209528,0.12781294665936352
0.136945225746664,207.741573582629,0.43480109174565823,41.880701234258005,236.1907902738693,0.12834503924268578
0.137579534192378,207.218532424899,0.43681502106080017,41.77525613685963,235.72756159194478,0.12890278956779086
0.138243697761196,206.269900813119,0.43892374039179727,41.58401200392479,234.7854146383597,0.1294864584383322
0.138813526479258,205.023755838105,0.4407329465716441,41.33278917696197,233.4838263980147,0.12998695418687192
0.13945049818728,204.246874976137,0.442755331744614,41.17616999518922,232.7292034447544,0.1305461270638717
0.140133603180373,203.45257784745,0.4449241900976842,41.01603969404592,231.9631206575485,0.13114545131177313
0.140771672426852,202.403480901285,0.4469500599552551,40.804541749699055,230.8961574127753,0.1317049390467063
0.141394152532615,201.207680992919,0.4489264342910526,40.56346848817247,229.65727052996553,0.13225045604147687
0.142013350777378,200.310303548607,0.45089238871817516,40.38255719539917,228.7570409507784,0.1327928018637122
0.142599257745234,198.770822799095,0.4527526433411179,40.07219787629755,227.11539459165536,0.13330571768892954
0.143242571521984,197.994693071565,0.4547951645822992,39.915730123227505,226.35596205484194,0.13386858585023262
0.143921534459147,197.098579154867,0.45695087190779166,39.735073557621185,225.4653091065531,0.13446230184580266
0.144597502713569,195.63253205401,0.45909707111558157,39.439518462088415,223.9205076385521,0.1350530491921002
0.145239625227493,194.307372890469,0.46113581009729027,39.17236637471855,222.52850290801945,0.1356138947849331
0.145915089775526,193.357223737381,0.46328041003729503,38.98081630545601,221.57096039776738,0.1362035228560356
0.146592826563181,192.129229169816,0.46543222433809966,38.733252600634906,220.29399593922452,0.1367947852046357
0.147152464477471,190.459711091118,0.46720907471597034,38.39667775596939,218.4863269618431,0.1372827538797807
0.147794185178432,189.025473959467,0.4692465379415216,38.10753555022855,216.96233986127334,0.13784200062112212
0.148508029690619,188.146441646094,0.47151299426771526,37.93032263585255,216.08769898825642,0.13846373458153868
0.149143414183042,186.463807663482,0.47353034003115835,37.59110362495797,214.27365655998378,0.13901680759904428
0.149762051502428,184.713996111126,0.4754945135202089,37.238341616003,212.37714310993974,0.1395550092289529
0.150369800806617,183.515005438369,0.47742411756100894,36.99662509637519,211.1101202511618,0.14008345660271715
0.150964110019894,181.658063011969,0.4793110493131634,36.62226550321295,209.08191082250872,0.14059994768964088
0.151620917080923,180.284190615949,0.48139641173193054,36.345292828175324,207.61904493233112,0.14117044308599988
0.152334293996797,178.540543601806,0.4836613834398304,35.99377359012409,205.73839126119145,0.14178970593906345
0.152928202218878,176.707452048863,0.48554704204493765,35.62422233305078,203.7310050093742,0.14230496893943426
0.153624507314299,174.838228804412,0.4877578107228993,35.24738692696946,201.6976655641945,0.1429087315273821
0.154321753477435,173.335301381286,0.48997156729085606,34.94439675846726,200.08470902998573,0.14351294506232726
0.154922016395677,171.173549234889,0.4918774020562744,34.508587525753626,197.6921006359627,0.14403282342215462
0.155458133792242,169.171317876194,0.4935795747903683,34.10493768384071,195.47037524440128,0.14449691796187267
0.156168889882283,167.438240448071,0.4958362253762485,33.755549274331116,193.58688458268904,0.14511185809292287
0.156834328467554,165.325694257814,0.4979489928844839,33.3296599623753,191.2544384951704,0.14568724735165872
0.157513676899008,163.301275515701,0.5001059241543504,32.921537143965324,189.02345986447702,0.1462743228039162
0.15830215995601,161.358659291701,0.5026093578603317,32.52990571320692,186.90208358518316,0.14695527771831132
0.159006832973945,158.836682897531,0.5048466946922753,32.021475272142254,184.09280080515418,0.14756345991741002
0.15972692787283,156.338839337807,0.5071329959962352,31.517910010501893,181.31036185243886,0.14818457039951366
0.159936853659436,155.506454238182,0.5077995103687093,31.350101174417492,180.3776672527719,0.1483655671360671