File: example/data/02 processed data/test_ID_093.csv
Strain,Stress_MPa,Displacement(mm),Force(kN),True Stress (MPa),True Strain
3.70226280380063e-05,0.572345909380986,0.00011754684402067,0.11538493533120678,0.572367099130698,3.7021942717374084e-05
8.00987873459341e-05,2.76338129549627,0.00025431364982334074,0.5570976691720481,2.7636026389870136,8.009557960936137e-05
0.0001828561726811,7.89060089979375,0.0005805683482624925,1.59074514139842,7.8920437448744405,0.00018283945652889356
0.0002771502367977,14.3839144365912,0.0008799520018326974,2.8997971504167857,14.387900941883379,0.0002771118377655767
0.0003557996376856,21.056229422998,0.0011296638496517799,4.244935851676397,21.063721221797728,0.00035573635600437143
0.0004816040435851,28.1401757285363,0.0015290928383826924,5.673059426872918,28.153728150954358,0.0004814881095790695
0.0005932721185778,35.4117803232912,0.0018836389764845148,7.139014913175505,35.4327891452262,0.0005930962022484594
0.0007338560589409,42.9288116388862,0.0023299929871373574,8.654448426399458,42.96031520741053,0.0007335869182489539
0.0008606239130773,50.7131493811267,0.0027324809240204273,10.223770915235143,50.75679433019155,0.0008602537886607976
0.0010005621715405,58.4902973532801,0.0031767848946410875,11.791643946421269,58.548820532213945,0.001000061942856442
0.0011271263064258,66.3183289996543,0.0035786260229019153,13.369775126330309,66.39307813286801,0.0011264915764729912
0.0012820618175914,74.2861907867501,0.004070546270852695,14.97609606260882,74.38143027553211,0.0012812406780988944
0.0014133704666045,82.1795807447039,0.004487451231469287,16.567403478132306,82.29573093708639,0.0014123725986938207
0.001538827195782,89.9356583944674,0.00488577634660785,18.13102873232463,90.07405383147535,0.001537644414454581
0.0016660741024019,97.5840596938138,0.005289785275126032,19.672946434272863,97.74664196847691,0.0016646877405853337
0.0017972042505454,105.109486668187,0.005706123495481644,21.1900725123065,105.29838988439971,0.00179559121133777
0.0019234569029254,112.389265567644,0.006106975666788145,22.657675938437034,112.60544147631481,0.0019216094283425076
0.0020521648748971,119.429178720737,0.006515623477798292,24.07692243010058,119.6742670863455,0.002050062060949297
0.0021871174190301,126.327924989666,0.006944097805420567,25.467709677916666,126.60421899492081,0.0021847291593632885
0.0023204392594927,132.99773057028,0.007367394648889322,26.812342482968447,133.3063437257187,0.0023177511978335957
0.0024506550473373,139.612436191766,0.007780829775295927,28.145867136260026,139.9545781131904,0.002447657089231948
0.0025685369332834,146.132205714026,0.008155104763174794,29.46025267194764,146.5075516815446,0.002565243879975181
0.0026926792195428,152.465760482599,0.00854925652204839,30.737097313291958,152.87630186754228,0.0026890604535148854
0.0028239875016002,158.561106928902,0.008966160317580634,31.965919156866644,159.00888151310915,0.0028200075400428163
0.0029451802427476,164.564792265372,0.00935094727072363,33.176262120699,165.04946524020383,0.002940851696233609
0.0030601529546836,170.40225328242,0.00971598563112043,34.35309426173587,170.92371024128693,0.0030554802170647977
0.0031868660309067,176.211275627423,0.010118299648128772,35.52419316648848,176.77283735598277,0.0031817987363621752
0.0033179812869895,181.856016945384,0.010534590586191663,36.66217301618941,182.45941180653523,0.0033124889327448685
0.0034501408158718,187.279397778657,0.010954197090392965,37.755526592177254,187.92553807290503,0.0034442027342725945
0.0035771666394794,192.469710952522,0.011357504080347094,38.80189372802844,193.15820718165162,0.0035707837960303897
0.003726564700591,197.344879378283,0.011831842924376425,39.78472768266185,198.08029783961652,0.0037196382609077146
0.003871737452556,201.796891750681,0.012292766411865299,40.68225337693729,202.57819633428153,0.003864261567335454
0.0040622960906872,205.821887422008,0.012897790087931859,41.493692504276815,206.65799687066024,0.004054067243736912
0.0042985394296065,209.278510403116,0.013647862689000638,42.19054769726819,210.1781023318531,0.004289327099267581
0.0046202730803074,211.558299878582,0.014669367029975993,42.650153255522135,212.5357569964266,0.0046096323813407825
0.0050330616721304,212.739071730949,0.01597997080901402,42.888196860959326,213.80980059904263,0.00502043815613787
0.0055064000593319,213.164128334225,0.01748282018837878,42.973888272179764,214.33789530313203,0.00549129526186121
0.0060087038618478,213.302633907019,0.019077634761366764,43.001810995655035,214.5843062671184,0.005990723590266387
0.0065345572866998,213.316932912567,0.020747219385271864,43.00469367517351,214.71086463090725,0.006513299623259414
0.0070735518273796,213.363454980694,0.022458527051930226,43.01407252410792,214.87269243756873,0.007048651612669274
0.0076238811224933,213.406476299737,0.024205822563916228,43.02274562202698,215.03346190581638,0.007594966210385798
0.0081673136745523,213.391997416968,0.02593122091670355,43.01982667926075,215.13483679551163,0.008134141663306504
0.0087124417856593,213.473109740242,0.027662002669468274,43.03617892363279,215.3329817816575,0.00867470747830409
0.0092657117951429,213.587682238577,0.029418634949578706,43.05927673929712,215.5667241451922,0.00922304842279344
0.0098111841665816,213.689962400509,0.03115050972889658,43.079896419942614,215.78651397617028,0.009763367006796109
0.0103469156641584,213.71145375543,0.03285145723370292,43.08422907709469,215.92270814390213,0.010293752732725814
0.0108797883982542,213.781012107216,0.034543328164457085,43.09825204081474,216.1069042825071,0.010821029307263866
0.0114262098329213,213.927794643533,0.03627821621952512,43.12784340013626,216.37217851422406,0.01136142373663556
0.0119772067246442,214.203946037521,0.03802763135074533,43.18351552116424,216.76951098044694,0.0119060476122638
0.0125332752984544,214.335876735804,0.039793149072592716,43.21011274993809,217.02220728526942,0.012455383950832183
0.013084999947323,214.431742980335,0.041544874832750524,43.229439384835544,217.23758232593707,0.01300013087502289
0.0136270002124978,214.52388111405,0.04326572567468052,43.248014432592484,217.44719808757702,0.01353498760656934
0.0141721685484091,214.680638361368,0.04499663514119889,43.27961669365179,217.72312855230538,0.014072682223910636
0.0147171549766891,214.791722991032,0.046726967050987896,43.302011354992054,217.95284606600111,0.014609908611834681
0.0152801156087152,214.886889784236,0.04851436705767076,43.32119698050197,218.17038630293635,0.015164550388565349
0.0158447860122814,214.972591283602,0.05030719558899344,43.33847440277417,218.3787859909963,0.015720567812863726
0.0163975109761914,215.059445547962,0.05206209734940769,43.35598422246914,218.58588516686834,0.016264523598409266
0.0169345947185867,215.15063032279,0.05376733823151277,43.37436707307447,218.7941190507549,0.016792803020528036
0.0174759781762328,215.218005460457,0.05548623070953913,43.38794990082813,218.97915062701628,0.017325029383916852
0.0180002600982233,215.233589928098,0.05715082581185898,43.39109172950456,219.10785052867809,0.017840173627535292
0.0185266009247297,215.224313066382,0.05882195793601679,43.38922151418261,219.21168802386197,0.018357074090082064
0.0190623313365927,215.322760231839,0.06052290199368182,43.409068462738745,219.42731403168804,0.018882921493084202
0.0195950166727714,215.510056892224,0.06221417793604919,43.44682746947235,219.73298005017702,0.019405505976270256
0.0201405896992959,215.695337992134,0.06394637229526448,43.48418013921422,220.03956929468453,0.019940450836604593
0.0206808083673439,215.703084695935,0.06566156656631687,43.4857418747005,220.1639988547766,0.02046986382803784
0.0212044398711191,215.762545171769,0.06732409659080314,43.49772910662863,220.3376690873034,0.020982754075622084
0.0217493116133397,215.834597501688,0.06905406437235354,43.5122548563403,220.52885141969193,0.021516169729054336
0.0223051569993495,215.902412143425,0.07081887347293465,43.525926288114476,220.7181493428224,0.0220600352749547
0.0228481740949613,215.958320220356,0.07254295275150213,43.53719735642377,220.8925735180061,0.022591063535883884
0.0233837427991959,216.060343142481,0.07424338338744697,43.55776517752417,221.11264263563078,0.02311453178211974
0.0239152425343902,216.090159602272,0.07593089504668887,43.56377617581804,221.25800817845544,0.023633752229101378
0.0244657346597108,216.111166307594,0.07767870754458178,43.56801112761095,221.39848475947622,0.024171242222127486
0.0250081940992627,216.13151760171,0.07940101626515907,43.57211394850473,221.5365765448618,0.02470060680160093
0.0255498964909627,216.193219285565,0.08112092135880657,43.58455300796991,221.71693366035916,0.025228953115501496
0.0260891681064572,216.263509033386,0.0828331087380016,43.598723421130614,221.90564407585032,0.02575465145807989
0.0266338529655771,216.287442107846,0.08456248316570729,43.603548328941756,222.04801003924717,0.026285346409431993
0.0271694936034757,216.292584388771,0.08626314219103534,43.604585012776234,222.16914437680092,0.02680695491780045
0.0277062794215696,216.295445731045,0.08796743716348347,43.60516185937867,222.2881877880823,0.027329405800087768
0.0282524834337018,216.28576718946,0.08970163490200321,43.60321066539514,222.3963772439257,0.027860743329663522
0.0287855537396585,216.220739379045,0.09139413312341572,43.59010105881547,222.44477309206917,0.028379032547710223
0.0293206086146153,216.317236123036,0.09309293235140358,43.609554802404055,222.65978913999487,0.028898981320808613
0.029885496827912,216.452343605567,0.0948864524286206,43.63679247088231,222.9211294337853,0.02944762793366935
0.030430613569313,216.514566785978,0.09661719808256877,43.649336664053166,223.10323789996932,0.02997678630055286
0.0309865236929439,216.489305827365,0.09838221272509687,43.64424405479678,223.19755683165363,0.030516133846528005
0.0315202206714518,216.459269647579,0.10007670063185946,43.63818876095193,223.28211359325198,0.031033656508577815
0.0320700938955536,216.386519772763,0.10182254811838266,43.62352238618902,223.32605577960757,0.03156658519431015
0.0326131546944348,216.381486158314,0.10354676615483048,43.622507609516106,223.4383690394068,0.03209263277257703
0.0331551757016649,216.442808238432,0.10526768285278605,43.634870140867896,223.61900757493896,0.032617397347280766
0.0336990260653705,216.467198119011,0.10699440775755133,43.63978714079261,223.76193187072124,0.03314365640879776
0.0342467600006579,216.486396167519,0.10873346300208882,43.64365746737183,223.90035382047537,0.033673393650254485
0.0347904956788587,216.454655687906,0.11045982378037637,43.63725858668186,223.98522045128496,0.03419898659376032
0.035343037018069,216.427624809845,0.11221414253236907,43.631809161664755,224.07683436523212,0.03473280853674549
0.0358987237083085,216.331555810939,0.11397844777387948,43.612441651485305,224.09758256238445,0.03526938202044846
0.0364525382141031,216.354034856497,0.11573680882977734,43.6169734270698,224.24068857987888,0.03580386141026465
0.0369916797189141,216.350363137542,0.11744858310755227,43.61623320852846,224.3535264777967,0.03632390580046195
0.0375309268256649,216.344191224533,0.11916069267148605,43.61498895086586,224.4637892345386,0.03684378166702996
0.0380694676988588,216.287543485033,0.12087055994387669,43.60356876658266,224.521495135402,0.03736270706972273
0.03861884481111,216.196177583392,0.12261483227527424,43.58514940081182,224.5454242142402,0.03789179669935808
0.0391699122073676,216.186235281691,0.12436447125839213,43.583145032788906,224.6542311381162,0.03842223311385599
0.0397129571153972,216.227768560491,0.1260886388413861,43.591518141794985,224.81481266049178,0.038944672283849305
0.040262437031307,216.264603003457,0.1278332375743997,43.598943965496936,224.9719429639843,0.03947302461939969
0.0408276383984961,216.275664058811,0.1296277519152251,43.601173874256304,225.10568866539873,0.04001620281986165
0.0413955073302999,216.272254209563,0.13143073577370215,43.6004864486479,225.22495389403542,0.04056164767004265
0.0419569561640619,216.19842290866,0.13321333582089653,43.58560205838586,225.26945066137796,0.04110063361427628
0.0425173478505648,216.196978892518,0.13499257942554324,43.58531094473163,225.38910104833238,0.0416383151764087
0.0430821090550369,216.128644644635,0.13678569624974216,43.57153476035842,225.43992248313245,0.042179896846279555
0.0436516481190275,216.072552541195,0.1385939827779123,43.56022659230491,225.50447557290332,0.042725763396024775
0.0442211915203569,216.017917029923,0.14040228307713315,43.54921207323248,225.5704867107318,0.04327133629169493
0.0447812809464441,215.984942593851,0.14218056700496,43.542564426920364,225.65702498834784,0.043807562980643124
0.045347385436348,215.918301543648,0.1439779487604049,43.529129591199435,225.7096319865094,0.04434925643028742
0.0459031433906152,215.821939403186,0.14574248026520326,43.5097029836823,225.7288448344511,0.04488076421444798
0.0464509511625809,215.774568044789,0.14748176994119433,43.50015291782947,225.79750196716446,0.04540439239565158
0.0470147362576471,215.720885588016,0.14927178761802953,43.489330534544024,225.86294612920264,0.04594300653400021
0.0475874727089145,215.756806723133,0.15109022585080353,43.49657223538361,226.02412787483263,0.04648987549373812
0.0481606629714114,215.740743982018,0.15291010493423118,43.49333398677482,226.1309612421375,0.04703687851097126
0.0487385617506273,215.698738309236,0.15474493355824168,43.48486564314197,226.2115845858531,0.047588072184976994
0.0493201646549202,215.615421817139,0.15659152277937163,43.46806903833522,226.24960992330037,0.0481424922418332
0.0498814155459777,215.60754861614,0.1583734943584792,43.46648180101383,226.3623583435113,0.0486772202162445
0.0504524095175545,215.571304445371,0.16018640021823555,43.459174976186794,226.44739617748226,0.0492209375804367
0.0510337091231392,215.501720845411,0.16203202646596693,43.44514692243486,226.49957298257166,0.04977416476119656
0.0516162276610057,215.422542746963,0.1638815228236931,43.42918461778774,226.54184175670298,0.05032824515525439
0.0521875162813624,215.335078152846,0.16569536419332562,43.41155175561376,226.57288104989607,0.05087134584707866
0.0527873212575198,215.256756025181,0.16759974499262537,43.39576201467649,226.6195835583338,0.05144123863790406
0.0533697868924982,215.14549867942,0.1694490733836818,43.37333253377107,226.6277680948209,0.05199434614120844
0.0539375213504952,215.049429664495,0.17125163028782225,43.353965020362196,226.64866286843548,0.05253317070610416
0.0544919149403911,214.941523212854,0.17301182993574174,43.33221107971137,226.65409841292694,0.053059053709945944
0.0550725726113084,214.97731884404,0.17485541804090415,43.33942747895847,226.8166728458628,0.05360955376719259
0.0556528748633438,214.932183919581,0.17669787769111656,43.33032827818754,226.89377785536266,0.05415941425932884
0.0562273482203302,214.909420928185,0.17852183059954838,43.325739259122095,226.99320777454358,0.05470345398741235
0.0568150721982144,214.860193059995,0.1803878542293307,43.315814920894994,227.06749044122088,0.05525973623462225
0.0574169513588426,214.78964576798,0.18229882056432525,43.301592586824775,227.12221241142313,0.055829095860416594
0.0580129602081402,214.688778814932,0.18419114866084513,43.28125780909029,227.14351039745688,0.056392583085220535
0.0585945205626019,214.567134104317,0.18603760278626102,43.256734235430315,227.13959245565098,0.05694210431140892
0.0591834468331262,214.470932568517,0.18790744369517567,43.237340005813024,227.1640616034368,0.057498278088615164
0.0597619649183422,214.399596046768,0.18974423861573647,43.222958563028435,227.21253718422173,0.05804432150849945
0.0603551656901476,214.41851252046,0.19162765106621862,43.226772124124736,227.35977737066736,0.058603913975086186
0.0609461785917067,214.283015757861,0.19350411702866877,43.199455976784776,227.3427467054091,0.059161131287416006
0.0615306976139344,214.119498840542,0.1953599649242417,43.16649096625327,227.29442097694658,0.05971192083293022
0.0621227502912576,213.982752693824,0.19723973217474286,43.138922943074924,227.27594980605838,0.06026950021881915
0.0627084699502304,213.971855126807,0.1990993920919815,43.13672599356429,227.38970277422143,0.060820809582338146
0.0632961183541586,213.942978216305,0.20096517577445355,43.13090440840709,227.48473828652544,0.06137362910316788
0.0639121134905129,213.927296184335,0.20292096033237844,43.12774291076194,227.5998418167868,0.06195278740497492
0.0645297231486426,213.838583808141,0.20488187099694022,43.10985849572123,227.63752841977816,0.06253312713033832
0.0651414497409782,213.78590776987,0.20682410292760578,43.09923900640579,227.71223173619038,0.06310760700023241
0.0657564454689246,213.691600904491,0.2087767143638356,43.08022674234539,227.74320100653435,0.06368482446936057
0.0663620469274486,213.578587160513,0.2106994989946493,43.05744317155942,227.75209938435714,0.06425289934603358
0.0669628064149555,213.484374367012,0.2126069103674837,43.03844987238962,227.7798872003681,0.06481611361923362
0.0675887776976314,213.414861449123,0.21459436918997968,43.024436068143196,227.8393110769786,0.06540262678225991
0.0682152516628488,213.343532392888,0.21658342402954492,43.01005613040622,227.89681514570995,0.06598926673103037
0.0688308848979961,213.210535648118,0.21853805955113761,42.98324398666059,227.88600548635372,0.06656542018101465
0.069437155962265,213.027129032906,0.22046297018019137,42.94626921303385,227.81912701575746,0.06713248761028916
0.0700351347736516,212.765499920991,0.22236155290634382,42.893524784071786,227.666560383141,0.06769148417177498
0.0706485571516283,212.694090458293,0.2243091689564198,42.87912863639187,227.7206210638493,0.06826459303141687
0.0712521197808691,212.722826741591,0.22622548030425937,42.884921871104744,227.87977907270792,0.06882816971983784
0.0718585579950526,212.728215304358,0.228150921634292,42.88600820535858,228.01455810099026,0.06939411177468234
0.0724729959684381,212.688598451704,0.23010176219979098,42.87802144786353,228.10277838982708,0.06996719291884215
0.0730971102931409,212.625004500489,0.23208332518072233,42.865200907298586,228.16727790554083,0.07054896308844355
0.073730316066492,212.560343429419,0.23409375351111208,42.85216523537087,228.23248473367212,0.07113886219625103
0.0743694589400649,212.454473364793,0.23612303213470603,42.830821830342266,228.2545975983291,0.07173393966878792
0.0749973110469875,212.358573429328,0.23811646257418528,42.81148840335253,228.28489541430184,0.07231816022485818
0.0756339096454158,212.288312133765,0.24013766312419516,42.79732372616702,228.344507152468,0.07291017117577896
0.0762785586367304,212.172208051698,0.24218442367161902,42.77391714322231,228.35639826465402,0.07350931172642923
0.0769203231722997,212.071566698138,0.24422202607205154,42.75362784634463,228.3841801442147,0.07410541509615946
0.0775568821655324,211.923610906715,0.24624310087556536,42.72379995879374,228.35974542590122,0.07469633247526057
0.0781841657094609,211.772652504998,0.24823472612753836,42.6933667450076,228.32992066118084,0.07527829807103663
0.0788182930013264,211.644442756406,0.2502480802792113,42.66751965969145,228.32589645768286,0.07586626894475847
0.0794400310323365,211.519525139051,0.25222209852766836,42.642336268032686,228.3226427800423,0.07644241688894592
0.080080964277501,211.470404687745,0.25425706158106565,42.63243358504939,228.40515861129302,0.07703600524986108
0.0807165309131974,211.37744348918,0.2562749856494017,42.61369260741869,228.43909744092704,0.077624275696712
0.0813383690649509,211.224044921905,0.25824932178121907,42.58276745625605,228.40466424315468,0.07819950453933427
0.08197943340995,211.104221283924,0.26028470107659124,42.55861101083908,228.41042573522878,0.07879217230458851
0.0826430015990864,211.133689139481,0.2623915300770993,42.56455173051937,228.58241094865613,0.07940527526350682
0.0832918102676242,211.075105893521,0.2644514975997068,42.552741348133836,228.6559335658228,0.08000437795523056
0.0839484402517561,211.005882656779,0.2665362977993256,42.53878594360665,228.71949738976065,0.08061033754283675
0.0846097151430499,210.872195848646,0.2686358455791834,42.51183468308703,228.71403227098935,0.0812202127358495
0.0852731028697678,210.773930322656,0.27074210161151274,42.492024353047455,228.74727736532512,0.08183166303342267
0.085934150462747,210.646837917921,0.2728409277192217,42.46640252425287,228.74859498206152,0.08244058474035812
0.0865916370103489,210.427068116275,0.2749284475078577,42.42209693224104,228.64829241575146,0.08304585863074494
0.08723909288099,210.256725749131,0.2769841198971432,42.387755911024804,228.59933177561228,0.08364154060439939
0.0879016208061007,210.230715948251,0.2790876460593697,42.382512335167405,228.71033662332925,0.08425072229221436
0.0885601143606054,210.225952133614,0.2811783630949221,42.38155195013658,228.843586496134,0.08485582695723765
0.089227604642724,210.064881693898,0.28329764474064867,42.349080149489836,228.80846790700173,0.08546882545768458
0.0898938296935521,209.973773048083,0.2854129092770279,42.33071264649353,228.84911964257992,0.0860802875461098
0.0905718772251288,209.916716147179,0.28756571018978394,42.319209975271285,228.9292671895635,0.08670221666086786
0.0912407133233897,209.779172680418,0.28968926480176227,42.29148121237227,228.91957403616988,0.08731531800798562
0.0919244296358341,209.655866556626,0.29186006409377324,42.266622697815805,228.92836250965038,0.08794167129784308
0.092603470439236,209.556912537274,0.2940160186445743,42.246673567514435,228.96260989275703,0.08856335328711742
0.0932844407398652,209.414827539136,0.29617809934907197,42.21802923188982,228.94997260875962,0.08918641389253659
0.0939571266177384,209.293164693411,0.2983138770113194,42.193502002191664,228.95774906873697,0.08980151366854801
0.094646225496177,209.257040643714,0.300501765950362,42.186219393772745,229.06242969914163,0.09043122932766413
0.0953350834730028,209.136605602608,0.3026888900267839,42.16193968948577,229.0746613549931,0.09106032876036108
0.0960164142775364,208.974660464243,0.30485211533117806,42.12929154959139,229.03965803688524,0.09168216494427556
0.0967011661103973,208.85691577952,0.30702620240051137,42.10555422115123,229.05362308562064,0.09230673407369278
0.0974005142368451,208.785920877104,0.3092466327019832,42.09124164882416,229.12177693594717,0.09294421423825878
0.0981039609629446,208.716198556369,0.3114800760573491,42.07718562896399,229.1920843518772,0.09358502072088469
0.0987970917094404,208.609972582199,0.31368076617747326,42.055770472571325,229.22003117490632,0.09421602844756517
0.0995007969051257,208.423439887353,0.3159150301737741,42.01816548129036,229.16173824985222,0.09485625580107084
0.100209625224169,208.306148708542,0.3181655600867366,41.994519579642066,229.18042980251502,0.09550073003408492
0.100914616405228,208.226083351441,0.3204039070865989,41.9783784036505,229.23913867841466,0.09614130378438246
0.10161907815869,208.083620976403,0.3226405731538407,41.949657988842844,229.22888671994735,0.09678098687229406
0.10233421653249,207.936087531186,0.32491113749065575,41.91991524628709,229.21506413752118,0.09742994654001559
0.10305336658711,207.854887512159,0.32719443891407424,41.90354532245126,229.27503343187203,0.09808212222615288
0.103773693631245,207.766350078898,0.32948147727920285,41.88569617590584,229.32703163886757,0.09873493918920524
0.104486765543033,207.548160931516,0.3317454805991298,41.84170924379363,229.23419696165502,0.0993807615002555
0.105192736793844,207.353190476241,0.3339869393204547,41.80240320001018,229.165240065372,0.1000197421977591
0.105899214221811,207.20014672912,0.33623000515424994,41.771549580590595,229.14247945437774,0.10065877256615596
0.10660964046512,207.142109154522,0.338485608476756,41.75984920555164,229.22545493667224,0.1013009632323941
0.10733264334899,207.120271262,0.3407811426330432,41.7554466864192,229.3510374677103,0.10195409941833519
0.108062949800196,207.077329260032,0.3430998656156223,41.74678957882246,229.45471629661748,0.10261340061033743
0.108799829078188,206.936326649206,0.3454394573232469,41.71836345247993,229.45096361870768,0.10327819530322647
0.109549611380177,206.797924664416,0.347820016132062,41.69046161234626,229.4525569456299,0.10395417746984614
0.110267305035942,206.598863652451,0.3500986934891158,41.65033091233412,229.3799635708948,0.10460080168057666
0.111004109680738,206.502274887195,0.3524380482363431,41.63085861725851,229.4248760580951,0.10526420973322374
0.111771790382307,206.489142151852,0.3548754344638247,41.62821105781337,229.5688032646712,0.10595495029062357
0.112511077151695,206.196537631271,0.3572226699566316,41.569221986464235,229.39593218511533,0.10661969199897542
0.113233386061443,205.84378667272,0.3595160007450815,41.49810739322035,229.15217563738142,0.1072687412919586
0.11395066097129,205.724265404055,0.3617933485838457,41.47401190545748,229.16668142468012,0.1079128505523504
0.114674415880512,205.788703406864,0.36409127042062556,41.48700260682378,229.38740276485404,0.10856235857609399
0.115425425149358,205.724521874881,0.3664757248492116,41.474063609976014,229.47036227593753,0.10923587936060676
0.116181034730243,205.673631472086,0.36887478526852147,41.463804104772535,229.5690067932396,0.10991306830350096
0.116944599034464,205.597346019803,0.37129910193442317,41.44842495759229,229.64084521263882,0.11059692085745758
0.117714657769754,205.460694729963,0.3737440384189689,41.420876057560534,229.6464300952365,0.11128611654886002
0.118483911557688,205.321474918999,0.37618641919565937,41.392809343670194,229.64876639419572,0.11197411789974966
0.119246098139885,205.142557688712,0.37860636159413485,41.35673963004434,229.6050072555272,0.11265533199471972
0.120016917941814,204.999711929119,0.38105371446525943,41.32794192491039,229.60314553381158,0.11334379049811029
0.120799015159737,204.922772795835,0.38353687313216495,41.312430995640334,229.67724193337438,0.11404183734624924
0.1215740100748,204.728819925291,0.38599748198748995,41.273330096938665,229.61852354149022,0.11473306484247675
0.122349989480968,204.568069845816,0.38846121660207333,41.24092288091651,229.59697103959354,0.11542469204308971
0.12312830833877,204.475582306847,0.39093237897559474,41.22227739306036,229.65231485287399,0.11611792420634631
0.123905393001239,204.342956739076,0.3933996227789338,41.19554007859772,229.6621511008664,0.11680957800128891
0.124687474949925,204.143037225102,0.3958827329660119,41.15523630458057,229.5971170653085,0.11750519701829222
0.125480830929749,203.961724814583,0.398401638201953,41.118683722619934,229.55501152218167,0.11821034961565582
0.12626742310124,203.887876467959,0.400899068346437,41.10379589594053,229.6322732311521,0.11890899983295095
0.127059488427507,203.788431310738,0.40341387575733473,41.08374775224478,229.68168514052448,0.11961201842722301
0.127863427353316,203.678089515685,0.40596638184677825,41.0615028463621,229.72106811793597,0.12032507070430605
0.128677100785808,203.532685872523,0.4085497949949404,41.03218947190064,229.72268180574784,0.12104623964198792
0.12946518576697,203.305797143066,0.41105196481012973,40.986448704042104,229.62681993769496,0.12174423375675289
0.130238496602062,203.09992514771,0.4135072267115468,40.944944909778336,229.55135405893907,0.12242866939432245
0.131039247050604,202.922188974471,0.41604960938566765,40.909113297253356,229.51295982754604,0.12313689772607878
0.131851489333955,202.886217310964,0.41862847863530706,40.901861409890344,229.63706722874707,0.12385477800653058
0.132644575144956,202.766228742808,0.4211465260852353,40.8776717145501,229.66206900814277,0.12455523039933235
0.133421791985999,202.526539509379,0.42361418955554675,40.82935036509081,229.54799333544358,0.12524119166047856
0.134209830915932,202.351498498646,0.42611621315808407,40.794062097327036,229.50905889773477,0.12593622426956502
0.135025429042475,202.248009484247,0.4287057372098581,40.7731987120242,229.556633737844,0.12665505512509953
0.135830960706418,202.01899731284,0.4312633002428772,40.72702985826855,229.45943179879038,0.1273645070317601
0.136627585109645,201.838532286161,0.4337925827231229,40.69064810889006,229.4152435344943,0.1280656194347352
0.137429209604421,201.705560004565,0.4363377404940367,40.663840896920306,229.42579568880947,0.12877063659160057
0.138246163816486,201.623448407894,0.438931570117343,40.64728719903143,229.49711668573653,0.12948862498019265
0.13908770869345,201.432605884936,0.4416034751017037,40.6088133464031,229.44940549362252,0.13022768649895164
0.13992325060767,201.234191905499,0.4442563206793522,40.568813088148595,229.39153417032406,0.1309609361116803
0.140744349820505,200.94757844346,0.4468633106801033,40.51103181420154,229.2298147194897,0.13168098777388434
0.141542231236314,200.744617693971,0.4493965841752969,40.470114927104554,229.1584587910565,0.13238018256820744
0.142339006932595,200.632832187163,0.45192634701098905,40.447578968932056,229.19071027875773,0.13307792088777515
0.143153581351051,200.539140265421,0.4545126207895869,40.428690677508875,229.24703639547675,0.1337907426725609
0.143993303797985,200.358829835748,0.45717873955860233,40.3923400948868,229.20915968889565,0.13452503961703574
0.14484216504412,200.131929667715,0.459873874015081,40.34659702101135,229.1194716552444,0.13526678038137585
0.145669834436669,199.831017360333,0.46250172433642406,40.285933099843135,228.9403685745238,0.13598947419722127
0.146465048010843,199.529791389242,0.4650265274344265,40.22520594407119,228.7539318646608,0.13668333703414928
0.14724435189245,199.323621141817,0.4675008172585287,40.183642022190305,228.6728985537001,0.137362851110018
0.148035171317654,199.08004904036,0.47001166893355145,40.13453788653658,228.55089820597664,0.1380519344643542
0.148846705387183,198.910537700213,0.472588289604306,40.10036440036294,228.51771590368276,0.1387585742890042
0.149682268617033,198.806970506187,0.4752412028590797,40.079485254047306,228.56484886843265,0.13948561604145185
0.150523369522864,198.608358866868,0.47791169823509316,40.03944514756059,228.50355825891518,0.14021694277969868
0.151371993143339,198.363225784218,0.48060607823010126,39.99002631809835,228.38986263751727,0.14095426878737455
0.15221035402223,198.12934587374,0.4832678740205802,39.94287612814598,228.2866837513748,0.1416821445821655
0.153022483736575,197.742692015955,0.4858463858636256,39.864926710416526,228.001769888993,0.1423867413019776
0.153799512715314,197.362586823282,0.48831345287112193,39.78829750357365,227.7168565049366,0.14306042051027507
0.154584712065874,197.088054244186,0.49080646080914997,39.7329517356279,227.55485436114685,0.1437407226648419
0.155406685106542,196.978192132404,0.4934162252132708,39.710803533892644,227.5899200099804,0.1444523903155232
0.156222070387916,196.667751122379,0.49600507348163325,39.64821862627161,227.39159438125245,0.14515785421257224
0.157025974301218,196.325424712066,0.49855746840636717,39.579205621952504,227.15361580757855,0.14585289765809495
0.157821171076145,195.796584510997,0.5010822181667604,39.472591437416995,226.69743077123195,0.1465399381028988
0.158597994870914,195.411231206536,0.5035486337151519,39.39490421123766,226.4030606511492,0.14721064903061878
0.159394672675247,195.24700863799,0.5060780857439092,39.36179694141878,226.36834167066357,0.14789803501492876
0.16021786557196,195.007026102799,0.508691723190973,39.31341646232428,226.25063559652492,0.1486078026314577
0.161018074584655,194.588325887613,0.5112323868062796,39.22900649894278,225.9205634586878,0.14929727071227714
0.161824157521344,194.205773095909,0.5137917001302671,39.15188385613526,225.63295871293576,0.1499913195442685
0.162636173617486,193.742728483651,0.516369851235518,39.05853406230404,225.2523045104435,0.1506899902148716
0.163446553155493,193.316291913853,0.5189428062686903,38.97256444983277,224.91317349597338,0.1513867664399525
0.164263002855813,192.984913935375,0.5215350340672062,38.9057586493716,224.68519540427033,0.15208827125759042
0.165063099225436,192.473009908456,0.5240753400407593,38.802558797544734,224.2432014411938,0.15277524797619968
0.165846560299828,191.910883498015,0.5265628289519538,38.68923411319983,223.73864341026183,0.15344748432881364
0.166618875501448,191.418466527895,0.5290149297170974,38.58996285202363,223.3123961709844,0.1541097151323149
0.167420745829238,190.93342907366,0.5315608680078306,38.492179301249855,222.89964617290607,0.1547968245986753
0.168197070979775,190.3360660484,0.5340257003607856,38.37175091535744,222.3500348595539,0.15546159532746445
0.168973688298369,189.734179626874,0.5364914603473215,38.2504106127778,221.79426375469217,0.1561261743652559
0.169718871183271,189.105209075427,0.5388574160068854,38.12361014960609,221.19993169458493,0.1567634388976112
0.170498824142363,188.522113928048,0.5413337666520025,38.00605816789447,220.66491267761276,0.15743000337110302
0.171285469490173,187.86673221626,0.5438313656312993,37.873933214798015,220.04557364550672,0.15810183756141458
0.172058005787939,187.071070238144,0.5462841683767063,37.71352776000983,219.25814552393453,0.15876118292320515
0.172813295039393,186.313954948949,0.5486822117500727,37.56089331770812,218.5114834154979,0.1594053882382755
0.173542414511475,185.68351144849,0.5509971660739331,37.43379590801559,217.90747636023008,0.1600268792531141
0.174290407052706,184.871917343704,0.5533720423923415,37.27017853649073,217.0933190701524,0.16066405627838412
0.175038208539717,183.941946308509,0.5557463121136014,37.082696375795415,216.13881506565923,0.16130066497356882
0.175768787419748,182.974400703187,0.5580659000576998,36.8876391817625,215.13558924364128,0.1619222208093368
0.176497929877627,182.041843364207,0.5603809273614657,36.699635622224136,214.17185186909677,0.16254216962370407
0.17721306846111,181.132948034262,0.5626514923640242,36.51640232370722,213.23207355482035,0.16314983862469337
0.177911516720727,180.145886263047,0.5648690655883082,36.317410670630274,212.19591411910528,0.16374296926796214
0.178616181611938,179.119032856447,0.5671063766179032,36.11039702385972,211.11259055928883,0.16434102284714358
0.179318504285196,178.068635991885,0.5693362511054972,35.89863701596402,209.99963745805482,0.1649367328964744
0.180001067000932,176.975325369348,0.5715033877279591,35.678225594460564,208.83107276866775,0.16551534271524254
0.180658511197689,175.649022575599,0.5735907730526625,35.41084295124076,207.38151348743597,0.1660723431568364
0.18133294556658,174.503755567861,0.5757321021738915,35.17995712248078,206.1470355774117,0.16664341582967657
0.182055869017567,173.355270795652,0.5780273841307753,34.94842259240344,204.9156152691301,0.16725518437920417
0.182783683629282,171.952651261749,0.5803381955229703,34.665654494368596,203.38279026919278,0.16787071420141103
0.183485415796712,170.510491484818,0.5825661951545605,34.37491508333931,201.79667991261158,0.1684638269527644
0.184134098268804,169.05907027383,0.5846257620034527,34.08230856720413,200.18860973286405,0.169011788721511
0.184805451275587,167.591859277561,0.5867573077999887,33.7865188303563,198.56374846146534,0.16957858496997186
0.185505691586859,165.985546668951,0.5889805707882773,33.462686208460525,196.7768102971976,0.17016942751294464
0.186202878384026,164.308639732386,0.5911941388692825,33.12462177004902,194.90338139392023,0.170757346978326
0.186913097511793,162.571451802384,0.5934490845999427,32.774404683360615,192.95818542575674,0.17135590107866067
0.187647272387263,160.895236210816,0.59578008982956,32.436479620100506,191.08678842588003,0.17197426808938918
0.188326943336711,159.062121799521,0.5979380450940573,32.06692375478343,189.0178049986764,0.1725463879074319
0.188941658663751,156.985515196601,0.5998897662574094,31.648279863634762,186.64661882403027,0.173063548938561
0.18953494758829,154.942946833383,0.6017734585928207,31.236498081610012,184.31005014062342,0.17356243039510713
0.190176809188553,152.661675373391,0.6038113691736557,30.776593755275627,181.6943856812812,0.17410187523669382
0.1908408944266,149.980637505994,0.605919839804455,30.236096521208392,178.60307651430958,0.17465969154713826
0.191585495890049,146.976446316985,0.6082839494509056,29.63045157750418,175.13500166878174,0.17528476982088448
0.192348469452612,143.293854290394,0.610706390512043,28.888041024943433,170.8562078451169,0.17592486606491292
0.192712078741641,141.284860876495,0.6118608500047101,28.48302795270139,168.5121601107279,0.1762297717765278