File: example/data/02 processed data/test_ID_154.csv
Strain,Stress_MPa,Displacement(mm),Force(kN),True Stress (MPa),True Strain
-4.46498028259908e-05,0.105050250349074,-0.00014176312397252077,0.021178130470373317,0.1050455598761091,-4.465079965815414e-05
-4.33349978614669e-05,0.203930370186091,-0.0001375886182101574,0.041112362629515946,0.2039215328639351,-4.33359368496134e-05
-6.15483855637818e-05,0.92014001479876,-0.0001954161241650072,0.18550022698343,0.9200833816663564,-6.155027974343109e-05
-9.42039787072917e-05,2.32851168207712,-0.00029909763239565116,0.46942795510674734,2.328292327012202,-9.420841618078623e-05
-7.66211237631061e-05,4.90798604536981,-0.00024327206794786185,0.9894499867465538,4.907609989963601,-7.662405931130862e-05
-5.02377661061506e-05,7.99816061578608,-0.00015950490738702813,1.612429180142474,7.997758806063785,-5.023902806496868e-05
-1.38393263222876e-05,11.3533568796939,-4.393986107326313e-05,2.28883674694629,11.353199756883189,-1.3839422086622551e-05
3.08271916883975e-05,14.9461395318224,9.787633361066205e-05,3.013141729615396,14.94660027933075,3.08267165403452e-05
9.99193291076019e-05,18.6208524175723,0.00031724386991663605,3.7539638473825763,18.622713000653278,9.99143375039161e-05
0.0001809733629203,22.4431517072383,0.0005745904272719525,4.524539384179241,22.44721331987729,0.00018095698921672995
0.0002733267186386,26.2840948371522,0.000867812331677555,5.2988735191698835,26.291278982546423,0.000273289371696118
0.0003645738529668,29.9439792363547,0.00115752198316959,6.036706214049108,29.954896028238053,0.00036450741206751767
0.0004397841484285,33.5956276815675,0.0013963146712604874,6.772878540604008,33.61040250607836,0.00043968747172343556
0.0005499747465982,37.085285650572,0.0017461698204492848,7.476393587155314,37.1056816211502,0.0005498235659151206
0.0006035643014249,40.4457665838092,0.0019163166570240575,8.153866543295935,40.47017820466295,0.0006033822297494786
0.000690343286186,43.6277940858857,0.00219183993364055,8.795363287714556,43.65791224062399,0.0006901051088693811
0.0007798184214019,46.705578434982,0.002475923487951032,9.415844612492371,46.74200030542783,0.0007795145209978262
0.0008567166768663,49.7387546162216,0.0027200754490505023,10.027332930630275,49.78136663678787,0.0008563499045990511
0.0009425192756798,52.7224967127605,0.002992498700283365,10.628855337292519,52.772188682174246,0.0009420753832834705
0.0010307592299543,55.6366278626812,0.0032726605551049023,11.21634417711653,55.69397583037419,0.0010302283624256765
0.0011162869492537,58.5593503280769,0.003544211063880497,11.805565026140306,58.624719366604914,0.001115664364256535
0.001202255529162,61.4647834631356,0.0038171613050893495,12.391300346168139,61.5386798389029,0.0012015333987155411
0.0012944722548338,64.3098526077368,0.004109949409097315,12.964866285719738,64.39309992764997,0.0012936351479544232
0.0013838258213128,67.1014099635853,0.00439364698266814,13.527644248658797,67.1942666273394,0.0013828692167752788
0.0014895556037713,69.8810427182453,0.0047293390419738774,14.088018211998252,69.98513441702364,0.0014884473162570032
0.0015824530380665,72.5366815342958,0.005024288395861137,14.623394997314033,72.65146742636101,0.00158120227859597
0.0016647123550146,75.077192056745,0.005285461727171354,15.135561918639794,75.20217398594167,0.0016633282572723414
0.0017688197389448,77.5250453489661,0.005616002671149739,15.629049142351567,77.66217317944194,0.0017672572195823314
0.0018586104510082,79.8464324911088,0.005901088181951035,16.097040790207533,79.9948359050125,0.0018568853717732634
0.001966110249328,82.0201508646212,0.0062424000416164,16.535262414307635,82.18141152388756,0.001964179984233658
0.0021141148334426,84.0576799437412,0.006712314596180254,16.94602827665823,84.23538753177505,0.0021118832373583107
0.002260486040075,85.9098071018348,0.0071770431772381245,17.319417111729898,86.10400502149403,0.002257934985198959
0.0024296995733924,87.5671429653228,0.0077142961455208695,17.653536021809078,87.77990481522883,0.00242675262588335
0.0026158360875629,89.0302479686193,0.008305279578012206,17.94849799047365,89.2631365041403,0.002612420743035625
0.002814957206181,90.1946580024237,0.008937489129624675,18.183243053288617,90.44855210492665,0.0028110026337080057
0.0030521837496757,91.1856050318257,0.009690683405220347,18.383017974416063,91.4639202537082,0.003047535293082096
0.0033501534005774,91.9018120370463,0.010636737046833244,18.527405306668534,92.20969720516143,0.0033445541387791726
0.003647281971901,92.4273183403094,0.011580120260785674,18.633347377406373,92.76442683220316,0.003640646767755779
0.0039699766303092,92.7809903374983,0.012604675801231709,18.704647652039657,93.1493287008751,0.003962117067739136
0.0042968587719605,92.9953396218976,0.013642526600974586,18.747860467774554,93.3949274627034,0.00428765363367322
0.0046513744306347,93.174336083164,0.014768113817265173,18.78394615436586,93.60772480761258,0.004640590216602498
0.0050228357507826,93.3010527455283,0.015947503508734754,18.809492233498503,93.76968860884419,0.005010263392977409
0.005364994192587,93.3765744618759,0.017033856561463723,18.824717411514182,93.87753924158754,0.005350653878844753
0.0057450047553265,93.3946774514764,0.018240390098161637,18.828366974217644,93.93123031755731,0.005728565149198793
0.0060671095345179,93.3836305762225,0.019263072772094332,18.82613992416646,93.9501992916594,0.006048778731427348
0.0064535676031942,93.3398167504148,0.020490077140141585,18.817307056883624,93.94219156788337,0.006432832498244873
0.0068601140853412,93.2793711008232,0.02178086222095831,18.805121213925958,93.91927822838373,0.006836690567029983
0.0072990735029142,93.1930057633221,0.023174558371752585,18.78770996188574,93.8732283623461,0.007272564183403038
0.0077100897670836,93.1134546986769,0.024479535010490428,18.771672467253264,93.83136779292698,0.007680518923621542
0.0081055036149912,93.0391500295618,0.02573497397759706,18.75669264595966,93.79327919646212,0.008072830456757059
0.0084859732073103,92.9626843411504,0.0269429649332102,18.741277163175923,93.75156318974906,0.008450169745558418
0.0088773582549078,92.8973061223667,0.028185612459332262,18.728096914269127,93.72198878973079,0.008838186169178234
0.0092816796552849,92.8018975218329,0.029469332905529555,18.708862540401512,93.66325500603313,0.009238869562500016
0.0097070006886772,92.7182544376997,0.03081972718655011,18.69200009464026,93.61827059737941,0.009660190438466077
0.0100989857293039,92.6241574478081,0.03206427969053988,18.673030141478115,93.55956749206231,0.010048331723504035
0.0104847088284643,92.5060655454144,0.03328895053037415,18.649222813955543,93.47596470752491,0.010430125464475784
0.0108827414342403,92.3824439022117,0.03455270405371295,18.62430069068588,93.38781815226268,0.010823950556364703
0.0112615280432018,92.2301711451906,0.03575535153716571,18.593602502870425,93.26882380397146,0.011198589121089612
0.0116946971232112,92.092036707646,0.03713066336619556,18.565754600261435,93.16902518440158,0.011626842665324488
0.0121395266234891,91.9438041962149,0.03854299702957789,18.535870925956925,93.05995845511973,0.012066433519379367
0.01256497829035,91.8293217592557,0.03989380607186125,18.51279126666595,92.98315519357833,0.012486694028594687
0.012981776631849,91.716163210032,0.04121714080612057,18.48997850314245,92.90680195435483,0.0128982356001419
0.0133876824433893,91.6064397852459,0.042505891757761025,18.467858260705572,92.83283771086025,0.013298859301956513
0.0138240345843298,91.4677470457069,0.043891309805247115,18.43989780441451,92.73220034421749,0.013729354197003026
0.0142551888698498,91.3021256387503,0.04526022466177311,18.40650852877206,92.60365468394944,0.014154539058648687
0.0146910630972263,91.150254717422,0.046644125333693505,18.375891351032276,92.4893488608039,0.01458419483061329
0.0151303063762349,90.9923814420706,0.048038722744545806,18.344064098721432,92.36912405119236,0.015016984919899456
0.0155586818014255,90.8402159959393,0.04939881471952596,18.313387544781364,92.25357001139288,0.015438886485366926
0.0159903100585421,90.6755757215971,0.05076923443587116,18.280196065473973,92.12550629212225,0.015863811766854793
0.0164209255026355,90.5116051054648,0.052136438470867706,18.247139589261703,91.9978894300256,0.01628756011364843
0.0168704377805125,90.3792678862961,0.053563639953127185,18.220460405877297,91.90400570182013,0.01672971247146336
0.0172849303400871,90.2258520895526,0.05487965382977655,18.189531781253805,91.78539965779552,0.017137245319550805
0.0177335496406953,90.0794082549721,0.05630402010920758,18.160008704202372,91.67683591286611,0.017578144812394662
0.0181303030365807,89.8934549152768,0.057563712141143725,18.122520510919802,91.52325049389597,0.01796790899076672
0.0185685963958327,89.7024946696085,0.05895529355676882,18.084022925393075,91.36814408882779,0.018398304829974857
0.0189965680214586,89.548036323425,0.060314103468131056,18.052884122802478,91.24914168663098,0.018818386248123684
0.0194782212155015,89.4126256915245,0.06184335235921726,18.02558533941134,91.15422459420284,0.01929094858301201
0.0199259660138815,89.2934290232076,0.06326494209407375,18.001555291078652,91.07268685518697,0.019730042322622415
0.0203885115436995,89.1467800843389,0.0647335241512459,17.971990865002724,90.96435023917208,0.020183448444894034
0.0208409180002726,88.9787865014888,0.06616991465086551,17.938123358700143,90.8331860947301,0.02062671705295239
0.0212988775924754,88.8450137404574,0.06762393635610939,17.911154770076212,90.7373128128172,0.021075226602463196
0.0217220695393591,88.6987377084985,0.06896757078746514,17.8816655220333,90.62545785705588,0.02148950718390368
0.0221900622254106,88.5729702865292,0.07045344756567865,17.856310809764288,90.53841000867672,0.02194744535742559
0.0226367001659082,88.4270093195932,0.07187152302675853,17.82688507882999,90.4287050161288,0.022384292092626018
0.0230757489125563,88.274983499919,0.07326550279736625,17.79623667358367,90.31199485442319,0.02281353008605658
0.0235713025906904,88.1092341164163,0.07483888572544202,17.76282159786953,90.18608353480832,0.023297789145237467
0.024048542233069,87.9408022899415,0.07635412158999408,17.728865741652207,90.05565038782113,0.023763930018238486
0.0245305627541596,87.7828596639085,0.07788453674445674,17.697024508243953,89.9362226116336,0.024234520125120583
0.0249937963055642,87.6413521459343,0.07935530327016634,17.668496592620357,89.83184224941401,0.02468656018724033
0.0254799175393303,87.5060956284018,0.0808987381873737,17.6412288786858,89.73574372920223,0.02516071524671894
0.0259456370901562,87.3360442918194,0.08237739776124593,17.606946529230793,89.60203360190476,0.025614760052562278
0.0264303022700066,87.1542188934776,0.08391620970727096,17.570290528925085,89.45773124293854,0.02608705674983366
0.0269173577000647,87.0033507268732,0.08546261069770542,17.539875506537637,89.34525103949262,0.026561458088377482
0.0274006897119238,86.8605278822017,0.08699718983535806,17.511082421051864,89.24056625491582,0.02703201036862083
0.0278771566541591,86.7295011604266,0.08850997237695513,17.484667433942004,89.14727305081288,0.02749566247445491
0.0283689450428706,86.5631745026652,0.09007140051111415,17.451135979737305,89.01888044286773,0.027973998601324702
0.028843943134881,86.3769241294376,0.09157951945324716,17.41358790449462,88.86837521719303,0.028435786589511226
0.0293047581738208,86.1834671024344,0.09304260720188104,17.374586967850774,88.7090527644527,0.028883582267585448
0.0297833696517907,86.0279170513989,0.09456219864443546,17.34322807756202,88.59011830531429,0.029348459394621898
0.0302411498008761,85.8811754149879,0.09601565061778161,17.31364496366156,88.47832090578787,0.02979290085859291
0.0307299187013082,85.7810225881034,0.09756749187665353,17.293454153761644,88.41706643835089,0.030267210194677298
0.0312269374665046,85.613129762088,0.0991455264561521,17.25960696003694,88.28656561148046,0.030749294747839117
0.0317205434750752,85.4630251585618,0.10071272553336375,17.22934587196606,88.1739587636154,0.031227839182489545
0.0322192321641197,85.3077267173812,0.10229606212108003,17.19803770622405,88.05627616988178,0.03171107876596492
0.0327415575575481,85.1560008946756,0.10395444524521522,17.167449780366603,87.94414099933924,0.03221697254096349
0.0332479007253362,85.0393190391844,0.10556208480294242,17.14392671829958,87.86669787634939,0.03270714268766602
0.0337580225981349,84.8945483858359,0.10718172174907831,17.11474095458452,87.7604204687034,0.03320072800099221
0.034271576863042,84.7335276902427,0.10881225654015833,17.082279182352927,87.63747929735554,0.03369738847006623
0.0347828641530832,84.565354937092,0.11043559368603917,17.048375555317747,87.50678018992613,0.034191611618875455
0.0353183776749498,84.3988920710169,0.11213584911796562,17.014816641517008,87.3797240165284,0.03470899069482752
0.0358327046304331,84.2669937069756,0.11376883720162509,16.98822593132628,87.28650800257223,0.035205648780710246
0.0363354449785774,84.1486481720641,0.11536503780698325,16.96436747148812,87.2062267477418,0.03569088001843885
0.0368360601097553,84.017031898937,0.11695449084847306,16.9378336308257,87.11188833620947,0.03617382620950834
0.037340451551608,83.8513744289988,0.11855593367635539,16.90443708488616,86.98242261340057,0.036660179660103674
0.0378795946437665,83.6971131121314,0.12026771299395864,16.873338003405692,86.86752582967242,0.03717978056245319
0.0383733389181166,83.5558204981687,0.1218353510650202,16.84485341243081,86.76213631672624,0.037655391482179154
0.0388958079876508,83.3919494001862,0.12349419036079128,16.81181699907754,86.63554665177173,0.038158426037262744
0.0394116898702274,83.2229339335525,0.12513211533797197,16.777743481004183,86.5028903958321,0.038654870277303
0.0399384444252255,83.0400275708554,0.12680456105009094,16.740869558284448,86.3565170970632,0.03916152334893164
0.0404749085259196,82.8960774130575,0.12850783456979473,16.71184920647239,86.25128856350854,0.03967725173706519
0.0410072781906886,82.8058324827098,0.1301981082554363,16.6936558285143,86.20147429113983,0.0401887811460362
0.0415418383385825,82.7004935952314,0.13189533672499942,16.672419508798654,86.1360241306855,0.04070215214448377
0.0420842079419006,82.5817105849935,0.1336173602155344,16.648472853934692,86.05709646545023,0.041222753829739035
0.0426178554968994,82.4323445042925,0.1353116912026556,16.61836065206537,85.94543425064707,0.04173471913740962
0.0431513365750657,82.2783330882084,0.13700549362583359,16.587311950582816,85.82875313213304,0.04224626288043487
0.043687548615521,82.1207467487544,0.13870796685427916,16.55554254454889,85.7084008646835,0.04276016173104699
0.0442204653549484,82.007577459034,0.14039997750196115,16.532727615741255,85.63399069690446,0.04327064087805378
0.0447414288308618,81.8668392585355,0.1420540365379862,16.504354794520758,85.52967862082888,0.04376941827381551
0.0452834040433914,81.719732178684,0.1437748078377677,16.474698007222695,85.42027982924908,0.04428804869021343
0.0458253752260569,81.5664204314824,0.14549556634273064,16.443790358986853,85.3042322536014,0.0448064064152384
0.0463818201908184,81.4188671898297,0.1472622791058484,16.414043625469667,85.1952224479685,0.04533832789901924
0.046925172954315,81.2952925225805,0.1489874241299501,16.389130972552227,85.11008818457421,0.04585746128698256
0.0474762287950054,81.1912327263426,0.15073702642414213,16.36815251763067,85.04588626740698,0.046383679282201704
0.0480442521485752,81.0687012357158,0.15254050057172627,16.343450169120306,84.96358635924204,0.046925810339995995
0.0486386088496552,80.9405278797662,0.15442758309765525,16.317610420560865,84.87736255539474,0.04749275990404923
0.0491927145251986,80.7780593495375,0.15618686861750555,16.28485676486676,84.75175136301885,0.048021025148499964
0.049733078545532,80.5863392725256,0.1579025243820641,16.246205997341164,84.59414601326301,0.048535920943344815
0.0502796403479118,80.4369290225119,0.15963785810461995,16.2160848909384,84.48126888445431,0.049056452852321755
0.0508393778087085,80.2538257716146,0.16141502454264947,16.179171275557504,84.33388034061197,0.04958925225035776
0.051402460609083,80.1462530803352,0.16320281243383852,16.157484620995575,84.26596769726272,0.05012494971727163
0.0519720636200229,80.0383387315037,0.1650113019935727,16.135729088271145,84.19809636409836,0.05066655846863996
0.0525532714171725,79.9447239820744,0.16685663674952267,16.116856354786197,84.14608075987529,0.05121889946663098
0.0531463207332311,79.8459438690667,0.16873956832800874,16.09694228400385,84.08946201117968,0.051782179560286905
0.0537108889480134,79.7409975036241,0.17053207240994253,16.07578509673062,84.02395736514507,0.05231811358154025
0.0542793641011942,79.5833618676421,0.17233698102129158,16.044005752516647,83.90309614285295,0.05285746632867888
0.0548529336325589,79.4204288305303,0.1741580642833745,16.01115845223491,83.77687234224075,0.053401357810612296
0.0554574784848851,79.2590307123148,0.1760774941895102,15.978620591602663,83.65453670277584,0.053974301833816136
0.0560433500583387,79.1169359792426,0.17793763643522537,15.949974293415307,83.55091411787045,0.05452923563310115
0.0566401209866643,78.9862423853406,0.17983238413265915,15.923626464884665,83.46003271032828,0.05509417681087495
0.0572361601323488,78.8665343909827,0.18172480842020744,15.899493333222111,83.38055198246838,0.055658106844817035
0.0577876172876106,78.739369983182,0.18347568488816365,15.873856988609491,83.2895305612377,0.05617957348140577
0.0584104954775496,78.6285885959511,0.18545332314121996,15.851523460943742,83.221323414541,0.05676825013145031
0.0590271420351726,78.4940706169235,0.18741117596167298,15.824404636371776,83.12735127214751,0.05735069616351413
0.0596353746312024,78.3843871593288,0.1893423144540676,15.802292451320687,83.05886945281257,0.05792486275017398
0.0602604828988248,78.2314637320416,0.19132703320376873,15.771463088379587,82.94572951441634,0.058514616518992674
0.0608326917807279,78.0758083927793,0.19314379640381107,15.740082971984307,82.82536998026839,0.059054158018267376
0.0614003445886375,77.8707671991344,0.19494609406892405,15.698746667345498,82.65205913854282,0.05958911606643574
0.0619679329479818,77.7303316454496,0.1967481871098422,15.670434859722638,82.54711962487922,0.060123727399634445
0.0625572374048258,77.5679684034477,0.1986192287603219,15.637702430135056,82.4204062178722,0.06067849086413119
0.0631761694626442,77.473551676025,0.20058433804389533,15.61866801788664,82.36803390558248,0.06126081419151454
0.0637884794941881,77.3862471957637,0.20252842239404723,15.601067434665964,82.32259823814285,0.061836573688748446
0.0644162770696138,77.295382687712,0.20452167969602378,15.582749149842742,82.27446347512549,0.06242655225326337
0.0650283293071768,77.1596748811633,0.2064649455502863,15.555390456042522,82.17723962857028,0.06300139909603589
0.0656287538658753,77.0183634517318,0.20837129352415407,15.52690207186913,82.07298266985804,0.06356500417292435
0.0662302881311477,76.8929215216912,0.21028116481639395,15.501612978772949,81.98556186931853,0.06412933255429132
0.0668354799825596,76.7793682709732,0.21220264894462673,15.478720643428197,81.9109542021214,0.06469677109903518
0.0674982404630652,76.6756305485205,0.21430691347023198,15.457807118581734,81.8511006969417,0.06531781784112518
0.0681651716488384,76.5442886206063,0.2164244199850619,15.43132858591423,81.76194319316814,0.0659423836820442
0.0687746089736651,76.4169186538103,0.21835938349138667,15.405650800608157,81.67246235319848,0.06651276694401152
0.0693918662604902,76.2674060946856,0.22031917537705636,15.375509068688617,81.55974373844252,0.06709013761287368
0.069994501917752,76.1334630536627,0.22223254358886257,15.348506151618398,81.46238687937738,0.06765351006598884
0.0706501959843348,76.0091591929248,0.22431437225026296,15.32344649329364,81.37922118650944,0.06826612372180209
0.0712884099578891,75.8630556360954,0.22634070161629788,15.293992016236832,81.2712122469395,0.06886204555697571
0.0719432143755114,75.7611526570324,0.2284197056422487,15.27344837565773,81.21165350397312,0.06947308958092721
0.0725803150064528,75.6249050503667,0.23044250014548764,15.245980858153928,81.11378448125541,0.07006725480313679
0.0732200850733507,75.4861093588549,0.23247377010788847,15.21799964674515,81.01320870796651,0.070663554520325
0.0738614511996825,75.2737775630849,0.23451010755899193,15.175193556717918,80.83360801117645,0.07126098515774891
0.074472161495688,75.1035467426108,0.2364491127488094,15.14087502331034,80.69667020452547,0.07182952843133286
0.0750825418836636,74.9366353628011,0.23838707048063193,15.107225689140702,80.56306842604944,0.07239744177954517
0.0756999860225432,74.8479514734921,0.24034745562157464,15.08934701705601,80.51394035385144,0.07297159946199826
0.0763396121486637,74.7572987962586,0.24237826857200723,15.071071437325735,80.46424199164674,0.07356603661408294
0.0769770451236223,74.6383890481596,0.2444021182675008,15.047099232108975,80.38383168987426,0.07415808422716876
0.0776159674117835,74.4980178590573,0.24643069653241262,15.01880040038595,80.28025358544836,0.07475116357270836
0.0782518841137156,74.3397387026873,0.248449732061047,14.986891322461759,80.15696332069389,0.07534110392543013
0.0788815144831654,74.2062596981608,0.2504488084840501,14.95998195514922,80.05976184728281,0.0759248697581226
0.0795399285089989,74.0600864927381,0.2525392730160715,14.930513436936002,79.95082047774075,0.07653495825441084
0.0801968796504454,73.9540832467401,0.25462509289016416,14.909143182542806,79.88496996053793,0.07714332049487112
0.080854013838431,73.8314150617333,0.25671149393701836,14.884413276445432,79.80098131684562,0.07775148220935887
0.0814902257442683,73.7181240045715,0.25873146673805186,14.861573799321613,79.72543057114798,0.07833992868568712
0.0821689350242999,73.575825233421,0.26088636870215215,14.832886367057675,79.62147243638522,0.07896730042204886
0.0828298874382224,73.4152259729671,0.2629848926163561,14.800509556150166,79.49620087655961,0.0795778803702675
0.083492233397175,73.2634870891902,0.2650878410360306,14.769918997180746,79.3804192527318,0.08018937389952739
0.0841217051281035,73.0946737790879,0.2670864137817286,14.735886233864122,79.24352237316725,0.08077017081860562
0.0847711846265071,72.8829565749229,0.26914851118916,14.693204045504457,79.06133114286139,0.08136907500689894
0.0854194740724954,72.7314949527567,0.2712068301801729,14.662669382475752,78.94418100012754,0.08196652432562432
0.0860632503251436,72.5704932294276,0.2732508197823309,14.630211435052605,78.81614575445096,0.08255946136746789
0.0867027708467868,72.4737657272575,0.27528129743854807,14.610711170615112,78.75744202951162,0.0831481308642104
0.0873409566065798,72.3431899965871,0.27730753722589085,14.584387103311961,78.66171341486056,0.0837352264870489
0.0880019748337829,72.1927902253959,0.2794062700972607,14.554066509439814,78.54589833399174,0.08434296353668337
0.088671431986368,72.0567612701559,0.2815317965567184,14.52664307206343,78.44613747628048,0.08495808307790274
0.0893358082906706,71.9218482760429,0.2836411913228791,14.499444612450247,78.34704472554216,0.08556816031972542
0.0899840444969245,71.7927899031648,0.2856993412777353,14.473426444478026,78.25299550436954,0.08616305805769853
0.0906497475654306,71.6360111393061,0.28781294852024214,14.44181984568411,78.12979746567858,0.08677361732868628
0.0912895209296988,71.3886380261669,0.2898442289517937,14.391949426075248,77.90567259139937,0.08736004371721186
0.0919282619093582,71.2119287105551,0.29187223156221226,14.35632482804791,77.75831754412955,0.08794518094255394
0.0925881023507384,71.0562240747648,0.2939672249635944,14.324934773472583,77.63518502205612,0.08854928762011671
0.0932245866751485,70.9512001111935,0.2959880626935965,14.303761942416612,77.56559641566525,0.08913166537425357
0.0938959601904143,70.8133588029714,0.29811967360456537,14.275973134679035,77.46244712208473,0.08974559910306941
0.0945571093388142,70.6339738649949,0.3002188221507351,14.239809131182971,77.31291825478218,0.09034981509263713
0.0951990361797799,70.4368405149252,0.30225693987080116,14.200067047808918,77.14235984349494,0.09093611495133855
0.095828422973594,70.2377081937832,0.3042552429411609,14.159921971866694,76.96847700327292,0.09151062788908952
0.0964776605395257,70.0681299251221,0.3063165722129941,14.125734992904613,76.8281391786774,0.0921029152432996
0.0971498648142723,69.8876601185806,0.30845082078531455,14.08935227990585,76.67723685128652,0.09271578528437806
0.0978209363479101,69.7320197062567,0.3105814729046146,14.057975172781351,76.55327116735364,0.09332724813772553
0.0984734768204333,69.5422063731614,0.3126532889048757,14.01970880482934,76.39026922049071,0.0939214676447385
0.0990870397139718,69.3400180435962,0.31460135109186044,13.978947637588995,76.21071516524954,0.09447987129721144
0.0996819815690995,69.1212545248078,0.3164902914818909,13.934844912201251,76.01139814438272,0.09502103034019241
0.100339727980464,68.9129368211263,0.3185786363379732,13.892848063139061,75.82764215609302,0.09561897574055554
0.10099081278915,68.6912684762056,0.32064583060555124,13.848159724803047,75.6284555111353,0.0962105132817043
0.101667039142251,68.5158719942415,0.3227928492766469,13.812799794039085,75.4816778341455,0.0968245227373747
0.102349093772616,68.3286378385544,0.3249583727280558,13.775053388252568,75.32201200004772,0.09744344257371487
0.102943968240099,68.146505606957,0.3268470991623143,13.738335530362534,75.16177731583332,0.09798293956135667
0.103584058280345,67.9189471893225,0.3288793850400954,13.692459753367416,74.95426737332096,0.09856311805943847
0.104245160489663,67.6848223769525,0.33097838455468,13.645260191193625,74.74063754835224,0.099161988862901
0.104918786512465,67.4365121280365,0.33311714717707636,13.595200845012158,74.51186914714322,0.09977183589991573
0.105590999005572,67.1440801538474,0.3352514218426911,13.536246559015636,74.23389065460233,0.1003800327224152
0.10621990528975,66.8948220443374,0.33724819929495625,13.485996124138422,74.00038370626162,0.10094871271210669
0.106873506229103,66.6373938976963,0.339323382277402,13.434098609775575,73.75916582951294,0.10153938001512593
0.107498160675036,66.4330039701407,0.34130666014323924,13.392893600380367,73.57442970504819,0.10210356214573936
0.108115840418998,66.2322501162282,0.3432677933303186,13.352421623431606,73.39300550038548,0.10266113197483333
0.108762201401157,65.9963617926968,0.3453199894486735,13.304866537407674,73.17427138573773,0.1032442592270155
0.109432467057371,65.7195131659789,0.3474480829071529,13.249053854261344,72.91136162554135,0.10384859363115431
0.110087280715439,65.4404937359211,0.3495271162715188,13.192803537161693,72.64465973998436,0.10443864350813631
0.1107478423262,65.1484939216884,0.35162439938568496,13.13393637461238,72.36354905431695,0.10503352029424935
0.111357854071453,64.8418800545333,0.35356118667686326,13.072123018993913,72.06253267136469,0.105582559668538
0.111987789416316,64.5039239127538,0.3555612313968033,13.003991060811169,71.72757576042135,0.10614921502737877
0.112580889431075,64.154058112404,0.3574443239436631,12.933458115460647,71.37657903531131,0.10668244201600953
0.113176514223151,63.8147483858076,0.35933543265850443,12.86505327457881,71.03707916414075,0.10721765291124563
0.113796158463048,63.5065070590093,0.3613028031201774,12.802911823096277,70.733303599731,0.107774143130895
0.114421555945289,63.2233386769911,0.3632884401262925,12.745825077281406,70.45745146046839,0.10833548639158197
0.115109539098465,62.9574829408116,0.36547278663762633,12.692228560867619,70.20448978492789,0.10895264143063198
0.115734865070272,62.6186434911753,0.3674581965981136,12.62391852782094,69.86580374650994,0.10951325963153978
0.116371051577347,62.300305485971,0.36947808875807675,12.559741585971754,69.55025754896342,0.1100832921909778
0.116981781479505,61.9559247867308,0.3714171561974283,12.49031443700493,69.2036392414928,0.11063020972979366
0.117596518051755,61.6194270476083,0.3733689448143221,12.422476492797832,68.86565711275117,0.1111804133972032
0.118192514450505,61.2688463378464,0.3752612333803534,12.351799421709835,68.51036534399807,0.11171355530299384
0.118787897692391,60.8227301485736,0.3771515751733414,12.261862397952436,68.04773439483427,0.11224586506548699
0.119397780149659,60.404475231103,0.3790879519751673,12.177542206590365,67.61663548480176,0.1127908444015631
0.119999768974187,60.000970276957,0.3809992664930437,12.096195607834531,67.2010728484189,0.11332847903393455