File: example/data/02 processed data/test_ID_084.csv
Strain,Stress_MPa,Displacement(mm),Force(kN),True Stress (MPa),True Strain
0.00021948053362839042,12.2246477870196,0.0006968506942701396,4.928977987726303,12.227330859239315,0.0002194564512997629
0.00025325149121269044,16.2814613604852,0.0008040734846002921,6.564685220547632,16.28558466485386,0.0002532194284668577
0.00029598191392399314,20.310679431978,0.0009397425767086781,8.18926594697353,20.316691025749375,0.0002959381199186946
0.00036271447620386446,24.4152920418353,0.0011516184619472696,9.844245751267994,24.42414782169962,0.00036264871121045693
0.00044469222396538075,28.7429987421099,0.0014118978110900838,11.589177092818712,28.755780530143962,0.00044459337768137317
0.0005374331735151904,33.2801978952406,0.0017063503259107295,13.41857579136101,33.29808377761066,0.0005372888080295102
0.0006342925286238904,38.1182955773349,0.0020138787783808517,15.369296776781432,38.14247372742347,0.0006340914501417512
0.0007354840174875904,43.2062669589873,0.0023351617555230995,17.42076683786368,43.238044477790936,0.0007352136816612511
0.0008240238565192904,48.5200968118715,0.002616275744448747,19.56330303454659,48.56007852916511,0.0008236845352543896
0.0009386365560607904,53.9604170313632,0.0029801710654930092,21.75684014704564,54.01106625136913,0.000938196312233099
0.0010388964437289903,59.5014399859735,0.003298496208839544,23.990980602344518,59.56325582037167,0.001038357164289845
0.0011472608198540904,65.0454155870764,0.003642553103036737,26.22631156470921,65.12003964389059,0.0011466032190714675
0.0012547130355618904,70.5922302108545,0.003983713887909002,28.462787221016534,70.68080320230943,0.0012539265409755877
0.0013589013030504903,76.1622780486406,0.004314511637185306,30.70863050921189,76.26577506752419,0.0013579788322779258
0.0014715155016214905,81.8021858375346,0.004672061717648232,32.98264132969395,81.92255902206104,0.0014704338836340433
0.0015764556663956904,87.4786459591166,0.005005246740806317,35.271390050715816,87.61655216622748,0.0015752143645619934
0.0016808621497798905,93.314917129255,0.005336737325551152,37.624574586515614,93.47176664146741,0.001679451081982318
0.0017793443825952905,99.1622270939794,0.005649418414740047,39.982209964292494,99.3386708457247,0.001777763224717776
0.0018791304998002905,105.018575881521,0.005966239336865922,42.34348979542927,105.21591949050556,0.0018773671427890063
0.0019739389956631905,110.713674385486,0.0062672563112306295,44.639753512227955,110.93221642470867,0.0019719933380694605
0.0020714798424539905,116.300857513409,0.006576948499791419,46.89250574940651,116.54177239540813,0.0020693372864159752
0.0021651132092005906,121.727803359022,0.006874234439211875,49.080650314357676,121.9913578340016,0.002162772729256862
0.0022523937623400905,127.117876285877,0.007151350195429787,51.25392771846561,127.40419579750522,0.0022498609260930293
0.0023399495171659906,132.393500451142,0.0074293397170020195,53.38105938190045,132.70329455859857,0.0023372160985053354
0.0024274939716363905,137.497563276327,0.007707293359945539,55.43901751301505,137.831337782295,0.0024245523676674507
0.0025187269040635903,142.63828031047,0.007996957920401898,57.51175462118151,142.99754718463737,0.002515560227669111
0.0026111004120273904,147.673777725734,0.008290243808186964,59.54206717901595,148.0593687875993,0.002607697411776401
0.0026954752265513906,152.654806771693,0.008558133844300665,61.55041809034661,153.06628402156008,0.0026918489481037164
0.0027818723329656905,157.572629134847,0.008832444657166066,63.53328406717032,158.01097607226993,0.0027780100873188115
0.0028640472196323906,162.387936896306,0.00909334992233284,65.47481615659058,162.8530236154757,0.0028599536506482073
0.00294822009580829,167.162506057739,0.00936059880419132,67.39992244248036,167.65533791736408,0.002943882618076309
0.0030382117918785903,171.891423448248,0.009646322439214523,69.30662193433359,172.41366599789126,0.0030336057534876147
0.0031233169225166903,176.501931516801,0.00991653122899049,71.16557878757416,177.05320298636428,0.0031184495005847647
0.0032086679861366902,181.071621079537,0.01018752085598399,73.00807761926933,181.6526197932928,0.00320353119624984
0.0032921049843766905,185.622007416121,0.010452433325395992,74.84279339017999,186.23309455194558,0.0032866978707031375
0.0033718487316649905,190.249353266571,0.010705619723036344,76.70853923708144,190.89084530708297,0.003366176796093378
0.0034558823959478903,194.930220910057,0.010972426607134551,78.59586507093498,195.60387682893827,0.0034499245568289623
0.0035394134802439903,199.488360563612,0.011237637799774668,80.43370697924836,200.1944323561426,0.003533164497167652
0.0036302028656961904,204.01314246304,0.011525894098585404,82.25809904109772,204.75375155744902,0.0036236295827038324
0.0037162350078041905,208.286922962571,0.011799046149778305,83.98128733850864,209.0609661173523,0.0037093468665143044
0.0038145136108889903,212.461144507981,0.012111080714572543,85.66433346561794,213.27158043549173,0.003807256802121407
0.003915175674611391,216.438547920101,0.012430682766891165,87.26802252138472,217.285942857966,0.0039075313204931204
0.0040228793629663905,220.161527672816,0.01277264197741829,88.76912795767942,221.0472109390101,0.004014809220016047
0.00415125470466229,223.665237001248,0.013180233687302772,90.1818235589032,224.59372836861883,0.004142662018927161
0.0043034974739878905,226.933457405401,0.01366360447991155,91.49957002585768,227.91006496610848,0.0042942639103336015
0.00450840572791309,229.977070789121,0.01431418818612406,92.7267549421736,231.01390073235532,0.004498273309430778
0.00477241289858539,232.674452035691,0.015152410953008613,93.81433906079062,233.7848705917574,0.004761061038994726
0.005085603489876291,235.051786556253,0.01614679108035722,94.77288033948122,236.24716674226514,0.00507271548550009
0.005445193311549291,236.990715308992,0.017288488764168997,95.55465641258557,238.28117556689182,0.005430421844516697
0.0058226064356580905,238.537282789189,0.018486775433214437,96.178232420601,239.92619150710172,0.005805720577570612
0.006213028679272791,239.600601963319,0.01972636605669111,96.60696271161024,241.08924737488812,0.006193807390449051
0.00661349307888469,240.309723039885,0.020997840525458892,96.89288032968163,241.89900972999794,0.006591719878750304
0.00700232824716839,240.801869438931,0.02223239218475964,97.09131375777697,242.48804317127414,0.006977925796481613
0.00739693340470199,241.153089099963,0.023485263559928818,97.23292552510509,242.93688244037358,0.007369710255593806
0.00777280643144539,241.468461232995,0.024678660419839113,97.3600835691436,243.34534884145802,0.007742753799938453
0.008144454298123192,241.748534506257,0.02585864239654113,97.47300911292281,243.71744439718148,0.008111467217029716
0.008510617671351889,242.020474512848,0.027021211106542247,97.58265532358031,244.08021824006602,0.008474606538514999
0.008869142853392891,242.259415883979,0.028159528559522428,97.67899648442034,244.40804925103353,0.008830043023832288
0.00921830953559349,242.477302970383,0.029268132775509333,97.76684855765843,244.7125338045199,0.009176080243647964
0.00955793844774639,242.66762461377,0.030346454571594787,97.84358624427206,244.98702683308923,0.009512550336057995
0.009896343630023192,242.853741229049,0.03142089102532363,97.91862846355257,245.2571053040884,0.009847695517058231
0.01023517712414379,243.046901558092,0.032496687369156535,97.9965107082227,245.5345296450134,0.010183152385897657
0.010576320658827191,243.291923665085,0.03357981809177633,98.09530362176227,245.86505706346983,0.01052078262830113
0.01092266683986819,243.495913980876,0.0346794672165815,98.17755251708921,246.15553872615828,0.01086344536181888
0.01126740181772139,243.716575911757,0.03577400077126541,98.26652340762043,246.46262850219398,0.011204397467692674
0.011610660159866289,243.869573543411,0.03686384600757547,98.32821205270331,246.70106028515505,0.011543773678143835
0.01195668817276399,244.074194310903,0.037962484948525665,98.4107151461561,246.99251334329708,0.01188577170114569
0.01231016769917909,244.207041560976,0.03908478244489361,98.46427915738552,247.213271195912,0.012235013728186273
0.01265751244007499,244.416879250493,0.04018760199723809,98.54888571379877,247.5105889401704,0.012578075741184592
0.01299833581914029,244.611828047308,0.04126971622577042,98.62748906867459,247.79137473360072,0.012914582441051125
0.01333494438975839,244.803491526994,0.042338448437482884,98.70476778368399,248.06793247292515,0.013246816607070978
0.01366401591904529,245.060527860158,0.04338325054296879,98.8084048332157,248.40903881396886,0.013571505014535966
0.01400550817643369,245.250063653621,0.044467488460176965,98.88482566513999,248.68491542539266,0.013908337280897874
0.01434895748292099,245.457086056285,0.04555794000827414,98.96829709789411,248.9791393479883,0.01424698549607361
0.014700670249584092,245.663158656918,0.046674628042429486,99.05138557046934,249.27457174480458,0.014593662842333113
0.01505028047974849,245.89566943354,0.04778464052320145,99.14513391560332,249.59646822727032,0.014938148685284734
0.015393752711266091,246.107110631155,0.048875164858269836,99.23038700648169,249.89562263269522,0.015276470972606352
0.015739916135157992,246.272072979167,0.04997423372912662,99.29689982520014,250.1483747542906,0.015617328329808116
0.01607440849971729,246.437700668454,0.05103624698660239,99.36368090952065,250.3990409387298,0.01594658318693325
0.01641578788303159,246.581047160465,0.05212012652862529,99.42147821509948,250.628869326627,0.01628250548277705
0.016751865568054292,246.77235055857,0.053187173178572376,99.49861174521543,250.90624780103994,0.016613100638088723
0.017089022863293193,246.980183140779,0.05425764759095588,99.58240984236208,251.2008331372521,0.01694464800764463
0.01741827785190379,247.164785526109,0.05530303217979453,99.65684152412716,251.46997043560899,0.017268318501596082
0.01775109164050759,247.414926626803,0.0563597159586116,99.75769841592697,251.8068116625849,0.017595381002201226
0.018086150277440892,247.607591616987,0.05742352713087483,99.83538093996917,252.08585972880707,0.01792454153926148
0.01842464084207409,247.842303437808,0.05849823467358523,99.93001674612418,252.40870886412196,0.01825696361060643
0.01876701196824309,248.076991554903,0.05958526299917181,100.0246429949369,252.7326554244596,0.018593084298043974
0.01909507757205819,248.279283002041,0.06062687129128475,100.10620690642294,253.0201951705,0.018915054669182516
0.01941558448763939,248.463539187797,0.061644480748255064,100.18049900051976,253.28760402499557,0.01922950670927958
0.019736408080323092,248.588965791536,0.06266309565502581,100.2310710071473,253.49521906466322,0.01954417044842227
0.020062870917112292,248.726228370069,0.06369961516183152,100.28641527881182,253.71639058355788,0.019864263550658352
0.02038656186985549,248.855865121407,0.06472733393679118,100.3386848169513,253.92918061238097,0.02018153772590366
0.02071373822126819,249.042870875155,0.0657661188525265,100.4140855368625,254.20147970833602,0.020502125944130978
0.02103409275389799,249.25604388912,0.06678324449362612,100.50003689609319,254.4989186357534,0.02081593015677525
0.02135457143058429,249.42649070473,0.06780076429210512,100.56876105214715,254.75288651716414,0.02112975747567551
0.021679016358128092,249.693684991118,0.06883087693705668,100.67649378841878,255.10679847256176,0.021447368436367045
0.02199700213817159,249.973700329072,0.0698404817886948,100.78939597268183,255.47237234969728,0.02175855844861134
0.02231875170479029,250.201798184517,0.07086203666270917,100.88136502799726,255.78598999428928,0.02207333327600324
0.02263693386914219,250.441255260132,0.07187226503452646,100.97791412088523,256.1104773935606,0.02238452062266717
0.02295619374306659,250.600724073108,0.07288591513423642,101.04221194627715,256.3535628470831,0.022696664687102363
0.02328135046068469,250.768428799357,0.07391828771267389,101.10983049190074,256.6066564747101,0.023014474045332533
0.023608380710230092,250.942414836393,0.07495660875498053,101.17998166203367,256.86675890219504,0.02333401275555003
0.02393336646131119,251.112293565013,0.07598843851466303,101.24847676541326,257.12225610984484,0.023651452684927927
0.02425756606485099,251.335247760118,0.0770177722559019,101.33837189687958,257.4320291370847,0.023968024349316046
0.02458090017320219,251.554816495067,0.07804435804991695,101.426902010811,257.73826032742045,0.024283651097215975
0.02490579397815129,251.777338036995,0.07907589588063034,101.5166226965164,258.0480525465117,0.024600700052544756
0.025228882340627493,251.973822536735,0.08010170143149228,101.59584524681155,258.3308404584325,0.024915887507186665
0.02555714520743709,252.176736668071,0.08114393603361277,101.67766022456622,258.6216541450345,0.0252360212170945
0.025878310138457893,252.360688524949,0.0821636346896038,101.75182961325943,258.8913566893524,0.02554913361145019
0.026195264157279092,252.586687372951,0.08316996369936111,101.84295234877384,259.2032623712975,0.025858044583563368
0.02650728446004619,252.794171364349,0.08416062816064665,101.92660989410551,259.49505837454547,0.02616205385697749
0.02681962105033429,252.912683172421,0.08515229683481136,101.97439385512014,259.6957054939286,0.026466278763258827
0.02713411546225019,253.07873441535,0.08615081659264434,102.04134571626912,259.9458020160163,0.02677251196489629
0.02745139378844309,253.274916158972,0.0871581752783068,102.1204461952975,260.22766561918684,0.027081360953937036
0.027769693153627692,253.458904157212,0.08816877576276792,102.19463015618788,260.49738015271254,0.027391108036381742
0.028089492191784693,253.669362797681,0.0891841377089164,102.27948708002498,260.79480638328147,0.027702217905205398
0.028413342218083292,253.839854806042,0.09021236154241445,102.34822945779614,261.05229346923466,0.02801717008864694
0.02873739104764969,254.056797338294,0.09124121657628777,102.43570068680015,261.357726871718,0.028332216358233825
0.029060048619812793,254.252919878772,0.09226565436790561,102.51477729512088,261.64152209217843,0.028645811436726554
0.02937915570147959,254.435231620782,0.0932788193521977,102.5882853894993,261.91032390651094,0.028955859052952698
0.02969942179222259,254.635795745169,0.09429566419030672,102.66915284445214,262.198331646403,0.029266936150083755
0.030019836968557992,254.810023232817,0.09531298237517162,102.73940136747183,262.45937858822066,0.02957806124886332
0.03034214641882139,254.991353332449,0.09633631487975791,102.81251366364344,262.7283383107956,0.02989092807080164
0.030662269528601592,255.129894692482,0.09735270575331005,102.86837354000875,262.9527562883466,0.03020157574324485
0.030973427499714393,255.33713944797,0.09834063231159319,102.95193462542152,263.2458058246462,0.03050343118154945
0.03128994384472229,255.482505362607,0.09934557170699328,103.01054616220314,263.4765386087119,0.030810391341819184
0.03160352629195029,255.729776900213,0.10034119597694216,103.11024604616588,263.81173962811346,0.031114413293687197
0.031927373622105494,255.878987472503,0.10136941125018493,103.17040774891322,264.0485315075837,0.03142829018579234
0.03225040315072659,256.072127114949,0.10239503000355692,103.24828165274745,264.3305564500703,0.03174127633930399
0.03257038904552109,256.232061512752,0.10341098521952946,103.31276720194161,264.5776394421582,0.03205121693905517
0.03288213116559889,256.403794283569,0.10440076645077648,103.38200985513504,264.83489747855856,0.032353080205719
0.03319570122846029,256.592147265931,0.10539635140036142,103.45795377762337,265.1099035241399,0.03265662159254627
0.03350663305750619,256.779491403604,0.10638355995758214,103.53349093393315,265.38330759875765,0.03295751817182974
0.03382516029869799,256.988554541384,0.10739488394836612,103.61778519108604,265.68123359367706,0.03326567116859212
0.03415183672942239,257.167158022468,0.10843208161591608,103.6897981146591,265.94988881542093,0.03358160933803129
0.03448674769856099,257.279644205439,0.10949542394293114,103.73515254363302,266.15238238312753,0.03390540777685563
0.03482035056273879,257.415760579642,0.11055461303669566,103.79003466571164,266.3790676033991,0.03422783731604587
0.03514990116424919,257.581995514409,0.11160093619649117,103.85706059140972,266.63597719843057,0.03454624827293742
0.03546761986351819,257.746255898329,0.11260969306667026,103.92329037820626,266.88790212377603,0.03485313131486676
0.035787459144983894,257.915514783348,0.11362518278532385,103.99153556064591,267.1456557315145,0.03516196752461153
0.03610783677777789,258.056964560038,0.11464238176944479,104.04856811060732,267.3748433157407,0.03547122797418922
0.03642923263132169,258.210625462702,0.11566281360444636,104.11052418656145,267.61704040556185,0.03578137524331543
0.03675078747463929,258.355329695137,0.11668375023197974,104.16886893307925,267.85009150970336,0.03609157970484582
0.03707072925779659,258.472369015569,0.11769956539350418,104.2160591870774,268.05412822796643,0.036400132570282025
0.03739326528375729,258.608743562985,0.1187236172759294,104.27104540459555,268.2789689157348,0.03671109099559894
0.037712017508079294,258.764357832395,0.11973565558815176,104.33378907802165,268.5228838254372,0.03701830646989081
0.03803115100985799,258.951354647093,0.12074890445629911,104.40918619370791,268.79957271988394,0.03732579490018736
0.03835223185323769,259.10836008608,0.12176833613402965,104.47249078670745,269.04574398721354,0.037635064227411544
0.03867216007354799,259.235849908969,0.12278410823351486,104.52389468329629,269.26106019345093,0.03794312822905165
0.03900023995493419,259.367564676231,0.12382576185691606,104.57700207745633,269.48296193513096,0.038258943065027376
0.03931641113449409,259.526283154751,0.12482960535201873,104.64099736799561,269.7299252034703,0.03856320005284795
0.039633297916358494,259.701270220827,0.1258357208844382,104.71155215303745,269.99408803274576,0.03886805281858725
0.03995224678356189,259.867220389914,0.126848383537809,104.77846326121333,270.2494997098901,0.039174795544816544
0.040269861379622095,259.961469934149,0.12785680988030015,104.81646467744889,270.43008229244003,0.03948016158941543
0.04059337843079519,260.04246054181,0.12888397651777472,104.84912009045779,270.59846255065884,0.039791106631444424
0.04091841879875089,260.191440945627,0.12991597968603408,104.90918898927681,270.8380632940906,0.040103418453102294
0.04123912540250889,260.361898898939,0.1309342231529657,104.97791763605221,271.0989958976677,0.04041147065327068
0.04156755475060539,260.59168766295,0.13197698633317212,105.07056846570144,271.42384690743233,0.04072684255403152
0.041894729676276894,260.749213749378,0.13301576672217913,105.13408298374921,271.6732315727099,0.0410409110455097
0.04222187904503439,260.883489770808,0.13405446596798418,105.1882230755898,271.89848092075755,0.041354856407372444
0.04254965761922129,260.95894481225,0.13509516294102758,105.2186465482992,272.0626585666845,0.04166930676428033
0.04288708307948129,261.039858194232,0.13616648877735307,105.25127082391435,272.23509627966405,0.04199290848915589
0.043224590830114394,261.135297241817,0.13723807588561318,105.2897518479006,272.42276361639483,0.04231648441061689
0.043564886253358893,261.249214844158,0.1383185138544145,105.33568342516452,272.6305071726231,0.042642626965961335
0.04390403195865749,261.441639314546,0.13939530146873752,105.41326897162497,272.9199814023356,0.04296756182398361
0.04423583873244779,261.578009897968,0.1404487879755217,105.4682535908607,273.14913255976916,0.04328536311808287
0.04457656443529529,261.699137429027,0.14153059208206253,105.5170922113837,273.36478589129325,0.043611601803139395
0.04491244687137099,261.84501333486,0.1425970188166029,105.57590937661557,273.6051135847954,0.043933099008581764
0.04524358655426379,261.977947038534,0.14364838730978752,105.62950824593692,273.83076896068025,0.044249955434961026
0.04557261454983989,262.149192575016,0.14469305119574166,105.69855444624646,274.09601668278896,0.044564691850451255
0.045897463579291795,262.231880606959,0.14572444686425143,105.73189426072588,274.2676587964461,0.04487533366690479
0.04622591145654529,262.278964952749,0.1467672688745313,105.75087866894839,274.4030491635691,0.0451893188590509
0.04655855503083849,262.360875399777,0.1478234122229122,105.78390496119009,274.57601865501647,0.04550721454532084
0.04689528336987969,262.466755882381,0.148892524699368,105.82659597177603,274.77520877465827,0.045828911002886295
0.047230101703032094,262.581317818429,0.14995557290712688,105.87278734439059,274.9830601643096,0.04614868014220528
0.04757349790889119,262.740681256549,0.15104585586072952,105.93704268264057,275.2401745068881,0.04647653542085628
0.04791637871039909,262.868714018332,0.1521345024055171,105.98866549219147,275.46443087035,0.046803791408483675
0.04825518496203419,263.011818080769,0.15321021225445855,106.04636505016606,275.7035020094574,0.047127053359420544
0.04859116757669149,263.135914018008,0.15427695705599548,106.09640053206084,275.92199531150294,0.047447518058348785
0.04892270932653729,263.25121962836,0.1553296021117559,106.14289175415476,276.13018252609464,0.04776364636267861
0.049261147131554495,263.295547746006,0.1564041421426855,106.16076485118961,276.2657884626052,0.04808624707939916
0.04959934326752229,263.356826033627,0.15747791487438328,106.1854722567584,276.419151649914,0.04840851350962819
0.049943719188868994,263.465473737641,0.15857130842465905,106.22927901101684,276.6239193739561,0.048736561960353524
0.05028564297410129,263.616277787678,0.15965691644277158,106.29008320399177,276.8723918146706,0.04906216810072381
0.050625995564671095,263.804057435171,0.16073753591783072,106.36579595786094,277.1594004768262,0.0493861727730803
0.05097248711678729,263.917070476377,0.16183764659579963,106.4113628160752,277.36957995113437,0.04971591373750437
0.05131776893724659,263.954359791119,0.1629339163757579,106.42639786777919,277.4999086368585,0.050044395328064546
0.05167327640235609,264.010279672594,0.16406265257748057,106.4489447639899,277.6525558271793,0.050382492315480566
0.05202222646485189,264.11845479461,0.16517056902590474,106.49256097318676,277.858484863482,0.05071424191062929
0.05237344753268239,264.193160592897,0.16628569591626657,106.52268235105609,278.02986722770265,0.05104803947107038
0.05271649949599609,264.347849261506,0.16737488589978758,106.58505282223922,278.2833425238678,0.05137396565473266
0.053059171812232395,264.432308717649,0.16846287050383785,106.61910687495607,278.462868018604,0.051699425126916776
0.05340881847971609,264.531295412154,0.16957299867309858,106.6590183101805,278.6595993510259,0.05203139947668734
0.05375794750470309,264.584503792827,0.1706814833274323,106.68047192926784,278.8080236582797,0.052362772421456365
0.05411223996651089,264.626559225493,0.17180636189367207,106.69742867971878,278.94609509981495,0.05269893398135684
0.05447049122689609,264.74475988405,0.17294380964539507,106.74508718524896,279.16553700468086,0.0530387368816961
0.05482342447007459,264.846622208,0.1740643726924868,106.78615807426559,279.36642099677465,0.053373382749534286
0.05519048397156809,264.962749617055,0.17522978660972868,106.83298064559658,279.58617200285767,0.053721304157756
0.05555137804027089,265.029383919586,0.17637562527786008,106.85984759637708,279.75213141748304,0.05406326361638521
0.05592167699156479,265.136048968229,0.1775513244482182,106.90285494398994,279.96290145744996,0.054414013017811465
0.05628315016199129,265.264128864638,0.17869900176432235,106.95449675822205,280.19402966211624,0.05475628396550423
0.05663762267056989,265.343922153299,0.17982445197905939,106.98666941221016,280.3723710941466,0.055091812411683275
0.056996634799890894,265.443170519604,0.18096431548965358,107.02668635350435,280.572537969835,0.055431523155398565
0.05735665152885789,265.437603113039,0.1821073686041238,107.02444157517733,280.6622152174489,0.05577206864018028
0.057716073784226794,265.526322034011,0.18324853426492005,107.06021304411324,280.85145882818034,0.05611193615823493
0.05807842670398599,265.601654191616,0.1843990047851555,107.09058697005956,281.02738039704116,0.056454458008271126
0.05844215480397389,265.692519415144,0.18555384150261708,107.12722382818606,281.2201627650617,0.05679816182740384
0.05881025577682659,265.763609119395,0.1867225620914244,107.15588719694007,281.39323494787925,0.057145877550594824
0.05917879208447749,265.789467107778,0.187892664868216,107.16631313785611,281.5185667199933,0.057493883421297895
0.05955013551877059,265.850708949115,0.18907168027209661,107.19100584828318,281.68215469479605,0.057844417586624626
0.05992391299057359,265.961708922926,0.19025842374507115,107.23576103772378,281.89917522724767,0.05819712535008197
0.060314451080101195,266.04641207648,0.19149838217932127,107.26991334923675,282.0928553827033,0.05856551609384215
0.06070850869453939,266.139350501363,0.19274951510516256,107.30738612214957,282.29627357523407,0.058937089270036186
0.06110283154457139,266.15927755116,0.19400149015401416,107.31542070862771,282.42236305139335,0.059308774393113384
0.06148926823042939,266.313442731732,0.1952284266316133,107.37758010943433,282.68886144523253,0.05967289210576143
0.06187138875711999,266.325234428545,0.19644165930385596,107.38233452158934,282.80314654370466,0.06003281262096768
0.06225710509424269,266.374216757494,0.19766630867422053,107.4020841966216,282.9579043645619,0.06039598871175378
0.06265226664560698,266.376794397243,0.19892094659980217,107.40312350096838,283.0659043480211,0.06076792133266949
0.06305092419503529,266.432831914677,0.20018668431923703,107.42571782799779,283.2316682027979,0.06114300432244881
0.06345185440475029,266.529058721965,0.20145963773508216,107.46451647669629,283.44082175062624,0.061520083739885205
0.06385398321455259,266.600423803487,0.20273639670620444,107.49329087756597,283.62392279002745,0.06189814768112103
0.06425564341146939,266.668801525478,0.2040116678314153,107.52086077507272,283.803776945263,0.06227562842427525
0.06465797107466979,266.715408506798,0.20528905816207657,107.53965270994095,283.9606856751993,0.06265359365992632
0.0650689553124363,266.780669598092,0.20659393311698523,107.56596598195071,284.1398090663921,0.0630395438376474
0.06547868200635779,266.833150866576,0.20789481537018595,107.58712642940344,284.305033900923,0.06342416485413685
0.06589430105002829,266.864058133708,0.2092144058338398,107.59958823951106,284.44887871980285,0.06381416609018763
0.0663066164993527,266.928314408501,0.2105235073854448,107.62549636950762,284.6274277848041,0.06420091712389187
0.0667190226263104,266.951011536352,0.21183289683853548,107.63464785145712,284.7617221151623,0.06458760364517115
0.0671354629339144,266.974599872935,0.2131550948151782,107.6441586687674,284.8980632270011,0.06497792108781698
0.0675531784358127,266.980004274258,0.2144813415337053,107.64633772338084,285.015352141791,0.06536928074480357
0.06797613234021059,266.959266098052,0.2158242201801686,107.63797609073458,285.1061244997787,0.06576539229222543
0.068406032990999,267.016046310828,0.2171891547464218,107.66086987252585,285.28155478389266,0.06616784899081371
0.06884332686968599,267.066674163009,0.21857756281125298,107.68128302252522,285.4524325084129,0.0665770608432086
0.06928995581143339,267.149353416389,0.219995609701301,107.71461929748804,285.66012030966357,0.06699483549913043
0.06974231124410459,267.223201435098,0.22143183820003204,107.74439481863152,285.8599651212307,0.0674177888564796
0.070200119396734,267.269517776964,0.22288537908463044,107.76306956767189,286.03186983601444,0.06784565845994052
0.0706683125946368,267.298889180686,0.22437189248797182,107.77491211765259,286.18845063750587,0.06828304470784857
0.07114713172616709,267.279097291877,0.2258921432305805,107.76693202808481,286.29523843455326,0.06873015992571367
0.07163438743707119,267.333943540618,0.22743918011270103,107.78904603557717,286.48424682728677,0.06918494798034722
0.07213390117833439,267.345944237851,0.22902513624121168,107.79388471670151,286.6306501599326,0.06965096266388904
0.07264041913022189,267.384007285853,0.2306333307384545,107.80923173765592,286.80689364381567,0.07012329017779861
0.07315498264280079,267.384213574066,0.2322670698908925,107.80931491306342,286.94470107703575,0.07060289184160776
0.07367751995040249,267.397305717937,0.2339261258425279,107.8145936654722,287.0984760446542,0.07108969024557212
0.07421547014052819,267.398252021382,0.235634117696177,107.81497521502122,287.24333900990433,0.07159059993134843
0.07475823283597739,267.395966946914,0.2373573892542282,107.81405387299571,287.3860169033327,0.07209573659843617
0.07529877256553029,267.38727880122,0.23907360289555865,107.81055081265191,287.5212126945891,0.0725985509327382
0.0758543105167121,267.386319289808,0.2408374358905609,107.8101639376506,287.6687241811378,0.07311505342426333
0.07641160570189579,267.361608131649,0.2426068481035191,107.80020039868089,287.79113791202934,0.07363292177262977
0.0769882013850579,267.338860723655,0.2444375393975588,107.79102864377771,287.92079877109967,0.0741684430400175
0.07757119614058519,267.307739834117,0.24628854774635797,107.77848070111597,288.0431209506858,0.07470961611737642
0.07816394060803349,267.263215795629,0.2481705114305063,107.76052860879761,288.1535619217905,0.07525953941016109
0.07877649231407609,267.236125502381,0.25011536309719157,107.74960580256003,288.28805008906284,0.07582752145840009
0.07940037025246999,267.11307057115,0.2520961755515922,107.69999005428768,288.32194727377345,0.07640567421927255
0.08004659352560418,266.985295982581,0.25414793444379324,107.64847134017668,288.3565594474118,0.07700418235886969
0.0807108190220157,266.813017560664,0.2562568503948998,107.57900868045972,288.3477147337206,0.07761899040115766
0.08137365585287729,266.566289122437,0.25836135733288534,107.4795277741666,288.2577625954648,0.07823213651948038
0.08205381602310319,266.265748893663,0.2605208658733526,107.35834995392491,288.1138696666374,0.07886091673187684
0.08274311375294699,265.8574416578,0.2627093861656067,107.19372047642496,287.85531419495885,0.07949774113203918
0.08344480424623879,265.379470889177,0.26493725348180813,107.00100266251617,287.5240088884948,0.08014559860738009
0.08414851723778329,264.868610679508,0.2671715422299619,106.79502382597762,287.1569115310203,0.0807949021545845
0.0848537547763516,264.234692826401,0.2694106714149163,106.5394281476049,286.65599865489696,0.08144518968311294
0.08555656192008369,263.518705019611,0.2716420840962657,106.25074186390715,286.06445942272165,0.08209281576827297
0.08628900028704749,262.690795634301,0.27396757591137577,105.91692879975017,285.358121774194,0.08276730055437055
0.08704619197524019,261.777712904675,0.2763716595213876,105.54877384316497,284.56446595701465,0.08346410215361316
0.08778462583391039,260.837072692119,0.2787161870226655,105.1695077094624,283.73455752200914,0.08414317464145923
0.08852409785960239,259.842008035171,0.28106401070423753,104.76829763978094,282.84428738251205,0.08482274004144078
0.08926360631807559,258.737902965902,0.28341195005989,104.32312247585169,281.8337812758147,0.085501877393055
0.09000259780492369,257.502475035249,0.2857582480306327,103.8249979342124,280.6783667296189,0.08618007954548171
0.09076404246082369,256.356640527749,0.2881758348131152,103.36299746078839,279.6246055337237,0.08687840707194372
0.09151344096251529,255.110199720937,0.29055517505598605,102.8604325274818,278.45621192203447,0.08756521114414975
0.09228083768099159,253.849287877828,0.2929916596371483,102.35203287234026,277.2747128079172,0.08826802162182938
0.0930388330218752,252.587279003181,0.29539829484445373,101.84319089408258,276.0877046778078,0.08896173740304326
0.09382398787998159,251.175485884355,0.2978911615189415,101.27395590857193,274.7417716277172,0.08967980246349293
0.0946171258270374,249.845800288895,0.3004093745008437,100.73782667648246,273.48549181218624,0.09040464534531793
0.09543016226940199,248.431483485584,0.3029907652053513,100.16757414138748,272.1393402674416,0.09114712838130962
0.09624534855898939,247.018576018823,0.3055789816747913,99.59788985078944,270.7929649682998,0.0918910216475818
0.09706811831746279,245.54592691423,0.30819127565794435,99.00411773181753,269.38060800031155,0.09264127445867548
0.09789188798665019,244.020997083982,0.31080674435761435,98.38926602426154,267.90867319691785,0.09339187556803281
0.0987162520479329,242.39145236071,0.3134241002521869,97.73223359183827,266.31942806621436,0.09414245468586456
0.099528565922828,240.731654236859,0.31600319680497885,97.06300298830155,264.6913305552836,0.0948815115054039
0.10038189171478949,239.014190757857,0.3187125061944566,96.37052171356794,263.0068873728102,0.09565729383944922
0.10125530059696349,237.265444988931,0.32148557939535904,95.66542741953697,261.2898289425575,0.09645071151157289
0.10215967814918349,235.500039528997,0.32435697812365755,94.95361593809159,259.55864777139936,0.09727159873593025
0.1030466707219285,233.68945486409,0.32717317954212294,94.2235882012011,257.77037517065685,0.09807605190742895
0.10392025960566449,231.795632391659,0.3299468242479847,93.45999898031693,255.8838946852594,0.09886771662823383
0.10478505359475149,229.805052771167,0.33269254516333596,92.65739727733454,253.88518754213842,0.0996507944142202
0.10561879816042949,227.757707253218,0.3353396841593636,91.83190756449751,251.81320256507783,0.10040517656439231
0.10646367900155149,225.679924514462,0.33802218082992597,90.99414556423108,249.70663955506402,0.10116905484734753
0.10731663069529249,223.511417570891,0.34073030245755365,90.11980356458325,247.4979098265276,0.10193963875055757
0.1081708911824425,221.267630675686,0.3434425795042549,89.2151086884366,245.20234747570248,0.10271081035143582
0.10902554217233248,219.021421474762,0.3461560963971556,88.30943713862403,242.9003506984029,0.10348173981836255
0.1098766549109565,216.643953735089,0.34885837934228686,87.3508421459879,240.4480666781846,0.104248887447928
0.11078897711397949,214.26779295819,0.35175500233688484,86.39277412074222,238.00630256849777,0.10507055302530659
0.1117905333046885,211.75698928974,0.35493494324238595,85.38041808162318,235.42941605343523,0.10597180875434392
0.1128668529756855,209.012044118208,0.3583522581978014,84.27365618846146,232.60257577184527,0.10693943618463042
0.11341885287176749,207.655271554762,0.3601048578678618,83.72660549088005,231.20729424727847,0.1074353293271358
0.1137069891471675,206.939472893111,0.3610196905422568,83.43799547050236,230.46993729148855,0.10769408100750476