File: example/data/02 processed data/test_ID_127.csv
Strain,Stress_MPa,Displacement(mm),Force(kN),True Stress (MPa),True Strain
0.0007805642201996,-0.843259542320858,5.41408778473721e-06,-0.1700011237318849,-0.8432609802676887,1.7052230452663527e-06
0.0007698739101063,-0.801126619655966,-2.852764676176604e-05,-0.1615071265226427,-0.8011194214647166,-8.985125960338656e-06
0.0007478271200035,-0.767907704370763,-9.852620533788484e-05,-0.1548101932011458,-0.7678838747543342,-3.1032357195589943e-05
0.0007208937311401,-0.713825590326714,-0.0001840397149793,-0.1439072390098655,-0.7137842132375207,-5.796694461134895e-05
0.0006790019539966,-0.403685419249949,-0.0003170461074099,-0.0813829805207897,-0.4036451084182037,-9.986202775021868e-05
0.0006418775497682,0.162475837589035,-0.000434916090835,0.0327551288579494,0.1624535814138729,-0.0001369908287474
0.0006025758687975,1.05245020646354,-0.000559698927917,0.2121739616230496,1.0522646772502349,-0.0001762986665996
0.0005565956509762,2.25493701767558,-0.0007056861194996,0.4545953027633969,2.254435827831889,-0.0002222880488821
0.0005241025180265,3.78580634677459,-0.0008088518166149,0.7632185595097574,3.7848418880845296,-0.0002547889336178
0.0005166513905405,5.6330543023798,-0.000832509146383,1.1356237473597677,5.631577272701437,-0.0002622419875845
0.0005240794473443,7.75635323058755,-0.0008089250660309,1.56368081128645,7.75437707041457,-0.0002548120101791
0.0005512833536816,9.93230944643094,-0.00072255266341,2.0023535844004776,9.930049094731938,-0.0002276015412847
0.000577432309645,12.1580396467775,-0.0006395297282262,2.451060792790344,12.155590693142518,-0.0002014469751349
0.0006156696581188,14.3833911518823,-0.0005181261468218,2.899691656219472,14.381043935808044,-0.0001632026544104
0.0006583500364098,16.6060936141596,-0.0003826159457479,3.3477884726145755,16.604092431100273,-0.0001205162210787
0.0007114173458289,18.8203879355904,-0.0002141272383423,3.7941902078150247,18.8191186575768,-6.744392416192626e-05
0.0007473146969734,21.0428446928076,-0.0001001531484586,4.242237490070012,21.04218091102854,-3.154479625894706e-05
0.0007939925955471,23.2951228643796,4.8049179512986426e-05,4.696296769458928,23.29547540344741,1.5133485334850488e-05
0.0008351352423864,25.5784104857964,0.0001786770832276,5.156607553936555,25.57984994273473,5.6274663237240895e-05
0.0008738261638458,27.8773424946247,0.0003015207588614,5.620072246916339,27.87998992689684,9.49626590493502e-05
0.0009055947565668,30.1904001429901,0.0004023860407505,6.086384668826804,30.19422634632308,0.0001267277305682
0.0009499691292418,32.4730924699561,0.0005432746739936,6.546575441943149,32.47864894514513,0.0001710954958721
0.0009877662596651,34.7221850783108,0.0006632805630876,6.999992511787458,34.72943879499439,0.0002088854458807
0.0010329105756301,36.9417277546678,0.0008066137662764,7.447452315341029,36.9511128589692,0.0002540193142916
0.0010746582145775,39.1241477949021,0.0009391625199344,7.887428195452263,39.13572068725906,0.0002957554789133
0.001112664089826,41.3162978679909,0.0010598311738484,8.329365650186965,41.33008945868964,0.0003337493936001
0.0011588506517824,43.4624218174808,0.00120647350806,8.76202423840413,43.47893717512456,0.0003799194775367
0.0012102568211031,45.5613245100055,0.0013696880956532,9.18516302121711,45.58097956632158,0.0004313048001137
0.0012601926557458,47.6526115311775,0.0015282343706438,9.606766484685384,47.67554833709652,0.0004812178561578
0.0013051013093998,49.7365635738737,0.0016708193459952,10.026891216492938,49.76273705816428,0.0005261038967714
0.0013587681598633,51.8108075916907,0.0018412115962168,10.445058810484843,51.84085315381579,0.0005797410818219
0.0014091445537967,53.8483231714824,0.0020011566469554,10.855821951370851,53.88226299190508,0.0006300870115767
0.0014618402728368,55.8295991337134,0.0021684655549077,11.255247185356623,55.86772970463175,0.0006827481515647
0.00151275724334,57.8228314908318,0.0023301269362554,11.65708282855169,57.86526756553648,0.0007336290760088
0.0015668757536053,59.7941185985166,0.0025019532063477,12.054494309460948,59.84123736599638,0.0007877064357148
0.001615324732371,61.7488162829597,0.0026557787139288,12.448561362644677,61.80046705206036,0.0008361160941684
0.0016651416707774,63.6856542219461,0.0028139474933691,12.839027891144337,63.74209771393394,0.00088589015849
0.0017158683513692,65.6030455006339,0.0029750047042481,13.225573972927794,65.66451616802834,0.0009365706364369
0.0017599504165704,67.5064952133948,0.0031149652612619,13.609309435020393,67.57272525670166,0.0009806104652304
0.0018050863389767,69.4035230202701,0.0032582718149019,13.991750240886452,69.4747468133132,0.0010257011319736
0.0018584903504861,71.2592398666369,0.0034278295514442,14.365862757114002,71.33617357631512,0.0010790489719892
0.0019095701879932,73.0888540233042,0.0035900080355293,14.734712971098126,73.1714964085802,0.0011300724198585
0.0019536744412919,74.8947943317564,0.0037300390397526,15.098790537282092,74.98278189293175,0.0011741258899401
0.0020029185538704,76.666845641354,0.0038863890971894,15.456036081296968,76.76069042655604,0.0012233110080532
0.0020419382218676,78.3948243391295,0.0040102765430805,15.804396586768508,78.49384321319128,0.0012622822126582
0.0020887771035698,80.0931965802804,0.004158989992485,16.14678843058453,80.19811210879806,0.0013090609136324
0.002135801029419,81.7399120303314,0.0043082909570562,16.47876626531481,81.8508283527978,0.0013560222198724
0.002178548995136,83.3567026376634,0.0044440157482077,16.80471125175294,83.47337618073126,0.0013987113464889
0.0022129345354074,84.9646752360085,0.0045531898385694,17.128878527579314,85.0865209985036,0.0014330482354174
0.0022567784463149,86.5525632315527,0.0046923942557007,17.448996747481026,86.68048094825315,0.0014768284025184
0.0023021652904434,88.1325966141847,0.0048364974858087,17.767531477419638,88.26684955337913,0.0015221472406227
0.0023539988856123,89.7093692143526,0.0050010691504699,18.085408833613485,89.85067402030096,0.0015739006582135
0.0023998482855995,91.3039999032996,0.0051466409954293,18.4068863805052,91.4520027092678,0.0016196769048101
0.002447240266373,92.9090028080902,0.0052971105343851,18.730454966110983,93.06401044825208,0.0016669910686836
0.0024907947516311,94.5088949837939,0.0054353960250796,19.05299322873285,94.67068814037012,0.0017104720641737
0.0025438411929602,96.0938524684909,0.0056038184762995,19.372520657647765,96.26345640736388,0.0017634264464939
0.0025941397034353,97.6396379307667,0.0057635162470579,19.68415100684257,97.81688128181264,0.001813635076931
0.0026378991095522,99.179365819459,0.0059024523614791,19.994560149202933,99.36374423898371,0.0018573142374304
0.0026821115893607,100.697876408975,0.0060428269848711,20.30069188404936,100.88952990342646,0.0019014437032624
0.0027303843036984,102.193048999881,0.0061960928528933,20.60211867837601,102.39248132130572,0.001949623556293
0.0027799265892572,103.662377585989,0.0063533896095425,20.898335321335384,103.86981301044736,0.0019990681247368
0.0028277568711189,105.108768405538,0.0065052507544534,21.189927710556464,105.32412553781197,0.0020468017468471
0.0028729899488621,106.552250296647,0.006648865776288,21.48093365980404,106.77538466212224,0.0020919413173271
0.0029207694786295,108.023185981707,0.0068005657832995,21.77747429391213,108.2545619761606,0.002139619862956
0.0029670841930635,109.456969939992,0.0069476150016275,22.06652513990239,109.6964864396417,0.0021858345195316
0.0030144788739768,110.883350768033,0.0070980931135272,22.35408351483545,111.13124379117988,0.0022331245984622
0.0030562146280805,112.288723828627,0.0072306041328064,22.637406723851203,112.54444518629089,0.002274766388383
0.0031047616938295,113.686986671753,0.0073847410665595,22.919296513025408,113.951411540795,0.0023232019733864
0.0031602063725761,115.089556618495,0.00756077792158,23.202054614288592,115.36362483225425,0.0023785164625804
0.0032108748358372,116.473933812366,0.007721650292434,23.481145056572988,116.75720026436072,0.0024290632757666
0.0032654899621564,117.837277461494,0.0078950533184974,23.75599513623719,118.1302952846326,0.0024835444153577
0.0033294558328508,119.180089554419,0.0080981449579522,24.02670605417088,119.48406991388778,0.0025473495854852
0.0033930964095519,120.519581619653,0.0083002037889781,24.296747654522047,120.8346484190248,0.0026108262390106
0.0034621313187344,121.835085660668,0.0085193896256326,24.561953269190667,122.16200237399572,0.0026796787747312
0.0035267858363255,123.125489332384,0.0087246677189843,24.822098649408616,123.46382916928556,0.0027441581920659
0.0035817748351052,124.401273993787,0.0088992577901099,25.07929683714746,124.74996029510632,0.0027989949956246
0.003652141605273,125.65304923095,0.0091226722853926,25.33165472495952,126.01408595214504,0.0028691626231321
0.0037258966155772,126.862754962006,0.0093568444431085,25.57553140034041,127.23662427344024,0.0029427036174013
0.0038106242505261,128.039261951247,0.0096258546840712,25.8127152093714,128.42744693688428,0.0030271787224001
0.0038991028688397,129.150168486017,0.0099067742972169,26.036673966781027,129.5531485079504,0.0031153860147374
0.0039942961661921,130.214317177609,0.0102090130163108,26.25120634300597,130.63301313319204,0.0032102787072446
0.0041025827666453,131.204352933585,0.0105528229727497,26.450797551410737,131.64043996028178,0.0033182124098766
0.0042269225687486,132.114109052419,0.0109476018444277,26.63420438496767,132.56964689932835,0.003442132631445
0.004349104442612,132.945990695744,0.011335529293944,26.80191172426199,133.42064051371062,0.0035638872496917
0.0044787075649776,133.625770966757,0.0117470192074547,26.93895542689821,134.1201660842869,0.0036930209651116
0.0046114178281714,134.243080247457,0.0121683742930951,27.06340497788733,134.75757475035746,0.0038252332899514
0.0047516366713783,134.75608359602,0.012613569120277,27.16682645295764,135.29143955659202,0.0039649070331029
0.0048987865365265,135.175205527628,0.0130807699421225,27.251321434369807,135.73211757971808,0.0041114638778435
0.005049830484149,135.52829525024,0.0135603344758239,27.322504322448385,136.1071327351318,0.0042618767760303
0.005213873023548,135.791798606804,0.0140811695384158,27.37562659913169,136.39403713849185,0.0044252083347018
0.0053747567269377,135.999453990493,0.0145919752966781,27.41748992448339,136.62449357253743,0.0045853688407368
0.005547804851354,136.197737518084,0.0151414030916998,27.457463883645737,136.84725715397025,0.0047576104576799
0.0057040765295438,136.323507381589,0.0156375656699524,27.48281908812834,136.99493031041982,0.0049131283283605
0.0058761495236269,136.41973349904,0.0161838974261663,27.502218273406463,137.1151045144269,0.0050843433210417
0.0060564504920075,136.504178221483,0.0167563530007747,27.51924232945097,137.22459151167507,0.0052637138160437
0.0062375648009113,136.566989894645,0.0173313909315442,27.53190516276043,137.31246891518308,0.0054438610682087
0.0064134733131588,136.634308263087,0.0178899004579301,27.54547654583834,137.4041898926822,0.005618799258233
0.0066079099731191,136.634507702763,0.018507236853304,27.54551675287702,137.4309572134369,0.0058121277919973
0.0067892861606294,136.644981355918,0.0190831062486492,27.547628241353067,137.4662760638108,0.0059924365989098
0.0069978489424444,136.652645572486,0.0197452930809118,27.549173347413177,137.50248700149726,0.0061997318315392
0.0071891688885771,136.660030904845,0.0203527339098832,27.55066223041675,137.53606405291515,0.006389851240736
0.0073811671910334,136.637624673444,0.0209623285201819,27.54614513416632,137.5397483826163,0.0065806084186228
0.0075813295193488,136.609441105371,0.0215978439125833,27.5404633268428,137.53872280174232,0.0067794381135659
0.0077778639733019,136.56047181026,0.0222218408038844,27.53059111694842,137.5162592322036,0.006974625630278
0.0079722532948846,136.522267272411,0.0228390268999095,27.52288908211806,137.50432577152006,0.0071676452467319
0.0081742434503911,136.492978289948,0.0234803456436426,27.51698442325352,137.5023963397679,0.0073681726777525
0.0083649844458177,136.46145525482,0.0240859483041221,27.510629379371714,137.49666897348865,0.0075574955028591
0.0085695585295125,136.417688201239,0.024735471019853,27.501805941369785,137.4804774211121,0.0077605087377651
0.0087735375274824,136.401108885251,0.0253831043384075,27.498463551266607,137.49159190216716,0.0079628904008983
0.0089661642241741,136.372553583023,0.0259946941004036,27.49270680233744,137.48907730399358,0.0081539710660657
0.009170347752701,136.347858567798,0.0266429768034765,27.48772828726808,137.49202009001075,0.0083564759518987
0.0093796690254933,136.313694302066,0.0273075718445921,27.480840771296503,137.4861024912173,0.0085640337831008
0.0095868449901445,136.274647533597,0.0279653555323597,27.47296894277316,137.47495272047072,0.0087694219679724
0.0098007925977617,136.252606105664,0.0286446391865443,27.468525390901863,137.4818680710571,0.0089814790956232