File: example/data/02 processed data/test_ID_062.csv
Strain,Stress_MPa,Displacement(mm),Force(kN),True Stress (MPa),True Strain
0.0024682730215466507,101.301306892906,0.007836766843410616,40.8446869392197,101.55134617575717,0.002465231838976784
0.0025831553868969504,105.857941464871,0.008201518353397818,42.68192199863599,106.1313889766118,0.002579824775445445
0.0026877802737692506,110.35389390465,0.00853370236921737,44.49469002235488,110.65050092382053,0.002684174651670842
0.0027934715722499506,114.701873110328,0.008869272241893593,46.247795238084244,115.02228953214552,0.002789577081617535
0.0028952771028088508,119.13862533515,0.009192504801418101,48.036693735132474,119.48356466914296,0.0028910938605429914
0.0029881614070999506,123.436058444691,0.009487412467542342,49.76941876489941,123.80490531077996,0.002983705726790311
0.0030894018602920506,127.706606423171,0.00980885090642726,51.491303709822546,128.10114345062632,0.0030846394644801016
0.0031990429923004506,132.001634371615,0.01015696150055393,53.22305897863517,132.42391327502375,0.0031939369410208807
0.0032969114147733507,136.208401736222,0.010467693741905388,54.91922758004471,136.65746877069418,0.0032914885182722467
0.0034025773382199507,140.252344894033,0.010803183048848343,56.54974546127411,140.72956434440167,0.003396801669679838
0.0035108805091247507,144.243964950197,0.011147045616471082,58.159166667919436,144.75038827529954,0.003504731755639922
0.003607800763970751,148.039622862822,0.011454767425607134,59.68957593828983,148.57372032728443,0.003601308261878042
0.0037052938306419507,151.869187631064,0.011764307912288193,61.23365645284501,152.43190759505796,0.0036984461393823097
0.0037910438585931506,155.628093264334,0.012036564251033253,62.749247204179476,156.21808619152833,0.003783875961986169
0.0038750349254457507,159.465783901923,0.012303235888290258,64.29660406925535,160.08371938395655,0.0038675463171206344
0.003969551159414351,163.246422548462,0.012603324931140563,65.82095757153988,163.8944375743595,0.0039616932791849
0.004087193974122051,167.081174316388,0.01297684086783751,67.36712948436764,167.76406748524317,0.004078864086361843
0.004190640152464051,170.817959371995,0.013305282484073361,68.87380121878837,171.53379597130126,0.004181883874436628
0.004309018342729651,174.491186275724,0.01368113323816664,70.35484630637193,175.24307199803076,0.004299761106729886
0.004395144235729151,178.081850028416,0.013954582948440052,71.80260193145733,178.86454544505636,0.00438551379710278
0.004499297231616151,181.711544332817,0.014285268710381278,73.26609467499182,182.52911858118637,0.004489205652513978
0.004597586888467951,185.11662568199,0.014597338370885744,74.63902347497837,185.96771545306297,0.004587050268875753
0.004694252144497851,188.456989830711,0.014904250558780675,75.98585829974267,189.34165445936944,0.004683268502809371
0.00482099292734205,191.681415147323,0.015306652544311008,77.28594658740064,192.60550989405115,0.004809409156206154
0.004948196789486851,194.77331640349,0.015710524806620753,78.53260117388719,195.73709310239548,0.004935994699427375
0.005107268343320651,197.521446258187,0.016215576990043067,79.64064713130101,198.53024128778836,0.0050942704852702655
0.0052918048964533514,199.891288329957,0.01680148054623939,80.59616745463866,200.94907402829986,0.005277852497525841
0.00548746104690255,201.716672800727,0.017422688823915598,81.33216247325313,202.82358518523176,0.00547245978672994
0.005732452099184051,203.105326163709,0.01820053541490936,81.89206750920748,204.26961771703165,0.005716084118303127
0.00599420736877025,203.984989957075,0.019031608395845542,82.24674795069265,205.2077182869942,0.005976313578236253
0.006287860733467751,204.401576647969,0.01996395782876011,82.4147157044611,205.68682529563267,0.006268174616444495
0.0065928559460073505,204.624982267448,0.020932317628573338,82.50479285023503,205.97404529849157,0.006571218122546353
0.006911803204504251,204.656465785844,0.021944975174300996,82.5174870048523,206.07101100188513,0.0068880261912192455
0.007256027442332651,204.649260235291,0.023037887129406166,82.51458172686932,206.13420088361133,0.007229829129327883
0.007593123386886251,204.530196251711,0.024108166753363844,82.46657512868988,206.0832192681943,0.007564440727978012
0.007933883640911151,204.369123006322,0.025190080559892903,82.40163039614903,205.99056384804922,0.007902575871871818
0.008296804558176751,204.228837959875,0.02634235447221118,82.3450674654216,205.92328471357163,0.008262575274032935
0.00865370156365525,204.062143145887,0.02747550246460542,82.27785611642165,205.8280360331114,0.008616472911203538
0.009017757949420951,203.890640340379,0.02863138148941152,82.20870618524081,205.729276783121,0.008977340770041677
0.00938092768176155,203.669817044459,0.02978444538959292,82.11967023232586,205.58042886911068,0.00933720003753433
0.00972827578697585,203.473390424303,0.030887275623648323,82.04047101907898,205.45283568166164,0.009681260782781892
0.01008842782952855,203.29319470756,0.032030758358753145,81.9678161060882,205.3441034306015,0.010037879327152522
0.010436665840914952,203.137423728515,0.03313641404490497,81.90500924733725,205.25750113975386,0.010382579836861987
0.010800372593407652,202.978270363608,0.034291182984069295,81.84083861060675,205.17051131190038,0.010742465144227921
0.011190989448219552,202.803515643023,0.03553139149809707,81.77037750726687,205.0730876466459,0.011128833619389844
0.011577916317879852,202.63740122928,0.03675988430926853,81.7034001756457,204.98352010358522,0.011511405126472446
0.01196611851938085,202.46434420874,0.037992426299034196,81.63362358496396,204.8870565474905,0.011895090580883415
0.012366851273440551,202.32238766277,0.03926475279317375,81.57638670562886,204.82447854028285,0.012291006435907177
0.01275422789882445,202.161978721869,0.040494673578767626,81.51170982065759,204.740398670965,0.012673577763708446
0.013150541040601552,201.978601667219,0.04175296780390993,81.43777219222271,204.63472955776712,0.013064823347320075
0.013526799126691752,201.754753110298,0.04294758722724631,81.34751645407216,204.4838491284763,0.013436128717894721
0.013889661525527052,201.567334011003,0.04409967534354839,81.27194907323641,204.3670360550187,0.013794084184620095
0.014249774142034951,201.304823977803,0.04524303290096097,81.16610502785018,204.1733722531888,0.014149200419686734
0.01462025816458295,201.147011938901,0.04641931967255086,81.10247521376489,204.08783318248217,0.014514412602593047
0.01500692790920095,201.005019713294,0.04764699611171302,81.04522394840014,204.0214875535189,0.014895437996763147
0.01538911242471235,200.903293593496,0.04886043194846171,81.00420797689759,203.99501696510129,0.015271901024106626
0.01576696850193735,200.83011232578,0.050060124993651076,80.97470128975449,203.9965943810611,0.015643961138178626
0.01613372383888655,200.70620249679,0.051224573188464795,80.92474084670573,203.94434094062487,0.016004958447067494
0.016528714135963452,200.590705694881,0.052478667381683955,80.87817253617602,203.90621212764285,0.01639360173054554
0.01690687145032385,200.449880589173,0.053679316854778225,80.82139185355456,203.83886095252691,0.016765541044876833
0.017293577443144352,200.312962568042,0.054907108381983316,80.76618650743454,203.7770902990781,0.01714574546149602
0.017694934209862453,200.13302610352,0.05618141611631328,80.69363612493927,203.67436683364247,0.017540201518249022
0.01808065808323345,199.979342093904,0.057406089414266205,80.6316707322621,203.59510020201387,0.017919146898522927
0.01848269728777025,199.830833633954,0.05868256388867055,80.57179212121025,203.52424644077317,0.01831396811407614
0.01887749199718965,199.70989616437,0.059936037091077136,80.52303013347398,203.4799181309725,0.018701523261602047
0.019256032467756153,199.555835164422,0.06113790308512578,80.46091273829495,203.3984888054783,0.019072981235650637
0.01964804877493995,199.395035124011,0.06238255486043434,80.39607816200125,203.31275849960844,0.019457517532007848
0.02002163690371175,199.25169162402,0.0635686971692848,80.33828206280486,203.2410366461665,0.0198238397218925
0.02042316788781185,199.119335246923,0.06484355804380262,80.28491597155936,203.18598286038042,0.020217411739464623
0.02082394088650685,198.978825564229,0.06611601231465924,80.22826246749713,203.12234886544505,0.020610086396170096
0.021233072514965052,198.794228472443,0.06741500523501404,80.15383292008902,203.01524074115488,0.02101079179396023
0.02161436173049465,198.611800111361,0.06862559849432051,80.08027780490076,202.90466740291265,0.021384083713430625
0.022001823786373952,198.343984088997,0.0698557905217373,79.9722943846836,202.70791347601045,0.021763276306705104
0.02238615944334375,198.183716020878,0.0710760562326164,79.90767429961801,202.6202882867957,0.022139267228829692
0.02276448820049725,198.067799103357,0.07227725003657877,79.86093659847354,202.5767111789438,0.022509243652722867
0.02316535908535655,198.015224523615,0.07355001509600705,79.83973852792157,202.60231830407204,0.022901115241596003
0.02357562675089285,197.95814401701,0.0748526149340848,79.81672366765844,202.62513133265452,0.023302013717631954
0.023987114391605353,197.867638681846,0.07615908819334699,79.78023191652031,202.61391236530426,0.02370394293619389
0.024373748174168153,197.735137568366,0.07738665045298387,79.72680746756518,202.55468401664186,0.024081448476570393
0.02475900834842165,197.510983677588,0.07860985150623874,79.63642861880349,202.4011597713664,0.02445747114036966
0.025143517189243052,197.235511705946,0.07983066707584668,79.52535831983744,202.19470618485363,0.024832619558931755
0.025547748221056352,197.032443605126,0.08111410060185391,79.44348126158681,202.06617886572926,0.02522685836402857
0.02595855529491665,196.899780048403,0.08241841306136036,79.38999131551608,202.01101387634637,0.025627351483301062
0.02635906579416445,196.814907606721,0.08369003389647213,79.35577074702991,202.00276470559893,0.026017652185508635
0.02676503024185145,196.736373329677,0.08497897101787835,79.32410572652577,202.002028311518,0.026413112405143217
0.02718416301733515,196.614844009829,0.0863097175800391,79.27510510476306,201.9596539810201,0.026821236211396017
0.02758247614165525,196.47827382215,0.08757436174975541,79.22004000509088,201.89763112220305,0.027208932917891445
0.027985760735387052,196.361078366027,0.08885479033485388,79.17278679718208,201.8563925229212,0.027601315512320732
0.02837115673992175,196.218300812978,0.09007842264925155,79.11521888779272,201.78524098058412,0.027976149283415613
0.02879520210739525,196.050228805642,0.09142476669097992,79.04745225443486,201.69553476730152,0.02838841090888454
0.02920360853183665,195.842062912053,0.09272145708858136,78.96351976613977,201.5613578514039,0.02878530757149806
0.02960683684215435,195.62270135505,0.09400170697384005,78.87507318635616,201.41447075669043,0.029177017567315847
0.03001088318743745,195.404714660721,0.0952845541201139,78.78718095120271,201.26898272667844,0.02956936838711812
0.03040360022899775,195.255556443438,0.09653143072706785,78.7270403579942,201.1920283240348,0.0299505703729096
0.03080163572426145,195.131896700397,0.0977951934245301,78.67718074960007,201.14227830074685,0.030336786644116903
0.031213443522340952,195.059146732396,0.09910268318343252,78.64784796250207,201.14761439244367,0.030736209332824758
0.03162328980117875,194.969106671597,0.10040394511874251,78.61154380998791,201.13467123414983,0.031133571157548744
0.03204155054641065,194.859085450536,0.1017319229848538,78.56718325365613,201.10267268642673,0.031538928406246766
0.03245244787788925,194.709376474795,0.10303652201229836,78.50682059463735,201.02817236617958,0.031936989468393455
0.03286840979436045,194.561593120187,0.10435720109709441,78.4472343460594,200.9565232931049,0.03233979557045768
0.033288580347793646,194.390287186192,0.10569124260424483,78.37816379347262,200.86126388002023,0.03274651254426937
0.033716892623586944,194.206714339334,0.10705113407988855,78.30414722161947,200.75476127349296,0.033160940360280756
0.03411665266632695,194.013756058398,0.10832037221558806,78.22634644274608,200.63285598633186,0.03354758661488947
0.034520694067519245,193.877986105085,0.1096032036643736,78.17160399757027,200.5707887498454,0.033938221935254524
0.034928149741818244,193.743784491623,0.11089687543027292,78.11749390702239,200.51089640789297,0.03433200376830929
0.03534510849052145,193.63275654479,0.1122207194574056,78.07272743885933,200.4767273321843,0.034734809294278156
0.03576417750102255,193.369933434891,0.11355126356574659,77.96675716094806,200.28565005761735,0.03513949003136396
0.03617538997775515,193.133735750212,0.11485686317937259,77.87152225448548,200.1204239588366,0.03553642485377493
0.03656824062279325,192.934578300368,0.11610416397736856,77.79122197070838,199.98985638411298,0.03591548827864078
0.03697057715720995,192.801503012201,0.11738158247414159,77.73756601451946,199.92948585533964,0.03630355580456899
0.03738299894592275,192.749726320508,0.11869102165330472,77.71668965242883,199.95528913637443,0.03670119466314941
0.03779306294895245,192.646348097396,0.11999297486292401,77.67500755287007,199.92704365792667,0.037096403547732124
0.038218767572870446,192.489553639886,0.12134458704386367,77.61178802760203,199.84626715065437,0.03750652127791657
0.038641538465242445,192.38290968972,0.12268688462714475,77.56878918689512,199.8168812945506,0.03791364629926009
0.03905765264884255,192.238232434502,0.12400804716007507,77.51045531759121,199.74660654275627,0.03831419917134406
0.039472445893323944,192.124410229252,0.12532501571130353,77.4645622044344,199.70803061681292,0.03871332088748239
0.03989746875935235,192.015819713175,0.1266744633109437,77.42077850835216,199.67676488148282,0.03912212056179945
0.04034339212038405,191.879386221838,0.12809026998221934,77.36576852464508,199.6204515400042,0.03955084338543754
0.04078245515107105,191.713070118814,0.12948429510465057,77.2987098719058,199.53159980280867,0.03997279099401399
0.04120218015389255,191.506860395387,0.13081692198860884,77.21556611142005,199.3973605581041,0.04037598802187887
0.04163167261169385,191.318466214295,0.13218056054212796,77.13960557760375,199.28337396429995,0.040788399663180354
0.042051275817618645,191.152853505375,0.13351280072093918,77.0728305333672,199.19107487145436,0.041191151158471856
0.04248232568495375,190.997767009131,0.13488138404972813,77.01029965808162,199.1117963523118,0.04160472076768171
0.04292176242187325,190.858063598655,0.13627659568944755,76.9539712429777,199.05002806073523,0.04202616114552465
0.04333972422637035,190.655737856418,0.13760362441872584,76.87239350370774,198.91870495729034,0.042426841321776716
0.04377424231723605,190.489292049073,0.13898321935722444,76.80528255418623,198.82781647806786,0.042843223085407015
0.044215099907593446,190.350034986016,0.14038294220660918,76.74913410636165,198.7663808003366,0.04326550263252269
0.04466469794395575,190.255382068936,0.1418104159720595,76.71097005019499,198.75308124125692,0.04369597071763455
0.04510895091805725,190.108007989963,0.14322091916483176,76.65154882155308,198.6835807915119,0.04412113923388578
0.045523623119988546,189.828587044192,0.14453750340596364,76.53888629621822,198.47027209819174,0.044517834676708806
0.04592315841296415,189.577918677633,0.14580602796116116,76.43781681082163,198.283935468666,0.04489990062394087
0.04633221517529645,189.344304880723,0.14710478318156622,76.34362372790751,198.1170459566736,0.045290920546946424
0.046769024656925645,189.258026229592,0.1484916532857389,76.30883617577149,198.10943952484487,0.04570830072871482
0.047203662684897146,189.226505764547,0.14987162902454843,76.29612712426535,198.1586899136984,0.046123433205695764
0.047646261259024145,189.121688921548,0.15127687949740165,76.25386497316816,198.13263032165196,0.0465459919538465
0.04808649220183945,189.011584218582,0.15267461274084024,76.20947075693226,198.10048828916612,0.0469661132203233
0.048527241326126846,188.890426914878,0.15407399121045273,76.1606201320788,198.0567582459714,0.0473865522585036
0.04896337906113625,188.792860921963,0.15545872851910758,76.12128152373549,198.0367973353215,0.04780241847221245
0.04942014072589835,188.685373158531,0.15690894680472725,76.07794245751971,198.01023085294423,0.048237764697217425
0.04987681850019145,188.550336100329,0.15835889873810782,76.02349551565266,197.9546269921552,0.04867284157330197
0.050322425075598747,188.347714346928,0.15977369961502602,75.94179842468138,197.82582809031155,0.04909718853319829
0.05075462468047015,188.104353454869,0.1611459333604927,75.84367531300317,197.65151931523337,0.04950859620719837
0.051209045762198646,187.84471914416,0.1625887202949807,75.73899075892531,197.46406796300062,0.04994097388831419
0.051662809381408645,187.636333244388,0.16402941978597244,75.65496956413725,197.3301533618193,0.050372539535210814
0.052105487577521946,187.548011671989,0.16543492305863217,75.61935830614597,197.32029226435276,0.05079338265114402
0.05254653262287585,187.456422996031,0.1668352410776308,75.5824297519997,197.30660804235953,0.05121249711527084
0.05297676519729605,187.343379126202,0.16820122950141495,75.53685046368464,197.26822533343883,0.051621167568695454
0.05342920370572435,187.196598774546,0.1696377217656748,75.47766862589695,197.19836398348994,0.052050750965310665
0.05388838777256095,187.036093963193,0.171095631177881,75.41295308595942,197.11516752214666,0.05248655055808295
0.054345950066937446,186.826998287339,0.17254839146252637,75.32864570945509,196.98028900741852,0.05292062213480327
0.05478799036147755,186.656518944654,0.17395186939769122,75.2599084384845,196.8830545055007,0.05333978973012695
0.055237938139087145,186.436124461355,0.17538045359160168,75.17104538281833,196.73447157124247,0.053766275280235094
0.05567820788046485,186.248907817803,0.1767783100204759,75.09555963213818,196.61891322479215,0.054183411459321956
0.05612502330747045,186.122913021573,0.17819694900121866,75.04475853029824,196.56906585296306,0.054606571559727424
0.056585857836445645,186.015364910906,0.17966009863071492,75.00139513207729,196.54120390514905,0.05504282106305203
0.05705302624878645,185.955980385046,0.18114335833989698,74.97745129125055,196.56533181507285,0.05548487237414963
0.057518940105147146,185.807841454144,0.18262263483384217,74.91772167431087,196.49531155781162,0.05592554204282375
0.05798808039320095,185.640768116897,0.184112155248413,74.85035770473287,196.4057199027152,0.056369067203646636
0.058455646530476545,185.446775189035,0.18559667773426303,74.77213975621892,196.287186329702,0.05681090852353092
0.05890655363544885,185.259817625641,0.18702830779255009,74.69675846665847,196.17283500909932,0.05723682253271961
0.05936926163987375,185.08287088326,0.18849740570659915,74.62541354013044,196.07110426978724,0.05767369483088533
0.05982080362932405,184.851751907983,0.18993105152310386,74.53222636929874,195.90973225940695,0.05809984065299324
0.06026857024668725,184.652894661387,0.191352710533232,74.45204712747123,195.78166061454093,0.05852224418893695
0.06074381763950395,184.438081249282,0.19286162100542503,74.3654343597105,195.64155442246837,0.05897037679154159
0.061202094131545745,184.298931866464,0.19431664886765773,74.30932932855828,195.57841244289864,0.05940231664130375
0.061682560287372845,184.216754215065,0.19584212891240876,74.27619529951421,195.5797152628799,0.059854970687326224
0.06215422761556465,184.121936696131,0.19733967267941774,74.23796487588002,195.5658934585609,0.06029913601926962
0.06262818679033125,184.027212122576,0.19884449305930169,74.19977192782265,195.5525027378926,0.06074526093014441
0.06311026097663296,183.866701101308,0.20037507860080964,74.13505388404738,195.47057659272411,0.06119882020510812
0.06358825478483135,183.624509378264,0.20189270894183953,74.03740218131605,195.30087146534873,0.061648337438232406
0.06403784932642055,183.421330046447,0.20332017161138524,73.95548027472744,195.16723754321305,0.06207096296196741
0.06448961492650415,183.17863891797,0.20475452739165068,73.8576272117255,194.99175880455104,0.06249544948089113
0.06495554964383825,183.015286320922,0.20623387011918642,73.79176344459576,194.90314483712194,0.06293306086673194
0.06542926193659246,182.823181003882,0.20773790664868105,73.71430658076522,194.78516680186604,0.0633777808046384
0.06590912901666565,182.620783104622,0.20926148462791344,73.63269974778359,194.65715985938903,0.06382807728521463
0.06638731991817766,182.490036472023,0.21077974074021405,73.57998270551968,194.60506090517111,0.06427659926232297
0.06685283937680506,182.352122299182,0.21225776502135604,73.52437571103019,194.54287944126875,0.06471304282353053
0.06732810142312365,182.305502527408,0.21376672201841757,73.50557861905091,194.57978589156687,0.06515842404223524
0.06781987437140376,182.197230375061,0.21532810112920692,73.4619232872246,194.55382364991536,0.06561906935820498
0.06832113974240266,182.0450037715,0.21691961868212842,73.4005455206688,194.48252591357888,0.06608838798172993
0.06880212423029636,181.850084643414,0.21844674443119091,73.32195412822453,194.36175675834005,0.06653851128919011
0.06928930080708076,181.55884716786,0.2199935300624814,73.20452717808115,194.13893274346066,0.06699422293885171
0.06976006696712216,181.319345589394,0.22148821262061283,73.10796014164366,193.9681952801449,0.06743438684973137
0.07025021774422906,181.110300953723,0.22304444133792725,73.02367334454111,193.8333390314449,0.06789246949464174
0.07075794402258015,181.005761351363,0.22465647227169197,72.98152297686956,193.81335688082723,0.0683667566056724
0.07126904414961126,180.943193469764,0.22627921517501573,72.95629560700884,193.83884191373227,0.06884396827438889
0.07177404698240115,180.801083036782,0.22788259916912365,72.8989966804305,193.77790846513298,0.06931526336334631
0.07228134243338975,180.621648449145,0.22949326222601246,72.82664865469526,193.67722367158098,0.06978847451540833
0.07276697227993385,180.390131851601,0.23103513698878997,72.73330116256554,193.51657557562007,0.07024126604603266
0.07325990518592745,180.135533437859,0.23260019896531967,72.63064708214475,193.33224553813304,0.0707006572305875
0.07373042629861296,179.902726836051,0.23409410349809612,72.53677946029576,193.16703157795595,0.07113896485900878
0.07422109075946196,179.635697986896,0.2356519631612917,72.42911342831647,192.9684554308207,0.07159583221889756
0.07470601653192456,179.452226453941,0.23719160248886045,72.355137706229,192.8583874500998,0.07204715118550971
0.07521937690181646,179.306891401351,0.23882152166326726,72.29653861302474,192.79424404676232,0.07252471229643609
0.07572981415476615,179.180576098423,0.24044215994138252,72.24560828288415,192.7498878265005,0.0729993281215367
0.07623660285965725,179.03629399402,0.24205121407941174,72.18743373838888,192.68541283670697,0.07347032870059134
0.07673796009784035,178.758552462675,0.2436430233106431,72.07544835295056,192.47611912870346,0.07393606318335903
0.07724347470388265,178.509110968852,0.2452480321848274,71.97487354264113,192.2977749663871,0.07440544013076969
0.07774555080689216,178.291146627088,0.24684212381188259,71.88699032004189,192.15249002560336,0.07487140641287184
0.07827024446652635,178.165380361988,0.24850802618122114,71.83628136195357,192.11042823839247,0.07535813166891385
0.07878662072689475,177.995148774578,0.2501475208078908,71.76764398590986,192.0187850523079,0.07583691021069894
0.07930368374908765,177.779472763041,0.2517891959033533,71.68068341805814,191.87803984812078,0.07631609593431249
0.07982299920349435,177.507376372946,0.25343802247109454,71.57097415357183,191.67654753577807,0.07679713807836194
0.08032885205250305,177.23660535391,0.2550441052666972,71.4617992786965,191.47381840367208,0.07726548742885876
0.08085505344511795,176.95963519725,0.2567147946882495,71.35012491153121,191.26771595875223,0.07775244404710355
0.08137567937363625,176.696441447713,0.25836778201129507,71.24400519171787,191.07523441342457,0.07823400776801205
0.08189008170033016,176.432402977667,0.26000100939854826,71.13754488059534,190.88046687209373,0.07870958718654261
0.08241576750155435,176.181284681648,0.2616700618174351,71.03629398364048,190.70140047809588,0.0791953649353352
0.08292788939159476,175.914284848595,0.26329604881831337,70.92863965095351,190.5024852049208,0.07966838167608098
0.08343051509410046,175.583796533591,0.26489188542376896,70.7953867623439,190.2328431205662,0.08013240989088027
0.08395808062993065,175.274901454021,0.2665669060000298,70.67084026626127,189.99064576270086,0.08061923126411287
0.08447051910554935,174.901816797786,0.2681938981601192,70.52041253286733,189.67586405519867,0.08109186705688955
0.08501326830215496,174.638604121303,0.269917126859342,70.41428518170936,189.48520262938115,0.0815922157675635
0.08551563031262846,174.335647707051,0.27151212624259535,70.29213315548297,189.24407050667983,0.0820551094150651
0.08600205006890785,173.909822633493,0.2730565089687824,70.12044048582439,188.86642390709355,0.08250310923455478
0.08649314290449095,173.437288409183,0.27461572872175877,69.92991468658259,188.43842458052586,0.08295520951586828
0.08697687647661595,172.995242020823,0.27615158281325564,69.75168158279584,188.0418278171104,0.08340033512220162
0.08748447228476715,172.628042831113,0.2777631995041357,69.60362686950477,187.7303160597451,0.0838672055199306
0.08796703078654436,172.285310237369,0.2792953227472783,69.46543708770719,187.44073742708898,0.0843108453887215
0.08847206416541285,171.916248260855,0.2808988037251858,69.31663129877674,187.12603360806642,0.08477493683892974
0.08897843054713496,171.395995704211,0.28250651698715346,69.10686546793788,186.6465424040352,0.0852400370945542
0.08950006838125295,170.859446594247,0.2841627171104781,68.8905288668004,186.15137874801516,0.08571893816642083
0.09002110885751345,170.347335564695,0.28581702062260517,68.68404569968503,185.68219160315175,0.08619706197785942
0.09054463094873716,169.767167589202,0.28747920326224047,68.45012197196625,185.1386731257787,0.08667723287271091
0.09105357603033605,169.073772684345,0.28909510389631693,68.1705451463279,184.46854430019476,0.08714381291408037
0.09156643239123576,168.387888038215,0.2907234228421735,67.89399645700829,183.8065662037692,0.08761375854672317
0.09207074788353456,167.663366129781,0.29232462453022223,67.6018692235277,183.1002576420208,0.088075662663232
0.09256626316336215,166.924987883077,0.2938978855436748,67.30415511445665,182.37661024000295,0.08852929892941212
0.09305359809350396,166.086857096399,0.29544517394687503,66.96622078126808,181.54183674526053,0.0889752455890822
0.09355375054099885,165.15242362,0.2970331579676713,66.589457203584,180.60305226058685,0.08943271451374298
0.09406284619536875,164.290900849856,0.29864953667029576,66.24209122266194,179.74457058779458,0.08989814859786882
0.09456121131964546,163.338967082072,0.3002318459398743,65.85827152749144,178.7844976650524,0.09035356270261556
0.09507971657517285,162.411747071131,0.3018781001261738,65.48441641908002,177.8538099511328,0.09082716114390656
0.09558156527361686,161.252045329227,0.3034714697437335,65.01682467674433,176.66476822536674,0.09128533211847141
0.09608244856917185,160.158752778453,0.3050617742071206,64.57600912027225,175.5471979051914,0.09174241249311982
0.09657232469451756,158.97070416657,0.30661713090509324,64.09698791996102,174.32287462626007,0.09218924629429079
0.09704652224032666,157.754374303333,0.3081227081130371,63.60656371910387,173.06388769767025,0.09262158899945869
0.09754509694896775,156.489314439084,0.30970568281297256,63.09649158183868,171.75407978752196,0.09307595573708681
0.09802891224868586,155.157908671654,0.3112417963895776,62.5596687764109,170.3678696855172,0.09351667447899438
0.09855532501897865,153.901739043775,0.3129131569352572,62.05318118245008,169.06957495622026,0.09399597572448193
0.09908204109529226,152.532061053807,0.3145854804775529,61.500927016894984,167.64524899548994,0.09447532331341595
0.09961217986542105,150.981476960973,0.31626867107271184,60.87573151066431,166.02107100035636,0.09495755388040283
0.10017677348271685,149.339298748727,0.31806125580762595,60.213605255486726,164.299627851546,0.09547087005906049
0.10077392409405035,147.58234760419,0.31995720899860985,59.505202554009415,162.4547998992764,0.09601349977506775
0.10144194811969845,145.581719565821,0.32207818528004256,58.69854932893902,160.3498128091935,0.09662018330193398
0.10215936688827246,143.174578022637,0.32435598987026504,57.72798985872724,157.8012022679252,0.0972713163258937
0.10296828371747245,140.240396939299,0.326924300802975,56.54492804592535,154.68070991999568,0.09800498529536333
0.10366559349448945,137.817840116291,0.32913825934500396,55.568153134888526,152.10480830607497,0.09863699752668938
0.10413406297812346,136.13124415589,0.33062564995554194,54.888117643654844,150.30714370810975,0.09906137433940557