File: example/data/02 processed data/test_ID_072.csv
Strain,Stress_MPa,Displacement(mm),Force(kN),True Stress (MPa),True Strain
-0.0005542521860224998,0.239495508755862,2.183582777650383e-06,0.0482822945651817,0.2394956734671275,6.87742370591312e-07
-0.0005581332237875998,0.241687347240518,-1.0138712126626028e-05,0.0487241692036884,0.2416865754614823,-3.1933002565439066e-06
-0.0005559917097523998,0.243317342419119,-3.3394050648319925e-06,0.0490527762316944,0.2433170865025314,-1.05178167587388e-06
-0.0005560138735851998,0.244073732843544,-3.409775233741869e-06,0.0492052645412584,0.2440734707217898,-1.0739455322001192e-06
-0.0005606048144297998,0.246915940127446,-1.798601241562703e-05,0.0497782535296931,0.2469145413768429,-5.664901845753444e-06
-0.0005636464186293998,0.249359879715941,-2.764310574907566e-05,0.0502709517507337,0.2493577086666419,-8.706527901436499e-06
-0.0005705566684542998,0.252122167427331,-4.958314894336471e-05,0.0508278289533499,0.2521182301010383,-1.5616861767193007e-05
-0.0005894245039430998,0.259035390413466,-0.0001094885266202,0.0522215347073547,0.2590264576880364,-3.448516992015749e-05
-0.0005975948239631998,0.319691294390609,-0.000135429292684,0.0644497649491467,0.3196776579919077,-4.2655805079422986e-05
-0.0006083749779713998,0.430620005316703,-0.00016965628166,0.0868129930718473,0.4305969951154714,-5.343647704485237e-05
-0.0006162822044287997,0.583591779000141,-0.0001947617256622,0.1176521026464284,0.5835559801522795,-6.134415731347029e-05
-0.0006154353300082998,0.770091479973829,-0.0001920728993771,0.1552504423627239,0.7700448929806497,-6.049723129924183e-05
-0.0006149182899960998,0.967657514422921,-0.0001904312973385,0.1950797549076608,0.967599475910842,-5.998016014034983e-05
-0.0006067514649107997,1.16246748947272,-0.0001645016276927,0.2343534458777003,1.1624072602462134,-5.181287854520812e-05
-0.0005882169756730997,1.34245348707771,-0.0001056546243631,0.2706386229948663,1.342408814189867,-3.3277600736691966e-05
-0.0005720635407017998,1.43557226132814,-5.436746832918388e-05,0.289411367883753,1.4355476791456354,-1.7123758682897368e-05
-0.0005508819348049998,1.41436819189316,1.288413039329826e-05,0.2851366274856611,1.4143739313905488,4.057985591111809e-06
-0.0005240894857410997,1.30579015236441,9.795015617121642e-05,0.263247294716665,1.30583043656893,3.0849967023404206e-05
-0.0004963242876791998,1.14681391024651,0.0001861046600177,0.2311976843056964,1.1468811314789102,5.861392312099993e-05
-0.00046911538925109976,0.97349452263701,0.0002724929125268,0.1962564957636212,0.9735780723560028,8.58208566633732e-05
-0.00043868558370769976,0.806200244526422,0.000369107545127,0.1625299692965267,0.8062939688077252,0.0001162475879091
-0.00040736247418829977,0.648007955982947,0.0004685584178511,0.1306384039261621,0.6481035873475487,0.0001475665659599
-0.0003641045744352998,0.522529688920757,0.0006059022495669,0.1053419852864246,0.5226294060590193,0.0001908171474444
-0.0003210697925502998,0.461301061913494,0.0007425376820517,0.0929982940817604,0.4614089464556172,0.0002338427927221
-0.00028296321688099977,0.452355985123665,0.0008635260598018,0.0911949666009308,0.4524790154170386,0.0002719397327874
-0.00024539264438399976,0.63393348860775,0.0009828126274797,0.1278009913033224,0.6341297209975408,0.0003094993843695
-0.00020023025006259978,0.909010820109776,0.0011262032294502,0.1832565813341308,0.909333255045591,0.0003546467839613
-0.00015317634595739978,1.44723801507092,0.0012755993749842,0.2917631838382974,1.4478194626008345,0.0004016828972943
-0.00010578043879229978,2.2773156833326,0.0014260813802334,0.4591068417598521,2.278338561283124,0.0004490586479085
-6.619917535729517e-05,3.54496490436021,0.0015517518916405,0.7146649247190183,3.546697473177892,0.000488621358411
-2.4186730132395124e-05,5.1459148920141,0.0016851414052295,1.0374164422300427,5.148646102802233,0.0005306123988363
2.4249196747704874e-05,7.05460423094002,0.0018389254730738,1.4222082129575082,7.058690180994424,0.000579021460093
7.390251107220489e-05,9.09108991140566,0.0019965747460541,1.8327637261393808,9.0968067745651,0.0006286448011464
0.0001222602293153002,11.3429338639484,0.002150110501476,2.2867354669719973,11.350615300552626,0.0006769709613869
0.0001681112817807002,13.6326705699347,0.0022956875930536,2.748346386898836,13.64252768889142,0.0007227899348203
0.00021612949640940023,15.9642299378052,0.0024481454244997,3.2183887554615285,15.97653946740454,0.0007707723037345
0.00026571297176820023,18.1998255386149,0.0026055729587639,3.669084828584764,18.2147612782299,0.0008203163489219
0.0003140039644713002,20.4417776326844,0.0027588968605963,4.121062370749175,20.45954039052245,0.0008685665799165
0.0003652028171279002,22.6874819248626,0.002921453217781,4.5737963560523,22.70835764677527,0.0009197196739258
0.0004146779095187002,25.0107530681337,0.0030785366361218,5.042167818535754,25.035003940454093,0.0009691480624167
0.00046241692343780024,27.4167224718075,0.0032301080053149,5.527211250316392,27.44461506227543,0.001016839695311
0.0005119892341173002,29.8666716616171,0.0033875000917223,6.021121006982007,29.89853728460708,0.0010663603983463
0.0005662851619074002,32.3807896329676,0.0035598896624559,6.527967190006268,32.41709578675549,0.0011205969871384
0.0006185604438029002,34.9378942094105,0.0037258636824741,7.0434794726171575,34.978893841277255,0.0011728123590739
0.0006676722519026002,37.5603668773998,0.0038817936731906,7.572169962483801,37.60628863944938,0.0012218653988814
0.0007127360159035003,40.2294344714509,0.0040248711238935,8.110253989444502,40.28043235779254,0.0012668731217909
0.0007603095268942002,42.9039625268679,0.004175917021289,8.649438845416569,42.96039194022119,0.0013143852726201
0.0008129232681012002,45.6100839614111,0.0043429656496212,9.194992926620476,45.67247231666173,0.0013669285241077
0.0008632861149774002,48.3527984195967,0.0045028676884531,9.747924161390696,48.42137361759667,0.0014172213108984
0.0009092651711299002,51.081150171009,0.0046488511917373,10.297959874475412,51.155943451590986,0.001463134196693
0.0009554261602093002,53.8142777389277,0.0047954123320644,10.848958392167823,53.89555699911995,0.0015092266331638
0.0010054285082938001,56.5435643161679,0.0049541697872327,11.39918256613945,56.63179310923801,0.0015591523269828
0.0010534878693389002,59.3348546479394,0.0051067582585509,11.961906697024585,59.43029047754359,0.0016071356633295
0.0011058260426940003,62.1249520388588,0.0052729319589533,12.524390331033937,62.22812704517507,0.0016593884244958
0.0011525220723462002,64.8912415503117,0.0054211918530991,13.08207429654284,65.00204087945502,0.0017060059449382
0.0012042139970921003,67.6891820293041,0.0055853137141673,13.646139097107708,67.80825771959987,0.0017576084267031
0.0012537827170734002,70.5171346160062,0.0057426944001079,14.21625433858685,70.64468055429629,0.0018070888766255
0.0013050825339784003,73.3927240565276,0.0059055713187813,14.795973169795964,73.52923617186474,0.0018582947628692
0.0013534971477216003,76.2933875704556,0.006059287717416,15.380746934203849,76.43898869997551,0.0019066183239297
0.0014070578825799002,79.1493979989315,0.0062293430505911,15.956518636584592,79.30468894456398,0.0019600756073333
0.0014577715764802002,81.9799802948021,0.0063903590287245,16.527164027432104,82.14498234433015,0.0020106887150491
0.0015093116197698003,84.8310871481286,0.006553998666169,17.101947169062726,85.00619985112655,0.0020621239086581
0.0015564944400492003,87.7195768940035,0.0067038041205561,17.684266701831106,87.90479102346347,0.0021092084238725
0.0016103034543331002,90.6027544060807,0.0068746477409075,18.26551528826587,90.7989314205367,0.0021629026217788
0.0016619627019963002,93.4497481947738,0.0070386658522381,18.8394692360664,93.65691718737816,0.0022144489277338
0.0017150479454424003,96.3434458736923,0.0072072115001795,19.42283868813637,96.56214432757191,0.0022674153439374
0.0017624612105722002,99.2698819083265,0.0073577486169666,20.012808192718623,99.49993004574932,0.0023147201064022
0.0018100334081097003,102.235369819713,0.0075087903441482,20.610650555654143,102.47715374340834,0.0023621811886685
0.0018612183261434003,105.263364523551,0.0076713024589052,21.22109428794788,105.5176974706698,0.0024132440376131
0.0019144298780829003,108.199049241716,0.0078402491363131,21.812928327129946,108.46623270702852,0.0024663259230448
0.0019612259260672,111.162105779681,0.0079888265886632,22.41028052518369,111.44180807458004,0.002513005609417
0.0020085067869874,114.132080814353,0.0081389433220849,23.00902749217357,114.42465232206312,0.0025601666903362
0.002057120639042,117.052894357613,0.0082932923023582,23.59786350249478,117.35864360729636,0.0026086550664285
0.0021111085931385005,119.939669956197,0.0084647040566146,24.17983746316932,120.25943493598513,0.0026625009183978
0.0021612605729851003,122.821269138875,0.0086239365926276,24.7607678583972,123.154876331719,0.0027125182952659
0.0022100509049201005,125.625196543744,0.0087788458965212,25.32603962321879,125.97254906065038,0.0027611752780943
0.0022568128699159,128.492718301381,0.0089273151353829,25.904132009558406,128.85400806165765,0.0028078072159173
0.0023048132428387,131.328307221233,0.0090797163194128,26.47578673580057,131.70387376431253,0.0028556718565518
0.0023544324529883006,134.156951713942,0.0092372573116377,27.046041465530703,134.54726424406064,0.002905148348664
0.0024007836540309,136.949221737297,0.009384422374948,27.60896310223908,137.35400578161295,0.0029513640200409
0.0024459150856889003,139.731961222526,0.0095277146704621,28.169963382461244,140.1512765790212,0.002996361436383
0.0024902742751824,142.50294475303,0.009668555097104,28.728593662210848,142.936896744477,0.0030405869306838
0.0025333805360789,145.264125984432,0.0098054174754504,29.28524779846149,145.71274815749777,0.0030835613988917
0.0025771483071605006,147.998919891869,0.0099443801486345,29.83658225020079,148.462465567772,0.0031271934653374
0.0026236081978763,150.706546715705,0.0100918903016571,30.38243981788613,151.18557472742043,0.003173507221425
0.0026686184186034004,153.400792073605,0.0102347977524657,30.92559968203877,153.89528847736608,0.0032183738217832
0.0027151536400831,156.077152066526,0.0103825470806637,31.465153856611643,156.5875389577218,0.0032647584404873
0.0027581642349261,158.767667260145,0.0105191057192903,32.00756171964523,159.29368107958263,0.0033076279261862
0.0028006954442598006,161.449482597201,0.0106541423089247,32.54821569159572,161.99124819193892,0.0033500177920391
0.0028451627873899,164.082288692212,0.0107953261233628,33.07898940034994,164.64018532764513,0.0033943354359789
0.0028913257884070004,166.673802157828,0.0109418936515921,33.601438515018124,167.2482043681327,0.0034403409516491
0.002935638450549,169.246265564105,0.011082586353893,34.12004713772357,169.83703291943985,0.0034845004500206
0.0029753985424037,171.851228177691,0.0112088246455316,34.645207600622506,172.4579211798211,0.0035241214539933
0.0030183179171815004,174.456022079135,0.0113450936604511,35.17033405115362,175.07939842877832,0.0035668889273445
0.0030614116557717,176.977802157581,0.011481916280475,35.678724914968335,177.6178161128175,0.003609828307256
0.0031058372717632,179.503397624899,0.011622967611248,36.18788496117964,180.1605195703173,0.0036540928638154
0.0031498039001009006,182.034008730037,0.0117625616562202,36.69805615997546,182.70839810049875,0.0036978981677165
0.0031924536975871005,184.608820491655,0.0118979747632389,37.21713821111765,185.30062240890885,0.0037403896390664
0.00323411666184,187.178210757981,0.0120302546747419,37.73512728880897,187.88743959104588,0.0037818961972707
0.0032808710176962,189.65826036295,0.0121786997545853,38.23510528917072,190.3857535941113,0.0038284729822275
0.0033234151712571002,192.176802767591,0.0123137774421412,38.74284343794635,192.9221326506847,0.0038708536699637
0.0033632871783076,194.732556081993,0.0124403710645265,39.25808330612979,195.4955624618368,0.003910570847898
0.0034026954463048003,197.271917636992,0.0125654923154176,39.77001859561759,198.0526479567133,0.0039498245375693
0.0034431287583028,199.83784421064,0.0126938680810113,40.28730939286503,200.63680963804268,0.0039900976490944
0.0034844546421109006,202.331035162901,0.012825077762102,40.78993668884085,203.1483300478304,0.004031258120022
0.0035240090666147006,204.791509636783,0.0129506630599016,41.28596834277545,205.6268437592506,0.0040706526354255
0.0035621052636196004,207.254728855819,0.0130716184853921,41.78255333733311,208.1080059408258,0.0041085933514907
0.0036009964683857004,209.648371287482,0.0131950980605245,42.26511165155637,210.5196565842907,0.0041473243458601
0.0036436692664261004,211.988320880299,0.0133305841943027,42.73684548946828,212.8783769935916,0.0041898196295146
0.0036874905729122,214.325282041339,0.0134697168423961,43.207976859533936,215.2345421551228,0.0042334567646127
0.0037294024292952,216.569661001911,0.0136027869864121,43.660443657985255,217.4975195739829,0.0042751906931373
0.0037726042287844,218.776551219926,0.0137399526997904,44.10535272593708,219.72331640593703,0.0043182072657124
0.0038181911717756,220.88152564233,0.0138846912437874,44.52971556949373,221.8474695116215,0.004363596749134
0.0038660664455279006,222.920947126901,0.014036695237951,44.94086294078325,223.9064820550824,0.0044112624336043
0.0039124572530012,224.855668353479,0.0141839860516787,45.33090274006137,225.8601879325551,0.0044574479831842
0.003962157977803,226.798552393368,0.0143417858529244,45.72258816250299,227.82302365956608,0.0045069264385266
0.0040139346281379,228.640597337537,0.0145061767177377,46.09394442324746,229.68522754535667,0.0045584689320346
0.0040686743021435,230.451377626007,0.0146799751827055,46.45899772940301,231.5168958951,0.0046129581602441
0.0041230782292971,232.349014903368,0.0148527076514182,46.84156140451899,233.4359478140624,0.0046671102360597
0.004177105159756,234.244482333821,0.0150242431556252,47.22368763849831,235.35293778593024,0.004720884158526
0.004233756749064,236.049565172084,0.0152041119516781,47.58759233869213,237.17993494059465,0.0047772673429796
0.004295257510517,237.873216126653,0.0153993768692914,47.95524037113325,239.02694819035213,0.0048384731264187
0.0043573750764346,239.730150398597,0.0155966001410797,48.32959832035716,240.9077804135664,0.0049002889534657
0.0044223575222404,241.595710350724,0.0158029194065132,48.70569520670596,242.7982040639939,0.0049649516547662
0.0044866613667059,243.400216897979,0.0160070841126911,49.06948372663256,244.6273437467769,0.0050289349780349
0.0045549032781965,245.032015418099,0.0162237521816738,49.39845430828876,246.28409059753807,0.0050968322617977
0.0046308836039135,246.7262223296,0.0164649897158252,49.74000642164736,248.0057009794524,0.0051724234566755
0.0047091176393336,248.366274474324,0.0167133827782841,50.07064093402372,249.67368884109743,0.0052502508486388
0.0047930307040027,250.028756241904,0.0169798067586085,50.40579725836785,251.3659026875994,0.0053337210194535
0.0048803995500841,251.527135005818,0.0172572028449169,50.707870417172906,252.89427037268297,0.005420621329096
0.0049748732554201,253.006050059705,0.0175571568593587,51.00601969203653,254.4051262509696,0.0055145798994674
0.0050777635549366,254.507611569343,0.0178838335603236,51.30873449237954,255.94117747962383,0.0056168991290211
0.0051874560556471,256.069538724836,0.0182321072500794,51.62361900692694,257.5399914157052,0.0057259712765765
0.0053049389374197,257.605140808186,0.0186051153997074,51.9331963869303,259.1146757285936,0.0058427765550104
0.0054317566033868,259.190552706421,0.019007761489153,52.25281542561447,260.74224788944,0.0059688474668642
0.0055648749472091,260.884927391122,0.0194304122307888,52.59440136205019,262.4814948506524,0.0061011648598667
0.0057037151730911,262.581986916508,0.0198712299479641,52.93652856236801,264.22539700854304,0.0062391510569699
0.005853345512804,264.246958725705,0.0203463062765526,53.27218687910213,265.9403286642501,0.0063878396819722
0.0060071016565775,265.908746380766,0.0208344820330334,53.607203270362426,267.653650632387,0.0065406051172181
0.0061639067966618,267.536418800615,0.0213323383528011,53.93534203020399,269.3339549919698,0.0066963758706303
0.0063264638429873,269.244782133436,0.0218484569748846,54.279748078100695,271.09756419269723,0.0068578349751756
0.0064930448045966,271.03482880912,0.0223773515279941,54.64062148791859,272.94507814473934,0.0070232637761455
0.0066651121997155,272.754909756554,0.0229236655074966,54.98738980692129,274.7242144232585,0.0071941123349158
0.0068438403991542,274.499740232257,0.0234911275407145,55.33914763082302,276.5307035102693,0.0073715436157401
0.0070198170735204,276.232433574276,0.0240498534818272,55.688458608574045,278.32482713471376,0.0075462125843923
0.0071957204666199,278.007461942919,0.0246083467549181,56.04630432769247,280.1622033677839,0.0077207783314699
0.0073815123661937,279.845310788726,0.0251982360360649,56.416814655007165,282.0662897477308,0.0079051243035508
0.0075655725132158,281.535595225073,0.02578262700286,56.75757599737472,283.82180852892066,0.0080877184968232
0.0077541225293377,283.263185247782,0.0263812733040471,57.10585814595285,285.6168367460487,0.0082747322353821
0.0079433577216755,284.856411987599,0.0269820950397196,57.42705265669996,287.27720656426766,0.0084623904090244
0.0081353508674052,286.393018597536,0.0275916732774114,57.73683254926326,288.8818572111029,0.0086527475698859
0.0083322571171456,287.972710667459,0.0282168506203372,58.05529847055974,290.53198089096685,0.0088479383385698
0.0085346505839195,289.480024727521,0.0288594498773443,58.35917298506824,292.1112796138569,0.0090485288197888
0.0087381552715829,290.788945623899,0.0295055772606756,58.62305143777804,293.4912749787514,0.0092501800624332
0.0089426320496321,292.080630261222,0.0301547910309818,58.88345506066236,294.8546870705841,0.0094527535952643
0.009145879414947,293.179163188117,0.0308001014158566,59.10491929872439,296.02324128550595,0.0096540685001046
0.0093525865563619,294.180130873642,0.0314563965898489,59.306714384126224,297.09472831163094,0.0098587687258326