File: example/data/02 processed data/test_ID_108.csv
Strain,Stress_MPa,Displacement(mm),Force(kN),True Stress (MPa),True Strain
2.87478828392049e-05,-0.227943921794082,9.127452801447555e-05,-0.045953494633686934,-0.22795047469923962,2.8747469626666203e-05
5.67129221798464e-05,0.714188874489251,0.00018006352792101233,0.143980477097033,0.7142293782273115,5.67113140628206e-05
0.0001064046571826,2.39123008468137,0.000337834786554755,0.48207198507176424,2.3914845226987755,0.00010639899660859283
0.0001443509554307,5.3022064006394,0.00045831428349247253,1.068924810368903,5.302971779199223,0.00014434053783398657
0.0002219237575396,8.64577524602088,0.0007046079301882299,1.7429882895978097,8.64769394895032,0.00022189913610517258
0.0002747325286503,11.9580936486865,0.0008722757784647025,2.4107516795751986,11.96137892599244,0.00027469479657980057
0.0002985581813739,15.178499257823,0.0009479222258621324,3.059985450377117,15.183030922957402,0.00029851362174896067
0.0003601477580259,18.5220093098263,0.0011434691317322324,3.734037076860982,18.52867996995337,0.0003600829203890997
0.0004391513777471,22.199184743324,0.0013943056243470426,4.475355644254119,22.208933545888893,0.0004390549790021889
0.0004903760322337,26.2527729580304,0.0015569439023419974,5.292559028338928,26.26564668866869,0.0004902558371994175
0.0005923694359909,30.5968541761146,0.0018807729592711074,6.168325801904704,30.614978817365998,0.0005921940544735037
0.0006646566370755,35.1702535991935,0.0021102848227147124,7.0903231255974095,35.193629741675835,0.0006644358506790084
0.0007271473772669,39.8173411661771,0.0023086929228224077,8.027175979101305,39.84629424137583,0.0007268831337010974
0.0008005381585136,44.4933358352253,0.0025417086532806797,8.969856504381422,44.52895444836096,0.0008002178987507554
0.0008634438803258,49.0666178477677,0.002741434320034415,9.891830158109968,49.108984118676645,0.0008630713270957652
0.0009107461703019,53.6231436514014,0.0028916190907085325,10.810425760122524,53.67198072412147,0.0009103316926454658
0.0009936177770488,58.2115193819488,0.0031547364421299394,11.735442307400879,58.269359382435724,0.0009931244656537096
0.0010669989113862,62.878460511553,0.0033877215436511846,12.676297639129084,62.945551760468476,0.0010664300726454224
0.0011772425717016,67.6912697266257,0.0037377451651525793,13.646559976887744,67.77095877108043,0.0011765501650324117
0.001261281224113,72.4875248570548,0.004004567886558775,14.613485011182247,72.57895201113942,0.0012604864771460073
0.0013368957903846,77.282417358829,0.004244644134471105,15.580135339539925,77.38573589726676,0.001336002940883268
0.0014225920295496,81.9978511706576,0.0045167296938199795,16.530766796004574,82.11450066017318,0.0014215811041510744
0.0015125635928928,86.7547385113598,0.00480238940743464,17.489755283890137,86.88596057034302,0.0015114208207800143
0.0015991923684988,91.4184918383657,0.00507743576998369,18.429967954614526,91.56468759285328,0.0015979150220169164
0.0016797005383156,96.0650234314554,0.005333049209152029,19.36670872378141,96.22638390302652,0.0016782914190779108
0.0017548129287739,100.586172138023,0.005571531048857132,20.27817230302544,100.76268205334668,0.0017532750434375876
0.0018380138812196,105.056401117246,0.00583569407287223,21.179370465236794,105.24949624081046,0.0018363268006410904
0.00190789116907,109.469484630972,0.0060575544617972495,22.069048101603958,109.67834049398208,0.0019060734563449582
0.0019909189436518,113.769422627259,0.006321167646094464,22.935915601655417,113.99592832597594,0.0019889396911172037
0.0020625805416669,118.057690810813,0.006548693219792408,23.8004304674599,118.30119430667352,0.002060456342807532
0.0021504449697156,122.148750144069,0.006827662778847029,24.625188029044313,122.41142430937336,0.002148136072443573
0.0022185348021465,126.287083134122,0.007043847996815137,25.459475959838997,126.5672554231166,0.002216077487566378
0.0022968786802178,130.241212240976,0.007292589809691515,26.256628387780765,130.54036050465803,0.0022942448866138726
0.0023653416553767,134.097571740593,0.007509959755821022,27.034070462903546,134.41475831291586,0.002362548638229434
0.0024370994419512,137.942441940768,0.007737790728195059,27.809196295258825,138.27862138904322,0.0024341345313171345
0.0024970674982832,141.665083366972,0.007928189307049159,28.559680806781557,142.01883064228923,0.002493955005563845
0.0025800117128943,145.344068098599,0.008191537188439402,29.301364128677555,145.71905749669307,0.002576689196202565
0.0026434055221673,148.945400074211,0.008392812532881176,30.027392654960938,149.33912316726858,0.002639917870622942
0.0027229878863634,152.399409973673,0.008645486539203794,30.723721050692475,152.81439172092024,0.0027192872711469538
0.0027882095072642,155.854715778515,0.008852565185563835,31.420310700948622,156.2892713788006,0.002784329661345004
0.0028638282430604,159.181060022402,0.00909265467171677,32.09090170051624,159.63692723785445,0.002859735299420541
0.0029434902615301,162.476986398684,0.009345581580358068,32.755360457974696,162.9552358258713,0.002939166676279847
0.0030175862831074,165.63990507615,0.009580836448865995,33.39300486335184,166.13973778164302,0.0030130425081465314
0.0030997932516019,168.707092065843,0.009841843573836032,34.01134976047395,169.23004917132607,0.003094998797822424
0.0031832308441633,171.70253670011,0.010106757930218478,34.615231398742175,172.24910551095485,0.003178175091104437
0.0032800293076136,174.508744145264,0.010414093051673179,35.18096281968522,175.0811379404953,0.003274661745455753
0.0033784668140272,177.191671296077,0.01072663213453636,35.72184093328912,177.7903074772728,0.0033727726165209485
0.0034996883348665,179.54167616884,0.011111510463201137,36.19560191563815,180.1700160785505,0.0034935786760975154
0.0036478148846337,181.654296000639,0.011581812258711997,36.62150607372882,182.31693724544778,0.0036411777437280373
0.0038364016868329,183.345760345234,0.012180575355694457,36.96250528559917,184.04914832949612,0.0038290614652508677
0.0040787119841917,184.628422556468,0.012949910549808647,37.22108998738395,185.38146871617147,0.00407041658717335
0.0043379133728636,185.552998971839,0.013772874958841929,37.407484592722746,186.3579118074539,0.004328531747980649
0.0046183289273741,185.991109107617,0.014663194344412767,37.49580759609559,186.8500772270431,0.004607697167741595
0.0049032713784649,186.213113160043,0.015567886626626056,37.54056361306467,187.1261665880955,0.004891289494350305
0.0052167013331282,186.353649999748,0.016563026732682035,37.5688958399492,187.32580133413498,0.005203141484737265
0.0055495533618913,186.402137747814,0.01761983192400488,37.578670969959305,187.43658635801611,0.005534211325427258
0.0058966809602654,186.424224049047,0.018721962048842643,37.58312356828788,187.52350822152928,0.005879363580453629
0.0062548178368493,186.35739329564,0.019859046631996526,37.569650488401024,187.52302484325432,0.006235337651570913
0.0066063876124667,186.283231023991,0.02097528066958177,37.55469937443659,187.51389025383816,0.00658466107063293
0.0069730514726819,186.245168206961,0.022139438425765032,37.54702591052334,187.54386535140642,0.00694885217941224
0.0073305004928254,186.225425678919,0.023274339064720644,37.54304581687007,187.59055125363497,0.007303762960904888
0.0077005758745979,186.203613944364,0.024449328401848328,37.538648571183785,187.6374890016669,0.00767107777830254
0.0080738463870721,186.167983715372,0.025634462278953912,37.531465517018994,187.67107541808087,0.008041427270406935
0.0084464446042159,186.118493692397,0.026817461618385482,37.521488328387235,187.69053323918993,0.008410972990376625
0.0088174537430613,186.056484893123,0.027995415634219624,37.5089873544536,187.6970293422647,0.008778807008853341
0.0091844530699153,185.994768474761,0.029160638496981073,37.49654532451182,187.7030286970672,0.009142532463879968
0.0095553015449796,185.964481234188,0.03033808240531023,37.49043941681231,187.74142792903638,0.009509938394622936
0.0099294174356657,185.898415852017,0.0315259003582386,37.47712063576663,187.74427882364063,0.009880444684122962
0.010290764800934,185.861414263473,0.03267317824296545,37.46966111551615,187.77407036322737,0.010238175363480732
0.0106477085886038,185.755341701573,0.03380647476881706,37.44827688703712,187.7332104487879,0.010591420943275984
0.0110084776715835,185.645753087396,0.03495191660727761,37.426183822419034,187.68943021508292,0.010948325435010188
0.0113656172175403,185.605152142606,0.03608583466569045,37.41799867194937,187.71466925546218,0.011301513849133775
0.0117464720889323,185.631116307682,0.03729504888236005,37.42323304762869,187.8116270342275,0.011678017828230174
0.0121180002510724,185.684879664072,0.03847465079715487,37.43407174027692,187.9350090824616,0.01204516510651012
0.0125048383180218,185.678193126811,0.039702861659719216,37.4327237343651,188.0000689110442,0.012427298572840232
0.0128844448534464,185.6127780763,0.04090811240969232,37.41953606018208,188.0042956795191,0.012802146551965687
0.0132587332235193,185.53969659355,0.04209647798467377,37.40480283325968,187.99971793305656,0.013171605510621881
0.0136391146659089,185.484456193707,0.043304189064260756,37.39366636865133,188.01429996047673,0.013546939124253506
0.0140061212098188,185.458860152075,0.04446943484117469,37.38850620665832,188.0564194267998,0.013908941846844424
0.0143799208592699,185.39998246064,0.04565624872818193,37.37663646406502,188.06601953573403,0.014277510399309174
0.0147547727273131,185.278276098675,0.04684640340921909,37.35210046149288,188.01201495381935,0.014646980078667849
0.0151439203099716,185.248071969831,0.04808194698415983,37.34601130911793,188.05345400931802,0.015030395850854535
0.0155246727746719,185.19347539753,0.04929083605958328,37.335004640142046,188.0685435030809,0.015405397926977423
0.0159130236074197,185.245885817362,0.05052384995355754,37.345570580780176,188.19370797155105,0.015787738806218112
0.0162908796396491,185.2220962223,0.05172354285588589,37.34077459841568,188.23952709846097,0.016159607038515083
0.0166622269006502,185.117773668531,0.05290257040956438,37.319743171575844,188.20224801673928,0.016524934958708274
0.0170500528685858,185.05945382533,0.054133917857759915,37.307985891186526,188.21472729688347,0.01690633204864544
0.0174233391602633,184.981494110209,0.05531910183383597,37.29226921261814,188.20448942046346,0.0172732931476002
0.0177875248120756,184.910269248651,0.056475391278340024,37.27791028052804,188.19936525091896,0.017631178084386044
0.0181779279734096,184.825165849717,0.05771492131557548,37.260753435302945,188.18490440220663,0.01801468475497794
0.0185694781568799,184.776997620433,0.05895809314809367,37.251042720279294,188.2082100416395,0.01839917051606487
0.0189541441067707,184.774182891456,0.06017940753899697,37.25047527091753,188.27641938119146,0.018776752351443507
0.0193670612400467,184.742023121837,0.061490419437148267,37.243991861362346,188.31993319724776,0.01918190649284309
0.0197485614866742,184.674328634431,0.06270168272019058,37.23034465270129,188.3213809684783,0.01955608856160533
0.0201396660456791,184.616922571691,0.06394343969503113,37.2187715904529,188.33504573866585,0.01993954541822974
0.0205348528644443,184.554487175995,0.06519815784461065,37.206184614680595,188.344286415627,0.02032685541798045
0.020926003378176,184.464745796541,0.0664400607257088,37.18809275258267,188.3248556902338,0.020710061902025675
0.021317340325167,184.341244954941,0.06768255553240522,37.16319498291611,188.27091000961045,0.02109330413707799
0.0216935274582973,184.249666162268,0.06887694968009392,37.14473269831323,188.24669135434127,0.021461571524505025
0.0220905626361449,184.189566930266,0.07013753636976006,37.13261669314163,188.25841809546347,0.02185010100251258
0.0224802291883462,184.201620133498,0.07137472767299918,37.1350466189132,188.34251477096373,0.022231272990762902
0.0228767499295862,184.18059949829,0.07263368102643619,37.13080885885527,188.39405301489364,0.022619000659092444
0.0232684855150466,184.14178052152,0.07387744151027295,37.12298295313843,188.42648087429987,0.02300190171954584
0.0236734638616126,184.088201314961,0.07516324776062,37.112181385096136,188.44620669613997,0.023397592815693594
0.0240760698695337,183.984749335729,0.0764415218357695,37.09132546608297,188.41437901566465,0.023790810840141348
0.0244551251958649,183.870721004478,0.07764502249687105,37.068337354502766,188.36730250649646,0.02416088607411429
0.0248640680006791,183.753897024063,0.07894341590215613,37.0447856400511,188.3227664150591,0.024559987211311373
0.0252618749982964,183.626584096716,0.08020645311959107,37.01911935389795,188.2653359105314,0.024948067762136608
0.0256641013180737,183.552910899466,0.081483521684884,37.004266837332345,188.26363140201724,0.025340306516317784
0.0260600837884017,183.496352358492,0.08274076602817539,36.99286463547199,188.2782826758204,0.025726306231210475
0.0264532229567743,183.461182592189,0.0839889828877584,36.98577441058531,188.31432215921365,0.026109386985803673
0.0268536712671809,183.422017375287,0.08526040627329935,36.977878702857865,188.3475719330461,0.02649943906872442
0.0272577821754041,183.355870307167,0.08654345840690801,36.96454345392487,188.3537446805814,0.02689290448926856
0.0276596545039481,183.26794360856,0.08781940305003522,36.94681743148569,188.3370716104218,0.02728403683015394
0.0280707334946725,183.157193656954,0.08912457884558518,36.92449024124193,188.2985504277305,0.02768397156731959
0.0284814788418786,183.01746270305,0.09042869532296455,36.89632048093488,188.2300706947212,0.02808342201667227
0.0288760923019219,182.911176770849,0.09168159305860203,36.874893237003164,188.19293679433721,0.028467033956976126
0.0292842545431982,182.82708758172,0.09297750817465428,36.857940856474755,188.1810425518547,0.02886366218592108
0.0296877442419586,182.816092098596,0.09425858796821855,36.85572416707695,188.24348948413345,0.029255595348842662
0.0300917169939107,182.758390178605,0.09554120145566647,36.844091460006766,188.2579039341223,0.029647843902374155
0.0305014770723866,182.686284746034,0.09684218970482744,36.829555004800454,188.25848627165465,0.030045554702406763
0.0308994929430465,182.611275128839,0.09810589009417263,36.814433065973944,188.25387093600327,0.03043171526155584
0.0313042480739159,182.530631920532,0.09939098763468299,36.79817539517925,188.24461610326094,0.030824261476089753
0.0316948058123876,182.441361464823,0.10063100845433062,36.78017847130831,188.22380498859818,0.031202892520444246
0.0321047670490626,182.293127674792,0.10193263538077375,36.75029453923807,188.14560607343623,0.03160018036511503
0.0325341288773629,182.176958783974,0.1032958591856272,36.72687489084916,188.1039274395378,0.03201609990953216
0.032948379240873,182.086178107405,0.10461110408977177,36.70857350645285,188.0856225582089,0.03241721719562499
0.0333526398457501,182.02527838834,0.10589463151025656,36.69629612308935,188.0963019412487,0.03280850637014585
0.0337685593694478,182.005726386088,0.10721517599799676,36.69235443943534,188.1517975631361,0.033210920635423136
0.0341726510011438,181.929686042475,0.10849816692863155,36.67702470616296,188.14670571035214,0.033601736036569615
0.0345837448808605,181.872753947279,0.10980338999673209,36.665547195771445,188.1625948705712,0.03399916696265275
0.0350090772761678,181.776989995238,0.11115382035183277,36.64624118303998,188.14083468501047,0.034410196994011336
0.0354265304617735,181.672036670222,0.11247923421613085,36.62508259271676,188.1080466113721,0.03481344855102915
0.0358584129266935,181.56297493763,0.11385046104225185,36.60309574742621,188.07353506514244,0.03523046743832161
0.0362796544899213,181.467724842918,0.11518790300550012,36.583893328332266,188.05131120129116,0.03563704417725079
0.0366904380129182,181.384678731622,0.11649214069101528,36.56715123229499,188.03976204311766,0.03603336781921697
0.037113210639527,181.282934019178,0.11783444378049822,36.54663949826628,188.01092573478323,0.03644109459001362
0.0375307386422188,181.162858668828,0.11916009518904468,36.522432307635725,187.962034569205,0.036843600290785296
0.0379500301175292,181.043208200761,0.1204913456231552,36.498310773273424,187.91380340455402,0.03724764304302452
0.0383828278483551,180.957067411092,0.12186547841852745,36.480944790076144,187.90271137747513,0.037664529704942475
0.0388186973549987,180.892051803113,0.12324936410212088,36.46783764350758,187.9140456159828,0.038084199638506656
0.0392602658033332,180.813141605724,0.1246513439255829,36.451929347713964,187.91191360590045,0.03850917719018665
0.0397031343401158,180.701541440993,0.12605745152986764,36.42943075450419,187.87595901629072,0.03893522465542917
0.0401212229705695,180.587151794795,0.12738488293155814,36.40636980183068,187.83252917757403,0.039337266909252815
0.040549638429193,180.437353428064,0.12874510201268777,36.3761704510977,187.75402286869252,0.039749072036748795
0.040955715124269,180.399418194266,0.13003439551955406,36.368522707964026,187.7878053744142,0.04013924802119621
0.0413841211109763,180.285058601578,0.13139458452734976,36.34546781407813,187.74599730124513,0.04055071399355739
0.0418160551428718,180.237758415671,0.13276597507861795,36.33593209659928,187.77459046040832,0.04096539717475998
0.04224925673841,180.138712751826,0.13414139014445173,36.315964490768124,187.7494394754046,0.0413811246467424
0.0426779448080698,180.037981576346,0.1355024747656216,36.295657085791355,187.72163261741758,0.04179235058823617
0.0431115714664477,179.95927808494,0.13687923940597144,36.2797904619239,187.7176053631492,0.04220814198160694
0.0435325372952405,179.782803400317,0.13821580591238858,36.24421316550391,187.60920499438416,0.04261162797400626
0.0439810164342945,179.648851579171,0.13963972717888504,36.217208478360874,187.54999067287665,0.043041305803070126
0.0444205818243695,179.537735394481,0.14103534729237313,36.19480745552737,187.51290606013353,0.04346226448930434
0.0448535147300492,179.473159279018,0.1424099092679062,36.18178891065003,187.5231612723879,0.04387669829920064
0.0452959401051042,179.452529659826,0.14381460983370584,36.17762997942093,187.58100069500694,0.04430004159710611
0.0457264281568682,179.364664606156,0.14518140939805652,36.159916384601054,187.56637005615013,0.04471179047591282
0.0461809663698119,179.249531039494,0.14662456822415276,36.136705457561995,187.52744760423343,0.04514635868030491
0.0466177028550373,179.182834693838,0.14801120656474342,36.123259474277745,187.5359268383186,0.045563729446052775
0.047061244588901,179.021914045729,0.14941945156976066,36.090817871618974,187.44690812940826,0.045987425486976874
0.0475057133133303,178.869314775276,0.1508306397698237,36.060053858695646,187.3666291635421,0.04641182703635096
0.0479444482180456,178.753215811732,0.15222362309229479,36.03664830764517,187.32344011102668,0.04683057706837814
0.0484075046695015,178.642452355271,0.15369382732566725,36.01431839482263,187.29008770182995,0.04727235065353306
0.0488401786615081,178.622661703167,0.15506756725028822,36.010328599358466,187.3466244137438,0.04768496190740072
0.0492914961073493,178.500383187114,0.15650050014083403,35.98567725052219,187.29893413014202,0.04811517080060748
0.0497437504901086,178.364778262781,0.1579364078060948,35.95833929777665,187.2373112889083,0.04854608723280225
0.0501742727943515,178.227574911501,0.159303316122066,35.9306791021586,187.17001387458637,0.04895612448711518
0.0506139830536709,178.026027734672,0.1606993961954051,35.890047191309876,187.03663408554704,0.049374739037645506
0.0510474940971808,177.927757630779,0.16207579375854902,35.87023593836505,187.0105237881608,0.04978728030974974
0.0515015035802556,177.845183756868,0.16351727386731152,35.853589045384595,187.00447812485353,0.050219146098021604
0.051972494285408,177.837063542278,0.16501266935617037,35.85195201012325,187.0796993109628,0.050666967857170196
0.0524226656990931,177.832944962005,0.1664419635946206,35.85112170434021,187.15542198603342,0.05109480710439148
0.0528780785345143,177.734590160404,0.1678878993470829,35.83129337633744,187.13285377720553,0.05152744158074535
0.0533381780288643,177.597116231424,0.16934871524164413,35.803578632255075,187.0698228343886,0.0519643383146252
0.0538041687823788,177.458448572586,0.1708282358840527,35.775623232233336,187.0064528914445,0.05240663473737647
0.0542798036383205,177.280259476258,0.1723383765516676,35.73970031041362,186.90299714957982,0.0528578832362364
0.0547548511779526,177.162864927735,0.17384665248999948,35.716033569431374,186.86339123111284,0.053308371374571166
0.055217566846809,177.015785330216,0.17531577473861856,35.686382322571546,186.7901662896276,0.053746970166025705
0.0556717613708371,176.901376940625,0.17675784235240777,35.663317591230005,186.74978818383596,0.05417730493058767
0.0561255450909313,176.820180642024,0.17819860566370688,35.64694841743204,186.74430966363454,0.05460706561423847
0.0565978189207409,176.722350959808,0.17969807507335236,35.627225953497295,186.72445057867887,0.05505414150284829
0.0570641539573185,176.637842447334,0.18117868881448623,35.61018903738254,186.71753148343723,0.05549539942405608
0.0575573525036518,176.552564430466,0.18274459419909445,35.59299698918194,186.71446261681405,0.05596186451368981
0.0580226724944787,176.418490889405,0.18422198516996985,35.56596776330405,186.65476320825115,0.05640176278539994
0.0584910034543316,176.315252616894,0.18570893596750282,35.54515492756583,186.6281086667601,0.056844312222068594
0.0589491041193693,176.217135824345,0.18716340557899752,35.52537458218796,186.60497811167136,0.05727700514268195
0.0594047102948888,176.084984378192,0.18860995518627194,35.498732850643506,186.5452618624585,0.057707156309540236
0.0598644534072923,175.951441691674,0.19006963956815304,35.47181064504148,186.48467857477112,0.05814102580331649
0.0603484195747326,175.776865264208,0.191606232149776,35.436616037264336,186.38472128070367,0.05859755182672952
0.06082380550036,175.65664834517,0.193115582463643,35.412380306386275,186.34075415896177,0.0590457812802052
0.0613171827170382,175.611957768237,0.19468205512659625,35.403370686076585,186.3799882700088,0.05951076190902
0.0617941723669253,175.573040268503,0.1961964972649878,35.39552491813021,186.42243098184,0.0599600927053253
0.0622736253752996,175.540984580786,0.19771876056657622,35.389062491486456,186.4725580925811,0.0604115406459483
0.0627654479181057,175.460119719841,0.1992802971399856,35.37276013551995,186.47295272582127,0.06087442394797193
0.0632646689507999,175.359085718413,0.20086532391878964,35.35239168083206,186.45312022390334,0.06134405138919055
0.0637517274671647,175.23445961641,0.20241173470824791,35.327267058668255,186.40595912873124,0.06180202484505856
0.0642486901140452,175.067829570578,0.2039895911120935,35.29367444142853,186.31570830159652,0.06226909491873825
0.0647442843983572,174.949796272852,0.20556310296478408,35.26987892860697,186.2767956381762,0.06273466178457293
0.0652469646659697,174.832157819919,0.2071591128144538,35.24616301649567,186.23942544367048,0.06320666398379868
0.0657554570717691,174.727209557222,0.20877357620286685,35.225005446735956,186.21647708453193,0.06368389705520512
0.0662638068485753,174.607379697261,0.21038758674422658,35.20084774696782,186.17752937985614,0.06416076871864863
0.0667686581460347,174.486966725537,0.21199048961366018,35.176572491868264,186.13722735777293,0.06463413357846362
0.0672712309999145,174.366303345285,0.21358615842472853,35.152246754409454,186.09613921622685,0.06510513964140295
0.0677702450639188,174.239937407847,0.21517052807794215,35.12677138142196,186.04822066589867,0.06557259105036654
0.0682664321019383,174.042157524862,0.2167459219236541,35.08689895701218,185.92339465440787,0.0660371776862128
0.0687548679973907,173.827010190094,0.21829670589171543,35.04352525432295,185.77846333009498,0.06649429610981926
0.0692318876989094,173.601505929166,0.21981124344403732,34.99806359531986,185.62026589201557,0.06694052872390187
0.0697138984870784,173.475146335646,0.22134162769647392,34.972589501266235,185.5687750773203,0.06739122812866598
0.0702082298822016,173.415392510736,0.22291112987599007,34.96054313016438,185.59058025324197,0.06785323690680112
0.0707024117722604,173.366313224389,0.22448015737692675,34.950648746036826,185.6237296894184,0.06831489269870639
0.0712085627424471,173.351630082812,0.22608718670726954,34.9476886246949,185.6957505100694,0.06878750896112858
0.0717110484355989,173.28543328863,0.2276825787830265,34.93434335098781,185.7119133883747,0.06925648194522034
0.0722058237251646,173.215058800397,0.22925349032739759,34.920155854160036,185.72219480268248,0.06971804396264211
0.0727165767121466,173.108398192574,0.23087513106106544,34.89865307562292,185.69624830926114,0.07019428776198101
0.0732323558973293,172.985820326913,0.2325127299740205,34.873941377905666,185.65397948628495,0.07067498810603563
0.0737601806742677,172.847070357345,0.23418857364079995,34.84596938404075,185.59630149592059,0.07116667569095371
0.0742682738413849,172.707130454659,0.23580176944639705,34.81775749965926,185.53379091362538,0.07163975431849727
0.0748023713957494,172.574309452854,0.23749752918150432,34.79098078569537,185.48327704191138,0.07213680411678491
0.0753188493638735,172.46177421709,0.23913734673029832,34.76829368216534,185.45139661037337,0.07261722166075513
0.075858962387848,172.351574520239,0.2408522055814174,34.746077423280184,185.42598612925622,0.07311937730067815
0.0763632533347823,172.23964703499,0.24245332933793382,34.72351284225399,185.39242683581642,0.073588000802916
0.0768902568707806,172.106929153886,0.2441265655647284,34.69675691742342,185.3402751457695,0.07407749592647975
0.0774343388724799,171.971813640372,0.24585402592012368,34.669517629899,185.28833733431551,0.07458260273753518
0.0779786896201833,171.804837851028,0.24758233954408196,34.63585531076724,185.20195397705922,0.07508770385001878
0.0785035350477728,171.615716502493,0.24924872377667862,34.597728446902586,185.0881569176951,0.07557446458650774
0.0790110564332012,171.454828439052,0.25086010417541377,34.56529341331289,185.00165556459476,0.07604493314954193
0.0795050780947184,171.188324303441,0.25242862295073093,34.511566179573705,184.79866539609006,0.07650267507904687
0.0800092722491386,171.024015955248,0.2540294393910151,34.478441616577996,184.70752300895245,0.0769696265151429
0.080523628283053,170.922967487766,0.25566251979869326,34.45807024553363,184.6863049867872,0.07744576464153305
0.0810668628906407,170.910434421632,0.25738728967778424,34.45554357940102,184.7656071754703,0.07794838955706858
0.0816058140674075,170.917354722646,0.2590984596640188,34.45693871208544,184.86520459303537,0.07844680172425944
0.0821551017124616,170.833052275356,0.26084244793706557,34.43994333871177,184.86785906088815,0.07895451738992997
0.0826744790269085,170.648856978875,0.26249147091043445,34.402809566941194,184.7571623261409,0.07943434945526477
0.0831700902483363,170.466690870962,0.26406503653846775,34.36608487958594,184.64442093503516,0.07989201039465924
0.0836877512316572,170.305009769755,0.2657086101605116,34.33348996958261,184.5574530608712,0.08036980915308209
0.0842232360590316,170.202669401891,0.26740877448742534,34.312858151421224,184.53768900480378,0.08086381913910451
0.0847857921194174,170.141028133321,0.26919488997915025,34.30043127167751,184.56656997561672,0.0813825408831743
0.0853479848418697,170.032625463284,0.2709798518729363,34.27857729339806,184.54456740394767,0.08190065892824332
0.0859018554415773,169.90360717553,0.2727383910270079,34.252567206586846,184.49864227812492,0.0824108449063335
0.0864492917196985,169.757778178847,0.27447650121004274,34.22316808085555,184.43321786631802,0.08291484840542243
0.0869924993683203,169.615048634495,0.27620118549441697,34.19439380471419,184.3702856456889,0.08341470781013198
0.0875458812258194,169.483517017932,0.27795817289197655,34.16787703081509,184.32110086851802,0.08392367272368197
0.0880943968116047,169.366034759941,0.27969970987684495,34.144192607604104,184.2862334324913,0.0844279064455378
0.0886396755598818,169.205353402484,0.2814309699026247,34.11179924594077,184.2036610310753,0.08492891276193051
0.08918932971023,169.024161294189,0.28317612182998025,34.07527091690851,184.09931294485153,0.08543368532275959
0.0897411762778682,168.865362446234,0.28492823468223155,34.04325706916078,184.0195387047476,0.08594021508855125
0.0902889068554686,168.678631745393,0.2866672792661128,34.005612159871234,183.9084410155607,0.08644271328191436
0.0908308714871967,168.585077639392,0.28838801697184946,33.98675165210143,183.89780716111468,0.08693967328224393
0.0913764509183277,168.46098873585,0.29012023166569045,33.961735329147366,183.85435600472437,0.08743969858863605
0.091924897713281,168.325907056563,0.29186155023966714,33.934502862603104,183.7992488452328,0.08794209996976741
0.0924657112076043,168.193057459069,0.2935786330841436,33.90772038374831,183.74514813720327,0.08843726187273913
0.0930145289300426,168.069753775536,0.29532112935288524,33.88286236114806,183.7026827503557,0.08893950181423593
0.0935579268391645,167.884929598168,0.29704641771434726,33.845601806990665,183.59189555891166,0.08943653352144039
0.0940895935420907,167.726212436162,0.29873445949613797,33.81360442713026,183.50750359063483,0.0899225960232287
0.0946716384558161,167.529997290077,0.30058245209721607,33.77404745367952,183.39033662402704,0.09045444474106633
0.0952238179088158,167.380744884743,0.3023356218604902,33.74395816876419,183.31937845708973,0.09095874229837408
0.0957974228143896,167.314648664084,0.30415681743568695,33.73063317067933,183.3429608051983,0.09148233824351341
0.096361124670893,167.217181898814,0.30594657083008525,33.71098387080091,183.33041761088103,0.0919966275676818
0.0969176388569639,167.089206704912,0.3077135033708604,33.68518407171025,183.28309809723524,0.09250409994854675
0.097481313740727,166.883921486749,0.3095031711268082,33.643798571728595,183.1519853954816,0.09301783961789283
0.0980313375121732,166.654268800298,0.3112494966011499,33.59750059014008,182.99160967290447,0.0935188832193854
0.0985840742676673,166.471854190237,0.31300443579984366,33.560725804751776,182.8833278272036,0.09402214543287618
0.0991495910941901,166.319435272877,0.31479995172405356,33.52999815101201,182.8099392711994,0.0945367818038954
0.0997076704367892,166.194235254587,0.3165718536368057,33.50475782732474,182.76507529184556,0.09504439033706014
0.100279046597827,166.072516829566,0.3183859729481007,33.48021939284051,182.72611048333647,0.09556382635861486
0.100815812292284,165.905523898829,0.32009020402800165,33.446553618003925,182.63142405446638,0.09605155245813249
0.101354582494784,165.529653891039,0.3218007994209392,33.370778224433465,182.30684285167135,0.09654086083728859
0.101885454076611,165.286679105686,0.3234863166932399,33.3217945077063,182.1269874591839,0.09702276165906815
0.102440342413489,165.069809717677,0.32524808716282755,33.27807363908368,181.9796175472853,0.09752621568522161
0.10299807658929,165.038587726471,0.32701889317099575,33.27177928565656,182.03724482531032,0.09803199647047052
0.103595058395175,165.038249928876,0.3289143104046806,33.27171118566141,182.1353970676954,0.09857308563728197
0.104152821434442,164.915662531318,0.33068520805435336,33.24699756631371,182.09209408268507,0.09907836348737484
0.104705748459017,164.713658736598,0.332440751357379,33.20627360129816,181.9601256560366,0.0995790085206607
0.105255936521148,164.460837854635,0.33418759845464485,33.15530491149442,181.77131736407728,0.10007692491191514
0.105813449063589,164.246669613845,0.3359577007768951,33.11212859415115,181.62617622289372,0.10058121714072599
0.106384647335401,164.073930583577,0.33777125528989815,33.07730440564912,181.52887782564392,0.10109762503876708
0.106956541536709,163.895238123016,0.33958701937905106,33.04128000560002,181.42490596698917,0.10161439508480459
0.107503258843121,163.699125617032,0.3413228468269091,33.00174372439365,181.29731509063237,0.10210816545482991
0.108078680772707,163.497475800101,0.3431498114533447,32.96109112130036,181.1680672942435,0.10262759733160678
0.108625609453496,163.310108128276,0.34488631001484976,32.92331779866044,181.04976815362633,0.10312105845251394
0.10921166299804,163.14009007798,0.346747030018777,32.88904215972077,180.95689061704624,0.10364954948786985
0.109786682358024,162.931105298508,0.34857271648672616,32.84691082817921,180.81877080215705,0.10416781879983977
0.110366786980577,162.707467847487,0.35041454866333194,32.801825518053384,180.66496829155972,0.10469039946263302
0.110931077451759,162.457192862981,0.3522061709093348,32.75137008117697,180.47874430705969,0.10519847223608317
0.111496152037258,162.202516000627,0.35400028271829415,32.70002722572641,180.2874723854587,0.10570699246133795
0.112043473066576,161.968410588866,0.3557380269863788,32.652831574715385,180.11591383831572,0.10619928954855215
0.112580874300077,161.669491837572,0.35744427590274447,32.59256955445452,179.870384576295,0.10668242841610119
0.113119717712425,161.422125331047,0.35915510373694937,32.54270046673908,179.68215058103473,0.10716662959285388
0.113653132844531,161.220875917848,0.3608486967813859,32.50212858503816,179.5441335458508,0.10764572214347069
0.114203527998426,161.088982681959,0.36259620139500254,32.475538908682935,179.48591282591607,0.10813982499556749
0.114758412414643,160.904394447064,0.3643579594164915,32.4383259205281,179.36952730434857,0.10863771095550165
0.115325065652931,160.70914533866,0.3661570834480559,32.39896370027385,179.2429380758674,0.10914590112511287
0.115903646274712,160.467560672272,0.3679940769222106,32.35026023153004,179.0663360629969,0.10966452176821985
0.116482233100635,160.231612128156,0.36983109009451615,32.30269300503625,178.8957481221584,0.11018287914023484
0.117045163795886,159.967570778272,0.37161839505193806,32.24946226889964,178.69100130204484,0.11068695239042448
0.117581288827556,159.599975770255,0.3733205920274903,32.17535511528341,178.36594661816832,0.11116678654017875
0.118122854690755,159.275972607879,0.37504006364314707,32.110036077748404,178.09010517596815,0.1116512566122691
0.118686316461145,159.02333065323,0.37682905476413536,32.05910345969117,177.89722399984456,0.11215506515309169
0.119259552121937,158.831298439734,0.3786490779871499,32.020389765450375,177.7734479546024,0.11266735249781792
0.119823675505722,158.608763372565,0.3804401697306673,31.975526695909103,177.61384836728308,0.11317124032901633
0.120381356484935,158.328168899238,0.3822108068396686,31.91895885008638,177.38792864110417,0.11366912421265139
0.120942052367076,158.017477054307,0.3839910162654663,31.856323374148293,177.1284350391222,0.11416944995022488
0.121484552292903,157.712470272729,0.385713453529967,31.79483400698217,176.8720991148193,0.11465330073515907
0.122018972737184,157.338588794763,0.38741023844055916,31.719459501024225,176.53688177141822,0.11512971670547231
0.122557032959862,157.000060576111,0.38911857964756186,31.651212212143978,176.24152217483777,0.1156091482164735
0.123095475403297,156.698042020045,0.390828134405468,31.590325271241074,175.98686199726822,0.11608869031103004
0.123654309845033,156.403488765192,0.39260243375797976,31.530943335062712,175.74345422580717,0.11658615064856259
0.124197416880675,156.134652919446,0.3943267985961431,31.476746028560317,175.52617349760195,0.11706937384318261
0.12473950003634,155.740245583788,0.39604791261537947,31.397233509691663,175.16720595344654,0.11755145332001075
0.125286356886398,155.406322472629,0.3977841831143136,31.329914610482007,174.87661445233746,0.11803754272128866
0.125842435444167,155.099547884707,0.39954973253523024,31.26806885355693,174.6176527268077,0.11853158692788769
0.126402682158061,154.804079407593,0.40132851585184365,31.208502408570755,174.37173025372223,0.11902908759606182
0.126961355242707,154.488978684077,0.4031023028955947,31.144978102709924,174.10310878786908,0.11952494453423965
0.127501477861242,154.066233981423,0.4048171922094433,31.059752770654878,173.70990650257033,0.12000410313551539
0.128033941448527,153.575275727535,0.40650776409907324,30.96077558667106,173.2381235879756,0.12047624255981149
0.128591965420648,153.149313681414,0.40827949021055737,30.87490163817306,172.84308493053035,0.12097080746026442
0.129143699701344,152.687389007443,0.4100312465517672,30.781777623900506,172.4060033216025,0.12145955758296688
0.12969500699642,152.329661354568,0.4117816472136335,30.709659729080908,172.08605784971098,0.12194769098035216
0.130241411819831,151.952293653554,0.4135164825279634,30.633582400556485,171.7427749082544,0.12243124868534655
0.130786704971508,151.522957107823,0.41524778828453784,30.54702815293712,171.3401453954943,0.12291358957991515
0.131335278841198,151.152359376199,0.4169895103208036,30.47231565024172,171.00399664237707,0.12339859780172568
0.131888355115997,150.661103182462,0.41874552749329047,30.37327840158434,170.53154826115843,0.12388734869448804
0.132431301316426,150.166310735235,0.42046938167965253,30.273528244223375,170.05303067978895,0.12436691544584519
0.132938007117729,149.516812132016,0.42207817259878955,30.14258932581443,169.39327916744213,0.12481426485405583
0.133477801422212,149.004037673995,0.42379201951552303,30.03921399507739,168.89276902575227,0.12529060667328923
0.134034048884635,148.541309485182,0.42555810520871606,29.94592799221269,168.45090262210658,0.12578123032626431
0.134607108498468,148.095593632944,0.42737756948263583,29.856071676401513,168.0303132732387,0.1262864310929491
0.135158948239665,147.623631888014,0.4291296606609364,29.760924188623623,167.57628670931746,0.12677268363023783
0.135718023379024,147.081200175686,0.43090472422840115,29.6515699554183,167.0427699397447,0.1272650706310676
0.13625585874302,146.549045625969,0.43261235150908844,29.544287598195353,166.51721168570543,0.1277385227057369
0.136809729371851,145.951761357855,0.43437089075562696,29.423875089743564,165.91938233056814,0.12822585632487118
0.137340516164174,145.328744749999,0.43605613882125244,29.2982749415998,165.28826956745536,0.12869265644329186
0.137897609807027,144.660663049789,0.4378249111373107,29.163589670837464,164.60902271745462,0.12918235784871998
0.138453576613321,144.040214575141,0.4395901057472941,29.038507258348425,163.98309745921947,0.12967082976875177
0.139010893588548,143.397094300518,0.44135958714363993,28.908854210984433,163.3308525172343,0.13016024858835867
0.139561600448117,142.72986870879,0.4431080814227714,28.774341531692066,162.64947761753837,0.1306436274334324
0.140084032186081,142.016197565799,0.44476680219080716,28.63046542926508,161.91039915655122,0.1311019721337061
0.140627053950768,141.270176800239,0.4464908962936884,28.480067642928184,161.13658557476074,0.1315781585110589
0.141150971342239,140.497164955945,0.4481543340116088,28.324228455118515,160.32847626030744,0.13203737706331997
0.141653964349695,139.754283196081,0.44975133681028157,28.174463492329927,159.55103144565584,0.13247805686712777
0.142158014332092,139.008004076078,0.451351695504392,28.02401362173733,158.7691059118006,0.13291946797739976
0.142647056011356,138.14759590712,0.45290440283605526,27.850555334875395,157.85394375831711,0.13334754973639087
0.143161296998433,137.376464201369,0.4545371179700247,27.695095182995992,157.0434569934958,0.13379749209054806
0.143676002131403,136.550791865135,0.45617130676720447,27.52863964001122,156.1698637281949,0.13424763792458447
0.144191370766639,135.776114854598,0.4578076021840788,27.37246475468696,155.3538589728511,0.13469816110617974
0.144674902296974,134.930834414093,0.4593428147928924,27.20205621788115,154.45193969980107,0.1351206685660681
0.14515774879888,134.009326628584,0.46087585243644397,27.016280248322538,153.46181880004306,0.13554239939328064
0.145631890356183,133.159846578675,0.46238125188088103,26.84502507026088,152.55216675546677,0.13595635408904977
0.146118121080428,132.235838664833,0.4639250344303588,26.658745074830335,151.557890950033,0.13638068547695345
0.146594443903447,131.249748868504,0.4654373593934442,26.459949371890414,150.49023281634942,0.13679619576563679
0.147085907808573,130.22520411773,0.46699775729221926,26.253401150134366,149.37949648494302,0.1372247331704066
0.147586092741295,129.122902384859,0.4685858444536116,26.031177120787575,148.179647031256,0.13766068649229682
0.148083363575534,128.041690093071,0.4701646793523204,25.813204722763114,147.00253423994909,0.13809391161592965
0.148562511623347,126.864063677782,0.4716859744041267,25.575795237440854,145.7113076124975,0.13851117059341406
0.149010099923743,125.716113724773,0.47310706725788404,25.344368526914238,144.44908439292604,0.13890078901401035
0.149479257872103,124.587632678306,0.474596643743927,25.11686674794649,143.21089955110133,0.13930902057991626
0.149912720395114,123.240883073569,0.4759728872544869,24.84536202763151,141.71625911902387,0.13968604418636757
0.150369025472231,122.000276582786,0.4774216558743334,24.59525575908966,140.34533927988218,0.14008278261540735
0.150802694538391,120.60815109781,0.47879855515939146,24.314603261318496,138.79618526665314,0.14045969414054285
0.151231359374941,119.108587090119,0.4801595660154377,24.01229115736799,137.12154062898625,0.14083211681672006
0.151651841446533,117.64986109109,0.4814945965927422,23.718211995963742,135.49167917148262,0.1411972956291886
0.152067109930556,115.874666485332,0.4828130740295153,23.36033276344293,133.4953921319235,0.1415578157249863
0.152492677849838,113.950285877116,0.4841642521732356,22.97237763282659,131.32687011227202,0.14192714259285585
0.152941080295918,111.642472253953,0.4855879299395396,22.507122406396924,128.7171925673796,0.1423161387634461
0.153445020849319,108.941694488337,0.48718794119658776,21.96264560884874,125.65825507046002,0.14275313459963365
0.153979840511636,105.547803685669,0.48888599362444424,21.27843722303087,121.80003766354177,0.1432166987059672
0.154786893058859,101.329127157319,0.4914483854618773,20.42795203491551,117.01354792636644,0.14391581877588155
0.155365057325794,95.8748579717973,0.4932840570093959,19.328371367114336,110.77046077668795,0.14441636098386065
0.155831553021222,92.2642651339882,0.49476518084237986,18.60047585101202,106.64194885817938,0.1448200442531026