File: example/data/02 processed data/test_ID_078.csv
Strain,Stress_MPa,Displacement(mm),Force(kN),True Stress (MPa),True Strain
0.0005565689981795843,39.1667084006418,0.00176710656922018,15.792016827138776,39.18850737629835,0.0005564141711001224
0.0006235563485631842,44.0372807589204,0.0019797914066881097,17.755831601996707,44.06474048491109,0.0006233620180831488
0.0006952079514923842,49.0065181619331,0.00220728524598832,19.75942812289143,49.040587883034235,0.0006949664063873531
0.0007653718799920842,54.124290825179,0.0024300557189748675,21.822914060712176,54.165716035401104,0.0007650791322990752
0.0008343484200098842,59.1447453462155,0.0026490562335313825,23.84716132359409,59.19409267104701,0.0008340005448529133
0.0009086532999928843,64.1867428789311,0.0028849742274774074,25.88009472878502,64.24506637466384,0.0009082407244895865
0.0009792855334729844,69.1939803585903,0.0031092315687767254,27.89901288058361,69.26174102255887,0.000978806346210147
0.0010531850846956844,74.279775165908,0.0033438626439087978,29.94960534689411,74.35800551720729,0.0010526308743743467
0.0011265681126199842,79.4628573279025,0.0035768537575684494,32.03942407461029,79.5523776491058,0.0011259340109582914
0.0011966006342594843,84.6690813559482,0.0037992070137738625,34.13857360271831,84.77039643240089,0.0011958852783271663
0.0012725990694000843,89.8550700339433,0.004040502045345267,36.22956423768594,89.96941951244938,0.00127179000154423
0.0013444361652456842,95.0304313935768,0.004268584824655047,38.31626993789017,95.15819374234123,0.0013435332201552504
0.0014226741895918844,100.116005949159,0.0045169905519542326,40.36677359870091,100.2584384067879,0.0014216631474758491
0.0014990900182472843,105.253192097034,0.004759610807935128,42.438087053524114,105.41097610669533,0.001497967504498552
0.0015767438973745842,110.424967613676,0.005006161874164305,44.52334694183416,110.59907950747865,0.0015755021418312753
0.0016568357313163844,115.80522341388,0.00526045344692952,46.69266608047642,115.99709364590521,0.00165546469317727
0.0017379457851929843,121.344721090989,0.0055179778679877245,48.926191543886766,121.5556116375645,0.0017364373049351717
0.0018183787935886842,126.851471672136,0.005773352669644072,51.146513378205235,127.08213569816012,0.0018167275442982035
0.0018952190469788842,132.222757765628,0.006017320474157957,53.31221593110121,132.4733488545895,0.0018934253852579761
0.0019704371252590846,137.426380639405,0.006256137872697593,55.410316673808104,137.69717068180688,0.0019684983604185526
0.0020471933355424845,142.536782674454,0.006499838840347388,57.47083077433986,142.8285830260148,0.002045100690811355
0.0021258209548119843,147.601505456904,0.00674948153152805,59.51292700022369,147.9152798301661,0.002123564594625437
0.002202289540105884,152.649266053919,0.006992269289836182,61.54818407294015,152.9854439358544,0.002199868055052467
0.0022796056984456846,157.673102528591,0.007237748092565048,63.57379493952789,158.03253503160678,0.0022770113393713078
0.0023545764830419846,162.641235518924,0.007475780333658301,65.57694616123015,163.02418674724973,0.002351808811446279
0.0024315706776562845,167.531552563958,0.007720236901558703,67.54872199378786,167.93891737475477,0.0024286191932032315
0.002505044537577384,172.380461850387,0.007953516406808194,69.50380221807605,172.81228258473038,0.002501912143610118
0.0025785293627673843,177.151366415752,0.008186830726786444,71.42743093883121,177.60815641570937,0.002575210659621538
0.0026512544225586847,181.859920751837,0.008417732791623823,73.32592004714068,182.34207767101648,0.0026477460472477793
0.0027212091407625844,186.420765023223,0.008639839021921204,75.16485245736351,186.92805491303216,0.002717513354322493
0.0027933361882564846,190.869421686664,0.008868842397714339,76.95855082406293,191.40258414949292,0.0027894420747526637
0.0028633235330546847,195.155733688679,0.009091052217448624,78.68679182327537,195.71452769356034,0.002859232030563317
0.002935469118615184,199.376322873722,0.009320114451603209,80.38853338268471,199.96158591250085,0.002931169042247628
0.003009295201478684,203.552983180668,0.009554512264694821,82.07256281844535,204.16553419620024,0.0030047763361371917
0.003084240778552184,207.637449556393,0.009792464471903184,83.71941966113765,208.27785344546942,0.003079494265051621
0.0031624182222925847,211.678457384416,0.010040677855778956,85.34875401739653,212.3478731953153,0.003157428295176206
0.003243440846228584,215.580375496807,0.010297924686775754,86.92200740031258,216.27959769233863,0.003238192237938504
0.003329245506382584,219.262678821498,0.010570354482764704,88.40671210082802,219.9926581096819,0.0033237158382447007
0.0034211691819827847,222.74900353815,0.01086221215279534,89.81239822658209,223.51106556437207,0.0034153302961180175
0.0035223564785587845,225.925819010752,0.01118348181942414,91.0932902251352,226.7216102830182,0.003516167509889013
0.003639356703149084,228.908279209218,0.011554957532498342,92.29581817715669,229.74135808956441,0.003632750268472568
0.0037781234858743845,231.636465382889,0.01199554206765117,93.39582284238087,232.51161655293706,0.0037710043031372992
0.003958628605608384,234.042476068578,0.01256864582280662,94.36592635085064,234.9689633092705,0.003950813852404339
0.0041788187527308845,236.080120249006,0.013267749539920557,95.18750448439921,237.06665628264952,0.004170111737909833
0.004450217709687584,237.61458256835,0.014129441228258079,95.80619969155873,238.67201919177572,0.004440344771169469
0.004762728273794184,238.709616642249,0.015121662269296534,96.2477174301548,239.84652568265759,0.004751422367251317
0.005099186320843285,239.433404960184,0.016189916568677427,96.53954887994618,240.65432050350992,0.005086229497780096
0.005455651487066484,239.885546583463,0.017321693471436087,96.7218523824523,241.19427852240682,0.005440823327557786
0.0058256482884297845,240.226264859672,0.018496433315764563,96.85922999141974,241.62573858838763,0.005808744816787908
0.006196737761838785,240.440007361778,0.019674642393838142,96.94541096826889,241.92995103485353,0.006177616932913057
0.006572689843452785,240.700329639808,0.02086829025296259,97.05037291077059,242.2823782517473,0.006551183900723552
0.006942249550830384,240.945675424199,0.02204164232388647,97.14929633103704,242.6183804311872,0.0069182630857814505
0.007317294301257984,241.163201622821,0.023232409406494098,97.23700289432144,242.9278637437288,0.007290652786906503
0.007693934434699484,241.378471381876,0.024428241830170862,97.32379966117242,243.23562151463616,0.007664487068777125
0.008072282227334584,241.561576526515,0.0256294960717873,97.39762765549085,243.51152974751696,0.008039875637104853
0.008447129559025983,241.752821203174,0.026819636349907493,97.47473750911975,243.79493860513728,0.008411652207980349
0.008810590495165983,241.944988465154,0.027973624822151995,97.55221934915009,244.07666668087816,0.008772003725250357
0.009171198802742184,242.170053974993,0.02911855619870643,97.64296576271718,244.39104368406845,0.009129398735777065
0.009523073653713184,242.405053179133,0.03023575885053936,97.73771744182643,244.71349435459013,0.009478015026352378
0.009880158772704683,242.529623571172,0.031369504103337366,97.78794422389656,244.92585475913947,0.009831669132654142
0.010235793927665484,242.717748604614,0.032498645720337914,97.86379623738037,245.20215746191772,0.010183762940100542
0.010597385887577783,242.905510815868,0.03364670019305946,97.93950196095798,245.479674248203,0.010541627178854311
0.010955225178867484,243.109555885567,0.03478283994290426,98.02177293306062,245.77287581342785,0.010895651400700482
0.011312350018883383,243.315860869037,0.03591671130995474,98.10495510239572,246.0683350523335,0.011248843874444794
0.011671919308728284,243.486525288824,0.0370583438052123,98.17376699645384,246.32848036475778,0.011604327897808813
0.012033825138387683,243.663382277403,0.038207394814380895,98.2450757342489,246.59558481235734,0.011961994356492792
0.012394805095996683,243.847468908734,0.039353506179789464,98.31929946400155,246.86991075900988,0.012318618399488283
0.012751875651903083,244.117697295564,0.040487205194792285,98.4282555495714,247.23065581590598,0.01267125513736126
0.013103053627715584,244.326369396821,0.04160219526799698,98.51239214079824,247.5277909176926,0.013017951215401733
0.013452347140516083,244.490971458424,0.04271120217113856,98.57875969203657,247.77994887920477,0.013362667689599175
0.013805453463305783,244.684348864164,0.04383231474599586,98.65672946203092,248.06232725560753,0.013711026271576717
0.014157852640787484,244.843042889492,0.04495118213450026,98.7207148930432,248.30949461084344,0.014058566268940526
0.014508440959554083,245.104090219521,0.04606430004658421,98.82596917651087,248.66016844141615,0.014404200564105614
0.014852933895021583,245.316212877939,0.04715806511669352,98.911497032385,248.95987837119208,0.014743709281522858
0.015190051294034584,245.522086435698,0.048228412858559805,98.99450525087343,249.25157952247463,0.015075837620254091
0.015527142539199883,245.727753254293,0.049298677561959624,99.07743011213094,249.54320310490974,0.015407829932413603
0.015859115028562784,245.879428506653,0.050352690215686835,99.13858557388248,249.77885864649727,0.015734673230758712
0.016193733318138684,246.104726147765,0.051415103285090316,99.22942558277886,250.0900804513355,0.016064013378454985
0.016523401125797085,246.315601646939,0.05246179857440574,99.31445058404582,250.3855731364934,0.016388375096042282
0.016858064553963385,246.526388706003,0.053524354958833745,99.3994399262604,250.68234648106426,0.0167175444494928
0.017190692618867184,246.730387394276,0.05458044906490331,99.48169219737208,250.971853643705,0.017044604522852346
0.017528565430774284,246.92263437083,0.05565319524270835,99.55920617831866,251.2508339237382,0.0173767120739809
0.017861393780426487,247.191887274777,0.05670992525285409,99.66776894919009,251.60707891271858,0.01770375343636208
0.018197623761041285,247.41679349956,0.05777745544130608,99.75845113902258,251.91919121982824,0.01803402871892954
0.018525336795307386,247.649068959657,0.05881794432510095,99.85210460453371,252.23685136917894,0.018355832953909672
0.018847600682211484,247.87019832426,0.05984113216602146,99.94126396434163,252.54195684329625,0.018672185334628843
0.019171491564366785,248.098872379493,0.06086948571686454,100.03346534341158,252.85529781844537,0.018990034059514955
0.019496534136767486,248.362680292938,0.06190149588423676,100.1398326941126,253.2048917675683,0.019308911455007637
0.019830627922989685,248.55256569122,0.06296224365549224,100.2163944866999,253.48151914074703,0.019636562452284238
0.020165657597832384,248.714384899279,0.06402596287311782,100.2816399913893,253.72987402481334,0.01996502351883892
0.020495617832952884,248.868614492206,0.06507358661962541,100.34382536325745,253.96933050545476,0.020288409121308842
0.020826174572764086,249.033246556844,0.06612310426852597,100.4102050117195,254.21965642405902,0.020612274514732017
0.021154109061568085,249.238420486733,0.06716429627047867,100.49293114025075,254.51083721604232,0.02093346712785529
0.021485704520761085,249.426805797304,0.06821711185341645,100.56888809747298,254.78591644622213,0.021258140582177367
0.021813349560826686,249.648093454334,0.06925738485562473,100.65811128078747,255.0937545840473,0.021578842578509474
0.022137642984815385,249.871921330973,0.07028701647678884,100.74835868064832,255.40349671732798,0.021896162737253724
0.022456062954483387,250.057511732351,0.07129799988048476,100.82318873048393,255.67281895805417,0.022207637795909473
0.022776244784130085,250.234023365825,0.07231457718961301,100.89435822110065,255.93341473532274,0.022520738494593663
0.023094385211562585,250.459891544907,0.07332467304671121,100.98542827090651,256.2441087602913,0.02283174587241368
0.023415003153498485,250.671797457813,0.07434263501235769,101.0708687349902,256.54127838578086,0.02314507738839092
0.023735126785784384,250.91293969532,0.07535902754486541,101.16809728515304,256.8683901311823,0.02345782790943325
0.024054327921811485,251.041445432087,0.07637249115175146,101.21991079821748,257.08007868247597,0.02376957982111398
0.024374702680488185,251.229784681435,0.07738968101054998,101.29584918355461,257.35343598752803,0.02408238027111997
0.024693966805375486,251.41364598581,0.07840334460706716,101.36998206147861,257.622046214202,0.024393999039417188
0.025018297910882087,251.566800384595,0.07943309586705062,101.4317339150687,257.86057354110426,0.024710464051406072
0.025339806696498487,251.776828434116,0.0804538862613827,101.51641722463557,258.15680459729396,0.02502407637847124
0.025662310226281987,251.946822892854,0.08147783496844531,101.58495899039873,258.4123604224566,0.025338560239585355
0.025985590085922685,252.110233542582,0.08250424852280452,101.65084616436907,258.6614667278858,0.025653701899386705
0.026314251061048087,252.281087874855,0.08354774711882768,101.71973463114153,258.9196757591483,0.025973987435978965
0.026639632188809884,252.503229689795,0.08458083219947138,101.80930221092535,259.2298228552177,0.02629097568704595
0.026964991292811186,252.638064065683,0.0856138473546755,101.86366743128339,259.45044726344685,0.026607842042919275
0.027288548846009786,252.872263914683,0.08664114258608106,101.95809681040019,259.7727810403199,0.02692285433283587
0.027608641321054884,253.063227549037,0.08765743619434925,102.03509334777173,260.0499594299868,0.02723439544464009
0.027929670330148385,253.275865494372,0.08867670329822111,102.1208289673308,260.34977692021283,0.027546750616892587
0.028253301470647786,253.468672522243,0.08970423216930672,102.19856876096837,260.62999934037884,0.027861538889736307
0.028576670868862484,253.603957407952,0.09073093000863838,102.25311562688626,260.85111422984005,0.028175973631768967
0.028898027856805685,253.742381933563,0.09175123844535804,102.30892839561261,261.0750363551313,0.028488353648646415
0.029215505274036584,253.913905570468,0.09275922924506615,102.3780867260127,261.3321286178132,0.028796866677338436
0.029524234903104987,254.113013940142,0.09373944581735832,102.45836722066527,261.6155062556468,0.029096787668183213
0.029836115303154585,254.277437968795,0.0947296660875158,102.52466298901814,261.8640889270227,0.029399678225829076
0.030156943623923484,254.503501631899,0.09574829600595705,102.61581185798168,262.1785493827033,0.029711163084452853
0.030480860462831584,254.710180276434,0.09677673196949027,102.6991446874582,262.4739657399026,0.030025548117022394
0.030811930499822185,254.90010776542,0.09782787933693543,102.77572345101736,262.7540721702853,0.030346773749100532
0.031138767556287784,255.051050681159,0.09886558699121371,102.83658363464332,262.9930260633066,0.03066379108565558
0.03145938390443418,255.140335999049,0.09988354389657852,102.87258347481657,263.1668937787494,0.03097467699477136
0.03177960022714118,255.266546407575,0.10090023072117324,102.92347151153425,263.37881520377067,0.031285078579600646
0.03210155249401548,255.452169677806,0.10192242916849914,102.99831481409139,263.6525809124283,0.03159706579752883
0.03242455715293558,255.647492125552,0.10294796896057046,103.07706882502256,263.9367488449816,0.031909975050694664
0.03275110816240468,255.822250678807,0.10398476841563485,103.14753147369498,264.20071288113843,0.03222622031512926
0.033078319023747284,255.983303704772,0.10502366290039762,103.21246805376408,264.45080108947127,0.03254300432427625
0.03340272827786988,256.143749513495,0.10605366228223687,103.27715980384117,264.69964957856905,0.032856976966039585
0.033729485405742984,256.298659842306,0.10709111616323397,103.33961964841778,264.94348174896857,0.033173122327648935
0.034058224819532384,256.414183999081,0.10813486380201531,103.38619898842946,265.14719592463865,0.033491084771214506
0.03438533680860648,256.593840972074,0.10917344436732558,103.45863667994024,265.4169066169128,0.03380737282264529
0.03471135099918428,256.737010844308,0.11020853942241007,103.51636277242498,265.64869934220616,0.03412249989737005
0.035030753723127285,256.929752630788,0.11122264307092912,103.59407626073373,265.93019551934117,0.034431140018039944
0.03534716071421648,257.053321987733,0.11222723526763732,103.64389942545395,266.1394270721566,0.03473679145621067
0.03566581672679848,257.165372708833,0.11323896810758516,103.68907827620147,266.33738576034506,0.03504452107313511
0.035983468069651685,257.292552676483,0.11424751112114409,103.74035723915794,266.5508310302764,0.0353511862482434
0.03630054677399818,257.440995702199,0.11525423600744422,103.80020946712665,266.78624460823136,0.03565720482923881
0.03661946362264428,257.558877466727,0.11626679700189559,103.84773939458432,266.99054541080886,0.03596490300337273
0.03693203911372738,257.698047985624,0.11725922418608443,103.90385294780359,267.2153623733602,0.036266391047473145
0.037246202180414585,257.829813406454,0.1182566919228163,103.95698076548224,267.4329947647293,0.036569318792866526
0.037563287161829585,257.994276339789,0.11926343673880893,104.02329222020293,267.68538942804895,0.036874970936364534
0.03788593332600068,258.162042008501,0.12028783831005216,104.0909353378276,267.94275191933923,0.03718588788252265
0.038206760642785685,258.311706497159,0.12130646504084454,104.15128005965451,268.1809600385254,0.03749495627842892
0.03852693094629548,258.471180985641,0.12232300575448814,104.21558017341046,268.42928232708226,0.037803296541162844
0.038845886474770185,258.584970345797,0.12333568955739532,104.26146004342534,268.62993274793166,0.038110372409592794
0.03917356683852318,258.725023744825,0.12437607471231109,104.31792957391345,268.8602057552914,0.03842574998312455
0.03950493839937758,258.90359886345,0.1254281794180238,104.38993106174303,269.13156958792774,0.03874457904959773
0.03983363700329088,259.082466791844,0.12647179748544854,104.46205061047151,269.40266372794747,0.03906073593769619
0.040166408448898384,259.208343884902,0.12752834682525235,104.51280425439249,269.61981209874546,0.039380708477287585
0.04049369690095878,259.319715935428,0.12856748766054413,104.55770946516458,269.82052991295996,0.0396953090734333
0.04082314528104478,259.414750821056,0.12961348626731717,104.59602753104977,270.00487688186996,0.040011885940693985
0.04115398368977958,259.551555342877,0.13066389821505014,104.651187114248,270.2331358181147,0.040329697704248796
0.04148024770128438,259.725921983488,0.1316997864515779,104.72149174374236,270.4994175618075,0.04064301629784154
0.04180630546868508,259.812478161912,0.13273501986307512,104.75639119488292,270.6742779885249,0.04095603878585875
0.042125555017353884,259.950158423335,0.13374863718009858,104.81190387628867,270.900703123767,0.04126243033082205
0.042447951479774385,260.071604433151,0.13477224594828366,104.86087090744648,271.1111112793965,0.041571746806337316
0.042774416897503685,260.230951256638,0.1358087736495742,104.92511954667644,271.3621784553234,0.0418848696898701
0.043103993292378184,260.384624592655,0.13685517870330072,104.98708063575849,271.6082417045352,0.04220087698541247
0.04343718312507618,260.513039807992,0.13791305642211688,105.03885765058237,271.828992424602,0.04252024747212584
0.04376698678518568,260.65875654405,0.13896018304296454,105.09761063856097,272.0670048971564,0.042836271814745475
0.04409430406987888,260.77753546977,0.13999941542186545,105.14550230141126,272.2763394133677,0.04314981494982666
0.04442099324836538,260.889478378469,0.14103665356356007,105.19063768219871,272.47844813608856,0.04346265841481874
0.044747382718560984,260.996974962256,0.14207294013143112,105.23398030478162,272.6759064892787,0.04377511716788586
0.04507664493200028,261.074388027953,0.1431183476591009,105.26519325287065,272.8427455179283,0.044090227159739176
0.04540648255148468,261.157148438202,0.14416558210096386,105.29856225028306,273.0153759419567,0.04440578830240993
0.04573402223899658,261.27011127398,0.14520552060881414,105.34410886566873,273.21904435336927,0.04471905246561677
0.046060769607844484,261.381807738326,0.14624294350490624,105.38914488009304,273.42125496424296,0.04503146109458846
0.04639582564602738,261.516950341765,0.14730674642613692,105.44363437779964,273.65024517330227,0.04535171246019035
0.04673715654613228,261.657689439827,0.14839047203397,105.50038038213825,273.88682583267547,0.045677856002941414
0.04708072013277368,261.798602248096,0.14948128642155642,105.55719642643231,274.12426897168996,0.04600602550951724
0.04742124373972658,261.886507842639,0.15056244887363188,105.59263996215205,274.30549176319056,0.046331185013615855
0.047757231397159684,261.924003759428,0.15162920968598198,105.60775831580136,274.43276901543754,0.04665190963378578
0.04808818925488348,262.04451682535,0.15268000088425504,105.65634918398113,274.64576314365195,0.046967732410803084
0.04841948511449818,262.13123734804,0.15373186523853172,105.69131489872973,274.8234968928584,0.047283777867180375
0.04874915497851698,262.26352647713,0.1547785670567914,105.7446538755788,275.048651774576,0.0475981730573734
0.049082471744046584,262.340716937598,0.15583684778734788,105.77577706923952,275.2170477640006,0.04791594571757024
0.04941534450277938,262.486617086019,0.15689371879632452,105.83460400908287,275.45748369669377,0.048233194331266736
0.04974822129131278,262.585815813341,0.15795060259991808,105.87460093593911,275.648993086383,0.04855034616902514
0.050082976363052985,262.675404923969,0.15901344995269323,105.9107232653443,275.8309710199315,0.04886918615478223
0.05042066022354858,262.791302389584,0.16008559620976673,105.95745312348028,276.04141335707305,0.04919071272348027
0.050759758537188684,262.872602689486,0.16116223335557406,105.99023340440075,276.2159525280466,0.049513482071182384
0.05110119049797918,262.959138711121,0.1622462798310839,106.02512472832399,276.39666375158254,0.04983836746757413
0.05143940397843738,263.079171904595,0.16332010763153867,106.0735221119327,276.6118077065082,0.050160086329282524
0.05177538727682148,263.180221053892,0.1643868546039082,106.11426512892926,276.8064789225567,0.05047958132583637
0.05210807467873268,263.266337865566,0.16544313710497624,106.14898742739622,276.98463985946137,0.05079584162323411
0.052444809168783385,263.327801228184,0.16651226911088723,106.17376945520378,277.13797751243146,0.05111584735510135
0.052780337657386184,263.385662065228,0.1675775720622011,106.19709894469995,277.2872462431449,0.05143460517722737
0.053120758302110584,263.446383389069,0.1686584076092011,106.22158178247263,277.44085504664486,0.05175790682547925
0.053462254622592985,263.544124247465,0.16974265842673272,106.26099089657788,277.63378732227125,0.05208212507026584
0.05379765903585438,263.613548500765,0.17080756743883765,106.28898275550844,277.7953403002408,0.052400457340452275
0.05413272779108708,263.672815766099,0.17187141073670148,106.31287931689113,277.9461445278747,0.052718369886472397
0.05446402104521828,263.737401621742,0.17292326681856804,106.33892033388636,278.10160101407973,0.05303260090958304
0.054800246136154585,263.831376731008,0.1739907814822908,106.37681109794244,278.28940111430774,0.053351408845615934
0.05513797363004718,263.949716914374,0.1750630662753998,106.4245258598756,278.5033694452572,0.053671539068968564
0.05547564864494938,264.047193861335,0.17613518444771428,106.46382856489028,278.6953832136713,0.053991517121056896
0.05581683839517928,264.128054154079,0.1772184619046942,106.49643143492466,278.8708470684304,0.05431472175072742
0.05615627890939178,264.168078346899,0.1782961855373189,106.51256918946967,279.0027746335055,0.054636165725893436
0.05650057470473158,264.225430108967,0.17938932468752278,106.53569341993548,279.1543187617285,0.05496210204423015
0.05684058965216278,264.327136187044,0.18046887214561683,106.57670131061614,279.3516464689831,0.05528388156199068
0.05718655703066918,264.414391689145,0.18156731857237465,106.61188272906327,279.535340379206,0.0556111880321443
0.05753289184873718,264.499612428317,0.18266693161974054,106.64624373109743,279.7170400241883,0.05593873485765637
0.05787976225117798,264.548469905298,0.18376824514749007,106.66594306581615,279.8604724473296,0.05626668071245426
0.05822809092760038,264.586841705779,0.1848741886951312,106.6814145757701,279.9932283828697,0.05659589708868494
0.05857530070720168,264.644375439296,0.18597657974536533,106.70461217712416,280.14599931112235,0.05692394813403688
0.05892493828733418,264.691988334669,0.18708667906228602,106.72380969653855,280.2889474124412,0.05725418430296043
0.05928236833171938,264.743578953655,0.18822151945320903,106.7446110341137,280.4382053146432,0.05759166784072437
0.05963409807936698,264.803315460693,0.18933826140199014,106.76869679375143,280.59462234661754,0.057923658040860894
0.05999004780224378,264.871415689984,0.190468401772124,106.79615480620156,280.7610645786741,0.058259519214092274
0.06033589756900158,264.895889200879,0.19156647478158,106.80602252579443,280.87862043815284,0.05858574242574523
0.06067981804235018,264.920257108777,0.1926584222844618,106.81584766625889,280.99557010587023,0.0589100403305947
0.06102127323318178,264.935938625708,0.19374254251535214,106.82217045388546,281.1026669258768,0.05923190960349425
0.06136451421895258,264.976821731454,0.19483233264517444,106.83865452212225,281.23699567628665,0.059555357857616946
0.06170267879266838,265.04751267639,0.1959060051667221,106.86715711112045,281.40165421585704,0.059873920150594624
0.06204315900195628,265.091327402064,0.1969870298312112,106.88482320851222,281.5384307781099,0.06019456135553142
0.06238111551380678,265.154869683625,0.1980600417563365,106.9104434564376,281.6955262384076,0.06051272427501541
0.06272561155236209,265.226602601627,0.19915381667874962,106.93936616897601,281.86310344976937,0.060836939560003474
0.06307162175558328,265.289426187221,0.2002523990739769,106.96469663868751,282.02166053145714,0.061162474094394174
0.06341843448839929,265.331283959331,0.20135352950066773,106.98157369240228,282.1581786088287,0.061488657360450366
0.06376128576996119,265.353585372168,0.20244208231962676,106.99056562205816,282.27287115916664,0.06181101026863734
0.06410513159437149,265.394386073634,0.20353379281212947,107.00701646488922,282.40752811729175,0.06213419392772154
0.06445198216288449,265.485381916744,0.20463504336715824,107.04370598883119,282.59644101654857,0.06246009598535592
0.06480194242126999,265.497845360011,0.20574616718753222,107.04873124915645,282.7026214480017,0.06278881230941315
0.06515839666263519,265.516516277528,0.20687790940386672,107.05625936309929,282.81714676562024,0.06312351736297883
0.06550906893044109,265.549916780035,0.20799129385415044,107.06972644571012,282.94584458285124,0.06345268395197973
0.06585915255021559,265.566080554929,0.20910280934693448,107.07624367974736,283.0560375663589,0.06378118995051585
0.0662042814181129,265.59576040892,0.21019859350250844,107.08821059687655,283.1793368744898,0.06410494098476106
0.06654947858397489,265.58919800549,0.21129459450412028,107.08556463581357,283.2640206502914,0.06442865127457525
0.06690130940834699,265.599843735533,0.21241165737150167,107.08985699416691,283.3688210600925,0.06475847451637846
0.06724768322204638,265.625359235504,0.21351139422999726,107.1001448437552,283.4880492491154,0.06508307586139862
0.06759429402501,265.611876345463,0.21461188352940672,107.09470854249068,283.5657236116928,0.06540779385898671
0.06793872733405949,265.617527130529,0.2157054592856389,107.0969869390293,283.6632438813972,0.06573036748214413
0.06828003477203129,265.588286195004,0.21678911040119933,107.08519699382562,283.72266361144307,0.06604991101104712
0.0686199089746359,265.593510789679,0.21786821099446896,107.08730355039857,283.81851332432075,0.06636801126320459
0.06896098462192368,265.568706653022,0.21895112617460769,107.07730252249847,283.8825861485852,0.0666871342972886
0.069296270450287,265.548827625035,0.2200156586796612,107.06928729841412,283.9503710018961,0.06700074093214602
0.06963092104618819,265.477904228624,0.2210781743216475,107.04069098498121,283.9633752174749,0.06731365536884332
0.06996670371778038,265.444497370084,0.2221442843039527,107.02722133961787,284.0167738710918,0.06762752996887324
0.07030430067539559,265.370295861917,0.22321615464438097,106.99730329152493,284.02696893251186,0.06794300119632252
0.07064907886369778,265.223341188466,0.22431082539224045,106.9380511671895,283.96112593658336,0.06826508031731376
0.07099968291216899,265.045067284944,0.22542399324613652,106.86617112928944,283.86318301960955,0.06859249539849886
0.07134549392854599,264.783841953984,0.2265219432231335,106.76084507584636,283.6749759424891,0.06891532948062411
0.07169041384079448,264.461805113966,0.22761706394452247,106.63099982195111,283.4211813676698,0.06923722788090417
0.07202265975736949,264.108777108012,0.2286719447296481,106.48865892995046,283.1305937005973,0.0695472002585764
0.07235984282863799,263.584084143493,0.22974250098092558,106.27710272665638,282.65698704424665,0.06986168060304936
0.0726982913120282,263.045392217519,0.2308170749156895,106.05990214210368,282.1683427692349,0.07017724173476131
0.07304701486332268,262.345706006847,0.23192427219104952,105.77778866196071,281.50927669285807,0.07050227896388728
0.07340213945615229,261.608044006938,0.2330517927732835,105.4803633435974,280.8106341359865,0.07083317391693597
0.0737499271001616,260.719803546514,0.23415601854301304,105.12222478995446,279.9478700516379,0.07115712642357755
0.07410690718816519,259.748314077857,0.23528943032242447,104.73052023619195,278.99745828150714,0.07148953227632512
0.07446019790245709,258.717073661,0.23641112834030123,104.31472410011519,277.9811981665426,0.0718183939782834
0.07480888287309079,257.619119718628,0.23751820312206323,103.8720290705508,276.8913182715276,0.07214286240041981
0.0751488258213197,256.415025605027,0.23859752198269002,103.38653832394688,275.6843137021884,0.07245909462181388
0.07548789381247839,255.235727526943,0.23967406285461887,102.91104533886343,274.5029350236475,0.0727744133280114
0.07582040369612339,254.085147796836,0.24072978173519174,102.44713159168428,273.3499862759813,0.07308353674530865
0.07617621605664929,252.806086169086,0.24185948597986148,101.93141394337549,272.0638972095382,0.07341421790019732
0.07652339437860609,251.584913332115,0.24296177715207432,101.43903705550878,270.8370448747359,0.07373676947523726
0.07688410508659979,250.193382717903,0.2441070336499543,100.8779719118585,269.42927704675816,0.07407178336504397
0.0772461102645137,248.859725012393,0.24525640008983096,100.34024112499687,268.08317077109683,0.07440788670619011
0.07760768913793509,247.384293536388,0.24640441301294388,99.74534715387165,266.5832168867677,0.07474348151723045
0.0779851745165216,245.988807852934,0.24760292908995604,99.18268732630298,265.17228796245615,0.07509371962463009
0.07835613928372569,244.41972742659,0.24878074222582905,98.55003409840108,263.57151363251813,0.07543778831959007
0.07874072104282429,242.839607612451,0.2500017893109671,97.91292978934025,261.96097341361195,0.075794361795957
0.07911692338383279,241.234646998396,0.2511962317436691,97.26580966975327,260.320390082494,0.0761430431334785
0.07949030655598188,239.558301351049,0.25238172331524245,96.58990710474296,258.60086416347417,0.07648899136407288
0.07988566738421508,237.912308032336,0.25363699394488287,95.92624259863787,256.9180915384181,0.07685517199905473
0.08029334454274138,236.201228188338,0.2549313689232039,95.23633520553788,255.1666147846829,0.07723261957271926
0.08071725792547789,234.379381285642,0.25627729391339227,94.50176653437086,253.2978422572891,0.07762494840968996
0.08113084116505129,232.446047539592,0.2575904206990378,93.72224636796349,251.3045909019706,0.07800756848812486
0.08155276639052819,230.486433360268,0.258930033289927,92.93212993086007,249.283239616284,0.07839775522589444
0.0819708384233982,228.49738927753,0.26025741199428926,92.13014735670009,247.22751185416672,0.07878422851155063
0.08241023992848319,226.450657251439,0.26165251177293414,91.3049050037802,245.1125102474928,0.0791902582218605
0.08283205431591949,224.389389715486,0.26299177245304434,90.47380193328397,242.97602383231518,0.07957988149302402
0.08325390902353069,222.216955619378,0.26433116114970995,89.59787650573323,240.71738582599966,0.07996939023836883
0.08367851566556989,220.106913186836,0.26567928723818435,88.74710739693228,238.52513297004091,0.08036128676696919
0.08411128950447959,217.828529632494,0.26705334417672266,87.82846314782158,236.1503681507478,0.08076056334224133
0.0845535805204791,215.582562068048,0.2684576181525211,86.92288902583697,233.81083958867987,0.08116845580017255
0.08499607683282659,213.113441166917,0.26986254394422443,85.92733947850093,231.22724758644836,0.08157637116360615
0.08546116565887858,210.623507541427,0.2713392009669395,84.92339824070335,228.62363801107895,0.08200493416320388
0.08593116006371139,207.99294091719,0.27283143320228365,83.86275377781101,225.86601561526712,0.08243783097932032
0.0864318991228619,205.293688572204,0.2744212797150865,82.77441523231266,223.03761195343694,0.08289883961772578
0.08693406976348529,202.326117019643,0.2760156714990658,81.57789038232006,219.9151497916037,0.08336095290812318
0.08745934410284459,199.214827134884,0.27768341752653153,80.32341830078522,216.63802525166253,0.08384409854885912
0.08799995583818919,195.798187861241,0.27939985978625065,78.94582934565237,213.02841974622768,0.08434110784385043
0.08842252918731479,193.081660980654,0.2807415301697244,77.8505257073997,210.1544297842511,0.08472942707630014
0.08871115922440849,191.310264525578,0.28165793053749694,77.13629865671304,208.28161986317025,0.08499457389784898