File: example/data/02 processed data/test_ID_104.csv
Strain,Stress_MPa,Displacement(mm),Force(kN),True Stress (MPa),True Strain
0.0012426284322174992,0.112738211085168,-5.597866498353228e-05,0.0227280233547698,0.1127362233892469,-1.763123101462931e-05
0.0012386574180344992,0.110463552592726,-6.858663501472651e-05,0.0222694522026935,0.1104611663491467,-2.160232309692581e-05
0.0012364403256330992,0.111945007046274,-7.562590338913023e-05,0.0225681134205288,0.1119423406077581,-2.3819465850984087e-05
0.001231619423600499,0.114941611274922,-9.093226734250189e-05,0.0231722288330242,0.1149383193374967,-2.8640494337378435e-05
0.001237849353546399,0.147471074700342,-7.115223976434939e-05,0.0297301686595889,0.1474677698508096,-2.241040536778324e-05
0.001224199405070599,0.359097796482235,-0.0001144908261748,0.0723941157708185,0.3590848473788029,-3.606075291340654e-05
0.0012134840505690992,0.779750404581771,-0.0001485120767171,0.157197681563685,0.7797139314000685,-4.677655123956469e-05
0.001175133961221899,1.41353982733207,-0.0002702736103946,0.2849696291901453,1.4134194989816544,-8.512916996599213e-05
0.0011240037694312992,2.15954848801572,-0.0004326119693298,0.4353649751839691,2.159254237141936,-0.000136265022028
0.0010852805850262992,2.87367145890736,-0.0005555580798157,0.5793321661157238,2.8731686269710663,-0.0001749942333743
0.001055705316281699,3.51442858385099,-0.0006494595580798,0.7085088025043597,3.5137096927533613,-0.0002045751155832
0.0010363991564849991,4.05741185863397,-0.0007107566154343,0.8179742307006085,4.056503564989855,-0.0002238854117864
0.001016488765516399,4.56634953700156,-0.0007739721067596,0.9205760666595144,4.565236394585385,-0.0002438004592034
0.000979227083790699,5.06979436678891,-0.0008922779462387,1.0220705443446445,5.068369590188768,-0.000281071921024
0.0009356810393831991,5.61812474484644,-0.0010305366372325,1.1326139485610425,5.616301222521368,-0.0003246311554118
0.0008834708767129991,6.15756434629703,-0.0011963039037104,1.2413649722134812,6.1552442460561405,-0.000376859633762
0.0008435206304339991,6.6920032438538,-0.0013231459356462,1.3491078539609265,6.689214425934607,-0.0004168257371476
0.0008296935590288992,7.22958136134848,-0.0013670468873574,1.4574836024478537,7.226468549790391,-0.0004306586689078
0.0008288205389456991,7.75042799911904,-0.0013698187261216,1.5624862846223986,7.747084162454898,-0.0004315320654271
0.0008196674006805991,8.5885823376335,-0.0013988799401133,1.7314581992669136,8.584798276044168,-0.0004406891963436
0.0008082747122142991,9.37614194594438,-0.0014350517259938,1.890230216302387,9.371904072343533,-0.0004520869715054
0.0007776850073026991,10.153994234644,-0.0015321740390881,2.0470452377042303,10.149094175948134,-0.0004826909770483
0.0007614998692833992,10.9620487719207,-0.0015835618522994,2.209949032419213,10.956581344437785,-0.0004988840604808
0.0007342516587794992,11.5909292192485,-0.0016700749206492,2.336731330600497,11.5848322995017,-0.0005261462396838
0.0007209634991569992,12.48696137524,-0.0017122648274507,2.517371413248384,12.480227206810218,-0.0005394414810424
0.0007237369346138992,13.305680935579,-0.001703459169875,2.6824252766127263,13.298542137405413,-0.000536666552926
0.0007298717317041992,14.1337146756258,-0.0016839811891133,2.849356878606162,14.12621832613098,-0.0005305284814496
0.0007505448275953991,14.9728728321948,-0.0016183441096588,3.018531162970472,14.96524093910735,-0.0005098446288948
0.0007764326500842992,15.8436336065589,-0.0015361502732565,3.1940765350822744,15.835968031096192,-0.0004839439396992
0.0007997055970432991,16.7672412313087,-0.0014622586666617,3.3802758322318334,16.75951901278697,-0.0004606599982859
0.0008121872037854991,17.7203506696587,-0.0014226295652552,3.5724226950031936,17.71241067130615,-0.0004481727184086
0.0008227475393291991,18.778117239499,-0.0013891004999039,3.785668435482999,18.76990158846132,-0.0004376077047598
0.0008383152874959991,19.8758450158685,-0.0013396728994744,4.00697035519909,19.86745851794034,-0.0004220332638179
0.0008571298525168992,20.9613110490776,-0.001279936655533,4.225800307494045,20.952860922980044,-0.00040321093389
0.0008855072705206992,22.046181754806,-0.0011898383533709,4.4445102417688895,22.03791989886985,-0.0003748224744501
0.0009178346104845991,23.0787366870147,-0.0010871990489856,4.652673316102164,23.07083395297441,-0.0003424835381105
0.0009312851998340992,24.1473182188823,-0.0010444934278009,4.868099352926672,24.13937437158194,-0.000329028431887
0.0009520963092056992,25.2494999273535,-0.0009784181555461,5.090299185354466,25.241718960692907,-0.0003082106906327
0.0009631578816228991,26.4375105049275,-0.0009432976631215,5.329802117793384,26.429655877564333,-0.0002971457696117
0.0009619998701584991,27.6062561005803,-0.0009469743495209,5.565421229876988,27.59802226863902,-0.0002983041258963
0.000982307233333799,28.824562971104,-0.0008824984714393,5.811031894974567,28.816551118265604,-0.000277990910362
0.001014022297295999,30.0112172598256,-0.0007818031433594,6.05026139958084,30.003827381403624,-0.0002462675318663
0.0010537362035564991,31.1487788525017,-0.0006557114909823,6.279593816664344,31.14234590376984,-0.0002065446331206
0.0010874906875973991,32.2662389064833,-0.0005485410041524,6.504873763547034,32.26066430645496,-0.0001727837464572
0.0011149971063430992,33.3806818886755,-0.0004612081246348,6.729545468756981,33.37583293066198,-0.0001452729530643
0.0011302368261459992,34.5619110063396,-0.0004128220142606,6.967681258878064,34.55741717398737,-0.0001300311353385
0.0011391153474087992,35.7932332581397,-0.0003846327092512,7.215915824840964,35.78889711694885,-0.0001211514989405
0.0011592074831559991,37.0476801605449,-0.0003208401782539,7.468812320365852,37.0439364174562,-0.0001010571307467
0.0011792196686787992,38.2829098699663,-0.000257301489219,7.717834629785207,38.27980742910924,-8.104312302929043e-05
0.001207514182319099,39.5526057935631,-0.0001674664084109,7.973805327982322,39.55051957849679,-5.274671656742312e-05
0.0012386443449448991,40.7904728138952,-6.862814207405855e-05,8.223359319281272,40.78959112118228,-2.161539646892325e-05
0.0012667550220660992,42.0535780264845,2.0623257785650857e-05,8.478001330139275,42.05385118610039,6.495493167365914e-06
0.0012945527719286992,43.3646979143335,0.0001088811135995,8.742323099529633,43.36618503137281,3.429267612520059e-05
0.0013192983833182992,44.681750343413,0.0001874484297614,9.007840869232062,44.68438830370934,5.9037132789685664e-05
0.0013527874072563992,46.0376817645766,0.0002937760807648,9.281196643738642,46.04194153456598,9.25236190114146e-05
0.001379376580849999,47.4476771205292,0.0003781967069245,9.565451707498688,47.45332894895068,0.0001191099791717
0.001404568592145299,48.8287385438016,0.0004581813427871,9.843873690430405,48.83578497435045,0.0001442986727882
0.001428965350334899,50.2976164741647,0.0005356410500391,10.139999481191603,50.30610197592932,0.0001686916133016
0.0014574416068699992,51.701980559487,0.000626053164538,10.42311928079258,51.712175264539646,0.0001971626612322
0.0014759676979462992,53.0313932670705,0.0006848735037052,10.691128882641411,53.04283257293292,0.0002156849284769
0.0015056724098558992,54.4638421786178,0.0007791859640182,10.979910583209348,54.47720830818382,0.0002453827932327
0.0015177442570512992,55.8605865572748,0.0008175140788636,11.2614942499466,55.874969806397374,0.0002574516057396
0.001542224262999699,57.3096753922027,0.0008952380977498,11.553630559068065,57.32583470079507,0.0002819250106061
0.0015743772113719992,58.7683011089204,0.0009973237088318,11.847689503558351,58.78676127270739,0.000314068378932
0.001612305200390299,60.1606356358413,0.0011177450739649,12.128384144185606,60.18181492848022,0.0003519837390424
0.0016532595874322992,61.607913279428,0.0012477752528233,12.420155317132686,61.63212519425262,0.000392922875325
0.0016860286393797991,63.0300893532894,0.0013518169927566,12.706866013623143,63.05692561969657,0.0004256785176197
0.0017162126522071992,64.4063498191601,0.0014476512334836,12.984320123542677,64.43571609687976,0.0004558492293551
0.001734750673589899,65.7547195876721,0.0015065094513737,13.256151468874696,65.78591962122525,0.0004743786304504
0.001758195434184499,67.1163397232085,0.0015809465662615,13.530654088198832,67.14975936000393,0.0004978119974257
0.0017868478295491991,68.4518365853215,0.0016719179215445,13.799890255600817,68.48788252306942,0.0005264497227702
0.0018132946111959992,69.7895427077936,0.001755886453273,14.06957180989119,69.82813877476076,0.0005528822358384
0.001844358203779599,71.1250249703392,0.001854513359726,14.338805034020382,71.16656900467568,0.0005839281767301
0.001872005794111099,72.519410306152,0.0019422944590285,14.619913117720245,72.56377378609204,0.0006115592458258
0.001894307028817299,73.8803990769048,0.0020131008792207,14.894288453904007,73.92724276079106,0.0006338465978104
0.0019186693480531991,75.2451916373972,0.0020904512427947,15.169430634099276,75.29473381200278,0.0006581931835853
0.0019415635520232991,76.6169975452468,0.0021631403403997,15.445986705121756,76.6691970155304,0.000681072061981
0.0019685216479937992,77.9699576649689,0.0022487322951061,15.718743465257733,78.02518083405528,0.000708011440928
0.002002438825265699,79.3164530868837,0.0023564193329443,15.990196942315754,79.37532011789929,0.000741904038589
0.0020394949067356993,80.648657222354,0.0024740723916116,16.258769296026568,80.71150151093806,0.0007789319526565
0.002067324652269299,81.9185954080104,0.0025624318336808,16.514788834254897,81.98470905104786,0.0008067396425151
0.0020914468450664993,83.2533168813122,0.0026390197958119,16.78386868327254,83.32251598408914,0.0008308420923642
0.002109024817808699,84.5344544686212,0.0026948298592684,17.042146020874036,84.60620438107443,0.0008484053124179
0.002136802893318399,85.8635341245527,0.0027830252490117,17.310088479509826,85.93879723744656,0.0008761594457057
0.0021795014137907993,87.1439264454162,0.0029185930515115,17.568215571395907,87.22403279445714,0.0009188196618901
0.002218864594129399,88.4287014374707,0.0030435711490866,17.827226209794095,88.5134696404459,0.0009581459178879
0.002252687289129399,89.730802344795,0.0031509582057116,18.08972975271067,89.81985368588268,0.0009919356504518
0.0022730288520457992,90.9918303503466,0.0032155426679712,18.34395299862988,91.083984086702,0.0010122568393742
0.0022897137191966992,92.3278986454715,0.0032685171211753,18.613304366927057,92.42294598956124,0.0010289246867901
0.002314868735191699,93.5804317840124,0.0033483842969594,18.865815047656906,93.67912257087484,0.0010540535177476
0.002351603169555899,94.8778782616398,0.0034650161260657,19.127380257546584,94.9814226327212,0.0010907485791793
0.002382966081064299,96.1874487958327,0.0035645933701049,19.39138967723987,96.29543907686102,0.0011220768095523
0.002416644955644599,97.4331323275015,0.0036715237968973,19.642519477224305,97.54580258386268,0.0011557173491932
0.0024458658701517993,98.7226960245877,0.0037643002004577,19.902495518556883,98.8397422811027,0.001184904086153
0.002464890354067899,99.9231289718589,0.0038247029368913,20.144502800726755,100.04349945527372,0.0012039058606953
0.0024869916023703992,101.138911212591,0.0038948744002518,20.389604500458343,101.26298156098512,0.0012259802735441
0.0025170310210619992,102.302200920198,0.0039902495545976,20.62412370551192,102.43077141205823,0.0012559824369974
0.0025430900022427993,103.423493024175,0.0040729868198466,20.85017619367368,103.5561678348679,0.0012820083704232
0.0025701619170318993,104.567939103075,0.004158940149302,21.080896523179923,104.70491289843424,0.0013090452355289
0.002592703626819999,105.770498126032,0.0042305100778792,21.32333242220805,105.91143140422552,0.0013315572031083
0.002618883092232899,107.01136580342,0.0043136298805652,21.573491345969472,107.1567539688026,0.0013577014904991
0.002651392663171399,108.244475179965,0.0044168477682949,21.822086196280942,108.3950576582733,0.0013901664261026
0.0026854822881544993,109.361630286071,0.0045250823276163,22.04730466567192,109.5174949728511,0.0014242081143336
0.002718992298007399,110.497096504402,0.0046314766088992,22.27621465528744,110.65828224229536,0.001457669873077
0.002751409116326299,111.649949790317,0.0047344000070617,22.50862987772791,111.81643656923848,0.0014900389489153
0.002784104568781799,112.835849345564,0.004838208068608,22.747707228065703,113.0077936972906,0.0015226851872563
0.0028164325104816992,114.022674197291,0.0049408492835051,22.986971118173862,114.20011320457006,0.0015549634201887
0.002836775012706699,115.188989364005,0.0050054367280695,23.22210025578341,115.37058659173157,0.001575274108884
0.002858466184569099,116.267110077915,0.0050743061987326,23.43944939170767,116.45292894952983,0.0015969309035938
0.0028657050382899993,117.38588701913,0.0050972895592965,23.66499482305661,117.57434366678712,0.001604158180474
0.002877499642254199,118.564142347324,0.0051347374268828,23.90253109722052,118.75588903683489,0.0016159338098623
0.002923739826790199,119.71389022859,0.0052815500127846,24.134320270083744,119.91303192889464,0.0016620982680654
0.002961414218257599,120.882438424948,0.0054011662056936,24.36989958646952,121.08807815448584,0.0016997093856953
0.002997886235348099,121.970248291163,0.005516964859956,24.589202055498465,122.18218705455908,0.0017361188007796
0.0030311899664014993,123.077686313316,0.0056227042060505,24.812461560764504,123.2956483367821,0.0017693642101261
0.003038169548257899,124.204017145784,0.0056448643784446,25.03952985659005,124.42484071493232,0.0017763314292078
0.003054150508972399,125.296011360664,0.0056956039287131,25.259675890309865,125.52077874792631,0.0017922839003961
0.0030750514111786992,126.368221925606,0.0057619642932181,25.47583354020217,126.59755395160056,0.0018131471581623
0.003099014577909499,127.397949909009,0.0058380473475884,25.683426701656213,127.6322035353254,0.0018370666294384
0.003132980828725299,128.438244677442,0.0059458901939286,25.893150126972305,128.6787737166713,0.0018709699645435
0.0031688281669627993,129.522081740062,0.0060597054928326,26.1116516787965,129.76928352594024,0.0019067496560904
0.003202961504909299,130.737186970846,0.0061680788408128,26.35661689332256,130.99117036507033,0.0019408173920042
0.003243556235611299,131.95435094405,0.0062969671107916,26.60199715032048,132.2160555764974,0.0019813325914012
0.003263215503096199,133.113992512395,0.0063593852850562,26.83578089049883,133.3806139817551,0.0020009527534245
0.003279159641254499,134.224770142546,0.0064100079237088,27.05971366073727,134.4957565488993,0.0020168648934144
0.003298393803651899,135.286060544077,0.0064710763893205,27.273669805685923,135.5617917038222,0.002036060117969
0.0033163126927323993,136.337261517922,0.0065279688621511,27.48559192201308,136.61757817869048,0.0020539424003415
0.003349667525244299,137.482306069547,0.0066338704553764,27.716432903620674,137.76956270210505,0.0020872282402775
0.003391385509333899,138.569193268142,0.0067663250548609,27.935549362857422,138.8645016789269,0.0021288583736761
0.0034239529332190993,139.706452823467,0.0068697266256964,28.164820889210947,140.00873475692936,0.0021613560118202
0.003460274608732599,140.764329116958,0.0069850479454517,28.378088749978733,141.07401276668753,0.0021975986112675
0.003478407418280299,141.808985776062,0.0070426196157657,28.5886915324541,142.1235390815481,0.0022156914522555
0.003500899052358699,142.894022366049,0.0071140305539646,28.80743490899548,143.21419636324302,0.002238133055166
0.0035216260065425993,144.000899501931,0.0071798386334985,29.03058133958929,144.32653831185306,0.002258813457702
0.003546471700469699,145.1467467168,0.007258723711717,29.261584138106883,145.47858297886987,0.00228360278592
0.0035776427212875993,146.255736126847,0.0073576917028139,29.48515640317236,146.5946667146232,0.0023147022221295
0.0036080987719191993,147.327339393603,0.0074543896635692,29.701191621750368,147.6732403057091,0.0023450873959656
0.003642161573861099,148.367898769414,0.0075625390597347,29.910968391913865,148.7212965740296,0.0023790698338403
0.003667827827110699,149.381722315892,0.0076440294138022,30.115355218883828,149.7413690180234,0.0024046747700495
0.003688395578214099,150.438999526387,0.0077093320235555,30.32850230451962,150.8042858875336,0.0024251929113207
0.0037082437945904993,151.639237844056,0.0077723501105506,30.57047034936169,152.01044831555868,0.0024449928542452
0.0037357390960353993,152.787666678668,0.0078596476926381,30.801993602419465,153.1658894288647,0.002472420635846
0.0037767759622210993,153.907771351168,0.0079899397427777,31.02780670439547,154.29508279023608,0.0025133553291241
0.003805588797485699,154.913327536648,0.0080814204947428,31.23052683138824,155.30763296658927,0.0025420954254236
0.003829813175146499,156.0374107712,0.0081583328938159,31.45714201147392,156.43835727228992,0.0025662580086928
0.003857058547740699,157.10357303114,0.0082448369518025,31.672080323077825,157.51153943875806,0.002593433183021
0.0038714667675713993,158.165979603238,0.0082905830497649,31.88626148801277,158.5789837574264,0.0026078039812482
0.0038987050804461993,159.104170302355,0.0083770646931424,32.07540073295477,159.52395799607834,0.0026349709854543
0.003924018568800499,159.959647598671,0.0084574350186673,32.24786495589208,160.38574155935598,0.0026602175426038
0.003947543900297599,160.925414063858,0.0085321279461706,32.44256347527377,161.35786641742757,0.0026836800995212
0.003968070023742899,161.960600892776,0.0085972983881095,32.65125713998364,162.3991595110414,0.0027041510017369
0.003995244247709799,163.011697259859,0.0086835765492044,32.86315816758758,163.45753176429105,0.0027312514745432
0.004011598411066699,164.040551929378,0.0087355010178625,33.07057526896261,164.4918830816142,0.0027475608985113
0.004039545718856499,164.996328002958,0.0088242337200951,33.26325972539633,165.45490002225108,0.0027754311363841
0.004066921581088399,165.980895565635,0.0089111520826814,33.46174854603201,166.446747850109,0.0028027307514985
0.004084710480682499,166.885787609117,0.0089676318388927,33.64417478199799,167.35714833428935,0.002820469706064
0.004107842652215599,167.785052419148,0.0090410764835103,33.82546656770024,168.2628343063012,0.0028435364598908
0.004132101207973199,168.650345334759,0.0091180973980407,33.99990961948742,169.1346824292395,0.0028677258409759
0.004157974207754299,169.58819503305,0.0092002441723456,34.18898011866288,170.07961323873548,0.002893524417587
0.004183373131608699,170.560416431704,0.0092808857555834,34.384979952631525,171.0589839086575,0.0029188496345725
0.004212457492114099,171.510150741137,0.009373228600188,34.57644638941322,172.0164826624439,0.0029478488054973
0.004238649610116499,172.510786168264,0.0094563885748456,34.77817449152202,173.0245905863299,0.0029739634857954
0.004256414240592399,173.467327709834,0.0095127912766066,34.971013266302535,173.98706266473616,0.0029916752065367
0.004280829279795999,174.384271046764,0.009590309026078,35.15586904302762,174.91101090459892,0.0030160170167586
0.004311034033256799,175.282857469825,0.0096862091183161,35.337024065916715,175.81760594614272,0.0030461303559965
0.004332244904508999,176.13007098853,0.0097535536345418,35.507822311287654,176.67113999452758,0.0030672764908957
0.004350639374289199,177.129990160571,0.009811956076094,35.70940601637111,177.67738911591414,0.0030856144580506
0.004377326939216799,178.162589486105,0.0098966890947391,35.917578040398766,178.7179342912885,0.0031122194484418
0.0044239479366959995,179.160245834743,0.0100447107617355,36.11870556028419,179.727053031408,0.0031586944967135
0.004461256235812899,180.115264389507,0.0101631646114317,36.31123730092461,180.69181276148245,0.0031958844446799
0.004507056592525999,181.076622724236,0.0103085807439958,36.50504714120598,181.66454177500856,0.0032415376202695
0.004532331102690899,182.084073285731,0.0103888273137694,36.708149174403374,182.6798654098108,0.003266730017471
0.004559485865542899,183.137137762121,0.0104750436858245,36.92044697284359,183.74134863410688,0.0032937958514949
0.0045831510208225994,184.093312734061,0.0105501805538375,37.1132118471867,184.70503484054868,0.0033173829086393
0.0046051451151975994,184.955413946402,0.0106200118034781,37.28701145159464,185.57406864852103,0.0033393039208036
0.004627383487207199,185.939106317438,0.0106906186346086,37.4853238335955,186.5651863410284,0.0033614679103588
0.004647674913992399,186.884226522025,0.0107550439146516,37.67586006684024,187.5172810301195,0.003381691038188
0.004669929951346299,187.852914778438,0.0108257036582502,37.8711476193331,188.4934313096915,0.0034038706970202
0.0046915543352478994,188.81607234945,0.0108943610771378,38.06532018564912,189.46395596184115,0.0034254213672296
0.004719949072740699,189.661610939443,0.0109845143686775,38.23578076539171,190.31778123567943,0.0034537186068059
0.004757262322089299,190.630404131224,0.0111029839353593,38.43108947285476,191.29703919095945,0.0034909025176444
0.004799096353531599,191.608476889377,0.0112358069851886,38.6282689408984,192.2865480273471,0.003532589896237
0.004827789030087299,192.650929405012,0.0113269062332529,38.83842736805042,193.33821728315988,0.0035611809834243
0.004840172141419599,193.693146934899,0.011366222611733,39.04853842207564,194.38655147865623,0.0035735199985583
0.004853629978832499,194.613054109183,0.0114089512455189,39.23399170841129,195.31237091109583,0.0035869297400355
0.004878059453614499,195.509569537455,0.0114865148279518,39.414729218750935,196.21688404753328,0.0036112714487139
0.004910278844616299,196.404935887455,0.0115888113943825,39.59523507491093,197.1218177012898,0.0036433741812891
0.004939043750729099,197.334665394019,0.0116801399712906,39.78266854343423,198.0606170516536,0.0036720340660708
0.004970865793585599,198.321786159703,0.01178117495736,39.98167208979613,199.05768022603488,0.0037037389689754
0.004988349767755999,199.310774574649,0.011836686575351,40.18105215424924,200.05382313204444,0.0037211581551261
0.005018111955827599,200.343430702358,0.0119311815224784,40.389235629595376,201.0962917538685,0.003750809359591
0.005036298845956499,201.270537920075,0.0119889248986376,40.57614044468712,202.03054338887253,0.0037689279977907
0.005053954981756199,202.225933466024,0.0120449831298017,40.76874818675044,202.99311707453003,0.0037865175594323
0.005082105792950199,203.065251012939,0.0121343619553426,40.93795460420851,203.8413351881653,0.0038145615854028
0.005096037298911999,203.895741720902,0.0121785944867713,41.10538153093385,204.6778404786968,0.0038284399537011
0.005129420237407499,204.784026294918,0.0122845853164946,41.28445970105547,205.5763686075086,0.0038616947790075
0.005151902691841999,205.671623171415,0.0123559671093241,41.46339923135727,206.4720237418803,0.0038840903297041
0.005165061172212699,206.538198971195,0.0123977452845011,41.63810091259291,207.34468967430192,0.0038971977145735
0.005189126469017099,207.38207166136,0.012474152601855,41.808225646930175,208.19684823105848,0.0039211691193583
0.0052146122519150994,208.221810577138,0.0125550699625562,41.97751701235102,209.0451930651777,0.0039465548416444
0.005257104376398099,209.121515392779,0.0126899824577897,42.15889750318424,209.9573416484895,0.0039888787034394
0.005286530264826999,210.06703105317,0.0127834096535515,42.34951346031908,210.91281779731423,0.0040181870198646
0.005316300182039299,211.040123747118,0.0128779291407005,42.545688947419,211.8961110729322,0.0040478371164221
0.005346113519001199,211.942631617096,0.0129725864855546,42.72763453400656,212.80859826863264,0.0040775295769428
0.005373061163356899,212.838826261734,0.0130581452563839,42.90830737436558,213.71419013874944,0.0041043672050642
0.005404376897814999,213.80060842206,0.0131575727132884,43.1022026578873,214.68662324141704,0.0041355541853391
0.005435766581289499,214.745344359149,0.0132572349583199,43.29266142280444,215.64201506351893,0.004166813834545
0.005449980014813599,215.709512883695,0.0133023626097589,43.48703779735291,216.6132754533811,0.0041809680663841
0.0054811286239882994,216.618556540264,0.0134012594438886,43.67030099851723,217.53287511555743,0.0042119862350176
0.005504227631405399,217.488782654374,0.0134745987924379,43.8457385831218,218.41179811520027,0.0042349878898037
0.005531622128689399,218.299629073329,0.0135615763213146,44.00920522118312,219.2320659491062,0.0042622662449813
0.005567756528812199,219.145717236102,0.0136763030417045,44.17977659479817,220.08968676026345,0.0042982463111392
0.005587575521416899,219.991502453941,0.0137392283432244,44.35028689471451,220.9434752053689,0.0043179801049345
0.005619906191008099,220.867155272611,0.0138418782191765,44.52681850295838,221.8300580335242,0.0043501709541753
0.005653262783053199,221.773895921759,0.0139477853989197,44.70961741782661,222.7481493729084,0.0043833822030057
0.005678722307015999,222.701601440073,0.0140286193875015,44.89664285031872,223.6856001813612,0.0044087300511181
0.005695754877017999,223.559415120955,0.0140826977972579,45.06957808838453,224.5510118714685,0.0044256875506248
0.005719009694493099,224.334655245051,0.0141565318427413,45.225866497402286,225.334907431006,0.0044488394089444
0.005740899499197599,225.077642937598,0.0142260319726781,45.37565281621976,226.0861348257131,0.0044706318082696
0.005785294153772699,225.835776312062,0.0143669850009541,45.528492504511696,226.8576910241736,0.0045148274570352
0.0058258571170447995,226.681770571295,0.014495772409343,45.69904494717307,227.716708321074,0.0045552068830564
0.005855841812320299,227.522118975978,0.0145909738168427,45.86845918555717,228.5677155998303,0.0045850548570046
0.005883155400258599,228.314529646529,0.0146776944585468,46.02820917674025,229.3700039478199,0.0046122431277042
0.005910875420524999,229.074193894383,0.0147657055228926,46.18135748910761,230.13952998570224,0.004639835210221
0.005935125082041299,229.965402106087,0.0148426981982069,46.36102506458714,231.04045944765863,0.0046639723266223
0.005979098328168999,230.857261852823,0.0149823132546623,46.54082398952912,231.9466400620175,0.0047077400024526
0.006012468115424499,231.634771920153,0.0150882623291985,46.69757001910285,232.7355486770965,0.0047409525110891
0.006053869403505999,232.230978880028,0.0152197114188573,46.81776534221364,233.34420359847613,0.004782157133254
0.006102066554463199,232.80829581493,0.0153727373731464,46.934152436289885,233.9355086621277,0.0048301231977053
0.006122677534767499,233.482481630241,0.0154381772356126,47.07006829665659,234.6177710579003,0.0048506346541155
0.006158354850958499,234.177950954578,0.015551452714519,47.21027491244293,235.3249768856184,0.0048861387014461
0.006197320943577899,234.821949277359,0.0156751700585856,47.34010497431557,235.9812796674098,0.0049249141129448
0.006237414766281599,235.364144770129,0.0158024679456698,47.44941158565801,236.535588660929,0.0049648101665932
0.006306298565202899,235.862934857259,0.016021174007245,47.54996766722342,237.05310843874176,0.005033350469156
0.006349798706228299,236.358705196796,0.0161592869550006,47.64991496767408,237.5616620917841,0.0050766312722049
0.0064033780776195995,236.811116699088,0.016329401459168,47.741121126536136,238.0290643509221,0.0051299379093218
0.006447803582522899,237.374617279451,0.0164704524372359,47.85472284353733,238.606008568808,0.0051741351209904
0.006499995399104199,237.92077189948,0.0166361614548816,47.96482761493517,239.1674139072878,0.0052260562395636
0.006567949156134399,238.407753127349,0.0168519146334525,48.06300303047356,239.673147490705,0.0052936535080418
0.0066354147762895995,238.844059194387,0.0170661179774452,48.15096233358842,240.12788309751244,0.0053607606804644
0.006719640158236299,239.148871903149,0.017333533565126,48.21241257567483,240.45447662699004,0.0054445322494241
0.006792692832427499,239.587235163455,0.0175654758056831,48.300786608952535,240.912735567428,0.0055171856274393
0.0068730098726971995,239.910531566037,0.0178204824085394,48.36596316371306,241.25708948962628,0.0055970575739939
0.0069472594539586995,240.130686829287,0.0180562248290446,48.41034646478426,241.4963100323555,0.0056708900112361
0.007026031198106299,240.320648559887,0.0183063251167132,48.44864274967322,241.70628255194896,0.0057492132463612
0.007116568119079799,240.393779592215,0.0185937798408041,48.46338596579054,241.80159975373823,0.005839227093317
0.007229131929953999,240.636644365104,0.0189511699403297,48.51234750400496,242.07297379541384,0.005951129272545
0.007328998500427399,240.881696193865,0.0192682463015827,48.56174995268319,242.34354433616625,0.0060503983617397
0.007430054505282599,241.065589449213,0.019589099116998,48.59882283296134,242.55291471706127,0.0061508397390747
0.007530609780323099,241.327060064071,0.0199083621152516,48.65153530891671,242.8402652609102,0.0062507734194482
0.0076060077157767995,241.350524448016,0.0201477505603171,48.65626572872003,242.8820741060256,0.0063256987224366
0.0077070420288804994,241.376261435352,0.0204685345044213,48.66145430536696,242.9323616985765,0.0064260909006131
0.007824597987688298,241.291001824192,0.0208417746736361,48.64426596775712,242.87491763231665,0.0065428870352346
0.0079557303557094,241.391950587338,0.0212581199421025,48.66461723840734,243.0081833554148,0.0066731557343848
0.0080751429035796,241.419898697143,0.0216372547815903,48.670251577344025,243.06514715618417,0.0067917670420033
0.008190654603194899,241.465042343231,0.0220040044278695,48.67935253639537,243.1384904883952,0.0069064902902473
0.008304104241686,241.464561214724,0.0223642070300782,48.67925554088836,243.1654000926557,0.0070191527427924
0.008419981244321098,241.383866824114,0.0227321165134452,48.66298755174138,243.11210814225944,0.0071342126152821
0.008539114922781699,241.311990587826,0.0231103659425576,48.64849730250573,243.0684656772155,0.0072524923979974
0.008665234398234398,241.271751723502,0.0235107952771196,48.640385147458005,243.0583629867849,0.0073776926638856
0.008785360937053198,241.237622911118,0.0238921970378693,48.63350477888139,243.05296049207536,0.0074969290983135
0.008906825034830698,241.209385986506,0.0242778455483126,48.6278122148796,243.05380936218592,0.0076174787268304
0.009027038466766998,241.1650439396,0.0246595231947106,48.61887285822336,243.0381195285077,0.0077367727985976
0.009155173068738698,241.216810296818,0.0250663505559708,48.62930895583852,243.121196163556,0.0078639117948089
0.009284388331085299,241.197211183534,0.0254766090139216,48.62535777460045,243.1326086778871,0.0079921066873685
0.009407051344114598,241.232019759911,0.0258660640802896,48.632375183598064,243.197286809148,0.0081137858683583
0.009525387616904399,241.272604569825,0.0262417817463972,48.64055708127672,243.2667535558112,0.0082311589822099
0.0096474365180765,241.181821690407,0.026629287007618,48.62225525278605,243.20465632058463,0.0083522000769104
0.009791885047530598,241.14551854396,0.0270879110886354,48.61493653846234,243.2028818087605,0.0084954369087734
0.0099223919913036,241.186096515705,0.027502270635114,48.62311705756613,243.2752824369024,0.0086248314633976
0.009985737008678698,241.181286404234,0.0277033910652806,48.62214733909357,243.28570829238643,0.0086876305180587