File: example/data/02 processed data/test_ID_151.csv
Strain,Stress_MPa,Displacement(mm),Force(kN),True Stress (MPa),True Strain
-0.0022996040305562,0.264751278298104,-0.007301242797015935,0.053373857704897776,0.2641424551914348,-0.002302252180481298
-0.0022975190550994,1.20766253411236,-0.0072946229999405945,0.2434647668770518,1.204887906428107,-0.002300162401539059
-0.002278978390349,2.76473676539784,-0.007235756389358075,0.5573709319042045,2.758435990054495,-0.0022815792138325035
-0.0022491175251872,5.27253648024973,-0.0071409481424693595,1.0629433544183455,5.260677926049812,-0.0022516505888261823
-0.0022332095493718,7.9995276167087,-0.007090440319255465,1.612704767528474,7.981662995244602,-0.0022357068805528035
-0.0022104605826438,10.6047179126616,-0.0070182123498940645,2.1379111311925785,10.581276601725605,-0.002212907256820381
-0.0021983385277428,13.156582712736,-0.00697972482558339,2.652367074887578,13.127660090065158,-0.0022007584210309347
-0.0021934756034432,15.8266539265782,-0.00696428504093216,3.190653431598165,15.791938547306112,-0.002195884794700856
-0.0021693584044238,18.6199529569459,-0.006887712934045565,3.753782516120294,18.579559605508777,-0.0021717148709977296
-0.0021560466272749,21.4106056637294,-0.006845448041597807,4.316378101807847,21.3644433996002,-0.002158374242036799
-0.0021404994029784,24.1911186696315,-0.006796085604456419,4.876929523797711,24.139337594561773,-0.0021427935461515377
-0.0021350405594661,26.8123806508604,-0.006778753776304868,5.405375939213457,26.75513513067497,-0.0021373230078867112
-0.0021219803051348,29.2853102280728,-0.00673728746880299,5.903918541979476,29.223167376539067,-0.0021242348953711535
-0.0021129968777836,31.5012589561555,-0.006708765086962929,6.350653805560949,31.43469689433489,-0.00211523240534995
-0.0020924346573311,33.5935636089774,-0.006643480037026242,6.772462423569843,33.523271272218715,-0.0020946268572859736
-0.0020608227429171,35.6449112011009,-0.006543112208761793,7.186014098141942,35.57145335742842,-0.002062949160054073
-0.0019992599845055,37.5813966001321,-0.006347650450804962,7.576409554586632,37.506261617747626,-0.002001261172456457
-0.0019624661932366,39.4791379409633,-0.006230830163526204,7.9589942088982015,39.401661467416034,-0.001964394353061683
-0.0019305838698569,41.2503945286906,-0.006129603786795657,8.316079536984025,41.17075718238828,-0.0019324498489023104
-0.0018969407152797,42.9692809243187,-0.006022786771013047,8.662607034342651,42.88777074582707,-0.001898742185867426
-0.0018733981687244,44.645711903121,-0.00594803918569997,9.000575519669193,44.56207270820029,-0.0018751551737967178
-0.0018196374937207,46.2785658894964,-0.005777349042563222,9.329758883322475,46.19435567584824,-0.0018212950450919427
-0.0018016152740932,47.8938525894902,-0.00572012849524591,9.655400682041225,47.80756629312981,-0.0018032401347669149
-0.0017713382287924,49.4862137050188,-0.00562399887641587,9.97642068293179,49.39855688288491,-0.001772908903424171
-0.0017585210401249,51.0498568185832,-0.005583304302396557,10.291651134626372,50.96008457127236,-0.0017600690533245277
-0.0017057418045353,52.7020066639696,-0.005415730229399577,10.62472454345627,52.612110648019964,-0.0017071982385230406
-0.001654455283681,54.3177338230598,-0.005252895525687175,10.950455138728856,54.227867561338655,-0.0016558254062367425
-0.0015829872135301,55.9886507511307,-0.005025984402958067,11.287311991427948,55.900021432888856,-0.0015842414616030825
-0.0015224596194229,57.6995064306526,-0.004833809291667707,11.632220496419563,57.6116612620513,-0.0015236197387086202
-0.0014598211173439,59.4361159592316,-0.004634932047566882,11.982320977381091,59.34934986202141,-0.001460887694325314
-0.0014011033420825,61.0190149057245,-0.004448503111111938,12.301433404994059,60.9335209600095,-0.0014020858051655752
-0.0013398048422438,62.5696175309997,-0.004253880374124065,12.61403489424954,62.48578645445432,-0.0013407031832422124
-0.0012772721403064,64.0191998810268,-0.00405533904547282,12.906270696015001,63.937429940574056,-0.0012780885476235012
-0.0011888027030086,65.4575440748391,-0.003774448582052305,13.196240885487564,65.37972796951064,-0.0011895098894676
-0.0010835034644766,66.9952436028794,-0.0034401234997132046,13.506241110340486,66.92265402433222,-0.0010840908787039434
-0.000986357894171,68.3924636814948,-0.003131686313992925,13.787920678189353,68.32500423504075,-0.0009868446652320146
-0.0008896584208312,69.7798470959637,-0.0028246654861390596,14.067617174546283,69.71776686739047,-0.0008900544017600287
-0.0008025575381173,71.094013804743,-0.0025481201835224274,14.33255318303619,71.03695676804898,-0.0008028797598308163
-0.0006946988849947,72.31540316932,-0.0022056689598581726,14.578785278934914,72.26516573937033,-0.0006949403000788125
-0.0005807649742434,73.4994644003225,-0.001843928793222795,14.817492023105014,73.45677848577314,-0.0005809336835445378
-0.0004524685565354,74.4875392253911,-0.0014365876669998948,15.016687907838845,74.45383595603792,-0.00045257095132079564
-0.0003063640233623,75.396031694912,-0.0009727057741753025,15.199839989694258,75.3729330632964,-0.0003064109624068665
-0.0001571779870093,76.2799100177674,-0.0004990401087545275,15.37802985958191,76.26792049506156,-0.00015719034076362522
-1.34957356192325e-05,77.0625669957504,-4.284896059106319e-05,15.535813506343281,77.06152697972009,-1.3495826687521515e-05
0.0001694956071927,77.7836386409942,0.0005381485528368226,15.68118155002443,77.79682262605532,0.0001694812444352023
0.0003347962084915,78.4197492673612,0.0010629779619605124,15.809421452300016,78.44600390208676,0.0003347401767466017
0.0005466102285181,78.9965619490738,0.0017354874755449673,15.925706888933279,79.03974227785292,0.0005464608915640622
0.0007540144356775,79.539101753678,0.0023939958332760626,16.035082913541483,79.5990753846011,0.000753730309607327
0.0009643775779306,80.0368293456087,0.0030618988099296546,16.135424796074712,80.11401506923826,0.0009639128646229873
0.0012122935423261,80.4282415262115,0.0038490319968853674,16.214333491684236,80.52574416403435,0.0012115593078548391
0.0014812293644626,80.7399202633714,0.004702903232168754,16.277167925095675,80.85951460414988,0.001480133426337868
0.001711491855739,80.9849383855755,0.005433986641971324,16.32656357853202,81.12354344805995,0.0017100289225139296
0.0019718725761114,81.1871705353089,0.0062606954291536945,16.367333579918274,81.34726129041954,0.001969930987341228
0.0021748024365873,81.3583614640574,0.006904997736164677,16.40184567115397,81.53529982680618,0.002172440976953858
0.0024401254116331,81.5413197949534,0.007747398181935092,16.438730070662604,81.74029084148316,0.002437153139782956
0.0026952172685038,81.6986316913321,0.008557314827499565,16.47044414897255,81.9188272542797,0.002691591683473383
0.0029874202617589,81.8647754203014,0.009485059331084506,16.503938724732762,82.10933990911634,0.002982966789240052
0.0032533247279186,81.9652282549976,0.010329306011141555,16.524190016207516,82.23188775890907,0.0032480441169543553
0.0035146554113349,82.015868418689,0.011159030930988306,16.5343990732077,82.30412593444208,0.0035084934439120396
0.0037944462009602,82.0503457622384,0.012047366688048634,16.541349705667262,82.3616813850034,0.003787265448893726
0.0040522096477304,82.097270513039,0.01286576563154402,16.550809735428665,82.42994586466428,0.004044021558664773
0.0043515640859236,82.1269523499577,0.01381621597280743,16.556793593751475,82.48433304629013,0.004342123408825511
0.004649406370675,82.1449625530404,0.014761865226893125,16.560424450692945,82.52688786525337,0.004638631266525464
0.0049412677451121,82.1357200656792,0.015688525090730914,16.558561165240928,82.54157464996129,0.00492909974873779
0.0052484427617577,82.1343620434704,0.016663805768580696,16.558287387963635,82.56543954142903,0.00523471768860766
0.0055561007113568,82.1126968188251,0.01764061975855784,16.55391967867514,82.5689232320316,0.005540722519359055
0.0058542436415806,82.078655285273,0.018587223562018404,16.547056905511038,82.55916373108629,0.005837174144204595
0.0061485265839421,82.0086111905825,0.019521571904016165,16.53293601602143,82.51284331659997,0.00612970151923113
0.0064535957395009,81.9490326876657,0.020490166472915357,16.520924989833407,82.47789861587505,0.006432860454135865
0.0067499423513155,81.9190673652741,0.021431066965426713,16.514883980839258,82.47201634746324,0.00672726348726001
0.007074968341364,81.8953906460538,0.022463024483830696,16.510110754244444,82.47479794217827,0.007050058176256961
0.007378767226398,81.8802548385231,0.02342758594381365,16.507059375446257,82.48443017941472,0.007351677302050978
0.0076887758094755,81.8154597489523,0.02441186319508471,16.493996685388787,82.44452047671116,0.007659367817532297
0.0080040084934571,81.7352306050969,0.02541272696672629,16.47782248998754,82.38944008507478,0.007972146321286937
0.0083111098106515,81.6956838963663,0.02638777364881851,16.469849873507446,82.37466569628528,0.008276762714608667
0.008673417187225,81.6448106985371,0.027538099569439374,16.45959383682508,82.35295020289752,0.008636019194388946
0.0090072063982216,81.6407020219503,0.028597880314353577,16.458765527625182,82.37605667555772,0.008966883465116362
0.009339508590393,81.591611448398,0.029652939774497775,16.44886886799704,82.35363700442431,0.009296165042663049
0.0096720013607576,81.5314493191768,0.03070860432040538,16.436740182746043,82.32002160793643,0.009625526982138562
0.009992387822746,81.4858796164139,0.03172583133721855,16.427553330669042,82.30011812761869,0.009942794015603737
0.0103320720660476,81.3991168602971,0.03280432880970113,16.410061959035897,82.24013840181031,0.010279061039288825
0.0106695188488606,81.3255237810729,0.0338757223451324,16.395225594264296,82.19322798994853,0.010613001188040644
0.0109969903731886,81.2399942258971,0.0349154444348738,16.377982835940855,82.13338966031719,0.01093696315278433
0.0113416724523741,81.1153987602403,0.03600981003628777,16.352864390064443,82.03538304382265,0.011277837892370666
0.0116726131796314,81.0527013222873,0.037060546845329695,16.34022458657312,81.99879815198656,0.011605013763109594
0.0120007106635647,80.9471961847603,0.038102256356817917,16.318954750847677,81.91862006520041,0.01192927310175122
0.0123337442499972,80.8756619363934,0.03915963799374111,16.304533446376908,81.87316166676611,0.012258303305854723
0.0126608931349983,80.820388186211,0.0401983357036196,16.29339025834014,81.8436464841657,0.012581414174207307
0.0129873578918427,80.7378584739965,0.04123486130660057,16.276752268357694,81.78642993741923,0.012903745318822834
0.013334861718447,80.6421932408971,0.042338185956069224,16.257466157364856,81.71754573643675,0.013246735023666417
0.0136799922343877,80.5243624023338,0.04343397534418095,16.23371146031049,81.62593505467675,0.013587265847703426
0.0140292568914705,80.4202688534037,0.04454289063041884,16.212726200846188,81.54850546442923,0.013931757702921314
0.0143673158962317,80.3319270002391,0.04561622797053565,16.194916483248203,81.48608117200456,0.01426508404790371
0.0147145410406974,80.2640952819057,0.04671866780421424,16.181241608832188,81.44514460602575,0.014607332584273085
0.0150484775304683,80.193754317972,0.04777891615923685,16.167060870503153,81.40054822790988,0.014936372466986779
0.0154121631563317,80.0836474175856,0.04893361802135315,16.144863319385255,81.31790965773958,0.015294602144002122
0.0157595488490052,80.0005396986848,0.05003656759559151,16.128108803254857,81.261312112013,0.01563665662812797
0.0161107405391615,79.8992877824635,0.051151601211837754,16.107696416944645,81.18652447719056,0.015982339810255826
0.0164770252965154,79.8523625620569,0.05231455531643639,16.09823629251067,81.16809195997843,0.016342752056630192
0.0168392661848306,79.7849736195427,0.05346467013683715,16.08465068169981,81.12849402787187,0.016699057559778137
0.0171916175090253,79.6880037740873,0.054583385591155324,16.065101560856,81.05796945502917,0.01704551378179882
0.0175246119964817,79.5964315327353,0.0556406430888294,16.04664059699944,80.99132811165101,0.01737282673640227
0.0178758646697382,79.4841392583352,0.05675587032641878,16.02400247448038,80.90498697510782,0.017717970289987863
0.0182269273941895,79.3795886419107,0.05787049447655166,16.002925070209198,80.82643464066744,0.018062808212020644
0.018597577369644,79.2793913667855,0.0590473081486197,15.98272529954396,80.75379598154758,0.018426757073278916
0.0189919449526594,79.1838214793524,0.06029942522469359,15.963458410237445,80.68767625802947,0.018813849354250445
0.0193325313932496,79.0967376692848,0.06138078717356747,15.945902314127819,80.62587783337987,0.019148032108480366
0.019676074322893,78.9675708712357,0.06247153597518527,15.919862287641115,80.52134266479645,0.019485002665574742
0.0200378378430997,78.8493135208733,0.06362013515184155,15.896021605808057,80.42928327924427,0.019839722532750417
0.0203977517346416,78.7427254719705,0.06476286175748708,15.874533455149253,80.3489000370568,0.02019250396541424
0.0207399177120055,78.6155046428096,0.06584923873561746,15.848885735990416,80.24598373998926,0.02052777383543903
0.0210801622813108,78.4995196374873,0.06692951524316179,15.825503158917439,80.15430225045047,0.020861049598361
0.0214313089247091,78.3582945007363,0.0680444058359514,15.79703217134844,80.03761531699492,0.021204887713160404
0.0217727849075251,78.2508578425316,0.06912859208139219,15.775372941054371,79.95459693916636,0.021539143098636686
0.0221424777029184,78.1796794459182,0.07030236670676591,15.761023376297107,79.91077125487075,0.021900892732966207
0.022516868779584,78.1077697788822,0.0714910583751792,15.746526387422653,79.86651218165925,0.02226710638268138
0.0228776454837459,78.0364723058473,0.07263652441089323,15.732152816858816,79.82176305406261,0.02261987618370256
0.0232478722496365,77.9579883743261,0.07381199439259589,15.716330456264144,79.77034572889109,0.022981756983997913
0.0235818964116103,77.859410097103,0.0748725211068627,15.696457075575964,79.69548264068196,0.023308138952887733
0.0239562638661831,77.7537386721007,0.07606113777513134,15.6751537162955,79.61642775231178,0.023673814636991725
0.0243405762035046,77.6426410909517,0.0772813294461271,15.652756443935862,79.53250771306736,0.02404906526894418
0.0247023669853034,77.5401072286893,0.0784300151783383,15.632085617303762,79.45553141353216,0.02440219675089899
0.0250971777590132,77.4199995838291,0.07968353938486691,15.607871916099946,79.36302307548718,0.024787415666186884
0.0254657792611698,77.3150338200702,0.0808538491542141,15.586710818126154,79.28392140490199,0.025146928164805737
0.0258211070334935,77.1993071449941,0.08198201483134185,15.563380320430811,79.19267871769652,0.025493371929694638
0.0261903617697185,77.1172029740596,0.08315439861885623,15.546828119570414,79.13693041861903,0.025853267325821307
0.0265586242567539,77.0394860030151,0.08432363201519362,15.531160378207845,79.08554876470264,0.026212066666113726
0.0269245565291288,76.9440940023248,0.08548546697998394,15.511929350868682,79.015779610873,0.026568468198565735
0.0273041625001591,76.8571328376841,0.08669071593800515,15.494397980077116,78.95565248198055,0.02693805311560527
0.0276832621243632,76.7277219854103,0.08789435724485316,15.468308752258716,78.85179562533767,0.02730700878313098
0.0280302246290881,76.5700148216834,0.08899596319735471,15.436514988051375,78.71628953698779,0.027644567990924386
0.028408752202867,76.4524381495266,0.09019778824410273,15.412811530944563,78.62435652022153,0.028012706877921435
0.0287875001825779,76.3033189207009,0.09140031307968483,15.382749094413303,78.49990072806189,0.02838092452711363
0.0291602484307509,76.2099905878094,0.0925837887676341,15.363934102502377,78.43229284625511,0.02874317692394964
0.0295442176939949,76.1072626530515,0.09380289117843381,15.343224150855184,78.3557921889673,0.029116197213179346
0.0299365152016429,76.0088528234912,0.09504843576521621,15.323384729215825,78.28429300150107,0.02949716461542463
0.0302960921910271,75.9110947600621,0.09619009270651104,15.303676703628518,78.21090428523473,0.02984622907712191
0.0306775336382017,75.8461948700915,0.09740116930129039,15.290592885810446,78.17296906454833,0.030216385634924906
0.0310522053994535,75.7682634926127,0.09859075214326486,15.274881920110722,78.12103517334523,0.030579839445850857
0.0314272425880466,75.6749441605025,0.09978149521704795,15.256068742757305,78.05319898847151,0.03094351549905236
0.0318171433699928,75.5970916611738,0.10101943019972713,15.24037367889264,78.00237516491185,0.031321464702977
0.0322034875133039,75.5011273986438,0.10224607285473988,15.221027283566592,77.9325270120664,0.03169582544534797
0.0325937843056087,75.3942793132598,0.10348526517030761,15.199486709553176,77.85166419107301,0.03207387398529928
0.0329872635035737,75.2907021274051,0.10473456162384649,15.17860554888487,77.77433635785088,0.03245486044249182
0.0333703726458837,75.1613777608982,0.10595093315068076,15.15253375659708,77.66954094535741,0.03282566667660867
0.0337701081206777,75.0576370895505,0.10722009328315169,15.13161963725338,77.5923416093472,0.03321241879480856
0.0341463911791668,74.9471287073635,0.10841479199385458,15.109341147404482,77.5063026819605,0.033576343607797474
0.0345310249499019,74.8389112509595,0.10963600421593853,15.087524508193436,77.42317556258989,0.033948208038828254
0.0349014329485629,74.7315636926616,0.1108120496116872,15.065883240440579,77.33980235202228,0.03430618831617699
0.0352824885827464,74.5958968435247,0.11202190125021981,15.03853280365458,77.22782572222609,0.03467432530586544
0.0356696932505039,74.4364216289596,0.11325127607034986,15.006382600398254,77.09154595512975,0.035048264091768935
0.0360554112287244,74.2874899294527,0.11447593065119997,14.976357969777666,76.96595592800884,0.03542062814899194
0.0364384027602986,74.1557814673375,0.11569192876394804,14.949805543815241,76.85789969944904,0.03579022301422037
0.0368292661159269,74.0763052897006,0.1169329199180679,14.933783146403641,76.80448125009963,0.036167273566955545
0.037223018607946,73.9969418488045,0.11818308408022855,14.917783476718988,76.75133139217365,0.036546967463440105
0.0376204596580839,73.9278929430938,0.11944495941441638,14.90386321732771,76.7090942571666,0.036930072077510444
0.0380064994922366,73.8205171301698,0.1206706358878512,14.882216253442232,76.62617657699425,0.03730204627730797
0.0383774643444996,73.7254555442428,0.12184844929378623,14.86305183771935,76.55485158567397,0.037659364444536
0.038780834373426,73.5943935573649,0.12312914913562754,14.836629741164764,76.44844554472579,0.03804775086096443
0.039173639343197,73.4915249756178,0.12437630491465047,14.81589143508455,76.37045546979421,0.03842581975459834
0.0395977263706543,73.382137824654,0.1257227812268274,14.793838985450245,76.2879036387283,0.03883383675958074
0.0399837817487808,73.264194108468,0.12694850705237903,14.77006153226715,76.1935736557013,0.03920511855936
0.0403814703822811,73.1536125929773,0.12821116846374248,14.747768298744223,76.10766303325748,0.03958744434367823
0.0407884897690093,73.0370338804757,0.1295034550166045,14.724266030303902,76.01610418966828,0.03997858913214902
0.0412039705423772,72.9404601006987,0.1308226064720476,14.70479675630086,75.94589667003534,0.040377707560100534
0.0416157695577326,72.8339908308002,0.132130068345801,14.68333255148932,75.86503340918479,0.04077313210192991
0.0420317147783737,72.7189141999667,0.13345069442133647,14.660133102713287,75.77541486061274,0.04117237931557148
0.0424266030534967,72.5983949767776,0.134704464694852,14.635836427318363,75.67849826277832,0.04155126746744186
0.0428425064942006,72.4686405451198,0.1360249581190869,14.609677933896151,75.57337874829999,0.04195016413196771
0.043235118402645,72.3411638589707,0.13727150092839785,14.583978633968494,75.46884264379844,0.04232657573659277
0.0436350382597255,72.2100181883082,0.13854124647462845,14.557539666762933,75.3609050946905,0.04270984813205006
0.0440324756500388,72.0854385640263,0.13980311018887318,14.532424414507702,75.25953888231916,0.04309059592111758
0.0444424722301646,71.9620421276492,0.1411048493307726,14.507547692934079,75.16021318653318,0.04348322364768809
0.0448635818432445,71.8831149350493,0.1424418723523013,14.491635970905941,75.10804894508524,0.04388633320453005
0.0452524070866893,71.7676866789161,0.14367639250023853,14.468365634469487,75.01534725218039,0.04425839413319575
0.0456444773681213,71.6745808296815,0.14492121564378513,14.449595495263791,74.94612961223147,0.044633420074400305
0.0460385360425136,71.5284170347455,0.14617235193498068,14.420128874204693,74.82148064046358,0.04501020630494072
0.0464532773304114,71.3881749711403,0.1474891555240562,14.391856074181886,74.70438966118661,0.04540661530465899
0.0468714592354518,71.2741079774971,0.14881688307255947,14.368860168263414,74.61482942410754,0.04580615380272244
0.0472785814454355,71.168069226702,0.15010949608925772,14.347482756103124,74.53279458395103,0.04619497237560791
0.0476648134010365,71.0671978322013,0.1513357825482909,14.327147082971782,74.45460255580772,0.046563700199879515
0.0480805513247914,70.9554480153152,0.15265575045621269,14.304618319887545,74.36702507538914,0.04696044489625893
0.048496974597029,70.8613941881546,0.15397789434556708,14.285657068331968,74.2979574220076,0.04735768589742853
0.0489117635803582,70.7533764082108,0.1552948493676373,14.263880683895298,74.2140488276013,0.04775321108161096
0.0493532479342453,70.6425991139895,0.15669656219122882,14.241547981380284,74.12904082278173,0.04817402004328096
0.0497839062610741,70.5277732370926,0.15806390237891027,14.218399084597868,74.03892128873031,0.048584339428091296
0.0502115751618895,70.4212859499782,0.15942175113899917,14.196931247515604,73.95724964245244,0.04899164402518308
0.0506480667590143,70.3077150011253,0.1608076119598704,14.174035344226862,73.86866484417605,0.04940718021303288
0.0510653019963663,70.1883018095794,0.162132333838463,14.149961644811208,73.77248863809767,0.049804223167639196
0.051488408609984,70.0456684810481,0.1634756973366992,14.121206765779295,73.65220848115978,0.050206692428894875
0.0518871702084925,69.8949994898943,0.16474176541196367,14.09083189716269,73.52165322514894,0.050585855910016686
0.0522944435204577,69.7387990569346,0.1660348581774532,14.059341889878015,73.38575074540202,0.05097296443182294
0.0527256657139065,69.599126312305,0.16740398864165312,14.03118386456069,73.26878658022756,0.051382672821390564
0.0531536421258519,69.4898421146243,0.16876281374957977,14.009152170308257,73.18348031376698,0.05178913145958896
0.053593427210183,69.3767417422643,0.17015913139233102,13.986351135240485,73.094879100908,0.05220663301648724
0.054008703180988,69.2738374391561,0.1714776325996369,13.965605627733868,73.01522756361548,0.05260070737254421
0.0544222454756133,69.157505128909,0.17279062938507223,13.942153033988054,72.92121184951547,0.05299298230115109
0.0548362749033348,69.0176140801157,0.174105172818088,13.913950998551327,72.8022829389852,0.05338556521978231
0.0552679871026551,68.8988913032726,0.1754758590509299,13.890016486739757,72.70679433920911,0.05379475088242195
0.0556987997378319,68.7659962251291,0.17684368916761628,13.863224838986028,72.59617967764508,0.054202917077971396
0.0561038701611661,68.6426937256003,0.17812978776170235,13.838367055081019,72.49381450189406,0.05458654234189931
0.0565445519905164,68.4846917275894,0.17952895256988957,13.806513852282022,72.35712793953455,0.055003726603247385
0.0569514891244709,68.3590832122722,0.18082097797019508,13.781191175594074,72.25223479639472,0.05538881096684867
0.0573726556094126,68.1978062448134,0.182158181559885,13.748677738954385,72.11049549581453,0.05578720445969237
0.0578176680425242,68.0630508852184,0.18357109603501434,13.721511058460031,71.99829776726139,0.05620798214073743
0.0582564056941761,67.9340368656461,0.1849640880790091,13.695501832114255,71.8916296777343,0.05662265350161659
0.058707412146769,67.8125564529496,0.18639603356599158,13.671011380914639,71.79365615335894,0.05704874152033034
0.0591681441825905,67.7467528375892,0.18785885777972483,13.657745372057983,71.75520247738599,0.057483830392018424
0.0595982387687405,67.6441064264283,0.18922440809075108,13.637051855567945,71.67557603252867,0.05788981624823971
0.0600499560171313,67.5125654884176,0.19065861035439186,13.610533202464987,71.56669207660076,0.05831603533151984
0.0604658632209815,67.3343593664815,0.19197911572661625,13.57460684828267,71.40578953000758,0.05870830517964851
0.0609045177752821,67.1461427009604,0.19337184393652065,13.536662368513618,71.23564614263266,0.05912186291052094
0.0613349762879611,66.9624780983332,0.19473854971427648,13.499635584623974,71.06962010467758,0.05952752732284236
0.0617827342411094,66.8484632779137,0.19616018121552234,13.476650196827402,70.9785441190396,0.0599493201961872
0.0622491096559413,66.7114177595587,0.1976409231576136,13.449021820327035,70.86414411897677,0.06038846184433776
0.0627096316904201,66.599766231203,0.1991030806170838,13.426512872210527,70.77621304222983,0.06082190276978085
0.0631662916988165,66.4567884153827,0.2005529761437424,13.397688544541154,70.6546172977953,0.061251523342078694
0.0635993315332246,66.3248094915336,0.20192787761798808,13.371081593493175,70.5430230392636,0.06165875189200651
0.0640274747629629,66.1713628280048,0.2032872323724072,13.340146746125768,70.40814809150575,0.06206121273170869
0.0644694163068101,66.0073280681572,0.20469039677412207,13.30707733854049,70.2627819806834,0.06247647436732771
0.0649275853917771,65.817466795555,0.2061450836188923,13.268801305983889,70.09083599119386,0.06290680191232931
0.0653835722244296,65.6578298017318,0.20759284181256396,13.23661848802913,69.95077325867263,0.06333489603180684
0.0658497142452754,65.4951904760356,0.20907284272874938,13.20383039996878,69.80803005332243,0.06377233479671192
0.0662891726059689,65.3102833899227,0.21046812302395124,13.166553131408417,69.63964803850203,0.06418455781804192
0.0667435547811512,65.1098170838795,0.21191078643015504,13.126139124110109,69.45547772720815,0.06461060114707415
0.0671866669087402,64.9168139125088,0.21331766743525013,13.087229684761773,69.2783582656252,0.06502590257488455
0.0676212398453871,64.7329211126853,0.214697436509104,13.050156896317358,69.11024149713872,0.06543303329730193
0.0681120016600156,64.6031329946257,0.21625560527054952,13.02399161171654,69.00338169639785,0.0658926055076594
0.0685675518093495,64.4165128328805,0.21770197699468463,12.986368987108708,68.83339541392667,0.06631901493858862
0.0690497701444972,64.2191531895041,0.2192330202087786,12.946581283004027,68.65347095611361,0.06677018862470639
0.0695455707861864,63.9787829298125,0.2208071872461418,12.8981226386502,68.42822390687184,0.06723385806331668
0.0699984077497195,63.7494134092089,0.22224494460535937,12.851881743296515,68.21177084283214,0.06765716038833336
0.0704957231541732,63.5455701666074,0.22382392101449988,12.810786945588053,68.02526108874665,0.06812183385435407
0.070963681228683,63.3828639377135,0.22530968790106853,12.777985369843043,67.88074528955039,0.0685588798062882
0.0714125911130263,63.2082373560064,0.22673497678385848,12.74278065097089,67.72210136528601,0.06897795641454689
0.0719014968848034,62.9980806837312,0.2282872526092508,12.700413065840209,67.52773698576111,0.06943417119239463
0.0723783634994023,62.7543670173478,0.2298013041106023,12.651280390697318,67.2964254045043,0.06987895140161111
0.0728407548303667,62.4771454306804,0.23126939658641427,12.59539251882517,67.02802786349775,0.07031004147923949
0.0733245559713427,62.2245468349244,0.23280546520901307,12.54446864192076,66.78713410211326,0.07076089318831903
0.0738091805136719,61.877475961778,0.23434414813090826,12.474499153894447,66.44460175477127,0.07121230852619365
0.074292192471484,61.5957235540603,0.23587771109696168,12.417697868498555,66.17180490375885,0.07166201911436873
0.0747604802592854,61.3181693924423,0.23736452482323114,12.361742949516367,65.9023451848415,0.07209782769286974
0.0751972682508783,61.0426987473021,0.2387513266965386,12.306208067456103,65.63294293976053,0.07250415009423325
0.0756628402991481,60.7268277906527,0.24022951794979522,12.242528482595585,65.32159206365073,0.07293706718976208
0.0761502087349033,60.417438100852,0.24177691273331797,12.180155521131764,65.01823862345998,0.07339005119253844
0.0766394045833639,60.1369381479203,0.24333010955218035,12.123606730620732,64.74579728104348,0.07384452742547298
0.0771418525535616,59.8897461413952,0.24492538185755805,12.073772822105273,64.50975210770494,0.07431110032153447
0.077638482603637,59.6483679664018,0.24650218226654744,12.025110982026604,64.27937674509663,0.07477205687544951
0.0781372965823496,59.3698091610702,0.24808591664895996,11.968953526871754,64.00880554752625,0.0752348266982027
0.0786115395413528,59.069272733546,0.24959163804379514,11.908365383082874,63.71279920271811,0.07567460249286491
0.0790793497011352,58.7490724950767,0.25107693530110425,11.843813015007463,63.394910943532224,0.07610822361018509
0.079536863016173,58.4188432262006,0.25252954007634926,11.777238794402042,63.0652947574462,0.07653211862143637
0.080009505984134,58.0887454626506,0.2540301814996255,11.710691085270362,62.73639729035538,0.07696984293455342
0.0805255296752699,57.7632159320936,0.2556685567189819,11.64506433191007,62.41462949077242,0.07744752433516129
0.0810361496706264,57.4480259354134,0.2572897752042388,11.581522028579341,62.103392763397586,0.07791997905133598
0.0815241670638903,57.1706511006632,0.2588392304278517,11.5256032618937,61.83144081214505,0.07837131203638291
0.0820236861575374,56.86587140748,0.26042520355018123,11.46415967574797,61.53021979688202,0.07883307127298046
0.0825029964323939,56.542022815853,0.2619470136728506,11.398871799675964,61.20690912250965,0.07927594895755324
0.0830059608401964,56.2123521745899,0.2635439256676236,11.332410198397325,60.878312477929235,0.0797404720112747
0.0835073757586367,55.8585249237617,0.26513591803367154,11.26107862463036,60.52312375389344,0.0802033493164106
0.084007120684146,55.5097548127058,0.26672260817216353,11.19076657024149,60.17296948440413,0.08066447189269296
0.0845139876518749,55.1542841914255,0.2683319107947028,11.119103692991382,59.81559268452763,0.08113194899034358
0.0850114367234474,54.8045075425787,0.2699113115969455,11.048588720583867,59.46351746769432,0.08159052769580712
0.0855193355443258,54.4826469965351,0.2715238903532344,10.983701634501477,59.14196676637484,0.08205852274719055
0.0860160453243846,54.1491325364544,0.2731009439049211,10.916465119349207,58.80682677498617,0.08251599610276883
0.0865653083629789,53.7805874274123,0.274844854052458,10.84216642536632,58.43612056200839,0.08302162784757264
0.0870626268237159,53.4021772274089,0.276423840165298,10.765878929045634,58.051511054932746,0.08347922085267194
0.0875531175663151,52.9733890916898,0.2779811482730504,10.679435240884663,57.611374454720675,0.08393032652702587
0.0880255092400908,52.5594874496899,0.27948099183728825,10.595992669857482,57.18606309784701,0.08436459415162839
0.0885181830920283,52.0596876744388,0.28104523131718984,10.495233035166862,56.667916639718584,0.08481730627690075
0.089017252589125,51.6549853630111,0.28262977697047187,10.413645049183037,56.253170242557815,0.08527568642324178
0.089523018956077,51.230046790956,0.2842355851855445,10.32797743305673,55.81631524094347,0.08574000317941509
0.0900277019834436,50.8967644414546,0.28583795379743343,10.260787711397247,55.47888318251141,0.08620311058181503
0.0905312237987077,50.5304126114601,0.28743663556089694,10.186931182470357,55.10499270422924,0.08666493880233231
0.0910456445369815,50.0505713249027,0.2890699214049162,10.090195179100384,54.60745785062262,0.08713654331489805
0.0915394322166201,49.6161340954278,0.2906376972877688,10.002612633638245,54.15796683930695,0.08758902298528773
0.0920389840980977,49.1398476947857,0.2922237745114602,9.906593295268799,53.662629355349026,0.08804657640902606
0.0925411706941643,48.741326384147,0.29381821695397164,9.826251399044036,53.25190578892232,0.08850633212346921
0.093065874086393,48.3228530810306,0.29548415022429775,9.74188718113577,52.820061641365065,0.08898647644178304
0.0935861867445689,47.8900193211535,0.2971361429140062,9.654627895144547,52.37186361254398,0.08946237535347196
0.0941083114070986,47.4308507157085,0.29879388871753804,9.562059504286834,51.894487985166,0.08993970404162692
0.0946268439783158,46.9520749651058,0.3004402296311527,9.46553831296533,51.39500163728705,0.09041352343420384
0.0951456570192931,46.4895019354995,0.3020874610362556,9.372283590196698,50.91277614165229,0.09088737453101732
0.0956549678883581,46.0290487542199,0.30370452304553697,9.279456228850732,50.43195593473647,0.09135232864181125
0.0961895544715645,45.5081794495014,0.3054018354472173,9.174448977019482,49.88559095556094,0.09184012473168271
0.0966975039682101,44.9748933245341,0.30701457509906704,9.066938494226076,49.32385325025306,0.09230339483378419
0.0971834399096892,44.4169301726614,0.30855742171326317,8.95445312280854,48.7335202370691,0.09274638692119151
0.0976860505275046,43.7819971458881,0.31015321042482713,8.826450624611041,48.05888753127638,0.09320437372067143
0.0981603014899838,43.2498173656347,0.31165895723069853,8.719163180911956,47.49523247763214,0.09363632650226522
0.0985627109684168,42.8015475139048,0.31293660732472334,8.628791978803209,47.02018407051876,0.09400269903139337
0.0988157447530031,42.5559885960699,0.3137399895907848,8.579287300967692,46.76119030289086,0.09423300417982684