File: example/data/02 processed data/test_ID_144.csv
Strain,Stress_MPa,Displacement(mm),Force(kN),True Stress (MPa),True Strain
4.35108300559915e-05,-0.692253066634534,0.000138146885427773,-0.13955821823352207,-0.6922831871400721,4.350988348733942e-05
5.03551973687427e-05,-0.816110855947823,0.00015987775164575806,-0.1645279485590811,-0.816151951371049,5.035392958834275e-05
7.81635934726999e-05,-1.00171224897663,0.0002481694092758222,-0.20194518939368858,-1.0017905464056356,7.816053885829067e-05
0.0001068125107232,-1.22148965498139,0.00033912972154616,-0.24625231444424825,-1.2216201253582613,0.00010680680667325748
0.0001533056359438,-0.974404542933398,0.00048674539412156494,-0.19643995585537305,-0.9745539246415188,0.00015329388583561838
0.000210304029469,-0.0035441632572232,0.0006677152935640749,-0.0007145033126561972,-0.00354490860903729,0.00021028191867651004
0.000235892538658,1.65376602447789,0.00074895881023915,0.3333992305347427,1.6541561355437506,0.0002358647203878429
0.0002589204320432,3.8535310388115,0.0008220723717371599,0.7768718574243983,3.8545287967329607,0.00025888691793292173
0.0002790420727714,6.11127266747508,0.0008859585810491949,1.2320325697629761,6.112977969667484,0.00027900314777319196
0.0003020060125596,8.40053528564601,0.00095886908987673,1.6935479135862355,8.403072297810994,0.0003019604179234466
0.0003491235295537,10.7376205464699,0.0011084672063329975,2.164704302168332,10.74136930245409,0.00034906260011504053
0.0003904030844124,13.2180544399323,0.00123952979300937,2.664759775090352,13.223214809155582,0.00039032689695681256
0.0004059947379963,15.9589426637487,0.0012890332931382524,3.2173228410117383,15.96542191049417,0.00040591234443291424
0.0004547640809354,18.8708058737246,0.0014438759569698949,3.8043544641428793,18.879387638414272,0.0004546607070899985
0.0004893359399225,21.8855572796522,0.0015536416092539374,4.412128347577884,21.896266669394368,0.0004892162541342385
0.0005158985601956,25.0985241573836,0.0016379779286210298,5.059862470128534,25.11147244985943,0.0005157655302847473
0.0005726084604885,28.2440211230907,0.0018180318620509876,5.693994658415086,28.260193888543995,0.0005724445828194526
0.0006093787033307,31.4584272009584,0.0019347773830749725,6.342018923713214,31.477597296534945,0.0006091931075236669
0.0006541662046415,34.5391286087219,0.0020769776997367623,6.963088327518336,34.561722939395494,0.0006539523311973266
0.0007119346591425,37.6914415102147,0.0022603925427774375,7.598594608459284,37.718275353778864,0.0007116813538803887
0.0007724399716412,40.9703547439299,0.00245249690996081,8.25962351637627,41.00200188358643,0.0007721417934261881
0.0008360288985219,44.2590397424883,0.0026543917528070323,8.92262241208564,44.29604157873385,0.0008356796210194421
0.0008836516866062,47.5154415405742,0.002805594104974685,9.57911301457976,47.557428640631365,0.0008832614962992107
0.0009383625959602,50.8166729645636,0.002979301242173635,10.244641269656022,50.86435742972469,0.0009379226090028594
0.0009932427374285,54.0309779459893,0.0031535456913354878,10.892645153911442,54.08464382243031,0.000992749798239185
0.0010568355798866,57.1993710454918,0.003355452966139955,11.531393202771147,57.25982137595981,0.0010562775223138953
0.0011090071185493,60.2680018267209,0.003521097601394027,12.150029168266933,60.33483946976747,0.001108392624431774
0.0011766289361895,63.3094026648949,0.003735796872401662,12.763175577242812,63.38389434000328,0.0011759372508808098
0.0012528756969434,66.1803231678999,0.003977880337795295,13.341953150648619,66.26323888641282,0.0012520915031173556
0.0013299486790235,68.9470083173927,0.004222587055899612,13.89971687678637,69.03870430002704,0.001329065080619311
0.0013780892887156,71.5554217841368,0.004375433491672029,14.42557303168198,71.65403154444705,0.0013771405951613937
0.0014381059940965,74.2603315084608,0.004565986531256387,14.970882832105698,74.3671257363267,0.0014370729100089826
0.0015104610972414,76.9422890895859,0.004795713983741445,15.511565480460519,77.05850742398842,0.0015093214982805307
0.0015863711187987,79.4894317322897,0.0050367283021858725,16.025069437229604,79.61553147103953,0.0015851141612938584
0.0016761692560057,81.9601434596891,0.005321837387818097,16.523164921473324,82.09752253237406,0.0016747660521042786
0.0017692201522709,84.3084931276087,0.0056172739834601075,16.99659221452591,84.45765341265766,0.0017676569258202976
0.0018620956707387,86.5587479077357,0.005912153754595372,17.450243578199515,86.71992857747925,0.0018603641198043119
0.0019725589830173,88.7229472697597,0.006262874771079927,17.886546169583557,88.89795851639643,0.0019706160431692946
0.0020981003647499,90.8156422805345,0.006661468658080932,18.308433483755756,91.0061826127283,0.0020959024259735626
0.0022467280136032,92.7447186777525,0.0071333614431901594,18.697335285434903,92.95309083531956,0.002244207894195631
0.0024169486356397,94.5703385362418,0.007673811918156048,19.06538024890635,94.79891018693897,0.0024140325130865823
0.0025963198270802,96.229119703791,0.008243315450979635,19.399790532284268,96.47896127522043,0.002592955211245535
0.0027889011126847,97.5793778185042,0.008854761032773922,19.672002568210445,97.8515170538773,0.002785019343548522
0.0030284075777924,98.6944510496889,0.00961519405949087,19.89680133161728,98.99333807313384,0.0030238311886834823
0.0032889964045215,99.4781292328216,0.010442563584355762,20.054790853336836,99.80531244219688,0.0032835994862392024
0.0035852402341527,99.9826780586601,0.01138313774343482,20.156507896625875,100.34113997875434,0.0035788285806932028
0.0038993078569588,100.361314494195,0.012380302445844189,20.232841002029712,100.75265415633692,0.0038917252609361177
0.0042134490192659,100.675756815863,0.013377700636169231,20.29623257407798,101.09994898468264,0.004204597298419064
0.0045445430007813,100.910022640828,0.014428924027480628,20.343460564390927,101.36861257792907,0.004534247744942889
0.0048863658660639,101.066913927998,0.01551421162475288,20.375089847884396,101.56076384640419,0.004874466328295321
0.0052333285367842,101.13154751896,0.016615818104289835,20.388119979822335,101.66080213256014,0.005219682262582505
0.0056038216325055,101.099568534467,0.017792133683204963,20.381673016548547,101.6661124836574,0.005588178637221654
0.0059803795415587,101.028871162209,0.018987705044448872,20.367420426301337,101.63306215641424,0.005962568049538556
0.0063652639708179,100.928327188426,0.020209713107346833,20.347150761186683,101.5707626331134,0.006345091236042911
0.0067278076405722,100.814324931207,0.021360789258816733,20.324167906131333,101.4925843167583,0.006705276941101855
0.0071063333570819,100.691468205545,0.02256260840873503,20.29939999023787,101.40701534482761,0.007081202359448489
0.007493074355916,100.548157991074,0.0237905110800333,20.270508651000522,101.30157281525152,0.00746514072665356
0.0079032588254778,100.431559431392,0.025092846770892015,20.247002381368628,101.22529603982464,0.007872191656013732
0.0083057603507116,100.308193608051,0.026370789113509326,20.22213183138308,101.14132942537225,0.00827145733407846
0.0087289885598372,100.210249856021,0.027714538677483105,20.202386370973834,101.08498398059263,0.008691111200295153
0.0091438398005117,100.041100818956,0.029031691366624646,20.16828592510153,100.95586061831138,0.009102288000625436
0.0095713763876585,99.8790509851972,0.030389120030815737,20.135616678615754,100.83503097541866,0.009525860964370523
0.0099856961668198,99.7138948094513,0.03170458532965286,20.102321193585382,100.70960746662873,0.009936168541813598
0.0103998586689014,99.5286720609548,0.03301955127376194,20.06498028748849,100.56375618389217,0.010346152177750277
0.0108151161591005,99.3228409205052,0.03433799380514409,20.02348472957385,100.39702898231234,0.010757051068975001
0.0112480565050673,99.0789044575203,0.03571257940358868,19.974307138636092,100.19334957331864,0.011185267514865642
0.0116821100540653,98.8745626780561,0.037090699421657325,19.93311183589611,100.02962620080874,0.011614401019160139
0.0121207079474215,98.7161695428576,0.03848324773306326,19.901179779840092,99.91267940357471,0.012047840380269258
0.0125455376671196,98.5906880467049,0.03983208209310473,19.87588271021571,99.82756123722207,0.012467494460889154
0.0129774026567463,98.4231195321197,0.0412032534351695,19.842100897675333,99.7003959850211,0.012893917670000683
0.0134220682259428,98.2678226368597,0.042615066617368386,19.810793043590916,99.58678005670647,0.013332790244458905
0.0138516411438797,97.9991269032935,0.04397896063181804,19.75662398370397,99.35657564157144,0.013756583955570298
0.0143028986755828,97.7395539576967,0.04541170329497539,19.704294077871655,99.1375128945503,0.014201577204644805
0.0147334123009977,97.4974830772571,0.0467785840556677,19.655492588375033,98.93395369374387,0.01462593001641681
0.0151721245466265,97.2646226827221,0.048171495435539134,19.608547932836778,98.740333652045,0.01505817895066119
0.0156083546956,97.0603160097759,0.04955652615853,19.567359707570823,98.57526784892352,0.015487797178866697
0.0160651746773225,96.8834459997017,0.05100692960049894,19.531702713539865,98.43989548302787,0.015937495403327034
0.0165211143616918,96.7203334759964,0.052454538098371466,19.498819228760876,98.3182611664543,0.016386125500337155
0.0169804148653193,96.5787161825888,0.05391281719738878,19.470269182409904,98.21866285052909,0.01683785912810819
0.0174469177129518,96.4315279207585,0.05539396373862197,19.440596028824913,98.11396085332618,0.017296467649866105
0.0179068592017718,96.2367311189427,0.05685427796562546,19.40132499357885,97.96002871312837,0.01774842003462175
0.0183646696989935,96.0258479363597,0.05830782629430435,19.358810943970116,97.78933091627671,0.018198075690498434
0.0188113893068027,95.7885842638905,0.059726161049098565,19.310978587600324,97.59050061362602,0.01863664319966848
0.0192732578514614,95.5488972390703,0.06119259367838994,19.262657683396572,97.39043577298169,0.019089881050421413
0.0197282077419424,95.2804180235486,0.06263705958066712,19.208532273547398,97.16012990405629,0.019536128790511677
0.020213474413388,95.0164002373031,0.0641777812625069,19.155306287840308,96.93701181235205,0.020011894038943847
0.0206995887175827,94.8624304322257,0.06572119417832507,19.1242659751367,96.82604372692306,0.02048826348570681
0.0211974977561059,94.7042462803106,0.06730205537563623,19.09237605011062,96.71173932833118,0.020975956084604334
0.021698830756693,94.5978054596866,0.06889378765250027,19.070917580672816,96.65046723031091,0.021466762204967793
0.0221952551266975,94.4298738334183,0.07046993502726456,19.03706256481713,96.52576897473287,0.021952525516476733
0.0226921284918308,94.205215664376,0.07204750796156278,18.9917714779382,96.34293252283265,0.022438492009196488
0.0231929168677897,94.0117694381071,0.0736375110552323,18.95277271872239,96.19217659127894,0.02292804872900984
0.0236865622703165,93.784953258795,0.07520483520825488,18.907046576973073,96.00639639417815,0.023410388228847008
0.0241662441969887,93.5582640918573,0.07672782532543912,18.86134604091843,95.81921594854748,0.023878861288952054
0.0246665588051016,93.3638933686294,0.07831632420619758,18.82216090311569,95.66685933467994,0.024367251183261173
0.0251850373416621,93.1446170698116,0.07996249355977715,18.77795480127402,95.49046772888961,0.02487312053360022
0.0256987378541008,92.9584767514753,0.08159349268677003,18.74042891309742,95.34739227682797,0.025374075808974324
0.0262145367626488,92.7665518329713,0.08323115422140993,18.701736849527016,95.19838401634088,0.02587682504871368
0.0267146991068416,92.5714083409982,0.08481916966422208,18.662395921545237,95.04442566072454,0.026364092067323
0.0272106620818956,92.3795789286294,0.08639385211001853,18.62372311201169,94.89328843412414,0.026847033652314743
0.0277089873887813,92.1729543596056,0.08797603495938063,18.582067598896487,94.72697358954262,0.02733204075882852
0.0282067134290806,91.9484266816882,0.0895563151373309,18.536802819028342,94.54198960335341,0.02781622992069472
0.0287211344848318,91.7697988088087,0.09118960198934095,18.500791439855835,94.40553154204244,0.028316413791507455
0.0292333769938306,91.5518589426697,0.09281597195541215,18.456854762842212,94.22822894962677,0.028814230936367126
0.0297446454560205,91.4002158748614,0.09443924932286508,18.42628352037206,94.11888289066289,0.029310854472046705
0.0302697535622256,91.1588767929035,0.09610646756006627,18.377629561449346,93.91823352843397,0.02982066461495513
0.0307883350050867,90.9879997434474,0.09775296364115026,18.343180748278996,93.7893687609914,0.03032388328373587
0.0313189786422482,90.8334222963449,0.09943775718913804,18.312017934943132,93.67823230924645,0.030838544810187718
0.0318533421099556,90.6927144455651,0.10113436119910903,18.283651232225925,93.5815805056802,0.03135654660216708
0.0323792929218464,90.5217539364768,0.10280425502686232,18.249185593593722,93.4527843229853,0.031866131437080045
0.0328948318014256,90.3145098308353,0.10444109096952627,18.207405181896398,93.28539044094882,0.0323653764371655
0.0334103715196934,90.1143335741721,0.10607792957502654,18.167049648553093,93.12508693813476,0.0328643731276221
0.0339483174218047,89.8546646667085,0.10778590781422992,18.114700396808434,92.90507934464374,0.03338479168597879
0.034492641376378,89.6888673982441,0.10951413637000015,18.08127566748601,92.78247333686525,0.033911104960547285
0.0350566836554023,89.5237292998485,0.11130497060590229,18.047983826849457,92.66213435756515,0.034456192034498824
0.0356284336413233,89.4056821975345,0.11312027681120147,18.024185531022958,92.5910666128666,0.035008424718913494
0.0361764389769379,89.2720689927462,0.11486019375177782,17.997249108937634,92.50161454900727,0.03553743722934571
0.0367327217839466,89.0888941194025,0.11662639166403044,17.960321054471546,92.36137168112998,0.0360741542557284
0.0372783514772144,88.8806913217471,0.11835876594015572,17.918347370464215,92.19401697237697,0.03660031316865807
0.0378320915629013,88.6742032746953,0.12011689071221163,17.87671938017857,92.0289338522509,0.0371340101587993
0.038390747849467,88.4692909041785,0.12189062442205771,17.835409046282386,91.86569314370195,0.03767215692170269
0.0389419770511009,88.2768772136206,0.12364077713724535,17.79661844626591,91.71455334021626,0.03820286556357241
0.0394819914759414,88.1008777722756,0.12535532293611393,17.761136958890763,91.57927587750353,0.03872250394839603
0.040019269434732,87.882109219134,0.1270611804552741,17.717033218577413,91.39908702646706,0.039239241284261234
0.0405788965573647,87.7108249279926,0.1288379965696329,17.682502305483307,91.27003341970675,0.03977718959669941
0.0411214661830593,87.4893473699839,0.13056065513121326,17.637852429788754,91.08703760923662,0.04029846503834474
0.0416767279971007,87.318411272914,0.1323236113907947,17.603391712619466,90.95755694867421,0.0408316533508251
0.0422494746823044,87.1566118332427,0.13414208211631648,17.57077294558173,90.83893289828671,0.04138133375590709
0.042832029915417,86.9753219717979,0.13599169498144897,17.534224909514457,90.70065156439698,0.041940117906057756
0.04341812283085,86.8794093695741,0.13785253998794875,17.51488892890614,90.65155023705397,0.042501980470889676
0.0440104580783316,86.7245665803904,0.13973320439870282,17.483672622606704,90.54135448223815,0.04306950672668357
0.0445845996270008,86.5413221016527,0.14155610381572753,17.446730535693185,90.3997322987462,0.043619294069149134
0.0451797144704269,86.3587258098541,0.1434455934436054,17.40991912326659,90.26038838397321,0.044188846200457745
0.0457651143137327,86.1868082493854,0.1453042379461013,17.375260543076095,90.13115738125428,0.04474878432081582
0.0463550858334726,86.0470872396363,0.1471773975212755,17.34709278751068,90.03580735434996,0.04531277823984309
0.0469453297605427,85.9044294200251,0.14905142198972307,17.31833297107706,89.93724118703943,0.04587671444156129
0.0475310266791145,85.7028520927626,0.1509110097061885,17.27769498190094,89.7763966420599,0.046435992116897924
0.048122519013647,85.5066436777585,0.15278899786832922,17.238139365436115,89.62143876393458,0.047000486521476356
0.0486920352442997,85.3292424062618,0.15459721190065154,17.20237526910238,89.48409688487689,0.04754370694457102
0.0492614673593963,85.1535185305752,0.15640515886608325,17.16694933576396,89.34830580420687,0.04808655227300497
0.0498409808861885,84.923025296695,0.15824511431364846,17.12048189981371,89.1556721773049,0.048638705925152695
0.0504232998079007,84.6998786219989,0.16009397689008473,17.07549553019498,88.97072599544875,0.04919322560344871
0.0510123078597355,84.5017378749731,0.1619640774546602,17.035550355594577,88.8123665421339,0.0497538024444523
0.0516064016718451,84.3470707550989,0.16385032530810817,17.00436946422794,88.69991956833007,0.050318901409115886
0.0522080659359012,84.2185585683911,0.16576060934648632,16.97846140738765,88.61544662715622,0.05089087606726465
0.0528188043187997,84.0577441923977,0.16769970371218904,16.94604122918738,88.49757373437568,0.05147114267446597
0.0534271837187898,83.8786479186632,0.1696313083071576,16.909935420402505,88.36004785109732,0.05204883342888393
0.0540418053595311,83.7403404969391,0.17158273201651122,16.882052644182924,88.26581967881553,0.05263211286156048
0.0546584560747605,83.5865918583677,0.17354059803736457,16.85105691864693,88.15530591789722,0.053216976195705354
0.0552679519358946,83.4487105304226,0.17547574739646535,16.823260042933196,88.06074985313037,0.053794717557464095
0.0558850789728064,83.2658146862967,0.17743512573866033,16.78638824075741,87.91913131577546,0.05437935263171457
0.0565010872381418,83.0750062188674,0.17939095198110022,16.747921253723668,87.7688343925488,0.05496258716775787
0.0571166054282677,82.9090734918046,0.18134522223474994,16.71446921594781,87.64455832885926,0.055545018143484066
0.0577434512389428,82.6929976891057,0.18333545768364337,16.67090833412371,87.46797676896857,0.05613781938066828
0.0583782703999455,82.5269463958928,0.18535100851982697,16.637432393411988,87.34472678787404,0.05673780299555666
0.0590048267436594,82.3008103199172,0.1873403249111186,16.59184336049531,87.1569553737067,0.05732962444047777
0.0596334776144796,82.1796643040399,0.18933629142597272,16.567420323694442,87.08032347568032,0.05792307249433097
0.0602454520565198,82.0175321803599,0.19127931027945036,16.534734487560556,86.95871548312584,0.058500439862320786
0.0608705629358075,81.822013970741,0.1932640373211888,16.495318016501386,86.80256602168151,0.059089856841841815
0.0614901100420769,81.615308949913,0.19523109938359415,16.45364628430246,86.63384327836125,0.05967368515317029
0.0621099222395111,81.4258215418192,0.19719900311044775,16.415445622830752,86.4831729860699,0.06025742239710739
0.0627046387944167,81.2708032048545,0.19908722817227303,16.384193926098668,86.36685956434704,0.060817204489476015
0.0632997349974389,81.0752918008263,0.2009766586168685,16.344778827046586,86.20733628665865,0.061377030448350134
0.0638946460476267,80.8101910141995,0.20286550120121474,16.29133450846262,85.97352956609288,0.06193636914442713
0.0645096806721414,80.5481617516719,0.20481823613404893,16.238509409137055,85.74429794500026,0.0625142994125744
0.0651295665248616,80.330801348159,0.20678637371643557,16.194689551788855,85.56271161855938,0.0630964504703582
0.0657565268347051,80.1808998583496,0.2087769727001887,16.16446941144328,85.45331735151598,0.06368490081492507
0.066382148624618,80.0761254048329,0.21076332188316213,16.143346881614313,85.39175066274005,0.06427174989286594
0.0669978288240837,79.918844786227,0.21271810651646572,16.11163910890336,85.27323386903315,0.06484893747601254
0.0676310421604509,79.7421471338131,0.21472855885943162,16.076016862176722,85.1351916485849,0.0654422147089286
0.0682655219677822,79.5492300726018,0.21674303224770847,16.037124782636525,84.97969978564315,0.06603632571285052
0.0688880328425944,79.3703400477616,0.2187195042752372,16.00106055362874,84.8380066396997,0.06661888646616343
0.0695135346418565,79.177334999985,0.22070547248789438,15.962150735996977,84.68123141935634,0.0672039045718483
0.070139796608166,78.9769645257395,0.22269385423092702,15.921756048389085,84.51639275430522,0.06778929097538076
0.0707628480288116,78.7742565893432,0.2246720424914768,15.880890128411588,84.3485473369575,0.06837133653433783
0.0713920496756972,78.5628147406824,0.22666975772033862,15.838263451721572,84.17157511331179,0.06895878393662826
0.072018736417355,78.3578068488393,0.22865948812510212,15.796933860726003,84.00103708652787,0.06954354049713576
0.0726388544032961,78.1393623967627,0.23062836273046508,15.752895459187362,83.81531616506754,0.07012183141488126
0.0732548869789563,77.9257873751999,0.23258426615818623,15.7098387348403,83.63423212211634,0.07069598155167801
0.0738713336339771,77.6902511226705,0.2345414842878773,15.662354626330373,83.42933358346076,0.07127018782426732
0.0744932225949656,77.5109666470098,0.23651598173901578,15.626210876037176,83.28500833899645,0.07184912958399364
0.0751046445143263,77.2780157138131,0.23845724633298598,15.579247967904722,83.08195361277157,0.0724180005762894
0.0757138031667708,77.0465631802771,0.24039132505449728,15.532587137143866,82.88005149958478,0.07298444417304108
0.0763071058017447,76.7900602700565,0.2422750609205394,15.480876150443391,82.64968752360605,0.07353583533056483
0.0768991501626317,76.5204770905037,0.24415480176635562,15.426528181445548,82.40483674880257,0.0740857542007773
0.0774939607460609,76.2463383123521,0.24604332536874332,15.371261803770183,82.15496906056039,0.07463793810401291
0.0780959939098212,75.9812920615971,0.24795478066368232,15.317828479617976,81.91512658369993,0.07519651667607687
0.0787160044947119,75.736053224269,0.24992331427071027,15.26838833001263,81.6976927302823,0.07577144912492083
0.0793269835634788,75.5264811508834,0.25186317281404513,15.226138600018094,81.51776907974693,0.07633768352198547
0.0799254739701955,75.3035354689781,0.25376337985537073,15.181192750545984,81.3222062329676,0.07689203317198127
0.0805253289918253,75.0566587477625,0.2556679195490453,15.131422403548921,81.10062088645323,0.0774473386075152
0.0811268224074959,74.7766457270535,0.2575776611437995,15.074971778573985,80.84303738518041,0.07800385130157202
0.0817419065235618,74.5089789137283,0.25953055321230867,15.021010149007624,80.59948490326032,0.07857261825854896
0.082365197815685,74.2179898880198,0.26150950306479986,14.962346761424792,80.33096930662906,0.07914864456344645
0.0829663336693323,73.9755304356962,0.26341810940013005,14.913466935836354,80.11300897719002,0.07970388135776643
0.0835553113552911,73.7336622190629,0.2652881135530492,14.86470630336308,79.89450132314256,0.08024758947332657
0.0841398856130722,73.4720609795777,0.26714413682150423,14.811967493482866,79.65399178615604,0.0807869404602823
0.0847422746098468,73.1397010415632,0.26905672188626356,14.74496372997914,79.33772567210944,0.08134242385473484
0.0853531220938901,72.8361137433679,0.27099616264810106,14.683760530662969,79.05290345255005,0.081905392193458
0.0859674875378423,72.5470077547218,0.27294677293264924,14.625476763351918,78.78369173978359,0.08247128325314014
0.0865860876252643,72.2751296175779,0.2749108282102142,14.570666130903705,78.53315032377283,0.08304075146898647
0.08719604906919,72.021641401736,0.27684745579467823,14.519562906589979,78.30164397944539,0.08360194980587413
0.0878048767861593,71.655709773526,0.27878048379605574,14.44579109034284,77.94743054121524,0.08416179116100493
0.0883896807260522,71.2926244013253,0.28063723630521575,14.37259307930718,77.5941567102808,0.0846992467409313
0.0889874690879676,70.9271839453552,0.2825352143542971,14.298920283383607,77.23881453418907,0.08524833707834552
0.0895589451161388,70.531210434664,0.28434965074374063,14.219092023628264,76.84791123895691,0.08577297684507554
0.0901521390562399,70.2171515503053,0.28623304150356166,14.15577775254155,76.5473779610015,0.0863172636168894
0.0907483843735479,69.8747856166379,0.2881261203860146,14.0867567803142,76.21580951979581,0.0868640518135612
0.0913314722323976,69.5370634200451,0.28997742433786233,14.018671985481092,75.88798579691543,0.08739848493337846
0.0919357388329373,69.2098304312346,0.2918959707945759,13.952701814936896,75.57268732643246,0.08795202836856274
0.0925329015841211,68.8005365110831,0.29379196252958445,13.870188160634353,75.16684978499788,0.08849876340060706
0.0931350428287226,68.3966042722498,0.2957037609811943,13.78875542128556,74.76672494048498,0.08904975401322437
0.0937475445034378,68.0288319140533,0.297648453798415,13.714612513873147,74.4063678614329,0.08960991366173866
0.0943621752598765,67.6242053986333,0.29959990645010787,13.633039808364472,74.005372520269,0.09017170520907526
0.0949675904450134,67.3325027885127,0.30152209966291754,13.57423256216416,73.72690833696988,0.09072476506333049
0.0955528780811203,66.9250608852982,0.30338038790755695,13.492092274476116,73.31994306864264,0.09125914733315599
0.0961320545817919,66.5085923078915,0.3052192732971893,13.408132209270928,72.90219993379188,0.09178766902486635
0.0967238922245704,66.0358100348937,0.307098357813011,13.312819303034571,72.42305060767096,0.09232745610756161
0.0973340875909608,65.5578688811034,0.3090357281013005,13.216466366430446,71.93888423305344,0.09288368150154495
0.0979497191270834,65.1094663454781,0.3109903582284898,13.126068415248385,71.48692028653197,0.09344454889406813
0.0985435279396826,64.6760194143846,0.31287570120849223,13.038685513939937,71.04942254057346,0.09398523694567813
0.0991247838052031,64.2568252434837,0.3147211885815199,12.954175969086315,70.62626915375274,0.09451421201982174
0.0997032317590046,63.7729944586017,0.3165577608348396,12.856635682854103,70.13136810507338,0.0950403540946461
0.100303805934465,63.2570943024759,0.3184645838419264,12.752630211379142,69.60202161336959,0.09558632888480749
0.100901072291611,62.7234947038722,0.3203609045258649,12.645056532300634,69.05236257737009,0.09612900110738132
0.101494253889973,62.2716894944352,0.32224425610066426,12.553972602078137,68.59190815814097,0.09666767062384253
0.10211520938134,61.7887020103466,0.3242157897857545,12.456602325285873,68.09826825353436,0.09723125098429439
0.102709006311367,61.364504606158,0.3261010950385902,12.371084128601453,67.66719189704578,0.09776988525740966
0.103324719644634,60.9107893499706,0.3280559848717129,12.279615132954072,67.20437958288967,0.09832809372177771
0.103923708192162,60.4203667124907,0.32995777351011435,12.180745929238125,66.699475271583,0.09887084056864609
0.104532087656931,59.8516025356961,0.33188937831075593,12.066083071196335,66.10801549836528,0.09942179520518614
0.105146938223151,59.2370516816175,0.33384152885850443,11.942189619014089,65.46564629530613,0.09997830189677985
0.105756245514898,58.6258340630582,0.33577607950980115,11.818968147112532,64.82588216374666,0.10052948596639856
0.106352355645344,58.0522400588188,0.3376687291739672,11.703331595857872,64.22623253956318,0.10106843793698697
0.106920741334691,57.4901027044206,0.3394733537376439,11.590004705211193,63.63698710498478,0.10158205345295526
0.107523749914381,56.8637004610502,0.34138790597815966,11.463722012947722,62.97789876863044,0.10212666732517242
0.108118899345379,56.2195241871434,0.3432775054215783,11.333856076128109,62.297917263978256,0.10266389244629982
0.108737443544709,55.4799589161457,0.3452413832544511,11.184759717494973,61.51270781665287,0.10322192970240382
0.109388948755545,54.7553972989729,0.3473099122988554,11.038688095472937,60.74503264819976,0.10380936712872257
0.110078884280506,54.0469339723511,0.3495004575906065,10.895861888825982,59.99636016280969,0.10443107971848371
0.110740812980001,53.2932259243674,0.35160208121150316,10.743914346352467,59.1949610895587,0.1050271917935997
0.111461544537156,52.4278695028411,0.3538904039054703,10.569458491772766,58.271560814420226,0.1056758560162693
0.112303343012345,51.3101207022918,0.35656311406419533,10.344120333582028,57.0724187875261,0.10643294910656068
0.113280650296537,49.9735117465656,0.35966606469150497,10.074659968107625,55.63454365481819,0.1073111971079377
0.114443495060784,48.0079548615874,0.36335809681798914,9.67840370009602,53.50215300666782,0.1083551727476364
0.115344592666197,46.0210756255313,0.3662190817151754,9.27784884610711,51.32935784761845,0.10916340888399916
0.115945202459537,44.6748816093037,0.36812601780903,9.006456132435625,49.85471980235027,0.10970176101482332