File: example/data/02 processed data/test_ID_065.csv
Strain,Stress_MPa,Displacement(mm),Force(kN),True Stress (MPa),True Strain
-1.08401493946855e-05,0.598606346032909,-3.4417474328126465e-05,0.12067903936023446,0.5985998570506894,-1.0840208149519315e-05
-1.21702794135195e-05,0.606464220718479,-3.8640637137924406e-05,0.12226318689684539,0.6064568398794586,-1.2170353471921751e-05
-1.37041238636371e-05,0.612952659285967,-4.351059326704779e-05,0.12357125611205096,0.6129442593068016,-1.3704217765952658e-05
-2.33267963946447e-05,0.618383239590936,-7.406257855299692e-05,0.12466606110153271,0.6183688146910122,-2.332706846855321e-05
-4.01269749828164e-05,0.731631619479456,-0.00012740314557044207,0.14749693448705833,0.7316022613157646,-4.012778009138881e-05
-5.84225126825539e-05,1.49663971273846,-0.00018549147776710862,0.3017225660880736,1.4965522752858615,-5.8424219343976e-05
-6.51826568287508e-05,3.13371008135605,-0.00020695493543128378,0.6317559524013797,3.133505817807216,-6.518478131045072e-05
-6.62267380479655e-05,5.87268657670881,-0.00021026989330229044,1.1839336138644962,5.872297647833257,-6.622893113525827e-05
-5.62111768612754e-05,9.84282772489422,-0.0001784704865345494,1.984314069338675,9.842274447964162,-5.621275676868406e-05
-3.24982651999961e-05,15.1074728721553,-0.00010318199200998761,3.0456665310265083,15.106981905495399,-3.2498793280082187e-05
2.03560004388531e-05,21.6644195108729,6.463030139335859e-05,4.367546973391977,21.66486051180597,2.0355793258249443e-05
9.59362942424773e-05,29.4603296637728,0.00030459773421986545,5.939202460216596,29.463155978627906,9.593169265056551e-05
0.0001934315250158,37.9612407400295,0.0006141450919251649,7.652986133189947,37.96858364071734,0.00019341281955050755
0.0003075117285145,46.9776385139939,0.0009763497380335373,9.470691924421171,46.99208468881487,0.0003074644564738117
0.0004338508847149,56.273220147163,0.0013774765589698074,11.344681181668061,56.2976343335096,0.0004337567986316342
0.0005752897433878,65.7133576203187,0.0018265449352562648,13.247812896256251,65.75116184096125,0.0005751243276815611
0.0007247695005626,75.1965971700138,0.002301143164286255,15.159633989474782,75.25109737018872,0.0007245069819840583
0.0008749644177404,84.7190519083096,0.00277801202632577,17.079360864715216,84.79317806423407,0.0008745818595078511
0.0010309119996643,94.2409379687579,0.003273145598934152,18.998973094501594,94.33809208256952,0.0010303809748173813
0.0011851125721935,103.720957024659,0.003762732416714362,20.910144936171257,103.84387803482888,0.0011844108806234573
0.0013407699764988,113.062167344389,0.004256944675383689,22.793332936628822,113.21375770384225,0.0013398719470449584
0.0014973861008147,122.252313583437,0.004754200870086672,24.6460664184209,122.43537249858929,0.0014962661361209255
0.001652496437378,131.296817936558,0.00524667618867515,26.469438496010095,131.51378546043725,0.0016511325674603667
0.0018065887820962,140.222466104685,0.005735919383155434,28.268849166704495,140.47579043894757,0.0018049588633490623
0.0019624603961844,148.973977710484,0.00623081175788547,30.033153906433576,149.26633324180287,0.001960537286387851
0.0021151156284045,157.543106150142,0.006715492120184288,31.760690199868627,157.87632803610754,0.0021128819204895427
0.0022719032186962,165.949755670275,0.0072132927193604346,33.45547074312744,166.32677745432414,0.0022693263487733157
0.0024272610418818,174.178167295733,0.007706553807974715,35.11431852681977,174.60094317555632,0.0024243200019521656
0.002580131642754,182.267592593796,0.00819191796574395,36.74514666690927,182.73786697689584,0.002576808817431042
0.0027299972984056,190.196946054668,0.00866774142243778,38.343704324621065,190.71618320356222,0.002726277624043716
0.0028824921341948,197.823708886257,0.00915191252606849,39.88125971146942,198.39393417107888,0.0028783457198364097
0.0030345059676779,205.184568354345,0.009634556447377332,41.365208980235955,205.80720215149168,0.0030299111474368827
0.0031907315986566,212.184808643819,0.010130572825734704,42.776457422593914,212.86183341751374,0.0031856520167760573
0.0033483875182009,218.795984173676,0.010631130370287857,44.109270409413085,219.52859791611564,0.003342794151077664
0.0035144545401118,225.076079981184,0.011158393164854964,45.375337724206695,225.86709963234443,0.003508293276189295
0.0036858693282509,230.909000596082,0.011702635117196608,46.55125452017013,231.76010099899617,0.0036790931575139954
0.0038742993226581,236.255129857634,0.012300900349439467,47.62903417929902,237.17045294721592,0.0038668135535479876
0.0040870019821321,241.153845772759,0.012976231293269417,48.616615307788216,242.13944201843108,0.004078672875868003
0.0043321864536447,245.53219542297,0.013754691990321921,49.49929059727076,246.59588667391506,0.004322829548082954
0.0046266795516021,249.42987071574,0.014689707576336666,50.28506193629319,250.5839027981393,0.004616009368785184
0.0049682482840703,252.80000945838,0.015774188301923203,50.964481906809404,254.05598267158456,0.004955947264752375
0.005357969452536,255.4674444173,0.017011553011801798,51.50223679452768,256.83623118060535,0.005343666600957121
0.0057939590558628,257.590240196498,0.01839582000236439,51.93019242361399,259.0827075013864,0.005777238628983974
0.0064762482570627,259.496363958489,0.02056208821617407,52.31446697403138,261.17692683328926,0.006455367465624858
0.0071988211447926,260.925454426004,0.022856257134716503,52.60257161228241,262.80381010454056,0.00717303331919055
0.0079532913577654,262.016237977046,0.025251700060905144,52.82247357617247,264.10012945814304,0.00792183063681657
0.008726944220942,262.822097635185,0.027708047901490847,52.9849348832533,265.1157314212782,0.008689084549936091
0.0095159185995965,263.463298594947,0.030213041553718883,53.11420099674131,265.9703938983577,0.009470927442463204
0.0103126180587341,264.10248936377,0.03274256233648076,53.24306185573603,266.82607746493943,0.01025980579128883
0.0111231983874385,264.689554640897,0.03531615488011724,53.36141421560483,267.6337490682504,0.011061790564246088
0.0117303878932297,264.934703477319,0.037243981561004294,53.4108362210275,268.04249031548574,0.01166212024519292
0.0123272203004733,265.198227343015,0.03913892445400273,53.46396263235182,268.46738431476734,0.012251858819950202
0.0129109434409986,265.530057842228,0.040992245425170555,53.530859660993166,268.95830140091414,0.012828307720765696
0.0134782966364786,265.843189668454,0.04279359182081955,53.593987037160325,269.4263030375931,0.01338827240976417
0.0140330515288717,266.168927624563,0.04455493860416764,53.65965580911191,269.90408990130305,0.013935499833905593
0.0145786610561618,266.465863725862,0.046287248853313714,53.71951812713378,270.35057923615875,0.014473414050866133
0.0151082478414928,266.733370629929,0.04796868689673964,53.77344751899369,270.76324450100276,0.014995254926941561
0.0156344500195743,267.05616844533,0.0496393788121484,53.83852355857853,271.2314447633075,0.01551349112733508
0.0161597434391676,267.468808645564,0.051307185419357124,53.92171182294571,271.7910359712562,0.016030564591752203
0.0166872150906601,267.824857602285,0.052981907912845815,53.99349129262067,272.29410860771975,0.016549513311543317
0.0172116846841215,268.151433912976,0.05464709887208576,54.05932907685597,272.7667718410812,0.01706524160575123
0.0177382356172791,268.44713808983,0.056318898084861145,54.11894303890973,273.2089166760516,0.017582749127342773
0.0182651654034531,268.82015804859,0.05799190015596359,54.19414386259574,273.7302026991299,0.018100361030814627
0.0187979675555056,269.174985266896,0.059683546988730275,54.26567702980623,274.23492790669684,0.018623469181545695
0.0193279121049683,269.470697288891,0.06136612093327435,54.32529257344043,274.67900324095524,0.019143500418766213
0.01985853691201,269.695690723456,0.06305085469563174,54.37065124984873,275.05145255269775,0.019663928375978083
0.020387773336802,269.955974355969,0.06473118034434634,54.42312443016334,275.459775572054,0.020182724987940073
0.0209179535704395,270.30421361682,0.06641450258614541,54.49332946515091,275.9584246071508,0.020702177060768306
0.0214560611582902,270.601658782383,0.06812299417757138,54.553294410528416,276.40770452275257,0.021229120310556324
0.021990346945464,270.829953487227,0.0698193515518482,54.59931862302496,276.785598127635,0.021752046478064554
0.0225178127898884,271.099542121697,0.07149405560789567,54.65366769173412,277.20411085861787,0.022268029604485762
0.0230483724229861,271.367104716777,0.07317858244298085,54.70760831090225,277.6216748096368,0.022786770722549397
0.0235747427123949,271.67519067778,0.07484980811185381,54.769718440640446,278.0798633993495,0.023301150040482346
0.0240992221043304,271.938756268239,0.07651503018124901,54.82285326367698,278.49226875432265,0.02381341850940517
0.0246240464274633,272.149034874844,0.07818134740719597,54.86524543076855,278.8504453447915,0.02432576133547117
0.0251377286585845,272.420343319303,0.07981228849100579,54.91994121317149,279.2683719907421,0.024826972986618498
0.0256556396826065,272.764030563417,0.08145665599227564,54.989228561584866,279.76196624992747,0.025332056573319512
0.0261684225693964,273.087695440922,0.08308474165783356,55.054479400889875,280.2339696537227,0.02583188782776232
0.0266790972650724,273.380467322209,0.08470613381660487,55.11350221215733,280.67401140026914,0.026329415969795298
0.0271894300088204,273.700615852354,0.08632644027800476,55.17804415583457,281.14237959044266,0.026826363800168857
0.0276976489699862,273.969982655962,0.08794003547970618,55.23234850344193,281.55830706388,0.0273210079844913
0.0282023424893507,274.26369859562,0.08954243740368847,55.291561636876985,281.99857735580974,0.02781197887957295
0.0287098342962603,274.520808172515,0.09115372389062645,55.34339492757902,282.4022550860234,0.028305429035524975
0.0292158244183625,274.7482913481,0.09276024252830092,55.389255535776954,282.7752891873712,0.028797176762325242
0.0297291694230546,275.009195869775,0.09439011291819835,55.441853887346646,283.18499084668554,0.0292958253584408
0.0302445117795131,275.302617205395,0.0960263248999541,55.50100762860763,283.62901045439435,0.029796164146175762
0.0307612210604137,275.479915122438,0.0976668768668135,55.5367508886835,283.95401368922336,0.030297578852106183
0.0312819385435454,275.746242661343,0.09932015487575663,55.59044252052675,284.3721196778887,0.030802628896063732
0.0318028898339358,275.986294797292,0.10097417522274617,55.63883703113407,284.76345652640634,0.03130765059395705
0.0323209534367564,276.257142355513,0.10261902716170157,55.69343989887142,285.1860365901569,0.03180962010066831
0.0328348500018428,276.4889672158,0.1042506487558509,55.74017579070528,285.5674409814952,0.0323073032050984
0.0333499531085629,276.7104736432,0.10588610111968721,55.78483148646911,285.9387549638489,0.032805906347098186
0.0338605583200256,276.939609027698,0.10750727266608127,55.83102517998392,286.31693881030543,0.03329991043523905
0.0343726704471977,277.211582158086,0.10913322866985269,55.885854963070145,286.74008451575213,0.033795127445114835
0.0348804174252413,277.465669220288,0.11074532532514111,55.937078914810066,287.1437875838656,0.03428588132264673
0.0353923830574017,277.736737960882,0.1123708162072504,55.99172637291382,287.5665029799067,0.03478046893687547
0.0359038430999467,277.999062990915,0.11399470184233076,56.04461109896846,287.980297730473,0.03527432398907056
0.0364208319017166,278.248553796741,0.11563614128795019,56.09490844542299,288.38259760146786,0.03577326975633511
0.0369361461498801,278.471492943081,0.11727226402586931,56.13985297732513,288.75715670500193,0.03627035179693824
0.0374578383980727,278.724918166382,0.11892863691388082,56.190943502342606,289.1653511085743,0.036773334608378346
0.0379766363723372,279.011606282898,0.1205758204821706,56.24873982663224,289.6075285983654,0.037273276178567245
0.0384976711072234,279.27935070811,0.12223010576543429,56.30271710275497,290.03095529870967,0.037775121777084364
0.0390169392572132,279.492680521114,0.1238787821416519,56.34572439305658,290.397629459842,0.038275015407880364
0.0395408203144069,279.730221721507,0.1255421044982419,56.393612699055815,290.79098415510634,0.038779096726645125
0.0400548328672634,279.944730124648,0.12717409435356128,56.436857593129034,291.15786950186197,0.03927343567425497
0.0405714381659655,280.156251806553,0.12881431617694045,56.47950036420108,291.5225938535312,0.039770022030498196
0.0410793045594948,280.37807510807,0.13042679197639598,56.52421994178692,291.89581144723934,0.040257967864236854
0.041587619142983,280.582160608246,0.13204069077897101,56.565363578622396,292.250904641937,0.04074610601805919
0.0420974321195154,280.779251389878,0.13365934697946139,56.605097080199414,292.59933686583173,0.04123544387302578
0.0426060108345931,281.027754672719,0.1352740843998331,56.655195342020164,293.00122623312626,0.041723358570807945
0.0431135946424079,281.192597368132,0.13688566298964508,56.68842762941541,293.31582102750747,0.04221008153826956
0.0436275559620088,281.443536282662,0.13851749017937792,56.73901691458467,293.72222991197947,0.04270267864821272
0.0441405388720433,281.698464989344,0.14014621091873747,56.790410541851756,294.1327870334011,0.04319409617837545
0.0446585225822661,281.902109358486,0.14179080919869486,56.83146524667077,294.49144107526035,0.043690059366409295
0.0451807080747205,282.082344743196,0.14344874813723757,56.867800700228315,294.827024814071,0.044189796854022356
0.045705633877707,282.278376146042,0.1451153875617197,56.90732063104207,295.18008825776667,0.04469190526946583
0.0462327016463558,282.477505826136,0.14678882772717966,56.947465174549016,295.53720407480245,0.04519580901352079
0.0467590285801946,282.739728268291,0.14845991574211787,57.000329218887465,295.9603633031445,0.045698751225219374
0.0472852482169835,282.916857846948,0.15013066308892262,57.03603854194472,296.29465169501,0.046201338160649676
0.0478066108294611,283.095376869734,0.151785989383539,57.07202797693838,296.629207379365,0.04669903721951277
0.0483358154254775,283.281810058466,0.15346621397589105,57.109612907786754,296.9744673428472,0.04720396913695479
0.0488636237581454,283.512791708409,0.15514200543211165,57.156178808415255,297.36625409307015,0.04770731501236375
0.0493892732230159,283.724976636912,0.15681094248307548,57.19895529000146,297.73794702822624,0.04820835039911159
0.049917286692282,283.895297075742,0.15848738524799535,57.233291890469594,298.06658001046236,0.04871138648777278
0.0504446647812789,284.098207259862,0.1601618106805605,57.27419858358819,298.42944609004803,0.049213564790621896
0.0509676829723058,284.295673596003,0.1618223934370709,57.3140077969542,298.7855653582422,0.04971134258505205
0.0514988902264381,284.476068208611,0.16350897646894097,57.350375350855984,299.126270017335,0.050216660740600806
0.0520249859550889,284.700445435793,0.16517933040740726,57.39560979985587,299.5119821109977,0.05071686494134903
0.0525536094825595,284.863302582868,0.1668577101071264,57.428441800706196,299.83389734272026,0.05121922065259079
0.0530883837065445,285.010946498255,0.16855561826827878,57.45820681404821,300.14171698651984,0.05172716477339832
0.0536222976005867,285.22794184284,0.17025079488186276,57.50195307551654,300.5225194243396,0.05223403447336281
0.054158320465033,285.344857335991,0.17195266747647978,57.52552323893578,300.79865556264275,0.052742648008763444
0.0546992779169609,285.503578796592,0.17367020738635086,57.557521485392954,301.12041839947375,0.05325568166661491
0.0552381973752969,285.681927614607,0.17538127666656764,57.59347660710477,301.46248231873795,0.053766520946324815
0.0557813587498527,285.851595309206,0.1771058140307823,57.627681614335934,301.79678569636656,0.05428111720855848
0.0563236286909795,286.007979803425,0.1788275210938599,57.65920872837048,302.1169870605302,0.054794604896212365
0.0568656426329471,286.204142976176,0.18054841535960703,57.69875522399709,302.4793254907281,0.05530758682472081
0.0574120135322221,286.404492813003,0.18228314296480516,57.739145751101404,302.8475514300723,0.05582442614319363
0.0579620625008319,286.625903216505,0.18402954844014127,57.78378208844741,303.23933173309746,0.05634447504351688
0.0585156692852725,286.846790447142,0.18578724998074017,57.828312954143826,303.6318223724888,0.056867614775867395
0.0590947574686985,287.031496597599,0.18762585496311773,57.86554971407596,303.9935532749117,0.05741454086816927
0.059674127276828,287.133850670101,0.1894653541039289,57.88618429509237,304.2683126204744,0.057961433761246225
0.0602502262346296,287.293444333273,0.19129446829494895,57.918358377587836,304.60293935007866,0.058504942751111004
0.0608160275224548,287.416374550788,0.19309088738379399,57.94314110943887,304.8958966958729,0.05903844923658095
0.0613899231093383,287.519773244985,0.1949130058721491,57.96398628618898,305.170590016909,0.059579297405159624
0.0619632127802315,287.665206333107,0.196733200577235,57.993305596754375,305.48986672259446,0.06011928265314637
0.0625374232887796,287.760563804864,0.19855631894187523,58.012529663060576,305.75636798934664,0.060659843115009056
0.0630919936951412,287.919672113182,0.20031707998207327,58.044605898017494,306.085098250854,0.06118163719116672
0.0636452018241456,288.107164206196,0.20207351579166227,58.08240430396911,306.44380281908155,0.061701878378133304
0.0642079881076137,288.243782661147,0.2038603622416735,58.10994658448723,306.7513360303475,0.06223084936095651
0.0647828985383555,288.406777683418,0.2056857028592787,58.14280638097707,307.0906046998569,0.06277092724322667
0.0653495450471002,288.596719058034,0.2074848055245431,58.18109856209966,307.4563833505623,0.06330295662366939
0.065918032861828,288.688955333976,0.2092897543363039,58.19969339532957,307.71876337852785,0.06383643053759998
0.0664915948222527,288.809713601963,0.2111108135606523,58.22403826215574,308.01313205951556,0.06437437781265452
0.0670642590544649,288.95922621104,0.21292902249792606,58.25418000414567,308.33806261383495,0.06491119454976874
0.0676424403016554,289.089120541558,0.21476474795775585,58.28036670117809,308.64381411964837,0.06545289075703031
0.0682161739602399,289.256112109762,0.2165863523237617,58.31403220132802,308.98805737250416,0.06599013013097857
0.0687958349176548,289.375663080088,0.21842677586355397,58.33813367694574,309.2835034265326,0.06653262682189384
0.0693822252786004,289.464138781193,0.22028856525955626,58.35597037828851,309.54780486818584,0.06708112218489752
0.069971246720878,289.587333013022,0.22215870833878762,58.380806335425234,309.8501197385172,0.06763177588927159
0.0705582468216925,289.71023876192,0.22402243365887367,58.40558413440307,310.151685295255,0.06818023842370534
0.071150264717438,289.797354185109,0.22590209047786564,58.42314660371797,310.41651264979265,0.06873308481492472
0.0717434584545798,289.941280958639,0.22778548059329085,58.45216224126163,310.74267120336276,0.06928672286601346
0.0723401404901223,290.07603245975,0.22967994605613828,58.4793281438856,311.0601734007056,0.06984330755444622
0.0729390197277587,290.217639538862,0.23158138763563385,58.507876131034585,311.3858296745306,0.07040163046579416
0.0735405166833949,290.309650235356,0.23349114046977879,58.52642548744777,311.65917191183974,0.07096208022660234
0.0741473905743345,290.438429511891,0.23541796507351204,58.55238738959723,311.97368118270555,0.07152722184242195
0.0747608804237143,290.591189250283,0.2373657953452929,58.58318375285705,312.31604240200835,0.07209820002173908
0.0753744303431505,290.730727616234,0.23931381633950283,58.61131468743278,312.64439059355726,0.0726689082306755
0.0759928196019349,290.800950646963,0.24127720223614327,58.625471650427734,312.8997348295488,0.07324378848492398
0.076620519410153,290.850139129682,0.2432701491272358,58.635388048543895,313.13522786031353,0.07382698641892671
0.0772477951969977,290.919893713735,0.2452617497504677,58.64945057268898,313.3928140820659,0.07440945081596059
0.0778769630734015,291.043852862663,0.24725935775804975,58.67444073711287,313.7094642447891,0.07499333153271623
0.078509704820152,291.153033963812,0.2492683128039826,58.696451647104496,314.01137271780254,0.07558018524901013
0.0791450850589889,291.218135667284,0.25128564506228973,58.709576150524455,314.2666197853914,0.07616913975663892
0.0797907179360603,291.29183078992,0.25333552944699145,58.72443308724788,314.5342150975572,0.0767672426695856
0.0804450331418105,291.408716136217,0.25541298022524833,58.74799717306134,314.8510999636074,0.0773730239834382
0.0811036344265917,291.493102430856,0.2575040393044286,58.76500945006058,315.1342524482812,0.07798240309670386
0.0817680195592527,291.570199687615,0.2596134621006273,58.78055225702318,315.4113174785671,0.07859675776942186
0.0824402820762478,291.62091597998,0.2617478955920868,58.79077666156397,315.6622265527033,0.07921801269955875
0.0831143751302752,291.652663463934,0.26388814103862374,58.797176954329096,315.8931923428193,0.07984057198113244
0.0838008974727242,291.705079336579,0.26606784947589934,58.807743994254324,316.1502267823365,0.08047421222918352
0.0844883609202675,291.719237270221,0.26825054592184927,58.81059823367656,316.3661174760926,0.08110831901905721
0.0851703045042498,291.736766131405,0.2704157168009931,58.814132052091246,316.5840753379018,0.08173693735179874
0.0858587386328404,291.77257855321,0.27260149515926824,58.82135183632714,316.82380411543994,0.08237113812754746
0.0865508243078121,291.821443265679,0.2747988671773034,58.8312029623609,317.07882973101897,0.08300829763024163
0.0872457552406822,291.794039158827,0.277005272889166,58.825678294419525,317.2518304799681,0.08364766836353088
0.0879475042940489,291.77309185638,0.27923332613360524,58.82145531824621,317.4338071053069,0.08429289753996082
0.0886418187497487,291.731925141416,0.2814377745304521,58.81315610850947,317.5915735733166,0.0849308814461567
0.0893370196141097,291.673892068475,0.2836450372747983,58.80145664100457,317.7311682851201,0.08556927230260196
0.0900427040966926,291.562551275832,0.285885585506999,58.77901033720773,317.81563180603854,0.08621687354397203
0.0907390307476574,291.449038090789,0.28809642262381224,58.75612607910306,317.89484131948427,0.08685547635644354
0.0914368777838889,291.203067238557,0.29031208696384725,58.7065383552931,317.82976650794257,0.08749506462913266
0.0921392727351008,291.027361758675,0.292542190933945,58.67111613054888,317.8424112171344,0.08813840832499692
0.0928335264672298,290.796186843043,0.2947464465334546,58.62451126755747,317.79182235090616,0.08877388878108881
0.0935323763581972,290.46793009042,0.2969652949372761,58.55833470622867,317.6360858476237,0.08941316870570233
0.0942231179006297,290.085504708731,0.2991583993344993,58.48123774928016,317.41826542016537,0.09004463009816367
0.0949133418104583,289.627071247952,0.3013498602482051,58.388817563587125,317.1165444588708,0.09067522023761215
0.0956126440535964,289.11082119901,0.30357014487016853,58.284741553720416,316.7534712383539,0.09131369909739946
0.0963181874802437,288.531525300686,0.30581024524977374,58.16795550061829,316.3223588485581,0.0919574634360033
0.0970394533147598,287.845952363761,0.3081002642743623,58.029743996534215,315.7783662200068,0.09261514538180132
0.0977920544329097,287.066280720664,0.31048977282448825,57.872562193285866,315.13908207075207,0.09330093938921344
0.0985802302248177,286.181822378571,0.3129922309637962,57.69425539151991,314.3936923148084,0.09401864633830075
0.0994110250614474,285.195658627469,0.3156300045700955,57.49544477929775,313.54725139470037,0.09477460464723066
0.100261039952657,284.08276047705,0.318328801849686,57.271084512173275,312.56519347510056,0.0955474606988566
0.101153925037355,282.820662669099,0.3211637119936021,57.01664559409036,311.42908277974414,0.09635865272567598
0.102075433966462,281.491896612646,0.32408950284351684,56.748766357109425,310.2253041174243,0.09719516026319243
0.103015906307987,279.749201174635,0.3270755025278587,56.39743895680642,308.5678186725754,0.09804816111750869
0.103486897593876,278.960666240565,0.32857089986055626,56.2384703140979,307.8294401405218,0.09847507314518396
0.103954947356263,278.155939302739,0.330056957856135,56.076237363432185,307.07162532978714,0.09889913846810236
0.104425239692352,277.249994591806,0.3315501360232176,55.89359890970809,306.2018917317586,0.09932505457254523