File: example/data/02 processed data/test_ID_064.csv
Strain,Stress_MPa,Displacement(mm),Force(kN),True Stress (MPa),True Strain
0.002002363297588115,79.088294760099,0.0063575034698422645,31.88840044727192,79.24665825879545,0.0020003612403188273
0.002093281243545015,83.2503219785185,0.006646167948255423,33.56652982173866,83.42458831603521,0.0020910933830356354
0.002190996111589715,87.0602172333362,0.006956412654297345,35.10267958848116,87.2509658307686,0.002188599379790883
0.002286344047697915,90.9224609608043,0.00725914235144088,36.6599362593963,91.13034098822408,0.002283734340181545
0.002379961523265515,94.7292371111026,0.00755637783636801,38.194828403196574,94.95468905055533,0.0023771339003732634
0.0024805207809990154,98.3893066494505,0.007875653479671873,39.67056844105844,98.63336336922255,0.002477449367414838
0.002562744499290815,102.132606198088,0.008136713785248337,41.17986681906908,102.39434597282039,0.002559466269256011
0.0026514783691334153,105.724593336783,0.008418443821998594,42.62815603339091,106.00491980910091,0.002647969401628099
0.002736233004705215,109.316822667595,0.008687539789939058,44.07654289957431,109.61593896574757,0.0027324963338931636
0.0028177245947826153,112.924306468596,0.008946275588434803,45.53108036813791,113.24249606428134,0.002813762250288572
0.002907465391735715,116.593603242815,0.009231202618760896,47.01054082750301,116.93259510914127,0.0029032468890227603
0.0029914695830030153,120.090430694206,0.009497915926034573,48.420461655903864,120.44967756483747,0.002987004041341577
0.0030744509719970153,123.541956696376,0.009761381836090523,49.81211693997881,123.9217803852236,0.0030697345121511875
0.003162118530961015,127.013182763162,0.010039726335801222,51.21171529010692,127.41481350205373,0.0031571295485614275
0.0032662311606804152,130.273883690715,0.010370283935160318,52.52642990409629,130.69938830904846,0.003260908614311645
0.0033510147260039152,133.656676047174,0.01063947175506243,53.890371782220555,134.1045615368368,0.003345412587899768
0.003449752476864115,137.013625435041,0.010952964114043564,55.24389377540854,137.48628852874967,0.0034438157304076625
0.0035248843436336153,140.323036558272,0.011191507791036727,56.578248340295275,140.81765903288738,0.0035186864990023785
0.003596487833065415,143.658194315889,0.011418848869982692,57.92298394816645,144.17485926386624,0.003590035935518655
0.003681393028203115,146.975753803603,0.01168842286454489,59.260623933612735,147.51682931897048,0.003674633285988052
0.003759579385385015,150.304405197543,0.011936664548597422,60.60273617564933,150.86948654085623,0.003752529830191253
0.003845588762912615,153.511919382678,0.012209744322247551,61.89600589509577,154.10226309482917,0.0038382133888358078
0.003928235581522515,156.833764214471,0.012472147971333983,63.235373731274706,157.44984418744238,0.0039205402103676965
0.0040250066487470156,160.181994873236,0.012779396109771773,64.58538033288876,160.82672846761034,0.00401692798002716
0.004110547720919315,163.760872934777,0.013050989013918823,66.02838396730209,164.43401981779482,0.004102122499926869
0.004195157355671615,167.163738530056,0.013319624604257377,67.40041937531858,167.86501671735192,0.004186382216551077
0.004280559969076115,170.34364125452,0.013590777901816665,68.68255615382247,171.07280742626077,0.004271424433112929
0.004362429817116515,173.583550241421,0.013850714669344935,69.98888745734095,174.34079629675512,0.004352942003434905
0.004463004963992015,176.605988514405,0.014170040760674647,71.20753456900809,177.3941819178155,0.004453075290497196
0.004560183256577815,179.851963266189,0.014478581839634562,72.51631158892741,180.67212117773812,0.004549817123275825
0.004667681249676816,183.068087917493,0.01481988796772389,73.81305304833317,183.92259139887966,0.004656821405966326
0.004772634321562015,186.272769116005,0.015153113970959397,75.10518050757322,187.16178092706045,0.004761281410244356
0.004877734687727415,189.420860673057,0.01548680763353454,76.37449102337659,190.34480537574115,0.004865877083085728
0.004983876306756915,192.561291072212,0.015823807273953203,77.64071256031588,193.5209927283853,0.004971497906477353
0.005088142212457715,195.515836386184,0.016154851524553242,78.83198523090938,196.51064876650452,0.005075241359282812
0.005211639946260515,198.3405387669,0.016546956829377134,79.97090523081408,199.37421824170042,0.0051981063519113795
0.0053594660179953155,200.951253746388,0.017016304607135126,81.02354551054364,202.02824516211535,0.005345155189490682
0.005517309380881015,203.427439082003,0.01751745728429722,82.02194343786361,204.5498111999787,0.005502144782429177
0.005703188119294815,205.687989620369,0.018107622278761035,82.93339741493278,206.8610669190535,0.00568698651328284
0.005921228132075915,207.557054455393,0.018799899319341028,83.68700435641446,208.7860471252451,0.005903766556190976
0.006172894046604415,209.027613040738,0.019598938597969014,84.27993357802556,210.31791834885308,0.006153919780204447
0.006457881538166115,210.020706333349,0.020503773883677415,84.68034879360631,211.37699517541176,0.006437118762276764
0.0067656391223748155,210.747665994663,0.02148090421354004,84.97345892904812,212.17350864866566,0.006742854894849715
0.007083433526634615,211.162015666132,0.022489901447064902,85.14052471658442,212.6577677674532,0.007058463856031435
0.007431393742216315,211.305875507154,0.023594675131536798,85.1985290044845,212.8761726680914,0.007403916978869905
0.007789996527731315,211.305814273028,0.024733238975546922,85.19850431488489,212.95188583250433,0.007759811166011252
0.008160694981818914,211.199774558618,0.02591020656727505,85.15574910203479,212.9233114990198,0.008127576568039217
0.008541804772757315,211.0915382746,0.02712023015350447,85.11210823231872,212.89464098372264,0.008505529980127952
0.008928466987843515,210.939150252228,0.028347882686403158,85.05066538169832,212.82251349169877,0.008888843900767022
0.009320461835864114,210.736571016595,0.029592466328868562,84.9689854338911,212.70073318417607,0.009277294351404205
0.009722922859217316,210.524072476283,0.030870280078014976,84.88330602243732,212.5709817929782,0.009675959414011795
0.010117776707154615,210.297127843565,0.0321239410452159,84.79180194652541,212.4248672252421,0.01006693465582354
0.010523032405077215,210.102259741732,0.033410627886120155,84.71323112786635,212.31317262937418,0.01046805067954104
0.010929927583978915,209.871614350466,0.034702520079133055,84.6202349061079,212.16549589724934,0.010870627630329347
0.011325918878320814,209.586040498067,0.035959792438668585,84.50509152882061,211.95979499077657,0.011262260865160564
0.011721945221915015,209.294461974572,0.03721717607958017,84.38752706814743,211.7478001930881,0.011653775426610734
0.012119756254924915,208.952448205712,0.0384802261093866,84.24962711654307,211.48490094683504,0.012046900084377128
0.012510712404408516,208.644299247468,0.039721511883997036,84.1253814565791,211.25458807017245,0.012433100095090053
0.012914974306863615,208.455343474358,0.041005043424291975,84.04919448886115,211.14753887945778,0.012832287199781916
0.013335882759893515,208.287971007607,0.04234142776266191,83.98170991026714,211.06567496926056,0.013247742628329664
0.013773866610336815,208.22672036856,0.04373202648781938,83.95701365260338,211.09480743962445,0.013679869065879422
0.014196193247595615,208.101037987757,0.045072913561116076,83.90633851666362,211.05528053805642,0.014096370918370797
0.014608926755702516,207.907743043169,0.046383342449355484,83.82840199500575,210.9450520332301,0.014503244412262802
0.015025890558420915,207.686152911412,0.0477072025229864,83.73905685388132,210.80682231555832,0.01491412010775959
0.015442645621764716,207.460777412916,0.04903039984910297,83.64818545288774,210.66452067891947,0.015324621488864635
0.015862598448997116,207.210466760848,0.05036375007556584,83.54726019797393,210.49736318950457,0.015738102263791357
0.016283520562650314,206.953755980932,0.051700177786414746,83.44375441151179,210.32369172196522,0.016152365899398138
0.016699174000576217,206.735206832235,0.053019877451829484,83.35563539475716,210.18751402317162,0.01656127586683573
0.017122357001209315,206.560209212069,0.05436348347883957,83.28507635430623,210.09700685644253,0.016977421531821236
0.017547547228738615,206.435657830407,0.0557134624512451,83.2348572372201,210.05809728588176,0.017395366705959335
0.017971247513488012,206.337092312557,0.057058710855324435,83.19511562042298,210.0452272697194,0.01781167363661834
0.018403999193718816,206.20293726186,0.05843269744005724,83.14102430398196,209.9978959529697,0.018236695191407856
0.018836532871259318,206.074372557848,0.05980599186624833,83.08918701532431,209.95609925045807,0.01866132220744438
0.019277113894333016,205.894388387235,0.06120483661450732,83.01661739773316,209.86343796237978,0.01909366417290406
0.019716412288024718,205.698150025648,0.06259960901447847,82.93749409034127,209.75377955843763,0.01952456147085797
0.020143641193426917,205.48374257734,0.06395606078913046,82.8510450071835,209.6229333589004,0.019943442080750613
0.020577402389731513,205.215134912711,0.06533325258739754,82.74274239680508,209.4379293202729,0.020368547907145616
0.021015848100225214,204.977049037181,0.06672531771821505,82.64674617179138,209.28481556377878,0.020798061197443547
0.021455688365001113,204.804037651222,0.06812181055887853,82.5769879809727,209.19824925896054,0.02122875534786108
0.02188722264115151,204.671817502228,0.06949193188565604,82.52367681689833,209.1515151402684,0.021651136026348064
0.022321587465014017,204.581895227255,0.0708710402014195,82.48742015562921,209.1484878953285,0.02207610712348089
0.022764146945806314,204.437411194214,0.07227616655293505,82.42916419350709,209.09125446385934,0.022508909993555388
0.023200030332532512,204.284551308871,0.07366009630579072,82.3675310877368,209.0239590957046,0.022935000927269286
0.023641090315303016,204.072236330599,0.07506046175108708,82.28192568849752,208.89672650053654,0.023365967439665156
0.024072981700524312,203.813322962135,0.07643171689916468,82.17753181833282,208.71971735612553,0.023787795269563573
0.024501555569373216,203.614699978085,0.07779243893275996,82.09744703116388,208.60357686433935,0.024206207064989493
0.024946178414107817,203.427689632024,0.07920411646479232,82.02204445963207,208.50243307195421,0.024640102347447797
0.02539467119387462,203.355815846694,0.08062808104055191,81.993064949387,208.5199699254829,0.02507758354673776
0.025827001947662215,203.230195775942,0.08200073118382753,81.94241493685982,208.47902243807104,0.02549911844552551
0.026271557590816515,203.078146279894,0.08341219535084243,81.88110858005327,208.4133254953225,0.025932387742501832
0.026716774996468913,202.946584799277,0.0848257606137888,81.82806299106848,208.36866304166108,0.026366113941102075
0.027168535015286814,202.807892310762,0.08626009867353562,81.77214217969924,208.31788563438346,0.0268060216846368
0.027626383397388612,202.655196199809,0.08771376728670884,81.710575107763,208.25382634749795,0.027251660697636394
0.02808333527157242,202.493495569312,0.08916458948724243,81.6453774135466,208.18018829569763,0.027696229186620937
0.028536236329571918,202.28040391404,0.09060255034639084,81.55945885814093,208.05272532497227,0.028136661701777855
0.02897494034580291,202.125283885997,0.09199543559792424,81.49691446283398,207.98185192897222,0.028563103149924142
0.029428883731020518,201.901740904872,0.09343670584599013,81.4067819328444,207.84348376305215,0.02900416664511116
0.029881829179462714,201.71118878757,0.09487480764479411,81.32995131914822,207.7386880745065,0.0294440667076968
0.030332482933607817,201.556366946487,0.09630563331420482,81.26752715282356,207.67007200705132,0.029881549117835454
0.030801130630385518,201.409467042398,0.09779358975147401,81.20829711149487,207.61310634696721,0.030336296642954407
0.031261223188567215,201.320990045611,0.0992543836237009,81.17262318639037,207.61453044797017,0.03078254169947719
0.03172997955026261,201.188996776304,0.10074268507208378,81.11940350020578,207.57271952975398,0.031236985101019903
0.03219589211519861,201.034009133728,0.10222195746575559,81.05691248271914,207.50647840328335,0.03168846698730895
0.032656959405564415,200.880747741508,0.10368584611266701,80.99511748937603,207.44090216586184,0.03213505309410014
0.03311697923965811,200.719754804112,0.1051464090859145,80.93020513701796,207.36698675694905,0.032580425971637295
0.03359099466214251,200.536497157233,0.10665140805230247,80.85631565379634,207.27271756280635,0.03303914141356904
0.034059839607278514,200.339343402379,0.10813999075310927,80.77682325983922,207.16286930569152,0.033492646372337516
0.03452142841043941,200.168960094041,0.10960553520314513,80.70812470991734,207.07907851991953,0.03393893177379483
0.034985624392507214,200.056011433153,0.1110793574462104,80.66258380984729,207.05509590661643,0.034387537145034376
0.03542805162138071,199.925397218111,0.11248406389788376,80.60992015834235,207.00836451117928,0.034814917663945455
0.035886794920874016,199.653920858647,0.11394057387377499,80.50046089020648,206.8188601716497,0.035257866554848985
0.036339208489576114,199.394542301062,0.11537698695440415,80.39587945578819,206.6403821454239,0.03569451156861249
0.036800898126585914,199.140773706288,0.11684285155191027,80.29355995837533,206.46933303230261,0.03613991286413413
0.03726161327360481,199.053398315636,0.11830562214369526,80.25833020086444,206.47044906447005,0.03658417638277362
0.03771878181392621,199.039588952107,0.1197571322592157,80.25276226548955,206.5471197801251,0.037024824929430884
0.03817905809614791,198.88556435533,0.12121850945526962,80.19065954806905,206.47882787133727,0.03746827284956961
0.03863827767417311,198.676017418396,0.12267653161549963,80.10617022309727,206.35251654660684,0.037910506817478144
0.03911072209764741,198.457148751371,0.12417654266003053,80.01792237655279,206.21895114447733,0.0383652724620949
0.039577177605403316,198.348087061897,0.12565753889715553,79.97394870335687,206.19814453123766,0.038814070490554964
0.04005678373362431,198.264766424477,0.12718028835425718,79.94035382234912,206.2066152951398,0.03927531140663907
0.04053194511814801,198.16509572967,0.12868892575011992,79.90016659820296,206.19711251411755,0.03973206807958992
0.041022167723751515,198.035562740576,0.13024538252291104,79.84793889700025,206.15941081058742,0.040203084049477276
0.04150768463549341,197.88369435845,0.13178689871769156,79.78670556532704,206.09738833838688,0.04066936012229168
0.04200056680235571,197.737258863828,0.1333517995974794,79.72766277389546,206.04233581405293,0.04114248728722277
0.042488889350022416,197.564470490465,0.13490222368632115,79.65799450175548,205.95876541663011,0.04161101693620553
0.04297960646330031,197.431668375582,0.1364602505209785,79.60444868903467,205.91720378575735,0.04208162305978851
0.04347650985129661,197.27741053713,0.13803791877786672,79.54225192857082,205.8543438197858,0.04255793635821388
0.04395886864203481,197.098198552703,0.1395694079384605,79.46999365644986,205.762412372463,0.04302009083187422
0.04444263698328911,196.87070627452,0.14110537242194293,79.37826876988646,205.62015960612223,0.04348338139032674
0.044930863662374414,196.576015772555,0.14265549212803877,79.25944955949419,205.40834593652443,0.043950724053398275
0.045407437536401515,196.316596844419,0.1441686141780748,79.15485184766975,205.2308304529909,0.044406701807823065
0.045875561796409316,196.123632707567,0.14565490870359957,79.077048707691,205.12091453957927,0.04485439278793033
0.046346710821699715,196.015159954102,0.1471508068588966,79.03331249349392,205.09981788916397,0.04530477422151004
0.04682075901100562,195.89258955177,0.14865590985994281,78.98389210727366,205.06442927921526,0.045757722400996674
0.04729087803536331,195.703478065907,0.15014853776227852,78.90764235617371,204.95846737821822,0.04620671377656487
0.047777615420993014,195.428652790732,0.15169392896165282,78.79683280522315,204.76576780601036,0.04667136435568162
0.04826324217669791,195.19502577936,0.15323579391101586,78.70263439423796,204.61577058023607,0.04713473964021772
0.048765059970852516,195.057611831952,0.15482906540745672,78.64722909064304,204.56960797070838,0.04761333862070769
0.04924948351793591,194.919342930153,0.15636711016944652,78.5914790694377,204.51901989711848,0.04807513099216257
0.049739798745412414,194.853444111051,0.1579238610166844,78.56490866557577,204.54541520598517,0.04854232274062742
0.05023560932006811,194.732761129415,0.15949805959121624,78.51624928738012,204.51528003933046,0.04901452882643623
0.050747224386291714,194.645512401561,0.1611224374264762,78.4810706003094,204.52323189518773,0.049501553344797965
0.05124938064387431,194.543985066848,0.16271678354430094,78.44013477895312,204.51424380951508,0.049979343143253196
0.05176115165413001,194.404324277658,0.16434165650186278,78.3838235487517,204.46691598881253,0.0504660463836777
0.05226061377202861,194.214883028797,0.16592744872619083,78.30744083721095,204.36467201954466,0.05094081535754243
0.05277169132730521,193.977534707165,0.16755011996419406,78.21174199392892,204.21405729316317,0.05142639229057169
0.05327561179283671,193.758224817622,0.16915006744225655,78.1233162464652,204.0808127846748,0.05190493849834365
0.053776449579360015,193.579522571818,0.17074022741446804,78.051263500957,203.98954200699794,0.05238033045010149
0.05427415394127661,193.449051579453,0.17232043876355324,77.99865759683544,203.94833518467019,0.05285252440060056
0.054793388416480814,193.239549332359,0.17396900822232658,77.91418629080715,203.82779901635266,0.053344907385276474
0.05528462657366901,193.030248906833,0.1755286893713991,77.82979635923508,203.70185413506965,0.0538105187632191
0.05577484872880331,192.812491295366,0.1770851447139505,77.74199649029157,203.56657883038872,0.054274951120223694
0.056241129432615417,192.625860469904,0.17856558594855393,77.6667469414653,203.4593564206608,0.05471650148367687
0.05674613842342041,192.50442231416,0.1801689894943598,77.6177830770693,203.42830490991992,0.055194506257395276
0.057251712766679515,192.318268606545,0.18177418803420745,77.54272590215894,203.32881888059205,0.05567281738965435
0.057751450146454913,192.111261256359,0.18336085421499435,77.45926053856395,203.2059651833782,0.05614538158987704
0.05825079060450351,191.87883098466,0.18494626016929863,77.36554465301491,203.05592458978435,0.056617347505320055
0.05875324466974921,191.715532762523,0.18654155182645374,77.29970280984928,202.9794423659108,0.05709203160257087
0.05925908457503251,191.543738512019,0.1881475935257282,77.23043536804606,202.89444511232062,0.05756968690978161
0.05977417301897011,191.41251959634,0.1897829993352301,77.17752790124429,202.8540446606886,0.058055841105084154
0.060284882585517514,191.276693791151,0.19140450220901808,77.12276293659208,202.80778681769652,0.05853762917138944
0.060801788515592814,191.093925034914,0.1930456785370072,77.04907057407733,202.7127774515014,0.05902502645444329
0.06129666533400821,190.891090306245,0.19461691243547605,76.96728761147799,202.5920775839908,0.059491429722857564
0.06179898075357011,190.672438929147,0.1962117638925851,76.87912737623208,202.45580131276563,0.059964621243795854
0.062306830713900016,190.467335091741,0.19782418751663253,76.79642950898997,202.3347510958298,0.060442798900732723
0.06282803573431832,190.269613435978,0.19947901345646066,76.71670813738632,202.22387950808854,0.06093331368085081
0.06334244157478432,190.072104594921,0.2011122519999402,76.63707257267215,202.11173577522106,0.06141719383626899
0.06384575015178132,189.835004188076,0.20271025673190568,76.54147368863224,201.95516243553024,0.061890408748185854
0.06434963291796211,189.630762555855,0.2043100845145297,76.45912346252074,201.8334325162775,0.062363939308025196
0.06484153000477572,189.46161032321,0.2058718577651629,76.39092128231827,201.74659101373555,0.0628259899722688
0.06535659676059362,189.240391962278,0.20750719471488474,76.3017260391905,201.60849995057328,0.06330957575650523
0.06586320122827992,189.04340121775,0.20911566389978872,76.2222993709968,201.49440479303308,0.0637849884546287
0.06638383915836271,188.866669581861,0.2107686893278016,76.15104117540635,201.4043641977589,0.06427333518985066
0.06688547468038121,188.678581892537,0.21236138211021033,76.07520421907093,201.29843840444056,0.06474363261363157
0.06738092608351111,188.477894708753,0.21393444031514774,75.99428714656922,201.17770980049931,0.06520791524662664
0.06787330477627342,188.231123972346,0.2154977426646681,75.89478918564991,201.00699241810156,0.06566910501445226
0.06836822183509242,187.952931225665,0.2170691043264184,75.78262187018814,200.80293892225714,0.06613245811522163
0.06888005147563481,187.767672188081,0.2186941634351405,75.70792542623427,200.70111911385618,0.06661141945697928
0.06939555279620371,187.563742511532,0.22033088012794677,75.62570098064971,200.57983210764462,0.06709358492669341
0.06992465565078361,187.401504760918,0.22201078169123795,75.56028671960213,200.50549044976384,0.06758823071490107
0.07043791983725121,187.264267265093,0.22364039548327258,75.5049525612855,200.4547727110932,0.06806783562126979
0.07096476389080561,187.11525907956,0.2253131253533078,75.44487246087859,200.39384926050786,0.06855989072906211
0.07148555266588201,186.945891085112,0.22696662971417536,75.37658328551717,200.309821427947,0.06904605256096957
0.0720004130624518,186.730563581197,0.22860131147328447,75.28976323593864,200.1752412904276,0.06952644796798738
0.07249860693519221,186.432154700476,0.23018307701923524,75.16944477523192,199.94822620418677,0.0699910729242658
0.07299569091144381,186.169936638349,0.2317613186438341,75.06371845258232,199.75953979020497,0.07045444771453649
0.07350467670165191,185.919682448916,0.2333773485277448,74.96281596340293,199.58564859979734,0.07092869482618618
0.07402255445772002,185.705598822633,0.23502161040326106,74.87649744528562,199.45200162458485,0.07141099629234957
0.07455378468339702,185.53365656237,0.2367082663697855,74.80717032594758,199.36589284524428,0.07190549139296519
0.07508565766683692,185.33719520378,0.2383969630922072,74.7279571061641,199.25336039578275,0.07240033995576589
0.07559842674742191,185.10378038339,0.24002500492306456,74.63384425058284,199.09733496537456,0.07287718273710893
0.07609496939136282,184.783682428274,0.24160152781757693,74.50478075508009,198.84479108667682,0.0733387193609107
0.07657966980590131,184.367011676247,0.24314045163373663,74.33677910786278,198.48577655351474,0.07378904326393244
0.07706099969410361,184.032298287598,0.24466867402877895,74.20182266955952,198.21401116964378,0.0742360350978378
0.07754281787689872,183.701178782349,0.24619844675915342,74.06831528504311,197.94588583244027,0.07468328037504114
0.07802648122932332,183.498784668067,0.24773407790310153,73.98670997816463,197.8165491455736,0.0751320373328825
0.07852840469359422,183.290108294222,0.24932768490216164,73.90257166423031,197.68358809468336,0.07559752372194684
0.07902704132716011,183.098149569637,0.2509108562137333,73.82517390647764,197.56785460260323,0.07605974743291886
0.07953365332955961,182.946573339939,0.2525193493213517,73.7640583706634,197.49698268178855,0.07652914540996497
0.08003303644290101,182.783928687233,0.2541048907062107,73.69848004669234,197.4126815130349,0.0769916299672676
0.08054272773510732,182.540889646095,0.2557231605589657,73.6004867053055,197.2432308213847,0.07746344059303881
0.08105778579474002,182.264251937469,0.2573584698982995,73.4889463811875,197.0381886290549,0.07793999309768194
0.08157150248560521,181.965091890068,0.2589895203917965,73.36832505007543,196.80825783547206,0.0784150784054704
0.08206996712851151,181.641825197578,0.26057214563302405,73.23798391966345,196.54916382070604,0.07887584296256128
0.08256963964227501,181.286059432225,0.2621586058642231,73.09453916307312,196.25478403171186,0.07933751105832704
0.08305861720184211,180.989883312711,0.2637111096158487,72.97512095168507,196.02265274818754,0.07978909139427004
0.08355322214691692,180.713125303275,0.2652814803164612,72.86353212228049,195.81228920660317,0.08024566136650403
0.08404505009973681,180.495391970273,0.2668430340666644,72.77574204241408,195.6651362311862,0.0806994612864961
0.08453908290928082,180.237533646931,0.2684115882369666,72.6717735664426,195.47464944727324,0.08115508835723861
0.08503713336831141,179.875649396405,0.26999289844438873,72.5258618366305,195.1717589838387,0.08161421070937587
0.08553643055380501,179.431991375727,0.2715781670083309,72.34697892269313,194.77996344516782,0.0820742708543987
0.08602906612204211,179.078067733098,0.2731422849374837,72.20427690998513,194.48398666311624,0.0825279855385215
0.08652639048666672,178.779397168877,0.2747212897951668,72.0838529384912,194.24853309928213,0.08298580986866541
0.08701868529478482,178.444182368322,0.2762843258109418,71.94869433090743,193.9721605165162,0.08343879777494037
0.08749628355173841,178.139745473626,0.27780070027676945,71.82594537496601,193.72631115542086,0.0838780665511738
0.08798466423492861,177.768584962505,0.2793513089458983,71.67629345688202,193.4094942219494,0.084327052962102
0.08847068581589661,177.442845780401,0.2808944274654717,71.54495541865768,193.14133603971746,0.08477367052219605
0.08895894778941842,177.156414806169,0.28244465923140344,71.42946644984734,192.91606306147153,0.08522214607719898
0.08943128984879521,176.80934177621,0.2839443452699248,71.28952660416788,192.62162926857295,0.08565580764859075
0.0898987418689794,176.285708650119,0.2854285054340096,71.07839772772797,192.13357206724615,0.08608479455791579
0.09036519609621851,175.795088966666,0.2869094976054938,70.88057987135973,191.68084665389097,0.08651268241702648
0.0908474464652392,175.360821036254,0.28844064252713447,70.70548304181762,191.29190383744546,0.08695486798616196
0.09133187920619551,174.991877365779,0.2899787164796707,70.5567249538821,190.9742143714157,0.08739885784823728
0.09180460926911412,174.650931958554,0.2914796344294373,70.41925576568897,190.68469252549568,0.08783193207222888
0.09230726616546071,174.219817609018,0.29307557007533774,70.24543045995607,190.30157268435164,0.08829221701539017
0.09279268440193732,173.758490946751,0.29461677297615096,70.05942354973001,189.88200775932975,0.08873651545065009
0.09329485811830021,173.333633502388,0.29621117452560314,69.88812102816286,189.50477024712274,0.08919594236327671
0.09379164509912181,172.880607845515,0.29778847318971174,69.70546108331165,189.095364461082,0.08965023348403008
0.09427135760562211,172.343918674422,0.2993115603978502,69.48906800952696,188.5910138629327,0.09008871492957637
0.09476258846053331,171.780292023464,0.30087121836219327,69.26181374386069,188.05863714211378,0.09053752556957578
0.09527138236595502,171.2102669599,0.30248663901190714,69.03197963823168,187.52170576841385,0.09100217033888353
0.09575266130339831,170.693420904574,0.3040146996382896,68.82358730872424,187.03777022316808,0.09144148906436672
0.09626317594310402,170.126996070804,0.3056355836193552,68.59520481574818,186.50396102623958,0.09190728373634076
0.09674158762053661,169.520718299609,0.3071545406952037,68.35075361840235,185.92042172248694,0.09234359075488503
0.0972061302845686,168.633757656317,0.3086294636535053,67.99313108702701,185.0259926734333,0.09276706727365806
0.09767681941563862,167.871484818768,0.3101239016446526,67.68578267892727,184.26863752644593,0.09319596407505662
0.09815766115354181,167.226131254941,0.31165057416249525,67.42557612199222,183.6406571826812,0.093633922172394
0.09864171731389351,166.660997810997,0.3131874524716119,67.19771431739399,183.1007248443208,0.09407461436570987
0.09912897309357012,166.047337717821,0.3147344895720851,66.95028656782543,182.5074397907098,0.09451802348913345
0.09961102147600691,165.242949196098,0.3162649931863219,66.62595711586673,181.70296815722924,0.0949565004271531
0.10008871775354282,164.390434113048,0.3177816788674984,66.28222303438096,180.84406187437122,0.0953908290553073
0.10057711613130171,163.488105824805,0.3193323437168829,65.91840426856137,179.93126803043296,0.09583469325154956
0.10106603314885922,162.581380639406,0.320884655247628,65.5528126738085,179.01283584449553,0.09627883155412077
0.10155576829847121,161.656439650341,0.3224395643476461,65.1798764670175,178.07358357942684,0.09672351539168215
0.10204973188644022,160.695268844324,0.3240078987394477,64.79233239803145,177.09417794530668,0.09717183846602666
0.10252445854531121,159.635036862407,0.3255151558813631,64.36484686292249,176.00153258158605,0.09760251271438632
0.10298907619276822,158.384535778056,0.32699031691203906,63.86064482571218,174.69641280105844,0.09802383649863176
0.10347298828100922,157.23279941348,0.32852673779220426,63.39626472351513,173.5021470245813,0.09846246819213879
0.10394009423204421,156.024086308595,0.33000979918674034,62.90891159962551,172.24124454197897,0.09888568391166808
0.10443558949058622,154.685491771077,0.3315829966326112,62.36919028209825,170.84016228983066,0.09933442573626687
0.10494522237674721,153.454379871593,0.33320108104617235,61.8728059642263,169.5586838919032,0.09979576123122773
0.10551229058855122,152.059891940375,0.33500152261865007,61.3105484303592,168.10407944565154,0.10030883892751265
0.10612915034671722,150.290182273665,0.33696005235082716,60.59700149274173,166.24035162382233,0.10086666874815571
0.10682235956696622,147.874006927239,0.3391609916251177,59.62279959306277,163.67025726582858,0.10149317072058256
0.10753698772148822,144.6174331673,0.3414299360157251,58.309749053055356,160.1691563021251,0.10213861987065562
0.10835348195467821,140.66067388813,0.34402230520610333,56.71438371169402,155.90174767800036,0.10287556448169653
0.10928956085828422,136.275841554347,0.3469943557250524,54.94641931471271,151.16936843341472,0.1037197751514292
0.11006027406782921,132.159031631756,0.34944137016535776,53.286521553924025,146.70449087368596,0.10441431481200714
0.11063847474908221,129.415850940447,0.35127715732833603,52.18047109918824,143.73422329685263,0.1049350524353583