File: example/data/02 processed data/test_ID_055.csv
Strain,Stress_MPa,Displacement(mm),Force(kN),True Stress (MPa),True Strain
1.7468883884456e-05,0.147058556774808,5.5463706333147794e-05,0.029647005045801294,0.14706112572366054,1.7468731305366435e-05
1.87186094914401e-05,0.167631981723558,5.943158513532231e-05,0.0337946075154693,0.16763511956116217,1.871843430055704e-05
1.95109698609625e-05,0.221216993897371,6.194732930855594e-05,0.044597345969709996,0.22122131005547166,1.951077952436196e-05
2.40037185867218e-05,0.293612184970729,7.62118065128417e-05,0.05919221649009897,0.2936192327549907,2.4003430502152905e-05
1.92074663153107e-05,0.365590622434757,6.098370555111147e-05,0.07370306948284701,0.3655976445043226,1.9207281854210626e-05
4.95859219659446e-06,0.394041652314453,1.574353022418741e-05,0.07943879710659373,0.3940436062063153,4.958579902846777e-06
-3.01324528836008e-05,0.409946092672834,-9.567053790543254e-05,0.08264513228284333,0.4099337399915117,-3.0132906875113862e-05
-5.49854110444563e-05,0.614013137913863,-0.00017457868006614873,0.1237850486034348,0.6139793761490882,-5.498692279755847e-05
-6.75371666761292e-05,1.64084373490912,-0.0002144305041967102,0.3307940969576786,1.640732916972306,-6.753944741331085e-05
-5.24652264125047e-05,3.89339922502937,-0.0001665770938597024,0.784909283765921,3.8931949569575144,-5.246660276068866e-05
-2.32823908439349e-05,7.50820431625458,-7.39215909294933e-05,1.5136539901569233,7.508029507307153,-2.328266188299481e-05
2.26469722705875e-05,12.2135472996604,7.190413695911531e-05,2.4622511356115364,12.213823899527421,2.2646715831807597e-05
7.77502707554995e-05,17.5199640205492,0.0002468571096487109,3.5320247465427186,17.521326202495423,7.774724835976473e-05
0.0001352429057691,23.2225873619238,0.0004293962258168925,4.681673612163839,23.225728052118104,0.0001352337612717466
0.000206956766376,29.1847400875646,0.0006570877332438,5.883643601653023,29.190780067000645,0.00020693535377875
0.0002798949003708,35.2891455659088,0.0008886663086772899,7.114291746087214,35.29902281779114,0.00027985573710077204
0.0003608458975323,41.5471228453016,0.0011456857246650524,8.375899965612803,41.5621149541346,0.000360780808309146
0.0004441309015485,47.8795942004791,0.0014101156124164875,9.652526190816586,47.90085900781714,0.00044403230461196274
0.0005384097712099,54.3839967806562,0.0017094510235914323,10.96381375098029,54.41327765592035,0.0005382648806737892
0.0006372850753678,60.9636729830996,0.002023380114292765,12.29027647339288,61.002524222031326,0.0006370820954669078
0.0007304954863,67.6479813750658,0.0023193231690025,13.637833045213265,67.6973979201176,0.0007302288043377668
0.0008238521881653,74.3707347253824,0.0026157306974248272,14.993140120637094,74.43200521792139,0.0008235130082280519
0.000925882766629,81.1088767541977,0.002939677784047075,16.351549553646255,81.18397406540504,0.0009254544015703607
0.0010291945128258,87.773270119212,0.003267692578221915,17.69509125603314,87.86360588719147,0.0010286652552613702
0.0011306058224244,94.4234888839346,0.00358967348619747,19.035775359001214,94.53024463024039,0.0011299671689929843
0.0012317857328105,101.030436287347,0.003910919701673337,20.367735955529156,101.15488413734538,0.0012310277071843764
0.0013320340089224,107.604228612178,0.00422920797832862,21.693012488215086,107.7475611041933,0.0013311476386515795
0.0014390682897537,114.178792120351,0.004569041819967997,23.018444491462766,114.34310319945376,0.001438033823308624
0.0015383960982329,120.686113252501,0.004884407611889457,24.330320431704205,120.87177629823955,0.0015372139791783185
0.0016399522863665,127.215949067175,0.0052068485092136374,25.646735331942484,127.42457715371002,0.0016386090329962501
0.0017402518803954,133.652052369257,0.005525299720255394,26.944253757642215,133.88464060471134,0.001738739396572868
0.0018455053583623,140.010326410038,0.005859479512800302,28.226081804263664,140.2687162176538,0.0018438045056488447
0.0019425701388785,146.22007265748,0.006167660190939238,29.477966647747966,146.50411540432904,0.0019406857894322211
0.0020394447069424,152.326227074935,0.0064752369445421195,30.708967378306895,152.6368879924715,0.0020373678628459175
0.0021430312117828,158.406047302999,0.0068041240974103905,31.9346591362846,158.74551640650446,0.0021407381958141953
0.0022412374092373,164.373999574955,0.0071159287743284266,33.13779831431093,164.74240073190836,0.0022387295830652494
0.0023474606451783,170.339609923968,0.0074531875484411024,34.34046536067195,170.73947545457955,0.0023447096638105165
0.002452607020493,176.134369351097,0.007787027290065274,35.508688861181156,176.56635774191764,0.002449604288573392
0.00255487636275,181.895747966131,0.00811173245173125,36.67018278997202,182.36046911309444,0.002551618214399855
0.00265551069522,187.581700578084,0.008431246457323498,37.81647083654173,188.07982579019665,0.0026519910562760748
0.00275379964253,193.205397558862,0.00874331386503275,38.95020814786658,193.73744651359445,0.0027500148830151244
0.0028617484567021,198.805249884603,0.009086051350029167,40.07913837673596,199.37418050164456,0.0028576614500541012
0.0029652188756788,204.28575033164,0.009414569930280189,41.18400726685863,204.89150229455558,0.0029608312854921127
0.0030717313613659,209.620971667458,0.009752747072336733,42.25958788815953,210.26487098012893,0.003067023233526437
0.0031813313435632,214.830950114422,0.010100727015813158,43.30991954306747,215.51439854958846,0.003176281616074083
0.003297521946635,219.897277181989,0.010469632180566124,44.33129107988899,220.6223932795019,0.003292097043693588
0.0034248820699636,224.826368023743,0.01087400057213443,45.32499579358659,225.59637182044256,0.0034190305181440494
0.0035622224071002,229.641449478052,0.011310056142543134,46.29571621477528,230.45948339498167,0.003555892720242445
0.0037177553072358,234.237564495558,0.011803873100473664,47.2222930023045,235.10840244411534,0.0037108615359271106
0.0039159718158736,238.631413764283,0.01243321051539868,48.10809301487945,239.56588765496602,0.003908324356564151
0.0041570941986876,242.665327698739,0.01319877408083313,48.92133006406578,243.67411032473808,0.0041484773550319425
0.0044478137427602,246.084361911837,0.014121808633263634,49.61060736142634,247.17889931862683,0.004437951452155875
0.0047726789286905,248.709011357487,0.015153255598592338,50.139736689669384,249.89601961536835,0.004761325805489751
0.0051162363801397,250.503407490878,0.016244050506943546,50.50148695016101,251.78504213763182,0.005103192912849233
0.0054732750927686,251.648000749841,0.017377648419540304,50.73223695116794,253.02533948449013,0.005458351153101125
0.0058347015619777,252.404009929976,0.018525177459279195,50.88464840188317,253.8767120009639,0.005817745614113041
0.006205251875799,252.948466941618,0.019701674705661826,50.99441093543019,254.51807589058794,0.006186078576266592
0.0065758157947485,253.368399454222,0.020878215148326485,51.079069329971155,255.0345033772432,0.006554289435448723
0.0069463948866948,253.717792242965,0.02205480376525599,51.14950691618174,255.48021621766503,0.006922379833622303
0.0073249668030092,253.994436996012,0.02325676959955421,51.20527849839602,255.85493781515677,0.007298269525519815
0.0077069374241003,254.270630548158,0.02446952632151845,51.26095911850865,256.2302783865792,0.007677390694633906
0.0080884368756798,254.500712676356,0.025680787080283363,51.30734367555337,256.5592256256542,0.008055900796401248
0.0084719252485921,254.72406451755,0.026898362664279914,51.35237140673809,256.8820677511602,0.008436239897315904
0.0088462223719032,254.925488403437,0.028086756030792658,51.392978462132895,257.1806159621198,0.008807323782173452
0.0092175400989823,255.143423981642,0.0292656898142688,51.43691427469903,257.4952187231844,0.009175317834863505
0.0095925957882464,255.339528253698,0.030456491627682315,51.476448895945516,257.78889713699726,0.009546878970714665
0.0099672183145621,255.560802652774,0.031645918148734666,51.521057814799235,258.1080329654589,0.009917873212129544
0.0103464985585158,255.764822307561,0.032850132923287666,51.5621881772043,258.4110926728852,0.010293339898557349
0.0107249785972814,255.959897975673,0.03405180704636844,51.60151543189568,258.7050624032244,0.010667873948904286
0.0111016246454469,256.162766908389,0.035247658249293906,51.64241380873123,259.0065897947451,0.011040453923782953
0.0114791617664232,256.355016116438,0.036446338608393664,51.6811712490739,259.2977568160726,0.011413776095037966
0.0118518038655864,256.535849583117,0.03762947727323682,51.71762727595638,259.57626215686764,0.011782121274058241
0.0122228816746559,256.736978709873,0.03880764931703248,51.75817490791039,259.8750444221524,0.012148785425216158
0.0125826744468259,256.917746813736,0.03994999136867223,51.794617757649185,260.15045918150525,0.012504170439711935
0.0129531702004117,257.123382404644,0.04112631538630714,51.836073892776234,260.4539453394369,0.012869995373096273
0.0133202791013874,257.314263207849,0.04229188614690499,51.87455546270237,260.7417610105454,0.01323234420130478
0.0136874869740899,257.508184315138,0.04345777114273543,51.913649957931824,261.032824233673,0.013594659415745806
0.0140499647505277,257.678060752967,0.04460863808292545,51.94789704779814,261.2984284235305,0.013952178856924373
0.0144086626107963,257.877603681858,0.04574750378927825,51.98812490226257,261.5932750681905,0.014305844304342397
0.0147683836802337,258.095045673668,0.046889618184741994,52.03196120781146,261.90669233414417,0.014660393035182042
0.0151267783122646,258.296413654857,0.0480275211414401,52.07255699281917,262.20360624306704,0.015013509434950367
0.0154846354542318,258.502153898415,0.04916371756718596,52.11403422592046,262.5049655156656,0.015365971893543622
0.0158392888243455,258.672744405704,0.05028974201729697,52.148425272189925,262.76993671533205,0.01571515635346995
0.0161872841670323,258.844080462251,0.051394627230327554,52.1829666211898,263.0340631476476,0.016057666978787778
0.016535586509764,259.036474503739,0.0525004871685007,52.221753259953786,263.3197945370799,0.016400362336984352
0.016879878621537,259.220904899054,0.05359361462337997,52.258934427649294,263.59652230991503,0.016738996640663903
0.0172294745465149,259.415442317065,0.054703581685184806,52.29815317112031,263.8850340774398,0.01708273030264783
0.0175838275032428,259.608022650308,0.055828652322795894,52.336977366302094,264.17292533904896,0.01743102069366597
0.0179380149652456,259.796814002516,0.05695319751465478,52.37503770290722,264.4570531400162,0.017779027242343284
0.0182936914730834,260.001756132707,0.05808247042703979,52.41635403635373,264.7581480418586,0.018128375020722915
0.0186440860774824,260.197122715152,0.05919497329600661,52.45573993937464,265.04826026816653,0.0184724155817228
0.0189947630290819,260.339961072516,0.060308372617335036,52.484536152219235,265.28505694008885,0.01881661490361483
0.0193477216848347,260.528513806015,0.06142901634935017,52.52254838329262,265.5691469820974,0.019162934191887117
0.0196994791786617,260.710611102134,0.06254584639225089,52.55925919819022,265.8464743571967,0.01950795562853405
0.020050823105622,260.904067295429,0.06366136336034985,52.59825996675849,266.13540859630695,0.019852452629016422
0.0204029779674043,261.105668993919,0.06477945504650866,52.638902869174075,266.43300220556625,0.020197625712664233
0.0207470174609702,261.28576876939,0.06587178043858039,52.67521098390903,266.7066691763516,0.020534729303869848
0.0211001151103278,261.473279953695,0.06699286547529076,52.71301323866492,266.9903962589929,0.02088059031103807
0.0214435333718208,261.641869848158,0.06808321845553104,52.74700096138866,267.2523960157126,0.02121685559964932
0.0217929364003597,261.828355395481,0.06919257307114204,52.78459644772897,267.5343640924255,0.02155886499221238
0.0221315055515981,262.010854256199,0.07026753012632396,52.82138821804973,267.809548931749,0.02189015821165411
0.0224744462175241,262.191279747323,0.07135636674063901,52.857761997060315,268.083883562708,0.022225617148223648
0.0228166656980406,262.371531949436,0.0724429135912789,52.894100841006306,268.3579754826091,0.022560258492642923
0.0231518920229188,262.54834915378,0.07350725717276718,52.92974718940205,268.6268401841839,0.02288795299861459
0.0234912400379395,262.710969614969,0.0745846871204579,52.96253147437775,268.88237606279404,0.023219567253014425
0.023831249029289,262.864557096166,0.07566421566799257,52.993494710587065,269.12894781729847,0.02355171716714962
0.0241766293251018,263.076653678197,0.07676079810719821,53.03625338152451,269.4369604182629,0.023889001317994412
0.024518788675587,263.255443015275,0.07784715404498872,53.07229731187944,269.71014759026457,0.024223027889890163
0.0248556655597176,263.430977584428,0.07891673815210339,53.10768508102068,269.978729861336,0.024551788587056627
0.0252003447910428,263.611637547807,0.08001109471156088,53.1441061296379,270.2547417049431,0.024888051823604915
0.0255408961671563,263.795849238508,0.08109234533072125,53.181243206483224,270.5334316332356,0.02522017698151609
0.0258841654788525,263.956808556641,0.08218222539535669,53.213692605018835,270.7891102685909,0.025554841231571084
0.0262219316351209,264.126391172029,0.08325463294150885,53.24788046028105,271.05229534437314,0.025884030994024084
0.0265546708377429,264.297235640554,0.08431107990983369,53.282322705135684,271.3155617363143,0.0262082155206163
0.0268831670414593,264.458212203958,0.08535405535663328,53.314775580317935,271.5676864981227,0.02652816307438103
0.0272176300109845,264.656199677518,0.08641597528487578,53.354689854987626,271.85951420045393,0.026853816978961553
0.0275579131114471,264.838512260253,0.08749637412884455,53.39144407166701,272.13690896968603,0.02718502892540738
0.0278930391396008,265.02016622259,0.08856039926823255,53.42806551047414,272.41238409182023,0.027511114090082493
0.0282342385427954,265.166654324856,0.08964370737337539,53.45759751189097,272.65343289665896,0.027842999581831823
0.028574119505954,265.327195069552,0.09072282943140395,53.489962526021685,272.9086860496489,0.02817349314961818
0.0289111659197747,265.490042056638,0.09179295179528467,53.52279247861822,273.16566871258544,0.028501122629375056
0.029246887038546,265.65323668531,0.09285886634738354,53.555692515758494,273.4227668900694,0.028827357168327322
0.0295779731267674,265.826408624705,0.09391006467748649,53.59060397874053,273.6890149953916,0.02914898344891223
0.0299086773873306,265.980160093634,0.09496005070477465,53.62160027487662,273.93527489330506,0.029470135580025057
0.0302431335003322,266.155433187571,0.09602194886355474,53.65693533061432,274.20480748530144,0.0297948263277383
0.0305763439109963,266.291013512183,0.09707989191741326,53.68426832405609,274.4332191217392,0.030118202942934522
0.0309114623226535,266.464898397315,0.09814389287442485,53.719323516898704,274.70171806443324,0.030443325811569246
0.0312536728966814,266.610736309439,0.09923041144696344,53.74872443998291,274.9433010527976,0.03077522025719324
0.0315923847826017,266.769929710916,0.10030582168476039,53.780817829720675,275.1978279787709,0.03110361304995952
0.0319348707789479,266.950489244896,0.10139321472315958,53.81721863177104,275.4755186233087,0.0314355553575477
0.0322676510230321,267.116141102839,0.10244979199812691,53.85061404633234,275.73535152656444,0.03175798520001949
0.0326069665084439,267.259243571758,0.10352711866430937,53.879463504066415,275.9737567759744,0.03208664001090727
0.0329441786095745,267.403404633787,0.10459776708539903,53.90852637417145,276.2127901568508,0.0324131505453218
0.0332813038442988,267.557702960072,0.10566813970564869,53.93963291675052,276.46237216816877,0.03273947043691017
0.0336144396872911,267.694086853252,0.10672584600714924,53.967127909615606,276.69247359042504,0.033061824234308625
0.0339522608151205,267.836044636503,0.10779842808800758,53.99574659871901,276.9296838796918,0.033388605595948535
0.0342854771293172,267.974607096303,0.10885638988558209,54.023680790614684,277.1622443591411,0.03371082804742643
0.0346239632773492,268.145832580466,0.1099310834055837,54.058199848221946,277.4301040407063,0.03403804019547052
0.0349704518367049,268.302054051227,0.11103118458153804,54.089694096727364,277.6846981101144,0.034372877359759774
0.0353051633705786,268.454031543823,0.11209389370158705,54.12033275923473,277.93184498496817,0.03469622709573825
0.0356385230403262,268.575973769213,0.11315231065303567,54.14491631187335,278.1476247984652,0.0350181669677052
0.0359723364988014,268.690607763622,0.11421216838369443,54.16802652514619,278.3560367201624,0.035340441259546475
0.0362904192020867,268.843444891774,0.11522208096662526,54.19883849018164,278.5998862066296,0.03564743196804462
0.036622032199421,268.987052182065,0.11627495223316167,54.22778971990431,278.8379046683039,0.035967380839921924
0.0369507424735604,269.153212528587,0.11731860735355426,54.26128764576314,279.0986235706623,0.03628442809373215
0.0372823857036329,269.248944713782,0.11837157460903446,54.28058725429845,279.28718772089735,0.03660420240298723
0.0376209968295516,269.416961525149,0.11944666493382632,54.31445944347004,279.5526961805141,0.036930589772900604
0.0379544676123527,269.557196292436,0.12050543466921983,54.3427307725551,279.78809616879386,0.037251918282880915
0.0382909049915482,269.704704882847,0.12157362334816552,54.37246850438196,280.0319421132897,0.037576000770027755
0.0386281813948427,269.811834095145,0.12264447592862555,54.39406575358124,280.2341745650475,0.037900786081569326
0.0389633522826367,269.936933770639,0.12370864349737151,54.41928584816082,280.45458161523914,0.03822343938975678
0.0393050547503117,270.099739349408,0.12479354883223964,54.45210745284066,280.71602439258146,0.038552273210833786
0.0396435054343351,270.247657197651,0.12586812975401393,54.481927691046444,280.96122166438244,0.038877871153462404
0.0399854803084791,270.398980257555,0.12695389997942114,54.512434419923096,281.21101335807634,0.03920675181397528
0.0403271302562653,270.52169538652,0.12803863856364234,54.53717378992243,281.4310590335179,0.039535212016660916
0.0406658862982476,270.637286880592,0.1291141889969361,54.56047703512735,281.6429920169444,0.03986078355128858
0.041008326661945,270.749396290421,0.13020143715167537,54.58307829214887,281.852375977023,0.04018978831548684
0.0413479785405176,270.859650579133,0.1312798318661434,54.60530555675322,282.05914959877106,0.040516007109778755
0.041687110762148,271.007973689073,0.13235657666981987,54.635207495717125,282.30551310567466,0.040841620659323216
0.0420204532835947,271.124133959067,0.13341493917541317,54.65862540614791,282.51689296414906,0.041161572009543505
0.0423586264045105,271.246597631113,0.13448863883432083,54.68331408243238,282.7362309236639,0.04148605533139086
0.0426942589362779,271.354605762805,0.13555427212268234,54.70508852178149,282.9398895647939,0.041807996838990995
0.0430294542099366,271.450074935202,0.13661851711654868,54.72433510693673,283.1304235049101,0.04212941551437123
0.0433629346797453,271.582194457057,0.13767731760819132,54.7509704025427,283.35879541548024,0.04244908737899692
0.0436992573411186,271.694160681104,0.13874514205805152,54.77354279331056,283.5669937267868,0.04277138028006171
0.0440314417692199,271.781221749124,0.13979982761727316,54.79109430462339,283.74814078853797,0.04308960564413388
0.0443652679850281,271.909919011089,0.1408597258524642,54.817039672635545,283.97327543580326,0.04340930181784686
0.0446957009470242,271.991616357692,0.14190885050680183,54.83350985771071,284.14847230251314,0.043725647745194836
0.0450327900194867,272.127871940293,0.14297910831187027,54.86097898316307,284.38254925583,0.04404826293357306
0.0453706619847066,272.249980184942,0.14405185180144345,54.885596005284306,284.60214201125603,0.04437152298927008
0.0457115327350665,272.372833771183,0.14513411643383614,54.9103632882705,284.8234134782573,0.04469754628404068
0.046054543280013,272.484292720553,0.14622317491404127,54.93283341246349,285.03343237277545,0.04502550891041084
0.0463960750524035,272.596920712125,0.1473075382913811,54.95553921556439,285.2443479045388,0.04535195080818485
0.0467350005111091,272.693199894025,0.14838362662277138,54.974949098635435,285.43751673044824,0.045675796233466175
0.0470786195316548,272.797233611493,0.149474617013004,54.995922296077,285.64015078197644,0.04600401935737873
0.0474185506507669,272.920959223737,0.1505538983161849,55.02086537950538,285.86247555234365,0.046328613849017174
0.0477613756428615,273.007578198428,0.15164236766608527,55.03832776480309,286.046795694111,0.04665586497513927
0.048108300294855,273.100194341065,0.15274385343616462,55.0569991791587,286.2385805010082,0.04698692053564963
0.0484501387107068,273.197707922866,0.1538291904064941,55.07665791724979,286.43417476717605,0.04731301535134494
0.0487920442297211,273.315097661002,0.15491474042936448,55.10032368845801,286.6506999947282,0.047639067845257684
0.0491323529260017,273.392338197416,0.1559952205400554,55.11589538059907,286.82474704499623,0.04796349202348521
0.0494741189789343,273.485850772336,0.1570803277581164,55.13474751570294,287.0163222925016,0.04828919963997198
0.0498155667248394,273.529883417014,0.1581644243513651,55.143624496870025,287.1559295756118,0.04861449800278623
0.0501571748659235,273.62442645774,0.1592490301993071,55.16268437388038,287.34865466316893,0.0489398433154483
0.0504972480734032,273.72294825071,0.16032876263305515,55.18254636734313,287.5452038719094,0.049263621664458884
0.050837017297225,273.792159409148,0.16140752991868937,55.19649933688424,287.71093615287543,0.04958700593737743
0.0511792557464024,273.9272803719,0.1624941369948276,55.22373972297504,287.94667470996995,0.04991263467450028
0.0515262124859783,274.005505641761,0.16359572464298108,55.23950993737902,288.1239715477863,0.05024264450989244
0.0518711856026018,274.117020890267,0.16469101428826072,55.26199141147782,288.3357957576983,0.0505706596724385
0.0522194594862821,274.168450415379,0.16579678386894567,55.27235960374042,288.4853787042617,0.050901704238102946
0.0525634398443692,274.25263369591,0.1668889215058722,55.28933095309546,288.66829550934483,0.05122856014448545
0.0529077690907332,274.332065768147,0.1679821668630779,55.305344458858436,288.84636335799195,0.05155564060796778
0.0532497578779369,274.425374507612,0.16906798126244965,55.32415550073458,289.0384592557045,0.05188039199605758
0.0535851617664508,274.496398844202,0.17013288860848128,55.33847400699113,289.2053327805768,0.05219878798258703
0.0539219962394021,274.543925847373,0.17120233806010166,55.34805545083039,289.3478823844657,0.05251844001749455
0.0542669537974283,274.632135704435,0.17229757830683484,55.3658385580141,289.5355851239966,0.052845694897659536
0.0546120910735275,274.700361178578,0.1733933891584498,55.379592813601334,289.70232232119344,0.05317301312866006
0.0549668158446606,274.811271875947,0.1745196403067974,55.401952410190916,289.9167724491891,0.053509312257659675
0.0553206310078541,274.874759391283,0.17564300344993677,55.41475149328266,290.08100452894087,0.05384463640227937
0.0556747672279586,274.959260682013,0.17676738594876856,55.43178695349382,290.26755351765564,0.05418015226718611
0.0560274280568149,275.028227703201,0.17788708408038728,55.44569070496533,290.4373519444354,0.05451415848541372
0.0563740708850413,275.095550694619,0.17898767506000612,55.459263020035195,290.60380676963695,0.05484235635074523
0.0567211568767407,275.142563107801,0.18008967308365173,55.46874072253268,290.7489675933071,0.05517086591364692
0.0570621939194268,275.204610685084,0.18117246569418008,55.48124951411293,290.90838954751666,0.05549354519439425
0.0574121451554126,275.252835029295,0.18228356086843497,55.49097154190588,291.0556907484357,0.055824550619916695
0.0577610543031611,275.304774915402,0.1833913474125365,55.50144262294504,291.20666896921006,0.056154461334559244
0.0581164108159026,275.413905652381,0.18451960434049075,55.52344337952002,291.41997333768705,0.05649035650990936
0.0584658183368484,275.467286802513,0.18562897321949365,55.53420501938662,291.57270715045325,0.05682051852233414
0.0588177035915136,275.555372456978,0.18674620890305568,55.55196308732676,291.76290667720167,0.05715291166124118
0.0591695136063808,275.603473410548,0.18786320570025902,55.561660239566486,291.91079688047927,0.0574851233150662
0.0595205824434346,275.652675521237,0.18897784925790484,55.57157938508138,292.05968332035206,0.05781652510046318
0.0598744252501536,275.712183532963,0.19010130016923768,55.583576200245346,292.220292056464,0.058150434361098485
0.0602352828337668,275.750013490933,0.19124702299720958,55.59120271977209,292.3598935449744,0.058490848430919645
0.0605876654200198,275.797874219544,0.19236583770856286,55.60085144266007,292.5078235463104,0.058823155839971115
0.060939409321952,275.855039006072,0.1934826245971976,55.61237586362411,292.66548214158604,0.0591547508588073
0.0612874940560742,275.926095325187,0.19458779362803558,55.626700817557705,292.8369142523452,0.05948278810750067
0.0616364476836662,275.983664549361,0.19569572139564018,55.63830677315117,292.99431725090415,0.05981153623066595
0.0619907326127562,276.036824291638,0.19682057604550093,55.64902377719422,293.1485492575753,0.060145196428335365
0.0623468289257937,276.072505746243,0.19795118183939497,55.65621715844259,293.2847510331192,0.06048045041321991
0.0627038439833729,276.100525946148,0.19908470464720895,55.66186603074344,293.4130902488025,0.06081645657579231
0.0630531898667404,276.192985188301,0.20019387782690076,55.68050581396148,293.6078339232408,0.06114513561196578
0.0634011916884291,276.226520711532,0.2012987836107624,55.687266575444845,293.73961130059166,0.06147244272733506
0.0637522190131096,276.256357775263,0.20241329536662295,55.69328172749302,293.86831359991555,0.06180248693204634
0.0641025617822428,276.292704055548,0.2035256336586209,55.70060913759848,294.0037741872517,0.0621317789264633
0.0644617985916074,276.343553454342,0.2046662105283535,55.71086037639535,294.15715593920487,0.06246931799219509
0.0648168057662172,276.394890505114,0.20579335830773962,55.72120992583098,294.30992443775887,0.0628027710003386
0.0651736082668792,276.489633791396,0.20692620624734143,55.74031017234544,294.5094608739693,0.06313779833346518
0.0655335686936008,276.510160756163,0.20806908060218254,55.74444840844246,294.6308583705556,0.06347567716922285
0.0658945600175748,276.566040344931,0.20921522805579995,55.755713733538094,294.7902378892631,0.0638144090481571
0.0662563911748284,276.587112093627,0.21036404198008016,55.75996179807521,294.91277598641847,0.06415381387362185
0.0666204770512488,276.609992601471,0.21152001463771491,55.764574508456555,295.0378822657234,0.06449521743552519
0.0669875912950747,276.651425930974,0.21268560236186215,55.77292746768437,295.18363858243777,0.06483934272535255
0.067353581695898,276.676333882902,0.21384762188447615,55.77794891079304,295.31147594040556,0.0651822967095063
0.067718371687846,276.703770627486,0.21500583010891106,55.78348015850118,295.44169941426657,0.06552400884236403
0.0680813881862166,276.717768585126,0.21615840749123771,55.7863021467614,295.55709840619363,0.06586394380133011
0.0684380571111996,276.742135993756,0.21729083132805874,55.791214616341215,295.681830101972,0.0661978222774482
0.0688014575287381,276.773227342054,0.21844462765374348,55.79748263215808,295.8156287881201,0.0665378875050948
0.0691569744978213,276.789952743313,0.2195733940305826,55.800854473051906,295.93190844643544,0.06687046363663643
0.0695220361401569,276.843324806802,0.22073246474499814,55.81161428105129,296.0900364391817,0.06721185347968005
0.0698896461226622,276.825318350496,0.22189962643945246,55.80798417945999,296.17254188780544,0.06755550869028844
0.0702542988636713,276.895812343574,0.22305739889215634,55.82219576846452,296.3489334980585,0.06789628272597177
0.0706201357664178,276.908235714628,0.2242189310583765,55.824700320069006,296.46353291563423,0.06823804672706367
0.0709787875239302,276.94052094969,0.22535765038847838,55.831209023457504,296.5974233429446,0.06857298503597388
0.0713430444821084,276.959887256845,0.22651416623069417,55.835113270979946,296.71904881316976,0.06891304315072241
0.071711402874981,276.935821763582,0.22768370412806466,55.83026166753814,296.7952780485842,0.06925681266806208
0.072084298324106,276.960079074528,0.22886764717903652,55.83515194142484,296.9245520384042,0.06960469605329049
0.0724567028723142,276.99329407362,0.23005003161959758,55.84184808524179,297.06331487993583,0.06995200072290869
0.072825128330387,277.016906427777,0.2312197824489787,55.84660833583984,297.1906981880666,0.07029547583777342
0.0731898267186226,277.028090198484,0.23237769983162676,55.848862984014374,297.303728116302,0.07063536013437495
0.0735535016012671,277.018797476684,0.23353236758402302,55.846989571299495,297.39450004046637,0.07097417556827053
0.0739238830921345,277.009689160622,0.23470832881752704,55.84515333478139,297.4873210375203,0.07131912122141673
0.0742976972858957,277.039025409186,0.23589518888271885,55.8510675224919,297.62238705541733,0.07166714323269222
0.074676035587255,277.068559234551,0.2370964129895346,55.857021541685484,297.75894082405983,0.07201925391648586
0.0750525413008308,277.080919182671,0.2382918186301378,55.85951330722647,297.87654631330054,0.07236953601393124
0.0754241588915086,277.067947779271,0.23947170448053978,55.85689827230103,297.9655646963189,0.07271515016947518
0.0757971776471026,277.051404214476,0.24065603902955074,55.853563089638364,298.0511187170999,0.07306194736137443
0.0761703920470639,277.035136579167,0.24184099474942786,55.850283534360074,298.13701154321404,0.07340880612352219
0.0765507912461188,276.997698611778,0.24304876220642718,55.84273604013444,298.2020916138635,0.07376221854494144
0.0769313066013635,276.980285233986,0.2442568984593291,55.83922550317158,298.28874047985494,0.07411561396864638
0.0773124633642331,276.977885365826,0.24546707118144007,55.83874168975052,298.3917279808742,0.07446947992584307
0.0776883953643874,276.954204523479,0.24666065528192999,55.83396763193337,298.47033226232844,0.07481837259792264
0.0780728218129212,276.906900426329,0.2478812092560248,55.82443112594793,298.5258035220821,0.07517502290737761
0.0784498080571867,276.818071939859,0.24907814058156774,55.80652330307557,298.53439655030144,0.07552464710596844
0.0788290136224467,276.763268078443,0.2502821182512682,55.79547484461411,298.58024350799144,0.07587620626962856
0.0792087230275841,276.661974322247,0.2514876956125795,55.775054023364994,298.57601601860245,0.07622810874344285
0.0795922756535746,276.615414463801,0.25270547520009934,55.76566755590228,298.6318647818316,0.07658344731356621
0.0799804445380525,276.487079251232,0.2539379114083167,55.73979517704837,298.6006387587733,0.07694293406298565
0.0803683755275362,276.327263381982,0.2551695922999274,55.70757629780758,298.53523665396153,0.07730207143010905
0.0807591988725875,276.16385468861,0.25641045642046534,55.674633105223776,298.4666263508278,0.07766375609319084
0.0811508272251519,275.925582506587,0.25765387643985727,55.62659743332794,298.3171717795784,0.07802605457196252
0.0815473947986404,275.672581079452,0.25891297848568323,55.57559234561752,298.15296188389834,0.07839278865801735
0.0819455283300198,275.358394982098,0.26017705244781286,55.51225242839096,297.9227841390123,0.07876083565425886
0.0823553009229451,275.001226794169,0.2614780804303507,55.44024732170447,297.6490355809819,0.0791395007568944
0.082766878200192,274.567649584296,0.2627848382856096,55.352838156194075,297.29275679515246,0.07951968926188777
0.0831859011236585,274.080915912032,0.2641152360676157,55.25471264786565,296.8805838829721,0.07990660714181007
0.0836025656324194,273.498807280653,0.2654381458829316,55.13735954777965,296.3640092667222,0.08029119891926256
0.0840281900686938,272.850648894008,0.2667895034681028,55.006690817032,295.77779507964016,0.08068390827774084
0.084457767299348,272.109516282367,0.26815341117542985,54.85727848252519,295.0912784884813,0.08108010843279738
0.0848931538852018,271.332279291851,0.2695357635855157,54.700587505237166,294.36653223179667,0.08148150646153292
0.0853320483549782,270.469060714539,0.27092925352705577,54.52656264005106,293.5487396819576,0.0818859755233674
0.0857734924712991,269.534108982169,0.27233083859637464,54.338076370805275,292.6529908497094,0.08229262928948172
0.0862272570878697,268.522259596055,0.2737715412539863,54.134087534564685,291.6761975080597,0.08271046029001361
0.0866765313938924,267.469749645852,0.2751979871756084,53.92190152860377,290.6530997979472,0.08312398463914171
0.0871383469699441,266.381154226034,0.27666425162957253,53.70244069196846,289.5931676692364,0.08354887416179223
0.0876002941801634,265.206706899602,0.27813093402201877,53.465672110959765,288.4388924425595,0.08397370426176491
0.0880771737521684,264.040521777034,0.2796450266631347,53.23056919025005,287.29646469120297,0.08441207767572044
0.0885578317855555,262.768849315848,0.2811711159191387,52.97420002207496,286.0390888720449,0.0848537300795247
0.0890487859055219,261.479518139211,0.282729895250032,52.71427085686494,284.7639517686687,0.08530464175870162
0.0895478752842649,260.096713059669,0.28431450402754105,52.43549735282927,283.38782108258346,0.08576281687331988
0.0900535031989469,258.684367290523,0.28591987265665636,52.150768445769444,281.9798007878377,0.08622678054001942
0.0905668667615051,257.192957254978,0.2875498019677787,51.85010018260357,280.48611754668707,0.08669762230515585
0.0910826757197871,255.652846604457,0.28918749541032407,51.539613875458535,278.93839192857126,0.0871704837412841
0.0915997591079255,254.065090014435,0.29082923516766346,51.219522146910094,277.3373910574906,0.08764428917404966
0.0921283023696769,252.412666842987,0.29250736002372413,50.88639363554618,275.6670173358342,0.08812836343347448
0.0926572793827544,250.715813999798,0.29418686204024524,50.544308102359274,273.94645922325196,0.08861260044769882
0.0932045798331922,248.963643732153,0.29592454097038523,50.19107057640205,272.1681955399489,0.08911336444572292
0.0937538880776381,247.157685298782,0.2976685946465009,49.826989356234456,270.3296792638121,0.08961571349720932
0.0943148745245232,245.269057750506,0.2994497266153611,49.44624204250201,268.401578156993,0.09012848207995695
0.0948846117864288,243.2742274863,0.3012586424219114,49.044084261238076,266.35720811898096,0.09064898035188769
0.0954590643446736,241.184525014162,0.30308252929433865,48.622800242855064,264.2077741064284,0.0911735122577029
0.09602217466313,239.034545602622,0.30487040455543774,48.189364393488596,261.98716249099886,0.09168742067802287
0.0965916424023385,236.825716829982,0.3066784646274247,47.74406451292438,259.70110178170114,0.09220686258574116
0.0971698510993216,234.502090788004,0.308514277240346,47.27562150286161,257.28862403235394,0.09273400166816644
0.097822160455407,232.121664250439,0.3105853594459172,46.795727512888504,254.82830693592157,0.09332836317094628
0.098357813197515,229.451386102462,0.31228605690211014,46.25739943825634,252.01972267463884,0.09381616722995388
0.0986944880720494,227.240907047303,0.31335499962875685,45.81176686073629,249.66833203736476,0.09412264593960985
0.0988924979706207,225.674567645008,0.3139836810567207,45.495992837233615,247.99208936786266,0.09430285259387626