File: example/data/02 processed data/test_ID_142.csv
Strain,Stress_MPa,Displacement(mm),Force(kN),True Stress (MPa),True Strain
3.6792926015639e-05,-0.345641443185096,0.00011681754009965382,-0.06968131494611536,-0.34565416034514307,3.6792249172560334e-05
1.56440815139438e-05,0.182918931311366,4.966995880677156e-05,0.03687645655237139,0.18292179291003788,1.5643959146632105e-05
-4.30543518838652e-05,1.32881517200939,-0.00013669756723127199,0.267889138677093,1.3287579607333855,-4.305527874910961e-05
-0.0001277264643308,3.43702443762852,-0.00040553152425029,0.6929041266259097,3.4365854386492836,-0.0001277346220502811
-0.0001796100546902,6.3042413607234,-0.000570261923641385,1.2709350583218375,6.30310905558782,-0.0001796261865077753
-0.0001632601288575,9.37621225235857,-0.0005183509091225625,1.8902443900754877,9.374681490738055,-0.00016327345724299829
-0.0001007601299284,12.5854795537151,-0.00031991341252267,2.537232678028964,12.584211439160056,-0.00010076520657134434
-2.25517376617765e-05,16.0352663769323,-7.160176707614038e-05,3.2327097015895516,16.03490475381163,-2.2551991956005758e-05
6.77450381402222e-05,19.6933460637402,0.0002150904960952055,3.9701785664500244,19.6946801902204,6.774274354886673e-05
0.00014809362599,23.3722454282488,0.00047019726251825003,4.711844678334958,23.3757067088218,0.00014808266121160861
0.0002155876785113,26.9826427715548,0.0006844908792733775,5.439700782745448,26.98845989687002,0.0002155644428271928
0.0002899850314805,30.4876057790233,0.0009207024749505875,6.146301325051097,30.4964467283449,0.00028994299394798756
0.0003616647346532,33.900288393636,0.00114828553252391,6.834298140157018,33.912548932442554,0.00036159934972748237
0.0004438044400839,37.2352675708641,0.0014090790972663824,7.506629942286203,37.25179274793976,0.00044370598802122925
0.0005236702729591,40.4537044928105,0.0016626531166451426,8.155466825750597,40.474888895284465,0.0005235332055318001
0.0006097295108029,43.573839819106,0.0019358911967992075,8.78448610753177,43.60040807514271,0.0006095437012899793
0.0006744424895254,46.5470685407601,0.0021413549042431446,9.383889017817237,46.578461861546835,0.0006742151553995875
0.0007428495026116,49.3934021189039,0.00235854717079183,9.957709867171028,49.43009398310022,0.0007425737264848317
0.0008432209245762,52.1079432260402,0.002677226435529435,10.504961354369705,52.15188173410502,0.0008428656135354016
0.0008894365454961,54.6859218539595,0.0028239610319501173,11.024681845758234,54.734561511380555,0.0008890412311991713
0.0009780676783742,57.1398201610695,0.0031053648788380846,11.519387744471613,57.19570677231715,0.0009775896818323433
0.0010399587442298,59.4698415783074,0.003301869012929615,11.989120062186773,59.531687760074725,0.0010394183617528174
0.0011334439581187,61.7681774556576,0.0035986845670268725,12.452464575060572,61.83818822319872,0.0011328020954801013
0.0012169119738338,64.0606602360946,0.0038636955169223147,12.914629103596672,64.13861642058761,0.0012161721366082177
0.0013282565261967,66.3601577783367,0.004217214470674522,13.378207808112679,66.44830109098523,0.0013273751738520443
0.001415161465331,68.6468611089715,0.004493137652425924,13.839207199568657,68.74400750152886,0.0014141610680491392
0.0015054854542771,70.8767224401619,0.004779916317329792,14.288747243936639,70.9834263148424,0.001504353347155336
0.0015712381938995,73.0374845711181,0.004988681265630912,14.72435688953741,73.15224385646259,0.0015700050906654456
0.0017103113650372,75.1836789353774,0.0054302385839931095,15.157029673372085,75.31226643592588,0.0017088504480659028
0.001840662046368,77.1761738785943,0.0058441019972184,15.55871665392461,77.31822913273652,0.0018389701038616286
0.0020093646824598,79.0554823098411,0.006379732866809865,15.937585233663965,79.21433360394931,0.002007348609478315
0.0022067169037072,80.7011046244512,0.007006326169270359,16.269342692289364,80.87918911617382,0.002204285679985366
0.0024086555507664,82.1454145619314,0.00764748137368332,16.560515575685372,82.34327457068599,0.0024057593896226566
0.0026732094988061,83.2810844426019,0.008487440158709367,16.78946662362854,83.50371222860473,0.0026696428291832007
0.002916400931654,84.160634545121,0.00925957295800145,16.966783924296394,84.40608069811698,0.002912156484793646
0.0032381819394248,84.7392653669141,0.010281227657673739,17.08343589796988,85.01366652558535,0.003232950319204638
0.0035367110360412,85.1213998549361,0.01122905753943081,17.16047421075512,85.42244964920633,0.0035304715806710094
0.0038735181979158,85.3940521239706,0.012298420278382663,17.215440908192473,85.72482753886656,0.0038660354431342917
0.0042277486515812,85.5782663377271,0.01342310196877031,17.252578493685782,85.94006973784109,0.004218836831378442
0.0045769183335732,85.7420044791634,0.014531715709094908,17.28558810299934,86.13443863142139,0.004566476092922476
0.0049452790239438,85.8610065114378,0.015701260901021565,17.30957891270586,86.2856131459135,0.004933091296258711
0.0053174664735816,85.9339047524766,0.01688295605362158,17.324275198099283,86.39085540994184,0.005303378667622571
0.0057143990350807,85.9900517672139,0.01814321693638122,17.335594436270323,86.481433236059,0.0056981337915582644
0.0060717344681737,85.977795296658,0.019277756936451496,17.33312353180625,86.4998296398583,0.006053375763754039
0.0064321885662508,85.9704639785456,0.020422198697846287,17.331645538074792,86.52344221398367,0.006411590322052097
0.0067891543172078,85.9974754598888,0.021555564957134767,17.337091052713586,86.58132559167629,0.006766211790734354
0.0071643209989447,86.0086013156982,0.02274671917164942,17.339334025244757,86.62479454419412,0.0071387791719322805
0.0075414985795315,86.001713142947,0.02394425799001251,17.337945369618115,86.6502949404518,0.007513203647533546
0.0079282028626811,85.9329585673779,0.025172044089012493,17.324084447183385,86.61425249549043,0.007896939793622128
0.0083052516441107,85.9034248436346,0.026369173970051472,17.318130448476733,86.61687440405193,0.008270952817741083
0.0087176521990981,85.8795456388786,0.027678545732136465,17.313316400797927,86.62821364877492,0.008679872875067501
0.0091187140805843,85.9047606388367,0.02895191720585515,17.31839974478948,86.6881015892633,0.009077389634572632
0.0095243487482279,85.8948308601822,0.03023980727562358,17.31639790141273,86.71292318496462,0.009479278091796722
0.0098881412765266,85.8539144665665,0.031394848552971956,17.308149156459805,86.70285010195474,0.009839573508440013
0.0102873935445428,85.8005044285756,0.032662474503923386,17.29738169280084,86.68316798395264,0.010234838440949684
0.0106667388479409,85.7260198613241,0.033866895842212356,17.28236560404294,86.64043692765824,0.010610250531479565
0.0110591045535871,85.6459642347113,0.035112656957639043,17.2662263897178,86.59313190777576,0.010998399806865148
0.0114582394632523,85.5851424159827,0.03637991029582605,17.253964711062114,86.56579747228159,0.01139309102276743
0.011879160924453,85.480649001476,0.037716335935138276,17.23289883869756,86.49608738689122,0.011809157534652495
0.0122753177590074,85.4432229575831,0.038974133884848494,17.225353748248754,86.49206566974115,0.012200586987082554
0.0126933933489013,85.3751571901612,0.04030152388276162,17.2116316895365,86.4588576426002,0.012613507535968927
0.0131199879040547,85.3082693961838,0.04165596159537367,17.198147110270654,86.42751285877758,0.013034666331153816
0.0135176163287522,85.2310124206384,0.042918431843788234,17.182572104000702,86.3831325458517,0.013427068434982668
0.0139157791843246,85.1358547396742,0.0441825989102306,17.16338831551832,86.32058649490024,0.013819843715859694
0.0142829372652326,85.0505455075866,0.045348325817113504,17.14618997432946,86.26531711344528,0.014181897080691265
0.0146938197239702,84.9746095704373,0.046652877623605385,17.130881289400158,86.22321116458005,0.014586911542230782
0.0151099804096374,84.8852676988282,0.04797418780059874,17.112869968083764,86.1678824308243,0.014996961707149125
0.0155157050135062,84.797162052014,0.049262363417882184,17.095107869686025,86.11284980439554,0.01539656722005127
0.0159672102365499,84.7240419720634,0.05069589250104593,17.08036686156798,86.07684856232162,0.01584107524627047
0.016385661452296,84.6629980710119,0.05202447511103979,17.068060411115997,86.05025729493988,0.01625286517457313
0.0168081635154492,84.5502418948869,0.053365919161551215,17.0453287660092,85.97137618592693,0.01666846949526927
0.0172118180214064,84.4643816254094,0.05464752221796532,17.028019335682536,85.91816719123658,0.01706537268690008
0.0176229337823984,84.3434936581221,0.05595281475911491,17.003648321477414,85.82987346183532,0.017469450478692538
0.0180399987437737,84.2633963929755,0.05727699601148149,16.98750071282386,85.78350795805086,0.017879208853271007
0.0184547396453381,84.1768387046785,0.058593798373948465,16.970050682863185,85.73030034714095,0.01828651745022454
0.0188775051214833,84.0489898151081,0.05993607876070947,16.944276346725793,85.63562505079831,0.01870153614273218
0.0192930114013349,83.9559204047436,0.061255311199238306,16.92551355359631,85.57568293432189,0.01910926089612195
0.0197117051830478,83.8679131417067,0.06258466395617676,16.90777128936807,85.52109271987348,0.019519945368003846
0.0201460688624242,83.7690796925136,0.06396376863819683,16.887846466010743,85.45669734054088,0.019945821810438434
0.0205644672091819,83.7055747974133,0.06529218338915253,16.87504387915852,85.42693534556042,0.020355873451986355
0.0209938488082633,83.6075172063093,0.06665546996623598,16.855275468791955,85.36276078177282,0.020776514490788774
0.0214381113760452,83.5201910535395,0.06806600361894351,16.837670516393565,85.31070621149385,0.021211547415702744
0.0218704752415863,83.4425106793691,0.0694387588920365,16.822010152960807,85.26743804327803,0.021634747195536205
0.0223319949760077,83.3300481332559,0.07090408404882444,16.79933770366439,85.19097434951824,0.0220862873428424
0.0227727917404691,83.2393380166848,0.07230361377598939,16.781050544163655,85.13493012595328,0.022517362341199998
0.0232054759620442,83.1504661721648,0.07367738617949034,16.763133980308424,85.08001231615573,0.02294032306845275
0.0236432031652931,83.0526264645399,0.07506717004980559,16.743409495251246,85.01625658545221,0.023368031491049525
0.0240632641418908,82.9485674478032,0.07640086365050328,16.72243119747713,84.94458073649113,0.02377830609748984
0.0245129589284235,82.8221545780097,0.0778286445977446,16.696946362926756,84.85237065154399,0.02421733764407478
0.0249569803012991,82.691602089458,0.07923841245662464,16.670626981234733,84.75533477388745,0.024650641271830965
0.0253997535843729,82.589021020083,0.08064421763038396,16.649946637648732,84.68676180276769,0.02508254005572456
0.0258328575754262,82.510272390081,0.08201932280197818,16.63407091384033,84.6417485052436,0.02550482663125312
0.0262699821460199,82.4002939012309,0.08340719331361317,16.611899250488147,84.56494815084302,0.025930852626387377
0.0267140446137647,82.2837011076921,0.08481709164870292,16.588394143310726,84.48183157006868,0.02636345460368678
0.027175403506568,82.1883970605114,0.08628190613335339,16.5691808473991,84.42189991418884,0.026812708482453387
0.027620683418652,82.0769674908144,0.08769566985422009,16.54671664614818,84.34398942584119,0.02724611393994618
0.0280825792875264,82.0110425099655,0.08916218923789632,16.533426170009044,84.31412411370431,0.02769549385291982
0.0285270036755843,81.8990395546849,0.09057323666998014,16.510846374224478,84.23537375708823,0.02812768516298404
0.0289917852753426,81.7863177756096,0.09204891824921274,16.488121663562897,84.15744913902101,0.028579473608523247
0.0294519751145228,81.6616215331039,0.09351002098860989,16.462982901073747,84.06671757830846,0.029026597650192356
0.0299015883148479,81.5750380432164,0.09493754289964208,16.445527669512426,84.01426124755271,0.029463252351408654
0.0303657056319447,81.5217867397752,0.09641111538142443,16.43479220673868,83.99725331850537,0.02991379323638135
0.0308216844664866,81.4026440766615,0.09785884818109496,16.41077304585496,83.91161068713008,0.030356236115831096
0.0312869424361653,81.3004476274596,0.09933604223482484,16.39017024169586,83.8440900524144,0.03080748099352915
0.0317425898843278,81.1862560552989,0.10078272288274076,16.36714922074826,83.76331808550627,0.031249207540273168
0.0322167763264248,81.1053937942895,0.10228826483639873,16.350847388928763,83.71834812502672,0.03170869958086557
0.0326927387025791,81.0290291795341,0.10379944538068862,16.335452282594076,83.67809005782426,0.032169700298930445
0.0331533631933412,80.9259142789007,0.10526192813885832,16.314664318626384,83.6088805067423,0.03261564300296139
0.0336270201514833,80.8241187432112,0.10676578898095947,16.294142338631378,83.54199301291504,0.0330739954919355
0.034087394346686,80.7294547610785,0.10822747705072804,16.275058079833425,83.48131152091233,0.03351929315933292
0.0345667025144689,80.5948231718864,0.10974928048343877,16.2479163514523,83.38072044867523,0.03398269414752855
0.035035342274547,80.4800472149971,0.11123721172168671,16.224777518543416,83.29969321544623,0.03443557325949885
0.0355126258101938,80.3696281366037,0.11275258694736531,16.202517032339305,83.22376466712333,0.03489659473927824
0.0359979695516745,80.2750727919465,0.11429355332656654,16.183454674856414,83.16481241806945,0.0353651839431647
0.0364624270063442,80.1984562009263,0.11576820574514284,16.16800877010674,83.12268655617407,0.03581340236337373
0.0369379352339138,80.0506841020098,0.11727794436767632,16.138217914965175,83.00759108680033,0.03627207715148109
0.0374213224491768,79.9611892464412,0.11881269877613633,16.120175752082545,82.95344269265192,0.036738136463263606
0.0378836901387725,79.8315689468425,0.12028071619060267,16.094044299683446,82.85588336811672,0.03718372657598571
0.0383721126580699,79.7591571327245,0.12183145768937191,16.07944607795726,82.8196844957341,0.03765421053817284
0.0388660721422849,79.6898507286791,0.12339977905175455,16.06547390690171,82.78708221610786,0.0381298030794039
0.0393670624972814,79.5926820145419,0.12499042342886843,16.045884694131647,82.72601210173461,0.03861193413231691
0.0398642191005182,79.5257519582892,0.12656889564414528,16.032391594791104,82.69598395848791,0.039090146072577034
0.0403463552590382,79.4236306775184,0.12809967794744628,16.011803944587708,82.62808469679621,0.03955369161272174
0.0408582606516082,79.3246335190586,0.129724977568856,15.991846117442213,82.56570007147359,0.040045623447755904
0.0413687378749922,79.2305380847112,0.13134574275310024,15.972876477877778,82.50820544643221,0.04053594197111811
0.0418885677658484,79.1203136592375,0.13299620265656867,15.95065523370228,82.43455027960765,0.04103499688885442
0.0423940147351476,79.0197869198084,0.13460099678409362,15.930389043033372,82.36975293085497,0.041520004999991394
0.0429006466840124,78.9187038792216,0.13620955322173936,15.910010702051075,82.30436731110429,0.04200591422731223
0.0433933548876081,78.8138687001319,0.1377739017681557,15.888875929946591,82.23386687470209,0.04247824287551289
0.0439065210266462,78.6836217535293,0.13940320425960168,15.862618145511506,82.13834584650331,0.04296994620506194
0.0444255947329973,78.5541808632218,0.14105126327726641,15.836522862025516,82.04399706683387,0.043467064180812524
0.0449315729786653,78.4670427152023,0.14265774420726232,15.818955811384784,81.99269037138045,0.04395140286964797
0.0454519743039662,78.3596737012526,0.14431001841509267,15.797310218172525,81.92127557678911,0.044449303206386064
0.0459405234666769,78.2883630795485,0.14586116200669916,15.782933996836977,81.88497146077223,0.04491650309556803
0.0464543946587251,78.1819671172123,0.14749270304145218,15.761484570829998,81.81386307287073,0.04540768303290004
0.0469746856368414,78.0535300700391,0.14914462689697144,15.735591662119882,81.72007010792494,0.04590475359882114
0.0474787158455642,77.9763675532649,0.15074492280966634,15.720035698738203,81.67858535099563,0.0463860536058741
0.0480103631300773,77.8489530766777,0.15243290293799544,15.694348940258227,81.58650958318535,0.046893474332857815
0.0485108675869066,77.7582657494832,0.15402200458842844,15.676066375095814,81.53038668304387,0.04737093619587603
0.0490394138657049,77.6842003667997,0.15570013902361304,15.66113479394682,81.49378801941353,0.04787490150689492
0.0495748186809384,77.5878425315425,0.15740004931197943,15.64170905435897,81.43424575688893,0.04838514757169922
0.0501138964998924,77.5384616340367,0.15911162138715837,15.631753865421798,81.42421607512568,0.04889863114371743
0.0506682662240202,77.4502589726333,0.16087174526126413,15.613972208882874,81.37452931337799,0.049426405747703045
0.0512208357795117,77.3422497110772,0.16262615359994964,15.592197541753166,81.30378438234627,0.049952189498800655
0.0517752922714715,77.2504984638136,0.164386552961922,15.573700490304823,81.25016559989442,0.05047949099727834
0.0523055239313752,77.1389078775866,0.16607003848211624,15.551203828121459,81.17369886961785,0.05098349413921525
0.0528603562104119,77.0267188952719,0.16783163096805778,15.528586529286816,81.09837869379524,0.051510609172873374
0.0534106279273594,76.9133940344427,0.1695787436693661,15.505740237343648,81.02138670584671,0.052033117182156946
0.0539789872200637,76.7939206515307,0.17138328442370224,15.481654403348589,80.93917871295827,0.05257251369659303
0.0545311109324075,76.7046557282972,0.1731362772103938,15.463658594824714,80.8874458188491,0.053096223519417146
0.0550948643409097,76.5927727443277,0.1749261942823883,15.441102985256466,80.81264116817057,0.053630681692125745
0.0556351973276565,76.5056963010555,0.1766417515153094,15.423548374292789,80.76210581145448,0.05414266852394529
0.0562209251408056,76.3945644232954,0.17850143732205778,15.401144187736355,80.68953751090196,0.05469737281647388
0.0567689364368664,76.2900369007898,0.18024137318705083,15.380071439199224,80.62094115637693,0.055216079809169774
0.0573340481303983,76.1750356668052,0.1820356028140146,15.356887190427928,80.54245882806062,0.05575069114184058
0.0578849103781617,76.018570759476,0.1837845904506634,15.325343865110362,80.41889891496423,0.05627154715818939
0.0584104978765124,75.8459317538765,0.18545333075792686,15.290539841581504,80.2761303895284,0.056768252398021565
0.0589630131833613,75.6887822828834,0.18720756685717213,15.258858508229293,80.15162095046162,0.057290139836873165
0.0595043792176805,75.6215051830667,0.18892640401613559,15.245295444906247,80.1213159044917,0.05780123200477295
0.0600463888266438,75.5654829622254,0.19064728452459406,15.23400136518464,80.10291733404831,0.0583126702104053
0.0606068230785119,75.496378163533,0.19242666327427527,15.220069837768252,80.07197379795868,0.05884121892527202
0.0611869214260265,75.4473584882956,0.19426847552763413,15.210187471240395,80.06375008392021,0.059388018880235316
0.0617843233277879,75.3430659184817,0.19616522656572657,15.189162089165912,79.99808626369601,0.059950816816388385
0.0623724724986563,75.2369174293025,0.19803260018323374,15.167762553747382,79.92962999254534,0.060504588729134445
0.0629585452432111,75.1119579071229,0.1998933811471952,15.142570714075978,79.84089750732467,0.06105610070963784
0.0635423502174245,75.005403073318,0.2017469619403228,15.121089259580911,79.77142266360188,0.06160517641435733
0.0641440799777205,74.9077673443056,0.20365745392926257,15.10140589661201,79.7126571637912,0.06217079526476564
0.0647371275076227,74.8257335754626,0.20554037983670206,15.084867888813262,79.66973663078873,0.0627279400628481
0.0653413894210877,74.7034711562269,0.20745891141195347,15.060219785095342,79.58469975615292,0.06329530124213972
0.0659168245378828,74.5959444574383,0.2092859179077779,15.038542402619562,79.51307223947691,0.0638352969376486
0.0665215793614437,74.4976320147744,0.21120601447258375,15.018722614178518,79.45333215508485,0.06440249253745417
0.0671274016496013,74.396652484814,0.21312950023748414,14.998365140938501,79.39070645754792,0.06497036692525622
0.0677333774844952,74.2980586435525,0.21505347351327225,14.978488622540183,79.3305170960214,0.06553806282101779
0.0683408290010576,74.1678648062382,0.21698213207835787,14.952241544937621,79.23655817233488,0.06610681790554905
0.0689380914263,74.0613707796017,0.2188784402785025,14.930772349167704,79.16702032956299,0.06666571776188615
0.0695399004574725,73.9375963050056,0.22078918395247518,14.905819415089129,79.07920939212048,0.06722855642503234
0.0701500914953621,73.8294429592132,0.22272654049777466,14.88401570057738,79.00858513785361,0.0677989110621301
0.0707267353363813,73.6823329692743,0.2245573846930106,14.8543583266057,78.89364383215927,0.06833760983053841
0.0713196755646498,73.5663247125962,0.2264399699177631,14.830971062059394,78.81305112358224,0.06889123018198894
0.0719274012966386,73.4539603829152,0.22836949911682755,14.808318413195705,78.73731286820454,0.0694583376842806
0.0725270810369123,73.3268245817623,0.23027348229219655,14.78268783568328,78.64500513038323,0.07001762188531682
0.0731361471920557,73.2354733352191,0.23220726733477684,14.76427142438017,78.59163369274356,0.07058534021453931
0.073741447943169,73.0935307679657,0.23412909721956157,14.735655802821887,78.48355356207408,0.0711492296216708
0.0743347622201499,72.9580056313538,0.23601287004897592,14.708333935280926,78.38132163201685,0.07170164418616515
0.0749523464990621,72.8252319392434,0.23797370013452215,14.681566758951469,78.28365395742813,0.0722763317589923
0.0755529744990572,72.6986582202651,0.23988069403450657,14.656049497205444,78.19125809089647,0.07283492420677486
0.0761649716211961,72.5939212728207,0.2418237848972976,14.634934528600652,78.12303522643643,0.07340376933793621
0.0767628617334531,72.4960915146299,0.2437220860037136,14.615212049349386,78.0610989637832,0.07395918983867424
0.0773766181559618,72.3662853097026,0.24567076264517868,14.589043118436045,77.96574373547685,0.07452902892741181
0.0780020376446147,72.2635090093062,0.24765646952165168,14.56832341627613,77.90020995938205,0.07510936269338137
0.078618639723135,72.1358903715481,0.2496141811209536,14.542595498904097,77.8071159477764,0.07568118517639154
0.079237135157094,72.0200601549731,0.25157790412377345,14.519244127242576,77.72672339549473,0.07625443521292892
0.0798541348448756,71.8945526076177,0.25353687813248,14.493941805695728,77.6356299061584,0.0768259716858419
0.0804603454327639,71.7669354911797,0.25546159674902535,14.468214195021826,77.54132791145089,0.07738719609028333
0.0810411707944973,71.509615376177,0.2573057172725289,14.416338459837283,77.30483832932657,0.07792462377317214
0.0816451368680975,71.3102056837955,0.25922330955620954,14.376137465853175,77.13233718694117,0.07848315700766047
0.0822505914389854,71.1326312872674,0.26114562781877865,14.340338467513108,76.98333228125642,0.07904275382997265
0.0828660925843711,71.0208566365094,0.2630998439553782,14.317804697920295,76.90607751797174,0.0796113154844167
0.0835021077138588,70.9737444990318,0.2651191919915017,14.308306891004811,76.90020175704585,0.08019848727513397
0.08411907682754,70.8736140178754,0.26707806892743946,14.288120586003682,76.83543700049047,0.08076774645634335
0.0847440314985783,70.7071582356725,0.2690623000079861,14.254563100311575,76.69916788037129,0.08134404349043077
0.0853548277115112,70.5386170429519,0.27100157798404806,14.220585195859103,76.55942854766133,0.08190696367857768
0.085958592497198,70.3055147177289,0.27291853117860365,14.173591767094146,76.34887780765591,0.08246309232921682
0.0865709467103124,70.1367064420339,0.2748627558052419,14.139560018714036,76.20850751786404,0.08302681698131455
0.0871816917441106,69.9822859152166,0.2768018712875511,14.108428840507665,76.08345999342522,0.08358874388970768
0.0878118707150274,69.8399297770667,0.278802689520212,14.079729843056649,75.97270466139707,0.08416822053683717
0.088428090502699,69.6999102802524,0.2807591873460693,14.051501912498884,75.86334025454455,0.08473453658205485
0.0890499236820657,69.5185543381018,0.28273350769055855,14.014940554561322,75.70917629639729,0.08530568650156717
0.0896842943294581,69.3562849400399,0.28474763449602947,13.982227043912044,75.57645441220019,0.08588801605794416
0.0902959649126578,69.1796048515917,0.2866896885976885,13.946608338080887,75.42624402394256,0.08644918682695317
0.0909113384854046,68.9681777184842,0.2886434996911596,13.903984628046414,75.23816706777086,0.08701343726579491
0.0915335644446547,68.743045605005,0.29061906711177865,13.858597993969006,75.03534160001256,0.08758364728601023
0.0921619601035166,68.5506594524462,0.2926142233286652,13.819812945613153,74.8684225939723,0.08815918143822477
0.0927735821527668,68.3493235404928,0.2945561233350346,13.77922362576335,74.69033512306275,0.08871903508461108
0.0933570808895009,68.1517115313395,0.29640873182416533,13.739385044718045,74.5141563775287,0.08925285381782293
0.0939717711478054,67.9420817619829,0.2983603733942821,13.697123683215755,74.32671952062545,0.08981490032849132
0.0945859575937712,67.7148542733388,0.3003104153602235,13.651314621505103,74.11972860810523,0.09037617084379339
0.0951924984043436,67.4898792209571,0.3022361824337909,13.605959650944953,73.91440944100741,0.09093014544740909
0.0958071355957758,67.2821271106316,0.30418765551658816,13.564076825503333,73.7282349858921,0.09149120186934304
0.0964062364019125,67.0403763691195,0.30608980057607216,13.515339876014492,73.50348674183402,0.09203777350210841
0.0970309127584002,66.8023649261678,0.3080731480079206,13.46735676911543,73.2842593693736,0.09260736025650017
0.0976455680833448,66.5642563012818,0.31002467866461975,13.41935407033841,73.06396092186583,0.09316749323863294
0.0982602506917569,66.3039081809783,0.31197629594632814,13.366867889285224,72.81894682068446,0.09372733748988572
0.0988647234925645,66.0381436282989,0.3138954970888923,13.313289755465057,72.56698643807293,0.09427757730160433
0.0994603078980769,65.7628293988171,0.31578647757639416,13.257786406801529,72.30362065907215,0.09481943022287845
0.0997607074030118,65.6092425250432,0.3167402460045624,13.22682329304871,72.15446697151728,0.09509261741480969