File: example/data/02 processed data/test_ID_094.csv
Strain,Stress_MPa,Displacement(mm),Force(kN),True Stress (MPa),True Strain
0.0006398491389772658,38.3440504691419,0.002031521016252819,15.460321149158013,38.368584876819476,0.000639644522794537
0.0007319444547707659,43.5407014253308,0.0023239236438971815,17.55561081469338,43.57257080029591,0.0007316767140680198
0.0008214335871758658,48.8914017752194,0.0026080516392833738,19.713013195768465,48.931562814761676,0.0008210963952480465
0.0009117143188743658,54.3832573728733,0.0028946929624261114,21.927329372742516,54.43283936732718,0.0009112989598147888
0.0010019473168828659,59.9446874155693,0.003181182731103099,24.16969796595754,60.004748834286715,0.0010014457027027563
0.0010967717022182658,65.5949185821264,0.003482250154542994,26.447871172313363,65.66686123263659,0.0010961706875453913
0.0011901769794365657,71.2318566581661,0.003778811909711096,28.720684604572572,71.31663517416317,0.001189469280284442
0.0012828313027741659,76.8881153594145,0.004072989386307977,31.001288112915926,76.98674984060887,0.0012820091777218797
0.0013827488743034658,82.4847488871763,0.004390227675913504,33.25785075130948,82.59880458084724,0.0013817937574352283
0.0014765187076147658,88.0901443720976,0.004687946896676881,35.51794621082975,88.22021111821948,0.001475429725670721
0.0015683781349721659,93.7021431152669,0.004979600578536626,37.78070410407562,93.84910350772893,0.0015671495144450633
0.0016618193509470658,99.3283748706639,0.005276276439256934,40.049200747851685,99.49344068612209,0.0016604400570495075
0.0017560381056844659,104.937080517397,0.005575420985548179,42.31063086461448,105.12135402948483,0.0017544980734101566
0.001850135978450066,110.569833945604,0.005874181731578959,44.58175704686754,110.77440317351801,0.0018484265849627636
0.0019435785884999658,116.132107611408,0.006170862018487391,46.82446578891971,116.35781948919892,0.0019416922833612573
0.002037798049152066,121.726606072883,0.006470008806057809,49.08016756858643,121.97466031326823,0.0020357245551377978
0.002132427611021066,127.332742946529,0.006770457664991884,51.340561956040496,127.60427080337521,0.002130157214327761
0.002227118124715866,132.926967714748,0.007071100045972873,53.5961533825864,133.22301177380902,0.0022246417732150166
0.002319175023059966,138.529372622921,0.007363380698215392,55.85504304156174,138.85064648386825,0.0023164898873978997
0.0024070700699015657,144.247777516109,0.007642447471937471,58.16070389449516,144.59499202401784,0.002404177717208023
0.002496565881877066,149.962526219773,0.007926596674959683,60.464890571812475,150.33691754629336,0.0024934546384825346
0.002581842348054666,155.678366097098,0.008197349455073564,62.76951721034992,156.08030309536343,0.0025785151187899535
0.002662655763045866,161.377927927207,0.008453932047670623,65.06758054024986,161.80762179703078,0.0026591171751587377
0.0027476607554856656,167.072886115847,0.008723822898666987,67.36378768190951,167.53194572833326,0.002743892836070256
0.0028335783052795657,172.703856946435,0.00899661111926262,69.63419512080259,173.1932268487165,0.0028295712899498978
0.002916656296291666,178.2850100162,0.009260383740726038,71.88451603853184,178.80500611319817,0.0029124111068188816
0.0030008403561424656,183.682819057812,0.009527668130752329,74.06091264410979,184.2340218739707,0.002996346822062209
0.003084104855278766,189.074389670795,0.009792032915510082,76.23479391526455,189.65751491398757,0.003079358759700018
0.003169460850337566,194.400310859225,0.01006303819982177,78.38220533843952,195.01645503378677,0.003164448697053333
0.0032527406618096657,199.632718480692,0.010327451601245688,80.49191209141502,200.28207194152176,0.0032474619446710164
0.003336272990222366,204.736347671611,0.01059266674395601,82.54969538119354,205.41940401846458,0.0033307199789696907
0.003420356505983466,209.736097824614,0.010859631906497504,84.56559464288438,210.45347005134798,0.003414520390613291
0.003503058415850666,214.53724082636,0.011122210470325864,86.50141550118835,215.28877731335015,0.003496936998341483
0.0035861802202462657,219.191373909532,0.011386122199281893,88.3779619603233,219.977433679095,0.003579765208311601
0.0036699233332651657,223.659320798155,0.0116520065831169,90.17943814581609,224.48013335825436,0.003663205595334527
0.003753281142861266,227.959935858553,0.011916667628584518,91.91344613816857,228.8155335871388,0.0037462551580358756
0.0038384974323505657,232.081096375524,0.012187229347713045,93.57509805861127,232.97193906805856,0.003831149199194958
0.003918243468393666,236.073103781454,0.012440423012149888,95.18467544468226,236.99809567840913,0.003910587145496424
0.003999497992017466,239.979806397369,0.012698406124655453,96.75985793941918,240.93960515118002,0.003991521261461738
0.0040811989639447654,243.818412151881,0.01295780671052463,98.30758377963843,244.8134836029459,0.004072893461389858
0.004159283781376666,247.691648951526,0.013205726005870914,99.86927285725528,248.7218688097925,0.004150657870724536
0.0042405985579794655,251.493267218341,0.013463900421584803,101.4020853424351,252.55974920464863,0.004231632558447081
0.004321361526857366,255.306411622629,0.013720322847772136,102.93954516624403,256.40968292737506,0.0043120512565270235
0.004403675675011566,259.029798373784,0.01398167026816172,104.4408147043097,260.1704815959858,0.004394007867487607
0.004492274506789766,262.823527259275,0.014262971559057504,105.9704461909397,264.0042026905664,0.004482214359045776
0.004582912842409066,266.731216904281,0.014550748274648783,107.54602665580609,267.95362282370303,0.0045724432725793495
0.004685592593373366,270.758245222601,0.014876756483960436,109.16972447375272,272.02690805101076,0.004674649374726303
0.004800522141291666,274.737171836964,0.015241657798601038,110.77402768466389,276.05605371340323,0.004789036378648302
0.0049354908413361655,278.734324303516,0.015670183421242323,112.38567955917766,280.11001500828206,0.004923351233311311
0.005096866190004966,282.714555511342,0.016182550153265765,113.9905087821731,284.1555137707501,0.005083921135035633
0.005288269603790766,286.768653208663,0.01679025599203568,115.62512097373292,288.28516316074644,0.005274335808280328
0.005511048094358066,290.549892086612,0.017497577699586857,117.14971648932195,292.15112651571184,0.0054959178324216745
0.005764882385056466,293.93146076355,0.018303501572554278,118.51316497986336,295.6259410641197,0.005748329038859705
0.006044811023708666,296.880392897216,0.019192275000275014,119.70217441615749,298.674978768924,0.006026614446645318
0.006353237845243066,299.398436686107,0.020171530158646735,120.71744967183835,301.3005861648678,0.006333141104353846
0.006677945170688566,301.473414288015,0.021202475916936196,121.55408064092767,303.4866372190507,0.006655746467848713
0.007011112845737966,303.110852200745,0.02226028328521804,122.21429560734039,305.23599659029225,0.006986649272095526
0.007354831724939666,304.3370898599,0.023351590726683438,122.70871463151168,306.5754379434774,0.007327916839157036
0.007700861961018365,305.312479118483,0.02445023672623331,123.10199158057235,307.66364837515073,0.007671361678487568
0.008051276789926867,306.047789727921,0.0255628038080178,123.39846881829773,308.5118651939658,0.008019038186627457
0.008403927084265767,306.598240032473,0.02668246849254381,123.6204103810931,309.1748692858701,0.008368810695589425
0.008757214426011866,307.045002017699,0.02780415580258767,123.80054481353623,309.7338609388033,0.008719092423794832
0.009111839179059666,307.414047163823,0.02893008939351444,123.94934381645344,310.21515452296364,0.009070576833613241
0.009473062481656466,307.747920303474,0.030076973379259277,124.08396146636073,310.6632355811086,0.009428474394578138
0.009831476953378066,308.004467892079,0.031214939326975357,124.18740145408626,311.0326067196974,0.00978346242980121
0.010188729825875065,308.162838298746,0.03234921719715333,124.2512564020544,311.3026262005468,0.010137174610523839
0.010547856701570766,308.357783940376,0.03348944502748718,124.32985848475961,311.61029765819296,0.010492616167697422
0.010907567606225965,308.571057984313,0.03463152714976744,124.415850579275,311.93681766060155,0.010848509158585689
0.011271190241519766,308.720673158936,0.03578602901682525,124.476175417683,312.2003225976004,0.011208143674378768
0.011636831839232765,308.914848301248,0.03694694108956403,124.5544668350632,312.50963844357176,0.011569644640022237
0.011999747326586065,309.088279856542,0.03809919776191076,124.62439443815772,312.7972611164296,0.011928321187956111
0.012366969967768366,309.253152992031,0.03926512964766456,124.69087128638691,313.0776774475211,0.012291123680284365
0.012742488993716666,309.462947151819,0.04045740255505041,124.77546029161341,313.40627534986413,0.012661986626571585
0.013119020958244465,309.592351254902,0.04165289154242617,124.82763602597649,313.65389979952727,0.013033711906916736
0.013499545996286366,309.729505058978,0.04286105853820921,124.88293643977994,313.9107127589287,0.013409238953513774
0.013875771739931667,309.967510493953,0.04405557527428304,124.97890023116184,314.26854891636196,0.01378038458666086
0.014255061735442266,310.155243165108,0.04525982101002919,125.05459404417155,314.5765253039977,0.01415441371108623
0.014637836223897166,310.283280364797,0.0464751300108735,125.10621864308617,314.8251562057905,0.014531737219272806
0.015018400688256266,310.423090621047,0.04768342218521364,125.16259013840615,315.0851489788808,0.014906741086329514
0.015399596285817666,310.56924469764,0.048893718207471085,125.22151946208844,315.35188568477497,0.015282225939801296
0.015779255927681864,310.76122323728,0.05009913757038992,125.29892520927129,315.66480411114054,0.01565605776251043
0.016155259771116766,310.935480103161,0.05129294977329573,125.36918557759454,315.9587235562845,0.016026152216659012
0.016535757786281965,311.064587038233,0.052501030971445234,125.42124149381556,316.20827570538705,0.016400530827399937
0.016913625234018865,311.195689990726,0.053700760118009894,125.47410220426073,316.4591372656711,0.016772182519585368
0.017288337164287966,311.377853129653,0.05489047049661429,125.54755038187608,316.7610584400506,0.017140594251983356
0.017661959910591066,311.582387775562,0.05607672271612663,125.6300187511066,317.08554341730024,0.01750780002702217
0.018032544261235565,311.768829177192,0.057253328029422915,125.7051919242438,317.3908143886033,0.01787188643977078
0.018400908791768866,311.939510476001,0.05842288541386615,125.77401062392359,317.6794809568189,0.01823366063278343
0.018771677280304065,312.123158570936,0.0596000753649654,125.8480575358014,317.98223377533884,0.018597663658510344
0.019139062558068166,312.312426936411,0.06076652362186642,125.92437054076092,318.289794013209,0.018958214564457256
0.019504964081706565,312.488260510344,0.06192826095941834,125.9952666377707,318.58333280755323,0.01931718015412005
0.019870715827911768,312.666515994104,0.06308952275361986,126.06713924882274,318.879423482326,0.019675870074500626
0.020238605955008766,312.84851315213,0.06425757390715282,126.14052050293881,319.18013093342637,0.020036527346301503
0.020603918415297167,313.044952685015,0.0654174409685685,126.21972492259806,319.4949053504576,0.02039452896556183
0.020968830901900867,313.249554013759,0.06657603811353525,126.30222017834764,319.81803094196937,0.02075201070664798
0.021332902424270765,313.422924348401,0.06773196519705968,126.37212309727529,320.10914501105503,0.0211085413017951
0.021699384777268165,313.584764472611,0.06889554666782642,126.43737703535677,320.3893609371912,0.021467304459111877
0.022062952986109666,313.761543446224,0.07004987573089819,126.50865431751751,320.6840496281272,0.02182308771821077
0.022424246890873866,313.962204867664,0.07119698387852452,126.58956100264213,321.0025708640197,0.022176520020009482
0.022786532753358967,314.162322517738,0.07234724149191471,126.67024843915196,321.3209925696598,0.022530797310037542
0.023150884893476067,314.320755865802,0.07350405953678651,126.73412876509137,321.5975595044816,0.02288696865802326
0.023513380120611264,314.49060795472,0.07465498188294076,126.80261312734312,321.8853451639215,0.02324119894104747
0.023871457910544364,314.643424158001,0.07579187886597835,126.864228620506,322.15442141461824,0.023590989353609444
0.024226757899765465,314.840133926863,0.07691995633175534,126.94354199931117,322.4676896286389,0.023937945363865776
0.024586590209521964,315.038787443529,0.07806242391523223,127.02363909723088,322.7845170105077,0.02428920460745503
0.024947681742108367,315.166962744885,0.07920888953119407,127.07531937873763,323.0296478270713,0.02464156908485284
0.025305072363172865,315.292580071226,0.08034360475307384,127.12596828471831,323.27108162549985,0.02499019988070843
0.025657972941441665,315.483237583494,0.08146406408907728,127.20284139366477,323.5778979568897,0.02533433146568204
0.026012153924420064,315.674683291921,0.0825885887100337,127.28003230330255,323.886061743753,0.025679592608649254
0.026368031297717667,315.903664521808,0.0837184993702536,127.372357535193,324.23342223498275,0.026026387397866963
0.026724146998746867,316.027885992028,0.0848491667210213,127.4224436319857,324.4734616729822,0.02637329408658279
0.027075029928221667,316.16802192699,0.08596322002210378,127.47894644096236,324.72828058300985,0.026714985656849776
0.027424749687776865,316.388234774549,0.08707358025869154,127.56773626109816,325.0651029173986,0.0270554283927437
0.027776498220413864,316.625424307783,0.08819038184981401,127.66337108089813,325.42016984260596,0.027397729212606976
0.028132385522064565,316.807163432917,0.08932032403255499,127.73664829615213,325.71970469076354,0.02774393843230509
0.028487480786789365,316.94693486978,0.09044775149805623,127.79300413949532,325.9759545873147,0.028089257734204877
0.028843960738077466,317.104143631153,0.09157957534339595,127.85639071208091,326.2506830999317,0.028435803699196738
0.029199288334977865,317.353040627393,0.09270774046355472,127.95674598096487,326.6195235646542,0.028781109951231124
0.029551578620475066,317.589981205063,0.09382626212000833,128.05228042188142,326.9752665037196,0.029123346881974096
0.029904307139263064,317.777137836928,0.09494617516716022,128.12774197584937,327.2800429686394,0.0294658922355076
0.030253506661381765,317.930160561243,0.0960548836498871,128.18944073829317,327.54866279163673,0.02980489493046988
0.030601631363398767,318.087710819558,0.09716017957879108,128.2529650024458,327.8217136872855,0.030142739836601255
0.030950292551193567,318.260720871137,0.09826717885003958,128.32272265524244,328.11098328965244,0.030480991022103294
0.03130260163296557,318.424413433133,0.09938576018466568,128.3887234962392,328.3919259970411,0.03082266500999591
0.03165397053594846,318.552430899502,0.10050135645163637,128.4403401386792,328.6358801613496,0.0311633109655345
0.032012002597811964,318.673433012756,0.10163810824805299,128.4891281907432,328.87480777821395,0.03151029741597446
0.03236572924971537,318.810772846785,0.1027611903678463,128.54450361182373,329.12931600263653,0.031852993086353164
0.03271908744527437,319.014705768515,0.1038831026387461,128.62672936586526,329.4525758228835,0.03219521457396568
0.03307215063210057,319.178992698109,0.10500407825691929,128.69296985587758,329.73492842322304,0.032537033421636385
0.033423652757397164,319.358251360709,0.10612009750473599,128.76524694863787,330.0323706593989,0.03287722489757365
0.03377093307792227,319.50760802884,0.1072227125224032,128.8254675572283,330.297678077469,0.033213216802904455
0.034115467950928964,319.687741951008,0.10831661074419946,128.89809755464643,330.59403886584244,0.03354644098390715
0.034459695742418764,319.884702885567,0.10940953398217956,128.9775122034606,330.90783241965767,0.033879257311502035
0.03480554942817626,320.058274247486,0.11050761943445964,129.04749617658635,331.19807833170364,0.03421353411800148
0.03515339125445577,320.168473741495,0.11161201723289706,129.0919286125708,331.4234813662717,0.034549619846773384
0.03550184956285556,320.341907633214,0.1127183723620664,129.1618571577119,331.71463784668657,0.03488618800628193
0.035853690965060366,320.53268038807,0.11383546881406666,129.23877673246983,332.02496005490633,0.035225908926910514
0.03620623720046687,320.715757779604,0.1149548031114823,129.31259353673636,332.32766857969983,0.03556619468217861
0.036559443079329866,320.868770637259,0.11607623177687232,129.37428832094284,332.5995541933064,0.03590700106048003
0.03691119134100546,321.008611898501,0.11719303250769234,129.4306723174756,332.8574221943971,0.036246285600333765
0.03726461821462307,321.171484785745,0.11831516283142823,129.4963426656124,333.1398175477094,0.03658707337291299
0.037617366320034165,321.352231703765,0.11943513806610846,129.56921982295805,333.44065632152603,0.03692709088854888
0.03796686976873027,321.490626212706,0.1205448115157186,129.62502048896306,333.6966189499914,0.03726386686316137
0.03831838190499606,321.60789290321,0.12166086254836249,129.67230241857425,333.9313869671363,0.03760246401819179
0.03866690861216147,321.780621589219,0.12276743484361265,129.7419466247731,334.2228834773738,0.03793807227890292
0.03901603494788257,321.933899694268,0.12387591095952714,129.80374835672887,334.49448397564765,0.03827414505659915
0.039364719369482264,322.078680300218,0.12498298399810619,129.86212389704792,334.75721716512925,0.03860967975027514
0.03971014681157787,322.217559727871,0.12607971612675972,129.9181200822776,335.0128663299331,0.03894196931896072
0.040056175392527864,322.296624684246,0.12717835687127596,129.949999072688,335.2065948110179,0.03927472649504211
0.040403872252342064,322.444968164797,0.12828229440118605,130.00981116404614,335.47299346693796,0.039608976473497516
0.040750313310545266,322.576259167936,0.1293822447609812,130.0627476965118,335.72134279557304,0.039941908135943865
0.04109963874850347,322.728482724365,0.1304913530264985,130.12412423446398,335.992506778189,0.040277499508310576
0.04145067671198106,322.921094924589,0.13160589856053986,130.20178547359427,336.3063928337871,0.04061462266369974
0.041798320624915064,323.095336272188,0.13270966798410533,130.27203958494619,336.60017873010764,0.04094837433390851
0.042149767431655966,323.251736962002,0.13382551159550768,130.3351003430792,336.8767224968292,0.04128566374345471
0.04250088578933427,323.441775526848,0.1349403123811363,130.41172389242513,337.1883374880141,0.04162252436847701
0.04284928740876687,323.573427586596,0.1360464875228348,130.4648060029155,337.4383183830939,0.04195666644893145
0.04319030057892707,323.726995976675,0.13712920433809342,130.52672477779538,337.70886223842075,0.042283614389096766
0.043534637794015965,323.833436731043,0.13822247499600068,130.56964168995654,337.93140810472033,0.042613640845274275
0.04388004427222696,323.912906899304,0.1393191405643206,130.60168406179938,338.12621959439116,0.04294458273653422
0.044227153760134565,324.035068779239,0.14042121318842724,130.65093973178918,338.3662175898142,0.043277046023315696
0.044572542190247366,324.189858140864,0.14151782145403538,130.71335080239638,338.63982427049797,0.043607751197134136
0.044919934321241764,324.349147488775,0.14262079146994258,130.77757626747407,338.9188898911215,0.043940264607065356
0.045270470767122865,324.507641268158,0.1437337446856151,130.8414809593213,339.1982549558961,0.04427567562829466
0.04562505054664437,324.644099101718,0.14485953548559585,130.8965007578127,339.4560025329037,0.044614841100032755
0.045973177909735964,324.764674706887,0.1459648398634117,130.94511684181683,339.6951388759842,0.044947722780242456
0.046322217284830464,324.91965494497,0.1470730398793367,131.00760487381189,339.97065380144306,0.04528136532338829
0.046671533032889165,325.072392388625,0.14818211737942308,131.0691886110936,340.244019288071,0.045615160635723906
0.047022257147078465,325.141959950685,0.14929566644197412,131.0972382521162,340.4308688007912,0.0459501896825835
0.047374462181844865,325.251685024109,0.15041391742735744,131.14147940172074,340.66030867586494,0.046286520459686065
0.04772818554268737,325.348756619169,0.15153698909803237,131.18061866884895,340.8770624411714,0.0466241873177636
0.04808460388429977,325.481345143349,0.15266861733265175,131.23407836179834,341.131986696296,0.046964311537680895
0.048438954126159166,325.650233977879,0.15379367935055535,131.30217433988082,341.4243907227065,0.04730234756296648
0.04878992330422187,325.748473154015,0.15490800649090442,131.34178437569886,341.64171617566683,0.047637045587694396
0.049142351789473265,325.821240323935,0.1560269669315776,131.3711240986106,341.8328623364163,0.047973022580613166
0.049491858083467864,325.969771381532,0.15713664941501046,131.4310118210337,342.1026210462472,0.048306102347998495
0.049836495774073564,326.049439309232,0.15823087408268355,131.46313392948235,342.29860081350563,0.048634433733671
0.05018062426895566,326.136690814942,0.15932348205393423,131.49831373658463,342.50243355704725,0.04896217248844406
0.050522290179582464,326.220558103638,0.16040827132017432,131.53212902738684,342.7019678026953,0.049287459716152
0.05087035253746187,326.304532473222,0.16151336930644142,131.56598749320312,342.9037590747065,0.04961872799413766
0.051221243976974265,326.425171493388,0.1626274496268933,131.61462914613406,343.14507484267654,0.049952577806727565
0.05157332400099487,326.534430292141,0.1637453037031587,131.65868229379126,343.37489626307786,0.050287446493067274
0.051926608381754565,326.640331332315,0.16486698161207072,131.7013815931894,343.6016558990947,0.05062334798623389
0.05228027460532406,326.765029417466,0.1659898718719039,131.7516598611223,343.8483948868279,0.05095949955931278
0.05263098898655556,326.942951234465,0.1671033900323139,131.82339793773627,344.1502821001181,0.05129273392462119
0.052983100402283066,327.056260952288,0.16822134377724873,131.86908441596253,344.3847156635184,0.0516271840223711
0.053334995447135464,327.152811303541,0.1693386105446551,131.90801351758773,344.6015050049329,0.05196131688560727
0.053684401468363965,327.251011486637,0.17044797466205558,131.94760783141206,344.8192861682138,0.05229297593434967
0.054033332565746765,327.368498022112,0.17155583089624596,131.99497840251559,345.0573089472898,0.05262407444430298
0.05438497781819407,327.446900649335,0.17267230457276617,132.02659034181187,345.25509307778555,0.052957637527089804
0.05473764228334207,327.537354730797,0.17379201424961105,132.06306142745737,345.4659772884835,0.05329205570180707
0.05509153050745146,327.582972514943,0.17491560936115838,132.081454518025,345.63001983897163,0.05362752193954055
0.055445602541354964,327.672755679312,0.176039788068802,132.1176550898986,345.84076905433767,0.05396304983116665
0.055797922632290865,327.761861201474,0.17715840435752347,132.1535824364343,346.0502921746095,0.05429680582852599
0.05615301831821316,327.849900745478,0.17828583316032678,132.18907998057674,346.25966222766317,0.054633078496970196
0.05650916972299007,327.925898544036,0.17941661387049346,132.2197222929553,346.4567188014249,0.05497023737657413
0.05686505724772287,328.017838386625,0.1805465567615201,132.2567924374872,346.67059154475476,0.055307032936541864
0.05721930888113486,328.125706965093,0.18167130569760317,132.3002850483255,346.9008331437694,0.0556421677517869
0.05757375712473867,328.207851913835,0.18279667887104525,132.3334058916583,347.1040110663543,0.055977376196168785
0.057929525740413865,328.301023999643,0.18392624422581402,132.37097287665608,347.31934662003454,0.05631372038614074
0.058285875750518364,328.373471284553,0.1850576555078958,132.40018362193175,347.5130066316109,0.056650500860587504
0.058639770728684364,328.444239311293,0.18618127206357285,132.42871729031336,347.7041342016644,0.05698484891107404
0.05899220925308996,328.524471990824,0.18730026437856062,132.46106710670023,347.90485638726756,0.05731770989068835
0.059343533068300765,328.610405752787,0.18841571749185493,132.49571559952372,348.1113082331653,0.05764940784716716
0.059695068607923465,328.663713880098,0.189531842830157,132.51720943645552,348.28331682910533,0.05798119561410015
0.06004587987053077,328.748198695416,0.19064566858893517,132.55127371399175,348.4881735419344,0.058312190084025384
0.060394379130539466,328.82657110698,0.1917521537394628,132.58287347033433,348.68584771061023,0.0586408947119131
0.060740378363563066,328.927020351806,0.19285070130431273,132.6233746058482,348.90617202197416,0.0589671344615283
0.06109217312824387,329.015409365013,0.19396764968217425,132.65901305597325,349.1156757158004,0.05929872968345744
0.061445355480458264,329.08718072846,0.19508900365045498,132.68795126971506,349.30805953238206,0.05963152224963232
0.06179814683993127,329.135867691115,0.19620911621678178,132.70758185305758,349.47585437297874,0.05996383586541314
0.06215289552503946,329.21928371825,0.19733544329200028,132.7412151951984,349.6812154640187,0.060297881878085685
0.06250929009416066,329.316449259699,0.1984669960489601,132.78039234151066,349.90178671925247,0.06063336539624316
0.06286691070427547,329.372503428458,0.19960244148607462,132.80299338235426,350.07913518993854,0.06096988992621151
0.06322814767747297,329.424016423545,0.20074936887597666,132.82376342197335,350.2528867824792,0.06130970255617792
0.06358586353352946,329.501985186102,0.20188511671895604,132.85520042703632,350.45365345017245,0.061646089149028915
0.06394400124798266,329.55005242779,0.20302220396234494,132.8745811388849,350.62280139150533,0.06198275912839284
0.06430760947385326,329.663975615064,0.2041766600794841,132.9205149679938,350.8638778165154,0.06232445578453694
0.06466925559889307,329.733860394189,0.20532488652648548,132.948692510937,351.0575036916305,0.06266419280512299
0.06503424261774407,329.78134157206,0.2064837203113374,132.9678369218546,351.22842135066253,0.0630069513372192
0.06539829885974546,329.852492109475,0.20763959887969183,132.99652481854034,351.4242839680823,0.06334871878439917
0.06576439607020487,329.935059193398,0.20880195752290046,133.02981586677805,351.6330391036391,0.06369228449614081
0.06613117968886567,330.012047651979,0.2099664955121485,133.06085761327793,351.83613367474254,0.06403637604213433
0.06649585429716116,330.077391904686,0.21112433739348668,133.0872044159694,352.026170063567,0.06437837171792606
0.06685407001101677,330.122758538922,0.21226167228497825,133.10549624289337,352.1928085505131,0.06471419634110714
0.06721504006439237,330.180385974242,0.21340775220444577,133.12873162481438,352.3734738459772,0.06505248909377746
0.06757333584381277,330.246256790859,0.21454534130410552,133.15529073807434,352.56209801214976,0.0653881624437248
0.06792951443761487,330.303954508371,0.21567620833942722,133.1785544577752,352.7413417549487,0.06572174064246881
0.06828692551172326,330.340042472411,0.21681098849972133,133.19310512487613,352.89794834626406,0.06605636130239775
0.06864071561424116,330.37631379846,0.21793427207521568,133.20772972353907,353.0535803995814,0.06638748164446416
0.06900088172271776,330.449896570174,0.21907779946962888,133.23739829709416,353.2512307986969,0.06672445685334227
0.06936745873849456,330.480150386059,0.22024168149472023,133.24959663565897,353.4047185818554,0.06706731361233141
0.06973318314131727,330.558528749192,0.22140285647368232,133.28119879167423,353.60942717338384,0.06740925582788318
0.07010189497614057,330.649883617244,0.2225735165492463,133.31803307447277,353.8290670324531,0.06775387288949024
0.07047378584439397,330.704206052988,0.22375427005595083,133.33993588056478,354.01018344820665,0.06810134097980566
0.07084387973901816,330.787451252719,0.22492931817138265,133.37350034509632,354.2217176684429,0.06844701028824836
0.07121763529854956,330.829433496287,0.22611599207289484,133.39042758570292,354.39032343705134,0.06879597838342276
0.07158868393430477,330.876981230699,0.22729407149141764,133.40959883221785,354.5640288611604,0.06914229866083962
0.07195826981470776,330.944314617846,0.22846750666169713,133.4367476539155,354.7584949027605,0.06948713447926579
0.07232808680510827,330.959491324794,0.22964167560621876,133.44286690215694,354.8971581423081,0.06983206694868647
0.07269629057308337,330.932575060569,0.2308107225695397,133.4320142644214,354.99014569727086,0.07017537658700561
0.07306734597210177,330.952529030629,0.2319888234614231,133.44005970514962,355.1343519696521,0.07052122586546049
0.07343662496313987,330.966626782789,0.23316128425796906,133.4457439188205,355.2716988291522,0.07086530069567884
0.07380489728263877,331.01124797113,0.23433054887237809,133.46373518195963,355.44149912703733,0.0712083196987062
0.07417062928187537,331.051334253102,0.23549174796995428,133.47989797085074,355.60562003925907,0.0715488561696741
0.07453585219927196,331.054047852971,0.23665133073268846,133.4809920943179,355.7294434337108,0.07188880294608274
0.07490201745744146,331.040333716552,0.23781390542737663,133.47546255451377,355.8359225717065,0.07222951087430961
0.07526567040178916,331.060765564475,0.23896850352568058,133.4837006755963,355.9782760284147,0.07256776630421702
0.07562907407361837,331.098376861883,0.2401223101837383,133.49886555071123,356.13904053122513,0.07290567561030506
0.07599967871063547,331.117752440442,0.24129897990626759,133.50667778398622,356.28259524130334,0.07325016314348434
0.07637381523858647,331.10763546724,0.24248686338251202,133.50259862039118,356.3955888425002,0.07359781333781261
0.07675302395395807,331.126918520208,0.24369085105381685,133.51037354734785,356.5419108291898,0.07395005335673743
0.07713160619143467,331.186725950637,0.24489284965780506,133.53448790329685,356.73169007249214,0.07430158772963442
0.07751390876653376,331.251165501664,0.24610666033374468,133.56046993027093,356.92773812316796,0.07465645128046629
0.07789927659225657,331.294172693871,0.2473302031804146,133.5778104301688,357.1017490859537,0.07501403267826677
0.07828436888576996,331.299571114535,0.24855287121231961,133.57998707338052,357.23514895136265,0.07537123072901303
0.07866481880425956,331.295899264649,0.24976079970352408,133.57850658350648,357.35723115089684,0.07572399742802134
0.07904338585557306,331.306057883049,0.2509627500914445,133.58260253844534,357.49361045258763,0.07607489478696938
0.07942328519069687,331.268283588417,0.25216893048046257,133.56737194284975,357.5786989504925,0.07642690331611889
0.07980589108698977,331.235673156316,0.2533837042011925,133.5542234166266,357.67023121235474,0.0767812945076616
0.08018975489136956,331.220271158,0.25460247178009837,133.5480133309056,357.78074351721295,0.07713672467636165
0.08057637275543897,331.215696027231,0.2558299834985187,133.54616863817952,357.90385541277334,0.07749457725767393
0.08096877517635157,331.23994423609,0.2570758611849162,133.5559455159915,358.0600368103692,0.07785765311162837
0.08136447577349566,331.217978572459,0.2583322105808487,133.54708896041546,358.16735576576406,0.07822364720748522
0.08176385069748136,331.207440427062,0.25960022596450333,133.54283998019142,358.28823613603527,0.07859290401359911
0.08216526794222007,331.204651809004,0.2608747257165487,133.54171560939042,358.41817076860053,0.07896391177525396
0.08257167056889046,331.174665261205,0.2621650540562272,133.52962503331787,358.52031062191577,0.07933938708055778
0.08298355838336417,331.132765518701,0.26347279786718125,133.51273105714023,358.611340698767,0.07971978635547257
0.08340196167671536,331.04372358519,0.2648012283235713,133.4768293495486,358.65341953295916,0.08010605490710307
0.08382431247027186,330.939614393616,0.26614219209311313,133.43485252350598,358.6804000393377,0.08049581651523911
0.08425485812998666,330.895720828035,0.2675091745627076,133.41715463786372,358.7752928422208,0.08089298435967285
0.08469698690081996,330.815380878177,0.26891293341010336,133.38476157008097,358.83444685900577,0.08130067324218095
0.08514772555032897,330.64203794917,0.27034402862229445,133.31486970110535,358.7954554518674,0.08171613030544984
0.08561019385029336,330.461423970581,0.2718123654746814,133.24204614493826,358.7522905367464,0.08214221955550206
0.08608042867782957,330.276812463392,0.2733053610521089,133.16761078523965,358.7071820625879,0.0825752783254827
0.08655761505124367,330.054812629524,0.2748204277876986,133.07810045222408,358.6235700469207,0.08301454742736045
0.08704410736273707,329.765210088158,0.27636504087669017,132.96133270754532,358.4693284395672,0.08346218446647415
0.08753768062839207,329.392545393338,0.2779321359951448,132.8110743025939,358.2268048333532,0.0839161322341383
0.08803553913732107,328.938123106953,0.27951283676099437,132.62785123672344,357.8963681174921,0.08437381254854594
0.08853823550435337,328.489164061242,0.2811088977263219,132.44683094949275,357.5730150295244,0.0848357278595059
0.08903937597656776,327.990977865083,0.28270001872560263,132.24596227520146,357.1950898601342,0.08529600121869134
0.08954117538616346,327.401593199272,0.284293231851069,132.00832237794646,356.7175166776373,0.08575666760824108
0.09004805105788466,326.726017985752,0.2859025621087838,131.7359304518552,356.14705913527234,0.08622177880874544
0.09055706683160566,325.977194140879,0.28751868719034795,131.43400467760242,355.49673269627385,0.08668863617672114
0.09107223676222216,325.159561030178,0.2891543517200553,131.10433500736778,354.7725695578186,0.08716091617345892
0.09159093990754506,324.300954332719,0.29080123420645554,130.7581447869523,354.0039835529666,0.08763620998940999
0.09211483608466717,323.407232618615,0.29246460456881823,130.3977961918256,353.1978368398745,0.08811603304335183
0.09264441137356637,322.402965524869,0.2941460061110732,129.99287569962718,352.27179849101265,0.08860082357566071
0.09318291571389817,321.373616465816,0.2958557573916267,129.577842159017,351.32014708162075,0.08909354717239978
0.09372685620843256,320.299812815002,0.29758276846177334,129.1448845270088,350.32050731430155,0.08959099842780587
0.09427635254120406,319.305006948341,0.29932741931832285,128.74377880157107,349.4079183515744,0.09009327954158725
0.09482414413142086,318.216175190371,0.3010666576172612,128.3047618367576,348.3907516515722,0.09059375140433021
0.09537522602849116,317.187427523978,0.3028163426404594,127.88997077766794,347.4392501174731,0.09109697674190272
0.09593611399604747,316.164073731691,0.3045971619374507,127.47735452861782,346.4956263506693,0.09160889667729531
0.09650238978071236,315.119245761734,0.3063950875537617,127.05607989113116,345.529006043637,0.09212546833600488
0.09707059430430727,314.035412343205,0.30819913691617556,126.61907825678026,344.5190164519581,0.09264353136871513
0.09764284272406927,312.936084400771,0.3100160256489199,126.17582923039086,343.49205327260154,0.0931650103217987
0.09792682546121166,312.352533588431,0.310917670839347,125.9405415428554,342.9402256275125,0.09342369738861425
0.09821659724309637,311.856209814591,0.31183769624683094,125.7404237972431,342.48566557170926,0.09368758888182976
0.09851197264299827,311.271506132234,0.31277551314151947,125.50467127251673,341.9354762288775,0.0939565118664272