File: example/data/02 processed data/test_ID_144.csv
Strain,Stress_MPa,Displacement(mm),Force(kN),True Stress (MPa),True Strain
2.453809607755757e-05,-0.692253066634534,0.0001381468854277,-0.139558218233522,-0.6922831871400721,4.350988348733942e-05
2.428969162482667e-05,-0.754830988675192,0.0001373582012903,-0.1521739273169187,-0.7548636444946827,4.326148981151832e-05
3.138246339030877e-05,-0.816110855947823,0.0001598777516457,-0.1645279485590811,-0.816151951371049,5.035392958834275e-05
4.291392007032506e-05,-0.878028811149136,0.0001964901266048,-0.1770106083276658,-0.8780831494144163,6.18847391487445e-05
5.919085949426597e-05,-1.00171224897663,0.0002481694092758,-0.2019451893936885,-1.0017905464056356,7.816053885829067e-05
7.108824936508457e-05,-1.1173944389113,0.0002859436221156,-0.2252667188845181,-1.1174950725532509,9.005692809652709e-05
8.783977674476607e-05,-1.22148965498139,0.0003391297215461,-0.2462523144442482,-1.2216201253582613,0.0001068068066732
0.0001086991417633,-1.19094004201523,0.0004053582054808,-0.2400935124702704,-1.1910920915642904,0.0001276637263816
0.0001343329019651,-0.974404542933398,0.0004867453941215,-0.196439955855373,-0.9745539246415188,0.0001532938858356
0.0001697599891815,-0.570199594359284,0.0005992263960336,-0.1149522382228316,-0.5703072096814723,0.0001887149153803
0.0001913312954903,-0.0035441632572232,0.000667715293564,-0.0007145033126561,-0.0035449086090372,0.0002102819186765
0.0002074064174613,0.722858609251339,0.000718753805822,0.1457282956250699,0.7230222493699126,0.0002263535315464
0.0002169198046793,1.65376602447789,0.0007489588102391,0.3333992305347427,1.6541561355437506,0.0002358647203878
0.0002286127126887,2.73642649071929,0.0007860837931689,0.5516635805290089,2.737103990094268,0.0002475548024487
0.0002399476980645,3.8535310388115,0.0008220723717371,0.7768718574243983,3.8545287967329607,0.0002588869179329
0.000255612838439,4.99891116035545,0.0008718091924261,1.0077804899276588,5.000283789237882,0.000274547880699
0.0002600693387927,6.11127266747508,0.0008859585810491,1.232032569762976,6.112977969667484,0.0002790031477731
0.0002751387151189,7.24710737083011,0.0009338038508848,1.4610168459593502,7.249238828080711,0.0002940682068037
0.0002830332785809,8.40053528564601,0.0009588690898767,1.6935479135862357,8.403072297810994,0.0003019604179234
0.0003034491886185,9.53207549418028,0.0010236896042461,1.9216664196267448,9.535148844287455,0.000322369955819
0.000330150795575,10.7376205464699,0.0011084672063329,2.164704302168332,10.74136930245409,0.000349062600115
0.0003550260516186,11.9878665564643,0.0011874461442714,2.416753897783203,11.992350003998322,0.0003739288654842
0.0003714303504337,13.2180544399323,0.0012395297930093,2.664759775090352,13.223214809155582,0.0003903268969568
0.000386500802129,14.5784936727299,0.0012873784771419,2.939024324422348,14.584404866110503,0.0004053913539277
0.0003870220040176,15.9589426637487,0.0012890332931382,3.2173228410117383,15.96542191049417,0.0004059123444329
0.0004087069613916,17.393449570487,0.0013578830328007,3.50651943341018,17.400888395700747,0.0004275882664767
0.0004357913469567,18.8708058737246,0.0014438759569698,3.8043544641428793,18.879387638414272,0.0004546607070899
0.0004499111390519,20.3669459566338,0.0014887062968721,4.105976304857374,20.37649568913575,0.0004687739813371
0.0004703632059438,21.8855572796522,0.0015536416092539,4.412128347577884,21.896266669394368,0.0004892162541342
0.0004832620507557,23.5239548524154,0.0015945954415317,4.742429298246945,23.535769400816804,0.0005021087070567
0.0004969258262169,25.0985241573836,0.001637977928621,5.059862470128534,25.11147244985943,0.0005157655302847
0.0005307304931698,26.6753286279676,0.0017453077461964,5.377746251398268,26.689992142199635,0.0005495521956752
0.0005536357265098,28.2440211230907,0.0018180318620509,5.693994658415086,28.260193888543995,0.0005724445828194
0.0005719561061164,29.8735907661772,0.0018761990673019,6.022515898461324,29.891243932518137,0.0005907543104011
0.000590405969352,31.4584272009584,0.0019347773830749,6.342018923713214,31.477597296534945,0.0006091931075236
0.0006043955987496,33.0398338307115,0.0019791944564123,6.660830500271438,33.06042981684018,0.000623174119396
0.0006351934706628,34.5391286087219,0.0020769776997367,6.963088327518336,34.561722939395494,0.0006539523311973
0.0006646137824008,36.1085990071655,0.0021703871895049,7.279493559844565,36.13328235857215,0.00068335297754
0.0006929619251638,37.6914415102147,0.0022603925427774,7.598594608459284,37.718275353778864,0.0007116813538803
0.0007226443243484,39.3709003560991,0.0023546341601885,7.937173511789579,39.40009848740488,0.0007413421962831
0.0007534672376625,40.9703547439299,0.0024524969099608,8.25962351637627,41.00200188358643,0.0007721417934261
0.0007836736757284,42.5776429894667,0.00254840235082,8.583652826676488,42.61181778174599,0.0008023244613398
0.0008170561645432,44.2590397424883,0.002654391752807,8.92262241208564,44.29604157873385,0.0008356796210194
0.0008288113704507,45.9023002895688,0.0026917145315633,9.25390373837707,45.941215530111045,0.000847424938468
0.0008646789526275,47.5154415405742,0.0028055941049746,9.57911301457976,47.557428640631365,0.0008832614962992
0.0008890065868846,49.2236321927337,0.0028828343437409,9.923484250055116,49.268326232862485,0.0009075673569906
0.0009193898619815,50.8166729645636,0.0029793012421736,10.244641269656022,50.86435742972469,0.0009379226090028
0.0009438700687004,52.429491633609,0.0030570258985061,10.569785513335573,52.479972992276544,0.0009623795668727
0.0009742700034498,54.0309779459893,0.0031535456913354,10.892645153911442,54.08464382243031,0.0009927497982391
0.0009994175329662,55.5883765178055,0.00323338909755,11.206616705989587,55.644987179406506,0.0010178720593722
0.0010378628459079,57.1993710454918,0.0033554529661399,11.531393202771149,57.25982137595981,0.0010562775223138
0.0010579425637828,58.7579962034997,0.0034192060703927,11.84561203462554,58.821273588477055,0.0010763358404624
0.0010900343845706,60.2680018267209,0.003521097601394,12.150029168266933,60.33483946976747,0.0011083926244317
0.0011272433436422,61.8243735898522,0.0036392360464463,12.463793715714203,61.89523768084974,0.0011455596735121
0.0011576562022108,63.3094026648949,0.0037357968724016,12.763175577242812,63.38389434000328,0.0011759372508808
0.0011976197418242,64.7622451241651,0.0038626811106742,13.056068617031686,64.84103438429928,0.0012158530268547
0.0012339029629647,66.1803231678999,0.0039778803377952,13.34195315064862,66.26323888641282,0.0012520915031173
0.0012759657739349,67.5696010152496,0.0041114297626256,13.62203156467432,67.6570994935686,0.0012941007981543
0.0013109759450448,68.9470083173927,0.0042225870558996,13.89971687678637,69.03870430002704,0.0013290650806193
0.0013386911683612,70.290787722453,0.0043105828899291,14.170622804846523,70.3862189876108,0.0013567431100273
0.0013591165547369,71.5554217841368,0.004375433491672,14.42557303168198,71.65403154444705,0.0013771405951613
0.0013918078900728,72.8616798562211,0.0044792284813635,14.688914659014172,72.9644717023981,0.0014097864080375
0.0014191332601178,74.2603315084608,0.0045659865312563,14.970882832105698,74.3671257363267,0.0014370729100089
0.0014519234159964,75.6334306286465,0.0046700952761709,15.247699614735136,75.74467955056758,0.001469815441843
0.0014914883632627,76.9422890895859,0.0047957139837414,15.51156548046052,77.05850742398842,0.0015093214982805
0.0015296122436376,78.2287456271799,0.0049167573039317,15.770915118439468,78.34988948747592,0.0015473871563589
0.00156739838482,79.4894317322897,0.0050367283021858,16.025069437229604,79.61553147103953,0.0015851141612938
0.0016080270413222,80.735179094934,0.0051657242865803,16.276212105538693,80.86653521318033,0.0016256776450426
0.001657196522027,81.9601434596891,0.005321837387818,16.523164921473324,82.09752253237406,0.0016747660521042
0.0017046001305237,83.1627202110687,0.0054723438447951,16.765604394551453,83.3060572189627,0.0017220892173308
0.0017502474182922,84.3084931276087,0.0056172739834601,16.99659221452591,84.45765341265766,0.0017676569258202
0.0017895494095548,85.4455854524718,0.0057420578057188,17.225830027218315,85.60011568582979,0.0018068887364338
0.00184312293676,86.5587479077357,0.0059121537545953,17.450243578199515,86.71992857747925,0.0018603641198043
0.0018952650660961,87.6166796677896,0.0060777050152374,17.663522621026384,87.78439882792672,0.0019124079816633
0.0019535862490386,88.7229472697597,0.0062628747710799,17.886546169583557,88.89795851639643,0.0019706160431692
0.0020133788935457,89.7923650743379,0.0064527164173899,18.10214079898652,89.974854733636,0.0020302891948749
0.0020791276307712,90.8156422805345,0.0066614686580809,18.30843348375576,91.0061826127283,0.0020959024259735
0.0021552401602141,91.7874568404826,0.0069031259390621,18.504351299041293,91.98702231267036,0.0021718527137422
0.0022277552796245,92.7447186777525,0.0071333614431901,18.697335285434903,92.95309083531956,0.0022442078941956
0.0023044308906162,93.6714941879731,0.0073768065080888,18.88417322829537,93.88913087709064,0.0023207086958577
0.002397975901661,94.5703385362418,0.007673811918156,19.06538024890635,94.79891018693895,0.0024140325130865
0.0024868918705607,95.4179551374776,0.0079561201194125,19.236259755715484,95.65705961389416,0.0025027301610666
0.0025773470931015,96.229119703791,0.0082433154509796,19.399790532284268,96.47896127522044,0.0025929552112455
0.0026720105198297,96.918455553221,0.0085438718308416,19.53876063952936,97.17926149409968,0.0026873690407782
0.002769928378706,97.5793778185042,0.0088547610327739,19.672002568210445,97.8515170538773,0.0027850193435485
0.0028851483299392,98.1771686446756,0.0092205843779393,19.792517198766603,98.46228702813242,0.0028999122509734
0.0030094348438137,98.6944510496889,0.0096151940594908,19.89680133161728,98.99333807313384,0.0030238311886834
0.0031373591636376,99.13852925527,0.0100213537749317,19.98632749786244,99.45144335744116,0.0031513611389218
0.0032700236705428,99.4781292328216,0.0104425635843557,20.05479085333684,99.80531244219688,0.0032835994862392
0.0034136474314827,99.7440089709513,0.0108985690253399,20.108392208543783,100.08639226752894,0.0034267421722989
0.003566267500174,99.9826780586601,0.0113831377434348,20.156507896625875,100.34113997875434,0.0035788285806932
0.0037157073432153,100.187858308164,0.0118576092450909,20.197872234925864,100.56202790656424,0.0037277234746313
0.0038803351229801,100.361314494195,0.0123803024458441,20.232841002029712,100.75265415633692,0.0038917252609361
0.0040333114648429,100.529726902025,0.0128660023312585,20.26679294344824,100.93710192586192,0.0040440958088756
0.0041944762852872,100.675756815863,0.0133777006361692,20.29623257407798,101.09994898468264,0.004204597298419
0.0043619154835241,100.804546087334,0.0139093200905713,20.322196491206537,101.24615953555872,0.0043713200612195
0.0045255702668026,100.910022640828,0.0144289240274806,20.343460564390927,101.36861257792908,0.0045342477449428
0.0046914781696282,100.987217893845,0.0149556816189519,20.35902312739915,101.4629132256258,0.0046993914461713
0.0048673931320852,101.066913927998,0.0155142116247528,20.3750898478844,101.5607638464042,0.0048744663282953
0.005031958942122,101.116258926598,0.0160367080716197,20.38503779960216,101.62699024177915,0.0050382185116155
0.0052143558028055,101.13154751896,0.0166158181042898,20.38811997982233,101.66080213256014,0.0052196822625825
0.0054005904773987,101.135274005206,0.0172071131961232,20.38887123944953,101.6833830155772,0.0054049302244659
0.0055848488985268,101.099568534467,0.0177921336832049,20.381673016548547,101.6661124836574,0.0055881786372216
0.0057759075579627,101.074455935239,0.0183987449269139,20.376610316544184,101.66017030795682,0.0057781545577866
0.00596140680758,101.028871162209,0.0189877050444488,20.367420426301337,101.63306215641424,0.0059625680495385
0.0061581129675978,100.975928056931,0.0196122471025053,20.35674709627729,101.59966501833487,0.0061580857105986
0.0063462912368392,100.928327188426,0.0202097131073468,20.347150761186683,101.5707626331134,0.0063450912360429
0.0065274912038885,100.87064617675,0.0207850230027283,20.3355222692328,101.53099222433544,0.006525128904885
0.0067088349065935,100.814324931207,0.0213607892588167,20.324167906131333,101.4925843167583,0.0067052769411018
0.0069041066133353,100.76085222033,0.0219807769277219,20.313387807618525,101.45842759535432,0.0068992248678411
0.0070873606231032,100.691468205545,0.022562608408735,20.29939999023787,101.4070153448276,0.0070812023594484
0.0072815176584578,100.618000335047,0.0231790569959858,20.28458886754548,101.3525610797992,0.0072739708048952
0.0074741016219373,100.548157991074,0.0237905110800333,20.27050865100052,101.30157281525152,0.0074651407266535
0.0076802569805786,100.48089615087,0.0244450543437194,20.2569486640154,101.25452165226012,0.0076697419043614
0.0078842860914991,100.431559431392,0.025092846770892,20.247002381368628,101.22529603982464,0.0078721916560137
0.0080850517598202,100.363809715407,0.0257302777678115,20.23334403862605,101.17716048763162,0.0080713632271147
0.0082867876167329,100.308193608051,0.0263707891135093,20.22213183138308,101.14132942537223,0.0082714573340784
0.0084996632726821,100.256538111415,0.027046669321148,20.211718083261264,101.11058706687405,0.0084825571771031
0.0087100158258585,100.210249856021,0.0277145386774831,20.20238637097384,101.08498398059264,0.0086911112002951
0.0089169323944304,100.125415433803,0.0283714987826988,20.185283751454687,101.020126647062,0.0088962161906674
0.009124867066533,100.041100818956,0.0290316913666246,20.16828592510153,100.95586061831138,0.0091022880006254
0.0093389417507184,99.9646182388883,0.0297113784889132,20.152867036959883,100.90007858786322,0.0093144004593177
0.0095524036536798,99.8790509851972,0.0303891200308157,20.135616678615754,100.83503097541866,0.0095258609643705
0.00975566542939,99.7993426007203,0.0310344761686956,20.11954746830521,100.7748450635844,0.0097271754245293
0.0099667234328411,99.7138948094513,0.0317045853296528,20.102321193585382,100.70960746662873,0.0099361685418135