File: example/data/02 processed data/test_ID_066.csv
Strain,Stress_MPa,Displacement(mm),Force(kN),True Stress (MPa),True Strain
2.5345956109095e-05,0.175511512674531,8.047341064637663e-05,0.03538312095518545,0.17551596118162788,2.5345634905717145e-05
2.19711220942967e-05,0.171187773451037,6.975831264939202e-05,0.03451145512772906,0.17119153463850856,2.1970880732776428e-05
1.83605955152704e-05,0.166194484381388,5.8294890760983516e-05,0.033504808051287825,0.16619753581109262,1.8360426961628105e-05
2.28243502176524e-05,0.215050764325037,7.246731194104637e-05,0.04335423408792746,0.21505567271899653,2.2824089746091496e-05
2.33181839218155e-05,0.347904027027898,7.403523395176422e-05,0.07013745184882424,0.3479121395179874,2.331791205713665e-05
2.19186186214209e-05,0.480066179611657,6.959161412301136e-05,0.09678134180971006,0.48007670199916097,2.1918378412030405e-05
1.95004221167497e-05,0.61658071208971,6.191384022068029e-05,0.12430267155728554,0.6165927356738649,1.9500231986087488e-05
3.23770206402804e-05,0.627769765931429,0.00010279704053289026,0.1265583848117761,0.6277900912460979,3.237649651587539e-05
6.55784740528989e-05,0.629637044844571,0.00020821165511795403,0.1269348282406655,0.629678335481179,6.557632387873646e-05
0.0001279982092625,0.631172407363975,0.0004063943144084375,0.12724435732457734,0.6312531963018535,0.00012799001819073679
0.0002223554650146,0.764578067676456,0.0007059786014213549,0.15413893844357351,0.7647480757882342,0.00022233074770224167
0.0002916315839683,1.95042567856266,0.0009259302790993525,0.3932058167982322,1.9509944842927116,0.00029158906774374153
0.0003619870201001,4.63773900931823,0.0011493087888178174,0.9349681842785552,4.639417810642215,0.00036192151860544187
0.0004516625930088,9.01886542965852,0.00143402873280294,1.8182032706191578,9.022938913804477,0.00045156062416244216
0.0005467452932719,14.2856126812033,0.0017359163061382824,2.8799795165305855,14.293423272698254,0.0005465958825213336
0.000649544816467,19.8101546871029,0.0020623047922827247,3.993727184919945,19.823022270393317,0.0006493339535376596
0.0007679803729264,25.3820587004675,0.0024383376840413197,5.117023034014248,25.401551623373923,0.0007676856268962148
0.0008518095272019,31.2460425741434,0.0027044952488660323,6.29920218294731,31.27265825089541,0.0008514469433535337
0.0009684782988625,37.4057459490703,0.0030749185988884374,7.540998383332573,37.441972602274745,0.0009680096263299545
0.0010862009006711,43.7103082675239,0.0034486878596307427,8.811998146732819,43.7577864437327,0.0010856114113034594
0.0011832554738277,50.1082725521845,0.003756836129402947,10.101827746520396,50.16756343996593,0.0011825559788028032
0.0013047406624564,56.5343399722795,0.00414255160329907,11.397322938411547,56.60810262446647,0.0013038902280088783
0.0014094917111924,63.0768892246695,0.00447513618303587,12.716300867693372,63.165795577199475,0.0014084993101616983
0.0015027105294196,69.6989318046531,0.004771105930907229,14.051304651818066,69.80366912336525,0.0015015825897884741
0.0016015793406885,76.3856376251026,0.0050850144066859875,15.399344545220686,76.50797528424829,0.0016002981802339007
0.0016989107212477,83.0725452724906,0.005394041539961447,16.747425126934107,83.21367811029538,0.0016974692048691566
0.0018099630525262,89.7445471713821,0.005746632691770685,18.09250070975063,89.90698148592799,0.0018083270431805479
0.00192509874639,96.3197543831021,0.00611218851978825,19.41806248363338,96.50517942151758,0.001923248118511871
0.0020231738209394,102.851978453477,0.006423576881482594,20.734958856220967,103.0600658837159,0.0020211299610427198
0.0021244980104549,109.344510794449,0.006745281183194307,22.043853376160918,109.57681299008597,0.002122244455773862
0.0022332155954007,115.698650833966,0.007090459515397222,23.324848008127546,115.95703086537524,0.0022307256757821796
0.0023339405022274,122.094780955407,0.007410261094571994,24.614307840610053,122.3797429097894,0.0023312210935634535
0.0024396412979446,128.385270860503,0.0077458611209741055,25.88247060547741,128.69848486934208,0.002436670204400487
0.0025453200500929,134.646098059804,0.008081391159044958,27.144653368856485,134.98881547286237,0.0025420862092917127
0.0026474930215158,140.864387352164,0.008405790343312665,28.398260490196265,141.23732483465895,0.002643994585229808
0.0027515120407709,146.951599161425,0.008736050729447607,29.62544239094328,147.3559382559282,0.002747733560950499
0.002853835513957,152.91903601766,0.009060927756813475,30.82847766116026,153.35544179340727,0.0028497710564125006
0.0029536221975035,158.790280455649,0.009377750477073612,32.01212053985884,159.2592869527506,0.0029492688254982467
0.0030560513265569,164.610840241371,0.009702962961818157,33.185545392660394,165.1138994180563,0.0030513910938944166
0.003156115487685,170.348580304853,0.010020666673399875,34.34227378945837,170.88622009745828,0.003151145409879679
0.0032527026275633,176.113165740313,0.010327330842513477,35.5044142132471,176.68600949726502,0.0032474240337383086
0.0033571025170636,181.773692775685,0.01065880049167693,36.645576463578095,182.38392569723817,0.003351480028408344
0.0034522756583123,187.300098453055,0.010960975215141552,37.75969984813589,187.946710023744,0.003446330234267692
0.0035469664996737,192.781330891491,0.011261618636463997,38.864716307724585,193.4651198139256,0.0035406908493018185
0.0036463850812305,198.168138890981,0.011577272632906838,39.950696800421774,198.89073623620828,0.0036397531360115856
0.0037399343071951,203.55592969716,0.011874291425344442,41.036875426947454,204.3172155020674,0.003732958141075913
0.0038470596313241,208.800234033626,0.012214414329454018,42.094127181179005,209.60350098498776,0.003839678621487518
0.0039515432155055,213.800176435792,0.01254614970922996,43.10211556945566,214.64501707246072,0.003943756375229989
0.004059656511001,218.524798935987,0.012889409422428175,44.05459946549499,219.41193455880267,0.00405143833996666
0.0041633953244267,222.785450970748,0.013218780155054772,44.9135469157028,223.7129948756699,0.004154752375151344
0.0042877496771625,226.739609986704,0.013613605224990936,45.71070537331953,227.71181267622444,0.004278583470773679
0.0044236353954355,230.604113555801,0.014045042380507711,46.48978929284948,231.62422207485946,0.004413879879695377
0.0045756653897558,234.335186212485,0.014527737612474665,47.24197354043697,235.40742561363945,0.00456522885682153
0.0047484833714788,237.933348646841,0.015076434704445191,47.96736308720315,239.06317119641082,0.004737244887441338
0.0049439791056296,241.325753706921,0.01569713366037398,48.65127194731527,242.51886319089834,0.004931797773932698
0.005198706390455,244.440961238451,0.016505892789694623,49.27929778567172,245.7117380257303,0.005185239768898419
0.0055029738988922,247.246835680975,0.017471942128982735,49.84496207328456,248.60742856431108,0.005487887858112454
0.0058718786788992,249.780695287958,0.01864321480550496,50.35578817005233,251.24737722701997,0.00585470638890078
0.0062878351579513,251.956028783852,0.019963876626495375,50.794335402824565,253.5402867598969,0.00626814920073822
0.0067302788332136,253.717969572351,0.02136863529545318,51.14954266578596,255.4255622525697,0.006707731616128873
0.0072085678818967,255.022951704388,0.02288720302502202,51.412627063604624,256.8613019631907,0.00718271034595013
0.0076857602586321,255.942361633969,0.024402288821156914,51.597980105408155,257.90947326551577,0.00765637527119462
0.0081889660207419,256.613016633978,0.025999967115855532,51.733184153409965,258.71441190767376,0.008155618369986203
0.0086915248453083,257.253770251541,0.02759559138385385,51.86236008271067,259.48969778723153,0.008653970986557648
0.0092003634552675,257.808730395589,0.029211153970474312,51.97424004775075,260.1806644171695,0.009158297926662267
0.0097153083586469,258.401080941959,0.030846104038703904,52.09365791789893,260.9115271235178,0.009668418207301311
0.0102131537531078,258.797736427399,0.03242676316611726,52.173623663763635,261.4408775004883,0.010161351906568129
0.0107107417351998,259.152553248584,0.03400660500925936,52.24515473491454,261.9282693164472,0.010653788057437424
0.01119040616762,259.460060781602,0.035529539582193494,52.30714825357097,262.36352424602353,0.011128256793870325
0.0116732330382083,259.857800003021,0.03706251489631135,52.38733248060903,262.89118065925237,0.011605626469610629
0.0121471609281922,260.228069907235,0.03856723594701023,52.461978893298586,263.38910215043103,0.012073976230350158
0.0126074533679796,260.52710966415,0.04002866444333523,52.52226530829264,263.81169305033524,0.012528641150698263
0.0130576216383541,260.755977536135,0.041457948701774265,52.568405071284815,264.160830430741,0.012973105818959187
0.0134869542367645,260.914108309665,0.042821079701727285,52.600284235228465,264.4330449481637,0.01339681483572074
0.0139080790913146,261.109635450457,0.044158151114923855,52.639702506812135,264.7411689118063,0.013812249276156768
0.0143351677432287,261.351924687284,0.04551415758475112,52.68854801695646,265.09844836769184,0.014233390733319674
0.0147572837368788,261.602208429018,0.04685437586459019,52.73900521929003,265.46274644499914,0.014649454574503054
0.015179533458106,261.89328852133,0.04819501872948655,52.797686965900134,265.86870645689294,0.015065477106574484
0.0155845400841361,262.183842259239,0.049480914767132116,52.85626259946258,266.2698568583409,0.015464348286812927
0.0159822157516546,262.488099834264,0.05074353501150335,52.917600926587625,266.6832412780571,0.01585584482164796
0.0163784546857512,262.755576190157,0.052001593627260055,52.971524159935655,267.05910648821595,0.016245774566777116
0.0167695106358705,263.035742470195,0.053243196268888834,53.02800568199131,267.446723151163,0.016630454837580435
0.017170315405284,263.23931055381,0.0545157514117767,53.0690450076481,267.75921254308844,0.01702457148692266
0.0175643543175523,263.451512450836,0.05576682495822855,53.11182491008854,268.0788681610175,0.017411883821112965
0.0179454545453411,263.685306428541,0.05697681818145799,53.15895777599387,268.4172591093287,0.017786335696100063
0.018328815251071,263.923849019443,0.05819398842215042,53.20704796231971,268.761260488472,0.01816286720361411
0.0186956604337262,264.165865989261,0.05935872187708068,53.25583858343503,269.1046213179775,0.018523044698779252
0.0190659348771577,264.426309192144,0.060534343234975696,53.30834393313623,269.4678439830086,0.018886457620446544
0.0194365832433411,264.745131327512,0.06171115179760799,53.372618475626425,269.89087211082847,0.01925010531474487
0.0198099026927688,264.999100815837,0.06289644104954094,53.42381872447274,270.2487072166699,0.019616240018099865
0.020193070218202,265.317912113053,0.06411299794279134,53.48809108199149,270.67549534249866,0.019991893911772855
0.0205737214542765,265.610315409103,0.0653215656173279,53.547039586475165,271.0749080537124,0.020364941182085317
0.0209559932317346,265.870739309002,0.06653527851075736,53.599541044694796,271.44232472247774,0.02073943661967408
0.021329733246756,266.096167183534,0.0677219030584503,53.64498730420046,271.77192744754296,0.021105438315076178
0.0217070957666788,266.226761174347,0.06892002905920519,53.67131505274836,272.0057709748113,0.0214748516500247
0.0220820106592127,266.406227599487,0.07011038384300032,53.70749548405658,272.2890127570195,0.021841733825451366
0.0224629774494638,266.55538590299,0.07131995340204757,53.73756579804279,272.543013525562,0.022214400405913846
0.0228482772871781,266.787993696499,0.07254328038679046,53.78445952921419,272.8836397533665,0.022591164423008854
0.0232266724650413,267.019636372448,0.07374468507650613,53.83115869268552,273.22161400820534,0.02296103863726778
0.0236070125802468,267.210911714551,0.07495226494228358,53.86971980165348,273.5189630689756,0.023332676179059066
0.0239775641795396,267.436397023371,0.07612876627003821,53.91517763991159,273.8488703969437,0.02369461639637061
0.0243478919864406,267.581520734222,0.0773045570569489,53.94443458001916,274.09656669862636,0.024056207187346842
0.0247204845844314,267.746762046742,0.0784875385555697,53.97774722862319,274.3655917504499,0.024419877435111557
0.0250903305032926,268.040694439753,0.079661799347954,54.03700399905421,274.76592405157845,0.02478073602767277
0.0254566994959693,268.314755454896,0.08082502089970252,54.09225469970703,275.14516355484574,0.025138073841646576
0.0258276783959184,268.585073748001,0.08200287890704092,54.14675086759701,275.5220026547084,0.02549977786278764
0.0261853543527602,268.854309096231,0.08313850007001364,54.20102871380018,275.89435444918234,0.025848387695918178
0.0265483499521053,269.044101178049,0.08429101109793433,54.239290797494675,276.1867781286735,0.02620205812318073
0.026912086193202,269.298878686124,0.08544587366341636,54.2906539431226,276.5462733210576,0.0265563247440499
0.027280126905439,269.4497450031,0.08661440292476882,54.32106859262496,276.80036824142275,0.026914656076267317
0.0276568828083791,269.693656244365,0.08781060291660364,54.37024109886398,277.1525420892787,0.027281339731659845
0.0280372559347993,269.830229935743,0.08901828759298777,54.39777435504578,277.3955291513971,0.02765140755798891
0.0284130899497094,269.964075134496,0.09021156059032734,54.424757547114396,277.63458868448254,0.028016924789996747
0.0287839429530778,270.08324919512,0.09138901887602201,54.44878303773619,277.85731003253426,0.02837746682992217
0.0291441243079038,270.218159143312,0.09253259467759456,54.4759808832917,278.0934307636376,0.02872750953961036
0.0295021007941216,270.362099154041,0.09366917002133608,54.504999189454665,278.3383490541938,0.029075288080149243
0.0298731804784638,270.457306708723,0.09484734801912256,54.524193032478564,278.53672664375193,0.029435668911882807
0.0302502056530521,270.616735592111,0.09604440294844041,54.55633389536958,278.80294749692996,0.029801690851476898
0.0306372526948902,270.796885437821,0.09727327730627638,54.592652104264715,279.0933580459687,0.03017730286737893
0.0310191393103106,271.088291149324,0.09848576731023616,54.65139949570372,279.4972166178789,0.03054776869405009
0.0313955150470866,271.400378441895,0.09968076027449994,54.714316293886036,279.92113310705247,0.030912754212514187
0.0317658125485563,271.678705052615,0.10085645484166625,54.77042693860718,280.3087998707509,0.0312717154827677
0.0321344216229684,271.902433109532,0.10202678865292467,54.81553051488166,280.6398605353847,0.031628912087747346
0.0324979141609142,272.113595841485,0.10318087746090258,54.85810092164337,280.9567201211593,0.03198102566787635
0.0328644392513592,272.318439266931,0.10434459462306546,54.89939735621329,281.2680320712441,0.032335951372498686
0.033233029371529,272.489163449684,0.10551486825460457,54.933815351456296,281.5448038220307,0.03269274976142051
0.0335905212967445,272.675550057911,0.10664990511716378,54.97139089167486,281.83486392923277,0.033038683432115225
0.0339605831807073,272.804784106028,0.10782485159874566,54.99744447577525,282.06939366875565,0.03339665464464117
0.0343292288208928,272.966688502194,0.10899530150633464,55.03008440204231,282.3374244122672,0.03375312852170626
0.0347111138471742,273.02849300236,0.11020778646477808,55.04254418927578,282.50561610648737,0.03412227070104686
0.0350836745104781,273.114393987168,0.11139066657076796,55.059861827813066,282.69625048994027,0.034482268387216554
0.0354646010633902,273.228827456408,0.11260010837626389,55.082931615211855,282.91877882116734,0.03485021591271347
0.03584442952554,273.444191435384,0.11380606374358948,55.126348993373426,283.2456424844579,0.0352169680108293
0.0362267628870311,273.736369851669,0.11501997216632373,55.18525216209647,283.6529524158421,0.03558600298147148
0.0366073699507743,273.991826065322,0.1162283995937084,55.23675213476892,284.02194620558345,0.03595323648268697
0.0369879754546228,274.318216172936,0.11743682206842737,55.302552380463894,284.4646916194964,0.03632033366870833
0.0373663567225797,274.515306950373,0.11863818259419054,55.342285881195195,284.7729438356891,0.03668515202812185
0.0377494930775584,274.611062314249,0.1198546405212479,55.3615901625526,284.9774907101017,0.037054419468654606
0.0381342043200281,274.617065399904,0.12107609871608921,55.36280038462064,285.08936868163045,0.03742506763873884
0.038521487577501,274.641742350594,0.12230572305856566,55.36777525787975,285.22135081681563,0.037798055094939595
0.0389047425471504,274.709794752048,0.12352255758720251,55.38149462201288,285.397308592057,0.03816702605375379
0.0392779792449973,274.824262128087,0.12470758410286642,55.404571245022346,285.6188037919757,0.03852622132368456
0.0396507276779107,275.013926794388,0.12589106037736647,55.44280764174862,285.91842911334516,0.03888481797557219
0.0400289009353205,275.201541040759,0.12709176046964257,55.480630673817025,286.21755626432713,0.03924850212804928
0.0404099199138001,275.346345572022,0.1283014957263153,55.509823267319646,286.47306934514495,0.03961478925836164
0.0407930415331114,275.494823287114,0.12951790686762868,55.539756374682185,286.73309505562247,0.03998296250310148
0.0411729638230613,275.691690276512,0.1307241601382196,55.579444759744824,287.04273426658546,0.040347927438349786
0.0415537821056974,275.927479439132,0.13193325818558924,55.62697985492901,287.39330979672,0.040713619469361036
0.0419381658170668,276.188388840726,0.1331536764691871,55.67957919029037,287.7712232886769,0.041082599744147845
0.0423215262933618,276.463045701015,0.1343708459814237,55.73495001332463,288.16338375879343,0.0414504622346708
0.0427049254867445,276.628636634879,0.13558813842041376,55.768333145591605,288.4420419498712,0.04181822658353698
0.0430872604556009,276.720894899279,0.13680205194653286,55.78693241169465,288.64404017131125,0.04218483546788854
0.0434742789116641,276.782389317573,0.13803083554453352,55.799329686422716,288.81530410860194,0.04255579836852615
0.0438689111348647,276.871903868471,0.13928379285319542,55.81737581988376,289.01797281501774,0.04293391752955759
0.0442595821530451,276.989000706497,0.14052417333591818,55.84098254242979,289.2484181387561,0.04330810046321755
0.0446563065139818,277.173144830101,0.1417837731818922,55.87810599774837,289.5506737430783,0.043687938031459345
0.0450382720191746,277.319016136033,0.14299651366087934,55.90751365302425,289.80898542085754,0.04405350868792807
0.045441678741036,277.468088129882,0.1442773300027893,55.937566566984216,290.0767038515696,0.04443945520391565
0.04584357200064,277.744658564602,0.145553341102032,55.99332316662376,290.4774658173015,0.044823805702642584
0.046258335592285,277.839326901499,0.1468702155055049,56.0124083033422,290.69171172604314,0.04522030990310583
0.046657895424105,278.03794628541,0.14813881797153336,56.05244997113866,291.01061170712757,0.04560213104888599
0.0470488222510132,278.167481950566,0.1493800106469669,56.078564361234115,291.2549343648701,0.04597556141346467
0.0474349877586083,278.274638099869,0.15060608613358134,56.100167040933584,291.4745921516674,0.046344306695834614
0.0478258680733333,278.484093767677,0.1518471311328332,56.142393303563686,291.8028372967317,0.04671741567476826
0.0482176076977218,278.626538904686,0.1530909044402667,56.17111024318471,292.0612440517662,0.04709120527739629
0.0486155847591437,278.8091652125,0.15435448161028126,56.207927706839996,292.36363581551433,0.047470803490198624
0.049012759837971,278.895542775329,0.1556155124855579,56.22534142350633,292.56498303325674,0.04784949315140277
0.0494090185284447,278.980836760398,0.15687363382781191,56.242536690896245,292.76500609297347,0.04822716621910428
0.0498030979660879,279.120392383087,0.15812483604232908,56.27067110443034,293.0214526292748,0.0486026208376978
0.0501891705675553,279.276703913655,0.15935061655198807,56.30218350899285,293.29337004192206,0.04897031038741836
0.0505842270044996,279.48857816626,0.1606049207392862,56.34489735831802,293.626291849387,0.04934641610358733
0.0509838763364352,279.585653300475,0.16187380736818174,56.36446770537576,293.84001367378784,0.049726750517797215
0.0513922512817026,279.6502044887,0.16317039781940573,56.37748122492192,294.0220580687628,0.050115239470881215
0.0518042848360603,279.820514052848,0.16447860435449146,56.41181563305416,294.31641566581453,0.050507055977377986
0.0522152154260524,279.991613757753,0.16578330897771634,56.44630933356301,294.6114361876021,0.05089767079360567
0.0526331053757206,280.098663977975,0.1671101095679129,56.467890657959764,294.84112647472625,0.051294744493433624
0.0530464921363615,280.2783673868,0.16842261253294774,56.50411886517889,295.1461515983762,0.05168738425348102
0.0534715936235675,280.323980132531,0.1697723097548268,56.51331439471826,295.3133500811187,0.052090990086110914
0.0538951588035844,280.44060885737,0.17111712920138045,56.5368267456458,295.55500000671185,0.05249297534589804
0.0543239275589785,280.555173824234,0.17247846999975674,56.559923042965565,295.79603276335826,0.052899734552357594
0.0547520151480968,280.715255369995,0.17383764809520733,56.592195482590995,296.08498128431484,0.05330568256620451
0.055183177312167,280.930317589533,0.17520658796613023,56.63555202604986,296.43294511743954,0.05371437964051514
0.0556086469375396,281.154585766096,0.1765574540266882,56.68076449044496,296.789211860833,0.05411751710414087
0.0560296419598617,281.265090271144,0.1778941132225609,56.70304219866264,297.02427257484436,0.054516254927861316
0.0564610462444344,281.283153370776,0.1792638218260792,56.706683719548444,297.1646945010237,0.05492468682578992
0.0568857233199183,281.310315422448,0.18061217154074058,56.71215958916552,297.3128561926083,0.05532658687107942
0.0573159109879087,281.41176081555,0.1819780173866101,56.73261098041488,297.5411322494047,0.05573353734065292
0.0577534907741088,281.628782098109,0.18336733320779544,56.776362470978775,297.89382736673565,0.056147310800832295
0.0581920072781453,281.916392051833,0.18475962310811134,56.83434463764953,298.3216727899417,0.05656179832966337
0.0586287650078442,282.077575228389,0.18614632889990532,56.86683916604322,298.61543510043674,0.0569744527608887
0.0590652966925794,282.154930576451,0.18753231699893957,56.88243400421253,298.8204952642232,0.05738672354051916
0.0595028885993563,282.124706248752,0.18892167130295623,56.876340779748396,298.9119412157976,0.05779982510226066
0.0599394339878553,282.088026560152,0.19030770291144056,56.86894615452665,298.9962232069186,0.05821176874424628
0.0603762543145488,282.15169803861,0.19169460744869243,56.881782324583774,299.1869607146709,0.0586238020421964
0.060815736778755,282.293549814547,0.19308996427254713,56.91037964261268,299.46144003440884,0.05903817516102772
0.0612529177748189,282.452660277808,0.19447801393505,56.94245631200609,299.7537098530834,0.059450208015206
0.0616939434204743,282.704337204508,0.1958782703600059,56.993194380428825,300.14548258872566,0.05986569241574499
0.0621377647917121,282.83220175337,0.1972874032136859,57.01897187347939,300.40676258144293,0.06028363643266686
0.062587609220487,282.973475262533,0.19871565927504622,57.047452612926655,300.68410855202757,0.060707074154076474
0.0630448797267087,283.065324889088,0.20016749313230012,57.06596949764015,300.9111442515223,0.06113731834318542
0.0635065100927924,283.143694308344,0.20163316954461585,57.08176877256215,301.1251621886473,0.061571477024273284
0.0639673465486239,283.27784661441,0.20309632529188087,57.10881387746505,301.3983787983419,0.06200470111452531
0.0644383191035048,283.37242346782,0.20459166315362773,57.12788057111251,301.6324661163729,0.062447260134329004
0.0649039359819924,283.488982670272,0.20606999674282586,57.15137890632684,301.8885334531035,0.06288459413716199
0.0653757074610934,283.536493152494,0.20756787118897155,57.16095701954279,302.07289198337577,0.06332751390900099
0.0658412265265986,283.682151666759,0.20904589422195055,57.19032177601862,302.360132476203,0.06376437142968297
0.0662989256145086,283.773771223894,0.2104990888260648,57.208792278737036,302.58766737361555,0.06419370445873439
0.066774189764035,283.865062646122,0.21200805250081112,57.2271966294582,302.81992220663386,0.06463931896108271
0.0672480490130709,283.903714118725,0.2135125556165001,57.234988766334965,302.9956850007739,0.06508341860373261
0.0677317821211002,284.027093065459,0.21504840823449314,57.259861961996535,303.26475424945806,0.06553656866093938
0.0682205285702332,284.142300030587,0.21660017821049038,57.28308768616635,303.52663792783545,0.06599420664772078
0.0686995665364224,284.216050467258,0.2181211237531411,57.29795577419922,303.7415699370526,0.06644255094970057
0.0691899238437718,284.318035837608,0.21967800820397546,57.31851602486177,303.9899790846229,0.06690128122379098
0.0696768661541438,284.38048122849,0.22122405003940654,57.33110501566359,304.1952219558985,0.06735660861590527
0.0701676233988821,284.500650547809,0.22278220429145068,57.355331150438296,304.46338505218466,0.06781529358646136
0.0706623042642316,284.586820666847,0.22435281603893534,57.372703046436364,304.6963811783981,0.06827743293509576
0.0711473272836539,284.639695068618,0.22589276412560114,57.383362525833384,304.8910486115844,0.06873034249397438
0.0716488770139229,284.64161978182,0.2274851845192052,57.383750548014916,305.0358721906114,0.0691984688966836
0.0721489549952733,284.686297250505,0.2290729321099927,57.39275752570181,305.2261160986027,0.06966500355116835
0.0726515569851615,284.794262637861,0.23066869342788776,57.41452334779277,305.4850092389426,0.07013367371072912
0.0731497078546931,284.994884738017,0.2322503224386506,57.454968763184226,305.84217729668484,0.07059797661393183
0.0736542336857134,285.159507753805,0.23385219195214005,57.48815676316708,306.16271277560674,0.07106800168752732
0.0741601381637359,285.306461719813,0.23545843866986146,57.517782682714305,306.464828339961,0.07153908940721984
0.0746593705581824,285.396587020292,0.23704350152222914,57.53595194329087,306.7041165666805,0.0720037467703928
0.0751619819696261,285.410512113908,0.23863929275356288,57.53875924216385,306.8625318793553,0.07247133113037703
0.0756498061487359,285.374587235275,0.24018813452223647,57.531516786631435,306.96311943939907,0.07292494979675182
0.0761439262774441,285.33408433752,0.241756965930885,57.523351402444035,307.06054181975816,0.07338421327535326
0.0766488412138695,285.353736009455,0.24336007085403566,57.52731317950614,307.2257692106282,0.07385329228129213
0.0771603336077141,285.433671881692,0.24498405920449226,57.54342825134911,307.45782922695815,0.07432825766767795
0.0776818836655278,285.492612625946,0.24663998063805076,57.55531070539071,307.6702165473223,0.07481233029612136
0.0782000062169965,285.611079912554,0.24828501973896389,57.57919371037088,307.9458681373588,0.07529298980151969
0.078712627726706,285.648834856479,0.24991259303229152,57.586805107066176,308.1330052551044,0.07576831876134314
0.0792158820632946,285.69504833639,0.2515104255509603,57.596121744616234,308.3266335914727,0.07623474231840638
0.0797226456040575,285.644193738751,0.2531193997928825,57.58586945773221,308.4165045650422,0.07670419852901686
0.0802304096623711,285.619686258768,0.2547315506780282,57.58092874976764,308.5350706949469,0.07717436066187365
0.0807352848338534,285.592733549542,0.2563345293474845,57.57549508358767,308.65014423914306,0.07764162877441637
0.081226003628518,285.646922690217,0.2578925615205447,57.586419614347754,308.8488806691276,0.0780955858417427
0.0817038501951457,285.680352104382,0.2594097243695876,57.59315898424341,309.0215367964149,0.07853743704052962
0.0821803264048843,285.694895004244,0.26092253633550766,57.5960908328556,309.17339472790195,0.07897782680130519
0.0826701811152263,285.662376564351,0.2624778250408435,57.58953511537317,309.2781369727319,0.07943037973001851
0.0831610067239731,285.60678669156,0.2640361963486146,57.57832819701849,309.3581346000292,0.07988362430411575
0.0836335779625051,285.558031783927,0.2655366100309537,57.56849920763968,309.44027169794754,0.08031981816334402
0.0841133998338415,285.465694757024,0.26706004447244674,57.54988406301604,309.4771848789669,0.08076250993880238
0.0845798253444424,285.364527137026,0.26854094546860463,57.52948867082445,309.50060900177505,0.08119265424171931
0.085047683786375,285.220225242812,0.2700263960217406,57.500397408950896,309.47754476874127,0.08162393421693678
0.0855126513708203,285.107642724059,0.27150266810235446,57.4777007731703,309.4879531794778,0.08205236514698394
0.0859586812933105,285.024464409335,0.2729188131062608,57.46093202492194,309.5247915062935,0.08246317409670727
0.0864261830816995,284.929743653762,0.2744031312843959,57.44183632059841,309.55513384420374,0.08289357830663581
0.086876607536378,284.772252995664,0.27583322892800016,57.410086203925864,309.5123002564185,0.08330808516971278
0.0873319497213372,284.56336507292,0.2772789403652456,57.36797439870068,309.41483856400276,0.08372694304799343
0.0877698100108367,284.280776790509,0.2786691467844065,57.31100460096661,309.232046559145,0.08412955436808905
0.0881963040002607,283.95409180608,0.2800232652008277,57.24514490810572,308.99779320912694,0.08452155862968061
0.0886347373630057,283.619168624482,0.2814152911275431,57.17762439469557,308.75767914662697,0.08492437663470026
0.0890688483712196,283.239767127199,0.2827935935786222,57.10113705284333,308.46760699815104,0.08532306359724925
0.0895276113256196,282.938693136381,0.28425016595884217,57.04044053629441,308.2695184844737,0.08574421819808316
0.089974149257036,282.546328989104,0.2856679238910893,56.961339924203365,307.96819456559723,0.0861539796818684
0.090426484596529,282.101712011967,0.28710408859397957,56.87170514161255,307.6111781278716,0.0865688899868454
0.0908831247053368,281.685132271142,0.2885539209394443,56.78772266586222,307.28555727497945,0.08698757435290796
0.0913106132018675,281.166898111213,0.28991119691592926,56.68324665922054,306.8404199898149,0.08737937137310213
0.0917288498194253,280.63973700149,0.2912390981766753,56.57697097950039,306.3824972902627,0.08776254046350056
0.0921615195930853,279.975799139325,0.29261282470804584,56.443121106487915,305.7787942372936,0.08815877810013374
0.092604832540366,279.150581126843,0.294020343315662,56.27675715517155,305.0012739456402,0.08856459994275959
0.0930767887510417,278.421154552667,0.29551880428455735,56.12970475781767,304.33570153878674,0.08899646175960733
0.093547376104816,277.595171983793,0.2970129191327908,55.963186671932675,303.563471942242,0.0894268853949105
0.0940104470566821,276.788711139797,0.29848316940496566,55.80060416578307,302.80974161429214,0.08985025336615211
0.0942529740841152,276.450580159822,0.29925319271706574,55.73243696022011,302.50686952716427,0.09007191500531592
0.0943718491815434,276.171236572967,0.29963062115140027,55.67612129311016,302.23402685911145,0.09018054495073331