File: example/data/02 processed data/test_ID_132.csv
Strain,Stress_MPa,Displacement(mm),Force(kN),True Stress (MPa),True Strain
2.97718773323336e-05,0.201398439609492,9.452571053015917e-05,0.04060192542527359,0.20140443561913096,2.977143415878577e-05
4.68641704904535e-05,0.686641318240118,0.00014879374130718985,0.1384268897572078,0.6866734971159218,4.6863072399559806e-05
5.56892133353899e-05,1.36580777627074,0.00017681325233986293,0.2753468476961812,1.3658838370313677,5.5687662748756385e-05
6.5266501922095e-05,2.02637311460199,0.0002072211436026516,0.4085168199037612,2.026505368886769,6.526437215659889e-05
8.71827350518907e-05,3.12919193822608,0.000276805183789753,0.6308450947463777,3.129464749737757,8.717893485815421e-05
0.000107251916527,4.45535913971644,0.000340524834973225,0.8982004025668343,4.455836985522991,0.00010724616545145757
0.0001349399902735,6.00833375045604,0.0004284344691183624,1.2112800840919378,6.009144514953886,0.00013493088669193636
0.0001567702839697,7.60155976596912,0.0004977456516037975,1.5324744488193747,7.602751464652244,0.00015675799679295627
0.0001888519403504,9.30576465886258,0.00059960491061252,1.8760421552266962,9.30752207057485,0.00018883411006747635
0.0002159770394373,10.9697713401312,0.0006857271002134275,2.21150590217045,10.972140558868544,0.00021595371975404454
0.0002491212749067,12.751419628215,0.0007909600478287724,2.5706861970481443,12.754596278129652,0.00024909024935456487
0.0002761784045488,14.6075880355299,0.0008768664344424398,2.944889747962828,14.61162233588786,0.0002761402743136219
0.0003162445785487,16.5412245226406,0.0010040765368921226,3.3347108637643452,16.546455595218443,0.00031619458377210623
0.0003546968254124,18.5192852786869,0.00112616242068437,3.733487912183279,18.52585401038416,0.00035463393536429695
0.0004048588883648,20.5639334730815,0.0012854269705582398,4.145688988173231,20.57225896432782,0.00040477695511850184
0.0004310200093078,22.6531445463784,0.0013684885295522648,4.566873940549885,22.66290850495163,0.00043092714686637995
0.0004714306196202,24.802229420476,0.001496792217294135,5.000129451167962,24.81392195085966,0.00047131953111804634
0.0005129144285694,26.9630626123397,0.0016285033107078448,5.435753422647685,26.97689235619199,0.0005127829329259475
0.0005596267588863,29.1683414934074,0.0017768149594640022,5.880337645070933,29.184664877819444,0.000559470226228878
0.0005969032350583,31.4036527256437,0.0018951677713101023,6.33097638948977,31.422397667548285,0.0005967251591815196
0.0006447002495862,33.6515059447814,0.002046923292436185,6.78414359846793,33.67320107906295,0.0006444925196578376
0.0006835270138352,35.9240131779057,0.0021701982689267597,7.24228105666579,35.94856821135817,0.0006832935156413968
0.0007367394336363,38.1542986524448,0.0023391477017952523,7.691906608332872,38.1824084288248,0.000736468174363279
0.0007872944092687,40.3877158541772,0.0024996597494281224,8.142163516202125,40.41951287707232,0.0007869846555927431
0.0008390142846561,42.6215995918444,0.0026638703537831174,8.59251447771583,42.65735972273686,0.0008386625089207238
0.0008913678327754,44.8245663430166,0.0028300928690618947,9.036632574752147,44.86452151957287,0.000890970800385755
0.0009382302275147,47.0363340576239,0.002978880972359172,9.482524946016978,47.08046496802824,0.0009377903646417311
0.0009847466723875,49.2466087732997,0.003126570684830312,9.92811632869722,49.29510420741558,0.0009842621274597613
0.001032978576161,51.4134073855821,0.0032797069793111745,10.36494292893335,51.466516333938834,0.0010324454209185514
0.0010826596832115,53.6138106995433,0.0034374444941965127,10.80854423702793,53.671856210851026,0.0010820740298873048
0.0011382230595174,55.7810268205277,0.0036138582139677447,11.245455007018384,55.84451807153838,0.0011375757747738302
0.0011862360576698,57.9376099077981,0.0037662994831016146,11.680222157412098,58.006337589765934,0.0011855330355893437
0.0012426941191744,60.0918208946391,0.00394555382837872,12.114511092359242,60.16649664707534,0.0012419226139346136
0.0013077541691063,62.22806899666,0.004152119486912503,12.545178709726656,62.30944801332581,0.001306899803408566
0.0013606235447328,64.3564951099115,0.00431997975452664,12.97426941415816,64.44406007241453,0.001359698735300801
0.0014223813575148,66.4948647822696,0.00451606081010949,13.405364740105552,66.58944583830636,0.0014213707313686299
0.001472813933352,68.5997279784036,0.0046761842383926,13.829705160446167,68.70076261359435,0.0014717304066691544
0.0015229036044645,70.690620915844,0.0048352189441747875,14.25122917663415,70.79827591723857,0.0015217451627512644
0.0015749349662508,72.7882535433501,0.00500041851784629,14.674111914339381,72.90289030898785,0.0015736960568074913
0.0016240213955311,74.8430306179262,0.005156267930811242,15.088354972573923,74.96457730095611,0.0016227040988038197
0.0016735955653394,76.8476631393119,0.0053136659199525945,15.49248888888528,76.97627504754854,0.0016721966648594168
0.001726016110203,78.8467061053675,0.005480101149894525,15.89549595084209,78.98279679034181,0.001724528256190698
0.0017742777773615,80.8379810530253,0.005633331943122762,16.296936980289903,80.98141008637445,0.001772705605917083
0.0018325148391019,82.7519767860992,0.005818234614148533,16.6827985200776,82.90362101152475,0.0018308378322315101
0.001880457383257,84.6400206825184,0.005970452191840975,17.06342816959571,84.79918263432985,0.0018786915366581002
0.0019413054240606,86.5023059288554,0.006163644721392404,17.43886487525725,86.67023332454885,0.0019394235258517968
0.0019895607779609,88.3483641248876,0.006316855470025857,17.81103020757734,88.52413856494749,0.001987584223132815
0.0020455725348033,90.2056652571407,0.006494692798000477,18.185462115839563,90.39018748847435,0.002043483200077613
0.0021006796375758,92.0254615822257,0.006669657849303165,18.552333054976703,92.21877759550999,0.002098476295243918
0.0021578276329036,93.7692780698411,0.00685110273446893,18.903886458879967,93.97161600917762,0.0021555028665528847
0.0022174173399711,95.5276875117491,0.007040300054408242,19.258381802368618,95.739512262485,0.0022149624984104076
0.0022833680769419,97.2750940705612,0.007249693644290532,19.610658964625138,97.49720891504343,0.0022807651535894807
0.0023293133329982,98.9668112267253,0.007395569832269285,19.95170914330782,99.19733593964003,0.0023266046880696476
0.0023893569369602,100.642624020069,0.007586208274848635,20.28955300244591,100.88309517192522,0.002386506962508798
0.0024428252460821,102.297601374213,0.007755970156310668,20.623196437041344,102.54749653746359,0.002439846398706857
0.002490078796543,103.896598566549,0.007906000179024025,20.94555427101628,104.1553092836725,0.0024869836873155954
0.0025407626953534,105.508541388828,0.008066921557747044,21.270521943987724,105.77661355482986,0.0025375404146958467
0.0025854647058715,107.039574525271,0.008208850441142012,21.579178224294633,107.31632156733757,0.0025821281418071085
0.0026316486973653,108.547732353867,0.008355484614134826,21.883222842539592,108.833391852318,0.00262819197319302
0.0026943951857378,110.055966956561,0.008554704714717516,22.187282938442696,110.35250122409047,0.0026907718101073738
0.0027461876674224,111.523980683805,0.00871914584406612,22.483234505855084,111.83024646418072,0.0027424237833833407
0.0028004616232609,112.952608537458,0.008891465653853358,22.771245881151536,113.26892798291436,0.0027965476362200744
0.0028575026700862,114.389358527895,0.009072570977523686,23.060894679223633,114.7162264253179,0.002853427770177234
0.0029085169280202,115.774734273851,0.009234541246464134,23.340186429608362,116.11146704832355,0.002904295376315473
0.0029633648241859,117.184652564457,0.009408683316790232,23.624425956994532,117.53191344180094,0.002958982713705394
0.0030177886989346,118.541818625123,0.009581479119117354,23.898030634824796,118.89955278572106,0.003013244314983774
0.003054448379225,119.862830583549,0.009697873604039373,24.164346645643477,120.22894541215423,0.0030497930290498175
0.0031104243496004,121.214102743865,0.00987559730998127,24.436763113163185,121.59113004055448,0.0031055969872895092
0.0031548028303167,122.53007677328,0.010016498986255522,24.702063477493247,122.91663500628327,0.003149836881519343
0.0032133358131751,123.786950183428,0.010202341206830941,24.955449156979086,124.18471922365615,0.003208184082860554
0.0032785468009731,125.036288524485,0.010409386093089593,25.207315766536176,125.4462258482325,0.0032731840844911425
0.0033383519740421,126.260354477316,0.010599267517583666,25.45408746262691,126.68185598092862,0.003332792047648789
0.0034071833080286,127.482450853558,0.010817807002990804,25.700462092077295,127.91680693217283,0.0034013920099293226
0.0034854185285049,128.699530736603,0.011066203828003057,25.945825396499167,129.14810246564227,0.003479358534340512
0.0035480402229639,129.865010980468,0.011265027707910382,26.18078621366235,130.32577726298237,0.0035417607770199216
0.0036213040983657,130.967621819192,0.011497640512311096,26.40307255874911,131.44189540483904,0.0036147629635484833
0.0036873854941775,132.070654938768,0.011707448944013562,26.62544403565563,132.55765035599572,0.0036806037544325734
0.0037609540716991,133.182567210422,0.011941029177644643,26.849605549621078,133.6834607288514,0.0037538993666828657
0.0038312269995618,134.250030699524,0.012164145723608714,27.06480618902404,134.764373041832,0.003823906541002253
0.0038988035156517,135.26069721198,0.012378701162194146,27.268556557935167,135.78805209379956,0.003891222878446481
0.0039682808888681,136.21519917422,0.012599291822156217,27.460984153522755,136.75573934587644,0.0039604280303051475
0.0040448882482888,137.115160329647,0.01284252018831694,27.64241632245684,137.66977583032664,0.004036729680747815
0.0041214276683831,137.994504663185,0.013085532847116343,27.819692140098102,138.5632390327887,0.00411295784922644
0.0041973986783754,138.81211060663,0.013326740803841894,27.98452149829661,139.39476037623277,0.004188614173343731
0.004266062358561,139.549604093055,0.013544747988431173,28.133200185159886,140.14493140622847,0.004256988511781489
0.0043476920407974,140.282802769014,0.013803922229531746,28.281013038233226,140.8927091940736,0.004338268132716576
0.0044294088593531,141.006439004983,0.014063373128446093,28.426898103404575,141.6310141751375,0.004419627899874495
0.0045195518175838,141.718293626949,0.014349577020828565,28.57040799519292,142.35879679849555,0.004509369311981704
0.0046082712641734,142.3699653154,0.014631261263750544,28.70178500758464,143.02604473544432,0.004597685690489751
0.0047015378620518,142.999564318751,0.014927382712014464,28.828712166660203,143.67188218465253,0.004690520152872734
0.0048010641403318,143.616291854787,0.015243378645553463,28.953044437925058,144.30580288357842,0.004789575788095223
0.0048994842184385,144.184706581477,0.015555862393542235,29.067636846825764,144.89113727591314,0.004887520806088805
0.0050034193551687,144.705194545534,0.01588585645266062,29.172567220379655,145.42921531671658,0.00499094384870254
0.0051096245175704,145.174615377042,0.01622305784328602,29.267202460011664,145.91640315110138,0.005096614684304783
0.0052077008168149,145.5562756742,0.016534450093387304,29.344145175918722,146.3142892099211,0.005194187637675346
0.0053166770539558,145.916276629045,0.016880449646309664,29.416721368415473,146.6920663487973,0.005302593423197861
0.005429960967563,146.251404346357,0.017240126072012526,29.48428311622557,147.04554376340897,0.005415271879632753
0.0055484979461504,146.553653381627,0.01761648097902752,29.545216521736002,147.3668060264158,0.005533161733896784
0.0056682816646266,146.839788841165,0.017996794285189455,29.60290143037886,147.67211812389098,0.005652277405396807
0.0057869892971143,147.092749123594,0.0183736910183379,29.653898223316553,147.94397328845534,0.005770308996095651
0.0059104470220857,147.31382900487,0.018765669295122096,29.698467927381795,148.18451958682388,0.005893048850407178
0.0060434098952057,147.532842032314,0.019187826417278096,29.7426209537145,148.4244434697199,0.006025221735840485
0.0061766712749947,147.704569956966,0.01961093129810817,29.777241303324345,148.61689253140463,0.00615767382816449
0.0063079603265873,147.846250592222,0.020027774036914678,29.805804119391954,148.7788588753924,0.00628814841635979
0.0064340302088032,147.9711637895,0.02042804591295016,29.830986619963202,148.9232147273534,0.006413420192845576
0.0065663639067474,148.082559693704,0.020848205403922994,29.853444034250728,149.05492366889553,0.006544899251192174
0.0066986929378746,148.173319205543,0.021268350077751855,29.871741151837472,149.1658867724866,0.006676356389304922
0.0068355526099903,148.264917247834,0.0217028795367192,29.890207317163338,149.27838988989745,0.006812296140644362
0.0069744214627041,148.339194251681,0.022143788144085515,29.90518156113889,149.37377431183015,0.0069502126816504825
0.0071117994260988,148.421136276321,0.022579963177863687,29.921701073306313,149.47667762811184,0.007086629844116405
0.0072565253333454,148.481672721988,0.02303946793337164,29.93390522075278,149.5591337416326,0.007230323433532815
0.0074055845995242,148.530176106436,0.023512731103489334,29.943683503057496,149.63012889117442,0.007378297891101547
0.0075457258091025,148.561928716569,0.023957679443900436,29.950084829260312,149.68293629633567,0.007517399227278082
0.0076976658334056,148.580738463673,0.024440089021062778,29.953876874276474,149.72446333764697,0.0076681899706901105
0.0078468611898946,148.577581772074,0.024913784277915355,29.95324048525012,149.74344943216968,0.007816234684921037
0.0080041496398951,148.561091398585,0.025413175106666942,29.949916025954735,149.7501966048054,0.007972286346948344
0.0081620623170944,148.551978069188,0.02591454785677472,29.948078778748304,149.76446857151635,0.008128932834312064
0.0083138699486353,148.549864053459,0.026396537086917075,29.947652593177338,149.78488830408693,0.008279500098119884
0.0084710725771635,148.542861195653,0.026895655432494114,29.946240817043645,149.8011785536609,0.008435394388613383
0.0086413524156122,148.49122022375,0.027436293919568734,29.935829997107998,149.7743851883277,0.008604229637202702
0.0087990778884179,148.447339124946,0.027937072295726832,29.92698356758912,149.7535388242348,0.008760591600369442
0.0089697265804847,148.400323050157,0.028478881893038918,29.917505126911653,149.7314333723725,0.008929737532347024
0.009123755098348,148.360268205104,0.0289679224372549,29.90943007014897,149.71387095853262,0.009082385087637024
0.009277307260788,148.278402488227,0.029455450553001902,29.892925941626565,149.65402678824904,0.009234537368568347
0.009438818233268,148.194641528378,0.0299682478906259,29.876039732121008,149.5934238129087,0.009394550924496396
0.0095981333553545,148.098269812929,0.030474073403250534,29.85661119428649,149.51973675629077,0.009552363907851392
0.0097588397272774,148.036977144735,0.03098431613410574,29.84425459237858,149.48164627840112,0.009711529795214875
0.0099185530313728,147.967148825982,0.03149140587460864,29.830177203317973,149.43476883851355,0.009869687038545835
0.0100698333900254,147.896266888057,0.031971721013330644,29.815887404632292,149.38555765462644,0.010019470433294325
0.0102347426001235,147.805286613771,0.03249530775539211,29.79754578133623,149.3180356772004,0.010182722264156096
0.0104016316958486,147.751330278724,0.03302518063431931,29.78666818419076,149.28818519885496,0.010347906953719828
0.0105679029075978,147.689051516501,0.03355309173162301,29.7741127857266,149.2498150734426,0.010512452939473095
0.010735776636975,147.615289764933,0.03408609082239562,29.759242416610498,149.20005454405165,0.010678557351652173
0.0108995598659061,147.538596871907,0.03460610257425187,29.743781129376455,149.14670264104413,0.01084058778941928
0.0110707958378457,147.44551288787,0.0351497767851601,29.725015398194593,149.07785205825806,0.01100996314338134
0.0112427598043494,147.359926821662,0.035695762378809344,29.70776124724706,149.01665908370444,0.011180029715341308
0.0114099266658455,147.253645138687,0.03622651716405946,29.686334859959302,148.93379843099785,0.011345324392964215
0.0115759888397048,147.134057847121,0.03675376456606273,29.662226061979595,148.83728005869978,0.011509499707245631
0.0117417624617452,147.008869124256,0.03728009581604101,29.63698801545001,148.7350123452828,0.011673362869425377
0.0119073518335832,146.89056471713,0.03780584207162666,29.613137846973405,148.6396423522506,0.011837017102797954
0.0120759905351621,146.768253040995,0.03834126994913967,29.58847981306459,148.54062507558035,0.012003657507824
0.0122420483845047,146.66216146679,0.03886850362080242,29.567091751704865,148.4576067436425,0.012167720512275253
0.0124081535261649,146.54134757728,0.039395887445573555,29.54273567157965,148.35965511594998,0.012331803317172686
0.0125760244409549,146.457739714836,0.039928877600031804,29.525880326510944,148.2995958290568,0.012497603047364332
0.0127411938795695,146.392016735103,0.04045329056763316,29.512630573796766,148.25722580274612,0.012660707806941281
0.0129149070656016,146.313637812018,0.04100482993328508,29.496829382902824,148.2032648467903,0.012832220815864161
0.0130865496319133,146.239310102136,0.041549795081324725,29.481844916590617,148.15307809192436,0.01300166054272603
0.013258250834383,146.139519584371,0.04209494639916602,29.461727148209192,148.0770739918368,0.013171129433549755
0.013441680232486,146.069095695105,0.04267733473814305,29.447529692133173,148.03250977128698,0.013352142316406258
0.0136164721817042,145.97784051701,0.04323229917691083,29.42913264822922,147.96554372155512,0.013524601058592189
0.0137914440789748,145.883111509204,0.04378783495074499,29.410035280255528,147.89505028365005,0.013697207563974379
0.0139722951462984,145.764721374371,0.044362037089497416,29.386167829073194,147.80138908333166,0.01387558245480085
0.0141487724173492,145.666883769531,0.04492235242508371,29.366443767937454,147.72789135673057,0.01404961276721042
0.0143120633238241,145.55714028826,0.045440801053141515,29.344319482113214,147.64036329730033,0.01421061257943295
0.0144876857862732,145.46901576479,0.045998402371417405,29.32655357818166,147.5765251568287,0.014383742000377411
0.0146549477714927,145.364862305183,0.04652945917448932,29.305556240724897,147.49517677007572,0.014548601762162723
0.0148234155121738,145.28187390509,0.04706434425115181,29.288825779266144,147.4354474883724,0.01471462249351499
0.0149978631828869,145.192582598767,0.047618215605665905,29.270824651911425,147.3701610877533,0.014886507252999536
0.0151764971355669,145.074786946334,0.0481853784054249,29.247077048380934,147.276514034868,0.015062486180359156
0.0153464748591602,144.94459346634,0.04872505767783363,29.220830042814143,147.1689820259424,0.015229908786589086
0.0155339312121557,144.832125584954,0.04932023159859435,29.198156517926726,147.08193786110098,0.015414514786004212
0.0157083149148457,144.725525691301,0.0498738998546351,29.17666597936628,146.99891982507654,0.015586216318355764
0.0158843089827707,144.58702626126,0.05043268102029697,29.14874449427002,146.88369126129385,0.015759473561264538
0.0160618761363398,144.457571423006,0.050996456732878864,29.122646398878004,146.77783104215877,0.01593424901085223
0.0162368255262195,144.328958985776,0.05155192104574691,29.096718131532445,146.67240311120895,0.016106417984014253
0.0164088659809087,144.238498891362,0.05209814948938512,29.07848137649858,146.60528908895782,0.016275695350767207
0.0165907116086669,144.171135955354,0.0526755093575174,29.064901008599367,146.5630376942832,0.016454589267173053
0.0167709388021984,144.096371166293,0.05324773069697992,29.049828427124673,146.51300258874178,0.01663185944827137
0.0169469423186106,144.008662457179,0.05380654186158865,29.03214635136729,146.4491689532211,0.01680494492731985
0.0171270573325675,143.919479386944,0.054378407030901806,29.014167044407912,146.38439656167745,0.0169820427265725
0.0173120905323169,143.836371962906,0.05496588744010616,28.997412587721847,146.32648025616783,0.017163943670086966
0.0174953328240583,143.752287693795,0.0555476817163851,28.980461199069072,146.26728181121774,0.01734405141899076
0.017676888443417,143.65520954473,0.05612412080784897,28.960890244217573,146.1945866581679,0.017522469361161065
0.0178577686104595,143.538589473317,0.05669841533820891,28.937379637820705,146.10186839080322,0.017700191874400237
0.0180379516184738,143.426591516559,0.057270496388654314,28.914800849738295,146.0137134351373,0.01787719800167335
0.018227814741446,143.316408329094,0.05787331180409105,28.892587919145353,145.92875326952617,0.01806367967480172
0.0184081493420156,143.223827255033,0.058445874160899525,28.873923574614654,145.86031285647869,0.018240770332357686
0.0185888539043807,143.113847591208,0.059019611146408725,28.85175167438754,145.7741699957748,0.018418192844566812
0.0187706425834396,143.009034890971,0.05959679020242072,28.830621434019754,145.69340637111205,0.01859664802624146
0.0189512504587871,142.902024452535,0.06017022020664904,28.809048129631055,145.61019650900272,0.01877391252581552
0.0191318979297252,142.792231337796,0.06074377592687751,28.786913837699675,145.52411773290845,0.01895118446052923
0.0193236277181752,142.685384007398,0.061352518005206254,28.765373415891435,145.44258324878183,0.019139297261228563
0.0194957891592264,142.584678480428,0.06189913058054381,28.74507118165429,145.36447930941853,0.01930818072391809
0.0196790058068119,142.475254297949,0.062480843436627784,28.72301126646652,145.27902565460533,0.019487877578283675
0.0198577563318044,142.345374240939,0.06304837635347897,28.696827446973302,145.17203399757506,0.019663162994823683
0.0200407386824053,142.217773328478,0.06362934531663683,28.671103103021164,145.06792255974756,0.019842566383314834
0.0202249409635472,142.105106260358,0.06421418755926236,28.648389422088176,144.97917364509235,0.02002313333935386
0.0204078791182721,142.003580980645,0.06479501620051392,28.627921925698033,144.90157289565977,0.020202428853387258
0.0205798315974599,141.893180559325,0.06534096532193519,28.605665200759923,144.81331832006387,0.02037092813311533
0.0207653999670677,141.788595865256,0.06593014489543994,28.58458092643561,144.73289276916697,0.020552738017351954
0.0209453122563929,141.645204064546,0.06650136641404746,28.555673139412477,144.61200709329842,0.020728974825743953
0.021124546580768,141.529877509985,0.0670704353939384,28.532423306012976,144.51963200001506,0.0209045166408876
0.0212993562917334,141.396839828709,0.06762545622625354,28.505602909467736,144.40850149874584,0.02107569531848387
0.0214761837971158,141.269658741074,0.06818688355584267,28.47996320220052,144.30359189715315,0.02124882007189301
0.0216413849010852,141.136313497075,0.0687113970609455,28.453080801010323,144.19069878098543,0.021410534803204075
0.0218186728089183,141.011191708663,0.0692742861683156,28.427856248466465,144.08786876294997,0.021584052174007492
0.0219993563564997,140.889378465698,0.06984795643188654,28.40329869868472,143.98885410941065,0.021760861993153656
0.0221809358065956,140.807989466378,0.07042447118594103,28.386890676421803,143.9312424417875,0.021938517018270175
0.0223627586944717,140.719736203675,0.07100175885494764,28.369098818660884,143.8666177079475,0.022116378600631464
0.0225478813600462,140.635713459544,0.07158952331814668,28.35215983344407,143.80675084161524,0.022297435574422014
0.0227361732004342,140.549692008502,0.07218734991137858,28.334817908914005,143.745254149275,0.022481558499059553
0.0229290162482635,140.458380559455,0.0727996265882366,28.316409520786127,143.67895304950756,0.022670096730433093
0.0231087704202718,140.324937245446,0.07337034608436296,28.289507348681916,143.56767400449004,0.022845806263895096
0.0232884386970255,140.191237245737,0.07394079286305597,28.26255342874058,143.45607228019452,0.023021400988531195
0.0234667668988192,140.077969974855,0.07450698490375096,28.239718746930766,143.3651470439147,0.023195655537152565
0.0236501381608716,139.972755030578,0.07508918866076732,28.218507414164527,143.28313002580902,0.023374806285299577
0.0238298873540745,139.880672420776,0.07565989234918653,28.19994356002844,143.2140130875753,0.02355038718613844
0.0240061106109177,139.773648085591,0.0762194011896637,28.17836745405514,143.12906974202517,0.023722493992985566
0.024191393353811,139.671224133903,0.07680767389834992,28.157718785394845,143.05006565713452,0.023903416724352977
0.0243811570542109,139.61301862693,0.0774101736471196,28.145984555189088,143.01694556088566,0.0240886810450186
0.0245663188410541,139.546597374424,0.07799806232034677,28.132594030683883,142.9747435787083,0.024269419487097287
0.0247530175551329,139.459582896523,0.07859083073754695,28.115051911939037,142.91162840019214,0.02445162507241487
0.0249407986932092,139.384445615521,0.0791870358509392,28.09990423608903,142.8608050145823,0.024634853549871515
0.0251269168574644,139.269492299035,0.07977796102244947,28.076729647485454,142.7689052528141,0.02481642624949955
0.0253144567114425,139.158308079313,0.08037340005882994,28.054314908789504,142.68102504522435,0.02499935257640511
0.0254965464397691,139.063323769265,0.08095153494626689,28.035166071883822,142.60895826181672,0.025176930840345946
0.0256772648943119,138.898643112946,0.08152531603944028,28.00196645156991,142.4651803656176,0.025353140632038716
0.0258722217278688,138.729053577738,0.08214430398598344,27.96777720127198,142.31828241199864,0.025543198766551187
0.026055886583776,138.568208128779,0.0827274399034888,27.935350758761846,142.17872564389953,0.025722215619679512
0.0262359863101556,138.412391499777,0.08329925653474402,27.903938126355044,142.04377710832102,0.02589772645146759
0.0264195651994254,138.311146673246,0.08388211950817563,27.88352716932639,141.9652670305871,0.026076596101199466
0.0266025796268199,138.235410883828,0.08446319031515317,27.868258834179723,141.9128294091112,0.026254883927602533
0.0267920156352348,138.144447723994,0.0850646496418705,27.849920661157196,141.84561592733613,0.026439394015813977
0.0269669944151636,138.11581728121,0.08562020726814443,27.84414876389194,141.84038575447815,0.026609792567441386
0.0270977508503955,138.086709359191,0.0860353589500057,27.838280606812905,141.82854860515732,0.026737107381358496
0.0272800264755195,138.037131696981,0.08661408405977442,27.82828575011137,141.8027883042794,0.0269145583133283
0.0274653524244199,137.969520236117,0.08720249394753318,27.81465527960119,141.7589017332301,0.027094946551507158
0.0276541915466674,137.886995744945,0.087802058160669,27.798018342180914,141.70014913707024,0.027278720895275135
0.0278434941017766,137.777836890885,0.0884030937731407,27.776011917202418,141.6140532797119,0.027462912351160586
0.0280341129283123,137.647740983478,0.08900830854739154,27.749784582269168,141.50657329853593,0.027648350264808868
0.0282328452053461,137.518124715987,0.08963928352697387,27.72365394274298,141.40065264402295,0.027841644503055988
0.0284706664892078,137.407262561971,0.09039436610323476,27.701304132493355,141.3193389075679,0.028072909032502567
0.0286661381574488,137.305846761904,0.09101498864989994,27.68085870719985,141.24187513500627,0.02826295149189355
0.0288626884738295,137.201251279978,0.09163903590440867,27.659772258043567,141.1612482538916,0.02845400623137949
0.0290567324763986,137.086034655852,0.09225512561256555,27.636544586619763,141.0693068910974,0.028642588934053675
0.0292444946416278,136.958727922331,0.09285127048716825,27.610879549141934,140.96401670717975,0.02882503275061089
0.0294335237137176,136.804137906817,0.09345143779105337,27.57971420201431,140.830765744032,0.029008673971759293
0.0296364493745311,136.658850863135,0.09409572676413623,27.550424334008017,140.7089339783219,0.02920577816357674
0.0298227998485653,136.502323043912,0.09468738951919482,27.51886832565266,140.57320450291482,0.029386748459165876
0.0300113332142117,136.355132720771,0.09528598295512215,27.48919475650743,140.44733204432214,0.029569805301604486
0.0301996582576044,136.201999796481,0.09588391496789396,27.458323158970572,140.31525364433705,0.02975262642497178
0.0303823689110771,136.046135228358,0.09646402129266979,27.426900862036973,140.17953909779226,0.029929965304514014
0.030578488902664,135.913292272556,0.0970867022659582,27.400119722147288,140.06931537203687,0.030120284292315436
0.0307638130266922,135.830460047672,0.09767510635974773,27.383420745610678,140.0091229239082,0.030300093462635416
0.0309407899524132,135.732872351147,0.09823700809891191,27.363747065991234,139.93255464420156,0.03047177365959467
0.0311208535749458,135.610557115329,0.0988087101004529,27.339088314450322,139.83087340653196,0.030646417927437507
0.0313159657029263,135.498127628765,0.099428191106791,27.316422529959024,139.74138234639813,0.03083562336320041
0.031497567657459,135.395127226252,0.10000477731243232,27.295657648812405,139.6597444065511,0.031011695462849646
0.0316890726033197,135.303130623958,0.10061280551554004,27.27711113378993,139.59076135375705,0.031197335426460984
0.0318724457952162,135.206003603105,0.10119501539981142,27.257530326385968,139.51534962413277,0.03137506038473751
0.0320628999465615,135.107479477106,0.10179970733033276,27.237667862584573,139.4394170736126,0.03155961476264363
0.0322589173172706,135.003798102806,0.10242206248233414,27.216765697525688,139.35887446332194,0.031749524465345035
0.0324599847222086,134.927999731385,0.10306045149301231,27.201484745847214,139.30776054126395,0.03194428938503939
0.0326477535537555,134.829662916151,0.1036566175331737,27.18166004389604,139.2315485227734,0.03212613833033559
0.0328471403804143,134.720186628636,0.1042896707078154,27.159589624333016,139.1453595109024,0.03231920278947673
0.033040770663568,134.61113554433,0.1049044468568284,27.137604925736934,139.0587912026127,0.03250665757120584
0.0332347213712591,134.509692603632,0.10552024035374764,27.117154028892216,138.98008475904743,0.03269438733813033
0.0334318205282909,134.399080047041,0.10614603017732359,27.094854537483467,138.89228597034108,0.03288512846993199
0.0336196809221609,134.292385798504,0.10674248692786086,27.073344976978404,138.80725295932544,0.03306689500478174
0.0338116888328965,134.16990220062,0.10735211204444639,27.048652283644987,138.7064131845675,0.033252640383415896
0.0340009015058907,134.051629084496,0.10795286228120296,27.024808423434393,138.60950532170213,0.03343564794842079
0.0341885897414764,133.931331659732,0.10854877242918756,27.00055646260197,138.5102550113762,0.033617147986879876
0.0343741412875829,133.800510074666,0.1091378985880757,26.974182831052662,138.39978771232322,0.0337965494077996
0.0345615296091281,133.600945702799,0.10973285650898172,26.933950653684285,138.21839874351383,0.0339776940655999
0.0347522343279645,133.409216252693,0.1103383439912873,26.895297996542908,138.04548459741667,0.03416201093692189
0.0349377947404797,133.247930491307,0.11092749830102304,26.86278278704749,137.90331933640596,0.03434132321113319
0.0351243927072218,133.105529416876,0.11151994684542921,26.834074730442204,137.78078030361704,0.03452160568610328
0.0353164039771783,132.973569883932,0.1121295826275411,26.80747168860069,137.66971819624047,0.03470708432506214
0.0355121203518149,132.860045461017,0.11275098211701229,26.784585164941028,137.57818738537622,0.034896106615338755
0.0357013090156411,132.753636593255,0.11335165612466049,26.763133137200214,137.4931151962209,0.0350787905065011
0.0358980632317267,132.684280655155,0.11397635076073227,26.74915098007925,137.44738935196992,0.03526874443225831
0.0360866085388884,132.628926593183,0.11457498211097066,26.73799160118569,137.41505474808417,0.03545073931885274
0.0362877712446144,132.545671776558,0.11521367370165071,26.721207430154095,137.3554587934495,0.03564487673757408
0.036486221587632,132.455518794078,0.11584375354073159,26.70303258888612,137.28832020330347,0.03583635959514591
0.0366726262565713,132.335435059032,0.11643558836461387,26.67882370790085,137.18852300945264,0.03601618630705988
0.0368655049526299,132.211815067717,0.11704797822459992,26.653901917651748,137.0858703908921,0.03620222455126846
0.0370701432244911,132.076783467225,0.11769770473775923,26.62667954699256,136.97288874698512,0.03639956748493685
0.0372673119674445,131.954148326382,0.11832371549663627,26.601956302598616,136.87172473745974,0.03658967034698919
0.0374633800586373,131.794246255271,0.11894623168617342,26.56972004506263,136.73170419227384,0.036778676170761894
0.037656462898823,131.648443648422,0.119559269703763,26.540326239521875,136.6058583823566,0.03696476936571467
0.0378523374176331,131.501133228768,0.12018117130098509,26.510628458919626,136.47875849454445,0.03715351780114588
0.0380561874972197,131.353156635655,0.12082839530367255,26.480796377748053,136.35195699293317,0.0373499138155127
0.0382491225595347,131.176741993564,0.12144096412652267,26.445231185902504,136.1941372750363,0.03753575841354547
0.0384405477453152,131.02152063973,0.12204873909137574,26.41393856096957,136.05805965954534,0.037720114496266756
0.0386329972090072,130.879049879476,0.12265976613859786,26.385216455702366,135.93529984818733,0.03790542277743978
0.0388237224379936,130.762949692591,0.12326531874062967,26.361810658026346,135.8396541566295,0.03808903693191883
0.03902026797255,130.632550699266,0.12388935081284626,26.335522220972024,135.7298678334891,0.0382782191188872
0.0392158477804642,130.495720822155,0.12451031670297383,26.307937317746447,135.61322114591857,0.03846643623917414
0.0394136287489784,130.378601074015,0.12513827127800642,26.284325976521423,135.51729485355736,0.03865673563725751
0.0396193091126618,130.290592325697,0.12579130643270123,26.266583412860513,135.4526155775206,0.03885459721088507
0.0398276781002864,130.189562867686,0.12645287796840932,26.246215874125497,135.37471086959718,0.0390550052901517
0.0400342529410808,130.067829476622,0.12710875308793154,26.221674422486995,135.27499786138645,0.03925364813118903
0.0402425553056441,129.942811121059,0.12777011309542,26.196470722005497,135.1720418841691,0.03945391221569313
0.040432925676937,129.806831665914,0.12837453902427498,26.169057263848263,135.05530164302056,0.03963690122437236
0.0406342757779364,129.652254288047,0.12901382559494806,26.13789446447028,134.92057974401862,0.039830407807424514
0.0408395988153175,129.47573681934,0.12966572623863304,26.102308542778943,134.76347396735946,0.04002769400981527
0.041039042474404,129.293191332667,0.1302989598562327,26.065507372665667,134.59926010341957,0.040219293708031324
0.0412386348643381,129.112694030925,0.13093266569427345,26.029119116634483,134.43712527641733,0.040410999543153574
0.0414350763586752,128.927378194708,0.13155636743879376,25.991759444053137,134.26949395492954,0.04059964310633984
0.0416388408821994,128.707422861984,0.1322033198009831,25.94741644897598,134.06665076289212,0.040795281410374695
0.0418468928791913,128.501360236634,0.13286388489143236,25.905874223705418,133.8787428932868,0.04099499671853545
0.0420484975889653,128.32877988478,0.13350397984496482,25.87108202477165,133.72481227636,0.04118848503980632
0.0422439007645773,128.158702999603,0.13412438492753292,25.836794524719966,133.5726265312352,0.04137598577275435
0.0424383805301828,127.985136087386,0.13474185818333037,25.801803435217018,133.41661799486974,0.04156256553880761
0.0426358878647975,127.801668487688,0.13536894397073207,25.764816367117902,133.25060609426308,0.04175201426799586
0.0428395848110709,127.642083881123,0.13601568177515008,25.7326441104344,133.1102177590102,0.041947362474762294
0.0430356861243199,127.508998105281,0.13663830344471567,25.70581401802465,132.99643532576638,0.04213539031761485
0.0432491775411211,127.376890713416,0.13731613869305948,25.67918116782467,132.8858364745165,0.042340052127000906
0.0434552977638395,127.225287022199,0.13797057040019042,25.64861786367532,132.7538997528386,0.04253760786699983
0.043656697524795,127.071715308839,0.1386100146412241,25.617657806261942,132.61924674803385,0.04273060159425079
0.0438742180211077,126.908032917862,0.13930064221701693,25.584659436240983,132.4760236227302,0.04293900137935598
0.0440835191962856,126.73936734547,0.13996517344820678,25.550656456846752,132.32648467876913,0.04313948549083785
0.0442884410389162,126.557586692954,0.14061580029855894,25.514009477299528,132.16262490923242,0.04333573582094204
0.0445031015666716,126.337435702089,0.14129734747418232,25.46962703754114,131.95984343481192,0.043541271437237634
0.0447004758588791,126.108171226381,0.14192401085194115,25.423407319238407,131.74526648989325,0.04373021835933497
0.0449149045051155,125.87059481601,0.1426048218037417,25.375511914907616,131.5240605621732,0.0439354510054995
0.0451347154468156,125.643150674512,0.14330272154363952,25.329659175981618,131.31401852804748,0.044145791411212415
0.0453423548133642,125.403487373498,0.1439619765324313,25.2813430544972,131.0895767928204,0.0443444440251879
0.0455502411465217,125.146515796044,0.1446220156402064,25.22953758448247,130.84696976920077,0.04454329339147679
0.0457699903299779,124.855759309963,0.14531971929767984,25.170921076888543,130.57040620622206,0.04475344694037635
0.0459839842650524,124.588141921247,0.14599915004154138,25.116969411323396,130.31720107896575,0.04495805411542663
0.0462109904008557,124.282639367924,0.14671989452271686,25.055380096573483,130.02586322274814,0.04517505696596664
0.0464199327626694,123.966573171366,0.14738328652147534,24.991661151347387,129.72109316279932,0.045374750433357584
0.0466382040100424,123.648409451752,0.1480762977318846,24.9275193454732,129.41514919728007,0.04558331726132047
0.0468576099582507,123.311994544184,0.14877291161744596,24.859698100107494,129.09009988770933,0.04579292451016016
0.0470905467565174,122.937044169447,0.14951248595194275,24.78410810456052,128.72621679601642,0.04601541024695421
0.047314580887317,122.53072615872,0.15022379431723146,24.702194393597953,128.32821611273846,0.046229346059750875
0.0475469688893046,122.048356635009,0.1509616262235421,24.604948697617814,127.85138605092453,0.04645121084405197
0.0477848552979054,121.520665087511,0.15171691557084965,24.49856608164222,127.32751248442295,0.04667827407754734
0.0480356597693948,120.922934609345,0.15251321976782847,24.378063617243953,126.73154755455627,0.046917611817476335
0.0482850285680326,120.175472568319,0.1533049657035035,24.227375269773113,125.97814869445709,0.04715552274513291
0.0485474728369547,119.382666321558,0.15413822625733117,24.067545530426095,125.17839307200705,0.04740584724183609
0.0488149012157053,118.498118494945,0.15498731135986432,23.889220688580913,124.28259244352269,0.04766086123799475
0.049088459474057,117.525413921193,0.15585585883013098,23.69312344651251,123.29455543963527,0.047921653288789924
0.0493569084340352,116.348250428679,0.15670818427806177,23.455807286421688,122.09084037154751,0.0481775083761304
0.0496371109739378,115.143444126312,0.1575978273422525,23.2129183358645,120.85883204033115,0.048444495836767326
0.0499225081695692,113.883712509322,0.15850396343838222,22.958956441879312,119.56907307744949,0.04871635970268184