File: example/data/02 processed data/test_ID_090.csv
Strain,Stress_MPa,Displacement(mm),Force(kN),True Stress (MPa),True Strain
0.0017516945150122787,95.5849836672474,0.005561630085163985,38.53986541463415,95.75241935885485,0.001750162087477548
0.001853744628452379,101.457822224252,0.0058856391953363025,40.907793920818406,101.64589911721468,0.0018520285643144076
0.0019568665090901787,107.379895475157,0.006213051166361317,43.29557385558331,107.59002359636193,0.001954954339989649
0.0020638013026997785,113.161945857159,0.0065525691360717965,45.62689656960651,113.39548962843503,0.00206167459036294
0.002172509167785879,119.075539598866,0.006897716607720165,48.01125756626278,119.33423230030357,0.0021701526821176816
0.002277853299907579,124.911070186159,0.0072321842272065635,50.36414349905931,125.19559927957751,0.0022752629249964407
0.002378951497678379,130.759018960971,0.007553171005128852,52.72203644506351,131.07008832496317,0.002376126272393054
0.002490554404946279,136.674763964423,0.007907510235704436,55.10726483045535,137.01515989985958,0.0024874581142456634
0.002582846796745279,142.421208291025,0.00820053857966626,57.424231182941284,142.78906045264807,0.0025795169803289127
0.002699670648454779,148.186563784211,0.008571454308843922,59.74882251779387,148.5866187009546,0.0026960330829981054
0.002807221702563079,153.807987189069,0.008912928905637775,62.01538043463262,154.23976030873368,0.002803288814326184
0.002909454510396379,159.471877602565,0.009237518070508502,64.29906104935421,159.93585377613718,0.0029052302391889065
0.003014969910028479,165.069009471106,0.00957252946434042,66.55582461874994,165.56668756773962,0.0030104340030444776
0.0031061801630312786,170.576692154878,0.00986212201762431,68.7765222768468,171.10653409232498,0.0031013659520567833
0.0032092102397990787,175.899660298273,0.010189242511362074,70.92274303226368,176.46415928927942,0.003204071715419153
0.0033068414248933788,181.020220427339,0.010499221524036477,72.98735287630309,181.61882559099146,0.00330138584863055
0.003408700883743779,186.003104711952,0.010822625305886497,74.99645181985905,186.63713365936272,0.003402904431399621
0.003502215938611779,190.920251905109,0.011119535605092398,76.97904556813995,191.58889585433485,0.0034960974616948925
0.003607722546380079,195.803113722531,0.01145451908475675,78.9478154529245,196.50951703055918,0.0036012303254632024
0.0037219346129658787,200.694688163514,0.011817142396166665,80.92009826752884,201.44166067002817,0.0037150253529034567
0.0038298081667933787,205.585616033327,0.012159640929568977,82.89212038463745,206.37296950458668,0.0038224931223588337
0.003945682595902679,210.410810416626,0.012527542241991005,84.8376387599836,211.24102468927668,0.003937918805928727
0.0040582171704669785,215.004710217211,0.012884839516232656,86.68989915957947,215.8772460239458,0.00405000481800788
0.0041675448110694785,219.308063429927,0.013231954775145594,88.42501117494656,220.22203961170007,0.0041588846489313425
0.004287805399073678,223.256859270552,0.013613782142058927,90.01716565788658,224.2141412371125,0.00427863895478168
0.0044077079754918785,226.954093982652,0.013994472822186714,91.5078906938053,227.95444135276986,0.0043980224808186615
0.004536636638597678,230.373343332832,0.014403821327547629,92.88653203179787,231.41846348275197,0.004526377120038546
0.004683668441163979,233.558401965185,0.014870647300695632,94.1707476723626,234.65231208163803,0.004672734194429026
0.004848404401917878,236.494747056498,0.015393683976089262,95.35468201318,237.6413692291572,0.004836688742205816
0.005034435436401278,239.250815117782,0.01598433251057406,96.4659286554897,240.45530789959886,0.005021805039859918
0.005242548557526578,241.70860400399,0.016645091670146887,97.45690913440876,242.97577309725284,0.00522885424106514
0.005487988149264578,243.948654942406,0.017424362373915033,98.36009767277811,245.28744226975897,0.005472984012286659
0.0057562191388649785,245.893165493822,0.018275995765896304,99.14412432710904,247.30858043915362,0.0057397154119034465
0.006056972173276879,247.322402366464,0.01923088665015409,99.72039263415829,248.82042727542563,0.006038702452997644
0.006376034328984079,248.42671078372,0.02024390899452445,100.16564978799592,250.0106880199136,0.006355793414385863
0.006710285790794578,249.265448389869,0.021305157385772783,100.50382879079518,250.93809078633558,0.006687872035696368
0.007054791678638078,249.998737994079,0.0223989635796759,100.79949115921265,251.76242701054966,0.007030023059228168
0.007410451395191479,250.663977753164,0.023528183179732945,101.06771583007573,252.5215109768292,0.007383128898578579
0.007772346372046378,251.216009655758,0.02467719973124725,101.29029509320162,253.16854749700587,0.0077422972888070785
0.008141811175053278,251.670476090198,0.025850250480794156,101.47353595956784,253.71952958486017,0.008108845443410336
0.00851127577555428,252.049377611719,0.027023300587384835,101.6263090530451,254.19463937362917,0.00847525908889594
0.008880160455494678,252.342461507866,0.0281945094461956,101.74448047997157,254.58330305579034,0.008840963708660478
0.009244981866169778,252.554162430441,0.029352817425089044,101.82983829195382,254.88902108233611,0.009202508597030812
0.009613744180813578,252.862103536072,0.03052363777408311,101.95400014574423,255.29305511249018,0.009567826203445986
0.009985565638531178,253.263862017099,0.03170417090233649,102.11598916529432,255.79284493513867,0.009936039304045626
0.010361385341122378,253.599040088181,0.03289739845806355,102.25113296355458,256.2266774646734,0.01030807412385089
0.010726070882814378,253.867380210275,0.034055275052935645,102.35932770078288,256.59037972524476,0.010668954643421416
0.011095236253422179,254.020819883597,0.03522737510461542,102.42119457706632,256.8392408934935,0.011034135654628985
0.011457029666951378,254.164401673087,0.03637606919257062,102.47908675458868,257.0763707633385,0.011391894930850603
0.011821652437039979,254.384548215218,0.03753374648760193,102.5678498403759,257.39179392957175,0.01175232256473123
0.012192090401390078,254.633458154197,0.0387098870244135,102.66821032777223,257.73797229523154,0.012118365502727073
0.012550399455278978,254.970435615985,0.03984751827051075,102.80407964036515,258.17041643225207,0.01247229599949311
0.012910756045752278,255.262087126874,0.040991650445263476,102.92167352955559,258.5577136614986,0.012828122714112367
0.013257493616535778,255.469208469404,0.04209254223250109,103.0051848548637,258.85608986990854,0.013170382123444332
0.013603745951792978,255.8001919112,0.0431918933969427,103.13863737859583,259.28003273637984,0.013512045708366742
0.013960711319979278,256.014710358892,0.044325258440934205,103.22513121670525,259.58885782388063,0.013864158185574757
0.014312647284505578,256.291274674451,0.04544265512830521,103.33664194873866,259.9594812909628,0.014211188300194444
0.014675739169852079,256.578589470474,0.04659547186428035,103.45248727449513,260.3440699261112,0.014569092654547802
0.015042202117102678,256.691526273354,0.047758991721801,103.49802339341633,260.55273209330534,0.01493019006988644
0.015390240645131179,256.996593143507,0.04886401404829149,103.62102635546204,260.95183255696446,0.015273012144738378
0.01574080991092058,257.244369669299,0.04997707146717284,103.72092985066135,261.293604392918,0.01561820825522535
0.01609908228710488,257.420690869735,0.05111458626155799,103.79202255867715,261.5649277544502,0.01597086633746202
0.01645849464903568,257.697163997701,0.05225572051068828,103.90349652387306,261.9384713924288,0.0163245216235461
0.01681724360259368,257.927224355866,0.053394748438234926,103.99625686028516,262.2648493195994,0.01667739944580283
0.01716462786674608,258.200909401731,0.054497693476918796,104.10660667077795,262.63283192646713,0.01701897994108923
0.01751503769187988,258.542336316233,0.055610244671718614,104.24427000270515,263.07071508175846,0.017363417283762308
0.01787400549259228,258.721534864785,0.05674996743898049,104.3165228574813,263.3459250000101,0.017716143761912835
0.01823056244808118,258.986483656447,0.05788203577265774,104.42335021027942,263.7079529199548,0.01806637818969983
0.018589825120652482,259.215930666089,0.05902269475807163,104.51586324456709,264.03470948565877,0.018419146336061325
0.01893383541095128,259.402755368681,0.06011492742977031,104.5911909646522,264.31424444397885,0.018756821230573005
0.01928271979400658,259.593210185517,0.06122263534597089,104.66798234680047,264.598873317951,0.01909916403568066
0.01962720310444138,259.686511720542,0.06231636985660138,104.70560152572254,264.783431629565,0.019437073336963394
0.01996474403562858,259.903202837306,0.06338806231312073,104.7929713840018,265.09210375599287,0.01976806202785529
0.02030441319475238,260.138712551429,0.06446651189333881,104.88792890073618,265.42067645902415,0.020101027079116457
0.02065154264741988,260.35991853395,0.06556864790555812,104.97711915288865,265.7367524952326,0.020441190672574865
0.02099307591289088,260.583025480817,0.06665301602342855,105.06707587386542,266.0534647163466,0.020775757487535705
0.02133937332303478,260.700911680092,0.06775251030063542,105.1146075894131,266.264105760089,0.021114877020785152
0.02168049787962128,260.894295505308,0.06883558076779756,105.19257994774019,266.5506137258161,0.02144881852039065
0.02203214055925548,261.120227679483,0.06995204627563614,105.28367580036755,266.8732652385821,0.021792939975129894
0.02237677143361248,261.400940331776,0.07104624930171961,105.39685914177208,267.2502494261115,0.022130084736728076
0.02272782133009398,261.681515948587,0.07216083272304838,105.50998723047027,267.62896668845457,0.022473392263562073
0.02307580167554408,261.974078176108,0.07326567031985244,105.62794832060673,268.01934004823335,0.022813581658959615
0.02341613479623708,262.15964091038,0.07434622797805272,105.70276721506522,268.2984064000706,0.023146183139341886
0.02376083011905428,262.30703301363,0.07544063562799734,105.76219571109563,268.5396658641001,0.023482935000057464
0.02409568352511018,262.429204585121,0.07650379519222482,105.8114552887208,268.7526156465505,0.023809963194473604
0.02444005319918378,262.573115710785,0.0775971689074085,105.86948025458851,268.990416627432,0.024146173758091135
0.02478574881686988,262.791534087629,0.07869475249356186,105.957546544132,269.30501904272484,0.024483565196970498
0.02512938210992608,263.060047802822,0.0797857881990153,106.06581127409784,269.67058426191454,0.024818831073192046
0.02547975930959388,263.347579324217,0.08089823580796056,106.1817439835243,270.0576122601622,0.025160560948476796
0.02582865507559548,263.558148850467,0.08200597986501565,106.26664561650828,270.36550136948813,0.02550072995175225
0.02617427051684938,263.687121647484,0.08310330889099678,106.31864744826555,270.5889397012946,0.025837586629889924
0.026507677623883782,263.784058505658,0.08416187645583101,106.3577323894813,270.77636129084567,0.026162436868153487
0.02684128673564858,263.980295333714,0.08522108538568424,106.43685507855349,271.06586613332746,0.02648737833742235
0.02717174422563098,264.17106940241,0.08627028791637836,106.51377518305172,271.3490581320237,0.026809146006713885
0.02750911064688748,264.385018602579,0.08734142630386775,106.60003950055986,271.6580153326967,0.027137534158565506
0.02784747976764718,264.537016266873,0.0884157482622798,106.6613249588032,271.9037054751585,0.027466790040872824
0.02818358880640088,264.703452189086,0.08948289446032279,106.72843192263949,272.163745441218,0.0277937394210501
0.02852145228639238,264.917001478775,0.09055561100929581,106.81453499624207,272.472819096306,0.028122287731362227
0.02886289673659168,265.144028539301,0.09163969713867857,106.90607230704619,272.79685325535473,0.02845420865172518
0.02920349325138388,265.344362012064,0.09272109107314382,106.98684676326421,273.09334429737606,0.02878519556211698
0.02955042645975618,265.567819575386,0.09382260400972586,107.07694485279565,273.4154618978262,0.02912222779150069
0.02989312238777628,265.685230732084,0.09491066358118969,107.12428503117626,273.62739185098275,0.029455032185556534
0.03023751682354808,265.889939017769,0.09600411591476515,107.20682341196445,273.92979052203094,0.02978937451552813
0.03057586514184488,266.101525407965,0.09707837182535749,107.2921350444915,274.23780976287816,0.030117738378358135
0.03091791487641288,266.24108835282,0.09816437973261088,107.34840682385702,274.472707659116,0.03044958486853187
0.03126133843833718,266.554174966931,0.09925474954172053,107.47464334666658,274.8870152427239,0.030782653455607375
0.03160520320938277,266.66072177778,0.1003465201897903,107.51760302080089,275.0885880775274,0.031116038836860305
0.03194118879711718,266.906882097973,0.10141327443084704,107.61685486190271,275.43220521031424,0.031441677835823474
0.03228065971731728,267.074364485955,0.10249109460248235,107.68438376073706,275.6957011651449,0.03177058717616856
0.03261949796963658,267.166267334795,0.10356690605359613,107.72143898938936,275.88109684967776,0.03209877568843071
0.032963491550395276,267.339465431628,0.104659085672505,107.79127246203241,276.1519076414707,0.03243184735457453
0.03330486849360718,267.49857590288,0.10574295746720279,107.85542580404123,276.40758079555263,0.032762275824486035
0.033651707166785276,267.731603272197,0.10684417025454325,107.94938243934983,276.7412287848069,0.03309787907858199
0.03398705488113678,267.983902191248,0.10790889924760926,108.05110936351119,277.0918857822831,0.03342225655055376
0.03432263206959608,268.183592237239,0.10897435682096754,108.13162439005477,277.38835900070035,0.03374675069523745
0.03465509740994908,268.294250811323,0.11002993427658832,108.17624192712545,277.59201420771876,0.03406813196336558
0.03499463875502508,268.405433896698,0.11110797804720463,108.22107094714863,277.7981850957987,0.03439624675708074
0.03534364986727428,268.541749962941,0.11221608832859582,108.27603358505783,278.03299554837633,0.03473340046521953
0.03567171270536398,268.699027820839,0.11325768783953062,108.33944801736229,278.28398234547456,0.035050213992306255
0.03601062183380708,268.855404712919,0.11433372432233747,108.40249918024894,278.53705502001105,0.035377396520067314
0.036346185260942576,268.9766392374,0.11539913820349268,108.45138094051967,278.75291399798823,0.03570124367700431
0.036695504704181474,269.112343844936,0.11650822743577617,108.50609703827818,278.98755712445114,0.036038255178737294
0.037042290474235275,269.364600251067,0.11760927225569699,108.60780682123021,279.34248201704327,0.03637270997248489
0.037390127678514073,269.61067849925,0.11871365537928218,108.7070255708976,279.69145619182774,0.03670806648204844
0.03775096184866038,269.812224312811,0.1198593038694967,108.7882888429254,279.99789529914614,0.037055834810288076
0.038103435793365774,269.936527771463,0.12097840864393633,108.83840799745387,280.222036925687,0.03739542890560918
0.03845410189995128,270.02417426232,0.1220917735323453,108.87374706256742,280.4077113748535,0.03773316682382581
0.03879110816683818,270.122840715053,0.12316176842971122,108.91352937630937,280.6012050475642,0.03805764105364748
0.03913334766871178,270.278835975462,0.1242483788481599,108.97642666530628,280.8557516311845,0.03838704620021767
0.03947445885348678,270.427021293254,0.12533140685982053,109.03617498544001,281.1019816181655,0.038715257406551906
0.039817213458856374,270.562671397861,0.12641965273186898,109.09086910761755,281.33572303890804,0.03904494141677348
0.04015589493388377,270.709316595001,0.12749496641508098,109.1499964511044,281.57989146981333,0.03937060089444086
0.04050024101648288,270.851292898437,0.12858826522733313,109.20724129664981,281.8208355404497,0.03970159848678038
0.04083638355522578,271.061160699473,0.12965551778784185,109.29185999402753,282.13031822472135,0.04002460490265454
0.041178012773393176,271.305243476627,0.13074019055552333,109.39027416977602,282.47705425799614,0.04035277671725481
0.04149318014048128,271.518448581589,0.13174084694602806,109.47623846809667,282.78461248004885,0.04065543358461455
0.041821916162657874,271.688769155618,0.13278458381643873,109.54491172354517,283.05131408157996,0.04097102293112138
0.04215669731204238,271.892922534148,0.13384751396573455,109.62722636576848,283.3550301707067,0.04129231332258682
0.04250511999015208,272.029623709958,0.13495375596873285,109.68234427985506,283.5922755066257,0.041626585940295995
0.042856597884551574,272.134904137623,0.13606969828345125,109.7247933482896,283.7976802946001,0.04196367652243828
0.04321144045860708,272.216428545661,0.13719632345607746,109.75766398961052,283.9792925396165,0.04230387882740202
0.043550445870188276,272.310655598231,0.13827266563784776,109.79565633720675,284.16990606473723,0.04262878931842118
0.043895404776401775,272.480474005265,0.13936791016507563,109.86412711892287,284.44111470539195,0.04295929744561092
0.044245191535910174,272.621234823504,0.14047848312651479,109.9208818808368,284.68341357502624,0.043294319678690206
0.044592568151984674,272.772556616538,0.14158140388255133,109.98189482778812,284.9361854374521,0.04362692245520159
0.04493503508616568,272.949113456387,0.14266873639857602,110.05308254561525,285.21409144628757,0.04395471610264295
0.045274998837817375,273.103171194832,0.14374812131007017,110.11519862575626,285.46791695328227,0.044280007579702046
0.04562157020159758,273.245127345525,0.1448484853900723,110.1724353457157,285.7109991049634,0.044611512611644734
0.04597487735302588,273.357747866254,0.14597023559585715,110.2178439396736,285.92533679790444,0.044949347527363515
0.04632649726705928,273.46512930879,0.1470866288229132,110.26114013730412,286.13381087434965,0.04528545581616796
0.04667861813037428,273.609473901078,0.14820461256393833,110.31933987691465,286.381186050159,0.04562192978275957
0.04702387221136588,273.769350827712,0.14930079427108664,110.38380225373349,286.64304579642294,0.04595173221239197
0.04737307340426638,273.919180206038,0.15040950805854575,110.44421345907453,286.8955736367751,0.04628519449791272
0.047712131632208374,274.003007410479,0.15148601793226157,110.47801258790513,287.0762749676687,0.04660886460935934
0.04805954784170498,274.069274063321,0.1525890643974133,110.50473130233104,287.2409194521085,0.04694040474427139
0.04840405037825528,274.102824316506,0.1536828599509605,110.51825876441521,287.37051123354416,0.047269055849822314
0.048751755589260676,274.212271343833,0.15478682399590263,110.56238780583347,287.5806009759636,0.04760065278048631
0.04909943574915468,274.371594602015,0.1558907085035661,110.62662694353247,287.8430850825698,0.04793211591239271
0.04944190123937878,274.60794966737,0.1569780364350276,110.7219253058836,288.1850887943724,0.04825850023204169
0.049801482652565975,274.799943826699,0.15811970742189696,110.79933735092504,288.48538846211045,0.04860108215414094
0.05016193707044968,274.982299987848,0.1592641501986777,110.87286335510032,288.77594481532594,0.048944378059239374
0.05051985803885028,275.100479330937,0.16040054927334962,110.9205132662338,288.9985164931556,0.049285144540576455
0.05086811994611148,275.175877892405,0.16150628082890392,110.95091396621771,289.1735574553124,0.04961660347543118
0.051220687057036876,275.202140205095,0.16262568140609207,110.96150293069432,289.298182905967,0.04995204802283267
0.05158030140990798,275.237266501317,0.1637674569764578,110.97566585333101,289.43408766669404,0.05029408168017754
0.05193563718808938,275.293685513447,0.16489564807218376,110.99841399902182,289.59123848444534,0.05063193106371805
0.05228660487605668,275.370541663015,0.16600997048147995,111.02940239852764,289.76873236945477,0.05096551530611012
0.052643318351815176,275.544928787622,0.16714253576701318,111.09971528716919,290.050528194017,0.05130444675958697
0.052994320308080975,275.729902756859,0.1682569669781571,111.17429679156555,290.342021542072,0.05163783931780546
0.053349012389475974,275.961601680799,0.1693831143365862,111.26771779769815,290.6838805878876,0.05197462399981012
0.05369819211151268,276.130100329257,0.17049175995405275,111.33565645275644,290.9577875045087,0.05230606386929891
0.05405177043945398,276.299909779516,0.17161437114526637,111.40412362310084,291.23440907536025,0.05264156697691616
0.054405851167710274,276.382026271677,0.1727385774574801,111.43723299274016,291.41882565844406,0.052977434037231964
0.05475799544203028,276.463516821835,0.17385663552844613,111.47008998256388,291.6021048158527,0.05331135240792473
0.055118936042223475,276.534408410307,0.17500262193405952,111.49867347103579,291.7766907809488,0.053653496158897286
0.05547665953555728,276.548488635433,0.17613839402539436,111.50435061780658,291.89047498453385,0.053992474878940835
0.055843040612386576,276.615577008867,0.17730165394432737,111.53140064997517,292.0626319097919,0.05433953845295216
0.05620373527619087,276.667524493962,0.178446859501906,111.55234587596547,292.21727280013965,0.054681097808008644
0.056565974013770476,276.76163420325,0.17959696749372125,111.59029091075041,292.4169256115997,0.055024001948991284
0.056931564866375475,276.890099195586,0.18075771845074212,111.64208799566028,292.65388583879667,0.05536996010557859
0.05730531281884338,276.996244364948,0.1819443681998277,111.68488572794702,292.8696007979261,0.05572351363622207
0.05767088326599588,277.128076612412,0.1831050543695369,111.73804049012452,293.1102975684563,0.0560692106246513
0.058034759410193676,277.265158324117,0.1842603611273649,111.79331183628398,293.35617508028645,0.05641318678130181
0.058392923905430175,277.418780372626,0.1853975333997408,111.8552522462428,293.618074104862,0.056751648143793965
0.05875699785701868,277.57387530245,0.1865534681960343,111.91778652194785,293.8832828987604,0.05709557650846464
0.05912360854114378,277.685634082955,0.18771745711813148,111.96284766224746,294.1034108099749,0.05744178175410442
0.059492108884625874,277.807343046542,0.18888744570868715,112.01192071636574,294.3346877480155,0.05778965073682488
0.05985378774541498,277.85549363716,0.19003577609169253,112.03133503450292,294.4861973772161,0.05813096252068744
0.06022060985141678,277.968695379541,0.19120043627824826,112.07697797703094,294.70813973489965,0.05847700897082913
0.060581922833333475,278.058023584325,0.19234760499583378,112.11299510919984,294.9033133122998,0.05881774129252711
0.06094064310020108,278.117124817097,0.1934865418431384,112.13682472625352,295.0657612606298,0.05915591376926279
0.06127552337892428,278.166691546907,0.19454978672808457,112.1568100317129,295.21150115802754,0.059471508652378206
0.06164599504261828,278.26110699349,0.19572603426031301,112.19487833977517,295.41478981576415,0.05982052924898517
0.062014376700496275,278.364065726591,0.19689564602407567,112.23639130096149,295.6266397584415,0.06016746011088249
0.062411468279657975,278.47546618845,0.19815641178791407,112.28130796718304,295.8555289131334,0.06054129437271318
0.06278289302407368,278.584021857848,0.19933568535143392,112.3250776130843,296.07433270036546,0.06089083863554443
0.06315984962536689,278.642270815356,0.20053252256053986,112.34856359275155,296.2412747393247,0.06124546399556134
0.06353686339540818,278.791387812446,0.20172954128042095,112.40868756597821,296.5049181357016,0.06160001739443799
0.06391567959544249,278.845890106469,0.2029322827155299,112.4306628909283,296.6685146750201,0.06195613927860037
0.06427814171887168,278.917512863172,0.20408309995741758,112.45954118643097,296.8458122828662,0.06229676814736558
0.06466038398013739,279.027054857723,0.2052967191369362,112.5037085186339,297.0690513656702,0.06265586002414744
0.06504581326556798,279.105859884031,0.20652045711817832,112.53548270524131,297.2605275273735,0.06301781538694544
0.06542970115068739,279.206089786322,0.20773930115343245,112.57589540184505,297.4744608004931,0.06337819304599525
0.06581850191600579,279.314806900003,0.20897374358331836,112.61973014208122,297.6988890531197,0.06374305038083969
0.06619721165512689,279.41175840028,0.21017614700502787,112.65882098699291,297.9080377100345,0.06409831018562766
0.06659571279657639,279.534096593198,0.21144138812913002,112.70814774637743,298.14986900676905,0.06447199967185789
0.06697921659496009,279.606942108507,0.21265901268899828,112.73751905815001,298.33479604544715,0.06483149377467179
0.06735675779967729,279.676943307779,0.21385770601397536,112.76574354169651,298.5150754403152,0.06518527238608457
0.06774684125904938,279.740228482055,0.21509622099748177,112.79126012396456,298.69174533479895,0.06555067241996058
0.06811859323462488,279.845948823951,0.21627653351993398,112.83388656581705,298.90866118024735,0.06589877672777489
0.06849897897412179,279.937801267109,0.21748425824283665,112.87092147089835,299.11325483016657,0.06625484020723267
0.06887895204927048,280.013739140779,0.21869067275643378,112.9015396215621,299.3007920521937,0.06661039087858238
0.06925917522233978,280.072997895275,0.21989788133092877,112.92543275137488,299.47062273154984,0.06696604907692556
0.06964428896998559,280.116761222419,0.22112061747970424,112.94307812487934,299.62529388632953,0.06732615298834999
0.07003024143274689,280.173238374183,0.22234601654897135,112.96584971247057,299.79383790052157,0.06768691109568196
0.07041308345847688,280.234370396898,0.22356153998066408,112.99049814402926,299.9665365075885,0.06804463327908238
0.07080744474267449,280.303910401657,0.22481363705799148,113.01853667394809,300.1515140485779,0.06841298514519117
0.07119828004365789,280.40282148234,0.22605453913861379,113.0584176216795,300.36702009127146,0.06877790975841523
0.07160737226590919,280.453309330712,0.22735340694426165,113.07877432214308,300.5358338551625,0.06915973834541804
0.07200695156492018,280.492513230555,0.22862207121862155,113.09458133455978,300.6899240450703,0.06953254729635372
0.07240358888424138,280.592971657657,0.22988139470746638,113.13508617236732,300.9089098213656,0.06990247396511674
0.07280975074401819,280.65723102415,0.23117095861225773,113.16099554893728,301.0918140595247,0.07028114200444609
0.07321403398606309,280.722007628524,0.2324545579057503,113.18711347582088,301.27479823567467,0.07065791625056982
0.07362345820804748,280.815380849512,0.23375447981055075,113.22476155852324,301.489980305663,0.07103933704132517
0.07402027170517558,280.930536153472,0.23501436266393247,113.27119217707993,301.7250907698327,0.07140887086680728
0.07443351841855128,281.015984756535,0.2363264209789003,113.30564505383491,301.9329932338178,0.07179356307696462
0.07483940315060779,281.037712352459,0.23761510500317973,113.31440562051147,302.0704070077292,0.07217125800142815
0.07524703155951819,281.093522288003,0.23890932520147024,113.3369081865228,302.24497543078445,0.0725504319799376
0.07564691777747538,281.096810774329,0.24017896394348434,113.33823410420946,302.36091810648526,0.07292226455930571
0.07605141763579358,281.225916064918,0.2414632509936446,113.39028935737495,302.6135456575797,0.07329824650475397
0.07646659040677328,281.301010175437,0.24278142454150517,113.4205673027362,302.8111393015337,0.07368400195448933
0.07688196358864959,281.361525212923,0.24410023439396242,113.44496696585057,302.99315174958986,0.07406979475729177
0.07729110419043009,281.426779400803,0.24539925580461552,113.47127745440378,303.17856592944764,0.07444965337944233
0.07769900049121618,281.422318259816,0.24669432655961138,113.46947872235782,303.28855110452463,0.0748282131740058
0.07811863171622309,281.54829193469,0.24802665569900828,113.52027130806701,303.54245926266765,0.07521751440620417
0.07854619025631629,281.568799630551,0.2493841540638042,113.52854001103815,303.68495613657484,0.07561401416948553
0.07897556844871469,281.662607858601,0.25074742982466913,113.56636348858792,303.90707242498144,0.07601204324737071
0.07939869735683408,281.636660748167,0.2520908641079482,113.55590161366094,303.9982447395001,0.07640412438014124
0.07982756283767109,281.685995792886,0.2534525120096057,113.57579350369164,304.1723023225345,0.07680136434927519
0.08026452596392529,281.71821477391,0.25483986993546276,113.58878419684052,304.33019373814113,0.07720594259339711
0.08070140369587349,281.78971783697,0.2562269567343983,113.6176142318663,304.5305436134776,0.07761027820267634
0.08114349589462318,281.877878580116,0.2576305994654286,113.65316064350276,304.7504350634667,0.07801927350571217
0.08157905134000928,281.882222044324,0.25901348800452945,113.65491192827145,304.8779063083138,0.07842205790524744
0.08201124852496318,281.908187433567,0.2603857140667581,113.66538117321421,305.02782985440314,0.07882157641920051
0.08244768252638428,281.975571777598,0.2617713920212701,113.69255054072752,305.2238041997131,0.07922484949689654
0.08288471008982629,281.995641782541,0.26315895453519844,113.70064276672052,305.3687687982814,0.07962850814151515
0.08332954447709569,282.045340831235,0.26457130371477877,113.72068142315396,305.54805060458904,0.0800392102616626
0.08377335800950018,282.105351367248,0.26598041168016306,113.7448776712744,305.73826396373227,0.08044880183029553
0.08422434531806239,282.137023794422,0.2674122963848481,113.75764799391096,305.8998299134938,0.0808648422295775
0.08466622411250649,282.264463093083,0.2688152615572081,113.80903151913108,306.1627293843183,0.08127231211928601
0.08511679762495689,282.232040138976,0.2702458324592381,113.79595858403513,306.25472758276396,0.08168762877944331
0.08555868721237068,282.265633556194,0.2716488318992769,113.80950344985742,306.41591060843,0.08209477355682213
0.08600969048851338,282.278676129398,0.27308076730103,113.81476221537326,306.55737769479487,0.08251014457369502
0.08646721896097188,282.318460917395,0.27453342020108573,113.83080344189366,306.72975309426397,0.08293134903136506
0.08692691643135368,282.383219417649,0.2759929596695479,113.85691406919608,306.9299219335836,0.08335437168496587
0.08739535059161219,282.379387680681,0.2774802381283687,113.85536911285058,307.0580332668789,0.08378525000931565
0.08786666518730778,282.374767604578,0.27897666196970217,113.85350629816585,307.18609676703323,0.0842185905445268
0.08834018658725538,282.350146700327,0.2804800924145358,113.84357914957185,307.2930113427728,0.08465377105784473
0.08881425771840028,282.369192393226,0.28198526825592085,113.85125837294872,307.4476026181745,0.08508926716137341
0.08929533301476639,282.432521509694,0.28351268232188326,113.87679267270863,307.6524275721023,0.08553100370781301
0.08978524520417869,282.480425900162,0.2850681535232673,113.89610772294533,307.84300020498887,0.08598065408106104
0.09028087265872939,282.528180963403,0.2866417706914658,113.91536256444408,308.0350716914624,0.08643534438520237
0.09077692914515188,282.573152518216,0.2882167500358572,113.93349509534468,308.2242755626843,0.08689022136697294
0.09127265158700738,282.589507954785,0.28979066878874843,113.94008960736932,308.38220165648596,0.08734458542428974
0.09177108608789879,282.566936738637,0.29137319832907865,113.93098889301847,308.49841141567236,0.08780122722303212
0.09227486684022898,282.581084838332,0.292972702217727,113.93669340681546,308.65621681335654,0.08826255520982593
0.09278566053276309,282.577503239954,0.2945944721915228,113.93524930634945,308.79664352977215,0.0887300879810601
0.09330326149614328,282.607324774965,0.29623785525025487,113.94727334926588,308.975509899169,0.08920362862054347
0.09381731720596868,282.595328715173,0.29786998212895055,113.94243653795776,309.1076643101694,0.08967370395548116
0.09433475471302369,282.595755400693,0.2995128462138502,113.94260857755943,309.254356669359,0.0901466487049256
0.09484749145121718,282.600261738457,0.3011407853576145,113.94442553294586,309.404187647807,0.09061507635499208
0.09534786711609808,282.601651451987,0.3027294780936114,113.94498586544115,309.5471161614209,0.09107199968069386
0.09584598431080539,282.576765782924,0.3043110001868071,113.93495196367496,309.6606140427523,0.0915266533873602
0.09635386660045138,282.528882656856,0.3059235264564331,113.91564548724435,309.7516329271493,0.09199000740001688
0.09688794375149189,282.507033143977,0.30761922141098674,113.90683576365154,309.8785586806315,0.09247702817362799
0.09743221126371668,282.543455742824,0.30934727076230045,113.92152135550663,310.0722894139394,0.09297309755725217
0.09798230143158608,282.566990304599,0.3110938070452858,113.93101049081433,310.25355432324034,0.09347422404266108
0.09852417912272649,282.533388534076,0.31281426871465656,113.91746225693943,310.36975871415814,0.09396762363599769
0.09907377988915499,282.445636658185,0.31455925114806704,113.88208070058019,310.42859349511025,0.09446780682522311
0.09961468413629729,282.403334555845,0.3162766221327439,113.86502449291672,310.5348535266626,0.09495983129063024
0.10017872205756378,282.309921188177,0.318067442532765,113.82736022307296,310.5913683169801,0.0954726412045422
0.10073101357926538,282.251466685385,0.31982096811416755,113.80379136754723,310.6829430088381,0.09597451688290509
0.10131666346961739,282.107051359984,0.3216804065160352,113.74556310834555,310.6891965450296,0.09650643080126783
0.10189214953020038,281.978805284571,0.3235075747583862,113.69385429073904,310.71023187697375,0.0970288380014163
0.10247714313418739,281.832827319533,0.32536492945104495,113.63499597523571,310.7142503046695,0.09755959627287895
0.10306466889680338,281.657399208033,0.3272303237473507,113.56426336067891,310.68632579974366,0.0980923685588618
0.10364769058229038,281.49389107138,0.32908141759877196,113.49833687998041,310.67008279395134,0.09862077607563509
0.10424332832806038,281.316223972559,0.3309725674415917,113.42670150573578,310.6415634721406,0.0991603296633064
0.10482960284235539,281.078823521329,0.33283398902447836,113.33098164379986,310.5442049584664,0.09969111750628537
0.10543130263560138,280.833149900225,0.33474438586803434,113.23192603977074,310.4417547174648,0.10023557794226237
0.10601351335736138,280.565541406905,0.33659290490962235,113.1240262952641,310.3092801784613,0.10076212125096355
0.10661377746362938,280.254630320411,0.33849874344702324,112.99866694518973,310.133635110543,0.1013047016697121
0.10720813878870639,279.934621183171,0.34038584065414274,112.86963926105454,309.9458909027403,0.10184165663884862
0.10782077068687039,279.572776791672,0.34233094693081345,112.72374360240215,309.71652904841847,0.10239481593276543
0.10844202973310538,279.207943648196,0.34430344440260957,112.57664287895264,309.48581977501294,0.10295545257061352
0.10906613178421738,278.836086725567,0.34628496841489015,112.42671016774861,309.24766010657316,0.1035183384967364
0.10969109525058938,278.367924715023,0.3482692274206213,112.23794724509727,308.9024072596475,0.10408168402664397
0.11031866291313938,277.852699742684,0.3502617547492175,112.0302085362502,308.5050380651029,0.10464705782913195
0.11093096176461838,277.28359241538,0.35220580360266335,111.80074446188121,308.04292800356654,0.10519836810077819
0.11152953269374039,276.681828701989,0.3541062663026257,111.55811333264197,307.5400237619714,0.10573702419395742
0.11213666883507438,276.03979427967,0.35603392355136115,111.29924505356294,306.9939772761114,0.10628309190502251
0.11277337047844438,275.369927361642,0.3580554512690609,111.02915471221407,306.42432219861877,0.10685543114526151
0.11342494870910338,274.690279121152,0.3601242121514032,110.75512054164848,305.847009941358,0.10744080419459773
0.11410988682498738,273.935824228629,0.3622988906693349,110.4509243289832,305.1946101286675,0.10805577831445821
0.11479371458653638,273.038925851092,0.364470043812253,110.0892949031603,304.38207837625674,0.10866937845631378
0.11548927961344038,272.096476761595,0.3666784627726732,109.7092994302751,303.5207028481468,0.10929312445739456
0.11617085778999639,270.969767703939,0.3688424734832385,109.2550103382282,302.44855805326165,0.10990395061889156
0.11686578673096139,269.865709250584,0.3710488728708024,108.80985396983547,301.4037776738624,0.11052635774786027
0.11754739628540338,268.709273323406,0.3732129832061557,108.34357900399732,300.2953487603152,0.11113645938954897
0.11823109648442238,267.469469798219,0.37538373133804104,107.84369022264191,299.09267848856956,0.1117480586356654
0.11890573584634338,266.112844024296,0.37752571131214024,107.29669871059616,297.75518756116816,0.11235118614456158
0.11957656262537539,264.6385084551,0.37965558633556684,106.70224660909633,296.2830716344672,0.11295054473638215
0.12028277905017239,263.02714078584,0.3818978234842973,106.05254316485069,294.66477624518177,0.11358113473376177
0.12104100726478938,261.084686513062,0.38430519806570623,105.26934560206661,292.6866399500148,0.11425772438865352
0.12142015938266139,260.164495972034,0.38550900603994986,104.89832477592411,291.75371053866814,0.114595881523434
0.12163555945783239,259.63921718482,0.38619290127861783,104.68653236891942,291.2205786242892,0.11478794101979331