File: example/data/02 processed data/test_ID_061.csv
Strain,Stress_MPa,Displacement(mm),Force(kN),True Stress (MPa),True Strain
1.55837128086851e-05,0.516839889364162,4.9478288167575186e-05,0.10419492169581507,0.5168479436485659,1.558359138384018e-05
1.72212882043691e-05,0.582722811435279,5.467759004887188e-05,0.11747691878535227,0.582732846672758,1.7221139919679697e-05
2.48892211799352e-05,0.624914068895418,7.902327724629425e-05,0.12598267628931628,0.6249296225198971,2.4888911448298454e-05
3.40925744569423e-05,0.735009498455341,0.0001082439239007918,0.14817791488859677,0.7350345568213936,3.4091993318248295e-05
4.14046416948809e-05,1.45636092991663,0.00013145973738124686,0.2936023634711926,1.4564212300191115,4.140378454625847e-05
5.80428532565621e-05,2.92677662786063,0.00018428605908958466,0.590038168176703,2.926946506326956,5.804116883538408e-05
8.09890648916366e-05,5.23867425370585,0.0002571402810309462,1.0561167295470992,5.239098529034929,8.098578545437188e-05
0.0001098876381603,8.33143910550226,0.0003488932511589525,1.6796181236692558,8.33235462766804,0.00010988160095598388
0.000161439090638,12.3263568244611,0.00051256911277565,2.484993535811358,12.32834678029772,0.00016142606075027067
0.0002113586562125,17.2839600364567,0.0006710637334746875,3.4844463433496706,17.287613151024036,0.00021133632311849652
0.0002672047971746,23.0177794967713,0.0008483752310293549,4.640384346549094,23.023929957873143,0.00026716910433081074
0.0003498718463939,29.1436794113244,0.0011108431123006324,5.8753657693229995,29.15387596425075,0.00034981065551168
0.000434253196392,35.5009426641632,0.0013787538985446,7.156990041095301,35.51635906199004,0.0004341589357602764
0.0005233970430996,41.9670175146099,0.00166178561184123,8.460550730945355,41.988982927484756,0.0005232601186423519
0.0006298451869793,48.6858562801592,0.001999758468659277,9.815068626080095,48.71652083241122,0.0006296469177477485
0.0007248730770316,55.4581964877506,0.00230147201957533,11.18037241193052,55.49839664128529,0.0007246104834329619
0.0008330348725675,62.2896618685079,0.0026448857204018125,12.557595832691193,62.34155132904481,0.0008326880915918611
0.0009483623541782,69.3117261365403,0.003011050474515785,13.973243989126525,69.3774587683113,0.0009479129427149209
0.0010564387337503,76.3850119556188,0.003354192979657202,15.39921841025275,76.4657080409267,0.0010558810950574897
0.0011681826951738,83.5102792894087,0.003708980057176815,16.835672304744794,83.60783455254371,0.0011675009006910824
0.0012865083260202,90.6659451698135,0.004084663935114135,18.2782545462344,90.78258766316097,0.0012856814832679067
0.0013985719533382,97.8029159440501,0.004440465951848785,19.7170678543205,97.93970035924414,0.0013975948624990553
0.001514507598724,104.973021134097,0.0048085616259487,21.16256106063395,105.1320035722656,0.0015133618887357705
0.0016318941402924,112.145710200606,0.00518126389542837,22.60857517644217,112.32872012794131,0.0016305640478998908
0.0017466842234124,119.279337134715,0.00554572240933437,24.046714366358547,119.4876804710673,0.001745160544523475
0.0018648847742841,126.391533093461,0.005921009158352017,25.48053307164174,126.62723873912543,0.0018631480355499942
0.0019856080988389,133.484577967839,0.006304305713813507,26.91049091831634,133.74962602692202,0.0019836393847102603
0.0021046916950022,140.54464041914,0.006682396131631985,28.333799508498625,140.84044355660723,0.0021024799342760233
0.0022245281261359,147.537826067888,0.0070628768004814815,29.743625735286223,147.86602811164497,0.0022220575267108186
0.0023442121276153,154.515812443329,0.007442873505178577,31.150387788575127,154.878030284767,0.0023414687489036793
0.0024650274962081,161.390443760279,0.007826462300460718,32.53631346207225,161.7882756417733,0.0024619942995158504
0.0025885369014277,168.242276167269,0.008218604662032947,33.917642875321434,168.67777750750818,0.002585192410098975
0.0027084216833422,175.046990827005,0.008599238844611485,35.289473350724215,175.52109189256467,0.0027047605184970618
0.0028305067711761,181.758989919566,0.008986858998484117,36.64261236778451,182.27345997125545,0.0028265084299960684
0.0029527311193793,188.413231773558,0.009374921304029277,37.98410752554929,188.96956538631864,0.0029483803711367524
0.0030757683523974,194.985397551691,0.009765564518861744,39.30905614642091,195.5851274666601,0.0030710478538816654
0.0032017957876778,201.528684710539,0.010165701625877014,40.628182837644665,202.17393840434144,0.0031966809544044465
0.0033226566631445,207.947337828267,0.010549434905483787,41.92218330617863,208.63827543588528,0.0033171488365330236
0.0034473546271724,214.245916686866,0.01094535094127237,43.19197680407218,214.98449833910928,0.003441426121410563
0.0035736323792923,220.435060777651,0.011346282804253052,44.439708252774444,221.22281464837727,0.0035672621272161598
0.0036997916311018,226.526929519269,0.011746838428748215,45.66782899108463,227.3650319573236,0.00369296423682079
0.0038254309117215,232.450086327174,0.01214574314471576,46.86193740355828,233.33930807284233,0.003818132557868929
0.0039592644557554,238.225810183997,0.012570664647023395,48.0263233330938,239.169009166702,0.003951447195181129
0.00409206885641,243.752265958579,0.01299231861910175,49.14045681724952,244.74971701478742,0.0040837191133786845
0.0042370876112842,249.182966311323,0.013452753165827334,50.23528600836272,250.23877637082379,0.004228136431286365
0.0043913243467812,254.344639526526,0.01394245480103031,51.275879328547646,255.46154933455213,0.004381710616418752
0.0045592458184693,259.217526548888,0.014475605473640027,52.258253352255814,260.39936297287994,0.004548883940215717
0.0047486282930913,263.716511447888,0.015076894830564876,53.16524870789423,264.9688031355048,0.0047373891241378205
0.0049662144110385,267.794476476271,0.015767730755047237,53.987366457616226,269.12440126454396,0.004953923444503984
0.0052072484771481,271.361745921525,0.016533013914945216,54.706527977779444,272.77479395973114,0.005193737641352951
0.0054814151394463,274.38032160038,0.017403493067742002,55.31507283463662,275.88431404916645,0.005466446856815564
0.0057832317429722,276.795486128931,0.018361760783936733,55.80197000359249,278.3962585706232,0.005766573054786955
0.0061083299398965,278.695395292359,0.019393947559171388,56.184991690939576,280.39775871953464,0.0060897497169345605
0.0064550280325017,280.111967564612,0.020494714003192895,56.47057266102577,281.9200981674808,0.006434283561955022
0.0068161289091207,281.127279021548,0.02164120928645822,56.67525945074408,283.0434787952292,0.0067930041240075395
0.0071863179104624,281.84772457632,0.02281655936571812,56.820501274586114,283.8731719274659,0.007160619373030925
0.0075626231494135,282.376659287419,0.02401132849938786,56.92713451234366,284.51216754780006,0.007534169879159
0.0079478897020683,282.800719012696,0.025234549804066853,57.01262495295951,285.0483879350745,0.007916471588716672
0.0083336592696338,283.162461717413,0.026459368181087312,57.085552282230466,285.52224119131665,0.008299126057254783
0.0087217100778587,283.489246093523,0.027691429497201367,57.15143201245424,285.96175710814146,0.008683895676284178
0.0091120371146299,283.779552213695,0.02893071783894993,57.20995772628092,286.36536202583926,0.00907077298189241
0.0095024972290176,284.069858333866,0.03017042870213088,57.268483440107396,286.76923137553104,0.009457632496291448
0.0098952175707485,284.317606488778,0.03141731578712648,57.31842946813764,287.1309910641789,0.009846580491828554
0.0102854211880822,284.575994135004,0.032656212272160985,57.37052041761681,287.50297809469976,0.010232886166380592
0.0106721709989964,284.8131027986,0.03388414292181357,57.418321524197765,287.8526769344214,0.010615625336297271
0.0110584875203426,285.069970517495,0.03511069787708775,57.470106056327,288.22241322888715,0.010997789522629536
0.0114443763005086,285.30555925376,0.0363358947541148,57.51760074555802,288.5707034344871,0.011379384814039484
0.0118286683110558,285.55026755401,0.03755602188760216,57.566933938888425,288.92794695503966,0.011759256444506648
0.0122135559448433,285.785856290275,0.038778040124877476,57.61442862811944,289.2763178343212,0.012139572263825291
0.012597491289282,286.026004808533,0.03999703484347035,57.662842569400254,289.6292149126166,0.012518803056312698
0.0129842958102762,286.358868893965,0.04122513919762694,57.72994796902334,290.07703715558034,0.012900722491172766
0.0133648117537998,286.498702208394,0.04243327731831436,57.758138365212226,290.32770343111713,0.013276290498260988
0.0137454176816008,286.711492034698,0.043641701139082535,57.80103679419511,290.65246124682983,0.013651806271154485
0.014124916836024,286.909082587694,0.0448466109543762,57.84087104967911,290.9616495187451,0.01402608972744244
0.0145005563205659,287.129472050652,0.04603926631779673,57.885301565411446,291.2930091314168,0.014396428652794243
0.014875960225615,287.345301731618,0.047231173716327624,57.9288128290942,291.61983901119487,0.014766398351635674
0.0152429125763773,287.570250976567,0.04839624742999792,57.974162596875914,291.95365917176974,0.015127906595980232
0.0156067736503691,287.675125962389,0.04955150633992189,57.99530539401763,292.16480653812545,0.015486240430682916
0.0159731207135664,287.979111428537,0.05071465826557332,58.05658886399306,292.57903653837064,0.015846892815740095
0.0163345749380674,288.197980964164,0.05186227542836399,58.10071296237547,292.90557248122286,0.01620260098836131
0.0166934780140751,288.465488174375,0.05300179269468844,58.15464241595401,293.2809804590334,0.016555673420603316
0.0170502928675657,288.676758073348,0.0541346798545211,58.19723442758696,293.598781342558,0.016906568024201443
0.0174024567205217,288.853069643714,0.0552528000876564,58.23277884017274,293.8798226867786,0.017252768108272865
0.0177547820600669,289.059779760696,0.056371433040712404,58.274451599756325,294.19197315267814,0.017599007048784497
0.0181066709377837,289.27408951433,0.05748868022746324,58.31765644608893,294.51188026399296,0.017944697449968596
0.0184573199160964,289.492959049957,0.058601990733606064,58.36178054447133,294.83622320859945,0.01828905096240665
0.018809202408525,289.555276070518,0.05971921764706687,58.37434365581643,295.0015798665847,0.018634496678096513
0.0191604325224041,289.742227132199,0.060834373258633015,58.41203298985131,295.2938135240566,0.018979182988762385
0.0195171023622901,289.958056813165,0.061966800000271056,58.455544253534065,295.6171978887583,0.019329086136682428
0.0198777788045026,290.189085767438,0.06311194770429575,58.5021196907155,295.95740022580395,0.01968279541515859
0.0202440273533164,290.407955303065,0.06427478684677958,58.54624378909791,296.28698189384096,0.02004184118550712
0.0206006759161969,290.620745129369,0.06540714603392515,58.589142218080795,296.6077289143028,0.020391351920880357
0.0209580385901289,290.832015028342,0.06654177252365925,58.63173422971376,296.927283622551,0.02074143999333461
0.0213174000872162,291.149679840467,0.06768274527691143,58.695775455838145,297.35623405089115,0.02109336265174841
0.0216782121548972,291.350310248125,0.0688283235917986,58.73622254602201,297.66626408507904,0.021446581297222038
0.0220376933126709,291.628456949651,0.06996967626773011,58.79229692104965,298.0552754451549,0.021798373012028652
0.0223923696449646,291.845806557947,0.0710957736227626,58.83611460208212,298.3809257377254,0.022145341433475938
0.0227434982375175,292.031237692298,0.07221060690411805,58.87349751876728,298.6730496320528,0.02248872066956208
0.0231021753313024,292.224268463302,0.07334940667688512,58.912412522201684,298.97528474940276,0.02283936011621604
0.0234577196266238,292.409699597653,0.07447825981453056,58.94979543888685,299.2689643469201,0.023186815668115077
0.0238075447478749,292.616409714634,0.0755889545745028,58.99146819847022,299.58288798287765,0.02352856437136644
0.0241518285817874,292.797281066993,0.07668205574717499,59.027931863105785,299.8688708085364,0.023864785725793054
0.0244945311207394,292.920395180783,0.07777013630834759,59.05275166844584,300.09534291643797,0.024199350586658928
0.0248343008151992,292.958393364051,0.07884890508825745,59.060412102192686,300.2338102311913,0.024530941781081405
0.0251732199469363,293.063268349873,0.07992497333152275,59.0815548993344,300.4406144624124,0.024861593382495006
0.025511858251347,293.206141518962,0.08100014994802672,59.11035813022274,300.68637503981813,0.02519186184847154
0.0258516019906584,293.394612507975,0.08207883632034042,59.14835388160776,300.97933325673466,0.02552309885156977
0.0261938041221349,293.58916320631,0.08316532808777831,59.1875753023921,301.2793802397175,0.02585662181712312
0.0265397273859036,293.782193977314,0.08426363445024393,59.22649030582651,301.5790933163046,0.02619365851646445
0.0268834635962935,293.940266419711,0.08535499691823185,59.258357710213744,301.84239887149016,0.026528451865551184
0.0272290719973733,294.250331595183,0.08645230359166022,59.320866849588896,302.26249505943923,0.026864955731188845
0.0275751457074622,294.508719241409,0.08755108762119247,59.372957799068054,302.6298400866089,0.027201799222533886
0.0279223773152778,294.716949285721,0.08865354797600701,59.41493697600136,302.94614714488443,0.02753965573389353
0.0282691983476104,294.868942018795,0.08975470475366303,59.445578710989075,303.20465062727436,0.02787699884892887
0.0286152312082911,295.055893080476,0.09085335908632423,59.48326804502396,303.49898568034257,0.028213461956892352
0.0289631569871332,295.223085086858,0.0919580234341479,59.51697395351058,303.7736776464545,0.028551651533682533
0.029309597682621,295.396356802563,0.09305797264232167,59.5519055313967,304.05430517735806,0.028888283982393168
0.0296592940533585,295.589387573567,0.09416825861941323,59.59082053483111,304.3563601386636,0.029227965048487407
0.0300065045930761,295.776338635249,0.0952706520830166,59.628509868866196,304.65155269903084,0.029565117360512917
0.0303555646595913,295.954170132946,0.09637891779420237,59.664360698801914,304.9380260806923,0.029903951078201402
0.030699386742209,296.169999813911,0.09747055290651357,59.707871962484454,305.2622371796382,0.030237588068882545
0.0310423082310053,296.343271529616,0.09855932863344181,59.74280354037059,305.54245070662284,0.030570240304412112
0.0313813392268237,296.448146515437,0.09963575204516524,59.763946337512095,305.75108636440103,0.030899009807506126
0.0317235115104464,296.622938158473,0.10072214904566733,59.799184332748155,306.03285935140576,0.031230715960625675
0.0320637247487954,296.782530528201,0.1018023260774254,59.83135815448532,306.2984838973082,0.0315604139405855
0.0324031176414731,296.974041371874,0.10287989851167709,59.86996674056981,306.5969261709106,0.03188920865771682
0.0327424946279657,297.159472506225,0.10395742044379108,59.907349657254954,306.88921493840917,0.03221787990252527
0.0330821057928171,297.300825747984,0.10503568589219428,59.93584647079358,307.13616311767066,0.032546669837393405
0.0334234079502291,297.474097463689,0.10611932024197739,59.970778048679705,307.4166955778441,0.032876988008088456
0.0337675495736786,297.709686199954,0.10721196989642955,60.01827273791072,307.76261278727526,0.0332099438246532
0.0341118712903232,297.846479659721,0.10830519134677614,60.04585029939975,308.0065804381493,0.033542962971081815
0.0344575143137087,298.012151738772,0.10940260794602512,60.07924979053644,308.28090972296985,0.03387714854784585
0.0348046125967778,298.153504980531,0.1105046449947695,60.107746604075054,308.5306222157499,0.03421262879639489
0.0351508460689914,298.310057495597,0.1116039362690477,60.139307591112356,308.7959084074567,0.03454716109175709
0.0354997411880226,298.48028935664,0.11271167827197175,60.173626334298625,309.07626237852685,0.03488415191433264
0.0358495181394416,298.630762162384,0.11382222009272708,60.20396165193661,309.33653108751963,0.0352218805259306
0.036192259406883,298.791874459443,0.11491042361685351,60.236441891023716,309.605827488548,0.03555270519778958
0.0365357685724566,298.978825521124,0.1160010652175497,60.2741312250586,309.90224669842866,0.035884161292444955
0.036877917589137,299.136897963521,0.11708738834550997,60.30599862944583,310.1684438344898,0.036214195787798796
0.0372204136611707,299.29801026058,0.11817481337421697,60.33847886853293,310.4380060104441,0.03654445599772851
0.0375607206868934,299.4621624123,0.11925528818088654,60.37157194231969,310.7101770509615,0.036872497373409606
0.0379015421695042,299.582236671429,0.12033739638817582,60.395778912960076,310.9368654478655,0.037200926843580125
0.0382396564438865,299.72814969518,0.12141090920933963,60.42519497854829,311.18965116608547,0.03752664098826101
0.0385816977080781,299.810225771041,0.12249689022314797,60.441741515441876,311.37741327153,0.037856030193163415
0.0389219296653703,299.902941338216,0.1235771266875507,60.46043297378435,311.5757425274197,0.038183569414612505
0.0392634018510093,299.969818140769,0.12466130087695453,60.47391533717904,311.74765365360423,0.038512194762442394
0.0396042828764975,300.07469312659,0.12574359813287955,60.495058134320544,311.9589361572536,0.03884014351170391
0.0399454460695906,300.175008330419,0.12682679127095015,60.515281679412475,312.1656329371207,0.039168256075115995
0.0402858298272764,300.247964842294,0.12790750970160256,60.52998971220647,312.3437032599167,0.03949551176506511
0.0406263588693694,300.302682226201,0.12898868941024783,60.541020736802125,312.50288676375686,0.03982280000623404
0.04096872402748,300.428836194653,0.130075698787249,60.56645337684205,312.73702227460876,0.040151745019614236
0.0413147126955808,300.559549945097,0.13117421280846903,60.592805268931556,312.97708139899174,0.04048406161511993
0.0416603761432535,300.719142314825,0.13227169425482985,60.62497909066872,313.24721489713716,0.04081595559954421
0.0420056489969912,300.845296283276,0.13336793556544704,60.65041173070845,313.4824982013471,0.0411473646187747
0.0423519759396247,300.980569815713,0.1344675236083084,60.67768287484774,313.72769166684265,0.04147967510299998
0.0427004120274176,301.197919424009,0.1355738081870509,60.72150055588021,314.0591946852151,0.04181389796766021
0.0430498761572633,301.410709250313,0.13668335679931098,60.7643989848631,314.38640295601186,0.042148994776799203
0.0434002627140726,301.612859585302,0.1377958341171805,60.805152492396886,314.7029369292468,0.0424848633926605
0.0437486714243954,301.799810646983,0.1389020317724554,60.84284182643178,315.0031513989226,0.04281872429531118
0.0440942763833983,301.971562435357,0.1399993275172896,60.87746698696797,315.2867799693082,0.04314978843260411
0.044442418074086,302.128114950423,0.14110467738522303,60.909027974005284,315.5554189469853,0.0434831717960243
0.0447888248651934,302.267948264852,0.14220451894698904,60.93721837019417,315.8061744620478,0.04381478352684858
0.0451345702653926,302.388022523981,0.1433022605926215,60.96142534083458,316.0361759740028,0.04414565249951919
0.0454780579845483,302.497457291794,0.14439283410094084,60.983487390025665,316.25445419468866,0.04447425256402182
0.0458189352301556,302.603852204946,0.14547511935574403,61.00493660451712,316.46883850952,0.044800248584416925
0.0461602851190441,302.710247118098,0.14655890525296503,61.02638581900856,316.6834384335257,0.04512659015473226
0.0465027556435572,302.818161958581,0.1476462491682941,61.04814145084993,316.900040948572,0.045453896100218404
0.0468417067715734,302.926076799064,0.14872241899974553,61.069897082691305,317.11565126194887,0.04577773303872914
0.0471835351667728,303.037031494208,0.14980772415450364,61.09226554923234,317.33538992654945,0.046104212769144726
0.0475295353716383,303.147986189352,0.15090627480495158,61.114634015773376,317.55646912177974,0.04643456847549758
0.0478786615334152,303.260460811827,0.15201475036859324,61.137308899664326,317.780165771504,0.0467677982161498
0.0482321032737314,303.371415506971,0.15313692789409716,61.15967736620535,318.0036569500013,0.04710503396685532
0.0485802609296768,303.482370202115,0.15424232845172384,61.18204583274639,318.22562293409055,0.04743711676557273
0.0489300130460918,303.59332489726,0.15535279142134145,61.20441429928762,318.44815024518937,0.04777060940586734
0.0492835834000965,303.704279592404,0.1564753772953064,61.22678276582865,318.6719147846625,0.04810762977209697
0.0496372789634828,303.815234287548,0.1575983607090579,61.24915123236968,318.89579582523487,0.048444655882110374
0.0499896072248788,303.926188982692,0.1587170029389902,61.27151969891071,319.11933979529107,0.04878026623937993
0.0503390018071987,304.037143677837,0.15982633073785585,61.29388816545194,319.34207000289115,0.0491129709257231
0.0506855033937178,304.148098372981,0.16092647327505402,61.31625663199298,319.5639978452576,0.04944281152377695
0.0510339409563024,304.260572995456,0.16203276253626012,61.338931515883935,319.7881891130368,0.049774385337506846
0.0513870000590288,304.3715276906,0.16315372518741642,61.36129998242495,320.01226740200354,0.05011024491648805
0.0517403051826057,304.484002313075,0.1642754689547731,61.383974866315924,320.23809751597474,0.05044622564958002
0.0520869808732065,304.594957008219,0.16537616427243063,61.40634333285695,320.4603887079813,0.05077579233600562
0.0524308759960953,304.705911703364,0.16646803128760257,61.42871179939818,320.6819095751602,0.051102608404424425
0.0527777902667782,304.816866398508,0.16756948409702077,61.45108026593922,320.90442704306497,0.05143218549517326
0.0531261410802291,304.927821093652,0.16867549792972739,61.47344873248025,321.1274595363602,0.05176301807632088
0.0534804217206022,305.038775788796,0.169800338962912,61.495817199021275,321.352378159117,0.05209937005582118
0.0538311482168255,305.149730483941,0.17091389558842093,61.51818566556251,321.5762908539464,0.052432236352827316
0.0541770573115993,305.274364525061,0.17201215696432778,61.543311888252305,321.8132312676973,0.0527604220752277
0.0545314325318735,305.272844597731,0.17313729828869837,61.54300547090257,321.9198101267253,0.053096528488529554
0.0548858016305534,305.321482272314,0.17426242017700702,61.552810826098494,322.0792965818587,0.0534325161691784
0.0552406389480815,305.367080092237,0.17538902866015874,61.562003346594985,322.2357527102422,0.05376883470824709
0.0555939990675829,305.433956894789,0.1765109470395757,61.575485709989465,322.41425200960606,0.054103640776366556
0.0559443916757103,305.494753988019,0.1776234435703802,61.587742403984635,322.5854721599995,0.054435524499513346
0.0562929575409489,305.563150717903,0.17873014019251277,61.60153118472925,322.7642041873445,0.05476556872350364
0.0566469184581029,305.567710499895,0.1798539661044767,61.60245043677883,322.87717968001175,0.05510060989006558
0.0569984010010521,305.734902506277,0.1809699231783404,61.63615634526545,323.16130307934736,0.05543319411595542
0.0573558642781866,305.845857201421,0.18210486908324244,61.65852481180647,323.38791067711134,0.055771324093897574
0.0577133191291479,305.950732187242,0.18323978823504458,61.679667608947994,323.60816443176077,0.05610933181219705
0.0580689795142054,306.026728553779,0.18436900995760214,61.69498847644184,323.79738838496763,0.056445529339357994
0.0584257758392951,306.098165138324,0.18550183828976194,61.70939009188613,323.9821879195153,0.056782687111724135
0.0587856250871174,306.154402449562,0.18664435965159773,61.7207275338317,324.15188037073244,0.0571226146703325
0.059145157667833,306.251677798729,0.18778587559536977,61.74033824422377,324.3649815681732,0.05746212773383445
0.059504640163347,306.304875255305,0.18892723251862673,61.75106285146949,324.5314366376508,0.057801478295056774
0.0598608436293185,306.35503285722,0.1900581785230862,61.76117462401556,324.6937035741408,0.058137619911072885
0.0602189808381223,306.405190459134,0.1911952641610383,61.77128639656142,324.8565987520939,0.058475472484431086
0.0605824521614328,306.455348061049,0.19234928561254913,61.78139816910748,325.0211645245728,0.05881824038454053
0.0609457286455661,306.505505662963,0.19350268844967236,61.79150994165334,325.18570703947,0.05916070718839472
0.0613082485382945,306.555663264878,0.19465368910908504,61.8016217141994,325.35005405914285,0.059502343863506925
0.061670573517962,306.605820866792,0.19580407091952934,61.81173348674526,325.51437768359256,0.05984368027197314
0.0620337325941966,306.655978468707,0.1969571009865742,61.821845259291344,325.6789934354465,0.060185685586676675
0.0623982350762971,306.706136070621,0.19811439636724326,61.8319570318372,325.8440576484984,0.060528838477636876
0.0627599204847132,306.753253817874,0.1992627475389644,61.8414559696834,326.0050636359108,0.06086922294357581
0.0631227550561866,306.795811783135,0.20041474730339245,61.85003565548001,326.1616086625857,0.061210572519609444
0.06348592038703,306.833809966404,0.20156779722882026,61.85769608922704,326.31343679798016,0.06155211663025595
0.0638491027582238,306.86724836768,0.20272090125736053,61.86443727092429,326.4604468418414,0.06189356014598887
0.0642119606396403,306.894607059633,0.20387297503085794,61.86995278322202,326.60091148866405,0.06223458220703231
0.0645724316796135,306.917405969595,0.20501747058277286,61.87454904347035,326.73580919785087,0.06257324594838541
0.0649323107037176,306.935645097564,0.2061600864843034,61.87822605166891,326.86568577108505,0.06291123911681332
0.0652954329007408,306.952364298202,0.20731299945985204,61.88159664251753,326.994951804959,0.06325216247736064
0.0656533055157172,306.967563571509,0.2084492450124021,61.884660816016215,327.12099880608463,0.06358804349776156
0.0660147370617944,306.984282772147,0.20959679017119723,61.88803140686484,327.2497694814539,0.06392715028392314
0.066373109105724,306.999482045455,0.21073462141067367,61.891095580363725,327.37599216265875,0.06426327304690703
0.066737205373549,307.140835287214,0.21189062706101808,61.91959239390234,327.63855629038017,0.0646046489887789
0.0671019728071197,307.251789982358,0.21304876366260503,61.94196086044337,327.868991238693,0.06494653739429086
0.0674666310054813,307.346025476864,0.2142065534424031,61.96095873613578,328.0816263687128,0.06528820662081068
0.0678319893395735,307.461539954001,0.21536656615314587,61.98424645472661,328.31726785448967,0.06563041481050061
0.0682043851460122,307.595293559106,0.2165489228385887,62.01121118151577,328.5746414301119,0.06597909408830657
0.0685734252675984,307.707768181581,0.2177206252246249,62.03388606540673,328.80834382724015,0.0663245114952612
0.0689493442995615,307.824802586048,0.21891416815110773,62.05748020134728,329.04912088349795,0.06667624485800308
0.0693223392309007,307.820242804056,0.2200984270581097,62.05656094929769,329.15906209785703,0.06702512001544493
0.0697006347127083,307.84912142334,0.22129951521284885,62.06238287894535,329.3064005822964,0.06737882868558048
0.0700814359375255,307.899279025255,0.22250855910164344,62.07249465149141,329.4773026234737,0.0677347539305486
0.0704625685553177,307.929677571869,0.2237186551631337,62.07862299848879,329.6271935879937,0.06809086211708439
0.070838558686025,307.946396772508,0.22491242382812934,62.08199358933762,329.76087567242723,0.0684420412481165
0.0712248929454801,307.987434810438,0.22613903510189928,62.0902668577843,329.9238068833645,0.06880275349812003
0.0716149202176489,308.028472848368,0.22737737169103522,62.098540126230986,330.08790735616805,0.06916678190013109
0.072005886651178,308.069510886298,0.22861869011749014,62.10681339467769,330.25232916786064,0.0695315539126171
0.0723950557902226,308.110548924228,0.22985430213395672,62.115086663124366,330.4162293031536,0.0698945169533572
0.072782559862489,308.151586962158,0.23108462756340253,62.12335993157105,330.5796482869522,0.07025579620002995
0.0731682202483361,308.194144927419,0.23230909928846707,62.13193961736767,330.74416200271605,0.07061522698807371
0.0735586246820154,308.236702892679,0.2335486333653989,62.14051930316408,330.91017083398344,0.07097894763460613
0.0739391023515121,308.27926085794,0.23475664996605092,62.14909898896071,331.0731526793638,0.07133329275794494
0.0743179079035448,308.321818823201,0.23595935759375472,62.15767867475733,331.2356513591571,0.07168595592082572
0.0746951762160875,308.364376788462,0.23715718448607778,62.16625836055394,331.3977082514401,0.07203706436144552
0.0750750766533861,308.406934753723,0.23836336837450087,62.17483804635056,331.56060902079463,0.07239049788835024
0.075457297201287,308.446452864322,0.2395769186140862,62.18280489744731,331.7209885287879,0.07274596387116684
0.0758415381433133,308.481411192929,0.24079688360501975,62.18985249649449,331.8771159064206,0.07310318151085439
0.076224886834073,308.513329666875,0.24201401569818176,62.196287260842,332.02972330753556,0.07345944253548169
0.0766129716203357,308.555887632136,0.24324618489456584,62.20486694663862,332.1952710945843,0.07381997576276811
0.0770023404267264,308.603005379388,0.24448243085485633,62.214365884484614,332.3661590563225,0.07418157127005783
0.0773951226968875,308.645563344649,0.2457295145626178,62.22294557028125,332.5332245895581,0.07454620433450962
0.0777865135882695,308.683561527918,0.24697218064275567,62.23060600402827,332.69497958118484,0.07490941353144723
0.0781774884084768,308.720039783856,0.24821352569691382,62.23796002042537,332.8549971155229,0.0752721049531323
0.0785700270872026,308.756518039794,0.24945983600186827,62.24531403682248,333.01552602553096,0.07563611481542716
0.0789667525144305,308.791476368401,0.2507194392333168,62.25236163586964,333.1757364613501,0.07600387256162182
0.079363012771733,308.8112354237,0.25197756555025225,62.256345061417925,333.31942544468575,0.0763710641447879
0.0797577524416727,308.821874915015,0.2532308640023108,62.258489982867026,333.4528135630599,0.07673671268163437
0.0801538271985383,308.830994479,0.25448840135535905,62.26032848696641,333.5849806440225,0.077103463584809
0.0805483659415664,308.838594115654,0.2557410618644733,62.26186057371585,333.71503821136065,0.07746865851881303
0.0809456526731441,308.840114042984,0.25700244723723253,62.26216699106558,333.8393786458416,0.07783626234526826
0.0813461938543191,308.824914769677,0.2582741654874631,62.259102817566884,333.9466461535747,0.07820674072116349
0.0817430491175898,308.824914769677,0.25953418094834757,62.259102817566884,334.0692049464302,0.07857367451181763
0.0821415952909254,308.841633970315,0.2607995650486882,62.26247340841551,334.21037847689274,0.07894203627164803
0.0825375848977751,308.841633970315,0.26205683205043595,62.26247340841551,334.3326765541075,0.07930790075160515
0.0829344884336171,308.8507535343,0.26331700077673426,62.26431191251488,334.46513278100434,0.07967447536152468
0.0833358495042181,308.844673824977,0.26459132217589243,62.26308624311537,334.5825070830346,0.08004503029011732
0.083739552224541,308.862912952946,0.2658730783129177,62.266763251313904,334.72695498239307,0.08041760867356527
0.0841416485570716,308.89179157223,0.2671497341687023,62.27258518096156,334.88245614086475,0.08078856658121879
0.084546504427665,308.900911136214,0.26843515155783637,62.274423685060746,335.01740338730167,0.08116193134990558
0.0849522356184938,308.887231790237,0.2697233480887178,62.27166592891179,335.12789268482555,0.0815359635519711
0.0853606348021596,308.885711862907,0.27102001549685667,62.27135951156205,335.2523923088417,0.0819123140717993
0.0857722159969104,308.870512589599,0.2723267857901905,62.26829533806316,335.3630209105105,0.08229145365280607
0.0861815200401158,308.867472734938,0.27362632612736765,62.2676825033635,335.486141026184,0.0826683530694552
0.0865943395201113,308.841633970315,0.27493702797635333,62.26247340841551,335.5855712802864,0.08304834577155239
0.0870086128863887,308.820354987685,0.2762523459142841,62.25818356551729,335.69038570624565,0.08342953164621741
0.0874243276866025,308.803635787047,0.2775722404049629,62.25481297466869,335.8005860329081,0.0838118978231841
0.0878431134416574,308.791476368401,0.2789018851772622,62.25236163586964,335.91668105684727,0.08419694083197538
0.088263439514717,308.783876731747,0.2802364204592265,62.2508295491202,336.0382037587794,0.08458325103146079
0.0886816560011296,308.782356804416,0.28156425780358646,62.25052313177027,336.1656875497633,0.08496747431060465
0.0891016690689562,308.785396659078,0.2828977992939359,62.25113596647013,336.2986908855215,0.085353199619637
0.0895176935133233,308.791476368401,0.28421867690480146,62.25236163586964,336.43377710947414,0.0857351153012555
0.0899390065344586,308.796036150393,0.285556345746906,62.25328088791923,336.56884486353806,0.08612173736754755
0.0903549119565411,308.797556077724,0.28687684546201797,62.25358730526916,336.6989320695218,0.08650325054207862
0.0907818193762267,308.817315133023,0.28823227651951977,62.257570730817434,336.85231285568034,0.08689470461188036
0.0912134466219524,308.821874915015,0.2896026930246988,62.258489982867026,336.99058251826693,0.08729033081518292
0.0916474092062264,308.894831426891,0.2909805242297688,62.27319801566123,337.20424244435964,0.08768793984173422
0.0920906843475186,308.903950990876,0.29238792280337156,62.275036519760604,337.35112723527817,0.08809391814901293
0.0925361908030179,308.906990845537,0.29380240579958183,62.275649354460256,337.49206709080573,0.08850177403208619
0.0929799294682299,308.903950990876,0.29521127606162995,62.275036519760604,337.62581856646517,0.08890784623369895
0.0934362550894891,308.887231790237,0.2966601099091279,62.27166592891179,337.7484979736758,0.08932526505003231
0.0938817595143094,308.8507535343,0.29807458645793233,62.26431191251488,337.84620570342037,0.08973261727591456
0.0943286205909335,308.820354987685,0.2994933703762138,62.25818356551729,337.9509530840757,0.09014104334581967
0.0947758123548453,308.716999929194,0.3009132042266338,62.23734718572551,337.97590438523406,0.0905496047313818
0.0952204044676553,308.672922036603,0.3023247841848056,62.22846108257916,338.0648825211413,0.09095562563269893
0.0956688670261502,308.634923853334,0.3037486528080269,62.22080064883213,338.1616773430846,0.09136501425000024
0.0961189954294192,308.603005379388,0.3051778104884059,62.214365884484614,338.2656162429544,0.0917757551043574
0.0965707449187893,308.58476625142,0.30661211511715597,62.21068887628627,338.3850269989101,0.09218780564433947
0.0970228606853281,308.563487268789,0.3080475826759167,62.20639903338786,338.5011995066477,0.09260002035155382
0.0974709024613639,308.549807922812,0.3094701153148304,62.2036412772389,338.62443615532897,0.09300835305204751
0.097922843516279,308.530048867513,0.3109050281641858,62.19965785169063,338.7421885628364,0.09342007059668153
0.0983723177737595,308.505730030221,0.3123321089316864,62.194755174092556,338.8541537397795,0.09382937283590449
0.098821730140783,308.472291628945,0.313758993196986,62.18801399239532,338.9560571882095,0.09423845129096163
0.0992729542892074,308.428213736353,0.3151916298682335,62.17912788924876,339.0467937001039,0.09464901063397704
0.0997253218087208,308.385655771092,0.31662789674268854,62.17054820345215,339.1395145340575,0.09506044117561195
0.100178831711106,308.350697442485,0.31806779068276153,62.16350060440498,339.2409100695779,0.09547274087338198
0.100637560731148,308.308139477224,0.3195242553213949,62.15492091860836,339.3355185877704,0.09588961256541455
0.10109834292236,308.241262674672,0.320987238778493,62.141438555213874,339.4039435513772,0.09630817520698708
0.101564919844924,308.186545290765,0.32246862050763364,62.130407530618236,339.4874870605056,0.09673182319479269
0.102037007731833,308.145507252835,0.32396749954856974,62.122134262171535,339.58775275892214,0.09716029250063564
0.102511361256912,308.102949287574,0.3254735719906956,62.113554576374916,339.68700202631254,0.09759063328069939
0.102985710860487,308.048231903667,0.3269796319820462,62.10252355177927,339.7727980455823,0.098020785391882
0.103466354740516,307.978315246453,0.3285056763011383,62.08842835368493,339.8437088641289,0.09845645666262907
0.103953718329029,307.903838807247,0.33005305569466703,62.073413903540995,339.91158773904226,0.09889802517274435
0.104441238651873,307.852161278002,0.33160093271969676,62.0629957136452,340.00462232353266,0.09933954069896175
0.104931668925223,307.782244620787,0.333158048837583,62.04890051555067,340.07834921439746,0.09978349498094227
0.105422235842818,307.694088835604,0.33471559880094715,62.031128309257774,340.1318876362721,0.10022737586770114
0.105915708227435,307.605933050421,0.3362823736221061,62.013356102964885,340.18623330441727,0.10067368701985359
0.106412872159115,307.5208171199,0.33786086910519014,61.996196731371846,340.2449905183465,0.10112313557325285
0.106915914215587,307.441780898701,0.3394580276344887,61.980263029178126,340.3121999715538,0.10157769259002358
0.107417030152892,307.350585258856,0.34104907073543206,61.961877988185364,340.3652723431155,0.10203030379028066
0.107918865360601,307.248750127697,0.34264239751990816,61.94134802574372,340.40668662494085,0.1024833594350784
0.108422295609653,307.149954851198,0.34424078856064827,61.92143089800152,340.45185805256614,0.10293764893398372
0.10892816238867,307.042040010716,0.3458469155840272,61.89967526616035,340.4875652051518,0.10339392934375718
0.109435026274079,306.931085315571,0.3474562084202008,61.87730679961912,340.5200967014121,0.10385090040856738
0.109946109583689,306.817090765766,0.34907889792821256,61.85432549837843,340.5504362492476,0.10431146422105263
0.110444345715839,306.681817233329,0.3506607976477888,61.82705435423913,340.5530898806086,0.10476024667669963
0.110952966120209,306.545023773563,0.35227566743166355,61.799476792750305,340.5571034106298,0.10521817503606863
0.111463844858578,306.39607089515,0.35389770742598514,61.76944789246224,340.54815500668485,0.10567792565066457
0.111978164290873,306.251677798729,0.35553067162352175,61.74033824422377,340.5451784896306,0.10614055920652243
0.112499705659878,306.096645210993,0.3571865654701126,61.709083674536195,340.53242770070585,0.10660947048283266
0.113029214426797,305.940092695927,0.35886775580508046,61.67752268749888,340.52026103500907,0.10708532031082765
0.113561755420578,305.76226119823,0.36055857346033515,61.64167185756317,340.4851603212663,0.10756366681554902
0.114109101184171,305.575310136549,0.3622963962597429,61.60398252352827,340.4442341203049,0.10805507314066638
0.11465290135536,305.344281182276,0.364022961803268,61.55740708634685,340.3528889320908,0.10854305721555693
0.115206237162816,305.120851864656,0.3657798029919408,61.512363735914654,340.272677087896,0.10903935387327432
0.115764164240174,304.856384509107,0.3675512214625524,61.45904711703597,340.14782907508487,0.10953951926196635
0.116322632900208,304.613196136188,0.3693243594581604,61.4100203410555,340.04660512689685,0.11003991975929743
0.116883847416723,304.321370088686,0.37110621554809553,61.351188209879105,339.8916226757801,0.11054252848202482
0.117436218853612,303.996105639907,0.3728599948602181,61.28561489700525,339.69625883248085,0.11103697102540162
0.117994129422324,303.628283225867,0.3746313609158787,61.21146189833478,339.454638173098,0.11153612375518895
0.118550151338309,303.304538704419,0.376396730499131,61.14619500281086,339.2613376694238,0.11203333897442086
0.119109965765047,302.942795999702,0.3781741413040242,61.07326767353993,339.0263020599941,0.11253369596263244
0.119676382446298,302.549134821039,0.37997251426699613,60.99390557992146,338.75712078867826,0.11303969931019534
0.120231779073101,302.085556985163,0.3817358985570956,60.900448288208864,338.40584093377777,0.11353560949769903
0.120780452334342,301.596140384663,0.3834779361615358,60.801781901548054,338.02305864261433,0.1140252750733837
0.121343014575647,301.038327054281,0.3852640712776792,60.68932673414305,337.567225161857,0.11452708709347306
0.121910086212023,300.304202153532,0.387064523723173,60.54132715415205,336.9143133279019,0.11503266682342522
0.122478007752322,299.66583267462,0.3888676746136223,60.412631867203395,336.36830685204814,0.1155387482395114
0.123050925240339,298.910428791241,0.3906866876380763,60.26034244431418,335.6916336179897,0.11604902222621521
0.123595171749912,298.123106433916,0.39241467030597055,60.10161825707747,334.9696829762331,0.11653351911332904
0.124152794556023,296.680695397041,0.39418512271537304,59.810828192043466,333.51443282140787,0.11702968044983948
0.124725504223125,295.086291627091,0.3960034759084219,59.48939639202155,331.89107813961203,0.11753900963834536
0.125301762954751,293.552684950372,0.39783309738133443,59.180221285994996,330.33535389475423,0.11805123342570274
0.125874177622819,291.943081907115,0.39965051395245027,58.85572531247439,328.6911772548444,0.11855978068767956
0.126456573219712,290.094850272932,0.40149961997258554,58.48312181502309,326.7792509471324,0.1190769299648495
0.126732006441156,289.03064782019,0.4023741204506703,58.2685786005503,325.66008174142985,0.11932141302792047
0.127036631116718,287.696100959553,0.40334130379557964,57.99953395344589,324.2440444108698,0.1195917377385766
0.127346759016562,286.984318990566,0.40432595987758435,57.85603870849811,323.53084190258977,0.1198668709773662