File: example/data/02 processed data/test_ID_112.csv
Strain,Stress_MPa,Displacement(mm),Force(kN),True Stress (MPa),True Strain
-6.88953713611942e-05,-0.453991782090731,-0.00021874280407179156,-0.09152474326949137,-0.4539605041583089,-6.889774475634156e-05
-7.97171180747151e-05,-0.391741740979957,-0.00025310184988722043,-0.07897513498155934,-0.3917105124573365,-7.972029565308113e-05
-0.0001483501474054,0.336416069352207,-0.000471011718012145,0.06782147958140493,0.33636616197872904,-0.00014836115237696433
-0.0002395692882202,1.91345193363492,-0.000760632490099135,0.3857519098207999,1.9129935293171356,-0.00023959798952620883
-0.0003460142882306,4.70861045514739,-0.001098595365132155,0.949255867757714,4.706981208652198,-0.0003460741649869265
-0.0004072678799849,8.24405980640723,-0.0012930755189520574,1.6620024569716978,8.240702265647407,-0.0004073508360722721
-0.0004276135424736,12.0627583095372,-0.0013576729973536798,2.4318520752026997,12.057600110724456,-0.00042770499521629625
-0.0004126464295184,16.2946769962423,-0.00131015241372092,3.285006882442447,16.287953055959644,-0.00041273159148499456
-0.000353221558212,20.7305248608229,-0.0011214784473231,4.179273811941896,20.723202392529007,-0.00035328395564048355
-0.0002884704514522,25.5343058068623,-0.000915893683360735,5.14771605066344,25.526939914138676,-0.0002885120670563151
-0.00022380962521,30.6001494732463,-0.00071059556004175,6.168990133806455,30.593300865261323,-0.00022383467432168485
-0.0001319447524098,35.7262595129169,-0.00041892458890111493,7.202413917804047,35.72154562045093,-0.0001319534578844654
-4.3071078951481e-05,40.8696890361355,-0.00013675067567095218,8.239329309684916,40.8679287345323,-4.3072006537073485e-05
4.12721763099693e-05,46.0067964994317,0.00013103915978415252,9.274970174285432,46.00869530004828,4.1271324637057056e-05
0.0001332727758883,51.1680731019099,0.0004231410634453524,10.315483537345035,51.174892413049044,0.00013326389586083216
0.0001982729226295,56.3116289538591,0.0006295165293486624,11.352424397097996,56.32279402510981,0.00019825326915139577
0.0003058382390544,61.4642729664254,0.0009710364089977199,12.391197430031362,61.483071091434205,0.00030579148007370277
0.0004075023198852,66.6267536586153,0.00129381986563551,13.431953537576845,66.65390421529762,0.00040741931336440063
0.0005368942557907,71.6656238156636,0.0017046392621354726,14.44778976123778,71.70410067742787,0.0005367501796364702
0.0006464367103608,76.7410387527898,0.00205243655539554,15.470993412562425,76.79064697743084,0.0006462278601514394
0.0007560542552175,81.7266459387496,0.0024004722603155624,16.47609182125192,81.78843571717624,0.0007557685901754382
0.0008710424821894,86.7146366524001,0.0027655598809513448,17.48167074912386,86.79016878475196,0.0008706633448336875
0.0009850576840779,91.6956351042472,0.0031275581469473322,18.48584003701624,91.78596059420305,0.000984572833135466
0.0010922581222826,96.6660138875939,0.0034679195382472552,19.487868399738932,96.7715981264113,0.001091662042388936
0.0012044121695474,101.613120447508,0.0038240086383129947,20.485205082217615,101.73550452636066,0.0012036874470616407
0.0013019410491326,106.532597172304,0.004133662830996004,21.476971589936483,106.67129633363332,0.0013010942587859623
0.0014065428369618,111.371744098773,0.004465773507353715,22.452543610312638,111.52839322767507,0.001405554582159012
0.0014902239239617,116.14640695633,0.004731460958578397,23.415115642396128,116.31949111065852,0.0014891146422054257
0.0015984349318561,120.835654037889,0.005075030908643118,24.360467854038426,121.02880196831684,0.0015971587944411474
0.0017023621552825,125.466030927887,0.005404999843021937,25.29395183506202,125.67961955071215,0.0017009147792346393
0.0018273003983359,130.022609467224,0.005801678764716482,26.212558068592358,130.26019983329613,0.0018256329159815551
0.0019421448878035,134.482356791367,0.006166310018776112,27.11164312913959,134.7435410131091,0.0019402613627455647
0.0020277530532309,138.883124784559,0.006438115944008107,27.99883795656709,139.1647454648831,0.002025699937015067
0.0021320618008556,143.195749200914,0.006769296217716529,28.868263038904267,143.50105138783016,0.002129792182499452
0.0022245753190338,147.422162845691,0.0070630266379323155,29.720308029691306,147.75011455063608,0.0022221046148586106
0.0023258634302033,151.476601140634,0.0073846163908954775,30.537682789951816,151.82891502775848,0.002323162796581289
0.0024241232600653,155.435889158498,0.007696591350707327,31.335875254353198,155.812684912856,0.0024211898130103125
0.0025365000310913,159.315233127494,0.008053387598714877,32.11795099850279,159.7193362212752,0.002533288544365203
0.0026433519402855,163.103870788153,0.008392642410406463,32.88174035089164,163.53501172146895,0.0026398644300049145
0.0027519746559977,166.936258936397,0.008737519532792698,33.65434980157764,167.39566329015702,0.0027481949066722705
0.0028682714991142,170.703483147695,0.009106762009687585,34.41382220257532,171.19310708320705,0.002864165857274536
0.0029838261859169,174.399552412702,0.009473648140286157,35.158949766400724,174.91993036400322,0.00297938341201249
0.0031137151864611,178.03513658489,0.009886045717013991,35.89188353551383,178.58948729339807,0.0031088776146092024
0.0032477949703685,181.506719877966,0.010311749030919987,36.59175472739794,182.0962164898737,0.003242532275973247
0.0033818235425104,184.90300554821,0.010737289747470518,37.27644591851914,185.52831488545388,0.0033761180369974533
0.0035169327666299,188.078548601474,0.011166261534049933,37.91663539805716,188.74000821175076,0.0035107628205460952
0.0036951019743122,190.999349191906,0.011731948768441235,38.50546879708825,191.70511126419734,0.0036882918559108468
0.00388166130908,193.574964976206,0.012324274656329,39.02471293920313,194.32635742816063,0.0038741471006186515
0.0041035759857148,195.740256425986,0.013028853754644487,39.46123569547878,196.54349144169333,0.004095179280952156
0.0043787417596088,197.462526285647,0.013902505086757938,39.80844529918643,198.32716369545182,0.004369182963418667
0.0046446670041362,198.769503696362,0.014746817738132434,40.07193194518658,199.69272185160904,0.004633913822123885
0.0049409520988637,199.682321287479,0.01568752291389225,40.25595597155577,200.66894207195034,0.0049287856544636514
0.0052422016288857,200.278910860798,0.016643990171712097,40.37622842953688,201.32881329354393,0.005228509121669758
0.0055667521949281,200.675669583983,0.017674438218896717,40.456214988130974,201.7927813081083,0.0055513150931106635
0.0058907153421385,201.002439789064,0.018703021211289736,40.5220918614753,202.18648794493672,0.005873432915873658
0.0062282869979954,201.225432963323,0.019774811218635394,40.56704728540591,202.47872271111447,0.0062089713791866705
0.0065653992018956,201.445324214025,0.020845142466018526,40.61137736154744,202.76789318484538,0.006543940839160275
0.0068933567835642,201.575690646145,0.021886407787816333,40.637659234262834,202.96522380066227,0.0068697062253088486
0.0072362108772589,201.600702123782,0.022974969535297006,40.642701548154456,203.05952731735317,0.0072101551244374805
0.0075974474869481,201.714312566582,0.024121895771060217,40.66560541342293,203.24682646367245,0.007568732232835464
0.0079425416937793,201.809776856884,0.025217569877749278,40.68485101434782,203.41265942378212,0.00791116573656734
0.0083224869783428,201.942549735815,0.026423896156238386,40.711618026740304,203.62321397636464,0.008288046041148025
0.0086909379824363,201.999665474816,0.02759372809423525,40.723132559722906,203.7552320399305,0.008653389180298409
0.0090586439564917,202.005487372058,0.028761194561861145,40.724306254206894,203.83538315941905,0.009017860551193293
0.0094227906432521,202.0323221964,0.029917360292325414,40.72971615479424,203.9360304716267,0.009378673075370004
0.0097888783030265,202.049299944926,0.03107968861210914,40.73313886889708,204.02713595329857,0.009741277619921416
0.0101736551962354,202.133577181721,0.03230135524804739,40.75012915983495,204.19001449954948,0.010122251911752853
0.0105558058748517,202.152019975721,0.03351468365265414,40.753847227105354,204.28589745579384,0.010500482338471522
0.010930582656831,202.162945055175,0.034704599935438424,40.756049723123276,204.37270383624895,0.010871275620483609
0.0113073485119781,202.150659084576,0.03590083152553047,40.75357287145052,204.43644703877138,0.011243898301227106
0.0116835782478085,202.139759781533,0.037095360936791985,40.751375571957055,204.50147548193374,0.01161585225830244
0.0120666654406099,202.129536866102,0.03831166277393643,40.749314632206165,204.56856636313066,0.011994443636929229
0.0124623777963192,202.112794266533,0.039568049503313454,40.745939324133055,204.63160026615225,0.012385361576160998
0.0128430349947304,202.110299806045,0.04077663610826902,40.74543644089867,204.7060094592495,0.012761262613594167
0.0132272522355546,202.079907654623,0.04199652584788585,40.739309383172,204.75286956490828,0.013140535976272169
0.0136155821390485,202.028772985242,0.043229473291478984,40.72900063382479,204.77951233827375,0.01352372297198745
0.0140180356227797,201.990400770102,0.04450726310232554,40.721264795252566,204.82190940355684,0.013920691621047936
0.0144005057066297,201.949401929575,0.045721605618549294,40.71299942900232,204.8575754445123,0.014297803228529075
0.0147785561143384,201.903372995728,0.046921915663024415,40.70371999593877,204.88721332321956,0.014670417375004142
0.0151594021594521,201.828520380744,0.04813110185626041,40.68862970875799,204.8881200884429,0.01504564662576031
0.0155328754276203,201.692705110214,0.04931687948269445,40.661249350219144,204.8255727733507,0.015413475150545742
0.0159346439655391,201.648512350484,0.05059249459058664,40.652340089857574,204.86170960096956,0.01580902028166062
0.016337512726033,201.659239957705,0.05187160290515477,40.65450277547333,204.95385035683617,0.016205491555889046
0.016723387696489,201.702121722491,0.053096755936352574,40.663147739254185,205.07526450326063,0.016585091571815123
0.0171005767151405,201.711890465465,0.05429433107057109,40.665117117837745,205.16128012272569,0.016956007668366302
0.017500901771924,201.635300556864,0.0555653631258587,40.64967659226378,205.16410014566208,0.017349524596553534
0.0178954924904952,201.544903124704,0.05681818865732225,40.63145246994033,205.15164842506974,0.01773725322241416
0.0183099273259545,201.460338304627,0.05813401925990553,40.6144042022128,205.14906245804693,0.01814431906866796
0.0187132943046335,201.392143876395,0.05941470941721136,40.600656205481236,205.1608543353951,0.0185403547934136
0.0191289658519473,201.353313111671,0.06073446657993267,40.592827923312875,205.20499376236063,0.018948307421745813
0.0195564783554618,201.290140919209,0.06209181877859121,40.580092409312535,205.22666720326336,0.01936770759061019
0.0199727822512639,201.236889255696,0.06341358364776288,40.569356873948315,205.25614982572174,0.019775942872765285
0.0203713969778075,201.173046724568,0.06467918540453882,40.556486219672905,205.27122272062917,0.020166675706640037
0.0207756902959109,201.089013238998,0.0659628166895171,40.539545068982,205.26677629996175,0.020562818959530802
0.0211684372756775,200.979844226813,0.06720978835027606,40.517536596125495,205.2342734530037,0.02094749842191835
0.0215887254390226,200.796395410464,0.06854420326889675,40.48055331474954,205.1313336601259,0.021358989495793183
0.0220095096319193,200.677817643552,0.06988019308134377,40.45664803694008,205.0946380038903,0.021770796661822234
0.0224336168717782,200.576289513388,0.07122673356789579,40.43617996589902,205.0759411458942,0.02218568445248217
0.0228417818438622,200.51297577864,0.07252265735426248,40.42341591697382,205.0930494282393,0.022584814054059356
0.0232751907397609,200.490798839892,0.07389873059874086,40.418945046122225,205.1572604244575,0.023008454450173535
0.0236945046437582,200.402789130169,0.07523005224393228,40.401202288642075,205.1512339478359,0.023418146797654943
0.0241144375998086,200.340355562584,0.0765633393793923,40.38861568141693,205.17145056552138,0.02382827584170194
0.0245348464994421,200.218440981532,0.07789813763572867,40.36403770187685,205.1307696973715,0.0242387012949975
0.0249471003389121,200.05913943393,0.07920704357604591,40.331922509880286,205.05003485910467,0.02464100183310769
0.0253728884996321,199.939353169784,0.08055892098633191,40.30777359902846,205.0123920844495,0.025056340091680715
0.0257813996085714,199.841522738711,0.0818559437572142,40.28805098412414,204.9937168948231,0.0254546632375396
0.0262064882018262,199.759473611224,0.08320560004079819,40.27150988002276,204.99446789961956,0.025868982056730435
0.0266199074126559,199.580208765348,0.08451820603518248,40.23537008709416,204.8930154440801,0.026271762552248182
0.0270570373794198,199.407504122427,0.08590609367965786,40.20055283108129,204.80288041520436,0.026697467261524988
0.0274997688539177,199.301025827094,0.0873117661111887,40.179086806742156,204.7817579696878,0.027128442428536615
0.0279532288020648,199.224896869416,0.08875150144655573,40.16373920887427,204.79387599467455,0.027569668723684902
0.0283945018324645,199.214804629445,0.09015254331807478,40.161704613296116,204.87140976454984,0.027998850063590885
0.0288282607189825,199.113752557369,0.09152972778276944,40.141332515565594,204.8538557288278,0.02842054371859186
0.0292743308979977,198.979634183226,0.09294600060114269,40.114294251338364,204.8046298362683,0.02885402083272304
0.029735055647415,198.865650240841,0.09440880168054262,40.09131508855355,204.77893141711178,0.029301541626088216
0.0301850799992446,198.658509528869,0.0958376289976016,40.04955552101999,204.6550325315286,0.029738475419007333
0.0306381714472694,198.527255376004,0.09727619434508034,40.02309468380241,204.60976746316987,0.03017819430805544
0.0310783494973013,198.335916044646,0.09867375965393162,39.98452067460064,204.4998689613489,0.030605195840272204
0.0315189468706606,198.232094999386,0.10007265631434739,39.96359035187621,204.4801618697314,0.0310324216306258
0.0319664009650096,198.138058989737,0.10149332306390547,39.94463269233098,204.47181962983166,0.03146610932492562
0.0324221408810994,198.042234285634,0.10294029729749057,39.925314431983814,204.46318750605053,0.0319076346620949
0.0328906602088752,197.97432506974,0.10442784616317874,39.911623934059584,204.4858313256902,0.03236133769009673
0.0333628876813246,197.830103148051,0.10592716838820561,39.882548794647086,204.43028665936427,0.032818423395917576
0.0338210468050444,197.681905306175,0.10738182360601596,39.852672109724885,204.3677142780455,0.03326169225417284
0.0342784777581821,197.517859500725,0.10883416688222816,39.819600475346164,204.28847105446434,0.03370406067519351
0.0347526162240536,197.319771218037,0.11033955651137017,39.77966587755626,204.1771495005955,0.0341623800069331
0.0352225022403345,197.123203150853,0.11183144461306202,39.740037755211965,204.06637561545583,0.03461638162285629
0.0356876506401492,196.948800882024,0.1133082907824737,39.704878257816034,203.97744088189796,0.03506560285728778
0.0361295330764183,196.794546434702,0.1147112675176281,39.67378056123592,203.90464150937328,0.035492167948495995
0.0366060944365647,196.710532570209,0.11622434983609292,39.656843366154135,203.91133690214102,0.03595200601198871
0.0370886777571361,196.53357975896,0.1177565518789071,39.621169679406336,203.8227503670965,0.036417439339741904
0.0375536685612972,196.44109591176,0.1192328976821186,39.60252493581082,203.8181797194482,0.0368657005186119
0.0379905928285402,196.264539093663,0.12062013223061513,39.56693108128246,203.72074528505146,0.03728672191702289
0.0384619001084293,196.135832002793,0.12211653284426302,39.54098373176307,203.67958878096806,0.037740676235347846
0.0389222056828204,195.938187800853,0.12357800304295476,39.50113866065197,203.5645342475569,0.038183835091373845
0.0393861440038435,195.722564324357,0.1250510072122031,39.45766896779037,203.43132142763764,0.03863029273929613
0.0398775936722048,195.60213890857,0.12661135990925024,39.433391203967716,203.40228152538012,0.039103007834171324
0.0403605809057155,195.462610603808,0.12814484437564672,39.405262297727695,203.35159511312537,0.03956736547176481
0.040862048552366,195.39498071849,0.12973700415376205,39.391628112847584,203.37921990749757,0.04004926265014174
0.041374065635169,195.261699241791,0.13136265839166159,39.36475856714507,203.34046960225552,0.04054105807106846
0.0418598638734722,195.106415698622,0.13290506779827424,39.333453404842196,203.27354370060738,0.04100744664148071
0.0423555395861629,195.013482648828,0.1344788381860672,39.314718102003724,203.27338393299593,0.04148309394858073
0.0428516062188493,194.859891016986,0.13605384974484652,39.28375402902438,203.2099503346938,0.04195888997972581
0.0433559263019633,194.690665627193,0.13765506600873345,39.24963819044211,203.13165977780577,0.04244237025201546
0.0438688323955704,194.51571073096,0.139283542855936,39.21436728336153,203.04888784332175,0.04293384209930353
0.0443968485304512,194.338751597195,0.14095999408418255,39.17869232199451,202.96677971545262,0.04343954034541844
0.0449133656486544,194.184004358396,0.1425999359344777,39.147495278652634,202.90546154926457,0.04393397829457571
0.0454220972783243,194.007153467319,0.14421515885867967,39.11184213901151,202.81936526480237,0.04442072470321359
0.0459276631038191,193.816874905181,0.14582033035462563,39.073481980884495,202.7184310396612,0.04490420751887664
0.046427263469128,193.64104692422,0.1474065615144814,39.038035059922755,202.63127082820856,0.045381755919923425
0.0469377866745696,193.501302012496,0.14902747269175845,39.0098624857192,202.58382484761,0.045869509563778006
0.0474587206662303,193.368963882522,0.1506814381152812,38.98318311871643,202.54600752494096,0.04636696455912152
0.0479792286387179,193.185358583905,0.15233405092792932,38.94616829051525,202.4542430730549,0.046863765701208274
0.0484956044943935,192.985887114084,0.15397354426969936,38.905954842199336,202.3448543685683,0.04735637916639953
0.0490088317874806,192.798046763319,0.15560304092525087,38.868086227485115,202.24685380609733,0.04784574862321859
0.0495320273662326,192.586836509291,0.15726418688778848,38.825506240273064,202.12605296564536,0.04834437659828034
0.0500599734186525,192.481107112924,0.15894041560422167,38.80419119396548,202.11670621858977,0.048847280079861076
0.0506034575107765,192.27956792204,0.1606659775967154,38.763560893083266,202.00957886757342,0.04936472051915116
0.0511390859164952,192.138240390364,0.16236659778487225,38.73506926269738,201.96401437353103,0.04987441988170141
0.0516841909443698,191.967279363575,0.16409730624837413,38.70060351969672,201.88895288527317,0.050392870524779795
0.052225500113443,191.813493709527,0.16581596286018152,38.66960033184064,201.83104934701382,0.050907445065044875
0.0527505117371102,191.657970777062,0.16748287476532486,38.638246908655695,201.7680268140481,0.051406274155350797
0.0533111655032832,191.441794217212,0.16926295047292414,38.59466571418994,201.64777939297127,0.05193869330097788
0.0538446184687389,191.228380444816,0.170956663638246,38.55164149767491,201.52499963026196,0.05244501844400713
0.0544275665170683,191.059801289097,0.17280752369169186,38.517655939881955,201.4587213324972,0.052998028693193575
0.0549876817165118,190.922808449985,0.17458588944992495,38.49003818351698,201.42121107345534,0.05352909076177058
0.0555551239063027,190.806799585106,0.17638751840251105,38.46665079635737,201.40709497822166,0.05406681233932112
0.0560982198390468,190.635998186645,0.1781118479889736,38.43221723442763,201.3303383221555,0.05458119217001371
0.0566538157280512,190.433796773017,0.17987586493656255,38.39145342944023,201.22259800378865,0.055107137375564205
0.0572100832697954,190.250740484594,0.1816420143816004,38.35454928169415,201.13500118985786,0.05563344141514628
0.0577655204631504,189.979854936522,0.1834055274705025,38.29993875520284,200.954140134444,0.05615868360247369
0.0583132180080658,189.73591605749,0.1851444671756089,38.25076067718998,200.8000278945105,0.05667633688936552
0.0588523463762624,189.531131744144,0.1868561997446331,38.209476159619435,200.6854835586354,0.05718562949162507
0.0593997828102448,189.349522703922,0.18859431042252722,38.17286377711068,200.59684322775848,0.05770250511622824
0.0599663500096591,189.228810130407,0.19039316128066763,38.14852812229005,200.5761711905983,0.0582371623461773
0.060555010522831,189.00021090595,0.19226215840998842,38.10244251863952,200.44512066617708,0.058792365928890006
0.0611277700626445,188.795249607755,0.19408066994889628,38.06112232092341,200.33588221469742,0.059332276568659546
0.061709417646311,188.554925627173,0.1959274010270374,38.01267300643808,200.19054028196933,0.05988026734401411
0.0622887352059248,188.407138247283,0.19776673427881125,37.98287907065225,200.14278059247405,0.060425764592400275
0.062874864882004,188.253787950128,0.19962769600036268,37.9519636507458,200.09021943101774,0.060977373598800615
0.0634583495111677,188.07630363719,0.20148025969795744,37.9161828132575,200.01131544816732,0.06152619129102268
0.0640711106806773,187.916902312386,0.20342577641115045,37.88404750617702,199.9569469592129,0.06210222203270525
0.064668465556686,187.726490491067,0.20532237814247803,37.84566048299911,199.86647457546613,0.0626634507507282
0.0652225930904052,187.537885587031,0.20708173306203653,37.807637734345455,199.7695927877089,0.0631837849189682
0.065811446593664,187.342567736568,0.20895134293488318,37.76826165569211,199.671853127883,0.06373643073060736
0.0664128612234693,187.138324104718,0.21086083438451503,37.72708613951115,199.56671565307727,0.0643005502217412
0.0670199352519677,186.927252231717,0.21278829442499744,37.68453404991415,199.45510457311488,0.06486965560522097
0.0676521535610499,186.708967295204,0.2147955875563334,37.64052780671312,199.34023102188416,0.06546198857371806
0.0682604782709127,186.446038739747,0.2167270185101478,37.587521409933,199.17293451583924,0.066031604312906
0.0688652635430608,186.226702381003,0.21864721174921803,37.54330320001021,199.05125331922594,0.06659758438273504
0.0694910797954577,186.016801161331,0.22063417835057816,37.50098711412433,198.94330953412884,0.0671829089683344
0.070105748126575,185.786907827303,0.2225857503018756,37.45464061798428,198.81163799265912,0.0677574736152861
0.0707165549263306,185.590277188491,0.22452506189109964,37.41499988119979,198.71458221908387,0.06832810184113997
0.0713284931021143,185.355744054911,0.22646796559921287,37.36771800147006,198.576889966169,0.06889946068627181
0.0719446107478801,185.103493636028,0.2284241391245193,37.316864317023246,198.4206924337447,0.06947439223524733
0.0725564959497635,184.838982582205,0.2303668746404991,37.26353888857253,198.25025147328918,0.07004504730889347
0.0731757314340823,184.588851725975,0.2323329473032113,37.21311250795656,198.0962759656006,0.07062222603940507
0.0737867971553175,184.295042300778,0.23427308096813304,37.15388052783685,197.89358320375615,0.07119146348961515
0.0743950002155698,184.062300414977,0.2362041256844341,37.10695976365936,197.75561529402748,0.07175771265646666
0.0750223475717614,183.881432127401,0.23819595354034245,37.070496716884044,197.67664884045612,0.07234144980239723
0.075661526753847,183.708559117098,0.24022534744346422,37.03564551800695,197.608229177647,0.07293584603936624
0.0763016502926508,183.520541796683,0.24225773967916628,36.997741226211296,197.52346199837132,0.07353076658866887
0.0769447550704232,183.300365196857,0.24429959734859363,36.953353623686375,197.4043669012483,0.07412810165937213
0.0775887529483991,183.028529234824,0.24634429061116714,36.89855149374051,197.2294845721336,0.07472590892925966
0.0782411032167021,182.800074729108,0.24841550271302912,36.85249506538817,197.10255424400899,0.07533110537957165
0.0788845734746984,182.52083646884,0.2504585207821674,36.79620063211814,196.91891480392962,0.075927705090043
0.0795240582983415,182.243627037043,0.2524888850972343,36.74031521066787,196.73637985803802,0.0765202572443855
0.0801601057979027,181.90231489347,0.25450833590834104,36.67150668252355,196.48362370021394,0.0771092762579289
0.0807902097325971,181.588171451711,0.2565089159009958,36.60817536466494,196.25871790825352,0.07769244927030548
0.0814332550070176,181.289823995151,0.25855058464728087,36.548028517422445,196.0528444627255,0.07828724930264762
0.0820863107340762,181.013469410055,0.26062403658069194,36.49231543306709,195.87219730710194,0.07889094686770175
0.0827530795418874,180.759841397035,0.2627410275454925,36.44118402564226,195.71827493014277,0.07950694529408872
0.0834065781918903,180.475797097603,0.2648158857592517,36.383920694876764,195.52866577996792,0.08011031602670812
0.0840484357839091,180.149300782086,0.2668537836139114,36.31809903766854,195.29056772038527,0.0807025844767039
0.0846732346164002,179.773465133323,0.2688375199070706,36.24233057087792,194.99546592436008,0.0812787753805939
0.0852891916374496,179.316515694265,0.27079318344890246,36.15020956396383,194.61027636507293,0.08184648754937679
0.0859123552217514,178.897666678157,0.2727717278290607,36.06576960231646,194.2671865661533,0.08242051403928467
0.0865665875835868,178.505646467842,0.2748489155778881,35.98673832791695,193.95827114696525,0.08302280515357074
0.0872158218309554,178.244848767416,0.2769102343132834,35.934161511511064,193.79061973980052,0.08362013657355176
0.087868685504982,178.011378074875,0.2789830764783178,35.8870938198948,193.65300387124464,0.08422044768002226
0.0885191740278496,177.665428092339,0.2810483775384225,35.817350303415544,193.39222504037718,0.08481821662951197
0.0891916130826352,177.2993182208,0.2831833715373667,35.743542553313276,193.11293041136457,0.0854357817167927
0.0898588161755426,176.901261162901,0.28530174135734776,35.66329425044084,192.79739907095978,0.08604816140732176
0.0905372539352732,176.519118682968,0.2874557812444924,35.586254326486355,192.5006749555985,0.08667046832754162
0.0911896331679386,176.143477056411,0.28952708530820503,35.51052497457246,192.2059361141103,0.08726850766598075
0.0918730384106571,175.633431676191,0.29169689695383627,35.40769982592011,191.76940869077325,0.08789460537168611
0.0925405830037823,175.127236069807,0.2938163510370088,35.305650791673095,191.33361259554792,0.08850579421189575
0.0932079909519525,174.642042386913,0.2959353712724492,35.20783574520166,190.9200762935429,0.0891164847340033
0.0938780338473297,174.198305820558,0.2980627574652718,35.11837845342449,190.55170027052785,0.08972921135631506
0.0945544521814148,173.71731208161,0.30021038567599195,35.02141011565258,190.1430573599145,0.09034738748004201
0.095222535067938,173.135163727281,0.3023315488407031,34.90404900741985,189.62153292679523,0.09095757099292212
0.0959004033935615,172.554760220151,0.30448378077455773,34.78703966038244,189.10283133274277,0.0915763115805458
0.096585927823549,171.924263966899,0.306660320839768,34.65993161572684,188.5297285175227,0.092201651353539
0.0972665673592062,171.322590954032,0.30882135136547967,34.538634336332855,187.98655128721606,0.09282214845531753
0.0979185508039377,170.677331170265,0.31089139880250216,34.408549963925424,187.38980809354112,0.0934161607402115
0.0985805924561721,169.928577318658,0.3129933810483464,34.25760118744146,186.68023714596575,0.09401897606505585
0.0992406356841631,169.263110789359,0.3150890182972178,34.12344313513477,186.0608895019739,0.09461961021981168
0.0999075710240459,168.528623937993,0.31720653800134574,33.975370585899384,185.36590940366273,0.09522614993213749
0.100613824977921,167.767584875705,0.31944889430489914,33.82194511094213,184.6473232973577,0.09586804687475137
0.101311305415456,167.059181533177,0.32166339469407274,33.679130997088485,183.98416529594078,0.09650156565450935
0.10201246079998,166.245285143908,0.3238895630399365,33.51504948501186,183.2043757778324,0.09713801810779225
0.102723594010891,165.412620062302,0.3261474109845789,33.34718420456009,182.4043988898597,0.09778311413551928
0.10336738281886,164.515110619569,0.32819144044988047,33.16624630090511,181.52060703846905,0.09836676080558476
0.104067070738927,163.50807944122,0.3304129495960932,32.96322881534995,180.52388631081553,0.09900069849045855
0.104756315172616,162.553554492641,0.33260130067305577,32.77079658571643,179.58206587950113,0.09962478139401319
0.105513105685818,161.590948198504,0.3350041105524721,32.57673515681841,178.64091099364433,0.10030957623000421
0.106240930237049,160.605488745189,0.3373149535026306,32.37806653103011,177.6683652706538,0.1009677186506182
0.10697236332235,159.500958885468,0.3396372535484612,32.15539331131035,176.56315340962752,0.1016286880330619
0.107698229503046,158.232128176695,0.341941878672171,31.899597040421714,175.2734482318241,0.1022841951852667
0.108438240420036,156.959944695508,0.3442914133336143,31.643124850614413,173.98040491471502,0.10295203397095294
0.109180208143724,155.527699490575,0.3466471608563237,31.354384217299923,172.50824609307054,0.10362119123906162
0.109928256886289,154.034119787132,0.34902221561396757,31.053278549085814,170.96682207634524,0.10429537979963652
0.110709468219707,152.292330694746,0.3515025615975697,30.70213386806079,169.1525336399011,0.10499897170642393
0.111541244466829,150.183590319466,0.35414345118218205,30.277011808404346,166.93525488219564,0.10574756076634988
0.112209336828967,148.40782018666,0.3562646444319702,29.919016549630655,165.06056327003768,0.106348430655139
0.112663400613042,147.128681435201,0.3577062969464083,29.661142177336526,163.70469901340368,0.10675660122843766