File: example/data/02 processed data/test_ID_127.csv
Strain,Stress_MPa,Displacement(mm),Force(kN),True Stress (MPa),True Strain
1.70522449912983e-06,-0.843259542320858,5.41408778473721e-06,-0.17000112373188497,-0.8432609802676887,1.7052230452663527e-06
-3.10318756969716e-05,-0.767907704370763,-9.852620533788484e-05,-0.15481019320114583,-0.7678838747543342,-3.1032357195589943e-05
-9.9857041703925e-05,-0.403685419249949,-0.00031704610740996187,-0.08138298052078971,-0.4036451084182037,-9.986202775021867e-05
-0.000176283126903,1.05245020646354,-0.000559698927917025,0.21217396162304966,1.0522646772502349,-0.00017629866659968715
-0.000254756477674,3.78580634677459,-0.0008088518166149499,0.7632185595097574,3.7848418880845296,-0.0002547889336178509
-0.0002547795483562,7.75635323058755,-0.0008089250660309349,1.56368081128645,7.75437707041457,-0.000254812010179163
-0.0002014266860555,12.1580396467775,-0.0006395297282262124,2.451060792790344,12.155590693142518,-0.00020144697513497617
-0.0001205089592907,16.6060936141596,-0.00038261594574797244,3.3477884726145755,16.604092431100273,-0.00012051622107876912
-3.15442987271278e-05,21.0428446928076,-0.00010015314845863077,4.2422374900700115,21.04218091102854,-3.154479625894706e-05
5.6276246685859e-05,25.5784104857964,0.0001786770832276023,5.156607553936555,25.57984994273473,5.6274663237240895e-05
0.0001267357608663,30.1904001429901,0.0004023860407505025,6.086384668826804,30.19422634632308,0.00012672773056823894
0.0002089072639646,34.7221850783108,0.000663280563087605,6.999992511787458,34.72943879499439,0.00020888544588072434
0.000295799218877,39.1241477949021,0.0009391625199344749,7.887428195452263,39.13572068725906,0.0002957554789133544
0.0003799916560819,43.4624218174808,0.0012064735080600324,8.76202423840413,43.47893717512456,0.00037991947753672907
0.0004813336600453,47.6526115311775,0.0015282343706438275,9.606766484685384,47.675548337096515,0.0004812178561578939
0.0005799091641628,51.8108075916907,0.0018412115962168898,10.445058810484845,51.84085315381579,0.0005797410818219091
0.0006829812771363,55.8295991337134,0.002168465554907752,11.255247185356623,55.86772970463175,0.0006827481515647206
0.0007880167579048,59.7941185985166,0.00250195320634774,12.054494309460948,59.84123736599638,0.0007877064357148393
0.0008862826750769,63.6856542219461,0.0028139474933691574,12.839027891144335,63.742097713933944,0.0008858901584900859
0.0009810914208699,67.5064952133948,0.0031149652612619326,13.609309435020391,67.57272525670166,0.0009806104652304276
0.0010796313547856,71.2592398666369,0.0034278295514442794,14.365862757114002,71.33617357631512,0.001079048971989291
0.0011748154455914,74.8947943317564,0.0037300390397526947,15.098790537282092,74.98278189293175,0.00117412588994015
0.0012630792261671,78.3948243391295,0.0040102765430805425,15.804396586768508,78.49384321319128,0.0012622822126582864
0.0013569420337185,81.7399120303314,0.004308290957056237,16.47876626531481,81.8508283527978,0.0013560222198724212
0.0014340755397069,84.9646752360085,0.0045531898385694075,17.128878527579314,85.0865209985036,0.0014330482354174283
0.0015233062947429,88.1325966141847,0.004836497485808708,17.767531477419638,88.26684955337913,0.001522147240622702
0.001620989289899,91.3039999032996,0.005146640995429325,18.4068863805052,91.45200270926779,0.0016196769048101175
0.0017119357559306,94.5088949837939,0.005435396025079655,19.05299322873285,94.67068814037013,0.0017104720641737262
0.0018152807077348,97.6396379307667,0.00576351624705799,19.684151006842566,97.81688128181263,0.001813635076931058
0.0019032525936602,100.697876408975,0.006042826984871135,20.30069188404936,100.88952990342646,0.001901443703262465
0.0020010675935567,103.662377585989,0.006353389609542522,20.898335321335384,103.86981301044736,0.0019990681247368594
0.0020941309531616,106.552250296647,0.00664886577628808,21.480933659804037,106.77538466212225,0.002091941317327107
0.002188225197363,109.456969939992,0.006947615001627524,22.06652513990239,109.6964864396417,0.002185834519531628
0.00227735563238,112.288723828627,0.007230604132806499,22.637406723851203,112.54444518629089,0.0022747663883830385
0.0023813473768756,115.089556618495,0.00756077792158003,23.202054614288592,115.36362483225423,0.0023785164625804846
0.0024866309664559,117.837277461494,0.007895053318497483,23.75599513623719,118.13029528463261,0.0024835444153577684
0.0026142374138514,120.519581619653,0.008300203788978194,24.296747654522047,120.8346484190248,0.0026108262390106157
0.002747926840625,123.125489332384,0.008724667718984374,24.822098649408616,123.46382916928555,0.002744158192065952
0.0028732826095725,125.65304923095,0.009122672285392687,25.33165472495952,126.01408595214505,0.0028691626231321407
0.0030317652548256,128.039261951247,0.009625854684071278,25.812715209371394,128.42744693688428,0.0030271787224001204
0.0032154371704916,130.214317177609,0.010209013016310829,26.251206343005975,130.63301313319204,0.0032102787072446045
0.0034480635730481,132.114109052419,0.010947601844427718,26.63420438496767,132.56964689932835,0.0034421326314450487
0.0036998485692771,133.625770966757,0.01174701920745479,26.93895542689821,134.1201660842869,0.003693020965111605
0.0039727776756778,134.75608359602,0.012613569120277016,27.166826452957636,135.29143955659202,0.003964907033102973
0.0042709714884485,135.52829525024,0.013560334475823986,27.322504322448385,136.1071327351318,0.004261876776030313
0.0045958977312372,135.999453990493,0.01459197529667811,27.41748992448339,136.62449357253743,0.004585368840736865
0.0049252175338433,136.323507381589,0.015637565669952478,27.48281908812834,136.99493031041982,0.00491312832836053
0.005277591496307,136.504178221483,0.016756353000774722,27.51924232945097,137.22459151167507,0.0052637138160437314
0.0056346143174583,136.634308263087,0.0178899004579301,27.54547654583834,137.4041898926822,0.005618799258233052
0.0060104271649289,136.644981355918,0.019083106248649256,27.547628241353067,137.4662760638108,0.005992436598909844
0.0064103098928766,136.660030904845,0.020352733909883205,27.55066223041675,137.53606405291515,0.006389851240736055
0.0068024705236483,136.609441105371,0.02159784391258335,27.540463326842794,137.53872280174232,0.006779438113565978
0.0071933942991841,136.522267272411,0.022839026899909517,27.52288908211806,137.50432577152006,0.007167645246731916
0.0075861254501172,136.46145525482,0.02408594830412211,27.510629379371714,137.49666897348865,0.007557495502859189
0.0079946785317819,136.401108885251,0.02538310433840753,27.498463551266607,137.49159190216716,0.007962890400898343
0.0083914887570005,136.347858567798,0.026642976803476586,27.48772828726808,137.49202009001075,0.008356475951898784
0.008807985994444,136.274647533597,0.0279653555323597,27.472968942773154,137.47495272047072,0.008769421967972413
0.0092338844501627,136.233210695982,0.02931758312926657,27.46461527630997,137.49117242182336,0.009191512776175489
0.0096633982547598,136.152823876353,0.030681289458862365,27.448409293472768,137.46852283698038,0.009617006252001799
0.0100787057397727,136.059028834621,0.03199989072377832,27.42950021305959,137.43032774948438,0.010028254292080485
0.0104886689362808,135.892160414926,0.033301523872691544,27.39585953964908,137.31748829655413,0.010434044474849828
0.010895042856675,135.78196996363,0.034591761069943126,27.373645144667808,137.2613203455475,0.01083611947278116
0.0113004031673583,135.643811525144,0.0358787800563626,27.345792403469034,137.1766412825353,0.01123703058838053
0.011720829249965,135.577057415044,0.03721363286863887,27.332334774872876,137.16613295521844,0.011652672383852087
0.0121419841098562,135.484172573314,0.03855079954879343,27.313609190780102,137.1292192438362,0.012068861527889094
0.0125733452774588,135.38551718881,0.03992037125593169,27.293720265264103,137.08776604199227,0.012494957155129192
0.0129949993896502,135.308105032769,0.04125912306213938,27.27811397460623,137.06643377508453,0.012911288817688932
0.0134182765550491,135.191188910812,0.04260302806228089,27.2545436844197,137.00522167142316,0.013329048784601475
0.0138513864313155,135.065701092884,0.04397815191942671,27.229245340325416,136.9365483123381,0.013756332722958136
0.0142736104806979,134.933565407353,0.04531871327621583,27.202606786122367,136.85955456074933,0.014172701591864375
0.0147037055099164,134.798969525052,0.046684264993984564,27.175472256250483,136.78101387598855,0.014596654124276392
0.0151151234290584,134.63317668435,0.047990516887260415,27.142048419564958,136.66817376758016,0.01500202815954526
0.0155368889832299,134.509960460315,0.049329622521754934,27.117208028799507,136.59982678312556,0.015417427309826502
0.0159529369757902,134.384853723853,0.050650574898133884,27.091986510728766,136.52868682581044,0.015827026209176812
0.0163791243311339,134.292691862347,0.05200371975135013,27.073406679449153,136.49228855912304,0.01624643342092639
0.0168162674469409,134.204531394229,0.05339164914403736,27.05563352907657,136.46135068674576,0.01667643943442669
0.0172585432346226,134.119326287122,0.054795874769926756,27.03845617948379,136.43403047844674,0.017111306227259454
0.0176982082701735,134.025527780047,0.056191811257800865,27.01954640045748,136.3975394842182,0.01754341864642221
0.0181348404684181,133.894679591462,0.05757811848722746,26.993167405638737,136.3228382454231,0.01797236561258913
0.0185747482700542,133.751973451123,0.05897482575742208,26.9643978477464,136.2363826886006,0.018404344536741415
0.0190124998613999,133.566425078525,0.06036468705994468,26.92699129583064,136.10585671681812,0.018834020957696575
0.0194510561330376,133.432528663784,0.061757103222394374,26.899997778618857,136.02793226879643,0.019264302163474738
0.0198853742751321,133.276681117644,0.0631360633235444,26.86857891331703,135.92693780381578,0.01969024281964585
0.0203343968617622,133.158602463914,0.06456171003609498,26.844774256725064,135.86630233197286,0.020130413628920665
0.0207787097052555,133.04369925095,0.0659724033141862,26.82160976899152,135.8081756557988,0.02056577691092759
0.0212238125374942,132.898022505123,0.06738560480654408,26.7922413370328,135.71862522137542,0.02100172430515433
0.0216739457884731,132.816013205278,0.06881477787840208,26.77570826218405,135.69466027533034,0.021442405446860106
0.0221302187793748,132.688666245406,0.07026344462451499,26.750035115073853,135.6250954589603,0.02188889930022618
0.0225856404358796,132.563560253689,0.07170940838391773,26.7248137471437,135.55759316047886,0.02233436135499843
0.023041330265117,132.424224935689,0.07315622359174648,26.696723747034902,135.47545523753436,0.022779887194559336
0.0234942725047905,132.286394352199,0.07459431520270984,26.668937101403323,135.39436694978573,0.023222530114092223
0.0239390141390098,132.119817021413,0.07600636989135612,26.635355111516866,135.282635189132,0.023656968338883838
0.0243882107458995,131.942873067971,0.0774325691182309,26.599683210502953,135.16072366277214,0.024095566829040373
0.0248398133522217,131.806419563614,0.07886640739330389,26.572174184024586,135.0804664241988,0.024536320721064424
0.0252933016580468,131.657687812932,0.08030623276429857,26.542189863087092,134.98774542638546,0.024978719616922603
0.0257490170284993,131.571851997989,0.08175312906548526,26.524885362794585,134.9596978555564,0.025423094044304952
0.0262233184502713,131.413675862163,0.08325903607961137,26.49299705381206,134.85977853301722,0.025885382372483938
0.0266850318189992,131.261555491254,0.08472497602532246,26.462329587036805,134.76427427614945,0.026335196292771534
0.0271489133301307,131.059487640651,0.08619779982316497,26.42159270835524,134.6176103116984,0.026786918809204953
0.0276140561321041,130.949863545141,0.0876746282194305,26.39949249070043,134.5659204275679,0.027239664762710628
0.0280712309306997,130.789674971489,0.08912615820497155,26.36719847425218,134.4611021409648,0.027684455421095877
0.0285376930479825,130.684020032546,0.09060717542734444,26.34589843856127,134.4134404825112,0.02813807800324372
0.0290072229795316,130.537230181697,0.09209793296001283,26.316305604630116,134.3237527247079,0.0285944762437309
0.0294782169146841,130.396419949387,0.09359333870412201,26.287918261796417,134.24027390155328,0.02905208836402454
0.0299527486374422,130.268672453486,0.09509997692387898,26.26216436662278,134.17057725481857,0.029512926079970015
0.0304317418664308,130.124697784399,0.09662078042591779,26.233139073334836,134.08461899782114,0.02997788127626995
0.0309195693075881,130.002398387077,0.09816963255159221,26.20848351483472,134.0220165541589,0.030451189680926503
0.0314001519025628,129.863592339603,0.09969548229063689,26.180500215663965,133.94132886567903,0.030917249912743295
0.0318884133344231,129.737021267249,0.10124571233679333,26.1549834874774,133.87412902619587,0.0313905345993361
0.0323862137691209,129.589089372715,0.10282622871695886,26.12516041753934,133.78598932328546,0.03187283519811439
0.0328882974085341,129.448787466876,0.10442034427209576,26.096875553322207,133.70613768826075,0.032359050126529044
0.0333961802911675,129.32281755574,0.1060328724244568,26.071480019237185,133.64170568659324,0.0328506406101655
0.0339008075517631,129.142714105157,0.10763506397684783,26.035171163599653,133.5207564027483,0.03333884068358096
0.0343947976017247,128.994758971538,0.10920348238547592,26.00534340866206,133.43150759804732,0.03381651907551282
0.0348980768058401,128.809818706045,0.11080139385854232,25.968059451138675,133.3050336525949,0.03430294535210532
0.035405807599045,128.651072764287,0.11241343912696787,25.936056269280257,133.20606789399008,0.03479343450899562
0.0359125668285397,128.530404738525,0.11402239968061355,25.911729595286637,133.14626148819653,0.035282745322689775
0.0364244881408955,128.38431646788,0.11564774984734322,25.882278199924613,133.0606494805413,0.035776797505505414
0.0369327653022142,128.186910888272,0.11726152983453007,25.842481235075635,132.9212079829244,0.03626709137131812
0.037442638703226,128.026541280785,0.11888037788274254,25.81015072220626,132.8201928103851,0.03675868359738813
0.0379528730651828,127.837877898161,0.12050037198195539,25.772116184269258,132.68969265095225,0.03725038204170231
0.0384641163070693,127.687052426053,0.12212356927494503,25.741709769092285,132.59842206147556,0.03774281034953645
0.0389786536002839,127.496109166147,0.12375722518090138,25.703215607895235,132.46573584071822,0.038238166766752006
0.0394966967785831,127.327218034184,0.12540201227200132,25.669167155691493,132.3562225565407,0.03873665060870083
0.040007915176422,127.222931404622,0.12702513068513985,25.648142971171797,132.31285565275388,0.03922832387087943
0.0405310740608224,127.052652219936,0.12868616014311113,25.613814687539097,132.20223267668615,0.03973123095229721
0.0410583727877442,126.908294356739,0.1303603336010878,25.584712142318587,132.11894241629477,0.04023786182420023
0.0415831749571397,126.764578509344,0.13202658048891855,25.555739027483753,132.0358521558661,0.040741839266762635
0.0421223653559803,126.602202452388,0.13373851000523745,25.523004014401423,131.9349866789593,0.04125936959956999
0.0426698646110726,126.502616212607,0.1354768201401555,25.50292742846157,131.90046571934542,0.04178460109248221
0.0432220771962153,126.352618957754,0.13723009509798356,25.47268798188321,131.81384160829003,0.04231407492281397
0.0437783089702824,126.17821716863,0.13899613098064661,25.437528581195807,131.70208614515766,0.04284711918186102
0.0443311479145442,125.978198400347,0.14075139462867783,25.397204797509954,131.5629565476406,0.04337663065488878
0.0448774863290612,125.795160076839,0.14248601909476932,25.36030427149074,131.44053065344943,0.04389964058124644
0.0454264644875279,125.627010315742,0.14422902474790109,25.326405279653585,131.33380123852436,0.044424902154688056
0.0459775840657659,125.510227472746,0.14597882940880674,25.302861858505594,131.28088450748757,0.04495193526565094
0.0465423122656903,125.32816854973,0.1477718414435667,25.266158779625567,131.1612313060586,0.04549169425635404
0.0471050787509967,125.147366862696,0.1495586250344145,25.229709159519516,131.04244343424318,0.04602928860129948
0.0476641544037934,124.968619668783,0.15133369023204404,25.193673725226656,130.92514325230482,0.04656307118433769
0.0482294113548068,124.783084868783,0.15312838105151158,25.156269909546655,130.8012995990413,0.0471024659073838
0.0487823000615568,124.632143322845,0.15488380269544283,25.12584009388555,130.711985935735,0.047629776953432144
0.049343972535197,124.45804739594,0.15666711279925047,25.090742355021504,130.5993018684295,0.048165180846318226
0.0499124770925053,124.238732725029,0.15847211476870432,25.046528517365847,130.4397956261689,0.04870680554520341
0.0504787130034719,124.099258565279,0.16026991378602326,25.01841052676025,130.36362942233936,0.04924597741695183
0.0510629130615657,123.982184466186,0.16212474897047108,24.9948083883831,130.31307597276586,0.0498019502950489
0.0516505558706595,123.822352397414,0.16399051488934388,24.96258624331866,130.21784572795312,0.050360887908827645
0.0522265335196178,123.660859577651,0.1658192439247865,24.930029290854442,130.11923760544792,0.05090842717930371
0.0528097523412018,123.44977502313,0.1676709636833157,24.88747464466301,129.96912706867857,0.05146254478803521
0.0533959321413846,123.236637328187,0.1695320845488961,24.8445060853625,129.8169724522953,0.05201916641301319
0.0540050461995998,123.119625787676,0.17146602168372937,24.820916558795485,129.7687068664169,0.05259723777336419
0.0546060108589084,122.979023126441,0.17337408447703415,24.79257106229051,129.6944169987014,0.0531672477555926
0.0552126637666712,122.763576752343,0.17530020745918104,24.74913707327235,129.54168083836404,0.05374232364413025
0.0558135997894809,122.552246948728,0.17720817933160185,24.706532984863568,129.39232901322592,0.054311654352531276
0.0564007998388926,122.31681470374,0.179072539488484,24.659069844273983,129.21558088677656,0.05486765857695321
0.0570041519166617,122.121598856869,0.1809881823354009,24.61971432954479,129.0830370304116,0.055438634899933475
0.0576172452260738,121.966103134354,0.18293475359278433,24.588366391885767,128.99345400791466,0.05601849598279131
0.0582319038769889,121.815543733803,0.18488629480943974,24.558013616734684,128.90909476723294,0.05659950022732024
0.0588699728591281,121.662232318026,0.1869121638277317,24.52710603531404,128.82448463256915,0.05720227613382744
0.0594892726106055,121.473641738027,0.18887844053867245,24.489086174386244,128.7000203263835,0.05778697372036302
0.0601032053198665,121.190376982801,0.19082767689057614,24.43197999973268,128.4743070933903,0.058366266893764916
0.0607013328907658,120.958747740246,0.1927267319281814,24.38528354443359,128.3011049528768,0.05893032414277695
0.0613020006933688,120.689505636961,0.19463385220144594,24.33100433641134,128.08801379520034,0.05949645691847976
0.0618982093644192,120.518995809302,0.19652681473203096,24.29662955515528,127.97890584429572,0.06005807016992613
0.062514908884162,120.335297991283,0.19848483570721434,24.259596075042655,127.85804818075653,0.06063865360896468
0.0631524915782452,120.196898498593,0.2005091607609285,24.23169473731635,127.7876321187566,0.06123854304892613
0.0637998345070244,120.030692917163,0.20256447455980245,24.19818769210006,127.68863126104145,0.06184724775831501
0.0644583919282181,119.85453553605,0.20465539437209246,24.16267436406768,127.58016616200723,0.062466117624793295
0.0651085653448693,119.670016309873,0.20671969496996004,24.125475288070398,127.46155938660594,0.06307673325688909
0.0657558992200851,119.422465011606,0.20877498002377018,24.075568946339768,127.27519658552329,0.0636843119235704
0.0664039660748775,119.201520777802,0.21083259228773607,24.031026588804885,127.11697451960497,0.06429220900042476
0.0670431380858851,118.969461619786,0.2128619634226852,23.984243462548857,126.94554766316473,0.06489140082372771
0.0676972196676262,118.773583390618,0.21493867244471315,23.944754411548587,126.81422475612379,0.0655041981597914
0.0683512488869778,118.568592902186,0.2170152152161545,23.903428329080697,126.67290430582206,0.06611657119291134
0.0690090843037224,118.34905467098,0.21910384266431862,23.859169421669566,126.5162145620355,0.06673212995228477
0.0696662111638414,118.096691119191,0.22119022044519646,23.808292929628905,126.3240401404515,0.0673466476232851
0.0703225846572334,117.804207043806,0.22327420628671604,23.749328140031288,126.08850336662229,0.0679600840256221
0.0709951569356861,117.568623585181,0.22540962327080336,23.70183451477249,125.91542646732354,0.06858826945322696
0.0716484926795858,117.345932513942,0.22748396425768488,23.65693999481071,125.75359170064634,0.06919811025831388
0.07232385703781,117.056623590543,0.22962824609504673,23.59861531585347,125.52261010043416,0.06982812246966708
0.0729760659726581,116.754847544362,0.23169900946318944,23.53777726494338,125.275157001387,0.07043615768930833
0.0736280546992355,116.41275682412,0.2337690736700727,23.468811775742594,124.98400165125511,0.07104361832012321
0.0742603971185359,116.10990597409,0.23577676085135146,23.407757044376545,124.73227370112177,0.07163242211673931
0.074906983920258,115.782210719064,0.23782967394681914,23.341693680963303,124.45510691564886,0.0722341312501787
0.0755581080631713,115.570261956345,0.23989699310056886,23.298964810399152,124.30253229813154,0.07283969714867976
0.076228462810555,115.279061046227,0.2420253694235121,23.240258706919363,124.066606664025,0.07346276523372519
0.0769058065356441,115.091248755169,0.24417593575067,23.202395749042072,123.94243406587972,0.07409193523680069
0.0775722406745286,114.87781708353,0.2462918641416283,23.15936792403965,123.78914675849806,0.07471058545790893
0.0782490279905569,114.537162353272,0.24844066387001815,23.090691930419634,123.49958397621215,0.07533845507595122
0.0789299831409226,114.207930537286,0.2506026964724292,23.02431879631686,123.22236056915366,0.07596979366164136
0.0796125398833383,113.889908927278,0.2527698141295991,22.960205639739247,122.95697384406068,0.07660221739931124
0.0803002905846379,113.443334250441,0.25495342260622533,22.870176184888905,122.55286695564162,0.07723904932589787
0.0809743423819882,113.093187836132,0.2570935370628125,22.79958666776421,122.25083434904546,0.07786280329859815
0.0816543300099767,112.699674752282,0.259252497781676,22.72025443006005,121.90209118652187,0.07849165619329806
0.0823232582954121,112.294848034092,0.2613763450879334,22.638641363672946,121.5393258140466,0.07910989578169014
0.0830095137455338,111.931007582781,0.2635552061420698,22.56529112868865,121.22234609527531,0.07974375260218385
0.083694438994366,111.503074116908,0.26572984380711206,22.47901974196865,120.8352613512698,0.08037598043449144
0.0843973076165405,111.102501883818,0.26796145168251606,22.398264379777707,120.47925391227385,0.08102435580688663
0.0850873661619627,110.663047364517,0.2701523875642316,22.309670348686627,120.07907459622028,0.08166050555897661
0.0857865089764079,110.231162068798,0.27237216600009506,22.22260227306968,119.68750864309281,0.08230461745015896
0.0864767553762839,109.721452803441,0.27456369831970134,22.119844885173706,119.20980803705466,0.0829401264461763
0.0871663169762114,109.219160696892,0.2767530563994712,22.01858279649343,118.73939267807306,0.08357460193281958
0.0878553908122564,108.698777153192,0.2789408658289141,21.913673474083506,118.24855070080004,0.08420822674367241
0.0885499871078296,108.190963689472,0.281146209067359,21.81129827979756,117.77127212935841,0.0848465235666843
0.0892419758999617,107.667481261754,0.28334327348237837,21.70576422236961,117.27594002972502,0.08548201935983143
0.0899397762924928,107.117845197699,0.28555878972866466,21.59495759185612,116.75200023171391,0.08612244360684881
0.0906368781667714,106.598312760763,0.2877720881794992,21.490219852569822,116.26005104724366,0.08676181750512571
0.091330740372781,105.994364965616,0.2899751006835796,21.368463977068185,115.67490879326847,0.08739781432148766
0.0920258778037912,105.394689605445,0.29218216202703706,21.247569424457712,115.09372843224418,0.08803457466444853
0.0927205753337531,104.75959262197,0.29438782668466607,21.119533872589155,114.47296232160865,0.08867052722761892
0.0934358558317049,104.134229744648,0.296658842265663,20.993460716521035,113.86410062221458,0.08932489990953582
0.0941557023883679,103.565553879056,0.29894435508306805,20.878815662017693,113.31684134777888,0.08998301781087771
0.0948923721057971,102.919280780687,0.30128328143590577,20.7485270053865,112.68553546938897,0.09065606812331405
0.0956259240808377,102.263385576696,0.3036123089566597,20.61629853226191,112.04241632210255,0.09132582012103833
0.0963654330608889,101.557649908309,0.3059602499683223,20.474022221515096,111.34429682236934,0.09200055727791465
0.0971041082947833,100.820112928539,0.30830554383593695,20.325334766393464,110.61016009264412,0.0926740795200896
0.0978455742927203,100.067496397256,0.31065969837938695,20.17360727368681,109.85865805028021,0.0933496904755685
0.0985763194580117,99.3183715953878,0.3129798142791871,20.02258371363018,109.10881112182426,0.09401508649473227
0.0993190916375336,98.489843143705,0.31533811594916916,19.855552377770927,108.27176490026093,0.09469098053777825
0.100057392920149,97.7083711779519,0.31768222252147305,19.698007629475104,107.484816064492,0.09536235382519052
0.100794202897376,96.8903854279261,0.3200215941991688,19.533101702269903,106.65637459555346,0.09603192191979053
0.101508665668978,96.0766475362908,0.3222900134990051,19.369052143316225,105.8292598296484,0.09668075438226821
0.102210311417572,95.2040508348638,0.3245177387507911,19.193136648308545,104.93488651890961,0.09731753772860122
0.102922399470979,94.3119658890082,0.3267786183203583,19.013292323224054,104.01877971713004,0.09796338373563987
0.103653633180099,93.4537702459847,0.3291002853468143,18.840280081590517,103.14059306635924,0.0986261605673171
0.104423338057868,92.5353895086859,0.3315440983337309,18.655134524951077,102.1982437696679,0.09932333273927604
0.105180134992614,91.5964319833233,0.33394692860154945,18.46584068783798,101.23055706417104,0.1000083397765741
0.105941987314535,90.5653359571306,0.3363658097236486,18.25797172895753,100.16000763023754,0.10069744902511675
0.106671674177676,89.5138164539554,0.3386825655141213,18.04598539711741,99.06240511713203,0.10135701910939621
0.107426402478742,88.4852618473356,0.3410788278700058,17.838628788422856,97.99091519998433,0.10203876698520617
0.108203460646106,87.4256366001885,0.34354598755138654,17.625008338598004,96.88539302951776,0.1027402002093712
0.108974570708757,86.2425870867663,0.3459942620003035,17.386505556692086,95.64083599135925,0.10343577817635141
0.109756276325124,84.9481518670901,0.34847617733226866,17.125547416405364,94.27174469672305,0.1041404203367617