File: example/data/02 processed data/test_ID_089.csv
Strain,Stress_MPa,Displacement(mm),Force(kN),True Stress (MPa),True Strain
0.0030013175100891344,157.543106150142,0.009529183094533001,63.521380399737254,158.01594303322426,0.0029968225483167454
0.0031581051003808343,165.949755670275,0.010026983693709149,66.91094148625488,166.47384244006426,0.0031531287609176304
0.0033134629235664344,174.178167295733,0.010520244782323428,70.22863705363955,174.75530019516216,0.003307985501448592
0.0034663335244386343,182.267592593796,0.011005608940092663,73.49029333381854,182.8993928604226,0.0034603396376009423
0.0036161991800902345,190.196946054668,0.011481432396786494,76.68740864924213,190.88473609504655,0.0036096764520947
0.0037686940158794344,197.823708886257,0.011965603500417204,79.76251942293884,198.5692459141357,0.0037616102806289206
0.003920707849362534,205.184568354345,0.012448247421726046,82.73041796047191,205.98903710205997,0.0039130419050947786
0.004076933480341234,212.184808643819,0.012944263800083419,85.55291484518783,213.04987199419878,0.004068645306292378
0.004234589399885535,218.795984173676,0.013444821344636572,88.21854081882617,219.7224953289954,0.0042256487572730995
0.004400656421796434,225.076079981184,0.013972084139203677,90.75067544841339,226.06656247794595,0.004391001847272517
0.004572071209935535,230.909000596082,0.014516326091545321,93.10250904034027,231.96473298982232,0.004561651041457592
0.004760501204342734,236.255129857634,0.01511459132378818,95.25806835859804,237.37982268785342,0.004749205851991746
0.004973203863816734,241.153845772759,0.01578992226761813,97.23323061557643,242.35315301033037,0.0049608783335069115
0.005218388335329335,245.53219542297,0.016568382964670638,98.99858119454152,246.81347776751304,0.00520481973061542
0.005512881433286734,249.42987071574,0.01750339855068538,100.57012387258638,250.80494801891592,0.005497741121445491
0.005854450165754935,252.80000945838,0.018587879276271917,101.92896381361881,254.28001451565646,0.005837379466351946
0.0062441713342206336,255.4674444173,0.01982524398615051,103.00447358905537,257.0626269105571,0.0062247572709734625
0.006680160937547435,257.590240196498,0.021209510976713104,103.86038484722798,259.3109844569521,0.0066579475336721846
0.007362450138747334,259.496363958489,0.023375779190522784,104.62893394806277,261.40689299931955,0.007335479601313496
0.008085023026477234,260.925454426004,0.025669948109065217,105.20514322456482,263.03504273323233,0.00805251433261692
0.008839493239450035,262.016237977046,0.028065391035253857,105.64494715234494,264.3323287412702,0.008800653632901726
0.009613146102626634,262.822097635185,0.03052173887583956,105.9698697665066,265.3486448587508,0.009567233820103774
0.010402120481281134,263.463298594947,0.0330267325280676,106.22840199348262,266.2038755693274,0.010348390707208553
0.011198819940418735,264.10248936377,0.03555625331082948,106.48612371147206,267.06012558797124,0.011136577420473878
0.012009400269123135,264.689554640897,0.03812984585446595,106.72282843120966,267.8683174496354,0.011937859625614474
0.012616589774914335,264.934703477319,0.040057672535353014,106.821672442055,268.2772759482309,0.012537663764236534
0.013213422182157935,265.198227343015,0.04195261542835144,106.92792526470365,268.7024034828582,0.013126886375204335
0.013797145322683235,265.530057842228,0.04380593639951927,107.06171932198633,269.19361463781775,0.013702831233133185
0.014364498518163234,265.843189668454,0.045607282795168264,107.18797407432065,269.66189377251027,0.01426230657081346
0.014919253410556334,266.168927624563,0.047368629578516355,107.31931161822382,270.1399693058099,0.014809056039127666
0.015464862937846435,266.465863725862,0.04910093982766243,107.43903625426756,270.5867217859973,0.01534650068916205
0.015994449723177435,266.733370629929,0.05078237787108836,107.54689503798738,270.99962411596306,0.015867886270480257
0.016520651901258936,267.05616844533,0.05245306978649712,107.67704711715706,271.46811044229923,0.016385670555986543
0.017045945320852234,267.468808645564,0.05412087639370584,107.84342364589142,272.0280673327698,0.016902293352598487
0.017573416972344734,267.824857602285,0.05579559888719453,107.98698258524134,272.53145550048885,0.017420790004193342
0.018097886565806135,268.151433912976,0.057460789846434476,108.11865815371193,273.0044081463913,0.017936069267750574
0.018624437498963736,268.44713808983,0.05913258905920986,108.23788607781945,273.4468150349597,0.01845312644208128
0.019151367285137735,268.82015804859,0.06080559113031231,108.38828772519147,273.9684316290273,0.018970288140322297
0.019684169437190233,269.174985266896,0.06249723796307899,108.53135405961245,274.47347128514275,0.019492941541820023
0.020214113986652935,269.470697288891,0.06417981190762306,108.65058514688086,274.9178086799515,0.02001252094015676
0.020744738793694633,269.695690723456,0.06586454566998046,108.74130249969745,275.2904573812991,0.020532496948761116
0.021273975218486636,269.955974355969,0.06754487131869506,108.84624886032668,275.6990110645003,0.021050843262641922
0.021804155452124135,270.30421361682,0.06922819356049413,108.98665893030181,276.19796870988534,0.021569844702263183
0.022342263039974834,270.601658782383,0.07093668515192009,109.10658882105683,276.6475122219525,0.022096331059025476
0.022876548827148634,270.829953487227,0.07263304252619691,109.19863724604993,277.02560814203196,0.022618804054313664
0.023404014671573034,271.099542121697,0.07430774658224439,109.30733538346824,277.44435978296997,0.02313434025742829
0.023934574304670733,271.367104716777,0.07599227341732957,109.4152166218045,277.8621608484641,0.023652632295522447
0.024460944594079534,271.67519067778,0.07766349908620251,109.53943688128089,278.3206224645352,0.024166566539312904
0.024985423986015033,271.938756268239,0.07932872115559772,109.64570652735397,278.7332613918305,0.024678391987810428
0.025510248309147936,272.149034874844,0.08099503838154469,109.7304908615371,279.0916243315962,0.025190291955885825
0.026023930540269136,272.420343319303,0.08262597946535451,109.83988242634298,279.5097914116008,0.02569107058989769
0.026541841564291135,272.764030563417,0.08427034696662435,109.97845712316973,280.0036902470687,0.02619571803365017
0.027054624451081033,273.087695440922,0.08589843263218228,110.10895880177975,280.47598048328734,0.02669511789719027
0.027565299146757035,273.380467322209,0.08751982479095358,110.22700442431466,280.9162816848259,0.027192216849971498
0.028075631890505034,273.700615852354,0.08914013125235348,110.35608831166914,281.38493359122924,0.027688736204618744
0.028583850851670835,273.969982655962,0.0907537264540549,110.46469700688387,281.8010997780349,0.028182954110669612
0.029088544371035335,274.26369859562,0.09235612837803718,110.58312327375397,282.24163036158296,0.0286735021013574
0.029596036177944936,274.520808172515,0.09396741486497516,110.68678985515804,282.64553594278743,0.029166527426348357
0.030102026300047133,274.7482913481,0.09557393350264964,110.77851107155391,283.0187716401535,0.029657851996195396
0.030615371304739236,275.009195869775,0.09720380389254707,110.88370777469329,283.42870451354594,0.030156071709298675
0.031130713661197736,275.302617205395,0.09884001587430281,111.00201525721526,283.87298415179447,0.030655980375015338
0.03164742294209833,275.479915122438,0.1004805678411622,111.073501777367,284.1981445083712,0.031156964249663795
0.03216814042523003,275.746242661343,0.10213384585010533,111.1808850410535,284.61648651700267,0.03166158055688029
0.032689091715620434,275.986294797292,0.10378786619709487,111.27767406226813,285.0080361001749,0.032166168761173175
0.03320715531844103,276.257142355513,0.10543271813605028,111.38687979774284,285.4308561895412,0.03266770761088441
0.033721051883527434,276.4889672158,0.10706433973019959,111.48035158141056,285.81246602450693,0.033164963948946635
0.034236154990247535,276.7104736432,0.10869979209403592,111.56966297293822,286.18397630627334,0.03366313974838878
0.03474676020171023,276.939609027698,0.11032096364042998,111.66205035996784,286.5623632129388,0.03415672064563035
0.03525887232888233,277.211582158086,0.11194691964420138,111.77170992614029,286.98574994148544,0.03465151363514888
0.03576661930692593,277.465669220288,0.11355901629948982,111.87415782962013,287.3896781820315,0.03514184752072134
0.03627858493908633,277.736737960882,0.1151845071815991,111.98345274582763,287.8126337997006,0.03563601207034575
0.03679004498163133,277.999062990915,0.11680839281667947,112.08922219793692,288.2266610232021,0.03612944489310957
0.03730703378340123,278.248553796741,0.1184498322622989,112.18981689084598,288.62918199341857,0.03662796429007482
0.03782234803156473,278.471492943081,0.120085955000218,112.27970595465025,289.0039386660436,0.03712462176432395
0.03834404027975733,278.724918166382,0.12174232788822952,112.38188700468521,289.4123576555258,0.03762717518403974
0.03886283825402183,279.011606282898,0.1233895114565193,112.49747965326448,289.8547892088651,0.03812669017256916
0.03938387298890803,279.27935070811,0.125043796739783,112.60543420550994,290.27845318482287,0.038628107779038974
0.039903141138897834,279.492680521114,0.12669247311600063,112.69144878611316,290.6453163992369,0.03912757529579524
0.04042702219609153,279.730221721507,0.1283557954725906,112.78722539811163,291.03888160396,0.03963122714635348
0.04094103474894803,279.944730124648,0.12998778532791,112.87371518625807,291.4059570484661,0.040125145136101575
0.04145764004765013,280.156251806553,0.13162800715128917,112.95900072840216,291.77086885104785,0.04062130882997308
0.04196550644117943,280.37807510807,0.1332404829507447,113.04843988357383,292.1442830249832,0.04110883955981517
0.04247382102466763,280.582160608246,0.1348543817533197,113.13072715724479,292.49955708063516,0.04159656264857718
0.04298363400120003,280.779251389878,0.1364730379538101,113.21019416039883,292.8481639667515,0.04208548462150879
0.043492212716277734,281.027754672719,0.1380877753741818,113.31039068404033,293.25027355812284,0.04257298484917754
0.043999796524092534,281.192597368132,0.1396993539639938,113.37685525883082,293.5650144364109,0.04305929456013352
0.04451375784369343,281.443536282662,0.14133118115372661,113.47803382916933,293.9716457034212,0.043551473630651025
0.04502674075372793,281.698464989344,0.14295990189308616,113.58082108370351,294.3824287431423,0.044042474327392514
0.045544724463950734,281.902109358486,0.14460450017304358,113.66293049334153,294.7412632550247,0.044538017033720005
0.04606690995640513,282.082344743196,0.1462624391115863,113.73560140045663,295.07700671877245,0.04503733105044296
0.04659183575939163,282.278376146042,0.14792907853606843,113.81464126208414,295.43024388586616,0.045539014198802484
0.047118903528040434,282.477505826136,0.14960251870152838,113.89493034909803,295.78753617199914,0.04604249136963827
0.04764523046187923,282.739728268291,0.15127360671646656,114.00065843777493,296.21092778236283,0.04654500803619225
0.048171450098668134,282.916857846948,0.1529443540632713,114.07207708388944,296.54537314679425,0.04704716994064465
0.048692812711145735,283.095376869734,0.1545996803578877,114.14405595387676,296.8800870350432,0.04754444831241943
0.04922201730716213,283.281810058466,0.15627990495023975,114.21922581557351,297.225512215968,0.048048953642825444
0.049749825639830034,283.512791708409,0.15795569640646034,114.31235761683051,297.6175036625638,0.04855187448530028
0.05027547510470053,283.724976636912,0.15962463345742417,114.39791058000291,297.9893846364028,0.04905248700236086
0.05080348857396663,283.895297075742,0.16130107622234405,114.46658378093919,298.3181685569323,0.049555098745669206
0.051330866662963534,284.098207259862,0.1629755016549092,114.54839716717638,298.681214455905,0.05005685363944887
0.05185388485399043,284.295673596003,0.1646360844114196,114.6280155939084,299.0375087191378,0.050554211944686775
0.052385092108122734,284.476068208611,0.16632266744328966,114.70075070171197,299.37837324427574,0.05105910446994901
0.05291118783677353,284.700445435793,0.16799302138175595,114.79121959971174,299.76428418145935,0.051558887559496294
0.05343981136424413,284.863302582868,0.1696714010814751,114.85688360141239,300.08634373749203,0.05206082055999738
0.05397458558822913,285.010946498255,0.17136930924262747,114.91641362809642,300.3942942236073,0.05256833748332974
0.05450849948227133,285.22794184284,0.17306448585621145,115.00390615103308,300.77528896310974,0.053074781105509436
0.05504452234671763,285.344857335991,0.17476635845082847,115.05104647787157,301.05152871214284,0.053582967314090506
0.05558547979864553,285.503578796592,0.17648389836069955,115.11504297078591,301.37343220823095,0.05409557015136973
0.05612439925698153,285.681927614607,0.17819496764091636,115.18695321420954,301.7156541805533,0.054605980672607586
0.05666756063153733,285.851595309206,0.17991950500513101,115.25536322867187,302.0501079180121,0.05512014524425848
0.057209830572664135,286.007979803425,0.18164121206820863,115.31841745674096,302.37044787040884,0.055633202392490665
0.05775184451463173,286.204142976176,0.18336210633395572,115.39751044799418,302.73296014077954,0.056145754426145146
0.05829821541390673,286.404492813003,0.18509683393915385,115.47829150220281,303.1013636305261,0.05666216083992861
0.05884826438251653,286.625903216505,0.18684323941448996,115.56756417689482,303.49334014786746,0.057181774372799324
0.05940187116695713,286.846790447142,0.1886009409550889,115.65662590828765,303.8860265379382,0.05770447637834077
0.05998095935038313,287.031496597599,0.19043954593746643,115.73109942815192,304.2479211272992,0.058250945085644254
0.06056032915851263,287.133850670101,0.1922790450782776,115.77236859018474,304.52277117923353,0.05879738087134237
0.06113642811631423,287.293444333273,0.19410815926929767,115.83671675517567,304.85753934104247,0.05934043582958216
0.061702229404139435,287.416374550788,0.1959045783581427,115.88628221887774,305.1506056278268,0.059873496878963935
0.06227612499102293,287.519773244985,0.1977266968464978,115.92797257237795,305.42539058098026,0.060413893724027896
0.06284941466191614,287.665206333107,0.19954689155158373,115.98661119350875,305.7447961697421,0.06095342861182919
0.06342362517046424,287.760563804864,0.20137000991622395,116.02505932612115,306.01138194246516,0.06149353847707254
0.06397819557682582,287.919672113182,0.20313077095642199,116.08921179603499,306.34025320605474,0.062014897830547734
0.06453140370583023,288.107164206196,0.20488720676601097,116.16480860793823,306.69912393012794,0.0625347058141689
0.06509418998929833,288.243782661147,0.2066740532160222,116.21989316897447,307.0067782129257,0.06306323655519226
0.06566910042004014,288.406777683418,0.20849939383362742,116.28561276195414,307.34619132893056,0.06360286519182269
0.06623574692878482,288.596719058034,0.21029849649889182,116.36219712419933,307.71213830603955,0.06413445225847185
0.06680423474351263,288.688955333976,0.2121034453106526,116.39938679065914,307.9746000739664,0.06466748289368959
0.06737779670393733,288.809713601963,0.213924504535001,116.44807652431147,308.2690757711584,0.0652049834121851
0.06795046093614954,288.95922621104,0.21574271347227478,116.50836000829133,308.59413882383325,0.0657413545709449
0.06852864218334002,289.089120541558,0.21757843893210457,116.56073340235618,308.9000054422468,0.06628260139190478
0.06910237584192454,289.256112109762,0.2194000432981104,116.62806440265604,309.24439668334463,0.06681939531707075
0.06968203679933943,289.375663080088,0.2212404668379027,116.67626735389148,309.5399486836679,0.06736144244270117
0.07026842716028503,289.464138781193,0.22310225623390495,116.71194075657702,309.80432853265387,0.06790948351701402
0.07085744860256263,289.587333013022,0.22497239931313634,116.76161267085047,310.1067525779454,0.06845968139543325
0.07144444870337713,289.71023876192,0.22683612463322236,116.81116826880614,310.40842705398916,0.06900769016697297
0.07203646659912263,289.797354185109,0.22871578145221436,116.84629320743593,310.6733316103787,0.06956007941996117
0.07262966033626443,289.941280958639,0.23059917156763957,116.90432448252326,310.9996177121264,0.07011325993120116
0.07322634237180693,290.07603245975,0.232493637030487,116.9586562877712,311.31723932650306,0.07066938489966852
0.07382522160944333,290.217639538862,0.23439507860998254,117.01575226206917,311.643021092788,0.07122724691212741
0.07442671856507953,290.309650235356,0.23630483144412748,117.05285097489553,311.9164448701495,0.07178723427683642
0.07503359245601914,290.438429511891,0.23823165604786073,117.10477477919446,312.23106826545245,0.07235190988768944
0.07564708230539893,290.591189250283,0.2401794863196416,117.1663675057141,312.5735648607229,0.072922417516478
0.07626063222483513,290.730727616234,0.24212750731385152,117.22262937486556,312.90203671143433,0.07349265566555761
0.07687902148361953,290.800950646963,0.244090893210492,117.25094330085547,313.1574431792078,0.07406706269458802
0.07750672129183764,290.850139129682,0.2460838401015845,117.27077609708779,313.3929798008985,0.07464978083416443
0.07813399707868234,290.919893713735,0.2480754407248164,117.29890114537795,313.65062783929454,0.07523176631922618
0.07876316495508613,291.043852862663,0.25007304873239844,117.34888147422573,313.96738785484877,0.0758151672391437
0.07939590670183663,291.153033963812,0.2520820037783313,117.39290329420899,314.2693930843595,0.07640153899754645
0.08003128694067353,291.218135667284,0.2540993360366384,117.41915230104891,314.5246978452004,0.07699001010603629
0.08067691981774493,291.29183078992,0.25614922042134014,117.44886617449576,314.7923584661225,0.07758762240210373
0.08133123502349514,291.408716136217,0.258226671199597,117.49599434612269,315.1093469161866,0.0781929070993533
0.08198983630827633,291.493102430856,0.26031773027877736,117.53001890012116,315.39257418415355,0.07880178694974266
0.08265422144093733,291.570199687615,0.262427153074976,117.56110451404636,315.66970753817344,0.07941563859075045
0.08332648395793243,291.62091597998,0.26456158656643547,117.58155332312793,315.92066155718334,0.08003638515317925
0.08400057701195983,291.652663463934,0.26670183201297243,117.59435390865819,316.1516554819794,0.08065843531616874
0.08468709935440884,291.705079336579,0.26888154045024804,117.61548798850865,316.40873637254157,0.08129155770890688
0.08537456280195213,291.719237270221,0.271064236896198,117.62119646735312,316.6246396130851,0.08192514659030102
0.08605650638593443,291.736766131405,0.27322940777534177,117.62826410418249,316.8426130090041,0.08255325182106672
0.08674494051452503,291.77257855321,0.27541518613361693,117.64270367265428,317.0823735235778,0.08318693526472395
0.08743702618949672,291.821443265679,0.2776125581516521,117.6624059247218,317.33744244315693,0.08382357535184295
0.08813195712236684,291.794039158827,0.2798189638635147,117.65135658883905,317.510418906535,0.08446242519924915
0.08883370617573354,291.77309185638,0.282047017107954,117.64291063649242,317.692376968335,0.08510712905425623
0.08952802063143334,291.731925141416,0.28425146550480085,117.62631221701893,317.8501069543245,0.085744593870744
0.09022322149579433,291.673892068475,0.286458728249147,117.60291328200914,317.98965023710946,0.08638246563748243
0.09092890597837723,291.562551275832,0.2886992764813477,117.55802067441546,318.07401508760796,0.08702954063818226
0.09162523262934204,291.449038090789,0.29091011359816094,117.51225215820612,318.1531240054555,0.08766762485545149
0.09232307966557353,291.203067238557,0.29312577793819594,117.4130767105862,318.08783121408175,0.08830669406423589
0.09302547461678543,291.027361758675,0.2953558819082937,117.34223226109776,318.1003202127466,0.08894951598298408
0.09371972834891443,290.796186843043,0.2975601375078033,117.24902253511495,318.0495264788732,0.08958448136853821
0.09441857823988183,290.46793009042,0.2997789859116248,117.11666941245734,317.8934990738389,0.09022324347294908
0.09510931978231434,290.085504708731,0.301972090308848,116.96247549856032,317.6753397402877,0.09085419370287913
0.09579954369214293,289.627071247952,0.3041635512225538,116.77763512717425,317.37321251439755,0.09148427370681766
0.09649884593528103,289.11082119901,0.3063838358445173,116.56948310744083,317.0096817921159,0.09212223637664833
0.09720438936192834,288.531525300686,0.30862393622412243,116.33591100123658,316.57805602920496,0.09276548058545667
0.09792565519644443,287.845952363761,0.31091395524871107,116.05948799306843,316.0334558446268,0.09342263150210557
0.09867825631459433,287.066280720664,0.313303463798837,115.74512438657173,315.39348074889494,0.09410787215350824
0.09946643210650233,286.181822378571,0.3158059219381449,115.38851078303982,314.6473071843042,0.09482500040247024
0.10029722694313203,285.195658627469,0.3184436955444442,114.9908895585955,313.79999232402434,0.09558034961711238
0.10114724183434164,284.08276047705,0.3211424928240347,114.54216902434655,312.8169481519895,0.09635258343495952
0.10204012691903963,282.820662669099,0.3239774029679508,114.03329118818073,311.6797189831808,0.09716312287998806
0.10296163584814663,281.491896612646,0.32690319381786553,113.49753271421885,310.4747627658814,0.09799895802381065
0.10390210818967163,279.749201174635,0.3298891935022074,112.79487791361284,308.8157329410561,0.09885127380542516
0.10437309947556063,278.960666240565,0.33138459083490496,112.4769406281958,308.0766556078602,0.09927784318536123
0.10484114923794763,278.155939302739,0.33287064883048373,112.15247472686437,307.318127646599,0.09970156829003363
0.10531144157403663,277.249994591806,0.3343638269975663,111.78719781941618,306.44759119866296,0.10012714283646267