File: example/data/02 processed data/test_ID_152.csv
Strain,Stress_MPa,Displacement(mm),Force(kN),True Stress (MPa),True Strain
-0.0001488505449192,1.53727554737229,-0.00047260048011845996,0.30991475035025373,1.5370467230693727,-0.0001488616242610181
-0.0001716240484356,2.58777354669331,-0.00054490635378303,0.5216951470133713,2.587329422520792,-0.00017163877752789485
-0.0001798837207842,3.88653925900868,-0.0005711308134898349,0.78352631461615,3.8858401338657957,-0.00017989990180114474
-0.0002008958266609,5.21616670300435,-0.0006378442496483575,1.0515792073256771,5.215118796882549,-0.00020091600893059328
-0.0002344366662963,7.51983405918874,-0.0007443364154907525,1.5159985463324501,7.518071134360802,-0.00023446415086723056
-0.0002393806916506,10.3110127291065,-0.000760033695990655,2.07870016618787,10.308544471747787,-0.00023940934778164536
-0.0002167589399774,13.3414098896025,-0.000688209634428245,2.689628233743864,13.338518019737027,-0.00021678243559176052
-0.0001823118296416,16.4874869866054,-0.00057884005911208,3.3238773764996488,16.48448112268668,-0.0001823284504633275
-0.0001262844933166,19.7161063826493,-0.000400953266280205,3.974767046742099,19.71361654414459,-0.00012629246787465036
-6.93129665755336e-05,22.9028671178084,-0.0002200686688773192,4.6172180109501735,22.901279652145377,-6.93153688302032e-05
2.10015833003801e-05,26.0871367450738,6.668002697870682e-05,5.259166767806878,26.08768461624922,2.1001362770265536e-05
0.0001050058471442,29.276734993435,0.000333393564682835,5.902189774676495,29.2798092217946,0.00010500033441606582
0.000196907910976,32.4148536935905,0.0006251826173488,6.534834504627845,32.4212364347159,0.000196888527157848
0.0002929812898549,35.507267029259,0.0009302155952893075,7.158265033098615,35.51766999415245,0.0002929383792179232
0.0003918525358817,38.4557375461491,0.0012441318014243974,7.752676689303659,38.47080652442576,0.0003917757817269786
0.0004799561159891,41.3514201109785,0.0015238606682653924,8.336446294373266,41.371266977965604,0.00047984097389315757
0.0005724444081822,44.1135242298439,0.001817510995978485,8.89328648473653,44.13877677011448,0.000572280624383807
0.0006632098361363,46.8159610839017,0.002105691229732752,9.438097754514583,46.847009889780715,0.0006629900096816256
0.0007721972286753,49.4286561679305,0.002451726201044077,9.964817083454788,49.46682483924052,0.0007718992377906888
0.0008647954940826,51.9329051812938,0.002745725693712255,10.46967368454883,51.9778165236892,0.000864421773904786
0.0009603115993599,54.3941172923572,0.0030489893279676823,10.965854046139212,54.44635259413,0.0009598507951628233
0.0010459683640208,56.7744836787222,0.00332094955576604,11.445735909630397,56.833867992533754,0.0010454217202596249
0.0011382154509268,59.0693467454663,0.0036138340566925897,11.908380303886005,59.13658038860814,0.0011375681748335821
0.0012430555376025,61.3273136662633,0.003946701331887937,12.363586435118682,61.40354692312243,0.0012422835837224246
0.0013337324615315,63.5171926007337,0.004234600565362513,12.805066028307916,63.60190754237065,0.0013328438304349884
0.001413415601073,65.6375141173998,0.004487594533406775,13.2325228460678,65.73028720386898,0.0014124176694597212
0.0015073291859615,67.7292720145169,0.004785770165427763,13.654221238126606,67.8313623229683,0.0015061943056064865
0.001588086819805,69.724952615843,0.005042175652880875,14.056550447353947,69.83568189410374,0.0015868271434054048
0.0016879714153149,71.698287307015,0.005359309243624807,14.454374721094224,71.81931196651627,0.0016865483926880168
0.001793482246111,73.5986009471271,0.005694306131402424,14.837477950940823,73.73059873126438,0.0017918758772033825
0.0018999016322246,75.4072243923072,0.006032187682313105,15.202096437489132,75.55049070101167,0.0018980991018443041
0.0020292029138623,77.2108930505072,0.006442719251512802,15.56571603898225,77.3675696196672,0.002027146862589726
0.002162553163738,78.8936979609005,0.006866106294868149,15.90496950891754,79.06430977702483,0.002160218211344765
0.0022999893625971,80.4058649504773,0.007302466226245793,16.209822374016223,80.5907975845538,0.002297348435690328
0.0024688495333301,81.7807241248293,0.007838597268323068,16.486993983565586,81.98262842742028,0.002465806931110036
0.002659945851705,83.0307196880505,0.008445328079163374,16.73899308911098,83.2515769064488,0.0026564144565650303
0.002859495660652,84.1053944369671,0.0090788987225701,16.95564751849257,84.34589344739703,0.002855415080019622
0.0030838601959667,85.0389979330783,0.009791256122194272,17.143861983308586,85.30124631390902,0.00307911485259313
0.0033292935936894,85.7582142656478,0.010570507159963844,17.288855995954595,86.04372853900867,0.0033237637659871305
0.0036091840753558,86.3424031057906,0.011459159439254664,17.406628466127383,86.65402873210796,0.003602686599542025
0.0039101208664957,86.8046915167227,0.012414633751123848,17.499825809771295,87.14410835233197,0.00390249621298217
0.0042333265441887,87.1683735838969,0.013440811777799122,17.573144114513614,87.53738577360336,0.00422439122591113
0.0045647411824286,87.400401544283,0.014493053254210804,17.619920951327455,87.79936175657298,0.0045543543482092375
0.0049184889872696,87.5514744534728,0.015616202534580978,17.650377249820117,87.98209541639142,0.004906432736507412
0.005278313057313,87.6450314866007,0.016758643956968772,17.669238347698702,88.10764940070504,0.005264431588680067
0.0056447334671381,87.7000087519313,0.017922028758163466,17.680321764389355,88.19505192640165,0.005628861659252558
0.0060127788342224,87.7212251518954,0.01909057279865612,17.684598990622113,88.24867347780076,0.005994774215381175
0.0063912923249495,87.7169040574342,0.020292353131714663,17.683727857978734,88.2775284331048,0.006370954626279156
0.0067729144954701,87.7017560633473,0.021504003523117567,17.68067402237082,88.29575255826693,0.006750081350069323
0.007161230671229,87.7009649195241,0.022736907381152072,17.680514527776058,88.32901175940216,0.007135710822118451
0.0075541474073878,87.6986525342543,0.023984418018456265,17.680048350905665,88.36114108292732,0.0075257577194770674
0.0079567174576326,87.6726503516774,0.025262577927983504,17.674806310898166,88.3702368592875,0.007925229697143831
0.008362302852793,87.6202072344548,0.02655031155761777,17.664233778466087,88.35291394337379,0.008327532503937137
0.0087748794765143,87.5638756173525,0.0278602423379329,17.652877324458263,88.33223807239125,0.008736603967285237
0.0091954320395462,87.5063612806624,0.029195496725559184,17.64128243418154,88.31102007884671,0.009153411456196614
0.0096080844143406,87.4455403110937,0.030505668015531402,17.62902092671649,88.28572444406032,0.00956222031468955
0.0100216275707745,87.3614587335221,0.031818667537209036,17.612070080678055,88.23696273698904,0.009971744060314138
0.0104413829050141,87.2818902676106,0.033151390723419764,17.5960290779503,88.19323390456815,0.010387248168137136
0.0108602115581643,87.2035304262712,0.03448117169717165,17.580231733936273,88.15057921531931,0.01080166297915942
0.0112849109783817,87.1253750881465,0.0358295923563619,17.564475617770334,88.10857718997434,0.011221711393814532
0.0117122782320955,87.0290242039992,0.03718648338690321,17.54505127952624,88.04833234974421,0.011644220394173758
0.0121323579229484,86.9503206007171,0.03852023640536117,17.52918463310457,88.00523301176013,0.012059350774620134
0.0125601157951783,86.8561385048819,0.0398783676496911,17.51019752258419,87.94706166202525,0.01248189186088065
0.0129948529617173,86.7757505178381,0.04125865815345243,17.49399130439616,87.90338863646006,0.012911144268166417
0.0134247784440048,86.692802773137,0.042623671559715234,17.47726903906442,87.85663444305617,0.013335464563997581
0.0138604693008879,86.6072625863383,0.044006990030319076,17.460024137405803,87.80767989065018,0.013765291460903913
0.0143005068378679,86.5129956851097,0.04540410921023058,17.441019930118117,87.75017537146904,0.01419921909195654
0.0147327852484924,86.4154889193118,0.04677659316396337,17.42136256613326,87.68862975970349,0.014625312068203618
0.0151790263624363,86.3186392942421,0.04819340870073525,17.401837681719208,87.62887219565903,0.015064977593158764
0.0156289213981854,86.2151034465199,0.04962182543923864,17.380964854818412,87.562552521622,0.015508047597493996
0.0160738000682094,86.0927812294291,0.05103431521656484,17.356304695852906,87.47661938222703,0.015945984380699257
0.0165212046062764,85.9688014509644,0.05245482462492756,17.331310372514423,87.38910960949214,0.01638621427820826
0.0169629802460598,85.8624462981655,0.05385746228123986,17.309869173710165,87.31892927859964,0.016820715465898382
0.0174086295115518,85.7530641028394,0.05527239869917696,17.287817723132424,87.24590742528609,0.01725883529659505
0.0178597528345568,85.6488930232263,0.05670471524971784,17.266816833482423,87.17856108317451,0.01770214128444986
0.018310471921294,85.5399833528539,0.05813574835010845,17.244860643935343,87.10626081618429,0.018144853871657946
0.0187622346908695,85.4314023305917,0.05957009514351066,17.222970709847285,87.03428635108835,0.018588395013331805
0.0192152891165134,85.3326030366824,0.06100854294493004,17.20305277219517,86.97229367509692,0.0190330068187267
0.019680039148905,85.2425241442235,0.06248412429777337,17.184892867475458,86.92010035653328,0.019488890977170506
0.0201535805821834,85.1332759675415,0.06398761834843229,17.162868435056367,86.84901630497859,0.01995318515999464
0.0206115691195818,85.0312399033556,0.0654417319546722,17.142297964516487,86.78386718194736,0.020402025189582788
0.0210841807823085,84.9094881401453,0.06694227398382949,17.117752809053293,86.6997351382254,0.020864985129809673
0.0215480541591116,84.7961117880551,0.06841507195517932,17.09489613647191,86.62330299734619,0.021319176909261994
0.0220233056142605,84.6903485159486,0.06992399532527709,17.07357426081524,86.55550994389357,0.0217842954493549
0.0225072448223341,84.5796202876783,0.07146050231091076,17.051251449995945,86.48327450847312,0.02225769431053409
0.0229823567262576,84.4578151751273,0.07296898260586789,17.026695539305663,86.39885481180241,0.02272224021886645
0.0234521040808684,84.3277065199063,0.07446043045675717,17.00046563441311,86.30536867011207,0.023181328815992445
0.0239426212205932,84.2039913734528,0.0760178223753834,16.975524660888084,86.22005564416946,0.023660491083090266
0.0244190296256791,84.0875394031023,0.07753041906153114,16.952047943665423,86.14087551893712,0.02412565153313042
0.0249119918706779,83.9802851483126,0.07909557418940233,16.93042548589982,86.07240132922458,0.02460674731447171
0.0253976715756336,83.8738465584509,0.08063760725263668,16.9089674661837,86.00404696712752,0.02508050961750219
0.0258814235965997,83.7629516115471,0.08217351991920405,16.886611044887896,85.93085604390703,0.02555216852639716
0.0263628929775256,83.6475586668159,0.08370218520364378,16.863347827230083,85.85275030378047,0.026021381071775953
0.0268539403954519,83.5396378640256,0.08526126075555977,16.841590993387562,85.78300631988378,0.026499701158877346
0.027344661451356,83.4330234592423,0.0868193001080553,16.82009752938325,85.71447123959832,0.026977474890002903
0.0278354591612105,83.321932965469,0.08837758283684333,16.79770168583855,85.64123722776243,0.027455095040433624
0.028326955589389,83.2025683792303,0.08993808399631006,16.77363778525283,85.55944383863186,0.02793316664996575
0.0288090620057761,83.0798687828039,0.09146877186833911,16.74890154661327,85.47332187399944,0.028401882788412523
0.0292998087810366,82.9501338217557,0.0930268928797912,16.72274697846595,85.38055688109453,0.028878773774624986
0.0298169180378156,82.8453626670163,0.09466871477006453,16.701625113670488,85.31555605547183,0.0293810369643848
0.0303168244129152,82.7505146606981,0.09625591751100576,16.682503755596738,85.25924748374486,0.029866351460828028
0.0308232615380623,82.6443909889939,0.0978638553833478,16.66110922338117,85.19176066710155,0.03035776603161881
0.031336035589922,82.5546942494781,0.09949191299800234,16.643026360694783,85.14163108659487,0.03085508363762742
0.0318489786099128,82.4382669557243,0.10112050708647313,16.61955461827402,85.06384155663544,0.03135231779455365
0.0323794754520194,82.3356377669092,0.10280483456016158,16.598864573808893,85.00162252880921,0.03186630824240546
0.0328936178021603,82.249690268545,0.10443723652185896,16.58153755813867,84.95518014458459,0.03236420109971471
0.0334106237476957,82.1406515241774,0.10607873039893383,16.559555347274163,84.88502192664228,0.032864617201010984
0.0339280871283318,82.0235846758523,0.10772167663245345,16.535954670651826,84.80648800331272,0.03336522543585959
0.0344472177743871,81.9176456043734,0.10936991643367903,16.514597353841676,84.73948058207232,0.03386719493406944
0.0349807025984117,81.8010707330642,0.11106373074995714,16.49109585978574,84.66252966060915,0.03438278171106287
0.0355199722576677,81.6888621422214,0.11277591191809493,16.468474607871833,84.59044825927354,0.034903689217154435
0.0360520670398071,81.5639641362372,0.11446531285138754,16.443295169865422,84.50451363930924,0.03541740033484386
0.0365889941524842,81.4421513112778,0.11617005643413732,16.418737704353607,84.42203770937188,0.03593550946115754
0.037108302847383,81.311630430941,0.11781886154044102,16.392424694877704,84.32896703798684,0.036436362412556086
0.0376478884024434,81.1765747011482,0.1195320456777578,16.365197459751478,84.23270132638963,0.03695650600292236
0.0381773588022269,81.0271681541852,0.1212131141970704,16.335077099883737,84.12057142553591,0.03746663604588111
0.0387035660487361,80.9089884488745,0.1228838222047371,16.3112520712931,84.04045482724193,0.037973364430231346
0.0392240114893609,80.8097752349854,0.12453623647872086,16.291250687373058,83.97945878725514,0.03847429185150788
0.0397556986346186,80.7106143130907,0.12622434316491404,16.271259845519086,83.91932117233686,0.03898578039972236
0.0402940594371049,80.5971054972774,0.12793363871280805,16.248376468251124,83.8446900566433,0.03950342264594116
0.0408438445713853,80.4997689797837,0.1296792065141483,16.228753426324392,83.78768903202639,0.0400317731661167
0.0413954952961925,80.4023834356296,0.13143069756541118,16.209120500622927,83.73067992094188,0.0405616361142915
0.0419593244024357,80.3151451195673,0.13322085497773334,16.19153325610477,83.68511434806793,0.041102906487132
0.0425115732956856,80.2027514620228,0.13497424521380177,16.1688746947438,83.61229660931623,0.041632776111870454
0.0430623039338344,80.0831125255164,0.13672281498992422,16.144755485144106,83.53167585705765,0.04216090954983004
0.043617810304827,79.9473702047909,0.1384865477178257,16.117389833285845,83.43449943275326,0.042693340352543914
0.044183118035275,79.8423314636904,0.1402813997619981,16.096214023079987,83.37001461896219,0.043234874496522406
0.0447460976192204,79.7334225707785,0.14206885994102478,16.074257990268947,83.3011820806451,0.043773887109641994
0.0452932873899076,79.6207607204537,0.14380618746295662,16.051545361243466,83.22704671796828,0.04429750382912977
0.045849916805005,79.5065845791793,0.14557348585589086,16.028527451162546,83.15195486758478,0.044829872370057276
0.0464165660281824,79.3886625709319,0.14737259713947912,16.00475437429987,83.07361166904465,0.04537153304443215
0.0469906543294678,79.2715337279051,0.14919532749606026,15.981141199545666,82.99655496747982,0.045920005706697
0.0475563977621229,79.1584961931087,0.1509915628947402,15.958352832530716,82.92298912431967,0.04646021171051845
0.048124217778515,79.0031907111123,0.1527943914467851,15.927043247360238,82.80515746609142,0.04700210728952651
0.048696066842015,78.8526160919178,0.15461001222339762,15.896687404130628,82.69242835579757,0.04754755134295531
0.0492812884442686,78.7166083617206,0.1564680908105528,15.869268245722875,82.59586424374908,0.04810544260518246
0.0498443045166572,78.5889857453508,0.1582556668403866,15.84353952626272,82.50619908249729,0.04864187176194903
0.0504019792963369,78.4556998577798,0.16002628426586965,15.816669091328409,82.41002241769124,0.049172928330965766
0.0509739091718308,78.3272180853406,0.16184216162056278,15.790767166004667,82.31986258570494,0.049717266821527835
0.0515525173192464,78.2139455242295,0.1636792424886073,15.767931417684668,82.24607130547393,0.05026766005771442
0.0521224851108604,78.1195022016602,0.16548889022698177,15.748891643854694,82.19128479203405,0.05080953825173424
0.0526889007099285,78.0094422162544,0.16728725975402298,15.726703550796888,82.11967397162353,0.05134774857932618
0.0532714392314553,77.8970462418776,0.1691368195598706,15.704044522362526,82.04673400706164,0.051900976980959544
0.0538684988188878,77.7727890344016,0.17103248374996874,15.678994269335362,81.96229242864287,0.0524676784065552
0.0544834177265925,77.6629691599022,0.17298485128193117,15.656854582636283,81.89431315052863,0.05305099556562627
0.0550889812617768,77.5306969564532,0.1749075155061413,15.630188506420966,81.80178406829974,0.0536251057996316
0.0556996260230865,77.3923666718026,0.17684631262329964,15.602301121035405,81.70309255246359,0.05420369976800693
0.0563062800443327,77.2557503766102,0.1787724391407563,15.574759275924617,81.60573429235068,0.05477818115197278
0.0569221901067887,77.130427643945,0.1807279535890541,15.549494213019312,81.52086050931155,0.05536109027760222
0.0575105424522319,76.975776052892,0.18259597228583627,15.518316452263027,81.40269468937535,0.05591760111057239
0.0581160639204402,76.8358350877369,0.18451850294739763,15.490104353687759,81.30123139107621,0.056490028667418785
0.0587168542842594,76.6964627261063,0.1864260123525236,15.46200688558303,81.19983775211321,0.0570576600329214
0.0593021497499721,76.5555967384268,0.1882843254561614,15.433608302466844,81.09550820040747,0.057610342024439494
0.0598784653402169,76.3975118972751,0.19011412745518866,15.401738398490659,80.9720776654949,0.058154246211131876
0.0604634832175874,76.2568226574698,0.19197155921583997,15.373375447745913,80.86757577444627,0.05870606087726461
0.0610527571467988,76.0964826521424,0.19384250394108618,15.341050902671908,80.74238272722923,0.05926158237943743
0.0616530133231485,75.9668075244556,0.19574831730099648,15.31490839693025,80.65039012087793,0.05982713998115493
0.0622317903555512,75.8181342782534,0.19758593437887506,15.284935870495886,80.5364325158067,0.06037215734342146
0.0628206729480032,75.6698643319203,0.19945563660991014,15.255044649315133,80.42349613113564,0.06092638611442364
0.0634167933151859,75.5066669259508,0.20134831877571524,15.22214405227168,80.2950576163124,0.06148711405968886
0.0640264617071112,75.3713099924041,0.20328401592007803,15.194856094468664,80.19706828544756,0.062060260635679064
0.0646361208748646,75.2076543978528,0.2052196837776951,15.161863126607127,80.06878543822747,0.06263307023867752
0.0652405919670774,75.0578669263345,0.20713887949547075,15.131665972349035,79.95468659639468,0.06320068159833715
0.0658456473532938,74.9024437679141,0.2090599303467078,15.100332663611482,79.83444366615608,0.06376851915583294
0.0664629869063472,74.7268126535677,0.21101998342765232,15.06492543095925,79.69337982451484,0.06434755312904213
0.0670739011596906,74.5528812078567,0.21295963618201763,15.029860851503912,79.55343379316264,0.06492023061444853
0.067689898671549,74.3950938697469,0.21491542828216806,14.998050924140976,79.43089023545045,0.06549734132712225
0.0682917700492115,74.2246188113596,0.21682636990624649,14.963683152370097,79.29354941121534,0.06606089615758294
0.0689026736159178,74.0568908786146,0.218765988730539,14.929869201128701,79.15960865983341,0.06663258357250713
0.0695131589229044,73.8824187246625,0.22070427958022146,14.89469561489196,79.01821903907853,0.06720355327286423
0.0701196437938101,73.6964249323656,0.22262986904534704,14.857199266364905,78.86399199750035,0.06777045885253048
0.0707251469914709,73.4943892996241,0.22455234169792007,14.81646888280422,78.6922907858884,0.06833612640247413
0.0713277797522142,73.2862360322056,0.22646570071328007,14.774505184092648,78.51358053477955,0.06889879483061491
0.0719214187862653,73.0681107140992,0.22835050464639234,14.7305311199624,78.32327290468913,0.0694527565907657
0.0725210000917225,72.8498865496626,0.23025417529121894,14.686537128411981,78.13303317881265,0.07001195213344193
0.0731194211543602,72.6153921424304,0.2321541621650936,14.639263055913968,77.92498758278178,0.07056975396475383
0.0737189983994981,72.3853232426069,0.23405781991840643,14.592881165709553,77.72149677087579,0.07112832162896716
0.0743341026953933,72.1439908524291,0.2360107760578737,14.544228555849706,77.50674967730907,0.07170103029468325
0.074924111176849,71.9181518975956,0.23788405298649554,14.498699422555275,77.30655550600457,0.07225006483364058
0.0755181619615066,71.6593318391969,0.23977016422778344,14.446521298782095,77.07091286708271,0.07280255657656158
0.0761183560416608,71.4192791801303,0.24167578043227303,14.398126682714269,76.85559730100223,0.07336045201168695
0.076715373699006,71.1681098463536,0.24357131149434402,14.347490945024886,76.62779798866853,0.073915086272942
0.0773090134894031,70.9120722258539,0.24545611782885482,14.295873760732148,76.39421457412396,0.07446627762338104
0.0779023706973514,70.6441852363026,0.2473400269640907,14.241867743638604,76.14753474219341,0.0750169031697136
0.07847922553359,70.3626785845509,0.24917154106914824,14.185116002645463,75.88468710633538,0.07555192429121374
0.0790650440383313,70.0960292188492,0.25103151482170183,14.13135949052,75.63817485594967,0.07609496623700318
0.079677087157252,69.814715968176,0.2529747517242751,14.074646739184281,75.37734917723117,0.07666200305578336
0.080270855756181,69.5215326680014,0.25485996702587466,14.015540985869082,75.10208558874317,0.07721180205981407
0.0808749759305094,69.2231573931917,0.2567780485793673,13.955388530467447,74.82157858119994,0.07777087602993327
0.081465780023849,68.9176572991529,0.2586538515757205,13.893799711509226,74.5320880084447,0.0783173246934144
0.0820693676717656,68.5975044067295,0.2605702423578558,13.829256888396667,74.22725821725095,0.07887528897166415
0.0826622932565396,68.2864420336108,0.26245278108951325,13.766546713975936,73.93115593043882,0.07942309414336586
0.0832715021131333,67.9038396095222,0.2643870192091982,13.689414065279676,73.5582943330564,0.07998563107220595
0.0838532686949209,67.5406077230864,0.2662341281063738,13.616186516974217,73.20410845030861,0.0805225328727846
0.0844529819143534,67.1816593175719,0.268138217578072,13.543822518422495,72.85535077689505,0.08107569572471665
0.0850434581461424,66.7868282947402,0.2700129796140021,13.464224584219625,72.46661113153753,0.08162003978121382
0.0856523157754277,66.392917489727,0.27194610258698293,13.384812165928963,72.07962462380901,0.08218101903272129
0.0862513825132314,65.9874227406831,0.2738481394795097,13.303064424521713,71.67892918055206,0.08273267033610833
0.0868643346888901,65.5625206023578,0.27579426263722606,13.217404153435332,71.25756533500827,0.0832967932560817
0.0874663359485246,65.1763057079718,0.27770561663656557,13.139543230727115,70.877038358909,0.08385052805193974
0.0880609463985509,64.7108809124652,0.2795935048153991,13.045713591952984,70.4093823279008,0.08439716377529514
0.0886654954317105,64.2670876808394,0.28151294799568083,12.956244876457221,69.9653608500142,0.08495263003608576
0.0892629873763407,63.8320999670415,0.2834099849198817,12.868551353355567,69.52994390060483,0.08550130917255516
0.0898542157508409,63.3854567517469,0.28528713500891983,12.778508081152175,69.08090725818396,0.0860439402785452
0.0904235827246184,62.9012812256617,0.2870948751506634,12.680898295093398,68.58904043205482,0.08656622875675532
0.0910002988408672,62.4260742197767,0.28892594881975336,12.585096562706983,68.10686562923853,0.08709498076553157
0.0915657138316917,61.9311163736518,0.2907211414156211,12.485313060928203,67.60188325279879,0.08761310026358136
0.0921289970421732,61.4821111244587,0.2925095656088999,12.394793602690873,67.14639635839052,0.08812899950551288
0.0926715529615973,60.964764654499,0.29423218065307144,12.290496554347,66.61446407096972,0.0886256635424897
0.0932055400569509,60.4284699012431,0.2959275896808191,12.182379532090609,66.06073807320367,0.08911424280221239
0.0937374565597832,59.9079086942379,0.29761642457731163,12.077434392758363,65.5235236830515,0.08960069033572766
0.0942718625107851,59.4033936659069,0.2993131634717427,11.97572416304683,65.0034622262533,0.09008917633710845
0.0948102056458829,58.8622421945405,0.30102240292567817,11.866628026419365,64.44298348178265,0.0905810200681237
0.095348087729056,58.3113301106488,0.30273017853975276,11.755564150306798,63.871203929636884,0.09107220108970948
0.0958646582376685,57.7489875067851,0.30437028990459747,11.642195881367877,63.28507445769444,0.09154369389124879
0.0963813915496217,57.1698746752667,0.3060109181700489,11.525446734533766,62.67998675118638,0.09201511298362026
0.0969257848925649,56.6010605211487,0.30773936703389354,11.410773801063579,62.08716273791261,0.09251152621745254
0.0974576440751217,55.9845949100226,0.3094280199385114,11.286494333860556,61.440721634453446,0.0929962721246175
0.0979789925619108,55.3608052165365,0.31108330138406676,11.160738331653759,60.78500113906892,0.09347121044703494
0.098479447312853,54.7573718339925,0.3126722452183083,11.03908616173289,60.14984754850846,0.09392690289312638
0.098979483066038,54.1540695468411,0.31425985873467066,10.917460420643165,59.514211356509705,0.09438200651750166
0.0994826718565177,53.5152541538075,0.3158574831444437,10.788675237407592,58.83909462210887,0.09483977086713104
0.0999929840119627,52.8894683770888,0.31747772423798154,10.662516824821102,58.17804414292024,0.09530380161304121