File: example/data/02 processed data/test_ID_120.csv
Strain,Stress_MPa,Displacement(mm),Force(kN),True Stress (MPa),True Strain
0.0014156124710563,0.408270021278028,-0.0007128831683738,0.0823072362896504,0.4081783523563521,-0.000224555342435
0.0013505269875983,0.903020831417128,-0.000919529578353,0.182048999613693,0.902759302483472,-0.0002896575619307
0.0012971973268794,1.38907372398837,-0.0010888512511355,0.2800372627560554,1.3885973477167843,-0.0003430040951276
0.0012434241334198,2.0815363999816,-0.0012595811403697,0.4196377382362906,2.0807106160469826,-0.0003967971829985
0.0011213185722303,3.21651252189436,-0.0016472662971464,0.648448924413903,3.214843717903284,-0.0005189586663548
0.0009941590448424,4.66346128359163,-0.002050997796603,0.9401537947720726,4.6604487642791295,-0.0006461922952625
0.0008984660131961,6.25911139087083,-0.00235482317208,1.2618368563995592,6.254469154480325,-0.0007419517677838
0.0008123128620374,7.89933777485494,-0.0026283594270088,1.5925064954107562,7.892798468112367,-0.000828172581052
0.0007483488497542,9.60075357047406,-0.002831445166008,1.9355119198075703,9.592191678415114,-0.0008921916376939
0.0006930732352999,11.3934898692322,-0.0030069452419004,2.296927557637212,11.382699443987812,-0.0009475181210774
0.0006507959691878,13.1113053833301,-0.0031411755618063,2.6432391652793483,13.09833375748648,-0.0009898363600533
0.0006237968445018,14.8669114953819,-0.0032268977826844,2.997169357468992,14.851801572944163,-0.0010168625878906
0.0006099024428097,16.6117652009839,-0.0032710125080568,3.3489318645183546,16.59465109334506,-0.0010307712221905
0.0006222087502751,18.511792188761,-0.0032319399818541,3.731977305254218,18.49294840882064,-0.001018452299076
0.0006311359975522,20.5148281628913,-0.0032035959717493,4.1357893576388856,20.49412856576885,-0.0010095159951207
0.0006405286720582,22.4944051341583,-0.0031737742301928,4.534872075046313,22.471919413421823,-0.0010001138779719
0.0006664816516056,24.551589790099,-0.0030913735201298,4.949600501683959,24.52768486582996,-0.0009741352669527
0.0006905381734874,26.6797096051276,-0.0030149940631551,5.378629456393724,26.65437443471306,-0.0009500555892645
0.000737047629758,28.9108709121007,-0.0028673265394959,5.828431575879502,28.88476164991292,-0.0009035030090167
0.0007883638269237,31.1586710557365,-0.0027043976134948,6.281588084836479,31.13213076104585,-0.0008521417455733
0.0008444296688176,33.3691303739368,-0.0025263885654817,6.72721668338566,33.34257812530159,-0.0007960296815846
0.0008902618510706,35.6152131206207,-0.0023808713868284,7.180026965117134,35.58850595783183,-0.0007501620529649
0.0009378455278551,37.9518073510604,-0.0022297932130376,7.651084361973777,37.92515390776784,-0.0007025438010866
0.0009706218049767,40.277798532235,-0.0021257285331766,8.120004184098578,40.25083170842603,-0.0006697450269898
0.001025820601069,42.5449090882597,-0.0019504723555835,8.577053672193156,42.518772814543965,-0.0006145107748351
0.0010571751419547,44.7571054503344,-0.0018509216882714,9.023032458787416,44.731013514214,-0.0005831374524727
0.0011051758632648,46.9409715431531,-0.0016985193981118,9.463299863099664,46.91585968465475,-0.0005351098853234
0.0011410907024869,49.1303117304952,-0.0015844897835817,9.904670844867834,49.10579315506177,-0.0004991764681859
0.0011904077080097,51.2409603441275,-0.0014279082910468,10.330177605376106,51.21791549621677,-0.0004498360558873
0.00124831942097,53.3548484060116,-0.0012440386023978,10.756337438651938,53.33394273954163,-0.000391899964618
0.0013073885746307,55.4557829975235,-0.0010564940395251,11.17988585230074,55.43732986234426,-0.000332809403103
0.0013549841580433,57.6679518008491,-0.0009053780621901,11.62585908305118,57.65150729739968,-0.0002851991101844
0.0014171799470624,59.7583763499728,-0.0007079064320545,12.047288672154515,59.7450524636776,-0.0002229875156333
0.001462444644485,61.8739865839942,-0.0005641910177377,12.473795695333232,61.86299170290371,-0.0001777137484953
0.0015059502010128,64.0145115033451,-0.0004260608757619,12.905325519074374,64.00592124229547,-0.0001342014064207
0.0015502593271338,66.1491368529208,-0.0002853794003277,13.335665989548836,66.14319115181614,-8.988731543751074e-05
0.0015941439676281,68.2427096848307,-0.0001460456667582,13.75773027246187,68.23957061332288,-4.599969316915933e-05
0.0016403675199549,70.3947382908459,7.141118793416411e-07,14.191579239434532,70.3947541238282,2.2491710207331025e-07
0.001692027660589,72.4339881778924,0.0001647350583925,14.60269201666311,72.4377464195529,5.188371177827297e-05
0.0017356357609346,74.5263016092988,0.0003031907769896,15.02450240443464,74.5334183612015,9.548859892559616e-05
0.0017866180669849,76.6079028800166,0.0004650595986994,15.444153220611344,76.61912405814907,0.0001464647376739
0.0018401741486838,78.6898548771706,0.0006351001580934,15.863874743237592,78.70559533048488,0.0002000115422139
0.0018898231128059,80.7500927803471,0.0007927356191811,16.279218704517977,80.7702545046933,0.0002496493449871
0.0019357351208804,82.7864404783071,0.0009385062448176,16.68974640042671,82.81091153070871,0.0002955488391916
0.0019853883495522,84.7652222095655,0.0010961552458506,17.088668797448403,84.79448704200351,0.0003451861631253
0.0020284258681802,86.7711213910408,0.0012327993674945,17.493058072433822,86.80481316539282,0.0003882079029128
0.0020837057856347,88.7759377602375,0.0014083131054125,17.897229052463878,88.81531549774711,0.0004434648377388
0.0021283527885238,90.8272588943704,0.0015500673395854,18.31077539310507,90.8716016873015,0.0004880910498774
0.0021759053453004,92.8492164778121,0.0017010467073511,18.71840204192692,92.8989616286687,0.000535619272856
0.0022344688008206,94.8255491944317,0.0018869856786277,19.11683071759743,94.88190650255704,0.0005941496561237
0.0022861061575982,96.7857550803674,0.0020509342863966,19.512008224202063,96.84827515077026,0.0006457550101169
0.0023377576575874,98.7500597294355,0.0022149277988623,19.9080120414542,98.8189492577612,0.0006973718344869
0.0023994529351386,100.674825407314,0.0024108103050874,20.2960448021145,100.75126884244938,0.0007590222020648
0.0024527568591008,102.578284395668,0.0025800502636674,20.679782134166672,102.66164097195195,0.0008122842640672
0.0025007420740648,104.400775669865,0.0027324033211781,21.047196375044784,104.49062292220324,0.0008602293678375
0.0025522260647469,106.219021601467,0.0028958649915937,21.41375475485575,106.31590221441095,0.0009116677665453
0.0026013671494314,108.046929855225,0.003051887935467,21.78226105881336,108.15078721638702,0.0009607628661179
0.0026477983762128,109.921161338853,0.003199307080498,22.160106125912765,110.0319240316933,0.0010071484290966
0.0026924624973613,111.709551532365,0.0033411156651444,22.520645588924783,111.82710571585196,0.0010517665940856
0.0027282857071463,113.487350911073,0.0034548543562118,22.87904994367232,113.61084138939428,0.0010875515057345
0.0027654948005392,115.293734689405,0.0035729932277343,23.24321691338405,115.42348074712012,0.0011247194635819
0.0028222321126157,117.044699087272,0.0037531341935772,23.596211335994035,117.18305639823936,0.0011813913920877
0.0028674467189536,118.743500578178,0.0038966905687,23.938689716560685,118.8892349652008,0.0012265515940818
0.0029094052047832,120.553190048754,0.004029908761209,24.30352311382881,120.70620370442934,0.0012684577691368
0.0029575043040894,122.296984303033,0.0041826234015062,24.65507203549145,122.45809366633364,0.0013164947416519
0.0030106102847342,124.068485555651,0.0043512348900534,25.01220668801924,124.2385174054481,0.0013695294481878
0.0030573897951364,125.812874008395,0.0044997598355804,25.36387540009244,125.9911819508397,0.0014162438453886
0.0031171660826778,127.546177430263,0.0046895495485243,25.713309369941022,127.73456612909264,0.0014759337535724
0.0031619601284956,129.326625944448,0.0048317706439959,26.07224779040072,129.52343747034578,0.0015206607348448
0.0032121375256699,131.044325371606,0.0049910838800243,26.41853599491577,131.25032638575746,0.0015707606321867
0.0032625811250214,132.716864560593,0.0051512423079653,26.755719895415552,132.9321895142009,0.00162112379067
0.0033162272481139,134.379779956614,0.005321568748784,27.09096363925338,134.60501184243623,0.0016746815829659
0.0033607772060029,135.990709189951,0.0054630148650815,27.41572697269412,136.22469950989355,0.0017191560072956
0.0034117766566586,137.622097579844,0.0056249381209134,27.744614872096548,137.86591357447608,0.0017700665612963
0.0034609688199214,139.23590286359,0.0057811232392728,28.069958017299747,139.48942724588477,0.001819170522554
0.0035071390795053,140.882824369461,0.0059277138134516,28.40197739288334,141.14585210618318,0.001865255804971
0.0035548564080107,142.512453587333,0.0060792163314563,28.730510643206337,142.7853241496272,0.0019128830772128
0.0036010794115388,144.160284251033,0.006225974367658,29.062713305008256,144.44297345877513,0.0019590166818825
0.0036520221594812,145.783445402396,0.0063877175923751,29.38994259312304,146.07674413589962,0.0020098584373566
0.0037019106070499,147.41069386269,0.0065461134134058,29.717995882718306,147.71462051477633,0.0020596454775084
0.0037477267532786,149.060589388295,0.0066915796776819,30.05061482068027,149.37474712394666,0.002105366310618
0.0037848107227629,150.655915391576,0.0068093212807945,30.372232542941724,150.979022330396,0.002142371602189
0.0038357641780333,152.189118387682,0.006971098501278,30.681326266956688,152.52326809952552,0.0021932147205391
0.0038813996569998,153.780742015025,0.0071159911469967,31.00219759022904,154.125404187862,0.0022387491840693
0.0039322612514392,155.278272332697,0.0072774767093418,31.30409970227172,155.63418855643494,0.0022894957518909
0.0039690795665154,156.81765365392,0.0073943748597087,31.61443897663027,157.1828720840734,0.0023262291933334
0.0040201230152096,158.40583986569,0.0075564378093128,31.93461731692311,158.7828426617773,0.0023771527446409
0.0040745016139843,159.939928471405,0.0077290898604225,32.24388957983525,160.32927967752312,0.0024314007592511
0.0041272984517469,161.535997094026,0.0078967198203187,32.56565701415564,161.9377622940094,0.0024840679957324
0.0041752749197231,163.119657054343,0.0080490451061432,32.88492286215555,163.53318696846236,0.0025319242896684
0.0042237454114122,164.727824170695,0.0082029389172561,33.20912935281211,165.15341543987444,0.0025802710442516
0.0042753342586018,166.329889115211,0.008366733507083,33.53210564562654,166.76820025111326,0.0026317256260094
0.0043278976069697,167.879916509183,0.0085336221381511,33.8445911682513,168.33113659487557,0.0026841494497806
0.0043741330940815,169.441858833146,0.0086804198097311,34.15947874076223,169.90511126401623,0.0027302599372367
0.0044211901406385,170.978300653296,0.0088298259325496,34.46922541170448,171.45379943534695,0.0027771875799353
0.0044717372029557,172.484420249689,0.0089903128554067,34.7728591223373,172.97282620267424,0.0028275931879433
0.0045248526288365,173.955343734262,0.0091589543325782,35.06939729682721,174.45715445841006,0.0028805572345244
0.0045845266627783,175.355897747547,0.0093484193903434,35.35174898590548,175.87221285769326,0.0029400578511376
0.0046337152688124,176.741253594451,0.0095045932145017,35.63103672464132,177.27034138016325,0.0029891008495803
0.0046853202914849,178.119786934379,0.0096684391614869,35.90894904597081,178.66219333545996,0.0030405505263871
0.0047466734128642,179.497567293127,0.0098632353218662,36.1867095662944,180.05518201624972,0.003101715513201
0.0048165678396957,180.926299596813,0.0100851501270562,36.47474199871751,181.50099846086547,0.0031713910558745
0.0048788547618881,182.316067777351,0.010282911105017,36.75491926391396,182.9065370428536,0.0032334788272949
0.0049426200516682,183.696952927246,0.0104853659000689,37.0333057101328,184.30360797170897,0.0032970362465314
0.0050001877895227,185.076234145459,0.0106681434677569,37.31136880372453,185.69809865517112,0.0033544128479488
0.0050720905265895,186.382682021613,0.010896434657944,37.574748695557176,187.02233768020224,0.0034260722300317
0.0051516858807908,187.710962996853,0.0111491499075331,37.842530140165564,188.3701181671645,0.0035053922054987
0.0052190503148937,188.959731472247,0.0113630319858098,38.09428186480499,189.63600091248296,0.0035725186612048
0.0052854253904976,190.119628303089,0.0115737728508522,38.328117065902745,190.8126681117405,0.0036386548466318
0.0053646002381919,191.255692184123,0.0118251529922816,38.5571475443192,191.96801590718505,0.0037175390164396
0.0054371042983112,192.366175381925,0.0120553533831604,38.78102095699608,193.09658238135685,0.0037897714314491
0.005502788096919,193.413772057875,0.0122638994437401,38.9922164468676,194.1608608930096,0.0038552046337668
0.0055801560426516,194.446582247717,0.0125095426714412,39.20043098113975,195.21270439510084,0.0039322719146838
0.0056637934056208,195.457410761547,0.0127750912988684,39.40421400952788,196.2438631292696,0.0040155775685728
0.005752544891228,196.445479681109,0.0130568772656712,39.60340870371157,197.2533425212955,0.0041039694736218
0.005838499345758,197.358483733377,0.013329782658804,39.78747032064881,198.1870650543336,0.0041895682328735
0.0059220605949552,198.192539257029,0.0135950896250051,39.95561591421705,199.04118345677915,0.0042727766669283
0.0060197953853431,198.97049857232,0.0139053975844867,40.11245251217972,199.8419202700308,0.0043700900141711
0.0061335213460814,199.743674540805,0.0142664775098308,40.26832478742629,200.64119852208603,0.0044833136565566
0.0062372526662791,200.581654408486,0.0145958244514585,40.43726152875078,201.50375035051096,0.004586575625958
0.0063357387034234,201.294993544374,0.0149085176193916,40.581070698545794,202.24019353113044,0.0046846061786209
0.0064493638611467,201.939850702396,0.0152692774951631,40.71107390160304,202.9110241252957,0.0047976938974088
0.0065658702290192,202.565503625679,0.0156391852131583,40.83720553093689,203.56328612300143,0.0049136359205773
0.0066914414845719,203.185203125708,0.0160378739495381,40.96213695014273,204.2115523150439,0.0050385838717828
0.0068105025914016,203.78491830362,0.0164158929637224,41.08303953000979,204.83855969149187,0.0051570395718728
0.0069364135127751,204.309751709823,0.0168156601390833,41.18884594470032,205.3918315044224,0.0052822949922843
0.0070605757880282,204.73182670206,0.0172098753630119,41.273936263135305,205.8415618895825,0.0054057955084515
0.0071947925165338,205.144875189622,0.0176360134760171,41.3572068382278,206.2843831528913,0.0055392797369066
0.0073206925006819,205.543852735427,0.0180357459256874,41.43764071146208,206.71145484708785,0.0056644764163643
0.0074560713681187,205.918775207282,0.0184655738297992,41.51322508178805,207.1163841353236,0.0057990815415308
0.0075812816891088,206.274377357458,0.0188631165989428,41.58491447526353,207.49988212327472,0.0059235601111878
0.0077213228024345,206.641255374266,0.0193077471337519,41.658877083452026,207.89787808486983,0.0060627644452645
0.0078560328817576,207.020968152836,0.0197354516356027,41.73542717961173,208.30778777631187,0.0061966513166421
0.0079997563359981,207.350801889456,0.0201917736028163,41.80192166091433,208.6694728967361,0.0063394767204079
0.0081473059965034,207.717481486391,0.0206602437749206,41.87584426765642,209.06913307814577,0.0064860832046981
0.0082965185172122,208.015433948071,0.0211339935281711,41.93591148393112,209.4000628724232,0.0066343200648126
0.0084471990685528,208.273621335098,0.0216124042786775,41.98796206115576,209.69135163584707,0.0067839930603076
0.0086101201935012,208.502793728751,0.0221296788503886,42.0341632157162,209.9560535286332,0.0069457995786545
0.0087588534101359,208.663070903747,0.0226019068132038,42.06647509419541,210.14848296167563,0.0070934923965149
0.0089201650236367,208.773302170597,0.0231140711860688,42.08869771759235,210.2931764912653,0.0072536509700731
0.0090824038439094,208.883399716654,0.0236291794404347,42.11089338287745,210.43796454627065,0.0074147042546265
0.0092351244727395,208.929727440815,0.0241140674369702,42.1202330520683,210.5165449328136,0.007566285203956
0.0093913293597084,209.014530018893,0.0246100179530965,42.13732925180884,210.63464067597107,0.0077213006446909
0.0095446825024135,209.109726396369,0.0250969141811852,42.15652084150799,210.7626425720606,0.0078734626840442
0.009694246119421,209.205487400493,0.025571778665184,42.1758262599394,210.890450052256,0.0080218423323771
0.0098562579357693,209.300788410705,0.0260861661820898,42.19503894359813,211.02042782756297,0.0081825468006397