File: example/data/02 processed data/test_ID_062.csv
Strain,Stress_MPa,Displacement(mm),Force(kN),True Stress (MPa),True Strain
0.00032382074608922003,0.464741622721054,3.6273816686571285e-05,0.0936919111405645,0.4647469323123702,1.1424758890365863e-05
0.00032431675950502,0.507515449057921,3.784865928165723e-05,0.1023151145300768,0.507521499067153,1.192076651644875e-05
0.00032278594329522006,0.536670838304791,3.298831781558256e-05,0.1081928410022458,0.5366764143262639,1.038996738337642e-05
0.00032232913454732006,0.558732492714701,3.153795004097773e-05,0.1126404705312837,0.558738042723344,9.933163277305257e-06
0.00031720403732792,0.606716686220694,1.526576636941509e-05,0.1223140839420919,0.6067196033845316,4.808103833102298e-06
0.00031494162541932,0.743202284287908,8.082608559539285e-06,0.1498295805124422,0.743204176260552,2.545700243049981e-06
0.00030953614074302006,1.46905418826863,-9.079805287817704e-06,0.2961613243549558,1.469049987095091,-2.8597852821474035e-06
0.00031195261705912005,2.8779979497038,-1.4074929841169615e-06,0.5802043866602861,2.877996673873273,-4.433049751777629e-07
0.00031757871218902005,5.04018117901485,1.6455359053131903e-05,1.0161005256893936,5.040207301216737,5.182776822355643e-06
0.00034144567682662004,7.98810291238228,9.223297177767595e-05,1.6104015471362678,7.988334964813927,2.904933295475051e-05
0.00037009101198222003,11.7723875854755,0.0001831819108966,2.3733133372318607,11.773066794437302,5.769342574846798e-05
0.00041343820773032005,16.3971219399133,0.0003208092573969,3.3056597830865218,16.39877874259456,0.0001010371813664
0.00048073310609362,21.8621948236321,0.0005344705597003,4.407418476444232,21.86587504394822,0.0001683230170437
0.00055199515952262,27.6455128138016,0.0007607275793374,5.573335383262402,27.652136657594475,0.0002395705382733
0.00063591663924412,33.6375073832691,0.0010271782774532,6.781321488467052,33.64838981378619,0.0003234683957651
0.0007293270393551201,39.7918296442285,0.0013237562978056,8.022032856276466,39.80842009622622,0.0004168442257918
0.00081705531677642,46.1443984620984,0.0016022935786182,9.302710729959038,46.16768566630156,0.0005045320971141
0.0009181242731192201,52.6072057647634,0.0019231875150066,10.605612682176302,52.63907144077164,0.0006055449718137
0.00101944675557882,59.1878647072509,0.0022448863968158,11.93227352498178,59.229713536333705,0.0007068009909629
0.00111342754806802,65.7499475514718,0.002543275412969,13.255189426376717,65.80261533887706,0.0008007109715238
0.00122271202813152,72.3962318902945,0.0028902536371707,14.595080349083371,72.4621353462121,0.0009099020197694
0.00132395811850172,79.1367670883551,0.003211709974096,15.953972245012388,79.2168188503001,0.001011050912295
0.00143193014548902,85.9277013726963,0.0035545211597807,17.323024596735575,86.02390037513429,0.0011189080124471
0.0015435704212866201,92.6787427246945,0.0039089790354381,18.68403453329841,92.792846429369,0.0012304172255203
0.00165305779975712,99.4731790603482,0.0042566014620819,20.0537928985662,99.60653895938007,0.0013397639931027
0.00176596690193692,106.238228617597,0.0046150878615028,21.41762688930756,106.39265342368223,0.0014525155683241
0.0018820536302836199,113.090829457659,0.0049836632240036,22.79911121866405,113.26834334986064,0.0015684270832919
0.00198507119651922,119.889072370826,0.0053107439968016,24.169636989958523,120.0896078578734,0.0016712779113024
0.00209475272583982,126.624430623468,0.0056589828523945,25.527485213691147,126.85012053893016,0.0017807702908906
0.00220475338406202,133.323093468879,0.00600823494225,26.877935643326005,133.57538841967855,0.0018905692093971
0.00231708827301892,139.948060973625,0.0063648982146882,28.2135290922828,140.22861378100768,0.0020026856368204
0.00242988463256862,146.510600607148,0.0067230266562585,29.53653708240104,146.82083514992163,0.0021152499911644
0.00254303698396052,153.024416048495,0.0070822853719277,30.8497222753766,153.3657585944251,0.0022281568757834
0.00265467301331422,159.456009415549,0.0074367297651257,32.14633149817468,159.82949957348563,0.0023395382363296
0.00278039549805992,165.817561756351,0.0078358986541933,33.428820450080366,166.22679942847958,0.0024649590667929
0.00290458520198792,172.128867273973,0.0082302009641647,34.701179642432955,172.57505787850806,0.0025888353521804
0.00302074980460252,178.345769669256,0.0085990235774661,35.954507165322006,178.82879312699686,0.0027046929009558
0.0031379295884579202,184.565717326551,0.008971069391207,37.20844861303269,185.0872139745429,0.0028215493497212
0.0032550718537805202,190.701920278545,0.0093429960836062,38.445507128154674,191.2630942295052,0.0029383547362012
0.0033669912771876202,196.726971167141,0.0096983402529238,39.66015738729562,197.32789245952085,0.0030499395575021
0.00348482323940002,202.546466870001,0.0100724567329482,40.83336772099221,203.1890308145552,0.0031674057874115
0.00360204708950082,208.21826736533,0.0104446424570182,41.97680270085053,208.9032328316767,0.0032842521026159
0.00371364787836182,213.634265851743,0.0107989749616519,43.068667995711394,214.3608898164308,0.0033954807814345
0.00383660318446452,218.843186521414,0.0111893580585279,44.11878640271706,219.61443526870767,0.0035180117959193
0.00395972672744082,223.811531492222,0.0115802753074777,45.12040474883195,224.6278461856608,0.0036406954238957
0.00408639702233062,228.487531309983,0.0119824534937528,46.06308631209257,229.34984350457333,0.0037668974254832
0.00422088299680912,232.980815407088,0.012409446462722,46.968932386068936,233.8914179128,0.0039008687834761
0.00435817170755622,237.276157473484,0.0128453381193441,47.834873346654376,238.23612360589524,0.0040376136421618
0.00450095987060622,241.379648033193,0.0132986905370278,48.66213704349171,242.3906821248876,0.0041798163328194
0.00465921841123452,245.323262337328,0.0138011614035227,49.45716968720532,246.389639011204,0.0043374023450194
0.00482733658864362,249.117658802929,0.0143349366167966,50.22212001467048,250.2424102514533,0.0045047788971396
0.00501798499950562,252.79785794312,0.0149402453212834,50.964048161333,253.9874207822901,0.0046945524024486
0.00523541568447242,256.3075224107,0.015630587746053,51.67159651799712,257.56932940881467,0.0049109413261123
0.00547829664909362,259.488298581101,0.0164017348087253,52.31284099394996,260.82878937143,0.0051526032380082
0.00574884119527582,262.324960144269,0.0172607137428538,52.88471196508464,263.7510754339244,0.0054217211452395
0.00604871605172472,264.736807656913,0.0182128164120791,53.37094042363367,266.25542273577133,0.0057199300945945
0.00637245623839132,266.746680584118,0.0192406915047455,53.776130805758186,268.363181557672,0.0060417719992801
0.00671656691502672,268.322603674766,0.0203332429030629,54.093836900832834,270.0409875100105,0.006383751423943
0.00707527184246732,269.429556415734,0.0214721310476868,54.31699857341198,271.2516750750974,0.0067401102584338
0.00743889229912172,270.207620859523,0.0226266259975645,54.47385636527984,272.1332544906664,0.0071012229050446
0.00781032109928382,270.746632235455,0.0238059124380792,54.58252105866774,272.7766702259753,0.0074699554592581
0.008184960287946422,271.177536809999,0.024995391862083,54.669391420895806,273.312399423152,0.00784173741689
0.00856720723901552,271.521651417233,0.0262090259317274,54.73876492571417,273.7630114181841,0.0082209267084591
0.008950726912445521,271.835313404357,0.0274267008948676,54.801999182318376,274.1835168164528,0.0086012340931267
0.009331355127720719,272.133749081427,0.0286351954783664,54.86216381481569,274.5881122629097,0.0089785312898706
0.009713959869272318,272.397164245371,0.0298499655327927,54.9152683118668,274.9581236040969,0.0093576443059595
0.01009641665763952,272.660579409315,0.0310642658358586,54.96837280891791,275.32829617206465,0.009736467130213