File: example/data/02 processed data/test_ID_083.csv
Strain,Stress_MPa,Displacement(mm),Force(kN),True Stress (MPa),True Strain
0.0005903185807671863,35.2190159803605,0.0018742614939358166,14.200307243281355,35.239806419890044,0.0005901444112940712
0.0007009566766967863,41.0018533628833,0.0022255374485122964,16.531947275914547,41.03059388575496,0.0007007111213080184
0.0007951232154281864,46.8848965424742,0.0025245162089844917,18.903990285925598,46.92217581216807,0.0007948072724289775
0.0009088193515336862,52.8715443780074,0.0028855014411194534,21.317806693212585,52.919595060683605,0.0009084066252702604
0.0010014361954183862,58.8662190665992,0.003179559920453376,23.734859527652798,58.925169829059925,0.0010009350927120885
0.0011013937518402862,64.8280624088509,0.0034969251620929087,26.138674763248684,64.89946363173192,0.0011007876627296507
0.0011922848455404862,70.7136816444676,0.0037855043845910433,28.511756439049336,70.79799249546468,0.001191574638420855
0.0012860611625052864,76.501786333999,0.004083244190954284,30.845520249868397,76.60017231026542,0.0012852348941935151
0.0013784570120258862,82.0918415816241,0.004376601013182189,33.09943052571084,82.2050016562824,0.001377507812346054
0.0014679818300974863,87.484271661052,0.004660842310559519,35.27365833373617,87.61269698226975,0.0014669053980971133
0.001548198508680086,92.769363402342,0.004915530265059273,37.404607323824294,92.91298879241269,0.0015470012849029876
0.0016298376456955863,97.9645922354927,0.0051747345250834865,39.49932358935066,98.12425861586333,0.00162851090170915
0.0017072700740753863,103.096699412978,0.0054205824851893515,41.56858920331273,103.27271332262173,0.0017058143451686189
0.0017891925348143861,108.224120199279,0.005680686298035676,43.635965264349295,108.4177539872264,0.0017875938364863965
0.0018731575660390861,113.16935421229,0.0059472752721740985,45.62988361839533,113.38133824437651,0.0018714053941270218
0.0019533759269492862,118.050317850127,0.006201968568063983,47.59788815717121,118.28091449918415,0.0019514705690432557
0.002048424845592886,122.914595232969,0.006503748884757413,49.5591647979331,123.16637654373022,0.0020463296841182923
0.0021317894201269864,127.751071326677,0.006768431408903181,51.509231958916175,128.0234097089411,0.0021295203812308986
0.0022217467351731864,132.67763347478,0.007054045884174866,53.4956218170313,132.97240957378312,0.00221928230544643
0.002300751468413986,137.588013577686,0.007304885912214405,55.475487074523,137.90456940196103,0.0022981087924051342
0.002376855139642486,142.515899860162,0.007546515068364893,57.46241082361732,142.85463950922542,0.0023740348874683763
0.0024624216571635864,147.428246720281,0.007818188761494387,59.4430690776173,147.7912772278827,0.002459394864762591
0.0025418646363904863,152.280144882681,0.008070420220539793,61.39935441669697,152.66722039778267,0.002538639562453714
0.0026287321872733864,157.189958796936,0.008346224694593002,63.37899138692459,157.60316910114167,0.002625283113954907
0.0027013155538444865,162.096980288846,0.008576676883456244,65.35750245246271,162.53485538293148,0.0026976735582955576
0.002782094468625886,167.067241605596,0.008833149937887188,67.3615118153763,167.5320384543555,0.002778231606715615
0.0028593485759812864,171.942834686308,0.009078431728740583,69.32735094551938,172.4344791858185,0.0028552684147269388
0.0029426595416396865,176.711440578419,0.009342944044706003,71.25005284121855,177.23144218515398,0.002938338394085951
0.003024603716273986,181.407437557107,0.009603116799169906,73.14347882302553,181.95612316690196,0.003020038804836171
0.0031081831341220863,186.038852523403,0.009868481450837624,75.01086533743609,186.61709534710764,0.0031033627188304723
0.003192389678915686,190.656121951911,0.010135837230557302,76.87254837101051,191.26477058785235,0.0031873048220070316
0.0032773444003450863,195.243446336155,0.010405568471095649,78.72215756273769,195.88332635170886,0.003271985612389542
0.0033635239893781864,199.839408839093,0.01067918866627574,80.5752496439223,200.51157348474644,0.0033578799948309306
0.0034529232823954864,204.434577705702,0.010963031421605669,82.42802173093905,205.1404746187887,0.0034469756300575575
0.0035401128840738864,209.001211451002,0.011239858406934589,84.269288457044,209.74109933244677,0.003533861434006253
0.003630511392607986,213.391331550791,0.011526873671530354,86.03938488127893,214.16605121106994,0.003623936993604275
0.003723994769363486,217.574410142121,0.011823683392729068,87.7260021693032,218.3846561074376,0.0037170778678604433
0.003828464607827486,221.520217647267,0.012155375129852267,89.31695175537806,222.3682999604478,0.0038211546884389974
0.003943425182059486,225.206097613507,0.012520374953038867,90.80309855776602,226.09418100998948,0.003935670261589855
0.004078632283714086,228.693275680895,0.012949657500792222,92.20912875453688,229.6260314581554,0.004070337210447439
0.004242567057988986,231.901485605474,0.01347015040911503,93.5026789961271,232.8853432090025,0.004233592744166697
0.004452187634814987,234.844670854146,0.014135695740537583,94.68937128839167,235.890243393825,0.00444230596661829
0.004707330229849985,237.614419573018,0.014945773479773702,95.80613397184086,238.73294911332232,0.004696285398453232
0.005014796323483886,239.991033791357,0.015921978327061336,96.76438482467515,241.194539945283,0.005002264112595267
0.005334253672280086,241.964572155572,0.016936255409489273,97.56011549312663,243.25527256315453,0.005320076933692875
0.005679695757157686,243.414944274543,0.01803303402897565,98.14490553149574,244.79746710076788,0.005663627099889642
0.006023282172804586,244.38613508164,0.01912392089865456,98.53648966491724,245.85814173235784,0.006005214722672134
0.006379603877741686,245.099655173192,0.020255242311829853,98.82418096583102,246.66329388376803,0.006359340341484148
0.006740440301241886,245.655448023489,0.021400897956442986,99.04827664307076,247.31127390556614,0.006717825100908033
0.007108128256527086,246.03188870556,0.022568307214473497,99.20005752608178,247.78071492567472,0.00708298459215437
0.007480221024719586,246.344262474511,0.023749701753484686,99.32600662972284,248.18697200599186,0.007452382908744871
0.007850110698731486,246.580185664565,0.024924101468472466,99.42113085995261,248.51586741814558,0.007819458888640368
0.008224053405743687,246.829148335329,0.026111369563236207,99.52151260880466,248.85908443333295,0.008190420153814406
0.008586931275846487,247.10710732298,0.027263506800812593,99.63358567262554,249.22899907133564,0.008550273285094313
0.008952673881497687,247.346431146844,0.028424739573755155,99.7300810384075,249.56084308065402,0.008912836288787423
0.009318950128466187,247.537311221752,0.02958766665788014,99.80704388461041,249.84409907996215,0.009275796602584908
0.009681050469235586,247.791431761118,0.030737335239822985,99.90950528608278,250.1903131178415,0.009634489365877985
0.010046451953360286,247.990464149889,0.03189748495191891,99.98975514523525,250.48188843286238,0.00999632182859695
0.010416554789878487,248.238860296203,0.03307256145786419,100.08990847142904,250.8246539854554,0.0103626763121212
0.010770276176669386,248.473337712789,0.034195626860925296,100.18444976579653,251.1494641824946,0.010712689863548359
0.011122543613232587,248.735060879475,0.03531407597201346,100.28997654660432,251.50162744224698,0.011061142992892748
0.011472549908796687,248.970562354286,0.036425345960429484,100.38493074124813,251.8268895567167,0.011407239253265243
0.011821279975258286,249.195718765471,0.03753256392144506,100.4757138062379,252.1415311256334,0.01175195445455164
0.012179459496769587,249.383369831705,0.03866978390224344,100.55137471614346,252.42072448373818,0.012105886662445754
0.012529054927593887,249.588868680766,0.039779749395110586,100.63423185208485,252.71598132578333,0.01245121581161239
0.012874276979745386,249.792901000799,0.0408758294106916,100.71649768352216,253.0088039958574,0.012792107968800273
0.013207900661455886,249.924029432205,0.041935084600122435,100.76936866706507,253.22500118585634,0.013121436846382286
0.013547286151834186,250.103838846379,0.04301263353207354,100.84186782286002,253.49206711890312,0.01345634211344038
0.013881518577719286,250.266815629289,0.04407382148425873,100.90758006172933,253.7408990798336,0.013786052757911041
0.014222446391774887,250.483016879802,0.04515626729388526,100.99475240593617,254.04549815942502,0.014122256249601424
0.014577619386886887,250.80503013527,0.04628394155336586,101.12458815054086,254.46117040489867,0.014472387348995136
0.014923405968047386,251.067054161634,0.04738181394855045,101.23023623797083,254.81382973608982,0.014813147545897213
0.015284216189697386,251.272567290136,0.0485273864022892,101.31309913138284,255.11307153113873,0.015168589247042171
0.015637006718130588,251.424413144433,0.049647496330064614,101.37432337983539,255.35593838187455,0.015516008465476119
0.015984546811737988,251.601053657906,0.05075093612726811,101.4455448348677,255.62278247798338,0.01585813920965285
0.016334872546002986,251.870033707138,0.05186322033355948,101.55399759071804,255.98429860590159,0.01620289381308596
0.016677656517793488,252.144457917379,0.05295155944399432,101.66464543228722,256.3496365793903,0.016540111582419255
0.017024034882673886,252.332227440615,0.05405131075248958,101.74035410405597,256.6279400825868,0.016880749906805038
0.017370033960323387,252.460844321333,0.05514985782402675,101.79221243036147,256.8460977608465,0.01722089942482086
0.017712919671720888,252.59933669112,0.05623851995771382,101.84805255385959,257.0736084510598,0.01755787410590723
0.018061335573950087,252.804571474449,0.05734474044729152,101.93080321849784,257.37055967447765,0.017900167368269864
0.018403469642678486,253.053683223862,0.058431016115504185,102.03124507586118,257.7107490010403,0.018236175209967828
0.018751596775743985,253.330318412941,0.05953631976298715,102.14278438409781,258.0806663948913,0.018577952958940335
0.019093128688584485,253.575975305043,0.06062068358625574,102.24183324299332,258.4175340338755,0.018913142300670396
0.019426745755861785,253.751541630337,0.06167991777486116,102.31262158535188,258.6811083147475,0.019240455342292406
0.019758584598173288,253.878619353558,0.06273350609920018,102.36385932335459,258.8949015317227,0.019565917516133433
0.020076562872200585,254.03495522074,0.06374308711923686,102.42689394500236,259.1351039709658,0.019877686118608184
0.020404272471140288,254.210954038817,0.06478356509587041,102.497856668451,259.3979436101735,0.020198894331967407
0.020730131179700486,254.456687205204,0.06581816649554904,102.59693628113824,259.7316077105199,0.020518186104959833
0.021053262229385788,254.613191835236,0.06684410757829987,102.66003894796715,259.9736301300041,0.0208347045499878
0.021384399259879686,254.820235742257,0.067895467650118,102.74351905127804,260.2694134028661,0.021158961235652175
0.021718780242036186,254.984863999346,0.06895712726846488,102.80989716453631,260.5228242255933,0.021486287812691327
0.022061752191135386,255.179066355026,0.07004606320685484,102.88819955434649,260.8087636813159,0.021821912843731656
0.022394897552246187,255.416852748358,0.07110379972838164,102.98407502813794,261.1368869987746,0.022147813971643657
0.022728940857224687,255.713111376013,0.07216438722168837,103.10352650680844,261.5251995608953,0.022474486911125857
0.023046439382799787,255.8296541814,0.07317244504038932,103.15051656594049,261.72561679881426,0.022784881230258805
0.023374489574119986,255.999807447043,0.07421400439783095,103.21912236264774,261.98367227719064,0.023105489947153942
0.023709782671530087,256.140502720506,0.07527855998210803,103.27585069690802,262.21353837338563,0.023433071087758984
0.024045092686999288,256.314429324576,0.07634316928122273,103.34597790366905,262.47753353470074,0.023760561474915204
0.024372108944048686,256.636293181587,0.07738144589735457,103.47575341081588,262.8910608780055,0.02407984824869076
0.024700141650916187,256.793066306696,0.07842294974165889,103.53896433485983,263.13589141944453,0.024400025060000954
0.025027532730649886,256.979042121002,0.07946241641981339,103.61394978318802,263.41059350877646,0.024719473430250008
0.025359674584088585,257.166698416101,0.08051696680448125,103.68961280137192,263.68836220179776,0.025043453071908764
0.02568821162295269,257.286840392304,0.08156007190287479,103.73805404617697,263.89607919610233,0.02536381325840986
0.026012961162845988,257.507615557415,0.08259115169203601,103.82707059274973,264.2061511600471,0.025680379381111198
0.026332357797426088,257.713203217246,0.08360523600682783,103.9099635371936,264.49939949348334,0.025991629767883894
0.026654097833184887,257.915311282592,0.08462676062036201,103.99145350914108,264.7898112221945,0.026305065872160478
0.026983444416111987,258.18386266075,0.08567243602115555,104.09973342481439,265.1505525679934,0.02662581048163995
0.027309703328745487,258.363221992683,0.08670830806876692,104.17205110744979,265.419044936362,0.026943446662956
0.027630754920841587,258.527348134718,0.08772764687367203,104.23822676791829,265.6706539313635,0.027255914689384198
0.027955614367125885,258.691560401134,0.08875907561562468,104.30443715373723,265.92344190373814,0.027571989415158142
0.028273784158573786,258.803752422188,0.08976926470347177,104.3496729766262,266.1211138576019,0.02788145857673658
0.028601932344464488,258.929909001503,0.09081113519367474,104.40053930940601,266.3358047407223,0.028200532972959675
0.028932691705286086,259.015480929467,0.09186129616428332,104.4350419107611,266.5094959860957,0.028522043347370664
0.029263455786417387,259.123199247861,0.0929114721218752,104.47847393673756,266.7060395322858,0.02884345497218764
0.029592688628743286,259.361386249086,0.09395678639625993,104.57451093563148,267.03658699467445,0.029163276098132043
0.029919546651521387,259.547985657637,0.0949945606185804,104.64974781715924,267.3135437228291,0.02948068914372922
0.030246805669153286,259.752877398571,0.09603360799956168,104.73236016710383,267.609572203249,0.029798390692457044
0.030576281661405986,259.888556414558,0.097079694274964,104.7870659463498,267.8349821160657,0.030118142540235957
0.03090248708323129,260.047175761123,0.09811539648925933,104.8510212668848,268.0832802511119,0.030434619653164643
0.031225305207910184,260.262848400462,0.09914034403511483,104.9379804750663,268.3896352760465,0.030747711914975658
0.03154795580076539,260.451025359499,0.1001647596674301,105.01385342495,268.6677227958045,0.031060543772538952
0.03188376737002949,260.571357973442,0.10123096139984361,105.06237153489181,268.8793545343599,0.03138603219888988
0.03221756831040449,260.721722075836,0.10229077938553424,105.12299834097709,269.12154196682053,0.03170946684574061
0.03255399055760839,260.857206040727,0.10335892002040663,105.17762547562114,269.34914906306096,0.03203533558287634
0.032878816686387785,261.065287645798,0.1043902429792812,105.26152397878576,269.64880538148327,0.03234987123885907
0.033199669147381684,261.232521477221,0.10540894954293684,105.3289526596155,269.905354760801,0.03266046201822504
0.033519482836952386,261.366880180544,0.10642435800732382,105.38312608879535,270.12776283490354,0.03296995127980782
0.03383715986955019,261.50946686438,0.10743298258582185,105.44061703971802,270.35820450207086,0.03327727806468454
0.03415969961528649,261.63667748395,0.1084570462785346,105.49190836152864,270.5741077951433,0.03358921253099892
0.03449255917281119,261.894447643893,0.10951387537367552,105.59584129001766,270.92785737628066,0.03391102549785532
0.03482488771203879,262.031398937333,0.11056901848572315,105.65106005153267,271.15661298235403,0.034232221786597766
0.03515572853448359,262.240840031586,0.11161943809698538,105.73550670073548,271.4601078143914,0.03455187775116614
0.035483670748945886,262.396106491723,0.11266065462790319,105.79811013746271,271.7068835402806,0.03486863229308942
0.03580237501975659,262.505603807865,0.11367254068772717,105.84225945533117,271.9039278801818,0.03517636793778902
0.036132277078947186,262.694840355831,0.11471997972565731,105.91855963147106,272.18660311477765,0.0354948162649544
0.036475850253029185,262.875539188926,0.11581082455336765,105.99141740097495,272.46414799156554,0.03582635330053601
0.03682242951098299,263.055720508196,0.11691121369737098,106.06406650890462,272.74207123406984,0.03616067978367132
0.037172884112319386,263.162127404599,0.11802390705661404,106.10696976953432,272.9446226693616,0.03649863098574965
0.037517197385824486,263.371380227693,0.11911710169999273,106.19134050780582,273.2523362854724,0.03683054877890503
0.03785117417534749,263.517636520127,0.12017747800672826,106.2503110449152,273.49208847832625,0.03715239698376603
0.03817542597336199,263.651840436224,0.1212069774654243,106.30442206388553,273.7168617535377,0.037464774292060535
0.038505698115860784,263.751048319397,0.12225559151785799,106.34442268238087,273.90696656372546,0.03778285119029218
0.03882403149627019,263.876806193678,0.12326630000065783,106.39512825729098,274.12156762847656,0.0380893344397865
0.039154314588612786,264.04673917535,0.12431494881884558,106.46364523550112,274.38530826711906,0.03840722331071363
0.039479364681973286,264.187964802942,0.1253469828652652,106.52058740854622,274.6179378099857,0.03871997692310011
0.039798791641139884,264.342178677952,0.12636116346061912,106.58276644295026,274.8626779691208,0.03902722485980173
0.040122653752486984,264.499507693885,0.12738942566414616,106.64620150217443,275.11192985879,0.039338642499810846
0.040442732461651684,264.628749591996,0.1284056755657441,106.69831183549279,275.33105931340646,0.03964632685696742
0.04076499881914629,264.775993452525,0.12942887125078947,106.75768056005808,275.5695865129554,0.03995601853764557
0.041089329785690284,264.900980396867,0.13045862206956665,106.80807529601678,275.7855841409465,0.04026759746486587
0.041406866347004884,265.045434265594,0.1314668006517405,106.8663190958875,276.0201351381133,0.040572555105955616
0.041730038757077884,265.197504385477,0.13249287305372226,106.92763376822431,276.26420652176324,0.04088282987654202
0.04206235835853569,265.34597213646,0.1335479877883508,106.98749596542066,276.5070495054578,0.04120178641437687
0.04239621310389999,265.479017978655,0.13460797660488247,107.0411400489937,276.7343229994922,0.041522113959178764
0.04274881447578069,265.683102459425,0.1357274859606037,107.12342691164017,277.0407401158128,0.04186031717341835
0.04309087705119879,265.778445523001,0.13681353463755613,107.16186923487399,277.2310718418914,0.042188302665183794
0.04342611896554599,265.915244091977,0.1378779277156085,107.21702641788514,277.4629111166674,0.042509643845602595
0.043761337158940886,266.005181883235,0.1389422454796373,107.25328933532037,277.64592433365266,0.042830859072623566
0.04409879569012859,266.130429391407,0.14001367631615827,107.30378913061531,277.86646082406486,0.04315411687022881
0.044437012882208284,266.300755865236,0.1410875159010113,107.37246476486317,278.13436598416126,0.043477996588879485
0.04478205770874149,266.408859888457,0.14218303322525422,107.41605230702588,278.3391968261019,0.043808306449178394
0.045121443004603384,266.548940122547,0.14326058153961574,107.47253265741094,278.57601293222393,0.04413309206605447
0.04545458457939679,266.647717255893,0.1443183060395848,107.51235959757605,278.76807847280406,0.04445179999460396
0.045794071992223184,266.683841380688,0.1453961785753086,107.52692484469341,278.8963804120379,0.04477647436055447
0.046128333631306584,266.830179512071,0.1464574592793984,107.58592837926705,279.13861105550524,0.04509604801302796
0.04646090506598129,266.894136363157,0.14751337358449057,107.6117157816249,279.29427949539263,0.04541390440961516
0.046795539527368986,267.036402071371,0.14857583799939653,107.6690773151768,279.53251457974824,0.045733630609529834
0.04712502693055839,267.143809727963,0.14962196050452287,107.71238408231467,279.7329689557252,0.04604833921040686
0.047469573176649786,267.244593114849,0.15071589483586306,107.75301994390713,279.9305798837783,0.04637732530555034
0.047809617637630586,267.419037216754,0.1517955359994771,107.82335580579522,280.20423913511036,0.04670190683669622
0.048158687381413885,267.57237309,0.15290383243598907,107.885180829888,280.45830735754436,0.047034993693186186
0.04850078030549219,267.713638181939,0.1539899774699377,107.94213891495781,280.6979585321853,0.0473613155708074
0.048841549323939484,267.832939430037,0.15507191910350784,107.99024117819091,280.9143151517849,0.04768626874285938
0.04917545086794189,267.929697309635,0.1561320565057155,108.02925395524484,281.1052609757475,0.048004570784063866
0.049510592722260285,268.042831709869,0.1571961318931764,108.07486974541918,281.3137911827777,0.04832395334077446
0.04984092750810329,268.150176540116,0.15824494483822793,108.11815118097476,281.51503005033703,0.048638655081179545
0.050181229760070986,268.240411369342,0.15932540448822538,108.15453386411869,281.70104508320287,0.048962749047301364
0.050517415155309685,268.289154075116,0.16039279311810825,108.17418692308678,281.8424286531955,0.04928281913343425
0.05085655840455969,268.374441645511,0.161469572934477,108.20857487147005,282.023042111347,0.04960560151911322
0.05119937120149469,268.561468941605,0.16255800356474562,108.28398427725516,282.3116472803649,0.04993177057593597
0.05154612091454329,268.684264383437,0.16365893390367495,108.3334953994018,282.5338959631808,0.050261577219195344
0.05188999246912679,268.800696615096,0.16475072608947755,108.38044087520672,282.74876273814937,0.05058853895143797
0.052237528127709584,268.849196490412,0.1658541518054779,108.39999602493413,282.89321395419205,0.05091887602306629
0.05258181522388799,268.930308867233,0.16694726333584436,108.43270053526837,283.071152676193,0.05124601773272064
0.052924615531511884,269.05118894505,0.16803565431255021,108.48143938264417,283.29061967826294,0.051571640400640925
0.05326998966013018,269.160857854347,0.1691322171709133,108.52565788687271,283.49905396915983,0.051899600723834656
0.053615581451454085,269.245058732057,0.1702294711083667,108.55960768076537,283.6807891089071,0.05222766011079141
0.053964584640269285,269.323766949826,0.17133755623285496,108.59134283416985,283.857712167026,0.05255884864408682
0.05430979758308189,269.394660331462,0.172433607326285,108.61992704564547,284.02542980402677,0.052886332532150686
0.054645070355711686,269.527610870777,0.1734980983793846,108.67353270309728,284.2559661296175,0.05320428412092219
0.054990678309238886,269.608245374015,0.17459540363183346,108.70604453480284,284.4341856648958,0.053531931163154634
0.055331876944109085,269.665160685489,0.17567870929754634,108.72899278838918,284.5862401726519,0.053855292762066555
0.05568705328633208,269.777360158078,0.17680639418410435,108.77423161573707,284.8004663886469,0.05419179030880865
0.056039249545063285,269.844032645532,0.17792461730557593,108.80111396267853,284.9658897292012,0.05452535272314663
0.056390918594804385,270.016307471605,0.1790411665385039,108.87057517255113,285.2427750855059,0.05485830484463577
0.056743408121547184,270.098815475949,0.1801603207859123,108.90384239990263,285.4251427956472,0.05519192256647736
0.05710041466515309,270.203816095213,0.18129381656186105,108.9461786495899,285.63256603835646,0.0555297020591265
0.057458665847363484,270.26834641059,0.18243126406537905,108.97219727274991,285.7976050161156,0.05586854450523239
0.057818014118766886,270.378672062264,0.18357219482708487,109.01668057550485,286.01142994097347,0.056208309301264824
0.058168380929760385,270.493562434046,0.18468460945198922,109.06300437340735,286.22773501275753,0.0565394709902202
0.05851515216674519,270.577350487186,0.18578560812941597,109.0967877164334,286.41022532381845,0.05686712624398409
0.05886662350396209,270.596706534025,0.1869015296250796,109.10459207451888,286.52582097897556,0.05719911298769127
0.05921131015156009,270.642315198205,0.18799590973120325,109.12298148791626,286.6674012635422,0.057524584156777005
0.059568006442014286,270.710203788781,0.18912842045339534,109.1503541676365,286.8358709519901,0.05786128396409575
0.05991826636892999,270.871818875831,0.1902404957213527,109.21551737073507,287.1019886710696,0.058191797951940176
0.06027466997026799,270.973497694035,0.19137207715560084,109.25651427023492,287.3063358382322,0.058527997170970264
0.060628435711206186,271.070428941724,0.19249528338307964,109.29559694930313,287.50500501602636,0.05886159632811347
0.060985653392831685,271.105093653226,0.1936294495222406,109.30957376098073,287.6386149277928,0.05919833776175653
0.061354398188040886,271.167959830014,0.1948002142470298,109.33492140346165,287.80530681326337,0.05954582665605035
0.06172369970119919,271.225697640519,0.19597274655130742,109.35820128865726,287.96675115293067,0.0598937191968383
0.06210551303014489,271.297985226531,0.19718500387071,109.3873476433373,288.1470857830694,0.06025327102028083
0.06248529719204529,271.41790261734,0.19839081858474378,109.4356983353115,288.3775309256261,0.060610783783791186
0.06286159867831488,271.558332705744,0.19958557580364975,109.49231974695599,288.62892363404484,0.06096489208576575
0.06323699817194019,271.657112701374,0.20077746919591008,109.532147841194,288.8358930406653,0.0613180266939938
0.06361323580118648,271.70210666198,0.20197202366876707,109.55028940611034,288.98595684074763,0.061671824650390505
0.06399237749647668,271.730519840375,0.20317579855131346,109.5617455996392,289.1192018433141,0.06202822688672013
0.06436427144894688,271.73449061247,0.20435656185040632,109.5633466149479,289.2244831282923,0.062377692711857564
0.06473464446034519,271.805164157866,0.20553249616159597,109.59184218845158,289.4003748221112,0.06272560798471467
0.06511083694875759,271.857799762408,0.20672690731230534,109.6130648642029,289.55868863598613,0.06307886599860188
0.06548975747794408,271.922340071795,0.20792997999247245,109.63908751694775,289.7304681759319,0.06343455963181745
0.06587207688434418,271.999901472915,0.20914384410779277,109.67036027387933,289.9170998952729,0.0637933156199719
0.06625772898013858,272.093084758966,0.21036828951193998,109.70793177481508,290.1213546262954,0.06415506854790272
0.06663681907076238,272.164279464003,0.21157190054967054,109.73663747988601,290.3004413121702,0.06451053862490412
0.06702425627153219,272.20479669976,0.21280201366211468,109.75297402934322,290.449120752105,0.06487370521167407
0.06740997762383909,272.243310560252,0.21402667895568908,109.7685028178936,290.5952260333584,0.06523513246989585
0.06779714826705568,272.2782529933,0.2152559457479018,109.78259160689855,290.7379420813816,0.06559778641832566
0.06820139354052308,272.327336342907,0.2165394244911608,109.80238201346012,290.900440180672,0.06597629349160443
0.06858996573593719,272.37734160396,0.21777314121160057,109.82254413471668,291.0596941318213,0.06633999039444946
0.06898494766751288,272.432012308753,0.2190272088443534,109.8445873628892,291.2257204208275,0.06670955118372923
0.06937849565788609,272.487026679567,0.2202767237137883,109.86676915720142,291.3917666768856,0.06707763453835718
0.06977088372816638,272.531299008687,0.22152255583692823,109.8846197603026,291.5460485841082,0.06744449818842527
0.07018033067798948,272.623040982598,0.2228225499026166,109.92161012418352,291.7558161491958,0.06782716761758173
0.07060894093625479,272.654025004143,0.22418338747260894,109.93410288167047,291.90583695169266,0.06822759027447296
0.07104889820803219,272.711566772147,0.22558025181050217,109.95730372252969,292.08742311989425,0.06863844701351407
0.07149169190874499,272.761363182377,0.22698612181026534,109.9773816351344,292.2615345236208,0.06905178219984327
0.07192974339347388,272.862106753127,0.22837693527427957,110.01800144286082,292.4890080736821,0.06946052262168739
0.07235077059502598,272.844712538452,0.2297136966392075,110.01098809550383,292.5852377433873,0.0698532205026
0.07278299729296639,272.858291104059,0.23108601640516827,110.01646297315659,292.7177353668491,0.07025620395310553
0.07321682975491259,272.83707297327,0.23246343447184745,110.00790782282246,292.8133384959825,0.07066052129030956
0.07364064175644408,272.880126656792,0.23380903757670995,110.02526706801855,292.97519430637794,0.07105534210413723
0.07404463669423458,272.945066630638,0.2350917215041948,110.05145086547324,293.1551849267873,0.0714315563908478
0.07444919258193179,272.98227682449,0.23637618644763342,110.06645401563438,293.30558692325064,0.07180815127510182
0.0748552118030417,272.814279354759,0.23766529747465737,109.99871743583883,293.23585001875364,0.07218596581371377
0.07529606142210259,272.79576545917,0.2390649950151757,109.99125263313736,293.3362121708732,0.07259602963641133
0.07575462176392019,272.888087901174,0.24052092410044656,110.02847704175336,293.56062178400686,0.07302238904518639
0.07622801938101079,272.93383517028,0.24202396153470923,110.04692234065692,293.7390408473737,0.07346235321188144
0.07672703999651859,273.174614569736,0.2436083519889465,110.14400459451755,294.13449414786163,0.07392592129452269
0.0772316307606336,273.179964179416,0.24521042766501164,110.14616155714053,294.2780983041238,0.0743944453940757
0.07774708417271319,273.190044249866,0.24684699224836434,110.15022584154596,294.42977361530757,0.07487282916495747
0.07827825987305949,273.144409889088,0.24853347509696386,110.13182606728029,294.5256789892596,0.07536556521980972
0.07882526107479469,273.099761353449,0.2502702039124731,110.11382377771065,294.62692134159875,0.07587272791102756
0.07939387390749658,272.970882293869,0.25207554965630163,110.061859740888,294.64309810312653,0.07639965572539256
0.07997623119960579,272.955358414197,0.2539245340587484,110.05560051260423,294.7852992659021,0.07693903274543226
0.08056311190550079,272.84905588724,0.255787880299965,110.01273933373517,294.83062490999396,0.07748230516692511
0.08115548667751658,272.755652317217,0.2576686702011151,109.9750790143019,294.8912700250643,0.0780303642780709
0.08174766744012668,272.588091769613,0.2595488441224022,109.90751860150796,294.8715324437341,0.0785779438368501
0.08236292484423278,272.364945401697,0.2615022863804391,109.81754598596424,294.79771893002055,0.0791465445570499
0.08299370670188978,272.122087264145,0.2635050187785,109.71962558490328,294.70650796165154,0.07972915701571835
0.08365938131503459,271.890580195263,0.2656185356752348,109.62628193473006,294.6367779197845,0.08034362975966773
0.08433321986604278,271.550775603137,0.2677579730746858,109.48927272318485,294.4515268668708,0.08096525418065476
0.08501579371492139,271.195136741373,0.2699251450448754,109.3458791341216,294.2510065430675,0.08159454330576163
0.08569024869928889,270.658216515657,0.2720665396202422,109.1293928991129,293.85098640138966,0.08221595863597489
0.08637312414815969,270.103908119643,0.274234669170407,108.90589575384006,293.4336265085641,0.08284473906651485
0.0870517454113734,269.46606956392,0.2763892916811105,108.64871924817253,292.92356124860174,0.08346921088035238
0.08773229477152558,268.754756485582,0.2785500358995937,108.36191781498667,292.3332280028246,0.08409506555814278
0.08842481655075639,268.018245789584,0.28074879254865154,108.06495670236028,291.7177100057835,0.08473152861405475
0.08912899271995219,267.11851245803,0.28298455188584815,107.7021842230777,290.92651641026623,0.0853782875513026
0.08985733477714508,266.27552919299,0.2852970379174356,107.36229337061357,290.20233856264593,0.08604680214923939
0.09059887378180069,265.289579231878,0.2876514242572172,106.96475834629322,289.32451633633394,0.08672697085002141
0.09133247547080249,264.241549742495,0.2899806096197979,106.54219285617398,288.37538460271827,0.08739940421223112
0.09208763995562469,263.098311860819,0.2923782568591084,106.08123934228223,287.3264144763908,0.0880911304719629
0.09284430201374248,261.885482984914,0.29478065889363236,105.59222673951734,286.20005786018015,0.088783748922755
0.09359794515172398,260.583879012883,0.2971734758567236,105.06742001799444,284.9739946281543,0.08947312744972548
0.09435096237776258,259.303448446448,0.29956430554939617,104.55115041360783,283.7689783552429,0.09016145911339356
0.09511108116171679,257.914958406091,0.3019776826884508,103.99131122933588,282.4455289478735,0.09085580210667428
0.09589945213801888,256.626961062847,0.30448076053820994,103.4719907005399,281.23734603261875,0.09157544356740112
0.09669383412008639,255.17607365272,0.30700292333127427,102.8869928967767,279.85002658991107,0.09230004855620948
0.09751476264744628,253.735468863643,0.30960937140564193,102.30614104582087,278.47842288511964,0.09304831703612759
0.09832270136131259,252.262486456282,0.3121745768221674,101.71223453917291,277.0656155767852,0.09378419914358667
0.09914714120309809,250.712025925888,0.3147921733198364,101.08708885331805,275.5694065616768,0.09453455290453325
0.09994721931292729,249.107771876954,0.3173324213185441,100.44025362078784,274.0054009852946,0.09526219621033734
0.10074885597967329,247.46095768869,0.31987761773546264,99.7762581400798,272.39236607545985,0.09599072634332753
0.10154601107462828,245.702372730891,0.32240858516194476,99.06719668509527,270.6524685932845,0.09671465767667843
0.10237535106767129,243.990470769365,0.32504173963985633,98.37695781420797,268.96908087154515,0.09746726169099099
0.10323149081777828,242.250741022585,0.327759983346446,97.67549878030628,267.25864617005794,0.09824359206578613
0.10409816395578028,240.470358889051,0.3305116705596024,96.95764870406536,265.50288173518874,0.09902886052866723
0.10495248481874529,238.659638394991,0.3332241392995163,96.22756620086037,263.70756047048854,0.09980233388115119
0.10577841037877829,236.678767161774,0.33584645295262106,95.42887891962728,261.71427092255544,0.1005495307473582
0.10660030410007329,234.553311418131,0.33845596551773266,94.57189516379042,259.556765742983,0.10129252628761205
0.10745771221498329,232.326047749665,0.34117823628257193,93.67386245266492,257.291273328793,0.1020670391065653
0.10832640632485328,230.000432916545,0.34393634008140916,92.73617455195095,254.91555326755483,0.10285113548771362
0.10905352452849029,228.230696306554,0.34624494037795667,92.02261675080257,253.1200581443752,0.10350697098038857
0.10952710357463429,227.023464112245,0.34774855384946385,91.53586073005718,251.88868657993913,0.10393389173083425