File: example/data/02 processed data/test_ID_128.csv
Strain,Stress_MPa,Displacement(mm),Force(kN),True Stress (MPa),True Strain
0.0005026923081495,-0.896785355652872,-0.0001099748680377,-0.180791927699619,-0.8967542930225897,-3.4638353613551366e-05
0.0005041018492305,-0.583058502383033,-0.0001054995751056,-0.1175445940804194,-0.5830391283911391,-3.3228764701028703e-05
0.0004937683344789,-0.154122450916748,-0.0001383084844418,-0.0310710861048163,-0.1541157370765575,-4.356267622289181e-05
0.0004877011127753,0.327277109437734,-0.0001575719133509,0.0659790652626471,0.3272608670187324,-4.963018064392957e-05
0.0004645987363084,1.16035968529818,-0.0002309219586331,0.233928512556113,1.160275290800149,-7.27339706048544e-05
0.0004471603406547,2.2604938066518,-0.0002862888648335,0.4557155514210029,2.260289978555463,-9.01737867411611e-05
0.0004245767510766,3.99125168556339,-0.0003579917617442,0.8046363398095795,3.990801658721664,-0.000112759667918
0.0003944267057913,5.80747417869862,-0.0004537181555251,1.170786794425642,5.806644271148189,-0.0001429135677283
0.0003690437445952,7.73779805886954,-0.0005343090573227,1.5599400886680994,7.736495893330457,-0.000168300478998
0.0003486007252751,9.73741815861726,-0.000599215643664,1.96306350077724,9.735580422148113,-0.0001887471482094
0.0003337891324401,11.8617641682668,-0.0006462424509151,2.391331656322587,11.859349813763403,-0.0002035616466883
0.0003373145708379,14.1223302264507,-0.0006350491840021,2.8470617736524613,14.119505541636048,-0.0002000354967903
0.0003502881909569,16.4716918180238,-0.0005938579401243,3.3206930705135984,16.46861092196918,-0.0001870593654175
0.000368397174111,18.5073381122959,-0.00053636191861,3.731079363438854,18.504211614224005,-0.0001689471585187
0.0003922171535714,20.7267431441397,-0.0004607334838232,4.178511417858564,20.72373542616266,-0.0001451234381875
0.0004282357690355,23.0730727529062,-0.0003463743797247,4.651531466985889,23.070555612350883,-0.0001091002440418
0.0004685375480569,25.4908257727847,-0.0002184162313315,5.138950475793396,25.48907219480082,-6.879488011870634e-05
0.0005195361771825,28.0835478668612,-5.649558385808813e-05,5.661643249959218,28.08304815144906,-1.7794042992750554e-05
0.0005578122292013,30.6636255151963,6.503088130172632e-05,6.181786903863574,30.664253572705327,2.0481957582350097e-05
0.0006021351658942,33.2652712594861,0.0002057562053016,6.706278685912398,33.26742701885072,6.480300427191283e-05
0.0006625985362834,35.9473115148142,0.0003977274062873,7.246978001386544,35.95181457968721,0.0001252606289811
0.0007176338245093,38.6342214473874,0.0005724644464045,7.788659043793299,38.6411873428813,0.0001802875098772
0.0007653439583939,41.3222122546458,0.0007239441214881,8.330557990536592,41.331634293275286,0.0002279879053139
0.00081457454634,44.0612160962084,0.000880251238217,8.882741164995613,44.07343182535046,0.0002772060593277
0.0008661956129445,46.6700725180651,0.0010441481246863,9.408686619641925,46.6854206971828,0.0003288114866598
0.0009299949741484,49.3688011193333,0.0012467110965086,9.952750305657592,49.3881865152945,0.0003925878395947
0.0009915174789824,52.050224512556,0.0014420450493563,10.493325261731291,52.07386506958788,0.0004540843052352
0.0010423287777127,54.6387047828482,0.0016033709228253,11.015162884222198,54.66629725859927,0.0005048712469116
0.0010985492693387,57.229676828251,0.0017818709837375,11.537502848575402,57.26179522212468,0.000561061782874
0.0011546417377068,59.7787368399918,0.0019599645708062,12.051393346942348,59.81563895221037,0.0006171212173694
0.0012128241267974,62.2853262386565,0.0021446936561689,12.556721769713151,62.32739960686327,0.0006752660215081
0.0012737469151115,64.7968814651695,0.0023381235090665,13.063051303378172,64.84459898071846,0.0007361458314069
0.0013289546716955,67.2261460451373,0.0025134081362207,13.55279104269968,67.27936391677088,0.0007913114403361
0.0013849524319505,69.6654407595449,0.00269120102503,14.044552857124252,69.72449074555473,0.0008472633411133
0.001434005248006,72.0611054312594,0.0028469437160062,14.527518854941896,72.1257208363857,0.0008962734131042
0.0014865337005247,74.4381001930385,0.0030137215527531,15.00672099891656,74.50875710859685,0.0009487534297594
0.0015436563679898,76.7454272305961,0.0031950860219548,15.471878129688177,76.82265817289326,0.0010058202992538
0.0016093767740987,79.054620232865,0.0034037483113505,15.937411438945585,79.13937047857276,0.0010714724805253
0.0016645459460739,81.3289926529245,0.0035789104323721,16.39592491882958,81.42066798528981,0.001126581053403
0.0017186166309906,83.5623490406764,0.0037505848569826,16.84616956660036,83.66106012128296,0.0011805893991334
0.0017730440608321,85.7760538827601,0.0039233919467294,17.292452462764437,85.88204855331941,0.0012349511328177
0.0018361631432467,87.9401761029963,0.0041237950333954,17.728739502364057,88.05439571290164,0.0012979903273499
0.0018968856929369,90.088376679763,0.0043165891286618,18.161816738640223,90.21085683957234,0.001358632272128
0.0019534028310266,92.2091335367461,0.0044960310420966,18.589361321008013,92.33970837981572,0.0014150710836487
0.0020047151588262,94.3134651592979,0.0046589476828603,19.013594576114457,94.4518593325157,0.0014663095394953
0.0020545054732148,96.3859572959557,0.0048170319310441,19.43140899086467,96.5321917003648,0.001516025663504
0.0021159496680481,98.4266198294366,0.0050121172496399,19.84280655761442,98.58199802126994,0.0015773748960323
0.0021746027370561,100.408391393418,0.0051983407437403,20.24233170491307,100.5727873090066,0.0016359338054847
0.0022343984589193,102.42575934875,0.0053881921606559,20.649033084708005,102.59958286798532,0.0016956300036229
0.0022956633599148,104.389967296971,0.0055827082213166,21.04501740706936,104.57351965245186,0.0017567892397733
0.0023561613075708,106.361229161323,0.0057747892051244,21.442423798922714,106.5546822882536,0.0018171791750801
0.002414960802645,108.275550831706,0.005961477601985,21.82835104767193,108.47885233442278,0.0018758701956079
0.0024777864626232,110.184776298394,0.0061609490724158,22.21325090175624,110.3985850528286,0.0019385761472129
0.0025423691089801,112.13559523949,0.006365998974599,22.606536000281185,112.36043148651696,0.0020030316391672
0.002601183755779,113.990639184036,0.0065527354781855,22.98051285950166,114.22589918578788,0.0020617268736761
0.0026586486927968,115.824805429117,0.006735186653217,23.35028077450999,116.07050674679816,0.0021190718114864
0.0027099298475304,117.637996572953,0.0068980043194962,23.715820109107327,117.89357685909384,0.0021702431035544
0.002773813442933,119.448161055446,0.0071008347348994,24.080749268777915,119.71530488254596,0.0022339861747276
0.0028319216397422,121.183900932485,0.0072853282597686,24.430674427988976,121.4619684909393,0.0022919630228307
0.0028984675419663,122.845231107335,0.0074966114993302,24.76559859123873,123.13528558675456,0.0023583543750056
0.0029634035560342,124.46310263495,0.0077027833439957,25.09176149120592,124.76505926925503,0.0024231353290491
0.0030343932391809,126.062181716438,0.0079281755879865,25.4141358340339,126.37696694845458,0.0024939506953622
0.0031136889459302,127.615033089342,0.0081799394569155,25.727190670811343,127.94381521358235,0.0025730457608277
0.0032047145878337,129.101377386207,0.0084689458699591,26.02683768105933,129.44574040252857,0.0026638333693319
0.0032807621669024,130.565603354165,0.0087103969335023,26.322025636199665,130.92380122222076,0.0027396757637924
0.0033833410687035,131.996126358035,0.0090360849467208,26.61041907377986,132.37178878651036,0.0028419687851709
0.0034722948877238,133.344948732584,0.0093185133221102,26.882341664488933,133.7363114668204,0.0029306662253704
0.0035816663303529,134.566265793871,0.0096657676524576,27.128559184044395,134.97593075734264,0.0030397116603637
0.0036906750989928,135.741186126768,0.0100118704928893,27.365423123156432,136.1692249223751,0.0031483836718638
0.0037969062346036,136.848831746732,0.0103491543484536,27.58872448014117,137.29490093796113,0.0032542752703348
0.0039171449669265,137.872726168574,0.0107309123235788,27.79514159558452,138.33871046348037,0.0033741161675099
0.0040540071983401,138.736085272262,0.011165449908317,27.96919479088801,139.2239752913434,0.0035105080862447
0.0041905336503578,139.489523726736,0.0115989213934732,28.121087983309977,139.99910735537205,0.0036465468476264
0.0043414447350568,140.178322004306,0.0120780640873925,28.259949716068093,140.71157641590636,0.0037968973269221
0.0044830762125161,140.789726981018,0.0125277440283258,28.383208959373228,141.34524750430495,0.0039379821108964
0.0046431862652777,141.293033307805,0.0130360934458438,28.484675514853485,141.8731621851112,0.0040974501772679
0.0048135645841646,141.675938791362,0.0135770446083098,28.561869260338582,142.2817783318012,0.0042671174134799
0.0049933831173038,141.979694020155,0.0141479684510267,28.62310631446325,142.61236306950417,0.004446154246543
0.0051806361843336,142.247394467396,0.0147424969388463,28.67707472462704,142.90789266503205,0.0046325592311612
0.0053739032915843,142.47099143594,0.0153561200043673,28.722151873485505,143.160062819131,0.0048249145862283
0.005567558712964,142.63313684512,0.0159709759672478,28.75484038797619,143.35061413667484,0.0050176193184999
0.0057856088352714,142.769920176862,0.0166632851055738,28.78241590765538,143.51921651840755,0.0052345545564356
0.0059936432110932,142.862089042745,0.0173237942488081,28.80099715101739,143.64158933771552,0.0054414813992944
0.0062010341929384,142.925226872413,0.0179822606161666,28.813725737478457,143.73471307028527,0.0056477256619921
0.006415473150719,142.951588149581,0.01866310430712,28.81904017095553,143.79187803950353,0.0058609342103395
0.0066294901005953,142.958823169674,0.0193426081229772,28.82049875100628,143.82975119937257,0.0060736778580472
0.0068461300370121,142.958307320342,0.0200304399211006,28.820394755780946,143.86020268601203,0.006288982801305
0.0070703097983168,142.937296251708,0.020742210663243,28.816158924344336,143.871102711704,0.0065117323134535
0.0072814612929274,142.879750361203,0.0214126166586316,28.80455767281853,143.8433501479008,0.0067214913120879
0.0075055194679507,142.849014524589,0.0221240013643306,28.798361328157142,143.8444135142694,0.0069440237698294
0.0077350581286437,142.787256189211,0.0228527866120309,28.78591084774494,143.8150000306628,0.0071719480532217
0.0079525834092573,142.747476066715,0.0235434293779791,28.777891175049746,143.8059847664509,0.0073878955165467
0.0081778007795642,142.677383290626,0.0242584945287035,28.763760471390206,143.76750565973634,0.0076114301499118
0.0083989979565434,142.603787281327,0.0249607955656124,28.74892351591552,143.7248908974565,0.0078309260002308
0.0086223170089921,142.534010704677,0.0256698335571371,28.734856558062884,143.68639632074638,0.0080524785426316
0.0088520173123155,142.468393960101,0.0263991320201889,28.72162822235636,143.6529740989536,0.0082803106606945
0.0090765495370761,142.387523178112,0.0271120218338038,28.70532467270738,143.60340148906198,0.0085029665753739
0.0093011795338561,142.323835242193,0.0278252220735803,28.69248518482611,143.57113991053242,0.0087256698480413
0.0095249192940043,142.266378882137,0.0285355958120508,28.68090198263881,143.54501065707393,0.0089474412285727
0.0097674206128912,142.221938139877,0.0293055374995167,28.671942728999205,143.53465950725092,0.0091877535818765