File: example/data/02 processed data/test_ID_117.csv
Strain,Stress_MPa,Displacement(mm),Force(kN),True Stress (MPa),True Strain
6.40698323998073e-05,0.369708863418553,0.00020342171786938816,0.0745333068651803,0.36973255060346893,6.406778001565625e-05
8.71171556426972e-05,1.25237865640991,0.0002765969691655636,0.25247953713223786,1.252487760076244,8.711336116366175e-05
0.0001540810808812,3.20701886038642,0.0004892074317978099,0.6465350022539024,3.2075130013188344,0.00015406921161056935
0.000225618951344,6.64486846867444,0.0007163401705172,1.339605483284767,6.646367676930162,0.0002255935032161428
0.0003093199115731,10.7850207321908,0.0009820907192445924,2.1742601796096652,10.788356753849996,0.00030927208203210916
0.0003891031191841,15.041557525935,0.0012354024034095174,3.032377997228496,15.047410242885727,0.000389027438196543
0.0004757186046938,19.2257943384037,0.001510406569902815,3.8759201386221855,19.234940406460492,0.00047560548647186744
0.0005686250490629,23.5575585755028,0.0018053845307747075,4.749203808821364,23.570953993403595,0.0005684634430988741
0.0006420829471012,28.0539871573271,0.00203861335704631,5.655683810917143,28.072000144079016,0.0006418769000405582
0.0007199161600047,32.598582915631,0.0022857338080149226,6.571874315791209,32.622051162265215,0.000719657144671373
0.0008010589309638,37.2211409996473,0.0025433621058100647,7.503782025528896,37.25095732706573,0.0008007382545006805
0.0008926886018958,41.8043870388084,0.002834286311019165,8.427764427023774,41.841705338627186,0.0008922903923929658
0.00097921303611,46.389388557119,0.00310900138964925,9.352100733115192,46.4348136511313,0.0009787339197706844
0.0010636421913586,50.9497447520093,0.003377063957563555,10.271468542005076,51.00393705016649,0.001063076924795022
0.0011500795008784,55.5244114036708,0.0036515024152889196,11.193721338980033,55.58826889102449,0.0011494186660756492
0.0012493094586877,60.195281732547,0.003966557531333447,12.135368797281476,60.27048426738384,0.0012485297209807323
0.0013396445792901,64.7129946914302,0.004253371539246067,13.046139729792328,64.7996871039782,0.0013387480560830482
0.0014324383444705,69.0978531109203,0.004547991743693837,13.930127187161531,69.19683152523697,0.0014314133833442406
0.0015202939482285,73.3382890509581,0.004826933285625488,14.784999072673152,73.44978480797569,0.0015191394713319193
0.0016009203918216,77.5650834319638,0.00508292224403358,15.637120819883904,77.68925895572337,0.0015996402848220358
0.0016805726916174,81.7259616539223,0.005335818295885245,16.475953869430736,81.86330807327404,0.0016791621095008516
0.0017626019116576,85.7961188385323,0.00559626106951288,17.29649755784811,85.9473432416099,0.0017610503518288476
0.0018406647469176,89.8182674316051,0.00584411057146338,18.10736271421159,89.98359275009567,0.0018389727994495204
0.0019163861785852,93.6186164835241,0.00608452611700801,18.873513083078457,93.79802590621138,0.0019145522532247514
0.0019998122713054,97.2746251096579,0.006349403961394645,19.610564422107036,97.46915609863883,0.001997815308668891
0.002067194127627,100.834596856708,0.006563341355215725,20.328254726312334,101.04304154319182,0.0020650604218629444
0.0021538427665219,104.364868852669,0.006838450783707033,21.03995756069807,104.58965437052635,0.002151526572406231
0.0022129991865812,107.919606811652,0.007026272417395309,21.756592733229045,108.15843281374234,0.0022105541105176593
0.0022868286080684,111.376864889035,0.00726068083061717,22.453575961629458,111.63156468994022,0.002284217795090655
0.0023566019339225,114.699312311407,0.007482211140203937,23.12338136197965,114.96961293261964,0.002353829502409026
0.0024274619103733,117.932091658521,0.007707191565435227,23.775109678357836,118.21836731903271,0.0024245203840437914
0.0025077220106568,121.006376830721,0.00796201738383534,24.394885569073352,121.30982718532923,0.0025045829226935665
0.0025745589143523,124.233904852654,0.008174224553068552,25.04555521829505,124.55375235985719,0.0025712504149515663
0.0026531511204315,127.473547953817,0.008423754807370013,25.69866726748951,127.81175454039605,0.002649637727999608
0.0027265498748178,130.648924245039,0.008656795852546514,26.338823127799866,131.00514505308442,0.0027228395803797207
0.0028001076953047,133.801563848406,0.008890341932592423,26.974395271838652,134.17622263698175,0.0027961946965954373
0.0028709380527746,136.893199264591,0.009115228317559355,27.597668971741545,137.28621115952575,0.0028668247808749992
0.0029385683958443,139.983507413823,0.009329954656805651,28.220675094626717,140.3948585246487,0.002934259243497675
0.0030160982368581,142.999208927264,0.009576111902024467,28.828640519736425,143.4305085891816,0.0030115589375955334
0.0030976284744038,145.978566470192,0.009834970406232064,29.429279000390707,146.4307538343427,0.0030928407079208785
0.0031919346757438,148.934822690971,0.010134392595486564,30.025260254499756,149.41021291594407,0.0031868512666574575
0.0032741259459955,151.901643763329,0.010395349878535711,30.623371382687125,152.39898887641385,0.003268777666421285
0.0033490112345587,154.817886141826,0.010633110669723871,31.211285846192123,155.3363729818256,0.003343415785767638
0.0034323619243274,157.67127417548,0.010897749109739494,31.786528873776767,158.21245905352012,0.003426484814543366
0.0035139088427072,160.389381384263,0.01115666057559536,32.33449928706742,160.9529750497855,0.0035077494897490505
0.0036159202749517,163.056090035214,0.011480546872971648,32.87210775109914,163.6456878571267,0.0036093985518600067
0.0037106069693095,165.62665677213,0.011781177127557661,33.39033400526141,166.2412321990521,0.003703739649975297
0.0038255472113665,168.153918978365,0.012146112396088636,33.89983006603838,168.79719973419301,0.003818248414306199
0.0039376785769622,170.542941734467,0.012502129481854985,34.38145705366855,171.21448502258693,0.0039299462124052775
0.0040710863539751,172.786797051426,0.01292569917387094,34.83381828556748,173.4902270230491,0.004062821904522724
0.0042096108556517,174.754549898114,0.013365514466694145,35.23051725945978,175.49019854843962,0.004200775231554039
0.004379927083235,176.492722889018,0.013906268489271125,35.58093293442603,177.2657481459935,0.0043703631187499425
0.0045515600602195,177.970104686498,0.014451203191196912,35.878773104798,178.78014630690214,0.00454123303492231
0.0047561216820818,179.218244245008,0.015100686340609714,36.13039803979361,180.07062802228631,0.004744847070172083
0.004975258291528,180.299645714667,0.0157964450756014,36.34840857607687,181.19668302196845,0.004962922592600859
0.0052317779230928,181.136770507727,0.01661089490581964,36.51717293435777,182.08443786472964,0.005218139720325527
0.0054999452146362,181.731696842547,0.017462326056469937,36.63711008345747,182.73121121894388,0.005484875744875769
0.0057858861740455,182.175425395998,0.01837018860259446,36.7265657598332,183.22947167104755,0.005769212219456492
0.0060832165348351,182.567163588343,0.01931421249810144,36.80554017940995,183.67775917660154,0.006064788469972952
0.0063922626195212,182.853406984499,0.02029543381697981,36.863246848075,184.0222539828181,0.0063719187583334115
0.0067103271448581,183.083748241993,0.021305288684924466,36.90968364558579,184.3123000876036,0.006687913114111123
0.0070369791473079,183.242597555191,0.022342408792702582,36.94170766712651,184.53207189308543,0.007012335154845031
0.0073646267131688,183.32135882862,0.02338268981431094,36.95758593984979,184.67145220494365,0.007337640265600579
0.0076947149474963,183.415500385326,0.02443071995830075,36.976564877681724,184.8268303777435,0.007665261621910663
0.0080332643541233,183.495350117467,0.025505614324341477,36.99266258368135,184.96941677271303,0.008001169455989972
0.0083704591128,183.562238217453,0.02657620768314,37.006147224638525,185.09873842710624,0.008335621091736977
0.0087264340884231,183.607066740512,0.027706428230743343,37.01518465488722,185.20930170659176,0.008688578830672014
0.0090628412928924,183.619171087842,0.02877452110493337,37.01762489130895,185.28328249374357,0.0090220201981039
0.0094216448425851,183.593074048104,0.02991372237520769,37.01236372809777,185.32282278734365,0.00937753796991376
0.0097703019585033,183.576092177369,0.031020708718247976,37.00894018295759,185.36968603030394,0.009722881184991306
0.0101197591420535,183.551602466499,0.03213023527601986,37.004003057246194,185.4091004735979,0.010068897231870887
0.0104822510099611,183.511696913156,0.03328114695662649,36.995958097692245,185.4353125834636,0.010427693145143494
0.0108312945053388,183.503566716684,0.03438936005445069,36.99431905008349,185.49114789057248,0.0107730561885184
0.0111882229551968,183.50261652114,0.035522607882749836,36.994127490661825,185.55568470764047,0.01112609773978238
0.0115538105529431,183.515601416173,0.03668334850559434,36.99674524550048,185.6359059084449,0.011487574977780116
0.0119156660612205,183.531450007653,0.037832239744375086,36.999940321542844,185.7183494776758,0.01184523346120853
0.012286157762158,183.501870028322,0.03900855089485165,36.993976997709716,185.756402953141,0.012211295482015237
0.0126553328309126,183.477274328206,0.0401806817381475,36.98901850456633,185.7992403017381,0.01257592337329994
0.0130123654376739,183.472679197698,0.041314260264614634,36.988092126255914,185.86009274724756,0.012928431941969461
0.013381717857653,183.468806514921,0.04248695419804827,36.98731139340807,185.923934319384,0.013292973495968363
0.0137550631294564,183.471700451546,0.04367232543602407,36.98789481103168,185.99536527372572,0.013661320890703918
0.0141357594028521,183.463191666181,0.044881036104055416,36.98617943990209,186.0565832028535,0.014036781219867723
0.0145128889007115,183.477115148785,0.04607842225975901,36.98898641399506,186.13989813676238,0.014408584885839388
0.0148925030289362,183.448684468339,0.047283697116872435,36.98325478881714,186.1806945574381,0.014782698539190108
0.0152740784966774,183.411888381339,0.048495199226950746,36.97583669767794,186.2133359616994,0.015158604118275808
0.0156544999072417,183.372744996271,0.0497030372054924,36.96794539124823,186.24335361580577,0.015533232176651413
0.0160395664183273,183.361762132493,0.05092562337818918,36.96573124591059,186.30280529479865,0.01591229172314381
0.0164285775832549,183.328758504971,0.0521607338268343,36.95907771460215,186.34058923731172,0.01629508854170746
0.0168138788459875,183.249570849712,0.05338406533601031,36.94311348330194,186.33070693255826,0.016674090333772543
0.0171870218924203,183.15838529005,0.05456879450843445,36.92473047447408,186.30633246781045,0.01704099582578432
0.0175692438605087,183.060958629914,0.05578234925711512,36.905089259790664,186.27720125342145,0.017416688953277935
0.017938319003475,183.006363577226,0.05695416283603312,36.894082897168765,186.28919010674022,0.017779325922792983
0.018321852925381,182.97897899108,0.058171883038084675,36.88856216460173,186.33149293259095,0.018156030168869967
0.0186963947311926,182.959469194702,0.059361053271536506,36.88462898965192,186.38015165057564,0.018523765519756763
0.0190829254427271,182.952261753902,0.060588288280658535,36.883175969586645,186.44352612453002,0.018903130166697254
0.0194694801095381,182.923594439753,0.06181559934778347,36.877396639054204,186.48502172326297,0.019282374448464205
0.0198563792193645,182.858604603248,0.06304400402148228,36.8642946880148,186.48951439977392,0.019661812695371563
0.020242543615372,182.774477066927,0.0642700759788061,36.84733457669248,186.47429739073107,0.020040386887335677
0.020615301589845,182.663955345519,0.06545358254775786,36.82505339765663,186.42962787456085,0.02040568227475705
0.0209886572262287,182.5674911616,0.06663898669327611,36.80560621817856,186.39933765424337,0.02077142964601742
0.0213834996696366,182.51129638311,0.06789261145109621,36.794277350834975,186.4140266290232,0.021158080479455218
0.0217690232043471,182.461016524167,0.06911664867380204,36.78414093127207,186.43301462677036,0.021535461546183847
0.0221608171464024,182.456694619073,0.07036059443982762,36.78326963520512,186.5000840656633,0.021918834731622434
0.0225478282671839,182.439148400582,0.07158935474830888,36.77973231755733,186.5527549879296,0.02229738365229233
0.0229353471317841,182.411432862039,0.07281972714341452,36.774144864987065,186.595102395536,0.022676285687662
0.0233327688886551,182.370534279416,0.07408154122147995,36.76589971073027,186.62574380785819,0.023064721356239836
0.0237241654751734,182.279993713203,0.07532422538367554,36.74764673258173,186.6044344468686,0.023447120677643596
0.0241060106224294,182.204226905829,0.07653658372621334,36.73237214421513,186.59644393507241,0.02382004725733584
0.0244946220958538,182.098881073419,0.07777042515433581,36.71113442440127,186.5593243493902,0.024199439386654954
0.0248981697223895,182.04135934086,0.07905168886858666,36.69953804311738,186.57385600222324,0.02459326104286708
0.0253064079825287,181.964766787307,0.08034784534452862,36.684096984321094,186.5696414140723,0.02499150253542248
0.0257163408806309,181.913507415648,0.0816493822960031,36.67376309499464,186.59165718314,0.025391237646881344
0.026120674250209,181.863112744148,0.08293314074441357,36.66360352922024,186.6134998702669,0.025785356060605318
0.0265116161830936,181.820563232358,0.08417438138132217,36.655025547643376,186.64092021896818,0.026166273713936445
0.0269102063225471,181.763392773972,0.08543990507408704,36.64349998323276,186.65468317540572,0.02655449413712566
0.0272894845848688,181.691860201769,0.08664411355695843,36.629079016676634,186.6501374199413,0.026923765214626524
0.0276936771012752,181.622130620057,0.08792742479654876,36.61502153300349,186.65191525989448,0.02731714315480105
0.0281069146257411,181.551547789716,0.089239453936728,36.60079203440675,186.65440164361272,0.027719164179305544
0.0285175125099025,181.505987964327,0.09054310221894044,36.591607173608324,186.6820872467219,0.028118457199653914
0.0289297111575065,181.392271891315,0.09185183292508313,36.568682013289106,186.63989792333462,0.028519146605804707
0.0293311756577181,181.269854046468,0.09312648271325497,36.54400257576795,186.5867119769539,0.028909247304773053
0.0297290427811664,181.154965740219,0.09438971083020331,36.52084109322816,186.54052946673073,0.029295702372805706
0.0301289676816383,181.068369569654,0.0956594723892016,36.50338330524225,186.52377262458506,0.029684005744655097
0.0305347052490374,181.029015003948,0.09694768916569374,36.495449424795915,186.55668261861712,0.030077798849247807
0.0309386801793322,180.945688402153,0.09823030956937974,36.478650781874045,186.5439091854563,0.03046972720332825
0.0313389839643123,180.833919652736,0.09950127408669154,36.45611820199158,186.50107096093683,0.030857942424748475
0.0317158400826154,180.720218160089,0.1006977922623039,36.43319598107394,186.45191169894974,0.03122328038678621
0.0321097449930124,180.657812380507,0.10194844035281435,36.42061497591021,186.45868866704055,0.03160500345294886
0.0325063106163539,180.572801011207,0.10320753620692363,36.40347668385933,186.44255656974235,0.031989157811470915
0.0329166312488654,180.542817162006,0.10451030421514765,36.39743193986041,186.48567849915906,0.03238648141003507
0.0333401086357669,180.432234928952,0.1058548449185599,36.37513856167672,186.4478652428775,0.03279637954578614
0.0337438285657631,180.34346073023,0.10713665569629784,36.35724168321437,186.4289395520673,0.03318699738946805
0.0341501387014164,180.284222597655,0.10842669037699706,36.345299275687246,186.44095380504197,0.033579967384364806
0.0345562989362321,180.242272163678,0.1097162491225369,36.336842068197484,186.47077800151175,0.0339726381206711
0.0349770958603888,180.215270374707,0.11105227935673444,36.33139850754093,186.518677162109,0.03437929686898
0.0353941568431968,180.157518844948,0.11237644797714984,36.31975579914151,186.53404232342726,0.03478218208862815
0.0358207559540855,180.070799914588,0.11373090015422146,36.30227326278094,186.52107209278543,0.03519411338005068
0.0362334752153076,179.960704105684,0.11504128380860162,36.28007794770589,186.48130581762658,0.03559248062398827
0.0366522209778817,179.87087311205,0.11637080160477438,36.26196801938928,186.46354010083738,0.03599650267791946
0.0370699526985273,179.794167294713,0.11769709981782418,36.24650412661414,186.45912857179908,0.03639938376931969
0.0374909015204449,179.738864061777,0.11903361232741255,36.23535499485425,186.47743611371374,0.03680520346541477
0.0379147460023157,179.643731634687,0.12037931855735234,36.2161762975529,186.45487809052432,0.03721364842485586
0.0383330709829986,179.496610066736,0.12170750037102056,36.18651658945398,186.3772663616318,0.037616610906425936
0.0387648266196451,179.380993430549,0.12307832451737319,36.163208275598684,186.33466653974395,0.03803234060637257
0.0391953358418153,179.27923619845,0.12444519129776357,36.142694017607525,186.3061460707124,0.03844669814421849
0.0396193735439945,179.226640392355,0.12579151100218253,36.13209070309877,186.32748760709487,0.03885465918677389
0.0400346982666437,179.123895528215,0.12711016699659375,36.11137733848815,186.2950666380329,0.03925407631465151
0.0404526571066606,179.008178644192,0.1284371863136474,36.08804881466911,186.2495351141733,0.039655865678629255
0.0408677716573408,178.867274773038,0.12975517501205702,36.05964259424446,186.17718171543336,0.04005476106297061
0.0412871840048798,178.762809191092,0.13108680921549337,36.03858233292415,186.14342218739384,0.04045762479035163
0.0417083595865916,178.648923394489,0.13242404168742833,36.01562295632898,186.10007693118382,0.04086201892239608
0.0421231468347627,178.581304477142,0.13374099120037156,36.00199098259183,186.1037109875761,0.04126011949086425
0.0425432168773363,178.49636139464,0.13507471358554277,35.98486645715943,186.09017080926756,0.041663128869795396
0.042962393168738,178.409113847806,0.13640559831074314,35.96727735171769,186.07399634182158,0.04206511896277545
0.0433947671784379,178.335795368544,0.1377783857915403,35.952496346298474,186.0746356881435,0.04247959643011164
0.0438343115189936,178.260798019628,0.13917393907280468,35.93737688075701,186.07473737164477,0.042900771423828796
0.0442675560090071,178.220057693421,0.14054949032859754,35.92916363099368,186.109424079293,0.04331573632852789
0.0447016894725405,178.165310876648,0.1419278640753161,35.918126672732235,186.12960127823456,0.0437313800444155
0.0451363736675825,178.041155809396,0.14330798639457443,35.893097011174234,186.07728794621718,0.04414737801954811
0.04558538733162,177.886872293889,0.1447336047778935,35.861993454448026,185.9959142686164,0.044576907839648544
0.0460198574219391,177.758320855299,0.14611304731465663,35.83607748442828,185.93873343662315,0.044992349613527785
0.0464563991319408,177.647922941845,0.14749906724391204,35.81382126507595,185.90080575499164,0.04540959852134016
0.0468868155475869,177.634937718285,0.1488656393635884,35.81120344400625,185.9636742778893,0.04582082246081965
0.0473243549074929,177.565825690148,0.15025482683128993,35.797270459133834,185.96901384455057,0.0462386784750029
0.047775554565554,177.448139346031,0.15168738574563392,35.773544892159855,185.92582260991335,0.04666939747126324
0.048217144621332,177.319231345538,0.1530894341727291,35.747557039260464,185.86905836746922,0.04709076350224504
0.0486528734972174,177.224112090839,0.15447287335366522,35.72838099751314,185.84657439705126,0.04750636282732675
0.049080342375732,177.129275557564,0.1558300870429491,35.70926195240491,185.8228410466946,0.0479139159720231
0.0495191714969664,176.9979181808,0.1572233695028683,35.68278030524929,185.76270844580108,0.04833212737894434
0.0499573568374308,176.854628683364,0.15861460795884277,35.65389314256618,185.68981847685015,0.048749550808940396
0.0503904652598518,176.71807803693,0.15998972720002946,35.62636453224509,185.62298420903767,0.04916196671834659
0.05082783067662,176.656097403288,0.1613783623982685,35.61386923650286,185.6351436100948,0.049578263705604336
0.0512663751525992,176.628742009162,0.16277074110950246,35.608354389047065,185.68385735973538,0.04999550902327427
0.0517158583189965,176.596372830919,0.16419785016281388,35.601828762713275,185.7292058278915,0.050422981177900936
0.0521743536424123,176.520510140432,0.16565357281465903,35.586534844311096,185.7303536616379,0.05085883598445625
0.0526373777398929,176.42766834823,0.16712367432415995,35.56781793900317,185.71435817084432,0.05129880322527518
0.053110482283799,176.309536677194,0.1686257812510618,35.54400259412231,185.67342120135288,0.051748149095070854
0.0535619370707951,176.210177336405,0.17005915019977444,35.523971751019246,185.64833576613117,0.052176744248032855
0.0540207420581966,176.1001131913,0.17151585603477418,35.501782819366085,185.61317198242645,0.05261212929763734
0.0544559230136772,175.984880588177,0.1728975555684251,35.478551926576486,185.56829969705794,0.053024921119210755
0.054905821624054,175.804986926407,0.17432598365637145,35.442285364363656,185.45770417920747,0.05345149434055864
0.055355565847002,175.662006964501,0.17575392156423134,35.4134606040434,185.38587675784095,0.053877739385297996
0.0558069920788794,175.549794108411,0.1771871998504421,35.39083849225566,185.346700077668,0.05430539592653674
0.0562631632344848,175.501904068388,0.17863554326948922,35.38118386018702,185.3761963449506,0.0547373618454253
0.0567257122927164,175.474592102475,0.18010413652937454,35.37567776785896,185.42851332876177,0.05517517680127058
0.057186142949795,175.412208068288,0.18156600386559912,35.36310114656686,185.44335567402032,0.055610796350134745
0.057650396798475,175.297964145366,0.1830400098351581,35.34006957170578,185.40396133631117,0.05604984102088042
0.0581065303567387,175.135181293572,0.18448823388264535,35.30725254878412,185.31167902193988,0.05648101868545638
0.0585636127163634,175.005365446301,0.1859394703744538,35.281081673974285,185.2543118915838,0.05691290682657775
0.0590219557315829,174.85706776536,0.1873947094477757,35.251184861496576,185.1774738783615,0.057345798917652194
0.0594754469461901,174.770278092067,0.18883454405415356,35.23368806336071,185.1648184945026,0.057773924268158236
0.0599357560837933,174.674192653483,0.19029602556604372,35.21431723894218,185.14342245849568,0.058208298819149344
0.0604030542474604,174.590079994766,0.19177969723568675,35.19736012694483,185.1358540677583,0.058649075707216405
0.0608701987580408,174.527219126304,0.19326288105677952,35.184687375862886,185.15072564321028,0.059089513559784757
0.0613428194407271,174.471426043145,0.19476345172430853,35.17343949029803,185.1739952284758,0.05953491718934187
0.0618098827570173,174.378812671455,0.1962463777535299,35.15476863456533,185.1571466379855,0.05997488867452148
0.0622861209634205,174.291663948837,0.19775843405886007,35.13719945208554,185.14761561247008,0.060423303636509114
0.0627617320216612,174.169020953108,0.19926849916877432,35.11247462414658,185.10017037264205,0.060870927501086074
0.0632410057702145,174.059652707578,0.20079019332043105,35.09042598584773,185.06736020881948,0.06132179592957178
0.063721361192088,173.952457812599,0.2023153217848794,35.06881549501996,185.03694520712705,0.061773478044405125
0.0641982318693392,173.815853631818,0.20382938618515198,35.041276092174506,184.97452410584057,0.062221681714120236
0.0646716691423358,173.703375622706,0.20533254952691615,35.01860052553753,184.93706285988455,0.06266645974454527
0.0651531413790779,173.580786458563,0.20686122387857234,34.993886550046305,184.89011997938928,0.06311858354605712
0.0656295180018239,173.493443466653,0.20837371965579088,34.976278202877246,184.8797345378461,0.06356572124786417
0.0661068363344109,173.40488307679,0.20988920536175462,34.95842442828086,184.868131301935,0.0640135424238675
0.066591383869464,173.310579055388,0.2114276437855482,34.939412737566215,184.85157035390444,0.06446794102447614
0.0670680069426244,173.18449767466,0.21294092204283244,34.91399473121146,184.799636767059,0.06491470687955177
0.0675439507033167,172.961041588082,0.2144520434830305,34.86894598415733,184.6435136547017,0.0653606368921467
0.068008441553895,172.779787618875,0.21592680193361663,34.8324051839652,184.53027170684766,0.06579564458344682
0.0684696742932713,172.578555889257,0.21739121588113638,34.79183686727421,184.39495340099754,0.0662274138050649
0.0689489726903717,172.476359994656,0.21891298829193015,34.771234174922654,184.36842782966224,0.0666758972182796
0.0694156381442844,172.460979085612,0.22039465110810297,34.76813338365938,184.43246800382784,0.06711236671366572
0.0699076856612462,172.422822831972,0.22195690197445667,34.76044108292556,184.47650333133424,0.06757236966895826
0.0703921147372699,172.396454553629,0.22349496429083193,34.75512523801161,184.5318055628666,0.06802504371416046
0.0708798962329209,172.259545624434,0.22504367053952384,34.727524397885894,184.469284343424,0.06848064347130427
0.0713660385844185,172.150220040553,0.22658717250552873,34.70548436017548,184.43589928628325,0.06893450579583166
0.0718407982480208,172.036484130734,0.22809453443746602,34.68255520075598,184.39572247846888,0.06937754252304677
0.0723368083337328,171.995066850041,0.22966936645960162,34.67420547696827,184.43664103511998,0.06984020018073074
0.0728251847047105,171.9370743375,0.23121996143745582,34.662514186440006,184.458423533716,0.0702955283853142
0.0733338887705803,171.850283897643,0.23283509684659243,34.64501723376483,184.45273350218542,0.07076958837619167
0.0738342937335955,171.74196747218,0.2344238826041657,34.62318064239149,184.4224143449065,0.07123569529427307
0.0743432652176492,171.619464116304,0.2360398670660362,34.59848396584689,184.37821545361322,0.07170955881775787
0.07485958193955,171.501213299277,0.23767917265807123,34.574644601134246,184.33972242898645,0.07219003159631986
0.0753633577087065,171.394710893444,0.23927866072514314,34.553173716118316,184.31159179988694,0.07265861163896115
0.0758824846603895,171.300347126959,0.24092688879673663,34.534149980794936,184.2990430901399,0.07314124077556242
0.0763928933795298,171.211477670892,0.2425474364800071,34.51623389845183,184.29081782995618,0.07361553763730813
0.0769141473869812,171.112960987628,0.2442024179536653,34.49637293510581,184.2739684888532,0.07409968040725658
0.0774108051311962,170.971860985526,0.24577930629154793,34.467927174682046,184.2069303991945,0.07456076010875033
0.0779099518716573,170.77168916401,0.2473640971925119,34.42757253546442,184.07650324781966,0.0750239364111758
0.078406878540753,170.576350029711,0.24894183936689077,34.388192165989736,183.95070918841552,0.07548483962436235
0.0788986965018718,170.418633370002,0.2505033613934429,34.3563964873924,183.86444140252556,0.07594079540116945
0.07940591382227,170.342537471887,0.2521137763857072,34.34105555433242,183.86874232264645,0.07641080999253853
0.0799109259688311,170.281699926394,0.25371718995103876,34.32879070516103,183.88906824305877,0.07687856178001372
0.0804239205258485,170.247135699137,0.255345947669569,34.321822556946024,183.93907781035776,0.07735348312611155
0.0809224869614681,170.132180670507,0.25692889610266123,34.29864762317422,183.89969984254228,0.07781483114763692
0.0814373989633786,170.03999305488,0.25856374170872704,34.28006259986381,183.88760780902038,0.07829108120665293
0.081954308323291,169.875658895988,0.2602049289264489,34.24693283343118,183.797701021772,0.078768950626239
0.0824744935708067,169.757308456892,0.2618565170873113,34.223073384909426,183.75795650181738,0.07924961809571247
0.0830078682206528,169.663535867915,0.26354998160057264,34.20416883097166,183.74694429508887,0.07974223320082102
0.0835202479567884,169.57993492997,0.2651767872628032,34.18731488188195,183.74329314381714,0.08021522936631038
0.0840314117370426,169.503496737434,0.2667997322651102,34.1719049422667,183.7471148626458,0.08068688021480945
0.0845322714027558,169.266659786259,0.2683899617037496,34.12415861290982,183.575155010749,0.08114880778328559
0.0850428422302328,169.112147412201,0.2700110240809891,34.093008918299724,183.49392508379267,0.08161947213935598
0.0855678341760745,168.989054756119,0.2716778735090365,34.06819343883359,183.44908217106217,0.08210319956388709
0.0860999150734899,168.979227401961,0.2733672303583304,34.06621224423534,183.52832453045377,0.08259322010984399
0.0866359717556425,168.967218781301,0.2750692103241649,34.06379130631028,183.60585797526724,0.08308665946092098
0.0871734260628696,168.914052448002,0.27677562774961095,34.0530729735172,183.63886911005758,0.08358114100904354
0.087704114143798,168.792903955394,0.27846056240655864,34.02864943740743,183.596736070561,0.08406915753562953
0.0882597338572529,168.659254817362,0.28022465499677796,34.001705771180184,183.54507576010496,0.08457984591498002
0.0888020374383203,168.511491369153,0.2819464688666669,33.97191666002124,183.4756551345037,0.08507804362294988
0.0893397138759867,168.390846540569,0.28365359155625774,33.94759466257871,183.4348365898386,0.08557174560379027
0.089877291792289,168.305508724392,0.28536040144051755,33.93039055883743,183.43235204226383,0.0860651135665113
0.0903908244966641,168.218989053814,0.28699086777690846,33.9129481932489,183.42444217038354,0.08653618655981417
0.0909364986307963,168.124739020439,0.28872338315277823,33.8939473865205,183.41341412017414,0.08703650041893042
0.091478893866421,167.980485498013,0.29044548802588666,33.86486587639942,183.3471545025156,0.087533560005897
0.0920297093102782,167.82644620363,0.29219432706013326,33.83381155465181,183.27146526232713,0.08803808328072146
0.0925796937779423,167.668706906809,0.29394052774496676,33.802011312412695,183.19142444838496,0.08854159157699272
0.0931269008474171,167.546171902779,0.29567791019054923,33.777308255600246,183.14922764093342,0.0890423057005197
0.0936699373655757,167.432684391077,0.29740205113570284,33.75442917324112,183.1160934509394,0.08953895588752508
0.0942207909535921,167.323276252916,0.2991510112776549,33.732372492587864,183.08860768641216,0.0900425035213498
0.0947638831812904,167.198871692455,0.300875329100597,33.707292533198924,183.04328603756235,0.09053870821867714
0.0953101440534581,167.033010725234,0.3026097073697294,33.67385496220717,182.95295103913884,0.09103755974305737
0.095856403435101,166.904261638211,0.30434408090644566,33.64789914626334,182.90310387684102,0.09153616117852188
0.0964008505839386,166.790308337018,0.30607270060400504,33.624926160742824,182.8690359298639,0.09203286124329112
0.0969469035791592,166.700886813866,0.3078064188638304,33.60689878167538,182.8620216143702,0.09253077864418269
0.0974931700551892,166.639580819373,0.3095408149252257,33.5945394931856,182.88580181012156,0.09302864276348731
0.098040466213276,166.562609191959,0.31127848022715127,33.579022013098935,182.8924850508384,0.09352719688297997
0.0986052421685125,166.418518275027,0.3130716438850272,33.549973284245446,182.82825657086104,0.09404141359578537
0.0991780756611997,166.270009585532,0.31489039022430904,33.520033932443255,182.7603491763943,0.0945626965639577
0.0997340620764325,166.085892248406,0.3166556470926732,33.48291587727865,182.65031293592818,0.09506838882654442
0.100286441171256,165.952986349206,0.3184094507187378,33.456122047999926,182.59582075190988,0.09557054697063051
0.100836773515205,165.848025629307,0.32015675591077586,33.43496196686829,182.57160542763333,0.09607059381193798
0.101403701949429,165.763130636981,0.3219567536894371,33.417847136415375,182.57212573029767,0.09658545897136445
0.101972848549617,165.689496693049,0.3237637941450339,33.40300253331868,182.58532664559155,0.09710207208746335
0.102550925122894,165.620730041235,0.32559918726518844,33.38913917631297,182.60528912649272,0.09762651785977061
0.103123712243424,165.546157838259,0.32741778637287117,33.37410542019301,182.6178921821761,0.0981458937674429
0.103695404191952,165.423097753337,0.32923290830944757,33.349296507072744,182.57671273755406,0.0986640077869011
0.104272084430934,165.27361200726,0.3310638680682154,33.319160180663616,182.50703603268644,0.09918637077917007
0.104840796891663,165.117165669728,0.33286953013103,33.28762059901717,182.428180899035,0.09970124937872113
0.105419521802795,164.972737589663,0.3347069817238741,33.258503898076064,182.36408469686324,0.10022492065803831
0.105996355224033,164.863481356384,0.3365384278363048,33.23647784144701,182.33840948970604,0.10074660763723839
0.106583128551272,164.722651169266,0.3384014331502886,33.20808647572402,182.2793066741462,0.10127700516220656
0.107162806663379,164.554710732153,0.3402419111562283,33.17422968360205,182.18885538389097,0.10180071306936514
0.107743644901658,164.401313036434,0.34208607256276413,33.143304708145095,182.11450972959787,0.10232519413824585
0.108332971396953,164.286238548928,0.3439571841853257,33.120105691463884,182.083854930562,0.10285705888051427
0.108906676619541,164.181734638768,0.34577869826704266,33.09903770317563,182.0622217199076,0.10337455389816336
0.109479111992916,164.043673313143,0.3475961805775083,33.071204539929624,182.00302899552187,0.10389063670848306
0.110029835504245,163.887074304164,0.34934472772597785,33.039634179719464,181.91954213112317,0.10438689379566662
0.110588864012158,163.685514860492,0.3511196432386017,32.998999795875186,181.787310004159,0.10489038277362053
0.111163364523873,163.52917527877,0.35294368236329676,32.967481736200035,181.70762860057224,0.1054075426235269
0.111740459961509,163.437807386316,0.354775960377791,32.949061969081306,181.70042315876347,0.10592676927134187
0.112331396341554,163.360499362333,0.3566521833844339,32.933476671446336,181.7110123627574,0.10645816972252445
0.112913052415587,163.329259474082,0.3584989414194887,32.92717870997493,181.77126471007801,0.10698094921994555
0.113513442725496,163.259515922127,0.3604051806534498,32.913118409900804,181.79166563214557,0.10752028013949096
0.114112390002387,163.151732822033,0.3623068382575787,32.891389336921854,181.7693669873861,0.10805802510772082
0.114708014549507,163.032428291994,0.3641979461946847,32.86733754366599,181.7335544485535,0.1085925002588658
0.115301716046896,162.863264715518,0.3660829484488948,32.83323416664843,181.64167861821713,0.10912496565869839
0.11590214698926,162.709566933347,0.3679893166909005,32.802248693762756,181.56795507661462,0.10966317820557069
0.116497173187533,162.549929670283,0.3698785248704172,32.77006582152906,181.48653697870327,0.11019626044313106
0.117097246840818,162.387599576389,0.3717837587195971,32.73734007460002,181.40274040787332,0.11073357703233938
0.117701264045288,162.242250586664,0.37370151334378937,32.70803771827146,181.3383685622667,0.11127413334310789
0.118295912340804,162.092133942535,0.3755895216820527,32.67777420281506,181.266970810535,0.11180601980147653
0.118890755941336,161.982114320735,0.37747815011374175,32.65559424706018,181.24029034130308,0.11233779805939588
0.119474335840426,161.799064807661,0.37933101629335253,32.61869146522446,181.12990061515836,0.11285923213148301
0.120061855077235,161.626956716961,0.38119638987022114,32.58399447413934,181.0321889708873,0.11338391152953851
0.120651768884519,161.450547215029,0.3830693662083478,32.54843031854985,180.9298413238958,0.11391045255165293
0.121252053675735,161.286492054249,0.3849752704204586,32.5153567981366,180.84281044598183,0.11444596598404996
0.121843758122858,161.165425975123,0.3868539320400741,32.49094987658479,180.80242715540325,0.11497354439397348
0.122429137562931,161.043509588473,0.3887125117623059,32.46637153303616,180.75992757749734,0.1154952095216622
0.123027776310332,160.884703531403,0.39061318978530407,32.43435623193085,180.67799084921853,0.11602840947565403
0.123643056827787,160.792980766617,0.39256670542822375,32.41586492254999,180.6739164250531,0.1165761359371917
0.124261513100791,160.680569777126,0.39453030409501144,32.3932028670686,180.6469805035289,0.11712638731074354
0.124910769921491,160.586846858385,0.3965916945007339,32.374308326650414,180.64587353873046,0.11770371688539165
0.125528990774432,160.454514928106,0.3985545457088216,32.34763020950617,180.59620825223215,0.11825313916213034
0.126125455844964,160.284209515014,0.40044832230776073,32.313296638226824,180.50012850484487,0.11878294078011792
0.12673019431316,160.048780507771,0.40236836694428296,32.26583415036663,180.33179356110512,0.11931980472226929
0.127324998475796,159.870617982823,0.4042568701606523,32.22991658533712,180.22614417381052,0.11984756835320876
0.127941575817029,159.698205456592,0.40621450321906705,32.195158220048945,180.13024551786006,0.12039435724603688
0.128544451556423,159.562525721054,0.408128633691643,32.167805185364486,180.0734030788245,0.12092870644778267
0.12915600660853,159.460651642655,0.4100703209820827,32.147267371159245,180.05595262001424,0.1214704568512542
0.129765290622414,159.322769849515,0.4120047977261644,32.11947040166223,179.9973353818053,0.12200990373628398
0.130385018620237,159.180658968136,0.41397243411925244,32.09082084797622,179.935432151678,0.12255829913354567
0.13100572840384,159.009936309409,0.415943187682192,32.05640315997685,179.84114883907134,0.12310726202287209
0.131624295073338,158.830703160104,0.41790713685784814,32.02026975707697,179.7366824995553,0.12365402988017975
0.132247275516349,158.649327072512,0.419885099764408,31.983704337818416,179.63026834035387,0.12420439719503068
0.132861118948176,158.494940993833,0.4218340526604588,31.952580104356734,179.5527562018988,0.12474639637560339
0.133468596966078,158.258692717097,0.4237627953672976,31.904952451766757,179.3812583917336,0.12528248609651638
0.134069179988918,158.047373580298,0.42566964646481464,31.86235051378808,179.23665535561074,0.12581220872604662
0.134667740363778,157.850058430997,0.4275700756549951,31.822571779688996,179.1073691161897,0.12633986830911959
0.135279806423159,157.700548921427,0.42951338539352985,31.79243066255969,179.0342486523436,0.1268791460339119
0.135880700663554,157.563869492193,0.43142122460678395,31.76487608962611,178.97375847805296,0.1274082977627668
0.136486521456053,157.41688945704,0.43334470562296823,31.73524491453927,178.90217311746343,0.1279415045446243
0.137108513507819,157.263737546862,0.4353195303873253,31.704369489447377,178.825934830596,0.1284886486557942
0.137729191067725,157.144590193791,0.4372901816400268,31.680349383068265,178.787987481851,0.12903433820020396
0.138368943578844,157.002355488813,0.43932139586282964,31.651674866544706,178.7266055571902,0.12959648665788964
0.139005390642218,156.819854945278,0.44134211528904216,31.614882756968047,178.61866014240232,0.1301554172389359
0.139631228971427,156.626434537033,0.4433291519842807,31.575889202665852,178.49637608085166,0.13070472671597913
0.140254211021967,156.426465667324,0.4453071199947452,31.535575478532518,178.36593619244937,0.13125122967188835
0.140885127548453,156.24259937218,0.44731027996633826,31.498508033431484,178.25485791323143,0.13180438881644893
0.141505310879672,156.017834807297,0.44927936204295854,31.453195497151075,178.09518702447687,0.13234783952149984
0.142140417274752,155.777827580893,0.45129582484733755,31.404810040308025,177.92015299539548,0.1329040610085932
0.142767913844088,155.522504744207,0.45328812645497935,31.35333695643213,177.7261283023447,0.13345331419005801
0.143382453310927,155.254603698309,0.4552392892621932,31.299328105579097,177.51538966438827,0.13399093366642306
0.143984379103423,155.014702586304,0.45715040365336795,31.250964041398888,177.33439829009475,0.13451723823450584
0.144576873365891,154.770680221318,0.45903157293670394,31.20176913261771,177.1469412564283,0.135035025796509
0.145158272564552,154.55934525262,0.46087751539245253,31.159164002928193,176.99491281819851,0.1355428567674308
0.145752295011167,154.344518990343,0.46276353666045517,31.115855028453154,176.84058685558014,0.13606144746960427
0.146348958142747,154.126519183206,0.46465794210322175,31.07190626733433,176.68277468783631,0.13658207293868974
0.146935379554095,153.882955176732,0.4665198300842516,31.022803763629174,176.49380560253093,0.1370934978976364
0.147538144892852,153.606107011495,0.46843361003480505,30.96699117351739,176.26886708418385,0.13761890413675898
0.148135862210193,153.418277094018,0.4703313625173628,30.92912466215403,176.14502585014264,0.13813963776792632
0.148745485010431,153.226481864638,0.4722669149081184,30.890458743911022,176.0182292260356,0.1386704643300303
0.14936315313639,153.03555336916,0.47422801120803826,30.851967559222658,175.89342616235,0.13920800910104697
0.149978579350286,152.828087688455,0.476181989437158,30.81014247799253,175.74902716479042,0.13974331554975516
0.150595132369216,152.563329915949,0.4781395452722608,30.75676731105532,175.53862477932972,0.14027931492291187
0.151218830689813,152.332910922578,0.48011978744015626,30.71031484199173,175.3685155878657,0.14082123390148288
0.15184758013648,152.103604620737,0.482116066933324,30.66408669154058,175.20016891243185,0.1413672446107981
0.1524914515545,151.846334820272,0.4841603586855375,30.612221099766835,175.0016028302459,0.14192607855486747
0.153107405307066,151.555734460438,0.4861160118499346,30.553636067224303,174.76003972308234,0.1424603898600513
0.153726881209121,151.235657623097,0.48808284783895917,30.489108576816356,174.48464359710616,0.1429974686789043
0.154342799246847,150.93737937101,0.4900383876087392,30.428975681195617,174.23347701411495,0.1435311770479032
0.154964034790061,150.663003406886,0.49201081045844364,30.373661486828215,174.01035030840575,0.1440692047790332
0.155579120250948,150.372779789934,0.4939637067967599,30.315152405650693,173.76764457934144,0.14460162112804173
0.156186651634154,150.057222678205,0.4958926189384389,30.251536091926127,173.49415784183446,0.14512722056772598
0.156784584433867,149.69110936893,0.49779105557752773,30.17772764877629,173.16036774478223,0.1456442462909247
0.157410912066251,149.348375769794,0.4997796458103469,30.10863255519047,172.85743981533045,0.14618553819873786
0.158017244075439,148.975046650088,0.5017047499395187,30.033369404657737,172.51567295774487,0.14670927029678565
0.158637631056955,148.628799542653,0.5036744786058321,29.963565987798848,172.20692020893853,0.14724485891898875
0.159237159644862,148.316543819934,0.5055779818724367,29.900615234098694,171.93404898616302,0.14776216779493143
0.159822478293191,147.959566611562,0.5074363685808814,29.828648628890903,171.6068312346083,0.1482669574529311
0.160400024176405,147.647461714277,0.5092700767600858,29.765728281598246,171.33011814283185,0.1487647940996558
0.160993030466692,147.245483599746,0.5111528717317471,29.68468949370879,170.9509802270027,0.1492756996544045
0.161591064272376,146.868666596891,0.5130516290647937,29.608723185933222,170.60133074054735,0.1497906724558242
0.1622033904637,146.555779991763,0.5149957647222475,29.54564524633942,170.32762439847903,0.15031767793537343
0.162829825244125,146.261547446964,0.5169846951500969,29.486327965307943,170.07728965768842,0.1508565388783923
0.163454975814415,145.84766310286,0.5189695482107676,29.402888881536573,169.68718934792693,0.1513940058171391
0.164071384970611,145.432357188752,0.5209266472816899,29.319163209252405,169.29364545225116,0.1519236747231438
0.164697952555771,145.031020031474,0.5229159993645729,29.238253638345157,168.91733208773277,0.1524617852093844
0.16531919146713,144.636409006488,0.5248884329081377,29.158700055707982,168.54758320014972,0.15299503358283392
0.165948885352553,144.230190618137,0.5268877109943557,29.07680642861642,168.16502998540307,0.15353524936239019
0.16658185931218,143.755823585229,0.5288974033161715,28.981174034782168,167.70293596501017,0.15407798516693402
0.167214490690927,143.299611782672,0.5309060079436932,28.889201735386678,167.26138338311907,0.15462013306620698
0.167861528784739,142.751300675822,0.5329603538915463,28.778662216245717,166.71375224327542,0.1551743232552848
0.16847283704463,142.26941992057,0.5349012576167003,28.68151505598691,166.23795271928222,0.15569762872284323
0.169088277780504,141.77318977021,0.5368552819531002,28.581475057674336,165.7453742639034,0.15622419527649714
0.169697722922652,141.256953293188,0.5387902702794201,28.4774017839067,165.22793661403338,0.15674535895351507
0.170305475284866,140.744020082476,0.5407198840294495,28.373994448627165,164.7134973161248,0.15726480471867058
0.170941750319131,140.19373605817,0.5427400572632409,28.263057189327075,164.15869868373187,0.1578083398421477
0.171538977411658,139.544769663206,0.5446362532820141,28.13222556410233,163.48213675437773,0.1583182497836872
0.172183802407942,138.939594223072,0.5466835726452158,28.010222195371316,162.86274186141708,0.15886850685172138
0.172804060386783,138.359865541498,0.548652891728036,27.893348893166,162.26901210163822,0.15939751427486998
0.173456975718671,137.808380091937,0.5507258979067804,27.7821694265345,161.71220493137352,0.15995407242308476
0.1740778178562,137.264708466814,0.552697071693435,27.6725652269097,161.15944938538442,0.16048300358414994
0.174691536087588,136.47061404037,0.5546456270780918,27.51247579053859,160.3108752378986,0.16100559065241588
0.175325641737619,135.806025143459,0.5566589125169403,27.378494668921334,159.61630365357118,0.16154525110375537
0.175967030355708,135.212428234487,0.5586953213793728,27.258825532072578,159.00535769809395,0.1620908136716227
0.176633683511277,134.736633405195,0.5608119451483045,27.16290529448731,158.53566126746315,0.16265755087397338
0.177253232019493,134.128658206334,0.5627790116618903,27.040337494396937,157.9033963798446,0.1631839555355014
0.177880404897281,133.338919648475,0.5647702855488671,26.88112620113256,157.05730066411178,0.16371655621920153
0.178501957126441,132.532075693523,0.5667437138764502,26.71846645981424,156.1893105868465,0.16424410408544962
0.179166333294977,131.724878133415,0.5688531082115519,26.555735431696462,155.32554155230665,0.16480769158316555
0.179827390339614,130.931616148854,0.5709519643282744,26.395813815608967,154.47670699385048,0.16536814840449388
0.180490318452251,130.130455329439,0.5730567610858969,26.234299794414902,153.61774265218588,0.16592987628341407
0.181119733939957,129.227234688405,0.5750551552593635,26.052210513182445,152.6328370529653,0.16646291559866552
0.181808722943409,128.398899368392,0.5772426953453236,25.885218112667825,151.7429392898986,0.1670460809678673
0.182499399111111,127.516810745854,0.5794355921777774,25.70738904636417,150.7885520835376,0.16763033323254153
0.183191034386428,126.610378732359,0.5816315341769088,25.524652352443574,149.80426497639723,0.16821505495709982
0.183894900085415,125.683538383989,0.5838663077711926,25.337801338212184,148.7961001174941,0.16880976570205586
0.184523453440267,124.601345585323,0.5858619646728477,25.11963127000112,147.59321617603098,0.16934054470794643
0.185156829552304,123.607379580258,0.5878729338285652,24.919247723380014,146.49413009260678,0.16987511144394507
0.185785807579328,122.661118654205,0.5898699390643664,24.72848152068773,145.44981364196025,0.17040568357329863
0.186403478918222,121.650225689438,0.5918310455653548,24.524685498990703,144.3262509691361,0.170926444168896
0.187049358133086,120.68311252521,0.593881712072548,24.32971548508234,143.25681126055355,0.1714706970149812
0.18770337625294,119.578004914179,0.5959582196030845,24.106925790698487,142.02320016216106,0.17202150647562034
0.188396565278804,118.379338835914,0.5981590947602027,23.86527470932026,140.6815996725759,0.1726049743958144
0.189119941706599,117.242553143456,0.6004558149184518,23.63609871372073,139.41545795947923,0.173213488740923
0.189837917747152,116.077289603381,0.6027353888472076,23.40118158404161,138.11316055942,0.17381709427306713
0.190509854781175,114.835341162224,0.6048687889302305,23.15080477830436,136.71260533078598,0.1743816647611492
0.191180388043382,113.634888848373,0.6069977320377378,22.908793591831994,135.35965099367152,0.17494473821870168
0.191858328657049,112.344906847584,0.6091501934861305,22.648733220472938,133.89921290849333,0.17551370978194575
0.192528667150549,111.004655250428,0.6112785182029931,22.378538498486286,132.3762335732991,0.17607598303065863
0.193197443200613,109.594197268573,0.6134018821619462,22.094190169344316,130.7675159704849,0.17663663084742184
0.193836900067206,108.073663956032,0.615432157713379,21.787650653536048,129.02232795617417,0.17717240603112888
0.194484653997265,106.548521855623,0.6174887764413164,21.480182006093596,127.27057426263384,0.17771484048250266
0.195141618390682,105.028630595427,0.6195746383904154,21.173771928038086,125.52408754717572,0.17826468747536517
0.195760082623196,103.374928999681,0.6215382623286473,20.84038568633569,123.61161364182557,0.17878203559222502
0.196432306704101,101.688996175975,0.6236725737855207,20.500501629076563,121.66400026124627,0.17934405067228143
0.197303926785446,99.7588761916056,0.626439967543791,20.11138944022769,119.44169419591252,0.1800723014358138
0.199092883240997,97.247003749013,0.6321199042901654,19.604995955801023,116.60819011195206,0.18156534030182248
0.200662070719943,91.7619263727232,0.637102074535819,18.499204356740997,110.17506453192478,0.18287313024929705
0.202121289191279,88.3663431597854,0.6417350931823108,17.814654781012738,106.22706236036018,0.18408773717148333