File: example/data/02 processed data/test_ID_077.csv
Strain,Stress_MPa,Displacement(mm),Force(kN),True Stress (MPa),True Strain
0.0012174031337883388,40.4457665838092,0.0038652549497779757,16.30773308659187,40.495005386796805,0.0012166626994704098
0.0013041821185494388,43.6277940858857,0.004140778226394468,17.590726575429112,43.68469267480427,0.0013033324117517455
0.0013936572537653388,46.705578434982,0.004424861780704951,18.831689224984743,46.770670003159225,0.001392687014843962
0.0014705555092297388,49.7387546162216,0.0046690137418044205,20.05466586126055,49.811898215844714,0.001469475301351036
0.0015563581080432387,52.7224967127605,0.004941436993037283,21.257710674585038,52.80455179799569,0.0015551482379278618
0.0016445980623177388,55.6366278626812,0.0052215988478588205,22.43268835423306,55.728127753058054,0.001643247191814228
0.0017301257816171387,58.5593503280769,0.005493149356634415,23.61113005228061,58.660665369834256,0.001728630838052251
0.0018160943615254388,61.4647834631356,0.005766099597843268,24.782600692336278,61.57640930981539,0.0018144472560583283
0.0019083110871972388,64.3098526077368,0.006058887701851233,25.929732571439477,64.43257581248416,0.0019064925747518124
0.0019976646536762387,67.1014099635853,0.006342585275422057,27.055288497317594,67.23545607848139,0.0019956719750032583
0.0021033944361347388,69.8810427182453,0.006678277334727795,28.176036423996504,70.02803011469015,0.0021011853991662055
0.0021962918704299386,72.5366815342958,0.006973226688615055,29.246789994628067,72.69599325825753,0.00219388354704926
0.0022785511873780386,75.077192056745,0.007234400019925273,30.27112383727959,75.2482592818509,0.0022759592261520655
0.0023826585713082387,77.5250453489661,0.0075649409639036574,31.258098284703134,77.70976106275788,0.0023798245411659888
0.002472449283371639,79.8464324911088,0.007850026474704954,32.194081580415066,80.04384874590123,0.002469397809350445
0.002579949081691439,82.0201508646212,0.008191338334370319,33.07052482861527,82.23175867752457,0.002576626726171131
0.0027279536658060387,84.0576799437412,0.008661252888934172,33.89205655331646,84.28698539988288,0.002724239553289244
0.002874324872438439,85.9098071018348,0.009125981469992044,34.638834223459796,86.156739797174,0.0028702018993223507
0.003043538405755839,87.5671429653228,0.009663234438274788,35.307072043618156,87.83365692802008,0.003038916218902893
0.0032296749199263388,89.0302479686193,0.010254217870766125,35.8969959809473,89.31778672759837,0.0032244707221162896
0.003428796038544439,90.1946580024237,0.010886427422378593,36.366486106577234,90.50391708848026,0.0034229311199901065
0.003666022582039139,91.1856050318257,0.011639621697974264,36.766035948832126,91.51989351902927,0.0036593190996694943
0.003963992232940839,91.9018120370463,0.012585675339587163,37.05481061333707,92.26611010615434,0.0039561563165778565
0.004261120804264438,92.4273183403094,0.013529058553539591,37.26669475481275,92.82116230937166,0.004252067936806872
0.004583815462672639,92.7809903374983,0.014553614093985628,37.409295304079315,93.2062812756494,0.00457334177468067
0.0049106976043239384,92.9953396218976,0.015591464893728504,37.49572093554911,93.45201161339213,0.00489867945777335
0.005265213262998139,93.174336083164,0.01671705211001909,37.56789230873172,93.66491883328013,0.005251400491224531
0.005636674583146039,93.3010527455283,0.017896441801488673,37.618984466997006,93.82696041811978,0.005620847978064116
0.005978833024950439,93.3765744618759,0.018982794854217642,37.649434823028365,93.93485740902531,0.005961030725522571
0.006358843587689939,93.3946774514764,0.020189328390915553,37.65673394843529,93.9885595973131,0.006338711441510987
0.006680948366881339,93.3836305762225,0.021212011064848248,37.65227984833292,94.00752179041416,0.00665872973745083
0.007067406435557639,93.3398167504148,0.0224390154328955,37.63461411376725,93.99948717201045,0.0070425493666503
0.007473952917704639,93.2793711008232,0.023729800513712228,37.610242427851915,93.97653672862384,0.007446161321081922
0.00791291233527764,93.1930057633221,0.025123496664506507,37.57541992377148,93.9304338481883,0.007881769424004842
0.008323928599447038,93.1134546986769,0.026428473303244344,37.54334493450653,93.88852444723653,0.008289475762385357
0.00871934244735464,93.0391500295618,0.02768391227035098,37.51338529191932,93.85039023968035,0.008681548514268085
0.009099812039673739,92.9626843411504,0.02889190322596412,37.482554326351845,93.80862729535839,0.009058658223016724
0.009491197087271239,92.8973061223667,0.03013455075208618,37.456193828538254,93.77901276365066,0.009446438660690814
0.009895518487648339,92.8018975218329,0.03141827119828348,37.417725080803024,93.72022041444905,0.009846878460221488
0.01032083952104064,92.7182544376997,0.03276866547930403,37.38400018928052,93.67518466242221,0.01026794330111349
0.010712824561667339,92.6241574478081,0.0340132179832938,37.34606028295623,93.61642379671873,0.010655848809575146
0.011098547660827738,92.5060655454144,0.03523788882312807,37.298445627911086,93.53274852278582,0.011037410718998915
0.011496580266603738,92.3824439022117,0.03650164234646687,37.24860138137176,93.4445260837585,0.011430996766368004
0.011875366875565238,92.2301711451906,0.03770428982991963,37.18720500574085,93.32543826453592,0.01180540801974284
0.01230853595557464,92.092036707646,0.03907960165894948,37.13150920052287,93.22555485268416,0.012233401826052292
0.012753365455852539,91.9438041962149,0.04049193532233181,37.07174185191385,93.11639713253057,0.01267272618164106
0.013178817122713439,91.8293217592557,0.041842744364615166,37.0255825333319,93.03952359722375,0.01309273202070496
0.01359561546421244,91.716163210032,0.043166079098874495,36.9799570062849,92.96310089688855,0.013504024309252951
0.01400152127575274,91.6064397852459,0.04445483005051495,36.935716521411145,92.88906930089497,0.013904405439811493
0.01443787341669324,91.4677470457069,0.04584024809800103,36.87979560882902,92.78834679926294,0.014334639785301967
0.014869027702213239,91.3021256387503,0.04720916295452703,36.81301705754412,92.65969947414382,0.014759567421205457
0.01530490192958974,91.150254717422,0.04859306362644742,36.75178270206455,92.54530042672926,0.01518896337365249
0.01574414520859834,90.9923814420706,0.04998766103729973,36.688128197442865,92.42497870837072,0.01562149186081563
0.01617252063378894,90.8402159959393,0.05134775301227988,36.62677508956273,92.30933126351148,0.016043138514675623
0.016604148890905536,90.6755757215971,0.05271817272862507,36.560392130947946,92.18116648164707,0.016467807166253668
0.01703476433499894,90.5116051054648,0.05408537676362163,36.494279178523406,92.05344896801887,0.016891299702444455
0.017484276612875937,90.3792678862961,0.0555125782458811,36.440920811754594,91.95948400608933,0.017333185254896345
0.017898769172450542,90.2258520895526,0.05682859212253047,36.37906356250761,91.84078378949117,0.017740472292255383
0.018347388473058737,90.0794082549721,0.058252958401961485,36.320017408404745,91.73213015164932,0.01818110596140416
0.018744141868944138,89.8934549152768,0.05951265043389763,36.245041021839604,91.5784305872983,0.018570635243709534
0.01918243522819614,89.7024946696085,0.06090423184952274,36.16804585078615,91.42320696341588,0.019000771805973628
0.019610406853822038,89.548036323425,0.062263041760884964,36.105768245604956,91.3041097486882,0.019420600268265965
0.020092060047864936,89.4126256915245,0.06379229065197117,36.05117067882268,91.20910953595588,0.019892878172334025
0.020539804846244937,89.2934290232076,0.06521388038682767,36.003110582157305,91.1274986293963,0.020331707745926336
0.02100235037606294,89.1467800843389,0.06668246244399983,35.94398173000545,91.01907199456802,0.020784841213241236
0.021454756832636042,88.9787865014888,0.06811885294361943,35.876246717400285,90.88780472914128,0.02122784338192815
0.021912716424838836,88.8450137404574,0.0695728746488633,35.822309540152425,90.79184933231296,0.021676083461957058
0.022335908371722536,88.6987377084985,0.07091650908021904,35.7633310440666,90.67990458664296,0.022090115246345375
0.022803901057774037,88.5729702865292,0.07240238585843256,35.712621619528576,90.59277953733637,0.022547778523997544
0.02325053899827164,88.4270093195932,0.07382046131951245,35.65377015765998,90.48298494827893,0.02298436314154035
0.023689587744919742,88.274983499919,0.07521444109012018,35.59247334716734,90.36618146722168,0.02341334369416614
0.024185141423053842,88.1092341164163,0.07678782401819595,35.52564319573906,90.2401684041988,0.02389731244552438
0.02466238106543244,87.9408022899415,0.078303059882748,35.457731483304414,90.1096318672159,0.024363174005031924
0.025144401586523042,87.7828596639085,0.07983347503721065,35.394049016487905,89.9901071397112,0.024833482264380834
0.025607635137927638,87.6413521459343,0.08130424156292025,35.336993185240715,89.88563991468203,0.025285251713819804
0.02609375637169374,87.5060956284018,0.08284767648012763,35.2824577573716,89.78945836876744,0.025759123052869707
0.026559475922519636,87.3360442918194,0.08432633605399983,35.213893058461586,89.65564385735608,0.026212896297653786
0.027044141102370037,87.1542188934776,0.08586514800002486,35.14058105785017,89.51122988689966,0.026684910648262623
0.027531196532428137,87.0033507268732,0.08741154899045933,35.079751013075274,89.3986570747145,0.027159028516086706
0.028014528544287237,86.8605278822017,0.08894612812811198,35.02216484210373,89.29388461992949,0.027629299758288043
0.028490995486522536,86.7295011604266,0.09045891066970904,34.96933486788401,89.20051098653666,0.028092675076460596
0.028982783875234036,86.5631745026652,0.09202033880386806,34.90227195947461,89.07201628083013,0.028570725784091023
0.02945778196724444,86.3769241294376,0.09352845774600109,34.82717580898924,88.92139672744378,0.029032238356592042
0.02991859700618424,86.1834671024344,0.09499154549463495,34.74917393570155,88.76195552326787,0.029479767085517822
0.030397208484154135,86.0279170513989,0.09651113693718938,34.68645615512404,88.6429255814678,0.02994436720682327
0.030854988633239537,85.8811754149879,0.09796458891053553,34.62728992732312,88.53103810622659,0.030388543962342907
0.03134375753367164,85.7810225881034,0.09951643016940745,34.58690830752329,88.46972216109532,0.03086257093039631
0.031840776298868036,85.613129762088,0.101094464748906,34.51921392007388,88.3391182750886,0.03134436862387492
0.03233438230743864,85.4630251585618,0.10266166382611767,34.45869174393212,88.22641928718899,0.03182262844201231
0.03283307099648314,85.3077267173812,0.10424500041383396,34.3960754124481,88.10864136524155,0.03230558075461
0.03335539638991154,85.1560008946756,0.10590338353796915,34.334899560733206,87.99641305949717,0.032811173940129876
0.03386173955769964,85.0393190391844,0.10751102309569635,34.28785343659916,87.9188983126534,0.03330105298486995
0.03437186143049834,84.8945483858359,0.10913066004183222,34.22948190916904,87.8125320391586,0.03379434531209964
0.03488541569540544,84.7335276902427,0.11076119483291226,34.164558364705854,87.68949202705497,0.03429071111554816
0.03539670298544664,84.565354937092,0.11238453197879308,34.096751110635495,87.55868968865913,0.034784641189930285
0.03593221650731324,84.3988920710169,0.11408478741071953,34.029633283034016,87.43153133389005,0.035301713615037054
0.03644654346279654,84.2669937069756,0.11571777549437902,33.97645186265256,87.33823435559609,0.03579807748054062
0.03694928381094084,84.1486481720641,0.11731397609973716,33.92873494297624,87.2578804556807,0.03628302140816284
0.03744989894211874,84.017031898937,0.118903429141227,33.8756672616514,87.16346125296897,0.03676568178043718
0.03795429038397144,83.8513744289988,0.12050487196910932,33.80887416977232,87.03389384317212,0.03725174753512466
0.03849343347612994,83.6971131121314,0.12221665128671255,33.746676006811384,86.91890236785736,0.037771041228945264
0.038987177750480044,83.5558204981687,0.12378428935777414,33.68970682486162,86.81342612401801,0.038246371088562874
0.03950964682001424,83.3919494001862,0.1254431286535452,33.62363399815508,86.68673586862006,0.03874910852300325
0.04002552870259084,83.2229339335525,0.12708105363072592,33.555486962008366,86.55397586442372,0.03924525968142704
0.04055228325758894,83.0400275708554,0.12875349934284486,33.481739116568896,86.40749029062671,0.0397516137944285
0.041088747358283044,82.8960774130575,0.13045677286254867,33.42369841294478,86.3021733948753,0.04026703802433233
0.04162111702305204,82.8058324827098,0.1321470465481902,33.3873116570286,86.25230372666391,0.04077826590630319
0.04215567717094594,82.7004935952314,0.13384427501775337,33.34483901759731,86.18678890510986,0.04129133444714668
0.04269804677426404,82.5817105849935,0.1355662985082883,33.296945707869384,86.1077883262503,0.041811629573201996
0.04323169432926284,82.4323445042925,0.13726062949540951,33.23672130413074,85.99603442474655,0.04232329356276545
0.04376517540742914,82.2783330882084,0.13895443191858753,33.17462390116563,85.87925876804472,0.04283453638974031
0.04430138744788444,82.1207467487544,0.1406569051470331,33.11108508909778,85.75880976798055,0.04334813309377349
0.04483430418731184,82.007577459034,0.1423489157947151,33.06545523148251,85.68433013249687,0.043858312258411115
0.04535526766322524,81.8668392585355,0.14400297483074015,33.008709589041516,85.57993166584862,0.04435679669610719
0.04589724287575484,81.719732178684,0.1457237461305216,32.94939601444539,85.4704425742307,0.044875122648551896
0.04643921405842034,81.5664204314824,0.14744450463548456,32.887580717973705,85.35430088987913,0.04539317622735424
0.04699565902318184,81.4188671898297,0.14921121739860232,32.82808725093933,85.24520051033667,0.045924785770140794
0.047539011786678444,81.2952925225805,0.15093636242270406,32.778261945104454,85.15999039201293,0.04644361487644055
0.04809006762736884,81.1912327263426,0.15268596471689605,32.73630503526134,85.09572459890185,0.04696952459854205
0.048658090980938644,81.0687012357158,0.1544894388644802,32.68690033824061,85.0133494761498,0.04751133823041163
0.04925244768201864,80.9405278797662,0.15637652139040917,32.63522084112173,84.92704699451934,0.04807795602085429
0.04980655335756204,80.7780593495375,0.15813580691025947,32.56971352973352,84.80133607265056,0.04860591229853852
0.05034691737789544,80.5863392725256,0.159851462674818,32.49241199468233,84.6436130376665,0.049120507102954
0.05089347918027524,80.4369290225119,0.16158679639737386,32.4321697818768,84.5306441950444,0.049640734884222444
0.05145321664107194,80.2538257716146,0.16336396283540341,32.35834255111501,84.38314325531633,0.050173223150915096
0.052016299441446444,80.1462530803352,0.16515175072659244,32.31496924199115,84.31516457967186,0.0507086079611244
0.05258590245238634,80.0383387315037,0.1669602402863266,32.27145817654229,84.2472270044896,0.051249900775828326
0.05316711024953594,79.9447239820744,0.16880557504227658,32.233712709572394,84.19515393589806,0.051801919752795564
0.05376015956559454,79.8459438690667,0.17068850662076265,32.1938845680077,84.13847455213323,0.052364871630838174
0.05432472778037684,79.7409975036241,0.17248101070269647,32.15157019346124,84.07290548594419,0.0529004935421461
0.05489320293355764,79.5833618676421,0.1742859193140455,32.08801150503329,83.95194750077732,0.053439532357118714
0.05546677246492234,79.4204288305303,0.17610700257612844,32.02231690446982,83.82562368553988,0.053983107436416995
0.05607131731724854,79.2590307123148,0.1780264324822641,31.957241183205326,83.70318897364254,0.054555718341964904
0.05665718889070214,79.1169359792426,0.17988657472797928,31.899948586830615,83.59947916547213,0.055110329676785946
0.05725395981902774,78.9862423853406,0.18178132242541306,31.84725292976933,83.50851753312689,0.05567494275860211
0.05784999896471224,78.8665343909827,0.18367374671296136,31.798986666444222,83.42896332385149,0.056238545468517906
0.05840145611997404,78.739369983182,0.18542462318091757,31.747713977218982,83.33786384416919,0.056759709592392224
0.05902433430991304,78.6285885959511,0.18740226143397387,31.703046921887484,83.26958869555513,0.05734804492931045
0.05964098086753604,78.4940706169235,0.18936011425442692,31.648809272743552,83.17553398080244,0.057930153458315065
0.06024921346356584,78.3843871593288,0.19129125274682154,31.604584902641374,83.106984833502,0.05850398753174643
0.060874321731188244,78.2314637320416,0.19327597149652267,31.542926176759174,82.99375102476769,0.059093399959026065
0.06144653061309134,78.0758083927793,0.195092734696565,31.480165943968615,82.87329594332806,0.0596326293551243
0.06201418342100094,77.8707671991344,0.196895032361678,31.397493334690996,82.69985923935559,0.06016727811757115
0.06258177178034524,77.7303316454496,0.19869712540259613,31.340869719445276,82.59483352089566,0.060701580530656024
0.06317107623718923,77.5679684034477,0.2005681670530758,31.27540486027011,82.46802044902579,0.061256023604779226
0.06379000829500764,77.473551676025,0.20253327633664925,31.23733603577328,82.41559018008233,0.061838010816288765
0.06440231832655154,77.3862471957637,0.2044773606868011,31.20213486933193,82.37010092176249,0.06241343817854373
0.06503011590197723,77.295382687712,0.2064706179887777,31.165498299685485,82.3219103825816,0.06300307660380997
0.06564216813954023,77.1596748811633,0.20841388384304022,31.110780912085044,82.22460323330488,0.0635775922240507
0.06624259269823873,77.0183634517318,0.21032023181690795,31.05380414373826,82.1202595321498,0.06414087274052485
0.06684412696351114,76.8929215216912,0.21223010310914783,31.003225957545897,82.03276173048243,0.06470487632807087
0.06744931881492304,76.7793682709732,0.21415158723738065,30.957441286856394,81.95808435989045,0.06527198847361847
0.06811207929542863,76.6756305485205,0.2162558517629859,30.915614237163467,81.89816717646832,0.06589267819236853
0.06877901048120183,76.5442886206063,0.2183733582778158,30.86265717182846,81.80892904991912,0.06651688521032925
0.06938844780602853,76.4169186538103,0.22030832178414056,30.811301601216314,81.71937002531774,0.0670869409737058
0.07000570509285363,76.2674060946856,0.22226811366981025,30.751018137377233,81.60655963394706,0.06766398032208042
0.07060834075011543,76.1334630536627,0.2241814818816165,30.697012303236797,81.50912055544204,0.06822702967173136
0.07126403481669823,76.0091591929248,0.22626331054301685,30.64689298658728,81.42587856003735,0.06883929218983989
0.07190224879025253,75.8630556360954,0.22828963990905177,30.587984032473663,81.3177799364307,0.0694348726609414
0.07255705320787484,75.7611526570324,0.2303686439350026,30.54689675131546,81.25815864145862,0.07004556686937215
0.07319415383881624,75.6249050503667,0.23239143843824153,30.491961716307856,81.16020598466912,0.07063939214377579
0.07383392390571414,75.4861093588549,0.2344227084006424,30.4359992934903,81.05954501319502,0.07123535089481865
0.07447529003204593,75.2737775630849,0.23645904585174582,30.350387113435836,80.87981397890337,0.07183244012315274
0.07508600032805143,75.1035467426108,0.23839805104156328,30.28175004662068,80.7427716779643,0.0724006586849364
0.07569638071602704,74.9366353628011,0.24033600877338582,30.214451378281403,80.60906744280179,0.07296824786526625
0.07631382485490663,74.8479514734921,0.24229639391432856,30.17869403411202,80.55988493298874,0.07354207800252478
0.07695345098102713,74.7572987962586,0.24432720686476112,30.14214287465147,80.51013092465048,0.07413617623836538
0.07759088395598573,74.6383890481596,0.2463510565602547,30.09419846421795,80.42964763145707,0.07472788649767217
0.07822980624414694,74.4980178590573,0.2483796348251665,30.0376008007719,80.32598336174435,0.07532062810162114
0.07886572294607903,74.3397387026873,0.2503986703538009,29.973782644923517,80.20259593909734,0.07591023269886675
0.07949535331552883,74.2062596981608,0.25239774677680404,29.91996391029844,80.10531253109,0.07649366648502524
0.08015376734136233,74.0600864927381,0.2544882113088254,29.861026873872003,79.9962814347582,0.07710340816938942
0.08081071848280884,73.9540832467401,0.25657403118291805,29.818286365085612,79.93036584864662,0.0777114247897409
0.08146785267079443,73.8314150617333,0.2586604322297723,29.768826552890864,79.84630190645885,0.07831924120801668
0.08210406457663173,73.7181240045715,0.26068040503080575,29.723147598643227,79.77068161831097,0.0789073537815838
0.08278277385666333,73.575825233421,0.26283530699490604,29.66577273411535,79.66663613503667,0.079534369744006
0.08344372627058583,73.4152259729671,0.26493383090911,29.60101911230033,79.54126599314856,0.08014460365481305
0.08410607222953843,73.2634870891902,0.2670367793287845,29.53983799436149,79.4253912261015,0.08075575084047534
0.08473554396046694,73.0946737790879,0.26903535207448254,29.471772467728243,79.28839072237179,0.08133621899813546
0.08538502345887053,72.8829565749229,0.2710974494819139,29.386408091008914,79.10606953182453,0.08193478437514327
0.08603331290485883,72.7314949527567,0.2731557684729268,29.325338764951503,78.9888264160654,0.08253189590763221
0.08667708915750703,72.5704932294276,0.27519975807508484,29.26042287010521,78.86069234127895,0.08312449791375046
0.08731660967915024,72.4737657272575,0.277230235731302,29.221422341230223,78.80192924124262,0.08371283498246634
0.08795479543894323,72.3431899965871,0.27925647551864474,29.168774206623922,78.70612047413752,0.08429959926080115
0.08861581366614633,72.1927902253959,0.2813552083900146,29.108133018879627,78.59021307204877,0.08490699352107485
0.08928527081873143,72.0567612701559,0.2834807348494723,29.05328614412686,78.49036871448246,0.08552176632084904
0.08994964712303403,71.9218482760429,0.28559012961563307,28.998889224900495,78.39119314890935,0.08613149987404789
0.09059788332928793,71.7927899031648,0.28764827957048916,28.94685288895605,78.2970647066958,0.08672606267655247
0.09126358639779403,71.6360111393061,0.28976188681299603,28.88363969136822,78.1737704311115,0.08733627840142727
0.09190335976206224,71.3886380261669,0.29179316724454757,28.783898852150497,77.94949370960936,0.08792237502011013
0.09254210074172163,71.2119287105551,0.29382116985496615,28.71264965609582,77.80203019129958,0.08850718339313875
0.09320194118310184,71.0562240747648,0.2959161632563483,28.649869546945165,77.67880209167433,0.08911095075909596
0.09383842550751194,70.9512001111935,0.2979370009863504,28.607523884833224,77.6091490174963,0.08969300160010765
0.09450979902277773,70.8133588029714,0.30006861189731926,28.55194626935807,77.50591511156806,0.09030659090806498
0.09517094817117763,70.6339738649949,0.302167760443489,28.479618262365943,77.35627613082464,0.09091046813476916
0.09581287501214333,70.4368405149252,0.30420587816355504,28.400134095617837,77.185596711432,0.09149643947106227
0.09644226180595743,70.2377081937832,0.3062041812339148,28.31984394373339,77.0115916360585,0.09207063067767499
0.09709149937188913,70.0681299251221,0.30826551050574796,28.251469985809226,76.87114971773654,0.09266258654029319
0.09776370364663574,69.8876601185806,0.31039975907806844,28.1787045598117,76.72013661097031,0.09327511377656736
0.09843477518027353,69.7320197062567,0.31253041119736846,28.115950345562702,76.59607538890847,0.0938862348214026
0.09908731565279673,69.5422063731614,0.3146022271976296,28.03941760965868,76.43295692725079,0.09448012235902939
0.09970087854633523,69.3400180435962,0.3165502893846143,27.95789527517799,76.25327876096148,0.09503821423079993
0.10029582040146294,69.1212545248078,0.31843922977464484,27.869689824402503,76.05382745455174,0.09557907128746318
0.10095356681282744,68.9129368211263,0.3205275746307271,27.785696126278122,75.86994359276602,0.09617668320255146
0.10160465162151343,68.6912684762056,0.32259476889830513,27.696319449606094,75.67062087917031,0.09676789102825256
0.10228087797461444,68.5158719942415,0.3247417875694008,27.62559958807817,75.52373553700882,0.09738155844903418
0.10296293260497943,68.3286378385544,0.32690731102080967,27.550106776505135,75.36395477131552,0.09800013372750545
0.10355780707246244,68.146505606957,0.32879603745506825,27.476671060725067,75.20360828726474,0.09853933054645991
0.10419789711270844,67.9189471893225,0.3308283233328493,27.384919506734832,74.995958660559,0.09911918642178837
0.10485899932202643,67.6848223769525,0.33292732284743387,27.29052038238725,74.78218512068884,0.09971772440432872
0.10553262534482843,67.4365121280365,0.33506608546983024,27.190401690024316,74.55326429700656,0.10032723272506176
0.10620483783793544,67.1440801538474,0.337200360135445,27.07249311803127,74.2751062983641,0.10093509195337877
0.10683374412211344,66.8948220443374,0.33919713758771014,26.971992248276845,74.04144634571645,0.10150345646923917
0.10748734506146643,66.6373938976963,0.3412723205701559,26.86819721955115,73.80007044957483,0.10209379629080106
0.10811199950739943,66.4330039701407,0.3432555984359932,26.785787200760733,73.61520886263561,0.10265766580449709
0.10872967925136143,66.2322501162282,0.34521673162307254,26.704843246863213,73.43366142746164,0.1032149268537322
0.10937604023352043,65.9963617926968,0.34726892774142737,26.60973307481535,73.21478251540078,0.10379773135648997
0.11004630588973444,65.7195131659789,0.3493970211999068,26.49810770852269,72.95170281476665,0.10440173147189102
0.11070111954780243,65.4404937359211,0.35147605456427267,26.385607074323385,72.68482965624851,0.10499145515639893
0.11136168115856343,65.1484939216884,0.35357333767843885,26.26787274922476,72.40353972975606,0.10558600327628938
0.11197169290381644,64.8418800545333,0.35551012496961715,26.144246037987827,72.10233513530561,0.10613473948263275
0.11260162824867943,64.5039239127538,0.3575101696895572,26.007982121622337,71.76717077375882,0.10670108212075634
0.11319472826343843,64.154058112404,0.359393262236417,25.866916230921294,71.41595928743442,0.10723401499852055
0.11379035305551444,63.8147483858076,0.3612843709512583,25.73010654915762,71.07625113477746,0.1077689308462061
0.11440999729541143,63.5065070590093,0.36325174141293126,25.605823646192555,70.77228635987157,0.10832511445489526
0.11503539477765243,63.2233386769911,0.3652373784190464,25.491650154562812,70.49626040085998,0.10888614860344968
0.11572337793082843,62.9574829408116,0.3674217249303802,25.384457121735238,70.24313553274483,0.10950296399685355
0.11634870390263544,62.6186434911753,0.3694071348908675,25.24783705564188,69.90424150151475,0.11006327384818529
0.11698489040971044,62.300305485971,0.37142702705083064,25.119483171943507,69.58849989573879,0.11063299305708713
0.11759562031186843,61.9559247867308,0.37336609449018227,24.98062887400986,69.24167019402186,0.1111796101196046
0.11821035688411843,61.6194270476083,0.37531788310707603,24.844952985595665,68.90348150990097,0.11172951167100119
0.11880635328286844,61.2688463378464,0.3772101716731073,24.70359884341967,68.54797454109436,0.11226236098781052
0.11940173652475443,60.8227301485736,0.3791005134660953,24.523724795904872,68.08506974848981,0.11279437877350294
0.12001161898202244,60.404475231103,0.3810368902679212,24.35508441318073,67.65371409734715,0.1133390593442841
0.12061360780655044,60.000970276957,0.3829482047857976,24.192391215669062,67.23790377395439,0.11387639939724377