File: example/data/02 processed data/test_ID_141.csv
Strain,Stress_MPa,Displacement(mm),Force(kN),True Stress (MPa),True Strain
0.0002338155850661,0.69732964231722,0.0002380889814227,0.1405816558911515,0.6973819341295839,7.498584405753196e-05
0.0002367937562944,1.23238253147606,0.0002475446750727,0.2484483183455736,1.232478616431436,7.796378753943944e-05
0.0002375821967185,2.09035190359843,0.0002500479734193,0.4214149437654435,2.090516529821179,7.875216618554527e-05
0.0002391311863603,2.91277432718135,0.000254966015532,0.5872153043597602,2.9130082353590967,8.030103264622881e-05
0.0002511651560049,4.28260164556759,0.0002931738691534,0.8633724917464263,4.282997093408369,9.233396359338728e-05
0.0002565007972286,5.87738247633249,0.0003101145300386,1.18488030722863,5.8779565430110745,9.766909794711014e-05
0.0002671526651316,7.57172672982864,0.0003439342106306,1.5264601087334535,7.572546942696651,0.0001083198688229
0.0002613957891806,9.31041569154188,0.0003256561294862,1.876979803414843,9.311370650262516,0.0001025635998549
0.0002698854212921,11.105325788101,0.0003526107114402,2.2388336788811616,11.106559128833888,0.0001110523252545
0.0002850546812118,12.7217380285395,0.0004007731116852,2.564702386553563,12.723343864928712,0.0001262197856597
0.0003016710444305,14.3658540381223,0.0004535300649046,2.896156174085456,14.3679061158276,0.0001428339136815
0.0003144570830849,16.020921506628,0.0004941257376323,3.2298177757362048,16.02341484510265,0.0001556180444689
0.0003285472844828,17.7305924684487,0.0005388621270707,3.5744874416392585,17.733601710896504,0.0001697059541128
0.0003434277897423,19.4572634576994,0.0005861077312696,3.9225843130722,19.460855285271656,0.0001845838236002
0.000363921367171,21.2390909721733,0.0006511748396057,4.281800739990138,21.243446991592883,0.000205073408682
0.0003840297670032,23.0126789255862,0.0007150190090729,4.639356071398178,23.0178614461788,0.0002251774831508
0.0004030275041435,24.7838060102016,0.0007753368244934,4.996415291656643,24.78985822987115,0.0002441707625366
0.0004293826078204,26.5609780314822,0.0008590142786675,5.354693171146812,26.568164254910364,0.0002705190847331
0.0004586678271295,28.3303694157097,0.0009519948499739,5.711402474207076,28.33886401910549,0.0002997959543312
0.000488446856333,30.0957019847509,0.001046543267695,6.067293520125782,30.1056221278371,0.0003295656141196
0.0005212484875916,31.8710584851208,0.0011506884469411,6.425205390600353,31.88260924379501,0.0003623558992624
0.0005495771189682,33.586735649294,0.0012406318515618,6.77108590689767,33.59985967261258,0.0003906738664944
0.0005782331154896,35.2878509838225,0.0013316146405172,7.114030758338616,35.3026509268154,0.0004193182597989
0.0006021773477619,36.9874245295156,0.0014076375779818,7.456664785150346,37.00382291965119,0.0004432521675038
0.0006263400774338,38.6691094144902,0.0014843542446901,7.795692457961224,38.68718773156037,0.0004674038977114
0.0006524937854742,40.3133571463348,0.0015673922677184,8.127172800701096,40.333258514611,0.0004935450425804
0.0006777523693672,41.9004874943767,0.0016475882715786,8.447138278866342,41.92223072328037,0.0005187908446223
0.0007068327420114,43.4660299348499,0.001739918454724,8.76275163486574,43.489849571901,0.000547855712161
0.0007437933081754,45.0137024177898,0.0018572682522947,9.074762407426425,45.04003392028391,0.0005847953525364
0.0007784602919236,46.5716706762161,0.0019673359256952,9.388848808325166,46.6005280371109,0.0006194414689368
0.0008054300776864,48.0541955651723,0.0020529649954921,9.687725825938736,48.08526755930831,0.0006463941904411
0.0008391359172142,49.5140812483575,0.0021599810359929,9.982038779668873,49.547766122849175,0.000680077682455
0.0008740134536533,50.9526125977987,0.002270717214187,10.27204669971622,50.98905321969906,0.0007149309001432
0.0009101055041437,52.3919114978032,0.002385309474494,10.562209357957125,52.43127241839613,0.0007509965061612
0.0009424802025925,53.8248531867462,0.002488099142069,10.851090402448037,53.86703320911973,0.0007833463771893
0.0009692768457764,55.2110787987756,0.0025731784841778,11.13055348583316,55.2558246129656,0.0008101216790776
0.0010048264813412,56.5546671482067,0.0026860485770961,11.40142089707847,56.60251237126861,0.000845641895924
0.0010556303900588,57.9176618202427,0.0028473509872745,11.676200622960929,57.969602579790575,0.0008964015725939
0.0010886675022415,59.2682500567386,0.0029522438184545,11.948479211438505,59.32336008031675,0.0009294085387906
0.0011277524358274,60.594238228884,0.0030763384825898,12.215798426943016,60.65294953184045,0.0009684564010033
0.0011634909053978,61.8617551402055,0.0031898081234758,12.47132983626543,61.92390541708068,0.0010041596388101
0.0012033695081207,63.1039469467614,0.003316422687121,12.721755704467098,63.16986170622632,0.0010439974236135
0.0012505533635153,64.368588495342,0.0034662314279988,12.976707440660944,64.43886138492262,0.0010911309340879
0.0012833497048275,65.6040900013465,0.0035703598116651,13.225784544271455,65.67786329470766,0.0011238909731977
0.0013164882850547,66.8017577954963,0.0036755748038864,13.467234371572054,66.87909160897928,0.0011569917823572
0.0013699837370012,67.935980993475,0.0038454228638166,13.69589376828456,68.01826211932952,0.0012104239487733
0.0014097123673059,69.0163577691585,0.003971561265034,13.913697726262356,69.10268932606235,0.0012501037324313
0.0014774543937425,70.1099808957929,0.0041866421989702,14.13417214859185,70.20242984211961,0.0013177588385597
0.0015286100772035,71.1539003796608,0.0043490614939589,14.344626316539616,71.25136579329423,0.0013688458505992
0.0015702781383751,72.149933805583,0.0044813575881787,14.545426655205532,72.25176991687316,0.0014104560479217
0.001628195274794,73.0639381489276,0.0046652444963087,14.729689930823806,73.17129598682617,0.0014682898799397
0.0016885760184422,73.9952498823127,0.0048569533573918,14.91744237627424,74.10844404840623,0.0015285802147091
0.0017447984711111,74.8997252007691,0.0050354596446155,15.09978460047505,75.018514033412,0.0015847152169004
0.0018121903770884,75.7711533668544,0.0052494289460934,15.275464518757849,75.89643062221279,0.0016519981469286
0.0018701973998865,76.5877388980425,0.0054336012434774,15.44008816184537,76.7188088927863,0.0017099077445492
0.0019487922532503,77.3204874414106,0.0056831399029075,15.587810268188376,77.4588884327462,0.001788365244926
0.0020519953397434,77.9560066523678,0.0060108097025231,15.71593094111735,78.1035905015508,0.0018913786254819
0.002156735622779,78.5707942064556,0.0063433601011611,15.83987211202145,78.72777147923853,0.0019959155280389
0.0022743878737441,79.0482714381755,0.0067169059979753,15.93613152193618,79.21550287394012,0.002113326296324
0.0023937958506221,79.4679254608405,0.0070960263245629,16.020733772905448,79.64553380447154,0.0022324750931438
0.0025332506127834,79.8220156516544,0.0075387951944251,16.09211835537353,80.0115469360651,0.0023716091936829
0.0026708977603218,80.0775746627696,0.0079758248878595,16.143639052014354,80.27873520228292,0.0025089208550976
0.002819433760884,80.2958120357226,0.0084474266896445,16.18763570640168,80.50944762175638,0.002657073682521
0.0029677748556245,80.475560157378,0.0089184096654456,16.223872927727406,80.70161181518579,0.0028050102040794
0.003123824653385,80.6100263956423,0.0094138677733351,16.250981321361486,80.84903494042769,0.0029606107874987
0.0032704718594431,80.7033819128077,0.0098794726525696,16.269801793622033,80.95450218196595,0.0031068137821413
0.003434681325993,80.7632310496074,0.0104008377088655,16.28186737960085,81.02779963511624,0.0032705004747385
0.0035933526711674,80.840258094088,0.0109046192297943,16.29739603176814,81.1179060414752,0.0034286412279589
0.0037590958136122,80.9035976548347,0.0114308537070565,16.310165287214677,81.19487236008415,0.003593803429696
0.0039305894209367,80.9156368903711,0.0119753459103118,16.312592397098815,81.22083145456493,0.0037646672307864
0.0040978563049405,80.9415340502164,0.0125064182670239,16.31781326452363,81.26036513053344,0.0039312917118306
0.0042743283773359,80.9704346152247,0.0130667170968792,16.3236396184293,81.30366855611557,0.0041070559355017
0.0044613409073276,81.0086948684982,0.0136604818796029,16.33135288548924,81.35723591049549,0.0042932846280306
0.0046381357101047,81.0334964600696,0.0142218053784202,16.33635288635003,81.3964705122863,0.0044693065346713
0.0048258004185013,81.0315681280733,0.0148176408275794,16.33596413461958,81.40974030829923,0.0046561169332955
0.0050087087099788,81.0407502400741,0.0153983746530205,16.33781524839894,81.43378829813979,0.0048381589913185
0.0051891941995049,81.063616203967,0.0159714160822658,16.34242502671975,81.47139596570769,0.0050177572435988
0.0053850592418705,81.0807952315992,0.0165932875917766,16.3458883186904,81.50454230355129,0.005212622956788
0.0055672100696521,81.0843557964908,0.0171716164699832,16.346606128572546,81.52289105931064,0.0053938103559106
0.0057468885376626,81.0342695783903,0.0177420956059165,16.336508747003485,81.4870940691668,0.0055725063142828
0.0059442866881451,81.0673264263391,0.0183688347336985,16.34317300754996,81.53633818111965,0.0057687882569647
0.0061299441618547,81.0700337484003,0.0189582972127264,16.343718803677504,81.55411242394297,0.0059533607607756
0.006326001844429,81.0599395161341,0.0195807803548998,16.341683806452632,81.55985034172366,0.0061482357193803
0.006516455293583,81.0553820986683,0.0201854700559638,16.34076503109153,81.5707020949604,0.0063375038957649
0.006701160170721,81.0440131379329,0.0207719080408769,16.33847304860727,81.57423007908716,0.0065210250654002
0.0068970269845704,81.0303919873093,0.0213937851748488,16.335727024641557,81.57639097906056,0.0067155998514054
0.0070932560584251,81.0539815516801,0.0220168124843375,16.340482680818706,81.61604464236744,0.0069104965507319
0.007279762370561,80.9839854969094,0.0226089700253689,16.326371476176934,81.56066722939272,0.0070957013032424
0.0074642167752811,80.9470554896866,0.0231946127603553,16.318926386720822,81.53840528690684,0.0072788347372332
0.0076491441977645,80.9176437949445,0.0237817573267401,16.31299698906081,81.52374261956905,0.0074624041406717
0.0078389126567453,80.8988947397072,0.0243842721840041,16.30921717952497,81.52020518654756,0.0076507440043972
0.0080294327498309,80.8684823845568,0.0249891734795509,16.30308604872665,81.50496633269402,0.0078397941676622
0.0082189552717237,80.8412641782601,0.0255909074865605,16.29759885833724,81.4928551428845,0.0080278190032772
0.0084127358177113,80.833561153826,0.0262061607200711,16.29604592861132,81.50075400269934,0.0082200316675807
0.0086056089897428,80.8350458091501,0.0268185330412712,16.29634523512466,81.51784182392974,0.0084113076199174
0.0088123018092633,80.824669109189,0.0274747827432487,16.294253292412503,81.52408335299056,0.0086162481721112
0.0090479516302563,80.8052513630818,0.0282229709249015,16.29033867479729,81.5235393189242,0.008849849011185
0.0092750168527984,80.7906538229926,0.0289439030064727,16.287395810715307,81.52715676727045,0.0090748882832375
0.0095023080314989,80.7750800534307,0.0296655524988468,16.28425613877163,81.52980048742239,0.0093001007885195
0.0097244384257376,80.7479572189793,0.0303708165005546,16.278788175346225,81.52036080685087,0.0095201507114698
0.0099546009617891,80.7131718383305,0.0311015825525182,16.271775442607428,81.50381983108811,0.0097481064787709