File: example/data/02 processed data/test_ID_126.csv
Strain,Stress_MPa,Displacement(mm),Force(kN),True Stress (MPa),True Strain
-8.61299125253971e-05,0.0080770100321853,-0.00027346247226813576,0.0016283252224885568,0.008076314360017761,-8.613362191934499e-05
-0.0001117324424004,0.280211713848883,-0.00035475050462127,0.056490681511934815,0.2801804051097055,-0.00011173868493471206
-0.0001369838850154,0.734317679071473,-0.000434923834923895,0.14803844410080896,0.7342170893829584,-0.00013699326816465397
-0.0001495678709639,1.27761806530535,-0.00047487799031038243,0.25756780196555856,1.2774269746914173,-0.00014957905735331624
-0.0001933726851443,2.20455914195408,-0.0006139582753331525,0.4444391230179426,2.204132840433241,-0.0001933913840525905
-0.0002167242868205,3.47428021089138,-0.0006880996106550874,0.7004148905157023,3.47352724999046,-0.00021674777492245158
-0.0002138062372777,5.06462871035137,-0.0006788348033566975,1.021029148006836,5.0635458611436,-0.0002138290970897238
-0.0002077232345262,6.89860175291574,-0.000659521269620685,1.390758113387813,6.897168753045916,-0.0002077448119854506
-0.0001891715488419,8.85497394462419,-0.0006006196675730325,1.7851627472362368,8.85329883548813,-0.00018918944403622663
-0.0001655065476647,10.8782537301519,-0.0005254832888354225,2.1930559519986232,10.876453307932403,-0.000165520245384729
-0.0001338730481344,12.9502566455605,-0.0004250469278267199,2.610771739744997,12.948522955229237,-0.00013388200993073792
-8.91545074284982e-05,15.0386769655199,-0.0002830655610854818,3.031797276248812,15.037336199682661,-8.915848192785268e-05
-5.40240124137806e-05,17.0642264872278,-0.0001715262394137534,3.440148059825124,17.06330460924422,-5.4025471763352415e-05
-1.76233992276103e-05,19.1057430176388,-5.59542925476627e-05,3.8517177923559824,19.10540630950206,-1.7623554521542285e-05
2.28625527035225e-05,21.1517839133034,7.258860483368393e-05,4.2641996369219655,21.15226749707789,2.286229135927621e-05
5.5078962799991e-05,23.1857559363502,0.00017487570688997143,4.674248396768201,23.18703298373891,5.507744600961626e-05
0.000101119308345,25.2206034253681,0.00032105380399537496,5.084473650554209,25.22315371534252,0.000101114196132476
0.0001416286960716,27.3034943310676,0.00044967111002733,5.504384457143228,27.307361289367908,0.00014161866767467988
0.0001863564155103,29.3792221229315,0.0005916816192452025,5.922851179982991,29.384697129456807,0.00018633905331043977
0.0002372866927499,31.4921621451258,0.0007533852494809324,6.348819888457362,31.499634816128758,0.00023725854471520844
0.0002804817032993,33.5579015657658,0.0008905294079752774,6.765272955658386,33.56731394315612,0.00028044237565998093
0.0003211076480067,35.5896545954546,0.0010195167824212723,7.174874366443647,35.60108270573512,0.00032105610397976795
0.0003708859118733,37.6397546427683,0.0011775627701977275,7.58817453598209,37.65371469749168,0.00037081715069476077
0.0004123063319028,39.6751061487252,0.0013090726037913898,7.9985013995830005,39.69146444620923,0.0004122213570034721
0.0004635344727527,41.6587690850368,0.0014717219509898223,8.39840784754342,41.67807936060016,0.00046342707383633915
0.0005111815719129,43.6244298782582,0.0016230014908234576,8.794685063456852,43.646729882897176,0.000511050963121233
0.0005462058413581,45.5569070740062,0.0017342035463119674,9.18427246611965,45.58179052276423,0.0005460567252438069
0.0005914825996849,47.4786219486615,0.0018779572539995573,9.571690184850159,47.50670472740115,0.0005913077427984974
0.000636077517874,49.4271184188286,0.00201954611924995,9.964507073235845,49.45855789762811,0.0006358753063132143
0.0006857137978659,51.3258564958951,0.0021771413082242322,10.347292669572452,51.36105134388163,0.0006854788035794271
0.0007440842737948,53.2048493712905,0.00236246756929849,10.726097633252166,53.244438262997306,0.0007438075803386471
0.000786617827505,55.0993784744138,0.002497511602328375,11.108034700441822,55.14272062780622,0.0007863086058507204
0.0008260866920766,57.0093101104165,0.002622825247343205,11.493076918259968,57.05640474282318,0.0008257456702613412
0.0008799300073173,58.9144997291805,0.002793777773232427,11.877163145402788,58.966340365358285,0.0008795430958617071
0.000920969806466,60.8121971062964,0.00292407913552955,12.259738936629356,60.86820330369616,0.0009205459739784975
0.0009765175977231,62.6879799956375,0.003100443372770842,12.63789676712052,62.74919591126895,0.0009760411145845445
0.0010280164552977,64.5427688494582,0.0032639522455701975,13.011822200050775,64.60911987790591,0.0010274884082444706
0.0010749850035631,66.393846548097,0.0034130773863128424,13.384999464096357,66.46521893746508,0.0010744076209323018
0.0011206839561617,68.2227084087316,0.0035581715608133976,13.75369801520029,68.29916450349117,0.001120056458670741
0.0011709803224396,69.9907473368941,0.00371786252374573,14.11013466311785,70.07270512477845,0.001170295259726277
0.0012140058131298,71.7291692849126,0.003854468456687115,14.46060052783838,71.81624891339546,0.0012132695039348271
0.0012700686771582,73.3894992936832,0.0040324680499772845,14.795323057606534,73.48270899796844,0.0012692628221912044
0.0013148257958453,75.0285515822726,0.0041745719018088275,15.125755998986156,75.12720105731788,0.0013139621693379743
0.0013568912849044,76.6743108323112,0.00430812982957147,15.45754106379394,76.77834953645562,0.0013559715398269792
0.0013948270919171,78.2453361544359,0.004428576016836792,15.774259768734279,78.35447486912027,0.0013938552242288534
0.0014404848885971,79.8041051661712,0.004573539521295793,16.088507601500115,79.91906177371109,0.0014394483854986613
0.0014882453070287,81.3604224254569,0.004725178849816122,16.402261160972113,81.48150669230945,0.0014871389675153778
0.0015267959297709,82.8843093714689,0.0048475770770226075,16.70947676928813,83.01085679765913,0.001525631561882746
0.0015701366088043,84.4355200022774,0.004985183732953652,17.022200832459124,84.56809530331641,0.0015689052331027203
0.0016126237019826,85.9501308954215,0.005120080253794754,17.327546388516975,86.08873611369197,0.0016113248205976856
0.0016556281108802,87.4194639622923,0.005256619252044634,17.623763934798127,87.56419808426634,0.0016542590695333174
0.0016974201121998,88.9031276123107,0.005389308856234365,17.922870526641837,89.0540335691573,0.00169598112283064
0.0017376102730523,90.3825082757461,0.005516912616941053,18.221113668390416,90.53955785063026,0.0017361023748286154
0.0017786496404699,91.8318167051585,0.005647212608491932,18.513294247759955,91.99515333292483,0.00177706971634172
0.001819552363821,93.2648415467004,0.005777078755131675,18.8021920558148,93.43454180959807,0.00181789898372254
0.0018641060297776,94.7032412896949,0.0059185366445438795,19.092173444002494,94.8797781728225,0.0018623707403067436
0.001909869672539,96.1608355407259,0.006063836210311324,19.386024445010342,96.34449020421114,0.0019080481902830659
0.0019530476514269,97.6063891840484,0.006200926293280407,19.677448059504158,97.79701911320856,0.0019511429334626133
0.0019985059670126,99.0635497910637,0.006345256445265005,19.971211637878444,99.2615288864346,0.0019965116106758856
0.0020450817055134,100.474905894207,0.006493134415005045,20.25574102827213,100.68038528611442,0.002042993372645066
0.0020825453946443,101.885782879724,0.0066120816279956526,20.540173828552362,102.0979646476399,0.002080379902952525
0.0021323441265559,103.291413511257,0.006770192601814982,20.823548963869413,103.5116663501814,0.0021300739075049337
0.0021650997227772,104.692221305576,0.006874191619817609,21.105951815204122,104.91889040490162,0.0021627592719697876
0.0021977056020862,106.076323944556,0.006977715286623684,21.384986907222487,106.30944847593764,0.0021952941795476293
0.0022411042912392,107.444888406505,0.00711550612468446,21.660889502751406,107.68568360698453,0.0022385967627401105
0.0022710144243616,108.770912428595,0.00721047079734808,21.92821594560475,109.01793273967131,0.0022684395687231087
0.0023020747037558,110.058206839409,0.0073090871844246645,22.187734498824852,110.31156905331473,0.0022994289894283943
0.0023382695135964,111.381187480029,0.007424005705668569,22.454447395973848,111.64162671510172,0.0023355400154775013
0.0023781087672975,112.704328816405,0.007550495336169563,22.721192689387248,112.97235196887569,0.0023752855417154915
0.0024224779624047,114.040817753653,0.007691367530634922,22.990628859136446,114.31707912147584,0.0024195484927621155
0.0024697818489209,115.342203805574,0.007841557370323857,23.25298828720372,115.62707388694756,0.0024667369501902795
0.0025062334760191,116.656214997539,0.007957291286360642,23.517892943503863,116.9485827087515,0.002503098110447049
0.0025588255988143,117.984652395155,0.008124271276235401,23.78570592286325,118.28655454397092,0.0025555573786081617
0.0026126202687906,119.350274824217,0.008295069353410154,24.061015404562145,119.66209177130847,0.00260921330922708
0.002659567624691,120.652144516758,0.008444127208393925,24.323472334578415,120.9730270541643,0.0026560372328743526
0.0026980158360325,121.949810215218,0.008566200279403188,24.58508173938795,122.27883273437982,0.0026943827246344197
0.0027502387141821,123.211449819659,0.008732007917528168,24.839428283643258,123.55031071898351,0.002746463727515194
0.0028034496134612,124.478770183547,0.00890095252273931,25.094920069003074,124.8277401437022,0.0027995272775975543
0.0028509842136977,125.763986377308,0.009051874878490197,25.35401965366529,126.1225375171214,0.002846927866097366
0.0029106811629568,127.012754924811,0.009241412692387839,25.6057713928419,127.38244855802591,0.0029064533324649183
0.0029652748943572,128.258072427396,0.00941474778958411,25.856827401363034,128.6383928695636,0.002960887138552363
0.0030329957453222,129.475213607392,0.009629761491397984,26.102203063250226,129.8679113793879,0.0030284054928619007
0.0031032767533006,130.655376519236,0.009852903691729404,26.340123906277977,131.06083631188187,0.0030984715287246337
0.0031783343989823,131.784378787806,0.010091211716768802,26.56773076362169,132.2032336121558,0.003173294171069184
0.0032567572973938,132.885296701345,0.010340204419225315,26.789675814991153,133.31807186109344,0.003251465549526341
0.0033442451778331,133.929008570467,0.010617978439620092,27.000088127806148,134.37690001155076,0.0033386656260605864
0.0034301623126991,134.963343190426,0.010890765342819643,27.208609987189885,135.4262893638337,0.0034242927245503236
0.0035272018547271,135.905430329406,0.011198865888758541,27.398534754408246,136.38479621533133,0.003520995867164184
0.0036371572395226,136.796554664248,0.011547974235484254,27.578185420312398,137.2941052433868,0.0036305587780513077
0.0037595176674477,137.606938960693,0.011936468594146446,27.741558894475705,138.1242746788791,0.0037524683434163398
0.0038885851212022,138.345776639389,0.012346257759816985,27.89050857050082,138.8837459680101,0.003881044116982594
0.0040111669283106,139.022502834693,0.012735454997386155,28.026936571474106,139.58014530035447,0.004003143646239861
0.0041566583460951,139.61156861181,0.013197390248851942,28.145692232140895,140.1918862036917,0.0041480433067243696
0.0043076265820965,140.123692021308,0.013676714398156386,28.24893631149569,140.72729256184047,0.004298375316527757
0.0044582884646442,140.525834978221,0.014155065875245334,28.330008331609356,141.15233968728893,0.004448379736357587
0.0046116605801846,140.865749067085,0.014642022342086105,28.398535011924338,141.51537408915587,0.004601059453568337
0.0047700297236588,141.141466952747,0.015144844372616689,28.454119737673796,141.81471594535242,0.004758689180728918
0.0049263757596666,141.36351199903,0.015641243036941452,28.49888401900445,142.05992177784339,0.004914280876963956
0.0051046928739588,141.527827780266,0.01620739987481919,28.532010080501625,142.2502838742028,0.005091708099401048
0.0052803568785851,141.636466822288,0.01676513308950769,28.553911711373264,142.38435791413156,0.005266464676599921
0.00545783971491,141.692010643329,0.01732864109483925,28.565109345695127,142.46534292630363,0.005442999679601935
0.0056418680977453,141.748221156827,0.017912931210341328,28.576441385216324,142.5479459236838,0.005626012369260132
0.0058291615901377,141.767245283502,0.0185075880486872,28.58027664915401,142.59362946444824,0.005812237763679943
0.0060245604626369,141.780138833582,0.019127979468872156,28.58287598885013,142.63430185238596,0.006006485358295545
0.0062212204301104,141.770050012282,0.019752374865600518,28.580842082476057,142.65203274379618,0.006201948526827873
0.0064203174425772,141.738081729765,0.020384507880182607,28.574397276720628,142.64808520817206,0.00639979499811423
0.0066175956830496,141.702068793547,0.021010866293682477,28.567137068779076,142.63979579227438,0.006595795520327631
0.006820385880955,141.642531990594,0.021654725172032124,28.55513444930375,142.60858871592535,0.006797232267272831
0.0070273693347471,141.592001322808,0.022311897637822042,28.544947466678092,142.58702061094937,0.0070027924482595795
0.0072371941497464,141.546398465306,0.022978091425444817,28.53575393060569,142.57079723219678,0.007211131332398308
0.0074387188731517,141.479685116594,0.023617932422256644,28.52230451950535,142.53211272043836,0.007411188048989557
0.0076486025861027,141.402044791509,0.024284313210876072,28.506652229968218,142.48357283698155,0.007619500325559216
0.0078553312152244,141.320777009486,0.024940676608337466,28.49026864511238,142.43089852048837,0.007824638729290031
0.0080667568579295,141.247887321219,0.02561195302392616,28.47557408395775,142.3872996849355,0.008034394497859969
0.0082740238621885,141.171479367501,0.026270025762448485,28.460170240488207,142.33953555644817,0.00823998177454541
0.0084904567438652,141.094433717224,0.02695720016177201,28.44463783739236,142.29238990350026,0.008454615545210153
0.0086961027533882,141.010713421305,0.027610126242007534,28.427759825735095,142.23695707454527,0.008658509438184227
0.0089141438967144,140.930947166903,0.02830240687206822,28.411678948847644,142.187225909449,0.008874647460418184
0.0091292882035129,140.858522707469,0.028985490046153455,28.39707817782575,142.14446075718658,0.009087868151500906
0.009347252624293,140.769128291919,0.029677527082130273,28.379056263650874,142.0849328957651,0.009303837390893552
0.009561174228694,140.673511941373,0.030356728176103447,28.359780007380795,142.01851589840675,0.009515755477277569
0.0097841125587612,140.586499042409,0.03106455737406681,28.342238206949656,141.96201317328212,0.009736558063572825
0.0100026902021798,140.477480403873,0.031758541391920865,28.320260049420796,141.8826331207357,0.009952994416135348
0.0102284802799989,140.379280753309,0.03247542488899651,28.30046299986709,141.81514745821465,0.010176523368721064
0.0104506740935487,140.299670961019,0.03318089024701712,28.284413665741425,141.7658970976647,0.010396443304020255
0.0106736138876519,140.222635407528,0.033888724093294784,28.268883298157643,141.71931767617696,0.010617052987782193
0.0108903074934275,140.143956362254,0.03457672629163231,28.253021602630408,141.67016714038442,0.01083143513450884
0.0111081021184215,140.046046411782,0.035268224225988264,28.23328295661525,141.60169219660526,0.011046860255320909
0.011328965446772,139.947893270395,0.0359694652935011,28.213495283311637,141.53335811760385,0.01126527331031362
0.0115474607432325,139.845948793466,0.036663187859763184,28.192943276762744,141.46081439725864,0.011481297674907723
0.0117783670626452,139.733868361674,0.037396315423898506,28.17034786171348,141.37970515432116,0.011709542001394312
0.0119959912589898,139.626156716302,0.03808727224729261,28.148633194006486,141.3011108717971,0.011924609650896343
0.0122096801094109,139.515590497836,0.0387657343473796,28.12634304436374,141.21903122809016,0.01213574318760906
0.0124279439276199,139.39114697034,0.03945872197019318,28.10125522922055,141.123492328894,0.012351350974862571
0.0126509612193437,139.280035038102,0.04016680187141625,28.078855063681363,141.04206135999786,0.012571606385215902
0.01286923385487,139.182150474269,0.04085981748921225,28.059121535612633,140.97331811714608,0.012787128932857649
0.0130879209032794,139.105211152439,0.041554148867912095,28.043610568331705,140.92580915323612,0.013003014099772748
0.0132990172193414,139.018108539801,0.04222437967140894,28.026050681623882,140.8669127590721,0.013211361590426402
0.0135323839237114,138.929788068973,0.04296531895778369,28.00824527470496,140.8098392995622,0.013441638963541442
0.0137562918493121,138.849095758068,0.043676226621565915,27.99197770482651,140.75914444232907,0.013662532938027692
0.0139884209667396,138.779469524657,0.044413236569398225,27.977941056170852,140.72077516590872,0.013891485938841154
0.0142203841345312,138.713540984046,0.045149719627136556,27.964649862383677,140.6861008215002,0.014120222909334096
0.0144484655949368,138.627650945155,0.04587387826392434,27.94733443054325,140.630607790343,0.014345081157043742
0.0146786052422988,138.513844678711,0.04660457164429869,27.924391087228138,140.54703472534288,0.014571917269632495
0.0149085829246427,138.420201404628,0.047334750785740565,27.905512603173,140.48385045571462,0.014798542353461487
0.0151224310396185,138.318529997791,0.04801371855078873,27.885015647554667,140.410242429184,0.015009226933446543
0.015354445613056,138.208230818756,0.0487503648214528,27.86277933306121,140.33034158213928,0.015237759035550406
0.0155794321926244,138.097155283681,0.04946469721158247,27.840386505190086,140.2486305504174,0.015459318765236643
0.0158019166315177,137.984341989695,0.05017108530506869,27.817643345122512,140.164759058271,0.015678366202992997
0.0160284748550521,137.8777717837,0.050890407664790416,27.79615879159392,140.08774218180565,0.01590137519569493
0.0162556278380308,137.763890758398,0.051611618385747786,27.773200376893037,140.00332929608564,0.016124919712550263
0.0164725507190569,137.651160081401,0.05230034853300566,27.750473872410446,139.9186257973789,0.016338350002087026
0.0166997768940695,137.541087783088,0.05302179163867066,27.72828329707054,139.83799326283318,0.01656186885769282
0.0169205300977391,137.437340900407,0.053722683060321644,27.707367925522053,139.76285356366557,0.01677897251640202
0.0171423309594548,137.356059366653,0.05442690079626899,27.690981568317245,139.71066239560267,0.016997059053294454
0.0173736405293585,137.261853459448,0.055161308680713235,27.671989657424717,139.64659155984592,0.017224444410934264
0.0176076199232273,137.155810707729,0.05590419325624668,27.650611438678165,139.5707980929328,0.01745440170778707
0.0178333829967127,137.087849728253,0.05662099101456282,27.636910505215802,139.53258985665272,0.017676233806174956
0.0180665021583892,137.021541317008,0.0573611443528857,27.623542729508813,139.49704128895755,0.017905242279916796
0.0182977112424775,136.94489455831,0.058095233194866064,27.608090742955298,139.4506726950695,0.018132322566989566
0.0185332120737641,136.861345100619,0.05884294833420101,27.59124717228479,139.39782543406938,0.01836356496383261
0.0187709674089035,136.780963322993,0.05959782152326861,27.575042205915388,139.34847432768734,0.01859696686681138
0.0190004283524523,136.713593074031,0.060326360019036046,27.56146036372465,139.31120990404045,0.018822174606007065
0.0192339910067081,136.641279907677,0.06106792144629822,27.54688202938768,139.26943705656632,0.01905135595341216
0.0194684735760972,136.569418979873,0.06181240360410861,27.532394866342397,139.2282171045856,0.019281387136968045
0.0197103856342085,136.482385856879,0.06258047438861197,27.51484898874681,139.17250631439492,0.019518651326083592
0.0199485249841699,136.392989187446,0.06333656682473943,27.496826620189115,139.1138281399174,0.019752160320949213
0.0201789863489383,136.299003505917,0.0640682816578791,27.477879106792866,139.0493792370368,0.01997808871460932
0.0204071349642545,136.197950637634,0.06479265351150804,27.457506848547013,138.97736059815105,0.020201699581981095
0.0206506840042168,136.077253154817,0.06556592171338833,27.433174236011105,138.88734150987895,0.020440349402534815
0.020883098106475,135.965056419624,0.06630383648805813,27.410555374196203,138.80442803188743,0.020668035180060187
0.0211174071819477,135.8598172076,0.06704776780268394,27.389339149052162,138.7288242872379,0.02089752491416589
0.0213475130678941,135.762226257696,0.06777835399056376,27.369664813551513,138.66041215685857,0.021122846665975265
0.0215857364043566,135.648828126796,0.0685347130838322,27.346803750362074,138.57690797430087,0.021356063622626868
0.0218255917255266,135.546343799236,0.06929625372854695,27.32614290992598,138.504722958886,0.02159082332956368
0.0220633229318751,135.446239785178,0.07005105030870344,27.305961940691883,138.43463391346657,0.02182344967800742
0.0222890169891574,135.364557380083,0.07076762894057474,27.28949476782473,138.38170029925743,0.022044247290818
0.0225186681127557,135.30037294885,0.07149677125799934,27.27655518648816,138.3471571428172,0.02226886609114523
0.0227541826641276,135.209754339873,0.07224452995860513,27.258286474918396,138.2863417880943,0.02249916744416366
0.02298435535535,135.083884500482,0.07297532825323624,27.23291111529717,138.18870050462212,0.022724193944780393
0.0232181710165543,134.978279306615,0.0737176929775599,27.211621108213585,138.1122280790762,0.02295273013238497
0.0234501244267176,134.873853182831,0.07445414505482838,27.190568801658728,138.03666182187922,0.02317939452316374
0.0236892509006359,134.767603348009,0.07521337160951898,27.169148834958616,137.96014691699736,0.023413014644869116
0.0239265801558166,134.669881749044,0.07596689199471769,27.14944816060727,137.89207146928686,0.02364482498022976
0.02417024872051,134.575182546073,0.07674053968761925,27.13035680128832,137.8278981798196,0.023882771314023696
0.0244140971579013,134.479586282497,0.07751475847633663,27.111084594551393,137.76278396775223,0.024120836628769956
0.0246605119690972,134.433741300106,0.07829712550188361,27.10184224610137,137.74894618648779,0.024361349893915404
0.0249048562652649,134.3758951225,0.07907291864221605,27.090180456696,137.72250747604218,0.024599785126196688
0.0251549291763825,134.323051209457,0.07986690013501443,27.07952712382653,137.70193804938646,0.02484375158428116
0.0254027603549957,134.250993462855,0.08065376412711134,27.06500028211157,137.66133927721202,0.025085472342575674
0.0256493826789176,134.169126483029,0.08143679000556338,27.04849589897865,137.61048175188833,0.025325956063038946
0.0258937589310424,134.071078467003,0.08221268460605961,27.028729418947805,137.54268265245244,0.025564192586877053
0.0261318918826787,133.97264243286,0.08296875672750487,27.008884714464575,137.47360104015226,0.025796288080040974
0.0263796277416941,133.852868432856,0.08375531807987877,26.984738276063773,137.3838572742727,0.026037685858177437
0.0266206504717611,133.760240791892,0.08452056524784149,26.966064543645427,137.32102540903156,0.02627248634382
0.0268545858753903,133.605929707302,0.0852633101543642,26.934955428992083,137.19386162008811,0.02650032975824296
0.0270937506142471,133.473183910934,0.08602265820023454,26.908193876444297,137.0894730695064,0.026733212675197265
0.0273429605050351,133.353487989696,0.08681389960348644,26.884063178722712,136.99976714500693,0.026975819216115807
0.027586627301364,133.238507663489,0.0875875416818307,26.860883144959384,136.9141087165916,0.027212972643578172
0.0278382738405347,133.156739458557,0.08838651944369767,26.844398674845092,136.86359323531707,0.027457833489905537
0.0280826746187616,133.061912454336,0.08916249191456807,26.825281550794138,136.79864684594128,0.027695586580131475
0.0283281430443684,132.950526370752,0.08994185416586967,26.8028261163436,136.71676789960674,0.027934321393880027
0.0285801282758082,132.900274072728,0.09074190727569102,26.792695253061964,136.69858095361664,0.02817933497685194
0.0288229558620331,132.835022823915,0.09151288486195508,26.779540601301264,136.66372082370088,0.028415387492982253
0.0290650041982069,132.740579634624,0.09228138832930691,26.760500854340197,136.59868513897675,0.028650627060915482
0.0293156011672123,132.647014317477,0.09307703370589905,26.74163808640336,136.53564128522964,0.02889411650071132
0.0295616909451056,132.546523625448,0.09385836875071027,26.721379162890315,136.46482299271162,0.029133168900781995
0.029810586188398,132.47011839771,0.09464861114816364,26.705975868978335,136.4191302795922,0.029374888425967343
0.0300658496369335,132.389417771804,0.09545907259726386,26.68970662279569,136.36981810005224,0.02962273188434443
0.0303170030992244,132.286975445656,0.09625648484003747,26.669054249844248,136.29752009022897,0.029866524889320463
0.0305779820062963,132.192237256603,0.09708509286999074,26.649955030931164,136.23440910880745,0.03011979243604474
0.0308277783070518,132.125637637602,0.09787819612488946,26.636528547740568,136.19877750337187,0.030362147732403477
0.0310759468865543,132.055480630007,0.0986661313648099,26.62238489500941,136.15922973214347,0.030602865645338456
0.0313294863040662,131.940261803399,0.09947111901541018,26.59915677956524,136.07388242852352,0.030848733324611428
0.0315798201225194,131.831781188021,0.10026592888899909,26.577287087505038,135.99500512437007,0.03109143310680942
0.0318302094030233,131.73569403485,0.10106091485459898,26.557915917425763,135.92886876183192,0.03133412775125728
0.03208184356767,131.650411798112,0.10185985332735224,26.54072301849938,135.87399971503837,0.0315779696974596
0.0323209484952688,131.562201432508,0.10261901147247844,26.522939808793613,135.8144165689323,0.031809615313893966
0.0325810154507088,131.472227769064,0.10344472405600044,26.504801118243304,135.755726453347,0.03206150810237108
0.0328387872552216,131.366616392248,0.10426314953532859,26.4835098646772,135.68053676039133,0.03231111528199949
0.033097031159079,131.301863891162,0.10508307393007582,26.470455760458258,135.64756577161293,0.03256111714836984
0.0333618651469885,131.217730053425,0.10592392184168849,26.45349437877048,135.5953982683613,0.03281743387437177
0.0336205444829139,131.132789325627,0.10674522873325162,26.4363703280464,135.5415451023178,0.033067730476868916
0.0338865093997866,131.049272503551,0.10758966734432246,26.419533336715887,135.4900749080778,0.03332501126131938
0.0341540402750531,130.974649731657,0.1084390778732936,26.404489385902053,135.447963193603,0.033583740111487126
0.034421546058843,130.888515618573,0.1092884087368265,26.38712474870432,135.39390068751132,0.033842377781822655
0.0346830708814622,130.79157596467,0.11011875004864247,26.36758171447747,135.3278294645508,0.034095168116222103
0.0349443983604751,130.693645927228,0.11094846479450844,26.347839018929168,135.26065675369196,0.03434770388344152
0.0352031673419931,130.585593382074,0.11177005631082809,26.326055625826115,135.1826198783566,0.03459770440239277
0.0354623509853165,130.492982051303,0.11259296437837987,26.30738518154268,135.1205699819269,0.034848042897319166
0.0357259908326086,130.396009320146,0.1134300208935323,26.287835478941435,135.0545359537263,0.03510262124096187
0.0359990692181832,130.296974392779,0.11429704476773166,26.267870037584245,134.9875441928645,0.035366245398840715
0.0362551965206245,130.199834904749,0.11511024895298277,26.2482867167974,134.92025550617356,0.03561344219122296
0.0365207804462924,130.119224160036,0.11595347791697837,26.23203559066326,134.87127977742657,0.035869701362568424
0.0367907147317685,130.030346782168,0.11681051927336498,26.214117911285072,134.8142561771037,0.036130090877244975
0.0370562326754114,129.959291663171,0.1176535387444312,26.19979319929527,134.77509341337313,0.03638615407942639
0.0373217196811849,129.828681618784,0.11849645998776207,26.173462214346856,134.67411128073806,0.036642121905271614
0.0375807409932722,129.684892694931,0.11931885265363923,26.14447436729809,134.5585470580395,0.03689179273880926
0.03784082262908,129.557811043239,0.120144611847329,26.118854706316984,134.4603851911381,0.03714242291604932
0.0381037037721427,129.442509447352,0.12097925947655307,26.095609904586162,134.3747484828567,0.03739568704823073
0.0383745075684813,129.349939798184,0.12183906152992811,26.0769478633139,134.31368004195204,0.03765651694415248
0.0386358698173512,129.248685740399,0.12266888667009004,26.056535045264436,134.2423211367288,0.037908188532407454
0.0388987888261247,129.161596422623,0.12350365452294591,26.038977838800797,134.18582608631178,0.03816129527032229
0.0391681848924817,129.108811582632,0.1243589870336294,26.02833641505861,134.16576938594912,0.038420570906067535
0.0394406104066561,129.062071367109,0.1252239380411331,26.018913587609177,134.15235824217518,0.03868269383785761
0.0397132091356459,128.971611352294,0.1260894390056757,26.000676848622472,134.09348792648888,0.03894491467788354
0.0399828352745061,128.86749547244,0.12694550199655685,25.979687087243907,134.01998331615275,0.03920420847333577
0.0402410484188869,128.766655717918,0.1277653287299659,25.959357792732273,133.94836094540088,0.03945246362291936
0.040511191958737,128.653158477088,0.12862303446898998,25.93647674898094,133.86505127625114,0.03971212312117757
0.04079454142811,128.506628557562,0.12952266903424925,25.9069363172045,133.7489975400402,0.03998440360989007
0.0410621435722285,128.380772013033,0.1303723058418255,25.881563637827455,133.6523617053457,0.04024148388589607
0.0413170811971458,128.269514157109,0.1311817328009379,25.859134054073174,133.5692360886567,0.04048633614254414
0.0415891215036412,128.171618841647,0.1320454607740608,25.839398358476032,133.50216387097063,0.040747548392706535
0.0418625212825363,128.068551489417,0.13291350507205274,25.81861998026647,133.4298239517663,0.04100999727786401
0.0421395146074511,127.96238019023,0.13379295887865722,25.79721584635037,133.3546527794604,0.041275825546527437
0.0424112864298271,127.880211586054,0.13465583441470103,25.780650655748488,133.30377586833706,0.04153657412006253
0.0426740279942767,127.812913248138,0.1354900388818285,25.767083310824624,133.2672050861191,0.041788594086845356
0.0429464722993548,127.739292814499,0.13635504955045147,25.752241431403,133.22524481489606,0.04204985379980793
0.0432313705711571,127.630980935757,0.1372596015634238,25.73040575664861,133.148643168951,0.0423229832212012
0.0434999744809999,127.516786803485,0.1381124189771747,25.70738421958258,133.0637637753357,0.04258042307991909
0.0437778500922315,127.425435926243,0.138994674042835,25.68896788273059,133.0038475581593,0.04284667955004667
0.0440514799816559,127.330390676109,0.13986344894175748,25.669806760303576,132.93948283203403,0.043108798571989286
0.0443232575717336,127.23339272583,0.14072634279025417,25.65025197352733,132.8727911633425,0.04336907522322905
0.0445993747933619,127.14409181596,0.14160301496892402,25.632248910097537,132.81463881962162,0.043633438506922174
0.0448825866807605,127.032633227402,0.14250221271141458,25.609778858644244,132.73418639951612,0.04390452186093504
0.0451630615916651,126.960586049683,0.1433927205535367,25.595254147616092,132.69451481715873,0.04417291304446745
0.045446319453947,126.889377773255,0.14429206426628172,25.58089855908821,132.6560329708509,0.04444389419147965
0.0457216609567326,126.810399509803,0.14516627353762598,25.56497654117629,132.60838160197804,0.044707231720512323
0.0460035489164492,126.721711534239,0.1460612678097262,25.547097045302586,132.55135998958053,0.044976758482529196
0.0462883974158572,126.621436377373,0.1469656617953466,25.5268815736784,132.4825397457755,0.04524904218716917
0.0465686779249118,126.516200942125,0.14785555241159495,25.5056661099324,132.40789315608222,0.04551688705248037
0.0468429185919844,126.403692744687,0.14872626652955048,25.482984457328904,132.3248106336526,0.04577889063466906
0.047133096896784,126.273530857494,0.1496475826472892,25.456743820870788,132.2251934228993,0.04605604596453992
0.0474148503133671,126.151712174559,0.15054214974494054,25.432185174391094,132.13317672409067,0.046325081026408824
0.0476940569936594,126.036596219429,0.1514286309548686,25.408977797836886,132.0477928228053,0.046591612929329444
0.0479754914906197,125.919067193351,0.15232218548271753,25.385283946179563,131.96009632999238,0.046860199643160905
0.0482636453819063,125.817168327093,0.1532370740875525,25.364741134741948,131.88956352218744,0.04713512428132175
0.0485508880607946,125.707327569556,0.15414906959302285,25.342597238022492,131.81052995880714,0.04740910433640412
0.0488382584525462,125.622648916555,0.15506147058683417,25.325526021577488,131.75784031183517,0.04768313111300644
0.0491015796860153,125.527348840598,0.15589751550309858,25.306313526264557,131.69093996246886,0.04793415950768669
0.0493789999938154,125.436737480595,0.15677832498036387,25.288046276087954,131.63067813987354,0.04819856062924359
0.0496669722827839,125.274666658058,0.15769263699783886,25.255372798264492,131.49668005469874,0.04847294460613453
0.0499602591790738,125.121254126509,0.1586238228935593,25.224444831904215,131.37234441148016,0.04875231505228107
0.0502326952878623,124.998442471116,0.15948880753896277,25.199686002176986,131.27745114322494,0.04901175417642167
0.0505056264945152,124.88746647238,0.16035536412008575,25.177313240831808,131.1949862078803,0.04927159730429591
0.0507888552734772,124.77329483325,0.1612546154932901,25.1542962383832,131.11038764653085,0.04954117282846417
0.0510785388680906,124.67308584612,0.16217436090618764,25.13409410657779,131.04120490731583,0.04981681685553736
0.0513631601926989,124.563078940868,0.163078033611819,25.11191671447899,130.9610323186036,0.05008756997699064
0.0516384085504906,124.487281956922,0.16395194714780764,25.096636042515474,130.91560708195365,0.05034933712301127
0.0518981046879514,124.376917826466,0.16477648238424566,25.07438663381555,130.83184412858867,0.05059625096277189
0.0521753502174669,124.236216554607,0.1656567369404574,25.04602125740877,130.71828466303668,0.05085978314172091
0.0524534224429139,124.105651374672,0.16653961625625163,25.019699317133874,130.61541753378066,0.051124031384144716
0.0527236081138459,123.978341182305,0.16739745576146073,24.994033582352692,130.5149266574055,0.05138071827412471
0.05300307531406,123.849962816982,0.16828476412214047,24.96815250390357,130.41439172381402,0.05164615367374657
0.0532788881374921,123.726571152247,0.1691604698365374,24.943276744292998,130.31858529630304,0.05190804911775128
0.0535693213563388,123.638198415704,0.17008259530637568,24.925460800605926,130.26141279855364,0.05218375310001034
0.0538566976111409,123.575440448656,0.17099501491537233,24.91280879444905,130.23080557706282,0.05245648035496203
0.0541480264870064,123.504106655319,0.17191998409624532,24.898427901712314,130.1916102937453,0.05273288284532634
0.0544364634900173,123.421136597812,0.17283577158080493,24.8817011381189,130.13974679411524,0.053006466385545944
0.0547300693810894,123.320111370052,0.17376797028495886,24.861334452202488,130.06942962141864,0.05328487578413326
0.0550234676756539,123.222507277574,0.17469950987020114,24.841657467158917,130.0026369236746,0.053563010922956206
0.0553116829775305,123.09862050483,0.17561459345365935,24.816681893773726,129.9074123771645,0.053836157397893485
0.0555952691062357,122.954616792032,0.17651497941229832,24.787650745273652,129.79031180043913,0.054104843926337104
0.0558865407851039,122.836889134914,0.17743976699270486,24.763916849598665,129.70181794946765,0.054380737073368914
0.0561749755526061,122.708270304657,0.17835554737952436,24.73798729341885,129.6014043891237,0.05465386810394188
0.0564680686976913,122.58194099297,0.17928611811516987,24.712519304182752,129.50390645805737,0.05493133395200658
0.0567503284621501,122.454458302419,0.18018229286732657,24.68681879376767,129.40378903273592,0.05519847128766165
0.057041700313791,122.325574382034,0.18110739849628643,24.660835795418055,129.30323313664636,0.05547415768397684
0.057332695425918,122.226806950967,0.18203130797728964,24.64092428131495,129.23439924676927,0.055749411787082155
0.0576185919850537,122.106949724815,0.18293902955254548,24.616761064522702,129.14258023954855,0.056019769371749836
0.0579056803999406,121.970896507646,0.1838505352698114,24.589332735941436,129.033704258912,0.056291180501744385
0.0581890588218758,121.84278926311,0.18475026175945564,24.56350631544298,128.93270649456255,0.05655901201077535
0.0584719538826412,121.695183312497,0.1856484535773858,24.533748955799393,128.8109384588849,0.05682631514599809
0.0587618570149027,121.546106353055,0.18656889602231605,24.503695040775888,128.68838127529136,0.057100165990983665
0.0590353266352232,121.364140491323,0.18743716206683364,24.467010723050716,128.52891216703136,0.05735842454751762
0.0593167035662767,121.204832122032,0.1883305338229285,24.434894155801654,128.3943032198149,0.05762408099054187
0.0595934957565507,121.073132142538,0.18920934902704847,24.408343439935663,128.28830332910664,0.0578853400018363
0.0598701696807322,120.940311572083,0.19008778873632473,24.381566812931933,128.18102854714422,0.058146419189241
0.0601487235661807,120.809909067666,0.19097219732262372,24.355277668041467,128.07647089223246,0.058409203533228385
0.06042734996824,120.689390113692,0.191856836149162,24.330981046920307,127.98233012754551,0.05867198722407549
0.0607110678888433,120.5629342343,0.19275764054707745,24.30548754163488,127.88243871947675,0.058939501988700876
0.0609959133525844,120.484603794651,0.19366202489445544,24.289696125001644,127.83367224802998,0.059208007930351345
0.0612737667081315,120.370943132084,0.1945442092983175,24.266782135428134,127.74652421999708,0.059469853406206974
0.0615346645470736,120.262781532504,0.19537255993695865,24.244976756952806,127.66311145160462,0.059715657819280045
0.0618137963601073,120.114735891987,0.19625880344334068,24.215130755824582,127.53948371626235,0.059978574452871504
0.0620957726172377,119.965803165819,0.19715407805972968,24.185105918229112,127.415172401048,0.060244100125815214
0.0623777954093215,119.800123922516,0.19804950042459576,24.151704982779226,127.27299154256605,0.06050959911623314
0.0626511305278896,119.646884483079,0.1989173394260495,24.120811911788728,127.14289706008373,0.06076685219805185
0.06292408993344,119.481316395797,0.19978398553867197,24.087433385392675,126.99956949405193,0.06102368564663862
0.0632062792275745,119.323382971192,0.20067993654754904,24.05559400699231,126.86537003364798,0.06128913436971276
0.0635131479838849,119.163165769327,0.20165424484883454,24.023294219096325,126.73159355106246,0.06157771851909669
0.0638014094328186,119.034360247516,0.20256947494919905,23.997327025899228,126.62892020224139,0.061848728229149205
0.0640810584075247,118.87503646654,0.20345736044389093,23.965207351654463,126.49267462154897,0.06211157073153603
0.0643583515115239,118.749727295737,0.20433776604908838,23.93994502282058,126.39226398693364,0.0623721307496185
0.0646433407893938,118.628926499803,0.2052426070063253,23.915591582360285,126.29749662300972,0.06263985179521732
0.0649299546861579,118.476026163134,0.20615260612855135,23.884766874487813,126.16866917330235,0.06290902675069181
0.0651983701383659,118.336420247885,0.2070048251893117,23.856622321973617,126.05176197605581,0.06316104485730112
0.0654766323047588,118.200360695477,0.20788830756760915,23.829192716208162,125.93972225102462,0.06342224111450222
0.065755186282415,118.049740968449,0.20877271644666762,23.798827779239318,125.81212367642021,0.06368364297310153
0.0660278828959016,117.90932138626,0.20963852819448756,23.770519191470015,125.6946242510872,0.06393948196433531
0.0663108996359759,117.7478570105,0.21053710634422348,23.7379679733168,125.5558233390745,0.06420493391226649
0.0665813672036144,117.57548167921,0.21139584087147573,23.703217106528736,125.40381799903533,0.06445854969332897
0.0668549745339578,117.428098071095,0.212264544145316,23.673504571132753,125.27875057720914,0.06471504418204713
0.0671426269328924,117.252928732197,0.21317784051193336,23.638190432410916,125.12559838285192,0.06498463436385336
0.0674170551936508,117.076686514603,0.21404915023984125,23.602660001343967,124.96965195124774,0.06524176304905098
0.0676887770683396,116.902902993855,0.21491186719197822,23.567625243561164,124.81591753324778,0.06549629083128077
0.0679697335949283,116.749354224225,0.21580390416389736,23.536669811603762,124.68477672822549,0.0657594008058452
0.0682394007122247,116.586087595001,0.2166600972613134,23.503755259152204,124.54185234386681,0.06601187338860688
0.0685218413221958,116.416518804734,0.21755684619797164,23.46957019103437,124.3935930335544,0.06627623667455557
0.0687998876252073,116.250027539217,0.21843964321003317,23.436005551906145,124.2480163703424,0.0665364186591528
0.0690782814269562,116.084772726422,0.21932354353058592,23.402690181646676,124.10370932620202,0.06679685801192077
0.06935246210796,115.915190504232,0.220194067192773,23.36850240565317,123.95419436141371,0.06705328968111107
0.0696276540332856,115.732706264672,0.22106780155568176,23.331713582957878,123.79090309680446,0.06731060102754889
0.0698987905962526,115.547612881586,0.221928660143102,23.29439875692774,123.62425127829286,0.06756405577226506
0.0701848938795014,115.356598441636,0.22283703806741692,23.255890245833818,123.45288906156247,0.06783143156418245
0.0704561352832081,115.143673427748,0.2236982295241857,23.212964563034,123.25625165977894,0.06808485229326605
0.0707253538176178,114.933069639081,0.2245529983709365,23.17050683923873,123.06175165464991,0.06833631956701079
0.0709859327880015,114.727368593866,0.22538033660190473,23.12903750852339,122.87139786981446,0.06857965672762555
0.0712520710908768,114.507751116479,0.22622532571353385,23.084762625082167,122.66666553948679,0.0688281242683587
0.0715193306979927,114.309422522084,0.2270738749661268,23.044779580452136,122.48475591333751,0.06907757655083605
0.0717907052463646,114.100384618531,0.2279354891572076,23.00263753909585,122.2917316991768,0.06933080594394397
0.0720342957441707,113.904159308022,0.22870888898774194,22.963078516497234,122.10916520610719,0.06955805443553421
0.0722993805899911,113.735915465837,0.2295505333732217,22.929160557912738,121.95895170485261,0.06980529659760676
0.0725675464684425,113.562022144444,0.23040196003730493,22.89410366431991,121.80293946346124,0.0700553502270097
0.0728352179001571,113.377111371556,0.23125181683299875,22.85682565250569,121.63495798319364,0.07030488046678464
0.0730954500657638,113.182342891734,0.23207805395880007,22.817560326973577,121.45545718490291,0.07054741595105468
0.0733524164706813,112.974606087746,0.23289392229441314,22.775680587289596,121.26156644410551,0.07078685005066758
0.0736100696642191,112.737494260984,0.2337119711838956,22.727878843014373,121.03610906730452,0.07102686653576082
0.0738737998743947,112.432439881762,0.23454931460120315,22.666379880163216,120.73825144497721,0.07127248441000199
0.0741225163887264,112.165276836912,0.2353389895342063,22.61251981032146,120.47924940750205,0.07150406443047047
0.0743663063943957,111.906883695939,0.23611302280220633,22.560427753101305,120.22898529651322,0.0717310053427344
0.0746119297432932,111.667179051072,0.2368928769349559,22.512103296696115,119.99888276906232,0.07195960081739913
0.074861363086728,111.410545705284,0.23768482780036138,22.46036601418525,119.75089101901777,0.07219168869249536
0.0751153564132545,111.173158371801,0.238491256612083,22.412508727755082,119.52396978648602,0.07242796411390282
0.07537630350958,110.961530665473,0.23931976364291646,22.36984458215936,119.32540067880127,0.07267065010285068
0.0756320865941316,110.804368632276,0.24013187493636784,22.338160716266838,119.18473423568037,0.0729084763121151
0.0758843012050792,110.615220925114,0.24093265632612645,22.300028538502985,119.00917966766173,0.07314292919709721
0.07611348806274,110.408100664689,0.24166032459919948,22.258273094001304,118.81164631666061,0.07335592835506141
0.0763599121446844,110.165266396876,0.24244272105937298,22.2093177056102,118.5774764603372,0.07358489665078766
0.0766077210038245,109.935510269102,0.24322951418714278,22.162998870250963,118.35741916821044,0.07381509877405151
0.0768522352031592,109.645312724216,0.24400584677003045,22.104495045201947,118.07180008662141,0.07404218839295139
0.0770923681476664,109.381586972552,0.24476826886884082,22.051327933666485,117.81407254401599,0.07426515879351646
0.0773388486555457,109.125452526779,0.24555084448135758,21.999691229398646,117.5650893842155,0.0744939713980055
0.0775931761493583,108.874900674718,0.2463583342742126,21.949179976023153,117.32285002101528,0.07473001364162694
0.0778772258088736,108.613635736722,0.24726019194317367,21.896508964523154,117.07216437291345,0.07499357528543478
0.0781410628759712,108.354207637109,0.24809787463120853,21.844208259641174,116.82112058895636,0.07523832002605149
0.0783954809325203,108.104685748597,0.24890565196075193,21.79390464691716,116.57960457891724,0.07547427063719224
0.0786597618719538,107.885243327854,0.24974474394345328,21.749665054895367,116.37147087752078,0.07571930927645518
0.0789088095701873,107.631027911044,0.2505354703853446,21.698415226866473,116.12406419632009,0.07595016886778967
0.0791644332023591,107.308304125802,0.25134707541749013,21.633354111761683,115.80330519982749,0.0761870687359692
0.0794112475182436,107.005365122243,0.25213071087042344,21.57228160864419,115.50279465774547,0.07641575130583647
0.0796542229698805,106.70578321628,0.2529021579293706,21.511885896402045,115.20534946476529,0.07664082595594207
0.0799011044002462,106.415980192268,0.25368600647078166,21.45346160676123,114.91873453546494,0.07686946694356793
0.0801488459257729,106.107593629991,0.25447258581432897,21.391290875806185,114.61199480339567,0.07709885194142461
0.0803879980899604,105.804230652791,0.2552318939356243,21.330132899602667,114.3096209444173,0.07732023410931194
0.0806327520707436,105.47235949921,0.2560089878246109,21.263227675040735,113.97688611302613,0.07754675112152606
0.0808740781914799,105.212421930697,0.2567751982579487,21.210824261228517,113.72137956863516,0.07777004546264069
0.0811127849904879,104.909408762209,0.25753309234479904,21.149736806461334,113.41890307861725,0.07799086715591093
0.081349761865335,104.597203528446,0.2582854939224386,21.086796231334716,113.10616112726505,0.07821004031675048
0.081585651860735,104.226690071092,0.25903444465783365,21.012100718332146,112.73009252182882,0.0784281605572702
0.0818283536953089,103.893730946936,0.25980502298260577,20.9449761589023,112.39518390958713,0.07865252985040477
0.0820772833443752,103.562872989842,0.2605953746183912,20.87827519475215,112.06303226018682,0.07888260425467043
0.0823177180444205,103.24560520015,0.26135875479103504,20.814314008350237,111.7445478183415,0.07910477691805215
0.0825652947002884,102.92384249797,0.26214481067341566,20.749446647590755,111.42177988550095,0.07933349750525213
0.0828091025587355,102.587063331724,0.2629189006239852,20.68155196767556,111.08220598036021,0.07955868522316911
0.0830541367319574,102.239152222826,0.26369688412396475,20.611413088121722,110.7305367509,0.07978495451831423
0.0833055899784452,101.936600948033,0.2644952481815635,20.550418751123452,110.42848963040623,0.08001709809494797
0.0835426136666502,101.593623847597,0.26524779839161433,20.481274567675555,110.08102071569178,0.08023587086246499
0.0837682415179225,101.213277445562,0.26596416681940394,20.404596733025297,109.69173571544235,0.08044408082140818
0.0839976958895055,100.856852004827,0.26669268444917993,20.332741364173124,109.32859518790133,0.08065577745200861
0.0842163758313947,100.467054478051,0.26738699326467813,20.254158182775083,108.92802569664775,0.0808574917988371
0.0844421530836334,100.068724634062,0.268103836040536,20.1738548862269,108.51874319849541,0.08106571015137541
0.0846568676778604,99.6837278777675,0.2687855548772068,20.096239540157928,108.12264003835152,0.08126368598638638
0.084868845412793,99.3014313340498,0.2694585841856178,20.01916855694444,107.72902915920835,0.0814590998819932
0.0850885164304436,98.9264617827718,0.2701560396666584,19.943574695406795,107.34396765158083,0.08166156562833793
0.0853098971539248,98.5509827473659,0.2708589234637112,19.867878121868966,106.9583569499619,0.08186556570764443
0.0855435133002565,98.1714151075443,0.2716006547283144,19.791357285680935,106.56934286150153,0.08208079548420003
0.085771130327281,97.8007397361188,0.27232333878911713,19.71662913080155,106.18921973012993,0.08229045374678887
0.0859916255470263,97.4422785061527,0.2730234111118085,19.644363346840386,105.82149843190284,0.08249351019934709
0.0862252155320832,97.0806424994374,0.2737650593143642,19.57145752788658,105.45144182294452,0.08270858079592833
0.0864545116235455,96.6570028454413,0.27449307440475695,19.486051773640966,105.01343682143958,0.08291965294747249
0.086690497867379,96.2462322686214,0.2752423307289283,19.403240425354074,104.58986606184759,0.08313683702283832
0.0869175261926829,95.8535565943542,0.2759631456617682,19.32407700942181,104.18491061030579,0.08334573239276373
0.087133903784247,95.4284093668488,0.2766501445149842,19.238367328356716,103.74345920690352,0.08354478710627689
0.0873578277565232,95.0081814823384,0.27736110312696116,19.153649386839422,103.30788983573302,0.08375074233693595
0.0875965962982249,94.5432713600992,0.27811919324686407,19.059923506196,102.82494013414333,0.0839703042183437
0.0878230348569211,94.0942851791259,0.27883813567072446,18.969407892111782,102.35793086624935,0.08417848341859653
0.0880511439195665,93.6990734754651,0.27956238194462363,18.889733212653763,101.94938407918332,0.08438815460795678
0.0882682006632867,93.2583229519878,0.28025153710593526,18.80087790712074,101.49006731583545,0.08458762601823493
0.0884873446257405,92.8187765654261,0.28094731918672605,18.712265355589903,101.03206363511057,0.0847889751900963
0.0887045606486274,92.3827993394264,0.281636980059392,18.624372346828363,100.57757496632053,0.08498851297368011
0.0889251760435065,91.9222208449989,0.2823374339381331,18.53151972235178,100.09642051595053,0.08519113272295765
0.0891429140696736,91.4985166812205,0.28302875217121365,18.44610096293405,99.65496109123713,0.085391069564125
0.0893687469323979,91.0463055593756,0.2837457715103633,18.35493520077012,99.1829998000412,0.0855983972250927
0.0895969930036449,90.5548798302595,0.28447045278657257,18.255863773780312,98.66832476485716,0.0858078966843073
0.0898303606146853,90.0760520727614,0.28521139495162584,18.1593320978687,98.16761631320473,0.0860220516654723