File: example/data/02 processed data/test_ID_099.csv
Strain,Stress_MPa,Displacement(mm),Force(kN),True Stress (MPa),True Strain
-1.47236694254865e-05,0.0051106696707534,-4.674765042591964e-05,0.0010303110056238854,0.005110594422942625,-1.4723777819738429e-05
-3.19216160132988e-06,-0.0690866716917611,-1.013511308422237e-05,-0.013927873013059039,-0.06908645115594056,-3.192166696342823e-06
1.60600699774528e-05,-0.178090983937625,5.0990722178412636e-05,-0.03590314236182521,-0.1780938440912894,1.6059941015909597e-05
2.25378689108577e-05,-0.19977285411136,7.15577337919732e-05,-0.040274207388850174,-0.19977735656575793,2.2537614936980837e-05
8.12148502222676e-06,0.505679868261667,2.578571494556996e-05,0.10194506144155208,0.5056839751331431,8.121452043191244e-06
-4.75319933887072e-05,3.23940057475833,-0.00015091407900914535,0.6530631558712794,3.2392465995916275,-4.75331230696894e-05
-0.0001265341002298,8.44030892379605,-0.00040174576822961497,1.7015662790372836,8.439240936900715,-0.00012654210634441233
-0.0001700505800113,14.6541035045862,-0.0005399105915358775,2.9542672665245777,14.6516115657857,-0.00017006504025051294
-0.0001275471232786,21.2425352547593,-0.00040496211640955493,4.282495107359475,21.23982583049641,-0.0001275552581046111
-2.15199733627431e-05,28.4827957607881,-6.832591542670934e-05,5.74213162537488,28.48218281178203,-2.152020492069799e-05
0.0001053132641486,36.1434736937618,0.000334369613671805,7.286524296662378,36.14728008095416,0.00010530771909614865
0.0002450460884638,44.1399051999199,0.000778021330872565,8.898604888303852,44.150721511034305,0.00024501606957493455
0.0003873942656004,52.274201114777,0.00122997679328127,10.538478944739042,52.2944518405277,0.000387319247815476
0.0005334740979498,60.4845622039727,0.001693780260990615,12.193687740320897,60.51682915123436,0.0005333318512310241
0.0006939826150771,68.7090430981329,0.0022033948028697924,13.851743088583591,68.75672597954159,0.0006937419204942561
0.0008409195540132,76.7308318433665,0.0026699195839919097,15.468935699622687,76.79535630025929,0.000840566179257566
0.0009883120610425,84.5072627230166,0.003137890793809937,17.036664164960147,84.59078227001145,0.000987824002220693
0.0011586186531939,92.1460748912436,0.003678614223890632,18.57664869807471,92.2528370524312,0.001157947972594283
0.0013201865415922,99.9702970127306,0.004191592269555235,20.15401187776649,100.10227645340578,0.001319315861562319
0.0014857222240698,107.778438433546,0.004717168061421614,21.728133188202875,107.93856725480227,0.0014846196307694345
0.0016589177859921,115.553282150416,0.005267063970524917,23.295541681523865,115.74497554540508,0.001657543301775941
0.0018342738508507,123.307645082191,0.0058238194764509725,24.858821248569708,123.53382507117526,0.0018325936249200497
0.0019962039837431,130.865464382613,0.006337947648384343,26.38247761953478,131.12669854394795,0.0019942142161187746
0.0021664127180987,138.337492418692,0.0068783603799633716,27.888838471608306,138.63718852165772,0.0021640694298088767
0.0023219216907453,145.550580719994,0.007372101368116327,29.34299707315079,145.88853777046833,0.002319230196064422
0.0024928794390836,152.746086262689,0.00791489221909043,30.793610990558104,153.12686384053373,0.00248977736945543
0.0026635035351601,159.81312763509,0.008456623724133317,32.21832653123415,160.23879046551107,0.0026599626955847856
0.0028273548035175,166.624280245126,0.008976851501168063,33.5914548974174,167.0953862042597,0.002823365353882418
0.002985616713087,173.045860116668,0.009479333064051224,34.88604539952027,173.56250872876285,0.0029811686108612814
0.0031463491427354,179.362967753302,0.009989658528184894,36.15957429906569,179.9273062731311,0.0031414097442742433
0.0033083680597112,185.576080234058,0.01050406858958306,37.412137775186096,186.19003421055078,0.003302907450590586
0.0034845549736268,191.573101345752,0.011063462041265088,38.62113723130361,192.24064834885948,0.003478497978488206
0.0036510484162633,197.345814907783,0.011592078721635977,39.784916285409054,198.06633403275825,0.003644399517713652
0.0038446187610565,202.697857226106,0.012206664566354388,40.86388801678297,203.47715321082347,0.0038372471024512712
0.0040742207906877,207.377392833938,0.012935651010433447,41.8072823953219,208.22229411934063,0.004065943627538959
0.0043630362675992,211.163369497094,0.013852640149627457,42.57053529061415,212.08468293659828,0.004353545819628765
0.0047026523752729,213.966315726406,0.014930921291491457,43.13560925044345,214.97252492928519,0.00469162945007283
0.0051044896470528,215.618331236065,0.01620675462939264,43.4686555771907,216.7189527755743,0.0050915059046168065
0.0055833246634026,216.470781971025,0.017727055806303255,43.64050964535864,217.67940862690983,0.005567795681670899
0.0060779993755045,216.959595093371,0.019297648017226787,43.739054370823595,218.2782753768582,0.006059602842410598
0.006589822194835,217.287246347974,0.020922685468601123,43.805108863751556,218.71913066661247,0.006568204236916181
0.0071116952757487,217.423459915036,0.02257963250050212,43.83256951887126,218.9697093077507,0.00708652642922685
0.0076398468362113,217.51779902923,0.024256513704970877,43.85158828429277,219.1796016979631,0.007610810998833895
0.0081631233612987,217.506489371093,0.025917916672123373,43.84930825721235,219.28202167571223,0.008129985287767302
0.0086906631088497,217.774616471803,0.027592855370597795,43.90336268071548,219.6672222972184,0.008653116675001037
0.009242741202628,217.940027401498,0.029345703318343897,43.936709524141996,219.9543906724637,0.009200288456163754
0.009779911950332,218.107534625269,0.031051220442304097,43.97047898045424,220.2406071096081,0.009732398147493567
0.0102996297154732,218.203484204385,0.032701324346627404,43.989822415604024,220.45089929431626,0.01024694994200315
0.0108568194297865,218.360339133208,0.03447040168957213,44.02144436925473,220.73103790580416,0.01079830728859961
0.011418872267036,218.45896090669,0.0362549194478393,44.04132651878871,220.95351587687293,0.011354169037845153
0.011957154713193,218.556921706571,0.03796396621438777,44.061075416044716,221.17024063305564,0.011886232729099618
0.0125006119788282,218.680364659511,0.039689443032779534,44.085961515357425,221.41400304550822,0.012423124421908549
0.0130600074133474,218.761428379701,0.04146552353737799,44.102303961347715,221.61845425609434,0.012975460840167367
0.0136158262603245,218.890553066381,0.043230248376530285,44.12833549818241,221.87092880695917,0.01352396381402953
0.0141603897681689,219.035041305889,0.044959237513936254,44.15746432726723,222.13666286366734,0.014061067974371412
0.0146998710976066,219.095948705175,0.04667209073490095,44.16974325896328,222.3166309091489,0.014592875267912786
0.0152409301251233,219.167977500844,0.048389953147266476,44.18426426417015,222.50830133159894,0.015125953907451169
0.0157824315398749,219.263630758072,0.05010922013910281,44.20354796082732,222.72414399969568,0.015659184039416102
0.016320698686108,219.365037342426,0.05181821832839289,44.223991528233086,222.94522801915858,0.01618894766294037
0.0168771576434552,219.560215402069,0.05358497551797026,44.26333942505711,223.2657677696407,0.01673632082636237
0.0174392729197805,219.659710832433,0.055369691520303084,44.283397703818494,223.4904164791199,0.017288953919411404
0.0179767509044915,219.732076295172,0.057076184121760506,44.29798658110667,223.68214509645702,0.017817079856234607
0.0185213070671251,219.798200063305,0.05880514993812219,44.31131713276229,223.86915001947884,0.018351876512171433
0.0190943221063229,219.959390215244,0.0606244726875752,44.34381306739319,224.15936566232426,0.018914313358551205
0.0196371893390512,220.065292126401,0.062348076151487554,44.36516289268245,224.38675593484075,0.01944686729467382
0.0201772547578631,220.164819451375,0.06406278385621535,44.385227601397204,224.60714110216432,0.019976391372703718
0.0207471862384238,220.200073210867,0.06587231630699555,44.39233475931079,224.76860513948742,0.020534894650852724
0.0213102346288651,220.266937082132,0.06765999494664669,44.40581451575781,224.9608771923337,0.021086346729483032
0.0218458564941157,220.250452661611,0.06936059436881735,44.40249125658078,225.0620124432206,0.021610655058002713
0.0223819415947205,220.325557103473,0.0710626645632376,44.41763231206016,225.25687085438716,0.022135141725677408
0.0229324956065713,220.347276181397,0.07281067355086387,44.422010878169644,225.40038912434684,0.022673498092927603
0.0234773583314415,220.440654547349,0.07454061270232676,44.44083595674556,225.61601878497464,0.023206004068401703
0.0240288929578143,220.560353044795,0.0762917351410604,44.46496717383067,225.8601741588461,0.02374474199837396
0.0245725202540559,220.620694381773,0.07801775180662747,44.47713198736544,226.041900862933,0.024275472188733202
0.0251095804873051,220.658987036923,0.07972291804719368,44.484851786643674,226.19964163217386,0.024799514668633553
0.0256518719797679,220.699418207487,0.08144469353576307,44.49300271062938,226.3607714293547,0.02532838310864667
0.0262022375095567,220.740469218169,0.08319210409284251,44.501278594382875,226.52436342059448,0.025864839906859154
0.0267451720956184,220.824282701423,0.08491592140358842,44.51817539260687,226.73026614516405,0.02639377172087394
0.0273023576139548,220.928391530131,0.08668498542430648,44.53916373247441,226.96025748276247,0.026936296198953245
0.0278546309821643,220.94876225281,0.08843845336837165,44.5432704701665,227.103208491328,0.027473747483276426
0.0284145752439262,221.020017158818,0.09021627639946568,44.55763545921771,227.3002070667911,0.028018369047327456
0.0289707065261172,221.012073367322,0.09198199322042211,44.556033990852114,227.41494928357534,0.028558988542045968
0.0295256371712745,220.970498830989,0.09374389801879653,44.547652564327386,227.4947936050283,0.029098149721806466
0.0300640220240418,220.955540101631,0.09545326992633271,44.54463688448881,227.59835232558046,0.029620957614754116
0.030614432228022,221.035235427996,0.09720082232396984,44.560703462284,227.80210366301128,0.03015516052829822
0.0311706378584383,221.09614224394,0.0989667752005416,44.572982276378305,227.9878500257236,0.03069469847721314
0.0317209985971052,221.156596181659,0.100714170545809,44.58516979022245,228.171904258878,0.0312282803115652
0.0322685613936784,221.133551829908,0.1024526824249289,44.580524048909446,228.26921342333353,0.03175886711300384
0.0328201519704048,221.00836925701,0.10420398250603523,44.55528724221322,228.2618975227564,0.03229307233748095
0.0333679281583999,220.985667405749,0.10594317190291969,44.55071054899901,228.3595012797801,0.03282330112555383
0.0339201841352701,221.080149596354,0.10769658462948256,44.569758158624964,228.5792289793154,0.033357581748291586
0.0344715211183808,221.140051992248,0.10944707955085904,44.581834481637195,228.76308596461863,0.03389068869778087
0.0350304813603335,221.212201650039,0.11122177831905886,44.596379852647864,228.961371556619,0.03443087687336648
0.0355852768302797,221.247789238723,0.11298325393613803,44.603554310526555,229.12095306687033,0.03496675175119263
0.0361524528878221,221.206533222799,0.11478403791883517,44.59523709771628,229.2036919936147,0.035514288308138235
0.0367111045992688,221.157220846172,0.11655775710267845,44.58529572258828,229.27614671353942,0.03605330277723298
0.0372617058549395,221.063149753903,0.1183059160894329,44.566330990386845,229.30033981539938,0.036584265638299425
0.0378207567394153,221.108817599916,0.12008090264764357,44.57553762814307,229.47132040330217,0.037123088463974066
0.038386117760084,221.159382979047,0.1218759238882667,44.58573160857587,229.6488330978282,0.03766769800321252
0.038948812852279,221.180646104376,0.12366248080598581,44.5900182546422,229.7953696960415,0.038209445121277226
0.0395175562554533,221.186036514049,0.12546824111106422,44.591104961232276,229.92676815491367,0.03875671730794592
0.0400857374466936,221.172197091551,0.12727221639325217,44.58831493365668,230.03804771467128,0.03930314960789343
0.0406478822668955,221.129309657698,0.1290570261973932,44.57966882699192,230.11774780242396,0.03984348291010263
0.0412163729589646,221.049197762196,0.13086198414471262,44.563518268858715,230.16004393944257,0.04038961910007961
0.0417910312115369,221.039883243508,0.13268652409662965,44.56164046189121,230.2773679031319,0.040941377356916046
0.0423525061108549,220.988835614103,0.1344692069019643,44.55134925980317,230.34826662488004,0.04148018373262573
0.0429037158350016,220.853858779036,0.13621929777613007,44.52413792985366,230.32930997715533,0.04200885712171238
0.0434608364389635,220.827984147282,0.13798815569370912,44.51892160409205,230.42535304745303,0.04254291586671589
0.0440221129322841,220.884390591304,0.139770208560002,44.53029314320688,230.60818817889316,0.04308067020575428
0.0445794981704569,220.892871987485,0.14153990669120065,44.53200299267697,230.74016537011804,0.04361441033928849
0.0451390743106518,220.876812728568,0.14331656093631945,44.52876544607931,230.8469875918228,0.044149962026428166
0.0457306500427284,220.844350212474,0.14519481388566266,44.52222100283476,230.9437059059544,0.04471582774342766
0.0463765568499344,220.866188922773,0.14724556799854172,44.52662368683104,231.10920228957832,0.04533329784782769
0.047041642965328,220.872888319999,0.1493572164149164,44.52797428531179,231.26311187306914,0.0459687047033038
0.0476371223502921,220.827081449436,0.1512478634621774,44.5187396202063,231.3466481467007,0.046537268638610435
0.0482130111003406,220.79294748555,0.1530763102435814,44.51185821308688,231.43804031354776,0.047086820112115874
0.0487947129490063,220.724227026405,0.154923213613095,44.49800416852325,231.49440232504972,0.04764161240678867
0.0493708850216295,220.639171766036,0.15675255994367365,44.48085702803285,231.5323229465645,0.04819082748081654
0.0499451861619629,220.555894452762,0.1585759660642322,44.46406832167683,231.57159966032344,0.0487379591515003
0.0505201002020558,220.510341540857,0.16040131814152717,44.454884854636774,231.6505460910907,0.0492853750580445
0.0510910583815177,220.445795081757,0.1622141103613187,44.441872288482216,231.70860406823914,0.04982872789586788
0.0516585844553033,220.310196041673,0.16401600564558796,44.41453552200128,231.6911089102562,0.05036852215002394
0.0522365080276495,220.258597374954,0.16585091298778715,44.404133230790734,231.7641373648896,0.05091790656462425
0.052805879337087,220.300501546724,0.16765866689525122,44.41258111181956,231.93366324930005,0.05145886605003887
0.0533875731831316,220.247542306115,0.1695055448564428,44.40190452891278,232.0060240893876,0.052011231133254426
0.05397868290126,220.181018207821,0.1713823182115005,44.38849327069672,232.06609957053755,0.052572224963277334
0.0545664000284501,220.161221398915,0.17324832009032906,44.38450223402127,232.17462667652035,0.0531296872126436
0.0551470848278687,220.165111737168,0.17509199432848313,44.385286526213065,232.3065758302748,0.05368017410885105
0.0557326223462486,220.098668660325,0.1769510759493393,44.37189160192152,232.365344639683,0.054234954688159254
0.056333062381662,219.989341586617,0.17885747306177682,44.34985126386199,232.38201488951665,0.05480353553858559
0.056920083709856,219.925650779632,0.18072126577879277,44.337011197173815,232.4438372319532,0.05535909732196996
0.0575077815460734,219.907028458571,0.18258720640878304,44.33325693724792,232.55339381161266,0.05591499034722603
0.0581055242718981,219.850464244231,0.18448503956327647,44.32185359163697,232.62499073056225,0.05648006784989305
0.0586941352991394,219.744380929527,0.1863538795747676,44.30046719539265,232.64208735503033,0.05703620082142916
0.0592732965154977,219.628562758927,0.1881927164367052,44.27711825219968,232.64667168260945,0.057583103688861506
0.0598558835906791,219.486720337274,0.19004243040040614,44.24852281999444,232.6242919194818,0.05813294000401202
0.0604364409677386,219.379145717044,0.19188570007257005,44.22683577655607,232.63764050672506,0.058680560145672495
0.0610419958990093,219.400075911844,0.1938083369793545,44.23105530382775,232.79269444589713,0.059251440280198964
0.0616441136579382,219.444128610435,0.19572006086395377,44.239936327863695,232.97156741606386,0.059818757108030585
0.0622396853147206,219.392453478638,0.19761100087423789,44.22951862129342,233.04737074357294,0.0603795897417944
0.0628341133246515,219.299776258043,0.1994983098057685,44.21083489362147,233.0792832515116,0.060939031984049576
0.0634378853092835,219.198289598196,0.2014152858569751,44.19037518299631,233.10376555371744,0.06150694803735567
0.0640337854990186,219.079645183687,0.20330726895938406,44.1664564690313,233.1081441905803,0.06206714370387887
0.0646211296071163,218.95768008788,0.20517208650259425,44.141868305716606,233.1069727113124,0.06261898902068928
0.0652180021213868,218.909960045279,0.20706715673540307,44.13224794512825,233.18683028390473,0.06317947504144465
0.0658220949351701,218.935422191289,0.20898515141916507,44.137381113763865,233.34621033543561,0.0637464215111979
0.0664269158571473,218.901442418841,0.21090545784644266,44.13053079163834,233.44239011540552,0.06431372948989743
0.0670266719759352,218.754398779462,0.21280968352359425,44.100886793939544,233.4167781097459,0.06487596917301726
0.0676244884088544,218.606079765633,0.21470775069811274,44.07098568075162,233.38920407284917,0.06543607609787927
0.0682226028344753,218.428249898115,0.21660676399945908,44.035135179459985,233.32999363874362,0.06599614843986273
0.0688155107124719,218.37488455699,0.21848924651209825,44.02437672668919,233.40246376455636,0.06655103596334791
0.0694160226452161,218.333658259969,0.2203958718985611,44.01606550520975,233.4895124259559,0.06711272625662443
0.0700223708597521,218.280922928029,0.2223210274797129,44.005434062290654,233.5654706649044,0.06767955560082196
0.0706354395863661,218.200896090074,0.22426752068671235,43.989300651758924,233.61361230353538,0.06825234097584446
0.0712480069107956,218.14852354946,0.226212421941776,43.97874234757114,233.6911710628918,0.06882433040144324
0.0718520294505174,218.167472053205,0.22813019350539274,43.98256236592612,233.8432476803168,0.06938802089229042
0.0724804188614819,218.113236980931,0.23012532988520504,43.97162857535569,233.92217575654252,0.0699741141815535
0.0731121916229086,218.016655532242,0.23213120840273482,43.952157755299986,233.95633102850095,0.07056301701110122
0.0737376986201727,217.904741321714,0.2341171931190483,43.929595850457545,233.97253546520125,0.07114573778520543
0.074354506404344,217.782051289662,0.2360755578337922,43.90486153999586,233.97512821703037,0.07172002207307779
0.0749620013278974,217.641369891693,0.23800435421607424,43.87650017016531,233.95620255051946,0.07228531335292894
0.0755694941343232,217.436661177329,0.23993314387647616,43.835230893349525,233.868239668756,0.07285028329070165
0.0761824004281148,217.273637266671,0.24187912135926448,43.80236527296087,233.8260645033935,0.07341996449968893
0.0768076021773305,217.24324134152,0.24386413691302433,43.79623745445043,233.92917379819326,0.07400073985492277
0.0774331216411152,217.250981830501,0.24585016121054074,43.797797937029,234.0734035332339,0.07458147298697103
0.0780503685988569,217.230535289149,0.24780992030137067,43.79367591429244,234.18545863939408,0.07515419551294589
0.07867012220447,217.122796182287,0.24977763799919225,43.771955710349054,234.20387309132374,0.07572891405001593
0.0792975653926376,217.013292261406,0.2517697701216244,43.749879719899454,234.2219179955764,0.07631042711849706
0.0799319174649568,216.932480907508,0.2537838379512378,43.73358815095361,234.27231006687526,0.07689799976476364
0.0805648101075082,216.85670298961,0.2557932720913385,43.718311322705375,234.32772208650826,0.07748387675552953
0.081190789863486,216.765209653393,0.25778075781656806,43.699866266124026,234.36454824007612,0.07806301694462629
0.0818253169457337,216.62368417555,0.25979538130270446,43.67133472979088,234.3489857911669,0.07864972279341932
0.0824665658512389,216.533888710935,0.26183134657768353,43.6532319641245,234.39069490334015,0.07924229436786018
0.0831042531413441,216.452489884508,0.2638560037237675,43.636821960716816,234.4406123969444,0.07983122667424698
0.0837347466252463,216.291856713662,0.265857820535157,43.60443831347427,234.4030005326846,0.08041317438864916
0.0843818359320917,216.138499628631,0.2679123290843911,43.57352152513201,234.37666304290258,0.0810100881628112
0.085025287622333,216.006223918532,0.26995528820090725,43.54685474197605,234.37221523541922,0.08160329328519131
0.0856453003792459,215.91058146101,0.27192382870410575,43.527573222539615,234.40230806529584,0.08217455709389763
0.0862771707087286,215.767729195805,0.2739300170002133,43.49877420587429,234.3835584010662,0.0827564105953194
0.0869074959965411,215.653311471299,0.275931299789018,43.47570759261388,234.39520077463172,0.08333650423866709
0.0875408153141726,215.589127803525,0.277942088622498,43.46276816519064,234.46197582431694,0.08391901459979668
0.0881789425401717,215.551508655942,0.2799681425650451,43.45518414503791,234.55861275216165,0.08450560415664857
0.0888085102622688,215.491096324685,0.2819670200827034,43.4430050190565,234.62853956406337,0.08508398850961059
0.0894615828883566,215.447092563745,0.2840405256705322,43.43413386085099,234.72133049319194,0.0856836135494154
0.090118800117712,215.367803637449,0.28612719037373563,43.41814921330972,234.7764916852429,0.08628668123565279
0.0907722335148802,215.288166802928,0.28820184140974464,43.40209442747028,234.83035455295385,0.08688591650843287
0.0914175260464439,215.161929358794,0.29025064519745936,43.37664495873287,234.83150064015464,0.0874773339573923
0.0920713357332143,214.98721234522,0.2923264909529554,43.34142200879636,234.7813721514046,0.08807620095209537
0.0927215166304562,214.808635973575,0.2943908153016984,43.30542101227272,234.72601848636447,0.08867138865213958
0.093371946803454,214.664628423507,0.2964559311009664,43.27638909017901,234.7082826892499,0.08926645030258616
0.0940346410382985,214.59644150142,0.2985599852965977,43.26264260668628,234.7759408461023,0.08987236806730631
0.0946903727707283,214.57429991058,0.3006419335470623,43.25817886197293,234.89242035613086,0.09047155869007655
0.0953356809296141,214.458430295536,0.30269078695152474,43.23481954758005,234.90397077885714,0.09106087421577228
0.0959776542551203,214.33338394084,0.3047290522600069,43.20961020247335,234.9045993600439,0.09164679986461904
0.0966481306962891,214.231199556857,0.30685781496071785,43.18900983066237,234.93624453085093,0.09225837386568056
0.0973165401449303,214.122446838369,0.30898001496015365,43.16708528261519,234.96010253204585,0.0928676903949797
0.0979701374851824,213.936954034802,0.3110551865154541,43.12968993341609,234.89638683475272,0.0934631455273087
0.0986145423736075,213.770156438494,0.3131011720362038,43.096063538000394,234.8510025888106,0.0940498790257443
0.0992645180617356,213.688442370984,0.3151648448460105,43.079589981990374,234.90012261830267,0.0946413362344473
0.0999332625237074,213.710981154553,0.317288108512771,43.08413380075788,235.06781673847004,0.09524950753080651
0.100608358228348,213.646084579988,0.3194315373750049,43.071050651325585,235.14066639149536,0.09586307986177582
0.101269003247834,213.480521051222,0.3215290853118729,43.03767304392636,235.09948063090752,0.09646315419004585
0.101919829965936,213.262614369658,0.3235954601418468,42.99374305692305,234.99830376430452,0.09705395850715341
0.102583250979921,213.135814142544,0.3257018218612492,42.96818013113687,234.9999788575384,0.09765583658094375
0.103262027164683,213.094012071362,0.3278569362478685,42.959752833586585,235.09853173450622,0.09827127068496877
0.103943886826405,213.037032060419,0.33002184067383583,42.948265663380475,235.18092921074043,0.09888911941316482
0.104626135599716,212.951574940588,0.33218798052909826,42.931037508022534,235.23187529649502,0.09950693889643636
0.105298625078727,212.819417002476,0.3343231346249582,42.904394467699156,235.22900900289295,0.10011554739907351
0.105964055065865,212.673674231163,0.33643587483412135,42.87501272500246,235.2094391584538,0.10071740263156093
0.106642580671744,212.536664891237,0.33859019363278714,42.84739164207338,235.20212332260414,0.1013307295701949
0.107319172239155,212.447470852058,0.3407383718593171,42.829410123774885,235.24715756820288,0.10194193397567707
0.108001502515895,212.355350328769,0.34290477048796664,42.81083862627983,235.29004723156527,0.10255794438544961
0.108686199652952,212.289873281777,0.3450786838981226,42.79763845360624,235.3628528335801,0.10317571039566614
0.109370845013061,212.193438630273,0.3472524329164687,42.77819722786304,235.40121431949305,0.10379304833429043
0.110056474344711,211.958801547124,0.3494293060444574,42.7308943919002,235.28623995173075,0.10441089181803993
0.11074810067263,211.754650318365,0.35162521963560023,42.68973750418239,235.20607564972087,0.10503375288205204
0.111421025792214,211.649819690845,0.35376175689027944,42.66860364967435,235.23205970953606,0.10563939997897118
0.112086275414182,211.663278506443,0.3558739244400278,42.671316946898905,235.3878270361849,0.10623777862288834
0.112784343593314,211.610363662877,0.3580902909087719,42.66064931443601,235.47669962613705,0.1068652921475625
0.113509787327198,211.523161783374,0.36039357476385364,42.643069415528196,235.53311089218127,0.10751699737328652
0.114221511281626,211.405033862881,0.36265329831916254,42.61925482675681,235.5520363232426,0.10815596489965537
0.114911525376224,211.204669594742,0.36484409306951116,42.57886139029999,235.47452034445521,0.10877505232538479
0.11559822721067,211.040974714842,0.3670243713938772,42.54586050251215,235.43693726068955,0.10939078767946267
0.116273187321202,210.897129349572,0.36916736974481634,42.51686127687372,235.41881077593854,0.10999562550902038
0.116966213556505,210.760025082586,0.3713677280419033,42.48922105664934,235.4118271855701,0.11061627214213728
0.117676598334525,210.619050153311,0.3736231997121168,42.460800510907504,235.40398351980136,0.1112520648497412
0.118374416821722,210.536989423089,0.3758387734089674,42.44425706769474,235.45918276544822,0.11187621743402579
0.119054157936293,210.397892539213,0.3779969514477302,42.41621513590534,235.44663646703964,0.1124838266718377
0.11972473731445,210.244667415565,0.38012604097337876,42.3853249509779,235.41615499365744,0.11308288484558947
0.120416127205935,210.104467164251,0.3823212038788436,42.357060580313004,235.40443340883664,0.11370015845046705
0.121126721261869,210.099763064134,0.38457734000643407,42.35611223372942,235.54845850198808,0.11433418075365316
0.12184350790635,210.064140001961,0.3868531376026612,42.34893062439534,235.65909170513055,0.11497332135352417
0.122552816183697,209.896805589267,0.38910519138323796,42.31519600679622,235.62025022219362,0.1156053918068114
0.123248331605752,209.710092466106,0.3913134528482626,42.27755464116697,235.55651148344154,0.1162247836394102
0.123951420974196,209.591914977323,0.39354576159307225,42.25373005942832,235.57113066346508,0.1168505307636511
0.12466332283255,209.584825119449,0.39580604999334623,42.25230074408092,235.7123658341184,0.11748372227331276
0.12538860833554,209.461440043479,0.3981088314653395,42.22742631276537,235.725518510489,0.11812840564089488
0.126101838403451,209.271937442711,0.4003733369309569,42.18922258845054,235.66151348048882,0.11876196825964958
0.126825984036318,209.138500409373,0.40267249931530963,42.1623216825296,235.6626965236716,0.1194048167793335
0.12755134661755,209.035602519492,0.4049755255107212,42.14157746792959,235.69837511186412,0.1200483315950661
0.128266750185835,208.898914506323,0.4072469318400261,42.114021164474714,235.69369938739763,0.12068260577992429
0.128954474829281,208.702535803049,0.40943045758296714,42.074431217894684,235.6156617030704,0.12129196090834911
0.129667220875695,208.579409179046,0.41169342628033156,42.049608890495676,235.62532149918732,0.12192309455187018
0.130403175129226,208.500620019046,0.41403008103529254,42.03372499583968,235.6897628859419,0.12257436123882362
0.131138829913647,208.427991406073,0.4163657849758292,42.019083067464315,235.7609943203171,0.12322493930346087
0.131865776596546,208.350516562533,0.4186738406940335,42.003464139006645,235.82481923334294,0.12386740083960802
0.132592711813677,208.286703017272,0.4209818600084244,41.99059932828203,235.90400180506205,0.12450943976045596
0.133329417025804,208.153660953657,0.4233208990569277,41.963778048257254,235.90666722039495,0.1251596873825684
0.134069368813358,208.011578337061,0.4256702459824116,41.93513419275149,235.89955935058114,0.1258123752277272
0.134817751155985,207.858984184324,0.4280463599202523,41.90437121155972,235.882064989622,0.12647206637161967
0.135545320419527,207.671048234776,0.4303563923319982,41.86648332413084,235.81988700961776,0.127112994069535
0.136267346041492,207.502114267229,0.432648823681737,41.83242623627337,235.7778766764227,0.127748632436144
0.136993428251998,207.36231075143,0.43495413470009364,41.804241847488285,235.76958459152453,0.12838743485019838
0.137704328856714,207.181181013728,0.4372112441200669,41.76772609236757,235.7109264969648,0.12901248547561822
0.138401335071653,207.012867863791,0.43942423885249826,41.73379416134026,235.66372515315138,0.12962494055428406
0.139111385399829,206.90057022425,0.44167864864445705,41.7111549572088,235.68279518816001,0.1302484719574667
0.139839409492902,206.869704724684,0.44399012513996383,41.704932472496296,235.79824207535484,0.13088738361757812
0.140576373321082,206.852593400878,0.4463299852944353,41.70148282961701,235.9311807932338,0.13153372527105206
0.141315423245892,206.771795022395,0.44867646880570705,41.68519387651483,235.99183875129756,0.1321814772387508
0.14206777261767,206.662823077738,0.45106517806110225,41.66322513247198,236.02295003527186,0.13284045502256447
0.142821333010863,206.544007003068,0.45345773230949,41.63927181181851,236.04289740865119,0.13350005851811975
0.143554349660753,206.382318172687,0.4557850601728908,41.606675343613695,236.0093976394457,0.13414126256919504
0.144295142882043,206.222115791906,0.45813707865048653,41.574378543648244,235.97896545553627,0.13478885171314312
0.145051574180958,206.127895332595,0.4605387480245416,41.555383699051156,236.02707103319563,0.13544967894460133
0.145824331276333,206.00533354115,0.4629922518023573,41.53067524189584,236.04592354414615,0.13612431795306393
0.14658769564617,205.903562620403,0.46541593367658973,41.51015822427325,236.08649139026474,0.1367903102695302
0.147332246936289,205.769847695626,0.46777988402271753,41.48320129543821,236.08638170836053,0.13743946223202355
0.148052327011162,205.503751838495,0.4700661382604393,41.4295563706406,235.92906050770853,0.1380668778787675
0.148756076486934,205.166179342395,0.47230054284601547,41.361501755426836,235.68589520918434,0.13867968432507233
0.149470648427319,204.951707188384,0.4745693087567378,41.31826416917822,235.58597175811778,0.13930153068658677
0.150209482273473,205.000394064901,0.47691510621827676,41.32807944348404,235.79339712324773,0.13994408428498603
0.150949052358884,205.062576539083,0.4792632412394567,41.34061543027913,236.01657814192873,0.1405868649537183
0.151707513088579,205.039849667187,0.4816713540562383,41.336033692904905,236.14593534425205,0.1412456351485494
0.15248877784589,204.914649877821,0.4841518696607007,41.310793415368714,236.16183440040837,0.14192375861426584
0.153260436149766,204.75636101593,0.48660188477550703,41.278882380811496,236.13741020967038,0.14259309275347
0.154035435382665,204.602711030232,0.48906250733996137,41.247906543694775,236.11877870424738,0.1432648741852376
0.154799068595474,204.462102203141,0.4914870427906299,41.21955980415322,236.1126451872598,0.14392636225581015
0.155550591484358,204.323948236166,0.49387312796283656,41.191707964411066,236.10665923872097,0.14457693297103646
0.156295860544517,204.186892623043,0.49623935722884144,41.16407755280547,236.1004587174724,0.1452216722315714
0.157067215501654,204.043589229638,0.4986884092177514,41.135187588695025,236.0921476309005,0.14588854116685435
0.157836325597488,203.841906135964,0.5011303337720244,41.09452827701034,236.0155636032526,0.14655302684453259
0.158584439440815,203.633037342929,0.5035055952245876,41.052420328334485,235.9260684215879,0.14719894910583212
0.1593417366074,203.501527229577,0.505910013728495,41.025907889482724,235.9278139805959,0.1478523756052223
0.160103812841165,203.388307783803,0.5083296057706989,41.00308284921468,235.95155134730223,0.14850949494252996
0.160862362729394,203.318078676536,0.510738001665826,40.98892466118966,236.0243051980444,0.1491631450673971
0.161611150277678,203.244012078634,0.5131154021316277,40.97399283505261,236.09051065771231,0.14980796411057282
0.162368680411179,203.089770221693,0.5155205603054933,40.942897676693306,236.06518821759883,0.15045988901140642
0.16312839127889,202.94604412618,0.5179326423104758,40.91392249583789,236.0523058208984,0.1511132640717204
0.163894107685599,202.832495533715,0.5203637919017768,40.891031099596944,236.07554639885646,0.15177137239227692
0.164669217941721,202.772620633717,0.5228247669649642,40.87896031975735,236.16302949346448,0.15243711360379525
0.165431117607316,202.610778415965,0.5252437984032282,40.84633292865855,236.12890592860634,0.15309107659510884
0.166177186446875,202.405566041104,0.5276125669688282,40.80496211388657,236.04075352700184,0.1537310373155476
0.166933459801724,202.297572975584,0.5300137348704737,40.78319071187774,236.06780674188997,0.1543793335140607
0.167705251905304,202.150893830259,0.5324641747993402,40.75362019618022,236.05266040294495,0.15504049973890302
0.168465984046151,201.934153359392,0.5348794993465295,40.70992531725343,235.95318921760838,0.15569176378669936
0.169232280998458,201.786510832903,0.5373124921701041,40.68016058391324,235.9353023358752,0.1563473633490655
0.169992140002142,201.761216484384,0.5397250445068008,40.67506124325181,236.05903744399987,0.15699703084021208
0.170762239258628,201.704686513786,0.5421701096461439,40.66366480117926,236.14823045183965,0.157655023230267
0.171530263329469,201.561856116017,0.544608586071064,40.63487019298903,236.13581437277395,0.15831081160641317
0.172312524506376,201.424898409726,0.5470922653077438,40.60725951940076,236.13293115314622,0.15897831474272592
0.173084220861319,201.309088074826,0.5495424012346878,40.583912155884924,236.1525147365599,0.1596363666346412
0.173851914003967,201.155308445346,0.5519798269625952,40.552910182581755,236.12654383062775,0.1602905754634403
0.174609228189112,201.025810514485,0.5543842995004306,40.52680339972017,236.1267721345099,0.16093552052792504
0.175386708034117,200.897751341088,0.5568527980083214,40.50098667036334,236.13254660025802,0.16159720667077113
0.176133042933595,200.672219877184,0.5592224113141641,40.4555195272403,236.01722859639187,0.16223197482377602
0.176897141681241,200.386519382868,0.5616484248379401,40.397922307586185,235.83432189314993,0.162881434214055
0.177669687710181,200.218027367711,0.5641012584798246,40.36395431733054,235.7907017640807,0.16353764498456183
0.178437598185828,200.206683623492,0.5665393742400039,40.36166741849599,235.93108339001785,0.1641894917891911
0.179186699870222,200.126280104369,0.5689177720879548,40.34545806904079,235.98624779357453,0.16482496344616424
0.179959268367,200.035509985904,0.5713706770652249,40.32715881315825,236.033754010387,0.16547991954875113
0.180743229301695,199.963085101127,0.5738597530328816,40.3125579563872,236.10505884343436,0.16614409554237028
0.181499038038389,199.841041979407,0.576259445771885,40.28795406304845,236.11199885925868,0.16678400345777286
0.182257846475203,199.647924251606,0.5786686625587695,40.24902152912377,236.03532497894815,0.1674260394199745
0.183036506197942,199.480519301848,0.5811409071784659,40.21527269125256,235.9927366094094,0.1680844435209168
0.183826413857902,199.324571122733,0.5836488639988388,40.183833538342974,235.96569222598933,0.16875191579621696
0.184611223683044,199.203868410195,0.5861406351936647,40.15949987149531,235.9791383197972,0.16941463947652546
0.185393207566233,199.056963022833,0.5886234340227898,40.129883745403134,235.96077188602905,0.17007454027776941
0.186157995642618,198.94372982911,0.5910516361653121,40.10705593354858,235.97869581976363,0.17071950893951443
0.186918897113132,198.793099205002,0.5934674983341941,40.0766887997284,235.95128606210238,0.17136078735650348
0.187696991684679,198.620473834536,0.5959379485988557,40.041887525042455,235.9009392602639,0.17201613090327694
0.188467147274201,198.378704703708,0.5983831925955881,39.99314686826753,235.76657325916696,0.1726643652603768
0.189240320461049,198.161436639564,0.6008380174638305,39.9493456265361,235.66157041225696,0.17331471710103966
0.19000137079786,198.018231562908,0.6032543522832055,39.92047548308226,235.6419670028286,0.17395445905374937
0.190764213070077,197.886789164508,0.6056763764974944,39.89397669556482,235.63650677643963,0.17459529686112749
0.191524893725204,197.747488063691,0.6080915375775227,39.86589359364011,235.6210546995155,0.1752339100998057
0.192288854514242,197.635124143904,0.6105171130827183,39.84324102741105,235.63815577731532,0.17587486689918377
0.193063865863528,197.521629786463,0.6129777741167014,39.82036056495094,235.65591922470213,0.17652467551653073
0.193839932218862,197.389007413652,0.6154417847948869,39.793623894592244,235.65087923146274,0.17717494586534346
0.194594036179865,197.221774628567,0.6178360648710713,39.75990976511911,235.59995577609556,0.17780640898807454
0.195362867495541,197.051329190785,0.6202771042983426,39.72554796486226,235.54784190530455,0.1784497940976677
0.196100298788716,196.931733424567,0.6226184486541733,39.70143745839271,235.55010519010435,0.17906651387570535
0.196832229271248,196.799566720562,0.6249423279362123,39.6747926508653,235.53606415778592,0.17967825741362387
0.197606899026164,196.677553964149,0.6274019044080706,39.65019487917244,235.5423955110555,0.18032531481657843
0.198366693626181,196.513975721086,0.6298142522631247,39.61721750537094,235.49580333621344,0.18095954102659645
0.199125506283563,196.306757091749,0.6322234824503125,39.5754422296966,235.39643948452797,0.18159254636671676
0.199867225853938,196.119304811414,0.6345784420862531,39.53765184998106,235.31712620047418,0.18221090555061326
0.200616906491849,195.988848039997,0.6369586781116205,39.5113517648634,235.3075244406823,0.1828355134388158
0.201374374550188,195.879476585011,0.6393636391968469,39.48930247953822,235.32458366953577,0.1834662135495333
0.20216621649687,195.74491100594,0.6418777373775623,39.46217405879751,235.31791906252744,0.18412510982803135
0.202943028817471,195.598247342823,0.6443441164954704,39.43260666431312,235.29354808996433,0.18477107827967346
0.203681912278133,195.43750907585,0.6466900714830722,39.40020182969136,235.2445946552941,0.18538511952163106
0.204411207296132,195.168934283928,0.6490055831652191,39.34605715163988,235.06365176760517,0.18599082287617957
0.2051353008028,194.938419740615,0.65130458004889,39.29958541970798,234.92717111212855,0.18659184346327434
0.20586953643192,194.745481508674,0.6536357781713459,39.26068907214868,234.83764350907578,0.18720091370691616
0.20661632225961,194.651237494965,0.6560068231742617,39.24168947898494,234.86936030945657,0.18782001441488688
0.207352043029744,194.494722339115,0.6583427366194372,39.21013602356558,234.82360037463326,0.18842956738458855
0.208077657418933,194.366701650513,0.6606465623051122,39.18432705274342,234.8100696101964,0.1890303833891958
0.208793728816321,194.207205759762,0.6629200889918191,39.15217268116802,234.7564524133412,0.18962294402144053
0.209518692680901,193.955947296887,0.6652218492618607,39.10151897505242,234.5933438122165,0.19022250583144704
0.210262389762919,193.813556297416,0.6675830874972678,39.072812949559065,234.56525781296074,0.19083718714359538
0.211000674442006,193.668257118156,0.669927141353369,39.04352063502025,234.53238998809476,0.1914470215006152
0.211705903862361,193.484747393052,0.6721662447629961,39.00652507443928,234.44661072347867,0.19202920462306955
0.212421158461899,193.34124508008,0.6744371781165293,38.97759500814413,234.4110163384565,0.19261931776640323
0.213175765999796,193.224845380731,0.6768330570493523,38.95412882875537,234.41569980496047,0.19324152136060446
0.213913892306118,193.066189391866,0.6791766080719246,38.92214378140019,234.3657294373902,0.19384976121408673
0.214642885006848,192.850558358345,0.6814911598967424,38.87867256504236,234.2445585795617,0.19445011178396884
0.215356094929511,192.642741472538,0.6837556014011974,38.836776680863665,234.12952999257914,0.1950371160988111
0.216062870886195,192.398227718361,0.685999615063669,38.78748270802158,233.96834115260597,0.1956184852388299
0.216776367875934,192.215039824525,0.6882649680060904,38.75055202862424,233.88271800881355,0.19620504023911714
0.217476401720036,191.971201296409,0.6904875754611143,38.70139418135606,233.72040738822471,0.19678019321595094
0.2181601930544,191.696538843657,0.6926586129477199,38.64602223088126,233.5170927656495,0.19734168203065833
0.218834866266471,191.489004358364,0.6948007003960454,38.60418327864619,233.39347501862628,0.1978953747652637
0.219531185282935,191.435416637871,0.6970115132733186,38.59337999419479,233.4614605575153,0.19846651053460362
0.220259836144726,191.289991283348,0.699324979759505,38.56406224272296,233.4234934195443,0.19906381651454633
0.220994744963362,191.140985991495,0.7016583152586743,38.53402277588539,233.382139442731,0.19966589123999554
0.221706329834555,190.953775151618,0.703917597224712,38.49628107056619,233.28943580853607,0.20024851258377221
0.222406909332148,190.781498777232,0.7061419371295699,38.46155015348997,233.21262227803112,0.20082179168193615
0.223077958370862,190.587978070583,0.7082725178274868,38.42253637902954,233.10395510859928,0.20137059823103334
0.223770734519281,190.34440863648,0.7104720820987172,38.373432781114374,232.9379167687033,0.20193685814644502
0.224475587066794,190.074757232014,0.7127099889370709,38.31907105797403,232.74189994824872,0.20251266014869684
0.225175018782963,189.868687328885,0.7149306846359075,38.27752736550322,232.6223725644632,0.2030837062672784
0.225869491614126,189.682652080472,0.7171356358748501,38.240022659423154,232.52617627390734,0.20365038128831622
0.226565648962941,189.416427225965,0.7193459354573377,38.18635172875455,232.33168298465748,0.20421810873276133
0.227259432407682,189.144715174338,0.7215486978943904,38.131574579146545,232.12963578777072,0.20478357973433758
0.227959761964628,188.925043221541,0.7237722442376938,38.08728871346266,231.99235110348056,0.2053540620583149
0.228657079791287,188.692511356023,0.7259862283373362,38.04041028937424,231.83838998117548,0.20592176788328084
0.229338308248427,188.536244388475,0.7281491286887557,38.008906868716565,231.77482772003987,0.20647606385787604
0.230013775543156,188.376856999306,0.7302937373495203,37.976774371060095,231.70612910266956,0.20702536895019283
0.23067893978706,188.091659219527,0.7324056338239154,37.919278498656645,231.48044375107645,0.20756600066414985
0.231359380297624,187.876209431893,0.7345660324449562,37.87584382146962,231.34313281872235,0.208118746348356
0.232068454329561,187.67758246611,0.7368173424963561,37.83580062516778,231.2316289413289,0.2086944271469187
0.232775882756738,187.437947325855,0.7390634277526431,37.78749018089237,231.06898097674187,0.20926844185118007
0.233482087065371,187.17817025905,0.7413056264325528,37.73511912422448,230.88092010421033,0.20984113484321554
0.234156359085412,186.937442850618,0.743446440096183,37.68658847868459,230.71003384525602,0.21038762660166105
0.23485829389558,186.651497321198,0.7456750831184664,37.62894185995352,230.48814953510998,0.21095622171164274
0.235531471735974,186.37794663916,0.7478124227617174,37.57379404245466,230.2758187102102,0.21150121899621854
0.23618761233476,186.034865535718,0.7498956691628629,37.50462889200075,229.97399623761737,0.21203213743142985
0.236830562721557,185.727866127262,0.7519370366409435,37.442737811256016,229.71390117525544,0.2125521096724496
0.237513209605279,185.461555568803,0.7541044404967607,37.38904960267069,229.5111248903372,0.2131038898322453
0.238168811161207,185.270476731089,0.7561859754368322,37.35052810898754,229.39612591740251,0.21363352293193583
0.238831835341405,185.022258409386,0.7582910772089608,37.30048729533222,229.21146396431138,0.21416886731867948
0.239547722421084,184.741345370006,0.7605640186869417,37.24385522659321,228.9957138903978,0.21474657310014228
0.240283730716156,184.446408855895,0.7629008450237953,37.18439602534843,228.7658800929869,0.2153401685364388
0.240988079925187,184.146397788067,0.7651371537624687,37.123913794074305,228.52348461615298,0.21590790095892406
0.241674372428372,183.838227470648,0.767316132460081,37.06178665808264,228.26721572296117,0.21646076912673767
0.242338697163648,183.54604871296,0.7694253634945823,37.00288342053273,228.0263590275942,0.21699564936488677
0.243028477314049,183.099573390328,0.7716154154721055,36.91287399549013,227.59798390823138,0.217550722414209
0.243738306567172,182.746254700686,0.7738691233507711,36.841644947658295,227.28851735292432,0.21812160769143119
0.244417431186991,182.49418214486,0.7760253440186964,36.790827120403776,227.0989413512775,0.21866749364734503
0.245076969832924,182.163084002164,0.7781193792195337,36.724077734836264,226.80706064483476,0.21919735116467334
0.245733474466286,181.717763444116,0.780203781430458,36.63430111033379,226.37190082748128,0.21972449256161655
0.246428209749421,181.172262249768,0.7824095659544117,36.52432806955323,225.81821849223095,0.22028202886075118
0.247143983696485,180.8102196514,0.7846821482363399,36.45134028172224,225.49637762908347,0.22085612410339497
0.247887307159844,180.527835455435,0.7870422002325047,36.39441162781569,225.27839445387818,0.2214519671199333
0.248622442189173,180.154209233224,0.7893762539506243,36.31908858141796,224.9445887034474,0.2220408973660647
0.249302626989732,179.719043868283,0.791535840692399,36.23135924384585,224.52347362472884,0.22258549722277213
0.250008082172102,179.163538251044,0.7937756608964238,36.11936931141047,223.95587084435556,0.22315001703098858
0.250715437801358,178.665358692586,0.7960215150193116,36.01893631242534,223.4595223171344,0.2237157378253679
0.251435163474507,178.16451148037,0.7983066440315597,35.91796551444259,222.96133454979255,0.2242910234957282
0.252193370417351,177.672279943319,0.8007139510750895,35.81873163657311,222.48005105195978,0.2248967099669914
0.252978751770947,177.132865637266,0.8032075368727566,35.70998571247283,221.94371688379243,0.22552371788582465
0.253728637090238,176.497942096356,0.8055884227615057,35.581985126625376,221.28052439369617,0.22612202093866024
0.254447581745427,175.84035093216,0.8078710720417306,35.449414747923456,220.58250300011534,0.22669530177074854
0.255196678959398,175.135918663854,0.8102494556960886,35.30740120263297,219.8300234733728,0.2272922766073395
0.25593458280298,174.33960840057,0.8125923003994614,35.14686505355491,218.9591433426048,0.22787998293401185
0.256644830272806,173.655858327953,0.814847336116159,35.00902103891533,218.22373661440895,0.22844533620009963
0.257410094477597,172.998678262094,0.8172770499663704,34.876533537638146,217.530284378039,0.22905412499058514
0.258215302516307,172.234729060721,0.8198335854892747,34.72252137864135,216.70837172894926,0.2296942903086574
0.259007704700174,171.353351681041,0.8223494624230523,34.54483569889787,215.73518999262913,0.2303238747417962
0.259812087797567,170.474022461853,0.8249033787572752,34.36756292830956,214.76523415291635,0.2309625731728102
0.260636584031989,169.532355173871,0.8275211543015651,34.1777228030524,213.71868910928666,0.231616818802207
0.261460888888433,168.465367723148,0.8301383222207748,33.96261813298664,212.51247251495903,0.23227048496273034
0.262264305772238,167.484913973267,0.8326891708268557,33.764958657010624,211.41022866378887,0.23290717624167398
0.263083216449398,166.473708727735,0.8352892122268387,33.56109967951137,210.2701474740877,0.23355572912293737
0.263929988062943,165.291869940327,0.837977712099844,33.32284097996992,208.91735120057905,0.23422590499991824
0.264772316328951,164.058821244122,0.8406521043444193,33.074258362814994,207.49705535912548,0.2348921188881248
0.265571544790572,162.724036470019,0.843189654710066,32.805165752355826,205.93891020991933,0.23552383420593617
0.26636534244971,161.382179685149,0.8457099622778292,32.534647424526035,204.36879924226432,0.2361508622247987
0.267137731736909,159.970005582266,0.8481622982646861,32.24995312538483,202.7040300194532,0.23676060240549868
0.267981983194913,158.5071686664,0.8508427966438488,31.955045203146238,200.98423407623244,0.23742664707726835
0.268884211271755,157.031274825931,0.853707370787822,31.65750500490769,199.25450530249967,0.23813794049656595
0.269792794591428,155.419978815365,0.856592122827784,31.332667729177583,197.35116923530288,0.2388537332944429
0.27065695913804,153.604543447835,0.859335845263277,30.96667595908354,195.17868208721296,0.23953405738168307
0.271497733621375,151.819087940832,0.8620053042478657,30.60672812887173,193.0376262372321,0.24019552343360018
0.272362169075243,150.047663223982,0.8647498868138965,30.24960890595477,190.9149702443373,0.24087514850746872
0.27323862645489,148.093451700225,0.8675326389942757,29.855639862765358,188.55830302975806,0.24156375405459077
0.274130453393302,145.930805153271,0.8703641895237338,29.419650318899436,185.93488293398678,0.2422639486058268
0.275044464813161,143.740468851251,0.8732661757817862,28.9780785204122,183.27548917843617,0.24298105236555664
0.275989875407495,141.419763925496,0.8762678544187965,28.510224407379994,180.450186951451,0.24372225025749414
0.276919986159235,138.940751076761,0.8792209560555712,28.010455417075015,177.41622194189137,0.244450917420324
0.277801087656968,136.291546748901,0.8820184533108733,27.47637582457844,174.15348667419622,0.24514070038074132
0.278725671036502,133.521150111277,0.8849540055408938,26.917863862433443,170.7369222736082,0.2458640125203074
0.279681872014022,130.496451574512,0.8879899436445198,26.308084637421622,166.99394344205868,0.2466115095519203
0.280355839315163,128.427711633194,0.8901297898256425,25.89102666525191,164.43317051944385,0.2471380387618058
0.280524706085153,127.854826816059,0.8906659418203607,25.775533086117495,163.7212645302021,0.24726992056358527