File: example/data/02 processed data/test_ID_078.csv
Strain,Stress_MPa,Displacement(mm),Force(kN),True Stress (MPa),True Strain
-3.35215202391165e-06,-0.152434929580203,-1.0643082675919489e-05,-0.030730881803368925,-0.15243441859514528,-3.352157642435149e-06
3.5107091304503e-06,-0.0779633034171759,1.1146501489179703e-05,-0.015717401968902662,-0.07796357712365705,3.5107029679915554e-06
1.26583941973761e-05,0.0630192127289406,4.0190401576669114e-05,0.012704673286154424,0.06302001045097731,1.2658314080488923e-05
2.95837310342644e-05,0.212209327517629,9.392834603378947e-05,0.04278140042755401,0.21221560546129722,2.958329344429223e-05
4.97569084878246e-05,0.407908026140309,0.00015797818444884308,0.0822342580698863,0.40792832238263715,4.9755670653941636e-05
6.33003533099592e-05,0.541077155265169,0.00020097862175912047,0.10908115450145807,0.5411114056402652,6.329834992710342e-05
7.01998130024205e-05,0.634173699879314,0.00022288440628268506,0.12784941789566973,0.6342182187544566,7.019734911081702e-05
7.87345002864226e-05,0.614620031941811,0.0002499820384093917,0.1239073984394691,0.614668423742892,7.873140088831025e-05
8.90335405974934e-05,0.542736307912396,0.00028268149139704156,0.10941563967513904,0.5427846296475002,8.902957734698038e-05
0.0001128936551422,0.826033012928171,0.000358437355076485,0.16652825540631927,0.8261262668142686,0.00011288728313310379
0.0001389342085097,2.11599283913178,0.00044111611201829744,0.42658415636896685,2.116286822922097,0.000138924558046329
0.0001742499482545,4.51000670555867,0.0005532435857080374,0.9092173518406278,4.510792573993741,0.00017423476849555715
0.0002241978803966,8.21705813682603,0.000711828270259205,1.6565589203841276,8.218900383843401,0.00022417275180750863
0.0002880719570727,12.0835611259925,0.0009146284637058225,2.436045923000088,12.087042061094474,0.00028803047231345754
0.0003575466262629,16.1977750579627,0.0011352105383847075,3.2654714516852805,16.20356651778764,0.0003574827217000054
0.0004357379667893,20.2285353597029,0.0013834680445560274,4.078072728516104,20.23734970057166,0.00043564306056983955
0.0005146336156592,24.5703569624208,0.0016339617297179598,4.9533839636240335,24.583001694062407,0.0005145012371956512
0.0005961427554754,29.3288780642642,0.001892753248634395,5.9127018177556625,29.346362262448434,0.0005959651329717687
0.0006802279042632,34.4026078204842,0.0021597235960356597,6.935565736609615,34.42600943430312,0.0006799966541249728
0.0007670964408695,39.5512389852526,0.0024355311997606623,7.973529779426926,39.581578599910166,0.0007668023727707959
0.0008568927207382,44.8141666778916,0.0027206343883437846,9.034536002262946,44.85256761110383,0.0008565257977648847
0.0009471139321515,50.1508985716724,0.0030070867345810123,10.110421152049156,50.19839718641955,0.0009466657027451686
0.0010384786576577,55.5130143452761,0.0032971697380631973,11.19142369200766,55.57066342589591,0.0010379398117174722
0.0011240375941368,60.9656830317352,0.0035688193613843395,12.290681699197817,61.0342107514151,0.0011234063368739482
0.0012111954573065,66.4731903354886,0.003845545576948137,13.400995171634502,66.55370236165561,0.0012104625518233481
0.0013015279330693,71.9743657471295,0.004132351187495028,14.510032134621307,72.06804239461432,0.0013006816797909125
0.0013941918271162,77.5386853033534,0.004426559051093935,15.631798957156049,77.64678910468868,0.0013932208440772123
0.0014862685029486,83.0429385524802,0.004718902496861805,16.741456412180007,83.16636265644304,0.0014851650990848461
0.0015731629522846,88.5215677420952,0.004994792373503605,17.845948056806392,88.66082659294521,0.0015719268276945069
0.0016659041749443,93.9600029047937,0.0052892457554481525,18.94233658560641,94.11653126591057,0.0016645180957541195
0.001758987666115,99.352713409034,0.0055847858399151245,20.029507023261253,99.52747360651554,0.0017574424590450295
0.0018514965621966,104.713871072965,0.005878501584974205,21.110316408309746,104.90774844527088,0.0018497846551708832
0.0019464811772141,110.098576878778,0.006180077737654767,22.195873098761645,110.3128816863106,0.001944589237413108
0.0020337454839874,115.364053741475,0.0064571419116599945,23.257393234281363,115.5986748647862,0.0020316802233095624
0.0021231436271892,120.599685160534,0.006740981016325709,24.312896528363655,120.85573561352359,0.0021208929428793225
0.0022131456368363,125.858106838908,0.0070267373969552524,25.372994338723853,126.13664915891901,0.0022107002373835797
0.0022974975119021,131.092748887319,0.007294554600289167,26.428298175683512,131.39393415171602,0.0022948622999835696
0.0023845551491901,136.411364989967,0.007570962598678567,27.50053118197735,136.7366454127619,0.0023817166091017325
0.0024688337186261,141.621462707018,0.007838547056637868,28.55088688173483,141.9711025494302,0.0024657911553538888
0.0025526819924541,146.790651012224,0.008104765326041766,29.592995244064358,147.16536086372352,0.002549429433766344
0.0026394376785665,151.817091908749,0.008380214629448638,30.6063257288038,152.21780366138336,0.0026359604801587957
0.0027239747370527,156.617505246367,0.008648619790142321,31.574089057667585,157.0441273740383,0.0027202714414666473
0.0028075417379734,161.449051073824,0.008913945018065545,32.54812869648292,161.90232602326995,0.002803607953790281
0.0028913880631288,166.148394269309,0.009180157100433938,33.4955162846927,166.62879375320728,0.0028872160406854595
0.0029765541856339,170.837831657295,0.009450559539387633,34.44090686211067,171.34633972017915,0.0029721330192786725
0.0030666974435547,175.412731041182,0.009736764383286172,35.3632065779023,175.95066881503294,0.003062004718613417
0.0031623651146488,179.839010723036,0.01004050923900994,36.25554456176406,180.4077273367995,0.0031573753549500976
0.0032604813390394,184.236274809689,0.010352028251450094,37.1420330016333,184.83697374568013,0.0032551774953534676
0.0033645699570398,188.573128878584,0.010682509613601364,38.01634278192253,189.20759636271384,0.003358922455605512
0.0034742143837726,192.839150683869,0.011030630668478003,38.87637277786799,193.50911523492937,0.0034681932427732937
0.0035977267842068,196.886659409203,0.01142278253985659,39.692350536895326,197.5950038172125,0.0035912704459934615
0.0037361324843291,200.93340386532,0.011862220637744891,40.50817421924852,201.68411768268803,0.003729170476626035
0.0039044687130303,204.823557086742,0.012396688163871203,41.29242910868719,205.62328425707875,0.003896866058191151
0.0041137984149915,208.685471835515,0.01306130996759801,42.07099112203982,209.54396179878367,0.004105359881326413
0.0043650996454593,212.412210286069,0.013859191374333276,42.82230159367151,213.33941074988,0.004355600231894158
0.0046605313562565,216.082801848318,0.014797187056114386,43.562292852620914,217.08986252187984,0.004649704705592931
0.004987804063961,219.661903948988,0.015836277903076172,44.28383983611599,220.7575344862022,0.004975406177665958
0.0053276809950035,223.188115568956,0.01691538715913611,44.994724098701525,224.37719065058337,0.005313539109344447
0.005676416221662,226.387274594607,0.01802262150377685,45.63967455827277,227.67234299249367,0.005660366080643884
0.0060267434702634,229.159721917471,0.019134910518086294,46.198599938562154,230.5408087751845,0.006008655290664742
0.0063768553797188,231.368053242578,0.020246515830607187,46.64379953370372,232.84345385759298,0.006356609262907489
0.0067354021761083,232.948056622141,0.021384901909143852,46.962328215023625,234.517055469634,0.0067128206950668986
0.0070937408243711,233.952715903616,0.022522627117378242,47.16486752616898,235.61231583539399,0.007068698603865936
0.0074493356893885,234.52913241482,0.023651640813808487,47.28107309482772,236.27621865111905,0.007421726417325084
0.0078046608153712,234.868958630952,0.024779798088803557,47.349582059999925,236.70203118912605,0.007774361996047242
0.0081542586894988,235.094659782381,0.025889771339158686,47.39508341212801,237.01168245476623,0.008121192354790663
0.0085080720584799,235.269668293342,0.02701312878567368,47.43036512793775,237.2713595843564,0.008472082404370865
0.0088644603953226,235.398007385714,0.028144661755149254,47.45623828895995,237.48468369932252,0.008825401719288554
0.0092193572802942,235.58769823072,0.029271459364934083,47.494479963313154,237.75966539155112,0.009177118417595847
0.009579100884906,235.762462720398,0.030413645309576545,47.52971248443224,238.02085513567056,0.009533512199218427
0.0099402633371252,235.906617529235,0.03156033609537251,47.55877409389378,238.2515914304461,0.009891183893254083
0.0103044402004844,236.087579727331,0.03271659763653797,47.59525607302993,238.52033007470837,0.01025171137456963
0.0106691512724179,236.222363734727,0.03387455528992683,47.62242852892096,238.74265586734094,0.01061263749199302
0.0110259104080879,236.356779877437,0.03500726554567908,47.649526823291296,238.96282855670975,0.01096556820457686
0.0113803784401952,236.556147795004,0.03613270154761976,47.68971939547281,239.24824627926586,0.011316109080257028
0.0117294119630732,236.745831821179,0.037240882982757406,47.727959695149686,239.52272121315008,0.011661155629877573
0.0120813976037066,236.950705271871,0.03835843739176845,47.76926218280919,239.81340095473917,0.012009000045490445
0.0124320413185442,237.152568993345,0.03947173118637783,47.80995790905835,240.10085952986915,0.01235539806054177
0.0127869547205499,237.326421120339,0.040598581237745936,47.84500649786034,240.36110332119495,0.012705891914621962
0.0131410142198664,237.468681174739,0.04172272014807582,47.87368612482738,240.5892604908292,0.013055420139069495
0.0134964869701193,237.608429850768,0.042851346130128774,47.90185945791484,240.8153089282394,0.013406220668211491
0.0138474909833996,237.71017011104,0.043965783872293725,47.922370294385665,241.001859548315,0.013752490487842078
0.0141914144447901,237.899863180968,0.04505774086220857,47.960612417283144,241.27599873572797,0.014091658995671844
0.014532978968751,238.091319574782,0.04614220822578442,47.99921002627605,241.55149571480447,0.014428387363800255
0.0148684095323924,238.329815588841,0.04720720026534587,48.04729082271035,241.87340089079544,0.014758958308115707
0.0152042181002646,238.568519593228,0.0482733924683401,48.09541354999477,242.19576739698064,0.015089792354508098
0.0155422334401204,238.733096142304,0.04934659117238226,48.128592182288486,242.44354165243035,0.015422689987022467
0.015873931482727,238.862978339156,0.050399732457658226,48.15477643317385,242.65467289107187,0.015749258271042364
0.0162200262590989,239.022052844556,0.051498583372639004,48.18684585346249,242.89899681819838,0.01608988698892193
0.0165707038934872,239.151286532238,0.05261198486182186,48.21289936489919,243.11419168711024,0.016434907883267347
0.0169186100973585,239.261390295862,0.05371658705911324,48.23509628364578,243.30936046962955,0.016777084461105277
0.017268834702171,239.422428624365,0.05482855017939292,48.26756161067198,243.5569749682715,0.01712142304127737
0.0176066876606354,239.571114529877,0.05590123332251739,48.29753668922321,243.78916831591485,0.017453485575674065
0.0179424139860219,239.748230843703,0.05696716440561953,48.333243338090526,244.04989285391704,0.01778334873462128
0.0182792534890857,239.964504674231,0.058036629827847096,48.37684414232497,244.35087668355413,0.018114196315232742
0.0186152609669253,240.126409186253,0.05910345356998782,48.409484091948606,244.59642495830576,0.01844411765234933
0.0189480964567097,240.421759534249,0.06016020625005329,48.4690267221046,244.97729422419582,0.01877081717953918
0.0192845726903259,240.587822860426,0.06122851829178473,48.502505088661884,245.22745621878514,0.019100981877383606
0.0196143711982089,240.768626000504,0.062275628554313255,48.53895500170161,245.4911512037606,0.019424488357925755
0.0199465269992666,240.828423700113,0.06333022322267146,48.55101021794279,245.63211435563815,0.01975020141144418
0.0202747282087447,240.87667591966,0.06437226206276442,48.56073786540345,245.76038505575698,0.020071932411424027
0.0206043839485652,241.025143206431,0.0654189190366945,48.59066887041649,245.99131779831424,0.020394985100555617
0.0209385709821805,241.186231715763,0.06647996286842309,48.62314431389782,246.23632674846814,0.020722371831060692
0.0212659432293357,241.365474896365,0.06751936975314084,48.65927973910718,246.49833938303271,0.02104297855549117
0.0215985470379671,241.510738949604,0.06857538684554554,48.688564972240165,246.72702000498123,0.02136860349356711
0.0219211216802433,241.689267577624,0.06959956133477248,48.724556343649,246.98736742100198,0.021684308450943632
0.0222473744404823,241.790589184129,0.0706354138485313,48.744982779520406,247.16979495789315,0.022003511846973196
0.0225740856700251,241.93772306946,0.07167272200232969,48.77464497080314,247.39924595684082,0.022323061733059882
0.022897735929449,242.030213346437,0.07270031157600057,48.793291010641695,247.57215725859194,0.0226395170943191
0.0232246916660246,242.174437368001,0.07373839603962809,48.822366573389,247.7988640052658,0.022959102799405683
0.0235494338692778,242.274386372795,0.07476945253495701,48.84251629275548,247.979811012901,0.02327642379924321
0.0238778321820855,242.448390418844,0.07581211717812146,48.87759550843896,248.23753239808195,0.023597214990284915
0.0242010771457638,242.554541101703,0.07683841993780006,48.898995486103324,248.4246222629606,0.023912871740510572
0.024537114337277,242.67839292359,0.07790533802085448,48.92396401339575,248.63302039794277,0.02424091482178251
0.0248735308963184,242.818095692565,0.07897346059581091,48.952128091621105,248.85783909795921,0.024569220486482263
0.025207542760045,242.959510660204,0.08003394826314286,48.98063734909712,249.08392291413065,0.02489507283542008
0.0255420186512009,243.123335201152,0.08109590921756285,49.01366437655224,249.333195963402,0.025221271509715308
0.0258723578071598,243.227696549331,0.08214473603773235,49.03470362434513,249.52057054306658,0.02554333141395019
0.0261999360877031,243.354450455756,0.08318479707845733,49.06025721188041,249.7303215043549,0.025862597245178746
0.0265324524844485,243.509724151593,0.08424053663812399,49.09156038896114,249.97063433714632,0.026186571672147545
0.0268622004944229,243.671211930646,0.08528748656979271,49.12411632521823,250.21675688024604,0.026507745210152613
0.027189030636493,243.843749688097,0.08632517227086527,49.15889993712036,250.473624868884,0.026825974999044738
0.0275149538500434,243.96083844691,0.08735997847388778,49.182505030897055,250.67340965799463,0.02714322090769605
0.0278403461529863,244.082083618882,0.08839309903573149,49.20694805756661,250.87741331657384,0.027459849673205285
0.0281661587364028,244.145707370531,0.08942755398807889,49.21977460589905,251.02235411914072,0.02777678698383047
0.0284941272125515,244.240907940441,0.090468853899851,49.23896704079291,251.20033944180497,0.028095720043577167
0.0288216979151389,244.372187997488,0.091508890880566,49.265433100293585,251.41540937881317,0.028414164787310604
0.0291456578852719,244.511175893748,0.09253746378573828,49.2934530601796,251.6376149754727,0.028728999686800767
0.0294645009458585,244.651068085345,0.09354979050310074,49.321655326005555,251.85958971235095,0.029038765051329317
0.0297897347700506,244.754034742644,0.09458240789491065,49.34241340411703,252.04519252152713,0.029354640401983448
0.0301179322744787,244.803243951398,0.09562443497146987,49.352333980601834,252.17621147329888,0.02967329304108547
0.0304501650456092,244.893164553807,0.0966792740198092,49.370461974047494,252.35020183301197,0.029995760203846672
0.0307855937282633,244.987277952476,0.09774426008723597,49.38943523521916,252.52935676011404,0.030321223881824438
0.0311194607819904,245.101789273499,0.09880428798281952,49.412520717537404,252.72922479239136,0.030645067170257837
0.0314487108944764,245.17316736366,0.09984965708996256,49.426910540513866,252.8835474231628,0.03096432945676437
0.0317775349956435,245.189566522288,0.1008936736111681,49.43021661089326,252.98108655301667,0.031283076956808285
0.0321085193856555,245.285148434478,0.10194454904945621,49.449485924390764,253.1608913779998,0.03160381597449458
0.0324403606993956,245.431719846349,0.10299814522058102,49.479034721023964,253.39361336523754,0.03192528215027642
0.032774379698989,245.599388206711,0.10405865554429006,49.512836662472935,253.64875580963715,0.03224875359948906
0.0331088840501721,245.731065340569,0.10512070685929642,49.53938277265871,253.86694669045514,0.03257259024599863
0.0334416607371501,245.800699458878,0.10617727284045157,49.55342101090981,254.02068305913602,0.032894650299834564
0.033777095703956,245.903236033667,0.10724227886006028,49.57409238438727,254.20913317108867,0.0332191780922655
0.0341102852870984,245.981317946314,0.10830015578653741,49.5898336979769,254.37181087675924,0.03354142928359113
0.0344442379364731,246.113328130408,0.1093604554483021,49.61644695109026,254.59051416386907,0.03386431432097033
0.0347711777767935,246.148365873159,0.11039848944131934,49.623510560028855,254.7072344624018,0.03418031800097213
0.0351006989663458,246.21668789487,0.11144471921814791,49.637284279605794,254.85906573715857,0.03449871567189922
0.035424530258131,246.321097182946,0.11247288356956592,49.65833319208192,255.04690634331934,0.034811516781352
0.0357547683840135,246.427669064629,0.11352138961924287,49.679818083429204,255.23863329544716,0.03513040576300367
0.0360893636556593,246.532697185558,0.11458372960671827,49.70099175260849,255.42990534729816,0.03545339847213694
0.0364263095447398,246.587280785005,0.11565353280454886,49.71199580625701,255.56954540467524,0.03577855489571047
0.036762889355577,246.583815282615,0.11672217370395696,49.711297160975185,255.6489488007258,0.036103252529648425
0.0370970211566315,246.631029231217,0.11778304217230501,49.720815493013355,255.78030574048927,0.036425484327709666
0.037436764198861,246.670452330153,0.11886172633138367,49.72876318975885,255.90499588886337,0.036753021095406804
0.0377872313855133,246.740631314613,0.11997445964900472,49.74291127302598,256.0642766423059,0.037090784335162816
0.0381364544453814,246.852926083635,0.12108324286408594,49.76554989846081,256.26702145393267,0.03742723510697702
0.0384769575307597,246.935184257679,0.12216434016016203,49.78213314634809,256.43649885521205,0.037755175865200136
0.0388132769880981,247.041838525557,0.12323215443721146,49.8036346467523,256.6303418318984,0.038078981806891045
0.0391433434979614,247.087634605659,0.12428011560602743,49.812867136500856,256.75947076112703,0.038396665544256144
0.0394738363703871,247.125078467093,0.12532943047597903,49.82041581896595,256.8800533775221,0.038714658562317865
0.039808593305062,247.273367968073,0.12639228374357184,49.85031098236352,257.11697290868693,0.039036651315961755
0.040144083164878,247.387050737197,0.12745746404848762,49.87322942861891,257.31817707590494,0.03935924506198375
0.0404809007625472,247.489949142168,0.12852685992108734,49.893973747061075,257.50856521312,0.03968301085660156
0.0408167291278965,247.454513234154,0.1295931149810714,49.88682986800546,257.55479707230796,0.04000572142277978
0.0411549645758341,247.350618015447,0.13066701252827326,49.86588459191412,257.53032393768336,0.040330639818102934
0.0414936224385965,247.339291474257,0.13174225124254388,49.86360116121022,257.6022946489198,0.0406558582614437
0.0418282190771104,247.368423917957,0.13280459556982552,49.869474261860134,257.7154045463568,0.04097707280902171
0.0421606141873286,247.451950426436,0.1338599500447683,49.8863132059695,257.8846766382669,0.04129607174772153
0.0424906709925235,247.569831546126,0.13490788040126211,49.910078039699,258.0892398060269,0.04161272596255282
0.0428294836269069,247.625793493669,0.1359836105154294,49.92135996832367,258.2314783617059,0.04193767619776184
0.0431683518137459,247.703481050635,0.13705951700864322,49.93702177980801,258.39643206611834,0.04226257412820299
0.0435071380997856,247.701870942344,0.13813516346681926,49.936697181976555,258.47867044900784,0.042587288048172016
0.0438422795588593,247.753493424751,0.13919923759937827,49.947104274429805,258.61557134516295,0.0429084048282553
0.044177238614425,247.738484042963,0.14026273260079936,49.944078383061346,258.6828861665049,0.043229243839120544
0.0445163098772338,247.754614898229,0.14133928386021732,49.94733036348297,258.7837361085533,0.0435539169018896
0.0448540293533661,247.813311596857,0.14241154319693736,49.95916361792637,258.9287371493773,0.04387719083062525
0.0451947363155663,247.846185305406,0.143493287801923,49.96579095756985,259.0475282971028,0.04420321859688075
0.045532913366083,247.948001277102,0.1445669999373135,49.986317057463765,259.2377961385457,0.04452672037246344
0.0458698841859168,247.998850430531,0.14563688229028585,49.99656824679505,259.37452897802,0.04484896420148036
0.0462047938138263,248.017857023399,0.1467002203588985,50.00039997591723,259.4774709693122,0.04516913406376332
0.0465433293000262,248.009882961689,0.14777507052758318,49.9987924050765,259.5530886140358,0.04549266606019777
0.0468868861552632,247.968240925762,0.14886586354296066,49.990397370633616,259.59469960816904,0.04582088990619457
0.0472289909603209,247.98924927748,0.14995204629901884,49.99463265433997,259.7015312898629,0.0461476194934535
0.0475663830111891,248.010830426943,0.15102326606052538,49.99898341407171,259.80780857795406,0.046469743609229085
0.047900459990253,248.094428229013,0.15208396046905326,50.01583673096902,259.97826546220153,0.04678860046254563
0.0482350173597315,248.145269155027,0.1531461801171475,50.02608626165345,260.114560520455,0.047107813963709444
0.0485705351736221,248.174439854606,0.15421144917625015,50.031967074688566,260.2284052147581,0.04742784155649108
0.0489095155978683,248.18138452906,0.15528771202323183,50.033367121058504,260.31981582678463,0.047751067922408366
0.0492484604760852,248.19444484587,0.15636386201157051,50.0360000809274,260.4176391532458,0.04807415596919081
0.0495916256651292,248.221099092971,0.1574534114867852,50.04137357714296,260.53078692137655,0.048401160579373236
0.0499383771608959,248.188790226866,0.15855434748584446,50.03486010973619,260.5829356403217,0.04873147402900501
0.0502865924889876,248.153611049411,0.15965993115253563,50.02776798756127,260.6324105629235,0.04906307215426737
0.0506323326365417,248.176797249065,0.1607576561210199,50.0324423254115,260.7425674000512,0.049392204465410136
0.0509732112488487,248.191668685598,0.16183994571509464,50.03544040701656,260.84279504371324,0.04971660274870194
0.0513155906782934,248.270849054169,0.16292700040358155,50.051403169320466,261.0110143215851,0.050042323393893764
0.0516587151159884,248.302440166364,0.16401642049326315,50.05777193753898,261.12942518552296,0.05036864639251002
0.0520050823571066,248.327593518504,0.16511613648381346,50.0628428533304,261.2418904709759,0.05069794544178219
0.0523497367737612,248.378331713879,0.1662104142566918,50.07307167351801,261.38087199940645,0.051025508471175304
0.0526999944790297,248.382052666296,0.16732248247091927,50.07382181752528,261.47178547049987,0.0513582870305611
0.0530510934692512,248.382683248025,0.16843722176487255,50.073948942801835,261.55965619315936,0.05169175378784738
0.0533985891378903,248.374839208281,0.1695405205128017,50.07236758438945,261.63770519935355,0.05202168872496992
0.0537455114355804,248.378697177568,0.17064199880796777,50.07314535099771,261.72793728707956,0.05235097071449346
0.0540877942020048,248.386947642002,0.17172874659136525,50.07480864462761,261.82164974852674,0.05267574285706988
0.0544344556731044,248.378613510841,0.17282939676210646,50.07312848378555,261.898968138144,0.05300456222261714
0.0547781387690686,248.375934478883,0.1739205905917928,50.07258839094282,261.9815058846644,0.0533304498073125
0.0551253340273951,248.406970416647,0.17502293553697942,50.078845235996035,262.1004876355979,0.05365955989783256
0.0554703725390162,248.408406052521,0.1761184328113764,50.07913466018824,262.18771287807755,0.05398651831400041
0.0558163402208765,248.399171451612,0.17721688020128287,50.07727296464498,262.263904115939,0.05431424991280788
0.0561653955045272,248.337799210474,0.17832513072687384,50.064900320831555,262.28578992185413,0.05464479755053071
0.0565125383121376,248.309750448566,0.17942730914103688,50.059245690430906,262.3423647340679,0.054973425785983104
0.0568629512532734,248.298174972054,0.18053987022914303,50.05691207436608,262.41714199176664,0.05530504025400085
0.0572103460781603,248.329130428413,0.18164284879815895,50.063152694368064,262.53612592151114,0.05563369000181447
0.0575569490347954,248.376727143886,0.18274331318547538,50.07274819220742,262.6725337695359,0.05596148300347426
0.0579093522422504,248.361699498518,0.183862193369145,50.06971861890123,262.7441646382616,0.056294651355531806
0.0582619499423709,248.382058380667,0.18498169106702758,50.07382296954246,262.85328143262444,0.056627892528417385
0.0586159332847104,248.379891977481,0.1861055881789555,50.073386222660176,262.93891115489663,0.05696233160819971
0.0589655347346858,248.384606126134,0.1872155727826274,50.07433659502862,263.0307372462258,0.05729252098549774
0.0593188599285562,248.354291255656,0.18833738027316593,50.068225117140244,263.08638467130606,0.057626116604704646
0.0596687628946966,248.30516918707,0.1894483221906617,50.05832210811331,263.1212314528208,0.05795637145428657
0.0600170803865238,248.299133545919,0.19055423022721305,50.05710532285727,263.20132260384867,0.05828502156634589
0.0603678210678953,248.319751191471,0.19166783189056757,50.06126184020055,263.310273499022,0.05861584894049838
0.0607204269915062,248.359149688195,0.19278735569803215,50.06920457714012,263.4396233045096,0.05894832537299163
0.0610664422911325,248.39455177417,0.19388595427434568,50.07634163767267,263.56312333551904,0.05927448000020969
0.0614127706754551,248.341862304901,0.19498554689456993,50.06571944066805,263.5932241437473,0.05960082325509809
0.0617559761044669,248.327978014092,0.19607522413168238,50.06292036764095,263.6637146904008,0.05992411873740172
0.0620981375758092,248.271076236464,0.19716158680319418,50.05144896927114,263.68824768469017,0.060246326813840324
0.0624504087585952,248.210224067187,0.19828004780853975,50.039181171944904,263.7110540182453,0.06057794661760713
0.062798981409876,248.164614368444,0.1993867659763563,50.02998625667831,263.749099372757,0.060905976500611934
0.0631524893874606,248.160914032584,0.20050915380518738,50.029240268968934,263.8328935224093,0.06123854098827662
0.0635093841222813,248.194849045637,0.20164229458824312,50.03608156760043,263.957551050848,0.061574179429550915
0.0638640839116961,248.149477941925,0.20276846641963508,50.026934753092085,263.9973170238517,0.06190764207542045
0.0642136894550551,248.094707945112,0.20387846401979992,50.01589312173458,264.025784476542,0.06223620670861144
0.064563918360349,248.040494243195,0.20499044079410805,50.00496363942812,264.05496046357325,0.06256524897884955
0.0649248612413309,247.994201877104,0.2061364344412256,49.99563109842416,264.0951910226296,0.0629042438473794
0.0652876760890779,248.036954421958,0.20728837158282232,50.00425001146673,264.2307107603802,0.0632448810794839
0.0656491077557258,248.064035726313,0.2084359171244294,50.0097096024247,264.3492183380299,0.06358410434772331
0.0660072204353074,248.106969242281,0.209572924882101,50.01836499924385,264.48382065259227,0.06392009911218392
0.0663621329666822,248.030458077588,0.21069977216921595,50.00294034844175,264.49028831632,0.06425298003085379
0.0667139790557342,247.994031198262,0.21181688350195607,49.99559668956962,264.53869980157,0.06458287551865197
0.0670683907631088,247.957479403089,0.21294214067287043,49.98822784766274,264.5875885243309,0.06491506657585319
0.0674233326460682,248.014594901424,0.21406908115126652,49.999742332127084,264.73656543454257,0.06524764400619719
0.0677791035226226,248.042208826849,0.21519865368432675,50.00530929949276,264.8542873769039,0.06558088723767741
0.0681345703884317,248.013744116298,0.21632726098327063,49.99957081384568,264.9120540220884,0.06591373483674738
0.0684888742599518,247.964597285434,0.21745217577534695,49.98966281274349,264.9474134098357,0.06624538323801815
0.0688419229764807,247.899526629234,0.2185731054503262,49.976544568453576,264.9654067473498,0.066575747372757
0.0691952399333008,247.797604117317,0.21969488678823004,49.95599699005111,264.94401878911185,0.06690625328366036
0.0695520061198078,247.738948059558,0.22082761943038975,49.944171928806895,264.9696888911111,0.06723987493107514
0.069906180737413,247.693960202916,0.22195212384128626,49.935102376907864,265.00929895242666,0.06757096307574308
0.0702646068125815,247.677526277858,0.22309012662994623,49.93178929761617,265.0804902780845,0.0679059139877025
0.0706205517675139,247.691202754411,0.22422025186185662,49.93454647528925,265.18329216088665,0.0682384352878625
0.0709840314769826,247.663963816628,0.22537429993941974,49.92905510543221,265.2441504199018,0.06857788143567393
0.0713495196128644,247.653519177481,0.22653472477084446,49.92694946618017,265.32347880122956,0.06891908707028843
0.0717125672997268,247.630426968838,0.22768740117663258,49.922294076917744,265.3886406283009,0.0692578991770887
0.072079937459788,247.572899683586,0.22885380143482686,49.91069657621094,265.41793880951724,0.06960062839443758
0.0724452664363721,247.565020237146,0.2300137209354814,49.90910807980864,265.4999340885519,0.06994133689201498
0.0728156106851141,247.527708622602,0.23118956392523723,49.90158605831656,265.55158988744375,0.07028660422651084
0.0731823354047466,247.533864265561,0.23235391491007043,49.9028270359371,265.64897054427627,0.07062837969173937
0.0735526912702294,247.50988985075,0.23352979478297833,49.897993793911205,265.7149083652707,0.07097342075601158
0.0739118182176359,247.512209453524,0.23467002284099397,49.89846142583044,265.8062868852983,0.07130788677318466
0.074280915263023,247.488403156492,0.235841905960098,49.89366207634879,265.8720682599403,0.07165152172107982
0.0746512932749244,247.458849369909,0.23701785614788495,49.88770403297365,265.9319725076974,0.071996230608682
0.0750152144629813,247.406350859899,0.23817330591996563,49.877120333355634,265.9655913291579,0.07233481446829325
0.0753836270174635,247.383715416841,0.2393430157804466,49.872557028035146,266.0323971500185,0.07267746026123195
0.0757451369281021,247.337305241852,0.24049080974672415,49.86320073675736,266.07190329482387,0.07301357209247253
0.0760990666489989,247.283402693082,0.2416145366105715,49.85233398292533,266.10143883581406,0.0733425268778608
0.0764533576565719,247.217852749949,0.24273941055961576,49.839119114389725,266.1184876653306,0.07367170911451315
0.076800166396584,247.178291865825,0.2438405283091542,49.83114364015032,266.1616258107438,0.07399383443708855
0.0771511440504736,247.1546154467,0.24495488236025367,49.82637047405472,266.22287678576777,0.0743197263505162
0.077502455343895,247.100592079783,0.2460702957168666,49.81547936328426,266.2514946828964,0.07464582173460334
0.0778601361171235,247.041976022626,0.2472059321718671,49.8036623661614,266.2766979023908,0.0749777202076761
0.0782246046677498,246.899045866093,0.24836311982010562,49.77484764660435,266.2126261218127,0.07531580390837982
0.0785945965012088,246.774474721644,0.24953784389133793,49.74973410388343,266.1696149891893,0.07565889417471999
0.0789661895318787,246.658290882427,0.25071765176371485,49.72631144189729,266.135956229858,0.07600335078215341
0.0793394033692169,246.593641264983,0.25190260569726364,49.713278079020576,266.1582336375895,0.07634919044664358
0.0797053456127358,246.620747331616,0.25306447232043616,49.718742662053785,266.27773923295365,0.07668817577540596
0.0800739392961943,246.629089386066,0.2542347572654169,49.720424420230906,266.3776521182415,0.0770295011039822
0.0804453915686752,246.691318446834,0.2554141182305437,49.73296979888173,266.53649815588227,0.07737335572341034
0.0808169805039055,246.702102971055,0.25659391309989993,49.73514395896469,266.63982201713924,0.07771721859142053
0.0811904643388952,246.730853912409,0.2577797242759922,49.74094014874166,266.7630465082896,0.0780627158648882
0.0815600082032231,246.68287015629,0.2589530260452333,49.73126662350806,266.8023270698316,0.078404450958803
0.0819334885530743,246.655924284148,0.26013882615601086,49.72583433568424,266.8653046330312,0.07874970769668652
0.0823077286123219,246.587482100563,0.261327038344122,49.712036391473504,266.8835376564919,0.07909554720848358
0.0826792053177555,246.507407937013,0.2625064768838737,49.69589344010182,266.888444530185,0.07943871483065917
0.0830573295102944,246.461087623322,0.2637070211951847,49.68655526486171,266.93148738951777,0.07978790245371514
0.0834288527539593,246.365892623724,0.26488660749382076,49.667363952942765,266.91991640302643,0.08013087555951963
0.0837976563252213,246.321671885482,0.26605755883257765,49.65844905211318,266.9628506915956,0.08047122168695682
0.0841618728487628,246.295828262839,0.26721394629482187,49.65323897778834,267.0245464442768,0.0808072210652355
0.0845247562112563,246.263578621316,0.2683661009707387,49.6467374500573,267.07894756799425,0.08114187832831608
0.0848890899665865,246.222742119734,0.2695228606439121,49.63850481133837,267.12436662735576,0.08147776053852455
0.0852572767533491,246.159346190645,0.27069185369188337,49.625724192034035,267.1462216942443,0.08181708031523768
0.0856195134217066,246.062585197066,0.2718419551139184,49.60621717572851,267.130344012926,0.08215080415747403
0.0859871473221328,246.002566525741,0.27300919274777163,49.59411741158939,267.15562545521266,0.08248938656338017
0.0863529055396377,245.925828306807,0.2741704750883497,49.578646986652295,267.16223812834187,0.08282612778442369
0.0867250674811987,245.838349373836,0.27535208925280585,49.56101123376534,267.1586968127485,0.08316864834725674
0.0870980048407377,245.768601576344,0.27653616536934217,49.54695007779095,267.17455642614175,0.08351176492187232
0.0874760920075365,245.700958892599,0.27773659212392837,49.533313312747964,267.193918579028,0.08385949937815661
0.0878535740433556,245.691200090114,0.278935097587654,49.53134593816698,267.2760501290317,0.08420655669595004
0.0882315217821331,245.678925459411,0.28013508165827256,49.52887137261726,267.35555092249405,0.08455392155158246
0.0886125782861327,245.613328696845,0.28134493605847133,49.51564706528396,267.3777590141118,0.08490402150396756
0.0889947994207188,245.551299831169,0.2825584881607822,49.50314204596367,267.40408850714067,0.08525506838452487
0.0893732492433462,245.475365097729,0.2837600663476242,49.487833603702164,267.41429608570974,0.08560253017057794
0.089755590653416,245.454455795123,0.2849740003245958,49.4836182882968,267.48536545352704,0.08595344233969174
0.0901299266765983,245.450016768662,0.2861625171981996,49.48272338056227,267.57240878279134,0.0862968879233115
0.0905037080922773,245.452456229184,0.2873492731929804,49.4832151758035,267.66681367828255,0.08663970701348787
0.0908788786950145,245.396272973784,0.28854043985667105,49.47188863151486,267.6976110975772,0.0869836820765592
0.0912529492552722,245.343593172527,0.28972811388548925,49.46126838358145,267.73191963040574,0.08732653080744755
0.0916245830502765,245.277476146021,0.29090805118462787,49.44793919103783,267.7509226295243,0.08766702979843055
0.0920504036008394,245.222326071453,0.29226003143266505,49.43682093600493,267.7951401582669,0.08805703340113093
0.0925349473882546,245.159327203169,0.29379845795770837,49.424120364158874,267.84513264765417,0.08850063593205672
0.0930230524674072,245.084974806493,0.29534819158401787,49.40913092098899,267.88352727689056,0.08894729997602158
0.0935075208207651,244.992223557197,0.2968863786059292,49.39043226913092,267.90083900239716,0.08939043886207655
0.0938905159049051,244.89372973239,0.2981023879980737,49.37057591404982,267.88692835884046,0.08974062212239163
0.0942725560253825,244.805412243369,0.2993153653805894,49.3527711082632,267.88384418439887,0.0900898101050061
0.0946536566772929,244.750835942951,0.30052535995040497,49.341768526098924,267.9173975397755,0.0904380179646858
0.0950306246477004,244.736871474865,0.30172223325644876,49.338953289332785,267.9943692454454,0.09078233059216978
0.0954102299831749,244.673979450927,0.3029274801965803,49.326274257306885,268.01838010123856,0.09112893236274237
0.0957882019137187,244.625455598636,0.3041275410760569,49.31649184868502,268.0576881327535,0.09147392342223787
0.0961677540744218,244.550550396514,0.3053326191862892,49.30139095993723,268.06842758581047,0.09182023710017452
0.0965487378482224,244.459977283274,0.3065422426681061,49.28313142030804,268.0622795443792,0.09216773644998809
0.096920309559655,244.418239047419,0.3077219828519046,49.27471699195968,268.1073304379206,0.09250653467960145
0.0972997045113346,244.346014621978,0.3089265618234873,49.260156547790764,268.1208096432187,0.09285234772754343
0.0976779230684356,244.299246154276,0.31012740574228304,49.25072802470204,268.1618891258102,0.09319696951875626
0.0980625402661501,244.214012841372,0.3113485653450266,49.2335449888206,268.16225930918716,0.09354729981331579
0.0984478526834326,244.149130631388,0.3125719322698985,49.22046473528783,268.1850882765751,0.09389814033059417
0.0988355256937063,244.081458751525,0.3138027940775175,49.20682208430744,268.20537803931865,0.09425100607209223
0.0992227104463502,244.01617536703,0.3150321056671619,49.19366095399325,268.22812167969863,0.09460330315893217
0.0996085656847977,243.948967535775,0.3162571960492327,49.180111855212246,268.2483742923008,0.09495426709745414
0.0999985841189817,243.87121391939,0.3174955045777669,49.16443672614903,268.25799001870627,0.09530889263893433
0.100389545478248,243.822971543929,0.31873680689343736,49.15471106325608,268.30024883437983,0.09566424936725121
0.100779431993051,243.753481405381,0.3199746965779369,49.14070185132481,268.31881880774404,0.09601850342304698
0.101167355030786,243.682508171259,0.3212063522227455,49.12639364732581,268.33522299021314,0.09637084894205242
0.101551598400964,243.616242699139,0.3224263249230607,49.11303452814643,268.3558615416738,0.09671972992251247
0.101941126761688,243.536597177501,0.3236630774683594,49.0969779909842,268.3629923014828,0.09707328531240188
0.102333219591467,243.479355802919,0.32490797220290774,49.08543812986847,268.39538218628803,0.09742904214871673
0.102725360575229,243.417691776673,0.3261530198263521,49.07300666217728,268.4228619348217,0.09778471613527018
0.103119028259248,243.358458487328,0.3274029147231124,49.061065231045326,268.4533462452098,0.09814164764883583
0.103508520528126,243.330198085577,0.3286395526768,49.05536793405232,268.51694688923095,0.09849466805151964
0.103901291779597,243.249873706173,0.32988660140022047,49.03917453916448,268.5238498094682,0.09885053423769494
0.104292892079312,243.138063938456,0.3311299323518156,49.01663368999273,268.4956358011623,0.09920521346534866
0.104684950226708,243.047189500148,0.33237471696979787,48.998313403229844,268.49057243571224,0.09956018140029486
0.105076604034541,242.968841172923,0.33361821780966766,48.98251838046128,268.4991818895815,0.0999146574849917
0.105459597656893,242.919366525996,0.3348342225606353,48.9725442916408,268.53754518289486,0.10026117397804103
0.105844094835194,242.857574062441,0.3360550011017409,48.9600869309881,268.56261416295115,0.10060893008542807
0.106224756533436,242.757290726881,0.33726360199365923,48.939869810539214,268.54412483106046,0.10095309812681974
0.106610275961315,242.681452849642,0.3384876261771751,48.924580894487825,268.5537895086352,0.10130153750537103
0.106999377453209,242.590426172146,0.33972302341393856,48.90622991630464,268.5474507486743,0.10165309135345008
0.107386030233515,242.536280546485,0.3409506459914101,48.89531415817138,268.5812889019741,0.10200231040347935
0.107776689350504,242.47900170035,0.3421909886878502,48.883766742790556,268.612585740629,0.10235502410490216
0.108163756554748,242.39714911865,0.34341992706132485,48.86726526231985,268.6157353454846,0.10270437212902954
0.10855649763355,242.304569476582,0.34466687998652124,48.84860120647893,268.6083048995649,0.10305871641958166
0.108956526422966,242.140202486485,0.345936971392917,48.815464821275384,268.522957856766,0.10341950689920053
0.109360960814414,242.028722151502,0.3472210505857644,48.792990385742804,268.4972157506751,0.10378413856103957
0.109763588233388,241.90458091349,0.3484993926410069,48.76796351215959,268.45689572464863,0.10414700906649622
0.110168190399679,241.858067703736,0.3497840045189808,48.758586449073185,268.5031333562196,0.10451152672840393
0.110574313489124,241.808257909703,0.3510734453279687,48.74854479459613,268.54604002406944,0.10487728105900397
0.110978319825672,241.733196354685,0.35235616544650855,48.733412385104494,268.5603403322172,0.1052409963587842
0.111385574277152,241.679605615334,0.35364919832995756,48.722608492051336,268.5992272778736,0.10560750200362423
0.111791291830702,241.646737765218,0.3549373515624788,48.71598233346795,268.6607387466666,0.10597249101033736
0.112195752006009,241.614091847216,0.35622151261907853,48.70940091639875,268.72216657726335,0.10633621631250309
0.112605493141697,241.571004155256,0.357522440724888,48.70071443769961,268.7732262068935,0.10670455585853156
0.113017949235486,241.47070367658,0.35883198882266804,48.68049386119853,268.76122740655677,0.10707519905958454
0.113434265879269,241.342987562781,0.36015379416667903,48.65474629265665,268.7195521820746,0.10744917218670484
0.113842626558908,241.211758630954,0.3614503393245329,48.62829054000033,268.6719387903952,0.10781586272760812
0.114241025381012,241.07858887757,0.36271525558471307,48.60144351771812,268.61965406835105,0.10817347840869167
0.114635291025731,240.992189496678,0.3639670490066959,48.58402540253029,268.61839927455776,0.10852725815495116
0.11504056148851,240.855958888857,0.3652537827260192,48.556561311993576,268.5641636372846,0.10889078226701893
0.115458522409505,240.75489873487,0.36658080865017834,48.53618758494979,268.55210360564814,0.10926555124038845
0.115883141710177,240.663322757382,0.3679289749298119,48.51772586788821,268.5521446929178,0.10964614674723136
0.116319877010605,240.558926642773,0.3693156095086709,48.49667961118303,268.5407114036635,0.11003745103482342
0.116759670598722,240.437742744233,0.3707119541509423,48.472248937237374,268.5111743865499,0.11043134080402024
0.117202520449953,240.264008426137,0.3721180024286007,48.43722409870922,268.42355578708896,0.1108278111281881
0.11764461171277,240.101773216857,0.37352164218804473,48.40451748051837,268.3484530985017,0.11122344558767429
0.118089102554194,239.941212270496,0.3749329006095659,48.372148393732,268.27565469328425,0.11162106972729677
0.118525402590795,239.84952549502,0.3763181532257741,48.35366433979603,268.2777870655284,0.11201121299170959
0.118962664469194,239.778948825496,0.3777064596896909,48.33943608322,268.3036914613995,0.11240206368754373
0.119401722394917,239.687090586852,0.3791004686038615,48.32091746230936,268.30614203874865,0.11279436615083413
0.119848068854828,239.565601393597,0.3805176186140789,48.296425240949155,268.2770760846651,0.11319302329713955
0.120300557272748,239.392144902816,0.3819542693409749,48.26145641240771,268.1911533413432,0.1135970040141298
0.120763854927082,239.189536600296,0.38342523939348533,48.22061057861967,268.0749870983701,0.11401046616935565
0.121221160264615,238.980322403936,0.3848771838401526,48.17843299663349,267.94979436615284,0.11441841300287714
0.121681085101639,238.708784227411,0.3863374451977038,48.12369090024606,267.7551281154954,0.11482852881993576
0.122140512013195,238.423245071644,0.3877961256418941,48.066126206443435,267.5443823005421,0.11523803278278831
0.122612741131468,238.163048178427,0.38929545309241087,48.01367051277089,267.3648723518098,0.11565877312436264
0.123095521083487,237.896744062348,0.3908282794400712,47.95998360296936,267.1807677367677,0.11608873098449918
0.123586502152082,237.716371789106,0.3923871443328603,47.92362055268377,267.0949066828055,0.11652580313919968
0.124082347472556,237.445433397526,0.3939614532253653,47.868999372941246,266.9082201701295,0.11696701166384549
0.124576423638379,237.163429917276,0.3955301450518533,47.812147471322845,266.7084018341816,0.11740645243638184
0.125075760730594,236.790422312891,0.397115540319636,47.736949138278824,266.40716451739445,0.1178503762605931
0.125573631717123,236.394915626045,0.39869628070186547,47.65721499021067,266.07988370067034,0.11829280056383715
0.126075680977973,236.063635805177,0.40029028710506426,47.59042897832368,265.8255194434509,0.11873873969506803
0.126575597158268,235.671085353345,0.40187752097750085,47.51129080723435,265.5012937148818,0.11918258663520832
0.127080850619906,235.302227503355,0.40348170071820155,47.43692906467637,265.20463472724,0.11963097216495584
0.127591718642721,234.816453798318,0.40510370669063916,47.338997085740914,264.7770887040345,0.1200841359977201
0.128103813221733,234.347525981327,0.4067296069790023,47.24446123783552,264.3683376786141,0.1205381818390808
0.128621691848729,233.738919997574,0.4083738716197145,47.121766271510914,263.8028153385567,0.1209971465070685
0.129138997839316,233.226015767752,0.4100163181398283,47.0183647787788,263.344589714056,0.12145539347894829
0.129667157790558,232.604382632954,0.41169322598502167,46.89304353880353,262.76553181859657,0.12192303870786789
0.130191104791478,231.999613969918,0.4133567577129426,46.77112217633547,262.20390002385807,0.12238673770968905
0.130718057881336,231.325253061952,0.41502983377324176,46.63517101728952,261.56364088111894,0.12285288036424555
0.131243090689149,230.620787514767,0.41669681293804806,46.49315076297703,260.8881724453705,0.12331710833524662
0.131763995980745,229.924867994693,0.41835068723886537,46.352853387730114,260.22068737701903,0.1237774739292072
0.132268227667847,229.12293895435,0.41995162284541415,46.191184493196964,259.42862400789016,0.12422290194933167
0.132768631509024,228.356811573829,0.42154040504115114,46.036733213283924,258.6754329422503,0.12466475246252814
0.133290685527187,227.502235914001,0.4231979265488187,45.864450760262606,257.826164897946,0.1251255118287761
0.133835935667663,226.648376711546,0.42492909574483,45.69231274504767,256.98207427629274,0.1256065172970119
0.134392157909394,225.741303646167,0.4266951013623259,45.50944681506727,256.07916457245517,0.12609696378645927
0.134936497768892,224.80296888532,0.42842338041623207,45.320278527280514,255.1370941947543,0.12657670026585885
0.135472792348282,223.826831618181,0.4301261157057953,45.12348925422529,254.14927749996468,0.12704912133257887
0.136013058603309,222.799662145636,0.4318414610655061,44.91641188856021,253.10332564984785,0.12752481548228148
0.136561792548491,221.716100018778,0.43358369134145885,44.69796576378565,251.99404807420285,0.12800773375057795
0.137109756528999,220.688351729989,0.43532347697957186,44.49077170876578,250.94687790447387,0.12848974179728934
0.137662935149455,219.692883079173,0.4370798190995196,44.29008522876127,249.93645019529797,0.12897610127697182
0.138212266487992,218.558256173389,0.4388239460993746,44.061344444555225,248.76568811877624,0.12945884422246354
0.13878328099798,217.411067909892,0.4406369171685865,43.83007129063423,247.58408923970148,0.12996039506878707
0.139358734904992,216.104670204989,0.44246398332334963,43.56670151332578,246.2207436518168,0.13046559089524037
0.139938087647679,214.839689274516,0.4443034282813808,43.31168135774243,244.90394454241334,0.13097395185062924
0.140511531754339,213.586430185305,0.4461241133200263,43.059024325357484,243.5977866525834,0.13147687383045986
0.141082537679774,212.256164269673,0.4479370571332824,42.790842716766086,242.20180256301344,0.13197740628275348
0.141653289915283,210.83560418858,0.4497491954810235,42.504457804417726,240.70116115316875,0.13247746611491004
0.142233696507419,209.368557564802,0.45159198641105525,42.20870120506408,239.1478214396701,0.13298572822076826
0.142825339872781,207.864139317573,0.45347045409607967,41.90541048642272,237.55240566296848,0.13350356462601085
0.143451274990823,206.367528759,0.455457798095863,41.6036937978144,235.9712138761839,0.13405112315817763
0.144144364019509,204.691397496636,0.4576583557619411,41.26578573532181,234.1965088090531,0.13465707732077017
0.14472280171949,203.447331577806,0.45949489545938077,41.01498204608569,232.89079940610014,0.13516251312845137
0.145139662317728,202.563018488506,0.4608184278587864,40.83670452728281,231.9629465899875,0.13552660539110045