File: example/data/02 processed data/test_ID_129.csv
Strain,Stress_MPa,Displacement(mm),Force(kN),True Stress (MPa),True Strain
0.0009877255404740996,1.49361916070233,-0.0002751148831953,0.3011136227975897,1.493489738068965,-8.665411127096612e-05
0.0009357678374829996,2.12667670961125,-0.000440080590192,0.428738024657628,2.12638193507849,-0.0001386176668878
0.0008874055189965996,2.79096841016737,-0.0005936309513863,0.5626592314897418,2.790446581747648,-0.0001869878595296
0.0008519709985860995,3.69965084526108,-0.0007061355536896,0.7458496104046337,3.6988280247892447,-0.000222429634437
0.0007898874610676996,5.25805936038012,-0.0009032507853106,1.0600247670526322,5.2565635032946165,-0.00028452891083
0.0007311075540189996,6.94158597755755,-0.0010898769901902,1.3994237330756023,6.939203150838695,-0.000343327273431
0.0006830444502878996,8.68121877038926,-0.0012424773445364,1.7501337041104748,8.677821536485267,-0.0003914080372309
0.0006466579721283996,10.5109088459774,-0.0013580044126928,2.118999223349044,10.506413141853226,-0.0004278094226604
0.0006442910035868996,12.4428671889314,-0.0013655195378121,2.5084820252885702,12.437515699717892,-0.0004301774068336
0.0006624568797037996,14.450167247046,-0.0013078428811409,2.913153717004474,14.444214948348254,-0.0004120038796257
0.0006879539068277995,16.3607125896014,-0.0012268898200222,3.2983196580636416,16.354390450475574,-0.0003864966707748
0.0007075026019585995,18.2996489775022,-0.0011648227129819,3.689209233864444,18.29293532497666,-0.0003669406098992
0.0007452457716508996,20.3844402518395,-0.0010449881492089,4.109503154770843,20.37773111845637,-0.0003291843009423
0.0007855397407358995,22.5399266502066,-0.000917054797364,4.54404921268165,22.533416304421777,-0.0002888778778467
0.0008308426334753996,24.7396314489205,-0.0007732181129161,4.987509700102373,24.7336065257258,-0.0002435629229512
0.0008737078928409995,26.9434054088643,-0.0006371209144303,5.431790530427043,26.937998729465257,-0.0002006881410628
0.0009082049094018996,29.1602053072252,-0.0005275928868495,5.8786973899366,29.15535972709948,-0.0001661847959124
0.0009484962579195996,31.3502689227982,-0.0003996678553058,6.320214214836117,31.346322562249025,-0.0001258875629731
0.0009965569024299997,33.5653609586858,-0.0002470753089852,6.766776769271058,33.562748936030665,-7.782202301104069e-05
0.0010388206749444996,35.7354430538069,-0.0001128878312515,7.204265319647471,35.73417247218008,-3.5555854543379066e-05
0.0010849366540181995,37.8682785203877,3.3530402307186106e-05,7.63424494971016,37.86867843806122,1.05607008676854e-05
0.0011265271365561995,39.9203848956661,0.0001655801843653,8.047949594966287,39.92246679320657,5.214987934164358e-05
0.0011718822969736995,41.93735770856,0.0003095828186911,8.454571314045696,41.94144686931839,9.750164614784332e-05
0.0012178192897131996,43.9375431858766,0.0004554327706388,8.857808706272722,43.94384573612171,0.0001434331053076
0.0012557291429633995,45.9340698857387,0.0005757965547082,9.260308488964922,45.94240017839506,0.0001813368030655
0.0013008092872179996,47.9055837055659,0.0007189260127166,9.657765675042086,47.91643112927624,0.0002264077576613
0.0013470186454912995,49.8225595397907,0.0008656407252343,10.044228003221804,49.83614329934127,0.0002726055878253
0.0013912737185396995,51.7099785067144,0.0010061505821629,10.424731666953624,51.72636528623508,0.0003168476196446
0.0014392578274332996,53.6236713657818,0.0011585001279001,10.810532147341611,53.64323767448597,0.0003648153768246
0.0014825443881014996,55.5182064817886,0.0012959349580217,11.192470426728583,55.54086726433551,0.0004080852126173
0.0015308916129368995,57.3936078859317,0.0014494373968741,11.570551349803832,57.4198089699038,0.0004564115439544
0.0015780555249346995,59.2151443680815,0.0015991828174671,11.937773104605233,59.24496982994206,0.0005035528235422
0.0016256731570128996,61.0134019390722,0.0017503687993154,12.300301830916956,61.047038460361726,0.0005511453511212
0.0016677878240800995,62.7656436965796,0.0018840828672537,12.653553769230449,62.80288957813579,0.00059323592746
0.0017128928624622996,64.4580185307642,0.0020272913641172,12.994736535802064,64.4991760691313,0.0006383131998526
0.0017575605937534995,66.1674641165738,0.0021691114109668,13.339360765901276,66.21266871545569,0.0006829514319385
0.0018022601610710996,67.9030168969098,0.0023110325372001,13.689248206417018,67.9524424343658,0.0007276194844124
0.0018442392439585995,69.5991546648573,0.002444316125368,14.03118958043523,69.65273650298622,0.0007695671537953
0.0018906534016593995,71.2796219063135,0.002591681076068,14.3699717763128,71.33780585818874,0.0008159445309782
0.0019353597954219995,72.9435059110331,0.0027336238762643,14.705410791664274,73.0063090950888,0.0008606134640095
0.0019862038107474997,74.6732544682161,0.0028950536249227,15.054128100792369,74.74134362602177,0.0009114124508241
0.0020326670205239998,76.400140984299,0.0030425743159631,15.40226842243468,76.47335456121075,0.0009578322553289
0.0020776309005763995,78.03603694542,0.0031853346351295,15.732065048196672,78.11432698991464,0.0010027520792355
0.0021263632595292996,79.6278853066987,0.0033400598748049,16.05298167783046,79.71165283571554,0.0010514344112025
0.0021774657766928996,81.2145876176457,0.0035023103667994,16.372860863717374,81.30417460729882,0.0011024819227121
0.0022243920159542995,82.7839918231523,0.0036513011764543,16.689252751547507,82.87919474810835,0.0011493553565745
0.0022714074918430997,84.3192942394571,0.0038005753124012,16.998769718674552,84.42022709868405,0.0011963157233613
0.0023144649477664994,85.7701385468421,0.003937282734958,17.29125993104337,85.87650115650366,0.0012393207750417
0.0023546136130853995,87.2855408351075,0.0040647547473455,17.59676503235767,87.39728707651982,0.0012794189101642
0.0024017250984922998,88.7894267623323,0.0042143337135125,17.89994843528619,88.90728133701197,0.0013264690519129
0.0024468658577449995,90.3424714572686,0.0043576556241398,18.21304224578535,90.46646559233773,0.0013715489569268
0.0024936980769781998,91.8614060463396,0.0045063479202052,18.519259458942063,91.9917869773897,0.0014183158939172
0.0025447367417920997,93.3909257519274,0.0046683956809893,18.827610631588563,93.52824411237586,0.0014692809223534
0.0025940972944578995,94.9158890665396,0.0048251154357032,19.135043235814383,95.06013477407612,0.0015185677891367
0.0026453996462461995,96.4481146658919,0.0049880004026311,19.443939916643806,96.5996369445648,0.0015697909820188
0.0027022576649919994,97.9634607018302,0.005168524612149,19.74943367748897,98.1229336333983,0.0016265582042898
0.0027514018784674994,99.4665960699842,0.0053245574899337,20.052465767708817,99.6334041358433,0.001675621343201
0.0028007371579854994,100.875077701851,0.0054811970024034,20.33641566469316,101.04922452815543,0.0017248728118191
0.0028495942584213997,102.341629778538,0.0056363182962873,20.632072563353265,102.52330851881916,0.0017736445232491
0.0029039758271739995,103.765337779546,0.0058089797770769,20.91909209635648,103.95518683426188,0.0018279282505286
0.0029540738393292994,105.161558780282,0.0059680409656699,21.200570250104853,105.35923074589284,0.0018779335204737
0.0030059493997977994,106.57393658678,0.0061327458701574,21.485305615894845,106.77979197873874,0.0019297104130578
0.0030551474462816998,107.916483568591,0.0062889496677438,21.755963087427943,108.13024146890056,0.0019788124075789
0.0031086968134080998,109.326786026982,0.0064589689083701,22.04028006303957,109.54919179447816,0.0020322544872722
0.0031591719371510995,110.710607025151,0.0066192274262541,22.31925837627044,110.94141606023705,0.0020826258682214
0.0032112614566325998,112.017118601439,0.0067846116506079,22.5826511100501,112.2564863645668,0.0021346056666352
0.0032586570219834995,113.296576657794,0.006935092570597,22.84058985421127,113.54404823166917,0.0021818990506973
0.0033072681142222995,114.589314255356,0.0070894327884552,23.10120575387977,114.8451798432894,0.0022304030177304
0.0033556268202466996,115.821292812992,0.0072429716800827,23.349572631099186,116.08551024410856,0.0022786528205061
0.0034076704029176994,117.051512752746,0.0074082100550631,23.597584970953594,117.32462840431616,0.0023305766008671
0.0034581334827955995,118.218709270669,0.0075684303336754,23.83289178896687,118.50051401563027,0.0023809209423151
0.0035167142616065994,119.435182256892,0.0077544243064004,24.07813274298943,119.7268833845557,0.0024393607031963
0.0035711996519313997,120.615354765727,0.0079274154206816,24.316055520770565,120.91651004866898,0.0024937118689249
0.0036269641814194995,121.775750169777,0.0081044678018063,24.54999123422704,122.08659352293978,0.0025493359639401
0.0036859636568192995,122.882415318415,0.0082917911362007,24.773094928192464,123.20333353011016,0.002608183489865
0.0037450510894017994,123.97766197334,0.0084793937346501,24.993896653825345,124.30876603953632,0.0026671152758697
0.0038123432047957994,125.068980390915,0.0086930462010261,25.213906446808465,125.4114151703964,0.0027342259025949
0.0038796625577768996,126.098160438059,0.0089067851467411,25.42138914431269,126.45190192543572,0.0028013591871783
0.0039461961785482,127.098896656766,0.0091180293926899,25.623137566004026,127.46390184589823,0.0028677044833034
0.004018850343118399,128.098920652261,0.0093487063652003,25.82474240349581,128.47610465064747,0.0029401479715659
0.004098194925105799,129.028012902771,0.0096006254130103,26.012047401198632,129.41817026329528,0.003019256482191
0.0041721036278959,129.935464007004,0.0098352855443689,26.194989543812003,130.33796869703517,0.0030929396575131
0.004254252519558599,130.781259265694,0.010096108275398,26.365501867963907,131.1971275346513,0.0031748315069066
0.004345161565567,131.542553834148,0.0103847444964746,26.51897885296424,131.97280133398468,0.0032654482838642
0.0044384096191736,132.28331289732,0.0106808070666756,26.668315880099712,132.72831842273635,0.0033583880183615
0.0045354949098483,132.895423569468,0.0109890528645678,26.79171739160475,133.3553904466535,0.0034551431249219
0.0046381914978093994,133.447869215198,0.0113151145313442,26.90309043378392,133.9234528133504,0.0035574802571415
0.0047402469005047,133.975832584019,0.0116391404349018,27.00952784893824,134.46697070380745,0.0036591680743997
0.004860464933443699,134.430545157748,0.0120208326894831,27.101197903802,134.93951117088102,0.0037789398402758
0.004981256287471399,134.842502715383,0.0124043452385211,27.184248547421216,135.36931624499178,0.0038992683526659
0.0050947507355051,135.23206294402,0.0127646901110281,27.26278388951443,135.77574652718707,0.0040123147270891
0.005219869310249899,135.568942448486,0.0131619415858428,27.330698797614783,136.13094260639514,0.0041369245283857
0.005350693638319899,135.850592654604,0.0135773088274651,27.387479479168164,136.43153295408925,0.0042672002777612
0.005482842370585399,136.090388293735,0.013996881052408,27.43582228001698,136.69033820785262,0.004398777649676
0.0056118643381722,136.302574368737,0.0144065257994961,27.47859899273738,136.92104572438456,0.0045272250750024
0.0057486183646799,136.512096529324,0.0148407198336581,27.52083866031172,137.1501871682207,0.0046633521188724
0.005890620803631199,136.680000902291,0.0152915775773285,27.554688181901867,137.33828526042225,0.0048046839042976
0.0060376264137562,136.82403919182,0.0157583203894753,27.58372630107091,137.50313117499064,0.0049509741920848
0.0061867268685335,136.909272984055,0.0162317143333933,27.60090943358549,137.60920123875414,0.0050993272738698
0.0063379748251825,137.010913240366,0.0167119265957538,27.621400109257785,137.7320837363944,0.0052497946100335
0.006496126309293599,137.101155454034,0.0172140575578066,27.63959293953325,137.8444837000899,0.0054071056328538
0.0066659981919852,137.145351692452,0.0177534007853524,27.648502901198327,137.91221669857617,0.0055760472076849
0.006835028909179199,137.166186518411,0.0182900733124434,27.652703202111656,137.9563533238945,0.0057441238988415
0.007005833607888099,137.179721056438,0.0188323782308441,27.6554317649779,137.99339677062275,0.0059139358677893
0.0071755498241619,137.179821141542,0.0193712272175134,27.655451942134864,138.01677908957058,0.0060826371244268
0.007348008267247399,137.168912340485,0.0199187827743099,27.65325272784177,138.02945966908294,0.0062540350598094
0.0075177545318787994,137.157658833532,0.0204577271645146,27.650984020840053,138.04141756201705,0.0064227088118628
0.007691292662866899,137.135839678975,0.0210087107304018,27.646585279281364,138.0432561156951,0.0065951210657972
0.0078633327637626,137.137266454067,0.0215549380507457,27.64687291713991,138.06828544079644,0.0067660156713683
0.0080377046318808,137.123378877638,0.0221085687320209,27.644073181731823,138.0782140419477,0.0069391967222859
0.0082114226832381,137.078453149029,0.0226601235450804,27.635016154844248,138.05678848248584,0.0071116986034229
0.0083912335220569,137.017319859251,0.0232310229583301,27.622691683625,138.01985608077513,0.0072902192823054
0.0085696568798094,136.993425657571,0.0237975171191942,27.617874612566315,138.02022987561924,0.007467330939318
0.0087498336782615,136.945451388665,0.0243695784542797,27.608202999954862,137.99657041908162,0.0076461513196128
0.0089369202713938,136.91363392552,0.0249635783874747,27.601788599384832,137.99012344766606,0.0078317956423392
0.0091228552451206,136.852247207206,0.0255539219290573,27.589413036972733,137.9536996925443,0.0080162630836757
0.0093083996898768,136.790714828472,0.0261430255411582,27.57700810941996,137.91705282896146,0.008200309163519
0.0094974137656743,136.759084656587,0.0267431452318153,27.57063146676793,137.9110116054819,0.0083877620328685
0.0096833537104135,136.717457902812,0.0273335045563623,27.562239513206897,137.89445546455084,0.0085721318830447
0.0098706562074865,136.651049884117,0.027928189984569,27.548851656637986,137.8530708235672,0.0087578184196064
0.0100624419426764,136.584893551419,0.028537109693797,27.535514539966066,137.8125275954481,0.008947913794381
0.0102447034508755,136.479548942338,0.0291157899823291,27.51427706677534,137.73111111049175,0.0091285354039363
0.0104314540909285,136.415290899944,0.0297087232644974,27.501322645428715,137.69173944368964,0.0093135719212055
0.0106196985442064,136.343264048404,0.0303063994036547,27.486802032158245,137.64470449446665,0.0095000538965056
0.0108029785424348,136.272039746963,0.0308883133980299,27.47244321298774,137.5977762732915,0.0096815844916724
0.0109904541259265,136.176685573362,0.031483548375616,27.45321981158978,137.5270242404108,0.0098672365380999