File: example/data/02 processed data/test_ID_078.csv
Strain,Stress_MPa,Displacement(mm),Force(kN),True Stress (MPa),True Strain
-9.544838407603119e-05,-0.152434929580203,-1.0643082675919489e-05,-0.0307308818033689,-0.1524344185951452,-3.352157642435149e-06
-9.071134210544675e-05,-0.121501191835529,4.397025580686172e-06,-0.0244946402740426,-0.121501360101308,1.384888987761394e-06
-8.858552292166926e-05,-0.0779633034171759,1.1146501489179705e-05,-0.0157174019689026,-0.077963577123657,3.510702967991556e-06
-8.530909050035731e-05,-0.0235211386743026,2.1549174426845112e-05,-0.0047418615567394,-0.0235212983156002,6.78711851912637e-06
-7.943783785474345e-05,0.0630192127289406,4.019040157666912e-05,0.0127046732861544,0.0630200104509773,1.2658314080488923e-05
-7.215545265983034e-05,0.137811519993736,6.331197457051822e-05,0.0277828024307371,0.1378142680628539,1.994058057768166e-05
-6.251250101785515e-05,0.212209327517629,9.392834603378949e-05,0.042781400427554,0.2122156054612972,2.958329344429223e-05
-5.0240922258275954e-05,0.315727029533149,0.0001328906085954,0.0636505691538828,0.3157402443857804,4.185443388479869e-05
-4.2339323564294955e-05,0.407908026140309,0.0001579781844488,0.0822342580698863,0.4079283223826371,4.975567065394164e-05
-3.2279341419058255e-05,0.475299869771663,0.0001899186277599,0.0958204537459672,0.4753283007319911,5.981510167430574e-05
-2.8795878742160354e-05,0.541077155265169,0.0002009786217591,0.109081154501458,0.5411114056402652,6.329834992710342e-05
-2.4278486516281045e-05,0.595177194005362,0.0002153213420762,0.1199877223114809,0.5952175575808537,6.781544601642991e-05
-2.1896419049699056e-05,0.634173699879314,0.0002228844062826,0.1278494178956697,0.6342182187544566,7.019734911081702e-05
-1.5755263382941746e-05,0.646150030770369,0.0002423825755246,0.1302638462033064,0.6461993584896237,7.633805484581043e-05
-1.3361731765696958e-05,0.614620031941811,0.0002499820384093,0.1239073984394691,0.614668423742892,7.873140088831025e-05
-8.69963053411245e-06,0.580547057626876,0.0002647842098196,0.1170382868175782,0.5805954732785032,8.339312421466087e-05
-3.0626914546261463e-06,0.542736307912396,0.000282681491397,0.109415639675139,0.5427846296475002,8.902957734698038e-05
9.348677992880445e-06,0.554878851791746,0.0003220875893928,0.111863576521216,0.5549351414269519,0.000101439764858
2.079742309008045e-05,0.826033012928171,0.0003584373550764,0.1665282554063192,0.8261262668142686,0.0001128872831331
3.320580147298045e-05,1.36582152132809,0.0003978339564421,0.2753496186997429,1.3659926615421447,0.0001252941838809
4.683797645758045e-05,2.11599283913178,0.0004411161120182,0.4265841563689668,2.116286822922097,0.0001389245580463
6.369647518688045e-05,3.1035231550652,0.0004946418454838,0.6256702680611442,3.1040066613395068,0.0001557805728155
8.215371620238045e-05,4.51000670555867,0.000553243585708,0.9092173518406278,4.510792573993741,0.0001742347684955
0.00010540313262929957,6.27745833531708,0.0006270604828637,1.2655356003999234,6.27869812935012,0.0001974798642495
0.00013210164834439957,8.21705813682603,0.0007118282702592,1.6565589203841276,8.218900383843401,0.0002241727518075
0.00016273832714109956,10.1463579192132,0.0008090997254387,2.045505756513381,10.14894356186096,0.0002548020943823
0.00019597572502049956,12.0835611259925,0.0009146284637058,2.436045923000088,12.087042061094474,0.0002880304723134
0.00023025621952689956,14.1098535340997,0.0010234690337636,2.8445464724745,14.11440187997784,0.0003223005071903
0.00026545039421069954,16.1977750579627,0.0011352105383847,3.2654714516852805,16.20356651778764,0.0003574827217
0.0003072273833178996,18.2079659990014,0.0012678524788,3.670725945398682,18.215236869812657,0.0003992439069141
0.00034364173473709956,20.2285353597029,0.001383468044556,4.078072728516104,20.23734970057166,0.0004356430605698
0.0003827426133217996,22.3468709792281,0.0015076133340624,4.5051291894123855,22.3574821416416,0.0004747261450842
0.0004225373836069996,24.5703569624208,0.0016339617297179,4.9533839636240335,24.583001694062407,0.0005145012371956
0.0004632532023135996,26.9105846483774,0.0017632344541114,5.4251738651128845,26.92552942634033,0.0005551952849371
0.0005040465234231996,29.3288780642642,0.0018927532486343,5.912701817755663,29.34636226244844,0.0005959651329717
0.0005475825067541996,31.8518109597712,0.0020309799957103,6.421325089489874,31.872185886034643,0.0006394742315698
0.0005881316722109995,34.4026078204842,0.0021597235960356,6.935565736609615,34.42600943430312,0.0006799966541249
0.0006324395751688995,36.9702344025346,0.0023004011879269,7.453199255550976,36.9970206611606,0.0007242734578665
0.0006750002088172995,39.5512389852526,0.0024355311997606,7.973529779426926,39.581578599910166,0.0007668023727707
0.0007189505910442995,42.1758214954075,0.0025750736633313,8.50264561347415,42.21002806144283,0.0008107181023483
0.0007647964886859995,44.8141666778916,0.0027206343883437,9.034536002262946,44.85256761110383,0.0008565257977648
0.0008117692517135996,47.47780173318,0.0028697729109564,9.571524829409087,47.5207152794117,0.0009034572433372
0.0008550177000992995,50.1508985716724,0.003007086734581,10.110421152049156,50.19839718641955,0.0009466657027451
0.0009013736901011996,52.8110485964655,0.003154267002837,10.646707397047445,52.86351478480347,0.0009929767575127
0.0009463824256054996,55.5130143452761,0.0032971697380631,11.19142369200766,55.57066342589591,0.0010379398117174
0.0009901544798129995,58.2287602136576,0.003436146010172,11.738918059073374,58.291778330849866,0.0010816655007556
0.0010319413620845995,60.9656830317352,0.0035688193613843,12.290681699197815,61.0342107514151,0.0011234063368739
0.0010771651175113996,63.7218893256045,0.0037124047848644,12.846332888041868,63.7963968679141,0.0011685782959053
0.0011190992252542995,66.4731903354886,0.0038455455769481,13.400995171634502,66.55370236165561,0.0012104625518233
0.0011667940460395995,69.2068143443638,0.0039969766329414,13.952093771823742,69.29393813011964,0.0012580985401302
0.0012094317010170996,71.9743657471295,0.004132351187495,14.510032134621309,72.06804239461432,0.0013006816797909
0.0012544740174583995,74.7531893965492,0.0042753605421961,15.070242982344318,74.85384981744663,0.0013456644368611
0.0013020955950639997,77.5386853033534,0.0044265590510939,15.631798957156049,77.64678910468868,0.0013932208440772
0.0013501607957312996,80.3052190837451,0.0045791660632126,16.189532167283012,80.42103985033633,0.0014412179740513
0.0013941722708963997,83.0429385524802,0.0047189024968618,16.741456412180007,83.16636265644304,0.0014851650990848
0.0014390370169049995,85.7887148052609,0.0048613480654391,17.295004904740598,85.92006875888453,0.0015299622595855
0.0014810667202323996,88.5215677420952,0.0049947923735036,17.845948056806392,88.66082659294521,0.0015719268276945
0.0015264077853835995,91.2675672075225,0.0051387502553586,18.39954154903653,91.41528413170948,0.0016171956513489
0.0015738079428920997,93.9600029047937,0.0052892457554481,18.94233658560641,94.11653126591057,0.0016645180957541
0.0016206373920517995,96.6677439146819,0.0054379292565301,19.488217173199875,96.83331001005088,0.0017112685684653
0.0016668914340627996,99.352713409034,0.0055847858399151,20.029507023261253,99.52747360651554,0.001757442459045
0.0017120242635364996,102.059120233155,0.0057280825734941,20.57511863900405,102.2432471837294,0.0018024950249437
0.0017594003301443996,104.713871072965,0.0058785015849742,21.110316408309743,104.90774844527088,0.0018497846551708
0.0018075976449510997,107.400810264859,0.0060315280594854,21.65200334939557,107.60483892650434,0.0018978917405675
0.0018543849451618996,110.098576878778,0.0061800777376547,22.195873098761645,110.3128816863106,0.0019445892374131
0.0018986723188179995,112.750385313314,0.0063206901490128,22.7304776791641,112.97484523449424,0.0019887895971492
0.0019416492519351996,115.364053741475,0.0064571419116599,23.257393234281363,115.5986748647862,0.0020316802233095
0.0019849284800882994,117.979414984254,0.006594553461046,23.78465006082561,118.22446114470016,0.0020748706784514
0.0020310473951369997,120.599685160534,0.0067409810163257,24.31289652836365,120.8557356135236,0.0021208929428793
0.0020751958475922995,123.266856051405,0.0068811523528712,24.85059817996325,123.53401133220788,0.0021649468900278
0.0021210494047840998,125.858106838908,0.0070267373969552,25.372994338723853,126.136649158919,0.0022107002373835
0.0021638467184634997,128.466631996305,0.0071626188678873,25.89887301045509,128.75644538913355,0.0022534021317949
0.0022054012798498994,131.092748887319,0.0072945546002891,26.428298175683512,131.39393415171602,0.0022948622999835
0.0022482249366458994,133.721313818416,0.0074305197106164,26.95821686579267,134.03426463985136,0.0023375868823529
0.0022924589171378997,136.411364989967,0.0075709625986785,27.50053118197735,136.7366454127619,0.0023817166091017
0.0023341018572055994,139.020205606298,0.0077031789333935,28.02647345022968,139.35749616350822,0.0024232596225819
0.0023767374865738995,141.621462707018,0.0078385470566378,28.55088688173483,141.9711025494302,0.0024657911553538
0.0024169680446127994,144.243980408154,0.0079662790784113,29.079586450283845,144.60589782652005,0.0025059218301952
0.0024605857604018994,146.790651012224,0.0081047653260417,29.59299524406436,147.16536086372352,0.0025494294337663
0.0025039356595222997,149.330034351646,0.008242401255749,30.10493492529184,149.71769988319278,0.0025926680213353
0.0025473414465142998,151.817091908749,0.0083802146294486,30.6063257288038,152.21780366138336,0.0026359604801587
0.0025898409042551997,154.235888429455,0.0085151504077759,31.09395510737813,154.64953938638533,0.0026783471602001
0.0026318785050004996,156.617505246367,0.0086486197901423,31.574089057667585,157.0441273740383,0.0027202714414666
0.0026735684634642994,159.031043568607,0.0087809854082648,32.060658383431175,159.47087011129585,0.0027618472817503
0.0027154455059211994,161.449051073824,0.0089139450180655,32.54812869648292,161.90232602326995,0.0028036079537902
0.0027562191958131997,163.808076257862,0.0090434014834726,33.023708173584986,164.27465332867624,0.0028442666637598
0.0027992918310765997,166.148394269309,0.0091801571004339,33.4955162846927,166.62879375320728,0.0028872160406854
0.0028417780677974995,168.538497152445,0.0093150509020227,33.97736102593291,169.03296791777584,0.0029295788900567
0.0028844579535816997,170.837831657295,0.0094505595393876,34.44090686211067,171.34633972017917,0.0029721330192786
0.0029291447305870998,173.18000349419,0.0095924400563797,34.91308870442871,173.70322201465666,0.0030166861859081
0.0029746012115024994,175.412731041182,0.0097367643832861,35.3632065779023,175.95066881503294,0.0030620047186134
0.0030217416015525995,177.603156758394,0.0098864351216952,35.80479640249223,178.15618418727593,0.0031089998810426
0.0030702688825965997,179.839010723036,0.0100405092390099,36.25554456176406,180.4077273367995,0.00315737535495
0.0031177320704298996,182.074122491622,0.0101912048603806,36.706143094311,182.6585491631452,0.0032046878007643
0.0031683851069871996,184.236274809689,0.01035202825145,37.1420330016333,184.83697374568013,0.0032551774953534
0.0032199759650036997,186.412885144694,0.0105158292256524,37.58083764517031,187.03029807875475,0.0033065993668796
0.0032724737249875996,188.573128878584,0.0106825096136013,38.01634278192253,189.20759636271384,0.0033589224556055
0.0033270402694281997,190.740943114684,0.0108557583922002,38.4533741319203,191.39311243561423,0.0034133045439975
0.0033821181517203996,192.839150683869,0.011030630668478,38.87637277786799,193.50911523492937,0.0034681932427732
0.0034405827333561997,194.882775421926,0.0112162557151716,39.28836752506028,195.57123370337945,0.0035264537119786
0.0035056305521545994,196.886659409203,0.0114227825398565,39.692350536895326,197.5950038172125,0.0035912704459934
0.0035719656167319995,198.921418179355,0.0116333963698898,40.10255790495797,199.650278558612,0.0036573655263433
0.0036440362522768997,200.93340386532,0.0118622206377448,40.50817421924852,201.68411768268805,0.003729170476626
0.0037240435898979996,202.888986076481,0.0121162439346918,40.90241959301857,203.6632388156825,0.0038088768322385
0.0038123724809780994,204.823557086742,0.0123966881638712,41.29242910868719,205.62328425707875,0.0038968660581911
0.0039124774562417,206.785846641851,0.0127145214603331,41.68802668299716,207.6139358024245,0.0039965767255895
0.004021702182939299,208.685471835515,0.013061309967598,42.07099112203982,209.54396179878367,0.0041053598813264
0.0041412257691917,210.550363620745,0.0134407973539493,42.4469533059422,211.4416911074306,0.0042243867021169
0.004273003413407099,212.412210286069,0.0138591913743332,42.82230159367151,213.33941074988,0.0043556002318941
0.004416651931262599,214.251368622384,0.0143152754185244,43.19307591427261,215.21737408714787,0.0044986142078657
0.004568435124204299,216.082801848318,0.0147971870561143,43.562292852620914,217.08986252187984,0.0046497047055929
0.004729228033539699,217.889969162452,0.0153077045432542,43.92661778315033,218.940487358004,0.0048097389046863
0.0048957078319088,219.661903948988,0.0158362779030761,44.28383983611599,220.7575344862022,0.0049754061776659
0.005066258912269899,221.458997001703,0.0163777775832226,44.64613379554333,222.6013611581432,0.0051450964063979
0.005235584762951299,223.188115568956,0.0169153871591361,44.994724098701525,224.37719065058337,0.0053135391093444
0.0054102739737742,224.817782217736,0.0174700254034988,45.32326489509558,226.05481288435084,0.0054872874687922
0.005584319989609799,226.387274594607,0.0180226215037768,45.63967455827277,227.67234299249367,0.0056603660806438
0.005759704298612599,227.85939905399,0.0185794666848607,45.93645484928438,229.19278680629105,0.0058347452496621
0.0059346472382112,229.159721917471,0.0191349105180862,46.19859993856216,230.5408087751845,0.0060086552906647
0.006109338875826799,230.35790587522,0.0196895564675158,46.44015382444435,231.7864554800921,0.0061822853390997
0.0062847591476666,231.368053242578,0.0202465158306071,46.64379953370372,232.8434538575929,0.0063566092629074
0.0064651238525601,232.238006308946,0.020819173768644,46.81918207188352,233.76084202832533,0.0065358150377757
0.006643305944056099,232.948056622141,0.0213849019091438,46.962328215023625,234.517055469634,0.0067128206950668
0.0068238043378352,233.525243437067,0.0219579843093924,47.07868907691271,235.14028080123649,0.0068920954225395
0.0070016445923189,233.952715903616,0.0225226271173782,47.16486752616898,235.612315835394,0.0070686986038659
0.0071791748694241,234.301541422995,0.0230862857471872,47.2351907508758,236.0052114501754,0.0072449628623432
0.007357239457336299,234.52913241482,0.0236516408138084,47.28107309482772,236.27621865111905,0.007421726417325
0.0075361192837543,234.731947251064,0.0242195842626856,47.32196056581451,236.5225331331401,0.0075992677995719
0.007712564583318999,234.868958630952,0.0247797980888035,47.349582059999925,236.70203118912605,0.0077743619960472
0.007888929032343,234.99663540042,0.0253397552144547,47.37532169672467,236.87214948459865,0.0079493453295354
0.0080621624574466,235.094659782381,0.0258897713391586,47.39508341212801,237.01168245476623,0.0081211923547906
0.0082397594931099,235.178182481278,0.0264536419273896,47.411921588225646,237.13765316741785,0.0082973374170879
0.0084159758264277,235.269668293342,0.0270131287856736,47.43036512793775,237.2713595843564,0.0084720824043708
0.0085939956257983,235.34928825237,0.0275783416486753,47.44641651167779,237.3935537888098,0.0086485847986541
0.0087723641632704,235.398007385714,0.0281446617551492,47.45623828895995,237.4846836993225,0.0088254017192885
0.0089484952277354,235.507322742102,0.0287038778848256,47.47827626480777,237.63644823280163,0.0089999699575219
0.009127261048242,235.58769823072,0.029271459364934,47.494479963313154,237.75966539155112,0.0091771184175958
0.0093067480987214,235.662944742506,0.0298413307502061,47.50964966008921,237.8779040746725,0.0093549500162698
0.0094870046528538,235.762462720398,0.0304136453095765,47.52971248443224,238.02085513567056,0.0095335121992184
0.0096702114153596,235.83740331321,0.0309953267805324,47.544820507943136,238.1397205991203,0.0097149641936502
0.009848167105073,235.906617529235,0.0315603360953725,47.55877409389378,238.2515914304461,0.009891183893254