File: example/data/02 processed data/test_ID_139.csv
Strain,Stress_MPa,Displacement(mm),Force(kN),True Stress (MPa),True Strain
0.0001117718180114,-1.6520638317866,4.999016857901235e-05,-0.3330560684881786,-1.6520898434242235,1.5744811035385373e-05
0.0001245189478698,-1.34012827111464,9.046230587961808e-05,-0.2701698594567114,-1.3401664541362397,2.849165895272933e-05
0.000145345752853,-0.878178697751938,0.0001565874117013,-0.1770408254667907,-0.8782220085328174,4.931765369170009e-05
0.0001493507275021,-0.337777774778614,0.000169303206212,-0.0680959993953685,-0.3377957863881438,5.332242281054923e-05
0.0001605265453331,0.605166471887691,0.0002047864278255,0.1220015607325585,0.6052055049207675,6.449758229359201e-05
0.000192847264209,1.7509485382266,0.0003074047102566,0.3529912253064826,1.7511180657315033,9.681569439271382e-05
0.0002194476097621,3.17640043013402,0.0003918608073877,0.6403623267150185,3.1767924637835123,0.0001234131110249
0.0002247762097634,4.7920021654058,0.0004087791123918,0.9660676365458092,4.792619132458322,0.0001287410392544
0.0002363199244914,6.41180842176502,0.0004454304066532,1.292620577827828,6.412707953869804,0.0001402832013171
0.0002381538470812,8.05483951613642,0.0004512531108758,1.6238556464531024,8.055984326022802,0.0001421168649752
0.0002683550928396,9.77194656581438,0.0005471420661588,1.9700244276681789,9.773630547872465,0.0001723133630135
0.0003092136677528,11.4312838128584,0.0006768680415082,2.3045468166722536,11.433720811499766,0.0002131640636536
0.0003350617986079,13.2283651436891,0.0007589358569731,2.6668384129677225,13.23152718483451,0.0002390063512884
0.0003525130565845,15.0513865807403,0.0008143436010488,3.0343595346772445,15.055247053291149,0.0002564532866034
0.0004296830848576,16.866695443968,0.0010593584408159,3.4003258015039486,16.87232312150729,0.0003336005509798
0.0004618750155703,18.73558400417,0.0011615678208287,3.777093735240672,18.74243838259006,0.0003657812264343
0.0005070201558373,20.6771417915233,0.0013049036411765,4.1685117851710976,20.685639957700587,0.0004109088382103
0.0005315844810237,22.5367361606893,0.0013828953736433,4.543406009994963,22.546552207358165,0.0004354627703216
0.0005495385753614,24.3871980603993,0.0014398996231655,4.916459128976499,24.398257939863,0.0004534088869892
0.0005704266206158,26.2014343582061,0.0015062191668482,5.28220916661435,26.213864311790115,0.0004742872456105
0.0005948294498,28.0053941999713,0.001583698149508,5.6458874707142135,28.01936336248177,0.0004986782061265
0.0005813856466741,29.8123435230589,0.0015410140745833,6.0101684542486735,29.826813205252705,0.000485241015182
0.0006105656576817,31.5871454663446,0.0016336606095324,6.367968526015073,31.603398277467733,0.0005144064449711
0.0006235740665684,33.316765619273,0.0016749623077477,6.716659948845437,33.3343417851402,0.0005274080794477
0.000652381782692,35.1009031599509,0.0017664268064401,7.076342077046101,35.120431719406646,0.0005562001916579
0.0006846783832779,36.8432700228559,0.0018689685133004,7.42760323660775,36.86495786902904,0.0005884783129189
0.0007190470790605,38.5189451813117,0.0019780891224101,7.765419348552439,38.54294326208961,0.0006228261995239
0.0007479158494789,40.185583706507,0.0020697474684885,8.101413675231813,40.21178024513575,0.0006516765791377
0.0007785964493863,41.8330354413862,0.0021671583731945,8.433539944983458,41.86158939824698,0.0006823367217032
0.0008118901583052,43.4639902791651,0.002272865899012,8.762340440279685,43.49510455360306,0.0007156071673832
0.0008484779644119,45.0145238135373,0.0023890321834008,9.074928000809122,45.04839504065888,0.0007521681319993
0.0008683061095527,46.5599042084806,0.0024519865442229,9.38647668842969,46.5958614552899,0.0007719811723692
0.0008888400773391,48.13152634567,0.0025171818919447,9.703315711287072,48.16968565481928,0.0007924990839424
0.0009167487754656,49.6552885908183,0.0026057920084963,10.01050617990897,49.69604177324021,0.0008203852843893
0.0009443297938011,51.168805162703,0.0026933617417115,10.315631120800925,51.21221180906342,0.0008479433052163
0.0009698917038271,52.6460586941706,0.0027745208060441,10.613445432744792,52.69206423281727,0.0008734832232324
0.0009971823154211,54.0935713103036,0.002861168497855,10.905263976157208,54.14231802594754,0.0009007496356109
0.0010269339206223,55.5859826080329,0.0029556298443688,11.206134093779433,55.63772799043444,0.0009304740123567
0.0010674998114143,57.0351509504363,0.0030844265476334,11.498286431607958,57.0905590555512,0.000971001353953
0.0011059553253463,58.4806247835056,0.0032065228043675,11.789693956354728,58.53968602979913,0.0010094188076919
0.0011385054740349,59.9409742340374,0.0033098695264538,12.08410040558194,60.00346141640061,0.0010419355875495
0.0011713897645699,61.3715057962903,0.0034142771489025,12.372495568532123,61.437502435608096,0.001074785093065
0.0012062551156063,62.7927560309966,0.003524974638443,12.659019615848916,62.86247032154375,0.0011096123849951
0.001251340710276,64.1956817771549,0.0036681214015193,12.941849446274428,64.2698479359618,0.0011546469658039
0.0012866218003847,65.5992041876266,0.0037801388626145,13.224799564225522,65.67730626671518,0.001189886721291
0.0013315852573972,66.9279908289852,0.0039228978386291,13.49268295112342,67.01068426853381,0.0012347957002775
0.0013726865445434,68.2392619576809,0.0040533944253183,13.75703521066847,68.326380270754,0.0012758454245007
0.0014197400490952,69.4926257052042,0.0042027893022703,14.009713342169167,69.58461400879493,0.0013228378301737
0.0014675275177215,70.6684744819443,0.0043545145151588,14.24676445555997,70.76539633954927,0.0013705609867539
0.0015151094185655,71.87337469739,0.0045055870503385,14.489672338993826,71.97536894819338,0.0014180765894863
0.001556939552896,73.0312584113135,0.0046383977268378,14.723101695720802,73.13795070202315,0.0014598465751435
0.0016140348475839,74.0498311916515,0.0048196752874719,14.928445968236945,74.1622394251746,0.0015168569551482
0.0016637920643022,75.0691545501929,0.0049776544505525,15.13394155731889,75.18684535688456,0.0015665375203997
0.0017224688267395,76.0288470759801,0.0051639531712909,15.327415570517587,76.15250358179667,0.001625120719418
0.0017754305780484,76.9695329323008,0.0053321067316967,15.51705783915184,77.09879585031146,0.0016779950735126
0.001843029084999,77.8404731894069,0.0055467319912649,15.69263939498443,77.97646066747143,0.0017454779685942
0.0019176333182075,78.6204086272544,0.0057836004317018,15.849874379254487,78.76362406954642,0.0018199493222791
0.0020007316039683,79.3579343726969,0.0060474374889924,15.998559569535695,79.50908780494082,0.0019028930709794
0.0020997752276926,80.0827283195709,0.006361900994317,16.144678029225496,80.24319395387765,0.002001743518617
0.0021930663804166,80.7214928816697,0.0066581004042157,16.273452964944614,80.89076904053091,0.0020948437791999
0.0023027972165517,81.2923503635678,0.0070064958089447,16.38853783329527,81.47174391069272,0.0022043389921578
0.0024259638254427,81.7537651021626,0.0073975497921736,16.481559044595983,81.94424621965581,0.0023272268480887
0.0025565453355963,82.1716209299744,0.0078121460869113,16.56579877948284,82.37380571955023,0.0024574963333477
0.0026969811459764,82.4976345797694,0.0082580297848681,16.63152313128151,82.71220715411299,0.002597577635114
0.0028366766112881,82.7803462365822,0.0087015628872328,16.68851780129497,83.00721817000095,0.0027369009955426
0.0029540771094424,83.0065588563137,0.0090743094688727,16.734122265432845,83.24379577064705,0.0028539737661732
0.0031147333145325,83.1855256716259,0.0095843929200337,16.77020197539978,83.43663835297909,0.0030141592859468
0.0032758104863599,83.3052834294401,0.0100958129405857,16.794345139375125,83.57017620376013,0.0031747387829145
0.0034442632953369,83.4210337463432,0.0106306506090877,16.817680403262788,83.70034708908534,0.003342643549449
0.0036229212073067,83.4951297008558,0.0111978894795918,16.83261814769253,83.78960819990286,0.0035206894175806
0.0037923569917978,83.5653067709417,0.011735848095351,16.84676584502185,83.8741917304079,0.003689515468247
0.0039640652128064,83.6039577005634,0.0122810216970534,16.85455787243358,83.92734101347054,0.0038605767045658
0.0041673117188869,83.6330088192819,0.0129263293538589,16.86041457796723,83.97350261986527,0.0040630195816285
0.0043543071704558,83.6695838313141,0.0135200399125902,16.86778810039292,84.02587237080046,0.0042492394684008
0.0045223429203129,83.678344827517,0.0140535534183865,16.869554317227426,84.04873162720067,0.0044165487120287
0.0047003477307028,83.684374700141,0.0146187186913744,16.870769939548428,84.06968441119767,0.0045937533873458
0.0048724565789118,83.6992427019058,0.015165164284438,16.87376732870421,84.09902625027037,0.0047650587495411
0.005064887680024,83.7238834837073,0.0157761330304692,16.87873491031539,84.13989580612194,0.0049565567494224
0.0052584763619986,83.7258046874387,0.0163907770957386,16.87912222498764,84.15803492422394,0.0051491697211059
0.0054426983210628,83.7279880407632,0.0169756818157674,16.87956238901786,84.17565408298505,0.005332428735117
0.0056292275641917,83.7198071975292,0.0175679121627017,16.877913131021888,84.18304569174165,0.0055179487616985
0.0058287529694722,83.7205420643562,0.0182014053244673,16.878061280174208,84.20048899981997,0.0057163565438615
0.0060274221719535,83.7278325429362,0.0188321800423454,16.879531040655937,84.22445541443349,0.0059138738142808
0.0062184660997451,83.7233400172821,0.0194387445130837,16.87862534748407,84.23593107755863,0.0061037732345542
0.0064023654741322,83.7000590054999,0.0200226250267628,16.87393189550878,84.22789991768417,0.0062865368452985
0.0065891445696307,83.6928450198833,0.0206156486549705,16.872477556008473,84.23627251212419,0.0064721282070729
0.0067805652335517,83.6756908368761,0.0212234092629197,16.869019272714223,84.23502420128195,0.006662295889417
0.0069709292808745,83.6482568699594,0.0218278151131696,16.863488584983816,84.22333047169055,0.0068513780133788
0.0071688518170878,83.6270406722075,0.0224562191656468,16.859211399517033,84.21852009063569,0.0070479298246938
0.0073468933432958,83.5800086193025,0.0230215010113572,16.849729737651383,84.18603610054927,0.0072247053125981
0.0075421639938133,83.5729337961614,0.0236414853267503,16.848303453306137,84.19522931995837,0.0074185514847846
0.0077254194102611,83.5341928861117,0.024223321273972,16.840493285840118,84.17150803308563,0.007600435899793
0.0079238332044212,83.5116738760793,0.0248532850704303,16.835953453417588,84.16538708475679,0.0077973279944647
0.008110360178256,83.4632123919204,0.0254455082123558,16.82618361821115,84.13211439391984,0.0079823890869991
0.0083074485012673,83.4263103368712,0.0260712636379167,16.818744163913234,84.1113589451015,0.008177891324939
0.0085011859282543,83.3999330640055,0.0266863799686004,16.813426505703507,84.10092276576988,0.0083700323887792
0.008711201452266,83.3733813980629,0.0273531792573376,16.808073689849483,84.09165763323506,0.0085782757279965
0.008915071099521,83.3011280904002,0.0280004653873722,16.793507423024682,84.03576442231338,0.0087803835796932
0.0091259854457324,83.2779005644948,0.0286701184365934,16.788824753802153,84.02989655578138,0.0089894322713335
0.0093206455408446,83.2357549096079,0.0292881642385746,16.780328189776952,84.00357300734471,0.0091823317181258
0.0095360753943047,83.2061750598792,0.0299721540233105,16.774364892071645,83.99164538888242,0.0093957696979761
0.0097356907988872,83.1726801175732,0.0306059329328599,16.767612311702756,83.97443680088804,0.0095934987960441
0.0099416544491685,83.1437597616637,0.031259867522503,16.7617819679514,83.96236225472589,0.0097974751774163