File: example/data/02 processed data/test_ID_082.csv
Strain,Stress_MPa,Displacement(mm),Force(kN),True Stress (MPa),True Strain
-9.23504460231675e-06,0.334300695536063,-2.9321266612355683e-05,0.0673950202200703,0.33429760825422916,-9.235087245549598e-06
-1.86473297334827e-05,1.75360779945217,-5.9205271903807575e-05,0.3535273323695574,1.7535750993493104,-1.8647503597060008e-05
-5.68594676465981e-05,4.02057032385998,-0.00018052880977794896,0.8105469772901719,4.02034171637173,-5.686108420736148e-05
-8.44462185205337e-05,7.96927059569958,-0.00026811674380269445,1.6066049520930354,7.968597620933406,-8.444978430320798e-05
-0.0001046848583456,12.1151727549914,-0.00033237442524728,2.4424188274062666,12.113904479847712,-0.00010469033818780726
-0.0001054936560733,16.5419528524746,-0.0003349423580327275,3.3348576950588797,16.5402077813896,-0.00010549922092037333
-6.20005816239267e-05,20.9939644170988,-0.00019685184665596726,4.232383226487118,20.992662779094346,-6.200250373948716e-05
-1.42019837143363e-05,25.7334372257117,-4.5091298293017754e-05,5.187860944703479,25.733071759855306,-1.4202084563504747e-05
6.83628945801697e-05,30.8603467692688,0.0002170521902920388,6.221445908684591,30.862456471901694,6.83605579439352e-05
0.0001460057954736,36.1500642651325,0.00046356840062867995,7.2878529558507115,36.15534238402196,0.00014599513766486868
0.0002323443699432,41.5347508986047,0.00073769337456966,8.373405781158707,41.544401264132986,0.00023231738217033979
0.0003214804713866,47.1294869541843,0.001020700496652455,9.501304569963555,47.144638163866546,0.00032142880761225085
0.0004115500177956,52.747025006427,0.00130667130650103,10.633800241295683,52.76873304550707,0.00041146535431515975
0.0005027485476612,58.4541714514472,0.0015962266388243101,11.784360964611755,58.48355920124916,0.0005026222119517266
0.0005989234038451,64.1936567196207,0.0019015818072081923,12.941441194675535,64.23210380300848,0.000598744120804173
0.0006971011779485,69.9833217371137,0.0022132962399864873,14.108637662202122,70.03210719313338,0.0006968583157820437
0.0007822001464558,75.8142135830688,0.002483485464997165,15.284145458346673,75.8735154720369,0.0007818943873539547
0.0008915056775569,81.5293292930016,0.0028305305262431575,16.436312785469124,81.60201315295372,0.0008911085223968814
0.0009816699371262,87.1721001799882,0.0031168020503756846,17.57389539628562,87.25767441009104,0.0009811884142986117
0.0010659149191397,92.6905455593038,0.0033842798682685474,18.686413984755646,92.78934579467865,0.0010653472351982748
0.0011645167992182,98.1179436604965,0.003697340837517785,19.780577441956094,98.2322036541939,0.0011638392754712654
0.0012615196790926,103.54971546196,0.004005324981119005,20.875622637131137,103.68034546577971,0.0012607246317172633
0.0013707658277855,108.969931049766,0.004352181503218962,21.968338099632827,109.11930330750516,0.0013698271859823507
0.0014832353579208,114.374573759161,0.0047092722613985396,23.057914069846856,114.54421817100771,0.0014821364508483506
0.0015786030366182,119.852985680258,0.005012064641262785,24.162361913140014,120.04218596740063,0.0015773583525804929
0.0016668001259832,125.220508958796,0.005292090399996659,25.244454606093274,125.4292265189042,0.0016654125563067691
0.0017660637385025,130.64348862391,0.0056072523697454375,26.337727306580256,130.87421335184015,0.0017645060816160946
0.0018595983892624,135.976411489664,0.00590422488590812,27.412844556316262,136.22927300544785,0.001857871476755448
0.0019577376960022,141.431885048899,0.006215817184806985,28.512668025858037,141.7087715816759,0.0019558238250568646
0.0020621631624819,146.841655615556,0.0065473680408800325,29.60327777209609,147.14446706848426,0.0020600398226420054
0.0021799599802955,152.250429822758,0.006921372937438212,30.693686652268017,152.5823296667544,0.002177587315121962
0.0022788231022985,157.65296797372,0.007235263349797737,31.782838343501954,158.01223119928443,0.002276230522872297
0.0023983675278809,163.009059201745,0.007614816901021856,32.862626335071795,163.4000148360849,0.00239549603482886
0.0024932916190992,168.480229209905,0.007916200890639961,33.96561420871685,168.90029955337795,0.0024901885244265954
0.0025887915947501,173.909047642631,0.008219413313331567,35.060064004754416,174.35926192341924,0.002585446445808027
0.0027043532687664,179.297578516529,0.008586321628333319,36.146391828932245,179.7824625090721,0.002700703084908829
0.0028126093070945,184.446699692992,0.008930034550025038,37.18445465810719,184.96547619721142,0.0028086613225636156
0.0029224114412333,189.578175100215,0.009278656325915726,38.21896010020335,190.132200528136,0.002918149498332243
0.003029046897821,194.54914123719,0.009617223900581675,39.221106873417504,195.13843970992824,0.003024468578232866
0.0031264076134236,199.505369584443,0.009926344172619929,40.22028250822371,200.1291046908307,0.0031215305635942056
0.0032380481754642,204.29376490508,0.010280802957098835,41.18562300486413,204.95527795778958,0.003232816986989118
0.0033421639808762,209.028496568929,0.010611370639281935,42.14014490829609,209.72710408113838,0.003336591363786725
0.0034503586332381,213.571079455494,0.010954888660530968,43.055929618227594,214.30797627330324,0.003444419802698683
0.0035551770781188,217.818591011252,0.01128768722302719,43.91222794786841,218.59297467320334,0.0035488723745634512
0.003659560781195,221.784780477002,0.011619105480294123,44.7118117441636,222.59641536150156,0.0036528808806802486
0.0037706829279733,225.411597549044,0.011971918296315226,45.44297806588727,226.26155321168937,0.0037635917233012307
0.0038849743394185,228.80561129635,0.012334793527653737,46.12721123734416,229.6945152249513,0.0038774473151751577
0.004008414790401,231.936514667335,0.012726716959523173,46.75840135693474,232.86621242316158,0.004000402499754413
0.0041249437707985,234.91400808562,0.013096696472285238,47.35866403006099,235.88301515994607,0.004116459513629008
0.0042572601990119,237.794003273548,0.013516801131862783,47.93927105994728,238.80635421924816,0.004248223704870425
0.0044045658415292,240.583521321785,0.013984496546855208,48.50163789847186,241.64318728183378,0.004394894130794589
0.0045761322850721,243.159352671385,0.014529220005103916,49.020925498551215,244.27208203556177,0.004565693625403922
0.0047713896791477,245.430961679646,0.015149162231293947,49.47888187461664,246.60200843714756,0.0047600426790701394
0.0049954667387538,247.16689043912,0.015860606895543312,49.8288451125266,248.4016044192298,0.004983030793158068
0.0052535191439209,248.513308630695,0.016679923281948856,50.10028301994811,249.8188780551055,0.00523976755402385
0.0055336696664614,249.364395628851,0.017569401191014942,50.271862158776365,250.74429582083786,0.005518415166175099
0.0058435285458317,249.909817206341,0.018553203133015648,50.38181914879834,251.3701723570698,0.0058265213554038655
0.0061606341949795,250.297186427291,0.01956001356905991,50.45991278374186,251.83917583290216,0.006141735068820495
0.0065011313733625,250.581280116423,0.020641092110425936,50.51718607147088,252.21034193816521,0.006480090164004832
0.0068530676047428,250.801078267483,0.021758489645058388,50.561497378724575,252.51983501219243,0.006829692072246644
0.0072016785931914,250.978587372951,0.022865329533382692,50.59728321438693,252.78605449298422,0.007175870340328262
0.0075544760341433,251.173410102515,0.023985461408404976,50.636559476667024,253.07089360954848,0.0075260838822970395
0.0079068975794832,251.287824242863,0.02510439981485916,50.65962536736118,253.27473133212249,0.007875801870987484
0.0082748975529773,251.473481814803,0.026272799730702925,50.69705393386428,253.55439911411102,0.008240848295341954
0.0086422271910343,251.67592187948,0.0274390713315339,50.73786585090318,253.85096237487545,0.008605096917768451
0.0090103444743993,251.917775665549,0.028607843706217773,50.786623574174676,254.18764160352,0.00896999352347658
0.0093744025903023,252.146358567903,0.029763728224209803,50.83270588728925,254.51008004479723,0.009330735567708243
0.0097418402892529,252.255788464484,0.030930342918377953,50.854766954439974,254.71322406774456,0.009694694506974378
0.0100970224281873,252.389255910921,0.03205804620949468,50.88167399164168,254.93763588848708,0.01004638804961433
0.0104606675885388,252.604258197908,0.03321261959361069,50.925018452698254,255.24666737436573,0.010406333391511143
0.0108275381621483,252.869084444737,0.03437743366482085,50.97840742405898,255.6070341065899,0.010769340088521897
0.0111931444227303,253.104666616892,0.0355382335421687,51.025900789965426,255.93770370440186,0.011130964742230975
0.0115649533088407,253.194835985162,0.036718726755569225,51.04407893460866,256.12302244137,0.01149859040217999
0.0119246069856253,253.251086933795,0.037860627179360326,51.05541912585307,256.27100661416296,0.011854069064021632
0.0122797751308051,253.364394090813,0.03898828604030619,51.078261848707896,256.47565187640083,0.012204990297037735
0.0126482222119021,253.537865895919,0.040158105522789166,51.11323376461727,256.744669162902,0.012568901592300435
0.0130172088934387,253.696528036177,0.041329638236667875,51.145220052093286,256.998948737164,0.01293321317105521
0.0133890983442275,253.950567589079,0.04251038724292231,51.19643442595832,257.3507367131016,0.013300256496607205
0.0137555253052965,254.179261267264,0.043673792844316384,51.24253907148042,257.6756305277074,0.013661776795440398
0.0141323777547849,254.421673308814,0.04487029937144205,51.29140933905691,258.0172565050186,0.014033446702103136
0.0144985331178754,254.511802591124,0.04603284264925439,51.3095794023706,258.20185038988154,0.014394434366349242
0.0148625926381428,254.594706690839,0.04718873162610339,51.326292868873146,258.37864410421236,0.01475322661830715
0.0152239593369561,254.734202485035,0.04833607089483562,51.35441522098306,258.6122656253991,0.01510923774726965
0.0155877780063212,254.90462686072,0.04949119517006981,51.388772775121154,258.878023597009,0.015467536516739265
0.0159541625624333,255.053886457891,0.05065446613572572,51.41886350991083,259.12305762462057,0.015828232550395206
0.0163063059782866,255.246089498616,0.05177252148105996,51.45761164292099,259.4082103337416,0.01617478598173812
0.0166550547623598,255.39584811887,0.05287979887049236,51.487802980764194,259.6494799553691,0.016517880340764395
0.0170203700111431,255.598396695235,0.05403967478537934,51.52863677375938,259.9487759812428,0.016877146375316853
0.0173807744562624,255.793970876975,0.05518395889863312,51.56806452879816,260.2398681920595,0.017231456487528243
0.0177429853514239,255.955200250904,0.056333978490770875,51.60056837058225,260.4966096195766,0.017587416067126802
0.0181020027045293,256.130359905856,0.05747385858688052,51.63588055702056,260.76683237358384,0.017940112229097242
0.01846310605453,256.261427832318,0.058620361723132744,51.662303850995315,260.99280975207137,0.018294732223549437
0.0188232948289432,256.389836591806,0.059763961081894655,51.68819105690809,261.21593807711815,0.018648328829318796
0.0191701400660978,256.620580868894,0.06086519470986051,51.73470910316904,261.5400333479941,0.01898870798321047
0.0195182290804837,256.862564440472,0.061970377330535745,51.783492991199154,261.8760668154216,0.019330191284961162
0.019877474433532,257.121659793162,0.0631109813264641,51.83572661430146,262.23258901200785,0.01968249697644133
0.0202327614832513,257.293161475195,0.06423901770932287,51.87030135339932,262.4989126425943,0.02003079879568254
0.0205819626242414,257.433443093986,0.06534773133196645,51.89858212774758,262.7319285979762,0.020373016185897347
0.0209396123561239,257.569863757204,0.06648326923069338,51.92608453345233,262.9632768588995,0.020723391846800904
0.021306929646342,257.785581194111,0.06764950162713584,51.96957316873278,263.2782004364553,0.021083110702114796
0.0216708771111789,257.947155416694,0.06880503482799301,52.00214653200551,263.53709652290735,0.021439401864439867
0.022039759400227,258.064816352568,0.06997623609572072,52.02586697667772,263.7525028146424,0.021800394547517348
0.0223879129019675,258.135028596418,0.07108162346374682,52.04002176503787,263.9141331335815,0.02214098229226635
0.0227364601493022,258.321681327363,0.07218826097403448,52.07765095559638,264.1950019405634,0.022481839068804972
0.0230763475974598,258.474062037358,0.07326740362193486,52.10837090673138,264.4386993378595,0.02281411526728964
0.0234092433989926,258.679227612942,0.0743243477918015,52.14973228676911,264.73471261439676,0.023139449397110552
0.0237553626358077,258.879791903947,0.07542327636868944,52.19016604783572,265.02957523970775,0.023477594399317944
0.0241038148294722,259.001733998964,0.07652961208357423,52.214749574191146,265.24466383578726,0.023817903147948263
0.0244544287031041,259.177093035216,0.07764281113235551,52.250101955899545,265.5151207783235,0.02416020620734372
0.0247972727222507,259.341931239534,0.07873134089314597,52.283333337890056,265.77290383679593,0.0244948103187927
0.0251606500297445,259.495527915611,0.07988506384443879,52.31429842778717,266.0246040777795,0.02484933204557227
0.0255055256337629,259.627222827195,0.0809800438871972,52.34084812196251,266.24915161423667,0.025185686749582697
0.0258572576693866,259.748925151043,0.08209679310030245,52.36538331045027,266.46532003801974,0.02552861199121568
0.0261956172761212,259.848691945804,0.0831710848516848,52.385496296274084,266.655588829717,0.02585838868842698
0.0265387127931892,260.001984770919,0.0842604131183757,52.416400129817276,266.90210277041365,0.026192670154116054
0.0268880696423115,260.228656919359,0.085369621114339,52.462097234942775,267.2257031695319,0.026532937316774356
0.0272474325491995,260.459857717473,0.0865105983437084,52.50870731584257,267.556720122404,0.026882829434573725
0.0276090582684091,260.652888765744,0.08765876000219888,52.547622375174,267.84926955950664,0.027234801189836334
0.0279542390137284,260.757476558079,0.08875470886858766,52.56870727410873,268.04675338240025,0.027570651464084914
0.0283034740453716,260.894056516638,0.08986353009405483,52.59624179375422,268.27826467384835,0.027910331682943868
0.0286530510657516,260.988635158047,0.09097343713376133,52.61530884786227,268.4667558488113,0.028250229021052897
0.0289880325651116,261.059762085072,0.09203700339422932,52.62964803635052,268.6273709698343,0.02857582662404023
0.0293550822491204,261.151725094865,0.09320238614095726,52.64818777912479,268.8178554645245,0.028932472399234663
0.0297054560989048,261.312618995815,0.09431482311402273,52.68062398955631,269.075029527485,0.029272796393251005
0.0300567947890784,261.524027693587,0.09543032345532391,52.723243983027146,269.3846017263864,0.02961394129327974
0.0304014497207796,261.646992831511,0.09652460286347522,52.748033754832626,269.6014407286714,0.029948483316476752
0.0307417739472366,261.768437271049,0.0976051322824762,52.77251695384348,269.815663396157,0.0302787119251846
0.0310877405558498,261.866410424287,0.09870357626482311,52.79226834153626,270.0072454518489,0.0306143037958282
0.0314181283620907,261.935173419401,0.09975255754963797,52.80613096135124,270.1646863204382,0.03093467894146606
0.031755714385866,262.140367030844,0.10082439317512455,52.84749799341816,270.4648216552816,0.03126192817252302
0.0320623676164507,262.204534470115,0.10179801718223096,52.860434149175184,270.6114326449961,0.03155909897019707
0.032416685164286,262.363894558887,0.10292297539660805,52.892561143071624,270.86886232727835,0.03190235026241719
0.0327677528789533,262.50125370157,0.10403761539067673,52.92025274623652,271.1028299132785,0.03224233705641196
0.0331336152968233,262.661921963246,0.10519922856741397,52.952643467790395,271.36486103870044,0.03259652862366752
0.0335087850549525,262.775692692042,0.10639039254947419,52.97557964671567,271.5809868961259,0.032959600398626304
0.0338622356785238,262.93877071552,0.10751259827931305,53.00845617624883,271.8424653385103,0.03330153285629393
0.0342142338404197,263.062900731961,0.10863019244333255,53.03348078756334,272.0633963323434,0.03364194402627044
0.0345539813612787,263.21774381088,0.10970889082205987,53.06469715227341,272.31296482447897,0.033970397954957994
0.0349041849475215,263.31942420113,0.11082078720838075,53.08519591894781,272.51037408372116,0.03430884750207824
0.0352534655213705,263.400507079331,0.11192975303035133,53.101542227193136,272.6862877739637,0.03464629095918324
0.0356097766538938,263.468189911327,0.11306104087611282,53.11518708612353,272.850233309475,0.03499040942029918
0.0359712395166071,263.577975187105,0.11420868546522754,53.137319797720366,273.05920166386267,0.03533938236758929
0.0363305177923581,263.805916653333,0.11534939399073697,53.18327279731193,273.39012220203625,0.03568612557531318
0.0366944473818006,263.956236811316,0.11650487043721691,53.21357734116131,273.6419650540869,0.03603723528146238
0.0370456671061115,264.05120066086,0.117619993061904,53.232722053229374,273.8331535395113,0.036375965988570194
0.0373824960056404,264.070066483794,0.11868942481790826,53.23652540313287,273.9416646893336,0.036700709846640235
0.0377235160873199,264.139390895073,0.11977216357724067,53.25050120444672,274.1036574567982,0.03702938711205437
0.0380696390453562,264.24106254786,0.12087110396900592,53.27099820964858,274.3006244200184,0.037362872132359094
0.0384237445258783,264.451795315523,0.1219953888696636,53.31348193560944,274.61302353813653,0.03770393316029824
0.0387757466180725,264.609648868195,0.12311299551238018,53.34530521182811,274.87008556540525,0.038042853034931656
0.0391318074916813,264.756031803953,0.12424348878608811,53.374816011676934,275.11641387276677,0.038385564024541935
0.0394789766954604,264.843063936881,0.12534575100808676,53.39236168967521,275.2987970859994,0.03871960367222231
0.039841861366774,264.929604295021,0.12649790983950743,53.40980822587624,275.4848928612975,0.0390686452134362
0.0401885439970279,264.997826524774,0.12759862719056356,53.42356182739444,275.64770333518163,0.0394019890266519
0.0405465353954261,265.043916533761,0.12873524988047788,53.432853573206216,275.7905290768395,0.03974608992202881
0.0408997815131461,265.108263478504,0.12985680630423885,53.44582591726641,275.95113353210434,0.04008551363739599
0.0412555576706259,265.15567796526,0.13098639560423722,53.45538467779642,276.0948233292497,0.04042725198347142
0.0416017794877461,265.269906719445,0.13208564987359386,53.478413194640105,276.30560688352233,0.04075970088828341
0.0419519030180609,265.373477516717,0.13319729208234335,53.49929306737015,276.5063999090639,0.041095783933851236
0.0422977257338992,265.530550684815,0.13429527920512996,53.53095901805871,276.76188909165256,0.041427627791939356
0.0426573825826309,265.684737405541,0.1354371896998531,53.562043060957066,277.01815289541497,0.04177262980264396
0.0430160018125051,265.839739308737,0.13657580575470368,53.59329144464138,277.2751020166776,0.042116518003060835
0.043371660389036,265.982304976236,0.13770502173518928,53.62203268320917,277.5183991771583,0.04245745040639038
0.0437246881801343,266.076927320154,0.1388258849719264,53.64110854774305,277.711057999156,0.04279574604349138
0.0440897581049022,266.128178799042,0.13998498198306447,53.651440845886874,277.86170582718995,0.04314546096105812
0.0444430890669268,266.271112382097,0.1411068077874926,53.68025625623075,278.10502314564417,0.04348381423701815
0.0447953158839981,266.321396145211,0.14222512793169395,53.69039346287454,278.25134721220314,0.0438209962642812
0.0451408760702139,266.387066975095,0.1433222815229291,53.703632702179156,278.41201255212553,0.04415168596734016
0.0454900831571524,266.453365808207,0.14443101402395886,53.71699854693454,278.5743515763255,0.04448575457820121
0.0458462011022743,266.592263291353,0.1455616884997209,53.74500027953676,278.8145058065188,0.044826319556912936
0.0462019148444069,266.76470421263,0.1466910796309919,53.77976436926622,279.08974436015535,0.04516638223792792
0.0465684485132925,266.866969815333,0.14785482402970368,53.800381114771135,279.2945505590767,0.04551666784885882
0.0469365267608448,266.927215714226,0.14902347246568223,53.81252668798797,279.45585211779456,0.04586830613555254
0.0473086456895382,266.998434574553,0.15020495006428378,53.82688441022989,279.62976891550187,0.04622367898062799
0.0476642728076998,267.066771196688,0.15133406616444686,53.840661073252306,279.7963146368785,0.04656318420137568
0.0480229278266188,267.10293193795,0.15247279584951468,53.84795107869072,279.9299967606845,0.04690546335669251
0.0483641396437981,267.120367932109,0.15355614336905896,53.851466175113174,280.03941470848025,0.04723098704025926
0.0487206573607118,267.174436551294,0.15468808712025997,53.86236640874086,280.1913507300508,0.04757099972916679
0.0490697339182689,267.277882851121,0.15579640519050375,53.883221182785995,280.3931374448637,0.047903803771200966
0.0494447223746452,267.412462082694,0.1569869935394985,53.91035235587111,280.63459702989314,0.0482611884527724
0.0498076414477849,267.509491012535,0.15813926159671704,53.92991338812706,280.8335078247668,0.048606948765357524
0.0501867688705432,267.540992893138,0.15934299116397466,53.936264167256624,280.9680108668616,0.048968023466332625
0.0505312720022028,267.614480743347,0.1604367886069939,53.95107931785875,281.13738086151733,0.049296009543516754
0.0508853233227862,267.693669613171,0.16156090154984618,53.967043794015275,281.31534854290027,0.049632973974768534
0.0512323834308086,267.742293273581,0.1626628173928173,53.976846323953936,281.4593691032171,0.049963174429348986
0.051587781531117,267.79606332987,0.16379120636129646,53.987686367301784,281.61106813982445,0.05030119487409656
0.051945337826931,267.848954427809,0.1649264476005059,53.9983492126463,281.7624588521518,0.05064115272497817
0.0523057476043629,267.946234297577,0.16607074864385218,54.01796083439152,281.96136240028557,0.05098370669437041
0.0526645736687477,268.050707864684,0.16721002139827396,54.039022705520296,282.1674841159836,0.05132463888161702
0.0530281804399878,268.15110235876,0.16836447289696124,54.05926223552601,282.3706673998219,0.05166999484501151
0.0533972149132323,268.260275586678,0.16953615734951255,54.08127155827429,282.58462717486276,0.05202038416127616
0.0537654292785441,268.327302197242,0.1707052379593775,54.094784122963986,282.7540347870303,0.05236987248394997
0.0541321488553797,268.416271448427,0.17186957261583055,54.11272032400288,282.9462210096792,0.05271782068061711
0.0545061022240955,268.487520152887,0.1730568745615032,54.127084062822014,283.12172837223414,0.05307250776119612
0.0548714836061089,268.603222590312,0.17421696044939575,54.1504096742069,283.3418799152243,0.05341894302069831
0.0552359387821969,268.730605738839,0.17537410563347516,54.17609011694994,283.57419302633224,0.053764380580744224
0.0556074276878037,268.867015400452,0.17655358290877673,54.203590304731115,283.81801851696827,0.05411636208287091
0.0559839209666528,268.98169841152,0.1777489490691226,54.226710399762425,284.04034855686655,0.054472958810811246
0.0563618781948046,268.962803352276,0.1789489632685046,54.222901155818846,284.12205211375016,0.05483081426453022
0.056728696222865,268.963014646916,0.18011361050759636,54.22294375281827,284.2209358000069,0.05517800054815294
0.057105451944732,268.933371779252,0.18130980992452408,54.21696775069721,284.29093351772684,0.05553446723328345
0.0574761573898877,269.054801919743,0.18248679971289344,54.241448067020194,284.5190380613872,0.05588508548071058
0.0578483908095962,269.172244023965,0.18366864082046794,54.26512439523134,284.7434251913593,0.05623702525644613
0.0582165615786982,269.26645598066,0.18483758301236677,54.284117525701056,284.94222319633593,0.05658500207294381
0.0585640737519149,269.299233226895,0.1859409341623298,54.29072541854203,285.070493382929,0.05691334235586062
0.0589339661974018,269.30342681387,0.1871153426767507,54.29157084567619,285.17454586656305,0.057262709809592104
0.0592997745427058,269.338567384192,0.1882767841730909,54.29865518465311,285.31028370572994,0.05760809978417794
0.0596812300677549,269.378490218536,0.1894879054651218,54.30670362805686,285.4553298685729,0.05796813654556447
0.0600722563394838,269.431607989049,0.19072941387786105,54.31741217059228,285.6169726101264,0.058337072158758725
0.0604553759637063,269.477174874752,0.19194581868476748,54.326598454750005,285.76851879544256,0.05869841583809108
0.0608353946798301,269.504401492098,0.19315237810846056,54.33208734080696,285.89980812482116,0.05905670591830845
0.0611940355351879,269.527171532441,0.19429106282422157,54.33667778094011,286.0206268448959,0.05939472277487592
0.0615588012275467,269.598772759329,0.19544919389746077,54.35111258828073,286.1949500228111,0.05973839509473525
0.0619295406823269,269.68903120413,0.1966262916663879,54.369308690752604,286.3907490336635,0.06008757474524703
0.0623194041729084,269.791886395616,0.19786410824898415,54.39004429735619,286.60515600647585,0.060454634826320096
0.062702479231407,269.852405526362,0.1990803715597172,54.402244954114586,286.772820379424,0.06081517234891204
0.0630955905226632,269.893225265044,0.20032849990945564,54.41047421343287,286.9222976912081,0.061185020549764546
0.0634724772579109,269.917134989621,0.2015251152938671,54.415294413907596,287.0494442017702,0.06153947592309961
0.0638552852231294,270.022426915075,0.20274053058343583,54.436521266079126,287.26478600237874,0.06189937154059849
0.0642349891353762,270.100721448616,0.20394609050481943,54.45230544404099,287.45063835632516,0.06225622098524025
0.0646109211134144,270.137397183523,0.20513967453509072,54.459699272198236,287.5912232427307,0.06260940012341663
0.0649902927998269,270.157505914315,0.2063441796394504,54.4637531923259,287.7151213257573,0.06296568437790238
0.0653637446199195,270.188843241904,0.2075298891682444,54.47007079756785,287.8493977907193,0.0633162850924863
0.0657496751237961,270.317782509732,0.20875521851805262,54.49606495396198,288.0910888899318,0.06367847182972877
0.0661290651490913,270.431879533371,0.20995978184836486,54.51906691392759,288.3152869134245,0.06403439266343605
0.0665047154914606,270.465975954115,0.2111524716853874,54.525940752349584,288.4532387350636,0.06438668038359167
0.066871507726013,270.472315385934,0.21231703703009125,54.527218781804294,288.5592069139371,0.06473054119367723
0.0672522009292581,270.450280827206,0.21352573795039445,54.52277661476472,288.6386574547715,0.06508730889719798
0.0676323026118319,270.421222898475,0.21473256079256625,54.51691853633256,288.7104328782063,0.06544339531401334
0.0680264165674379,270.413873978214,0.2159838726016153,54.51543699400794,288.8091608150706,0.06581247484581339
0.0684059689112791,270.482835458088,0.21718895129331114,54.52933962835055,288.9854758914686,0.06616778901387618
0.0687989442185881,270.564414046734,0.21843664789401723,54.54578587182157,289.17896007627024,0.06653553598032157
0.0691902680645074,270.634763886626,0.21967910110481098,54.559968399543806,289.3600557475163,0.06690160316909965
0.0695786166216577,270.647478353524,0.22091210777376316,54.56253163607044,289.4787554895022,0.06726475466639219
0.0699699731602956,270.659962075431,0.22215466478393853,54.56504835440689,289.59803235741555,0.06763058561304298
0.0703620147654571,270.65544006623,0.22339939688032628,54.56413671735198,289.6993021365214,0.06799692280910186
0.0707659913614361,270.846467242029,0.22468202257255962,54.60264779599305,290.0131860031539,0.06837427213115688
0.0711716604299922,270.842236714581,0.22597002186522525,54.60179492165953,290.11852841613074,0.06875305913559396
0.0715843449020952,270.881157460733,0.22728029506415223,54.60964134408378,290.27200766388086,0.06913824949434567
0.0719777197387908,270.869985406715,0.22852926017066078,54.60738905799374,290.36658930196984,0.06950527860686864
0.0723761281858267,270.773142896337,0.22979420698999975,54.58786560790154,290.37065459588143,0.06987686695457138
0.0727683987576982,270.81248443869,0.23103966605569176,54.5957968628399,290.5190752948875,0.07024259576334574
0.0731590841544833,270.80010985149,0.23228009219048446,54.59330214606039,290.6115978771585,0.07060671375355063
0.0735574445606738,270.778560305513,0.2335448864801393,54.58895775759142,290.6963392434048,0.0709778483728022
0.0739477357943768,270.738806719619,0.23478406114714634,54.58094343467519,290.7593284682062,0.07134133176885682
0.0743307467801232,270.76310227535,0.23600012102689116,54.58584141871055,290.88912586797966,0.07169790657320503
0.0747207479322332,270.867167688985,0.23723837468484038,54.60682100609937,291.10656504899157,0.07206085846835579
0.0751177905022216,270.936485748508,0.23849898484455356,54.62079552689921,291.28863592437256,0.07243022813719772
0.0755118725948946,270.999546964229,0.23975019548879034,54.63350866798857,291.46323022786606,0.07279670880455381
0.0759176263045914,271.025621087461,0.24103846351707767,54.63876521123214,291.6012429081486,0.07317390333006807
0.076312312723087,271.067928352563,0.2422915928958012,54.6472943558767,291.7537488702031,0.0735406730843243
0.0767144158439782,271.143498757995,0.24356827030463077,54.662529349611795,291.94411387510706,0.07391419666415847
0.0771206766649778,271.21468339786,0.2448581484113045,54.67688017300857,292.1309433029806,0.07429144079694316
0.0775280054443519,271.239113085039,0.24615141728581727,54.68180519794386,292.26774052101706,0.07466953378965129
0.0779332411427585,271.257332943563,0.24743804062825822,54.685478321422295,292.39729608359517,0.07504554213016089
0.0783369254968596,271.245616218919,0.2487197384525292,54.68311622973407,292.4941638480102,0.07541997049731348
0.0787484245799335,271.247685356438,0.25002624804128887,54.68353336785791,292.608013249211,0.07580150300185809
0.0791601630475394,271.274035568293,0.2513335176759376,54.68884557056788,292.74813245444307,0.07618311181973227
0.0795681097496071,271.255396281173,0.2526287484550025,54.68508789028448,292.8386754226465,0.07656106277545421
0.0799789939717784,271.223585869368,0.2539333058603964,54.67867491126459,292.9157754086183,0.07694159092084293
0.0803904561983176,271.160120299072,0.2552396984296584,54.66588025229292,292.95880607270504,0.07732250931559438
0.0808038419704407,271.194349954725,0.2565521982561492,54.67278095087256,293.10789535174297,0.07770506240442575
0.081210494217806,271.235997700952,0.257843319141534,54.68117713651193,293.263207123906,0.0780812414568531
0.0816223837117124,271.258831623544,0.25915106828468687,54.68578045530647,293.3996240635117,0.07846212109215822
0.0820262679377049,271.20360794219,0.26043340070221305,54.6746473611455,293.44942775292833,0.0788354573363544
0.0824265736722866,271.13782167143,0.26170437140951,54.66138484896029,293.48678330477344,0.0792053482680951
0.0828381904883653,271.097705625195,0.2630112548005598,54.65329745403931,293.55494900473366,0.07958554825827643
0.0832397473195187,271.116718830129,0.2642861977394719,54.65713051615401,293.68440599964595,0.07995631685228191
0.0836459680552664,271.209564278061,0.26557594857547084,54.6758481584571,293.8951508279464,0.08033125193780494
0.0840580095671551,271.258987910158,0.26688418037571743,54.68581196268785,294.06047851108684,0.08071141594645627
0.0844672171989184,271.319507360011,0.2681834146065659,54.698012683778224,294.23711111849263,0.08108882233451184
0.0848817959201245,271.363352053841,0.2694997020463953,54.70685177405435,294.39716072307607,0.08147103720519049
0.085303682111651,271.360275403306,0.2708391907044919,54.70623152130649,294.5083060740397,0.0818598391772909
0.0857192870249394,271.353902358848,0.2721587363041826,54.70494671554377,294.6141654004835,0.08224270469670132
0.0861462035674434,271.380992428648,0.27351419632663276,54.71040807361545,294.75943464674117,0.08263583820322061
0.0865773331505639,271.406919139489,0.2748830327530404,54.71563489852099,294.9046063971967,0.08303269457403174
0.0870084511621778,271.439965545159,0.2762518324399145,54.72229705390406,295.05753653075817,0.08342938286706238
0.0874293010881002,271.44440163851,0.2775880309547181,54.72319137032361,295.17659595804247,0.08381647137372741
0.0878574978282185,271.42297039018,0.2789475556045937,54.71887083066029,295.26951342176386,0.08421016359478282
0.0882838675335366,271.398988319412,0.2803012794189787,54.71403604519346,295.35914065293883,0.0846020220627672
0.0887199288825439,271.415238039667,0.28168577420207686,54.717311988796865,295.495178656185,0.08500262894784198
0.089150493699425,271.406172944985,0.28305281749567435,54.71548446570897,295.6021672561019,0.08539802880085996
0.0895788033442823,271.393006956409,0.28441270061809626,54.712830202412064,295.70406775557063,0.08579120261181125
0.0900073640819646,271.32036145838,0.2857733809602376,54.6981848700094,295.7411920150146,0.08618445225672997
0.0904385293156516,271.265852455883,0.28714233057719385,54.68719585510602,295.7987372055496,0.08657993580494584
0.0908601708334323,271.235156868331,0.2884810423961475,54.681007624655535,295.87962955742034,0.0869665325814472
0.0912830841776008,271.208427161881,0.2898237922638825,54.675618915835216,295.96516884817373,0.08735414540062623
0.0917031361270381,271.238204905576,0.29115745720334596,54.68162210896413,296.11159893288556,0.08773898700037111
0.0921288177666984,271.236802656791,0.2925089964092674,54.68133941560907,296.22552862038043,0.08812883535321027
0.0925676699526802,271.287285208576,0.2939023520997596,54.69151669804893,296.39971708812215,0.08853058652949633
0.0930112587301918,271.327495148345,0.2953107464683589,54.699623021906355,296.5640070002026,0.08893650990090247
0.0934349266590735,271.275896267943,0.2966558921425584,54.68922068761731,296.62253974011264,0.08932405013584188
0.0938715146950196,271.172554270627,0.2980420591566872,54.668386940958406,296.62793268372815,0.0897232516683658
0.094300690914251,271.113273549844,0.2994046936527469,54.65643594764855,296.6794425616186,0.09011552081759872
0.0947365583338244,271.111129665232,0.30078857270989245,54.65600374051077,296.79526501571127,0.09051374832650325
0.0951759005305692,271.176786758306,0.30218348418455715,54.669240210474484,296.9862816410139,0.09091499012122499
0.0956144725106187,271.182085976204,0.30357595022121436,54.67030853280273,297.111018081148,0.09131536798604037
0.0960469476087049,271.158466365777,0.30494905865763805,54.66554681934063,297.2024093784675,0.09171002301781614
0.0965136838484565,271.108530308089,0.30643094621884936,54.65547971011074,297.2742132908636,0.0921357683678925
0.0969688679221463,271.043759862332,0.3078761556528145,54.642421988246134,297.32656641354447,0.09255080160338022
0.0974369458231097,271.033823635028,0.3093623029883733,54.640418844821646,297.44253162478446,0.092977411763753
0.0978837352863649,271.000857872339,0.31078085953420853,54.63377294706355,297.5274341066928,0.09338444976350256
0.0983181977801941,270.991498120027,0.31216027795211626,54.63188602099745,297.63489382894295,0.09378009871814139
0.0987527390539381,270.94333790983,0.31353994649625344,54.62217692262173,297.6997346568424,0.09417566289599731
0.0992045145366286,270.9167427755,0.3149743336537958,54.61681534354079,297.7929067223882,0.09458674958871156
0.0996611246280504,270.879210997189,0.31642407069406,54.6092489370333,297.87533780352777,0.09500206382151599
0.10011251276121,270.825769044019,0.31785722801684174,54.598475039274234,297.93881730350284,0.09541245890201228
0.100582455109712,270.827954078281,0.3193492949733356,54.59891554218145,298.06849461181486,0.09583954431140003
0.101036419590119,270.827051445207,0.3207906321986278,54.59873357135373,298.1904470513797,0.09625193584024945
0.101503512436836,270.806396828142,0.3222736519869543,54.594569600553434,298.29419729656206,0.09667607603124197
0.101963068408278,270.773541385416,0.3237327421962826,54.58794594329987,298.3824425088489,0.09709319692801445
0.102409600377795,270.688240500931,0.3251504811994991,54.57074928498769,298.4093150375998,0.09749832985489881
0.102868171853214,270.646256962618,0.3266064456339544,54.56228540366379,298.48714263527773,0.09791421531640664
0.103323029807648,270.623744062001,0.3280506196392824,54.5577468028994,298.5854092363764,0.09832656213434011
0.103783411302582,270.584356552998,0.3295123308856978,54.54980628108439,298.66652412118225,0.09874374319369988
0.104253490222101,270.506038496688,0.3310048314551706,54.5340173609323,298.70723713612176,0.09916953220682415
0.104724763884526,270.415454805539,0.33250112533337006,54.515755688796666,298.73464946077576,0.09959622148608605
0.105199164657043,270.312293802861,0.3340073477861115,54.49495843065678,298.74892130745116,0.10002555823716354
0.105668700528534,270.236896870253,0.33549812417809544,54.47975840904301,298.7924785973961,0.10045031078429134
0.106134809393041,270.242345612729,0.33697801982290515,54.48085687552617,298.92446545426435,0.1008717848160633
0.10658776150119,270.20759962622,0.33841614276627824,54.473852084645955,299.0084228109886,0.10128119187001026
0.107052955293074,270.212524196917,0.33989313305550994,54.474844878098466,299.1395734693982,0.10170148934213621
0.107509757842834,270.191167999591,0.34134348115099794,54.470539468717554,299.2393550424995,0.10211403359164346
0.107987762133623,270.100248531552,0.342861144774253,54.45221010396088,299.26776992220965,0.10254554325834006
0.108463278352269,270.020560942557,0.34437090876845405,54.436145086019486,299.30787620490537,0.10297462219331836
0.108949719000355,269.911383642222,0.3459153578261271,54.41413494227196,299.3181530450391,0.10341336829652062
0.109437803824862,269.80574718722,0.34746502714393684,54.39283863294355,299.33269561871526,0.10385340397771768
0.10992346577937,269.755953238663,0.34900700384949973,54.38280017291446,299.4084625332745,0.10429106319878424
0.110400375942008,269.65880585922,0.35052119361587536,54.363215261218755,299.42923940215087,0.10472064933483419
0.110885121045281,269.637448142335,0.35206025931876717,54.35890954549475,299.5362292179385,0.10515710391181268
0.111363822039527,269.580070319348,0.3535801349754982,54.347342176380565,299.6015372957951,0.10558792963288226
0.111862221248414,269.534235140358,0.3551625524637144,54.33810180429617,299.68493338565077,0.10603628639691066
0.11235593559811,269.419240604558,0.3567300955239992,54.3149189058789,299.69009145081543,0.106480230581329
0.112835384675447,269.299338562705,0.3582523463445442,54.290746654241325,299.68583302227125,0.10691115899668654
0.113327422871813,269.232604467195,0.35981456761800623,54.277293060586516,299.74404168452844,0.10735320950863496
0.113820169434738,269.178630045454,0.36137903795529314,54.26641181716353,299.8165873254382,0.10779570067775822
0.114317959975016,269.097346403156,0.3629595229206758,54.25002503487625,299.860006078655,0.10824252266064105
0.114815676422401,268.995431362649,0.36453977264112314,54.22947896271005,299.8803237690871,0.10868907862079465
0.115309526997965,268.897786616441,0.36610774821853886,54.20979378187451,299.90426320198253,0.10913196907634297
0.115797383807461,268.814774931969,0.3676566935886887,54.193058626284945,299.94282259788247,0.1095692917478014
0.116320469734769,268.750028434457,0.36931749140789155,54.18000573238653,300.0111579831856,0.11003798199733589
0.116835861098987,268.672700720151,0.3709538589892837,54.16441646518244,300.0633070625803,0.1104995630933411
0.117360757620484,268.618808278603,0.37262040544503666,54.153551748966365,300.14411512929144,0.1109694380602589
0.117873941867673,268.46626898746,0.37424976542986177,54.122799827871944,300.111446371519,0.11142861512683125
0.118359038538529,268.331084804366,0.37578994735982957,54.095546696560184,300.09049401181124,0.11186246677173164
0.118843533428949,268.185361235527,0.37732821863691307,54.06616882508225,300.05745717867615,0.11229559241181905
0.119325929374566,268.085518508417,0.37885982576424704,54.04604053129687,300.0750721562963,0.1127266553506213
0.119826148751298,268.034375389261,0.3804480222853711,54.03573007847502,300.1519023251158,0.11317344892926189
0.120344666469915,268.001005241606,0.3820943160419801,54.02900265670776,300.253496831009,0.11363637588496889
0.120860722051759,267.954232175781,0.38373279251433484,54.01957320663745,300.33937415337056,0.11409689199260202
0.121377569870862,267.904023767584,0.3853737843399868,54.00945119154494,300.421563131119,0.11455790260875161
0.121887578468075,267.810417826101,0.3869930616361381,53.990580233741966,300.45318114344786,0.11501260463662201
0.122407368993117,267.725468111636,0.38864339655314645,53.97345437130583,300.497038275632,0.11547581517401045
0.122932057679052,267.63470011321,0.3903092831309901,53.955155542823135,300.5355845044429,0.11594317319503193
0.123449570348225,267.51266532511,0.39195238585561437,53.93055332954217,300.5369889222033,0.11640392543042374
0.123970262686582,267.385218719811,0.3936055840298978,53.9048600939139,300.53303452301515,0.11686729443697945
0.124493616933108,267.23978496121,0.39526723376261785,53.875540648179935,300.509432379457,0.11733281604105861
0.125030232609346,267.160053684902,0.39697098853467355,53.85946682287624,300.56313734105066,0.11780990872582905
0.125551580837849,267.070770811993,0.3986262691601706,53.841467395697784,300.6019282830216,0.1182732095796026
0.126072437838105,266.97379464123,0.40027999013598337,53.82191699967197,300.63183177053946,0.11873585965370582
0.126592219469924,266.80953350453,0.40193029681700865,53.78880195451325,300.58554452660354,0.11919734125005205
0.127122363391197,266.661297406134,0.40361350376705046,53.758917557076614,300.55991175736466,0.11966780360148102
0.12766174422391,266.513936026517,0.4053260379109142,53.729209502945835,300.53756995964176,0.12014623596330219
0.128172047120948,266.422989282399,0.40694624960900994,53.710874639331635,300.57096921880645,0.12059866548865147
0.128682553548762,266.344382768258,0.4085671075173194,53.69502756608082,300.6182580662463,0.1210510707400749
0.129200686272053,266.233249203226,0.41021217891376827,53.672623039370364,300.6307677087213,0.12151002514767932
0.129734791253818,266.141626498608,0.41190796223087217,53.654151902119374,300.6694548563565,0.1219829071728915
0.130273276872751,266.053800715358,0.4136176540709844,53.63644622421618,300.7135011589976,0.12245944142665594
0.130824184486902,265.943894102816,0.41536678574591385,53.614289051127706,300.73578716808794,0.12294673366811551
0.131361076496076,265.859541058277,0.4170714178750413,53.59728347734864,300.78313656844495,0.12342140037955998
0.131909760572796,265.678629903969,0.41881348981862726,53.56081178864015,300.72423436391,0.12390625979495336
0.132448494554797,265.500615909922,0.42052397021148047,53.52492416744027,300.6657727905625,0.12438209791901898
0.132977670686236,265.318820980264,0.4222041044287993,53.48827430962122,300.60029978343795,0.12484927371947789
0.133529758987566,265.194271383269,0.423956984785522,53.46316511086703,300.60559852596003,0.12533644469012725
0.134059098271667,265.08213677854,0.42563763701254276,53.440558774553665,300.61880900299775,0.12580331882564044
0.134606047475797,264.970927995351,0.4273742007356554,53.41813908386277,300.63761730879924,0.12628549594706556
0.135146695354205,264.865467733182,0.42909075774960087,53.39687829500949,300.6611604107674,0.12676188958980128
0.135705365050216,264.730332206358,0.43086453403443575,53.36963497280178,300.65565857828676,0.12725392490731335
0.136263485340157,264.553775605881,0.43263656595499844,53.33404116214562,300.6027951298362,0.12774523472529073
0.136814404649259,264.390469557422,0.4343857347613973,53.30111866277628,300.56289424485874,0.1282299689460718
0.137376119868979,264.246436831959,0.4361691805840083,53.27208166532293,300.54758701313676,0.12872396030263306
0.137915370726183,264.125560418666,0.437881302055631,53.247712980403065,300.5525350020672,0.12919796626585123
0.138471099815456,263.936533665941,0.43964574191407274,53.209605187053704,300.4841157641429,0.12968622175981467
0.139017549545053,263.722856115048,0.4413807198055432,53.16652779279368,300.38496133118457,0.130166092199772
0.139555070372488,263.47143716272,0.44308734843264935,53.115841732004355,300.2402121171039,0.13063789707683177
0.140101546251516,263.280469675188,0.44482240934856326,53.077342686517895,300.16647057450723,0.13111733409862775
0.140644639736357,263.142628543676,0.4465467311629334,53.04955391440508,300.1522287344793,0.13159357603948224
0.141197114017456,262.988352168985,0.4483008370054228,53.018451797267375,300.121548515452,0.1320778114523768
0.141743523409703,262.790466495305,0.450035686825807,52.9785580454535,300.03931313482906,0.13255650055512697
0.142291870668879,262.611797799384,0.4517766893736908,52.94253843635582,299.97932176797576,0.13303665709835094
0.142837689279317,262.414226978271,0.45350966346183147,52.90270815881944,299.89686879386545,0.1335143705990512
0.143396865695014,262.280914329281,0.45528504858166946,52.875832328783055,299.8911753757224,0.13400353862919098
0.143956752640611,262.079288732881,0.4570626896339399,52.835184608548815,299.8073720732276,0.13449308860720108
0.144525104472864,261.839080112253,0.45886720670134323,52.7867585506302,299.6814005205549,0.13498979505228087
0.145109170811475,261.582364935557,0.46072161732643313,52.73500477100829,299.5403650102603,0.13549997814796952
0.145678521791469,261.313961677898,0.4625293066879141,52.680894674264245,299.38179333860677,0.1359970569419195
0.146244349102112,261.071541050841,0.4643258083992056,52.63202267584955,299.25177864090654,0.13649081467637414
0.146814407472753,260.789552679921,0.46613574372599076,52.57517382027207,299.0772163317079,0.13698801814379546
0.147370433342254,260.511138751777,0.46790112586165644,52.519045572358245,298.9027781601105,0.13747274445746985
0.147923260196725,260.139704550472,0.46965635112460186,52.44416443737516,298.62041775419067,0.13795444914451443
0.148469894052587,259.815823191743,0.47139191361696375,52.378869955455386,298.39065093420675,0.13843052952750556
0.148994677019991,259.553312524466,0.4730580995384714,52.32594780493234,298.22537449351756,0.13888736614917832
0.14955050031008,259.296933458963,0.47482283848450396,52.27426178532694,298.07491958662047,0.1393709966702617
0.150110922513339,259.037490704759,0.47660217897985124,52.221958126079414,297.9218473999909,0.1398583920831613
0.150656182970883,258.685644238343,0.47833338093255356,52.15102587844995,297.6582359886556,0.14033237353608838
0.151219687835995,258.264026352061,0.48012250887928404,52.066027712575504,297.31863179628687,0.14082197845659272
0.151769387567713,258.002732820926,0.4818678055274887,52.01335093669868,297.1596495719542,0.1412993578311006
0.152322238205603,257.678882673934,0.48362310630278954,51.948062747065094,296.92910682114666,0.14177924382375434
0.152882805368778,257.319731612784,0.4854029070458701,51.87565789313725,296.65949405848744,0.1422655929021472
0.153444413127384,256.926206674664,0.48718601167944414,51.796323265612266,296.35009767490277,0.14275260772398368
0.15401401677767,256.517348750868,0.4889945032691022,51.71389750817499,296.0246160051476,0.14324631426662274
0.154570158617906,256.09082364725,0.4907602536118515,51.627910047285596,295.6748228789956,0.1437281176653652
0.155139957452574,255.631270372666,0.49256936491192244,51.53526410712947,295.2898947818288,0.1442215119162391
0.155699053380083,255.137202768299,0.4943444944817635,51.43566007808908,294.86182372136545,0.14470540191099637
0.156282111766289,254.602529895768,0.49619570485796755,51.32787002698683,294.3923509289183,0.14520978179726568
0.156853357977101,254.143799067144,0.49800941157729567,51.23538989193623,294.00710735988315,0.14570369685749213
0.157398744988593,253.532426042862,0.49974101533878273,51.11213709024098,293.43811171592176,0.14617502582021802
0.157952728621534,252.995314476131,0.5014999133733704,51.00385539838801,292.956614726099,0.14665355674723
0.158508928940356,252.433830205674,0.5032658493856303,50.890660169463885,292.4468462598871,0.14713377218934184
0.159079442083133,251.85481271969,0.5050772286139472,50.7739302442895,291.9197358130902,0.1476261056523795
0.159671550414676,251.282675582842,0.5069571725665963,50.658587397500945,291.40536998550243,0.14813681883057636
0.160234855467063,250.522065861139,0.508745666107925,50.50524847760562,290.66443287570866,0.14862244623522455
0.160806652509685,249.743339519731,0.5105611217182499,50.34825724717777,289.90372993448864,0.14911515354116836
0.161381453225394,248.976587498561,0.5123861139906258,50.193680039709896,289.1567910081783,0.14961020450282705
0.161947159902826,248.231640187667,0.5141822326914725,50.043498661833674,288.43204931407985,0.1500971839902874
0.162518701883691,247.528973777532,0.5159968784807188,49.901841113550454,287.7570612744587,0.15058894599185443
0.16308400672169,246.635758259966,0.5177917213413656,49.72176886520914,286.8581059178434,0.15107510370661895
0.16366421584888,245.761172365128,0.519633885320194,49.5454523488098,285.9834819263681,0.15157383333588273
0.16424601268271,244.839466641165,0.5214810902676043,49.35963647485886,285.0533727843377,0.15207367807973282
0.164842330038824,243.905376817564,0.5233743978732662,49.17132396642091,284.1113074411686,0.1525857388360433
0.165440266874747,242.900407998138,0.5252728473273217,48.96872225242463,283.0859163213349,0.15309892710757553
0.166062184204197,241.691617379293,0.5272474348483255,48.72503006366547,281.82745526514344,0.1536324177276798
0.166693914444559,240.419073613666,0.5292531783614748,48.468485240515065,280.49547010146256,0.15417403479272235
0.16731602857565,239.113931377887,0.5312283907276888,48.20536856578202,279.1215247531456,0.15470712090718755
0.16796748283524,237.59338351865,0.5332967580018869,47.89882611735984,277.50134608658544,0.15526504398017232
0.168638640620395,235.999566504095,0.535427683969754,47.57751260722556,275.7982125863481,0.15583951632865725
0.169332803653418,234.129206654828,0.5376316515996021,47.20044806161332,273.77496163484057,0.15643333286574207
0.170060166452975,232.1824972312,0.5399410284881956,46.80799144180992,271.66749135780526,0.1570551718062619
0.170808442127878,229.893663082747,0.5423168037560125,46.3465624774818,269.16144152898227,0.1576944863732106
0.17143963650151,228.109305974278,0.5443208458922942,45.98683608441444,267.2162824731199,0.1582334509642549
0.171861748479144,226.838801738834,0.5456610514212822,45.73070243054894,265.82371482858395,0.15859372214823933