File: example/data/02 processed data/test_ID_077.csv
Strain,Stress_MPa,Displacement(mm),Force(kN),True Stress (MPa),True Strain
1.61656307736074e-05,-0.616690117054909,5.1325877706203494e-05,-0.12432472759826965,-0.616700086239643,1.6165500111155933e-05
2.39144434317254e-05,-0.455800952069896,7.592835789572813e-05,-0.09188947193729105,-0.4558118522959804,2.391415748600602e-05
2.58104128068189e-05,-0.271632219057395,8.194806066165e-05,-0.05476105536197083,-0.2716392299971005,2.5810079723830438e-05
3.05247922641569e-05,-0.0484350435846749,9.691621543869816e-05,-0.00976450478667046,-0.04843652205431863,3.052432639207293e-05
2.68415781410525e-05,0.0992992221880021,8.522201059784169e-05,0.020018723193101225,0.09930188753583381,2.6841217912322223e-05
1.70709616774088e-05,0.225121355003634,5.4200303325772936e-05,0.04538446516873262,0.22512519804165804,1.7070815970148722e-05
1.56477665990144e-05,0.33371706523204,4.968165895187071e-05,0.06727736035077926,0.3337222871587869,1.564764417410238e-05
2.85732985837626e-05,0.351151609310266,9.072022300344625e-05,0.07079216443694963,0.35116164287004703,2.857289037493596e-05
2.18063382723247e-05,0.460755614067626,6.923512401463092e-05,0.09288833179603341,0.46076566146040726,2.180610051768512e-05
-1.00595074673091e-05,1.36402594738018,-3.193893620870639e-05,0.27498763099184426,1.3640122259509766,-1.005955806453719e-05
-5.53710024321059e-05,3.72109001731989,-0.00017580293272193622,0.7501717474916899,3.720883976835491,-5.537253546268205e-05
-8.65862166903075e-05,7.51228005490762,-0.0002749112379917263,1.5144756590693762,7.511629594998948,-8.658996549319033e-05
-6.33965056150592e-05,11.9974936799697,-0.00020128390532781292,2.4186947258818914,11.996733080794252,-6.339851525844197e-05
-4.73625434030995e-06,16.7811589806339,-1.5037607530484091e-05,3.3830816504957943,16.781079500796842,-4.7362655563642494e-06
7.58258839997281e-05,21.3877088753471,0.0002407471816991367,4.311762109269976,21.389330617279303,7.582300936265212e-05
0.0001730464543123,26.5152087080691,0.0005494224924415524,5.345466075546731,26.519797070921385,0.00017303148350177272
0.0002612375974318,32.1403709098955,0.000829429371845965,6.479498775434934,32.148767183172566,0.000261203480832203
0.0003597449546532,37.7136973047183,0.0011421902310239098,7.60308137663121,37.727264617044995,0.00035968026195188035
0.0004577209412485,43.4474588817856,0.0014532639884639873,8.759007710567976,43.46734569355982,0.0004576162189728791
0.0005669840122507,49.0977414147943,0.0018001742388959723,9.898104669222532,49.1255790492141,0.0005668233375460207
0.000670143917081,54.7592841622987,0.002127706936732175,11.039471687119416,54.795980763483776,0.0006699194709148468
0.0007666584588953,60.5735564274527,0.0024341406069925773,12.211628975774465,60.61999565687317,0.0007663647264176712
0.0008721770123868,66.2751055382226,0.00276916201432809,13.361061276505678,66.33290916176655,0.0008717968870246092
0.0009745674136572,72.0601530423961,0.0030942515383616098,14.527326853347054,72.13038051937437,0.0009740928311520545
0.0010820129276579,77.837958546056,0.003435391045313832,15.69213244288489,77.92218022346533,0.00108142797358394
0.0011984228247104,83.6478235137482,0.0038049924684555197,16.863401220371635,83.74806897468441,0.0011977052892936596
0.0012933013687018,89.4816551339333,0.004106231845628214,18.039501675000956,89.59738188099172,0.0012924657748587982
0.0013809836829444,95.221550549398,0.00438462319334847,19.196664590758637,95.35304995697139,0.0013800310019684828
0.0014730005809897,100.878596646758,0.004676776844642298,20.33712508398641,101.0271908782281,0.0014719167797966122
0.0015603167796859,106.405690286351,0.004954005775502732,21.451387161728363,106.57171687035886,0.001559100750222451
0.0016689372412811,111.811948306592,0.005298875741067493,22.541288778608948,111.99855543114106,0.0016675461131120297
0.0017613672107073,117.163845214244,0.005592340893995677,23.62023119519159,117.37021376948476,0.0017598178225759922
0.0018555777439149,122.513800001409,0.005891459336929807,24.698782080284055,122.74113388201405,0.001853858286262664
0.0019443790412122,127.771571324027,0.006173403455848735,25.75874877892384,128.02000768937216,0.0019424911830293406
0.0020316117191234,132.885118166407,0.006450367208216795,26.789639822347652,133.155089129771,0.0020295507869054637
0.0021233482423459,137.946827313262,0.006741630669448232,27.810080386353615,138.2397364665748,0.0021210971245083266
0.0022072864653903,142.91650127653,0.0070081345276142015,28.81196665734845,143.23195893547862,0.002204853987413066
0.0022972235154959,147.819784692226,0.0072936846616994825,29.80046859395276,148.1593597776765,0.0022945889316030627
0.0023855680683881,152.687764435717,0.007574178617132218,30.78185331024055,153.05201149098843,0.0023827271181734136
0.0024736106527694,157.462465948245,0.007853713822542845,31.744433135166197,157.85196678142594,0.0024705563137321527
0.0025680791587877,162.165900398125,0.008153651329150947,32.692645520262,162.58235526720344,0.002564787278173618
0.0026553411141213,166.831728907826,0.008430708037335127,33.63327654781772,167.2747240567349,0.0026518219242948
0.002756277500992,171.391897814362,0.0087511810656496,34.55260659937538,171.86430144616006,0.0027524859336373175
0.0028498768310352,175.888566107635,0.00904835893853676,35.45913492729922,176.38982685702916,0.00284582363098039
0.0029341325941983,180.460478082049,0.009315870986579601,36.38083238134108,180.98997305275415,0.0029298364287858396
0.0030341247695807,185.057307195516,0.009633346143418722,37.30755313061603,185.6187941550698,0.003029531102515718
0.003123171088167,189.58615303344,0.009916068204930224,38.22056845154151,190.17826302531086,0.0031183041202931814
0.0032075118309053,193.995373106218,0.010183850063124326,39.10946721821355,194.6176155605971,0.0032023787382075256
0.0033064560689395,198.382488032722,0.010497998018882912,39.99390958739676,199.0384310142491,0.0033010017627139515
0.0034059408302885,202.76616108045,0.010813862136165987,40.87765807381872,203.45677062747473,0.0034001537503970283
0.003517498271647,206.984179280064,0.011168057012479225,41.7280105428609,207.71224577293992,0.003511326343531342
0.0036288541892128,211.159552467518,0.011521612050750639,42.56976577745163,211.9258196940821,0.0036222857835777143
0.0037446372500022,215.195203394418,0.011889223268756985,43.38335300431467,216.00103136907055,0.0037376435497448813
0.0038675141075506,219.038418587315,0.012279357291473154,44.1581451872027,219.88555276129702,0.003860054502098055
0.0040142609101874,222.638742492482,0.012745278389844994,44.88397048648438,223.53247249356286,0.0040062252624724366
0.0041937637013978,225.985378543503,0.013315199751938013,45.5586523143702,226.93310782108537,0.004184994383488316
0.0044250892399258,228.958758303066,0.014049658336764413,46.15808567389811,229.97192124081965,0.004415327320184571
0.0047095936933676,231.538779850265,0.014952959976442129,46.67821801781343,232.62923342761786,0.004698538254484034
0.0050306183518006,233.584392141484,0.015972213266966902,47.09061345572317,234.75946607128512,0.00501800706865132
0.0053833817613848,234.995853592338,0.01709223709239674,47.37516408421534,236.26092598456805,0.005368943157620955
0.0057495309637662,235.854209294537,0.018254760809957683,47.548208593778654,237.21026037381054,0.005733065492957584
0.0061255141222706,236.362582478372,0.019448507338209155,47.65069662763979,237.81042481531964,0.006106829424072278
0.0065124222989773,236.664035655102,0.020676940799252926,47.71146958806857,238.2052917982682,0.006491308097032867
0.0068962997102473,236.825167029661,0.021895751580035178,47.74395367317966,238.45838436042692,0.006872628999962623
0.007280637791291,237.021178567436,0.023116024987348924,47.783469599195094,238.74684391745043,0.007254261892835693
0.0076569551985253,237.184836063805,0.024310832755317827,47.816462950463084,239.00094972731512,0.007627789502741689
0.0080402894873511,237.349880439283,0.02552791912233974,47.84973589655945,239.25824218780298,0.008008138579923427
0.008415490906575,237.531938202499,0.026719183628375623,47.8864387416238,239.53088606846325,0.008380278080528544
0.0087873926593,237.63659268001,0.027899971693277497,47.90753708429002,239.7247987301074,0.00874900822658241
0.0091533641516039,237.793125328228,0.02906193118134238,47.93909406617077,239.96973239710528,0.00911172600715259
0.0095059737347856,237.95154184084,0.030181466607944275,47.971030835113346,240.21350294773077,0.009461076271607827
0.0098666208137427,238.115276462514,0.03132652108363307,48.00403973484283,240.46466960532916,0.009818263532408713
0.0102243839288537,238.331525494647,0.0324624189741105,48.04763553972083,240.76831851365364,0.010172468484573089
0.010583361109638,238.478143388036,0.033602171523100646,48.07719370702806,241.0020436962676,0.010527749372071378
0.0109468693591037,238.679290168358,0.03475631021515425,48.11774489794097,241.2920811765546,0.010887386094693547
0.0112956882147254,238.842412076778,0.03586381008175314,48.15063027467844,241.54030149605026,0.011232368310377655
0.0116392204662828,239.019157124422,0.036954524980447885,48.18626207628348,241.80115378985823,0.011572005787970597
0.0119906904089294,239.161098686032,0.03807044204835085,48.214877495104055,242.0288053782356,0.011919371622298154
0.0123410809147145,239.350018424784,0.03918293190421853,48.252963714436454,242.30385636910265,0.012265550558229426
0.012688370012277,239.544056425394,0.04028557478897947,48.29208177535943,242.58348004756115,0.012608547151003383
0.0130337792764612,239.769066821746,0.04138224920276431,48.33744387126399,242.89416391602373,0.012949570491892378
0.0133807900418493,239.971494435884,0.04248400838287152,48.378253278274215,243.18250261895938,0.013292057931564417
0.0137256439135017,240.168919660172,0.043578919425367894,48.41805420349068,243.46539273051792,0.013632300426188973
0.0140746590724801,240.315945346208,0.04468704255512432,48.44769458179553,243.69831034663662,0.013976530735170465
0.0144166703879279,240.470998913848,0.045772928481671075,48.478953381031765,243.9377900430447,0.014313738307834377
0.0147594153590781,240.609353692653,0.046861143765072964,48.506845704438845,244.16060708308223,0.014651555195010754
0.01509852820345,240.778607534944,0.04793782704595375,48.54096727904471,244.41401013159776,0.014985679904182678
0.0154376078178632,240.972146773776,0.04901440482171566,48.57998478959324,244.69218027069815,0.015319660286555584
0.0157822380332198,241.16622667396,0.05010860575547286,48.61911129747034,244.9723694689019,0.015658993539297603
0.0161372697997155,241.380339916108,0.051235831614096713,48.66227652708737,245.27555958568126,0.01600844810060294
0.016482257963964,241.548187225862,0.05233116903558569,48.69611454473378,245.52944675844654,0.016347899889635774
0.016821266924555,241.722005849117,0.05340752248546212,48.731156379181996,245.78807623104387,0.016681356217805865
0.0171503261709895,241.897123375178,0.05445228559289166,48.76646007243588,246.04573794088643,0.017004919487246126
0.0174689148015548,242.034964155997,0.055463804494936486,48.794248773849,246.26305232383547,0.017318087304352494
0.0177890858468896,242.137538250829,0.056480347563874475,48.814927711367126,246.44494370552752,0.017632711836351858
0.0181165767365166,242.234378329709,0.0575201311384402,48.83445067126934,246.62283603294154,0.01795442703020419
0.0184454893294115,242.39563970818,0.05856442862088151,48.86696096516909,246.8667458939131,0.018277434711860573
0.0187828397344542,242.570068804071,0.05963551615689209,48.90212587090072,247.12622353079342,0.018608620375552283
0.0191192072549323,242.812318666614,0.06070348303441005,48.95096344318939,247.45469771125164,0.018938731946939593
0.0194383059702028,243.011592385526,0.06171662145539388,48.99113702492205,247.73532607262206,0.01925179519465925
0.0197720329980874,243.199321139284,0.0627762047689275,49.02898314167965,248.0078661419624,0.01957910525629119
0.0201038583980435,243.357889101732,0.0638297504137881,49.060950442909174,248.25032164428,0.019904444071542113
0.0204407307825698,243.492904221997,0.06489932023465912,49.088169491154595,248.4700771246649,0.020234622975127837
0.0207839240037616,243.667814282749,0.06598895871194307,49.1234313594022,248.73218761696432,0.020570885055463548
0.0211044137251381,243.841658913188,0.06700651357731346,49.158478436898704,248.98779416631595,0.020884800089980032
0.0214386731595605,243.984819227463,0.06806778728160458,49.18733955625654,249.21553002277506,0.021212097408262
0.0217758983959814,244.163859277073,0.06913847740724094,49.22343403025791,249.48074666866125,0.0215421902376472
0.0221072945182841,244.24869852087,0.07019066009555201,49.24053762180739,249.64837643477844,0.021866471122538825
0.0224530972450972,244.391267871899,0.07128858375318362,49.26927960297484,249.87860877527933,0.022204737217786964
0.0227736054527063,244.558396903237,0.07230619731234249,49.302972815692584,250.12787334445767,0.022518157935216603
0.0230987933378315,244.733146663707,0.073338668847615,49.338202367403326,250.3861870414092,0.02283605448444026
0.0234298507979746,244.866290307,0.07438977628356935,49.3650441258912,250.60347095434656,0.023159585224143808
0.0237594489872663,244.980019035162,0.0754362505345705,49.38797183748866,250.80060930032747,0.023481585922539513
0.0240884701481872,245.067573268941,0.07648089272049435,49.40562277101851,250.97087619191856,0.023802919514431257
0.0244156123300125,245.165385456354,0.07751956914778968,49.425341708000964,251.15124846439443,0.02412231568982058
0.0247358851545435,245.37445328877,0.0785364353656756,49.467489783016035,251.4440075851799,0.024434906367017357
0.0250567245832171,245.544279385139,0.07955510055171429,49.50172672404402,251.69681476667694,0.024747952115908953
0.025376224740428,245.659168001705,0.0805695135508589,49.52488826914373,251.89307025846287,0.025059593771786716
0.0257051630807033,245.809021236817,0.08161389278123297,49.55509868134231,252.12758221441743,0.02538034003280625
0.0260267964221904,245.910530365464,0.08263507864045451,49.575562921677545,252.3107936773588,0.025693863778081055
0.0263632386942175,246.08317195958,0.08370328285414055,49.61036746705133,252.57072136058056,0.026021717908421022
0.0266951747080252,246.263727755896,0.08475717969798001,49.646767515588635,252.83778099258924,0.026345075504613406
0.0270232265231921,246.408633384293,0.08579874421113491,49.67598049027347,253.06738970150693,0.026664546584738283
0.0273536825209305,246.536303211511,0.08684794200395433,49.70171872744062,253.27997897944252,0.02698625580872119
0.0276788706399574,246.612390277627,0.08788041428186474,49.7170578799696,253.43834272633208,0.027302735585395265
0.0280114394833569,246.71506881731,0.08893632035965815,49.7377578735697,253.6259130371183,0.027626294873156803
0.0283472751283919,246.85038634111,0.09000259853264428,49.765037886367786,253.8479221582713,0.027952926258658386
0.0286850283569116,247.036859468017,0.09107496503319432,49.80263086875223,254.12311878705947,0.028281315104066965
0.0290207598186031,247.202017939011,0.09214091242406483,49.83592681650462,254.37600832829307,0.028607631399234154
0.0293644162918962,247.296032885483,0.09323202172677042,49.85488022971337,254.55773654246676,0.0289415402132642
0.0296979878342839,247.399336685887,0.09429111137385138,49.87570627587482,254.74659917699435,0.029265543550547474
0.0300305231297573,247.470355167868,0.09534691093697942,49.890023601842195,254.90201939266592,0.02958843590902342
0.0303528610513199,247.565912204324,0.09637033383794068,49.90928790039172,255.08024593850513,0.029901327118171415
0.0306745025174632,247.698306456606,0.09739154549294565,49.935978581651774,255.29632878158054,0.03021344472945583
0.0310025622187646,247.791032455022,0.0984331350445776,49.95467214293243,255.47318935596073,0.030531690209974035
0.0313306270857851,247.906611726373,0.0994747409973677,49.9779729240368,255.67368133047253,0.03084983945131787
0.0316639927571611,248.017669748785,0.10053317700398648,50.00036222135506,255.8708994473585,0.031173025630352128
0.031981252744837,248.148612384077,0.10154047746485746,50.02676025662993,256.0847158750128,0.03148050094944292
0.0323088329757046,248.218074308078,0.10258054469786211,50.04076378050853,256.2377106124487,0.031797879050401955
0.0326345511737152,248.287859409354,0.10361469997654575,50.05483245692577,256.3906222630608,0.03211335326941653
0.0329627420285764,248.344082636328,0.10465670594073007,50.066167059483725,256.5301845665927,0.03243112175091369
0.0332968767899841,248.441284495145,0.10571758380819951,50.08576295422124,256.71360333452526,0.0327545416747967
0.0336231599706757,248.561081987728,0.10675353290689533,50.10991412872596,256.9184910098856,0.033070260887537284
0.0339568997186923,248.734890128088,0.10781315660684804,50.14495384982254,257.1811558487074,0.03339309216011708
0.0342897814725364,248.889930988217,0.10887005617530306,50.17621008722455,257.4243123325177,0.033714989697529604
0.0346184632479692,249.021594270579,0.10991362081230222,50.20275340494873,257.6423391797857,0.03403272421189154
0.0349456401292238,249.145666688057,0.11095240741028556,50.22776640431229,257.8522214958934,0.034348903723747645
0.0352766413076943,249.227267869379,0.1120033361519294,50.24421720246681,258.01916880210376,0.034668677290343904
0.0356204260070212,249.324720693522,0.1130948525722923,50.26386369181404,258.20577345870686,0.03500069253910822
0.0359645629446568,249.405289461653,0.11418748734928534,50.28010635546925,258.375041693227,0.03533293760038896
0.0363036978062513,249.497670052654,0.11526424053484786,50.29873028261505,258.5553580696093,0.03566024547943661
0.0366465523135448,249.605777019873,0.11635280359550473,50.3205246472064,258.7529681851948,0.03599103442181489
0.0369727408121497,249.716655344646,0.11738845207857529,50.34287771748063,258.9493645191805,0.036305642317658246
0.0373032022560818,249.794380383231,0.11843766716305971,50.358547085259374,259.1125106770993,0.03662427055787118
0.0376301941746381,249.827213036848,0.11947586650447596,50.36516614822855,259.2282595735333,0.036939453610807624
0.0379607681205207,249.896734641335,0.12052543878265323,50.37918170369314,259.38300663913003,0.03725798838445312
0.0382975696307523,249.988375203913,0.12159478357763855,50.39765644110886,259.5623224101635,0.037582419604847976
0.0386369688999204,250.075048778421,0.12267237625724728,50.41512983372968,259.73719066071897,0.03790924673001029
0.0389686270025812,250.177449689412,0.1237253907331953,50.435773857385456,259.9265214108157,0.03822851628351191
0.0393066544932238,250.239574706684,0.12479862801598555,50.448298260867496,260.0756552102109,0.03855381245253538
0.0396355136174276,250.326119093505,0.12584275573533263,50.46574560925061,260.24792339563345,0.03887018404958227
0.0399678005941089,250.423188403708,0.12689776688629575,50.48531478218754,260.43205246196834,0.03918975170677765
0.0403109310705386,250.479444823851,0.12798720614896003,50.496656076488364,260.576504458732,0.039519640653214054
0.0406478543772399,250.50554310518,0.12905693764773668,50.50191749000429,260.68805594201075,0.03984345610982146
0.0409803112735955,250.605541880611,0.1301124882936657,50.52207724313118,260.87543499376653,0.040162876172124835
0.0413044127033965,250.674995066199,0.1311415103332839,50.53607900534572,261.0289785168352,0.040474170231660764
0.0416348080689029,250.721541011944,0.13219051561876669,50.545462668007914,261.16028425071585,0.040791409798694035
0.0419745248030311,250.733273452886,0.13326911624962373,50.547827928101825,261.25768345837935,0.04111749466669576
0.0423121608690489,250.78347903356,0.13434111075923025,50.557949373165705,261.3946699417277,0.04144147703562054
0.042657599955851,250.940466303361,0.13543787985982692,50.589598006757576,261.6449843276645,0.04177283828263083
0.0430024924373319,251.087146886067,0.13653291348852878,50.61916881223111,261.88452002114633,0.0421035656968271
0.0433498551759714,251.211017855898,0.13763579018370917,50.644141199749036,262.10097909855955,0.04243655139049138
0.043695467214688,251.254068772183,0.1387331084066344,50.6528202644721,262.2327326967749,0.04276774883806763
0.0440317257323396,251.28382479992,0.13980072920017822,50.65881907966387,262.34828525448336,0.04308987763123093
0.0443720351060112,251.295136596664,0.14088121146158555,50.661099537887466,262.4456132197011,0.043415781446446526
0.044712577878214,251.343707677828,0.14196243476332943,50.670891467850126,262.58193278157194,0.04374180249231756
0.0450569183377559,251.351702702355,0.14305571572237497,50.67250326479477,262.6768358450709,0.044071351242341565
0.0454045303116151,251.429828859744,0.14415938373937792,50.68825349812439,262.84588214545045,0.044403920854938564
0.0457504598154844,251.525742106598,0.14525770991416298,50.70758960869015,263.03316046340575,0.04473477103931799
0.0461014658045095,251.575285120246,0.14637215392931766,50.7175774802416,263.17327452447677,0.04507036457538103
0.0464474003580723,251.651787597114,0.14747049613687954,50.733000379578186,263.34035892646176,0.04540099920218297
0.0467987207964856,251.626871546361,0.14858593852884178,50.72797730374638,263.4026872527523,0.04573666965981467
0.0471416055558692,251.617442365666,0.1496745976398847,50.726076380918265,263.47909258464483,0.04606417160257123
0.0474889462050158,251.66337604628,0.15077740420092517,50.735336610930055,263.6146045731145,0.04639582020956634
0.0478320621347054,251.696962684176,0.15186679727768965,50.74210767712988,263.7361474424021,0.04672332700340925
0.0481800799189853,251.724889454602,0.15297175374277833,50.747737714047766,263.8530147461225,0.04705540312119068
0.0485213707012172,251.755727909346,0.15405535197636458,50.75395474652416,263.97126090939014,0.04738095331828247
0.0488634598844992,251.783465635551,0.15514148513328496,50.75954667212708,264.08647690821397,0.047707158773120345
0.0492080582928923,251.862781689635,0.15623558507993304,50.77553678863042,264.2564601328285,0.048035649397492386
0.0495471099015859,251.888344110939,0.15731207393753524,50.7806901727653,264.36868357953216,0.04835874721926913
0.049899994883539,251.9246152664,0.15843248375523633,50.78800243770624,264.4956522792309,0.04869491666547444
0.0502376943742491,251.950161011097,0.1595046796382409,50.79315245983716,264.60755619751535,0.04901651414486632
0.0505825049646446,251.994732747491,0.1605994532627466,50.80213812189419,264.74125756775527,0.049344776976307486
0.0509211363607629,252.015396743665,0.16167460794542218,50.80630398352287,264.8483071262609,0.04966705231515539
0.0512645532915945,251.981728515232,0.16276495670081254,50.799516468670774,264.8994592652092,0.04999377600619464
0.0516101010149219,251.997887939074,0.16386207072237702,50.80277420851732,265.0035243911566,0.05032241920490347
0.0519529617944879,252.045302156668,0.16495065369749906,50.812332914784264,265.1398021100935,0.050648400192746204
0.0522999561168401,252.111413651154,0.16605236067096732,50.82566099207264,265.2968295216639,0.05097820306249042
0.0526521494398631,252.164442491719,0.16717057447156533,50.83635160633055,265.4414424012127,0.05131283616447869
0.0530063825432696,252.204288682739,0.16829526457488098,50.844384598440186,265.57272568770946,0.051649294428121884
0.0533563418821913,252.273813616146,0.16940638547595738,50.85840082501503,265.73422146337333,0.051981582251186466
0.0537188880525235,252.315420197452,0.1705574695667621,50.86678871180632,265.86952400896433,0.05232570491824569
0.0540738436990676,252.350073690053,0.1716844537445396,50.87377485591468,265.9956121322171,0.05266250810060084
0.0544400207242414,252.369707513655,0.17284706579946643,50.87773303475285,266.1087196208691,0.053009839967878246
0.0547891699614683,252.375861821707,0.17395561462766185,50.87897374325613,266.2033258092285,0.05334090805849413
0.0551446328066568,252.400500707896,0.17508420916113535,50.88394094271183,266.3190336396492,0.053677850239414814
0.0554998873151285,252.368887783215,0.17621214222553297,50.87756777709615,266.3753326170277,0.05401448154652478
0.0558573392369098,252.324460486721,0.17734705207718862,50.86861123412296,266.418633473898,0.054353080738268514
0.0562140682609959,252.295405756709,0.17847966672866197,50.86275380055254,266.4779569178523,0.05469088089617227
0.0565672675299556,252.286851201619,0.179601074407609,50.86102920224639,266.55802900783107,0.05502522621271458
0.0569121467762665,252.303283164746,0.18069606601464613,50.8643418860128,266.662404648352,0.055351587801133785
0.0572710603907489,252.317616308101,0.18183561674062773,50.867231447713166,266.7681137493321,0.05569111714439376
0.0576183574187114,252.321810730758,0.18293828480440869,50.86807704332081,266.86017900597926,0.05601954758445343
0.0579848354145332,252.332360124899,0.18410185244114288,50.87020380117964,266.963810496502,0.05636600007680061
0.0583378840011793,252.305998170733,0.18522278170374426,50.86488923121978,267.02499622481895,0.05669964351093489
0.0586979594705115,252.313814137798,0.186366021318874,50.866464930180086,267.12412017390864,0.05703981297373809
0.059051362153184,252.268676645121,0.1874880748363592,50.857365211656386,267.1654856295965,0.05737356605994579
0.0594124686505497,252.27629290902,0.1886345879654953,50.85890065045843,267.26465025275405,0.05771447959890956
0.0597755600043971,252.313945390055,0.18978740301396077,50.86649139063509,267.39615277266444,0.05805714985986878
0.0601422335087528,252.357981714547,0.19095159139029014,50.87536911365268,267.53535437862087,0.058403081677728994
0.0605036411406287,252.34635514285,0.19209906062149612,50.873025196798565,267.6142284575587,0.05874392843549779
0.0608718868186249,252.327682640801,0.19326824064913403,50.86926082038548,267.6873447797177,0.05909110476221738
0.0612249999898572,252.303931407815,0.1943893749677966,50.864472571815504,267.7512396056994,0.059423901230358414
0.0615933954695393,252.303869662759,0.19555903061578725,50.864460124012226,267.84412168539245,0.05977098271803373
0.0619704176589696,252.326546743023,0.19675607606722847,50.869031823393435,267.9633282311337,0.060126067120076086
0.0623433333797451,252.342258523209,0.19794008348069067,50.87219931827894,268.0741160721193,0.060477160007766324
0.0627154844949584,252.32698247939,0.1991216632714929,50.86911966784503,268.15179143673583,0.060827410189914166
0.063088116351593,252.316083548695,0.2003047694163078,50.86692244341691,268.23422998499336,0.061177989952129995
0.0634546882568362,252.289140297953,0.2014686352154549,50.86149068406732,268.2980690461448,0.061522748503972435
0.0638260070288091,252.253769311153,0.20264757231646888,50.854359893128446,268.3541201642502,0.06187185031885464
0.0641956471784317,252.199248202368,0.20382117979152062,50.84336843759739,268.389342158633,0.06221925294289234
0.0645544811526674,252.165304745906,0.204960477659719,50.83652543677466,268.44370515848226,0.06255638408182573
0.0649315897872889,252.111273964568,0.20615779757464225,50.82563283125691,268.48125978638615,0.06291056215672342
0.0652920638705483,252.117974807593,0.20730230278899084,50.826983721210745,268.5792777216436,0.06324899994102011
0.0656604414684058,252.07112807476,0.2084719016621884,50.81753941987162,268.6222296255878,0.06359473979266313
0.0660270303744657,252.048966881003,0.20963582143892856,50.81307172321021,268.69101167310765,0.06393868224625057
0.0663976196191333,251.99191694566,0.21081244229074822,50.80157045624505,268.72358039411415,0.06428625771476684
0.0667750488555358,252.005148792795,0.21201078011632615,50.80423799662747,268.83280491528046,0.06464012427786217
0.067154372552895,252.004063196913,0.2132151328554416,50.80401914049766,268.92723794168177,0.06499564091074497
0.067529986245801,252.031298528338,0.21440770633041817,50.80950978331294,269.050968651468,0.06534755588612233
0.0679159756925035,252.054961833034,0.2156332228236986,50.81428030553966,269.1735204940612,0.06570906299778506
0.0682954399397276,252.053386549882,0.21683802180863512,50.81396272845621,269.2674834726044,0.06606433144026085
0.0686760190252535,252.072542081362,0.21804636040517986,50.81782448360258,269.38388077708566,0.06642051690820712
0.0690649869369435,252.040778186977,0.21928133352479562,50.811420882494566,269.44797124003765,0.06678442246542628
0.0694440079235952,252.01868001863,0.22048472515741477,50.80696589175581,269.51986723073776,0.06713889466220566
0.0698303499034621,251.996481694616,0.22171136094349214,50.80249070963458,269.5934841857924,0.06750008441110669
0.0702080666711798,251.94373126696,0.22291061168099588,50.79185622341914,269.6322135491365,0.06785308440280265
0.0705854851915977,251.851065909295,0.22410891548332268,50.77317488731387,269.6280955925236,0.06820568124615518
0.0709686797159622,251.777937996609,0.22532555809817997,50.758432300116375,269.6462858378357,0.06856354707531159
0.0713520880187636,251.727817655482,0.2265428794595744,50.74832803934517,269.6891230576073,0.06892148442313509
0.0717496328666286,251.715197401292,0.22780508435154578,50.74578379610047,269.7756704017856,0.06929248394084386
0.072136246062091,251.750450611557,0.2290325812471389,50.75289084328989,269.91078306311454,0.06965314977987301
0.0725148382858498,251.718988656579,0.2302346115575731,50.74654811316633,269.9723504124885,0.07000620695589065
0.0729018766145042,251.657024611775,0.23146345825105083,50.73405616173385,270.00329396919585,0.0703670117638005
0.0732798485798768,251.584844016774,0.2326635192411088,50.71950455378165,270.0209432913152,0.07071923913098321
0.0736682509798985,251.535921478525,0.23389669686117773,50.70964177007064,270.066132872465,0.0710810572898278
0.0740517353519893,251.521106714128,0.23511425974256603,50.7066551135682,270.1466811439621,0.07143816564529944
0.0744395875297836,251.522851692157,0.2363456904070629,50.70700690113885,270.2461090264361,0.07179921172249486
0.0748371481743129,251.531683091722,0.23760794545344346,50.708787311291154,270.3555969297915,0.07216916003343977
0.0752390726770441,251.516731665575,0.23888405574961502,50.70577310377992,270.4406173188538,0.07254303004187503
0.0756458493254377,251.501032912988,0.2401755716082647,50.702608235258374,270.52604215391585,0.07292127124769877
0.0760480426666821,251.481757844487,0.24145253546671563,50.69872238144858,270.6064532949367,0.0732951100613193
0.07644607510408,251.471410218083,0.24271628845545398,50.69663629996553,270.6954125301435,0.0736649437706416
0.0768486767774286,251.431465759918,0.2439945487683358,50.688583497199474,270.7536412037771,0.07403888391765405
0.0772539411121014,251.380562210439,0.24528126303092193,50.6783213416245,270.80070136017116,0.0744151560005981
0.07767354049235,251.31165554382,0.2466134910632112,50.66442975763411,270.8319215969024,0.07480458848882203
0.0780755086591819,251.253575083808,0.24788973999290254,50.65272073689569,270.8703257609143,0.075177515172147
0.0784820094692501,251.224006211771,0.24918038006486906,50.64675965229304,270.94057104618616,0.07555450564095227
0.0788940021497694,251.172532968921,0.2504884568255178,50.63638264653448,270.9885393249341,0.0759364443325007
0.0793072296688319,251.131391652139,0.25180045419854125,50.62808855707122,271.0479266069486,0.07631938130614327
0.0797215395518363,251.073578369931,0.25311588807708024,50.616433399378096,271.0895505783705,0.07670317414299313
0.0801315789400067,251.043230722767,0.2544177631345213,50.610315313709826,271.15972118278273,0.0770828660670282
0.080531860283362,250.999049142149,0.2556886563996743,50.601408307057234,271.2124694989213,0.0774533831412454
0.0809286782482078,250.941102831194,0.2569485534380598,50.58972633076871,271.2494346014701,0.07782055891173018
0.0813216191517516,250.799420973325,0.2581961408068113,50.561163268222316,271.1948359691976,0.07818401443613643
0.0817203485343988,250.679251073869,0.2594621065967162,50.536937016492,271.1648468419677,0.07855268910183431
0.0821310569973266,250.588690873728,0.26076610596651195,50.51868008014357,271.1698049267636,0.07893229785575313
0.0825401093650054,250.575950778434,0.2620648472338921,50.5161116769323,271.2585171599261,0.07931023273926253
0.0829496397727599,250.631788586941,0.2633651062785127,50.527368579127305,271.4216051658303,0.07968846626615857
0.0833760252504398,250.653134019354,0.26471888017014633,50.53167181830177,271.55159605045355,0.08008211482054756
0.083805592097577,250.667664321171,0.266082754909807,50.53460112714807,271.6750163493234,0.08047854385014466
0.0842362264489485,250.661138566512,0.2674500189754115,50.533285535008815,271.7758869967519,0.0808758003544711
0.0846671290031859,250.639217247017,0.2688181345851152,50.52886619699863,271.86012018692776,0.0812731463762048
0.0850866567053172,250.5983697554,0.2701501350393821,50.52063134268864,271.9209472136899,0.08165985173431743
0.0855214508315954,250.547040488322,0.2715306063903154,50.51028336244572,271.97418689244574,0.08206047138609485
0.085957301469825,250.475623752327,0.27291443216669437,50.49588574846913,272.00583245404823,0.08246190349186212
0.0863950405513174,250.406486109905,0.2743042537504327,50.48194759975685,272.04036463168313,0.08286491278179146
0.0868295124961829,250.337431514422,0.2756837021753807,50.46802619330748,272.07410865236585,0.08326475360822107
0.0872746529176252,250.283730088064,0.27709702301346,50.457199985753704,272.12715576242834,0.08367424680063011
0.0877201146352532,250.230988238778,0.2785113639669289,50.446567228937646,272.18127921237635,0.08408386776202488
0.0881699731269181,250.16410816398,0.27993966467796494,50.43308420585837,272.2210708581175,0.08449736153232563
0.0886205370360063,250.114522754621,0.28137020508932,50.423087787331596,272.2798060816399,0.08491133238842692
0.0890651725520393,250.067082801918,0.28278192285272474,50.41352389286667,272.3393506812559,0.08531968839705949
0.089512457472069,249.996734985199,0.2842020524738191,50.399341773016126,272.3745570937177,0.08573030945563469
0.0899487132311013,249.908629143045,0.2855871645087466,50.38157963523788,272.3875887598104,0.08613064305250989
0.0903918979781958,249.808540198706,0.28699427608077166,50.361401704059126,272.3892082784294,0.08653717105177718
0.0908430432041305,249.714615277102,0.28842666217311436,50.34246643986376,272.3994508614226,0.08695083142723715
0.0912854434255437,249.638431400244,0.28983128287610127,50.327107770289196,272.42678630667245,0.08735630730107788
0.0917329870380882,249.584568553295,0.29125223384593,50.316249020344266,272.47970654530127,0.08776633005908052
0.092180321014728,249.566359555284,0.2926725192217614,50.312578086345255,272.5714666935671,0.08817599282476486
0.0926255065914419,249.557454663417,0.29408598342782805,50.31078286014486,272.67284032528676,0.08858352156461899
0.0930826731739383,249.48062156722,0.2955374873272541,50.29529330795155,272.7029447277925,0.08900184510240461
0.0935446829218835,249.369591328483,0.2970043682769801,50.27290961182218,272.69679067966564,0.08942442259694887
0.0940145339614148,249.295984691555,0.29849614532749197,50.258070513817486,272.73343051078353,0.08985398906822893
0.0944977116188488,249.234303973016,0.30003023438984494,50.245635680960035,272.7863753553826,0.09029554717809124
0.0949748214153441,249.254190490422,0.3015450579937175,50.24964480286907,272.92706271927597,0.09073136886285654
0.0954583896969081,249.241009121231,0.3030803872876832,50.24698743884017,273.0331544983761,0.09117289639902307
0.0959315726814823,249.198262352962,0.30458274326370627,50.23836969035714,273.10424356997424,0.09160475289198118
0.0964159214792871,249.144479976242,0.3061205506967365,50.22752716321039,273.1659745946291,0.09204660693836296
0.0969028050656155,249.065641398055,0.3076664060833292,50.21163330584789,273.20080069499323,0.09249057669837403
0.097388341332389,248.977383625932,0.30920798373033503,50.19384053898789,273.2248780465394,0.09293312168653088
0.0978758471912805,248.885587180294,0.31075581483231557,50.17533437554727,273.2454748792646,0.09337726491945367
0.0983729044657076,248.813246445056,0.3123339716786216,50.16075048332329,273.28972816739804,0.09382990698246113
0.0988567865134674,248.710107426171,0.31387029718025894,50.13995765711608,273.2967894197415,0.09427035438545123
0.0993499150508993,248.619459105689,0.31543598028660524,50.1216829557069,273.3197812478397,0.09471901878571273
0.0998441176149766,248.498994596851,0.3170050734275507,50.097397310725164,273.31015744058243,0.09516845850322356
0.100353174457845,248.423598505608,0.31862132890365785,50.08219745873057,273.3536952258869,0.0956311959620741
0.100858853655238,248.395462845479,0.3202268603553806,50.07652530964857,273.44834448123623,0.09609065120748465
0.101365304563899,248.344763112301,0.3218348419903793,50.06630424343988,273.5183056620287,0.09655059613697702
0.101868189627812,248.292931146359,0.32343150206830307,50.055854919105975,273.58608253962154,0.09700709343875806
0.102378788422884,248.189452737722,0.3250526532426567,50.03499367192476,273.5987882083486,0.0974703798211726
0.102895101831442,248.075908764597,0.32669194831482834,50.012103206942754,273.60170465885767,0.09793863314813905
0.103417343251484,247.982301466733,0.3283500648234617,49.99323197569337,273.6279722578111,0.09841203974198702
0.103936126687332,247.897733353832,0.3299972022322791,49.97618304413253,273.6632635731983,0.09888208991969086
0.104460445749145,247.778446354267,0.33166191525353533,49.95213478502023,273.66149330746435,0.09935693133015926
0.104981298966599,247.658036436509,0.3333156242189518,49.92786014560022,273.65749880113106,0.09982841081437585
0.105508634162292,247.547399394388,0.33498991346527707,49.90555571790862,273.6657873949173,0.10030553147237425
0.106031699206154,247.455289278102,0.33665064497953895,49.88698631846536,273.69339407780956,0.10077856381614239
0.106559441211623,247.307042934874,0.33832622584690303,49.857099855670604,273.65994323771304,0.10125559909467761
0.107084919257417,247.16623650283,0.33999461864229896,49.828713278970525,273.6340129818952,0.10173036194732737
0.107623387754792,247.028171580094,0.34170425612146454,49.80087939054695,273.61418027641577,0.10221662779667685
0.10816118994127,246.899129485804,0.34341177806353224,49.77486450433808,273.60403312645224,0.10270205603049712
0.108703840977096,246.807443038551,0.3451346951022798,49.75638051657188,273.63636007857735,0.10319162218729601
0.109233729174425,246.635585453009,0.34681709012879935,49.72173402732662,273.57651019915875,0.10366944285686021
0.109767816882815,246.463931987851,0.34851281860293765,49.68712868875076,273.517739742512,0.10415081946486869
0.1103011586832,246.231833089387,0.35020617881916,49.640337550820426,273.39148958383475,0.10463129265422949
0.110844411379798,246.009833252665,0.35193100613085865,49.595582383737266,273.2786484131989,0.1051204570878915
0.111393532785992,245.800815258016,0.3536744665955246,49.55344435601603,273.1814364312834,0.10561466286708107
0.111947292127462,245.581435345015,0.35543265250469186,49.509217365555024,273.0736120286648,0.10611279553906325
0.112504123403176,245.343117832736,0.3572005918050838,49.46117255507958,272.9452302375101,0.1066134414812106
0.113050823304614,245.048097553014,0.3589363639921494,49.401696466687625,272.7509867306116,0.10710473459733244
0.113596750884667,244.69481301851,0.3606696840588177,49.33047430453162,272.4913487357438,0.10759509292553879
0.114138573466152,244.285964799221,0.3623899707550326,49.248050503522954,272.1684163392067,0.10808152646748272
0.11467640775782,243.885844782991,0.3640975946310785,49.16738630825099,271.85379736568564,0.10856414553334348
0.115216098712064,243.468432934105,0.36581111341080313,49.08323607951557,271.51991593631243,0.10904819663734598
0.115748864650408,243.057876082828,0.3675026452650454,49.00046781829812,271.19154928375485,0.1095258069604309
0.116277875161217,242.527532830031,0.36918225363686397,48.89355061853425,270.7281190155993,0.10999982504567946
0.116813238458532,242.017655486691,0.3708820321058391,48.790759346116914,270.2885215882327,0.1104793068763192
0.117350256709015,241.463229565353,0.3725870650511226,48.678987080375165,269.799001540635,0.11096004005630959
0.117882580843991,240.91442508487,0.3742771941796714,48.56834809710979,269.3140392764208,0.11143634313856253
0.118410756270023,240.252616332348,0.375954151157323,48.43492745260136,268.701110328113,0.11190871000304073
0.11892003952533,239.531904588598,0.37757112549292277,48.28963196506135,268.01704814985163,0.11236396969468794
0.119428978892372,238.763291452679,0.3791870079832811,48.134679556860085,267.27854754785426,0.11281871501959004
0.119921010635672,237.929883233916,0.3807492087682586,47.966664459957464,266.46267529175464,0.11325815660176257
0.120411026842455,237.212327770051,0.38230501022479463,47.82200527844228,265.77530773653183,0.11369560623547732
0.120907672190886,236.335670516274,0.383881859206063,47.64527117608084,264.9104662940689,0.1141387786917404
0.121414148529658,235.424222467968,0.3854899215816641,47.46152324954235,264.0080539821731,0.11459052147255361
0.121954731501161,234.586168533883,0.38720627251618617,47.29257157643082,263.19506173131884,0.11507246003092286
0.12249440968437,233.600258412346,0.3889197507478747,47.09381209592895,262.21498416868263,0.11555336038522954
0.123005241127997,232.598022677059,0.39054164058139046,46.8917613716951,261.20879854234596,0.11600834282288369
0.123486025546645,231.513060457599,0.39206813111059785,46.67303298825196,260.10168815564805,0.11643637424514705
0.123958423483089,230.307968845873,0.39356799455880753,46.430086519328,258.85658157959983,0.1168567610036318
0.124429635679025,229.141557999233,0.39506409328090436,46.19493809264537,257.65355858000174,0.11727591658570748
0.124927704981423,227.990891469766,0.396645463316018,45.96296372030483,256.47327029775255,0.11771877135274224
0.125402976382538,226.743655160085,0.3981544500145581,45.71152088027314,255.1779843930155,0.1181411727465618
0.125879570217447,225.536779679588,0.3996676354403942,45.46821478340494,253.92725257388153,0.11856457037183853
0.126347363543703,224.156440041751,0.401152879251257,45.189938312417006,252.47801526236836,0.11897997552126699
0.126782475271783,222.739371746075,0.40253435898791096,44.90425734400872,250.97882063652423,0.11936620424718695
0.127219947798089,221.213933002397,0.40392333425893256,44.596728893283235,249.35675801117193,0.11975437821481158
0.12764449144551,219.717156608339,0.4052712603394942,44.29497877224114,247.76284132546388,0.12013093624202478
0.128069860683722,218.203806339953,0.40662180767081735,43.98988735813452,246.14913741856864,0.12050808438833388
0.128505567011012,216.619566969325,0.4080051752599631,43.67050470101593,244.45638724839802,0.12089425037007516
0.128956246734698,215.068345951611,0.4094360833826661,43.35777854384478,242.80275263697035,0.12129353041718764
0.129388545712116,213.307065499563,0.4108086326359683,43.002704404711906,240.90655649467053,0.1216763762821273
0.129841162901007,211.577796706342,0.4122456922106972,42.65408381599855,239.04930387472632,0.1220770590398132
0.130277161412926,209.803329635653,0.41362998748604,42.296351254547645,237.1359118755663,0.12246287823577047
0.130742909550872,207.895775257233,0.4151087378240186,41.91178829185817,235.07667379769785,0.12287485878429782
0.131194605746842,205.925017419636,0.4165428732462233,41.514483511798616,232.94126889341672,0.12327424753745243
0.131658142417804,203.863385871294,0.41801460217652764,41.09885859165287,230.7036605621126,0.12368393984095878
0.13208793895709,201.540454974223,0.41937920618876073,40.63055572280336,228.1615182882423,0.12406366135476844
0.132424845185523,199.801689656371,0.42044888346403547,40.280020634724394,226.26039747692184,0.12436121430591805
0.132638643037714,198.600946231111,0.4211276916447419,40.03795076019198,224.94310624521157,0.12454999299043398