File: example/data/02 processed data/test_ID_072.csv
Strain,Stress_MPa,Displacement(mm),Force(kN),True Stress (MPa),True Strain
0.00042495357030630614,16.0840702137286,0.0013492275857225219,6.4850971101753725,16.09090519679098,0.00042486330310980054
0.0004665480983529061,18.7104144353403,0.001481290212270477,7.5440391003292095,18.719143743614506,0.000466439298627853
0.000533158917960906,21.3246480266245,0.0016927795645258765,8.598098084335,21.336017452892275,0.0005330168392431207
0.0006165088224077062,23.9350521069796,0.001957415511144467,9.650613009534176,23.94980827776834,0.0006163188589157624
0.0006958216869830061,26.5952310689583,0.0022092338561710443,10.723197167003987,26.613736607506404,0.0006955797153125579
0.0007757348373358061,29.5494193098321,0.002462958108541184,11.914325865724303,29.57234182381378,0.0007754341105796761
0.0008503167875587061,32.6698881993739,0.002699755800498892,13.172498921987557,32.697667953757495,0.0008499554730457353
0.0009420396217590435,35.9153323777364,0.002990975799084963,14.481062014703316,35.94916604386487,0.0009415961809052191
0.0010306600498925333,39.2535683454846,0.003272345658408793,15.827038756899393,39.294025430194026,0.0010301292844845467
0.001127574164014506,42.765325181374,0.0035800479707460567,17.242979113129998,42.8135462571642,0.0011269389297377532
0.0012286490760330061,46.4069220051208,0.0039009608164047942,18.711270952464705,46.46393982696392,0.0012278949044351936
0.001324057989499306,50.1780474000158,0.004203884116660297,20.23178871168637,50.244486044573264,0.001323182197700374
0.0014316699479438061,53.9705185933953,0.004545552084721584,21.760913096856985,54.0477865629404,0.0014306460856292635
0.001522934278651506,57.8756481890794,0.004835316334718532,23.335461349836816,57.963788997605725,0.0015217757902949661
0.0016215210209150062,61.8072009686483,0.005148329241405144,24.920663430559,61.90742264426288,0.0016202077751497272
0.001716557246640106,65.7655766016502,0.005450069258082336,26.51668048578536,65.87846697874524,0.0017150856460667933
0.0018120055184873063,69.5949677754594,0.005753117521197197,28.06069100706523,69.72107424112748,0.0018103658169545316
0.001910665443092306,73.3299668522452,0.006066362781818072,29.566642634825268,73.47007588585289,0.0019088424435999523
0.001989026110662306,76.798896391694,0.006315157901352822,30.965315025131023,76.95165140188713,0.001987050617332678
0.002094598821301606,80.3318306325723,0.006650351257632599,32.38979411105315,80.5000935903283,0.0020924082076284618
0.002182142956396206,83.7211675697713,0.006928303886557953,33.75637476413179,83.90385912588494,0.002179765540401292
0.002282188851365506,87.1661038306862,0.007245949603085481,35.14537306453268,87.36503334106555,0.0022795886137928927
0.002372498535155506,90.581528741661,0.007532682849118732,36.522472388637716,90.79643328591273,0.002369688603999885
0.002464264165774506,94.0495277103745,0.007824038726334056,37.920769572823005,94.2812905913192,0.0024612328457960576
0.0025554002862994063,97.3869917417344,0.008113395909000615,39.26643507026731,97.63585448831306,0.0025521408026637654
0.002641663375306306,100.612524488682,0.008387281216597521,40.566969873836584,100.87830890972086,0.0026381803153117133
0.002735969470721006,103.820837033985,0.008686703069539194,41.860561492102754,104.10488767453468,0.0027322335189971353
0.0028207765878311064,106.978791356384,0.008955965666363763,43.133848674894026,107.28055462643655,0.002816805663193451
0.0029084489670368058,110.081902277342,0.009234325470341857,44.385022998224294,110.40206987230998,0.002904227612422094
0.0030057914716626064,113.247145124371,0.009543387922528774,45.66124891414639,113.58754242737596,0.0030012831123430762
0.003097219462382706,116.277704519854,0.009833671793065091,46.88317046240513,116.63784208933407,0.0030924329588714167
0.0031778340350968057,119.200443615322,0.010089623061432358,48.06161886569783,119.5792428420414,0.0031727953923443193
0.003260624525181606,121.963114715086,0.010352482867451598,49.175527853122674,122.36079063809355,0.003255320216147042
0.0033625147924910065,124.680063029835,0.010675984466158944,50.27100141362948,125.09930158610152,0.003356874180516803
0.003482673853777306,127.284122016645,0.011057489485742946,51.320957997111265,127.72741110039335,0.0034766233889855494
0.0036034088543598058,129.716733262311,0.011440823112592383,52.30178685136381,130.18415568750703,0.0035969321308659567
0.003728481957002706,132.041960058198,0.01183793021348359,53.23931829546543,132.53427612384226,0.003721548397241602
0.003869930785380506,134.227343633803,0.012287030243583106,54.120464953149366,134.7467941631713,0.003862461866503198
0.004024127240648606,136.304318346882,0.012776603989059323,54.95790115746283,136.85282426735975,0.004016052096978782
0.0041937935163548065,138.061270376297,0.01331529441442651,55.66630421572295,138.6402708368608,0.004185024073930124
0.004383681622508406,139.51601609028,0.01391818915146419,56.2528576876009,140.12760988606055,0.00437410127814034
0.004600112742970706,140.716490797228,0.01460535795893199,56.73688908944233,141.36380251969044,0.004589564560528716
0.0048400909420757065,141.773276250746,0.015367288741090368,57.162984984300785,142.4594718009556,0.004828415360672688
0.005112344845763606,142.690625459752,0.01623169488529945,57.53286018537201,143.42010914335992,0.005099321179641728
0.005412585631527507,143.41893696462,0.017184959380099833,57.82651538413478,144.19520424212365,0.005397990232130975
0.005721434160473906,143.859218307305,0.01816555345950465,58.00403682150538,144.6822993532275,0.005705128919393867
0.006059050833680906,144.215450393249,0.019237486396936877,58.147669598558,145.08925913818388,0.006040768596679478
0.006397224771518406,144.312235041036,0.02031118864957094,58.18669316854571,145.2354328458737,0.006376849380267197
0.006744635905232006,144.397971158726,0.02141421899911162,58.22126197119832,145.3718828996458,0.006721992605340837
0.007097722323453106,144.409746754154,0.02253526837696361,58.2260098912749,145.4347270374152,0.007072652050352863
0.007454259669419306,144.393198391921,0.023667274450406294,58.219337591622555,145.46954278723237,0.007426613976255622
0.007831234321057106,144.366359524373,0.02486416896935631,58.20851616022719,145.49692631388635,0.007800729363042016
0.008212510467900705,144.299485773427,0.026074720735584738,58.18155266384577,145.48454681085394,0.008178971305831962
0.008611033370511906,144.234096569446,0.027340030951375303,58.15518773680063,145.47610118817113,0.00857416989324976
0.009017516557801206,144.155704079659,0.028630615071018828,58.12357988491851,145.45563052809882,0.008977101535749935
0.009427560954879106,144.043513853672,0.02993250603174116,58.07834478580055,145.40149286068248,0.009383398845780155
0.009827773343175706,143.886982717086,0.031203180364582864,58.015231431529074,145.30107137026297,0.009779794870333682
0.010237078103146406,143.689362726575,0.03250272297748984,57.93555105135504,145.1603219553983,0.010185034103399828
0.010646612759788307,143.510148402688,0.03380299551232787,57.8632918359638,145.03804537983117,0.01059033665900932
0.011050857480249306,143.310212497886,0.03508647249979155,57.78267767914764,144.89391323166438,0.010990242907890626
0.011460038684587906,143.150765933926,0.036385622823566596,57.71838882455897,144.7912792492572,0.011394869860158079
0.011866954284392606,142.993063384133,0.03767757985294652,57.65480315648242,144.68995553029774,0.011797094124159515
0.012293947460507807,142.847309851765,0.039033283187112286,57.59603533223165,144.60346717395748,0.012218990606875582
0.012714416759815706,142.688367574725,0.04036827321241487,57.53194980612911,144.50256694684782,0.01263426721785639
0.013131730750546406,142.518424039012,0.041693245132984835,57.46342857252964,144.38993761048448,0.013046257039636536
0.013551684078354607,142.307577966763,0.04302659694877588,57.37841543619885,144.23608530532437,0.01346068124693597
0.013979591796273807,142.145553428216,0.04438520395316933,57.31308714225669,144.13269024079787,0.013882778532796935
0.014398750672916107,141.94774298538,0.045716033386508634,57.23332997170522,143.99161314520967,0.014296073107909256
0.014823454649929306,141.721374505484,0.04706446851352555,57.142058200611146,143.82217487339167,0.014714661059588779
0.015239604059065106,141.487110331236,0.04838574288753171,57.04760288555436,143.64331787214533,0.015124647747617822
0.015661694468799704,141.237152114476,0.049725879938439056,56.946819732556726,143.44916523853632,0.015540315821805244
0.016096505398712907,141.088035688136,0.051106404640913476,56.88669598945643,143.35906001628388,0.015968330274095482
0.016524295353515305,140.970347697482,0.05246463774741109,56.83924419162474,143.29978335892295,0.016389254787866403
0.016967178189062907,140.833945058902,0.053870790750274726,56.784246647749285,143.2234996997851,0.01682484337853669
0.017397261505898105,140.669110008209,0.05523630528122648,56.71778515530987,143.11636730082378,0.01724766174367385
0.017823441813747707,140.457224753085,0.05658942775864897,56.63235302044387,142.9606559257921,0.017666466754239718
0.018255791925915407,140.205009685033,0.057962139364781416,56.53065990500531,142.7645631688139,0.018091155647973818
0.018679603159726905,139.995359012121,0.05930774003213292,56.44612875368719,142.61041676267095,0.018507281992431922
0.019108367460484405,139.805958817812,0.06066906668703798,56.36976259534181,142.4774224520681,0.01892809545611551
0.019541414304159805,139.671386221082,0.06204399041570738,56.315502924340265,142.40076264566449,0.01935293237912435
0.019980474507140706,139.557419129217,0.06343800656017173,56.269551392900304,142.3458425844107,0.019783484472899
0.020419425558694405,139.395632296898,0.06483167614885472,56.20431894210927,142.24201103379164,0.02021374430413227
0.020864871786588905,139.246600303838,0.06624596792241977,56.144229242507485,142.15196276589597,0.02065018153685323
0.021309441699968606,139.065928870736,0.06765747739740031,56.07138252068076,142.02934617445894,0.02108557034520971
0.021761696552583407,138.881599649173,0.06909338655445231,55.997060978546564,141.90389887747568,0.02152829096470648
0.022208830038180905,138.709589223906,0.07051303537122437,55.9277063750789,141.7901669156456,0.021965805583350064
0.022631969110167807,138.5371700883,0.07185650192478278,55.858186979602564,141.67253904234846,0.02237966575104891
0.023078514408482107,138.361255968558,0.07327428324693068,55.78725840652259,141.55442820800405,0.02281623320182394
0.023509555321335005,138.171216103234,0.07464283814523864,55.71063433282395,141.4195599520291,0.023237462002676932
0.023953007120200605,137.993828877684,0.07605079760663691,55.63911180348219,141.2991960433349,0.023670634080090507
0.024404507686689305,137.829009490687,0.07748431190523854,55.572656626645006,141.19265861225125,0.024111475652459625
0.024855895403186206,137.685596717264,0.0789174679051162,55.51483259640084,141.10789550779356,0.024552012856141954
0.025299001715200806,137.521454899018,0.08032433044576255,55.44865061528406,141.0006104223852,0.024984279042016215
0.025739893755995908,137.342628295416,0.08172416267528701,55.37654772871173,140.87781295590923,0.025414199750550242
0.026170278277503106,137.148850483455,0.08309063353107235,55.29841651492905,140.73807406604666,0.025833696211637718
0.026610253220134408,136.946695292199,0.08448755397392674,55.216907541814635,140.590881531585,0.026262358645461125
0.027048165268488206,136.720893491195,0.08587792472745005,55.12586425564982,140.41894281400022,0.026688828842304474
0.027501245740425707,136.535639253026,0.08731645522585162,55.05116974682009,140.2905394204496,0.027129879786958817
0.027945050617505907,136.402279436378,0.08872553571058125,54.99739906874761,140.21404803957077,0.027561712897620157
0.028390625044379107,136.292409977975,0.09014023451590367,54.95309970311953,140.1618366860545,0.02799508030851556
0.028851425755826606,136.193455417666,0.09160327677474947,54.91320122440293,140.12283078507826,0.028443059406526496
0.029291733846538305,136.062427319172,0.09300125496275911,54.860370695090154,140.04793172671916,0.028870928668559986
0.029750208596087305,135.959162754413,0.09445691229257719,54.81873442257932,140.00397620690617,0.029316256903672986
0.030203211855939008,135.784863011602,0.09589519764260634,54.748456766277926,139.88600199597107,0.029756075845845758
0.030658149844129505,135.623566764849,0.09733962575511117,54.683422119587114,139.78153439712102,0.030197578611665
0.031114064052853507,135.459496537054,0.09878715336780988,54.61726900374018,139.6741919888752,0.03063983330215131
0.0315792711456931,135.305064966523,0.10026418588757559,54.555002194502066,139.57790030048642,0.031090900935704668
0.03204145591413791,135.21001585278,0.10173162252738785,54.5166783918409,139.54234161487676,0.03153883671199572
0.03250821262200881,135.040340299432,0.10321357507487795,54.44826520873098,139.43026039443436,0.03199099993474276
0.032970721098727805,134.829206253456,0.10468203948846078,54.36313596139345,139.27462240880155,0.032438846172144035
0.03344107256632921,134.600428718096,0.10617540539809522,54.27089285913631,139.10161142231686,0.032894081161768375
0.033908077635882904,134.408107507243,0.10765814649392821,54.19334894692038,138.96562805149068,0.033345872362545034
0.03437262761225031,134.277097648019,0.10913309266889472,54.14052577168127,138.89255432232812,0.03379508603359123
0.034831507368715306,134.162577438449,0.1105900358956711,54.09435122318264,138.83566224310218,0.0342386186519831
0.035293253867913606,133.962588024779,0.1120560810306257,54.013715491590894,138.69056365274025,0.03468472365541305
0.03575073539717081,133.785797544007,0.11350858488601731,53.94243356974363,138.56873819190227,0.03512651198928658
0.03620943710319951,133.591126726148,0.11496496280265843,53.86394229598287,138.42838622688402,0.03556928277186299
0.03666722596581211,133.48893349514,0.11641844244145344,53.82273798524045,138.38360238354156,0.03601097703974805
0.03712407856642821,133.33123215429,0.11786894944840955,53.759152804609734,138.28103129214455,0.03645157355204727
0.037595974277461405,133.18521205875,0.11936721833093995,53.700277502088,138.19243986544902,0.03690647417203599
0.038072941011839105,133.055605099037,0.12088158771258915,53.648019975931724,138.12142330326716,0.03736605299914024
0.038539982317386604,132.909306771398,0.12236444385770245,53.58903249022767,138.0316291041838,0.03781586365780991
0.039017526974809306,132.813043440858,0.12388064814501955,53.55021911535395,137.99507994591818,0.03827558105547233
0.03947570182894801,132.653158941676,0.12533535330690992,53.48575368528376,137.88973549072566,0.03871645317880728
0.0399598562482948,132.500365401308,0.126872543588336,53.42414732980738,137.7950609555908,0.03918211264703633
0.04044724996893641,132.402734651107,0.1284200186513731,53.384782611326344,137.7580611561111,0.03965066875617675
0.04094336166492311,132.295253573491,0.12999517328613086,53.34144624083157,137.71186598710315,0.040127380530131165
0.04143675392088841,132.156049673808,0.13156169369882068,53.285319228479395,137.6321673832983,0.040601253922894896
0.04192925017363991,132.008366545762,0.1331253693013067,53.22577339125123,137.5433783716728,0.04107404292008264
0.042418321418865604,131.852739050267,0.13467817050489828,53.16302438506765,137.445710915259,0.0415433228625132
0.042902920476850105,131.712607698571,0.13621677251399908,53.10652342406382,137.36346323246133,0.04200809448328011
0.04339191849051251,131.557059607854,0.13776934120737722,53.04380643388673,137.26557281520948,0.04247686621533225
0.04388889933670521,131.391613234983,0.13934725539403903,52.977098456345146,137.15824652194047,0.04295306553776134
0.04438385240679701,131.210609395118,0.14091873139158048,52.904117708111585,137.03424171671682,0.04342709660381506
0.04488357759049521,131.039355067334,0.1425053588498223,52.83506796314907,136.92087012790714,0.04390547020601943
0.045379376687192906,130.90763310564,0.14407952098183746,52.781957668194046,136.84813989956967,0.04437985942578824
0.04585527563784301,130.716091803191,0.14559050015015154,52.704728215046615,136.7101142231279,0.04483499625927197
0.046332815045053204,130.544224751556,0.14710668776804392,52.63543141982738,136.5927061721697,0.04529149385394787
0.04680979166892111,130.361673412085,0.14862108854882453,52.56182671975267,136.46387618611664,0.04574724553622124
0.047305593466038506,130.217523989393,0.15019525925467225,52.50370567252326,136.3775412413893,0.0462207646268127
0.0478134004619836,130.135648850192,0.15180754646679792,52.47069361639742,136.35787674304632,0.0467055170512438
0.04831944095323291,130.008051101186,0.15341422502651447,52.41924620399819,136.28996744981464,0.04718834952357744
0.04882730908247201,129.92406316764,0.15502670633684862,52.385382269192455,136.267905557177,0.04767269153651366
0.049340675592227407,129.738037518711,0.156656645005322,52.31037672754427,136.13939993989393,0.048162038932670105
0.04985033101450221,129.608863097779,0.15827480097104452,52.25829360102449,136.06990782561658,0.048647612118420884
0.0503626206563637,129.486806372575,0.15990132058395476,52.20908032942224,136.008101281921,0.04913545755486961
0.050870593141556106,129.368173058576,0.16151413322444064,52.16124737721784,135.94920875570523,0.04961895695108376
0.05138055988917511,129.221541605817,0.16313327764813096,52.102125575465415,135.8610167632662,0.05010411949399577
0.051897929991253006,129.082448403262,0.1647759277222283,52.046043196195235,135.781560273594,0.05059608488517163
0.05241083669187631,128.856621056767,0.16640440649670726,51.95498961008846,135.6101043796402,0.051083567253635075
0.052919543754612906,128.659108469453,0.16801955142089597,51.875352534883454,135.4676897895317,0.05156682354192252
0.053435952509356906,128.459338855637,0.16965914921720818,51.79480542659283,135.32368598611018,0.05205715745374939
0.05395274137815131,128.323595178598,0.17129995387563038,51.74007357601071,135.2470049219835,0.05254761171181074
0.054469998698769805,128.221163523005,0.1729422458685941,51.698773132475615,135.20537013325784,0.05303826979585026
0.05497465649066881,128.112700082835,0.17454453435787345,51.65504067339907,135.15565176198095,0.053516744355763875
0.055489542769405605,127.912743328147,0.17617929829286277,51.574418109908876,135.01056296980622,0.05400468088568246
0.05599911576767061,127.700142291161,0.17779719256235418,51.488697371796114,134.85123734287174,0.054487347942498224
0.056520378561541906,127.541447321809,0.17945220193289554,51.42471156015339,134.7501382067246,0.054980846635267366
0.057038646614327206,127.403967269721,0.18109770300048886,51.36927960315151,134.6709171360819,0.05547126876873915
0.057573387527599704,127.264845035014,0.18279550540012904,51.31318551811764,134.5919132768548,0.055977026719641984
0.05810012389502671,127.143233183313,0.1844678933667098,51.26415161951181,134.53027078367776,0.05647496401995463
0.05864401738627491,127.027446457021,0.1861947552014228,51.217466411470866,134.47684623558067,0.05698886033138013
0.05918591802950571,126.946855863562,0.1879152897436806,51.1849722841882,134.46032206880628,0.05750061120050823
0.05971570535662351,126.843511508565,0.18959736450727963,51.14330384025341,134.41806126820995,0.058000669657503424
0.060254113049448305,126.698830694101,0.19130680893199836,51.08496853586153,134.33295636197627,0.058508608685433006
0.06079374942380961,126.559735932184,0.1930201544205955,51.028885527856595,134.2537768055887,0.05901744810914641
0.061337356687336,126.357840190609,0.1947461074822918,50.94748116485354,134.1082961046218,0.059529770155462326
0.0618878165568609,126.191462388478,0.19649381756803336,50.880397635034335,134.00117646381813,0.06004828311282003
0.062430610661234905,126.020153167674,0.1982171888494208,50.81132575720616,133.88766828555424,0.060559312070844445
0.0629849821479365,125.890205443722,0.1999773183196984,50.75893083490871,133.81939778619488,0.06108097145938835
0.06351988387195401,125.725897124239,0.20167563129345398,50.69268172049317,133.71199150926788,0.06158405211896867
0.06406446657528411,125.58567208822,0.20340468137652704,50.6361429859703,133.63125118005036,0.06209597797056538
0.064619074130268,125.430693111802,0.2051655603636009,50.57365546267857,133.53590836820442,0.06261705830677086
0.0651741382398622,125.325849772608,0.2069278889115625,50.53138262831554,133.49385403071616,0.06313829587944933
0.06573410691046391,125.18735539982,0.2087057894407229,50.475541697207426,133.41643440351004,0.06366386396504452
0.06628403286601771,125.037364855127,0.21045180434960623,50.4150655095872,133.32534565666447,0.06417973759434406
0.0668193169563811,124.783435330688,0.21215133133650999,50.312681125333405,133.1213792469553,0.06468162054496986
0.06735649732260901,124.555305140504,0.2138568789992836,50.22069903265122,132.94491421771713,0.06518502834668723
0.06788861633343021,124.335683368522,0.2155463568586409,50.13214753418807,132.77666087328245,0.06568344327660196
0.06842897062478691,124.231356160386,0.21726198173369843,50.09008280386764,132.7323799817625,0.0661893177834439
0.06899308454550081,124.16597531388,0.21905304343196505,50.06372124655642,132.7325689463851,0.06671716293451946
0.06956356405353281,124.099212242542,0.22086431586996666,50.03680237619294,132.73199574236904,0.06725068120436514
0.070130177142847,123.944621319307,0.2226633124285392,49.974471315944584,132.63687956833311,0.0677803019548955
0.07069602105574421,123.757782226946,0.22445986685198785,49.89913779390463,132.50696500507436,0.06830892396685505
0.07125058007377891,123.572041923608,0.22622059173424802,49.82424730359874,132.3766215915664,0.06882673242214819
0.07180798781606411,123.440508837357,0.22799036131600353,49.77121316322235,132.30452339195867,0.06934693076222798
0.07238221048745841,123.36020705863,0.22981351829768043,49.73883548603962,132.2892915317242,0.06988253873728184
0.072963571671581,123.278103919787,0.23165934005726968,49.70573150045812,132.272914690675,0.07042451309236064
0.0735539148263213,123.118974834772,0.23353367957357013,49.64157065338008,132.1748574232728,0.07097456048152732
0.0741373514229149,122.965426913971,0.2353860907677548,49.57966013171311,132.08175798196083,0.07151787564056747
0.0747191698427064,122.793206045018,0.23723336425059283,49.510220677351256,131.96821246302613,0.07205939009558224
0.07529531895016561,122.642811976175,0.2390626376667758,49.44958178879376,131.87724162086627,0.0725953391547663
0.07586461308785791,122.492972269022,0.24087014655394887,49.38916641886967,131.7858542161931,0.07312462955526543
0.07643552422499571,122.316368946643,0.24268278941436136,49.317959959286455,131.66568472837764,0.07365514213632247
0.0770072830563232,122.122093102728,0.24449812370382618,49.23962793901993,131.52638369372045,0.07418616050637604
0.07757149043003911,121.889581475331,0.24628948211537416,49.14587925085346,131.3447379782661,0.0747098892217567
0.07814485083208461,121.684057643243,0.24810990139186861,49.06301204175558,131.19304017641699,0.07524183343407347
0.078715588097374,121.510569434084,0.24992199220916245,48.993061595822674,131.07534536713473,0.07577106311283184
0.07929257913001511,121.350239395603,0.25175393873779794,48.92841652430713,130.97241285532513,0.07630580719318608
0.0798597958411321,121.200887821088,0.25355485179559445,48.868197969462685,130.87996597824403,0.0768312140433375
0.080444967801595,121.02734033868,0.25541277277006413,48.798223624555774,130.7633808353378,0.07737296350815678
0.0810219814937841,120.911450571898,0.2572447912427645,48.75149687058927,130.7079358825209,0.07790687285716072
0.0816017284237903,120.778650145442,0.2590854877455342,48.69795173864222,130.63439675400232,0.07844302433023972
0.08217266679433341,120.574269938392,0.26089821707200855,48.615545639159656,130.4821792460095,0.07897074883336276
0.0827389643969946,120.367045351272,0.26269621196045784,48.53199268563287,130.32609003116232,0.07949390886208482
0.08330738628737021,120.192701998908,0.2645009514624004,48.46169744595971,130.2056418532538,0.08001875626735312
0.0838871607701664,120.069815833679,0.26634173544527834,48.41214974413937,130.1421317781631,0.08055380236869608
0.084475231993434,119.984665177299,0.2682088615791529,48.37781699948696,130.12039760380583,0.08109621284366864
0.08506369673329901,119.85524365893,0.27007723712822435,48.325634243280575,130.05057375742888,0.08163869193588894
0.08566312700520891,119.697546137639,0.2719804282415383,48.26205060269604,129.9512122346394,0.08219097726317301
0.0862564418562876,119.565352688174,0.2738642028937131,48.20875020387176,129.878634580348,0.0827373279424005
0.08685095111747751,119.406934864626,0.2757517697979911,48.14487613741721,129.77754072764145,0.08328447925019489
0.0874545751320315,119.262729848076,0.2776682760442,48.08673267474425,129.69280121602574,0.08383971311477736
0.08804972616050441,119.096835850918,0.2795578805596015,48.01984421509013,129.58327963417386,0.08438685158098624
0.08864943395454901,118.903534905648,0.2814619528056931,47.941905273957275,129.44426597022866,0.08493787656432555
0.0892507721731762,118.694599646658,0.2833712016498344,47.85766257753251,129.28818431790822,0.08549009491869874
0.08983310261898911,118.47754731658,0.2852201008152904,47.770147078045056,129.12075298271648,0.08602456765415596
0.0904275412348785,118.287668888949,0.28710744342073924,47.69358809602424,128.9841319449821,0.08656985900021077
0.0910154355915653,118.079765524135,0.2889740080032198,47.60976145933123,128.82684681786404,0.08710885486410894
0.0916119743849339,117.912965257748,0.2908680186721651,47.54250759192399,128.7152048105924,0.08765547936400815
0.09220097663662001,117.735258468264,0.2927381008212685,47.47085621440405,128.59056428360284,0.08819490492762423
0.09278465483432091,117.572456982347,0.2945912790989689,47.405214655282315,128.4813768214771,0.08872916767350009
0.093381165522833,117.356721874514,0.2964852005349948,47.31823025980404,128.31562934509506,0.08927488172479571
0.09397065101200541,117.162008813733,0.29835681696311717,47.23972195369714,128.1717990558338,0.08981387641141858
0.094562895740412,116.977485986081,0.3002371939758081,47.16532234958786,128.0392157973583,0.09035510160190521
0.095152990175441,116.832176626381,0.3021107438070252,47.10673361575682,127.94910758108642,0.09089407056414277
0.09574846795640071,116.670625292654,0.30400138576157226,47.04159611799809,127.84165891994091,0.09143766214687929
0.09635718966750041,116.48169549982,0.3059340771943138,46.96541962552743,127.70554432588818,0.0919930384122787
0.09695149935405871,116.280448627739,0.3078210104491364,46.88427688670436,127.55401246776091,0.09253496824101487
0.09754257325028971,116.080857481944,0.3096976700696698,46.80380173671982,127.40368302583296,0.09307365633127054
0.098117518546337,115.809740782782,0.31152312138461996,46.694487483617706,127.1727051718831,0.09359736700154814
0.0986806663247312,115.53346554135,0.31331111558102154,46.583093306272325,126.9343849037758,0.09411006570515079
0.0992515025763437,115.318410612883,0.31512352067989124,46.49638315911443,126.76393614092741,0.09462949598832686
0.0998452816889729,115.134615393709,0.31700876936248895,46.42227692674347,126.63026349984544,0.09516951690173807
0.10043838687643,115.054885497584,0.31889187833266525,46.390129832625874,126.6108125992137,0.09570863393496053
0.1010249006121587,114.86220735069,0.32075405944360386,46.3124420037982,126.46615043238661,0.096241473844614
0.10159680594903671,114.598819196369,0.3225698588881915,46.20624389997598,126.24169319225125,0.09676076896281467
0.1021592801318507,114.35590636653,0.324355714418626,46.108301446984896,126.03842343976002,0.09727123761093845
0.10272825066925971,114.065811242095,0.3261621958748996,45.991335092812704,125.7835924921654,0.09778733699658962
0.10330289251103571,113.875550841038,0.32798668372253836,45.91462209910653,125.63922462920475,0.09830831047110251
0.1038965723706407,113.676699147859,0.3298716172767842,45.83444509641675,125.48731854773007,0.0988462590193582
0.10448107086225071,113.556248459631,0.331727399987646,45.78587937892322,125.42072690179306,0.09937560553493231
0.1050799144849807,113.363972610421,0.33362872848981373,45.708353756521745,125.27624915800175,0.09991765315558068
0.10565862760629871,113.165780912517,0.3354661426499984,45.62844286392685,125.12272201572861,0.10044120048921461
0.10624427911166971,112.907395749799,0.33732558617955133,45.52426196631895,124.9031606176124,0.10097074590215106
0.10681196988197571,112.645666966114,0.33912800437527285,45.41873292073716,124.67757255343363,0.10148378372757073
0.1074003607958227,112.382574547285,0.34099614552673707,45.312654057465316,124.45250360082686,0.10201525121110391
0.1079752641246527,112.119580315653,0.3428214635957723,45.20661478327129,124.22572161378085,0.10253426327864526
0.10853838831509671,111.902859533813,0.344609382900432,45.1192329640334,124.04861555546373,0.10304238034071699
0.1090981041184767,111.510739203927,0.3463864805761635,44.961130047023374,123.67634943992533,0.10354716623973573
0.1096492747310917,111.248055880897,0.3481364472712161,44.85521613117767,123.44632452348132,0.10404399668488401
0.1102295049221267,110.978395432425,0.34997867812775224,44.746489038353765,123.21148901799322,0.10456675514319871
0.1108042120217827,110.828727780639,0.35180337316916005,44.68614304115365,123.10901763174937,0.10508426832464947
0.1113865632465707,110.632250013493,0.35365233830786197,44.60692320544038,122.95519612673137,0.10560839185589663
0.11195176599983371,110.365773833284,0.355446857049472,44.49948000958011,122.72141711985837,0.10611681898819897
0.11250978742736571,110.032460906298,0.3572185750818861,44.36508823741935,122.41218969297552,0.10661853270707855
0.11306010241842471,109.745419186427,0.3589658251784984,44.249353015967365,122.1532475195974,0.10711307121138318
0.11359985858262671,109.379760095849,0.3606795509998398,44.10191927064631,121.80528537453908,0.10759788360683442
0.11414322522880571,109.043275060113,0.3624047401014581,43.96624850423756,121.4898261649861,0.10808570166889259
0.1146933090840187,108.760089956024,0.3641512563417594,43.85206827026888,121.23414456935595,0.10857930795891287
0.1152474375105547,108.473153379152,0.36591061409601117,43.736375442474085,120.97440634478863,0.10907629734196081
0.1158018366663317,108.260964188749,0.36767083141560314,43.6508207609036,120.79778268107408,0.10957328248128946
0.1163471082224317,107.931080910414,0.36940206860622066,43.51781182307893,120.48855006166197,0.11006184447281307
0.1168959501513227,107.598402433212,0.3711446417304496,43.383675861071076,120.17621992040671,0.11055336458557712
0.1174436728151257,107.219740529891,0.3728836611880241,43.230999381652055,119.8120206560062,0.11104364159552185
0.11797437929915071,106.889093514955,0.37456865427480346,43.09768250522985,119.4992679762307,0.11151845792215365
0.1185094246395747,106.569821006705,0.37626742323064966,42.96895182990345,119.19934917815206,0.11199692805432185
0.11903563142129471,106.220691513462,0.3779381297626107,42.82818281822788,118.86473859777352,0.11246727102238464
0.11956642149672571,105.89395220529,0.3796233882521041,42.69644152917294,118.55531312862185,0.11294148669165568
0.1201054775658007,105.52521172925,0.3813348912714172,42.5477653692336,118.19936767922383,0.11342285727072104
0.1206188888318417,105.171297625065,0.38296497204109736,42.40506720242621,117.85694268160326,0.11388111200541737
0.12113729469853371,104.7878499369,0.38461091066784453,42.25046109455808,117.48156659553197,0.1143436117899535
0.12164540723645871,104.358271261488,0.38622416797575637,42.07725497263196,117.05297566758453,0.11479672081935707
0.12217281781631571,104.023932555125,0.38789869656680237,41.942449606226404,116.732829515719,0.11526682181388613
0.1226864693557597,103.627938929548,0.38952954020453706,41.78278497639375,116.34168488342851,0.11572444653125102
0.12321615748453271,103.236484166587,0.3912113000133913,41.62495041596788,115.95688705780665,0.11619613941077654
0.1237309041046517,102.832848549479,0.3928456205322691,41.46220453514993,115.55644987216276,0.11665431364898908
0.12423333885751371,102.341044298714,0.394440850872606,41.263909061241485,115.05521393410794,0.11710132677457713
0.12473432575371171,101.870903693318,0.39603148426803464,41.07434836914582,114.57770217942532,0.11754685288183801
0.1252390698410737,101.467151299324,0.3976340467454089,40.91155540388744,114.17480294747483,0.11799551960546897
0.1257324685961267,101.058423877104,0.39920058779270223,40.746756507248335,113.76474898360605,0.11843390699023132
0.1262475861025227,100.645492627168,0.40083608587550956,40.58026262727414,113.3517431234472,0.1188913866329175
0.12676493605896771,100.228476586599,0.4024786719872225,40.41212175971672,112.93393301238697,0.11935063837736999
0.1272800192719147,99.7554870982571,0.40411406118832915,40.221412398017264,112.45236741860252,0.1198076685006553
0.1277822345310107,99.2595937116729,0.40570859463595893,40.021468184546514,111.94320639479072,0.12025307994466478
0.1282672993061077,98.699392914844,0.4072486752968919,39.7955952232651,111.35929748718341,0.12068309247346451
0.1287456873483947,98.1488033024876,0.40876755733115316,39.573597491563,110.78503844608876,0.12110700500943995
0.1292310600117957,97.6033258370231,0.41030861553745135,39.35366097748771,110.21670709561829,0.12153692322843336
0.1297214428393077,97.0942868247343,0.4118655810148019,39.14841644773287,109.68949780309241,0.12197109157380252
0.1301965167183667,96.5537854562716,0.4133739405808143,38.930486295968706,109.12475199865065,0.12239152620422612
0.1306734760462287,95.9882033387632,0.4148882864467761,38.702443586189325,108.5313155284716,0.12281345168995869
0.1311606891448207,95.4194126164431,0.4164351880348057,38.47310716694986,107.93468853300978,0.12324426409311859
0.13161837698352272,94.8265592678151,0.4178883469226846,38.23406869678305,107.30747709357674,0.12364880013624782
0.1320621447656507,94.2759180738906,0.419297309630941,38.01205016739269,106.72619801447937,0.12404087647701165
0.13249358190419372,93.6303525151244,0.420667122545815,37.75175813409816,106.03577329480557,0.12442191116622849
0.13291281533513372,92.9624953089023,0.42199818868904954,37.48247810854941,105.31840228098768,0.12479202880713985
0.1333580998928737,92.3222490292624,0.42341196715987395,37.2243308085986,104.63416873764152,0.12518499556188922
0.1338061653467227,91.6658744162385,0.4248345749758446,36.95968056462736,103.93133356502962,0.12558026066601283
0.1342738279948647,91.0185743746823,0.4263194038836954,36.698689187871906,103.2399867746062,0.12599264705109864
0.1347180181132237,90.3558932491639,0.42772970750948525,36.431496158062885,102.52846011254127,0.1263841778755
0.13516337929034872,89.7083395047864,0.4291437292468572,36.17040248832988,101.83362182277922,0.12677658708538161
0.1355773235816047,88.983574075037,0.4304580023715949,35.87817706705492,101.04772889085598,0.1271411767501704
0.1360008512180467,88.2641555724149,0.43180270261729825,35.588107526797685,100.2681558623054,0.12751406961033962
0.1364093362599347,87.4931352650416,0.43309964262529266,35.277232138864775,99.42801577384662,0.12787358660998954
0.1368222312961197,86.7534687017019,0.43441058436518004,34.97899858052621,98.62327186214684,0.12823685364060647
0.13721872917205372,86.0189575619094,0.4356694651212705,34.682843688961874,97.82236960325943,0.1285855702089047
0.1376083801893047,85.2063844293126,0.43690660710104245,34.355214201898846,96.9314969724175,0.12892814659148624
0.13797319564260072,84.4028262795582,0.43806489616525723,34.031219555917865,96.04815394261612,0.1292487815098702
0.1383285738836777,83.5388360827178,0.4391932220806767,33.68285870855182,95.09464414194247,0.12956102327739147
0.1386831435232017,82.6992699335803,0.44031898068616543,33.344345637219575,94.168264655043,0.12987245746078127
0.1390455056834057,81.7977240975837,0.4414694805448131,32.98084235614574,93.17133000848392,0.13019063597900582
0.1394150025181337,80.9162485375997,0.4426426329950745,32.6254314103602,92.1971875312271,0.13051497501111733
0.1397974500351097,80.0154751285771,0.4438569038614733,32.26223957184229,91.20143451489992,0.1308505712124605
0.14018511452391472,79.1642717291415,0.4450877386134292,31.91903436118986,90.26192422769351,0.13119063038533912
0.14051287849232572,78.2556408563989,0.44612838921313414,31.552674393300038,89.25156621139315,0.13147805464902598
0.1408329137750047,77.1747436128913,0.4471445012356399,31.116856624717776,88.04348762573372,0.1317586217475018
0.1410894647422047,76.1987053372324,0.4479590505564999,30.723317991972102,86.9495398873115,0.13198347687026699
0.1413392817361117,75.1686855839293,0.44875221951215466,30.308014027440294,85.79297361340949,0.1322023813993043
0.1415979400461507,74.2687996617167,0.44957345964652845,29.945180023604177,84.78510870351603,0.13242898273435447
0.14186037758518671,73.1995381266667,0.4504066988329678,29.514053772672014,83.5836522443769,0.13265884245035212
0.14211368407576772,72.0279759398908,0.45121094694056246,29.041679898963967,82.26413695722944,0.13288065450668987
0.1424015595305917,70.6196124630489,0.4521249515096286,28.473827745101318,80.67595541123306,0.1331326777375729
0.1426858016458437,68.9099006348472,0.45302742022555376,27.78447193597039,78.74236504826581,0.1333814578249755
0.1428400107980387,68.0848270771613,0.4535170342837729,27.451802277511433,77.81006451204561,0.1335164019604471
0.14290880621902272,67.5616653661771,0.4537354597453971,27.240863475642605,77.21682230982655,0.13357659704443228