File: example/data/02 processed data/test_ID_110.csv
Strain,Stress_MPa,Displacement(mm),Force(kN),True Stress (MPa),True Strain
0.00018298131760800042,0.218924981318501,2.5995349482358344e-05,0.0441352762338098,0.2189267737693356,8.18747813050404e-06
0.00019709578611410043,0.676133632029286,7.080878698942974e-05,0.136308540217104,0.6761487111481291,2.2301731468720435e-05
0.00020131032790730044,1.19976708294294,8.418995718286958e-05,0.2418730439212967,1.1997988965931266,2.651617039054175e-05
0.00022009454491280043,1.82084959690805,0.0001438298461751,0.3670832787366629,1.820932082740312,4.529971290521489e-05
0.0002483372152440004,2.84480500072767,0.0002335003244768,0.5735126881466983,2.845014217386172,7.354070510006272e-05
0.00027053434418590044,4.09673533334703,0.0003039762088673,0.8259018432027613,4.097127556992814,9.573595539320647e-05
0.0002957370520642004,5.81033658392972,0.0003839948063808,1.1713638553202317,5.811039304897139,0.0001209359330594
0.0003211427096142004,7.62614732392903,0.000464657769102,1.5374313005040925,7.627263402228992,0.000146338195698
0.00034216146188390044,9.4822042485188,0.0005313923075583,1.9116123765013904,9.483791262816869,0.0001673536515203
0.00037289034146650044,11.4071688251207,0.0006289565002331,2.299685235144333,11.409428545744891,0.0001980769169785
0.00040195237535950044,13.3566788612264,0.0007212284578434,2.692706458423242,13.359712945288445,0.0002271327727983
0.00041506389205300044,15.388528922267,0.0007628575233452,3.1023274307290274,15.392226325436,0.0002402412258586
0.0004327083223314004,17.5279252961779,0.0008188785894791,3.5336297397094647,17.53244600255366,0.0002578812621403
0.00046226453357270045,19.5213257979203,0.0009127195601703,3.935499280860733,19.52693760765139,0.00028742941582
0.0005037013734571005,21.5302841073622,0.0010442815268032,4.340505276044219,21.53736558073547,0.0003288534892605
0.0005421641182228004,23.6680864854271,0.0011664007414343,4.771486235462104,23.67678143774992,0.000367302848312
0.0005807412573779004,25.9098642636401,0.0012888831582518,5.223428635549844,25.92038230700451,0.0004058650770436
0.0005977231895319005,28.1641824568665,0.0013428007928407,5.677899183304286,28.176093917191785,0.0004228399741484
0.0006317902278874005,30.522198768685,0.0014509636396194,6.153275271766896,30.536147304311648,0.0004568920308656
0.0006723361709983004,32.861842220713,0.0015796970089966,6.624947391695741,32.87819237941101,0.0004974186318758
0.0007056606041927004,35.2203785136794,0.0016855020843888,7.100428308357768,35.2390758432535,0.0005307259383036
0.0007332651613614005,37.643853171341,0.0017731465533994,7.589000799342346,37.66487618504413,0.0005583154683103
0.0007588933419858004,40.0436555360024,0.0018545160268819,8.072800956058083,40.06704501662176,0.0005839290162888
0.0007839002605999004,42.4790470260639,0.0019339129934816,8.563775880454484,42.50492128779443,0.0006089210245972
0.0008277013742287005,44.9933201521109,0.0020729815292531,9.070653342665558,45.02269663135974,0.0006526945168524
0.0008665844898174004,47.4613419796809,0.0021964354212472,9.56820654310367,47.49417529390582,0.0006915515069828
0.0009048056420839004,50.0409590181677,0.0023177875796933,10.088257338062608,50.07748951054195,0.0007297455070912
0.0009363373248674004,52.5856851659772,0.0024179006725309,10.601274129461004,52.62573145370266,0.0007612536917765
0.0009717218141722004,55.1607605415158,0.0025302464260737,11.120409325169586,55.20471969654562,0.0007966106296945
0.0010059141951864004,57.7111282994326,0.0026388072357938,11.634563465165613,57.75909319484752,0.000830775199925
0.0010431062481397004,60.2700344003812,0.0027568920039205,12.15043893511685,60.32236762114165,0.0008679356770152
0.0010767328294175003,62.7909486756447,0.0028636563994775,12.658655253009972,62.84758228257518,0.0009015325208651
0.0011164055323841003,65.2628384356901,0.0029896172313965,13.156988228635123,65.32429068966086,0.0009411686881938
0.0011489544309316005,67.6821449958493,0.0030929599842848,13.644720431163218,67.74807827651787,0.0009736864384408
0.0011943627647736004,70.164446558763,0.0032371314442331,14.145152426246623,70.23598405048665,0.0010190495514004
0.0012353564213603003,72.5926799674501,0.0033672863038959,14.63468428143794,72.6696690499753,0.0010600006161915
0.0012806317804747004,75.1043699251076,0.0035110355690841,15.141040976901692,75.1874231894228,0.0011052269860965
0.0013168889651224004,77.5501264401143,0.0036261521303406,15.634105490327045,77.63869606411397,0.0011414434646369
0.0013628904713653004,80.0047725578307,0.0037722069126618,16.12896214765867,80.09982596132316,0.001187391437093
0.0014014800039405004,82.5233767739586,0.003894728678588,16.636712757630054,82.62460706125798,0.0012259344331899
0.0014493880964382003,85.0158401065257,0.0040468368722682,17.13919336547558,85.12420081092569,0.0012737826847476
0.0014941657360435004,87.5126706677271,0.0041890058780151,17.642554406613783,87.62813242893273,0.0013185023237439
0.0015323552936294005,90.022513242435,0.0043102577233503,18.14853866967489,90.14472433943612,0.0013566408342078
0.0015718681713926003,92.4399483968139,0.0044357111102485,18.635893596797683,92.569093879061,0.0013960993650343
0.0016187625942743005,94.8521687996645,0.0045846009028979,19.12219723001236,94.98913237091512,0.0014429272678782
0.0016572645399381004,97.2801968990035,0.0047068445803804,19.611687694839105,97.42441194390187,0.0014813729590516
0.0016979906242523004,99.656611714222,0.004836149898078,20.09077292158716,99.80840834810688,0.0015220379306786
0.0017345097789030004,102.049688921973,0.004952098214094,20.57321728666976,102.20885745181847,0.0015585008792881
0.0017666962533309004,104.35660941139,0.0050542902704026,21.038292457336222,104.52273495331131,0.0015906367137748
0.0018092530467097004,106.69280910962,0.0051894080893802,21.5092703164994,106.86719415739076,0.0016331249659256
0.0018466559437921005,109.080406239537,0.0053081622876169,21.99060989789066,109.26277364070822,0.0016704661320642
0.0018900827379536005,111.460154531405,0.0054460423590796,22.47036715353125,111.651340900831,0.0017138195040225
0.0019232494479428004,113.810417968118,0.0055513466632953,22.944180262372587,114.0094104355308,0.0017469288728166
0.0019601751309443003,116.18598891923,0.0056685857068251,23.42309536611677,116.39342521407124,0.0017837894262291
0.0020026968805249004,118.555312650615,0.0058035922617435,23.90075103036398,118.77202027111504,0.0018262344927676
0.0020413554291693003,120.955642795419,0.0059263331536895,24.38465758755647,121.18141395637151,0.0018648217617652
0.0020823469618629006,123.338358460492,0.0060564812699917,24.86501306563519,123.5736329354172,0.0019057360867853
0.0021296101466804006,125.681598773751,0.0062065418817872,25.3374103127882,125.9272832167618,0.0019529081735969
0.0021695634256581006,128.02250436315,0.0063333935425414,25.80933687961104,128.27787976549126,0.0019927827086279
0.0022105119253282004,130.349274418379,0.006463405028994,26.278413722745203,130.61462879815898,0.0020336488530568
0.0022580376630853003,132.673032520961,0.0066142992463728,26.746883356225737,132.94942280096646,0.0020810769136336
0.0022950934017717003,134.930361880515,0.0067319512167021,27.201960955111826,135.21645467227296,0.0021180549329687
0.0023366913195360006,137.185441823737,0.0068640246056038,27.656585071665376,137.48202268931456,0.0021595639757875
0.0023720174334887004,139.399398933598,0.0069761850174036,28.10291882501336,139.70569058659822,0.00219481326179
0.0024113139528872006,141.607560700073,0.0071009514664938,28.54808423713472,141.92426886253594,0.0022340228585407
0.0024477823601276004,143.77357193104,0.0072167386594821,28.98475210129767,144.10036761443106,0.0022704092234706
0.0024942448070134006,145.897165246137,0.0073642569283445,29.41286851362122,146.23556657211802,0.002316765226793
0.0025292803924571003,147.929210923947,0.0074754949121282,29.822528922267715,148.27750826681853,0.0023517191260684
0.0025719219672697005,149.984671993292,0.0076108819121582,30.236909873847672,150.34420447429193,0.0023942596328379
0.0026135908709873003,152.022788691312,0.0077431806814616,30.6477942001685,152.39354142218963,0.0024358280257414
0.0026548573282161006,154.054244999384,0.0078742016831631,31.05733579187581,154.43630931285568,0.0024769932400012
0.0027052942187607005,156.057788800321,0.0080343388106422,31.46125022214472,156.45269309930097,0.0025273040876968
0.0027448251386366002,158.026381388723,0.0081598494812482,31.85811848796656,158.4325141402815,0.0025667344496714
0.0027787552473197003,159.996100530732,0.008267577576317,32.255213866995575,160.41272420728197,0.0026005770077822
0.0028204638721115003,162.048868122444,0.008400002460031,32.66905181348471,162.47759596208925,0.0026421764417303
0.0028609383769682005,164.002244165347,0.008528509012951,33.06285242373396,164.44277790314493,0.0026825433322039
0.0029020370879794003,165.909564815395,0.0086589974204115,33.44736826678363,166.36204056146053,0.0027235311018735
0.0029493370596799006,167.824634537334,0.0088091748305606,33.83344632272653,168.29027124489755,0.0027707013133655
0.0029783803219371003,169.734842853573,0.0089013871882272,34.21854431928032,170.21070917028877,0.0027996637973776
0.0030186435724251005,171.62798326163,0.0090292230085266,34.600201425544604,172.11606746174746,0.0028398136759307
0.0030708558611892006,173.503143279079,0.0091949970253527,34.97823368506233,174.00561914879253,0.0028918765465632
0.0031205203851696005,175.275824340599,0.0093526818889904,35.33560618706476,175.792138995052,0.002941396428213
0.0031686493275451004,177.095427558598,0.0095054912810326,35.70243819581336,177.6256256822418,0.0029893828609193
0.0032139172875854005,178.857240335327,0.0096492170541606,36.057619651601925,179.4008095742888,0.0030345146813048
0.0032611911017467006,180.538334283165,0.0097993114141227,36.39652819148606,181.0955473098824,0.0030816441492074
0.0033195708110137006,182.11185056168,0.0099846669910454,36.71374907323469,182.68455172167413,0.0031398425363438
0.0033862982028430005,183.670786923776,0.0101965264601035,37.02803064383325,184.26064646356068,0.0032063585310078
0.0034449570295732005,185.131909797926,0.0103827682349719,37.32259301526188,185.73732136086448,0.0032648278683494
0.0035157101588620004,186.473501710852,0.0106074094204638,37.59305794490776,187.09649408210063,0.0033353478909269
0.0035874938220342005,187.666888774512,0.0108353225510355,37.83364477694162,188.30733956884936,0.0034068899702508
0.0036796236631543005,188.749989879544,0.0111278347965919,38.05199795971607,189.4115264796189,0.0034987022543267
0.0037763600731751004,189.670142584419,0.0114349728984079,38.23750074501888,190.3532521718489,0.0035950961577914
0.0038816342953131005,190.453500337747,0.011769218553696,38.39542566808979,191.15948108413795,0.0036999870872371
0.0040000883895387005,191.0477452499,0.0121453103028623,38.51522544237984,191.77855915500936,0.0038179967492431
0.0041320530236452005,191.486153867714,0.0125642980161505,38.60360861973114,192.2439142151661,0.0039494498630745
0.0042699423001578,191.821957638412,0.013002096469078,38.671306659903856,192.607497039389,0.0040867861957316
0.004425616705980901,192.028994351551,0.0134963627075663,38.71304526127268,192.84527559820856,0.0042418136744153
0.0045824690921848,192.128361877529,0.0139943690337637,38.73307775450984,192.97520130995943,0.0043979899350035
0.0047504526840394,192.145019792861,0.014527716937902,38.73643599024078,193.02420985855497,0.0045652223748047
0.0049248423493371,192.129793362216,0.0150814041252222,38.733366341822745,193.0424192073156,0.0047388026610584
0.0050946131484186,192.078924015572,0.015620426412306,38.72311108153932,193.02391762122247,0.0049077565795087
0.0052704979160572,191.966533644149,0.0161788605495586,38.70045318266044,192.9447382986406,0.0050827649473897
0.005454896725409501,191.825844972091,0.0167643267692521,38.67209034637355,192.83870517615404,0.0052662120513836
0.005628632305906201,191.715213322203,0.0173159372373291,38.64978700575613,192.76079713364504,0.0054390201761685
0.005815730587560101,191.605540467292,0.0179099742815803,38.62767695820607,192.68637520807232,0.0056250862775709
0.0060053757868494,191.510322263457,0.0185120977893238,38.60848096831293,192.62693889760064,0.0058136499217312
0.0061916730181904005,191.375998117,0.0191035914988315,38.5814012203872,192.52748438179,0.0059988500777737
0.006384483403617301,191.231408743849,0.0197157644725619,38.55225200275996,192.41889643347105,0.0061904889210389
0.006584795346912701,191.145198395388,0.0203517548925248,38.53487199651023,192.37043941164816,0.0063895448528066
0.006783865048678301,191.070802240701,0.0209838011956306,38.51987373172532,192.3336027851132,0.0065873270845856
0.0069842348770484,190.986506914623,0.0216199754007056,38.502879793988,192.2870182788312,0.0067863615404686
0.0071817524666241,190.861727951835,0.0222470937476085,38.47772435508994,192.1990881894964,0.0069825240011928
0.007371782048464901,190.76178378164,0.022850437669953,38.45757561037862,192.1346940966357,0.007171213515675
0.007562431961497501,190.681771307414,0.0234557511438315,38.44144509557466,192.09045923669007,0.0073604832153477
0.0077566100672764,190.628321167382,0.0240722666296795,38.430669547344216,192.0736300726763,0.0075532187488361
0.0079509431692538,190.586782451806,0.0246892742284578,38.42229534228409,192.0688137388208,0.0077460709427335
0.0081390714428227,190.523980819197,0.025286581497039,38.40963453315012,192.0413666989214,0.0079327301688871
0.0083383776301583,190.454860026747,0.0259193786418296,38.3956997813922,192.0096542413013,0.0081304420221823
0.0085368744261636,190.422493266387,0.0265496059691464,38.38917464250362,192.0148215069807,0.0083273121142881
0.0087434766996099,190.368868852515,0.0272055681873384,38.37836396066702,192.00007932253504,0.0085321801027252
0.0089521240341355,190.294803898362,0.0278680234744572,38.36343246590978,191.96508423288384,0.0087390333980076
0.0091591360088798,190.194872469735,0.0285252864942703,38.34328628989858,191.90364828924385,0.0089442231171891
0.0093562317505829,190.110314850293,0.0291510654741777,38.32623947381907,191.8558009087237,0.0091395447743775
0.0095592203374663,190.065821791931,0.0297955542375325,38.31726967325329,191.8494805326877,0.0093406663638585
0.0097659722372697,190.000683220934,0.0304519915194082,38.3041377373403,191.8230136757768,0.0095454750797416
0.0099718743789713,189.943764806807,0.0311057308193108,38.29266298505229,191.8046591749604,0.009749400344234