File: example/data/02 processed data/test_ID_061.csv
Strain,Stress_MPa,Displacement(mm),Force(kN),True Stress (MPa),True Strain
0.00018679333539860043,0.516839889364162,4.947828816757519e-05,0.104194921695815,0.5168479436485659,1.558359138384018e-05
0.00018843091079430042,0.582722811435279,5.467759004887188e-05,0.1174769187853522,0.582732846672758,1.7221139919679697e-05
0.00019609884376980044,0.624914068895418,7.902327724629425e-05,0.1259826762893162,0.6249296225198971,2.4888911448298454e-05
0.00020530219704680043,0.735009498455341,0.0001082439239007,0.1481779148885967,0.7350345568213936,3.409199331824829e-05
0.00021261426428480045,1.45636092991663,0.0001314597373812,0.2936023634711926,1.4564212300191115,4.140378454625847e-05
0.00022925247584650043,2.92677662786063,0.0001842860590895,0.590038168176703,2.926946506326956,5.804116883538408e-05
0.0002521986874815004,5.23867425370585,0.0002571402810309,1.0561167295470992,5.239098529034929,8.098578545437188e-05
0.0002810972607502004,8.33143910550226,0.0003488932511589,1.6796181236692558,8.33235462766804,0.0001098816009559
0.0003326487132279004,12.3263568244611,0.0005125691127756,2.484993535811358,12.32834678029772,0.0001614260607502
0.00038256827880240045,17.2839600364567,0.0006710637334746,3.48444634334967,17.287613151024036,0.0002113363231184
0.00043841441976450043,23.0177794967713,0.0008483752310293,4.640384346549094,23.023929957873143,0.0002671691043308
0.0005210814689838004,29.1436794113244,0.0011108431123006,5.875365769323,29.15387596425075,0.0003498106555116
0.0006054628189819004,35.5009426641632,0.0013787538985446,7.156990041095301,35.51635906199004,0.0004341589357602
0.0006946066656895004,41.9670175146099,0.0016617856118412,8.460550730945355,41.98898292748476,0.0005232601186423
0.0008010548095692005,48.6858562801592,0.0019997584686592,9.815068626080096,48.71652083241122,0.0006296469177477
0.0008960826996215005,55.4581964877506,0.0023014720195753,11.18037241193052,55.49839664128529,0.0007246104834329
0.0010042444951574004,62.2896618685079,0.0026448857204018,12.557595832691192,62.34155132904481,0.0008326880915918
0.0011195719767681004,69.3117261365403,0.0030110504745157,13.973243989126525,69.3774587683113,0.0009479129427149
0.0012276483563402004,76.3850119556188,0.0033541929796572,15.39921841025275,76.4657080409267,0.0010558810950574
0.0013393923177637003,83.5102792894087,0.0037089800571768,16.835672304744794,83.60783455254371,0.001167500900691
0.0014577179486101005,90.6659451698135,0.0040846639351141,18.2782545462344,90.78258766316095,0.0012856814832679
0.0015697815759281005,97.8029159440501,0.0044404659518487,19.7170678543205,97.93970035924414,0.001397594862499
0.0016857172213139004,104.973021134097,0.0048085616259487,21.16256106063395,105.1320035722656,0.0015133618887357
0.0018031037628823004,112.145710200606,0.0051812638954283,22.60857517644217,112.32872012794132,0.0016305640478998
0.0019178938460023005,119.279337134715,0.0055457224093343,24.046714366358547,119.4876804710673,0.0017451605445234
0.0020360943968740003,126.391533093461,0.005921009158352,25.48053307164174,126.62723873912545,0.0018631480355499
0.0021568177214288005,133.484577967839,0.0063043057138135,26.91049091831634,133.74962602692202,0.0019836393847102
0.0022759013175921005,140.54464041914,0.0066823961316319,28.333799508498625,140.84044355660723,0.002102479934276
0.0023957377487258003,147.537826067888,0.0070628768004814,29.743625735286223,147.86602811164497,0.0022220575267108
0.0025154217502052004,154.515812443329,0.0074428735051785,31.150387788575127,154.878030284767,0.0023414687489036
0.0026362371187980006,161.390443760279,0.0078264623004607,32.53631346207225,161.7882756417733,0.0024619942995158
0.0027597465240176006,168.242276167269,0.0082186046620329,33.917642875321434,168.67777750750818,0.0025851924100989
0.0028796313059321005,175.046990827005,0.0085992388446114,35.289473350724215,175.52109189256467,0.002704760518497
0.0030017163937660005,181.758989919566,0.0089868589984841,36.64261236778451,182.27345997125545,0.002826508429996
0.0031239407419692005,188.413231773558,0.0093749213040292,37.98410752554929,188.96956538631864,0.0029483803711367
0.0032469779749873004,194.985397551691,0.0097655645188617,39.30905614642091,195.5851274666601,0.0030710478538816
0.0033730054102677006,201.528684710539,0.010165701625877,40.628182837644665,202.17393840434144,0.0031966809544044
0.0034938662857344005,207.947337828267,0.0105494349054837,41.92218330617863,208.63827543588528,0.003317148836533
0.0036185642497623006,214.245916686866,0.0109453509412723,43.19197680407218,214.98449833910928,0.0034414261214105
0.0037448420018822005,220.435060777651,0.011346282804253,44.439708252774444,221.22281464837727,0.0035672621272161
0.0038710012536917002,226.526929519269,0.0117468384287482,45.66782899108463,227.3650319573236,0.0036929642368207
0.0039966405343114,232.450086327174,0.0121457431447157,46.86193740355828,233.3393080728424,0.0038181325578689
0.004130474078345301,238.225810183997,0.0125706646470233,48.0263233330938,239.169009166702,0.0039514471951811
0.004263278478999901,243.752265958579,0.0129923186191017,49.14045681724952,244.74971701478745,0.0040837191133786
0.004408297233874101,249.182966311323,0.0134527531658273,50.23528600836272,250.23877637082376,0.0042281364312863
0.0045625339693711,254.344639526526,0.0139424548010303,51.275879328547646,255.46154933455213,0.0043817106164187
0.004730455441059201,259.217526548888,0.01447560547364,52.25825335225581,260.39936297287994,0.0045488839402157
0.004919837915681201,263.716511447888,0.0150768948305648,53.16524870789423,264.9688031355048,0.0047373891241378
0.0051374240336284,267.794476476271,0.0157677307550472,53.98736645761623,269.124401264544,0.0049539234445039
0.005378458099738,271.361745921525,0.0165330139149452,54.70652797777944,272.77479395973114,0.0051937376413529
0.0056526247620362,274.38032160038,0.017403493067742,55.31507283463662,275.88431404916645,0.0054664468568155
0.005954441365562101,276.795486128931,0.0183617607839367,55.80197000359249,278.3962585706232,0.0057665730547869
0.0062795395624864,278.695395292359,0.0193939475591713,56.184991690939576,280.39775871953464,0.0060897497169345
0.006626237655091601,280.111967564612,0.0204947140031928,56.47057266102577,281.9200981674808,0.006434283561955
0.0069873385317106,281.127279021548,0.0216412092864582,56.67525945074408,283.0434787952292,0.0067930041240075
0.007357527533052301,281.84772457632,0.0228165593657181,56.820501274586114,283.8731719274659,0.0071606193730309
0.0077338327720034,282.376659287419,0.0240113284993878,56.92713451234366,284.51216754780006,0.007534169879159
0.0081190993246582,282.800719012696,0.0252345498040668,57.01262495295951,285.0483879350745,0.0079164715887166
0.0085048688922237,283.162461717413,0.0264593681810873,57.08555228223047,285.52224119131665,0.0082991260572547
0.0088929197004486,283.489246093523,0.0276914294972013,57.15143201245424,285.96175710814146,0.0086838956762841
0.0092832467372198,283.779552213695,0.0289307178389499,57.20995772628092,286.36536202583926,0.0090707729818924
0.0096737068516075,284.069858333866,0.0301704287021308,57.2684834401074,286.76923137553104,0.0094576324962914
0.0100664271933384,284.317606488778,0.0314173157871264,57.31842946813764,287.1309910641789,0.0098465804918285