File: example/data/02 processed data/test_ID_148.csv
Strain,Stress_MPa,Displacement(mm),Force(kN),True Stress (MPa),True Strain
-0.00023110949657829957,0.109391525355271,0.0002141678251083,0.0220533315116226,0.1093989042986003,6.745215815699335e-05
-0.00023365174160279957,0.0901036196821974,0.0002060961971557,0.0181648897279309,0.0901094685053049,6.491008137555419e-05
-0.00022198925664689958,0.0620485212346953,0.0002431245868908,0.0125089818809145,0.0620532725799212,7.657174134584171e-05
-0.00020621749436719957,0.028991408844156,0.0002931999321287,0.0058446680229818,0.0289940860974175,9.234217164662288e-05
-0.00019060456344229958,-0.0273938310112417,0.0003427709878151,-0.0055225963318663,-0.0273967884318765,0.0001079535390479
-0.00016446905513829957,-0.100760262041888,0.0004257512266803,-0.0203132688276446,-0.1007737734765856,0.0001340858846309
-0.00013731424919989957,-0.188790134270027,0.0005119677355347,-0.0380600910688374,-0.1888205766188564,0.0001612366811511
-0.00010229410030099957,-0.288173339113896,0.0006231567082888,-0.0580957451653614,-0.2882298988459963,0.0001962505709791
-7.280041474348926e-05,-0.355117728658692,0.0007167991599341,-0.0715917340975923,-0.3551979012853314,0.0002257380341925
-5.487101970588925e-05,-0.185574050874708,0.0007737249891785,-0.0374117286563411,-0.185619273955182,0.0002436632216835
-2.3994072929589235e-05,0.167036475952585,0.0008717592951933,0.0336745535520411,0.1670823391338599,0.0002745321693491
2.0308097670810753e-05,0.925633317870385,0.0010124186868495,0.1866076768826696,0.9259284764430408,0.0003188211984742
6.594930723591075e-05,1.92410285038341,0.0011573295272187,0.3878991346372954,1.9248042113415689,0.0003644468181091
0.00010433384272270044,3.3079620328949,0.0012792004273893,0.6668851458316118,3.309294803429158,0.0004028166308924
0.00012842812525610042,4.89840562014773,0.0013556997744329,0.9875185730217824,4.900497200429404,0.0004269009197738
0.00017434052749600043,6.70262969617335,0.0015014716515445,1.3512501467485474,6.705799399631493,0.0004727926731073
0.00024203290433980044,8.62110797911497,0.0017163949480236,1.738015368589578,8.625768522794253,0.0005404507641957
0.00030102141396300044,10.6672369715668,0.0019036834660773,2.150514973467867,10.673632890512154,0.0005994056641728
0.0003375343016203004,12.6035963537987,0.0020196118843892,2.540885024925818,12.611613479147415,0.0006358960065756
0.00035440022254320044,14.6187646364866,0.0020731611833194,2.947142950715699,14.628310165744065,0.0006527510638888
0.0003902725121141004,16.5820777375315,0.002187055702707,3.34294687188635,16.593500076957827,0.0006885993028693
0.00044788731624560046,18.6793236462075,0.0023699827058245,3.765751647075432,18.69326685061632,0.0007461727897583
0.0004968903656936005,20.8286761842198,0.0025255673878219,4.199061118738711,20.84524444415755,0.0007951380892828
0.0005192377586637004,22.9247532264514,0.002596520360502,4.621630250452602,22.94350112834493,0.0008174674707497
0.0005347112353646004,25.0588485205942,0.0026456486490274,5.051863861751791,25.07972943673111,0.0008329281840379
0.0005810124074733004,27.1775914433925,0.0027926548704725,5.479002434987929,27.201496209727026,0.0008791897365701
0.0006360632605172004,29.2771755416195,0.0029674413288869,5.902278589190492,29.304538785932973,0.0009341906981587
0.0006743039381661005,31.3694567283381,0.0030888554804221,6.324082476432961,31.399975064821,0.0009723949386123
0.0007013320102178004,33.4112094947742,0.0031746696091863,6.735699834146478,33.44461722749521,0.0009993963769354
0.0007380876054731005,35.4171293114721,0.0032913686241218,7.140093269192776,35.45384453294368,0.0010361145830099
0.0007769596937452004,37.4130411540919,0.0034147875043858,7.542469096664927,37.45327976367743,0.0010749456622664
0.0008231316138234005,39.3020121572954,0.003561383350634,7.923285650910754,39.346097049183086,0.0011210669131045
0.0008506982892277005,41.1862469428927,0.0036489075450427,8.30314738368717,41.23358074044291,0.0011486023226347
0.0008801324422153005,43.075646500015,0.0037423609807783,8.684050334403024,43.12641960826176,0.0011780022547122
0.0009280271902999004,44.914095334485,0.0038944268059469,9.054681619432175,44.96918656498436,0.0012258394716761
0.0009700747683026004,46.7021805092696,0.0040279278661055,9.415159590668752,46.76142870274399,0.0012678346558672
0.0010015263400554005,48.4521955616082,0.0041277866064206,9.767962625220212,48.515187789605335,0.0012992458841565
0.0010453685508836005,50.1865905597781,0.0042669856258002,10.117616656851265,50.25403794892031,0.0013430302116128
0.0010838829847630005,51.8912580567675,0.0043892689533673,10.461277624244328,51.96299496635481,0.0013814922144907
0.0011310751928233003,53.5382260398919,0.0045391042139587,10.793306369642208,53.61476638238813,0.001428618161451
0.0011750836247290005,55.1508054330462,0.0046788309852593,11.118402375302114,55.23207828259648,0.00147256280142
0.0012130382540840004,56.7080369340562,0.0047993369334614,11.43234024590573,56.79375692652288,0.00151046086319
0.0012576171911183004,58.2182569283852,0.0049408750585453,11.736800596762455,58.30885508070315,0.0015549715256982
0.0013102739596552004,59.7216564670194,0.00510806029865,12.039885943751113,59.817738930757606,0.0016075450960723
0.0013611605444004003,61.1313882755369,0.005269625205216,12.32408787634824,61.23284953679252,0.0016583486535304
0.0014081275330659004,62.5404118008756,0.005418745394229,12.60814701905652,62.64714898777298,0.0017052367198377
0.0014683601037408004,63.9279075267561,0.0056099838061218,12.887866157394033,64.04086328297164,0.0017653648595119
0.0015380553269240004,65.2470544848926,0.0058312661397284,13.153806184154348,65.36688848159648,0.0018349347336967
0.0016082852060612005,66.5454125388689,0.0060542460059891,13.415555167835972,66.67230460125641,0.001905033406779
0.0016813144303383005,67.8073934906461,0.0062861137930688,13.669970527714256,67.94164388166772,0.0019779209840133
0.0017496240429157005,69.008809309834,0.0065029968130021,13.912175956862535,69.1501523230658,0.002046093295321
0.0018365662574578005,70.1803912727736,0.0067790383441733,14.148366880591158,70.3302355447255,0.0021328540360267
0.0019277789459399004,71.31706080688,0.0070686386301039,14.377519458667008,71.47583703711778,0.0022238682465579
0.0020227954065677005,72.3886118919028,0.0073703158925972,14.593544157407605,72.55665187195632,0.002318669144131
0.0021238675748986003,73.4107451592808,0.0076912200270478,14.799606224111008,73.58857766112948,0.0024195021472094
0.0022256451688836003,74.3514812904391,0.0080143638879502,14.989258628152523,74.53915997600437,0.0025210286337616
0.0023341043751649005,75.2271906199072,0.0083587218678933,15.165801628973291,75.42523886031502,0.0026292089039531
0.0024589565146905003,76.0949060921072,0.0087551274108871,15.340733068168811,76.3047393513689,0.0027537254597709
0.0025787758577422003,76.8845446934681,0.0091355538250762,15.499924210203169,77.10576765295271,0.0028732081687824
0.0027178952649592005,77.5464713610809,0.0095772579429902,15.63336862639391,77.78038712763014,0.0030119188099048
0.0028542317444088003,78.1729067883082,0.0100101262652427,15.759658008522932,78.4193699906616,0.0031478360355612
0.0029829244814719006,78.7267866907184,0.010418725705418,15.87132019684883,78.9851277288915,0.0032761160776841
0.0031240446068460004,79.2196713319229,0.0108667821034808,15.970685740515655,79.49080925528459,0.0034167647421497
0.0032893782465819002,79.6645912863158,0.0113917164096423,16.060381603321265,79.9504232333469,0.0035815208666764
0.0034499418359473003,80.0067385782771,0.0119015058058774,16.129358497380665,80.30664429912709,0.0037414976258018
0.0036106268495834006,80.3183518405033,0.012411680724172,16.192179731045464,80.63233160092409,0.0039015697479127
0.0037619057875268006,80.6275167945839,0.0128919913521423,16.254507385788113,80.95490238490216,0.0040522482578581
0.003925359860248001,80.8688985177728,0.0134109580330321,16.303169941182997,81.21048258208756,0.0042150280649517
0.0040794100907715,81.0665376015356,0.0139000675149443,16.34301398046958,81.42144479708335,0.004368418571048
0.004253001875108301,81.2252555333471,0.0144512214302136,16.375011515522775,81.59495762891814,0.0045412387534661
0.004422779381137701,81.3721047340581,0.0149902650118569,16.40461631438611,81.75629037643168,0.0047102327270207
0.0045837100331295,81.4972352977236,0.0155012198319309,16.42984263602108,81.89512712765892,0.0048703943140646
0.0047582471430491005,81.61209377905,0.0160553751559256,16.45299810585648,82.02479071854079,0.0050440683439471
0.004935841039616201,81.7165035442212,0.0166192357775262,16.474047114514995,82.14424081644685,0.005220753090527
0.005088306054399701,81.7928268004543,0.0171033121994638,16.48943388297159,82.23343412405899,0.005372412696416
0.0052787182463018,81.855299694786,0.017707870908753,16.502028418468857,82.31182979878365,0.0055617867260491
0.005448277849318001,81.9049163337345,0.0182462226483294,16.512031132880878,82.37561092882683,0.0057303916777806
0.0056190217881118,81.9397737898788,0.0187883346539997,16.519058396039565,82.42465942497715,0.0059001455759655
0.0058050493163620005,81.9519961035511,0.0193789720561941,16.5215224144759,82.4521993925086,0.0060850616482974
0.005979038444933901,81.9582099542833,0.0199313875394099,16.522775126783515,82.47271100771171,0.0062579803057117
0.0061623252831495,81.9554669257575,0.0205133232507444,16.522222132232713,82.4849721179508,0.0064401071338994
0.0063581063457141,81.9639922749185,0.021134928124387,16.52394084262357,82.50959954594785,0.0066346124793613
0.006551071314970201,81.9448949895246,0.0217475919017751,16.520090829888158,82.5061876303643,0.0068262830684406
0.006744905260208401,81.9523604728006,0.0223630146779064,16.521595871316602,82.52958939882969,0.0070187798255027
0.0069276656207236005,81.9623050338111,0.0229432788225422,16.52360069481632,82.5545834644659,0.007200245456576
0.0071111771223195,81.9750326049164,0.0235259278401092,16.526166573151144,82.58244636924832,0.0073824237803835
0.007294501711268001,81.9783041491569,0.0241079834100206,16.52682611647003,82.60077079369532,0.0075643834172091
0.007481773434623501,81.95865850686,0.0247025711316744,16.522865554982978,82.59632451996939,0.0077502266198784
0.007662267107545001,81.9574623036674,0.0252756385432001,16.522624400419346,82.60991181330691,0.0079293107961936
0.0078408673679994,81.9555018997885,0.0258426943701428,16.52222918299736,82.62257307696895,0.0081064847832798
0.0080271925495914,81.9405852944774,0.0264342768216974,16.519221995366646,82.62280265340846,0.008291288551033
0.0082180984338954,81.9195059058733,0.0270404030043626,16.514972390624056,82.61718667866482,0.0084806002028415
0.0084009286276462,81.8915382708478,0.0276208888695214,16.50933411540292,82.60395309854331,0.0086618700125298
0.0085893879569129,81.8780213511375,0.0282192472399432,16.506609104389323,82.60574926547612,0.0088486865297854
0.0087690524090432,81.8577987711784,0.0287896818754569,16.502532232269566,82.60005388476813,0.0090267523459353
0.0089642686398525,81.8158930006141,0.0294094934082764,16.4940840289238,82.57373991900585,0.0092201956262698
0.0091558317336276,81.7915931352087,0.0300177062310124,16.489185176058076,82.56488321864153,0.0094099825777765
0.0093496553118772,81.7705865133751,0.0306330960919549,16.48495024109642,82.55952705956713,0.0096019724027751
0.0095337261049105,81.7461198402658,0.0312175208598356,16.480017759797587,82.54987139973798,0.0097842675947293