File: example/data/02 processed data/test_ID_083.csv
Strain,Stress_MPa,Displacement(mm),Force(kN),True Stress (MPa),True Strain
1.62914209712405e-05,0.0652635359859469,5.1725261583688585e-05,0.013157128854766895,0.06526459922168572,1.6291288267391098e-05
4.31680879945534e-05,1.09570715350446,0.00013705867938270703,0.22089456214649913,1.095754453087279,4.316715627955236e-05
7.46997251401037e-05,3.31105019575092,0.00023717162731982922,0.6675077194633855,3.311297530290468,7.469693525464844e-05
0.0001410033907796,7.2879254061428,0.00044768576572523,1.4692457618783885,7.288953028336815,0.0001409934507358737
0.0002100263632028,12.1537407064457,0.0006668337031688899,2.4501941264194533,12.156293312405584,0.00021000431075383176
0.0002739377355235,17.4954347409579,0.0008697523102871124,3.527079643777113,17.500227400732836,0.0002739002214328103
0.000329712337277,22.5996893431952,0.001046836670854475,4.5560973715881525,22.60714073959028,0.00032965799410903697
0.000378187934835,27.9885011133927,0.0012007466931011248,5.642481824459968,27.999086026827904,0.0003781164398031273
0.0004383269911808,33.675476821324,0.0013916881969990398,6.788976127178918,33.69023769175566,0.0004382309539679155
0.0005033099806542,39.4144575298111,0.0015980091885770848,7.945954638009919,39.43429521966792,0.0005031833626694788
0.0005784369041462,45.3311002700754,0.0018365371706641847,9.138749814447202,45.35732145137717,0.0005782696740050724
0.0006644673071971,51.3876113336169,0.0021096837003507923,10.359742444857169,51.421756721343044,0.0006642466465384435
0.0007506592672152,57.4850240619502,0.00238334317340826,11.588980850889161,57.5281757279884,0.0007503776634643957
0.0008430734701807,63.6980151625657,0.0026767582678237224,12.841519856773246,63.75171726925243,0.0008427182833610645
0.0009356862305352,70.0199996074572,0.00297080378194926,14.11603192086337,70.08551635695197,0.000935248749049853
0.0010306775389252,76.2764589725345,0.00327240118608751,15.377334128862957,76.35507540554624,0.001030146755510372
0.001118440659068,82.5749005784632,0.0035510490925409,16.64709995661818,82.66725570468866,0.0011178156702793221
0.0012132467429048,88.8734148486479,0.00385205840872274,17.916880433487417,88.98124022974386,0.0012125113538208297
0.0013139528098699,95.1910195227976,0.004171800171336932,19.190509535795996,95.31609603037396,0.0013130903292996859
0.001401319317102,101.618916664135,0.00444918883179885,20.486373599489617,101.76131721503944,0.001400338385479857
0.0014954274487841,107.830176534897,0.004747982149889518,21.738563589435234,107.99142874069453,0.0014943104106512025
0.0015933552783556,113.975600895911,0.00505890300877903,22.97748114061566,114.15720452120225,0.0015920872346181383
0.0016986638355978,120.017456623886,0.005393257678023015,24.19551925537542,120.22132593709343,0.0016972227379141607
0.0017992805543753,125.970353065355,0.005712715760141577,25.39562317797557,126.19700907205329,0.0017976637881722034
0.0019065985085327,131.921936231005,0.006053450264591322,26.595462344170606,132.17345839786577,0.0019047832565346097
0.0019952712609189,137.869565922881,0.006334986253417507,27.794504490052816,138.14465310552228,0.0019932833510568904
0.002101917538511,143.752721712849,0.006673588184772425,28.98054869731036,144.05487807982593,0.00209971160043418
0.0022056451344602,149.553120941679,0.007002923301911134,30.149909181842485,149.88298205522736,0.0022032162700503584
0.0023144793932851,155.263347311774,0.007348472073680193,31.30109081805364,155.62270112965956,0.002311805111439287
0.002413345867021,160.884609345276,0.007662373127791675,32.434337244007644,161.2728795523067,0.002410438424720446
0.0025208178058848,166.466282372398,0.008003596533684241,33.55960252627544,166.8859135410818,0.002517645874136041
0.0026233076643197,172.123664018599,0.008329001834215047,34.700130666149555,172.57519734562976,0.002619872798597116
0.0027425249584293,177.669927769659,0.008707516743013026,35.81825743836326,178.1571919809296,0.0027387710986585077
0.002852057234082,183.145221307688,0.00905528171821035,36.9220766156299,183.66756196100613,0.0028479978354419297
0.0029520583498728,188.55228341023,0.00937278526084614,38.012140335502366,189.10890075285874,0.002947709582064329
0.0030642395366725,193.799484941376,0.009728960528935187,39.0699761641814,194.39333298532011,0.003059554323340666
0.0031631154884958,198.993377441446,0.010042891675974164,40.117064892195515,199.62281647573914,0.003158123363041818
0.0032806619906249,204.055977963477,0.010416101820234057,41.13768515743696,204.7254166543416,0.003275292359833936
0.003392362271766,208.989113356517,0.010770750212857049,42.13220525267383,209.69808013987748,0.0033866211910943
0.003509464180653,213.77428236699,0.011142548773573274,43.09689532518519,214.52451555370178,0.0035033203813351374
0.003630033891237,218.40058610057,0.011525357604677475,44.02955815787491,219.1933876299811,0.003623461219423158
0.0037538368658072,222.666986592672,0.011918432048937859,44.88966449708268,223.5028421357418,0.0037468088028433065
0.0038940907704729,226.659342091653,0.012363738196251457,45.69452336567724,227.5419741437336,0.0038865284249575876
0.0040491699764896,230.333896699747,0.012856114675354479,46.43531357466899,231.26655779883143,0.004040994150515185
0.0042219571899367,233.622471761998,0.013404714078049022,47.098290307218804,234.60881583638437,0.004213069734868483
0.0044301609165092,236.6109782598,0.01406576090991671,47.70077321717567,237.65920296810356,0.004420376640271704
0.004665379085631,239.154611813885,0.014812578596878423,48.213569741679215,240.2703587380737,0.00465452993513823
0.0049444593561304,241.167926494097,0.01569865845571402,48.61945398120996,242.3603715046493,0.004932275661651748
0.0052714683201406,242.784521012403,0.016736911916446405,48.945359436100446,244.0643519235404,0.005257622767296175
0.0056661254312244,243.928482466596,0.01798994824413747,49.17598206526576,245.31061184449996,0.005650133322946426
0.0061100604346067,244.761247878312,0.019399441879876272,49.3438675722677,246.25675389489822,0.006091469703908612
0.0065853269144808,245.386168077794,0.02090841295347654,49.46985148448327,247.00211621487801,0.006563738375755344
0.0070543455913834,245.936191724791,0.022397547252642293,49.580736251717866,247.6711106146464,0.007029580096881753
0.0075422581322211,246.373386494634,0.02394666956980199,49.66887471731821,248.231598172486,0.007513957514649098
0.008040331548564,246.741983199032,0.025528052666690695,49.743183812924855,248.7258705509024,0.008008180305648597
0.0085417535040413,247.0392253139,0.027120067375331125,49.80310782328225,249.14937348236066,0.008505479145629075
0.0090563888746513,247.36725055635,0.028754034677017874,49.86923771216016,249.60750457224162,0.009015625711450573
0.0095549291691113,247.722127885125,0.030336900111928376,49.940780981641204,250.0890952706889,0.00950956954317273
0.0100756476576027,248.028600291871,0.03199018131288857,50.0025658188412,250.52764907742025,0.010025226719296457
0.01057064883076,248.381857239402,0.033561810037662995,50.07378241946344,251.00741462821168,0.010515170143753647
0.0110629344785899,248.703235728806,0.03512481696952293,50.13857232292729,251.4546233302871,0.011002187832443226
0.011542548738072,249.050540872202,0.0366475922433786,50.20858903983593,251.92521887846257,0.011476441731635416
0.0120336433091199,249.336373163289,0.03820681750645568,50.26621282971906,252.33679814192564,0.011961814689292487
0.0125202292903733,249.570131842299,0.03975172799693523,50.31333857940747,252.69480711699325,0.012442499345016306
0.0130042341789311,249.756983179515,0.04128844351810624,50.351007808990225,253.0048814766048,0.012920405098808992
0.0134698170483649,249.920813593931,0.04276666912855855,50.384036020536485,253.28720122961977,0.01337990555709885
0.0139255814123352,250.066049019463,0.044213720984164255,50.413315482323746,253.54836414354452,0.013829511363636447
0.0143821118478856,250.244750165931,0.045663205117036774,50.449341633451695,253.8437981521636,0.01427967032598399
0.0148384438098571,250.405744568845,0.04711205909629629,50.48179810507915,254.1213761392952,0.014729431164835717
0.0152954600543893,250.605205180824,0.048563085672686024,50.522009364454114,254.43832708608932,0.015179663783859059
0.0157528551469188,250.918932155745,0.050015315091467186,50.585256722598196,254.871621747614,0.015630066757376257
0.0162084688347579,251.148928282752,0.05146188855035633,50.6316239418028,255.21966785970582,0.016078513969532648
0.0166525456234301,251.387497905417,0.052871832354390566,50.679719577732065,255.57373968344692,0.016515412304025374
0.0170959831857452,251.591040744632,0.054279746614741005,50.72075381411781,255.89223694688636,0.016951491360074507
0.0175255070671296,251.733597787856,0.05564348493813648,50.749493314031774,256.14535673492105,0.01737370639105002
0.0179454296964657,251.910390587324,0.056976739286278597,50.785134742404516,256.43103079141804,0.017786311285287487
0.0183679531803636,252.063602046856,0.05831825134765442,50.81602217264617,256.69349448772647,0.018201299954040198
0.0187779087152955,252.254884209764,0.05961986017106321,50.854584656688424,256.9917033984424,0.018603780255656437
0.0191915383001079,252.469941278156,0.06093313410284258,50.89794016167625,257.31522782582175,0.019009703505485198
0.0196041579188337,252.654039669088,0.062243201392297,50.93505439728814,257.6071093615921,0.01941447150173367
0.0200135007313285,252.897250353027,0.06354286482196798,50.98408567117024,257.95860965791826,0.019815863219690824
0.0204227552047221,253.029477214502,0.06484224777499267,51.010742606443614,258.19703628723255,0.020217007315901574
0.0208330470780501,253.265533033857,0.06614492447280906,51.05833145962557,258.5418258067988,0.020619006789357595
0.0212306442754087,253.370803688569,0.06740729557442261,51.079554023615515,258.7500290914554,0.02100841403856966
0.0216215464140524,253.471519814212,0.06864840986461636,51.09985839454514,258.95196604451536,0.021391116365440156
0.022008965474925,253.58205630032,0.06987846538288688,51.12214255014452,259.1631350224942,0.02177026422339178
0.0223875603850136,253.767493724096,0.07108050422241818,51.15952673477776,259.44872881359777,0.022140637494552903
0.022772239023491,253.967054657075,0.07230185889958392,51.19975821886632,259.7504531298179,0.022516821930727605
0.0231490064419842,254.196315466139,0.07349809545329983,51.24597719797362,260.0807076103933,0.022885132708659373
0.0235381059194265,254.318609867891,0.07473348629417914,51.27063174936683,260.30478824424273,0.023265356417285752
0.0239282703201216,254.542765181851,0.07597225826638608,51.31582146066116,260.6335332751536,0.023646475648297922
0.0243278375344278,254.813648694094,0.07724088417180826,51.37043157672935,261.0127137410787,0.02403662922122515
0.0247202877617107,255.013291409981,0.07848691364343147,51.410679548252176,261.3172933566967,0.02441968536054837
0.0251104054224174,255.21743720421,0.07972553721617523,51.45183534036874,261.6260505232781,0.024800319397021618
0.0255033036488477,255.349879335522,0.08097298908509144,51.47853567404123,261.86214484491245,0.02518352002569204
0.0258853918765526,255.512146043647,0.08218611920805449,51.51124864239923,262.1261780732058,0.02555603668521829
0.0262728272407918,255.63112901336,0.08341622648951395,51.53523560909338,262.34728150329653,0.025933624889902435
0.0266638507702032,255.759992295506,0.08465772619539515,51.56121444677401,262.5795385630617,0.026314565557316538
0.0270607810985464,255.907669778289,0.08591797998788481,51.59098622730306,262.8327312115984,0.026701112348571903
0.0274544568058475,256.114662238278,0.08716790035856581,51.63271590723685,263.146151170043,0.02708434212935536
0.0278387326175108,256.286527103056,0.08838797606059678,51.6673638639761,263.42121920454844,0.027458279841131673
0.0282123525752162,256.41516993863,0.08957421942631143,51.69329825962781,263.64924511857265,0.027821714353540965
0.0285848660188104,256.518397350455,0.09075694960972303,51.71410890585174,263.85094137007775,0.02818394106631514
0.0289604518441819,256.591549454207,0.09194943460527753,51.72885636996813,264.0225566657996,0.028549022531381776
0.0293353284172305,256.659410460298,0.09313966772470683,51.742537148796075,264.18859855752356,0.028913281721716304
0.0297166967917826,256.81943763706,0.09435051231390974,51.7747986276313,264.4512629955566,0.029283712749435836
0.0301012375465556,256.952075407778,0.09557142921031402,51.801538402208045,264.686650867708,0.02965708629166007
0.0304872512023593,257.114226058896,0.09679702256749077,51.83422797347344,264.9529320564538,0.030031749803978772
0.0308797069643371,257.261470326569,0.09804306961177028,51.86391241783631,265.20562914346795,0.03041252215037234
0.0312568326639092,257.421441303307,0.0992404437079117,51.89616256674669,265.4676202182268,0.030778284258292026
0.0316331491492099,257.595984392083,0.10043524854874143,51.93135045344393,265.7445565865953,0.03114312823232147
0.0320167936440705,257.753810237667,0.10165331981992383,51.96316814391366,266.00626079101926,0.031514939837889645
0.0323939273618875,257.879994060997,0.10285071937399282,51.988606802697,266.23373985669286,0.03188030678563395
0.0327881987785509,257.938858408998,0.10410253112189911,52.00047385525399,266.3962089712247,0.032262134050612824
0.0331882324684458,258.013954352834,0.10537263808731541,52.01561319753133,266.5769814499988,0.032649392771326086
0.0335767125859125,258.150940042336,0.10660606246027218,52.043229512534936,266.8187999599207,0.033025323399500775
0.0339721477236273,258.312415533284,0.10786156902251666,52.075782971510066,267.0878430726277,0.03340783928594719
0.0343617881427387,258.48458580957,0.10909867735319537,52.11049249920931,267.366578385322,0.033784606709199395
0.0347514670997579,258.571847301278,0.11033590804173132,52.12808441593765,267.55759834569204,0.03416126947585952
0.0351433297513926,258.648702464163,0.1115800719606715,52.14357841677526,267.7384791046309,0.03453989998105448
0.0355527203552357,258.714540807658,0.11287988712787334,52.15685142682386,267.9125465288259,0.03493531350314639
0.035951311021772,258.806221172659,0.11414541249412609,52.17533418840805,268.11064412440675,0.0353201456496621
0.036350012600369,258.925260025776,0.11541129000617156,52.19933242119645,268.3371964902668,0.035704936779187305
0.0367372386089554,259.007980318111,0.11664073258343338,52.21600883213117,268.52321829268107,0.03607851103455345
0.0371304142326218,259.070914355203,0.1178890651885742,52.22869633400893,268.6903247208358,0.03645768241305318
0.0375317623746728,259.17591635797,0.11916334553958614,52.24986473776675,268.90324526395534,0.036844586991140994
0.0379335405471521,259.288143894873,0.12043899123720792,52.27248980920639,269.12386121470496,0.03723175624608609
0.0383285134981769,259.445082270844,0.12169303035671164,52.304128585802154,269.38922660869764,0.03761222166471624
0.0387138043286157,259.588966093724,0.12291632874335484,52.33313556449476,269.6386425329441,0.0379832211687238
0.0391014604102017,259.668073484428,0.12414713680239038,52.34908361446069,269.82147437957275,0.03835635933231571
0.0394895619397181,259.804814537602,0.12537935915860496,52.376650610780565,270.0643928535216,0.03872978684148261
0.0398873017141574,259.973874182159,0.12664218294244975,52.41073303512326,270.3435305394612,0.039112343545120346
0.0402916573145924,260.129150256418,0.12792601197383088,52.442036691693865,270.6101848360857,0.039501113562981374
0.0407128248088188,260.27140583005,0.12926321876799968,52.470715415338084,270.86778997835387,0.03990588683819041
0.0411276233536135,260.363415780486,0.13058020414772287,52.489264621345974,271.0715442797661,0.040304378999921446
0.0415418007434262,260.424234179562,0.13189521736037818,52.5015256105997,271.2427258246088,0.04070211604880752
0.0419600505362939,260.558124609228,0.1332231604527331,52.52851792122036,271.49115668547313,0.0411036033796
0.0423650675052119,260.648060383018,0.13450908932904776,52.54664897321643,271.69043305624706,0.04149223466414377
0.042778096947617,260.768318760816,0.13582045780868396,52.5708930621805,271.92349118163327,0.04188839877876993
0.0431843592644959,260.910010339507,0.13711034066477448,52.599458084444606,272.17724196171156,0.042277919041520236
0.0436062621422088,260.938367604943,0.13844988230151292,52.6051749091565,272.3169144656842,0.04268227478198948
0.0440258042285823,261.024649316521,0.1397819284257488,52.622569302210636,272.5164694261645,0.04308420584903895
0.044455143938808,261.024183616213,0.14114508200571538,52.62247541702855,272.6280512703816,0.04349535608399837
0.0448771489247673,261.103189561917,0.1424849478361362,52.63840301568247,272.8207562846189,0.04389931766841412
0.045278280773849,261.151842286473,0.14375854145697056,52.64821140495297,272.97634872612787,0.044283147357160595
0.0456830000784063,261.252997263061,0.14504352524894,52.668604248233095,273.1878179575133,0.04467026051254769
0.046101470361639,261.246867534401,0.14637216839820383,52.667368494935246,273.2907322551092,0.04507036893167865
0.0465336781843443,261.44065219729,0.14774442823529313,52.70643548297366,273.6064473709438,0.045483444119822615
0.0469869506866771,261.587498901246,0.14918356843019978,52.7360397784912,273.8786978123701,0.045916468283200396
0.0474331991109047,261.706878168196,0.15060040717712242,52.760106638708315,274.12047262904133,0.04634259904881919
0.0478648582333617,261.810858011267,0.1519709248909234,52.78106897507142,274.34239761393104,0.046754625516414704
0.0482896652703432,261.777824048992,0.15331968723333966,52.77440932827679,274.4189875475166,0.04715994586664096
0.0487131712351233,261.783867245447,0.15466431867151648,52.775627636682124,274.53618959716727,0.04756386136276256
0.0491409707794563,261.832050026988,0.15602258222477375,52.78534128544078,274.69873114648937,0.047971706256928794
0.0495691610797973,261.921204826252,0.1573820864283564,52.8033148929724,274.9044192184991,0.048379757182859105
0.0499990031690701,262.020543608049,0.15874683506179754,52.823341591382686,275.1213095982693,0.0487892148061909
0.0504135076185906,262.064700678997,0.16006288668902513,52.832243656885794,275.2763014632412,0.04918390342356731
0.0508354755067356,262.10770115346,0.16140263473388552,52.84091255253754,275.4320707755735,0.04958553873400033
0.0512662507526198,262.241287770548,0.16277034613956784,52.86784361454248,275.68541538708286,0.049995390689815
0.0517074534840835,262.361688089025,0.16417116481196511,52.89211631874744,275.9277428718939,0.050414989600679354
0.0521571997687602,262.487437288285,0.16559910926581364,52.91746735731826,276.17804699171995,0.050842532590036724
0.0526051104062446,262.535298969805,0.1670212255398266,52.92711627231269,276.34599735764806,0.05126814895733923
0.053058530845527,262.595334193847,0.16846083543454823,52.93921937347955,276.5282568330627,0.05169881645561158
0.053506457620409,262.655992288292,0.16988300294479858,52.951448045319665,276.70978400841193,0.05212408392572077
0.053950346349769,262.732141658035,0.17129234966051657,52.96679975825986,276.90663169770255,0.05254533928439581
0.0543859518347155,262.694971753967,0.1726753970752217,52.959306305599746,276.9818878350002,0.052958561303596316
0.0548265508892196,262.721757603419,0.17407429907327224,52.964706332849275,277.1258854163681,0.05337634667168407
0.0552666618418909,262.744974957174,0.1754716513480036,52.96938695136628,277.26601263878825,0.05379349502929971
0.0557152028748623,262.819712139056,0.17689576912768779,52.984453967233684,277.46276572039636,0.05421845466274658
0.0561690328945461,262.940311389786,0.17833667944018386,53.00876677618086,277.7094143895411,0.054648241503315896
0.0566166302123981,262.963284914594,0.17975780092436397,53.013398238782145,277.851379976041,0.05507194498859036
0.0570666614935447,263.020544269076,0.18118665024200442,53.02494172464572,278.0302486347273,0.0554977715915756
0.0575262657675276,263.029410448125,0.1826458938119001,53.02672914634201,278.16051021823995,0.05593246923507473
0.0579815282181838,263.01557270417,0.18409135209273356,53.02393945716067,278.2656175547386,0.05636287413263978
0.0584397096421127,263.06000987287,0.18554607811370782,53.03289799037059,278.4331604682919,0.05679585167311297
0.0589031588012968,263.094624654739,0.18701752919411732,53.03987633039538,278.59172911054463,0.05723361654671218
0.0593650959574955,263.138802305977,0.1884841796650482,53.048782544884965,278.7600625550117,0.05766976259429942
0.0598268027712686,263.237651356019,0.1899500987987778,53.06871051337344,278.9863184056675,0.058105501161774466
0.0602889514900594,263.288884943969,0.19141742098093859,53.07903920470415,279.1622957562277,0.05854146672184523
0.0607526474687323,263.296884059555,0.19288965571322506,53.080651826406296,279.29286683644085,0.05897870094326536
0.0612088577025661,263.302938875959,0.19433812320564736,53.08187247739334,279.419410994285,0.05940869012049687
0.0616700113925357,263.338523084488,0.19580228617130085,53.08904625383278,279.57861280320185,0.05984315079928261
0.0621349536489888,263.404980530609,0.19727847783553942,53.102444074970784,279.7716367867912,0.06028098974545117
0.0625969423526818,263.428331513773,0.1987452919697647,53.107151633176635,279.9181395956038,0.0607158575156794
0.0630686873272051,263.447440724957,0.20024308226387616,53.11100405015134,280.0627249911917,0.061159713760689245
0.0635410199561057,263.501520677878,0.20174273836063558,53.1219065686602,280.2446760617352,0.06160392562998514
0.0640066603940578,263.548614397948,0.20322114675113348,53.13140066262631,280.4174810570419,0.06204165066871177
0.064467721529872,263.546113607714,0.20468501585734358,53.13089650331514,280.5363310700561,0.06247488223301054
0.0649264602059685,263.548518778753,0.20614151115394996,53.131381385796615,280.6597911955837,0.06290574532743247
0.0654135176264792,263.555513022086,0.20768791846407147,53.13279142525255,280.795606218712,0.0633630032619079
0.0658982330452188,263.596532137011,0.2092268899185697,53.14106087882143,280.96707784168734,0.06381785499999255
0.0663789098709674,263.603422117428,0.21075303884032145,53.14244989887349,281.1011299158393,0.06426871274659238
0.0668643090652755,263.59285686127,0.21229418128224972,53.14031994323203,281.21781110984085,0.06472379372224156
0.0673352512872378,263.581199741555,0.21378942283698002,53.13796986789749,281.3295060607442,0.06516512286348501
0.0678229315897496,263.604579125519,0.21533780779745496,53.14268315170463,281.48301446229385,0.06562193240097344
0.0683117550842819,263.580813148716,0.21688982239259502,53.137891930781144,281.58648110144696,0.06607960345150632
0.0688011069720385,263.558984442136,0.21844351463622225,53.13349126353462,281.69213432418127,0.0665375595145642
0.0692797754558162,263.546515081685,0.21996328707221643,53.130977440467696,281.80495846870707,0.06698531478491812
0.0697603583204529,263.529427757379,0.22148913766743794,53.127532635887604,281.91333506571766,0.06743465920359848
0.070235170607974,263.537175983395,0.22299666668031745,53.129094678252436,282.0467545001324,0.06787840993942391
0.0707303136215288,263.504665520383,0.22456874574835395,53.122540568909216,282.14243315337575,0.06834095174687455
0.071216066654353,263.491449871111,0.22611101162757075,53.119876294015974,282.2562745279842,0.06879451402614056
0.0717070532110383,263.495553470188,0.2276698939450466,53.1207035795899,282.3900431437467,0.06925275404485627
0.0722034451429938,263.479189828044,0.2292459383290053,53.11740466933367,282.50329505711363,0.06971582555946197
0.0727036694845918,263.456666156721,0.23083415061357893,53.11286389719495,282.61093253649165,0.07018225540834025
0.0731974004471348,263.410609050045,0.23240174641965297,53.10357878448908,282.69158088270484,0.07064241732183515
0.0736822506951872,263.365972300022,0.23394114595721935,53.09458001568444,282.771369895614,0.07109409634915054
0.0741556186521504,263.347825739833,0.2354440892205775,53.09092166915034,282.876546678269,0.07153488191437685
0.0746385146418802,263.315333957392,0.23697728398796963,53.084371325810224,282.9687993664024,0.07198433958030859
0.0751287727060433,263.296155343136,0.23853385334168747,53.080504917176214,283.0772723522855,0.07244044296931017
0.0756207900933359,263.251657256777,0.24009600854634147,53.07153410296625,283.15895557191453,0.07289797405929471
0.0761069589040744,263.15030994946,0.2416395945204362,53.051102485811136,283.17787977437797,0.07334986098526669
0.0766002651443941,263.065564477401,0.24320584183345123,53.03401779864404,283.2164564667296,0.07380817342408205
0.0770987190494859,262.98905883117,0.24478843298211772,53.01859426036387,283.26517839108305,0.07427105511520965
0.0775962019021252,262.982267921106,0.2463679410392475,53.017225212894964,283.3886930793909,0.07473282151809277
0.0780842444680145,262.94258155412,0.24791747618594603,53.0092244413106,283.4742543732428,0.0751856182904989
0.0785738176995932,262.864142262964,0.24947187119620837,52.99341108021354,283.518381456894,0.07563962928888224
0.079064263138975,262.756613253839,0.2510290354662456,52.97173323197395,283.53127126564647,0.07609424255529079
0.0795483730276433,262.592625985949,0.25256608436276745,52.938673398767314,283.4814421521877,0.07654278055481291
0.0800318971682594,262.459181293709,0.25410127350922357,52.91177094881173,283.46428750187266,0.0769905751150511
0.0805110665873299,262.362715425457,0.2556226364147724,52.892323429772134,283.48581747710864,0.07743413901076171
0.0809916224154279,262.301890725646,0.2571484011689836,52.880061170290226,283.54614641815033,0.07787878878007329
0.0814750257214109,262.177626267686,0.25868320666547956,52.855009455565494,283.53855511142416,0.07832587388490175
0.0819388184811577,262.006374236461,0.26015574867767566,52.82048504607054,283.4748669759286,0.07875463398375625
0.0824031868127592,261.814500152741,0.26163011813051046,52.78180323079258,283.3888493191165,0.07918374207997333
0.0828675620860282,261.620064028676,0.2631045096231395,52.74260490818108,283.29988092752296,0.07961267253185775
0.0833202749172171,261.504548584589,0.26454187286216424,52.719316994653134,283.29317946475965,0.08003065367831844
0.0837932886652982,261.375641007326,0.26604369151232177,52.69332922707692,283.2771655443302,0.08046719172001736
0.0842563518304225,261.195779354117,0.26751391706159144,52.65706911778999,283.20318283599886,0.08089436198726262
0.0847197749888708,260.980035505606,0.2689852855896648,52.61357515793017,283.09020539022845,0.08132168173483385
0.0851752410490672,260.734050202755,0.27043139033078833,52.5639845208754,282.9421357784742,0.08174148643830478
0.0856241713383189,260.484860247909,0.2718567439991625,52.513747825978456,282.788660552814,0.08215509470914716
0.0860774719059634,260.239381774284,0.2732959733014338,52.46425936569566,282.64012984778526,0.0825725558973706
0.086533310827099,260.004122348841,0.2747432618760393,52.41683106552635,282.50313988438035,0.08299217908201753
0.0869886575847622,259.722819621347,0.27618898783161994,52.36012043566356,282.31575904433737,0.08341117347999699
0.0874410260715622,259.423730552069,0.27762525777721,52.29982407929712,282.1080077388544,0.08382725361054917
0.0878813855332786,259.070912629625,0.27902339906815954,52.22869598613241,281.8384233828874,0.08423212184100771
0.0883192552279594,258.687436074523,0.28041363534877106,52.151387112623844,281.5345177654553,0.08463453850460802
0.0887523461753458,258.294496986881,0.2817886991067229,52.0721705925552,281.21873959864746,0.08503240410794448
0.0891761533680485,257.944856851237,0.28313428694355397,52.00168314120938,280.9473869663022,0.08542158786502435
0.0895877776662286,257.560740280767,0.2844411940902758,51.92424524060262,280.6350346165896,0.08579943908351974
0.0900041444393199,257.207679431741,0.28576315859484064,51.85306817343899,280.3574365622177,0.08618149847173193
0.090408313088938,256.78579320005,0.28704639405737814,51.768015909130085,280.0013635884714,0.08655222526046558
0.0908188779180713,256.306183939935,0.28834993738987635,51.6713266822909,279.5836239688227,0.08692867832842167
0.0912124409649344,255.852952137157,0.2895995000636667,51.57995515085085,279.18992442967163,0.0872894092196102
0.0916029805507093,255.282442410059,0.290839463248502,51.46494038986789,278.66707501708515,0.08764724029052212
0.091997508736047,254.771936973244,0.2920920902369492,51.36202249380599,278.2103204706396,0.08800859594286457
0.0923661212709571,254.19890904182,0.29326243503528876,51.24650006283091,277.6782763013217,0.08834609701946676
0.0927546798815683,253.719342018793,0.29449610862397935,51.149819350988665,277.25299836750827,0.08870173741655771
0.0931395497596575,253.168247848417,0.29571807048691257,51.03871876624086,276.74822446645993,0.08905387694540333
0.0935320568695894,252.605382401037,0.2969642805609463,50.92524509204905,276.2320833933352,0.08941287654365813
0.0939232645953354,251.86911741663,0.2982063650901899,50.776814071192604,275.5254871751457,0.08977055948792491
0.0943288170258198,251.133990474785,0.29949399405697785,50.62861247971666,274.823162711245,0.09014122284845263
0.0947064426136713,250.375541140549,0.30069295529840634,50.475709093934675,274.0877179594433,0.09048623838891448
0.0950609543681682,249.540704528413,0.301818530118934,50.30740603292806,273.262282054589,0.09081002780881618
0.0954147401805955,248.707581763702,0.30294180007339067,50.13944848356232,272.43795105862984,0.0911330497134957
0.0957610922335207,247.909436152279,0.3040414678414282,49.97854232829945,271.64951453321754,0.09144918322563668
0.0961395444908247,247.090252085763,0.3052430537583684,49.81339482048982,270.8453963694113,0.0917945020368307
0.0965227960662192,246.229186431846,0.30645987751024595,49.63980398466015,269.99591597935813,0.09214407850577308
0.0968866573712158,245.184124433575,0.3076151371536101,49.42911948580871,268.9391946904323,0.09247585541843663
0.0972440617034698,244.14310446765,0.3087498959085166,49.21924986067824,267.8845715829788,0.09280163759021703
0.0975947386985506,242.967704181993,0.30986329536789814,48.98228916308979,266.68007378382134,0.09312118451821966
0.0979331199908729,241.893978746889,0.3109376559710214,48.76582611537282,265.5834107925777,0.09342943047707859
0.0982736591306576,240.705772312246,0.31201886773983784,48.5262836981488,264.3608093312414,0.09373954621458691
0.0986280202059995,239.542029779544,0.31314396415404844,48.29167320355607,263.167585932827,0.09406214697705893
0.0989668021955888,238.253242716723,0.31421959697099444,48.03185373169136,261.8324042611265,0.09437046768187639
0.0992961985209036,237.043174900331,0.3152654303038689,47.78790405990674,260.5806610532595,0.09467015550601098
0.0996378087708003,235.39110263692,0.31635004284729096,47.45484629160307,258.84495630780526,0.09498086083096585
0.0999899407929267,234.03784531332,0.31746806201754224,47.18202961516531,257.439275609503,0.0953010350288086
0.100377221366225,232.212966541862,0.31869767783776437,46.81413405483938,255.52185888854228,0.09565304953253115
0.100792096084468,230.419526443559,0.32001490506818586,46.4525765310215,253.6439934925958,0.0960300080153398
0.101168172691104,228.278051567242,0.32120894829425517,46.02085519595598,251.37252490978548,0.09637159148133204
0.101554951085977,225.878048745959,0.3224369696979769,45.537014627185336,248.8170829377508,0.09672277352021204
0.101939291279493,223.270401512751,0.32365724981239025,45.011312944970605,246.03042800664866,0.0970716196301987
0.102128556099262,221.930471108137,0.3242581656151568,44.74118297540041,244.59590967684,0.09724336100418525
0.10223407854292,221.178713778256,0.324593199373771,44.589628697696405,243.79071577468426,0.09733910064527734