File: example/data/02 processed data/test_ID_150.csv
Strain,Stress_MPa,Displacement(mm),Force(kN),True Stress (MPa),True Strain
-0.0002391159833409,0.0330069942876414,-5.4342865537630414e-05,0.0066542100483885,0.0330064293444438,-1.7116009639500485e-05
-0.0002296665490252,0.0320113773254113,-2.4340911585412808e-05,0.0064534936688029,0.0320111319124647,-7.66645823296979e-06
-0.0002187205076889,0.0361162499730311,1.0412769657473137e-05,0.007281035994563,0.0361163684203356,3.2796071125526444e-06
-0.0002089534580689,0.0429741831291092,4.1423152200822576e-05,0.0086635953188284,0.0429747437987559,1.3046577003482718e-05
-0.0001975211903392,0.050811899008724,7.772060224270263e-05,0.0102436788401587,0.0508131428296348,2.4478630236141048e-05
-0.0001682281660115,0.0567083898732143,0.000170725954483,0.01143241139844,0.0567114391941554,5.37705085080768e-05
-0.0001420995393082,0.0634996618056139,0.0002536843442661,0.0128015318200117,0.0635047354654772,7.989738898975981e-05
-0.0001130638464717,0.0728345742289811,0.0003458726690219,0.0146834501645625,0.0728425085560946,0.0001089303405826
-7.556191703906754e-05,0.0826560015164489,0.000464941294971,0.0166634499057161,0.0826681055127897,0.0001464274821133
-6.007492657596756e-05,0.0883716181382118,0.0005141124896914,0.0178157182166634,0.0883859277295879,0.0001619120851344
-4.186596742936755e-05,0.0897585516271517,0.0005719259349818,0.0180953240080337,0.0897747202078011,0.0001801179305419
-1.027458999566756e-05,0.0883819326627622,0.0006722285583338,0.0178177976248128,0.0884006453743139,0.000211703119497
7.408711635632456e-06,0.0903464322844297,0.0007283730410132,0.018213840748541,0.0903671585539187,0.0002293825216328
2.111220976693244e-05,0.0849712894570257,0.0007718816475801,0.0171302119545363,0.0849919470251841,0.0002430827829326
3.990457035923245e-05,0.118431591351293,0.0008315473924606,0.0238758088164206,0.1184626091405758,0.0002618703994925
5.330352570543247e-05,0.365218338755446,0.0008740890756848,0.0736280170930979,0.3653188846956494,0.00027526575679
9.580488861803248e-05,0.800813796581522,0.0010090309029323,0.1614440613908348,0.8010682992171897,0.0003177545194826
0.0001285564652723,1.43549529410212,0.00111301715881,0.2893958512909874,1.4359985164308529,0.0003504951548484
0.000151497954316,2.27700543310787,0.0011858563865238,0.4590442953145466,2.277855890252752,0.0003734283414526
0.0001782236036191,3.39773257047255,0.0012707103230611,0.6849828862072661,3.399092423654377,0.0004001436556469
0.0002144396212606,4.86902515427948,0.0013856961790729,0.981595471102743,4.871150190358879,0.0004363445293181
0.0002548408354495,6.47626679355536,0.0015139700341227,1.3056153855807606,6.479354942802109,0.0004767273031088
0.0002810176089284,8.06335032444975,0.0015970812899182,1.6255714254090696,8.067406332618958,0.0005028912580998
0.0003031876960304,9.68405454415832,0.001667471316467,1.9523053961023176,9.689140491616426,0.000525049953356
0.0003281353516989,11.3634219844792,0.0017466801232145,2.2908658720710067,11.369673405994789,0.0005499842028363
0.0003523935449308,13.1042296146214,0.0018236998867258,2.641812690307674,13.111756601098191,0.0005742287642116
0.0003966798532847,14.831584963108,0.0019643089157494,2.9900475285625725,14.840760967699412,0.0006184886699093
0.0004283484487615,16.4633507466497,0.0020648567063883,3.319011510524579,16.474057663247763,0.000650137183955
0.0004492868979028,18.1773092599556,0.0021313362824119,3.664545546807049,18.18951145168548,0.0006710618057346
0.000482450767113,19.9382638965864,0.0022366315671543,4.019554001551818,19.952309424279424,0.0007042028782329
0.0005152310685293,21.7561627713869,0.002340709024151,4.386042414711599,21.7722020931286,0.0007369595672865
0.000557008984018,23.5055178196872,0.0024733539058276,4.73871239244894,23.52382883206762,0.0007787058340953
0.0005962995541604,25.2163298203526,0.0025981014660298,5.083612091783084,25.23696433483264,0.0008179650496978
0.0006226614952161,26.9586554178139,0.0026818006288816,5.4348649322312825,26.98142635924801,0.0008443050895219
0.000656170014276,28.6843134994752,0.0027881901768968,5.7827576014942,28.709503206917805,0.0008777847686579
0.0006921810167668,30.362810992324,0.0029025251098051,6.121142696052519,30.390568101397854,0.000913763527865
0.0007305379449866,32.0310714376616,0.003024308356903,6.457464001832579,32.06158225247403,0.0009520846886662
0.00076586953358,33.6408678193213,0.003136486150687,6.781998952375175,33.67410061176615,0.0009873820316449
0.0008036322623061,35.3098093854687,0.0032563828143924,7.11845757211049,35.34602426939383,0.0010251067809457
0.000838093465486,36.9274626790468,0.0033657971344885,7.444576476095834,36.96660924536776,0.0010595320832555
0.0008730548928858,38.4592102344858,0.0034767996664829,7.753376783272338,38.50132518545161,0.0010944558776756
0.0009065144497406,39.9589317423534,0.0035830337594969,8.055720639258446,40.0040259790231,0.0011278782760192
0.0009483485549953,41.4568277525965,0.0037158570436806,8.357696474923454,41.50534669603371,0.0011696643510441
0.0009904942819099,42.9406450352283,0.0038496697266344,8.656834039102025,42.99271032695564,0.0012117599243922
0.0010275483437363,44.4125461129942,0.0039673163729333,8.95356929637963,44.46804174176828,0.0012487684279615
0.0010651233774534,45.8312103549033,0.004086617104985,9.239572007548505,45.89020078267605,0.0012862958642853
0.0011124345879539,47.2932803364993,0.0042368301983241,9.53432531583826,47.356390131241824,0.0013335451414297
0.0011641589940814,48.6858417134864,0.0044010551877789,9.81506568943886,48.75332803671302,0.0013851992826
0.0012153541937521,50.0953662630651,0.0045635999467334,10.099225838633926,50.167371053871314,0.0014363223090061
0.0012628094186023,51.4611282061548,0.0047142702856328,10.374563446360808,51.53753818019178,0.0014837082990515
0.00130522167424,52.7476349488302,0.0048489291972825,10.633923205684168,52.82819228652816,0.001526056777224
0.001343443569379,54.0355264361108,0.0049702837143488,10.893562129519935,54.12011600998219,0.0015642196598526
0.0013981233616437,55.2646563132379,0.0051438920547892,11.141354712748765,55.35419188064588,0.0016188124975551
0.0014572372798081,56.4636325045786,0.0053315787449612,11.383068312923047,56.55844834801946,0.0016778290572725
0.001511547641484,57.6666728075605,0.0055040141432822,11.625601238004196,57.76664073912865,0.0017320469020336
0.0015768351785727,58.818258199349,0.0057113020735388,11.85776085298876,58.92406255840912,0.0017972193321512
0.0016466790018489,59.9737491583006,0.0059330562124408,12.090707830313402,60.08582085122249,0.0018669353132727
0.001725026288265,61.153958536769,0.0061818088468119,12.32863804101263,61.27302690902102,0.001945133409275
0.0018216032978858,62.2678124214153,0.0064884408523579,12.553190984157323,62.39506313571517,0.0020415181011575
0.001904635490969,63.3707806245563,0.0067520680653971,12.77554937391055,63.50554718333878,0.0021243775224918
0.0019904549951611,64.4361977066295,0.007024544991207,12.990337457656508,64.57875990185865,0.0022100112405006
0.0020856343415594,65.4939715370424,0.0073267394160216,13.203584661867747,65.64510768279744,0.0023049759624455
0.0021859902924456,66.4949983965361,0.0076453695600853,13.40539167674168,66.6551177151625,0.0024050958495005
0.0022928319504953,67.4644067030413,0.0079845918243931,13.600824391333129,67.63406835664718,0.0025116751721085
0.0024069242530244,68.4189222376113,0.008346834884923,13.79325472310244,68.5987904098701,0.0026254747959864
0.0025251414258505,69.3071759594379,0.0087221744086458,13.972326673422682,69.4975725819541,0.0027433750491831
0.0026530044565607,70.1918825556399,0.0091281395311507,14.150683523217008,70.3936845392374,0.002870879655303
0.0027898465134737,71.0357853178994,0.0095626130618495,14.320814320088518,71.24973420877805,0.0030073201101001
0.0029277919693458,71.8228544357386,0.0100005898842434,14.479487454244902,72.04908149448744,0.0031448418864384
0.0030604807835787,72.56602536227,0.0104218768694329,14.62931071303363,72.8042219547833,0.0032771053235972
0.00320079231684,73.251751646591,0.0108673659875375,14.767553131952743,73.5024771881254,0.0034169480153506
0.0033437364822057,73.8529556775887,0.0113212137125736,14.88875586460188,74.11629586484261,0.0035593944354863
0.0035000850917696,74.4021450257835,0.011817620547939,14.999472437197952,74.67907614952126,0.0037151753934346
0.0036419463465013,74.9340527266624,0.0122680300317121,15.10670502969514,75.22359389492968,0.0038565005996567
0.0037887470578188,75.3916160273813,0.0127341222901452,15.198949791120071,75.69399273860786,0.0040027255728024
0.0039419656139472,75.7753072071856,0.0132205912058529,15.276301932968618,76.09083298988926,0.0041553204196954
0.0041062094261347,76.1418320261385,0.0137420653095482,15.350193336469522,76.4713898303879,0.0043188697873008
0.0042602988248636,76.4601652604974,0.0142312991505124,15.414369316516275,76.80288257858237,0.004472283360537
0.0044188541634068,76.7534205314852,0.0147347123503871,15.473489579147415,77.10962197193867,0.0046301187213188
0.0045733121156376,77.0709754837878,0.0152251163487199,15.53750865753162,77.44055487555158,0.0047838513505095
0.0047350998899877,77.2750957200944,0.0157387925322814,15.578659297171033,77.65815609787417,0.0049448540428946
0.0049000543373284,77.458256606304,0.0162625229025882,15.615584531830889,77.85500201482513,0.0051089813583234
0.0050635149167373,77.6443876819,0.0167815102422114,15.65310855667104,78.0547782605249,0.0052715957279164
0.0052314121206187,77.7909942237975,0.0173145838645349,15.682664435517577,78.21522058392142,0.0054385962290692
0.0054318403906605,77.9080393540809,0.0179509436219176,15.706260733782711,78.34851898310113,0.0056379175436646
0.0056059877567507,77.9989138427802,0.018503861509254,15.724581030704488,78.45349056706966,0.0058110708519051
0.0057851425109265,78.0411620880967,0.0190726778537621,15.733098276960297,78.50996647985717,0.0059891716832629
0.0059713370902704,78.1091879994855,0.019663845643179,15.746812300696275,78.59294454000076,0.0061742373183631
0.0061508370658999,78.1616902994681,0.0202337580658027,15.757396764372771,78.65980202593539,0.0063526165223754
0.0063351519719082,78.2176464849227,0.020818957892379,15.768677531360416,78.7305314892095,0.0065357474881867
0.0065121743635013,78.2726113737048,0.0213810039856871,15.77975845293889,78.7997127959887,0.0067116012155758
0.0066763886305941,78.3242780712199,0.0219023842837068,15.790174459157932,78.86458938997887,0.0068747037303594
0.006851882156656,78.3677876647837,0.0224595762289533,15.798945993220396,78.92215216902044,0.007048979741038
0.0070308836434759,78.4007729946329,0.0230279059496065,15.805595835717993,78.96940468814373,0.0072267080920771
0.0072119234991173,78.4128881674646,0.0236027074912679,15.808038254560865,78.99580358887002,0.0074064281909682
0.007389852355723,78.4116107254096,0.024167631610991,15.807780722242576,79.00846833864934,0.0075830285036548
0.0075676221072747,78.4168132771086,0.0247320505721677,15.808829556665094,79.02765062881812,0.0077594397589248
0.0077525076819286,78.4237901002514,0.0253190622716938,15.81023608421068,79.04918122627676,0.0079428794505216
0.0079273003442539,78.4291439998824,0.0258740289745766,15.811315430376292,79.06828665950576,0.0081162742212658
0.0081133086152018,78.4338723669047,0.0264646052348362,15.812268669167986,79.08764290839434,0.0083007618891874
0.0082889295538556,78.4492394809904,0.027022201715062,15.815366679367663,79.11691544119466,0.0084749159082229
0.0084758169682585,78.4684796911711,0.0276155692557912,15.819245505740094,79.15098417473273,0.0086602089922802
0.008661757380329,78.501374583899,0.0282059300641151,15.825877116114036,79.19876175915896,0.008844529086138
0.0088499547449781,78.5073777474189,0.028803456696876,15.827087353879651,79.21959313492539,0.0090310518765457
0.0090323480950432,78.5099936998133,0.0293825555833327,15.82761472988236,79.23655251988633,0.0092117891044986
0.0092173431548971,78.5084112155368,0.0299699148983688,15.82729570105222,79.24947905898114,0.0093950710567348
0.0094013393316876,78.5015324827351,0.0305541027596786,15.825908948519396,79.25697937730824,0.009577330061246
0.0095886347487956,78.4927884272212,0.0311487657089965,15.824146146927797,79.2628525143284,0.0097628230459405
0.0097661750575503,78.4804989467982,0.0317124561892927,15.82166858767452,79.26437591831449,0.0099386230398101