File: example/data/02 processed data/test_ID_079.csv
Strain,Stress_MPa,Displacement(mm),Force(kN),True Stress (MPa),True Strain
0.0023698307756058194,137.77644701028,0.0075242127125484766,55.55146343454491,138.1029538745586,0.0023670271551837576
0.0024750906135619193,143.910190861978,0.007858412698059094,58.02458895554953,144.2663816245764,0.0024720326216213758
0.0025799699792103193,149.969061001552,0.008191404683992763,60.46752539582577,150.3559766767464,0.002576647569914166
0.0026798601212231193,155.873721832103,0.008508555884883404,62.84828464270393,156.29144160318745,0.0026762756984946264
0.0027791558234948194,161.719839718095,0.008823819739596051,65.2054393743359,162.16928435242218,0.002775301110196911
0.0028834311713960194,167.499673751528,0.009154893969182362,67.53586845661609,167.98264753202184,0.0028792820576118397
0.0029797917765364192,173.236897697518,0.00946083889050313,69.84911715163926,173.75310758066973,0.0029753609967060005
0.0030799960457897194,178.973453111551,0.009778987445382359,72.16209629457737,179.5246906394359,0.0030752625748592566
0.003182438011903319,184.522891125366,0.010104240687793038,74.39962970174757,185.11012378814962,0.003177384774291931
0.003274038158219619,190.060954112163,0.01039507115234729,76.63257669802411,190.68322092831386,0.0032686901651319705
0.003372709008145519,195.474827316139,0.010708351100862023,78.81545037386725,196.13410702709382,0.003367034181232088
0.003466197914931419,200.846590079339,0.011005178379907256,80.98134511998948,201.5427641110931,0.0034602044965286296
0.003570320692606519,206.185990835929,0.011335768199025698,83.13419150504659,206.9221409455361,0.003563962227694051
0.0036751664209378194,211.352309597724,0.011668653386477577,85.21725122980232,212.1290645089452,0.0036684294979902926
0.0037786143314314197,216.201769052837,0.011997100502294756,87.17255328210388,217.01871215586084,0.0037714933010795444
0.0038874188634513197,220.694857495924,0.012342554891457939,88.98416654235656,221.55279084802032,0.0038798823760824884
0.003999623292420119,224.784146798889,0.012698803953433879,90.63296798931204,225.68319870819263,0.0039916460627142806
0.00412960926947902,228.733797776953,0.013111509430595887,92.22546726366745,229.6783789884958,0.00412110583565372
0.0042705253750589195,232.469012521759,0.013558918065812069,93.73150584877324,233.4617773386481,0.004261432559776619
0.00443639479371162,236.150085212514,0.014085553470034392,95.21571435768566,237.19774022108535,0.004426583002943972
0.00461955694362772,239.687593430513,0.01466709329601801,96.64203767118285,240.79484391704636,0.004608919537937211
0.00484018777866472,242.926578816019,0.015367596197260485,97.94799657861886,244.10238907391715,0.004828511730816951
0.00511825545435712,245.853390899918,0.016250461067583856,99.12808721084694,247.11173135886372,0.0051052017075700245
0.00545394482059052,248.555221403772,0.0173162748053749,100.21746527000087,249.91082786617787,0.005439125920096949
0.005853165392054919,250.902020237898,0.01858380011977437,101.16369455992049,252.3705912595511,0.005836102169700923
0.00627905389966302,252.870839334453,0.019935996131430087,101.95752241965145,254.45862896428707,0.006259422774465292
0.00674211386359312,254.407588266955,0.021406211516908153,102.57713958923625,256.1228331948129,0.006719487456857116
0.00721829974383532,255.531847760964,0.02291810168667714,103.0304410172207,257.3763532321987,0.007192372510504239
0.007706638961819119,256.286653360677,0.024468578703775702,103.33477863502497,258.26176206886066,0.007677094514946909
0.008217303725929319,256.95641214845,0.026089939329825586,103.60482537825504,259.06790103139883,0.008183725508527001
0.008716422917823619,257.546177155034,0.02767464276408999,103.84261862890972,259.791058555986,0.008678654216882123
0.00923575186764062,258.127631309282,0.029323512179758964,104.0770609439025,260.51163406223634,0.009193363106192237
0.00973659844767332,258.619452120169,0.030913700071362786,104.27536309485215,261.13752587622037,0.009689503224434364
0.01023878225170512,258.973492012067,0.03250813364916375,104.41811197926543,261.62506520574226,0.010186720981815106
0.01072822008932582,259.310833572775,0.034062098783609475,104.55412809654288,262.0927772668902,0.010671081039769853
0.01120471260877202,259.618824598078,0.03557496253285116,104.67831007794504,262.52777891552665,0.011142404811752075
0.011684991365234319,260.041615675276,0.03709984758461896,104.84877944027129,263.0801997090432,0.011617249055156148
0.01215558712659752,260.382197795638,0.03859398912694712,104.98610215120124,263.5472962871578,0.012082301268107864
0.01260986184527402,260.648989164572,0.04003631135874501,105.09367243115545,263.9357369080476,0.012531019638455008
0.01304665127625832,260.811195335997,0.041423117802120164,105.15907395947399,264.21390805048986,0.012962276798713396
0.01347221676317752,261.016864517787,0.042774288223088625,105.24199977357172,264.53334029541554,0.013382273374996562
0.01389868414452082,261.226876823532,0.0441283221588536,105.3266767352481,264.8575866745619,0.013802983159715834
0.01432083376754372,261.469101411185,0.045468647211951305,105.42434168898981,265.21355694784364,0.014219259233770803
0.01474199406873252,261.756698501526,0.046805831168225745,105.54030083581529,265.6155141982865,0.014634387145493614
0.015161011565728919,262.018551534244,0.048136211721189315,105.6458799786072,265.99101782449026,0.015047231997474089
0.01556011517513772,262.335682933892,0.04940336568106226,105.77374735894524,266.41765637489175,0.01544029789834218
0.01595489404508882,262.653027283427,0.050656788593157,105.90170060067776,266.8436285043559,0.0158289525458627
0.01634606983290902,262.900461224357,0.05189877171948614,106.00146596566074,267.1978505226343,0.016213911072777403
0.01674327650615112,263.137410227345,0.0531599029070298,106.0970038036655,267.54319264589395,0.01660465305272144
0.01714275193308872,263.344460996489,0.05442823738755668,106.18048667378436,267.8589097643047,0.01699747293199562
0.01752891386065882,263.595457793619,0.05565430150759174,106.28168858238718,268.2159998673443,0.017377054501542054
0.01791173256035912,263.81374987706,0.0568697508791402,106.36970395043059,268.5391112106033,0.01775320765038189
0.01828433668840882,264.045644409485,0.05805276898569801,106.46320382590437,268.8735438729759,0.018119188252973126
0.01865298597814632,264.28337869584,0.059223230480614564,106.55905829016268,269.2130528529106,0.018481152550705995
0.01902857943276452,264.60507871627,0.060415739699027346,106.68876773840006,269.64013747493544,0.018849800395636586
0.01939690202030862,264.885428596166,0.061585163914479865,106.80180480997413,270.02338530125326,0.019211179896534532
0.01977621315891022,265.150683495032,0.06278947677953994,106.9087555851969,270.39435993106054,0.01958320436091468
0.02015707873808862,265.462365282539,0.06399872499343136,107.03442568191973,270.8133110815384,0.019956614202419544
0.020542446698727918,265.742050886627,0.06522226826846114,107.14719491748802,271.2010428025762,0.020334296424046487
0.02091927594376792,266.006820726819,0.06641870112146314,107.25395011705344,271.57149081252777,0.02070347233867712
0.02129336968363452,266.155063356881,0.0676064487455396,107.31372154549442,271.82240151411025,0.02106983354484423
0.02167060934485452,266.304350025228,0.0688041846699131,107.37391393017194,272.0753275614601,0.02143913977772923
0.02204582884008172,266.492801799599,0.06999550656725946,107.44989768559833,272.3678564951868,0.02180633308540406
0.022432980401090218,266.654651593635,0.07122471277346144,107.51515552255364,272.63651016669456,0.022185061946653397
0.02281403328787442,266.910090703579,0.07243455568900128,107.61814857168305,272.99938639776,0.022557684802125277
0.02319109230343432,267.121770043511,0.07363171806340396,107.70349768154364,273.31661566884685,0.02292626552082682
0.023569866627832118,267.316137644555,0.07483432654336697,107.78186669828457,273.61674335630437,0.023296386249453075
0.02393676707412792,267.524428757004,0.07599923546035614,107.865849674824,273.92809869479953,0.023654773806478544
0.02430755815736652,267.652662087795,0.07717649714963869,107.91755335379897,274.1586447374681,0.024016831284408787
0.02467957201750392,267.872228595384,0.07835764115557493,108.00608256965883,274.48320055249303,0.024379951050996326
0.02504601234863772,268.189317481,0.07952108920692476,108.1339328083392,274.90639043840184,0.024737501679073275
0.025415551441980818,268.45280001784,0.08069437582828909,108.24016896719309,275.2756759664372,0.025097946472450092
0.02578268852521102,268.730444616159,0.08186003606754498,108.35211526923531,275.6590379669389,0.025455919758500457
0.02614097621549692,268.940644445648,0.08299759948420271,108.43686784048526,275.9710154354821,0.025805141028359378
0.02650560660240602,269.154784567965,0.08415530096263911,108.5232091378035,276.28889540287884,0.02616041932497093
0.02686845457736772,269.370749597563,0.0853073432831425,108.61028623773743,276.60832534759663,0.026513835670875112
0.02724366566822102,269.567255193961,0.08649863849660173,108.68951729420507,276.9112553695653,0.02687916246226925
0.02762475917865352,269.751307660036,0.08770861039222493,108.76372724852652,277.20312257227135,0.027250080142636163
0.02800083372678712,269.867746044794,0.0889026470825491,108.81067520526095,277.4242679300171,0.027615978050919966
0.02837274148436742,270.04963635514,0.09008345421286655,108.88401337839247,277.7116848753919,0.027977690306045643
0.02874094251521822,270.119737894933,0.09125249248581785,108.91227831923699,277.8832337539971,0.028335668610936338
0.02909753693028702,270.284037316762,0.09238467975366128,108.97852384611845,278.1486370742536,0.028682240435887442
0.02946205385900462,270.414574806791,0.09354202100233966,109.03115656209813,278.3815435740085,0.02903638800019254
0.02983648544865082,270.545121726803,0.09473084129946635,109.08379308024698,278.6172373144082,0.029400037647512034
0.03021814057672832,270.695537034302,0.0959425963311124,109.14444053223056,278.8754528258975,0.029770566785547948
0.03060601115001302,270.946506680678,0.09717408540129133,109.24563149364937,279.2390984852039,0.0301469895652787
0.030984600565428618,271.264814565562,0.09837610679523585,109.3739732328346,279.66984649233103,0.03051426851728783
0.031356826125833515,271.545479716983,0.0995579229495214,109.48713742188755,280.0602841097245,0.030875242272291954
0.031726241257351115,271.818494035725,0.10073081599208979,109.59721679520432,280.44227315571226,0.03123336176956876
0.03209289579489702,272.022574012328,0.10189494414879803,109.67950184177066,280.7525661339653,0.03158867831336921
0.03245631605248132,272.234548687916,0.10304880346662817,109.76497003096773,281.0702792405356,0.03194073604999528
0.03282509636288641,272.410081592094,0.10421968095216436,109.83574489793232,281.35196877057626,0.03229785959946184
0.033181420589225116,272.58508187631,0.10535101037078974,109.90630501252821,281.62984212439625,0.032642799682610676
0.03355172611949241,272.733017557281,0.1065267304293884,109.96595267909571,281.8836810661056,0.033001148349752055
0.03391857806684041,272.913893669856,0.1076914853622183,110.03888192768595,282.1707448778224,0.033356028369508926
0.03428973902923812,273.008838514088,0.10886992141783101,110.07716368888029,282.37024033941145,0.03371494866135187
0.034674342441401815,273.052662933275,0.11009103725145075,110.09483369469646,282.52058447236,0.03408673222206061
0.035048572449507216,273.184227516102,0.1112792175271854,110.14788053449233,282.7589447062628,0.034448355519064576
0.03542799941315752,273.310770886458,0.1124838981367751,110.19890282141988,282.993624717033,0.034814867242069655
0.035812288362304615,273.582292815553,0.11370401555031714,110.30838046323098,283.37990077668405,0.03518593858113623
0.036193083852290114,273.861052240314,0.11491304123102111,110.42077626329461,283.7729282679241,0.03555350084654259
0.03657476826541332,274.177264359078,0.11612488924268727,110.54827298958024,284.20523426665625,0.035921785618083596
0.03695179534088842,274.415739342069,0.11732195020732072,110.64442610272224,284.55589358055573,0.03628544344262998
0.037330831535289516,274.563678630483,0.1185253901245442,110.70407522381076,284.813369063147,0.03665090588608759
0.037717503550589115,274.648181224848,0.11975307377312043,110.73814666985871,285.007224975359,0.037023593127379247
0.03810457626852202,274.621492317797,0.1209820296525574,110.72738570253574,285.0858279167958,0.03739652751918688
0.038488729955681714,274.65098708763,0.12220171760928944,110.73927799373243,285.22195476170725,0.03776651204180918
0.03886676876110461,274.763803900308,0.12340199081650714,110.7847657326042,285.44298513042276,0.03813047363608571
0.03923880151952162,274.921347942232,0.12458319482448113,110.84828749030794,285.70893214761657,0.03848852355203989
0.03961633023052922,275.090659621213,0.12578184848193028,110.91655395927307,285.9887420361011,0.03885173184817566
0.039994716064804016,275.273513957393,0.12698322350575275,110.99028082762086,286.28299998827976,0.03921563243345521
0.040375602067310216,275.41956323051,0.12819253656370994,111.04916789454163,286.53979391705747,0.039581803786163314
0.04075934964275391,275.573424801021,0.12941093511574367,111.11120487977166,286.805618374737,0.03995059061517458
0.04113882234475952,275.793150906315,0.13061576094461147,111.19979844542623,287.13895634535135,0.04031513553991106
0.04152219363446192,276.073142810788,0.13183296478941658,111.31269118130973,287.536305303852,0.040683290790420906
0.041904446508572016,276.336853217773,0.13304661766471615,111.41901921740607,287.9165961017843,0.04105023711916051
0.04228777414568432,276.557186765826,0.1342636829125477,111.50785770398103,288.2521746181451,0.041418080005853855
0.04267124739390801,276.660269700687,0.13548121047565792,111.549420743317,288.46570851315033,0.041785927285906764
0.043054660551629514,276.766162105772,0.1366985472514237,111.59211656104728,288.6822352674133,0.042153581693976226
0.04344914348420872,276.83991662455,0.13795103056236266,111.62185438301859,288.8683738841265,0.04253170986850103
0.04383898894731211,276.931039193133,0.13918878990771594,111.65859500267123,289.07141595948843,0.042905252420273404
0.04423284745315702,277.059515915567,0.14043929066377353,111.7103968171566,289.3146472185058,0.04328249855103382
0.044625611415394714,277.264459004535,0.1416863162438782,111.79302987062853,289.63755501137103,0.04365855463582862
0.04501430569056022,277.401813090244,0.14292042056752868,111.84841103798637,289.8888631038039,0.044030574979110414
0.045420288573257715,277.619178677915,0.14420941622009323,111.93605284293534,290.2287218869367,0.04441899458230267
0.045829962492676714,277.800231634305,0.14551013091424855,112.00905339495179,290.5318058305621,0.04481079267002634
0.046236911238778114,277.930234795584,0.14680219318312052,112.06147066957946,290.7808703924002,0.04519983257725286
0.04662949653890332,278.137146361732,0.14804865151101804,112.14489741305034,291.1065414653468,0.04557499776053538
0.04702189977307532,278.19301416585,0.14929453177951413,112.16742331167072,291.27417819552636,0.04594984835835509
0.047404136499359914,278.400228773027,0.15050813338546773,112.25097224128447,291.59755121923655,0.04631485215787666
0.047798386758205115,278.544182754686,0.15175987795730123,112.30901448668939,291.8581453312426,0.04669118834411353
0.048191909787692416,278.709827673617,0.1530093135759234,112.37580251800237,292.1413865458072,0.04706668916084899
0.048588122851415616,278.882083611447,0.15426729005324458,112.44525611213544,292.4324405510187,0.04744461441983795
0.04898571934077792,278.924988591528,0.15552965890696988,112.46255540010411,292.5883297998023,0.04782371572833692
0.04938254473809912,279.030754340558,0.15678957954346467,112.505200150113,292.81000305008615,0.04820193856828822
0.04977166390215482,279.209488090874,0.15802503288934153,112.57726559824039,293.1062088904257,0.04857267757060736
0.05016325627245512,279.374457611049,0.159268338665045,112.64378130877496,293.38879012417027,0.04894563424757613
0.050559478650158814,279.539378778832,0.16052634471425423,112.71027752362505,293.672744032079,0.04932285907198089
0.050960778328778815,279.639560127096,0.16180047119387272,112.7506706432451,293.8902097626902,0.049704772767235623
0.05137690874481492,279.71021938073,0.16312168526478735,112.77916045431033,294.0808657968459,0.050100646773613464
0.051784010698409016,279.911159252306,0.16441423396744861,112.86017941052978,294.4060817176315,0.05048778021158786
0.052199534010160316,280.061063916765,0.165733520482259,112.92062097123966,294.6801209476099,0.05088276744254664
0.05261455434873562,280.190298613589,0.16705121005723558,112.97272840099907,294.9323863079821,0.05127712088805894
0.053031722732603814,280.324296812225,0.1683757196760171,113.02675647468912,295.19037719598305,0.05167335874991354
0.053457645340028816,280.370479375717,0.16972802395459147,113.0453772842891,295.358425025998,0.052077749695042364
0.05388381696359042,280.512550541143,0.17108111885939956,113.10266037818887,295.6276374704919,0.05248221345850438
0.054313848558262615,280.630889447085,0.1724464691724838,113.15037462506467,295.8730330772845,0.052890174825381206
0.05474129680951911,280.827289589066,0.17380361737022318,113.22956316231142,296.2001396006739,0.05329552056330371
0.05516866222531352,281.068817560503,0.1751605025653704,113.32694724039482,296.5750082185667,0.05370062355815803
0.055595868762355415,281.243447812842,0.17651688332047843,113.3973581581379,296.87942162771714,0.05410541200007415
0.056019685497860315,281.259715829886,0.17786250145570648,113.40391742261004,297.01579665389374,0.054506826680261286
0.05644554832517592,281.303273630561,0.17921461593243354,113.42147992784221,297.18159115630505,0.05491001706301056
0.056876166375592514,281.35383085149,0.1805818282425062,113.44186459932077,297.35615814540967,0.055317544277992334
0.057313283658843216,281.521614825857,0.1819696756168272,113.50951509778555,297.65654299246694,0.055731052433065274
0.057744908991543616,281.778126991851,0.18334008604815097,113.61294080311434,298.0493792908031,0.05613919755190123
0.05818797982023992,282.005944259372,0.18474683592926172,113.70479672537878,298.41530045312396,0.05655799234214699
0.058624364230800315,282.146873779865,0.186132356432791,113.76161950804158,298.6875548749175,0.056970295698151964
0.059063297083177216,282.177454959616,0.18752596823908765,113.77394983971718,298.8437858120707,0.0573848354498641
0.05949715327608852,282.09981258251,0.18890346165158103,113.74264443326805,298.8839483708875,0.057794411866626566
0.05993260277937031,282.113143223327,0.19028601382450072,113.74801934764544,299.02091817497023,0.058205323818923765
0.060371746738272815,282.220469476222,0.19168029589401617,113.7912932928127,299.25861218379686,0.05861955111160608
0.060812244627087515,282.374629831611,0.19307887669100285,113.85345074810556,299.54646489741424,0.059034883206266556
0.061246858685152415,282.577465066359,0.1944587763253589,113.93523391475595,299.88444713688693,0.059444498625048546
0.061691000727248015,282.780511510563,0.19586892730901242,114.01710224105898,300.22552425181266,0.05986292071555513
0.062136980562981815,282.882851090671,0.19728491328746725,114.05836555975856,300.46033731049295,0.06028289808304246
0.06258969766416772,283.053259068394,0.1987222900837325,114.12707405637649,300.76947697634216,0.06070903958413626
0.06305162595498952,283.069653883892,0.20018891240709172,114.13368444598525,300.9176558197875,0.06114366445989545
0.06351220049182112,283.216678606412,0.20165123656153203,114.19296481410532,301.2043930806901,0.06157682761098939
0.06397609115494562,283.324890866277,0.20312408941695234,114.23659599728288,301.4509099108029,0.062012919947946187
0.06444972700806682,283.417087440238,0.20462788325061215,114.27376965590396,301.68324135518276,0.06245797737667818
0.06491124468396732,283.510476986082,0.20609320187159624,114.31142432078826,301.9134949281938,0.0628914573636439
0.06538513838800292,283.619854734811,0.20759781438190925,114.35552542907578,302.1643781862319,0.06333636607739693
0.06584668066959982,283.718970067868,0.20906321112597942,114.39548873136437,302.40092248983467,0.06376948863561432
0.06631124566286672,283.820695892193,0.21053820497960185,114.43650458373223,302.641199781706,0.06420525842065788
0.06678512630014913,283.911688054878,0.21204277600297347,114.47319262372683,302.8727659997116,0.06464957087771031
0.06726327594752063,283.931526475273,0.21356090113337797,114.48119147483008,303.0296910907801,0.06509768597657058
0.06775340206503522,284.106430877454,0.2151170515564868,114.55171292978945,303.35560811795625,0.06555681693434906
0.06823607588599713,284.17269933509,0.21664954093804087,114.57843237190828,303.56352921164785,0.0660087609482687
0.06871737415986132,284.28941217031,0.21817766295755966,114.62549098706901,303.8250340761042,0.06645921370098724
0.06920754157221302,284.33495760875,0.21973394449177633,114.643854907848,304.013081007891,0.06691775872970515
0.06969536346935862,284.434528508054,0.2212827790152136,114.68400189444736,304.25829635565844,0.06737390089908928
0.07019178607472643,284.551715579619,0.2228589207872564,114.73125172170238,304.52490872678004,0.06783787173454103
0.07067832243935662,284.621176102119,0.22440367374495726,114.75925820437439,304.7377233597335,0.06829239381981024
0.07117264078584362,284.635739570734,0.2259731344950535,114.76513019491995,304.89401681801485,0.06875397435342431
0.07167194356398503,284.64147681316,0.22755842081565245,114.76744345106613,305.04228467528213,0.06921999301928945
0.07217499059012972,284.73450776652,0.22915559512366185,114.80495353146085,305.28521818525377,0.06968928681761337
0.07268113872134423,284.88226707834,0.2307626154402679,114.8645300859867,305.58783465111185,0.07016125147173904
0.07317503980930093,285.078058796591,0.23233075139453044,114.94347330678549,305.93865709778976,0.07062158157365352
0.07368195705027672,285.243529213381,0.23394021363462858,115.01019097883523,306.2608306817507,0.07109382285580503
0.07418655899835483,285.375847372049,0.23554232481977658,115.06354166041015,306.546899509821,0.07156368584191543
0.07468785087647552,285.401457258112,0.23713392653280976,115.07386756647075,306.7174787377346,0.0720302481360267
0.07518366794179862,285.385894005675,0.2387081457152106,115.06759246308818,306.842252295871,0.07249150088510839
0.07566890247461772,285.350060452307,0.24024876535691123,115.05314437437019,306.9421863477989,0.07294270293189249
0.07617146412196323,285.333504646757,0.24184439858723322,115.04646907357241,307.0677754587515,0.07340980231740861
0.07667760144201623,285.376520887973,0.24345138457840151,115.06381322203072,307.25850801753023,0.0738800046529779
0.07719233522674593,285.426258175097,0.2450856643449183,115.08386729619912,307.4589775786648,0.07435796647023116
0.07771976697084902,285.55984147033,0.24676026013244562,115.13772808083706,307.7534858056366,0.07484748226449245
0.07823365055759862,285.603928900586,0.2483918405203756,115.15550413271629,307.9477668720717,0.07532419348868084
0.07873876900464602,285.661528530465,0.2499955915897511,115.17872830348348,308.15416563893933,0.07579255224162525
0.07924107633040513,285.668533140374,0.25159041734903625,115.1815525621988,308.30521518014524,0.07625808702029051
0.07975258729640733,285.606187697812,0.25321446466609326,115.15641487975779,308.38402011457583,0.07673192905529998
0.08026140947146312,285.60279932793,0.2548299750718954,115.15504868902137,308.52568255098504,0.07720305765467826
0.08075925473623642,285.61088028489,0.25641063378755063,115.15830693086765,308.67660212125816,0.07766380778245467
0.08123266030101452,285.657564077262,0.2579136964557211,115.17712983595204,308.8622879423655,0.07810174241953778
0.08171934208842932,285.691764313377,0.2594589111307631,115.19091937115361,309.03830733314874,0.07855175868905319
0.08220042716824842,285.688710201563,0.2609863562591887,115.18968795327021,309.1724442172774,0.07899640094851232
0.08269101876041712,285.632469074567,0.2625439845643244,115.16701153086541,309.25170893339623,0.07944962607579446
0.08317214793736882,285.591153141452,0.264071569701146,115.15035294663346,309.34438278013664,0.07989391008437235
0.08364862990623072,285.505186573964,0.2655843999522825,115.11569122662229,309.38730426199885,0.080333708319108
0.08412485990282133,285.428461136068,0.2670964301914577,115.08475553006261,309.44009044141757,0.08077308079643615
0.08458677810533882,285.293884021953,0.26856302048445074,115.03049403765145,309.4259744845282,0.08119906477826873
0.08505826098379832,285.161281365779,0.2700599786235596,114.9770286466821,309.4166040586638,0.08163368231006453
0.08551012990396652,285.06464640289,0.2714946624450937,114.93806542964525,309.4405613478294,0.0820500423092178
0.08596624955699432,284.98170222387,0.27294284234345695,114.90462233666437,309.48051035642425,0.0824701432728298
0.08642646387757963,284.871007552784,0.2744040228113153,114.85999024528252,309.4914013968144,0.0828938367649169
0.08687784914831052,284.677073224622,0.2758371710458859,114.7817959241676,309.40920504821327,0.0833092275360261
0.08733123951650733,284.435055004856,0.27727668546491074,114.68421417795795,309.275120920376,0.08372628988493502
0.08775512506101422,284.127042319073,0.2786225220687201,114.56002346305023,309.06064645099934,0.08411605422420575
0.08818421365628622,283.781196369881,0.2799848783587087,114.42057837633602,308.8062180221991,0.08451044812407145
0.08862733012757702,283.467194411152,0.28139177315505703,114.29397278657649,308.59013503056724,0.08491757246028396
0.08907340330771023,283.108923621583,0.28280805550197996,114.14951800422229,308.32639895534004,0.08532724600222041
0.08952231909163483,282.7318608074,0.28423336311594055,113.99748627754367,308.0426726679717,0.08573936082064453
0.08997565534471592,282.339751190538,0.28567270571947306,113.83938768002493,307.74345533377067,0.0861553614455005
0.09043580954412542,281.911274640884,0.2871336953025982,113.66662593520444,307.40614898264863,0.08657744160206789
0.09087058071823302,281.443522531,0.28851409378038984,113.4780282844992,307.01845886277704,0.08697607535824815
0.09129628066475562,280.907153090935,0.28986569111059907,113.261764126265,306.5529313802625,0.08736623796171936
0.09172128465531262,280.328052555867,0.2912150787806176,113.02827079052557,306.0401016612131,0.08775561091288404
0.09215519803208612,279.566728211848,0.29259275375187344,112.7213048150171,305.3302554133932,0.08815298996423904
0.09261372267832402,278.772037536448,0.29404856950367875,112.40088553469585,304.5901537113199,0.08857273655494112
0.09308490946697472,278.007388522394,0.29554458755764473,112.09257905222927,303.88568111415117,0.08900389095932269
0.09354972369746502,277.208453279013,0.2970203727394514,111.77044836209804,303.14122748986625,0.08942903216073006
0.09390768274601143,276.611939036781,0.29815689271858625,111.5299338196301,302.58792525160607,0.08975631538067967
0.09414719497450452,276.171236572967,0.29891734404405185,111.35224258622031,302.17198382895214,0.08997524245777311