File: example/data/02 processed data/test_ID_107.csv
Strain,Stress_MPa,Displacement(mm),Force(kN),True Stress (MPa),True Strain
-3.67544426085743e-05,7.30456135089725,-0.0001166953552822234,1.4725995683408855,7.304292875816298,-3.675511806960969e-05
-7.08399234006571e-05,9.90229559755114,-0.0002249167567970863,1.9963027924663097,9.901594119689518,-7.084243266650149e-05
-0.0001198229340395,13.0397700640169,-0.0003804378155754125,2.6288176449058067,13.03820760050863,-0.00011983011338071501
-0.0002062691869305,17.5757628564854,-0.0006549046685043375,3.543273791867457,17.57213751817131,-0.00020629046334502018
-0.0002666645861538,22.0682951838714,-0.0008466600610383149,4.448968309068475,22.062410351069072,-0.00026670014747662263
-0.0002816838148809,26.865178005588,-0.0008943461122468574,5.4160198859265405,26.85761051975993,-0.0002817234952184146
-0.0002763523369128,32.2311617662538,-0.00087741866969814,6.497802212076766,32.22225460937828,-0.0002763905292563936
-0.0001958703904421,37.8111131568671,-0.0006218884896536675,7.622720412424408,37.803707079370014,-0.00019588957555227352
-0.000126203292657,43.4969304687404,-0.000400695454185975,8.768981182498065,43.491441012894775,-0.00012621125696262798
-2.20183145984031e-05,49.1985042925969,-6.990814884992984e-05,9.918418465387536,49.19742102445162,-2.201855700500704e-05
7.14830145264626e-05,54.7944450786131,0.00022695857112151873,11.046560127848402,54.79836195072663,7.148045973759566e-05
0.0001793467284789,60.459868366742,0.0005694258629205074,12.188709462735188,60.47071164633785,0.00017933064777711256
0.0002729375950997,66.038836330034,0.0008665768644415474,13.313429404134855,66.0568608112051,0.000272900354410302
0.0003599298489197,71.5871126037478,0.0011427772703200474,14.431961900915555,71.61287894237186,0.00035986508971028186
0.0004732306803194,77.0833770895484,0.0015025074100140949,15.54000882125296,77.11985530852982,0.00047311874199476816
0.0005702757982796,82.4822271466667,0.0018106256595377302,16.628416992768006,82.52926476459663,0.0005701132528306766
0.0006947661078039,87.8928625681192,0.0022058823922773826,17.71920109373283,87.95392755014939,0.0006945248695611947
0.0007977050274523,93.0621547593874,0.0025327134621610523,18.7613303994925,93.13639090810452,0.0007973870298978725
0.0009012856551758,98.1057316708544,0.002861581955183165,19.778115504844248,98.19415295949986,0.0009008797411376872
0.001024017747874,102.817335924311,0.00325125634949995,20.727974922341097,102.92262270108661,0.0010234937993578723
0.0011205492970669,107.652851568021,0.003557744018187407,21.702814876113035,107.77348189517281,0.0011199219503082846
0.0011921132274487,112.41452930998,0.003784959497149622,22.66276910889197,112.54854015732784,0.0011914032246881823
0.0012958923189534,117.205138395467,0.0041144581126770444,23.62855590052615,117.35702363405557,0.00129505337521123
0.0014028586422883,122.0164704067,0.004454076189265352,24.59852043399072,122.18764226671155,0.0014018755554170345
0.0015193419774377,126.68989084011,0.004823910778364697,25.540681993366174,126.88237610938039,0.0015181889451680159
0.0016280710539196,131.345323803303,0.005169125596194729,26.47921727874588,131.55916332305483,0.0016267471829505176
0.0017320649928989,135.961531552653,0.005499306352454007,27.40984476101485,136.19702576183627,0.0017305666981754979
0.0018313830663374,140.415170717672,0.0058146412356212445,28.307698416682676,140.67232468358122,0.0018297081290257193
0.0019417460830007,144.834358189437,0.0061650438135272215,29.198606610990502,145.11558973713528,0.001939863330898975
0.0020499371044274,149.249287297668,0.006508550306556994,30.088656319209868,149.5552389495088,0.002047838850397844
0.0021313756535727,153.827071091686,0.006767117700093321,31.0115375320839,154.15493436587124,0.00212910749477832
0.0022453670355896,158.135087781097,0.00712904033799698,31.88003369666916,158.49015909437074,0.0022428499661529292
0.0023622335493904,162.188065728032,0.00750009151931452,32.697114050771255,162.5711918182055,0.0023594478618201276
0.0024842506071617,166.087194110849,0.007887495677738398,33.48317833274716,166.49979632366063,0.002481169957637491
0.0026353256718792,169.938475489529,0.00836715900821646,34.25959665868905,170.38631871662656,0.0026318592898755162
0.0027377435408878,173.797318658583,0.008692335742318764,35.03753944157034,174.27313114516414,0.002734002747040626
0.0028555304486575,177.359778905154,0.009066309174487561,35.755731427279045,177.86623515418484,0.0028514611663849176
0.0029679378978296,180.663594519837,0.009423202825608979,36.42178065519914,181.19979284877056,0.0029635422653087494
0.0030641673928487,183.601621767056,0.009728731472294623,37.01408694823849,184.16420786974874,0.003059482399904903
0.0031787354244523,186.205668849179,0.010092484972636052,37.53906283999449,186.79756740498374,0.003173693925904427
0.0033083022558326,188.208343025888,0.010503859662268505,37.942801954019025,188.8309931116871,0.0033028418636954484
0.0034627504434666,189.628412029415,0.010994232658006454,38.22908786513006,190.2850478972637,0.0034567689275038353
0.0036486153919695,190.454603262109,0.01158435386950316,38.39564801764117,191.14949885904258,0.0036419753412564124
0.0038544564387466,190.953160116214,0.012237899193020454,38.49615707942875,191.68918075372295,0.003847047054856118
0.0041052068458425,191.235983099152,0.013034031735549938,38.55317419278905,192.02104636614206,0.004096803474752674
0.0043845838134074,191.346757112375,0.013921053607568493,38.5755062338548,192.1857330063579,0.0043749995309795555
0.0046792452695637,191.370191541496,0.014856603730864747,38.5802306147656,192.26565960500204,0.0046683316332290095
0.0050155272622965,191.295592726805,0.015924299057791386,38.565191493723894,192.25504098728348,0.005002991403924169
0.0053581154142023,191.199186049074,0.0170120164400923,38.545755907493316,192.2236533550265,0.0053438117847226544
0.0057273318124164,191.130033062707,0.018184278504422068,38.531814665441736,192.22469818137526,0.005710993003075613
0.0061037924809174,191.040237615619,0.019379541126912744,38.51371190330879,192.20630758152987,0.006085239795809781
0.0064718364652591,190.985492019594,0.020548080777197643,38.50267519115015,192.2215188911819,0.006450984052225447
0.0068487440265859,190.930081965292,0.02174476228441023,38.49150452420287,192.23771322364735,0.006825397912970566
0.0072317702035108,190.82419745406,0.022960870396146787,38.470158206738496,192.20419419931713,0.007205746343766865
0.0076242111280294,190.694663848783,0.024206870331493345,38.44404423191465,192.14856022695471,0.00759529371898117
0.0080279691490935,190.567976205197,0.025488802048371863,38.418504002967715,192.0978500389775,0.007995916435950896
0.0084092852653724,190.451780558073,0.02669948071755737,38.395078960507526,192.05334391008392,0.008374124208089034
0.0087984427858641,190.406246866879,0.027935055845118514,38.38589936836281,192.08152533600835,0.008759962037191085
0.0091694250144017,190.34570124783,0.029112924420725397,38.373693371562524,192.09106188223566,0.009127641065818388
0.0095549196604869,190.260592961135,0.030336869922045904,38.35653554096481,192.07851764143524,0.009509560124542696
0.0099282942314339,190.20311835389,0.03152233418480263,38.344948660144226,192.09151087664367,0.009879332522384678
0.0103022474374061,190.159374000059,0.032709635613764367,38.336129798411896,192.11844292354985,0.010249540973875976
0.0106824558857821,190.15041245419,0.03391679743735816,38.3343231507647,192.18168584689514,0.010625801568264764
0.0110474085261509,190.094019796276,0.03507552207052911,38.32295439092925,192.19406609134367,0.010986831645286526
0.0114564307437464,190.015976248341,0.036374167611394816,38.307220811665545,192.19288112043546,0.011391302791624924
0.0118543046129875,189.952887776217,0.037637417146235315,38.294502175685345,192.20464717003293,0.011784592727191363
0.012272955310158,189.911919029671,0.038966633109751646,38.28624287638168,192.2426995247885,0.012198253183655031
0.0126311918169505,189.920150737411,0.04010403401881783,38.28790238866206,192.3190685912794,0.012552083769698737
0.013030327661515,189.869281917871,0.041371290325310124,38.2776472346428,192.34334087411742,0.012946163279914743
0.0134244475276235,189.811374475979,0.042622620900204605,38.26597309435736,192.35948731277787,0.013335138031192925
0.0138083946979132,189.726666027133,0.043841653165874406,38.24889587107001,192.34648671635483,0.013713927449836169
0.0142341345910487,189.632350309475,0.045193377326579624,38.229881822390155,192.33160270659693,0.014133780478794676
0.0146184295678527,189.588941221198,0.04641351387793232,38.22113055019352,192.36043380528386,0.01451261035356112
0.0150200357981768,189.512017561644,0.047688613659211336,38.20562274042743,192.35849484960463,0.014908352001562628
0.0154339743011847,189.485547669399,0.04900286840626142,38.200286410150845,192.4100627425744,0.015316082003506431
0.0158489900727657,189.434512719138,0.05032054348103109,38.18999776417822,192.43685843066282,0.015724706291342788
0.0162660145403659,189.323900185104,0.05164459616566173,38.167698277316966,192.4034454983537,0.016135140221024698
0.0166556222839093,189.251914723255,0.052881600751412024,38.15318600820821,192.40402313139217,0.016518438564901945
0.0170467246854231,189.150703304765,0.054123350876218335,38.13278178624062,192.37510326805548,0.016903059654529932
0.0174398788124927,189.09236897185,0.05537161522966432,38.12102158472496,192.39011697108623,0.01728954942672859
0.0178215704147078,189.027074188145,0.05658348606669727,38.10785815633004,192.39583350107523,0.017664628124194975
0.01821866585868,188.892626579584,0.057844264101308995,38.08075351844413,192.33399822640587,0.01805469453047973
0.0186182061482781,188.778503625583,0.05911280452078296,38.05774633091754,192.29322072244756,0.018447009006139006
0.019043066893951,188.70721227552,0.060461737388294426,38.04337399474483,192.30077634225373,0.0188640172277218
0.0194321203266027,188.686428524546,0.06169698203696357,38.03918399054847,192.3530059076319,0.01924572747841771
0.0198097518579403,188.701808747056,0.06289596214896044,38.04228464340649,192.4399447534797,0.01961609211324116
0.0201652140219826,188.695944652423,0.06402455451979475,38.04110244192848,192.5010387614193,0.019964588711077105
0.0205425189257314,188.644305616881,0.0652224975891972,38.03069201236321,192.51953483524724,0.020334367197193812
0.020957209456174,188.588739510177,0.06653914002335244,38.01948988525168,192.5410332251676,0.020740627879359146
0.021354690300338,188.525937268718,0.06780114170357315,38.00682895337355,192.55185027267243,0.021129873860083262
0.0217615366289434,188.441330232937,0.06909287879689528,37.9897721749601,192.54210314320787,0.021528134447141828
0.0221646712581907,188.34496168807,0.07037283124475546,37.97034427631491,192.51956584702256,0.021922605277761024
0.0225815011399161,188.289321415288,0.07169626611923362,37.95912719732206,192.54117694146134,0.022330313474627987
0.022993889615208,188.208920994761,0.07300559952828539,37.94291847254382,192.53657614871193,0.022733513945989166
0.0233957270583503,188.152229249867,0.0742814334102622,37.93148941677318,192.554187450817,0.023126242139127923
0.0237923677742554,188.049890384258,0.0755407676832609,37.910857901466414,192.52404253618866,0.02351374021208894
0.0241772092279408,187.940966259056,0.07676263929871203,37.88889879782569,192.4848543228026,0.023889567531534445
0.0245926950001579,187.875873784645,0.07808180662550132,37.875776154984436,192.4962478465189,0.02429516288614736
0.0250120448879231,187.77151445873,0.07941324251915584,37.85473731487997,192.46806400704506,0.024704363631496713
0.0254217745703693,187.699640649775,0.08071413426092253,37.84024755499464,192.47129860131292,0.025104015338380796
0.0258308311272326,187.629322923286,0.0820128888289635,37.82607150133446,192.47594427823438,0.02550285121178759
0.0262379601058902,187.56614841399,0.08330552333620138,37.81333552026039,192.48750153329175,0.025899649784758207
0.0266333318481865,187.513051995655,0.08456082861799213,37.80263128232405,192.5071493353215,0.02628483881120547
0.0270288466161634,187.418084482221,0.08581658800631879,37.78348583161576,192.4837791407861,0.026670018785803638
0.02743399943979,187.309118380182,0.08710294822133324,37.76151826544469,192.4477566288915,0.027064431203294263
0.0278416452949349,187.24071107622,0.0883972238114183,37.74772735296595,192.4538005387755,0.02746111362546431
0.0282578927044482,187.240018563398,0.08971880933662303,37.747587742381036,192.53102691794138,0.027866003960301707
0.0286762030540588,187.215453166208,0.09104694469663668,37.74263535830753,192.58408151605983,0.028272735859238157
0.0290813258413418,187.095155207952,0.0923332095462602,37.718383289923125,192.53613037989086,0.028666487588320314
0.0294949890320759,186.942247562701,0.09364659017684097,37.687557108640526,192.45610710419447,0.029068380093653413
0.0299040354971824,186.81296434869,0.09494531270355411,37.66149361269591,192.39942586590712,0.02946562848079316
0.0303044990733391,186.778708245852,0.09621678455785164,37.65458758236376,192.4389434368079,0.029854388719847202
0.0307040121548226,186.763129089637,0.09748523859156175,37.651446824470824,192.4975064752779,0.030242075703487272
0.0311099094229956,186.733226642114,0.09877396241801102,37.64541849105018,192.54248040921388,0.0306358040309263
0.0315343926565267,186.655611438806,0.10012169668447228,37.629771266063294,192.54168278146142,0.031047395345139575
0.031949330179035,186.558747586648,0.10143912331843612,37.610243513468234,192.51917461108107,0.03144956719026638
0.0323670110781765,186.430157192331,0.10276526017321039,37.58431968997393,192.46434415548134,0.031854234727400565
0.0327880298189902,186.336446206,0.10410199467529388,37.5654275551296,192.446051160567,0.0322619704550423
0.0331973683455072,186.221092340618,0.10540164449698534,37.54217221586859,192.40314253675217,0.032658235145235165
0.0336107808262513,186.130905874209,0.10671422912334788,37.52399062424053,192.38691095653866,0.03305828435775972
0.0340244312328168,186.05273368237,0.10802756916419334,37.50823111036579,192.38307212522338,0.03345840369183914
0.0344552741396546,185.974643037684,0.10939549539340335,37.4924880363971,192.3824503465718,0.03387498299106981
0.0348791857361459,185.925948631204,0.11074141471226323,37.48267124405073,192.41089432668088,0.034284691146653834
0.035298180522961,185.852393778342,0.11207172316040116,37.46784258571375,192.41264512455436,0.034689482348958925
0.0357264985438507,185.75900491053,0.11343163287672597,37.449015389962845,192.39552372897322,0.0351031114392597
0.0361525293202222,185.636208127231,0.11478428059170548,37.42425955844977,192.3474265844456,0.03551436207372858
0.0366005035318482,185.506406202914,0.11620659871361802,37.39809149050746,192.29603407832423,0.03594661252662935
0.0370301634397326,185.419387348331,0.11757076892115101,37.38054848942353,192.2854975667348,0.03636101603722233
0.0374661871196865,185.335453912378,0.11895514410500464,37.363627508735405,192.27926670857116,0.0367813818636139
0.0378888954541397,185.306604552082,0.12029724306689353,37.357811477699734,192.32766711891745,0.03718874188007376
0.038294188532254,185.207268152801,0.12158404858990643,37.33778525960468,192.2996301969881,0.0375791632127478
0.0387092698873576,185.061195350852,0.12290193189236037,37.30833698273176,192.22477910736515,0.03797885572067009
0.0391245694110502,184.901209852109,0.12422050788008437,37.27608390618517,192.135390071155,0.038378598492558924
0.039580815038925,184.767744055755,0.12566908774858687,37.24917720164021,192.08100195838526,0.038817569439201095
0.0400028577916615,184.714219422002,0.12700907348852528,37.23838663547561,192.10331607363813,0.03922346102610356
0.0404429485985595,184.654425428981,0.12840636180042642,37.22633216648257,192.12239486510182,0.039646534592461875
0.0408659268315849,184.532459864574,0.12974931769028206,37.20174390869812,192.07354986745207,0.04005298866935727
0.0413059773585446,184.431872381127,0.1311464781133791,37.1814654720352,192.05001112589582,0.04047567282202099
0.0417337260710404,184.309910353822,0.13250458027555326,37.15687792733052,192.00184966470644,0.040886369476341985
0.0421608070299711,184.273804056092,0.13386056232015822,37.149598897708145,192.04293634957958,0.04129625678889662
0.0425880301304906,184.236809961995,0.13521699566430767,37.14214088833819,192.0830927758019,0.04170611249802073
0.0430137073315524,184.144834626606,0.13656852077767886,37.12359866072377,192.06558664985195,0.042114318148530734
0.0434446383724452,184.119804044018,0.1379367268325135,37.11855249527403,192.11882234791582,0.04252739233993027
0.0438856458974799,184.024292204556,0.13933692572449866,37.09929730843849,192.1003171287795,0.042949948880138714
0.044322734725137,183.934889391904,0.14072468275230998,37.081273701407845,192.08738670111876,0.043368574567207295
0.044768886072775,183.83797332308,0.14214121328106064,37.06173542193293,192.06819460663084,0.043795699304082704
0.045206854292628,183.740058774064,0.1435317623790939,37.04199584885131,192.04636883878203,0.04421481251942307
0.0456584289440934,183.632030100873,0.14496551189749654,37.020217268336005,192.01638009909334,0.04464676254710491
0.0461174086290947,183.522693152298,0.14642277239737567,36.99817493950327,191.98628418511447,0.04508560468699678
0.0465640346577741,183.362268083879,0.14784081003843277,36.96583324571001,191.9003550898648,0.045512450384791056
0.0470204202823601,183.275400436355,0.14928983439649332,36.94832072796917,191.89308679229026,0.04594843531077615
0.0474514848521764,183.206035999143,0.15065846440566005,36.93433685742723,191.89943444118362,0.046360056564654833
0.0479177214950157,183.050539680007,0.15213876574667484,36.902988799489414,191.8219044599059,0.04680507279293722
0.0483711474964937,182.897484994694,0.15357839330136747,36.87213297493031,191.74444621811006,0.04723767157763361
0.0488253590862222,182.744366706156,0.15502051509875547,36.84126432796105,191.66692603156835,0.04767083231903749
0.0492768919654561,182.63575736685,0.1564541319903231,36.81936868515696,191.6354798516455,0.04810125260573083
0.0497126050288591,182.594104457626,0.15783752096662765,36.810971458657406,191.67133305312618,0.048516417207826484
0.0501342214741125,182.585719120155,0.15917615318030717,36.80928097462325,191.73951200053494,0.04891798597522215
0.0505552313913481,182.4915411718,0.1605128596675302,36.79029470023488,191.71744326270408,0.04931881620959876
0.0510032486216203,182.457332634097,0.16193531437364445,36.78339825903396,191.76324933327155,0.049745182871597717
0.051467918624763,182.383481762972,0.1634106416336225,36.76850992341515,191.7703799608496,0.050187205590336924
0.0519327542565101,182.322052385343,0.16488649476441958,36.75612576088515,191.79053872741355,0.050629190463031055
0.0524123219690335,182.222921832458,0.16640912225168134,36.73614104142354,191.77364828167885,0.051084978561897386
0.0528811671821485,182.067752784057,0.16789770580332147,36.70485896126589,191.69570805750882,0.051530375104737326
0.0533417893327492,181.904991338854,0.1693601811314787,36.67204625391297,191.6081290654267,0.05196776674603481
0.0538098603445316,181.802171911953,0.1708463065938878,36.651317857449726,191.58492139286773,0.052412035690372866
0.0542592742691539,181.713170358451,0.1722731958045636,36.633375144263724,191.57279510724769,0.052838410636100716
0.0547196897264434,181.657562614084,0.1737350148814578,36.62216462299933,191.59780807678865,0.05327503468258413
0.055189575243785,181.576794221925,0.17522690139901737,36.60588171514008,191.5979403691612,0.053720442959528644
0.0556853007674454,181.423254469149,0.17680082993663912,36.574928100980436,191.52586296047232,0.05419013023318692
0.0561639706075352,181.259380355129,0.17832060667892427,36.54189107959401,191.4396268657345,0.05464344842665372
0.0566371664341382,181.068178351367,0.17982300342838878,36.50334475563559,191.32336690457961,0.05509138063022838
0.0571116701059982,180.951159948552,0.18132955258654426,36.47975384562808,191.2855829008314,0.05554034946855747
0.0575782155757936,180.901518971673,0.18281083445314467,36.469746224689274,191.3175056290125,0.055981591922615453
0.0580411148967649,180.878499110249,0.18428053979722855,36.4651054206262,191.3768888594614,0.056419193642065574
0.0585149589922358,180.787718330004,0.18578499480034866,36.44680401532881,191.36650425438407,0.056866943748224125
0.0590110040771371,180.668936722387,0.1873599379449103,36.42285764323322,191.33039208392378,0.05733545757296692
0.0594838619691005,180.519210934277,0.18886126175189408,36.392672924350244,191.25719076026246,0.05778186686797611
0.0599613994111375,180.368214858285,0.19037744313036153,36.36223211543026,191.1833454304765,0.05823249181103955
0.0604240706369764,180.278831733884,0.19184642427240006,36.34421247755102,191.17201259692376,0.05866889475731257
0.0608816868299796,180.184525173928,0.19329935568518522,36.325200275063885,191.15446300717565,0.05910034241495559
0.0613749141835847,180.105813307592,0.1948653525328814,36.309331962810546,191.15979214331017,0.05956515648338615
0.0618614189951511,180.061844372031,0.19641000530960473,36.300467825401455,191.2007255717689,0.06002342371673965
0.0623736785196129,179.989998746831,0.19803642929977094,36.28598374736113,191.21663706541136,0.06050572394329269
0.0628628723972877,179.914451924289,0.19958961986138846,36.27075350793667,191.22439115803354,0.060966090471530295
0.0633521282322102,179.825115573616,0.20114300713726738,36.25274329964098,191.21741935480773,0.0614263034259238
0.0638412068922955,179.728566491203,0.2026958318830382,36.233279004626525,191.20265508902358,0.06188613813923119
0.0643169390504521,179.60148043107,0.2042062814851854,36.207658454903715,191.1528979013261,0.062333221610906236
0.0648142163064912,179.493664016282,0.20578513677310956,36.185922665682455,191.12740518147794,0.06280033916149012
0.0653139061781955,179.324438089778,0.20737165211577072,36.151806718899245,191.0368176146314,0.06326950331701271
0.0658245549291489,179.150553509658,0.20899296190004776,36.11675158754706,190.94305895974193,0.06374872958038835
0.0663216612762242,178.986722632264,0.21057127455201183,36.08372328266442,190.8574194236225,0.064215026265207
0.0668399055623179,178.811765551236,0.21221670016035935,36.04845193512918,190.76352707411195,0.0647009194149301
0.0673480789582355,178.675228726926,0.2138301506923977,36.02092611134829,190.70866213910782,0.06517714119970945
0.0678398049670915,178.59787047225,0.21539138077051548,36.0053306872056,190.7139151726253,0.06563773393841034
0.0683466583973041,178.464139732445,0.2170006404114405,35.97837057006092,190.66156732690715,0.06611227438552639
0.068818167448738,178.386140567868,0.21849768164974315,35.96264593848219,190.66234786000166,0.06655352164299755
0.0692992583484316,178.285053933157,0.22002514525627034,35.94226687292445,190.6400759453349,0.06700353519417848
0.0698008334386739,178.141447605499,0.22161764616778962,35.9133158372686,190.57586911833468,0.06747249417497649
0.0703007553833305,178.077553207182,0.22320489834207433,35.900434726567894,190.59653971446215,0.0679396887757945
0.0708048082291778,177.932534946065,0.22480526612763949,35.87119904512671,190.53101396065264,0.06841052296886306
0.0713189560865212,177.859492052329,0.22643768557470478,35.85647359774952,190.54424535558002,0.06889055860058645
0.0718172239798559,177.7979024553,0.22801968613604248,35.84405713498848,190.56685423908084,0.06935554809303843
0.0723292792737773,177.71135166102,0.22964546169424294,35.82660849486163,190.56508564543034,0.0698331789852178
0.0728339371719641,177.648481197107,0.231247750520986,35.813933809336774,190.58731951531195,0.0703036866870355
0.073331817740399,177.528225344897,0.2328285213257668,35.78969022953124,190.54669280966547,0.07076765884410377
0.0738552264515499,177.377268823069,0.23449034398367094,35.75925739473071,190.4775071793542,0.07125518853829971
0.0743711785669443,177.256578214226,0.23612849195004812,35.734926167987965,190.43935884476176,0.07173554025924479
0.0749097139010763,177.13770625708,0.23783834163591724,35.71096158142733,190.40704115389076,0.0722366709837486
0.0754497154514041,177.068892251031,0.239552846558208,35.697088677807855,190.4286897866666,0.07273891405465832
0.0759853377148804,176.964898151052,0.24125344724474526,35.67612346725209,190.41163570073914,0.0732368349877159
0.0765401485322973,176.889683089265,0.24301497159004393,35.66096011079582,190.42884570674835,0.07375233255859055
0.0770545069358763,176.779246764269,0.24464805952140725,35.63869614767663,190.40088446018535,0.07423000686192628
0.077606463394462,176.661889413438,0.24640052127741685,35.6150369057491,190.37199386739846,0.07474234404931644
0.0781379159991125,176.526645989305,0.24808788329718218,35.58777183144389,190.32007022522237,0.075235401222975
0.0786780457940879,176.270509808546,0.24980279539622904,35.53613477740287,190.13912905140998,0.07573625972535528
0.0792580085844689,176.049731981949,0.2516441772556887,35.49162596756092,190.00308315066778,0.07627377593503912
0.0797708895626481,175.840589604721,0.2532725743614077,35.449462864311755,189.86754985871013,0.07674887933756117
0.0803006673617196,175.551671210392,0.2549546188734597,35.391216916015026,189.64858756505166,0.07723939809653076
0.080808814740764,175.35235331878,0.25656798680192566,35.35103442906605,189.52236915247425,0.0777096633862972
0.0812922007730708,175.183355026572,0.25810273745449974,35.31696437335692,189.42439549549223,0.07815680811902918
0.0818016483820154,175.222671882035,0.25972023361289887,35.32489065141826,189.5561752758865,0.07862784419410576
0.0823171264709862,175.303903069222,0.26135687654538114,35.341266858755155,189.73441662902863,0.07910423033770309
0.0828368012906602,175.397875332693,0.26300684409784614,35.36021166707091,189.92727427843127,0.07958426533474418
0.0833240651599196,175.351734988185,0.2645539068827447,35.3509097736181,189.96275438024549,0.08003415239994292
0.0838398603489194,175.229454654032,0.26619155660781907,35.326258058252854,189.92066766124336,0.0805101617988332
0.0843839830672424,175.080314845765,0.2679191462384946,35.29619147290622,189.8542891691175,0.08101206821536641
0.084939479490263,174.935120391761,0.269682847381585,35.26692027097902,189.79401846240364,0.08152420616505437
0.0855333365429413,174.836347231504,0.27156834352383863,35.2470076018712,189.7906833591948,0.08207142063658385
0.0860914485965068,174.733387790292,0.2733403492939091,35.22625097852287,189.7764382633334,0.08258542477732891
0.0866572910908667,174.624675923491,0.27513689921350176,35.20433466617579,189.75717729664123,0.0831062788427959
0.0872251495502425,174.491226940484,0.27693984982201997,35.17743135120158,189.71125030557303,0.08362871599181146
0.0878006450404985,174.355728812728,0.2787670480035827,35.15011492864596,189.66427426899173,0.08415790098365585
0.0883636732508874,174.231291508755,0.28055466257156747,35.12502836816501,189.62700842171475,0.08467535108447714
0.0889418739920305,174.090776058815,0.2823904499246968,35.09670045345711,189.57473592621292,0.08520646694505715
0.0895152908857306,173.925306598885,0.28421104856219465,35.06334181033522,189.49428101147407,0.08573291007755318
0.0900701582391495,173.77688572672,0.28597275240929965,35.03342016250675,189.42899732243225,0.08624205952670945
0.0906461060028367,173.622330841918,0.2878013865590065,35.00226189773067,189.36051904787408,0.0867702784303081
0.0912117871086283,173.44846160539,0.28959742406989486,34.96720985964663,189.2690057596599,0.08728881001777053
0.0917778160280478,173.317311221628,0.29139456588905177,34.940769942280205,189.22399552540247,0.0878073914450859
0.0923689660300409,173.19375801541,0.2932714671453798,34.91586161590666,189.1914863661505,0.08834870123368055
0.092929597074082,173.107848308694,0.2950514707102103,34.89854221903271,189.19469090238223,0.08886179456180164
0.0934924315289454,173.000813803338,0.2968384701044016,34.87696406275294,189.1750805422984,0.08937663978375116
0.0940559561740917,172.864031901492,0.2986276608527411,34.84938883134079,189.12292371009553,0.08989185093133478
0.0946216518318486,172.728721676206,0.3004237445661193,34.82211028992313,189.07259864001222,0.0904087801202519
0.0952185962808661,172.494034819126,0.30231904319174985,34.7747974195358,188.918674681426,0.09095397465151336
0.0958028440107626,172.354848770273,0.30417402973417124,34.74673751208704,188.86693346151006,0.09148728549274951
0.0963680842883775,172.233209685195,0.30596866761559854,34.72221507253531,188.83099415339564,0.09200297547188803
0.0969262508012195,172.1572601499,0.3077408462938719,34.70690364621984,188.84381792443997,0.09251195095772397
0.0974979242620325,172.124663949115,0.30955590953195317,34.700332252141585,188.9064613984536,0.0930329746324007
0.0980810521665954,172.064802024361,0.3114073406289404,34.688264088111175,188.94109884774724,0.09356415836528793
0.098681322307469,171.979281883362,0.31331319832621407,34.67102322768579,188.9504248291011,0.0941106627690311
0.0992727656199233,171.798623301319,0.3151910308432565,34.63460245754591,188.85354776613633,0.09464883900299163
0.0998742584879969,171.568505426674,0.31710077069939013,34.58821069401748,188.7037826860569,0.09519586280492821
0.100483726575125,171.343855475125,0.31903583187602186,34.5429212637852,188.5611245990152,0.095749834573933
0.101100344054419,171.14411758903,0.3209935923727803,34.50265410594845,188.44684676017087,0.09630999260163978
0.101695210497376,171.031806551697,0.3228822933291688,34.48001220082212,188.42492212071832,0.09685009397980772
0.102297508002581,170.885774935179,0.32479458790819465,34.45057222693209,188.36696386413772,0.09739664525934909
0.10287184583003,170.758360021498,0.3266181105103452,34.424885380334,188.3245877078183,0.09791754660367208
0.103485606427473,170.631034326765,0.32856680040722674,34.39921652027582,188.28889038941722,0.09847390306590044
0.104073417660256,170.47302700462,0.3304331010713128,34.3673622441314,188.21473754387992,0.09900644714763168
0.104678931481755,170.36074833419,0.3323556074545721,34.344726864172706,188.19392943624518,0.09955473300403682
0.105255732996951,170.202967838783,0.3341869522653194,34.31291831629865,188.11780597691057,0.10007674076975488
0.105855720655434,170.069461357685,0.33609191308100295,34.286003409709295,188.0722867511842,0.10061944310365843
0.10644131151177,169.955117682078,0.33795116404986975,34.26295172470692,188.04536330629557,0.10114883934792203
0.107031047561671,169.820039258085,0.33982357600830543,34.235719914429936,187.9960559568419,0.10168169991104375
0.107627405958854,169.699707818497,0.34171701391936143,34.211461096209,187.96404716297727,0.10222025556114789
0.108232036062613,169.539009149611,0.34363671449879624,34.17906424456158,187.88856130191135,0.10276598522910314
0.108848036351634,169.387559242479,0.34559251541643793,34.148531943283764,187.82506244841892,0.10332167134304784
0.109452700292087,169.241132908026,0.3475123234273762,34.11901239425804,187.76503190530144,0.1038668309288878
0.110055090453893,169.068700445425,0.34942491219111027,34.084250009797685,187.6755715658684,0.10440964513220677
0.110657997860148,168.843467082066,0.3513391432059699,34.03884296374451,187.52734710113324,0.10495263055814114
0.111249121918349,168.62339635278,0.35321596209075806,33.99447670472045,187.3826011319165,0.10548471767095094
0.111843030772896,168.461649538918,0.35510162270394474,33.96186854704587,187.30291099235203,0.10601902648757595
0.112445053194412,168.353621834796,0.3570130438922581,33.94009016189487,187.28415379748157,0.1065603434514676
0.113059097583661,168.240407802865,0.3589626348281237,33.91726621305759,187.26151648616403,0.10711216844322607
0.113670032929,168.1332382416,0.360902354549575,33.89566082950656,187.24494896898204,0.10766089738586837
0.114267886609843,167.945144106564,0.3628005399862515,33.8577410518833,187.13588079000658,0.10819758531594949
0.114881930053666,167.769700391411,0.3647501279203895,33.82237159890846,187.0434073769016,0.10874850697654304
0.11549597413871,167.616080222064,0.36669971789040423,33.791401772768104,186.97506268862344,0.10929912586440382
0.116127775274562,167.451345704026,0.36870568649673435,33.758191293931645,186.89709794736612,0.10986535137880629
0.116734321147213,167.333602599148,0.37063146964240123,33.73445428398824,186.86717710367705,0.11040864143558336
0.117350983938018,167.142964625817,0.37258937400320713,33.69602166856471,186.75735598297396,0.11096069090751941
0.11796910832218,166.923093815456,0.37455191892292145,33.651695713195934,186.61486235124497,0.11151374315454
0.11859961939228,166.707732696661,0.376553791570489,33.608278911646856,186.47920634423494,0.11207756315165421
0.119217335383546,166.522093633204,0.3785150398427585,33.57085407645393,186.37441391864394,0.1126296333338348
0.119855467235661,166.394729821759,0.38054110847322364,33.54517753206662,186.33804791009752,0.11319962986869145
0.120466450351356,166.204808071137,0.3824809798655553,33.50688930714122,186.22691133079528,0.11374507213397142
0.121084303474673,165.998569799738,0.3844426635320867,33.46531167162718,186.09839100173113,0.1142963450756254
0.12171467816358,165.792024123516,0.3864441031693665,33.42367206330083,185.97134698179826,0.11485847722448715
0.122333342828428,165.633711657709,0.38840836348025887,33.391756270194136,185.89623728987652,0.11540985997096562
0.122960337358411,165.497721743613,0.3903990711129549,33.36434070351238,185.84737744125607,0.11596835666279103
0.12356645819867,165.348083736999,0.3923235047807772,33.334173681379,185.77956081431708,0.11650796371859383
0.124195373306829,165.164384588068,0.39432031024918207,33.29713993295451,185.6770369889758,0.11706755603460856
0.124822293713172,164.921902718019,0.39631078253932106,33.248255587952634,185.50783289882276,0.1176250620353609
0.125436465322311,164.617488135928,0.39826077739833743,33.186885608203085,185.2665239779363,0.11817092959119055
0.126061253754846,164.373864428087,0.40024448067163604,33.137771068702335,185.09503986242072,0.11872592766494254
0.126687666265471,164.137310255896,0.40223334039287045,33.09008174758864,184.93148303930704,0.11928205935028298
0.127324276612064,163.991550786242,0.4042545782433032,33.060696638506386,184.87165636059078,0.11984692801970757
0.127942365324752,163.813376283242,0.4062170099060876,33.02477665870159,184.7720471167536,0.12039505720023982
0.128551703947096,163.607385818924,0.4081516600320298,32.98324898109508,184.63939404427663,0.1209351327496976
0.129148702194574,163.381492164284,0.41004712946777244,32.937708820319656,184.48199983991424,0.12146398791557209
0.129755048437116,163.193757182352,0.41197227878784326,32.89986144796216,184.368971050183,0.12200083793136855
0.130370830920376,162.994653148106,0.41392738817219377,32.85972207465817,184.24440151460306,0.12254574784468003
0.130989411312194,162.816457018718,0.4158913809162159,32.82379773497355,184.14368887553704,0.12309283485513893
0.131626390776589,162.59901870063,0.41791379071567003,32.779962170047014,184.00134067600905,0.12365588182107544
0.132250414514623,162.312616913758,0.41989506608392796,32.722223569813615,183.7785277815557,0.12420716955226274
0.132883808666879,162.043931564669,0.4219060925173408,32.66805660343727,183.5769463623373,0.1247664248602108
0.133498532249967,161.805024670731,0.42385783989364517,32.61989297361937,183.4057579749433,0.12530889608147383
0.134125750460334,161.608586205992,0.42584925771156046,32.58029097912799,183.28445911170425,0.12586209021609693
0.134756200465804,161.382912949934,0.4278509364789277,32.53479525070669,183.1302611191707,0.126417826508537
0.135383785673836,161.143814955599,0.42984351951442923,32.486593095048754,182.9600746622121,0.126970730935446
0.136016593528545,160.886119769016,0.43185268445313035,32.43464174543363,182.7693017260231,0.1275279271716318
0.136632423487195,160.629967081782,0.43380794457184413,32.38300136368726,182.57722876883423,0.12806987620917515
0.137287843222928,160.355827554225,0.43588890223279636,32.32773483493176,182.37073326737232,0.12864634299517358
0.137941177761225,160.063766227025,0.43796323939188936,32.268855271368245,182.14315065727823,0.129220645230446
0.138569383700439,159.719008141675,0.43995779324889384,32.19935204136168,181.8511726651123,0.12977254774809246
0.139211992506185,159.388270093657,0.4419980762071373,32.132675250881256,181.577028755509,0.1303367887498914
0.139802298971826,159.127077004246,0.44387229923554755,32.08001872405599,181.37340819810635,0.1308548254125395
0.140401348018384,158.902906838734,0.44577427995836916,32.034826018688776,181.21308916293196,0.13138026011319098
0.141010014915761,158.713891135278,0.4477067973575412,31.996720452872047,181.094139291602,0.13191384815584495
0.141643303551687,158.410658607341,0.4497174887766062,31.935588775239946,180.84846761028325,0.13246871879436967
0.142287057717318,158.010588973548,0.4517614082524846,31.85493473706728,180.49345076677466,0.13303244367284742
0.142938730729732,157.629490544166,0.4538304700668991,31.778105293703867,180.1608498481234,0.13360277946493707
0.143527541410908,157.284013199691,0.4556999439796329,31.708457061057707,179.85860091748347,0.1341178193772824
0.14413372544113,157.068978382563,0.4576245782755878,31.6651060419247,179.7079153880741,0.13464777899428776
0.144734373999842,156.785103588338,0.45953163744949826,31.60787688340894,179.47729740869644,0.13517262231981325
0.145378419114009,156.413574440264,0.46157648068697854,31.532976607157227,179.15273262036095,0.13573507944688823
0.146004709106771,156.014536751845,0.4635649514139979,31.45253060917195,178.79339380672576,0.13628172745231734
0.146631425598046,155.684302490472,0.46555477627379604,31.385955382079157,178.51251370788734,0.13682844875483782
0.147252475901233,155.345082682623,0.46752661098641474,31.317568668816797,178.220030726721,0.13736993240878873
0.1478807115418,155.046403099031,0.469521259145215,31.257354864764654,177.97477551131246,0.1379173826915822
0.148516026210239,154.588172434154,0.47153838321750874,31.164975562725445,177.54699350317773,0.13847069708556603
0.149165867674846,154.074967101503,0.473601629867636,31.061513367663007,177.05769325617206,0.13903634673764656
0.149812782584016,153.607695281744,0.4756555847042508,30.96731136879959,176.6200915382197,0.13959913136913663
0.150444168494263,153.167233271315,0.477660234969285,30.87851422749711,176.21035032138482,0.14014810127948302
0.151053125483506,152.888083156603,0.4795936734101315,30.822237564371164,175.98230596659002,0.14067728461160953
0.151671720765995,152.497102242827,0.4815577134320341,30.743415812153923,175.62660015182445,0.1412145570507175
0.152310332458812,152.034566779862,0.48358530555672813,30.650168662820178,175.19100219133423,0.14176891181079682
0.152978313097157,151.562222207173,0.48570614408347346,30.554943996966077,174.74795528968278,0.14234843200088443
0.153627025357798,151.055685118721,0.4877658055110087,30.45282611993415,174.26192068689429,0.14291091424865315
0.154267181697221,150.57659957321,0.4897983018886767,30.35624247395913,173.80562721892005,0.14346566788847206
0.154906186551254,150.108169732206,0.4918271423002314,30.26180701801273,173.3608538756104,0.14401911690978017
0.155514579715836,149.639726453447,0.4937587905977792,30.167368853014914,172.91088562164745,0.14454576832109603
0.156094847133577,149.130285921364,0.4956011396491069,30.064665641746984,172.40875510524594,0.14504781457786356
0.1567783962734,148.554496872302,0.497771408168045,29.948586569456083,171.8446326511433,0.14563889682733216
0.157418874303555,147.945439427779,0.4998049259137871,29.82580058864025,171.23484396084476,0.14619241752727496
0.158136781658866,147.323292510534,0.5020842817668995,29.700375770123657,170.62052385153754,0.14681249105171373
0.158795982536876,146.729205533866,0.5041772445545812,29.58060783562739,170.02921389347148,0.1473815199903035
0.159480376963367,146.092097451827,0.5063501968586902,29.45216684628832,169.3909202248133,0.1479719538646506
0.160125692688113,145.394695094921,0.5083990742847587,29.311570531136073,168.6761213601722,0.14852835501382594
0.160766418415398,144.759881428981,0.5104333784688886,29.18359209608257,168.03240909655597,0.14908049247898186
0.161398615340325,144.094406647587,0.5124406037055319,29.04943238015354,167.35104435879327,0.14962498172187036
0.162020377339366,143.51318985949,0.5144146980524871,28.932259075673187,166.76525103370065,0.15016019471258968
0.162657949640323,142.792319899003,0.5164389901080255,28.786931691639,166.01862587815992,0.1507087199081349
0.163289443538393,142.007766991045,0.5184439832343978,28.628765825394673,165.1961362411425,0.15125171921709435
0.163941817564903,141.306923437997,0.520515270768567,28.487475765100193,164.47303730092682,0.1518123631500817
0.164606023060396,140.531070814919,0.5226241232167573,28.33106387628767,163.6633314981817,0.1523828521921526
0.165244494297055,139.867292453326,0.5246512693931497,28.197246158590524,162.97959246347415,0.15293093134820565
0.165854812580861,139.096660592307,0.5265890299442336,28.04188677540909,162.1665111654677,0.15345456266322555
0.166480151582864,138.341468373876,0.5285744812755931,27.889640024173406,161.37257699895488,0.15399079697484533
0.167109908573518,137.598308244734,0.5305739597209197,27.739818942138378,160.59234895538225,0.15453052930975222
0.167759548369406,136.623806048445,0.532636566072864,27.54335929936651,159.54375404764147,0.15508699709061266
0.168414691749189,135.7799536472,0.534716646303675,27.373238655275518,158.64729268641233,0.15564786569853273
0.1690661219064,134.8777396499,0.5367849370528199,27.191352313419845,157.6809960240097,0.15620524368449992
0.16973191784711,134.058372229273,0.5388988391645743,27.02616784142144,156.81235685120924,0.15677459251016027
0.170395561686646,133.158768564549,0.541005908355101,26.84480774261308,155.84843172760742,0.1573417785828262
0.171035631397644,132.085675489873,0.5430381296875196,26.628472178758397,154.67703239586774,0.15788851233168252
0.171703566485646,131.106943937513,0.545158823591926,26.43115989780262,153.61847380261761,0.1584587295429739
0.172421792428036,130.075149593511,0.5474391909590143,26.22315015805182,152.50294003676908,0.15907151755973595
0.173125664902264,129.125015249706,0.5496739860646882,26.03160307434073,151.47986937032633,0.15967169513717702
0.173833511170251,128.020070542221,0.551921397965547,25.80884622131175,150.2742489048385,0.16027489803620149
0.174486245604875,126.857807861335,0.5539938297954781,25.57453406484514,148.99275048072394,0.16083081419672532
0.175153836379534,125.744022709298,0.5561134305050204,25.349994978194477,147.76857068862677,0.16139906360457446
0.175829736063303,124.498344026824,0.5582594120009869,25.09886615580772,146.38885499737876,0.16197405673537607
0.176522792009092,123.398405271115,0.560459864628867,24.877118502656785,145.18103629904166,0.1625633017210414
0.17718368613237,122.189948139372,0.5625582034702747,24.633493544897398,143.84001355902905,0.16312487908575055
0.177810388626459,120.89931966205,0.5645479838890073,24.373302843869283,142.39647467583362,0.16365711185491133
0.178430120663434,119.697329095106,0.566515633106403,24.13098154557337,141.05493796863652,0.16418314648407772
0.179043529683357,118.344752529848,0.5684632067446584,23.85830211001736,139.53361474229538,0.16470354172469978
0.179645715567917,117.055536147497,0.5703751469281364,23.598396087335395,138.08406169990027,0.1652141523520692
0.179962888775266,116.415010240027,0.5713821718614696,23.469266064389444,137.36539177962445,0.16548298779255324