File: examples/hot axisymmetric compression example/data/04 corrected data/testID_0131.csv
level_0,index,Time(sec),Force(kN),Jaw(mm),PowAngle(deg),Power(W),Pram,PTemp,Strain,Stress(MPa),Stroke(mm),TC1(C),wedge(mm),uncorrected stress
1773,1773,145.347,0.21278074,0.032323588,0.0,0,9.0337067,0.0,0.0022823047,2.587976465950603,10.074883,294.54654,-9.3237391,2.587976465950603
1775,1775,145.3474,2.4359467,0.060379427,0.0,0,8.9751787,0.0,0.0037557527,29.568461637408372,10.006702,295.03302,-9.3232327,29.568461637408372
1777,1777,145.3478,5.7853661,0.12646425,0.0,0,8.9166508,0.0,0.0078554461,69.89441053206373,9.9525833,295.51953,-9.3232574,69.89441053206373
1779,1779,145.3482,6.6644325,0.17576744,0.0,0,8.8581219,0.0,0.011389344,80.23047819911314,9.8775597,296.00604,-9.3205166,80.23047819911314
1781,1781,145.3486,7.6427975,0.31811184,0.0,0,8.7995939,0.0,0.020336781,91.06769185353983,9.790163,296.49252,-9.3177938,91.06769185353983
1783,1783,145.349,7.9481492,0.41904137,0.0,0,8.7416534,0.0,0.027719626,94.01214841825583,9.6836815,296.97903,-9.3185635,94.01214841825583
1785,1785,145.3494,8.8252029,0.49924701,0.0,0,8.6858492,0.0,0.033287253,103.77369035828166,9.5773439,297.46552,-9.3184738,103.77369035828166
1787,1787,145.3498,9.4707241,0.58950216,0.0,0,8.6301851,0.0,0.039602194,110.62458916864148,9.4862356,297.95203,-9.3173971,110.62458916864148
1789,1789,145.3502,9.6432486,0.6164608,0.0,0,8.574522,0.0,0.041664451,112.41482046451941,9.4054289,298.43854,-9.3160563,112.41482046451941
1791,1791,145.3506,9.2993841,0.69526267,0.0,0,8.518857,0.0,0.047026142,107.77205039787707,9.339735,298.92502,-9.3166962,107.77205039787707
1793,1793,145.351,9.978693,0.75428903,0.0,0,8.4631929,0.0,0.051113885,115.13485100697636,9.2673731,299.41153,-9.3175125,115.13485100697636
1795,1795,145.3514,10.203602,0.81727892,0.0,0,8.4075298,0.0,0.055527404,117.1734962125277,9.1962833,299.89804,-9.3166494,117.1734962125277
1797,1797,145.3518,10.367243,0.9189201,0.0,0,8.3518648,0.0,0.06253469,118.1403870904139,9.1146126,300.38452,-9.3172121,118.1403870904139
1799,1799,145.3522,10.045422,1.0118383,0.0,0,8.2962017,0.0,0.069048904,113.66482513201295,9.0290165,300.87103,-9.3164263,113.66482513201295
1801,1801,145.3526,10.454737,1.0916568,0.0,0,8.2405376,0.0,0.075297154,117.57357446394852,8.9429398,301.35754,-9.315279,117.57357446394852
1803,1803,145.353,10.490437,1.1489681,0.0,0,8.1848736,0.0,0.079291798,117.45431960671785,8.8639212,301.84402,-9.315114,117.45431960671785
1805,1805,145.3534,10.809104,1.1923382,0.0,0,8.1292095,0.0,0.082336068,120.61614792667763,8.8022757,302.26047,-9.3153696,120.61614792667763
1807,1807,145.3538,10.589496,1.2497556,0.0,0,8.0735455,0.0,0.086902127,117.63887839770516,8.7424231,302.59131,-9.3167086,117.63887839770516
1809,1809,145.3542,10.878234,1.3032954,0.0,0,8.0196619,0.0,0.090317078,120.34188633766907,8.6887569,302.92215,-9.3175945,120.34188633766907
1811,1811,145.3546,11.078134,1.369097,0.0,0,7.9666953,0.0,0.095082141,121.92169545095906,8.6290712,303.25299,-9.3172054,121.92169545095906
1813,1813,145.355,10.981328,1.4540911,0.0,0,7.9137359,0.0,0.10165628,120.04747277988108,8.5609331,303.58383,-9.3158855,120.04747277988108
1815,1815,145.3554,10.943342,1.5332434,0.0,0,7.8607755,0.0,0.10689767,118.88148479902388,8.4912539,303.91467,-9.3145685,118.88148479902388
1817,1817,145.3558,11.022887,1.5918709,0.0,0,7.8078156,0.0,0.11192904,119.1854420953775,8.421155,304.24554,-9.314723,119.1854420953775
1819,1819,145.3562,11.291644,1.6305107,0.0,0,7.7548552,0.0,0.11486384,121.7131616475987,8.3581915,304.57639,-9.3156071,121.7131616475987
1821,1821,145.3566,11.217353,1.6818477,0.0,0,7.7018952,0.0,0.11813539,120.41312639645453,8.3034964,304.90723,-9.3172979,120.41312639645453
1823,1823,145.357,11.258385,1.7297304,0.0,0,7.6489348,0.0,0.12239156,120.38618380865155,8.2579842,305.23807,-9.3171577,120.38618380865155
1825,1825,145.3574,11.349437,1.7729124,0.0,0,7.5959754,0.0,0.1253614,120.93484337596011,8.206665,305.56891,-9.3162031,120.93484337596011
1827,1827,145.3578,11.622049,1.8346921,0.0,0,7.543015,0.0,0.12972176,123.21703300784382,8.1518202,305.89975,-9.3157406,123.21703300784382
1829,1829,145.3582,11.492576,1.8909816,0.0,0,7.4900556,0.0,0.13459899,121.28330103508695,8.0957403,306.23059,-9.3145285,121.28330103508695
1831,1831,145.3586,11.536364,1.9523007,0.0,0,7.4370952,0.0,0.13874221,121.13181665686741,8.0369358,306.56143,-9.3151531,121.13181665686741
1833,1833,145.359,11.497,2.0098932,0.0,0,7.3846664,0.0,0.14352876,120.14409876436396,7.9785824,306.89227,-9.3161058,120.14409876436396
1835,1835,145.3594,11.749326,2.0412283,0.0,0,7.3341722,0.0,0.14627548,122.46151012642574,7.923162,307.22311,-9.3167238,122.46151012642574
1837,1837,145.3598,11.739275,2.0936892,0.0,0,7.2838039,0.0,0.14961028,121.82241940090215,7.8740234,307.55396,-9.3167953,121.82241940090215
1839,1839,145.3602,11.770989,2.1453061,0.0,0,7.2334356,0.0,0.1542315,121.62431851915385,7.8296061,307.8848,-9.3153772,121.62431851915385
1841,1841,145.3606,11.807833,2.1835911,0.0,0,7.1830673,0.0,0.1570701,121.61271491803373,7.778635,308.21564,-9.3152084,121.61271491803373
1843,1843,145.361,11.965198,2.2406273,0.0,0,7.1326995,0.0,0.16105892,122.64118942386783,7.7287989,308.54648,-9.3151541,122.64118942386783
1845,1845,145.3614,12.011025,2.2963433,0.0,0,7.0823312,0.0,0.16610028,122.53005790946513,7.6766715,308.87732,-9.3148193,122.53005790946513
1847,1847,145.3618,11.952735,2.3526397,0.0,0,7.0319633,0.0,0.17001823,121.35129650249615,7.6240344,309.20816,-9.3161182,121.35129650249615
1849,1849,145.3622,12.028191,2.4033377,0.0,0,6.981595,0.0,0.17410433,121.5879629187378,7.5725818,309.539,-9.3167315,121.5879629187378
1851,1851,145.3626,12.114168,2.437372,0.0,0,6.9312277,0.0,0.1774641,122.09909835261001,7.5214529,309.86984,-9.3168945,122.09909835261001
1853,1853,145.363,12.190685,2.4881649,0.0,0,6.8808594,0.0,0.18067831,122.33265914699595,7.4757009,310.20068,-9.316391,122.33265914699595
1855,1855,145.3634,12.170264,2.5314434,0.0,0,6.830492,0.0,0.18454948,121.67034472101132,7.4298887,310.25327,-9.3160028,121.67034472101132
1857,1857,145.3638,12.287962,2.569732,0.0,0,6.7801232,0.0,0.18781085,122.43840966233219,7.3858266,310.02768,-9.3155394,122.43840966233219
1859,1859,145.3642,12.357078,2.6295531,0.0,0,6.7313671,0.0,0.19186524,122.48504203014687,7.3369904,309.80206,-9.3151875,122.48504203014687
1861,1861,145.3646,12.389972,2.6742427,0.0,0,6.6834416,0.0,0.19612119,122.33011972532061,7.2915859,309.57648,-9.3151598,122.33011972532061
1863,1863,145.365,12.366549,2.724699,0.0,0,6.6355219,0.0,0.20002927,121.55679340020554,7.2424264,309.35089,-9.3173199,121.55679340020554
1865,1865,145.3654,12.459235,2.7781401,0.0,0,6.5876017,0.0,0.20406055,121.88935259530682,7.1934695,309.12527,-9.3176498,121.88935259530682
1867,1867,145.3658,12.569793,2.8127904,0.0,0,6.5396819,0.0,0.20768049,122.59249647394354,7.1448426,308.89969,-9.3169012,122.59249647394354
1869,1869,145.3662,12.596852,2.8590841,0.0,0,6.4917622,0.0,0.21096063,122.34964908950127,7.0955791,308.67407,-9.3165131,122.34964908950127
1871,1871,145.3666,12.609886,2.9092405,0.0,0,6.4438419,0.0,0.21500628,121.92658453176885,7.0523677,308.44849,-9.315918,121.92658453176885
1873,1873,145.367,12.681778,2.9480488,0.0,0,6.3959212,0.0,0.21884641,122.19395450664499,7.0083718,308.22287,-9.3154287,122.19395450664499
1875,1875,145.3674,12.783061,3.0012498,0.0,0,6.3480015,0.0,0.22246723,122.57870822729916,6.9589791,307.99728,-9.3159857,122.57870822729916
1877,1877,145.3678,12.829938,3.0532713,0.0,0,6.3000817,0.0,0.2272341,122.44799056915015,6.911015,307.7717,-9.3167562,122.44799056915015
1879,1879,145.3682,12.823696,3.0977488,0.0,0,6.252162,0.0,0.2311693,121.89252084218411,6.8605313,307.54608,-9.3155174,121.89252084218411
1881,1881,145.3686,12.870502,3.1465251,0.0,0,6.2042422,0.0,0.23470522,121.79155722937352,6.8137612,307.3205,-9.3155241,121.79155722937352
1883,1883,145.369,12.963423,3.1887875,0.0,0,6.1568027,0.0,0.23894787,122.19442320854775,6.7644606,307.09488,-9.3167133,122.19442320854775
1885,1885,145.3694,13.038097,3.2301311,0.0,0,6.1111121,0.0,0.24221876,122.42950550054915,6.718327,306.86929,-9.3165998,122.42950550054915
1887,1887,145.3698,13.078543,3.2771158,0.0,0,6.065536,0.0,0.24579027,122.27482612312704,6.6719213,306.64368,-9.3163023,122.27482612312704
1889,1889,145.3702,13.129228,3.3224101,0.0,0,6.0199599,0.0,0.25046334,122.23139940415005,6.6277394,306.41809,-9.3160133,122.23139940415005
1891,1891,145.3706,13.192636,3.3763721,0.0,0,5.9743834,0.0,0.25435036,122.20238735185607,6.5774331,306.1925,-9.3148842,122.20238735185607
1893,1893,145.371,13.242862,3.4256947,0.0,0,5.9288077,0.0,0.25865623,122.09931971334102,6.5296516,305.96689,-9.3148947,122.09931971334102
1895,1895,145.3714,13.294017,3.4695823,0.0,0,5.8832321,0.0,0.26304045,122.06327763421972,6.4803286,305.7413,-9.3158321,122.06327763421972
1897,1897,145.3718,13.366506,3.5209346,0.0,0,5.8376555,0.0,0.26670438,122.1315102369984,6.4314394,305.51569,-9.3176651,122.1315102369984
1899,1899,145.3722,13.424427,3.5643573,0.0,0,5.792079,0.0,0.27092904,122.1533887525234,6.3883796,305.2901,-9.3180828,122.1533887525234
1901,1901,145.3726,13.468905,3.6052115,0.0,0,5.7465038,0.0,0.274813,122.07913752091319,6.3376164,305.06448,-9.3157568,122.07913752091319
1903,1903,145.373,13.507151,3.6592071,0.0,0,5.7009277,0.0,0.27866542,121.79088183673946,6.2936678,304.8389,-9.3148098,121.79088183673946
1905,1905,145.3734,13.597254,3.7019382,0.0,0,5.6553516,0.0,0.28321615,122.0974552685834,6.2463164,304.67795,-9.3157091,122.0974552685834
1907,1907,145.3738,13.666557,3.7479601,0.0,0,5.6097755,0.0,0.28716785,122.17210918415492,6.1990061,304.56985,-9.3167381,122.17210918415492
1909,1909,145.3742,13.704864,3.8051841,0.0,0,5.5656581,0.0,0.29169208,121.83159995841484,6.1525469,304.46176,-9.318079,121.83159995841484
1911,1911,145.3746,13.723404,3.8442867,0.0,0,5.5222936,0.0,0.2960535,121.52904867226678,6.1054263,304.35367,-9.3177433,121.52904867226678
1913,1913,145.375,13.808023,3.8903294,0.0,0,5.4789333,0.0,0.29965946,121.72463494554073,6.0598817,304.24557,-9.3166304,121.72463494554073
1915,1915,145.3754,13.900265,3.9424415,0.0,0,5.4355736,0.0,0.30428699,121.9067674984693,6.0134788,304.13751,-9.3150883,121.9067674984693
1917,1917,145.3758,13.943125,3.9787388,0.0,0,5.3922133,0.0,0.30819789,121.84172606860024,5.964509,304.02942,-9.3148432,121.84172606860024
1919,1919,145.3762,13.979658,4.0296674,0.0,0,5.3488536,0.0,0.31200612,121.54061671909813,5.9193792,303.92133,-9.3163576,121.54061671909813
1921,1921,145.3766,14.022763,4.080802,0.0,0,5.3054934,0.0,0.31718051,121.29051490173089,5.8722024,303.81323,-9.3186226,121.29051490173089
1923,1923,145.377,14.107494,4.1219416,0.0,0,5.2621331,0.0,0.32111841,121.517580514625,5.827086,303.70514,-9.3175774,121.517580514625
1925,1925,145.3774,14.190267,4.1719031,0.0,0,5.2187734,0.0,0.32511896,121.61260072442924,5.7791581,303.59705,-9.3170099,121.61260072442924
1927,1927,145.3778,14.245504,4.2175894,0.0,0,5.1754136,0.0,0.33011907,121.51863955028917,5.7288995,303.48895,-9.3158703,121.51863955028917
1929,1929,145.3782,14.275371,4.2595863,0.0,0,5.1320534,0.0,0.33372253,121.25072911735653,5.6853065,303.38089,-9.3152189,121.25072911735653
1931,1931,145.3786,14.330572,4.3086486,0.0,0,5.0886931,0.0,0.33782086,121.10653744062913,5.6358857,303.2728,-9.3154678,121.10653744062913
1933,1933,145.379,14.421631,4.3524561,0.0,0,5.0457683,0.0,0.34278417,121.32513428117937,5.589025,303.1647,-9.3174028,121.32513428117937
1935,1935,145.3794,14.484818,4.4020195,0.0,0,5.0044241,0.0,0.34673747,121.23057880117382,5.5489516,303.05661,-9.3181114,121.23057880117382
1937,1937,145.3798,14.532552,4.4478183,0.0,0,4.9631839,0.0,0.35120592,121.04953749635484,5.4965334,302.94852,-9.3162165,121.04953749635484
1939,1939,145.3802,14.577383,4.4875445,0.0,0,4.9219441,0.0,0.35563418,120.9177757198329,5.4503798,302.84042,-9.3152027,120.9177757198329
1941,1941,145.3806,14.619015,4.5399075,0.0,0,4.8807039,0.0,0.35955301,120.59524494811899,5.4056005,302.73236,-9.3157434,120.59524494811899
1943,1943,145.381,14.706896,4.5823555,0.0,0,4.8394642,0.0,0.36420661,120.7754677618226,5.3634825,302.62427,-9.315505,120.7754677618226
1945,1945,145.3814,14.78048,4.6241493,0.0,0,4.798224,0.0,0.36841321,120.84067773320038,5.3133931,302.51617,-9.3165588,120.84067773320038
1947,1947,145.3818,14.830111,4.6773858,0.0,0,4.7569842,0.0,0.37268609,120.55738571639289,5.2703934,302.40808,-9.3168306,120.55738571639289
1949,1949,145.3822,14.893362,4.7168517,0.0,0,4.715744,0.0,0.37746519,120.55850335260345,5.2246237,302.29999,-9.3160639,120.55850335260345
1951,1951,145.3826,14.951896,4.7624984,0.0,0,4.6745043,0.0,0.38149112,120.43650677411985,5.1800375,302.19189,-9.3156729,120.43650677411985
1953,1953,145.383,15.038627,4.8147297,0.0,0,4.6332641,0.0,0.38614157,120.44930961016364,5.1317563,302.0838,-9.3158684,120.44930961016364
1955,1955,145.3834,15.111715,4.8500957,0.0,0,4.5920238,0.0,0.39068753,120.56801890501666,5.0856671,301.99924,-9.3164158,120.56801890501666
1957,1957,145.3838,15.152948,4.8964896,0.0,0,4.5507841,0.0,0.39443922,120.28305852358598,5.0452747,301.93033,-9.3167009,120.28305852358598
1959,1959,145.3842,15.202382,4.948627,0.0,0,4.5108657,0.0,0.39964968,119.98317750274484,5.0022464,301.86139,-9.3165579,119.98317750274484
1961,1961,145.3846,15.268815,4.9839602,0.0,0,4.4716296,0.0,0.40391499,120.03622855718702,4.9549208,301.79248,-9.3152256,120.03622855718702
1963,1963,145.385,15.343359,5.0315166,0.0,0,4.4323978,0.0,0.4077003,119.98479434161564,4.9113441,301.72357,-9.3161154,119.98479434161564
1965,1965,145.3854,15.424795,5.0765843,0.0,0,4.3931656,0.0,0.41288903,120.0142330234586,4.8673792,301.65463,-9.3161745,120.0142330234586
1967,1967,145.3858,15.469569,5.1142025,0.0,0,4.3539338,0.0,0.4168154,119.85408070497324,4.824738,301.58572,-9.3157959,119.85408070497324
1969,1969,145.3862,15.535028,5.1622367,0.0,0,4.314702,0.0,0.42092776,119.70908909527867,4.7787414,301.51682,-9.3163252,119.70908909527867
1971,1971,145.3866,15.607189,5.2036662,0.0,0,4.2754698,0.0,0.42607361,119.69997985762261,4.7380443,301.44788,-9.3155804,119.69997985762261
1973,1973,145.387,15.673553,5.2447801,0.0,0,4.2362375,0.0,0.42978525,119.64565153128831,4.6956315,301.37897,-9.3153849,119.64565153128831
1975,1975,145.3874,15.747339,5.2898378,0.0,0,4.1970053,0.0,0.43416327,119.58857726685986,4.6530247,301.31006,-9.3160496,119.58857726685986
1977,1977,145.3878,15.806298,5.3279839,0.0,0,4.1577735,0.0,0.43893954,119.50912258770475,4.6111507,301.24112,-9.3164406,119.50912258770475
1979,1979,145.3882,15.854663,5.3725128,0.0,0,4.1185417,0.0,0.4425413,119.25743102103462,4.5706921,301.17221,-9.3155098,119.25743102103462
1981,1981,145.3886,15.923334,5.4141722,0.0,0,4.0793095,0.0,0.44725543,119.19380639164432,4.5292978,301.1033,-9.3158092,119.19380639164432
1983,1983,145.389,16.002893,5.4499683,0.0,0,4.0404716,0.0,0.45165837,119.28828873845156,4.4858031,301.03436,-9.3163671,119.28828873845156
1985,1985,145.3894,16.081039,5.4990683,0.0,0,4.0030656,0.0,0.4555833,119.18008465260826,4.4449878,300.96545,-9.3163404,119.18008465260826
1987,1987,145.3898,16.149872,5.5368371,0.0,0,3.9657533,0.0,0.46039745,119.15656366107206,4.4053679,300.89655,-9.3158169,119.15656366107206
1989,1989,145.3902,16.19919,5.5739837,0.0,0,3.9284413,0.0,0.46442243,118.99391368717394,4.3649402,300.82761,-9.3149385,118.99391368717394
1991,1991,145.3906,16.266636,5.6242046,0.0,0,3.8911293,0.0,0.46873298,118.77444807764874,4.3222485,300.7587,-9.3150988,118.77444807764874
1993,1993,145.391,16.354605,5.6551361,0.0,0,3.8538175,0.0,0.47330505,118.97402445692629,4.2814188,300.68979,-9.3151627,118.97402445692629
1995,1995,145.3914,16.442797,5.6932511,0.0,0,3.8165054,0.0,0.47688806,119.06701975245066,4.2401156,300.62088,-9.3165751,119.06701975245066
1997,1997,145.3918,16.497137,5.7412491,0.0,0,3.7791932,0.0,0.48157871,118.76732740045719,4.2011747,300.55194,-9.3165283,118.76732740045719
1999,1999,145.3922,16.54949,5.7723174,0.0,0,3.7418811,0.0,0.48599121,118.69406721412955,4.162683,300.48303,-9.3158512,118.69406721412955
2001,2001,145.3926,16.617435,5.814805,0.0,0,3.7045693,0.0,0.48965999,118.56315429194579,4.1198778,300.41412,-9.3160152,118.56315429194579
2003,2003,145.393,16.724602,5.861711,0.0,0,3.6672573,0.0,0.49496004,118.64077281771941,4.080554,300.34518,-9.3156509,118.64077281771941
2005,2005,145.3934,16.807045,5.8921533,0.0,0,3.6299453,0.0,0.4990679,118.77748580143113,4.0427289,300.29227,-9.3148317,118.77748580143113
2007,2007,145.3938,16.859478,5.9342046,0.0,0,3.5926332,0.0,0.5026409,118.52702862618057,4.0006337,300.24799,-9.3154068,118.52702862618057
2009,2009,145.3942,16.923107,5.9728785,0.0,0,3.5565166,0.0,0.50764978,118.40100221851388,3.9617827,300.20367,-9.3158274,118.40100221851388
2011,2011,145.3946,17.000494,6.0072422,0.0,0,3.5210168,0.0,0.51142418,118.43059038842028,3.9254565,300.15936,-9.3155336,118.43059038842028
2013,2013,145.395,17.095659,6.051012,0.0,0,3.4855206,0.0,0.51554996,118.43786489298893,3.8861454,300.11505,-9.3159237,118.43786489298893
2015,2015,145.3954,17.190458,6.0875368,0.0,0,3.4500248,0.0,0.52082652,118.54438238593775,3.8490312,300.07077,-9.3154268,118.54438238593775
2017,2017,145.3958,17.23229,6.1259651,0.0,0,3.4145288,0.0,0.52433372,118.25245614925481,3.8116927,300.02646,-9.315115,118.25245614925481
2019,2019,145.3962,17.303873,6.1663566,0.0,0,3.3790326,0.0,0.52867901,118.13102031102761,3.772908,299.98215,-9.3152466,118.13102031102761
2021,2021,145.3966,17.40015,6.2004466,0.0,0,3.3435369,0.0,0.53355783,118.26827630831045,3.7356663,299.93784,-9.3165751,118.26827630831045
2023,2023,145.397,17.5051,6.2418985,0.0,0,3.3080409,0.0,0.53711754,118.34541725616283,3.6965404,299.89355,-9.3159456,118.34541725616283
2025,2025,145.3974,17.588896,6.2791824,0.0,0,3.2725446,0.0,0.54185748,118.33689004486867,3.6604626,299.84924,-9.3147392,118.33689004486867
2027,2027,145.3978,17.646931,6.3091469,0.0,0,3.2370486,0.0,0.54597676,118.26362067414847,3.6211751,299.80493,-9.3150797,118.26362067414847
2029,2029,145.3982,17.730864,6.3549294,0.0,0,3.2015526,0.0,0.54990077,118.11413500151872,3.5840046,299.76062,-9.3157272,118.11413500151872
2031,2031,145.3986,17.82132,6.3873191,0.0,0,3.1660566,0.0,0.55460191,118.21037511399986,3.5475066,299.71634,-9.3159304,118.21037511399986
2033,2033,145.399,17.914518,6.4203544,0.0,0,3.1309152,0.0,0.55845821,118.30938669809258,3.5118902,299.67203,-9.3154106,118.30938669809258
2035,2035,145.3994,17.997368,6.4681334,0.0,0,3.0970623,0.0,0.56299675,118.1020790098381,3.4772153,299.62772,-9.3152199,118.1020790098381
2037,2037,145.3998,18.060446,6.4963703,0.0,0,3.0632944,0.0,0.56783688,118.0685152379017,3.439425,299.5834,-9.3151808,118.0685152379017
2039,2039,145.4002,18.136644,6.5323186,0.0,0,3.0295265,0.0,0.57125491,117.99448875799159,3.4039662,299.53912,-9.3164806,117.99448875799159
2041,2041,145.4006,18.243528,6.5757375,0.0,0,2.9957583,0.0,0.57603872,117.99463288806598,3.3686233,299.49481,-9.3156538,117.99463288806598
2043,2043,145.401,18.350231,6.6022148,0.0,0,2.9619906,0.0,0.58038193,118.25827705034479,3.3314445,299.4505,-9.3149109,118.25827705034479
2045,2045,145.4014,18.431141,6.6417451,0.0,0,2.9282222,0.0,0.58392245,118.14009150699145,3.2953453,299.40619,-9.3146992,118.14009150699145
2047,2047,145.4018,18.49369,6.6841168,0.0,0,2.8944542,0.0,0.5892638,117.85301669665539,3.2563324,299.36191,-9.315239,117.85301669665539
2049,2049,145.4022,18.584484,6.7115822,0.0,0,2.8606863,0.0,0.59329718,117.98340793026644,3.2212119,299.3176,-9.3154106,117.98340793026644
2051,2051,145.4026,18.695719,6.7521191,0.0,0,2.8269184,0.0,0.59706467,118.0240357088624,3.1856022,299.27328,-9.3149681,118.0240357088624
2053,2053,145.403,18.815042,6.788662,0.0,0,2.7931502,0.0,0.60243756,118.17343334294436,3.1493745,299.22897,-9.3145304,118.17343334294436
2055,2055,145.4034,18.898577,6.8192892,0.0,0,2.7593822,0.0,0.60610098,118.1896800694215,3.1119001,298.93423,-9.3147707,118.1896800694215
2057,2057,145.4038,18.966944,6.8586636,0.0,0,2.7256143,0.0,0.61017752,117.96117658972028,3.0766089,298.53217,-9.3147554,117.96117658972028
2059,2059,145.4042,19.069656,6.8932276,0.0,0,2.6929309,0.0,0.61558628,118.02087471160137,3.0422375,298.13013,-9.3147287,118.02087471160137
2061,2061,145.4046,19.18042,6.9297495,0.0,0,2.6608074,0.0,0.61910391,118.09085930743281,3.0069139,297.72806,-9.3147116,118.09085930743281
2063,2063,145.405,19.277945,6.9656291,0.0,0,2.6286874,0.0,0.62361509,118.08345872302749,2.9699001,297.32599,-9.315156,118.08345872302749
2065,2065,145.4054,19.375185,6.9961281,0.0,0,2.5965672,0.0,0.62847275,118.15973017459618,2.9393096,296.92395,-9.3145094,118.15973017459618
2067,2067,145.4058,19.454952,7.0354095,0.0,0,2.5644474,0.0,0.63210016,117.97445518285976,2.9014385,296.52188,-9.3149614,117.97445518285976
2069,2069,145.4062,19.556742,7.0676894,0.0,0,2.5323272,0.0,0.63666117,118.03675093627236,2.8728292,296.11984,-9.315074,118.03675093627236
2071,2071,145.4066,19.656384,7.0962305,0.0,0,2.5002072,0.0,0.64096946,118.14492314873755,2.8342314,295.71777,-9.3142691,118.14492314873755
2073,2073,145.407,19.758144,7.1391611,0.0,0,2.4680872,0.0,0.64492679,118.01072979280629,2.8035903,295.31573,-9.315526,118.01072979280629
2075,2075,145.4074,19.861893,7.1675153,0.0,0,2.4359674,0.0,0.64963436,118.13516421215638,2.7683966,294.91367,-9.3138914,118.13516421215638
2077,2077,145.4078,19.950039,7.1989107,0.0,0,2.4038472,0.0,0.65350771,118.10860396151342,2.7327898,294.5116,-9.3144169,118.10860396151342
2079,2079,145.4082,20.030159,7.2429404,0.0,0,2.3717272,0.0,0.65810049,117.80722720927047,2.7028697,294.10956,-9.3148146,117.80722720927047
2081,2081,145.4086,20.141733,7.2669601,0.0,0,2.3396072,0.0,0.66282499,118.03787199414643,2.6684525,293.70749,-9.315136,118.03787199414643
2083,2083,145.409,20.276617,7.300045,0.0,0,2.3078089,0.0,0.66617858,118.23816933541313,2.633446,293.30545,-9.3149776,118.23816933541313
2085,2085,145.4094,20.366344,7.3413744,0.0,0,2.2771804,0.0,0.67118287,118.02080207873534,2.5999241,292.90338,-9.3151445,118.02080207873534
2087,2087,145.4098,20.456615,7.3650813,0.0,0,2.246628,0.0,0.67572695,118.11717788549093,2.5673358,292.50131,-9.3148432,118.11717788549093
2089,2089,145.4102,20.559189,7.4004917,0.0,0,2.2160764,0.0,0.67888069,118.06878382739333,2.5357616,292.09927,-9.314496,118.06878382739333
2091,2091,145.4106,20.685591,7.4370089,0.0,0,2.1855242,0.0,0.6843155,118.12987187491147,2.5024776,291.6972,-9.3138752,118.12987187491147
2093,2093,145.411,20.816298,7.4626188,0.0,0,2.1549723,0.0,0.6882717,118.40706522920324,2.4695537,291.29517,-9.3136187,118.40706522920324
2095,2095,145.4114,20.909286,7.4996853,0.0,0,2.1244202,0.0,0.69196087,118.25374345393395,2.4364247,290.8931,-9.3144741,118.25374345393395
2097,2097,145.4118,21.004519,7.5314221,0.0,0,2.0938683,0.0,0.69744402,118.20545975438566,2.4041023,290.49103,-9.314538,118.20545975438566
2099,2099,145.4122,21.117298,7.5583463,0.0,0,2.0633163,0.0,0.70069063,118.33953293055134,2.3715503,290.08899,-9.3150711,118.33953293055134
2101,2101,145.4126,21.24505,7.5956278,0.0,0,2.0327644,0.0,0.70480859,118.35800193816961,2.3382428,289.68692,-9.3139639,118.35800193816961
2103,2103,145.413,21.375961,7.6251459,0.0,0,2.0022123,0.0,0.71037316,118.53164882804502,2.31001,289.28488,-9.3141747,118.53164882804502
2105,2105,145.4134,21.480005,7.6576829,0.0,0,1.9716601,0.0,0.71366298,118.49304196704647,2.2771711,289.05423,-9.3143291,118.49304196704647
2107,2107,145.4138,21.579817,7.6904311,0.0,0,1.9411081,0.0,0.71815413,118.42117048719577,2.2444642,288.88071,-9.314023,118.42117048719577
2109,2109,145.4142,21.695028,7.7161579,0.0,0,1.9115355,0.0,0.72291583,118.5617307373008,2.2144289,288.70718,-9.314805,118.5617307373008
2111,2111,145.4146,21.843399,7.7541118,0.0,0,1.8824685,0.0,0.72648823,118.64218982143473,2.1831081,288.53366,-9.3145437,118.64218982143473
2113,2113,145.415,21.978449,7.7838469,0.0,0,1.8534043,0.0,0.73150516,118.7998982183985,2.1525121,288.36014,-9.314332,118.7998982183985
2115,2115,145.4154,22.073404,7.8105946,0.0,0,1.8243403,0.0,0.73566395,118.79291094627081,2.1192355,288.18661,-9.3137655,118.79291094627081
2117,2117,145.4158,22.182976,7.8512359,0.0,0,1.7952764,0.0,0.73962373,118.58811230480875,2.0903103,288.01309,-9.3136139,118.58811230480875
2119,2119,145.4162,22.296234,7.8745303,0.0,0,1.7662123,0.0,0.7444579,118.73583436226306,2.0571816,287.83957,-9.3133774,118.73583436226306
2121,2121,145.4166,22.461798,7.9008002,0.0,0,1.7371484,0.0,0.74791014,119.09743842893033,2.0264454,287.66605,-9.3130035,119.09743842893033
2123,2123,145.417,22.600294,7.9421072,0.0,0,1.7080843,0.0,0.75234425,119.00886098260207,1.996437,287.49252,-9.3140621,119.00886098260207
2125,2125,145.4174,22.709896,7.9635496,0.0,0,1.6790204,0.0,0.75737137,119.15671914470927,1.9656135,287.319,-9.3144026,119.15671914470927
2127,2127,145.4178,22.826784,7.9962282,0.0,0,1.6499563,0.0,0.76089579,119.11236123934738,1.9334821,287.14545,-9.3137846,119.11236123934738
2129,2129,145.4182,22.961596,8.0347128,0.0,0,1.6208923,0.0,0.76610982,119.03666303477772,1.9041544,286.97192,-9.3134604,119.03666303477772
2131,2131,145.4186,23.121416,8.0541525,0.0,0,1.5918283,0.0,0.77036756,119.46884632489136,1.8715304,286.7984,-9.3121433,119.46884632489136
2133,2133,145.419,23.263578,8.0881901,0.0,0,1.5630548,0.0,0.77372861,119.50509770714864,1.8419271,286.62488,-9.312109,119.50509770714864
2135,2135,145.4194,23.366282,8.1227961,0.0,0,1.5353373,0.0,0.77946144,119.3195198834963,1.8106546,286.45135,-9.313097,119.3195198834963
2137,2137,145.4198,23.488649,8.144434,0.0,0,1.5076892,0.0,0.78314358,119.49609456675964,1.7819231,286.27783,-9.3140326,119.49609456675964
2139,2139,145.4202,23.63513,8.178463,0.0,0,1.4800413,0.0,0.78669113,119.53184200710189,1.7539269,286.10431,-9.314043,119.53184200710189
2141,2141,145.4206,23.809153,8.2070484,0.0,0,1.4523933,0.0,0.79237485,119.81153377629182,1.7250788,285.93079,-9.3129807,119.81153377629182
2143,2143,145.421,23.936903,8.2331266,0.0,0,1.4247453,0.0,0.79565698,119.9036641858926,1.6987438,285.75726,-9.3122683,119.9036641858926
2145,2145,145.4214,24.055965,8.2678337,0.0,0,1.3970973,0.0,0.79997265,119.76340019471098,1.668252,285.58374,-9.3121748,119.76340019471098
2147,2147,145.4218,24.203543,8.2932434,0.0,0,1.3694494,0.0,0.80549312,119.95544361482315,1.6381869,285.41022,-9.3131161,119.95544361482315
2149,2149,145.4222,24.343622,8.3239756,0.0,0,1.3418013,0.0,0.80863345,119.98949006366499,1.6121768,285.23669,-9.3129587,119.98949006366499
2151,2151,145.4226,24.514652,8.35291,0.0,0,1.3141534,0.0,0.81306344,120.20649874723532,1.580205,285.06317,-9.3134289,120.20649874723532
2153,2153,145.423,24.656872,8.3753643,0.0,0,1.2865053,0.0,0.81780517,120.41521709375307,1.550975,284.88965,-9.3131227,120.41521709375307
2155,2155,145.4234,24.785055,8.4118423,0.0,0,1.2588574,0.0,0.82145381,120.2431927407437,1.5233353,285.25241,-9.3114653,120.2431927407437
2157,2157,145.4238,24.922283,8.4400778,0.0,0,1.2312094,0.0,0.82681733,120.28777035657073,1.4938568,285.74921,-9.3111401,120.28777035657073
2159,2159,145.4242,25.081863,8.4627399,0.0,0,1.2044513,0.0,0.83079994,120.55619873559064,1.4622926,286.246,-9.3123016,120.55619873559064
2161,2161,145.4246,25.25168,8.4981728,0.0,0,1.1781524,0.0,0.83437246,120.58249666580774,1.4381795,286.7428,-9.3133259,120.58249666580774
2163,2163,145.425,25.406788,8.5181837,0.0,0,1.1518564,0.0,0.83929521,120.87428519286895,1.4082124,287.23956,-9.3126621,120.87428519286895
2165,2165,145.4254,25.539101,8.5438538,0.0,0,1.1255604,0.0,0.84261733,120.92490556821308,1.378643,287.73636,-9.3112297,120.92490556821308
2167,2167,145.4258,25.674648,8.5822439,0.0,0,1.0992644,0.0,0.84743112,120.69633892756782,1.3520839,288.23315,-9.3096027,120.69633892756782
2169,2169,145.4262,25.836227,8.5998459,0.0,0,1.0729684,0.0,0.85236907,121.05431605830255,1.3223513,288.72995,-9.3114119,121.05431605830255
2171,2171,145.4266,26.013672,8.6305151,0.0,0,1.0466723,0.0,0.85559326,121.18113611591983,1.2940013,289.22672,-9.3124018,121.18113611591983
2173,2173,145.427,26.165405,8.6653795,0.0,0,1.0203763,0.0,0.86100054,121.08226202596497,1.2706313,289.72351,-9.3121672,121.08226202596497
2175,2175,145.4274,26.297152,8.6794147,0.0,0,0.99408036,0.0,0.86493188,121.3659320093151,1.2419713,290.22031,-9.3109474,121.3659320093151
2177,2177,145.4278,26.440609,8.7078094,0.0,0,0.96778435,0.0,0.86752325,121.36485238891814,1.2148423,290.7171,-9.3104258,121.36485238891814
2179,2179,145.4282,26.60166,8.7379293,0.0,0,0.94148839,0.0,0.87316924,121.39631117162908,1.1854774,291.21387,-9.3109226,121.39631117162908
2181,2181,145.4286,26.776861,8.7576828,0.0,0,0.91519243,0.0,0.87671202,121.72857395060944,1.1588942,291.71066,-9.3105354,121.72857395060944
2183,2183,145.429,26.934511,8.7912807,0.0,0,0.88916051,0.0,0.88082063,121.64578249406378,1.1356243,292.20746,-9.3106022,121.64578249406378
2185,2185,145.4294,27.076212,8.8168554,0.0,0,0.86408949,0.0,0.8865602,121.67395702552912,1.1106302,292.70425,-9.3106546,121.67395702552912
2187,2187,145.4298,27.235569,8.8377419,0.0,0,0.83908135,0.0,0.88942957,121.88745887436798,1.0835128,293.20102,-9.3113146,121.88745887436798
2189,2189,145.4302,27.402287,8.8654928,0.0,0,0.81407332,0.0,0.89298004,121.96165937428485,1.056282,293.69781,-9.3111572,121.96165937428485
2191,2191,145.4306,27.587885,8.8840799,0.0,0,0.78906536,0.0,0.89780098,122.33461155620748,1.0335448,294.19461,-9.3112106,122.33461155620748
2193,2193,145.431,27.747305,8.913866,0.0,0,0.7640574,0.0,0.90087199,122.31120256970938,1.005186,294.69141,-9.3105326,122.31120256970938
2195,2195,145.4314,27.899794,8.9427738,0.0,0,0.73904938,0.0,0.9060654,122.27064830973805,0.98085421,295.18817,-9.3102236,122.27064830973805
2197,2197,145.4318,28.053669,8.9629049,0.0,0,0.71404135,0.0,0.91080952,122.44590678580033,0.95279163,295.68497,-9.3103848,122.44590678580033
2199,2199,145.4322,28.227991,8.9933805,0.0,0,0.68903339,0.0,0.91391039,122.44648129476064,0.93080199,296.18176,-9.3105698,122.44648129476064
2201,2201,145.4326,28.423861,9.0133276,0.0,0,0.66402543,0.0,0.91837358,122.79501707553821,0.90579784,296.67856,-9.3109026,122.79501707553821
2203,2203,145.433,28.59726,9.031827,0.0,0,0.63901734,0.0,0.92173022,123.07654142227314,0.87849188,297.17532,-9.3106604,123.07654142227314
2205,2205,145.4334,28.742456,9.0663824,0.0,0,0.61400938,0.0,0.92573345,122.82355671524526,0.85402852,297.40674,-9.3097591,122.82355671524526
2207,2207,145.4338,28.916445,9.0838699,0.0,0,0.58900136,0.0,0.93065953,123.1200796951294,0.83017033,297.59134,-9.3098211,123.1200796951294
2209,2209,145.4342,29.102154,9.1071339,0.0,0,0.56478846,0.0,0.93389708,123.31233367160974,0.80376005,297.77594,-9.3099079,123.31233367160974
2211,2211,145.4346,29.306408,9.1414995,0.0,0,0.54098594,0.0,0.938676,123.28752666243285,0.78142065,297.96054,-9.3091249,123.28752666243285
2213,2213,145.435,29.469276,9.1543169,0.0,0,0.51718587,0.0,0.94305664,123.63878392745426,0.75581604,298.14514,-9.3094091,123.63878392745426
2215,2215,145.4354,29.629372,9.181077,0.0,0,0.49338591,0.0,0.94595301,123.6095443124067,0.73139459,298.32974,-9.3105602,123.6095443124067
2217,2217,145.4358,29.801479,9.2116966,0.0,0,0.4695859,0.0,0.95115525,123.52085004226853,0.70595211,298.51434,-9.3101702,123.52085004226853
2219,2219,145.4362,30.015211,9.2228651,0.0,0,0.44578591,0.0,0.95474696,124.1103635287924,0.68142301,298.69894,-9.3086987,124.1103635287924
2221,2221,145.4366,30.215919,9.251646,0.0,0,0.42198589,0.0,0.95762026,124.1714399101186,0.65901107,298.88354,-9.3089495,124.1714399101186
2223,2223,145.437,30.391705,9.2773781,0.0,0,0.39818591,0.0,0.96359777,124.20242098735592,0.63138443,299.06815,-9.308816,124.20242098735592
2225,2225,145.4374,30.550674,9.2947674,0.0,0,0.37438589,0.0,0.96683103,124.38239047563539,0.60948676,299.25275,-9.3089695,124.38239047563539
2227,2227,145.4378,30.733202,9.3223705,0.0,0,0.35058588,0.0,0.97004646,124.37548675175314,0.584391,299.43735,-9.3083429,124.37548675175314
2229,2229,145.4382,30.947805,9.3428659,0.0,0,0.32678592,0.0,0.97577041,124.68316868334784,0.56285536,299.62195,-9.3082113,124.68316868334784
2231,2231,145.4386,31.145613,9.3637657,0.0,0,0.30298588,0.0,0.9784233,124.90457023075247,0.54146731,299.80655,-9.3080997,124.90457023075247
2232,2232,145.4388,31.24165,9.3766966,0.0,0,0.29108587,0.0,0.98190469,124.93252367793565,0.52887118,299.89883,-9.3080816,124.93252367793565