File: examples/hot axisymmetric compression example/data/04 corrected data/testID_0140.csv
level_0,index,Time(sec),Force(kN),Jaw(mm),PowAngle(deg),Power(W),Pram,PTemp,Strain,Stress(MPa),Stroke(mm),TC1(C),wedge(mm),uncorrected stress
1972,1972,165.3437,0.48988101,0.038960356,0.0,0,9.0629654,0.0,0.0026651777,5.955437402151924,10.05454,360.74109,-9.287818,5.955437402151924
1974,1974,165.3441,4.1785111,0.10166378,0.0,0,9.0044374,0.0,0.0060520191,50.57121671432526,9.9893322,360.92413,-9.2873917,50.57121671432526
1976,1976,165.3445,6.2359042,0.143987,0.0,0,8.9459095,0.0,0.0094992639,75.24297843807358,9.9335051,361.10718,-9.2851009,75.24297843807358
1978,1978,165.3449,6.7424273,0.23419167,0.0,0,8.8873816,0.0,0.0147804,80.82874484751883,9.8504953,361.29022,-9.2831631,80.82874484751883
1980,1980,165.3453,6.9424734,0.39043668,0.0,0,8.8288536,0.0,0.025315521,82.28863386878265,9.7645473,361.47327,-9.2825356,82.28863386878265
1982,1982,165.3457,7.5262156,0.43537864,0.0,0,8.7703257,0.0,0.029317416,88.91506489430515,9.6610699,361.65628,-9.2829514,88.91506489430515
1984,1984,165.3461,7.9085369,0.54334193,0.0,0,8.7136831,0.0,0.035983499,92.6930650950142,9.5701656,361.79779,-9.2820959,92.6930650950142
1986,1986,165.3465,8.5026789,0.59598184,0.0,0,8.6580124,0.0,0.04035588,99.26947616387783,9.4851303,361.81476,-9.2809668,99.26947616387783
1988,1988,165.3469,7.8667517,0.61699843,0.0,0,8.6023483,0.0,0.041656833,91.70189641592354,9.4132805,361.83173,-9.281662,91.70189641592354
1990,1990,165.3473,8.1063938,0.719522,0.0,0,8.5466843,0.0,0.048441101,93.77608278873171,9.352169,361.84869,-9.2834377,93.77608278873171
1992,1992,165.3477,8.6379719,0.7520079,0.0,0,8.4910212,0.0,0.05119225,99.68257413142331,9.2893124,361.86569,-9.2823381,99.68257413142331
1994,1994,165.3481,8.8279161,0.82727009,0.0,0,8.4353561,0.0,0.056059334,101.29939335372352,9.2172651,361.88266,-9.2798548,101.29939335372352
1996,1996,165.3485,8.5641785,0.92894113,0.0,0,8.3796921,0.0,0.063141622,97.51917565423356,9.1399374,361.89963,-9.2809172,97.51917565423356
1998,1998,165.3489,8.5072651,1.000856,0.0,0,8.324029,0.0,0.068578117,96.34135213335732,9.0644188,361.9166,-9.2810936,96.34135213335732
2000,2000,165.3493,8.8295813,1.0721527,0.0,0,8.2683649,0.0,0.07377822,99.44628452920605,8.9827671,361.93356,-9.2817259,99.44628452920605
2002,2002,165.3497,8.8362751,1.1142014,0.0,0,8.2127008,0.0,0.076761588,99.19987648740558,8.9147663,361.95053,-9.2811451,99.19987648740558
2004,2004,165.3501,9.0458469,1.1677152,0.0,0,8.1570368,0.0,0.080820203,101.13333143744731,8.8558168,361.9675,-9.2800016,101.13333143744731
2006,2006,165.3505,8.6738167,1.2305402,0.0,0,8.1013727,0.0,0.085169159,96.50195543703107,8.7988205,361.98447,-9.2788944,96.50195543703107
2008,2008,165.3509,9.2040672,1.2769774,0.0,0,8.0462637,0.0,0.088435955,102.03106406809404,8.7439842,362.00146,-9.2792521,102.03106406809404
2010,2010,165.3513,9.2089806,1.3525676,0.0,0,7.9931717,0.0,0.094166905,101.48240647828905,8.6797743,362.01843,-9.2798014,101.48240647828905
2012,2012,165.3517,9.136673,1.4349113,0.0,0,7.9402113,0.0,0.099872671,100.03363886432982,8.6158447,362.0354,-9.2804556,100.03363886432982
2014,2014,165.3521,9.0861015,1.4941436,0.0,0,7.8872514,0.0,0.10442524,99.01352768747397,8.5477304,362.05237,-9.2809563,99.01352768747397
2016,2016,165.3525,9.1648827,1.5533683,0.0,0,7.8342915,0.0,0.10926408,99.40156749327511,8.4837694,362.06934,-9.2800493,99.40156749327511
2018,2018,165.3529,9.3427105,1.5919124,0.0,0,7.7813311,0.0,0.11162143,101.01812497378609,8.4240971,362.0863,-9.2778301,101.01812497378609
2020,2020,165.3533,9.2236605,1.6434853,0.0,0,7.7283711,0.0,0.11559139,99.31852257719807,8.3699236,362.10327,-9.2796583,99.31852257719807
2022,2022,165.3537,9.2585688,1.696395,0.0,0,7.6754107,0.0,0.1198269,99.2697039634833,8.3207865,362.12024,-9.2804947,99.2697039634833
2024,2024,165.3541,9.4884377,1.7408608,0.0,0,7.6224508,0.0,0.12258908,101.36852187235507,8.2674465,362.13724,-9.2800188,101.36852187235507
2026,2026,165.3545,9.561183,1.8015329,0.0,0,7.5694909,0.0,0.12762466,101.64266224094268,8.210537,362.15421,-9.2797976,101.64266224094268
2028,2028,165.3549,9.4504337,1.8600278,0.0,0,7.516531,0.0,0.13199699,99.98590299367469,8.1537437,362.17117,-9.2792606,99.98590299367469
2030,2030,165.3553,9.4876032,1.9278661,0.0,0,7.4635711,0.0,0.13683532,99.8209183450945,8.0960484,362.18814,-9.2791948,99.8209183450945
2032,2032,165.3557,9.5230379,1.9720715,0.0,0,7.4106107,0.0,0.14093213,99.828571451965,8.0379028,362.20511,-9.2790718,99.828571451965
2034,2034,165.3561,9.6986599,2.0123925,0.0,0,7.3593569,0.0,0.143566,101.33034565132716,7.9862394,362.14963,-9.2809143,101.33034565132716
2036,2036,165.3565,9.6096287,2.0720975,0.0,0,7.3089838,0.0,0.14816882,99.90238861480933,7.9369092,361.87686,-9.2819309,99.90238861480933
2038,2038,165.3569,9.585454,2.1129725,0.0,0,7.258616,0.0,0.15171768,99.31110921924956,7.8858633,361.60413,-9.28092,99.31110921924956
2040,2040,165.3573,9.753932,2.1581726,0.0,0,7.2082477,0.0,0.15469356,100.67407444953723,7.8384099,361.33139,-9.280158,100.67407444953723
2042,2042,165.3577,9.8788395,2.216342,0.0,0,7.1578794,0.0,0.15954465,101.46459767484545,7.7852383,361.05862,-9.2794552,101.46459767484545
2044,2044,165.3581,9.8580055,2.2636201,0.0,0,7.107511,0.0,0.16330622,100.84610419854322,7.7343311,360.78589,-9.2802315,100.84610419854322
2046,2046,165.3585,9.7714491,2.3224714,0.0,0,7.0571437,0.0,0.16748936,99.46148281166337,7.6833019,360.51315,-9.2807932,99.46148281166337
2048,2048,165.3589,9.8535604,2.3688974,0.0,0,7.0067749,0.0,0.1718315,99.90015265337495,7.6323571,360.24042,-9.2816362,99.90015265337495
2050,2050,165.3593,9.974802,2.4084136,0.0,0,6.9564075,0.0,0.1746628,100.78715217248953,7.5848083,359.96765,-9.2810144,100.78715217248953
2052,2052,165.3597,10.002891,2.4633989,0.0,0,6.9060392,0.0,0.1788628,100.5934146083966,7.5325508,359.69492,-9.2802143,100.5934146083966
2054,2054,165.3601,9.9541254,2.5035887,0.0,0,6.8556719,0.0,0.18263035,99.75562150488406,7.4893522,359.42218,-9.2804461,99.75562150488406
2056,2056,165.3605,10.065613,2.5543368,0.0,0,6.8053036,0.0,0.18607397,100.42929733425053,7.4380584,359.14941,-9.2804489,100.42929733425053
2058,2058,165.3609,10.121484,2.6056612,0.0,0,6.7554379,0.0,0.19033869,100.53557188445423,7.3883848,358.87668,-9.2813196,100.53557188445423
2060,2060,165.3613,10.119414,2.6501408,0.0,0,6.7073984,0.0,0.19436148,100.12404602220505,7.3423014,358.60394,-9.2815447,100.12404602220505
2062,2062,165.3617,10.176924,2.7089381,0.0,0,6.6594777,0.0,0.19838375,100.17325754172279,7.2916608,358.33121,-9.2821798,100.17325754172279
2064,2064,165.3621,10.204155,2.7484403,0.0,0,6.6115575,0.0,0.20221446,100.09110094141498,7.2413669,358.05844,-9.2802601,100.09110094141498
2066,2066,165.3625,10.297059,2.7914608,0.0,0,6.5636377,0.0,0.20571251,100.61749045802097,7.1919775,357.78571,-9.2808409,100.61749045802097
2068,2068,165.3629,10.280476,2.8482873,0.0,0,6.515718,0.0,0.20970513,99.94780390587113,7.145988,357.51297,-9.2795668,99.94780390587113
2070,2070,165.3633,10.340587,2.8854682,0.0,0,6.4677982,0.0,0.21357173,100.19808653266064,7.0962567,357.24023,-9.279604,100.19808653266064
2072,2072,165.3637,10.436534,2.9347942,0.0,0,6.419878,0.0,0.21735449,100.68037483182462,7.046452,356.96747,-9.281146,100.68037483182462
2074,2074,165.3641,10.473282,2.9935119,0.0,0,6.3719578,0.0,0.22183646,100.50033558491806,6.9982648,356.69473,-9.2816858,100.50033558491806
2076,2076,165.3645,10.49384,3.0350168,0.0,0,6.324038,0.0,0.22606848,100.31897945030245,6.9473524,356.422,-9.2807322,100.31897945030245
2078,2078,165.3649,10.49893,3.0877049,0.0,0,6.2761183,0.0,0.2298739,99.88670916724075,6.8978038,356.14923,-9.2807693,99.88670916724075
2080,2080,165.3653,10.578212,3.1368823,0.0,0,6.2281981,0.0,0.23406082,100.18867228050686,6.849515,355.8765,-9.2809772,100.18867228050686
2082,2082,165.3657,10.644554,3.1767426,0.0,0,6.1802783,0.0,0.23786992,100.4480488376603,6.8025427,355.60376,-9.2794924,100.4480488376603
2084,2084,165.3661,10.662606,3.2267425,0.0,0,6.1339011,0.0,0.24155773,100.15474620715082,6.7527723,355.37073,-9.280591,100.15474620715082
2086,2086,165.3665,10.676274,3.2742579,0.0,0,6.0883203,0.0,0.24596006,99.84190511981001,6.7028604,355.25677,-9.2801208,99.84190511981001
2088,2088,165.3669,10.740751,3.3204424,0.0,0,6.0427446,0.0,0.24995808,100.01337548186453,6.657402,355.14282,-9.2807665,100.01337548186453
2090,2090,165.3673,10.8171,3.3692687,0.0,0,5.9971681,0.0,0.25371528,100.26482789759112,6.6091642,355.02887,-9.2813492,100.26482789759112
2092,2092,165.3677,10.856305,3.4178038,0.0,0,5.951592,0.0,0.25844234,100.16977955651485,6.5615416,354.91495,-9.2813358,100.16977955651485
2094,2094,165.3681,10.869115,3.4650776,0.0,0,5.9060163,0.0,0.26228654,99.84086985750962,6.5121017,354.80099,-9.2812243,99.84086985750962
2096,2096,165.3685,10.906929,3.5151849,0.0,0,5.8604403,0.0,0.26636583,99.71261247880264,6.4641418,354.68704,-9.2809067,99.71261247880264
2098,2098,165.3689,10.954626,3.5621493,0.0,0,5.8148637,0.0,0.27108854,99.70088956450212,6.418108,354.57309,-9.2803841,99.70088956450212
2100,2100,165.3693,11.017509,3.610029,0.0,0,5.7692881,0.0,0.27462664,99.81403046153714,6.3689752,354.45914,-9.2816763,99.81403046153714
2102,2102,165.3697,11.054774,3.656214,0.0,0,5.723712,0.0,0.27892065,99.70716727635111,6.3190908,354.34518,-9.2812595,99.70716727635111
2104,2104,165.3701,11.105408,3.7000539,0.0,0,5.6781363,0.0,0.28321919,99.73997664561405,6.2730708,354.23123,-9.2810268,99.73997664561405
2106,2106,165.3705,11.143604,3.7520118,0.0,0,5.6325603,0.0,0.28707242,99.5788686556428,6.2259569,354.11728,-9.2809753,99.5788686556428
2108,2108,165.3709,11.185519,3.7971101,0.0,0,5.5874381,0.0,0.29153091,99.51412798594407,6.1790247,354.00333,-9.2817802,99.51412798594407
2110,2110,165.3713,11.234664,3.84235,0.0,0,5.5439701,0.0,0.29574358,99.50870059497309,6.1334825,353.8894,-9.2823067,99.50870059497309
2112,2112,165.3717,11.305867,3.8975136,0.0,0,5.5006099,0.0,0.29985383,99.59612428554404,6.0849323,353.77545,-9.2815256,99.59612428554404
2114,2114,165.3721,11.348713,3.9393439,0.0,0,5.4572496,0.0,0.304483,99.5600170699396,6.0337152,353.6615,-9.2809763,99.5600170699396
2116,2116,165.3725,11.36283,3.9843807,0.0,0,5.4138899,0.0,0.30830631,99.23801277977496,5.9855409,353.54755,-9.2813444,99.23801277977496
2118,2118,165.3729,11.408148,4.0400519,0.0,0,5.3705297,0.0,0.31292361,99.08040648810038,5.9393563,353.43359,-9.2818918,99.08040648810038
2120,2120,165.3733,11.484165,4.0808768,0.0,0,5.3271699,0.0,0.3174673,99.33204948886626,5.8905826,353.31964,-9.2811527,99.33204948886626
2122,2122,165.3737,11.540627,4.1264057,0.0,0,5.2838097,0.0,0.32126015,99.362481021863,5.8430037,353.20569,-9.281147,99.362481021863
2124,2124,165.3741,11.569389,4.1805959,0.0,0,5.2404499,0.0,0.32596865,99.06363736610949,5.7941899,353.09174,-9.2802448,99.06363736610949
2126,2126,165.3745,11.594121,4.220397,0.0,0,5.1970901,0.0,0.33030972,98.8731284511062,5.7454948,352.97781,-9.2809,98.8731284511062
2128,2128,165.3749,11.642632,4.2693334,0.0,0,5.1537299,0.0,0.33416975,98.79008760780076,5.698278,352.86386,-9.2809553,98.79008760780076
2130,2130,165.3753,11.708944,4.3202987,0.0,0,5.1103697,0.0,0.33933714,98.83241449071708,5.6515117,352.74991,-9.2808056,98.83241449071708
2132,2132,165.3757,11.779339,4.3603611,0.0,0,5.0670099,0.0,0.34325859,99.015066920279,5.6070838,352.63596,-9.2812853,99.015066920279
2134,2134,165.3761,11.780351,4.4096322,0.0,0,5.0250454,0.0,0.34732506,98.51734162789236,5.5567904,352.49033,-9.2809391,98.51734162789236
2136,2136,165.3765,11.815627,4.4531174,0.0,0,4.9838009,0.0,0.35208818,98.36417248992174,5.5140963,352.24979,-9.2806501,98.36417248992174
2138,2138,165.3769,11.875482,4.4950285,0.0,0,4.9425607,0.0,0.35583708,98.42827029449995,5.4677253,352.00925,-9.2808924,98.42827029449995
2140,2140,165.3773,11.951224,4.5444174,0.0,0,4.9013209,0.0,0.36011955,98.54106326052734,5.4213018,351.76868,-9.2811842,98.54106326052734
2142,2142,165.3777,11.980403,4.5884948,0.0,0,4.8600807,0.0,0.36512721,98.3208726427868,5.3756256,351.52814,-9.2817392,98.3208726427868
2144,2144,165.3781,12.002568,4.6379089,0.0,0,4.818841,0.0,0.36919084,97.9851880930708,5.3314915,351.2876,-9.281539,97.9851880930708
2146,2146,165.3785,12.045468,4.6832986,0.0,0,4.7776008,0.0,0.37371403,97.85821563662927,5.2872243,351.04703,-9.2808714,97.85821563662927
2148,2148,165.3789,12.103669,4.7228737,0.0,0,4.7363605,0.0,0.37823701,97.91292253794009,5.2428207,350.80649,-9.2810392,97.91292253794009
2150,2150,165.3793,12.174501,4.7700286,0.0,0,4.6951208,0.0,0.38193902,97.98474076678605,5.1976991,350.56595,-9.280961,97.98474076678605
2152,2152,165.3797,12.213825,4.8116989,0.0,0,4.6538811,0.0,0.38646331,97.85686367653382,5.1511207,350.32538,-9.2808704,97.85686367653382
2154,2154,165.3801,12.251293,4.8528504,0.0,0,4.6126404,0.0,0.39076704,97.71682224174687,5.1080942,350.08484,-9.2809381,97.71682224174687
2156,2156,165.3805,12.268497,4.9072948,0.0,0,4.5714006,0.0,0.39516154,97.27070773936042,5.0665421,349.84427,-9.2809067,97.27070773936042
2158,2158,165.3809,12.325236,4.9452405,0.0,0,4.5305729,0.0,0.39986271,97.31206829376166,5.0224442,349.60373,-9.2810869,97.31206829376166
2160,2160,165.3813,12.39559,4.9883819,0.0,0,4.4912429,0.0,0.40390018,97.40040724993545,4.9764814,349.36319,-9.2815027,97.40040724993545
2162,2162,165.3817,12.441247,5.0387354,0.0,0,4.4520106,0.0,0.40840435,97.2118629124907,4.9358106,349.12262,-9.2815933,97.2118629124907
2164,2164,165.3821,12.461862,5.0719314,0.0,0,4.4127784,0.0,0.41276711,97.01148814456762,4.8906794,348.88208,-9.281723,97.01148814456762
2166,2166,165.3825,12.505978,5.1169972,0.0,0,4.3735466,0.0,0.4165622,96.86242783907628,4.848907,348.64154,-9.2809906,96.86242783907628
2168,2168,165.3829,12.576447,5.1660771,0.0,0,4.3343148,0.0,0.42146003,96.86878107905548,4.803967,348.40097,-9.2807837,96.86878107905548
2170,2170,165.3833,12.659675,5.2015119,0.0,0,4.295083,0.0,0.42585137,97.11773892440202,4.7587252,348.16043,-9.2796736,97.11773892440202
2172,2172,165.3837,12.683419,5.2496114,0.0,0,4.2558503,0.0,0.42992023,96.766591528005,4.7173023,347.91989,-9.2798843,96.766591528005
2174,2174,165.3841,12.706209,5.2973652,0.0,0,4.2166185,0.0,0.43514299,96.40997624618505,4.6744514,347.67932,-9.2819271,96.40997624618505
2176,2176,165.3845,12.768609,5.3321252,0.0,0,4.1773863,0.0,0.43920434,96.49535898663372,4.6293383,347.43878,-9.2825079,96.49535898663372
2178,2178,165.3849,12.830825,5.3758993,0.0,0,4.1381545,0.0,0.44289756,96.47437790249784,4.5883832,347.19821,-9.2828236,96.47437790249784
2180,2180,165.3853,12.895928,5.4155326,0.0,0,4.0989227,0.0,0.44783261,96.5168734120662,4.5462322,346.95767,-9.2803078,96.5168734120662
2182,2182,165.3857,12.941602,5.4546642,0.0,0,4.0596905,0.0,0.45165762,96.41574463151224,4.5030866,346.71713,-9.2793055,96.41574463151224
2184,2184,165.3861,12.971951,5.5008316,0.0,0,4.0217228,0.0,0.45602828,96.11794490494347,4.4626918,346.47809,-9.2796907,96.11794490494347
2186,2186,165.3865,13.032932,5.5412979,0.0,0,3.9844062,0.0,0.46115875,96.10837069158735,4.4242988,346.24359,-9.2803593,96.10837069158735
2188,2188,165.3869,13.09472,5.5867453,0.0,0,3.9470942,0.0,0.46527967,96.04326803659632,4.3816214,346.00909,-9.2815638,96.04326803659632
2190,2190,165.3873,13.15993,5.6261926,0.0,0,3.9097824,0.0,0.46952981,96.06724922869789,4.3381901,345.77463,-9.2823162,96.06724922869789
2192,2192,165.3877,13.201122,5.6612182,0.0,0,3.8724704,0.0,0.47404271,95.96326428411247,4.2982178,345.54013,-9.2823915,95.96326428411247
2194,2194,165.3881,13.244125,5.7067513,0.0,0,3.8351583,0.0,0.47791436,95.74800063389422,4.2577443,345.30563,-9.2802925,95.74800063389422
2196,2196,165.3885,13.296914,5.744915,0.0,0,3.7978463,0.0,0.48245519,95.68538527077443,4.218914,345.07114,-9.2807646,95.68538527077443
2198,2198,165.3889,13.372079,5.782084,0.0,0,3.7605343,0.0,0.48685524,95.79110927960504,4.1784806,344.83664,-9.2800541,95.79110927960504
2200,2200,165.3893,13.444922,5.8293681,0.0,0,3.7232223,0.0,0.49096075,95.75624140297592,4.136775,344.60214,-9.2813196,95.75624140297592
2202,2202,165.3897,13.486806,5.8645625,0.0,0,3.6859105,0.0,0.49577522,95.6388545987265,4.097795,344.36768,-9.2814589,95.6388545987265
2204,2204,165.3901,13.537451,5.9037166,0.0,0,3.6485984,0.0,0.49984232,95.53374580113937,4.0569925,344.13318,-9.282342,95.53374580113937
2206,2206,165.3905,13.594055,5.9504642,0.0,0,3.6112862,0.0,0.50432903,95.376526992973,4.017859,343.89868,-9.2812119,95.376526992973
2208,2208,165.3909,13.67968,5.9803905,0.0,0,3.5743468,0.0,0.50870192,95.61862538004303,3.9781563,343.66418,-9.2800474,95.61862538004303
2210,2210,165.3913,13.737982,6.0196972,0.0,0,3.5387621,0.0,0.51240093,95.55301894113738,3.9366882,343.42969,-9.2799931,95.55301894113738
2212,2212,165.3917,13.800986,6.0671425,0.0,0,3.5032659,0.0,0.51746702,95.41745058504189,3.9003835,343.19519,-9.2804909,95.41745058504189
2214,2214,165.3921,13.828938,6.1018224,0.0,0,3.4677699,0.0,0.52228218,95.19039719047255,3.8620045,342.96069,-9.280838,95.19039719047255
2216,2216,165.3925,13.894278,6.1449747,0.0,0,3.4322741,0.0,0.52627873,95.1146348182384,3.8225565,342.72623,-9.2812643,95.1146348182384
2218,2218,165.3929,13.975206,6.1881833,0.0,0,3.3967779,0.0,0.53148544,95.13928889092698,3.7812099,342.49173,-9.2814884,95.13928889092698
2220,2220,165.3933,14.044254,6.2160888,0.0,0,3.3612819,0.0,0.53510493,95.26575240352471,3.7426453,342.25723,-9.2807894,95.26575240352471
2222,2222,165.3937,14.091854,6.2545681,0.0,0,3.3257859,0.0,0.53861374,95.11319096465292,3.7037222,342.02274,-9.2803736,95.11319096465292
2224,2224,165.3941,14.129383,6.2942486,0.0,0,3.2902899,0.0,0.54392242,94.87484167452448,3.667088,341.78824,-9.2811432,94.87484167452448
2226,2226,165.3945,14.20035,6.3295593,0.0,0,3.2547936,0.0,0.54782307,94.91160724739296,3.628072,341.55374,-9.2804785,94.91160724739296
2228,2228,165.3949,14.278234,6.3725004,0.0,0,3.2192979,0.0,0.55224109,94.89437886172811,3.5931046,341.31927,-9.2815075,94.89437886172811
2230,2230,165.3953,14.359899,6.4086022,0.0,0,3.1838019,0.0,0.55746686,94.98235740209972,3.5564468,341.08478,-9.2811842,94.98235740209972
2232,2232,165.3957,14.411586,6.446928,0.0,0,3.1483059,0.0,0.56115997,94.8396523934944,3.5168419,340.85028,-9.2801847,94.8396523934944
2234,2234,165.3961,14.454937,6.4853783,0.0,0,3.1139472,0.0,0.56555474,94.63725631840634,3.4791944,340.6239,-9.280241,94.63725631840634
2236,2236,165.3965,14.519673,6.5158715,0.0,0,3.0801756,0.0,0.57016802,94.6725549739653,3.4422085,340.42188,-9.2808857,94.6725549739653
2238,2238,165.3969,14.609849,6.556736,0.0,0,3.0464077,0.0,0.57375509,94.73655802346681,3.4064612,340.21985,-9.2804279,94.73655802346681
2240,2240,165.3973,14.690093,6.591783,0.0,0,3.0126395,0.0,0.57837778,94.80499391590249,3.3696764,340.01779,-9.2801561,94.80499391590249
2242,2242,165.3977,14.720103,6.6250072,0.0,0,2.9788716,0.0,0.58287632,94.56934943133079,3.3318977,339.81577,-9.2794456,94.56934943133079
2244,2244,165.3981,14.773238,6.6709623,0.0,0,2.9451036,0.0,0.58710933,94.31467056345132,3.2947209,339.61374,-9.2794333,94.31467056345132
2246,2246,165.3985,14.845007,6.7001452,0.0,0,2.9113355,0.0,0.59169704,94.392464001283,3.2591476,339.41171,-9.2806911,94.392464001283
2248,2248,165.3989,14.949669,6.7338729,0.0,0,2.8775675,0.0,0.59559554,94.6151854344546,3.2259247,339.20966,-9.2808561,94.6151854344546
2250,2250,165.3993,15.025197,6.7771578,0.0,0,2.8437996,0.0,0.60000217,94.52201293318635,3.1900043,339.00763,-9.2807722,94.52201293318635
2252,2252,165.3997,15.060502,6.8039923,0.0,0,2.8100314,0.0,0.60446692,94.38913620038474,3.1527247,338.8056,-9.2800493,94.38913620038474
2254,2254,165.4001,15.116457,6.8386068,0.0,0,2.7762637,0.0,0.6080538,94.28018447044808,3.1199746,338.60358,-9.2800016,94.28018447044808
2256,2256,165.4005,15.199747,6.8808932,0.0,0,2.7424955,0.0,0.61283457,94.2349803482986,3.0877483,338.40152,-9.2790174,94.2349803482986
2258,2258,165.4009,15.289216,6.9069982,0.0,0,2.7090657,0.0,0.61729127,94.43898065182604,3.0512562,338.19949,-9.2786856,94.43898065182604
2260,2260,165.4013,15.35642,6.9463186,0.0,0,2.6768651,0.0,0.620951,94.32349217176773,3.0177326,337.99747,-9.2795944,94.32349217176773
2262,2262,165.4017,15.404053,6.9840064,0.0,0,2.6447449,0.0,0.62612629,94.10586112238725,2.9849229,337.79544,-9.2807827,94.10586112238725
2264,2264,165.4021,15.475149,7.0094833,0.0,0,2.6126249,0.0,0.62996513,94.19367232111743,2.9497838,337.59341,-9.2809439,94.19367232111743
2266,2266,165.4025,15.567039,7.0465245,0.0,0,2.5805047,0.0,0.63339782,94.2461247223214,2.9156861,337.39136,-9.2807512,94.2461247223214
2268,2268,165.4029,15.662562,7.0809121,0.0,0,2.5483847,0.0,0.63864547,94.35094956900309,2.8824201,337.18933,-9.2798996,94.35094956900309
2270,2270,165.4033,15.726118,7.1113701,0.0,0,2.5162647,0.0,0.64239758,94.31268019403177,2.8484223,336.9873,-9.2793655,94.31268019403177
2272,2272,165.4037,15.784067,7.1494503,0.0,0,2.4841447,0.0,0.64652103,94.13169549836454,2.8149145,336.78528,-9.2795868,94.13169549836454
2274,2274,165.4041,15.866069,7.1816831,0.0,0,2.4520247,0.0,0.65184474,94.17099714846766,2.7776527,336.58322,-9.2797279,94.17099714846766
2276,2276,165.4045,15.96032,7.2155991,0.0,0,2.4199049,0.0,0.65529025,94.25432998175414,2.7485073,336.3812,-9.2803183,94.25432998175414
2278,2278,165.4049,16.06078,7.250412,0.0,0,2.3877847,0.0,0.65949583,94.3557990742666,2.7136946,336.17917,-9.2802782,94.3557990742666
2280,2280,165.4053,16.140276,7.2785392,0.0,0,2.3556647,0.0,0.6645112,94.42347200306618,2.6805918,335.97714,-9.2807951,94.42347200306618
2282,2282,165.4057,16.187246,7.3171229,0.0,0,2.3235447,0.0,0.66812104,94.14877732478678,2.6491666,335.77509,-9.280694,94.14877732478678
2284,2284,165.4061,16.275148,7.3479977,0.0,0,2.2924569,0.0,0.67267919,94.21790543998449,2.6169672,335.51941,-9.28057,94.21790543998449
2286,2286,165.4065,16.36824,7.3762765,0.0,0,2.2619016,0.0,0.67698896,94.34951117785087,2.5829976,335.10281,-9.2803192,94.34951117785087
2288,2288,165.4069,16.470812,7.4182968,0.0,0,2.2313497,0.0,0.6810233,94.33166015135757,2.5506685,334.68622,-9.2793226,94.33166015135757
2290,2290,165.4073,16.545916,7.4468036,0.0,0,2.2007978,0.0,0.68591589,94.34665210545849,2.5162528,334.26962,-9.2791271,94.34665210545849
2292,2292,165.4077,16.609678,7.475955,0.0,0,2.1702456,0.0,0.68981194,94.28402411939942,2.483248,333.85303,-9.2791996,94.28402411939942
2294,2294,165.4081,16.702509,7.5166459,0.0,0,2.1396937,0.0,0.69407839,94.21266528087892,2.4530053,333.43646,-9.2791014,94.21266528087892
2296,2296,165.4085,16.791569,7.5396347,0.0,0,2.1091418,0.0,0.69869411,94.37516131241527,2.4206202,333.01987,-9.2799234,94.37516131241527
2298,2298,165.4089,16.911333,7.5715284,0.0,0,2.0785899,0.0,0.70211726,94.57337233177577,2.3880038,332.60327,-9.2794228,94.57337233177577
2300,2300,165.4093,16.984333,7.6124797,0.0,0,2.048038,0.0,0.70718127,94.36912816081274,2.3527038,332.18668,-9.2791243,94.36912816081274
2302,2302,165.4097,17.064978,7.636869,0.0,0,2.0174859,0.0,0.71183449,94.4506668448426,2.3203888,331.77008,-9.2786207,94.4506668448426
2304,2304,165.4101,17.154661,7.6724119,0.0,0,1.9869336,0.0,0.71538788,94.41001259881484,2.2884614,331.35352,-9.2791939,94.41001259881484
2306,2306,165.4105,17.275444,7.7099977,0.0,0,1.9563816,0.0,0.72086841,94.50277826343876,2.2561915,330.93692,-9.2794619,94.50277826343876
2308,2308,165.4109,17.375885,7.7318563,0.0,0,1.9261349,0.0,0.72480589,94.71762979039995,2.2243168,330.52032,-9.2782001,94.71762979039995
2310,2310,165.4113,17.460325,7.7660575,0.0,0,1.896998,0.0,0.72819567,94.65180269702697,2.1920414,330.10373,-9.2786655,94.65180269702697
2312,2312,165.4117,17.547049,7.7989192,0.0,0,1.867934,0.0,0.73366916,94.61385515963745,2.1619256,329.68713,-9.2791319,94.61385515963745
2314,2314,165.4121,17.625904,7.8262897,0.0,0,1.83887,0.0,0.7373808,94.61392550451225,2.1294873,329.27057,-9.2788429,94.61392550451225
2316,2316,165.4125,17.744289,7.8624372,0.0,0,1.809806,0.0,0.74150944,94.68413745749774,2.0975449,328.85397,-9.2785339,94.68413745749774
2318,2318,165.4129,17.857702,7.8933187,0.0,0,1.7807419,0.0,0.74725044,94.80325992871495,2.0686724,328.43738,-9.2792521,94.80325992871495
2320,2320,165.4133,17.951406,7.9253654,0.0,0,1.751678,0.0,0.75092953,94.79362995773765,2.0362165,328.02078,-9.2779188,94.79362995773765
2322,2322,165.4137,18.018539,7.9588418,0.0,0,1.722614,0.0,0.75530845,94.6163873376093,2.0064957,327.60419,-9.2791548,94.6163873376093
2324,2324,165.4141,18.113796,7.9832983,0.0,0,1.69355,0.0,0.76020855,94.72603013776653,1.9760492,327.18762,-9.2795916,94.72603013776653
2326,2326,165.4145,18.239067,8.0181532,0.0,0,1.6644859,0.0,0.76373029,94.82062179298087,1.945863,326.77103,-9.2797785,94.82062179298087
2328,2328,165.4149,18.371584,8.0489359,0.0,0,1.635422,0.0,0.76848948,95.01087561312382,1.9168034,326.35443,-9.2785006,95.01087561312382
2330,2330,165.4153,18.455282,8.0749779,0.0,0,1.6063581,0.0,0.77329701,95.01989997764642,1.8862258,325.93784,-9.2777433,95.01989997764642
2332,2332,165.4157,18.540852,8.1150618,0.0,0,1.577294,0.0,0.77739024,94.80502309844552,1.8541812,325.52124,-9.2791929,94.80502309844552
2334,2334,165.4161,18.645041,8.1420145,0.0,0,1.5491621,0.0,0.7824561,94.89452646315132,1.8244863,325.02896,-9.2794828,94.89452646315132
2336,2336,165.4165,18.790535,8.1669102,0.0,0,1.521511,0.0,0.7862972,95.22237889402896,1.7922995,324.30969,-9.2783012,95.22237889402896
2338,2338,165.4169,18.92234,8.2057695,0.0,0,1.493863,0.0,0.79043609,95.2416446935595,1.7584344,323.59045,-9.2778301,95.2416446935595
2340,2340,165.4173,19.01157,8.2288799,0.0,0,1.466215,0.0,0.79560196,95.30313826833952,1.7306777,322.87122,-9.2775478,95.30313826833952
2342,2342,165.4177,19.103497,8.2601957,0.0,0,1.438567,0.0,0.79941744,95.23612497099846,1.7004297,322.15195,-9.278573,95.23612497099846
2344,2344,165.4181,19.222555,8.2993612,0.0,0,1.4109191,0.0,0.80462515,95.1653405085299,1.6673073,321.43271,-9.2791996,95.1653405085299
2346,2346,165.4185,19.369392,8.3204908,0.0,0,1.3832711,0.0,0.80929607,95.53112306573385,1.6418191,320.71344,-9.2782164,95.53112306573385
2348,2348,165.4189,19.500069,8.3534775,0.0,0,1.355623,0.0,0.81294149,95.60794870484526,1.6079036,319.9942,-9.2774649,95.60794870484526
2350,2350,165.4193,19.578259,8.3893509,0.0,0,1.3279752,0.0,0.81861019,95.37141839434987,1.5770131,319.27496,-9.2765675,95.37141839434987
2352,2352,165.4197,19.68635,8.4083967,0.0,0,1.3003271,0.0,0.82253569,95.56700906044733,1.5478009,318.55569,-9.2778044,95.56700906044733
2354,2354,165.4201,19.813206,8.4405203,0.0,0,1.2726791,0.0,0.82596642,95.62099452759783,1.5178077,317.83646,-9.2782192,95.62099452759783
2356,2356,165.4205,19.96196,8.4727821,0.0,0,1.2450311,0.0,0.83189732,95.77036524900402,1.4877943,317.11719,-9.2779493,95.77036524900402
2358,2358,165.4209,20.092169,8.4985762,0.0,0,1.2176605,0.0,0.83598822,95.93750591025585,1.4569328,316.39795,-9.2782421,95.93750591025585
2360,2360,165.4213,20.168373,8.5337391,0.0,0,1.1912985,0.0,0.84018362,95.6752105856824,1.4329267,315.67871,-9.277585,95.6752105856824
2362,2362,165.4217,20.277111,8.5604305,0.0,0,1.1650023,0.0,0.84590977,95.71314171973778,1.3995641,314.95944,-9.2764578,95.71314171973778
2364,2364,165.4221,20.408875,8.5864134,0.0,0,1.1387062,0.0,0.84916699,95.86683160644947,1.3713864,314.2402,-9.2763004,95.86683160644947
2366,2366,165.4225,20.554562,8.6161432,0.0,0,1.1124103,0.0,0.85327786,96.01151128988111,1.3440082,313.52097,-9.2765074,96.01151128988111
2368,2368,165.4229,20.685276,8.6393185,0.0,0,1.0861143,0.0,0.85864025,96.19870283476088,1.3111376,312.8017,-9.2770643,96.19870283476088
2370,2370,165.4233,20.790396,8.6718626,0.0,0,1.0598181,0.0,0.86209726,96.08997754002954,1.2853876,312.08246,-9.2768154,96.08997754002954
2372,2372,165.4237,20.902067,8.7025156,0.0,0,1.0335222,0.0,0.86734462,96.04017083963599,1.2579583,311.36319,-9.2769365,96.04017083963599
2374,2374,165.4241,21.044373,8.7247906,0.0,0,1.0072262,0.0,0.87196076,96.27995685318497,1.2292207,310.64395,-9.2782612,96.27995685318497
2376,2376,165.4245,21.195522,8.7594995,0.0,0,0.98093021,0.0,0.87551641,96.32158893387451,1.1999631,309.92471,-9.2769995,96.32158893387451
2378,2378,165.4249,21.332617,8.7819014,0.0,0,0.95463419,0.0,0.88036907,96.5224169040504,1.1733481,309.20544,-9.2757387,96.5224169040504
2380,2380,165.4253,21.44066,8.8060722,0.0,0,0.92833829,0.0,0.88442338,96.55341595657494,1.143857,308.48621,-9.2764158,96.55341595657494
2382,2382,165.4257,21.556599,8.8411179,0.0,0,0.90204227,0.0,0.88852382,96.40803843105567,1.1154759,307.76694,-9.2768002,96.40803843105567
2384,2384,165.4261,21.696682,8.8619671,0.0,0,0.87659407,0.0,0.89371824,96.63483659207009,1.0866153,307.02588,-9.2776175,96.63483659207009
2386,2386,165.4265,21.84329,8.8872356,0.0,0,0.85158336,0.0,0.89720535,96.80009942521374,1.0632375,306.21939,-9.277688,96.80009942521374
2388,2388,165.4269,21.971323,8.9229479,0.0,0,0.82657528,0.0,0.90221786,96.67411489682569,1.0343957,305.41293,-9.27707,96.67411489682569
2390,2390,165.4273,22.085575,8.9407015,0.0,0,0.80156738,0.0,0.90699631,96.83032154101967,1.0064918,304.60645,-9.2764711,96.83032154101967
2392,2392,165.4277,22.212997,8.9689217,0.0,0,0.77655935,0.0,0.91019446,96.8349971960909,0.97744524,303.79999,-9.276762,96.8349971960909
2394,2394,165.4281,22.35442,8.9993086,0.0,0,0.75155133,0.0,0.91535079,96.8511699534799,0.95346636,302.9935,-9.2762747,96.8511699534799
2396,2396,165.4285,22.514118,9.014143,0.0,0,0.72654337,0.0,0.91922426,97.24788318953095,0.92721885,302.18704,-9.2762747,97.24788318953095
2398,2398,165.4289,22.651861,9.0452299,0.0,0,0.70153534,0.0,0.92253268,97.22046229937312,0.89885873,301.38055,-9.2766724,97.22046229937312
2400,2400,165.4293,22.777182,9.0759106,0.0,0,0.67652738,0.0,0.92872494,97.14064838728677,0.87541097,300.5741,-9.2769365,97.14064838728677
2402,2402,165.4297,22.908232,9.0966425,0.0,0,0.65151936,0.0,0.93258172,97.27974843576132,0.84909153,299.76761,-9.276288,97.27974843576132
2404,2404,165.4301,23.054361,9.1268787,0.0,0,0.62651134,0.0,0.93627638,97.28409873617996,0.82710302,298.96112,-9.2756405,97.28409873617996
2406,2406,165.4305,23.206108,9.1479073,0.0,0,0.60150337,0.0,0.94184405,97.49305781723551,0.79866338,298.15466,-9.2752457,97.49305781723551
2408,2408,165.4309,23.340189,9.1691484,0.0,0,0.57674313,0.0,0.94450456,97.6180901175435,0.7733475,297.34818,-9.2754049,97.6180901175435
2410,2410,165.4313,23.457289,9.1963444,0.0,0,0.5528841,0.0,0.94854587,97.5438855853164,0.7488789,296.54172,-9.2760458,97.5438855853164
2412,2412,165.4317,23.590269,9.2175713,0.0,0,0.52908403,0.0,0.95390999,97.6541750510039,0.72388071,295.73523,-9.2749662,97.6541750510039
2414,2414,165.4321,23.749422,9.2456474,0.0,0,0.50528395,0.0,0.95693195,97.72350919851499,0.70075846,294.92877,-9.2747393,97.72350919851499
2416,2416,165.4325,23.925352,9.2707348,0.0,0,0.48148397,0.0,0.96181226,97.91676341408268,0.67316246,294.12228,-9.2747622,97.91676341408268
2418,2418,165.4329,24.075239,9.2896042,0.0,0,0.45768398,0.0,0.96652138,98.12854972919992,0.64705789,293.3158,-9.2748747,98.12854972919992
2420,2420,165.4333,24.196636,9.3209858,0.0,0,0.43388397,0.0,0.96986002,97.9520063401133,0.62387884,292.50934,-9.2755423,97.9520063401133
2422,2422,165.4337,24.34091,9.341258,0.0,0,0.41008398,0.0,0.97462767,98.0997746873654,0.60042071,291.70285,-9.2771034,98.0997746873654
2424,2424,165.4341,24.50054,9.361331,0.0,0,0.38628396,0.0,0.97851205,98.30829429388568,0.57436228,290.89639,-9.2751007,98.30829429388568
2426,2426,165.4345,24.67432,9.3946247,0.0,0,0.36248395,0.0,0.98253649,98.27924111701024,0.55022371,290.0899,-9.2739639,98.27924111701024
2427,2427,165.4347,24.74828,9.3969994,0.0,0,0.35058397,0.0,0.98461026,98.52186526189978,0.53980845,289.68668,-9.2732239,98.52186526189978