File: examples/hot axisymmetric compression example/data/04 corrected data/testID_0144.csv
level_0,index,Time(sec),Force(kN),Jaw(mm),PowAngle(deg),Power(W),Pram,PTemp,Strain,Stress(MPa),Stroke(mm),TC1(C),wedge(mm),uncorrected stress
2272,2272,195.3437,0.47431728,0.022016106,0.0,0,9.0629702,0.0,0.0014829352,5.773179509634895,10.086761,451.12708,-9.2364321,5.773179509634895
2274,2274,195.3441,3.7112069,0.083357193,0.0,0,9.0044422,0.0,0.0047389716,44.974327082825745,10.022059,451.25644,-9.2366714,44.974327082825745
2276,2276,195.3445,5.4027309,0.13672768,0.0,0,8.9459143,0.0,0.0089517171,65.22375094610558,9.9609251,451.38577,-9.2338886,65.22375094610558
2278,2278,195.3449,5.7217126,0.2288678,0.0,0,8.8873854,0.0,0.014353752,68.61868311845893,9.873558,451.51514,-9.2315588,68.61868311845893
2280,2280,195.3453,5.4645395,0.40028676,0.0,0,8.8288574,0.0,0.02583996,64.72422534438165,9.7725,451.64447,-9.230896,64.72422534438165
2282,2282,195.3457,5.702342,0.46729094,0.0,0,8.7703295,0.0,0.031437367,67.21029563795157,9.6609125,451.77383,-9.2314482,67.21029563795157
2284,2284,195.3461,5.7803726,0.58603245,0.0,0,8.7136869,0.0,0.038737755,67.53609450004532,9.5551195,451.9032,-9.2326374,67.53609450004532
2286,2286,195.3465,6.4034781,0.65696263,0.0,0,8.6580172,0.0,0.044600517,74.42319673342168,9.4613857,452.03253,-9.231595,74.42319673342168
2288,2288,195.3469,5.8336544,0.66768527,0.0,0,8.6023531,0.0,0.045333352,67.74639295125368,9.3811407,452.1619,-9.2312508,67.74639295125368
2290,2290,195.3473,5.8467789,0.77441156,0.0,0,8.546689,0.0,0.052130587,67.35869869502764,9.3131399,452.29123,-9.2314453,67.35869869502764
2292,2292,195.3477,6.4199986,0.81641179,0.0,0,8.491025,0.0,0.055891309,73.72914540630899,9.2453518,452.42059,-9.2313671,73.72914540630899
2294,2294,195.3481,6.4729533,0.89041042,0.0,0,8.4353609,0.0,0.060484849,73.92261155146225,9.1729994,452.54996,-9.229908,73.92261155146225
2296,2296,195.3485,6.3124781,0.99950659,0.0,0,8.3796968,0.0,0.068170823,71.49364930482656,9.0945797,452.67929,-9.230258,71.49364930482656
2298,2298,195.3489,6.1055241,1.0707333,0.0,0,8.3240328,0.0,0.073689803,68.77313158228992,9.0138874,452.80865,-9.2322187,68.77313158228992
2300,2300,195.3493,6.3787684,1.1546376,0.0,0,8.2683687,0.0,0.079574399,71.38742564302868,8.9289255,452.93799,-9.2323503,71.38742564302868
2302,2302,195.3497,6.3152809,1.1997073,0.0,0,8.2127056,0.0,0.0829667,70.43036182054348,8.8579683,453.06735,-9.2310715,70.43036182054348
2304,2304,195.3501,6.3970532,1.2539908,0.0,0,8.1570406,0.0,0.087078415,71.04149383763637,8.7932911,453.19672,-9.2312727,71.04149383763637
2306,2306,195.3505,6.1786366,1.3193798,0.0,0,8.1013775,0.0,0.091575027,68.26587113544736,8.7336855,453.29642,-9.2309942,68.26587113544736
2308,2308,195.3509,6.6274734,1.3615779,0.0,0,8.0462675,0.0,0.094665378,72.98261126980067,8.6796961,453.38623,-9.2313719,72.98261126980067
2310,2310,195.3513,6.6766887,1.4322349,0.0,0,7.993176,0.0,0.10004213,73.11577801829797,8.6202822,453.47607,-9.2300959,73.11577801829797
2312,2312,195.3517,6.4681993,1.5170757,0.0,0,7.9402156,0.0,0.10578534,70.3570309380409,8.556221,453.56589,-9.2307968,70.3570309380409
2314,2314,195.3521,6.4307094,1.5774111,0.0,0,7.8872552,0.0,0.11066414,69.61292809944796,8.4947081,453.65573,-9.2322607,69.61292809944796
2316,2316,195.3525,6.4486856,1.633285,0.0,0,7.8342953,0.0,0.11518759,69.4951756829663,8.4272861,453.74554,-9.2328272,69.4951756829663
2318,2318,195.3529,6.6185331,1.6726786,0.0,0,7.7813349,0.0,0.11762575,71.0995234799978,8.3708611,453.83539,-9.2311726,71.0995234799978
2320,2320,195.3533,6.5111399,1.7174016,0.0,0,7.728375,0.0,0.12126799,69.69337987181548,8.3186026,453.9252,-9.2308407,69.69337987181548
2322,2322,195.3537,6.4434614,1.7751464,0.0,0,7.675415,0.0,0.12564388,68.64634153350327,8.2639589,454.01505,-9.2319918,68.64634153350327
2324,2324,195.3541,6.6908455,1.8151495,0.0,0,7.6224551,0.0,0.12830587,71.04977947784657,8.2175932,454.10486,-9.232029,71.04977947784657
2326,2326,195.3545,6.7511001,1.8664739,0.0,0,7.5694952,0.0,0.13255984,71.38912079163742,8.1674442,454.1947,-9.2319641,71.38912079163742
2328,2328,195.3549,6.7330918,1.9255894,0.0,0,7.5165353,0.0,0.13690653,70.85346469344461,8.1141281,454.28452,-9.2312555,70.85346469344461
2330,2330,195.3553,6.6587214,1.9860134,0.0,0,7.4635754,0.0,0.14134586,69.72184050926938,8.0578012,454.37433,-9.2299347,69.72184050926938
2332,2332,195.3557,6.6388631,2.0332439,0.0,0,7.410615,0.0,0.14564803,69.24188908475452,8.003356,454.46417,-9.2316351,69.24188908475452
2334,2334,195.3561,6.7803392,2.071291,0.0,0,7.3593607,0.0,0.14817175,70.49363674014147,7.9498501,454.55399,-9.2321892,70.49363674014147
2336,2336,195.3565,6.7291317,2.130528,0.0,0,7.3089876,0.0,0.15266004,69.6153737388106,7.9039135,454.64383,-9.2315025,69.6153737388106
2338,2338,195.3569,6.7078938,2.1686652,0.0,0,7.2586198,0.0,0.15615425,69.17366770591619,7.8539023,454.73364,-9.2305088,69.17366770591619
2340,2340,195.3573,6.8250399,2.2097888,0.0,0,7.2082515,0.0,0.15875438,70.13813601052651,7.8095107,454.82349,-9.2302837,70.13813601052651
2342,2342,195.3577,6.9022574,2.2675545,0.0,0,7.1578832,0.0,0.1636598,70.58561790084694,7.7606416,454.9133,-9.2301884,70.58561790084694
2344,2344,195.3581,6.8620315,2.3166471,0.0,0,7.1075149,0.0,0.16749583,69.88183884378077,7.7095194,455.00314,-9.2308521,69.88183884378077
2346,2346,195.3585,6.8541994,2.3708789,0.0,0,7.0571475,0.0,0.17141365,69.4793919453784,7.6564307,455.09296,-9.2314062,69.4793919453784
2348,2348,195.3589,6.8923235,2.4155927,0.0,0,7.0067787,0.0,0.17554514,69.59828771129509,7.6074977,455.1828,-9.2316189,69.59828771129509
2350,2350,195.3593,6.9708371,2.4544835,0.0,0,6.9564114,0.0,0.1783198,70.15572725213435,7.559309,455.27261,-9.2329779,70.15572725213435
2352,2352,195.3597,6.9336853,2.5092409,0.0,0,6.9060431,0.0,0.18243751,69.4521411594128,7.5126801,455.36246,-9.2309027,69.4521411594128
2354,2354,195.3601,6.8983879,2.5502183,0.0,0,6.8556757,0.0,0.18641129,68.85309506567843,7.4690123,455.45227,-9.2315054,68.85309506567843
2356,2356,195.3605,7.0144963,2.5958102,0.0,0,6.8053074,0.0,0.18944089,69.73422645406329,7.4224877,455.50528,-9.2311831,69.73422645406329
2358,2358,195.3609,7.0780754,2.6450431,0.0,0,6.7554412,0.0,0.19354679,70.06361348559173,7.3740816,455.54599,-9.2316113,70.06361348559173
2360,2360,195.3613,7.0434732,2.6881082,0.0,0,6.7074018,0.0,0.19743943,69.45760453636476,7.3280277,455.58673,-9.231596,69.45760453636476
2362,2362,195.3617,7.0383501,2.7428002,0.0,0,6.6594815,0.0,0.20123206,69.07266167049828,7.2800975,455.62744,-9.2323122,69.07266167049828
2364,2364,195.3621,7.0590901,2.7806869,0.0,0,6.6115613,0.0,0.2047853,69.04382966076322,7.2334185,455.66815,-9.230937,69.04382966076322
2366,2366,195.3625,7.1672215,2.8202548,0.0,0,6.5636415,0.0,0.20815286,69.85502734113484,7.1887789,455.70889,-9.2327642,69.85502734113484
2368,2368,195.3629,7.1585217,2.8759828,0.0,0,6.5157218,0.0,0.21204157,69.42356216496768,7.1406369,455.7496,-9.2317944,69.42356216496768
2370,2370,195.3633,7.1502709,2.9134526,0.0,0,6.467802,0.0,0.2157952,69.11069877616383,7.0950317,455.79031,-9.2316847,69.11069877616383
2372,2372,195.3637,7.2045169,2.9612544,0.0,0,6.4198813,0.0,0.21953675,69.33567792589854,7.0510674,455.83105,-9.2328329,69.33567792589854
2374,2374,195.3641,7.2335453,3.0159566,0.0,0,6.3719611,0.0,0.22370946,69.27108256812927,7.0014191,455.87177,-9.2330027,69.27108256812927
2376,2376,195.3645,7.287334,3.055197,0.0,0,6.3240414,0.0,0.22770737,69.53758267486253,6.9549356,455.91248,-9.2324286,69.53758267486253
2378,2378,195.3649,7.2747293,3.1033213,0.0,0,6.2761216,0.0,0.23128484,69.11292107547033,6.9111862,455.95322,-9.2317753,69.11292107547033
2380,2380,195.3653,7.3042331,3.1518073,0.0,0,6.2282019,0.0,0.23524229,69.0852705744031,6.858089,455.99393,-9.2322626,69.0852705744031
2382,2382,195.3657,7.3304071,3.1921661,0.0,0,6.1802816,0.0,0.23919225,69.0755563772536,6.8139997,456.03464,-9.2323055,69.0755563772536
2384,2384,195.3661,7.3592019,3.2413204,0.0,0,6.1339045,0.0,0.24276598,69.03228891499226,6.7631474,456.07538,-9.2324286,69.03228891499226
2386,2386,195.3665,7.4099317,3.2910466,0.0,0,6.0883236,0.0,0.24727273,69.18765970891256,6.7189355,456.11609,-9.2313929,69.18765970891256
2388,2388,195.3669,7.465148,3.3345942,0.0,0,6.042748,0.0,0.25128761,69.42042844400935,6.6689467,456.15683,-9.2302485,69.42042844400935
2390,2390,195.3673,7.4751139,3.382412,0.0,0,5.9971714,0.0,0.25488314,69.20213259322105,6.6257005,456.19754,-9.2313528,69.20213259322105
2392,2392,195.3677,7.48211,3.4310522,0.0,0,5.9515953,0.0,0.25950295,68.95024942444046,6.5751595,456.23825,-9.2322168,68.95024942444046
2394,2394,195.3681,7.5219393,3.475647,0.0,0,5.9060197,0.0,0.2633141,69.02539858100293,6.5271311,456.27899,-9.2322969,69.02539858100293
2396,2396,195.3685,7.5838261,3.5246162,0.0,0,5.8604436,0.0,0.26714224,69.2701092998328,6.4816332,456.3197,-9.2309685,69.2701092998328
2398,2398,195.3689,7.6131635,3.5726132,0.0,0,5.814867,0.0,0.27192864,69.2200339198203,6.4333482,456.36041,-9.2310352,69.2200339198203
2400,2400,195.3693,7.614913,3.6202416,0.0,0,5.7692914,0.0,0.27570072,68.92023411840512,6.3857489,456.40115,-9.2314301,68.92023411840512
2402,2402,195.3697,7.6179199,3.6670551,0.0,0,5.7237153,0.0,0.27974233,68.63698659476427,6.3377528,456.44186,-9.232275,68.63698659476427
2404,2404,195.3701,7.6880765,3.7117298,0.0,0,5.6781397,0.0,0.28435498,68.97005444366931,6.2901583,456.48257,-9.2330236,68.97005444366931
2406,2406,195.3705,7.7529349,3.7629833,0.0,0,5.6325636,0.0,0.2880502,69.2058927163335,6.2424989,456.2384,-9.2316961,69.2058927163335
2408,2408,195.3709,7.7670698,3.8097064,0.0,0,5.5874414,0.0,0.29257843,69.01602971166649,6.1929212,455.89926,-9.2316961,69.01602971166649
2410,2410,195.3713,7.7552471,3.8556597,0.0,0,5.5439734,0.0,0.29705775,68.60058486515202,6.1468005,455.56015,-9.2326727,68.60058486515202
2412,2412,195.3717,7.7906947,3.9101818,0.0,0,5.5006132,0.0,0.30113256,68.54414563126554,6.0970345,455.22101,-9.2315865,68.54414563126554
2414,2414,195.3721,7.8551931,3.9538217,0.0,0,5.457253,0.0,0.30572805,68.81297904942693,6.0471864,454.8819,-9.2322235,68.81297904942693
2416,2416,195.3725,7.8964429,3.9995277,0.0,0,5.4138932,0.0,0.30980533,68.85988246470207,6.002429,454.54276,-9.232831,68.85988246470207
2418,2418,195.3729,7.8968482,4.0544605,0.0,0,5.370533,0.0,0.31416458,68.48541826887072,5.9552078,454.20361,-9.2330894,68.48541826887072
2420,2420,195.3733,7.9226418,4.095674,0.0,0,5.3271732,0.0,0.31879196,68.42455834511686,5.9058385,453.8645,-9.2331171,68.42455834511686
2422,2422,195.3737,7.9751477,4.1424861,0.0,0,5.283813,0.0,0.32269838,68.55264210753764,5.8567123,453.52536,-9.2329416,68.55264210753764
2424,2424,195.3741,8.0072737,4.1983609,0.0,0,5.2404532,0.0,0.3275798,68.43879324584347,5.8098583,453.18622,-9.2313843,68.43879324584347
2426,2426,195.3745,8.0639124,4.2389436,0.0,0,5.1970935,0.0,0.33210084,68.63758953113081,5.7581811,452.84711,-9.2316074,68.63758953113081
2428,2428,195.3749,8.0847778,4.2899756,0.0,0,5.1537333,0.0,0.33619174,68.45546085869957,5.7093906,452.50797,-9.2318001,68.45546085869957
2430,2430,195.3753,8.1088848,4.3434501,0.0,0,5.110373,0.0,0.34130499,68.2814590884656,5.662879,452.16882,-9.2330217,68.2814590884656
2432,2432,195.3757,8.1344404,4.3820214,0.0,0,5.0670133,0.0,0.34541526,68.2230204379854,5.6144233,451.82971,-9.2343225,68.2230204379854
2434,2434,195.3761,8.1666718,4.4316678,0.0,0,5.0250483,0.0,0.34940371,68.13970698755527,5.5648646,451.49057,-9.2327585,68.13970698755527
2436,2436,195.3765,8.2130499,4.4805865,0.0,0,4.9838037,0.0,0.35446906,68.17619231740349,5.5194378,451.15146,-9.2318211,68.17619231740349
2438,2438,195.3769,8.2382355,4.5227633,0.0,0,4.9425635,0.0,0.35864726,68.08211978294521,5.4705257,450.81232,-9.231267,68.08211978294521
2440,2440,195.3773,8.2331305,4.573782,0.0,0,4.9013238,0.0,0.36286864,67.67342691135023,5.4259696,450.47318,-9.2328854,67.67342691135023
2442,2442,195.3777,8.2750864,4.6188164,0.0,0,4.8600836,0.0,0.3680197,67.69308483266923,5.3776994,450.13406,-9.2331648,67.69308483266923
2444,2444,195.3781,8.3372793,4.6635752,0.0,0,4.8188438,0.0,0.37195024,67.87616165484795,5.3318539,449.79492,-9.2323065,67.87616165484795
2446,2446,195.3785,8.3718395,4.7120457,0.0,0,4.7776036,0.0,0.37639499,67.80332931912703,5.2867641,449.45578,-9.2327604,67.80332931912703
2448,2448,195.3789,8.401763,4.7562857,0.0,0,4.7363639,0.0,0.38143742,67.72120052100075,5.2391038,449.11667,-9.2316837,67.72120052100075
2450,2450,195.3793,8.4063959,4.8057065,0.0,0,4.6951237,0.0,0.38545883,67.3958203540756,5.1950045,448.77753,-9.2315407,67.3958203540756
2452,2452,195.3797,8.4434261,4.8514504,0.0,0,4.6538839,0.0,0.39008906,67.35544009493942,5.148149,448.43839,-9.2327547,67.35544009493942
2454,2454,195.3801,8.5007334,4.891571,0.0,0,4.6126437,0.0,0.39475721,67.51475314019393,5.1008162,448.09927,-9.2321396,67.51475314019393
2456,2456,195.3805,8.526825,4.9434867,0.0,0,4.5714035,0.0,0.3989622,67.33534122842042,5.0529017,447.61719,-9.2321348,67.33534122842042
2458,2458,195.3809,8.5337973,4.9872541,0.0,0,4.5305758,0.0,0.4037407,67.06413737975943,5.0127459,447.08746,-9.2315607,67.06413737975943
2460,2460,195.3813,8.5463476,5.0276856,0.0,0,4.4912457,0.0,0.40812922,66.86089137633053,4.965508,446.55771,-9.2307405,66.86089137633053
2462,2462,195.3817,8.5717678,5.0789843,0.0,0,4.4520135,0.0,0.41229767,66.67556114342901,4.92312,446.02798,-9.2319841,66.67556114342901
2464,2464,195.3821,8.6367159,5.116992,0.0,0,4.4127812,0.0,0.41706136,66.89390957330596,4.8782854,445.49826,-9.2324638,66.89390957330596
2466,2466,195.3825,8.6644659,5.1584802,0.0,0,4.3735495,0.0,0.42115057,66.79468143962949,4.8372855,444.96854,-9.2328281,66.79468143962949
2468,2468,195.3829,8.6911278,5.2087874,0.0,0,4.3343177,0.0,0.42552811,66.61805716991171,4.7893019,444.43881,-9.2315226,66.61805716991171
2470,2470,195.3833,8.7201872,5.2441635,0.0,0,4.2950859,0.0,0.430217,66.57113117929751,4.7468438,443.90906,-9.2309151,66.57113117929751
2472,2472,195.3837,8.7220573,5.2858982,0.0,0,4.2558532,0.0,0.43399239,66.26716541827436,4.7042823,443.37933,-9.2324095,66.26716541827436
2474,2474,195.3841,8.7742481,5.3362646,0.0,0,4.2166214,0.0,0.43885696,66.27728157674713,4.6620159,442.84961,-9.2341375,66.27728157674713
2476,2476,195.3845,8.8157473,5.3713689,0.0,0,4.1773891,0.0,0.44327173,66.3201229090877,4.6181374,442.31989,-9.233408,66.3201229090877
2478,2478,195.3849,8.8295097,5.4144645,0.0,0,4.1381574,0.0,0.44706413,66.0908654914651,4.5782251,441.79016,-9.2332153,66.0908654914651
2480,2480,195.3853,8.8390856,5.4615617,0.0,0,4.0989256,0.0,0.45223156,65.79840933894705,4.5369916,441.26041,-9.2322073,65.79840933894705
2482,2482,195.3857,8.8964891,5.4958858,0.0,0,4.0596933,0.0,0.45629501,65.95858930382971,4.49402,440.73068,-9.2312021,65.95858930382971
2484,2484,195.3861,8.9387131,5.5401068,0.0,0,4.0217257,0.0,0.46008253,65.92580719082879,4.4538436,440.20096,-9.2314291,65.92580719082879
2486,2486,195.3865,8.9885416,5.5815063,0.0,0,3.9844091,0.0,0.46522337,65.96769679361373,4.4107399,439.67123,-9.2327757,65.96769679361373
2488,2488,195.3869,9.0000896,5.6174016,0.0,0,3.9470971,0.0,0.46895793,65.7697335024063,4.3721895,439.14151,-9.232748,65.7697335024063
2490,2490,195.3873,9.0121326,5.6612678,0.0,0,3.9097853,0.0,0.47311103,65.51174192082544,4.3331461,438.61176,-9.2337122,65.51174192082544
2492,2492,195.3877,9.0496788,5.7021642,0.0,0,3.8724732,0.0,0.47829673,65.46071772301396,4.2899041,438.08203,-9.2324991,65.46071772301396
2494,2494,195.3881,9.1196375,5.7411814,0.0,0,3.8351612,0.0,0.48204675,65.65526429327603,4.2516947,437.55231,-9.2315331,65.65526429327603
2496,2496,195.3885,9.1483097,5.7818766,0.0,0,3.7978492,0.0,0.48619664,65.53572928824121,4.2115951,437.02258,-9.2308664,65.53572928824121
2498,2498,195.3889,9.1528072,5.8175964,0.0,0,3.7605371,0.0,0.4909611,65.28167025099903,4.1727104,436.49283,-9.2312384,65.28167025099903
2500,2500,195.3893,9.1805735,5.8592873,0.0,0,3.7232251,0.0,0.49448073,65.14452499633666,4.1327724,435.9631,-9.2322121,65.14452499633666
2502,2502,195.3897,9.2348471,5.89779,0.0,0,3.6859133,0.0,0.49902973,65.21822404417284,4.0946479,435.43338,-9.2333012,65.21822404417284
2504,2504,195.3901,9.3069391,5.9324079,0.0,0,3.6486013,0.0,0.50354117,65.4451340150576,4.0562243,434.90366,-9.2333355,65.4451340150576
2506,2506,195.3905,9.3205719,5.9786725,0.0,0,3.611289,0.0,0.50744671,65.163233732152,4.0178409,434.71817,-9.2321787,65.163233732152
2508,2508,195.3909,9.3435507,6.0132036,0.0,0,3.5743496,0.0,0.51207238,65.04119941030038,3.9785953,434.64737,-9.2308283,65.04119941030038
2510,2510,195.3913,9.3756104,6.0473423,0.0,0,3.5387647,0.0,0.51594841,64.98390663333278,3.9416525,434.5766,-9.230444,64.98390663333278
2512,2512,195.3917,9.4263487,6.0949755,0.0,0,3.5032687,0.0,0.52034682,64.94208941310283,3.9003375,434.50583,-9.2310867,64.94208941310283
2514,2514,195.3921,9.4723034,6.1267295,0.0,0,3.4677725,0.0,0.52504092,64.99506321266225,3.8620396,434.43506,-9.2320156,64.99506321266225
2516,2516,195.3925,9.5036755,6.1651497,0.0,0,3.4322767,0.0,0.52893829,64.89026303349233,3.8220716,434.36429,-9.2316628,64.89026303349233
2518,2518,195.3929,9.5287914,6.212554,0.0,0,3.3967807,0.0,0.53366876,64.66575038895687,3.7833416,434.29352,-9.2313757,64.66575038895687
2520,2520,195.3933,9.5553341,6.2401476,0.0,0,3.3612847,0.0,0.53807062,64.61470054586802,3.7457192,434.22275,-9.2314653,64.61470054586802
2522,2522,195.3937,9.6160603,6.277051,0.0,0,3.3257885,0.0,0.5414539,64.71416958118085,3.7115991,434.15198,-9.2306509,64.71416958118085
2524,2524,195.3941,9.6706333,6.320734,0.0,0,3.2902927,0.0,0.54642433,64.7109607886908,3.6735709,434.08118,-9.2308683,64.7109607886908
2526,2526,195.3945,9.7138233,6.3504176,0.0,0,3.2547965,0.0,0.55078298,64.74706721327921,3.6346674,434.01041,-9.231513,64.74706721327921
2528,2528,195.3949,9.7153301,6.3921018,0.0,0,3.2193005,0.0,0.55448258,64.4018737271303,3.6005213,433.93964,-9.2321653,64.4018737271303
2530,2530,195.3953,9.7562361,6.4316635,0.0,0,3.1838045,0.0,0.55969739,64.33442352283123,3.560905,433.86887,-9.2325258,64.33442352283123
2532,2532,195.3957,9.8055258,6.4619627,0.0,0,3.1483085,0.0,0.56352437,64.3987768216691,3.5246668,433.7981,-9.2321291,64.3987768216691
2534,2534,195.3961,9.8775911,6.501946,0.0,0,3.1139498,0.0,0.56718177,64.5255193607492,3.4909506,433.72733,-9.2314405,64.5255193607492
2536,2536,195.3965,9.8971825,6.5392871,0.0,0,3.0801783,0.0,0.57254815,64.32916646493281,3.453666,433.65656,-9.2314186,64.32916646493281
2538,2538,195.3969,9.9234543,6.5716839,0.0,0,3.0464103,0.0,0.57625568,64.21775908850906,3.4175262,433.58578,-9.2314558,64.21775908850906
2540,2540,195.3973,9.9839258,6.6122146,0.0,0,3.0126421,0.0,0.58031178,64.2538852080068,3.3826053,433.51501,-9.2316351,64.2538852080068
2542,2542,195.3977,10.033422,6.6461177,0.0,0,2.9788742,0.0,0.58546567,64.27380054609655,3.3443124,433.44421,-9.2314653,64.27380054609655
2544,2544,195.3981,10.102072,6.6804986,0.0,0,2.9451063,0.0,0.58887571,64.40862755823326,3.3119335,433.37344,-9.2315693,64.40862755823326
2546,2546,195.3985,10.132404,6.7195201,0.0,0,2.9113381,0.0,0.59342903,64.254835190347,3.2728202,433.30267,-9.2314625,64.254835190347
2548,2548,195.3989,10.159205,6.751895,0.0,0,2.8775702,0.0,0.59828353,64.13595300894141,3.2354643,433.2319,-9.232255,64.13595300894141
2550,2550,195.3993,10.213429,6.7924385,0.0,0,2.8438022,0.0,0.6021499,64.11458128919546,3.2029395,433.16113,-9.2303762,64.11458128919546
2552,2552,195.3997,10.267885,6.8297172,0.0,0,2.810034,0.0,0.60707659,64.12019688866616,3.168242,433.09036,-9.2307329,64.12019688866616
2554,2554,195.4001,10.327139,6.8600659,0.0,0,2.7762663,0.0,0.61153847,64.21488638312208,3.1304224,433.01959,-9.2298841,64.21488638312208
2556,2556,195.4005,10.376661,6.9025898,0.0,0,2.7424982,0.0,0.61528951,64.135128124069,3.0959485,432.87222,-9.2312851,64.135128124069
2558,2558,195.4009,10.400347,6.9334216,0.0,0,2.7090681,0.0,0.6201188,63.99975672306912,3.0581629,432.69931,-9.2309742,63.99975672306912
2560,2560,195.4013,10.455997,6.9663668,0.0,0,2.6768675,0.0,0.62417084,64.03948178599661,3.0230267,432.52643,-9.2312174,64.03948178599661
2562,2562,195.4017,10.517264,7.0099969,0.0,0,2.6447473,0.0,0.62868088,64.0114188706343,2.9888897,432.35352,-9.2305937,64.0114188706343
2564,2564,195.4021,10.587186,7.0375319,0.0,0,2.6126273,0.0,0.6334275,64.18074023269261,2.9531236,432.18063,-9.2310553,64.18074023269261
2566,2566,195.4025,10.63565,7.0712657,0.0,0,2.580507,0.0,0.6370703,64.15913304408282,2.9167855,432.00775,-9.2310467,64.15913304408282
2568,2568,195.4029,10.65788,7.116909,0.0,0,2.5483871,0.0,0.64221865,63.865536200510476,2.8805246,431.83484,-9.2306833,63.865536200510476
2570,2570,195.4033,10.701791,7.1424484,0.0,0,2.5162671,0.0,0.64690232,63.88833622527951,2.8493233,431.66196,-9.2296829,63.88833622527951
2572,2572,195.4037,10.775538,7.1771741,0.0,0,2.4841471,0.0,0.65023798,63.99953936014857,2.8139658,431.48904,-9.2305517,63.99953936014857
2574,2574,195.4041,10.845046,7.2178535,0.0,0,2.4520271,0.0,0.65553725,64.02436359594384,2.7796152,431.31616,-9.2297163,64.02436359594384
2576,2576,195.4045,10.876534,7.243876,0.0,0,2.4199073,0.0,0.65975434,63.96130052973225,2.7455828,431.14325,-9.2302198,63.96130052973225
2578,2578,195.4049,10.904782,7.2831173,0.0,0,2.3877871,0.0,0.66364288,63.75098630390323,2.7101684,430.97037,-9.2313547,63.75098630390323
2580,2580,195.4053,10.947817,7.320497,0.0,0,2.3556671,0.0,0.66925579,63.642542670065744,2.6759322,430.79745,-9.231164,63.642542670065744
2582,2582,195.4057,11.033027,7.348053,0.0,0,2.3235471,0.0,0.67303449,63.87038428772459,2.6430354,430.62457,-9.2300396,63.87038428772459
2584,2584,195.4061,11.09912,7.3865151,0.0,0,2.2924592,0.0,0.67709911,63.87734144088245,2.60847,430.45169,-9.2299747,63.87734144088245
2586,2586,195.4065,11.129926,7.4189811,0.0,0,2.261904,0.0,0.68250203,63.73662638024796,2.5766153,430.27878,-9.22999,63.73662638024796
2588,2588,195.4069,11.171445,7.4503922,0.0,0,2.2313521,0.0,0.68629509,63.665534009695605,2.5427804,430.1059,-9.2304964,63.665534009695605
2590,2590,195.4073,11.237762,7.4873929,0.0,0,2.2008002,0.0,0.6905452,63.67745632611529,2.5134101,429.93298,-9.2313709,63.67745632611529
2592,2592,195.4077,11.321638,7.5160379,0.0,0,2.170248,0.0,0.69583005,63.86722569169106,2.4779556,429.7601,-9.2318039,63.86722569169106
2594,2594,195.4081,11.394994,7.5516806,0.0,0,2.1396961,0.0,0.69931871,63.92345093748138,2.4443293,429.58719,-9.2305546,63.92345093748138
2596,2596,195.4085,11.424351,7.5850224,0.0,0,2.109144,0.0,0.70391941,63.752735121001564,2.4114404,429.41431,-9.2296429,63.752735121001564
2598,2598,195.4089,11.46968,7.6143937,0.0,0,2.0785921,0.0,0.70886201,63.70902779966299,2.377996,429.24139,-9.2293482,63.70902779966299
2600,2600,195.4093,11.525092,7.6520472,0.0,0,2.0480402,0.0,0.71259332,63.63462361276285,2.3448768,429.06851,-9.2297602,63.63462361276285
2602,2602,195.4097,11.610468,7.6821709,0.0,0,2.0174882,0.0,0.71752781,63.79795705068747,2.3110547,428.89563,-9.2313509,63.79795705068747
2604,2604,195.4101,11.673897,7.7107325,0.0,0,1.986936,0.0,0.72175384,63.85278185622533,2.2784064,428.72272,-9.230998,63.85278185622533
2606,2606,195.4105,11.7092,7.7536502,0.0,0,1.9563839,0.0,0.72612536,63.60315751201214,2.2463965,428.71188,-9.2297354,63.60315751201214
2608,2608,195.4109,11.757034,7.7790318,0.0,0,1.9261371,0.0,0.73108387,63.60006344345852,2.2127452,428.75507,-9.2299242,63.60006344345852
2610,2610,195.4113,11.829518,7.808372,0.0,0,1.8970003,0.0,0.73477864,63.6863388275897,2.1820538,428.79825,-9.2299757,63.6863388275897
2612,2612,195.4117,11.911733,7.8473253,0.0,0,1.8679363,0.0,0.73921829,63.72006170740501,2.1502213,428.84143,-9.2296934,63.72006170740501
2614,2614,195.4121,11.973514,7.8678031,0.0,0,1.8388723,0.0,0.74382108,63.83445834876912,2.1196523,428.88461,-9.2294369,63.83445834876912
2616,2616,195.4125,12.00759,7.9014745,0.0,0,1.8098083,0.0,0.74739552,63.659770554208094,2.0863247,428.92783,-9.2308683,63.659770554208094
2618,2618,195.4129,12.057719,7.9426098,0.0,0,1.7807442,0.0,0.75303781,63.488318594422665,2.0583749,428.97101,-9.2302351,63.488318594422665
2620,2620,195.4133,12.139209,7.9645576,0.0,0,1.7516803,0.0,0.75747573,63.68251679119329,2.0261192,429.01419,-9.2298803,63.68251679119329
2622,2622,195.4137,12.226155,7.9997988,0.0,0,1.7226163,0.0,0.76109278,63.75876648974395,1.9955124,429.05737,-9.2297001,63.75876648974395
2624,2624,195.4141,12.284498,8.0356188,0.0,0,1.6935523,0.0,0.76662803,63.675029499470384,1.9670149,429.10056,-9.2291164,63.675029499470384
2626,2626,195.4145,12.327125,8.0576725,0.0,0,1.6644882,0.0,0.77055913,63.65625176144712,1.9356679,429.14374,-9.2281303,63.65625176144712
2628,2628,195.4149,12.395352,8.091958,0.0,0,1.6354243,0.0,0.77416617,63.63378533262736,1.9029169,429.18692,-9.2285995,63.63378533262736
2630,2630,195.4153,12.477856,8.1223726,0.0,0,1.6063603,0.0,0.77976584,63.72261937225945,1.875688,429.2301,-9.2289848,63.72261937225945
2632,2632,195.4157,12.554649,8.147769,0.0,0,1.5772963,0.0,0.78328687,63.83355819731898,1.8445545,429.27328,-9.229269,63.83355819731898
2634,2634,195.4161,12.619371,8.182579,0.0,0,1.5491643,0.0,0.78761697,63.77513871434203,1.8135127,429.31647,-9.2301998,63.77513871434203
2636,2636,195.4165,12.673265,8.210866,0.0,0,1.5215131,0.0,0.7929886,63.73124931336819,1.7830939,429.35965,-9.2289753,63.73124931336819
2638,2638,195.4169,12.737383,8.2418404,0.0,0,1.4938651,0.0,0.79674643,63.705602793315286,1.7529595,429.40283,-9.2286386,63.705602793315286
2640,2640,195.4173,12.818652,8.2754898,0.0,0,1.4662172,0.0,0.801337,63.731476651627005,1.724702,429.44601,-9.2283831,63.731476651627005
2642,2642,195.4177,12.911024,8.3006859,0.0,0,1.4385692,0.0,0.80650759,63.903673374371834,1.6932961,429.4892,-9.2286015,63.903673374371834
2644,2644,195.4181,12.979398,8.3346739,0.0,0,1.4109212,0.0,0.81014645,63.85279038868668,1.6653514,429.53238,-9.2290201,63.85279038868668
2646,2646,195.4185,13.032725,8.3633451,0.0,0,1.3832732,0.0,0.81502157,63.78535462770975,1.6333922,429.57556,-9.2298126,63.78535462770975
2648,2648,195.4189,13.105412,8.3878613,0.0,0,1.3556252,0.0,0.8196193,63.857520903270775,1.6032307,429.61874,-9.2297812,63.857520903270775
2650,2650,195.4193,13.170098,8.423748,0.0,0,1.3279773,0.0,0.82331431,63.755523009411824,1.5727758,429.66193,-9.2297878,63.755523009411824
2652,2652,195.4197,13.271713,8.4479198,0.0,0,1.3003292,0.0,0.82815313,63.96424398472471,1.5447892,429.70511,-9.2289009,63.96424398472471
2654,2654,195.4201,13.34092,8.4738102,0.0,0,1.2726812,0.0,0.83214378,63.99286762957098,1.5165721,429.74829,-9.2283449,63.99286762957098
2656,2656,195.4205,13.400691,8.5129261,0.0,0,1.2450333,0.0,0.83675647,63.81678162273803,1.4855806,428.97168,-9.2292738,63.81678162273803
2658,2658,195.4209,13.469628,8.5341034,0.0,0,1.2176626,0.0,0.84180152,63.89321096949983,1.4588045,427.92181,-9.2301807,63.89321096949983
2660,2660,195.4213,13.564751,8.5626183,0.0,0,1.1913005,0.0,0.84551442,64.00288275203364,1.4289936,426.87195,-9.2297688,64.00288275203364
2662,2662,195.4217,13.670921,8.5990438,0.0,0,1.1650044,0.0,0.85033017,64.064082671342,1.4052495,425.82211,-9.2282486,64.064082671342
2664,2664,195.4221,13.746996,8.6184053,0.0,0,1.1387082,0.0,0.85501671,64.18552554185912,1.3751788,424.77225,-9.2277813,64.18552554185912
2666,2666,195.4225,13.807141,8.6467857,0.0,0,1.1124123,0.0,0.85826224,64.12026991465875,1.3461431,423.72241,-9.2293367,64.12026991465875
2668,2668,195.4229,13.883663,8.6829643,0.0,0,1.0861163,0.0,0.86374402,64.03199124562892,1.3183118,422.67255,-9.2289143,64.03199124562892
2670,2670,195.4233,13.973939,8.7011757,0.0,0,1.0598202,0.0,0.86809689,64.22356157195603,1.2883685,421.62268,-9.2279148,64.22356157195603
2672,2672,195.4237,14.082419,8.7333679,0.0,0,1.0335243,0.0,0.87159055,64.32167074358219,1.2587683,420.57285,-9.2283802,64.32167074358219
2674,2674,195.4241,14.165251,8.7648954,0.0,0,1.0072283,0.0,0.87756026,64.30548256067401,1.233173,419.52298,-9.2279425,64.30548256067401
2676,2676,195.4245,14.220405,8.7860928,0.0,0,0.98093224,0.0,0.88143802,64.28955863082001,1.2028452,418.47314,-9.227046,64.28955863082001
2678,2678,195.4249,14.293784,8.8192244,0.0,0,0.95463622,0.0,0.88534099,64.20289486580809,1.1769607,417.42328,-9.2268343,64.20289486580809
2680,2680,195.4253,14.403731,8.8448076,0.0,0,0.92834032,0.0,0.89101475,64.37115614352247,1.1476005,416.37341,-9.2284842,64.37115614352247
2682,2682,195.4257,14.533969,8.8679304,0.0,0,0.9020443,0.0,0.89420313,64.65625144399586,1.1186709,415.32358,-9.2288198,64.65625144399586
2684,2684,195.4261,14.599164,8.8982639,0.0,0,0.87659597,0.0,0.89842594,64.5549658614537,1.0900455,414.27371,-9.2283516,64.5549658614537
2686,2686,195.4265,14.65408,8.9237509,0.0,0,0.85158527,0.0,0.90407544,64.46774915249215,1.0630827,413.22388,-9.2276087,64.46774915249215
2688,2688,195.4269,14.747192,8.9528437,0.0,0,0.82657719,0.0,0.90767473,64.49822595270388,1.0346334,412.17401,-9.2267637,64.49822595270388
2690,2690,195.4273,14.870009,8.9835329,0.0,0,0.80156928,0.0,0.9125542,64.63207017748832,1.0071272,411.12415,-9.2271919,64.63207017748832
2692,2692,195.4277,14.971081,9.0060167,0.0,0,0.77656126,0.0,0.91795814,64.77388080686353,0.97847629,410.07431,-9.2270041,64.77388080686353
2694,2694,195.4281,15.051815,9.0373306,0.0,0,0.75155324,0.0,0.92125541,64.7066007372085,0.95255393,409.02444,-9.2280521,64.7066007372085
2696,2696,195.4285,15.117152,9.0602856,0.0,0,0.72654527,0.0,0.92584461,64.68076010762813,0.92472464,407.97461,-9.2281561,64.68076010762813
2698,2698,195.4289,15.22239,9.0799809,0.0,0,0.70153725,0.0,0.93015981,64.8660308419475,0.89932555,406.92474,-9.228322,64.8660308419475
2700,2700,195.4293,15.345043,9.1153498,0.0,0,0.67652929,0.0,0.93406957,64.90893483869975,0.87435132,405.87488,-9.2281733,64.90893483869975
2702,2702,195.4297,15.457418,9.1382179,0.0,0,0.65152127,0.0,0.93948638,65.07180768151295,0.84721988,404.82504,-9.2273855,65.07180768151295
2704,2704,195.4301,15.521222,9.1621218,0.0,0,0.62651324,0.0,0.9436183,65.01242657832185,0.82251179,403.77518,-9.2272167,65.01242657832185
2706,2706,195.4305,15.606873,9.1985369,0.0,0,0.60150528,0.0,0.94836891,64.86876817737905,0.79673207,403.03955,-9.2286892,64.86876817737905
2708,2708,195.4309,15.719954,9.2154732,0.0,0,0.57674497,0.0,0.95337808,65.10341151810167,0.77062786,402.40866,-9.2286196,65.10341151810167
2710,2710,195.4313,15.845315,9.2404537,0.0,0,0.55288589,0.0,0.95661294,65.27265018798222,0.7424981,401.77774,-9.2276411,65.27265018798222
2712,2712,195.4317,15.959925,9.2734165,0.0,0,0.52908581,0.0,0.96175796,65.27966124905568,0.71495742,401.14685,-9.2272615,65.27966124905568
2714,2714,195.4321,16.030581,9.2907429,0.0,0,0.5052858,0.0,0.96665883,65.32309481467756,0.69028682,400.51593,-9.2271976,65.32309481467756
2716,2716,195.4325,16.12883,9.3201313,0.0,0,0.48148578,0.0,0.97003841,65.30437131114626,0.66892719,399.88501,-9.2281199,65.30437131114626
2718,2718,195.4329,16.231501,9.3514414,0.0,0,0.4576858,0.0,0.97595298,65.27074468452679,0.64233685,399.25412,-9.2276316,65.27074468452679
2720,2720,195.4333,16.36426,9.3665247,0.0,0,0.43388578,0.0,0.97983265,65.58636547608852,0.61391395,398.6232,-9.2273836,65.58636547608852
2722,2722,195.4337,16.471321,9.3947611,0.0,0,0.4100858,0.0,0.98320723,65.60423603748684,0.58937383,397.99231,-9.2262831,65.60423603748684
2724,2724,195.4341,16.5525,9.42272,0.0,0,0.38628578,0.0,0.98931777,65.51837735407891,0.5636121,397.36139,-9.226819,65.51837735407891
2726,2726,195.4345,16.654343,9.4430428,0.0,0,0.36248577,0.0,0.9928996,65.6222295809622,0.53730839,396.7305,-9.2273331,65.6222295809622
2728,2728,195.4349,16.764303,9.4707623,0.0,0,0.33868581,0.0,0.99673581,65.64461722381002,0.51177067,396.09958,-9.2268047,65.64461722381002