File: examples/hot axisymmetric compression example/data/04 corrected data/testID_0145.csv
level_0,index,Time(sec),Force(kN),Jaw(mm),PowAngle(deg),Power(W),Pram,PTemp,Strain,Stress(MPa),Stroke(mm),TC1(C),wedge(mm),uncorrected stress
2271,2271,195.349,0.16597185,0.024383038,0.0,0,9.0922346,0.0,0.0016659051,2.019796070442895,10.122318,451.5834,-9.2368612,2.019796070442895
2273,2273,195.3494,2.3637195,0.059480421,0.0,0,9.0337067,0.0,0.0034653232,28.693577392102124,10.046723,451.71753,-9.2375975,28.693577392102124
2275,2275,195.3498,4.9518552,0.12452741,0.0,0,8.9751787,0.0,0.0082457056,59.83285697800594,9.9910955,451.85168,-9.2355833,59.83285697800594
2277,2277,195.3502,5.389008,0.18361937,0.0,0,8.9166508,0.0,0.011569147,64.83955106820983,9.9173794,451.98581,-9.2329273,64.83955106820983
2279,2279,195.3506,5.3455672,0.34173158,0.0,0,8.8581219,0.0,0.021779224,63.58584523353645,9.8246384,452.11996,-9.2319908,63.58584523353645
2281,2281,195.351,5.151897,0.43700182,0.0,0,8.7995939,0.0,0.029484421,60.85751849228569,9.7210979,452.25409,-9.2322378,60.85751849228569
2283,2283,195.3514,5.5246887,0.52939463,0.0,0,8.7416534,0.0,0.034810513,64.81952815129867,9.6148663,452.38824,-9.2342653,64.81952815129867
2285,2285,195.3518,5.8732724,0.63445354,0.0,0,8.6858492,0.0,0.042896282,68.375396484627,9.5224094,452.5224,-9.2326937,68.375396484627
2287,2287,195.3522,5.913835,0.63418633,0.0,0,8.6301851,0.0,0.043281242,68.84898529005811,9.4380417,452.65652,-9.230279,68.84898529005811
2289,2289,195.3526,5.2686806,0.730739,0.0,0,8.574522,0.0,0.048774678,60.897801181934426,9.3685808,452.84454,-9.2318087,60.897801181934426
2291,2291,195.353,6.0136509,0.79722118,0.0,0,8.518857,0.0,0.054516323,69.16243305648973,9.3018723,453.05054,-9.2328558,69.16243305648973
2293,2293,195.3534,6.0904889,0.83787644,0.0,0,8.4631929,0.0,0.056933012,69.8317858216561,9.2302113,453.2565,-9.2310877,69.8317858216561
2295,2295,195.3538,6.1510687,0.96223813,0.0,0,8.4075298,0.0,0.065199934,69.86406976342677,9.1520691,453.46246,-9.2312069,69.86406976342677
2297,2297,195.3542,5.7540426,1.0272511,0.0,0,8.3518648,0.0,0.070771918,65.03069292081743,9.0679893,453.66846,-9.2309885,65.03069292081743
2299,2299,195.3546,5.9792228,1.1094691,0.0,0,8.2962017,0.0,0.076091856,67.14986905077964,8.9883957,453.87442,-9.2327385,67.14986905077964
2301,2301,195.355,5.9779768,1.1738133,0.0,0,8.2405376,0.0,0.081049062,66.8027079849341,8.9115667,454.08041,-9.2317953,66.8027079849341
2303,2303,195.3554,6.1156526,1.2111586,0.0,0,8.1848736,0.0,0.084013216,68.14336683548916,8.8471346,454.28638,-9.2320585,68.14336683548916
2305,2305,195.3558,5.9302039,1.2871561,0.0,0,8.1292095,0.0,0.089008875,65.68657817580147,8.7845955,454.49237,-9.2312469,65.68657817580147
2307,2307,195.3562,6.0953321,1.3355892,0.0,0,8.0735455,0.0,0.092957616,67.25985914598802,8.7273283,454.69833,-9.2319832,67.25985914598802
2309,2309,195.3566,6.4014416,1.3938653,0.0,0,8.0196619,0.0,0.097146869,70.31442191739482,8.6701937,454.90433,-9.2321568,70.31442191739482
2311,2311,195.357,6.1884971,1.4807926,0.0,0,7.9666953,0.0,0.10314348,67.50921367881831,8.6042185,455.11029,-9.231493,67.50921367881831
2313,2313,195.3574,6.1196918,1.5484067,0.0,0,7.9137359,0.0,0.10866673,66.39999497470488,8.5371313,455.31625,-9.2319593,66.39999497470488
2315,2315,195.3578,6.1219468,1.6095254,0.0,0,7.8607755,0.0,0.11319141,66.1001234923758,8.4720278,455.52225,-9.23246,66.1001234923758
2317,2317,195.3582,6.2660651,1.6508906,0.0,0,7.8078156,0.0,0.11616388,67.43150185473066,8.4141483,455.72821,-9.2317896,67.43150185473066
2319,2319,195.3586,6.2657237,1.6918641,0.0,0,7.7548552,0.0,0.11952503,67.20524962206977,8.358036,455.9342,-9.2318525,67.20524962206977
2321,2321,195.359,6.095284,1.7554625,0.0,0,7.7018952,0.0,0.12389287,65.04102089331612,8.305459,456.14017,-9.2316427,65.04102089331612
2323,2323,195.3594,6.2767906,1.7966264,0.0,0,7.6489348,0.0,0.12719543,66.75377459961805,8.2581482,456.34616,-9.2313623,66.75377459961805
2325,2325,195.3598,6.4678369,1.8414757,0.0,0,7.5959754,0.0,0.13088736,68.53399482059584,8.2052946,456.55212,-9.2322464,68.53399482059584
2327,2327,195.3602,6.3949533,1.9110947,0.0,0,7.543015,0.0,0.13551089,67.37557592592711,8.1494656,456.75812,-9.2322512,67.37557592592711
2329,2329,195.3606,6.3580136,1.963541,0.0,0,7.4900556,0.0,0.13988698,66.69714709341204,8.0952482,456.96408,-9.231636,66.69714709341204
2331,2331,195.361,6.2555161,2.0175912,0.0,0,7.4370952,0.0,0.14432472,65.32861120130306,8.0367126,457.17004,-9.2312794,65.32861120130306
2333,2333,195.3614,6.4214025,2.0642259,0.0,0,7.3846664,0.0,0.14741339,66.80121631291445,7.9801989,457.37604,-9.2315388,66.80121631291445
2335,2335,195.3618,6.454627,2.1079748,0.0,0,7.3341722,0.0,0.15111069,66.90183569736261,7.9331307,457.582,-9.2312689,66.90183569736261
2337,2337,195.3622,6.368865,2.158417,0.0,0,7.2838039,0.0,0.15511839,65.73414845453469,7.8859382,457.78799,-9.232749,65.73414845453469
2339,2339,195.3626,6.4256587,2.2027035,0.0,0,7.2334356,0.0,0.15813974,66.07337099132944,7.8373051,457.66342,-9.2324791,66.07337099132944
2341,2341,195.363,6.5379829,2.2488422,0.0,0,7.1830673,0.0,0.16217037,66.96656723311462,7.7863398,457.42865,-9.2313061,66.96656723311462
2343,2343,195.3634,6.5666099,2.3002632,0.0,0,7.1326995,0.0,0.16600016,66.96670151862067,7.7392635,457.19391,-9.2318163,66.96670151862067
2345,2345,195.3638,6.5224228,2.3589208,0.0,0,7.0823312,0.0,0.17039791,66.18396228267582,7.6886964,456.95917,-9.2312641,66.18396228267582
2347,2347,195.3642,6.5071244,2.4025223,0.0,0,7.0319633,0.0,0.17450239,65.7824114511328,7.6397071,456.72443,-9.2309809,65.7824114511328
2349,2349,195.3646,6.564116,2.4424536,0.0,0,6.981595,0.0,0.17722715,66.13097928617,7.58922,456.48969,-9.2324219,66.13097928617
2351,2351,195.365,6.6112394,2.4965427,0.0,0,6.9312277,0.0,0.1815072,66.29522192924038,7.543592,456.25491,-9.2321987,66.29522192924038
2353,2353,195.3654,6.553236,2.537657,0.0,0,6.8808594,0.0,0.1853389,65.47960820024942,7.5004334,456.02017,-9.2321749,65.47960820024942
2355,2355,195.3658,6.6367278,2.5787463,0.0,0,6.830492,0.0,0.18804449,66.07702151419109,7.4515533,455.78543,-9.2313662,66.07702151419109
2357,2357,195.3662,6.7254114,2.6300077,0.0,0,6.7801232,0.0,0.192471,66.66053915691109,7.4071889,455.55069,-9.2318363,66.66053915691109
2359,2359,195.3666,6.6943498,2.672595,0.0,0,6.7313671,0.0,0.19596504,66.10501874541325,7.3654175,455.31592,-9.2322254,66.10501874541325
2361,2361,195.367,6.689363,2.724745,0.0,0,6.6834416,0.0,0.19976407,65.75271809361382,7.3134656,455.08118,-9.2328348,65.75271809361382
2363,2363,195.3674,6.6928792,2.7706337,0.0,0,6.6355219,0.0,0.2041119,65.5204414685679,7.2637515,454.84644,-9.2327547,65.5204414685679
2365,2365,195.3678,6.7890821,2.8113837,0.0,0,6.5876017,0.0,0.20719324,66.22184108159564,7.2181683,454.61169,-9.2327871,66.22184108159564
2367,2367,195.3682,6.8129082,2.8624029,0.0,0,6.5396819,0.0,0.21112825,66.15219480476419,7.1695704,454.37692,-9.2317905,66.15219480476419
2369,2369,195.3686,6.7667537,2.9032006,0.0,0,6.4917622,0.0,0.21511261,65.46411958628642,7.125649,454.14218,-9.2316809,65.46411958628642
2371,2371,195.369,6.8260198,2.9496219,0.0,0,6.4438419,0.0,0.21839882,65.76207125244942,7.076458,453.90744,-9.231905,65.76207125244942
2373,2373,195.3694,6.9016695,2.9992611,0.0,0,6.3959212,0.0,0.22261776,66.19308559890604,7.0279059,453.6727,-9.2333059,66.19308559890604
2375,2375,195.3698,6.933486,3.0422239,0.0,0,6.3480015,0.0,0.22666016,66.23927573355897,6.981822,453.43793,-9.2329979,66.23927573355897
2377,2377,195.3702,6.9370165,3.1000566,0.0,0,6.3000817,0.0,0.23075855,65.92420203453462,6.9324279,453.20319,-9.2320299,65.92420203453462
2379,2379,195.3706,6.9180846,3.1428239,0.0,0,6.252162,0.0,0.23489659,65.48702331685577,6.8879619,452.96844,-9.2317429,65.48702331685577
2381,2381,195.371,6.9757323,3.1840925,0.0,0,6.2042422,0.0,0.23847064,65.78237927118182,6.8365784,452.7337,-9.2322378,65.78237927118182
2383,2383,195.3714,7.0282969,3.2399406,0.0,0,6.1568027,0.0,0.24246094,65.93670081798714,6.7888432,452.49893,-9.2331648,65.93670081798714
2385,2385,195.3718,7.0481253,3.2806482,0.0,0,6.1111121,0.0,0.24660167,65.87316849878131,6.7420073,452.26419,-9.2325077,65.87316849878131
2387,2387,195.3722,7.07441,3.3278232,0.0,0,6.065536,0.0,0.25051245,65.82852073812163,6.6935606,452.02945,-9.2326708,65.82852073812163
2389,2389,195.3726,7.1118093,3.3856757,0.0,0,6.0199599,0.0,0.25502914,65.81858444532405,6.6418686,451.79114,-9.2324038,65.81858444532405
2391,2391,195.373,7.1229339,3.4257734,0.0,0,5.9743834,0.0,0.25923017,65.67303382780973,6.5937958,451.55161,-9.2324238,65.67303382780973
2393,2393,195.3734,7.1587715,3.4738626,0.0,0,5.9288077,0.0,0.26288095,65.70388998082194,6.5483727,451.3121,-9.2321529,65.70388998082194
2395,2395,195.3738,7.208149,3.5290463,0.0,0,5.8832321,0.0,0.26758361,65.81091037063787,6.4997382,451.0726,-9.2327099,65.81091037063787
2397,2397,195.3742,7.2335057,3.5701473,0.0,0,5.8376555,0.0,0.27166542,65.78365348983169,6.448719,450.83307,-9.2327557,65.78365348983169
2399,2399,195.3746,7.2505193,3.6222036,0.0,0,5.792079,0.0,0.27570572,65.60983530319854,6.4026394,450.59357,-9.2331638,65.60983530319854
2401,2401,195.375,7.2579007,3.6734529,0.0,0,5.7465038,0.0,0.28038996,65.35280902971436,6.3533635,450.35406,-9.233285,65.35280902971436
2403,2403,195.3754,7.3104496,3.7176857,0.0,0,5.7009277,0.0,0.28462765,65.5444367448625,6.3022933,450.11453,-9.231514,65.5444367448625
2405,2405,195.3758,7.3710766,3.7692225,0.0,0,5.6553516,0.0,0.28862068,65.75721949631544,6.2534118,449.87503,-9.2312689,65.75721949631544
2407,2407,195.3762,7.3892441,3.8183684,0.0,0,5.6097755,0.0,0.2936357,65.60303149659559,6.2033114,449.63553,-9.2302504,65.60303149659559
2409,2409,195.3766,7.3838897,3.8660853,0.0,0,5.5656581,0.0,0.29772636,65.24861663554255,6.1550031,449.396,-9.2333279,65.24861663554255
2411,2411,195.377,7.4055161,3.9172835,0.0,0,5.5222936,0.0,0.30194142,65.10945023318807,6.1065269,449.15649,-9.2334118,65.10945023318807
2413,2413,195.3774,7.4873805,3.9629557,0.0,0,5.4789333,0.0,0.3067821,65.53128809133852,6.057075,448.91699,-9.2333612,65.53128809133852
2415,2415,195.3778,7.534699,4.0124612,0.0,0,5.4355736,0.0,0.31067771,65.62043178476347,6.0085392,448.67749,-9.2319393,65.62043178476347
2417,2417,195.3782,7.5305939,4.0623183,0.0,0,5.3922133,0.0,0.31523359,65.2575111219323,5.9563355,448.43796,-9.2320042,65.2575111219323
2419,2419,195.3786,7.5341473,4.1100802,0.0,0,5.3488536,0.0,0.32023183,64.97469764279214,5.9062209,448.19846,-9.2321434,64.97469764279214
2421,2421,195.379,7.5822353,4.1628299,0.0,0,5.3054934,0.0,0.32426247,65.04079923849949,5.8604655,447.95895,-9.2313786,65.04079923849949
2423,2423,195.3794,7.6443062,4.2079039,0.0,0,5.2621331,0.0,0.32879695,65.2728871967137,5.8055906,447.71942,-9.2328072,65.2728871967137
2425,2425,195.3798,7.6762543,4.2536521,0.0,0,5.2187734,0.0,0.33345807,65.2395229237803,5.7591906,447.47992,-9.2333679,65.2395229237803
2427,2427,195.3802,7.6688495,4.3109751,0.0,0,5.1754136,0.0,0.33797839,64.79328647701948,5.7111845,447.24042,-9.2328615,64.79328647701948
2429,2429,195.3806,7.6929464,4.3549886,0.0,0,5.1320534,0.0,0.34266862,64.70160859832203,5.6611133,447.00089,-9.231739,64.70160859832203
2431,2431,195.381,7.7383375,4.3989019,0.0,0,5.0886931,0.0,0.34681237,64.78700125230549,5.6127949,446.76138,-9.2318516,64.78700125230549
2433,2433,195.3814,7.7986321,4.4523244,0.0,0,5.0457683,0.0,0.35106885,64.92839819898036,5.5664444,446.52188,-9.2322273,64.92839819898036
2435,2435,195.3818,7.8025999,4.4927979,0.0,0,5.0044241,0.0,0.3558898,64.6859410146042,5.5193553,446.28235,-9.232975,64.6859410146042
2437,2437,195.3822,7.8240614,4.5406027,0.0,0,4.9631839,0.0,0.36010233,64.53753695512881,5.4708419,446.04285,-9.2331972,64.53753695512881
2439,2439,195.3826,7.8424997,4.5971484,0.0,0,4.9219441,0.0,0.36506563,64.30267027604505,5.4240704,445.96051,-9.2321758,64.30267027604505
2441,2441,195.383,7.8852415,4.6362453,0.0,0,4.8807039,0.0,0.36972049,64.38407878386455,5.3764362,445.93054,-9.2313423,64.38407878386455
2443,2443,195.3834,7.9378462,4.6847343,0.0,0,4.8394642,0.0,0.3737922,64.47766449956491,5.3283134,445.90057,-9.2317791,64.47766449956491
2445,2445,195.3838,7.9512458,4.736238,0.0,0,4.798224,0.0,0.37888846,64.22903148844925,5.2841415,445.87064,-9.2327366,64.22903148844925
2447,2447,195.3842,7.9863205,4.7744436,0.0,0,4.7569842,0.0,0.38310474,64.24598151234655,5.2366614,445.84067,-9.2328615,64.24598151234655
2449,2449,195.3846,7.9855404,4.8247342,0.0,0,4.715744,0.0,0.38725176,63.88906027169089,5.1921034,445.8107,-9.2339249,63.88906027169089
2451,2451,195.385,8.0257692,4.8727779,0.0,0,4.6745043,0.0,0.39251101,63.874202386395176,5.1439362,445.78076,-9.2318268,63.874202386395176
2453,2453,195.3854,8.0682583,4.9131126,0.0,0,4.6332641,0.0,0.39655912,63.928142851610616,5.0955639,445.75079,-9.2319012,63.928142851610616
2455,2455,195.3858,8.0952215,4.9605165,0.0,0,4.5920238,0.0,0.40074322,63.806599151486324,5.0532374,445.72083,-9.2316561,63.806599151486324
2457,2457,195.3862,8.0909662,5.0068631,0.0,0,4.5507841,0.0,0.40614516,63.4454802768748,5.0097079,445.69089,-9.231698,63.4454802768748
2459,2459,195.3866,8.1111221,5.049705,0.0,0,4.5108657,0.0,0.41004452,63.299933869252584,4.962091,445.66092,-9.2330818,63.299933869252584
2461,2461,195.387,8.1481638,5.0939274,0.0,0,4.4716296,0.0,0.41428366,63.27415893560941,4.9194093,445.63095,-9.2318735,63.27415893560941
2463,2463,195.3874,8.2121515,5.1329017,0.0,0,4.4323978,0.0,0.41891372,63.49135376902871,4.874568,445.60101,-9.2327337,63.49135376902871
2465,2465,195.3878,8.2175951,5.1774302,0.0,0,4.3931656,0.0,0.42272633,63.21363276505455,4.833055,445.57104,-9.2312841,63.21363276505455
2467,2467,195.3882,8.2223501,5.2231979,0.0,0,4.3539338,0.0,0.42746502,62.92127051024372,4.7897711,445.54108,-9.2316074,62.92127051024372
2469,2469,195.3886,8.2542257,5.2619815,0.0,0,4.314702,0.0,0.43214333,62.885339109679926,4.7474804,445.51114,-9.2314053,62.885339109679926
2471,2471,195.389,8.2974958,5.3101277,0.0,0,4.2754698,0.0,0.43602118,62.865712467922656,4.7031913,445.48117,-9.2318172,62.865712467922656
2473,2473,195.3894,8.3480949,5.3475828,0.0,0,4.2362375,0.0,0.44047481,62.97566159725952,4.6614199,445.4512,-9.2327471,62.97566159725952
2475,2475,195.3898,8.3517103,5.3832011,0.0,0,4.1970053,0.0,0.44456202,62.742789978218475,4.6211534,445.42123,-9.2326059,62.742789978218475
2477,2477,195.3902,8.372324,5.432951,0.0,0,4.1577735,0.0,0.44859341,62.533351832725145,4.5813155,445.3913,-9.2323151,62.533351832725145
2479,2479,195.3906,8.3984079,5.4691262,0.0,0,4.1185417,0.0,0.45332953,62.46241791765832,4.5375261,445.36133,-9.2316017,62.46241791765832
2481,2481,195.391,8.4414253,5.5092406,0.0,0,4.0793095,0.0,0.45735514,62.486118775656394,4.497787,445.33136,-9.2307177,62.486118775656394
2483,2483,195.3914,8.4827042,5.5578675,0.0,0,4.0404716,0.0,0.46181527,62.4307748796888,4.4594579,445.30142,-9.2316885,62.4307748796888
2485,2485,195.3918,8.5261259,5.5891523,0.0,0,4.0030656,0.0,0.4663204,62.51694037863905,4.4148493,445.27145,-9.2326403,62.51694037863905
2487,2487,195.3922,8.5307827,5.6283388,0.0,0,3.9657533,0.0,0.46981779,62.258534706528074,4.3779793,445.24149,-9.2342052,62.258534706528074
2489,2489,195.3926,8.5436449,5.6750183,0.0,0,3.9284413,0.0,0.47454542,62.00334346604303,4.3385863,444.92459,-9.2318811,62.00334346604303
2491,2491,195.393,8.593194,5.7080512,0.0,0,3.8911293,0.0,0.47893667,62.11445739104578,4.2993565,444.51205,-9.2315912,62.11445739104578
2493,2493,195.3934,8.6403704,5.7498565,0.0,0,3.8538175,0.0,0.48255104,62.13923945282623,4.2592506,444.09952,-9.2313776,62.13923945282623
2495,2495,195.3938,8.6642179,5.7935114,0.0,0,3.8165054,0.0,0.48771602,61.97957506853854,4.2208109,443.68695,-9.2326965,61.97957506853854
2497,2497,195.3942,8.6785469,5.8248029,0.0,0,3.7791932,0.0,0.49151394,61.844278724914936,4.1838584,443.27441,-9.2329531,61.844278724914936
2499,2499,195.3946,8.7096062,5.8663669,0.0,0,3.7418811,0.0,0.49520236,61.748580780987915,4.1455297,442.86188,-9.2330246,61.748580780987915
2501,2501,195.395,8.7658539,5.9065409,0.0,0,3.7045693,0.0,0.50036865,61.83891582534151,4.1037335,442.44931,-9.2320843,61.83891582534151
2503,2503,195.3954,8.8237982,5.9403558,0.0,0,3.6672573,0.0,0.50391543,61.986318238256295,4.0650587,442.03677,-9.2315044,61.986318238256295
2505,2505,195.3958,8.8369551,5.9834366,0.0,0,3.6299453,0.0,0.50812709,61.745222271367574,4.0262728,441.62424,-9.2312593,61.745222271367574
2507,2507,195.3962,8.8527946,6.0201793,0.0,0,3.5926332,0.0,0.51321596,61.570896995955536,3.9853339,441.2117,-9.2309561,61.570896995955536
2509,2509,195.3966,8.8878918,6.0583968,0.0,0,3.5565166,0.0,0.51673597,61.51734957500962,3.9480047,440.79913,-9.232666,61.51734957500962
2511,2511,195.397,8.9403095,6.0984192,0.0,0,3.5210168,0.0,0.52111608,61.5665771679353,3.9103341,440.3866,-9.2321281,61.5665771679353
2513,2513,195.3974,9.0048494,6.1303282,0.0,0,3.4855206,0.0,0.52567869,61.75918127966131,3.8733284,439.97406,-9.2320137,61.75918127966131
2515,2515,195.3978,9.0146923,6.1722932,0.0,0,3.4500248,0.0,0.52928531,61.49507699643064,3.8330462,439.56152,-9.2323742,61.49507699643064
2517,2517,195.3982,9.0278454,6.2100019,0.0,0,3.4145288,0.0,0.53398478,61.28635367090106,3.7994461,439.14896,-9.2313652,61.28635367090106
2519,2519,195.3986,9.0749435,6.2422805,0.0,0,3.3790326,0.0,0.53829855,61.34925056363655,3.7636282,438.73642,-9.230957,61.34925056363655
2521,2521,195.399,9.1428003,6.2873063,0.0,0,3.3435369,0.0,0.54218251,61.44700067643551,3.7223771,438.32388,-9.2321415,61.44700067643551
2523,2523,195.3994,9.1966324,6.3183498,0.0,0,3.3080409,0.0,0.54666567,61.55841826525356,3.6848962,437.91132,-9.2324486,61.55841826525356
2525,2525,195.3998,9.2016926,6.3531103,0.0,0,3.2725446,0.0,0.55065793,61.31174935224698,3.6498535,437.49878,-9.2316637,61.31174935224698
2527,2527,195.4002,9.2297077,6.4009185,0.0,0,3.2370486,0.0,0.55509424,61.11134854109527,3.6116059,437.08624,-9.2309532,61.11134854109527
2529,2529,195.4006,9.2794285,6.4314008,0.0,0,3.2015526,0.0,0.55990469,61.192404822414986,3.5767777,436.67371,-9.2315292,61.192404822414986
2531,2531,195.401,9.3462276,6.4681797,0.0,0,3.1660566,0.0,0.56369698,61.331305604360935,3.5394843,436.26114,-9.2308121,61.331305604360935
2533,2533,195.4014,9.3942556,6.5132451,0.0,0,3.1309152,0.0,0.56857491,61.27497275214953,3.5032296,435.8486,-9.2314224,61.27497275214953
2535,2535,195.4018,9.4092607,6.5408506,0.0,0,3.0970623,0.0,0.57291228,61.14488756884506,3.4661422,435.43607,-9.2320395,61.14488756884506
2537,2537,195.4022,9.4317064,6.5770431,0.0,0,3.0632944,0.0,0.57638806,60.9911386902546,3.4306178,435.0235,-9.2312632,60.9911386902546
2539,2539,195.4026,9.4880857,6.6200995,0.0,0,3.0295265,0.0,0.58146626,60.997115456007855,3.3909984,434.71704,-9.2310724,60.997115456007855
2541,2541,195.403,9.5497513,6.6473656,0.0,0,2.9957583,0.0,0.58555937,61.16495794088599,3.3575015,434.44595,-9.2304182,61.16495794088599
2543,2543,195.4034,9.595953,6.687933,0.0,0,2.9619906,0.0,0.58936864,61.11908192750111,3.3178778,434.17487,-9.2302036,61.11908192750111
2545,2545,195.4038,9.6335192,6.7273412,0.0,0,2.9282222,0.0,0.59485102,61.02498284746138,3.2827888,433.90375,-9.231226,61.02498284746138
2547,2547,195.4042,9.6567192,6.758965,0.0,0,2.8944542,0.0,0.59876102,60.90375524148271,3.2480714,433.63266,-9.2322178,60.90375524148271
2549,2549,195.4046,9.718565,6.797956,0.0,0,2.8606863,0.0,0.60275143,60.9609834554295,3.2113771,433.36154,-9.2312641,60.9609834554295
2551,2551,195.405,9.7902632,6.8320184,0.0,0,2.8269184,0.0,0.60797662,61.117785239625555,3.1766903,433.09045,-9.2305593,61.117785239625555
2553,2553,195.4054,9.8322001,6.8647709,0.0,0,2.7931502,0.0,0.61147588,61.09667880416666,3.1423211,432.81937,-9.2304945,61.09667880416666
2555,2555,195.4058,9.8637486,6.9042716,0.0,0,2.7593822,0.0,0.61574131,60.95038946334813,3.1061649,432.54825,-9.2309408,60.95038946334813
2557,2557,195.4062,9.9057636,6.9381294,0.0,0,2.7256143,0.0,0.621185,60.91529937993737,3.0724909,432.27716,-9.2313833,60.91529937993737
2559,2559,195.4066,9.9471359,6.9758501,0.0,0,2.6929309,0.0,0.62478989,60.83997377901797,3.0385637,432.00604,-9.2317543,60.83997377901797
2561,2561,195.407,10.03002,7.0114422,0.0,0,2.6608074,0.0,0.62940884,61.033154802144004,3.0017323,431.73495,-9.2305479,61.033154802144004
2563,2563,195.4074,10.070148,7.0413022,0.0,0,2.6286874,0.0,0.63400733,61.01302104394353,2.9660239,431.46387,-9.2309437,61.01302104394353
2565,2565,195.4078,10.088629,7.0825062,0.0,0,2.5965672,0.0,0.63794196,60.75955340098666,2.9318924,431.19275,-9.2312717,60.75955340098666
2567,2567,195.4082,10.12858,7.1142826,0.0,0,2.5644474,0.0,0.64268196,60.7171857692941,2.8981354,430.92166,-9.2310886,60.7171857692941
2569,2569,195.4086,10.184989,7.1452546,0.0,0,2.5323272,0.0,0.64693826,60.77796112052898,2.861582,430.65054,-9.2306509,60.77796112052898
2571,2571,195.409,10.249131,7.1889124,0.0,0,2.5002072,0.0,0.65119714,60.767226457926185,2.8277123,430.37946,-9.2296124,60.767226457926185
2573,2573,195.4094,10.303197,7.2164197,0.0,0,2.4680872,0.0,0.65604639,60.83851968585975,2.7939894,430.10837,-9.229537,60.83851968585975
2575,2575,195.4098,10.339851,7.2479625,0.0,0,2.4359674,0.0,0.65972799,60.768077444199136,2.7579279,429.83725,-9.2301502,60.768077444199136
2577,2577,195.4102,10.375829,7.289957,0.0,0,2.4038472,0.0,0.66422403,60.59621452392598,2.7230952,429.56616,-9.2312841,60.59621452392598
2579,2579,195.4106,10.436361,7.3142543,0.0,0,2.3717272,0.0,0.6688621,60.72663633128007,2.69103,429.29504,-9.231081,60.72663633128007
2581,2581,195.411,10.510854,7.3484597,0.0,0,2.3396072,0.0,0.6725117,60.8437543035725,2.6570418,429.02396,-9.2312202,60.8437543035725
2583,2583,195.4114,10.572346,7.3923554,0.0,0,2.3078089,0.0,0.67795765,60.79132828114408,2.6239438,428.75287,-9.230051,60.79132828114408
2585,2585,195.4118,10.603814,7.4187918,0.0,0,2.2771804,0.0,0.68261838,60.725560432920815,2.5900059,428.48175,-9.2294216,60.725560432920815
2587,2587,195.4122,10.629955,7.4553537,0.0,0,2.246628,0.0,0.68635386,60.533185405249625,2.5585849,428.21066,-9.2293053,60.533185405249625
2589,2589,195.4126,10.708163,7.4924145,0.0,0,2.2160764,0.0,0.69168794,60.62920950064921,2.5251343,427.79654,-9.2299395,60.62920950064921
2591,2591,195.413,10.787343,7.5150461,0.0,0,2.1855242,0.0,0.69530493,60.86259870072061,2.4925663,427.33478,-9.2307539,60.86259870072061
2593,2593,195.4134,10.84094,7.5501909,0.0,0,2.1549723,0.0,0.69869632,60.82954747171094,2.457298,426.87299,-9.2320147,60.82954747171094
2595,2595,195.4138,10.87206,7.5836,0.0,0,2.1244202,0.0,0.70430517,60.68433416366833,2.4260571,426.41122,-9.2305422,60.68433416366833
2597,2597,195.4142,10.90864,7.6137052,0.0,0,2.0938683,0.0,0.70815748,60.59931162910857,2.3909905,425.94943,-9.2291441,60.59931162910857
2599,2599,195.4146,10.993791,7.6512394,0.0,0,2.0633163,0.0,0.71249199,60.7089210189924,2.361896,425.48767,-9.229701,60.7089210189924
2601,2601,195.415,11.075599,7.6829209,0.0,0,2.0327644,0.0,0.71812826,60.8516070481733,2.3252215,425.02588,-9.2303667,60.8516070481733
2603,2603,195.4154,11.120255,7.7157326,0.0,0,2.0022123,0.0,0.72170699,60.77554119786022,2.2958081,424.56412,-9.2309656,60.77554119786022
2605,2605,195.4158,11.166894,7.7476602,0.0,0,1.9716601,0.0,0.72586906,60.71633961971711,2.2637703,424.10233,-9.2307549,60.71633961971711
2607,2607,195.4162,11.216227,7.7736979,0.0,0,1.9411081,0.0,0.7307018,60.727263095337534,2.2309449,423.64056,-9.2301769,60.727263095337534
2609,2609,195.4166,11.299296,7.8099194,0.0,0,1.9115355,0.0,0.73424256,60.816386094109035,2.2016289,423.17877,-9.2297049,60.816386094109035
2611,2611,195.417,11.390156,7.8418746,0.0,0,1.8824685,0.0,0.73929077,60.984676301255845,2.1657488,422.71698,-9.2303715,60.984676301255845
2613,2613,195.4174,11.439127,7.8705444,0.0,0,1.8534043,0.0,0.74411869,60.95784067122896,2.1336131,422.25522,-9.2320423,60.95784067122896
2615,2615,195.4178,11.472992,7.9100761,0.0,0,1.8243403,0.0,0.74814415,60.73854446528242,2.1054897,421.79343,-9.2306566,60.73854446528242
2617,2617,195.4182,11.521163,7.9350867,0.0,0,1.7952764,0.0,0.75281209,60.73956108475797,2.0742159,421.33167,-9.229558,60.73956108475797
2619,2619,195.4186,11.609316,7.96139,0.0,0,1.7662123,0.0,0.75646925,60.935107814019844,2.0467649,420.86987,-9.229723,60.935107814019844
2621,2621,195.419,11.695812,8.0021896,0.0,0,1.7371484,0.0,0.76108843,60.96840084022808,2.0118914,420.40811,-9.2297125,60.96840084022808
2623,2623,195.4194,11.739811,8.0284567,0.0,0,1.7080843,0.0,0.76640487,60.92585961795841,1.981207,419.94632,-9.2299747,60.92585961795841
2625,2625,195.4198,11.777314,8.0591116,0.0,0,1.6790204,0.0,0.77020109,60.80212717620687,1.9523805,419.48456,-9.2301884,60.80212717620687
2627,2627,195.4202,11.844139,8.0966625,0.0,0,1.6499563,0.0,0.77489316,60.75489136210111,1.9223403,419.02277,-9.2301941,60.75489136210111
2629,2629,195.4206,11.951365,8.116312,0.0,0,1.6208923,0.0,0.77925819,61.09779081790076,1.891975,418.561,-9.2285051,61.09779081790076
2631,2631,195.421,12.035185,8.147521,0.0,0,1.5918283,0.0,0.78261238,61.1949991784943,1.8590711,418.09921,-9.2288065,61.1949991784943
2633,2633,195.4214,12.080694,8.1843405,0.0,0,1.5630548,0.0,0.78811783,61.03402764969697,1.8279386,417.63745,-9.2305374,61.03402764969697
2635,2635,195.4218,12.141011,8.2086105,0.0,0,1.5353373,0.0,0.79258072,61.07881205410538,1.7983518,417.17566,-9.229497,61.07881205410538
2637,2637,195.4222,12.210181,8.2451658,0.0,0,1.5076892,0.0,0.79660243,61.03299431684559,1.7685246,416.7139,-9.2291241,61.03299431684559
2639,2639,195.4226,12.306054,8.276576,0.0,0,1.4800413,0.0,0.80220991,61.17115909336506,1.7358805,416.27118,-9.2289515,61.17115909336506
2641,2641,195.423,12.388738,8.3002968,0.0,0,1.4523933,0.0,0.80600172,61.32284994875094,1.7059704,415.83481,-9.2291546,61.32284994875094
2643,2643,195.4234,12.434714,8.3344383,0.0,0,1.4247453,0.0,0.80995417,61.175775975333366,1.6761962,415.39844,-9.2296953,61.175775975333366
2645,2645,195.4238,12.498471,8.3631334,0.0,0,1.3970973,0.0,0.81561971,61.172919710859304,1.6476198,414.9621,-9.2295609,61.172919710859304
2647,2647,195.4242,12.575627,8.3887272,0.0,0,1.3694494,0.0,0.81887472,61.26647546716259,1.617431,414.52573,-9.2295389,61.26647546716259
2649,2649,195.4246,12.666612,8.4209681,0.0,0,1.3418013,0.0,0.82319194,61.349265069940756,1.5901123,414.08936,-9.2282572,61.349265069940756
2651,2651,195.425,12.743983,8.4482298,0.0,0,1.3141534,0.0,0.82875919,61.417313044690744,1.5600964,413.65298,-9.2288275,61.417313044690744
2653,2653,195.4254,12.798708,8.4812441,0.0,0,1.2865053,0.0,0.83248979,61.30802160262218,1.529525,413.21664,-9.2295036,61.30802160262218
2655,2655,195.4258,12.875991,8.5127029,0.0,0,1.2588574,0.0,0.83743554,61.32059232352106,1.500689,412.78027,-9.2306919,61.32059232352106
2657,2657,195.4262,12.94876,8.5370483,0.0,0,1.2312094,0.0,0.84250718,61.388801989478225,1.4719197,412.3439,-9.2298479,61.388801989478225
2659,2659,195.4266,13.044004,8.5697327,0.0,0,1.2044513,0.0,0.84593529,61.46388331471549,1.4449505,411.90756,-9.2282257,61.46388331471549
2661,2661,195.427,13.125267,8.5934296,0.0,0,1.1781524,0.0,0.85060805,61.57213654753806,1.414969,411.47119,-9.2281895,61.57213654753806
2663,2663,195.4274,13.176652,8.6177921,0.0,0,1.1518564,0.0,0.85483867,61.52969195614132,1.3878624,411.03482,-9.2288942,61.52969195614132
2665,2665,195.4278,13.245081,8.6558027,0.0,0,1.1255604,0.0,0.85888046,61.40458355412117,1.3577015,410.59845,-9.2289753,61.40458355412117
2667,2667,195.4282,13.321759,8.678009,0.0,0,1.0992644,0.0,0.86404651,61.49877618442755,1.3298881,410.16211,-9.2284908,61.49877618442755
2669,2669,195.4286,13.425488,8.7047195,0.0,0,1.0729684,0.0,0.86801946,61.66088087845451,1.301245,409.72574,-9.2286758,61.66088087845451
2671,2671,195.429,13.505756,8.7424202,0.0,0,1.0466723,0.0,0.87287772,61.57975236351972,1.2734509,409.28937,-9.2287836,61.57975236351972
2673,2673,195.4294,13.581347,8.7614937,0.0,0,1.0203763,0.0,0.87763661,61.695568748084774,1.2456498,408.85303,-9.2294655,61.695568748084774
2675,2675,195.4298,13.650677,8.7889853,0.0,0,0.99408036,0.0,0.88095391,61.678970416336846,1.2165254,408.41666,-9.2284241,61.678970416336846
2677,2677,195.4302,13.748824,8.8215141,0.0,0,0.96778435,0.0,0.88598776,61.72730265005352,1.1870891,407.98029,-9.2284279,61.72730265005352
2679,2679,195.4306,13.854035,8.8388548,0.0,0,0.94148839,0.0,0.89023292,61.98739937806201,1.1612256,407.54391,-9.2289228,61.98739937806201
2681,2681,195.431,13.951651,8.8686209,0.0,0,0.91519243,0.0,0.89342588,62.057221677058784,1.131902,407.10757,-9.2290325,62.057221677058784
2683,2683,195.4314,14.011188,8.9037361,0.0,0,0.88916051,0.0,0.89989138,61.88728557592629,1.1017735,406.6712,-9.2286663,61.88728557592629
2685,2685,195.4318,14.073849,8.9250116,0.0,0,0.86408949,0.0,0.90413857,61.8994572532193,1.0761877,406.23483,-9.2291861,61.8994572532193
2687,2687,195.4322,14.160179,8.955142,0.0,0,0.83908135,0.0,0.90757227,61.90210855331948,1.0471699,405.79849,-9.228013,61.90210855331948
2689,2689,195.4326,14.267135,8.9816265,0.0,0,0.81407332,0.0,0.91338187,62.03573364369287,1.0219759,406.08792,-9.2279272,62.03573364369287
2691,2691,195.433,14.364684,9.0025511,0.0,0,0.78906536,0.0,0.91660815,62.19424211233433,0.99511474,406.61932,-9.2278957,62.19424211233433
2693,2693,195.4334,14.435548,9.0322342,0.0,0,0.7640574,0.0,0.92048544,62.122341279319215,0.9668653,407.1507,-9.2285919,62.122341279319215
2695,2695,195.4338,14.515427,9.0569782,0.0,0,0.73904938,0.0,0.92624366,62.14863334649945,0.94154423,407.68207,-9.2283764,62.14863334649945
2697,2697,195.4342,14.619436,9.0830851,0.0,0,0.71404135,0.0,0.92963719,62.25659424492026,0.91610396,408.21347,-9.2291574,62.25659424492026
2699,2699,195.4346,14.748887,9.1133041,0.0,0,0.68903339,0.0,0.9343881,62.41388884670358,0.88810766,408.74484,-9.2278404,62.41388884670358
2701,2701,195.435,14.847974,9.135623,0.0,0,0.66402543,0.0,0.93976879,62.54026218669311,0.85978627,409.27621,-9.2271385,62.54026218669311
2703,2703,195.4354,14.907614,9.1666527,0.0,0,0.63901734,0.0,0.94324136,62.38254806649022,0.83776224,409.80762,-9.2268829,62.38254806649022
2705,2705,195.4358,14.976017,9.1907635,0.0,0,0.61400938,0.0,0.94817561,62.34957936048286,0.81099194,410.33899,-9.2273264,62.34957936048286
2707,2707,195.4362,15.079769,9.2087421,0.0,0,0.58900136,0.0,0.95239127,62.54185219903383,0.78641689,410.87036,-9.2267494,62.54185219903383
2709,2709,195.4366,15.205647,9.2417164,0.0,0,0.56478846,0.0,0.95592266,62.620649058356086,0.76000243,411.40176,-9.2280302,62.620649058356086
2711,2711,195.437,15.309986,9.2628565,0.0,0,0.54098594,0.0,0.96101022,62.76420194106717,0.73300886,411.93314,-9.2292852,62.76420194106717
2713,2713,195.4374,15.380179,9.2861996,0.0,0,0.51718587,0.0,0.96510035,62.73454793864069,0.70819259,412.46451,-9.2294264,62.73454793864069
2715,2715,195.4378,15.478451,9.3221636,0.0,0,0.49338591,0.0,0.96974313,62.643225298442765,0.68717462,412.99591,-9.2274179,62.643225298442765
2717,2717,195.4382,15.602856,9.3401842,0.0,0,0.4695859,0.0,0.97494996,62.898109787061436,0.65628117,413.52728,-9.227416,62.898109787061436
2719,2719,195.4386,15.719871,9.362628,0.0,0,0.44578591,0.0,0.97816694,63.05787691745369,0.63396931,414.05865,-9.2271767,63.05787691745369
2721,2721,195.439,15.814137,9.394866,0.0,0,0.42198589,0.0,0.9830119,62.98524671886583,0.60730511,414.59006,-9.2275448,62.98524671886583
2723,2723,195.4394,15.890785,9.41012,0.0,0,0.39818591,0.0,0.98772955,63.07620066531335,0.58102959,415.12143,-9.2281332,63.07620066531335
2725,2725,195.4398,15.994005,9.437191,0.0,0,0.37438589,0.0,0.99080235,63.10308905603679,0.55630553,415.6528,-9.2282562,63.10308905603679
2726,2726,195.44,16.053583,9.4473639,0.0,0,0.36248589,0.0,0.99434692,63.19375117625038,0.54364753,415.91849,-9.2273302,63.19375117625038