File: examples/hot axisymmetric compression example/data/04 corrected data/testID_0137.csv
level_0,index,Time(sec),Force(kN),Jaw(mm),PowAngle(deg),Power(W),Pram,PTemp,Strain,Stress(MPa),Stroke(mm),TC1(C),wedge(mm),uncorrected stress
1872,1872,155.3437,0.20522638,0.017086202,0.0,0,9.0629654,0.0,0.0013593487,2.4987992144072364,10.074247,330.84628,-9.3046198,2.4987992144072364
1874,1874,155.3441,2.8604155,0.062240697,0.0,0,9.0044374,0.0,0.0036085686,34.71622437635408,9.9985628,330.99252,-9.3046293,34.71622437635408
1876,1876,155.3445,5.7684398,0.12895332,0.0,0,8.9459095,0.0,0.0082608964,69.67750372088233,9.947607,331.13876,-9.3026409,69.67750372088233
1878,1878,155.3449,6.5943432,0.18412398,0.0,0,8.8873816,0.0,0.011909558,79.33904430079298,9.870162,331.285,-9.2998056,79.33904430079298
1880,1880,155.3453,7.0864091,0.34196398,0.0,0,8.8288536,0.0,0.021803239,84.29184034625382,9.7807989,331.43124,-9.2985163,84.29184034625382
1882,1882,155.3457,7.5552607,0.40819198,0.0,0,8.7703257,0.0,0.027408548,89.43590656246283,9.681695,331.57748,-9.2999554,89.43590656246283
1884,1884,155.3461,8.1473179,0.48449156,0.0,0,8.7136831,0.0,0.032193612,95.90660049643198,9.5841265,331.72372,-9.2994576,95.90660049643198
1886,1886,155.3465,8.763978,0.5800845,0.0,0,8.6580124,0.0,0.038937692,102.44073099310292,9.5012512,331.86996,-9.298934,102.44073099310292
1888,1888,155.3469,8.6785297,0.57524639,0.0,0,8.6023483,0.0,0.038997173,101.47827368710784,9.4223499,332.0162,-9.2978048,101.47827368710784
1890,1890,155.3473,8.4535379,0.67376447,0.0,0,8.5466843,0.0,0.045182262,98.1266960932357,9.361908,332.16245,-9.2984352,98.1266960932357
1892,1892,155.3477,9.1361418,0.73943013,0.0,0,8.4910212,0.0,0.050093938,105.53094327922307,9.298028,332.30865,-9.2981901,105.53094327922307
1894,1894,155.3481,9.2260771,0.78540272,0.0,0,8.4353561,0.0,0.053368054,106.20263350135778,9.2287216,332.41351,-9.2971048,106.20263350135778
1896,1896,155.3485,9.3226376,0.89648885,0.0,0,8.3796921,0.0,0.060828574,106.41759773781908,9.1513319,332.51834,-9.2965765,106.41759773781908
1898,1898,155.3489,9.0100079,0.97089326,0.0,0,8.324029,0.0,0.066282593,102.26848310912968,9.0744448,332.62317,-9.2978182,102.26848310912968
1900,1900,155.3493,9.5023232,1.0357691,0.0,0,8.2683649,0.0,0.071258731,107.32269068606409,8.9950361,332.728,-9.2977962,107.32269068606409
1902,1902,155.3497,9.4003916,1.0881308,0.0,0,8.2127008,0.0,0.074880444,105.74515330555904,8.926259,332.83286,-9.2986622,105.74515330555904
1904,1904,155.3501,9.731329,1.1365325,0.0,0,8.1570368,0.0,0.078390338,109.05992013875063,8.8641624,332.93768,-9.2990904,109.05992013875063
1906,1906,155.3505,9.4647799,1.2013227,0.0,0,8.1013727,0.0,0.083172821,105.54150179628245,8.8079338,333.04251,-9.2975721,105.54150179628245
1908,1908,155.3509,9.7509375,1.2590724,0.0,0,8.0462637,0.0,0.087093696,108.2446146739663,8.7481556,333.14737,-9.2970467,108.2446146739663
1910,1910,155.3513,9.9868231,1.3272533,0.0,0,7.9931717,0.0,0.092189714,110.2732332051624,8.6854668,333.2522,-9.2969856,110.2732332051624
1912,1912,155.3517,9.7631998,1.4101264,0.0,0,7.9402113,0.0,0.098267347,107.10291764685078,8.6181011,333.35703,-9.2958431,107.10291764685078
1914,1914,155.3521,9.8253422,1.4661344,0.0,0,7.8872514,0.0,0.10227906,107.30772874492658,8.5533848,333.46185,-9.2975588,107.30772874492658
1916,1916,155.3525,9.8446016,1.5263799,0.0,0,7.8342915,0.0,0.10714985,107.00403545560651,8.4876385,333.56671,-9.2978373,107.00403545560651
1918,1918,155.3529,10.136589,1.5646787,0.0,0,7.7813311,0.0,0.10987338,109.84123671358526,8.430686,333.67154,-9.2970829,109.84123671358526
1920,1920,155.3533,10.02853,1.6087232,0.0,0,7.7283711,0.0,0.11286505,108.28741040456268,8.3747797,333.77637,-9.2975559,108.28741040456268
1922,1922,155.3537,10.027311,1.6747134,0.0,0,7.6754107,0.0,0.11829312,107.70059532842548,8.3254242,333.88123,-9.2986174,107.70059532842548
1924,1924,155.3541,10.171208,1.7176386,0.0,0,7.6224508,0.0,0.12111659,108.86761225758485,8.269372,333.98605,-9.2969093,108.86761225758485
1926,1926,155.3545,10.382428,1.7775227,0.0,0,7.5694909,0.0,0.12564366,110.58929392671493,8.2135344,334.09088,-9.2967472,110.58929392671493
1928,1928,155.3549,10.290697,1.8394004,0.0,0,7.516531,0.0,0.13065438,109.0600116139835,8.1537857,334.19571,-9.2966013,109.0600116139835
1930,1930,155.3553,10.282034,1.8995224,0.0,0,7.4635711,0.0,0.13457388,108.43205809862937,8.0949764,334.30057,-9.2971172,108.43205809862937
1932,1932,155.3557,10.305506,1.9500476,0.0,0,7.4106107,0.0,0.13901359,108.22794944955119,8.0389738,334.4054,-9.2972927,108.22794944955119
1934,1934,155.3561,10.461086,1.9859682,0.0,0,7.3593569,0.0,0.14179721,109.53587890847515,7.9917445,334.51022,-9.2973709,109.53587890847515
1936,1936,155.3565,10.527006,2.043251,0.0,0,7.3089838,0.0,0.14566109,109.70297370055832,7.9378014,334.61508,-9.2961054,109.70297370055832
1938,1938,155.3569,10.43521,2.090914,0.0,0,7.258616,0.0,0.15009356,108.31482420229604,7.8924665,334.71991,-9.2967281,108.31482420229604
1940,1940,155.3573,10.578487,2.1325879,0.0,0,7.2082477,0.0,0.15286916,109.41947954223927,7.8422294,334.82474,-9.2967777,109.41947954223927
1942,1942,155.3577,10.650688,2.1949379,0.0,0,7.1578794,0.0,0.15749566,109.5900232782432,7.7891526,334.92953,-9.2970314,109.5900232782432
1944,1944,155.3581,10.70978,2.2401245,0.0,0,7.107511,0.0,0.16168536,109.7780478655828,7.7403903,334.77844,-9.2969961,109.7780478655828
1946,1946,155.3585,10.683045,2.2926259,0.0,0,7.0571437,0.0,0.16523054,109.01718723520327,7.6861725,334.62732,-9.2975922,109.01718723520327
1948,1948,155.3589,10.732936,2.3472519,0.0,0,7.0067749,0.0,0.16982551,109.01736946946924,7.6351609,334.4762,-9.29673,109.01736946946924
1950,1950,155.3593,10.827108,2.3801432,0.0,0,6.9564075,0.0,0.17266743,109.66474239276596,7.586225,334.3251,-9.2976809,109.66474239276596
1952,1952,155.3597,10.860914,2.4354351,0.0,0,6.9060392,0.0,0.17642367,109.4857751874859,7.5413136,334.17398,-9.2957067,109.4857751874859
1954,1954,155.3601,10.841933,2.4821644,0.0,0,6.8556719,0.0,0.18084858,108.85452062228023,7.4934845,334.02286,-9.2954922,108.85452062228023
1956,1956,155.3605,10.961103,2.5238006,0.0,0,6.8053036,0.0,0.18386936,109.65469424205692,7.4461908,333.87177,-9.2976017,109.65469424205692
1958,1958,155.3609,11.057557,2.5790231,0.0,0,6.7554379,0.0,0.18798266,110.08931079394667,7.3979101,333.72064,-9.2984533,110.08931079394667
1960,1960,155.3613,10.988693,2.6233456,0.0,0,6.7073984,0.0,0.19220334,108.98067257919033,7.3497458,333.56952,-9.2974281,108.98067257919033
1962,1962,155.3617,11.066596,2.6732986,0.0,0,6.6594777,0.0,0.1957528,109.27308513281366,7.2984548,333.41843,-9.2972622,109.27308513281366
1964,1964,155.3621,11.113399,2.7188034,0.0,0,6.6115575,0.0,0.19951759,109.29589792922265,7.2497826,333.2673,-9.2969151,109.29589792922265
1966,1966,155.3625,11.241803,2.7582061,0.0,0,6.5636377,0.0,0.2031215,110.1738573244877,7.1995664,333.11618,-9.2961483,110.1738573244877
1968,1968,155.3629,11.250187,2.8144615,0.0,0,6.515718,0.0,0.20710298,109.70611579651413,7.1549125,332.96509,-9.2982121,109.70611579651413
1970,1970,155.3633,11.244265,2.8589296,0.0,0,6.4677982,0.0,0.21109954,109.21386506570744,7.1061654,332.81396,-9.2984209,109.21386506570744
1972,1972,155.3637,11.336721,2.9044662,0.0,0,6.419878,0.0,0.21499015,109.66323176379677,7.0565791,332.66284,-9.2984457,109.66323176379677
1974,1974,155.3641,11.435444,2.9624519,0.0,0,6.3719578,0.0,0.21920715,110.04186920955107,7.0069423,332.51175,-9.2973261,110.04186920955107
1976,1976,155.3645,11.479074,3.0049589,0.0,0,6.324038,0.0,0.22336382,110.03756724593681,6.9562917,332.36063,-9.2968254,110.03756724593681
1978,1978,155.3649,11.478513,3.0530169,0.0,0,6.2761183,0.0,0.22723213,109.55262788456115,6.907546,332.2095,-9.2964134,109.55262788456115
1980,1980,155.3653,11.510918,3.1077266,0.0,0,6.2281981,0.0,0.23139374,109.31436525924757,6.8615856,332.05841,-9.2977571,109.31436525924757
1982,1982,155.3657,11.600352,3.146404,0.0,0,6.1802783,0.0,0.23526855,109.77354704598292,6.8097472,331.90729,-9.2985649,109.77354704598292
1984,1984,155.3661,11.667279,3.1957703,0.0,0,6.1339011,0.0,0.23912594,109.90599855871082,6.7603345,331.75616,-9.2978888,109.90599855871082
1986,1986,155.3665,11.695992,3.2465341,0.0,0,6.0883203,0.0,0.24331538,109.66009573551291,6.7130847,331.60507,-9.2970324,109.66009573551291
1988,1988,155.3669,11.745732,3.2897902,0.0,0,6.0427446,0.0,0.24747743,109.6845235197304,6.6660719,331.45395,-9.2963848,109.6845235197304
1990,1990,155.3673,11.798163,3.3401723,0.0,0,5.9971681,0.0,0.2512199,109.65705348169053,6.6154399,331.30283,-9.2967405,109.65705348169053
1992,1992,155.3677,11.849575,3.393203,0.0,0,5.951592,0.0,0.25606057,109.58819519199939,6.5679274,331.1517,-9.2970552,109.58819519199939
1994,1994,155.3681,11.908017,3.4380836,0.0,0,5.9060163,0.0,0.26015446,109.66366702085988,6.5180545,330.9201,-9.2979355,109.66366702085988
1996,1996,155.3685,11.971218,3.4873557,0.0,0,5.8604403,0.0,0.26387125,109.7324169604427,6.4710073,330.68848,-9.2978373,109.7324169604427
1998,1998,155.3689,12.027963,3.5361748,0.0,0,5.8148637,0.0,0.2686972,109.74152931753835,6.4208584,330.45685,-9.2972469,109.74152931753835
2000,2000,155.3693,12.057498,3.5826249,0.0,0,5.7692881,0.0,0.27260715,109.52352056743727,6.3768163,330.22525,-9.2969713,109.52352056743727
2002,2002,155.3697,12.123571,3.6303575,0.0,0,5.723712,0.0,0.27645633,109.61994802990682,6.322999,329.99362,-9.2967339,109.61994802990682
2004,2004,155.3701,12.194649,3.6786392,0.0,0,5.6781363,0.0,0.28125128,109.75004441373257,6.2749882,329.76199,-9.2982655,109.75004441373257
2006,2006,155.3705,12.259513,3.7281468,0.0,0,5.6325603,0.0,0.28513679,109.8053561853198,6.2255478,329.53036,-9.298254,109.8053561853198
2008,2008,155.3709,12.288246,3.7780099,0.0,0,5.5874381,0.0,0.28956971,109.52915018296787,6.1784477,329.29877,-9.2984352,109.52915018296787
2010,2010,155.3713,12.329753,3.8235502,0.0,0,5.5439701,0.0,0.29430139,109.41010941027274,6.1293249,329.06714,-9.2978601,109.41010941027274
2012,2012,155.3717,12.380492,3.8751411,0.0,0,5.5006099,0.0,0.29815498,109.30402839623346,6.0802517,328.83551,-9.2963696,109.30402839623346
2014,2014,155.3721,12.475898,3.9204981,0.0,0,5.4572496,0.0,0.30262655,109.65341527632465,6.0308995,328.60391,-9.2964239,109.65341527632465
2016,2016,155.3725,12.497291,3.9646554,0.0,0,5.4138899,0.0,0.30675304,109.36067847487293,5.9862947,328.37228,-9.2978277,109.36067847487293
2018,2018,155.3729,12.543771,4.0193915,0.0,0,5.3705297,0.0,0.31094864,109.16918229460083,5.936451,328.14066,-9.2987309,109.16918229460083
2020,2020,155.3733,12.581646,4.0623541,0.0,0,5.3271699,0.0,0.31562638,109.02778170768093,5.8873692,327.90906,-9.2984266,109.02778170768093
2022,2022,155.3737,12.66039,4.1069193,0.0,0,5.2838097,0.0,0.31949306,109.21843640910745,5.8422246,327.67743,-9.2978544,109.21843640910745
2024,2024,155.3741,12.742561,4.161695,0.0,0,5.2404499,0.0,0.32398295,109.31894067534799,5.7926111,327.4458,-9.2962065,109.31894067534799
2026,2026,155.3745,12.781321,4.200943,0.0,0,5.1970901,0.0,0.32853666,109.21417800244876,5.7466574,327.2142,-9.2962923,109.21417800244876
2028,2028,155.3749,12.826608,4.248734,0.0,0,5.1537299,0.0,0.33243483,109.06673283000298,5.697464,326.98257,-9.2969265,109.06673283000298
2030,2030,155.3753,12.869964,4.3037214,0.0,0,5.1103697,0.0,0.33741623,108.81834936087812,5.6470981,326.75095,-9.2990398,108.81834936087812
2032,2032,155.3757,12.924994,4.3425379,0.0,0,5.0670099,0.0,0.3417981,108.84614165087324,5.5973034,326.51935,-9.2986774,108.84614165087324
2034,2034,155.3761,12.989186,4.3902125,0.0,0,5.0250454,0.0,0.34546474,108.84665977448785,5.5567646,326.28772,-9.2981234,108.84665977448785
2036,2036,155.3765,13.050587,4.4404826,0.0,0,4.9838009,0.0,0.35066614,108.78895400737144,5.509511,326.05609,-9.2975597,108.78895400737144
2038,2038,155.3769,13.077126,4.48001,0.0,0,4.9425607,0.0,0.35460436,108.55926654181648,5.4644618,325.82449,-9.2967386,108.55926654181648
2040,2040,155.3773,13.125514,4.5285664,0.0,0,4.9013209,0.0,0.35860488,108.40492906216123,5.4167314,325.59286,-9.2969503,108.40492906216123
2042,2042,155.3777,13.189966,4.5733528,0.0,0,4.8600807,0.0,0.36358839,108.42180514596376,5.3744478,325.36124,-9.2977953,108.42180514596376
2044,2044,155.3781,13.272518,4.6145339,0.0,0,4.818841,0.0,0.36734223,108.62341714739564,5.3289876,325.08417,-9.2995071,108.62341714739564
2046,2046,155.3785,13.314768,4.6637015,0.0,0,4.7776008,0.0,0.37160376,108.39784485115541,5.2824316,324.8071,-9.2988205,108.39784485115541
2048,2048,155.3789,13.348535,4.707406,0.0,0,4.7363605,0.0,0.37665322,108.16353039441076,5.2357593,324.53003,-9.2965393,108.16353039441076
2050,2050,155.3793,13.391438,4.7542319,0.0,0,4.6951208,0.0,0.3805075,107.96376819017081,5.1959238,324.25299,-9.296855,107.96376819017081
2052,2052,155.3797,13.478343,4.7994232,0.0,0,4.6538811,0.0,0.38503051,108.132617130505,5.1481643,323.97592,-9.2968254,108.132617130505
2054,2054,155.3801,13.543941,4.8393316,0.0,0,4.6126404,0.0,0.38962057,108.18692435831015,5.1022935,323.69885,-9.2976847,108.18692435831015
2056,2056,155.3805,13.588553,4.8891153,0.0,0,4.5714006,0.0,0.39353016,107.9525135902108,5.0605288,323.42178,-9.298481,107.9525135902108
2058,2058,155.3809,13.608966,4.930398,0.0,0,4.5305729,0.0,0.39821947,107.62399835840014,5.0150046,323.14471,-9.2982731,107.62399835840014
2060,2060,155.3813,13.67022,4.968761,0.0,0,4.4912429,0.0,0.40229025,107.65033128758122,4.9714069,322.86765,-9.2964001,107.65033128758122
2062,2062,155.3817,13.749053,5.0201159,0.0,0,4.4520106,0.0,0.40641052,107.6542967642468,4.9291396,322.59058,-9.2976685,107.6542967642468
2064,2064,155.3821,13.821118,5.0584822,0.0,0,4.4127784,0.0,0.4110631,107.75526661870148,4.8836875,322.31351,-9.2979059,107.75526661870148
2066,2066,155.3825,13.866096,5.1023569,0.0,0,4.3735466,0.0,0.41539916,107.57433666237219,4.8409901,322.03647,-9.2984638,107.57433666237219
2068,2068,155.3829,13.898834,5.1538224,0.0,0,4.3343148,0.0,0.4199498,107.2031951534973,4.7977719,321.7594,-9.2977505,107.2031951534973
2070,2070,155.3833,13.951997,5.1872473,0.0,0,4.295083,0.0,0.42443621,107.20564970162953,4.7571673,321.48233,-9.2973652,107.20564970162953
2072,2072,155.3837,14.045354,5.2309809,0.0,0,4.2558503,0.0,0.42833227,107.38606153633629,4.7121625,321.20526,-9.2981224,107.38606153633629
2074,2074,155.3841,14.101556,5.2786016,0.0,0,4.2166185,0.0,0.43294498,107.22869049960649,4.6676364,320.92819,-9.2970791,107.22869049960649
2076,2076,155.3845,14.133388,5.3114772,0.0,0,4.1773863,0.0,0.43715581,107.06448671652505,4.6275892,320.65112,-9.2972946,107.06448671652505
2078,2078,155.3849,14.18337,5.3574462,0.0,0,4.1381545,0.0,0.44103569,106.87298611322689,4.5843773,320.37405,-9.2980709,106.87298611322689
2080,2080,155.3853,14.241721,5.4031758,0.0,0,4.0989227,0.0,0.44623119,106.74309794112018,4.5426412,320.09698,-9.2976246,106.74309794112018
2082,2082,155.3857,14.32793,5.4404955,0.0,0,4.0596905,0.0,0.45036185,106.92155096710945,4.5041685,319.81992,-9.2981958,106.92155096710945
2084,2084,155.3861,14.385266,5.4848313,0.0,0,4.0217228,0.0,0.4543249,106.79151063769304,4.4583526,319.54288,-9.296998,106.79151063769304
2086,2086,155.3865,14.432204,5.5247645,0.0,0,3.9844062,0.0,0.45938411,106.63575441074725,4.4194226,319.26581,-9.2971964,106.63575441074725
2088,2088,155.3869,14.481903,5.5635777,0.0,0,3.9470942,0.0,0.46314237,106.51115561348048,4.37816,318.98874,-9.2972841,106.51115561348048
2090,2090,155.3873,14.543442,5.605546,0.0,0,3.9097824,0.0,0.46711659,106.42964712474759,4.3382616,318.71167,-9.2978182,106.42964712474759
2092,2092,155.3877,14.609097,5.6441293,0.0,0,3.8724704,0.0,0.47222996,106.41680371282709,4.294981,318.4346,-9.2976675,106.41680371282709
2094,2094,155.3881,14.685023,5.6861873,0.0,0,3.8351583,0.0,0.47587425,106.42927464004349,4.2545886,318.00027,-9.2979031,106.42927464004349
2096,2096,155.3885,14.727638,5.7262268,0.0,0,3.7978463,0.0,0.48024133,106.2219182872238,4.2166786,317.56595,-9.2976694,106.2219182872238
2098,2098,155.3889,14.78191,5.7623215,0.0,0,3.7605343,0.0,0.48478308,106.14623354492083,4.1756096,317.13162,-9.2968636,106.14623354492083
2100,2100,155.3893,14.842999,5.8059607,0.0,0,3.7232223,0.0,0.48858789,106.01774690012675,4.1370287,316.6973,-9.2961521,106.01774690012675
2102,2102,155.3897,14.922889,5.8428197,0.0,0,3.6859105,0.0,0.49315345,106.10669615740046,4.0984688,316.26297,-9.2958441,106.10669615740046
2104,2104,155.3901,15.010238,5.8794551,0.0,0,3.6485984,0.0,0.49745533,106.24616891470025,4.0562763,315.82864,-9.2968817,106.24616891470025
2106,2106,155.3905,15.038777,5.9263902,0.0,0,3.6112862,0.0,0.501544,105.82991637556533,4.0171452,315.39432,-9.2974625,105.82991637556533
2108,2108,155.3909,15.10517,5.9580326,0.0,0,3.5743468,0.0,0.50612354,105.87842914599045,3.9762721,314.95999,-9.2964096,105.87842914599045
2110,2110,155.3913,15.173428,5.995358,0.0,0,3.5387621,0.0,0.50992966,105.86069046290991,3.9383214,314.52567,-9.296608,105.86069046290991
2112,2112,155.3917,15.25142,6.0412517,0.0,0,3.5032659,0.0,0.51432604,105.79151376132276,3.9011183,314.09134,-9.2969093,105.79151376132276
2114,2114,155.3921,15.325754,6.0732589,0.0,0,3.4677699,0.0,0.51914263,105.87726441387892,3.8625238,313.65701,-9.2964125,105.87726441387892
2116,2116,155.3925,15.370165,6.1136017,0.0,0,3.4322741,0.0,0.52291226,105.64062790298031,3.8299265,313.22272,-9.2971144,105.64062790298031
2118,2118,155.3929,15.419878,6.1577716,0.0,0,3.3967779,0.0,0.52770752,105.3853059687234,3.7884169,312.78839,-9.2984896,105.3853059687234
2120,2120,155.3933,15.491633,6.1858478,0.0,0,3.3612819,0.0,0.53182018,105.49441801283054,3.7493529,312.35406,-9.2966318,105.49441801283054
2122,2122,155.3937,15.586467,6.2252755,0.0,0,3.3257859,0.0,0.53526419,105.60143323433813,3.7143803,311.91974,-9.2963333,105.60143323433813
2124,2124,155.3941,15.655581,6.26612,0.0,0,3.2902899,0.0,0.54033846,105.50900647275213,3.6740994,311.48541,-9.2971449,105.50900647275213
2126,2126,155.3945,15.709837,6.2978811,0.0,0,3.2547936,0.0,0.54434228,105.43710136931597,3.638912,311.05109,-9.2969332,105.43710136931597
2128,2128,155.3949,15.765775,6.3385639,0.0,0,3.2192979,0.0,0.54818785,105.25000456702904,3.6026044,310.61676,-9.2969198,105.25000456702904
2130,2130,155.3953,15.84629,6.3742037,0.0,0,3.1838019,0.0,0.55334693,105.29213861182133,3.56494,310.18243,-9.2959833,105.29213861182133
2132,2132,155.3957,15.94173,6.4092727,0.0,0,3.1483059,0.0,0.55697173,105.43586973013868,3.5311031,309.74811,-9.2963486,105.43586973013868
2134,2134,155.3961,16.017891,6.4488854,0.0,0,3.1139472,0.0,0.56119502,105.38290251038441,3.4901545,309.31378,-9.296937,105.38290251038441
2136,2136,155.3965,16.069426,6.4817657,0.0,0,3.0801756,0.0,0.56608886,105.25834383648562,3.4533544,308.87946,-9.2971239,105.25834383648562
2138,2138,155.3969,16.122444,6.5197868,0.0,0,3.0464077,0.0,0.56960458,105.06769816402782,3.4161153,308.44513,-9.2968807,105.06769816402782
2140,2140,155.3973,16.203789,6.5547605,0.0,0,3.0126395,0.0,0.57394522,105.10044743787465,3.3811128,308.0108,-9.2955027,105.10044743787465
2142,2142,155.3977,16.301271,6.5862665,0.0,0,2.9788716,0.0,0.57847553,105.28193864660794,3.3436506,307.57651,-9.2970028,105.28193864660794
2144,2144,155.3981,16.377623,6.6287928,0.0,0,2.9451036,0.0,0.58226758,105.16366359347911,3.3083098,307.30103,-9.2971516,105.16366359347911
2146,2146,155.3985,16.425274,6.66429,0.0,0,2.9113355,0.0,0.58720243,104.95775205972294,3.2738326,307.02554,-9.2961588,104.95775205972294
2148,2148,155.3989,16.497581,6.6962657,0.0,0,2.8775675,0.0,0.59143692,104.95660983211668,3.2399547,306.75006,-9.2959232,104.95660983211668
2150,2150,155.3993,16.592716,6.7395058,0.0,0,2.8437996,0.0,0.59522957,104.93180949004572,3.2036989,306.47458,-9.295475,104.93180949004572
2152,2152,155.3997,16.69058,6.767889,0.0,0,2.8100314,0.0,0.599904,105.13464519640105,3.1705339,306.1991,-9.2965355,105.13464519640105
2154,2154,155.4001,16.765158,6.8014154,0.0,0,2.7762637,0.0,0.60373986,105.1107259453097,3.1355109,305.92365,-9.2964087,105.1107259453097
2156,2156,155.4005,16.808878,6.8472948,0.0,0,2.7424955,0.0,0.60856235,104.70739291870771,3.1018922,305.64816,-9.2964058,104.70739291870771
2158,2158,155.4009,16.885849,6.8746734,0.0,0,2.7090657,0.0,0.61325914,104.78070572106884,3.0665283,305.37268,-9.2960768,104.78070572106884
2160,2160,155.4013,16.991642,6.9085903,0.0,0,2.6768651,0.0,0.6165148,104.93081658024575,3.0306125,305.0972,-9.2959356,104.93081658024575
2162,2162,155.4017,17.104372,6.9471307,0.0,0,2.6447449,0.0,0.62135911,105.04770291531989,2.9956746,304.82172,-9.2943068,105.04770291531989
2164,2164,155.4021,17.167395,6.9723392,0.0,0,2.6126249,0.0,0.6254521,105.05443886013671,2.9591236,304.54623,-9.2953272,105.05443886013671
2166,2166,155.4025,17.230295,7.0129352,0.0,0,2.5805047,0.0,0.6292305,104.82456354366597,2.9255977,304.27075,-9.2966681,104.82456354366597
2168,2168,155.4029,17.326157,7.0530758,0.0,0,2.5483847,0.0,0.63496816,104.79641139144758,2.8939097,303.99527,-9.2970943,104.79641139144758
2170,2170,155.4033,17.433016,7.0817971,0.0,0,2.5162647,0.0,0.63901949,105.00256384774319,2.8576581,303.71979,-9.296174,105.00256384774319
2172,2172,155.4037,17.529129,7.1187038,0.0,0,2.4841447,0.0,0.64262843,105.01266610357621,2.8246307,303.44431,-9.2953548,105.01266610357621
2174,2174,155.4041,17.60216,7.1504731,0.0,0,2.4520247,0.0,0.64773709,104.95845452889034,2.7874002,303.16882,-9.2953329,104.95845452889034
2176,2176,155.4045,17.678362,7.1817589,0.0,0,2.4199049,0.0,0.65130305,104.92644899072519,2.7524939,302.89334,-9.2948503,104.92644899072519
2178,2178,155.4049,17.765678,7.2206759,0.0,0,2.3877847,0.0,0.65564358,104.83661691246812,2.7185409,302.61789,-9.2964363,104.83661691246812
2180,2180,155.4053,17.885233,7.2526937,0.0,0,2.3556647,0.0,0.66098893,105.03841733805174,2.6845045,302.34241,-9.2965736,105.03841733805174
2182,2182,155.4057,17.968718,7.2884126,0.0,0,2.3235447,0.0,0.66455972,104.96410509184184,2.6497791,302.06693,-9.2968531,104.96410509184184
2184,2184,155.4061,18.047918,7.3213539,0.0,0,2.2924569,0.0,0.66900045,104.90369216936512,2.617121,301.79144,-9.2948523,104.90369216936512
2186,2186,155.4065,18.122416,7.3484063,0.0,0,2.2619016,0.0,0.67355061,104.90534611269679,2.5845592,301.51596,-9.2946377,104.90534611269679
2188,2188,155.4069,18.229332,7.388412,0.0,0,2.2313497,0.0,0.67723364,104.88250511252514,2.5525796,301.24048,-9.2954588,104.88250511252514
2190,2190,155.4073,18.330008,7.4188118,0.0,0,2.2007978,0.0,0.68203789,104.97134212360208,2.5203056,300.965,-9.2961779,104.97134212360208
2192,2192,155.4077,18.432295,7.4480963,0.0,0,2.1702456,0.0,0.68626451,105.08202200875294,2.4858804,300.68951,-9.2960701,105.08202200875294
2194,2194,155.4081,18.514029,7.4909267,0.0,0,2.1396937,0.0,0.69061357,104.84997291434318,2.4547772,300.28958,-9.2963467,104.84997291434318
2196,2196,155.4085,18.605297,7.5168843,0.0,0,2.1091418,0.0,0.69548041,104.94168246855048,2.4192307,299.88968,-9.2948313,104.94168246855048
2198,2198,155.4089,18.719515,7.5467963,0.0,0,2.0785899,0.0,0.6990214,105.09293279752275,2.3885169,299.48975,-9.2952385,105.09293279752275
2200,2200,155.4093,18.814568,7.5870142,0.0,0,2.048038,0.0,0.70368528,104.96028793782848,2.3576427,299.08984,-9.2947035,104.96028793782848
2202,2202,155.4097,18.935507,7.611145,0.0,0,2.0174859,0.0,0.70841902,105.23258734033388,2.3198712,298.68994,-9.2953548,105.23258734033388
2204,2204,155.4101,19.017551,7.64502,0.0,0,1.9869336,0.0,0.71196556,105.12117813321468,2.2911017,298.29001,-9.2955627,105.12117813321468
2206,2206,155.4105,19.102942,7.6854706,0.0,0,1.9563816,0.0,0.71726972,104.91256853776807,2.2581074,297.89011,-9.2953138,104.91256853776807
2208,2208,155.4109,19.212151,7.7090054,0.0,0,1.9261349,0.0,0.72169948,105.11404341062384,2.2241518,297.49017,-9.2932806,105.11404341062384
2210,2210,155.4113,19.325563,7.7443953,0.0,0,1.896998,0.0,0.72526616,105.13202693625281,2.1918082,297.09027,-9.2935133,105.13202693625281
2212,2212,155.4117,19.444342,7.7789307,0.0,0,1.867934,0.0,0.73070335,105.18654187858782,2.1631951,296.69037,-9.2944775,105.18654187858782
2214,2214,155.4121,19.527729,7.8034983,0.0,0,1.83887,0.0,0.73444438,105.21490701409157,2.131789,296.29044,-9.295372,105.21490701409157
2216,2216,155.4125,19.632923,7.8381705,0.0,0,1.809806,0.0,0.73812205,105.18182789728748,2.0976231,295.89053,-9.295187,105.18182789728748
2218,2218,155.4129,19.738314,7.8683186,0.0,0,1.7807419,0.0,0.74358541,105.22200975237749,2.0642231,295.4906,-9.2959652,105.22200975237749
2220,2220,155.4133,19.87269,7.8977304,0.0,0,1.751678,0.0,0.7474193,105.42318495433229,2.0358582,295.0907,-9.2936954,105.42318495433229
2222,2222,155.4137,19.990149,7.9346395,0.0,0,1.722614,0.0,0.75193262,105.39592820803229,2.0042696,294.6908,-9.2932186,105.39592820803229
2224,2224,155.4141,20.08918,7.962935,0.0,0,1.69355,0.0,0.75722814,105.41695015651486,1.9753691,294.29086,-9.2946959,105.41695015651486
2226,2226,155.4145,20.189407,7.9951458,0.0,0,1.6644859,0.0,0.7606433,105.36954103065322,1.9413425,293.89096,-9.2952747,105.36954103065322
2228,2228,155.4149,20.299324,8.0251589,0.0,0,1.635422,0.0,0.76508719,105.40601905108267,1.9133888,293.49103,-9.2945213,105.40601905108267
2230,2230,155.4153,20.441814,8.0492182,0.0,0,1.6063581,0.0,0.76967269,105.7122324861297,1.880178,293.09113,-9.2945337,105.7122324861297
2232,2232,155.4157,20.557009,8.0866547,0.0,0,1.577294,0.0,0.77338451,105.62927762105855,1.8561424,292.69122,-9.2945347,105.62927762105855
2234,2234,155.4161,20.659702,8.1155024,0.0,0,1.5491621,0.0,0.778427,105.63132001211622,1.8238074,292.29129,-9.2945786,105.63132001211622
2236,2236,155.4165,20.752239,8.1409597,0.0,0,1.521511,0.0,0.78260922,105.63848511861165,1.7921103,291.89139,-9.2939596,105.63848511861165
2238,2238,155.4169,20.882439,8.1791601,0.0,0,1.493863,0.0,0.78655148,105.59759506773304,1.7632399,291.49146,-9.294322,105.59759506773304
2240,2240,155.4173,21.03602,8.2023535,0.0,0,1.466215,0.0,0.79172099,105.94380618141379,1.7314483,291.09155,-9.294446,105.94380618141379
2242,2242,155.4177,21.16671,8.2313299,0.0,0,1.438567,0.0,0.79545087,106.0608905932949,1.7006516,290.69165,-9.2936506,106.0608905932949
2244,2244,155.4181,21.272938,8.2717657,0.0,0,1.4109191,0.0,0.8003872,105.83420410061115,1.6729062,290.41272,-9.293787,105.83420410061115
2246,2246,155.4185,21.378206,8.2921371,0.0,0,1.3832711,0.0,0.8052063,105.97363008060717,1.6415193,290.13379,-9.2938957,105.97363008060717
2248,2248,155.4189,21.508064,8.3223333,0.0,0,1.355623,0.0,0.80853575,106.04422286057297,1.6142184,289.85483,-9.2947454,106.04422286057297
2250,2250,155.4193,21.659298,8.3563652,0.0,0,1.3279752,0.0,0.81348825,106.13934895017323,1.5837417,289.5759,-9.2947578,106.13934895017323
2252,2252,155.4197,21.789471,8.3758907,0.0,0,1.3003271,0.0,0.81783283,106.40174728284535,1.5554492,289.29697,-9.2937469,106.40174728284535
2254,2254,155.4201,21.892416,8.4107342,0.0,0,1.2726791,0.0,0.82147735,106.23114337002104,1.5244956,289.01804,-9.2926617,106.23114337002104
2256,2256,155.4205,22.019207,8.4442205,0.0,0,1.2450311,0.0,0.82740915,106.19550511138209,1.4962076,288.73911,-9.293375,106.19550511138209
2258,2258,155.4209,22.162525,8.4659081,0.0,0,1.2176605,0.0,0.83121121,106.46238686337577,1.468513,288.46014,-9.2935915,106.46238686337577
2260,2260,155.4213,22.321512,8.4983854,0.0,0,1.1912985,0.0,0.83485949,106.5860903459635,1.4391332,288.18121,-9.2932758,106.5860903459635
2262,2262,155.4217,22.468481,8.5248404,0.0,0,1.1650023,0.0,0.84036463,106.76305820900915,1.4126076,287.90228,-9.2933035,106.76305820900915
2264,2264,155.4221,22.572031,8.5506363,0.0,0,1.1387062,0.0,0.84372669,106.74096396160176,1.3821841,287.62335,-9.2931547,106.74096396160176
2266,2266,155.4225,22.705549,8.5829611,0.0,0,1.1124103,0.0,0.84812546,106.7242450879219,1.3508523,287.34442,-9.2929831,106.7242450879219
2268,2268,155.4229,22.864731,8.6070833,0.0,0,1.0861143,0.0,0.85337138,106.98538408250415,1.3213868,287.06546,-9.2928524,106.98538408250415
2270,2270,155.4233,23.027895,8.6369896,0.0,0,1.0598181,0.0,0.85664248,107.14062464759624,1.2961637,286.78653,-9.2919827,107.14062464759624
2272,2272,155.4237,23.155428,8.6657782,0.0,0,1.0335222,0.0,0.861112,107.14522640607748,1.2658238,286.5076,-9.2929897,107.14522640607748
2274,2274,155.4241,23.275848,8.6876287,0.0,0,1.0072262,0.0,0.86606765,107.25321572163266,1.2400284,286.22867,-9.2931986,107.25321572163266
2276,2276,155.4245,23.413334,8.7223663,0.0,0,0.98093021,0.0,0.86965275,107.16831323232702,1.2081367,285.94974,-9.2924767,107.16831323232702
2278,2278,155.4249,23.570486,8.7465134,0.0,0,0.95463419,0.0,0.8747251,107.3848519326357,1.1840322,285.67078,-9.2922392,107.3848519326357
2280,2280,155.4253,23.729845,8.7703533,0.0,0,0.92833829,0.0,0.87899083,107.61110849952246,1.1545826,285.39185,-9.2923756,107.61110849952246
2282,2282,155.4257,23.867229,8.806879,0.0,0,0.90204227,0.0,0.8830052,107.46393632101731,1.1276503,285.11292,-9.2921581,107.46393632101731
2284,2284,155.4261,23.976702,8.8254747,0.0,0,0.87659407,0.0,0.88777578,107.56291422847208,1.0978361,284.83398,-9.2927113,107.56291422847208
2286,2286,155.4265,24.119539,8.8477573,0.0,0,0.85158336,0.0,0.89092517,107.72883471766046,1.0717119,284.55505,-9.2924614,107.72883471766046
2288,2288,155.4269,24.283419,8.8824644,0.0,0,0.82657528,0.0,0.89536387,107.71608501748018,1.0452111,284.27609,-9.2931108,107.71608501748018
2290,2290,155.4273,24.442581,8.8998137,0.0,0,0.80156738,0.0,0.90007108,108.04737083773539,1.0180435,283.99716,-9.2924604,108.04737083773539
2292,2292,155.4277,24.57321,8.9273386,0.0,0,0.77655935,0.0,0.90346861,108.02710628982304,0.9915939,283.71826,-9.2915545,108.02710628982304
2294,2294,155.4281,24.707636,8.9623289,0.0,0,0.75155133,0.0,0.90903902,107.85404701802327,0.96782172,283.58618,-9.2910452,107.85404701802327
2296,2296,155.4285,24.858929,8.9788246,0.0,0,0.72654337,0.0,0.91330332,108.15206777835577,0.93919921,283.4541,-9.2919016,108.15206777835577
2298,2298,155.4289,25.017996,9.0064697,0.0,0,0.70153534,0.0,0.91619474,108.23284790412087,0.91868311,283.32205,-9.293047,108.23284790412087
2300,2300,155.4293,25.193455,9.0331631,0.0,0,0.67652738,0.0,0.92154515,108.39753507481213,0.89102381,283.18997,-9.2932262,108.39753507481213
2302,2302,155.4297,25.32431,9.0495329,0.0,0,0.65151936,0.0,0.92481834,108.59414027207836,0.86508006,283.05792,-9.2930841,108.59414027207836
2304,2304,155.4301,25.453274,9.0802851,0.0,0,0.62651134,0.0,0.92828751,108.45528677164697,0.83960247,282.92584,-9.2915335,108.45528677164697
2306,2306,155.4305,25.585667,9.1046362,0.0,0,0.60150337,0.0,0.93426299,108.46868116478124,0.81949472,282.79376,-9.2906761,108.46868116478124
2308,2308,155.4309,25.743357,9.1262007,0.0,0,0.57674313,0.0,0.93720943,108.64647202399416,0.79403955,282.66171,-9.2907772,108.64647202399416
2310,2310,155.4313,25.910992,9.1537209,0.0,0,0.5528841,0.0,0.94119722,108.72360233876867,0.76719224,282.52963,-9.2914581,108.72360233876867
2312,2312,155.4317,26.042728,9.1721983,0.0,0,0.52908403,0.0,0.94629371,108.85098312420475,0.74286205,282.39758,-9.2927856,108.85098312420475
2314,2314,155.4321,26.190924,9.1965113,0.0,0,0.50528395,0.0,0.94876903,108.90746350413274,0.72029912,282.2655,-9.2915039,108.90746350413274
2316,2316,155.4325,26.332935,9.2200489,0.0,0,0.48148397,0.0,0.95300549,108.95002462167733,0.69683075,282.13342,-9.2911348,108.95002462167733
2318,2318,155.4329,26.498699,9.2370214,0.0,0,0.45768398,0.0,0.95739937,109.23824558076437,0.67175102,282.00137,-9.2904787,109.23824558076437
2320,2320,155.4333,26.67905,9.2693129,0.0,0,0.43388397,0.0,0.96084535,109.22007120549402,0.64783043,281.86929,-9.2912521,109.22007120549402
2322,2322,155.4337,26.824476,9.2903004,0.0,0,0.41008398,0.0,0.96587169,109.31768599586131,0.62340492,281.73724,-9.2900448,109.31768599586131
2324,2324,155.4341,26.97057,9.3109035,0.0,0,0.38628396,0.0,0.96957213,109.42177207822165,0.60070455,281.60516,-9.2907925,109.42177207822165
2326,2326,155.4345,27.128401,9.3428078,0.0,0,0.36248395,0.0,0.97334939,109.29686696140621,0.57745129,281.47308,-9.2913837,109.29686696140621
2328,2328,155.4349,27.300758,9.3545408,0.0,0,0.33868399,0.0,0.97752255,109.7080586098042,0.553949,281.34103,-9.2913113,109.7080586098042
2329,2329,155.4351,27.393179,9.3722496,0.0,0,0.32678398,0.0,0.9787125,109.65054444169013,0.54212224,281.27499,-9.290761,109.65054444169013