File: examples/hot axisymmetric compression example/data/03 trimmed data/testID_0145.csv
level_0,index,Time(sec),Force(kN),Jaw(mm),PowAngle(deg),Power(W),Pram,PTemp,Strain,Stress(MPa),Stroke(mm),TC1(C),wedge(mm)
2271,2271,195.349,0.16597185,0.024383038,0.0,0,9.0922346,0.0,0.0016659051,2.1878426,10.122318,451.5834,-9.2368612
2273,2273,195.3494,2.3637195,0.059480421,0.0,0,9.0337067,0.0,0.0034653232,25.359081,10.046723,451.71753,-9.2375975
2275,2275,195.3498,4.9518552,0.12452741,0.0,0,8.9751787,0.0,0.0082457056,60.763412,9.9910955,451.85168,-9.2355833
2277,2277,195.3502,5.389008,0.18361937,0.0,0,8.9166508,0.0,0.011569147,67.494965,9.9173794,451.98581,-9.2329273
2279,2279,195.3506,5.3455672,0.34173158,0.0,0,8.8581219,0.0,0.021779224,67.180275,9.8246384,452.11996,-9.2319908
2281,2281,195.351,5.151897,0.43700182,0.0,0,8.7995939,0.0,0.029484421,63.172665,9.7210979,452.25409,-9.2322378
2283,2283,195.3514,5.5246887,0.52939463,0.0,0,8.7416534,0.0,0.034810513,68.084885,9.6148663,452.38824,-9.2342653
2285,2285,195.3518,5.8732724,0.63445354,0.0,0,8.6858492,0.0,0.042896282,70.51429,9.5224094,452.5224,-9.2326937
2287,2287,195.3522,5.913835,0.63418633,0.0,0,8.6301851,0.0,0.043281242,73.085823,9.4380417,452.65652,-9.230279
2289,2289,195.3526,5.2686806,0.730739,0.0,0,8.574522,0.0,0.048774678,63.738071,9.3685808,452.84454,-9.2318087
2291,2291,195.353,6.0136509,0.79722118,0.0,0,8.518857,0.0,0.054516323,71.898605,9.3018723,453.05054,-9.2328558
2293,2293,195.3534,6.0904889,0.83787644,0.0,0,8.4631929,0.0,0.056933012,73.118225,9.2302113,453.2565,-9.2310877
2295,2295,195.3538,6.1510687,0.96223813,0.0,0,8.4075298,0.0,0.065199934,73.624016,9.1520691,453.46246,-9.2312069
2297,2297,195.3542,5.7540426,1.0272511,0.0,0,8.3518648,0.0,0.070771918,68.508553,9.0679893,453.66846,-9.2309885
2299,2299,195.3546,5.9792228,1.1094691,0.0,0,8.2962017,0.0,0.076091856,70.223091,8.9883957,453.87442,-9.2327385
2301,2301,195.355,5.9779768,1.1738133,0.0,0,8.2405376,0.0,0.081049062,70.209358,8.9115667,454.08041,-9.2317953
2303,2303,195.3554,6.1156526,1.2111586,0.0,0,8.1848736,0.0,0.084013216,71.397247,8.8471346,454.28638,-9.2320585
2305,2305,195.3558,5.9302039,1.2871561,0.0,0,8.1292095,0.0,0.089008875,69.426819,8.7845955,454.49237,-9.2312469
2307,2307,195.3562,6.0953321,1.3355892,0.0,0,8.0735455,0.0,0.092957616,70.207016,8.7273283,454.69833,-9.2319832
2309,2309,195.3566,6.4014416,1.3938653,0.0,0,8.0196619,0.0,0.097146869,74.021812,8.6701937,454.90433,-9.2321568
2311,2311,195.357,6.1884971,1.4807926,0.0,0,7.9666953,0.0,0.10314348,71.324211,8.6042185,455.11029,-9.231493
2313,2313,195.3574,6.1196918,1.5484067,0.0,0,7.9137359,0.0,0.10866673,69.85405,8.5371313,455.31625,-9.2319593
2315,2315,195.3578,6.1219468,1.6095254,0.0,0,7.8607755,0.0,0.11319141,69.46199,8.4720278,455.52225,-9.23246
2317,2317,195.3582,6.2660651,1.6508906,0.0,0,7.8078156,0.0,0.11616388,70.864937,8.4141483,455.72821,-9.2317896
2319,2319,195.3586,6.2657237,1.6918641,0.0,0,7.7548552,0.0,0.11952503,70.932785,8.358036,455.9342,-9.2318525
2321,2321,195.359,6.095284,1.7554625,0.0,0,7.7018952,0.0,0.12389287,68.687386,8.305459,456.14017,-9.2316427
2323,2323,195.3594,6.2767906,1.7966264,0.0,0,7.6489348,0.0,0.12719543,70.025772,8.2581482,456.34616,-9.2313623
2325,2325,195.3598,6.4678369,1.8414757,0.0,0,7.5959754,0.0,0.13088736,72.17852,8.2052946,456.55212,-9.2322464
2327,2327,195.3602,6.3949533,1.9110947,0.0,0,7.543015,0.0,0.13551089,71.140938,8.1494656,456.75812,-9.2322512
2329,2329,195.3606,6.3580136,1.963541,0.0,0,7.4900556,0.0,0.13988698,70.474434,8.0952482,456.96408,-9.231636
2331,2331,195.361,6.2555161,2.0175912,0.0,0,7.4370952,0.0,0.14432472,68.948746,8.0367126,457.17004,-9.2312794
2333,2333,195.3614,6.4214025,2.0642259,0.0,0,7.3846664,0.0,0.14741339,70.273438,7.9801989,457.37604,-9.2315388
2335,2335,195.3618,6.454627,2.1079748,0.0,0,7.3341722,0.0,0.15111069,70.72699,7.9331307,457.582,-9.2312689
2337,2337,195.3622,6.368865,2.158417,0.0,0,7.2838039,0.0,0.15511839,69.454498,7.8859382,457.78799,-9.232749
2339,2339,195.3626,6.4256587,2.2027035,0.0,0,7.2334356,0.0,0.15813974,69.699387,7.8373051,457.66342,-9.2324791
2341,2341,195.363,6.5379829,2.2488422,0.0,0,7.1830673,0.0,0.16217037,70.654243,7.7863398,457.42865,-9.2313061
2343,2343,195.3634,6.5666099,2.3002632,0.0,0,7.1326995,0.0,0.16600016,70.894714,7.7392635,457.19391,-9.2318163
2345,2345,195.3638,6.5224228,2.3589208,0.0,0,7.0823312,0.0,0.17039791,70.08432,7.6886964,456.95917,-9.2312641
2347,2347,195.3642,6.5071244,2.4025223,0.0,0,7.0319633,0.0,0.17450239,69.523346,7.6397071,456.72443,-9.2309809
2349,2349,195.3646,6.564116,2.4424536,0.0,0,6.981595,0.0,0.17722715,69.994743,7.58922,456.48969,-9.2324219
2351,2351,195.365,6.6112394,2.4965427,0.0,0,6.9312277,0.0,0.1815072,70.273743,7.543592,456.25491,-9.2321987
2353,2353,195.3654,6.553236,2.537657,0.0,0,6.8808594,0.0,0.1853389,69.41684,7.5004334,456.02017,-9.2321749
2355,2355,195.3658,6.6367278,2.5787463,0.0,0,6.830492,0.0,0.18804449,69.933525,7.4515533,455.78543,-9.2313662
2357,2357,195.3662,6.7254114,2.6300077,0.0,0,6.7801232,0.0,0.192471,70.695068,7.4071889,455.55069,-9.2318363
2359,2359,195.3666,6.6943498,2.672595,0.0,0,6.7313671,0.0,0.19596504,70.122032,7.3654175,455.31592,-9.2322254
2361,2361,195.367,6.689363,2.724745,0.0,0,6.6834416,0.0,0.19976407,69.668442,7.3134656,455.08118,-9.2328348
2363,2363,195.3674,6.6928792,2.7706337,0.0,0,6.6355219,0.0,0.2041119,69.402657,7.2637515,454.84644,-9.2327547
2365,2365,195.3678,6.7890821,2.8113837,0.0,0,6.5876017,0.0,0.20719324,70.194817,7.2181683,454.61169,-9.2327871
2367,2367,195.3682,6.8129082,2.8624029,0.0,0,6.5396819,0.0,0.21112825,70.223587,7.1695704,454.37692,-9.2317905
2369,2369,195.3686,6.7667537,2.9032006,0.0,0,6.4917622,0.0,0.21511261,69.515152,7.125649,454.14218,-9.2316809
2371,2371,195.369,6.8260198,2.9496219,0.0,0,6.4438419,0.0,0.21839882,69.781738,7.076458,453.90744,-9.231905
2373,2373,195.3694,6.9016695,2.9992611,0.0,0,6.3959212,0.0,0.22261776,70.389053,7.0279059,453.6727,-9.2333059
2375,2375,195.3698,6.933486,3.0422239,0.0,0,6.3480015,0.0,0.22666016,70.414894,6.981822,453.43793,-9.2329979
2377,2377,195.3702,6.9370165,3.1000566,0.0,0,6.3000817,0.0,0.23075855,70.130569,6.9324279,453.20319,-9.2320299
2379,2379,195.3706,6.9180846,3.1428239,0.0,0,6.252162,0.0,0.23489659,69.6362,6.8879619,452.96844,-9.2317429
2381,2381,195.371,6.9757323,3.1840925,0.0,0,6.2042422,0.0,0.23847064,69.870789,6.8365784,452.7337,-9.2322378
2383,2383,195.3714,7.0282969,3.2399406,0.0,0,6.1568027,0.0,0.24246094,70.155945,6.7888432,452.49893,-9.2331648
2385,2385,195.3718,7.0481253,3.2806482,0.0,0,6.1111121,0.0,0.24660167,70.092262,6.7420073,452.26419,-9.2325077
2387,2387,195.3722,7.07441,3.3278232,0.0,0,6.065536,0.0,0.25051245,70.099174,6.6935606,452.02945,-9.2326708
2389,2389,195.3726,7.1118093,3.3856757,0.0,0,6.0199599,0.0,0.25502914,70.143593,6.6418686,451.79114,-9.2324038
2391,2391,195.373,7.1229339,3.4257734,0.0,0,5.9743834,0.0,0.25923017,69.918724,6.5937958,451.55161,-9.2324238
2393,2393,195.3734,7.1587715,3.4738626,0.0,0,5.9288077,0.0,0.26288095,69.990608,6.5483727,451.3121,-9.2321529
2395,2395,195.3738,7.208149,3.5290463,0.0,0,5.8832321,0.0,0.26758361,70.116302,6.4997382,451.0726,-9.2327099
2397,2397,195.3742,7.2335057,3.5701473,0.0,0,5.8376555,0.0,0.27166542,70.098846,6.448719,450.83307,-9.2327557
2399,2399,195.3746,7.2505193,3.6222036,0.0,0,5.792079,0.0,0.27570572,70.043808,6.4026394,450.59357,-9.2331638
2401,2401,195.375,7.2579007,3.6734529,0.0,0,5.7465038,0.0,0.28038996,69.818893,6.3533635,450.35406,-9.233285
2403,2403,195.3754,7.3104496,3.7176857,0.0,0,5.7009277,0.0,0.28462765,69.930359,6.3022933,450.11453,-9.231514
2405,2405,195.3758,7.3710766,3.7692225,0.0,0,5.6553516,0.0,0.28862068,70.277435,6.2534118,449.87503,-9.2312689
2407,2407,195.3762,7.3892441,3.8183684,0.0,0,5.6097755,0.0,0.2936357,70.12825,6.2033114,449.63553,-9.2302504
2409,2409,195.3766,7.3838897,3.8660853,0.0,0,5.5656581,0.0,0.29772636,69.839317,6.1550031,449.396,-9.2333279
2411,2411,195.377,7.4055161,3.9172835,0.0,0,5.5222936,0.0,0.30194142,69.690514,6.1065269,449.15649,-9.2334118
2413,2413,195.3774,7.4873805,3.9629557,0.0,0,5.4789333,0.0,0.3067821,70.06337,6.057075,448.91699,-9.2333612
2415,2415,195.3778,7.534699,4.0124612,0.0,0,5.4355736,0.0,0.31067771,70.369995,6.0085392,448.67749,-9.2319393
2417,2417,195.3782,7.5305939,4.0623183,0.0,0,5.3922133,0.0,0.31523359,69.969086,5.9563355,448.43796,-9.2320042
2419,2419,195.3786,7.5341473,4.1100802,0.0,0,5.3488536,0.0,0.32023183,69.600304,5.9062209,448.19846,-9.2321434
2421,2421,195.379,7.5822353,4.1628299,0.0,0,5.3054934,0.0,0.32426247,69.745361,5.8604655,447.95895,-9.2313786
2423,2423,195.3794,7.6443062,4.2079039,0.0,0,5.2621331,0.0,0.32879695,69.963585,5.8055906,447.71942,-9.2328072
2425,2425,195.3798,7.6762543,4.2536521,0.0,0,5.2187734,0.0,0.33345807,69.964249,5.7591906,447.47992,-9.2333679
2427,2427,195.3802,7.6688495,4.3109751,0.0,0,5.1754136,0.0,0.33797839,69.650749,5.7111845,447.24042,-9.2328615
2429,2429,195.3806,7.6929464,4.3549886,0.0,0,5.1320534,0.0,0.34266862,69.471809,5.6611133,447.00089,-9.231739
2431,2431,195.381,7.7383375,4.3989019,0.0,0,5.0886931,0.0,0.34681237,69.588646,5.6127949,446.76138,-9.2318516
2433,2433,195.3814,7.7986321,4.4523244,0.0,0,5.0457683,0.0,0.35106885,69.891624,5.5664444,446.52188,-9.2322273
2435,2435,195.3818,7.8025999,4.4927979,0.0,0,5.0044241,0.0,0.3558898,69.574471,5.5193553,446.28235,-9.232975
2437,2437,195.3822,7.8240614,4.5406027,0.0,0,4.9631839,0.0,0.36010233,69.528976,5.4708419,446.04285,-9.2331972
2439,2439,195.3826,7.8424997,4.5971484,0.0,0,4.9219441,0.0,0.36506563,69.228302,5.4240704,445.96051,-9.2321758
2441,2441,195.383,7.8852415,4.6362453,0.0,0,4.8807039,0.0,0.36972049,69.25264,5.3764362,445.93054,-9.2313423
2443,2443,195.3834,7.9378462,4.6847343,0.0,0,4.8394642,0.0,0.3737922,69.51017,5.3283134,445.90057,-9.2317791
2445,2445,195.3838,7.9512458,4.736238,0.0,0,4.798224,0.0,0.37888846,69.346779,5.2841415,445.87064,-9.2327366
2447,2447,195.3842,7.9863205,4.7744436,0.0,0,4.7569842,0.0,0.38310474,69.378143,5.2366614,445.84067,-9.2328615
2449,2449,195.3846,7.9855404,4.8247342,0.0,0,4.715744,0.0,0.38725176,69.015121,5.1921034,445.8107,-9.2339249
2451,2451,195.385,8.0257692,4.8727779,0.0,0,4.6745043,0.0,0.39251101,68.968788,5.1439362,445.78076,-9.2318268
2453,2453,195.3854,8.0682583,4.9131126,0.0,0,4.6332641,0.0,0.39655912,69.127289,5.0955639,445.75079,-9.2319012
2455,2455,195.3858,8.0952215,4.9605165,0.0,0,4.5920238,0.0,0.40074322,69.027702,5.0532374,445.72083,-9.2316561
2457,2457,195.3862,8.0909662,5.0068631,0.0,0,4.5507841,0.0,0.40614516,68.610168,5.0097079,445.69089,-9.231698
2459,2459,195.3866,8.1111221,5.049705,0.0,0,4.5108657,0.0,0.41004452,68.511482,4.962091,445.66092,-9.2330818
2461,2461,195.387,8.1481638,5.0939274,0.0,0,4.4716296,0.0,0.41428366,68.508553,4.9194093,445.63095,-9.2318735
2463,2463,195.3874,8.2121515,5.1329017,0.0,0,4.4323978,0.0,0.41891372,68.698242,4.874568,445.60101,-9.2327337
2465,2465,195.3878,8.2175951,5.1774302,0.0,0,4.3931656,0.0,0.42272633,68.569084,4.833055,445.57104,-9.2312841
2467,2467,195.3882,8.2223501,5.2231979,0.0,0,4.3539338,0.0,0.42746502,68.240112,4.7897711,445.54108,-9.2316074
2469,2469,195.3886,8.2542257,5.2619815,0.0,0,4.314702,0.0,0.43214333,68.202217,4.7474804,445.51114,-9.2314053
2471,2471,195.389,8.2974958,5.3101277,0.0,0,4.2754698,0.0,0.43602118,68.262306,4.7031913,445.48117,-9.2318172
2473,2473,195.3894,8.3480949,5.3475828,0.0,0,4.2362375,0.0,0.44047481,68.33065,4.6614199,445.4512,-9.2327471
2475,2475,195.3898,8.3517103,5.3832011,0.0,0,4.1970053,0.0,0.44456202,68.171417,4.6211534,445.42123,-9.2326059
2477,2477,195.3902,8.372324,5.432951,0.0,0,4.1577735,0.0,0.44859341,68.059814,4.5813155,445.3913,-9.2323151
2479,2479,195.3906,8.3984079,5.4691262,0.0,0,4.1185417,0.0,0.45332953,67.907677,4.5375261,445.36133,-9.2316017
2481,2481,195.391,8.4414253,5.5092406,0.0,0,4.0793095,0.0,0.45735514,68.016495,4.497787,445.33136,-9.2307177
2483,2483,195.3914,8.4827042,5.5578675,0.0,0,4.0404716,0.0,0.46181527,68.062248,4.4594579,445.30142,-9.2316885
2485,2485,195.3918,8.5261259,5.5891523,0.0,0,4.0030656,0.0,0.4663204,68.120224,4.4148493,445.27145,-9.2326403
2487,2487,195.3922,8.5307827,5.6283388,0.0,0,3.9657533,0.0,0.46981779,67.92778,4.3779793,445.24149,-9.2342052
2489,2489,195.3926,8.5436449,5.6750183,0.0,0,3.9284413,0.0,0.47454542,67.709763,4.3385863,444.92459,-9.2318811
2491,2491,195.393,8.593194,5.7080512,0.0,0,3.8911293,0.0,0.47893667,67.731468,4.2993565,444.51205,-9.2315912
2493,2493,195.3934,8.6403704,5.7498565,0.0,0,3.8538175,0.0,0.48255104,67.908501,4.2592506,444.09952,-9.2313776
2495,2495,195.3938,8.6642179,5.7935114,0.0,0,3.8165054,0.0,0.48771602,67.726784,4.2208109,443.68695,-9.2326965
2497,2497,195.3942,8.6785469,5.8248029,0.0,0,3.7791932,0.0,0.49151394,67.559532,4.1838584,443.27441,-9.2329531
2499,2499,195.3946,8.7096062,5.8663669,0.0,0,3.7418811,0.0,0.49520236,67.504173,4.1455297,442.86188,-9.2330246
2501,2501,195.395,8.7658539,5.9065409,0.0,0,3.7045693,0.0,0.50036865,67.613503,4.1037335,442.44931,-9.2320843
2503,2503,195.3954,8.8237982,5.9403558,0.0,0,3.6672573,0.0,0.50391543,67.861572,4.0650587,442.03677,-9.2315044
2505,2505,195.3958,8.8369551,5.9834366,0.0,0,3.6299453,0.0,0.50812709,67.689255,4.0262728,441.62424,-9.2312593
2507,2507,195.3962,8.8527946,6.0201793,0.0,0,3.5926332,0.0,0.51321596,67.465843,3.9853339,441.2117,-9.2309561
2509,2509,195.3966,8.8878918,6.0583968,0.0,0,3.5565166,0.0,0.51673597,67.414497,3.9480047,440.79913,-9.232666
2511,2511,195.397,8.9403095,6.0984192,0.0,0,3.5210168,0.0,0.52111608,67.544685,3.9103341,440.3866,-9.2321281
2513,2513,195.3974,9.0048494,6.1303282,0.0,0,3.4855206,0.0,0.52567869,67.715012,3.8733284,439.97406,-9.2320137
2515,2515,195.3978,9.0146923,6.1722932,0.0,0,3.4500248,0.0,0.52928531,67.589874,3.8330462,439.56152,-9.2323742
2517,2517,195.3982,9.0278454,6.2100019,0.0,0,3.4145288,0.0,0.53398478,67.371651,3.7994461,439.14896,-9.2313652
2519,2519,195.3986,9.0749435,6.2422805,0.0,0,3.3790326,0.0,0.53829855,67.411606,3.7636282,438.73642,-9.230957
2521,2521,195.399,9.1428003,6.2873063,0.0,0,3.3435369,0.0,0.54218251,67.630882,3.7223771,438.32388,-9.2321415
2523,2523,195.3994,9.1966324,6.3183498,0.0,0,3.3080409,0.0,0.54666567,67.738823,3.6848962,437.91132,-9.2324486
2525,2525,195.3998,9.2016926,6.3531103,0.0,0,3.2725446,0.0,0.55065793,67.532021,3.6498535,437.49878,-9.2316637
2527,2527,195.4002,9.2297077,6.4009185,0.0,0,3.2370486,0.0,0.55509424,67.446297,3.6116059,437.08624,-9.2309532
2529,2529,195.4006,9.2794285,6.4314008,0.0,0,3.2015526,0.0,0.55990469,67.453186,3.5767777,436.67371,-9.2315292
2531,2531,195.401,9.3462276,6.4681797,0.0,0,3.1660566,0.0,0.56369698,67.715202,3.5394843,436.26114,-9.2308121
2533,2533,195.4014,9.3942556,6.5132451,0.0,0,3.1309152,0.0,0.56857491,67.687813,3.5032296,435.8486,-9.2314224
2535,2535,195.4018,9.4092607,6.5408506,0.0,0,3.0970623,0.0,0.57291228,67.502525,3.4661422,435.43607,-9.2320395
2537,2537,195.4022,9.4317064,6.5770431,0.0,0,3.0632944,0.0,0.57638806,67.497101,3.4306178,435.0235,-9.2312632
2539,2539,195.4026,9.4880857,6.6200995,0.0,0,3.0295265,0.0,0.58146626,67.485535,3.3909984,434.71704,-9.2310724
2541,2541,195.403,9.5497513,6.6473656,0.0,0,2.9957583,0.0,0.58555937,67.691513,3.3575015,434.44595,-9.2304182
2543,2543,195.4034,9.595953,6.687933,0.0,0,2.9619906,0.0,0.58936864,67.729591,3.3178778,434.17487,-9.2302036
2545,2545,195.4038,9.6335192,6.7273412,0.0,0,2.9282222,0.0,0.59485102,67.668533,3.2827888,433.90375,-9.231226
2547,2547,195.4042,9.6567192,6.758965,0.0,0,2.8944542,0.0,0.59876102,67.53521,3.2480714,433.63266,-9.2322178
2549,2549,195.4046,9.718565,6.797956,0.0,0,2.8606863,0.0,0.60275143,67.684273,3.2113771,433.36154,-9.2312641
2551,2551,195.405,9.7902632,6.8320184,0.0,0,2.8269184,0.0,0.60797662,67.814278,3.1766903,433.09045,-9.2305593
2553,2553,195.4054,9.8322001,6.8647709,0.0,0,2.7931502,0.0,0.61147588,67.863968,3.1423211,432.81937,-9.2304945
2555,2555,195.4058,9.8637486,6.9042716,0.0,0,2.7593822,0.0,0.61574131,67.809158,3.1061649,432.54825,-9.2309408
2557,2557,195.4062,9.9057636,6.9381294,0.0,0,2.7256143,0.0,0.621185,67.67524,3.0724909,432.27716,-9.2313833
2559,2559,195.4066,9.9471359,6.9758501,0.0,0,2.6929309,0.0,0.62478989,67.756172,3.0385637,432.00604,-9.2317543
2561,2561,195.407,10.03002,7.0114422,0.0,0,2.6608074,0.0,0.62940884,67.950775,3.0017323,431.73495,-9.2305479
2563,2563,195.4074,10.070148,7.0413022,0.0,0,2.6286874,0.0,0.63400733,67.931946,2.9660239,431.46387,-9.2309437
2565,2565,195.4078,10.088629,7.0825062,0.0,0,2.5965672,0.0,0.63794196,67.882355,2.9318924,431.19275,-9.2312717
2567,2567,195.4082,10.12858,7.1142826,0.0,0,2.5644474,0.0,0.64268196,67.839615,2.8981354,430.92166,-9.2310886
2569,2569,195.4086,10.184989,7.1452546,0.0,0,2.5323272,0.0,0.64693826,67.900208,2.861582,430.65054,-9.2306509
2571,2571,195.409,10.249131,7.1889124,0.0,0,2.5002072,0.0,0.65119714,68.009209,2.8277123,430.37946,-9.2296124
2573,2573,195.4094,10.303197,7.2164197,0.0,0,2.4680872,0.0,0.65604639,68.077225,2.7939894,430.10837,-9.229537
2575,2575,195.4098,10.339851,7.2479625,0.0,0,2.4359674,0.0,0.65972799,67.97728,2.7579279,429.83725,-9.2301502
2577,2577,195.4102,10.375829,7.289957,0.0,0,2.4038472,0.0,0.66422403,67.97123,2.7230952,429.56616,-9.2312841
2579,2579,195.4106,10.436361,7.3142543,0.0,0,2.3717272,0.0,0.6688621,68.03299,2.69103,429.29504,-9.231081
2581,2581,195.411,10.510854,7.3484597,0.0,0,2.3396072,0.0,0.6725117,68.283638,2.6570418,429.02396,-9.2312202
2583,2583,195.4114,10.572346,7.3923554,0.0,0,2.3078089,0.0,0.67795765,68.314598,2.6239438,428.75287,-9.230051
2585,2585,195.4118,10.603814,7.4187918,0.0,0,2.2771804,0.0,0.68261838,68.184563,2.5900059,428.48175,-9.2294216
2587,2587,195.4122,10.629955,7.4553537,0.0,0,2.246628,0.0,0.68635386,68.11512,2.5585849,428.21066,-9.2293053
2589,2589,195.4126,10.708163,7.4924145,0.0,0,2.2160764,0.0,0.69168794,68.241936,2.5251343,427.79654,-9.2299395
2591,2591,195.413,10.787343,7.5150461,0.0,0,2.1855242,0.0,0.69530493,68.483215,2.4925663,427.33478,-9.2307539
2593,2593,195.4134,10.84094,7.5501909,0.0,0,2.1549723,0.0,0.69869632,68.575409,2.457298,426.87299,-9.2320147
2595,2595,195.4138,10.87206,7.5836,0.0,0,2.1244202,0.0,0.70430517,68.424171,2.4260571,426.41122,-9.2305422
2597,2597,195.4142,10.90864,7.6137052,0.0,0,2.0938683,0.0,0.70815748,68.42218,2.3909905,425.94943,-9.2291441
2599,2599,195.4146,10.993791,7.6512394,0.0,0,2.0633163,0.0,0.71249199,68.578903,2.361896,425.48767,-9.229701
2601,2601,195.415,11.075599,7.6829209,0.0,0,2.0327644,0.0,0.71812826,68.743393,2.3252215,425.02588,-9.2303667
2603,2603,195.4154,11.120255,7.7157326,0.0,0,2.0022123,0.0,0.72170699,68.802742,2.2958081,424.56412,-9.2309656
2605,2605,195.4158,11.166894,7.7476602,0.0,0,1.9716601,0.0,0.72586906,68.731995,2.2637703,424.10233,-9.2307549
2607,2607,195.4162,11.216227,7.7736979,0.0,0,1.9411081,0.0,0.7307018,68.691994,2.2309449,423.64056,-9.2301769
2609,2609,195.4166,11.299296,7.8099194,0.0,0,1.9115355,0.0,0.73424256,68.974991,2.2016289,423.17877,-9.2297049
2611,2611,195.417,11.390156,7.8418746,0.0,0,1.8824685,0.0,0.73929077,69.188828,2.1657488,422.71698,-9.2303715
2613,2613,195.4174,11.439127,7.8705444,0.0,0,1.8534043,0.0,0.74411869,69.203865,2.1336131,422.25522,-9.2320423
2615,2615,195.4178,11.472992,7.9100761,0.0,0,1.8243403,0.0,0.74814415,69.118294,2.1054897,421.79343,-9.2306566
2617,2617,195.4182,11.521163,7.9350867,0.0,0,1.7952764,0.0,0.75281209,69.072014,2.0742159,421.33167,-9.229558
2619,2619,195.4186,11.609316,7.96139,0.0,0,1.7662123,0.0,0.75646925,69.308929,2.0467649,420.86987,-9.229723
2621,2621,195.419,11.695812,8.0021896,0.0,0,1.7371484,0.0,0.76108843,69.571556,2.0118914,420.40811,-9.2297125
2623,2623,195.4194,11.739811,8.0284567,0.0,0,1.7080843,0.0,0.76640487,69.45047,1.981207,419.94632,-9.2299747
2625,2625,195.4198,11.777314,8.0591116,0.0,0,1.6790204,0.0,0.77020109,69.425278,1.9523805,419.48456,-9.2301884
2627,2627,195.4202,11.844139,8.0966625,0.0,0,1.6499563,0.0,0.77489316,69.455093,1.9223403,419.02277,-9.2301941
2629,2629,195.4206,11.951365,8.116312,0.0,0,1.6208923,0.0,0.77925819,69.724281,1.891975,418.561,-9.2285051
2631,2631,195.421,12.035185,8.147521,0.0,0,1.5918283,0.0,0.78261238,69.998962,1.8590711,418.09921,-9.2288065
2633,2633,195.4214,12.080694,8.1843405,0.0,0,1.5630548,0.0,0.78811783,69.924126,1.8279386,417.63745,-9.2305374
2635,2635,195.4218,12.141011,8.2086105,0.0,0,1.5353373,0.0,0.79258072,69.92025,1.7983518,417.17566,-9.229497
2637,2637,195.4222,12.210181,8.2451658,0.0,0,1.5076892,0.0,0.79660243,70.036171,1.7685246,416.7139,-9.2291241
2639,2639,195.4226,12.306054,8.276576,0.0,0,1.4800413,0.0,0.80220991,70.170341,1.7358805,416.27118,-9.2289515
2641,2641,195.423,12.388738,8.3002968,0.0,0,1.4523933,0.0,0.80600172,70.375809,1.7059704,415.83481,-9.2291546
2643,2643,195.4234,12.434714,8.3344383,0.0,0,1.4247453,0.0,0.80995417,70.37291,1.6761962,415.39844,-9.2296953
2645,2645,195.4238,12.498471,8.3631334,0.0,0,1.3970973,0.0,0.81561971,70.353813,1.6476198,414.9621,-9.2295609
2647,2647,195.4242,12.575627,8.3887272,0.0,0,1.3694494,0.0,0.81887472,70.553368,1.617431,414.52573,-9.2295389
2649,2649,195.4246,12.666612,8.4209681,0.0,0,1.3418013,0.0,0.82319194,70.775513,1.5901123,414.08936,-9.2282572
2651,2651,195.425,12.743983,8.4482298,0.0,0,1.3141534,0.0,0.82875919,70.786583,1.5600964,413.65298,-9.2288275
2653,2653,195.4254,12.798708,8.4812441,0.0,0,1.2865053,0.0,0.83248979,70.855019,1.529525,413.21664,-9.2295036
2655,2655,195.4258,12.875991,8.5127029,0.0,0,1.2588574,0.0,0.83743554,70.893127,1.500689,412.78027,-9.2306919
2657,2657,195.4262,12.94876,8.5370483,0.0,0,1.2312094,0.0,0.84250718,70.986374,1.4719197,412.3439,-9.2298479
2659,2659,195.4266,13.044004,8.5697327,0.0,0,1.2044513,0.0,0.84593529,71.187378,1.4449505,411.90756,-9.2282257
2661,2661,195.427,13.125267,8.5934296,0.0,0,1.1781524,0.0,0.85060805,71.352928,1.414969,411.47119,-9.2281895
2663,2663,195.4274,13.176652,8.6177921,0.0,0,1.1518564,0.0,0.85483867,71.319611,1.3878624,411.03482,-9.2288942
2665,2665,195.4278,13.245081,8.6558027,0.0,0,1.1255604,0.0,0.85888046,71.396118,1.3577015,410.59845,-9.2289753
2667,2667,195.4282,13.321759,8.678009,0.0,0,1.0992644,0.0,0.86404651,71.43911,1.3298881,410.16211,-9.2284908
2669,2669,195.4286,13.425488,8.7047195,0.0,0,1.0729684,0.0,0.86801946,71.704369,1.301245,409.72574,-9.2286758
2671,2671,195.429,13.505756,8.7424202,0.0,0,1.0466723,0.0,0.87287772,71.823647,1.2734509,409.28937,-9.2287836
2673,2673,195.4294,13.581347,8.7614937,0.0,0,1.0203763,0.0,0.87763661,71.853226,1.2456498,408.85303,-9.2294655
2675,2675,195.4298,13.650677,8.7889853,0.0,0,0.99408036,0.0,0.88095391,71.968819,1.2165254,408.41666,-9.2284241
2677,2677,195.4302,13.748824,8.8215141,0.0,0,0.96778435,0.0,0.88598776,72.122742,1.1870891,407.98029,-9.2284279
2679,2679,195.4306,13.854035,8.8388548,0.0,0,0.94148839,0.0,0.89023292,72.348976,1.1612256,407.54391,-9.2289228
2681,2681,195.431,13.951651,8.8686209,0.0,0,0.91519243,0.0,0.89342588,72.629074,1.131902,407.10757,-9.2290325
2683,2683,195.4314,14.011188,8.9037361,0.0,0,0.88916051,0.0,0.89989138,72.520004,1.1017735,406.6712,-9.2286663
2685,2685,195.4318,14.073849,8.9250116,0.0,0,0.86408949,0.0,0.90413857,72.54187,1.0761877,406.23483,-9.2291861
2687,2687,195.4322,14.160179,8.955142,0.0,0,0.83908135,0.0,0.90757227,72.683151,1.0471699,405.79849,-9.228013
2689,2689,195.4326,14.267135,8.9816265,0.0,0,0.81407332,0.0,0.91338187,72.808731,1.0219759,406.08792,-9.2279272
2691,2691,195.433,14.364684,9.0025511,0.0,0,0.78906536,0.0,0.91660815,73.059219,0.99511474,406.61932,-9.2278957
2693,2693,195.4334,14.435548,9.0322342,0.0,0,0.7640574,0.0,0.92048544,73.148849,0.9668653,407.1507,-9.2285919
2695,2695,195.4338,14.515427,9.0569782,0.0,0,0.73904938,0.0,0.92624366,73.171989,0.94154423,407.68207,-9.2283764
2697,2697,195.4342,14.619436,9.0830851,0.0,0,0.71404135,0.0,0.92963719,73.427841,0.91610396,408.21347,-9.2291574
2699,2699,195.4346,14.748887,9.1133041,0.0,0,0.68903339,0.0,0.9343881,73.732361,0.88810766,408.74484,-9.2278404
2701,2701,195.435,14.847974,9.135623,0.0,0,0.66402543,0.0,0.93976879,73.796158,0.85978627,409.27621,-9.2271385
2703,2703,195.4354,14.907614,9.1666527,0.0,0,0.63901734,0.0,0.94324136,73.88002,0.83776224,409.80762,-9.2268829
2705,2705,195.4358,14.976017,9.1907635,0.0,0,0.61400938,0.0,0.94817561,73.8423,0.81099194,410.33899,-9.2273264
2707,2707,195.4362,15.079769,9.2087421,0.0,0,0.58900136,0.0,0.95239127,74.011246,0.78641689,410.87036,-9.2267494
2709,2709,195.4366,15.205647,9.2417164,0.0,0,0.56478846,0.0,0.95592266,74.407288,0.76000243,411.40176,-9.2280302
2711,2711,195.437,15.309986,9.2628565,0.0,0,0.54098594,0.0,0.96101022,74.504524,0.73300886,411.93314,-9.2292852
2713,2713,195.4374,15.380179,9.2861996,0.0,0,0.51718587,0.0,0.96510035,74.548264,0.70819259,412.46451,-9.2294264
2715,2715,195.4378,15.478451,9.3221636,0.0,0,0.49338591,0.0,0.96974313,74.684189,0.68717462,412.99591,-9.2274179
2717,2717,195.4382,15.602856,9.3401842,0.0,0,0.4695859,0.0,0.97494996,74.846954,0.65628117,413.52728,-9.227416
2719,2719,195.4386,15.719871,9.362628,0.0,0,0.44578591,0.0,0.97816694,75.240623,0.63396931,414.05865,-9.2271767
2721,2721,195.439,15.814137,9.394866,0.0,0,0.42198589,0.0,0.9830119,75.327515,0.60730511,414.59006,-9.2275448
2723,2723,195.4394,15.890785,9.41012,0.0,0,0.39818591,0.0,0.98772955,75.305336,0.58102959,415.12143,-9.2281332
2725,2725,195.4398,15.994005,9.437191,0.0,0,0.37438589,0.0,0.99080235,75.551201,0.55630553,415.6528,-9.2282562
2726,2726,195.44,16.053583,9.4473639,0.0,0,0.36248589,0.0,0.99434692,75.563354,0.54364753,415.91849,-9.2273302