File: examples/hot axisymmetric compression example/data/03 trimmed data/testID_0147.csv
level_0,index,Time(sec),Force(kN),Jaw(mm),PowAngle(deg),Power(W),Pram,PTemp,Strain,Stress(MPa),Stroke(mm),TC1(C),wedge(mm)
2437,2437,212.0103,0.42579189,0.090491921,0.0,0,9.0922337,0.0,0.0060958923,4.2624669,10.140811,500.39365,-9.2089701
2439,2439,212.0107,3.2889717,0.14669029,0.0,0,9.0337057,0.0,0.0091848122,37.511425,10.07314,500.51422,-9.2084837
2441,2441,212.0111,4.7077785,0.21328419,0.0,0,8.9751778,0.0,0.014155177,58.485943,10.013556,500.6348,-9.2060976
2443,2443,212.0115,4.7625852,0.30824369,0.0,0,8.9166498,0.0,0.019780027,59.480606,9.9260597,500.75534,-9.2020216
2445,2445,212.0119,4.3270526,0.47480282,0.0,0,8.8581219,0.0,0.031043185,54.231472,9.8234386,500.87592,-9.202713
2447,2447,212.0123,4.6089058,0.56114042,0.0,0,8.7995939,0.0,0.037822299,55.571522,9.7069063,500.99646,-9.204917
2449,2449,212.0127,4.6787691,0.68525076,0.0,0,8.7416534,0.0,0.045575093,57.154308,9.5956955,501.11703,-9.2057419
2451,2451,212.0131,5.1296306,0.76151448,0.0,0,8.6858492,0.0,0.051964048,61.524139,9.4985342,501.23761,-9.2052736
2453,2453,212.0135,4.5476437,0.78389442,0.0,0,8.6301851,0.0,0.053505383,56.074245,9.4090919,501.35815,-9.2030344
2455,2455,212.0139,4.6091723,0.8852852,0.0,0,8.5745211,0.0,0.059988666,54.335114,9.3308697,501.47873,-9.20399
2457,2457,212.0143,5.2257395,0.92035365,0.0,0,8.518857,0.0,0.063188367,62.299873,9.2577581,501.5993,-9.2031031
2459,2459,212.0147,5.2753077,1.0050497,0.0,0,8.4631929,0.0,0.068649739,62.599689,9.1778088,501.71985,-9.201726
2461,2461,212.0151,5.0003142,1.1270803,0.0,0,8.4075289,0.0,0.077077314,59.629826,9.0959883,501.84042,-9.2034283
2463,2463,212.0155,4.817059,1.1938062,0.0,0,8.3518648,0.0,0.082505412,56.216427,9.0085802,501.961,-9.2055254
2465,2465,212.0159,5.0774345,1.2807752,0.0,0,8.2962008,0.0,0.088670887,58.984585,8.9227295,502.08154,-9.2043247
2467,2467,212.0163,5.0738988,1.3360677,0.0,0,8.2405367,0.0,0.092706814,58.778332,8.8441954,502.20212,-9.2027454
2469,2469,212.0167,5.0922098,1.392681,0.0,0,8.1848736,0.0,0.097129397,58.852951,8.7773256,502.32266,-9.2022018
2471,2471,212.0171,4.8795347,1.4591674,0.0,0,8.1292095,0.0,0.10188583,56.149014,8.7137604,502.44324,-9.2028723
2473,2473,212.0175,5.2045774,1.5076636,0.0,0,8.0735445,0.0,0.10534369,59.140373,8.6583624,502.56021,-9.2044296
2475,2475,212.0179,5.3653584,1.5772005,0.0,0,8.0196619,0.0,0.11071683,61.251522,8.5952625,502.67722,-9.2042713
2477,2477,212.0183,5.1717353,1.6546289,0.0,0,7.9666953,0.0,0.11622236,58.707916,8.5334101,502.79419,-9.2029696
2479,2479,212.0187,5.0761561,1.723981,0.0,0,7.9137354,0.0,0.12156626,57.274704,8.4665546,502.91119,-9.2019691
2481,2481,212.0191,5.1170645,1.7769345,0.0,0,7.860775,0.0,0.12594907,57.278809,8.4044552,503.02817,-9.2020283
2483,2483,212.0195,5.1679564,1.8154349,0.0,0,7.8078156,0.0,0.12846719,57.869583,8.3494892,503.14514,-9.2029753
2485,2485,212.0199,5.1281219,1.865653,0.0,0,7.7548552,0.0,0.13259666,57.22855,8.2929087,503.26215,-9.2052021
2487,2487,212.0203,5.0569549,1.9150113,0.0,0,7.7018952,0.0,0.13634416,56.278187,8.2428608,503.37912,-9.2050924
2489,2489,212.0207,5.2818112,1.9519892,0.0,0,7.6489348,0.0,0.13889946,58.181911,8.1965075,503.49609,-9.2035131
2491,2491,212.0211,5.2913041,2.0031202,0.0,0,7.5959754,0.0,0.14319767,58.512257,8.1465921,503.6131,-9.2022429
2493,2493,212.0215,5.2469535,2.0616093,0.0,0,7.543015,0.0,0.14740461,57.626431,8.0999107,503.73007,-9.2032995
2495,2495,212.0219,5.2288365,2.1126585,0.0,0,7.4900556,0.0,0.15122721,57.417145,8.0445623,503.84705,-9.2033606
2497,2497,212.0223,5.2156367,2.1572075,0.0,0,7.4370952,0.0,0.15527904,56.741554,7.9936185,503.96405,-9.2046375
2499,2499,212.0227,5.283299,2.1988165,0.0,0,7.384666,0.0,0.1579586,57.556156,7.943274,504.08102,-9.2049866
2501,2501,212.0231,5.1700835,2.2479985,0.0,0,7.3341718,0.0,0.1619294,56.10857,7.895606,504.19803,-9.2041273
2503,2503,212.0235,5.2040052,2.2845676,0.0,0,7.2838035,0.0,0.16527732,56.031738,7.852026,504.315,-9.2034349
2505,2505,212.0239,5.3156629,2.3252797,0.0,0,7.2334356,0.0,0.1678292,57.100796,7.8109922,504.43198,-9.2026825
2507,2507,212.0243,5.4090056,2.3706422,0.0,0,7.1830673,0.0,0.17173056,57.948734,7.7688189,504.54898,-9.2021637
2509,2509,212.0247,5.3360415,2.414638,0.0,0,7.132699,0.0,0.1752519,57.072113,7.719686,504.66595,-9.2033596
2511,2511,212.0251,5.3080482,2.4709013,0.0,0,7.0823312,0.0,0.17920715,56.468071,7.6766782,504.78293,-9.2022486
2513,2513,212.0255,5.370513,2.5076926,0.0,0,7.0319633,0.0,0.18286636,56.913963,7.6307087,504.89993,-9.2032938
2515,2515,212.0259,5.4292417,2.5482776,0.0,0,6.981595,0.0,0.18578258,57.350986,7.5879846,505.01691,-9.2037516
2517,2517,212.0263,5.3917561,2.6049287,0.0,0,6.9312272,0.0,0.18997648,56.79842,7.5398355,505.13388,-9.2028513
2519,2519,212.0267,5.3399134,2.6363723,0.0,0,6.8808589,0.0,0.19332796,56.092804,7.4981985,505.25089,-9.2030897
2521,2521,212.0271,5.450685,2.6753154,0.0,0,6.8304915,0.0,0.1959838,56.867435,7.4543395,505.36786,-9.2027349
2523,2523,212.0275,5.4938822,2.7277942,0.0,0,6.7801232,0.0,0.20012514,57.242641,7.4102097,505.48837,-9.2016735
2525,2525,212.0279,5.469758,2.7666852,0.0,0,6.7313666,0.0,0.20378716,56.880547,7.3672285,505.60889,-9.2026262
2527,2527,212.0283,5.4706931,2.8134456,0.0,0,6.6834412,0.0,0.20705505,56.657265,7.3224907,505.7294,-9.2032499
2529,2529,212.0287,5.5063968,2.8569317,0.0,0,6.6355214,0.0,0.21103731,56.736526,7.2776661,505.84991,-9.203311
2531,2531,212.0291,5.5677342,2.8942583,0.0,0,6.5876012,0.0,0.21413411,57.193684,7.2317071,505.97043,-9.2031984
2533,2533,212.0295,5.5571213,2.9432228,0.0,0,6.5396814,0.0,0.21774445,56.965694,7.1889052,506.09091,-9.203517
2535,2535,212.0299,5.570281,2.9875846,0.0,0,6.4917617,0.0,0.22199915,56.801743,7.1432519,506.21143,-9.2034092
2537,2537,212.0303,5.6474681,3.0315993,0.0,0,6.4438419,0.0,0.22546996,57.319485,7.0983758,506.33194,-9.2032309
2539,2539,212.0307,5.6839547,3.0813861,0.0,0,6.3959212,0.0,0.22934565,57.492577,7.0500927,506.45245,-9.2025805
2541,2541,212.0311,5.6758113,3.129318,0.0,0,6.3480015,0.0,0.23390363,57.210938,7.0037208,506.57297,-9.202527
2543,2543,212.0315,5.6825829,3.1793849,0.0,0,6.3000817,0.0,0.23769078,56.987297,6.9530158,506.69348,-9.2040005
2545,2545,212.0319,5.7431374,3.2251146,0.0,0,6.252162,0.0,0.24150147,57.33094,6.9074235,506.814,-9.2046366
2547,2547,212.0323,5.7718215,3.2678814,0.0,0,6.2042418,0.0,0.24569985,57.475994,6.8594646,506.93451,-9.203825
2549,2549,212.0327,5.7608862,3.3181653,0.0,0,6.1568022,0.0,0.24931875,57.158112,6.8111353,507.05499,-9.203433
2551,2551,212.0331,5.7683187,3.3634079,0.0,0,6.1111116,0.0,0.25348088,57.007599,6.7632165,507.17551,-9.2026157
2553,2553,212.0335,5.8407331,3.4093068,0.0,0,6.0655355,0.0,0.25777832,57.36409,6.7154369,507.29602,-9.2026806
2555,2555,212.0339,5.8745031,3.4645202,0.0,0,6.0199599,0.0,0.2618179,57.549564,6.6677012,507.41653,-9.2025127
2557,2557,212.0343,5.8838625,3.509912,0.0,0,5.9743834,0.0,0.26624376,57.437649,6.6172547,507.53705,-9.2036238
2559,2559,212.0347,5.8872743,3.5575545,0.0,0,5.9288073,0.0,0.27042201,57.123257,6.56914,507.65756,-9.2040253
2561,2561,212.0351,5.9248877,3.6133521,0.0,0,5.8832316,0.0,0.27460712,57.313854,6.5174279,507.77808,-9.2042046
2563,2563,212.0355,5.9639969,3.6574214,0.0,0,5.8376555,0.0,0.27921626,57.446907,6.4688568,507.89859,-9.2033043
2565,2565,212.0359,5.9954247,3.704644,0.0,0,5.792079,0.0,0.28320363,57.526703,6.4226947,508.01907,-9.2031212
2567,2567,212.0363,6.0024047,3.7631187,0.0,0,5.7465034,0.0,0.28796792,57.249416,6.3703218,508.13959,-9.2014303
2569,2569,212.0367,6.0241299,3.8045268,0.0,0,5.7009273,0.0,0.29242918,57.230434,6.3199077,508.2601,-9.2020826
2571,2571,212.0371,6.0467782,3.8525283,0.0,0,5.6553516,0.0,0.2961255,57.242523,6.2720413,508.38062,-9.2028627
2573,2573,212.0375,6.0917702,3.9075747,0.0,0,5.6097751,0.0,0.30116484,57.420322,6.2196574,508.29108,-9.2035999
2575,2575,212.0379,6.1235447,3.9494216,0.0,0,5.5656581,0.0,0.30551359,57.37587,6.1693864,508.20157,-9.2034855
2577,2577,212.0383,6.134829,4.0028458,0.0,0,5.5222936,0.0,0.30967131,57.327904,6.1233582,508.11203,-9.2029266
2579,2579,212.0387,6.1412821,4.0566001,0.0,0,5.4789333,0.0,0.31493491,57.086594,6.0724287,508.02249,-9.2019348
2581,2581,212.0391,6.16923,4.1001754,0.0,0,5.4355731,0.0,0.31912196,57.041634,6.0206738,507.93295,-9.2020826
2583,2583,212.0395,6.2121119,4.1504445,0.0,0,5.3922133,0.0,0.32311815,57.229836,5.9728851,507.84344,-9.2017736
2585,2585,212.0399,6.2471623,4.1981292,0.0,0,5.3488531,0.0,0.32819906,57.290825,5.9261765,507.75391,-9.2028217
2587,2587,212.0403,6.2596736,4.2437696,0.0,0,5.3054934,0.0,0.33220333,57.137306,5.8702831,507.66437,-9.203476
2589,2589,212.0407,6.2601781,4.2969356,0.0,0,5.2621331,0.0,0.33679309,56.847519,5.8253098,507.57486,-9.2024965
2591,2591,212.0411,6.3076549,4.3445487,0.0,0,5.2187734,0.0,0.34191543,56.996918,5.7746735,507.48532,-9.2030783
2593,2593,212.0415,6.3423867,4.3930511,0.0,0,5.1754136,0.0,0.34593603,57.090485,5.7254581,507.39578,-9.2034454
2595,2595,212.0419,6.3711271,4.4416227,0.0,0,5.1320534,0.0,0.35054755,57.109219,5.6794987,507.30627,-9.2021875
2597,2597,212.0423,6.3788142,4.4858961,0.0,0,5.0886931,0.0,0.35535252,56.914894,5.6284995,507.21674,-9.2034502
2599,2599,212.0427,6.3775311,4.5400906,0.0,0,5.0457678,0.0,0.35964167,56.618019,5.5807357,507.1272,-9.2033997
2601,2601,212.0431,6.4129381,4.5840745,0.0,0,5.0044241,0.0,0.36426091,56.661766,5.5328989,507.03769,-9.2035093
2603,2603,212.0435,6.4573646,4.6265445,0.0,0,4.9631839,0.0,0.36873904,56.880199,5.4888539,506.94815,-9.2038546
2605,2605,212.0439,6.4659519,4.6802187,0.0,0,4.9219437,0.0,0.37302461,56.677776,5.4400978,506.85861,-9.203846
2607,2607,212.0443,6.4702263,4.7233443,0.0,0,4.8807039,0.0,0.37777421,56.44173,5.3916035,506.7691,-9.202177
2609,2609,212.0447,6.489563,4.7686443,0.0,0,4.8394637,0.0,0.38222787,56.364761,5.3474894,506.67957,-9.2022457
2611,2611,212.0451,6.5351119,4.8212161,0.0,0,4.798224,0.0,0.38675621,56.485828,5.3030162,506.59003,-9.2038612
2613,2613,212.0455,6.5780497,4.8611469,0.0,0,4.7569838,0.0,0.39160225,56.536942,5.2626562,506.50052,-9.2047224
2615,2615,212.0459,6.5760918,4.9055047,0.0,0,4.7157435,0.0,0.39554688,56.408947,5.2076817,506.41098,-9.2037678
2617,2617,212.0463,6.5902529,4.9591746,0.0,0,4.6745038,0.0,0.40053523,56.16909,5.1645365,506.32144,-9.2034521
2619,2619,212.0467,6.6084738,4.9972758,0.0,0,4.6332641,0.0,0.40523759,56.102547,5.1198335,506.23193,-9.2027531
2621,2621,212.0471,6.6332636,5.041749,0.0,0,4.5920234,0.0,0.40898943,56.104515,5.0737977,506.1424,-9.2019625
2623,2623,212.0475,6.6642509,5.0917425,0.0,0,4.5507836,0.0,0.41402856,56.056297,5.0274711,506.09229,-9.2019911
2625,2625,212.0479,6.696454,5.129055,0.0,0,4.5108657,0.0,0.41840956,55.973713,4.9849238,506.04218,-9.2027836
2627,2627,212.0483,6.7041283,5.1777349,0.0,0,4.4716296,0.0,0.42253083,55.923717,4.9391589,505.99207,-9.2035942
2629,2629,212.0487,6.7302237,5.2242365,0.0,0,4.4323974,0.0,0.42788157,55.794151,4.8956647,505.94196,-9.2026749
2631,2631,212.0491,6.7532458,5.2627759,0.0,0,4.3931651,0.0,0.43183208,55.784538,4.8522964,505.89185,-9.2021561
2633,2633,212.0495,6.7935219,5.3082714,0.0,0,4.3539338,0.0,0.43600947,55.878471,4.8086939,505.84171,-9.2021904
2635,2635,212.0499,6.8083568,5.350565,0.0,0,4.3147016,0.0,0.44119102,55.781857,4.7621436,505.7916,-9.2011023
2637,2637,212.0503,6.8258262,5.3899155,0.0,0,4.2754693,0.0,0.44490311,55.672626,4.7180967,505.74149,-9.2026329
2639,2639,212.0507,6.8378344,5.4343305,0.0,0,4.236237,0.0,0.44907418,55.54388,4.6792178,505.69138,-9.2029629
2641,2641,212.0511,6.8728218,5.4738131,0.0,0,4.1970053,0.0,0.45411184,55.505116,4.6376204,505.64127,-9.2033854
2643,2643,212.0515,6.9162669,5.5180693,0.0,0,4.1577735,0.0,0.45798233,55.665318,4.5920191,505.59116,-9.2027264
2645,2645,212.0519,6.9407439,5.5619712,0.0,0,4.1185412,0.0,0.46271476,55.623589,4.5524368,505.54105,-9.2016191
2647,2647,212.0523,6.9566398,5.5988503,0.0,0,4.0793095,0.0,0.46736032,55.518101,4.5129542,505.49094,-9.2026196
2649,2649,212.0527,6.9648385,5.6455369,0.0,0,4.0404716,0.0,0.47128785,55.384209,4.4696469,505.44083,-9.2028761
2651,2651,212.0531,6.9962082,5.6822958,0.0,0,4.0030656,0.0,0.47584221,55.332111,4.4295149,505.39072,-9.2044554
2653,2653,212.0535,7.0306444,5.7181859,0.0,0,3.9657531,0.0,0.4799372,55.442616,4.3913321,505.34061,-9.2034512
2655,2655,212.0539,7.052824,5.7661223,0.0,0,3.928441,0.0,0.4840503,55.334953,4.3503232,505.2905,-9.2031384
2657,2657,212.0543,7.0678802,5.7991099,0.0,0,3.8911293,0.0,0.48859152,55.269615,4.3113518,505.24039,-9.2032661
2659,2659,212.0547,7.0911226,5.8371496,0.0,0,3.8538172,0.0,0.49267414,55.16148,4.2699652,505.19025,-9.2028809
2661,2661,212.0551,7.1292949,5.8847995,0.0,0,3.8165052,0.0,0.49701858,55.156197,4.2343702,505.14014,-9.2031355
2663,2663,212.0555,7.1671162,5.9178643,0.0,0,3.7791932,0.0,0.50179678,55.226372,4.1976399,505.09003,-9.203887
2665,2665,212.0559,7.1891494,5.9590211,0.0,0,3.7418811,0.0,0.50574929,55.149303,4.1548238,505.03992,-9.2032042
2667,2667,212.0563,7.2050619,6.004293,0.0,0,3.7045693,0.0,0.51042813,55.019764,4.1159515,504.98981,-9.2021055
2669,2669,212.0567,7.2317972,6.0337262,0.0,0,3.6672573,0.0,0.51470912,54.987896,4.0747137,504.9397,-9.203269
2671,2671,212.0571,7.2724023,6.0715261,0.0,0,3.629945,0.0,0.51820105,55.075378,4.0369368,504.88959,-9.2030106
2673,2673,212.0575,7.312572,6.1155586,0.0,0,3.5926332,0.0,0.52303326,55.164555,3.9991562,504.83707,-9.203476
2675,2675,212.0579,7.3213639,6.1489029,0.0,0,3.5565164,0.0,0.52741969,55.014133,3.9586599,504.78455,-9.2038813
2677,2677,212.0583,7.355844,6.1922731,0.0,0,3.5210166,0.0,0.53147572,55.0033,3.9205501,504.73199,-9.203311
2679,2679,212.0587,7.3773193,6.2343068,0.0,0,3.4855206,0.0,0.53696948,54.936584,3.8804977,504.67947,-9.2026415
2681,2681,212.0591,7.4283657,6.2692099,0.0,0,3.4500246,0.0,0.54089266,55.043423,3.8401151,504.62695,-9.2016706
2683,2683,212.0595,7.4693942,6.3090415,0.0,0,3.4145288,0.0,0.54484773,55.143265,3.8070929,504.57443,-9.2019644
2685,2685,212.0599,7.4852476,6.3459015,0.0,0,3.3790326,0.0,0.55005682,54.945156,3.7698712,504.52191,-9.2030964
2687,2687,212.0603,7.4962621,6.3803387,0.0,0,3.3435366,0.0,0.55352819,54.841751,3.7305274,504.46936,-9.2038832
2689,2689,212.0607,7.5289006,6.4185843,0.0,0,3.3080406,0.0,0.55763447,54.885452,3.6916127,504.41684,-9.2027426
2691,2691,212.0611,7.5785007,6.4541173,0.0,0,3.2725446,0.0,0.56273365,54.913731,3.6537006,504.36432,-9.2019482
2693,2693,212.0615,7.6236906,6.4952002,0.0,0,3.2370486,0.0,0.56653744,55.099976,3.6178882,504.3118,-9.2018766
2695,2695,212.0619,7.6371021,6.533885,0.0,0,3.2015524,0.0,0.57127523,54.920887,3.5805972,504.25928,-9.202136
2697,2697,212.0623,7.6572833,6.5670934,0.0,0,3.1660566,0.0,0.5760932,54.789257,3.5470076,504.20673,-9.2024212
2699,2699,212.0627,7.6954541,6.6096601,0.0,0,3.1309149,0.0,0.57998693,54.858696,3.5064511,504.15421,-9.2032881
2701,2701,212.0631,7.7574911,6.6434469,0.0,0,3.0970623,0.0,0.58459628,54.986523,3.4710739,504.10168,-9.201829
2703,2703,212.0635,7.7731209,6.6759195,0.0,0,3.0632942,0.0,0.58891439,54.930569,3.4337032,504.04916,-9.2017918
2705,2705,212.0639,7.8051915,6.7191529,0.0,0,3.0295262,0.0,0.5929693,54.887142,3.3974378,503.99664,-9.2017889
2707,2707,212.0643,7.8339252,6.7488585,0.0,0,2.9957583,0.0,0.59760386,54.840839,3.3625433,503.94409,-9.2032747
2709,2709,212.0647,7.8830876,6.7834973,0.0,0,2.9619904,0.0,0.60163456,54.929699,3.3271644,503.89157,-9.202322
2711,2711,212.0651,7.9519153,6.8285885,0.0,0,2.9282222,0.0,0.60624743,55.149929,3.2911532,503.83905,-9.2027435
2713,2713,212.0655,7.9781504,6.8580523,0.0,0,2.894454,0.0,0.61113691,55.076042,3.2519803,503.78653,-9.2024403
2715,2715,212.0659,8.0008211,6.8950377,0.0,0,2.8606861,0.0,0.6149258,55.014996,3.2166839,503.73401,-9.2015057
2717,2717,212.0663,8.025651,6.939568,0.0,0,2.8269181,0.0,0.62009585,54.906715,3.1828573,503.68146,-9.2020731
2719,2719,212.0667,8.075984,6.9674006,0.0,0,2.7931502,0.0,0.6246689,54.964638,3.1464326,503.62894,-9.2034397
2721,2721,212.0671,8.1128654,7.0050812,0.0,0,2.7593822,0.0,0.62834865,55.111862,3.1118703,503.57642,-9.2028198
2723,2723,212.0675,8.145463,7.0446243,0.0,0,2.7256143,0.0,0.63361019,55.015091,3.0778172,503.27203,-9.2024622
2725,2725,212.0679,8.180438,7.0708966,0.0,0,2.6929309,0.0,0.63754529,55.110008,3.0408127,502.96765,-9.2019644
2727,2727,212.0683,8.2256212,7.1106143,0.0,0,2.6608074,0.0,0.6415031,55.104176,3.0098987,502.6633,-9.2032156
2729,2729,212.0687,8.2537632,7.1464114,0.0,0,2.6286871,0.0,0.64692169,54.998573,2.9711101,502.35892,-9.2027416
2731,2731,212.0691,8.318573,7.1768603,0.0,0,2.5965672,0.0,0.65080798,55.202045,2.9380894,502.05453,-9.2029552
2733,2733,212.0695,8.364234,7.2166991,0.0,0,2.5644472,0.0,0.65501481,55.285233,2.9023194,501.75018,-9.2021532
2735,2735,212.0699,8.3778276,7.2517033,0.0,0,2.5323269,0.0,0.66080165,55.109089,2.8655217,501.4458,-9.2022057
2737,2737,212.0703,8.42099,7.2856789,0.0,0,2.5002072,0.0,0.66449261,55.175587,2.8302443,501.14142,-9.2017393
2739,2739,212.0707,8.4667654,7.3212895,0.0,0,2.4680872,0.0,0.6688143,55.2188,2.7991686,500.83707,-9.2023087
2741,2741,212.0711,8.520237,7.3512759,0.0,0,2.4359672,0.0,0.67377865,55.323315,2.7606413,500.53268,-9.2019587
2743,2743,212.0715,8.567625,7.3882294,0.0,0,2.4038472,0.0,0.67746753,55.418144,2.7270029,500.2283,-9.2018757
2745,2745,212.0719,8.5975189,7.4236798,0.0,0,2.3717272,0.0,0.68231279,55.301384,2.6926649,499.92392,-9.2018585
2747,2747,212.0723,8.6410275,7.4529877,0.0,0,2.339607,0.0,0.68721318,55.287804,2.6598542,499.61957,-9.2012672
2749,2749,212.0727,8.6856833,7.49506,0.0,0,2.3078086,0.0,0.69125617,55.336578,2.6256225,499.31519,-9.1999378
2751,2751,212.0731,8.7507706,7.5260973,0.0,0,2.2771802,0.0,0.69619322,55.482063,2.5912569,499.0108,-9.2005644
2753,2753,212.0735,8.7823009,7.5553651,0.0,0,2.2466278,0.0,0.70058399,55.5005,2.5580957,498.70645,-9.2012796
2755,2755,212.0739,8.8282719,7.595437,0.0,0,2.2160761,0.0,0.70470458,55.575779,2.5239463,498.40207,-9.201746
2757,2757,212.0743,8.8635235,7.6194944,0.0,0,2.185524,0.0,0.70933354,55.482788,2.4906502,498.09769,-9.2017612
2759,2759,212.0747,8.9074335,7.6520443,0.0,0,2.1549721,0.0,0.71322227,55.532536,2.4589343,497.79333,-9.2006216
2761,2761,212.0751,8.9652767,7.6948857,0.0,0,2.1244199,0.0,0.71822476,55.631107,2.4240398,497.48895,-9.2004261
2763,2763,212.0755,9.0154924,7.7214446,0.0,0,2.093868,0.0,0.72324592,55.649437,2.3930359,497.18457,-9.2005892
2765,2765,212.0759,9.0341148,7.7546759,0.0,0,2.0633161,0.0,0.72690696,55.570328,2.3618002,496.88022,-9.2025242
2767,2767,212.0763,9.0846157,7.7925301,0.0,0,2.0327642,0.0,0.73207814,55.571144,2.3284273,496.57584,-9.2016535
2769,2769,212.0767,9.1435242,7.8130622,0.0,0,2.002212,0.0,0.73619217,55.691051,2.2946708,496.27145,-9.2024755
2771,2771,212.0771,9.2129555,7.848105,0.0,0,1.9716599,0.0,0.73959446,55.937279,2.2631552,495.96707,-9.2018442
2773,2773,212.0775,9.2662516,7.8878994,0.0,0,1.941108,0.0,0.7456491,55.931034,2.231868,495.05496,-9.2016964
2775,2775,212.0779,9.2811518,7.9151683,0.0,0,1.9115354,0.0,0.75024307,55.784145,2.1982262,494.14285,-9.2018003
2777,2777,212.0783,9.3332176,7.9515228,0.0,0,1.8824683,0.0,0.75408483,55.88377,2.1668801,493.23074,-9.2019348
2779,2779,212.0787,9.3995743,7.9825163,0.0,0,1.8534042,0.0,0.75968814,55.975906,2.1353056,492.31863,-9.2019577
2781,2781,212.0791,9.4808016,8.0065937,0.0,0,1.8243402,0.0,0.76307672,56.236332,2.1049356,491.40652,-9.2004795
2783,2783,212.0795,9.5048666,8.0419588,0.0,0,1.7952763,0.0,0.76706147,56.186165,2.0697803,490.49442,-9.2012987
2785,2785,212.0799,9.5391064,8.0731859,0.0,0,1.7662122,0.0,0.77294403,56.046101,2.0403223,489.58231,-9.2021284
2787,2787,212.0803,9.5800486,8.1068544,0.0,0,1.7371483,0.0,0.7768234,56.063801,2.0123119,488.6702,-9.2020063
2789,2789,212.0807,9.6569223,8.1409521,0.0,0,1.7080842,0.0,0.78152317,56.260868,1.9819493,487.75809,-9.2018719
2791,2791,212.0811,9.7360716,8.1684475,0.0,0,1.6790203,0.0,0.7868892,56.414261,1.9505033,486.84598,-9.2011805
2793,2793,212.0815,9.7730703,8.2019234,0.0,0,1.6499562,0.0,0.79043245,56.42197,1.9198521,485.93387,-9.2000427
2795,2795,212.0819,9.8157148,8.2317514,0.0,0,1.6208922,0.0,0.79520202,56.392803,1.8877783,485.02176,-9.2000751
2797,2797,212.0823,9.881031,8.2573957,0.0,0,1.5918282,0.0,0.7999602,56.442387,1.8559279,484.10965,-9.2011003
2799,2799,212.0827,9.9449129,8.2947903,0.0,0,1.5630547,0.0,0.80383319,56.672115,1.8250819,483.19757,-9.2013617
2801,2801,212.0831,10.007489,8.3208141,0.0,0,1.5353372,0.0,0.8089394,56.731892,1.7936389,482.28546,-9.2018414
2803,2803,212.0835,10.037433,8.3492718,0.0,0,1.5076891,0.0,0.81324059,56.673687,1.7613766,481.37335,-9.2006187
2805,2805,212.0839,10.087614,8.3900976,0.0,0,1.4800411,0.0,0.81787562,56.701206,1.7324129,480.46124,-9.2003584
2807,2807,212.0843,10.159346,8.4138241,0.0,0,1.4523932,0.0,0.82333153,56.746281,1.701575,479.54913,-9.1998615
2809,2809,212.0847,10.236085,8.4421597,0.0,0,1.4247452,0.0,0.82695782,56.935314,1.6704637,478.63702,-9.199194
2811,2811,212.0851,10.307444,8.4783182,0.0,0,1.3970972,0.0,0.83171242,57.08408,1.6427599,477.72491,-9.2006683
2813,2813,212.0855,10.34514,8.4986658,0.0,0,1.3694493,0.0,0.83656019,57.049526,1.6118687,476.81281,-9.2011948
2815,2815,212.0859,10.392766,8.5292759,0.0,0,1.3418012,0.0,0.84003407,57.106358,1.5818778,475.9007,-9.2011328
2817,2817,212.0863,10.464288,8.5668907,0.0,0,1.3141533,0.0,0.84552681,57.162437,1.5543023,474.98859,-9.2015381
2819,2819,212.0867,10.543143,8.586256,0.0,0,1.2865052,0.0,0.85009402,57.317738,1.5216166,474.07648,-9.2004395
2821,2821,212.0871,10.60823,8.6211052,0.0,0,1.2588573,0.0,0.85380793,57.438263,1.4972862,473.16437,-9.1994963
2823,2823,212.0875,10.656989,8.6546049,0.0,0,1.2312093,0.0,0.8598851,57.420361,1.4676545,472.55606,-9.2004528
2825,2825,212.0879,10.71803,8.6759501,0.0,0,1.2044512,0.0,0.86388302,57.488583,1.4399625,471.94775,-9.2011471
2827,2827,212.0883,10.78784,8.7089272,0.0,0,1.1781523,0.0,0.86758685,57.656425,1.4097216,471.33948,-9.2017107
2829,2829,212.0887,10.853243,8.7361612,0.0,0,1.1518563,0.0,0.87337726,57.671093,1.3828642,470.73117,-9.2007875
2831,2831,212.0891,10.921551,8.75982,0.0,0,1.1255603,0.0,0.87681425,57.823803,1.3547177,470.12286,-9.2003851
2833,2833,212.0895,10.98815,8.7922525,0.0,0,1.0992643,0.0,0.88114196,57.929764,1.3265686,469.51456,-9.2006235
2835,2835,212.0899,11.03096,8.8180962,0.0,0,1.0729682,0.0,0.88689506,57.82877,1.2972485,468.90625,-9.2012157
2837,2837,212.0903,11.109231,8.8475275,0.0,0,1.0466722,0.0,0.89031887,58.032993,1.2678812,468.29794,-9.2011833
2839,2839,212.0907,11.2017,8.8776617,0.0,0,1.0203762,0.0,0.89501977,58.217941,1.2412845,467.68964,-9.2012711
2841,2841,212.0911,11.284107,8.8993492,0.0,0,0.99408025,0.0,0.90031642,58.317516,1.21057,467.08133,-9.2005615
2843,2843,212.0915,11.343131,8.9303217,0.0,0,0.96778423,0.0,0.90357774,58.47414,1.1878372,466.47302,-9.2003765
2845,2845,212.0919,11.411122,8.9568119,0.0,0,0.94148827,0.0,0.90872228,58.515244,1.1560227,465.86472,-9.2007751
2847,2847,212.0923,11.466,8.9781742,0.0,0,0.91519231,0.0,0.91317278,58.515045,1.1259059,465.25641,-9.2011404
2849,2849,212.0927,11.555508,9.0144167,0.0,0,0.88916039,0.0,0.91704744,58.766163,1.1010501,464.6481,-9.2011938
2851,2851,212.0931,11.645846,9.0373554,0.0,0,0.86408937,0.0,0.92240387,58.893673,1.0713524,464.03983,-9.1998549
2853,2853,212.0935,11.701029,9.0618744,0.0,0,0.83908123,0.0,0.9266569,58.936935,1.0452721,463.43152,-9.200326
2855,2855,212.0939,11.764704,9.0966024,0.0,0,0.8140732,0.0,0.93091559,59.032974,1.0181298,462.82321,-9.1996222
2857,2857,212.0943,11.841114,9.1140747,0.0,0,0.78906524,0.0,0.935848,59.118095,0.99229723,462.2149,-9.1995592
2859,2859,212.0947,11.945148,9.1404877,0.0,0,0.76405728,0.0,0.93943369,59.424423,0.96222079,461.6066,-9.1999226
2861,2861,212.0951,12.026601,9.1771536,0.0,0,0.73904926,0.0,0.94474375,59.497364,0.93469167,460.99829,-9.2009792
2863,2863,212.0955,12.08289,9.1943178,0.0,0,0.71404123,0.0,0.94972837,59.4795,0.90926754,460.38998,-9.201478
2865,2865,212.0959,12.152611,9.22223,0.0,0,0.68903327,0.0,0.95317852,59.615307,0.88457209,459.78168,-9.1989117
2867,2867,212.0963,12.244909,9.2545357,0.0,0,0.66402531,0.0,0.95873266,59.730537,0.85697562,459.17337,-9.1993523
2869,2869,212.0967,12.33801,9.269105,0.0,0,0.63901722,0.0,0.96266973,59.937752,0.83157575,458.56506,-9.1981955
2871,2871,212.0971,12.420709,9.2989645,0.0,0,0.61400926,0.0,0.96615773,60.164131,0.81002921,457.95679,-9.1992159
2873,2873,212.0975,12.484186,9.3285522,0.0,0,0.58900124,0.0,0.97216451,60.075653,0.78348345,458.10406,-9.200779
2875,2875,212.0979,12.551108,9.3481102,0.0,0,0.56478834,0.0,0.97616577,60.177784,0.75864643,458.25134,-9.199069
2877,2877,212.0983,12.648293,9.3793106,0.0,0,0.54098582,0.0,0.98028547,60.380589,0.73010772,458.39865,-9.1992645
2879,2879,212.0987,12.762835,9.4036036,0.0,0,0.51718581,0.0,0.98628604,60.495068,0.70606732,458.54593,-9.1988344
2881,2881,212.0991,12.83291,9.4250927,0.0,0,0.49338579,0.0,0.98960364,60.707222,0.67601043,458.69321,-9.1996508
2883,2883,212.0995,12.896463,9.4535074,0.0,0,0.46958581,0.0,0.99369901,60.731293,0.65460086,458.84048,-9.2003508
2885,2885,212.0999,12.980083,9.4746103,0.0,0,0.44578579,0.0,0.99928921,60.791454,0.62650633,458.98776,-9.1993256
2887,2887,212.1003,13.081344,9.5012274,0.0,0,0.42198581,0.0,1.0026172,61.056702,0.60246378,459.13504,-9.1993341
2889,2889,212.1007,13.188879,9.5282688,0.0,0,0.39818579,0.0,1.0075278,61.262947,0.57788342,459.28235,-9.1991243