File: examples/hot axisymmetric compression example/data/03 trimmed data/testID_0142.csv
level_0,index,Time(sec),Force(kN),Jaw(mm),PowAngle(deg),Power(W),Pram,PTemp,Strain,Stress(MPa),Stroke(mm),TC1(C),wedge(mm)
2105,2105,178.6798,0.39999792,0.008381472,0.0,0,9.0629702,0.0,0.00064967287,3.8648806,10.073219,404.65091,-9.2641535
2107,2107,178.6802,3.6657939,0.065122217,0.0,0,9.0044422,0.0,0.0036153095,41.42767,10.006762,404.68454,-9.2648335
2109,2109,178.6806,5.7659225,0.11932088,0.0,0,8.9459143,0.0,0.0077365818,71.690048,9.9497671,404.7182,-9.2629423
2111,2111,178.681,6.1532989,0.20483555,0.0,0,8.8873854,0.0,0.01295334,76.777946,9.8671303,404.75183,-9.2607803
2113,2113,178.6814,6.2101603,0.36067301,0.0,0,8.8288574,0.0,0.023243081,77.601479,9.7772284,404.78549,-9.2597857
2115,2115,178.6818,6.5188756,0.42109522,0.0,0,8.7703295,0.0,0.028265491,79.753372,9.6725283,404.81912,-9.2608261
2117,2117,178.6822,6.8414464,0.52478838,0.0,0,8.7136869,0.0,0.03471091,83.946281,9.573554,404.85278,-9.260457
2119,2119,178.6826,7.3528161,0.58900917,0.0,0,8.6580172,0.0,0.039825104,89.390137,9.4886475,404.88641,-9.2594242
2121,2121,178.683,6.8489795,0.61021191,0.0,0,8.6023531,0.0,0.04125623,84.752502,9.4142246,404.92007,-9.2587395
2123,2123,178.6834,6.8954453,0.70410562,0.0,0,8.546689,0.0,0.047328934,82.811295,9.3495541,404.95251,-9.2598715
2125,2125,178.6838,7.5308414,0.74481136,0.0,0,8.491025,0.0,0.050651196,90.856834,9.2895155,404.98376,-9.259654
2127,2127,178.6842,7.5956473,0.82012355,0.0,0,8.4353609,0.0,0.055650756,91.361191,9.2147932,405.01498,-9.2588301
2129,2129,178.6846,7.3571715,0.92336518,0.0,0,8.3796968,0.0,0.062690906,88.616417,9.134943,405.04623,-9.26017
2131,2131,178.685,7.2372723,0.99806505,0.0,0,8.3240328,0.0,0.068469271,85.564728,9.057951,405.07748,-9.2603645
2133,2133,178.6854,7.578167,1.0699742,0.0,0,8.2683687,0.0,0.073657729,89.584969,8.9806404,405.1087,-9.2596884
2135,2135,178.6858,7.5358343,1.1152791,0.0,0,8.2127056,0.0,0.076803461,88.84549,8.9091129,405.13995,-9.2595739
2137,2137,178.6862,7.6885834,1.1688162,0.0,0,8.1570406,0.0,0.080950171,90.386078,8.8503075,405.1712,-9.2597933
2139,2139,178.6866,7.3649807,1.2332293,0.0,0,8.1013775,0.0,0.085382521,86.264893,8.7903671,405.20245,-9.259057
2141,2141,178.687,7.8305135,1.2820896,0.0,0,8.0462675,0.0,0.088838749,90.502701,8.7355947,405.23367,-9.2605476
2143,2143,178.6874,7.9394355,1.3546467,0.0,0,7.993176,0.0,0.094347596,92.255493,8.6706238,405.26492,-9.2591944
2145,2145,178.6878,7.7517266,1.4390546,0.0,0,7.9402156,0.0,0.10012966,89.386986,8.6034889,405.29617,-9.259099
2147,2147,178.6882,7.6694832,1.4992908,0.0,0,7.8872552,0.0,0.10475143,87.95929,8.5386391,405.32739,-9.2600536
2149,2149,178.6886,7.7206268,1.5560215,0.0,0,7.8342953,0.0,0.10943417,87.8106,8.4727974,405.35864,-9.2591667
2151,2151,178.689,7.9422092,1.5950336,0.0,0,7.7813349,0.0,0.1118403,90.323936,8.4160814,405.38989,-9.2580814
2153,2153,178.6894,7.8558059,1.6459111,0.0,0,7.728375,0.0,0.11578475,89.190094,8.360404,405.42114,-9.2591991
2155,2155,178.6898,7.8221879,1.7007586,0.0,0,7.675415,0.0,0.12017086,88.243706,8.3121967,405.45236,-9.2597198
2157,2157,178.6902,8.0093012,1.7468596,0.0,0,7.6224551,0.0,0.12311648,89.929039,8.256794,405.48361,-9.2595606
2159,2159,178.6906,8.0941563,1.8058305,0.0,0,7.5694952,0.0,0.12793332,90.650101,8.2022524,405.51486,-9.2608795
2161,2161,178.691,8.0437918,1.8628995,0.0,0,7.5165353,0.0,0.13220221,89.734795,8.1448393,405.54608,-9.2585306
2163,2163,178.6914,8.0328026,1.9262706,0.0,0,7.4635754,0.0,0.13672091,89.218285,8.0882349,405.57733,-9.2575989
2165,2165,178.6918,8.037776,1.9718735,0.0,0,7.410615,0.0,0.14090414,88.742271,8.0328569,405.60858,-9.257967
2167,2167,178.6922,8.1573696,2.0104921,0.0,0,7.3593607,0.0,0.14342415,89.867325,7.9788747,405.63983,-9.2587738
2169,2169,178.6926,8.1138525,2.0715735,0.0,0,7.3089876,0.0,0.14799874,89.189445,7.9305353,405.67105,-9.2594986
2171,2171,178.693,8.0914164,2.1113508,0.0,0,7.2586198,0.0,0.15163822,88.513077,7.8810205,405.7023,-9.258913
2173,2173,178.6934,8.2487745,2.156707,0.0,0,7.2082515,0.0,0.15459745,89.816833,7.8315115,405.65622,-9.2590723
2175,2175,178.6938,8.3303251,2.2167246,0.0,0,7.1578832,0.0,0.15957797,90.408081,7.7808194,405.51563,-9.2595282
2177,2177,178.6942,8.2798367,2.2632937,0.0,0,7.1075149,0.0,0.1633255,89.63781,7.7326131,405.37503,-9.2588167
2179,2179,178.6946,8.2192602,2.3187346,0.0,0,7.0571475,0.0,0.16729726,88.586754,7.6805806,405.23447,-9.2588043
2181,2181,178.695,8.3121586,2.3639536,0.0,0,7.0067787,0.0,0.17148429,88.998703,7.6291261,405.09387,-9.2594566
2183,2183,178.6954,8.4290953,2.4042916,0.0,0,6.9564114,0.0,0.17429,90.063789,7.5828733,404.95328,-9.2600164
2185,2185,178.6958,8.3994503,2.4593186,0.0,0,6.9060431,0.0,0.17843166,89.498894,7.5340791,404.81268,-9.2590294
2187,2187,178.6962,8.3427439,2.5023301,0.0,0,6.8556757,0.0,0.18250398,88.527893,7.4881873,404.67209,-9.2578707
2189,2189,178.6966,8.456152,2.5521994,0.0,0,6.8053074,0.0,0.18587297,89.222717,7.4370933,404.53152,-9.2586241
2191,2191,178.697,8.5709352,2.6032393,0.0,0,6.7554412,0.0,0.19013332,90.139069,7.3895283,404.39093,-9.2595043
2193,2193,178.6974,8.5566149,2.6456332,0.0,0,6.7074018,0.0,0.19396617,89.719116,7.337811,404.25034,-9.2602768
2195,2195,178.6978,8.5368299,2.70244,0.0,0,6.6594815,0.0,0.19788243,89.175293,7.2898726,404.10974,-9.2609348
2197,2197,178.6982,8.5470896,2.7421374,0.0,0,6.6115613,0.0,0.20169334,88.857491,7.2398801,403.96915,-9.2595224
2199,2199,178.6986,8.678072,2.7860107,0.0,0,6.5636415,0.0,0.20534776,89.905487,7.1921978,403.82858,-9.2582397
2201,2201,178.699,8.6917772,2.8463204,0.0,0,6.5157218,0.0,0.20955093,89.716721,7.1428652,403.68799,-9.2579966
2203,2203,178.6994,8.7082052,2.884769,0.0,0,6.467802,0.0,0.21335885,89.548965,7.0965528,403.54739,-9.2587662
2205,2205,178.6998,8.7585936,2.9339402,0.0,0,6.4198813,0.0,0.21723907,89.675896,7.0439401,403.4068,-9.2608833
2207,2207,178.7002,8.8023567,2.9906905,0.0,0,6.3719611,0.0,0.22160347,89.690231,6.993762,403.26624,-9.2609854
2209,2209,178.7006,8.8331661,3.0324411,0.0,0,6.3240414,0.0,0.22574995,89.68087,6.9447408,403.12564,-9.2596722
2211,2211,178.701,8.8453207,3.0847149,0.0,0,6.2761216,0.0,0.22969361,89.498749,6.8941998,402.98505,-9.2588024
2213,2213,178.7014,8.9009705,3.1368461,0.0,0,6.2282019,0.0,0.23398119,89.608757,6.8440065,402.84445,-9.2584972
2215,2215,178.7018,8.9356651,3.1795533,0.0,0,6.1802816,0.0,0.23809889,89.664902,6.7978587,402.70386,-9.2601824
2217,2217,178.7022,8.9434891,3.2288449,0.0,0,6.1339045,0.0,0.24175915,89.444267,6.7484374,402.56329,-9.2597036
2219,2219,178.7026,8.9934874,3.2769251,0.0,0,6.0883236,0.0,0.24614491,89.426506,6.6998711,402.4227,-9.2601213
2221,2221,178.703,9.0592461,3.3210564,0.0,0,6.042748,0.0,0.25004569,89.817398,6.6516109,402.2821,-9.2591286
2223,2223,178.7034,9.094101,3.373543,0.0,0,5.9971714,0.0,0.25407287,89.87738,6.6025434,402.08423,-9.2587862
2225,2225,178.7038,9.1099005,3.4243858,0.0,0,5.9515953,0.0,0.25900322,89.562897,6.5518198,401.80042,-9.2590914
2227,2227,178.7042,9.1279602,3.4742022,0.0,0,5.9060197,0.0,0.26303136,89.273727,6.4995298,401.51657,-9.259016
2229,2229,178.7046,9.1853485,3.5218463,0.0,0,5.8604436,0.0,0.26698458,89.443382,6.4520745,401.23276,-9.2599688
2231,2231,178.705,9.2594776,3.5699027,0.0,0,5.814867,0.0,0.27182466,89.76152,6.4047213,400.94894,-9.2590876
2233,2233,178.7054,9.2781582,3.6192799,0.0,0,5.7692914,0.0,0.27556753,89.665581,6.3530436,400.66513,-9.2582235
2235,2235,178.7058,9.2809601,3.6680167,0.0,0,5.7237153,0.0,0.27978769,89.282104,6.3066487,400.38129,-9.2578936
2237,2237,178.7062,9.3355179,3.7142982,0.0,0,5.6781397,0.0,0.28442693,89.271973,6.2564678,400.09747,-9.2587681
2239,2239,178.7066,9.3899593,3.7677057,0.0,0,5.6325636,0.0,0.28838417,89.513824,6.2063475,399.81366,-9.2595415
2241,2241,178.707,9.4283419,3.8136415,0.0,0,5.5874414,0.0,0.2929661,89.526192,6.159699,399.52985,-9.2602911
2243,2243,178.7074,9.4441605,3.8593485,0.0,0,5.5439734,0.0,0.29740408,89.281288,6.1100988,399.246,-9.2601347
2245,2245,178.7078,9.470665,3.9153464,0.0,0,5.5006132,0.0,0.30149701,89.210907,6.0632224,398.96219,-9.2588663
2247,2247,178.7082,9.5260868,3.958293,0.0,0,5.457253,0.0,0.30613056,89.234001,6.0108414,398.67838,-9.2579823
2249,2249,178.7086,9.5594387,4.0033779,0.0,0,5.4138932,0.0,0.31006378,89.240929,5.9614959,398.39456,-9.2589722
2251,2251,178.709,9.6161242,4.0589728,0.0,0,5.370533,0.0,0.31460011,89.308479,5.9148407,398.11072,-9.2599344
2253,2253,178.7094,9.6494904,4.1012163,0.0,0,5.3271732,0.0,0.31929132,89.244751,5.8682499,397.8269,-9.2603245
2255,2255,178.7098,9.6864624,4.1479378,0.0,0,5.283813,0.0,0.32318148,89.294914,5.8197618,397.54309,-9.2609215
2257,2257,178.7102,9.7067051,4.2038026,0.0,0,5.2404532,0.0,0.32813448,89.025299,5.7684588,397.25928,-9.2595406
2259,2259,178.7106,9.7597046,4.2441444,0.0,0,5.1970935,0.0,0.33259147,89.031166,5.7214689,396.97546,-9.2587557
2261,2261,178.711,9.8333836,4.2940173,0.0,0,5.1537333,0.0,0.33643723,89.418182,5.6710758,396.69162,-9.2585154
2263,2263,178.7114,9.8640394,4.3471184,0.0,0,5.110373,0.0,0.34162819,89.176453,5.6236172,396.40781,-9.2591419
2265,2265,178.7118,9.869236,4.3872581,0.0,0,5.0670133,0.0,0.34588984,88.891167,5.5762792,396.12399,-9.2603664
2267,2267,178.7122,9.8877735,4.4386244,0.0,0,5.0250483,0.0,0.35003093,88.717354,5.5269938,395.84018,-9.2598133
2269,2269,178.7126,9.9540157,4.4859447,0.0,0,4.9838037,0.0,0.35515353,88.775719,5.483079,395.55634,-9.2595177
2271,2271,178.713,10.015789,4.5278926,0.0,0,4.9425635,0.0,0.35909963,89.083374,5.4360914,395.27252,-9.2579794
2273,2273,178.7134,10.02865,4.5777512,0.0,0,4.9013238,0.0,0.36335802,88.755806,5.3862476,394.98901,-9.2587767
2275,2275,178.7138,10.046042,4.6219559,0.0,0,4.8600836,0.0,0.36828279,88.463707,5.3407984,394.70612,-9.2588758
2277,2277,178.7142,10.073727,4.6670842,0.0,0,4.8188438,0.0,0.37218609,88.402237,5.2941446,394.42322,-9.2597771
2279,2279,178.7146,10.152826,4.7145281,0.0,0,4.7776036,0.0,0.37661484,88.589996,5.2460032,394.14032,-9.2603159
2281,2281,178.715,10.204501,4.7573571,0.0,0,4.7363639,0.0,0.38145095,88.677078,5.2038245,393.85742,-9.2595196
2283,2283,178.7154,10.21195,4.807117,0.0,0,4.6951237,0.0,0.38543403,88.389587,5.1602497,393.57449,-9.259923
2285,2285,178.7158,10.230834,4.8497229,0.0,0,4.6538839,0.0,0.39014938,88.170937,5.1143594,393.2916,-9.2577829
2287,2287,178.7162,10.277773,4.8893199,0.0,0,4.6126437,0.0,0.39446941,88.088684,5.0697994,393.0087,-9.2584372
2289,2289,178.7166,10.319885,4.9406528,0.0,0,4.5714035,0.0,0.39851159,88.164497,5.027113,392.7258,-9.2597637
2291,2291,178.717,10.363314,4.979835,0.0,0,4.5305758,0.0,0.40320703,88.099365,4.9839697,392.4429,-9.2608156
2293,2293,178.7174,10.383986,5.0196009,0.0,0,4.4912457,0.0,0.40713972,87.994301,4.9399252,392.16,-9.2588148
2295,2295,178.7178,10.404065,5.0708857,0.0,0,4.4520135,0.0,0.41155267,87.750038,4.8958521,391.87708,-9.2589521
2297,2297,178.7182,10.450939,5.1070261,0.0,0,4.4127812,0.0,0.41609067,87.790253,4.8550787,391.59418,-9.2586803
2299,2299,178.7186,10.505749,5.1489458,0.0,0,4.3735495,0.0,0.41997811,87.828293,4.8094983,391.31128,-9.2583256
2301,2301,178.719,10.554223,5.1982617,0.0,0,4.3343177,0.0,0.42467687,87.885262,4.7698236,391.02838,-9.2584133
2303,2303,178.7194,10.576309,5.2296462,0.0,0,4.2950859,0.0,0.42874974,87.73687,4.7285395,390.74548,-9.2599745
2305,2305,178.7198,10.58078,5.2703857,0.0,0,4.2558532,0.0,0.43218124,87.425629,4.6843514,390.46255,-9.2602358
2307,2307,178.7202,10.624486,5.3171911,0.0,0,4.2166214,0.0,0.43711463,87.30896,4.6443353,390.17966,-9.2589712
2309,2309,178.7206,10.69039,5.3504467,0.0,0,4.1773891,0.0,0.44116634,87.517799,4.6065078,389.89676,-9.2589426
2311,2311,178.721,10.731611,5.394383,0.0,0,4.1381574,0.0,0.44487429,87.57383,4.5651894,389.61386,-9.2591667
2313,2313,178.7214,10.744685,5.4362593,0.0,0,4.0989256,0.0,0.44989857,87.217667,4.5245833,389.33096,-9.259347
2315,2315,178.7218,10.768649,5.47158,0.0,0,4.0596933,0.0,0.45353341,87.09301,4.485889,389.04807,-9.2600842
2317,2317,178.7222,10.82709,5.5136471,0.0,0,4.0217257,0.0,0.45737979,87.163895,4.4437199,388.76514,-9.2594404
2319,2319,178.7226,10.894411,5.5520158,0.0,0,3.9844091,0.0,0.46232456,87.296097,4.4047394,388.48224,-9.2589388
2321,2321,178.723,10.92461,5.5896211,0.0,0,3.9470971,0.0,0.46581817,87.266304,4.3647757,388.19934,-9.2589426
2323,2323,178.7234,10.946791,5.630877,0.0,0,3.9097853,0.0,0.46997336,87.09433,4.3264408,387.90332,-9.2587032
2325,2325,178.7238,10.98445,5.6655025,0.0,0,3.8724732,0.0,0.47453991,86.947815,4.2887392,387.57669,-9.2591028
2327,2327,178.7242,11.043018,5.7066932,0.0,0,3.8351612,0.0,0.47798359,87.102448,4.2497497,387.25006,-9.258276
2329,2329,178.7246,11.103601,5.745049,0.0,0,3.7978492,0.0,0.4824039,87.243073,4.2146115,386.92346,-9.2585373
2331,2331,178.725,11.14247,5.7793474,0.0,0,3.7605371,0.0,0.48680454,87.157654,4.176065,386.59683,-9.2589617
2333,2333,178.7254,11.186238,5.8264933,0.0,0,3.7232251,0.0,0.49077833,87.192497,4.1364617,386.2702,-9.2588396
2335,2335,178.7258,11.224271,5.860775,0.0,0,3.6859133,0.0,0.49519962,87.028702,4.0976138,385.94357,-9.2589397
2337,2337,178.7262,11.265972,5.894474,0.0,0,3.6486013,0.0,0.49905139,87.073463,4.0566955,385.61697,-9.2588577
2339,2339,178.7266,11.339179,5.9406624,0.0,0,3.611289,0.0,0.50301588,87.157845,4.020762,385.29034,-9.2574272
2341,2341,178.727,11.39083,5.9702425,0.0,0,3.5743496,0.0,0.50758052,87.224312,3.9812398,384.96371,-9.2577305
2343,2343,178.7274,11.403419,6.0071993,0.0,0,3.5387647,0.0,0.51119143,87.127785,3.9462509,384.63708,-9.2593088
2345,2345,178.7278,11.444193,6.0546393,0.0,0,3.5032687,0.0,0.51596236,86.996597,3.9066801,384.31046,-9.2598867
2347,2347,178.7282,11.49658,6.0851617,0.0,0,3.4677725,0.0,0.5205394,86.948792,3.8696756,383.98386,-9.2594051
2349,2349,178.7286,11.56765,6.1247568,0.0,0,3.4322767,0.0,0.52413684,87.120667,3.8323233,383.65723,-9.2587585
2351,2351,178.729,11.629387,6.1699195,0.0,0,3.3967807,0.0,0.52913469,87.129883,3.7942333,383.3306,-9.2580338
2353,2353,178.7294,11.655787,6.1964707,0.0,0,3.3612847,0.0,0.53306311,87.018127,3.7563555,383.00397,-9.2578001
2355,2355,178.7298,11.68609,6.2365208,0.0,0,3.3257885,0.0,0.53655785,86.98568,3.7215488,382.67734,-9.2582264
2357,2357,178.7302,11.758909,6.2761979,0.0,0,3.2902927,0.0,0.54164273,87.042198,3.6828053,382.35074,-9.2587662
2359,2359,178.7306,11.83245,6.3082132,0.0,0,3.2547965,0.0,0.54557782,87.25972,3.6458433,382.02411,-9.2597466
2361,2361,178.731,11.895963,6.3499298,0.0,0,3.2193005,0.0,0.54955572,87.324203,3.6061306,381.69748,-9.2581968
2363,2363,178.7314,11.910388,6.3866262,0.0,0,3.1838045,0.0,0.55477369,87.108078,3.5707104,381.37085,-9.2581692
2365,2365,178.7318,11.956681,6.421792,0.0,0,3.1483085,0.0,0.55846423,87.092087,3.5323145,381.04422,-9.2580223
2367,2367,178.7322,12.03016,6.4615889,0.0,0,3.1139498,0.0,0.56262726,87.204895,3.4962683,380.71762,-9.2591782
2369,2369,178.7326,12.113177,6.4948969,0.0,0,3.0801783,0.0,0.56759536,87.308952,3.459641,380.39099,-9.2596025
2371,2371,178.733,12.163353,6.5321393,0.0,0,3.0464103,0.0,0.57107282,87.447556,3.4219244,380.06436,-9.259408
2373,2373,178.7334,12.184426,6.5713396,0.0,0,3.0126421,0.0,0.57572538,87.216263,3.386868,379.72769,-9.2594833
2375,2375,178.7338,12.246223,6.6033907,0.0,0,2.9788742,0.0,0.58044541,87.234833,3.3493891,379.36096,-9.2586403
2377,2377,178.7342,12.33418,6.6451159,0.0,0,2.9451063,0.0,0.5841772,87.476181,3.3150725,378.9942,-9.2587814
2379,2379,178.7346,12.404664,6.6801925,0.0,0,2.9113381,0.0,0.58905953,87.637451,3.275847,378.62744,-9.2582617
2381,2381,178.735,12.4494,6.7132039,0.0,0,2.8775702,0.0,0.5934062,87.549683,3.2387288,378.26068,-9.2593222
2383,2383,178.7354,12.492085,6.7575321,0.0,0,2.8438022,0.0,0.59762168,87.429443,3.2053709,377.89392,-9.2599192
2385,2385,178.7358,12.539669,6.7882786,0.0,0,2.810034,0.0,0.60240686,87.349449,3.1697748,377.52719,-9.2597122
2387,2387,178.7362,12.627095,6.8234129,0.0,0,2.7762663,0.0,0.60639024,87.602783,3.1352639,377.16043,-9.2585487
2389,2389,178.7366,12.709378,6.8682356,0.0,0,2.7424982,0.0,0.61105412,87.80481,3.0992198,376.79367,-9.2568445
2391,2391,178.737,12.75417,6.8956151,0.0,0,2.7090681,0.0,0.61583722,87.6968,3.0643892,376.42691,-9.2572355
2393,2393,178.7374,12.804595,6.9316206,0.0,0,2.6768675,0.0,0.61943102,87.701027,3.0300057,376.06015,-9.2581291
2395,2395,178.7378,12.876282,6.9752169,0.0,0,2.6447473,0.0,0.62469107,87.711891,2.9881859,375.69342,-9.2579927
2397,2397,178.7382,12.961167,7.0016804,0.0,0,2.6126273,0.0,0.62893575,87.911995,2.9554577,375.32666,-9.2571936
2399,2399,178.7386,13.051438,7.041986,0.0,0,2.580507,0.0,0.63286781,88.150574,2.9183183,374.9599,-9.2577553
2401,2401,178.739,13.089659,7.082664,0.0,0,2.5483871,0.0,0.63849717,87.96479,2.8800931,374.59314,-9.2578697
2403,2403,178.7394,13.131121,7.112371,0.0,0,2.5162671,0.0,0.64270389,87.872658,2.8458393,374.22638,-9.2586164
2405,2405,178.7398,13.201687,7.153286,0.0,0,2.4841471,0.0,0.64686704,87.98822,2.8092422,373.85965,-9.2577047
2407,2407,178.7402,13.293741,7.1870484,0.0,0,2.4520271,0.0,0.65217233,88.103119,2.7726879,373.49289,-9.2582293
2409,2409,178.7406,13.367547,7.2158456,0.0,0,2.4199073,0.0,0.65564543,88.298828,2.7379553,373.12613,-9.2577858
2411,2411,178.741,13.410415,7.2540703,0.0,0,2.3877871,0.0,0.65992856,88.219131,2.7046993,372.75937,-9.2572575
2413,2413,178.7414,13.458322,7.2873716,0.0,0,2.3556671,0.0,0.66540438,88.049416,2.6683595,372.39261,-9.2570705
2415,2415,178.7418,13.54109,7.3233595,0.0,0,2.3235471,0.0,0.66907924,88.254616,2.6340969,372.02588,-9.257287
2417,2417,178.7422,13.628839,7.3607736,0.0,0,2.2924592,0.0,0.67399567,88.409622,2.6032104,371.65912,-9.2575693
2419,2419,178.7426,13.711004,7.3898487,0.0,0,2.261904,0.0,0.6789251,88.480614,2.5672598,371.29236,-9.2580347
2421,2421,178.743,13.762789,7.4291768,0.0,0,2.2313521,0.0,0.68272924,88.542496,2.5332313,370.9256,-9.2581434
2423,2423,178.7434,13.811892,7.4610267,0.0,0,2.2008002,0.0,0.68758929,88.420952,2.4994743,370.43301,-9.2574883
2425,2425,178.7438,13.900988,7.4882784,0.0,0,2.170248,0.0,0.69177568,88.551994,2.4679391,369.43701,-9.2573681
2427,2427,178.7442,13.983185,7.5277472,0.0,0,2.1396961,0.0,0.69559783,88.769585,2.4350131,368.44104,-9.2569084
2429,2429,178.7446,14.054851,7.5552907,0.0,0,2.109144,0.0,0.70050925,88.777519,2.3985147,367.44507,-9.2579308
2431,2431,178.745,14.113359,7.5874715,0.0,0,2.0785921,0.0,0.70445031,88.833115,2.3673847,366.4491,-9.257987
2433,2433,178.7454,14.183224,7.6293449,0.0,0,2.0480402,0.0,0.7092092,88.795547,2.3350518,365.45313,-9.2586479
2435,2435,178.7458,14.25666,7.6543608,0.0,0,2.0174882,0.0,0.71426123,88.817665,2.3026195,364.45715,-9.2572832
2437,2437,178.7462,14.357068,7.6876454,0.0,0,1.986936,0.0,0.71776742,89.069084,2.2689052,363.46118,-9.2575693
2439,2439,178.7466,14.430157,7.72579,0.0,0,1.9563839,0.0,0.72274649,89.148453,2.2357841,362.46521,-9.2574463
2441,2441,178.747,14.482532,7.7483296,0.0,0,1.9261371,0.0,0.72726065,89.07605,2.2042632,361.46924,-9.2577925
2443,2443,178.7474,14.537132,7.7818046,0.0,0,1.8970003,0.0,0.73053223,89.127419,2.1737745,360.47327,-9.2574463
2445,2445,178.7478,14.611658,7.8190002,0.0,0,1.8679363,0.0,0.73598528,89.030701,2.1408441,359.47729,-9.2574749
2447,2447,178.7482,14.703915,7.8422256,0.0,0,1.8388723,0.0,0.74006838,89.230476,2.1086798,358.48129,-9.2568007
2449,2449,178.7486,14.787512,7.8771296,0.0,0,1.8098083,0.0,0.74370897,89.445107,2.0817342,357.48532,-9.2566566
2451,2451,178.749,14.851816,7.9077487,0.0,0,1.7807442,0.0,0.74909306,89.345352,2.0476432,356.48935,-9.2571783
2453,2453,178.7494,14.913383,7.9328542,0.0,0,1.7516803,0.0,0.75254321,89.425369,2.0181384,355.49338,-9.2572165
2455,2455,178.7498,14.992713,7.9684691,0.0,0,1.7226163,0.0,0.75652188,89.535599,1.9915457,354.49741,-9.2574453
2457,2457,178.7502,15.10831,7.9964318,0.0,0,1.6935523,0.0,0.76189953,89.720383,1.9608788,353.50143,-9.2575693
2459,2459,178.7506,15.194688,8.0260639,0.0,0,1.6644882,0.0,0.76539797,89.96949,1.932878,352.50546,-9.2564793
2461,2461,178.751,15.254029,8.0607319,0.0,0,1.6354243,0.0,0.77004832,89.850273,1.901464,351.50949,-9.256568
2463,2463,178.7514,15.314003,8.0862904,0.0,0,1.6063603,0.0,0.77505481,89.807289,1.8701522,350.51352,-9.2568722
2465,2465,178.7518,15.402235,8.118187,0.0,0,1.5772963,0.0,0.77816081,90.019463,1.8423473,349.51755,-9.2567015
2467,2467,178.7522,15.517645,8.1457586,0.0,0,1.5491643,0.0,0.78266013,90.301399,1.811937,348.52158,-9.2571974
2469,2469,178.7526,15.600574,8.1702213,0.0,0,1.5215131,0.0,0.78715807,90.361176,1.7854003,347.5256,-9.2572536
2471,2471,178.753,15.657546,8.209507,0.0,0,1.4938651,0.0,0.79122823,90.363998,1.7514683,346.5296,-9.2569418
2473,2473,178.7534,15.738964,8.2361765,0.0,0,1.4662172,0.0,0.79631722,90.325302,1.724535,345.62604,-9.2564669
2475,2475,178.7538,15.851192,8.2604389,0.0,0,1.4385692,0.0,0.80002815,90.615662,1.6938174,345.24597,-9.2558203
2477,2477,178.7542,15.970768,8.2980661,0.0,0,1.4109212,0.0,0.80400634,90.949753,1.6663651,344.86591,-9.2565947
2479,2479,178.7546,16.057251,8.3177948,0.0,0,1.3832732,0.0,0.80876499,91.004044,1.637551,344.48584,-9.2576914
2481,2481,178.755,16.113394,8.3463593,0.0,0,1.3556252,0.0,0.81241703,91.027954,1.6079895,344.10577,-9.2580061
2483,2483,178.7554,16.204353,8.3848248,0.0,0,1.3279773,0.0,0.81736976,91.083122,1.5813016,343.72571,-9.2569857
2485,2485,178.7558,16.31566,8.4041672,0.0,0,1.3003292,0.0,0.82201421,91.282745,1.5491769,343.34564,-9.2550955
2487,2487,178.7562,16.443243,8.4362946,0.0,0,1.2726812,0.0,0.82553661,91.644585,1.5199641,342.96558,-9.2543964
2489,2489,178.7566,16.524258,8.4710827,0.0,0,1.2450333,0.0,0.83101493,91.563004,1.4903696,342.58551,-9.256382
2491,2491,178.757,16.604446,8.4892282,0.0,0,1.2176626,0.0,0.83509362,91.632645,1.4600768,342.20544,-9.2570658
2493,2493,178.7574,16.677507,8.5211105,0.0,0,1.1913005,0.0,0.8382681,91.782906,1.4352988,341.82538,-9.257452
2495,2495,178.7578,16.812313,8.5510979,0.0,0,1.1650044,0.0,0.84404105,91.957832,1.4076637,341.44531,-9.2563124
2497,2497,178.7582,16.946678,8.5739422,0.0,0,1.1387082,0.0,0.84763145,92.381706,1.3802602,341.06525,-9.2550793
2499,2499,178.7586,17.041187,8.6070023,0.0,0,1.1124123,0.0,0.85156566,92.550865,1.3498297,340.68518,-9.2555885
2501,2501,178.759,17.119257,8.6355457,0.0,0,1.0861163,0.0,0.85753506,92.418137,1.3235327,340.30511,-9.2561064
2503,2503,178.7594,17.223999,8.6603117,0.0,0,1.0598202,0.0,0.86082685,92.657372,1.2959206,339.92505,-9.2559166
2505,2505,178.7598,17.355461,8.6901093,0.0,0,1.0335243,0.0,0.86508709,92.962891,1.2673277,339.54498,-9.2556171
2507,2507,178.7602,17.485247,8.7121325,0.0,0,1.0072283,0.0,0.87009805,93.208984,1.2381459,339.16492,-9.2547331
2509,2509,178.7606,17.570072,8.7450428,0.0,0,0.98093224,0.0,0.87346673,93.37159,1.2103826,338.78485,-9.2556477
2511,2511,178.761,17.65395,8.7746286,0.0,0,0.95463622,0.0,0.87867761,93.289337,1.1779625,338.40479,-9.255167
2513,2513,178.7614,17.772833,8.7959976,0.0,0,0.92834032,0.0,0.88351965,93.475571,1.1550606,338.02472,-9.2561436
2515,2515,178.7618,17.895388,8.8303614,0.0,0,0.9020443,0.0,0.88710964,93.791534,1.1255394,337.64465,-9.2549534
2517,2517,178.7622,18.023222,8.8540812,0.0,0,0.87659597,0.0,0.89213485,93.989029,1.0957106,337.26459,-9.2541494
2519,2519,178.7626,18.12385,8.8749924,0.0,0,0.85158527,0.0,0.89591515,94.143486,1.0699338,336.88452,-9.2542887
2521,2521,178.763,18.219595,8.9104633,0.0,0,0.82657719,0.0,0.8997708,94.313538,1.0441083,336.50446,-9.2553711
2523,2523,178.7634,18.352518,8.9313555,0.0,0,0.80156928,0.0,0.90497416,94.464249,1.016086,336.1991,-9.2558556
2525,2525,178.7638,18.475046,8.9581289,0.0,0,0.77656126,0.0,0.90885067,94.752434,0.98740166,336.56604,-9.255147
2527,2527,178.7642,18.610804,8.9957876,0.0,0,0.75155324,0.0,0.91411197,94.955177,0.96143979,336.93295,-9.2538452
2529,2529,178.7646,18.720736,9.012804,0.0,0,0.72654527,0.0,0.91901976,95.020004,0.933411,337.29987,-9.2548094
2531,2531,178.765,18.823694,9.0390444,0.0,0,0.70153725,0.0,0.92203575,95.291512,0.90711313,337.66681,-9.2555447
2533,2533,178.7654,18.945206,9.0715914,0.0,0,0.67652929,0.0,0.92724216,95.356781,0.88231903,338.03372,-9.2550802
2535,2535,178.7658,19.084345,9.0864029,0.0,0,0.65152127,0.0,0.93129146,95.662361,0.854141,338.40067,-9.2550259
2537,2537,178.7662,19.23509,9.1152716,0.0,0,0.62651324,0.0,0.9344517,96.156067,0.83010954,338.76758,-9.2555189
2539,2539,178.7666,19.350483,9.1468267,0.0,0,0.60150528,0.0,0.94072354,96.085495,0.80337971,339.13449,-9.2554331
2541,2541,178.767,19.456026,9.1675463,0.0,0,0.57674497,0.0,0.94484454,96.224358,0.77532494,339.50143,-9.2545633
2543,2543,178.7674,19.584236,9.2003336,0.0,0,0.55288589,0.0,0.94880748,96.446533,0.74858809,339.86835,-9.255312
2545,2545,178.7678,19.713629,9.2244978,0.0,0,0.52908581,0.0,0.95467269,96.546951,0.72514611,340.23526,-9.25564
2547,2547,178.7682,19.863016,9.244648,0.0,0,0.5052858,0.0,0.95779908,96.98745,0.69635284,340.6022,-9.2548828
2549,2549,178.7686,19.974628,9.2733183,0.0,0,0.48148578,0.0,0.96181393,97.157288,0.66991347,340.96912,-9.2539654
2551,2551,178.769,20.096024,9.295228,0.0,0,0.4576858,0.0,0.9673636,97.196671,0.64807636,341.33603,-9.2540064
2553,2553,178.7694,20.231371,9.3216839,0.0,0,0.43388578,0.0,0.9705857,97.531113,0.62046212,341.70297,-9.2546892
2555,2555,178.7698,20.391554,9.3503323,0.0,0,0.4100858,0.0,0.9754675,97.795441,0.59589362,342.06989,-9.2549219
2557,2557,178.7702,20.545828,9.370471,0.0,0,0.38628578,0.0,0.98073888,98.001862,0.56783175,342.4368,-9.2542219
2559,2559,178.7706,20.65016,9.4011917,0.0,0,0.36248577,0.0,0.98415291,98.194191,0.5449965,342.80374,-9.2531948