File: examples/hot axisymmetric compression example/data/03 trimmed data/testID_0135.csv
level_0,index,Time(sec),Force(kN),Jaw(mm),PowAngle(deg),Power(W),Pram,PTemp,Strain,Stress(MPa),Stroke(mm),TC1(C),wedge(mm)
1873,1873,155.3448,1.1591333,0.038278293,0.0,0,9.0337067,0.0,0.0023505834,13.593298,10.0417,331.97104,-9.3067589
1875,1875,155.3452,3.8391709,0.07576222,0.0,0,8.9751787,0.0,0.004608199,44.704453,9.9791651,332.08072,-9.3068399
1877,1877,155.3456,5.6797256,0.119481,0.0,0,8.9166508,0.0,0.0080047138,70.405487,9.9199362,332.1904,-9.3051519
1879,1879,155.346,6.5432987,0.18562315,0.0,0,8.8581219,0.0,0.011464315,81.084343,9.8470488,332.30008,-9.3023567
1881,1881,155.3464,7.1073799,0.29927117,0.0,0,8.7995939,0.0,0.019553082,88.414581,9.766923,332.40976,-9.3018894
1883,1883,155.3468,7.7221799,0.37501228,0.0,0,8.7416534,0.0,0.02492414,94.898056,9.6745338,332.51944,-9.3020668
1885,1885,155.3472,8.1628437,0.4735606,0.0,0,8.6858492,0.0,0.031053908,100.51572,9.5806141,332.62912,-9.3017092
1887,1887,155.3476,8.7290859,0.52054697,0.0,0,8.6301851,0.0,0.035388146,106.64704,9.4964256,332.7388,-9.3011446
1889,1889,155.348,8.5535288,0.5628804,0.0,0,8.574522,0.0,0.037774369,105.37555,9.4273472,332.84848,-9.2993011
1891,1891,155.3484,8.7617273,0.64329618,0.0,0,8.518857,0.0,0.043202978,106.00609,9.3645163,332.95816,-9.2998018
1893,1893,155.3488,9.1322584,0.68240106,0.0,0,8.4631929,0.0,0.046429303,110.84363,9.2989101,333.0654,-9.2998209
1895,1895,155.3492,9.3572559,0.76828927,0.0,0,8.4075298,0.0,0.051657207,112.76898,9.2317066,333.16534,-9.2991152
1897,1897,155.3496,9.1771364,0.86437494,0.0,0,8.3518648,0.0,0.058741193,110.76372,9.1544733,333.26529,-9.299921
1899,1899,155.35,9.2920256,0.93382192,0.0,0,8.2962017,0.0,0.063983761,110.3189,9.0750008,333.36523,-9.3003502
1901,1901,155.3504,9.5192327,1.0089239,0.0,0,8.2405376,0.0,0.068938039,113.26202,9.0017767,333.46521,-9.2990894
1903,1903,155.3508,9.5786724,1.0511856,0.0,0,8.1848736,0.0,0.072599664,112.99609,8.9315138,333.56516,-9.2991743
1905,1905,155.3512,9.7302265,1.1003945,0.0,0,8.1292095,0.0,0.0758316,115.0556,8.8717623,333.6651,-9.2991133
1907,1907,155.3516,9.5296907,1.1664138,0.0,0,8.0735455,0.0,0.080364987,111.75169,8.8164616,333.76505,-9.3004246
1909,1909,155.352,10.003962,1.2111076,0.0,0,8.0196619,0.0,0.084020741,116.61097,8.7600842,333.86499,-9.3004379
1911,1911,155.3524,9.9430161,1.2933317,0.0,0,7.9666953,0.0,0.089409277,115.94748,8.6981974,333.96497,-9.2995996
1913,1913,155.3528,9.9906025,1.3647949,0.0,0,7.9137359,0.0,0.094754301,115.6599,8.6297226,334.06491,-9.298934
1915,1915,155.3532,9.8699818,1.4291692,0.0,0,7.8607755,0.0,0.099952213,113.83443,8.5600929,334.16486,-9.299037
1917,1917,155.3536,10.090405,1.4959933,0.0,0,7.8078156,0.0,0.1044347,115.4842,8.4948406,334.2648,-9.2999401
1919,1919,155.354,10.161061,1.5295426,0.0,0,7.7548552,0.0,0.10725559,116.22135,8.4315081,334.36475,-9.300704
1921,1921,155.3544,10.249875,1.5867324,0.0,0,7.7018952,0.0,0.11155573,116.64887,8.3797235,334.46472,-9.3010616
1923,1923,155.3548,10.185847,1.6485093,0.0,0,7.6489348,0.0,0.11567579,115.5039,8.3251543,334.56467,-9.300909
1925,1925,155.3552,10.417478,1.6920284,0.0,0,7.5959754,0.0,0.11943962,117.32692,8.2702274,334.66461,-9.2995443
1927,1927,155.3556,10.417029,1.7593325,0.0,0,7.543015,0.0,0.12426782,117.28234,8.2115355,334.76456,-9.2988167
1929,1929,155.356,10.482315,1.8242031,0.0,0,7.4900556,0.0,0.12890838,117.06621,8.15273,334.8645,-9.299078
1931,1931,155.3564,10.495643,1.879208,0.0,0,7.4370952,0.0,0.13367057,117.00807,8.0931435,334.96448,-9.3004665
1933,1933,155.3568,10.536559,1.9307352,0.0,0,7.3846664,0.0,0.13738585,116.72497,8.0327435,335.06442,-9.3000803
1935,1935,155.3572,10.652377,1.977481,0.0,0,7.3341722,0.0,0.14081424,117.87108,7.9777188,335.16437,-9.2992678
1937,1937,155.3576,10.634737,2.0272987,0.0,0,7.2838039,0.0,0.1450787,117.03008,7.9245181,335.26431,-9.2991781
1939,1939,155.358,10.73982,2.0777459,0.0,0,7.2334356,0.0,0.14845818,117.77348,7.8749065,335.36426,-9.2997808
1941,1941,155.3584,10.797514,2.1352813,0.0,0,7.1830673,0.0,0.15321213,117.79482,7.8204594,335.46423,-9.2998295
1943,1943,155.3588,10.900977,2.1882582,0.0,0,7.1326995,0.0,0.1574358,118.57482,7.7678704,335.54163,-9.2988043
1945,1945,155.3592,10.863918,2.2433038,0.0,0,7.0823312,0.0,0.16123544,117.74972,7.7141223,335.55133,-9.2991695
1947,1947,155.3596,10.908585,2.2992022,0.0,0,7.0319633,0.0,0.16621432,117.52422,7.659678,335.56107,-9.2990141
1949,1949,155.36,10.994457,2.3395083,0.0,0,6.981595,0.0,0.16923502,117.99751,7.6069689,335.5708,-9.2990112
1951,1951,155.3604,11.110624,2.3897243,0.0,0,6.9312277,0.0,0.1728743,118.85297,7.5550556,335.58051,-9.2990942
1953,1953,155.3608,11.088168,2.4432595,0.0,0,6.8808594,0.0,0.17778003,118.2726,7.5038519,335.59024,-9.2992125
1955,1955,155.3612,11.105292,2.4939177,0.0,0,6.830492,0.0,0.18115692,117.94181,7.4544363,335.59998,-9.2996807
1957,1957,155.3616,11.214992,2.5475187,0.0,0,6.7801232,0.0,0.18563634,118.43129,7.4023719,335.60968,-9.2998705
1959,1959,155.362,11.308801,2.5929458,0.0,0,6.7313671,0.0,0.18976173,119.03793,7.3495846,335.61942,-9.2992964
1961,1961,155.3624,11.319166,2.6511934,0.0,0,6.6834416,0.0,0.19363637,118.78576,7.2971015,335.62912,-9.2995634
1963,1963,155.3628,11.322593,2.6988747,0.0,0,6.6355219,0.0,0.19816615,118.18777,7.2487154,335.63885,-9.2991953
1965,1965,155.3632,11.38709,2.7397406,0.0,0,6.5876017,0.0,0.20140736,118.46917,7.1984816,335.64859,-9.2995625
1967,1967,155.3636,11.495247,2.7983968,0.0,0,6.5396819,0.0,0.20558257,118.97424,7.1455402,335.65829,-9.2998381
1969,1969,155.364,11.547348,2.8412855,0.0,0,6.4917622,0.0,0.20990214,119.20971,7.0978374,335.66803,-9.2997026
1971,1971,155.3644,11.565466,2.8888552,0.0,0,6.4438419,0.0,0.21346046,118.8939,7.0500312,335.67776,-9.2994785
1973,1973,155.3648,11.609278,2.9482465,0.0,0,6.3959212,0.0,0.21811149,118.82182,6.9996848,335.68747,-9.2990656
1975,1975,155.3652,11.671983,2.9861882,0.0,0,6.3480015,0.0,0.22197007,118.99942,6.9491901,335.6972,-9.2997465
1977,1977,155.3656,11.735884,3.0390983,0.0,0,6.3000817,0.0,0.22563535,119.16814,6.9033899,335.70694,-9.2992344
1979,1979,155.366,11.769296,3.0936801,0.0,0,6.252162,0.0,0.23057,118.98772,6.8499374,335.71664,-9.2991848
1981,1981,155.3664,11.834893,3.1339464,0.0,0,6.2042422,0.0,0.23417592,119.15174,6.7989225,335.72638,-9.2998438
1983,1983,155.3668,11.874241,3.1879795,0.0,0,6.1568027,0.0,0.2381532,119.08519,6.749867,335.73608,-9.3000107
1985,1985,155.3672,11.921841,3.2328184,0.0,0,6.1111121,0.0,0.24265844,118.94099,6.6998219,335.74582,-9.3002863
1987,1987,155.3676,11.99191,3.2784057,0.0,0,6.065536,0.0,0.24627861,119.26478,6.6499748,335.75555,-9.2990656
1989,1989,155.368,12.044986,3.3320923,0.0,0,6.0199599,0.0,0.25057948,119.30433,6.601697,335.76526,-9.2990274
1991,1991,155.3684,12.115691,3.3769073,0.0,0,5.9743834,0.0,0.25510073,119.48695,6.5529079,335.77499,-9.2991962
1993,1993,155.3688,12.126412,3.4289088,0.0,0,5.9288077,0.0,0.25892854,119.08891,6.5041752,335.75851,-9.2995682
1995,1995,155.3692,12.165275,3.4745679,0.0,0,5.8832321,0.0,0.26298547,118.98914,6.4591026,335.66345,-9.3003597
1997,1997,155.3696,12.244893,3.5185895,0.0,0,5.8376555,0.0,0.26734269,119.32993,6.4069996,335.56836,-9.2998619
1999,1999,155.37,12.309864,3.5725951,0.0,0,5.792079,0.0,0.27131981,119.48298,6.3611064,335.4733,-9.2988977
2001,2001,155.3704,12.346461,3.6165562,0.0,0,5.7465038,0.0,0.27560145,119.34702,6.3146544,335.3782,-9.2986183
2003,2003,155.3708,12.376193,3.6635056,0.0,0,5.7009277,0.0,0.27978167,119.09926,6.2598538,335.28314,-9.298872
2005,2005,155.3712,12.429432,3.7183619,0.0,0,5.6553516,0.0,0.2839182,119.12636,6.2149382,335.18805,-9.3002558
2007,2007,155.3716,12.514719,3.7573006,0.0,0,5.6097755,0.0,0.28818902,119.42724,6.170536,335.09299,-9.3012667
2009,2009,155.372,12.565833,3.8039312,0.0,0,5.5656581,0.0,0.29210266,119.44324,6.1217093,334.99792,-9.3008585
2011,2011,155.3724,12.588557,3.8565321,0.0,0,5.5222936,0.0,0.29646945,119.16331,6.0756316,334.90283,-9.2994833
2013,2013,155.3728,12.632616,3.8968222,0.0,0,5.4789333,0.0,0.30091467,118.99057,6.0285873,334.80777,-9.2985888
2015,2015,155.3732,12.681898,3.946928,0.0,0,5.4355736,0.0,0.30469796,119.06123,5.9793096,334.71268,-9.2983475
2017,2017,155.3736,12.761629,3.9981651,0.0,0,5.3922133,0.0,0.30936274,119.13886,5.934021,334.61761,-9.299674
2019,2019,155.374,12.803366,4.0371881,0.0,0,5.3488536,0.0,0.31344482,119.12739,5.8887043,334.52252,-9.3003654
2021,2021,155.3744,12.846189,4.084424,0.0,0,5.3054934,0.0,0.31710169,119.04428,5.842453,334.42746,-9.3009939
2023,2023,155.3748,12.897276,4.1323857,0.0,0,5.2621331,0.0,0.32195321,118.91434,5.7938738,334.3324,-9.3005972
2025,2025,155.3752,12.935925,4.1737056,0.0,0,5.2187734,0.0,0.32582778,118.80418,5.746944,334.2373,-9.2985983
2027,2027,155.3756,13.013003,4.2221026,0.0,0,5.1754136,0.0,0.32971498,118.97128,5.7011471,334.14224,-9.2987089
2029,2029,155.376,13.073525,4.2693133,0.0,0,5.1320534,0.0,0.33492976,119.04707,5.6551867,334.04715,-9.2993155
2031,2031,155.3764,13.112039,4.3131661,0.0,0,5.0886931,0.0,0.3384527,118.98683,5.6100831,333.95209,-9.2998714
2033,2033,155.3768,13.154297,4.3595939,0.0,0,5.0457683,0.0,0.34272772,118.79623,5.5660486,333.85699,-9.3011427
2035,2035,155.3772,13.203218,4.4010959,0.0,0,5.0044241,0.0,0.34740645,118.66116,5.5214028,333.76193,-9.2999992
2037,2037,155.3776,13.271134,4.4483509,0.0,0,4.9631839,0.0,0.35096449,118.91875,5.4739146,333.66684,-9.2999229
2039,2039,155.378,13.334622,4.4918356,0.0,0,4.9219441,0.0,0.35552752,118.94623,5.4308257,333.57178,-9.2987614
2041,2041,155.3784,13.373243,4.5321574,0.0,0,4.8807039,0.0,0.35974675,118.81467,5.3846421,333.47672,-9.2991552
2043,2043,155.3788,13.399556,4.5870352,0.0,0,4.8394642,0.0,0.36392939,118.58612,5.3403339,333.33652,-9.2999935
2045,2045,155.3792,13.457165,4.6252828,0.0,0,4.798224,0.0,0.3686015,118.41456,5.2930055,333.0611,-9.3005543
2047,2047,155.3796,13.550257,4.6665959,0.0,0,4.7569842,0.0,0.37233898,118.79715,5.2496953,332.78564,-9.3005276
2049,2049,155.38,13.610285,4.7208624,0.0,0,4.715744,0.0,0.37695566,118.86362,5.2073588,332.51019,-9.2991037
2051,2051,155.3804,13.647268,4.7567749,0.0,0,4.6745043,0.0,0.38145283,118.62481,5.1624937,332.23477,-9.2982807
2053,2053,155.3808,13.678047,4.8007107,0.0,0,4.6332641,0.0,0.3851231,118.46838,5.1203671,331.95932,-9.298687
2055,2055,155.3812,13.758043,4.8526044,0.0,0,4.5920238,0.0,0.38995498,118.50101,5.0747156,331.68387,-9.2986679
2057,2057,155.3816,13.834229,4.8871007,0.0,0,4.5507841,0.0,0.3943108,118.73004,5.0316,331.40845,-9.2990932
2059,2059,155.382,13.879668,4.9367285,0.0,0,4.5108657,0.0,0.39828721,118.6501,4.9896722,331.133,-9.2990322
2061,2061,155.3824,13.918731,4.9840398,0.0,0,4.4716296,0.0,0.40351924,118.35901,4.9421487,330.85754,-9.2987471
2063,2063,155.3828,13.965414,5.0197291,0.0,0,4.4323978,0.0,0.40734193,118.26741,4.8977733,330.58212,-9.2994871
2065,2065,155.3832,14.035857,5.067492,0.0,0,4.3931656,0.0,0.41138682,118.35195,4.8551917,330.30667,-9.2990484
2067,2067,155.3836,14.134053,5.1083035,0.0,0,4.3539338,0.0,0.41639787,118.59338,4.8139119,330.03122,-9.2986698
2069,2069,155.384,14.185126,5.1489739,0.0,0,4.314702,0.0,0.42005554,118.63465,4.7693543,329.7558,-9.2987299
2071,2071,155.3844,14.213331,5.1943502,0.0,0,4.2754698,0.0,0.42431304,118.31072,4.7258554,329.48035,-9.298501
2073,2073,155.3848,14.261034,5.2349844,0.0,0,4.2362375,0.0,0.4293094,118.18628,4.6824756,329.2049,-9.2989902
2075,2075,155.3852,14.333986,5.2804766,0.0,0,4.1970053,0.0,0.43311316,118.25744,4.638515,328.92947,-9.299839
2077,2077,155.3856,14.406914,5.3233943,0.0,0,4.1577735,0.0,0.43774655,118.35737,4.5986776,328.65402,-9.2989922
2079,2079,155.386,14.459109,5.3595209,0.0,0,4.1185417,0.0,0.44225121,118.27355,4.5579033,328.37857,-9.2991924
2081,2081,155.3864,14.495157,5.4075823,0.0,0,4.0793095,0.0,0.44602644,118.14406,4.5169644,328.10315,-9.2995806
2083,2083,155.3868,14.551303,5.4448647,0.0,0,4.0404716,0.0,0.45066559,118.01353,4.4760036,327.8277,-9.3003511
2085,2085,155.3872,14.628588,5.4828477,0.0,0,4.0030656,0.0,0.45480147,118.16588,4.4332995,327.55225,-9.3011265
2087,2087,155.3876,14.709411,5.5331225,0.0,0,3.9657533,0.0,0.45910561,118.30748,4.3955522,327.27682,-9.2991142
2089,2089,155.388,14.771003,5.5671039,0.0,0,3.9284413,0.0,0.46390623,118.21383,4.3551521,327.00137,-9.2989826
2091,2091,155.3884,14.792273,5.6070285,0.0,0,3.8911293,0.0,0.46762547,117.95353,4.3083043,326.72592,-9.2986298
2093,2093,155.3888,14.855343,5.6550875,0.0,0,3.8538175,0.0,0.47232586,117.84473,4.2713017,326.4541,-9.2994642
2095,2095,155.3892,14.933197,5.6867352,0.0,0,3.8165054,0.0,0.47672167,117.9594,4.2320499,326.19308,-9.2994862
2097,2097,155.3896,15.008009,5.7267299,0.0,0,3.7791932,0.0,0.48012608,118.17051,4.1909852,325.93207,-9.299262
2099,2099,155.39,15.055437,5.7711086,0.0,0,3.7418811,0.0,0.48514307,118.01678,4.1520834,325.67105,-9.2995253
2101,2101,155.3904,15.108071,5.8020015,0.0,0,3.7045693,0.0,0.48907685,117.92392,4.1134057,325.41003,-9.2986803
2103,2103,155.3908,15.169834,5.8450656,0.0,0,3.6672573,0.0,0.49284551,117.93798,4.0739756,325.14902,-9.2989063
2105,2105,155.3912,15.244363,5.8858314,0.0,0,3.6299453,0.0,0.4981823,117.92029,4.0344787,324.888,-9.2989826
2107,2107,155.3916,15.329807,5.9210601,0.0,0,3.5926332,0.0,0.50187719,118.05299,3.9953015,324.62701,-9.2990274
2109,2109,155.392,15.387864,5.9613662,0.0,0,3.5565166,0.0,0.50567329,118.10277,3.9574771,324.366,-9.2998304
2111,2111,155.3924,15.424809,5.9971714,0.0,0,3.5210168,0.0,0.51072413,117.83228,3.9178727,324.10498,-9.2986231
2113,2113,155.3928,15.484628,6.0357661,0.0,0,3.4855206,0.0,0.51419485,117.80226,3.8815224,323.84396,-9.2983294
2115,2115,155.3932,15.561644,6.0757651,0.0,0,3.4500248,0.0,0.51855779,117.89656,3.8428316,323.58295,-9.2983608
2117,2117,155.3936,15.644235,6.109478,0.0,0,3.4145288,0.0,0.52332991,117.94779,3.804394,323.32193,-9.2989693
2119,2119,155.394,15.704908,6.1524725,0.0,0,3.3790326,0.0,0.52707326,118.06857,3.7678261,323.06091,-9.2994566
2121,2121,155.3944,15.755421,6.1884117,0.0,0,3.3435369,0.0,0.53174001,117.78906,3.7324982,322.7999,-9.2989035
2123,2123,155.3948,15.819256,6.2215466,0.0,0,3.3080409,0.0,0.53578651,117.74851,3.6934524,322.53891,-9.2985897
2125,2125,155.3952,15.910109,6.2657266,0.0,0,3.2725446,0.0,0.53956282,118.06914,3.6564522,322.27789,-9.298645
2127,2127,155.3956,15.996084,6.2965317,0.0,0,3.2370486,0.0,0.54423833,118.05949,3.6206343,322.01688,-9.2986841
2129,2129,155.396,16.056276,6.3330879,0.0,0,3.2015526,0.0,0.54814333,118.14019,3.5816867,321.75586,-9.2989721
2131,2131,155.3964,16.116499,6.3793349,0.0,0,3.1660566,0.0,0.5527848,118.03899,3.5472233,321.49484,-9.299489
2133,2133,155.3968,16.180073,6.407104,0.0,0,3.1309152,0.0,0.55728996,117.93991,3.5100613,321.23383,-9.2986107
2135,2135,155.3972,16.274866,6.445446,0.0,0,3.0970623,0.0,0.56089872,118.22569,3.4736822,320.97281,-9.2984715
2137,2137,155.3976,16.364223,6.4881454,0.0,0,3.0632944,0.0,0.56576598,118.2658,3.438653,320.71179,-9.298336
2139,2139,155.398,16.421707,6.5170083,0.0,0,3.0295265,0.0,0.57019788,118.18676,3.4013269,320.45078,-9.2989712
2141,2141,155.3984,16.48107,6.5591836,0.0,0,2.9957583,0.0,0.57398534,118.16441,3.3660588,320.18979,-9.2989397
2143,2143,155.3988,16.554806,6.5964613,0.0,0,2.9619906,0.0,0.579153,118.06186,3.3279808,319.8793,-9.2986498
2145,2145,155.3992,16.654881,6.625176,0.0,0,2.9282222,0.0,0.58272439,118.33855,3.2892148,319.42044,-9.2980556
2147,2147,155.3996,16.75071,6.6646781,0.0,0,2.8944542,0.0,0.58650583,118.52483,3.255631,318.96155,-9.2983332
2149,2149,155.4,16.821007,6.6990104,0.0,0,2.8606863,0.0,0.59184533,118.4798,3.2186007,318.50269,-9.2985563
2151,2151,155.4004,16.874989,6.7345901,0.0,0,2.8269184,0.0,0.5955531,118.36599,3.1826749,318.04382,-9.2990017
2153,2153,155.4008,16.947269,6.7744403,0.0,0,2.7931502,0.0,0.59996581,118.36244,3.1510677,317.58496,-9.2987204
2155,2155,155.4012,17.057444,6.8050747,0.0,0,2.7593822,0.0,0.60480642,118.53219,3.1151087,317.12607,-9.2987871
2157,2157,155.4016,17.16073,6.8428783,0.0,0,2.7256143,0.0,0.60825282,118.90762,3.0772452,316.66721,-9.2982101
2159,2159,155.402,17.214445,6.8770394,0.0,0,2.6929309,0.0,0.61285532,118.70838,3.0421247,316.20834,-9.2979851
2161,2161,155.4024,17.275969,6.906002,0.0,0,2.6608074,0.0,0.61720014,118.5839,3.0062704,315.74948,-9.2982159
2163,2163,155.4028,17.372812,6.9482317,0.0,0,2.6286874,0.0,0.62101239,118.76723,2.9729724,315.29059,-9.2986507
2165,2165,155.4032,17.495111,6.9791346,0.0,0,2.5965672,0.0,0.62585551,119.0619,2.9385262,314.83173,-9.2986889
2167,2167,155.4036,17.584597,7.0116396,0.0,0,2.5644474,0.0,0.62993997,119.25124,2.9037111,314.37286,-9.2976418
2169,2169,155.404,17.652279,7.0557523,0.0,0,2.5323272,0.0,0.63432002,119.13557,2.8689501,313.914,-9.2968636
2171,2171,155.4044,17.73774,7.0824518,0.0,0,2.5002072,0.0,0.63919032,119.12055,2.8390038,313.45511,-9.2981958
2173,2173,155.4048,17.833265,7.11689,0.0,0,2.4680872,0.0,0.64280814,119.31655,2.8042059,312.99625,-9.2978039
2175,2175,155.4052,17.947962,7.1590629,0.0,0,2.4359674,0.0,0.64774162,119.4495,2.7685137,312.53738,-9.2979393
2177,2177,155.4056,18.033636,7.1844311,0.0,0,2.4038472,0.0,0.65225714,119.57639,2.7339118,312.07852,-9.2979527
2179,2179,155.406,18.099159,7.2210426,0.0,0,2.3717272,0.0,0.65576899,119.60011,2.7008929,311.61963,-9.2981176
2181,2181,155.4064,18.178486,7.2585254,0.0,0,2.3396072,0.0,0.66103202,119.50153,2.6673853,311.16077,-9.2976618
2183,2183,155.4068,18.293335,7.2838187,0.0,0,2.3078089,0.0,0.66487294,119.6569,2.6330812,310.7019,-9.2984972
2185,2185,155.4072,18.410078,7.3229365,0.0,0,2.2771804,0.0,0.66873616,120.00218,2.6012104,310.24304,-9.2979784
2187,2187,155.4076,18.480598,7.3555541,0.0,0,2.246628,0.0,0.67412961,119.88035,2.564389,309.78418,-9.297574
2189,2189,155.408,18.568743,7.3841949,0.0,0,2.2160764,0.0,0.67758417,120.02952,2.5305622,309.32529,-9.2972469
2191,2191,155.4084,18.661201,7.4226117,0.0,0,2.1855242,0.0,0.68181831,120.08282,2.4984539,308.86642,-9.2969141
2193,2193,155.4088,18.765799,7.4541831,0.0,0,2.1549723,0.0,0.68737209,120.09155,2.4654908,308.57382,-9.298131
2195,2195,155.4092,18.878803,7.4893823,0.0,0,2.1244202,0.0,0.69102675,120.39021,2.4328406,308.77997,-9.2984629
2197,2197,155.4096,18.983519,7.5239382,0.0,0,2.0938683,0.0,0.69576418,120.44109,2.399771,308.98611,-9.2979527
2199,2199,155.41,19.068459,7.5497084,0.0,0,2.0633163,0.0,0.70025599,120.46896,2.3653607,309.19229,-9.2983952
2201,2201,155.4104,19.153824,7.586719,0.0,0,2.0327644,0.0,0.70358515,120.57565,2.3326583,309.39844,-9.2969799
2203,2203,155.4108,19.269325,7.6176548,0.0,0,2.0022123,0.0,0.7085644,120.71657,2.3008835,309.60458,-9.297266
2205,2205,155.4112,19.394508,7.6464601,0.0,0,1.9716601,0.0,0.71283746,120.9862,2.2694764,309.81076,-9.2974062
2207,2207,155.4116,19.487141,7.6894054,0.0,0,1.9411081,0.0,0.7172547,121.07535,2.2354479,310.01691,-9.2977695
2209,2209,155.412,19.563211,7.7156596,0.0,0,1.9115355,0.0,0.722413,120.9007,2.2068613,310.22305,-9.2983131
2211,2211,155.4124,19.659235,7.745141,0.0,0,1.8824685,0.0,0.72599506,121.04961,2.1749551,310.4292,-9.2976923
2213,2213,155.4128,19.783033,7.7839589,0.0,0,1.8534043,0.0,0.73047382,121.20351,2.141324,310.63538,-9.2970152
2215,2215,155.4132,19.896124,7.8049712,0.0,0,1.8243403,0.0,0.73508471,121.46508,2.1113904,310.84152,-9.2959728
2217,2217,155.4136,19.989534,7.8383055,0.0,0,1.7952764,0.0,0.73843676,121.62077,2.0806139,311.04767,-9.2970171
2219,2219,155.414,20.083956,7.8757176,0.0,0,1.7662123,0.0,0.74372739,121.50873,2.0452566,311.25385,-9.2980576
2221,2221,155.4144,20.183193,7.8981905,0.0,0,1.7371484,0.0,0.74815768,121.53767,2.0155904,311.45999,-9.2981501
2223,2223,155.4148,20.31422,7.935667,0.0,0,1.7080843,0.0,0.75187904,121.88095,1.9844904,311.66614,-9.2962618
2225,2225,155.4152,20.440792,7.967279,0.0,0,1.6790204,0.0,0.75733066,121.94127,1.954181,311.87228,-9.2958403
2227,2227,155.4156,20.545795,7.9911013,0.0,0,1.6499563,0.0,0.76081157,122.2076,1.9217697,312.07846,-9.2970161
2229,2229,155.416,20.645353,8.0261955,0.0,0,1.6208923,0.0,0.76472378,122.29803,1.8941395,312.28461,-9.2966843
2231,2231,155.4164,20.745697,8.0548754,0.0,0,1.5918283,0.0,0.77036065,122.19026,1.862902,312.49075,-9.2959776
2233,2233,155.4168,20.873987,8.083622,0.0,0,1.5630548,0.0,0.7737267,122.53165,1.830716,312.6969,-9.2965002
2235,2235,155.4172,21.01005,8.117321,0.0,0,1.5353373,0.0,0.77813423,122.7991,1.8015951,312.90308,-9.2961092
2237,2237,155.4176,21.121798,8.1417713,0.0,0,1.5076892,0.0,0.78322864,122.77934,1.7742919,313.10922,-9.2964678
2239,2239,155.418,21.211546,8.1768026,0.0,0,1.4800413,0.0,0.78666872,122.93992,1.7430874,313.31537,-9.2961731
2241,2241,155.4184,21.316675,8.2053785,0.0,0,1.4523933,0.0,0.79145461,122.90353,1.7133707,313.52155,-9.2961531
2243,2243,155.4188,21.466492,8.2293196,0.0,0,1.4247453,0.0,0.79579908,123.19929,1.6867099,313.83047,-9.2966433
2245,2245,155.4192,21.613348,8.2676983,0.0,0,1.3970973,0.0,0.79962891,123.63498,1.657537,314.44785,-9.2968969
2247,2247,155.4196,21.725311,8.2907209,0.0,0,1.3694494,0.0,0.80462766,123.65843,1.6286541,315.06519,-9.2980995
2249,2249,155.42,21.823795,8.3162327,0.0,0,1.3418013,0.0,0.80828154,123.79114,1.6015347,315.68253,-9.2968626
2251,2251,155.4204,21.946598,8.3556967,0.0,0,1.3141534,0.0,0.81279022,123.90499,1.5702448,316.29987,-9.2959394
2253,2253,155.4208,22.106281,8.3771181,0.0,0,1.2865053,0.0,0.81795865,124.10793,1.5424109,316.91721,-9.2966003
2255,2255,155.4212,22.255777,8.4063005,0.0,0,1.2588574,0.0,0.82131332,124.57166,1.512779,317.53458,-9.2968454
2257,2257,155.4216,22.357359,8.4421787,0.0,0,1.2312094,0.0,0.82639235,124.53452,1.4837654,318.15192,-9.2968893
2259,2259,155.422,22.471251,8.4604759,0.0,0,1.2044513,0.0,0.83075333,124.599,1.4534848,318.76926,-9.2966757
2261,2261,155.4224,22.619144,8.493763,0.0,0,1.1781524,0.0,0.83414519,124.98589,1.4262638,319.3866,-9.2962341
2263,2263,155.4228,22.778797,8.5272522,0.0,0,1.1518564,0.0,0.8399902,125.11619,1.3957857,320.00394,-9.2950516
2265,2265,155.4232,22.925819,8.5484505,0.0,0,1.1255604,0.0,0.84396499,125.44351,1.3697706,320.62131,-9.2956505
2267,2267,155.4236,23.050098,8.5825977,0.0,0,1.0992644,0.0,0.84770727,125.66391,1.3388357,321.23865,-9.295805
2269,2269,155.424,23.1658,8.6097345,0.0,0,1.0729684,0.0,0.85338998,125.55822,1.3092707,321.85599,-9.2958345
2271,2271,155.4244,23.306166,8.6324148,0.0,0,1.0466723,0.0,0.85654837,125.90434,1.2821302,322.47333,-9.2953386
2273,2273,155.4248,23.473099,8.6632175,0.0,0,1.0203763,0.0,0.86054868,126.30379,1.2545018,323.09067,-9.2950907
2275,2275,155.4252,23.624323,8.6863337,0.0,0,0.99408036,0.0,0.8660416,126.45493,1.2268815,323.70804,-9.2946701
2277,2277,155.4256,23.743843,8.7183685,0.0,0,0.96778435,0.0,0.86947954,126.6875,1.1973881,324.32538,-9.2947121
2279,2279,155.426,23.874361,8.7487564,0.0,0,0.94148839,0.0,0.87452424,126.711,1.1721826,324.94272,-9.2952204
2281,2281,155.4264,24.030979,8.7694855,0.0,0,0.91519243,0.0,0.87926608,126.89336,1.14059,325.56006,-9.2951803
2283,2283,155.4268,24.201405,8.803504,0.0,0,0.88916051,0.0,0.8827073,127.37248,1.1144485,326.1774,-9.2950563
2285,2285,155.4272,24.339722,8.8254147,0.0,0,0.86408949,0.0,0.88750058,127.51657,1.0888622,326.79477,-9.2943974
2287,2287,155.4276,24.464502,8.848321,0.0,0,0.83908135,0.0,0.89136308,127.72005,1.0641881,327.41211,-9.2949114
2289,2289,155.428,24.5961,8.884409,0.0,0,0.81407332,0.0,0.89557111,127.82686,1.035787,328.02945,-9.2942553
2291,2291,155.4284,24.762566,8.9036198,0.0,0,0.78906536,0.0,0.90063334,128.02562,1.0090218,328.64679,-9.2935839
2293,2293,155.4288,24.930958,8.9285526,0.0,0,0.7640574,0.0,0.90396065,128.442,0.98172408,329.15976,-9.2945127
2295,2295,155.4292,25.0763,8.9630318,0.0,0,0.73904938,0.0,0.90889114,128.60728,0.95539188,329.3595,-9.2942839
2297,2297,155.4296,25.21228,8.9791679,0.0,0,0.71404135,0.0,0.91349614,128.71469,0.92921501,329.55927,-9.2936087
2299,2299,155.43,25.352745,9.0076914,0.0,0,0.68903339,0.0,0.91646546,129.00584,0.90498447,329.75903,-9.294528
2301,2301,155.4304,25.499277,9.0387745,0.0,0,0.66402543,0.0,0.9221158,129.01218,0.87624884,329.9588,-9.2941761
2303,2303,155.4308,25.660172,9.0540524,0.0,0,0.63901734,0.0,0.92581284,129.39081,0.85151523,330.15857,-9.2948961
2305,2305,155.4312,25.818495,9.0841246,0.0,0,0.61400938,0.0,0.92906946,129.75676,0.82519126,330.35834,-9.2939873
2307,2307,155.4316,25.968756,9.1108503,0.0,0,0.58900136,0.0,0.93508172,129.70045,0.80035877,330.55811,-9.293046
2309,2309,155.432,26.09881,9.1297436,0.0,0,0.56478846,0.0,0.93821603,129.98988,0.77716559,330.75787,-9.2939072
2311,2311,155.4324,26.275074,9.1583643,0.0,0,0.54098594,0.0,0.94181228,130.35536,0.74853909,330.95764,-9.29459
2313,2313,155.4328,26.447643,9.1797972,0.0,0,0.51718587,0.0,0.9473967,130.46121,0.72376209,331.15741,-9.2951822
2315,2315,155.4332,26.604391,9.2044868,0.0,0,0.49338591,0.0,0.95015872,130.93867,0.69986808,331.35718,-9.2935915
2317,2317,155.4336,26.739105,9.2316523,0.0,0,0.4695859,0.0,0.95477909,130.97755,0.67456758,331.55695,-9.2926464
2319,2319,155.434,26.888689,9.2489195,0.0,0,0.44578591,0.0,0.959517,131.05814,0.65169477,331.75668,-9.2921686
2321,2321,155.4344,27.039337,9.2775612,0.0,0,0.42198589,0.0,0.96227229,131.48003,0.62856543,331.95645,-9.2937984
2323,2323,155.4348,27.242138,9.2999039,0.0,0,0.39818591,0.0,0.96721929,131.75008,0.60362548,332.15622,-9.2936678
2325,2325,155.4352,27.406052,9.3175325,0.0,0,0.37438589,0.0,0.97135746,132.03201,0.58154851,332.35599,-9.2935457
2327,2327,155.4356,27.555019,9.3510208,0.0,0,0.35058588,0.0,0.9747858,132.29771,0.55903393,332.55576,-9.2930021
2329,2329,155.436,27.705269,9.3663092,0.0,0,0.32678592,0.0,0.97954702,132.36531,0.53535354,332.75552,-9.2922373
2330,2330,155.4362,27.782387,9.3851385,0.0,0,0.31488591,0.0,0.98076451,132.57573,0.52509475,332.85541,-9.2919397