File: examples/hot axisymmetric compression example/data/03 trimmed data/testID_0139.csv
level_0,index,Time(sec),Force(kN),Jaw(mm),PowAngle(deg),Power(W),Pram,PTemp,Strain,Stress(MPa),Stroke(mm),TC1(C),wedge(mm)
1972,1972,165.3437,1.0057675,0.012191684,0.0,0,9.0629425,0.0,0.00098395417,12.628573,10.084554,362.57523,-9.2901678
1974,1974,165.3441,2.9290299,0.04168338,0.0,0,9.0044146,0.0,0.0021816557,33.177467,10.008451,362.74573,-9.2895546
1976,1976,165.3445,5.3089318,0.088600598,0.0,0,8.9458866,0.0,0.0056985379,65.378731,9.9541521,362.9162,-9.2880573
1978,1978,165.3449,6.1955533,0.14413022,0.0,0,8.8873577,0.0,0.0091574807,77.12748,9.8848896,363.08667,-9.2855635
1980,1980,165.3453,6.7792959,0.27897361,0.0,0,8.8288298,0.0,0.017488703,84.657021,9.8028316,363.25714,-9.2839947
1982,1982,165.3457,6.9407258,0.37495244,0.0,0,8.7703018,0.0,0.025029739,85.46698,9.7065926,363.42764,-9.2840738
1984,1984,165.3461,7.4629827,0.46529588,0.0,0,8.7136612,0.0,0.030638635,91.846741,9.606493,363.59811,-9.2840986
1986,1986,165.3465,7.8228846,0.54433584,0.0,0,8.6579905,0.0,0.036522839,95.174713,9.5139418,363.76859,-9.2840757
1988,1988,165.3469,7.9609499,0.56655842,0.0,0,8.6023264,0.0,0.038411759,98.036865,9.4393501,363.93906,-9.2827959
1990,1990,165.3473,7.71205,0.64359951,0.0,0,8.5466623,0.0,0.043118067,93.745987,9.3742037,364.10956,-9.2832355
1992,1992,165.3477,8.2013712,0.70056087,0.0,0,8.4909992,0.0,0.04763839,99.129059,9.3145542,364.26282,-9.2834988
1994,1994,165.3481,8.4234905,0.76524359,0.0,0,8.4353342,0.0,0.051814888,101.46114,9.245801,364.3475,-9.2831326
1996,1996,165.3485,8.4266939,0.86982626,0.0,0,8.3796701,0.0,0.058823511,101.60294,9.1670876,364.43219,-9.2828646
1998,1998,165.3489,8.1389208,0.95276463,0.0,0,8.324007,0.0,0.065346576,96.986,9.0815506,364.51688,-9.282979
2000,2000,165.3493,8.524291,1.0306028,0.0,0,8.268343,0.0,0.070602126,100.91953,9.0033627,364.60156,-9.2830572
2002,2002,165.3497,8.4880257,1.0846555,0.0,0,8.2126789,0.0,0.074712612,100.18403,8.9297323,364.68625,-9.2831011
2004,2004,165.3501,8.7481346,1.1216658,0.0,0,8.1570148,0.0,0.077657342,103.03306,8.8665361,364.77094,-9.2838411
2006,2006,165.3505,8.4462013,1.1906265,0.0,0,8.1013508,0.0,0.081993423,99.394958,8.8139572,364.85562,-9.2836733
2008,2008,165.3509,8.8192949,1.2374334,0.0,0,8.0462427,0.0,0.08576563,102.40668,8.755827,364.94031,-9.2828321
2010,2010,165.3513,8.9373493,1.3048011,0.0,0,7.9931507,0.0,0.090645507,104.10314,8.6939907,365.02499,-9.2830687
2012,2012,165.3517,8.9198666,1.3934797,0.0,0,7.9401903,0.0,0.096616209,103.06512,8.6288719,365.10968,-9.2823191
2014,2014,165.3521,8.813386,1.4569892,0.0,0,7.8872304,0.0,0.10169546,101.54359,8.5531673,365.19437,-9.2831802
2016,2016,165.3525,8.8447132,1.5205263,0.0,0,7.8342705,0.0,0.10652275,100.87588,8.4878016,365.27905,-9.283843
2018,2018,165.3529,9.0381498,1.5661951,0.0,0,7.7813101,0.0,0.10970087,103.07948,8.4262524,365.36374,-9.2834253
2020,2020,165.3533,9.0898952,1.6090285,0.0,0,7.7283502,0.0,0.11328877,103.27637,8.3711777,365.44843,-9.2827206
2022,2022,165.3537,9.0352116,1.6708652,0.0,0,7.6753898,0.0,0.11758974,102.36813,8.3171129,365.53314,-9.2831879
2024,2024,165.3541,9.1194754,1.7237386,0.0,0,7.6224298,0.0,0.12146928,102.48319,8.2653189,365.61783,-9.2822351
2026,2026,165.3545,9.2821722,1.7773423,0.0,0,7.5694699,0.0,0.12588696,104.32704,8.2070417,365.70251,-9.2830687
2028,2028,165.3549,9.236762,1.8407034,0.0,0,7.51651,0.0,0.13025147,103.19847,8.1506901,365.7872,-9.2836027
2030,2030,165.3553,9.3156147,1.9031997,0.0,0,7.4635501,0.0,0.13529457,103.65636,8.0918713,365.87189,-9.2831211
2032,2032,165.3557,9.2057114,1.9535009,0.0,0,7.4105897,0.0,0.13936977,102.04494,8.0358095,365.95657,-9.2835531
2034,2034,165.3561,9.4069576,1.9955343,0.0,0,7.3593369,0.0,0.14226459,103.76941,7.9807391,366.04126,-9.2831821
2036,2036,165.3565,9.3902264,2.0489485,0.0,0,7.3089638,0.0,0.14673793,103.34278,7.9289131,366.12595,-9.2830954
2038,2038,165.3569,9.4385624,2.0985575,0.0,0,7.2585959,0.0,0.1503718,103.28582,7.8789687,366.21063,-9.2833738
2040,2040,165.3573,9.4719496,2.1479578,0.0,0,7.2082276,0.0,0.15391921,103.32417,7.8294449,366.29532,-9.2835398
2042,2042,165.3577,9.6092548,2.2003059,0.0,0,7.1578593,0.0,0.15854424,104.2701,7.7759266,366.30789,-9.2841663
2044,2044,165.3581,9.5873289,2.2534966,0.0,0,7.107491,0.0,0.16219933,103.86214,7.722373,365.91348,-9.2839756
2046,2046,165.3585,9.5757141,2.3094473,0.0,0,7.0571237,0.0,0.16669196,103.19535,7.6681747,365.51907,-9.283865
2048,2048,165.3589,9.6069336,2.3522658,0.0,0,7.0067549,0.0,0.17067081,103.05952,7.618618,365.12469,-9.2832251
2050,2050,165.3593,9.7459536,2.398993,0.0,0,6.9563875,0.0,0.17346089,104.08679,7.5714412,364.73029,-9.282444
2052,2052,165.3597,9.761548,2.4474723,0.0,0,6.9060192,0.0,0.17784378,104.13178,7.5234857,364.33588,-9.2822647
2054,2054,165.3601,9.7169628,2.490206,0.0,0,6.8556519,0.0,0.18130945,103.19331,7.4744096,363.94147,-9.2837648
2056,2056,165.3605,9.7862492,2.5480623,0.0,0,6.8052835,0.0,0.18527085,103.42842,7.4214625,363.54706,-9.2840643
2058,2058,165.3609,9.9122419,2.5921414,0.0,0,6.7554183,0.0,0.18957418,104.24369,7.3747916,363.15265,-9.2839355
2060,2060,165.3613,9.9441032,2.6397099,0.0,0,6.7073793,0.0,0.19307476,104.43128,7.3252101,362.75827,-9.2830238
2062,2062,165.3617,9.8918209,2.7002828,0.0,0,6.6594586,0.0,0.19776779,103.43631,7.2780228,362.36386,-9.2824373
2064,2064,165.3621,9.9269533,2.7356856,0.0,0,6.6115384,0.0,0.20132951,103.2907,7.2301779,361.96945,-9.2825098
2066,2066,165.3625,10.031512,2.7802339,0.0,0,6.5636187,0.0,0.204382,104.00308,7.1796041,361.57504,-9.2839403
2068,2068,165.3629,10.108747,2.8335557,0.0,0,6.5156989,0.0,0.20894687,104.42477,7.1328602,361.18063,-9.2846851
2070,2070,165.3633,10.109157,2.8744314,0.0,0,6.4677792,0.0,0.21251687,104.07551,7.0842848,360.78622,-9.283391
2072,2072,165.3637,10.142405,2.9295084,0.0,0,6.4198589,0.0,0.21651204,103.9361,7.0364084,360.39185,-9.2822304
2074,2074,165.3641,10.200469,2.9780786,0.0,0,6.3719387,0.0,0.22123326,104.04027,6.9886065,359.99744,-9.2827072
2076,2076,165.3645,10.261048,3.0228174,0.0,0,6.324019,0.0,0.22473121,104.30854,6.9379644,359.60303,-9.282814
2078,2078,165.3649,10.273978,3.0762265,0.0,0,6.2760992,0.0,0.22878152,103.99995,6.8893237,359.20862,-9.284153
2080,2080,165.3653,10.332596,3.1185398,0.0,0,6.228179,0.0,0.23306149,104.15895,6.8409204,358.81421,-9.2840567
2082,2082,165.3657,10.37124,3.1667886,0.0,0,6.1802592,0.0,0.23656249,104.27156,6.7921948,358.4198,-9.2846756
2084,2084,165.3661,10.413713,3.2127392,0.0,0,6.133883,0.0,0.24056274,104.18777,6.7455969,358.02542,-9.2837982
2086,2086,165.3665,10.455701,3.2540381,0.0,0,6.0883021,0.0,0.24458826,104.22144,6.6975012,357.63101,-9.2826328
2088,2088,165.3669,10.509563,3.3120468,0.0,0,6.0427265,0.0,0.24866982,104.291,6.6488538,357.2366,-9.2832232
2090,2090,165.3673,10.581858,3.3555956,0.0,0,5.9971499,0.0,0.25290731,104.54369,6.5999637,356.84219,-9.2831602
2092,2092,165.3677,10.591735,3.4025173,0.0,0,5.9515738,0.0,0.25706318,104.26992,6.5517206,356.45117,-9.2835073
2094,2094,165.3681,10.606057,3.4573381,0.0,0,5.9059982,0.0,0.26107797,103.94909,6.5048108,356.09042,-9.2837715
2096,2096,165.3685,10.677283,3.4971936,0.0,0,5.8604221,0.0,0.26537064,104.20451,6.4552164,355.72968,-9.28407
2098,2098,165.3689,10.752674,3.544327,0.0,0,5.8148456,0.0,0.26917809,104.56504,6.4089937,355.3689,-9.2846889
2100,2100,165.3693,10.789203,3.5990839,0.0,0,5.7692699,0.0,0.27349806,104.48292,6.3616028,355.00815,-9.2831736
2102,2102,165.3697,10.807729,3.6394849,0.0,0,5.7236938,0.0,0.27789763,104.14774,6.3128538,354.6474,-9.2828588
2104,2104,165.3701,10.829756,3.6903262,0.0,0,5.6781182,0.0,0.28174245,103.96189,6.2657046,354.28665,-9.2823706
2106,2106,165.3705,10.912553,3.7412558,0.0,0,5.6325421,0.0,0.28637415,104.25869,6.2191682,353.92587,-9.28302
2108,2108,165.3709,10.97462,3.7799921,0.0,0,5.5874209,0.0,0.29028088,104.51788,6.1700487,353.56512,-9.283371
2110,2110,165.3713,11.00006,3.8294463,0.0,0,5.5439529,0.0,0.29393277,104.34825,6.1245646,353.20438,-9.2847471
2112,2112,165.3717,11.042579,3.8791046,0.0,0,5.5005927,0.0,0.2990298,104.24685,6.0764904,352.84363,-9.2852068
2114,2114,165.3721,11.091552,3.9245772,0.0,0,5.4572325,0.0,0.30304542,104.26427,6.0295196,352.48285,-9.2834759
2116,2116,165.3725,11.159499,3.9745898,0.0,0,5.4138727,0.0,0.30711851,104.37754,5.9815774,352.1221,-9.2827425
2118,2118,165.3729,11.218306,4.0203505,0.0,0,5.3705125,0.0,0.31198385,104.54234,5.935781,351.76135,-9.2833996
2120,2120,165.3733,11.242106,4.0667605,0.0,0,5.3271527,0.0,0.31571057,104.41293,5.8877592,351.4006,-9.2842932
2122,2122,165.3737,11.281223,4.1145964,0.0,0,5.2837925,0.0,0.31992337,104.28075,5.8397565,351.03986,-9.284874
2124,2124,165.3741,11.318838,4.1568313,0.0,0,5.2404327,0.0,0.32458159,104.18301,5.7900524,350.67908,-9.2843723
2126,2126,165.3745,11.389072,4.206903,0.0,0,5.197073,0.0,0.32836619,104.30487,5.7447996,350.31833,-9.2841873
2128,2128,165.3749,11.453753,4.2538238,0.0,0,5.1537127,0.0,0.33306038,104.43113,5.6949902,349.95758,-9.2825603
2130,2130,165.3753,11.49268,4.2981105,0.0,0,5.1103525,0.0,0.33762789,104.33505,5.6474042,349.59683,-9.2825451
2132,2132,165.3757,11.530754,4.355063,0.0,0,5.0669928,0.0,0.34185171,104.22041,5.6028318,349.23605,-9.2832642
2134,2134,165.3761,11.561649,4.3962421,0.0,0,5.0250292,0.0,0.34665629,104.04026,5.5553803,348.87531,-9.2840338
2136,2136,165.3765,11.611034,4.4372211,0.0,0,4.9837847,0.0,0.35036817,104.09796,5.5072236,348.51456,-9.2850704
2138,2138,165.3769,11.690038,4.4916329,0.0,0,4.9425445,0.0,0.35499561,104.31458,5.4606299,348.15381,-9.2854519
2140,2140,165.3773,11.70984,4.5287557,0.0,0,4.9013047,0.0,0.35949618,104.07452,5.4155989,347.79303,-9.2834148
2142,2142,165.3777,11.745206,4.5754275,0.0,0,4.8600645,0.0,0.36317596,103.98185,5.3694739,347.43869,-9.2824507
2144,2144,165.3781,11.788837,4.6286659,0.0,0,4.8188248,0.0,0.36823803,103.77431,5.3237553,347.20456,-9.2825327
2146,2146,165.3785,11.859876,4.6644855,0.0,0,4.7775846,0.0,0.37246743,103.96867,5.2788749,346.97046,-9.2836981
2148,2148,165.3789,11.928674,4.7149534,0.0,0,4.7363443,0.0,0.37645867,104.14115,5.2377677,346.73636,-9.283947
2150,2150,165.3793,11.956252,4.7616639,0.0,0,4.6951046,0.0,0.3815873,103.92388,5.1894631,346.50223,-9.2836542
2152,2152,165.3797,11.988939,4.7998567,0.0,0,4.6538649,0.0,0.38547409,103.82385,5.1447363,346.26813,-9.2840633
2154,2154,165.3801,12.038085,4.8483248,0.0,0,4.6126242,0.0,0.3896738,103.7374,5.1006293,346.034,-9.2830763
2156,2156,165.3805,12.114473,4.8927226,0.0,0,4.5713844,0.0,0.39486563,103.90374,5.0523376,345.7999,-9.2828484
2158,2158,165.3809,12.173349,4.9373932,0.0,0,4.5305572,0.0,0.39872545,103.98167,5.0124102,345.5658,-9.2823896
2160,2160,165.3813,12.199394,4.9840746,0.0,0,4.4912271,0.0,0.40315181,103.78094,4.9662104,345.33167,-9.2830038
2162,2162,165.3817,12.226334,5.0237241,0.0,0,4.4519949,0.0,0.40806201,103.53458,4.9243994,345.09756,-9.2840261
2164,2164,165.3821,12.272808,5.0720568,0.0,0,4.4127631,0.0,0.41192201,103.51413,4.8791766,344.86346,-9.2842712
2166,2166,165.3825,12.353411,5.1151991,0.0,0,4.3735313,0.0,0.41656852,103.63933,4.8351755,344.62933,-9.2828655
2168,2168,165.3829,12.423361,5.1543531,0.0,0,4.3342991,0.0,0.42103687,103.73755,4.7904181,344.39523,-9.28193
2170,2170,165.3833,12.460442,5.206326,0.0,0,4.2950673,0.0,0.4252342,103.62589,4.7463264,344.1611,-9.2822599
2172,2172,165.3837,12.48038,5.2453418,0.0,0,4.2558346,0.0,0.43007609,103.34848,4.7013683,343.927,-9.2826986
2174,2174,165.3841,12.534426,5.2872624,0.0,0,4.2166028,0.0,0.43425009,103.27383,4.6589146,343.6929,-9.2834435
2176,2176,165.3845,12.609901,5.3385782,0.0,0,4.177371,0.0,0.43881246,103.44824,4.6168437,343.45877,-9.2837925
2178,2178,165.3849,12.676383,5.3716297,0.0,0,4.1381388,0.0,0.44343099,103.53918,4.574306,343.22467,-9.283061
2180,2180,165.3853,12.695992,5.4138904,0.0,0,4.098907,0.0,0.44715595,103.35009,4.5314183,342.99057,-9.2829533
2182,2182,165.3857,12.738661,5.4635806,0.0,0,4.0596752,0.0,0.45203808,103.14581,4.4860234,342.75644,-9.2820864
2184,2184,165.3861,12.80549,5.4985785,0.0,0,4.021708,0.0,0.45664817,103.21053,4.4446602,342.52234,-9.281724
2186,2186,165.3865,12.888484,5.5437956,0.0,0,3.9843915,0.0,0.46053892,103.49703,4.4033132,342.28821,-9.2826347
2188,2188,165.3869,12.952784,5.5893145,0.0,0,3.9470794,0.0,0.46582785,103.49062,4.3601556,342.05411,-9.2838888
2190,2190,165.3873,12.971778,5.6240315,0.0,0,3.9097676,0.0,0.46986216,103.272,4.3164225,341.82001,-9.283658
2192,2192,165.3877,13.00938,5.6694541,0.0,0,3.8724556,0.0,0.47381309,103.14635,4.277339,341.58591,-9.2829838
2194,2194,165.3881,13.081762,5.7082076,0.0,0,3.8351436,0.0,0.47888979,103.10947,4.2366724,341.37241,-9.2828035
2196,2196,165.3885,13.156265,5.7446094,0.0,0,3.7978315,0.0,0.48243305,103.35875,4.1928811,341.15891,-9.2830753
2198,2198,165.3889,13.206782,5.7896657,0.0,0,3.7605195,0.0,0.48681635,103.35085,4.1558857,340.94543,-9.2830105
2200,2200,165.3893,13.229138,5.8281374,0.0,0,3.7232075,0.0,0.49208137,102.92323,4.1138458,340.73193,-9.2819071
2202,2202,165.3897,13.285624,5.8701973,0.0,0,3.6858957,0.0,0.49573573,102.98257,4.0767479,340.51843,-9.2822905
2204,2204,165.3901,13.362424,5.9085016,0.0,0,3.6485837,0.0,0.50014716,103.11608,4.0360732,340.30496,-9.2832251
2206,2206,165.3905,13.431986,5.9398451,0.0,0,3.6112714,0.0,0.50437552,103.26038,3.9996116,340.09146,-9.2837963
2208,2208,165.3909,13.476682,5.9856653,0.0,0,3.5743327,0.0,0.50812143,103.22092,3.9597654,339.87796,-9.2831783
2210,2210,165.3913,13.515279,6.020669,0.0,0,3.538748,0.0,0.51292104,103.00115,3.9231369,339.66449,-9.2821779
2212,2212,165.3917,13.563208,6.0558295,0.0,0,3.5032518,0.0,0.5169338,102.94903,3.8854055,339.45099,-9.281848
2214,2214,165.3921,13.644002,6.1038342,0.0,0,3.4677558,0.0,0.5212158,103.13717,3.8485775,339.23749,-9.2819948
2216,2216,165.3925,13.703314,6.1330786,0.0,0,3.43226,0.0,0.5258258,103.11586,3.8085089,339.02402,-9.2832842
2218,2218,165.3929,13.765594,6.1693816,0.0,0,3.3967638,0.0,0.52933294,103.21098,3.769325,338.81052,-9.2822218
2220,2220,165.3933,13.809322,6.215209,0.0,0,3.3612678,0.0,0.53409809,103.04487,3.7337537,338.59705,-9.282361
2222,2222,165.3937,13.858036,6.2420425,0.0,0,3.3257718,0.0,0.53827935,102.95824,3.6962907,338.38354,-9.2827682
2224,2224,165.3941,13.935164,6.2828789,0.0,0,3.2902758,0.0,0.54188854,103.08906,3.6571038,338.17004,-9.2827244
2226,2226,165.3945,14.00873,6.3240881,0.0,0,3.2547796,0.0,0.54700619,103.14692,3.6207623,337.95657,-9.2825708
2228,2228,165.3949,14.073476,6.3511457,0.0,0,3.2192838,0.0,0.55071193,103.22293,3.5860949,337.74307,-9.2825375
2230,2230,165.3953,14.116409,6.3915462,0.0,0,3.1837878,0.0,0.5542177,103.25175,3.5468712,337.52957,-9.2826118
2232,2232,165.3957,14.163875,6.4283996,0.0,0,3.1482918,0.0,0.55959964,103.00195,3.5146928,337.3161,-9.2835121
2234,2234,165.3961,14.232369,6.4598398,0.0,0,3.1139338,0.0,0.56305283,103.08075,3.4796193,337.1026,-9.2824612
2236,2236,165.3965,14.334474,6.5014553,0.0,0,3.0801623,0.0,0.56715256,103.41562,3.4435768,336.8891,-9.2822771
2238,2238,165.3969,14.3998,6.5361514,0.0,0,3.0463943,0.0,0.57249439,103.39127,3.407428,336.67563,-9.2824306
2240,2240,165.3973,14.427806,6.5740385,0.0,0,3.0126262,0.0,0.57596797,103.25214,3.3728235,336.46213,-9.2827425
2242,2242,165.3977,14.486943,6.6108837,0.0,0,2.9788582,0.0,0.58044207,103.22067,3.3382447,336.24863,-9.2824535
2244,2244,165.3981,14.572481,6.640511,0.0,0,2.9450903,0.0,0.58485651,103.32961,3.3014617,336.24268,-9.2824345
2246,2246,165.3985,14.669436,6.6808858,0.0,0,2.9113221,0.0,0.58841211,103.62181,3.2654819,336.24753,-9.2817593
2248,2248,165.3989,14.729045,6.7121696,0.0,0,2.8775542,0.0,0.59295088,103.65005,3.2300525,336.25238,-9.2816772
2250,2250,165.3993,14.777076,6.7435126,0.0,0,2.8437862,0.0,0.59704739,103.52318,3.1949391,336.25723,-9.2824888
2252,2252,165.3997,14.841427,6.7906418,0.0,0,2.8100181,0.0,0.60141647,103.55914,3.1596224,336.26208,-9.2834444
2254,2254,165.4001,14.939795,6.8207884,0.0,0,2.7762504,0.0,0.60651308,103.63648,3.1250751,336.26694,-9.2830172
2256,2256,165.4005,15.031834,6.8553219,0.0,0,2.7424822,0.0,0.61016911,103.92708,3.0901191,336.27179,-9.2814789
2258,2258,165.4009,15.081806,6.8969107,0.0,0,2.7090528,0.0,0.61477214,103.82623,3.0535588,336.27664,-9.2803545
2260,2260,165.4013,15.136976,6.9222369,0.0,0,2.6768525,0.0,0.61922473,103.73392,3.014221,336.28149,-9.2796001
2262,2262,165.4017,15.208533,6.9582186,0.0,0,2.644732,0.0,0.62264925,103.8476,2.9820521,336.28635,-9.281682
2264,2264,165.4021,15.30498,6.9999061,0.0,0,2.612612,0.0,0.62789029,103.95443,2.946656,336.2912,-9.2827463
2266,2266,165.4025,15.417205,7.0260606,0.0,0,2.580492,0.0,0.6320796,104.24062,2.9114375,336.29605,-9.2814379
2268,2268,165.4029,15.476049,7.0666256,0.0,0,2.548372,0.0,0.63603109,104.34076,2.8791173,336.3009,-9.2822647
2270,2270,165.4033,15.532187,7.1054969,0.0,0,2.516252,0.0,0.64178157,104.0783,2.8415048,336.30576,-9.2810011
2272,2272,165.4037,15.604596,7.1360044,0.0,0,2.4841321,0.0,0.64553189,104.14425,2.8096764,336.31061,-9.2815275
2274,2274,165.4041,15.71481,7.1741204,0.0,0,2.4520121,0.0,0.64960092,104.39391,2.7745459,336.31546,-9.2814798
2276,2276,165.4045,15.799938,7.2036915,0.0,0,2.4198921,0.0,0.65472585,104.51047,2.739006,336.32031,-9.2809381
2278,2278,165.4049,15.861618,7.2360268,0.0,0,2.3877721,0.0,0.65802276,104.54095,2.7050934,336.32516,-9.2810793
2280,2280,165.4053,15.920197,7.2728672,0.0,0,2.3556519,0.0,0.66249794,104.44629,2.6713896,336.33002,-9.2809782
2282,2282,165.4057,16.011412,7.3024936,0.0,0,2.3235321,0.0,0.66759527,104.54971,2.6372011,336.33487,-9.2809572
2284,2284,165.4061,16.123079,7.3408914,0.0,0,2.2924447,0.0,0.67102146,104.86037,2.6041875,336.33972,-9.2809896
2286,2286,165.4065,16.215031,7.3744226,0.0,0,2.2618895,0.0,0.67603713,104.95503,2.5700819,336.34457,-9.281127
2288,2288,165.4069,16.27808,7.4024725,0.0,0,2.2313375,0.0,0.68036169,104.92548,2.5354612,336.34943,-9.2819319
2290,2290,165.4073,16.34885,7.4448814,0.0,0,2.2007856,0.0,0.68446112,104.9166,2.503684,336.35428,-9.2816515
2292,2292,165.4077,16.437534,7.4724236,0.0,0,2.1702335,0.0,0.68944895,104.99184,2.4726224,336.35913,-9.2811556
2294,2294,165.4081,16.545715,7.5021687,0.0,0,2.1396816,0.0,0.69324189,105.23042,2.439559,336.19641,-9.2811003
2296,2296,165.4085,16.6371,7.5434365,0.0,0,2.1091297,0.0,0.6975686,105.36129,2.4068434,336.01517,-9.2805948
2298,2298,165.4089,16.692152,7.5663757,0.0,0,2.0785778,0.0,0.70234746,105.27576,2.3751507,335.83389,-9.2811642
2300,2300,165.4093,16.774078,7.5992417,0.0,0,2.0480258,0.0,0.70562643,105.4058,2.3425171,335.65265,-9.2815266
2302,2302,165.4097,16.865967,7.6390319,0.0,0,2.0174737,0.0,0.71072632,105.41096,2.3091893,335.47141,-9.2806845
2304,2304,165.4101,16.980677,7.6613708,0.0,0,1.9869215,0.0,0.71526879,105.71687,2.2771306,335.29016,-9.2805967
2306,2306,165.4105,17.079645,7.6982131,0.0,0,1.9563695,0.0,0.71885204,105.94169,2.2433448,335.10892,-9.2806997
2308,2308,165.4109,17.145739,7.7315102,0.0,0,1.9261233,0.0,0.72426331,105.76807,2.2167783,334.92764,-9.2806444
2310,2310,165.4113,17.234276,7.7555523,0.0,0,1.8969866,0.0,0.72778785,105.90676,2.1835251,334.7464,-9.2810078
2312,2312,165.4117,17.335302,7.7929649,0.0,0,1.8679224,0.0,0.73184377,106.10023,2.1492035,334.56516,-9.2809143
2314,2314,165.4121,17.444813,7.8236475,0.0,0,1.8388585,0.0,0.73761195,106.19421,2.1191292,334.38391,-9.2795906
2316,2316,165.4125,17.548361,7.8533835,0.0,0,1.8097944,0.0,0.74090546,106.46611,2.0860639,334.20267,-9.2791348
2318,2318,165.4129,17.626953,7.8886948,0.0,0,1.7807305,0.0,0.74531263,106.49492,2.0559661,334.02139,-9.2801352
2320,2320,165.4133,17.713835,7.9137306,0.0,0,1.7516665,0.0,0.75042433,106.48028,2.0264308,333.84015,-9.2804089
2322,2322,165.4137,17.81942,7.9477472,0.0,0,1.7226025,0.0,0.75366992,106.68193,1.9955238,333.65891,-9.2805395
2324,2324,165.4141,17.934723,7.9778895,0.0,0,1.6935385,0.0,0.75846589,106.86963,1.9615514,333.47766,-9.280798
2326,2326,165.4145,18.032112,8.0021534,0.0,0,1.6644745,0.0,0.76285815,107.02608,1.9333258,333.29642,-9.2809238
2328,2328,165.4149,18.111834,8.0418978,0.0,0,1.6354104,0.0,0.76678991,107.09207,1.9060591,333.11514,-9.279974
2330,2330,165.4153,18.207983,8.0682678,0.0,0,1.6063465,0.0,0.77175212,107.0957,1.8735899,332.9339,-9.2796526
2332,2332,165.4157,18.316322,8.0969114,0.0,0,1.5772824,0.0,0.77591068,107.28986,1.8443764,332.75266,-9.2797098
2334,2334,165.4161,18.44138,8.1354618,0.0,0,1.5491512,0.0,0.78031832,107.55742,1.8144982,332.57141,-9.2793636
2336,2336,165.4165,18.540485,8.1543226,0.0,0,1.5215,0.0,0.7849381,107.65958,1.7857356,332.39017,-9.2808132
2338,2338,165.4169,18.628313,8.1817894,0.0,0,1.493852,0.0,0.78794366,107.83695,1.7548785,332.20889,-9.2805338
2340,2340,165.4173,18.725248,8.2211008,0.0,0,1.466204,0.0,0.79310673,107.81296,1.724668,332.02765,-9.2793684
2342,2342,165.4177,18.838457,8.241004,0.0,0,1.4385561,0.0,0.79753822,108.01248,1.6964521,331.84641,-9.2785215
2344,2344,165.4181,18.973158,8.2738266,0.0,0,1.4109081,0.0,0.8009885,108.36016,1.6693604,331.67145,-9.2798948
2346,2346,165.4185,19.098444,8.3097439,0.0,0,1.3832601,0.0,0.80694735,108.43918,1.6414533,331.49759,-9.2804689
2348,2348,165.4189,19.188293,8.3311424,0.0,0,1.355612,0.0,0.81082547,108.50607,1.6114777,331.32373,-9.2795782
2350,2350,165.4193,19.289429,8.3661261,0.0,0,1.3279642,0.0,0.8145588,108.68337,1.5808899,331.14987,-9.2793865
2352,2352,165.4197,19.413481,8.3928843,0.0,0,1.3003161,0.0,0.82011044,108.80267,1.5504496,330.97601,-9.2788858
2354,2354,165.4201,19.558126,8.4181614,0.0,0,1.2726681,0.0,0.82343769,109.18384,1.5216247,330.80215,-9.2782564
2356,2356,165.4205,19.666561,8.4501114,0.0,0,1.2450202,0.0,0.8275699,109.41286,1.4942333,330.62827,-9.2785759
2358,2358,165.4209,19.749311,8.4752083,0.0,0,1.2176499,0.0,0.83281088,109.27383,1.4656005,330.45441,-9.2794485
2360,2360,165.4213,19.862228,8.5061197,0.0,0,1.191288,0.0,0.83618569,109.51275,1.4356955,330.28055,-9.2799416
2362,2362,165.4217,20.006973,8.5361347,0.0,0,1.1649919,0.0,0.84100235,109.76539,1.4057859,330.10669,-9.280324
2364,2364,165.4221,20.153505,8.5585833,0.0,0,1.1386957,0.0,0.8458823,110.02319,1.3771396,329.93283,-9.2787046
2366,2366,165.4225,20.270716,8.5947485,0.0,0,1.1123998,0.0,0.84952837,110.3104,1.3491476,329.75897,-9.2783003
2368,2368,165.4229,20.362679,8.6191893,0.0,0,1.0861038,0.0,0.85458928,110.28202,1.3236126,329.58511,-9.2786026
2370,2370,165.4233,20.489817,8.6426029,0.0,0,1.0598078,0.0,0.85843647,110.48633,1.2948987,329.41125,-9.2801027
2372,2372,165.4237,20.645992,8.6790762,0.0,0,1.0335118,0.0,0.86258894,110.85574,1.2652103,329.2374,-9.2793207
2374,2374,165.4241,20.814018,8.6993914,0.0,0,1.0072157,0.0,0.8678202,111.20635,1.2384472,329.06354,-9.2793636
2376,2376,165.4245,20.916698,8.7266788,0.0,0,0.98091978,0.0,0.87139434,111.36751,1.2105994,328.88968,-9.2786379
2378,2378,165.4249,21.024885,8.7656345,0.0,0,0.95462376,0.0,0.87680584,111.31375,1.1824056,328.71582,-9.2788029
2380,2380,165.4253,21.16214,8.7825022,0.0,0,0.92832786,0.0,0.88131279,111.54932,1.1534637,328.54196,-9.2784395
2382,2382,165.4257,21.335882,8.8108902,0.0,0,0.90203184,0.0,0.88420689,112.10114,1.1286167,328.3681,-9.27845
2384,2384,165.4261,21.475676,8.8448734,0.0,0,0.87658417,0.0,0.88993096,112.2111,1.1006775,328.19424,-9.2787571
2386,2386,165.4265,21.585197,8.863286,0.0,0,0.85157341,0.0,0.89417917,112.31563,1.0729889,328.02039,-9.2782803
2388,2388,165.4269,21.710665,8.8984442,0.0,0,0.82656538,0.0,0.89812523,112.48359,1.0447857,327.84653,-9.278389
2390,2390,165.4273,21.845133,8.9245214,0.0,0,0.80155742,0.0,0.90389919,112.60838,1.0172267,327.67267,-9.2781897
2392,2392,165.4277,22.004887,8.9440794,0.0,0,0.77654946,0.0,0.90685254,113.06615,0.99099863,327.49881,-9.277915
2394,2394,165.4281,22.162109,8.9745321,0.0,0,0.75154138,0.0,0.91082376,113.43241,0.9610101,327.31107,-9.2777491
2396,2396,165.4285,22.298059,8.9974222,0.0,0,0.72653341,0.0,0.91653752,113.43719,0.93525434,327.11987,-9.277874
2398,2398,165.4289,22.437054,9.0263939,0.0,0,0.70152539,0.0,0.91982192,113.77643,0.90863687,326.92868,-9.278389
2400,2400,165.4293,22.57822,9.0577488,0.0,0,0.67651743,0.0,0.92503822,113.9183,0.88233292,326.73752,-9.2783909
2402,2402,165.4297,22.745703,9.0805635,0.0,0,0.65150946,0.0,0.93060327,114.10491,0.85168618,326.54633,-9.2776098
2404,2404,165.4301,22.902576,9.1123753,0.0,0,0.62650138,0.0,0.9339062,114.51299,0.82933867,326.35513,-9.2770529
2406,2406,165.4305,23.036587,9.1329346,0.0,0,0.60149342,0.0,0.93864822,114.64332,0.80227184,326.16394,-9.2777796
2408,2408,165.4309,23.175552,9.150795,0.0,0,0.57673365,0.0,0.94221163,114.94232,0.77396542,325.97275,-9.2793283
2410,2410,165.4313,23.329514,9.1871271,0.0,0,0.55287462,0.0,0.94617289,115.23422,0.74954104,325.78156,-9.2791739
2412,2412,165.4317,23.506536,9.2065592,0.0,0,0.52907455,0.0,0.95156479,115.43363,0.72128016,325.59039,-9.2774296
2414,2414,165.4321,23.670557,9.2324924,0.0,0,0.50527453,0.0,0.95531327,115.8477,0.69519377,325.3992,-9.2762861
2416,2416,165.4325,23.800245,9.2691631,0.0,0,0.48147455,0.0,0.96053934,115.91949,0.66930711,325.20801,-9.275547
2418,2418,165.4329,23.943539,9.2834396,0.0,0,0.45767456,0.0,0.96531433,116.01361,0.64471871,325.01682,-9.277565
2420,2420,165.4333,24.105267,9.3096066,0.0,0,0.43387455,0.0,0.96816522,116.48846,0.61880863,324.82562,-9.2783041
2422,2422,165.4337,24.284681,9.3411751,0.0,0,0.41007456,0.0,0.97383046,116.67202,0.59383464,324.63443,-9.278101
2424,2424,165.4341,24.448692,9.3541088,0.0,0,0.38627455,0.0,0.97775757,117.04205,0.56883657,324.44327,-9.2771616
2426,2426,165.4345,24.600714,9.3829746,0.0,0,0.36247453,0.0,0.98100591,117.38772,0.54742277,324.25208,-9.2756119
2427,2427,165.4347,24.671164,9.3896418,0.0,0,0.35057452,0.0,0.98390716,117.38577,0.5349496,324.15646,-9.2760677