File: examples/hot axisymmetric compression example/data/03 trimmed data/testID_0138.csv
level_0,index,Time(sec),Force(kN),Jaw(mm),PowAngle(deg),Power(W),Pram,PTemp,Strain,Stress(MPa),Stroke(mm),TC1(C),wedge(mm)
1973,1973,165.3448,1.1929153,0.0049397689,0.0,0,9.0337067,0.0,0.0004131037,13.913824,10.069327,366.05283,-9.2889547
1975,1975,165.3452,4.1833806,0.046077829,0.0,0,8.9751787,0.0,0.0025571147,49.10289,9.9994001,366.42032,-9.2891808
1977,1977,165.3456,5.7447758,0.093895137,0.0,0,8.9166508,0.0,0.0062234914,71.709335,9.9401598,366.78784,-9.2880239
1979,1979,165.346,6.5363612,0.16673504,0.0,0,8.8581219,0.0,0.010415925,81.084839,9.871666,367.15536,-9.2848864
1981,1981,165.3464,6.8610334,0.30044442,0.0,0,8.7995939,0.0,0.019280119,85.813171,9.7890549,367.52286,-9.2844124
1983,1983,165.3468,7.2679081,0.38466361,0.0,0,8.7416534,0.0,0.025764674,89.302284,9.688344,367.88754,-9.2838135
1985,1985,165.3472,7.5888481,0.48586982,0.0,0,8.6858492,0.0,0.032036178,93.390381,9.5906782,368.19809,-9.2844925
1987,1987,165.3476,8.0880413,0.54053092,0.0,0,8.6301851,0.0,0.03646569,98.796066,9.4997864,368.50867,-9.2828865
1989,1989,165.348,7.7894135,0.5831117,0.0,0,8.574522,0.0,0.039452024,95.986282,9.43081,368.81921,-9.2831297
1991,1991,165.3484,7.9901423,0.66412133,0.0,0,8.518857,0.0,0.044558004,96.631721,9.3708715,369.12979,-9.2835369
1993,1993,165.3488,8.2674894,0.70693135,0.0,0,8.4631929,0.0,0.04803383,100.08778,9.3061762,369.44034,-9.2834911
1995,1995,165.3492,8.5689278,0.78766358,0.0,0,8.4075298,0.0,0.053222623,103.08552,9.2289286,369.75089,-9.2816095
1997,1997,165.3496,8.2878599,0.90385705,0.0,0,8.3518648,0.0,0.061094727,99.828964,9.1481209,370.06146,-9.2821465
1999,1999,165.35,8.417222,0.97596925,0.0,0,8.2962017,0.0,0.066942707,99.585861,9.0616188,370.37201,-9.2827816
2001,2001,165.3504,8.4959488,1.0539738,0.0,0,8.2405376,0.0,0.072335072,100.77423,8.9810848,370.68259,-9.2823067
2003,2003,165.3508,8.6119232,1.1013557,0.0,0,8.1848736,0.0,0.075799398,101.20741,8.9102192,370.99313,-9.2827272
2005,2005,165.3512,8.6542311,1.1410048,0.0,0,8.1292095,0.0,0.078972541,102.1539,8.8527775,371.30371,-9.2821417
2007,2007,165.3516,8.5800495,1.2044305,0.0,0,8.0735455,0.0,0.083155915,100.14865,8.7955008,371.61426,-9.2822351
2009,2009,165.352,8.9477091,1.2601793,0.0,0,8.0196619,0.0,0.087237664,104.19189,8.734458,371.92484,-9.2821941
2011,2011,165.3524,8.9296608,1.3366531,0.0,0,7.9666953,0.0,0.092888452,103.55205,8.6719694,372.23538,-9.2823687
2013,2013,165.3528,8.8899527,1.4146684,0.0,0,7.9137359,0.0,0.098356552,102.78444,8.6052771,372.54596,-9.28195
2015,2015,165.3532,8.8107328,1.4838626,0.0,0,7.8607755,0.0,0.10384245,101.00597,8.5333967,372.85651,-9.2824936
2017,2017,165.3536,8.9796381,1.5425806,0.0,0,7.8078156,0.0,0.10816115,102.51373,8.4641457,373.16708,-9.2820187
2019,2019,165.354,9.0303326,1.5834581,0.0,0,7.7548552,0.0,0.11107834,102.73123,8.4051723,373.47763,-9.2818947
2021,2021,165.3544,9.055582,1.6427799,0.0,0,7.7018952,0.0,0.11577302,102.82114,8.3464575,373.78821,-9.2833462
2023,2023,165.3548,8.9811621,1.6982923,0.0,0,7.6489348,0.0,0.11963145,101.39011,8.292346,374.09875,-9.2835131
2025,2025,165.3552,9.2538357,1.7453718,0.0,0,7.5959754,0.0,0.12315945,103.84354,8.2394962,374.40933,-9.2822132
2027,2027,165.3556,9.2546692,1.8091917,0.0,0,7.543015,0.0,0.12840812,103.72401,8.1844463,374.71988,-9.2814598
2029,2029,165.356,9.2855453,1.874349,0.0,0,7.4900556,0.0,0.13266446,103.52471,8.1238127,375.03046,-9.2813072
2031,2031,165.3564,9.2067728,1.9333948,0.0,0,7.4370952,0.0,0.13758367,102.27359,8.0637255,375.341,-9.2810154
2033,2033,165.3568,9.282053,1.9800955,0.0,0,7.3846664,0.0,0.1414481,102.34193,8.0045385,375.604,-9.2824087
2035,2035,165.3572,9.3705244,2.0283029,0.0,0,7.3341722,0.0,0.14442633,103.19083,7.9516344,375.43921,-9.2833996
2037,2037,165.3576,9.4045095,2.0773652,0.0,0,7.2838039,0.0,0.1488719,103.09262,7.8986254,375.27441,-9.2825565
2039,2039,165.358,9.3902931,2.1236475,0.0,0,7.2334356,0.0,0.15233296,102.65845,7.848958,375.10962,-9.2823458
2041,2041,165.3584,9.4926281,2.181921,0.0,0,7.1830673,0.0,0.15644498,103.20927,7.7974629,374.94482,-9.2826023
2043,2043,165.3588,9.5652714,2.2317948,0.0,0,7.1326995,0.0,0.16100898,103.71896,7.7430797,374.78003,-9.2826662
2045,2045,165.3592,9.5592623,2.2849147,0.0,0,7.0823312,0.0,0.16464809,103.17303,7.6950684,374.61523,-9.2819395
2047,2047,165.3596,9.569911,2.347358,0.0,0,7.0319633,0.0,0.16963995,102.83069,7.6431651,374.45044,-9.2805796
2049,2049,165.36,9.6174345,2.3801398,0.0,0,6.981595,0.0,0.17279623,102.9662,7.5896368,374.28564,-9.2820911
2051,2051,165.3604,9.680624,2.4285603,0.0,0,6.9312277,0.0,0.17587763,103.43607,7.5392528,374.12085,-9.2840509
2053,2053,165.3608,9.6534948,2.481344,0.0,0,6.8808594,0.0,0.1805921,102.65644,7.4944034,373.95605,-9.2847528
2055,2055,165.3612,9.7009506,2.5222154,0.0,0,6.830492,0.0,0.18381432,102.7254,7.4453359,373.79126,-9.2829056
2057,2057,165.3616,9.828474,2.5783565,0.0,0,6.7801232,0.0,0.18785861,103.5631,7.3943777,373.6265,-9.2821274
2059,2059,165.362,9.8434916,2.6250005,0.0,0,6.7313671,0.0,0.19239147,103.42896,7.347693,373.4617,-9.2811975
2061,2061,165.3624,9.8165541,2.6755109,0.0,0,6.6834416,0.0,0.19592471,102.80219,7.2943473,373.29691,-9.2812672
2063,2063,165.3628,9.8342304,2.7272213,0.0,0,6.6355219,0.0,0.20007141,102.39548,7.2469912,373.13211,-9.2827978
2065,2065,165.3632,9.9336891,2.7615223,0.0,0,6.5876017,0.0,0.20355406,103.05106,7.1961331,372.96732,-9.2826023
2067,2067,165.3636,10.002175,2.8154166,0.0,0,6.5396819,0.0,0.20713684,103.53245,7.1527452,372.80252,-9.2823439
2069,2069,165.364,9.9986134,2.8618307,0.0,0,6.4917622,0.0,0.21135193,103.05859,7.1036983,372.63773,-9.282074
2071,2071,165.3644,10.00335,2.9046454,0.0,0,6.4438419,0.0,0.21516974,102.72855,7.0579667,372.47293,-9.2812986
2073,2073,165.3648,10.090338,2.962471,0.0,0,6.3959212,0.0,0.21913116,103.1427,7.0114365,372.30814,-9.2815857
2075,2075,165.3652,10.168361,3.0013537,0.0,0,6.3480015,0.0,0.2230936,103.52316,6.9615545,372.14334,-9.2821884
2077,2077,165.3656,10.183341,3.0483174,0.0,0,6.3000817,0.0,0.2268541,103.36362,6.9121528,371.97855,-9.2822638
2079,2079,165.366,10.178814,3.1056979,0.0,0,6.252162,0.0,0.23115009,102.84295,6.8642821,371.81375,-9.2828112
2081,2081,165.3664,10.231557,3.1421869,0.0,0,6.2042422,0.0,0.23501733,102.89438,6.8165674,371.64899,-9.2827826
2083,2083,165.3668,10.278911,3.1910679,0.0,0,6.1568027,0.0,0.23865588,103.03504,6.7671814,371.49091,-9.2829103
2085,2085,165.3672,10.341702,3.2424533,0.0,0,6.1111121,0.0,0.24293886,103.28339,6.7189617,371.37094,-9.2813377
2087,2087,165.3676,10.376317,3.2825713,0.0,0,6.065536,0.0,0.24693874,103.20623,6.6722112,371.25101,-9.2813454
2089,2089,165.368,10.409492,3.3332376,0.0,0,6.0199599,0.0,0.25058722,103.11764,6.624115,371.13104,-9.2822676
2091,2091,165.3684,10.457788,3.382803,0.0,0,5.9743834,0.0,0.25524512,103.10281,6.576292,371.01108,-9.2834139
2093,2093,165.3688,10.487926,3.4284368,0.0,0,5.9288077,0.0,0.25922874,102.95848,6.5296354,370.89111,-9.2836666
2095,2095,165.3692,10.541587,3.4777844,0.0,0,5.8832321,0.0,0.26305869,103.12067,6.4825187,370.77118,-9.2827263
2097,2097,165.3696,10.595619,3.5260329,0.0,0,5.8376555,0.0,0.26789802,103.14867,6.4334655,370.65121,-9.2812614
2099,2099,165.37,10.621255,3.5730126,0.0,0,5.792079,0.0,0.27163619,103.0332,6.3837967,370.53125,-9.2820778
2101,2101,165.3704,10.664164,3.6213284,0.0,0,5.7465038,0.0,0.27569842,103.02805,6.3374949,370.41129,-9.2833853
2103,2103,165.3708,10.707494,3.6668818,0.0,0,5.7009277,0.0,0.28036034,103.01135,6.2918038,370.29135,-9.2826462
2105,2105,165.3712,10.777369,3.7177033,0.0,0,5.6553516,0.0,0.28411111,103.23565,6.240623,370.17139,-9.2835464
2107,2107,165.3716,10.820365,3.7639329,0.0,0,5.6097755,0.0,0.28851449,103.21496,6.1939926,370.05142,-9.2821589
2109,2109,165.372,10.836491,3.8079457,0.0,0,5.5656581,0.0,0.29289877,102.95441,6.1473823,369.93146,-9.2819996
2111,2111,165.3724,10.86016,3.8618393,0.0,0,5.5222936,0.0,0.29672062,102.79898,6.0988269,369.81152,-9.2825918
2113,2113,165.3728,10.927508,3.9055474,0.0,0,5.4789333,0.0,0.30137467,102.89898,6.0516529,369.69156,-9.2824278
2115,2115,165.3732,10.986647,3.9504681,0.0,0,5.4355736,0.0,0.30537739,103.05132,6.0065298,369.57159,-9.2821512
2117,2117,165.3736,11.030666,4.0037003,0.0,0,5.3922133,0.0,0.30953759,103.01001,5.9581671,369.45163,-9.282403
2119,2119,165.374,11.05323,4.0425668,0.0,0,5.3488536,0.0,0.31400561,102.76389,5.9112048,369.3317,-9.2828197
2121,2121,165.3744,11.090002,4.0883594,0.0,0,5.3054934,0.0,0.31764939,102.72708,5.8625979,369.21173,-9.2832403
2123,2123,165.3748,11.142904,4.1426592,0.0,0,5.2621331,0.0,0.32242784,102.73954,5.8167152,369.09177,-9.2827959
2125,2125,165.3752,11.203777,4.1810174,0.0,0,5.2187734,0.0,0.32679328,102.81868,5.7690811,368.97183,-9.2820206
2127,2127,165.3756,11.256859,4.2302623,0.0,0,5.1754136,0.0,0.33059216,102.95559,5.7235017,368.85187,-9.2814941
2129,2129,165.376,11.284446,4.2840872,0.0,0,5.1320534,0.0,0.33582932,102.63769,5.6752048,368.7319,-9.2821865
2131,2131,165.3764,11.318296,4.3239999,0.0,0,5.0886931,0.0,0.33992767,102.51913,5.6290803,368.61194,-9.2825642
2133,2133,165.3768,11.370773,4.3733873,0.0,0,5.0457683,0.0,0.34381714,102.58454,5.5828195,368.42801,-9.2825193
2135,2135,165.3772,11.425694,4.4161863,0.0,0,5.0044241,0.0,0.34869853,102.67133,5.5372324,367.98822,-9.2826452
2137,2137,165.3776,11.480114,4.4586115,0.0,0,4.9631839,0.0,0.35241067,102.72411,5.4874387,367.54843,-9.2823181
2139,2139,165.378,11.507144,4.5098696,0.0,0,4.9219441,0.0,0.356938,102.50632,5.4417195,367.10864,-9.2824469
2141,2141,165.3784,11.522997,4.5529237,0.0,0,4.8807039,0.0,0.36184144,102.14529,5.3972144,366.66885,-9.2824268
2143,2143,165.3788,11.594222,4.6013136,0.0,0,4.8394642,0.0,0.36564836,102.28134,5.3507447,366.22906,-9.2816887
2145,2145,165.3792,11.657073,4.6463404,0.0,0,4.798224,0.0,0.37011924,102.4735,5.3081694,365.78928,-9.2821894
2147,2147,165.3796,11.705957,4.6864552,0.0,0,4.7569842,0.0,0.37468514,102.44297,5.2629886,365.34949,-9.2820749
2149,2149,165.38,11.719223,4.7385273,0.0,0,4.715744,0.0,0.37879369,102.21956,5.2193236,364.9097,-9.2828732
2151,2151,165.3804,11.749196,4.7802906,0.0,0,4.6745043,0.0,0.38338432,101.90566,5.1730194,364.46994,-9.2838755
2153,2153,165.3808,11.819448,4.8224831,0.0,0,4.6332641,0.0,0.38771656,102.06319,5.1278172,364.03015,-9.2828388
2155,2155,165.3812,11.896065,4.8763885,0.0,0,4.5920238,0.0,0.3920376,102.28379,5.0804043,363.59036,-9.2820692
2157,2157,165.3816,11.921979,4.9133015,0.0,0,4.5507841,0.0,0.39685723,102.02042,5.0373664,363.15057,-9.2826223
2159,2159,165.382,11.942378,4.9570851,0.0,0,4.5108657,0.0,0.40072596,101.83525,4.9913445,362.71078,-9.2820148
2161,2161,165.3824,11.993333,5.0071869,0.0,0,4.4716296,0.0,0.40530765,101.78107,4.9495397,362.271,-9.2814283
2163,2163,165.3828,12.05731,5.0424705,0.0,0,4.4323978,0.0,0.40989378,101.87127,4.9078693,361.83121,-9.2822323
2165,2165,165.3832,12.123912,5.0914106,0.0,0,4.3931656,0.0,0.41378674,101.99076,4.8622065,361.39142,-9.2826338
2167,2167,165.3836,12.158972,5.1412091,0.0,0,4.3539338,0.0,0.41918826,101.82493,4.8196235,360.95163,-9.2820225
2169,2169,165.384,12.179654,5.1764436,0.0,0,4.314702,0.0,0.42331895,101.50935,4.7761264,360.51184,-9.2817068
2171,2171,165.3844,12.232708,5.2227974,0.0,0,4.2754698,0.0,0.42709121,101.57432,4.7296886,360.07208,-9.2817669
2173,2173,165.3848,12.311827,5.2647538,0.0,0,4.2362375,0.0,0.43225899,101.63293,4.6881657,359.63229,-9.2815514
2175,2175,165.3852,12.36078,5.3038464,0.0,0,4.1970053,0.0,0.43600461,101.72173,4.6477103,359.1925,-9.281354
2177,2177,165.3856,12.393806,5.349174,0.0,0,4.1577735,0.0,0.44013163,101.60064,4.6025925,358.75272,-9.282217
2179,2179,165.386,12.418296,5.3898082,0.0,0,4.1185417,0.0,0.44526383,101.30848,4.5620508,358.31293,-9.282033
2181,2181,165.3864,12.487411,5.4334803,0.0,0,4.0793095,0.0,0.44911399,101.37989,4.5210819,357.87314,-9.2822752
2183,2183,165.3868,12.54425,5.4777293,0.0,0,4.0404716,0.0,0.45375222,101.38635,4.4793315,357.45709,-9.2818918
2185,2185,165.3872,12.602687,5.5141444,0.0,0,4.0030656,0.0,0.45853773,101.43113,4.4353695,357.11224,-9.2816992
2187,2187,165.3876,12.63735,5.560575,0.0,0,3.9657533,0.0,0.46222398,101.2728,4.3936558,356.76736,-9.2819033
2189,2189,165.388,12.688177,5.5994787,0.0,0,3.9284413,0.0,0.46691117,101.16376,4.3534131,356.42252,-9.2813988
2191,2191,165.3884,12.734859,5.6347389,0.0,0,3.8911293,0.0,0.47101706,101.21924,4.3135839,356.07764,-9.2804413
2193,2193,165.3888,12.815489,5.6843462,0.0,0,3.8538175,0.0,0.47513938,101.42862,4.2710962,355.73279,-9.2806215
2195,2195,165.3892,12.862727,5.7194881,0.0,0,3.8165054,0.0,0.48012045,101.29766,4.2282867,355.38791,-9.2821589
2197,2197,165.3896,12.903205,5.7605634,0.0,0,3.7791932,0.0,0.48412317,101.20603,4.1860781,355.04306,-9.2828369
2199,2199,165.39,12.942401,5.8100572,0.0,0,3.7418811,0.0,0.48896447,100.9455,4.1488481,354.69818,-9.2824879
2201,2201,165.3904,13.012091,5.8396964,0.0,0,3.7045693,0.0,0.49338469,101.09483,4.1068358,354.35333,-9.2815447
2203,2203,165.3908,13.079983,5.8788033,0.0,0,3.6672573,0.0,0.49676546,101.29031,4.0685844,354.00848,-9.2817106
2205,2205,165.3912,13.149238,5.9265547,0.0,0,3.6299453,0.0,0.50198019,101.22497,4.0262728,353.6636,-9.2812061
2207,2207,165.3916,13.183145,5.9590015,0.0,0,3.5926332,0.0,0.50630957,101.08225,3.9856319,353.31876,-9.281826
2209,2209,165.392,13.245503,6.0043654,0.0,0,3.5565166,0.0,0.51024044,101.18549,3.9464488,352.97388,-9.2815218
2211,2211,165.3924,13.296005,6.0455403,0.0,0,3.5210168,0.0,0.51566285,101.05579,3.9112043,352.62903,-9.282053
2213,2213,165.3928,13.359416,6.0790939,0.0,0,3.4855206,0.0,0.51943094,101.16447,3.8695557,352.28415,-9.2821798
2215,2215,165.3932,13.421166,6.1220884,0.0,0,3.4500248,0.0,0.52357453,101.19415,3.8294182,351.9393,-9.2818928
2217,2217,165.3936,13.470981,6.1564302,0.0,0,3.4145288,0.0,0.52842969,101.05031,3.7908542,351.59442,-9.2811556
2219,2219,165.394,13.50957,6.1940632,0.0,0,3.3790326,0.0,0.53207797,100.97536,3.7530615,351.24957,-9.2816153
2221,2221,165.3944,13.572731,6.2364702,0.0,0,3.3435369,0.0,0.53664684,100.96053,3.7155898,350.90472,-9.2820282
2223,2223,165.3948,13.657862,6.2715187,0.0,0,3.3080409,0.0,0.54175162,101.08267,3.6781151,350.55984,-9.2820444
2225,2225,165.3952,13.729022,6.3150091,0.0,0,3.2725446,0.0,0.545479,101.26797,3.6389222,350.215,-9.2809515
2227,2227,165.3956,13.769493,6.3498211,0.0,0,3.2370486,0.0,0.55002111,101.1334,3.6027167,349.87012,-9.2806902
2229,2229,165.396,13.806307,6.3799095,0.0,0,3.2015526,0.0,0.55423278,101.00449,3.5637994,349.52527,-9.2803183
2231,2231,165.3964,13.869314,6.4270287,0.0,0,3.1660566,0.0,0.55820042,101.02931,3.5273416,349.18039,-9.2806711
2233,2233,165.3968,13.964731,6.4582891,0.0,0,3.1309152,0.0,0.56308734,101.20911,3.4921262,348.93353,-9.2815914
2235,2235,165.3972,14.030474,6.4943228,0.0,0,3.0970623,0.0,0.56702316,101.27103,3.453675,348.91528,-9.281311
2237,2237,165.3976,14.068712,6.5414581,0.0,0,3.0632944,0.0,0.57166028,101.07906,3.4203479,348.897,-9.281744
2239,2239,165.398,14.116496,6.5675292,0.0,0,3.0295265,0.0,0.57611424,100.93856,3.3808792,348.87872,-9.2806168
2241,2241,165.3984,14.193636,6.6037722,0.0,0,2.9957583,0.0,0.57958454,101.16021,3.3442905,348.86047,-9.2808113
2243,2243,165.3988,14.2732,6.6462774,0.0,0,2.9619906,0.0,0.58444744,101.30169,3.309288,348.84219,-9.2805662
2245,2245,165.3992,14.333548,6.6729255,0.0,0,2.9282222,0.0,0.58877164,101.25211,3.2748923,348.82394,-9.2804871
2247,2247,165.3996,14.389856,6.7136025,0.0,0,2.8944542,0.0,0.59235913,101.28341,3.2383006,348.80566,-9.2807512
2249,2249,165.4,14.429812,6.7523212,0.0,0,2.8606863,0.0,0.59781247,101.06939,3.2040048,348.78738,-9.280509
2251,2251,165.4004,14.514577,6.7809772,0.0,0,2.8269184,0.0,0.60150963,101.22608,3.1674647,348.76913,-9.280488
2253,2253,165.4008,14.603241,6.82026,0.0,0,2.7931502,0.0,0.60527861,101.4488,3.1316686,348.75085,-9.2807512
2255,2255,165.4012,14.657215,6.852921,0.0,0,2.7593822,0.0,0.61050767,101.32491,3.0965729,348.73257,-9.2810888
2257,2257,165.4016,14.701217,6.8854952,0.0,0,2.7256143,0.0,0.61405545,101.25215,3.0587826,348.71432,-9.2807207
2259,2259,165.402,14.763168,6.9253764,0.0,0,2.6929309,0.0,0.61839396,101.22193,3.0259814,348.69604,-9.2806492
2261,2261,165.4024,14.848374,6.954071,0.0,0,2.6608074,0.0,0.62330222,101.28957,2.992801,348.67776,-9.2806177
2263,2263,165.4028,14.944722,6.9894061,0.0,0,2.6286874,0.0,0.62646931,101.66744,2.9590404,348.65952,-9.2808628
2265,2265,165.4032,15.008615,7.0235696,0.0,0,2.5965672,0.0,0.63096291,101.64449,2.9254458,348.64124,-9.2805576
2267,2267,165.4036,15.055572,7.0541458,0.0,0,2.5644474,0.0,0.63565999,101.47064,2.8908637,348.62299,-9.2803993
2269,2269,165.404,15.122825,7.0972338,0.0,0,2.5323272,0.0,0.63965225,101.55286,2.8558156,348.60471,-9.2804384
2271,2271,165.4044,15.210993,7.1256313,0.0,0,2.5002072,0.0,0.64423317,101.63232,2.8221056,348.58643,-9.2802143
2273,2273,165.4048,15.299659,7.1559625,0.0,0,2.4680872,0.0,0.64815909,101.83376,2.7930138,348.56818,-9.2804842
2275,2275,165.4052,15.370317,7.19946,0.0,0,2.4359674,0.0,0.65247798,101.90749,2.7591729,348.5499,-9.2793827
2277,2277,165.4056,15.428474,7.2242603,0.0,0,2.4038472,0.0,0.65715313,101.72193,2.7261121,348.53162,-9.2795143
2279,2279,165.406,15.502721,7.2556157,0.0,0,2.3717272,0.0,0.66053283,101.91291,2.6929443,348.51337,-9.2795343
2281,2281,165.4064,15.609646,7.2988076,0.0,0,2.3396072,0.0,0.66549486,102.09079,2.6582158,348.49509,-9.280571
2283,2283,165.4068,15.692349,7.3202529,0.0,0,2.3078089,0.0,0.66986859,102.21834,2.6256886,348.3728,-9.2801962
2285,2285,165.4072,15.756914,7.3567939,0.0,0,2.2771804,0.0,0.67326921,102.29347,2.59062,348.05737,-9.2797232
2287,2287,165.4076,15.813579,7.3963842,0.0,0,2.246628,0.0,0.67880839,102.04384,2.5569725,347.74197,-9.2795229
2289,2289,165.408,15.900475,7.4207401,0.0,0,2.2160764,0.0,0.68263471,102.23662,2.523416,347.42654,-9.2810688
2291,2291,165.4084,16.002428,7.4587355,0.0,0,2.1855242,0.0,0.68651623,102.47662,2.4905193,347.11115,-9.279705
2293,2293,165.4088,16.084108,7.4914818,0.0,0,2.1549723,0.0,0.69215173,102.44511,2.4580441,346.79572,-9.2792606
2295,2295,165.4092,16.15695,7.519052,0.0,0,2.1244202,0.0,0.69527864,102.553,2.4260664,346.48032,-9.2784538
2297,2297,165.4096,16.225451,7.5550075,0.0,0,2.0938683,0.0,0.69956177,102.60081,2.3935683,346.16489,-9.2795
2299,2299,165.41,16.311108,7.5837574,0.0,0,2.0633163,0.0,0.70475084,102.57368,2.3614931,345.84949,-9.2812738
2301,2301,165.4104,16.413067,7.6172638,0.0,0,2.0327644,0.0,0.70809138,102.89262,2.3306932,345.53409,-9.281024
2303,2303,165.4108,16.503361,7.6505432,0.0,0,2.0022123,0.0,0.71270829,102.99315,2.2985716,345.21866,-9.2797031
2305,2305,165.4112,16.589661,7.6773715,0.0,0,1.9716601,0.0,0.71749175,103.06227,2.267777,344.90326,-9.2788944
2307,2307,165.4116,16.671301,7.7166047,0.0,0,1.9411081,0.0,0.72115475,103.11626,2.2342579,344.58783,-9.2794361
2309,2309,165.412,16.769382,7.7439232,0.0,0,1.9115355,0.0,0.72608948,103.24526,2.205934,344.27243,-9.2800388
2311,2311,165.4124,16.868286,7.770782,0.0,0,1.8824685,0.0,0.73005736,103.41107,2.1727366,343.957,-9.2802572
2313,2313,165.4128,16.975977,7.8124633,0.0,0,1.8534043,0.0,0.73418969,103.58126,2.1427481,343.6416,-9.2798281
2315,2315,165.4132,17.051796,7.836987,0.0,0,1.8243403,0.0,0.73914862,103.6255,2.109005,343.32617,-9.2791462
2317,2317,165.4136,17.122997,7.8673515,0.0,0,1.7952764,0.0,0.74284613,103.64767,2.0775445,343.01077,-9.27948
2319,2319,165.414,17.215063,7.9080157,0.0,0,1.7662123,0.0,0.74787027,103.70245,2.0502529,342.69534,-9.27985
2321,2321,165.4144,17.327343,7.9308295,0.0,0,1.7371484,0.0,0.75268626,103.84685,2.0176518,342.37994,-9.2793446
2323,2323,165.4148,17.44562,7.9630384,0.0,0,1.7080843,0.0,0.75601006,104.21414,1.9842019,342.06451,-9.2795858
2325,2325,165.4152,17.537104,7.9996963,0.0,0,1.6790204,0.0,0.76129711,104.2374,1.9543368,341.74911,-9.2785025
2327,2327,165.4156,17.616812,8.0206299,0.0,0,1.6499563,0.0,0.76543117,104.28213,1.9251059,341.43369,-9.2789097
2329,2329,165.416,17.716263,8.0582962,0.0,0,1.6208923,0.0,0.76931453,104.4371,1.8917954,341.11829,-9.2790737
2331,2331,165.4164,17.83976,8.0904646,0.0,0,1.5918283,0.0,0.77509302,104.54206,1.8619317,340.80286,-9.2793865
2333,2333,165.4168,17.955742,8.1161814,0.0,0,1.5630548,0.0,0.77881324,104.8122,1.8319062,340.57077,-9.2786951
2335,2335,165.4172,18.028851,8.1512785,0.0,0,1.5353373,0.0,0.78280324,104.89641,1.8000036,340.46359,-9.2783012
2337,2337,165.4176,18.099117,8.1778364,0.0,0,1.5076892,0.0,0.78828299,104.74937,1.7711058,340.35641,-9.2785816
2339,2339,165.418,18.217421,8.2064705,0.0,0,1.4800413,0.0,0.79148155,105.047,1.7401544,340.24927,-9.2781868
2341,2341,165.4184,18.357042,8.2389622,0.0,0,1.4523933,0.0,0.79599506,105.35543,1.7125008,340.14209,-9.2781773
2343,2343,165.4188,18.467155,8.262208,0.0,0,1.4247453,0.0,0.80083758,105.50359,1.6854877,340.03491,-9.27771
2345,2345,165.4192,18.545723,8.2992163,0.0,0,1.3970973,0.0,0.8045131,105.58076,1.6523209,339.92773,-9.2786112
2347,2347,165.4196,18.635208,8.3288012,0.0,0,1.3694494,0.0,0.80982,105.51978,1.6234834,339.82056,-9.2781858
2349,2349,165.42,18.740908,8.3532906,0.0,0,1.3418013,0.0,0.81430179,105.6608,1.5954634,339.71338,-9.27808
2351,2351,165.4204,18.883709,8.3899145,0.0,0,1.3141534,0.0,0.81785381,106.00517,1.5691552,339.60623,-9.2781277
2353,2353,165.4208,19.000782,8.4096451,0.0,0,1.2865053,0.0,0.82250226,106.1996,1.5381924,339.49905,-9.2786636
2355,2355,165.4212,19.085985,8.436347,0.0,0,1.2588574,0.0,0.82618141,106.31108,1.5084271,339.39188,-9.2788057
2357,2357,165.4216,19.198997,8.4777317,0.0,0,1.2312094,0.0,0.83122438,106.37127,1.4776182,339.2847,-9.2773838
2359,2359,165.422,19.328985,8.4980888,0.0,0,1.2044513,0.0,0.83649218,106.54948,1.4511662,339.17752,-9.2766724
2361,2361,165.4224,19.471087,8.5284758,0.0,0,1.1781524,0.0,0.8398298,106.98653,1.4206216,339.07034,-9.2775326
2363,2363,165.4228,19.587252,8.5637283,0.0,0,1.1518564,0.0,0.84501582,107.08701,1.3943204,338.9632,-9.2790041
2365,2365,165.4232,19.671843,8.5805769,0.0,0,1.1255604,0.0,0.84926081,107.11375,1.3640245,338.85602,-9.2783594
2367,2367,165.4236,19.789438,8.6130524,0.0,0,1.0992644,0.0,0.85256183,107.32346,1.3350537,338.74884,-9.2773724
2369,2369,165.424,19.914505,8.6437197,0.0,0,1.0729684,0.0,0.85847414,107.3944,1.3066056,338.64166,-9.2761478
2371,2371,165.4244,20.078072,8.6648245,0.0,0,1.0466723,0.0,0.86208946,107.85659,1.2772356,338.53448,-9.2768784
2373,2373,165.4248,20.195126,8.7003727,0.0,0,1.0203763,0.0,0.86619306,108.10126,1.2495279,338.42734,-9.2781839
2375,2375,165.4252,20.303856,8.7273092,0.0,0,0.99408036,0.0,0.87225986,107.98792,1.2231205,338.32016,-9.2790709
2377,2377,165.4256,20.42914,8.7529306,0.0,0,0.96778435,0.0,0.87537855,108.2804,1.194827,338.21298,-9.2782717
2379,2379,165.426,20.578804,8.7844505,0.0,0,0.94148839,0.0,0.87995142,108.58938,1.1658703,338.1058,-9.2776527
2381,2381,165.4264,20.735321,8.8059664,0.0,0,0.91519243,0.0,0.88507086,108.85715,1.1367476,337.99863,-9.2763824
2383,2383,165.4268,20.857821,8.836935,0.0,0,0.88916051,0.0,0.88842982,109.19116,1.1076781,337.98575,-9.2763042
2385,2385,165.4272,20.964359,8.8663836,0.0,0,0.86408949,0.0,0.89368165,109.18367,1.0834889,338.08804,-9.2773199
2387,2387,165.4276,21.094738,8.88976,0.0,0,0.83908135,0.0,0.89858532,109.2708,1.054765,338.19034,-9.2774544
2389,2389,165.428,21.245407,8.9252462,0.0,0,0.81407332,0.0,0.90247709,109.59781,1.0280242,338.29263,-9.2780161
2391,2391,165.4284,21.392466,8.945632,0.0,0,0.78906536,0.0,0.90722507,109.90755,0.99906868,338.39493,-9.2771215
2393,2393,165.4288,21.517639,8.9673328,0.0,0,0.7640574,0.0,0.91072363,110.154,0.97009867,338.49725,-9.2760191
2395,2395,165.4292,21.637888,9.003912,0.0,0,0.73904938,0.0,0.91525573,110.26169,0.94501382,338.59955,-9.2764311
2397,2397,165.4296,21.779057,9.0215712,0.0,0,0.71404135,0.0,0.9205097,110.36459,0.91531616,338.70184,-9.2759018
2399,2399,165.43,21.93919,9.0509405,0.0,0,0.68903339,0.0,0.92409593,110.74213,0.8907817,338.80414,-9.2767868
2401,2401,165.4304,22.104143,9.087018,0.0,0,0.66402543,0.0,0.9297232,110.97915,0.86301404,338.90643,-9.27738
2403,2403,165.4308,22.235271,9.1051006,0.0,0,0.63901734,0.0,0.9345206,111.14208,0.83562785,339.00876,-9.2767706
2405,2405,165.4312,22.376045,9.1346884,0.0,0,0.61400938,0.0,0.93758953,111.47383,0.81022453,339.11105,-9.2758112
2407,2407,165.4316,22.516792,9.1627541,0.0,0,0.58900136,0.0,0.94334263,111.56412,0.78538263,339.21335,-9.2763205
2409,2409,165.432,22.669813,9.1797018,0.0,0,0.56478846,0.0,0.94691998,111.87769,0.75702977,339.31564,-9.2755442
2411,2411,165.4324,22.827164,9.2115002,0.0,0,0.54098594,0.0,0.95076257,112.28519,0.73088235,339.41794,-9.2759991
2413,2413,165.4328,22.96637,9.2374287,0.0,0,0.51718587,0.0,0.95690209,112.23843,0.704826,339.52026,-9.2758055
2415,2415,165.4332,23.10787,9.2603588,0.0,0,0.49338591,0.0,0.96035004,112.56908,0.67963833,339.62256,-9.2763624
2417,2417,165.4336,23.254652,9.290494,0.0,0,0.4695859,0.0,0.96459466,112.7837,0.65109587,339.72485,-9.2771358
2419,2419,165.434,23.418932,9.3085451,0.0,0,0.44578591,0.0,0.96994406,112.93867,0.6281271,339.82715,-9.2745771
2421,2421,165.4344,23.574181,9.3347263,0.0,0,0.42198589,0.0,0.97276819,113.40212,0.60160476,339.92944,-9.2750835
2423,2423,165.4348,23.717697,9.3626566,0.0,0,0.39818591,0.0,0.97769719,113.5498,0.57576585,340.03174,-9.2763119
2425,2425,165.4352,23.852461,9.3821173,0.0,0,0.37438589,0.0,0.98289603,113.58476,0.55167931,340.13406,-9.2772884
2426,2426,165.4354,23.924355,9.4005766,0.0,0,0.36248589,0.0,0.98502868,113.66866,0.53969985,340.18521,-9.2776518