File: examples/hot axisymmetric compression example/data/03 trimmed data/testID_0141.csv
level_0,index,Time(sec),Force(kN),Jaw(mm),PowAngle(deg),Power(W),Pram,PTemp,Strain,Stress(MPa),Stroke(mm),TC1(C),wedge(mm)
1972,1972,165.3446,0.17373385,0.041767292,0.0,0,9.0629702,0.0,0.0025008966,1.8865349,10.081654,359.45267,-9.2893105
1974,1974,165.345,3.0217962,0.07847099,0.0,0,9.0044422,0.0,0.0050025117,32.782932,10.005486,359.63733,-9.2893534
1976,1976,165.3454,5.9221358,0.14450262,0.0,0,8.9459143,0.0,0.0092860721,72.626816,9.9529362,359.82202,-9.2878704
1978,1978,165.3458,6.506928,0.20908505,0.0,0,8.8873854,0.0,0.013261824,81.10601,9.8744173,360.00671,-9.2854204
1980,1980,165.3462,6.9048162,0.35445711,0.0,0,8.8288574,0.0,0.023088818,85.976791,9.7863255,360.19141,-9.2833652
1982,1982,165.3466,7.1178908,0.42836994,0.0,0,8.7703295,0.0,0.028584333,87.010574,9.6884098,360.37607,-9.2845488
1984,1984,165.347,7.7319679,0.51553786,0.0,0,8.7136869,0.0,0.034118455,94.924675,9.5913668,360.56076,-9.2853117
1986,1986,165.3474,8.2003727,0.59724092,0.0,0,8.6580172,0.0,0.04054711,99.336609,9.5086136,360.74545,-9.2842531
1988,1988,165.3478,8.0497246,0.60779721,0.0,0,8.6023531,0.0,0.04097141,99.426895,9.4290409,360.93011,-9.2822275
1990,1990,165.3482,7.7280664,0.70670503,0.0,0,8.546689,0.0,0.047617067,93.232689,9.36831,361.11481,-9.2833853
1992,1992,165.3486,8.4773407,0.7594291,0.0,0,8.491025,0.0,0.051861852,102.04094,9.3044529,361.2995,-9.2837934
1994,1994,165.349,8.5772409,0.81977403,0.0,0,8.4353609,0.0,0.05534387,103.07723,9.2272921,361.48416,-9.2818966
1996,1996,165.3494,8.6076345,0.92826355,0.0,0,8.3796968,0.0,0.063471228,103.34853,9.1530218,361.66885,-9.2820511
1998,1998,165.3498,8.2415075,1.0018117,0.0,0,8.3240328,0.0,0.068527594,97.93335,9.0715761,361.85355,-9.2830315
2000,2000,165.3502,8.7016525,1.0768085,0.0,0,8.2683687,0.0,0.073863521,102.48198,8.9927044,362.03824,-9.2827959
2002,2002,165.3506,8.63731,1.1234082,0.0,0,8.2127056,0.0,0.077873677,101.73685,8.9195108,362.2229,-9.2831011
2004,2004,165.351,8.8993797,1.1750528,0.0,0,8.1570406,0.0,0.080887631,104.26102,8.8569288,362.40759,-9.2833319
2006,2006,165.3514,8.6119099,1.2405235,0.0,0,8.1013775,0.0,0.085953295,101.11694,8.7977896,362.59229,-9.2823458
2008,2008,165.3518,8.9007788,1.2887301,0.0,0,8.0462675,0.0,0.089630365,102.83694,8.7426109,362.75418,-9.2825842
2010,2010,165.3522,9.1450205,1.3604411,0.0,0,7.993176,0.0,0.094095588,106.0432,8.6790981,362.91357,-9.2827549
2012,2012,165.3526,8.9315395,1.4416093,0.0,0,7.9402156,0.0,0.10057224,102.90569,8.6143599,363.07294,-9.2830334
2014,2014,165.353,8.9657755,1.5023921,0.0,0,7.8872552,0.0,0.10512144,102.74009,8.5474548,363.2323,-9.2836571
2016,2016,165.3534,8.9638863,1.5712762,0.0,0,7.8342953,0.0,0.10992184,102.09029,8.4801531,363.39169,-9.283144
2018,2018,165.3538,9.2185631,1.6050813,0.0,0,7.7813349,0.0,0.1131753,104.58369,8.4198837,363.55106,-9.2819958
2020,2020,165.3542,9.1152067,1.6494508,0.0,0,7.728375,0.0,0.1159337,103.52094,8.3638859,363.71045,-9.2827482
2022,2022,165.3546,9.0793772,1.7223979,0.0,0,7.675415,0.0,0.12134898,102.29337,8.3126745,363.86981,-9.2829638
2024,2024,165.355,9.2727737,1.7555795,0.0,0,7.6224551,0.0,0.12442093,104.00018,8.2590427,364.02921,-9.2829084
2026,2026,165.3554,9.4423828,1.8175422,0.0,0,7.5694952,0.0,0.12835099,105.65649,8.2007618,364.18857,-9.2830715
2028,2028,165.3558,9.3441448,1.8866926,0.0,0,7.5165353,0.0,0.13403283,104.19419,8.1436501,364.34793,-9.2830029
2030,2030,165.3562,9.3284407,1.9379501,0.0,0,7.4635754,0.0,0.13809706,103.46848,8.0864849,364.50732,-9.2822866
2032,2032,165.3566,9.351285,1.9965119,0.0,0,7.410615,0.0,0.1422285,103.27983,8.0277033,364.66669,-9.2830429
2034,2034,165.357,9.5070324,2.0365255,0.0,0,7.3593607,0.0,0.14581658,104.38319,7.9745746,364.82608,-9.2828789
2036,2036,165.3574,9.5381756,2.0856693,0.0,0,7.3089876,0.0,0.14930715,104.75094,7.9218292,364.98544,-9.2816868
2038,2038,165.3578,9.4358501,2.1410651,0.0,0,7.2586198,0.0,0.15350144,103.14805,7.8752837,365.14484,-9.2813215
2040,2040,165.3582,9.5685863,2.1796441,0.0,0,7.2082515,0.0,0.15700446,103.97697,7.8265533,365.3042,-9.2830725
2042,2042,165.3586,9.6788092,2.2358456,0.0,0,7.1578832,0.0,0.16081093,104.82916,7.77531,365.46356,-9.2837687
2044,2044,165.359,9.7134304,2.2914979,0.0,0,7.1075149,0.0,0.16532119,104.8255,7.7234912,365.62296,-9.2828226
2046,2046,165.3594,9.6547127,2.3404891,0.0,0,7.0571475,0.0,0.16958387,103.82556,7.6707911,365.78232,-9.282443
2048,2048,165.3598,9.6955376,2.3952088,0.0,0,7.0067787,0.0,0.17329733,103.70751,7.6155043,365.94171,-9.2816525
2050,2050,165.3602,9.7959442,2.4316313,0.0,0,6.9564114,0.0,0.1766787,104.42284,7.5686798,366.10107,-9.2830086
2052,2052,165.3606,9.8120518,2.4795136,0.0,0,6.9060431,0.0,0.18056858,104.31137,7.5222554,366.26047,-9.2835512
2054,2054,165.361,9.7970638,2.5354304,0.0,0,6.8556757,0.0,0.18443464,103.7541,7.4711804,366.41983,-9.2838421
2056,2056,165.3614,9.9063482,2.5718167,0.0,0,6.8053074,0.0,0.18788038,104.32228,7.4242039,366.57919,-9.2842512
2058,2058,165.3618,9.9969778,2.6229005,0.0,0,6.7554412,0.0,0.19187994,105.02708,7.3772025,366.64288,-9.2829952
2060,2060,165.3622,9.9363823,2.6783426,0.0,0,6.7074018,0.0,0.19590795,104.02025,7.3299274,366.68262,-9.2821674
2062,2062,165.3626,9.9780512,2.7191498,0.0,0,6.6594815,0.0,0.19996467,104.03336,7.2801785,366.72238,-9.2830696
2064,2064,165.363,10.027951,2.7645967,0.0,0,6.6115613,0.0,0.20329946,104.1311,7.2306404,366.76212,-9.2836237
2066,2066,165.3634,10.1268,2.8122847,0.0,0,6.5636415,0.0,0.20700435,104.76598,7.1839857,366.80188,-9.2833805
2068,2068,165.3638,10.133085,2.8576128,0.0,0,6.5157218,0.0,0.21129417,104.52286,7.1361961,366.84161,-9.283699
2070,2070,165.3642,10.117955,2.9059219,0.0,0,6.467802,0.0,0.21476549,103.87009,7.0896068,366.88138,-9.2831497
2072,2072,165.3646,10.22543,2.9544773,0.0,0,6.4198813,0.0,0.21897995,104.46724,7.043097,366.92111,-9.2832174
2074,2074,165.365,10.303287,2.9982293,0.0,0,6.3719611,0.0,0.2228331,104.87357,6.9951305,366.96085,-9.2823801
2076,2076,165.3654,10.328493,3.0469935,0.0,0,6.3240414,0.0,0.22635587,104.87312,6.9457507,367.00061,-9.2822361
2078,2078,165.3658,10.309958,3.0998459,0.0,0,6.2761216,0.0,0.23124991,104.22786,6.8957453,367.04034,-9.2822819
2080,2080,165.3662,10.343328,3.1428103,0.0,0,6.2282019,0.0,0.23480307,104.10748,6.8495955,367.08011,-9.2841959
2082,2082,165.3666,10.435468,3.1894009,0.0,0,6.1802816,0.0,0.23842496,104.59615,6.7998695,367.11984,-9.2843876
2084,2084,165.367,10.484544,3.2344773,0.0,0,6.1339045,0.0,0.24288952,104.71215,6.75387,367.15961,-9.2826233
2086,2086,165.3674,10.507305,3.2789245,0.0,0,6.0883236,0.0,0.2460928,104.49789,6.7037802,367.19934,-9.2824059
2088,2088,165.3678,10.550919,3.3261223,0.0,0,6.042748,0.0,0.25015411,104.48589,6.6575766,367.23907,-9.2816572
2090,2090,165.3682,10.595968,3.3728328,0.0,0,5.9971714,0.0,0.25469816,104.50932,6.6111145,367.27884,-9.2833099
2092,2092,165.3686,10.650795,3.4256058,0.0,0,5.9515953,0.0,0.25850624,104.61633,6.5605812,367.31857,-9.2838488
2094,2094,165.369,10.698177,3.4736443,0.0,0,5.9060197,0.0,0.26300988,104.65663,6.5169525,367.35834,-9.2836218
2096,2096,165.3694,10.726142,3.515208,0.0,0,5.8604436,0.0,0.26697391,104.53905,6.4695234,367.39807,-9.2839975
2098,2098,165.3698,10.768418,3.5684133,0.0,0,5.814867,0.0,0.27078435,104.48233,6.4222164,367.43784,-9.2831354
2100,2100,165.3702,10.813875,3.6112723,0.0,0,5.7692914,0.0,0.27528778,104.45078,6.3721585,367.47757,-9.2824841
2102,2102,165.3706,10.855525,3.6546071,0.0,0,5.7237153,0.0,0.27896544,104.55254,6.3255782,367.5173,-9.2824459
2104,2104,165.371,10.923186,3.7111659,0.0,0,5.6781397,0.0,0.28330427,104.71973,6.2793322,367.55707,-9.2830658
2106,2106,165.3714,10.962426,3.7511518,0.0,0,5.6325636,0.0,0.28767681,104.73737,6.2307124,367.5968,-9.283514
2108,2108,165.3718,10.986844,3.7972102,0.0,0,5.5874414,0.0,0.29131749,104.51897,6.1825609,367.39999,-9.2832985
2110,2110,165.3722,11.021204,3.8530791,0.0,0,5.5439734,0.0,0.296101,104.34121,6.1370325,367.10175,-9.2831669
2112,2112,165.3726,11.101121,3.8931537,0.0,0,5.5006132,0.0,0.30047756,104.56747,6.0894318,366.80353,-9.2829952
2114,2114,165.373,11.166239,3.9429145,0.0,0,5.457253,0.0,0.30423504,104.87497,6.0426011,366.50531,-9.2826939
2116,2116,165.3734,11.17841,3.9931035,0.0,0,5.4138932,0.0,0.30906811,104.54201,5.9956918,366.20709,-9.2816696
2118,2118,165.3738,11.208585,4.0332031,0.0,0,5.370533,0.0,0.31301042,104.3756,5.9459057,365.90884,-9.2829247
2120,2120,165.3742,11.248676,4.0855227,0.0,0,5.3271732,0.0,0.31719488,104.30508,5.8985777,365.61063,-9.2843199
2122,2122,165.3746,11.334742,4.1314955,0.0,0,5.283813,0.0,0.32207957,104.48908,5.8511376,365.31241,-9.2833672
2124,2124,165.375,11.394669,4.1764226,0.0,0,5.2404532,0.0,0.32598802,104.65922,5.8014731,365.01419,-9.2820272
2126,2126,165.3754,11.400357,4.2256999,0.0,0,5.1970935,0.0,0.33022097,104.30769,5.7545447,364.71594,-9.2819586
2128,2128,165.3758,11.444669,4.2702861,0.0,0,5.1537333,0.0,0.33505666,104.19917,5.7071404,364.41772,-9.2816582
2130,2130,165.3762,11.510249,4.3181305,0.0,0,5.110373,0.0,0.3389878,104.38916,5.6602812,364.11951,-9.2835255
2132,2132,165.3766,11.575825,4.3652153,0.0,0,5.0670133,0.0,0.3432987,104.48531,5.6133194,363.82129,-9.2837362
2134,2134,165.377,11.606699,4.4086752,0.0,0,5.0250483,0.0,0.34806207,104.34641,5.5704551,363.52307,-9.28304
2136,2136,165.3774,11.637017,4.4602733,0.0,0,4.9838037,0.0,0.35211504,104.18021,5.5207591,363.22482,-9.2826424
2138,2138,165.3778,11.685396,4.5037637,0.0,0,4.9425635,0.0,0.35658416,104.06512,5.4737554,362.92661,-9.2830534
2140,2140,165.3782,11.729447,4.5453453,0.0,0,4.9013238,0.0,0.36092955,104.01833,5.4279008,362.62839,-9.2830973
2142,2142,165.3786,11.787486,4.5991602,0.0,0,4.8600836,0.0,0.36513385,104.09225,5.3785844,362.33017,-9.283577
2144,2144,165.379,11.837365,4.6383286,0.0,0,4.8188438,0.0,0.36969623,104.10486,5.3367548,362.03192,-9.2833118
2146,2146,165.3794,11.872477,4.6832809,0.0,0,4.7776036,0.0,0.37387863,103.97758,5.2944012,361.7337,-9.2826109
2148,2148,165.3798,11.90571,4.7354069,0.0,0,4.7363639,0.0,0.37831873,103.778,5.2436357,361.43549,-9.2828798
2150,2150,165.3802,11.951527,4.775002,0.0,0,4.6951237,0.0,0.38309515,103.70501,5.203403,361.13727,-9.2825356
2152,2152,165.3806,12.008119,4.8191481,0.0,0,4.6538839,0.0,0.38702482,103.80916,5.1559215,360.83902,-9.2836218
2154,2154,165.381,12.084074,4.8701277,0.0,0,4.6126437,0.0,0.3917827,103.9579,5.1109476,360.5408,-9.2829494
2156,2156,165.3814,12.115498,4.9089842,0.0,0,4.5714035,0.0,0.39643887,103.75474,5.0656905,360.24258,-9.2829199
2158,2158,165.3818,12.124918,4.9551358,0.0,0,4.5305758,0.0,0.40020376,103.47216,5.0228338,359.9162,-9.2829161
2160,2160,165.3822,12.17924,5.003006,0.0,0,4.4912457,0.0,0.40532532,103.33994,4.9786739,359.57101,-9.2832842
2162,2162,165.3826,12.264888,5.0402117,0.0,0,4.4520135,0.0,0.40933427,103.60571,4.9322371,359.22586,-9.2830877
2164,2164,165.383,12.309346,5.0870132,0.0,0,4.4127812,0.0,0.41339323,103.70082,4.8893104,358.88068,-9.2815857
2166,2166,165.3834,12.331613,5.1335025,0.0,0,4.3735495,0.0,0.41876069,103.28444,4.8473792,358.53552,-9.2817001
2168,2168,165.3838,12.356467,5.1743879,0.0,0,4.3343177,0.0,0.4227646,103.09029,4.8007035,358.19034,-9.2830095
2170,2170,165.3842,12.438459,5.2201743,0.0,0,4.2950859,0.0,0.42696333,103.25987,4.7590446,357.84518,-9.283926
2172,2172,165.3846,12.517095,5.2601585,0.0,0,4.2558532,0.0,0.43191278,103.42848,4.7138996,357.5,-9.2832365
2174,2174,165.385,12.543233,5.3030772,0.0,0,4.2166214,0.0,0.43568629,103.27447,4.6702361,357.15485,-9.2843494
2176,2176,165.3854,12.578712,5.3483138,0.0,0,4.1773891,0.0,0.44024456,103.06575,4.6273732,356.80966,-9.282423
2178,2178,165.3858,12.604307,5.385704,0.0,0,4.1381574,0.0,0.44491598,102.79727,4.5849686,356.46451,-9.2824068
2180,2180,165.3862,12.676683,5.4318438,0.0,0,4.0989256,0.0,0.4487696,102.97263,4.5424981,356.11932,-9.2820396
2182,2182,165.3866,12.746221,5.4733338,0.0,0,4.0596933,0.0,0.45350528,103.12612,4.4994044,355.77417,-9.2828293
2184,2184,165.387,12.790253,5.5107589,0.0,0,4.0217257,0.0,0.45785004,103.01716,4.4604273,355.42899,-9.283309
2186,2186,165.3874,12.822345,5.560833,0.0,0,3.9844091,0.0,0.46208951,102.80234,4.4199176,355.08383,-9.284132
2188,2188,165.3878,12.875946,5.5950556,0.0,0,3.9470971,0.0,0.46666837,102.72589,4.3754072,354.73865,-9.2824097
2190,2190,165.3882,12.930708,5.6341591,0.0,0,3.9097853,0.0,0.47069788,102.84062,4.336391,354.39349,-9.2812605
2192,2192,165.3886,13.002939,5.6839266,0.0,0,3.8724732,0.0,0.47520834,102.88108,4.2956357,354.04831,-9.2818184
2194,2194,165.389,13.045982,5.7157717,0.0,0,3.8351612,0.0,0.47976461,102.77009,4.2547731,353.70316,-9.2820005
2196,2196,165.3894,13.07993,5.7557626,0.0,0,3.7978492,0.0,0.48341486,102.686,4.2148943,353.35797,-9.2837391
2198,2198,165.3898,13.122822,5.8023486,0.0,0,3.7605371,0.0,0.48825696,102.50961,4.1757665,353.01279,-9.2832212
2200,2200,165.3902,13.197958,5.8341084,0.0,0,3.7232251,0.0,0.49270847,102.57356,4.1332755,352.66763,-9.2832508
2202,2202,165.3906,13.27982,5.8766341,0.0,0,3.6859133,0.0,0.4963505,102.86432,4.0960355,352.32245,-9.2805977
2204,2204,165.391,13.318419,5.9194593,0.0,0,3.6486013,0.0,0.50143754,102.65736,4.0555048,351.97729,-9.2813616
2206,2206,165.3914,13.341702,5.9530292,0.0,0,3.611289,0.0,0.50561666,102.44099,4.0162244,351.63211,-9.28234
2208,2208,165.3918,13.405991,5.9949765,0.0,0,3.5743496,0.0,0.50942963,102.49725,3.9782736,351.51627,-9.283453
2210,2210,165.3922,13.475355,6.0312381,0.0,0,3.5387647,0.0,0.51417941,102.5664,3.939728,351.62976,-9.2838688
2212,2212,165.3926,13.555835,6.0667009,0.0,0,3.5032687,0.0,0.51803529,102.74326,3.9012623,351.74326,-9.2829218
2214,2214,165.393,13.58469,6.1102409,0.0,0,3.4677725,0.0,0.5223437,102.56904,3.8646202,351.85675,-9.2822084
2216,2216,165.3934,13.625897,6.1473632,0.0,0,3.4322767,0.0,0.52747333,102.34146,3.8239932,351.97025,-9.2817125
2218,2218,165.3938,13.691483,6.1860709,0.0,0,3.3967807,0.0,0.53107715,102.41587,3.7860782,352.08374,-9.282114
2220,2220,165.3942,13.768173,6.2245417,0.0,0,3.3612847,0.0,0.53548133,102.55202,3.7459922,352.19724,-9.2825613
2222,2222,165.3946,13.829482,6.257246,0.0,0,3.3257885,0.0,0.54009604,102.53365,3.7100542,352.31073,-9.2836027
2224,2224,165.395,13.87824,6.2985315,0.0,0,3.2902927,0.0,0.54367173,102.55743,3.6728988,352.42422,-9.2831211
2226,2226,165.3954,13.928039,6.333602,0.0,0,3.2547965,0.0,0.54821187,102.47966,3.6361139,352.53772,-9.2829161
2228,2228,165.3958,13.987903,6.3648243,0.0,0,3.2193005,0.0,0.55232519,102.49431,3.5992787,352.65121,-9.2819834
2230,2230,165.3962,14.078149,6.4106393,0.0,0,3.1838045,0.0,0.55640799,102.64799,3.5626509,352.76471,-9.2814426
2232,2232,165.3966,14.142567,6.4447947,0.0,0,3.1483085,0.0,0.56128949,102.68231,3.5259507,352.8782,-9.2822418
2234,2234,165.397,14.192851,6.4805388,0.0,0,3.1139498,0.0,0.56538767,102.66697,3.4906754,352.9917,-9.2823973
2236,2236,165.3974,14.250753,6.5246897,0.0,0,3.0801783,0.0,0.5697065,102.6127,3.4508421,353.10519,-9.2824697
2238,2238,165.3978,14.299299,6.5506344,0.0,0,3.0464103,0.0,0.57409239,102.47892,3.4152298,353.21869,-9.2815247
2240,2240,165.3982,14.387031,6.5853992,0.0,0,3.0126421,0.0,0.57757133,102.68826,3.3815615,353.33218,-9.2819204
2242,2242,165.3986,14.458733,6.6290874,0.0,0,2.9788742,0.0,0.58240443,102.78543,3.3458242,353.44568,-9.2821522
2244,2244,165.399,14.518862,6.6563783,0.0,0,2.9451063,0.0,0.586748,102.77208,3.3105166,353.55917,-9.2816801
2246,2246,165.3994,14.57298,6.6964831,0.0,0,2.9113381,0.0,0.59047842,102.76954,3.2739329,353.67267,-9.2818222
2248,2248,165.3998,14.629052,6.7372246,0.0,0,2.8775702,0.0,0.59577435,102.59723,3.2392397,353.78616,-9.2815647
2250,2250,165.4002,14.737682,6.7642875,0.0,0,2.8438022,0.0,0.59966755,102.89302,3.2020869,353.89966,-9.2823477
2252,2252,165.4006,14.832313,6.8028455,0.0,0,2.810034,0.0,0.60335422,103.24743,3.1656373,354.01315,-9.2823296
2254,2254,165.401,14.868945,6.8383775,0.0,0,2.7762663,0.0,0.60854691,102.99168,3.1341715,354.12665,-9.2815351
2256,2256,165.4014,14.929197,6.8706903,0.0,0,2.7424982,0.0,0.61222345,103.05173,3.0969436,354.24014,-9.2822638
2258,2258,165.4018,15.005623,6.9106774,0.0,0,2.7090681,0.0,0.61659861,103.07053,3.0634167,354.10953,-9.2832699
2260,2260,165.4022,15.101566,6.944283,0.0,0,2.6768675,0.0,0.62187833,103.16072,3.0263944,353.61276,-9.2826509
2262,2262,165.4026,15.191176,6.9783459,0.0,0,2.6447473,0.0,0.62526363,103.46431,2.9938955,353.116,-9.2809563
2264,2264,165.403,15.233953,7.013351,0.0,0,2.6126273,0.0,0.62957132,103.33279,2.9606237,352.61923,-9.2805061
2266,2266,165.4034,15.28942,7.0434089,0.0,0,2.580507,0.0,0.6343224,103.15031,2.9235456,352.12247,-9.2823772
2268,2268,165.4038,15.371442,7.0852189,0.0,0,2.5483871,0.0,0.63815618,103.35168,2.8891721,351.6257,-9.2821856
2270,2270,165.4042,15.479835,7.1174879,0.0,0,2.5162671,0.0,0.64300144,103.48128,2.8548861,351.12891,-9.2820902
2272,2272,165.4046,15.567628,7.1479592,0.0,0,2.4841471,0.0,0.64746076,103.73826,2.8189652,350.63214,-9.2814322
2274,2274,165.405,15.633365,7.1907582,0.0,0,2.4520271,0.0,0.6515885,103.72549,2.7877769,350.13538,-9.2820377
2276,2276,165.4054,15.688075,7.2179513,0.0,0,2.4199073,0.0,0.65609878,103.61613,2.752151,349.63861,-9.2820625
2278,2278,165.4058,15.776332,7.2503376,0.0,0,2.3877871,0.0,0.66005677,103.73764,2.7183607,349.14185,-9.280817
2280,2280,165.4062,15.876677,7.2934566,0.0,0,2.3556671,0.0,0.6646291,103.91651,2.6848943,348.64508,-9.280756
2282,2282,165.4066,15.962631,7.3189678,0.0,0,2.3235471,0.0,0.66938967,104.04405,2.6506374,348.14832,-9.2814293
2284,2284,165.407,16.014784,7.3527603,0.0,0,2.2924592,0.0,0.67308319,103.99716,2.6171367,347.65155,-9.2815514
2286,2286,165.4074,16.077284,7.3944225,0.0,0,2.261904,0.0,0.67819589,103.83195,2.5812182,347.15479,-9.2815084
2288,2288,165.4078,16.172468,7.4182134,0.0,0,2.2313521,0.0,0.68258119,103.97543,2.5479054,346.65802,-9.2806988
2290,2290,165.4082,16.296284,7.4527726,0.0,0,2.2008002,0.0,0.6859569,104.39874,2.5173252,346.16125,-9.2800627
2292,2292,165.4086,16.370958,7.4916859,0.0,0,2.170248,0.0,0.69137478,104.40082,2.4822161,345.66446,-9.2801189
2294,2294,165.409,16.431763,7.5160613,0.0,0,2.1396961,0.0,0.69546819,104.34586,2.4493353,345.16769,-9.2814617
2296,2296,165.4094,16.515474,7.5524225,0.0,0,2.109144,0.0,0.69914901,104.42144,2.4172473,344.67093,-9.2814283
2298,2298,165.4098,16.624317,7.5866933,0.0,0,2.0785921,0.0,0.7048009,104.48845,2.3836415,344.17416,-9.2809515
2300,2300,165.4102,16.728251,7.6159825,0.0,0,2.0480402,0.0,0.70850527,104.81611,2.3508136,343.6774,-9.2809515
2302,2302,165.4106,16.804489,7.652699,0.0,0,2.0174882,0.0,0.71266961,104.87174,2.3167758,343.18063,-9.2806578
2304,2304,165.411,16.868637,7.6841769,0.0,0,1.986936,0.0,0.71823752,104.70287,2.2822466,342.68387,-9.2797852
2306,2306,165.4114,16.966734,7.714694,0.0,0,1.9563839,0.0,0.72163486,104.90565,2.254885,342.1871,-9.2811346
2308,2308,165.4118,17.080908,7.7484121,0.0,0,1.9261372,0.0,0.72597438,105.10387,2.2215111,341.5928,-9.2815247
2310,2310,165.4122,17.178553,7.7741561,0.0,0,1.8970003,0.0,0.73082948,105.24585,2.1917195,340.7709,-9.2815733
2312,2312,165.4126,17.274315,7.8103447,0.0,0,1.8679363,0.0,0.73435116,105.48369,2.1587133,339.94897,-9.2811413
2314,2314,165.413,17.345625,7.8424172,0.0,0,1.8388723,0.0,0.73948497,105.41364,2.1267765,339.12708,-9.2800093
2316,2316,165.4134,17.43655,7.8694386,0.0,0,1.8098083,0.0,0.7439158,105.45782,2.096873,338.30518,-9.2798138
2318,2318,165.4138,17.540346,7.9105668,0.0,0,1.7807442,0.0,0.74803078,105.6254,2.063844,337.48328,-9.2800665
2320,2320,165.4142,17.661314,7.9365239,0.0,0,1.7516803,0.0,0.75310624,105.86569,2.0325353,336.66138,-9.2799511
2322,2322,165.4146,17.753149,7.9647202,0.0,0,1.7226163,0.0,0.75699407,105.98937,2.0039799,335.83945,-9.2799854
2324,2324,165.415,17.834679,8.0048084,0.0,0,1.6935523,0.0,0.76145047,105.96638,1.9727234,335.01755,-9.2802382
2326,2326,165.4154,17.931683,8.0263338,0.0,0,1.6644882,0.0,0.76609278,106.0479,1.9409657,334.19565,-9.2798414
2328,2328,165.4158,18.043451,8.056263,0.0,0,1.6354243,0.0,0.76964062,106.32847,1.9097973,333.37375,-9.2808533
2330,2330,165.4162,18.171223,8.0965691,0.0,0,1.6063603,0.0,0.77492183,106.51324,1.8792943,332.55185,-9.2805672
2332,2332,165.4166,18.265162,8.118269,0.0,0,1.5772963,0.0,0.77960002,106.61351,1.8495942,331.72992,-9.2787714
2334,2334,165.417,18.359474,8.1531477,0.0,0,1.5491643,0.0,0.78326243,106.74921,1.8168877,330.90802,-9.2798433
2336,2336,165.4174,18.446646,8.1870813,0.0,0,1.5215131,0.0,0.78860414,106.66894,1.7891268,330.08612,-9.2800074
2338,2338,165.4178,18.569078,8.2078266,0.0,0,1.4938651,0.0,0.79243058,106.99828,1.7558351,329.26422,-9.2810545
2340,2340,165.4182,18.694897,8.2405462,0.0,0,1.4662172,0.0,0.79591179,107.30142,1.7278996,328.44232,-9.2800255
2342,2342,165.4186,18.792543,8.2723742,0.0,0,1.4385692,0.0,0.80177361,107.23108,1.6973035,327.62039,-9.2798166
2344,2344,165.419,18.885647,8.2985973,0.0,0,1.4109212,0.0,0.80562377,107.40919,1.6678787,326.79849,-9.2787104
2346,2346,165.4194,18.977129,8.3340902,0.0,0,1.3832732,0.0,0.80982488,107.4316,1.6383059,325.97659,-9.2799158
2348,2348,165.4198,19.108494,8.3610477,0.0,0,1.3556252,0.0,0.81543785,107.56178,1.6111159,325.15469,-9.2802382
2350,2350,165.4202,19.238588,8.3884258,0.0,0,1.3279773,0.0,0.81868404,107.95728,1.5760827,324.33279,-9.2787256
2352,2352,165.4206,19.347942,8.4175243,0.0,0,1.3003292,0.0,0.82282221,108.11942,1.5511864,323.51086,-9.2796888
2354,2354,165.421,19.432695,8.4406481,0.0,0,1.2726812,0.0,0.82774854,108.11446,1.5206982,322.68896,-9.2792625
2356,2356,165.4214,19.549858,8.4772482,0.0,0,1.2450333,0.0,0.83143336,108.35349,1.4924772,321.86707,-9.2786293
2358,2358,165.4218,19.675011,8.5059519,0.0,0,1.2176626,0.0,0.83664143,108.44035,1.466114,321.0647,-9.2796555
2360,2360,165.4222,19.820107,8.5294218,0.0,0,1.1913005,0.0,0.84126121,108.73409,1.4395554,320.34042,-9.279952
2362,2362,165.4226,19.923201,8.567112,0.0,0,1.1650044,0.0,0.8450231,108.9054,1.4082495,319.61615,-9.2795181
2364,2364,165.423,20.014389,8.5872068,0.0,0,1.1387082,0.0,0.84983838,108.88924,1.3780422,318.89188,-9.2796412
2366,2366,165.4234,20.133142,8.6114569,0.0,0,1.1124123,0.0,0.85345227,109.16312,1.3515158,318.1676,-9.2790632
2368,2368,165.4238,20.284256,8.6489019,0.0,0,1.0861163,0.0,0.85773385,109.43896,1.3209572,317.44333,-9.2797527
2370,2370,165.4242,20.424253,8.6688662,0.0,0,1.0598202,0.0,0.86294299,109.6688,1.2933129,316.71906,-9.2781973
2372,2372,165.4246,20.520847,8.6984396,0.0,0,1.0335243,0.0,0.86652744,109.79164,1.2651386,315.99478,-9.2785406
2374,2374,165.425,20.62674,8.7334003,0.0,0,1.0072283,0.0,0.87173593,109.77872,1.2363185,315.27051,-9.2782364
2376,2376,165.4254,20.75341,8.7523661,0.0,0,0.98093224,0.0,0.87625796,109.95948,1.2079455,314.54623,-9.2787361
2378,2378,165.4258,20.907061,8.7820768,0.0,0,0.95463622,0.0,0.87952703,110.38759,1.1814259,313.82196,-9.2800121
2380,2380,165.4262,21.049047,8.8123045,0.0,0,0.92834032,0.0,0.88506281,110.55315,1.1520203,313.09769,-9.2797766
2382,2382,165.4266,21.159452,8.8310575,0.0,0,0.9020443,0.0,0.88886869,110.68166,1.1228515,312.37341,-9.27843
2384,2384,165.427,21.263302,8.8635111,0.0,0,0.87659597,0.0,0.89248097,110.84663,1.0966598,311.64914,-9.2784662
2386,2386,165.4274,21.407084,8.8925228,0.0,0,0.85158527,0.0,0.89850819,110.8963,1.0711476,310.92487,-9.278738
2388,2388,165.4278,21.5597,8.9134302,0.0,0,0.82657719,0.0,0.90183443,111.31428,1.0430071,310.20059,-9.2783318
2390,2390,165.4282,21.702812,8.9435472,0.0,0,0.80156928,0.0,0.90559304,111.64809,1.0138742,309.47632,-9.2783537
2392,2392,165.4286,21.806618,8.9672489,0.0,0,0.77656126,0.0,0.91129863,111.57483,0.98721862,308.75204,-9.2778339
2394,2394,165.429,21.940243,8.9928684,0.0,0,0.75155324,0.0,0.91453654,111.88428,0.96056002,308.02777,-9.2787504
2396,2396,165.4294,22.082701,9.0222187,0.0,0,0.72654527,0.0,0.91904473,112.06501,0.93565041,307.3035,-9.2785101
2398,2398,165.4298,22.248308,9.0433798,0.0,0,0.70153725,0.0,0.92413163,112.35135,0.90784705,306.57922,-9.2773647
2400,2400,165.4302,22.387941,9.074111,0.0,0,0.67652929,0.0,0.92754519,112.68694,0.88278872,305.85495,-9.2773485
2402,2402,165.4306,22.503107,9.100275,0.0,0,0.65152127,0.0,0.9326061,112.68984,0.85617751,305.13068,-9.2774696
2404,2404,165.431,22.633995,9.1204128,0.0,0,0.62651324,0.0,0.93706089,112.8317,0.83350843,304.4064,-9.2778206
2406,2406,165.4314,22.777891,9.1531029,0.0,0,0.60150528,0.0,0.94058537,113.18772,0.80742759,303.68213,-9.2781963
2408,2408,165.4318,22.961382,9.1731911,0.0,0,0.57674497,0.0,0.94556123,113.47279,0.77979475,303.0405,-9.276722
2410,2410,165.4322,23.101204,9.1966639,0.0,0,0.55288589,0.0,0.9494611,113.72623,0.75559515,303.14276,-9.2766972
2412,2412,165.4326,23.226871,9.2310734,0.0,0,0.52908581,0.0,0.95393395,113.84669,0.73040527,303.24503,-9.2772989
2414,2414,165.433,23.369579,9.2459831,0.0,0,0.5052858,0.0,0.95864135,114.01027,0.70408458,303.34732,-9.2783365
2416,2416,165.4334,23.533064,9.2695246,0.0,0,0.48148578,0.0,0.96164495,114.47364,0.6762889,303.44958,-9.2780361
2418,2418,165.4338,23.70001,9.3048372,0.0,0,0.4576858,0.0,0.96715224,114.61214,0.64979607,303.55185,-9.2774382
2420,2420,165.4342,23.844109,9.3206463,0.0,0,0.43388578,0.0,0.97180617,114.82662,0.62720907,303.65411,-9.2771368
2422,2422,165.4346,23.9795,9.3474684,0.0,0,0.4100858,0.0,0.97490317,115.08654,0.60065818,303.75638,-9.2770405
2424,2424,165.435,24.127638,9.3771973,0.0,0,0.38628578,0.0,0.980483,115.17865,0.57584476,303.85864,-9.2769861
2426,2426,165.4354,24.293562,9.3895969,0.0,0,0.36248577,0.0,0.98382384,115.54377,0.55096054,303.96091,-9.2767763