File: examples/hot axisymmetric compression example/data/03 trimmed data/testID_0129.csv
level_0,index,Time(sec),Force(kN),Jaw(mm),PowAngle(deg),Power(W),Pram,PTemp,Strain,Stress(MPa),Stroke(mm),TC1(C),wedge(mm)
1774,1774,145.3503,0.52556747,0.050097056,0.0,0,9.0044422,0.0,0.0032141537,5.2431979,10.00265,303.39368,-9.3250828
1776,1776,145.3507,3.2693472,0.098543696,0.0,0,8.9459143,0.0,0.0063455738,37.114708,9.9455481,303.52588,-9.323905
1778,1778,145.3511,5.6602211,0.15143561,0.0,0,8.8873863,0.0,0.0096986722,69.355415,9.8943682,303.65805,-9.3226986
1780,1780,145.3515,6.6184416,0.21798514,0.0,0,8.8288584,0.0,0.013947632,82.113518,9.8221865,303.79025,-9.3203363
1782,1782,145.3519,7.2970009,0.34239709,0.0,0,8.7703304,0.0,0.022501944,90.170334,9.7477865,303.92242,-9.3193521
1784,1784,145.3523,8.1640196,0.39457124,0.0,0,8.7136879,0.0,0.026089035,100.14811,9.6597433,304.05463,-9.3184633
1786,1786,145.3527,8.7618446,0.4727008,0.0,0,8.6580172,0.0,0.031506926,107.37279,9.5792437,304.18683,-9.3177567
1788,1788,145.3531,9.5440435,0.51927799,0.0,0,8.6023531,0.0,0.035187084,116.64198,9.5044212,304.319,-9.3158894
1790,1790,145.3535,9.31991,0.54990578,0.0,0,8.546689,0.0,0.036716912,114.9236,9.4376392,304.4512,-9.3148851
1792,1792,145.3539,9.5885201,0.63841605,0.0,0,8.4910259,0.0,0.043158013,116.08076,9.3792095,304.58337,-9.3174839
1794,1794,145.3543,10.105489,0.67700082,0.0,0,8.4353609,0.0,0.045813207,122.5358,9.3145647,304.71558,-9.3178244
1796,1796,145.3547,10.470045,0.75648421,0.0,0,8.3796968,0.0,0.051014557,126.27061,9.2465124,304.84775,-9.315444
1798,1798,145.3551,10.37673,0.84499371,0.0,0,8.3240337,0.0,0.057651304,125.1423,9.1693258,304.97995,-9.3146648
1800,1800,145.3555,10.426847,0.91442597,0.0,0,8.2683697,0.0,0.062175624,124.23476,9.0965719,305.11212,-9.3149319
1802,1802,145.3559,10.789588,0.98296064,0.0,0,8.2127056,0.0,0.067542821,128.22513,9.0212917,305.24432,-9.316
1804,1804,145.3563,10.917842,1.0244187,0.0,0,8.1570415,0.0,0.070509739,129.08412,8.9568806,305.3765,-9.3152189
1806,1806,145.3567,11.199667,1.0791249,0.0,0,8.1013775,0.0,0.073998205,132.53993,8.8947611,305.5087,-9.3151712
1808,1808,145.3571,10.905468,1.1466415,0.0,0,8.0462685,0.0,0.079350345,128.36563,8.8365173,305.64087,-9.3144131
1810,1810,145.3575,11.344,1.2027155,0.0,0,7.993176,0.0,0.083086818,132.37964,8.7747612,305.77307,-9.3146391
1812,1812,145.3579,11.372816,1.27902,0.0,0,7.9402156,0.0,0.088422425,132.72331,8.708889,305.90524,-9.3146935
1814,1814,145.3583,11.432663,1.3533994,0.0,0,7.8872557,0.0,0.094343849,132.26392,8.6401005,306.03745,-9.3145666
1816,1816,145.3587,11.409471,1.4201654,0.0,0,7.8342957,0.0,0.098725595,131.75842,8.5684242,306.16962,-9.314126
1818,1818,145.3591,11.571761,1.4812549,0.0,0,7.7813354,0.0,0.10370342,132.43921,8.5049171,306.26511,-9.3143244
1820,1820,145.3595,11.73944,1.5132889,0.0,0,7.7283754,0.0,0.1063336,134.34039,8.446909,306.32391,-9.3146935
1822,1822,145.3599,11.737772,1.5766145,0.0,0,7.675415,0.0,0.11017173,133.85175,8.3888464,306.38269,-9.3151932
1824,1824,145.3603,11.800645,1.6317301,0.0,0,7.6224551,0.0,0.11490381,133.83461,8.3346224,306.4415,-9.3143253
1826,1826,145.3607,11.95469,1.6770442,0.0,0,7.5694952,0.0,0.11820566,135.0724,8.2828207,306.50031,-9.3146029
1828,1828,145.3611,12.073888,1.7555597,0.0,0,7.5165353,0.0,0.12354897,135.94514,8.2209597,306.55908,-9.3143454
1830,1830,145.3615,12.001537,1.8137643,0.0,0,7.4635754,0.0,0.12867789,134.32121,8.15588,306.61789,-9.3142958
1832,1832,145.3619,12.094654,1.8727539,0.0,0,7.410615,0.0,0.13283214,134.77953,8.0959501,306.67667,-9.3147793
1834,1834,145.3623,12.156249,1.9321619,0.0,0,7.3593612,0.0,0.13734955,134.75432,8.0369329,306.73547,-9.3140612
1836,1836,145.3627,12.360521,1.9674063,0.0,0,7.3089881,0.0,0.1405059,136.62216,7.9796758,306.79425,-9.3154364
1838,1838,145.3631,12.324464,2.0295327,0.0,0,7.2586198,0.0,0.14462526,135.87059,7.9245272,306.85306,-9.3153677
1840,1840,145.3635,12.356412,2.0847921,0.0,0,7.2082515,0.0,0.14934053,135.3324,7.8745937,306.91183,-9.3157501
1842,1842,145.3639,12.479041,2.1282039,0.0,0,7.1578832,0.0,0.15277442,136.31024,7.8214869,306.97064,-9.3144722
1844,1844,145.3643,12.608895,2.1920643,0.0,0,7.1075153,0.0,0.15727003,137.02567,7.765615,307.02945,-9.3136845
1846,1846,145.3647,12.632498,2.2457948,0.0,0,7.0571475,0.0,0.1619945,136.83987,7.7098904,307.08823,-9.3136215
1848,1848,145.3651,12.600059,2.3005154,0.0,0,7.0067792,0.0,0.16601445,135.80186,7.6517749,307.14703,-9.3134518
1850,1850,145.3655,12.702672,2.3509769,0.0,0,6.9564114,0.0,0.16994759,136.3474,7.5961838,307.20581,-9.3145838
1852,1852,145.3659,12.824482,2.3949547,0.0,0,6.9060431,0.0,0.17384575,137.13475,7.5452909,307.26462,-9.3151283
1854,1854,145.3663,12.883869,2.4552515,0.0,0,6.8556757,0.0,0.17814556,137.30951,7.491281,307.32339,-9.3139114
1856,1856,145.3667,12.854342,2.5024011,0.0,0,6.8053074,0.0,0.18212423,136.43484,7.4433217,307.3822,-9.3135748
1858,1858,145.3671,12.998834,2.5493269,0.0,0,6.7554417,0.0,0.1861964,137.20004,7.3900986,307.44101,-9.3140135
1860,1860,145.3675,13.045452,2.608711,0.0,0,6.7074022,0.0,0.1903381,137.27327,7.3395281,307.49979,-9.3147831
1862,1862,145.3679,13.072547,2.6526811,0.0,0,6.6594815,0.0,0.19429992,136.90402,7.2884545,307.55859,-9.3155117
1864,1864,145.3683,13.130764,2.7029896,0.0,0,6.6115613,0.0,0.19847886,137.00427,7.2351093,307.61737,-9.3161335
1866,1866,145.3687,13.205389,2.7561734,0.0,0,6.5636415,0.0,0.20227717,137.33932,7.1842504,307.67618,-9.3142328
1868,1868,145.3691,13.281794,2.7969546,0.0,0,6.5157218,0.0,0.20617652,137.6366,7.1310916,307.70251,-9.3130894
1870,1870,145.3695,13.290393,2.8494861,0.0,0,6.467802,0.0,0.21028921,137.24442,7.0853338,307.69638,-9.3145323
1872,1872,145.3699,13.360425,2.9017913,0.0,0,6.4198818,0.0,0.21431324,137.13048,7.0348969,307.69028,-9.3155022
1874,1874,145.3703,13.472844,2.9458675,0.0,0,6.3719616,0.0,0.21851757,137.73177,6.9828782,307.68417,-9.3152227
1876,1876,145.3707,13.53595,2.9987597,0.0,0,6.3240418,0.0,0.22245872,137.93852,6.9355936,307.67804,-9.3151207
1878,1878,145.3711,13.556349,3.053885,0.0,0,6.2761221,0.0,0.22706984,137.62155,6.8848181,307.67194,-9.314846
1880,1880,145.3715,13.582551,3.0983365,0.0,0,6.2282019,0.0,0.23123108,137.2296,6.8354101,307.6658,-9.3140078
1882,1882,145.3719,13.682456,3.1446402,0.0,0,6.1802821,0.0,0.23461297,137.59077,6.785964,307.6597,-9.3146105
1884,1884,145.3723,13.784101,3.1935048,0.0,0,6.1339049,0.0,0.23910603,138.06943,6.7382059,307.65359,-9.3152189
1886,1886,145.3727,13.804499,3.2372139,0.0,0,6.0883236,0.0,0.24290881,137.84726,6.6888289,307.64746,-9.3165073
1888,1888,145.3731,13.847589,3.2858362,0.0,0,6.042748,0.0,0.24653347,137.74957,6.6395173,307.64136,-9.3160086
1890,1890,145.3735,13.897832,3.337599,0.0,0,5.9971719,0.0,0.2515313,137.50095,6.5887299,307.63522,-9.3141623
1892,1892,145.3739,14.010098,3.3852589,0.0,0,5.9515953,0.0,0.25531119,137.9303,6.542418,307.62912,-9.3134699
1894,1894,145.3743,14.056162,3.4359632,0.0,0,5.9060202,0.0,0.25949132,138.08772,6.4914894,307.62302,-9.3136101
1896,1896,145.3747,14.087594,3.4801505,0.0,0,5.8604436,0.0,0.26404631,137.70613,6.4433613,307.61688,-9.3144455
1898,1898,145.3751,14.138648,3.5293579,0.0,0,5.8148675,0.0,0.2675353,137.69852,6.3925681,307.61078,-9.3155088
1900,1900,145.3755,14.206112,3.5769587,0.0,0,5.7692914,0.0,0.27189019,137.64255,6.3476205,307.60464,-9.3146095
1902,1902,145.3759,14.276779,3.6195812,0.0,0,5.7237153,0.0,0.27612722,137.90445,6.2953711,307.59854,-9.3142223
1904,1904,145.3763,14.343575,3.6723838,0.0,0,5.6781397,0.0,0.27991092,137.99626,6.2495594,307.59244,-9.3145056
1906,1906,145.3767,14.37946,3.7177169,0.0,0,5.6325636,0.0,0.28454873,137.70079,6.203547,307.5863,-9.3144226
1908,1908,145.3771,14.442343,3.7601273,0.0,0,5.5874419,0.0,0.28841379,137.72804,6.157445,307.5802,-9.3150883
1910,1910,145.3775,14.499973,3.8157704,0.0,0,5.5439739,0.0,0.29259849,137.72998,6.1120563,307.57407,-9.315424
1912,1912,145.3779,14.561862,3.8538578,0.0,0,5.5006137,0.0,0.29683629,137.71327,6.0637798,307.56796,-9.3152695
1914,1914,145.3783,14.640604,3.8988328,0.0,0,5.4572535,0.0,0.30053306,138.00813,6.0141706,307.56186,-9.3149023
1916,1916,145.3787,14.682769,3.9558721,0.0,0,5.4138937,0.0,0.30531833,137.75233,5.9694543,307.55573,-9.313735
1918,1918,145.3791,14.734923,3.995415,0.0,0,5.3705335,0.0,0.30968499,137.55846,5.9229851,307.48581,-9.3141794
1920,1920,145.3795,14.790279,4.0450068,0.0,0,5.3271737,0.0,0.31352097,137.57629,5.8736978,307.35211,-9.3151035
1922,1922,145.3799,14.862392,4.0946021,0.0,0,5.2838135,0.0,0.31833607,137.53062,5.8265858,307.21838,-9.3152046
1924,1924,145.3803,14.939839,4.1307001,0.0,0,5.2404532,0.0,0.3219966,137.82817,5.779418,307.08466,-9.3156309
1926,1926,145.3807,14.9656,4.1794581,0.0,0,5.1970935,0.0,0.32585618,137.56944,5.7313237,306.95096,-9.3152475
1928,1928,145.3811,15.011374,4.2266154,0.0,0,5.1537337,0.0,0.33077696,137.29378,5.6882429,306.81723,-9.3151512
1930,1930,145.3815,15.073768,4.2701097,0.0,0,5.1103735,0.0,0.33466759,137.28459,5.6445694,306.68353,-9.3150053
1932,1932,145.3819,15.154811,4.3171339,0.0,0,5.0670133,0.0,0.33872476,137.48759,5.5988317,306.5498,-9.3145065
1934,1934,145.3823,15.220222,4.360261,0.0,0,5.0250487,0.0,0.34346914,137.44548,5.5527596,306.41611,-9.3145151
1936,1936,145.3827,15.256269,4.4061756,0.0,0,4.9838042,0.0,0.34720665,137.27454,5.5062675,306.28238,-9.3149776
1938,1938,145.3831,15.309183,4.4503927,0.0,0,4.942564,0.0,0.35135719,137.1011,5.4610295,306.14868,-9.3156805
1940,1940,145.3835,15.382099,4.4922128,0.0,0,4.9013243,0.0,0.35589856,137.13379,5.4157538,306.01495,-9.314887
1942,1942,145.3839,15.454971,4.5403876,0.0,0,4.8600841,0.0,0.35977986,137.26241,5.3712635,305.88123,-9.3151703
1944,1944,145.3843,15.511594,4.5836363,0.0,0,4.8188443,0.0,0.3642109,137.09949,5.3282199,305.74753,-9.315752
1946,1946,145.3847,15.569089,4.6254478,0.0,0,4.7776041,0.0,0.36870262,137.05003,5.281198,305.6138,-9.3148451
1948,1948,145.3851,15.60767,4.6751943,0.0,0,4.7363639,0.0,0.37259623,136.82086,5.242415,305.4801,-9.3154593
1950,1950,145.3855,15.682252,4.7131286,0.0,0,4.6951241,0.0,0.37693501,136.8654,5.1963491,305.34637,-9.3146791
1952,1952,145.3859,15.757402,4.7553978,0.0,0,4.6538844,0.0,0.38094509,137.01964,5.1522775,305.21268,-9.3157873
1954,1954,145.3863,15.805582,4.8068652,0.0,0,4.6126437,0.0,0.38539064,136.88138,5.1095471,305.07895,-9.3154116
1956,1956,145.3867,15.863666,4.8428111,0.0,0,4.571404,0.0,0.38985249,136.78828,5.0646791,304.94522,-9.3147221
1958,1958,145.3871,15.913755,4.8870697,0.0,0,4.5305758,0.0,0.39365873,136.64792,5.0210438,304.81152,-9.3149786
1960,1960,145.3875,15.964799,4.9377451,0.0,0,4.4912457,0.0,0.39851242,136.46281,4.9783463,304.6778,-9.3152685
1962,1962,145.3879,16.059271,4.9725275,0.0,0,4.4520135,0.0,0.40276995,136.6032,4.934916,304.5441,-9.3151913
1964,1964,145.3883,16.121498,5.017067,0.0,0,4.4127817,0.0,0.40645683,136.65308,4.8929996,304.41037,-9.3151922
1966,1966,145.3887,16.162401,5.0631576,0.0,0,4.3735499,0.0,0.41137311,136.39787,4.8503008,304.27667,-9.3145361
1968,1968,145.3891,16.204372,5.0997968,0.0,0,4.3343177,0.0,0.41535887,136.1062,4.8084545,304.13327,-9.3144665
1970,1970,145.3895,16.290274,5.1453567,0.0,0,4.2950859,0.0,0.41929236,136.29802,4.7637396,303.98016,-9.3146925
1972,1972,145.3899,16.37797,5.1877069,0.0,0,4.2558532,0.0,0.42443106,136.32315,4.72365,303.82709,-9.3137856
1974,1974,145.3903,16.446085,5.2274079,0.0,0,4.2166214,0.0,0.42825833,136.36978,4.6789923,303.67398,-9.3139877
1976,1976,145.3907,16.484224,5.2723532,0.0,0,4.1773896,0.0,0.43227875,136.17569,4.6388154,303.5209,-9.3142672
1978,1978,145.3911,16.536455,5.3100753,0.0,0,4.1381574,0.0,0.4371289,135.90857,4.5957785,303.3678,-9.3151808
1980,1980,145.3915,16.62015,5.3531013,0.0,0,4.0989256,0.0,0.4407869,136.0919,4.5519967,303.21472,-9.3151884
1982,1982,145.3919,16.717127,5.3964205,0.0,0,4.0596938,0.0,0.44537959,136.30974,4.5111136,303.06161,-9.3145695
1984,1984,145.3923,16.768036,5.4348736,0.0,0,4.0217257,0.0,0.45004058,136.09378,4.4686427,302.90851,-9.3137255
1986,1986,145.3927,16.814501,5.4809608,0.0,0,3.9844093,0.0,0.45385033,135.9037,4.4270673,302.75543,-9.314744
1988,1988,145.3931,16.881697,5.5189185,0.0,0,3.9470973,0.0,0.45850897,135.82919,4.3876328,302.60233,-9.3156042
1990,1990,145.3935,16.967203,5.5555148,0.0,0,3.9097853,0.0,0.4625603,135.92397,4.3474445,302.44925,-9.3152514
1992,1992,145.3939,17.050808,5.6061563,0.0,0,3.8724735,0.0,0.46689942,136.03244,4.3069715,302.29614,-9.3149776
1994,1994,145.3943,17.099691,5.6411095,0.0,0,3.8351612,0.0,0.47155198,135.83995,4.2630582,302.14307,-9.315177
1996,1996,145.3947,17.157579,5.6791706,0.0,0,3.7978494,0.0,0.47543344,135.75998,4.2240238,301.98996,-9.3154583
1998,1998,145.3951,17.224754,5.7272053,0.0,0,3.7605371,0.0,0.48000041,135.64076,4.1851125,301.83688,-9.3135376
2000,2000,145.3955,17.321838,5.7574344,0.0,0,3.7232254,0.0,0.48441029,135.72287,4.1466484,301.68378,-9.3150702
2002,2002,145.3959,17.405281,5.7989025,0.0,0,3.6859133,0.0,0.48808435,136.0322,4.1063199,301.5307,-9.3154869
2004,2004,145.3963,17.486109,5.8460836,0.0,0,3.6486013,0.0,0.49313971,135.92859,4.0623016,301.37759,-9.3148565
2006,2006,145.3967,17.537144,5.8781166,0.0,0,3.6112893,0.0,0.4974111,135.68982,4.0261407,301.22452,-9.3141193
2008,2008,145.3971,17.599844,5.9213548,0.0,0,3.5743496,0.0,0.50119728,135.67287,3.9874914,301.07141,-9.3135662
2010,2010,145.3975,17.709867,5.962266,0.0,0,3.538765,0.0,0.50632888,135.78793,3.9452679,300.91833,-9.3135738
2012,2012,145.3979,17.796968,5.9958768,0.0,0,3.5032687,0.0,0.51014924,135.96443,3.9057941,300.76523,-9.3148594
2014,2014,145.3983,17.847696,6.0388784,0.0,0,3.4677727,0.0,0.51426178,135.90305,3.8681691,300.61215,-9.3164845
2016,2016,145.3987,17.916233,6.078599,0.0,0,3.432277,0.0,0.51948708,135.60281,3.829942,300.45905,-9.3153868
2018,2018,145.3991,17.99629,6.1153708,0.0,0,3.3967807,0.0,0.52335221,135.7206,3.792948,300.40155,-9.3136501
2020,2020,145.3995,18.099054,6.1569848,0.0,0,3.3612847,0.0,0.52754724,135.93143,3.7531781,300.43961,-9.3131104
2022,2022,145.3999,18.188034,6.1931686,0.0,0,3.3257887,0.0,0.53269255,135.87808,3.7144499,300.47769,-9.3133631
2024,2024,145.4003,18.246365,6.2343264,0.0,0,3.2902927,0.0,0.53644657,135.80092,3.6732466,300.51578,-9.3136549
2026,2026,145.4007,18.312866,6.2710624,0.0,0,3.2547965,0.0,0.54090661,135.70073,3.6336637,300.55383,-9.3147039
2028,2028,145.4011,18.401659,6.3039579,0.0,0,3.2193007,0.0,0.54536992,135.72737,3.5971153,300.59192,-9.3149509
2030,2030,145.4015,18.503391,6.347528,0.0,0,3.1838048,0.0,0.54915541,135.99091,3.5603662,300.62997,-9.3134975
2032,2032,145.4019,18.591589,6.3827076,0.0,0,3.1483088,0.0,0.55398357,135.99577,3.5199361,300.66806,-9.3137922
2034,2034,145.4023,18.650852,6.4193897,0.0,0,3.11395,0.0,0.55841315,135.83405,3.4850316,300.70615,-9.3136911
2036,2036,145.4027,18.734074,6.4638848,0.0,0,3.0801783,0.0,0.56263697,135.79143,3.448297,300.7442,-9.3137426
2038,2038,145.4031,18.816294,6.4933481,0.0,0,3.0464106,0.0,0.56728101,135.82677,3.411572,300.78229,-9.3136349
2040,2040,145.4035,18.920683,6.5289359,0.0,0,3.0126424,0.0,0.57088786,136.01341,3.3753295,300.82034,-9.3128605
2042,2042,145.4039,19.021481,6.5713453,0.0,0,2.9788744,0.0,0.57545066,136.14899,3.3378017,300.85843,-9.3141212
2044,2044,145.4043,19.090517,6.6006804,0.0,0,2.9451065,0.0,0.58004481,136.00693,3.3004746,300.89651,-9.3150225
2046,2046,145.4047,19.164169,6.6405816,0.0,0,2.9113381,0.0,0.58395833,136.03995,3.2649157,300.93457,-9.3145609
2048,2048,145.4051,19.256548,6.6834626,0.0,0,2.8775704,0.0,0.58912832,135.96181,3.2304585,300.97266,-9.3140383
2050,2050,145.4055,19.358335,6.7099161,0.0,0,2.8438022,0.0,0.59311801,136.15044,3.1931617,301.01071,-9.3129816
2052,2052,145.4059,19.465652,6.7499738,0.0,0,2.810034,0.0,0.59681588,136.40349,3.1571767,301.0488,-9.3133993
2054,2054,145.4063,19.528872,6.791038,0.0,0,2.7762663,0.0,0.60258567,136.0582,3.1225152,301.08688,-9.3147078
2056,2056,145.4067,19.602577,6.8230147,0.0,0,2.7424984,0.0,0.60659522,136.05058,3.086925,301.12494,-9.3139229
2058,2058,145.4071,19.696053,6.8614049,0.0,0,2.7090683,0.0,0.61051387,136.10443,3.0500755,301.16302,-9.3140621
2060,2060,145.4075,19.812115,6.8919392,0.0,0,2.6768677,0.0,0.61543196,136.21552,3.015609,301.20108,-9.3129196
2062,2062,145.4079,19.909882,6.924047,0.0,0,2.6447473,0.0,0.61863321,136.48647,2.97967,301.23917,-9.3125706
2064,2064,145.4083,19.974304,6.9610147,0.0,0,2.6126273,0.0,0.62300247,136.35992,2.9446511,301.27725,-9.3130207
2066,2066,145.4087,20.057535,6.9931488,0.0,0,2.5805073,0.0,0.62802202,136.24869,2.9121342,301.31531,-9.3132534
2068,2068,145.4091,20.15873,7.0330005,0.0,0,2.5483873,0.0,0.63174671,136.39326,2.8760159,301.32822,-9.3142004
2070,2070,145.4095,20.286009,7.0679874,0.0,0,2.5162673,0.0,0.63664234,136.57706,2.8404119,301.31592,-9.3126526
2072,2072,145.4099,20.38633,7.0962877,0.0,0,2.4841473,0.0,0.64102095,136.64297,2.8066978,301.30365,-9.3123684
2074,2074,145.4103,20.45908,7.1375432,0.0,0,2.4520273,0.0,0.6447385,136.66458,2.774004,301.29135,-9.312211
2076,2076,145.4107,20.544355,7.1662178,0.0,0,2.4199073,0.0,0.64941525,136.56009,2.7377183,301.27908,-9.3133774
2078,2078,145.4111,20.650238,7.1965985,0.0,0,2.3877873,0.0,0.65325201,136.73088,2.7037804,301.26678,-9.3136435
2080,2080,145.4115,20.770449,7.2388196,0.0,0,2.3556671,0.0,0.65762413,136.86932,2.6701498,301.25452,-9.3143969
2082,2082,145.4119,20.880278,7.2641535,0.0,0,2.3235474,0.0,0.66236073,136.94014,2.6399267,301.24222,-9.3136015
2084,2084,145.4123,20.951942,7.2977557,0.0,0,2.2924595,0.0,0.66599512,137.00337,2.6072454,301.22995,-9.312192
2086,2086,145.4127,21.034847,7.3372574,0.0,0,2.2619042,0.0,0.67084599,136.88725,2.5747633,301.21765,-9.3120975
2088,2088,145.4131,21.146246,7.3608861,0.0,0,2.2313523,0.0,0.67511171,136.95023,2.5448682,301.20538,-9.3125315
2090,2090,145.4135,21.279488,7.3966999,0.0,0,2.2008004,0.0,0.67849439,137.3855,2.512032,301.19308,-9.3143482
2092,2092,145.4139,21.372766,7.4333873,0.0,0,2.1702483,0.0,0.68379831,137.30708,2.4761646,301.18082,-9.3136616
2094,2094,145.4143,21.449678,7.45785,0.0,0,2.1396964,0.0,0.68769032,137.22343,2.4471152,301.16855,-9.3128433
2096,2096,145.4147,21.547461,7.4944611,0.0,0,2.1091442,0.0,0.69135123,137.3532,2.4143641,301.15625,-9.3121338
2098,2098,145.4151,21.665821,7.525136,0.0,0,2.0785923,0.0,0.69662195,137.37683,2.3802593,301.14398,-9.3126497
2100,2100,145.4155,21.81052,7.5512137,0.0,0,2.0480404,0.0,0.69964105,137.84946,2.348793,301.13168,-9.3135424
2102,2102,145.4159,21.913319,7.5860186,0.0,0,2.0174885,0.0,0.70366889,137.98274,2.3181131,301.11942,-9.314065
2104,2104,145.4163,21.993797,7.6180501,0.0,0,1.9869361,0.0,0.70925802,137.7256,2.2880318,301.10712,-9.3134985
2106,2106,145.4167,22.097565,7.6523027,0.0,0,1.9563841,0.0,0.71291775,137.86429,2.2530756,301.09485,-9.3121109
2108,2108,145.4171,22.236177,7.6860547,0.0,0,1.9261373,0.0,0.71754462,138.10002,2.2213719,301.08255,-9.3119154
2110,2110,145.4175,22.375509,7.7112556,0.0,0,1.8970004,0.0,0.72225606,138.23962,2.1921711,301.07028,-9.3126469
2112,2112,145.4179,22.469118,7.7474041,0.0,0,1.8679364,0.0,0.7256732,138.40253,2.1611328,301.05798,-9.3132915
2114,2114,145.4183,22.568167,7.7759004,0.0,0,1.8388724,0.0,0.73024434,138.36449,2.1291418,301.04572,-9.3132868
2116,2116,145.4187,22.673286,7.8006473,0.0,0,1.8098084,0.0,0.73424911,138.46933,2.097398,301.03342,-9.3127098
2118,2118,145.4191,22.814163,7.8411412,0.0,0,1.7807443,0.0,0.73831308,138.70337,2.0666854,300.98737,-9.3129168
2120,2120,145.4195,22.957031,7.8661537,0.0,0,1.7516804,0.0,0.74323386,138.91373,2.0342178,300.90753,-9.3116798
2122,2122,145.4199,23.046822,7.8968306,0.0,0,1.7226164,0.0,0.74701726,138.94719,2.0061841,300.8277,-9.3121157
2124,2124,145.4203,23.161751,7.9369001,0.0,0,1.6935524,0.0,0.7518217,138.92317,1.9778535,300.74786,-9.3122425
2126,2126,145.4207,23.268841,7.9569302,0.0,0,1.6644883,0.0,0.75639343,138.95372,1.9471983,300.66803,-9.3122377
2128,2128,145.4211,23.387114,7.9874821,0.0,0,1.6354244,0.0,0.75959098,139.23055,1.9178052,300.5882,-9.3118753
2130,2130,145.4215,23.534126,8.0224371,0.0,0,1.6063604,0.0,0.76442122,139.46237,1.8884277,300.50836,-9.3113422
2132,2132,145.4219,23.647314,8.0418406,0.0,0,1.5772964,0.0,0.76853496,139.5233,1.8583921,300.42853,-9.3109961
2134,2134,145.4223,23.74542,8.0765781,0.0,0,1.5491644,0.0,0.77206403,139.61255,1.8287334,300.34869,-9.3112841
2136,2136,145.4227,23.869989,8.1116219,0.0,0,1.5215132,0.0,0.7778855,139.58076,1.7987715,300.26886,-9.3123951
2138,2138,145.4231,24.008135,8.1353436,0.0,0,1.4938653,0.0,0.7818085,139.79179,1.7693415,300.18903,-9.3115168
2140,2140,145.4235,24.162607,8.1678562,0.0,0,1.4662173,0.0,0.78533518,140.21198,1.7407427,300.10919,-9.3101959
2142,2142,145.4239,24.277792,8.1953535,0.0,0,1.4385693,0.0,0.79054052,140.21117,1.7094253,300.02936,-9.3104982
2144,2144,145.4243,24.384832,8.2186441,0.0,0,1.4109213,0.0,0.79364705,140.35649,1.6846889,299.94952,-9.3111238
2146,2146,145.4247,24.512484,8.2510042,0.0,0,1.3832734,0.0,0.79778296,140.4734,1.6548525,299.86969,-9.3118868
2148,2148,145.4251,24.656494,8.2788076,0.0,0,1.3556253,0.0,0.80320674,140.55083,1.6261282,299.78986,-9.3123713
2150,2150,145.4255,24.79903,8.3115196,0.0,0,1.3279774,0.0,0.80675697,140.87453,1.5967053,299.71002,-9.3119783
2152,2152,145.4259,24.923965,8.3408384,0.0,0,1.3003293,0.0,0.8113687,140.9301,1.5667945,299.63019,-9.3110619
2154,2154,145.4263,25.035934,8.3613472,0.0,0,1.2726814,0.0,0.81570953,140.96077,1.5402246,299.55035,-9.3106356
2156,2156,145.4267,25.178329,8.394475,0.0,0,1.2450334,0.0,0.81889874,141.26346,1.5120621,299.47052,-9.3105307
2158,2158,145.4271,25.322117,8.4195881,0.0,0,1.2176627,0.0,0.82363254,141.40996,1.4828721,299.39069,-9.3105574
2160,2160,145.4275,25.477468,8.4446917,0.0,0,1.1913006,0.0,0.82787097,141.6676,1.456309,299.31085,-9.3113871
2162,2162,145.4279,25.599871,8.4834003,0.0,0,1.1650045,0.0,0.83217651,141.74747,1.4261999,299.23102,-9.3120794
2164,2164,145.4283,25.722374,8.5041342,0.0,0,1.1387084,0.0,0.83693725,141.72478,1.3994939,299.15118,-9.3120203
2166,2166,145.4287,25.862091,8.5294161,0.0,0,1.1124125,0.0,0.84051955,142.00177,1.3706267,299.07135,-9.3108416
2168,2168,145.4291,26.028648,8.5642204,0.0,0,1.0861164,0.0,0.84491944,142.28175,1.3434615,298.81976,-9.3103666
2170,2170,145.4295,26.192226,8.5804043,0.0,0,1.0598203,0.0,0.84920102,142.5739,1.3158344,298.39642,-9.3096666
2172,2172,145.4299,26.317324,8.6096849,0.0,0,1.0335244,0.0,0.85235852,142.78598,1.2879333,297.97311,-9.3103085
2174,2174,145.4303,26.440985,8.6452379,0.0,0,1.0072284,0.0,0.85788631,142.7063,1.2611556,297.54977,-9.3114166
2176,2176,145.4307,26.590214,8.6630898,0.0,0,0.98093235,0.0,0.86212844,142.87175,1.2331939,297.12646,-9.3111496
2178,2178,145.4311,26.767597,8.6951218,0.0,0,0.95463634,0.0,0.86544073,143.33821,1.2094115,296.70313,-9.310503
2180,2180,145.4315,26.928394,8.7227192,0.0,0,0.92834044,0.0,0.87105697,143.40128,1.1776284,296.27979,-9.3105726
2182,2182,145.4319,27.053873,8.7409039,0.0,0,0.90204442,0.0,0.87416846,143.66837,1.1507571,295.85648,-9.3101988
2184,2184,145.4323,27.188278,8.7697792,0.0,0,0.87659609,0.0,0.87753564,143.88774,1.1244739,295.43314,-9.3100233
2186,2186,145.4327,27.349537,8.7961884,0.0,0,0.85158539,0.0,0.88323975,143.84221,1.094267,295.00983,-9.3104258
2188,2188,145.4331,27.527691,8.8222446,0.0,0,0.82657731,0.0,0.88675398,144.28333,1.0707238,294.58649,-9.3097534
2190,2190,145.4335,27.670622,8.8521528,0.0,0,0.8015694,0.0,0.89101511,144.46922,1.0451849,294.16315,-9.3096733
2192,2192,145.4339,27.805758,8.8731365,0.0,0,0.77656138,0.0,0.89602327,144.44284,1.0208286,293.73984,-9.3094139
2194,2194,145.4343,27.943096,8.902216,0.0,0,0.75155336,0.0,0.89883727,144.72563,0.99315792,293.3165,-9.3106251
2196,2196,145.4347,28.111818,8.9250689,0.0,0,0.72654539,0.0,0.9032892,144.94618,0.96783733,292.89319,-9.3100634
2198,2198,145.4351,28.301996,8.9436607,0.0,0,0.70153737,0.0,0.90739113,145.37106,0.94306767,292.46985,-9.3084431
2200,2200,145.4355,28.450665,8.9771729,0.0,0,0.67652941,0.0,0.91097492,145.59729,0.91499358,292.04651,-9.3086157
2202,2202,145.4359,28.58864,8.9991951,0.0,0,0.65152138,0.0,0.91611981,145.59203,0.88959426,291.6232,-9.3092222
2204,2204,145.4363,28.735203,9.0229588,0.0,0,0.62651336,0.0,0.91999519,145.72542,0.86669111,291.19986,-9.3104372
2206,2206,145.4367,28.911192,9.0568113,0.0,0,0.6015054,0.0,0.92406428,146.01558,0.84073949,290.77655,-9.3097029
2208,2208,145.4371,29.097622,9.0724163,0.0,0,0.57674509,0.0,0.92873996,146.26765,0.81547534,290.35321,-9.3084288
2210,2210,145.4375,29.24604,9.095336,0.0,0,0.55288601,0.0,0.93177956,146.60219,0.79077172,289.92987,-9.3099766
2212,2212,145.4379,29.378765,9.1254988,0.0,0,0.52908593,0.0,0.9364025,146.58258,0.76651096,289.50656,-9.3091469
2214,2214,145.4383,29.549345,9.1390743,0.0,0,0.50528592,0.0,0.94044328,146.81664,0.74185091,289.08322,-9.3086081
2216,2216,145.4387,29.7339,9.1663237,0.0,0,0.4814859,0.0,0.94329637,147.29433,0.72012794,288.65991,-9.3086557
2218,2218,145.4391,29.934464,9.1980829,0.0,0,0.45768592,0.0,0.94894713,147.46101,0.69654131,288.50107,-9.3088026
2220,2220,145.4395,30.097383,9.2151642,0.0,0,0.4338859,0.0,0.95315874,147.63339,0.66969919,288.60669,-9.3089199
2222,2222,145.4399,30.251108,9.2446766,0.0,0,0.41008592,0.0,0.95664084,147.90231,0.64705962,288.71231,-9.3082428
2224,2224,145.4403,30.423075,9.268404,0.0,0,0.3862859,0.0,0.9621765,147.91582,0.62259305,288.81793,-9.3091555
2226,2226,145.4407,30.617556,9.284503,0.0,0,0.36248589,0.0,0.96501827,148.39293,0.59665841,288.92355,-9.3082552
2228,2228,145.4411,30.813896,9.311285,0.0,0,0.3386859,0.0,0.96847272,148.85709,0.57199955,289.02917,-9.3083677
2230,2230,145.4415,30.991417,9.3329363,0.0,0,0.31488591,0.0,0.97385222,148.90462,0.54600674,289.1348,-9.308218
2232,2232,145.4419,31.166315,9.3570166,0.0,0,0.29108587,0.0,0.97712195,149.29735,0.52276528,289.24042,-9.3075857