File: examples/hot axisymmetric compression example/data/03 trimmed data/testID_0136.csv
level_0,index,Time(sec),Force(kN),Jaw(mm),PowAngle(deg),Power(W),Pram,PTemp,Strain,Stress(MPa),Stroke(mm),TC1(C),wedge(mm)
1873,1873,155.3444,0.78002334,0.0084406519,0.0,0,9.0337067,0.0,0.00027091574,9.7883873,10.043098,330.94385,-9.3071289
1875,1875,155.3448,2.8870025,0.025295578,0.0,0,8.9751787,0.0,0.001486312,32.267494,9.9658289,331.14594,-9.3070183
1877,1877,155.3452,5.5549741,0.08062499,0.0,0,8.9166508,0.0,0.0051362058,68.464485,9.9078436,331.34799,-9.3056107
1879,1879,155.3456,6.3817549,0.14786839,0.0,0,8.8581219,0.0,0.008974934,79.394257,9.8414745,331.55005,-9.3032179
1881,1881,155.346,7.232254,0.27199197,0.0,0,8.7995939,0.0,0.017527811,89.94416,9.7653904,331.75214,-9.3023443
1883,1883,155.3464,7.6681657,0.36512429,0.0,0,8.7416534,0.0,0.024138324,94.326241,9.670927,331.95419,-9.302701
1885,1885,155.3468,8.3517656,0.45969856,0.0,0,8.6858492,0.0,0.030168159,102.67503,9.5755301,332.15628,-9.3029509
1887,1887,155.3472,8.7704687,0.52604181,0.0,0,8.6301851,0.0,0.035716444,106.84486,9.4824982,332.35834,-9.3008604
1889,1889,155.3476,8.9234905,0.56079763,0.0,0,8.574522,0.0,0.037574045,109.9332,9.4112062,332.56039,-9.2986326
1891,1891,155.348,8.8246059,0.6391629,0.0,0,8.518857,0.0,0.042979002,107.1709,9.3431339,332.76248,-9.2990723
1893,1893,155.3484,9.2854347,0.68715984,0.0,0,8.4631929,0.0,0.046822734,112.54171,9.2856503,332.96454,-9.2998362
1895,1895,155.3488,9.5658875,0.74996251,0.0,0,8.4075298,0.0,0.050428618,115.3391,9.2196636,333.16663,-9.3011589
1897,1897,155.3492,9.514636,0.85662758,0.0,0,8.3518648,0.0,0.058249995,114.80713,9.1437864,333.36868,-9.2998466
1899,1899,155.3496,9.3902884,0.93359119,0.0,0,8.2962017,0.0,0.063864239,111.68375,9.0598831,333.57074,-9.2975225
1901,1901,155.35,9.732729,1.0124574,0.0,0,8.2405376,0.0,0.069152512,115.52273,8.9826488,333.77283,-9.2977257
1903,1903,155.3504,9.747077,1.060209,0.0,0,8.1848736,0.0,0.073364787,114.96117,8.9104795,333.97488,-9.2981911
1905,1905,155.3508,10.043615,1.0987325,0.0,0,8.1292095,0.0,0.07554584,118.60396,8.8459482,334.17697,-9.2998028
1907,1907,155.3512,9.7464075,1.1655114,0.0,0,8.0735455,0.0,0.080377042,114.71532,8.7900324,334.37903,-9.3000746
1909,1909,155.3516,10.108418,1.213627,0.0,0,8.0196619,0.0,0.084362604,117.8837,8.734704,334.58109,-9.2990227
1911,1911,155.352,10.196647,1.2903594,0.0,0,7.9666953,0.0,0.089074805,118.77898,8.6707582,334.78317,-9.2980633
1913,1913,155.3524,10.269426,1.3674419,0.0,0,7.9137359,0.0,0.095089771,118.90353,8.6049738,334.98523,-9.297904
1915,1915,155.3528,10.114515,1.4302582,0.0,0,7.8607755,0.0,0.099989399,116.68261,8.5352907,335.20221,-9.299015
1917,1917,155.3532,10.248122,1.5070355,0.0,0,7.8078156,0.0,0.10504171,117.27987,8.4678516,335.46381,-9.2994127
1919,1919,155.3536,10.314922,1.5396031,0.0,0,7.7548552,0.0,0.10824599,117.79739,8.4066029,335.72543,-9.2991953
1921,1921,155.354,10.493971,1.5904995,0.0,0,7.7018952,0.0,0.11158706,119.39355,8.35254,335.98703,-9.2987576
1923,1923,155.3544,10.393657,1.6566843,0.0,0,7.6489348,0.0,0.11631645,117.90682,8.3000546,336.24866,-9.2984715
1925,1925,155.3548,10.588933,1.6957351,0.0,0,7.5959754,0.0,0.11991721,119.31883,8.2443695,336.51028,-9.2977877
1927,1927,155.3552,10.61489,1.7623681,0.0,0,7.543015,0.0,0.12431422,119.43443,8.187952,336.77188,-9.2987976
1929,1929,155.3556,10.657887,1.8298641,0.0,0,7.4900556,0.0,0.12947495,119.01126,8.1289043,337.03351,-9.2989731
1931,1931,155.356,10.692117,1.8818864,0.0,0,7.4370952,0.0,0.13389455,119.08745,8.067646,337.2951,-9.2992077
1933,1933,155.3564,10.693617,1.9386661,0.0,0,7.3846664,0.0,0.13774888,118.55172,8.0119753,337.55673,-9.2995195
1935,1935,155.3568,10.80055,1.9781163,0.0,0,7.3341722,0.0,0.14118136,119.31702,7.9586782,337.81836,-9.2991018
1937,1937,155.3572,10.828578,2.0276935,0.0,0,7.2838039,0.0,0.14496492,119.30402,7.9052434,338.07996,-9.2983494
1939,1939,155.3576,10.868293,2.0804834,0.0,0,7.2334356,0.0,0.14873137,119.08727,7.8539758,338.34158,-9.2986383
1941,1941,155.358,10.953706,2.1291347,0.0,0,7.1830673,0.0,0.15293992,119.50043,7.8079996,338.60318,-9.2986383
1943,1943,155.3584,11.046988,2.1840384,0.0,0,7.1326995,0.0,0.1568846,120.14616,7.7521563,338.86481,-9.2987089
1945,1945,155.3588,11.074766,2.2370169,0.0,0,7.0823312,0.0,0.16092272,120.06297,7.6996598,339.12643,-9.2991457
1947,1947,155.3592,11.041647,2.2903185,0.0,0,7.0319633,0.0,0.16559523,119.06969,7.6489959,339.38803,-9.2984791
1949,1949,155.3596,11.11167,2.3402343,0.0,0,6.981595,0.0,0.16906393,119.33252,7.5957456,339.64966,-9.298748
1951,1951,155.36,11.211173,2.3809314,0.0,0,6.9312277,0.0,0.17236458,120.05547,7.5452824,339.91125,-9.2976809
1953,1953,155.3604,11.254734,2.4276388,0.0,0,6.8808594,0.0,0.17650951,120.18969,7.4978147,340.17288,-9.2969685
1955,1955,155.3608,11.240395,2.479013,0.0,0,6.830492,0.0,0.17985937,119.50512,7.4484138,340.43451,-9.2975349
1957,1957,155.3612,11.300659,2.5262682,0.0,0,6.7801232,0.0,0.1841795,119.61114,7.4015446,340.69611,-9.2992134
1959,1959,155.3616,11.388411,2.57546,0.0,0,6.7313671,0.0,0.18815799,120.0635,7.3526964,340.95773,-9.3001308
1961,1961,155.362,11.449078,2.6310103,0.0,0,6.6834416,0.0,0.19199918,120.29572,7.3014207,341.21933,-9.2991095
1963,1963,155.3624,11.438499,2.6754484,0.0,0,6.6355219,0.0,0.19631736,119.73029,7.2534933,341.48096,-9.2984257
1965,1965,155.3628,11.502731,2.7164872,0.0,0,6.5876017,0.0,0.19938622,119.93106,7.2066388,341.69022,-9.2992353
1967,1967,155.3632,11.549538,2.7689507,0.0,0,6.5396819,0.0,0.2033911,119.97239,7.1564817,341.74249,-9.2990723
1969,1969,155.3636,11.629908,2.8086963,0.0,0,6.4917622,0.0,0.2072994,120.25204,7.1099911,341.79474,-9.2988729
1971,1971,155.364,11.663646,2.8557646,0.0,0,6.4438419,0.0,0.21051346,120.30223,7.0620818,341.84702,-9.2990074
1973,1973,155.3644,11.71941,2.9111755,0.0,0,6.3959212,0.0,0.21532263,120.32952,7.0175757,341.89929,-9.2980633
1975,1975,155.3648,11.773714,2.9511137,0.0,0,6.3480015,0.0,0.21892655,120.31033,6.9689021,341.95154,-9.298562
1977,1977,155.3652,11.809544,3.0021224,0.0,0,6.3000817,0.0,0.22258,120.29549,6.9227223,342.00381,-9.29916
1979,1979,155.3656,11.834092,3.0513873,0.0,0,6.252162,0.0,0.22730023,120.01678,6.8719926,342.05606,-9.2991409
1981,1981,155.366,11.907089,3.0933189,0.0,0,6.2042422,0.0,0.23068088,120.25763,6.8249307,342.10834,-9.2994642
1983,1983,155.3664,11.962745,3.1443458,0.0,0,6.1568027,0.0,0.23461166,120.42355,6.7798548,342.16061,-9.2997341
1985,1985,155.3668,12.005458,3.1868792,0.0,0,6.1111121,0.0,0.23891258,120.32033,6.7300506,342.21286,-9.2985773
1987,1987,155.3672,12.053741,3.2336247,0.0,0,6.065536,0.0,0.24216123,120.40579,6.6815634,342.26514,-9.2985945
1989,1989,155.3676,12.092227,3.2825854,0.0,0,6.0199599,0.0,0.24643873,120.25703,6.634851,342.31738,-9.2989912
1991,1991,155.368,12.19345,3.3258924,0.0,0,5.9743834,0.0,0.25065634,120.66766,6.586328,342.36966,-9.2994175
1993,1993,155.3684,12.240971,3.3836129,0.0,0,5.9288077,0.0,0.25473005,120.77699,6.5376782,342.42194,-9.2988777
1995,1995,155.3688,12.248789,3.4303212,0.0,0,5.8832321,0.0,0.25935873,120.30572,6.4885263,342.47418,-9.2986536
1997,1997,155.3692,12.292492,3.4742112,0.0,0,5.8376555,0.0,0.2632896,120.2362,6.4415755,342.52646,-9.2989063
1999,1999,155.3696,12.360831,3.5325558,0.0,0,5.792079,0.0,0.26750776,120.41125,6.3942719,342.5787,-9.29953
2001,2001,155.37,12.446403,3.5681419,0.0,0,5.7465038,0.0,0.27152148,120.77515,6.3463883,342.63098,-9.2993355
2003,2003,155.3704,12.484735,3.615026,0.0,0,5.7009277,0.0,0.27526495,120.7104,6.2964015,342.68326,-9.2987747
2005,2005,155.3708,12.509054,3.671382,0.0,0,5.6553516,0.0,0.27981049,120.40603,6.2484865,342.7355,-9.2982273
2007,2007,155.3712,12.571374,3.711854,0.0,0,5.6097755,0.0,0.28429735,120.24979,6.2029481,342.78778,-9.2983341
2009,2009,155.3716,12.655971,3.7634597,0.0,0,5.5656581,0.0,0.28817987,120.73357,6.1529894,342.84003,-9.2983465
2011,2011,155.372,12.697213,3.8160734,0.0,0,5.5222936,0.0,0.29297319,120.62289,6.1027727,342.8923,-9.2990189
2013,2013,155.3724,12.742992,3.8575056,0.0,0,5.4789333,0.0,0.29722518,120.53062,6.0580301,342.94458,-9.2990341
2015,2015,155.3728,12.78101,3.9075718,0.0,0,5.4355736,0.0,0.3009927,120.39705,6.0106215,342.95734,-9.2992115
2017,2017,155.3732,12.836389,3.9525352,0.0,0,5.3922133,0.0,0.30561826,120.36322,5.9616561,342.85159,-9.2987165
2019,2019,155.3736,12.897606,3.9951179,0.0,0,5.3488536,0.0,0.30949208,120.47546,5.9120584,342.74585,-9.297883
2021,2021,155.374,12.9757,4.0453715,0.0,0,5.3054934,0.0,0.31354684,120.66773,5.8675027,342.64008,-9.298049
2023,2023,155.3744,13.024099,4.0930786,0.0,0,5.2621331,0.0,0.31861457,120.52287,5.817101,342.53433,-9.2981615
2025,2025,155.3748,13.042657,4.1421123,0.0,0,5.2187734,0.0,0.32262784,120.32349,5.7708578,342.42859,-9.2981405
2027,2027,155.3752,13.097849,4.1916256,0.0,0,5.1754136,0.0,0.32698545,120.23152,5.7234244,342.32285,-9.2984867
2029,2029,155.3756,13.170399,4.2352223,0.0,0,5.1320534,0.0,0.33184513,120.29144,5.6782079,342.2171,-9.2992067
2031,2031,155.376,13.260033,4.2847977,0.0,0,5.0886931,0.0,0.33555102,120.56237,5.6300211,342.11136,-9.2990036
2033,2033,155.3764,13.288176,4.3290505,0.0,0,5.0457683,0.0,0.34008685,120.36547,5.5832934,342.00562,-9.298748
2035,2035,155.3768,13.315804,4.3730354,0.0,0,5.0044241,0.0,0.344598,120.07085,5.5357351,341.89987,-9.2990561
2037,2037,155.3772,13.364712,4.4275088,0.0,0,4.9631839,0.0,0.34879565,120.00337,5.490437,341.79413,-9.2978172
2039,2039,155.3776,13.463663,4.469739,0.0,0,4.9219441,0.0,0.35352963,120.2893,5.4418454,341.68839,-9.2990007
2041,2041,155.378,13.517685,4.5119915,0.0,0,4.8807039,0.0,0.35750416,120.34765,5.3945618,341.58264,-9.3003836
2043,2043,155.3784,13.543106,4.5657482,0.0,0,4.8394642,0.0,0.36193281,120.0454,5.3518705,341.4769,-9.3005962
2045,2045,155.3788,13.581142,4.6033087,0.0,0,4.798224,0.0,0.36659986,119.79795,5.3055887,341.37115,-9.2995148
2047,2047,155.3792,13.65273,4.6482615,0.0,0,4.7569842,0.0,0.37038463,119.9754,5.2586217,341.26541,-9.299552
2049,2049,155.3796,13.719999,4.704401,0.0,0,4.715744,0.0,0.37547147,119.97993,5.2125454,341.15967,-9.2981138
2051,2051,155.38,13.773232,4.7427592,0.0,0,4.6745043,0.0,0.38006228,119.91396,5.1696253,341.05392,-9.2985878
2053,2053,155.3804,13.807782,4.7895651,0.0,0,4.6332641,0.0,0.38376939,119.69373,5.1208668,340.94818,-9.2992678
2055,2055,155.3808,13.855811,4.8369141,0.0,0,4.5920238,0.0,0.38895851,119.47334,5.0765719,340.84244,-9.2992563
2057,2057,155.3812,13.916677,4.8726339,0.0,0,4.5507841,0.0,0.39267144,119.59677,5.0361247,340.73669,-9.299593
2059,2059,155.3816,13.978306,4.9200096,0.0,0,4.5108657,0.0,0.39656997,119.57318,4.9905386,340.63095,-9.2979698
2061,2061,155.382,14.029277,4.9618568,0.0,0,4.4716296,0.0,0.401584,119.53559,4.947546,340.52521,-9.29879
2063,2063,155.3824,14.085856,5.0018139,0.0,0,4.4323978,0.0,0.40533578,119.50768,4.9043651,340.41946,-9.2990732
2065,2065,155.3828,14.129436,5.050899,0.0,0,4.3931656,0.0,0.40974897,119.33862,4.8602748,340.21127,-9.2986383
2067,2067,155.3832,14.194504,5.0916643,0.0,0,4.3539338,0.0,0.4148072,119.30106,4.8180757,339.69589,-9.2984447
2069,2069,155.3836,14.267962,5.1395383,0.0,0,4.314702,0.0,0.41871718,119.41533,4.7730594,339.18051,-9.2978945
2071,2071,155.384,14.328987,5.182663,0.0,0,4.2754698,0.0,0.42338052,119.3849,4.7285833,338.66513,-9.298584
2073,2073,155.3844,14.370019,5.2197337,0.0,0,4.2362375,0.0,0.42781171,119.2792,4.6867089,338.14972,-9.2989407
2075,2075,155.3848,14.408772,5.268487,0.0,0,4.1970053,0.0,0.43171546,119.06847,4.6431398,337.63434,-9.2984619
2077,2077,155.3852,14.471498,5.3056931,0.0,0,4.1577735,0.0,0.43627355,119.04866,4.6016378,337.11896,-9.2985973
2079,2079,155.3856,14.547789,5.3436604,0.0,0,4.1185417,0.0,0.44022363,119.27174,4.5580134,336.60358,-9.2988701
2081,2081,155.386,14.610601,5.3951135,0.0,0,4.0793095,0.0,0.44458789,119.20982,4.5199342,336.0882,-9.2977867
2083,2083,155.3864,14.641874,5.4294853,0.0,0,4.0404716,0.0,0.44935483,118.95425,4.4775233,335.57278,-9.2978792
2085,2085,155.3868,14.691337,5.4728642,0.0,0,4.0030656,0.0,0.45337918,118.84371,4.4329882,335.0574,-9.2989674
2087,2087,155.3872,14.756018,5.5220761,0.0,0,3.9657533,0.0,0.45819435,118.77355,4.3947682,334.54202,-9.2999086
2089,2089,155.3876,14.850708,5.5527167,0.0,0,3.9284413,0.0,0.46244353,119.02993,4.3547535,334.02664,-9.2992992
2091,2091,155.388,14.909626,5.592813,0.0,0,3.8911293,0.0,0.46582505,119.16991,4.3150501,333.51126,-9.2986097
2093,2093,155.3884,14.960092,5.6383724,0.0,0,3.8538175,0.0,0.47081867,118.93624,4.273068,332.99585,-9.2979269
2095,2095,155.3888,15.014074,5.6725411,0.0,0,3.8165054,0.0,0.47510365,118.82366,4.2283607,332.48047,-9.2982368
2097,2097,155.3892,15.082983,5.7199564,0.0,0,3.7791932,0.0,0.47922069,118.86836,4.1893716,331.96509,-9.2983742
2099,2099,155.3896,15.159572,5.7630091,0.0,0,3.7418811,0.0,0.4846738,118.8303,4.1498389,331.44971,-9.2992458
2101,2101,155.39,15.229249,5.7973456,0.0,0,3.7045693,0.0,0.4883506,118.94501,4.1077962,330.93433,-9.2985611
2103,2103,155.3904,15.266991,5.837966,0.0,0,3.6672573,0.0,0.49217793,118.76409,4.0709648,330.41891,-9.2986584
2105,2105,155.3908,15.329489,5.8736401,0.0,0,3.6299453,0.0,0.49710658,118.6788,4.0295978,329.90353,-9.2982454
2107,2107,155.3912,15.410011,5.9130907,0.0,0,3.5926332,0.0,0.50064379,118.88042,3.9898736,329.38815,-9.298521
2109,2109,155.3916,15.494488,5.9539599,0.0,0,3.5565166,0.0,0.50494629,118.97124,3.9501476,328.87277,-9.2985077
2111,2111,155.392,15.557748,5.9891658,0.0,0,3.5210168,0.0,0.50983077,118.89021,3.9123974,328.35739,-9.2988129
2113,2113,155.3924,15.589083,6.0339785,0.0,0,3.4855206,0.0,0.51371586,118.72727,3.8764627,327.84198,-9.2991896
2115,2115,155.3928,15.645274,6.0710797,0.0,0,3.4500248,0.0,0.51835459,118.55552,3.8386106,327.33197,-9.298418
2117,2117,155.3932,15.727001,6.1032844,0.0,0,3.4145288,0.0,0.52242273,118.73706,3.8005948,326.83798,-9.2972488
2119,2119,155.3936,15.821076,6.1474814,0.0,0,3.3790326,0.0,0.52618325,118.99234,3.7631726,326.34399,-9.2993917
2121,2121,155.394,15.874632,6.1789322,0.0,0,3.3435369,0.0,0.53085732,118.89561,3.7246439,325.85004,-9.2979345
2123,2123,155.3944,15.92529,6.2159023,0.0,0,3.3080409,0.0,0.53476995,118.77878,3.6854987,325.35605,-9.2974424
2125,2125,155.3948,15.986321,6.2622442,0.0,0,3.2725446,0.0,0.53922629,118.64626,3.6482079,324.86209,-9.2974348
2127,2127,155.3952,16.073219,6.2897735,0.0,0,3.2370486,0.0,0.54383689,118.76456,3.6118925,324.3681,-9.2972927
2129,2129,155.3956,16.16559,6.3278823,0.0,0,3.2015526,0.0,0.54736334,119.0535,3.5728254,323.87411,-9.2975655
2131,2131,155.396,16.224142,6.3702159,0.0,0,3.1660566,0.0,0.55206275,118.93079,3.5391419,323.38016,-9.2978992
2133,2133,155.3964,16.278641,6.3985038,0.0,0,3.1309152,0.0,0.55631334,118.772,3.5030077,322.88617,-9.2983484
2135,2135,155.3968,16.349894,6.4401116,0.0,0,3.0970623,0.0,0.55995053,118.84507,3.4679637,322.39221,-9.2980719
2137,2137,155.3972,16.446753,6.4791303,0.0,0,3.0632944,0.0,0.56527472,118.91468,3.4320295,321.89822,-9.2975578
2139,2139,155.3976,16.535763,6.5080714,0.0,0,3.0295265,0.0,0.56888282,119.1699,3.3975773,321.40424,-9.2974224
2141,2141,155.398,16.58951,6.5488472,0.0,0,2.9957583,0.0,0.57270068,119.07936,3.3600788,320.91028,-9.2979679
2143,2143,155.3984,16.65654,6.5830135,0.0,0,2.9619906,0.0,0.57790643,118.90945,3.3240163,320.41629,-9.2982798
2145,2145,155.3988,16.727686,6.6185355,0.0,0,2.9282222,0.0,0.5815621,118.96661,3.2903728,319.92233,-9.2976637
2147,2147,155.3992,16.831411,6.6576772,0.0,0,2.8944542,0.0,0.58585912,119.19291,3.2553718,319.42834,-9.2974501
2149,2149,155.3996,16.921839,6.6870079,0.0,0,2.8606863,0.0,0.59062147,119.32858,3.215193,318.93436,-9.2980213
2151,2151,155.4,16.986265,6.7259312,0.0,0,2.8269184,0.0,0.59404355,119.36193,3.181288,318.4404,-9.29807
2153,2153,155.4004,17.052223,6.7603717,0.0,0,2.7931502,0.0,0.59865963,119.27814,3.1447682,317.94641,-9.2970819
2155,2155,155.4008,17.141367,6.7899432,0.0,0,2.7593822,0.0,0.60302997,119.3491,3.1112988,317.45245,-9.2967768
2157,2157,155.4012,17.240997,6.836936,0.0,0,2.7256143,0.0,0.6071595,119.53069,3.0721805,316.95847,-9.2973433
2159,2159,155.4016,17.335743,6.8690562,0.0,0,2.6929309,0.0,0.61220819,119.59836,3.0373926,316.46448,-9.2978106
2161,2161,155.402,17.408928,6.9014068,0.0,0,2.6608074,0.0,0.6161834,119.63675,3.0028269,315.97052,-9.2983036
2163,2163,155.4024,17.473337,6.9454403,0.0,0,2.6286874,0.0,0.62045574,119.58089,2.9673548,315.47653,-9.2978907
2165,2165,155.4028,17.574137,6.9700274,0.0,0,2.5965672,0.0,0.62498909,119.75494,2.9328284,315.10028,-9.2980986
2167,2167,155.4032,17.678782,7.0025806,0.0,0,2.5644474,0.0,0.62837505,119.99361,2.8984332,315.07703,-9.2967567
2169,2169,155.4036,17.790184,7.0467086,0.0,0,2.5323272,0.0,0.6334697,120.16568,2.860441,315.05377,-9.2962084
2171,2171,155.404,17.85392,7.0723529,0.0,0,2.5002072,0.0,0.63794053,120.06889,2.8296218,315.03055,-9.2964268
2173,2173,155.4044,17.928274,7.1122923,0.0,0,2.4680872,0.0,0.64168751,120.07182,2.7939506,315.00729,-9.2970705
2175,2175,155.4048,18.020645,7.1543026,0.0,0,2.4359674,0.0,0.64743322,120.0444,2.7642729,314.98407,-9.2974625
2177,2177,155.4052,18.129402,7.1801848,0.0,0,2.4038472,0.0,0.65147734,120.23235,2.7296185,314.96082,-9.2976885
2179,2179,155.4056,18.230413,7.2150993,0.0,0,2.3717272,0.0,0.65483594,120.50429,2.6948941,314.93756,-9.2973452
2181,2181,155.406,18.300344,7.2465191,0.0,0,2.3396072,0.0,0.65996146,120.3987,2.6578732,314.91434,-9.2957497
2183,2183,155.4064,18.376577,7.2758212,0.0,0,2.3078089,0.0,0.66342616,120.51299,2.6265903,314.89108,-9.2964954
2185,2185,155.4068,18.477121,7.3154936,0.0,0,2.2771804,0.0,0.66769779,120.57069,2.592736,314.86786,-9.2962971
2187,2187,155.4072,18.590422,7.3472543,0.0,0,2.246628,0.0,0.67333424,120.61682,2.5588648,314.8446,-9.2958593
2189,2189,155.4076,18.689207,7.3830986,0.0,0,2.2160764,0.0,0.67697042,120.88338,2.5215588,314.82135,-9.2966967
2191,2191,155.408,18.778757,7.4181747,0.0,0,2.1855242,0.0,0.68160993,120.84686,2.4884334,314.79813,-9.2973318
2193,2193,155.4084,18.860037,7.4444122,0.0,0,2.1549723,0.0,0.68615621,120.88427,2.4566627,314.77487,-9.2972622
2195,2195,155.4088,18.957384,7.4839439,0.0,0,2.1244202,0.0,0.68982613,121.01845,2.426188,314.75165,-9.2961788
2197,2197,155.4092,19.077787,7.5135221,0.0,0,2.0938683,0.0,0.69469923,121.17997,2.3904181,314.72839,-9.2964001
2199,2199,155.4096,19.183847,7.5413885,0.0,0,2.0633163,0.0,0.69881207,121.38757,2.3594797,314.70514,-9.2968721
2201,2201,155.41,19.264992,7.5854979,0.0,0,2.0327644,0.0,0.70312607,121.34573,2.3238678,314.68192,-9.2973738
2203,2203,155.4104,19.342157,7.6103835,0.0,0,2.0022123,0.0,0.7079919,121.30334,2.2950063,314.65866,-9.2970028
2205,2205,155.4108,19.444817,7.6382484,0.0,0,1.9716601,0.0,0.71130461,121.50508,2.26122,314.63544,-9.296546
2207,2207,155.4112,19.574337,7.6778669,0.0,0,1.9411081,0.0,0.71581137,121.74489,2.2292509,314.61218,-9.2971849
2209,2209,155.4116,19.67374,7.6999874,0.0,0,1.9115355,0.0,0.72057736,121.81633,2.201596,314.58893,-9.2971754
2211,2211,155.412,19.754614,7.7353926,0.0,0,1.8824685,0.0,0.72426599,121.86994,2.1666343,314.5657,-9.2960958
2213,2213,155.4124,19.837269,7.7744398,0.0,0,1.8534043,0.0,0.72962773,121.71511,2.1384509,314.54245,-9.297327
2215,2215,155.4128,19.959307,7.795146,0.0,0,1.8243403,0.0,0.73361564,121.98381,2.1079397,314.41559,-9.2974005
2217,2217,155.4132,20.089157,7.8291254,0.0,0,1.7952764,0.0,0.73690033,122.34631,2.0763893,313.97787,-9.2969103
2219,2219,155.4136,20.201454,7.8608584,0.0,0,1.7662123,0.0,0.74236107,122.38676,2.0431609,313.54016,-9.2970181
2221,2221,155.414,20.278038,7.8875661,0.0,0,1.7371484,0.0,0.74616325,122.39794,2.0138855,313.10245,-9.294899
2223,2223,155.4144,20.36838,7.9246764,0.0,0,1.7080843,0.0,0.75024104,122.41463,1.9838823,312.66473,-9.2947407
2225,2225,155.4148,20.489025,7.9522352,0.0,0,1.6790204,0.0,0.75564015,122.4642,1.9551973,312.22705,-9.2954121
2227,2227,155.4152,20.623243,7.980051,0.0,0,1.6499563,0.0,0.7588172,122.87159,1.9230325,311.78934,-9.2960587
2229,2229,155.4156,20.739687,8.0130453,0.0,0,1.6208923,0.0,0.76309651,123.02941,1.8906778,311.35162,-9.2958889
2231,2231,155.416,20.81797,8.0383396,0.0,0,1.5918283,0.0,0.76812899,122.92945,1.8628726,310.91391,-9.2960234
2233,2233,155.4164,20.936705,8.0722885,0.0,0,1.5630548,0.0,0.7714988,123.12534,1.8337039,310.4762,-9.2950239
2235,2235,155.4168,21.069199,8.1034298,0.0,0,1.5353373,0.0,0.77648544,123.30315,1.8002838,310.03851,-9.2947054
2237,2237,155.4172,21.218208,8.1284437,0.0,0,1.5076892,0.0,0.7809881,123.65991,1.7689691,309.6008,-9.2953081
2239,2239,155.4176,21.311619,8.1671228,0.0,0,1.4800413,0.0,0.78488356,123.72298,1.7405033,309.16309,-9.2952185
2241,2241,155.418,21.401028,8.1894464,0.0,0,1.4523933,0.0,0.78950274,123.65736,1.7114352,308.72537,-9.2945814
2243,2243,155.4184,21.522129,8.2159328,0.0,0,1.4247453,0.0,0.79323035,123.896,1.683863,308.28766,-9.294754
2245,2245,155.4188,21.65531,8.2533779,0.0,0,1.3970973,0.0,0.79756242,124.12654,1.6578432,307.84998,-9.2944698
2247,2247,155.4192,21.785198,8.2733488,0.0,0,1.3694494,0.0,0.80243623,124.27641,1.6289386,307.41226,-9.294632
2249,2249,155.4196,21.902534,8.3038645,0.0,0,1.3418013,0.0,0.80584735,124.52478,1.599701,306.97455,-9.2954826
2251,2251,155.42,21.998535,8.3414021,0.0,0,1.3141534,0.0,0.81112456,124.43901,1.5703037,306.53683,-9.2955551
2253,2253,155.4204,22.121807,8.3602667,0.0,0,1.2865053,0.0,0.81543684,124.58614,1.540884,306.09912,-9.2942648
2255,2255,155.4208,22.268593,8.3923397,0.0,0,1.2588574,0.0,0.81876874,124.99911,1.5136517,305.66144,-9.2944269
2257,2257,155.4212,22.41522,8.4248705,0.0,0,1.2312094,0.0,0.82440436,125.1201,1.4860473,305.22372,-9.2946301
2259,2259,155.4216,22.540178,8.4436684,0.0,0,1.2044513,0.0,0.82779056,125.34104,1.4580936,304.78601,-9.2957544
2261,2261,155.422,22.643824,8.4764957,0.0,0,1.1781524,0.0,0.83140177,125.50682,1.4291915,304.3483,-9.2959204
2263,2263,155.4224,22.782265,8.5046492,0.0,0,1.1518564,0.0,0.83722436,125.47658,1.4021248,303.91058,-9.2945862
2265,2265,155.4228,22.928373,8.531024,0.0,0,1.1255604,0.0,0.84066719,125.8698,1.3731545,303.6196,-9.2950583
2267,2267,155.4232,23.086275,8.5653696,0.0,0,1.0992644,0.0,0.84515655,126.19205,1.3448521,303.76859,-9.2939396
2269,2269,155.4236,23.207676,8.5895786,0.0,0,1.0729684,0.0,0.8506915,126.1534,1.3145632,303.91754,-9.2938938
2271,2271,155.424,23.336779,8.6181192,0.0,0,1.0466723,0.0,0.85367656,126.49138,1.2850039,304.06653,-9.2947817
2273,2273,155.4244,23.46846,8.6457863,0.0,0,1.0203763,0.0,0.85820967,126.62006,1.2597324,304.21552,-9.2941961
2275,2275,155.4248,23.616362,8.664607,0.0,0,0.99408036,0.0,0.86263222,126.81421,1.2317822,304.3645,-9.2946301
2277,2277,155.4252,23.774395,8.6994429,0.0,0,0.96778435,0.0,0.86600065,127.26029,1.2027893,304.51349,-9.2945919
2279,2279,155.4256,23.908594,8.724617,0.0,0,0.94148839,0.0,0.87108529,127.32537,1.1790302,304.66248,-9.2942543
2281,2281,155.426,24.033861,8.7491941,0.0,0,0.91519243,0.0,0.87537634,127.44828,1.1484821,304.81143,-9.2940836
2283,2283,155.4264,24.177837,8.7861376,0.0,0,0.88916051,0.0,0.87954158,127.66359,1.1230878,304.96042,-9.2932539
2285,2285,155.4268,24.347101,8.8042545,0.0,0,0.86408949,0.0,0.88452715,127.90529,1.0961442,305.10941,-9.2939014
2287,2287,155.4272,24.516983,8.8292685,0.0,0,0.83908135,0.0,0.88782233,128.41226,1.068873,305.25839,-9.2944117
2289,2289,155.4276,24.664627,8.866744,0.0,0,0.81407332,0.0,0.89288425,128.50807,1.0405539,305.40738,-9.294384
2291,2291,155.428,24.792633,8.8835039,0.0,0,0.78906536,0.0,0.89763969,128.56403,1.0135809,305.55637,-9.2942095
2293,2293,155.4284,24.936283,8.9116383,0.0,0,0.7640574,0.0,0.90056103,128.94009,0.9878844,305.70532,-9.2935276
2295,2295,155.4288,25.102942,8.9433355,0.0,0,0.73904938,0.0,0.90603316,129.1091,0.9603104,305.85431,-9.2931013
2297,2297,155.4292,25.283781,8.9599123,0.0,0,0.71404135,0.0,0.91016674,129.49153,0.93248057,306.0033,-9.2929258
2299,2299,155.4296,25.429392,8.9930773,0.0,0,0.68903339,0.0,0.91367167,129.79062,0.90449101,306.15228,-9.2930212
2301,2301,155.43,25.564741,9.0206451,0.0,0,0.66402543,0.0,0.91979665,129.66765,0.88352555,306.30127,-9.2939682
2303,2303,155.4304,25.726416,9.0417032,0.0,0,0.63901734,0.0,0.9231329,130.02574,0.85305512,306.45026,-9.2937603
2305,2305,155.4308,25.907772,9.0712223,0.0,0,0.61400938,0.0,0.92691737,130.47629,0.82883942,306.59921,-9.2924719
2307,2307,155.4312,26.073715,9.0935774,0.0,0,0.58900136,0.0,0.9326483,130.54442,0.80371654,306.7482,-9.291482
2309,2309,155.4316,26.199938,9.1183853,0.0,0,0.56478846,0.0,0.9354918,130.82788,0.77670956,306.89719,-9.2916174
2311,2311,155.432,26.338919,9.1453562,0.0,0,0.54098594,0.0,0.93995047,130.93655,0.7525962,307.04617,-9.2931662
2313,2313,155.4324,26.499949,9.1640453,0.0,0,0.51718587,0.0,0.94474804,131.11746,0.72525358,307.19516,-9.2939644
2315,2315,155.4328,26.692327,9.1928015,0.0,0,0.49338591,0.0,0.94762367,131.64449,0.70147389,307.38452,-9.2922163
2317,2317,155.4332,26.864101,9.2161827,0.0,0,0.4695859,0.0,0.95257163,131.87398,0.67518473,307.69501,-9.2907801
2319,2319,155.4336,26.989477,9.2361765,0.0,0,0.44578591,0.0,0.95687443,131.92647,0.64856791,308.00549,-9.291852
2321,2321,155.434,27.138191,9.2713938,0.0,0,0.42198589,0.0,0.96077907,132.12971,0.62670726,308.31601,-9.2929506
2323,2323,155.4344,27.306023,9.2901077,0.0,0,0.39818591,0.0,0.96605498,132.25781,0.60079986,308.6265,-9.2930803
2325,2325,155.4348,27.501873,9.3104658,0.0,0,0.37438589,0.0,0.96928859,132.7637,0.57479024,308.93698,-9.2929134
2327,2327,155.4352,27.67721,9.3422098,0.0,0,0.35058588,0.0,0.97352356,133.0215,0.55370021,309.24747,-9.2919321
2329,2329,155.4356,27.815386,9.3541002,0.0,0,0.32678592,0.0,0.97776091,133.15599,0.53199774,309.55798,-9.2914829
2331,2331,155.436,27.961082,9.3765068,0.0,0,0.30298588,0.0,0.98031515,133.51016,0.5076887,309.86847,-9.291379
2332,2332,155.4362,28.052172,9.3860855,0.0,0,0.29108587,0.0,0.98363435,133.47002,0.49547279,310.02371,-9.2916698