File: examples/hot axisymmetric compression example/data/03 trimmed data/testID_0143.csv
level_0,index,Time(sec),Force(kN),Jaw(mm),PowAngle(deg),Power(W),Pram,PTemp,Strain,Stress(MPa),Stroke(mm),TC1(C),wedge(mm)
2104,2104,178.7032,0.13591053,0.026852572,0.0,0,9.0922346,0.0,0.0015671256,1.6581799,10.11375,395.25552,-9.2656384
2106,2106,178.7036,2.2440124,0.051866949,0.0,0,9.0337067,0.0,0.0033286866,23.837675,10.033341,395.2543,-9.2641487
2108,2108,178.704,4.9732537,0.11809945,0.0,0,8.9751787,0.0,0.0074258014,60.74585,9.9830065,395.25311,-9.263319
2110,2110,178.7044,5.604177,0.17081104,0.0,0,8.9166508,0.0,0.010920446,70.053673,9.9122725,395.25189,-9.2599459
2112,2112,178.7048,5.8561554,0.31763175,0.0,0,8.8581219,0.0,0.020450082,73.249069,9.8205853,395.2507,-9.2590733
2114,2114,178.7052,5.8871808,0.41789082,0.0,0,8.7995939,0.0,0.027756009,72.167801,9.7238588,395.24948,-9.2605333
2116,2116,178.7056,6.4134865,0.49276227,0.0,0,8.7416534,0.0,0.032731459,78.942337,9.6203413,395.24826,-9.2606897
2118,2118,178.706,6.7114391,0.59732461,0.0,0,8.6858492,0.0,0.040242348,81.068802,9.5340824,395.24707,-9.2595167
2120,2120,178.7064,6.8731894,0.60030901,0.0,0,8.6301851,0.0,0.040619753,84.828362,9.4509554,395.24585,-9.2578926
2122,2122,178.7068,6.2518263,0.68237853,0.0,0,8.574522,0.0,0.045977995,75.935135,9.3916607,395.24466,-9.2592793
2124,2124,178.7072,7.0778928,0.74948776,0.0,0,8.518857,0.0,0.051024765,84.75753,9.326642,395.24344,-9.260911
2126,2126,178.7076,7.0941296,0.79130012,0.0,0,8.4631929,0.0,0.053485643,85.692329,9.2591267,395.24222,-9.2589741
2128,2128,178.708,7.1585369,0.900231,0.0,0,8.4075298,0.0,0.061469458,85.865189,9.185936,395.24103,-9.2590914
2130,2130,178.7084,6.8214841,0.97625262,0.0,0,8.3518648,0.0,0.066667072,81.448555,9.1054316,395.26666,-9.2593565
2132,2132,178.7088,7.1740437,1.0523185,0.0,0,8.2962017,0.0,0.072113097,84.483559,9.0266905,395.31015,-9.258297
2134,2134,178.7092,7.1496048,1.1083504,0.0,0,8.2405376,0.0,0.076708786,84.474121,8.949151,395.35367,-9.2584534
2136,2136,178.7096,7.2617078,1.1630371,0.0,0,8.1848736,0.0,0.079915278,85.026314,8.8888388,395.39719,-9.2580919
2138,2138,178.71,7.1148467,1.2274517,0.0,0,8.1292095,0.0,0.084980257,83.672615,8.8234692,395.44067,-9.2598982
2140,2140,178.7104,7.2655821,1.2751551,0.0,0,8.0735455,0.0,0.088628411,84.040527,8.7691669,395.48419,-9.2594395
2142,2142,178.7108,7.6482916,1.3441589,0.0,0,8.0196619,0.0,0.092894413,88.691841,8.7064438,395.52771,-9.2586184
2144,2144,178.7112,7.3557901,1.4258395,0.0,0,7.9666953,0.0,0.099500515,85.145454,8.6438341,395.57123,-9.2570295
2146,2146,178.7116,7.3580623,1.494807,0.0,0,7.9137359,0.0,0.10447919,84.462288,8.5735121,395.61472,-9.2575378
2148,2148,178.712,7.3181362,1.5640289,0.0,0,7.8607755,0.0,0.10935435,83.537346,8.5058327,395.65823,-9.2593222
2150,2150,178.7124,7.5281801,1.6037377,0.0,0,7.8078156,0.0,0.1130789,85.377785,8.4457493,395.70175,-9.2594328
2152,2152,178.7128,7.5635109,1.6441867,0.0,0,7.7548552,0.0,0.1154943,86.040611,8.3890371,395.74527,-9.2587252
2154,2154,178.7132,7.3882747,1.7157056,0.0,0,7.7018952,0.0,0.12094569,83.492043,8.3350897,395.78876,-9.258873
2156,2156,178.7136,7.5584836,1.750376,0.0,0,7.6489348,0.0,0.12409171,84.682762,8.2813921,395.83228,-9.2578487
2158,2158,178.714,7.7334609,1.8038816,0.0,0,7.5959754,0.0,0.12739657,86.631592,8.2262077,395.87579,-9.2571058
2160,2160,178.7144,7.6887465,1.8742211,0.0,0,7.543015,0.0,0.13318361,85.699944,8.1692057,395.91928,-9.2585278
2162,2162,178.7148,7.676743,1.9225612,0.0,0,7.4900556,0.0,0.13683695,85.410194,8.1125555,395.9628,-9.2580624
2164,2164,178.7152,7.6174173,1.9849712,0.0,0,7.4370952,0.0,0.14124145,84.234215,8.0539808,396.00632,-9.2586689
2166,2166,178.7156,7.7422872,2.0267885,0.0,0,7.3846664,0.0,0.14515767,85.115074,7.9994335,396.04984,-9.2594652
2168,2168,178.716,7.7852144,2.0764158,0.0,0,7.3341722,0.0,0.14848624,85.442802,7.9431882,396.09332,-9.2586317
2170,2170,178.7164,7.7431321,2.133065,0.0,0,7.2838039,0.0,0.15283884,84.558983,7.8980451,396.13684,-9.2590103
2172,2172,178.7168,7.7921095,2.1677539,0.0,0,7.2334356,0.0,0.15607327,84.74221,7.8498445,396.18036,-9.2592506
2174,2174,178.7172,7.9278631,2.2236152,0.0,0,7.1830673,0.0,0.15974365,85.962051,7.796525,396.22388,-9.2589159
2176,2176,178.7176,7.9301043,2.2795722,0.0,0,7.1326995,0.0,0.16439046,85.669662,7.7478247,396.26736,-9.2585306
2178,2178,178.718,7.8831692,2.3275468,0.0,0,7.0823312,0.0,0.16850804,84.78125,7.693768,396.31088,-9.2587757
2180,2180,178.7184,7.9270511,2.3872886,0.0,0,7.0319633,0.0,0.17266183,84.877663,7.6422544,396.30881,-9.258666
2182,2182,178.7188,8.0068913,2.4250073,0.0,0,6.981595,0.0,0.17616057,85.358894,7.5933323,396.28223,-9.2590828
2184,2184,178.7192,8.0318403,2.472069,0.0,0,6.9312277,0.0,0.17981607,85.506523,7.5462508,396.25562,-9.2594185
2186,2186,178.7196,7.9742489,2.5290058,0.0,0,6.8808594,0.0,0.18388546,84.599274,7.4991331,396.22903,-9.2600021
2188,2188,178.72,8.0424042,2.5625873,0.0,0,6.830492,0.0,0.18722649,84.730675,7.4483905,396.20242,-9.259716
2190,2190,178.7204,8.1801758,2.6130958,0.0,0,6.7801232,0.0,0.19096272,85.930687,7.4017735,396.17584,-9.2587461
2192,2192,178.7208,8.1582155,2.6715469,0.0,0,6.7313671,0.0,0.1954546,85.358353,7.352489,396.14923,-9.2585402
2194,2194,178.7212,8.1505136,2.7112846,0.0,0,6.6834416,0.0,0.19934496,85.00087,7.3035665,396.12265,-9.2589865
2196,2196,178.7216,8.1411629,2.760375,0.0,0,6.6355219,0.0,0.20284297,84.662773,7.2527447,396.09604,-9.2594976
2198,2198,178.722,8.2489758,2.8083301,0.0,0,6.5876017,0.0,0.20681663,85.238602,7.2041125,396.06946,-9.2592506
2200,2200,178.7224,8.303277,2.850575,0.0,0,6.5396819,0.0,0.21059974,85.615707,7.1600103,396.04285,-9.2593784
2202,2202,178.7228,8.2694073,2.8978937,0.0,0,6.4917622,0.0,0.21405278,85.036728,7.1096253,396.01627,-9.258749
2204,2204,178.7232,8.3296375,2.9447079,0.0,0,6.4438419,0.0,0.21826966,85.160141,7.0634685,395.98965,-9.259366
2206,2206,178.7236,8.3862495,2.9907782,0.0,0,6.3959212,0.0,0.2221853,85.396057,7.014719,395.96307,-9.2594271
2208,2208,178.724,8.4216385,3.0419867,0.0,0,6.3480015,0.0,0.22600317,85.543137,6.9654341,395.93646,-9.2588844
2210,2210,178.7244,8.457181,3.0908265,0.0,0,6.3000817,0.0,0.23059489,85.446289,6.9184642,395.90988,-9.2594185
2212,2212,178.7248,8.4615965,3.1362555,0.0,0,6.252162,0.0,0.23414764,85.204018,6.8706841,395.88327,-9.25879
2214,2214,178.7252,8.5042715,3.1808672,0.0,0,6.2042422,0.0,0.23778807,85.347191,6.8235297,395.85669,-9.2582531
2216,2216,178.7256,8.5238829,3.226397,0.0,0,6.1568027,0.0,0.24222152,85.144882,6.7746878,395.83008,-9.2595692
2218,2218,178.726,8.5547056,3.2739201,0.0,0,6.1111121,0.0,0.24567169,85.137344,6.7321658,395.8035,-9.2602167
2220,2220,178.7264,8.6149483,3.319783,0.0,0,6.065536,0.0,0.24970233,85.422424,6.6821585,395.77689,-9.259264
2222,2222,178.7268,8.6645889,3.3643241,0.0,0,6.0199599,0.0,0.25399768,85.577034,6.6347942,395.75031,-9.2586832
2224,2224,178.7272,8.6637316,3.4172273,0.0,0,5.9743834,0.0,0.25769547,85.334648,6.5877752,395.72369,-9.2585096
2226,2226,178.7276,8.6633205,3.4609272,0.0,0,5.9288077,0.0,0.26201352,84.923065,6.5413198,395.69711,-9.2595701
2228,2228,178.728,8.7478552,3.5040331,0.0,0,5.8832321,0.0,0.26585999,85.281334,6.4936275,395.6705,-9.2594357
2230,2230,178.7284,8.8125906,3.5587184,0.0,0,5.8376555,0.0,0.26988918,85.548698,6.4482689,395.42978,-9.2589912
2232,2232,178.7288,8.8285923,3.601383,0.0,0,5.792079,0.0,0.27439368,85.457298,6.4015245,395.09729,-9.2595949
2234,2234,178.7292,8.8281221,3.6478341,0.0,0,5.7465038,0.0,0.2781921,85.105034,6.3548412,394.7648,-9.2602301
2236,2236,178.7296,8.872159,3.7026391,0.0,0,5.7009277,0.0,0.28267893,85.102066,6.305769,394.43231,-9.2598305
2238,2238,178.73,8.9514685,3.7417226,0.0,0,5.6553516,0.0,0.28685182,85.523338,6.256577,394.09982,-9.2591629
2240,2240,178.7304,9.0033321,3.7887454,0.0,0,5.6097755,0.0,0.29046336,85.704094,6.2072148,393.76733,-9.2586985
2242,2242,178.7308,9.0003233,3.845155,0.0,0,5.5656581,0.0,0.29557553,85.238129,6.1604524,393.43484,-9.2589397
2244,2244,178.7312,9.0131102,3.8857987,0.0,0,5.5222936,0.0,0.29979196,84.956642,6.1123128,393.10236,-9.2599154
2246,2246,178.7316,9.0775051,3.9363463,0.0,0,5.4789333,0.0,0.30362156,85.222672,6.064846,392.76987,-9.2592659
2248,2248,178.732,9.1368561,3.9877903,0.0,0,5.4355736,0.0,0.30865377,85.424454,6.0163336,392.43738,-9.2600155
2250,2250,178.7324,9.168293,4.0288234,0.0,0,5.3922133,0.0,0.31260329,85.414642,5.9679255,392.10489,-9.2600403
2252,2252,178.7328,9.179554,4.0794702,0.0,0,5.3488536,0.0,0.31660557,85.086975,5.9197598,391.7724,-9.2594872
2254,2254,178.7332,9.2052765,4.1255403,0.0,0,5.3054934,0.0,0.32146928,84.957481,5.8725834,391.43988,-9.2579689
2256,2256,178.7336,9.2702007,4.1707706,0.0,0,5.2621331,0.0,0.32532373,85.203163,5.8235745,391.10739,-9.25877
2258,2258,178.734,9.3098984,4.222033,0.0,0,5.2187734,0.0,0.32981375,85.201004,5.7766924,390.7749,-9.2594395
2260,2260,178.7344,9.3626852,4.2662416,0.0,0,5.1754136,0.0,0.33466905,85.196571,5.7283301,390.44241,-9.2593908
2262,2262,178.7348,9.3803768,4.3165469,0.0,0,5.1320534,0.0,0.33860311,85.144836,5.6797042,390.10992,-9.2593584
2264,2264,178.7352,9.406023,4.3620028,0.0,0,5.0886931,0.0,0.34300163,84.956825,5.6331615,389.77744,-9.2586718
2266,2266,178.7356,9.4492188,4.4047132,0.0,0,5.0457683,0.0,0.34763196,84.986076,5.5863838,389.44495,-9.2585049
2268,2268,178.736,9.5103407,4.4566669,0.0,0,5.0044241,0.0,0.35169294,85.145248,5.5390587,389.11246,-9.2593365
2270,2270,178.7364,9.541584,4.4985266,0.0,0,4.9631839,0.0,0.3562071,85.042686,5.4929638,388.77997,-9.2586794
2272,2272,178.7368,9.5613117,4.5406752,0.0,0,4.9219441,0.0,0.36043009,84.875343,5.4457412,388.44748,-9.2584801
2274,2274,178.7372,9.5756207,4.5945449,0.0,0,4.8807039,0.0,0.36465773,84.688896,5.4010162,388.11499,-9.2591057
2276,2276,178.7376,9.6437359,4.6357093,0.0,0,4.8394642,0.0,0.3694852,84.780212,5.3567333,387.7825,-9.2579536
2278,2278,178.738,9.7130098,4.6805673,0.0,0,4.798224,0.0,0.37368101,85.09597,5.3112621,387.45001,-9.2589693
2280,2280,178.7384,9.7376871,4.735146,0.0,0,4.7569842,0.0,0.37835464,84.929413,5.2642975,386.92191,-9.2596006
2282,2282,178.7388,9.7665787,4.7722235,0.0,0,4.715744,0.0,0.38290742,84.756149,5.2187638,386.32864,-9.2600288
2284,2284,178.7392,9.7920942,4.8177352,0.0,0,4.6745043,0.0,0.38688716,84.712662,5.1706262,385.73535,-9.2599506
2286,2286,178.7396,9.8505211,4.8685794,0.0,0,4.6332641,0.0,0.39169189,84.735245,5.1261802,385.14209,-9.2594433
2288,2288,178.74,9.9093723,4.907846,0.0,0,4.5920238,0.0,0.3961851,84.769997,5.081862,384.5488,-9.2595682
2290,2290,178.7404,9.9334545,4.9567504,0.0,0,4.5507841,0.0,0.40030029,84.694511,5.0366573,383.95554,-9.2592373
2292,2292,178.7408,9.9593763,5.0053301,0.0,0,4.5108657,0.0,0.40554118,84.453087,4.99261,383.36224,-9.2593737
2294,2294,178.7412,9.9832115,5.0446692,0.0,0,4.4716296,0.0,0.40972328,84.34491,4.9474139,382.76898,-9.2601643
2296,2296,178.7416,10.034413,5.089869,0.0,0,4.4323978,0.0,0.41365483,84.47821,4.90346,382.17569,-9.2594347
2298,2298,178.742,10.087618,5.1336951,0.0,0,4.3931656,0.0,0.41883022,84.484085,4.8606701,381.58243,-9.2589531
2300,2300,178.7424,10.138528,5.1730847,0.0,0,4.3539338,0.0,0.42255324,84.555023,4.8153477,380.98914,-9.2584743
2302,2302,178.7428,10.16398,5.2207112,0.0,0,4.314702,0.0,0.42700607,84.441727,4.7713461,380.39587,-9.2572994
2304,2304,178.7432,10.192187,5.2621861,0.0,0,4.2754698,0.0,0.43214923,84.229912,4.730165,379.80258,-9.2586193
2306,2306,178.7436,10.252347,5.3059621,0.0,0,4.2362375,0.0,0.4359372,84.340851,4.6837745,379.20932,-9.2594481
2308,2308,178.744,10.312185,5.348846,0.0,0,4.1970053,0.0,0.44034755,84.504875,4.6411362,378.61603,-9.2595482
2310,2310,178.7444,10.348422,5.3858819,0.0,0,4.1577735,0.0,0.44499665,84.418488,4.6005664,378.02277,-9.2587862
2312,2312,178.7448,10.364152,5.4350452,0.0,0,4.1185417,0.0,0.44902331,84.175682,4.5578141,377.42947,-9.258234
2314,2314,178.7452,10.398704,5.4756908,0.0,0,4.0793095,0.0,0.4538618,84.055298,4.5129328,376.83621,-9.258606
2316,2316,178.7456,10.451297,5.5139022,0.0,0,4.0404716,0.0,0.45822716,84.16021,4.4729056,376.24292,-9.257946
2318,2318,178.746,10.508549,5.562139,0.0,0,4.0030656,0.0,0.46227795,84.260201,4.4309483,375.64966,-9.258584
2320,2320,178.7464,10.558542,5.5960083,0.0,0,3.9657533,0.0,0.46674648,84.237946,4.3884697,375.05637,-9.2588053
2322,2322,178.7468,10.574763,5.6347337,0.0,0,3.9284413,0.0,0.47074535,84.07692,4.3468013,374.4631,-9.2585211
2324,2324,178.7472,10.601468,5.6832657,0.0,0,3.8911293,0.0,0.47522196,83.920258,4.3043571,373.86981,-9.2585516
2326,2326,178.7476,10.65982,5.7153859,0.0,0,3.8538175,0.0,0.47974291,83.969719,4.2664981,373.27652,-9.2586689
2328,2328,178.748,10.741591,5.7566161,0.0,0,3.8165054,0.0,0.48359162,84.252457,4.2274804,372.68326,-9.2590389
2330,2330,178.7484,10.762524,5.8041015,0.0,0,3.7791932,0.0,0.48844972,84.094398,4.1898484,372.16483,-9.2588911
2332,2332,178.7488,10.783298,5.835146,0.0,0,3.7418811,0.0,0.49271712,83.834389,4.14783,371.6651,-9.2581406
2334,2334,178.7492,10.829594,5.87501,0.0,0,3.7045693,0.0,0.49623141,83.911873,4.1085963,371.16537,-9.2590322
2336,2336,178.7496,10.909001,5.9186082,0.0,0,3.6672573,0.0,0.50124347,84.038002,4.071939,370.66568,-9.258544
2338,2338,178.75,10.958789,5.9500604,0.0,0,3.6299453,0.0,0.50524402,84.162392,4.0306087,370.16595,-9.2593708
2340,2340,178.7504,10.995233,5.9937601,0.0,0,3.5926332,0.0,0.5091821,84.141068,3.99229,369.66623,-9.2586498
2342,2342,178.7508,11.015442,6.0339165,0.0,0,3.5565166,0.0,0.5143767,83.848808,3.9482462,369.1665,-9.2573357
2344,2344,178.7512,11.06016,6.0669718,0.0,0,3.5210168,0.0,0.51805264,83.87722,3.9164646,368.66678,-9.2585258
2346,2346,178.7516,11.145169,6.1074004,0.0,0,3.4855206,0.0,0.52201223,84.101006,3.8768837,368.16705,-9.258769
2348,2348,178.752,11.196854,6.144114,0.0,0,3.4500248,0.0,0.52710003,84.149727,3.8374016,367.66733,-9.259613
2350,2350,178.7524,11.20516,6.1829333,0.0,0,3.4145288,0.0,0.5307951,83.883461,3.8040664,367.1676,-9.2591343
2352,2352,178.7528,11.243414,6.2248478,0.0,0,3.3790326,0.0,0.53539979,83.776123,3.7654777,366.66791,-9.2577162
2354,2354,178.7532,11.310415,6.2580681,0.0,0,3.3435369,0.0,0.54009712,83.843674,3.7305918,366.16818,-9.2579327
2356,2356,178.7536,11.376888,6.2960062,0.0,0,3.3080409,0.0,0.5434444,84.110336,3.6912429,365.66846,-9.258213
2358,2358,178.754,11.415022,6.330739,0.0,0,3.2725446,0.0,0.54788804,84.02224,3.6502736,365.16873,-9.2580824
2360,2360,178.7544,11.460011,6.3626504,0.0,0,3.2370486,0.0,0.55214781,84.002602,3.6173503,364.66901,-9.2586269
2362,2362,178.7548,11.508285,6.4091105,0.0,0,3.2015526,0.0,0.55616021,83.966782,3.5803151,364.16928,-9.2578945
2364,2364,178.7552,11.561522,6.4430699,0.0,0,3.1660566,0.0,0.56106955,83.946556,3.5434155,363.66956,-9.25809
2366,2366,178.7556,11.623982,6.4766402,0.0,0,3.1309152,0.0,0.56496066,84.068214,3.5030935,363.16983,-9.2577448
2368,2368,178.756,11.685492,6.5191803,0.0,0,3.0970623,0.0,0.56916451,84.20607,3.4675186,362.67014,-9.2571793
2370,2370,178.7564,11.728062,6.5466404,0.0,0,3.0632944,0.0,0.5735178,84.094643,3.4292064,362.17041,-9.2589016
2372,2372,178.7568,11.761429,6.5813122,0.0,0,3.0295265,0.0,0.57712471,84.071579,3.3926764,361.67068,-9.2585735
2374,2374,178.7572,11.83155,6.6276798,0.0,0,2.9957583,0.0,0.5820927,84.100754,3.3590267,361.17096,-9.2579641
2376,2376,178.7576,11.905659,6.6543941,0.0,0,2.9619906,0.0,0.58658075,84.27372,3.3263307,360.67123,-9.2573786
2378,2378,178.758,11.975874,6.6919804,0.0,0,2.9282222,0.0,0.58998245,84.493118,3.286756,360.17151,-9.2575026
2380,2380,178.7584,12.000839,6.7318497,0.0,0,2.8944542,0.0,0.59506458,84.254288,3.2525361,359.7804,-9.2578707
2382,2382,178.7588,12.054117,6.7591147,0.0,0,2.8606863,0.0,0.598975,84.250557,3.2172654,359.40845,-9.2570152
2384,2384,178.7592,12.11551,6.799686,0.0,0,2.8269184,0.0,0.60283619,84.347069,3.1839182,359.0365,-9.2578316
2386,2386,178.7596,12.198811,6.8364105,0.0,0,2.7931502,0.0,0.60819793,84.533524,3.1500909,358.66455,-9.2597198
2388,2388,178.76,12.251677,6.8652744,0.0,0,2.7593822,0.0,0.61175871,84.596443,3.1179035,358.2926,-9.257288
2390,2390,178.7604,12.293481,6.9037604,0.0,0,2.7256143,0.0,0.61583209,84.495605,3.0827169,357.92065,-9.2569418
2392,2392,178.7608,12.340849,6.9370251,0.0,0,2.6929309,0.0,0.62095088,84.402779,3.0444949,357.54871,-9.2574606
2394,2394,178.7612,12.411038,6.9700346,0.0,0,2.6608074,0.0,0.62433505,84.568748,3.0133786,357.17676,-9.2578545
2396,2396,178.7616,12.499801,7.0076103,0.0,0,2.6286874,0.0,0.6289382,84.801949,2.9783685,356.80481,-9.2578163
2398,2398,178.762,12.556847,7.0394726,0.0,0,2.5965672,0.0,0.63384688,84.81057,2.942342,356.43286,-9.2574921
2400,2400,178.7624,12.604875,7.0773106,0.0,0,2.5644474,0.0,0.63738525,84.807594,2.9070539,356.06088,-9.257062
2402,2402,178.7628,12.666077,7.1122441,0.0,0,2.5323272,0.0,0.64219582,84.788757,2.8730109,355.68893,-9.2571239
2404,2404,178.7632,12.740947,7.1397195,0.0,0,2.5002072,0.0,0.64657116,84.929527,2.8377461,355.31699,-9.2573662
2406,2406,178.7636,12.835055,7.1816649,0.0,0,2.4680872,0.0,0.65040714,85.200035,2.8043635,354.94504,-9.2575197
2408,2408,178.764,12.905334,7.2121439,0.0,0,2.4359674,0.0,0.65531135,85.277977,2.7701929,354.57309,-9.2572756
2410,2410,178.7644,12.956738,7.2435174,0.0,0,2.4038472,0.0,0.65948105,85.246033,2.7335229,354.20114,-9.2583818
2412,2412,178.7648,13.017118,7.2869277,0.0,0,2.3717272,0.0,0.66384506,85.291214,2.6998038,353.82919,-9.2584381
2414,2414,178.7652,13.095934,7.3146343,0.0,0,2.3396072,0.0,0.66882092,85.380714,2.6653666,353.45724,-9.2566996
2416,2416,178.7656,13.204463,7.3478403,0.0,0,2.3078089,0.0,0.67255318,85.73674,2.6304197,353.0853,-9.2565708
2418,2418,178.766,13.268116,7.3908782,0.0,0,2.2771804,0.0,0.67754233,85.765587,2.5981803,352.71335,-9.2554045
2420,2420,178.7664,13.316802,7.4169307,0.0,0,2.246628,0.0,0.68238115,85.659264,2.5651722,352.34137,-9.2562847
2422,2422,178.7668,13.379766,7.451992,0.0,0,2.2160764,0.0,0.685983,85.730957,2.5338945,351.96942,-9.2573614
2424,2424,178.7672,13.460683,7.4911861,0.0,0,2.1855242,0.0,0.69122666,85.793968,2.4952269,351.59747,-9.257822
2426,2426,178.7676,13.572949,7.5162954,0.0,0,2.1549723,0.0,0.69558471,86.13726,2.4626122,351.22552,-9.2567043
2428,2428,178.768,13.632801,7.5549436,0.0,0,2.1244202,0.0,0.69939977,86.225403,2.4290204,350.85358,-9.2561569
2430,2430,178.7684,13.682165,7.5905004,0.0,0,2.0938683,0.0,0.70519209,86.036987,2.3954031,350.29446,-9.2560959
2432,2432,178.7688,13.751842,7.6177235,0.0,0,2.0633163,0.0,0.70893782,86.174156,2.3622303,349.71454,-9.2568693
2434,2434,178.7692,13.84233,7.6548443,0.0,0,2.0327644,0.0,0.71294093,86.348625,2.3276346,349.13461,-9.2563133
2436,2436,178.7696,13.954132,7.6861339,0.0,0,2.0022123,0.0,0.71843517,86.583832,2.2957926,348.55472,-9.2559414
2438,2438,178.77,14.015668,7.7172723,0.0,0,1.9716601,0.0,0.72211057,86.673027,2.2623768,347.97479,-9.2568684
2440,2440,178.7704,14.070989,7.7533965,0.0,0,1.9411081,0.0,0.72643578,86.56617,2.22961,347.39487,-9.2567959
2442,2442,178.7708,14.138835,7.7825365,0.0,0,1.9115355,0.0,0.73183846,86.561523,2.1991067,346.81497,-9.2566233
2444,2444,178.7712,14.251122,7.8188663,0.0,0,1.8824685,0.0,0.73561978,86.882774,2.1644263,346.23505,-9.2567596
2446,2446,178.7716,14.349546,7.851181,0.0,0,1.8534043,0.0,0.7404955,87.064156,2.1298022,345.65512,-9.2561646
2448,2448,178.772,14.400675,7.8771391,0.0,0,1.8243403,0.0,0.74518394,87.006042,2.0994291,345.07523,-9.2555008
2450,2450,178.7724,14.44885,7.9153633,0.0,0,1.7952764,0.0,0.74892944,86.966064,2.0672643,344.4953,-9.255827
2452,2452,178.7728,14.537847,7.9427824,0.0,0,1.7662123,0.0,0.75377852,87.021812,2.0374527,343.91537,-9.2572241
2454,2454,178.7732,14.651127,7.9698343,0.0,0,1.7371484,0.0,0.75785893,87.375038,2.007571,343.33548,-9.2567167
2456,2456,178.7736,14.732725,8.0112486,0.0,0,1.7080843,0.0,0.76219779,87.500229,1.9748286,342.75555,-9.2555637
2458,2458,178.774,14.80388,8.0354147,0.0,0,1.6790204,0.0,0.76729566,87.459381,1.9473344,342.17563,-9.2545109
2460,2460,178.7744,14.870378,8.0652895,0.0,0,1.6499563,0.0,0.77112335,87.508194,1.9163439,341.59573,-9.2552061
2462,2462,178.7748,14.955606,8.1026697,0.0,0,1.6208923,0.0,0.77575129,87.628387,1.8820648,341.01581,-9.256217
2464,2464,178.7752,15.068161,8.1244612,0.0,0,1.5918283,0.0,0.78052145,87.850494,1.8532611,340.43591,-9.2563114
2466,2466,178.7756,15.148449,8.155715,0.0,0,1.5630548,0.0,0.78379762,88.062347,1.8253641,339.85599,-9.2558985
2468,2468,178.776,15.226792,8.1930561,0.0,0,1.5353373,0.0,0.78913444,88.038048,1.7931772,339.27606,-9.2559195
2470,2470,178.7764,15.300573,8.2129078,0.0,0,1.5076892,0.0,0.79332703,88.073074,1.7654605,338.69617,-9.2557116
2472,2472,178.7768,15.385717,8.2465973,0.0,0,1.4800413,0.0,0.79684734,88.267921,1.7359889,338.11624,-9.2541504
2474,2474,178.7772,15.493406,8.280714,0.0,0,1.4523933,0.0,0.80282724,88.350006,1.7057096,337.53632,-9.2550478
2476,2476,178.7776,15.612204,8.3035412,0.0,0,1.4247453,0.0,0.80656773,88.659447,1.6749763,336.95642,-9.2554569
2478,2478,178.778,15.684915,8.3361664,0.0,0,1.3970973,0.0,0.81017733,88.746109,1.6448609,336.3765,-9.2548876
2480,2480,178.7784,15.7638,8.3632965,0.0,0,1.3694494,0.0,0.81564522,88.753784,1.61875,336.3082,-9.2550535
2482,2482,178.7788,15.855324,8.3891363,0.0,0,1.3418013,0.0,0.81894404,88.937439,1.5883693,336.26678,-9.2553596
2484,2484,178.7792,15.976054,8.4219208,0.0,0,1.3141534,0.0,0.82334453,89.246414,1.5604085,336.22537,-9.2549133
2486,2486,178.7796,16.071495,8.4480848,0.0,0,1.2865053,0.0,0.82877672,89.276917,1.5320762,336.18396,-9.2543793
2488,2488,178.78,16.1399,8.4794941,0.0,0,1.2588574,0.0,0.83223248,89.382057,1.500494,336.14255,-9.254735
2490,2490,178.7804,16.238802,8.5107298,0.0,0,1.2312094,0.0,0.83718127,89.467552,1.4720142,336.10117,-9.2545233
2492,2492,178.7808,16.335087,8.5318871,0.0,0,1.2044513,0.0,0.84173799,89.575607,1.4448106,336.05975,-9.2540741
2494,2494,178.7812,16.45615,8.5643578,0.0,0,1.1781524,0.0,0.84493929,89.944542,1.4171616,336.01834,-9.254405
2496,2496,178.7816,16.574009,8.5894299,0.0,0,1.1518564,0.0,0.84976536,90.148903,1.3865159,335.97693,-9.2545891
2498,2498,178.782,16.661295,8.6127739,0.0,0,1.1255604,0.0,0.85387295,90.298927,1.359666,335.93552,-9.2547512
2500,2500,178.7824,16.756947,8.6520367,0.0,0,1.0992644,0.0,0.85812902,90.415283,1.3308578,335.8941,-9.2552757
2502,2502,178.7828,16.869261,8.6742001,0.0,0,1.0729684,0.0,0.86355507,90.507523,1.3054667,335.85269,-9.2554073
2504,2504,178.7832,16.989447,8.6990318,0.0,0,1.0466723,0.0,0.86715144,90.832809,1.2730482,335.81128,-9.2541752
2506,2506,178.7836,17.120995,8.7336521,0.0,0,1.0203763,0.0,0.8715148,91.141365,1.2463048,335.7699,-9.2538738
2508,2508,178.784,17.199291,8.7507191,0.0,0,0.99408036,0.0,0.87599289,91.183548,1.2182313,335.72849,-9.2535658
2510,2510,178.7844,17.293865,8.7784929,0.0,0,0.96778435,0.0,0.879233,91.33564,1.1918098,335.68707,-9.2546625
2512,2512,178.7848,17.410635,8.8170681,0.0,0,0.94148839,0.0,0.88512808,91.42469,1.1657525,335.64566,-9.2546806
2514,2514,178.7852,17.564594,8.8370066,0.0,0,0.91519243,0.0,0.88993967,91.738792,1.1378379,335.60425,-9.2545376
2516,2516,178.7856,17.684801,8.8663549,0.0,0,0.88916051,0.0,0.89297396,92.114403,1.1081825,335.56284,-9.2541428
2518,2518,178.786,17.769032,8.8941603,0.0,0,0.86408949,0.0,0.89840704,92.103317,1.0800579,335.52142,-9.2534323
2520,2520,178.7864,17.870144,8.9110117,0.0,0,0.83908135,0.0,0.9018361,92.332672,1.0547609,335.48001,-9.2541771
2522,2522,178.7868,18.001381,8.9438629,0.0,0,0.81407332,0.0,0.90561861,92.584038,1.0290455,335.43863,-9.2538786
2524,2524,178.7872,18.155556,8.9722481,0.0,0,0.78906536,0.0,0.91185713,92.792839,1.0009395,335.39722,-9.2535124
2526,2526,178.7876,18.283663,8.9973774,0.0,0,0.7640574,0.0,0.91557735,93.128403,0.97219366,335.3558,-9.2529373
2528,2528,178.788,18.396196,9.0285501,0.0,0,0.73904938,0.0,0.9199478,93.276169,0.94454592,335.31442,-9.2532845
2530,2530,178.7884,18.493698,9.049284,0.0,0,0.71404135,0.0,0.92526025,93.31237,0.91627121,335.83603,-9.2534294
2532,2532,178.7888,18.645817,9.0744715,0.0,0,0.68903339,0.0,0.92809474,93.757629,0.89132529,336.35764,-9.2533512
2534,2534,178.7892,18.812153,9.1034517,0.0,0,0.66402543,0.0,0.93269235,94.205391,0.86615294,336.87927,-9.2534046
2536,2536,178.7896,18.929262,9.1256514,0.0,0,0.63901734,0.0,0.93807244,94.256203,0.83799779,337.40088,-9.2533503
2538,2538,178.79,19.030834,9.1596165,0.0,0,0.61400938,0.0,0.94199824,94.423645,0.81180769,337.92249,-9.2530069
2540,2540,178.7904,19.151556,9.1844721,0.0,0,0.58900136,0.0,0.94699627,94.531754,0.78764427,338.44409,-9.2533875
2542,2542,178.7908,19.294996,9.2024527,0.0,0,0.56478846,0.0,0.95120293,94.819618,0.75955498,338.9657,-9.2519588
2544,2544,178.7912,19.457239,9.2370825,0.0,0,0.54098594,0.0,0.95491683,95.245522,0.73465091,339.4873,-9.2523775
2546,2546,178.7916,19.578884,9.2575121,0.0,0,0.51718587,0.0,0.96004307,95.347878,0.7074784,340.00894,-9.2532272
2548,2548,178.792,19.677319,9.2812471,0.0,0,0.49338591,0.0,0.96412194,95.475395,0.68147075,340.53055,-9.2532349
2550,2550,178.7924,19.813173,9.3157148,0.0,0,0.4695859,0.0,0.96878517,95.671501,0.65474093,341.05215,-9.2525778
2552,2552,178.7928,19.958094,9.3324451,0.0,0,0.44578591,0.0,0.97384787,95.915657,0.62939209,341.57376,-9.2516985
2554,2554,178.7932,20.10977,9.3548555,0.0,0,0.42198589,0.0,0.97666061,96.366631,0.60571742,342.09537,-9.252492
2556,2556,178.7936,20.236414,9.3867683,0.0,0,0.39818591,0.0,0.98171741,96.500313,0.57793403,342.617,-9.2538071
2558,2558,178.794,20.352856,9.402277,0.0,0,0.37438589,0.0,0.9863174,96.577385,0.55119634,343.13861,-9.2525034