File: examples/hot axisymmetric compression example/data/03 trimmed data/testID_0146.csv
level_0,index,Time(sec),Force(kN),Jaw(mm),PowAngle(deg),Power(W),Pram,PTemp,Strain,Stress(MPa),Stroke(mm),TC1(C),wedge(mm)
2438,2438,212.0228,0.45978087,0.088185161,0.0,0,9.0922346,0.0,0.0058085644,5.1843791,10.141538,502.88791,-9.2086935
2439,2439,212.023,1.4044549,0.10342281,0.0,0,9.0629702,0.0,0.0064606895,14.65673,10.10292,502.98697,-9.2084723
2440,2440,212.0232,2.8678088,0.12922996,0.0,0,9.0337067,0.0,0.0084299166,32.449268,10.0713,503.08603,-9.2085485
2441,2441,212.0234,3.9029236,0.16914169,0.0,0,9.0044422,0.0,0.01086496,47.047642,10.044653,503.18509,-9.2083578
2442,2442,212.0236,4.355937,0.20228878,0.0,0,8.9751787,0.0,0.013023217,53.897099,10.016842,503.28415,-9.2067146
2443,2443,212.0238,4.5132227,0.22852725,0.0,0,8.9459143,0.0,0.015099088,56.402004,9.9784212,503.38321,-9.204567
2444,2444,212.024,4.5850811,0.28534612,0.0,0,8.9166508,0.0,0.018342223,57.265026,9.9293575,503.48227,-9.2037163
2445,2445,212.0242,4.474535,0.3728416,0.0,0,8.8873863,0.0,0.023682496,56.135426,9.8790751,503.58133,-9.2036695
2446,2446,212.0244,4.2007275,0.45501149,0.0,0,8.8581219,0.0,0.029861057,52.614498,9.829237,503.68039,-9.2036572
2447,2447,212.0246,4.1323729,0.5195902,0.0,0,8.8288584,0.0,0.034569256,50.681702,9.7726555,503.77945,-9.2038555
2448,2448,212.0248,4.4508109,0.56700265,0.0,0,8.7995939,0.0,0.037605017,53.676464,9.7101793,503.87851,-9.204071
2449,2449,212.025,4.6085997,0.61243987,0.0,0,8.7703304,0.0,0.04098279,56.261299,9.6465654,503.97757,-9.20432
2450,2450,212.0252,4.4671545,0.68613338,0.0,0,8.7416534,0.0,0.045865253,54.801064,9.5870266,504.0766,-9.2051239
2451,2451,212.0254,4.5484476,0.75924349,0.0,0,8.7136879,0.0,0.050707299,54.5769,9.533906,504.17566,-9.2053146
2452,2452,212.0256,4.8809323,0.78728914,0.0,0,8.6858492,0.0,0.053599607,58.127056,9.481637,504.27472,-9.2047558
2453,2453,212.0258,4.9011159,0.79695606,0.0,0,8.6580172,0.0,0.054693516,59.346428,9.4314203,504.37378,-9.2046757
2454,2454,212.026,4.4941068,0.81721109,0.0,0,8.6301851,0.0,0.055435494,55.179615,9.3855495,504.47284,-9.2044449
2455,2455,212.0262,4.1888175,0.84853506,0.0,0,8.6023531,0.0,0.057593234,50.720005,9.342865,504.5719,-9.2041092
2456,2456,212.0264,4.3477216,0.89556164,0.0,0,8.574522,0.0,0.061149538,51.381294,9.2999363,504.67096,-9.2044697
2457,2457,212.0266,4.7244782,0.93141627,0.0,0,8.546689,0.0,0.0635539,55.561253,9.2591267,504.77002,-9.2044039
2458,2458,212.0268,4.9412246,0.93846053,0.0,0,8.518857,0.0,0.064379238,58.609047,9.2209654,504.76465,-9.2040319
2459,2459,212.027,4.9885736,0.96042103,0.0,0,8.4910259,0.0,0.065996945,59.327511,9.1810608,504.75928,-9.2038717
2460,2460,212.0272,5.0555577,1.0148721,0.0,0,8.4631929,0.0,0.069096476,59.814976,9.1416817,504.75391,-9.2036943
2461,2461,212.0274,5.0957489,1.0736358,0.0,0,8.4353609,0.0,0.073254272,60.310089,9.1039534,504.74854,-9.2043238
2462,2462,212.0276,4.9149542,1.1302093,0.0,0,8.4075298,0.0,0.07781478,58.42783,9.0616617,504.74316,-9.2044754
2463,2463,212.0278,4.6893969,1.1783458,0.0,0,8.3796968,0.0,0.081028201,55.482883,9.0168333,504.73779,-9.204607
2464,2464,212.028,4.67312,1.2132306,0.0,0,8.3518648,0.0,0.083533861,54.561737,8.9723167,504.73242,-9.2051172
2465,2465,212.0282,4.8078485,1.2586331,0.0,0,8.3240337,0.0,0.087193288,55.716965,8.9267206,504.72705,-9.2050962
2466,2466,212.0284,4.9025965,1.3119072,0.0,0,8.2962017,0.0,0.09081313,56.855598,8.8809004,504.72168,-9.205143
2467,2467,212.0286,4.8612518,1.3455467,0.0,0,8.2683697,0.0,0.093275733,56.521572,8.8403568,504.71631,-9.204443
2468,2468,212.0288,4.8102117,1.3704516,0.0,0,8.2405376,0.0,0.09560819,55.733219,8.8006716,504.71094,-9.203867
2469,2469,212.029,4.8647766,1.4019378,0.0,0,8.2127056,0.0,0.097728878,56.046585,8.7582531,504.70557,-9.2038412
2470,2470,212.0292,4.9056778,1.4321011,0.0,0,8.1848736,0.0,0.099617071,56.57777,8.7225599,504.70016,-9.2039347
2471,2471,212.0294,4.8169422,1.4646423,0.0,0,8.1570415,0.0,0.10242762,55.728123,8.692091,504.69479,-9.2038498
2472,2472,212.0296,4.6784902,1.495679,0.0,0,8.1292095,0.0,0.10479677,54.03093,8.6611557,504.68942,-9.203311
2473,2473,212.0298,4.6852074,1.5150465,0.0,0,8.1013775,0.0,0.10595848,53.563198,8.6303148,504.68405,-9.2039099
2474,2474,212.03,4.8620505,1.5364014,0.0,0,8.0735455,0.0,0.10783181,55.082378,8.6035891,504.67868,-9.2047853
2475,2475,212.0302,5.0488582,1.5691364,0.0,0,8.0462685,0.0,0.11020971,57.251556,8.5779619,504.67331,-9.2044678
2476,2476,212.0304,5.1354508,1.6034431,0.0,0,8.0196619,0.0,0.11231621,58.419334,8.549448,504.66794,-9.2039661
2477,2477,212.0306,5.1007948,1.6369396,0.0,0,7.993176,0.0,0.11507009,58.056953,8.5184402,504.66257,-9.2039175
2478,2478,212.0308,4.9905348,1.6712703,0.0,0,7.9666953,0.0,0.11786128,56.758636,8.4881763,504.6572,-9.2037802
2479,2479,212.031,4.9160528,1.7037681,0.0,0,7.9402156,0.0,0.11998911,55.656021,8.4583359,504.65182,-9.2036219
2480,2480,212.0312,4.9102387,1.7361075,0.0,0,7.9137359,0.0,0.12258619,55.287033,8.4258118,504.64645,-9.2036552
2481,2481,212.0314,4.9178252,1.7695771,0.0,0,7.8872557,0.0,0.12533753,55.247921,8.3945808,504.64108,-9.2039576
2482,2482,212.0316,4.9230499,1.8000402,0.0,0,7.8607755,0.0,0.12727477,55.247009,8.3622999,504.63571,-9.2040195
2483,2483,212.0318,4.9262462,1.8224576,0.0,0,7.8342957,0.0,0.12913474,55.165123,8.3297348,504.63034,-9.203722
2484,2484,212.032,4.9283366,1.840879,0.0,0,7.8078156,0.0,0.13098441,55.037472,8.3016462,504.62497,-9.2042236
2485,2485,212.0322,4.9335303,1.8649497,0.0,0,7.7813354,0.0,0.13232844,54.994026,8.273284,504.6196,-9.2044601
2486,2486,212.0324,4.9155478,1.8910586,0.0,0,7.7548552,0.0,0.13418028,54.777489,8.2475891,504.61423,-9.2039661
2487,2487,212.0326,4.8603706,1.9147822,0.0,0,7.7283754,0.0,0.13646129,54.178566,8.2220469,504.60886,-9.2038927
2488,2488,212.0328,4.8172488,1.9401647,0.0,0,7.7018952,0.0,0.13808195,53.470119,8.1971741,504.60349,-9.2038336
2489,2489,212.033,4.8568182,1.95811,0.0,0,7.675415,0.0,0.1393992,53.546085,8.1781578,504.59811,-9.2036676
2490,2490,212.0332,4.954957,1.9676452,0.0,0,7.6489348,0.0,0.14074768,54.519463,8.1559658,504.59274,-9.203392
2491,2491,212.0334,5.0306516,1.9876634,0.0,0,7.6224551,0.0,0.14188024,55.462704,8.1312838,504.58737,-9.2039223
2492,2492,212.0336,5.0323858,2.0131707,0.0,0,7.5959754,0.0,0.14341775,55.615101,8.108429,504.582,-9.2047892
2493,2493,212.0338,5.000843,2.0335863,0.0,0,7.5694952,0.0,0.14556839,55.135181,8.0877991,504.57663,-9.2043438
2494,2494,212.034,5.0178366,2.0606861,0.0,0,7.543015,0.0,0.14746341,55.01487,8.0665693,504.57126,-9.2039375
2495,2495,212.0342,5.0560575,2.086225,0.0,0,7.5165353,0.0,0.14907534,55.373016,8.0431356,504.56586,-9.2039042
2496,2496,212.0344,5.0323477,2.1027398,0.0,0,7.4900556,0.0,0.15087384,55.235931,8.0207949,504.56049,-9.203516
2497,2497,212.0346,4.9775105,2.1290598,0.0,0,7.4635754,0.0,0.15280531,54.536716,7.9933429,504.55511,-9.2027102
2498,2498,212.0348,4.9801931,2.1562617,0.0,0,7.4370952,0.0,0.15449004,54.243031,7.9687371,504.54974,-9.20257
2499,2499,212.035,5.0303364,2.1699009,0.0,0,7.410615,0.0,0.1561289,54.646523,7.9493814,504.54437,-9.2025766
2500,2500,212.0352,5.0499802,2.1915295,0.0,0,7.3846664,0.0,0.15781102,54.937397,7.9272981,504.539,-9.2022581
2501,2501,212.0354,4.9927559,2.2194736,0.0,0,7.3593612,0.0,0.15933783,54.360359,7.9049845,504.53363,-9.2022734
2502,2502,212.0356,4.9219356,2.2363677,0.0,0,7.3341722,0.0,0.16112058,53.439869,7.8839097,504.52826,-9.2028952
2503,2503,212.0358,4.9128566,2.2592866,0.0,0,7.3089881,0.0,0.16314191,53.105965,7.8610549,504.52289,-9.2040892
2504,2504,212.036,4.9425669,2.2832296,0.0,0,7.2838039,0.0,0.16454744,53.308777,7.8381081,504.51752,-9.2048855
2505,2505,212.0362,4.9740038,2.2911105,0.0,0,7.2586198,0.0,0.16559277,53.5979,7.8183517,504.51215,-9.2052031
2506,2506,212.0364,5.0136566,2.3084445,0.0,0,7.2334356,0.0,0.16713774,53.908226,7.7990971,504.50677,-9.2044744
2507,2507,212.0366,5.0695443,2.3360844,0.0,0,7.2082515,0.0,0.16860935,54.448387,7.7801504,504.5014,-9.2038937
2508,2508,212.0368,5.1207757,2.3517909,0.0,0,7.1830673,0.0,0.17009902,54.990688,7.7619662,504.42084,-9.2031775
2509,2509,212.037,5.1256742,2.3726165,0.0,0,7.1578832,0.0,0.17215906,54.960793,7.7415533,504.3403,-9.2028942
2510,2510,212.0372,5.0862346,2.3998432,0.0,0,7.1326995,0.0,0.1737282,54.47681,7.7227588,504.25974,-9.2035513
2511,2511,212.0374,5.0504785,2.4155076,0.0,0,7.1075153,0.0,0.1750672,53.975883,7.7026758,504.1792,-9.2034817
2512,2512,212.0376,5.059515,2.4367783,0.0,0,7.0823312,0.0,0.17721653,53.831135,7.6791434,504.09863,-9.2034187
2513,2513,212.0378,5.0928464,2.4643276,0.0,0,7.0571475,0.0,0.17893872,54.070789,7.6576076,504.01807,-9.2035723
2514,2514,212.038,5.110424,2.4781175,0.0,0,7.0319633,0.0,0.1800503,54.302689,7.6365285,503.93753,-9.2031965
2515,2515,212.0382,5.1259165,2.494704,0.0,0,7.0067792,0.0,0.18187292,54.407951,7.6178226,503.85696,-9.2039242
2516,2516,212.0384,5.1462488,2.5203221,0.0,0,6.981595,0.0,0.18353286,54.527798,7.5991173,503.77643,-9.2046261
2517,2517,212.0386,5.1546884,2.5390432,0.0,0,6.9564114,0.0,0.18480642,54.593082,7.5779014,503.69586,-9.2046614
2518,2518,212.0388,5.1366754,2.5605326,0.0,0,6.9312277,0.0,0.18704624,54.331753,7.5570011,503.6153,-9.2044535
2519,2519,212.039,5.0999508,2.5870597,0.0,0,6.9060431,0.0,0.18904398,53.852005,7.5358148,503.53476,-9.2036858
2520,2520,212.0392,5.0842543,2.6028306,0.0,0,6.8808594,0.0,0.19007432,53.525497,7.516304,503.45419,-9.2029572
2521,2521,212.0394,5.1179395,2.6185594,0.0,0,6.8556757,0.0,0.19179785,53.670753,7.4973979,503.37366,-9.2029209
2522,2522,212.0396,5.1806793,2.6423743,0.0,0,6.830492,0.0,0.19362618,54.240356,7.4752021,503.29309,-9.2023325
2523,2523,212.0398,5.2328649,2.6617639,0.0,0,6.8053074,0.0,0.19474107,54.755905,7.4523683,503.21252,-9.2015905
2524,2524,212.04,5.241714,2.6802967,0.0,0,6.7801232,0.0,0.19660676,54.847797,7.4311128,503.13199,-9.2020874
2525,2525,212.0402,5.2237902,2.703757,0.0,0,6.7554417,0.0,0.1986288,54.591896,7.4104357,503.05142,-9.2022486
2526,2526,212.0404,5.2206588,2.7237823,0.0,0,6.7313671,0.0,0.19982305,54.431335,7.3899884,502.97089,-9.2029819
2527,2527,212.0406,5.2334242,2.7435188,0.0,0,6.7074022,0.0,0.20171025,54.452858,7.3689756,502.89032,-9.2041979
2528,2528,212.0408,5.2421398,2.7679586,0.0,0,6.6834416,0.0,0.20386168,54.464375,7.3499818,502.80975,-9.2044849
2529,2529,212.041,5.2451572,2.7902811,0.0,0,6.6594815,0.0,0.20518631,54.40773,7.328053,502.72922,-9.204504
2530,2530,212.0412,5.2494426,2.8099561,0.0,0,6.6355219,0.0,0.20704032,54.356735,7.3011231,502.64865,-9.205039
2531,2531,212.0414,5.2725382,2.831193,0.0,0,6.6115613,0.0,0.20915267,54.454975,7.2776122,502.56812,-9.2047482
2532,2532,212.0416,5.3111048,2.8550892,0.0,0,6.5876017,0.0,0.21059312,54.74789,7.2571549,502.48755,-9.2039862
2533,2533,212.0418,5.3179817,2.8778939,0.0,0,6.5636415,0.0,0.21254627,54.794067,7.2372923,502.40698,-9.2035494
2534,2534,212.042,5.2996526,2.8999143,0.0,0,6.5396819,0.0,0.21479845,54.516575,7.2132993,502.32645,-9.2030678
2535,2535,212.0422,5.3034391,2.9236326,0.0,0,6.5157218,0.0,0.21628825,54.404461,7.1901121,502.24588,-9.2024136
2536,2536,212.0424,5.3381467,2.9437804,0.0,0,6.4917622,0.0,0.21793754,54.580589,7.1674166,502.16534,-9.202651
2537,2537,212.0426,5.3816233,2.9617491,0.0,0,6.467802,0.0,0.21996026,54.971542,7.1427379,502.08478,-9.2028351
2538,2538,212.0428,5.4101691,2.988209,0.0,0,6.4438419,0.0,0.22164005,55.201363,7.118907,502.00421,-9.203001
2539,2539,212.043,5.4168777,3.0141761,0.0,0,6.4198818,0.0,0.22362922,55.129734,7.0957847,501.92368,-9.2038202
2540,2540,212.0432,5.4231539,3.0343089,0.0,0,6.3959212,0.0,0.22596496,55.055607,7.0723162,501.84311,-9.2038984
2541,2541,212.0434,5.4296904,3.0617845,0.0,0,6.3719616,0.0,0.22788411,55.019798,7.0488844,501.76257,-9.2038555
2542,2542,212.0436,5.433147,3.0882196,0.0,0,6.3480015,0.0,0.22981918,54.950069,7.0252404,501.68201,-9.2043667
2543,2543,212.0438,5.4396844,3.1079841,0.0,0,6.3240418,0.0,0.2321482,54.862274,7.001987,501.60144,-9.2041807
2544,2544,212.044,5.4506774,3.1364048,0.0,0,6.3000817,0.0,0.23421864,54.855732,6.9777279,501.5209,-9.203927
2545,2545,212.0442,5.4658875,3.1635211,0.0,0,6.2761221,0.0,0.23601781,54.952648,6.9522877,501.44034,-9.2037811
2546,2546,212.0444,5.4915538,3.179724,0.0,0,6.252162,0.0,0.2380909,55.056801,6.929112,501.3598,-9.2032957
2547,2547,212.0446,5.5236011,3.2056346,0.0,0,6.2282019,0.0,0.24018054,55.203068,6.9052181,501.27924,-9.2031527
2548,2548,212.0448,5.5398235,3.234587,0.0,0,6.2042422,0.0,0.24208689,55.336864,6.8791156,501.19867,-9.2031937
2549,2549,212.045,5.5341773,3.2524893,0.0,0,6.1802821,0.0,0.24421769,55.182388,6.8544626,501.11813,-9.2032986
2550,2550,212.0452,5.5238714,3.2787011,0.0,0,6.1568027,0.0,0.24639536,54.942612,6.8300085,501.03757,-9.2034874
2551,2551,212.0454,5.5225735,3.3069274,0.0,0,6.1339049,0.0,0.24814242,54.879269,6.8040266,500.95703,-9.2049484
2552,2552,212.0456,5.5393891,3.3221443,0.0,0,6.1111121,0.0,0.25002518,54.913921,6.7800484,500.87646,-9.20574
2553,2553,212.0458,5.573997,3.3478215,0.0,0,6.0883236,0.0,0.25238934,55.043674,6.7582731,500.7959,-9.2045422
2554,2554,212.046,5.6075368,3.3800893,0.0,0,6.065536,0.0,0.25448328,55.244244,6.7344871,500.71536,-9.2037449
2555,2555,212.0462,5.638032,3.3992455,0.0,0,6.042748,0.0,0.25656828,55.423317,6.7076077,500.6348,-9.2037048
2556,2556,212.0464,5.6595116,3.4259846,0.0,0,6.0199599,0.0,0.25916022,55.497784,6.6796613,500.55426,-9.2035379
2557,2557,212.0466,5.6656184,3.4590037,0.0,0,5.9971719,0.0,0.26129183,55.496159,6.6542211,500.47369,-9.203474
2558,2558,212.0468,5.6674352,3.4787879,0.0,0,5.9743834,0.0,0.26327538,55.447029,6.6311359,500.39133,-9.2036448
2559,2559,212.047,5.6681299,3.5048959,0.0,0,5.9515953,0.0,0.26602021,55.311771,6.6050744,500.30896,-9.2033997
2560,2560,212.0472,5.6714211,3.537709,0.0,0,5.9288077,0.0,0.26828021,55.229031,6.5779843,500.22656,-9.2031126
2561,2561,212.0474,5.6809435,3.5568178,0.0,0,5.9060202,0.0,0.27002862,55.208168,6.5523787,500.1442,-9.2039232
2562,2562,212.0476,5.6975651,3.5812573,0.0,0,5.8832321,0.0,0.27271077,55.187725,6.5255198,500.06183,-9.2042685
2563,2563,212.0478,5.7171431,3.6136365,0.0,0,5.8604436,0.0,0.27499664,55.287708,6.4987869,499.97946,-9.203805
2564,2564,212.048,5.7466712,3.6339717,0.0,0,5.8376555,0.0,0.27672446,55.435726,6.4751153,499.89709,-9.2034769
2565,2565,212.0482,5.7731233,3.658056,0.0,0,5.8148675,0.0,0.27947968,55.522095,6.4516759,499.81473,-9.2034321
2566,2566,212.0484,5.7826958,3.6894305,0.0,0,5.792079,0.0,0.2818028,55.549465,6.4248986,499.73236,-9.2036934
2567,2567,212.0486,5.7830663,3.7100642,0.0,0,5.7692914,0.0,0.28343379,55.483925,6.3963156,499.64996,-9.204195
2568,2568,212.0488,5.7775354,3.7333333,0.0,0,5.7465038,0.0,0.2860401,55.258884,6.3705153,499.5676,-9.2042007
2569,2569,212.049,5.7774663,3.7647839,0.0,0,5.7237153,0.0,0.2885296,55.099762,6.3459778,499.48523,-9.2041559
2570,2570,212.0492,5.7915277,3.7880092,0.0,0,5.7009277,0.0,0.29028869,55.124054,6.3196063,499.40286,-9.2046499
2571,2571,212.0494,5.811738,3.8122308,0.0,0,5.6781397,0.0,0.2930285,55.131874,6.2922726,499.3205,-9.2040224
2572,2572,212.0496,5.8237224,3.8433368,0.0,0,5.6553516,0.0,0.2957525,55.132591,6.2663937,499.23813,-9.2034626
2573,2573,212.0498,5.841589,3.8669074,0.0,0,5.6325636,0.0,0.29741311,55.253986,6.2412553,499.15573,-9.2035952
2574,2574,212.05,5.85992,3.8904026,0.0,0,5.6097755,0.0,0.3000173,55.329895,6.2129645,499.07336,-9.2037859
2575,2575,212.0502,5.8702021,3.9210918,0.0,0,5.5874419,0.0,0.30277792,55.258411,6.1883407,498.991,-9.204257
2576,2576,212.0504,5.8903303,3.9464903,0.0,0,5.5656581,0.0,0.30446577,55.244499,6.1659689,498.90863,-9.2048712
2577,2577,212.0506,5.9108725,3.9689314,0.0,0,5.5439739,0.0,0.30696684,55.296535,6.1389141,498.82626,-9.2044735
2578,2578,212.0508,5.9237423,3.9964581,0.0,0,5.5222936,0.0,0.30967316,55.310539,6.1120872,498.7439,-9.2034788
2579,2579,212.051,5.9250851,4.0225735,0.0,0,5.5006137,0.0,0.3114678,55.249557,6.0866728,498.6615,-9.2030706
2580,2580,212.0512,5.9213905,4.0462251,0.0,0,5.4789333,0.0,0.31391671,55.089527,6.0610065,498.57913,-9.2026014
2581,2581,212.0514,5.9269662,4.0718055,0.0,0,5.4572535,0.0,0.31658447,54.954826,6.0342717,498.49677,-9.2018948
2582,2582,212.0516,5.9345794,4.09727,0.0,0,5.4355736,0.0,0.31832018,54.943512,6.0094919,498.4144,-9.2024832
2583,2583,212.0518,5.9544177,4.1207886,0.0,0,5.4138937,0.0,0.32061526,54.983341,5.9841094,498.33203,-9.2029438
2584,2584,212.052,5.9864531,4.1442037,0.0,0,5.3922133,0.0,0.32338274,55.074684,5.9584742,498.24966,-9.2030125
2585,2585,212.0522,6.0127387,4.171278,0.0,0,5.3705335,0.0,0.32523817,55.175289,5.9338446,498.16727,-9.2035904
2586,2586,212.0524,6.0257792,4.195941,0.0,0,5.3488536,0.0,0.32747909,55.204258,5.9078946,498.0849,-9.2036924
2587,2587,212.0526,6.0320086,4.2178502,0.0,0,5.3271737,0.0,0.33021232,55.181885,5.8816156,498.00253,-9.2036991
2588,2588,212.0528,6.0337639,4.246038,0.0,0,5.3054934,0.0,0.3321735,55.049118,5.8553953,497.92017,-9.2037392
2589,2589,212.053,6.0272336,4.2716608,0.0,0,5.2838135,0.0,0.3343538,54.884804,5.831183,497.8378,-9.2037411
2590,2590,212.0532,6.0256519,4.2920289,0.0,0,5.2621331,0.0,0.33705711,54.782036,5.807765,497.75543,-9.2033997
2591,2591,212.0534,6.0420165,4.3213358,0.0,0,5.2404532,0.0,0.33923629,54.780994,5.7798929,497.67307,-9.2036524
2592,2592,212.0536,6.0648746,4.3480639,0.0,0,5.2187734,0.0,0.34138599,54.840271,5.7562904,497.59067,-9.2040043
2593,2593,212.0538,6.0912695,4.3661847,0.0,0,5.1970935,0.0,0.3440049,54.914326,5.7334809,497.5083,-9.2039652
2594,2594,212.054,6.1178145,4.3945632,0.0,0,5.1754136,0.0,0.34630638,54.998493,5.7067752,497.42593,-9.2042074
2595,2595,212.0542,6.130229,4.4224005,0.0,0,5.1537337,0.0,0.34839457,55.029354,5.680954,497.34357,-9.20401
2596,2596,212.0544,6.133142,4.4400573,0.0,0,5.1320534,0.0,0.35085502,54.968559,5.6560974,497.2612,-9.2035103
2597,2597,212.0546,6.1329269,4.4672441,0.0,0,5.1103735,0.0,0.35327187,54.847572,5.6322775,497.17883,-9.2034626
2598,2598,212.0548,6.1242738,4.495317,0.0,0,5.0886931,0.0,0.35527179,54.708878,5.6091146,497.09644,-9.2035828
2599,2599,212.055,6.1235976,4.5111151,0.0,0,5.0670133,0.0,0.35747305,54.578857,5.5882821,497.01407,-9.2030258
2600,2600,212.0552,6.1355085,4.5358191,0.0,0,5.0457683,0.0,0.35986853,54.498436,5.5639358,496.9317,-9.2030039
2601,2601,212.0554,6.1536665,4.5646334,0.0,0,5.0250487,0.0,0.36184961,54.552586,5.5386395,496.84933,-9.2028933
2602,2602,212.0556,6.1772523,4.5800066,0.0,0,5.0044241,0.0,0.36399117,54.648674,5.5143108,496.76697,-9.2029696
2603,2603,212.0558,6.1970716,4.6034231,0.0,0,4.9838042,0.0,0.36654904,54.652294,5.4893498,496.6846,-9.2037315
2604,2604,212.056,6.202107,4.6333928,0.0,0,4.9631839,0.0,0.36854485,54.603848,5.4670458,496.6022,-9.2037058
2605,2605,212.0562,6.2046809,4.6490903,0.0,0,4.942564,0.0,0.37052438,54.594265,5.4437675,496.51984,-9.2036457
2606,2606,212.0564,6.2172728,4.6728444,0.0,0,4.9219441,0.0,0.37316963,54.537792,5.4192986,496.43747,-9.2036657
2607,2607,212.0566,6.2228322,4.7038994,0.0,0,4.9013243,0.0,0.37532318,54.424263,5.3967981,496.3551,-9.2036133
2608,2608,212.0568,6.2233324,4.7194452,0.0,0,4.8807039,0.0,0.37723798,54.336853,5.3734145,496.24228,-9.2033482
2609,2609,212.057,6.2345562,4.7409587,0.0,0,4.8600841,0.0,0.37988716,54.321762,5.3494678,496.12949,-9.2033615
2610,2610,212.0572,6.2482915,4.770813,0.0,0,4.8394642,0.0,0.38199696,54.320278,5.3286715,496.01666,-9.2036247
2611,2611,212.0574,6.259232,4.7873998,0.0,0,4.8188443,0.0,0.38377467,54.315079,5.3059163,495.90384,-9.2036695
2612,2612,212.0576,6.2777662,4.8102179,0.0,0,4.798224,0.0,0.3865875,54.351231,5.2826786,495.79105,-9.2036724
2613,2613,212.0578,6.288826,4.8414216,0.0,0,4.7776041,0.0,0.38894564,54.333801,5.2612462,495.67822,-9.2031002
2614,2614,212.058,6.2978067,4.8587556,0.0,0,4.7569842,0.0,0.39073533,54.2864,5.2385716,495.5654,-9.2023325
2615,2615,212.0582,6.3152223,4.8800941,0.0,0,4.7363639,0.0,0.39355713,54.221123,5.2152338,495.45258,-9.2022753
2616,2616,212.0584,6.329432,4.9100633,0.0,0,4.715744,0.0,0.39595813,54.220993,5.192111,495.33978,-9.2022715
2617,2617,212.0586,6.343493,4.9280028,0.0,0,4.6951241,0.0,0.39750022,54.248711,5.1703453,495.22696,-9.2025299
2618,2618,212.0588,6.3467026,4.9467402,0.0,0,4.6745043,0.0,0.40010992,54.17701,5.1480188,495.11414,-9.2032843
2619,2619,212.059,6.3455954,4.9735136,0.0,0,4.6538844,0.0,0.40245265,54.041096,5.1255999,495.00134,-9.2036409
2620,2620,212.0592,6.3557324,4.9919119,0.0,0,4.6332641,0.0,0.40385133,53.981178,5.1029525,494.88852,-9.2036581
2621,2621,212.0594,6.3667712,5.0108809,0.0,0,4.6126437,0.0,0.40645456,53.92601,5.0789714,494.7757,-9.2041874
2622,2622,212.0596,6.3710532,5.0373859,0.0,0,4.5920238,0.0,0.40897304,53.842258,5.0574484,494.6629,-9.2046413
2623,2623,212.0598,6.3871012,5.0566244,0.0,0,4.571404,0.0,0.4103018,53.881332,5.0350304,494.55008,-9.2048206
2624,2624,212.06,6.4139729,5.0743365,0.0,0,4.5507841,0.0,0.41271767,53.956074,5.0131049,494.43726,-9.2041292
2625,2625,212.0602,6.4251094,5.0999541,0.0,0,4.5305758,0.0,0.41530859,53.988861,4.9927506,494.32446,-9.2033691
2626,2626,212.0604,6.429657,5.121892,0.0,0,4.5108657,0.0,0.41686621,53.972008,4.9714189,494.21164,-9.203023
2627,2627,212.0606,6.4320273,5.1421704,0.0,0,4.4912457,0.0,0.41943264,53.844543,4.9512634,494.09882,-9.2025661
2628,2628,212.0608,6.431056,5.1672096,0.0,0,4.4716296,0.0,0.42221612,53.68343,4.9306612,493.98602,-9.2025881
2629,2629,212.061,6.436079,5.1897602,0.0,0,4.4520135,0.0,0.4238306,53.604118,4.9100766,493.8732,-9.2028656
2630,2630,212.0612,6.4489388,5.2096949,0.0,0,4.4323978,0.0,0.42623568,53.554611,4.8876176,493.76038,-9.2028046
2631,2631,212.0614,6.4532361,5.2316227,0.0,0,4.4127817,0.0,0.42890352,53.443058,4.8640876,493.64758,-9.2029238
2632,2632,212.0616,6.4586668,5.2537436,0.0,0,4.3931656,0.0,0.43044615,53.436611,4.8430037,493.53476,-9.2040777
2633,2633,212.0618,6.4773631,5.272315,0.0,0,4.3735499,0.0,0.43259802,53.505436,4.8225446,493.42194,-9.204752
2634,2634,212.062,6.5038581,5.2912645,0.0,0,4.3539338,0.0,0.43519947,53.565948,4.8016057,493.30914,-9.2042913
2635,2635,212.0622,6.5242991,5.3143268,0.0,0,4.3343177,0.0,0.43683168,53.655045,4.7827282,493.19632,-9.2042694
2636,2636,212.0624,6.5287471,5.3338132,0.0,0,4.314702,0.0,0.43877831,53.609043,4.7615666,493.0835,-9.2042189
2637,2637,212.0626,6.5298629,5.350307,0.0,0,4.2950859,0.0,0.44126332,53.490208,4.7393599,492.9707,-9.203475
2638,2638,212.0628,6.5274043,5.3733802,0.0,0,4.2754698,0.0,0.44295016,53.408413,4.719624,492.85788,-9.2029552
2639,2639,212.063,6.5337276,5.3939352,0.0,0,4.2558532,0.0,0.44489434,53.366867,4.6994905,492.74506,-9.2023935
2640,2640,212.0632,6.552413,5.4104939,0.0,0,4.2362375,0.0,0.44751158,53.338268,4.6785431,492.63226,-9.2021093
2641,2641,212.0634,6.5665369,5.4353232,0.0,0,4.2166214,0.0,0.44951773,53.336407,4.6595068,492.51944,-9.2020979
2642,2642,212.0636,6.5819292,5.4582415,0.0,0,4.1970053,0.0,0.45151621,53.373009,4.6377406,492.40662,-9.2026892
2643,2643,212.0638,6.5982275,5.4736199,0.0,0,4.1773896,0.0,0.45403346,53.352539,4.6144147,492.29379,-9.2034616
2644,2644,212.064,6.6129107,5.4980092,0.0,0,4.1577735,0.0,0.45622343,53.367062,4.593513,492.181,-9.2036066
2645,2645,212.0642,6.6327901,5.5219254,0.0,0,4.1381574,0.0,0.45817497,53.4025,4.5740042,492.06818,-9.2036514
2646,2646,212.0644,6.6473117,5.5359764,0.0,0,4.1185417,0.0,0.46055824,53.361332,4.555366,491.95535,-9.2040138
2647,2647,212.0646,6.6497669,5.5599356,0.0,0,4.0989256,0.0,0.46283004,53.297211,4.5361214,491.84256,-9.2040339
2648,2648,212.0648,6.6535921,5.5839448,0.0,0,4.0793095,0.0,0.46459818,53.213333,4.5147171,491.72974,-9.2037001
2649,2649,212.065,6.6625676,5.5951319,0.0,0,4.0596938,0.0,0.46671912,53.146492,4.4937596,491.61691,-9.2029505
2650,2650,212.0652,6.674192,5.6172943,0.0,0,4.0404716,0.0,0.46906185,53.156345,4.4734735,491.50412,-9.2028751
2651,2651,212.0654,6.6857429,5.6437402,0.0,0,4.0217257,0.0,0.47095877,53.103008,4.4514723,491.3913,-9.2035046
2652,2652,212.0656,6.7013693,5.6554375,0.0,0,4.0030656,0.0,0.47303453,53.073849,4.430007,491.27847,-9.203577
2653,2653,212.0658,6.7254143,5.6763773,0.0,0,3.9844093,0.0,0.47546452,53.132607,4.4096966,491.16568,-9.203557
2654,2654,212.066,6.7421217,5.7032037,0.0,0,3.9657533,0.0,0.47732541,53.150616,4.3919406,491.05286,-9.2028465
2655,2655,212.0662,6.7555022,5.7144318,0.0,0,3.9470973,0.0,0.47915143,53.163445,4.3734727,490.94003,-9.2021303
2656,2656,212.0664,6.7656517,5.7342334,0.0,0,3.9284413,0.0,0.48167795,53.168499,4.3541741,490.82724,-9.202075
2657,2657,212.0666,6.7713885,5.7613964,0.0,0,3.9097853,0.0,0.48364142,53.155979,4.3341107,490.71442,-9.2020168
2658,2658,212.0668,6.7735424,5.7731161,0.0,0,3.8911293,0.0,0.48541284,53.069534,4.3135777,490.61346,-9.2021389
2659,2659,212.067,6.77316,5.7923427,0.0,0,3.8724735,0.0,0.48815686,52.902306,4.2948112,490.51251,-9.2026987
2660,2660,212.0672,6.7798362,5.8196278,0.0,0,3.8538175,0.0,0.49017134,52.824512,4.274323,490.41159,-9.2033482
2661,2661,212.0674,6.7916198,5.8311543,0.0,0,3.8351612,0.0,0.4916802,52.864246,4.2542591,490.31064,-9.2036409
2662,2662,212.0676,6.8116713,5.8494816,0.0,0,3.8165054,0.0,0.49438807,52.86657,4.2357235,490.20969,-9.2031088
2663,2663,212.0678,6.8362827,5.8772273,0.0,0,3.7978494,0.0,0.49647191,52.876915,4.2167239,490.10873,-9.2021294
2664,2664,212.068,6.8631878,5.8902664,0.0,0,3.7791932,0.0,0.49798125,53.044666,4.1992941,490.00778,-9.2018881
2665,2665,212.0682,6.8855166,5.9077067,0.0,0,3.7605371,0.0,0.50076479,53.087685,4.1820264,489.90686,-9.2027054
2666,2666,212.0684,6.8925452,5.9351325,0.0,0,3.7418811,0.0,0.50301349,53.024014,4.1602263,489.80591,-9.2034836
2667,2667,212.0686,6.8856211,5.949544,0.0,0,3.7232254,0.0,0.50444412,52.979733,4.1406422,489.70496,-9.2029028
2668,2668,212.0688,6.8848548,5.9654899,0.0,0,3.7045693,0.0,0.50713992,52.831215,4.1216583,489.604,-9.2021561
2669,2669,212.069,6.9026136,5.9918647,0.0,0,3.6859133,0.0,0.50955951,52.783154,4.1016631,489.50308,-9.2021484
2670,2670,212.0692,6.9234958,6.0080137,0.0,0,3.6672573,0.0,0.51083338,52.878868,4.0811281,489.40213,-9.2028723
2671,2671,212.0694,6.9375291,6.0226488,0.0,0,3.6486013,0.0,0.51329911,52.900436,4.0609608,489.30118,-9.2036257
2672,2672,212.0696,6.9537382,6.0463676,0.0,0,3.6299453,0.0,0.51571709,52.880268,4.0426965,489.20023,-9.2036133
2673,2673,212.0698,6.9764972,6.0633216,0.0,0,3.6112893,0.0,0.51695651,52.970757,4.0243115,489.09927,-9.2035751
2674,2674,212.07,7.0040569,6.0782013,0.0,0,3.5926332,0.0,0.51945931,53.039139,4.0052233,488.99835,-9.2033367
2675,2675,212.0702,7.0164251,6.1013913,0.0,0,3.5743496,0.0,0.52209252,53.008869,3.9858556,488.8974,-9.2026777
2676,2676,212.0704,7.0206623,6.1198754,0.0,0,3.5565166,0.0,0.52340961,52.976051,3.9683936,488.79645,-9.2024508
2677,2677,212.0706,7.028605,6.1358795,0.0,0,3.538765,0.0,0.52588296,52.886097,3.9500182,488.6955,-9.2023792
2678,2678,212.0708,7.0352535,6.1583409,0.0,0,3.5210168,0.0,0.52864057,52.784885,3.9312255,488.59457,-9.202527
2679,2679,212.071,7.0473413,6.1787066,0.0,0,3.5032687,0.0,0.53003186,52.834435,3.9109414,488.49362,-9.2031164
2680,2680,212.0712,7.0613813,6.1953845,0.0,0,3.4855206,0.0,0.53241432,52.827602,3.8905249,488.39267,-9.2034101
2681,2681,212.0714,7.0807986,6.2163529,0.0,0,3.4677727,0.0,0.53523427,52.804073,3.8733051,488.29172,-9.2030506
2682,2682,212.0716,7.1096911,6.2375832,0.0,0,3.4500248,0.0,0.53669834,52.891308,3.8565652,488.19077,-9.2023573
2683,2683,212.0718,7.1338592,6.2547383,0.0,0,3.432277,0.0,0.53894567,52.927711,3.8358672,488.08984,-9.2028637
2684,2684,212.072,7.1466856,6.2734718,0.0,0,3.4145288,0.0,0.54177719,52.921852,3.817241,487.98889,-9.2032375
2685,2685,212.0722,7.1584759,6.295188,0.0,0,3.3967807,0.0,0.54337436,52.952503,3.8013453,487.88794,-9.2032452
2686,2686,212.0724,7.166183,6.3125257,0.0,0,3.3790326,0.0,0.54548126,52.912682,3.7829416,487.78699,-9.20362
2687,2687,212.0726,7.1699104,6.3281946,0.0,0,3.3612847,0.0,0.54816341,52.798481,3.7633779,487.68607,-9.2034702
2688,2688,212.0728,7.1738095,6.3504767,0.0,0,3.3435369,0.0,0.54978251,52.738636,3.7437449,487.58511,-9.2034292
2689,2689,212.073,7.1822748,6.3682675,0.0,0,3.3257887,0.0,0.55170411,52.68367,3.7245462,487.48416,-9.2032804
2690,2690,212.0732,7.2007217,6.3810916,0.0,0,3.3080409,0.0,0.55437535,52.656067,3.7061739,487.38321,-9.2026291
2691,2691,212.0734,7.2268438,6.4034142,0.0,0,3.2902927,0.0,0.55624121,52.718758,3.6875198,487.28226,-9.2021742
2692,2692,212.0736,7.2562599,6.4230828,0.0,0,3.2725446,0.0,0.55806053,52.844296,3.6697319,487.18134,-9.2027979
2693,2693,212.0738,7.2868705,6.4359188,0.0,0,3.2547965,0.0,0.56062382,52.925621,3.6513662,487.08038,-9.2028198
2694,2694,212.074,7.303988,6.4583182,0.0,0,3.2370486,0.0,0.56271648,52.934517,3.6327419,486.97943,-9.2021208
2695,2695,212.0742,7.3067489,6.4780769,0.0,0,3.2193007,0.0,0.56449455,52.893806,3.6132195,486.87848,-9.2033806
2696,2696,212.0744,7.307909,6.4892669,0.0,0,3.2015526,0.0,0.56685674,52.795338,3.594732,486.77756,-9.2036457
2697,2697,212.0746,7.3209343,6.5131693,0.0,0,3.1838048,0.0,0.56918746,52.755611,3.5771365,486.67661,-9.2031364
2698,2698,212.0748,7.3427491,6.5378323,0.0,0,3.1660566,0.0,0.57117748,52.773796,3.5569766,486.57565,-9.2035704
2699,2699,212.075,7.3581014,6.5498686,0.0,0,3.1483088,0.0,0.57365918,52.781013,3.539149,486.4747,-9.2029972
2700,2700,212.0752,7.3819313,6.5718222,0.0,0,3.1309152,0.0,0.57622057,52.825111,3.5222566,486.37375,-9.202467
2701,2701,212.0754,7.4153557,6.5965004,0.0,0,3.11395,0.0,0.57814485,52.948299,3.503706,486.27283,-9.2022209
2702,2702,212.0756,7.4438972,6.6065855,0.0,0,3.0970623,0.0,0.58031958,53.035919,3.4844728,486.17188,-9.2019739
2703,2703,212.0758,7.4639368,6.6260753,0.0,0,3.0801783,0.0,0.58289093,53.023205,3.465126,486.07092,-9.2020054
2704,2704,212.076,7.4747829,6.650835,0.0,0,3.0632944,0.0,0.58471882,52.982159,3.4469271,485.96997,-9.2017813
2705,2705,212.0762,7.4851413,6.6606646,0.0,0,3.0464106,0.0,0.58662575,52.95414,3.4294577,485.86905,-9.201725
2706,2706,212.0764,7.5011482,6.6797118,0.0,0,3.0295265,0.0,0.58938217,52.915516,3.4113653,485.7681,-9.201786
2707,2707,212.0766,7.5160379,6.7058463,0.0,0,3.0126424,0.0,0.59141123,52.936596,3.3926687,485.66714,-9.2025928
2708,2708,212.0768,7.5288143,6.7166739,0.0,0,2.9957583,0.0,0.59333223,52.957447,3.3740993,485.38327,-9.2034559
2709,2709,212.077,7.549283,6.7350287,0.0,0,2.9788744,0.0,0.59626335,52.920952,3.3540666,485.09937,-9.2029619
2710,2710,212.0772,7.5698833,6.7617512,0.0,0,2.9619906,0.0,0.59830028,52.957958,3.3344212,484.81549,-9.2033606
2711,2711,212.0774,7.589922,6.7724161,0.0,0,2.9451065,0.0,0.59983528,53.018894,3.3180733,484.53162,-9.2033558
2712,2712,212.0776,7.6132183,6.789413,0.0,0,2.9282222,0.0,0.60273576,53.010414,3.3010316,484.24771,-9.2028942
2713,2713,212.0778,7.6341577,6.816143,0.0,0,2.9113381,0.0,0.60496813,53.037102,3.2802248,483.96384,-9.2032938
2714,2714,212.078,7.6532645,6.827971,0.0,0,2.8944542,0.0,0.60646874,53.112171,3.2595801,483.67996,-9.2027597
2715,2715,212.0782,7.6740742,6.8452196,0.0,0,2.8775704,0.0,0.60954434,53.080688,3.2419598,483.39606,-9.2023811
2716,2716,212.0784,7.6925125,6.8720889,0.0,0,2.8606863,0.0,0.61207634,53.040531,3.225034,483.11218,-9.202342
2717,2717,212.0786,7.7060061,6.8849797,0.0,0,2.8438022,0.0,0.61349422,53.057682,3.2083316,482.82831,-9.2020292
2718,2718,212.0788,7.7219644,6.901041,0.0,0,2.8269184,0.0,0.61642754,53.040028,3.191299,482.5444,-9.2017717
2719,2719,212.079,7.7374663,6.9280353,0.0,0,2.810034,0.0,0.61910379,53.015022,3.1717644,482.26053,-9.2023563
2720,2720,212.0792,7.752346,6.94312,0.0,0,2.7931502,0.0,0.62046397,53.074703,3.1537173,481.97665,-9.2033377
2721,2721,212.0794,7.7733617,6.9574776,0.0,0,2.7762663,0.0,0.62327361,53.083828,3.1360712,481.69275,-9.2030497
2722,2722,212.0796,7.796886,6.9815116,0.0,0,2.7593822,0.0,0.62596864,53.083454,3.1176493,481.40887,-9.202632
2723,2723,212.0798,7.8283038,6.997488,0.0,0,2.7424984,0.0,0.62715083,53.194603,3.1002352,481.125,-9.2030916
2724,2724,212.08,7.8553696,7.0120239,0.0,0,2.7256143,0.0,0.62991041,53.219627,3.0821683,480.84109,-9.2028828
2725,2725,212.0802,7.8672495,7.0338912,0.0,0,2.7090683,0.0,0.6327619,53.165512,3.0629344,480.55722,-9.2020016
2726,2726,212.0804,7.8751912,7.0501361,0.0,0,2.6929309,0.0,0.63389784,53.170338,3.0455196,480.27335,-9.2013597
2727,2727,212.0806,7.8837481,7.0640287,0.0,0,2.6768677,0.0,0.63645649,53.107746,3.0283802,479.98944,-9.2014952
2728,2728,212.0808,7.9007421,7.0850778,0.0,0,2.6608074,0.0,0.63941264,53.065582,3.0115085,479.70557,-9.2014313
2729,2729,212.081,7.9194999,7.103622,0.0,0,2.6447473,0.0,0.64075768,53.161591,2.9939134,479.42169,-9.2015867
2730,2730,212.0812,7.9399977,7.1189547,0.0,0,2.6286874,0.0,0.64330149,53.160854,2.9734623,479.13779,-9.2029028
2731,2731,212.0814,7.9623919,7.1387835,0.0,0,2.6126273,0.0,0.64634502,53.109615,2.9554307,478.85391,-9.203413
2732,2732,212.0816,7.9852543,7.1586871,0.0,0,2.5965672,0.0,0.64776409,53.162334,2.9366105,478.57004,-9.2034464
2733,2733,212.0818,8.010107,7.1743731,0.0,0,2.5805073,0.0,0.65011489,53.2038,2.9178603,478.28616,-9.2035894
2734,2734,212.082,8.0343084,7.1922927,0.0,0,2.5644474,0.0,0.65315634,53.191032,2.902,478.00226,-9.2028971
2735,2735,212.0822,8.0484447,7.2140627,0.0,0,2.5483873,0.0,0.65482622,53.209167,2.8850434,477.71838,-9.2023821
2736,2736,212.0824,8.058794,7.2300844,0.0,0,2.5323272,0.0,0.65708631,53.156322,2.8673484,477.43451,-9.2021875
2737,2737,212.0826,8.0756559,7.2451677,0.0,0,2.5162673,0.0,0.6600886,53.090408,2.8494921,477.1506,-9.2014675
2738,2738,212.0828,8.0909195,7.2677536,0.0,0,2.5002072,0.0,0.66193444,53.127487,2.8303418,476.86673,-9.2012596
2739,2739,212.083,8.1089869,7.2856312,0.0,0,2.4841473,0.0,0.66404378,53.151997,2.8150563,476.58286,-9.2015963
2740,2740,212.0832,8.1299734,7.2987213,0.0,0,2.4680872,0.0,0.66691244,53.129784,2.7984869,476.29895,-9.2019615
2741,2741,212.0834,8.1608553,7.3207455,0.0,0,2.4520273,0.0,0.66881353,53.179996,2.7786229,476.01508,-9.2027531
2742,2742,212.0836,8.1903343,7.3386788,0.0,0,2.4359674,0.0,0.6707648,53.240414,2.7602692,475.7312,-9.2034836
2743,2743,212.0838,8.2139425,7.3487253,0.0,0,2.4199073,0.0,0.67349017,53.281216,2.7427676,475.4473,-9.2035599
2744,2744,212.084,8.2444448,7.3700523,0.0,0,2.4038472,0.0,0.67553782,53.374069,2.7249918,475.16342,-9.2036066
2745,2745,212.0842,8.263526,7.3884649,0.0,0,2.3877873,0.0,0.67720449,53.382946,2.7067795,474.87955,-9.2033453
2746,2746,212.0844,8.2694349,7.396513,0.0,0,2.3717272,0.0,0.67967242,53.319878,2.6900556,474.59564,-9.2027874
2747,2747,212.0846,8.2778864,7.4181633,0.0,0,2.3556671,0.0,0.68203294,53.270535,2.6749203,474.31177,-9.2025185
2748,2748,212.0848,8.2950783,7.4410639,0.0,0,2.3396072,0.0,0.6839875,53.270401,2.6562665,474.02789,-9.2018166
2749,2749,212.085,8.3159094,7.4512229,0.0,0,2.3235474,0.0,0.68664747,53.255089,2.6366167,473.74399,-9.2015886
2750,2750,212.0852,8.3377323,7.4735184,0.0,0,2.3078089,0.0,0.6894322,53.215496,2.6194363,473.46011,-9.2015343
2751,2751,212.0854,8.3665352,7.4986868,0.0,0,2.2924595,0.0,0.69156206,53.306625,2.6011617,473.17624,-9.200839
2752,2752,212.0856,8.3962755,7.5079632,0.0,0,2.2771804,0.0,0.69398308,53.406998,2.5853899,472.89233,-9.2013874
2753,2753,212.0858,8.4268312,7.5270514,0.0,0,2.2619042,0.0,0.69667625,53.447887,2.5706887,472.60846,-9.2019358
2754,2754,212.086,8.4548283,7.5506868,0.0,0,2.246628,0.0,0.69860834,53.503094,2.5542095,472.32458,-9.202467
2755,2755,212.0862,8.4663734,7.5592685,0.0,0,2.2313523,0.0,0.7008127,53.461197,2.5378203,472.04068,-9.2030878
2756,2756,212.0864,8.4729939,7.5776,0.0,0,2.2160764,0.0,0.70368862,53.343803,2.5198767,471.75681,-9.2032976
2757,2757,212.0866,8.4837847,7.6017065,0.0,0,2.2008004,0.0,0.70550406,53.338032,2.5019639,471.47293,-9.2030373
2758,2758,212.0868,8.4997883,7.6095767,0.0,0,2.1855242,0.0,0.70731008,53.346931,2.4843123,471.1655,-9.2023077
2759,2759,212.087,8.525156,7.625113,0.0,0,2.1702483,0.0,0.71022266,53.315083,2.4674087,470.85806,-9.2023869
2760,2760,212.0872,8.5577297,7.6483016,0.0,0,2.1549723,0.0,0.71201485,53.41193,2.4509304,470.55063,-9.2024508
2761,2761,212.0874,8.5887356,7.656219,0.0,0,2.1396964,0.0,0.71350878,53.500458,2.4356496,470.24319,-9.202033
2762,2762,212.0876,8.6193972,7.6709757,0.0,0,2.1244202,0.0,0.7165212,53.544373,2.4197841,469.93576,-9.2024727
2763,2763,212.0878,8.6483831,7.6959491,0.0,0,2.1091442,0.0,0.71861535,53.653385,2.4015434,469.62833,-9.2029018
2764,2764,212.088,8.6717405,7.7058415,0.0,0,2.0938683,0.0,0.72003597,53.701534,2.3857977,469.32089,-9.2021189
2765,2765,212.0882,8.6804419,7.7204847,0.0,0,2.0785923,0.0,0.72316003,53.601086,2.3692954,469.01346,-9.2015305
2766,2766,212.0884,8.6836958,7.7464976,0.0,0,2.0633163,0.0,0.72562796,53.489315,2.3522143,468.70602,-9.2016382
2767,2767,212.0886,8.6950655,7.7577939,0.0,0,2.0480404,0.0,0.72710443,53.487167,2.3365121,468.39859,-9.2019911
2768,2768,212.0888,8.7134361,7.7713261,0.0,0,2.0327644,0.0,0.73023003,53.492451,2.3191528,468.09116,-9.2028332
2769,2769,212.089,8.7481613,7.7961545,0.0,0,2.0174885,0.0,0.73288631,53.526432,2.3048272,467.78372,-9.2028341
2770,2770,212.0892,8.7856741,7.8091683,0.0,0,2.0022123,0.0,0.73417169,53.618999,2.2885201,467.47629,-9.2021589
2771,2771,212.0894,8.8161278,7.821712,0.0,0,1.9869361,0.0,0.73708498,53.626122,2.2705035,467.16885,-9.2021151
2772,2772,212.0896,8.8438845,7.8441682,0.0,0,1.9716601,0.0,0.73979461,53.643787,2.255698,466.86142,-9.2020903
2773,2773,212.0898,8.8650208,7.8576779,0.0,0,1.9563841,0.0,0.74089539,53.773319,2.2394831,466.55399,-9.2015018
2774,2774,212.09,8.8798885,7.8689561,0.0,0,1.9411081,0.0,0.74363828,53.752075,2.2235837,466.24655,-9.2007217
2775,2775,212.0902,8.8897238,7.8895588,0.0,0,1.9261373,0.0,0.74647897,53.645046,2.206459,465.93912,-9.200676
2776,2776,212.0904,8.9015207,7.9048719,0.0,0,1.9115355,0.0,0.74754745,53.684158,2.1888955,465.63168,-9.2008257
2777,2777,212.0906,8.9241714,7.9162459,0.0,0,1.8970004,0.0,0.75014699,53.657482,2.173728,465.32425,-9.2011251
2778,2778,212.0908,8.9489183,7.9342618,0.0,0,1.8824685,0.0,0.75305974,53.600182,2.1597044,465.01682,-9.2024345
2779,2779,212.091,8.969924,7.9495034,0.0,0,1.8679364,0.0,0.75404626,53.671055,2.1447115,464.70938,-9.2029533
2780,2780,212.0912,9.0014648,7.961133,0.0,0,1.8534043,0.0,0.75634527,53.726063,2.1289752,464.40195,-9.2023134
2781,2781,212.0914,9.0386219,7.97826,0.0,0,1.8388724,0.0,0.75936228,53.775478,2.1121335,464.09451,-9.2021856
2782,2782,212.0916,9.0734634,7.9965615,0.0,0,1.8243403,0.0,0.76071966,53.920666,2.096065,463.78708,-9.2024126
2783,2783,212.0918,9.1011,8.0115805,0.0,0,1.8098084,0.0,0.76314974,53.959766,2.0818527,463.47964,-9.2018328
2784,2784,212.092,9.1181736,8.0279274,0.0,0,1.7952764,0.0,0.76643139,53.869007,2.0668421,463.17221,-9.2017107
2785,2785,212.0922,9.1319723,8.0470238,0.0,0,1.7807443,0.0,0.76800996,53.855091,2.0513873,462.86478,-9.2022362
2786,2786,212.0924,9.1415215,8.060957,0.0,0,1.7662123,0.0,0.77020329,53.843578,2.035367,462.55734,-9.2015495
2787,2787,212.0926,9.1603537,8.0737505,0.0,0,1.7516804,0.0,0.77321714,53.817234,2.0197532,462.24991,-9.2008333
2788,2788,212.0928,9.1870089,8.0933676,0.0,0,1.7371484,0.0,0.77478677,53.869629,2.0049767,461.94247,-9.2008953
2789,2789,212.093,9.2188463,8.1083479,0.0,0,1.7226164,0.0,0.77684581,53.917419,1.9896139,461.63504,-9.2010384
2790,2790,212.0932,9.2510824,8.1193199,0.0,0,1.7080843,0.0,0.7798332,53.951824,1.9752727,461.32761,-9.2009668
2791,2791,212.0934,9.2848101,8.1387348,0.0,0,1.6935524,0.0,0.78159183,54.075809,1.9595438,461.0202,-9.2016544
2792,2792,212.0936,9.3222456,8.1537905,0.0,0,1.6790204,0.0,0.78331256,54.199383,1.9453068,460.71277,-9.201684
2793,2793,212.0938,9.3414631,8.1628809,0.0,0,1.6644883,0.0,0.78606766,54.191864,1.9312018,460.40533,-9.2010107
2794,2794,212.094,9.3494091,8.1838179,0.0,0,1.6499563,0.0,0.78813386,54.135563,1.9145083,460.0979,-9.2012482
2795,2795,212.0942,9.3645582,8.202035,0.0,0,1.6354244,0.0,0.79006106,54.085842,1.8975136,459.79047,-9.2010889
2796,2796,212.0944,9.3802538,8.2100363,0.0,0,1.6208923,0.0,0.79292971,53.996185,1.8814096,459.48303,-9.2009287
2797,2797,212.0946,9.4013844,8.2296391,0.0,0,1.6063604,0.0,0.79534012,54.002537,1.8676959,459.1756,-9.2016287
2798,2798,212.0948,9.4305,8.2486897,0.0,0,1.5918283,0.0,0.79702497,54.097321,1.8540198,458.86816,-9.2015696
2799,2799,212.095,9.4627638,8.2552156,0.0,0,1.5772964,0.0,0.79942369,54.114304,1.839437,458.56073,-9.2012844
2800,2800,212.0952,9.4935379,8.2732906,0.0,0,1.5630548,0.0,0.80191666,54.148438,1.8254863,458.2533,-9.2017822
2801,2801,212.0954,9.5215816,8.2939615,0.0,0,1.5491644,0.0,0.80357653,54.263474,1.8101261,457.94586,-9.2017717
2802,2802,212.0956,9.546463,8.3003025,0.0,0,1.5353373,0.0,0.80580372,54.302841,1.7947831,457.63843,-9.201416
2803,2803,212.0958,9.5695839,8.3177023,0.0,0,1.5215132,0.0,0.8085463,54.268742,1.7787719,457.33099,-9.2015266
2804,2804,212.096,9.5878525,8.3398571,0.0,0,1.5076892,0.0,0.81035691,54.277718,1.762722,457.02356,-9.2017136
2805,2805,212.0962,9.6080589,8.3458633,0.0,0,1.4938653,0.0,0.81244326,54.273769,1.7480733,456.71613,-9.2012033
2806,2806,212.0964,9.6319199,8.3620739,0.0,0,1.4800413,0.0,0.81545639,54.232822,1.7315916,456.40869,-9.2006674
2807,2807,212.0966,9.6609669,8.3848782,0.0,0,1.4662173,0.0,0.81737196,54.31575,1.7158662,456.10126,-9.2006588
2808,2808,212.0968,9.6937513,8.3902349,0.0,0,1.4523933,0.0,0.81907755,54.385815,1.7022513,456.07974,-9.2010574
2809,2809,212.097,9.7195158,8.4048796,0.0,0,1.4385693,0.0,0.82211059,54.366169,1.6892558,456.0582,-9.2017603
2810,2810,212.0972,9.7519636,8.4286318,0.0,0,1.4247453,0.0,0.82411337,54.446712,1.6758481,456.03668,-9.2018108
2811,2811,212.0974,9.7941217,8.4349594,0.0,0,1.4109213,0.0,0.825629,54.552444,1.6600126,456.01514,-9.2023525
2812,2812,212.0976,9.8306351,8.4480639,0.0,0,1.3970973,0.0,0.82874638,54.612343,1.6455989,455.99362,-9.2021017
2813,2813,212.0978,9.8537474,8.4717112,0.0,0,1.3832734,0.0,0.8308481,54.676125,1.6315863,455.97208,-9.2012844
2814,2814,212.098,9.869791,8.4791126,0.0,0,1.3694494,0.0,0.83213842,54.729076,1.6140984,455.95056,-9.2010918
2815,2815,212.0982,9.8947058,8.4907999,0.0,0,1.3556253,0.0,0.83522445,54.665501,1.599237,455.92902,-9.2012005
2816,2816,212.0984,9.9246759,8.5139713,0.0,0,1.3418013,0.0,0.83751166,54.636593,1.5849524,455.9075,-9.2016335
2817,2817,212.0986,9.9486237,8.522706,0.0,0,1.3279774,0.0,0.83871871,54.734173,1.5724348,455.88596,-9.2017927
2818,2818,212.0988,9.9780893,8.5342579,0.0,0,1.3141534,0.0,0.8418954,54.755112,1.5591069,455.86444,-9.201251
2819,2819,212.099,10.005696,8.557023,0.0,0,1.3003293,0.0,0.84434319,54.762112,1.54506,455.8429,-9.2011881
2820,2820,212.0992,10.036669,8.5667067,0.0,0,1.2865053,0.0,0.84535646,54.871056,1.5333608,455.82138,-9.2011528
2821,2821,212.0994,10.076821,8.5770111,0.0,0,1.2726814,0.0,0.84851134,54.904472,1.5177106,455.79984,-9.20047
2822,2822,212.0996,10.11253,8.5990849,0.0,0,1.2588574,0.0,0.85135174,54.907269,1.5013635,455.77832,-9.2007532
2823,2823,212.0998,10.133222,8.6122026,0.0,0,1.2450334,0.0,0.85231358,54.972099,1.486766,455.75677,-9.2008133
2824,2824,212.1,10.150292,8.6229134,0.0,0,1.2312094,0.0,0.85538572,54.934395,1.4736769,455.73526,-9.2012196
2825,2825,212.1002,10.172528,8.6425982,0.0,0,1.2176627,0.0,0.85843515,54.906036,1.4586374,455.71371,-9.2012587
2826,2826,212.1004,10.201379,8.6559286,0.0,0,1.2044513,0.0,0.85927743,54.986198,1.4440336,455.6922,-9.2007027
2827,2827,212.1006,10.235082,8.6652479,0.0,0,1.1913006,0.0,0.86195719,55.000092,1.4324852,455.67065,-9.2005529
2828,2828,212.1008,10.272834,8.6831999,0.0,0,1.1781524,0.0,0.86504406,55.023251,1.4196793,455.64914,-9.2005024
2829,2829,212.101,10.308336,8.6974669,0.0,0,1.1650045,0.0,0.86589313,55.180737,1.4041399,455.62759,-9.2006998
2830,2830,212.1012,10.341102,8.706337,0.0,0,1.1518564,0.0,0.86821353,55.239208,1.3893018,455.60608,-9.2008486
2831,2831,212.1014,10.379946,8.7217665,0.0,0,1.1387084,0.0,0.8712858,55.242142,1.3759564,455.58453,-9.2008972
2832,2832,212.1016,10.414113,8.7370949,0.0,0,1.1255604,0.0,0.87231958,55.366798,1.3616523,455.56302,-9.2006798
2833,2833,212.1018,10.447204,8.7477474,0.0,0,1.1124125,0.0,0.87464571,55.429867,1.3472406,455.5415,-9.2009106
2834,2834,212.102,10.477007,8.762167,0.0,0,1.0992644,0.0,0.87791854,55.390282,1.3311437,455.51996,-9.201005
2835,2835,212.1022,10.501449,8.7797346,0.0,0,1.0861164,0.0,0.87923485,55.446465,1.3164848,455.49844,-9.2013302
2836,2836,212.1024,10.522366,8.7916079,0.0,0,1.0729684,0.0,0.88147658,55.480503,1.302103,455.4769,-9.2018995
2837,2837,212.1026,10.551587,8.8038416,0.0,0,1.0598203,0.0,0.88477546,55.43182,1.2871586,455.45538,-9.2011948
2838,2838,212.1028,10.587623,8.8225403,0.0,0,1.0466723,0.0,0.88612747,55.514729,1.2729236,455.43384,-9.200634
2839,2839,212.103,10.621375,8.8362913,0.0,0,1.0335244,0.0,0.88815069,55.613075,1.258554,455.41232,-9.1999731
2840,2840,212.1032,10.662498,8.8464642,0.0,0,1.0203763,0.0,0.89149618,55.64463,1.2434194,455.39078,-9.199482
2841,2841,212.1034,10.707063,8.8645687,0.0,0,1.0072284,0.0,0.89339274,55.714321,1.2309173,455.36926,-9.199913
2842,2842,212.1036,10.743273,8.8789024,0.0,0,0.99408036,0.0,0.89519042,55.811821,1.2185204,455.34772,-9.2000065
2843,2843,212.1038,10.767822,8.8869686,0.0,0,0.98093235,0.0,0.8981002,55.830624,1.2054662,455.3262,-9.2001715
2844,2844,212.104,10.792274,8.9054174,0.0,0,0.96778435,0.0,0.90022796,55.835258,1.1917925,455.30466,-9.2005711
2845,2845,212.1042,10.820157,8.9205704,0.0,0,0.95463634,0.0,0.9019863,55.874893,1.1775535,455.28314,-9.2011299
2846,2846,212.1044,10.847852,8.9261265,0.0,0,0.94148839,0.0,0.90474397,55.868793,1.1641104,455.2616,-9.2023878
2847,2847,212.1046,10.884395,8.9441175,0.0,0,0.92834044,0.0,0.90681624,55.925449,1.1481119,455.24008,-9.2026434
2848,2848,212.1048,10.920403,8.9612513,0.0,0,0.91519243,0.0,0.9082728,56.041622,1.134179,455.21854,-9.2021894
2849,2849,212.105,10.955606,8.9657478,0.0,0,0.90204442,0.0,0.91079271,56.079288,1.1213969,455.19702,-9.2019701
2850,2850,212.1052,11.005026,8.9827576,0.0,0,0.88916051,0.0,0.9132871,56.167805,1.1063612,455.17548,-9.2011423
2851,2851,212.1054,11.04747,9.0023003,0.0,0,0.87659609,0.0,0.91497767,56.307949,1.0929041,455.15396,-9.2005148
2852,2852,212.1056,11.082927,9.0072145,0.0,0,0.86408949,0.0,0.91740692,56.35532,1.082755,455.13242,-9.1997452
2853,2853,212.1058,11.10878,9.0236645,0.0,0,0.85158539,0.0,0.92022812,56.344219,1.0685486,455.1109,-9.199357
2854,2854,212.106,11.124189,9.0449657,0.0,0,0.83908135,0.0,0.92195362,56.347202,1.051949,455.08936,-9.2000866
2855,2855,212.1062,11.153677,9.0496769,0.0,0,0.82657731,0.0,0.92416507,56.342213,1.0396032,455.06784,-9.2012148
2856,2856,212.1064,11.187431,9.0647945,0.0,0,0.81407332,0.0,0.92738473,56.316849,1.0273491,455.0463,-9.2019186
2857,2857,212.1066,11.218467,9.0864744,0.0,0,0.8015694,0.0,0.92915767,56.367012,1.0133873,455.02478,-9.2019749
2858,2858,212.1068,11.260846,9.0901594,0.0,0,0.78906536,0.0,0.93083137,56.453083,1.0005077,455.00562,-9.2014828
2859,2859,212.107,11.308899,9.1034937,0.0,0,0.77656138,0.0,0.93410438,56.50906,0.98796022,454.98645,-9.2003603
2860,2860,212.1072,11.359301,9.1259375,0.0,0,0.7640574,0.0,0.93611097,56.666939,0.97270238,454.96729,-9.200058
2861,2861,212.1074,11.411105,9.1304436,0.0,0,0.75155336,0.0,0.93755752,56.840492,0.95781714,454.94812,-9.1996775
2862,2862,212.1076,11.446017,9.1419401,0.0,0,0.73904938,0.0,0.94074041,56.838451,0.94386995,454.92896,-9.1991596
2863,2863,212.1078,11.468191,9.163991,0.0,0,0.72654539,0.0,0.94267285,56.854088,0.93110901,454.90979,-9.1991358
2864,2864,212.108,11.492446,9.1696844,0.0,0,0.71404135,0.0,0.94395941,56.896915,0.91778129,454.89066,-9.1996717
2865,2865,212.1082,11.517454,9.1805925,0.0,0,0.70153737,0.0,0.94746006,56.829659,0.90532511,454.87149,-9.1999817
2866,2866,212.1084,11.55458,9.2037191,0.0,0,0.68903339,0.0,0.94985467,56.870029,0.8946318,454.85233,-9.2005882
2867,2867,212.1086,11.594964,9.211256,0.0,0,0.67652941,0.0,0.95097536,56.979832,0.88173604,454.83316,-9.2012501
2868,2868,212.1088,11.63026,9.2204828,0.0,0,0.66402543,0.0,0.95427817,56.971565,0.86874419,454.814,-9.2009315
2869,2869,212.109,11.676514,9.2410364,0.0,0,0.65152138,0.0,0.95674491,57.043221,0.8554036,454.79483,-9.2007828
2870,2870,212.1092,11.72602,9.249548,0.0,0,0.63901734,0.0,0.95754015,57.236752,0.84176499,454.77567,-9.2005901
2871,2871,212.1094,11.770685,9.258585,0.0,0,0.62651336,0.0,0.96073717,57.297905,0.82859904,454.7565,-9.2004948
2872,2872,212.1096,11.805929,9.2791014,0.0,0,0.61400938,0.0,0.96365631,57.321205,0.81545085,454.73734,-9.1997442
2873,2873,212.1098,11.83721,9.2903299,0.0,0,0.6015054,0.0,0.96450472,57.430645,0.80084896,454.71817,-9.1990089
2874,2874,212.11,11.870627,9.2990112,0.0,0,0.58900136,0.0,0.96767813,57.391041,0.78662515,454.69901,-9.1988239
2875,2875,212.1102,11.906913,9.3186178,0.0,0,0.57674509,0.0,0.97097558,57.361462,0.77346569,454.67984,-9.1994343
2876,2876,212.1104,11.953391,9.3317003,0.0,0,0.56478846,0.0,0.97173321,57.521626,0.75973654,454.66071,-9.200201
2877,2877,212.1106,12.000763,9.3400793,0.0,0,0.55288601,0.0,0.97455311,57.609962,0.74713314,454.64154,-9.2003565
2878,2878,212.1108,12.04736,9.3561659,0.0,0,0.54098594,0.0,0.9777711,57.665409,0.73461086,454.62238,-9.200098
2879,2879,212.111,12.101616,9.368331,0.0,0,0.52908593,0.0,0.97844416,57.871147,0.72107321,454.60321,-9.2000942
2880,2880,212.1112,12.154937,9.3768024,0.0,0,0.51718587,0.0,0.98095345,57.990311,0.70900643,454.58405,-9.2005873
2881,2881,212.1114,12.197445,9.392292,0.0,0,0.50528592,0.0,0.98424572,57.994099,0.69639099,454.56488,-9.2001858
2882,2882,212.1116,12.228569,9.406827,0.0,0,0.49338591,0.0,0.98512745,58.1003,0.6822688,454.54572,-9.1999083
2883,2883,212.1118,12.254227,9.4161825,0.0,0,0.4814859,0.0,0.98762339,58.065853,0.66843665,454.52655,-9.1996145
2884,2884,212.112,12.278365,9.4303284,0.0,0,0.4695859,0.0,0.99130309,57.949234,0.6548332,454.50739,-9.1997881
2885,2885,212.1122,12.306397,9.4467459,0.0,0,0.45768592,0.0,0.99260372,58.041656,0.64246678,454.48822,-9.2000189
2886,2886,212.1124,12.348496,9.4572773,0.0,0,0.44578591,0.0,0.9947868,58.136715,0.62988186,454.46906,-9.1997128
2887,2887,212.1126,12.400826,9.4685183,0.0,0,0.4338859,0.0,0.99816722,58.159527,0.61706293,454.44989,-9.199441
2888,2888,212.1128,12.445567,9.4852619,0.0,0,0.42198589,0.0,0.99952155,58.270493,0.60396832,454.43073,-9.1990099
2889,2889,212.113,12.492324,9.4955864,0.0,0,0.41008592,0.0,1.0013995,58.397892,0.59082448,454.41159,-9.1989794
2890,2890,212.1132,12.540371,9.5029535,0.0,0,0.39818591,0.0,1.0046115,58.43784,0.58039254,454.39243,-9.1989737