File: examples/hot axisymmetric compression example/data/03 trimmed data/testID_0132.csv
level_0,index,Time(sec),Force(kN),Jaw(mm),PowAngle(deg),Power(W),Pram,PTemp,Strain,Stress(MPa),Stroke(mm),TC1(C),wedge(mm)
1773,1773,145.3439,0.48595235,0.046863034,0.0,0,9.0336914,0.0,0.0029801505,5.9371953,10.035624,302.31415,-9.3252954
1775,1775,145.3443,2.5057325,0.069299914,0.0,0,8.9751635,0.0,0.0046001635,27.08316,9.9516277,302.57858,-9.3259897
1777,1777,145.3447,5.6528659,0.13554043,0.0,0,8.9166355,0.0,0.0085107693,68.849358,9.8903818,302.84302,-9.3243046
1779,1779,145.3451,6.616365,0.17955042,0.0,0,8.8581076,0.0,0.011563532,82.214897,9.8258114,303.10748,-9.3209686
1781,1781,145.3455,7.5038505,0.30156913,0.0,0,8.7995796,0.0,0.019515907,93.020203,9.7432623,303.37192,-9.3193054
1783,1783,145.3459,7.8089981,0.4131965,0.0,0,8.7416391,0.0,0.027187278,95.918709,9.6416073,303.63635,-9.3199987
1785,1785,145.3463,8.659667,0.48920563,0.0,0,8.6858358,0.0,0.032477558,105.90292,9.5374994,303.90079,-9.3199062
1787,1787,145.3467,9.1537657,0.57159173,0.0,0,8.6301718,0.0,0.038582537,111.23672,9.4529486,304.16522,-9.319438
1789,1789,145.3471,9.4395494,0.60397226,0.0,0,8.5745077,0.0,0.040564995,115.91578,9.3775616,304.42969,-9.3171587
1791,1791,145.3475,9.1060486,0.6652503,0.0,0,8.5188437,0.0,0.045004513,110.5875,9.317009,304.69412,-9.3173285
1793,1793,145.3479,9.6239338,0.71893162,0.0,0,8.4631796,0.0,0.048828773,116.25664,9.2569551,304.95856,-9.3188019
1795,1795,145.3483,9.9864082,0.77840769,0.0,0,8.4075155,0.0,0.05251142,120.11056,9.1940069,305.22299,-9.3175726
1797,1797,145.3487,10.098038,0.87873399,0.0,0,8.3518515,0.0,0.059781276,121.54702,9.1155424,305.48743,-9.3165159
1799,1799,145.3491,9.7758846,0.96905285,0.0,0,8.2961874,0.0,0.066025637,116.45129,9.0335789,305.75189,-9.316349
1801,1801,145.3495,10.154439,1.0564793,0.0,0,8.2405233,0.0,0.072405547,119.86536,8.948698,306.01633,-9.3167953
1803,1803,145.3499,10.175343,1.1063942,0.0,0,8.1848602,0.0,0.076612458,119.81683,8.8746815,306.28076,-9.317543
1805,1805,145.3503,10.58254,1.1416467,0.0,0,8.1291962,0.0,0.07852523,124.34261,8.8069992,306.5452,-9.3175106
1807,1807,145.3507,10.281699,1.2093796,0.0,0,8.0735312,0.0,0.083785281,120.85067,8.7526522,306.80963,-9.3170633
1809,1809,145.3511,10.526853,1.2491795,0.0,0,8.0196486,0.0,0.086745836,122.32267,8.6992769,307.0741,-9.3180618
1811,1811,145.3515,10.715414,1.3122951,0.0,0,7.9666824,0.0,0.090793774,124.54664,8.643198,307.33853,-9.3183098
1813,1813,145.3519,10.763949,1.3907238,0.0,0,7.9137225,0.0,0.097181186,124.31467,8.5781174,307.60297,-9.3162279
1815,1815,145.3523,10.6746,1.4624104,0.0,0,7.8607621,0.0,0.10185686,122.91405,8.5122957,307.84357,-9.3158455
1817,1817,145.3527,10.765322,1.5366082,0.0,0,7.8078027,0.0,0.10749457,122.90701,8.4429893,308.0762,-9.3159676
1819,1819,145.3531,10.845127,1.5717976,0.0,0,7.7548423,0.0,0.11086278,123.55598,8.3829088,308.30887,-9.3164606
1821,1821,145.3535,10.991618,1.617704,0.0,0,7.7018824,0.0,0.11333983,124.75441,8.3251629,308.5415,-9.3171158
1823,1823,145.3539,10.928802,1.6723835,0.0,0,7.648922,0.0,0.11800154,123.85725,8.2767401,308.77417,-9.316968
1825,1825,145.3543,11.078884,1.7065918,0.0,0,7.5959625,0.0,0.12072743,124.61807,8.2264214,309.00681,-9.3167496
1827,1827,145.3547,11.223829,1.7738726,0.0,0,7.5430021,0.0,0.12491523,126.12695,8.1759071,309.23947,-9.3153448
1829,1829,145.3551,11.200974,1.828559,0.0,0,7.4900427,0.0,0.12974922,125.18023,8.117506,309.47211,-9.3149891
1831,1831,145.3555,11.246924,1.8872795,0.0,0,7.4370823,0.0,0.13394341,125.31445,8.0597868,309.70477,-9.3154259
1833,1833,145.3559,11.208066,1.9562832,0.0,0,7.3846536,0.0,0.1389633,124.10149,8.0025978,309.93741,-9.3167067
1835,1835,145.3563,11.388322,1.9859102,0.0,0,7.3341594,0.0,0.14209738,125.60752,7.9483943,310.17007,-9.3177423
1837,1837,145.3567,11.420402,2.0355265,0.0,0,7.2837911,0.0,0.1451741,125.83624,7.8957944,310.40271,-9.317297
1839,1839,145.3571,11.416974,2.0909884,0.0,0,7.2334232,0.0,0.14962262,125.14433,7.8498912,310.63538,-9.3164139
1841,1841,145.3575,11.448411,2.123255,0.0,0,7.1830549,0.0,0.15260501,125.07859,7.8033719,310.86801,-9.3161497
1843,1843,145.3579,11.604254,2.1800959,0.0,0,7.1326866,0.0,0.15635091,126.1018,7.7590432,311.10068,-9.3155384
1845,1845,145.3583,11.680368,2.2326384,0.0,0,7.0823188,0.0,0.16084681,126.7383,7.706172,311.33331,-9.3158398
1847,1847,145.3587,11.657157,2.2831628,0.0,0,7.031951,0.0,0.16487557,125.95163,7.6555681,311.56598,-9.3161201
1849,1849,145.3591,11.675376,2.33514,0.0,0,6.9815826,0.0,0.16866764,125.49773,7.6035972,311.79861,-9.3167944
1851,1851,145.3595,11.782069,2.3753376,0.0,0,6.9312148,0.0,0.17229559,126.11736,7.552062,312.03128,-9.317379
1853,1853,145.3599,11.860147,2.4248588,0.0,0,6.8808465,0.0,0.17582832,126.64497,7.5037088,312.26395,-9.3172817
1855,1855,145.3603,11.879191,2.4713626,0.0,0,6.8304791,0.0,0.17949212,126.2753,7.45715,312.49658,-9.3159513
1857,1857,145.3607,11.94117,2.5143871,0.0,0,6.7801108,0.0,0.1834054,126.41058,7.4078751,312.72925,-9.3159313
1859,1859,145.3611,12.004824,2.5674047,0.0,0,6.7313552,0.0,0.18706438,126.7494,7.3615322,312.96188,-9.3167629
1861,1861,145.3615,12.080425,2.6121964,0.0,0,6.6834297,0.0,0.19096085,126.93462,7.312438,313.19455,-9.3173723
1863,1863,145.3619,12.093709,2.6630957,0.0,0,6.63551,0.0,0.19540149,126.58804,7.2635326,313.42719,-9.3187666
1865,1865,145.3623,12.171521,2.7157469,0.0,0,6.5875897,0.0,0.19902819,126.87074,7.2142496,313.45224,-9.3172874
1867,1867,145.3627,12.247671,2.758173,0.0,0,6.53967,0.0,0.20291761,127.2907,7.1640081,313.4082,-9.3161077
1869,1869,145.3631,12.292533,2.8076999,0.0,0,6.4917502,0.0,0.20687667,127.18702,7.1160946,313.36417,-9.3158941
1871,1871,145.3635,12.30547,2.8614647,0.0,0,6.44383,0.0,0.21079344,126.9966,7.0671039,313.32016,-9.3165827
1873,1873,145.3639,12.395163,2.9026887,0.0,0,6.3959093,0.0,0.21497636,127.2411,7.0203128,313.27612,-9.3176413
1875,1875,145.3643,12.493302,2.9501719,0.0,0,6.3479896,0.0,0.21854044,127.78634,6.9709177,313.23209,-9.3176813
1877,1877,145.3647,12.545019,3.0045164,0.0,0,6.3000698,0.0,0.22281344,127.82558,6.9251204,313.18805,-9.3168201
1879,1879,145.3651,12.534706,3.0497184,0.0,0,6.2521501,0.0,0.22725107,127.16986,6.8728747,313.14401,-9.3166771
1881,1881,145.3655,12.599799,3.0973668,0.0,0,6.2042303,0.0,0.23060182,127.30973,6.823247,313.09998,-9.3164768
1883,1883,145.3659,12.717048,3.1525409,0.0,0,6.1567912,0.0,0.23549025,127.86301,6.7738171,313.05594,-9.3173037
1885,1885,145.3663,12.775563,3.1943636,0.0,0,6.1111007,0.0,0.23935436,128.0372,6.7227707,313.0119,-9.3176632
1887,1887,145.3667,12.821433,3.2441916,0.0,0,6.0655246,0.0,0.24291351,128.06897,6.6767626,312.96786,-9.3164234
1889,1889,145.3671,12.862032,3.2956083,0.0,0,6.019949,0.0,0.24794079,127.69572,6.6226254,312.92383,-9.3168983
1891,1891,145.3675,12.942324,3.3390977,0.0,0,5.9743724,0.0,0.25149545,128.04837,6.5760984,312.87979,-9.3166561
1893,1893,145.3679,13.049384,3.3931844,0.0,0,5.9287963,0.0,0.25565362,128.53404,6.5289049,312.83575,-9.3165598
1895,1895,145.3683,13.075983,3.4414499,0.0,0,5.8832207,0.0,0.26067302,128.3073,6.4777741,312.79172,-9.3167782
1897,1897,145.3687,13.118585,3.4909685,0.0,0,5.8376446,0.0,0.26427117,128.17444,6.4270406,312.74768,-9.3166857
1899,1899,145.3691,13.161179,3.5414712,0.0,0,5.792068,0.0,0.26870215,128.06818,6.3789692,312.70364,-9.3168831
1901,1901,145.3695,13.243287,3.5825744,0.0,0,5.7464924,0.0,0.27298284,128.23093,6.3278389,312.65961,-9.3178873
1903,1903,145.3699,13.323252,3.6356659,0.0,0,5.7009163,0.0,0.27670673,128.59283,6.2826467,312.61557,-9.3168621
1905,1905,145.3703,13.371292,3.6825376,0.0,0,5.6553407,0.0,0.28133219,128.44408,6.2338758,312.57153,-9.3175783
1907,1907,145.3707,13.435526,3.7247005,0.0,0,5.6097641,0.0,0.28533375,128.53426,6.1857314,312.5275,-9.3173265
1909,1909,145.3711,13.484893,3.7823794,0.0,0,5.5656476,0.0,0.28953767,128.44589,6.1380243,312.48346,-9.3163376
1911,1911,145.3715,13.54546,3.8244486,0.0,0,5.5222831,0.0,0.29418182,128.54884,6.0881515,312.43942,-9.3161917
1913,1913,145.3719,13.63042,3.8722301,0.0,0,5.4789228,0.0,0.29817677,128.71298,6.0397887,312.39539,-9.3164806
1915,1915,145.3723,13.66688,3.9281003,0.0,0,5.4355626,0.0,0.30283359,128.57204,5.9922256,312.15732,-9.3169909
1917,1917,145.3727,13.739833,3.9667037,0.0,0,5.3922029,0.0,0.30713481,128.54977,5.9440675,311.85468,-9.3176193
1919,1919,145.3731,13.789521,4.0159268,0.0,0,5.3488426,0.0,0.31093022,128.52162,5.8982601,311.552,-9.3184214
1921,1921,145.3735,13.856441,4.0687757,0.0,0,5.3054829,0.0,0.31585208,128.54669,5.8487635,311.24936,-9.3170509
1923,1923,145.3739,13.947438,4.106832,0.0,0,5.2621226,0.0,0.31992856,128.91447,5.8016691,310.94669,-9.3163195
1925,1925,145.3743,13.994882,4.1582437,0.0,0,5.2187629,0.0,0.32385543,128.79176,5.7550721,310.64401,-9.3157072
1927,1927,145.3747,14.036995,4.2070546,0.0,0,5.1754031,0.0,0.32892662,128.60497,5.7049971,310.34137,-9.3154106
1929,1929,145.3751,14.088339,4.2495651,0.0,0,5.1320429,0.0,0.33285624,128.56827,5.6557002,310.0387,-9.3165054
1931,1931,145.3755,14.151876,4.3001986,0.0,0,5.0886827,0.0,0.33698389,128.6058,5.6115065,309.73605,-9.3176603
1933,1933,145.3759,14.241361,4.3447342,0.0,0,5.0457578,0.0,0.3419891,128.71121,5.5660896,309.43338,-9.3170214
1935,1935,145.3763,14.28328,4.3895702,0.0,0,5.0044141,0.0,0.3456555,128.72235,5.5161238,309.13074,-9.3168621
1937,1937,145.3767,14.328567,4.4363637,0.0,0,4.9631739,0.0,0.34989616,128.44659,5.4717116,308.82806,-9.3172817
1939,1939,145.3771,14.377374,4.479043,0.0,0,4.9219337,0.0,0.35481244,128.27435,5.4275494,308.52539,-9.3166294
1941,1941,145.3775,14.446808,4.5280714,0.0,0,4.8806939,0.0,0.35853049,128.45309,5.3798857,308.22275,-9.3167105
1943,1943,145.3779,14.522292,4.5713339,0.0,0,4.8394537,0.0,0.36302814,128.53014,5.3332591,307.92007,-9.3160114
1945,1945,145.3783,14.575896,4.6136317,0.0,0,4.798214,0.0,0.36754161,128.43576,5.2841992,307.61743,-9.3165598
1947,1947,145.3787,14.625874,4.6675763,0.0,0,4.7569737,0.0,0.3717663,128.37032,5.2436962,307.31476,-9.3182554
1949,1949,145.3791,14.676018,4.7079244,0.0,0,4.7157335,0.0,0.37642971,128.24864,5.198473,307.01212,-9.3176489
1951,1951,145.3795,14.760394,4.750041,0.0,0,4.6744938,0.0,0.38053936,128.40665,5.1543183,306.70944,-9.3162584
1953,1953,145.3799,14.838024,4.8010712,0.0,0,4.6332541,0.0,0.38474354,128.54646,5.109879,306.4068,-9.3158855
1955,1955,145.3803,14.905247,4.8376012,0.0,0,4.5920134,0.0,0.38933215,128.48515,5.0647058,306.10413,-9.3159113
1957,1957,145.3807,14.942702,4.8833995,0.0,0,4.5507736,0.0,0.39330208,128.35768,5.0210142,305.80145,-9.3173971
1959,1959,145.3811,14.984212,4.9366126,0.0,0,4.5108562,0.0,0.39821142,128.09392,4.9788361,305.49881,-9.3178835
1961,1961,145.3815,15.060888,4.9720769,0.0,0,4.4716201,0.0,0.40272865,128.08653,4.9342141,305.19614,-9.3169613
1963,1963,145.3819,15.142141,5.0167546,0.0,0,4.4323878,0.0,0.40640396,128.33952,4.8906355,304.89349,-9.3157244
1965,1965,145.3823,15.199157,5.0642648,0.0,0,4.3931556,0.0,0.41138703,128.22459,4.8489532,304.60922,-9.3154345
1967,1967,145.3827,15.228462,5.0988469,0.0,0,4.3539243,0.0,0.4153547,127.99229,4.8068676,304.33112,-9.317832
1969,1969,145.3831,15.285192,5.1443114,0.0,0,4.314692,0.0,0.4191516,127.92776,4.7594519,304.05298,-9.3174438
1971,1971,145.3835,15.38324,5.1865249,0.0,0,4.2754598,0.0,0.42422941,128.12422,4.7211199,303.77484,-9.3176003
1973,1973,145.3839,15.466925,5.2248302,0.0,0,4.2362275,0.0,0.42795157,128.34283,4.6782069,303.4967,-9.3167458
1975,1975,145.3843,15.50408,5.273181,0.0,0,4.1969957,0.0,0.43228859,128.06738,4.6351628,303.21857,-9.3146801
1977,1977,145.3847,15.543545,5.3125334,0.0,0,4.157764,0.0,0.4374297,127.78857,4.5955486,302.94046,-9.3154068
1979,1979,145.3851,15.61842,5.3533559,0.0,0,4.1185317,0.0,0.44084039,127.86349,4.552341,302.66232,-9.318594
1981,1981,145.3855,15.695856,5.3946013,0.0,0,4.0792999,0.0,0.44512627,127.94102,4.5064621,302.38419,-9.3173399
1983,1983,145.3859,15.783778,5.4312253,0.0,0,4.040462,0.0,0.44973353,128.04259,4.4706955,302.10605,-9.3168316
1985,1985,145.3863,15.821348,5.4792147,0.0,0,4.0030565,0.0,0.45367059,127.95769,4.4300284,301.82794,-9.3159008
1987,1987,145.3867,15.878031,5.5171885,0.0,0,3.965744,0.0,0.4581621,127.8063,4.3876491,301.5498,-9.3154078
1989,1989,145.3871,15.95125,5.5524378,0.0,0,3.928432,0.0,0.46212047,127.87596,4.3464365,301.27167,-9.3165932
1991,1991,145.3875,16.046568,5.5985351,0.0,0,3.89112,0.0,0.46606255,128.09833,4.3091674,300.99353,-9.3174782
1993,1993,145.3879,16.113625,5.6312428,0.0,0,3.8538082,0.0,0.4706521,128.08011,4.2651939,300.71542,-9.3181276
1995,1995,145.3883,16.149536,5.6699429,0.0,0,3.8164961,0.0,0.47443473,127.96455,4.2300372,300.43729,-9.3177843
1997,1997,145.3887,16.192078,5.7189937,0.0,0,3.7791839,0.0,0.47905153,127.6472,4.1906433,300.15915,-9.3168297
1999,1999,145.3891,16.272188,5.7483706,0.0,0,3.7418718,0.0,0.48342273,127.66733,4.1503153,299.88101,-9.3159962
2001,2001,145.3895,16.376244,5.7878714,0.0,0,3.70456,0.0,0.48676535,128.11856,4.1173248,299.60291,-9.3168869
2003,2003,145.3899,16.444502,5.8337045,0.0,0,3.667248,0.0,0.49169686,127.99237,4.0746765,299.32477,-9.3179398
2005,2005,145.3903,16.483822,5.863152,0.0,0,3.629936,0.0,0.49578485,127.79208,4.0365224,299.04663,-9.317193
2007,2007,145.3907,16.545973,5.9054837,0.0,0,3.5926239,0.0,0.49944493,127.73529,3.9962664,298.76849,-9.3163538
2009,2009,145.3911,16.634779,5.9446497,0.0,0,3.5565078,0.0,0.50454634,127.81157,3.9586082,298.49039,-9.3164749
2011,2011,145.3915,16.728588,5.9764328,0.0,0,3.521008,0.0,0.5080837,128.0943,3.923517,298.21225,-9.3163996
2013,2013,145.3919,16.784481,6.0179768,0.0,0,3.4855118,0.0,0.51197684,128.0024,3.887635,297.93411,-9.3157406
2015,2015,145.3923,16.849974,6.0556717,0.0,0,3.450016,0.0,0.51710176,127.85854,3.8493595,297.83887,-9.3167305
2017,2017,145.3927,16.923229,6.0920653,0.0,0,3.41452,0.0,0.52063125,127.95065,3.8129158,297.80447,-9.3168812
2019,2019,145.3931,17.000141,6.1306658,0.0,0,3.3790238,0.0,0.5246557,128.03156,3.7744374,297.77008,-9.3169127
2021,2021,145.3935,17.083683,6.164752,0.0,0,3.343528,0.0,0.52953941,128.04028,3.7342753,297.73569,-9.3154802
2023,2023,145.3939,17.170233,6.2057953,0.0,0,3.308032,0.0,0.53312707,128.22296,3.6990218,297.70129,-9.3147316
2025,2025,145.3943,17.228601,6.2434397,0.0,0,3.2725358,0.0,0.5377779,128.10423,3.6628618,297.6669,-9.3165312
2027,2027,145.3947,17.306942,6.276257,0.0,0,3.2370398,0.0,0.54227352,128.06357,3.622838,297.63251,-9.3172655
2029,2029,145.3951,17.388716,6.3208261,0.0,0,3.2015438,0.0,0.54600197,128.17442,3.5893693,297.59811,-9.318222
2031,2031,145.3955,17.495571,6.3513665,0.0,0,3.1660478,0.0,0.5505299,128.38898,3.5506649,297.56372,-9.3164721
2033,2033,145.3959,17.572805,6.3843002,0.0,0,3.1309066,0.0,0.55417222,128.52295,3.5146654,297.52933,-9.3157196
2035,2035,145.3963,17.633718,6.4310007,0.0,0,3.097054,0.0,0.55851436,128.35631,3.4752934,297.49493,-9.3156853
2037,2037,145.3967,17.701675,6.4598465,0.0,0,3.0632861,0.0,0.5635618,128.22237,3.4414494,297.46054,-9.3165636
2039,2039,145.3971,17.803822,6.4985948,0.0,0,3.0295181,0.0,0.56712425,128.43217,3.4043651,297.42615,-9.3165321
2041,2041,145.3975,17.901194,6.5417089,0.0,0,2.99575,0.0,0.57200813,128.55235,3.3664486,297.39178,-9.3163548
2043,2043,145.3979,17.998005,6.5678945,0.0,0,2.9619823,0.0,0.57613993,128.77299,3.3305182,297.35739,-9.3154659
2045,2045,145.3983,18.070143,6.6074424,0.0,0,2.9282138,0.0,0.57978249,128.80537,3.2945759,297.323,-9.3156509
2047,2047,145.3987,18.14879,6.6486568,0.0,0,2.8944459,0.0,0.58514965,128.64845,3.2597582,297.2886,-9.316515
2049,2049,145.3991,18.243259,6.6782203,0.0,0,2.860678,0.0,0.58917427,128.82166,3.2241805,297.25421,-9.3160238
2051,2051,145.3995,18.360291,6.7190561,0.0,0,2.82691,0.0,0.59309036,129.11925,3.1879947,297.21982,-9.3158178
2053,2053,145.3999,18.445343,6.7553759,0.0,0,2.7931418,0.0,0.59839922,129.08684,3.1508307,297.18542,-9.3146734
2055,2055,145.4003,18.518465,6.7874594,0.0,0,2.7593739,0.0,0.60198075,129.11887,3.115792,297.15103,-9.3144417
2057,2057,145.4007,18.604385,6.8262606,0.0,0,2.725606,0.0,0.60619026,129.09332,3.0814891,297.11664,-9.3157568
2059,2059,145.4011,18.71855,6.8591499,0.0,0,2.6929231,0.0,0.61144912,129.24054,3.0423629,297.08224,-9.3162613
2061,2061,145.4015,18.832317,6.895977,0.0,0,2.6607995,0.0,0.61492503,129.56549,3.0081792,297.04785,-9.3154097
2063,2063,145.4019,18.933647,6.9334369,0.0,0,2.6286793,0.0,0.61972785,129.61412,2.971312,297.01346,-9.3143978
2065,2065,145.4023,18.99666,6.9627485,0.0,0,2.5965593,0.0,0.62436944,129.47749,2.9351792,296.80838,-9.3151541
2067,2067,145.4027,19.084354,7.0048614,0.0,0,2.5644393,0.0,0.62807393,129.55629,2.9006441,296.54648,-9.3154516
2069,2069,145.4031,19.19701,7.0365696,0.0,0,2.5323191,0.0,0.63297838,129.74536,2.8646696,296.28458,-9.3158855
2071,2071,145.4035,19.315409,7.0693383,0.0,0,2.5001993,0.0,0.63727254,129.95815,2.8329511,296.02267,-9.3157349
2073,2073,145.4039,19.408175,7.1142402,0.0,0,2.4680793,0.0,0.6415627,130.02319,2.7977238,295.76077,-9.3145142
2075,2075,145.4043,19.477581,7.140727,0.0,0,2.4359593,0.0,0.64633781,129.85991,2.7620592,295.49887,-9.314887
2077,2077,145.4047,19.563946,7.1702428,0.0,0,2.4038393,0.0,0.64982045,130.02217,2.7307401,295.23694,-9.3154583
2079,2079,145.4051,19.691189,7.2127824,0.0,0,2.3717194,0.0,0.65434653,130.20294,2.6969476,294.97504,-9.3159418
2081,2081,145.4055,19.817305,7.2371645,0.0,0,2.3395991,0.0,0.65896428,130.45149,2.6642585,294.71313,-9.3153458
2083,2083,145.4059,19.898659,7.2747502,0.0,0,2.3078012,0.0,0.662754,130.55896,2.6283984,294.45123,-9.3149576
2085,2085,145.4063,19.979452,7.316958,0.0,0,2.2771728,0.0,0.66818273,130.36319,2.5951331,294.18933,-9.3155069
2087,2087,145.4067,20.083271,7.3403511,0.0,0,2.2466204,0.0,0.67241764,130.48045,2.5619409,293.92743,-9.3150949
2089,2089,145.4071,20.217361,7.3772855,0.0,0,2.2160687,0.0,0.67575902,130.86665,2.5290396,293.66553,-9.3151865
2091,2091,145.4075,20.337152,7.410419,0.0,0,2.1855166,0.0,0.68107462,130.98997,2.4955158,293.40363,-9.3142681
2093,2093,145.4079,20.416977,7.4377499,0.0,0,2.1549647,0.0,0.68481153,131.02245,2.462229,293.14169,-9.3148699
2095,2095,145.4083,20.509829,7.4771166,0.0,0,2.1244125,0.0,0.68892813,131.05246,2.4302471,292.87979,-9.3149414
2097,2097,145.4087,20.614857,7.505754,0.0,0,2.0938606,0.0,0.69424766,130.97842,2.3947897,292.61789,-9.3144779
2099,2099,145.4091,20.742485,7.5376868,0.0,0,2.0633087,0.0,0.69762754,131.39825,2.365823,292.35599,-9.3148575
2101,2101,145.4095,20.86581,7.57304,0.0,0,2.0327568,0.0,0.70208591,131.61195,2.3317711,292.09409,-9.3152256
2103,2103,145.4099,20.95722,7.5999227,0.0,0,2.0022047,0.0,0.70716482,131.48332,2.2971528,291.83218,-9.3148308
2105,2105,145.4103,21.047943,7.6368766,0.0,0,1.9716525,0.0,0.71060199,131.65779,2.2689917,291.57028,-9.3140039
2107,2107,145.4107,21.169374,7.6690683,0.0,0,1.9411005,0.0,0.71552873,131.71156,2.2376695,291.30838,-9.3142233
2109,2109,145.4111,21.30599,7.6932774,0.0,0,1.9115282,0.0,0.71955824,131.99937,2.2026865,291.04648,-9.3147802
2111,2111,145.4115,21.427582,7.7342219,0.0,0,1.8824612,0.0,0.72352803,132.22728,2.1725261,290.78455,-9.3150692
2113,2113,145.4119,21.524277,7.7620239,0.0,0,1.8533971,0.0,0.72853327,132.20978,2.1406074,290.52264,-9.3147392
2115,2115,145.4123,21.615974,7.7910886,0.0,0,1.8243332,0.0,0.73241735,132.27069,2.108043,290.25687,-9.3136501
2117,2117,145.4127,21.74268,7.829442,0.0,0,1.7952691,0.0,0.73667747,132.42038,2.0784755,289.98978,-9.314271
2119,2119,145.4131,21.878857,7.8490644,0.0,0,1.7662052,0.0,0.74122488,132.64383,2.0479021,289.72269,-9.3138275
2121,2121,145.4135,22.004814,7.8807969,0.0,0,1.7371411,0.0,0.74468714,132.96449,2.0171866,289.4556,-9.3146973
2123,2123,145.4139,22.112856,7.9217968,0.0,0,1.7080772,0.0,0.74989635,132.92326,1.9851698,289.18851,-9.3142776
2125,2125,145.4143,22.224842,7.9434538,0.0,0,1.6790133,0.0,0.75449765,132.99124,1.9552783,288.92139,-9.3147421
2127,2127,145.4147,22.359474,7.9776425,0.0,0,1.6499492,0.0,0.75788158,133.35558,1.9233854,288.6543,-9.3135681
2129,2129,145.4151,22.513319,8.0110846,0.0,0,1.6208851,0.0,0.76335305,133.4924,1.8924642,288.38721,-9.3134336
2131,2131,145.4155,22.63652,8.0317421,0.0,0,1.5918212,0.0,0.76691693,133.8145,1.864078,288.12012,-9.3130836
2133,2133,145.4159,22.741468,8.067318,0.0,0,1.5630479,0.0,0.77066207,133.94783,1.8346001,287.85303,-9.3139591
2135,2135,145.4163,22.854557,8.0968275,0.0,0,1.5353305,0.0,0.77628583,133.82426,1.8047569,287.58594,-9.3143587
2137,2137,145.4167,22.982779,8.1236849,0.0,0,1.5076824,0.0,0.77961063,134.14717,1.7736166,287.31885,-9.3136091
2139,2139,145.4171,23.140074,8.1580067,0.0,0,1.4800345,0.0,0.78394336,134.38167,1.7475624,287.05176,-9.3132086
2141,2141,145.4175,23.271782,8.1835995,0.0,0,1.4523864,0.0,0.7893067,134.53253,1.7154136,286.78467,-9.3128662
2143,2143,145.4179,23.392626,8.2135429,0.0,0,1.4247384,0.0,0.79225332,134.75568,1.6861333,286.51758,-9.3137636
2145,2145,145.4183,23.518902,8.244647,0.0,0,1.3970906,0.0,0.79690272,134.88885,1.6593269,286.25049,-9.3138056
2147,2147,145.4187,23.657396,8.2665501,0.0,0,1.3694425,0.0,0.80159014,135.05217,1.6319443,285.9834,-9.3136234
2149,2149,145.4191,23.819824,8.3032923,0.0,0,1.3417945,0.0,0.80502278,135.4744,1.6046855,285.71631,-9.3140545
2151,2151,145.4195,23.960146,8.3289261,0.0,0,1.3141465,0.0,0.81015605,135.61102,1.5739563,285.44922,-9.3126373
2153,2153,145.4199,24.082176,8.3540144,0.0,0,1.2864985,0.0,0.81423849,135.76384,1.5445412,285.18213,-9.3130569
2155,2155,145.4203,24.20439,8.3924398,0.0,0,1.2588505,0.0,0.81834131,135.88077,1.5153178,284.91504,-9.3123083
2157,2157,145.4207,24.343658,8.4113903,0.0,0,1.2312026,0.0,0.8229658,136.05263,1.4869902,284.64795,-9.312788
2159,2159,145.4211,24.520664,8.4369345,0.0,0,1.2044448,0.0,0.8262704,136.52084,1.4568893,284.38086,-9.312727
2161,2161,145.4215,24.666552,8.4754066,0.0,0,1.1781459,0.0,0.83111233,136.72173,1.428854,284.11377,-9.3127689
2163,2163,145.4219,24.793865,8.4938412,0.0,0,1.1518499,0.0,0.8358748,136.77231,1.4021909,283.84668,-9.3128023
2165,2165,145.4223,24.910046,8.5244541,0.0,0,1.1255538,0.0,0.83904088,136.99367,1.3729303,283.88248,-9.3129044
2167,2167,145.4227,25.073507,8.5562353,0.0,0,1.0992578,0.0,0.84430546,137.13998,1.3462719,284.0191,-9.3122959
2169,2169,145.4231,25.25576,8.5730009,0.0,0,1.0729618,0.0,0.84791434,137.60568,1.3187071,284.15573,-9.3120356
2171,2171,145.4235,25.393372,8.6053829,0.0,0,1.0466658,0.0,0.85121787,137.93771,1.2924755,284.29236,-9.3110161
2173,2173,145.4239,25.511999,8.6350155,0.0,0,1.0203698,0.0,0.85719991,137.75864,1.2670128,284.42899,-9.3123245
2175,2175,145.4243,25.661581,8.6570005,0.0,0,0.99407381,0.0,0.86071217,138.03651,1.2397858,284.56561,-9.3128109
2177,2177,145.4247,25.826408,8.6880112,0.0,0,0.96777779,0.0,0.86448354,138.42894,1.211153,284.70224,-9.3119535
2179,2179,145.4251,26.012594,8.7100391,0.0,0,0.94148183,0.0,0.86958814,138.72639,1.1858929,284.83887,-9.3122377
2181,2181,145.4255,26.158842,8.7343092,0.0,0,0.91518587,0.0,0.87240875,139.13942,1.1622334,284.97549,-9.3119974
2183,2183,145.4259,26.28525,8.7635889,0.0,0,0.88915426,0.0,0.87670016,139.20805,1.1309909,285.11212,-9.3117962
2185,2185,145.4263,26.431217,8.7849665,0.0,0,0.86408323,0.0,0.88174874,139.25974,1.1073854,285.24875,-9.3121119
2187,2187,145.4267,26.60099,8.8164787,0.0,0,0.83907515,0.0,0.88482463,139.71236,1.0826416,285.38538,-9.312294
2189,2189,145.4271,26.792923,8.8410664,0.0,0,0.81406713,0.0,0.88970971,140.05354,1.0560426,285.522,-9.3117924
2191,2191,145.4275,26.934921,8.8618841,0.0,0,0.78905916,0.0,0.89406955,140.16512,1.0295419,285.65863,-9.3120403
2193,2193,145.4279,27.073471,8.8959675,0.0,0,0.76405114,0.0,0.89752138,140.43945,1.0029526,285.79529,-9.3115377
2195,2195,145.4283,27.243166,8.9146023,0.0,0,0.73904312,0.0,0.90224808,140.60834,0.97693348,285.93192,-9.311924
2197,2197,145.4287,27.417358,8.9359741,0.0,0,0.71403515,0.0,0.90557778,141.04778,0.94986683,286.06854,-9.3122768
2199,2199,145.4291,27.6014,8.9706736,0.0,0,0.68902713,0.0,0.90979266,141.39813,0.92625773,286.20517,-9.3117228
2201,2201,145.4295,27.753153,8.9862041,0.0,0,0.66401917,0.0,0.91459799,141.51871,0.90104371,286.3418,-9.3104
2203,2203,145.4299,27.899952,9.0136757,0.0,0,0.63901114,0.0,0.91782224,141.77814,0.87149256,286.47842,-9.3105736
2205,2205,145.4303,28.067116,9.0479803,0.0,0,0.61400312,0.0,0.923159,141.90253,0.85050988,286.61505,-9.3109474
2207,2207,145.4307,28.273081,9.0608387,0.0,0,0.58899516,0.0,0.92723221,142.29811,0.8265475,286.75168,-9.3112917
2209,2209,145.4311,28.446243,9.0884199,0.0,0,0.56478256,0.0,0.92987716,142.8282,0.80097204,286.88831,-9.3119059
2211,2211,145.4315,28.613094,9.1158895,0.0,0,0.54098004,0.0,0.93560529,142.86008,0.77488047,287.02493,-9.3110609
2213,2213,145.4319,28.767683,9.1342936,0.0,0,0.51717997,0.0,0.93908703,143.12354,0.74594295,287.16156,-9.3103447
2215,2215,145.4323,28.941845,9.1644173,0.0,0,0.49337998,0.0,0.94258553,143.48918,0.72741956,287.34079,-9.3097525
2217,2217,145.4327,29.141888,9.1871176,0.0,0,0.46957999,0.0,0.9483878,143.62918,0.70053548,287.53418,-9.3101158
2219,2219,145.4331,29.318716,9.2077971,0.0,0,0.44577998,0.0,0.95125568,144.11761,0.67489523,287.72757,-9.3109655
2221,2221,145.4335,29.489557,9.2355566,0.0,0,0.42197999,0.0,0.95520872,144.35933,0.65284365,287.92096,-9.3113899
2223,2223,145.4339,29.648695,9.2551441,0.0,0,0.39817998,0.0,0.96046227,144.40552,0.6284954,288.11438,-9.31001
2225,2225,145.4343,29.832609,9.2802277,0.0,0,0.37437996,0.0,0.96308261,144.9057,0.60425615,288.30777,-9.3089027
2227,2227,145.4347,30.04575,9.3056316,0.0,0,0.35057998,0.0,0.96782625,145.20107,0.58188647,288.50116,-9.3078556
2229,2229,145.4351,30.22558,9.322854,0.0,0,0.32677999,0.0,0.97239572,145.48068,0.5569061,288.69458,-9.3091059
2231,2231,145.4355,30.395836,9.3529167,0.0,0,0.30297998,0.0,0.97546744,145.83519,0.53494269,288.88797,-9.3095427
2233,2233,145.4359,30.561296,9.371995,0.0,0,0.27941972,0.0,0.98019707,145.95355,0.51165944,289.08136,-9.3106728
2235,2235,145.4363,30.737118,9.3900795,0.0,0,0.25673065,0.0,0.98374611,146.25948,0.4882437,289.27475,-9.3111095