File: examples/hot axisymmetric compression example/data/03 trimmed data/testID_0133.csv
level_0,index,Time(sec),Force(kN),Jaw(mm),PowAngle(deg),Power(W),Pram,PTemp,Strain,Stress(MPa),Stroke(mm),TC1(C),wedge(mm)
1774,1774,145.3667,1.1697621,0.0090850368,0.0,0,9.0044422,0.0,0.00034193476,13.221002,9.9895821,300.78027,-9.3248425
1776,1776,145.3671,4.3669977,0.055429477,0.0,0,8.9459143,0.0,0.0034001493,51.018879,9.9177094,300.89557,-9.323473
1778,1778,145.3675,6.0283017,0.10262972,0.0,0,8.8873863,0.0,0.0066933464,74.986404,9.861083,301.01083,-9.3223629
1780,1780,145.3679,7.0650787,0.1944975,0.0,0,8.8288584,0.0,0.011987154,87.384674,9.7862291,301.1261,-9.3211899
1782,1782,145.3683,7.6501145,0.33340281,0.0,0,8.7703304,0.0,0.021935046,94.859306,9.6963987,301.24136,-9.3197479
1784,1784,145.3687,8.3719501,0.41452417,0.0,0,8.7136879,0.0,0.027457312,102.63782,9.5964375,301.35666,-9.3191252
1786,1786,145.3691,8.9396152,0.51451308,0.0,0,8.6580172,0.0,0.034084674,109.52855,9.4996624,301.47192,-9.3180056
1788,1788,145.3695,9.6441574,0.55628312,0.0,0,8.6023531,0.0,0.037936956,117.5085,9.413949,301.58719,-9.3172369
1790,1790,145.3699,9.414608,0.60045606,0.0,0,8.546689,0.0,0.040187769,115.61593,9.346242,301.70245,-9.316433
1792,1792,145.3703,9.6504068,0.66833168,0.0,0,8.4910259,0.0,0.045162011,116.88012,9.2895164,301.81775,-9.318428
1794,1794,145.3707,10.037052,0.70354307,0.0,0,8.4353609,0.0,0.048033461,121.30593,9.2304287,301.93301,-9.3181343
1796,1796,145.3711,10.453019,0.79523015,0.0,0,8.3796968,0.0,0.053284135,125.87029,9.1609602,302.04828,-9.3166647
1798,1798,145.3715,10.114444,0.90015411,0.0,0,8.3240337,0.0,0.061361965,121.61005,9.0785971,302.16354,-9.3156061
1800,1800,145.3719,10.334159,0.97965664,0.0,0,8.2683697,0.0,0.066966549,122.51146,8.9928589,302.27884,-9.3165026
1802,1802,145.3723,10.460711,1.0619305,0.0,0,8.2127056,0.0,0.072639421,123.92935,8.913763,302.3941,-9.3171759
1804,1804,145.3727,10.751703,1.0816581,0.0,0,8.1570415,0.0,0.07492277,126.35678,8.8456907,302.50937,-9.3183184
1806,1806,145.3731,10.828257,1.1300635,0.0,0,8.1013775,0.0,0.077764288,127.94794,8.7872581,302.62463,-9.3169355
1808,1808,145.3735,10.732053,1.1937256,0.0,0,8.0462685,0.0,0.082361706,125.67101,8.7359552,302.73993,-9.3164492
1810,1810,145.3739,11.040557,1.2373143,0.0,0,7.993176,0.0,0.085867077,128.81738,8.680541,302.85519,-9.3157167
1812,1812,145.3743,11.114555,1.3216037,0.0,0,7.9402156,0.0,0.091445111,129.05272,8.6194506,302.97046,-9.3149748
1814,1814,145.3747,11.095923,1.3983256,0.0,0,7.8872557,0.0,0.097315699,128.36212,8.5502195,303.08572,-9.3161297
1816,1816,145.3751,11.066709,1.4627407,0.0,0,7.8342957,0.0,0.10229009,126.96053,8.4804688,303.20712,-9.3170214
1818,1818,145.3755,11.174508,1.5214498,0.0,0,7.7813354,0.0,0.10636792,128.01332,8.4156561,303.34686,-9.3172598
1820,1820,145.3759,11.31817,1.5550402,0.0,0,7.7283754,0.0,0.10936543,128.88808,8.3597832,303.4866,-9.3165951
1822,1822,145.3763,11.414923,1.6102185,0.0,0,7.675415,0.0,0.11320975,129.88885,8.309516,303.62637,-9.3166409
1824,1824,145.3767,11.382804,1.65693,0.0,0,7.6224551,0.0,0.11654051,128.84372,8.2576151,303.76611,-9.3150778
1826,1826,145.3771,11.630391,1.7033873,0.0,0,7.5694952,0.0,0.12043664,131.11703,8.2095661,303.90585,-9.3148708
1828,1828,145.3775,11.594741,1.7733762,0.0,0,7.5165353,0.0,0.12509046,130.35388,8.1565714,304.04559,-9.3162451
1830,1830,145.3779,11.666566,1.8301557,0.0,0,7.4635754,0.0,0.12958251,130.46051,8.096076,304.18533,-9.3168192
1832,1832,145.3783,11.633227,1.8892077,0.0,0,7.410615,0.0,0.13449839,129.59805,8.0363235,304.3251,-9.3160896
1834,1834,145.3787,11.729156,1.9353223,0.0,0,7.3593612,0.0,0.13755345,129.98495,7.984921,304.46484,-9.3170691
1836,1836,145.3791,11.886075,1.9696317,0.0,0,7.3089881,0.0,0.14052704,131.3849,7.9303107,304.60458,-9.3147621
1838,1838,145.3795,11.883195,2.0219061,0.0,0,7.2586198,0.0,0.14459676,131.00806,7.8809509,304.74432,-9.3146849
1840,1840,145.3799,11.902253,2.0724616,0.0,0,7.2082515,0.0,0.14791985,130.62601,7.8400321,304.88406,-9.3154535
1842,1842,145.3803,12.001151,2.1197758,0.0,0,7.1578832,0.0,0.15220095,131.09041,7.7916265,305.02383,-9.3153305
1844,1844,145.3807,12.139552,2.1728401,0.0,0,7.1075153,0.0,0.15609851,132.10051,7.7384553,305.16357,-9.3154507
1846,1846,145.3811,12.12826,2.2331917,0.0,0,7.0571475,0.0,0.16041236,131.66103,7.6831708,305.30331,-9.315588
1848,1848,145.3815,12.127222,2.2832994,0.0,0,7.0067792,0.0,0.16512182,130.86284,7.6275177,305.44305,-9.3152189
1850,1850,145.3819,12.180955,2.3240306,0.0,0,6.9564114,0.0,0.16785638,130.98302,7.5800691,305.58279,-9.3150778
1852,1852,145.3823,12.327658,2.3746924,0.0,0,6.9060431,0.0,0.17173798,132.06157,7.53192,305.72256,-9.3155613
1854,1854,145.3827,12.364279,2.4151025,0.0,0,6.8556757,0.0,0.1755345,132.00662,7.4831219,305.8623,-9.3150597
1856,1856,145.3831,12.38343,2.4592474,0.0,0,6.8053074,0.0,0.17845595,131.87712,7.4365549,306.00204,-9.3150835
1858,1858,145.3835,12.440351,2.5159817,0.0,0,6.7554417,0.0,0.18327819,131.72153,7.3870745,306.14178,-9.3148441
1860,1860,145.3839,12.539041,2.5600557,0.0,0,6.7074022,0.0,0.18687829,132.25279,7.3376408,306.28152,-9.3156214
1862,1862,145.3843,12.569303,2.6141758,0.0,0,6.6594815,0.0,0.19082627,132.18484,7.2895517,306.4213,-9.3159027
1864,1864,145.3847,12.615844,2.6644945,0.0,0,6.6115613,0.0,0.19553165,131.98697,7.2378378,306.56104,-9.3169794
1866,1866,145.3851,12.670658,2.7047889,0.0,0,6.5636415,0.0,0.19844672,132.26315,7.1920028,306.66492,-9.3170481
1868,1868,145.3855,12.739336,2.7567909,0.0,0,6.5157218,0.0,0.20244998,132.4187,7.142518,306.66125,-9.3162174
1870,1870,145.3859,12.797793,2.7968121,0.0,0,6.467802,0.0,0.20642574,132.48228,7.0981159,306.65756,-9.3150129
1872,1872,145.3863,12.865599,2.8486605,0.0,0,6.4198818,0.0,0.20985317,132.69899,7.0478082,306.6539,-9.315053
1874,1874,145.3867,12.929694,2.8997905,0.0,0,6.3719616,0.0,0.21436639,132.75836,7.0012879,306.65024,-9.3153267
1876,1876,145.3871,12.99898,2.9430242,0.0,0,6.3240418,0.0,0.21831729,133.04424,6.9553328,306.64658,-9.3169937
1878,1878,145.3875,13.022959,3.0044863,0.0,0,6.2761221,0.0,0.22260267,132.7018,6.8998666,306.64288,-9.3165255
1880,1880,145.3879,13.047662,3.047143,0.0,0,6.2282019,0.0,0.22687092,132.32022,6.8525577,306.63922,-9.3158503
1882,1882,145.3883,13.151754,3.0897844,0.0,0,6.1802821,0.0,0.23032108,132.9343,6.8020692,306.63556,-9.317008
1884,1884,145.3887,13.235262,3.1458066,0.0,0,6.1339049,0.0,0.23446463,133.2204,6.75667,306.6319,-9.3157682
1886,1886,145.3891,13.288211,3.1813278,0.0,0,6.0883236,0.0,0.23830822,133.33611,6.7051659,306.62823,-9.3156109
1888,1888,145.3895,13.316385,3.2309186,0.0,0,6.042748,0.0,0.24203523,133.1541,6.6554928,306.62454,-9.3164654
1890,1890,145.3899,13.379495,3.2886581,0.0,0,5.9971719,0.0,0.24682994,132.96155,6.6098967,306.62088,-9.3160791
1892,1892,145.3903,13.490265,3.3308749,0.0,0,5.9515953,0.0,0.25107241,133.51057,6.5601735,306.61722,-9.3170128
1894,1894,145.3907,13.538468,3.3878658,0.0,0,5.9060202,0.0,0.25522402,133.49854,6.5062132,306.61356,-9.31637
1896,1896,145.3911,13.566675,3.43735,0.0,0,5.8604436,0.0,0.25987926,133.15442,6.459075,306.60986,-9.3150682
1898,1898,145.3915,13.612935,3.479064,0.0,0,5.8148675,0.0,0.2637091,133.10576,6.4114275,306.6062,-9.3151407
1900,1900,145.3919,13.681659,3.5279825,0.0,0,5.7692914,0.0,0.26743135,133.21573,6.3611689,306.60254,-9.3158607
1902,1902,145.3923,13.78044,3.5739396,0.0,0,5.7237153,0.0,0.27205482,133.61319,6.3144236,306.59888,-9.3165541
1904,1904,145.3927,13.811548,3.6221268,0.0,0,5.6781397,0.0,0.27606559,133.45157,6.264873,306.59518,-9.3164377
1906,1906,145.3931,13.866257,3.671411,0.0,0,5.6325636,0.0,0.28008589,133.3214,6.2183595,306.59152,-9.315239
1908,1908,145.3935,13.919384,3.7192874,0.0,0,5.5874419,0.0,0.28491873,133.22276,6.1682992,306.58786,-9.3161917
1910,1910,145.3939,13.994837,3.7702067,0.0,0,5.5439739,0.0,0.28878284,133.42345,6.1212039,306.5842,-9.3161793
1912,1912,145.3943,14.059449,3.8159423,0.0,0,5.5006137,0.0,0.29306009,133.47458,6.0733056,306.58051,-9.3168058
1914,1914,145.3947,14.115295,3.8597322,0.0,0,5.4572535,0.0,0.29757696,133.40039,6.0257769,306.57684,-9.316968
1916,1916,145.3951,14.158712,3.9117153,0.0,0,5.4138937,0.0,0.30133396,133.37196,5.9798784,306.5459,-9.3157358
1918,1918,145.3955,14.225893,3.9548206,0.0,0,5.3705335,0.0,0.30581865,133.35698,5.9314981,306.4332,-9.3153982
1920,1920,145.3959,14.272043,4.0009904,0.0,0,5.3271737,0.0,0.31003839,133.28143,5.8864384,306.32047,-9.3160324
1922,1922,145.3963,14.34836,4.053823,0.0,0,5.2838135,0.0,0.31409433,133.32843,5.8401356,306.20773,-9.3174648
1924,1924,145.3967,14.407469,4.0932422,0.0,0,5.2404532,0.0,0.31857809,133.37653,5.7924542,306.095,-9.317337
1926,1926,145.3971,14.460972,4.1380711,0.0,0,5.1970935,0.0,0.32235089,133.29849,5.7457829,305.98227,-9.3164034
1928,1928,145.3975,14.51388,4.1934242,0.0,0,5.1537337,0.0,0.32702425,133.19333,5.699708,305.86957,-9.3158007
1930,1930,145.3979,14.575425,4.2338605,0.0,0,5.1103735,0.0,0.33168256,133.10576,5.6536398,305.75684,-9.3160477
1932,1932,145.3983,14.658116,4.281177,0.0,0,5.0670133,0.0,0.33538181,133.35699,5.606112,305.6441,-9.3167667
1934,1934,145.3987,14.723126,4.3351812,0.0,0,5.0250487,0.0,0.34039646,133.35472,5.5609951,305.53137,-9.315918
1936,1936,145.3991,14.764081,4.3717084,0.0,0,4.9838042,0.0,0.34451923,133.10602,5.5120559,305.41864,-9.3158941
1938,1938,145.3995,14.811089,4.4197493,0.0,0,4.942564,0.0,0.34828576,133.04346,5.4628835,305.30594,-9.3170147
1940,1940,145.3999,14.866258,4.467114,0.0,0,4.9013243,0.0,0.35340714,132.89435,5.4157572,305.19321,-9.3163519
1942,1942,145.4003,14.958204,4.5070615,0.0,0,4.8600841,0.0,0.35709503,133.14792,5.3727984,305.08047,-9.3164377
1944,1944,145.4007,15.020097,4.5580893,0.0,0,4.8188443,0.0,0.36144587,133.18132,5.3257809,304.96774,-9.3146515
1946,1946,145.4011,15.062298,4.6012182,0.0,0,4.7776041,0.0,0.36645219,132.97182,5.2795215,304.85501,-9.3154593
1948,1948,145.4015,15.113685,4.6460614,0.0,0,4.7363639,0.0,0.37020391,132.89334,5.2345643,304.74231,-9.3168097
1950,1950,145.4019,15.18965,4.6927519,0.0,0,4.6951241,0.0,0.3745777,132.87692,5.1911082,304.62958,-9.3162317
1952,1952,145.4023,15.28013,4.7321229,0.0,0,4.6538844,0.0,0.37923509,133.07887,5.1453447,304.51685,-9.3150892
1954,1954,145.4027,15.331079,4.7834463,0.0,0,4.6126437,0.0,0.38326976,133.02309,5.1022501,304.40411,-9.3157835
1956,1956,145.4031,15.381878,4.8256125,0.0,0,4.571404,0.0,0.38780448,132.91039,5.0577378,304.29138,-9.3158941
1958,1958,145.4035,15.427872,4.864747,0.0,0,4.5305758,0.0,0.39198211,132.70688,5.0174022,304.17868,-9.3154917
1960,1960,145.4039,15.504635,4.9181695,0.0,0,4.4912457,0.0,0.3961615,132.73926,4.9731097,304.06595,-9.3147516
1962,1962,145.4043,15.585431,4.95504,0.0,0,4.4520135,0.0,0.40074995,132.90329,4.9292541,303.95322,-9.3149176
1964,1964,145.4047,15.644625,4.997107,0.0,0,4.4127817,0.0,0.40481794,132.85464,4.8846221,303.84048,-9.3169394
1966,1966,145.4051,15.688069,5.0491948,0.0,0,4.3735499,0.0,0.40936786,132.58989,4.8403625,303.71606,-9.3173704
1968,1968,145.4055,15.752136,5.084187,0.0,0,4.3343177,0.0,0.41395935,132.56,4.7986064,303.55658,-9.3161783
1970,1970,145.4059,15.82954,5.1291628,0.0,0,4.2950859,0.0,0.41780671,132.71057,4.7544546,303.39706,-9.3165684
1972,1972,145.4063,15.91543,5.1769938,0.0,0,4.2558532,0.0,0.42258334,132.79004,4.7129731,303.23755,-9.3162622
1974,1974,145.4067,15.982297,5.2108278,0.0,0,4.2166214,0.0,0.4268328,132.78966,4.670011,303.07806,-9.3157578
1976,1976,145.4071,16.021618,5.2557664,0.0,0,4.1773896,0.0,0.43046558,132.59544,4.6266799,302.91855,-9.3164206
1978,1978,145.4075,16.078693,5.3010736,0.0,0,4.1381574,0.0,0.4356983,132.32401,4.5869856,302.75906,-9.3173103
1980,1980,145.4079,16.158813,5.3359432,0.0,0,4.0989256,0.0,0.43952942,132.47124,4.5442996,302.59955,-9.3169289
1982,1982,145.4083,16.247391,5.3818979,0.0,0,4.0596938,0.0,0.44347444,132.74608,4.5027914,302.44003,-9.3172884
1984,1984,145.4087,16.304237,5.4235363,0.0,0,4.0217257,0.0,0.44864953,132.46855,4.4605384,302.28055,-9.3164616
1986,1986,145.4091,16.345854,5.4615893,0.0,0,3.9844093,0.0,0.45226893,132.38831,4.4168983,302.12103,-9.3156786
1988,1988,145.4095,16.422743,5.5042338,0.0,0,3.9470973,0.0,0.45641553,132.43846,4.3786745,301.96155,-9.3163195
1990,1990,145.4099,16.544161,5.5419536,0.0,0,3.9097853,0.0,0.46133837,132.68741,4.338419,301.80203,-9.3171005
1992,1992,145.4103,16.61729,5.5845032,0.0,0,3.8724735,0.0,0.46501106,132.89421,4.2976084,301.64252,-9.3169441
1994,1994,145.4107,16.663017,5.6262145,0.0,0,3.8351612,0.0,0.46957746,132.58522,4.255218,301.48303,-9.317049
1996,1996,145.4111,16.713514,5.662899,0.0,0,3.7978494,0.0,0.47421321,132.40999,4.2167516,301.32352,-9.3154535
1998,1998,145.4115,16.800266,5.7087507,0.0,0,3.7605371,0.0,0.47791523,132.62349,4.1762686,301.16403,-9.3154898
2000,2000,145.4119,16.897141,5.7442799,0.0,0,3.7232254,0.0,0.48256803,132.75424,4.1335812,301.00452,-9.3156185
2002,2002,145.4123,16.975269,5.7807612,0.0,0,3.6859133,0.0,0.48658738,132.79387,4.0963206,300.845,-9.3155775
2004,2004,145.4127,17.043123,5.8293514,0.0,0,3.6486013,0.0,0.49081787,132.73827,4.0558677,300.68552,-9.3153334
2006,2006,145.4131,17.106499,5.8624139,0.0,0,3.6112893,0.0,0.49564755,132.61884,4.0183978,300.526,-9.3159132
2008,2008,145.4135,17.189512,5.898973,0.0,0,3.5743496,0.0,0.49920359,132.82942,3.9772835,300.36652,-9.3163891
2010,2010,145.4139,17.280582,5.9474096,0.0,0,3.538765,0.0,0.50403482,132.84715,3.9371693,300.207,-9.3156471
2012,2012,145.4143,17.364538,5.9782238,0.0,0,3.5032687,0.0,0.50854003,132.84384,3.9009769,300.04749,-9.3148909
2014,2014,145.4147,17.433939,6.019083,0.0,0,3.4677727,0.0,0.51212841,132.97498,3.8592832,299.888,-9.3154345
2016,2016,145.4151,17.504784,6.0634894,0.0,0,3.432277,0.0,0.51731431,132.75548,3.8206022,299.65482,-9.3158293
2018,2018,145.4155,17.577152,6.0953131,0.0,0,3.3967807,0.0,0.52151853,132.79784,3.7834563,299.20068,-9.3159456
2020,2020,145.4159,17.669851,6.1387277,0.0,0,3.3612847,0.0,0.52539104,132.96034,3.7444155,298.74658,-9.3148546
2022,2022,145.4163,17.76943,6.1774712,0.0,0,3.3257887,0.0,0.53068155,133.00766,3.7055235,298.29245,-9.3138628
2024,2024,145.4167,17.837444,6.2098413,0.0,0,3.2902927,0.0,0.53425729,133.12704,3.6661081,297.83832,-9.3157406
2026,2026,145.4171,17.907398,6.2521362,0.0,0,3.2547965,0.0,0.53832865,133.03587,3.6282737,297.38419,-9.3162022
2028,2028,145.4175,17.987858,6.2872205,0.0,0,3.2193007,0.0,0.54345179,132.9229,3.59144,296.93008,-9.3172684
2030,2030,145.4179,18.106194,6.3251729,0.0,0,3.1838048,0.0,0.54700488,133.28131,3.5537827,296.47595,-9.3163271
2032,2032,145.4183,18.190474,6.3653355,0.0,0,3.1483088,0.0,0.55148977,133.3616,3.5186622,296.02182,-9.3147087
2034,2034,145.4187,18.253099,6.3985472,0.0,0,3.11395,0.0,0.55634397,133.17381,3.4833903,295.56769,-9.3150749
2036,2036,145.4191,18.325104,6.4404154,0.0,0,3.0801783,0.0,0.56004173,133.17999,3.4452868,295.11359,-9.3154116
2038,2038,145.4195,18.396149,6.4742312,0.0,0,3.0464106,0.0,0.5645889,133.11238,3.4088602,294.65945,-9.315485
2040,2040,145.4199,18.511349,6.5062451,0.0,0,3.0126424,0.0,0.56874079,133.41383,3.371793,294.20532,-9.3156099
2042,2042,145.4203,18.613537,6.55446,0.0,0,2.9788744,0.0,0.57295513,133.55634,3.3362091,293.75119,-9.3158836
2044,2044,145.4207,18.682224,6.5834913,0.0,0,2.9451065,0.0,0.57776886,133.39819,3.2978785,293.29706,-9.3156519
2046,2046,145.4211,18.760427,6.6181879,0.0,0,2.9113381,0.0,0.5816521,133.46631,3.2607436,292.84296,-9.3161335
2048,2048,145.4215,18.856215,6.6604924,0.0,0,2.8775704,0.0,0.5859223,133.56522,3.2253411,292.38882,-9.3153591
2050,2050,145.4219,18.975084,6.6876826,0.0,0,2.8438022,0.0,0.59050745,133.79228,3.19034,291.93469,-9.3146877
2052,2052,145.4223,19.063534,6.724546,0.0,0,2.810034,0.0,0.59404194,134.01184,3.1526151,291.48056,-9.3148899
2054,2054,145.4227,19.14229,6.7674646,0.0,0,2.7762663,0.0,0.59911096,133.82608,3.1169806,291.02646,-9.3156204
2056,2056,145.4231,19.220507,6.7932677,0.0,0,2.7424984,0.0,0.60331285,133.82976,3.083045,290.57233,-9.3158436
2058,2058,145.4235,19.326651,6.8348527,0.0,0,2.7090683,0.0,0.60710305,134.00615,3.046623,290.11819,-9.314641
2060,2060,145.4239,19.441956,6.8735962,0.0,0,2.6768677,0.0,0.61258036,134.10309,3.0153644,289.66406,-9.3140097
2062,2062,145.4243,19.550022,6.9010954,0.0,0,2.6447473,0.0,0.61634988,134.30421,2.9791231,289.20996,-9.3140869
2064,2064,145.4247,19.61607,6.9404535,0.0,0,2.6126273,0.0,0.62008774,134.31421,2.9408386,288.75583,-9.314085
2066,2066,145.4251,19.69656,6.9716568,0.0,0,2.5805073,0.0,0.62524652,134.12807,2.9080207,288.41925,-9.3138657
2068,2068,145.4255,19.813995,7.0030346,0.0,0,2.5483873,0.0,0.6285069,134.4734,2.8722403,288.43521,-9.313653
2070,2070,145.4259,19.943844,7.0419626,0.0,0,2.5162673,0.0,0.63306063,134.75664,2.8376629,288.45117,-9.3140574
2072,2072,145.4263,20.046013,7.0729785,0.0,0,2.4841473,0.0,0.63816077,134.73219,2.8032217,288.46713,-9.3145819
2074,2074,145.4267,20.120838,7.1106963,0.0,0,2.4520273,0.0,0.64159542,134.78667,2.7724142,288.48312,-9.3140526
2076,2076,145.4271,20.215918,7.1461821,0.0,0,2.4199073,0.0,0.64651126,134.75426,2.7355254,288.49908,-9.3146524
2078,2078,145.4275,20.32641,7.174057,0.0,0,2.3877873,0.0,0.65093672,134.87819,2.7036886,288.51505,-9.3143244
2080,2080,145.4279,20.456915,7.2146854,0.0,0,2.3556671,0.0,0.65446478,135.28749,2.6704488,288.53101,-9.3140621
2082,2082,145.4283,20.542923,7.2429447,0.0,0,2.3235474,0.0,0.65936792,135.22313,2.6370447,288.54697,-9.3132496
2084,2084,145.4287,20.623795,7.2719135,0.0,0,2.2924595,0.0,0.66307318,135.23169,2.6033237,288.56296,-9.3145456
2086,2086,145.4291,20.728754,7.3129683,0.0,0,2.2619042,0.0,0.66721487,135.3591,2.5708187,288.57892,-9.3146009
2088,2088,145.4295,20.860884,7.3382335,0.0,0,2.2313523,0.0,0.67199844,135.53795,2.539423,288.59488,-9.3143682
2090,2090,145.4299,20.988441,7.3710761,0.0,0,2.2008004,0.0,0.67557162,135.91917,2.5062566,288.61084,-9.3140068
2092,2092,145.4303,21.07737,7.4118052,0.0,0,2.1702483,0.0,0.68047333,135.8683,2.471674,288.6268,-9.3133564
2094,2094,145.4307,21.158913,7.434607,0.0,0,2.1396964,0.0,0.68479967,135.76527,2.4439151,288.64279,-9.3131227
2096,2096,145.4311,21.267683,7.468359,0.0,0,2.1091442,0.0,0.68794054,136.03636,2.4112806,288.65875,-9.3141956
2098,2098,145.4315,21.389336,7.5026913,0.0,0,2.0785923,0.0,0.69297898,136.13274,2.3814678,288.67471,-9.3153801
2100,2100,145.4319,21.513329,7.5265479,0.0,0,2.0480404,0.0,0.69693363,136.36548,2.3495805,288.69067,-9.3148413
2102,2102,145.4323,21.62311,7.5657973,0.0,0,2.0174885,0.0,0.70077401,136.51779,2.3174927,288.70663,-9.3154869
2104,2104,145.4327,21.734564,7.5977325,0.0,0,1.9869361,0.0,0.70621037,136.43716,2.2856123,288.72263,-9.3135815
2106,2106,145.4331,21.846926,7.6231213,0.0,0,1.9563841,0.0,0.70957822,136.70692,2.2545767,288.73859,-9.3122616
2108,2108,145.4335,21.978752,7.6584468,0.0,0,1.9261373,0.0,0.71344167,137.0498,2.2214479,288.75455,-9.311985
2110,2110,145.4339,22.107725,7.6860089,0.0,0,1.8970004,0.0,0.71868432,137.13878,2.1890833,288.77051,-9.3137779
2112,2112,145.4343,22.212618,7.7184558,0.0,0,1.8679364,0.0,0.72196388,137.34778,2.1568,288.78647,-9.3143892
2114,2114,145.4347,22.318068,7.7532525,0.0,0,1.8388724,0.0,0.72676152,137.29134,2.1274579,288.80246,-9.3141069
2116,2116,145.4351,22.433331,7.7799201,0.0,0,1.8098084,0.0,0.73161429,137.37167,2.095361,288.94333,-9.3142691
2118,2118,145.4355,22.578251,7.8166552,0.0,0,1.7807443,0.0,0.73526591,137.71956,2.0647612,289.4588,-9.3135643
2120,2120,145.4359,22.716816,7.8430319,0.0,0,1.7516804,0.0,0.73963761,137.96179,2.0371923,289.97427,-9.3124208
2122,2122,145.4363,22.824776,7.8677669,0.0,0,1.7226164,0.0,0.74363303,138.12433,2.0040975,290.48975,-9.3118315
2124,2124,145.4367,22.947935,7.9072142,0.0,0,1.6935524,0.0,0.74750942,138.25284,1.9702277,291.00522,-9.312129
2126,2126,145.4371,23.08403,7.9308147,0.0,0,1.6644883,0.0,0.75238723,138.36685,1.9430538,291.52069,-9.312582
2128,2128,145.4375,23.225227,7.960794,0.0,0,1.6354244,0.0,0.75609511,138.71098,1.9112514,292.03616,-9.3132782
2130,2130,145.4379,23.359188,8.0014591,0.0,0,1.6063604,0.0,0.76096594,138.87772,1.8814009,292.55164,-9.3136492
2132,2132,145.4383,23.485342,8.0210972,0.0,0,1.5772964,0.0,0.76554561,138.98912,1.8522683,293.06711,-9.3128328
2134,2134,145.4387,23.596394,8.0531816,0.0,0,1.5491644,0.0,0.7688573,139.24475,1.8225425,293.58258,-9.3124294
2136,2136,145.4391,23.733099,8.0883265,0.0,0,1.5215132,0.0,0.77407587,139.24371,1.7962348,294.09805,-9.3124952
2138,2138,145.4395,23.886663,8.1063843,0.0,0,1.4938653,0.0,0.77786613,139.61609,1.7668599,294.61353,-9.3125277
2140,2140,145.4399,24.028248,8.139761,0.0,0,1.4662173,0.0,0.78104132,140.01373,1.7374384,295.129,-9.3123827
2142,2142,145.4403,24.146326,8.1713734,0.0,0,1.4385693,0.0,0.78676611,139.92612,1.7067991,295.6445,-9.3118973
2144,2144,145.4407,24.269432,8.1947889,0.0,0,1.4109213,0.0,0.79035121,140.11177,1.6798663,296.15997,-9.3114214
2146,2146,145.4411,24.406879,8.2300587,0.0,0,1.3832734,0.0,0.79446554,140.30846,1.6515518,296.67545,-9.3119478
2148,2148,145.4415,24.570236,8.2552338,0.0,0,1.3556253,0.0,0.79975069,140.49001,1.6230112,297.19092,-9.3124561
2150,2150,145.4419,24.721075,8.2825003,0.0,0,1.3279774,0.0,0.80277956,140.95381,1.5957317,297.70639,-9.3125153
2152,2152,145.4423,24.854773,8.3159208,0.0,0,1.3003293,0.0,0.80731505,141.05992,1.5683808,298.22186,-9.3134604
2154,2154,145.4427,24.979624,8.3387785,0.0,0,1.2726814,0.0,0.8124125,141.05508,1.5373696,298.73734,-9.3129749
2156,2156,145.4431,25.123898,8.369482,0.0,0,1.2450334,0.0,0.81539083,141.46881,1.5089447,299.25281,-9.3119888
2158,2158,145.4435,25.296705,8.3950405,0.0,0,1.2176627,0.0,0.81982136,141.8055,1.4831997,299.76828,-9.3118792
2160,2160,145.4439,25.455835,8.4156895,0.0,0,1.1913006,0.0,0.82398212,142.08321,1.4503902,300.28375,-9.3112745
2162,2162,145.4443,25.583136,8.4531088,0.0,0,1.1650045,0.0,0.82751662,142.32021,1.4233832,300.79922,-9.3123693
2164,2164,145.4447,25.712929,8.4766598,0.0,0,1.1387084,0.0,0.8326295,142.29088,1.3976132,301.3147,-9.3129511
2166,2166,145.4451,25.862759,8.5029707,0.0,0,1.1124125,0.0,0.83659488,142.55872,1.3709046,301.72095,-9.3123455
2168,2168,145.4455,26.053585,8.5416155,0.0,0,1.0861164,0.0,0.84108704,142.98851,1.3416151,301.79956,-9.3118038
2170,2170,145.4459,26.225338,8.5578833,0.0,0,1.0598203,0.0,0.84563822,143.22585,1.3154886,301.87817,-9.3108006
2172,2172,145.4463,26.352383,8.5829744,0.0,0,1.0335244,0.0,0.84842569,143.59598,1.2879249,301.95676,-9.3109694
2174,2174,145.4467,26.504618,8.6171217,0.0,0,1.0072284,0.0,0.85326779,143.67148,1.2625499,302.03537,-9.310956
2176,2176,145.4471,26.677223,8.6336727,0.0,0,0.98093235,0.0,0.85760081,143.96758,1.2356583,302.11398,-9.3115711
2178,2178,145.4475,26.874985,8.6653461,0.0,0,0.95463634,0.0,0.86086172,144.57037,1.2072734,302.1926,-9.3099794
2180,2180,145.4479,27.022087,8.6973324,0.0,0,0.92834044,0.0,0.8665877,144.57408,1.1794939,302.27118,-9.31077
2182,2182,145.4483,27.159533,8.715457,0.0,0,0.90204442,0.0,0.87031454,144.76875,1.1535516,302.34979,-9.3099432
2184,2184,145.4487,27.321964,8.7474051,0.0,0,0.87659609,0.0,0.8737874,145.11554,1.1270949,302.42841,-9.3101482
2186,2186,145.4491,27.502731,8.7737894,0.0,0,0.85158539,0.0,0.8795498,145.24142,1.1004434,302.50702,-9.310957
2188,2188,145.4495,27.697981,8.7953835,0.0,0,0.82657731,0.0,0.88250148,145.86978,1.0736564,302.5856,-9.3105936
2190,2190,145.4499,27.867857,8.8256445,0.0,0,0.8015694,0.0,0.88637155,146.1429,1.0464748,302.66422,-9.3103447
2192,2192,145.4503,28.013321,8.8472223,0.0,0,0.77656138,0.0,0.89181662,146.08131,1.0194515,302.74283,-9.3097353
2194,2194,145.4507,28.170416,8.8761225,0.0,0,0.75155336,0.0,0.89487028,146.47034,0.99261039,302.82144,-9.3106833
2196,2196,145.4511,28.351236,8.9019814,0.0,0,0.72654539,0.0,0.89935809,146.7635,0.96782172,302.90002,-9.3101988
2198,2198,145.4515,28.542511,8.9205494,0.0,0,0.70153737,0.0,0.90379095,147.11234,0.94326466,302.97864,-9.3109493
2200,2200,145.4519,28.712351,8.953269,0.0,0,0.67652941,0.0,0.90694743,147.50786,0.91484618,303.05725,-9.310338
2202,2202,145.4523,28.866825,8.974534,0.0,0,0.65152138,0.0,0.9118399,147.55356,0.89348006,303.13586,-9.3101816
2204,2204,145.4527,29.03735,8.9950485,0.0,0,0.62651336,0.0,0.91560841,147.86049,0.86515605,303.21445,-9.3109455
2206,2206,145.4531,29.215694,9.0287342,0.0,0,0.6015054,0.0,0.91931492,148.28935,0.84174174,303.29306,-9.3113556
2208,2208,145.4535,29.410425,9.0466499,0.0,0,0.57674509,0.0,0.92431939,148.49072,0.81670308,303.37167,-9.311141
2210,2210,145.4539,29.579733,9.0697937,0.0,0,0.55288601,0.0,0.9275918,148.89021,0.79224789,303.45029,-9.3107634
2212,2212,145.4543,29.744986,9.1029387,0.0,0,0.52908593,0.0,0.93217391,149.01863,0.76778913,303.5289,-9.3100023
2214,2214,145.4547,29.919596,9.1157808,0.0,0,0.50528592,0.0,0.93653601,149.24669,0.74189585,303.60748,-9.3090982
2216,2216,145.4551,30.123791,9.1424093,0.0,0,0.4814859,0.0,0.93926245,149.81992,0.71848154,303.67746,-9.3092575
2218,2218,145.4555,30.317293,9.1731071,0.0,0,0.45768592,0.0,0.94477767,149.94838,0.69409734,303.7215,-9.3099461
2220,2220,145.4559,30.4834,9.1869593,0.0,0,0.4338859,0.0,0.94849133,150.25404,0.67139882,303.76553,-9.3104172
2222,2222,145.4563,30.658142,9.2154398,0.0,0,0.41008592,0.0,0.95138735,150.64746,0.6477474,303.80957,-9.3104668
2224,2224,145.4567,30.831066,9.2389202,0.0,0,0.3862859,0.0,0.95708233,150.65184,0.62222552,303.85361,-9.3094559
2226,2226,145.4571,31.021418,9.2551317,0.0,0,0.36248589,0.0,0.95989239,151.19521,0.59834743,303.89764,-9.3078356
2228,2228,145.4575,31.238953,9.2837248,0.0,0,0.3386859,0.0,0.96338081,151.66528,0.57248569,303.94168,-9.3085966
2230,2230,145.4579,31.428186,9.3059893,0.0,0,0.31488591,0.0,0.96923852,151.69554,0.55303949,303.98572,-9.3081779
2232,2232,145.4583,31.617704,9.326849,0.0,0,0.29108587,0.0,0.97175372,152.23909,0.53139675,304.02975,-9.3083248
2234,2234,145.4587,31.81245,9.3527765,0.0,0,0.26805463,0.0,0.97568792,152.57216,0.50862199,304.07379,-9.3079052
2235,2235,145.4589,31.91988,9.362114,0.0,0,0.25673628,0.0,0.97746998,152.83234,0.49414158,304.09579,-9.3083849